{"op":"mcm","clk":"11449075385","pt":1717303241523,"mc":[{"id":"1.229554928","marketDefinition":{"bspMarket":false,"turnInPlayEnabled":false,"persistenceEnabled":false,"marketBaseRate":7.0,"eventId":"33318908","eventTypeId":"4339","numberOfWinners":1,"bettingType":"ODDS","marketType":"QUINELLA","marketTime":"2024-06-02T10:41:00.000Z","suspendTime":"2024-06-02T10:41:00.000Z","bspReconciled":false,"complete":true,"inPlay":false,"crossMatching":true,"runnersVoidable":false,"numberOfActiveRunners":15,"betDelay":0,"status":"OPEN","runners":[{"status":"ACTIVE","sortPriority":1,"id":52671542,"name":"1 - 2 / 2 - 1"},{"status":"ACTIVE","sortPriority":2,"id":52671544,"name":"1 - 4 / 4 - 1"},{"status":"ACTIVE","sortPriority":3,"id":52237612,"name":"1 - 5 / 5 - 1"},{"status":"ACTIVE","sortPriority":4,"id":52671560,"name":"1 - 7 / 7 - 1"},{"status":"ACTIVE","sortPriority":5,"id":52671546,"name":"1 - 8 / 8 - 1"},{"status":"ACTIVE","sortPriority":6,"id":52671548,"name":"2 - 4 / 4 - 2"},{"status":"ACTIVE","sortPriority":7,"id":52237617,"name":"2 - 5 / 5 - 2"},{"status":"ACTIVE","sortPriority":8,"id":52671561,"name":"2 - 7 / 7 - 2"},{"status":"ACTIVE","sortPriority":9,"id":52671550,"name":"2 - 8 / 8 - 2"},{"status":"ACTIVE","sortPriority":10,"id":52237624,"name":"4 - 5 / 5 - 4"},{"status":"ACTIVE","sortPriority":11,"id":52671563,"name":"4 - 7 / 7 - 4"},{"status":"ACTIVE","sortPriority":12,"id":52671555,"name":"4 - 8 / 8 - 4"},{"status":"ACTIVE","sortPriority":13,"id":52237627,"name":"5 - 7 / 7 - 5"},{"status":"ACTIVE","sortPriority":14,"id":52237628,"name":"5 - 8 / 8 - 5"},{"status":"ACTIVE","sortPriority":15,"id":52671565,"name":"7 - 8 / 8 - 7"}],"regulators":["MR_INT"],"venue":"Murray Bridge","countryCode":"AU","discountAllowed":true,"timezone":"Australia/Adelaide","openDate":"2024-06-02T08:21:00.000Z","version":5962801916,"name":"Quinella","eventName":"Murray Bridge (AUS) 2nd Jun"},"rc":[],"con":true,"img":false}]}
{"op":"mcm","clk":"11449099388","pt":1717303849619,"mc":[{"id":"1.229554928","rc":[{"atb":[[8.6,13.75],[6.6,43.55]],"id":52237628},{"atb":[[5.1,25.49],[4.1,78.68]],"id":52237627},{"atb":[[5.8,50.81],[7.6,15.83]],"id":52671563},{"atb":[[18,14.34],[26,4.18]],"id":52671565},{"atb":[[6.8,42.05],[8.8,13.4]],"id":52671561},{"atb":[[300,0.35],[200,1.22]],"id":52671560},{"atb":[[9,30.48],[12.5,9.08]],"id":52671555},{"atb":[[2.14,213.95],[2.34,78]],"id":52237624},{"atb":[[16,6.96],[11,24.39]],"id":52237612},{"atb":[[9.6,28.36],[14,8.04]],"id":52671550},{"atb":[[550,0.44],[650,0.16]],"id":52671546},{"atb":[[2.64,63.73],[2.44,169.37]],"id":52237617},{"atb":[[3.45,42.66],[2.98,123.18]],"id":52671548},{"atb":[[17,15.24],[24,4.54]],"id":52671542},{"atb":[[20,5.5],[15,17.42]],"id":52671544}],"con":true,"img":false}]}
{"op":"mcm","clk":"11449301261","pt":1717306860499,"mc":[{"id":"1.229554928","rc":[{"atb":[[9.2,12.76],[10.5,8.26],[13,4.36],[15.5,1.81]],"id":52237628},{"atb":[[8,7.48],[9,3.27],[6,20.93],[7,13.08]],"id":52237627},{"atb":[[17.5,1.59],[10,11.63],[12.5,6.82],[15,3.74]],"id":52671563},{"atb":[[80,0.66],[42,2.55],[110,0.24],[55,1.45]],"id":52671565},{"atb":[[16,3.49],[18.5,1.5],[11,10.46],[13.5,6.28]],"id":52671561},{"atb":[[150,0.53],[200,1.49],[100,1.06],[250,0.1]],"id":52671560},{"atb":[[17.5,6.34],[20,4.13],[25,2.18],[30,0.9]],"id":52671555},{"atb":[[2.58,49.67],[2.78,14.7],[2.68,31.14],[2.48,70.7]],"id":52237624},{"atb":[[36,0.75],[19,5.81],[23,3.57],[28,1.94]],"id":52237612},{"atb":[[32,0.84],[18,6.15],[21,3.92],[26,2.09]],"id":52671550},{"atb":[[280,0.38],[330,0.24],[380,0.14],[430,0.06]],"id":52671546},{"atb":[[2.86,28.13],[2.66,63.03],[2.96,13.35],[2.76,44.59]],"id":52237617},{"atb":[[4,34.88],[4.5,22.42],[5,13.08],[5.5,5.81]],"id":52671548},{"atb":[[75,0.36],[40,2.01],[50,1.07],[30,3.61]],"id":52671542},{"atb":[[70,0.38],[38,2.12],[48,1.11],[29,3.74]],"id":52671544}],"con":true,"img":false}]}
{"op":"mcm","clk":"11449369369","pt":1717308079925,"mc":[{"id":"1.229554928","rc":[{"atb":[[9.2,0],[10.5,0],[13,0],[15.5,0]],"id":52237628},{"atb":[[8,0],[9,0],[6,0],[7,0]],"id":52237627},{"atb":[[36,0],[19,0],[23,0],[28,0]],"id":52237612}],"con":true,"img":false}]}
{"op":"mcm","clk":"11449369411","pt":1717308080599,"mc":[{"id":"1.229554928","rc":[{"atb":[[6.8,13.53],[8.8,3.35],[7.8,7.7],[5.9,21.36]],"id":52237627}],"con":true,"img":false}]}
{"op":"mcm","clk":"11449369417","pt":1717308080699,"mc":[{"id":"1.229554928","rc":[{"atb":[[9,13.08],[10,8.72],[12.5,4.55],[15,1.87]],"id":52237628},{"atb":[[34,0.8],[18.5,5.98],[22,3.74],[27,2.01]],"id":52237612}],"con":true,"img":false}]}
{"op":"mcm","clk":"11449438770","pt":1717309149763,"mc":[{"id":"1.229554928","rc":[{"atb":[[2.58,0],[2.78,0],[2.68,0],[2.48,0]],"id":52237624},{"atb":[[2.86,0],[2.66,0],[2.96,0],[2.76,0]],"id":52237617},{"atb":[[4,0],[4.5,0],[5,0],[5.5,0]],"id":52671548}],"con":true,"img":false}]}
{"op":"mcm","clk":"11449438810","pt":1717309150433,"mc":[{"id":"1.229554928","rc":[{"atb":[[2.82,14.37],[2.72,30.42],[2.52,68.84],[2.62,48.44]],"id":52237624},{"atb":[[2.88,27.83],[2.98,13.21],[2.78,44.09],[2.68,62.28]],"id":52237617},{"atb":[[4,34.88],[4.5,22.42],[5,13.08],[5.5,5.81]],"id":52671548}],"con":true,"img":false}]}
{"op":"mcm","clk":"11449477330","pt":1717309717162,"mc":[{"id":"1.229554928","rc":[{"atb":[[2.82,0],[2.72,0],[2.52,0],[2.62,0]],"id":52237624},{"atb":[[2.88,0],[2.98,0],[2.78,0],[2.68,0]],"id":52237617}],"con":true,"img":false}]}
{"op":"mcm","clk":"11449477370","pt":1717309717829,"mc":[{"id":"1.229554928","rc":[{"atb":[[2.58,49.67],[2.78,14.7],[2.68,31.14],[2.48,70.7]],"id":52237624},{"atb":[[2.86,28.13],[2.66,63.03],[2.96,13.35],[2.76,44.59]],"id":52237617}],"con":true,"img":false}]}
{"op":"mcm","clk":"11449487755","pt":1717309764482,"mc":[{"id":"1.229554928","rc":[{"atb":[[9,0],[10,0],[12.5,0],[15,0]],"id":52237628},{"atb":[[34,0],[18.5,0],[22,0],[27,0]],"id":52237612}],"con":true,"img":false}]}
{"op":"mcm","clk":"11449487797","pt":1717309765201,"mc":[{"id":"1.229554928","rc":[{"atb":[[9.2,12.76],[10.5,8.26],[13,4.36],[15.5,1.81]],"id":52237628},{"atb":[[36,0.75],[19,5.81],[23,3.57],[28,1.94]],"id":52237612}],"con":true,"img":false}]}
{"op":"mcm","clk":"11449546209","pt":1717310727222,"mc":[{"id":"1.229554928","rc":[{"atb":[[4,0],[4.5,0],[5,0],[5.5,0]],"id":52671548}],"con":true,"img":false}]}
{"op":"mcm","clk":"11449546254","pt":1717310727987,"mc":[{"id":"1.229554928","rc":[{"atb":[[4.6,21.8],[4.1,33.76]],"id":52671548}],"con":true,"img":false}]}
{"op":"mcm","clk":"11449546260","pt":1717310728088,"mc":[{"id":"1.229554928","rc":[{"atb":[[5.6,5.69]],"id":52671548}],"con":true,"img":false}]}
{"op":"mcm","clk":"11449546277","pt":1717310728400,"mc":[{"id":"1.229554928","rc":[{"atb":[[5.1,12.76]],"id":52671548}],"con":true,"img":false}]}
{"op":"mcm","clk":"11449574430","pt":1717311237755,"mc":[{"id":"1.229554928","rc":[{"atb":[[2.58,0],[2.68,0]],"id":52237624},{"atb":[[2.86,0],[2.66,0],[2.96,0],[2.76,0]],"id":52237617}],"con":true,"img":false}]}
{"op":"mcm","clk":"11449574438","pt":1717311237860,"mc":[{"id":"1.229554928","rc":[{"atb":[[2.78,0],[2.48,0]],"id":52237624}],"con":true,"img":false}]}
{"op":"mcm","clk":"11449574470","pt":1717311238471,"mc":[{"id":"1.229554928","rc":[{"atb":[[2.72,30.42],[2.62,48.44]],"id":52237624},{"atb":[[2.88,27.83],[2.98,13.21],[2.78,44.09],[2.68,62.28]],"id":52237617}],"con":true,"img":false}]}
{"op":"mcm","clk":"11449574478","pt":1717311238573,"mc":[{"id":"1.229554928","rc":[{"atb":[[2.82,14.37],[2.52,68.84]],"id":52237624}],"con":true,"img":false}]}
{"op":"mcm","clk":"11449600167","pt":1717311693782,"mc":[{"id":"1.229554928","rc":[{"atb":[[9.2,0],[10.5,0],[13,0],[15.5,0]],"id":52237628},{"atb":[[36,0],[19,0],[23,0],[28,0]],"id":52237612},{"atb":[[4.6,0],[4.1,0]],"id":52671548}],"con":true,"img":false}]}
{"op":"mcm","clk":"11449600207","pt":1717311694501,"mc":[{"id":"1.229554928","rc":[{"atb":[[34,0.8],[18.5,5.98],[22,3.74],[27,2.01]],"id":52237612},{"atb":[[4.2,32.7],[4.7,21.21]],"id":52671548}],"con":true,"img":false}]}
{"op":"mcm","clk":"11449600213","pt":1717311694605,"mc":[{"id":"1.229554928","rc":[{"atb":[[9,13.08],[10,8.72],[12.5,4.55],[15,1.87]],"id":52237628}],"con":true,"img":false}]}
{"op":"mcm","clk":"11449610222","pt":1717311879674,"mc":[{"id":"1.229554928","rc":[{"atb":[[16,0],[18.5,0],[11,0],[13.5,0]],"id":52671561},{"atb":[[2.82,0],[2.72,0],[2.52,0],[2.62,0]],"id":52237624},{"atb":[[34,0],[18.5,0],[22,0],[27,0]],"id":52237612}],"con":true,"img":false}]}
{"op":"mcm","clk":"11449610254","pt":1717311880341,"mc":[{"id":"1.229554928","rc":[{"atb":[[16.5,3.37],[19,1.45],[11.5,9.97],[14,6.04]],"id":52671561},{"atb":[[36,0.75],[19,5.81],[23,3.57],[28,1.94]],"id":52237612}],"con":true,"img":false}]}
{"op":"mcm","clk":"11449610260","pt":1717311880444,"mc":[{"id":"1.229554928","rc":[{"atb":[[2.58,49.67],[2.78,14.7],[2.68,31.14],[2.48,70.7]],"id":52237624}],"con":true,"img":false}]}
{"op":"mcm","clk":"11449623590","pt":1717312146983,"mc":[{"id":"1.229554928","rc":[{"atb":[[5.6,0]],"id":52671548}],"con":true,"img":false}]}
{"op":"mcm","clk":"11449623603","pt":1717312147287,"mc":[{"id":"1.229554928","rc":[{"atb":[[5.1,0]],"id":52671548}],"con":true,"img":false}]}
{"op":"mcm","clk":"11449623613","pt":1717312147696,"mc":[{"id":"1.229554928","rc":[{"atb":[[5.7,5.57]],"id":52671548}],"con":true,"img":false}]}
{"op":"mcm","clk":"11449623616","pt":1717312148004,"mc":[{"id":"1.229554928","rc":[{"atb":[[5.2,12.46]],"id":52671548}],"con":true,"img":false}]}
{"op":"mcm","clk":"11449623951","pt":1717312158403,"mc":[{"id":"1.229554928","rc":[{"atb":[[2.78,0]],"id":52237624},{"atb":[[36,0],[19,0],[23,0],[28,0]],"id":52237612}],"con":true,"img":false}]}
{"op":"mcm","clk":"11449623978","pt":1717312159119,"mc":[{"id":"1.229554928","rc":[{"atb":[[2.82,14.37]],"id":52237624},{"atb":[[34,0.8],[18.5,5.98],[22,3.74],[27,2.01]],"id":52237612}],"con":true,"img":false}]}
{"op":"mcm","clk":"11449624746","pt":1717312180212,"mc":[{"id":"1.229554928","rc":[{"atb":[[2.82,0]],"id":52237624}],"con":true,"img":false}]}
{"op":"mcm","clk":"11449624782","pt":1717312180929,"mc":[{"id":"1.229554928","rc":[{"atb":[[2.78,14.7]],"id":52237624}],"con":true,"img":false}]}
{"op":"mcm","clk":"11449627906","pt":1717312255147,"mc":[{"id":"1.229554928","rc":[{"atb":[[2.88,0],[2.98,0],[2.78,0],[2.68,0]],"id":52237617}],"con":true,"img":false}]}
{"op":"mcm","clk":"11449627944","pt":1717312256070,"mc":[{"id":"1.229554928","rc":[{"atb":[[2.86,28.13],[2.66,63.03],[2.96,13.35],[2.76,44.59]],"id":52237617}],"con":true,"img":false}]}
{"op":"mcm","clk":"11449628008","pt":1717312257876,"mc":[{"id":"1.229554928","rc":[{"atb":[[16.5,0],[19,0],[11.5,0],[14,0]],"id":52671561},{"atb":[[2.58,0],[2.78,0],[2.68,0],[2.48,0]],"id":52237624}],"con":true,"img":false}]}
{"op":"mcm","clk":"11449628044","pt":1717312258548,"mc":[{"id":"1.229554928","rc":[{"atb":[[16,3.49],[18.5,1.5],[11,10.46],[13.5,6.28]],"id":52671561},{"atb":[[2.38,56.87],[2.28,81.75],[2.58,16.56],[2.48,35.35]],"id":52237624}],"con":true,"img":false}]}
{"op":"mcm","clk":"11449628167","pt":1717312261769,"mc":[{"id":"1.229554928","rc":[{"atb":[[2.86,0],[2.66,0],[2.96,0],[2.76,0]],"id":52237617}],"con":true,"img":false}]}
{"op":"mcm","clk":"11449628207","pt":1717312262439,"mc":[{"id":"1.229554928","rc":[{"atb":[[2.56,33.54],[2.36,76.94],[2.46,53.75],[2.66,15.76]],"id":52237617}],"con":true,"img":false}]}
{"op":"mcm","clk":"11449628483","pt":1717312271866,"mc":[{"id":"1.229554928","rc":[{"atb":[[150,0],[200,1.22],[100,0],[250,0]],"id":52671560}],"con":true,"img":false}]}
{"op":"mcm","clk":"11449628759","pt":1717312278298,"mc":[{"id":"1.229554928","rc":[{"atb":[[140,0.57],[190,0.28],[95,1.11],[240,0.11]],"id":52671560}],"con":true,"img":false}]}
{"op":"mcm","clk":"11449634996","pt":1717312440500,"mc":[{"id":"1.229554928","rc":[{"atb":[[17.5,0],[10,0],[12.5,0],[15,0]],"id":52671563}],"con":true,"img":false}]}
{"op":"mcm","clk":"11449635031","pt":1717312441170,"mc":[{"id":"1.229554928","rc":[{"atb":[[17,1.64],[12,7.14],[9.8,11.89],[14.5,3.88]],"id":52671563}],"con":true,"img":false}]}
{"op":"mcm","clk":"11449635660","pt":1717312459113,"mc":[{"id":"1.229554928","rc":[{"atb":[[17,0],[12,0],[9.8,0],[14.5,0]],"id":52671563}],"con":true,"img":false}]}
{"op":"mcm","clk":"11449635693","pt":1717312459828,"mc":[{"id":"1.229554928","rc":[{"atb":[[17.5,1.59],[10,11.63],[12.5,6.82],[15,3.74]],"id":52671563}],"con":true,"img":false}]}
{"op":"mcm","clk":"11449636076","pt":1717312469738,"mc":[{"id":"1.229554928","rc":[{"atb":[[17.5,0],[10,0],[12.5,0],[15,0]],"id":52671563}],"con":true,"img":false}]}
{"op":"mcm","clk":"11449636111","pt":1717312470411,"mc":[{"id":"1.229554928","rc":[{"atb":[[17,1.64],[12,7.14],[9.8,11.89],[14.5,3.88]],"id":52671563}],"con":true,"img":false}]}
{"op":"mcm","clk":"11449658409","pt":1717313016896,"mc":[{"id":"1.229554928","rc":[{"atb":[[9,0],[10,0],[12.5,0],[15,0]],"id":52237628}],"con":true,"img":false}]}
{"op":"mcm","clk":"11449658445","pt":1717313017622,"mc":[{"id":"1.229554928","rc":[{"atb":[[9.2,12.76],[10.5,8.26],[13,4.36],[15.5,1.81]],"id":52237628}],"con":true,"img":false}]}
{"op":"mcm","clk":"11449661060","pt":1717313081861,"mc":[{"id":"1.229554928","rc":[{"atb":[[2.38,0],[2.28,0],[2.58,0],[2.48,0]],"id":52237624}],"con":true,"img":false}]}
{"op":"mcm","clk":"11449661093","pt":1717313082579,"mc":[{"id":"1.229554928","rc":[{"atb":[[2.56,16.77],[2.36,57.7],[2.46,35.83],[2.26,83.04]],"id":52237624}],"con":true,"img":false}]}
{"op":"mcm","clk":"11449662076","pt":1717313103716,"mc":[{"id":"1.229554928","rc":[{"atb":[[2.56,0],[2.36,0],[2.46,0],[2.66,0]],"id":52237617}],"con":true,"img":false}]}
{"op":"mcm","clk":"11449662132","pt":1717313104499,"mc":[{"id":"1.229554928","rc":[{"atb":[[2.54,33.98],[2.64,79.69],[2.44,223.88],[2.34,78.08]],"id":52237617}],"con":true,"img":false}]}
{"op":"mcm","clk":"11449663876","pt":1717313137929,"mc":[{"id":"1.229554928","rc":[{"atb":[[17,0],[12,0],[9.8,0],[14.5,0]],"id":52671563}],"con":true,"img":false}]}
{"op":"mcm","clk":"11449663906","pt":1717313138646,"mc":[{"id":"1.229554928","rc":[{"atb":[[17.5,1.59],[10,11.63],[12.5,6.82],[15,3.74]],"id":52671563}],"con":true,"img":false}]}
{"op":"mcm","clk":"11449674672","pt":1717313357869,"mc":[{"id":"1.229554928","rc":[{"atb":[[17.5,0],[10,0],[12.5,0],[15,0]],"id":52671563}],"con":true,"img":false}]}
{"op":"mcm","clk":"11449674711","pt":1717313358588,"mc":[{"id":"1.229554928","rc":[{"atb":[[17,1.64],[12,7.14],[9.8,11.89],[14.5,3.88]],"id":52671563}],"con":true,"img":false}]}
{"op":"mcm","clk":"11449679679","pt":1717313434890,"mc":[{"id":"1.229554928","rc":[{"atb":[[18.5,0]],"id":52237612}],"con":true,"img":false}]}
{"op":"mcm","clk":"11449679705","pt":1717313435007,"mc":[{"id":"1.229554928","rc":[{"atb":[[34,0],[22,0],[27,0]],"id":52237612}],"con":true,"img":false}]}
{"op":"mcm","clk":"11449679733","pt":1717313435606,"mc":[{"id":"1.229554928","rc":[{"atb":[[19,5.81]],"id":52237612}],"con":true,"img":false}]}
{"op":"mcm","clk":"11449679741","pt":1717313435709,"mc":[{"id":"1.229554928","rc":[{"atb":[[36,0.75]],"id":52237612}],"con":true,"img":false}]}
{"op":"mcm","clk":"11449679749","pt":1717313435764,"mc":[{"id":"1.229554928","rc":[{"atb":[[23,3.57],[28,1.94]],"id":52237612}],"con":true,"img":false}]}
{"op":"mcm","clk":"11449684877","pt":1717313500703,"mc":[{"id":"1.229554928","rc":[{"atb":[[9.2,0],[10.5,0],[13,0],[15.5,0]],"id":52237628}],"con":true,"img":false}]}
{"op":"mcm","clk":"11449684932","pt":1717313501422,"mc":[{"id":"1.229554928","rc":[{"atb":[[9,13.08],[10,8.72],[12.5,4.55],[15,1.87]],"id":52237628}],"con":true,"img":false}]}
{"op":"mcm","clk":"11449699822","pt":1717313682073,"mc":[{"id":"1.229554928","rc":[{"atb":[[16,0],[18.5,0],[11,0],[13.5,0]],"id":52671561}],"con":true,"img":false}]}
{"op":"mcm","clk":"11449699922","pt":1717313683160,"mc":[{"id":"1.229554928","rc":[{"atb":[[16.5,3.37],[19,1.45],[11.5,9.97],[14,6.04]],"id":52671561}],"con":true,"img":false}]}
{"op":"mcm","clk":"11449724024","pt":1717313963328,"mc":[{"id":"1.229554928","rc":[{"atb":[[16.5,0],[19,0],[11.5,0],[14,0]],"id":52671561}],"con":true,"img":false}]}
{"op":"mcm","clk":"11449724098","pt":1717313964049,"mc":[{"id":"1.229554928","rc":[{"atb":[[16,3.49],[18.5,1.5],[11,10.46],[13.5,6.28]],"id":52671561}],"con":true,"img":false}]}
{"op":"mcm","clk":"11449741850","pt":1717314153752,"mc":[{"id":"1.229554928","rc":[{"atb":[[8.6,0],[6.6,0]],"id":52237628},{"atb":[[5.1,0],[4.1,0]],"id":52237627},{"atb":[[5.8,0],[7.6,0]],"id":52671563},{"atb":[[18,0],[26,0]],"id":52671565},{"atb":[[6.8,0],[8.8,0]],"id":52671561},{"atb":[[300,0],[200,0]],"id":52671560},{"atb":[[9,0],[12.5,0]],"id":52671555},{"atb":[[2.14,0],[2.34,0]],"id":52237624},{"atb":[[16,0],[11,0]],"id":52237612},{"atb":[[9.6,0],[14,0]],"id":52671550},{"atb":[[550,0],[650,0]],"id":52671546},{"atb":[[2.64,15.95],[2.44,54.5]],"id":52237617},{"atb":[[3.45,0],[2.98,0]],"id":52671548},{"atb":[[17,0],[24,0]],"id":52671542},{"atb":[[20,0],[15,0]],"id":52671544}],"con":true,"img":false}]}
{"op":"mcm","clk":"11449743681","pt":1717314174823,"mc":[{"id":"1.229554928","rc":[{"atb":[[8.6,13.75],[6.6,43.55]],"id":52237628},{"atb":[[5.1,25.49],[4.1,78.68]],"id":52237627},{"atb":[[5.8,50.81],[7.6,15.83]],"id":52671563},{"atb":[[18,14.34],[26,4.18]],"id":52671565},{"atb":[[6.8,42.05],[8.8,13.4]],"id":52671561},{"atb":[[300,0.35],[200,1.22]],"id":52671560},{"atb":[[9,30.48],[12.5,9.08]],"id":52671555},{"atb":[[2.14,213.95],[2.34,78]],"id":52237624},{"atb":[[16,6.96],[11,24.39]],"id":52237612},{"atb":[[9.6,28.36],[14,8.04]],"id":52671550},{"atb":[[550,0.44],[650,0.16]],"id":52671546},{"atb":[[2.64,79.69],[2.44,223.88]],"id":52237617},{"atb":[[3.45,42.66],[2.98,123.18]],"id":52671548},{"atb":[[17,15.24],[24,4.54]],"id":52671542},{"atb":[[20,5.5],[15,17.42]],"id":52671544}],"con":true,"img":false}]}
{"op":"mcm","clk":"11449753549","pt":1717314282973,"mc":[{"id":"1.229554928","rc":[{"atb":[[2.56,0],[2.36,0],[2.46,0],[2.26,0]],"id":52237624}],"con":true,"img":false}]}
{"op":"mcm","clk":"11449753616","pt":1717314283663,"mc":[{"id":"1.229554928","rc":[{"atb":[[2.56,16.77],[2.36,57.7],[2.46,35.83],[2.26,83.04]],"id":52237624}],"con":true,"img":false}]}
{"op":"mcm","clk":"11449756815","pt":1717314321371,"mc":[{"id":"1.229554928","rc":[{"atb":[[8.6,0],[6.6,0]],"id":52237628},{"atb":[[5.1,0],[4.1,0]],"id":52237627},{"atb":[[5.8,0],[7.6,0]],"id":52671563},{"atb":[[18,0],[26,0]],"id":52671565},{"atb":[[6.8,0],[8.8,0]],"id":52671561},{"atb":[[300,0],[200,0]],"id":52671560},{"atb":[[9,0],[12.5,0]],"id":52671555},{"atb":[[2.14,0],[2.34,0]],"id":52237624},{"atb":[[16,0],[11,0]],"id":52237612},{"atb":[[9.6,0],[14,0]],"id":52671550},{"atb":[[550,0],[650,0]],"id":52671546},{"atb":[[2.64,15.95],[2.44,54.5]],"id":52237617},{"atb":[[3.45,0],[2.98,0]],"id":52671548},{"atb":[[17,0],[24,0]],"id":52671542},{"atb":[[20,0],[15,0]],"id":52671544}],"con":true,"img":false}]}
{"op":"mcm","clk":"11449757855","pt":1717314333634,"mc":[{"id":"1.229554928","rc":[{"atb":[[300,0.35],[200,1.22]],"id":52671560},{"atb":[[16,6.96],[11,24.39]],"id":52237612},{"atb":[[550,0.44],[650,0.16]],"id":52671546},{"atb":[[2.64,79.69],[2.44,223.88]],"id":52237617},{"atb":[[3.45,42.66],[2.98,123.18]],"id":52671548},{"atb":[[17,15.24],[24,4.54]],"id":52671542},{"atb":[[20,5.5],[15,17.42]],"id":52671544}],"con":true,"img":false}]}
{"op":"mcm","clk":"11449757869","pt":1717314333743,"mc":[{"id":"1.229554928","rc":[{"atb":[[8.6,13.75],[6.6,43.55]],"id":52237628},{"atb":[[5.1,25.49],[4.1,78.68]],"id":52237627},{"atb":[[5.8,50.81],[7.6,15.83]],"id":52671563},{"atb":[[18,14.34],[26,4.18]],"id":52671565},{"atb":[[6.8,42.05],[8.8,13.4]],"id":52671561},{"atb":[[9,30.48],[12.5,9.08]],"id":52671555},{"atb":[[2.14,213.95],[2.34,78]],"id":52237624},{"atb":[[9.6,28.36],[14,8.04]],"id":52671550}],"con":true,"img":false}]}
{"op":"mcm","clk":"11449759702","pt":1717314355492,"mc":[{"id":"1.229554928","rc":[{"atb":[[8.6,0],[6.6,0]],"id":52237628},{"atb":[[5.1,0],[4.1,0]],"id":52237627},{"atb":[[5.8,0],[7.6,0]],"id":52671563},{"atb":[[18,0],[26,0]],"id":52671565},{"atb":[[6.8,0],[8.8,0]],"id":52671561},{"atb":[[300,0],[200,0]],"id":52671560},{"atb":[[9,0],[12.5,0]],"id":52671555},{"atb":[[2.14,0],[2.34,0]],"id":52237624},{"atb":[[16,0],[11,0]],"id":52237612},{"atb":[[9.6,0],[14,0]],"id":52671550},{"atb":[[550,0],[650,0]],"id":52671546},{"atb":[[2.64,15.95],[2.44,54.5]],"id":52237617},{"atb":[[3.45,0],[2.98,0]],"id":52671548},{"atb":[[17,0],[24,0]],"id":52671542},{"atb":[[20,0],[15,0]],"id":52671544}],"con":true,"img":false}]}
{"op":"mcm","clk":"11449760268","pt":1717314362080,"mc":[{"id":"1.229554928","rc":[{"atb":[[8.6,13.75],[6.6,43.55]],"id":52237628},{"atb":[[5.1,25.49],[4.1,78.68]],"id":52237627},{"atb":[[5.8,50.81],[7.6,15.83]],"id":52671563},{"atb":[[18,14.34],[26,4.18]],"id":52671565},{"atb":[[6.8,42.05],[8.8,13.4]],"id":52671561},{"atb":[[300,0.35],[200,1.22]],"id":52671560},{"atb":[[9,30.48],[12.5,9.08]],"id":52671555},{"atb":[[2.14,213.95],[2.34,78]],"id":52237624},{"atb":[[16,6.96],[11,24.39]],"id":52237612},{"atb":[[9.6,28.36],[14,8.04]],"id":52671550},{"atb":[[550,0.44],[650,0.16]],"id":52671546},{"atb":[[2.64,79.69],[2.44,223.88]],"id":52237617},{"atb":[[3.45,42.66],[2.98,123.18]],"id":52671548},{"atb":[[17,15.24],[24,4.54]],"id":52671542},{"atb":[[20,5.5],[15,17.42]],"id":52671544}],"con":true,"img":false}]}
{"op":"mcm","clk":"11449760671","pt":1717314366670,"mc":[{"id":"1.229554928","rc":[{"atb":[[19,0]],"id":52237612}],"con":true,"img":false}]}
{"op":"mcm","clk":"11449760681","pt":1717314366777,"mc":[{"id":"1.229554928","rc":[{"atb":[[32,0],[18,0],[21,0],[26,0]],"id":52671550},{"atb":[[280,0],[330,0],[380,0],[430,0]],"id":52671546},{"atb":[[75,0],[40,0],[50,0],[30,0]],"id":52671542},{"atb":[[70,0],[38,0],[48,0],[29,0]],"id":52671544}],"con":true,"img":false}]}
{"op":"mcm","clk":"11449760722","pt":1717314367405,"mc":[{"id":"1.229554928","rc":[{"atb":[[46,0.58]],"id":52237612}],"con":true,"img":false}]}
{"op":"mcm","clk":"11449760733","pt":1717314367504,"mc":[{"id":"1.229554928","rc":[{"atb":[[34,0.8],[18.5,5.98],[22,3.74],[27,2.01]],"id":52671550},{"atb":[[530,0.1],[580,0.05],[430,0.25],[480,0.16]],"id":52671546},{"atb":[[75,0.71],[40,2.68],[100,0.27],[50,1.6]],"id":52671542},{"atb":[[65,0.82],[36,2.99],[90,0.29],[46,1.74]],"id":52671544}],"con":true,"img":false}]}
{"op":"mcm","clk":"11449777459","pt":1717314550215,"mc":[{"id":"1.229554928","rc":[{"atb":[[80,0],[42,0],[110,0],[55,0]],"id":52671565},{"atb":[[16,0],[18.5,0],[11,0],[13.5,0]],"id":52671561},{"atb":[[17.5,0],[20,0],[25,0],[30,0]],"id":52671555},{"atb":[[34,0],[18.5,0],[22,0],[27,0]],"id":52671550},{"atb":[[530,0],[580,0],[430,0],[480,0]],"id":52671546}],"con":true,"img":false}]}
{"op":"mcm","clk":"11449777518","pt":1717314550893,"mc":[{"id":"1.229554928","rc":[{"atb":[[85,0.62],[44,2.43],[120,0.22],[60,1.33]],"id":52671565},{"atb":[[18,1.54],[10.5,11.01],[13,6.54],[15.5,3.61]],"id":52671561},{"atb":[[34,0.8],[18.5,5.98],[22,3.74],[27,2.01]],"id":52671555},{"atb":[[36,0.75],[19,5.81],[23,3.57],[28,1.94]],"id":52671550},{"atb":[[540,0.15],[590,0.09],[640,0.04],[490,0.21]],"id":52671546}],"con":true,"img":false}]}
{"op":"mcm","clk":"11449786987","pt":1717314665911,"mc":[{"id":"1.229554928","rc":[{"atb":[[85,0],[44,0],[120,0],[60,0]],"id":52671565}],"con":true,"img":false}]}
{"op":"mcm","clk":"11449787047","pt":1717314666632,"mc":[{"id":"1.229554928","rc":[{"atb":[[80,0.66],[42,2.55],[110,0.24],[55,1.45]],"id":52671565}],"con":true,"img":false}]}
{"op":"mcm","clk":"11449823489","pt":1717315077010,"mc":[{"id":"1.229554928","rc":[{"atb":[[2.56,0],[2.36,0],[2.46,0],[2.26,0]],"id":52237624}],"con":true,"img":false}]}
{"op":"mcm","clk":"11449823553","pt":1717315077693,"mc":[{"id":"1.229554928","rc":[{"atb":[[2.02,76.94],[2.22,21.44],[2.12,46.71],[1.96,108.99]],"id":52237624}],"con":true,"img":false}]}
{"op":"mcm","clk":"11449851305","pt":1717315296778,"mc":[{"id":"1.229554928","rc":[{"atb":[[8.6,0],[6.6,0]],"id":52237628},{"atb":[[5.1,0],[4.1,0]],"id":52237627},{"atb":[[5.8,0],[7.6,0]],"id":52671563},{"atb":[[18,0],[26,0]],"id":52671565},{"atb":[[6.8,0],[8.8,0]],"id":52671561},{"atb":[[300,0],[200,0]],"id":52671560},{"atb":[[9,0],[12.5,0]],"id":52671555},{"atb":[[2.14,0],[2.34,0]],"id":52237624},{"atb":[[16,0],[11,0]],"id":52237612},{"atb":[[9.6,0],[14,0]],"id":52671550},{"atb":[[550,0],[650,0]],"id":52671546},{"atb":[[2.64,15.95],[2.44,54.5]],"id":52237617},{"atb":[[3.45,0],[2.98,0]],"id":52671548},{"atb":[[17,0],[24,0]],"id":52671542},{"atb":[[20,0],[15,0]],"id":52671544}],"con":true,"img":false}]}
{"op":"mcm","clk":"11449855885","pt":1717315342157,"mc":[{"id":"1.229554928","rc":[{"atb":[[8.6,13.75],[6.6,43.55]],"id":52237628},{"atb":[[5.1,25.49],[4.1,78.68]],"id":52237627},{"atb":[[5.8,50.81],[7.6,15.83]],"id":52671563},{"atb":[[18,14.34],[26,4.18]],"id":52671565},{"atb":[[6.8,42.05],[8.8,13.4]],"id":52671561},{"atb":[[300,0.35],[200,1.22]],"id":52671560},{"atb":[[9,30.48],[12.5,9.08]],"id":52671555},{"atb":[[2.14,213.95],[2.34,78]],"id":52237624},{"atb":[[16,6.96],[11,24.39]],"id":52237612},{"atb":[[9.6,28.36],[14,8.04]],"id":52671550},{"atb":[[550,0.44],[650,0.16]],"id":52671546},{"atb":[[2.64,79.69],[2.44,223.88]],"id":52237617},{"atb":[[3.45,42.66],[2.98,123.18]],"id":52671548},{"atb":[[17,15.24],[24,4.54]],"id":52671542},{"atb":[[20,5.5],[15,17.42]],"id":52671544}],"con":true,"img":false}]}
{"op":"mcm","clk":"11449893743","pt":1717315713497,"mc":[{"id":"1.229554928","rc":[{"atb":[[8.6,0],[6.6,0]],"id":52237628},{"atb":[[5.1,0],[4.1,0]],"id":52237627},{"atb":[[5.8,0],[7.6,0]],"id":52671563},{"atb":[[18,0],[26,0]],"id":52671565},{"atb":[[6.8,0],[8.8,0]],"id":52671561},{"atb":[[300,0],[200,0]],"id":52671560},{"atb":[[9,0],[12.5,0]],"id":52671555},{"atb":[[2.14,0],[2.34,0]],"id":52237624},{"atb":[[16,0],[11,0]],"id":52237612},{"atb":[[9.6,0],[14,0]],"id":52671550},{"atb":[[550,0],[650,0]],"id":52671546},{"atb":[[2.64,15.95],[2.44,54.5]],"id":52237617},{"atb":[[3.45,0],[2.98,0]],"id":52671548},{"atb":[[17,0],[24,0]],"id":52671542},{"atb":[[20,0],[15,0]],"id":52671544}],"con":true,"img":false}]}
{"op":"mcm","clk":"11449899234","pt":1717315764715,"mc":[{"id":"1.229554928","rc":[{"atb":[[8.6,13.75],[6.6,43.55]],"id":52237628},{"atb":[[5.1,25.49],[4.1,78.68]],"id":52237627},{"atb":[[5.8,50.81],[7.6,15.83]],"id":52671563},{"atb":[[18,14.34],[26,4.18]],"id":52671565},{"atb":[[6.8,42.05],[8.8,13.4]],"id":52671561},{"atb":[[300,0.35],[200,1.22]],"id":52671560},{"atb":[[9,30.48],[12.5,9.08]],"id":52671555},{"atb":[[2.14,213.95],[2.34,78]],"id":52237624},{"atb":[[16,6.96],[11,24.39]],"id":52237612},{"atb":[[9.6,28.36],[14,8.04]],"id":52671550},{"atb":[[550,0.44],[650,0.16]],"id":52671546},{"atb":[[2.64,79.69],[2.44,223.88]],"id":52237617},{"atb":[[3.45,42.66],[2.98,123.18]],"id":52671548},{"atb":[[17,15.24],[24,4.54]],"id":52671542},{"atb":[[20,5.5],[15,17.42]],"id":52671544}],"con":true,"img":false}]}
{"op":"mcm","clk":"11449959215","pt":1717316398585,"mc":[{"id":"1.229554928","rc":[{"atb":[[8.6,0],[6.6,0]],"id":52237628},{"atb":[[5.1,0],[4.1,0]],"id":52237627},{"atb":[[5.8,0],[7.6,0]],"id":52671563},{"atb":[[18,0],[26,0]],"id":52671565},{"atb":[[6.8,0],[8.8,0]],"id":52671561},{"atb":[[300,0],[200,0]],"id":52671560},{"atb":[[9,0],[12.5,0]],"id":52671555},{"atb":[[2.14,0],[2.34,0]],"id":52237624},{"atb":[[16,0],[11,0]],"id":52237612},{"atb":[[9.6,0],[14,0]],"id":52671550},{"atb":[[550,0],[650,0]],"id":52671546},{"atb":[[2.64,15.95],[2.44,54.5]],"id":52237617},{"atb":[[3.45,0],[2.98,0]],"id":52671548},{"atb":[[17,0],[24,0]],"id":52671542},{"atb":[[20,0],[15,0]],"id":52671544}],"con":true,"img":false}]}
{"op":"mcm","clk":"11449961540","pt":1717316425941,"mc":[{"id":"1.229554928","rc":[{"atb":[[8.6,13.75],[6.6,43.55]],"id":52237628},{"atb":[[5.1,25.49],[4.1,78.68]],"id":52237627},{"atb":[[5.8,50.81],[7.6,15.83]],"id":52671563},{"atb":[[18,14.34],[26,4.18]],"id":52671565},{"atb":[[6.8,42.05],[8.8,13.4]],"id":52671561},{"atb":[[300,0.35],[200,1.22]],"id":52671560},{"atb":[[9,30.48],[12.5,9.08]],"id":52671555},{"atb":[[2.14,213.95],[2.34,78]],"id":52237624},{"atb":[[16,6.96],[11,24.39]],"id":52237612},{"atb":[[9.6,28.36],[14,8.04]],"id":52671550},{"atb":[[550,0.44],[650,0.16]],"id":52671546},{"atb":[[2.64,79.69],[2.44,223.88]],"id":52237617},{"atb":[[3.45,42.66],[2.98,123.18]],"id":52671548},{"atb":[[17,15.24],[24,4.54]],"id":52671542},{"atb":[[20,5.5],[15,17.42]],"id":52671544}],"con":true,"img":false}]}
{"op":"mcm","clk":"11450057442","pt":1717317526728,"mc":[{"id":"1.229554928","rc":[{"atb":[[8.6,0],[6.6,0]],"id":52237628},{"atb":[[5.1,0],[4.1,0]],"id":52237627},{"atb":[[5.8,0],[7.6,0]],"id":52671563},{"atb":[[18,0],[26,0]],"id":52671565},{"atb":[[6.8,0],[8.8,0]],"id":52671561},{"atb":[[300,0],[200,0]],"id":52671560},{"atb":[[9,0],[12.5,0]],"id":52671555},{"atb":[[2.14,0],[2.34,0]],"id":52237624},{"atb":[[16,0],[11,0]],"id":52237612},{"atb":[[9.6,0],[14,0]],"id":52671550},{"atb":[[550,0],[650,0]],"id":52671546},{"atb":[[2.64,15.95],[2.44,54.5]],"id":52237617},{"atb":[[3.45,0],[2.98,0]],"id":52671548},{"atb":[[17,0],[24,0]],"id":52671542},{"atb":[[20,0],[15,0]],"id":52671544}],"con":true,"img":false}]}
{"op":"mcm","clk":"11450060558","pt":1717317561154,"mc":[{"id":"1.229554928","rc":[{"atb":[[8.6,13.75],[6.6,43.55]],"id":52237628},{"atb":[[5.1,25.49],[4.1,78.68]],"id":52237627},{"atb":[[5.8,50.81],[7.6,15.83]],"id":52671563},{"atb":[[18,14.34],[26,4.18]],"id":52671565},{"atb":[[6.8,42.05],[8.8,13.4]],"id":52671561},{"atb":[[300,0.35],[200,1.22]],"id":52671560},{"atb":[[9,30.48],[12.5,9.08]],"id":52671555},{"atb":[[2.14,213.95],[2.34,78]],"id":52237624},{"atb":[[16,6.96],[11,24.39]],"id":52237612},{"atb":[[9.6,28.36],[14,8.04]],"id":52671550},{"atb":[[550,0.44],[650,0.16]],"id":52671546},{"atb":[[2.64,79.69],[2.44,223.88]],"id":52237617},{"atb":[[3.45,42.66],[2.98,123.18]],"id":52671548},{"atb":[[17,15.24],[24,4.54]],"id":52671542},{"atb":[[20,5.5],[15,17.42]],"id":52671544}],"con":true,"img":false}]}
{"op":"mcm","clk":"11450067590","pt":1717317638860,"mc":[{"id":"1.229554928","rc":[{"atb":[[2.02,0],[2.22,0],[2.12,0],[1.96,0]],"id":52237624}],"con":true,"img":false}]}
{"op":"mcm","clk":"11450067660","pt":1717317639591,"mc":[{"id":"1.229554928","rc":[{"atb":[[1.99,105.69],[2.28,20.44],[2.18,44.34],[2.08,72.66]],"id":52237624}],"con":true,"img":false}]}
{"op":"mcm","clk":"11450105868","pt":1717318070743,"mc":[{"id":"1.229554928","rc":[{"atb":[[1.99,0],[2.28,0],[2.18,0],[2.08,0]],"id":52237624}],"con":true,"img":false}]}
{"op":"mcm","clk":"11450105934","pt":1717318071424,"mc":[{"id":"1.229554928","rc":[{"atb":[[2.06,74.03],[1.98,106.77],[2.26,20.76],[2.16,45.1]],"id":52237624}],"con":true,"img":false}]}
{"op":"mcm","clk":"11450117854","pt":1717318204474,"mc":[{"id":"1.229554928","rc":[{"atb":[[2.06,0],[1.98,0],[2.26,0],[2.16,0]],"id":52237624}],"con":true,"img":false}]}
{"op":"mcm","clk":"11450117929","pt":1717318205197,"mc":[{"id":"1.229554928","rc":[{"atb":[[2,78.48],[2.2,21.8],[1.95,110.14],[2.1,47.56]],"id":52237624}],"con":true,"img":false}]}
{"op":"mcm","clk":"11450133833","pt":1717318390220,"mc":[{"id":"1.229554928","rc":[{"atb":[[8.6,0],[6.6,0]],"id":52237628},{"atb":[[5.1,0],[4.1,0]],"id":52237627},{"atb":[[5.8,0],[7.6,0]],"id":52671563},{"atb":[[18,0],[26,0]],"id":52671565},{"atb":[[6.8,0],[8.8,0]],"id":52671561},{"atb":[[300,0],[200,0]],"id":52671560},{"atb":[[9,0],[12.5,0]],"id":52671555},{"atb":[[2.14,0],[2.34,0]],"id":52237624},{"atb":[[16,0],[11,0]],"id":52237612},{"atb":[[9.6,0],[14,0]],"id":52671550},{"atb":[[550,0],[650,0]],"id":52671546},{"atb":[[2.64,15.95],[2.44,54.5]],"id":52237617},{"atb":[[3.45,0],[2.98,0]],"id":52671548},{"atb":[[17,0],[24,0]],"id":52671542},{"atb":[[20,0],[15,0]],"id":52671544}],"con":true,"img":false}]}
{"op":"mcm","clk":"11450134730","pt":1717318401243,"mc":[{"id":"1.229554928","rc":[{"atb":[[300,0.35],[200,1.22]],"id":52671560},{"atb":[[16,6.96],[11,24.39]],"id":52237612},{"atb":[[550,0.44],[650,0.16]],"id":52671546},{"atb":[[2.64,79.69],[2.44,223.88]],"id":52237617},{"atb":[[3.45,42.66],[2.98,123.18]],"id":52671548},{"atb":[[17,15.24],[24,4.54]],"id":52671542},{"atb":[[20,5.5],[15,17.42]],"id":52671544}],"con":true,"img":false}]}
{"op":"mcm","clk":"11450134739","pt":1717318401349,"mc":[{"id":"1.229554928","rc":[{"atb":[[8.6,13.75],[6.6,43.55]],"id":52237628},{"atb":[[5.1,25.49],[4.1,78.68]],"id":52237627},{"atb":[[5.8,50.81],[7.6,15.83]],"id":52671563},{"atb":[[18,14.34],[26,4.18]],"id":52671565},{"atb":[[6.8,42.05],[8.8,13.4]],"id":52671561},{"atb":[[9,30.48],[12.5,9.08]],"id":52671555},{"atb":[[2.14,213.95],[2.34,78]],"id":52237624},{"atb":[[9.6,28.36],[14,8.04]],"id":52671550}],"con":true,"img":false}]}
{"op":"mcm","clk":"11450178843","pt":1717318876369,"mc":[{"id":"1.229554928","rc":[{"atb":[[2,0],[2.2,0],[1.95,0],[2.1,0]],"id":52237624}],"con":true,"img":false}]}
{"op":"mcm","clk":"11450178925","pt":1717318877048,"mc":[{"id":"1.229554928","rc":[{"atb":[[2.06,74.03],[1.98,106.77],[2.26,20.76],[2.16,45.1]],"id":52237624}],"con":true,"img":false}]}
{"op":"mcm","clk":"11450210817","pt":1717319206634,"mc":[{"id":"1.229554928","rc":[{"atb":[[540,0],[590,0],[640,0],[490,0]],"id":52671546}],"con":true,"img":false}]}
{"op":"mcm","clk":"11450210883","pt":1717319207310,"mc":[{"id":"1.229554928","rc":[{"atb":[[530,0.1],[580,0.05],[430,0.25],[480,0.16]],"id":52671546}],"con":true,"img":false}]}
{"op":"mcm","clk":"11450214766","pt":1717319245838,"mc":[{"id":"1.229554928","rc":[{"atb":[[8.6,0],[6.6,0]],"id":52237628},{"atb":[[5.1,0],[4.1,0]],"id":52237627},{"atb":[[5.8,0],[7.6,0]],"id":52671563},{"atb":[[18,0],[26,0]],"id":52671565},{"atb":[[6.8,0],[8.8,0]],"id":52671561},{"atb":[[300,0],[200,0]],"id":52671560},{"atb":[[9,0],[12.5,0]],"id":52671555},{"atb":[[2.14,0],[2.34,0]],"id":52237624},{"atb":[[16,0],[11,0]],"id":52237612},{"atb":[[9.6,0],[14,0]],"id":52671550},{"atb":[[550,0],[650,0]],"id":52671546},{"atb":[[2.64,15.95],[2.44,54.5]],"id":52237617},{"atb":[[3.45,0],[2.98,0]],"id":52671548},{"atb":[[17,0],[24,0]],"id":52671542},{"atb":[[20,0],[15,0]],"id":52671544}],"con":true,"img":false}]}
{"op":"mcm","clk":"11450214807","pt":1717319246254,"mc":[{"id":"1.229554928","rc":[{"atb":[[36,0],[19,0],[23,0],[28,0]],"id":52671550}],"con":true,"img":false}]}
{"op":"mcm","clk":"11450214900","pt":1717319246977,"mc":[{"id":"1.229554928","rc":[{"atb":[[34,0.8],[18.5,5.98],[22,3.74],[27,2.01]],"id":52671550}],"con":true,"img":false}]}
{"op":"mcm","clk":"11450218223","pt":1717319279103,"mc":[{"id":"1.229554928","rc":[{"atb":[[8.6,13.75],[6.6,43.55]],"id":52237628},{"atb":[[5.1,25.49],[4.1,78.68]],"id":52237627},{"atb":[[5.8,50.81],[7.6,15.83]],"id":52671563},{"atb":[[18,14.34],[26,4.18]],"id":52671565},{"atb":[[6.8,42.05],[8.8,13.4]],"id":52671561},{"atb":[[300,0.35],[200,1.22]],"id":52671560},{"atb":[[9,30.48],[12.5,9.08]],"id":52671555},{"atb":[[2.14,213.95],[2.34,78]],"id":52237624},{"atb":[[16,6.96],[11,24.39]],"id":52237612},{"atb":[[9.6,28.36],[14,8.04]],"id":52671550},{"atb":[[550,0.44],[650,0.16]],"id":52671546},{"atb":[[2.64,79.69],[2.44,223.88]],"id":52237617},{"atb":[[3.45,42.66],[2.98,123.18]],"id":52671548},{"atb":[[17,15.24],[24,4.54]],"id":52671542},{"atb":[[20,5.5],[15,17.42]],"id":52671544}],"con":true,"img":false}]}
{"op":"mcm","clk":"11450232196","pt":1717319430046,"mc":[{"id":"1.229554928","rc":[{"atb":[[75,0],[40,0],[100,0],[50,0]],"id":52671542}],"con":true,"img":false}]}
{"op":"mcm","clk":"11450232273","pt":1717319430763,"mc":[{"id":"1.229554928","rc":[{"atb":[[70,0.76],[38,2.83],[95,0.28],[48,1.67]],"id":52671542}],"con":true,"img":false}]}
{"op":"mcm","clk":"11450234741","pt":1717319455778,"mc":[{"id":"1.229554928","rc":[{"atb":[[6.8,0],[8.8,0],[7.8,0],[5.9,0]],"id":52237627},{"atb":[[2.06,0],[1.98,0],[2.26,0],[2.16,0]],"id":52237624}],"con":true,"img":false}]}
{"op":"mcm","clk":"11450234820","pt":1717319456601,"mc":[{"id":"1.229554928","rc":[{"atb":[[6.8,9.02],[7.8,3.85],[5.9,16.01],[5.4,23.78]],"id":52237627}],"con":true,"img":false}]}
{"op":"mcm","clk":"11450234896","pt":1717319457388,"mc":[{"id":"1.229554928","rc":[{"atb":[[6.8,0],[7.8,0],[5.9,0],[5.4,0]],"id":52237627}],"con":true,"img":false}]}
{"op":"mcm","clk":"11450234933","pt":1717319457806,"mc":[{"id":"1.229554928","rc":[{"atb":[[2.56,50.3],[2.46,71.67],[2.66,31.52],[2.76,14.86]],"id":52237624}],"con":true,"img":false}]}
{"op":"mcm","clk":"11450234980","pt":1717319458173,"mc":[{"id":"1.229554928","rc":[{"atb":[[5.6,17.06],[7.2,4.22],[5.1,51.02],[6.2,10.06]],"id":52237627}],"con":true,"img":false}]}
{"op":"mcm","clk":"11450235018","pt":1717319458587,"mc":[{"id":"1.229554928","rc":[{"atb":[[2.56,0],[2.46,0],[2.66,0],[2.76,0]],"id":52237624}],"con":true,"img":false}]}
{"op":"mcm","clk":"11450235085","pt":1717319459302,"mc":[{"id":"1.229554928","rc":[{"atb":[[2.58,49.67],[2.78,14.7],[2.68,31.14],[2.48,70.7]],"id":52237624}],"con":true,"img":false}]}
{"op":"mcm","clk":"11450263839","pt":1717319778238,"mc":[{"id":"1.229554928","rc":[{"atb":[[530,0],[580,0],[430,0]],"id":52671546}],"con":true,"img":false}]}
{"op":"mcm","clk":"11450263849","pt":1717319778343,"mc":[{"id":"1.229554928","rc":[{"atb":[[480,0]],"id":52671546}],"con":true,"img":false}]}
{"op":"mcm","clk":"11450263901","pt":1717319778959,"mc":[{"id":"1.229554928","rc":[{"atb":[[540,0.1],[590,0.04],[440,0.24]],"id":52671546}],"con":true,"img":false}]}
{"op":"mcm","clk":"11450263911","pt":1717319779064,"mc":[{"id":"1.229554928","rc":[{"atb":[[490,0.16]],"id":52671546}],"con":true,"img":false}]}
{"op":"mcm","clk":"11450279952","pt":1717319976351,"mc":[{"id":"1.229554928","rc":[{"atb":[[2.58,0],[2.78,0],[2.68,0],[2.48,0]],"id":52237624}],"con":true,"img":false}]}
{"op":"mcm","clk":"11450280028","pt":1717319977177,"mc":[{"id":"1.229554928","rc":[{"atb":[[2.56,50.3],[2.46,71.67],[2.66,31.52],[2.76,14.86]],"id":52237624}],"con":true,"img":false}]}
{"op":"mcm","clk":"11450280251","pt":1717319980268,"mc":[{"id":"1.229554928","rc":[{"atb":[[70,0],[38,0],[95,0],[48,0]],"id":52671542}],"con":true,"img":false}]}
{"op":"mcm","clk":"11450280299","pt":1717319980941,"mc":[{"id":"1.229554928","rc":[{"atb":[[75,0.71],[40,2.68],[100,0.27],[50,1.6]],"id":52671542}],"con":true,"img":false}]}
{"op":"mcm","clk":"11450286425","pt":1717320065083,"mc":[{"id":"1.229554928","rc":[{"atb":[[17,0],[12,0],[9.8,0],[14.5,0]],"id":52671563}],"con":true,"img":false}]}
{"op":"mcm","clk":"11450286469","pt":1717320065760,"mc":[{"id":"1.229554928","rc":[{"atb":[[16.5,1.69],[9.6,12.17],[11.5,7.48],[14,4.02]],"id":52671563}],"con":true,"img":false}]}
{"op":"mcm","clk":"11450286947","pt":1717320073091,"mc":[{"id":"1.229554928","rc":[{"atb":[[8.6,0],[6.6,0]],"id":52237628},{"atb":[[5.1,25.52],[4.1,0]],"id":52237627},{"atb":[[5.8,0],[7.6,0]],"id":52671563},{"atb":[[18,0],[26,0]],"id":52671565},{"atb":[[6.8,0],[8.8,0]],"id":52671561},{"atb":[[300,0],[200,0]],"id":52671560},{"atb":[[9,0],[12.5,0]],"id":52671555},{"atb":[[2.14,0],[2.34,0]],"id":52237624},{"atb":[[16,0],[11,0]],"id":52237612},{"atb":[[9.6,0],[14,0]],"id":52671550},{"atb":[[550,0],[650,0]],"id":52671546},{"atb":[[2.64,15.95],[2.44,54.5]],"id":52237617},{"atb":[[3.45,0],[2.98,0]],"id":52671548},{"atb":[[17,0],[24,0]],"id":52671542},{"atb":[[20,0],[15,0]],"id":52671544}],"con":true,"img":false}]}
{"op":"mcm","clk":"11450287958","pt":1717320087503,"mc":[{"id":"1.229554928","rc":[{"atb":[[8.6,13.75],[6.6,43.55]],"id":52237628},{"atb":[[5.1,51.02],[4.1,78.68]],"id":52237627},{"atb":[[5.8,50.81],[7.6,15.83]],"id":52671563},{"atb":[[18,14.34],[26,4.18]],"id":52671565},{"atb":[[6.8,42.05],[8.8,13.4]],"id":52671561},{"atb":[[300,0.35],[200,1.22]],"id":52671560},{"atb":[[9,30.48],[12.5,9.08]],"id":52671555},{"atb":[[2.14,213.95],[2.34,78]],"id":52237624},{"atb":[[16,6.96],[11,24.39]],"id":52237612},{"atb":[[9.6,28.36],[14,8.04]],"id":52671550},{"atb":[[550,0.44],[650,0.16]],"id":52671546},{"atb":[[2.64,79.69],[2.44,223.88]],"id":52237617},{"atb":[[3.45,42.66],[2.98,123.18]],"id":52671548},{"atb":[[17,15.24],[24,4.54]],"id":52671542},{"atb":[[20,5.5],[15,17.42]],"id":52671544}],"con":true,"img":false}]}
{"op":"mcm","clk":"11450305423","pt":1717320352357,"mc":[{"id":"1.229554928","rc":[{"atb":[[75,0],[40,0],[100,0],[50,0]],"id":52671542}],"con":true,"img":false}]}
{"op":"mcm","clk":"11450305460","pt":1717320353033,"mc":[{"id":"1.229554928","rc":[{"atb":[[70,0.76],[38,2.83],[95,0.28],[48,1.67]],"id":52671542}],"con":true,"img":false}]}
{"op":"mcm","clk":"11450312726","pt":1717320471453,"mc":[{"id":"1.229554928","rc":[{"atb":[[2.56,0],[2.46,0],[2.66,0],[2.76,0]],"id":52237624}],"con":true,"img":false}]}
{"op":"mcm","clk":"11450312767","pt":1717320472127,"mc":[{"id":"1.229554928","rc":[{"atb":[[2.56,67.08],[2.86,14.06],[2.66,47.27],[2.76,29.73]],"id":52237624}],"con":true,"img":false}]}
{"op":"mcm","clk":"11450337156","pt":1717320708991,"mc":[{"id":"1.229554928","rc":[{"atb":[[2.56,0],[2.86,0],[2.66,0],[2.76,0]],"id":52237624}],"con":true,"img":false}]}
{"op":"mcm","clk":"11450337211","pt":1717320709665,"mc":[{"id":"1.229554928","rc":[{"atb":[[2.54,67.95],[2.74,30.07],[2.64,47.85],[2.84,14.21]],"id":52237624}],"con":true,"img":false}]}
{"op":"mcm","clk":"11450360425","pt":1717320990854,"mc":[{"id":"1.229554928","rc":[{"atb":[[8.6,0],[6.6,0]],"id":52237628},{"atb":[[5.1,25.52],[4.1,0]],"id":52237627},{"atb":[[5.8,0],[7.6,0]],"id":52671563},{"atb":[[18,0],[26,0]],"id":52671565},{"atb":[[6.8,0],[8.8,0]],"id":52671561},{"atb":[[300,0],[200,0]],"id":52671560},{"atb":[[9,0],[12.5,0]],"id":52671555},{"atb":[[2.14,0],[2.34,0]],"id":52237624},{"atb":[[16,0],[11,0]],"id":52237612},{"atb":[[9.6,0],[14,0]],"id":52671550},{"atb":[[550,0],[650,0]],"id":52671546},{"atb":[[2.64,15.95],[2.44,54.5]],"id":52237617},{"atb":[[3.45,0],[2.98,0]],"id":52671548},{"atb":[[17,0],[24,0]],"id":52671542},{"atb":[[20,0],[15,0]],"id":52671544}],"con":true,"img":false}]}
{"op":"mcm","clk":"11450362925","pt":1717321022537,"mc":[{"id":"1.229554928","rc":[{"atb":[[8.6,13.75],[6.6,43.55]],"id":52237628},{"atb":[[5.1,51.02],[4.1,78.68]],"id":52237627},{"atb":[[5.8,50.81],[7.6,15.83]],"id":52671563},{"atb":[[18,14.34],[26,4.18]],"id":52671565},{"atb":[[6.8,42.05],[8.8,13.4]],"id":52671561},{"atb":[[300,0.35],[200,1.22]],"id":52671560},{"atb":[[9,30.48],[12.5,9.08]],"id":52671555},{"atb":[[2.14,213.95],[2.34,78]],"id":52237624},{"atb":[[16,6.96],[11,24.39]],"id":52237612},{"atb":[[9.6,28.36],[14,8.04]],"id":52671550},{"atb":[[550,0.44],[650,0.16]],"id":52671546},{"atb":[[2.64,79.69],[2.44,223.88]],"id":52237617},{"atb":[[3.45,42.66],[2.98,123.18]],"id":52671548},{"atb":[[17,15.24],[24,4.54]],"id":52671542},{"atb":[[20,5.5],[15,17.42]],"id":52671544}],"con":true,"img":false}]}
{"op":"mcm","clk":"11450365319","pt":1717321052849,"mc":[{"id":"1.229554928","rc":[{"atb":[[16.5,0],[9.6,0],[11.5,0],[14,0]],"id":52671563},{"atb":[[2.54,0],[2.74,0],[2.64,0],[2.84,0]],"id":52237624},{"atb":[[70,0],[38,0],[95,0],[48,0]],"id":52671542}],"con":true,"img":false}]}
{"op":"mcm","clk":"11450365380","pt":1717321053522,"mc":[{"id":"1.229554928","rc":[{"atb":[[17,1.64],[12,7.14],[9.8,11.89],[14.5,3.88]],"id":52671563}],"con":true,"img":false}]}
{"op":"mcm","clk":"11450365389","pt":1717321053625,"mc":[{"id":"1.229554928","rc":[{"atb":[[2.54,50.96],[2.74,15.04],[2.64,31.9],[2.44,72.66]],"id":52237624},{"atb":[[75,0.71],[40,2.68],[100,0.27],[50,1.6]],"id":52671542}],"con":true,"img":false}]}
{"op":"mcm","clk":"11450372173","pt":1717321152276,"mc":[{"id":"1.229554928","rc":[{"atb":[[17,0],[12,0],[9.8,0],[14.5,0]],"id":52671563},{"atb":[[5.2,0],[5.7,0],[4.2,0],[4.7,0]],"id":52671548}],"con":true,"img":false}]}
{"op":"mcm","clk":"11450372248","pt":1717321153260,"mc":[{"id":"1.229554928","rc":[{"atb":[[11,5.23],[13.5,2.09],[8.4,14.14],[9.4,9.34]],"id":52671563}],"con":true,"img":false}]}
{"op":"mcm","clk":"11450372257","pt":1717321153365,"mc":[{"id":"1.229554928","rc":[{"atb":[[5.6,5.69],[5.1,12.76],[4.6,21.8],[4.1,33.76]],"id":52671548}],"con":true,"img":false}]}
{"op":"mcm","clk":"11450376953","pt":1717321229205,"mc":[{"id":"1.229554928","rc":[{"atb":[[18,0],[10.5,0],[13,0],[15.5,0]],"id":52671561},{"atb":[[540,0],[590,0],[440,0],[490,0]],"id":52671546},{"atb":[[5.6,0],[5.1,0],[4.6,0],[4.1,0]],"id":52671548}],"con":true,"img":false}]}
{"op":"mcm","clk":"11450377007","pt":1717321229882,"mc":[{"id":"1.229554928","rc":[{"atb":[[17.5,1.59],[10,11.63],[12.5,6.82],[15,3.74]],"id":52671561},{"atb":[[560,0.09],[610,0.04],[460,0.23],[510,0.15]],"id":52671546},{"atb":[[3.95,35.47],[4.9,13.41],[4.4,23.08],[5.4,5.94]],"id":52671548}],"con":true,"img":false}]}
{"op":"mcm","clk":"11450378793","pt":1717321260336,"mc":[{"id":"1.229554928","rc":[{"atb":[[5.4,21.81]],"id":52237628},{"atl":[[560,2]],"id":52237628},{"atb":[[3,34.14]],"id":52237627},{"atl":[[270,2]],"id":52237627},{"atb":[[3.55,23.5]],"id":52671563},{"atl":[[410,2]],"id":52671563},{"atb":[[25,4.17]],"id":52671565},{"atl":[[1000,2]],"id":52671565},{"atb":[[4.1,18.46]],"id":52671561},{"atl":[[510,2]],"id":52671561},{"atb":[[29,2]],"id":52671560},{"atb":[[6.8,9.73]],"id":52671555},{"atl":[[710,2]],"id":52671555},{"atb":[[1.89,112.36]],"id":52237624},{"atl":[[19,2]],"id":52237624},{"atb":[[26,4]],"id":52237612},{"atb":[[1.8,9.73]],"id":52671550},{"atl":[[890,2]],"id":52671550},{"atb":[[1.8,2]],"id":52671546},{"atb":[[2.32,75.76]],"id":52237617},{"atl":[[60,2]],"id":52237617},{"atb":[[2.7,58.57]],"id":52671548},{"atl":[[150,2]],"id":52671548},{"atb":[[28,3.7]],"id":52671542},{"atb":[[28,3.7]],"id":52671544}],"con":true,"img":false}]}
{"op":"mcm","clk":"11450379602","pt":1717321271933,"mc":[{"id":"1.229554928","rc":[{"atb":[[2.58,63.29]],"id":52671548}],"con":true,"img":false}]}
{"op":"mcm","clk":"11450379611","pt":1717321272033,"mc":[{"id":"1.229554928","rc":[{"atb":[[2.7,0]],"id":52671548}],"con":true,"img":false}]}
{"op":"mcm","clk":"11450382317","pt":1717321314587,"mc":[{"id":"1.229554928","rc":[{"atb":[[8.6,0],[6.6,0]],"id":52237628},{"atb":[[5.1,25.52],[4.1,0]],"id":52237627},{"atb":[[5.8,0],[7.6,0]],"id":52671563},{"atb":[[18,0],[26,0]],"id":52671565},{"atb":[[6.8,0],[8.8,0]],"id":52671561},{"atb":[[300,0],[200,0]],"id":52671560},{"atb":[[9,0],[12.5,0]],"id":52671555},{"atb":[[2.14,0],[2.34,0]],"id":52237624},{"atb":[[16,0],[11,0]],"id":52237612},{"atb":[[9.6,0],[14,0]],"id":52671550},{"atb":[[550,0],[650,0]],"id":52671546},{"atb":[[2.64,15.95],[2.44,54.5]],"id":52237617},{"atb":[[3.45,0],[2.98,0]],"id":52671548},{"atb":[[17,0],[24,0]],"id":52671542},{"atb":[[20,0],[15,0]],"id":52671544}],"con":true,"img":false}]}
{"op":"mcm","clk":"11450384115","pt":1717321343797,"mc":[{"id":"1.229554928","rc":[{"atb":[[300,0.35],[200,1.22]],"id":52671560},{"atb":[[16,6.96],[11,24.39]],"id":52237612},{"atb":[[550,0.44],[650,0.16]],"id":52671546},{"atb":[[2.64,79.69],[2.44,223.88]],"id":52237617},{"atb":[[3.45,42.66],[2.98,123.18]],"id":52671548},{"atb":[[17,15.24],[24,4.54]],"id":52671542},{"atb":[[20,5.5],[15,17.42]],"id":52671544}],"con":true,"img":false}]}
{"op":"mcm","clk":"11450384130","pt":1717321343906,"mc":[{"id":"1.229554928","rc":[{"atb":[[8.6,13.75],[6.6,43.55]],"id":52237628},{"atb":[[5.1,51.02],[4.1,78.68]],"id":52237627},{"atb":[[5.8,50.81],[7.6,15.83]],"id":52671563},{"atb":[[18,14.34],[26,4.18]],"id":52671565},{"atb":[[6.8,42.05],[8.8,13.4]],"id":52671561},{"atb":[[9,30.48],[12.5,9.08]],"id":52671555},{"atb":[[2.14,213.95],[2.34,78]],"id":52237624},{"atb":[[9.6,28.36],[14,8.04]],"id":52671550}],"con":true,"img":false}]}
{"op":"mcm","clk":"11450389955","pt":1717321440041,"mc":[{"id":"1.229554928","rc":[{"atb":[[2.54,0],[2.74,0],[2.64,0],[2.44,0]],"id":52237624}],"con":true,"img":false}]}
{"op":"mcm","clk":"11450389998","pt":1717321440786,"mc":[{"id":"1.229554928","rc":[{"atb":[[2.56,67.08],[2.86,14.06],[2.66,47.27],[2.76,29.73]],"id":52237624}],"con":true,"img":false}]}
{"op":"mcm","clk":"11450406740","pt":1717321679548,"mc":[{"id":"1.229554928","rc":[{"atb":[[8.6,0],[6.6,0]],"id":52237628},{"atb":[[5.1,25.52],[4.1,0]],"id":52237627},{"atb":[[5.8,0],[7.6,0]],"id":52671563},{"atb":[[18,0],[26,0]],"id":52671565},{"atb":[[6.8,0],[8.8,0]],"id":52671561},{"atb":[[300,0],[200,0]],"id":52671560},{"atb":[[9,0],[12.5,0]],"id":52671555},{"atb":[[2.14,0],[2.34,0]],"id":52237624},{"atb":[[16,0],[11,0]],"id":52237612},{"atb":[[9.6,0],[14,0]],"id":52671550},{"atb":[[550,0],[650,0]],"id":52671546},{"atb":[[2.64,15.95],[2.44,54.5]],"id":52237617},{"atb":[[3.45,0],[2.98,0]],"id":52671548},{"atb":[[17,0],[24,0]],"id":52671542},{"atb":[[20,0],[15,0]],"id":52671544}],"con":true,"img":false}]}
{"op":"mcm","clk":"11450408943","pt":1717321708983,"mc":[{"id":"1.229554928","rc":[{"atb":[[300,0.35],[200,1.22]],"id":52671560},{"atb":[[16,6.96],[11,24.39]],"id":52237612},{"atb":[[550,0.44],[650,0.16]],"id":52671546},{"atb":[[2.64,79.69],[2.44,223.88]],"id":52237617},{"atb":[[3.45,42.66],[2.98,123.18]],"id":52671548},{"atb":[[17,15.24],[24,4.54]],"id":52671542},{"atb":[[20,5.5],[15,17.42]],"id":52671544}],"con":true,"img":false}]}
{"op":"mcm","clk":"11450408949","pt":1717321709095,"mc":[{"id":"1.229554928","rc":[{"atb":[[8.6,13.75],[6.6,43.55]],"id":52237628},{"atb":[[5.1,51.02],[4.1,78.68]],"id":52237627},{"atb":[[5.8,50.81],[7.6,15.83]],"id":52671563},{"atb":[[18,14.34],[26,4.18]],"id":52671565},{"atb":[[6.8,42.05],[8.8,13.4]],"id":52671561},{"atb":[[9,30.48],[12.5,9.08]],"id":52671555},{"atb":[[2.14,213.95],[2.34,78]],"id":52237624},{"atb":[[9.6,28.36],[14,8.04]],"id":52671550}],"con":true,"img":false}]}
{"op":"mcm","clk":"11450416407","pt":1717321796111,"mc":[{"id":"1.229554928","rc":[{"atb":[[75,0],[40,0],[100,0],[50,0]],"id":52671542}],"con":true,"img":false}]}
{"op":"mcm","clk":"11450416423","pt":1717321796268,"mc":[{"id":"1.229554928","rc":[{"atb":[[25,4.17],[28,0]],"id":52671542}],"con":true,"img":false}]}
{"op":"mcm","clk":"11450416478","pt":1717321796889,"mc":[{"id":"1.229554928","rc":[{"atb":[[70,0.76],[38,2.83],[95,0.28],[48,1.67]],"id":52671542}],"con":true,"img":false}]}
{"op":"mcm","clk":"11450430400","pt":1717321954043,"mc":[{"id":"1.229554928","rc":[{"atb":[[2.56,0],[2.86,0],[2.66,0],[2.76,0]],"id":52237624}],"con":true,"img":false}]}
{"op":"mcm","clk":"11450430466","pt":1717321954726,"mc":[{"id":"1.229554928","rc":[{"atb":[[2.56,50.3],[2.46,71.67],[2.66,31.52],[2.76,14.86]],"id":52237624}],"con":true,"img":false}]}
{"op":"mcm","clk":"11450433802","pt":1717321996779,"mc":[{"id":"1.229554928","rc":[{"atb":[[2.56,0],[2.46,0],[2.66,0],[2.76,0]],"id":52237624}],"con":true,"img":false}]}
{"op":"mcm","clk":"11450433862","pt":1717321997495,"mc":[{"id":"1.229554928","rc":[{"atb":[[2.54,50.96],[2.74,15.04],[2.64,31.9],[2.44,72.66]],"id":52237624}],"con":true,"img":false}]}
{"op":"mcm","clk":"11450433905","pt":1717321997965,"mc":[{"id":"1.229554928","rc":[{"atb":[[560,0],[610,0],[460,0],[510,0]],"id":52671546},{"atb":[[65,0],[36,0],[90,0],[46,0]],"id":52671544}],"con":true,"img":false}]}
{"op":"mcm","clk":"11450433910","pt":1717321998067,"mc":[{"id":"1.229554928","rc":[{"atb":[[46,0],[23,0],[28,0]],"id":52237612}],"con":true,"img":false}]}
{"op":"mcm","clk":"11450433917","pt":1717321998167,"mc":[{"id":"1.229554928","rc":[{"atb":[[21,5],[28,0]],"id":52671544}],"con":true,"img":false}]}
{"op":"mcm","clk":"11450433925","pt":1717321998276,"mc":[{"id":"1.229554928","rc":[{"atb":[[16.5,6.45],[26,0]],"id":52237612}],"con":true,"img":false}]}
{"op":"mcm","clk":"11450433957","pt":1717321998691,"mc":[{"id":"1.229554928","rc":[{"atb":[[550,0.59],[600,0.09],[650,0.2],[500,0.21]],"id":52671546},{"atb":[[75,0.71],[40,2.68],[100,0.27],[50,1.6]],"id":52671544}],"con":true,"img":false}]}
{"op":"mcm","clk":"11450433964","pt":1717321998787,"mc":[{"id":"1.229554928","rc":[{"atb":[[50,0.53],[25,4.36],[30,2.71]],"id":52237612}],"con":true,"img":false}]}
{"op":"mcm","clk":"11450436494","pt":1717322028049,"mc":[{"id":"1.229554928","rc":[{"atb":[[16.5,0],[24,4.35]],"id":52237612}],"con":true,"img":false}]}
{"op":"mcm","clk":"11450438283","pt":1717322047773,"mc":[{"id":"1.229554928","rc":[{"atl":[[270,0],[260,2]],"id":52237627},{"atl":[[700,2],[710,0]],"id":52671555},{"atl":[[18,2],[19,0]],"id":52237624},{"atb":[[2.74,57.47],[2.58,0]],"id":52671548},{"atb":[[21,0],[27,3.85]],"id":52671544}],"con":true,"img":false}]}
{"op":"mcm","clk":"11450438314","pt":1717322048088,"mc":[{"id":"1.229554928","rc":[{"atb":[[11,0],[13.5,0],[8.4,0],[9.4,0]],"id":52671563}],"con":true,"img":false}]}
{"op":"mcm","clk":"11450438375","pt":1717322048763,"mc":[{"id":"1.229554928","rc":[{"atb":[[9.2,9.57],[10.5,5.51],[8.2,14.53],[13,2.18]],"id":52671563}],"con":true,"img":false}]}
{"op":"mcm","clk":"11450440040","pt":1717322066795,"mc":[{"id":"1.229554928","rc":[{"atb":[[8.6,0],[6.6,0]],"id":52237628},{"atb":[[5.1,25.52],[4.1,0]],"id":52237627},{"atb":[[5.8,0],[7.6,0]],"id":52671563},{"atb":[[18,0],[26,0]],"id":52671565},{"atb":[[6.8,0],[8.8,0]],"id":52671561},{"atb":[[300,0],[200,0]],"id":52671560},{"atb":[[9,0],[12.5,0]],"id":52671555},{"atb":[[2.14,0],[2.34,0]],"id":52237624},{"atb":[[16,0],[11,0]],"id":52237612},{"atb":[[9.6,0],[14,0]],"id":52671550},{"atb":[[550,0.14],[650,0.04]],"id":52671546},{"atb":[[2.64,15.95],[2.44,54.5]],"id":52237617},{"atb":[[3.45,0],[2.98,0]],"id":52671548},{"atb":[[17,0],[24,0]],"id":52671542},{"atb":[[20,0],[15,0]],"id":52671544}],"con":true,"img":false}]}
{"op":"mcm","clk":"11450441776","pt":1717322083405,"mc":[{"id":"1.229554928","rc":[{"atb":[[8.6,13.75],[6.6,43.55]],"id":52237628},{"atb":[[5.1,51.02],[4.1,78.68]],"id":52237627},{"atb":[[5.8,50.81],[7.6,15.83]],"id":52671563},{"atb":[[18,14.34],[26,4.18]],"id":52671565},{"atb":[[6.8,42.05],[8.8,13.4]],"id":52671561},{"atb":[[300,0.35],[200,1.22]],"id":52671560},{"atb":[[9,30.48],[12.5,9.08]],"id":52671555},{"atb":[[2.14,213.95],[2.34,78]],"id":52237624},{"atb":[[16,6.96],[11,24.39]],"id":52237612},{"atb":[[9.6,28.36],[14,8.04]],"id":52671550},{"atb":[[550,0.59],[650,0.2]],"id":52671546},{"atb":[[2.64,79.69],[2.44,223.88]],"id":52237617},{"atb":[[3.45,42.66],[2.98,123.18]],"id":52671548},{"atb":[[17,15.24],[24,4.54]],"id":52671542},{"atb":[[20,5.5],[15,17.42]],"id":52671544}],"con":true,"img":false}]}
{"op":"mcm","clk":"11450443762","pt":1717322108929,"mc":[{"id":"1.229554928","rc":[{"atb":[[70,0],[38,0],[95,0],[48,0]],"id":52671542}],"con":true,"img":false}]}
{"op":"mcm","clk":"11450443814","pt":1717322109600,"mc":[{"id":"1.229554928","rc":[{"atb":[[80,0.66],[42,2.55],[110,0.24],[55,1.45]],"id":52671542}],"con":true,"img":false}]}
{"op":"mcm","clk":"11450448899","pt":1717322168883,"mc":[{"id":"1.229554928","rc":[{"atb":[[2.74,0],[2.58,63.29]],"id":52671548}],"con":true,"img":false}]}
{"op":"mcm","clk":"11450463905","pt":1717322335614,"mc":[{"id":"1.229554928","rc":[{"atb":[[9.2,0],[10.5,0],[8.2,0],[13,0]],"id":52671563}],"con":true,"img":false}]}
{"op":"mcm","clk":"11450463985","pt":1717322336336,"mc":[{"id":"1.229554928","rc":[{"atb":[[11,5.23],[13.5,2.09],[8.4,14.14],[9.4,9.34]],"id":52671563}],"con":true,"img":false}]}
{"op":"mcm","clk":"11450476596","pt":1717322471436,"mc":[{"id":"1.229554928","rc":[{"atb":[[8.6,0],[6.6,0]],"id":52237628},{"atb":[[5.1,25.52],[4.1,0]],"id":52237627},{"atb":[[5.8,0],[7.6,0]],"id":52671563},{"atb":[[18,0],[26,0]],"id":52671565},{"atb":[[6.8,0],[8.8,0]],"id":52671561},{"atb":[[300,0],[200,0]],"id":52671560},{"atb":[[9,0],[12.5,0]],"id":52671555},{"atb":[[2.14,0],[2.34,0]],"id":52237624},{"atb":[[16,0],[11,0]],"id":52237612},{"atb":[[9.6,0],[14,0]],"id":52671550},{"atb":[[550,0.14],[650,0.04]],"id":52671546},{"atb":[[2.64,15.95],[2.44,54.5]],"id":52237617},{"atb":[[3.45,0],[2.98,0]],"id":52671548},{"atb":[[17,0],[24,0]],"id":52671542},{"atb":[[20,0],[15,0]],"id":52671544}],"con":true,"img":false}]}
{"op":"mcm","clk":"11450478952","pt":1717322501181,"mc":[{"id":"1.229554928","rc":[{"atb":[[8.6,13.75],[6.6,43.55]],"id":52237628},{"atb":[[5.1,51.02],[4.1,78.68]],"id":52237627},{"atb":[[5.8,50.81],[7.6,15.83]],"id":52671563},{"atb":[[18,14.34],[26,4.18]],"id":52671565},{"atb":[[6.8,42.05],[8.8,13.4]],"id":52671561},{"atb":[[300,0.35],[200,1.22]],"id":52671560},{"atb":[[9,30.48],[12.5,9.08]],"id":52671555},{"atb":[[2.14,213.95],[2.34,78]],"id":52237624},{"atb":[[16,6.96],[11,24.39]],"id":52237612},{"atb":[[9.6,28.36],[14,8.04]],"id":52671550},{"atb":[[550,0.59],[650,0.2]],"id":52671546},{"atb":[[2.64,79.69],[2.44,223.88]],"id":52237617},{"atb":[[3.45,42.66],[2.98,123.18]],"id":52671548},{"atb":[[17,15.24],[24,4.54]],"id":52671542},{"atb":[[20,5.5],[15,17.42]],"id":52671544}],"con":true,"img":false}]}
{"op":"mcm","clk":"11450481155","pt":1717322528170,"mc":[{"id":"1.229554928","rc":[{"atb":[[8.6,0],[6.6,0]],"id":52237628},{"atb":[[5.1,25.52],[4.1,0]],"id":52237627},{"atb":[[5.8,0],[7.6,0]],"id":52671563},{"atb":[[18,0],[26,0]],"id":52671565},{"atb":[[6.8,0],[8.8,0]],"id":52671561},{"atb":[[300,0],[200,0]],"id":52671560},{"atb":[[9,0],[12.5,0]],"id":52671555},{"atb":[[2.14,0],[2.34,0]],"id":52237624},{"atb":[[16,0],[11,0]],"id":52237612},{"atb":[[9.6,0],[14,0]],"id":52671550},{"atb":[[550,0.14],[650,0.04]],"id":52671546},{"atb":[[2.64,15.95],[2.44,54.5]],"id":52237617},{"atb":[[3.45,0],[2.98,0]],"id":52671548},{"atb":[[17,0],[24,0]],"id":52671542},{"atb":[[20,0],[15,0]],"id":52671544}],"con":true,"img":false}]}
{"op":"mcm","clk":"11450482365","pt":1717322542927,"mc":[{"id":"1.229554928","rc":[{"atb":[[6.2,46.9],[8.2,14.51]],"id":52237628},{"atb":[[5.2,24.88],[4.2,76.22]],"id":52237627},{"atb":[[5.8,50.81],[7.6,15.83]],"id":52671563},{"atb":[[17,15.24],[24,4.54]],"id":52671565},{"atb":[[6.8,42.05],[8.8,13.4]],"id":52671561},{"atb":[[150,1.63],[250,0.41]],"id":52671560},{"atb":[[11,10.45],[8.4,32.96]],"id":52671555},{"atb":[[2.36,76.85],[2.16,210.26]],"id":52237624},{"atb":[[10.5,25.67],[15.5,7.2]],"id":52237612},{"atb":[[9.2,29.74],[13,8.71]],"id":52671550},{"atb":[[550,0.59],[650,0.2]],"id":52671546},{"atb":[[2.68,62.22],[2.48,164.8]],"id":52237617},{"atb":[[3.4,43.55],[2.96,124.44]],"id":52671548},{"atb":[[16.5,15.73],[23,4.75]],"id":52671542},{"atb":[[19.5,5.65],[14.5,18.06]],"id":52671544}],"con":true,"img":false}]}
{"op":"mcm","clk":"11450485462","pt":1717322584695,"mc":[{"id":"1.229554928","rc":[{"atb":[[6.2,0],[8.2,0]],"id":52237628},{"atb":[[5.2,0],[4.2,0]],"id":52237627},{"atb":[[5.8,0],[7.6,0]],"id":52671563},{"atb":[[17,0],[24,0]],"id":52671565},{"atb":[[6.8,0],[8.8,0]],"id":52671561},{"atb":[[150,0],[250,0]],"id":52671560},{"atb":[[11,0],[8.4,0]],"id":52671555},{"atb":[[2.36,0],[2.16,0]],"id":52237624},{"atb":[[10.5,0],[15.5,0]],"id":52237612},{"atb":[[9.2,0],[13,0]],"id":52671550},{"atb":[[550,0.14],[650,0.04]],"id":52671546},{"atb":[[2.68,0],[2.48,0]],"id":52237617},{"atb":[[3.4,0],[2.96,0]],"id":52671548},{"atb":[[16.5,0],[23,0]],"id":52671542},{"atb":[[19.5,0],[14.5,0]],"id":52671544}],"con":true,"img":false}]}
{"op":"mcm","clk":"11450487902","pt":1717322612351,"mc":[{"id":"1.229554928","rc":[{"atb":[[6.2,46.9],[8.2,14.51]],"id":52237628},{"atb":[[5.2,24.88],[4.2,76.22]],"id":52237627},{"atb":[[5.8,50.81],[7.6,15.83]],"id":52671563},{"atb":[[17,15.24],[24,4.54]],"id":52671565},{"atb":[[6.8,42.05],[8.8,13.4]],"id":52671561},{"atb":[[150,1.63],[250,0.41]],"id":52671560},{"atb":[[11,10.45],[8.4,32.96]],"id":52671555},{"atb":[[2.36,76.85],[2.16,210.26]],"id":52237624},{"atb":[[10.5,25.67],[15.5,7.2]],"id":52237612},{"atb":[[9.2,29.74],[13,8.71]],"id":52671550},{"atb":[[550,0.59],[650,0.2]],"id":52671546},{"atb":[[2.68,62.22],[2.48,164.8]],"id":52237617},{"atb":[[3.4,43.55],[2.96,124.44]],"id":52671548},{"atb":[[16.5,15.73],[23,4.75]],"id":52671542},{"atb":[[19.5,5.65],[14.5,18.06]],"id":52671544}],"con":true,"img":false}]}
{"op":"mcm","clk":"11450490356","pt":1717322639593,"mc":[{"id":"1.229554928","rc":[{"atb":[[6.2,0],[8.2,0]],"id":52237628},{"atb":[[5.2,0],[4.2,0]],"id":52237627},{"atb":[[5.8,0],[7.6,0]],"id":52671563},{"atb":[[17,0],[24,0]],"id":52671565},{"atb":[[6.8,0],[8.8,0]],"id":52671561},{"atb":[[150,0],[250,0]],"id":52671560},{"atb":[[11,0],[8.4,0]],"id":52671555},{"atb":[[2.36,0],[2.16,0]],"id":52237624},{"atb":[[10.5,0],[15.5,0]],"id":52237612},{"atb":[[9.2,0],[13,0]],"id":52671550},{"atb":[[550,0.14],[650,0.04]],"id":52671546},{"atb":[[2.68,0],[2.48,0]],"id":52237617},{"atb":[[3.4,0],[2.96,0]],"id":52671548},{"atb":[[16.5,0],[23,0]],"id":52671542},{"atb":[[19.5,0],[14.5,0]],"id":52671544}],"con":true,"img":false}]}
{"op":"mcm","clk":"11450491515","pt":1717322652008,"mc":[{"id":"1.229554928","rc":[{"atb":[[6.2,46.9],[8.2,14.51]],"id":52237628},{"atb":[[5.2,24.88],[4.2,76.22]],"id":52237627},{"atb":[[5.8,50.81],[7.6,15.83]],"id":52671563},{"atb":[[17,15.24],[24,4.54]],"id":52671565},{"atb":[[6.8,42.05],[8.8,13.4]],"id":52671561},{"atb":[[150,1.63],[250,0.41]],"id":52671560},{"atb":[[11,10.45],[8.4,32.96]],"id":52671555},{"atb":[[2.36,76.85],[2.16,210.26]],"id":52237624},{"atb":[[10.5,25.67],[15.5,7.2]],"id":52237612},{"atb":[[9.2,29.74],[13,8.71]],"id":52671550},{"atb":[[550,0.59],[650,0.2]],"id":52671546},{"atb":[[2.68,62.22],[2.48,164.8]],"id":52237617},{"atb":[[3.4,43.55],[2.96,124.44]],"id":52671548},{"atb":[[16.5,15.73],[23,4.75]],"id":52671542},{"atb":[[19.5,5.65],[14.5,18.06]],"id":52671544}],"con":true,"img":false}]}
{"op":"mcm","clk":"11450505727","pt":1717322805577,"mc":[{"id":"1.229554928","rc":[{"atb":[[6.2,0],[8.2,0]],"id":52237628},{"atb":[[5.2,0],[4.2,0]],"id":52237627},{"atb":[[5.8,0],[7.6,0]],"id":52671563},{"atb":[[17,0],[24,0]],"id":52671565},{"atb":[[6.8,0],[8.8,0]],"id":52671561},{"atb":[[150,0],[250,0]],"id":52671560},{"atb":[[11,0],[8.4,0]],"id":52671555},{"atb":[[2.36,0],[2.16,0]],"id":52237624},{"atb":[[10.5,0],[15.5,0]],"id":52237612},{"atb":[[9.2,0],[13,0]],"id":52671550},{"atb":[[550,0.14],[650,0.04]],"id":52671546},{"atb":[[2.68,0],[2.48,0]],"id":52237617},{"atb":[[3.4,0],[2.96,0]],"id":52671548},{"atb":[[16.5,0],[23,0]],"id":52671542},{"atb":[[19.5,0],[14.5,0]],"id":52671544}],"con":true,"img":false}]}
{"op":"mcm","clk":"11450507017","pt":1717322820895,"mc":[{"id":"1.229554928","rc":[{"atb":[[6.2,46.9],[8.2,14.51]],"id":52237628},{"atb":[[5.2,24.88],[4.2,76.22]],"id":52237627},{"atb":[[5.8,50.81],[7.6,15.83]],"id":52671563},{"atb":[[17,15.24],[24,4.54]],"id":52671565},{"atb":[[6.8,42.05],[8.8,13.4]],"id":52671561},{"atb":[[150,1.63],[250,0.41]],"id":52671560},{"atb":[[11,10.45],[8.4,32.96]],"id":52671555},{"atb":[[2.36,76.85],[2.16,210.26]],"id":52237624},{"atb":[[10.5,25.67],[15.5,7.2]],"id":52237612},{"atb":[[9.2,29.74],[13,8.71]],"id":52671550},{"atb":[[550,0.59],[650,0.2]],"id":52671546},{"atb":[[2.68,62.22],[2.48,164.8]],"id":52237617},{"atb":[[3.4,43.55],[2.96,124.44]],"id":52671548},{"atb":[[16.5,15.73],[23,4.75]],"id":52671542},{"atb":[[19.5,5.65],[14.5,18.06]],"id":52671544}],"con":true,"img":false}]}
{"op":"mcm","clk":"11450522030","pt":1717322967266,"mc":[{"id":"1.229554928","rc":[{"atb":[[36,0],[50,0],[25,0],[30,0]],"id":52237612},{"atb":[[550,0.44],[600,0],[650,0.16],[500,0]],"id":52671546},{"atb":[[80,0],[42,0],[110,0],[55,0]],"id":52671542},{"atb":[[75,0],[40,0],[100,0],[50,0]],"id":52671544}],"con":true,"img":false}]}
{"op":"mcm","clk":"11450522036","pt":1717322967365,"mc":[{"id":"1.229554928","rc":[{"atb":[[16,6.67],[24,0]],"id":52237612},{"atb":[[24,4.35]],"id":52671542},{"atb":[[20,5.26],[27,0]],"id":52671544}],"con":true,"img":false}]}
{"op":"mcm","clk":"11450522049","pt":1717322967471,"mc":[{"id":"1.229554928","rc":[{"atb":[[25,0]],"id":52671542}],"con":true,"img":false}]}
{"op":"mcm","clk":"11450522090","pt":1717322967951,"mc":[{"id":"1.229554928","rc":[{"atb":[[36,0.75],[19,5.81],[23,3.57],[28,1.94]],"id":52237612},{"atb":[[280,0.38],[330,0.24],[380,0.14],[430,0.06]],"id":52671546},{"atb":[[70,0.38],[38,2.12],[48,1.11],[29,3.74]],"id":52671542},{"atb":[[70,0.38],[38,2.12],[48,1.11],[29,3.74]],"id":52671544}],"con":true,"img":false}]}
{"op":"mcm","clk":"11450522106","pt":1717322968150,"mc":[{"id":"1.229554928","rc":[{"atb":[[16,0],[24,4.35]],"id":52237612},{"atb":[[20,0],[25,4.17]],"id":52671544}],"con":true,"img":false}]}
{"op":"mcm","clk":"11450531531","pt":1717323064996,"mc":[{"id":"1.229554928","rc":[{"atb":[[10,12.23],[11,3.32]],"id":52237628},{"atl":[[40,2.76],[44,4.33]],"id":52237628},{"atb":[[7,4.12],[6.6,2.64]],"id":52237627},{"atl":[[16,3.56],[15,3.79]],"id":52237627},{"atl":[[32,2.85],[36,4.6]],"id":52671563},{"atb":[[50,3.96],[60,4.36]],"id":52671565},{"atl":[[280,3.25],[300,4.14]],"id":52671565},{"atb":[[11,4.31],[12,4.2]],"id":52671561},{"atl":[[34,3.61],[38,3.18]],"id":52671561},{"atb":[[130,3.71],[150,5.4]],"id":52671560},{"atb":[[18,2.62],[19,3.43]],"id":52671555},{"atl":[[65,3.69],[75,3.84]],"id":52671555},{"atb":[[23,8.01],[25,2.76]],"id":52237612},{"atl":[[270,4.4],[290,3.4]],"id":52237612},{"atl":[[100,4.05],[120,4.48]],"id":52671550},{"atb":[[2.74,9.01],[2.78,8.81]],"id":52237617},{"atl":[[5.7,2.77],[5.9,3.9]],"id":52237617},{"atb":[[4.6,3.84],[4.4,26.03]],"id":52671548},{"atl":[[11.5,2.75],[12.5,3.21]],"id":52671548},{"atb":[[70,0],[38,0],[46,2.66],[48,0],[50,3.8],[29,0]],"id":52671542},{"atl":[[620,2.73],[640,4.1]],"id":52671542},{"atb":[[70,0],[38,0],[44,3.99],[48,3.02],[29,0]],"id":52671544},{"atl":[[440,4.36],[460,3.67]],"id":52671544}],"con":true,"img":false}]}
{"op":"mcm","clk":"11450531541","pt":1717323065101,"mc":[{"id":"1.229554928","rc":[{"atb":[[2.58,9.93],[2.62,9.68]],"id":52237624},{"atl":[[4.5,3.78],[4.7,4.53]],"id":52237624},{"atb":[[36,0],[19,0],[23,4.44]],"id":52237612},{"atb":[[280,0],[330,0],[380,0],[430,0]],"id":52671546}],"con":true,"img":false}]}
{"op":"mcm","clk":"11450531552","pt":1717323065235,"mc":[{"id":"1.229554928","rc":[{"atl":[[560,0],[180,2]],"id":52237628},{"atl":[[260,0],[28,3.7]],"id":52237627},{"atl":[[410,0],[60,2]],"id":52671563},{"atl":[[890,2],[1000,0]],"id":52671565},{"atl":[[110,2],[510,0]],"id":52671561},{"atl":[[330,2],[700,0]],"id":52671555},{"atl":[[530,2],[890,0]],"id":52671550},{"atl":[[11.5,6.68],[60,0]],"id":52237617},{"atl":[[150,0],[18.5,5.71]],"id":52671548}],"con":true,"img":false}]}
{"op":"mcm","clk":"11450531562","pt":1717323065311,"mc":[{"id":"1.229554928","rc":[{"atl":[[18,0],[6.2,8.33]],"id":52237624}],"con":true,"img":false}]}
{"op":"mcm","clk":"11450531603","pt":1717323065723,"mc":[{"id":"1.229554928","rc":[{"atb":[[70,0.76],[38,2.83],[95,0.28],[48,1.67]],"id":52671542}],"con":true,"img":false}]}
{"op":"mcm","clk":"11450531614","pt":1717323065781,"mc":[{"id":"1.229554928","rc":[{"atb":[[36,1.5],[23,9.2],[46,0.58]],"id":52237612},{"atb":[[520,0.1],[570,0.05],[420,0.25],[470,0.17]],"id":52671546},{"atb":[[65,0.82],[36,2.99],[90,0.29],[46,1.74]],"id":52671544}],"con":true,"img":false}]}
{"op":"mcm","clk":"11450531683","pt":1717323066413,"mc":[{"id":"1.229554928","rc":[{"atl":[[4.5,0],[4.6,2.71]],"id":52237624},{"atl":[[11,3.67],[11.5,0]],"id":52671548}],"con":true,"img":false}]}
{"op":"mcm","clk":"11450531844","pt":1717323068021,"mc":[{"id":"1.229554928","rc":[{"atb":[[6,20],[5.4,0]],"id":52237628},{"atb":[[3,0],[3.25,34.14]],"id":52237627},{"atb":[[6.8,0],[7.8,9.73]],"id":52671555},{"atb":[[1.89,0],[1.97,103.09]],"id":52237624},{"atb":[[30,2.77]],"id":52237612},{"atb":[[2.32,0],[2.46,68.49]],"id":52237617},{"atb":[[2.88,53.19],[2.58,0]],"id":52671548},{"atb":[[32,3.23],[24,0]],"id":52671542},{"atb":[[32,3.23],[25,0]],"id":52671544}],"con":true,"img":false}]}
{"op":"mcm","clk":"11450531858","pt":1717323068086,"mc":[{"id":"1.229554928","rc":[{"atb":[[24,0]],"id":52237612}],"con":true,"img":false}]}
{"op":"mcm","clk":"11450537205","pt":1717323120725,"mc":[{"id":"1.229554928","rc":[{"atb":[[130,0],[150,1.63]],"id":52671560},{"atb":[[2.64,41.47],[2.62,0]],"id":52237624},{"atb":[[23,4.76],[25,0]],"id":52237612},{"atb":[[2.86,8.43],[2.78,0]],"id":52237617},{"atb":[[4.6,0],[4.7,4.69]],"id":52671548},{"atb":[[38,6.89],[50,0]],"id":52671542},{"atb":[[44,0],[48,0]],"id":52671544}],"con":true,"img":false}]}
{"op":"mcm","clk":"11450538219","pt":1717323130724,"mc":[{"id":"1.229554928","rc":[{"atb":[[2.82,8.62]],"id":52237617},{"atb":[[34,3.71],[46,0]],"id":52671542}],"con":true,"img":false}]}
{"op":"mcm","clk":"11450539238","pt":1717323140774,"mc":[{"id":"1.229554928","rc":[{"atb":[[2.74,0]],"id":52237617}],"con":true,"img":false}]}
{"op":"mcm","clk":"11450539341","pt":1717323141666,"mc":[{"id":"1.229554928","rc":[{"atb":[[6.2,0],[8.2,0]],"id":52237628},{"atb":[[5.2,0],[4.2,0]],"id":52237627},{"atb":[[5.8,0],[7.6,0]],"id":52671563},{"atb":[[17,0],[24,0]],"id":52671565},{"atb":[[6.8,0],[8.8,0]],"id":52671561},{"atb":[[150,0],[250,0]],"id":52671560},{"atb":[[11,0],[8.4,0]],"id":52671555},{"atb":[[2.36,0],[2.16,0]],"id":52237624},{"atb":[[10.5,0],[15.5,0]],"id":52237612},{"atb":[[9.2,0],[13,0]],"id":52671550},{"atb":[[550,0],[650,0]],"id":52671546},{"atb":[[2.68,0],[2.48,0]],"id":52237617},{"atb":[[3.4,0],[2.96,0]],"id":52671548},{"atb":[[16.5,0],[23,0]],"id":52671542},{"atb":[[19.5,0],[14.5,0]],"id":52671544}],"con":true,"img":false}]}
{"op":"mcm","clk":"11450539378","pt":1717323141983,"mc":[{"id":"1.229554928","rc":[{"atl":[[11,0],[11.5,2.78]],"id":52671548}],"con":true,"img":false}]}
{"op":"mcm","clk":"11450539534","pt":1717323143194,"mc":[{"id":"1.229554928","rc":[{"atb":[[3.75,5.7],[3.65,5.92]],"id":52671563},{"atb":[[100,4.24],[120,3.88]],"id":52671560},{"atb":[[1.88,17.83],[1.9,17.43]],"id":52671550},{"atb":[[1.88,17.83],[1.9,17.43]],"id":52671546},{"atl":[[11.5,0],[12,2.66]],"id":52671548},{"atb":[[34,4.46],[30,3.89]],"id":52671544}],"con":true,"img":false}]}
{"op":"mcm","clk":"11450539545","pt":1717323143296,"mc":[{"id":"1.229554928","rc":[{"atb":[[20,2.76],[22,3.41]],"id":52237612}],"con":true,"img":false}]}
{"op":"mcm","clk":"11450540628","pt":1717323152918,"mc":[{"id":"1.229554928","rc":[{"atb":[[6.2,46.9],[8.2,14.51]],"id":52237628},{"atb":[[5.2,24.88],[4.2,76.22]],"id":52237627},{"atb":[[5.8,50.81],[7.6,15.83]],"id":52671563},{"atb":[[17,15.24],[24,4.54]],"id":52671565},{"atb":[[6.8,42.05],[8.8,13.4]],"id":52671561},{"atb":[[150,1.63],[250,0.41]],"id":52671560},{"atb":[[11,10.45],[8.4,32.96]],"id":52671555},{"atb":[[2.36,76.85],[2.16,210.26]],"id":52237624},{"atb":[[10.5,25.67],[15.5,7.2]],"id":52237612},{"atb":[[9.2,29.74],[13,8.71]],"id":52671550},{"atb":[[550,0.44],[650,0.16]],"id":52671546},{"atb":[[2.68,62.22],[2.48,164.8]],"id":52237617},{"atb":[[3.4,43.55],[2.96,124.44]],"id":52671548},{"atb":[[16.5,15.73],[23,4.75]],"id":52671542},{"atb":[[19.5,5.65],[14.5,18.06]],"id":52671544}],"con":true,"img":false}]}
{"op":"mcm","clk":"11450540675","pt":1717323153184,"mc":[{"id":"1.229554928","rc":[{"atl":[[11.5,2.66]],"id":52671548}],"con":true,"img":false}]}
{"op":"mcm","clk":"11450540688","pt":1717323153284,"mc":[{"id":"1.229554928","rc":[{"atl":[[11,3.37],[12,0]],"id":52671548}],"con":true,"img":false}]}
{"op":"mcm","clk":"11450541824","pt":1717323163288,"mc":[{"id":"1.229554928","rc":[{"atl":[[11.5,0],[12,3.75],[12.5,0]],"id":52671548}],"con":true,"img":false}]}
{"op":"mcm","clk":"11450551194","pt":1717323248091,"mc":[{"id":"1.229554928","rc":[{"atb":[[32,3.23],[25,0]],"id":52671565},{"atl":[[800,2],[890,0]],"id":52671565},{"atb":[[5,18.46]],"id":52671561},{"atb":[[38,2]],"id":52671560},{"atl":[[5.6,8.33]],"id":52237624},{"atb":[[2.6,62.5]],"id":52237617},{"atb":[[2.88,0],[3.05,48.78]],"id":52671548}],"con":true,"img":false}]}
{"op":"mcm","clk":"11450551202","pt":1717323248133,"mc":[{"id":"1.229554928","rc":[{"atb":[[4.1,0]],"id":52671561},{"atb":[[29,0]],"id":52671560},{"atl":[[6.2,0]],"id":52237624},{"atb":[[2.46,0]],"id":52237617}],"con":true,"img":false}]}
{"op":"mcm","clk":"11450551215","pt":1717323248240,"mc":[{"id":"1.229554928","rc":[{"atl":[[800,0],[890,2]],"id":52671565}],"con":true,"img":false}]}
{"op":"mcm","clk":"11450551220","pt":1717323248342,"mc":[{"id":"1.229554928","rc":[{"atl":[[40,0]],"id":52237628},{"atl":[[260,3.62]],"id":52237612},{"atl":[[110,2.69]],"id":52671550},{"atl":[[430,3.05],[440,0]],"id":52671544}],"con":true,"img":false}]}
{"op":"mcm","clk":"11450551233","pt":1717323248449,"mc":[{"id":"1.229554928","rc":[{"atl":[[38,2.87]],"id":52237628},{"atb":[[6.8,3.13],[7,0]],"id":52237627},{"atb":[[11,0],[13.5,0],[8.4,0],[9.4,0]],"id":52671563},{"atl":[[270,0]],"id":52237612},{"atl":[[100,0]],"id":52671550},{"atl":[[5.7,0]],"id":52237617},{"atl":[[620,0]],"id":52671542}],"con":true,"img":false}]}
{"op":"mcm","clk":"11450551245","pt":1717323248547,"mc":[{"id":"1.229554928","rc":[{"atl":[[65,0],[70,3.86]],"id":52671555},{"atl":[[670,3.03]],"id":52671542},{"atl":[[450,3.64]],"id":52671544}],"con":true,"img":false}]}
{"op":"mcm","clk":"11450551307","pt":1717323249164,"mc":[{"id":"1.229554928","rc":[{"atb":[[9.2,9.57],[10.5,5.51],[8.2,14.53],[13,2.18]],"id":52671563}],"con":true,"img":false}]}
{"op":"mcm","clk":"11450551315","pt":1717323249268,"mc":[{"id":"1.229554928","rc":[{"atl":[[830,2],[890,0]],"id":52671565}],"con":true,"img":false}]}
{"op":"mcm","clk":"11450551350","pt":1717323249528,"mc":[{"id":"1.229554928","rc":[{"atl":[[38,0],[40,3.52]],"id":52237628},{"atb":[[6.8,0],[7,3.29]],"id":52237627},{"atl":[[65,4.63],[70,0]],"id":52671555},{"atl":[[260,0],[270,2.64]],"id":52237612},{"atl":[[100,2.89],[110,0]],"id":52671550},{"atl":[[5.7,3.22]],"id":52237617},{"atl":[[620,2.69],[640,0]],"id":52671542},{"atl":[[430,0],[440,4.46],[450,0]],"id":52671544}],"con":true,"img":false}]}
{"op":"mcm","clk":"11450552358","pt":1717323259566,"mc":[{"id":"1.229554928","rc":[{"atl":[[640,3.36]],"id":52671542}],"con":true,"img":false}]}
{"op":"mcm","clk":"11450553443","pt":1717323269577,"mc":[{"id":"1.229554928","rc":[{"atl":[[670,0]],"id":52671542}],"con":true,"img":false}]}
{"op":"mcm","clk":"11450564619","pt":1717323369258,"mc":[{"id":"1.229554928","rc":[{"atl":[[830,0],[890,2]],"id":52671565},{"atl":[[5.6,0],[6.2,9.08]],"id":52237624},{"atb":[[2.46,67.96],[2.6,0]],"id":52237617},{"atb":[[2.88,53.19],[3.05,0]],"id":52671548}],"con":true,"img":false}]}
{"op":"mcm","clk":"11450569327","pt":1717323407395,"mc":[{"id":"1.229554928","rc":[{"atb":[[130,3.34],[120,0]],"id":52671560},{"atb":[[2.8,8.72],[2.86,0]],"id":52237617},{"atb":[[4.6,4.34],[4.7,0]],"id":52671548}],"con":true,"img":false}]}
{"op":"mcm","clk":"11450570405","pt":1717323415917,"mc":[{"id":"1.229554928","rc":[{"atb":[[10.5,0]],"id":52671563}],"con":true,"img":false}]}
{"op":"mcm","clk":"11450570413","pt":1717323416058,"mc":[{"id":"1.229554928","rc":[{"atb":[[9.2,0],[8.2,0],[13,0]],"id":52671563}],"con":true,"img":false}]}
{"op":"mcm","clk":"11450570470","pt":1717323416635,"mc":[{"id":"1.229554928","rc":[{"atb":[[11,5.23]],"id":52671563}],"con":true,"img":false}]}
{"op":"mcm","clk":"11450570481","pt":1717323416737,"mc":[{"id":"1.229554928","rc":[{"atb":[[13.5,2.09],[8.4,14.14],[9.4,9.34]],"id":52671563}],"con":true,"img":false}]}
{"op":"mcm","clk":"11450570562","pt":1717323417419,"mc":[{"id":"1.229554928","rc":[{"atb":[[2.82,0],[2.76,8.92]],"id":52237617}],"con":true,"img":false}]}
{"op":"mcm","clk":"11450578815","pt":1717323487451,"mc":[{"id":"1.229554928","rc":[{"atb":[[6.2,0],[8.2,0]],"id":52237628},{"atb":[[5.2,0],[4.2,0]],"id":52237627},{"atb":[[5.8,0],[7.6,0]],"id":52671563},{"atb":[[17,0],[24,0]],"id":52671565},{"atb":[[6.8,0],[8.8,0]],"id":52671561},{"atb":[[150,0],[250,0]],"id":52671560},{"atb":[[11,0],[8.4,0]],"id":52671555},{"atb":[[2.36,0],[2.16,0]],"id":52237624},{"atb":[[10.5,0],[15.5,0]],"id":52237612},{"atb":[[9.2,0],[13,0]],"id":52671550},{"atb":[[550,0],[650,0]],"id":52671546},{"atb":[[2.68,0],[2.48,0]],"id":52237617},{"atb":[[3.4,0],[2.96,0]],"id":52671548},{"atb":[[16.5,0],[23,0]],"id":52671542},{"atb":[[19.5,0],[14.5,0]],"id":52671544}],"con":true,"img":false}]}
{"op":"mcm","clk":"11450579227","pt":1717323491125,"mc":[{"id":"1.229554928","rc":[{"atb":[[65,0],[36,0],[90,0],[46,0]],"id":52671544}],"con":true,"img":false}]}
{"op":"mcm","clk":"11450579240","pt":1717323491234,"mc":[{"id":"1.229554928","rc":[{"atb":[[36,0],[46,0],[23,0],[28,0]],"id":52237612},{"atb":[[70,0],[38,4.05],[95,0],[48,0]],"id":52671542}],"con":true,"img":false}]}
{"op":"mcm","clk":"11450579251","pt":1717323491329,"mc":[{"id":"1.229554928","rc":[{"atb":[[23,4.55],[30,0]],"id":52237612}],"con":true,"img":false}]}
{"op":"mcm","clk":"11450579311","pt":1717323491947,"mc":[{"id":"1.229554928","rc":[{"atb":[[36,0.75],[19,5.81],[23,8.12],[28,1.94]],"id":52237612},{"atb":[[70,0.38],[38,6.18],[48,1.11],[29,3.74]],"id":52671542},{"atb":[[70,0.38],[38,2.12],[48,1.11],[29,3.74]],"id":52671544}],"con":true,"img":false}]}
{"op":"mcm","clk":"11450579871","pt":1717323497097,"mc":[{"id":"1.229554928","rc":[{"atb":[[6.2,46.9],[8.2,14.51]],"id":52237628},{"atb":[[5.2,24.88],[4.2,76.22]],"id":52237627},{"atb":[[5.8,50.81],[7.6,15.83]],"id":52671563},{"atb":[[17,15.24],[24,4.54]],"id":52671565},{"atb":[[6.8,42.05],[8.8,13.4]],"id":52671561},{"atb":[[150,1.63],[250,0.41]],"id":52671560},{"atb":[[11,10.45],[8.4,32.96]],"id":52671555},{"atb":[[2.36,76.85],[2.16,210.26]],"id":52237624},{"atb":[[10.5,25.67],[15.5,7.2]],"id":52237612},{"atb":[[9.2,29.74],[13,8.71]],"id":52671550},{"atb":[[550,0.44],[650,0.16]],"id":52671546},{"atb":[[2.68,62.22],[2.48,164.8]],"id":52237617},{"atb":[[3.4,43.55],[2.96,124.44]],"id":52671548},{"atb":[[16.5,15.73],[23,4.75]],"id":52671542},{"atb":[[19.5,5.65],[14.5,18.06]],"id":52671544}],"con":true,"img":false}]}
{"op":"mcm","clk":"11450579941","pt":1717323497565,"mc":[{"id":"1.229554928","rc":[{"atb":[[520,0],[570,0],[420,0],[470,0]],"id":52671546}],"con":true,"img":false}]}
{"op":"mcm","clk":"11450580012","pt":1717323498243,"mc":[{"id":"1.229554928","rc":[{"atb":[[280,0.38],[330,0.24],[380,0.14],[430,0.06]],"id":52671546}],"con":true,"img":false}]}
{"op":"mcm","clk":"11450580829","pt":1717323506150,"mc":[{"id":"1.229554928","rc":[{"atb":[[23,3.57],[28,5.35]],"id":52237612}],"con":true,"img":false}]}
{"op":"mcm","clk":"11450580843","pt":1717323506260,"mc":[{"id":"1.229554928","rc":[{"atb":[[24,3.41],[28,1.94]],"id":52237612}],"con":true,"img":false}]}
{"op":"mcm","clk":"11450582326","pt":1717323520975,"mc":[{"id":"1.229554928","rc":[{"atb":[[24,0],[28,5.35]],"id":52237612}],"con":true,"img":false}]}
{"op":"mcm","clk":"11450586631","pt":1717323564239,"mc":[{"id":"1.229554928","rc":[{"atl":[[11,0],[11.5,4.37]],"id":52671548}],"con":true,"img":false}]}
{"op":"mcm","clk":"11450594235","pt":1717323641744,"mc":[{"id":"1.229554928","rc":[{"atb":[[2.7,18.7]],"id":52671563},{"atb":[[6,6.46]],"id":52671565},{"atb":[[1.8,0],[2.42,17.44]],"id":52671550},{"atb":[[3.95,17.44]],"id":52671546}],"con":true,"img":false}]}
{"op":"mcm","clk":"11450594243","pt":1717323641845,"mc":[{"id":"1.229554928","rc":[{"atb":[[3.55,0]],"id":52671563},{"atb":[[32,0]],"id":52671565},{"atb":[[1.8,0]],"id":52671546}],"con":true,"img":false}]}
{"op":"mcm","clk":"11450594260","pt":1717323642008,"mc":[{"id":"1.229554928","rc":[{"atb":[[3.75,0],[3.65,0]],"id":52671563},{"atb":[[50,0],[60,0]],"id":52671565},{"atb":[[11,0],[12,0]],"id":52671561}],"con":true,"img":false}]}
{"op":"mcm","clk":"11450595005","pt":1717323648863,"mc":[{"id":"1.229554928","rc":[{"atb":[[130,0]],"id":52671560},{"atb":[[2.8,0],[2.86,8.43]],"id":52237617},{"atb":[[4.6,0],[4.7,4.65]],"id":52671548},{"atb":[[70,0],[38,4.05],[48,0],[29,0]],"id":52671542}],"con":true,"img":false}]}
{"op":"mcm","clk":"11450595070","pt":1717323649544,"mc":[{"id":"1.229554928","rc":[{"atb":[[75,0.36],[40,2.01],[50,1.07],[30,3.61]],"id":52671542}],"con":true,"img":false}]}
{"op":"mcm","clk":"11450595100","pt":1717323649860,"mc":[{"id":"1.229554928","rc":[{"atb":[[130,3.89]],"id":52671560},{"atb":[[2.8,8.72],[2.86,0]],"id":52237617},{"atb":[[4.6,2.88],[4.7,0]],"id":52671548}],"con":true,"img":false}]}
{"op":"mcm","clk":"11450595439","pt":1717323653676,"mc":[{"id":"1.229554928","rc":[{"atb":[[130,0]],"id":52671560},{"atb":[[2.8,0],[2.86,8.43]],"id":52237617},{"atb":[[4.6,0],[4.7,4.21]],"id":52671548}],"con":true,"img":false}]}
{"op":"mcm","clk":"11450596395","pt":1717323663550,"mc":[{"id":"1.229554928","rc":[{"atb":[[2.82,8.62]],"id":52237617}],"con":true,"img":false}]}
{"op":"mcm","clk":"11450596455","pt":1717323664168,"mc":[{"id":"1.229554928","rc":[{"atl":[[11,2.81],[11.5,0]],"id":52671548}],"con":true,"img":false}]}
{"op":"mcm","clk":"11450596902","pt":1717323668405,"mc":[{"id":"1.229554928","rc":[{"atb":[[2.76,0]],"id":52237617}],"con":true,"img":false}]}
{"op":"mcm","clk":"11450600780","pt":1717323710356,"mc":[{"id":"1.229554928","rc":[{"atb":[[280,0],[330,0],[380,0],[430,0]],"id":52671546},{"atb":[[2.76,8.92]],"id":52237617},{"atb":[[4.7,0]],"id":52671548},{"atb":[[50,4.35]],"id":52671542}],"con":true,"img":false}]}
{"op":"mcm","clk":"11450600791","pt":1717323710458,"mc":[{"id":"1.229554928","rc":[{"atb":[[11,0],[12,2.8]],"id":52237628},{"atb":[[150,4.47]],"id":52671560},{"atb":[[19,0],[20,4.26]],"id":52671555},{"atb":[[2.64,31.9],[2.62,9.68]],"id":52237624},{"atb":[[36,0],[19,0],[22,0],[23,0],[26,3.4],[28,3.41]],"id":52237612},{"atb":[[2.86,0]],"id":52237617},{"atb":[[4.6,4.09]],"id":52671548},{"atb":[[38,0]],"id":52671542},{"atb":[[70,0],[34,0],[38,0],[46,3.02],[48,0],[29,0]],"id":52671544}],"con":true,"img":false}]}
{"op":"mcm","clk":"11450600797","pt":1717323710511,"mc":[{"id":"1.229554928","rc":[{"atb":[[27,3.85],[28,0]],"id":52237612}],"con":true,"img":false}]}
{"op":"mcm","clk":"11450600822","pt":1717323710832,"mc":[{"id":"1.229554928","rc":[{"atb":[[130,3.6]],"id":52671560},{"atl":[[4.5,4.68],[4.6,0]],"id":52237624},{"atb":[[2.8,8.72]],"id":52237617}],"con":true,"img":false}]}
{"op":"mcm","clk":"11450600838","pt":1717323711035,"mc":[{"id":"1.229554928","rc":[{"atb":[[280,0.38],[330,0.24],[380,0.14],[430,0.06]],"id":52671546}],"con":true,"img":false}]}
{"op":"mcm","clk":"11450600847","pt":1717323711140,"mc":[{"id":"1.229554928","rc":[{"atb":[[36,0.75],[19,5.81],[23,3.57],[28,1.94]],"id":52237612},{"atb":[[70,0.38],[38,2.12],[48,1.11],[29,3.74]],"id":52671544}],"con":true,"img":false}]}
{"op":"mcm","clk":"11450601684","pt":1717323720152,"mc":[{"id":"1.229554928","rc":[{"atb":[[11,4.09],[12,0]],"id":52237628},{"atb":[[19,3.51],[20,0]],"id":52671555},{"atb":[[22,3.67],[26,0]],"id":52237612},{"atb":[[38,4.36],[50,1.07]],"id":52671542},{"atb":[[34,3],[46,0]],"id":52671544}],"con":true,"img":false}]}
{"op":"mcm","clk":"11450601755","pt":1717323720837,"mc":[{"id":"1.229554928","rc":[{"atb":[[150,1.63],[110,4.46]],"id":52671560},{"atb":[[2.64,41.47],[2.62,0]],"id":52237624},{"atb":[[2.82,0]],"id":52237617}],"con":true,"img":false}]}
{"op":"mcm","clk":"11450602880","pt":1717323730885,"mc":[{"id":"1.229554928","rc":[{"atb":[[100,0]],"id":52671560},{"atl":[[4.5,0],[4.6,3.74]],"id":52237624}],"con":true,"img":false}]}
{"op":"mcm","clk":"11450606577","pt":1717323769735,"mc":[{"id":"1.229554928","rc":[{"atb":[[130,0]],"id":52671560},{"atb":[[2.8,0],[2.86,8.43]],"id":52237617},{"atb":[[4.6,0],[4.7,3.99]],"id":52671548}],"con":true,"img":false}]}
{"op":"mcm","clk":"11450607471","pt":1717323779748,"mc":[{"id":"1.229554928","rc":[{"atb":[[2.82,8.62]],"id":52237617}],"con":true,"img":false}]}
{"op":"mcm","clk":"11450608407","pt":1717323789755,"mc":[{"id":"1.229554928","rc":[{"atb":[[2.76,0]],"id":52237617}],"con":true,"img":false}]}
{"op":"mcm","clk":"11450614327","pt":1717323847894,"mc":[{"id":"1.229554928","rc":[{"atb":[[6.2,0],[8.2,0]],"id":52237628},{"atb":[[5.2,0],[4.2,0]],"id":52237627},{"atb":[[5.8,0],[7.6,0]],"id":52671563},{"atb":[[17,0],[24,0]],"id":52671565},{"atb":[[6.8,0],[8.8,0]],"id":52671561},{"atb":[[150,0],[250,0]],"id":52671560},{"atb":[[11,0],[8.4,0]],"id":52671555},{"atb":[[2.36,0],[2.16,0]],"id":52237624},{"atb":[[10.5,0],[15.5,0]],"id":52237612},{"atb":[[9.2,0],[13,0]],"id":52671550},{"atb":[[550,0],[650,0]],"id":52671546},{"atb":[[2.68,0],[2.48,0]],"id":52237617},{"atb":[[3.4,0],[2.96,0]],"id":52671548},{"atb":[[16.5,0],[23,0]],"id":52671542},{"atb":[[19.5,0],[14.5,0]],"id":52671544}],"con":true,"img":false}]}
{"op":"mcm","clk":"11450615075","pt":1717323854402,"mc":[{"id":"1.229554928","rc":[{"atb":[[2.6,9.8]],"id":52671550}],"con":true,"img":false}]}
{"op":"mcm","clk":"11450615090","pt":1717323854504,"mc":[{"id":"1.229554928","rc":[{"atb":[[2.82,8.62],[2.86,8.43]],"id":52671563},{"atb":[[5.8,3.78],[6,9.93]],"id":52671565},{"atb":[[5.8,3.32],[6,3.19]],"id":52671561},{"atb":[[120,4.17]],"id":52671560},{"atb":[[1.9,0]],"id":52671550},{"atb":[[4.1,5.06],[1.9,0]],"id":52671546},{"atl":[[11,0],[11.5,2.95]],"id":52671548}],"con":true,"img":false}]}
{"op":"mcm","clk":"11450616149","pt":1717323863247,"mc":[{"id":"1.229554928","rc":[{"atb":[[6.2,46.9],[8.2,14.51]],"id":52237628},{"atb":[[5.2,24.88],[4.2,76.22]],"id":52237627},{"atb":[[5.8,50.81],[7.6,15.83]],"id":52671563},{"atb":[[17,15.24],[24,4.54]],"id":52671565},{"atb":[[6.8,42.05],[8.8,13.4]],"id":52671561},{"atb":[[11,10.45],[8.4,32.96]],"id":52671555},{"atb":[[2.36,76.85],[2.16,210.26]],"id":52237624},{"atb":[[9.2,29.74],[13,8.71]],"id":52671550}],"con":true,"img":false}]}
{"op":"mcm","clk":"11450616163","pt":1717323863301,"mc":[{"id":"1.229554928","rc":[{"atb":[[150,1.63],[250,0.41]],"id":52671560},{"atb":[[10.5,25.67],[15.5,7.2]],"id":52237612},{"atb":[[550,0.44],[650,0.16]],"id":52671546},{"atb":[[2.68,62.22],[2.48,164.8]],"id":52237617},{"atb":[[3.4,43.55],[2.96,124.44]],"id":52671548},{"atb":[[16.5,15.73],[23,4.75]],"id":52671542},{"atb":[[19.5,5.65],[14.5,18.06]],"id":52671544}],"con":true,"img":false}]}
{"op":"mcm","clk":"11450616213","pt":1717323863781,"mc":[{"id":"1.229554928","rc":[{"atl":[[11,3.31],[11.5,0]],"id":52671548}],"con":true,"img":false}]}
{"op":"mcm","clk":"11450622634","pt":1717323927291,"mc":[{"id":"1.229554928","rc":[{"atl":[[15,0],[15.5,4.14]],"id":52237627},{"atl":[[32,0],[34,3.11]],"id":52671563},{"atl":[[280,0],[290,3.2]],"id":52671565},{"atl":[[34,0]],"id":52671561},{"atb":[[130,2.84],[120,0]],"id":52671560},{"atb":[[2.64,31.9]],"id":52237624},{"atb":[[21,4.34],[22,0]],"id":52237612},{"atb":[[280,0],[330,0],[380,0],[430,0]],"id":52671546},{"atb":[[2.8,8.72],[2.86,0]],"id":52237617},{"atb":[[4.8,2.97],[4.7,0]],"id":52671548}],"con":true,"img":false}]}
{"op":"mcm","clk":"11450622719","pt":1717323928117,"mc":[{"id":"1.229554928","rc":[{"atb":[[270,0.39],[320,0.25],[370,0.14],[420,0.06]],"id":52671546}],"con":true,"img":false}]}
{"op":"mcm","clk":"11450622783","pt":1717323928793,"mc":[{"id":"1.229554928","rc":[{"atl":[[15,2.63],[15.5,0]],"id":52237627},{"atl":[[34,4.22]],"id":52671561},{"atb":[[270,0],[320,0],[370,0],[420,0]],"id":52671546}],"con":true,"img":false}]}
{"op":"mcm","clk":"11450622793","pt":1717323928904,"mc":[{"id":"1.229554928","rc":[{"atl":[[32,2.97],[34,0]],"id":52671563},{"atl":[[280,2.83],[290,0]],"id":52671565},{"atb":[[2.82,0]],"id":52237617}],"con":true,"img":false}]}
{"op":"mcm","clk":"11450622807","pt":1717323929107,"mc":[{"id":"1.229554928","rc":[{"atb":[[130,0]],"id":52671560},{"atb":[[2.64,41.47]],"id":52237624},{"atb":[[21,0],[22,2.94]],"id":52237612},{"atb":[[2.86,8.43]],"id":52237617},{"atb":[[4.8,0],[4.7,4.56]],"id":52671548}],"con":true,"img":false}]}
{"op":"mcm","clk":"11450622841","pt":1717323929569,"mc":[{"id":"1.229554928","rc":[{"atb":[[290,0.36],[340,0.23],[390,0.14],[440,0.06]],"id":52671546}],"con":true,"img":false}]}
{"op":"mcm","clk":"11450622936","pt":1717323930512,"mc":[{"id":"1.229554928","rc":[{"atl":[[15,0],[15.5,2.94]],"id":52237627},{"atl":[[32,0],[34,3.76]],"id":52671563},{"atl":[[280,0],[290,3.08]],"id":52671565},{"atl":[[34,0]],"id":52671561}],"con":true,"img":false}]}
{"op":"mcm","clk":"11450622954","pt":1717323930620,"mc":[{"id":"1.229554928","rc":[{"atl":[[11,0],[11.5,3.37]],"id":52671548}],"con":true,"img":false}]}
{"op":"mcm","clk":"11450623136","pt":1717323932238,"mc":[{"id":"1.229554928","rc":[{"atl":[[15,3.76],[15.5,0]],"id":52237627},{"atl":[[32,3.26],[34,0]],"id":52671563},{"atl":[[280,3.84],[290,0]],"id":52671565},{"atl":[[34,4.66]],"id":52671561}],"con":true,"img":false}]}
{"op":"mcm","clk":"11450623311","pt":1717323934011,"mc":[{"id":"1.229554928","rc":[{"atl":[[32,0]],"id":52671563},{"atb":[[130,4.61]],"id":52671560},{"atb":[[2.64,31.9]],"id":52237624},{"atb":[[21,3.06],[22,0]],"id":52237612},{"atb":[[2.86,0]],"id":52237617},{"atb":[[4.8,3.36],[4.7,0]],"id":52671548}],"con":true,"img":false}]}
{"op":"mcm","clk":"11450623321","pt":1717323934116,"mc":[{"id":"1.229554928","rc":[{"atl":[[15,0],[15.5,3.81]],"id":52237627},{"atl":[[34,3.41]],"id":52671563},{"atl":[[34,0]],"id":52671561},{"atb":[[19,0],[19.5,4.68]],"id":52671555},{"atb":[[2.6,9.8]],"id":52237624},{"atb":[[36,0],[19,0],[23,0],[28,0]],"id":52237612},{"atb":[[2.78,8.81]],"id":52237617},{"atb":[[34,0],[36,3.67]],"id":52671544}],"con":true,"img":false}]}
{"op":"mcm","clk":"11450623336","pt":1717323934317,"mc":[{"id":"1.229554928","rc":[{"atl":[[4.5,4.11],[4.6,0]],"id":52237624},{"atb":[[22,4.76],[27,0]],"id":52237612}],"con":true,"img":false}]}
{"op":"mcm","clk":"11450623374","pt":1717323934792,"mc":[{"id":"1.229554928","rc":[{"atb":[[34,0.8],[18.5,5.98],[22,8.5],[27,2.01]],"id":52237612}],"con":true,"img":false}]}
{"op":"mcm","clk":"11450623385","pt":1717323934898,"mc":[{"id":"1.229554928","rc":[{"atb":[[22,3.74],[27,5.07]],"id":52237612}],"con":true,"img":false}]}
{"op":"mcm","clk":"11450623430","pt":1717323935415,"mc":[{"id":"1.229554928","rc":[{"atb":[[130,0]],"id":52671560},{"atb":[[19,3.88]],"id":52671555},{"atb":[[2.64,41.47],[2.6,0]],"id":52237624},{"atl":[[4.5,0],[4.6,4.11]],"id":52237624},{"atb":[[22,8.33]],"id":52237612},{"atb":[[2.8,0],[2.86,8.43]],"id":52237617},{"atb":[[4.8,0],[4.7,3.14]],"id":52671548},{"atb":[[34,4.15],[36,0]],"id":52671544}],"con":true,"img":false}]}
{"op":"mcm","clk":"11450623437","pt":1717323935515,"mc":[{"id":"1.229554928","rc":[{"atb":[[19.5,0]],"id":52671555},{"atb":[[21,0]],"id":52237612}],"con":true,"img":false}]}
{"op":"mcm","clk":"11450623476","pt":1717323936026,"mc":[{"id":"1.229554928","rc":[{"atl":[[15,3.44],[15.5,0]],"id":52237627},{"atl":[[32,2.64],[34,0]],"id":52671563},{"atl":[[34,2.94]],"id":52671561}],"con":true,"img":false}]}
{"op":"mcm","clk":"11450623723","pt":1717323938498,"mc":[{"id":"1.229554928","rc":[{"atl":[[15,0],[15.5,4.25]],"id":52237627},{"atl":[[32,0],[34,4.03]],"id":52671563},{"atl":[[34,0]],"id":52671561},{"atb":[[130,2.67]],"id":52671560},{"atb":[[19,0],[19.5,3.88]],"id":52671555},{"atb":[[2.64,31.9],[2.6,9.8]],"id":52237624},{"atb":[[21,3.87],[22,3.74]],"id":52237612},{"atb":[[2.86,0]],"id":52237617},{"atb":[[4.8,4.1],[4.7,0]],"id":52671548},{"atb":[[34,0],[36,2.89]],"id":52671544}],"con":true,"img":false}]}
{"op":"mcm","clk":"11450623738","pt":1717323938714,"mc":[{"id":"1.229554928","rc":[{"atl":[[14.5,3.81]],"id":52237627},{"atl":[[270,2.84],[280,0]],"id":52671565}],"con":true,"img":false}]}
{"op":"mcm","clk":"11450623819","pt":1717323939590,"mc":[{"id":"1.229554928","rc":[{"atl":[[16,0],[14.5,0]],"id":52237627},{"atl":[[270,0],[280,3.53]],"id":52671565},{"atb":[[130,0]],"id":52671560},{"atb":[[19.5,0],[19,3.36]],"id":52671555},{"atb":[[2.64,41.47],[2.6,0]],"id":52237624},{"atb":[[21,0],[22,7.08]],"id":52237612},{"atb":[[2.86,8.43]],"id":52237617},{"atb":[[4.8,0],[4.7,2.62]],"id":52671548},{"atb":[[34,2.96],[36,0]],"id":52671544}],"con":true,"img":false}]}
{"op":"mcm","clk":"11450623895","pt":1717323940467,"mc":[{"id":"1.229554928","rc":[{"atl":[[14.5,3.91]],"id":52237627},{"atl":[[32,4.48],[34,0]],"id":52671563},{"atl":[[270,4.59],[280,0]],"id":52671565},{"atl":[[34,3.52]],"id":52671561},{"atb":[[130,2.87]],"id":52671560},{"atb":[[19,0],[19.5,4.11]],"id":52671555},{"atb":[[2.64,31.9],[2.6,9.8]],"id":52237624},{"atb":[[21,4.02],[22,3.74]],"id":52237612},{"atb":[[2.86,0]],"id":52237617},{"atb":[[4.8,3.26],[4.7,0]],"id":52671548},{"atb":[[34,0],[36,3.15]],"id":52671544}],"con":true,"img":false}]}
{"op":"mcm","clk":"11450623949","pt":1717323940935,"mc":[{"id":"1.229554928","rc":[{"atl":[[830,2],[890,0]],"id":52671565},{"atl":[[5.8,9.08],[6.2,0]],"id":52237624},{"atb":[[2.56,64.1],[2.46,0]],"id":52237617},{"atb":[[2.88,0],[3,50]],"id":52671548}],"con":true,"img":false}]}
{"op":"mcm","clk":"11450623982","pt":1717323941208,"mc":[{"id":"1.229554928","rc":[{"atl":[[14.5,0]],"id":52237627},{"atl":[[32,0],[34,3.8]],"id":52671563},{"atl":[[270,0],[280,3.6]],"id":52671565},{"atl":[[34,0]],"id":52671561},{"atl":[[4.5,4.66],[4.6,0]],"id":52237624}],"con":true,"img":false}]}
{"op":"mcm","clk":"11450624001","pt":1717323941410,"mc":[{"id":"1.229554928","rc":[{"atl":[[11,3.84],[11.5,0]],"id":52671548}],"con":true,"img":false}]}
{"op":"mcm","clk":"11450624031","pt":1717323941823,"mc":[{"id":"1.229554928","rc":[{"atb":[[130,0]],"id":52671560},{"atb":[[19.5,0],[19,4.7]],"id":52671555},{"atb":[[2.64,41.47],[2.6,0]],"id":52237624},{"atb":[[21,0],[22,8.22]],"id":52237612},{"atb":[[2.86,8.43]],"id":52237617},{"atb":[[4.8,0],[4.7,4.48]],"id":52671548},{"atb":[[34,2.92],[36,0]],"id":52671544}],"con":true,"img":false}]}
{"op":"mcm","clk":"11450624504","pt":1717323946301,"mc":[{"id":"1.229554928","rc":[{"atl":[[840,2]],"id":52237612}],"con":true,"img":false}]}
{"op":"mcm","clk":"11450624524","pt":1717323946508,"mc":[{"id":"1.229554928","rc":[{"atl":[[830,0],[950,2]],"id":52671565}],"con":true,"img":false}]}
{"op":"mcm","clk":"11450624534","pt":1717323946608,"mc":[{"id":"1.229554928","rc":[{"atl":[[14.5,2.73]],"id":52237627},{"atl":[[32,3.52],[34,0]],"id":52671563},{"atl":[[270,4],[280,0]],"id":52671565},{"atl":[[34,4.54]],"id":52671561},{"atb":[[130,3.32]],"id":52671560},{"atb":[[19,0],[19.5,2.77]],"id":52671555},{"atb":[[2.64,31.9],[2.6,9.8]],"id":52237624},{"atl":[[4.5,0],[4.6,4.14]],"id":52237624},{"atb":[[21,2.79],[22,3.74]],"id":52237612},{"atl":[[100,0],[110,4.45]],"id":52671550},{"atb":[[2.86,0]],"id":52237617},{"atb":[[4.8,3.51],[4.7,0]],"id":52671548},{"atl":[[530,4.08]],"id":52671542},{"atb":[[34,0],[36,3.65]],"id":52671544}],"con":true,"img":false}]}
{"op":"mcm","clk":"11450624543","pt":1717323946718,"mc":[{"id":"1.229554928","rc":[{"atl":[[36,4.45],[40,0]],"id":52237628},{"atl":[[270,0],[210,3.02]],"id":52237612},{"atl":[[6,3.25],[5.7,0]],"id":52237617},{"atl":[[620,0]],"id":52671542},{"atl":[[340,4.09],[440,0]],"id":52671544}],"con":true,"img":false}]}
{"op":"mcm","clk":"11450624552","pt":1717323946819,"mc":[{"id":"1.229554928","rc":[{"atl":[[38,3.76]],"id":52237628},{"atb":[[6.8,4.08],[7,0]],"id":52237627},{"atb":[[11,0],[13.5,0],[8.4,0],[9.4,0]],"id":52671563},{"atl":[[200,3.34]],"id":52237612},{"atl":[[5.8,2.96]],"id":52237617},{"atl":[[520,4.68]],"id":52671542},{"atl":[[350,3.83]],"id":52671544}],"con":true,"img":false}]}
{"op":"mcm","clk":"11450624598","pt":1717323947538,"mc":[{"id":"1.229554928","rc":[{"atb":[[9.6,9.12],[8.6,13.77],[11.5,4.98],[14,2.01]],"id":52671563}],"con":true,"img":false}]}
{"op":"mcm","clk":"11450624650","pt":1717323948112,"mc":[{"id":"1.229554928","rc":[{"atl":[[36,0],[44,0]],"id":52237628},{"atl":[[14.5,0]],"id":52237627},{"atl":[[32,0],[34,3.36]],"id":52671563},{"atl":[[270,0],[280,4.58]],"id":52671565},{"atl":[[34,0]],"id":52671561},{"atb":[[130,0]],"id":52671560},{"atb":[[19.5,0],[19,4.43]],"id":52671555},{"atb":[[2.64,41.47],[2.6,0]],"id":52237624},{"atb":[[21,0],[22,6.75]],"id":52237612},{"atl":[[290,0],[210,0]],"id":52237612},{"atb":[[2.86,8.43]],"id":52237617},{"atl":[[6,0],[5.9,0]],"id":52237617},{"atb":[[4.8,0],[4.7,4.59]],"id":52671548},{"atl":[[530,0],[640,0]],"id":52671542},{"atb":[[34,2.81],[36,0]],"id":52671544},{"atl":[[340,0],[460,0]],"id":52671544}],"con":true,"img":false}]}
{"op":"mcm","clk":"11450624658","pt":1717323948211,"mc":[{"id":"1.229554928","rc":[{"atl":[[15,3.48]],"id":52237627}],"con":true,"img":false}]}
{"op":"mcm","clk":"11450624825","pt":1717323950300,"mc":[{"id":"1.229554928","rc":[{"atl":[[14.5,3.17],[15,0]],"id":52237627},{"atl":[[32,3.91],[34,0]],"id":52671563},{"atl":[[270,3.06],[280,0]],"id":52671565},{"atl":[[34,3.35]],"id":52671561},{"atb":[[130,3.14]],"id":52671560},{"atb":[[19,0],[19.5,4.18]],"id":52671555},{"atb":[[2.64,31.9],[2.6,9.8]],"id":52237624},{"atb":[[21,3.24],[22,3.74]],"id":52237612},{"atb":[[2.86,0]],"id":52237617},{"atb":[[4.8,4.41],[4.7,0]],"id":52671548},{"atb":[[34,0],[36,4.37]],"id":52671544}],"con":true,"img":false}]}
{"op":"mcm","clk":"11450624897","pt":1717323951188,"mc":[{"id":"1.229554928","rc":[{"atl":[[5.8,0],[5.4,9.08]],"id":52237624}],"con":true,"img":false}]}
{"op":"mcm","clk":"11450625088","pt":1717323953322,"mc":[{"id":"1.229554928","rc":[{"atb":[[130,0]],"id":52671560},{"atb":[[19.5,0],[19,4.63]],"id":52671555},{"atb":[[2.64,41.47],[2.6,0]],"id":52237624},{"atb":[[21,0],[22,6.49]],"id":52237612},{"atb":[[2.86,8.43]],"id":52237617},{"atb":[[4.8,0],[4.7,4.25]],"id":52671548},{"atb":[[34,3],[36,0]],"id":52671544}],"con":true,"img":false}]}
{"op":"mcm","clk":"11450625382","pt":1717323956901,"mc":[{"id":"1.229554928","rc":[{"atl":[[42,4.63]],"id":52237628},{"atl":[[540,4.22]],"id":52671542}],"con":true,"img":false}]}
{"op":"mcm","clk":"11450625668","pt":1717323960328,"mc":[{"id":"1.229554928","rc":[{"atl":[[16.5,4.03],[14.5,0]],"id":52237627},{"atl":[[32,0],[34,3.39]],"id":52671563},{"atl":[[270,0],[280,3.34]],"id":52671565},{"atl":[[34,0],[42,2.87]],"id":52671561},{"atb":[[130,4.31]],"id":52671560}],"con":true,"img":false}]}
{"op":"mcm","clk":"11450625706","pt":1717323960741,"mc":[{"id":"1.229554928","rc":[{"atb":[[19.5,3.96]],"id":52671555}],"con":true,"img":false}]}
{"op":"mcm","clk":"11450625720","pt":1717323960847,"mc":[{"id":"1.229554928","rc":[{"atb":[[19,0]],"id":52671555},{"atb":[[2.64,31.9],[2.6,9.8]],"id":52237624},{"atl":[[4.5,2.99],[4.6,0]],"id":52237624},{"atb":[[21,2.83],[22,3.74]],"id":52237612},{"atb":[[2.86,0]],"id":52237617},{"atb":[[4.8,2.85],[4.7,0]],"id":52671548},{"atb":[[34,0],[36,3.56]],"id":52671544}],"con":true,"img":false}]}
{"op":"mcm","clk":"11450625936","pt":1717323963348,"mc":[{"id":"1.229554928","rc":[{"atb":[[2.74,9.01]],"id":52237617},{"atl":[[6,3.19]],"id":52237617}],"con":true,"img":false}]}
{"op":"mcm","clk":"11450626009","pt":1717323964243,"mc":[{"id":"1.229554928","rc":[{"atb":[[2.64,41.47],[2.6,0]],"id":52237624},{"atb":[[4.8,0],[4.9,18.03]],"id":52671548}],"con":true,"img":false}]}
{"op":"mcm","clk":"11450626508","pt":1717323970331,"mc":[{"id":"1.229554928","rc":[{"atl":[[15,4.43],[15.5,0]],"id":52237627},{"atl":[[32,2.85],[34,0]],"id":52671563},{"atl":[[36,3.63],[38,0]],"id":52671561}],"con":true,"img":false}]}
{"op":"mcm","clk":"11450626574","pt":1717323970852,"mc":[{"id":"1.229554928","rc":[{"atl":[[220,4.32]],"id":52237612},{"atl":[[370,3.95]],"id":52671544}],"con":true,"img":false}]}
{"op":"mcm","clk":"11450626657","pt":1717323971638,"mc":[{"id":"1.229554928","rc":[{"atl":[[4.5,0],[4.6,4.35]],"id":52237624}],"con":true,"img":false}]}
{"op":"mcm","clk":"11450626665","pt":1717323971740,"mc":[{"id":"1.229554928","rc":[{"atb":[[6.2,0],[8.2,0]],"id":52237628},{"atb":[[5.2,0],[4.2,0]],"id":52237627},{"atb":[[5.8,0],[7.6,0]],"id":52671563},{"atb":[[17,0],[24,0]],"id":52671565},{"atb":[[6.8,0],[8.8,0]],"id":52671561},{"atb":[[150,0],[250,0]],"id":52671560},{"atb":[[11,0],[8.4,0]],"id":52671555},{"atb":[[2.36,0],[2.16,0]],"id":52237624},{"atb":[[10.5,0],[15.5,0]],"id":52237612},{"atb":[[9.2,0],[13,0]],"id":52671550},{"atb":[[550,0],[650,0]],"id":52671546},{"atb":[[2.68,0],[2.48,0]],"id":52237617},{"atb":[[3.4,0],[2.96,0]],"id":52671548},{"atb":[[16.5,0],[23,0]],"id":52671542},{"atb":[[19.5,0],[14.5,0]],"id":52671544}],"con":true,"img":false}]}
{"op":"mcm","clk":"11450626709","pt":1717323972220,"mc":[{"id":"1.229554928","rc":[{"atl":[[11,0],[11.5,3.94]],"id":52671548}],"con":true,"img":false}]}
{"op":"mcm","clk":"11450626888","pt":1717323973968,"mc":[{"id":"1.229554928","rc":[{"atl":[[15,0],[15.5,4]],"id":52237627},{"atl":[[32,0],[34,4.65]],"id":52671563},{"atl":[[36,0],[38,4.08]],"id":52671561},{"atl":[[4.5,3.19],[4.6,0]],"id":52237624}],"con":true,"img":false}]}
{"op":"mcm","clk":"11450626896","pt":1717323974071,"mc":[{"id":"1.229554928","rc":[{"atl":[[11,4]],"id":52671548}],"con":true,"img":false}]}
{"op":"mcm","clk":"11450626907","pt":1717323974176,"mc":[{"id":"1.229554928","rc":[{"atl":[[11.5,0]],"id":52671548}],"con":true,"img":false}]}
{"op":"mcm","clk":"11450626978","pt":1717323974858,"mc":[{"id":"1.229554928","rc":[{"atl":[[12,0]],"id":52671548}],"con":true,"img":false}]}
{"op":"mcm","clk":"11450627059","pt":1717323975742,"mc":[{"id":"1.229554928","rc":[{"atl":[[34,0]],"id":52671563},{"atl":[[280,0]],"id":52671565},{"atl":[[65,0],[70,3.99]],"id":52671555},{"atb":[[2.64,31.9]],"id":52237624},{"atl":[[4.5,0],[4.6,3.59]],"id":52237624},{"atb":[[2.78,0],[2.76,8.92]],"id":52237617},{"atb":[[4.8,3.79],[4.9,13.41]],"id":52671548}],"con":true,"img":false}]}
{"op":"mcm","clk":"11450627112","pt":1717323976157,"mc":[{"id":"1.229554928","rc":[{"atl":[[38,0],[40,4.11]],"id":52671561}],"con":true,"img":false}]}
{"op":"mcm","clk":"11450627286","pt":1717323978035,"mc":[{"id":"1.229554928","rc":[{"atl":[[300,0],[310,3.01]],"id":52671565},{"atl":[[65,4.53],[70,0]],"id":52671555}],"con":true,"img":false}]}
{"op":"mcm","clk":"11450627402","pt":1717323979135,"mc":[{"id":"1.229554928","rc":[{"atb":[[80,0],[42,0],[110,0],[55,0]],"id":52671565},{"atb":[[2.56,10.06],[2.58,0]],"id":52237624},{"atb":[[2.76,0]],"id":52237617},{"atb":[[34,3.37],[36,0]],"id":52671544}],"con":true,"img":false}]}
{"op":"mcm","clk":"11450627470","pt":1717323979871,"mc":[{"id":"1.229554928","rc":[{"atb":[[85,0.62],[44,2.43],[120,0.22],[60,1.33]],"id":52671565}],"con":true,"img":false}]}
{"op":"mcm","clk":"11450627565","pt":1717323981077,"mc":[{"id":"1.229554928","rc":[{"atb":[[6.2,46.9],[8.2,14.51]],"id":52237628},{"atb":[[5.2,24.88],[4.2,76.22]],"id":52237627},{"atb":[[5.8,50.81],[7.6,15.83]],"id":52671563},{"atb":[[17.5,14.77],[25,4.35]],"id":52671565},{"atb":[[9,13.06],[7,40.65]],"id":52671561},{"atb":[[170,0.61],[85,2.9]],"id":52671560},{"atb":[[8.6,32.09],[11.5,9.95]],"id":52671555},{"atb":[[2.14,213.95],[2.34,78]],"id":52237624},{"atb":[[9.8,27.71],[14.5,7.74]],"id":52237612},{"atb":[[13.5,8.36],[9.4,29.03]],"id":52671550},{"atb":[[550,0.44],[650,0.16]],"id":52671546},{"atb":[[2.46,167.06],[2.66,62.96]],"id":52237617},{"atb":[[3.45,42.66],[2.98,123.18]],"id":52671548},{"atb":[[20,5.5],[15,17.42]],"id":52671542},{"atb":[[18.5,5.97],[13.5,19.51]],"id":52671544}],"con":true,"img":false}]}
{"op":"mcm","clk":"11450627602","pt":1717323981441,"mc":[{"id":"1.229554928","rc":[{"atl":[[4.6,0],[4.4,2.96]],"id":52237624}],"con":true,"img":false}]}
{"op":"mcm","clk":"11450627845","pt":1717323984058,"mc":[{"id":"1.229554928","rc":[{"atl":[[40,3.75]],"id":52671563}],"con":true,"img":false}]}
{"op":"mcm","clk":"11450627942","pt":1717323985259,"mc":[{"id":"1.229554928","rc":[{"atl":[[65,0],[70,4.41]],"id":52671555},{"atb":[[2.58,9.93]],"id":52237624},{"atl":[[4.5,3.85],[4.4,0]],"id":52237624},{"atb":[[2.76,8.92]],"id":52237617},{"atb":[[34,0],[36,3.88]],"id":52671544}],"con":true,"img":false}]}
{"op":"mcm","clk":"11450627978","pt":1717323985773,"mc":[{"id":"1.229554928","rc":[{"atb":[[4.6,4.08]],"id":52671548},{"atl":[[12,4.34]],"id":52671548}],"con":true,"img":false}]}
{"op":"mcm","clk":"11450628178","pt":1717323988059,"mc":[{"id":"1.229554928","rc":[{"atl":[[300,4.69]],"id":52671565}],"con":true,"img":false}]}
{"op":"mcm","clk":"11450628605","pt":1717323992897,"mc":[{"id":"1.229554928","rc":[{"atl":[[300,0]],"id":52671565},{"atl":[[65,4.41],[70,0]],"id":52671555},{"atb":[[2.58,0]],"id":52237624},{"atl":[[4.5,0],[4.4,3.87]],"id":52237624},{"atb":[[2.76,0]],"id":52237617},{"atb":[[4.4,23.08]],"id":52671548},{"atb":[[34,4.46],[36,0]],"id":52671544}],"con":true,"img":false}]}
{"op":"mcm","clk":"11450628762","pt":1717323994474,"mc":[{"id":"1.229554928","rc":[{"atl":[[4.6,4.34],[4.4,0]],"id":52237624}],"con":true,"img":false}]}
{"op":"mcm","clk":"11450628829","pt":1717323995259,"mc":[{"id":"1.229554928","rc":[{"atb":[[2.7,9.23]],"id":52237617}],"con":true,"img":false}]}
{"op":"mcm","clk":"11450629075","pt":1717323998095,"mc":[{"id":"1.229554928","rc":[{"atl":[[330,4.29]],"id":52671565}],"con":true,"img":false}]}
{"op":"mcm","clk":"11450629180","pt":1717323999193,"mc":[{"id":"1.229554928","rc":[{"atb":[[10.5,2.66],[11,0]],"id":52237628},{"atb":[[19.5,0],[19,3.27]],"id":52671555},{"atb":[[2.6,9.8]],"id":52237624},{"atb":[[21,0]],"id":52237612},{"atb":[[2.82,8.62],[2.74,0]],"id":52237617},{"atb":[[4.8,0],[4.9,17.98]],"id":52671548}],"con":true,"img":false}]}
{"op":"mcm","clk":"11450629226","pt":1717323999813,"mc":[{"id":"1.229554928","rc":[{"atb":[[6.2,0],[8.2,0]],"id":52237628},{"atb":[[5.2,0],[4.2,0]],"id":52237627},{"atb":[[5.8,0],[7.6,0]],"id":52671563},{"atb":[[17.5,0],[25,0]],"id":52671565},{"atb":[[9,0],[7,0]],"id":52671561},{"atb":[[170,0],[85,0]],"id":52671560},{"atb":[[8.6,0],[11.5,0]],"id":52671555},{"atb":[[2.14,0],[2.34,0]],"id":52237624},{"atb":[[9.8,0],[14.5,0]],"id":52237612},{"atb":[[13.5,0],[9.4,0]],"id":52671550},{"atb":[[550,0],[650,0]],"id":52671546},{"atb":[[2.46,0],[2.66,0]],"id":52237617},{"atb":[[3.45,0],[2.98,0]],"id":52671548},{"atb":[[20,0],[15,0]],"id":52671542},{"atb":[[18.5,0],[13.5,0]],"id":52671544}],"con":true,"img":false}]}
{"op":"mcm","clk":"11450629249","pt":1717324000084,"mc":[{"id":"1.229554928","rc":[{"atb":[[10.5,0],[11,4.3]],"id":52237628},{"atb":[[19,0],[19.5,3.42]],"id":52671555},{"atb":[[2.6,0]],"id":52237624},{"atb":[[21,4.65]],"id":52237612},{"atb":[[2.74,9.01]],"id":52237617},{"atb":[[4.8,4.37],[4.9,13.41]],"id":52671548}],"con":true,"img":false}]}
{"op":"mcm","clk":"11450629257","pt":1717324000184,"mc":[{"id":"1.229554928","rc":[{"atb":[[2.82,0]],"id":52237617}],"con":true,"img":false}]}
{"op":"mcm","clk":"11450629735","pt":1717324004825,"mc":[{"id":"1.229554928","rc":[{"atb":[[6.2,46.9],[8.2,14.51]],"id":52237628},{"atb":[[5.1,51.02],[4.1,78.68]],"id":52237627},{"atb":[[7.8,15.37],[5.9,49.77]],"id":52671563},{"atb":[[17.5,14.77],[25,4.35]],"id":52671565},{"atb":[[6.8,42.05],[8.8,13.4]],"id":52671561},{"atb":[[160,0.65],[80,3.08]],"id":52671560},{"atb":[[8.6,32.09],[11.5,9.95]],"id":52671555},{"atb":[[2.36,76.85],[2.16,210.26]],"id":52237624},{"atb":[[9.8,27.71],[14.5,7.74]],"id":52237612},{"atb":[[13.5,8.36],[9.4,29.03]],"id":52671550},{"atb":[[540,0.44],[640,0.16]],"id":52671546},{"atb":[[2.64,79.69],[2.44,223.88]],"id":52237617},{"atb":[[3,171.95],[3.5,41.81]],"id":52671548},{"atb":[[20,5.5],[15,17.42]],"id":52671542},{"atb":[[18.5,5.97],[13.5,19.51]],"id":52671544}],"con":true,"img":false}]}
{"op":"mcm","clk":"11450630136","pt":1717324009195,"mc":[{"id":"1.229554928","rc":[{"atb":[[2.52,10.32]],"id":52237624}],"con":true,"img":false}]}
{"op":"mcm","clk":"11450630157","pt":1717324009503,"mc":[{"id":"1.229554928","rc":[{"atl":[[11,0],[11.5,2.77]],"id":52671548}],"con":true,"img":false}]}
{"op":"mcm","clk":"11450630221","pt":1717324010294,"mc":[{"id":"1.229554928","rc":[{"atl":[[11,4.02],[11.5,0]],"id":52671548}],"con":true,"img":false}]}
{"op":"mcm","clk":"11450630317","pt":1717324011399,"mc":[{"id":"1.229554928","rc":[{"atl":[[11,0],[11.5,3.58]],"id":52671548}],"con":true,"img":false}]}
{"op":"mcm","clk":"11450630596","pt":1717324014727,"mc":[{"id":"1.229554928","rc":[{"atl":[[11,3.91],[11.5,0]],"id":52671548}],"con":true,"img":false}]}
{"op":"mcm","clk":"11450632034","pt":1717324030943,"mc":[{"id":"1.229554928","rc":[{"atl":[[11,0],[11.5,3.5]],"id":52671548}],"con":true,"img":false}]}
{"op":"mcm","clk":"11450632529","pt":1717324037414,"mc":[{"id":"1.229554928","rc":[{"atl":[[11,3.44],[11.5,0]],"id":52671548}],"con":true,"img":false}]}
{"op":"mcm","clk":"11450635066","pt":1717324066519,"mc":[{"id":"1.229554928","rc":[{"atl":[[950,0]],"id":52671565},{"atb":[[1.97,0],[1.91,101.92]],"id":52237624},{"atb":[[2.56,0],[2.48,67.57]],"id":52237617}],"con":true,"img":false}]}
{"op":"mcm","clk":"11450636998","pt":1717324088149,"mc":[{"id":"1.229554928","rc":[{"atb":[[6.2,0],[8.2,0]],"id":52237628},{"atb":[[5.1,25.52],[4.1,0]],"id":52237627},{"atb":[[7.8,0],[5.9,0]],"id":52671563},{"atb":[[17.5,0],[25,0]],"id":52671565},{"atb":[[6.8,0],[8.8,0]],"id":52671561},{"atb":[[160,0],[80,0]],"id":52671560},{"atb":[[8.6,0],[11.5,0]],"id":52671555},{"atb":[[2.36,0],[2.16,0]],"id":52237624},{"atb":[[9.8,0],[14.5,0]],"id":52237612},{"atb":[[13.5,0],[9.4,0]],"id":52671550},{"atb":[[540,0],[640,0]],"id":52671546},{"atb":[[2.64,15.95],[2.44,54.5]],"id":52237617},{"atb":[[3,50],[3.5,0]],"id":52671548},{"atb":[[20,0],[15,0]],"id":52671542},{"atb":[[18.5,0],[13.5,0]],"id":52671544}],"con":true,"img":false}]}
{"op":"mcm","clk":"11450637329","pt":1717324092258,"mc":[{"id":"1.229554928","rc":[{"atl":[[11.5,3.31]],"id":52671548}],"con":true,"img":false}]}
{"op":"mcm","clk":"11450637336","pt":1717324092361,"mc":[{"id":"1.229554928","rc":[{"atl":[[11,0]],"id":52671548}],"con":true,"img":false}]}
{"op":"mcm","clk":"11450637419","pt":1717324093292,"mc":[{"id":"1.229554928","rc":[{"atl":[[11,2.65],[11.5,0]],"id":52671548}],"con":true,"img":false}]}
{"op":"mcm","clk":"11450637502","pt":1717324094082,"mc":[{"id":"1.229554928","rc":[{"atb":[[6.2,46.9],[8.2,14.51]],"id":52237628},{"atb":[[5.1,51.02],[4.1,78.68]],"id":52237627},{"atb":[[7.8,15.37],[5.9,49.77]],"id":52671563},{"atb":[[17.5,14.77],[25,4.35]],"id":52671565},{"atb":[[6.8,42.05],[8.8,13.4]],"id":52671561},{"atb":[[160,0.65],[80,3.08]],"id":52671560},{"atb":[[8.6,32.09],[11.5,9.95]],"id":52671555},{"atb":[[2.36,76.85],[2.16,210.26]],"id":52237624},{"atb":[[9.8,27.71],[14.5,7.74]],"id":52237612},{"atb":[[13.5,8.36],[9.4,29.03]],"id":52671550},{"atb":[[540,0.44],[640,0.16]],"id":52671546},{"atb":[[2.64,79.69],[2.44,223.88]],"id":52237617},{"atb":[[3,171.95],[3.5,41.81]],"id":52671548},{"atb":[[20,5.5],[15,17.42]],"id":52671542},{"atb":[[18.5,5.97],[13.5,19.51]],"id":52671544}],"con":true,"img":false}]}
{"op":"mcm","clk":"11450637536","pt":1717324094454,"mc":[{"id":"1.229554928","rc":[{"atl":[[11,0],[11.5,2.71]],"id":52671548}],"con":true,"img":false}]}
{"op":"mcm","clk":"11450637828","pt":1717324097779,"mc":[{"id":"1.229554928","rc":[{"atl":[[11,3.86],[11.5,0]],"id":52671548}],"con":true,"img":false}]}
{"op":"mcm","clk":"11450637903","pt":1717324098669,"mc":[{"id":"1.229554928","rc":[{"atl":[[11,0],[11.5,3.33]],"id":52671548}],"con":true,"img":false}]}
{"op":"mcm","clk":"11450647193","pt":1717324197239,"mc":[{"id":"1.229554928","rc":[{"atb":[[3.05,22.91],[2.7,0]],"id":52671563},{"atb":[[9.2,6.86],[6,3.47]],"id":52671565},{"atl":[[5.4,0],[15.5,6.9]],"id":52237624},{"atb":[[2.42,0],[3.65,17.44]],"id":52671550},{"atb":[[3.95,0],[6.2,17.44]],"id":52671546},{"atl":[[11.5,0],[15.5,6.4]],"id":52237617}],"con":true,"img":false}]}
{"op":"mcm","clk":"11450647220","pt":1717324197495,"mc":[{"id":"1.229554928","rc":[{"atb":[[5.8,0],[6,0]],"id":52671561},{"atl":[[4.6,0],[4.7,0],[15.5,10.38]],"id":52237624},{"atl":[[5.8,0],[6,0],[15.5,10.33]],"id":52237617},{"atl":[[11.5,0],[12,0],[15.5,2.74]],"id":52671548}],"con":true,"img":false}]}
{"op":"mcm","clk":"11450647232","pt":1717324197599,"mc":[{"id":"1.229554928","rc":[{"atl":[[21,5]],"id":52671548}],"con":true,"img":false}]}
{"op":"mcm","clk":"11450647240","pt":1717324197713,"mc":[{"id":"1.229554928","rc":[{"atl":[[18.5,0]],"id":52671548}],"con":true,"img":false}]}
{"op":"mcm","clk":"11450647675","pt":1717324201634,"mc":[{"id":"1.229554928","rc":[{"atb":[[6.2,0],[8.2,0]],"id":52237628},{"atb":[[5.1,25.52],[4.1,0]],"id":52237627},{"atb":[[7.8,0],[5.9,0]],"id":52671563},{"atb":[[17.5,0],[25,0]],"id":52671565},{"atb":[[6.8,0],[8.8,0]],"id":52671561},{"atb":[[160,0],[80,0]],"id":52671560},{"atb":[[8.6,0],[11.5,0]],"id":52671555},{"atb":[[2.36,0],[2.16,0]],"id":52237624},{"atb":[[9.8,0],[14.5,0]],"id":52237612},{"atb":[[13.5,0],[9.4,0]],"id":52671550},{"atb":[[540,0],[640,0]],"id":52671546},{"atb":[[2.64,15.95],[2.44,54.5]],"id":52237617},{"atb":[[3,50],[3.5,0]],"id":52671548},{"atb":[[20,0],[15,0]],"id":52671542},{"atb":[[18.5,0],[13.5,0]],"id":52671544}],"con":true,"img":false}]}
{"op":"mcm","clk":"11450647897","pt":1717324203248,"mc":[{"id":"1.229554928","rc":[{"atb":[[3.2,7.13],[2.86,0]],"id":52671563},{"atb":[[9,3.58],[6,0]],"id":52671565},{"atb":[[5.2,4.32],[5.4,4.35]],"id":52671561},{"atb":[[3.85,5.5],[2.6,0]],"id":52671550},{"atb":[[6.2,21.99],[4.1,0]],"id":52671546}],"con":true,"img":false}]}
{"op":"mcm","clk":"11450648343","pt":1717324207540,"mc":[{"id":"1.229554928","rc":[{"atl":[[16.5,4.38]],"id":52237624},{"atl":[[16.5,4.48]],"id":52237617},{"atl":[[16.5,4.41]],"id":52671548}],"con":true,"img":false}]}
{"op":"mcm","clk":"11450648483","pt":1717324208859,"mc":[{"id":"1.229554928","rc":[{"atb":[[6.2,46.9],[8.2,14.51]],"id":52237628},{"atb":[[5.1,51.02],[4.1,78.68]],"id":52237627},{"atb":[[7.8,15.37],[5.9,49.77]],"id":52671563},{"atb":[[17.5,14.77],[25,4.35]],"id":52671565},{"atb":[[6.8,42.05],[8.8,13.4]],"id":52671561},{"atb":[[8.6,32.09],[11.5,9.95]],"id":52671555},{"atb":[[2.36,76.85],[2.16,210.26]],"id":52237624},{"atb":[[13.5,8.36],[9.4,29.03]],"id":52671550}],"con":true,"img":false}]}
{"op":"mcm","clk":"11450648497","pt":1717324208959,"mc":[{"id":"1.229554928","rc":[{"atb":[[160,0.65],[80,3.08]],"id":52671560},{"atb":[[9.8,27.71],[14.5,7.74]],"id":52237612},{"atb":[[540,0.44],[640,0.16]],"id":52671546},{"atb":[[2.64,79.69],[2.44,223.88]],"id":52237617},{"atb":[[3,171.95],[3.5,41.81]],"id":52671548},{"atb":[[20,5.5],[15,17.42]],"id":52671542},{"atb":[[18.5,5.97],[13.5,19.51]],"id":52671544}],"con":true,"img":false}]}
{"op":"mcm","clk":"11450654245","pt":1717324264298,"mc":[{"id":"1.229554928","rc":[{"atb":[[7.2,16.29],[7,5]],"id":52237627},{"atl":[[10,5],[15,11.44]],"id":52237627},{"atb":[[10,5]],"id":52671563},{"atl":[[34,4.85],[29,5]],"id":52671563},{"atb":[[100,5]],"id":52671565},{"atl":[[220,5]],"id":52671565},{"atb":[[16.5,5]],"id":52671561},{"atl":[[38,4.33],[30,5]],"id":52671561},{"atb":[[160,5.66],[250,0.64]],"id":52671560},{"atl":[[1000,0.02]],"id":52671560},{"atb":[[2.74,46.22],[2.68,5]],"id":52237624},{"atl":[[3.6,5],[15,11.44]],"id":52237624},{"atb":[[29,5]],"id":52237612},{"atl":[[210,5]],"id":52237612},{"atb":[[36,4.57],[48,5]],"id":52671550},{"atl":[[110,10.92]],"id":52671550},{"atb":[[3.65,5]],"id":52237617},{"atl":[[5.6,5]],"id":52237617},{"atb":[[5.7,5],[5.4,20.09]],"id":52671548},{"atl":[[10.5,5],[15,11.44]],"id":52671548},{"atb":[[80,2.02],[90,5]],"id":52671542},{"atl":[[520,4.99]],"id":52671542},{"atb":[[75,2.16],[90,5]],"id":52671544},{"atl":[[350,4.29]],"id":52671544}],"con":true,"img":false}]}
{"op":"mcm","clk":"11450654255","pt":1717324264391,"mc":[{"id":"1.229554928","rc":[{"atb":[[15.5,16.05]],"id":52237628},{"atl":[[38,13.1]],"id":52237628},{"atb":[[120,1.56]],"id":52671565},{"atl":[[300,0.53]],"id":52671565},{"atb":[[32,5],[34,5.65]],"id":52671555},{"atl":[[65,6.91],[70,5]],"id":52671555},{"atl":[[200,4.15]],"id":52237612},{"atb":[[2.74,36.74]],"id":52237617},{"atl":[[15,11.44]],"id":52237617}],"con":true,"img":false}]}
{"op":"mcm","clk":"11450654365","pt":1717324265383,"mc":[{"id":"1.229554928","rc":[{"atl":[[870,2]],"id":52671565},{"atb":[[27,2.01],[29,8.57]],"id":52237612},{"atl":[[760,2],[840,0]],"id":52237612},{"atl":[[18,5.88],[21,0]],"id":52671548}],"con":true,"img":false}]}
{"op":"mcm","clk":"11450654448","pt":1717324266117,"mc":[{"id":"1.229554928","rc":[{"atb":[[4,26.16],[6,0]],"id":52237628},{"atl":[[40,2.56],[180,0]],"id":52237628},{"atb":[[3.6,34.14],[3.25,0]],"id":52237627},{"atl":[[17.5,6.06],[28,0]],"id":52237627},{"atl":[[95,2],[60,0]],"id":52671563},{"atl":[[430,2],[870,0]],"id":52671565},{"atb":[[38,0],[50,2.04]],"id":52671560},{"atb":[[7.8,0],[9.4,11.9]],"id":52671555},{"atl":[[330,0],[190,2]],"id":52671555},{"atb":[[2.04,96.15],[1.91,0]],"id":52237624},{"atb":[[21,9.65],[29,5]],"id":52237612},{"atl":[[550,2],[760,0]],"id":52237612},{"atl":[[530,0],[200,2]],"id":52671550},{"atb":[[2.66,60.24],[2.48,0]],"id":52237617},{"atb":[[3,121.95],[4.2,31.25]],"id":52671548},{"atl":[[34,3.03],[18,0]],"id":52671548},{"atb":[[32,0],[48,2.13]],"id":52671542},{"atb":[[32,0],[46,2.22]],"id":52671544}],"con":true,"img":false}]}
{"op":"mcm","clk":"11450654461","pt":1717324266270,"mc":[{"id":"1.229554928","rc":[{"atl":[[350,2],[430,0]],"id":52671565},{"atb":[[85,5],[90,0]],"id":52671544}],"con":true,"img":false}]}
{"op":"mcm","clk":"11450654476","pt":1717324266381,"mc":[{"id":"1.229554928","rc":[{"atb":[[9,0],[10,3.51],[11,0],[12.5,0],[15,0],[15.5,0],[9.4,2.83]],"id":52237628},{"atl":[[38,9.33],[28,2.76]],"id":52237628},{"atb":[[5.6,0],[7.2,0],[5.1,25.49],[6.2,0],[6.8,0],[7,0],[5.9,4.29]],"id":52237627},{"atb":[[9.6,0],[8.6,0],[11.5,0],[14,12.32]],"id":52671563},{"atb":[[85,0],[44,0],[100,0],[120,0],[60,0]],"id":52671565},{"atb":[[17.5,11.3]],"id":52671561},{"atl":[[40,9.12],[30,0]],"id":52671561},{"atl":[[1000,0]],"id":52671560},{"atb":[[32,0],[34,0],[18.5,0],[22,0],[26,5],[27,0]],"id":52671555},{"atl":[[3.6,0],[3.85,5]],"id":52237624},{"atl":[[150,3.2],[200,0.8]],"id":52237612},{"atb":[[36,0],[48,0]],"id":52671550},{"atl":[[75,4.13],[110,6.47]],"id":52671550},{"atl":[[10.5,0],[14.5,5]],"id":52671548},{"atl":[[520,0.3],[610,4.63]],"id":52671542},{"atl":[[350,0],[370,0],[490,2.97]],"id":52671544}],"con":true,"img":false}]}
{"op":"mcm","clk":"11450654518","pt":1717324266895,"mc":[{"id":"1.229554928","rc":[{"atb":[[9.4,7.84]],"id":52237628},{"atb":[[6,5]],"id":52237627},{"atb":[[44,5]],"id":52671565},{"atb":[[25,5]],"id":52671550}],"con":true,"img":false}]}
{"op":"mcm","clk":"11450654529","pt":1717324267106,"mc":[{"id":"1.229554928","rc":[{"atb":[[8,14.95],[9,9.81],[10,9.32],[12.5,2.28],[9.4,11.68]],"id":52237628},{"atb":[[5,26.16],[5.5,17.44],[6,15.47],[7,4.36],[4.2,6.02]],"id":52237627},{"atb":[[16,3.49],[18.5,1.5],[11,10.46],[13.5,6.28]],"id":52671563},{"atb":[[34,3.17],[18,0.92],[85,0.31],[44,6.83],[60,0.88]],"id":52671565},{"atb":[[32,0.84],[18,8.77],[21,3.92],[12,5.78],[26,7.1]],"id":52671555},{"atb":[[27,8.18]],"id":52671550},{"atl":[[1000,0.16]],"id":52671544}],"con":true,"img":false}]}
{"op":"mcm","clk":"11450654602","pt":1717324267850,"mc":[{"id":"1.229554928","rc":[{"atb":[[10,5.81]],"id":52237628},{"atb":[[6.6,0]],"id":52237627},{"atl":[[540,0]],"id":52671542}],"con":true,"img":false}]}
{"op":"mcm","clk":"11450655176","pt":1717324273173,"mc":[{"id":"1.229554928","rc":[{"atb":[[4,0],[9.6,4.17],[4.7,26.16]],"id":52237628},{"atl":[[34,3.03],[40,0]],"id":52237628},{"atb":[[5,0],[5.5,0],[6,5],[5.7,4.25],[7,0]],"id":52237627},{"atl":[[17.5,0],[15.5,10.9]],"id":52237627},{"atl":[[160,2],[190,0]],"id":52671555},{"atb":[[2.22,81.97],[2.04,0]],"id":52237624},{"atb":[[21,4.65],[27,5.86]],"id":52237612},{"atl":[[550,0],[450,2]],"id":52237612},{"atl":[[170,2],[200,0]],"id":52671550},{"atb":[[5.1,24.39],[4.2,0]],"id":52671548},{"atl":[[610,0],[620,3.57]],"id":52671542}],"con":true,"img":false}]}
{"op":"mcm","clk":"11450655184","pt":1717324273279,"mc":[{"id":"1.229554928","rc":[{"atb":[[5.9,0]],"id":52237627},{"atb":[[34,0],[85,0],[44,5],[60,0]],"id":52671565}],"con":true,"img":false}]}
{"op":"mcm","clk":"11450655275","pt":1717324274003,"mc":[{"id":"1.229554928","rc":[{"atb":[[6.8,4.51],[4.9,26.83],[5.9,10.68],[5.4,17.84]],"id":52237627},{"atb":[[32,3.37],[80,0.33],[42,1.92],[55,0.97]],"id":52671565},{"atl":[[640,4.43]],"id":52671542}],"con":true,"img":false}]}
{"op":"mcm","clk":"11450655640","pt":1717324277298,"mc":[{"id":"1.229554928","rc":[{"atl":[[170,4.03]],"id":52237612},{"atl":[[85,3.97]],"id":52671550},{"atl":[[510,3.6]],"id":52671544}],"con":true,"img":false}]}
{"op":"mcm","clk":"11450655878","pt":1717324279897,"mc":[{"id":"1.229554928","rc":[{"atl":[[10,22.81]],"id":52237627},{"atl":[[29,10.73]],"id":52671563},{"atl":[[40,13.23]],"id":52671561},{"atl":[[3.85,37.77]],"id":52237624},{"atb":[[5.8,24.7]],"id":52671548},{"atl":[[14.5,16.87]],"id":52671548},{"atb":[[95,1.7]],"id":52671542},{"atb":[[90,1.79]],"id":52671544},{"atl":[[490,3.3]],"id":52671544}],"con":true,"img":false}]}
{"op":"mcm","clk":"11450655890","pt":1717324280004,"mc":[{"id":"1.229554928","rc":[{"atl":[[27,6.16]],"id":52237628},{"atl":[[210,0.76]],"id":52671565},{"atl":[[150,4.27]],"id":52237612},{"atl":[[70,2.32]],"id":52671550},{"atb":[[3.65,34.38]],"id":52237617},{"atl":[[5.6,34.38]],"id":52237617}],"con":true,"img":false}]}
{"op":"mcm","clk":"11450655958","pt":1717324280683,"mc":[{"id":"1.229554928","rc":[{"atl":[[38,5]],"id":52237628},{"atl":[[15,0]],"id":52237627},{"atl":[[34,0]],"id":52671563},{"atl":[[300,0]],"id":52671565},{"atl":[[40,9.12]],"id":52671561},{"atl":[[15,0]],"id":52237624},{"atl":[[200,0]],"id":52237612},{"atl":[[110,5]],"id":52671550},{"atb":[[2.74,9.01]],"id":52237617},{"atl":[[15,0]],"id":52237617},{"atb":[[5.4,5.94]],"id":52671548},{"atl":[[15,0]],"id":52671548},{"atb":[[80,0]],"id":52671542},{"atb":[[75,0]],"id":52671544},{"atl":[[1000,0]],"id":52671544}],"con":true,"img":false}]}
{"op":"mcm","clk":"11450656208","pt":1717324283298,"mc":[{"id":"1.229554928","rc":[{"atb":[[5.8,5],[6,0]],"id":52237627},{"atl":[[220,0]],"id":52237612},{"atl":[[120,0]],"id":52671550}],"con":true,"img":false}]}
{"op":"mcm","clk":"11450656294","pt":1717324284026,"mc":[{"id":"1.229554928","rc":[{"atl":[[30,2.7]],"id":52237628},{"atb":[[5.5,3.98]],"id":52237627}],"con":true,"img":false}]}
{"op":"mcm","clk":"11450656947","pt":1717324290713,"mc":[{"id":"1.229554928","rc":[{"atl":[[42,0]],"id":52237628}],"con":true,"img":false}]}
{"op":"mcm","clk":"11450657284","pt":1717324293637,"mc":[{"id":"1.229554928","rc":[{"atb":[[90,0]],"id":52671544}],"con":true,"img":false}]}
{"op":"mcm","clk":"11450657364","pt":1717324294319,"mc":[{"id":"1.229554928","rc":[{"atb":[[85,6.91]],"id":52671544}],"con":true,"img":false}]}
{"op":"mcm","clk":"11450657925","pt":1717324299741,"mc":[{"id":"1.229554928","rc":[{"atb":[[26,4],[27,2.01],[28,5],[29,0]],"id":52237612}],"con":true,"img":false}]}
{"op":"mcm","clk":"11450657958","pt":1717324300052,"mc":[{"id":"1.229554928","rc":[{"atb":[[9.6,0]],"id":52237628},{"atb":[[5.8,8.21],[5.7,0]],"id":52237627},{"atl":[[490,0.32],[480,3.89]],"id":52671544}],"con":true,"img":false}]}
{"op":"mcm","clk":"11450658007","pt":1717324300526,"mc":[{"id":"1.229554928","rc":[{"atl":[[470,0.34]],"id":52671544}],"con":true,"img":false}]}
{"op":"mcm","clk":"11450658081","pt":1717324301254,"mc":[{"id":"1.229554928","rc":[{"atl":[[490,0]],"id":52671544}],"con":true,"img":false}]}
{"op":"mcm","clk":"11450658256","pt":1717324302765,"mc":[{"id":"1.229554928","rc":[{"atb":[[6.2,0],[8.2,0]],"id":52237628},{"atb":[[5.1,0],[4.1,0]],"id":52237627},{"atb":[[7.8,0],[5.9,0]],"id":52671563},{"atb":[[17.5,0],[25,0]],"id":52671565},{"atb":[[6.8,0],[8.8,0]],"id":52671561},{"atb":[[160,5],[80,0]],"id":52671560},{"atb":[[8.6,0],[11.5,0]],"id":52671555},{"atb":[[2.36,0],[2.16,0]],"id":52237624},{"atb":[[9.8,0],[14.5,0]],"id":52237612},{"atb":[[13.5,0],[9.4,0]],"id":52671550},{"atb":[[540,0],[640,0]],"id":52671546},{"atb":[[2.64,15.95],[2.44,54.5]],"id":52237617},{"atb":[[3,0],[3.5,0]],"id":52671548},{"atb":[[20,0],[15,0]],"id":52671542},{"atb":[[18.5,0],[13.5,0]],"id":52671544}],"con":true,"img":false}]}
{"op":"mcm","clk":"11450658323","pt":1717324303344,"mc":[{"id":"1.229554928","rc":[{"atb":[[4.7,0],[5.4,22.73]],"id":52237628},{"atl":[[34,0],[55,2]],"id":52237628},{"atb":[[2.82,18.9],[3.6,0]],"id":52237627},{"atl":[[36,7.46],[95,0]],"id":52671563},{"atl":[[350,0],[240,2]],"id":52671565},{"atl":[[65,2],[110,0]],"id":52671561},{"atl":[[160,0],[220,2]],"id":52671555},{"atb":[[2.22,0],[2.42,70.42]],"id":52237624},{"atb":[[26,0],[29,3.57]],"id":52237612},{"atl":[[170,0],[250,2]],"id":52671550},{"atb":[[3,50],[2.66,0]],"id":52237617},{"atb":[[5.1,0],[5.4,28.67]],"id":52671548}],"con":true,"img":false}]}
{"op":"mcm","clk":"11450658364","pt":1717324303658,"mc":[{"id":"1.229554928","rc":[{"atb":[[11,4.43],[12.5,15.18]],"id":52237628},{"atb":[[5.8,0],[5.5,0],[6.8,0],[4.9,0],[5.9,0],[5.4,0]],"id":52237627},{"atb":[[16,0],[18.5,0],[11,0],[13.5,0],[14,0]],"id":52671563},{"atb":[[32,0],[80,0],[42,0],[44,0],[55,0]],"id":52671565},{"atb":[[16.5,0],[13.5,5]],"id":52671561},{"atl":[[860,4.27],[880,2.75],[1000,0.16]],"id":52671560},{"atb":[[32,6.01]],"id":52671555},{"atl":[[3.85,32.77]],"id":52237624},{"atl":[[150,1.07]],"id":52237612},{"atb":[[34,5.65]],"id":52671550},{"atl":[[5.6,29.38],[6.2,5]],"id":52237617},{"atl":[[16.5,9.42],[14.5,11.86],[15.5,0]],"id":52671548},{"atl":[[620,0],[700,3.91]],"id":52671542},{"atl":[[520,3.8],[480,0]],"id":52671544}],"con":true,"img":false}]}
{"op":"mcm","clk":"11450658378","pt":1717324303715,"mc":[{"id":"1.229554928","rc":[{"atb":[[17.5,1.59]],"id":52671561},{"atl":[[4.5,5]],"id":52237624}],"con":true,"img":false}]}
{"op":"mcm","clk":"11450658400","pt":1717324303924,"mc":[{"id":"1.229554928","rc":[{"atl":[[36,4.6],[42,2.44]],"id":52671563},{"atl":[[290,2],[240,0]],"id":52671565},{"atl":[[590,2],[450,0]],"id":52237612},{"atl":[[310,2],[250,0]],"id":52671550}],"con":true,"img":false}]}
{"op":"mcm","clk":"11450658413","pt":1717324304028,"mc":[{"id":"1.229554928","rc":[{"atb":[[18.5,1.15]],"id":52671565}],"con":true,"img":false}]}
{"op":"mcm","clk":"11450658425","pt":1717324304133,"mc":[{"id":"1.229554928","rc":[{"atb":[[4.2,11.02]],"id":52237627},{"atb":[[29,5]],"id":52671565}],"con":true,"img":false}]}
{"op":"mcm","clk":"11450658514","pt":1717324304824,"mc":[{"id":"1.229554928","rc":[{"atb":[[9.4,7.84]],"id":52237628},{"atb":[[2.82,24.95],[3.6,40.24],[3.85,27.54],[4.2,27.38],[4.7,7.07]],"id":52237627},{"atb":[[9.2,9.57],[10.5,5.51],[8.2,14.53],[13,2.18],[3.25,5.64]],"id":52671563},{"atb":[[27,2.01]],"id":52671550}],"con":true,"img":false}]}
{"op":"mcm","clk":"11450658526","pt":1717324304929,"mc":[{"id":"1.229554928","rc":[{"atb":[[32,2.53],[42,1.28],[26,4.19],[55,0.49]],"id":52671565},{"atb":[[13.5,14.93]],"id":52671561},{"atb":[[12,0]],"id":52671555}],"con":true,"img":false}]}
{"op":"mcm","clk":"11450658540","pt":1717324305038,"mc":[{"id":"1.229554928","rc":[{"atb":[[18,0]],"id":52671565}],"con":true,"img":false}]}
{"op":"mcm","clk":"11450658610","pt":1717324305654,"mc":[{"id":"1.229554928","rc":[{"atb":[[2.82,18.9]],"id":52237627}],"con":true,"img":false}]}
{"op":"mcm","clk":"11450658658","pt":1717324306125,"mc":[{"id":"1.229554928","rc":[{"atl":[[17.5,3.33]],"id":52671548}],"con":true,"img":false}]}
{"op":"mcm","clk":"11450658679","pt":1717324306333,"mc":[{"id":"1.229554928","rc":[{"atb":[[3.95,5.32],[4.1,5.06]],"id":52237627},{"atl":[[860,0],[890,4.05]],"id":52671560},{"atl":[[170,0],[180,4.67]],"id":52237612},{"atl":[[16,3.19]],"id":52671548},{"atl":[[520,0],[640,0],[720,4.31]],"id":52671542},{"atl":[[540,4.07],[510,0]],"id":52671544}],"con":true,"img":false}]}
{"op":"mcm","clk":"11450658748","pt":1717324307054,"mc":[{"id":"1.229554928","rc":[{"atl":[[710,0.22]],"id":52671542}],"con":true,"img":false}]}
{"op":"mcm","clk":"11450658932","pt":1717324308732,"mc":[{"id":"1.229554928","rc":[{"atl":[[880,0]],"id":52671560},{"atl":[[16.5,5],[17.5,0]],"id":52671548},{"atl":[[700,0]],"id":52671542},{"atl":[[520,0]],"id":52671544}],"con":true,"img":false}]}
{"op":"mcm","clk":"11450659243","pt":1717324311238,"mc":[{"id":"1.229554928","rc":[{"atl":[[65,0],[85,2]],"id":52671561},{"atl":[[280,2],[220,0]],"id":52671555}],"con":true,"img":false}]}
{"op":"mcm","clk":"11450659281","pt":1717324311549,"mc":[{"id":"1.229554928","rc":[{"atb":[[3.6,0],[3.85,0],[4.2,11.02],[4.7,0]],"id":52237627},{"atl":[[890,0],[910,3.15]],"id":52671560},{"atl":[[65,2.5],[70,9.46]],"id":52671555},{"atl":[[16,0],[16.5,8.78]],"id":52671548},{"atl":[[720,0],[730,3.17]],"id":52671542}],"con":true,"img":false}]}
{"op":"mcm","clk":"11450659292","pt":1717324311652,"mc":[{"id":"1.229554928","rc":[{"atb":[[130,0]],"id":52671560},{"atb":[[2.56,0],[2.62,9.68]],"id":52237624},{"atb":[[2.74,0],[2.84,8.52]],"id":52237617},{"atb":[[4.8,0],[5,3.52]],"id":52671548}],"con":true,"img":false}]}
{"op":"mcm","clk":"11450659358","pt":1717324312230,"mc":[{"id":"1.229554928","rc":[{"atb":[[4.6,7.27],[4.1,21.94],[3.8,28.03],[3.55,41.03]],"id":52237627}],"con":true,"img":false}]}
{"op":"mcm","clk":"11450659471","pt":1717324313275,"mc":[{"id":"1.229554928","rc":[{"atb":[[3.75,5.7]],"id":52671550}],"con":true,"img":false}]}
{"op":"mcm","clk":"11450659483","pt":1717324313381,"mc":[{"id":"1.229554928","rc":[{"atb":[[6.2,46.9],[8.2,14.51]],"id":52237628},{"atb":[[5.1,25.49],[4.1,100.62]],"id":52237627},{"atb":[[7.8,15.37],[5.9,49.77]],"id":52671563},{"atb":[[17.5,14.77],[25,4.35]],"id":52671565},{"atb":[[6.8,42.05],[8.8,13.4]],"id":52671561},{"atb":[[160,5.66],[80,3.08]],"id":52671560},{"atb":[[8.6,32.09],[11.5,9.95]],"id":52671555},{"atb":[[2.36,76.85],[2.16,210.26]],"id":52237624},{"atb":[[9.8,27.71],[14.5,7.74]],"id":52237612},{"atb":[[13.5,8.36],[9.4,29.03]],"id":52671550},{"atb":[[540,0.44],[640,0.16]],"id":52671546},{"atb":[[2.64,79.69],[2.44,223.88]],"id":52237617},{"atb":[[3,121.95],[3.5,41.81]],"id":52671548},{"atb":[[20,5.5],[15,17.42]],"id":52671542},{"atb":[[18.5,5.97],[13.5,19.51]],"id":52671544}],"con":true,"img":false}]}
{"op":"mcm","clk":"11450659551","pt":1717324313861,"mc":[{"id":"1.229554928","rc":[{"atb":[[120,3.26]],"id":52671560},{"atb":[[80,5],[85,0]],"id":52671544}],"con":true,"img":false}]}
{"op":"mcm","clk":"11450659560","pt":1717324313962,"mc":[{"id":"1.229554928","rc":[{"atb":[[10,8.48]],"id":52237628}],"con":true,"img":false}]}
{"op":"mcm","clk":"11450659631","pt":1717324314641,"mc":[{"id":"1.229554928","rc":[{"atb":[[75,1.14]],"id":52671544}],"con":true,"img":false}]}
{"op":"mcm","clk":"11450659831","pt":1717324316568,"mc":[{"id":"1.229554928","rc":[{"atl":[[200,4.14]],"id":52237612},{"atl":[[560,4.13]],"id":52671544}],"con":true,"img":false}]}
{"op":"mcm","clk":"11450659838","pt":1717324316672,"mc":[{"id":"1.229554928","rc":[{"atb":[[19.5,0],[21,6.58]],"id":52671555},{"atb":[[2.56,10.06],[2.62,0]],"id":52237624},{"atb":[[2.84,0],[2.76,8.92]],"id":52237617},{"atb":[[38,0]],"id":52671542}],"con":true,"img":false}]}
{"op":"mcm","clk":"11450659848","pt":1717324316778,"mc":[{"id":"1.229554928","rc":[{"atb":[[11,0],[11.5,4.59],[9.4,5]],"id":52237628},{"atb":[[130,2.64],[120,0]],"id":52671560},{"atb":[[20,0],[21,0]],"id":52237612},{"atb":[[34,4.85],[18.5,0],[22,0],[27,0]],"id":52671550},{"atb":[[290,0],[340,0],[390,0],[440,0]],"id":52671546},{"atb":[[40,6.3]],"id":52671542}],"con":true,"img":false}]}
{"op":"mcm","clk":"11450659894","pt":1717324317247,"mc":[{"id":"1.229554928","rc":[{"atb":[[160,5]],"id":52671546}],"con":true,"img":false}]}
{"op":"mcm","clk":"11450659915","pt":1717324317456,"mc":[{"id":"1.229554928","rc":[{"atl":[[16,3.66],[15.5,6.9]],"id":52237627},{"atl":[[36,0],[38,2.76]],"id":52671563},{"atl":[[310,0],[320,3.44]],"id":52671565},{"atl":[[40,5]],"id":52671561},{"atb":[[20,3.14],[21,3.92]],"id":52671555},{"atb":[[2.56,0],[2.62,9.68]],"id":52237624},{"atb":[[36,0.75],[19,5.81],[23,3.57],[28,1.94]],"id":52671550},{"atb":[[320,0.33],[370,0.21],[420,0.13],[470,0.06]],"id":52671546},{"atb":[[2.82,8.62],[2.76,0]],"id":52237617}],"con":true,"img":false}]}
{"op":"mcm","clk":"11450659925","pt":1717324317558,"mc":[{"id":"1.229554928","rc":[{"atb":[[130,0]],"id":52671560},{"atb":[[19.5,4.21],[21,3.93]],"id":52237612},{"atb":[[40,2.01]],"id":52671542}],"con":true,"img":false}]}
{"op":"mcm","clk":"11450659974","pt":1717324318132,"mc":[{"id":"1.229554928","rc":[{"atb":[[36,0],[19,0],[23,0],[28,0]],"id":52671550}],"con":true,"img":false}]}
{"op":"mcm","clk":"11450660023","pt":1717324318650,"mc":[{"id":"1.229554928","rc":[{"atb":[[130,4.15]],"id":52671560},{"atb":[[20,0],[21,7.8]],"id":52671555},{"atb":[[2.56,10.06],[2.62,0]],"id":52237624},{"atb":[[21,0]],"id":52237612},{"atb":[[2.82,0],[2.76,8.92]],"id":52237617},{"atb":[[40,4.92]],"id":52671542}],"con":true,"img":false}]}
{"op":"mcm","clk":"11450660031","pt":1717324318750,"mc":[{"id":"1.229554928","rc":[{"atl":[[870,4.24]],"id":52671560},{"atl":[[170,2.85],[180,0]],"id":52237612},{"atl":[[75,0],[80,3.19]],"id":52671550},{"atl":[[710,3.69]],"id":52671542},{"atl":[[540,0],[520,3.65]],"id":52671544}],"con":true,"img":false}]}
{"op":"mcm","clk":"11450660043","pt":1717324318861,"mc":[{"id":"1.229554928","rc":[{"atb":[[38,0.71],[19.5,5.66],[24,3.41],[29,1.87]],"id":52671550}],"con":true,"img":false}]}
{"op":"mcm","clk":"11450660051","pt":1717324318961,"mc":[{"id":"1.229554928","rc":[{"atl":[[910,3.33]],"id":52671560}],"con":true,"img":false}]}
{"op":"mcm","clk":"11450660076","pt":1717324319279,"mc":[{"id":"1.229554928","rc":[{"atb":[[38,5.04]],"id":52671550}],"con":true,"img":false}]}
{"op":"mcm","clk":"11450660114","pt":1717324319646,"mc":[{"id":"1.229554928","rc":[{"atl":[[1000,0]],"id":52671560}],"con":true,"img":false}]}
{"op":"mcm","clk":"11450660141","pt":1717324319954,"mc":[{"id":"1.229554928","rc":[{"atb":[[11,2.8],[11.5,0]],"id":52237628},{"atb":[[130,0]],"id":52671560},{"atb":[[19.5,3.04],[21,3.92]],"id":52671555},{"atb":[[2.56,0],[2.62,9.68]],"id":52237624},{"atb":[[21,4.3]],"id":52237612},{"atb":[[34,0]],"id":52671550},{"atb":[[2.84,8.52],[2.76,0]],"id":52237617},{"atb":[[40,2.01]],"id":52671542}],"con":true,"img":false}]}
{"op":"mcm","clk":"11450660228","pt":1717324320755,"mc":[{"id":"1.229554928","rc":[{"atl":[[16,0],[15.5,10.05]],"id":52237627},{"atl":[[36,3.81],[38,0]],"id":52671563},{"atl":[[310,3.73],[320,0]],"id":52671565},{"atl":[[40,8.94]],"id":52671561},{"atb":[[27,7.02],[28,0]],"id":52237612}],"con":true,"img":false}]}
{"op":"mcm","clk":"11450660236","pt":1717324320858,"mc":[{"id":"1.229554928","rc":[{"atb":[[11,0],[11.5,3.38]],"id":52237628},{"atb":[[19.5,0],[20,3.62]],"id":52671555},{"atb":[[2.82,8.62],[2.84,0]],"id":52237617}],"con":true,"img":false}]}
{"op":"mcm","clk":"11450660243","pt":1717324320957,"mc":[{"id":"1.229554928","rc":[{"atb":[[28,3.7],[29,0]],"id":52237612}],"con":true,"img":false}]}
{"op":"mcm","clk":"11450660322","pt":1717324321777,"mc":[{"id":"1.229554928","rc":[{"atb":[[4.8,3.11]],"id":52671548},{"atl":[[17.5,4.29]],"id":52671548}],"con":true,"img":false}]}
{"op":"mcm","clk":"11450660458","pt":1717324323163,"mc":[{"id":"1.229554928","rc":[{"atb":[[4.6,0]],"id":52671548}],"con":true,"img":false}]}
{"op":"mcm","clk":"11450660498","pt":1717324323575,"mc":[{"id":"1.229554928","rc":[{"atb":[[75,6.14],[80,0]],"id":52671544}],"con":true,"img":false}]}
{"op":"mcm","clk":"11450660545","pt":1717324324002,"mc":[{"id":"1.229554928","rc":[{"atl":[[860,4.09],[870,0]],"id":52671560},{"atl":[[710,0.22],[720,3.95]],"id":52671542},{"atl":[[520,0],[510,2.71]],"id":52671544}],"con":true,"img":false}]}
{"op":"mcm","clk":"11450660566","pt":1717324324217,"mc":[{"id":"1.229554928","rc":[{"atb":[[12,5],[9.4,0]],"id":52237628},{"atl":[[10,17.8],[8.8,5]],"id":52237627},{"atl":[[25,5],[29,5.72]],"id":52671563},{"atb":[[29,0],[30,5]],"id":52671565},{"atb":[[13.5,9.92],[14.5,5]],"id":52671561},{"atb":[[32,11.02],[26,2.09]],"id":52671555},{"atb":[[3.15,5],[2.68,0]],"id":52237624},{"atl":[[180,5],[210,0]],"id":52237612},{"atb":[[32,5],[25,0]],"id":52671550},{"atb":[[4,5],[3.65,29.38]],"id":52237617},{"atb":[[10,5],[5.7,0]],"id":52671548},{"atb":[[90,0],[100,5]],"id":52671542}],"con":true,"img":false}]}
{"op":"mcm","clk":"11450660572","pt":1717324324273,"mc":[{"id":"1.229554928","rc":[{"atb":[[75,1.14],[80,5]],"id":52671544}],"con":true,"img":false}]}
{"op":"mcm","clk":"11450660624","pt":1717324324643,"mc":[{"id":"1.229554928","rc":[{"atl":[[8.8,25.54]],"id":52237627},{"atl":[[25,11.68]],"id":52671563},{"atb":[[3.2,23.11]],"id":52237624},{"atb":[[4,58.41]],"id":52237617},{"atb":[[10.5,16.86]],"id":52671548},{"atb":[[100,6.62]],"id":52671542}],"con":true,"img":false}]}
{"op":"mcm","clk":"11450660648","pt":1717324324856,"mc":[{"id":"1.229554928","rc":[{"atl":[[75,5]],"id":52671550}],"con":true,"img":false}]}
{"op":"mcm","clk":"11450660662","pt":1717324324956,"mc":[{"id":"1.229554928","rc":[{"atl":[[38,0],[21,5]],"id":52237628},{"atl":[[34,3.03],[42,0]],"id":52671563},{"atl":[[290,0],[150,5],[220,0],[230,2]],"id":52671565},{"atl":[[65,2],[34,5],[40,3.93],[85,0]],"id":52671561},{"atl":[[280,0],[210,2]],"id":52671555},{"atl":[[4.5,0],[4.4,5]],"id":52237624},{"atl":[[590,0],[450,2]],"id":52237612},{"atl":[[260,2],[310,0],[110,0]],"id":52671550}],"con":true,"img":false}]}
{"op":"mcm","clk":"11450660691","pt":1717324325268,"mc":[{"id":"1.229554928","rc":[{"atb":[[11,4.42],[11.5,0]],"id":52237628},{"atb":[[120,3.54]],"id":52671560},{"atb":[[19.5,4.58],[20,0]],"id":52671555}],"con":true,"img":false}]}
{"op":"mcm","clk":"11450660702","pt":1717324325372,"mc":[{"id":"1.229554928","rc":[{"atl":[[20,8.39]],"id":52237628},{"atl":[[10,0]],"id":52237627},{"atl":[[29,0]],"id":52671563},{"atl":[[34,9.86]],"id":52671561},{"atb":[[2.74,15.04]],"id":52237624},{"atb":[[3.65,0]],"id":52237617},{"atb":[[5.8,0]],"id":52671548},{"atb":[[95,0]],"id":52671542}],"con":true,"img":false}]}
{"op":"mcm","clk":"11450660716","pt":1717324325477,"mc":[{"id":"1.229554928","rc":[{"atl":[[150,6.08]],"id":52671565}],"con":true,"img":false}]}
{"op":"mcm","clk":"11450660802","pt":1717324326102,"mc":[{"id":"1.229554928","rc":[{"atl":[[27,0]],"id":52237628},{"atl":[[38,0]],"id":52671561}],"con":true,"img":false}]}
{"op":"mcm","clk":"11450660813","pt":1717324326209,"mc":[{"id":"1.229554928","rc":[{"atl":[[210,0]],"id":52671565}],"con":true,"img":false}]}
{"op":"mcm","clk":"11450660822","pt":1717324326314,"mc":[{"id":"1.229554928","rc":[{"atb":[[11,0],[11.5,3.81]],"id":52237628},{"atb":[[19.5,0],[20,3.94]],"id":52671555},{"atb":[[75,6.14],[80,0]],"id":52671544}],"con":true,"img":false}]}
{"op":"mcm","clk":"11450661153","pt":1717324329395,"mc":[{"id":"1.229554928","rc":[{"atl":[[65,5.88],[70,5]],"id":52671555},{"atl":[[16.5,5],[17,3.58]],"id":52671548}],"con":true,"img":false}]}
{"op":"mcm","clk":"11450661208","pt":1717324329913,"mc":[{"id":"1.229554928","rc":[{"atb":[[2.58,9.93]],"id":52237624}],"con":true,"img":false}]}
{"op":"mcm","clk":"11450661297","pt":1717324330700,"mc":[{"id":"1.229554928","rc":[{"atb":[[2.52,0]],"id":52237624}],"con":true,"img":false}]}
{"op":"mcm","clk":"11450661303","pt":1717324330801,"mc":[{"id":"1.229554928","rc":[{"atb":[[2.78,8.81]],"id":52237617}],"con":true,"img":false}]}
{"op":"mcm","clk":"11450661460","pt":1717324332115,"mc":[{"id":"1.229554928","rc":[{"atb":[[8,0],[9,0],[10,2.66],[12.5,12.9]],"id":52237628},{"atb":[[32,10.17],[18,2.62],[21,0],[26,0]],"id":52671555}],"con":true,"img":false}]}
{"op":"mcm","clk":"11450661558","pt":1717324332693,"mc":[{"id":"1.229554928","rc":[{"atb":[[2.7,0]],"id":52237617}],"con":true,"img":false}]}
{"op":"mcm","clk":"11450661571","pt":1717324332801,"mc":[{"id":"1.229554928","rc":[{"atb":[[16.5,1.69],[9.6,12.17],[11.5,11.3],[14,4.02]],"id":52237628}],"con":true,"img":false}]}
{"op":"mcm","clk":"11450661590","pt":1717324332901,"mc":[{"id":"1.229554928","rc":[{"atb":[[34,0.8],[18.5,5.98],[22,3.74],[27,2.01]],"id":52671555}],"con":true,"img":false}]}
{"op":"mcm","clk":"11450661697","pt":1717324333425,"mc":[{"id":"1.229554928","rc":[{"atl":[[20,0]],"id":52237628},{"atb":[[34,5.65]],"id":52671555}],"con":true,"img":false}]}
{"op":"mcm","clk":"11450661707","pt":1717324333531,"mc":[{"id":"1.229554928","rc":[{"atl":[[860,4.27]],"id":52671560}],"con":true,"img":false}]}
{"op":"mcm","clk":"11450661786","pt":1717324334006,"mc":[{"id":"1.229554928","rc":[{"atl":[[530,4.63]],"id":52671544}],"con":true,"img":false}]}
{"op":"mcm","clk":"11450661848","pt":1717324334433,"mc":[{"id":"1.229554928","rc":[{"atl":[[27,6.16]],"id":52237628},{"atl":[[910,3.15]],"id":52671560},{"atb":[[32,5]],"id":52671555}],"con":true,"img":false}]}
{"op":"mcm","clk":"11450661878","pt":1717324334591,"mc":[{"id":"1.229554928","rc":[{"atl":[[34,0],[28,3.7]],"id":52671563},{"atl":[[190,2],[230,0]],"id":52671565},{"atl":[[65,0],[55,2]],"id":52671561},{"atl":[[170,2],[210,0]],"id":52671555},{"atl":[[370,2],[450,0]],"id":52237612},{"atl":[[260,0],[210,2]],"id":52671550},{"atl":[[34,0],[27,3.85]],"id":52671548}],"con":true,"img":false}]}
{"op":"mcm","clk":"11450661919","pt":1717324334906,"mc":[{"id":"1.229554928","rc":[{"atl":[[65,2.5],[70,8.62]],"id":52671555},{"atl":[[560,0]],"id":52671544}],"con":true,"img":false}]}
{"op":"mcm","clk":"11450661970","pt":1717324335013,"mc":[{"id":"1.229554928","rc":[{"atb":[[19.5,3.62]],"id":52671555}],"con":true,"img":false}]}
{"op":"mcm","clk":"11450662000","pt":1717324335112,"mc":[{"id":"1.229554928","rc":[{"atb":[[11,3.28],[11.5,7.48]],"id":52237628},{"atl":[[27,10.83],[28,0]],"id":52237628},{"atb":[[20,0]],"id":52671555},{"atb":[[2.82,0],[2.84,8.52]],"id":52237617}],"con":true,"img":false}]}
{"op":"mcm","clk":"11450662012","pt":1717324335223,"mc":[{"id":"1.229554928","rc":[{"atl":[[880,3.73]],"id":52671560}],"con":true,"img":false}]}
{"op":"mcm","clk":"11450662167","pt":1717324336417,"mc":[{"id":"1.229554928","rc":[{"atb":[[11,0]],"id":52237628},{"atl":[[300,3.37],[310,0]],"id":52671565},{"atb":[[120,0]],"id":52671560},{"atl":[[910,0]],"id":52671560},{"atb":[[19.5,0]],"id":52671555},{"atb":[[2.6,9.8],[2.62,0]],"id":52237624},{"atb":[[20,3.44],[21,0]],"id":52237612},{"atb":[[2.82,8.62],[2.84,0]],"id":52237617},{"atb":[[5,0],[4.9,17.66]],"id":52671548}],"con":true,"img":false}]}
{"op":"mcm","clk":"11450662177","pt":1717324336523,"mc":[{"id":"1.229554928","rc":[{"atb":[[130,2.79]],"id":52671560}],"con":true,"img":false}]}
{"op":"mcm","clk":"11450662391","pt":1717324338505,"mc":[{"id":"1.229554928","rc":[{"atb":[[16.5,0],[9.6,0],[11.5,0],[14,0]],"id":52237628}],"con":true,"img":false}]}
{"op":"mcm","clk":"11450662473","pt":1717324339212,"mc":[{"id":"1.229554928","rc":[{"atb":[[9.2,12.76],[10.5,8.26],[13,4.36],[15.5,1.81]],"id":52237628}],"con":true,"img":false}]}
{"op":"mcm","clk":"11450662680","pt":1717324340933,"mc":[{"id":"1.229554928","rc":[{"atb":[[10.5,11.38]],"id":52237628},{"atb":[[19,4.23]],"id":52671555}],"con":true,"img":false}]}
{"op":"mcm","clk":"11450662741","pt":1717324341400,"mc":[{"id":"1.229554928","rc":[{"atl":[[150,0],[160,5]],"id":52671565}],"con":true,"img":false}]}
{"op":"mcm","clk":"11450662821","pt":1717324342129,"mc":[{"id":"1.229554928","rc":[{"atl":[[180,0.89]],"id":52671565}],"con":true,"img":false}]}
{"op":"mcm","clk":"11450663220","pt":1717324345103,"mc":[{"id":"1.229554928","rc":[{"atb":[[9.2,0],[10.5,0],[8.2,0],[13,0]],"id":52671563},{"atl":[[65,6.48],[70,5]],"id":52671555},{"atl":[[6.4,5],[6.2,0]],"id":52237617},{"atl":[[16.5,8.79],[17,0]],"id":52671548},{"atl":[[720,0]],"id":52671542},{"atl":[[510,0],[500,3.94]],"id":52671544}],"con":true,"img":false}]}
{"op":"mcm","clk":"11450663276","pt":1717324345529,"mc":[{"id":"1.229554928","rc":[{"atl":[[9,5],[8.8,0]],"id":52237627},{"atb":[[27,2.01],[28,8.7]],"id":52237612}],"con":true,"img":false}]}
{"op":"mcm","clk":"11450663290","pt":1717324345685,"mc":[{"id":"1.229554928","rc":[{"atb":[[10,16.28]],"id":52671563},{"atb":[[38,4.17]],"id":52671542}],"con":true,"img":false}]}
{"op":"mcm","clk":"11450663314","pt":1717324345837,"mc":[{"id":"1.229554928","rc":[{"atb":[[8,14.95],[9,9.81],[10,22.1],[12.5,2.28]],"id":52671563}],"con":true,"img":false}]}
{"op":"mcm","clk":"11450663361","pt":1717324346211,"mc":[{"id":"1.229554928","rc":[{"atl":[[15,11.44]],"id":52237627}],"con":true,"img":false}]}
{"op":"mcm","clk":"11450663385","pt":1717324346420,"mc":[{"id":"1.229554928","rc":[{"atb":[[3.25,0]],"id":52671563},{"atb":[[27,7.02],[28,3.7]],"id":52237612}],"con":true,"img":false}]}
{"op":"mcm","clk":"11450663496","pt":1717324347361,"mc":[{"id":"1.229554928","rc":[{"atb":[[9.2,0],[10.5,3.12],[13,0],[15.5,0]],"id":52237628},{"atb":[[19,0],[19.5,4.63]],"id":52671555},{"atb":[[2.6,0],[2.58,0]],"id":52237624},{"atb":[[2.82,0],[2.76,8.92]],"id":52237617},{"atb":[[5,2.78],[4.9,13.41]],"id":52671548},{"atb":[[38,0],[40,5.17]],"id":52671542},{"atb":[[34,0],[36,4.55]],"id":52671544}],"con":true,"img":false}]}
{"op":"mcm","clk":"11450663545","pt":1717324347724,"mc":[{"id":"1.229554928","rc":[{"atl":[[34,3.03],[28,0]],"id":52671563},{"atl":[[190,0],[230,2]],"id":52671565},{"atl":[[370,0],[450,2]],"id":52237612}],"con":true,"img":false}]}
{"op":"mcm","clk":"11450663577","pt":1717324348036,"mc":[{"id":"1.229554928","rc":[{"atl":[[16,4.45],[15.5,6.9]],"id":52237627},{"atl":[[36,0],[38,4.68]],"id":52671563}],"con":true,"img":false}]}
{"op":"mcm","clk":"11450663585","pt":1717324348139,"mc":[{"id":"1.229554928","rc":[{"atb":[[9.2,12.76],[10.5,11.38],[13,4.36],[15.5,1.81]],"id":52237628}],"con":true,"img":false}]}
{"op":"mcm","clk":"11450663628","pt":1717324348508,"mc":[{"id":"1.229554928","rc":[{"atb":[[2.82,8.62]],"id":52237617}],"con":true,"img":false}]}
{"op":"mcm","clk":"11450663638","pt":1717324348611,"mc":[{"id":"1.229554928","rc":[{"atb":[[19.5,0],[19,2.64]],"id":52671555},{"atb":[[2.56,10.06],[2.6,9.8]],"id":52237624},{"atb":[[2.78,0]],"id":52237617},{"atb":[[5,0],[4.9,16.07]],"id":52671548},{"atb":[[38,3.22],[40,2.01]],"id":52671542},{"atb":[[36,0]],"id":52671544}],"con":true,"img":false}]}
{"op":"mcm","clk":"11450663827","pt":1717324350233,"mc":[{"id":"1.229554928","rc":[{"atl":[[16,0],[15.5,10.23]],"id":52237627},{"atl":[[36,4.68],[38,0]],"id":52671563},{"atl":[[860,0.18],[850,4.64]],"id":52671560},{"atl":[[720,2.76]],"id":52671542}],"con":true,"img":false}]}
{"op":"mcm","clk":"11450663880","pt":1717324350706,"mc":[{"id":"1.229554928","rc":[{"atl":[[840,0.18]],"id":52671560}],"con":true,"img":false}]}
{"op":"mcm","clk":"11450663994","pt":1717324351644,"mc":[{"id":"1.229554928","rc":[{"atl":[[860,0]],"id":52671560}],"con":true,"img":false}]}
{"op":"mcm","clk":"11450664074","pt":1717324352325,"mc":[{"id":"1.229554928","rc":[{"atb":[[19,0],[19.5,3.85]],"id":52671555},{"atb":[[2.56,0],[2.6,0]],"id":52237624},{"atb":[[2.82,0]],"id":52237617},{"atb":[[5,4.3],[4.9,13.41]],"id":52671548},{"atb":[[38,0],[40,5.05]],"id":52671542},{"atb":[[36,3.2]],"id":52671544}],"con":true,"img":false}]}
{"op":"mcm","clk":"11450664085","pt":1717324352428,"mc":[{"id":"1.229554928","rc":[{"atl":[[16,3.31],[15.5,6.9]],"id":52237627},{"atl":[[36,0],[38,4.48]],"id":52671563}],"con":true,"img":false}]}
{"op":"mcm","clk":"11450664121","pt":1717324352740,"mc":[{"id":"1.229554928","rc":[{"atb":[[20,0],[21,4.66]],"id":52237612},{"atb":[[2.7,9.23]],"id":52237617}],"con":true,"img":false}]}
{"op":"mcm","clk":"11450664238","pt":1717324353732,"mc":[{"id":"1.229554928","rc":[{"atb":[[2.76,0]],"id":52237617},{"atb":[[5,0]],"id":52671548}],"con":true,"img":false}]}
{"op":"mcm","clk":"11450664256","pt":1717324353943,"mc":[{"id":"1.229554928","rc":[{"atb":[[26,5],[27,2.01]],"id":52237612},{"atb":[[95,5],[100,1.61]],"id":52671542}],"con":true,"img":false}]}
{"op":"mcm","clk":"11450664273","pt":1717324354045,"mc":[{"id":"1.229554928","rc":[{"atl":[[34,0],[28,3.7]],"id":52671563},{"atl":[[190,2],[230,0]],"id":52671565},{"atl":[[370,2],[450,0]],"id":52237612},{"atb":[[100,0]],"id":52671542}],"con":true,"img":false}]}
{"op":"mcm","clk":"11450664316","pt":1717324354525,"mc":[{"id":"1.229554928","rc":[{"atl":[[850,0],[860,2.92]],"id":52671560}],"con":true,"img":false}]}
{"op":"mcm","clk":"11450664345","pt":1717324354735,"mc":[{"id":"1.229554928","rc":[{"atb":[[80,2.02]],"id":52671542}],"con":true,"img":false}]}
{"op":"mcm","clk":"11450664410","pt":1717324355314,"mc":[{"id":"1.229554928","rc":[{"atl":[[860,0],[850,2.62]],"id":52671560},{"atl":[[65,2.5],[70,8.12]],"id":52671555},{"atl":[[16.5,5],[17,3.03]],"id":52671548}],"con":true,"img":false}]}
{"op":"mcm","clk":"11450664426","pt":1717324355421,"mc":[{"id":"1.229554928","rc":[{"atb":[[2.92,50.98]],"id":52237627},{"atb":[[11,10],[9.4,0]],"id":52671555}],"con":true,"img":false}]}
{"op":"mcm","clk":"11450664436","pt":1717324355533,"mc":[{"id":"1.229554928","rc":[{"atb":[[2.82,0]],"id":52237627}],"con":true,"img":false}]}
{"op":"mcm","clk":"11450664442","pt":1717324355628,"mc":[{"id":"1.229554928","rc":[{"atb":[[21,0]],"id":52237612}],"con":true,"img":false}]}
{"op":"mcm","clk":"11450664457","pt":1717324355737,"mc":[{"id":"1.229554928","rc":[{"atl":[[80,0]],"id":52671550},{"atl":[[6.4,0],[6,5]],"id":52237617},{"atl":[[16.5,0]],"id":52671548},{"atl":[[710,2.93]],"id":52671542}],"con":true,"img":false}]}
{"op":"mcm","clk":"11450664464","pt":1717324355842,"mc":[{"id":"1.229554928","rc":[{"atb":[[4.3,4.75],[4.1,95.56],[4.4,5],[4.2,6.02]],"id":52237627},{"atl":[[890,2.98]],"id":52671560},{"atl":[[160,4.27],[170,0]],"id":52237612},{"atl":[[75,0],[80,5]],"id":52671550},{"atl":[[16,9.01]],"id":52671548},{"atl":[[720,0]],"id":52671542}],"con":true,"img":false}]}
{"op":"mcm","clk":"11450664483","pt":1717324356054,"mc":[{"id":"1.229554928","rc":[{"atb":[[250,0]],"id":52671560}],"con":true,"img":false}]}
{"op":"mcm","clk":"11450664502","pt":1717324356237,"mc":[{"id":"1.229554928","rc":[{"atl":[[150,1.07]],"id":52671565}],"con":true,"img":false}]}
{"op":"mcm","clk":"11450664520","pt":1717324356452,"mc":[{"id":"1.229554928","rc":[{"atl":[[850,0]],"id":52671560},{"atl":[[17,0]],"id":52671548}],"con":true,"img":false}]}
{"op":"mcm","clk":"11450664554","pt":1717324356767,"mc":[{"id":"1.229554928","rc":[{"atb":[[200,0.7]],"id":52671560}],"con":true,"img":false}]}
{"op":"mcm","clk":"11450664577","pt":1717324356929,"mc":[{"id":"1.229554928","rc":[{"atl":[[180,0]],"id":52671565}],"con":true,"img":false}]}
{"op":"mcm","clk":"11450664658","pt":1717324357754,"mc":[{"id":"1.229554928","rc":[{"atl":[[880,0]],"id":52671560}],"con":true,"img":false}]}
{"op":"mcm","clk":"11450664756","pt":1717324358546,"mc":[{"id":"1.229554928","rc":[{"atb":[[26,0]],"id":52237612},{"atb":[[90,5],[95,0]],"id":52671542}],"con":true,"img":false}]}
{"op":"mcm","clk":"11450664816","pt":1717324359020,"mc":[{"id":"1.229554928","rc":[{"atb":[[25,5]],"id":52237612}],"con":true,"img":false}]}
{"op":"mcm","clk":"11450664827","pt":1717324359118,"mc":[{"id":"1.229554928","rc":[{"atl":[[32,3.23],[28,0]],"id":52671563},{"atl":[[190,0],[210,2]],"id":52671565},{"atb":[[20,3.06]],"id":52237612}],"con":true,"img":false}]}
{"op":"mcm","clk":"11450664938","pt":1717324360216,"mc":[{"id":"1.229554928","rc":[{"atl":[[8.8,20.53]],"id":52237627}],"con":true,"img":false}]}
{"op":"mcm","clk":"11450664961","pt":1717324360434,"mc":[{"id":"1.229554928","rc":[{"atb":[[2.92,0],[3.2,45.45]],"id":52237627},{"atl":[[32,0],[26,4]],"id":52671563},{"atl":[[210,0],[240,2]],"id":52671565},{"atb":[[2.14,87.72]],"id":52237624},{"atl":[[20,5.26],[27,0]],"id":52671548}],"con":true,"img":false}]}
{"op":"mcm","clk":"11450664969","pt":1717324360527,"mc":[{"id":"1.229554928","rc":[{"atb":[[2.42,0]],"id":52237624}],"con":true,"img":false}]}
{"op":"mcm","clk":"11450664989","pt":1717324360733,"mc":[{"id":"1.229554928","rc":[{"atb":[[5.1,53.59]],"id":52237627},{"atb":[[8,0],[9,0],[10,16.28],[9.2,5],[12.5,0]],"id":52671563},{"atb":[[17.5,11.3]],"id":52671561},{"atb":[[32,0]],"id":52671555},{"atl":[[65,6.02],[70,3.11]],"id":52671555},{"atb":[[2.74,20.04],[3.15,0]],"id":52237624},{"atl":[[160,0]],"id":52237612},{"atl":[[6,0]],"id":52237617},{"atb":[[10.5,0],[8.4,5]],"id":52671548},{"atl":[[16,5]],"id":52671548},{"atl":[[770,3.09]],"id":52671542}],"con":true,"img":false}]}
{"op":"mcm","clk":"11450664999","pt":1717324360839,"mc":[{"id":"1.229554928","rc":[{"atl":[[21,2.91],[25,5]],"id":52237628},{"atb":[[4.3,0],[4.9,3.08]],"id":52237627},{"atb":[[10,11.27]],"id":52671563},{"atl":[[890,0]],"id":52671560},{"atb":[[34,0.8],[29,5]],"id":52671555},{"atl":[[65,11.02],[70,0]],"id":52671555},{"atb":[[3.2,0]],"id":52237624},{"atl":[[180,9.25]],"id":52237612},{"atl":[[80,0],[85,0],[90,5],[95,4.19]],"id":52671550},{"atl":[[6.6,5]],"id":52237617},{"atb":[[10,0]],"id":52671548},{"atl":[[15.5,3.85]],"id":52671548},{"atl":[[710,0.22]],"id":52671542},{"atl":[[400,3.72],[500,0]],"id":52671544}],"con":true,"img":false}]}
{"op":"mcm","clk":"11450665011","pt":1717324360944,"mc":[{"id":"1.229554928","rc":[{"atl":[[15,0]],"id":52237627}],"con":true,"img":false}]}
{"op":"mcm","clk":"11450665048","pt":1717324361358,"mc":[{"id":"1.229554928","rc":[{"atl":[[390,0.41]],"id":52671544}],"con":true,"img":false}]}
{"op":"mcm","clk":"11450665067","pt":1717324361567,"mc":[{"id":"1.229554928","rc":[{"atb":[[4.2,0]],"id":52237627},{"atb":[[9.2,19.27],[12,2.38],[9.8,5.94],[8.8,10.06],[7.8,30.76]],"id":52671563},{"atb":[[13.5,0]],"id":52671561},{"atb":[[27,8.18]],"id":52671555},{"atb":[[5.5,13.3]],"id":52671548}],"con":true,"img":false}]}
{"op":"mcm","clk":"11450665079","pt":1717324361625,"mc":[{"id":"1.229554928","rc":[{"atl":[[27,4.67]],"id":52237628},{"atb":[[2.64,55.02]],"id":52237624}],"con":true,"img":false}]}
{"op":"mcm","clk":"11450665136","pt":1717324362042,"mc":[{"id":"1.229554928","rc":[{"atl":[[470,0]],"id":52671544}],"con":true,"img":false}]}
{"op":"mcm","clk":"11450665146","pt":1717324362141,"mc":[{"id":"1.229554928","rc":[{"atb":[[2.66,9.45]],"id":52237617}],"con":true,"img":false}]}
{"op":"mcm","clk":"11450665172","pt":1717324362349,"mc":[{"id":"1.229554928","rc":[{"atb":[[9.2,5]],"id":52671563}],"con":true,"img":false}]}
{"op":"mcm","clk":"11450665466","pt":1717324364863,"mc":[{"id":"1.229554928","rc":[{"atb":[[2.52,10.32],[2.48,10.6]],"id":52237624},{"atl":[[730,0]],"id":52671542}],"con":true,"img":false}]}
{"op":"mcm","clk":"11450665506","pt":1717324365232,"mc":[{"id":"1.229554928","rc":[{"atl":[[32,3.23],[26,0]],"id":52671563},{"atl":[[320,2],[240,0]],"id":52671565},{"atl":[[90,2],[55,0]],"id":52671561},{"atl":[[370,0],[490,2]],"id":52237612},{"atl":[[320,2],[210,0]],"id":52671550},{"atl":[[20,0],[26,4]],"id":52671548}],"con":true,"img":false}]}
{"op":"mcm","clk":"11450665532","pt":1717324365547,"mc":[{"id":"1.229554928","rc":[{"atb":[[10.5,8.26],[11.5,4.61],[5.9,20.41],[5.4,0]],"id":52237628},{"atb":[[19.5,0],[21,2.86]],"id":52671555},{"atb":[[2.54,0],[2.74,5],[2.64,23.11],[2.44,0]],"id":52237624},{"atb":[[40,2.01]],"id":52671542}],"con":true,"img":false}]}
{"op":"mcm","clk":"11450665543","pt":1717324365652,"mc":[{"id":"1.229554928","rc":[{"atl":[[300,0],[310,3.24]],"id":52671565},{"atl":[[40,0]],"id":52671561}],"con":true,"img":false}]}
{"op":"mcm","clk":"11450665557","pt":1717324365850,"mc":[{"id":"1.229554928","rc":[{"atb":[[10,0]],"id":52671563}],"con":true,"img":false}]}
{"op":"mcm","clk":"11450665569","pt":1717324365955,"mc":[{"id":"1.229554928","rc":[{"atl":[[150,0]],"id":52671565}],"con":true,"img":false}]}
{"op":"mcm","clk":"11450665586","pt":1717324366164,"mc":[{"id":"1.229554928","rc":[{"atb":[[32,0],[42,0],[26,0],[55,0]],"id":52671565},{"atb":[[21,2.89]],"id":52237612}],"con":true,"img":false}]}
{"op":"mcm","clk":"11450665596","pt":1717324366223,"mc":[{"id":"1.229554928","rc":[{"atb":[[20,0]],"id":52237612}],"con":true,"img":false}]}
{"op":"mcm","clk":"11450665606","pt":1717324366323,"mc":[{"id":"1.229554928","rc":[{"atb":[[2.54,50.96],[2.74,20.04],[2.64,55.02],[2.44,72.66]],"id":52237624}],"con":true,"img":false}]}
{"op":"mcm","clk":"11450665626","pt":1717324366535,"mc":[{"id":"1.229554928","rc":[{"atb":[[32,0.51]],"id":52671565}],"con":true,"img":false}]}
{"op":"mcm","clk":"11450665632","pt":1717324366640,"mc":[{"id":"1.229554928","rc":[{"atl":[[160,5.11]],"id":52671565}],"con":true,"img":false}]}
{"op":"mcm","clk":"11450665658","pt":1717324366848,"mc":[{"id":"1.229554928","rc":[{"atb":[[75,0.36],[40,2.01],[50,1.07],[30,8.62]],"id":52671565}],"con":true,"img":false}]}
{"op":"mcm","clk":"11450665668","pt":1717324366952,"mc":[{"id":"1.229554928","rc":[{"atb":[[10.5,11.44],[11.5,0]],"id":52237628}],"con":true,"img":false}]}
{"op":"mcm","clk":"11450665675","pt":1717324367052,"mc":[{"id":"1.229554928","rc":[{"atb":[[130,0],[140,4.65]],"id":52671560},{"atb":[[19.5,4.52],[21,0]],"id":52671555},{"atb":[[21,0]],"id":52237612},{"atb":[[36,0]],"id":52671544}],"con":true,"img":false}]}
{"op":"mcm","clk":"11450665697","pt":1717324367258,"mc":[{"id":"1.229554928","rc":[{"atb":[[18.5,0]],"id":52671565}],"con":true,"img":false}]}
{"op":"mcm","clk":"11450665869","pt":1717324368935,"mc":[{"id":"1.229554928","rc":[{"atb":[[95,1.7]],"id":52671542}],"con":true,"img":false}]}
{"op":"mcm","clk":"11450665947","pt":1717324369722,"mc":[{"id":"1.229554928","rc":[{"atb":[[80,0]],"id":52671542}],"con":true,"img":false}]}
{"op":"mcm","clk":"11450666013","pt":1717324370247,"mc":[{"id":"1.229554928","rc":[{"atb":[[4.7,3.7]],"id":52237627},{"atl":[[110,3.03]],"id":52671550},{"atb":[[4.6,4.48]],"id":52671548},{"atl":[[16.5,4.66]],"id":52671548},{"atl":[[790,3.46]],"id":52671542},{"atl":[[420,3.4]],"id":52671544}],"con":true,"img":false}]}
{"op":"mcm","clk":"11450666045","pt":1717324370555,"mc":[{"id":"1.229554928","rc":[{"atb":[[250,0.64]],"id":52671560}],"con":true,"img":false}]}
{"op":"mcm","clk":"11450666055","pt":1717324370658,"mc":[{"id":"1.229554928","rc":[{"atb":[[6.2,0],[8.2,0]],"id":52237628},{"atb":[[5.1,28.09],[4.1,16.88]],"id":52237627},{"atb":[[7.8,15.39],[5.9,0]],"id":52671563},{"atb":[[17.5,0],[25,0]],"id":52671565},{"atb":[[6.8,0],[8.8,0]],"id":52671561},{"atb":[[160,5],[80,0]],"id":52671560},{"atb":[[8.6,0],[11.5,0]],"id":52671555},{"atb":[[2.36,0],[2.16,0]],"id":52237624},{"atb":[[9.8,0],[14.5,0]],"id":52237612},{"atb":[[13.5,0],[9.4,0]],"id":52671550},{"atb":[[540,0],[640,0]],"id":52671546},{"atb":[[2.64,15.95],[2.44,54.5]],"id":52237617},{"atb":[[3,0],[3.5,0]],"id":52671548},{"atb":[[20,0],[15,0]],"id":52671542},{"atb":[[18.5,0],[13.5,0]],"id":52671544}],"con":true,"img":false}]}
{"op":"mcm","clk":"11450666081","pt":1717324370968,"mc":[{"id":"1.229554928","rc":[{"atb":[[34,2.66]],"id":52671544}],"con":true,"img":false}]}
{"op":"mcm","clk":"11450666111","pt":1717324371241,"mc":[{"id":"1.229554928","rc":[{"atb":[[3.95,0]],"id":52237627},{"atb":[[12,0],[9.8,0],[8.8,0],[7.8,0]],"id":52671563},{"atb":[[200,0]],"id":52671560},{"atb":[[20,2.69]],"id":52237612},{"atl":[[180,5],[190,3.11]],"id":52237612},{"atb":[[1.88,0]],"id":52671550},{"atl":[[17.5,0]],"id":52671548},{"atl":[[770,0]],"id":52671542},{"atl":[[400,0],[410,3.55],[420,0]],"id":52671544}],"con":true,"img":false}]}
{"op":"mcm","clk":"11450666164","pt":1717324371766,"mc":[{"id":"1.229554928","rc":[{"atb":[[9.2,16.6]],"id":52671563}],"con":true,"img":false}]}
{"op":"mcm","clk":"11450666194","pt":1717324371929,"mc":[{"id":"1.229554928","rc":[{"atb":[[9.6,6.08],[8.6,10.33],[11.5,2.49],[7.6,15.85]],"id":52671563}],"con":true,"img":false}]}
{"op":"mcm","clk":"11450666205","pt":1717324372031,"mc":[{"id":"1.229554928","rc":[{"atb":[[2.54,0],[2.74,5],[2.64,23.11],[2.44,0]],"id":52237624}],"con":true,"img":false}]}
{"op":"mcm","clk":"11450666301","pt":1717324372870,"mc":[{"id":"1.229554928","rc":[{"atb":[[2.72,15.21],[2.42,73.69],[2.52,61.95],[2.62,32.3]],"id":52237624}],"con":true,"img":false}]}
{"op":"mcm","clk":"11450666371","pt":1717324373451,"mc":[{"id":"1.229554928","rc":[{"atl":[[8.8,0]],"id":52237627}],"con":true,"img":false}]}
{"op":"mcm","clk":"11450666431","pt":1717324374035,"mc":[{"id":"1.229554928","rc":[{"atb":[[3.1,7.47]],"id":52671563}],"con":true,"img":false}]}
{"op":"mcm","clk":"11450666440","pt":1717324374139,"mc":[{"id":"1.229554928","rc":[{"atl":[[15,11.44]],"id":52237627},{"atl":[[46,3.08]],"id":52671561}],"con":true,"img":false}]}
{"op":"mcm","clk":"11450666561","pt":1717324375238,"mc":[{"id":"1.229554928","rc":[{"atb":[[8.4,26.65]],"id":52671548}],"con":true,"img":false}]}
{"op":"mcm","clk":"11450666572","pt":1717324375342,"mc":[{"id":"1.229554928","rc":[{"atb":[[2.82,0]],"id":52671563},{"atb":[[2.74,43.44]],"id":52237624}],"con":true,"img":false}]}
{"op":"mcm","clk":"11450666620","pt":1717324375967,"mc":[{"id":"1.229554928","rc":[{"atb":[[5.5,0]],"id":52671548}],"con":true,"img":false}]}
{"op":"mcm","clk":"11450666629","pt":1717324376070,"mc":[{"id":"1.229554928","rc":[{"atb":[[2.64,0]],"id":52237624}],"con":true,"img":false}]}
{"op":"mcm","clk":"11450666969","pt":1717324379346,"mc":[{"id":"1.229554928","rc":[{"atl":[[810,3.38]],"id":52671542}],"con":true,"img":false}]}
{"op":"mcm","clk":"11450667083","pt":1717324380551,"mc":[{"id":"1.229554928","rc":[{"atb":[[5.9,3.18]],"id":52671546},{"atl":[[430,3.07]],"id":52671544}],"con":true,"img":false}]}
{"op":"mcm","clk":"11450667124","pt":1717324380971,"mc":[{"id":"1.229554928","rc":[{"atb":[[12,0],[13.5,5]],"id":52237628},{"atl":[[9,0],[8.8,5]],"id":52237627},{"atb":[[38,5],[30,3.61]],"id":52671565},{"atb":[[17.5,16.3],[14.5,0]],"id":52671561},{"atb":[[32,0],[38,10.05]],"id":52671550},{"atb":[[90,0],[95,6.71]],"id":52671542}],"con":true,"img":false}]}
{"op":"mcm","clk":"11450667194","pt":1717324381664,"mc":[{"id":"1.229554928","rc":[{"atl":[[150,5],[160,0.1]],"id":52671565},{"atl":[[3.65,5]],"id":52237624}],"con":true,"img":false}]}
{"op":"mcm","clk":"11450667208","pt":1717324381766,"mc":[{"id":"1.229554928","rc":[{"atl":[[26,4.37],[27,0]],"id":52237628},{"atl":[[300,4.41],[310,0]],"id":52671565},{"atb":[[2.54,10.19],[2.52,51.63]],"id":52237624},{"atl":[[4.4,0]],"id":52237624},{"atb":[[1.88,0]],"id":52671546},{"atb":[[2.68,9.34],[2.7,0]],"id":52237617},{"atb":[[4.8,0],[4.9,16.6]],"id":52671548},{"atb":[[34,0],[36,3.88]],"id":52671544},{"atl":[[530,0]],"id":52671544}],"con":true,"img":false}]}
{"op":"mcm","clk":"11450667234","pt":1717324382077,"mc":[{"id":"1.229554928","rc":[{"atl":[[150,6.08]],"id":52671565},{"atl":[[790,0],[800,3.89]],"id":52671542}],"con":true,"img":false}]}
{"op":"mcm","clk":"11450667246","pt":1717324382181,"mc":[{"id":"1.229554928","rc":[{"atl":[[3.6,61.61]],"id":52237624}],"con":true,"img":false}]}
{"op":"mcm","clk":"11450667311","pt":1717324382662,"mc":[{"id":"1.229554928","rc":[{"atb":[[38,2.73]],"id":52671542}],"con":true,"img":false}]}
{"op":"mcm","clk":"11450667327","pt":1717324382769,"mc":[{"id":"1.229554928","rc":[{"atl":[[160,0]],"id":52671565}],"con":true,"img":false}]}
{"op":"mcm","clk":"11450667342","pt":1717324382882,"mc":[{"id":"1.229554928","rc":[{"atl":[[3.85,0]],"id":52237624}],"con":true,"img":false}]}
{"op":"mcm","clk":"11450667570","pt":1717324384874,"mc":[{"id":"1.229554928","rc":[{"atb":[[15.5,12.85]],"id":52237628},{"atl":[[8.8,0]],"id":52237627},{"atl":[[150,0],[160,5]],"id":52671565},{"atb":[[4,53.4],[4.1,5]],"id":52237617}],"con":true,"img":false}]}
{"op":"mcm","clk":"11450667583","pt":1717324384976,"mc":[{"id":"1.229554928","rc":[{"atl":[[9,5]],"id":52237627}],"con":true,"img":false}]}
{"op":"mcm","clk":"11450667608","pt":1717324385235,"mc":[{"id":"1.229554928","rc":[{"atb":[[4.1,56.68]],"id":52237617}],"con":true,"img":false}]}
{"op":"mcm","clk":"11450667631","pt":1717324385553,"mc":[{"id":"1.229554928","rc":[{"atl":[[160,6.01]],"id":52671565}],"con":true,"img":false}]}
{"op":"mcm","clk":"11450667642","pt":1717324385668,"mc":[{"id":"1.229554928","rc":[{"atb":[[12.5,0]],"id":52237628}],"con":true,"img":false}]}
{"op":"mcm","clk":"11450667676","pt":1717324385920,"mc":[{"id":"1.229554928","rc":[{"atl":[[160,1],[170,5]],"id":52671565},{"atb":[[75,1.14],[80,5]],"id":52671544}],"con":true,"img":false}]}
{"op":"mcm","clk":"11450667684","pt":1717324385973,"mc":[{"id":"1.229554928","rc":[{"atb":[[4,0]],"id":52237617}],"con":true,"img":false}]}
{"op":"mcm","clk":"11450667719","pt":1717324386284,"mc":[{"id":"1.229554928","rc":[{"atl":[[160,0]],"id":52671565}],"con":true,"img":false}]}
{"op":"mcm","clk":"11450667731","pt":1717324386345,"mc":[{"id":"1.229554928","rc":[{"atb":[[80,7.03]],"id":52671544}],"con":true,"img":false}]}
{"op":"mcm","clk":"11450667795","pt":1717324386883,"mc":[{"id":"1.229554928","rc":[{"atb":[[7,16.67],[5.9,0]],"id":52237628},{"atb":[[3.2,0],[3.55,80.25]],"id":52237627},{"atb":[[2.26,79.37],[2.14,0]],"id":52237624},{"atb":[[3,0],[3.25,44.44]],"id":52237617},{"atb":[[5.8,20.83],[5.4,5.94]],"id":52671548},{"atb":[[48,0],[60,2]],"id":52671542},{"atb":[[46,0],[55,2]],"id":52671544}],"con":true,"img":false}]}
{"op":"mcm","clk":"11450667801","pt":1717324386974,"mc":[{"id":"1.229554928","rc":[{"atl":[[170,5.95]],"id":52671565}],"con":true,"img":false}]}
{"op":"mcm","clk":"11450667829","pt":1717324387198,"mc":[{"id":"1.229554928","rc":[{"atb":[[6.4,45.16],[8.4,14.12]],"id":52237628},{"atb":[[4.3,73.9],[5,3.41],[5.3,24.31],[4.9,0]],"id":52237627},{"atb":[[6.2,46.9],[8.2,14.51]],"id":52671563},{"atb":[[19.5,13.18],[29,3.73]],"id":52671565},{"atb":[[7.4,38.1],[9.4,12.44]],"id":52671561},{"atb":[[120,0.87],[60,4.13]],"id":52671560},{"atb":[[9,30.48],[12.5,9.08]],"id":52671555},{"atb":[[2.32,79.18],[2.12,217.77]],"id":52237624},{"atb":[[9.2,29.74],[13,8.71]],"id":52237612},{"atl":[[180,0],[200,9.15]],"id":52237612},{"atb":[[9.6,28.36],[14,8.04]],"id":52671550},{"atb":[[560,0.18],[460,0.53]],"id":52671546},{"atb":[[2.64,79.69],[2.44,223.88]],"id":52237617},{"atl":[[6.8,5],[6.6,0]],"id":52237617},{"atb":[[3.55,40.99],[3.05,118.97]],"id":52671548},{"atb":[[19,5.8],[14,18.76]],"id":52671542},{"atl":[[800,0],[820,4.07]],"id":52671542},{"atb":[[17.5,6.33],[75,0],[12.5,21.2]],"id":52671544}],"con":true,"img":false}]}
{"op":"mcm","clk":"11450667875","pt":1717324387564,"mc":[{"id":"1.229554928","rc":[{"atl":[[14.5,11.86]],"id":52237627},{"atb":[[75,5],[80,0]],"id":52671544}],"con":true,"img":false}]}
{"op":"mcm","clk":"11450667974","pt":1717324388393,"mc":[{"id":"1.229554928","rc":[{"atl":[[15,0]],"id":52237627},{"atb":[[75,7.17]],"id":52671544}],"con":true,"img":false}]}
{"op":"mcm","clk":"11450668008","pt":1717324388661,"mc":[{"id":"1.229554928","rc":[{"atl":[[9,0],[9.2,5]],"id":52237627},{"atl":[[170,0],[180,5]],"id":52671565},{"atl":[[34,0],[36,5]],"id":52671561},{"atl":[[810,0]],"id":52671542}],"con":true,"img":false}]}
{"op":"mcm","clk":"11450668092","pt":1717324389386,"mc":[{"id":"1.229554928","rc":[{"atl":[[290,0.55]],"id":52671565},{"atl":[[40,4.1]],"id":52671561}],"con":true,"img":false}]}
{"op":"mcm","clk":"11450668255","pt":1717324390795,"mc":[{"id":"1.229554928","rc":[{"atl":[[28,2.94]],"id":52237628}],"con":true,"img":false}]}
{"op":"mcm","clk":"11450668309","pt":1717324391176,"mc":[{"id":"1.229554928","rc":[{"atl":[[24,5],[25,6.67]],"id":52671563},{"atl":[[34,5],[36,0]],"id":52671561},{"atb":[[4,5],[4.1,0]],"id":52237617}],"con":true,"img":false}]}
{"op":"mcm","clk":"11450668357","pt":1717324391598,"mc":[{"id":"1.229554928","rc":[{"atl":[[24,11.97]],"id":52671563}],"con":true,"img":false}]}
{"op":"mcm","clk":"11450668387","pt":1717324391883,"mc":[{"id":"1.229554928","rc":[{"atb":[[3.25,67.48]],"id":52237617}],"con":true,"img":false}]}
{"op":"mcm","clk":"11450668438","pt":1717324392286,"mc":[{"id":"1.229554928","rc":[{"atb":[[3.2,41.19],[3.55,41.03]],"id":52237627},{"atl":[[25,0]],"id":52671563},{"atb":[[2.12,307.06],[2.26,0]],"id":52237624},{"atl":[[560,2],[490,0]],"id":52237612},{"atb":[[5.8,0],[4.9,42.24]],"id":52671548},{"atb":[[48,2.13],[60,0]],"id":52671542},{"atb":[[46,2.22],[55,0]],"id":52671544}],"con":true,"img":false}]}
{"op":"mcm","clk":"11450668605","pt":1717324393606,"mc":[{"id":"1.229554928","rc":[{"atl":[[30,0]],"id":52237628},{"atl":[[190,0]],"id":52237612},{"atl":[[70,0],[90,0],[95,9.2]],"id":52671550},{"atl":[[820,0],[860,3.84]],"id":52671542},{"atl":[[410,0]],"id":52671544}],"con":true,"img":false}]}
{"op":"mcm","clk":"11450668675","pt":1717324394172,"mc":[{"id":"1.229554928","rc":[{"atl":[[34,0],[36,5]],"id":52671561}],"con":true,"img":false}]}
{"op":"mcm","clk":"11450668697","pt":1717324394373,"mc":[{"id":"1.229554928","rc":[{"atl":[[110,4.5]],"id":52671550}],"con":true,"img":false}]}
{"op":"mcm","clk":"11450668806","pt":1717324395375,"mc":[{"id":"1.229554928","rc":[{"atl":[[180,5.9]],"id":52671565}],"con":true,"img":false}]}
{"op":"mcm","clk":"11450668883","pt":1717324396067,"mc":[{"id":"1.229554928","rc":[{"atl":[[290,0]],"id":52671565}],"con":true,"img":false}]}
{"op":"mcm","clk":"11450669072","pt":1717324397799,"mc":[{"id":"1.229554928","rc":[{"atl":[[32,0],[30,3.45]],"id":52671563}],"con":true,"img":false}]}
{"op":"mcm","clk":"11450669106","pt":1717324398069,"mc":[{"id":"1.229554928","rc":[{"atl":[[26,0],[27,4.68]],"id":52237628},{"atl":[[95,5],[100,3.1]],"id":52671550},{"atl":[[420,3.62]],"id":52671544}],"con":true,"img":false}]}
{"op":"mcm","clk":"11450669137","pt":1717324398389,"mc":[{"id":"1.229554928","rc":[{"atl":[[180,0],[190,5]],"id":52671565}],"con":true,"img":false}]}
{"op":"mcm","clk":"11450669145","pt":1717324398490,"mc":[{"id":"1.229554928","rc":[{"atb":[[4,34.55]],"id":52237617}],"con":true,"img":false}]}
{"op":"mcm","clk":"11450669246","pt":1717324399203,"mc":[{"id":"1.229554928","rc":[{"atl":[[290,0.55]],"id":52671565},{"atb":[[3.25,44.44]],"id":52237617}],"con":true,"img":false}]}
{"op":"mcm","clk":"11450669296","pt":1717324399613,"mc":[{"id":"1.229554928","rc":[{"atl":[[300,0],[320,5.77]],"id":52671565},{"atb":[[130,3.05],[140,0.57]],"id":52671560},{"atb":[[2.56,10.06],[2.54,0]],"id":52237624},{"atb":[[20,0],[21,3.09]],"id":52237612},{"atb":[[2.68,0],[2.7,9.23]],"id":52237617}],"con":true,"img":false}]}
{"op":"mcm","clk":"11450669376","pt":1717324400179,"mc":[{"id":"1.229554928","rc":[{"atl":[[180,0.89]],"id":52671565}],"con":true,"img":false}]}
{"op":"mcm","clk":"11450669445","pt":1717324400750,"mc":[{"id":"1.229554928","rc":[{"atl":[[9,20.02]],"id":52237627}],"con":true,"img":false}]}
{"op":"mcm","clk":"11450669472","pt":1717324400961,"mc":[{"id":"1.229554928","rc":[{"atl":[[290,0]],"id":52671565}],"con":true,"img":false}]}
{"op":"mcm","clk":"11450669506","pt":1717324401278,"mc":[{"id":"1.229554928","rc":[{"atb":[[25,0],[29,5]],"id":52237612}],"con":true,"img":false}]}
{"op":"mcm","clk":"11450669515","pt":1717324401384,"mc":[{"id":"1.229554928","rc":[{"atb":[[28,0],[30,3.45]],"id":52237612}],"con":true,"img":false}]}
{"op":"mcm","clk":"11450669527","pt":1717324401496,"mc":[{"id":"1.229554928","rc":[{"atl":[[14.5,0]],"id":52237627}],"con":true,"img":false}]}
{"op":"mcm","clk":"11450669618","pt":1717324402284,"mc":[{"id":"1.229554928","rc":[{"atl":[[880,3.45]],"id":52671542}],"con":true,"img":false}]}
{"op":"mcm","clk":"11450669646","pt":1717324402482,"mc":[{"id":"1.229554928","rc":[{"atl":[[38,4.33]],"id":52671561}],"con":true,"img":false}]}
{"op":"mcm","clk":"11450669715","pt":1717324403111,"mc":[{"id":"1.229554928","rc":[{"atb":[[2.56,0],[2.54,10.19]],"id":52237624},{"atb":[[21,0],[28,5],[29,0]],"id":52237612},{"atb":[[2.7,0],[2.76,8.92]],"id":52237617},{"atb":[[5,2.87],[4.9,39.05]],"id":52671548},{"atb":[[38,0],[40,6.64]],"id":52671542}],"con":true,"img":false}]}
{"op":"mcm","clk":"11450669725","pt":1717324403170,"mc":[{"id":"1.229554928","rc":[{"atl":[[27,0]],"id":52237628},{"atb":[[5,0],[4.9,3.81]],"id":52237627},{"atl":[[16,0],[16.5,0]],"id":52237627},{"atl":[[38,0],[42,3.57]],"id":52671563},{"atl":[[320,2],[380,4.3]],"id":52671565},{"atl":[[40,0],[42,0]],"id":52671561},{"atl":[[65,7.5],[70,3.4]],"id":52671555},{"atl":[[95,8.87],[100,0]],"id":52671550},{"atl":[[860,0],[850,3.17]],"id":52671542}],"con":true,"img":false}]}
{"op":"mcm","clk":"11450669739","pt":1717324403274,"mc":[{"id":"1.229554928","rc":[{"atb":[[29,3.57],[30,0]],"id":52237612}],"con":true,"img":false}]}
{"op":"mcm","clk":"11450669897","pt":1717324404484,"mc":[{"id":"1.229554928","rc":[{"atl":[[26,4.54]],"id":52237628},{"atl":[[16,4.1],[17,3.3]],"id":52237627},{"atl":[[38,4.63],[40,0]],"id":52671563},{"atl":[[320,6.31],[330,0]],"id":52671565},{"atl":[[42,2.71]],"id":52671561},{"atl":[[65,11.59],[70,0]],"id":52671555}],"con":true,"img":false}]}
{"op":"mcm","clk":"11450670109","pt":1717324406410,"mc":[{"id":"1.229554928","rc":[{"atb":[[2.56,10.06],[2.54,0]],"id":52237624},{"atb":[[2.76,0],[2.7,9.23]],"id":52237617},{"atb":[[5,0],[4.9,43.44]],"id":52671548},{"atb":[[38,4.27],[40,2.01]],"id":52671542}],"con":true,"img":false}]}
{"op":"mcm","clk":"11450670221","pt":1717324407396,"mc":[{"id":"1.229554928","rc":[{"atl":[[95,10.57]],"id":52671550}],"con":true,"img":false}]}
{"op":"mcm","clk":"11450670249","pt":1717324407706,"mc":[{"id":"1.229554928","rc":[{"atb":[[2.56,0],[2.54,10.19]],"id":52237624},{"atb":[[2.7,0],[2.76,8.92]],"id":52237617},{"atb":[[5,3.02],[4.9,39.05]],"id":52671548},{"atb":[[38,0],[40,4.68]],"id":52671542}],"con":true,"img":false}]}
{"op":"mcm","clk":"11450670287","pt":1717324408072,"mc":[{"id":"1.229554928","rc":[{"atl":[[110,3.03]],"id":52671550}],"con":true,"img":false}]}
{"op":"mcm","clk":"11450670305","pt":1717324408286,"mc":[{"id":"1.229554928","rc":[{"atl":[[220,3.77]],"id":52237612}],"con":true,"img":false}]}
{"op":"mcm","clk":"11450670326","pt":1717324408490,"mc":[{"id":"1.229554928","rc":[{"atl":[[850,0],[860,3.42]],"id":52671542},{"atl":[[420,0]],"id":52671544}],"con":true,"img":false}]}
{"op":"mcm","clk":"11450670475","pt":1717324409801,"mc":[{"id":"1.229554928","rc":[{"atb":[[20,4.32]],"id":52237612}],"con":true,"img":false}]}
{"op":"mcm","clk":"11450670600","pt":1717324410698,"mc":[{"id":"1.229554928","rc":[{"atl":[[24,0],[25,5]],"id":52671563}],"con":true,"img":false}]}
{"op":"mcm","clk":"11450670612","pt":1717324410801,"mc":[{"id":"1.229554928","rc":[{"atb":[[10.5,8.26],[11,3.55]],"id":52237628},{"atl":[[32,3.23],[30,0]],"id":52671563},{"atb":[[130,0],[140,5.07]],"id":52671560},{"atb":[[19.5,0],[21,3.7]],"id":52671555},{"atb":[[2.72,0],[2.54,0],[2.42,0],[2.52,0],[2.62,0],[2.48,0]],"id":52237624},{"atb":[[19.5,0],[20,0]],"id":52237612},{"atb":[[2.68,9.34],[2.76,0]],"id":52237617},{"atb":[[5.1,4.38],[5,0]],"id":52671548},{"atb":[[75,0],[40,0],[42,3.68],[50,0],[30,0]],"id":52671542}],"con":true,"img":false}]}
{"op":"mcm","clk":"11450670639","pt":1717324411009,"mc":[{"id":"1.229554928","rc":[{"atb":[[5,5],[4.4,0]],"id":52237627},{"atl":[[16,0],[13.5,5]],"id":52671548}],"con":true,"img":false}]}
{"op":"mcm","clk":"11450670691","pt":1717324411376,"mc":[{"id":"1.229554928","rc":[{"atl":[[30,5.52]],"id":52671563}],"con":true,"img":false}]}
{"op":"mcm","clk":"11450670705","pt":1717324411489,"mc":[{"id":"1.229554928","rc":[{"atb":[[2.32,158.46],[2.42,55.26],[2.52,34.42],[2.62,16.15]],"id":52237624},{"atl":[[13,13.35]],"id":52671548},{"atb":[[32,3.37],[80,0.33],[42,5.6],[55,0.97]],"id":52671542}],"con":true,"img":false}]}
{"op":"mcm","clk":"11450670778","pt":1717324412173,"mc":[{"id":"1.229554928","rc":[{"atl":[[14.5,0]],"id":52671548}],"con":true,"img":false}]}
{"op":"mcm","clk":"11450670801","pt":1717324412380,"mc":[{"id":"1.229554928","rc":[{"atb":[[2.42,66.32],[2.38,11.37]],"id":52237624}],"con":true,"img":false}]}
{"op":"mcm","clk":"11450670888","pt":1717324413119,"mc":[{"id":"1.229554928","rc":[{"atl":[[340,3.17]],"id":52671565}],"con":true,"img":false}]}
{"op":"mcm","clk":"11450670913","pt":1717324413278,"mc":[{"id":"1.229554928","rc":[{"atb":[[3.2,0],[3.55,80.25]],"id":52237627},{"atb":[[2.12,217.77],[2.26,79.37]],"id":52237624},{"atb":[[5.8,20.83],[4.9,13.41]],"id":52671548},{"atb":[[48,0],[60,2]],"id":52671542},{"atb":[[46,0],[55,2]],"id":52671544}],"con":true,"img":false}]}
{"op":"mcm","clk":"11450670940","pt":1717324413592,"mc":[{"id":"1.229554928","rc":[{"atl":[[26,0],[27,4.59]],"id":52237628},{"atl":[[190,4.01],[200,5]],"id":52237612},{"atl":[[95,6.71],[100,2.79]],"id":52671550},{"atl":[[820,3.43],[860,0]],"id":52671542},{"atl":[[410,2.74]],"id":52671544}],"con":true,"img":false}]}
{"op":"mcm","clk":"11450670969","pt":1717324413905,"mc":[{"id":"1.229554928","rc":[{"atl":[[380,0]],"id":52671565}],"con":true,"img":false}]}
{"op":"mcm","clk":"11450671033","pt":1717324414423,"mc":[{"id":"1.229554928","rc":[{"atl":[[180,0]],"id":52671565},{"atb":[[18.5,9.06],[19.5,3.76],[27,7.02],[28,0]],"id":52237612},{"atb":[[70,5.38],[75,0]],"id":52671544}],"con":true,"img":false}]}
{"op":"mcm","clk":"11450671042","pt":1717324414525,"mc":[{"id":"1.229554928","rc":[{"atb":[[28,3.7],[29,0]],"id":52237612}],"con":true,"img":false}]}
{"op":"mcm","clk":"11450671116","pt":1717324415103,"mc":[{"id":"1.229554928","rc":[{"atl":[[190,5.85]],"id":52671565},{"atb":[[60,2.71]],"id":52671544}],"con":true,"img":false}]}
{"op":"mcm","clk":"11450671125","pt":1717324415206,"mc":[{"id":"1.229554928","rc":[{"atl":[[16,0]],"id":52237627},{"atl":[[38,0]],"id":52671563},{"atl":[[320,2],[370,3.91]],"id":52671565},{"atl":[[42,0],[48,3.78]],"id":52671561},{"atl":[[65,7.5],[70,4.59]],"id":52671555}],"con":true,"img":false}]}
{"op":"mcm","clk":"11450671135","pt":1717324415318,"mc":[{"id":"1.229554928","rc":[{"atl":[[36,9.58]],"id":52671561}],"con":true,"img":false}]}
{"op":"mcm","clk":"11450671188","pt":1717324415826,"mc":[{"id":"1.229554928","rc":[{"atl":[[65,2.5],[60,5]],"id":52671555}],"con":true,"img":false}]}
{"op":"mcm","clk":"11450671221","pt":1717324416087,"mc":[{"id":"1.229554928","rc":[{"atl":[[38,0]],"id":52671561}],"con":true,"img":false}]}
{"op":"mcm","clk":"11450671249","pt":1717324416395,"mc":[{"id":"1.229554928","rc":[{"atl":[[32,0],[30,8.97]],"id":52671563}],"con":true,"img":false}]}
{"op":"mcm","clk":"11450671327","pt":1717324417126,"mc":[{"id":"1.229554928","rc":[{"atb":[[26,5]],"id":52237612}],"con":true,"img":false}]}
{"op":"mcm","clk":"11450671337","pt":1717324417232,"mc":[{"id":"1.229554928","rc":[{"atl":[[16,3.07]],"id":52237627},{"atl":[[38,2.78]],"id":52671563},{"atl":[[320,5.38],[340,0]],"id":52671565},{"atl":[[42,4.24],[46,0]],"id":52671561},{"atl":[[65,6.64],[70,0]],"id":52671555},{"atb":[[27,2.01]],"id":52237612}],"con":true,"img":false}]}
{"op":"mcm","clk":"11450671506","pt":1717324418704,"mc":[{"id":"1.229554928","rc":[{"atl":[[25,0],[27,9.6]],"id":52237628},{"atb":[[5,9.57],[4.9,0]],"id":52237627},{"atl":[[16,0]],"id":52237627},{"atl":[[38,0]],"id":52671563},{"atl":[[320,2]],"id":52671565},{"atl":[[42,0]],"id":52671561},{"atl":[[65,2.5],[70,3.81]],"id":52671555},{"atl":[[560,0],[490,2]],"id":52237612},{"atl":[[820,0],[830,3.33]],"id":52671542}],"con":true,"img":false}]}
{"op":"mcm","clk":"11450671542","pt":1717324419015,"mc":[{"id":"1.229554928","rc":[{"atb":[[5.3,53.34]],"id":52237627},{"atb":[[75,0],[40,0],[50,0],[30,0]],"id":52671565},{"atl":[[180,3.52],[190,5],[200,0]],"id":52237612},{"atl":[[770,3.27]],"id":52671542},{"atl":[[380,3.77],[410,0]],"id":52671544}],"con":true,"img":false}]}
{"op":"mcm","clk":"11450671576","pt":1717324419325,"mc":[{"id":"1.229554928","rc":[{"atb":[[4.9,16.74]],"id":52671548}],"con":true,"img":false}]}
{"op":"mcm","clk":"11450671588","pt":1717324419429,"mc":[{"id":"1.229554928","rc":[{"atl":[[26,5],[27,4.59]],"id":52237628},{"atb":[[40,3]],"id":52671565},{"atl":[[370,0.43]],"id":52671544}],"con":true,"img":false}]}
{"op":"mcm","clk":"11450671628","pt":1717324419703,"mc":[{"id":"1.229554928","rc":[{"atb":[[5.1,0]],"id":52237627},{"atb":[[32,3.89],[80,0.33],[42,1.92],[55,0.97]],"id":52671565}],"con":true,"img":false}]}
{"op":"mcm","clk":"11450671662","pt":1717324420026,"mc":[{"id":"1.229554928","rc":[{"atb":[[6.4,0],[8.4,0]],"id":52237628},{"atb":[[4.3,0],[5.3,29.03]],"id":52237627},{"atb":[[6.2,0],[8.2,0]],"id":52671563},{"atb":[[19.5,0],[29,0]],"id":52671565},{"atb":[[7.4,0],[9.4,0]],"id":52671561},{"atb":[[120,0],[60,0]],"id":52671560},{"atb":[[9,0],[12.5,0]],"id":52671555},{"atb":[[2.32,79.27],[2.12,0]],"id":52237624},{"atb":[[9.2,0],[13,0]],"id":52237612},{"atb":[[9.6,0],[14,0]],"id":52671550},{"atb":[[560,0],[460,0]],"id":52671546},{"atb":[[2.64,15.95],[2.44,54.5]],"id":52237617},{"atb":[[3.55,0],[3.05,0]],"id":52671548},{"atb":[[19,0],[14,0]],"id":52671542},{"atb":[[17.5,0],[12.5,0]],"id":52671544}],"con":true,"img":false}]}
{"op":"mcm","clk":"11450671714","pt":1717324420443,"mc":[{"id":"1.229554928","rc":[{"atb":[[32,3.37]],"id":52671565},{"atb":[[4.6,0]],"id":52671548},{"atl":[[880,0]],"id":52671542},{"atl":[[390,0]],"id":52671544}],"con":true,"img":false}]}
{"op":"mcm","clk":"11450671841","pt":1717324421514,"mc":[{"id":"1.229554928","rc":[{"atl":[[32,3.23],[30,5.52]],"id":52671563}],"con":true,"img":false}]}
{"op":"mcm","clk":"11450672043","pt":1717324423360,"mc":[{"id":"1.229554928","rc":[{"atl":[[9,0]],"id":52237627}],"con":true,"img":false}]}
{"op":"mcm","clk":"11450672131","pt":1717324424007,"mc":[{"id":"1.229554928","rc":[{"atl":[[15,11.44]],"id":52237627}],"con":true,"img":false}]}
{"op":"mcm","clk":"11450672150","pt":1717324424113,"mc":[{"id":"1.229554928","rc":[{"atl":[[25,11.68]],"id":52671563}],"con":true,"img":false}]}
{"op":"mcm","clk":"11450672237","pt":1717324424844,"mc":[{"id":"1.229554928","rc":[{"atl":[[30,0]],"id":52671563}],"con":true,"img":false}]}
{"op":"mcm","clk":"11450672319","pt":1717324425421,"mc":[{"id":"1.229554928","rc":[{"atb":[[5,5],[5.3,0],[4.9,4.31]],"id":52237627},{"atb":[[32,0],[80,0],[42,0],[55,0]],"id":52671565},{"atb":[[34,5.65]],"id":52671555},{"atl":[[60,7.72]],"id":52671555},{"atl":[[95,10.14],[100,0]],"id":52671550},{"atl":[[770,0],[780,2.94]],"id":52671542},{"atl":[[380,0],[390,4.14]],"id":52671544}],"con":true,"img":false}]}
{"op":"mcm","clk":"11450672332","pt":1717324425530,"mc":[{"id":"1.229554928","rc":[{"atl":[[46,3.01]],"id":52671563},{"atl":[[390,3.27]],"id":52671565},{"atl":[[55,3.56]],"id":52671561}],"con":true,"img":false}]}
{"op":"mcm","clk":"11450672412","pt":1717324426213,"mc":[{"id":"1.229554928","rc":[{"atl":[[16.5,3.36]],"id":52237627},{"atl":[[48,0],[50,3.13]],"id":52671561}],"con":true,"img":false}]}
{"op":"mcm","clk":"11450672451","pt":1717324426525,"mc":[{"id":"1.229554928","rc":[{"atb":[[4.9,19.36]],"id":52237627},{"atb":[[75,0.36],[40,5.02],[50,1.07],[30,3.61]],"id":52671565},{"atb":[[27,2.01]],"id":52671555},{"atl":[[65,0]],"id":52671555}],"con":true,"img":false}]}
{"op":"mcm","clk":"11450672520","pt":1717324427036,"mc":[{"id":"1.229554928","rc":[{"atb":[[19.5,3.08]],"id":52671555}],"con":true,"img":false}]}
{"op":"mcm","clk":"11450672582","pt":1717324427457,"mc":[{"id":"1.229554928","rc":[{"atl":[[200,3.11]],"id":52237612}],"con":true,"img":false}]}
{"op":"mcm","clk":"11450672643","pt":1717324427911,"mc":[{"id":"1.229554928","rc":[{"atb":[[10.5,10.9],[11,0]],"id":52237628},{"atb":[[130,4.58],[140,0.57]],"id":52671560},{"atb":[[18,0],[19.5,0],[21,0]],"id":52671555},{"atb":[[2.42,55.26],[2.52,44.75]],"id":52237624},{"atb":[[19.5,0],[20,2.79]],"id":52237612},{"atb":[[2.82,8.62],[2.68,0]],"id":52237617},{"atb":[[40,4.64],[42,1.92]],"id":52671542},{"atb":[[70,7.71],[36,0]],"id":52671544}],"con":true,"img":false}]}
{"op":"mcm","clk":"11450672719","pt":1717324428640,"mc":[{"id":"1.229554928","rc":[{"atb":[[60,0]],"id":52671544}],"con":true,"img":false}]}
{"op":"mcm","clk":"11450672962","pt":1717324430527,"mc":[{"id":"1.229554928","rc":[{"atb":[[6.4,45.16],[8.4,14.12]],"id":52237628},{"atb":[[4.3,73.9],[5.3,24.31]],"id":52237627},{"atb":[[6.2,46.9],[8.2,14.51]],"id":52671563},{"atb":[[19.5,13.18],[29,3.73]],"id":52671565},{"atb":[[7.4,38.1],[9.4,12.44]],"id":52671561},{"atb":[[120,0.87],[60,4.13]],"id":52671560},{"atb":[[9,30.48],[12.5,9.08]],"id":52671555},{"atb":[[2.32,158.46],[2.12,217.77]],"id":52237624},{"atb":[[9.2,29.74],[13,8.71]],"id":52237612},{"atb":[[9.6,28.36],[14,8.04]],"id":52671550},{"atb":[[560,0.18],[460,0.53]],"id":52671546},{"atb":[[2.64,79.69],[2.44,223.88]],"id":52237617},{"atb":[[3.55,40.99],[3.05,118.97]],"id":52671548},{"atb":[[19,5.8],[14,18.76]],"id":52671542},{"atb":[[17.5,6.33],[12.5,21.2]],"id":52671544}],"con":true,"img":false}]}
{"op":"mcm","clk":"11450672988","pt":1717324430742,"mc":[{"id":"1.229554928","rc":[{"atl":[[16.5,0]],"id":52237627},{"atl":[[360,2.86],[370,0]],"id":52671565},{"atl":[[48,3.44],[50,0]],"id":52671561},{"atl":[[220,0]],"id":52237612},{"atb":[[2.82,0],[2.8,8.72]],"id":52237617},{"atb":[[34,4.2]],"id":52671544}],"con":true,"img":false}]}
{"op":"mcm","clk":"11450673032","pt":1717324431004,"mc":[{"id":"1.229554928","rc":[{"atb":[[18,2.91],[19,3.46]],"id":52671555}],"con":true,"img":false}]}
{"op":"mcm","clk":"11450673443","pt":1717324434240,"mc":[{"id":"1.229554928","rc":[{"atb":[[3.85,35.09],[3.55,41.03]],"id":52237627},{"atl":[[320,0],[250,2]],"id":52671550}],"con":true,"img":false}]}
{"op":"mcm","clk":"11450673474","pt":1717324434552,"mc":[{"id":"1.229554928","rc":[{"atb":[[9.2,0],[10.5,2.63],[13,0],[15.5,11.04]],"id":52237628},{"atl":[[18,3.57]],"id":52237627},{"atb":[[9.6,0],[8.6,0],[9.2,11.59],[11.5,0],[7.6,0],[9.8,5]],"id":52671563},{"atb":[[75,0],[40,3],[50,0],[30,0]],"id":52671565},{"atl":[[370,3.87]],"id":52671565},{"atb":[[25,5],[29,0]],"id":52671555},{"atb":[[2.74,38.43],[2.76,5]],"id":52237624},{"atb":[[38,5.04],[30,5]],"id":52671550},{"atl":[[70,5],[80,3.92],[95,1.7]],"id":52671550},{"atl":[[6.8,0]],"id":52237617},{"atl":[[700,3.16]],"id":52671542}],"con":true,"img":false}]}
{"op":"mcm","clk":"11450673487","pt":1717324434613,"mc":[{"id":"1.229554928","rc":[{"atb":[[15.5,0]],"id":52237628},{"atl":[[21,0]],"id":52237628},{"atb":[[5.5,3.31],[4.9,15.05],[5.4,27.54]],"id":52237627},{"atl":[[360,0]],"id":52671565},{"atb":[[34,0],[18.5,0],[22,0],[27,0]],"id":52671555},{"atl":[[6.4,5]],"id":52237617},{"atl":[[780,0]],"id":52671542}],"con":true,"img":false}]}
{"op":"mcm","clk":"11450673515","pt":1717324434827,"mc":[{"id":"1.229554928","rc":[{"atb":[[10.5,0]],"id":52237628},{"atb":[[130,0],[140,3.91]],"id":52671560},{"atb":[[19,0],[19.5,3.21]],"id":52671555},{"atb":[[2.52,34.42],[2.44,10.89]],"id":52237624},{"atb":[[2.8,0],[2.7,9.23]],"id":52237617},{"atb":[[40,0],[42,6.54]],"id":52671542},{"atb":[[34,0],[36,4.56]],"id":52671544}],"con":true,"img":false}]}
{"op":"mcm","clk":"11450673532","pt":1717324434925,"mc":[{"id":"1.229554928","rc":[{"atl":[[9.2,0],[8.8,5]],"id":52237627},{"atb":[[17.5,11.3],[18,5]],"id":52671561},{"atb":[[95,1.7],[100,5]],"id":52671542},{"atl":[[690,0.23]],"id":52671542}],"con":true,"img":false}]}
{"op":"mcm","clk":"11450673547","pt":1717324435026,"mc":[{"id":"1.229554928","rc":[{"atb":[[9.8,15.23]],"id":52671563},{"atb":[[2.76,44.85]],"id":52237624},{"atl":[[70,7.32]],"id":52671550}],"con":true,"img":false}]}
{"op":"mcm","clk":"11450673573","pt":1717324435238,"mc":[{"id":"1.229554928","rc":[{"atb":[[12,4.76],[9.8,8.92],[8.8,13.41],[14.5,1.94]],"id":52237628},{"atb":[[9.2,21.16],[10.5,5.51],[8.2,29.05],[13,2.18]],"id":52671563},{"atb":[[70,0.38],[38,10.13],[48,1.11],[29,7.47]],"id":52671565}],"con":true,"img":false}]}
{"op":"mcm","clk":"11450673589","pt":1717324435339,"mc":[{"id":"1.229554928","rc":[{"atb":[[10,9.57]],"id":52237628},{"atl":[[27,10.76]],"id":52237628},{"atb":[[4.9,0]],"id":52237627},{"atb":[[18.5,9.15]],"id":52671561},{"atb":[[32,0.84],[18,9.07],[20,8.43],[21,3.92],[26,2.09]],"id":52671555},{"atb":[[100,6.62]],"id":52671542}],"con":true,"img":false}]}
{"op":"mcm","clk":"11450673615","pt":1717324435544,"mc":[{"id":"1.229554928","rc":[{"atl":[[290,2],[320,0]],"id":52671565},{"atl":[[140,2],[170,0]],"id":52671555}],"con":true,"img":false}]}
{"op":"mcm","clk":"11450673630","pt":1717324435675,"mc":[{"id":"1.229554928","rc":[{"atb":[[10.5,4.33]],"id":52237628},{"atl":[[26,9.71],[27,6.16]],"id":52237628},{"atl":[[38,3.58],[42,0]],"id":52671563},{"atl":[[320,3.93],[180,5],[190,0.84],[370,0]],"id":52671565},{"atl":[[44,4.33],[48,0]],"id":52671561},{"atb":[[130,4.62],[140,0.57]],"id":52671560},{"atb":[[19.5,0],[19,3.09]],"id":52671555},{"atl":[[65,4.2],[70,0]],"id":52671555},{"atl":[[75,3.77],[80,0]],"id":52671550},{"atb":[[2.8,8.72],[2.7,0]],"id":52237617},{"atb":[[42,1.92]],"id":52671542},{"atl":[[710,0]],"id":52671542},{"atb":[[34,3.63],[36,0]],"id":52671544}],"con":true,"img":false}]}
{"op":"mcm","clk":"11450673645","pt":1717324435709,"mc":[{"id":"1.229554928","rc":[{"atb":[[9.2,9.57]],"id":52671563},{"atb":[[2.74,0]],"id":52237624},{"atl":[[95,0]],"id":52671550}],"con":true,"img":false}]}
{"op":"mcm","clk":"11450673667","pt":1717324435912,"mc":[{"id":"1.229554928","rc":[{"atb":[[12,0],[9.8,0],[8.8,0],[14.5,0]],"id":52237628},{"atb":[[38,7.13]],"id":52671565}],"con":true,"img":false}]}
{"op":"mcm","clk":"11450673678","pt":1717324436025,"mc":[{"id":"1.229554928","rc":[{"atb":[[17.5,1.59]],"id":52671561},{"atb":[[95,0]],"id":52671542}],"con":true,"img":false}]}
{"op":"mcm","clk":"11450673693","pt":1717324436124,"mc":[{"id":"1.229554928","rc":[{"atl":[[180,5.9]],"id":52671565}],"con":true,"img":false}]}
{"op":"mcm","clk":"11450673711","pt":1717324436335,"mc":[{"id":"1.229554928","rc":[{"atb":[[2.52,44.75],[2.44,0]],"id":52237624},{"atl":[[690,4.88],[700,0]],"id":52671542},{"atl":[[380,3.71],[390,0]],"id":52671544}],"con":true,"img":false}]}
{"op":"mcm","clk":"11450673740","pt":1717324436550,"mc":[{"id":"1.229554928","rc":[{"atl":[[26,5],[27,9.41]],"id":52237628},{"atl":[[8.8,25.54]],"id":52237627},{"atl":[[38,0],[42,2.69]],"id":52671563},{"atl":[[320,0],[370,3.66]],"id":52671565},{"atl":[[44,0],[48,3.14]],"id":52671561},{"atl":[[65,0],[70,3.48]],"id":52671555},{"atl":[[75,0],[80,2.67]],"id":52671550}],"con":true,"img":false}]}
{"op":"mcm","clk":"11450673749","pt":1717324436646,"mc":[{"id":"1.229554928","rc":[{"atb":[[9,13.08],[10,18.3],[12.5,4.55],[15,1.87]],"id":52237628}],"con":true,"img":false}]}
{"op":"mcm","clk":"11450673762","pt":1717324436742,"mc":[{"id":"1.229554928","rc":[{"atl":[[360,4.08]],"id":52671565},{"atb":[[2.8,0],[2.82,8.62]],"id":52237617}],"con":true,"img":false}]}
{"op":"mcm","clk":"11450673775","pt":1717324436800,"mc":[{"id":"1.229554928","rc":[{"atl":[[190,0]],"id":52671565}],"con":true,"img":false}]}
{"op":"mcm","clk":"11450673833","pt":1717324437326,"mc":[{"id":"1.229554928","rc":[{"atl":[[15,0]],"id":52237627}],"con":true,"img":false}]}
{"op":"mcm","clk":"11450673916","pt":1717324438010,"mc":[{"id":"1.229554928","rc":[{"atl":[[370,0],[390,0]],"id":52671565},{"atb":[[40,4.29]],"id":52671542}],"con":true,"img":false}]}
{"op":"mcm","clk":"11450673998","pt":1717324438736,"mc":[{"id":"1.229554928","rc":[{"atb":[[4,29.54],[4.1,5]],"id":52237617}],"con":true,"img":false}]}
{"op":"mcm","clk":"11450674025","pt":1717324438947,"mc":[{"id":"1.229554928","rc":[{"atb":[[5.5,38.91]],"id":52237627}],"con":true,"img":false}]}
{"op":"mcm","clk":"11450674051","pt":1717324439101,"mc":[{"id":"1.229554928","rc":[{"atb":[[4.1,56.68]],"id":52237617}],"con":true,"img":false}]}
{"op":"mcm","clk":"11450674098","pt":1717324439647,"mc":[{"id":"1.229554928","rc":[{"atb":[[5.4,0]],"id":52237627},{"atb":[[70,2.7],[80,5]],"id":52671544}],"con":true,"img":false}]}
{"op":"mcm","clk":"11450674113","pt":1717324439706,"mc":[{"id":"1.229554928","rc":[{"atb":[[9,0],[10,9.57],[10.5,0],[12.5,0],[15,0]],"id":52237628},{"atb":[[130,0],[140,4.8]],"id":52671560},{"atb":[[19,0],[19.5,4.34]],"id":52671555},{"atb":[[2.4,11.21],[2.32,79.18],[2.42,0],[2.52,0],[2.62,0]],"id":52237624},{"atb":[[20,0]],"id":52237612},{"atb":[[2.82,0]],"id":52237617},{"atb":[[5.1,0],[5.2,3.63]],"id":52671548},{"atb":[[40,0],[42,6.27]],"id":52671542}],"con":true,"img":false}]}
{"op":"mcm","clk":"11450674132","pt":1717324439810,"mc":[{"id":"1.229554928","rc":[{"atb":[[4,0]],"id":52237617}],"con":true,"img":false}]}
{"op":"mcm","clk":"11450674204","pt":1717324440333,"mc":[{"id":"1.229554928","rc":[{"atb":[[80,7.03]],"id":52671544}],"con":true,"img":false}]}
{"op":"mcm","clk":"11450674216","pt":1717324440434,"mc":[{"id":"1.229554928","rc":[{"atb":[[12,4.76],[9.8,8.92],[8.8,13.41],[14.5,1.94]],"id":52237628},{"atb":[[2.38,68.24],[2.28,81.75],[2.58,16.56],[2.48,35.35]],"id":52237624}],"con":true,"img":false}]}
{"op":"mcm","clk":"11450674251","pt":1717324440650,"mc":[{"id":"1.229554928","rc":[{"atl":[[16.5,3.6],[17,0]],"id":52237627},{"atl":[[40,4.28],[42,0]],"id":52671563},{"atl":[[48,0],[50,4.22]],"id":52671561},{"atl":[[65,2.96],[70,0]],"id":52671555},{"atl":[[80,0],[85,3.91]],"id":52671550},{"atb":[[2.76,8.92]],"id":52237617},{"atb":[[75,5],[80,2.02]],"id":52671544}],"con":true,"img":false}]}
{"op":"mcm","clk":"11450674296","pt":1717324441021,"mc":[{"id":"1.229554928","rc":[{"atl":[[840,0]],"id":52671560},{"atl":[[180,0],[190,8.17]],"id":52237612},{"atl":[[690,0.23],[730,3.09]],"id":52671542},{"atl":[[380,0],[400,4.04]],"id":52671544}],"con":true,"img":false}]}
{"op":"mcm","clk":"11450674309","pt":1717324441122,"mc":[{"id":"1.229554928","rc":[{"atb":[[70,0.38],[80,0]],"id":52671544}],"con":true,"img":false}]}
{"op":"mcm","clk":"11450674412","pt":1717324441920,"mc":[{"id":"1.229554928","rc":[{"atl":[[1000,0.6]],"id":52671560},{"atb":[[75,6.22]],"id":52671544}],"con":true,"img":false}]}
{"op":"mcm","clk":"11450674760","pt":1717324444649,"mc":[{"id":"1.229554928","rc":[{"atb":[[9.6,2.66]],"id":52237628},{"atl":[[24,5],[25,6.67]],"id":52671563},{"atl":[[34,5],[36,4.57]],"id":52671561}],"con":true,"img":false}]}
{"op":"mcm","clk":"11450674778","pt":1717324444746,"mc":[{"id":"1.229554928","rc":[{"atl":[[380,3.4]],"id":52671565}],"con":true,"img":false}]}
{"op":"mcm","clk":"11450674831","pt":1717324445122,"mc":[{"id":"1.229554928","rc":[{"atl":[[24,11.97]],"id":52671563},{"atl":[[34,9.86]],"id":52671561}],"con":true,"img":false}]}
{"op":"mcm","clk":"11450674886","pt":1717324445637,"mc":[{"id":"1.229554928","rc":[{"atb":[[10,6.91],[11,4.63],[12,0],[9.8,0],[8.8,0],[14.5,0]],"id":52237628},{"atb":[[19.5,0],[20,12.12]],"id":52671555},{"atb":[[2.4,0],[2.36,11.54],[2.38,11.37],[2.28,0],[2.58,0],[2.48,0]],"id":52237624},{"atb":[[19.5,2.62]],"id":52237612},{"atb":[[38,4.33],[19.5,0],[24,0],[29,0]],"id":52671550},{"atb":[[5.1,3.23],[5.2,0]],"id":52671548}],"con":true,"img":false}]}
{"op":"mcm","clk":"11450674910","pt":1717324445843,"mc":[{"id":"1.229554928","rc":[{"atl":[[25,0]],"id":52671563},{"atl":[[36,0]],"id":52671561},{"atl":[[90,3.97]],"id":52671550}],"con":true,"img":false}]}
{"op":"mcm","clk":"11450674924","pt":1717324445946,"mc":[{"id":"1.229554928","rc":[{"atl":[[27,6.16]],"id":52237628},{"atl":[[16.5,0],[15.5,10.55]],"id":52237627},{"atl":[[36,3.21],[40,0]],"id":52671563},{"atl":[[340,3.31],[360,0]],"id":52671565},{"atl":[[48,4.16],[50,0]],"id":52671561},{"atl":[[85,0]],"id":52671550}],"con":true,"img":false}]}
{"op":"mcm","clk":"11450674936","pt":1717324446046,"mc":[{"id":"1.229554928","rc":[{"atb":[[130,3.32],[140,0.57]],"id":52671560},{"atb":[[18.5,5.98]],"id":52237612},{"atb":[[38,3.79],[42,1.92]],"id":52671542},{"atb":[[34,0]],"id":52671544}],"con":true,"img":false}]}
{"op":"mcm","clk":"11450674976","pt":1717324446319,"mc":[{"id":"1.229554928","rc":[{"atb":[[9.2,12.76],[10.5,8.26],[13,4.36],[15.5,1.81]],"id":52237628},{"atb":[[2.24,84.38],[2.54,16.99],[2.44,36.33],[2.34,58.56]],"id":52237624},{"atb":[[40,0.67],[20,5.51],[25,3.27],[30,6.81]],"id":52671550}],"con":true,"img":false}]}
{"op":"mcm","clk":"11450674996","pt":1717324446418,"mc":[{"id":"1.229554928","rc":[{"atl":[[21,5],[26,0]],"id":52671548}],"con":true,"img":false}]}
{"op":"mcm","clk":"11450675038","pt":1717324446736,"mc":[{"id":"1.229554928","rc":[{"atl":[[27,10.01]],"id":52237628},{"atl":[[16,4.3],[15.5,6.9]],"id":52237627},{"atl":[[36,0],[38,3.73]],"id":52671563},{"atl":[[340,0],[360,3.88]],"id":52671565},{"atl":[[48,0],[50,3.26]],"id":52671561},{"atb":[[2.38,0]],"id":52237624},{"atb":[[19.5,0]],"id":52237612}],"con":true,"img":false}]}
{"op":"mcm","clk":"11450675053","pt":1717324446839,"mc":[{"id":"1.229554928","rc":[{"atb":[[40,4.78]],"id":52671550}],"con":true,"img":false}]}
{"op":"mcm","clk":"11450675138","pt":1717324447512,"mc":[{"id":"1.229554928","rc":[{"atl":[[26,11.41]],"id":52237628}],"con":true,"img":false}]}
{"op":"mcm","clk":"11450675149","pt":1717324447622,"mc":[{"id":"1.229554928","rc":[{"atb":[[38,0]],"id":52671550}],"con":true,"img":false}]}
{"op":"mcm","clk":"11450675229","pt":1717324448245,"mc":[{"id":"1.229554928","rc":[{"atl":[[27,3.85]],"id":52237628}],"con":true,"img":false}]}
{"op":"mcm","clk":"11450675285","pt":1717324448669,"mc":[{"id":"1.229554928","rc":[{"atb":[[2.72,9.12]],"id":52237617}],"con":true,"img":false}]}
{"op":"mcm","clk":"11450675317","pt":1717324448940,"mc":[{"id":"1.229554928","rc":[{"atl":[[16,0],[16.5,3.04]],"id":52237627},{"atl":[[38,0],[40,3.22]],"id":52671563},{"atl":[[360,0]],"id":52671565},{"atl":[[50,0]],"id":52671561}],"con":true,"img":false}]}
{"op":"mcm","clk":"11450675366","pt":1717324449357,"mc":[{"id":"1.229554928","rc":[{"atl":[[9,5],[8.8,0]],"id":52237627}],"con":true,"img":false}]}
{"op":"mcm","clk":"11450675450","pt":1717324450044,"mc":[{"id":"1.229554928","rc":[{"atl":[[15,11.44]],"id":52237627}],"con":true,"img":false}]}
{"op":"mcm","clk":"11450675771","pt":1717324452925,"mc":[{"id":"1.229554928","rc":[{"atb":[[2.66,0]],"id":52237617}],"con":true,"img":false}]}
{"op":"mcm","clk":"11450675849","pt":1717324453556,"mc":[{"id":"1.229554928","rc":[{"atb":[[19,4.33]],"id":52671555},{"atb":[[2.32,91.07]],"id":52237624}],"con":true,"img":false}]}
{"op":"mcm","clk":"11450675909","pt":1717324453972,"mc":[{"id":"1.229554928","rc":[{"atb":[[6.4,0],[8.4,0]],"id":52237628},{"atb":[[4.3,0],[5.3,0]],"id":52237627},{"atb":[[6.2,0],[8.2,14.53]],"id":52671563},{"atb":[[19.5,0],[29,3.74]],"id":52671565},{"atb":[[7.4,0],[9.4,0]],"id":52671561},{"atb":[[120,0],[60,0]],"id":52671560},{"atb":[[9,0],[12.5,0]],"id":52671555},{"atb":[[2.32,11.89],[2.12,0]],"id":52237624},{"atb":[[9.2,0],[13,0]],"id":52237612},{"atb":[[9.6,0],[14,0]],"id":52671550},{"atb":[[560,0],[460,0]],"id":52671546},{"atb":[[2.64,15.95],[2.44,54.5]],"id":52237617},{"atb":[[3.55,0],[3.05,0]],"id":52671548},{"atb":[[19,0],[14,0]],"id":52671542},{"atl":[[750,3.28]],"id":52671542},{"atb":[[17.5,0],[12.5,0]],"id":52671544}],"con":true,"img":false}]}
{"op":"mcm","clk":"11450675948","pt":1717324454246,"mc":[{"id":"1.229554928","rc":[{"atb":[[26,0],[29,5]],"id":52237612}],"con":true,"img":false}]}
{"op":"mcm","clk":"11450675961","pt":1717324454354,"mc":[{"id":"1.229554928","rc":[{"atb":[[30,3.45]],"id":52237612}],"con":true,"img":false}]}
{"op":"mcm","clk":"11450675977","pt":1717324454458,"mc":[{"id":"1.229554928","rc":[{"atb":[[28,0]],"id":52237612}],"con":true,"img":false}]}
{"op":"mcm","clk":"11450675990","pt":1717324454558,"mc":[{"id":"1.229554928","rc":[{"atb":[[18,6.15]],"id":52671555},{"atb":[[32,4.69]],"id":52671544}],"con":true,"img":false}]}
{"op":"mcm","clk":"11450676002","pt":1717324454667,"mc":[{"id":"1.229554928","rc":[{"atb":[[10,11.53]],"id":52237628},{"atl":[[400,3.01]],"id":52671565},{"atl":[[65,3.4]],"id":52671561}],"con":true,"img":false}]}
{"op":"mcm","clk":"11450676091","pt":1717324455255,"mc":[{"id":"1.229554928","rc":[{"atl":[[830,0]],"id":52671542}],"con":true,"img":false}]}
{"op":"mcm","clk":"11450676177","pt":1717324455677,"mc":[{"id":"1.229554928","rc":[{"atb":[[9.6,0]],"id":52237628},{"atb":[[130,0],[140,4.86]],"id":52671560},{"atb":[[38,0],[42,6.36]],"id":52671542},{"atb":[[32,0],[34,3.45]],"id":52671544}],"con":true,"img":false}]}
{"op":"mcm","clk":"11450676333","pt":1717324456740,"mc":[{"id":"1.229554928","rc":[{"atb":[[5.3,4.45]],"id":52237627}],"con":true,"img":false}]}
{"op":"mcm","clk":"11450676463","pt":1717324457839,"mc":[{"id":"1.229554928","rc":[{"atb":[[4.7,0]],"id":52237627},{"atb":[[28,5]],"id":52237612}],"con":true,"img":false}]}
{"op":"mcm","clk":"11450676475","pt":1717324457938,"mc":[{"id":"1.229554928","rc":[{"atb":[[29,0]],"id":52237612}],"con":true,"img":false}]}
{"op":"mcm","clk":"11450676487","pt":1717324458037,"mc":[{"id":"1.229554928","rc":[{"atb":[[29,3.57],[30,0]],"id":52237612},{"atl":[[190,5]],"id":52237612},{"atl":[[730,0],[740,3.33]],"id":52671542},{"atl":[[400,0],[410,3.16]],"id":52671544}],"con":true,"img":false}]}
{"op":"mcm","clk":"11450676589","pt":1717324458822,"mc":[{"id":"1.229554928","rc":[{"atb":[[3.4,41.67],[3.25,0]],"id":52237617}],"con":true,"img":false}]}
{"op":"mcm","clk":"11450676629","pt":1717324459140,"mc":[{"id":"1.229554928","rc":[{"atl":[[370,3.61]],"id":52671565},{"atb":[[18.5,10.42],[19.5,4.29]],"id":52237612}],"con":true,"img":false}]}
{"op":"mcm","clk":"11450676640","pt":1717324459244,"mc":[{"id":"1.229554928","rc":[{"atb":[[9.2,0],[10.5,3.52],[11,0],[13,0],[15.5,0]],"id":52237628},{"atl":[[380,0]],"id":52671565},{"atb":[[32,0],[18,0],[20,8.43],[21,0],[26,0]],"id":52671555},{"atb":[[2.36,0],[2.42,11.05]],"id":52237624},{"atb":[[2.78,8.81],[2.76,0]],"id":52237617}],"con":true,"img":false}]}
{"op":"mcm","clk":"11450676686","pt":1717324459658,"mc":[{"id":"1.229554928","rc":[{"atb":[[25,11.68]],"id":52671555}],"con":true,"img":false}]}
{"op":"mcm","clk":"11450676696","pt":1717324459757,"mc":[{"id":"1.229554928","rc":[{"atb":[[13.5,15.2]],"id":52237628}],"con":true,"img":false}]}
{"op":"mcm","clk":"11450676724","pt":1717324459962,"mc":[{"id":"1.229554928","rc":[{"atb":[[12,4.76],[9.8,8.92],[8.8,13.41],[14.5,1.94]],"id":52237628},{"atb":[[17.5,6.34],[20,12.56],[25,13.86],[30,0.9]],"id":52671555}],"con":true,"img":false}]}
{"op":"mcm","clk":"11450676757","pt":1717324460230,"mc":[{"id":"1.229554928","rc":[{"atl":[[26,14.19],[27,0]],"id":52237628},{"atl":[[360,3.64],[370,0]],"id":52671565},{"atl":[[50,3.63],[55,0]],"id":52671561},{"atl":[[65,0],[70,3.77]],"id":52671555},{"atb":[[2.4,11.21],[2.42,0]],"id":52237624},{"atb":[[19.5,0],[20,3.22]],"id":52237612},{"atl":[[85,3.47],[90,0]],"id":52671550},{"atb":[[2.8,8.72],[2.78,0]],"id":52237617}],"con":true,"img":false}]}
{"op":"mcm","clk":"11450676767","pt":1717324460331,"mc":[{"id":"1.229554928","rc":[{"atb":[[20,4.13]],"id":52671555}],"con":true,"img":false}]}
{"op":"mcm","clk":"11450676776","pt":1717324460435,"mc":[{"id":"1.229554928","rc":[{"atb":[[10,4.61]],"id":52237628}],"con":true,"img":false}]}
