{"op":"mcm","clk":"11449075394","pt":1717303241533,"mc":[{"id":"1.229554922","marketDefinition":{"bspMarket":false,"turnInPlayEnabled":false,"persistenceEnabled":false,"marketBaseRate":7.0,"eventId":"33318908","eventTypeId":"4339","numberOfWinners":1,"bettingType":"ODDS","marketType":"EXACTA","marketTime":"2024-06-02T10:24:00.000Z","suspendTime":"2024-06-02T10:24:00.000Z","bspReconciled":false,"complete":true,"inPlay":false,"crossMatching":true,"runnersVoidable":false,"numberOfActiveRunners":42,"betDelay":0,"status":"OPEN","runners":[{"status":"ACTIVE","sortPriority":1,"id":52385882,"name":"1 - 2"},{"status":"ACTIVE","sortPriority":2,"id":52385883,"name":"1 - 3"},{"status":"ACTIVE","sortPriority":3,"id":52385884,"name":"1 - 4"},{"status":"ACTIVE","sortPriority":4,"id":52385886,"name":"1 - 6"},{"status":"ACTIVE","sortPriority":5,"id":52385887,"name":"1 - 7"},{"status":"ACTIVE","sortPriority":6,"id":52385888,"name":"1 - 8"},{"status":"ACTIVE","sortPriority":7,"id":52385889,"name":"2 - 1"},{"status":"ACTIVE","sortPriority":8,"id":52385890,"name":"2 - 3"},{"status":"ACTIVE","sortPriority":9,"id":52385891,"name":"2 - 4"},{"status":"ACTIVE","sortPriority":10,"id":52385893,"name":"2 - 6"},{"status":"ACTIVE","sortPriority":11,"id":52385894,"name":"2 - 7"},{"status":"ACTIVE","sortPriority":12,"id":52385895,"name":"2 - 8"},{"status":"ACTIVE","sortPriority":13,"id":52385896,"name":"3 - 1"},{"status":"ACTIVE","sortPriority":14,"id":52385897,"name":"3 - 2"},{"status":"ACTIVE","sortPriority":15,"id":52385898,"name":"3 - 4"},{"status":"ACTIVE","sortPriority":16,"id":52385900,"name":"3 - 6"},{"status":"ACTIVE","sortPriority":17,"id":52385901,"name":"3 - 7"},{"status":"ACTIVE","sortPriority":18,"id":52385902,"name":"3 - 8"},{"status":"ACTIVE","sortPriority":19,"id":52385903,"name":"4 - 1"},{"status":"ACTIVE","sortPriority":20,"id":52385904,"name":"4 - 2"},{"status":"ACTIVE","sortPriority":21,"id":52385905,"name":"4 - 3"},{"status":"ACTIVE","sortPriority":22,"id":52385907,"name":"4 - 6"},{"status":"ACTIVE","sortPriority":23,"id":52385908,"name":"4 - 7"},{"status":"ACTIVE","sortPriority":24,"id":52385909,"name":"4 - 8"},{"status":"ACTIVE","sortPriority":25,"id":52385917,"name":"6 - 1"},{"status":"ACTIVE","sortPriority":26,"id":52385918,"name":"6 - 2"},{"status":"ACTIVE","sortPriority":27,"id":52385919,"name":"6 - 3"},{"status":"ACTIVE","sortPriority":28,"id":52385920,"name":"6 - 4"},{"status":"ACTIVE","sortPriority":29,"id":52385922,"name":"6 - 7"},{"status":"ACTIVE","sortPriority":30,"id":52385923,"name":"6 - 8"},{"status":"ACTIVE","sortPriority":31,"id":52385924,"name":"7 - 1"},{"status":"ACTIVE","sortPriority":32,"id":52385925,"name":"7 - 2"},{"status":"ACTIVE","sortPriority":33,"id":52385926,"name":"7 - 3"},{"status":"ACTIVE","sortPriority":34,"id":52385927,"name":"7 - 4"},{"status":"ACTIVE","sortPriority":35,"id":52385929,"name":"7 - 6"},{"status":"ACTIVE","sortPriority":36,"id":52385930,"name":"7 - 8"},{"status":"ACTIVE","sortPriority":37,"id":52385931,"name":"8 - 1"},{"status":"ACTIVE","sortPriority":38,"id":52385932,"name":"8 - 2"},{"status":"ACTIVE","sortPriority":39,"id":52385933,"name":"8 - 3"},{"status":"ACTIVE","sortPriority":40,"id":52385934,"name":"8 - 4"},{"status":"ACTIVE","sortPriority":41,"id":52385936,"name":"8 - 6"},{"status":"ACTIVE","sortPriority":42,"id":52385937,"name":"8 - 7"}],"regulators":["MR_INT"],"venue":"Murray Bridge","countryCode":"AU","discountAllowed":true,"timezone":"Australia/Adelaide","openDate":"2024-06-02T08:21:00.000Z","version":5962801943,"name":"Exacta","eventName":"Murray Bridge (AUS) 2nd Jun"},"rc":[],"con":true,"img":false}]}
{"op":"mcm","clk":"11449099382","pt":1717303849562,"mc":[{"id":"1.229554922","rc":[{"atb":[[21,5.22],[15.5,16.82]],"id":52385886},{"atb":[[10,27.1],[15,7.46]],"id":52385887},{"atb":[[4.5,69.68],[5.5,23.22]],"id":52385888},{"atb":[[5.7,22.24],[4.7,65.92]],"id":52385889},{"atb":[[5.7,22.24],[4.7,65.92]],"id":52385882},{"atb":[[5.3,56.72],[6.6,18.66]],"id":52385883},{"atb":[[13.5,8.36],[9.4,29.03]],"id":52385884},{"atb":[[10,27.1],[15,7.46]],"id":52385894},{"atb":[[4.5,69.68],[5.5,23.22]],"id":52385895},{"atb":[[5.5,54.2],[7,17.42]],"id":52385896},{"atb":[[5.5,54.2],[7,17.42]],"id":52385897},{"atb":[[5.3,56.72],[6.6,18.66]],"id":52385890},{"atb":[[13.5,8.36],[9.4,29.03]],"id":52385891},{"atb":[[21,5.22],[15.5,16.82]],"id":52385893},{"atb":[[5.3,56.72],[6.6,18.66]],"id":52385902},{"atb":[[9.8,27.71],[14.5,7.74]],"id":52385903},{"atb":[[9.8,27.71],[14.5,7.74]],"id":52385904},{"atb":[[16,6.96],[11,24.39]],"id":52385905},{"atb":[[10,27.1],[15,7.46]],"id":52385898},{"atb":[[17.5,14.77],[25,4.35]],"id":52385900},{"atb":[[17,6.53],[12,22.17]],"id":52385901}],"con":true,"img":false}]}
{"op":"mcm","clk":"11449099395","pt":1717303849820,"mc":[{"id":"1.229554922","rc":[{"atb":[[44,2.43],[27,9.38]],"id":52385908},{"atb":[[17.5,14.77],[25,4.35]],"id":52385918},{"atb":[[260,0.94],[360,0.29]],"id":52385920},{"atb":[[46,2.32],[28,9.03]],"id":52385927},{"atb":[[410,0.59],[510,0.2]],"id":52385929},{"atb":[[17,15.24],[24,4.54]],"id":52385923},{"atb":[[16.5,6.74],[11.5,23.22]],"id":52385925},{"atb":[[9.8,27.71],[14.5,7.74]],"id":52385937},{"atb":[[4.5,69.68],[5.5,23.22]],"id":52385931},{"atb":[[5.1,59.49],[6.2,20.1]],"id":52385933},{"atb":[[330,0.31],[230,1.06]],"id":52385907},{"atb":[[9.8,27.71],[14.5,7.74]],"id":52385909},{"atb":[[19.5,13.18],[29,3.73]],"id":52385919},{"atb":[[17.5,14.77],[25,4.35]],"id":52385917},{"atb":[[18,6.14],[13,20.32]],"id":52385926},{"atb":[[530,0.19],[430,0.57]],"id":52385922},{"atb":[[16.5,6.74],[11.5,23.22]],"id":52385924},{"atb":[[9.2,29.74],[13,8.71]],"id":52385934},{"atb":[[20,5.5],[15,17.42]],"id":52385936},{"atb":[[16,6.96],[11,24.39]],"id":52385930},{"atb":[[4.4,71.73],[5.4,23.75]],"id":52385932}],"con":true,"img":false}]}
{"op":"mcm","clk":"11449225677","pt":1717305840462,"mc":[{"id":"1.229554922","rc":[{"atb":[[34,3.17],[85,0.31],[44,4.26],[60,0.88]],"id":52385908},{"atb":[[140,0.19],[70,1.14],[95,0.55],[48,2.23]],"id":52385918},{"atb":[[17.5,4.76],[20,2.75],[25,1.09],[15,14.94]],"id":52385887},{"atb":[[290,0.27],[340,0.15],[390,0.07],[240,0.44]],"id":52385920},{"atb":[[12,2.38],[9.8,5.94],[8.8,10.06],[7.8,15.39]],"id":52385889},{"atb":[[9.6,9.12],[8.6,13.77],[11.5,4.98],[14,2.01]],"id":52385883},{"atb":[[36,1.5],[46,0.58],[23,4.76],[28,2.91]],"id":52385894},{"atb":[[75,0.71],[40,2.68],[100,0.27],[50,1.6]],"id":52385927},{"atb":[[8,11.21],[9,6.54],[10,2.91],[7,34.86]],"id":52385896},{"atb":[[170,0.31],[85,1.25],[220,0.12],[120,0.66]],"id":52385929},{"atb":[[11,5.23],[13.5,2.09],[8.4,14.14],[9.4,9.34]],"id":52385890},{"atb":[[140,0.19],[70,1.14],[95,0.55],[48,2.23]],"id":52385923},{"atb":[[70,0.38],[38,2.12],[48,1.11],[29,3.74]],"id":52385925},{"atb":[[12,2.38],[9.8,5.94],[8.8,10.06],[7.8,15.39]],"id":52385902},{"atb":[[34,2.38],[44,1.22],[27,4.02],[60,0.44]],"id":52385904},{"atb":[[16.5,1.69],[9.6,12.17],[11.5,7.48],[14,4.02]],"id":52385937},{"atb":[[17.5,4.76],[20,2.75],[25,1.09],[15,14.94]],"id":52385898},{"atb":[[5.8,16.35],[5.3,24.33],[7.6,3.97],[6.6,9.34]],"id":52385931},{"atb":[[65,0.41],[36,2.24],[46,1.16],[28,3.88]],"id":52385900},{"atb":[[8,14.95],[9,9.81],[10,5.81],[12.5,2.28]],"id":52385933},{"atb":[[140,0.57],[190,0.28],[95,1.11],[240,0.11]],"id":52385907},{"atb":[[38,1.41],[48,0.55],[24,4.55],[29,2.8]],"id":52385909},{"atb":[[70,0.38],[38,2.12],[48,1.11],[29,3.74]],"id":52385886},{"atb":[[9.6,6.08],[8.6,10.33],[11.5,2.49],[7.6,15.85]],"id":52385888},{"atb":[[12,2.38],[9.8,5.94],[8.8,10.06],[7.8,15.39]],"id":52385882},{"atb":[[150,0.18],[75,1.06],[100,0.53],[50,2.13]],"id":52385917},{"atb":[[70,0.38],[38,2.12],[48,1.11],[29,3.74]],"id":52385926},{"atb":[[11,2.62],[7.4,16.35],[8.4,10.61],[9.4,6.23]],"id":52385895},{"atb":[[12,4.76],[9.8,8.92],[8.8,13.41],[14.5,1.94]],"id":52385897},{"atb":[[300,0.09],[150,0.7],[200,0.39],[250,0.21]],"id":52385922},{"atb":[[40,0.67],[20,5.51],[25,3.27],[30,1.81]],"id":52385891},{"atb":[[32,1.69],[42,0.64],[21,5.23],[26,3.14]],"id":52385924},{"atb":[[34,3.17],[85,0.31],[44,1.83],[60,0.88]],"id":52385893},{"atb":[[17.5,3.17],[20,1.38],[12.5,9.1],[15,5.6]],"id":52385934},{"atb":[[38,0.71],[19.5,5.66],[24,3.41],[29,1.87]],"id":52385903},{"atb":[[38,1.41],[48,0.55],[24,4.55],[29,2.8]],"id":52385936},{"atb":[[34,2.38],[44,1.22],[27,4.02],[60,0.44]],"id":52385905},{"atb":[[36,1.5],[46,0.58],[23,4.76],[28,2.91]],"id":52385930},{"atb":[[11,2.62],[7.4,16.35],[8.4,10.61],[9.4,6.23]],"id":52385932},{"atb":[[16.5,5.06],[19,2.91],[23,1.19],[14,8.05]],"id":52385901}],"con":true,"img":false}]}
{"op":"mcm","clk":"11449225684","pt":1717305840567,"mc":[{"id":"1.229554922","rc":[{"atb":[[160,0.16],[80,0.99],[110,0.48],[55,1.94]],"id":52385919},{"atb":[[16.5,6.75],[19,4.36],[23,2.38],[28,0.97]],"id":52385884}],"con":true,"img":false}]}
{"op":"mcm","clk":"11449227019","pt":1717305859051,"mc":[{"id":"1.229554922","rc":[{"atb":[[12,0],[9.8,0],[8.8,0],[7.8,0]],"id":52385889},{"atb":[[160,0],[80,0],[110,0],[55,0]],"id":52385919},{"atb":[[150,0],[75,0],[100,0],[50,0]],"id":52385917},{"atb":[[40,0],[20,0],[25,0],[30,0]],"id":52385891},{"atb":[[34,0],[85,0],[44,0],[60,0]],"id":52385893}],"con":true,"img":false}]}
{"op":"mcm","clk":"11449227081","pt":1717305859772,"mc":[{"id":"1.229554922","rc":[{"atb":[[9.6,6.08],[8.6,10.33],[11.5,2.49],[7.6,15.85]],"id":52385889},{"atb":[[170,0.16],[85,0.94],[120,0.44],[60,1.77]],"id":52385919},{"atb":[[140,0.19],[70,1.14],[95,0.55],[48,2.23]],"id":52385917},{"atb":[[38,0.71],[19.5,5.66],[24,3.41],[29,1.87]],"id":52385891},{"atb":[[32,3.37],[80,0.33],[42,1.92],[55,0.97]],"id":52385893}],"con":true,"img":false}]}
{"op":"mcm","clk":"11449249280","pt":1717306178326,"mc":[{"id":"1.229554922","rc":[{"atb":[[170,0],[85,0],[120,0],[60,0]],"id":52385919},{"atb":[[12,0],[9.8,0],[8.8,0],[14.5,0]],"id":52385897}],"con":true,"img":false}]}
{"op":"mcm","clk":"11449249336","pt":1717306178993,"mc":[{"id":"1.229554922","rc":[{"atb":[[130,0.41],[65,1.64],[180,0.15],[90,0.88]],"id":52385919},{"atb":[[9.6,9.12],[8.6,13.77],[11.5,4.98],[14,2.01]],"id":52385897}],"con":true,"img":false}]}
{"op":"mcm","clk":"11449289064","pt":1717306703015,"mc":[{"id":"1.229554922","rc":[{"atb":[[17.5,0],[20,0],[25,0],[15,7.46]],"id":52385887},{"atb":[[290,0],[340,0],[390,0],[240,0]],"id":52385920},{"atb":[[9.6,0],[8.6,0],[11.5,0],[14,0]],"id":52385883},{"atb":[[8,0],[9,0],[10,0],[7,17.42]],"id":52385896},{"atb":[[170,0],[85,0],[220,0],[120,0]],"id":52385929},{"atb":[[12,0],[9.8,0],[8.8,0],[7.8,0]],"id":52385902},{"atb":[[17.5,0],[20,0],[25,0],[15,7.46]],"id":52385898},{"atb":[[65,0],[36,0],[46,0],[28,0]],"id":52385900},{"atb":[[140,0],[190,0],[95,0],[240,0]],"id":52385907},{"atb":[[70,0],[38,0],[48,0],[29,0]],"id":52385886},{"atb":[[130,0],[65,0],[180,0],[90,0]],"id":52385919},{"atb":[[16.5,0],[19,0],[23,0],[28,0]],"id":52385884},{"atb":[[140,0],[70,0],[95,0],[48,0]],"id":52385917},{"atb":[[70,0],[38,0],[48,0],[29,0]],"id":52385926},{"atb":[[300,0],[150,0],[200,0],[250,0]],"id":52385922},{"atb":[[16.5,0],[19,0],[23,0],[14,0]],"id":52385901}],"con":true,"img":false}]}
{"op":"mcm","clk":"11449289130","pt":1717306703797,"mc":[{"id":"1.229554922","rc":[{"atb":[[16,5.23],[18.5,2.99],[22,1.25],[13.5,8.37]],"id":52385887},{"atb":[[300,0.17],[350,0.07],[200,0.53],[250,0.31]],"id":52385920},{"atb":[[11,5.23],[13.5,2.09],[8.4,14.14],[9.4,9.34]],"id":52385883},{"atb":[[5.8,16.35],[5.3,24.33],[7.6,3.97],[6.6,9.34]],"id":52385896},{"atb":[[160,0.33],[80,1.32],[210,0.13],[110,0.72]],"id":52385929},{"atb":[[9.6,6.08],[8.6,10.33],[11.5,2.49],[7.6,15.85]],"id":52385902},{"atb":[[16,5.23],[18.5,2.99],[22,1.25],[13.5,8.37]],"id":52385898},{"atb":[[38,1.41],[48,0.55],[24,4.55],[29,2.8]],"id":52385900},{"atb":[[130,0.61],[180,0.29],[90,1.18],[230,1.18]],"id":52385907},{"atb":[[32,2.53],[42,1.28],[26,4.19],[55,0.49]],"id":52385886},{"atb":[[170,0.16],[85,0.94],[120,0.44],[60,1.77]],"id":52385919},{"atb":[[17.5,4.76],[20,2.75],[25,1.09],[15,7.48]],"id":52385884},{"atb":[[130,0.2],[65,1.22],[90,0.59],[46,2.32]],"id":52385917},{"atb":[[65,0.41],[36,2.24],[46,1.16],[28,3.88]],"id":52385926},{"atb":[[260,0.1],[160,0.49],[210,0.25],[110,0.96]],"id":52385922},{"atb":[[16.5,3.37],[19,1.45],[11.5,9.97],[14,6.04]],"id":52385901}],"con":true,"img":false}]}
{"op":"mcm","clk":"11449350021","pt":1717307639566,"mc":[{"id":"1.229554922","rc":[{"atb":[[170,0],[85,0],[120,0],[60,0]],"id":52385919}],"con":true,"img":false}]}
{"op":"mcm","clk":"11449350059","pt":1717307640283,"mc":[{"id":"1.229554922","rc":[{"atb":[[160,0.16],[80,0.99],[110,0.48],[55,1.94]],"id":52385919}],"con":true,"img":false}]}
{"op":"mcm","clk":"11449350277","pt":1717307646176,"mc":[{"id":"1.229554922","rc":[{"atb":[[34,0],[85,0],[44,2.43],[60,0]],"id":52385908},{"atb":[[75,0],[40,0],[100,0],[50,0]],"id":52385927},{"atb":[[16.5,0],[9.6,0],[11.5,0],[14,0]],"id":52385937},{"atb":[[5.8,0],[5.3,0],[7.6,0],[6.6,0]],"id":52385931},{"atb":[[38,0],[48,0],[24,0],[29,0]],"id":52385909},{"atb":[[17.5,0],[20,0],[12.5,0],[15,0]],"id":52385934},{"atb":[[38,0],[19.5,0],[24,0],[29,0]],"id":52385903},{"atb":[[38,0],[48,0],[24,0],[29,0]],"id":52385936},{"atb":[[36,0],[46,0],[23,0],[28,0]],"id":52385930}],"con":true,"img":false}]}
{"op":"mcm","clk":"11449350297","pt":1717307646894,"mc":[{"id":"1.229554922","rc":[{"atb":[[65,0.82],[36,2.99],[90,0.29],[46,1.74]],"id":52385908},{"atb":[[80,0.66],[42,2.55],[110,0.24],[55,1.45]],"id":52385927},{"atb":[[16.5,5.06],[19,2.91],[23,1.19],[14,8.05]],"id":52385937},{"atb":[[8,11.21],[9,6.54],[10,2.91],[7,17.44]],"id":52385931},{"atb":[[32,2.53],[42,1.28],[26,4.19],[55,0.49]],"id":52385909},{"atb":[[17,6.54],[19.5,4.24],[24,2.28],[29,0.94]],"id":52385934},{"atb":[[40,0.67],[20,5.51],[25,3.27],[30,1.81]],"id":52385903},{"atb":[[34,2.38],[44,1.22],[27,4.02],[60,0.44]],"id":52385936},{"atb":[[32,2.53],[42,1.28],[26,4.19],[55,0.49]],"id":52385930}],"con":true,"img":false}]}
{"op":"mcm","clk":"11449350968","pt":1717307661284,"mc":[{"id":"1.229554922","rc":[{"atb":[[8,0],[9,0],[10,0],[12.5,0]],"id":52385933},{"atb":[[9.6,0],[8.6,0],[11.5,0],[7.6,0]],"id":52385888},{"atb":[[11,0],[7.4,0],[8.4,0],[9.4,0]],"id":52385895}],"con":true,"img":false}]}
{"op":"mcm","clk":"11449350973","pt":1717307661383,"mc":[{"id":"1.229554922","rc":[{"atb":[[65,0],[36,0],[90,0],[46,0]],"id":52385908},{"atb":[[80,0],[42,0],[110,0],[55,0]],"id":52385927},{"atb":[[16.5,0],[19,0],[23,0],[14,0]],"id":52385937},{"atb":[[32,0],[42,0],[26,0],[55,0]],"id":52385909},{"atb":[[17.5,0],[20,0],[25,0],[15,0]],"id":52385884},{"atb":[[32,0],[42,0],[21,0],[26,0]],"id":52385924},{"atb":[[17,0],[19.5,0],[24,0],[29,0]],"id":52385934},{"atb":[[34,0],[44,0],[27,0],[60,0]],"id":52385905},{"atb":[[32,0],[42,0],[26,0],[55,0]],"id":52385930},{"atb":[[11,0],[7.4,0],[8.4,0],[9.4,0]],"id":52385932}],"con":true,"img":false}]}
{"op":"mcm","clk":"11449350979","pt":1717307661485,"mc":[{"id":"1.229554922","rc":[{"atb":[[8,0],[9,0],[10,0],[7,0]],"id":52385931},{"atb":[[40,0],[20,0],[25,0],[30,0]],"id":52385903},{"atb":[[34,0],[44,0],[27,0],[60,0]],"id":52385936}],"con":true,"img":false}]}
{"op":"mcm","clk":"11449351015","pt":1717307662206,"mc":[{"id":"1.229554922","rc":[{"atb":[[11,5.23],[13.5,2.09],[8.4,14.14],[9.4,9.34]],"id":52385933},{"atb":[[9.6,6.08],[8.6,10.33],[11.5,2.49],[7.6,15.85]],"id":52385895},{"atb":[[38,0.71],[19.5,5.66],[24,3.41],[29,1.87]],"id":52385934}],"con":true,"img":false}]}
{"op":"mcm","clk":"11449351023","pt":1717307662307,"mc":[{"id":"1.229554922","rc":[{"atb":[[160,0.16],[80,0.99],[110,0.48],[55,1.94]],"id":52385908},{"atb":[[140,0.38],[70,1.52],[190,0.14],[95,0.84]],"id":52385927},{"atb":[[38,0.71],[19.5,5.66],[24,3.41],[29,1.87]],"id":52385937},{"atb":[[9.6,6.08],[8.6,10.33],[11.5,2.49],[7.6,15.85]],"id":52385931},{"atb":[[34,2.38],[44,1.22],[27,4.02],[60,0.44]],"id":52385909},{"atb":[[12,2.38],[9.8,5.94],[8.8,10.06],[7.8,15.39]],"id":52385888},{"atb":[[38,0.71],[19.5,5.66],[24,3.41],[29,1.87]],"id":52385884},{"atb":[[65,0.41],[36,2.24],[46,1.16],[28,3.88]],"id":52385924},{"atb":[[34,2.38],[44,1.22],[27,4.02],[60,0.44]],"id":52385903},{"atb":[[32,3.37],[80,0.33],[42,1.92],[55,0.97]],"id":52385936},{"atb":[[70,0.38],[38,2.12],[48,1.11],[29,3.74]],"id":52385905},{"atb":[[70,0.38],[38,2.12],[48,1.11],[29,3.74]],"id":52385930},{"atb":[[9.6,6.08],[8.6,10.33],[11.5,2.49],[7.6,15.85]],"id":52385932}],"con":true,"img":false}]}
{"op":"mcm","clk":"11449363063","pt":1717307950880,"mc":[{"id":"1.229554922","rc":[{"atb":[[9.6,0],[8.6,0],[11.5,0],[14,0]],"id":52385897}],"con":true,"img":false}]}
{"op":"mcm","clk":"11449363085","pt":1717307951594,"mc":[{"id":"1.229554922","rc":[{"atb":[[12,4.76],[9.8,8.92],[8.8,13.41],[14.5,1.94]],"id":52385897}],"con":true,"img":false}]}
{"op":"mcm","clk":"11449446207","pt":1717309266059,"mc":[{"id":"1.229554922","rc":[{"atb":[[160,0],[80,0],[110,0],[55,0]],"id":52385919}],"con":true,"img":false}]}
{"op":"mcm","clk":"11449446240","pt":1717309266729,"mc":[{"id":"1.229554922","rc":[{"atb":[[170,0.16],[85,0.94],[120,0.44],[60,1.77]],"id":52385919}],"con":true,"img":false}]}
{"op":"mcm","clk":"11449456205","pt":1717309416811,"mc":[{"id":"1.229554922","rc":[{"atb":[[38,0],[19.5,0],[24,0],[29,0]],"id":52385884}],"con":true,"img":false}]}
{"op":"mcm","clk":"11449456245","pt":1717309417535,"mc":[{"id":"1.229554922","rc":[{"atb":[[40,0.67],[20,5.51],[25,3.27],[30,1.81]],"id":52385884}],"con":true,"img":false}]}
{"op":"mcm","clk":"11449456834","pt":1717309426543,"mc":[{"id":"1.229554922","rc":[{"atb":[[40,0],[20,0],[25,0],[30,0]],"id":52385884}],"con":true,"img":false}]}
{"op":"mcm","clk":"11449456880","pt":1717309427261,"mc":[{"id":"1.229554922","rc":[{"atb":[[38,0.71],[19.5,5.66],[24,3.41],[29,1.87]],"id":52385884}],"con":true,"img":false}]}
{"op":"mcm","clk":"11449523808","pt":1717310348948,"mc":[{"id":"1.229554922","rc":[{"atb":[[140,0],[70,0],[190,0],[95,0]],"id":52385927}],"con":true,"img":false}]}
{"op":"mcm","clk":"11449523863","pt":1717310349622,"mc":[{"id":"1.229554922","rc":[{"atb":[[140,0.38],[70,1.52],[190,0.14],[95,0.84]],"id":52385927}],"con":true,"img":false}]}
{"op":"mcm","clk":"11449589230","pt":1717311489650,"mc":[{"id":"1.229554922","rc":[{"atb":[[38,0],[19.5,0],[24,0],[29,0]],"id":52385884}],"con":true,"img":false}]}
{"op":"mcm","clk":"11449589260","pt":1717311490372,"mc":[{"id":"1.229554922","rc":[{"atb":[[40,0.67],[20,5.51],[25,3.27],[30,1.81]],"id":52385884}],"con":true,"img":false}]}
{"op":"mcm","clk":"11449593444","pt":1717311568954,"mc":[{"id":"1.229554922","rc":[{"atb":[[140,0],[70,0],[190,0],[95,0]],"id":52385927}],"con":true,"img":false}]}
{"op":"mcm","clk":"11449593492","pt":1717311569758,"mc":[{"id":"1.229554922","rc":[{"atb":[[140,0.38],[70,1.52],[190,0.14],[95,0.84]],"id":52385927}],"con":true,"img":false}]}
{"op":"mcm","clk":"11449620341","pt":1717312070889,"mc":[{"id":"1.229554922","rc":[{"atb":[[40,0],[20,0],[25,0],[30,0]],"id":52385884}],"con":true,"img":false}]}
{"op":"mcm","clk":"11449620379","pt":1717312071596,"mc":[{"id":"1.229554922","rc":[{"atb":[[38,0.71],[19.5,5.66],[24,3.41],[29,1.87]],"id":52385884}],"con":true,"img":false}]}
{"op":"mcm","clk":"11449620531","pt":1717312074595,"mc":[{"id":"1.229554922","rc":[{"atb":[[160,0],[80,0],[110,0],[55,0]],"id":52385908},{"atb":[[140,0],[70,0],[95,0],[48,0]],"id":52385918},{"atb":[[300,0],[350,0],[200,0],[250,0]],"id":52385920},{"atb":[[36,0],[46,0],[23,0],[28,0]],"id":52385894},{"atb":[[140,0],[70,0],[190,0],[95,0]],"id":52385927},{"atb":[[160,0],[80,0],[210,0],[110,0]],"id":52385929},{"atb":[[140,0],[70,0],[95,0],[48,0]],"id":52385923},{"atb":[[70,0],[38,0],[48,0],[29,0]],"id":52385925},{"atb":[[34,0],[44,0],[27,0],[60,0]],"id":52385904},{"atb":[[38,0],[19.5,0],[24,0],[29,0]],"id":52385937},{"atb":[[130,0],[180,0],[90,0],[230,1.06]],"id":52385907},{"atb":[[34,0],[44,0],[27,0],[60,0]],"id":52385909},{"atb":[[170,0],[85,0],[120,0],[60,0]],"id":52385919},{"atb":[[130,0],[65,0],[90,0],[46,0]],"id":52385917},{"atb":[[65,0],[36,0],[46,0],[28,0]],"id":52385926},{"atb":[[260,0],[160,0],[210,0],[110,0]],"id":52385922},{"atb":[[65,0],[36,0],[46,0],[28,0]],"id":52385924},{"atb":[[34,0],[44,0],[27,0],[60,0]],"id":52385903},{"atb":[[70,0],[38,0],[48,0],[29,0]],"id":52385905},{"atb":[[70,0],[38,0],[48,0],[29,0]],"id":52385930}],"con":true,"img":false}]}
{"op":"mcm","clk":"11449620560","pt":1717312075312,"mc":[{"id":"1.229554922","rc":[{"atb":[[40,0.67],[20,5.51],[25,3.27],[30,1.81]],"id":52385894},{"atb":[[16.5,6.75],[19,4.36],[23,2.38],[28,0.97]],"id":52385904},{"atb":[[18,3.08],[21,1.31],[13,8.72],[15.5,5.41]],"id":52385903},{"atb":[[34,0.8],[18.5,5.98],[22,3.74],[27,2.01]],"id":52385905}],"con":true,"img":false}]}
{"op":"mcm","clk":"11449620568","pt":1717312075420,"mc":[{"id":"1.229554922","rc":[{"atb":[[16.5,3.37],[19,1.45],[11.5,9.97],[14,6.04]],"id":52385908},{"atb":[[65,0.82],[36,2.99],[90,0.29],[46,1.74]],"id":52385918},{"atb":[[70,0.38],[38,2.12],[48,1.11],[29,3.74]],"id":52385920},{"atb":[[16.5,5.06],[19,2.91],[23,1.19],[14,8.05]],"id":52385927},{"atb":[[40,0.67],[20,5.51],[25,3.27],[30,1.81]],"id":52385929},{"atb":[[75,0.71],[40,2.68],[100,0.27],[50,1.6]],"id":52385923},{"atb":[[17.5,6.34],[20,4.13],[25,2.18],[30,0.9]],"id":52385925},{"atb":[[34,0.8],[18.5,5.98],[22,3.74],[27,2.01]],"id":52385937},{"atb":[[34,1.59],[44,0.61],[22,4.98],[27,3.02]],"id":52385907},{"atb":[[34,0.8],[18.5,5.98],[22,3.74],[27,2.01]],"id":52385909},{"atb":[[80,0.66],[42,2.55],[110,0.24],[55,1.45]],"id":52385919},{"atb":[[70,0.38],[38,2.12],[48,1.11],[29,3.74]],"id":52385917},{"atb":[[38,0.71],[19.5,5.66],[24,3.41],[29,1.87]],"id":52385926},{"atb":[[40,1.34],[50,0.53],[25,4.36],[30,2.71]],"id":52385922},{"atb":[[16.5,11.81],[19,2.91],[23,1.19],[14,8.05]],"id":52385924},{"atb":[[32,0.84],[18,6.15],[21,3.92],[26,2.09]],"id":52385930}],"con":true,"img":false}]}
{"op":"mcm","clk":"11449620661","pt":1717312077419,"mc":[{"id":"1.229554922","rc":[{"atb":[[38,0],[19.5,0],[24,0],[29,0]],"id":52385884}],"con":true,"img":false}]}
{"op":"mcm","clk":"11449620695","pt":1717312078089,"mc":[{"id":"1.229554922","rc":[{"atb":[[23,3.57],[28,1.94]],"id":52385884}],"con":true,"img":false}]}
{"op":"mcm","clk":"11449620703","pt":1717312078193,"mc":[{"id":"1.229554922","rc":[{"atb":[[36,0.75]],"id":52385884}],"con":true,"img":false}]}
{"op":"mcm","clk":"11449620709","pt":1717312078293,"mc":[{"id":"1.229554922","rc":[{"atb":[[19,5.81]],"id":52385884}],"con":true,"img":false}]}
{"op":"mcm","clk":"11449663223","pt":1717313123014,"mc":[{"id":"1.229554922","rc":[{"atb":[[38,0],[19.5,0],[24,0],[29,0]],"id":52385934}],"con":true,"img":false}]}
{"op":"mcm","clk":"11449663266","pt":1717313123832,"mc":[{"id":"1.229554922","rc":[{"atb":[[36,0.75],[19,5.81],[23,3.57],[28,1.94]],"id":52385934}],"con":true,"img":false}]}
{"op":"mcm","clk":"11449663775","pt":1717313135455,"mc":[{"id":"1.229554922","rc":[{"atb":[[36,0],[19,0],[23,0],[28,0]],"id":52385934}],"con":true,"img":false}]}
{"op":"mcm","clk":"11449663804","pt":1717313136124,"mc":[{"id":"1.229554922","rc":[{"atb":[[38,0.71],[19.5,5.66],[24,3.41],[29,1.87]],"id":52385934}],"con":true,"img":false}]}
{"op":"mcm","clk":"11449665036","pt":1717313165895,"mc":[{"id":"1.229554922","rc":[{"atb":[[38,0],[19.5,0],[24,0],[29,0]],"id":52385934}],"con":true,"img":false}]}
{"op":"mcm","clk":"11449665076","pt":1717313166672,"mc":[{"id":"1.229554922","rc":[{"atb":[[36,0.75],[19,5.81],[23,3.57],[28,1.94]],"id":52385934}],"con":true,"img":false}]}
{"op":"mcm","clk":"11449667357","pt":1717313215831,"mc":[{"id":"1.229554922","rc":[{"atb":[[44,0],[27,0]],"id":52385908},{"atb":[[17.5,0],[25,0]],"id":52385918},{"atb":[[10,0],[15,0]],"id":52385887},{"atb":[[260,0],[360,0]],"id":52385920},{"atb":[[5.7,0],[4.7,0]],"id":52385889},{"atb":[[5.3,0],[6.6,0]],"id":52385883},{"atb":[[10,0],[15,0]],"id":52385894},{"atb":[[46,0],[28,0]],"id":52385927},{"atb":[[5.5,0],[7,0]],"id":52385896},{"atb":[[410,0],[510,0]],"id":52385929},{"atb":[[5.3,0],[6.6,0]],"id":52385890},{"atb":[[17,0],[24,0]],"id":52385923},{"atb":[[16.5,0],[11.5,0]],"id":52385925},{"atb":[[5.3,0],[6.6,0]],"id":52385902},{"atb":[[9.8,0],[14.5,0]],"id":52385904},{"atb":[[9.8,0],[14.5,0]],"id":52385937},{"atb":[[10,0],[15,0]],"id":52385898},{"atb":[[4.5,0],[5.5,0]],"id":52385931},{"atb":[[17.5,0],[25,0]],"id":52385900},{"atb":[[5.1,0],[6.2,0]],"id":52385933},{"atb":[[330,0],[230,0]],"id":52385907},{"atb":[[9.8,0],[14.5,0]],"id":52385909},{"atb":[[21,0],[15.5,0]],"id":52385886},{"atb":[[19.5,0],[29,0]],"id":52385919},{"atb":[[4.5,0],[5.5,0]],"id":52385888},{"atb":[[5.7,0],[4.7,0]],"id":52385882},{"atb":[[13.5,0],[9.4,0]],"id":52385884},{"atb":[[17.5,0],[25,0]],"id":52385917},{"atb":[[18,0],[13,0]],"id":52385926},{"atb":[[4.5,0],[5.5,0]],"id":52385895},{"atb":[[5.5,0],[7,0]],"id":52385897},{"atb":[[530,0],[430,0]],"id":52385922},{"atb":[[13.5,0],[9.4,0]],"id":52385891},{"atb":[[16.5,5.06],[11.5,0]],"id":52385924},{"atb":[[21,0],[15.5,0]],"id":52385893},{"atb":[[9.2,0],[13,0]],"id":52385934},{"atb":[[9.8,0],[14.5,0]],"id":52385903},{"atb":[[20,0],[15,0]],"id":52385936},{"atb":[[16,0],[11,0]],"id":52385905},{"atb":[[16,0],[11,0]],"id":52385930},{"atb":[[4.4,0],[5.4,0]],"id":52385932},{"atb":[[17,0],[12,0]],"id":52385901}],"con":true,"img":false}]}
{"op":"mcm","clk":"11449667890","pt":1717313226923,"mc":[{"id":"1.229554922","rc":[{"atb":[[16.5,0],[19,0],[11.5,0],[14,0]],"id":52385908},{"atb":[[65,0],[36,0],[90,0],[46,0]],"id":52385918},{"atb":[[40,0],[20,0],[25,0],[30,0]],"id":52385894},{"atb":[[75,0],[40,0],[100,0],[50,0]],"id":52385923},{"atb":[[34,0],[18.5,0],[22,0],[27,0]],"id":52385937},{"atb":[[80,0],[42,0],[110,0],[55,0]],"id":52385919},{"atb":[[36,0],[19,0],[23,0],[28,0]],"id":52385884},{"atb":[[16.5,0],[19,0],[23,0],[14,0]],"id":52385924}],"con":true,"img":false}]}
{"op":"mcm","clk":"11449667899","pt":1717313227132,"mc":[{"id":"1.229554922","rc":[{"atb":[[16.5,0],[19,0],[23,0],[14,0]],"id":52385927}],"con":true,"img":false}]}
{"op":"mcm","clk":"11449667918","pt":1717313227643,"mc":[{"id":"1.229554922","rc":[{"atb":[[17,3.27],[19.5,1.41],[12,9.51],[14.5,5.81]],"id":52385908},{"atb":[[75,0.71],[40,2.68],[100,0.27],[50,1.6]],"id":52385918},{"atb":[[38,0.71],[19.5,5.66],[24,3.41],[29,1.87]],"id":52385894},{"atb":[[34,0.8],[18.5,5.98],[22,3.74],[27,2.01]],"id":52385937},{"atb":[[130,0.2],[65,1.22],[90,0.59],[46,2.32]],"id":52385919},{"atb":[[34,0.8],[18.5,5.98],[22,3.74],[27,2.01]],"id":52385884},{"atb":[[16.5,5.06],[19,2.91],[23,1.19],[14,8.05]],"id":52385924}],"con":true,"img":false}]}
{"op":"mcm","clk":"11449667923","pt":1717313227746,"mc":[{"id":"1.229554922","rc":[{"atb":[[80,0.66],[42,2.55],[110,0.24],[55,1.45]],"id":52385923}],"con":true,"img":false}]}
{"op":"mcm","clk":"11449667926","pt":1717313227849,"mc":[{"id":"1.229554922","rc":[{"atb":[[17,4.9],[19.5,2.83],[24,1.14],[14.5,7.75]],"id":52385927}],"con":true,"img":false}]}
{"op":"mcm","clk":"11449668636","pt":1717313241266,"mc":[{"id":"1.229554922","rc":[{"atb":[[46,2.32],[28,9.03]],"id":52385908},{"atb":[[17,15.24],[24,4.54]],"id":52385918},{"atb":[[340,0.3],[240,1.02]],"id":52385920},{"atb":[[48,2.22],[29,8.71]],"id":52385927},{"atb":[[540,0.19],[440,0.55]],"id":52385929},{"atb":[[17,15.24],[24,4.54]],"id":52385923},{"atb":[[17,6.53],[12,22.17]],"id":52385925},{"atb":[[10,27.1],[15,7.46]],"id":52385937},{"atb":[[5.6,22.72],[4.6,67.75]],"id":52385931},{"atb":[[6.4,19.35],[5.2,58.07]],"id":52385933},{"atb":[[310,0.34],[210,1.16]],"id":52385907},{"atb":[[9.8,27.71],[14.5,7.74]],"id":52385909},{"atb":[[19,13.55],[28,3.87]],"id":52385919},{"atb":[[17,15.24],[24,4.54]],"id":52385917},{"atb":[[18,6.14],[13,20.32]],"id":52385926},{"atb":[[560,0.18],[460,0.53]],"id":52385922},{"atb":[[17,6.53],[12,22.17]],"id":52385924},{"atb":[[9.2,29.74],[13,8.71]],"id":52385934},{"atb":[[20,5.5],[15,17.42]],"id":52385936},{"atb":[[17,6.53],[12,22.17]],"id":52385930},{"atb":[[4.5,69.68],[5.5,23.22]],"id":52385932}],"con":true,"img":false}]}
{"op":"mcm","clk":"11449668645","pt":1717313241365,"mc":[{"id":"1.229554922","rc":[{"atb":[[10,27.1],[15,7.46]],"id":52385887},{"atb":[[5.6,22.72],[4.6,67.75]],"id":52385889},{"atb":[[6.4,19.35],[5.2,58.07]],"id":52385883},{"atb":[[10,27.1],[15,7.46]],"id":52385894},{"atb":[[6.8,18.02],[5.4,55.43]],"id":52385896},{"atb":[[6.4,19.35],[5.2,58.07]],"id":52385890},{"atb":[[5.3,56.72],[6.6,18.66]],"id":52385902},{"atb":[[9.8,27.71],[14.5,7.74]],"id":52385904},{"atb":[[10,27.1],[15,7.46]],"id":52385898},{"atb":[[17,15.24],[24,9.1]],"id":52385900},{"atb":[[20,5.5],[15,17.42]],"id":52385886},{"atb":[[5.6,22.72],[4.6,67.75]],"id":52385888},{"atb":[[5.6,22.72],[4.6,67.75]],"id":52385882},{"atb":[[13.5,8.36],[9.4,29.03]],"id":52385884},{"atb":[[4.5,69.68],[5.5,23.22]],"id":52385895},{"atb":[[5.3,56.72],[6.6,18.66]],"id":52385897},{"atb":[[9.2,29.74],[13,8.71]],"id":52385891},{"atb":[[20,5.5],[15,17.42]],"id":52385893},{"atb":[[9.8,27.71],[14.5,7.74]],"id":52385903},{"atb":[[16,6.96],[11,24.39]],"id":52385905},{"atb":[[17,6.53],[12,22.17]],"id":52385901}],"con":true,"img":false}]}
{"op":"mcm","clk":"11449670124","pt":1717313273432,"mc":[{"id":"1.229554922","rc":[{"atb":[[46,0],[28,0]],"id":52385908},{"atb":[[17,0],[24,0]],"id":52385918},{"atb":[[10,0],[15,0]],"id":52385887},{"atb":[[340,0],[240,0]],"id":52385920},{"atb":[[5.6,0],[4.6,0]],"id":52385889},{"atb":[[6.4,0],[5.2,0]],"id":52385883},{"atb":[[10,0],[15,0]],"id":52385894},{"atb":[[48,0],[29,0]],"id":52385927},{"atb":[[6.8,0],[5.4,0]],"id":52385896},{"atb":[[540,0],[440,0]],"id":52385929},{"atb":[[6.4,0],[5.2,0]],"id":52385890},{"atb":[[17,0],[24,0]],"id":52385923},{"atb":[[17,0],[12,0]],"id":52385925},{"atb":[[5.3,0],[6.6,0]],"id":52385902},{"atb":[[9.8,0],[14.5,0]],"id":52385904},{"atb":[[10,0],[15,0]],"id":52385937},{"atb":[[10,0],[15,0]],"id":52385898},{"atb":[[5.6,0],[4.6,0]],"id":52385931},{"atb":[[17,0],[24,4.55]],"id":52385900},{"atb":[[6.4,0],[5.2,0]],"id":52385933},{"atb":[[310,0],[210,0]],"id":52385907},{"atb":[[9.8,0],[14.5,0]],"id":52385909},{"atb":[[20,0],[15,0]],"id":52385886},{"atb":[[19,0],[28,0]],"id":52385919},{"atb":[[5.6,0],[4.6,0]],"id":52385888},{"atb":[[5.6,0],[4.6,0]],"id":52385882},{"atb":[[13.5,0],[9.4,0]],"id":52385884},{"atb":[[17,0],[24,0]],"id":52385917},{"atb":[[18,0],[13,0]],"id":52385926},{"atb":[[4.5,0],[5.5,0]],"id":52385895},{"atb":[[5.3,0],[6.6,0]],"id":52385897},{"atb":[[560,0],[460,0]],"id":52385922},{"atb":[[9.2,0],[13,0]],"id":52385891},{"atb":[[17,0],[12,0]],"id":52385924},{"atb":[[20,0],[15,0]],"id":52385893},{"atb":[[9.2,0],[13,0]],"id":52385934},{"atb":[[9.8,0],[14.5,0]],"id":52385903},{"atb":[[20,0],[15,0]],"id":52385936},{"atb":[[16,0],[11,0]],"id":52385905},{"atb":[[17,0],[12,0]],"id":52385930},{"atb":[[4.5,0],[5.5,0]],"id":52385932},{"atb":[[17,0],[12,0]],"id":52385901}],"con":true,"img":false}]}
{"op":"mcm","clk":"11449671581","pt":1717313301949,"mc":[{"id":"1.229554922","rc":[{"atb":[[10,27.1],[15,7.46]],"id":52385887},{"atb":[[4.4,71.73],[5.4,23.75]],"id":52385889},{"atb":[[5.3,56.72],[6.6,18.66]],"id":52385883},{"atb":[[9.8,27.71],[14.5,7.74]],"id":52385894},{"atb":[[5.5,54.2],[7,17.42]],"id":52385896},{"atb":[[5,60.97],[6,20.9]],"id":52385890},{"atb":[[5.5,54.2],[7,17.42]],"id":52385902},{"atb":[[9.8,27.71],[14.5,7.74]],"id":52385904},{"atb":[[10.5,25.67],[15.5,7.2]],"id":52385898},{"atb":[[18,14.34],[26,4.18]],"id":52385900},{"atb":[[21,5.22],[15.5,16.82]],"id":52385886},{"atb":[[5.6,22.72],[4.6,67.75]],"id":52385888},{"atb":[[4.4,71.73],[5.4,23.75]],"id":52385882},{"atb":[[9.6,28.36],[14,8.04]],"id":52385884},{"atb":[[4.4,71.73],[5.4,23.75]],"id":52385895},{"atb":[[5.3,56.72],[6.6,18.66]],"id":52385897},{"atb":[[13.5,8.36],[9.4,29.03]],"id":52385891},{"atb":[[20,5.5],[15,17.42]],"id":52385893},{"atb":[[10,27.1],[15,7.46]],"id":52385903},{"atb":[[17,6.53],[12,22.17]],"id":52385905},{"atb":[[17.5,6.33],[12.5,21.2]],"id":52385901}],"con":true,"img":false}]}
{"op":"mcm","clk":"11449671587","pt":1717313302053,"mc":[{"id":"1.229554922","rc":[{"atb":[[34,7.39],[60,1.77]],"id":52385908},{"atb":[[17,15.24],[24,4.54]],"id":52385918},{"atb":[[350,0.7],[450,0.23]],"id":52385920},{"atb":[[34,7.39],[60,1.77]],"id":52385927},{"atb":[[610,0.17],[510,0.48]],"id":52385929},{"atb":[[17.5,14.77],[25,4.35]],"id":52385923},{"atb":[[16.5,6.74],[11.5,23.22]],"id":52385925},{"atb":[[10,27.1],[15,7.46]],"id":52385937},{"atb":[[5.6,22.72],[4.6,67.75]],"id":52385931},{"atb":[[5.3,56.72],[6.6,18.66]],"id":52385933},{"atb":[[320,0.76],[420,0.25]],"id":52385907},{"atb":[[10,27.1],[15,7.46]],"id":52385909},{"atb":[[20,12.83],[30,3.6]],"id":52385919},{"atb":[[17.5,14.77],[25,4.35]],"id":52385917},{"atb":[[18.5,5.97],[13.5,19.51]],"id":52385926},{"atb":[[530,0.46],[630,0.16]],"id":52385922},{"atb":[[17,6.53],[12,22.17]],"id":52385924},{"atb":[[9.6,28.36],[14,8.04]],"id":52385934},{"atb":[[21,5.22],[15.5,16.82]],"id":52385936},{"atb":[[17,6.53],[12,22.17]],"id":52385930},{"atb":[[4.4,71.73],[5.4,23.75]],"id":52385932}],"con":true,"img":false}]}
{"op":"mcm","clk":"11449673069","pt":1717313329752,"mc":[{"id":"1.229554922","rc":[{"atb":[[34,0],[60,0]],"id":52385908},{"atb":[[17,0],[24,0]],"id":52385918},{"atb":[[10,0],[15,0]],"id":52385887},{"atb":[[350,0],[450,0]],"id":52385920},{"atb":[[4.4,0],[5.4,0]],"id":52385889},{"atb":[[5.3,0],[6.6,0]],"id":52385883},{"atb":[[9.8,0],[14.5,0]],"id":52385894},{"atb":[[34,0],[60,0]],"id":52385927},{"atb":[[5.5,0],[7,0]],"id":52385896},{"atb":[[610,0],[510,0]],"id":52385929},{"atb":[[5,0],[6,0]],"id":52385890},{"atb":[[17.5,0],[25,0]],"id":52385923},{"atb":[[16.5,0],[11.5,0]],"id":52385925},{"atb":[[5.5,0],[7,0]],"id":52385902},{"atb":[[9.8,0],[14.5,0]],"id":52385904},{"atb":[[10,0],[15,0]],"id":52385937},{"atb":[[10.5,0],[15.5,0]],"id":52385898},{"atb":[[5.6,0],[4.6,0]],"id":52385931},{"atb":[[18,0],[26,0]],"id":52385900},{"atb":[[5.3,0],[6.6,0]],"id":52385933},{"atb":[[320,0],[420,0]],"id":52385907},{"atb":[[10,0],[15,0]],"id":52385909},{"atb":[[21,0],[15.5,0]],"id":52385886},{"atb":[[20,0],[30,0]],"id":52385919},{"atb":[[5.6,0],[4.6,0]],"id":52385888},{"atb":[[4.4,0],[5.4,0]],"id":52385882},{"atb":[[9.6,0],[14,0]],"id":52385884},{"atb":[[17.5,0],[25,0]],"id":52385917},{"atb":[[18.5,0],[13.5,0]],"id":52385926},{"atb":[[4.4,0],[5.4,0]],"id":52385895},{"atb":[[5.3,0],[6.6,0]],"id":52385897},{"atb":[[530,0],[630,0]],"id":52385922},{"atb":[[13.5,0],[9.4,0]],"id":52385891},{"atb":[[17,0],[12,0]],"id":52385924},{"atb":[[20,0],[15,0]],"id":52385893},{"atb":[[9.6,0],[14,0]],"id":52385934},{"atb":[[10,0],[15,0]],"id":52385903},{"atb":[[21,0],[15.5,0]],"id":52385936},{"atb":[[17,0],[12,0]],"id":52385905},{"atb":[[17,0],[12,0]],"id":52385930},{"atb":[[4.4,0],[5.4,0]],"id":52385932},{"atb":[[17.5,0],[12.5,0]],"id":52385901}],"con":true,"img":false}]}
{"op":"mcm","clk":"11449674320","pt":1717313351272,"mc":[{"id":"1.229554922","rc":[{"atb":[[70,1.51],[38,6.59]],"id":52385908},{"atb":[[17,15.24],[24,4.54]],"id":52385918},{"atb":[[350,0.7],[450,0.23]],"id":52385920},{"atb":[[70,1.51],[38,6.59]],"id":52385927},{"atb":[[550,0.44],[650,0.16]],"id":52385929},{"atb":[[17.5,14.77],[25,4.35]],"id":52385923},{"atb":[[17,6.53],[12,22.17]],"id":52385925},{"atb":[[10.5,25.67],[15.5,7.2]],"id":52385937},{"atb":[[4.5,69.68],[5.5,23.22]],"id":52385931},{"atb":[[6.4,19.35],[5.2,58.07]],"id":52385933},{"atb":[[320,0.76],[420,0.25]],"id":52385907},{"atb":[[10,27.1],[15,7.46]],"id":52385909},{"atb":[[20,12.83],[30,3.6]],"id":52385919},{"atb":[[17.5,14.77],[25,4.35]],"id":52385917},{"atb":[[18.5,5.97],[13.5,19.51]],"id":52385926},{"atb":[[550,0.44],[650,0.16]],"id":52385922},{"atb":[[17.5,6.33],[12.5,21.2]],"id":52385924},{"atb":[[13.5,8.36],[9.4,29.03]],"id":52385934},{"atb":[[21,5.22],[15.5,16.82]],"id":52385936},{"atb":[[17.5,6.33],[12.5,21.2]],"id":52385930},{"atb":[[4.4,71.73],[5.4,23.75]],"id":52385932}],"con":true,"img":false}]}
{"op":"mcm","clk":"11449674328","pt":1717313351382,"mc":[{"id":"1.229554922","rc":[{"atb":[[10.5,25.67],[15.5,7.2]],"id":52385887},{"atb":[[4.4,71.73],[5.4,23.75]],"id":52385889},{"atb":[[6.4,19.35],[5.2,58.07]],"id":52385883},{"atb":[[10,27.1],[15,7.46]],"id":52385894},{"atb":[[6.8,18.02],[5.4,55.43]],"id":52385896},{"atb":[[5,60.97],[6,20.9]],"id":52385890},{"atb":[[6.8,18.02],[5.4,55.43]],"id":52385902},{"atb":[[9.8,27.71],[14.5,7.74]],"id":52385904},{"atb":[[10.5,25.67],[15.5,7.2]],"id":52385898},{"atb":[[18,14.34],[26,4.18]],"id":52385900},{"atb":[[21,5.22],[15.5,16.82]],"id":52385886},{"atb":[[4.5,69.68],[5.5,23.22]],"id":52385888},{"atb":[[4.4,71.73],[5.4,23.75]],"id":52385882},{"atb":[[13.5,8.36],[9.4,29.03]],"id":52385884},{"atb":[[4.4,71.73],[5.4,23.75]],"id":52385895},{"atb":[[5.3,56.72],[6.6,18.66]],"id":52385897},{"atb":[[13.5,8.36],[9.4,29.03]],"id":52385891},{"atb":[[20,5.5],[15,17.42]],"id":52385893},{"atb":[[10,27.1],[15,7.46]],"id":52385903},{"atb":[[16.5,6.74],[11.5,23.22]],"id":52385905},{"atb":[[18,6.14],[13,20.32]],"id":52385901}],"con":true,"img":false}]}
{"op":"mcm","clk":"11449680095","pt":1717313441278,"mc":[{"id":"1.229554922","rc":[{"atb":[[70,0],[38,0]],"id":52385908},{"atb":[[17,0],[24,0]],"id":52385918},{"atb":[[10.5,0],[15.5,0]],"id":52385887},{"atb":[[350,0],[450,0]],"id":52385920},{"atb":[[4.4,0],[5.4,0]],"id":52385889},{"atb":[[6.4,0],[5.2,0]],"id":52385883},{"atb":[[10,0],[15,0]],"id":52385894},{"atb":[[70,0],[38,0]],"id":52385927},{"atb":[[6.8,0],[5.4,0]],"id":52385896},{"atb":[[550,0],[650,0]],"id":52385929},{"atb":[[5,0],[6,0]],"id":52385890},{"atb":[[17.5,0],[25,0]],"id":52385923},{"atb":[[17,0],[12,0]],"id":52385925},{"atb":[[6.8,0],[5.4,0]],"id":52385902},{"atb":[[9.8,0],[14.5,0]],"id":52385904},{"atb":[[10.5,0],[15.5,0]],"id":52385937},{"atb":[[10.5,0],[15.5,0]],"id":52385898},{"atb":[[4.5,0],[5.5,0]],"id":52385931},{"atb":[[18,0],[26,0]],"id":52385900},{"atb":[[6.4,0],[5.2,0]],"id":52385933},{"atb":[[320,0],[420,0]],"id":52385907},{"atb":[[10,0],[15,0]],"id":52385909},{"atb":[[21,0],[15.5,0]],"id":52385886},{"atb":[[20,0],[30,0]],"id":52385919},{"atb":[[4.5,0],[5.5,0]],"id":52385888},{"atb":[[4.4,0],[5.4,0]],"id":52385882},{"atb":[[13.5,0],[9.4,0]],"id":52385884},{"atb":[[17.5,0],[25,0]],"id":52385917},{"atb":[[18.5,0],[13.5,0]],"id":52385926},{"atb":[[4.4,0],[5.4,0]],"id":52385895},{"atb":[[5.3,0],[6.6,0]],"id":52385897},{"atb":[[550,0],[650,0]],"id":52385922},{"atb":[[13.5,0],[9.4,0]],"id":52385891},{"atb":[[17.5,0],[12.5,0]],"id":52385924},{"atb":[[20,0],[15,0]],"id":52385893},{"atb":[[13.5,0],[9.4,0]],"id":52385934},{"atb":[[10,0],[15,0]],"id":52385903},{"atb":[[21,0],[15.5,0]],"id":52385936},{"atb":[[16.5,0],[11.5,0]],"id":52385905},{"atb":[[17.5,0],[12.5,0]],"id":52385930},{"atb":[[4.4,0],[5.4,0]],"id":52385932},{"atb":[[18,0],[13,0]],"id":52385901}],"con":true,"img":false}]}
{"op":"mcm","clk":"11449680688","pt":1717313449438,"mc":[{"id":"1.229554922","rc":[{"atb":[[80,1.32],[42,5.94]],"id":52385908},{"atb":[[17,15.24],[24,4.54]],"id":52385918},{"atb":[[340,0.72],[440,0.24]],"id":52385920},{"atb":[[80,1.32],[42,5.94]],"id":52385927},{"atb":[[550,0.44],[650,0.16]],"id":52385929},{"atb":[[17.5,14.77],[25,4.35]],"id":52385923},{"atb":[[17.5,12.68],[12.5,21.2]],"id":52385925},{"atb":[[16,6.96],[11,24.39]],"id":52385937},{"atb":[[4.5,69.68],[5.5,23.22]],"id":52385931},{"atb":[[6.4,19.35],[5.2,58.07]],"id":52385933},{"atb":[[310,0.78],[410,0.25]],"id":52385907},{"atb":[[10,27.1],[15,7.46]],"id":52385909},{"atb":[[20,12.83],[30,3.6]],"id":52385919},{"atb":[[17.5,14.77],[25,4.35]],"id":52385917},{"atb":[[19,5.8],[14,18.76]],"id":52385926},{"atb":[[550,0.44],[650,0.16]],"id":52385922},{"atb":[[18,6.14],[13,20.32]],"id":52385924},{"atb":[[13.5,8.36],[9.4,29.03]],"id":52385934},{"atb":[[21,5.22],[15.5,16.82]],"id":52385936},{"atb":[[18,12.3],[13,20.32]],"id":52385930},{"atb":[[4.4,71.73],[5.4,23.75]],"id":52385932}],"con":true,"img":false}]}
{"op":"mcm","clk":"11449680695","pt":1717313449544,"mc":[{"id":"1.229554922","rc":[{"atb":[[16,12.2],[11,24.39]],"id":52385887},{"atb":[[4.3,73.9],[5.3,24.31]],"id":52385889},{"atb":[[6.4,19.35],[5.2,58.07]],"id":52385883},{"atb":[[10.5,25.67],[15.5,7.2]],"id":52385894},{"atb":[[6.8,18.02],[5.4,55.43]],"id":52385896},{"atb":[[5,60.97],[6,20.9]],"id":52385890},{"atb":[[6.8,18.02],[5.4,55.43]],"id":52385902},{"atb":[[9.8,27.71],[14.5,7.74]],"id":52385904},{"atb":[[10.5,25.67],[15.5,7.2]],"id":52385898},{"atb":[[18,14.34],[26,4.18]],"id":52385900},{"atb":[[21,5.22],[15.5,16.82]],"id":52385886},{"atb":[[4.5,69.68],[5.5,23.22]],"id":52385888},{"atb":[[4.4,71.73],[5.4,23.75]],"id":52385882},{"atb":[[13.5,8.36],[9.4,29.03]],"id":52385884},{"atb":[[4.3,73.9],[5.3,24.31]],"id":52385895},{"atb":[[6.4,19.35],[5.2,58.07]],"id":52385897},{"atb":[[13.5,8.36],[9.4,29.03]],"id":52385891},{"atb":[[20,5.5],[15,17.42]],"id":52385893},{"atb":[[10,27.1],[15,7.46]],"id":52385903},{"atb":[[16.5,6.74],[11.5,23.22]],"id":52385905},{"atb":[[18,6.14],[13,20.32]],"id":52385901}],"con":true,"img":false}]}
{"op":"mcm","clk":"11449693458","pt":1717313605037,"mc":[{"id":"1.229554922","rc":[{"atb":[[80,0],[42,0]],"id":52385908},{"atb":[[17,0],[24,0]],"id":52385918},{"atb":[[16,5.23],[11,0]],"id":52385887},{"atb":[[340,0],[440,0]],"id":52385920},{"atb":[[4.3,0],[5.3,0]],"id":52385889},{"atb":[[6.4,0],[5.2,0]],"id":52385883},{"atb":[[10.5,0],[15.5,0]],"id":52385894},{"atb":[[80,0],[42,0]],"id":52385927},{"atb":[[6.8,0],[5.4,0]],"id":52385896},{"atb":[[550,0],[650,0]],"id":52385929},{"atb":[[5,0],[6,0]],"id":52385890},{"atb":[[17.5,0],[25,0]],"id":52385923},{"atb":[[17.5,6.34],[12.5,0]],"id":52385925},{"atb":[[6.8,0],[5.4,0]],"id":52385902},{"atb":[[9.8,0],[14.5,0]],"id":52385904},{"atb":[[16,0],[11,0]],"id":52385937},{"atb":[[10.5,0],[15.5,0]],"id":52385898},{"atb":[[4.5,0],[5.5,0]],"id":52385931},{"atb":[[18,0],[26,0]],"id":52385900},{"atb":[[6.4,0],[5.2,0]],"id":52385933},{"atb":[[310,0],[410,0]],"id":52385907},{"atb":[[10,0],[15,0]],"id":52385909},{"atb":[[21,0],[15.5,0]],"id":52385886},{"atb":[[20,0],[30,0]],"id":52385919},{"atb":[[4.5,0],[5.5,0]],"id":52385888},{"atb":[[4.4,0],[5.4,0]],"id":52385882},{"atb":[[13.5,0],[9.4,0]],"id":52385884},{"atb":[[17.5,0],[25,0]],"id":52385917},{"atb":[[19,0],[14,0]],"id":52385926},{"atb":[[4.3,0],[5.3,0]],"id":52385895},{"atb":[[6.4,0],[5.2,0]],"id":52385897},{"atb":[[550,0],[650,0]],"id":52385922},{"atb":[[13.5,0],[9.4,0]],"id":52385891},{"atb":[[18,0],[13,0]],"id":52385924},{"atb":[[20,0],[15,0]],"id":52385893},{"atb":[[13.5,0],[9.4,0]],"id":52385934},{"atb":[[10,0],[15,0]],"id":52385903},{"atb":[[21,0],[15.5,0]],"id":52385936},{"atb":[[16.5,0],[11.5,0]],"id":52385905},{"atb":[[18,6.15],[13,0]],"id":52385930},{"atb":[[4.4,0],[5.4,0]],"id":52385932},{"atb":[[18,0],[13,0]],"id":52385901}],"con":true,"img":false}]}
{"op":"mcm","clk":"11449696048","pt":1717313635048,"mc":[{"id":"1.229554922","rc":[{"atb":[[16,12.2],[11,24.39]],"id":52385887},{"atb":[[4.3,73.9],[5.3,24.31]],"id":52385889},{"atb":[[5.3,56.72],[6.6,18.66]],"id":52385883},{"atb":[[10.5,25.67],[15.5,7.2]],"id":52385894},{"atb":[[5.6,53.02],[7.2,16.86]],"id":52385896},{"atb":[[5.1,59.49],[6.2,20.1]],"id":52385890},{"atb":[[5.6,53.02],[7.2,16.86]],"id":52385902},{"atb":[[9.8,27.71],[14.5,7.74]],"id":52385904},{"atb":[[16,12.2],[11,24.39]],"id":52385898},{"atb":[[18.5,13.93],[27,4.01]],"id":52385900},{"atb":[[21,5.22],[15.5,16.82]],"id":52385886},{"atb":[[4.5,69.68],[5.5,23.22]],"id":52385888},{"atb":[[4.3,73.9],[5.3,24.31]],"id":52385882},{"atb":[[13.5,8.36],[9.4,29.03]],"id":52385884},{"atb":[[4.3,73.9],[5.3,24.31]],"id":52385895},{"atb":[[6.8,18.02],[5.4,55.43]],"id":52385897},{"atb":[[9.2,29.74],[13,8.71]],"id":52385891},{"atb":[[20,5.5],[15,17.42]],"id":52385893},{"atb":[[10,27.1],[15,7.46]],"id":52385903},{"atb":[[17,6.53],[12,22.17]],"id":52385905},{"atb":[[18.5,5.97],[13.5,19.51]],"id":52385901}],"con":true,"img":false}]}
{"op":"mcm","clk":"11449696065","pt":1717313635211,"mc":[{"id":"1.229554922","rc":[{"atb":[[75,1.41],[40,6.25]],"id":52385908},{"atb":[[17,15.24],[24,4.54]],"id":52385918},{"atb":[[330,0.74],[430,0.24]],"id":52385920},{"atb":[[80,1.32],[42,5.94]],"id":52385927},{"atb":[[550,0.44],[650,0.16]],"id":52385929},{"atb":[[17.5,14.77],[25,4.35]],"id":52385923},{"atb":[[17.5,12.68],[12.5,21.2]],"id":52385925},{"atb":[[16,6.96],[11,24.39]],"id":52385937},{"atb":[[4.5,69.68],[5.5,23.22]],"id":52385931},{"atb":[[5.3,56.72],[6.6,18.66]],"id":52385933},{"atb":[[300,0.81],[400,0.26]],"id":52385907},{"atb":[[10,27.1],[15,7.46]],"id":52385909},{"atb":[[32,3.37],[21,12.19]],"id":52385919},{"atb":[[17.5,14.77],[25,4.35]],"id":52385917},{"atb":[[19,5.8],[14,18.76]],"id":52385926},{"atb":[[550,0.44],[650,0.16]],"id":52385922},{"atb":[[18,6.14],[13,20.32]],"id":52385924},{"atb":[[13.5,8.36],[9.4,29.03]],"id":52385934},{"atb":[[21,5.22],[15.5,16.82]],"id":52385936},{"atb":[[18,12.3],[13,20.32]],"id":52385930},{"atb":[[4.3,73.9],[5.3,24.31]],"id":52385932}],"con":true,"img":false}]}
{"op":"mcm","clk":"11449697014","pt":1717313647828,"mc":[{"id":"1.229554922","rc":[{"atb":[[32,0],[80,0],[42,0],[55,0]],"id":52385936}],"con":true,"img":false}]}
{"op":"mcm","clk":"11449697094","pt":1717313648544,"mc":[{"id":"1.229554922","rc":[{"atb":[[34,3.17],[85,0.31],[44,1.83],[60,0.88]],"id":52385936}],"con":true,"img":false}]}
{"op":"mcm","clk":"11449730180","pt":1717314027587,"mc":[{"id":"1.229554922","rc":[{"atb":[[11,0],[13.5,0],[8.4,0],[9.4,0]],"id":52385933},{"atb":[[12,0],[9.8,0],[8.8,0],[14.5,0]],"id":52385897}],"con":true,"img":false}]}
{"op":"mcm","clk":"11449730256","pt":1717314028318,"mc":[{"id":"1.229554922","rc":[{"atb":[[9.6,9.12],[8.6,13.77],[11.5,4.98],[14,2.01]],"id":52385933},{"atb":[[9.2,12.76],[10.5,8.26],[13,4.36],[15.5,1.81]],"id":52385897}],"con":true,"img":false}]}
{"op":"mcm","clk":"11449749719","pt":1717314240095,"mc":[{"id":"1.229554922","rc":[{"atb":[[36,0],[19,0],[23,0],[28,0]],"id":52385934}],"con":true,"img":false}]}
{"op":"mcm","clk":"11449749790","pt":1717314240821,"mc":[{"id":"1.229554922","rc":[{"atb":[[40,0.67],[20,5.51],[25,3.27],[30,1.81]],"id":52385934}],"con":true,"img":false}]}
{"op":"mcm","clk":"11449750501","pt":1717314248437,"mc":[{"id":"1.229554922","rc":[{"atb":[[17,0],[19.5,0],[24,0],[14.5,0]],"id":52385927},{"atb":[[16.5,0],[19,0],[23,0],[28,0]],"id":52385904},{"atb":[[34,0],[18.5,0],[22,0],[27,0]],"id":52385937},{"atb":[[16.5,0],[19,0],[23,0],[14,0]],"id":52385924},{"atb":[[18,0],[21,0],[13,0],[15.5,0]],"id":52385903},{"atb":[[34,0],[85,0],[44,0],[60,0]],"id":52385936},{"atb":[[34,0],[18.5,0],[22,0],[27,0]],"id":52385905}],"con":true,"img":false}]}
{"op":"mcm","clk":"11449750565","pt":1717314249108,"mc":[{"id":"1.229554922","rc":[{"atb":[[17,4.9],[19.5,2.83],[24,1.14],[14.5,7.75]],"id":52385927},{"atb":[[34,3.17],[85,0.31],[44,1.83],[60,0.88]],"id":52385936}],"con":true,"img":false}]}
{"op":"mcm","clk":"11449750576","pt":1717314249213,"mc":[{"id":"1.229554922","rc":[{"atb":[[16.5,6.75],[19,4.36],[23,2.38],[28,0.97]],"id":52385904},{"atb":[[34,0.8],[18.5,5.98],[22,3.74],[27,2.01]],"id":52385937},{"atb":[[16.5,5.06],[19,2.91],[23,1.19],[14,8.05]],"id":52385924},{"atb":[[18,3.08],[21,1.31],[13,8.72],[15.5,5.41]],"id":52385903},{"atb":[[34,0.8],[18.5,5.98],[22,3.74],[27,2.01]],"id":52385905}],"con":true,"img":false}]}
{"op":"mcm","clk":"11449753616","pt":1717314283663,"mc":[{"id":"1.229554922","rc":[{"atb":[[75,0],[40,0]],"id":52385908},{"atb":[[17,0],[24,0]],"id":52385918},{"atb":[[16,5.23],[11,0]],"id":52385887},{"atb":[[330,0],[430,0]],"id":52385920},{"atb":[[4.3,0],[5.3,0]],"id":52385889},{"atb":[[5.3,0],[6.6,0]],"id":52385883},{"atb":[[10.5,0],[15.5,0]],"id":52385894},{"atb":[[80,0],[42,0]],"id":52385927},{"atb":[[5.6,0],[7.2,0]],"id":52385896},{"atb":[[550,0],[650,0]],"id":52385929},{"atb":[[5.1,0],[6.2,0]],"id":52385890},{"atb":[[17.5,0],[25,0]],"id":52385923},{"atb":[[17.5,6.34],[12.5,0]],"id":52385925},{"atb":[[5.6,0],[7.2,0]],"id":52385902},{"atb":[[9.8,0],[14.5,0]],"id":52385904},{"atb":[[16,0],[11,0]],"id":52385937},{"atb":[[16,5.23],[11,0]],"id":52385898},{"atb":[[4.5,0],[5.5,0]],"id":52385931},{"atb":[[18.5,0],[27,0]],"id":52385900},{"atb":[[5.3,0],[6.6,0]],"id":52385933},{"atb":[[300,0],[400,0]],"id":52385907},{"atb":[[10,0],[15,0]],"id":52385909},{"atb":[[21,0],[15.5,0]],"id":52385886},{"atb":[[32,0],[21,0]],"id":52385919},{"atb":[[4.5,0],[5.5,0]],"id":52385888},{"atb":[[4.3,0],[5.3,0]],"id":52385882},{"atb":[[13.5,0],[9.4,0]],"id":52385884},{"atb":[[17.5,0],[25,0]],"id":52385917},{"atb":[[19,0],[14,0]],"id":52385926},{"atb":[[4.3,0],[5.3,0]],"id":52385895},{"atb":[[6.8,0],[5.4,0]],"id":52385897},{"atb":[[550,0],[650,0]],"id":52385922},{"atb":[[9.2,0],[13,0]],"id":52385891},{"atb":[[18,0],[13,0]],"id":52385924},{"atb":[[20,0],[15,0]],"id":52385893},{"atb":[[13.5,0],[9.4,0]],"id":52385934},{"atb":[[10,0],[15,0]],"id":52385903},{"atb":[[21,0],[15.5,0]],"id":52385936},{"atb":[[17,0],[12,0]],"id":52385905},{"atb":[[18,6.15],[13,0]],"id":52385930},{"atb":[[4.3,0],[5.3,0]],"id":52385932},{"atb":[[18.5,0],[13.5,0]],"id":52385901}],"con":true,"img":false}]}
{"op":"mcm","clk":"11449755540","pt":1717314306202,"mc":[{"id":"1.229554922","rc":[{"atb":[[75,1.41],[40,6.25]],"id":52385908},{"atb":[[17,15.24],[24,4.54]],"id":52385918},{"atb":[[16,12.2],[11,24.39]],"id":52385887},{"atb":[[330,0.74],[430,0.24]],"id":52385920},{"atb":[[4.3,73.9],[5.3,24.31]],"id":52385889},{"atb":[[5.3,56.72],[6.6,18.66]],"id":52385883},{"atb":[[10.5,25.67],[15.5,7.2]],"id":52385894},{"atb":[[80,1.32],[42,5.94]],"id":52385927},{"atb":[[5.6,53.02],[7.2,16.86]],"id":52385896},{"atb":[[550,0.44],[650,0.16]],"id":52385929},{"atb":[[5.1,59.49],[6.2,20.1]],"id":52385890},{"atb":[[17.5,14.77],[25,4.35]],"id":52385923},{"atb":[[17.5,12.68],[12.5,21.2]],"id":52385925},{"atb":[[5.6,53.02],[7.2,16.86]],"id":52385902},{"atb":[[9.8,27.71],[14.5,7.74]],"id":52385904},{"atb":[[16,6.96],[11,24.39]],"id":52385937},{"atb":[[16,12.2],[11,24.39]],"id":52385898},{"atb":[[4.5,69.68],[5.5,23.22]],"id":52385931},{"atb":[[18.5,13.93],[27,4.01]],"id":52385900},{"atb":[[5.3,56.72],[6.6,18.66]],"id":52385933},{"atb":[[300,0.81],[400,0.26]],"id":52385907},{"atb":[[10,27.1],[15,7.46]],"id":52385909},{"atb":[[21,5.22],[15.5,16.82]],"id":52385886},{"atb":[[32,3.37],[21,12.19]],"id":52385919},{"atb":[[4.5,69.68],[5.5,23.22]],"id":52385888},{"atb":[[4.3,73.9],[5.3,24.31]],"id":52385882},{"atb":[[13.5,8.36],[9.4,29.03]],"id":52385884},{"atb":[[17.5,14.77],[25,4.35]],"id":52385917},{"atb":[[19,5.8],[14,18.76]],"id":52385926},{"atb":[[4.3,73.9],[5.3,24.31]],"id":52385895},{"atb":[[6.8,18.02],[5.4,55.43]],"id":52385897},{"atb":[[550,0.44],[650,0.16]],"id":52385922},{"atb":[[9.2,29.74],[13,8.71]],"id":52385891},{"atb":[[18,6.14],[13,20.32]],"id":52385924},{"atb":[[20,5.5],[15,17.42]],"id":52385893},{"atb":[[13.5,8.36],[9.4,29.03]],"id":52385934},{"atb":[[10,27.1],[15,7.46]],"id":52385903},{"atb":[[21,5.22],[15.5,16.82]],"id":52385936},{"atb":[[17,6.53],[12,22.17]],"id":52385905},{"atb":[[18,12.3],[13,20.32]],"id":52385930},{"atb":[[4.3,73.9],[5.3,24.31]],"id":52385932},{"atb":[[18.5,5.97],[13.5,19.51]],"id":52385901}],"con":true,"img":false}]}
{"op":"mcm","clk":"11449788889","pt":1717314686017,"mc":[{"id":"1.229554922","rc":[{"atb":[[11,0],[13.5,0],[8.4,0],[9.4,0]],"id":52385890},{"atb":[[40,0],[20,0],[25,0],[30,0]],"id":52385934}],"con":true,"img":false}]}
{"op":"mcm","clk":"11449788952","pt":1717314686737,"mc":[{"id":"1.229554922","rc":[{"atb":[[9.6,9.12],[8.6,13.77],[11.5,4.98],[14,2.01]],"id":52385890},{"atb":[[38,0.71],[19.5,5.66],[24,3.41],[29,1.87]],"id":52385934}],"con":true,"img":false}]}
{"op":"mcm","clk":"11449823477","pt":1717315076909,"mc":[{"id":"1.229554922","rc":[{"atb":[[17,0],[19.5,0],[12,0],[14.5,0]],"id":52385908},{"atb":[[38,0],[19.5,0],[24,0],[29,0]],"id":52385894},{"atb":[[17.5,6.33],[20,0],[25,0],[30,0]],"id":52385925},{"atb":[[34,0],[18.5,0],[22,0],[27,0]],"id":52385937},{"atb":[[130,0],[65,0],[90,0],[46,0]],"id":52385919},{"atb":[[34,0],[85,0],[44,0],[60,0]],"id":52385936},{"atb":[[32,0],[18,6.14],[21,0],[26,0]],"id":52385930}],"con":true,"img":false}]}
{"op":"mcm","clk":"11449823489","pt":1717315077010,"mc":[{"id":"1.229554922","rc":[{"atb":[[75,0],[40,0],[100,0],[50,0]],"id":52385918},{"atb":[[80,0],[42,0],[110,0],[55,0]],"id":52385923},{"atb":[[38,0],[48,0],[24,0],[29,0]],"id":52385900},{"atb":[[34,0],[18.5,0],[22,0],[27,0]],"id":52385909},{"atb":[[32,0],[42,0],[26,0],[55,0]],"id":52385886},{"atb":[[34,0],[18.5,0],[22,0],[27,0]],"id":52385884},{"atb":[[70,0],[38,0],[48,0],[29,0]],"id":52385917},{"atb":[[32,0],[80,0],[42,0],[55,0]],"id":52385893}],"con":true,"img":false}]}
{"op":"mcm","clk":"11449823546","pt":1717315077637,"mc":[{"id":"1.229554922","rc":[{"atb":[[150,0.53],[200,0.26],[100,1.06],[250,0.1]],"id":52385908},{"atb":[[36,1.5],[46,0.58],[23,4.76],[28,2.91]],"id":52385894},{"atb":[[75,0.36],[40,2.01],[50,1.07],[30,3.61]],"id":52385925},{"atb":[[17.5,6.34],[20,4.13],[25,2.18],[30,0.9]],"id":52385937},{"atb":[[34,3.17],[85,0.31],[44,1.83],[60,0.88]],"id":52385919},{"atb":[[17.5,6.34],[20,4.13],[25,2.18],[30,0.9]],"id":52385936},{"atb":[[32,3.37],[80,0.33],[42,1.92],[55,0.97]],"id":52385930}],"con":true,"img":false}]}
{"op":"mcm","clk":"11449823553","pt":1717315077693,"mc":[{"id":"1.229554922","rc":[{"atb":[[34,2.38],[44,1.22],[27,4.02],[60,0.44]],"id":52385918},{"atb":[[34,2.38],[44,1.22],[27,4.02],[60,0.44]],"id":52385923},{"atb":[[32,1.69],[42,0.64],[21,5.23],[26,3.14]],"id":52385900},{"atb":[[34,2.38],[44,1.22],[27,4.02],[60,0.44]],"id":52385909},{"atb":[[36,1.5],[46,0.58],[23,4.76],[28,2.91]],"id":52385886},{"atb":[[40,0.67],[20,5.51],[25,3.27],[30,1.81]],"id":52385884},{"atb":[[40,1.34],[25,8.71],[50,0.53],[30,2.71]],"id":52385917},{"atb":[[36,1.5],[46,0.58],[23,4.76],[28,2.91]],"id":52385893}],"con":true,"img":false}]}
{"op":"mcm","clk":"11449843249","pt":1717315213880,"mc":[{"id":"1.229554922","rc":[{"atb":[[17,0],[19.5,0],[24,0],[14.5,0]],"id":52385927}],"con":true,"img":false}]}
{"op":"mcm","clk":"11449843263","pt":1717315213980,"mc":[{"id":"1.229554922","rc":[{"atb":[[16.5,0],[19,0],[23,0],[28,0]],"id":52385904},{"atb":[[16.5,0],[19,0],[23,0],[14,0]],"id":52385924},{"atb":[[18,0],[21,0],[13,0],[15.5,0]],"id":52385903},{"atb":[[34,0],[18.5,0],[22,0],[27,0]],"id":52385905}],"con":true,"img":false}]}
{"op":"mcm","clk":"11449843328","pt":1717315214593,"mc":[{"id":"1.229554922","rc":[{"atb":[[270,0.1],[170,0.47],[220,0.24],[120,0.88]],"id":52385927}],"con":true,"img":false}]}
{"op":"mcm","clk":"11449843343","pt":1717315214699,"mc":[{"id":"1.229554922","rc":[{"atb":[[34,2.38],[44,1.22],[27,4.02],[60,0.44]],"id":52385904},{"atb":[[75,0.36],[40,2.01],[50,1.07],[30,3.61]],"id":52385924},{"atb":[[34,2.38],[44,1.22],[27,4.02],[60,0.44]],"id":52385903},{"atb":[[75,0.36],[40,2.01],[50,1.07],[30,3.61]],"id":52385905}],"con":true,"img":false}]}
{"op":"mcm","clk":"11449862824","pt":1717315412181,"mc":[{"id":"1.229554922","rc":[{"atb":[[75,0],[40,0]],"id":52385908},{"atb":[[17,0],[24,0]],"id":52385918},{"atb":[[16,5.23],[11,0]],"id":52385887},{"atb":[[330,0],[430,0]],"id":52385920},{"atb":[[4.3,0],[5.3,0]],"id":52385889},{"atb":[[5.3,0],[6.6,0]],"id":52385883},{"atb":[[10.5,0],[15.5,0]],"id":52385894},{"atb":[[80,0],[42,0]],"id":52385927},{"atb":[[5.6,0],[7.2,0]],"id":52385896},{"atb":[[550,0],[650,0]],"id":52385929},{"atb":[[5.1,0],[6.2,0]],"id":52385890},{"atb":[[17.5,0],[25,0]],"id":52385923},{"atb":[[17.5,0],[12.5,0]],"id":52385925},{"atb":[[5.6,0],[7.2,0]],"id":52385902},{"atb":[[9.8,0],[14.5,0]],"id":52385904},{"atb":[[16,0],[11,0]],"id":52385937},{"atb":[[16,5.23],[11,0]],"id":52385898},{"atb":[[4.5,0],[5.5,0]],"id":52385931},{"atb":[[18.5,0],[27,0]],"id":52385900},{"atb":[[5.3,0],[6.6,0]],"id":52385933},{"atb":[[300,0],[400,0]],"id":52385907},{"atb":[[10,0],[15,0]],"id":52385909},{"atb":[[21,0],[15.5,0]],"id":52385886},{"atb":[[32,0],[21,0]],"id":52385919},{"atb":[[4.5,0],[5.5,0]],"id":52385888},{"atb":[[4.3,0],[5.3,0]],"id":52385882},{"atb":[[13.5,0],[9.4,0]],"id":52385884},{"atb":[[17.5,0],[25,4.36]],"id":52385917},{"atb":[[19,0],[14,0]],"id":52385926},{"atb":[[4.3,0],[5.3,0]],"id":52385895},{"atb":[[6.8,0],[5.4,0]],"id":52385897},{"atb":[[550,0],[650,0]],"id":52385922},{"atb":[[9.2,0],[13,0]],"id":52385891},{"atb":[[18,0],[13,0]],"id":52385924},{"atb":[[20,0],[15,0]],"id":52385893},{"atb":[[13.5,0],[9.4,0]],"id":52385934},{"atb":[[10,0],[15,0]],"id":52385903},{"atb":[[21,0],[15.5,0]],"id":52385936},{"atb":[[17,0],[12,0]],"id":52385905},{"atb":[[18,0],[13,0]],"id":52385930},{"atb":[[4.3,0],[5.3,0]],"id":52385932},{"atb":[[18.5,0],[13.5,0]],"id":52385901}],"con":true,"img":false}]}
{"op":"mcm","clk":"11449866542","pt":1717315447498,"mc":[{"id":"1.229554922","rc":[{"atb":[[75,1.41],[40,6.25]],"id":52385908},{"atb":[[17,15.24],[24,4.54]],"id":52385918},{"atb":[[16,12.2],[11,24.39]],"id":52385887},{"atb":[[330,0.74],[430,0.24]],"id":52385920},{"atb":[[4.3,73.9],[5.3,24.31]],"id":52385889},{"atb":[[5.3,56.72],[6.6,18.66]],"id":52385883},{"atb":[[10.5,25.67],[15.5,7.2]],"id":52385894},{"atb":[[80,1.32],[42,5.94]],"id":52385927},{"atb":[[5.6,53.02],[7.2,16.86]],"id":52385896},{"atb":[[550,0.44],[650,0.16]],"id":52385929},{"atb":[[5.1,59.49],[6.2,20.1]],"id":52385890},{"atb":[[17.5,14.77],[25,4.35]],"id":52385923},{"atb":[[17.5,6.33],[12.5,21.2]],"id":52385925},{"atb":[[5.6,53.02],[7.2,16.86]],"id":52385902},{"atb":[[9.8,27.71],[14.5,7.74]],"id":52385904},{"atb":[[16,6.96],[11,24.39]],"id":52385937},{"atb":[[16,12.2],[11,24.39]],"id":52385898},{"atb":[[4.5,69.68],[5.5,23.22]],"id":52385931},{"atb":[[18.5,13.93],[27,4.01]],"id":52385900},{"atb":[[5.3,56.72],[6.6,18.66]],"id":52385933},{"atb":[[300,0.81],[400,0.26]],"id":52385907},{"atb":[[10,27.1],[15,7.46]],"id":52385909},{"atb":[[21,5.22],[15.5,16.82]],"id":52385886},{"atb":[[32,3.37],[21,12.19]],"id":52385919},{"atb":[[4.5,69.68],[5.5,23.22]],"id":52385888},{"atb":[[4.3,73.9],[5.3,24.31]],"id":52385882},{"atb":[[13.5,8.36],[9.4,29.03]],"id":52385884},{"atb":[[17.5,14.77],[25,8.71]],"id":52385917},{"atb":[[19,5.8],[14,18.76]],"id":52385926},{"atb":[[4.3,73.9],[5.3,24.31]],"id":52385895},{"atb":[[6.8,18.02],[5.4,55.43]],"id":52385897},{"atb":[[550,0.44],[650,0.16]],"id":52385922},{"atb":[[9.2,29.74],[13,8.71]],"id":52385891},{"atb":[[18,6.14],[13,20.32]],"id":52385924},{"atb":[[20,5.5],[15,17.42]],"id":52385893},{"atb":[[13.5,8.36],[9.4,29.03]],"id":52385934},{"atb":[[10,27.1],[15,7.46]],"id":52385903},{"atb":[[21,5.22],[15.5,16.82]],"id":52385936},{"atb":[[17,6.53],[12,22.17]],"id":52385905},{"atb":[[18,6.14],[13,20.32]],"id":52385930},{"atb":[[4.3,73.9],[5.3,24.31]],"id":52385932},{"atb":[[18.5,5.97],[13.5,19.51]],"id":52385901}],"con":true,"img":false}]}
{"op":"mcm","clk":"11449875824","pt":1717315535557,"mc":[{"id":"1.229554922","rc":[{"atb":[[270,0],[170,0],[220,0],[120,0]],"id":52385927},{"atb":[[75,0],[40,0],[50,0],[30,0]],"id":52385925}],"con":true,"img":false}]}
{"op":"mcm","clk":"11449875903","pt":1717315536380,"mc":[{"id":"1.229554922","rc":[{"atb":[[260,0.1],[160,0.49],[210,0.25],[110,0.96]],"id":52385927},{"atb":[[32,3.37],[80,0.33],[42,1.92],[55,0.97]],"id":52385925}],"con":true,"img":false}]}
{"op":"mcm","clk":"11449875985","pt":1717315537362,"mc":[{"id":"1.229554922","rc":[{"atb":[[32,0],[80,0],[42,0],[55,0]],"id":52385925}],"con":true,"img":false}]}
{"op":"mcm","clk":"11449876050","pt":1717315538080,"mc":[{"id":"1.229554922","rc":[{"atb":[[75,0.36],[40,2.01],[50,1.07],[30,3.61]],"id":52385925}],"con":true,"img":false}]}
{"op":"mcm","clk":"11449893712","pt":1717315713192,"mc":[{"id":"1.229554922","rc":[{"atb":[[75,0],[40,0]],"id":52385908},{"atb":[[17,0],[24,0]],"id":52385918},{"atb":[[16,5.23],[11,0]],"id":52385887},{"atb":[[330,0],[430,0]],"id":52385920},{"atb":[[4.3,0],[5.3,0]],"id":52385889},{"atb":[[5.3,0],[6.6,0]],"id":52385883},{"atb":[[10.5,0],[15.5,0]],"id":52385894},{"atb":[[80,0],[42,0]],"id":52385927},{"atb":[[5.6,0],[7.2,0]],"id":52385896},{"atb":[[550,0],[650,0]],"id":52385929},{"atb":[[5.1,0],[6.2,0]],"id":52385890},{"atb":[[17.5,0],[25,0]],"id":52385923},{"atb":[[17.5,0],[12.5,0]],"id":52385925},{"atb":[[5.6,0],[7.2,0]],"id":52385902},{"atb":[[9.8,0],[14.5,0]],"id":52385904},{"atb":[[16,0],[11,0]],"id":52385937},{"atb":[[16,5.23],[11,0]],"id":52385898},{"atb":[[4.5,0],[5.5,0]],"id":52385931},{"atb":[[18.5,0],[27,0]],"id":52385900},{"atb":[[5.3,0],[6.6,0]],"id":52385933},{"atb":[[300,0],[400,0]],"id":52385907},{"atb":[[10,0],[15,0]],"id":52385909},{"atb":[[21,0],[15.5,0]],"id":52385886},{"atb":[[32,0],[21,0]],"id":52385919},{"atb":[[4.5,0],[5.5,0]],"id":52385888},{"atb":[[4.3,0],[5.3,0]],"id":52385882},{"atb":[[13.5,0],[9.4,0]],"id":52385884},{"atb":[[17.5,0],[25,4.36]],"id":52385917},{"atb":[[19,0],[14,0]],"id":52385926},{"atb":[[4.3,0],[5.3,0]],"id":52385895},{"atb":[[6.8,0],[5.4,0]],"id":52385897},{"atb":[[550,0],[650,0]],"id":52385922},{"atb":[[9.2,0],[13,0]],"id":52385891},{"atb":[[18,0],[13,0]],"id":52385924},{"atb":[[20,0],[15,0]],"id":52385893},{"atb":[[13.5,0],[9.4,0]],"id":52385934},{"atb":[[10,0],[15,0]],"id":52385903},{"atb":[[21,0],[15.5,0]],"id":52385936},{"atb":[[17,0],[12,0]],"id":52385905},{"atb":[[18,0],[13,0]],"id":52385930},{"atb":[[4.3,0],[5.3,0]],"id":52385932},{"atb":[[18.5,0],[13.5,0]],"id":52385901}],"con":true,"img":false}]}
{"op":"mcm","clk":"11449899234","pt":1717315764715,"mc":[{"id":"1.229554922","rc":[{"atb":[[75,1.41],[40,6.25]],"id":52385908},{"atb":[[19,13.55],[28,3.87]],"id":52385918},{"atb":[[610,0.17],[510,0.48]],"id":52385920},{"atb":[[75,1.41],[40,6.25]],"id":52385927},{"atb":[[550,0.44],[650,0.16]],"id":52385929},{"atb":[[19.5,13.18],[29,3.73]],"id":52385923},{"atb":[[17,6.53],[12,22.17]],"id":52385925},{"atb":[[10.5,25.67],[15.5,7.2]],"id":52385937},{"atb":[[4.4,71.73],[5.4,23.75]],"id":52385931},{"atb":[[5.3,56.72],[6.6,18.66]],"id":52385933},{"atb":[[570,0.18],[470,0.51]],"id":52385907},{"atb":[[10,27.1],[15,7.46]],"id":52385909},{"atb":[[42,2.54],[26,9.75]],"id":52385919},{"atb":[[19.5,13.18],[29,3.73]],"id":52385917},{"atb":[[19,5.8],[14,18.76]],"id":52385926},{"atb":[[550,0.44],[650,0.16]],"id":52385922},{"atb":[[17.5,6.33],[12.5,21.2]],"id":52385924},{"atb":[[13.5,8.36],[9.4,29.03]],"id":52385934},{"atb":[[17,15.24],[24,4.54]],"id":52385936},{"atb":[[17.5,6.33],[12.5,21.2]],"id":52385930},{"atb":[[4.3,73.9],[5.3,24.31]],"id":52385932}],"con":true,"img":false}]}
{"op":"mcm","clk":"11449899246","pt":1717315764822,"mc":[{"id":"1.229554922","rc":[{"atb":[[10.5,25.67],[15.5,7.2]],"id":52385887},{"atb":[[4.3,73.9],[5.3,24.31]],"id":52385889},{"atb":[[5.3,56.72],[6.6,18.66]],"id":52385883},{"atb":[[10.5,25.67],[15.5,7.2]],"id":52385894},{"atb":[[5.5,54.2],[7,17.42]],"id":52385896},{"atb":[[5.1,59.49],[6.2,20.1]],"id":52385890},{"atb":[[5.5,54.2],[7,17.42]],"id":52385902},{"atb":[[9.8,27.71],[14.5,7.74]],"id":52385904},{"atb":[[10.5,25.67],[15.5,7.2]],"id":52385898},{"atb":[[32,5.06],[21,17.43]],"id":52385900},{"atb":[[17,15.24],[24,4.54]],"id":52385886},{"atb":[[4.4,71.73],[5.4,23.75]],"id":52385888},{"atb":[[4.3,73.9],[5.3,24.31]],"id":52385882},{"atb":[[13.5,8.36],[9.4,29.03]],"id":52385884},{"atb":[[4.3,73.9],[5.3,24.31]],"id":52385895},{"atb":[[5.3,56.72],[6.6,18.66]],"id":52385897},{"atb":[[9.2,29.74],[13,8.71]],"id":52385891},{"atb":[[16.5,15.73],[23,9.51]],"id":52385893},{"atb":[[10,27.1],[15,7.46]],"id":52385903},{"atb":[[17,6.53],[12,22.17]],"id":52385905},{"atb":[[18.5,5.97],[13.5,19.51]],"id":52385901}],"con":true,"img":false}]}
{"op":"mcm","clk":"11449928464","pt":1717316047189,"mc":[{"id":"1.229554922","rc":[{"atb":[[150,0],[200,0],[100,0],[250,0]],"id":52385908},{"atb":[[9.6,0],[8.6,0],[11.5,0],[14,0]],"id":52385933}],"con":true,"img":false}]}
{"op":"mcm","clk":"11449928532","pt":1717316047860,"mc":[{"id":"1.229554922","rc":[{"atb":[[12,4.76],[9.8,8.92],[8.8,13.41],[14.5,1.94]],"id":52385933}],"con":true,"img":false}]}
{"op":"mcm","clk":"11449928546","pt":1717316047962,"mc":[{"id":"1.229554922","rc":[{"atb":[[260,0.1],[160,0.49],[210,0.25],[110,0.96]],"id":52385908}],"con":true,"img":false}]}
{"op":"mcm","clk":"11449970502","pt":1717316552663,"mc":[{"id":"1.229554922","rc":[{"atb":[[75,0],[40,0]],"id":52385908},{"atb":[[19,0],[28,0]],"id":52385918},{"atb":[[10.5,0],[15.5,0]],"id":52385887},{"atb":[[610,0],[510,0]],"id":52385920},{"atb":[[4.3,0],[5.3,0]],"id":52385889},{"atb":[[5.3,0],[6.6,0]],"id":52385883},{"atb":[[10.5,0],[15.5,0]],"id":52385894},{"atb":[[5.5,0],[7,0]],"id":52385896},{"atb":[[5.1,0],[6.2,0]],"id":52385890},{"atb":[[19.5,0],[29,0]],"id":52385923},{"atb":[[5.5,0],[7,0]],"id":52385902},{"atb":[[9.8,0],[14.5,0]],"id":52385904},{"atb":[[10.5,0],[15.5,0]],"id":52385898},{"atb":[[32,1.69],[21,5.23]],"id":52385900},{"atb":[[570,0],[470,0]],"id":52385907},{"atb":[[10,0],[15,0]],"id":52385909},{"atb":[[17,0],[24,0]],"id":52385886},{"atb":[[42,0],[26,0]],"id":52385919},{"atb":[[4.4,0],[5.4,0]],"id":52385888},{"atb":[[4.3,0],[5.3,0]],"id":52385882},{"atb":[[13.5,0],[9.4,0]],"id":52385884},{"atb":[[19.5,0],[29,0]],"id":52385917},{"atb":[[4.3,0],[5.3,0]],"id":52385895},{"atb":[[5.3,0],[6.6,0]],"id":52385897},{"atb":[[550,0],[650,0]],"id":52385922},{"atb":[[9.2,0],[13,0]],"id":52385891},{"atb":[[16.5,0],[23,4.76]],"id":52385893},{"atb":[[10,0],[15,0]],"id":52385903},{"atb":[[17,0],[12,0]],"id":52385905},{"atb":[[18.5,0],[13.5,0]],"id":52385901}],"con":true,"img":false}]}
{"op":"mcm","clk":"11449970518","pt":1717316552873,"mc":[{"id":"1.229554922","rc":[{"atb":[[75,0],[40,0]],"id":52385927},{"atb":[[550,0],[650,0]],"id":52385929},{"atb":[[17,0],[12,0]],"id":52385925},{"atb":[[10.5,0],[15.5,0]],"id":52385937},{"atb":[[4.4,0],[5.4,0]],"id":52385931},{"atb":[[5.3,0],[6.6,0]],"id":52385933},{"atb":[[19,0],[14,0]],"id":52385926},{"atb":[[17.5,0],[12.5,0]],"id":52385924},{"atb":[[13.5,0],[9.4,0]],"id":52385934},{"atb":[[17,0],[24,0]],"id":52385936},{"atb":[[17.5,0],[12.5,0]],"id":52385930},{"atb":[[4.3,0],[5.3,0]],"id":52385932}],"con":true,"img":false}]}
{"op":"mcm","clk":"11449971667","pt":1717316571229,"mc":[{"id":"1.229554922","rc":[{"atb":[[10.5,25.67],[15.5,7.2]],"id":52385887},{"atb":[[4.3,73.9],[5.3,24.31]],"id":52385889},{"atb":[[5.3,56.72],[6.6,18.66]],"id":52385883},{"atb":[[10.5,25.67],[15.5,7.2]],"id":52385894},{"atb":[[5.5,54.2],[7,17.42]],"id":52385896},{"atb":[[5.1,59.49],[6.2,20.1]],"id":52385890},{"atb":[[5.5,54.2],[7,17.42]],"id":52385902},{"atb":[[9.8,27.71],[14.5,7.74]],"id":52385904},{"atb":[[10.5,25.67],[15.5,7.2]],"id":52385898},{"atb":[[32,5.06],[21,17.43]],"id":52385900},{"atb":[[17,15.24],[24,4.54]],"id":52385886},{"atb":[[4.4,71.73],[5.4,23.75]],"id":52385888},{"atb":[[4.3,73.9],[5.3,24.31]],"id":52385882},{"atb":[[13.5,8.36],[9.4,29.03]],"id":52385884},{"atb":[[4.3,73.9],[5.3,24.31]],"id":52385895},{"atb":[[5.3,56.72],[6.6,18.66]],"id":52385897},{"atb":[[9.2,29.74],[13,8.71]],"id":52385891},{"atb":[[16.5,15.73],[23,9.51]],"id":52385893},{"atb":[[10,27.1],[15,7.46]],"id":52385903},{"atb":[[17,6.53],[12,22.17]],"id":52385905},{"atb":[[18.5,5.97],[13.5,19.51]],"id":52385901}],"con":true,"img":false}]}
{"op":"mcm","clk":"11449972397","pt":1717316581815,"mc":[{"id":"1.229554922","rc":[{"atb":[[75,1.41],[40,6.25]],"id":52385908},{"atb":[[19,13.55],[28,3.87]],"id":52385918},{"atb":[[610,0.17],[510,0.48]],"id":52385920},{"atb":[[75,1.41],[40,6.25]],"id":52385927},{"atb":[[550,0.44],[650,0.16]],"id":52385929},{"atb":[[19.5,13.18],[29,3.73]],"id":52385923},{"atb":[[17,6.53],[12,22.17]],"id":52385925},{"atb":[[10.5,25.67],[15.5,7.2]],"id":52385937},{"atb":[[4.4,71.73],[5.4,23.75]],"id":52385931},{"atb":[[5.3,56.72],[6.6,18.66]],"id":52385933},{"atb":[[570,0.18],[470,0.51]],"id":52385907},{"atb":[[10,27.1],[15,7.46]],"id":52385909},{"atb":[[42,2.54],[26,9.75]],"id":52385919},{"atb":[[19.5,13.18],[29,3.73]],"id":52385917},{"atb":[[19,5.8],[14,18.76]],"id":52385926},{"atb":[[550,0.44],[650,0.16]],"id":52385922},{"atb":[[17.5,6.33],[12.5,21.2]],"id":52385924},{"atb":[[13.5,8.36],[9.4,29.03]],"id":52385934},{"atb":[[17,15.24],[24,4.54]],"id":52385936},{"atb":[[17.5,6.33],[12.5,21.2]],"id":52385930},{"atb":[[4.3,73.9],[5.3,24.31]],"id":52385932}],"con":true,"img":false}]}
{"op":"mcm","clk":"11449974938","pt":1717316617552,"mc":[{"id":"1.229554922","rc":[{"atb":[[260,0],[160,0],[210,0],[110,0]],"id":52385908},{"atb":[[36,0],[46,0],[23,0],[28,0]],"id":52385894},{"atb":[[75,0],[40,0],[50,0],[30,0]],"id":52385925}],"con":true,"img":false}]}
{"op":"mcm","clk":"11449974982","pt":1717316618275,"mc":[{"id":"1.229554922","rc":[{"atb":[[260,0.1],[160,0.49],[210,0.25],[110,0.96]],"id":52385908},{"atb":[[36,1.5],[46,0.58],[23,4.76],[28,2.91]],"id":52385894},{"atb":[[75,0.36],[40,2.01],[50,1.07],[30,3.61]],"id":52385925}],"con":true,"img":false}]}
{"op":"mcm","clk":"11449975039","pt":1717316619059,"mc":[{"id":"1.229554922","rc":[{"atb":[[260,0],[160,0],[210,0],[110,0]],"id":52385908},{"atb":[[34,0],[44,0],[27,0],[60,0]],"id":52385918},{"atb":[[36,0],[46,0],[23,0],[28,0]],"id":52385894},{"atb":[[260,0],[160,0],[210,0],[110,0]],"id":52385927},{"atb":[[34,0],[44,0],[27,0],[60,0]],"id":52385923},{"atb":[[75,0],[40,0],[50,0],[30,0]],"id":52385925},{"atb":[[32,3.37],[42,0],[21,12.19],[26,0]],"id":52385900},{"atb":[[34,0],[85,0],[44,0],[60,0]],"id":52385919},{"atb":[[40,0],[50,0],[25,0],[30,0]],"id":52385917},{"atb":[[17.5,0],[20,0],[25,0],[30,0]],"id":52385936}],"con":true,"img":false}]}
{"op":"mcm","clk":"11449975079","pt":1717316619783,"mc":[{"id":"1.229554922","rc":[{"atb":[[140,0.57],[190,0.28],[95,1.11],[240,0.11]],"id":52385908},{"atb":[[36,1.5],[46,0.58],[23,4.76],[28,2.91]],"id":52385894},{"atb":[[150,0.53],[200,0.26],[100,1.06],[250,0.1]],"id":52385927},{"atb":[[40,1.34],[50,0.53],[25,4.36],[30,2.71]],"id":52385923},{"atb":[[75,0.36],[40,2.01],[50,1.07],[30,3.61]],"id":52385925},{"atb":[[75,0.36],[40,2.01],[50,1.07],[30,3.61]],"id":52385919},{"atb":[[38,1.41],[48,0.55],[24,4.55],[29,6.54]],"id":52385917}],"con":true,"img":false}]}
{"op":"mcm","clk":"11449975087","pt":1717316619887,"mc":[{"id":"1.229554922","rc":[{"atb":[[32,2.53],[42,1.28],[26,4.19],[55,0.49]],"id":52385918},{"atb":[[40,0.67],[20,5.51],[25,3.27],[30,1.81]],"id":52385900},{"atb":[[17,21.79],[19.5,4.24],[24,6.82],[29,0.94]],"id":52385936}],"con":true,"img":false}]}
{"op":"mcm","clk":"11450000357","pt":1717316949476,"mc":[{"id":"1.229554922","rc":[{"atb":[[36,0],[46,0],[23,4.75],[28,0]],"id":52385893}],"con":true,"img":false}]}
{"op":"mcm","clk":"11450000425","pt":1717316950155,"mc":[{"id":"1.229554922","rc":[{"atb":[[36,1.5],[23,9.51],[46,0.58],[28,2.91]],"id":52385893}],"con":true,"img":false}]}
{"op":"mcm","clk":"11450051676","pt":1717317460761,"mc":[{"id":"1.229554922","rc":[{"atb":[[75,0],[40,0]],"id":52385908},{"atb":[[19,0],[28,0]],"id":52385918},{"atb":[[10.5,0],[15.5,0]],"id":52385887},{"atb":[[610,0],[510,0]],"id":52385920},{"atb":[[4.3,0],[5.3,0]],"id":52385889},{"atb":[[5.3,0],[6.6,0]],"id":52385883},{"atb":[[10.5,0],[15.5,0]],"id":52385894},{"atb":[[75,0],[40,0]],"id":52385927},{"atb":[[5.5,0],[7,0]],"id":52385896},{"atb":[[550,0],[650,0]],"id":52385929},{"atb":[[5.1,0],[6.2,0]],"id":52385890},{"atb":[[19.5,0],[29,0]],"id":52385923},{"atb":[[17,0],[12,0]],"id":52385925},{"atb":[[5.5,0],[7,0]],"id":52385902},{"atb":[[9.8,0],[14.5,0]],"id":52385904},{"atb":[[10.5,0],[15.5,0]],"id":52385937},{"atb":[[10.5,0],[15.5,0]],"id":52385898},{"atb":[[4.4,0],[5.4,0]],"id":52385931},{"atb":[[32,0],[21,0]],"id":52385900},{"atb":[[5.3,0],[6.6,0]],"id":52385933},{"atb":[[570,0],[470,0]],"id":52385907},{"atb":[[10,0],[15,0]],"id":52385909},{"atb":[[17,0],[24,0]],"id":52385886},{"atb":[[42,0],[26,0]],"id":52385919},{"atb":[[4.4,0],[5.4,0]],"id":52385888},{"atb":[[4.3,0],[5.3,0]],"id":52385882},{"atb":[[13.5,0],[9.4,0]],"id":52385884},{"atb":[[19.5,0],[29,2.8]],"id":52385917},{"atb":[[19,0],[14,0]],"id":52385926},{"atb":[[4.3,0],[5.3,0]],"id":52385895},{"atb":[[5.3,0],[6.6,0]],"id":52385897},{"atb":[[550,0],[650,0]],"id":52385922},{"atb":[[9.2,0],[13,0]],"id":52385891},{"atb":[[17.5,0],[12.5,0]],"id":52385924},{"atb":[[16.5,0],[23,4.76]],"id":52385893},{"atb":[[13.5,0],[9.4,0]],"id":52385934},{"atb":[[10,0],[15,0]],"id":52385903},{"atb":[[17,6.54],[24,2.28]],"id":52385936},{"atb":[[17,0],[12,0]],"id":52385905},{"atb":[[17.5,0],[12.5,0]],"id":52385930},{"atb":[[4.3,0],[5.3,0]],"id":52385932},{"atb":[[18.5,0],[13.5,0]],"id":52385901}],"con":true,"img":false}]}
{"op":"mcm","clk":"11450054325","pt":1717317490793,"mc":[{"id":"1.229554922","rc":[{"atb":[[75,1.41],[40,6.25]],"id":52385908},{"atb":[[19,13.55],[28,3.87]],"id":52385918},{"atb":[[10.5,25.67],[15.5,7.2]],"id":52385887},{"atb":[[610,0.17],[510,0.48]],"id":52385920},{"atb":[[4.3,73.9],[5.3,24.31]],"id":52385889},{"atb":[[5.3,56.72],[6.6,18.66]],"id":52385883},{"atb":[[10.5,25.67],[15.5,7.2]],"id":52385894},{"atb":[[75,1.41],[40,6.25]],"id":52385927},{"atb":[[5.5,54.2],[7,17.42]],"id":52385896},{"atb":[[550,0.44],[650,0.16]],"id":52385929},{"atb":[[5.1,59.49],[6.2,20.1]],"id":52385890},{"atb":[[19.5,13.18],[29,3.73]],"id":52385923},{"atb":[[17,6.53],[12,22.17]],"id":52385925},{"atb":[[5.5,54.2],[7,17.42]],"id":52385902},{"atb":[[9.8,27.71],[14.5,7.74]],"id":52385904},{"atb":[[10.5,25.67],[15.5,7.2]],"id":52385937},{"atb":[[10.5,25.67],[15.5,7.2]],"id":52385898},{"atb":[[4.4,71.73],[5.4,23.75]],"id":52385931},{"atb":[[32,3.37],[21,12.19]],"id":52385900},{"atb":[[5.3,56.72],[6.6,18.66]],"id":52385933},{"atb":[[570,0.18],[470,0.51]],"id":52385907},{"atb":[[10,27.1],[15,7.46]],"id":52385909},{"atb":[[17,15.24],[24,4.54]],"id":52385886},{"atb":[[42,2.54],[26,9.75]],"id":52385919},{"atb":[[4.4,71.73],[5.4,23.75]],"id":52385888},{"atb":[[4.3,73.9],[5.3,24.31]],"id":52385882},{"atb":[[13.5,8.36],[9.4,29.03]],"id":52385884},{"atb":[[19.5,13.18],[29,6.54]],"id":52385917},{"atb":[[19,5.8],[14,18.76]],"id":52385926},{"atb":[[4.3,73.9],[5.3,24.31]],"id":52385895},{"atb":[[5.3,56.72],[6.6,18.66]],"id":52385897},{"atb":[[550,0.44],[650,0.16]],"id":52385922},{"atb":[[9.2,29.74],[13,8.71]],"id":52385891},{"atb":[[17.5,6.33],[12.5,21.2]],"id":52385924},{"atb":[[16.5,15.73],[23,9.51]],"id":52385893},{"atb":[[13.5,8.36],[9.4,29.03]],"id":52385934},{"atb":[[10,27.1],[15,7.46]],"id":52385903},{"atb":[[17,21.79],[24,6.82]],"id":52385936},{"atb":[[17,6.53],[12,22.17]],"id":52385905},{"atb":[[17.5,6.33],[12.5,21.2]],"id":52385930},{"atb":[[4.3,73.9],[5.3,24.31]],"id":52385932},{"atb":[[18.5,5.97],[13.5,19.51]],"id":52385901}],"con":true,"img":false}]}
{"op":"mcm","clk":"11450100509","pt":1717318012931,"mc":[{"id":"1.229554922","rc":[{"atb":[[9.6,0],[8.6,0],[11.5,0],[7.6,0]],"id":52385889}],"con":true,"img":false}]}
{"op":"mcm","clk":"11450100572","pt":1717318013861,"mc":[{"id":"1.229554922","rc":[{"atb":[[9.6,0],[8.6,0],[11.5,0],[14,0]],"id":52385890},{"atb":[[12,0],[9.8,0],[8.8,0],[7.8,0]],"id":52385888},{"atb":[[12,0],[9.8,0],[8.8,0],[7.8,0]],"id":52385882},{"atb":[[9.6,0],[8.6,0],[11.5,0],[7.6,0]],"id":52385895},{"atb":[[9.6,0],[8.6,0],[11.5,0],[7.6,0]],"id":52385932}],"con":true,"img":false}]}
{"op":"mcm","clk":"11450100635","pt":1717318014546,"mc":[{"id":"1.229554922","rc":[{"atb":[[11,2.62],[7.4,16.35],[8.4,10.61],[9.4,6.23]],"id":52385889},{"atb":[[11,5.23],[13.5,2.09],[8.4,14.14],[9.4,9.34]],"id":52385890},{"atb":[[11,2.62],[7.4,16.35],[8.4,10.61],[9.4,6.23]],"id":52385882},{"atb":[[11,2.62],[7.4,16.35],[8.4,10.61],[9.4,6.23]],"id":52385895}],"con":true,"img":false}]}
{"op":"mcm","clk":"11450100660","pt":1717318014851,"mc":[{"id":"1.229554922","rc":[{"atb":[[11,2.62],[7.4,16.35],[8.4,10.61],[9.4,6.23]],"id":52385932}],"con":true,"img":false}]}
{"op":"mcm","clk":"11450100697","pt":1717318015389,"mc":[{"id":"1.229554922","rc":[{"atb":[[9.6,6.08],[8.6,10.33],[11.5,2.49],[7.6,15.85]],"id":52385888}],"con":true,"img":false}]}
{"op":"mcm","clk":"11450105868","pt":1717318070743,"mc":[{"id":"1.229554922","rc":[{"atb":[[150,0],[200,0],[100,0],[250,0]],"id":52385927},{"atb":[[40,0],[20,0],[25,0],[30,0]],"id":52385900},{"atb":[[17,15.24],[19.5,0],[24,4.54],[29,0]],"id":52385936}],"con":true,"img":false}]}
{"op":"mcm","clk":"11450105934","pt":1717318071424,"mc":[{"id":"1.229554922","rc":[{"atb":[[260,0.1],[160,0.49],[210,0.25],[110,0.96]],"id":52385927},{"atb":[[38,0.71],[19.5,5.66],[24,3.41],[29,1.87]],"id":52385900},{"atb":[[17.5,6.34],[20,4.13],[25,2.18],[30,0.9]],"id":52385936}],"con":true,"img":false}]}
{"op":"mcm","clk":"11450118696","pt":1717318214487,"mc":[{"id":"1.229554922","rc":[{"atb":[[140,0],[190,0],[95,0],[240,0]],"id":52385908},{"atb":[[32,0],[42,0],[26,0],[55,0]],"id":52385918},{"atb":[[260,0],[160,0],[210,0],[110,0]],"id":52385927},{"atb":[[40,0],[50,0],[25,0],[30,0]],"id":52385923},{"atb":[[38,0],[19.5,0],[24,0],[29,0]],"id":52385900},{"atb":[[75,0],[40,0],[50,0],[30,0]],"id":52385919},{"atb":[[38,0],[48,0],[24,0],[29,3.73]],"id":52385917},{"atb":[[36,0],[46,0],[23,4.75],[28,0]],"id":52385893}],"con":true,"img":false}]}
{"op":"mcm","clk":"11450118715","pt":1717318214696,"mc":[{"id":"1.229554922","rc":[{"atb":[[75,0],[40,0],[50,0],[30,0]],"id":52385924},{"atb":[[17.5,0],[20,0],[25,0],[30,0]],"id":52385936}],"con":true,"img":false}]}
{"op":"mcm","clk":"11450118763","pt":1717318215162,"mc":[{"id":"1.229554922","rc":[{"atb":[[260,0.1],[160,0.49],[210,0.25],[110,0.96]],"id":52385908},{"atb":[[34,2.38],[44,1.22],[27,4.02],[60,0.44]],"id":52385918},{"atb":[[270,0.1],[170,0.47],[220,0.24],[120,0.88]],"id":52385927},{"atb":[[34,2.38],[44,1.22],[27,4.02],[60,0.44]],"id":52385923},{"atb":[[32,5.06],[21,17.43],[42,0.64],[26,3.14]],"id":52385900},{"atb":[[34,3.17],[85,0.31],[44,1.83],[60,0.88]],"id":52385919},{"atb":[[40,1.34],[50,0.53],[25,4.36],[30,2.71]],"id":52385917},{"atb":[[36,1.5],[23,9.51],[46,0.58],[28,2.91]],"id":52385893}],"con":true,"img":false}]}
{"op":"mcm","clk":"11450118785","pt":1717318215375,"mc":[{"id":"1.229554922","rc":[{"atb":[[32,3.37],[80,0.33],[42,1.92],[55,0.97]],"id":52385924},{"atb":[[32,0.84],[18,6.15],[21,3.92],[26,2.09]],"id":52385936}],"con":true,"img":false}]}
{"op":"mcm","clk":"11450120884","pt":1717318238993,"mc":[{"id":"1.229554922","rc":[{"atb":[[260,0],[160,0],[210,0],[110,0]],"id":52385908},{"atb":[[34,0],[44,0],[27,0],[60,0]],"id":52385918},{"atb":[[270,0],[170,0],[220,0],[120,0]],"id":52385927},{"atb":[[34,0],[44,0],[27,0],[60,0]],"id":52385923},{"atb":[[32,3.37],[42,0],[21,12.19],[26,0]],"id":52385900},{"atb":[[34,0],[85,0],[44,0],[60,0]],"id":52385919},{"atb":[[40,0],[50,0],[25,0],[30,0]],"id":52385917},{"atb":[[32,0],[80,0],[42,0],[55,0]],"id":52385924},{"atb":[[32,0],[18,0],[21,0],[26,0]],"id":52385936}],"con":true,"img":false}]}
{"op":"mcm","clk":"11450120948","pt":1717318239720,"mc":[{"id":"1.229554922","rc":[{"atb":[[140,0.57],[190,0.28],[95,1.11],[240,0.11]],"id":52385908},{"atb":[[32,2.53],[42,1.28],[26,4.19],[55,0.49]],"id":52385918},{"atb":[[260,0.1],[160,0.49],[210,0.25],[110,0.96]],"id":52385927},{"atb":[[40,1.34],[50,0.53],[25,4.36],[30,2.71]],"id":52385923},{"atb":[[38,0.71],[19.5,5.66],[24,3.41],[29,1.87]],"id":52385900},{"atb":[[75,0.36],[40,2.01],[50,1.07],[30,3.61]],"id":52385919},{"atb":[[38,1.41],[48,0.55],[24,4.55],[29,6.54]],"id":52385917},{"atb":[[75,0.36],[40,2.01],[50,1.07],[30,3.61]],"id":52385924},{"atb":[[17.5,6.34],[20,4.13],[25,2.18],[30,0.9]],"id":52385936}],"con":true,"img":false}]}
{"op":"mcm","clk":"11450128162","pt":1717318324073,"mc":[{"id":"1.229554922","rc":[{"atb":[[75,0],[40,0]],"id":52385908},{"atb":[[19,0],[28,0]],"id":52385918},{"atb":[[10.5,0],[15.5,0]],"id":52385887},{"atb":[[610,0],[510,0]],"id":52385920},{"atb":[[4.3,0],[5.3,0]],"id":52385889},{"atb":[[5.3,0],[6.6,0]],"id":52385883},{"atb":[[10.5,0],[15.5,0]],"id":52385894},{"atb":[[75,0],[40,0]],"id":52385927},{"atb":[[5.5,0],[7,0]],"id":52385896},{"atb":[[550,0],[650,0]],"id":52385929},{"atb":[[5.1,0],[6.2,0]],"id":52385890},{"atb":[[19.5,0],[29,0]],"id":52385923},{"atb":[[17,0],[12,0]],"id":52385925},{"atb":[[5.5,0],[7,0]],"id":52385902},{"atb":[[9.8,0],[14.5,0]],"id":52385904},{"atb":[[10.5,0],[15.5,0]],"id":52385937},{"atb":[[10.5,0],[15.5,0]],"id":52385898},{"atb":[[4.4,0],[5.4,0]],"id":52385931},{"atb":[[32,0],[21,0]],"id":52385900},{"atb":[[5.3,0],[6.6,0]],"id":52385933},{"atb":[[570,0],[470,0]],"id":52385907},{"atb":[[10,0],[15,0]],"id":52385909},{"atb":[[17,0],[24,0]],"id":52385886},{"atb":[[42,0],[26,0]],"id":52385919},{"atb":[[4.4,0],[5.4,0]],"id":52385888},{"atb":[[4.3,0],[5.3,0]],"id":52385882},{"atb":[[13.5,0],[9.4,0]],"id":52385884},{"atb":[[19.5,0],[29,2.8]],"id":52385917},{"atb":[[19,0],[14,0]],"id":52385926},{"atb":[[4.3,0],[5.3,0]],"id":52385895},{"atb":[[5.3,0],[6.6,0]],"id":52385897},{"atb":[[550,0],[650,0]],"id":52385922},{"atb":[[9.2,0],[13,0]],"id":52385891},{"atb":[[17.5,0],[12.5,0]],"id":52385924},{"atb":[[16.5,0],[23,4.76]],"id":52385893},{"atb":[[13.5,0],[9.4,0]],"id":52385934},{"atb":[[10,0],[15,0]],"id":52385903},{"atb":[[17,0],[24,0]],"id":52385936},{"atb":[[17,0],[12,0]],"id":52385905},{"atb":[[17.5,0],[12.5,0]],"id":52385930},{"atb":[[4.3,0],[5.3,0]],"id":52385932},{"atb":[[18.5,0],[13.5,0]],"id":52385901}],"con":true,"img":false}]}
{"op":"mcm","clk":"11450129281","pt":1717318336161,"mc":[{"id":"1.229554922","rc":[{"atb":[[75,1.41],[40,6.25]],"id":52385908},{"atb":[[19,13.55],[28,3.87]],"id":52385918},{"atb":[[610,0.17],[510,0.48]],"id":52385920},{"atb":[[75,1.41],[40,6.25]],"id":52385927},{"atb":[[550,0.44],[650,0.16]],"id":52385929},{"atb":[[19.5,13.18],[29,3.73]],"id":52385923},{"atb":[[17,6.53],[12,22.17]],"id":52385925},{"atb":[[10.5,25.67],[15.5,7.2]],"id":52385937},{"atb":[[4.4,71.73],[5.4,23.75]],"id":52385931},{"atb":[[5.3,56.72],[6.6,18.66]],"id":52385933},{"atb":[[570,0.18],[470,0.51]],"id":52385907},{"atb":[[10,27.1],[15,7.46]],"id":52385909},{"atb":[[42,2.54],[26,9.75]],"id":52385919},{"atb":[[19.5,13.18],[29,6.54]],"id":52385917},{"atb":[[19,5.8],[14,18.76]],"id":52385926},{"atb":[[550,0.44],[650,0.16]],"id":52385922},{"atb":[[17.5,6.33],[12.5,21.2]],"id":52385924},{"atb":[[13.5,8.36],[9.4,29.03]],"id":52385934},{"atb":[[17,15.24],[24,4.54]],"id":52385936},{"atb":[[17.5,6.33],[12.5,21.2]],"id":52385930},{"atb":[[4.3,73.9],[5.3,24.31]],"id":52385932}],"con":true,"img":false}]}
{"op":"mcm","clk":"11450129288","pt":1717318336259,"mc":[{"id":"1.229554922","rc":[{"atb":[[10.5,25.67],[15.5,7.2]],"id":52385887},{"atb":[[4.3,73.9],[5.3,24.31]],"id":52385889},{"atb":[[5.3,56.72],[6.6,18.66]],"id":52385883},{"atb":[[10.5,25.67],[15.5,7.2]],"id":52385894},{"atb":[[5.5,54.2],[7,17.42]],"id":52385896},{"atb":[[5.1,59.49],[6.2,20.1]],"id":52385890},{"atb":[[5.5,54.2],[7,17.42]],"id":52385902},{"atb":[[9.8,27.71],[14.5,7.74]],"id":52385904},{"atb":[[10.5,25.67],[15.5,7.2]],"id":52385898},{"atb":[[32,3.37],[21,12.19]],"id":52385900},{"atb":[[17,15.24],[24,4.54]],"id":52385886},{"atb":[[4.4,71.73],[5.4,23.75]],"id":52385888},{"atb":[[4.3,73.9],[5.3,24.31]],"id":52385882},{"atb":[[13.5,8.36],[9.4,29.03]],"id":52385884},{"atb":[[4.3,73.9],[5.3,24.31]],"id":52385895},{"atb":[[5.3,56.72],[6.6,18.66]],"id":52385897},{"atb":[[9.2,29.74],[13,8.71]],"id":52385891},{"atb":[[16.5,15.73],[23,9.51]],"id":52385893},{"atb":[[10,27.1],[15,7.46]],"id":52385903},{"atb":[[17,6.53],[12,22.17]],"id":52385905},{"atb":[[18.5,5.97],[13.5,19.51]],"id":52385901}],"con":true,"img":false}]}
{"op":"mcm","clk":"11450137816","pt":1717318436672,"mc":[{"id":"1.229554922","rc":[{"atb":[[36,0],[46,0],[23,0],[28,0]],"id":52385894},{"atb":[[11,0],[13.5,0],[8.4,0],[9.4,0]],"id":52385890},{"atb":[[75,0],[40,0],[50,0],[30,0]],"id":52385925},{"atb":[[11,0],[7.4,0],[8.4,0],[9.4,0]],"id":52385882},{"atb":[[11,0],[7.4,0],[8.4,0],[9.4,0]],"id":52385895},{"atb":[[11,0],[7.4,0],[8.4,0],[9.4,0]],"id":52385932}],"con":true,"img":false}]}
{"op":"mcm","clk":"11450137901","pt":1717318437558,"mc":[{"id":"1.229554922","rc":[{"atb":[[38,1.41],[48,0.55],[24,4.55],[29,2.8]],"id":52385894},{"atb":[[9.6,9.12],[8.6,13.77],[11.5,4.98],[14,2.01]],"id":52385890},{"atb":[[32,3.37],[80,0.33],[42,1.92],[55,0.97]],"id":52385925},{"atb":[[9.6,6.08],[8.6,10.33],[11.5,2.49],[7.6,15.85]],"id":52385882},{"atb":[[9.6,6.08],[8.6,10.33],[11.5,2.49],[7.6,15.85]],"id":52385895},{"atb":[[9.6,6.08],[8.6,10.33],[11.5,2.49],[7.6,15.85]],"id":52385932}],"con":true,"img":false}]}
{"op":"mcm","clk":"11450138456","pt":1717318443286,"mc":[{"id":"1.229554922","rc":[{"atb":[[38,0],[48,0]],"id":52385894},{"atb":[[32,0],[80,0],[55,0]],"id":52385925}],"con":true,"img":false}]}
{"op":"mcm","clk":"11450138467","pt":1717318443395,"mc":[{"id":"1.229554922","rc":[{"atb":[[24,0],[29,0]],"id":52385894},{"atb":[[42,0]],"id":52385925}],"con":true,"img":false}]}
{"op":"mcm","clk":"11450138515","pt":1717318443960,"mc":[{"id":"1.229554922","rc":[{"atb":[[46,0.58]],"id":52385894},{"atb":[[75,0.36],[50,1.07],[30,3.61]],"id":52385925}],"con":true,"img":false}]}
{"op":"mcm","clk":"11450138529","pt":1717318444071,"mc":[{"id":"1.229554922","rc":[{"atb":[[36,1.5],[23,4.76],[28,2.91]],"id":52385894},{"atb":[[40,2.01]],"id":52385925}],"con":true,"img":false}]}
{"op":"mcm","clk":"11450208399","pt":1717319183137,"mc":[{"id":"1.229554922","rc":[{"atb":[[75,0],[40,0]],"id":52385908},{"atb":[[19,0],[28,0]],"id":52385918},{"atb":[[10.5,0],[15.5,0]],"id":52385887},{"atb":[[610,0],[510,0]],"id":52385920},{"atb":[[4.3,0],[5.3,0]],"id":52385889},{"atb":[[5.3,0],[6.6,0]],"id":52385883},{"atb":[[10.5,0],[15.5,0]],"id":52385894},{"atb":[[5.5,0],[7,0]],"id":52385896},{"atb":[[5.1,0],[6.2,0]],"id":52385890},{"atb":[[19.5,0],[29,0]],"id":52385923},{"atb":[[5.5,0],[7,0]],"id":52385902},{"atb":[[9.8,0],[14.5,0]],"id":52385904},{"atb":[[10.5,0],[15.5,0]],"id":52385898},{"atb":[[32,0],[21,0]],"id":52385900},{"atb":[[570,0],[470,0]],"id":52385907},{"atb":[[10,0],[15,0]],"id":52385909},{"atb":[[17,0],[24,0]],"id":52385886},{"atb":[[42,0],[26,0]],"id":52385919},{"atb":[[4.4,0],[5.4,0]],"id":52385888},{"atb":[[4.3,0],[5.3,0]],"id":52385882},{"atb":[[13.5,0],[9.4,0]],"id":52385884},{"atb":[[19.5,0],[29,2.8]],"id":52385917},{"atb":[[4.3,0],[5.3,0]],"id":52385895},{"atb":[[5.3,0],[6.6,0]],"id":52385897},{"atb":[[550,0],[650,0]],"id":52385922},{"atb":[[9.2,0],[13,0]],"id":52385891},{"atb":[[16.5,0],[23,4.76]],"id":52385893},{"atb":[[10,0],[15,0]],"id":52385903},{"atb":[[17,0],[12,0]],"id":52385905},{"atb":[[18.5,0],[13.5,0]],"id":52385901}],"con":true,"img":false}]}
{"op":"mcm","clk":"11450208408","pt":1717319183232,"mc":[{"id":"1.229554922","rc":[{"atb":[[75,0],[40,0]],"id":52385927},{"atb":[[550,0],[650,0]],"id":52385929},{"atb":[[17,0],[12,0]],"id":52385925},{"atb":[[10.5,0],[15.5,0]],"id":52385937},{"atb":[[4.4,0],[5.4,0]],"id":52385931},{"atb":[[5.3,0],[6.6,0]],"id":52385933},{"atb":[[19,0],[14,0]],"id":52385926},{"atb":[[17.5,0],[12.5,0]],"id":52385924},{"atb":[[13.5,0],[9.4,0]],"id":52385934},{"atb":[[17,0],[24,0]],"id":52385936},{"atb":[[17.5,0],[12.5,0]],"id":52385930},{"atb":[[4.3,0],[5.3,0]],"id":52385932}],"con":true,"img":false}]}
{"op":"mcm","clk":"11450211546","pt":1717319214150,"mc":[{"id":"1.229554922","rc":[{"atb":[[75,1.41],[40,6.25]],"id":52385908},{"atb":[[19,13.55],[28,3.87]],"id":52385918},{"atb":[[10.5,25.67],[15.5,7.2]],"id":52385887},{"atb":[[610,0.17],[510,0.48]],"id":52385920},{"atb":[[4.3,73.9],[5.3,24.31]],"id":52385889},{"atb":[[5.3,56.72],[6.6,18.66]],"id":52385883},{"atb":[[10.5,25.67],[15.5,7.2]],"id":52385894},{"atb":[[75,1.41],[40,6.25]],"id":52385927},{"atb":[[5.5,54.2],[7,17.42]],"id":52385896},{"atb":[[550,0.44],[650,0.16]],"id":52385929},{"atb":[[5.1,59.49],[6.2,20.1]],"id":52385890},{"atb":[[19.5,13.18],[29,3.73]],"id":52385923},{"atb":[[17,6.53],[12,22.17]],"id":52385925},{"atb":[[5.5,54.2],[7,17.42]],"id":52385902},{"atb":[[9.8,27.71],[14.5,7.74]],"id":52385904},{"atb":[[10.5,25.67],[15.5,7.2]],"id":52385937},{"atb":[[10.5,25.67],[15.5,7.2]],"id":52385898},{"atb":[[4.4,71.73],[5.4,23.75]],"id":52385931},{"atb":[[32,3.37],[21,12.19]],"id":52385900},{"atb":[[5.3,56.72],[6.6,18.66]],"id":52385933},{"atb":[[570,0.18],[470,0.51]],"id":52385907},{"atb":[[10,27.1],[15,7.46]],"id":52385909},{"atb":[[17,15.24],[24,4.54]],"id":52385886},{"atb":[[42,2.54],[26,9.75]],"id":52385919},{"atb":[[4.4,71.73],[5.4,23.75]],"id":52385888},{"atb":[[4.3,73.9],[5.3,24.31]],"id":52385882},{"atb":[[13.5,8.36],[9.4,29.03]],"id":52385884},{"atb":[[19.5,13.18],[29,6.54]],"id":52385917},{"atb":[[19,5.8],[14,18.76]],"id":52385926},{"atb":[[4.3,73.9],[5.3,24.31]],"id":52385895},{"atb":[[5.3,56.72],[6.6,18.66]],"id":52385897},{"atb":[[550,0.44],[650,0.16]],"id":52385922},{"atb":[[9.2,29.74],[13,8.71]],"id":52385891},{"atb":[[17.5,6.33],[12.5,21.2]],"id":52385924},{"atb":[[16.5,15.73],[23,9.51]],"id":52385893},{"atb":[[13.5,8.36],[9.4,29.03]],"id":52385934},{"atb":[[10,27.1],[15,7.46]],"id":52385903},{"atb":[[17,15.24],[24,4.54]],"id":52385936},{"atb":[[17,6.53],[12,22.17]],"id":52385905},{"atb":[[17.5,6.33],[12.5,21.2]],"id":52385930},{"atb":[[4.3,73.9],[5.3,24.31]],"id":52385932},{"atb":[[18.5,5.97],[13.5,19.51]],"id":52385901}],"con":true,"img":false}]}
{"op":"mcm","clk":"11450244062","pt":1717319556948,"mc":[{"id":"1.229554922","rc":[{"atb":[[38,0],[19.5,0],[24,0],[29,0]],"id":52385900},{"atb":[[36,0],[46,0],[23,0],[28,0]],"id":52385886}],"con":true,"img":false}]}
{"op":"mcm","clk":"11450244132","pt":1717319557770,"mc":[{"id":"1.229554922","rc":[{"atb":[[40,0.67],[20,5.51],[25,3.27],[30,1.81]],"id":52385900},{"atb":[[38,1.41],[24,9.1],[48,0.55],[29,2.8]],"id":52385886}],"con":true,"img":false}]}
{"op":"mcm","clk":"11450252173","pt":1717319648389,"mc":[{"id":"1.229554922","rc":[{"atb":[[40,0],[20,0],[25,0],[30,0]],"id":52385900},{"atb":[[38,0],[48,0],[24,4.54],[29,0]],"id":52385886},{"atb":[[36,0],[46,0],[23,4.75],[28,0]],"id":52385893}],"con":true,"img":false}]}
{"op":"mcm","clk":"11450252240","pt":1717319649101,"mc":[{"id":"1.229554922","rc":[{"atb":[[40,0.67],[20,5.51],[25,3.27],[30,1.81]],"id":52385900},{"atb":[[38,1.41],[24,9.1],[48,0.55],[29,2.8]],"id":52385886},{"atb":[[36,1.5],[23,9.51],[46,0.58],[28,2.91]],"id":52385893}],"con":true,"img":false}]}
{"op":"mcm","clk":"11450271304","pt":1717319866495,"mc":[{"id":"1.229554922","rc":[{"atb":[[140,0],[190,0],[95,0],[240,0]],"id":52385908},{"atb":[[260,0],[160,0],[210,0],[110,0]],"id":52385927},{"atb":[[9.6,0],[8.6,0],[11.5,0],[7.6,0]],"id":52385931},{"atb":[[9.6,0],[8.6,0],[11.5,0],[7.6,0]],"id":52385888},{"atb":[[32,0],[80,0],[42,0],[55,0]],"id":52385930},{"atb":[[9.6,0],[8.6,0],[11.5,0],[7.6,0]],"id":52385932}],"con":true,"img":false}]}
{"op":"mcm","clk":"11450271387","pt":1717319867274,"mc":[{"id":"1.229554922","rc":[{"atb":[[170,0.31],[85,1.25],[220,0.12],[120,0.66]],"id":52385908},{"atb":[[130,0.61],[180,0.29],[90,1.18],[230,0.12]],"id":52385927},{"atb":[[12,2.38],[9.8,5.94],[8.8,10.06],[7.8,15.39]],"id":52385931},{"atb":[[12,2.38],[9.8,5.94],[8.8,10.06],[7.8,15.39]],"id":52385888},{"atb":[[75,0.36],[40,2.01],[50,1.07],[30,3.61]],"id":52385930},{"atb":[[12,2.38],[9.8,5.94],[8.8,10.06],[7.8,15.39]],"id":52385932}],"con":true,"img":false}]}
{"op":"mcm","clk":"11450273093","pt":1717319888960,"mc":[{"id":"1.229554922","rc":[{"atb":[[40,0],[20,0],[25,0],[30,0]],"id":52385900},{"atb":[[36,0],[46,0],[23,4.75],[28,0]],"id":52385893}],"con":true,"img":false}]}
{"op":"mcm","clk":"11450273145","pt":1717319889589,"mc":[{"id":"1.229554922","rc":[{"atb":[[34,1.59],[44,0.61],[22,4.98],[27,3.02]],"id":52385900},{"atb":[[38,1.41],[48,0.55],[24,4.55],[29,2.8]],"id":52385893}],"con":true,"img":false}]}
{"op":"mcm","clk":"11450274566","pt":1717319908087,"mc":[{"id":"1.229554922","rc":[{"atb":[[36,0],[46,0],[23,0],[28,0]],"id":52385894},{"atb":[[12,0],[9.8,0],[8.8,0],[14.5,0]],"id":52385933}],"con":true,"img":false}]}
{"op":"mcm","clk":"11450274615","pt":1717319908792,"mc":[{"id":"1.229554922","rc":[{"atb":[[34,1.59],[44,0.61],[22,4.98],[27,3.02]],"id":52385894},{"atb":[[9,13.08],[10,8.72],[12.5,4.55],[15,1.87]],"id":52385933}],"con":true,"img":false}]}
{"op":"mcm","clk":"11450275817","pt":1717319924278,"mc":[{"id":"1.229554922","rc":[{"atb":[[34,0],[44,0],[22,0],[27,0]],"id":52385894}],"con":true,"img":false}]}
{"op":"mcm","clk":"11450275875","pt":1717319924996,"mc":[{"id":"1.229554922","rc":[{"atb":[[32,1.69],[42,0.64],[21,5.23],[26,3.14]],"id":52385894}],"con":true,"img":false}]}
{"op":"mcm","clk":"11450277222","pt":1717319942195,"mc":[{"id":"1.229554922","rc":[{"atb":[[32,0],[42,0],[21,0],[26,0]],"id":52385894}],"con":true,"img":false}]}
{"op":"mcm","clk":"11450277296","pt":1717319942916,"mc":[{"id":"1.229554922","rc":[{"atb":[[40,0.67],[20,5.51],[25,3.27],[30,1.81]],"id":52385894}],"con":true,"img":false}]}
{"op":"mcm","clk":"11450277340","pt":1717319943633,"mc":[{"id":"1.229554922","rc":[{"atb":[[12,0],[9.8,0],[8.8,0],[7.8,0]],"id":52385931}],"con":true,"img":false}]}
{"op":"mcm","clk":"11450277387","pt":1717319944312,"mc":[{"id":"1.229554922","rc":[{"atb":[[9.6,6.08],[8.6,10.33],[11.5,2.49],[7.6,15.85]],"id":52385931}],"con":true,"img":false}]}
{"op":"mcm","clk":"11450277650","pt":1717319946943,"mc":[{"id":"1.229554922","rc":[{"atb":[[34,0],[44,0],[27,0],[60,0]],"id":52385909},{"atb":[[40,0],[20,0],[25,0],[30,0]],"id":52385884},{"atb":[[34,0],[44,0],[27,0],[60,0]],"id":52385903},{"atb":[[75,0],[40,0],[50,0],[30,0]],"id":52385905}],"con":true,"img":false}]}
{"op":"mcm","clk":"11450277707","pt":1717319947620,"mc":[{"id":"1.229554922","rc":[{"atb":[[65,0.41],[36,2.24],[46,1.16],[28,3.88]],"id":52385909},{"atb":[[32,1.69],[42,0.64],[21,5.23],[26,3.14]],"id":52385884},{"atb":[[65,0.41],[36,2.24],[46,1.16],[28,3.88]],"id":52385903},{"atb":[[34,3.17],[85,0.31],[44,1.83],[60,0.88]],"id":52385905}],"con":true,"img":false}]}
{"op":"mcm","clk":"11450279072","pt":1717319965053,"mc":[{"id":"1.229554922","rc":[{"atb":[[75,0],[40,0]],"id":52385908},{"atb":[[19,0],[28,0]],"id":52385918},{"atb":[[10.5,0],[15.5,0]],"id":52385887},{"atb":[[610,0],[510,0]],"id":52385920},{"atb":[[4.3,0],[5.3,0]],"id":52385889},{"atb":[[5.3,0],[6.6,0]],"id":52385883},{"atb":[[10.5,0],[15.5,0]],"id":52385894},{"atb":[[5.5,0],[7,0]],"id":52385896},{"atb":[[5.1,0],[6.2,0]],"id":52385890},{"atb":[[19.5,0],[29,0]],"id":52385923},{"atb":[[5.5,0],[7,0]],"id":52385902},{"atb":[[9.8,0],[14.5,0]],"id":52385904},{"atb":[[10.5,0],[15.5,0]],"id":52385898},{"atb":[[32,0],[21,0]],"id":52385900},{"atb":[[570,0],[470,0]],"id":52385907},{"atb":[[10,0],[15,0]],"id":52385909},{"atb":[[17,0],[24,4.55]],"id":52385886},{"atb":[[42,0],[26,0]],"id":52385919},{"atb":[[4.4,0],[5.4,0]],"id":52385888},{"atb":[[4.3,0],[5.3,0]],"id":52385882},{"atb":[[13.5,0],[9.4,0]],"id":52385884},{"atb":[[19.5,0],[29,2.8]],"id":52385917},{"atb":[[4.3,0],[5.3,0]],"id":52385895},{"atb":[[5.3,0],[6.6,0]],"id":52385897},{"atb":[[550,0],[650,0]],"id":52385922},{"atb":[[9.2,0],[13,0]],"id":52385891},{"atb":[[16.5,0],[23,0]],"id":52385893},{"atb":[[10,0],[15,0]],"id":52385903},{"atb":[[17,0],[12,0]],"id":52385905},{"atb":[[18.5,0],[13.5,0]],"id":52385901}],"con":true,"img":false}]}
{"op":"mcm","clk":"11450279077","pt":1717319965151,"mc":[{"id":"1.229554922","rc":[{"atb":[[75,0],[40,0]],"id":52385927},{"atb":[[550,0],[650,0]],"id":52385929},{"atb":[[17,0],[12,0]],"id":52385925},{"atb":[[10.5,0],[15.5,0]],"id":52385937},{"atb":[[4.4,0],[5.4,0]],"id":52385931},{"atb":[[5.3,0],[6.6,0]],"id":52385933},{"atb":[[19,0],[14,0]],"id":52385926},{"atb":[[17.5,0],[12.5,0]],"id":52385924},{"atb":[[13.5,0],[9.4,0]],"id":52385934},{"atb":[[17,0],[24,0]],"id":52385936},{"atb":[[17.5,0],[12.5,0]],"id":52385930},{"atb":[[4.3,0],[5.3,0]],"id":52385932}],"con":true,"img":false}]}
{"op":"mcm","clk":"11450279455","pt":1717319969648,"mc":[{"id":"1.229554922","rc":[{"atb":[[32,0],[42,0],[21,0],[26,0]],"id":52385884}],"con":true,"img":false}]}
{"op":"mcm","clk":"11450279461","pt":1717319969750,"mc":[{"id":"1.229554922","rc":[{"atb":[[34,0],[44,0],[22,0],[27,0]],"id":52385900},{"atb":[[38,0],[48,0],[24,0],[29,0]],"id":52385886},{"atb":[[38,0],[48,0],[24,0],[29,0]],"id":52385893},{"atb":[[12,0],[9.8,0],[8.8,0],[7.8,0]],"id":52385932}],"con":true,"img":false}]}
{"op":"mcm","clk":"11450279517","pt":1717319970364,"mc":[{"id":"1.229554922","rc":[{"atb":[[34,1.59],[44,0.61],[22,4.98],[27,3.02]],"id":52385884}],"con":true,"img":false}]}
{"op":"mcm","clk":"11450279526","pt":1717319970466,"mc":[{"id":"1.229554922","rc":[{"atb":[[34,1.59],[44,0.61],[22,4.98],[27,3.02]],"id":52385900},{"atb":[[38,1.41],[48,0.55],[24,4.55],[29,2.8]],"id":52385886},{"atb":[[32,1.69],[42,0.64],[21,5.23],[26,3.14]],"id":52385893},{"atb":[[6.8,18.04],[9.8,2.97],[8.8,6.71],[7.8,11.54]],"id":52385932}],"con":true,"img":false}]}
{"op":"mcm","clk":"11450280036","pt":1717319977282,"mc":[{"id":"1.229554922","rc":[{"atb":[[110,0.95],[55,4.51]],"id":52385908},{"atb":[[18.5,13.93],[27,4.01]],"id":52385918},{"atb":[[16.5,6.74],[11.5,23.22]],"id":52385887},{"atb":[[550,0.44],[650,0.16]],"id":52385920},{"atb":[[5.1,25.49],[4.1,78.68]],"id":52385889},{"atb":[[6.8,18.02],[5.4,55.43]],"id":52385883},{"atb":[[10,27.1],[15,7.46]],"id":52385894},{"atb":[[120,0.87],[60,4.13]],"id":52385927},{"atb":[[5.6,53.02],[7.2,16.86]],"id":52385896},{"atb":[[550,0.44],[650,0.16]],"id":52385929},{"atb":[[4.9,62.54],[5.9,21.33]],"id":52385890},{"atb":[[20,12.83],[30,6.31]],"id":52385923},{"atb":[[17.5,6.33],[12.5,21.2]],"id":52385925},{"atb":[[5.6,53.02],[7.2,16.86]],"id":52385902},{"atb":[[9.8,27.71],[14.5,7.74]],"id":52385904},{"atb":[[16.5,6.74],[11.5,23.22]],"id":52385937},{"atb":[[16.5,6.74],[11.5,23.22]],"id":52385898},{"atb":[[4.5,69.68],[5.5,23.22]],"id":52385931},{"atb":[[34,4.75],[22,16.6]],"id":52385900},{"atb":[[6.8,18.02],[5.4,55.43]],"id":52385933},{"atb":[[550,0.44],[650,0.16]],"id":52385907},{"atb":[[10.5,25.67],[15.5,7.2]],"id":52385909},{"atb":[[17.5,14.77],[25,4.35]],"id":52385886},{"atb":[[44,2.43],[27,9.38]],"id":52385919},{"atb":[[4.5,69.68],[5.5,23.22]],"id":52385888},{"atb":[[5.2,24.88],[4.2,76.22]],"id":52385882},{"atb":[[9.6,28.36],[14,8.04]],"id":52385884},{"atb":[[20,12.83],[30,3.6]],"id":52385917},{"atb":[[19.5,11.31],[14.5,18.06]],"id":52385926},{"atb":[[5.1,25.49],[4.1,78.68]],"id":52385895},{"atb":[[6.4,19.35],[5.2,58.07]],"id":52385897},{"atb":[[550,0.44],[650,0.16]],"id":52385922},{"atb":[[13.5,8.36],[9.4,29.03]],"id":52385891},{"atb":[[18,6.14],[13,20.32]],"id":52385924},{"atb":[[16,16.26],[22,4.97]],"id":52385893},{"atb":[[9.6,28.36],[14,8.04]],"id":52385934},{"atb":[[10.5,25.67],[15.5,7.2]],"id":52385903},{"atb":[[17.5,21.12],[25,6.53]],"id":52385936},{"atb":[[18,6.14],[13,20.32]],"id":52385905},{"atb":[[18,6.14],[13,20.32]],"id":52385930},{"atb":[[5.2,24.88],[4.2,76.22]],"id":52385932},{"atb":[[18.5,5.97],[13.5,19.51]],"id":52385901}],"con":true,"img":false}]}
{"op":"mcm","clk":"11450282296","pt":1717320005126,"mc":[{"id":"1.229554922","rc":[{"atb":[[110,0],[55,0]],"id":52385908},{"atb":[[18.5,0],[27,0]],"id":52385918},{"atb":[[16.5,0],[11.5,0]],"id":52385887},{"atb":[[550,0],[650,0]],"id":52385920},{"atb":[[5.1,0],[4.1,0]],"id":52385889},{"atb":[[6.8,0],[5.4,0]],"id":52385883},{"atb":[[10,0],[15,0]],"id":52385894},{"atb":[[120,0],[60,0]],"id":52385927},{"atb":[[5.6,0],[7.2,0]],"id":52385896},{"atb":[[550,0],[650,0]],"id":52385929},{"atb":[[4.9,0],[5.9,0]],"id":52385890},{"atb":[[20,0],[30,2.71]],"id":52385923},{"atb":[[17.5,0],[12.5,0]],"id":52385925},{"atb":[[5.6,0],[7.2,0]],"id":52385902},{"atb":[[9.8,0],[14.5,0]],"id":52385904},{"atb":[[16.5,0],[11.5,0]],"id":52385937},{"atb":[[16.5,0],[11.5,0]],"id":52385898},{"atb":[[4.5,0],[5.5,0]],"id":52385931},{"atb":[[34,1.59],[22,4.98]],"id":52385900},{"atb":[[6.8,0],[5.4,0]],"id":52385933},{"atb":[[550,0],[650,0]],"id":52385907},{"atb":[[10.5,0],[15.5,0]],"id":52385909},{"atb":[[17.5,0],[25,0]],"id":52385886},{"atb":[[44,0],[27,0]],"id":52385919},{"atb":[[4.5,0],[5.5,0]],"id":52385888},{"atb":[[5.2,0],[4.2,0]],"id":52385882},{"atb":[[9.6,0],[14,0]],"id":52385884},{"atb":[[20,0],[30,0]],"id":52385917},{"atb":[[19.5,5.66],[14.5,0]],"id":52385926},{"atb":[[5.1,0],[4.1,0]],"id":52385895},{"atb":[[6.4,0],[5.2,0]],"id":52385897},{"atb":[[550,0],[650,0]],"id":52385922},{"atb":[[13.5,0],[9.4,0]],"id":52385891},{"atb":[[18,0],[13,0]],"id":52385924},{"atb":[[16,0],[22,0]],"id":52385893},{"atb":[[9.6,0],[14,0]],"id":52385934},{"atb":[[10.5,0],[15.5,0]],"id":52385903},{"atb":[[17.5,6.34],[25,2.18]],"id":52385936},{"atb":[[18,0],[13,0]],"id":52385905},{"atb":[[18,0],[13,0]],"id":52385930},{"atb":[[5.2,0],[4.2,0]],"id":52385932},{"atb":[[18.5,0],[13.5,0]],"id":52385901}],"con":true,"img":false}]}
{"op":"mcm","clk":"11450283145","pt":1717320015532,"mc":[{"id":"1.229554922","rc":[{"atb":[[180,0.58],[90,2.74]],"id":52385908},{"atb":[[18,14.34],[26,8.37]],"id":52385918},{"atb":[[17,6.53],[12,22.17]],"id":52385887},{"atb":[[550,0.44],[650,0.16]],"id":52385920},{"atb":[[4,81.3],[5,26.13]],"id":52385889},{"atb":[[5.5,54.2],[7,17.42]],"id":52385883},{"atb":[[10,27.1],[15,7.46]],"id":52385894},{"atb":[[190,0.55],[95,2.59]],"id":52385927},{"atb":[[7.4,16.33],[5.7,51.89]],"id":52385896},{"atb":[[550,0.44],[650,0.16]],"id":52385929},{"atb":[[5.6,22.72],[4.6,67.75]],"id":52385890},{"atb":[[20,12.83],[30,6.31]],"id":52385923},{"atb":[[17.5,6.33],[12.5,21.2]],"id":52385925},{"atb":[[5.6,53.02],[7.2,16.86]],"id":52385902},{"atb":[[10,27.1],[15,7.46]],"id":52385904},{"atb":[[17,6.53],[12,22.17]],"id":52385937},{"atb":[[17.5,6.33],[12.5,21.2]],"id":52385898},{"atb":[[5.6,22.72],[4.6,67.75]],"id":52385931},{"atb":[[34,4.75],[22,16.6]],"id":52385900},{"atb":[[6.8,18.02],[5.4,55.43]],"id":52385933},{"atb":[[550,0.44],[650,0.16]],"id":52385907},{"atb":[[16.5,6.74],[11.5,23.22]],"id":52385909},{"atb":[[17.5,14.77],[25,4.35]],"id":52385886},{"atb":[[44,2.43],[27,9.38]],"id":52385919},{"atb":[[5.6,22.72],[4.6,67.75]],"id":52385888},{"atb":[[5.1,25.49],[4.1,78.68]],"id":52385882},{"atb":[[10,27.1],[15,7.46]],"id":52385884},{"atb":[[32,3.37],[21,12.19]],"id":52385917},{"atb":[[20,5.5],[15,17.42]],"id":52385926},{"atb":[[3.95,82.67],[4.9,26.8]],"id":52385895},{"atb":[[5,60.97],[6,20.9]],"id":52385897},{"atb":[[550,0.44],[650,0.16]],"id":52385922},{"atb":[[9.2,29.74],[13,8.71]],"id":52385891},{"atb":[[18.5,5.97],[13.5,19.51]],"id":52385924},{"atb":[[21,10.46],[15.5,16.82]],"id":52385893},{"atb":[[9.8,27.71],[14.5,7.74]],"id":52385934},{"atb":[[16.5,6.74],[11.5,23.22]],"id":52385903},{"atb":[[17.5,21.12],[25,6.53]],"id":52385936},{"atb":[[18.5,5.97],[13.5,19.51]],"id":52385905},{"atb":[[18.5,5.97],[13.5,19.51]],"id":52385930},{"atb":[[5.1,25.49],[4.1,78.68]],"id":52385932},{"atb":[[19,7.26],[14,24.8]],"id":52385901}],"con":true,"img":false}]}
{"op":"mcm","clk":"11450284717","pt":1717320037324,"mc":[{"id":"1.229554922","rc":[{"atb":[[180,0],[90,0]],"id":52385908},{"atb":[[18,0],[26,4.19]],"id":52385918},{"atb":[[17,0],[12,0]],"id":52385887},{"atb":[[550,0],[650,0]],"id":52385920},{"atb":[[4,0],[5,0]],"id":52385889},{"atb":[[5.5,0],[7,0]],"id":52385883},{"atb":[[10,0],[15,0]],"id":52385894},{"atb":[[7.4,0],[5.7,0]],"id":52385896},{"atb":[[5.6,0],[4.6,0]],"id":52385890},{"atb":[[20,0],[30,2.71]],"id":52385923},{"atb":[[5.6,0],[7.2,0]],"id":52385902},{"atb":[[10,0],[15,0]],"id":52385904},{"atb":[[17.5,0],[12.5,0]],"id":52385898},{"atb":[[34,1.59],[22,4.98]],"id":52385900},{"atb":[[550,0],[650,0]],"id":52385907},{"atb":[[16.5,0],[11.5,0]],"id":52385909},{"atb":[[17.5,0],[25,0]],"id":52385886},{"atb":[[44,0],[27,0]],"id":52385919},{"atb":[[5.6,0],[4.6,0]],"id":52385888},{"atb":[[5.1,0],[4.1,0]],"id":52385882},{"atb":[[10,0],[15,0]],"id":52385884},{"atb":[[32,0],[21,0]],"id":52385917},{"atb":[[3.95,0],[4.9,0]],"id":52385895},{"atb":[[5,0],[6,0]],"id":52385897},{"atb":[[550,0],[650,0]],"id":52385922},{"atb":[[9.2,0],[13,0]],"id":52385891},{"atb":[[21,5.23],[15.5,0]],"id":52385893},{"atb":[[16.5,0],[11.5,0]],"id":52385903},{"atb":[[18.5,0],[13.5,0]],"id":52385905},{"atb":[[19,1.45],[14,6.04]],"id":52385901}],"con":true,"img":false}]}
{"op":"mcm","clk":"11450284723","pt":1717320037424,"mc":[{"id":"1.229554922","rc":[{"atb":[[190,0],[95,0]],"id":52385927},{"atb":[[550,0],[650,0]],"id":52385929},{"atb":[[17.5,0],[12.5,0]],"id":52385925},{"atb":[[17,0],[12,0]],"id":52385937},{"atb":[[5.6,0],[4.6,0]],"id":52385931},{"atb":[[6.8,0],[5.4,0]],"id":52385933},{"atb":[[20,0],[15,0]],"id":52385926},{"atb":[[18.5,0],[13.5,0]],"id":52385924},{"atb":[[9.8,0],[14.5,0]],"id":52385934},{"atb":[[17.5,6.34],[25,2.18]],"id":52385936},{"atb":[[18.5,0],[13.5,0]],"id":52385930},{"atb":[[5.1,0],[4.1,0]],"id":52385932}],"con":true,"img":false}]}
{"op":"mcm","clk":"11450285301","pt":1717320046061,"mc":[{"id":"1.229554922","rc":[{"atb":[[180,0.58],[90,2.74]],"id":52385908},{"atb":[[18,14.34],[26,8.37]],"id":52385918},{"atb":[[17,6.53],[12,22.17]],"id":52385887},{"atb":[[550,0.44],[650,0.16]],"id":52385920},{"atb":[[4,81.3],[5,26.13]],"id":52385889},{"atb":[[5.5,54.2],[7,17.42]],"id":52385883},{"atb":[[10,27.1],[15,7.46]],"id":52385894},{"atb":[[190,0.55],[95,2.59]],"id":52385927},{"atb":[[7.4,16.33],[5.7,51.89]],"id":52385896},{"atb":[[550,0.44],[650,0.16]],"id":52385929},{"atb":[[5.6,22.72],[4.6,67.75]],"id":52385890},{"atb":[[20,12.83],[30,6.31]],"id":52385923},{"atb":[[17.5,6.33],[12.5,21.2]],"id":52385925},{"atb":[[5.6,53.02],[7.2,16.86]],"id":52385902},{"atb":[[10,27.1],[15,7.46]],"id":52385904},{"atb":[[17,6.53],[12,22.17]],"id":52385937},{"atb":[[17.5,6.33],[12.5,21.2]],"id":52385898},{"atb":[[5.6,22.72],[4.6,67.75]],"id":52385931},{"atb":[[34,4.75],[22,16.6]],"id":52385900},{"atb":[[6.8,18.02],[5.4,55.43]],"id":52385933},{"atb":[[550,0.44],[650,0.16]],"id":52385907},{"atb":[[16.5,6.74],[11.5,23.22]],"id":52385909},{"atb":[[17.5,14.77],[25,4.35]],"id":52385886},{"atb":[[44,2.43],[27,9.38]],"id":52385919},{"atb":[[5.6,22.72],[4.6,67.75]],"id":52385888},{"atb":[[5.1,25.49],[4.1,78.68]],"id":52385882},{"atb":[[10,27.1],[15,7.46]],"id":52385884},{"atb":[[32,3.37],[21,12.19]],"id":52385917},{"atb":[[20,5.5],[15,17.42]],"id":52385926},{"atb":[[3.95,82.67],[4.9,26.8]],"id":52385895},{"atb":[[5,60.97],[6,20.9]],"id":52385897},{"atb":[[550,0.44],[650,0.16]],"id":52385922},{"atb":[[9.2,29.74],[13,8.71]],"id":52385891},{"atb":[[18.5,5.97],[13.5,19.51]],"id":52385924},{"atb":[[21,10.46],[15.5,16.82]],"id":52385893},{"atb":[[9.8,27.71],[14.5,7.74]],"id":52385934},{"atb":[[16.5,6.74],[11.5,23.22]],"id":52385903},{"atb":[[17.5,21.12],[25,6.53]],"id":52385936},{"atb":[[18.5,5.97],[13.5,19.51]],"id":52385905},{"atb":[[18.5,5.97],[13.5,19.51]],"id":52385930},{"atb":[[5.1,25.49],[4.1,78.68]],"id":52385932},{"atb":[[19,7.26],[14,24.8]],"id":52385901}],"con":true,"img":false}]}
{"op":"mcm","clk":"11450286920","pt":1717320072613,"mc":[{"id":"1.229554922","rc":[{"atb":[[180,0],[90,0]],"id":52385908},{"atb":[[18,0],[26,4.19]],"id":52385918},{"atb":[[17,0],[12,0]],"id":52385887},{"atb":[[550,0],[650,0]],"id":52385920},{"atb":[[4,0],[5,0]],"id":52385889},{"atb":[[5.5,0],[7,0]],"id":52385883},{"atb":[[10,0],[15,0]],"id":52385894},{"atb":[[7.4,0],[5.7,0]],"id":52385896},{"atb":[[5.6,0],[4.6,0]],"id":52385890},{"atb":[[20,0],[30,2.71]],"id":52385923},{"atb":[[5.6,0],[7.2,0]],"id":52385902},{"atb":[[10,0],[15,0]],"id":52385904},{"atb":[[17.5,0],[12.5,0]],"id":52385898},{"atb":[[34,1.59],[22,4.98]],"id":52385900},{"atb":[[550,0],[650,0]],"id":52385907},{"atb":[[16.5,0],[11.5,0]],"id":52385909},{"atb":[[17.5,0],[25,0]],"id":52385886},{"atb":[[44,0],[27,0]],"id":52385919},{"atb":[[5.6,0],[4.6,0]],"id":52385888},{"atb":[[5.1,0],[4.1,0]],"id":52385882},{"atb":[[10,0],[15,0]],"id":52385884},{"atb":[[32,0],[21,0]],"id":52385917},{"atb":[[3.95,0],[4.9,0]],"id":52385895},{"atb":[[5,0],[6,0]],"id":52385897},{"atb":[[550,0],[650,0]],"id":52385922},{"atb":[[9.2,0],[13,0]],"id":52385891},{"atb":[[21,5.23],[15.5,0]],"id":52385893},{"atb":[[16.5,0],[11.5,0]],"id":52385903},{"atb":[[18.5,0],[13.5,0]],"id":52385905},{"atb":[[19,1.45],[14,6.04]],"id":52385901}],"con":true,"img":false}]}
{"op":"mcm","clk":"11450286924","pt":1717320072668,"mc":[{"id":"1.229554922","rc":[{"atb":[[190,0],[95,0]],"id":52385927},{"atb":[[550,0],[650,0]],"id":52385929},{"atb":[[17.5,0],[12.5,0]],"id":52385925},{"atb":[[17,0],[12,0]],"id":52385937},{"atb":[[5.6,0],[4.6,0]],"id":52385931},{"atb":[[6.8,0],[5.4,0]],"id":52385933},{"atb":[[20,0],[15,0]],"id":52385926},{"atb":[[18.5,0],[13.5,0]],"id":52385924},{"atb":[[9.8,0],[14.5,0]],"id":52385934},{"atb":[[17.5,6.34],[25,2.18]],"id":52385936},{"atb":[[18.5,0],[13.5,0]],"id":52385930},{"atb":[[5.1,0],[4.1,0]],"id":52385932}],"con":true,"img":false}]}
{"op":"mcm","clk":"11450287958","pt":1717320087503,"mc":[{"id":"1.229554922","rc":[{"atb":[[170,0.93],[85,4.15]],"id":52385908},{"atb":[[18,14.34],[26,8.37]],"id":52385918},{"atb":[[17,6.53],[12,22.17]],"id":52385887},{"atb":[[550,0.44],[650,0.16]],"id":52385920},{"atb":[[3.95,82.67],[4.9,26.8]],"id":52385889},{"atb":[[5.6,53.02],[7.2,16.86]],"id":52385883},{"atb":[[10,27.1],[15,7.46]],"id":52385894},{"atb":[[170,0.61],[85,2.9]],"id":52385927},{"atb":[[5.8,67.17],[7.6,19.8]],"id":52385896},{"atb":[[550,0.44],[650,0.16]],"id":52385929},{"atb":[[5.7,22.24],[4.7,65.92]],"id":52385890},{"atb":[[20,12.83],[30,6.31]],"id":52385923},{"atb":[[17,6.53],[12,22.17]],"id":52385925},{"atb":[[7.4,16.33],[5.7,51.89]],"id":52385902},{"atb":[[9.8,27.71],[14.5,7.74]],"id":52385904},{"atb":[[17,6.53],[12,22.17]],"id":52385937},{"atb":[[18,6.14],[13,20.32]],"id":52385898},{"atb":[[4.5,69.68],[5.5,23.22]],"id":52385931},{"atb":[[38,2.82],[24,10.6]],"id":52385900},{"atb":[[5.6,53.02],[7.2,16.86]],"id":52385933},{"atb":[[550,0.44],[650,0.16]],"id":52385907},{"atb":[[16,6.96],[11,24.39]],"id":52385909},{"atb":[[17.5,14.77],[25,4.35]],"id":52385886},{"atb":[[48,2.22],[29,8.71]],"id":52385919},{"atb":[[4.5,69.68],[5.5,23.22]],"id":52385888},{"atb":[[4,81.3],[5,26.13]],"id":52385882},{"atb":[[9.8,27.71],[14.5,7.74]],"id":52385884},{"atb":[[20,12.83],[30,3.6]],"id":52385917},{"atb":[[21,5.22],[15.5,16.82]],"id":52385926},{"atb":[[3.95,82.67],[4.9,26.8]],"id":52385895},{"atb":[[6.4,19.35],[5.2,58.07]],"id":52385897},{"atb":[[550,0.44],[650,0.16]],"id":52385922},{"atb":[[9.2,29.74],[13,8.71]],"id":52385891},{"atb":[[18.5,5.97],[13.5,19.51]],"id":52385924},{"atb":[[20,5.5],[15,17.42]],"id":52385893},{"atb":[[9.8,27.71],[14.5,7.74]],"id":52385934},{"atb":[[16,6.96],[11,24.39]],"id":52385903},{"atb":[[17,15.24],[24,4.54]],"id":52385936},{"atb":[[18.5,5.97],[13.5,19.51]],"id":52385905},{"atb":[[18.5,5.97],[13.5,19.51]],"id":52385930},{"atb":[[4,81.3],[5,26.13]],"id":52385932},{"atb":[[19.5,5.65],[14.5,18.06]],"id":52385901}],"con":true,"img":false}]}
{"op":"mcm","clk":"11450288950","pt":1717320103223,"mc":[{"id":"1.229554922","rc":[{"atb":[[65,0],[36,0],[46,0],[28,0]],"id":52385909},{"atb":[[65,0],[36,0],[46,0],[28,0]],"id":52385903}],"con":true,"img":false}]}
{"op":"mcm","clk":"11450289013","pt":1717320104112,"mc":[{"id":"1.229554922","rc":[{"atb":[[70,0.38],[38,2.12],[48,1.11],[29,3.74]],"id":52385909},{"atb":[[70,0.38],[38,2.12],[48,1.11],[29,3.74]],"id":52385903}],"con":true,"img":false}]}
{"op":"mcm","clk":"11450289698","pt":1717320114643,"mc":[{"id":"1.229554922","rc":[{"atb":[[170,0.31],[85,1.25]],"id":52385908},{"atb":[[18,0],[26,4.19]],"id":52385918},{"atb":[[17,0],[12,0]],"id":52385887},{"atb":[[550,0],[650,0]],"id":52385920},{"atb":[[3.95,0],[4.9,0]],"id":52385889},{"atb":[[5.6,0],[7.2,0]],"id":52385883},{"atb":[[10,0],[15,0]],"id":52385894},{"atb":[[170,0],[85,0]],"id":52385927},{"atb":[[5.8,16.35],[7.6,3.97]],"id":52385896},{"atb":[[550,0],[650,0]],"id":52385929},{"atb":[[5.7,0],[4.7,0]],"id":52385890},{"atb":[[20,0],[30,2.71]],"id":52385923},{"atb":[[17,0],[12,0]],"id":52385925},{"atb":[[7.4,0],[5.7,0]],"id":52385902},{"atb":[[9.8,0],[14.5,0]],"id":52385904},{"atb":[[17,0],[12,0]],"id":52385937},{"atb":[[18,0],[13,0]],"id":52385898},{"atb":[[4.5,0],[5.5,0]],"id":52385931},{"atb":[[38,0],[24,0]],"id":52385900},{"atb":[[5.6,0],[7.2,0]],"id":52385933},{"atb":[[550,0],[650,0]],"id":52385907},{"atb":[[16,0],[11,0]],"id":52385909},{"atb":[[17.5,0],[25,0]],"id":52385886},{"atb":[[48,0],[29,0]],"id":52385919},{"atb":[[4.5,0],[5.5,0]],"id":52385888},{"atb":[[4,0],[5,0]],"id":52385882},{"atb":[[9.8,0],[14.5,0]],"id":52385884},{"atb":[[20,0],[30,0]],"id":52385917},{"atb":[[21,0],[15.5,0]],"id":52385926},{"atb":[[3.95,0],[4.9,0]],"id":52385895},{"atb":[[6.4,0],[5.2,0]],"id":52385897},{"atb":[[550,0],[650,0]],"id":52385922},{"atb":[[9.2,0],[13,0]],"id":52385891},{"atb":[[18.5,0],[13.5,0]],"id":52385924},{"atb":[[20,0],[15,0]],"id":52385893},{"atb":[[9.8,0],[14.5,0]],"id":52385934},{"atb":[[16,0],[11,0]],"id":52385903},{"atb":[[17,0],[24,0]],"id":52385936},{"atb":[[18.5,0],[13.5,0]],"id":52385905},{"atb":[[18.5,0],[13.5,0]],"id":52385930},{"atb":[[4,0],[5,0]],"id":52385932},{"atb":[[19.5,0],[14.5,0]],"id":52385901}],"con":true,"img":false}]}
{"op":"mcm","clk":"11450290837","pt":1717320129973,"mc":[{"id":"1.229554922","rc":[{"atb":[[190,0.55],[95,2.59]],"id":52385908},{"atb":[[18,14.34],[26,8.37]],"id":52385918},{"atb":[[550,0.44],[650,0.16]],"id":52385920},{"atb":[[200,0.52],[100,2.46]],"id":52385927},{"atb":[[550,0.44],[650,0.16]],"id":52385929},{"atb":[[20,12.83],[30,6.31]],"id":52385923},{"atb":[[17.5,6.33],[12.5,21.2]],"id":52385925},{"atb":[[17,6.53],[12,22.17]],"id":52385937},{"atb":[[4.5,69.68],[5.5,23.22]],"id":52385931},{"atb":[[5.6,53.02],[7.2,16.86]],"id":52385933},{"atb":[[550,0.44],[650,0.16]],"id":52385907},{"atb":[[16,6.96],[11,24.39]],"id":52385909},{"atb":[[48,2.22],[29,8.71]],"id":52385919},{"atb":[[20,12.83],[30,3.6]],"id":52385917},{"atb":[[16,16.26],[22,4.97]],"id":52385926},{"atb":[[550,0.44],[650,0.16]],"id":52385922},{"atb":[[18.5,5.97],[13.5,19.51]],"id":52385924},{"atb":[[9.8,27.71],[14.5,7.74]],"id":52385934},{"atb":[[17,15.24],[24,4.54]],"id":52385936},{"atb":[[18.5,5.97],[13.5,19.51]],"id":52385930},{"atb":[[4,81.3],[5,26.13]],"id":52385932}],"con":true,"img":false}]}
{"op":"mcm","clk":"11450290851","pt":1717320130177,"mc":[{"id":"1.229554922","rc":[{"atb":[[17.5,6.33],[12.5,21.2]],"id":52385887},{"atb":[[3.95,82.67],[4.9,26.8]],"id":52385889},{"atb":[[5.6,53.02],[7.2,16.86]],"id":52385883},{"atb":[[10,27.1],[15,7.46]],"id":52385894},{"atb":[[5.8,67.17],[7.6,19.8]],"id":52385896},{"atb":[[5.7,22.24],[4.7,65.92]],"id":52385890},{"atb":[[7.4,16.33],[5.7,51.89]],"id":52385902},{"atb":[[9.8,27.71],[14.5,7.74]],"id":52385904},{"atb":[[18,6.14],[13,20.32]],"id":52385898},{"atb":[[38,2.82],[24,10.6]],"id":52385900},{"atb":[[17.5,14.77],[25,4.35]],"id":52385886},{"atb":[[4.5,69.68],[5.5,23.22]],"id":52385888},{"atb":[[4,81.3],[5,26.13]],"id":52385882},{"atb":[[9.8,27.71],[14.5,7.74]],"id":52385884},{"atb":[[4.8,27.5],[3.9,84.1]],"id":52385895},{"atb":[[6.4,19.35],[5.2,58.07]],"id":52385897},{"atb":[[9.2,29.74],[13,8.71]],"id":52385891},{"atb":[[20,5.5],[15,17.42]],"id":52385893},{"atb":[[16,6.96],[11,24.39]],"id":52385903},{"atb":[[18.5,5.97],[13.5,19.51]],"id":52385905},{"atb":[[20,5.5],[15,17.42]],"id":52385901}],"con":true,"img":false}]}
{"op":"mcm","clk":"11450298222","pt":1717320240412,"mc":[{"id":"1.229554922","rc":[{"atb":[[22,2]],"id":52385908},{"atb":[[6.4,5.08]],"id":52385918},{"atl":[[910,2]],"id":52385918},{"atb":[[5.7,11.58]],"id":52385887},{"atl":[[740,2]],"id":52385887},{"atb":[[21,2]],"id":52385920},{"atb":[[3.35,26.96]],"id":52385889},{"atl":[[500,2]],"id":52385889},{"atb":[[4.6,23.5]],"id":52385883},{"atl":[[590,2]],"id":52385883},{"atb":[[5.8,8.79]],"id":52385894},{"atl":[[750,2]],"id":52385894},{"atb":[[22,2]],"id":52385927},{"atb":[[3.3,43.48]],"id":52385896},{"atl":[[480,2]],"id":52385896},{"atb":[[21,5]],"id":52385929},{"atl":[[1000,2]],"id":52385929},{"atb":[[4.6,22.91]],"id":52385890},{"atl":[[590,2]],"id":52385890},{"atb":[[6.2,8.72]],"id":52385923},{"atl":[[890,2]],"id":52385923},{"atb":[[10,5.64]],"id":52385925},{"atl":[[1000,2]],"id":52385925},{"atb":[[3.6,26.19]],"id":52385902},{"atl":[[530,2]],"id":52385902},{"atb":[[16,6.67]],"id":52385904},{"atl":[[1000,2]],"id":52385904},{"atb":[[4.6,10.48]],"id":52385937},{"atl":[[590,2]],"id":52385937},{"atb":[[6.2,11.39]],"id":52385898},{"atl":[[890,2]],"id":52385898},{"atb":[[3.1,26.19]],"id":52385931},{"atl":[[430,2]],"id":52385931},{"atb":[[5.5,5.85]],"id":52385900},{"atl":[[700,2]],"id":52385900},{"atb":[[3.75,21.81]],"id":52385933},{"atl":[[530,2]],"id":52385933},{"atb":[[22,9.74]],"id":52385907},{"atb":[[16.5,6.45]],"id":52385909},{"atl":[[1000,2]],"id":52385909},{"atb":[[9.8,4.24]],"id":52385919},{"atl":[[1000,2]],"id":52385919},{"atb":[[3.75,25.46]],"id":52385888},{"atl":[[540,2]],"id":52385888},{"atb":[[3.55,26.19]],"id":52385882},{"atl":[[530,2]],"id":52385882},{"atb":[[7,8.01]],"id":52385884},{"atl":[[940,2]],"id":52385884},{"atb":[[6,6.41]],"id":52385917},{"atl":[[810,2]],"id":52385917},{"atb":[[16.5,6.45]],"id":52385926},{"atl":[[1000,2]],"id":52385926},{"atb":[[1.35,26.19]],"id":52385895},{"atl":[[540,2]],"id":52385895},{"atb":[[3.45,21.04]],"id":52385897},{"atl":[[520,2]],"id":52385897},{"atb":[[13.5,2]],"id":52385922},{"atl":[[1000,2]],"id":52385922},{"atb":[[7,9.08]],"id":52385891},{"atl":[[950,2]],"id":52385891},{"atb":[[8,5.64]],"id":52385924},{"atl":[[990,2]],"id":52385924},{"atb":[[5.7,8.38]],"id":52385893},{"atl":[[740,2]],"id":52385893},{"atb":[[5.8,9.08]],"id":52385934},{"atl":[[760,2]],"id":52385934},{"atb":[[12,9.09]],"id":52385903},{"atl":[[1000,2]],"id":52385903},{"atb":[[4.7,8.68]],"id":52385936},{"atl":[[600,2]],"id":52385936},{"atb":[[21,5]],"id":52385905},{"atb":[[8.8,5.64]],"id":52385930},{"atl":[[1000,2]],"id":52385930}],"con":true,"img":false}]}
{"op":"mcm","clk":"11450298231","pt":1717320240522,"mc":[{"id":"1.229554922","rc":[{"atb":[[5.7,7.16]],"id":52385886},{"atl":[[730,2]],"id":52385886},{"atb":[[1.35,29.59]],"id":52385932},{"atl":[[460,2]],"id":52385932},{"atb":[[5.5,11.54]],"id":52385901},{"atl":[[700,2]],"id":52385901}],"con":true,"img":false}]}
{"op":"mcm","clk":"11450298442","pt":1717320243522,"mc":[{"id":"1.229554922","rc":[{"atb":[[34,0],[44,0],[27,0],[60,0]],"id":52385904},{"atb":[[34,0],[85,0],[44,0],[60,0]],"id":52385905}],"con":true,"img":false}]}
{"op":"mcm","clk":"11450298450","pt":1717320243727,"mc":[{"id":"1.229554922","rc":[{"atb":[[19,5.56],[21,0]],"id":52385905}],"con":true,"img":false}]}
{"op":"mcm","clk":"11450298490","pt":1717320244207,"mc":[{"id":"1.229554922","rc":[{"atb":[[65,0.41],[36,2.24],[46,1.16],[28,3.88]],"id":52385904},{"atb":[[65,0.82],[36,2.99],[90,0.29],[46,1.74]],"id":52385905}],"con":true,"img":false}]}
{"op":"mcm","clk":"11450298507","pt":1717320244415,"mc":[{"id":"1.229554922","rc":[{"atb":[[19,0],[23,4.55]],"id":52385905}],"con":true,"img":false}]}
{"op":"mcm","clk":"11450298889","pt":1717320249698,"mc":[{"id":"1.229554922","rc":[{"atb":[[16.5,0],[22,4.76]],"id":52385909}],"con":true,"img":false}]}
{"op":"mcm","clk":"11450298907","pt":1717320250009,"mc":[{"id":"1.229554922","rc":[{"atb":[[38,0],[48,0],[24,0],[29,0]],"id":52385886}],"con":true,"img":false}]}
{"op":"mcm","clk":"11450298951","pt":1717320250731,"mc":[{"id":"1.229554922","rc":[{"atb":[[40,1.34],[25,8.71],[50,0.53],[30,2.71]],"id":52385886}],"con":true,"img":false}]}
{"op":"mcm","clk":"11450300295","pt":1717320270244,"mc":[{"id":"1.229554922","rc":[{"atb":[[170,0],[85,0],[220,0],[120,0]],"id":52385908},{"atb":[[130,0],[180,0],[90,0],[230,0]],"id":52385927},{"atb":[[75,0],[40,0],[50,0],[30,0]],"id":52385930}],"con":true,"img":false}]}
{"op":"mcm","clk":"11450300336","pt":1717320270958,"mc":[{"id":"1.229554922","rc":[{"atb":[[300,0.09],[150,0.7],[200,0.39],[250,0.21]],"id":52385908},{"atb":[[260,0.2],[310,0.08],[210,0.38]],"id":52385927},{"atb":[[34,3.17],[44,1.83]],"id":52385930}],"con":true,"img":false}]}
{"op":"mcm","clk":"11450300345","pt":1717320271013,"mc":[{"id":"1.229554922","rc":[{"atb":[[160,0.66]],"id":52385927},{"atb":[[85,0.31],[60,0.88]],"id":52385930}],"con":true,"img":false}]}
{"op":"mcm","clk":"11450300807","pt":1717320277574,"mc":[{"id":"1.229554922","rc":[{"atl":[[860,2],[910,0]],"id":52385918},{"atl":[[470,2],[500,0]],"id":52385889},{"atl":[[700,2],[750,0]],"id":52385894},{"atl":[[570,2],[590,0]],"id":52385890},{"atl":[[860,2],[890,0]],"id":52385923},{"atl":[[530,0],[520,2]],"id":52385902},{"atb":[[16,0],[20,5.26]],"id":52385904},{"atl":[[590,0],[580,2]],"id":52385937},{"atb":[[7.2,11.39],[6.2,0]],"id":52385898},{"atl":[[430,0],[420,2]],"id":52385931},{"atl":[[700,0],[680,2]],"id":52385900},{"atb":[[4.1,25.46],[3.75,0]],"id":52385888},{"atb":[[3.8,26.19],[3.55,0]],"id":52385882},{"atl":[[530,0],[520,2]],"id":52385882},{"atb":[[8.6,8.01],[7,0]],"id":52385884},{"atl":[[790,2],[810,0]],"id":52385917},{"atl":[[540,0],[520,2]],"id":52385895},{"atl":[[520,0],[510,2]],"id":52385897},{"atl":[[910,2],[950,0]],"id":52385891},{"atl":[[990,0],[960,2]],"id":52385924},{"atl":[[690,2],[740,0]],"id":52385893},{"atb":[[16.5,6.45],[12,0]],"id":52385903},{"atl":[[600,0],[590,2]],"id":52385936},{"atl":[[980,2],[1000,0]],"id":52385930}],"con":true,"img":false}]}
{"op":"mcm","clk":"11450300813","pt":1717320277665,"mc":[{"id":"1.229554922","rc":[{"atl":[[440,2],[460,0]],"id":52385932},{"atl":[[700,0],[680,2]],"id":52385901}],"con":true,"img":false}]}
{"op":"mcm","clk":"11450302633","pt":1717320306503,"mc":[{"id":"1.229554922","rc":[{"atb":[[200,0],[100,0]],"id":52385927},{"atb":[[550,0],[650,0]],"id":52385929},{"atb":[[17.5,0],[12.5,0]],"id":52385925},{"atb":[[17,0],[12,0]],"id":52385937},{"atb":[[4.5,0],[5.5,0]],"id":52385931},{"atb":[[5.6,0],[7.2,0]],"id":52385933},{"atb":[[16,0],[22,0]],"id":52385926},{"atb":[[18.5,0],[13.5,0]],"id":52385924},{"atb":[[9.8,0],[14.5,0]],"id":52385934},{"atb":[[17,0],[24,0]],"id":52385936},{"atb":[[18.5,0],[13.5,0]],"id":52385930},{"atb":[[4,0],[5,0]],"id":52385932}],"con":true,"img":false}]}
{"op":"mcm","clk":"11450302638","pt":1717320306610,"mc":[{"id":"1.229554922","rc":[{"atb":[[190,0],[95,0]],"id":52385908},{"atb":[[18,0],[26,4.19]],"id":52385918},{"atb":[[17.5,0],[12.5,0]],"id":52385887},{"atb":[[550,0],[650,0]],"id":52385920},{"atb":[[3.95,0],[4.9,0]],"id":52385889},{"atb":[[5.6,0],[7.2,0]],"id":52385883},{"atb":[[10,0],[15,0]],"id":52385894},{"atb":[[5.8,16.35],[7.6,3.97]],"id":52385896},{"atb":[[5.7,0],[4.7,0]],"id":52385890},{"atb":[[20,0],[30,2.71]],"id":52385923},{"atb":[[7.4,0],[5.7,0]],"id":52385902},{"atb":[[9.8,0],[14.5,0]],"id":52385904},{"atb":[[18,0],[13,0]],"id":52385898},{"atb":[[38,0],[24,0]],"id":52385900},{"atb":[[550,0],[650,0]],"id":52385907},{"atb":[[16,0],[11,0]],"id":52385909},{"atb":[[17.5,0],[25,4.36]],"id":52385886},{"atb":[[48,0],[29,0]],"id":52385919},{"atb":[[4.5,0],[5.5,0]],"id":52385888},{"atb":[[4,0],[5,0]],"id":52385882},{"atb":[[9.8,0],[14.5,0]],"id":52385884},{"atb":[[20,0],[30,0]],"id":52385917},{"atb":[[4.8,0],[3.9,0]],"id":52385895},{"atb":[[6.4,0],[5.2,0]],"id":52385897},{"atb":[[550,0],[650,0]],"id":52385922},{"atb":[[9.2,0],[13,0]],"id":52385891},{"atb":[[20,0],[15,0]],"id":52385893},{"atb":[[16,0],[11,0]],"id":52385903},{"atb":[[18.5,0],[13.5,0]],"id":52385905},{"atb":[[20,0],[15,0]],"id":52385901}],"con":true,"img":false}]}
{"op":"mcm","clk":"11450302697","pt":1717320307658,"mc":[{"id":"1.229554922","rc":[{"atb":[[9,0],[10,0],[12.5,0],[15,0]],"id":52385933}],"con":true,"img":false}]}
{"op":"mcm","clk":"11450302740","pt":1717320308400,"mc":[{"id":"1.229554922","rc":[{"atb":[[9.2,12.76],[10.5,8.26],[15.5,1.81]],"id":52385933}],"con":true,"img":false}]}
{"op":"mcm","clk":"11450302746","pt":1717320308495,"mc":[{"id":"1.229554922","rc":[{"atb":[[13,4.36]],"id":52385933}],"con":true,"img":false}]}
{"op":"mcm","clk":"11450303933","pt":1717320326820,"mc":[{"id":"1.229554922","rc":[{"atb":[[190,0.55],[95,2.59]],"id":52385908},{"atb":[[18,14.34],[26,8.37]],"id":52385918},{"atb":[[17.5,6.33],[12.5,21.2]],"id":52385887},{"atb":[[550,0.44],[650,0.16]],"id":52385920},{"atb":[[3.95,82.67],[4.9,26.8]],"id":52385889},{"atb":[[5.6,53.02],[7.2,16.86]],"id":52385883},{"atb":[[10,27.1],[15,7.46]],"id":52385894},{"atb":[[200,0.52],[100,2.46]],"id":52385927},{"atb":[[5.8,67.17],[7.6,19.8]],"id":52385896},{"atb":[[550,0.44],[650,0.16]],"id":52385929},{"atb":[[5.7,22.24],[4.7,65.92]],"id":52385890},{"atb":[[20,12.83],[30,6.31]],"id":52385923},{"atb":[[17.5,6.33],[12.5,21.2]],"id":52385925},{"atb":[[7.4,16.33],[5.7,51.89]],"id":52385902},{"atb":[[9.8,27.71],[14.5,7.74]],"id":52385904},{"atb":[[17,6.53],[12,22.17]],"id":52385937},{"atb":[[18,6.14],[13,20.32]],"id":52385898},{"atb":[[4.5,69.68],[5.5,23.22]],"id":52385931},{"atb":[[38,2.82],[24,10.6]],"id":52385900},{"atb":[[5.6,53.02],[7.2,16.86]],"id":52385933},{"atb":[[550,0.44],[650,0.16]],"id":52385907},{"atb":[[16,6.96],[11,24.39]],"id":52385909},{"atb":[[17.5,14.77],[25,8.71]],"id":52385886},{"atb":[[48,2.22],[29,8.71]],"id":52385919},{"atb":[[4.5,69.68],[5.5,23.22]],"id":52385888},{"atb":[[4,81.3],[5,26.13]],"id":52385882},{"atb":[[9.8,27.71],[14.5,7.74]],"id":52385884},{"atb":[[20,12.83],[30,3.6]],"id":52385917},{"atb":[[16,16.26],[22,4.97]],"id":52385926},{"atb":[[4.8,27.5],[3.9,84.1]],"id":52385895},{"atb":[[6.4,19.35],[5.2,58.07]],"id":52385897},{"atb":[[550,0.44],[650,0.16]],"id":52385922},{"atb":[[9.2,29.74],[13,8.71]],"id":52385891},{"atb":[[18.5,5.97],[13.5,19.51]],"id":52385924},{"atb":[[20,5.5],[15,17.42]],"id":52385893},{"atb":[[9.8,27.71],[14.5,7.74]],"id":52385934},{"atb":[[16,6.96],[11,24.39]],"id":52385903},{"atb":[[17,15.24],[24,4.54]],"id":52385936},{"atb":[[18.5,5.97],[13.5,19.51]],"id":52385905},{"atb":[[18.5,5.97],[13.5,19.51]],"id":52385930},{"atb":[[4,81.3],[5,26.13]],"id":52385932},{"atb":[[20,5.5],[15,17.42]],"id":52385901}],"con":true,"img":false}]}
{"op":"mcm","clk":"11450305986","pt":1717320363052,"mc":[{"id":"1.229554922","rc":[{"atb":[[34,0],[44,0],[22,0],[27,0]],"id":52385884}],"con":true,"img":false}]}
{"op":"mcm","clk":"11450305993","pt":1717320363156,"mc":[{"id":"1.229554922","rc":[{"atb":[[32,0],[42,0],[21,0],[26,0]],"id":52385893},{"atb":[[6.8,0],[9.8,0],[8.8,0],[7.8,0]],"id":52385932}],"con":true,"img":false}]}
{"op":"mcm","clk":"11450306031","pt":1717320363778,"mc":[{"id":"1.229554922","rc":[{"atb":[[36,1.5],[46,0.58],[23,4.76],[28,2.91]],"id":52385884}],"con":true,"img":false}]}
{"op":"mcm","clk":"11450306037","pt":1717320363849,"mc":[{"id":"1.229554922","rc":[{"atb":[[22,4.98],[27,3.02]],"id":52385893},{"atb":[[7.2,16.88],[10.5,2.75],[8.2,10.9]],"id":52385932}],"con":true,"img":false}]}
{"op":"mcm","clk":"11450306042","pt":1717320363936,"mc":[{"id":"1.229554922","rc":[{"atb":[[34,1.59],[44,0.61]],"id":52385893},{"atb":[[9.2,6.38]],"id":52385932}],"con":true,"img":false}]}
{"op":"mcm","clk":"11450308123","pt":1717320400340,"mc":[{"id":"1.229554922","rc":[{"atb":[[190,0],[95,0]],"id":52385908},{"atb":[[18,0],[26,4.19]],"id":52385918},{"atb":[[17.5,0],[12.5,0]],"id":52385887},{"atb":[[550,0],[650,0]],"id":52385920},{"atb":[[3.95,0],[4.9,0]],"id":52385889},{"atb":[[5.6,0],[7.2,0]],"id":52385883},{"atb":[[10,0],[15,0]],"id":52385894},{"atb":[[5.8,16.35],[7.6,3.97]],"id":52385896},{"atb":[[5.7,0],[4.7,0]],"id":52385890},{"atb":[[20,0],[30,2.71]],"id":52385923},{"atb":[[7.4,0],[5.7,0]],"id":52385902},{"atb":[[9.8,0],[14.5,0]],"id":52385904},{"atb":[[18,0],[13,0]],"id":52385898},{"atb":[[38,0],[24,0]],"id":52385900},{"atb":[[550,0],[650,0]],"id":52385907},{"atb":[[16,0],[11,0]],"id":52385909},{"atb":[[17.5,0],[25,4.36]],"id":52385886},{"atb":[[48,0],[29,0]],"id":52385919},{"atb":[[4.5,0],[5.5,0]],"id":52385888},{"atb":[[4,0],[5,0]],"id":52385882},{"atb":[[9.8,0],[14.5,0]],"id":52385884},{"atb":[[20,0],[30,0]],"id":52385917},{"atb":[[4.8,0],[3.9,0]],"id":52385895},{"atb":[[6.4,0],[5.2,0]],"id":52385897},{"atb":[[550,0],[650,0]],"id":52385922},{"atb":[[9.2,0],[13,0]],"id":52385891},{"atb":[[20,0],[15,0]],"id":52385893},{"atb":[[16,0],[11,0]],"id":52385903},{"atb":[[18.5,0],[13.5,0]],"id":52385905},{"atb":[[20,0],[15,0]],"id":52385901}],"con":true,"img":false}]}
{"op":"mcm","clk":"11450308129","pt":1717320400392,"mc":[{"id":"1.229554922","rc":[{"atb":[[200,0],[100,0]],"id":52385927},{"atb":[[550,0],[650,0]],"id":52385929},{"atb":[[17.5,0],[12.5,0]],"id":52385925},{"atb":[[17,0],[12,0]],"id":52385937},{"atb":[[4.5,0],[5.5,0]],"id":52385931},{"atb":[[5.6,0],[7.2,0]],"id":52385933},{"atb":[[16,0],[22,0]],"id":52385926},{"atb":[[18.5,0],[13.5,0]],"id":52385924},{"atb":[[9.8,0],[14.5,0]],"id":52385934},{"atb":[[17,0],[24,0]],"id":52385936},{"atb":[[18.5,0],[13.5,0]],"id":52385930},{"atb":[[4,0],[5,0]],"id":52385932}],"con":true,"img":false}]}
{"op":"mcm","clk":"11450308813","pt":1717320411094,"mc":[{"id":"1.229554922","rc":[{"atb":[[17.5,6.33],[12.5,21.2]],"id":52385887},{"atb":[[3.95,82.67],[4.9,26.8]],"id":52385889},{"atb":[[5.6,53.02],[7.2,16.86]],"id":52385883},{"atb":[[10,27.1],[15,7.46]],"id":52385894},{"atb":[[5.8,67.17],[7.6,19.8]],"id":52385896},{"atb":[[5.7,22.24],[4.7,65.92]],"id":52385890},{"atb":[[7.4,16.33],[5.7,51.89]],"id":52385902},{"atb":[[9.8,27.71],[14.5,7.74]],"id":52385904},{"atb":[[18,6.14],[13,20.32]],"id":52385898},{"atb":[[38,2.82],[24,10.6]],"id":52385900},{"atb":[[17.5,14.77],[25,8.71]],"id":52385886},{"atb":[[4.5,69.68],[5.5,23.22]],"id":52385888},{"atb":[[4,81.3],[5,26.13]],"id":52385882},{"atb":[[9.8,27.71],[14.5,7.74]],"id":52385884},{"atb":[[4.8,27.5],[3.9,84.1]],"id":52385895},{"atb":[[6.4,19.35],[5.2,58.07]],"id":52385897},{"atb":[[9.2,29.74],[13,8.71]],"id":52385891},{"atb":[[20,5.5],[15,17.42]],"id":52385893},{"atb":[[16,6.96],[11,24.39]],"id":52385903},{"atb":[[18.5,5.97],[13.5,19.51]],"id":52385905},{"atb":[[20,5.5],[15,17.42]],"id":52385901}],"con":true,"img":false}]}
{"op":"mcm","clk":"11450308825","pt":1717320411304,"mc":[{"id":"1.229554922","rc":[{"atb":[[190,0.55],[95,2.59]],"id":52385908},{"atb":[[18,14.34],[26,8.37]],"id":52385918},{"atb":[[550,0.44],[650,0.16]],"id":52385920},{"atb":[[200,0.52],[100,2.46]],"id":52385927},{"atb":[[550,0.44],[650,0.16]],"id":52385929},{"atb":[[20,12.83],[30,6.31]],"id":52385923},{"atb":[[17.5,6.33],[12.5,21.2]],"id":52385925},{"atb":[[17,6.53],[12,22.17]],"id":52385937},{"atb":[[4.5,69.68],[5.5,23.22]],"id":52385931},{"atb":[[5.6,53.02],[7.2,16.86]],"id":52385933},{"atb":[[550,0.44],[650,0.16]],"id":52385907},{"atb":[[16,6.96],[11,24.39]],"id":52385909},{"atb":[[48,2.22],[29,8.71]],"id":52385919},{"atb":[[20,12.83],[30,3.6]],"id":52385917},{"atb":[[16,16.26],[22,4.97]],"id":52385926},{"atb":[[550,0.44],[650,0.16]],"id":52385922},{"atb":[[18.5,5.97],[13.5,19.51]],"id":52385924},{"atb":[[9.8,27.71],[14.5,7.74]],"id":52385934},{"atb":[[17,15.24],[24,4.54]],"id":52385936},{"atb":[[18.5,5.97],[13.5,19.51]],"id":52385930},{"atb":[[4,81.3],[5,26.13]],"id":52385932}],"con":true,"img":false}]}
{"op":"mcm","clk":"11450324430","pt":1717320545549,"mc":[{"id":"1.229554922","rc":[{"atb":[[75,0],[40,0],[50,0],[30,0]],"id":52385925}],"con":true,"img":false}]}
{"op":"mcm","clk":"11450324473","pt":1717320546225,"mc":[{"id":"1.229554922","rc":[{"atb":[[70,0.38],[38,2.12],[48,1.11],[29,3.74]],"id":52385925}],"con":true,"img":false}]}
{"op":"mcm","clk":"11450325371","pt":1717320556670,"mc":[{"id":"1.229554922","rc":[{"atb":[[5.1,23.5],[4.6,0]],"id":52385883},{"atl":[[530,0],[520,2]],"id":52385933},{"atl":[[540,0],[530,2]],"id":52385888},{"atb":[[16.5,0],[19,5.56]],"id":52385926},{"atl":[[520,0],[510,2]],"id":52385895},{"atb":[[8,0],[9.2,5.64]],"id":52385924},{"atl":[[590,0],[580,2]],"id":52385936},{"atl":[[430,2],[440,0]],"id":52385932}],"con":true,"img":false}]}
{"op":"mcm","clk":"11450331271","pt":1717320633604,"mc":[{"id":"1.229554922","rc":[{"atb":[[300,0],[150,0],[200,0],[250,0]],"id":52385908},{"atb":[[260,0],[310,0],[160,0],[210,0]],"id":52385927}],"con":true,"img":false}]}
{"op":"mcm","clk":"11450331330","pt":1717320634287,"mc":[{"id":"1.229554922","rc":[{"atb":[[260,0.2],[310,0.08],[160,0.66],[210,0.38]],"id":52385908},{"atb":[[270,0.19],[320,0.08],[170,0.62],[220,0.36]],"id":52385927}],"con":true,"img":false}]}
{"op":"mcm","clk":"11450334592","pt":1717320676667,"mc":[{"id":"1.229554922","rc":[{"atl":[[1000,0]],"id":52385929},{"atl":[[520,0],[530,2]],"id":52385933},{"atl":[[530,0],[540,2]],"id":52385888},{"atl":[[520,2],[510,0]],"id":52385895},{"atl":[[580,0],[590,2]],"id":52385936},{"atl":[[430,0],[440,2]],"id":52385932}],"con":true,"img":false}]}
{"op":"mcm","clk":"11450344118","pt":1717320794258,"mc":[{"id":"1.229554922","rc":[{"atb":[[190,0],[95,0]],"id":52385908},{"atb":[[18,0],[26,4.19]],"id":52385918},{"atb":[[17.5,0],[12.5,0]],"id":52385887},{"atb":[[550,0],[650,0]],"id":52385920},{"atb":[[3.95,0],[4.9,0]],"id":52385889},{"atb":[[5.6,0],[7.2,0]],"id":52385883},{"atb":[[10,0],[15,0]],"id":52385894},{"atb":[[200,0],[100,0]],"id":52385927},{"atb":[[5.8,16.35],[7.6,3.97]],"id":52385896},{"atb":[[550,0],[650,0]],"id":52385929},{"atb":[[5.7,0],[4.7,0]],"id":52385890},{"atb":[[20,0],[30,2.71]],"id":52385923},{"atb":[[17.5,0],[12.5,0]],"id":52385925},{"atb":[[7.4,0],[5.7,0]],"id":52385902},{"atb":[[9.8,0],[14.5,0]],"id":52385904},{"atb":[[17,0],[12,0]],"id":52385937},{"atb":[[18,0],[13,0]],"id":52385898},{"atb":[[4.5,0],[5.5,0]],"id":52385931},{"atb":[[38,0],[24,0]],"id":52385900},{"atb":[[5.6,0],[7.2,0]],"id":52385933},{"atb":[[550,0],[650,0]],"id":52385907},{"atb":[[16,0],[11,0]],"id":52385909},{"atb":[[17.5,0],[25,4.36]],"id":52385886},{"atb":[[48,0],[29,0]],"id":52385919},{"atb":[[4.5,0],[5.5,0]],"id":52385888},{"atb":[[4,0],[5,0]],"id":52385882},{"atb":[[9.8,0],[14.5,0]],"id":52385884},{"atb":[[20,0],[30,0]],"id":52385917},{"atb":[[16,0],[22,0]],"id":52385926},{"atb":[[4.8,0],[3.9,0]],"id":52385895},{"atb":[[6.4,0],[5.2,0]],"id":52385897},{"atb":[[550,0],[650,0]],"id":52385922},{"atb":[[9.2,0],[13,0]],"id":52385891},{"atb":[[18.5,0],[13.5,0]],"id":52385924},{"atb":[[20,0],[15,0]],"id":52385893},{"atb":[[9.8,0],[14.5,0]],"id":52385934},{"atb":[[16,0],[11,0]],"id":52385903},{"atb":[[17,0],[24,0]],"id":52385936},{"atb":[[18.5,0],[13.5,0]],"id":52385905},{"atb":[[18.5,0],[13.5,0]],"id":52385930},{"atb":[[4,0],[5,0]],"id":52385932},{"atb":[[20,0],[15,0]],"id":52385901}],"con":true,"img":false}]}
{"op":"mcm","clk":"11450345301","pt":1717320809190,"mc":[{"id":"1.229554922","rc":[{"atb":[[190,0.55],[95,2.59]],"id":52385908},{"atb":[[18,14.34],[26,8.37]],"id":52385918},{"atb":[[17.5,6.33],[12.5,21.2]],"id":52385887},{"atb":[[550,0.44],[650,0.16]],"id":52385920},{"atb":[[3.95,82.67],[4.9,26.8]],"id":52385889},{"atb":[[5.6,53.02],[7.2,16.86]],"id":52385883},{"atb":[[10,27.1],[15,7.46]],"id":52385894},{"atb":[[200,0.52],[100,2.46]],"id":52385927},{"atb":[[5.8,67.17],[7.6,19.8]],"id":52385896},{"atb":[[550,0.44],[650,0.16]],"id":52385929},{"atb":[[5.7,22.24],[4.7,65.92]],"id":52385890},{"atb":[[20,12.83],[30,6.31]],"id":52385923},{"atb":[[17.5,6.33],[12.5,21.2]],"id":52385925},{"atb":[[7.4,16.33],[5.7,51.89]],"id":52385902},{"atb":[[9.8,27.71],[14.5,7.74]],"id":52385904},{"atb":[[17,6.53],[12,22.17]],"id":52385937},{"atb":[[18,6.14],[13,20.32]],"id":52385898},{"atb":[[4.5,69.68],[5.5,23.22]],"id":52385931},{"atb":[[38,2.82],[24,10.6]],"id":52385900},{"atb":[[5.6,53.02],[7.2,16.86]],"id":52385933},{"atb":[[550,0.44],[650,0.16]],"id":52385907},{"atb":[[16,6.96],[11,24.39]],"id":52385909},{"atb":[[17.5,14.77],[25,8.71]],"id":52385886},{"atb":[[48,2.22],[29,8.71]],"id":52385919},{"atb":[[4.5,69.68],[5.5,23.22]],"id":52385888},{"atb":[[4,81.3],[5,26.13]],"id":52385882},{"atb":[[9.8,27.71],[14.5,7.74]],"id":52385884},{"atb":[[20,12.83],[30,3.6]],"id":52385917},{"atb":[[16,16.26],[22,4.97]],"id":52385926},{"atb":[[4.8,27.5],[3.9,84.1]],"id":52385895},{"atb":[[6.4,19.35],[5.2,58.07]],"id":52385897},{"atb":[[550,0.44],[650,0.16]],"id":52385922},{"atb":[[9.2,29.74],[13,8.71]],"id":52385891},{"atb":[[18.5,5.97],[13.5,19.51]],"id":52385924},{"atb":[[20,5.5],[15,17.42]],"id":52385893},{"atb":[[9.8,27.71],[14.5,7.74]],"id":52385934},{"atb":[[16,6.96],[11,24.39]],"id":52385903},{"atb":[[17,15.24],[24,4.54]],"id":52385936},{"atb":[[18.5,5.97],[13.5,19.51]],"id":52385905},{"atb":[[18.5,5.97],[13.5,19.51]],"id":52385930},{"atb":[[4,81.3],[5,26.13]],"id":52385932},{"atb":[[20,5.5],[15,17.42]],"id":52385901}],"con":true,"img":false}]}
{"op":"mcm","clk":"11450349908","pt":1717320862831,"mc":[{"id":"1.229554922","rc":[{"atl":[[460,2],[470,0]],"id":52385889},{"atl":[[590,0],[580,2]],"id":52385883},{"atl":[[570,0],[560,2]],"id":52385890},{"atb":[[10,0],[13,8.33]],"id":52385925},{"atb":[[3.6,0],[3.85,26.19]],"id":52385902},{"atb":[[5.1,10.48],[4.6,0]],"id":52385937},{"atl":[[410,2],[420,0]],"id":52385931},{"atb":[[5.5,0],[6,5.85]],"id":52385900},{"atl":[[730,0],[710,2]],"id":52385886},{"atl":[[540,0],[530,2]],"id":52385888},{"atl":[[520,0],[510,2]],"id":52385882},{"atb":[[19,0],[22,9.73]],"id":52385926},{"atl":[[520,0],[510,2]],"id":52385895},{"atb":[[17.5,2],[13.5,0]],"id":52385922},{"atl":[[910,0],[900,2]],"id":52385891},{"atb":[[9.2,0],[10.5,5.64]],"id":52385924},{"atl":[[670,2],[690,0]],"id":52385893},{"atl":[[590,0],[580,2]],"id":52385936},{"atb":[[11.5,5.64],[8.8,0]],"id":52385930},{"atl":[[430,2],[440,0]],"id":52385932},{"atb":[[6.2,11.54],[5.5,0]],"id":52385901}],"con":true,"img":false}]}
{"op":"mcm","clk":"11450349937","pt":1717320863140,"mc":[{"id":"1.229554922","rc":[{"atb":[[34,0],[44,0],[22,0],[27,0]],"id":52385900}],"con":true,"img":false}]}
{"op":"mcm","clk":"11450349948","pt":1717320863245,"mc":[{"id":"1.229554922","rc":[{"atb":[[40,0],[50,0],[25,4.35],[30,0]],"id":52385886},{"atb":[[34,0],[44,0],[22,0],[27,0]],"id":52385893}],"con":true,"img":false}]}
{"op":"mcm","clk":"11450350001","pt":1717320863814,"mc":[{"id":"1.229554922","rc":[{"atb":[[36,1.5],[46,0.58],[23,4.76],[28,2.91]],"id":52385900}],"con":true,"img":false}]}
{"op":"mcm","clk":"11450350008","pt":1717320863918,"mc":[{"id":"1.229554922","rc":[{"atb":[[38,1.41],[48,0.55],[24,4.55],[29,2.8]],"id":52385886},{"atb":[[32,1.69],[42,0.64],[21,5.23],[26,3.14]],"id":52385893}],"con":true,"img":false}]}
{"op":"mcm","clk":"11450351262","pt":1717320878441,"mc":[{"id":"1.229554922","rc":[{"atl":[[1000,2]],"id":52385929},{"atl":[[530,0],[520,2]],"id":52385933}],"con":true,"img":false}]}
{"op":"mcm","clk":"11450353548","pt":1717320905844,"mc":[{"id":"1.229554922","rc":[{"atb":[[36,0],[46,0],[23,0],[28,0]],"id":52385900}],"con":true,"img":false}]}
{"op":"mcm","clk":"11450353624","pt":1717320906565,"mc":[{"id":"1.229554922","rc":[{"atb":[[34,1.59],[44,0.61],[22,4.98],[27,3.02]],"id":52385900}],"con":true,"img":false}]}
{"op":"mcm","clk":"11450354252","pt":1717320913873,"mc":[{"id":"1.229554922","rc":[{"atb":[[70,0],[38,0],[29,0]],"id":52385925}],"con":true,"img":false}]}
{"op":"mcm","clk":"11450354261","pt":1717320913977,"mc":[{"id":"1.229554922","rc":[{"atb":[[260,0],[310,0],[160,0],[210,0]],"id":52385908},{"atb":[[270,0],[320,0],[170,0],[220,0]],"id":52385927}],"con":true,"img":false}]}
{"op":"mcm","clk":"11450354413","pt":1717320915858,"mc":[{"id":"1.229554922","rc":[{"atl":[[570,2],[580,0]],"id":52385937},{"atb":[[9,7.24],[10.5,0]],"id":52385924},{"atb":[[11.5,0],[9.4,6.36]],"id":52385930}],"con":true,"img":false}]}
{"op":"mcm","clk":"11450355653","pt":1717320931165,"mc":[{"id":"1.229554922","rc":[{"atl":[[1000,0]],"id":52385929}],"con":true,"img":false}]}
{"op":"mcm","clk":"11450355819","pt":1717320933080,"mc":[{"id":"1.229554922","rc":[{"atb":[[300,0.09],[150,0.7],[200,0.92],[250,0.21]],"id":52385927},{"atb":[[34,0],[44,0],[22,0],[27,0]],"id":52385900}],"con":true,"img":false}]}
{"op":"mcm","clk":"11450355855","pt":1717320933491,"mc":[{"id":"1.229554922","rc":[{"atb":[[75,0.36],[40,2.01],[30,3.61]],"id":52385925}],"con":true,"img":false}]}
{"op":"mcm","clk":"11450355910","pt":1717320934173,"mc":[{"id":"1.229554922","rc":[{"atb":[[36,1.5],[46,0.58],[23,4.76],[28,2.91]],"id":52385900}],"con":true,"img":false}]}
{"op":"mcm","clk":"11450356283","pt":1717320938780,"mc":[{"id":"1.229554922","rc":[{"atb":[[300,0],[150,0],[200,0.52],[250,0]],"id":52385927}],"con":true,"img":false}]}
{"op":"mcm","clk":"11450356338","pt":1717320939605,"mc":[{"id":"1.229554922","rc":[{"atb":[[270,0.19],[320,0.08],[170,0.62],[220,0.36]],"id":52385927}],"con":true,"img":false}]}
{"op":"mcm","clk":"11450356865","pt":1717320946002,"mc":[{"id":"1.229554922","rc":[{"atb":[[270,0],[320,0],[170,0],[220,0]],"id":52385927}],"con":true,"img":false}]}
{"op":"mcm","clk":"11450356924","pt":1717320946689,"mc":[{"id":"1.229554922","rc":[{"atb":[[300,0.09],[150,0.7],[200,0.92],[250,0.21]],"id":52385927}],"con":true,"img":false}]}
{"op":"mcm","clk":"11450357217","pt":1717320950529,"mc":[{"id":"1.229554922","rc":[{"atb":[[300,0],[150,0],[200,0.52],[250,0]],"id":52385927}],"con":true,"img":false}]}
{"op":"mcm","clk":"11450357279","pt":1717320951203,"mc":[{"id":"1.229554922","rc":[{"atb":[[270,0.19],[320,0.08],[170,0.62],[220,0.36]],"id":52385927}],"con":true,"img":false}]}
{"op":"mcm","clk":"11450358517","pt":1717320966705,"mc":[{"id":"1.229554922","rc":[{"atb":[[270,0],[320,0],[170,0],[220,0]],"id":52385927}],"con":true,"img":false}]}
{"op":"mcm","clk":"11450358589","pt":1717320967425,"mc":[{"id":"1.229554922","rc":[{"atb":[[300,0.09],[150,0.7],[200,0.92],[250,0.21]],"id":52385927}],"con":true,"img":false}]}
{"op":"mcm","clk":"11450359008","pt":1717320972403,"mc":[{"id":"1.229554922","rc":[{"atb":[[300,0],[150,0],[200,0.52],[250,0]],"id":52385927}],"con":true,"img":false}]}
{"op":"mcm","clk":"11450359062","pt":1717320973129,"mc":[{"id":"1.229554922","rc":[{"atb":[[270,0.19],[320,0.08],[170,0.62],[220,0.36]],"id":52385927}],"con":true,"img":false}]}
{"op":"mcm","clk":"11450360963","pt":1717320997061,"mc":[{"id":"1.229554922","rc":[{"atb":[[260,0.2],[310,0.08],[160,0.66],[210,0.38]],"id":52385908}],"con":true,"img":false}]}
{"op":"mcm","clk":"11450360971","pt":1717320997165,"mc":[{"id":"1.229554922","rc":[{"atb":[[270,0],[320,0],[170,0],[220,0]],"id":52385927}],"con":true,"img":false}]}
{"op":"mcm","clk":"11450361024","pt":1717320997892,"mc":[{"id":"1.229554922","rc":[{"atb":[[300,0.09],[150,0.7],[200,0.92],[250,0.21]],"id":52385927}],"con":true,"img":false}]}
{"op":"mcm","clk":"11450363342","pt":1717321027622,"mc":[{"id":"1.229554922","rc":[{"atb":[[260,0],[310,0],[160,0],[210,0]],"id":52385908}],"con":true,"img":false}]}
{"op":"mcm","clk":"11450363396","pt":1717321028341,"mc":[{"id":"1.229554922","rc":[{"atb":[[140,0.75],[290,0.09],[190,0.97],[240,0.22]],"id":52385908}],"con":true,"img":false}]}
{"op":"mcm","clk":"11450370533","pt":1717321129036,"mc":[{"id":"1.229554922","rc":[{"atb":[[36,0],[46,0],[23,0],[28,0]],"id":52385900}],"con":true,"img":false}]}
{"op":"mcm","clk":"11450370583","pt":1717321129756,"mc":[{"id":"1.229554922","rc":[{"atb":[[38,4.24],[24,15.16],[48,0.55],[29,2.8]],"id":52385900}],"con":true,"img":false}]}
{"op":"mcm","clk":"11450372143","pt":1717321151905,"mc":[{"id":"1.229554922","rc":[{"atb":[[6.4,0],[24,4.35]],"id":52385918},{"atl":[[860,0]],"id":52385918},{"atb":[[3.35,0],[3.05,32.7]],"id":52385889},{"atl":[[350,2],[460,0]],"id":52385889},{"atl":[[630,2],[700,0]],"id":52385894},{"atb":[[4.6,0],[3.8,27.56]],"id":52385890},{"atl":[[520,2],[560,0]],"id":52385890},{"atb":[[6.2,0],[24,4.35]],"id":52385923},{"atl":[[860,0]],"id":52385923},{"atb":[[8,7.24],[13,0]],"id":52385925},{"atl":[[930,2],[1000,0]],"id":52385925},{"atb":[[3.85,0],[4.4,26.19]],"id":52385902},{"atb":[[20,0],[7,7.76]],"id":52385904},{"atl":[[890,2],[1000,0]],"id":52385904},{"atb":[[5.1,0],[5.7,10.48]],"id":52385937},{"atl":[[890,0],[870,2]],"id":52385898},{"atb":[[23,4.55],[6,0]],"id":52385900},{"atl":[[680,0],[930,2]],"id":52385900},{"atb":[[4.4,21.81],[3.75,0]],"id":52385933},{"atb":[[22,0],[12.5,8.7]],"id":52385909},{"atb":[[20,5.26],[5.7,0]],"id":52385886},{"atl":[[710,0],[780,2]],"id":52385886},{"atb":[[9.8,0],[25,4.17]],"id":52385919},{"atl":[[1000,0]],"id":52385919},{"atb":[[3.8,0],[3.3,31.72]],"id":52385882},{"atl":[[430,2],[510,0]],"id":52385882},{"atb":[[8.6,0],[6.4,9.52]],"id":52385884},{"atl":[[790,2],[940,0]],"id":52385884},{"atb":[[24,8.9],[6,0]],"id":52385917},{"atl":[[790,0]],"id":52385917},{"atl":[[450,2],[510,0]],"id":52385895},{"atl":[[470,2],[510,0]],"id":52385897},{"atb":[[17.5,0],[25,7.54]],"id":52385922},{"atl":[[1000,0]],"id":52385922},{"atb":[[5.6,11.32],[7,0]],"id":52385891},{"atl":[[640,2],[900,0]],"id":52385891},{"atl":[[950,2],[960,0]],"id":52385924},{"atb":[[11.5,8.38],[5.7,0]],"id":52385893},{"atl":[[710,2],[760,0]],"id":52385934},{"atb":[[16.5,0],[7.6,7.48]],"id":52385903},{"atl":[[910,2],[1000,0]],"id":52385903},{"atb":[[14,7.69],[4.7,0]],"id":52385936},{"atl":[[580,0],[710,2]],"id":52385936},{"atl":[[1000,2]],"id":52385905},{"atb":[[12.5,6.36],[9.4,0]],"id":52385930},{"atl":[[400,2],[430,0]],"id":52385932}],"con":true,"img":false}]}
{"op":"mcm","clk":"11450372150","pt":1717321151965,"mc":[{"id":"1.229554922","rc":[{"atb":[[5.7,0],[7,11.58]],"id":52385887},{"atl":[[720,2],[740,0]],"id":52385887},{"atb":[[21,0],[29,6.61]],"id":52385920},{"atl":[[560,2],[580,0]],"id":52385883},{"atb":[[22,0],[27,2]],"id":52385927},{"atb":[[3.8,35.71],[3.3,0]],"id":52385896},{"atl":[[460,2],[480,0]],"id":52385896},{"atb":[[21,0],[28,3.7]],"id":52385929},{"atb":[[3.1,0],[3.5,26.19]],"id":52385931},{"atb":[[22,4.98],[28,3.7]],"id":52385907},{"atl":[[530,0],[510,2]],"id":52385888},{"atb":[[3.6,31.72]],"id":52385882},{"atl":[[420,2]],"id":52385882},{"atb":[[22,4.97],[25,4.17]],"id":52385926},{"atb":[[3.45,0],[3.75,21.04]],"id":52385897},{"atb":[[5.8,0],[6.6,9.08]],"id":52385934},{"atl":[[680,2]],"id":52385934},{"atb":[[7.2,11.54],[6.2,0]],"id":52385901}],"con":true,"img":false}]}
{"op":"mcm","clk":"11450372154","pt":1717321152061,"mc":[{"id":"1.229554922","rc":[{"atb":[[3.3,0]],"id":52385882},{"atl":[[430,0]],"id":52385882},{"atl":[[710,0]],"id":52385934}],"con":true,"img":false}]}
{"op":"mcm","clk":"11450372173","pt":1717321152276,"mc":[{"id":"1.229554922","rc":[{"atb":[[140,0],[290,0],[190,0.55],[240,0]],"id":52385908},{"atb":[[11,0],[7.4,0],[8.4,0],[9.4,0]],"id":52385889},{"atb":[[40,0],[20,0],[25,0],[30,0]],"id":52385894},{"atb":[[300,0],[150,0],[200,0.52],[250,0]],"id":52385927},{"atb":[[36,0],[46,0],[23,0],[28,0]],"id":52385884},{"atb":[[9.2,0],[10.5,0],[13,0],[15.5,0]],"id":52385897}],"con":true,"img":false}]}
{"op":"mcm","clk":"11450372248","pt":1717321153260,"mc":[{"id":"1.229554922","rc":[{"atb":[[130,0.61],[180,0.29],[90,1.18],[230,0.12]],"id":52385908},{"atb":[[8,11.21],[9,6.54],[10,2.91],[7,17.44]],"id":52385889},{"atb":[[38,0.71],[19.5,5.66],[24,3.41],[29,1.87]],"id":52385894},{"atb":[[270,0.1],[170,0.47],[220,0.24],[120,0.88]],"id":52385927},{"atb":[[34,1.59],[44,0.61],[22,4.98],[27,3.02]],"id":52385884},{"atb":[[9,13.08],[10,8.72],[12.5,4.55],[15,1.87]],"id":52385897}],"con":true,"img":false}]}
{"op":"mcm","clk":"11450372359","pt":1717321154864,"mc":[{"id":"1.229554922","rc":[{"atb":[[75,0],[40,0],[30,0]],"id":52385925},{"atb":[[7.2,0],[9.2,0],[10.5,0],[8.2,0]],"id":52385932}],"con":true,"img":false}]}
{"op":"mcm","clk":"11450372364","pt":1717321154970,"mc":[{"id":"1.229554922","rc":[{"atb":[[65,0],[36,0],[46,0],[28,0]],"id":52385904},{"atb":[[9,0],[10,0],[12.5,0],[15,0]],"id":52385897},{"atb":[[38,0],[19.5,0],[24,0],[29,0]],"id":52385891}],"con":true,"img":false}]}
{"op":"mcm","clk":"11450372399","pt":1717321155592,"mc":[{"id":"1.229554922","rc":[{"atb":[[70,0.38],[38,2.12],[29,3.74]],"id":52385925},{"atb":[[8,11.21],[9,6.54],[10,2.91],[7,17.44]],"id":52385932}],"con":true,"img":false}]}
{"op":"mcm","clk":"11450372407","pt":1717321155653,"mc":[{"id":"1.229554922","rc":[{"atb":[[34,2.38],[44,1.22],[27,4.02],[60,0.44]],"id":52385904},{"atb":[[12,4.76],[9.8,8.92],[8.8,13.41],[14.5,1.94]],"id":52385897},{"atb":[[36,0.75],[19,5.81],[23,3.57],[28,1.94]],"id":52385891}],"con":true,"img":false}]}
{"op":"mcm","clk":"11450372579","pt":1717321158093,"mc":[{"id":"1.229554922","rc":[{"atb":[[190,0],[95,0]],"id":52385908},{"atb":[[18,0],[26,4.19]],"id":52385918},{"atb":[[17.5,0],[12.5,0]],"id":52385887},{"atb":[[550,0],[650,0]],"id":52385920},{"atb":[[3.95,0],[4.9,0]],"id":52385889},{"atb":[[5.6,0],[7.2,0]],"id":52385883},{"atb":[[10,0],[15,0]],"id":52385894},{"atb":[[200,0],[100,0]],"id":52385927},{"atb":[[5.8,16.35],[7.6,3.97]],"id":52385896},{"atb":[[550,0],[650,0]],"id":52385929},{"atb":[[5.7,0],[4.7,0]],"id":52385890},{"atb":[[20,0],[30,2.71]],"id":52385923},{"atb":[[17.5,0],[12.5,0]],"id":52385925},{"atb":[[7.4,0],[5.7,0]],"id":52385902},{"atb":[[9.8,0],[14.5,0]],"id":52385904},{"atb":[[17,0],[12,0]],"id":52385937},{"atb":[[18,0],[13,0]],"id":52385898},{"atb":[[4.5,0],[5.5,0]],"id":52385931},{"atb":[[38,1.41],[24,4.55]],"id":52385900},{"atb":[[5.6,0],[7.2,0]],"id":52385933},{"atb":[[550,0],[650,0]],"id":52385907},{"atb":[[16,0],[11,0]],"id":52385909},{"atb":[[17.5,0],[25,0]],"id":52385886},{"atb":[[48,0],[29,0]],"id":52385919},{"atb":[[4.5,0],[5.5,0]],"id":52385888},{"atb":[[4,0],[5,0]],"id":52385882},{"atb":[[9.8,0],[14.5,0]],"id":52385884},{"atb":[[20,0],[30,0]],"id":52385917},{"atb":[[16,0],[22,0]],"id":52385926},{"atb":[[4.8,0],[3.9,0]],"id":52385895},{"atb":[[6.4,0],[5.2,0]],"id":52385897},{"atb":[[550,0],[650,0]],"id":52385922},{"atb":[[9.2,0],[13,0]],"id":52385891},{"atb":[[18.5,0],[13.5,0]],"id":52385924},{"atb":[[20,0],[15,0]],"id":52385893},{"atb":[[9.8,0],[14.5,0]],"id":52385934},{"atb":[[16,0],[11,0]],"id":52385903},{"atb":[[17,0],[24,0]],"id":52385936},{"atb":[[18.5,0],[13.5,0]],"id":52385905},{"atb":[[18.5,0],[13.5,0]],"id":52385930},{"atb":[[4,0],[5,0]],"id":52385932},{"atb":[[20,0],[15,0]],"id":52385901}],"con":true,"img":false}]}
{"op":"mcm","clk":"11450372645","pt":1717321158980,"mc":[{"id":"1.229554922","rc":[{"atb":[[8,0],[9,0],[10,0],[7,0]],"id":52385889}],"con":true,"img":false}]}
{"op":"mcm","clk":"11450372702","pt":1717321159656,"mc":[{"id":"1.229554922","rc":[{"atb":[[7.2,12.66],[9.2,3.19],[6.2,20.12],[8.2,7.27]],"id":52385889}],"con":true,"img":false}]}
{"op":"mcm","clk":"11450373232","pt":1717321167195,"mc":[{"id":"1.229554922","rc":[{"atb":[[29,0]],"id":52385886},{"atb":[[42,0],[21,0]],"id":52385893}],"con":true,"img":false}]}
{"op":"mcm","clk":"11450373236","pt":1717321167289,"mc":[{"id":"1.229554922","rc":[{"atb":[[38,0],[48,0],[24,0]],"id":52385886},{"atb":[[32,0],[26,0]],"id":52385893}],"con":true,"img":false}]}
{"op":"mcm","clk":"11450373277","pt":1717321167916,"mc":[{"id":"1.229554922","rc":[{"atb":[[50,1.6]],"id":52385886},{"atb":[[80,0.33],[55,0.97]],"id":52385893}],"con":true,"img":false}]}
{"op":"mcm","clk":"11450373282","pt":1717321167968,"mc":[{"id":"1.229554922","rc":[{"atb":[[40,2.68],[100,0.27]],"id":52385886},{"atb":[[32,3.37],[42,1.92]],"id":52385893}],"con":true,"img":false}]}
{"op":"mcm","clk":"11450373291","pt":1717321168065,"mc":[{"id":"1.229554922","rc":[{"atb":[[75,0.71]],"id":52385886}],"con":true,"img":false}]}
{"op":"mcm","clk":"11450373752","pt":1717321175010,"mc":[{"id":"1.229554922","rc":[{"atb":[[190,0.55],[95,2.59]],"id":52385908},{"atb":[[18,14.34],[26,8.37]],"id":52385918},{"atb":[[550,0.44],[650,0.16]],"id":52385920},{"atb":[[200,0.52],[100,2.46]],"id":52385927},{"atb":[[550,0.44],[650,0.16]],"id":52385929},{"atb":[[20,12.83],[30,6.31]],"id":52385923},{"atb":[[17.5,6.33],[12.5,21.2]],"id":52385925},{"atb":[[17,6.53],[12,22.17]],"id":52385937},{"atb":[[4.5,69.68],[5.5,23.22]],"id":52385931},{"atb":[[5.6,53.02],[7.2,16.86]],"id":52385933},{"atb":[[550,0.44],[650,0.16]],"id":52385907},{"atb":[[16,6.96],[11,24.39]],"id":52385909},{"atb":[[48,2.22],[29,8.71]],"id":52385919},{"atb":[[20,12.83],[30,3.6]],"id":52385917},{"atb":[[16,16.26],[22,4.97]],"id":52385926},{"atb":[[550,0.44],[650,0.16]],"id":52385922},{"atb":[[18.5,5.97],[13.5,19.51]],"id":52385924},{"atb":[[9.8,27.71],[14.5,7.74]],"id":52385934},{"atb":[[17,15.24],[24,4.54]],"id":52385936},{"atb":[[18.5,5.97],[13.5,19.51]],"id":52385930},{"atb":[[4,81.3],[5,26.13]],"id":52385932}],"con":true,"img":false}]}
{"op":"mcm","clk":"11450373757","pt":1717321175112,"mc":[{"id":"1.229554922","rc":[{"atb":[[17.5,6.33],[12.5,21.2]],"id":52385887},{"atb":[[3.95,82.67],[4.9,26.8]],"id":52385889},{"atb":[[5.6,53.02],[7.2,16.86]],"id":52385883},{"atb":[[10,27.1],[15,7.46]],"id":52385894},{"atb":[[5.8,67.17],[7.6,19.8]],"id":52385896},{"atb":[[5.7,22.24],[4.7,65.92]],"id":52385890},{"atb":[[7.4,16.33],[5.7,51.89]],"id":52385902},{"atb":[[9.8,27.71],[14.5,7.74]],"id":52385904},{"atb":[[18,6.14],[13,20.32]],"id":52385898},{"atb":[[38,4.24],[24,15.16]],"id":52385900},{"atb":[[17.5,14.77],[25,4.35]],"id":52385886},{"atb":[[4.5,69.68],[5.5,23.22]],"id":52385888},{"atb":[[4,81.3],[5,26.13]],"id":52385882},{"atb":[[9.8,27.71],[14.5,7.74]],"id":52385884},{"atb":[[4.8,27.5],[3.9,84.1]],"id":52385895},{"atb":[[6.4,19.35],[5.2,58.07]],"id":52385897},{"atb":[[9.2,29.74],[13,8.71]],"id":52385891},{"atb":[[20,5.5],[15,17.42]],"id":52385893},{"atb":[[16,6.96],[11,24.39]],"id":52385903},{"atb":[[18.5,5.97],[13.5,19.51]],"id":52385905},{"atb":[[20,5.5],[15,17.42]],"id":52385901}],"con":true,"img":false}]}
{"op":"mcm","clk":"11450374070","pt":1717321179887,"mc":[{"id":"1.229554922","rc":[{"atb":[[24,0],[27,3.85]],"id":52385918},{"atl":[[330,2],[350,0]],"id":52385889},{"atl":[[600,2],[630,0]],"id":52385894},{"atb":[[4.1,27.56],[3.8,0]],"id":52385890},{"atl":[[520,0],[510,2]],"id":52385890},{"atb":[[24,0],[28,3.7]],"id":52385923},{"atb":[[8,0],[9,7.24]],"id":52385925},{"atl":[[870,2],[930,0]],"id":52385925},{"atl":[[830,2],[890,0]],"id":52385904},{"atl":[[820,2],[870,0]],"id":52385898},{"atb":[[4.9,21.81],[4.4,0]],"id":52385933},{"atl":[[750,2],[790,0]],"id":52385884},{"atb":[[24,4.55],[27,3.85]],"id":52385917},{"atl":[[430,2],[450,0]],"id":52385895},{"atl":[[450,2],[470,0]],"id":52385897},{"atb":[[5.6,0],[6.2,11.32]],"id":52385891},{"atl":[[620,2],[640,0]],"id":52385891},{"atl":[[890,2],[950,0]],"id":52385924},{"atl":[[850,2],[910,0]],"id":52385903},{"atl":[[380,2],[400,0]],"id":52385932}],"con":true,"img":false}]}
{"op":"mcm","clk":"11450375388","pt":1717321202182,"mc":[{"id":"1.229554922","rc":[{"atb":[[34,0],[85,0],[44,0],[60,0]],"id":52385930}],"con":true,"img":false}]}
{"op":"mcm","clk":"11450375397","pt":1717321202286,"mc":[{"id":"1.229554922","rc":[{"atb":[[12.5,0],[14,7.69]],"id":52385930}],"con":true,"img":false}]}
{"op":"mcm","clk":"11450375434","pt":1717321202858,"mc":[{"id":"1.229554922","rc":[{"atb":[[70,0.76],[38,2.83],[95,0.28],[48,1.67]],"id":52385930}],"con":true,"img":false}]}
{"op":"mcm","clk":"11450375914","pt":1717321211958,"mc":[{"id":"1.229554922","rc":[{"atb":[[70,0],[38,0],[95,0],[48,0]],"id":52385930}],"con":true,"img":false}]}
{"op":"mcm","clk":"11450375945","pt":1717321212680,"mc":[{"id":"1.229554922","rc":[{"atb":[[34,3.17],[85,0.31],[44,1.83],[60,0.88]],"id":52385930}],"con":true,"img":false}]}
{"op":"mcm","clk":"11450387973","pt":1717321406555,"mc":[{"id":"1.229554922","rc":[{"atb":[[38,2.82],[48,0],[24,10.6],[29,0]],"id":52385900}],"con":true,"img":false}]}
{"op":"mcm","clk":"11450388020","pt":1717321407241,"mc":[{"id":"1.229554922","rc":[{"atb":[[140,0.19],[70,1.14],[95,0.55],[48,2.23]],"id":52385900}],"con":true,"img":false}]}
{"op":"mcm","clk":"11450389209","pt":1717321427736,"mc":[{"id":"1.229554922","rc":[{"atb":[[34,0],[44,0],[22,0],[27,0]],"id":52385884}],"con":true,"img":false}]}
{"op":"mcm","clk":"11450389261","pt":1717321428773,"mc":[{"id":"1.229554922","rc":[{"atb":[[36,1.5],[46,0.58],[23,4.76],[28,2.91]],"id":52385884}],"con":true,"img":false}]}
{"op":"mcm","clk":"11450389887","pt":1717321438857,"mc":[{"id":"1.229554922","rc":[{"atb":[[7.2,0],[9.2,0],[6.2,0],[8.2,0]],"id":52385889},{"atb":[[12,0],[9.8,0],[8.8,0],[14.5,0]],"id":52385897},{"atb":[[8,0],[9,0],[10,0],[7,0]],"id":52385932}],"con":true,"img":false}]}
{"op":"mcm","clk":"11450389892","pt":1717321438956,"mc":[{"id":"1.229554922","rc":[{"atb":[[70,0],[38,0],[29,0]],"id":52385925},{"atb":[[34,0],[44,0],[27,0],[60,0]],"id":52385904},{"atb":[[36,0],[46,0],[23,0],[28,0]],"id":52385884},{"atb":[[36,0],[19,0],[23,0],[28,0]],"id":52385891}],"con":true,"img":false}]}
{"op":"mcm","clk":"11450389931","pt":1717321439574,"mc":[{"id":"1.229554922","rc":[{"atb":[[8,11.21],[9,6.54],[10,2.91],[7,17.44]],"id":52385889},{"atb":[[9,13.08],[10,8.72],[12.5,4.55],[15,1.87]],"id":52385897},{"atb":[[7.2,16.88],[9.2,6.38],[10.5,2.75],[8.2,10.9]],"id":52385932}],"con":true,"img":false}]}
{"op":"mcm","clk":"11450389938","pt":1717321439683,"mc":[{"id":"1.229554922","rc":[{"atb":[[75,0.36],[40,2.01],[30,3.61]],"id":52385925},{"atb":[[65,0.41],[36,2.24],[46,1.16],[28,3.88]],"id":52385904},{"atb":[[34,1.59],[44,0.61],[22,4.98],[27,3.02]],"id":52385884},{"atb":[[38,0.71],[19.5,5.66],[24,3.41],[29,1.87]],"id":52385891}],"con":true,"img":false}]}
{"op":"mcm","clk":"11450390289","pt":1717321445365,"mc":[{"id":"1.229554922","rc":[{"atb":[[8,0],[9,0],[10,0],[7,0]],"id":52385889},{"atb":[[9,0],[10,0],[12.5,0],[15,0]],"id":52385897},{"atb":[[7.2,0],[9.2,0],[10.5,0],[8.2,0]],"id":52385932}],"con":true,"img":false}]}
{"op":"mcm","clk":"11450390295","pt":1717321445470,"mc":[{"id":"1.229554922","rc":[{"atb":[[75,0],[40,0],[30,0]],"id":52385925},{"atb":[[65,0],[36,0],[46,0],[28,0]],"id":52385904},{"atb":[[38,0],[19.5,0],[24,0],[29,0]],"id":52385891}],"con":true,"img":false}]}
{"op":"mcm","clk":"11450390370","pt":1717321446491,"mc":[{"id":"1.229554922","rc":[{"atb":[[7.2,12.66],[9.2,3.19],[6.2,20.12],[8.2,7.27]],"id":52385889},{"atb":[[70,0.38],[38,2.12],[29,3.74]],"id":52385925},{"atb":[[34,2.38],[44,1.22],[27,4.02],[60,0.44]],"id":52385904},{"atb":[[12,4.76],[9.8,8.92],[8.8,13.41],[14.5,1.94]],"id":52385897},{"atb":[[36,0.75],[19,5.81],[23,3.57],[28,1.94]],"id":52385891},{"atb":[[8,11.21],[9,6.54],[10,2.91],[7,17.44]],"id":52385932}],"con":true,"img":false}]}
{"op":"mcm","clk":"11450394599","pt":1717321511655,"mc":[{"id":"1.229554922","rc":[{"atb":[[190,0],[95,0]],"id":52385908},{"atb":[[18,0],[26,4.19]],"id":52385918},{"atb":[[17.5,0],[12.5,0]],"id":52385887},{"atb":[[550,0],[650,0]],"id":52385920},{"atb":[[3.95,0],[4.9,0]],"id":52385889},{"atb":[[5.6,0],[7.2,0]],"id":52385883},{"atb":[[10,0],[15,0]],"id":52385894},{"atb":[[200,0],[100,0]],"id":52385927},{"atb":[[5.8,16.35],[7.6,3.97]],"id":52385896},{"atb":[[550,0],[650,0]],"id":52385929},{"atb":[[5.7,0],[4.7,0]],"id":52385890},{"atb":[[20,0],[30,2.71]],"id":52385923},{"atb":[[17.5,0],[12.5,0]],"id":52385925},{"atb":[[7.4,0],[5.7,0]],"id":52385902},{"atb":[[9.8,0],[14.5,0]],"id":52385904},{"atb":[[17,0],[12,0]],"id":52385937},{"atb":[[18,0],[13,0]],"id":52385898},{"atb":[[4.5,0],[5.5,0]],"id":52385931},{"atb":[[38,0],[24,0]],"id":52385900},{"atb":[[5.6,0],[7.2,0]],"id":52385933},{"atb":[[550,0],[650,0]],"id":52385907},{"atb":[[16,0],[11,0]],"id":52385909},{"atb":[[17.5,0],[25,0]],"id":52385886},{"atb":[[48,0],[29,0]],"id":52385919},{"atb":[[4.5,0],[5.5,0]],"id":52385888},{"atb":[[4,0],[5,0]],"id":52385882},{"atb":[[9.8,0],[14.5,0]],"id":52385884},{"atb":[[20,0],[30,0]],"id":52385917},{"atb":[[16,0],[22,0]],"id":52385926},{"atb":[[4.8,0],[3.9,0]],"id":52385895},{"atb":[[6.4,0],[5.2,0]],"id":52385897},{"atb":[[550,0],[650,0]],"id":52385922},{"atb":[[9.2,0],[13,0]],"id":52385891},{"atb":[[18.5,0],[13.5,0]],"id":52385924},{"atb":[[20,0],[15,0]],"id":52385893},{"atb":[[9.8,0],[14.5,0]],"id":52385934},{"atb":[[16,0],[11,0]],"id":52385903},{"atb":[[17,0],[24,0]],"id":52385936},{"atb":[[18.5,0],[13.5,0]],"id":52385905},{"atb":[[18.5,0],[13.5,0]],"id":52385930},{"atb":[[4,0],[5,0]],"id":52385932},{"atb":[[20,0],[15,0]],"id":52385901}],"con":true,"img":false}]}
{"op":"mcm","clk":"11450396064","pt":1717321532382,"mc":[{"id":"1.229554922","rc":[{"atb":[[17.5,6.33],[12.5,21.2]],"id":52385887},{"atb":[[3.95,82.67],[4.9,26.8]],"id":52385889},{"atb":[[5.6,53.02],[7.2,16.86]],"id":52385883},{"atb":[[10,27.1],[15,7.46]],"id":52385894},{"atb":[[5.8,67.17],[7.6,19.8]],"id":52385896},{"atb":[[5.7,22.24],[4.7,65.92]],"id":52385890},{"atb":[[7.4,16.33],[5.7,51.89]],"id":52385902},{"atb":[[9.8,27.71],[14.5,7.74]],"id":52385904},{"atb":[[18,6.14],[13,20.32]],"id":52385898},{"atb":[[38,2.82],[24,10.6]],"id":52385900},{"atb":[[17.5,14.77],[25,4.35]],"id":52385886},{"atb":[[4.5,69.68],[5.5,23.22]],"id":52385888},{"atb":[[4,81.3],[5,26.13]],"id":52385882},{"atb":[[9.8,27.71],[14.5,7.74]],"id":52385884},{"atb":[[4.8,27.5],[3.9,84.1]],"id":52385895},{"atb":[[6.4,19.35],[5.2,58.07]],"id":52385897},{"atb":[[9.2,29.74],[13,8.71]],"id":52385891},{"atb":[[20,5.5],[15,17.42]],"id":52385893},{"atb":[[16,6.96],[11,24.39]],"id":52385903},{"atb":[[18.5,5.97],[13.5,19.51]],"id":52385905},{"atb":[[20,5.5],[15,17.42]],"id":52385901}],"con":true,"img":false}]}
{"op":"mcm","clk":"11450396082","pt":1717321532587,"mc":[{"id":"1.229554922","rc":[{"atb":[[190,0.55],[95,2.59]],"id":52385908},{"atb":[[18,14.34],[26,8.37]],"id":52385918},{"atb":[[550,0.44],[650,0.16]],"id":52385920},{"atb":[[200,0.52],[100,2.46]],"id":52385927},{"atb":[[550,0.44],[650,0.16]],"id":52385929},{"atb":[[20,12.83],[30,6.31]],"id":52385923},{"atb":[[17.5,6.33],[12.5,21.2]],"id":52385925},{"atb":[[17,6.53],[12,22.17]],"id":52385937},{"atb":[[4.5,69.68],[5.5,23.22]],"id":52385931},{"atb":[[5.6,53.02],[7.2,16.86]],"id":52385933},{"atb":[[550,0.44],[650,0.16]],"id":52385907},{"atb":[[16,6.96],[11,24.39]],"id":52385909},{"atb":[[48,2.22],[29,8.71]],"id":52385919},{"atb":[[20,12.83],[30,3.6]],"id":52385917},{"atb":[[16,16.26],[22,4.97]],"id":52385926},{"atb":[[550,0.44],[650,0.16]],"id":52385922},{"atb":[[18.5,5.97],[13.5,19.51]],"id":52385924},{"atb":[[9.8,27.71],[14.5,7.74]],"id":52385934},{"atb":[[17,15.24],[24,4.54]],"id":52385936},{"atb":[[18.5,5.97],[13.5,19.51]],"id":52385930},{"atb":[[4,81.3],[5,26.13]],"id":52385932}],"con":true,"img":false}]}
{"op":"mcm","clk":"11450407180","pt":1717321685549,"mc":[{"id":"1.229554922","rc":[{"atb":[[34,0],[44,0],[22,0],[27,0]],"id":52385884}],"con":true,"img":false}]}
{"op":"mcm","clk":"11450407236","pt":1717321686247,"mc":[{"id":"1.229554922","rc":[{"atb":[[36,1.5],[46,0.58],[23,4.76],[28,2.91]],"id":52385884}],"con":true,"img":false}]}
{"op":"mcm","clk":"11450421284","pt":1717321850506,"mc":[{"id":"1.229554922","rc":[{"atb":[[190,0],[95,0]],"id":52385908},{"atb":[[18,0],[26,4.19]],"id":52385918},{"atb":[[17.5,0],[12.5,0]],"id":52385887},{"atb":[[550,0],[650,0]],"id":52385920},{"atb":[[3.95,0],[4.9,0]],"id":52385889},{"atb":[[5.6,0],[7.2,0]],"id":52385883},{"atb":[[10,0],[15,0]],"id":52385894},{"atb":[[200,0],[100,0]],"id":52385927},{"atb":[[5.8,16.35],[7.6,3.97]],"id":52385896},{"atb":[[550,0],[650,0]],"id":52385929},{"atb":[[5.7,0],[4.7,0]],"id":52385890},{"atb":[[20,0],[30,2.71]],"id":52385923},{"atb":[[17.5,0],[12.5,0]],"id":52385925},{"atb":[[7.4,0],[5.7,0]],"id":52385902},{"atb":[[9.8,0],[14.5,0]],"id":52385904},{"atb":[[17,0],[12,0]],"id":52385937},{"atb":[[18,0],[13,0]],"id":52385898},{"atb":[[4.5,0],[5.5,0]],"id":52385931},{"atb":[[38,0],[24,0]],"id":52385900},{"atb":[[5.6,0],[7.2,0]],"id":52385933},{"atb":[[550,0],[650,0]],"id":52385907},{"atb":[[16,0],[11,0]],"id":52385909},{"atb":[[17.5,0],[25,0]],"id":52385886},{"atb":[[48,0],[29,0]],"id":52385919},{"atb":[[4.5,0],[5.5,0]],"id":52385888},{"atb":[[4,0],[5,0]],"id":52385882},{"atb":[[9.8,0],[14.5,0]],"id":52385884},{"atb":[[20,0],[30,0]],"id":52385917},{"atb":[[16,0],[22,0]],"id":52385926},{"atb":[[4.8,0],[3.9,0]],"id":52385895},{"atb":[[6.4,0],[5.2,0]],"id":52385897},{"atb":[[550,0],[650,0]],"id":52385922},{"atb":[[9.2,0],[13,0]],"id":52385891},{"atb":[[18.5,0],[13.5,0]],"id":52385924},{"atb":[[20,0],[15,0]],"id":52385893},{"atb":[[9.8,0],[14.5,0]],"id":52385934},{"atb":[[16,0],[11,0]],"id":52385903},{"atb":[[17,0],[24,0]],"id":52385936},{"atb":[[18.5,0],[13.5,0]],"id":52385905},{"atb":[[18.5,0],[13.5,0]],"id":52385930},{"atb":[[4,0],[5,0]],"id":52385932},{"atb":[[20,0],[15,0]],"id":52385901}],"con":true,"img":false}]}
{"op":"mcm","clk":"11450422893","pt":1717321869440,"mc":[{"id":"1.229554922","rc":[{"atb":[[190,0.55],[95,2.59]],"id":52385908},{"atb":[[18,14.34],[26,8.37]],"id":52385918},{"atb":[[17.5,6.33],[12.5,21.2]],"id":52385887},{"atb":[[550,0.44],[650,0.16]],"id":52385920},{"atb":[[3.95,82.67],[4.9,26.8]],"id":52385889},{"atb":[[5.6,53.02],[7.2,16.86]],"id":52385883},{"atb":[[10,27.1],[15,7.46]],"id":52385894},{"atb":[[200,0.52],[100,2.46]],"id":52385927},{"atb":[[5.8,67.17],[7.6,19.8]],"id":52385896},{"atb":[[550,0.44],[650,0.16]],"id":52385929},{"atb":[[5.7,22.24],[4.7,65.92]],"id":52385890},{"atb":[[20,12.83],[30,6.31]],"id":52385923},{"atb":[[17.5,6.33],[12.5,21.2]],"id":52385925},{"atb":[[7.4,16.33],[5.7,51.89]],"id":52385902},{"atb":[[9.8,27.71],[14.5,7.74]],"id":52385904},{"atb":[[17,6.53],[12,22.17]],"id":52385937},{"atb":[[18,6.14],[13,20.32]],"id":52385898},{"atb":[[4.5,69.68],[5.5,23.22]],"id":52385931},{"atb":[[38,2.82],[24,10.6]],"id":52385900},{"atb":[[5.6,53.02],[7.2,16.86]],"id":52385933},{"atb":[[550,0.44],[650,0.16]],"id":52385907},{"atb":[[16,6.96],[11,24.39]],"id":52385909},{"atb":[[17.5,14.77],[25,4.35]],"id":52385886},{"atb":[[48,2.22],[29,8.71]],"id":52385919},{"atb":[[4.5,69.68],[5.5,23.22]],"id":52385888},{"atb":[[4,81.3],[5,26.13]],"id":52385882},{"atb":[[9.8,27.71],[14.5,7.74]],"id":52385884},{"atb":[[20,12.83],[30,3.6]],"id":52385917},{"atb":[[16,16.26],[22,4.97]],"id":52385926},{"atb":[[4.8,27.5],[3.9,84.1]],"id":52385895},{"atb":[[6.4,19.35],[5.2,58.07]],"id":52385897},{"atb":[[550,0.44],[650,0.16]],"id":52385922},{"atb":[[9.2,29.74],[13,8.71]],"id":52385891},{"atb":[[18.5,5.97],[13.5,19.51]],"id":52385924},{"atb":[[20,5.5],[15,17.42]],"id":52385893},{"atb":[[9.8,27.71],[14.5,7.74]],"id":52385934},{"atb":[[16,6.96],[11,24.39]],"id":52385903},{"atb":[[17,15.24],[24,4.54]],"id":52385936},{"atb":[[18.5,5.97],[13.5,19.51]],"id":52385905},{"atb":[[18.5,5.97],[13.5,19.51]],"id":52385930},{"atb":[[4,81.3],[5,26.13]],"id":52385932},{"atb":[[20,5.5],[15,17.42]],"id":52385901}],"con":true,"img":false}]}
{"op":"mcm","clk":"11450425676","pt":1717321903598,"mc":[{"id":"1.229554922","rc":[{"atb":[[190,0],[95,0]],"id":52385908},{"atb":[[18,0],[26,4.19]],"id":52385918},{"atb":[[17.5,0],[12.5,0]],"id":52385887},{"atb":[[550,0],[650,0]],"id":52385920},{"atb":[[3.95,0],[4.9,0]],"id":52385889},{"atb":[[5.6,0],[7.2,0]],"id":52385883},{"atb":[[10,0],[15,0]],"id":52385894},{"atb":[[200,0],[100,0]],"id":52385927},{"atb":[[5.8,16.35],[7.6,3.97]],"id":52385896},{"atb":[[550,0],[650,0]],"id":52385929},{"atb":[[5.7,0],[4.7,0]],"id":52385890},{"atb":[[20,0],[30,2.71]],"id":52385923},{"atb":[[17.5,0],[12.5,0]],"id":52385925},{"atb":[[7.4,0],[5.7,0]],"id":52385902},{"atb":[[9.8,0],[14.5,0]],"id":52385904},{"atb":[[17,0],[12,0]],"id":52385937},{"atb":[[18,0],[13,0]],"id":52385898},{"atb":[[4.5,0],[5.5,0]],"id":52385931},{"atb":[[38,0],[24,0]],"id":52385900},{"atb":[[5.6,0],[7.2,0]],"id":52385933},{"atb":[[550,0],[650,0]],"id":52385907},{"atb":[[16,0],[11,0]],"id":52385909},{"atb":[[17.5,0],[25,0]],"id":52385886},{"atb":[[48,0],[29,0]],"id":52385919},{"atb":[[4.5,0],[5.5,0]],"id":52385888},{"atb":[[4,0],[5,0]],"id":52385882},{"atb":[[9.8,0],[14.5,0]],"id":52385884},{"atb":[[20,0],[30,0]],"id":52385917},{"atb":[[16,0],[22,0]],"id":52385926},{"atb":[[4.8,0],[3.9,0]],"id":52385895},{"atb":[[6.4,0],[5.2,0]],"id":52385897},{"atb":[[550,0],[650,0]],"id":52385922},{"atb":[[9.2,0],[13,0]],"id":52385891},{"atb":[[18.5,0],[13.5,0]],"id":52385924},{"atb":[[20,0],[15,0]],"id":52385893},{"atb":[[9.8,0],[14.5,0]],"id":52385934},{"atb":[[16,0],[11,0]],"id":52385903},{"atb":[[17,0],[24,0]],"id":52385936},{"atb":[[18.5,0],[13.5,0]],"id":52385905},{"atb":[[18.5,0],[13.5,0]],"id":52385930},{"atb":[[4,0],[5,0]],"id":52385932},{"atb":[[20,0],[15,0]],"id":52385901}],"con":true,"img":false}]}
{"op":"mcm","clk":"11450426490","pt":1717321913706,"mc":[{"id":"1.229554922","rc":[{"atb":[[17.5,6.33],[12.5,21.2]],"id":52385887},{"atb":[[3.95,82.67],[4.9,26.8]],"id":52385889},{"atb":[[5.6,53.02],[7.2,16.86]],"id":52385883},{"atb":[[10,27.1],[15,7.46]],"id":52385894},{"atb":[[5.8,67.17],[7.6,19.8]],"id":52385896},{"atb":[[5.7,22.24],[4.7,65.92]],"id":52385890},{"atb":[[5.8,50.81],[7.6,31.69]],"id":52385902},{"atb":[[9.8,27.71],[14.5,7.74]],"id":52385904},{"atb":[[18,6.14],[13,20.32]],"id":52385898},{"atb":[[38,2.82],[24,10.6]],"id":52385900},{"atb":[[17.5,14.77],[25,4.35]],"id":52385886},{"atb":[[4.5,69.68],[5.5,23.22]],"id":52385888},{"atb":[[4,81.3],[5,26.13]],"id":52385882},{"atb":[[9.8,27.71],[14.5,7.74]],"id":52385884},{"atb":[[3.95,82.67],[4.9,26.8]],"id":52385895},{"atb":[[6.4,19.35],[5.2,58.07]],"id":52385897},{"atb":[[9.2,29.74],[13,8.71]],"id":52385891},{"atb":[[20,5.5],[15,17.42]],"id":52385893},{"atb":[[16,6.96],[11,24.39]],"id":52385903},{"atb":[[18.5,5.97],[13.5,19.51]],"id":52385905},{"atb":[[20,5.5],[15,17.42]],"id":52385901}],"con":true,"img":false}]}
{"op":"mcm","clk":"11450426499","pt":1717321913810,"mc":[{"id":"1.229554922","rc":[{"atb":[[190,0.55],[95,2.59]],"id":52385908},{"atb":[[17.5,14.77],[25,4.35]],"id":52385918},{"atb":[[550,0.44],[650,0.16]],"id":52385920},{"atb":[[200,0.52],[100,2.46]],"id":52385927},{"atb":[[550,0.44],[650,0.16]],"id":52385929},{"atb":[[20,12.83],[30,6.31]],"id":52385923},{"atb":[[17.5,6.33],[12.5,21.2]],"id":52385925},{"atb":[[17.5,12.68],[12.5,21.2]],"id":52385937},{"atb":[[4.5,69.68],[5.5,23.22]],"id":52385931},{"atb":[[5.6,53.02],[7.2,16.86]],"id":52385933},{"atb":[[550,0.44],[650,0.16]],"id":52385907},{"atb":[[16,6.96],[11,24.39]],"id":52385909},{"atb":[[48,2.22],[29,8.71]],"id":52385919},{"atb":[[20,12.83],[30,3.6]],"id":52385917},{"atb":[[16,16.26],[22,4.97]],"id":52385926},{"atb":[[550,0.44],[650,0.16]],"id":52385922},{"atb":[[18.5,5.97],[13.5,19.51]],"id":52385924},{"atb":[[9.8,27.71],[14.5,7.74]],"id":52385934},{"atb":[[17.5,21.12],[25,6.53]],"id":52385936},{"atb":[[18.5,5.97],[13.5,19.51]],"id":52385930},{"atb":[[4,81.3],[5,26.13]],"id":52385932}],"con":true,"img":false}]}
{"op":"mcm","clk":"11450426676","pt":1717321915793,"mc":[{"id":"1.229554922","rc":[{"atb":[[7.2,0],[9.2,0],[6.2,0],[8.2,0]],"id":52385889},{"atb":[[70,0],[38,0],[29,0]],"id":52385925},{"atb":[[140,0],[70,0],[95,0],[48,0]],"id":52385900},{"atb":[[70,0],[38,0],[48,0],[29,0]],"id":52385909},{"atb":[[12,0],[9.8,0]],"id":52385897},{"atb":[[36,0],[19,0],[23,0],[28,0]],"id":52385891},{"atb":[[65,0],[36,0],[90,0],[46,0]],"id":52385905},{"atb":[[9,0],[10,0],[7,0]],"id":52385932}],"con":true,"img":false}]}
{"op":"mcm","clk":"11450426690","pt":1717321916011,"mc":[{"id":"1.229554922","rc":[{"atb":[[12.5,0],[13,8.33]],"id":52385909},{"atb":[[19,5.56],[23,0]],"id":52385905}],"con":true,"img":false}]}
{"op":"mcm","clk":"11450426712","pt":1717321916212,"mc":[{"id":"1.229554922","rc":[{"atb":[[8,0]],"id":52385932}],"con":true,"img":false}]}
{"op":"mcm","clk":"11450426737","pt":1717321916485,"mc":[{"id":"1.229554922","rc":[{"atb":[[7.2,12.66],[9.2,3.19],[6.2,20.12],[8.2,7.27]],"id":52385889},{"atb":[[75,0.36],[40,2.01],[30,3.61]],"id":52385925},{"atb":[[140,0.19],[70,1.14],[95,0.55],[48,2.23]],"id":52385900},{"atb":[[70,0.38],[38,2.12],[48,1.11],[29,3.74]],"id":52385909},{"atb":[[12,4.76],[9.8,8.92]],"id":52385897},{"atb":[[36,0.75],[19,5.81],[23,3.57],[28,1.94]],"id":52385891},{"atb":[[65,0.82],[36,2.99],[90,0.29],[46,1.74]],"id":52385905},{"atb":[[6.8,18.04],[9.8,2.97],[8.8,6.71]],"id":52385932}],"con":true,"img":false}]}
{"op":"mcm","clk":"11450426764","pt":1717321916891,"mc":[{"id":"1.229554922","rc":[{"atb":[[7.8,11.54]],"id":52385932}],"con":true,"img":false}]}
{"op":"mcm","clk":"11450427426","pt":1717321923507,"mc":[{"id":"1.229554922","rc":[{"atb":[[140,0],[70,0],[95,0],[48,0]],"id":52385900},{"atb":[[6.8,0],[9.8,0],[8.8,0]],"id":52385932}],"con":true,"img":false}]}
{"op":"mcm","clk":"11450427502","pt":1717321924188,"mc":[{"id":"1.229554922","rc":[{"atb":[[130,0.2],[65,1.22],[90,0.59],[46,2.32]],"id":52385900},{"atb":[[7.2,16.88],[9.2,6.38],[10.5,2.75]],"id":52385932}],"con":true,"img":false}]}
{"op":"mcm","clk":"11450428781","pt":1717321936379,"mc":[{"id":"1.229554922","rc":[{"atb":[[9.6,0],[8.6,0],[11.5,0],[14,0]],"id":52385890},{"atb":[[9.2,0],[10.5,0],[13,0],[15.5,0]],"id":52385933},{"atb":[[75,0],[40,0],[100,0],[50,0]],"id":52385886},{"atb":[[9.6,0],[8.6,0],[11.5,0],[7.6,0]],"id":52385882},{"atb":[[9.6,0],[8.6,0],[11.5,0],[7.6,0]],"id":52385895}],"con":true,"img":false}]}
{"op":"mcm","clk":"11450428793","pt":1717321936486,"mc":[{"id":"1.229554922","rc":[{"atb":[[20,0],[21,5]],"id":52385886}],"con":true,"img":false}]}
{"op":"mcm","clk":"11450428864","pt":1717321937118,"mc":[{"id":"1.229554922","rc":[{"atb":[[8,14.95],[9,9.81],[10,5.81],[12.5,2.28]],"id":52385890},{"atb":[[12,4.76],[9.8,8.92],[8.8,13.41],[14.5,1.94]],"id":52385933},{"atb":[[70,0.76],[38,2.83],[95,0.28],[48,1.67]],"id":52385886},{"atb":[[11,2.62],[7.4,16.35],[8.4,10.61],[9.4,6.23]],"id":52385882},{"atb":[[6.8,18.04],[9.8,2.97],[8.8,6.71],[7.8,11.54]],"id":52385895}],"con":true,"img":false}]}
{"op":"mcm","clk":"11450429777","pt":1717321946631,"mc":[{"id":"1.229554922","rc":[{"atb":[[8,0],[9,0],[10,0],[12.5,0]],"id":52385890},{"atb":[[12,0],[9.8,0],[8.8,0],[14.5,0]],"id":52385933},{"atb":[[70,0],[38,0],[95,0],[48,0]],"id":52385886},{"atb":[[6.8,0],[9.8,0],[8.8,0],[7.8,0]],"id":52385895},{"atb":[[7.2,0],[9.2,0],[10.5,0]],"id":52385932}],"con":true,"img":false}]}
{"op":"mcm","clk":"11450429842","pt":1717321947312,"mc":[{"id":"1.229554922","rc":[{"atb":[[12,2.38],[9.8,5.94],[8.8,10.06],[7.8,15.39]],"id":52385890},{"atb":[[9,13.08],[10,8.72],[12.5,4.55],[15,1.87]],"id":52385933},{"atb":[[75,0.71],[40,2.68],[100,0.27],[50,1.6]],"id":52385886},{"atb":[[7.2,12.66],[9.2,3.19],[6.2,20.12],[8.2,7.27]],"id":52385895},{"atb":[[6.8,18.04],[9.8,2.97],[8.8,6.71]],"id":52385932}],"con":true,"img":false}]}
{"op":"mcm","clk":"11450430391","pt":1717321953940,"mc":[{"id":"1.229554922","rc":[{"atb":[[9,0],[10,0],[12.5,0],[15,0]],"id":52385933},{"atb":[[75,0],[40,0],[100,0],[50,0]],"id":52385886}],"con":true,"img":false}]}
{"op":"mcm","clk":"11450430454","pt":1717321954613,"mc":[{"id":"1.229554922","rc":[{"atb":[[12,4.76],[9.8,8.92],[8.8,13.41],[14.5,1.94]],"id":52385933}],"con":true,"img":false}]}
{"op":"mcm","clk":"11450430466","pt":1717321954726,"mc":[{"id":"1.229554922","rc":[{"atb":[[70,0.76],[38,2.83],[95,0.28],[48,1.67]],"id":52385886}],"con":true,"img":false}]}
{"op":"mcm","clk":"11450437628","pt":1717322040647,"mc":[{"id":"1.229554922","rc":[{"atb":[[28,3.37],[30,2.78]],"id":52385887},{"atl":[[95,4.4],[110,3.88]],"id":52385887},{"atb":[[180,3.26],[200,4.15]],"id":52385920},{"atb":[[7.4,3.31],[7.8,2.72]],"id":52385889},{"atl":[[16,3.53],[17,3.37]],"id":52385889},{"atb":[[10.5,3.71],[9.8,2.92]],"id":52385883},{"atl":[[38,3.88],[42,3.33]],"id":52385883},{"atb":[[22,3.24],[24,6.15]],"id":52385894},{"atl":[[70,4.24],[80,3.73]],"id":52385894},{"atb":[[10.5,4.32],[11.5,3.1]],"id":52385896},{"atl":[[32,4.19],[36,4.55]],"id":52385896},{"atb":[[180,3.35],[200,3.88]],"id":52385929},{"atb":[[9.2,4.65],[8.8,14.47]],"id":52385890},{"atl":[[27,3.7],[29,2.66]],"id":52385890},{"atb":[[34,3.68],[30,4.08]],"id":52385898},{"atl":[[130,3.12],[110,3.84]],"id":52385898},{"atb":[[46,4.03],[50,4.42]],"id":52385886},{"atl":[[180,3.34],[200,2.67]],"id":52385886},{"atb":[[9,2.96],[8.6,3.6]],"id":52385888},{"atl":[[28,3.08],[30,3.41]],"id":52385888},{"atb":[[8.2,4.53],[7.8,4.03]],"id":52385882},{"atl":[[18.5,3.74],[19.5,2.94]],"id":52385882},{"atl":[[19,2.65],[20,4.41]],"id":52385895},{"atb":[[21,4.14],[23,7.05]],"id":52385891},{"atl":[[70,3.56],[60,2.88]],"id":52385891},{"atb":[[40,5.58],[44,3.24]],"id":52385924},{"atl":[[280,4.04],[300,2.91]],"id":52385924},{"atb":[[38,3.4],[42,6.25]],"id":52385893},{"atl":[[130,2.85],[150,3.1]],"id":52385893},{"atb":[[24,6.31],[26,4.45]],"id":52385934},{"atl":[[70,3.6],[80,3.55]],"id":52385934},{"atb":[[46,4.47],[50,2.87]],"id":52385936},{"atl":[[160,2.78],[180,3.23]],"id":52385936},{"atl":[[17,4.26],[18,2.72]],"id":52385932},{"atb":[[34,4.5],[30,4.06]],"id":52385901},{"atl":[[140,2.65],[160,4.2]],"id":52385901}],"con":true,"img":false}]}
{"op":"mcm","clk":"11450437635","pt":1717322040750,"mc":[{"id":"1.229554922","rc":[{"atb":[[130,4.96],[110,3.08]],"id":52385908},{"atl":[[850,2.95],[870,4.6]],"id":52385908},{"atb":[[90,3.06],[100,3.32]],"id":52385918},{"atl":[[600,3.46],[620,4.69]],"id":52385918},{"atb":[[140,4.19],[120,3.6]],"id":52385927},{"atl":[[970,4.39]],"id":52385927},{"atb":[[95,4.4],[110,3.89]],"id":52385923},{"atl":[[680,4.12],[700,4.67]],"id":52385923},{"atb":[[38,2.76],[42,3.63]],"id":52385925},{"atl":[[260,4.01],[240,3.19]],"id":52385925},{"atb":[[10,2.8],[11,2.71]],"id":52385902},{"atl":[[34,3.59],[38,3.2]],"id":52385902},{"atb":[[34,6.69],[30,4.66]],"id":52385904},{"atl":[[170,3.63],[190,4.32]],"id":52385904},{"atb":[[23,2.69],[25,6.12]],"id":52385937},{"atl":[[90,4.67],[100,4.53]],"id":52385937},{"atb":[[8.8,4.08],[8.4,4.36]],"id":52385931},{"atl":[[20,4.17],[22,3.59]],"id":52385931},{"atb":[[70,4.67],[80,3.57]],"id":52385900},{"atl":[[260,3.78],[240,2.73]],"id":52385900},{"atb":[[10.5,4.64],[9.8,12.21]],"id":52385933},{"atl":[[34,4.16],[38,4.14]],"id":52385933},{"atb":[[170,3.96],[190,2.78]],"id":52385907},{"atb":[[34,4.49],[38,5.98]],"id":52385909},{"atl":[[190,4.33],[210,3.92]],"id":52385909},{"atb":[[100,4.65],[120,2.77]],"id":52385919},{"atl":[[860,2.88],[880,3.98]],"id":52385919},{"atb":[[25,3.98],[27,3.09]],"id":52385884},{"atl":[[80,3.09],[90,4.14]],"id":52385884},{"atb":[[95,2.67],[110,4.61]],"id":52385917},{"atl":[[690,4.26],[710,3.31]],"id":52385917},{"atb":[[65,3.03],[55,3.41]],"id":52385926},{"atl":[[350,3.22],[370,4.6]],"id":52385926},{"atb":[[10.5,2.88],[9.8,11.74]],"id":52385897},{"atl":[[27,3.93],[29,3.66]],"id":52385897},{"atb":[[200,4.61],[220,3.79]],"id":52385922},{"atb":[[34,3.56],[38,4.93]],"id":52385903},{"atl":[[200,2.8],[220,4.62]],"id":52385903},{"atb":[[46,4.43],[50,3.18]],"id":52385905},{"atl":[[260,4.45],[240,4.47]],"id":52385905},{"atb":[[46,3.03],[50,2.87]],"id":52385930},{"atl":[[280,3.33],[300,3.23]],"id":52385930}],"con":true,"img":false}]}
{"op":"mcm","clk":"11450437643","pt":1717322040852,"mc":[{"id":"1.229554922","rc":[{"atl":[[350,2],[720,0]],"id":52385887},{"atl":[[330,0],[40,2.56]],"id":52385889},{"atl":[[560,0],[170,2]],"id":52385883},{"atl":[[600,0],[220,2]],"id":52385894},{"atl":[[90,2],[460,0]],"id":52385896},{"atl":[[120,2],[510,0]],"id":52385890},{"atl":[[820,0],[450,2]],"id":52385898},{"atl":[[120,2],[510,0]],"id":52385888},{"atl":[[65,2],[420,0]],"id":52385882},{"atl":[[70,2],[430,0]],"id":52385895},{"atl":[[620,0],[230,2]],"id":52385891},{"atl":[[530,2],[890,0]],"id":52385924},{"atl":[[300,2],[680,0]],"id":52385934},{"atl":[[380,0],[48,2.13]],"id":52385932},{"atl":[[680,0],[420,2]],"id":52385901}],"con":true,"img":false}]}
{"op":"mcm","clk":"11450437654","pt":1717322040961,"mc":[{"id":"1.229554922","rc":[{"atl":[[870,0],[510,2]],"id":52385925},{"atl":[[520,0],[150,2]],"id":52385902},{"atl":[[830,0],[470,2]],"id":52385904},{"atl":[[570,0],[250,2]],"id":52385937},{"atl":[[410,0],[55,2]],"id":52385931},{"atl":[[520,0],[150,2]],"id":52385933},{"atl":[[650,2],[1000,0]],"id":52385909},{"atl":[[750,0],[370,2]],"id":52385884},{"atl":[[850,2],[1000,0]],"id":52385926},{"atl":[[80,2],[450,0]],"id":52385897},{"atl":[[850,0],[490,2]],"id":52385903},{"atl":[[760,2],[1000,0]],"id":52385905},{"atl":[[650,2],[980,0]],"id":52385930}],"con":true,"img":false}]}
{"op":"mcm","clk":"11450437669","pt":1717322041070,"mc":[{"id":"1.229554922","rc":[{"atb":[[7.2,16.9],[6.8,4.25]],"id":52385889},{"atb":[[8.4,3.44]],"id":52385890},{"atb":[[10.5,4],[11.5,6.28]],"id":52385902},{"atb":[[32,3.49],[29,3.47]],"id":52385904},{"atb":[[75,4.15],[85,4.19]],"id":52385900},{"atb":[[32,2.74],[36,3.51]],"id":52385909},{"atb":[[48,5.57],[55,4.43]],"id":52385886},{"atb":[[130,4.03],[110,3.46]],"id":52385919},{"atb":[[8.8,13.82],[8.4,3.59]],"id":52385888},{"atb":[[7.4,20.79]],"id":52385882},{"atb":[[24,2.63],[26,2.68]],"id":52385884},{"atb":[[70,4.36],[60,2.71]],"id":52385926},{"atb":[[9.6,4.27],[10,3.96]],"id":52385897},{"atb":[[20,3.17],[22,3.6]],"id":52385891},{"atb":[[32,4.67],[36,3.32]],"id":52385903},{"atb":[[48,4.23],[55,4.44]],"id":52385936}],"con":true,"img":false}]}
{"op":"mcm","clk":"11450437702","pt":1717322041385,"mc":[{"id":"1.229554922","rc":[{"atb":[[22,0],[30,2.36]],"id":52385908},{"atb":[[3.55,32.7],[3.05,0]],"id":52385889},{"atb":[[5.1,0],[6,20]],"id":52385883},{"atb":[[5.8,0],[6.8,11.32]],"id":52385894},{"atb":[[3.8,0],[4.2,31.25]],"id":52385896},{"atb":[[4.6,27.56],[4.1,0]],"id":52385890},{"atb":[[9,0],[10,7.24]],"id":52385925},{"atb":[[4.4,0],[5.4,22.73]],"id":52385902},{"atb":[[9,8.06],[7,0]],"id":52385904},{"atb":[[5.7,0],[7,10.48]],"id":52385937},{"atb":[[7.2,0],[8.4,11.39]],"id":52385898},{"atb":[[3.85,26.19],[3.5,0]],"id":52385931},{"atb":[[23,0],[29,3.57]],"id":52385900},{"atb":[[4.9,0],[5.4,22.73]],"id":52385933},{"atb":[[16,13.63],[13,0]],"id":52385909},{"atb":[[32,3.23],[25,0]],"id":52385919},{"atb":[[4.8,26.32],[4.1,0]],"id":52385888},{"atb":[[3.6,0],[3.95,31.72]],"id":52385882},{"atb":[[8,9.52],[6.4,0]],"id":52385884},{"atb":[[25,0],[29,5.44]],"id":52385926},{"atb":[[4.1,21.04],[3.75,0]],"id":52385897},{"atb":[[32,3.23],[25,4.36]],"id":52385922},{"atb":[[9,0],[10.5,7.24]],"id":52385924},{"atb":[[11.5,0],[14.5,7.41]],"id":52385893},{"atb":[[7.6,0],[9.4,7.48]],"id":52385903},{"atb":[[18,5.88],[14,0]],"id":52385936},{"atb":[[19,0],[26,4]],"id":52385905},{"atb":[[7.2,0],[8.2,11.54]],"id":52385901}],"con":true,"img":false}]}
{"op":"mcm","clk":"11450437804","pt":1717322042369,"mc":[{"id":"1.229554922","rc":[{"atb":[[7.2,12.66],[6.8,0]],"id":52385889},{"atb":[[8.4,0]],"id":52385890},{"atb":[[11.5,2.49]],"id":52385902},{"atb":[[29,0],[30,0]],"id":52385904},{"atb":[[85,0]],"id":52385900},{"atb":[[32,0],[34,0]],"id":52385909},{"atb":[[55,0]],"id":52385886},{"atb":[[130,0]],"id":52385919},{"atb":[[8.6,0],[8.4,0]],"id":52385888},{"atb":[[7.4,16.35]],"id":52385882},{"atb":[[24,0],[25,0]],"id":52385884},{"atb":[[70,0]],"id":52385926},{"atb":[[9.6,0],[9.8,8.92]],"id":52385897},{"atb":[[20,0],[21,0]],"id":52385891},{"atb":[[32,0],[34,0]],"id":52385903},{"atb":[[55,0]],"id":52385936}],"con":true,"img":false}]}
{"op":"mcm","clk":"11450437813","pt":1717322042474,"mc":[{"id":"1.229554922","rc":[{"atb":[[7.4,0],[7.8,0]],"id":52385889},{"atb":[[9.2,0]],"id":52385890},{"atb":[[10,0],[10.5,0]],"id":52385902},{"atb":[[34,2.38]],"id":52385904},{"atb":[[70,0],[75,0]],"id":52385900},{"atb":[[38,2.12]],"id":52385909},{"atb":[[46,0],[48,1.67]],"id":52385886},{"atb":[[100,0],[110,0]],"id":52385919},{"atb":[[9,0]],"id":52385888},{"atb":[[8.2,0]],"id":52385882},{"atb":[[27,0]],"id":52385884},{"atb":[[55,0],[60,0]],"id":52385926},{"atb":[[10.5,0]],"id":52385897},{"atb":[[23,3.57]],"id":52385891},{"atb":[[38,2.12]],"id":52385903},{"atb":[[46,0],[48,0]],"id":52385936}],"con":true,"img":false}]}
{"op":"mcm","clk":"11450438114","pt":1717322045945,"mc":[{"id":"1.229554922","rc":[{"atb":[[7.2,15.56],[6.8,4.32]],"id":52385889},{"atb":[[11.5,6.11]],"id":52385902},{"atb":[[55,4.61]],"id":52385886},{"atb":[[130,2.69]],"id":52385919},{"atb":[[70,3.2]],"id":52385926},{"atb":[[55,4.01]],"id":52385936}],"con":true,"img":false}]}
{"op":"mcm","clk":"11450438126","pt":1717322046048,"mc":[{"id":"1.229554922","rc":[{"atb":[[85,3.96]],"id":52385900}],"con":true,"img":false}]}
{"op":"mcm","clk":"11450438554","pt":1717322051039,"mc":[{"id":"1.229554922","rc":[{"atb":[[8.4,2.89]],"id":52385890},{"atb":[[29,4.63]],"id":52385904},{"atb":[[32,3.91]],"id":52385909},{"atb":[[8.4,3.9]],"id":52385888},{"atb":[[7.4,20.95]],"id":52385882},{"atb":[[24,3.47]],"id":52385884},{"atb":[[9.6,4.12]],"id":52385897},{"atb":[[20,3.18]],"id":52385891},{"atb":[[32,3.94]],"id":52385903}],"con":true,"img":false}]}
{"op":"mcm","clk":"11450439792","pt":1717322064408,"mc":[{"id":"1.229554922","rc":[{"atb":[[34,3.03],[27,0]],"id":52385918},{"atb":[[8.8,11.58],[7,0]],"id":52385887},{"atb":[[38,4.82],[29,3.74]],"id":52385920},{"atb":[[34,2],[27,0]],"id":52385927},{"atb":[[36,2.86],[28,0]],"id":52385929},{"atb":[[36,2.86],[28,0]],"id":52385923},{"atb":[[10,0],[14.5,7.41]],"id":52385925},{"atb":[[6.2,19.23],[5.4,0]],"id":52385902},{"atb":[[8.2,10.48],[7,0]],"id":52385937},{"atb":[[10,11.11],[8.4,0]],"id":52385898},{"atb":[[6,20],[5.4,0]],"id":52385933},{"atb":[[36,2.86],[28,0]],"id":52385907},{"atl":[[680,2],[780,0]],"id":52385886},{"atl":[[320,2],[370,0]],"id":52385884},{"atb":[[34,3.03],[27,0]],"id":52385917},{"atl":[[850,0]],"id":52385926},{"atb":[[6.2,0],[7.4,11.32]],"id":52385891},{"atb":[[10.5,0],[15,7.14]],"id":52385924},{"atl":[[560,2],[670,0]],"id":52385893},{"atb":[[8.2,11.32],[6.6,0]],"id":52385934},{"atl":[[640,2],[710,0]],"id":52385936},{"atb":[[25,4.17],[14,0]],"id":52385930},{"atb":[[8.2,0],[11,10]],"id":52385901}],"con":true,"img":false}]}
{"op":"mcm","clk":"11450439800","pt":1717322064451,"mc":[{"id":"1.229554922","rc":[{"atb":[[21,0],[26,4]],"id":52385886},{"atl":[[710,2],[760,0]],"id":52385905}],"con":true,"img":false}]}
{"op":"mcm","clk":"11450439821","pt":1717322064664,"mc":[{"id":"1.229554922","rc":[{"atb":[[130,0],[140,3.11],[180,0],[90,0],[230,0]],"id":52385908},{"atb":[[38,0],[19.5,0],[24,0],[25,2.71],[29,0]],"id":52385894},{"atb":[[270,0],[140,0],[160,3.84],[170,0],[220,0],[120,2.72]],"id":52385927},{"atb":[[200,0],[210,4.22]],"id":52385929},{"atl":[[26,4.21],[27,0]],"id":52385890},{"atl":[[34,0],[36,4.39]],"id":52385902},{"atb":[[25,2.18],[28,2.8]],"id":52385937},{"atl":[[34,0],[36,3.32]],"id":52385933},{"atl":[[170,4.18],[180,0]],"id":52385886},{"atl":[[26,3.32],[28,0]],"id":52385888},{"atb":[[11,0],[7.4,4.59],[8.4,0],[9.4,0]],"id":52385882},{"atl":[[18,3.28],[19,0]],"id":52385895},{"atb":[[44,0],[50,5.6]],"id":52385924},{"atl":[[130,0],[120,3.17]],"id":52385893},{"atb":[[34,0],[42,2.8]],"id":52385901}],"con":true,"img":false}]}
{"op":"mcm","clk":"11450439829","pt":1717322064770,"mc":[{"id":"1.229554922","rc":[{"atl":[[27,3.88]],"id":52385888},{"atb":[[40,3.93]],"id":52385901}],"con":true,"img":false}]}
{"op":"mcm","clk":"11450439891","pt":1717322065388,"mc":[{"id":"1.229554922","rc":[{"atb":[[270,0.1],[170,0.47],[220,0.24],[120,0.88]],"id":52385908},{"atb":[[40,0.67],[20,5.51],[25,5.99],[30,1.81]],"id":52385894},{"atb":[[290,0.18],[340,0.08],[190,0.55],[240,0.33]],"id":52385927},{"atb":[[8,11.21],[9,6.54],[10,2.91],[7,17.44]],"id":52385882}],"con":true,"img":false}]}
{"op":"mcm","clk":"11450440096","pt":1717322067213,"mc":[{"id":"1.229554922","rc":[{"atl":[[26,0],[30,0]],"id":52385888},{"atb":[[42,0]],"id":52385901}],"con":true,"img":false}]}
{"op":"mcm","clk":"11450440893","pt":1717322074690,"mc":[{"id":"1.229554922","rc":[{"atb":[[140,3.32]],"id":52385927},{"atb":[[26,3.7]],"id":52385937},{"atl":[[19,4.37]],"id":52385895},{"atb":[[46,3.27]],"id":52385924}],"con":true,"img":false}]}
{"op":"mcm","clk":"11450440901","pt":1717322074793,"mc":[{"id":"1.229554922","rc":[{"atl":[[29,3.19]],"id":52385888},{"atb":[[36,3.95]],"id":52385901}],"con":true,"img":false}]}
{"op":"mcm","clk":"11450441266","pt":1717322078009,"mc":[{"id":"1.229554922","rc":[{"atb":[[120,0]],"id":52385927},{"atb":[[23,0]],"id":52385937},{"atl":[[20,0]],"id":52385895},{"atb":[[40,2.01]],"id":52385924},{"atb":[[30,0]],"id":52385901}],"con":true,"img":false}]}
{"op":"mcm","clk":"11450441299","pt":1717322078378,"mc":[{"id":"1.229554922","rc":[{"atb":[[3.8,32.7],[3.55,0]],"id":52385889},{"atb":[[11,7.24],[14.5,0]],"id":52385925},{"atl":[[830,2],[930,0]],"id":52385900},{"atl":[[600,2],[650,0]],"id":52385909},{"atl":[[790,2]],"id":52385926},{"atb":[[11.5,9.22],[15,0]],"id":52385924},{"atb":[[17.5,6.06],[25,0]],"id":52385930},{"atl":[[600,2],[650,0]],"id":52385930},{"atb":[[9,11],[11,0]],"id":52385901}],"con":true,"img":false}]}
{"op":"mcm","clk":"11450441328","pt":1717322078692,"mc":[{"id":"1.229554922","rc":[{"atb":[[270,0],[130,3.23],[140,0],[170,0],[220,0],[120,0]],"id":52385908},{"atb":[[40,0],[20,0],[24,4.64],[25,0],[30,0]],"id":52385894},{"atb":[[140,0],[290,0],[160,0],[340,0],[190,0],[240,0]],"id":52385927},{"atb":[[200,2.64],[210,0]],"id":52385929},{"atl":[[26,0],[27,2.76]],"id":52385890},{"atl":[[34,2.88],[36,0]],"id":52385902},{"atb":[[25,5.58],[26,0],[28,0]],"id":52385937},{"atl":[[34,2.94],[36,0]],"id":52385933},{"atl":[[170,0],[180,4.33]],"id":52385886},{"atl":[[27,0],[28,3.26]],"id":52385888},{"atl":[[18,0]],"id":52385895},{"atb":[[44,4.65],[46,0],[50,1.07]],"id":52385924},{"atl":[[130,4.27],[120,0]],"id":52385893},{"atb":[[34,4.38],[36,0],[40,0]],"id":52385901}],"con":true,"img":false}]}
{"op":"mcm","clk":"11450441410","pt":1717322079424,"mc":[{"id":"1.229554922","rc":[{"atb":[[130,3.85],[180,0.29],[90,1.18],[230,0.12]],"id":52385908},{"atb":[[38,0.71],[19.5,5.66],[24,8.06],[29,1.87]],"id":52385894},{"atb":[[270,0.1],[170,0.47],[220,0.24],[120,0.88]],"id":52385927}],"con":true,"img":false}]}
{"op":"mcm","clk":"11450441465","pt":1717322080034,"mc":[{"id":"1.229554922","rc":[{"atb":[[140,4.2],[120,4.34]],"id":52385927}],"con":true,"img":false}]}
{"op":"mcm","clk":"11450441880","pt":1717322084701,"mc":[{"id":"1.229554922","rc":[{"atl":[[20,4.2]],"id":52385895}],"con":true,"img":false}]}
{"op":"mcm","clk":"11450442195","pt":1717322088704,"mc":[{"id":"1.229554922","rc":[{"atb":[[23,3.32]],"id":52385937},{"atb":[[40,6.18]],"id":52385924},{"atb":[[30,4.01]],"id":52385901}],"con":true,"img":false}]}
{"op":"mcm","clk":"11450447183","pt":1717322149246,"mc":[{"id":"1.229554922","rc":[{"atb":[[70,0],[38,0],[95,0],[48,0]],"id":52385886}],"con":true,"img":false}]}
{"op":"mcm","clk":"11450447702","pt":1717322155649,"mc":[{"id":"1.229554922","rc":[{"atb":[[75,0.71],[40,2.68],[50,6.03],[100,0.27]],"id":52385886}],"con":true,"img":false}]}
{"op":"mcm","clk":"11450448479","pt":1717322164147,"mc":[{"id":"1.229554922","rc":[{"atb":[[85,0]],"id":52385900}],"con":true,"img":false}]}
{"op":"mcm","clk":"11450449377","pt":1717322174080,"mc":[{"id":"1.229554922","rc":[{"atb":[[70,2.97]],"id":52385900}],"con":true,"img":false}]}
{"op":"mcm","clk":"11450451530","pt":1717322198430,"mc":[{"id":"1.229554922","rc":[{"atb":[[6.2,0],[5.4,20.66]],"id":52385902},{"atb":[[8.2,0],[7,11.18]],"id":52385937},{"atb":[[10,0],[8.4,10.48]],"id":52385898},{"atl":[[830,0],[900,2]],"id":52385900},{"atb":[[6,0],[5.4,22.73]],"id":52385933},{"atl":[[680,0],[750,2]],"id":52385886},{"atl":[[790,0],[850,2]],"id":52385926},{"atl":[[560,0],[630,2]],"id":52385893}],"con":true,"img":false}]}
{"op":"mcm","clk":"11450452388","pt":1717322207445,"mc":[{"id":"1.229554922","rc":[{"atb":[[190,0],[95,0]],"id":52385908},{"atb":[[17.5,0],[25,0]],"id":52385918},{"atb":[[17.5,0],[12.5,0]],"id":52385887},{"atb":[[550,0],[650,0]],"id":52385920},{"atb":[[3.95,0],[4.9,0]],"id":52385889},{"atb":[[5.6,0],[7.2,0]],"id":52385883},{"atb":[[10,0],[15,0]],"id":52385894},{"atb":[[200,0],[100,0]],"id":52385927},{"atb":[[5.8,16.35],[7.6,3.97]],"id":52385896},{"atb":[[550,0],[650,0]],"id":52385929},{"atb":[[5.7,0],[4.7,0]],"id":52385890},{"atb":[[20,0],[30,2.71]],"id":52385923},{"atb":[[17.5,0],[12.5,0]],"id":52385925},{"atb":[[5.8,0],[7.6,15.85]],"id":52385902},{"atb":[[9.8,0],[14.5,0]],"id":52385904},{"atb":[[17.5,6.34],[12.5,0]],"id":52385937},{"atb":[[18,0],[13,0]],"id":52385898},{"atb":[[4.5,0],[5.5,0]],"id":52385931},{"atb":[[38,0],[24,0]],"id":52385900},{"atb":[[5.6,0],[7.2,0]],"id":52385933},{"atb":[[550,0],[650,0]],"id":52385907},{"atb":[[16,6.67],[11,0]],"id":52385909},{"atb":[[17.5,0],[25,0]],"id":52385886},{"atb":[[48,0],[29,0]],"id":52385919},{"atb":[[4.5,0],[5.5,0]],"id":52385888},{"atb":[[4,0],[5,0]],"id":52385882},{"atb":[[9.8,0],[14.5,0]],"id":52385884},{"atb":[[20,0],[30,0]],"id":52385917},{"atb":[[16,0],[22,0]],"id":52385926},{"atb":[[3.95,0],[4.9,0]],"id":52385895},{"atb":[[6.4,0],[5.2,0]],"id":52385897},{"atb":[[550,0],[650,0]],"id":52385922},{"atb":[[9.2,0],[13,0]],"id":52385891},{"atb":[[18.5,0],[13.5,0]],"id":52385924},{"atb":[[20,0],[15,0]],"id":52385893},{"atb":[[9.8,0],[14.5,0]],"id":52385934},{"atb":[[16,0],[11,0]],"id":52385903},{"atb":[[17.5,6.34],[25,2.18]],"id":52385936},{"atb":[[18.5,0],[13.5,0]],"id":52385905},{"atb":[[18.5,0],[13.5,0]],"id":52385930},{"atb":[[4,0],[5,0]],"id":52385932},{"atb":[[20,0],[15,0]],"id":52385901}],"con":true,"img":false}]}
{"op":"mcm","clk":"11450453191","pt":1717322215948,"mc":[{"id":"1.229554922","rc":[{"atl":[[16,0],[16.5,3.32]],"id":52385889},{"atb":[[75,4.6],[80,0]],"id":52385900},{"atb":[[1.45,34.88],[1.43,36.5]],"id":52385895},{"atb":[[1.45,34.88],[1.43,36.5]],"id":52385932}],"con":true,"img":false}]}
{"op":"mcm","clk":"11450454127","pt":1717322225837,"mc":[{"id":"1.229554922","rc":[{"atl":[[16.5,0],[16,3.25]],"id":52385889},{"atb":[[75,0],[80,4.44]],"id":52385900}],"con":true,"img":false}]}
{"op":"mcm","clk":"11450455186","pt":1717322236055,"mc":[{"id":"1.229554922","rc":[{"atb":[[190,0.55],[95,2.59]],"id":52385908},{"atb":[[17.5,14.77],[25,4.35]],"id":52385918},{"atb":[[17.5,6.33],[12.5,21.2]],"id":52385887},{"atb":[[550,0.44],[650,0.16]],"id":52385920},{"atb":[[3.95,82.67],[4.9,26.8]],"id":52385889},{"atb":[[5.6,53.02],[7.2,16.86]],"id":52385883},{"atb":[[10,27.1],[15,7.46]],"id":52385894},{"atb":[[200,0.52],[100,2.46]],"id":52385927},{"atb":[[5.8,67.17],[7.6,19.8]],"id":52385896},{"atb":[[550,0.44],[650,0.16]],"id":52385929},{"atb":[[5.7,22.24],[4.7,65.92]],"id":52385890},{"atb":[[20,12.83],[30,6.31]],"id":52385923},{"atb":[[17.5,6.33],[12.5,21.2]],"id":52385925},{"atb":[[5.8,50.81],[7.6,31.69]],"id":52385902},{"atb":[[9.8,27.71],[14.5,7.74]],"id":52385904},{"atb":[[17.5,12.68],[12.5,21.2]],"id":52385937},{"atb":[[18,6.14],[13,20.32]],"id":52385898},{"atb":[[4.5,69.68],[5.5,23.22]],"id":52385931},{"atb":[[38,2.82],[24,10.6]],"id":52385900},{"atb":[[5.6,53.02],[7.2,16.86]],"id":52385933},{"atb":[[550,0.44],[650,0.16]],"id":52385907},{"atb":[[16,13.63],[11,24.39]],"id":52385909},{"atb":[[17.5,14.77],[25,4.35]],"id":52385886},{"atb":[[48,2.22],[29,8.71]],"id":52385919},{"atb":[[4.5,69.68],[5.5,23.22]],"id":52385888},{"atb":[[4,81.3],[5,26.13]],"id":52385882},{"atb":[[9.8,27.71],[14.5,7.74]],"id":52385884},{"atb":[[20,12.83],[30,3.6]],"id":52385917},{"atb":[[16,16.26],[22,4.97]],"id":52385926},{"atb":[[3.95,82.67],[4.9,26.8]],"id":52385895},{"atb":[[6.4,19.35],[5.2,58.07]],"id":52385897},{"atb":[[550,0.44],[650,0.16]],"id":52385922},{"atb":[[9.2,29.74],[13,8.71]],"id":52385891},{"atb":[[18.5,5.97],[13.5,19.51]],"id":52385924},{"atb":[[20,5.5],[15,17.42]],"id":52385893},{"atb":[[9.8,27.71],[14.5,7.74]],"id":52385934},{"atb":[[16,6.96],[11,24.39]],"id":52385903},{"atb":[[17.5,21.12],[25,6.53]],"id":52385936},{"atb":[[18.5,5.97],[13.5,19.51]],"id":52385905},{"atb":[[18.5,5.97],[13.5,19.51]],"id":52385930},{"atb":[[4,81.3],[5,26.13]],"id":52385932},{"atb":[[20,5.5],[15,17.42]],"id":52385901}],"con":true,"img":false}]}
{"op":"mcm","clk":"11450470675","pt":1717322411239,"mc":[{"id":"1.229554922","rc":[{"atl":[[16,0],[16.5,2.91]],"id":52385889}],"con":true,"img":false}]}
{"op":"mcm","clk":"11450471137","pt":1717322415737,"mc":[{"id":"1.229554922","rc":[{"atl":[[16.5,0],[16,4]],"id":52385889}],"con":true,"img":false}]}
{"op":"mcm","clk":"11450485429","pt":1717322584325,"mc":[{"id":"1.229554922","rc":[{"atb":[[190,0],[95,0]],"id":52385908},{"atb":[[17.5,0],[25,0]],"id":52385918},{"atb":[[17.5,0],[12.5,0]],"id":52385887},{"atb":[[550,0],[650,0]],"id":52385920},{"atb":[[3.95,0],[4.9,0]],"id":52385889},{"atb":[[5.6,0],[7.2,0]],"id":52385883},{"atb":[[10,0],[15,0]],"id":52385894},{"atb":[[200,0],[100,0]],"id":52385927},{"atb":[[5.8,16.35],[7.6,3.97]],"id":52385896},{"atb":[[550,0],[650,0]],"id":52385929},{"atb":[[5.7,0],[4.7,0]],"id":52385890},{"atb":[[20,0],[30,2.71]],"id":52385923},{"atb":[[17.5,0],[12.5,0]],"id":52385925},{"atb":[[5.8,0],[7.6,15.85]],"id":52385902},{"atb":[[9.8,0],[14.5,0]],"id":52385904},{"atb":[[17.5,6.34],[12.5,0]],"id":52385937},{"atb":[[18,0],[13,0]],"id":52385898},{"atb":[[4.5,0],[5.5,0]],"id":52385931},{"atb":[[38,0],[24,0]],"id":52385900},{"atb":[[5.6,0],[7.2,0]],"id":52385933},{"atb":[[550,0],[650,0]],"id":52385907},{"atb":[[16,6.67],[11,0]],"id":52385909},{"atb":[[17.5,0],[25,0]],"id":52385886},{"atb":[[48,0],[29,0]],"id":52385919},{"atb":[[4.5,0],[5.5,0]],"id":52385888},{"atb":[[4,0],[5,0]],"id":52385882},{"atb":[[9.8,0],[14.5,0]],"id":52385884},{"atb":[[20,0],[30,0]],"id":52385917},{"atb":[[16,0],[22,0]],"id":52385926},{"atb":[[3.95,0],[4.9,0]],"id":52385895},{"atb":[[6.4,0],[5.2,0]],"id":52385897},{"atb":[[550,0],[650,0]],"id":52385922},{"atb":[[9.2,0],[13,0]],"id":52385891},{"atb":[[18.5,0],[13.5,0]],"id":52385924},{"atb":[[20,0],[15,0]],"id":52385893},{"atb":[[9.8,0],[14.5,0]],"id":52385934},{"atb":[[16,0],[11,0]],"id":52385903},{"atb":[[17.5,6.34],[25,2.18]],"id":52385936},{"atb":[[18.5,0],[13.5,0]],"id":52385905},{"atb":[[18.5,0],[13.5,0]],"id":52385930},{"atb":[[4,0],[5,0]],"id":52385932},{"atb":[[20,0],[15,0]],"id":52385901}],"con":true,"img":false}]}
{"op":"mcm","clk":"11450485559","pt":1717322585995,"mc":[{"id":"1.229554922","rc":[{"atl":[[16,0],[16.5,3.12]],"id":52385889},{"atb":[[75,3.1],[80,0]],"id":52385900}],"con":true,"img":false}]}
{"op":"mcm","clk":"11450486470","pt":1717322596013,"mc":[{"id":"1.229554922","rc":[{"atb":[[75,0],[80,3.57]],"id":52385900}],"con":true,"img":false}]}
{"op":"mcm","clk":"11450486978","pt":1717322601760,"mc":[{"id":"1.229554922","rc":[{"atb":[[190,0.55],[95,2.59]],"id":52385908},{"atb":[[17.5,14.77],[25,4.35]],"id":52385918},{"atb":[[17.5,6.33],[12.5,21.2]],"id":52385887},{"atb":[[550,0.44],[650,0.16]],"id":52385920},{"atb":[[3.95,82.67],[4.9,26.8]],"id":52385889},{"atb":[[5.6,53.02],[7.2,16.86]],"id":52385883},{"atb":[[10,27.1],[15,7.46]],"id":52385894},{"atb":[[200,0.52],[100,2.46]],"id":52385927},{"atb":[[5.8,67.17],[7.6,19.8]],"id":52385896},{"atb":[[550,0.44],[650,0.16]],"id":52385929},{"atb":[[5.7,22.24],[4.7,65.92]],"id":52385890},{"atb":[[20,12.83],[30,6.31]],"id":52385923},{"atb":[[17.5,6.33],[12.5,21.2]],"id":52385925},{"atb":[[5.8,50.81],[7.6,31.69]],"id":52385902},{"atb":[[9.8,27.71],[14.5,7.74]],"id":52385904},{"atb":[[17.5,12.68],[12.5,21.2]],"id":52385937},{"atb":[[18,6.14],[13,20.32]],"id":52385898},{"atb":[[4.5,69.68],[5.5,23.22]],"id":52385931},{"atb":[[38,2.82],[24,10.6]],"id":52385900},{"atb":[[5.6,53.02],[7.2,16.86]],"id":52385933},{"atb":[[550,0.44],[650,0.16]],"id":52385907},{"atb":[[16,13.63],[11,24.39]],"id":52385909},{"atb":[[17.5,14.77],[25,4.35]],"id":52385886},{"atb":[[48,2.22],[29,8.71]],"id":52385919},{"atb":[[4.5,69.68],[5.5,23.22]],"id":52385888},{"atb":[[4,81.3],[5,26.13]],"id":52385882},{"atb":[[9.8,27.71],[14.5,7.74]],"id":52385884},{"atb":[[20,12.83],[30,3.6]],"id":52385917},{"atb":[[16,16.26],[22,4.97]],"id":52385926},{"atb":[[3.95,82.67],[4.9,26.8]],"id":52385895},{"atb":[[6.4,19.35],[5.2,58.07]],"id":52385897},{"atb":[[550,0.44],[650,0.16]],"id":52385922},{"atb":[[9.2,29.74],[13,8.71]],"id":52385891},{"atb":[[18.5,5.97],[13.5,19.51]],"id":52385924},{"atb":[[20,5.5],[15,17.42]],"id":52385893},{"atb":[[9.8,27.71],[14.5,7.74]],"id":52385934},{"atb":[[16,6.96],[11,24.39]],"id":52385903},{"atb":[[17.5,21.12],[25,6.53]],"id":52385936},{"atb":[[18.5,5.97],[13.5,19.51]],"id":52385905},{"atb":[[18.5,5.97],[13.5,19.51]],"id":52385930},{"atb":[[4,81.3],[5,26.13]],"id":52385932},{"atb":[[20,5.5],[15,17.42]],"id":52385901}],"con":true,"img":false}]}
{"op":"mcm","clk":"11450486997","pt":1717322602026,"mc":[{"id":"1.229554922","rc":[{"atl":[[16.5,0],[16,4.53]],"id":52385889}],"con":true,"img":false}]}
{"op":"mcm","clk":"11450489173","pt":1717322625071,"mc":[{"id":"1.229554922","rc":[{"atl":[[16,0],[16.5,4.46]],"id":52385889}],"con":true,"img":false}]}
{"op":"mcm","clk":"11450489786","pt":1717322632484,"mc":[{"id":"1.229554922","rc":[{"atb":[[7.2,0],[9.2,0],[6.2,0],[8.2,0],[7.8,3.66]],"id":52385889},{"atb":[[12,0],[9.8,0],[8.8,0],[7.8,0],[9.4,2.82]],"id":52385890},{"atb":[[40,6.24],[42,0]],"id":52385925},{"atb":[[8.8,10.06]],"id":52385888},{"atb":[[7.2,0],[9.2,0],[6.2,0],[8.2,0]],"id":52385895},{"atb":[[12,0],[9.8,0]],"id":52385897},{"atb":[[210,3.13],[220,0]],"id":52385922},{"atb":[[26,0]],"id":52385934},{"atb":[[55,0]],"id":52385936},{"atb":[[50,0]],"id":52385905},{"atb":[[6.8,0],[9.8,0],[8.8,0]],"id":52385932}],"con":true,"img":false}]}
{"op":"mcm","clk":"11450489796","pt":1717322632587,"mc":[{"id":"1.229554922","rc":[{"atb":[[29,3.74],[30,0]],"id":52385887},{"atb":[[10.5,0],[11,9.49]],"id":52385883},{"atb":[[32,4.41],[34,0]],"id":52385898},{"atb":[[9,4.23],[8.8,0]],"id":52385931},{"atb":[[9,4.53]],"id":52385888},{"atb":[[8,0],[9,0],[10,0],[7.8,0],[7,0],[8.4,3.43]],"id":52385882},{"atb":[[70,0],[60,3.08]],"id":52385926},{"atb":[[10,0],[10.5,3.76]],"id":52385897},{"atb":[[25,2.63]],"id":52385934},{"atb":[[36,0],[38,5.68]],"id":52385903},{"atb":[[48,4.4]],"id":52385905},{"atb":[[44,5.62],[50,0]],"id":52385930}],"con":true,"img":false}]}
{"op":"mcm","clk":"11450489843","pt":1717322633160,"mc":[{"id":"1.229554922","rc":[{"atb":[[7.2,12.66],[9.2,3.19],[6.2,20.12],[8.2,7.27]],"id":52385889},{"atb":[[12,2.38],[9.8,5.94],[8.8,10.06],[7.8,15.39]],"id":52385890},{"atb":[[7.2,12.66],[9.2,3.19],[6.2,20.12],[8.2,7.27]],"id":52385895},{"atb":[[12,4.76],[9.8,8.92]],"id":52385897},{"atb":[[6.8,18.04],[9.8,2.97],[8.8,6.71]],"id":52385932}],"con":true,"img":false}]}
