{"op":"mcm","clk":"11449075391","pt":1717303241532,"mc":[{"id":"1.229554927","marketDefinition":{"bspMarket":false,"turnInPlayEnabled":false,"persistenceEnabled":false,"marketBaseRate":7.0,"eventId":"33318908","eventTypeId":"4339","numberOfWinners":1,"bettingType":"ODDS","marketType":"EXACTA","marketTime":"2024-06-02T10:41:00.000Z","suspendTime":"2024-06-02T10:41:00.000Z","bspReconciled":false,"complete":true,"inPlay":false,"crossMatching":true,"runnersVoidable":false,"numberOfActiveRunners":30,"betDelay":0,"status":"OPEN","runners":[{"status":"ACTIVE","sortPriority":1,"id":52385882,"name":"1 - 2"},{"status":"ACTIVE","sortPriority":2,"id":52385884,"name":"1 - 4"},{"status":"ACTIVE","sortPriority":3,"id":52385885,"name":"1 - 5"},{"status":"ACTIVE","sortPriority":4,"id":52385887,"name":"1 - 7"},{"status":"ACTIVE","sortPriority":5,"id":52385888,"name":"1 - 8"},{"status":"ACTIVE","sortPriority":6,"id":52385889,"name":"2 - 1"},{"status":"ACTIVE","sortPriority":7,"id":52385891,"name":"2 - 4"},{"status":"ACTIVE","sortPriority":8,"id":52385892,"name":"2 - 5"},{"status":"ACTIVE","sortPriority":9,"id":52385894,"name":"2 - 7"},{"status":"ACTIVE","sortPriority":10,"id":52385895,"name":"2 - 8"},{"status":"ACTIVE","sortPriority":11,"id":52385903,"name":"4 - 1"},{"status":"ACTIVE","sortPriority":12,"id":52385904,"name":"4 - 2"},{"status":"ACTIVE","sortPriority":13,"id":52385906,"name":"4 - 5"},{"status":"ACTIVE","sortPriority":14,"id":52385908,"name":"4 - 7"},{"status":"ACTIVE","sortPriority":15,"id":52385909,"name":"4 - 8"},{"status":"ACTIVE","sortPriority":16,"id":52385910,"name":"5 - 1"},{"status":"ACTIVE","sortPriority":17,"id":52385911,"name":"5 - 2"},{"status":"ACTIVE","sortPriority":18,"id":52385913,"name":"5 - 4"},{"status":"ACTIVE","sortPriority":19,"id":52385915,"name":"5 - 7"},{"status":"ACTIVE","sortPriority":20,"id":52385916,"name":"5 - 8"},{"status":"ACTIVE","sortPriority":21,"id":52385924,"name":"7 - 1"},{"status":"ACTIVE","sortPriority":22,"id":52385925,"name":"7 - 2"},{"status":"ACTIVE","sortPriority":23,"id":52385927,"name":"7 - 4"},{"status":"ACTIVE","sortPriority":24,"id":52385928,"name":"7 - 5"},{"status":"ACTIVE","sortPriority":25,"id":52385930,"name":"7 - 8"},{"status":"ACTIVE","sortPriority":26,"id":52385931,"name":"8 - 1"},{"status":"ACTIVE","sortPriority":27,"id":52385932,"name":"8 - 2"},{"status":"ACTIVE","sortPriority":28,"id":52385934,"name":"8 - 4"},{"status":"ACTIVE","sortPriority":29,"id":52385935,"name":"8 - 5"},{"status":"ACTIVE","sortPriority":30,"id":52385937,"name":"8 - 7"}],"regulators":["MR_INT"],"venue":"Murray Bridge","countryCode":"AU","discountAllowed":true,"timezone":"Australia/Adelaide","openDate":"2024-06-02T08:21:00.000Z","version":5962801948,"name":"Exacta","eventName":"Murray Bridge (AUS) 2nd Jun"},"rc":[],"con":true,"img":false}]}
{"op":"mcm","clk":"11449099382","pt":1717303849562,"mc":[{"id":"1.229554927","rc":[{"atb":[[3,121.95],[3.5,41.81]],"id":52385906},{"atb":[[10.5,11],[8.2,33.87]],"id":52385908},{"atb":[[16,6.96],[11,24.39]],"id":52385909},{"atb":[[550,0.44],[650,0.16]],"id":52385887},{"atb":[[550,0.44],[650,0.16]],"id":52385888},{"atb":[[48,2.22],[29,8.71]],"id":52385889},{"atb":[[90,1.17],[46,5.42]],"id":52385882},{"atb":[[50,2.13],[30,8.41]],"id":52385884},{"atb":[[19,13.55],[28,3.87]],"id":52385885},{"atb":[[9.2,29.74],[13,8.71]],"id":52385894},{"atb":[[18.5,5.97],[13.5,19.51]],"id":52385895},{"atb":[[4.3,73.9],[5.3,24.31]],"id":52385891},{"atb":[[4,34.84],[3.5,97.56]],"id":52385892},{"atb":[[32,3.37],[21,12.19]],"id":52385903},{"atb":[[5.1,25.49],[4.1,78.68]],"id":52385904}],"con":true,"img":false}]}
{"op":"mcm","clk":"11449099391","pt":1717303849717,"mc":[{"id":"1.229554927","rc":[{"atb":[[19.5,5.65],[14.5,18.06]],"id":52385910},{"atb":[[8.6,32.09],[11.5,9.95]],"id":52385916},{"atb":[[9.2,29.74],[13,8.71]],"id":52385927},{"atb":[[9.6,28.36],[14,8.04]],"id":52385925},{"atb":[[10,27.1],[15,7.46]],"id":52385935},{"atb":[[90,1.17],[46,5.42]],"id":52385937},{"atb":[[550,0.44],[650,0.16]],"id":52385931},{"atb":[[3.45,42.66],[2.98,123.18]],"id":52385911},{"atb":[[2.82,134.01],[3.05,50.98]],"id":52385913},{"atb":[[7.4,16.33],[5.7,51.89]],"id":52385915},{"atb":[[7.4,38.1],[9.4,12.44]],"id":52385928},{"atb":[[550,0.44],[650,0.16]],"id":52385924},{"atb":[[18.5,5.97],[13.5,19.51]],"id":52385934},{"atb":[[85,1.24],[44,5.67]],"id":52385930},{"atb":[[19.5,5.65],[14.5,18.06]],"id":52385932}],"con":true,"img":false}]}
{"op":"mcm","clk":"11449301261","pt":1717306860499,"mc":[{"id":"1.229554927","rc":[{"atb":[[38,1.41],[48,0.55],[24,4.55],[29,2.8]],"id":52385910},{"atb":[[4.8,27.54],[5.8,10.9],[5.3,18.25],[6.6,4.67]],"id":52385906},{"atb":[[17,6.54],[19.5,4.24],[24,2.28],[29,0.94]],"id":52385908},{"atb":[[530,0.1],[580,0.05],[430,0.25],[480,0.16]],"id":52385887},{"atb":[[80,0.66],[42,2.55],[110,0.24],[55,1.45]],"id":52385889},{"atb":[[16,5.23],[18.5,2.99],[22,1.25],[13.5,8.37]],"id":52385916},{"atb":[[140,0.19],[70,1.14],[95,0.55],[48,2.23]],"id":52385885},{"atb":[[32,0.84],[18,6.15],[21,3.92],[26,2.09]],"id":52385894},{"atb":[[34,1.59],[44,0.61],[22,4.98],[27,3.02]],"id":52385927},{"atb":[[5.6,17.06],[7.2,4.22],[5.1,25.52],[6.2,10.06]],"id":52385892},{"atb":[[36,1.5],[46,0.58],[23,4.76],[28,2.91]],"id":52385925},{"atb":[[32,2.53],[42,1.28],[26,4.19],[55,0.49]],"id":52385935},{"atb":[[11,2.62],[7.4,16.35],[8.4,10.61],[9.4,6.23]],"id":52385904},{"atb":[[130,0.61],[90,2.35],[180,0.29],[230,0.12]],"id":52385937},{"atb":[[630,0.17],[680,0.12],[730,0.07],[780,0.03]],"id":52385931},{"atb":[[5.1,6.38],[4.6,14.53],[4.1,25.32],[3.8,37.37]],"id":52385911},{"atb":[[3.95,26.6],[3.7,38.75],[4.9,6.71],[4.4,15.39]],"id":52385913},{"atb":[[38,1.41],[48,0.55],[24,4.55],[29,2.8]],"id":52385909},{"atb":[[800,0.13],[850,0.09],[900,0.06],[950,0.03]],"id":52385888},{"atb":[[130,0.61],[90,2.35],[180,0.29],[230,0.12]],"id":52385882},{"atb":[[11,5.23],[13.5,2.09],[8.4,14.14],[9.4,9.34]],"id":52385915},{"atb":[[160,0.33],[80,1.32],[210,0.13],[110,0.72]],"id":52385884},{"atb":[[40,1.34],[50,0.53],[25,4.36],[30,2.71]],"id":52385895},{"atb":[[16,6.97],[18.5,4.48],[22,2.49],[27,1]],"id":52385928},{"atb":[[9.6,6.08],[8.6,10.33],[11.5,2.49],[7.6,15.85]],"id":52385891},{"atb":[[270,0.39],[320,0.25],[370,0.14],[420,0.06]],"id":52385924},{"atb":[[32,3.37],[80,0.33],[42,1.92],[55,0.97]],"id":52385934},{"atb":[[75,0.71],[40,2.68],[100,0.27],[50,1.6]],"id":52385903},{"atb":[[150,0.35],[75,1.41],[200,0.13],[100,0.8]],"id":52385930},{"atb":[[34,3.17],[85,0.31],[44,1.83],[60,0.88]],"id":52385932}],"con":true,"img":false}]}
{"op":"mcm","clk":"11449312950","pt":1717307027651,"mc":[{"id":"1.229554927","rc":[{"atb":[[38,0],[48,0],[24,0],[29,0]],"id":52385910}],"con":true,"img":false}]}
{"op":"mcm","clk":"11449312997","pt":1717307028376,"mc":[{"id":"1.229554927","rc":[{"atb":[[36,1.5],[46,0.58],[23,4.76],[28,2.91]],"id":52385910}],"con":true,"img":false}]}
{"op":"mcm","clk":"11449438770","pt":1717309149763,"mc":[{"id":"1.229554927","rc":[{"atb":[[5.6,0],[7.2,0],[5.1,0],[6.2,0]],"id":52385892},{"atb":[[5.1,0],[4.6,0],[4.1,0],[3.8,0]],"id":52385911},{"atb":[[40,0],[50,0],[25,0],[30,0]],"id":52385895},{"atb":[[34,0],[85,0],[44,0],[60,0]],"id":52385932}],"con":true,"img":false}]}
{"op":"mcm","clk":"11449438775","pt":1717309149863,"mc":[{"id":"1.229554927","rc":[{"atb":[[16,0],[18.5,0],[22,0],[27,0]],"id":52385928}],"con":true,"img":false}]}
{"op":"mcm","clk":"11449438810","pt":1717309150433,"mc":[{"id":"1.229554927","rc":[{"atb":[[5.6,17.06],[7.2,4.22],[5.1,25.52],[6.2,10.06]],"id":52385892},{"atb":[[40,1.34],[50,0.53],[25,4.36],[30,2.71]],"id":52385895},{"atb":[[34,3.17],[85,0.31],[44,1.83],[60,0.88]],"id":52385932}],"con":true,"img":false}]}
{"op":"mcm","clk":"11449438816","pt":1717309150533,"mc":[{"id":"1.229554927","rc":[{"atb":[[3.85,36.72],[5.2,6.23],[4.2,24.52],[4.7,14.14]],"id":52385911},{"atb":[[16.5,6.75],[19,4.36],[23,2.38],[28,0.97]],"id":52385928}],"con":true,"img":false}]}
{"op":"mcm","clk":"11449477330","pt":1717309717162,"mc":[{"id":"1.229554927","rc":[{"atb":[[3.85,0],[5.2,0],[4.2,0],[4.7,0]],"id":52385911}],"con":true,"img":false}]}
{"op":"mcm","clk":"11449477370","pt":1717309717829,"mc":[{"id":"1.229554927","rc":[{"atb":[[5.1,6.38],[4.6,14.53],[4.1,25.32],[3.8,37.37]],"id":52385911}],"con":true,"img":false}]}
{"op":"mcm","clk":"11449546209","pt":1717310727222,"mc":[{"id":"1.229554927","rc":[{"atb":[[5.6,0],[7.2,0],[5.1,0],[6.2,0]],"id":52385892},{"atb":[[40,0],[50,0],[25,0],[30,0]],"id":52385895},{"atb":[[34,0],[85,0],[44,0],[60,0]],"id":52385932}],"con":true,"img":false}]}
{"op":"mcm","clk":"11449546254","pt":1717310727987,"mc":[{"id":"1.229554927","rc":[{"atb":[[42,1.28]],"id":52385895}],"con":true,"img":false}]}
{"op":"mcm","clk":"11449546270","pt":1717310728295,"mc":[{"id":"1.229554927","rc":[{"atb":[[5.7,16.69]],"id":52385892}],"con":true,"img":false}]}
{"op":"mcm","clk":"11449546277","pt":1717310728400,"mc":[{"id":"1.229554927","rc":[{"atb":[[6.4,9.69],[7.4,4.09],[5.2,24.91]],"id":52385892},{"atb":[[32,2.53],[26,4.19],[55,0.49]],"id":52385895},{"atb":[[65,0.82],[36,2.99],[90,0.29],[46,1.74]],"id":52385932}],"con":true,"img":false}]}
{"op":"mcm","clk":"11449574430","pt":1717311237755,"mc":[{"id":"1.229554927","rc":[{"atb":[[5.1,0],[4.1,0],[3.8,0]],"id":52385911}],"con":true,"img":false}]}
{"op":"mcm","clk":"11449574438","pt":1717311237860,"mc":[{"id":"1.229554927","rc":[{"atb":[[4.6,0]],"id":52385911}],"con":true,"img":false}]}
{"op":"mcm","clk":"11449574470","pt":1717311238471,"mc":[{"id":"1.229554927","rc":[{"atb":[[3.85,36.72],[5.2,6.23],[4.2,24.52]],"id":52385911}],"con":true,"img":false}]}
{"op":"mcm","clk":"11449574478","pt":1717311238573,"mc":[{"id":"1.229554927","rc":[{"atb":[[4.7,14.14]],"id":52385911}],"con":true,"img":false}]}
{"op":"mcm","clk":"11449600167","pt":1717311693782,"mc":[{"id":"1.229554927","rc":[{"atb":[[4.8,0],[5.8,0],[5.3,0],[6.6,0]],"id":52385906},{"atb":[[11,0],[7.4,0],[8.4,0],[9.4,0]],"id":52385904},{"atb":[[160,0],[80,0],[210,0],[110,0]],"id":52385884},{"atb":[[9.6,0],[8.6,0],[11.5,0],[7.6,0]],"id":52385891},{"atb":[[32,0],[80,0],[42,0],[55,0]],"id":52385934}],"con":true,"img":false}]}
{"op":"mcm","clk":"11449600207","pt":1717311694501,"mc":[{"id":"1.229554927","rc":[{"atb":[[12,2.38],[9.8,5.94],[8.8,10.06],[7.8,15.39]],"id":52385891}],"con":true,"img":false}]}
{"op":"mcm","clk":"11449600213","pt":1717311694605,"mc":[{"id":"1.229554927","rc":[{"atb":[[6.8,4.51],[4.9,26.83],[5.9,10.68],[5.4,17.84]],"id":52385906},{"atb":[[9.6,6.08],[8.6,10.33],[11.5,2.49],[7.6,15.85]],"id":52385904},{"atb":[[170,0.31],[85,1.25],[220,0.12],[120,0.66]],"id":52385884},{"atb":[[34,3.17],[85,0.31],[44,1.83],[60,0.88]],"id":52385934}],"con":true,"img":false}]}
{"op":"mcm","clk":"11449627911","pt":1717312255246,"mc":[{"id":"1.229554927","rc":[{"atb":[[3.85,0],[5.2,0],[4.2,0],[4.7,0]],"id":52385911}],"con":true,"img":false}]}
{"op":"mcm","clk":"11449627944","pt":1717312256070,"mc":[{"id":"1.229554927","rc":[{"atb":[[5.1,6.38],[4.6,14.53],[4.1,25.32],[3.8,37.37]],"id":52385911}],"con":true,"img":false}]}
{"op":"mcm","clk":"11449628008","pt":1717312257876,"mc":[{"id":"1.229554927","rc":[{"atb":[[6.8,0],[4.9,0],[5.9,0],[5.4,0]],"id":52385906},{"atb":[[16,0],[18.5,0],[22,0],[13.5,0]],"id":52385916},{"atb":[[9.6,0],[8.6,0],[11.5,0],[7.6,0]],"id":52385904},{"atb":[[3.95,0],[3.7,0],[4.9,0],[4.4,0]],"id":52385913},{"atb":[[16.5,0],[19,0],[23,0],[28,0]],"id":52385928},{"atb":[[12,0],[9.8,0],[8.8,0],[7.8,0]],"id":52385891}],"con":true,"img":false}]}
{"op":"mcm","clk":"11449628021","pt":1717312258082,"mc":[{"id":"1.229554927","rc":[{"atb":[[6.4,0],[7.4,0],[5.2,0],[5.7,0]],"id":52385892}],"con":true,"img":false}]}
{"op":"mcm","clk":"11449628044","pt":1717312258548,"mc":[{"id":"1.229554927","rc":[{"atb":[[4.8,27.54],[5.8,10.9],[5.3,18.25],[6.6,4.67]],"id":52385906},{"atb":[[17,3.27],[19.5,1.41],[12,9.51],[14.5,5.81]],"id":52385916},{"atb":[[11,2.62],[7.4,16.35],[8.4,10.61],[9.4,6.23]],"id":52385904},{"atb":[[2.92,54.5],[3.55,10.26],[3.3,22.75],[3.05,89.27]],"id":52385913},{"atb":[[16,6.97],[18.5,4.48],[22,2.49],[27,1]],"id":52385928},{"atb":[[9.6,6.08],[8.6,10.33],[11.5,2.49],[7.6,15.85]],"id":52385891}],"con":true,"img":false}]}
{"op":"mcm","clk":"11449628051","pt":1717312258755,"mc":[{"id":"1.229554927","rc":[{"atb":[[5.6,17.06],[7.2,4.22],[5.1,25.52],[6.2,10.06]],"id":52385892}],"con":true,"img":false}]}
{"op":"mcm","clk":"11449628167","pt":1717312261769,"mc":[{"id":"1.229554927","rc":[{"atb":[[5.1,0],[4.6,0],[4.1,0],[3.8,0]],"id":52385911}],"con":true,"img":false}]}
{"op":"mcm","clk":"11449628207","pt":1717312262439,"mc":[{"id":"1.229554927","rc":[{"atb":[[3.8,9.34],[3.55,20.52],[3.3,34.12],[3.05,51.04]],"id":52385911}],"con":true,"img":false}]}
{"op":"mcm","clk":"11449628483","pt":1717312271866,"mc":[{"id":"1.229554927","rc":[{"atb":[[530,0],[580,0],[430,0],[480,0]],"id":52385887},{"atb":[[130,0],[180,0],[90,1.17],[230,0]],"id":52385937},{"atb":[[270,0],[320,0],[370,0],[420,0]],"id":52385924},{"atb":[[150,0],[75,0],[200,0],[100,0]],"id":52385930}],"con":true,"img":false}]}
{"op":"mcm","clk":"11449628525","pt":1717312272695,"mc":[{"id":"1.229554927","rc":[{"atb":[[170,0.31],[85,1.25],[220,0.12],[120,0.66]],"id":52385937}],"con":true,"img":false}]}
{"op":"mcm","clk":"11449628759","pt":1717312278298,"mc":[{"id":"1.229554927","rc":[{"atb":[[520,0.1],[570,0.05],[420,0.25],[470,0.17]],"id":52385887},{"atb":[[300,0.26],[350,0.15],[400,0.07],[250,0.42]],"id":52385924},{"atb":[[140,0.38],[70,1.52],[190,0.14],[95,0.84]],"id":52385930}],"con":true,"img":false}]}
{"op":"mcm","clk":"11449661048","pt":1717313081655,"mc":[{"id":"1.229554927","rc":[{"atb":[[17,0],[19.5,0],[12,0],[14.5,0]],"id":52385916}],"con":true,"img":false}]}
{"op":"mcm","clk":"11449661083","pt":1717313082380,"mc":[{"id":"1.229554927","rc":[{"atb":[[17,3.27],[19.5,1.41],[12,9.51],[14.5,5.81]],"id":52385916}],"con":true,"img":false}]}
{"op":"mcm","clk":"11449662416","pt":1717313108596,"mc":[{"id":"1.229554927","rc":[{"atb":[[3.8,0],[3.55,0],[3.3,0],[3.05,0]],"id":52385911}],"con":true,"img":false}]}
{"op":"mcm","clk":"11449662462","pt":1717313109113,"mc":[{"id":"1.229554927","rc":[{"atb":[[2.92,0],[3.55,0],[3.3,0],[3.05,50.98]],"id":52385913}],"con":true,"img":false}]}
{"op":"mcm","clk":"11449662478","pt":1717313109324,"mc":[{"id":"1.229554927","rc":[{"atb":[[3,52.32],[3.25,34.88],[3.5,20.93],[3.75,9.51]],"id":52385911}],"con":true,"img":false}]}
{"op":"mcm","clk":"11449662518","pt":1717313109791,"mc":[{"id":"1.229554927","rc":[{"atb":[[2.9,55.07],[3,39.24],[3.25,23.25],[3.5,10.46]],"id":52385913}],"con":true,"img":false}]}
{"op":"mcm","clk":"11449686781","pt":1717313524549,"mc":[{"id":"1.229554927","rc":[{"atb":[[4.8,0],[5.8,0],[5.3,0],[6.6,0]],"id":52385906},{"atb":[[11,0],[7.4,0],[8.4,0],[9.4,0]],"id":52385904},{"atb":[[9.6,0],[8.6,0],[11.5,0],[7.6,0]],"id":52385891}],"con":true,"img":false}]}
{"op":"mcm","clk":"11449686790","pt":1717313524650,"mc":[{"id":"1.229554927","rc":[{"atb":[[5.6,0],[7.2,0],[5.1,0],[6.2,0]],"id":52385892}],"con":true,"img":false}]}
{"op":"mcm","clk":"11449686831","pt":1717313525215,"mc":[{"id":"1.229554927","rc":[{"atb":[[6.8,4.51],[4.9,26.83],[5.9,10.68],[5.4,17.84]],"id":52385906},{"atb":[[9.6,6.08],[8.6,10.33],[11.5,2.49],[7.6,15.85]],"id":52385904},{"atb":[[12,2.38],[9.8,5.94],[8.8,10.06],[7.8,15.39]],"id":52385891}],"con":true,"img":false}]}
{"op":"mcm","clk":"11449686840","pt":1717313525315,"mc":[{"id":"1.229554927","rc":[{"atb":[[6.4,9.69],[7.4,4.09],[5.2,24.91],[5.7,16.69]],"id":52385892}],"con":true,"img":false}]}
{"op":"mcm","clk":"11449699829","pt":1717313682171,"mc":[{"id":"1.229554927","rc":[{"atb":[[12,0],[9.8,0],[8.8,0],[7.8,0]],"id":52385891}],"con":true,"img":false}]}
{"op":"mcm","clk":"11449699922","pt":1717313683160,"mc":[{"id":"1.229554927","rc":[{"atb":[[9.6,6.08],[8.6,10.33],[11.5,2.49],[7.6,15.85]],"id":52385891}],"con":true,"img":false}]}
{"op":"mcm","clk":"11449733053","pt":1717314056148,"mc":[{"id":"1.229554927","rc":[{"atb":[[6.4,0],[7.4,0],[5.2,0],[5.7,0]],"id":52385892},{"atb":[[170,0],[85,0],[220,0],[120,0]],"id":52385937}],"con":true,"img":false}]}
{"op":"mcm","clk":"11449733129","pt":1717314056853,"mc":[{"id":"1.229554927","rc":[{"atb":[[5.6,17.06],[7.2,4.22],[5.1,25.52],[6.2,10.06]],"id":52385892},{"atb":[[130,0.61],[90,2.35],[180,0.29],[230,0.12]],"id":52385937}],"con":true,"img":false}]}
{"op":"mcm","clk":"11449741840","pt":1717314153703,"mc":[{"id":"1.229554927","rc":[{"atb":[[19.5,0],[14.5,0]],"id":52385910},{"atb":[[3,0],[3.5,0]],"id":52385906},{"atb":[[10.5,0],[8.2,0]],"id":52385908},{"atb":[[550,0],[650,0]],"id":52385887},{"atb":[[48,0],[29,0]],"id":52385889},{"atb":[[8.6,0],[11.5,0]],"id":52385916},{"atb":[[19,0],[28,0]],"id":52385885},{"atb":[[9.2,0],[13,0]],"id":52385894},{"atb":[[9.2,0],[13,0]],"id":52385927},{"atb":[[4,0],[3.5,0]],"id":52385892},{"atb":[[9.6,0],[14,0]],"id":52385925},{"atb":[[10,0],[15,0]],"id":52385935},{"atb":[[5.1,0],[4.1,0]],"id":52385904},{"atb":[[90,1.18],[46,0]],"id":52385937},{"atb":[[550,0],[650,0]],"id":52385931},{"atb":[[3.45,0],[2.98,0]],"id":52385911},{"atb":[[2.82,0],[3.05,0]],"id":52385913},{"atb":[[16,0],[11,0]],"id":52385909},{"atb":[[550,0],[650,0]],"id":52385888},{"atb":[[90,1.18],[46,0]],"id":52385882},{"atb":[[7.4,0],[5.7,0]],"id":52385915},{"atb":[[50,0],[30,0]],"id":52385884},{"atb":[[18.5,0],[13.5,0]],"id":52385895},{"atb":[[7.4,0],[9.4,0]],"id":52385928},{"atb":[[4.3,0],[5.3,0]],"id":52385891},{"atb":[[550,0],[650,0]],"id":52385924},{"atb":[[18.5,0],[13.5,0]],"id":52385934},{"atb":[[32,0],[21,0]],"id":52385903},{"atb":[[85,0],[44,0]],"id":52385930},{"atb":[[19.5,0],[14.5,0]],"id":52385932}],"con":true,"img":false}]}
{"op":"mcm","clk":"11449743681","pt":1717314174823,"mc":[{"id":"1.229554927","rc":[{"atb":[[19.5,5.65],[14.5,18.06]],"id":52385910},{"atb":[[8.6,32.09],[11.5,9.95]],"id":52385916},{"atb":[[9.2,29.74],[13,8.71]],"id":52385927},{"atb":[[9.6,28.36],[14,8.04]],"id":52385925},{"atb":[[10,27.1],[15,7.46]],"id":52385935},{"atb":[[90,2.35],[46,5.42]],"id":52385937},{"atb":[[550,0.44],[650,0.16]],"id":52385931},{"atb":[[3.45,42.66],[2.98,123.18]],"id":52385911},{"atb":[[2.82,134.01],[3.05,50.98]],"id":52385913},{"atb":[[7.4,16.33],[5.7,51.89]],"id":52385915},{"atb":[[7.4,38.1],[9.4,12.44]],"id":52385928},{"atb":[[550,0.44],[650,0.16]],"id":52385924},{"atb":[[18.5,5.97],[13.5,19.51]],"id":52385934},{"atb":[[85,1.24],[44,5.67]],"id":52385930},{"atb":[[19.5,5.65],[14.5,18.06]],"id":52385932}],"con":true,"img":false}]}
{"op":"mcm","clk":"11449743692","pt":1717314174926,"mc":[{"id":"1.229554927","rc":[{"atb":[[3,121.95],[3.5,41.81]],"id":52385906},{"atb":[[10.5,11],[8.2,33.87]],"id":52385908},{"atb":[[550,0.44],[650,0.16]],"id":52385887},{"atb":[[48,2.22],[29,8.71]],"id":52385889},{"atb":[[19,13.55],[28,3.87]],"id":52385885},{"atb":[[9.2,29.74],[13,8.71]],"id":52385894},{"atb":[[4,34.84],[3.5,97.56]],"id":52385892},{"atb":[[5.1,25.49],[4.1,78.68]],"id":52385904},{"atb":[[16,6.96],[11,24.39]],"id":52385909},{"atb":[[550,0.44],[650,0.16]],"id":52385888},{"atb":[[90,2.35],[46,5.42]],"id":52385882},{"atb":[[50,2.13],[30,8.41]],"id":52385884},{"atb":[[18.5,5.97],[13.5,19.51]],"id":52385895},{"atb":[[4.3,73.9],[5.3,24.31]],"id":52385891},{"atb":[[32,3.37],[21,12.19]],"id":52385903}],"con":true,"img":false}]}
{"op":"mcm","clk":"11449750058","pt":1717314243519,"mc":[{"id":"1.229554927","rc":[{"atb":[[17,0],[19.5,0],[24,0],[29,0]],"id":52385908},{"atb":[[130,0],[180,0],[90,1.17],[230,0]],"id":52385937}],"con":true,"img":false}]}
{"op":"mcm","clk":"11449750129","pt":1717314244199,"mc":[{"id":"1.229554927","rc":[{"atb":[[16.5,6.75],[19,4.36],[23,2.38],[28,0.97]],"id":52385908},{"atb":[[170,0.31],[85,1.25],[220,0.12],[120,0.66]],"id":52385937}],"con":true,"img":false}]}
{"op":"mcm","clk":"11449753549","pt":1717314282973,"mc":[{"id":"1.229554927","rc":[{"atb":[[17,0],[19.5,0],[12,0],[14.5,0]],"id":52385916}],"con":true,"img":false}]}
{"op":"mcm","clk":"11449753616","pt":1717314283663,"mc":[{"id":"1.229554927","rc":[{"atb":[[17,3.27],[19.5,1.41],[12,9.51],[14.5,5.81]],"id":52385916}],"con":true,"img":false}]}
{"op":"mcm","clk":"11449756807","pt":1717314321219,"mc":[{"id":"1.229554927","rc":[{"atb":[[19.5,0],[14.5,0]],"id":52385910},{"atb":[[3,0],[3.5,0]],"id":52385906},{"atb":[[10.5,0],[8.2,0]],"id":52385908},{"atb":[[550,0],[650,0]],"id":52385887},{"atb":[[48,0],[29,0]],"id":52385889},{"atb":[[8.6,0],[11.5,0]],"id":52385916},{"atb":[[19,0],[28,0]],"id":52385885},{"atb":[[9.2,0],[13,0]],"id":52385894},{"atb":[[9.2,0],[13,0]],"id":52385927},{"atb":[[4,0],[3.5,0]],"id":52385892},{"atb":[[9.6,0],[14,0]],"id":52385925},{"atb":[[10,0],[15,0]],"id":52385935},{"atb":[[5.1,0],[4.1,0]],"id":52385904},{"atb":[[90,0],[46,0]],"id":52385937},{"atb":[[550,0],[650,0]],"id":52385931},{"atb":[[3.45,0],[2.98,0]],"id":52385911},{"atb":[[2.82,0],[3.05,0]],"id":52385913},{"atb":[[16,0],[11,0]],"id":52385909},{"atb":[[550,0],[650,0]],"id":52385888},{"atb":[[90,1.18],[46,0]],"id":52385882},{"atb":[[7.4,0],[5.7,0]],"id":52385915},{"atb":[[50,0],[30,0]],"id":52385884},{"atb":[[18.5,0],[13.5,0]],"id":52385895},{"atb":[[7.4,0],[9.4,0]],"id":52385928},{"atb":[[4.3,0],[5.3,0]],"id":52385891},{"atb":[[550,0],[650,0]],"id":52385924},{"atb":[[18.5,0],[13.5,0]],"id":52385934},{"atb":[[32,0],[21,0]],"id":52385903},{"atb":[[85,0],[44,0]],"id":52385930},{"atb":[[19.5,0],[14.5,0]],"id":52385932}],"con":true,"img":false}]}
{"op":"mcm","clk":"11449757855","pt":1717314333634,"mc":[{"id":"1.229554927","rc":[{"atb":[[19.5,5.65],[14.5,18.06]],"id":52385910},{"atb":[[8.6,32.09],[11.5,9.95]],"id":52385916},{"atb":[[9.2,29.74],[13,8.71]],"id":52385927},{"atb":[[9.6,28.36],[14,8.04]],"id":52385925},{"atb":[[10,27.1],[15,7.46]],"id":52385935},{"atb":[[90,1.17],[46,5.42]],"id":52385937},{"atb":[[550,0.44],[650,0.16]],"id":52385931},{"atb":[[3.45,42.66],[2.98,123.18]],"id":52385911},{"atb":[[2.82,134.01],[3.05,50.98]],"id":52385913},{"atb":[[7.4,16.33],[5.7,51.89]],"id":52385915},{"atb":[[7.4,38.1],[9.4,12.44]],"id":52385928},{"atb":[[550,0.44],[650,0.16]],"id":52385924},{"atb":[[18.5,5.97],[13.5,19.51]],"id":52385934},{"atb":[[85,1.24],[44,5.67]],"id":52385930},{"atb":[[19.5,5.65],[14.5,18.06]],"id":52385932}],"con":true,"img":false}]}
{"op":"mcm","clk":"11449757869","pt":1717314333743,"mc":[{"id":"1.229554927","rc":[{"atb":[[3,121.95],[3.5,41.81]],"id":52385906},{"atb":[[10.5,11],[8.2,33.87]],"id":52385908},{"atb":[[550,0.44],[650,0.16]],"id":52385887},{"atb":[[48,2.22],[29,8.71]],"id":52385889},{"atb":[[19,13.55],[28,3.87]],"id":52385885},{"atb":[[9.2,29.74],[13,8.71]],"id":52385894},{"atb":[[4,34.84],[3.5,97.56]],"id":52385892},{"atb":[[5.1,25.49],[4.1,78.68]],"id":52385904},{"atb":[[16,6.96],[11,24.39]],"id":52385909},{"atb":[[550,0.44],[650,0.16]],"id":52385888},{"atb":[[90,2.35],[46,5.42]],"id":52385882},{"atb":[[50,2.13],[30,8.41]],"id":52385884},{"atb":[[18.5,5.97],[13.5,19.51]],"id":52385895},{"atb":[[4.3,73.9],[5.3,24.31]],"id":52385891},{"atb":[[32,3.37],[21,12.19]],"id":52385903}],"con":true,"img":false}]}
{"op":"mcm","clk":"11449759695","pt":1717314355396,"mc":[{"id":"1.229554927","rc":[{"atb":[[19.5,0],[14.5,0]],"id":52385910},{"atb":[[3,0],[3.5,0]],"id":52385906},{"atb":[[10.5,0],[8.2,0]],"id":52385908},{"atb":[[550,0],[650,0]],"id":52385887},{"atb":[[48,0],[29,0]],"id":52385889},{"atb":[[8.6,0],[11.5,0]],"id":52385916},{"atb":[[19,0],[28,0]],"id":52385885},{"atb":[[9.2,0],[13,0]],"id":52385894},{"atb":[[9.2,0],[13,0]],"id":52385927},{"atb":[[4,0],[3.5,0]],"id":52385892},{"atb":[[9.6,0],[14,0]],"id":52385925},{"atb":[[10,0],[15,0]],"id":52385935},{"atb":[[5.1,0],[4.1,0]],"id":52385904},{"atb":[[90,0],[46,0]],"id":52385937},{"atb":[[550,0],[650,0]],"id":52385931},{"atb":[[3.45,0],[2.98,0]],"id":52385911},{"atb":[[2.82,0],[3.05,0]],"id":52385913},{"atb":[[16,0],[11,0]],"id":52385909},{"atb":[[550,0],[650,0]],"id":52385888},{"atb":[[90,1.18],[46,0]],"id":52385882},{"atb":[[7.4,0],[5.7,0]],"id":52385915},{"atb":[[50,0],[30,0]],"id":52385884},{"atb":[[18.5,0],[13.5,0]],"id":52385895},{"atb":[[7.4,0],[9.4,0]],"id":52385928},{"atb":[[4.3,0],[5.3,0]],"id":52385891},{"atb":[[550,0],[650,0]],"id":52385924},{"atb":[[18.5,0],[13.5,0]],"id":52385934},{"atb":[[32,0],[21,0]],"id":52385903},{"atb":[[85,0],[44,0]],"id":52385930},{"atb":[[19.5,0],[14.5,0]],"id":52385932}],"con":true,"img":false}]}
{"op":"mcm","clk":"11449760268","pt":1717314362080,"mc":[{"id":"1.229554927","rc":[{"atb":[[3,121.95],[3.5,41.81]],"id":52385906},{"atb":[[10.5,11],[8.2,33.87]],"id":52385908},{"atb":[[550,0.44],[650,0.16]],"id":52385887},{"atb":[[48,2.22],[29,8.71]],"id":52385889},{"atb":[[19,13.55],[28,3.87]],"id":52385885},{"atb":[[9.2,29.74],[13,8.71]],"id":52385894},{"atb":[[4,34.84],[3.5,97.56]],"id":52385892},{"atb":[[5.1,25.49],[4.1,78.68]],"id":52385904},{"atb":[[16,6.96],[11,24.39]],"id":52385909},{"atb":[[550,0.44],[650,0.16]],"id":52385888},{"atb":[[90,2.35],[46,5.42]],"id":52385882},{"atb":[[50,2.13],[30,8.41]],"id":52385884},{"atb":[[18.5,5.97],[13.5,19.51]],"id":52385895},{"atb":[[4.3,73.9],[5.3,24.31]],"id":52385891},{"atb":[[32,3.37],[21,12.19]],"id":52385903}],"con":true,"img":false}]}
{"op":"mcm","clk":"11449760275","pt":1717314362177,"mc":[{"id":"1.229554927","rc":[{"atb":[[19.5,5.65],[14.5,18.06]],"id":52385910},{"atb":[[8.6,32.09],[11.5,9.95]],"id":52385916},{"atb":[[9.2,29.74],[13,8.71]],"id":52385927},{"atb":[[9.6,28.36],[14,8.04]],"id":52385925},{"atb":[[10,27.1],[15,7.46]],"id":52385935},{"atb":[[90,1.17],[46,5.42]],"id":52385937},{"atb":[[550,0.44],[650,0.16]],"id":52385931},{"atb":[[3.45,42.66],[2.98,123.18]],"id":52385911},{"atb":[[2.82,134.01],[3.05,50.98]],"id":52385913},{"atb":[[7.4,16.33],[5.7,51.89]],"id":52385915},{"atb":[[7.4,38.1],[9.4,12.44]],"id":52385928},{"atb":[[550,0.44],[650,0.16]],"id":52385924},{"atb":[[18.5,5.97],[13.5,19.51]],"id":52385934},{"atb":[[85,1.24],[44,5.67]],"id":52385930},{"atb":[[19.5,5.65],[14.5,18.06]],"id":52385932}],"con":true,"img":false}]}
{"op":"mcm","clk":"11449760671","pt":1717314366670,"mc":[{"id":"1.229554927","rc":[{"atb":[[80,0],[42,0],[110,0],[55,0]],"id":52385889},{"atb":[[140,0],[70,0],[95,0],[48,0]],"id":52385885}],"con":true,"img":false}]}
{"op":"mcm","clk":"11449760681","pt":1717314366777,"mc":[{"id":"1.229554927","rc":[{"atb":[[34,0],[44,0],[22,0],[27,0]],"id":52385927},{"atb":[[630,0],[680,0],[730,0],[780,0]],"id":52385931},{"atb":[[800,0],[850,0],[900,0],[950,0]],"id":52385888},{"atb":[[130,0],[180,0],[90,1.17],[230,0]],"id":52385882},{"atb":[[170,0],[85,0],[220,0],[120,0]],"id":52385884},{"atb":[[75,0],[40,0],[100,0],[50,0]],"id":52385903}],"con":true,"img":false}]}
{"op":"mcm","clk":"11449760722","pt":1717314367405,"mc":[{"id":"1.229554927","rc":[{"atb":[[140,0.19],[70,1.14],[95,0.55],[48,4.45]],"id":52385889},{"atb":[[140,0.38],[70,1.52],[190,0.14],[95,0.84]],"id":52385885}],"con":true,"img":false}]}
{"op":"mcm","clk":"11449760733","pt":1717314367504,"mc":[{"id":"1.229554927","rc":[{"atb":[[32,1.69],[42,0.64],[21,5.23],[26,3.14]],"id":52385927},{"atb":[[840,0.13],[890,0.09],[940,0.06],[990,0.03]],"id":52385931},{"atb":[[840,0.13],[890,0.09],[940,0.06],[990,0.03]],"id":52385888},{"atb":[[270,0.19],[320,0.08],[170,0.62],[220,0.36]],"id":52385882},{"atb":[[140,0.75],[290,0.09],[190,0.41],[240,0.22]],"id":52385884},{"atb":[[130,0.2],[65,1.22],[90,0.59],[46,2.32]],"id":52385903}],"con":true,"img":false}]}
{"op":"mcm","clk":"11449767814","pt":1717314444710,"mc":[{"id":"1.229554927","rc":[{"atb":[[11,0],[13.5,0],[8.4,0],[9.4,0]],"id":52385915}],"con":true,"img":false}]}
{"op":"mcm","clk":"11449767823","pt":1717314444782,"mc":[{"id":"1.229554927","rc":[{"atb":[[140,0],[290,0],[190,0],[240,0]],"id":52385884}],"con":true,"img":false}]}
{"op":"mcm","clk":"11449767881","pt":1717314445355,"mc":[{"id":"1.229554927","rc":[{"atb":[[9.2,9.57],[10.5,5.51],[8.2,14.53],[13,2.18]],"id":52385915}],"con":true,"img":false}]}
{"op":"mcm","clk":"11449767890","pt":1717314445455,"mc":[{"id":"1.229554927","rc":[{"atb":[[300,0.09],[150,0.7],[200,0.39],[250,0.21]],"id":52385884}],"con":true,"img":false}]}
{"op":"mcm","clk":"11449777459","pt":1717314550215,"mc":[{"id":"1.229554927","rc":[{"atb":[[32,0],[18,0],[21,0],[26,0]],"id":52385894},{"atb":[[5.6,0],[7.2,0],[5.1,0],[6.2,0]],"id":52385892},{"atb":[[36,0],[46,0],[23,0],[28,0]],"id":52385925},{"atb":[[32,0],[42,0],[26,0],[55,0]],"id":52385935},{"atb":[[38,0],[48,0],[24,0],[29,0]],"id":52385909},{"atb":[[9.2,0],[10.5,0],[8.2,0],[13,0]],"id":52385915},{"atb":[[34,0],[85,0],[44,0],[60,0]],"id":52385934},{"atb":[[65,0],[36,0],[90,0],[46,0]],"id":52385932}],"con":true,"img":false}]}
{"op":"mcm","clk":"11449777518","pt":1717314550893,"mc":[{"id":"1.229554927","rc":[{"atb":[[17.5,6.34],[20,4.13],[25,2.18],[30,0.9]],"id":52385894},{"atb":[[5,26.16],[5.5,17.44],[6,10.46],[7,4.36]],"id":52385892},{"atb":[[34,1.59],[44,0.61],[22,4.98],[27,3.02]],"id":52385925},{"atb":[[34,2.38],[44,1.22],[27,4.02],[60,0.44]],"id":52385935},{"atb":[[32,2.53],[42,1.28],[26,4.19],[55,0.49]],"id":52385909},{"atb":[[11,5.23],[13.5,2.09],[8.4,14.14],[9.4,9.34]],"id":52385915},{"atb":[[70,0.76],[38,2.83],[95,0.28],[48,1.67]],"id":52385934},{"atb":[[75,0.71],[40,2.68],[100,0.27],[50,1.6]],"id":52385932}],"con":true,"img":false}]}
{"op":"mcm","clk":"11449786987","pt":1717314665911,"mc":[{"id":"1.229554927","rc":[{"atb":[[34,0],[44,0],[22,0],[27,0]],"id":52385925}],"con":true,"img":false}]}
{"op":"mcm","clk":"11449787047","pt":1717314666632,"mc":[{"id":"1.229554927","rc":[{"atb":[[36,1.5],[46,0.58],[23,4.76],[28,2.91]],"id":52385925}],"con":true,"img":false}]}
{"op":"mcm","clk":"11449823489","pt":1717315077010,"mc":[{"id":"1.229554927","rc":[{"atb":[[6.8,0],[4.9,0],[5.9,0],[5.4,0]],"id":52385906},{"atb":[[2.9,0],[3,0],[3.25,0],[3.5,0]],"id":52385913}],"con":true,"img":false}]}
{"op":"mcm","clk":"11449823553","pt":1717315077693,"mc":[{"id":"1.229554927","rc":[{"atb":[[4.8,27.54],[5.8,10.9],[5.3,18.25],[6.6,4.67]],"id":52385906},{"atb":[[2.86,42.19],[3.15,12.17],[2.96,26.69],[2.76,59.45]],"id":52385913}],"con":true,"img":false}]}
{"op":"mcm","clk":"11449848518","pt":1717315267956,"mc":[{"id":"1.229554927","rc":[{"atb":[[17.5,0],[20,0],[25,0],[30,0]],"id":52385894}],"con":true,"img":false}]}
{"op":"mcm","clk":"11449848591","pt":1717315268630,"mc":[{"id":"1.229554927","rc":[{"atb":[[32,0.84],[18,6.15],[21,3.92],[26,2.09]],"id":52385894}],"con":true,"img":false}]}
{"op":"mcm","clk":"11449851295","pt":1717315296672,"mc":[{"id":"1.229554927","rc":[{"atb":[[19.5,0],[14.5,0]],"id":52385910},{"atb":[[3,0],[3.5,0]],"id":52385906},{"atb":[[10.5,0],[8.2,0]],"id":52385908},{"atb":[[550,0],[650,0]],"id":52385887},{"atb":[[48,2.23],[29,0]],"id":52385889},{"atb":[[8.6,0],[11.5,0]],"id":52385916},{"atb":[[19,0],[28,0]],"id":52385885},{"atb":[[9.2,0],[13,0]],"id":52385894},{"atb":[[9.2,0],[13,0]],"id":52385927},{"atb":[[4,0],[3.5,0]],"id":52385892},{"atb":[[9.6,0],[14,0]],"id":52385925},{"atb":[[10,0],[15,0]],"id":52385935},{"atb":[[5.1,0],[4.1,0]],"id":52385904},{"atb":[[90,0],[46,0]],"id":52385937},{"atb":[[550,0],[650,0]],"id":52385931},{"atb":[[3.45,0],[2.98,0]],"id":52385911},{"atb":[[2.82,0],[3.05,0]],"id":52385913},{"atb":[[16,0],[11,0]],"id":52385909},{"atb":[[550,0],[650,0]],"id":52385888},{"atb":[[90,0],[46,0]],"id":52385882},{"atb":[[7.4,0],[5.7,0]],"id":52385915},{"atb":[[50,0],[30,0]],"id":52385884},{"atb":[[18.5,0],[13.5,0]],"id":52385895},{"atb":[[7.4,0],[9.4,0]],"id":52385928},{"atb":[[4.3,0],[5.3,0]],"id":52385891},{"atb":[[550,0],[650,0]],"id":52385924},{"atb":[[18.5,0],[13.5,0]],"id":52385934},{"atb":[[32,0],[21,0]],"id":52385903},{"atb":[[85,0],[44,0]],"id":52385930},{"atb":[[19.5,0],[14.5,0]],"id":52385932}],"con":true,"img":false}]}
{"op":"mcm","clk":"11449852714","pt":1717315311616,"mc":[{"id":"1.229554927","rc":[{"atb":[[170,0],[85,0],[220,0],[120,0]],"id":52385937}],"con":true,"img":false}]}
{"op":"mcm","clk":"11449852789","pt":1717315312393,"mc":[{"id":"1.229554927","rc":[{"atb":[[230,0.12]],"id":52385937}],"con":true,"img":false}]}
{"op":"mcm","clk":"11449852799","pt":1717315312491,"mc":[{"id":"1.229554927","rc":[{"atb":[[130,0.61],[180,0.29],[90,1.18]],"id":52385937}],"con":true,"img":false}]}
{"op":"mcm","clk":"11449855873","pt":1717315342051,"mc":[{"id":"1.229554927","rc":[{"atb":[[19.5,5.65],[14.5,18.06]],"id":52385910},{"atb":[[3,121.95],[3.5,41.81]],"id":52385906},{"atb":[[10.5,11],[8.2,33.87]],"id":52385908},{"atb":[[550,0.44],[650,0.16]],"id":52385887},{"atb":[[48,4.45],[29,8.71]],"id":52385889},{"atb":[[8.6,32.09],[11.5,9.95]],"id":52385916},{"atb":[[19,13.55],[28,3.87]],"id":52385885},{"atb":[[9.2,29.74],[13,8.71]],"id":52385894},{"atb":[[9.2,29.74],[13,8.71]],"id":52385927},{"atb":[[4,34.84],[3.5,97.56]],"id":52385892},{"atb":[[9.6,28.36],[14,8.04]],"id":52385925},{"atb":[[10,27.1],[15,7.46]],"id":52385935},{"atb":[[5.1,25.49],[4.1,78.68]],"id":52385904},{"atb":[[90,2.35],[46,5.42]],"id":52385937},{"atb":[[550,0.44],[650,0.16]],"id":52385931},{"atb":[[3.45,42.66],[2.98,123.18]],"id":52385911},{"atb":[[2.82,134.01],[3.05,50.98]],"id":52385913},{"atb":[[16,6.96],[11,24.39]],"id":52385909},{"atb":[[550,0.44],[650,0.16]],"id":52385888},{"atb":[[90,1.17],[46,5.42]],"id":52385882},{"atb":[[7.4,16.33],[5.7,51.89]],"id":52385915},{"atb":[[50,2.13],[30,8.41]],"id":52385884},{"atb":[[18.5,5.97],[13.5,19.51]],"id":52385895},{"atb":[[7.4,38.1],[9.4,12.44]],"id":52385928},{"atb":[[4.3,73.9],[5.3,24.31]],"id":52385891},{"atb":[[550,0.44],[650,0.16]],"id":52385924},{"atb":[[18.5,5.97],[13.5,19.51]],"id":52385934},{"atb":[[32,3.37],[21,12.19]],"id":52385903},{"atb":[[85,1.24],[44,5.67]],"id":52385930},{"atb":[[19.5,5.65],[14.5,18.06]],"id":52385932}],"con":true,"img":false}]}
{"op":"mcm","clk":"11449856392","pt":1717315346945,"mc":[{"id":"1.229554927","rc":[{"atb":[[12,0]],"id":52385916}],"con":true,"img":false}]}
{"op":"mcm","clk":"11449856400","pt":1717315347042,"mc":[{"id":"1.229554927","rc":[{"atb":[[17,0]],"id":52385916}],"con":true,"img":false}]}
{"op":"mcm","clk":"11449856414","pt":1717315347148,"mc":[{"id":"1.229554927","rc":[{"atb":[[19.5,0],[14.5,0]],"id":52385916}],"con":true,"img":false}]}
{"op":"mcm","clk":"11449856476","pt":1717315347664,"mc":[{"id":"1.229554927","rc":[{"atb":[[13.5,8.37]],"id":52385916}],"con":true,"img":false}]}
{"op":"mcm","clk":"11449856488","pt":1717315347767,"mc":[{"id":"1.229554927","rc":[{"atb":[[18.5,2.99]],"id":52385916}],"con":true,"img":false}]}
{"op":"mcm","clk":"11449856501","pt":1717315347879,"mc":[{"id":"1.229554927","rc":[{"atb":[[16,5.23],[22,1.25]],"id":52385916}],"con":true,"img":false}]}
{"op":"mcm","clk":"11449893743","pt":1717315713497,"mc":[{"id":"1.229554927","rc":[{"atb":[[19.5,0],[14.5,0]],"id":52385910},{"atb":[[3,0],[3.5,0]],"id":52385906},{"atb":[[10.5,0],[8.2,0]],"id":52385908},{"atb":[[550,0],[650,0]],"id":52385887},{"atb":[[48,2.23],[29,0]],"id":52385889},{"atb":[[8.6,0],[11.5,0]],"id":52385916},{"atb":[[19,0],[28,0]],"id":52385885},{"atb":[[9.2,0],[13,0]],"id":52385894},{"atb":[[9.2,0],[13,0]],"id":52385927},{"atb":[[4,0],[3.5,0]],"id":52385892},{"atb":[[9.6,0],[14,0]],"id":52385925},{"atb":[[10,0],[15,0]],"id":52385935},{"atb":[[5.1,0],[4.1,0]],"id":52385904},{"atb":[[90,1.18],[46,0]],"id":52385937},{"atb":[[550,0],[650,0]],"id":52385931},{"atb":[[3.45,0],[2.98,0]],"id":52385911},{"atb":[[2.82,0],[3.05,0]],"id":52385913},{"atb":[[16,0],[11,0]],"id":52385909},{"atb":[[550,0],[650,0]],"id":52385888},{"atb":[[90,0],[46,0]],"id":52385882},{"atb":[[7.4,0],[5.7,0]],"id":52385915},{"atb":[[50,0],[30,0]],"id":52385884},{"atb":[[18.5,0],[13.5,0]],"id":52385895},{"atb":[[7.4,0],[9.4,0]],"id":52385928},{"atb":[[4.3,0],[5.3,0]],"id":52385891},{"atb":[[550,0],[650,0]],"id":52385924},{"atb":[[18.5,0],[13.5,0]],"id":52385934},{"atb":[[32,0],[21,0]],"id":52385903},{"atb":[[85,0],[44,0]],"id":52385930},{"atb":[[19.5,0],[14.5,0]],"id":52385932}],"con":true,"img":false}]}
{"op":"mcm","clk":"11449899234","pt":1717315764715,"mc":[{"id":"1.229554927","rc":[{"atb":[[19.5,5.65],[14.5,18.06]],"id":52385910},{"atb":[[3,121.95],[3.5,41.81]],"id":52385906},{"atb":[[10.5,11],[8.2,33.87]],"id":52385908},{"atb":[[550,0.44],[650,0.16]],"id":52385887},{"atb":[[48,4.45],[29,8.71]],"id":52385889},{"atb":[[8.6,32.09],[11.5,9.95]],"id":52385916},{"atb":[[19,13.55],[28,3.87]],"id":52385885},{"atb":[[9.2,29.74],[13,8.71]],"id":52385894},{"atb":[[9.2,29.74],[13,8.71]],"id":52385927},{"atb":[[4,34.84],[3.5,97.56]],"id":52385892},{"atb":[[9.6,28.36],[14,8.04]],"id":52385925},{"atb":[[10,27.1],[15,7.46]],"id":52385935},{"atb":[[5.1,25.49],[4.1,78.68]],"id":52385904},{"atb":[[90,2.35],[46,5.42]],"id":52385937},{"atb":[[550,0.44],[650,0.16]],"id":52385931},{"atb":[[3.45,42.66],[2.98,123.18]],"id":52385911},{"atb":[[2.82,134.01],[3.05,50.98]],"id":52385913},{"atb":[[16,6.96],[11,24.39]],"id":52385909},{"atb":[[550,0.44],[650,0.16]],"id":52385888},{"atb":[[90,1.17],[46,5.42]],"id":52385882},{"atb":[[7.4,16.33],[5.7,51.89]],"id":52385915},{"atb":[[50,2.13],[30,8.41]],"id":52385884},{"atb":[[18.5,5.97],[13.5,19.51]],"id":52385895},{"atb":[[7.4,38.1],[9.4,12.44]],"id":52385928},{"atb":[[4.3,73.9],[5.3,24.31]],"id":52385891},{"atb":[[550,0.44],[650,0.16]],"id":52385924},{"atb":[[18.5,5.97],[13.5,19.51]],"id":52385934},{"atb":[[32,3.37],[21,12.19]],"id":52385903},{"atb":[[85,1.24],[44,5.67]],"id":52385930},{"atb":[[19.5,5.65],[14.5,18.06]],"id":52385932}],"con":true,"img":false}]}
{"op":"mcm","clk":"11449908370","pt":1717315853922,"mc":[{"id":"1.229554927","rc":[{"atb":[[18.5,0]],"id":52385916},{"atb":[[32,0],[42,0],[21,0],[26,0]],"id":52385927}],"con":true,"img":false}]}
{"op":"mcm","clk":"11449908449","pt":1717315854596,"mc":[{"id":"1.229554927","rc":[{"atb":[[19,2.91]],"id":52385916},{"atb":[[34,1.59],[44,0.61],[22,4.98],[27,3.02]],"id":52385927}],"con":true,"img":false}]}
{"op":"mcm","clk":"11449909046","pt":1717315860424,"mc":[{"id":"1.229554927","rc":[{"atb":[[19,0]],"id":52385916},{"atb":[[34,0],[44,0],[22,0],[27,0]],"id":52385927}],"con":true,"img":false}]}
{"op":"mcm","clk":"11449909123","pt":1717315861102,"mc":[{"id":"1.229554927","rc":[{"atb":[[18.5,2.99]],"id":52385916},{"atb":[[32,1.69],[42,0.64],[21,5.23],[26,3.14]],"id":52385927}],"con":true,"img":false}]}
{"op":"mcm","clk":"11449954234","pt":1717316332769,"mc":[{"id":"1.229554927","rc":[{"atb":[[11,0],[13.5,0],[8.4,0],[9.4,0]],"id":52385915}],"con":true,"img":false}]}
{"op":"mcm","clk":"11449954284","pt":1717316333487,"mc":[{"id":"1.229554927","rc":[{"atb":[[9.2,9.57],[10.5,5.51],[8.2,14.53],[13,2.18]],"id":52385915}],"con":true,"img":false}]}
{"op":"mcm","clk":"11449959210","pt":1717316398480,"mc":[{"id":"1.229554927","rc":[{"atb":[[19.5,0],[14.5,0]],"id":52385910},{"atb":[[3,0],[3.5,0]],"id":52385906},{"atb":[[10.5,0],[8.2,0]],"id":52385908},{"atb":[[550,0],[650,0]],"id":52385887},{"atb":[[48,2.23],[29,0]],"id":52385889},{"atb":[[8.6,0],[11.5,0]],"id":52385916},{"atb":[[19,0],[28,0]],"id":52385885},{"atb":[[9.2,0],[13,0]],"id":52385894},{"atb":[[9.2,0],[13,0]],"id":52385927},{"atb":[[4,0],[3.5,0]],"id":52385892},{"atb":[[9.6,0],[14,0]],"id":52385925},{"atb":[[10,0],[15,0]],"id":52385935},{"atb":[[5.1,0],[4.1,0]],"id":52385904},{"atb":[[90,1.18],[46,0]],"id":52385937},{"atb":[[550,0],[650,0]],"id":52385931},{"atb":[[3.45,0],[2.98,0]],"id":52385911},{"atb":[[2.82,0],[3.05,0]],"id":52385913},{"atb":[[16,0],[11,0]],"id":52385909},{"atb":[[550,0],[650,0]],"id":52385888},{"atb":[[90,0],[46,0]],"id":52385882},{"atb":[[7.4,0],[5.7,0]],"id":52385915},{"atb":[[50,0],[30,0]],"id":52385884},{"atb":[[18.5,0],[13.5,0]],"id":52385895},{"atb":[[7.4,0],[9.4,0]],"id":52385928},{"atb":[[4.3,0],[5.3,0]],"id":52385891},{"atb":[[550,0],[650,0]],"id":52385924},{"atb":[[18.5,0],[13.5,0]],"id":52385934},{"atb":[[32,0],[21,0]],"id":52385903},{"atb":[[85,0],[44,0]],"id":52385930},{"atb":[[19.5,0],[14.5,0]],"id":52385932}],"con":true,"img":false}]}
{"op":"mcm","clk":"11449961549","pt":1717316426050,"mc":[{"id":"1.229554927","rc":[{"atb":[[19.5,5.65],[14.5,18.06]],"id":52385910},{"atb":[[3,121.95],[3.5,41.81]],"id":52385906},{"atb":[[10.5,11],[8.2,33.87]],"id":52385908},{"atb":[[550,0.44],[650,0.16]],"id":52385887},{"atb":[[48,4.45],[29,8.71]],"id":52385889},{"atb":[[8.6,32.09],[11.5,9.95]],"id":52385916},{"atb":[[19,13.55],[28,3.87]],"id":52385885},{"atb":[[9.2,29.74],[13,8.71]],"id":52385894},{"atb":[[9.2,29.74],[13,8.71]],"id":52385927},{"atb":[[4,34.84],[3.5,97.56]],"id":52385892},{"atb":[[9.6,28.36],[14,8.04]],"id":52385925},{"atb":[[10,27.1],[15,7.46]],"id":52385935},{"atb":[[5.1,25.49],[4.1,78.68]],"id":52385904},{"atb":[[90,2.35],[46,5.42]],"id":52385937},{"atb":[[550,0.44],[650,0.16]],"id":52385931},{"atb":[[3.45,42.66],[2.98,123.18]],"id":52385911},{"atb":[[2.82,134.01],[3.05,50.98]],"id":52385913},{"atb":[[16,6.96],[11,24.39]],"id":52385909},{"atb":[[550,0.44],[650,0.16]],"id":52385888},{"atb":[[90,1.17],[46,5.42]],"id":52385882},{"atb":[[7.4,16.33],[5.7,51.89]],"id":52385915},{"atb":[[50,2.13],[30,8.41]],"id":52385884},{"atb":[[18.5,5.97],[13.5,19.51]],"id":52385895},{"atb":[[7.4,38.1],[9.4,12.44]],"id":52385928},{"atb":[[4.3,73.9],[5.3,24.31]],"id":52385891},{"atb":[[550,0.44],[650,0.16]],"id":52385924},{"atb":[[18.5,5.97],[13.5,19.51]],"id":52385934},{"atb":[[32,3.37],[21,12.19]],"id":52385903},{"atb":[[85,1.24],[44,5.67]],"id":52385930},{"atb":[[19.5,5.65],[14.5,18.06]],"id":52385932}],"con":true,"img":false}]}
{"op":"mcm","clk":"11449970808","pt":1717316557400,"mc":[{"id":"1.229554927","rc":[{"atb":[[16,0],[22,0],[13.5,0]],"id":52385916}],"con":true,"img":false}]}
{"op":"mcm","clk":"11449970860","pt":1717316558077,"mc":[{"id":"1.229554927","rc":[{"atb":[[16.5,5.06],[23,1.19],[14,8.05]],"id":52385916}],"con":true,"img":false}]}
{"op":"mcm","clk":"11449970976","pt":1717316560158,"mc":[{"id":"1.229554927","rc":[{"atb":[[16.5,0],[23,0],[14,0]],"id":52385916}],"con":true,"img":false}]}
{"op":"mcm","clk":"11449971020","pt":1717316560881,"mc":[{"id":"1.229554927","rc":[{"atb":[[16,5.23],[22,1.25],[13.5,8.37]],"id":52385916}],"con":true,"img":false}]}
{"op":"mcm","clk":"11450006519","pt":1717317019168,"mc":[{"id":"1.229554927","rc":[{"atb":[[18.5,0]],"id":52385916},{"atb":[[32,0],[18,0],[21,0],[26,0]],"id":52385894}],"con":true,"img":false}]}
{"op":"mcm","clk":"11450006605","pt":1717317019843,"mc":[{"id":"1.229554927","rc":[{"atb":[[19,2.91]],"id":52385916},{"atb":[[17.5,6.34],[20,4.13],[25,2.18],[30,0.9]],"id":52385894}],"con":true,"img":false}]}
{"op":"mcm","clk":"11450023457","pt":1717317191920,"mc":[{"id":"1.229554927","rc":[{"atb":[[9.2,0],[10.5,0],[8.2,0],[13,0]],"id":52385915}],"con":true,"img":false}]}
{"op":"mcm","clk":"11450023526","pt":1717317192595,"mc":[{"id":"1.229554927","rc":[{"atb":[[11,5.23],[13.5,2.09],[8.4,14.14],[9.4,9.34]],"id":52385915}],"con":true,"img":false}]}
{"op":"mcm","clk":"11450044882","pt":1717317396471,"mc":[{"id":"1.229554927","rc":[{"atb":[[22,0]],"id":52385916}],"con":true,"img":false}]}
{"op":"mcm","clk":"11450044892","pt":1717317396576,"mc":[{"id":"1.229554927","rc":[{"atb":[[16,0],[13.5,0]],"id":52385916}],"con":true,"img":false}]}
{"op":"mcm","clk":"11450044963","pt":1717317397193,"mc":[{"id":"1.229554927","rc":[{"atb":[[23,1.19]],"id":52385916}],"con":true,"img":false}]}
{"op":"mcm","clk":"11450044971","pt":1717317397296,"mc":[{"id":"1.229554927","rc":[{"atb":[[16.5,5.06],[14,8.05]],"id":52385916}],"con":true,"img":false}]}
{"op":"mcm","clk":"11450057442","pt":1717317526728,"mc":[{"id":"1.229554927","rc":[{"atb":[[19.5,0],[14.5,0]],"id":52385910},{"atb":[[3,0],[3.5,0]],"id":52385906},{"atb":[[10.5,0],[8.2,0]],"id":52385908},{"atb":[[550,0],[650,0]],"id":52385887},{"atb":[[48,2.23],[29,0]],"id":52385889},{"atb":[[8.6,0],[11.5,0]],"id":52385916},{"atb":[[19,0],[28,0]],"id":52385885},{"atb":[[9.2,0],[13,0]],"id":52385894},{"atb":[[9.2,0],[13,0]],"id":52385927},{"atb":[[4,0],[3.5,0]],"id":52385892},{"atb":[[9.6,0],[14,0]],"id":52385925},{"atb":[[10,0],[15,0]],"id":52385935},{"atb":[[5.1,0],[4.1,0]],"id":52385904},{"atb":[[90,1.18],[46,0]],"id":52385937},{"atb":[[550,0],[650,0]],"id":52385931},{"atb":[[3.45,0],[2.98,0]],"id":52385911},{"atb":[[2.82,0],[3.05,0]],"id":52385913},{"atb":[[16,0],[11,0]],"id":52385909},{"atb":[[550,0],[650,0]],"id":52385888},{"atb":[[90,0],[46,0]],"id":52385882},{"atb":[[7.4,0],[5.7,0]],"id":52385915},{"atb":[[50,0],[30,0]],"id":52385884},{"atb":[[18.5,0],[13.5,0]],"id":52385895},{"atb":[[7.4,0],[9.4,0]],"id":52385928},{"atb":[[4.3,0],[5.3,0]],"id":52385891},{"atb":[[550,0],[650,0]],"id":52385924},{"atb":[[18.5,0],[13.5,0]],"id":52385934},{"atb":[[32,0],[21,0]],"id":52385903},{"atb":[[85,0],[44,0]],"id":52385930},{"atb":[[19.5,0],[14.5,0]],"id":52385932}],"con":true,"img":false}]}
{"op":"mcm","clk":"11450060558","pt":1717317561154,"mc":[{"id":"1.229554927","rc":[{"atb":[[19.5,5.65],[14.5,18.06]],"id":52385910},{"atb":[[3,121.95],[3.5,41.81]],"id":52385906},{"atb":[[10.5,11],[8.2,33.87]],"id":52385908},{"atb":[[550,0.44],[650,0.16]],"id":52385887},{"atb":[[48,4.45],[29,8.71]],"id":52385889},{"atb":[[8.6,32.09],[11.5,9.95]],"id":52385916},{"atb":[[19,13.55],[28,3.87]],"id":52385885},{"atb":[[9.2,29.74],[13,8.71]],"id":52385894},{"atb":[[9.2,29.74],[13,8.71]],"id":52385927},{"atb":[[4,34.84],[3.5,97.56]],"id":52385892},{"atb":[[9.6,28.36],[14,8.04]],"id":52385925},{"atb":[[10,27.1],[15,7.46]],"id":52385935},{"atb":[[5.1,25.49],[4.1,78.68]],"id":52385904},{"atb":[[90,2.35],[46,5.42]],"id":52385937},{"atb":[[550,0.44],[650,0.16]],"id":52385931},{"atb":[[3.45,42.66],[2.98,123.18]],"id":52385911},{"atb":[[2.82,134.01],[3.05,50.98]],"id":52385913},{"atb":[[16,6.96],[11,24.39]],"id":52385909},{"atb":[[550,0.44],[650,0.16]],"id":52385888},{"atb":[[90,1.17],[46,5.42]],"id":52385882},{"atb":[[7.4,16.33],[5.7,51.89]],"id":52385915},{"atb":[[50,2.13],[30,8.41]],"id":52385884},{"atb":[[18.5,5.97],[13.5,19.51]],"id":52385895},{"atb":[[7.4,38.1],[9.4,12.44]],"id":52385928},{"atb":[[4.3,73.9],[5.3,24.31]],"id":52385891},{"atb":[[550,0.44],[650,0.16]],"id":52385924},{"atb":[[18.5,5.97],[13.5,19.51]],"id":52385934},{"atb":[[32,3.37],[21,12.19]],"id":52385903},{"atb":[[85,1.24],[44,5.67]],"id":52385930},{"atb":[[19.5,5.65],[14.5,18.06]],"id":52385932}],"con":true,"img":false}]}
{"op":"mcm","clk":"11450067590","pt":1717317638860,"mc":[{"id":"1.229554927","rc":[{"atb":[[2.86,0],[3.15,0],[2.96,0],[2.76,0]],"id":52385913}],"con":true,"img":false}]}
{"op":"mcm","clk":"11450067660","pt":1717317639591,"mc":[{"id":"1.229554927","rc":[{"atb":[[2.8,58.13],[2.9,41.31],[3,26.16],[3.25,11.63]],"id":52385913}],"con":true,"img":false}]}
{"op":"mcm","clk":"11450067916","pt":1717317642385,"mc":[{"id":"1.229554927","rc":[{"atb":[[32,0],[42,0],[26,0]],"id":52385927}],"con":true,"img":false}]}
{"op":"mcm","clk":"11450067981","pt":1717317643065,"mc":[{"id":"1.229554927","rc":[{"atb":[[34,1.59],[44,0.61],[27,3.02]],"id":52385927}],"con":true,"img":false}]}
{"op":"mcm","clk":"11450068579","pt":1717317649208,"mc":[{"id":"1.229554927","rc":[{"atb":[[34,0],[44,0],[27,0]],"id":52385927}],"con":true,"img":false}]}
{"op":"mcm","clk":"11450068642","pt":1717317649883,"mc":[{"id":"1.229554927","rc":[{"atb":[[32,1.69],[42,0.64],[26,3.14]],"id":52385927}],"con":true,"img":false}]}
{"op":"mcm","clk":"11450089020","pt":1717317879509,"mc":[{"id":"1.229554927","rc":[{"atb":[[16.5,0],[19,0],[23,0],[14,0]],"id":52385916},{"atb":[[17.5,0],[20,0],[25,0],[30,0]],"id":52385894}],"con":true,"img":false}]}
{"op":"mcm","clk":"11450089094","pt":1717317880188,"mc":[{"id":"1.229554927","rc":[{"atb":[[16,5.23],[18.5,2.99],[22,1.25],[13.5,8.37]],"id":52385916},{"atb":[[32,0.84],[18,6.15],[21,3.92],[26,2.09]],"id":52385894}],"con":true,"img":false}]}
{"op":"mcm","clk":"11450089611","pt":1717317885976,"mc":[{"id":"1.229554927","rc":[{"atb":[[32,0],[18,0],[21,0],[26,0]],"id":52385894}],"con":true,"img":false}]}
{"op":"mcm","clk":"11450089670","pt":1717317886702,"mc":[{"id":"1.229554927","rc":[{"atb":[[17.5,6.34]],"id":52385894}],"con":true,"img":false}]}
{"op":"mcm","clk":"11450089680","pt":1717317886807,"mc":[{"id":"1.229554927","rc":[{"atb":[[20,4.13],[25,2.18],[30,0.9]],"id":52385894}],"con":true,"img":false}]}
{"op":"mcm","clk":"11450105868","pt":1717318070743,"mc":[{"id":"1.229554927","rc":[{"atb":[[2.8,0],[2.9,0],[3,0],[3.25,0]],"id":52385913}],"con":true,"img":false}]}
{"op":"mcm","clk":"11450105934","pt":1717318071424,"mc":[{"id":"1.229554927","rc":[{"atb":[[3.2,11.89],[2.88,41.74],[2.98,26.43],[2.78,58.78]],"id":52385913}],"con":true,"img":false}]}
{"op":"mcm","clk":"11450117841","pt":1717318204368,"mc":[{"id":"1.229554927","rc":[{"atb":[[3.2,0],[2.88,0],[2.98,0],[2.78,0]],"id":52385913}],"con":true,"img":false}]}
{"op":"mcm","clk":"11450117918","pt":1717318205092,"mc":[{"id":"1.229554927","rc":[{"atb":[[2.74,60.13],[3.1,12.46],[2.84,42.65],[2.94,26.97]],"id":52385913}],"con":true,"img":false}]}
{"op":"mcm","clk":"11450119291","pt":1717318220861,"mc":[{"id":"1.229554927","rc":[{"atb":[[11,0],[13.5,0],[8.4,0],[9.4,0]],"id":52385915}],"con":true,"img":false}]}
{"op":"mcm","clk":"11450119353","pt":1717318221686,"mc":[{"id":"1.229554927","rc":[{"atb":[[9.2,9.57],[10.5,5.51],[8.2,14.53],[13,2.18]],"id":52385915}],"con":true,"img":false}]}
{"op":"mcm","clk":"11450133833","pt":1717318390220,"mc":[{"id":"1.229554927","rc":[{"atb":[[19.5,0],[14.5,0]],"id":52385910},{"atb":[[3,0],[3.5,0]],"id":52385906},{"atb":[[10.5,0],[8.2,0]],"id":52385908},{"atb":[[550,0],[650,0]],"id":52385887},{"atb":[[48,2.23],[29,0]],"id":52385889},{"atb":[[8.6,0],[11.5,0]],"id":52385916},{"atb":[[19,0],[28,0]],"id":52385885},{"atb":[[9.2,0],[13,0]],"id":52385894},{"atb":[[9.2,0],[13,0]],"id":52385927},{"atb":[[4,0],[3.5,0]],"id":52385892},{"atb":[[9.6,0],[14,0]],"id":52385925},{"atb":[[10,0],[15,0]],"id":52385935},{"atb":[[5.1,0],[4.1,0]],"id":52385904},{"atb":[[90,1.18],[46,0]],"id":52385937},{"atb":[[550,0],[650,0]],"id":52385931},{"atb":[[3.45,0],[2.98,0]],"id":52385911},{"atb":[[2.82,0],[3.05,0]],"id":52385913},{"atb":[[16,0],[11,0]],"id":52385909},{"atb":[[550,0],[650,0]],"id":52385888},{"atb":[[90,0],[46,0]],"id":52385882},{"atb":[[7.4,0],[5.7,0]],"id":52385915},{"atb":[[50,0],[30,0]],"id":52385884},{"atb":[[18.5,0],[13.5,0]],"id":52385895},{"atb":[[7.4,0],[9.4,0]],"id":52385928},{"atb":[[4.3,0],[5.3,0]],"id":52385891},{"atb":[[550,0],[650,0]],"id":52385924},{"atb":[[18.5,0],[13.5,0]],"id":52385934},{"atb":[[32,0],[21,0]],"id":52385903},{"atb":[[85,0],[44,0]],"id":52385930},{"atb":[[19.5,0],[14.5,0]],"id":52385932}],"con":true,"img":false}]}
{"op":"mcm","clk":"11450134739","pt":1717318401349,"mc":[{"id":"1.229554927","rc":[{"atb":[[19.5,5.65],[14.5,18.06]],"id":52385910},{"atb":[[3,121.95],[3.5,41.81]],"id":52385906},{"atb":[[10.5,11],[8.2,33.87]],"id":52385908},{"atb":[[550,0.44],[650,0.16]],"id":52385887},{"atb":[[48,4.45],[29,8.71]],"id":52385889},{"atb":[[8.6,32.09],[11.5,9.95]],"id":52385916},{"atb":[[19,13.55],[28,3.87]],"id":52385885},{"atb":[[9.2,29.74],[13,8.71]],"id":52385894},{"atb":[[9.2,29.74],[13,8.71]],"id":52385927},{"atb":[[4,34.84],[3.5,97.56]],"id":52385892},{"atb":[[9.6,28.36],[14,8.04]],"id":52385925},{"atb":[[10,27.1],[15,7.46]],"id":52385935},{"atb":[[5.1,25.49],[4.1,78.68]],"id":52385904},{"atb":[[90,2.35],[46,5.42]],"id":52385937},{"atb":[[550,0.44],[650,0.16]],"id":52385931},{"atb":[[3.45,42.66],[2.98,123.18]],"id":52385911},{"atb":[[2.82,134.01],[3.05,50.98]],"id":52385913},{"atb":[[16,6.96],[11,24.39]],"id":52385909},{"atb":[[550,0.44],[650,0.16]],"id":52385888},{"atb":[[90,1.17],[46,5.42]],"id":52385882},{"atb":[[7.4,16.33],[5.7,51.89]],"id":52385915},{"atb":[[50,2.13],[30,8.41]],"id":52385884},{"atb":[[18.5,5.97],[13.5,19.51]],"id":52385895},{"atb":[[7.4,38.1],[9.4,12.44]],"id":52385928},{"atb":[[4.3,73.9],[5.3,24.31]],"id":52385891},{"atb":[[550,0.44],[650,0.16]],"id":52385924},{"atb":[[18.5,5.97],[13.5,19.51]],"id":52385934},{"atb":[[32,3.37],[21,12.19]],"id":52385903},{"atb":[[85,1.24],[44,5.67]],"id":52385930},{"atb":[[19.5,5.65],[14.5,18.06]],"id":52385932}],"con":true,"img":false}]}
{"op":"mcm","clk":"11450151413","pt":1717318589725,"mc":[{"id":"1.229554927","rc":[{"atb":[[17.5,0]],"id":52385894}],"con":true,"img":false}]}
{"op":"mcm","clk":"11450151423","pt":1717318589831,"mc":[{"id":"1.229554927","rc":[{"atb":[[20,0],[25,0],[30,0]],"id":52385894}],"con":true,"img":false}]}
{"op":"mcm","clk":"11450151487","pt":1717318590394,"mc":[{"id":"1.229554927","rc":[{"atb":[[18,6.15]],"id":52385894}],"con":true,"img":false}]}
{"op":"mcm","clk":"11450151501","pt":1717318590497,"mc":[{"id":"1.229554927","rc":[{"atb":[[32,0.84],[21,3.92],[26,2.09]],"id":52385894}],"con":true,"img":false}]}
{"op":"mcm","clk":"11450178834","pt":1717318876262,"mc":[{"id":"1.229554927","rc":[{"atb":[[2.74,0],[3.1,0],[2.94,0]],"id":52385913}],"con":true,"img":false}]}
{"op":"mcm","clk":"11450178843","pt":1717318876369,"mc":[{"id":"1.229554927","rc":[{"atb":[[2.84,0]],"id":52385913}],"con":true,"img":false}]}
{"op":"mcm","clk":"11450178915","pt":1717318876938,"mc":[{"id":"1.229554927","rc":[{"atb":[[3.2,11.89],[2.98,26.43],[2.78,58.78]],"id":52385913}],"con":true,"img":false}]}
{"op":"mcm","clk":"11450178925","pt":1717318877048,"mc":[{"id":"1.229554927","rc":[{"atb":[[2.88,41.74]],"id":52385913}],"con":true,"img":false}]}
{"op":"mcm","clk":"11450210817","pt":1717319206634,"mc":[{"id":"1.229554927","rc":[{"atb":[[9.6,0],[8.6,0],[11.5,0],[7.6,0]],"id":52385904},{"atb":[[32,0],[42,0],[26,0],[55,0]],"id":52385909}],"con":true,"img":false}]}
{"op":"mcm","clk":"11450210883","pt":1717319207310,"mc":[{"id":"1.229554927","rc":[{"atb":[[11,2.62],[7.4,16.35],[8.4,10.61],[9.4,6.23]],"id":52385904},{"atb":[[38,1.41],[48,0.55],[24,4.55],[29,2.8]],"id":52385909}],"con":true,"img":false}]}
{"op":"mcm","clk":"11450214753","pt":1717319245681,"mc":[{"id":"1.229554927","rc":[{"atb":[[19.5,0],[14.5,0]],"id":52385910},{"atb":[[3,0],[3.5,0]],"id":52385906},{"atb":[[10.5,0],[8.2,0]],"id":52385908},{"atb":[[550,0],[650,0]],"id":52385887},{"atb":[[48,2.23],[29,0]],"id":52385889},{"atb":[[8.6,0],[11.5,0]],"id":52385916},{"atb":[[19,0],[28,0]],"id":52385885},{"atb":[[9.2,0],[13,0]],"id":52385894},{"atb":[[9.2,0],[13,0]],"id":52385927},{"atb":[[4,0],[3.5,0]],"id":52385892},{"atb":[[9.6,0],[14,0]],"id":52385925},{"atb":[[10,0],[15,0]],"id":52385935},{"atb":[[5.1,0],[4.1,0]],"id":52385904},{"atb":[[90,1.18],[46,0]],"id":52385937},{"atb":[[550,0],[650,0]],"id":52385931},{"atb":[[3.45,0],[2.98,0]],"id":52385911},{"atb":[[2.82,0],[3.05,0]],"id":52385913},{"atb":[[16,0],[11,0]],"id":52385909},{"atb":[[550,0],[650,0]],"id":52385888},{"atb":[[90,0],[46,0]],"id":52385882},{"atb":[[7.4,0],[5.7,0]],"id":52385915},{"atb":[[50,0],[30,0]],"id":52385884},{"atb":[[18.5,0],[13.5,0]],"id":52385895},{"atb":[[7.4,0],[9.4,0]],"id":52385928},{"atb":[[4.3,0],[5.3,0]],"id":52385891},{"atb":[[550,0],[650,0]],"id":52385924},{"atb":[[18.5,0],[13.5,0]],"id":52385934},{"atb":[[32,0],[21,0]],"id":52385903},{"atb":[[85,0],[44,0]],"id":52385930},{"atb":[[19.5,0],[14.5,0]],"id":52385932}],"con":true,"img":false}]}
{"op":"mcm","clk":"11450214797","pt":1717319246148,"mc":[{"id":"1.229554927","rc":[{"atb":[[34,0],[44,0],[27,0],[60,0]],"id":52385935},{"atb":[[75,0],[40,0],[100,0],[50,0]],"id":52385932}],"con":true,"img":false}]}
{"op":"mcm","clk":"11450214885","pt":1717319246875,"mc":[{"id":"1.229554927","rc":[{"atb":[[32,2.53],[42,1.28],[26,4.19],[55,0.49]],"id":52385935},{"atb":[[65,0.82],[36,2.99],[90,0.29],[46,1.74]],"id":52385932}],"con":true,"img":false}]}
{"op":"mcm","clk":"11450218223","pt":1717319279103,"mc":[{"id":"1.229554927","rc":[{"atb":[[3,121.95],[3.5,41.81]],"id":52385906},{"atb":[[10.5,11],[8.2,33.87]],"id":52385908},{"atb":[[550,0.44],[650,0.16]],"id":52385887},{"atb":[[48,4.45],[29,8.71]],"id":52385889},{"atb":[[19,13.55],[28,3.87]],"id":52385885},{"atb":[[9.2,29.74],[13,8.71]],"id":52385894},{"atb":[[4,34.84],[3.5,97.56]],"id":52385892},{"atb":[[5.1,25.49],[4.1,78.68]],"id":52385904},{"atb":[[16,6.96],[11,24.39]],"id":52385909},{"atb":[[550,0.44],[650,0.16]],"id":52385888},{"atb":[[90,1.17],[46,5.42]],"id":52385882},{"atb":[[50,2.13],[30,8.41]],"id":52385884},{"atb":[[18.5,5.97],[13.5,19.51]],"id":52385895},{"atb":[[4.3,73.9],[5.3,24.31]],"id":52385891},{"atb":[[32,3.37],[21,12.19]],"id":52385903}],"con":true,"img":false}]}
{"op":"mcm","clk":"11450218252","pt":1717319279421,"mc":[{"id":"1.229554927","rc":[{"atb":[[19.5,5.65],[14.5,18.06]],"id":52385910},{"atb":[[8.6,32.09],[11.5,9.95]],"id":52385916},{"atb":[[9.2,29.74],[13,8.71]],"id":52385927},{"atb":[[9.6,28.36],[14,8.04]],"id":52385925},{"atb":[[10,27.1],[15,7.46]],"id":52385935},{"atb":[[90,2.35],[46,5.42]],"id":52385937},{"atb":[[550,0.44],[650,0.16]],"id":52385931},{"atb":[[3.45,42.66],[2.98,123.18]],"id":52385911},{"atb":[[2.82,134.01],[3.05,50.98]],"id":52385913},{"atb":[[7.4,16.33],[5.7,51.89]],"id":52385915},{"atb":[[7.4,38.1],[9.4,12.44]],"id":52385928},{"atb":[[550,0.44],[650,0.16]],"id":52385924},{"atb":[[18.5,5.97],[13.5,19.51]],"id":52385934},{"atb":[[85,1.24],[44,5.67]],"id":52385930},{"atb":[[19.5,5.65],[14.5,18.06]],"id":52385932}],"con":true,"img":false}]}
{"op":"mcm","clk":"11450232196","pt":1717319430046,"mc":[{"id":"1.229554927","rc":[{"atb":[[16,0],[18.5,0],[22,0],[13.5,0]],"id":52385916},{"atb":[[32,0],[18,0],[21,0],[26,0]],"id":52385894},{"atb":[[9.2,0],[10.5,0],[8.2,0],[13,0]],"id":52385915}],"con":true,"img":false}]}
{"op":"mcm","clk":"11450232273","pt":1717319430763,"mc":[{"id":"1.229554927","rc":[{"atb":[[16.5,5.06],[19,2.91],[23,1.19],[14,8.05]],"id":52385916},{"atb":[[17.5,6.34],[20,4.13],[25,2.18],[30,0.9]],"id":52385894},{"atb":[[11,5.23],[13.5,2.09],[8.4,14.14],[9.4,9.34]],"id":52385915}],"con":true,"img":false}]}
{"op":"mcm","clk":"11450234896","pt":1717319457388,"mc":[{"id":"1.229554927","rc":[{"atb":[[32,0],[42,0],[26,0]],"id":52385927},{"atb":[[3.2,0],[2.88,0],[2.98,0],[2.78,0]],"id":52385913},{"atb":[[11,0],[13.5,0],[8.4,0],[9.4,0]],"id":52385915}],"con":true,"img":false}]}
{"op":"mcm","clk":"11450234980","pt":1717319458173,"mc":[{"id":"1.229554927","rc":[{"atb":[[32,1.69],[42,0.64],[26,3.14]],"id":52385927},{"atb":[[4,17.44],[4.5,7.48],[3.5,41.85],[3.75,28.54]],"id":52385913},{"atb":[[6.8,13.53],[8.8,3.35],[7.8,7.7],[5.9,21.36]],"id":52385915}],"con":true,"img":false}]}
{"op":"mcm","clk":"11450237020","pt":1717319481299,"mc":[{"id":"1.229554927","rc":[{"atb":[[4,0],[4.5,0],[3.5,0],[3.75,0]],"id":52385913}],"con":true,"img":false}]}
{"op":"mcm","clk":"11450237088","pt":1717319482125,"mc":[{"id":"1.229554927","rc":[{"atb":[[3.45,42.71],[3.95,17.74],[3.7,29.07],[4.4,7.7]],"id":52385913}],"con":true,"img":false}]}
{"op":"mcm","clk":"11450239875","pt":1717319513065,"mc":[{"id":"1.229554927","rc":[{"atb":[[3.45,0],[3.95,0],[3.7,0],[4.4,0]],"id":52385913}],"con":true,"img":false}]}
{"op":"mcm","clk":"11450241317","pt":1717319527929,"mc":[{"id":"1.229554927","rc":[{"atb":[[4,17.44],[4.5,7.48],[3.5,41.85],[3.75,28.54]],"id":52385913}],"con":true,"img":false}]}
{"op":"mcm","clk":"11450244062","pt":1717319556948,"mc":[{"id":"1.229554927","rc":[{"atb":[[4,0],[4.5,0],[3.5,0],[3.75,0]],"id":52385913}],"con":true,"img":false}]}
{"op":"mcm","clk":"11450244132","pt":1717319557770,"mc":[{"id":"1.229554927","rc":[{"atb":[[3.45,42.71],[3.95,17.74],[3.7,29.07],[4.4,7.7]],"id":52385913}],"con":true,"img":false}]}
{"op":"mcm","clk":"11450279952","pt":1717319976351,"mc":[{"id":"1.229554927","rc":[{"atb":[[32,0],[42,0],[26,0]],"id":52385927}],"con":true,"img":false}]}
{"op":"mcm","clk":"11450280028","pt":1717319977177,"mc":[{"id":"1.229554927","rc":[{"atb":[[34,1.59],[44,0.61],[27,3.02]],"id":52385927}],"con":true,"img":false}]}
{"op":"mcm","clk":"11450280259","pt":1717319980371,"mc":[{"id":"1.229554927","rc":[{"atb":[[17.5,0],[20,0],[25,0],[30,0]],"id":52385894}],"con":true,"img":false}]}
{"op":"mcm","clk":"11450280305","pt":1717319981043,"mc":[{"id":"1.229554927","rc":[{"atb":[[32,0.84],[18,6.15],[21,3.92],[26,2.09]],"id":52385894}],"con":true,"img":false}]}
{"op":"mcm","clk":"11450280769","pt":1717319986778,"mc":[{"id":"1.229554927","rc":[{"atb":[[32,0],[18,0],[21,0],[26,0]],"id":52385894}],"con":true,"img":false}]}
{"op":"mcm","clk":"11450280827","pt":1717319987453,"mc":[{"id":"1.229554927","rc":[{"atb":[[17.5,6.34],[20,4.13],[25,2.18],[30,0.9]],"id":52385894}],"con":true,"img":false}]}
{"op":"mcm","clk":"11450286425","pt":1717320065083,"mc":[{"id":"1.229554927","rc":[{"atb":[[4.8,0],[5.8,0],[5.3,0],[6.6,0]],"id":52385906},{"atb":[[16,0],[18.5,0],[22,0],[27,0]],"id":52385928}],"con":true,"img":false}]}
{"op":"mcm","clk":"11450286469","pt":1717320065760,"mc":[{"id":"1.229554927","rc":[{"atb":[[6.8,4.51],[4.9,26.83],[5.9,10.68],[5.4,17.84]],"id":52385906},{"atb":[[16.5,6.75],[19,4.36],[23,2.38],[28,0.97]],"id":52385928}],"con":true,"img":false}]}
{"op":"mcm","clk":"11450286938","pt":1717320072982,"mc":[{"id":"1.229554927","rc":[{"atb":[[19.5,0],[14.5,0]],"id":52385910},{"atb":[[3,0],[3.5,0]],"id":52385906},{"atb":[[10.5,0],[8.2,0]],"id":52385908},{"atb":[[550,0],[650,0]],"id":52385887},{"atb":[[48,2.23],[29,0]],"id":52385889},{"atb":[[8.6,0],[11.5,0]],"id":52385916},{"atb":[[19,0],[28,0]],"id":52385885},{"atb":[[9.2,0],[13,0]],"id":52385894},{"atb":[[9.2,0],[13,0]],"id":52385927},{"atb":[[4,0],[3.5,0]],"id":52385892},{"atb":[[9.6,0],[14,0]],"id":52385925},{"atb":[[10,0],[15,0]],"id":52385935},{"atb":[[5.1,0],[4.1,0]],"id":52385904},{"atb":[[90,1.18],[46,0]],"id":52385937},{"atb":[[550,0],[650,0]],"id":52385931},{"atb":[[3.45,0],[2.98,0]],"id":52385911},{"atb":[[2.82,0],[3.05,0]],"id":52385913},{"atb":[[16,0],[11,0]],"id":52385909},{"atb":[[550,0],[650,0]],"id":52385888},{"atb":[[90,0],[46,0]],"id":52385882},{"atb":[[7.4,0],[5.7,0]],"id":52385915},{"atb":[[50,0],[30,0]],"id":52385884},{"atb":[[18.5,0],[13.5,0]],"id":52385895},{"atb":[[7.4,0],[9.4,0]],"id":52385928},{"atb":[[4.3,0],[5.3,0]],"id":52385891},{"atb":[[550,0],[650,0]],"id":52385924},{"atb":[[18.5,0],[13.5,0]],"id":52385934},{"atb":[[32,0],[21,0]],"id":52385903},{"atb":[[85,0],[44,0]],"id":52385930},{"atb":[[19.5,0],[14.5,0]],"id":52385932}],"con":true,"img":false}]}
{"op":"mcm","clk":"11450287958","pt":1717320087503,"mc":[{"id":"1.229554927","rc":[{"atb":[[19.5,5.65],[14.5,18.06]],"id":52385910},{"atb":[[8.6,32.09],[11.5,9.95]],"id":52385916},{"atb":[[9.2,29.74],[13,8.71]],"id":52385927},{"atb":[[9.6,28.36],[14,8.04]],"id":52385925},{"atb":[[10,27.1],[15,7.46]],"id":52385935},{"atb":[[90,2.35],[46,5.42]],"id":52385937},{"atb":[[550,0.44],[650,0.16]],"id":52385931},{"atb":[[3.45,42.66],[2.98,123.18]],"id":52385911},{"atb":[[2.82,134.01],[3.05,50.98]],"id":52385913},{"atb":[[7.4,16.33],[5.7,51.89]],"id":52385915},{"atb":[[7.4,38.1],[9.4,12.44]],"id":52385928},{"atb":[[550,0.44],[650,0.16]],"id":52385924},{"atb":[[18.5,5.97],[13.5,19.51]],"id":52385934},{"atb":[[85,1.24],[44,5.67]],"id":52385930},{"atb":[[19.5,5.65],[14.5,18.06]],"id":52385932}],"con":true,"img":false}]}
{"op":"mcm","clk":"11450287962","pt":1717320087597,"mc":[{"id":"1.229554927","rc":[{"atb":[[3,121.95],[3.5,41.81]],"id":52385906},{"atb":[[10.5,11],[8.2,33.87]],"id":52385908},{"atb":[[550,0.44],[650,0.16]],"id":52385887},{"atb":[[48,4.45],[29,8.71]],"id":52385889},{"atb":[[19,13.55],[28,3.87]],"id":52385885},{"atb":[[9.2,29.74],[13,8.71]],"id":52385894},{"atb":[[4,34.84],[3.5,97.56]],"id":52385892},{"atb":[[5.1,25.49],[4.1,78.68]],"id":52385904},{"atb":[[16,6.96],[11,24.39]],"id":52385909},{"atb":[[550,0.44],[650,0.16]],"id":52385888},{"atb":[[90,1.17],[46,5.42]],"id":52385882},{"atb":[[50,2.13],[30,8.41]],"id":52385884},{"atb":[[18.5,5.97],[13.5,19.51]],"id":52385895},{"atb":[[4.3,73.9],[5.3,24.31]],"id":52385891},{"atb":[[32,3.37],[21,12.19]],"id":52385903}],"con":true,"img":false}]}
{"op":"mcm","clk":"11450337156","pt":1717320708991,"mc":[{"id":"1.229554927","rc":[{"atb":[[16.5,0],[19,0],[23,0],[28,0]],"id":52385908}],"con":true,"img":false}]}
{"op":"mcm","clk":"11450337211","pt":1717320709665,"mc":[{"id":"1.229554927","rc":[{"atb":[[16,6.97],[18.5,4.48],[22,2.49],[27,1]],"id":52385908}],"con":true,"img":false}]}
{"op":"mcm","clk":"11450337367","pt":1717320711890,"mc":[{"id":"1.229554927","rc":[{"atb":[[16,0],[18.5,0],[22,0],[27,0]],"id":52385908}],"con":true,"img":false}]}
{"op":"mcm","clk":"11450337424","pt":1717320712572,"mc":[{"id":"1.229554927","rc":[{"atb":[[16.5,6.75],[19,4.36],[23,2.38],[28,0.97]],"id":52385908}],"con":true,"img":false}]}
{"op":"mcm","clk":"11450339659","pt":1717320739339,"mc":[{"id":"1.229554927","rc":[{"atb":[[16.5,0],[19,0],[23,0],[28,0]],"id":52385908}],"con":true,"img":false}]}
{"op":"mcm","clk":"11450339714","pt":1717320740014,"mc":[{"id":"1.229554927","rc":[{"atb":[[16,6.97],[18.5,4.48],[22,2.49],[27,1]],"id":52385908}],"con":true,"img":false}]}
{"op":"mcm","clk":"11450360425","pt":1717320990854,"mc":[{"id":"1.229554927","rc":[{"atb":[[19.5,0],[14.5,0]],"id":52385910},{"atb":[[3,0],[3.5,0]],"id":52385906},{"atb":[[10.5,0],[8.2,0]],"id":52385908},{"atb":[[550,0],[650,0]],"id":52385887},{"atb":[[48,2.23],[29,0]],"id":52385889},{"atb":[[8.6,0],[11.5,0]],"id":52385916},{"atb":[[19,0],[28,0]],"id":52385885},{"atb":[[9.2,0],[13,0]],"id":52385894},{"atb":[[9.2,0],[13,0]],"id":52385927},{"atb":[[4,0],[3.5,0]],"id":52385892},{"atb":[[9.6,0],[14,0]],"id":52385925},{"atb":[[10,0],[15,0]],"id":52385935},{"atb":[[5.1,0],[4.1,0]],"id":52385904},{"atb":[[90,1.18],[46,0]],"id":52385937},{"atb":[[550,0],[650,0]],"id":52385931},{"atb":[[3.45,0],[2.98,0]],"id":52385911},{"atb":[[2.82,0],[3.05,0]],"id":52385913},{"atb":[[16,0],[11,0]],"id":52385909},{"atb":[[550,0],[650,0]],"id":52385888},{"atb":[[90,0],[46,0]],"id":52385882},{"atb":[[7.4,0],[5.7,0]],"id":52385915},{"atb":[[50,0],[30,0]],"id":52385884},{"atb":[[18.5,0],[13.5,0]],"id":52385895},{"atb":[[7.4,0],[9.4,0]],"id":52385928},{"atb":[[4.3,0],[5.3,0]],"id":52385891},{"atb":[[550,0],[650,0]],"id":52385924},{"atb":[[18.5,0],[13.5,0]],"id":52385934},{"atb":[[32,0],[21,0]],"id":52385903},{"atb":[[85,0],[44,0]],"id":52385930},{"atb":[[19.5,0],[14.5,0]],"id":52385932}],"con":true,"img":false}]}
{"op":"mcm","clk":"11450362925","pt":1717321022537,"mc":[{"id":"1.229554927","rc":[{"atb":[[19.5,5.65],[14.5,18.06]],"id":52385910},{"atb":[[8.6,32.09],[11.5,9.95]],"id":52385916},{"atb":[[9.2,29.74],[13,8.71]],"id":52385927},{"atb":[[9.6,28.36],[14,8.04]],"id":52385925},{"atb":[[10,27.1],[15,7.46]],"id":52385935},{"atb":[[90,2.35],[46,5.42]],"id":52385937},{"atb":[[550,0.44],[650,0.16]],"id":52385931},{"atb":[[3.45,42.66],[2.98,123.18]],"id":52385911},{"atb":[[2.82,134.01],[3.05,50.98]],"id":52385913},{"atb":[[7.4,16.33],[5.7,51.89]],"id":52385915},{"atb":[[7.4,38.1],[9.4,12.44]],"id":52385928},{"atb":[[550,0.44],[650,0.16]],"id":52385924},{"atb":[[18.5,5.97],[13.5,19.51]],"id":52385934},{"atb":[[85,1.24],[44,5.67]],"id":52385930},{"atb":[[19.5,5.65],[14.5,18.06]],"id":52385932}],"con":true,"img":false}]}
{"op":"mcm","clk":"11450362936","pt":1717321022627,"mc":[{"id":"1.229554927","rc":[{"atb":[[3,121.95],[3.5,41.81]],"id":52385906},{"atb":[[10.5,11],[8.2,33.87]],"id":52385908},{"atb":[[550,0.44],[650,0.16]],"id":52385887},{"atb":[[48,4.45],[29,8.71]],"id":52385889},{"atb":[[19,13.55],[28,3.87]],"id":52385885},{"atb":[[9.2,29.74],[13,8.71]],"id":52385894},{"atb":[[4,34.84],[3.5,97.56]],"id":52385892},{"atb":[[5.1,25.49],[4.1,78.68]],"id":52385904},{"atb":[[16,6.96],[11,24.39]],"id":52385909},{"atb":[[550,0.44],[650,0.16]],"id":52385888},{"atb":[[90,1.17],[46,5.42]],"id":52385882},{"atb":[[50,2.13],[30,8.41]],"id":52385884},{"atb":[[18.5,5.97],[13.5,19.51]],"id":52385895},{"atb":[[4.3,73.9],[5.3,24.31]],"id":52385891},{"atb":[[32,3.37],[21,12.19]],"id":52385903}],"con":true,"img":false}]}
{"op":"mcm","clk":"11450372173","pt":1717321152276,"mc":[{"id":"1.229554927","rc":[{"atb":[[6.8,0],[4.9,0],[5.9,0],[5.4,0]],"id":52385906},{"atb":[[16,0],[18.5,0],[22,0],[27,0]],"id":52385908},{"atb":[[34,0],[44,0],[27,0]],"id":52385927}],"con":true,"img":false}]}
{"op":"mcm","clk":"11450372248","pt":1717321153260,"mc":[{"id":"1.229554927","rc":[{"atb":[[4.8,27.54],[5.8,10.9],[5.3,18.25],[6.6,4.67]],"id":52385906},{"atb":[[17.5,3.17],[20,1.38],[12.5,9.1],[15,5.6]],"id":52385908}],"con":true,"img":false}]}
{"op":"mcm","clk":"11450372257","pt":1717321153365,"mc":[{"id":"1.229554927","rc":[{"atb":[[32,1.69],[42,0.64],[26,3.14]],"id":52385927}],"con":true,"img":false}]}
{"op":"mcm","clk":"11450376953","pt":1717321229205,"mc":[{"id":"1.229554927","rc":[{"atb":[[16.5,0],[19,0],[23,0],[14,0]],"id":52385916},{"atb":[[32,0],[42,0],[26,0],[55,0]],"id":52385935},{"atb":[[130,0],[180,0],[90,1.17],[230,0]],"id":52385937},{"atb":[[38,0],[48,0],[24,0],[29,0]],"id":52385909},{"atb":[[65,0],[36,0],[90,0],[46,0]],"id":52385932}],"con":true,"img":false}]}
{"op":"mcm","clk":"11450377007","pt":1717321229882,"mc":[{"id":"1.229554927","rc":[{"atb":[[17.5,4.76],[20,2.75],[25,1.09],[15,7.48]],"id":52385916},{"atb":[[34,2.38],[44,1.22],[27,4.02],[60,0.44]],"id":52385935},{"atb":[[150,0.53],[200,0.26],[100,1.06],[250,0.1]],"id":52385937},{"atb":[[40,1.34],[50,0.53],[25,4.36],[30,2.71]],"id":52385909},{"atb":[[70,0.76],[38,2.83],[95,0.28],[48,1.67]],"id":52385932}],"con":true,"img":false}]}
{"op":"mcm","clk":"11450378801","pt":1717321260440,"mc":[{"id":"1.229554927","rc":[{"atb":[[27,3.85]],"id":52385910},{"atb":[[2.94,45.79]],"id":52385906},{"atl":[[240,2]],"id":52385906},{"atb":[[3.95,14.71]],"id":52385908},{"atl":[[500,2]],"id":52385908},{"atb":[[29,2]],"id":52385887},{"atb":[[29,12.28]],"id":52385889},{"atb":[[6,12.24]],"id":52385916},{"atl":[[600,2]],"id":52385916},{"atb":[[29,3.57]],"id":52385885},{"atb":[[5.4,10.48]],"id":52385894},{"atl":[[560,2]],"id":52385894},{"atb":[[6.8,8.38]],"id":52385927},{"atl":[[720,2]],"id":52385927},{"atb":[[3.5,137.56]],"id":52385892},{"atl":[[410,2]],"id":52385892},{"atb":[[7.2,7.67]],"id":52385925},{"atl":[[800,2]],"id":52385925},{"atb":[[25,4.17]],"id":52385935},{"atl":[[1000,2]],"id":52385935},{"atb":[[3.4,26.96]],"id":52385904},{"atl":[[370,2]],"id":52385904},{"atb":[[27,2]],"id":52385937},{"atb":[[30,2]],"id":52385931},{"atb":[[2.7,58.82]],"id":52385911},{"atl":[[150,2]],"id":52385911},{"atb":[[2.42,70.42]],"id":52385913},{"atl":[[75,2]],"id":52385913},{"atb":[[7.8,7.07]],"id":52385909},{"atl":[[830,2]],"id":52385909},{"atb":[[30,2]],"id":52385888},{"atb":[[29,2]],"id":52385882},{"atb":[[3.3,29.86]],"id":52385915},{"atl":[[350,2]],"id":52385915},{"atb":[[29,2]],"id":52385884},{"atb":[[1.35,6.73]],"id":52385895},{"atl":[[1000,2]],"id":52385895},{"atb":[[6.4,11.11]],"id":52385928},{"atl":[[660,2]],"id":52385928},{"atb":[[3.7,26.19]],"id":52385891},{"atl":[[430,2]],"id":52385891},{"atb":[[29,2]],"id":52385924},{"atb":[[26,4]],"id":52385934},{"atb":[[28,3.7]],"id":52385903},{"atb":[[27,2.09]],"id":52385930},{"atb":[[1.35,4.51]],"id":52385932}],"con":true,"img":false}]}
{"op":"mcm","clk":"11450379602","pt":1717321271933,"mc":[{"id":"1.229554927","rc":[{"atb":[[2.94,0]],"id":52385906}],"con":true,"img":false}]}
{"op":"mcm","clk":"11450379611","pt":1717321272033,"mc":[{"id":"1.229554927","rc":[{"atb":[[2.82,54.95]],"id":52385906}],"con":true,"img":false}]}
{"op":"mcm","clk":"11450382311","pt":1717321314481,"mc":[{"id":"1.229554927","rc":[{"atb":[[19.5,0],[14.5,0]],"id":52385910},{"atb":[[3,0],[3.5,0]],"id":52385906},{"atb":[[10.5,0],[8.2,0]],"id":52385908},{"atb":[[550,0],[650,0]],"id":52385887},{"atb":[[48,2.23],[29,3.57]],"id":52385889},{"atb":[[8.6,0],[11.5,0]],"id":52385916},{"atb":[[19,0],[28,0]],"id":52385885},{"atb":[[9.2,0],[13,0]],"id":52385894},{"atb":[[9.2,0],[13,0]],"id":52385927},{"atb":[[4,0],[3.5,40]],"id":52385892},{"atb":[[9.6,0],[14,0]],"id":52385925},{"atb":[[10,0],[15,0]],"id":52385935},{"atb":[[5.1,0],[4.1,0]],"id":52385904},{"atb":[[90,0],[46,0]],"id":52385937},{"atb":[[550,0],[650,0]],"id":52385931},{"atb":[[3.45,0],[2.98,0]],"id":52385911},{"atb":[[2.82,0],[3.05,0]],"id":52385913},{"atb":[[16,0],[11,0]],"id":52385909},{"atb":[[550,0],[650,0]],"id":52385888},{"atb":[[90,0],[46,0]],"id":52385882},{"atb":[[7.4,0],[5.7,0]],"id":52385915},{"atb":[[50,0],[30,0]],"id":52385884},{"atb":[[18.5,0],[13.5,0]],"id":52385895},{"atb":[[7.4,0],[9.4,0]],"id":52385928},{"atb":[[4.3,0],[5.3,0]],"id":52385891},{"atb":[[550,0],[650,0]],"id":52385924},{"atb":[[18.5,0],[13.5,0]],"id":52385934},{"atb":[[32,0],[21,0]],"id":52385903},{"atb":[[85,0],[44,0]],"id":52385930},{"atb":[[19.5,0],[14.5,0]],"id":52385932}],"con":true,"img":false}]}
{"op":"mcm","clk":"11450384115","pt":1717321343797,"mc":[{"id":"1.229554927","rc":[{"atb":[[3,121.95],[3.5,41.81]],"id":52385906},{"atb":[[10.5,11],[8.2,33.87]],"id":52385908},{"atb":[[550,0.44],[650,0.16]],"id":52385887},{"atb":[[48,4.45],[29,12.28]],"id":52385889},{"atb":[[19,13.55],[28,3.87]],"id":52385885},{"atb":[[9.2,29.74],[13,8.71]],"id":52385894},{"atb":[[4,34.84],[3.5,137.56]],"id":52385892},{"atb":[[5.1,25.49],[4.1,78.68]],"id":52385904},{"atb":[[16,6.96],[11,24.39]],"id":52385909},{"atb":[[550,0.44],[650,0.16]],"id":52385888},{"atb":[[90,1.17],[46,5.42]],"id":52385882},{"atb":[[50,2.13],[30,8.41]],"id":52385884},{"atb":[[18.5,5.97],[13.5,19.51]],"id":52385895},{"atb":[[4.3,73.9],[5.3,24.31]],"id":52385891},{"atb":[[32,3.37],[21,12.19]],"id":52385903}],"con":true,"img":false}]}
{"op":"mcm","clk":"11450384130","pt":1717321343906,"mc":[{"id":"1.229554927","rc":[{"atb":[[19.5,5.65],[14.5,18.06]],"id":52385910},{"atb":[[8.6,32.09],[11.5,9.95]],"id":52385916},{"atb":[[9.2,29.74],[13,8.71]],"id":52385927},{"atb":[[9.6,28.36],[14,8.04]],"id":52385925},{"atb":[[10,27.1],[15,7.46]],"id":52385935},{"atb":[[90,1.17],[46,5.42]],"id":52385937},{"atb":[[550,0.44],[650,0.16]],"id":52385931},{"atb":[[3.45,42.66],[2.98,123.18]],"id":52385911},{"atb":[[2.82,134.01],[3.05,50.98]],"id":52385913},{"atb":[[7.4,16.33],[5.7,51.89]],"id":52385915},{"atb":[[7.4,38.1],[9.4,12.44]],"id":52385928},{"atb":[[550,0.44],[650,0.16]],"id":52385924},{"atb":[[18.5,5.97],[13.5,19.51]],"id":52385934},{"atb":[[85,1.24],[44,5.67]],"id":52385930},{"atb":[[19.5,5.65],[14.5,18.06]],"id":52385932}],"con":true,"img":false}]}
{"op":"mcm","clk":"11450395855","pt":1717321529681,"mc":[{"id":"1.229554927","rc":[{"atb":[[4.8,0],[5.8,0],[5.3,0],[6.6,0]],"id":52385906}],"con":true,"img":false}]}
{"op":"mcm","clk":"11450395914","pt":1717321530353,"mc":[{"id":"1.229554927","rc":[{"atb":[[6.8,4.51],[4.9,26.83],[5.9,10.68],[5.4,17.84]],"id":52385906}],"con":true,"img":false}]}
{"op":"mcm","clk":"11450406735","pt":1717321679445,"mc":[{"id":"1.229554927","rc":[{"atb":[[19.5,0],[14.5,0]],"id":52385910},{"atb":[[3,0],[3.5,0]],"id":52385906},{"atb":[[10.5,0],[8.2,0]],"id":52385908},{"atb":[[550,0],[650,0]],"id":52385887},{"atb":[[48,2.23],[29,3.57]],"id":52385889},{"atb":[[8.6,0],[11.5,0]],"id":52385916},{"atb":[[19,0],[28,0]],"id":52385885},{"atb":[[9.2,0],[13,0]],"id":52385894},{"atb":[[9.2,0],[13,0]],"id":52385927},{"atb":[[4,0],[3.5,40]],"id":52385892},{"atb":[[9.6,0],[14,0]],"id":52385925},{"atb":[[10,0],[15,0]],"id":52385935},{"atb":[[5.1,0],[4.1,0]],"id":52385904},{"atb":[[90,0],[46,0]],"id":52385937},{"atb":[[550,0],[650,0]],"id":52385931},{"atb":[[3.45,0],[2.98,0]],"id":52385911},{"atb":[[2.82,0],[3.05,0]],"id":52385913},{"atb":[[16,0],[11,0]],"id":52385909},{"atb":[[550,0],[650,0]],"id":52385888},{"atb":[[90,0],[46,0]],"id":52385882},{"atb":[[7.4,0],[5.7,0]],"id":52385915},{"atb":[[50,0],[30,0]],"id":52385884},{"atb":[[18.5,0],[13.5,0]],"id":52385895},{"atb":[[7.4,0],[9.4,0]],"id":52385928},{"atb":[[4.3,0],[5.3,0]],"id":52385891},{"atb":[[550,0],[650,0]],"id":52385924},{"atb":[[18.5,0],[13.5,0]],"id":52385934},{"atb":[[32,0],[21,0]],"id":52385903},{"atb":[[85,0],[44,0]],"id":52385930},{"atb":[[19.5,0],[14.5,0]],"id":52385932}],"con":true,"img":false}]}
{"op":"mcm","clk":"11450408949","pt":1717321709095,"mc":[{"id":"1.229554927","rc":[{"atb":[[19.5,5.65],[14.5,18.06]],"id":52385910},{"atb":[[8.6,32.09],[11.5,9.95]],"id":52385916},{"atb":[[9.2,29.74],[13,8.71]],"id":52385927},{"atb":[[9.6,28.36],[14,8.04]],"id":52385925},{"atb":[[10,27.1],[15,7.46]],"id":52385935},{"atb":[[90,1.17],[46,5.42]],"id":52385937},{"atb":[[550,0.44],[650,0.16]],"id":52385931},{"atb":[[3.45,42.66],[2.98,123.18]],"id":52385911},{"atb":[[2.82,134.01],[3.05,50.98]],"id":52385913},{"atb":[[7.4,16.33],[5.7,51.89]],"id":52385915},{"atb":[[7.4,38.1],[9.4,12.44]],"id":52385928},{"atb":[[550,0.44],[650,0.16]],"id":52385924},{"atb":[[18.5,5.97],[13.5,19.51]],"id":52385934},{"atb":[[85,1.24],[44,5.67]],"id":52385930},{"atb":[[19.5,5.65],[14.5,18.06]],"id":52385932}],"con":true,"img":false}]}
{"op":"mcm","clk":"11450408957","pt":1717321709206,"mc":[{"id":"1.229554927","rc":[{"atb":[[3,121.95],[3.5,41.81]],"id":52385906},{"atb":[[10.5,11],[8.2,33.87]],"id":52385908},{"atb":[[550,0.44],[650,0.16]],"id":52385887},{"atb":[[48,4.45],[29,12.28]],"id":52385889},{"atb":[[19,13.55],[28,3.87]],"id":52385885},{"atb":[[9.2,29.74],[13,8.71]],"id":52385894},{"atb":[[4,34.84],[3.5,137.56]],"id":52385892},{"atb":[[5.1,25.49],[4.1,78.68]],"id":52385904},{"atb":[[16,6.96],[11,24.39]],"id":52385909},{"atb":[[550,0.44],[650,0.16]],"id":52385888},{"atb":[[90,1.17],[46,5.42]],"id":52385882},{"atb":[[50,2.13],[30,8.41]],"id":52385884},{"atb":[[18.5,5.97],[13.5,19.51]],"id":52385895},{"atb":[[4.3,73.9],[5.3,24.31]],"id":52385891},{"atb":[[32,3.37],[21,12.19]],"id":52385903}],"con":true,"img":false}]}
{"op":"mcm","clk":"11450416407","pt":1717321796111,"mc":[{"id":"1.229554927","rc":[{"atb":[[17.5,0],[20,0],[25,0],[15,0]],"id":52385916},{"atb":[[40,0],[50,0],[25,0],[30,0]],"id":52385909}],"con":true,"img":false}]}
{"op":"mcm","clk":"11450416478","pt":1717321796889,"mc":[{"id":"1.229554927","rc":[{"atb":[[16.5,5.06],[19,2.91],[23,1.19],[14,8.05]],"id":52385916},{"atb":[[36,1.5],[46,0.58],[23,4.76],[28,2.91]],"id":52385909}],"con":true,"img":false}]}
{"op":"mcm","clk":"11450430400","pt":1717321954043,"mc":[{"id":"1.229554927","rc":[{"atb":[[6.8,0],[4.9,0],[5.9,0],[5.4,0]],"id":52385906},{"atb":[[32,0],[42,0],[26,0]],"id":52385927},{"atb":[[36,0],[46,0],[23,0],[28,0]],"id":52385909}],"con":true,"img":false}]}
{"op":"mcm","clk":"11450430466","pt":1717321954726,"mc":[{"id":"1.229554927","rc":[{"atb":[[34,1.59],[44,0.61],[27,3.02]],"id":52385927},{"atb":[[38,1.41],[48,0.55],[24,4.55],[29,2.8]],"id":52385909}],"con":true,"img":false}]}
{"op":"mcm","clk":"11450430475","pt":1717321954819,"mc":[{"id":"1.229554927","rc":[{"atb":[[4.8,27.54],[5.8,10.9],[5.3,18.25],[6.6,4.67]],"id":52385906}],"con":true,"img":false}]}
{"op":"mcm","clk":"11450430662","pt":1717321956900,"mc":[{"id":"1.229554927","rc":[{"atb":[[4.8,0],[5.8,0],[5.3,0],[6.6,0]],"id":52385906}],"con":true,"img":false}]}
{"op":"mcm","clk":"11450430706","pt":1717321957626,"mc":[{"id":"1.229554927","rc":[{"atb":[[6.8,4.51],[4.9,26.83],[5.9,10.68],[5.4,17.84]],"id":52385906}],"con":true,"img":false}]}
{"op":"mcm","clk":"11450430969","pt":1717321960810,"mc":[{"id":"1.229554927","rc":[{"atb":[[34,0],[44,0],[27,0]],"id":52385927}],"con":true,"img":false}]}
{"op":"mcm","clk":"11450431027","pt":1717321961527,"mc":[{"id":"1.229554927","rc":[{"atb":[[32,1.69],[42,0.64],[26,3.14]],"id":52385927}],"con":true,"img":false}]}
{"op":"mcm","clk":"11450433788","pt":1717321996677,"mc":[{"id":"1.229554927","rc":[{"atb":[[6.8,0],[4.9,0],[5.9,0],[5.4,0]],"id":52385906}],"con":true,"img":false}]}
{"op":"mcm","clk":"11450433857","pt":1717321997390,"mc":[{"id":"1.229554927","rc":[{"atb":[[4.8,27.54],[5.8,10.9],[5.3,18.25],[6.6,4.67]],"id":52385906}],"con":true,"img":false}]}
{"op":"mcm","clk":"11450433905","pt":1717321997965,"mc":[{"id":"1.229554927","rc":[{"atb":[[140,0],[70,0],[95,0],[48,2.22]],"id":52385889},{"atb":[[140,0],[70,0],[190,0],[95,0]],"id":52385885},{"atb":[[270,0],[320,0],[170,0],[220,0]],"id":52385882},{"atb":[[300,0],[150,0],[200,0],[250,0]],"id":52385884},{"atb":[[130,0],[65,0],[90,0],[46,0]],"id":52385903}],"con":true,"img":false}]}
{"op":"mcm","clk":"11450433917","pt":1717321998167,"mc":[{"id":"1.229554927","rc":[{"atb":[[27,3.85],[29,0]],"id":52385885},{"atb":[[26,4],[28,0]],"id":52385903}],"con":true,"img":false}]}
{"op":"mcm","clk":"11450433957","pt":1717321998691,"mc":[{"id":"1.229554927","rc":[{"atb":[[160,0.16],[80,0.99],[110,0.48],[55,1.94]],"id":52385889},{"atb":[[170,0.31],[85,1.25],[220,0.12],[120,0.66]],"id":52385885},{"atb":[[260,0.3],[310,0.17],[360,0.07],[210,0.5]],"id":52385882},{"atb":[[290,0.18],[340,0.08],[190,0.55],[240,0.33]],"id":52385884},{"atb":[[140,0.19],[70,1.14],[95,0.55],[48,2.23]],"id":52385903}],"con":true,"img":false}]}
{"op":"mcm","clk":"11450438283","pt":1717322047773,"mc":[{"id":"1.229554927","rc":[{"atb":[[2.82,0],[2.92,52.08]],"id":52385906},{"atl":[[230,2],[240,0]],"id":52385906},{"atl":[[490,2],[500,0]],"id":52385908},{"atl":[[600,0],[590,2]],"id":52385916},{"atl":[[720,0],[710,2]],"id":52385927},{"atl":[[70,2],[75,0]],"id":52385913},{"atl":[[830,0],[820,2]],"id":52385909},{"atl":[[350,0],[340,2]],"id":52385915},{"atl":[[660,0],[650,2]],"id":52385928}],"con":true,"img":false}]}
{"op":"mcm","clk":"11450438314","pt":1717322048088,"mc":[{"id":"1.229554927","rc":[{"atb":[[17.5,0],[20,0],[12.5,0],[15,0]],"id":52385908}],"con":true,"img":false}]}
{"op":"mcm","clk":"11450438375","pt":1717322048763,"mc":[{"id":"1.229554927","rc":[{"atb":[[17,3.27],[19.5,1.41],[12,9.51],[14.5,5.81]],"id":52385908}],"con":true,"img":false}]}
{"op":"mcm","clk":"11450440032","pt":1717322066690,"mc":[{"id":"1.229554927","rc":[{"atb":[[19.5,0],[14.5,0]],"id":52385910},{"atb":[[3,0],[3.5,0]],"id":52385906},{"atb":[[10.5,0],[8.2,0]],"id":52385908},{"atb":[[550,0],[650,0]],"id":52385887},{"atb":[[48,0],[29,3.57]],"id":52385889},{"atb":[[8.6,0],[11.5,0]],"id":52385916},{"atb":[[19,0],[28,0]],"id":52385885},{"atb":[[9.2,0],[13,0]],"id":52385894},{"atb":[[9.2,0],[13,0]],"id":52385927},{"atb":[[4,0],[3.5,40]],"id":52385892},{"atb":[[9.6,0],[14,0]],"id":52385925},{"atb":[[10,0],[15,0]],"id":52385935},{"atb":[[5.1,0],[4.1,0]],"id":52385904},{"atb":[[90,0],[46,0]],"id":52385937},{"atb":[[550,0],[650,0]],"id":52385931},{"atb":[[3.45,0],[2.98,0]],"id":52385911},{"atb":[[2.82,0],[3.05,0]],"id":52385913},{"atb":[[16,0],[11,0]],"id":52385909},{"atb":[[550,0],[650,0]],"id":52385888},{"atb":[[90,0],[46,0]],"id":52385882},{"atb":[[7.4,0],[5.7,0]],"id":52385915},{"atb":[[50,0],[30,0]],"id":52385884},{"atb":[[18.5,0],[13.5,0]],"id":52385895},{"atb":[[7.4,0],[9.4,0]],"id":52385928},{"atb":[[4.3,0],[5.3,0]],"id":52385891},{"atb":[[550,0],[650,0]],"id":52385924},{"atb":[[18.5,0],[13.5,0]],"id":52385934},{"atb":[[32,0],[21,0]],"id":52385903},{"atb":[[85,0],[44,0]],"id":52385930},{"atb":[[19.5,0],[14.5,0]],"id":52385932}],"con":true,"img":false}]}
{"op":"mcm","clk":"11450441787","pt":1717322083512,"mc":[{"id":"1.229554927","rc":[{"atb":[[19.5,5.65],[14.5,18.06]],"id":52385910},{"atb":[[3,121.95],[3.5,41.81]],"id":52385906},{"atb":[[10.5,11],[8.2,33.87]],"id":52385908},{"atb":[[550,0.44],[650,0.16]],"id":52385887},{"atb":[[48,2.22],[29,12.28]],"id":52385889},{"atb":[[8.6,32.09],[11.5,9.95]],"id":52385916},{"atb":[[19,13.55],[28,3.87]],"id":52385885},{"atb":[[9.2,29.74],[13,8.71]],"id":52385894},{"atb":[[9.2,29.74],[13,8.71]],"id":52385927},{"atb":[[4,34.84],[3.5,137.56]],"id":52385892},{"atb":[[9.6,28.36],[14,8.04]],"id":52385925},{"atb":[[10,27.1],[15,7.46]],"id":52385935},{"atb":[[5.1,25.49],[4.1,78.68]],"id":52385904},{"atb":[[90,1.17],[46,5.42]],"id":52385937},{"atb":[[550,0.44],[650,0.16]],"id":52385931},{"atb":[[3.45,42.66],[2.98,123.18]],"id":52385911},{"atb":[[2.82,134.01],[3.05,50.98]],"id":52385913},{"atb":[[16,6.96],[11,24.39]],"id":52385909},{"atb":[[550,0.44],[650,0.16]],"id":52385888},{"atb":[[90,1.17],[46,5.42]],"id":52385882},{"atb":[[7.4,16.33],[5.7,51.89]],"id":52385915},{"atb":[[50,2.13],[30,8.41]],"id":52385884},{"atb":[[18.5,5.97],[13.5,19.51]],"id":52385895},{"atb":[[7.4,38.1],[9.4,12.44]],"id":52385928},{"atb":[[4.3,73.9],[5.3,24.31]],"id":52385891},{"atb":[[550,0.44],[650,0.16]],"id":52385924},{"atb":[[18.5,5.97],[13.5,19.51]],"id":52385934},{"atb":[[32,3.37],[21,12.19]],"id":52385903},{"atb":[[85,1.24],[44,5.67]],"id":52385930},{"atb":[[19.5,5.65],[14.5,18.06]],"id":52385932}],"con":true,"img":false}]}
{"op":"mcm","clk":"11450463905","pt":1717322335614,"mc":[{"id":"1.229554927","rc":[{"atb":[[17,0],[19.5,0],[12,0],[14.5,0]],"id":52385908}],"con":true,"img":false}]}
{"op":"mcm","clk":"11450463985","pt":1717322336336,"mc":[{"id":"1.229554927","rc":[{"atb":[[17.5,3.17],[20,1.38],[12.5,9.1],[15,5.6]],"id":52385908}],"con":true,"img":false}]}
{"op":"mcm","clk":"11450475547","pt":1717322460095,"mc":[{"id":"1.229554927","rc":[{"atb":[[16.5,0],[19,0],[23,0],[14,0]],"id":52385916},{"atb":[[38,0],[48,0],[24,0],[29,0]],"id":52385909}],"con":true,"img":false}]}
{"op":"mcm","clk":"11450475636","pt":1717322460906,"mc":[{"id":"1.229554927","rc":[{"atb":[[17.5,4.76],[20,2.75],[25,1.09],[15,7.48]],"id":52385916},{"atb":[[40,1.34],[50,0.53],[25,4.36],[30,2.71]],"id":52385909}],"con":true,"img":false}]}
{"op":"mcm","clk":"11450476587","pt":1717322471333,"mc":[{"id":"1.229554927","rc":[{"atb":[[19.5,0],[14.5,0]],"id":52385910},{"atb":[[3,0],[3.5,0]],"id":52385906},{"atb":[[10.5,0],[8.2,0]],"id":52385908},{"atb":[[550,0],[650,0]],"id":52385887},{"atb":[[48,0],[29,3.57]],"id":52385889},{"atb":[[8.6,0],[11.5,0]],"id":52385916},{"atb":[[19,0],[28,0]],"id":52385885},{"atb":[[9.2,0],[13,0]],"id":52385894},{"atb":[[9.2,0],[13,0]],"id":52385927},{"atb":[[4,0],[3.5,40]],"id":52385892},{"atb":[[9.6,0],[14,0]],"id":52385925},{"atb":[[10,0],[15,0]],"id":52385935},{"atb":[[5.1,0],[4.1,0]],"id":52385904},{"atb":[[90,0],[46,0]],"id":52385937},{"atb":[[550,0],[650,0]],"id":52385931},{"atb":[[3.45,0],[2.98,0]],"id":52385911},{"atb":[[2.82,0],[3.05,0]],"id":52385913},{"atb":[[16,0],[11,0]],"id":52385909},{"atb":[[550,0],[650,0]],"id":52385888},{"atb":[[90,0],[46,0]],"id":52385882},{"atb":[[7.4,0],[5.7,0]],"id":52385915},{"atb":[[50,0],[30,0]],"id":52385884},{"atb":[[18.5,0],[13.5,0]],"id":52385895},{"atb":[[7.4,0],[9.4,0]],"id":52385928},{"atb":[[4.3,0],[5.3,0]],"id":52385891},{"atb":[[550,0],[650,0]],"id":52385924},{"atb":[[18.5,0],[13.5,0]],"id":52385934},{"atb":[[32,0],[21,0]],"id":52385903},{"atb":[[85,0],[44,0]],"id":52385930},{"atb":[[19.5,0],[14.5,0]],"id":52385932}],"con":true,"img":false}]}
{"op":"mcm","clk":"11450478952","pt":1717322501181,"mc":[{"id":"1.229554927","rc":[{"atb":[[3,121.95],[3.5,41.81]],"id":52385906},{"atb":[[10.5,11],[8.2,33.87]],"id":52385908},{"atb":[[550,0.44],[650,0.16]],"id":52385887},{"atb":[[48,2.22],[29,12.28]],"id":52385889},{"atb":[[19,13.55],[28,3.87]],"id":52385885},{"atb":[[9.2,29.74],[13,8.71]],"id":52385894},{"atb":[[4,34.84],[3.5,137.56]],"id":52385892},{"atb":[[5.1,25.49],[4.1,78.68]],"id":52385904},{"atb":[[16,6.96],[11,24.39]],"id":52385909},{"atb":[[550,0.44],[650,0.16]],"id":52385888},{"atb":[[90,1.17],[46,5.42]],"id":52385882},{"atb":[[50,2.13],[30,8.41]],"id":52385884},{"atb":[[18.5,5.97],[13.5,19.51]],"id":52385895},{"atb":[[4.3,73.9],[5.3,24.31]],"id":52385891},{"atb":[[32,3.37],[21,12.19]],"id":52385903}],"con":true,"img":false}]}
{"op":"mcm","clk":"11450478960","pt":1717322501228,"mc":[{"id":"1.229554927","rc":[{"atb":[[19.5,5.65],[14.5,18.06]],"id":52385910},{"atb":[[8.6,32.09],[11.5,9.95]],"id":52385916},{"atb":[[9.2,29.74],[13,8.71]],"id":52385927},{"atb":[[9.6,28.36],[14,8.04]],"id":52385925},{"atb":[[10,27.1],[15,7.46]],"id":52385935},{"atb":[[90,1.17],[46,5.42]],"id":52385937},{"atb":[[550,0.44],[650,0.16]],"id":52385931},{"atb":[[3.45,42.66],[2.98,123.18]],"id":52385911},{"atb":[[2.82,134.01],[3.05,50.98]],"id":52385913},{"atb":[[7.4,16.33],[5.7,51.89]],"id":52385915},{"atb":[[7.4,38.1],[9.4,12.44]],"id":52385928},{"atb":[[550,0.44],[650,0.16]],"id":52385924},{"atb":[[18.5,5.97],[13.5,19.51]],"id":52385934},{"atb":[[85,1.24],[44,5.67]],"id":52385930},{"atb":[[19.5,5.65],[14.5,18.06]],"id":52385932}],"con":true,"img":false}]}
{"op":"mcm","clk":"11450481136","pt":1717322527904,"mc":[{"id":"1.229554927","rc":[{"atb":[[19.5,0],[14.5,0]],"id":52385910},{"atb":[[3,0],[3.5,0]],"id":52385906},{"atb":[[10.5,0],[8.2,0]],"id":52385908},{"atb":[[550,0],[650,0]],"id":52385887},{"atb":[[48,0],[29,3.57]],"id":52385889},{"atb":[[8.6,0],[11.5,0]],"id":52385916},{"atb":[[19,0],[28,0]],"id":52385885},{"atb":[[9.2,0],[13,0]],"id":52385894},{"atb":[[9.2,0],[13,0]],"id":52385927},{"atb":[[4,0],[3.5,40]],"id":52385892},{"atb":[[9.6,0],[14,0]],"id":52385925},{"atb":[[10,0],[15,0]],"id":52385935},{"atb":[[5.1,0],[4.1,0]],"id":52385904},{"atb":[[90,0],[46,0]],"id":52385937},{"atb":[[550,0],[650,0]],"id":52385931},{"atb":[[3.45,0],[2.98,0]],"id":52385911},{"atb":[[2.82,0],[3.05,0]],"id":52385913},{"atb":[[16,0],[11,0]],"id":52385909},{"atb":[[550,0],[650,0]],"id":52385888},{"atb":[[90,0],[46,0]],"id":52385882},{"atb":[[7.4,0],[5.7,0]],"id":52385915},{"atb":[[50,0],[30,0]],"id":52385884},{"atb":[[18.5,0],[13.5,0]],"id":52385895},{"atb":[[7.4,0],[9.4,0]],"id":52385928},{"atb":[[4.3,0],[5.3,0]],"id":52385891},{"atb":[[550,0],[650,0]],"id":52385924},{"atb":[[18.5,0],[13.5,0]],"id":52385934},{"atb":[[32,0],[21,0]],"id":52385903},{"atb":[[85,0],[44,0]],"id":52385930},{"atb":[[19.5,0],[14.5,0]],"id":52385932}],"con":true,"img":false}]}
{"op":"mcm","clk":"11450482356","pt":1717322542828,"mc":[{"id":"1.229554927","rc":[{"atb":[[19,5.8],[14,18.76]],"id":52385910},{"atb":[[3,121.95],[3.5,41.81]],"id":52385906},{"atb":[[8,34.84],[10,11.61]],"id":52385908},{"atb":[[550,0.44],[650,0.16]],"id":52385887},{"atb":[[42,2.54],[26,9.75]],"id":52385889},{"atb":[[10.5,11],[8.2,33.87]],"id":52385916},{"atb":[[18.5,13.93],[27,7.86]],"id":52385885},{"atb":[[9.2,29.74],[13,8.71]],"id":52385894},{"atb":[[9.2,29.74],[13,8.71]],"id":52385927},{"atb":[[4.1,33.71],[3.55,95.64]],"id":52385892},{"atb":[[9.6,28.36],[14,8.04]],"id":52385925},{"atb":[[9.8,27.71],[14.5,7.74]],"id":52385935},{"atb":[[5.1,25.49],[4.1,78.68]],"id":52385904},{"atb":[[70,1.51],[38,6.59]],"id":52385937},{"atb":[[550,0.44],[650,0.16]],"id":52385931},{"atb":[[3,174.27],[3.5,62.74]],"id":52385911},{"atb":[[3.1,49.77],[2.84,132.55]],"id":52385913},{"atb":[[10.5,25.67],[15.5,7.2]],"id":52385909},{"atb":[[550,0.44],[650,0.16]],"id":52385888},{"atb":[[70,1.51],[38,6.59]],"id":52385882},{"atb":[[7.4,16.33],[5.7,51.89]],"id":52385915},{"atb":[[44,2.43],[27,9.38]],"id":52385884},{"atb":[[17.5,6.33],[12.5,21.2]],"id":52385895},{"atb":[[7.4,38.1],[9.4,12.44]],"id":52385928},{"atb":[[4.3,73.9],[5.3,24.31]],"id":52385891},{"atb":[[550,0.44],[650,0.16]],"id":52385924},{"atb":[[18,6.14],[13,20.32]],"id":52385934},{"atb":[[19.5,13.18],[29,3.73]],"id":52385903},{"atb":[[65,1.63],[36,6.96]],"id":52385930},{"atb":[[19,5.8],[14,18.76]],"id":52385932}],"con":true,"img":false}]}
{"op":"mcm","clk":"11450485457","pt":1717322584634,"mc":[{"id":"1.229554927","rc":[{"atb":[[19,0],[14,0]],"id":52385910},{"atb":[[3,0],[3.5,0]],"id":52385906},{"atb":[[8,0],[10,0]],"id":52385908},{"atb":[[550,0],[650,0]],"id":52385887},{"atb":[[42,0],[26,0]],"id":52385889},{"atb":[[10.5,0],[8.2,0]],"id":52385916},{"atb":[[18.5,0],[27,3.85]],"id":52385885},{"atb":[[9.2,0],[13,0]],"id":52385894},{"atb":[[9.2,0],[13,0]],"id":52385927},{"atb":[[4.1,0],[3.55,0]],"id":52385892},{"atb":[[9.6,0],[14,0]],"id":52385925},{"atb":[[9.8,0],[14.5,0]],"id":52385935},{"atb":[[5.1,0],[4.1,0]],"id":52385904},{"atb":[[70,0],[38,0]],"id":52385937},{"atb":[[550,0],[650,0]],"id":52385931},{"atb":[[3,52.32],[3.5,20.93]],"id":52385911},{"atb":[[3.1,0],[2.84,0]],"id":52385913},{"atb":[[10.5,0],[15.5,0]],"id":52385909},{"atb":[[550,0],[650,0]],"id":52385888},{"atb":[[70,0],[38,0]],"id":52385882},{"atb":[[7.4,0],[5.7,0]],"id":52385915},{"atb":[[44,0],[27,0]],"id":52385884},{"atb":[[17.5,0],[12.5,0]],"id":52385895},{"atb":[[7.4,0],[9.4,0]],"id":52385928},{"atb":[[4.3,0],[5.3,0]],"id":52385891},{"atb":[[550,0],[650,0]],"id":52385924},{"atb":[[18,0],[13,0]],"id":52385934},{"atb":[[19.5,0],[29,0]],"id":52385903},{"atb":[[65,0],[36,0]],"id":52385930},{"atb":[[19,0],[14,0]],"id":52385932}],"con":true,"img":false}]}
{"op":"mcm","clk":"11450486988","pt":1717322601864,"mc":[{"id":"1.229554927","rc":[{"atb":[[3,121.95],[3.5,41.81]],"id":52385906},{"atb":[[8,34.84],[10,11.61]],"id":52385908},{"atb":[[550,0.44],[650,0.16]],"id":52385887},{"atb":[[42,2.54],[26,9.75]],"id":52385889},{"atb":[[18.5,13.93],[27,7.86]],"id":52385885},{"atb":[[9.2,29.74],[13,8.71]],"id":52385894},{"atb":[[4.1,33.71],[3.55,95.64]],"id":52385892},{"atb":[[5.1,25.49],[4.1,78.68]],"id":52385904},{"atb":[[10.5,25.67],[15.5,7.2]],"id":52385909},{"atb":[[550,0.44],[650,0.16]],"id":52385888},{"atb":[[70,1.51],[38,6.59]],"id":52385882},{"atb":[[44,2.43],[27,9.38]],"id":52385884},{"atb":[[17.5,6.33],[12.5,21.2]],"id":52385895},{"atb":[[4.3,73.9],[5.3,24.31]],"id":52385891},{"atb":[[19.5,13.18],[29,3.73]],"id":52385903}],"con":true,"img":false}]}
{"op":"mcm","clk":"11450487915","pt":1717322612480,"mc":[{"id":"1.229554927","rc":[{"atb":[[19,5.8],[14,18.76]],"id":52385910},{"atb":[[10.5,11],[8.2,33.87]],"id":52385916},{"atb":[[9.2,29.74],[13,8.71]],"id":52385927},{"atb":[[9.6,28.36],[14,8.04]],"id":52385925},{"atb":[[9.8,27.71],[14.5,7.74]],"id":52385935},{"atb":[[70,1.51],[38,6.59]],"id":52385937},{"atb":[[550,0.44],[650,0.16]],"id":52385931},{"atb":[[3,174.27],[3.5,62.74]],"id":52385911},{"atb":[[3.1,49.77],[2.84,132.55]],"id":52385913},{"atb":[[7.4,16.33],[5.7,51.89]],"id":52385915},{"atb":[[7.4,38.1],[9.4,12.44]],"id":52385928},{"atb":[[550,0.44],[650,0.16]],"id":52385924},{"atb":[[18,6.14],[13,20.32]],"id":52385934},{"atb":[[65,1.63],[36,6.96]],"id":52385930},{"atb":[[19,5.8],[14,18.76]],"id":52385932}],"con":true,"img":false}]}
{"op":"mcm","clk":"11450490338","pt":1717322639481,"mc":[{"id":"1.229554927","rc":[{"atb":[[19,0],[14,0]],"id":52385910},{"atb":[[3,0],[3.5,0]],"id":52385906},{"atb":[[8,0],[10,0]],"id":52385908},{"atb":[[550,0],[650,0]],"id":52385887},{"atb":[[42,0],[26,0]],"id":52385889},{"atb":[[10.5,0],[8.2,0]],"id":52385916},{"atb":[[18.5,0],[27,3.85]],"id":52385885},{"atb":[[9.2,0],[13,0]],"id":52385894},{"atb":[[9.2,0],[13,0]],"id":52385927},{"atb":[[4.1,0],[3.55,0]],"id":52385892},{"atb":[[9.6,0],[14,0]],"id":52385925},{"atb":[[9.8,0],[14.5,0]],"id":52385935},{"atb":[[5.1,0],[4.1,0]],"id":52385904},{"atb":[[70,0],[38,0]],"id":52385937},{"atb":[[550,0],[650,0]],"id":52385931},{"atb":[[3,52.32],[3.5,20.93]],"id":52385911},{"atb":[[3.1,0],[2.84,0]],"id":52385913},{"atb":[[10.5,0],[15.5,0]],"id":52385909},{"atb":[[550,0],[650,0]],"id":52385888},{"atb":[[70,0],[38,0]],"id":52385882},{"atb":[[7.4,0],[5.7,0]],"id":52385915},{"atb":[[44,0],[27,0]],"id":52385884},{"atb":[[17.5,0],[12.5,0]],"id":52385895},{"atb":[[7.4,0],[9.4,0]],"id":52385928},{"atb":[[4.3,0],[5.3,0]],"id":52385891},{"atb":[[550,0],[650,0]],"id":52385924},{"atb":[[18,0],[13,0]],"id":52385934},{"atb":[[19.5,0],[29,0]],"id":52385903},{"atb":[[65,0],[36,0]],"id":52385930},{"atb":[[19,0],[14,0]],"id":52385932}],"con":true,"img":false}]}
{"op":"mcm","clk":"11450491523","pt":1717322652112,"mc":[{"id":"1.229554927","rc":[{"atb":[[19,5.8],[14,18.76]],"id":52385910},{"atb":[[3,121.95],[3.5,41.81]],"id":52385906},{"atb":[[8,34.84],[10,11.61]],"id":52385908},{"atb":[[550,0.44],[650,0.16]],"id":52385887},{"atb":[[42,2.54],[26,9.75]],"id":52385889},{"atb":[[10.5,11],[8.2,33.87]],"id":52385916},{"atb":[[18.5,13.93],[27,7.86]],"id":52385885},{"atb":[[9.2,29.74],[13,8.71]],"id":52385894},{"atb":[[9.2,29.74],[13,8.71]],"id":52385927},{"atb":[[4.1,33.71],[3.55,95.64]],"id":52385892},{"atb":[[9.6,28.36],[14,8.04]],"id":52385925},{"atb":[[9.8,27.71],[14.5,7.74]],"id":52385935},{"atb":[[5.1,25.49],[4.1,78.68]],"id":52385904},{"atb":[[70,1.51],[38,6.59]],"id":52385937},{"atb":[[550,0.44],[650,0.16]],"id":52385931},{"atb":[[3,174.27],[3.5,62.74]],"id":52385911},{"atb":[[3.1,49.77],[2.84,132.55]],"id":52385913},{"atb":[[10.5,25.67],[15.5,7.2]],"id":52385909},{"atb":[[550,0.44],[650,0.16]],"id":52385888},{"atb":[[70,1.51],[38,6.59]],"id":52385882},{"atb":[[7.4,16.33],[5.7,51.89]],"id":52385915},{"atb":[[44,2.43],[27,9.38]],"id":52385884},{"atb":[[17.5,6.33],[12.5,21.2]],"id":52385895},{"atb":[[7.4,38.1],[9.4,12.44]],"id":52385928},{"atb":[[4.3,73.9],[5.3,24.31]],"id":52385891},{"atb":[[550,0.44],[650,0.16]],"id":52385924},{"atb":[[18,6.14],[13,20.32]],"id":52385934},{"atb":[[19.5,13.18],[29,3.73]],"id":52385903},{"atb":[[65,1.63],[36,6.96]],"id":52385930},{"atb":[[19,5.8],[14,18.76]],"id":52385932}],"con":true,"img":false}]}
{"op":"mcm","clk":"11450505727","pt":1717322805577,"mc":[{"id":"1.229554927","rc":[{"atb":[[19,0],[14,0]],"id":52385910},{"atb":[[3,0],[3.5,0]],"id":52385906},{"atb":[[8,0],[10,0]],"id":52385908},{"atb":[[550,0],[650,0]],"id":52385887},{"atb":[[42,0],[26,0]],"id":52385889},{"atb":[[10.5,0],[8.2,0]],"id":52385916},{"atb":[[18.5,0],[27,3.85]],"id":52385885},{"atb":[[9.2,0],[13,0]],"id":52385894},{"atb":[[9.2,0],[13,0]],"id":52385927},{"atb":[[4.1,0],[3.55,0]],"id":52385892},{"atb":[[9.6,0],[14,0]],"id":52385925},{"atb":[[9.8,0],[14.5,0]],"id":52385935},{"atb":[[5.1,0],[4.1,0]],"id":52385904},{"atb":[[70,0],[38,0]],"id":52385937},{"atb":[[550,0],[650,0]],"id":52385931},{"atb":[[3,52.32],[3.5,20.93]],"id":52385911},{"atb":[[3.1,0],[2.84,0]],"id":52385913},{"atb":[[10.5,0],[15.5,0]],"id":52385909},{"atb":[[550,0],[650,0]],"id":52385888},{"atb":[[70,0],[38,0]],"id":52385882},{"atb":[[7.4,0],[5.7,0]],"id":52385915},{"atb":[[44,0],[27,0]],"id":52385884},{"atb":[[17.5,0],[12.5,0]],"id":52385895},{"atb":[[7.4,0],[9.4,0]],"id":52385928},{"atb":[[4.3,0],[5.3,0]],"id":52385891},{"atb":[[550,0],[650,0]],"id":52385924},{"atb":[[18,0],[13,0]],"id":52385934},{"atb":[[19.5,0],[29,0]],"id":52385903},{"atb":[[65,0],[36,0]],"id":52385930},{"atb":[[19,0],[14,0]],"id":52385932}],"con":true,"img":false}]}
{"op":"mcm","clk":"11450507017","pt":1717322820895,"mc":[{"id":"1.229554927","rc":[{"atb":[[3,121.95],[3.5,41.81]],"id":52385906},{"atb":[[8,34.84],[10,11.61]],"id":52385908},{"atb":[[550,0.44],[650,0.16]],"id":52385887},{"atb":[[42,2.54],[26,9.75]],"id":52385889},{"atb":[[18.5,13.93],[27,7.86]],"id":52385885},{"atb":[[9.2,29.74],[13,8.71]],"id":52385894},{"atb":[[4.1,33.71],[3.55,95.64]],"id":52385892},{"atb":[[5.1,25.49],[4.1,78.68]],"id":52385904},{"atb":[[10.5,25.67],[15.5,7.2]],"id":52385909},{"atb":[[550,0.44],[650,0.16]],"id":52385888},{"atb":[[70,1.51],[38,6.59]],"id":52385882},{"atb":[[44,2.43],[27,9.38]],"id":52385884},{"atb":[[17.5,6.33],[12.5,21.2]],"id":52385895},{"atb":[[4.3,73.9],[5.3,24.31]],"id":52385891},{"atb":[[19.5,13.18],[29,3.73]],"id":52385903}],"con":true,"img":false}]}
{"op":"mcm","clk":"11450507046","pt":1717322821167,"mc":[{"id":"1.229554927","rc":[{"atb":[[19,5.8],[14,18.76]],"id":52385910},{"atb":[[10.5,11],[8.2,33.87]],"id":52385916},{"atb":[[9.2,29.74],[13,8.71]],"id":52385927},{"atb":[[9.6,28.36],[14,8.04]],"id":52385925},{"atb":[[9.8,27.71],[14.5,7.74]],"id":52385935},{"atb":[[70,1.51],[38,6.59]],"id":52385937},{"atb":[[550,0.44],[650,0.16]],"id":52385931},{"atb":[[3,174.27],[3.5,62.74]],"id":52385911},{"atb":[[3.1,49.77],[2.84,132.55]],"id":52385913},{"atb":[[7.4,16.33],[5.7,51.89]],"id":52385915},{"atb":[[7.4,38.1],[9.4,12.44]],"id":52385928},{"atb":[[550,0.44],[650,0.16]],"id":52385924},{"atb":[[18,6.14],[13,20.32]],"id":52385934},{"atb":[[65,1.63],[36,6.96]],"id":52385930},{"atb":[[19,5.8],[14,18.76]],"id":52385932}],"con":true,"img":false}]}
{"op":"mcm","clk":"11450522030","pt":1717322967266,"mc":[{"id":"1.229554927","rc":[{"atb":[[160,0],[80,0],[110,0],[55,0]],"id":52385889},{"atb":[[17.5,0],[20,0],[25,0],[15,0]],"id":52385916},{"atb":[[840,0],[890,0],[940,0],[990,0]],"id":52385931},{"atb":[[32,0],[42,0],[26,0],[55,0]],"id":52385895},{"atb":[[140,0],[70,0],[95,0],[48,0]],"id":52385903}],"con":true,"img":false}]}
{"op":"mcm","clk":"11450522036","pt":1717322967365,"mc":[{"id":"1.229554927","rc":[{"atb":[[26,13.75],[29,0]],"id":52385889}],"con":true,"img":false}]}
{"op":"mcm","clk":"11450522090","pt":1717322967951,"mc":[{"id":"1.229554927","rc":[{"atb":[[80,0.66],[42,5.1],[110,0.24],[55,1.45]],"id":52385889},{"atb":[[16.5,5.06],[19,2.91],[23,1.19],[14,8.05]],"id":52385916},{"atb":[[630,0.17],[680,0.12],[730,0.07],[780,0.03]],"id":52385931},{"atb":[[40,1.34],[50,0.53],[25,4.36],[30,2.71]],"id":52385895},{"atb":[[70,0.76],[38,2.83],[95,0.28],[48,1.67]],"id":52385903}],"con":true,"img":false}]}
{"op":"mcm","clk":"11450531531","pt":1717323064996,"mc":[{"id":"1.229554927","rc":[{"atb":[[26,3.18],[28,6.74]],"id":52385910},{"atl":[[310,3.31],[330,3.7]],"id":52385910},{"atb":[[5.6,3.25],[5.4,3.31]],"id":52385906},{"atl":[[12,2.78],[13,4.19]],"id":52385906},{"atb":[[12.5,13.68],[13.5,3.45]],"id":52385908},{"atl":[[50,3.17],[60,4.11]],"id":52385908},{"atb":[[70,3.07],[80,3.88]],"id":52385889},{"atl":[[850,3.37],[870,3.57]],"id":52385889},{"atb":[[95,4.54],[110,3.6]],"id":52385885},{"atb":[[23,3.19],[25,4.39]],"id":52385927},{"atl":[[100,3.94],[120,3.38]],"id":52385927},{"atb":[[5.7,3.64],[5.9,2.95]],"id":52385892},{"atl":[[16.5,3.01],[17.5,2.74]],"id":52385892},{"atb":[[24,3.39],[26,3.05]],"id":52385925},{"atl":[[130,2.66],[110,3.1]],"id":52385925},{"atb":[[8.2,3.32],[7.8,2.76]],"id":52385904},{"atl":[[23,3.26],[25,4.41]],"id":52385904},{"atb":[[100,4.07],[120,3.92]],"id":52385937},{"atl":[[680,4.23],[700,3.1]],"id":52385937},{"atb":[[4.5,2.84],[4.3,4.75]],"id":52385911},{"atl":[[8,4.37],[8.4,3.8]],"id":52385911},{"atb":[[8.6,4.29],[8.2,3.32]],"id":52385915},{"atl":[[19.5,4.3],[21,3.55]],"id":52385915},{"atb":[[42,4.43],[46,3.98]],"id":52385934},{"atl":[[260,3.02],[280,2.97]],"id":52385934},{"atb":[[95,5.32],[110,4.3]],"id":52385930},{"atl":[[460,4.34],[480,3.82]],"id":52385930}],"con":true,"img":false}]}
{"op":"mcm","clk":"11450531541","pt":1717323065101,"mc":[{"id":"1.229554927","rc":[{"atb":[[80,3.21],[42,2.54],[110,0],[55,0]],"id":52385889},{"atb":[[14,12.69],[15,4.61]],"id":52385916},{"atl":[[46,3.4],[50,4.35]],"id":52385916},{"atb":[[18,3.4],[19,2.73]],"id":52385894},{"atl":[[65,4.46],[55,4.43]],"id":52385894},{"atb":[[28,3.16],[30,3.27]],"id":52385935},{"atl":[[210,4.43],[230,3.1]],"id":52385935},{"atb":[[630,0],[680,0],[730,0],[780,0]],"id":52385931},{"atb":[[4.3,4.75],[4.1,5.06]],"id":52385913},{"atl":[[7.4,2.9],[7.8,2.91]],"id":52385913},{"atb":[[25,8.88],[27,2.67]],"id":52385909},{"atl":[[85,4.33],[95,3.02]],"id":52385909},{"atb":[[130,3.03],[150,3.32]],"id":52385882},{"atb":[[140,2.66],[120,2.67]],"id":52385884},{"atl":[[140,4.57],[160,2.65]],"id":52385895},{"atb":[[16.5,11.44],[17.5,3.42]],"id":52385928},{"atl":[[65,4.66],[75,4.67]],"id":52385928},{"atb":[[8,4.55],[8.4,3.94]],"id":52385891},{"atl":[[22,3.02],[24,3.61]],"id":52385891},{"atb":[[65,3.09],[70,0],[75,3.19],[38,0],[95,0],[48,0]],"id":52385903},{"atl":[[550,4.38],[570,2.7]],"id":52385903},{"atl":[[300,3.69],[320,3.61]],"id":52385932}],"con":true,"img":false}]}
{"op":"mcm","clk":"11450531552","pt":1717323065235,"mc":[{"id":"1.229554927","rc":[{"atl":[[25,4.17],[230,0]],"id":52385906},{"atl":[[110,2],[490,0]],"id":52385908},{"atl":[[340,2],[710,0]],"id":52385927},{"atl":[[410,0],[55,2]],"id":52385892},{"atl":[[800,0],[430,2]],"id":52385925},{"atl":[[370,0],[46,2.22]],"id":52385904},{"atl":[[150,0],[18.5,5.71]],"id":52385911},{"atl":[[340,0],[42,2.44]],"id":52385915}],"con":true,"img":false}]}
{"op":"mcm","clk":"11450531562","pt":1717323065311,"mc":[{"id":"1.229554927","rc":[{"atl":[[590,0],[210,2]],"id":52385916},{"atl":[[560,0],[170,2]],"id":52385894},{"atl":[[910,2],[1000,0]],"id":52385935},{"atl":[[70,0],[13.5,5.83]],"id":52385913},{"atl":[[820,0],[470,2]],"id":52385909},{"atl":[[660,2],[1000,0]],"id":52385895},{"atl":[[280,2],[650,0]],"id":52385928},{"atl":[[70,2],[430,0]],"id":52385891}],"con":true,"img":false}]}
{"op":"mcm","clk":"11450531614","pt":1717323065781,"mc":[{"id":"1.229554927","rc":[{"atb":[[70,4.21],[140,0.19],[95,0.55],[48,2.23]],"id":52385889},{"atb":[[840,0.13],[890,0.09],[940,0.06],[990,0.03]],"id":52385931},{"atb":[[65,4.32],[130,0.2],[90,0.59],[46,2.32]],"id":52385903}],"con":true,"img":false}]}
{"op":"mcm","clk":"11450531683","pt":1717323066413,"mc":[{"id":"1.229554927","rc":[{"atl":[[7.4,0],[7.6,2.98]],"id":52385913},{"atl":[[260,0]],"id":52385934}],"con":true,"img":false}]}
{"op":"mcm","clk":"11450531690","pt":1717323066514,"mc":[{"id":"1.229554927","rc":[{"atl":[[270,2.87]],"id":52385934}],"con":true,"img":false}]}
{"op":"mcm","clk":"11450531844","pt":1717323068021,"mc":[{"id":"1.229554927","rc":[{"atb":[[27,0],[30,3.45]],"id":52385910},{"atb":[[2.92,0],[3.15,46.51]],"id":52385906},{"atb":[[3.95,0],[4.4,14.71]],"id":52385908},{"atb":[[32,3.23],[26,9.75]],"id":52385889},{"atb":[[34,3.03],[27,4.01]],"id":52385885},{"atb":[[6,10.48],[5.4,0]],"id":52385894},{"atb":[[6.8,0],[7.8,8.38]],"id":52385927},{"atb":[[3.85,35.09],[3.5,0]],"id":52385892},{"atb":[[7.2,0],[8.2,7.67]],"id":52385925},{"atb":[[25,0],[29,3.57]],"id":52385935},{"atb":[[3.7,26.96]],"id":52385904},{"atb":[[2.9,52.63],[2.7,0]],"id":52385911},{"atb":[[2.42,0],[2.58,63.29]],"id":52385913},{"atb":[[8.8,7.07],[7.8,0]],"id":52385909},{"atb":[[3.6,29.86],[3.3,0]],"id":52385915},{"atb":[[4,26.19],[3.7,0]],"id":52385891},{"atb":[[32,3.23],[26,0]],"id":52385903}],"con":true,"img":false}]}
{"op":"mcm","clk":"11450531858","pt":1717323068086,"mc":[{"id":"1.229554927","rc":[{"atb":[[3.4,0]],"id":52385904}],"con":true,"img":false}]}
{"op":"mcm","clk":"11450537205","pt":1717323120725,"mc":[{"id":"1.229554927","rc":[{"atb":[[27,3.54],[28,2.91]],"id":52385910},{"atb":[[80,0],[60,4.1]],"id":52385889},{"atb":[[85,4.84],[110,0]],"id":52385885},{"atb":[[19,0],[19.5,3.6]],"id":52385894},{"atb":[[6,13.44],[5.9,0]],"id":52385892},{"atb":[[26,0],[27,4.35]],"id":52385925},{"atb":[[8.2,0],[8.4,13.5]],"id":52385904},{"atb":[[4.5,0],[4.6,2.69]],"id":52385911},{"atb":[[130,0],[150,0]],"id":52385882},{"atb":[[140,0]],"id":52385884},{"atb":[[40,0],[50,0],[25,0],[30,0]],"id":52385895},{"atb":[[8.6,13],[8.4,0]],"id":52385891},{"atb":[[75,0],[50,4.28]],"id":52385903}],"con":true,"img":false}]}
{"op":"mcm","clk":"11450537292","pt":1717323121516,"mc":[{"id":"1.229554927","rc":[{"atb":[[32,2.53],[42,1.28],[26,4.19],[55,0.49]],"id":52385895}],"con":true,"img":false}]}
{"op":"mcm","clk":"11450538219","pt":1717323130724,"mc":[{"id":"1.229554927","rc":[{"atb":[[70,1.14],[50,3.7]],"id":52385889},{"atb":[[75,2.98],[95,0]],"id":52385885},{"atb":[[100,3.05]],"id":52385884},{"atb":[[65,1.22],[46,6.12]],"id":52385903}],"con":true,"img":false}]}
{"op":"mcm","clk":"11450539327","pt":1717323141563,"mc":[{"id":"1.229554927","rc":[{"atb":[[19,0],[14,0]],"id":52385910},{"atb":[[3,0],[3.5,0]],"id":52385906},{"atb":[[8,0],[10,0]],"id":52385908},{"atb":[[550,0],[650,0]],"id":52385887},{"atb":[[42,0],[26,0]],"id":52385889},{"atb":[[10.5,0],[8.2,0]],"id":52385916},{"atb":[[18.5,0],[27,0]],"id":52385885},{"atb":[[9.2,0],[13,0]],"id":52385894},{"atb":[[9.2,0],[13,0]],"id":52385927},{"atb":[[4.1,0],[3.55,0]],"id":52385892},{"atb":[[9.6,0],[14,0]],"id":52385925},{"atb":[[9.8,0],[14.5,0]],"id":52385935},{"atb":[[5.1,0],[4.1,0]],"id":52385904},{"atb":[[70,0],[38,0]],"id":52385937},{"atb":[[550,0],[650,0]],"id":52385931},{"atb":[[3,52.32],[3.5,20.93]],"id":52385911},{"atb":[[3.1,0],[2.84,0]],"id":52385913},{"atb":[[10.5,0],[15.5,0]],"id":52385909},{"atb":[[550,0],[650,0]],"id":52385888},{"atb":[[70,0],[38,0]],"id":52385882},{"atb":[[7.4,0],[5.7,0]],"id":52385915},{"atb":[[44,0],[27,0]],"id":52385884},{"atb":[[17.5,0],[12.5,0]],"id":52385895},{"atb":[[7.4,0],[9.4,0]],"id":52385928},{"atb":[[4.3,0],[5.3,0]],"id":52385891},{"atb":[[550,0],[650,0]],"id":52385924},{"atb":[[18,0],[13,0]],"id":52385934},{"atb":[[19.5,0],[29,0]],"id":52385903},{"atb":[[65,0],[36,0]],"id":52385930},{"atb":[[19,0],[14,0]],"id":52385932}],"con":true,"img":false}]}
{"op":"mcm","clk":"11450539378","pt":1717323141983,"mc":[{"id":"1.229554927","rc":[{"atl":[[50,0],[55,3.22]],"id":52385908},{"atl":[[22,0],[23,3.48]],"id":52385891}],"con":true,"img":false}]}
{"op":"mcm","clk":"11450539534","pt":1717323143194,"mc":[{"id":"1.229554927","rc":[{"atb":[[170,3.7],[190,3.7]],"id":52385887},{"atl":[[23,0],[24,2.63]],"id":52385904},{"atb":[[190,3.59],[210,3.4]],"id":52385931},{"atb":[[200,2.67],[220,4.49]],"id":52385888},{"atb":[[100,2.8],[120,3.27]],"id":52385882},{"atb":[[1.45,34.88],[1.43,36.5]],"id":52385895},{"atb":[[140,2.68],[160,3.97]],"id":52385924},{"atb":[[1.45,34.88],[1.43,36.5]],"id":52385932}],"con":true,"img":false}]}
{"op":"mcm","clk":"11450540642","pt":1717323152974,"mc":[{"id":"1.229554927","rc":[{"atb":[[19,5.8],[14,18.76]],"id":52385910},{"atb":[[3,121.95],[3.5,41.81]],"id":52385906},{"atb":[[8,34.84],[10,11.61]],"id":52385908},{"atb":[[550,0.44],[650,0.16]],"id":52385887},{"atb":[[42,2.54],[26,9.75]],"id":52385889},{"atb":[[10.5,11],[8.2,33.87]],"id":52385916},{"atb":[[18.5,13.93],[27,4.01]],"id":52385885},{"atb":[[9.2,29.74],[13,8.71]],"id":52385894},{"atb":[[9.2,29.74],[13,8.71]],"id":52385927},{"atb":[[4.1,33.71],[3.55,95.64]],"id":52385892},{"atb":[[9.6,28.36],[14,8.04]],"id":52385925},{"atb":[[9.8,27.71],[14.5,7.74]],"id":52385935},{"atb":[[5.1,25.49],[4.1,78.68]],"id":52385904},{"atb":[[70,1.51],[38,6.59]],"id":52385937},{"atb":[[550,0.44],[650,0.16]],"id":52385931},{"atb":[[3,174.27],[3.5,62.74]],"id":52385911},{"atb":[[3.1,49.77],[2.84,132.55]],"id":52385913},{"atb":[[10.5,25.67],[15.5,7.2]],"id":52385909},{"atb":[[550,0.44],[650,0.16]],"id":52385888},{"atb":[[70,1.51],[38,6.59]],"id":52385882},{"atb":[[7.4,16.33],[5.7,51.89]],"id":52385915},{"atb":[[44,2.43],[27,9.38]],"id":52385884},{"atb":[[17.5,6.33],[12.5,21.2]],"id":52385895},{"atb":[[7.4,38.1],[9.4,12.44]],"id":52385928},{"atb":[[4.3,73.9],[5.3,24.31]],"id":52385891},{"atb":[[550,0.44],[650,0.16]],"id":52385924},{"atb":[[18,6.14],[13,20.32]],"id":52385934},{"atb":[[19.5,13.18],[29,3.73]],"id":52385903},{"atb":[[65,1.63],[36,6.96]],"id":52385930},{"atb":[[19,5.8],[14,18.76]],"id":52385932}],"con":true,"img":false}]}
{"op":"mcm","clk":"11450540688","pt":1717323153284,"mc":[{"id":"1.229554927","rc":[{"atl":[[50,3.47],[55,0]],"id":52385908},{"atl":[[23,2.7],[24,0]],"id":52385904},{"atl":[[22,3.97],[23,0]],"id":52385891}],"con":true,"img":false}]}
{"op":"mcm","clk":"11450544126","pt":1717323184130,"mc":[{"id":"1.229554927","rc":[{"atl":[[22,3.05],[23,0]],"id":52385904}],"con":true,"img":false}]}
{"op":"mcm","clk":"11450551194","pt":1717323248091,"mc":[{"id":"1.229554927","rc":[{"atb":[[34,3.03],[30,0]],"id":52385910},{"atl":[[95,2],[110,0]],"id":52385908},{"atb":[[38,2]],"id":52385887},{"atb":[[7.2,12.24],[6,0]],"id":52385916},{"atb":[[3.85,0],[4.2,31.25]],"id":52385892},{"atb":[[9.2,7.76],[8.2,0]],"id":52385925},{"atl":[[820,2],[910,0]],"id":52385935},{"atb":[[3.95,27.02]],"id":52385904},{"atb":[[34,3.03],[27,0]],"id":52385937},{"atb":[[2.9,0],[3.05,48.78]],"id":52385911},{"atl":[[420,2],[470,0]],"id":52385909},{"atb":[[38,9.29],[29,0]],"id":52385882},{"atb":[[38,2.7],[29,0]],"id":52385884},{"atb":[[8,14.29],[6.4,0]],"id":52385928},{"atb":[[38,2],[29,0]],"id":52385924},{"atb":[[32,3.23],[26,0]],"id":52385934},{"atb":[[34,3.03],[27,0]],"id":52385930}],"con":true,"img":false}]}
{"op":"mcm","clk":"11450551202","pt":1717323248133,"mc":[{"id":"1.229554927","rc":[{"atb":[[29,0]],"id":52385887},{"atb":[[3.7,0]],"id":52385904}],"con":true,"img":false}]}
{"op":"mcm","clk":"11450551215","pt":1717323248240,"mc":[{"id":"1.229554927","rc":[{"atl":[[820,0],[950,2]],"id":52385935},{"atb":[[10,7.07],[8.8,0]],"id":52385909}],"con":true,"img":false}]}
{"op":"mcm","clk":"11450551220","pt":1717323248342,"mc":[{"id":"1.229554927","rc":[{"atl":[[300,3.45]],"id":52385910},{"atb":[[17.5,0],[20,0],[12.5,4.57],[13,4.14],[13.5,0],[15,0]],"id":52385908},{"atl":[[890,2.65]],"id":52385889},{"atl":[[210,0]],"id":52385935},{"atl":[[8,0]],"id":52385911},{"atb":[[8.6,0]],"id":52385915},{"atl":[[540,4.52],[550,0]],"id":52385903}],"con":true,"img":false}]}
{"op":"mcm","clk":"11450551233","pt":1717323248449,"mc":[{"id":"1.229554927","rc":[{"atl":[[310,0]],"id":52385910},{"atl":[[850,0]],"id":52385889},{"atl":[[44,4.42],[46,0]],"id":52385916},{"atl":[[16.5,0]],"id":52385892},{"atl":[[200,4.57]],"id":52385935},{"atl":[[8.2,4.64]],"id":52385911},{"atb":[[8.4,4.42]],"id":52385915}],"con":true,"img":false}]}
{"op":"mcm","clk":"11450551245","pt":1717323248547,"mc":[{"id":"1.229554927","rc":[{"atl":[[920,3.44]],"id":52385889},{"atl":[[48,3.3]],"id":52385916},{"atl":[[220,2.63]],"id":52385935},{"atl":[[140,0],[150,2.76]],"id":52385895},{"atl":[[560,2.65]],"id":52385903},{"atl":[[300,0],[330,3.88]],"id":52385932}],"con":true,"img":false}]}
{"op":"mcm","clk":"11450551298","pt":1717323249065,"mc":[{"id":"1.229554927","rc":[{"atb":[[17,3.27],[19.5,1.41],[12,9.51],[14.5,5.81]],"id":52385908}],"con":true,"img":false}]}
{"op":"mcm","clk":"11450551315","pt":1717323249268,"mc":[{"id":"1.229554927","rc":[{"atl":[[850,2],[950,0]],"id":52385935},{"atb":[[2.58,0],[2.7,58.82]],"id":52385913},{"atb":[[3.6,0],[3.85,29.86]],"id":52385915},{"atl":[[610,2],[660,0]],"id":52385895}],"con":true,"img":false}]}
{"op":"mcm","clk":"11450551338","pt":1717323249423,"mc":[{"id":"1.229554927","rc":[{"atl":[[16.5,4.38]],"id":52385892}],"con":true,"img":false}]}
{"op":"mcm","clk":"11450551350","pt":1717323249528,"mc":[{"id":"1.229554927","rc":[{"atl":[[300,0],[310,2.81]],"id":52385910},{"atl":[[850,4.37],[870,0],[920,0]],"id":52385889},{"atl":[[44,0],[46,4.54],[48,0]],"id":52385916},{"atl":[[200,0],[210,2.73],[220,0]],"id":52385935},{"atl":[[8,3.63],[8.2,0]],"id":52385911},{"atb":[[8.6,3.05],[8.4,0]],"id":52385915},{"atl":[[140,3.73],[150,0]],"id":52385895},{"atl":[[540,0],[560,0],[550,2.65]],"id":52385903},{"atl":[[300,3.48],[320,0]],"id":52385932}],"con":true,"img":false}]}
{"op":"mcm","clk":"11450552253","pt":1717323258376,"mc":[{"id":"1.229554927","rc":[{"atb":[[13,0],[13.5,4.57]],"id":52385908}],"con":true,"img":false}]}
{"op":"mcm","clk":"11450552358","pt":1717323259566,"mc":[{"id":"1.229554927","rc":[{"atl":[[870,3.11]],"id":52385889}],"con":true,"img":false}]}
{"op":"mcm","clk":"11450553443","pt":1717323269577,"mc":[{"id":"1.229554927","rc":[{"atl":[[890,0]],"id":52385889}],"con":true,"img":false}]}
{"op":"mcm","clk":"11450564619","pt":1717323369258,"mc":[{"id":"1.229554927","rc":[{"atl":[[850,0],[910,2]],"id":52385935},{"atb":[[2.9,52.63],[3.05,0]],"id":52385911},{"atb":[[2.58,58.14],[2.7,0]],"id":52385913},{"atb":[[10,0],[8.8,9.78]],"id":52385909}],"con":true,"img":false}]}
{"op":"mcm","clk":"11450569327","pt":1717323407395,"mc":[{"id":"1.229554927","rc":[{"atb":[[27,0],[28,5.85]],"id":52385910},{"atb":[[19.5,0],[19,3]],"id":52385894},{"atb":[[26,4.23],[27,0]],"id":52385925},{"atb":[[8.2,4.18],[8.4,10.61]],"id":52385904},{"atb":[[4.5,4.35],[4.6,0]],"id":52385911},{"atb":[[4.3,0],[4.4,11.4]],"id":52385913},{"atb":[[8.6,10.33],[8.4,4.33]],"id":52385891}],"con":true,"img":false}]}
{"op":"mcm","clk":"11450570405","pt":1717323415917,"mc":[{"id":"1.229554927","rc":[{"atb":[[17,0],[19.5,0],[12,0],[14.5,0]],"id":52385908}],"con":true,"img":false}]}
{"op":"mcm","clk":"11450570470","pt":1717323416635,"mc":[{"id":"1.229554927","rc":[{"atb":[[17.5,3.17],[20,1.38],[12.5,13.68],[15,5.6]],"id":52385908}],"con":true,"img":false}]}
{"op":"mcm","clk":"11450578815","pt":1717323487451,"mc":[{"id":"1.229554927","rc":[{"atb":[[19,0],[14,0]],"id":52385910},{"atb":[[3,0],[3.5,0]],"id":52385906},{"atb":[[8,0],[10,0]],"id":52385908},{"atb":[[550,0],[650,0]],"id":52385887},{"atb":[[42,0],[26,0]],"id":52385889},{"atb":[[10.5,0],[8.2,0]],"id":52385916},{"atb":[[18.5,0],[27,0]],"id":52385885},{"atb":[[9.2,0],[13,0]],"id":52385894},{"atb":[[9.2,0],[13,0]],"id":52385927},{"atb":[[4.1,0],[3.55,0]],"id":52385892},{"atb":[[9.6,0],[14,0]],"id":52385925},{"atb":[[9.8,0],[14.5,0]],"id":52385935},{"atb":[[5.1,0],[4.1,0]],"id":52385904},{"atb":[[70,0],[38,0]],"id":52385937},{"atb":[[550,0],[650,0]],"id":52385931},{"atb":[[3,52.32],[3.5,20.93]],"id":52385911},{"atb":[[3.1,0],[2.84,0]],"id":52385913},{"atb":[[10.5,0],[15.5,0]],"id":52385909},{"atb":[[550,0],[650,0]],"id":52385888},{"atb":[[70,0],[38,2.7]],"id":52385882},{"atb":[[7.4,0],[5.7,0]],"id":52385915},{"atb":[[44,0],[27,0]],"id":52385884},{"atb":[[17.5,0],[12.5,0]],"id":52385895},{"atb":[[7.4,0],[9.4,0]],"id":52385928},{"atb":[[4.3,0],[5.3,0]],"id":52385891},{"atb":[[550,0],[650,0]],"id":52385924},{"atb":[[18,0],[13,0]],"id":52385934},{"atb":[[19.5,0],[29,0]],"id":52385903},{"atb":[[65,0],[36,0]],"id":52385930},{"atb":[[19,0],[14,0]],"id":52385932}],"con":true,"img":false}]}
{"op":"mcm","clk":"11450579227","pt":1717323491125,"mc":[{"id":"1.229554927","rc":[{"atb":[[140,0],[70,0],[95,0],[48,0]],"id":52385889},{"atb":[[840,0],[890,0],[940,0],[990,0]],"id":52385931},{"atb":[[130,0],[65,0],[90,0],[46,3.79]],"id":52385903}],"con":true,"img":false}]}
{"op":"mcm","clk":"11450579240","pt":1717323491234,"mc":[{"id":"1.229554927","rc":[{"atb":[[32,0],[42,0],[26,0],[55,0]],"id":52385895}],"con":true,"img":false}]}
{"op":"mcm","clk":"11450579303","pt":1717323491851,"mc":[{"id":"1.229554927","rc":[{"atb":[[80,0.66],[42,2.55],[110,0.24],[55,1.45]],"id":52385889},{"atb":[[630,0.17],[680,0.12],[730,0.07],[780,0.03]],"id":52385931},{"atb":[[70,0.76],[38,2.83],[95,0.28],[48,1.67]],"id":52385903}],"con":true,"img":false}]}
{"op":"mcm","clk":"11450579311","pt":1717323491947,"mc":[{"id":"1.229554927","rc":[{"atb":[[40,1.34],[50,0.53],[25,4.36],[30,2.71]],"id":52385895}],"con":true,"img":false}]}
{"op":"mcm","clk":"11450579871","pt":1717323497097,"mc":[{"id":"1.229554927","rc":[{"atb":[[19,5.8],[14,18.76]],"id":52385910},{"atb":[[3,121.95],[3.5,41.81]],"id":52385906},{"atb":[[8,34.84],[10,11.61]],"id":52385908},{"atb":[[550,0.44],[650,0.16]],"id":52385887},{"atb":[[42,5.1],[26,9.75]],"id":52385889},{"atb":[[10.5,11],[8.2,33.87]],"id":52385916},{"atb":[[18.5,13.93],[27,4.01]],"id":52385885},{"atb":[[9.2,29.74],[13,8.71]],"id":52385894},{"atb":[[9.2,29.74],[13,8.71]],"id":52385927},{"atb":[[4.1,33.71],[3.55,95.64]],"id":52385892},{"atb":[[9.6,28.36],[14,8.04]],"id":52385925},{"atb":[[9.8,27.71],[14.5,7.74]],"id":52385935},{"atb":[[5.1,25.49],[4.1,78.68]],"id":52385904},{"atb":[[70,1.51],[38,6.59]],"id":52385937},{"atb":[[550,0.44],[650,0.16]],"id":52385931},{"atb":[[3,174.27],[3.5,62.74]],"id":52385911},{"atb":[[3.1,49.77],[2.84,132.55]],"id":52385913},{"atb":[[10.5,25.67],[15.5,7.2]],"id":52385909},{"atb":[[550,0.44],[650,0.16]],"id":52385888},{"atb":[[70,1.51],[38,9.29]],"id":52385882},{"atb":[[7.4,16.33],[5.7,51.89]],"id":52385915},{"atb":[[44,2.43],[27,9.38]],"id":52385884},{"atb":[[17.5,6.33],[12.5,21.2]],"id":52385895},{"atb":[[7.4,38.1],[9.4,12.44]],"id":52385928},{"atb":[[4.3,73.9],[5.3,24.31]],"id":52385891},{"atb":[[550,0.44],[650,0.16]],"id":52385924},{"atb":[[18,6.14],[13,20.32]],"id":52385934},{"atb":[[19.5,13.18],[29,3.73]],"id":52385903},{"atb":[[65,1.63],[36,6.96]],"id":52385930},{"atb":[[19,5.8],[14,18.76]],"id":52385932}],"con":true,"img":false}]}
{"op":"mcm","clk":"11450579931","pt":1717323497464,"mc":[{"id":"1.229554927","rc":[{"atb":[[160,0],[170,3.22]],"id":52385924}],"con":true,"img":false}]}
{"op":"mcm","clk":"11450579941","pt":1717323497565,"mc":[{"id":"1.229554927","rc":[{"atb":[[170,0],[85,3.59],[220,0],[120,0]],"id":52385885}],"con":true,"img":false}]}
{"op":"mcm","clk":"11450580012","pt":1717323498243,"mc":[{"id":"1.229554927","rc":[{"atb":[[140,0.19],[70,1.14],[95,0.55],[48,2.23]],"id":52385885}],"con":true,"img":false}]}
{"op":"mcm","clk":"11450586619","pt":1717323564129,"mc":[{"id":"1.229554927","rc":[{"atl":[[50,0]],"id":52385908}],"con":true,"img":false}]}
{"op":"mcm","clk":"11450586631","pt":1717323564239,"mc":[{"id":"1.229554927","rc":[{"atb":[[27,4.39],[28,2.91]],"id":52385910},{"atl":[[48,2.73]],"id":52385908},{"atl":[[22,0],[23,2.68]],"id":52385891}],"con":true,"img":false}]}
{"op":"mcm","clk":"11450595005","pt":1717323648863,"mc":[{"id":"1.229554927","rc":[{"atb":[[19,0],[19.5,3.45]],"id":52385894},{"atb":[[26,0],[27,4.39]],"id":52385925},{"atb":[[8.2,0],[8.4,15.27]],"id":52385904},{"atb":[[4.5,0],[4.6,2.73]],"id":52385911},{"atb":[[4.3,4.75],[4.4,7.7]],"id":52385913},{"atb":[[40,0],[50,0],[25,0],[30,0]],"id":52385895},{"atb":[[8.6,14.17],[8.4,0]],"id":52385891},{"atb":[[170,0]],"id":52385924}],"con":true,"img":false}]}
{"op":"mcm","clk":"11450595070","pt":1717323649544,"mc":[{"id":"1.229554927","rc":[{"atb":[[32,2.53],[42,1.28],[26,4.19],[55,0.49]],"id":52385895}],"con":true,"img":false}]}
{"op":"mcm","clk":"11450595100","pt":1717323649860,"mc":[{"id":"1.229554927","rc":[{"atb":[[19.5,0],[19,2.62]],"id":52385894},{"atb":[[26,4.13],[27,0]],"id":52385925},{"atb":[[8.2,3.44],[8.4,10.61]],"id":52385904},{"atb":[[4.5,3.99],[4.6,0]],"id":52385911},{"atb":[[4.3,0],[4.4,11.88]],"id":52385913},{"atb":[[8.6,10.33],[8.4,4.56]],"id":52385891}],"con":true,"img":false}]}
{"op":"mcm","clk":"11450595427","pt":1717323653572,"mc":[{"id":"1.229554927","rc":[{"atb":[[19.5,2.95]],"id":52385894},{"atb":[[27,3.92]],"id":52385925},{"atb":[[8.4,13.59]],"id":52385904},{"atb":[[4.5,0],[4.6,3.25]],"id":52385911},{"atb":[[4.3,4.75],[4.4,7.7]],"id":52385913},{"atb":[[8.6,12.99],[8.4,0]],"id":52385891}],"con":true,"img":false}]}
{"op":"mcm","clk":"11450595439","pt":1717323653676,"mc":[{"id":"1.229554927","rc":[{"atb":[[19,0]],"id":52385894},{"atb":[[26,0]],"id":52385925},{"atb":[[8.2,0]],"id":52385904}],"con":true,"img":false}]}
{"op":"mcm","clk":"11450595497","pt":1717323654253,"mc":[{"id":"1.229554927","rc":[{"atb":[[18,0]],"id":52385894},{"atb":[[24,0]],"id":52385925},{"atb":[[7.8,0]],"id":52385904}],"con":true,"img":false}]}
{"op":"mcm","clk":"11450596404","pt":1717323663655,"mc":[{"id":"1.229554927","rc":[{"atb":[[18.5,3.69]],"id":52385894},{"atb":[[25,4.35]],"id":52385925},{"atb":[[8,3.21]],"id":52385904}],"con":true,"img":false}]}
{"op":"mcm","clk":"11450596455","pt":1717323664168,"mc":[{"id":"1.229554927","rc":[{"atl":[[22,3.65],[23,0]],"id":52385891}],"con":true,"img":false}]}
{"op":"mcm","clk":"11450600780","pt":1717323710356,"mc":[{"id":"1.229554927","rc":[{"atb":[[5.5,4.21]],"id":52385906},{"atb":[[16.5,0],[19,0],[23,0],[14,4.64],[15,0],[15.5,4.3]],"id":52385916},{"atb":[[110,4.34]],"id":52385885},{"atb":[[6,10.46],[5.9,3.3]],"id":52385892},{"atb":[[27,0]],"id":52385925},{"atb":[[8.2,2.82]],"id":52385904},{"atb":[[130,3.03],[120,0]],"id":52385937},{"atb":[[28,4.19]],"id":52385909},{"atb":[[50,3.35]],"id":52385934},{"atb":[[110,0]],"id":52385930}],"con":true,"img":false}]}
{"op":"mcm","clk":"11450600791","pt":1717323710458,"mc":[{"id":"1.229554927","rc":[{"atb":[[27,0],[29,4.59]],"id":52385910},{"atb":[[5.6,0]],"id":52385906},{"atb":[[80,3.46],[42,2.54],[110,0],[55,0],[60,0]],"id":52385889},{"atb":[[140,0],[70,0],[85,0],[95,0],[48,0]],"id":52385885},{"atb":[[19.5,0]],"id":52385894},{"atb":[[26,2.96]],"id":52385925},{"atb":[[32,3.13],[30,0]],"id":52385935},{"atb":[[8.4,10.61]],"id":52385904},{"atb":[[630,0],[680,0],[730,0],[780,0]],"id":52385931},{"atb":[[4.5,2.95],[4.6,0]],"id":52385911},{"atb":[[27,0]],"id":52385909},{"atb":[[150,4.38],[120,0]],"id":52385882},{"atb":[[140,3.55],[120,0]],"id":52385884},{"atb":[[8.6,10.33],[8.4,2.85]],"id":52385891},{"atb":[[46,0]],"id":52385934},{"atb":[[70,4.11],[38,0],[95,0],[48,0],[50,0]],"id":52385903},{"atb":[[120,3.89]],"id":52385930}],"con":true,"img":false}]}
{"op":"mcm","clk":"11450600813","pt":1717323710720,"mc":[{"id":"1.229554927","rc":[{"atl":[[11.5,3.94]],"id":52385906},{"atb":[[19,2.74]],"id":52385894}],"con":true,"img":false}]}
{"op":"mcm","clk":"11450600822","pt":1717323710832,"mc":[{"id":"1.229554927","rc":[{"atb":[[28,6.08]],"id":52385910},{"atl":[[12,0]],"id":52385906},{"atb":[[4.3,0],[4.4,12.05]],"id":52385913},{"atl":[[7.4,4.45],[7.6,0]],"id":52385913},{"atl":[[270,0],[260,3.22]],"id":52385934}],"con":true,"img":false}]}
{"op":"mcm","clk":"11450600838","pt":1717323711035,"mc":[{"id":"1.229554927","rc":[{"atb":[[16.5,5.06],[19,2.91],[23,1.19],[14,12.69]],"id":52385916}],"con":true,"img":false}]}
{"op":"mcm","clk":"11450600847","pt":1717323711140,"mc":[{"id":"1.229554927","rc":[{"atb":[[80,4.13],[42,5.1],[110,0.24],[55,1.45]],"id":52385889},{"atb":[[140,0.19],[70,1.14],[95,0.55],[48,2.23]],"id":52385885},{"atb":[[630,0.17],[680,0.12],[730,0.07],[780,0.03]],"id":52385931},{"atb":[[70,4.88],[38,2.83],[95,0.28],[48,1.67]],"id":52385903}],"con":true,"img":false}]}
{"op":"mcm","clk":"11450601684","pt":1717323720152,"mc":[{"id":"1.229554927","rc":[{"atb":[[80,0.66],[60,3.18]],"id":52385889},{"atb":[[15,3.18],[15.5,0]],"id":52385916},{"atb":[[85,3.58],[110,0]],"id":52385885},{"atb":[[6,13.37],[5.9,0]],"id":52385892},{"atb":[[32,0],[30,3.09]],"id":52385935},{"atb":[[130,0],[120,3.55]],"id":52385937},{"atb":[[27,2.79],[28,0]],"id":52385909},{"atb":[[150,0]],"id":52385882},{"atb":[[140,0],[120,4.67]],"id":52385884},{"atb":[[70,0.76],[50,3.02]],"id":52385903},{"atb":[[110,3.36],[120,0]],"id":52385930}],"con":true,"img":false}]}
{"op":"mcm","clk":"11450601692","pt":1717323720261,"mc":[{"id":"1.229554927","rc":[{"atb":[[120,4.41]],"id":52385882}],"con":true,"img":false}]}
{"op":"mcm","clk":"11450601755","pt":1717323720837,"mc":[{"id":"1.229554927","rc":[{"atb":[[29,0]],"id":52385910},{"atb":[[5.6,4.54],[5.5,0]],"id":52385906},{"atb":[[46,3.95],[50,0]],"id":52385934}],"con":true,"img":false}]}
{"op":"mcm","clk":"11450602867","pt":1717323730781,"mc":[{"id":"1.229554927","rc":[{"atl":[[11.5,0]],"id":52385906}],"con":true,"img":false}]}
{"op":"mcm","clk":"11450602880","pt":1717323730885,"mc":[{"id":"1.229554927","rc":[{"atl":[[12,3.28]],"id":52385906},{"atl":[[260,0],[270,4.51]],"id":52385934}],"con":true,"img":false}]}
{"op":"mcm","clk":"11450606577","pt":1717323769735,"mc":[{"id":"1.229554927","rc":[{"atb":[[27,2.97],[28,2.91]],"id":52385910},{"atb":[[19,0],[19.5,4.54]],"id":52385894},{"atb":[[26,0],[27,4.65]],"id":52385925},{"atb":[[8.2,0],[8.4,15.3]],"id":52385904},{"atb":[[4.5,0],[4.6,3.38]],"id":52385911},{"atb":[[4.3,4.75],[4.4,7.7]],"id":52385913},{"atl":[[7.4,0],[7.6,3.26]],"id":52385913},{"atb":[[8.6,15.02],[8.4,0]],"id":52385891}],"con":true,"img":false}]}
{"op":"mcm","clk":"11450614327","pt":1717323847894,"mc":[{"id":"1.229554927","rc":[{"atb":[[19,0],[14,0]],"id":52385910},{"atb":[[3,0],[3.5,0]],"id":52385906},{"atb":[[8,0],[10,0]],"id":52385908},{"atb":[[550,0],[650,0]],"id":52385887},{"atb":[[42,2.55],[26,0]],"id":52385889},{"atb":[[10.5,0],[8.2,0]],"id":52385916},{"atb":[[18.5,0],[27,0]],"id":52385885},{"atb":[[9.2,0],[13,0]],"id":52385894},{"atb":[[9.2,0],[13,0]],"id":52385927},{"atb":[[4.1,0],[3.55,0]],"id":52385892},{"atb":[[9.6,0],[14,0]],"id":52385925},{"atb":[[9.8,0],[14.5,0]],"id":52385935},{"atb":[[5.1,0],[4.1,0]],"id":52385904},{"atb":[[70,0],[38,0]],"id":52385937},{"atb":[[550,0],[650,0]],"id":52385931},{"atb":[[3,52.32],[3.5,20.93]],"id":52385911},{"atb":[[3.1,0],[2.84,0]],"id":52385913},{"atb":[[10.5,0],[15.5,0]],"id":52385909},{"atb":[[550,0],[650,0]],"id":52385888},{"atb":[[70,0],[38,2.7]],"id":52385882},{"atb":[[7.4,0],[5.7,0]],"id":52385915},{"atb":[[44,0],[27,0]],"id":52385884},{"atb":[[17.5,0],[12.5,0]],"id":52385895},{"atb":[[7.4,0],[9.4,0]],"id":52385928},{"atb":[[4.3,0],[5.3,0]],"id":52385891},{"atb":[[550,0],[650,0]],"id":52385924},{"atb":[[18,0],[13,0]],"id":52385934},{"atb":[[19.5,0],[29,0]],"id":52385903},{"atb":[[65,0],[36,0]],"id":52385930},{"atb":[[19,0],[14,0]],"id":52385932}],"con":true,"img":false}]}
{"op":"mcm","clk":"11450615090","pt":1717323854504,"mc":[{"id":"1.229554927","rc":[{"atl":[[48,0],[55,3.42]],"id":52385908},{"atl":[[22,0],[23,3.65]],"id":52385904},{"atl":[[22,0],[23,3.89]],"id":52385891},{"atb":[[160,3.5]],"id":52385924}],"con":true,"img":false}]}
{"op":"mcm","clk":"11450616149","pt":1717323863247,"mc":[{"id":"1.229554927","rc":[{"atb":[[19,5.8],[14,18.76]],"id":52385910},{"atb":[[10.5,11],[8.2,33.87]],"id":52385916},{"atb":[[9.2,29.74],[13,8.71]],"id":52385927},{"atb":[[9.6,28.36],[14,8.04]],"id":52385925},{"atb":[[9.8,27.71],[14.5,7.74]],"id":52385935},{"atb":[[70,1.51],[38,6.59]],"id":52385937},{"atb":[[550,0.44],[650,0.16]],"id":52385931},{"atb":[[3,174.27],[3.5,62.74]],"id":52385911},{"atb":[[3.1,49.77],[2.84,132.55]],"id":52385913},{"atb":[[7.4,16.33],[5.7,51.89]],"id":52385915},{"atb":[[7.4,38.1],[9.4,12.44]],"id":52385928},{"atb":[[550,0.44],[650,0.16]],"id":52385924},{"atb":[[18,6.14],[13,20.32]],"id":52385934},{"atb":[[65,1.63],[36,6.96]],"id":52385930},{"atb":[[19,5.8],[14,18.76]],"id":52385932}],"con":true,"img":false}]}
{"op":"mcm","clk":"11450616163","pt":1717323863301,"mc":[{"id":"1.229554927","rc":[{"atb":[[3,121.95],[3.5,41.81]],"id":52385906},{"atb":[[8,34.84],[10,11.61]],"id":52385908},{"atb":[[550,0.44],[650,0.16]],"id":52385887},{"atb":[[42,5.1],[26,9.75]],"id":52385889},{"atb":[[18.5,13.93],[27,4.01]],"id":52385885},{"atb":[[9.2,29.74],[13,8.71]],"id":52385894},{"atb":[[4.1,33.71],[3.55,95.64]],"id":52385892},{"atb":[[5.1,25.49],[4.1,78.68]],"id":52385904},{"atb":[[10.5,25.67],[15.5,7.2]],"id":52385909},{"atb":[[550,0.44],[650,0.16]],"id":52385888},{"atb":[[70,1.51],[38,9.29]],"id":52385882},{"atb":[[44,2.43],[27,9.38]],"id":52385884},{"atb":[[17.5,6.33],[12.5,21.2]],"id":52385895},{"atb":[[4.3,73.9],[5.3,24.31]],"id":52385891},{"atb":[[19.5,13.18],[29,3.73]],"id":52385903}],"con":true,"img":false}]}
{"op":"mcm","clk":"11450616213","pt":1717323863781,"mc":[{"id":"1.229554927","rc":[{"atl":[[48,2.62],[55,0]],"id":52385908},{"atl":[[22,3.37],[23,0]],"id":52385904}],"con":true,"img":false}]}
{"op":"mcm","clk":"11450622634","pt":1717323927291,"mc":[{"id":"1.229554927","rc":[{"atb":[[5.6,0],[5.5,2.99]],"id":52385906},{"atl":[[48,0],[50,3.97]],"id":52385908},{"atb":[[14.5,4.49],[15,0]],"id":52385916},{"atb":[[19.5,0],[20,7.13]],"id":52385894},{"atl":[[100,0],[110,2.67]],"id":52385927},{"atl":[[110,0],[120,2.83]],"id":52385925},{"atl":[[680,0]],"id":52385937},{"atb":[[630,0],[680,0],[730,0],[780,0]],"id":52385931},{"atb":[[4.5,4.31],[4.6,0]],"id":52385911},{"atb":[[4.3,0],[4.2,4.9]],"id":52385913},{"atl":[[7.4,3.7],[7.6,0]],"id":52385913},{"atb":[[27,0],[28,3.29]],"id":52385909},{"atl":[[19.5,0],[20,3.04]],"id":52385915},{"atl":[[65,0],[70,3.7]],"id":52385928},{"atb":[[70,0],[38,0],[95,0],[48,0],[55,2.98]],"id":52385903},{"atl":[[460,0]],"id":52385930}],"con":true,"img":false}]}
{"op":"mcm","clk":"11450622642","pt":1717323927389,"mc":[{"id":"1.229554927","rc":[{"atb":[[50,0]],"id":52385903}],"con":true,"img":false}]}
{"op":"mcm","clk":"11450622709","pt":1717323928006,"mc":[{"id":"1.229554927","rc":[{"atb":[[620,0.17],[670,0.12],[720,0.07],[770,0.04]],"id":52385931},{"atb":[[70,0.76],[38,2.83],[95,0.28],[48,1.67]],"id":52385903}],"con":true,"img":false}]}
{"op":"mcm","clk":"11450622783","pt":1717323928793,"mc":[{"id":"1.229554927","rc":[{"atl":[[110,4.16],[120,0]],"id":52385925},{"atl":[[680,3.22]],"id":52385937},{"atl":[[19.5,2.69],[20,0]],"id":52385915},{"atl":[[460,4.28]],"id":52385930}],"con":true,"img":false}]}
{"op":"mcm","clk":"11450622793","pt":1717323928904,"mc":[{"id":"1.229554927","rc":[{"atl":[[48,4.25],[50,0]],"id":52385908},{"atl":[[100,3.74],[110,0]],"id":52385927},{"atl":[[7.4,0],[7.6,3.54]],"id":52385913},{"atl":[[65,3.24],[70,0]],"id":52385928}],"con":true,"img":false}]}
{"op":"mcm","clk":"11450622807","pt":1717323929107,"mc":[{"id":"1.229554927","rc":[{"atb":[[5.6,3.66],[5.5,0]],"id":52385906},{"atb":[[14.5,0],[15,4.27]],"id":52385916},{"atb":[[19.5,3.74],[20,4.13]],"id":52385894},{"atb":[[4.5,0],[4.6,3.56]],"id":52385911},{"atb":[[4.3,4.75],[4.2,0]],"id":52385913},{"atb":[[27,3.03],[28,0]],"id":52385909},{"atb":[[50,3.55]],"id":52385903}],"con":true,"img":false}]}
{"op":"mcm","clk":"11450622815","pt":1717323929201,"mc":[{"id":"1.229554927","rc":[{"atb":[[55,0]],"id":52385903}],"con":true,"img":false}]}
{"op":"mcm","clk":"11450622936","pt":1717323930512,"mc":[{"id":"1.229554927","rc":[{"atl":[[48,0],[50,4.67]],"id":52385908},{"atl":[[100,0],[110,3.03]],"id":52385927},{"atl":[[110,0],[120,2.7]],"id":52385925},{"atl":[[680,0]],"id":52385937},{"atl":[[7.4,2.86],[7.6,0]],"id":52385913},{"atl":[[19.5,0],[20,4.23]],"id":52385915},{"atl":[[65,0],[70,3.21]],"id":52385928},{"atl":[[460,0]],"id":52385930}],"con":true,"img":false}]}
{"op":"mcm","clk":"11450622954","pt":1717323930620,"mc":[{"id":"1.229554927","rc":[{"atb":[[14.5,4.36],[15,0]],"id":52385916},{"atl":[[22,0],[23,3.77]],"id":52385904}],"con":true,"img":false}]}
{"op":"mcm","clk":"11450623136","pt":1717323932238,"mc":[{"id":"1.229554927","rc":[{"atb":[[14.5,0],[15,4.3]],"id":52385916},{"atl":[[100,2.99],[110,0]],"id":52385927},{"atl":[[110,4.5],[120,0]],"id":52385925},{"atl":[[22,3.48],[23,0]],"id":52385904},{"atl":[[680,4.24]],"id":52385937},{"atl":[[7.4,0],[7.6,3.31]],"id":52385913},{"atl":[[19.5,3.34],[20,0]],"id":52385915},{"atl":[[65,4.25],[70,0]],"id":52385928},{"atl":[[460,4.61]],"id":52385930}],"con":true,"img":false}]}
{"op":"mcm","clk":"11450623311","pt":1717323934011,"mc":[{"id":"1.229554927","rc":[{"atb":[[5.6,0],[5.5,4.46]],"id":52385906},{"atb":[[14.5,3.09],[15,0]],"id":52385916},{"atb":[[19.5,0],[20,8.05]],"id":52385894},{"atl":[[110,0],[120,2.85]],"id":52385925},{"atl":[[690,4.58]],"id":52385937},{"atb":[[4.5,3.01],[4.6,0]],"id":52385911},{"atb":[[4.3,0],[4.2,4.9]],"id":52385913},{"atb":[[27,0],[28,3.88]],"id":52385909},{"atl":[[260,3.68]],"id":52385934},{"atb":[[50,0],[55,4.62]],"id":52385903},{"atl":[[470,4.25]],"id":52385930}],"con":true,"img":false}]}
{"op":"mcm","clk":"11450623321","pt":1717323934116,"mc":[{"id":"1.229554927","rc":[{"atb":[[80,2.79],[85,0]],"id":52385885},{"atb":[[25,0],[26,6.73]],"id":52385927},{"atl":[[100,0],[110,4.35]],"id":52385927},{"atb":[[8.6,2.87],[11,0],[7.4,0],[8.4,0],[9.4,0]],"id":52385904},{"atl":[[680,0]],"id":52385937},{"atl":[[7.4,3.36],[7.6,0]],"id":52385913},{"atl":[[65,0],[70,4.29]],"id":52385928},{"atb":[[8.6,10.33],[8.8,3.37]],"id":52385891},{"atl":[[270,0]],"id":52385934},{"atl":[[460,0]],"id":52385930}],"con":true,"img":false}]}
{"op":"mcm","clk":"11450623374","pt":1717323934792,"mc":[{"id":"1.229554927","rc":[{"atb":[[9.6,6.08],[8.6,13.21],[11.5,2.49],[7.6,15.85]],"id":52385904}],"con":true,"img":false}]}
{"op":"mcm","clk":"11450623430","pt":1717323935415,"mc":[{"id":"1.229554927","rc":[{"atb":[[5.6,4.57],[5.5,0]],"id":52385906},{"atb":[[14.5,0],[15,3.01]],"id":52385916},{"atb":[[80,0],[85,3.69]],"id":52385885},{"atb":[[19.5,3.31],[20,4.13]],"id":52385894},{"atb":[[25,4.08],[26,3.14]],"id":52385927},{"atb":[[8.6,10.33]],"id":52385904},{"atb":[[4.5,0],[4.6,2.8]],"id":52385911},{"atb":[[4.3,4.75],[4.2,0]],"id":52385913},{"atb":[[27,3.08],[28,0]],"id":52385909},{"atb":[[8.6,14.8],[8.8,0]],"id":52385891},{"atb":[[50,3.08],[55,0]],"id":52385903}],"con":true,"img":false}]}
{"op":"mcm","clk":"11450623476","pt":1717323936026,"mc":[{"id":"1.229554927","rc":[{"atl":[[100,4.62],[110,0]],"id":52385927},{"atl":[[110,3.49],[120,0]],"id":52385925},{"atb":[[8.4,2.82]],"id":52385904},{"atl":[[690,0],[680,3.75]],"id":52385937},{"atl":[[7.6,4.24]],"id":52385913},{"atl":[[65,3.53],[70,0]],"id":52385928},{"atl":[[260,0],[270,3.02]],"id":52385934},{"atl":[[460,4.38],[470,0]],"id":52385930}],"con":true,"img":false}]}
{"op":"mcm","clk":"11450623489","pt":1717323936084,"mc":[{"id":"1.229554927","rc":[{"atl":[[7.4,0]],"id":52385913}],"con":true,"img":false}]}
{"op":"mcm","clk":"11450623705","pt":1717323938385,"mc":[{"id":"1.229554927","rc":[{"atb":[[28,4.66]],"id":52385909},{"atl":[[270,0]],"id":52385934}],"con":true,"img":false}]}
{"op":"mcm","clk":"11450623723","pt":1717323938498,"mc":[{"id":"1.229554927","rc":[{"atb":[[14.5,3.72],[15,0]],"id":52385916},{"atb":[[80,3.46],[85,0]],"id":52385885},{"atb":[[25,0],[26,6.02]],"id":52385927},{"atl":[[100,0],[110,3.45]],"id":52385927},{"atl":[[110,0],[120,3.13]],"id":52385925},{"atb":[[8.6,13.53],[8.4,0]],"id":52385904},{"atl":[[680,0],[690,4.3]],"id":52385937},{"atb":[[4.5,3.77],[4.6,0]],"id":52385911},{"atb":[[4.3,0]],"id":52385913},{"atl":[[7.6,0]],"id":52385913},{"atb":[[27,0]],"id":52385909},{"atl":[[65,0],[70,3.17]],"id":52385928},{"atb":[[8.6,10.33],[8.8,3.97]],"id":52385891},{"atl":[[260,4.56]],"id":52385934},{"atb":[[50,0],[55,4.45]],"id":52385903},{"atl":[[460,0],[470,3.37]],"id":52385930}],"con":true,"img":false}]}
{"op":"mcm","clk":"11450623738","pt":1717323938714,"mc":[{"id":"1.229554927","rc":[{"atl":[[670,3.77]],"id":52385937},{"atl":[[19.5,0],[19,4.26]],"id":52385915},{"atl":[[450,4.32]],"id":52385930}],"con":true,"img":false}]}
{"op":"mcm","clk":"11450623795","pt":1717323939324,"mc":[{"id":"1.229554927","rc":[{"atb":[[4.2,4.9]],"id":52385913},{"atl":[[7.4,3.26]],"id":52385913}],"con":true,"img":false}]}
{"op":"mcm","clk":"11450623819","pt":1717323939590,"mc":[{"id":"1.229554927","rc":[{"atb":[[14.5,0],[15,2.68]],"id":52385916},{"atb":[[80,0],[85,3.6]],"id":52385885},{"atb":[[25,4.15],[26,3.14]],"id":52385927},{"atb":[[8.6,10.33],[8.4,4.69]],"id":52385904},{"atl":[[670,0],[700,0]],"id":52385937},{"atb":[[4.5,0],[4.6,2.97]],"id":52385911},{"atb":[[4.3,4.75]],"id":52385913},{"atb":[[27,3.26],[28,0]],"id":52385909},{"atl":[[19,0],[19.5,3.34]],"id":52385915},{"atb":[[8.6,13.52],[8.8,0]],"id":52385891},{"atb":[[50,3.85],[55,0]],"id":52385903},{"atl":[[450,0],[480,0]],"id":52385930}],"con":true,"img":false}]}
{"op":"mcm","clk":"11450623895","pt":1717323940467,"mc":[{"id":"1.229554927","rc":[{"atb":[[14.5,4.39],[15,0]],"id":52385916},{"atb":[[80,3.92],[85,0]],"id":52385885},{"atb":[[25,0],[26,5.97]],"id":52385927},{"atl":[[100,4.39],[110,0]],"id":52385927},{"atl":[[110,2.86],[120,0]],"id":52385925},{"atb":[[8.6,13.38],[8.4,0]],"id":52385904},{"atl":[[670,4.52]],"id":52385937},{"atb":[[4.5,4.13],[4.6,0]],"id":52385911},{"atb":[[4.3,0],[4.1,0]],"id":52385913},{"atl":[[7.4,0],[7.6,4.14]],"id":52385913},{"atb":[[27,0],[28,4.58]],"id":52385909},{"atl":[[19.5,0],[19,3.79]],"id":52385915},{"atl":[[65,2.82],[70,0]],"id":52385928},{"atb":[[8.6,10.33],[8.8,4.33]],"id":52385891},{"atl":[[260,0],[270,4.18]],"id":52385934},{"atb":[[50,0],[55,2.91]],"id":52385903},{"atl":[[450,3.48]],"id":52385930}],"con":true,"img":false}]}
{"op":"mcm","clk":"11450623949","pt":1717323940935,"mc":[{"id":"1.229554927","rc":[{"atl":[[850,2],[910,0]],"id":52385935},{"atb":[[2.9,0],[3.05,48.78]],"id":52385911},{"atb":[[2.58,0],[2.7,58.14]],"id":52385913},{"atb":[[9.8,9.78],[8.8,0]],"id":52385909}],"con":true,"img":false}]}
{"op":"mcm","clk":"11450623982","pt":1717323941208,"mc":[{"id":"1.229554927","rc":[{"atl":[[100,0],[110,3.39]],"id":52385927},{"atl":[[110,0],[120,4.45]],"id":52385925},{"atl":[[670,0],[680,3.6]],"id":52385937},{"atl":[[7.4,4.45],[7.6,0]],"id":52385913},{"atl":[[19,0],[19.5,3]],"id":52385915},{"atl":[[65,0],[70,4.23]],"id":52385928},{"atl":[[270,0],[260,3.25]],"id":52385934},{"atl":[[450,0]],"id":52385930}],"con":true,"img":false}]}
{"op":"mcm","clk":"11450624031","pt":1717323941823,"mc":[{"id":"1.229554927","rc":[{"atb":[[14.5,0],[15,2.87]],"id":52385916},{"atb":[[80,0],[85,4.09]],"id":52385885},{"atb":[[25,3.54],[26,3.14]],"id":52385927},{"atb":[[9.6,0],[8.6,0],[11.5,0],[7.6,0],[8.4,3.89]],"id":52385904},{"atb":[[4.5,0],[4.6,4.45]],"id":52385911},{"atb":[[4.3,4.75]],"id":52385913},{"atb":[[27,3.42],[28,0]],"id":52385909},{"atb":[[8.6,14.43],[8.8,0]],"id":52385891},{"atb":[[50,2.81],[55,0]],"id":52385903}],"con":true,"img":false}]}
{"op":"mcm","clk":"11450624108","pt":1717323942667,"mc":[{"id":"1.229554927","rc":[{"atb":[[11,2.62],[7.4,16.35],[8.4,14.5],[9.4,6.23]],"id":52385904}],"con":true,"img":false}]}
{"op":"mcm","clk":"11450624504","pt":1717323946301,"mc":[{"id":"1.229554927","rc":[{"atb":[[7.2,10.48],[6,0]],"id":52385894}],"con":true,"img":false}]}
{"op":"mcm","clk":"11450624524","pt":1717323946508,"mc":[{"id":"1.229554927","rc":[{"atl":[[850,0],[910,2]],"id":52385935}],"con":true,"img":false}]}
{"op":"mcm","clk":"11450624534","pt":1717323946608,"mc":[{"id":"1.229554927","rc":[{"atl":[[310,0],[240,4.27]],"id":52385910},{"atl":[[48,4.31],[50,0]],"id":52385908},{"atl":[[850,0]],"id":52385889},{"atb":[[14.5,3.74],[15,0]],"id":52385916},{"atl":[[42,4.53],[46,0]],"id":52385916},{"atb":[[80,3.99],[85,0]],"id":52385885},{"atb":[[25,0],[26,6.85]],"id":52385927},{"atl":[[100,4.65],[110,0]],"id":52385927},{"atl":[[18,3.73]],"id":52385892},{"atl":[[110,3.64],[120,0]],"id":52385925},{"atl":[[200,4.21]],"id":52385935},{"atb":[[8.6,4.33],[8.4,10.61]],"id":52385904},{"atl":[[670,4.03],[680,0]],"id":52385937},{"atb":[[4.5,4.44],[4.6,0]],"id":52385911},{"atl":[[8.2,4.05]],"id":52385911},{"atb":[[4.3,0]],"id":52385913},{"atl":[[7.4,0],[7.6,4.68]],"id":52385913},{"atb":[[27,0],[28,2.78]],"id":52385909},{"atl":[[19.5,0],[19,3.62]],"id":52385915},{"atl":[[140,0]],"id":52385895},{"atl":[[65,3.77],[70,0]],"id":52385928},{"atb":[[8.6,10.33],[8.8,3.09]],"id":52385891},{"atl":[[260,0],[270,3.84]],"id":52385934},{"atb":[[50,0],[55,4.19]],"id":52385903},{"atl":[[440,4.67]],"id":52385903},{"atl":[[450,3.43]],"id":52385930}],"con":true,"img":false}]}
{"op":"mcm","clk":"11450624543","pt":1717323946718,"mc":[{"id":"1.229554927","rc":[{"atl":[[760,3.3]],"id":52385889},{"atl":[[16.5,0]],"id":52385892},{"atl":[[210,0]],"id":52385935},{"atl":[[8,0]],"id":52385911},{"atl":[[11.5,7.61],[13.5,0]],"id":52385913},{"atl":[[150,4.31]],"id":52385895},{"atl":[[550,0]],"id":52385903}],"con":true,"img":false}]}
{"op":"mcm","clk":"11450624552","pt":1717323946819,"mc":[{"id":"1.229554927","rc":[{"atl":[[44,4.05]],"id":52385916},{"atl":[[220,3.91]],"id":52385935},{"atb":[[8.6,0],[8.4,4.38]],"id":52385915},{"atl":[[450,3.52]],"id":52385903},{"atl":[[300,0],[320,4.25]],"id":52385932}],"con":true,"img":false}]}
{"op":"mcm","clk":"11450624650","pt":1717323948112,"mc":[{"id":"1.229554927","rc":[{"atl":[[48,0],[50,4.35]],"id":52385908},{"atb":[[14.5,0],[15,4.69]],"id":52385916},{"atl":[[42,0],[50,0]],"id":52385916},{"atb":[[80,0],[85,3.34]],"id":52385885},{"atb":[[25,3.61],[26,3.14]],"id":52385927},{"atl":[[100,0],[110,3.29]],"id":52385927},{"atl":[[17.5,0]],"id":52385892},{"atl":[[110,0],[120,3.55]],"id":52385925},{"atl":[[200,0],[230,0]],"id":52385935},{"atb":[[8.6,0],[8.4,15.09]],"id":52385904},{"atl":[[670,0]],"id":52385937},{"atb":[[4.5,0],[4.6,3.14]],"id":52385911},{"atl":[[8,2.87],[8.2,0]],"id":52385911},{"atl":[[7.4,4.49],[7.6,0]],"id":52385913},{"atb":[[27,3.5],[28,0]],"id":52385909},{"atl":[[19,0],[19.5,3.55]],"id":52385915},{"atl":[[65,0],[70,3.09]],"id":52385928},{"atb":[[8.6,14.38],[8.8,0]],"id":52385891},{"atl":[[270,0],[260,2.76]],"id":52385934},{"atb":[[50,4.1],[55,0]],"id":52385903},{"atl":[[440,0]],"id":52385903},{"atl":[[450,0]],"id":52385930}],"con":true,"img":false}]}
{"op":"mcm","clk":"11450624658","pt":1717323948211,"mc":[{"id":"1.229554927","rc":[{"atl":[[460,4.1]],"id":52385930}],"con":true,"img":false}]}
{"op":"mcm","clk":"11450624667","pt":1717323948317,"mc":[{"id":"1.229554927","rc":[{"atl":[[680,3.88]],"id":52385937}],"con":true,"img":false}]}
{"op":"mcm","clk":"11450624825","pt":1717323950300,"mc":[{"id":"1.229554927","rc":[{"atl":[[48,3.31],[50,0]],"id":52385908},{"atb":[[14.5,3.87],[15,0]],"id":52385916},{"atb":[[80,4.48],[85,0]],"id":52385885},{"atb":[[25,0],[26,7.64]],"id":52385927},{"atl":[[100,4.33],[110,0]],"id":52385927},{"atl":[[110,4.63],[120,0]],"id":52385925},{"atb":[[8.6,4.43],[8.4,10.61]],"id":52385904},{"atl":[[670,3.19],[680,0]],"id":52385937},{"atb":[[4.5,3.4],[4.6,0]],"id":52385911},{"atl":[[7.4,0],[7.6,3.22]],"id":52385913},{"atb":[[27,0],[28,3.42]],"id":52385909},{"atl":[[19.5,0],[19,2.87]],"id":52385915},{"atl":[[65,3.28],[70,0]],"id":52385928},{"atb":[[8.6,10.33],[8.8,3.47]],"id":52385891},{"atl":[[260,0],[270,3.48]],"id":52385934},{"atb":[[50,0],[55,3.73]],"id":52385903},{"atl":[[460,0],[450,2.8]],"id":52385930}],"con":true,"img":false}]}
{"op":"mcm","clk":"11450625088","pt":1717323953322,"mc":[{"id":"1.229554927","rc":[{"atb":[[14.5,0],[15,2.94]],"id":52385916},{"atb":[[80,0],[85,2.99]],"id":52385885},{"atb":[[25,3.85],[26,3.14]],"id":52385927},{"atb":[[8.6,0],[8.4,15.26]],"id":52385904},{"atb":[[4.5,0],[4.6,3.4]],"id":52385911},{"atb":[[27,3.13],[28,0]],"id":52385909},{"atb":[[8.6,13.98],[8.8,0]],"id":52385891},{"atb":[[50,3.3],[55,0]],"id":52385903}],"con":true,"img":false}]}
{"op":"mcm","clk":"11450625364","pt":1717323956743,"mc":[{"id":"1.229554927","rc":[{"atl":[[780,3.53]],"id":52385889},{"atl":[[19,3.13]],"id":52385892}],"con":true,"img":false}]}
{"op":"mcm","clk":"11450625382","pt":1717323956901,"mc":[{"id":"1.229554927","rc":[{"atl":[[260,3.33]],"id":52385910},{"atl":[[240,2.65]],"id":52385935}],"con":true,"img":false}]}
{"op":"mcm","clk":"11450625668","pt":1717323960328,"mc":[{"id":"1.229554927","rc":[{"atl":[[50,3.7]],"id":52385908},{"atl":[[110,0],[120,3.46]],"id":52385925},{"atl":[[680,3.94]],"id":52385937},{"atb":[[4,5.23]],"id":52385913},{"atl":[[7.4,3.67],[7.6,0]],"id":52385913},{"atl":[[19,0],[19.5,3.82]],"id":52385915},{"atl":[[65,0],[70,4.03]],"id":52385928},{"atl":[[270,0],[260,4.47]],"id":52385934},{"atl":[[450,0],[490,3.03]],"id":52385930}],"con":true,"img":false}]}
{"op":"mcm","clk":"11450625678","pt":1717323960429,"mc":[{"id":"1.229554927","rc":[{"atl":[[48,0]],"id":52385908},{"atl":[[670,0]],"id":52385937}],"con":true,"img":false}]}
{"op":"mcm","clk":"11450625706","pt":1717323960741,"mc":[{"id":"1.229554927","rc":[{"atb":[[14.5,3.3]],"id":52385916},{"atb":[[8.4,10.61]],"id":52385904},{"atb":[[4.6,0]],"id":52385911},{"atb":[[8.8,2.72]],"id":52385891}],"con":true,"img":false}]}
{"op":"mcm","clk":"11450625720","pt":1717323960847,"mc":[{"id":"1.229554927","rc":[{"atl":[[330,0]],"id":52385910},{"atl":[[870,0]],"id":52385889},{"atb":[[15,0]],"id":52385916},{"atb":[[80,3.64],[85,0]],"id":52385885},{"atb":[[25,0],[26,5.89]],"id":52385927},{"atl":[[100,0],[110,3.91]],"id":52385927},{"atb":[[8.6,3.87]],"id":52385904},{"atb":[[4.5,2.99]],"id":52385911},{"atb":[[27,0],[28,2.75]],"id":52385909},{"atb":[[8.6,10.33]],"id":52385891},{"atb":[[50,0],[55,3.95]],"id":52385903}],"con":true,"img":false}]}
{"op":"mcm","clk":"11450626009","pt":1717323964243,"mc":[{"id":"1.229554927","rc":[{"atb":[[5.6,0],[5.7,2.88]],"id":52385906},{"atl":[[680,0]],"id":52385937},{"atb":[[9.6,0],[8.6,0],[11.5,0],[7.6,0]],"id":52385891},{"atb":[[46,0],[48,5.11]],"id":52385934},{"atl":[[260,0],[270,3.44]],"id":52385934}],"con":true,"img":false}]}
{"op":"mcm","clk":"11450626058","pt":1717323964911,"mc":[{"id":"1.229554927","rc":[{"atb":[[12,2.38],[9.8,5.94],[8.8,12.79],[7.8,15.39]],"id":52385891}],"con":true,"img":false}]}
{"op":"mcm","clk":"11450626508","pt":1717323970331,"mc":[{"id":"1.229554927","rc":[{"atl":[[48,4.5],[50,0]],"id":52385908},{"atl":[[110,2.84],[120,0]],"id":52385925},{"atl":[[680,4.03]],"id":52385937},{"atl":[[65,3.88],[70,0]],"id":52385928},{"atl":[[460,3.28],[470,0]],"id":52385930}],"con":true,"img":false}]}
{"op":"mcm","clk":"11450626558","pt":1717323970745,"mc":[{"id":"1.229554927","rc":[{"atl":[[48,3.5]],"id":52385916},{"atl":[[100,2.76],[110,0]],"id":52385927},{"atl":[[470,3.68]],"id":52385903}],"con":true,"img":false}]}
{"op":"mcm","clk":"11450626574","pt":1717323970852,"mc":[{"id":"1.229554927","rc":[{"atb":[[8.4,2.85]],"id":52385891}],"con":true,"img":false}]}
{"op":"mcm","clk":"11450626657","pt":1717323971638,"mc":[{"id":"1.229554927","rc":[{"atb":[[19,0],[14,0]],"id":52385910},{"atb":[[3,0],[3.5,0]],"id":52385906},{"atb":[[8,0],[10,0]],"id":52385908},{"atb":[[550,0],[650,0]],"id":52385887},{"atb":[[42,2.55],[26,0]],"id":52385889},{"atb":[[10.5,0],[8.2,0]],"id":52385916},{"atb":[[18.5,0],[27,0]],"id":52385885},{"atb":[[9.2,0],[13,0]],"id":52385894},{"atb":[[9.2,0],[13,0]],"id":52385927},{"atb":[[4.1,0],[3.55,0]],"id":52385892},{"atb":[[9.6,0],[14,0]],"id":52385925},{"atb":[[9.8,0],[14.5,0]],"id":52385935},{"atb":[[5.1,0],[4.1,0]],"id":52385904},{"atb":[[70,0],[38,0]],"id":52385937},{"atb":[[550,0],[650,0]],"id":52385931},{"atb":[[3,52.32],[3.5,20.93]],"id":52385911},{"atb":[[3.1,0],[2.84,0]],"id":52385913},{"atb":[[10.5,0],[15.5,0]],"id":52385909},{"atb":[[550,0],[650,0]],"id":52385888},{"atb":[[70,0],[38,2.7]],"id":52385882},{"atb":[[7.4,0],[5.7,0]],"id":52385915},{"atb":[[44,0],[27,0]],"id":52385884},{"atb":[[17.5,0],[12.5,0]],"id":52385895},{"atb":[[7.4,0],[9.4,0]],"id":52385928},{"atb":[[4.3,0],[5.3,0]],"id":52385891},{"atl":[[23,0]],"id":52385891},{"atb":[[550,0],[650,0]],"id":52385924},{"atb":[[18,0],[13,0]],"id":52385934},{"atb":[[19.5,0],[29,0]],"id":52385903},{"atl":[[570,0]],"id":52385903},{"atb":[[65,0],[36,0]],"id":52385930},{"atb":[[19,0],[14,0]],"id":52385932}],"con":true,"img":false}]}
{"op":"mcm","clk":"11450626665","pt":1717323971740,"mc":[{"id":"1.229554927","rc":[{"atl":[[22,3.15]],"id":52385891}],"con":true,"img":false}]}
{"op":"mcm","clk":"11450626709","pt":1717323972220,"mc":[{"id":"1.229554927","rc":[{"atl":[[48,0],[50,3.59]],"id":52385908},{"atl":[[22,0],[23,3.36]],"id":52385904},{"atb":[[8,0]],"id":52385891}],"con":true,"img":false}]}
{"op":"mcm","clk":"11450626888","pt":1717323973968,"mc":[{"id":"1.229554927","rc":[{"atl":[[100,0],[110,3.5]],"id":52385927},{"atl":[[110,0],[120,4.39]],"id":52385925},{"atl":[[680,0]],"id":52385937},{"atl":[[65,0],[70,4.44]],"id":52385928},{"atl":[[22,0]],"id":52385891},{"atl":[[460,0],[470,4.38]],"id":52385930}],"con":true,"img":false}]}
{"op":"mcm","clk":"11450626896","pt":1717323974071,"mc":[{"id":"1.229554927","rc":[{"atl":[[23,4.16]],"id":52385891}],"con":true,"img":false}]}
{"op":"mcm","clk":"11450626907","pt":1717323974176,"mc":[{"id":"1.229554927","rc":[{"atl":[[22,3.78],[23,0]],"id":52385904}],"con":true,"img":false}]}
{"op":"mcm","clk":"11450626978","pt":1717323974858,"mc":[{"id":"1.229554927","rc":[{"atl":[[22,3.2]],"id":52385891}],"con":true,"img":false}]}
{"op":"mcm","clk":"11450626985","pt":1717323974962,"mc":[{"id":"1.229554927","rc":[{"atl":[[23,0]],"id":52385891}],"con":true,"img":false}]}
{"op":"mcm","clk":"11450627049","pt":1717323975637,"mc":[{"id":"1.229554927","rc":[{"atl":[[24,0]],"id":52385891}],"con":true,"img":false}]}
{"op":"mcm","clk":"11450627059","pt":1717323975742,"mc":[{"id":"1.229554927","rc":[{"atb":[[5.5,4.22],[5.7,0]],"id":52385906},{"atb":[[19.5,0],[20,8.82]],"id":52385894},{"atl":[[55,0],[60,4.55]],"id":52385894},{"atl":[[110,0]],"id":52385927},{"atl":[[690,0],[730,4.45]],"id":52385937},{"atb":[[4.5,0],[4.4,4.67]],"id":52385911},{"atl":[[85,0],[90,4.39]],"id":52385909},{"atl":[[70,0]],"id":52385928},{"atb":[[160,0],[170,4.01]],"id":52385924},{"atb":[[46,3.17],[48,1.67]],"id":52385934},{"atl":[[270,0]],"id":52385934},{"atl":[[470,0]],"id":52385930}],"con":true,"img":false}]}
{"op":"mcm","clk":"11450627112","pt":1717323976157,"mc":[{"id":"1.229554927","rc":[{"atl":[[7.2,3.09]],"id":52385913},{"atl":[[20,3.06]],"id":52385915},{"atl":[[500,4.61]],"id":52385930}],"con":true,"img":false}]}
{"op":"mcm","clk":"11450627125","pt":1717323976263,"mc":[{"id":"1.229554927","rc":[{"atl":[[7.4,0]],"id":52385913},{"atl":[[19.5,0]],"id":52385915}],"con":true,"img":false}]}
{"op":"mcm","clk":"11450627286","pt":1717323978035,"mc":[{"id":"1.229554927","rc":[{"atl":[[7.2,0],[7.4,3.89]],"id":52385913},{"atl":[[85,4.38],[90,0]],"id":52385909},{"atl":[[270,3.62]],"id":52385934},{"atl":[[520,2.72],[490,0]],"id":52385930}],"con":true,"img":false}]}
{"op":"mcm","clk":"11450627402","pt":1717323979135,"mc":[{"id":"1.229554927","rc":[{"atb":[[27,0]],"id":52385910},{"atb":[[190,0],[200,3.61]],"id":52385887},{"atb":[[14.5,0]],"id":52385916},{"atb":[[20,4.13]],"id":52385894},{"atb":[[27,3.03]],"id":52385927},{"atb":[[36,0],[46,0],[23,0],[27,0],[28,0],[29,2.65]],"id":52385925},{"atb":[[8.6,0],[8.4,13.64]],"id":52385904},{"atb":[[130,4.23],[120,0]],"id":52385937},{"atb":[[16.5,4.68],[17.5,0],[19,3.06],[23,0],[28,0]],"id":52385928},{"atb":[[110,0],[120,4.34]],"id":52385930},{"atl":[[500,0]],"id":52385930}],"con":true,"img":false}]}
{"op":"mcm","clk":"11450627408","pt":1717323979240,"mc":[{"id":"1.229554927","rc":[{"atb":[[21,4.64]],"id":52385894}],"con":true,"img":false}]}
{"op":"mcm","clk":"11450627421","pt":1717323979397,"mc":[{"id":"1.229554927","rc":[{"atb":[[26,3.14]],"id":52385927}],"con":true,"img":false}]}
{"op":"mcm","clk":"11450627470","pt":1717323979871,"mc":[{"id":"1.229554927","rc":[{"atb":[[40,1.34],[25,8.71],[50,0.53],[30,2.71]],"id":52385925},{"atb":[[17.5,6.34],[20,4.13],[25,2.18],[30,0.9]],"id":52385928}],"con":true,"img":false}]}
{"op":"mcm","clk":"11450627537","pt":1717323980753,"mc":[{"id":"1.229554927","rc":[{"atb":[[13,4.19]],"id":52385916}],"con":true,"img":false}]}
{"op":"mcm","clk":"11450627552","pt":1717323980962,"mc":[{"id":"1.229554927","rc":[{"atb":[[18,6.14],[13,20.32]],"id":52385910},{"atb":[[3,121.95],[3.5,41.81]],"id":52385906},{"atb":[[10.5,11],[8.2,33.87]],"id":52385908},{"atb":[[550,0.44],[650,0.16]],"id":52385887},{"atb":[[34,3.16],[22,11.61]],"id":52385889},{"atb":[[10.5,11],[8.2,33.87]],"id":52385916},{"atb":[[16.5,15.73],[23,4.75]],"id":52385885},{"atb":[[9.2,29.74],[13,8.71]],"id":52385894},{"atb":[[9.2,29.74],[13,8.71]],"id":52385927},{"atb":[[4.1,33.71],[3.55,95.64]],"id":52385892},{"atb":[[9.6,28.36],[14,8.04]],"id":52385925},{"atb":[[9.8,27.71],[14.5,7.74]],"id":52385935},{"atb":[[5.2,24.88],[4.2,76.22]],"id":52385904},{"atb":[[75,1.41],[40,6.25]],"id":52385937},{"atb":[[550,0.44],[650,0.16]],"id":52385931},{"atb":[[3,174.27],[3.5,62.74]],"id":52385911},{"atb":[[3.1,49.77],[2.84,132.55]],"id":52385913},{"atb":[[10.5,25.67],[15.5,7.2]],"id":52385909},{"atb":[[550,0.44],[650,0.16]],"id":52385888},{"atb":[[48,2.22],[29,8.71]],"id":52385882},{"atb":[[7.4,16.33],[5.7,51.89]],"id":52385915},{"atb":[[36,2.98],[23,11.08]],"id":52385884},{"atb":[[18,6.14],[13,20.32]],"id":52385895},{"atb":[[7.4,38.1],[9.4,12.44]],"id":52385928},{"atb":[[4.3,73.9],[5.3,24.31]],"id":52385891},{"atb":[[550,0.44],[650,0.16]],"id":52385924},{"atb":[[18,6.14],[13,20.32]],"id":52385934},{"atb":[[18,14.34],[26,4.18]],"id":52385903},{"atb":[[70,3.03],[38,6.59]],"id":52385930},{"atb":[[19,5.8],[14,18.76]],"id":52385932}],"con":true,"img":false}]}
{"op":"mcm","clk":"11450627602","pt":1717323981441,"mc":[{"id":"1.229554927","rc":[{"atl":[[11.5,4.06],[12,0]],"id":52385906},{"atl":[[7.2,3.57],[7.4,0]],"id":52385913},{"atl":[[70,2.84]],"id":52385928}],"con":true,"img":false}]}
{"op":"mcm","clk":"11450627639","pt":1717323981753,"mc":[{"id":"1.229554927","rc":[{"atb":[[24,4.04]],"id":52385910}],"con":true,"img":false}]}
{"op":"mcm","clk":"11450627909","pt":1717323984840,"mc":[{"id":"1.229554927","rc":[{"atl":[[24,4.36]],"id":52385891}],"con":true,"img":false}]}
{"op":"mcm","clk":"11450627942","pt":1717323985259,"mc":[{"id":"1.229554927","rc":[{"atb":[[26,0],[27,4.22]],"id":52385910},{"atl":[[11.5,0],[12,2.63]],"id":52385906},{"atb":[[200,0]],"id":52385887},{"atb":[[14,8.05],[14.5,3.32]],"id":52385916},{"atb":[[20,6.91],[21,0]],"id":52385894},{"atb":[[26,6.23],[27,0]],"id":52385927},{"atb":[[27,2.74],[29,0]],"id":52385925},{"atl":[[120,0]],"id":52385925},{"atb":[[8.6,3.82],[8.4,10.61]],"id":52385904},{"atb":[[130,0],[120,4.18]],"id":52385937},{"atl":[[730,0],[760,3.27]],"id":52385937},{"atl":[[85,0],[90,4.3]],"id":52385909},{"atl":[[19.5,4.49],[20,0]],"id":52385915},{"atb":[[17.5,9.79],[19,0]],"id":52385928},{"atl":[[70,0]],"id":52385928},{"atl":[[270,0]],"id":52385934},{"atb":[[110,4.34],[120,0]],"id":52385930}],"con":true,"img":false}]}
{"op":"mcm","clk":"11450628178","pt":1717323988059,"mc":[{"id":"1.229554927","rc":[{"atl":[[300,4.66]],"id":52385934}],"con":true,"img":false}]}
{"op":"mcm","clk":"11450628605","pt":1717323992897,"mc":[{"id":"1.229554927","rc":[{"atb":[[26,4.53],[27,0]],"id":52385910},{"atl":[[11.5,2.7],[12,0]],"id":52385906},{"atb":[[14,12.56],[14.5,0]],"id":52385916},{"atb":[[20,4.13],[21,3.73]],"id":52385894},{"atb":[[26,3.14],[27,3.17]],"id":52385927},{"atb":[[27,0],[29,3.3]],"id":52385925},{"atl":[[120,4.13]],"id":52385925},{"atb":[[8.6,0],[8.4,15.18]],"id":52385904},{"atb":[[130,4.42],[120,0]],"id":52385937},{"atl":[[730,3.86]],"id":52385937},{"atl":[[85,3.17],[90,0]],"id":52385909},{"atl":[[19.5,0],[20,3.36]],"id":52385915},{"atb":[[17.5,6.34],[19,4.61]],"id":52385928},{"atl":[[270,2.67],[280,0]],"id":52385934},{"atb":[[110,0],[120,3.98]],"id":52385930}],"con":true,"img":false}]}
{"op":"mcm","clk":"11450628762","pt":1717323994474,"mc":[{"id":"1.229554927","rc":[{"atl":[[11.5,0],[12,4.5]],"id":52385906},{"atl":[[7.2,0],[7.4,3.14]],"id":52385913}],"con":true,"img":false}]}
{"op":"mcm","clk":"11450629180","pt":1717323999193,"mc":[{"id":"1.229554927","rc":[{"atb":[[5.6,4.42],[5.5,0]],"id":52385906},{"atb":[[6.2,4.44],[6,10.46]],"id":52385892},{"atb":[[8.6,4.34],[8.4,10.61]],"id":52385904},{"atb":[[4.5,3.11],[4.4,0]],"id":52385911},{"atb":[[27,3.67],[28,0]],"id":52385909},{"atb":[[9,4.15],[8.8,10.06]],"id":52385891},{"atb":[[50,4.48],[55,0]],"id":52385903}],"con":true,"img":false}]}
{"op":"mcm","clk":"11450629226","pt":1717323999813,"mc":[{"id":"1.229554927","rc":[{"atb":[[18,0],[13,0]],"id":52385910},{"atb":[[3,0],[3.5,0]],"id":52385906},{"atb":[[10.5,0],[8.2,0]],"id":52385908},{"atb":[[550,0],[650,0]],"id":52385887},{"atb":[[34,0],[22,0]],"id":52385889},{"atb":[[10.5,0],[8.2,0]],"id":52385916},{"atb":[[16.5,0],[23,0]],"id":52385885},{"atb":[[9.2,0],[13,0]],"id":52385894},{"atb":[[9.2,0],[13,0]],"id":52385927},{"atb":[[4.1,0],[3.55,0]],"id":52385892},{"atb":[[9.6,0],[14,0]],"id":52385925},{"atb":[[9.8,0],[14.5,0]],"id":52385935},{"atb":[[5.2,0],[4.2,0]],"id":52385904},{"atb":[[75,0],[40,0]],"id":52385937},{"atb":[[550,0],[650,0]],"id":52385931},{"atb":[[3,52.32],[3.5,20.93]],"id":52385911},{"atb":[[3.1,0],[2.84,0]],"id":52385913},{"atb":[[10.5,0],[15.5,0]],"id":52385909},{"atb":[[550,0],[650,0]],"id":52385888},{"atb":[[48,0],[29,0]],"id":52385882},{"atb":[[7.4,0],[5.7,0]],"id":52385915},{"atb":[[36,0],[23,0]],"id":52385884},{"atb":[[18,0],[13,0]],"id":52385895},{"atb":[[7.4,0],[9.4,0]],"id":52385928},{"atb":[[4.3,0],[5.3,0]],"id":52385891},{"atb":[[550,0],[650,0]],"id":52385924},{"atb":[[18,0],[13,0]],"id":52385934},{"atb":[[18,0],[26,0]],"id":52385903},{"atb":[[70,1.52],[38,0]],"id":52385930},{"atb":[[19,0],[14,0]],"id":52385932}],"con":true,"img":false}]}
{"op":"mcm","clk":"11450629249","pt":1717324000084,"mc":[{"id":"1.229554927","rc":[{"atb":[[5.5,4.38]],"id":52385906},{"atb":[[6.2,0],[6,13.64]],"id":52385892},{"atb":[[8.6,0]],"id":52385904},{"atb":[[4.5,0],[4.4,3.91]],"id":52385911},{"atb":[[27,0],[28,3.25]],"id":52385909},{"atb":[[9,0],[8.8,12.77]],"id":52385891},{"atb":[[50,0],[55,3.53]],"id":52385903}],"con":true,"img":false}]}
{"op":"mcm","clk":"11450629257","pt":1717324000184,"mc":[{"id":"1.229554927","rc":[{"atb":[[5.6,0]],"id":52385906},{"atb":[[8.4,13.87]],"id":52385904}],"con":true,"img":false}]}
{"op":"mcm","clk":"11450629266","pt":1717324000285,"mc":[{"id":"1.229554927","rc":[{"atb":[[200,4.35]],"id":52385887}],"con":true,"img":false}]}
{"op":"mcm","clk":"11450629547","pt":1717324002897,"mc":[{"id":"1.229554927","rc":[{"atb":[[19.5,4.17]],"id":52385894},{"atb":[[25,3.44]],"id":52385927},{"atl":[[140,3.27]],"id":52385927},{"atb":[[27,3.53]],"id":52385925},{"atb":[[18,3.08]],"id":52385928},{"atl":[[85,3.68]],"id":52385928},{"atl":[[540,4.38]],"id":52385930}],"con":true,"img":false}]}
{"op":"mcm","clk":"11450629673","pt":1717324004300,"mc":[{"id":"1.229554927","rc":[{"atb":[[18.5,0]],"id":52385894},{"atb":[[23,0]],"id":52385927},{"atb":[[25,4.36]],"id":52385925},{"atb":[[16.5,0]],"id":52385928}],"con":true,"img":false}]}
{"op":"mcm","clk":"11450629735","pt":1717324004825,"mc":[{"id":"1.229554927","rc":[{"atb":[[18,6.14],[13,20.32]],"id":52385910},{"atb":[[3.55,40.99],[3.05,118.97]],"id":52385906},{"atb":[[10.5,11],[8.2,33.87]],"id":52385908},{"atb":[[550,0.44],[650,0.16]],"id":52385887},{"atb":[[34,3.16],[22,11.61]],"id":52385889},{"atb":[[10.5,11],[8.2,33.87]],"id":52385916},{"atb":[[16.5,15.73],[23,4.75]],"id":52385885},{"atb":[[9.2,29.74],[13,8.71]],"id":52385894},{"atb":[[9.2,29.74],[13,8.71]],"id":52385927},{"atb":[[4,34.84],[3.5,97.56]],"id":52385892},{"atb":[[9.6,28.36],[14,8.04]],"id":52385925},{"atb":[[9.8,27.71],[14.5,7.74]],"id":52385935},{"atb":[[5.2,24.88],[4.2,76.22]],"id":52385904},{"atb":[[70,1.51],[38,6.59]],"id":52385937},{"atb":[[550,0.44],[650,0.16]],"id":52385931},{"atb":[[3.45,42.66],[2.98,123.18]],"id":52385911},{"atb":[[3.1,49.77],[2.84,132.55]],"id":52385913},{"atb":[[10.5,25.67],[15.5,7.2]],"id":52385909},{"atb":[[550,0.44],[650,0.16]],"id":52385888},{"atb":[[48,2.22],[29,8.71]],"id":52385882},{"atb":[[7.4,16.33],[5.7,51.89]],"id":52385915},{"atb":[[36,2.98],[23,11.08]],"id":52385884},{"atb":[[18,6.14],[13,20.32]],"id":52385895},{"atb":[[7.4,38.1],[9.4,12.44]],"id":52385928},{"atb":[[4.4,71.73],[5.4,23.75]],"id":52385891},{"atb":[[540,0.44],[640,0.16]],"id":52385924},{"atb":[[18,6.14],[13,20.32]],"id":52385934},{"atb":[[18,14.34],[26,4.18]],"id":52385903},{"atb":[[65,1.63],[36,6.96]],"id":52385930},{"atb":[[19,5.8],[14,18.76]],"id":52385932}],"con":true,"img":false}]}
{"op":"mcm","clk":"11450630157","pt":1717324009503,"mc":[{"id":"1.229554927","rc":[{"atl":[[22,0],[23,3.07]],"id":52385904},{"atl":[[23,3.33]],"id":52385891}],"con":true,"img":false}]}
{"op":"mcm","clk":"11450630170","pt":1717324009608,"mc":[{"id":"1.229554927","rc":[{"atl":[[22,0]],"id":52385891}],"con":true,"img":false}]}
{"op":"mcm","clk":"11450630214","pt":1717324010190,"mc":[{"id":"1.229554927","rc":[{"atl":[[22,4.43],[23,0]],"id":52385904},{"atl":[[24,0]],"id":52385891}],"con":true,"img":false}]}
{"op":"mcm","clk":"11450630833","pt":1717324017598,"mc":[{"id":"1.229554927","rc":[{"atl":[[22,4.16]],"id":52385891}],"con":true,"img":false}]}
{"op":"mcm","clk":"11450631203","pt":1717324021935,"mc":[{"id":"1.229554927","rc":[{"atl":[[22,0]],"id":52385891}],"con":true,"img":false}]}
{"op":"mcm","clk":"11450631702","pt":1717324026929,"mc":[{"id":"1.229554927","rc":[{"atb":[[620,0],[670,0],[720,0],[770,0]],"id":52385931},{"atb":[[70,0],[38,0],[95,0],[48,0]],"id":52385903}],"con":true,"img":false}]}
{"op":"mcm","clk":"11450631770","pt":1717324027610,"mc":[{"id":"1.229554927","rc":[{"atb":[[630,0.17],[680,0.12],[730,0.07],[780,0.03]],"id":52385931},{"atl":[[25,3.28]],"id":52385891},{"atb":[[75,0.71],[100,0.27],[50,1.6]],"id":52385903}],"con":true,"img":false}]}
{"op":"mcm","clk":"11450631779","pt":1717324027712,"mc":[{"id":"1.229554927","rc":[{"atb":[[40,2.68]],"id":52385903}],"con":true,"img":false}]}
{"op":"mcm","clk":"11450632758","pt":1717324040168,"mc":[{"id":"1.229554927","rc":[{"atb":[[11,0],[7.4,0],[8.4,3.26],[9.4,0]],"id":52385904}],"con":true,"img":false}]}
{"op":"mcm","clk":"11450632823","pt":1717324040850,"mc":[{"id":"1.229554927","rc":[{"atb":[[9.6,6.08],[8.6,10.33],[11.5,2.49],[7.6,15.85]],"id":52385904}],"con":true,"img":false}]}
{"op":"mcm","clk":"11450635066","pt":1717324066519,"mc":[{"id":"1.229554927","rc":[{"atb":[[34,0],[29,3.57]],"id":52385910},{"atl":[[910,0],[980,2]],"id":52385935},{"atb":[[2.88,53.19],[3.05,0]],"id":52385911},{"atb":[[2.48,58.14],[2.7,0]],"id":52385913},{"atl":[[420,0],[480,2]],"id":52385909},{"atl":[[610,0],[710,2]],"id":52385895}],"con":true,"img":false}]}
{"op":"mcm","clk":"11450636628","pt":1717324083883,"mc":[{"id":"1.229554927","rc":[{"atb":[[16.5,0],[19,0],[23,0],[14,4.5]],"id":52385916}],"con":true,"img":false}]}
{"op":"mcm","clk":"11450636688","pt":1717324084559,"mc":[{"id":"1.229554927","rc":[{"atb":[[16,5.23],[18.5,2.99],[22,1.25],[13.5,8.37]],"id":52385916}],"con":true,"img":false}]}
{"op":"mcm","clk":"11450636987","pt":1717324088093,"mc":[{"id":"1.229554927","rc":[{"atb":[[18,0],[13,0]],"id":52385910},{"atb":[[3.55,0],[3.05,0]],"id":52385906},{"atb":[[10.5,0],[8.2,0]],"id":52385908},{"atb":[[550,0],[650,0]],"id":52385887},{"atb":[[34,0],[22,0]],"id":52385889},{"atb":[[10.5,0],[8.2,0]],"id":52385916},{"atb":[[16.5,0],[23,0]],"id":52385885},{"atb":[[9.2,0],[13,0]],"id":52385894},{"atb":[[9.2,0],[13,0]],"id":52385927},{"atb":[[4,0],[3.5,0]],"id":52385892},{"atb":[[9.6,0],[14,0]],"id":52385925},{"atb":[[9.8,0],[14.5,0]],"id":52385935},{"atb":[[5.2,0],[4.2,0]],"id":52385904},{"atb":[[70,0],[38,0]],"id":52385937},{"atb":[[550,0],[650,0]],"id":52385931},{"atb":[[3.45,0],[2.98,0]],"id":52385911},{"atb":[[3.1,0],[2.84,0]],"id":52385913},{"atb":[[10.5,0],[15.5,0]],"id":52385909},{"atb":[[550,0],[650,0]],"id":52385888},{"atb":[[48,0],[29,0]],"id":52385882},{"atb":[[7.4,0],[5.7,0]],"id":52385915},{"atb":[[36,0],[23,0]],"id":52385884},{"atb":[[18,0],[13,0]],"id":52385895},{"atb":[[7.4,0],[9.4,0]],"id":52385928},{"atb":[[4.4,0],[5.4,0]],"id":52385891},{"atb":[[540,0],[640,0]],"id":52385924},{"atb":[[18,0],[13,0]],"id":52385934},{"atb":[[18,0],[26,0]],"id":52385903},{"atb":[[65,0],[36,0]],"id":52385930},{"atb":[[19,0],[14,0]],"id":52385932}],"con":true,"img":false}]}
{"op":"mcm","clk":"11450637502","pt":1717324094082,"mc":[{"id":"1.229554927","rc":[{"atb":[[3.55,40.99],[3.05,118.97]],"id":52385906},{"atb":[[10.5,11],[8.2,33.87]],"id":52385908},{"atb":[[550,0.44],[650,0.16]],"id":52385887},{"atb":[[34,3.16],[22,11.61]],"id":52385889},{"atb":[[16.5,15.73],[23,4.75]],"id":52385885},{"atb":[[9.2,29.74],[13,8.71]],"id":52385894},{"atb":[[4,34.84],[3.5,97.56]],"id":52385892},{"atb":[[5.2,24.88],[4.2,76.22]],"id":52385904},{"atb":[[10.5,25.67],[15.5,7.2]],"id":52385909},{"atb":[[550,0.44],[650,0.16]],"id":52385888},{"atb":[[48,2.22],[29,8.71]],"id":52385882},{"atb":[[36,2.98],[23,11.08]],"id":52385884},{"atb":[[18,6.14],[13,20.32]],"id":52385895},{"atb":[[4.4,71.73],[5.4,23.75]],"id":52385891},{"atb":[[18,14.34],[26,4.18]],"id":52385903}],"con":true,"img":false}]}
{"op":"mcm","clk":"11450637514","pt":1717324094192,"mc":[{"id":"1.229554927","rc":[{"atb":[[18,6.14],[13,20.32]],"id":52385910},{"atb":[[10.5,11],[8.2,33.87]],"id":52385916},{"atb":[[9.2,29.74],[13,8.71]],"id":52385927},{"atb":[[9.6,28.36],[14,8.04]],"id":52385925},{"atb":[[9.8,27.71],[14.5,7.74]],"id":52385935},{"atb":[[70,1.51],[38,6.59]],"id":52385937},{"atb":[[550,0.44],[650,0.16]],"id":52385931},{"atb":[[3.45,42.66],[2.98,123.18]],"id":52385911},{"atb":[[3.1,49.77],[2.84,132.55]],"id":52385913},{"atb":[[7.4,16.33],[5.7,51.89]],"id":52385915},{"atb":[[7.4,38.1],[9.4,12.44]],"id":52385928},{"atb":[[540,0.44],[640,0.16]],"id":52385924},{"atb":[[18,6.14],[13,20.32]],"id":52385934},{"atb":[[65,1.63],[36,6.96]],"id":52385930},{"atb":[[19,5.8],[14,18.76]],"id":52385932}],"con":true,"img":false}]}
{"op":"mcm","clk":"11450637903","pt":1717324098669,"mc":[{"id":"1.229554927","rc":[{"atl":[[22,0],[23,2.75]],"id":52385904}],"con":true,"img":false}]}
{"op":"mcm","clk":"11450637980","pt":1717324099595,"mc":[{"id":"1.229554927","rc":[{"atl":[[22,4.63],[23,0]],"id":52385904}],"con":true,"img":false}]}
{"op":"mcm","clk":"11450638047","pt":1717324100491,"mc":[{"id":"1.229554927","rc":[{"atl":[[22,0],[23,2.97]],"id":52385904}],"con":true,"img":false}]}
{"op":"mcm","clk":"11450647660","pt":1717324201524,"mc":[{"id":"1.229554927","rc":[{"atb":[[18,0],[13,0]],"id":52385910},{"atb":[[3.55,0],[3.05,0]],"id":52385906},{"atb":[[10.5,0],[8.2,0]],"id":52385908},{"atb":[[550,0],[650,0]],"id":52385887},{"atb":[[34,0],[22,0]],"id":52385889},{"atb":[[10.5,0],[8.2,0]],"id":52385916},{"atb":[[16.5,0],[23,0]],"id":52385885},{"atb":[[9.2,0],[13,0]],"id":52385894},{"atb":[[9.2,0],[13,0]],"id":52385927},{"atb":[[4,0],[3.5,0]],"id":52385892},{"atb":[[9.6,0],[14,0]],"id":52385925},{"atb":[[9.8,0],[14.5,0]],"id":52385935},{"atb":[[5.2,0],[4.2,0]],"id":52385904},{"atb":[[70,0],[38,0]],"id":52385937},{"atb":[[550,0],[650,0]],"id":52385931},{"atb":[[3.45,0],[2.98,0]],"id":52385911},{"atb":[[3.1,0],[2.84,0]],"id":52385913},{"atb":[[10.5,0],[15.5,0]],"id":52385909},{"atb":[[550,0],[650,0]],"id":52385888},{"atb":[[48,0],[29,0]],"id":52385882},{"atb":[[7.4,0],[5.7,0]],"id":52385915},{"atb":[[36,0],[23,0]],"id":52385884},{"atb":[[18,0],[13,0]],"id":52385895},{"atb":[[7.4,0],[9.4,0]],"id":52385928},{"atb":[[4.4,0],[5.4,0]],"id":52385891},{"atb":[[540,0],[640,0]],"id":52385924},{"atb":[[18,0],[13,0]],"id":52385934},{"atb":[[18,0],[26,0]],"id":52385903},{"atb":[[65,0],[36,0]],"id":52385930},{"atb":[[19,0],[14,0]],"id":52385932}],"con":true,"img":false}]}
{"op":"mcm","clk":"11450647719","pt":1717324201932,"mc":[{"id":"1.229554927","rc":[{"atl":[[22,4.67],[23,0]],"id":52385904}],"con":true,"img":false}]}
{"op":"mcm","clk":"11450648483","pt":1717324208859,"mc":[{"id":"1.229554927","rc":[{"atb":[[18,6.14],[13,20.32]],"id":52385910},{"atb":[[10.5,11],[8.2,33.87]],"id":52385916},{"atb":[[9.2,29.74],[13,8.71]],"id":52385927},{"atb":[[9.6,28.36],[14,8.04]],"id":52385925},{"atb":[[9.8,27.71],[14.5,7.74]],"id":52385935},{"atb":[[70,1.51],[38,6.59]],"id":52385937},{"atb":[[550,0.44],[650,0.16]],"id":52385931},{"atb":[[3.45,42.66],[2.98,123.18]],"id":52385911},{"atb":[[3.1,49.77],[2.84,132.55]],"id":52385913},{"atb":[[7.4,16.33],[5.7,51.89]],"id":52385915},{"atb":[[7.4,38.1],[9.4,12.44]],"id":52385928},{"atb":[[540,0.44],[640,0.16]],"id":52385924},{"atb":[[18,6.14],[13,20.32]],"id":52385934},{"atb":[[65,1.63],[36,6.96]],"id":52385930},{"atb":[[19,5.8],[14,18.76]],"id":52385932}],"con":true,"img":false}]}
{"op":"mcm","clk":"11450648497","pt":1717324208959,"mc":[{"id":"1.229554927","rc":[{"atb":[[3.55,40.99],[3.05,118.97]],"id":52385906},{"atb":[[10.5,11],[8.2,33.87]],"id":52385908},{"atb":[[550,0.44],[650,0.16]],"id":52385887},{"atb":[[34,3.16],[22,11.61]],"id":52385889},{"atb":[[16.5,15.73],[23,4.75]],"id":52385885},{"atb":[[9.2,29.74],[13,8.71]],"id":52385894},{"atb":[[4,34.84],[3.5,97.56]],"id":52385892},{"atb":[[5.2,24.88],[4.2,76.22]],"id":52385904},{"atb":[[10.5,25.67],[15.5,7.2]],"id":52385909},{"atb":[[550,0.44],[650,0.16]],"id":52385888},{"atb":[[48,2.22],[29,8.71]],"id":52385882},{"atb":[[36,2.98],[23,11.08]],"id":52385884},{"atb":[[18,6.14],[13,20.32]],"id":52385895},{"atb":[[4.4,71.73],[5.4,23.75]],"id":52385891},{"atb":[[18,14.34],[26,4.18]],"id":52385903}],"con":true,"img":false}]}
{"op":"mcm","clk":"11450648522","pt":1717324209121,"mc":[{"id":"1.229554927","rc":[{"atl":[[22,0],[23,2.95]],"id":52385904}],"con":true,"img":false}]}
{"op":"mcm","clk":"11450649673","pt":1717324220453,"mc":[{"id":"1.229554927","rc":[{"atl":[[22,2.95],[23,0]],"id":52385904}],"con":true,"img":false}]}
{"op":"mcm","clk":"11450649772","pt":1717324221278,"mc":[{"id":"1.229554927","rc":[{"atl":[[22,0],[23,4.48]],"id":52385904}],"con":true,"img":false}]}
{"op":"mcm","clk":"11450650517","pt":1717324227695,"mc":[{"id":"1.229554927","rc":[{"atl":[[22,3.68],[23,0]],"id":52385904}],"con":true,"img":false}]}
{"op":"mcm","clk":"11450651126","pt":1717324233497,"mc":[{"id":"1.229554927","rc":[{"atl":[[22,0],[23,3.22]],"id":52385904}],"con":true,"img":false}]}
{"op":"mcm","clk":"11450651546","pt":1717324237416,"mc":[{"id":"1.229554927","rc":[{"atl":[[22,4.13],[23,0]],"id":52385904}],"con":true,"img":false}]}
{"op":"mcm","clk":"11450654245","pt":1717324264298,"mc":[{"id":"1.229554927","rc":[{"atb":[[30,5]],"id":52385910},{"atl":[[240,4.94],[250,5]],"id":52385910},{"atb":[[6.2,5],[6.6,18.01]],"id":52385906},{"atl":[[10.5,5],[11.5,13.33]],"id":52385906},{"atb":[[14.5,5]],"id":52385908},{"atl":[[46,5]],"id":52385908},{"atb":[[120,6.35]],"id":52385889},{"atl":[[760,3.51]],"id":52385889},{"atb":[[18.5,7.99]],"id":52385916},{"atl":[[44,7.78],[46,5]],"id":52385916},{"atb":[[22,5]],"id":52385894},{"atl":[[48,5],[55,2.96]],"id":52385894},{"atl":[[110,1.47]],"id":52385927},{"atb":[[85,5]],"id":52385935},{"atl":[[210,5]],"id":52385935},{"atb":[[9.2,5]],"id":52385904},{"atl":[[20,5],[21,8]],"id":52385904},{"atb":[[150,5.54]],"id":52385937},{"atl":[[720,0.22]],"id":52385937},{"atb":[[5.3,5],[4.4,16.95]],"id":52385911},{"atl":[[8,15.9],[7.8,5]],"id":52385911},{"atb":[[4.2,9.91]],"id":52385913},{"atl":[[7.2,15.22],[5.8,5]],"id":52385913},{"atb":[[42,5]],"id":52385909},{"atl":[[85,8.17]],"id":52385909},{"atb":[[65,5],[60,2.71]],"id":52385895},{"atl":[[150,10.4]],"id":52385895},{"atb":[[30,6.42]],"id":52385928},{"atl":[[70,2.32]],"id":52385928},{"atb":[[11,5]],"id":52385891},{"atl":[[22,5]],"id":52385891},{"atb":[[100,1.61]],"id":52385934},{"atl":[[270,3.27]],"id":52385934},{"atb":[[110,1.47]],"id":52385903},{"atl":[[450,3.87]],"id":52385903},{"atb":[[140,5.38]],"id":52385930},{"atl":[[510,0.31]],"id":52385930}],"con":true,"img":false}]}
{"op":"mcm","clk":"11450654255","pt":1717324264391,"mc":[{"id":"1.229554927","rc":[{"atl":[[48,3.41]],"id":52385908},{"atb":[[150,1.07],[160,5]],"id":52385885},{"atl":[[1000,1.11]],"id":52385885},{"atb":[[29,5]],"id":52385927},{"atl":[[85,5]],"id":52385927},{"atb":[[7.2,11.08],[10.5,5]],"id":52385892},{"atl":[[17.5,5],[18,13.15]],"id":52385892},{"atb":[[36,5]],"id":52385925},{"atl":[[90,5],[110,1.47]],"id":52385925},{"atb":[[65,2.5]],"id":52385935},{"atl":[[220,4.64]],"id":52385935},{"atb":[[8.8,18.45]],"id":52385915},{"atl":[[19.5,8.65],[13.5,5]],"id":52385915},{"atb":[[26,5]],"id":52385928},{"atl":[[60,5]],"id":52385928},{"atb":[[12,12.33]],"id":52385891},{"atl":[[23,10.62]],"id":52385891},{"atb":[[110,5]],"id":52385934},{"atb":[[110,6.47]],"id":52385903},{"atb":[[140,5],[100,1.61]],"id":52385932},{"atl":[[320,4.76]],"id":52385932}],"con":true,"img":false}]}
{"op":"mcm","clk":"11450654365","pt":1717324265383,"mc":[{"id":"1.229554927","rc":[{"atl":[[970,2]],"id":52385910},{"atl":[[840,2]],"id":52385935},{"atl":[[410,2],[480,0]],"id":52385909},{"atl":[[610,2],[710,0]],"id":52385895}],"con":true,"img":false}]}
{"op":"mcm","clk":"11450654379","pt":1717324265485,"mc":[{"id":"1.229554927","rc":[{"atl":[[980,0]],"id":52385935}],"con":true,"img":false}]}
{"op":"mcm","clk":"11450654448","pt":1717324266117,"mc":[{"id":"1.229554927","rc":[{"atb":[[18.5,5.71],[29,0]],"id":52385910},{"atl":[[520,2],[970,0]],"id":52385910},{"atb":[[3.95,33.9],[3.15,0]],"id":52385906},{"atl":[[38,2.7],[25,0]],"id":52385906},{"atb":[[4.4,0],[7,14.71]],"id":52385908},{"atl":[[150,2],[95,0]],"id":52385908},{"atb":[[38,0],[50,2]],"id":52385887},{"atb":[[32,0],[48,2.13]],"id":52385889},{"atb":[[7.2,0],[4.1,16]],"id":52385916},{"atl":[[48,5.63],[210,0]],"id":52385916},{"atb":[[34,0],[50,2.04]],"id":52385885},{"atb":[[7.2,0],[8.2,10.48]],"id":52385894},{"atl":[[170,0],[240,2]],"id":52385894},{"atb":[[13,17.04],[7.8,0]],"id":52385927},{"atl":[[340,0],[440,2]],"id":52385927},{"atb":[[5.3,23.26],[4.2,0]],"id":52385892},{"atb":[[9.2,0],[15,7.14]],"id":52385925},{"atl":[[380,2],[430,0]],"id":52385925},{"atb":[[10,11.11],[29,0]],"id":52385935},{"atl":[[380,2],[840,0]],"id":52385935},{"atb":[[3.95,0],[4.9,25.64]],"id":52385904},{"atl":[[90,2],[46,0]],"id":52385904},{"atl":[[720,2.22]],"id":52385937},{"atb":[[50,2],[30,0]],"id":52385931},{"atb":[[2.88,0],[2.7,55.82]],"id":52385911},{"atl":[[18.5,0],[11,10]],"id":52385911},{"atb":[[2.58,58.14],[2.48,0]],"id":52385913},{"atl":[[8.6,8.16],[11.5,0]],"id":52385913},{"atl":[[320,2],[410,0]],"id":52385909},{"atb":[[50,2],[30,0]],"id":52385888},{"atb":[[38,0],[50,2.04]],"id":52385882},{"atb":[[3.85,0],[3.4,32.66]],"id":52385915},{"atl":[[42,0],[22,4.76]],"id":52385915},{"atb":[[38,0],[50,2.04]],"id":52385884},{"atl":[[610,0],[350,2]],"id":52385895},{"atb":[[8,0],[10.5,10.53]],"id":52385928},{"atl":[[280,0],[210,2]],"id":52385928},{"atb":[[4,0],[5.9,20.41]],"id":52385891},{"atl":[[70,0],[120,2]],"id":52385891},{"atb":[[38,0],[50,2]],"id":52385924},{"atb":[[32,0],[22,4.76]],"id":52385934},{"atl":[[550,2]],"id":52385934},{"atb":[[32,0],[46,6.01]],"id":52385903},{"atl":[[870,2]],"id":52385930},{"atl":[[500,2]],"id":52385932}],"con":true,"img":false}]}
{"op":"mcm","clk":"11450654461","pt":1717324266270,"mc":[{"id":"1.229554927","rc":[{"atb":[[18.5,2.99]],"id":52385916},{"atl":[[34,4.36]],"id":52385916},{"atl":[[48,0],[50,5]],"id":52385894},{"atl":[[85,0],[90,5]],"id":52385927},{"atl":[[25,9.41]],"id":52385904},{"atb":[[2.86,53.76],[2.58,0]],"id":52385913}],"con":true,"img":false}]}
{"op":"mcm","clk":"11450654476","pt":1717324266381,"mc":[{"id":"1.229554927","rc":[{"atl":[[140,3.72],[240,0.66]],"id":52385910},{"atl":[[10.5,0],[12,0],[13,0],[15,3.99]],"id":52385906},{"atb":[[17.5,0],[19,3.97],[20,8.43],[12.5,4.57],[13.5,0],[15,0]],"id":52385908},{"atl":[[760,0.2],[740,4.03]],"id":52385889},{"atb":[[16,0],[18.5,0],[22,0],[13,0],[13.5,0],[14,0]],"id":52385916},{"atl":[[44,3.72]],"id":52385916},{"atb":[[30,6.42]],"id":52385894},{"atb":[[44,3.72]],"id":52385927},{"atl":[[17.5,0],[18,9.42],[21,8.45]],"id":52385892},{"atb":[[50,3.8]],"id":52385925},{"atl":[[90,0],[120,9.13]],"id":52385925},{"atb":[[65,0],[34,0],[85,0],[44,0],[27,0],[60,0]],"id":52385935},{"atl":[[170,3.13],[220,0.73]],"id":52385935},{"atb":[[11.5,17.54]],"id":52385904},{"atl":[[20,0],[22,0],[26,3.64]],"id":52385904},{"atb":[[130,0],[150,0],[200,0],[100,3],[250,0]],"id":52385937},{"atb":[[5.3,0],[4.4,21.96]],"id":52385911},{"atb":[[36,5],[40,0],[42,0],[50,0],[25,4.52],[30,0]],"id":52385909},{"atl":[[85,10.08]],"id":52385909},{"atb":[[8.2,0],[6.8,4.07],[8.8,0],[7.8,0],[8.4,0],[5.9,0]],"id":52385915},{"atb":[[65,0],[60,0]],"id":52385895},{"atl":[[150,6.08],[95,2.84]],"id":52385895},{"atl":[[65,5],[60,0]],"id":52385928},{"atl":[[34,8.87],[22,0],[23,0],[25,0]],"id":52385891},{"atb":[[70,5.77],[100,0],[110,0]],"id":52385934},{"atl":[[180,5]],"id":52385934},{"atl":[[560,4.26],[450,0.35],[470,0]],"id":52385903},{"atb":[[140,0.38],[100,5],[110,2.82],[120,0]],"id":52385930},{"atb":[[140,0],[70,0],[38,0],[95,0],[48,0],[100,0]],"id":52385932},{"atl":[[280,2.92],[320,0.5],[190,5]],"id":52385932}],"con":true,"img":false}]}
{"op":"mcm","clk":"11450654518","pt":1717324266895,"mc":[{"id":"1.229554927","rc":[{"atl":[[14.5,5]],"id":52385906},{"atb":[[10.5,16.6],[9.8,5]],"id":52385916},{"atb":[[40,5]],"id":52385935},{"atb":[[95,5],[100,4.62]],"id":52385937},{"atb":[[36,8]],"id":52385909},{"atb":[[7,5]],"id":52385915},{"atb":[[38,5]],"id":52385895}],"con":true,"img":false}]}
{"op":"mcm","clk":"11450654529","pt":1717324267106,"mc":[{"id":"1.229554927","rc":[{"atb":[[11,5.23],[13.5,2.09],[8.4,14.14],[9.4,9.34]],"id":52385916},{"atl":[[50,0],[60,9.56]],"id":52385894},{"atl":[[90,0],[110,6.47]],"id":52385927},{"atb":[[32,2.53],[42,1.28],[26,4.19],[55,0.49],[29,1.09]],"id":52385935},{"atb":[[5.8,5.04]],"id":52385915},{"atb":[[70,8.09]],"id":52385934},{"atl":[[180,0]],"id":52385934},{"atb":[[60,5]],"id":52385932},{"atl":[[190,0],[200,5]],"id":52385932}],"con":true,"img":false}]}
{"op":"mcm","clk":"11450654540","pt":1717324267158,"mc":[{"id":"1.229554927","rc":[{"atb":[[17.5,6.34],[20,12.56],[25,2.18],[30,0.9]],"id":52385908},{"atb":[[150,0.18],[75,1.06],[100,5.15],[50,2.13]],"id":52385937},{"atb":[[38,1.41],[48,0.55],[24,4.55],[29,2.8]],"id":52385909},{"atb":[[5.6,22.75],[7.2,8.44],[6.2,15.09],[8.2,3.63]],"id":52385915},{"atl":[[110,1.47]],"id":52385891},{"atl":[[190,5]],"id":52385934},{"atb":[[65,0.82],[36,2.99],[90,0.29],[46,1.74],[14.5,1.16]],"id":52385932}],"con":true,"img":false}]}
{"op":"mcm","clk":"11450654602","pt":1717324267850,"mc":[{"id":"1.229554927","rc":[{"atb":[[9.6,2.98],[10,2.77]],"id":52385916},{"atl":[[19,0]],"id":52385892},{"atl":[[25,5]],"id":52385904}],"con":true,"img":false}]}
{"op":"mcm","clk":"11450654985","pt":1717324271294,"mc":[{"id":"1.229554927","rc":[{"atl":[[380,0],[470,2]],"id":52385925},{"atl":[[8.6,0],[9.8,10.02]],"id":52385913}],"con":true,"img":false}]}
{"op":"mcm","clk":"11450655176","pt":1717324273173,"mc":[{"id":"1.229554927","rc":[{"atb":[[18.5,0],[24,8.39]],"id":52385910},{"atb":[[3.95,0],[4.7,27.03]],"id":52385906},{"atb":[[8.6,13.16],[7,0]],"id":52385908},{"atb":[[4.1,0],[4.9,16]],"id":52385916},{"atb":[[10,11.11],[8.2,0]],"id":52385894},{"atb":[[13,8.71],[15.5,6.9]],"id":52385927},{"atb":[[17.5,6.06],[15,0]],"id":52385925},{"atb":[[10,0],[13,8.33]],"id":52385935},{"atb":[[6,20],[4.9,0]],"id":52385904},{"atl":[[25,0],[26,8.65],[27,2.81]],"id":52385904},{"atb":[[3,102.32],[2.7,0]],"id":52385911},{"atb":[[5.6,0],[7.2,0],[3.85,32.66],[6.2,0],[8.2,0],[3.4,0],[7,0],[6.6,3.58]],"id":52385915},{"atb":[[7.2,16.13],[5.9,0]],"id":52385891},{"atb":[[22,0],[28,3.7]],"id":52385934},{"atl":[[560,0],[570,3.46]],"id":52385903},{"atb":[[70,0]],"id":52385930},{"atl":[[790,2],[870,0]],"id":52385930}],"con":true,"img":false}]}
{"op":"mcm","clk":"11450655184","pt":1717324273279,"mc":[{"id":"1.229554927","rc":[{"atl":[[26,5]],"id":52385904},{"atb":[[6.8,0]],"id":52385915}],"con":true,"img":false}]}
{"op":"mcm","clk":"11450655237","pt":1717324273695,"mc":[{"id":"1.229554927","rc":[{"atb":[[6.8,5]],"id":52385915}],"con":true,"img":false}]}
{"op":"mcm","clk":"11450655275","pt":1717324274003,"mc":[{"id":"1.229554927","rc":[{"atb":[[8,3.74],[5.5,23.25],[6,15.7],[7,8.72]],"id":52385915}],"con":true,"img":false}]}
{"op":"mcm","clk":"11450655413","pt":1717324275307,"mc":[{"id":"1.229554927","rc":[{"atb":[[90,3.19]],"id":52385937}],"con":true,"img":false}]}
{"op":"mcm","clk":"11450655640","pt":1717324277298,"mc":[{"id":"1.229554927","rc":[{"atl":[[160,4.15]],"id":52385910},{"atl":[[16,3.96]],"id":52385906},{"atb":[[18,3.2]],"id":52385908},{"atl":[[760,4.63]],"id":52385889},{"atl":[[23,3.24]],"id":52385892},{"atl":[[190,4.6]],"id":52385935},{"atl":[[110,4.21]],"id":52385895},{"atl":[[38,4.03]],"id":52385891},{"atl":[[300,4.21]],"id":52385932}],"con":true,"img":false}]}
{"op":"mcm","clk":"11450655757","pt":1717324278697,"mc":[{"id":"1.229554927","rc":[{"atl":[[38,4.27]],"id":52385916}],"con":true,"img":false}]}
{"op":"mcm","clk":"11450655878","pt":1717324279897,"mc":[{"id":"1.229554927","rc":[{"atl":[[140,4.87]],"id":52385910},{"atl":[[740,4.25]],"id":52385889},{"atl":[[32,5.16]],"id":52385916},{"atl":[[7.8,26.82]],"id":52385911},{"atl":[[5.8,24.42]],"id":52385913},{"atl":[[95,4.55]],"id":52385895},{"atl":[[190,5.85]],"id":52385934}],"con":true,"img":false}]}
{"op":"mcm","clk":"11450655890","pt":1717324280004,"mc":[{"id":"1.229554927","rc":[{"atl":[[46,8.56]],"id":52385908},{"atb":[[170,0.94]],"id":52385885},{"atb":[[10.5,21.86]],"id":52385892},{"atl":[[160,1]],"id":52385935},{"atl":[[13,13.35]],"id":52385915},{"atl":[[34,13.72]],"id":52385891},{"atl":[[200,5.81]],"id":52385932}],"con":true,"img":false}]}
{"op":"mcm","clk":"11450655958","pt":1717324280683,"mc":[{"id":"1.229554927","rc":[{"atl":[[240,0]],"id":52385910},{"atl":[[48,0]],"id":52385908},{"atl":[[760,4.42]],"id":52385889},{"atl":[[44,0]],"id":52385916},{"atb":[[150,0]],"id":52385885},{"atb":[[7.2,0]],"id":52385892},{"atl":[[220,0]],"id":52385935},{"atl":[[8,2.87]],"id":52385911},{"atl":[[7.2,0]],"id":52385913},{"atl":[[19.5,0]],"id":52385915},{"atl":[[150,5]],"id":52385895},{"atl":[[110,0]],"id":52385891},{"atl":[[270,2.67]],"id":52385934},{"atl":[[320,0]],"id":52385932}],"con":true,"img":false}]}
{"op":"mcm","clk":"11450656208","pt":1717324283298,"mc":[{"id":"1.229554927","rc":[{"atl":[[260,0]],"id":52385910},{"atb":[[12.5,0]],"id":52385908},{"atl":[[740,0.21],[760,0],[750,3.72],[780,0]],"id":52385889},{"atl":[[48,2.13]],"id":52385916},{"atl":[[240,0]],"id":52385935},{"atb":[[150,0],[75,0],[95,9.4],[100,1.61],[50,0]],"id":52385937},{"atb":[[6.4,3.23],[6.6,0]],"id":52385915},{"atl":[[160,0]],"id":52385895},{"atl":[[330,0]],"id":52385932}],"con":true,"img":false}]}
{"op":"mcm","clk":"11450656294","pt":1717324284026,"mc":[{"id":"1.229554927","rc":[{"atl":[[29,2.83]],"id":52385904},{"atb":[[70,2.65],[140,0.19],[95,11.66],[48,2.23]],"id":52385937},{"atl":[[590,2.95]],"id":52385903}],"con":true,"img":false}]}
{"op":"mcm","clk":"11450656377","pt":1717324284802,"mc":[{"id":"1.229554927","rc":[{"atb":[[95,9.96]],"id":52385937}],"con":true,"img":false}]}
{"op":"mcm","clk":"11450657284","pt":1717324293637,"mc":[{"id":"1.229554927","rc":[{"atb":[[95,5.56],[100,4.34]],"id":52385937},{"atb":[[6.6,4.61]],"id":52385915}],"con":true,"img":false}]}
{"op":"mcm","clk":"11450657320","pt":1717324293950,"mc":[{"id":"1.229554927","rc":[{"atl":[[770,4.65]],"id":52385889}],"con":true,"img":false}]}
{"op":"mcm","clk":"11450657925","pt":1717324299741,"mc":[{"id":"1.229554927","rc":[{"atb":[[25,3.07],[26,0]],"id":52385910}],"con":true,"img":false}]}
{"op":"mcm","clk":"11450657958","pt":1717324300052,"mc":[{"id":"1.229554927","rc":[{"atl":[[570,0],[560,4.61]],"id":52385903},{"atb":[[65,3.27]],"id":52385930}],"con":true,"img":false}]}
{"op":"mcm","clk":"11450658256","pt":1717324302765,"mc":[{"id":"1.229554927","rc":[{"atb":[[18,0],[13,0]],"id":52385910},{"atb":[[3.55,0],[3.05,0]],"id":52385906},{"atb":[[10.5,0],[8.2,0]],"id":52385908},{"atb":[[550,0],[650,0]],"id":52385887},{"atb":[[34,0],[22,0]],"id":52385889},{"atb":[[10.5,5.6],[8.2,0]],"id":52385916},{"atb":[[16.5,0],[23,0]],"id":52385885},{"atb":[[9.2,0],[13,0]],"id":52385894},{"atb":[[9.2,0],[13,0]],"id":52385927},{"atb":[[4,0],[3.5,0]],"id":52385892},{"atb":[[9.6,0],[14,0]],"id":52385925},{"atb":[[9.8,0],[14.5,0]],"id":52385935},{"atb":[[5.2,0],[4.2,0]],"id":52385904},{"atb":[[70,1.14],[38,0]],"id":52385937},{"atb":[[550,0],[650,0]],"id":52385931},{"atb":[[3.45,0],[2.98,0]],"id":52385911},{"atb":[[3.1,0],[2.84,0]],"id":52385913},{"atb":[[10.5,0],[15.5,0]],"id":52385909},{"atb":[[550,0],[650,0]],"id":52385888},{"atb":[[48,0],[29,0]],"id":52385882},{"atb":[[7.4,0],[5.7,0]],"id":52385915},{"atb":[[36,0],[23,0]],"id":52385884},{"atb":[[18,0],[13,0]],"id":52385895},{"atb":[[7.4,0],[9.4,0]],"id":52385928},{"atb":[[4.4,0],[5.4,0]],"id":52385891},{"atb":[[540,0],[640,0]],"id":52385924},{"atb":[[18,0],[13,0]],"id":52385934},{"atb":[[18,0],[26,0]],"id":52385903},{"atb":[[65,1.64],[36,0]],"id":52385930},{"atb":[[19,0],[14,0]],"id":52385932}],"con":true,"img":false}]}
{"op":"mcm","clk":"11450658285","pt":1717324303026,"mc":[{"id":"1.229554927","rc":[{"atb":[[25,0],[26,4.31]],"id":52385910}],"con":true,"img":false}]}
{"op":"mcm","clk":"11450658307","pt":1717324303235,"mc":[{"id":"1.229554927","rc":[{"atl":[[65,7.5]],"id":52385928}],"con":true,"img":false}]}
{"op":"mcm","clk":"11450658323","pt":1717324303344,"mc":[{"id":"1.229554927","rc":[{"atb":[[32,3.23],[24,4.04]],"id":52385910},{"atl":[[520,0],[580,2]],"id":52385910},{"atb":[[8.6,0],[6,8.98]],"id":52385908},{"atl":[[150,0],[95,2]],"id":52385908},{"atb":[[5.6,16],[4.9,0]],"id":52385916},{"atl":[[80,2],[48,0]],"id":52385916},{"atb":[[10,0],[8.4,9.18]],"id":52385894},{"atl":[[150,2],[240,0]],"id":52385894},{"atb":[[9.2,6.9],[15.5,0]],"id":52385927},{"atl":[[180,2],[440,0]],"id":52385927},{"atb":[[17.5,0],[10,7.34]],"id":52385925},{"atl":[[220,2],[470,0]],"id":52385925},{"atb":[[20,5.26],[13,0]],"id":52385935},{"atl":[[380,0],[490,2]],"id":52385935},{"atb":[[3,52.32],[3.4,41.67]],"id":52385911},{"atl":[[11,0],[15,7.14]],"id":52385911},{"atb":[[2.86,0],[3.15,46.51]],"id":52385913},{"atl":[[9.8,0],[12.5,8.7]],"id":52385913},{"atb":[[9.8,0],[14.5,7.41]],"id":52385909},{"atl":[[320,0],[410,2]],"id":52385909},{"atb":[[3.85,0],[3.2,10.1]],"id":52385915},{"atl":[[22,0],[13.5,13]],"id":52385915},{"atl":[[350,0],[450,2]],"id":52385895},{"atb":[[6.4,9.63],[10.5,0]],"id":52385928},{"atl":[[100,2],[210,0]],"id":52385928},{"atb":[[8,14.29],[7.2,0]],"id":52385891},{"atb":[[40,2.56],[28,0]],"id":52385934},{"atl":[[550,0],[760,2]],"id":52385934},{"atb":[[34,0],[21,5]],"id":52385930},{"atl":[[520,4.72],[790,0]],"id":52385930},{"atl":[[630,2],[500,0]],"id":52385932}],"con":true,"img":false}]}
{"op":"mcm","clk":"11450658364","pt":1717324303658,"mc":[{"id":"1.229554927","rc":[{"atl":[[140,1.15],[170,4.57]],"id":52385910},{"atl":[[11.5,0],[14.5,0],[15,0],[15.5,5]],"id":52385906},{"atb":[[17.5,0],[18,0],[19,0],[20,0],[25,0],[30,0]],"id":52385908},{"atl":[[750,0],[870,3.25]],"id":52385889},{"atb":[[10,0],[13,2.67],[13.5,14.91]],"id":52385916},{"atb":[[30,0.9]],"id":52385894},{"atb":[[32,0],[42,0],[21,0],[44,0],[25,0],[26,0],[27,0],[29,0]],"id":52385927},{"atl":[[21,0],[24,8.4]],"id":52385892},{"atb":[[36,0],[40,0],[50,0],[25,0],[29,0],[30,0]],"id":52385925},{"atb":[[55,3.45]],"id":52385935},{"atl":[[21,0],[26,0],[27,0],[28,5],[30,4.56]],"id":52385904},{"atb":[[140,0],[70,0],[80,3.31],[95,0],[48,0],[100,0]],"id":52385937},{"atb":[[4.4,27.12]],"id":52385913},{"atl":[[5.8,19.42],[6.8,5]],"id":52385913},{"atb":[[48,3.97]],"id":52385909},{"atl":[[85,1.9],[95,8.03]],"id":52385909},{"atb":[[8,0],[6.4,0],[5.8,0],[5.5,0],[6.8,0],[6,0],[7,0],[6.6,0]],"id":52385915},{"atb":[[55,3.45]],"id":52385895},{"atl":[[95,1.7]],"id":52385895},{"atb":[[17.5,0],[18,0],[19,0],[20,0],[25,0],[26,0],[30,0]],"id":52385928},{"atl":[[34,4.85],[40,5]],"id":52385891},{"atb":[[95,1.98]],"id":52385934},{"atl":[[190,0.84],[220,5]],"id":52385934},{"atl":[[560,0],[630,3.27],[450,0]],"id":52385903},{"atb":[[95,0.84],[100,0],[110,0]],"id":52385930},{"atb":[[90,2.09]],"id":52385932}],"con":true,"img":false}]}
{"op":"mcm","clk":"11450658400","pt":1717324303924,"mc":[{"id":"1.229554927","rc":[{"atl":[[13.5,5],[14,7.69]],"id":52385915}],"con":true,"img":false}]}
{"op":"mcm","clk":"11450658413","pt":1717324304028,"mc":[{"id":"1.229554927","rc":[{"atb":[[22,5]],"id":52385927},{"atb":[[27,8.53]],"id":52385925},{"atb":[[5.1,5]],"id":52385915}],"con":true,"img":false}]}
{"op":"mcm","clk":"11450658425","pt":1717324304133,"mc":[{"id":"1.229554927","rc":[{"atb":[[75,5]],"id":52385937},{"atl":[[13.5,13],[14,0]],"id":52385915},{"atb":[[14.5,5]],"id":52385928}],"con":true,"img":false}]}
{"op":"mcm","clk":"11450658499","pt":1717324304723,"mc":[{"id":"1.229554927","rc":[{"atl":[[70,0]],"id":52385928}],"con":true,"img":false}]}
{"op":"mcm","clk":"11450658514","pt":1717324304824,"mc":[{"id":"1.229554927","rc":[{"atl":[[16,11.48]],"id":52385906},{"atb":[[16,5.23],[18.5,2.99],[6.2,5.39],[22,1.25],[13.5,8.37]],"id":52385908},{"atb":[[10.5,0]],"id":52385916},{"atb":[[38,0.71],[19.5,5.66],[1.01,4.92],[24,3.41],[29,1.87]],"id":52385927},{"atb":[[34,1.59],[1.01,2.61],[44,0.61],[22,4.98],[27,11.56]],"id":52385925},{"atb":[[29,0]],"id":52385935},{"atl":[[29,8.55]],"id":52385904},{"atb":[[85,1.9]],"id":52385937},{"atb":[[36,5]],"id":52385909},{"atb":[[4.8,20.65],[4.3,31.71],[3.2,15.14],[5.8,5.45],[5.3,12.17]],"id":52385915},{"atb":[[6.6,3.48]],"id":52385928},{"atb":[[70,5.77]],"id":52385934},{"atl":[[620,0.25]],"id":52385903},{"atb":[[14.5,0]],"id":52385932}],"con":true,"img":false}]}
{"op":"mcm","clk":"11450658526","pt":1717324304929,"mc":[{"id":"1.229554927","rc":[{"atb":[[130,0.2],[65,1.22],[90,3.78],[46,2.32]],"id":52385937},{"atb":[[16.5,5.06],[19,2.91],[23,1.19],[14,8.05]],"id":52385928}],"con":true,"img":false}]}
{"op":"mcm","clk":"11450658619","pt":1717324305710,"mc":[{"id":"1.229554927","rc":[{"atb":[[65,0]],"id":52385930}],"con":true,"img":false}]}
{"op":"mcm","clk":"11450658646","pt":1717324306020,"mc":[{"id":"1.229554927","rc":[{"atb":[[32,0],[34,3.03]],"id":52385910}],"con":true,"img":false}]}
{"op":"mcm","clk":"11450658658","pt":1717324306125,"mc":[{"id":"1.229554927","rc":[{"atb":[[22,8.79],[24,6.87]],"id":52385927},{"atb":[[25,4.69]],"id":52385925},{"atl":[[8,0],[7.8,30.34]],"id":52385911},{"atl":[[7.4,0],[7.6,4.7]],"id":52385913},{"atl":[[110,4.34]],"id":52385909},{"atb":[[14.5,8.73],[15.5,3.87]],"id":52385928}],"con":true,"img":false}]}
{"op":"mcm","clk":"11450658668","pt":1717324306230,"mc":[{"id":"1.229554927","rc":[{"atb":[[55,5]],"id":52385930}],"con":true,"img":false}]}
{"op":"mcm","clk":"11450658679","pt":1717324306333,"mc":[{"id":"1.229554927","rc":[{"atl":[[160,0]],"id":52385910},{"atb":[[13.5,11.19],[14.5,8.61]],"id":52385908},{"atl":[[50,0],[55,2.72]],"id":52385908},{"atl":[[770,0],[890,4.36]],"id":52385889},{"atl":[[23,0]],"id":52385892},{"atl":[[29,5.72]],"id":52385904},{"atb":[[90,0.59]],"id":52385937},{"atb":[[4.9,3.21],[4.7,3.77]],"id":52385915},{"atl":[[590,0],[650,4.63]],"id":52385903},{"atb":[[50,4.38],[60,4.54]],"id":52385930}],"con":true,"img":false}]}
{"op":"mcm","clk":"11450658700","pt":1717324306540,"mc":[{"id":"1.229554927","rc":[{"atb":[[40,2.68]],"id":52385930}],"con":true,"img":false}]}
{"op":"mcm","clk":"11450658932","pt":1717324308732,"mc":[{"id":"1.229554927","rc":[{"atl":[[870,0]],"id":52385889},{"atl":[[630,0]],"id":52385903},{"atl":[[270,5]],"id":52385930}],"con":true,"img":false}]}
{"op":"mcm","clk":"11450658973","pt":1717324309144,"mc":[{"id":"1.229554927","rc":[{"atl":[[270,5.6]],"id":52385930}],"con":true,"img":false}]}
{"op":"mcm","clk":"11450659074","pt":1717324309931,"mc":[{"id":"1.229554927","rc":[{"atl":[[510,0]],"id":52385930}],"con":true,"img":false}]}
{"op":"mcm","clk":"11450659207","pt":1717324310929,"mc":[{"id":"1.229554927","rc":[{"atl":[[270,0]],"id":52385930}],"con":true,"img":false}]}
{"op":"mcm","clk":"11450659281","pt":1717324311549,"mc":[{"id":"1.229554927","rc":[{"atb":[[14.5,5],[15,3.37]],"id":52385908},{"atl":[[890,0],[910,3.12]],"id":52385889},{"atb":[[24,3.41],[25,3.86]],"id":52385927},{"atb":[[34,0],[44,0],[22,0],[27,5],[28,3.61]],"id":52385925},{"atl":[[28,0],[29,10.73]],"id":52385904},{"atb":[[85,6.19]],"id":52385937},{"atl":[[95,5],[100,3.47]],"id":52385909},{"atb":[[4.8,0],[4.3,0],[5.8,0],[5.3,0]],"id":52385915},{"atl":[[110,0],[120,4.5]],"id":52385895},{"atb":[[16.5,0],[19,0],[23,0],[14,0]],"id":52385928},{"atl":[[38,0],[40,9.53]],"id":52385891}],"con":true,"img":false}]}
{"op":"mcm","clk":"11450659292","pt":1717324311652,"mc":[{"id":"1.229554927","rc":[{"atb":[[5.6,2.96],[5.5,0]],"id":52385906},{"atb":[[190,3.48],[200,0]],"id":52385887},{"atb":[[20,8.43],[21,0]],"id":52385894},{"atb":[[6.2,2.94],[6,10.46]],"id":52385892},{"atb":[[8.8,3.76],[8.4,0]],"id":52385904},{"atb":[[4.5,3.31],[4.4,18.04]],"id":52385911},{"atb":[[4.3,4.75],[4.2,5]],"id":52385913},{"atb":[[9,3.62],[8.8,10.06]],"id":52385891},{"atb":[[160,4.64],[170,0]],"id":52385924},{"atl":[[270,5],[530,0.3]],"id":52385930},{"atb":[[65,0],[36,0],[90,1.79],[46,0]],"id":52385932}],"con":true,"img":false}]}
{"op":"mcm","clk":"11450659336","pt":1717324312023,"mc":[{"id":"1.229554927","rc":[{"atb":[[4.6,17.87]],"id":52385911}],"con":true,"img":false}]}
{"op":"mcm","clk":"11450659358","pt":1717324312230,"mc":[{"id":"1.229554927","rc":[{"atb":[[36,1.5],[46,0.58],[23,4.76],[28,6.52]],"id":52385925},{"atb":[[17,4.9],[19.5,2.83],[24,1.14],[14.5,16.49]],"id":52385928}],"con":true,"img":false}]}
{"op":"mcm","clk":"11450659369","pt":1717324312337,"mc":[{"id":"1.229554927","rc":[{"atb":[[27,9],[28,2.91]],"id":52385925},{"atb":[[5.2,12.46],[5.7,5.57],[4.2,32.7],[4.7,24.98]],"id":52385915}],"con":true,"img":false}]}
{"op":"mcm","clk":"11450659377","pt":1717324312440,"mc":[{"id":"1.229554927","rc":[{"atb":[[70,0.76],[38,2.83],[95,0.28],[48,1.67]],"id":52385932}],"con":true,"img":false}]}
{"op":"mcm","clk":"11450659409","pt":1717324312750,"mc":[{"id":"1.229554927","rc":[{"atb":[[4.4,5]],"id":52385911}],"con":true,"img":false}]}
{"op":"mcm","clk":"11450659483","pt":1717324313381,"mc":[{"id":"1.229554927","rc":[{"atb":[[18,6.14],[13,20.32]],"id":52385910},{"atb":[[3.55,40.99],[3.05,118.97]],"id":52385906},{"atb":[[10.5,11],[8.2,33.87]],"id":52385908},{"atb":[[550,0.44],[650,0.16]],"id":52385887},{"atb":[[34,3.16],[22,11.61]],"id":52385889},{"atb":[[10.5,11],[8.2,33.87]],"id":52385916},{"atb":[[16.5,15.73],[23,4.75]],"id":52385885},{"atb":[[9.2,29.74],[13,8.71]],"id":52385894},{"atb":[[9.2,36.64],[13,8.71]],"id":52385927},{"atb":[[4,34.84],[3.5,97.56]],"id":52385892},{"atb":[[9.6,28.36],[14,8.04]],"id":52385925},{"atb":[[9.8,27.71],[14.5,7.74]],"id":52385935},{"atb":[[5.2,24.88],[4.2,76.22]],"id":52385904},{"atb":[[70,1.51],[38,6.59]],"id":52385937},{"atb":[[550,0.44],[650,0.16]],"id":52385931},{"atb":[[3.45,42.66],[2.98,123.18]],"id":52385911},{"atb":[[3.1,49.77],[2.84,132.55]],"id":52385913},{"atb":[[10.5,25.67],[15.5,7.2]],"id":52385909},{"atb":[[550,0.44],[650,0.16]],"id":52385888},{"atb":[[48,2.22],[29,8.71]],"id":52385882},{"atb":[[7.4,16.33],[5.7,57.46]],"id":52385915},{"atb":[[36,2.98],[23,11.08]],"id":52385884},{"atb":[[18,6.14],[13,20.32]],"id":52385895},{"atb":[[7.4,38.1],[9.4,12.44]],"id":52385928},{"atb":[[4.4,71.73],[5.4,23.75]],"id":52385891},{"atb":[[540,0.44],[640,0.16]],"id":52385924},{"atb":[[18,6.14],[13,20.32]],"id":52385934},{"atb":[[18,14.34],[26,4.18]],"id":52385903},{"atb":[[65,1.63],[36,6.96]],"id":52385930},{"atb":[[19,5.8],[14,18.76]],"id":52385932}],"con":true,"img":false}]}
{"op":"mcm","clk":"11450659551","pt":1717324313861,"mc":[{"id":"1.229554927","rc":[{"atb":[[26,0]],"id":52385910},{"atb":[[100,5.27],[110,0]],"id":52385903}],"con":true,"img":false}]}
{"op":"mcm","clk":"11450659560","pt":1717324313962,"mc":[{"id":"1.229554927","rc":[{"atl":[[190,4.09]],"id":52385910},{"atb":[[12,2.79]],"id":52385916}],"con":true,"img":false}]}
{"op":"mcm","clk":"11450659631","pt":1717324314641,"mc":[{"id":"1.229554927","rc":[{"atb":[[80,2.02]],"id":52385903}],"con":true,"img":false}]}
{"op":"mcm","clk":"11450659819","pt":1717324316464,"mc":[{"id":"1.229554927","rc":[{"atl":[[13.5,5],[14,7.69]],"id":52385915}],"con":true,"img":false}]}
{"op":"mcm","clk":"11450659831","pt":1717324316568,"mc":[{"id":"1.229554927","rc":[{"atl":[[670,2.64]],"id":52385903}],"con":true,"img":false}]}
{"op":"mcm","clk":"11450659838","pt":1717324316672,"mc":[{"id":"1.229554927","rc":[{"atb":[[5.6,0],[5.5,4.59]],"id":52385906},{"atb":[[9.6,0]],"id":52385916},{"atb":[[6.2,0]],"id":52385892},{"atb":[[30,0]],"id":52385935},{"atb":[[630,0],[680,0],[730,0],[780,0]],"id":52385931},{"atb":[[4.5,0],[4.4,7.84]],"id":52385911},{"atb":[[4.1,5.06]],"id":52385913},{"atb":[[38,0],[48,3.41],[24,0],[29,0],[30,4.42]],"id":52385909},{"atb":[[50,3.75]],"id":52385934}],"con":true,"img":false}]}
{"op":"mcm","clk":"11450659848","pt":1717324316778,"mc":[{"id":"1.229554927","rc":[{"atb":[[65,4.36],[60,0]],"id":52385889},{"atb":[[6,14.7]],"id":52385892},{"atb":[[32,6.01]],"id":52385935},{"atb":[[9.6,0],[8.6,0],[11.5,15.05],[7.6,0]],"id":52385904},{"atb":[[4.3,0]],"id":52385913},{"atb":[[28,0]],"id":52385909},{"atb":[[32,0],[42,0],[26,0],[55,2.96]],"id":52385895},{"atb":[[46,0]],"id":52385934},{"atb":[[70,0],[38,0],[95,0],[48,0]],"id":52385932}],"con":true,"img":false}]}
{"op":"mcm","clk":"11450659909","pt":1717324317352,"mc":[{"id":"1.229554927","rc":[{"atb":[[700,0.15],[750,0.1],[800,0.07],[850,0.03]],"id":52385931},{"atb":[[32,2.53],[42,1.28],[26,4.19],[55,0.49]],"id":52385909}],"con":true,"img":false}]}
{"op":"mcm","clk":"11450659915","pt":1717324317456,"mc":[{"id":"1.229554927","rc":[{"atb":[[5.6,3.71],[5.5,0]],"id":52385906},{"atl":[[60,5]],"id":52385894},{"atl":[[130,4.46],[120,0]],"id":52385927},{"atb":[[6.2,4.41]],"id":52385892},{"atl":[[120,5]],"id":52385925},{"atb":[[12,2.38],[9.8,5.94],[8.8,13.82],[7.8,15.39]],"id":52385904},{"atl":[[730,0],[750,3.97]],"id":52385937},{"atb":[[4.5,4.02],[4.4,5]],"id":52385911},{"atb":[[4.1,0],[4.2,9.91]],"id":52385913},{"atl":[[7.2,4.34],[7.6,0]],"id":52385913},{"atb":[[25,0],[29,3.1],[30,0]],"id":52385909},{"atl":[[20,0]],"id":52385915},{"atb":[[34,2.38],[44,1.22],[27,4.02],[60,0.44]],"id":52385895},{"atl":[[75,0],[80,4.52]],"id":52385928},{"atb":[[42,0]],"id":52385934},{"atb":[[50,4.37],[55,0]],"id":52385903},{"atl":[[520,2]],"id":52385930},{"atb":[[75,0.71],[40,2.68],[100,0.27],[50,1.6]],"id":52385932},{"atl":[[280,0],[290,4.51]],"id":52385932}],"con":true,"img":false}]}
{"op":"mcm","clk":"11450659925","pt":1717324317558,"mc":[{"id":"1.229554927","rc":[{"atb":[[65,0],[60,3.03]],"id":52385889},{"atb":[[6,10.46]],"id":52385892},{"atl":[[720,0.22],[740,2]],"id":52385937}],"con":true,"img":false}]}
{"op":"mcm","clk":"11450659943","pt":1717324317764,"mc":[{"id":"1.229554927","rc":[{"atl":[[85,0]],"id":52385909}],"con":true,"img":false}]}
{"op":"mcm","clk":"11450659951","pt":1717324317867,"mc":[{"id":"1.229554927","rc":[{"atb":[[12.5,13.93]],"id":52385904}],"con":true,"img":false}]}
{"op":"mcm","clk":"11450660015","pt":1717324318543,"mc":[{"id":"1.229554927","rc":[{"atb":[[11.5,0]],"id":52385904}],"con":true,"img":false}]}
{"op":"mcm","clk":"11450660023","pt":1717324318650,"mc":[{"id":"1.229554927","rc":[{"atb":[[5.6,0],[5.5,4.31]],"id":52385906},{"atb":[[65,3.01],[60,0]],"id":52385889},{"atb":[[6.2,0],[6,14.92]],"id":52385892},{"atb":[[4.5,0],[4.4,9.46]],"id":52385911},{"atb":[[4.1,5.06],[4.2,5]],"id":52385913},{"atb":[[30,3.33]],"id":52385909},{"atb":[[340,0.55]],"id":52385884},{"atb":[[50,1.6],[55,3.71]],"id":52385903}],"con":true,"img":false}]}
{"op":"mcm","clk":"11450660031","pt":1717324318750,"mc":[{"id":"1.229554927","rc":[{"atl":[[160,3.2],[170,0]],"id":52385910},{"atl":[[890,4.33]],"id":52385889},{"atb":[[24,8.03],[25,0]],"id":52385927},{"atl":[[630,3.74],[650,0]],"id":52385903}],"con":true,"img":false}]}
{"op":"mcm","clk":"11450660051","pt":1717324318961,"mc":[{"id":"1.229554927","rc":[{"atb":[[60,3.16]],"id":52385895},{"atb":[[100,1.88]],"id":52385932}],"con":true,"img":false}]}
{"op":"mcm","clk":"11450660086","pt":1717324319331,"mc":[{"id":"1.229554927","rc":[{"atb":[[340,0.08]],"id":52385884}],"con":true,"img":false}]}
{"op":"mcm","clk":"11450660114","pt":1717324319646,"mc":[{"id":"1.229554927","rc":[{"atl":[[15.5,16.05]],"id":52385906},{"atb":[[55,0]],"id":52385895}],"con":true,"img":false}]}
{"op":"mcm","clk":"11450660123","pt":1717324319749,"mc":[{"id":"1.229554927","rc":[{"atb":[[90,0]],"id":52385932}],"con":true,"img":false}]}
