{"op":"mcm","clk":"11449075378","pt":1717303241522,"mc":[{"id":"1.229554912","marketDefinition":{"bspMarket":false,"turnInPlayEnabled":false,"persistenceEnabled":false,"marketBaseRate":7.0,"eventId":"33318908","eventTypeId":"4339","numberOfWinners":1,"bettingType":"ODDS","marketType":"EXACTA","marketTime":"2024-06-02T09:38:00.000Z","suspendTime":"2024-06-02T09:38:00.000Z","bspReconciled":false,"complete":true,"inPlay":false,"crossMatching":true,"runnersVoidable":false,"numberOfActiveRunners":30,"betDelay":0,"status":"OPEN","runners":[{"status":"ACTIVE","sortPriority":1,"id":52385882,"name":"1 - 2"},{"status":"ACTIVE","sortPriority":2,"id":52385883,"name":"1 - 3"},{"status":"ACTIVE","sortPriority":3,"id":52385885,"name":"1 - 5"},{"status":"ACTIVE","sortPriority":4,"id":52385886,"name":"1 - 6"},{"status":"ACTIVE","sortPriority":5,"id":52385887,"name":"1 - 7"},{"status":"ACTIVE","sortPriority":6,"id":52385889,"name":"2 - 1"},{"status":"ACTIVE","sortPriority":7,"id":52385890,"name":"2 - 3"},{"status":"ACTIVE","sortPriority":8,"id":52385892,"name":"2 - 5"},{"status":"ACTIVE","sortPriority":9,"id":52385893,"name":"2 - 6"},{"status":"ACTIVE","sortPriority":10,"id":52385894,"name":"2 - 7"},{"status":"ACTIVE","sortPriority":11,"id":52385896,"name":"3 - 1"},{"status":"ACTIVE","sortPriority":12,"id":52385897,"name":"3 - 2"},{"status":"ACTIVE","sortPriority":13,"id":52385899,"name":"3 - 5"},{"status":"ACTIVE","sortPriority":14,"id":52385900,"name":"3 - 6"},{"status":"ACTIVE","sortPriority":15,"id":52385901,"name":"3 - 7"},{"status":"ACTIVE","sortPriority":16,"id":52385910,"name":"5 - 1"},{"status":"ACTIVE","sortPriority":17,"id":52385911,"name":"5 - 2"},{"status":"ACTIVE","sortPriority":18,"id":52385912,"name":"5 - 3"},{"status":"ACTIVE","sortPriority":19,"id":52385914,"name":"5 - 6"},{"status":"ACTIVE","sortPriority":20,"id":52385915,"name":"5 - 7"},{"status":"ACTIVE","sortPriority":21,"id":52385917,"name":"6 - 1"},{"status":"ACTIVE","sortPriority":22,"id":52385918,"name":"6 - 2"},{"status":"ACTIVE","sortPriority":23,"id":52385919,"name":"6 - 3"},{"status":"ACTIVE","sortPriority":24,"id":52385921,"name":"6 - 5"},{"status":"ACTIVE","sortPriority":25,"id":52385922,"name":"6 - 7"},{"status":"ACTIVE","sortPriority":26,"id":52385924,"name":"7 - 1"},{"status":"ACTIVE","sortPriority":27,"id":52385925,"name":"7 - 2"},{"status":"ACTIVE","sortPriority":28,"id":52385926,"name":"7 - 3"},{"status":"ACTIVE","sortPriority":29,"id":52385928,"name":"7 - 5"},{"status":"ACTIVE","sortPriority":30,"id":52385929,"name":"7 - 6"}],"regulators":["MR_INT"],"venue":"Murray Bridge","countryCode":"AU","discountAllowed":true,"timezone":"Australia/Adelaide","openDate":"2024-06-02T08:21:00.000Z","version":5962801920,"name":"Exacta","eventName":"Murray Bridge (AUS) 2nd Jun"},"rc":[],"con":true,"img":false}]}
{"op":"mcm","clk":"11449095047","pt":1717303714043,"mc":[{"id":"1.229554912","rc":[{"atb":[[38,1.41],[48,0.55],[24,4.55],[29,2.8]],"id":52385894},{"atb":[[36,0.75],[19,5.81],[23,3.57],[28,1.94]],"id":52385893},{"atb":[[170,0.31],[85,1.25],[220,0.12],[120,0.66]],"id":52385919},{"atb":[[300,0.35],[350,0.23],[400,0.13],[450,0.06]],"id":52385900}],"con":true,"img":false}]}
{"op":"mcm","clk":"11449095056","pt":1717303714149,"mc":[{"id":"1.229554912","rc":[{"atb":[[160,0.33],[80,1.32],[210,0.13],[110,0.72]],"id":52385912},{"atb":[[16.5,5.06],[19,2.91],[23,1.19],[14,8.05]],"id":52385918},{"atb":[[6.4,19.38],[7.4,12.26],[8.4,7.07],[9.4,3.11]],"id":52385887},{"atb":[[17,1.64],[12,7.14],[9.8,11.89],[14.5,3.88]],"id":52385889},{"atb":[[17.5,3.17],[20,1.38],[12.5,9.1],[15,5.6]],"id":52385914},{"atb":[[70,0.38],[38,2.12],[48,1.11],[29,3.74]],"id":52385883},{"atb":[[6.4,4.84],[5.2,18.68],[5.7,11.13],[4.7,28.28]],"id":52385885},{"atb":[[170,0.31],[85,1.25],[220,0.12],[120,0.66]],"id":52385896},{"atb":[[36,0.75],[19,5.81],[23,3.57],[28,1.94]],"id":52385929},{"atb":[[260,0.3],[310,0.17],[360,0.07],[210,0.5]],"id":52385890},{"atb":[[17.5,4.76],[20,2.75],[25,1.09],[15,7.48]],"id":52385892},{"atb":[[17,1.64],[12,7.14],[9.8,11.89],[14.5,3.88]],"id":52385911},{"atb":[[17,3.27],[19.5,1.41],[12,9.51],[14.5,5.81]],"id":52385921},{"atb":[[16,6.97],[18.5,4.48],[22,2.49],[27,1]],"id":52385915},{"atb":[[8,11.21],[9,6.54],[10,2.91],[7,17.44]],"id":52385917},{"atb":[[260,0.3],[310,0.17],[360,0.07],[210,0.5]],"id":52385926},{"atb":[[540,0.15],[590,0.09],[640,0.04],[490,0.21]],"id":52385897},{"atb":[[17.5,6.34],[20,4.13],[25,2.18],[30,0.9]],"id":52385922},{"atb":[[17,1.64],[12,7.14],[9.8,11.89],[14.5,3.88]],"id":52385924},{"atb":[[290,0.36],[340,0.23],[390,0.14],[440,0.06]],"id":52385899},{"atb":[[540,0.15],[590,0.09],[640,0.04],[490,0.21]],"id":52385901}],"con":true,"img":false}]}
{"op":"mcm","clk":"11449095066","pt":1717303714409,"mc":[{"id":"1.229554912","rc":[{"atb":[[9.6,3.04],[8.6,6.89],[7.6,11.89],[6.6,18.68]],"id":52385910},{"atb":[[8.6,3.44],[5.8,21.8],[7.6,7.93],[6.6,14.02]],"id":52385882},{"atb":[[34,0.8],[18.5,5.98],[22,3.74],[27,2.01]],"id":52385928}],"con":true,"img":false}]}
{"op":"mcm","clk":"11449095068","pt":1717303714511,"mc":[{"id":"1.229554912","rc":[{"atb":[[34,1.59],[44,0.61],[22,4.98],[27,3.02]],"id":52385925},{"atb":[[4.8,27.54],[5.8,10.9],[5.3,18.25],[6.6,4.67]],"id":52385886}],"con":true,"img":false}]}
{"op":"mcm","clk":"11449099388","pt":1717303849619,"mc":[{"id":"1.229554912","rc":[{"atb":[[4.8,27.5],[3.9,84.1]],"id":52385910},{"atb":[[150,1.63],[250,0.41]],"id":52385912},{"atb":[[8.6,32.09],[11.5,9.95]],"id":52385918},{"atb":[[6.8,42.05],[8.8,13.4]],"id":52385914},{"atb":[[12,9.5],[8.8,31.27]],"id":52385929},{"atb":[[10,27.1],[15,7.46]],"id":52385925},{"atb":[[11,10.45],[8.4,32.96]],"id":52385911},{"atb":[[260,0.4],[160,1.53]],"id":52385919},{"atb":[[6.8,42.05],[8.8,13.4]],"id":52385921},{"atb":[[11,10.45],[8.4,32.96]],"id":52385915},{"atb":[[4.8,27.5],[3.9,84.1]],"id":52385917},{"atb":[[540,0.44],[640,0.16]],"id":52385926},{"atb":[[12,9.5],[8.8,31.27]],"id":52385928},{"atb":[[8.6,32.09],[11.5,9.95]],"id":52385922},{"atb":[[5.3,56.72],[6.6,18.66]],"id":52385924}],"con":true,"img":false}]}
{"op":"mcm","clk":"11449099391","pt":1717303849717,"mc":[{"id":"1.229554912","rc":[{"atb":[[3.95,82.67],[4.9,26.8]],"id":52385887},{"atb":[[5.3,56.72],[6.6,18.66]],"id":52385889},{"atb":[[16,16.26],[22,4.97]],"id":52385883},{"atb":[[3.2,110.86],[3.7,38.71]],"id":52385885},{"atb":[[10,27.1],[15,7.46]],"id":52385894},{"atb":[[38,2.82],[24,10.6]],"id":52385896},{"atb":[[540,0.44],[640,0.16]],"id":52385890},{"atb":[[12,9.5],[8.8,31.27]],"id":52385892},{"atb":[[280,0.87],[380,0.27]],"id":52385900},{"atb":[[3.25,108.4],[3.75,38]],"id":52385886},{"atb":[[3.95,82.67],[4.9,26.8]],"id":52385882},{"atb":[[550,0.44],[650,0.16]],"id":52385897},{"atb":[[12,9.5],[8.8,31.27]],"id":52385893},{"atb":[[260,0.94],[360,0.29]],"id":52385899},{"atb":[[550,0.44],[650,0.16]],"id":52385901}],"con":true,"img":false}]}
{"op":"mcm","clk":"11449105759","pt":1717304051610,"mc":[{"id":"1.229554912","rc":[{"atb":[[16.5,0],[19,0],[23,0],[14,0]],"id":52385918},{"atb":[[38,0],[48,0],[24,0],[29,0]],"id":52385894},{"atb":[[17,0],[19.5,0],[12,0],[14.5,0]],"id":52385921}],"con":true,"img":false}]}
{"op":"mcm","clk":"11449105789","pt":1717304052278,"mc":[{"id":"1.229554912","rc":[{"atb":[[16.5,5.06],[19,2.91],[23,1.19],[14,8.05]],"id":52385918},{"atb":[[38,1.41],[48,0.55],[24,4.55],[29,2.8]],"id":52385894},{"atb":[[17,3.27],[19.5,1.41],[12,9.51],[14.5,5.81]],"id":52385921}],"con":true,"img":false}]}
{"op":"mcm","clk":"11449111956","pt":1717304219910,"mc":[{"id":"1.229554912","rc":[{"atb":[[540,0],[590,0],[640,0],[490,0]],"id":52385901}],"con":true,"img":false}]}
{"op":"mcm","clk":"11449111985","pt":1717304220583,"mc":[{"id":"1.229554912","rc":[{"atb":[[530,0.15],[580,0.09],[630,0.04],[480,0.22]],"id":52385901}],"con":true,"img":false}]}
{"op":"mcm","clk":"11449115276","pt":1717304291307,"mc":[{"id":"1.229554912","rc":[{"atb":[[17.5,0],[20,0],[12.5,0],[15,0]],"id":52385914},{"atb":[[260,0],[310,0],[360,0],[210,0]],"id":52385890},{"atb":[[8,0],[9,0],[10,0],[7,0]],"id":52385917},{"atb":[[260,0],[310,0],[360,0],[210,0]],"id":52385926},{"atb":[[540,0],[590,0],[640,0],[490,0]],"id":52385897}],"con":true,"img":false}]}
{"op":"mcm","clk":"11449115324","pt":1717304292179,"mc":[{"id":"1.229554912","rc":[{"atb":[[18,3.08],[21,1.31],[13,8.72],[15.5,5.41]],"id":52385914},{"atb":[[300,0.17],[350,0.07],[200,0.53],[250,0.31]],"id":52385890},{"atb":[[7.2,16.88],[9.2,6.38],[10.5,2.75],[8.2,10.9]],"id":52385917},{"atb":[[300,0.17],[350,0.07],[200,0.53],[250,0.31]],"id":52385926},{"atb":[[530,0.15],[580,0.09],[630,0.04],[480,0.22]],"id":52385897}],"con":true,"img":false}]}
{"op":"mcm","clk":"11449124733","pt":1717304346070,"mc":[{"id":"1.229554912","rc":[{"atb":[[18,0],[21,0],[13,0],[15.5,0]],"id":52385914},{"atb":[[530,0],[580,0],[630,0],[480,0]],"id":52385901}],"con":true,"img":false}]}
{"op":"mcm","clk":"11449124766","pt":1717304346738,"mc":[{"id":"1.229554912","rc":[{"atb":[[17.5,3.17],[20,1.38],[12.5,9.1],[15,5.6]],"id":52385914},{"atb":[[540,0.15],[590,0.09],[640,0.04],[490,0.21]],"id":52385901}],"con":true,"img":false}]}
{"op":"mcm","clk":"11449199696","pt":1717305485296,"mc":[{"id":"1.229554912","rc":[{"atb":[[9.6,0],[8.6,0],[7.6,0],[6.6,0]],"id":52385910},{"atb":[[540,0],[590,0],[640,0],[490,0]],"id":52385901}],"con":true,"img":false}]}
{"op":"mcm","clk":"11449199752","pt":1717305486014,"mc":[{"id":"1.229554912","rc":[{"atb":[[6.8,18.04],[9.8,2.97],[8.8,6.71],[7.8,11.54]],"id":52385910},{"atb":[[530,0.15],[580,0.09],[630,0.04],[480,0.22]],"id":52385901}],"con":true,"img":false}]}
{"op":"mcm","clk":"11449204163","pt":1717305549629,"mc":[{"id":"1.229554912","rc":[{"atb":[[16.5,0],[19,0],[23,0],[14,0]],"id":52385918},{"atb":[[38,0],[48,0],[24,0],[29,0]],"id":52385894},{"atb":[[17,0],[19.5,0],[12,0],[14.5,0]],"id":52385921},{"atb":[[8.6,0],[5.8,0],[7.6,0],[6.6,0]],"id":52385882}],"con":true,"img":false}]}
{"op":"mcm","clk":"11449204221","pt":1717305550303,"mc":[{"id":"1.229554912","rc":[{"atb":[[16.5,5.06],[19,2.91],[23,1.19],[14,8.05]],"id":52385918},{"atb":[[38,1.41],[48,0.55],[24,4.55],[29,2.8]],"id":52385894},{"atb":[[17,3.27],[19.5,1.41],[12,9.51],[14.5,5.81]],"id":52385921},{"atb":[[8.6,3.44],[5.8,21.8],[7.6,7.93],[6.6,14.02]],"id":52385882}],"con":true,"img":false}]}
{"op":"mcm","clk":"11449232528","pt":1717305940783,"mc":[{"id":"1.229554912","rc":[{"atb":[[530,0],[580,0],[630,0],[480,0]],"id":52385901}],"con":true,"img":false}]}
{"op":"mcm","clk":"11449232575","pt":1717305941507,"mc":[{"id":"1.229554912","rc":[{"atb":[[540,0.15],[590,0.09],[640,0.04],[490,0.21]],"id":52385901}],"con":true,"img":false}]}
{"op":"mcm","clk":"11449235098","pt":1717305976770,"mc":[{"id":"1.229554912","rc":[{"atb":[[300,0],[200,0],[250,0]],"id":52385926},{"atb":[[530,0]],"id":52385897}],"con":true,"img":false}]}
{"op":"mcm","clk":"11449235103","pt":1717305976873,"mc":[{"id":"1.229554912","rc":[{"atb":[[300,0],[350,0],[200,0],[250,0]],"id":52385890},{"atb":[[350,0]],"id":52385926},{"atb":[[580,0],[630,0],[480,0]],"id":52385897}],"con":true,"img":false}]}
{"op":"mcm","clk":"11449235139","pt":1717305977444,"mc":[{"id":"1.229554912","rc":[{"atb":[[260,0.3],[310,0.17],[210,0.5]],"id":52385926},{"atb":[[540,0.15]],"id":52385897}],"con":true,"img":false}]}
{"op":"mcm","clk":"11449235148","pt":1717305977545,"mc":[{"id":"1.229554912","rc":[{"atb":[[260,0.3],[310,0.17],[360,0.07],[210,0.5]],"id":52385890},{"atb":[[360,0.07]],"id":52385926},{"atb":[[590,0.09],[640,0.04],[490,0.21]],"id":52385897}],"con":true,"img":false}]}
{"op":"mcm","clk":"11449239463","pt":1717306042263,"mc":[{"id":"1.229554912","rc":[{"atb":[[260,0],[310,0],[360,0],[210,0]],"id":52385890},{"atb":[[260,0],[310,0],[360,0],[210,0]],"id":52385926},{"atb":[[540,0],[590,0],[640,0],[490,0]],"id":52385897},{"atb":[[540,0],[590,0],[640,0],[490,0]],"id":52385901}],"con":true,"img":false}]}
{"op":"mcm","clk":"11449239528","pt":1717306042988,"mc":[{"id":"1.229554912","rc":[{"atb":[[300,0.17],[350,0.07],[200,0.53],[250,0.31]],"id":52385890},{"atb":[[300,0.17],[350,0.07],[200,0.53],[250,0.31]],"id":52385926},{"atb":[[530,0.15],[580,0.09],[630,0.04],[480,0.22]],"id":52385897},{"atb":[[530,0.15],[580,0.09],[630,0.04],[480,0.22]],"id":52385901}],"con":true,"img":false}]}
{"op":"mcm","clk":"11449308294","pt":1717306959766,"mc":[{"id":"1.229554912","rc":[{"atb":[[16.5,0],[19,0],[23,0],[14,0]],"id":52385918},{"atb":[[38,0],[48,0],[24,0],[29,0]],"id":52385894},{"atb":[[17,0],[19.5,0],[12,0],[14.5,0]],"id":52385921},{"atb":[[8.6,0],[5.8,0],[7.6,0],[6.6,0]],"id":52385882}],"con":true,"img":false}]}
{"op":"mcm","clk":"11449308338","pt":1717306960487,"mc":[{"id":"1.229554912","rc":[{"atb":[[16.5,5.06],[19,2.91],[23,1.19],[14,8.05]],"id":52385918},{"atb":[[38,1.41],[48,0.55],[24,4.55],[29,2.8]],"id":52385894},{"atb":[[17,3.27],[19.5,1.41],[12,9.51],[14.5,5.81]],"id":52385921},{"atb":[[8.6,3.44],[5.8,21.8],[7.6,7.93],[6.6,14.02]],"id":52385882}],"con":true,"img":false}]}
{"op":"mcm","clk":"11449346563","pt":1717307552448,"mc":[{"id":"1.229554912","rc":[{"atb":[[300,0],[350,0],[200,0],[250,0]],"id":52385890},{"atb":[[300,0],[350,0],[200,0],[250,0]],"id":52385926},{"atb":[[530,0],[580,0],[630,0],[480,0]],"id":52385897},{"atb":[[530,0],[580,0],[630,0],[480,0]],"id":52385901}],"con":true,"img":false}]}
{"op":"mcm","clk":"11449346595","pt":1717307553162,"mc":[{"id":"1.229554912","rc":[{"atb":[[260,0.3],[310,0.17],[360,0.07],[210,0.5]],"id":52385890},{"atb":[[260,0.3],[310,0.17],[360,0.07],[210,0.5]],"id":52385926},{"atb":[[540,0.15],[590,0.09],[640,0.04],[490,0.21]],"id":52385897},{"atb":[[540,0.15],[590,0.09],[640,0.04],[490,0.21]],"id":52385901}],"con":true,"img":false}]}
{"op":"mcm","clk":"11449375605","pt":1717308221713,"mc":[{"id":"1.229554912","rc":[{"atb":[[260,0],[310,0],[360,0],[210,0]],"id":52385890},{"atb":[[260,0],[310,0],[360,0],[210,0]],"id":52385926},{"atb":[[540,0],[590,0],[640,0],[490,0]],"id":52385897},{"atb":[[540,0],[590,0],[640,0],[490,0]],"id":52385901}],"con":true,"img":false}]}
{"op":"mcm","clk":"11449375645","pt":1717308222488,"mc":[{"id":"1.229554912","rc":[{"atb":[[300,0.17],[350,0.07],[200,0.53],[250,0.31]],"id":52385890},{"atb":[[300,0.17],[350,0.07],[200,0.53],[250,0.31]],"id":52385926},{"atb":[[530,0.15],[580,0.09],[630,0.04],[480,0.22]],"id":52385901}],"con":true,"img":false}]}
{"op":"mcm","clk":"11449375650","pt":1717308222588,"mc":[{"id":"1.229554912","rc":[{"atb":[[530,0.15],[580,0.09],[630,0.04],[480,0.22]],"id":52385897}],"con":true,"img":false}]}
{"op":"mcm","clk":"11449376907","pt":1717308250434,"mc":[{"id":"1.229554912","rc":[{"atb":[[16.5,0],[19,0],[23,0],[14,0]],"id":52385918},{"atb":[[38,0],[48,0],[24,0],[29,0]],"id":52385894},{"atb":[[17,0],[19.5,0],[12,0],[14.5,0]],"id":52385921}],"con":true,"img":false}]}
{"op":"mcm","clk":"11449376934","pt":1717308251157,"mc":[{"id":"1.229554912","rc":[{"atb":[[16.5,5.06],[19,2.91],[23,1.19],[14,8.05]],"id":52385918},{"atb":[[38,1.41],[48,0.55],[24,4.55],[29,2.8]],"id":52385894},{"atb":[[17,3.27],[19.5,1.41],[12,9.51],[14.5,5.81]],"id":52385921}],"con":true,"img":false}]}
{"op":"mcm","clk":"11449473391","pt":1717309665273,"mc":[{"id":"1.229554912","rc":[{"atb":[[16.5,0],[19,0],[23,0],[14,0]],"id":52385918},{"atb":[[38,0],[48,0],[24,0],[29,0]],"id":52385894},{"atb":[[17,0],[19.5,0],[12,0],[14.5,0]],"id":52385921},{"atb":[[8.6,0],[5.8,0],[7.6,0],[6.6,0]],"id":52385882}],"con":true,"img":false}]}
{"op":"mcm","clk":"11449473435","pt":1717309665990,"mc":[{"id":"1.229554912","rc":[{"atb":[[16.5,5.06],[19,2.91],[23,1.19],[14,8.05]],"id":52385918},{"atb":[[38,1.41],[48,0.55],[24,4.55],[29,2.8]],"id":52385894},{"atb":[[17,3.27],[19.5,1.41],[12,9.51],[14.5,5.81]],"id":52385921},{"atb":[[8.6,3.44],[5.8,21.8],[7.6,7.93],[6.6,14.02]],"id":52385882}],"con":true,"img":false}]}
{"op":"mcm","clk":"11449523474","pt":1717310343599,"mc":[{"id":"1.229554912","rc":[{"atb":[[160,0],[80,0],[210,0],[110,0]],"id":52385912},{"atb":[[6.4,0],[5.2,0],[5.7,0],[4.7,0]],"id":52385885},{"atb":[[300,0],[350,0],[200,0],[250,0]],"id":52385890},{"atb":[[300,0],[350,0],[400,0],[450,0]],"id":52385900},{"atb":[[170,0],[85,0],[220,0],[120,0]],"id":52385919},{"atb":[[300,0],[350,0],[200,0],[250,0]],"id":52385926},{"atb":[[530,0],[580,0],[630,0],[480,0]],"id":52385897},{"atb":[[17.5,0],[20,0],[25,0],[30,0]],"id":52385922},{"atb":[[530,0],[580,0],[630,0],[480,0]],"id":52385901}],"con":true,"img":false}]}
{"op":"mcm","clk":"11449523516","pt":1717310344323,"mc":[{"id":"1.229554912","rc":[{"atb":[[170,0.31],[85,1.25],[220,0.12],[120,0.66]],"id":52385912},{"atb":[[5.6,11.37],[5.1,19.14],[4.6,29.07],[6.2,5.03]],"id":52385885},{"atb":[[260,0.3],[310,0.17],[360,0.07],[210,0.5]],"id":52385890},{"atb":[[310,0.34],[360,0.22],[410,0.13],[460,0.06]],"id":52385900},{"atb":[[130,0.61],[180,0.29],[90,1.18],[230,0.12]],"id":52385919},{"atb":[[260,0.3],[310,0.17],[360,0.07],[210,0.5]],"id":52385926},{"atb":[[540,0.15],[590,0.09],[640,0.04],[490,0.21]],"id":52385897},{"atb":[[32,0.84],[18,6.15],[21,3.92],[26,2.09]],"id":52385922},{"atb":[[540,0.15],[590,0.09],[640,0.04],[490,0.21]],"id":52385901}],"con":true,"img":false}]}
{"op":"mcm","clk":"11449524704","pt":1717310363066,"mc":[{"id":"1.229554912","rc":[{"atb":[[4.8,0],[3.9,0]],"id":52385910},{"atb":[[150,0],[250,0]],"id":52385912},{"atb":[[8.6,0],[11.5,0]],"id":52385918},{"atb":[[3.95,0],[4.9,0]],"id":52385887},{"atb":[[5.3,0],[6.6,0]],"id":52385889},{"atb":[[6.8,0],[8.8,0]],"id":52385914},{"atb":[[16,0],[22,0]],"id":52385883},{"atb":[[3.2,0],[3.7,0]],"id":52385885},{"atb":[[10,0],[15,0]],"id":52385894},{"atb":[[38,0],[24,0]],"id":52385896},{"atb":[[12,0],[8.8,0]],"id":52385929},{"atb":[[540,0],[640,0]],"id":52385890},{"atb":[[12,0],[8.8,0]],"id":52385892},{"atb":[[10,0],[15,0]],"id":52385925},{"atb":[[280,0],[380,0]],"id":52385900},{"atb":[[11,0],[8.4,0]],"id":52385911},{"atb":[[3.25,0],[3.75,0]],"id":52385886},{"atb":[[260,0],[160,0]],"id":52385919},{"atb":[[6.8,0],[8.8,0]],"id":52385921},{"atb":[[3.95,0],[4.9,0]],"id":52385882},{"atb":[[11,0],[8.4,0]],"id":52385915},{"atb":[[4.8,0],[3.9,0]],"id":52385917},{"atb":[[540,0],[640,0]],"id":52385926},{"atb":[[12,0],[8.8,0]],"id":52385928},{"atb":[[550,0],[650,0]],"id":52385897},{"atb":[[8.6,0],[11.5,0]],"id":52385922},{"atb":[[5.3,0],[6.6,0]],"id":52385924},{"atb":[[12,0],[8.8,0]],"id":52385893},{"atb":[[260,0],[360,0]],"id":52385899},{"atb":[[550,0],[650,0]],"id":52385901}],"con":true,"img":false}]}
{"op":"mcm","clk":"11449527131","pt":1717310402797,"mc":[{"id":"1.229554912","rc":[{"atb":[[4.8,27.5],[3.9,84.1]],"id":52385910},{"atb":[[150,1.63],[250,0.41]],"id":52385912},{"atb":[[8.6,32.09],[11.5,9.95]],"id":52385918},{"atb":[[6.8,42.05],[8.8,13.4]],"id":52385914},{"atb":[[12,9.5],[8.8,31.27]],"id":52385929},{"atb":[[10,27.1],[15,7.46]],"id":52385925},{"atb":[[11,10.45],[8.4,32.96]],"id":52385911},{"atb":[[260,0.4],[160,1.53]],"id":52385919},{"atb":[[6.8,42.05],[8.8,13.4]],"id":52385921},{"atb":[[11,10.45],[8.4,32.96]],"id":52385915},{"atb":[[4.8,27.5],[3.9,84.1]],"id":52385917},{"atb":[[540,0.44],[640,0.16]],"id":52385926},{"atb":[[12,9.5],[8.8,31.27]],"id":52385928},{"atb":[[8.6,32.09],[11.5,9.95]],"id":52385922},{"atb":[[5.3,56.72],[6.6,18.66]],"id":52385924}],"con":true,"img":false}]}
{"op":"mcm","clk":"11449527137","pt":1717310402901,"mc":[{"id":"1.229554912","rc":[{"atb":[[3.95,82.67],[4.9,26.8]],"id":52385887},{"atb":[[5.3,56.72],[6.6,18.66]],"id":52385889},{"atb":[[16,16.26],[22,4.97]],"id":52385883},{"atb":[[3.2,110.86],[3.7,38.71]],"id":52385885},{"atb":[[10,27.1],[15,7.46]],"id":52385894},{"atb":[[38,2.82],[24,10.6]],"id":52385896},{"atb":[[540,0.44],[640,0.16]],"id":52385890},{"atb":[[12,9.5],[8.8,31.27]],"id":52385892},{"atb":[[280,0.87],[380,0.27]],"id":52385900},{"atb":[[3.25,108.4],[3.75,38]],"id":52385886},{"atb":[[3.95,82.67],[4.9,26.8]],"id":52385882},{"atb":[[550,0.44],[650,0.16]],"id":52385897},{"atb":[[12,9.5],[8.8,31.27]],"id":52385893},{"atb":[[260,0.94],[360,0.29]],"id":52385899},{"atb":[[550,0.44],[650,0.16]],"id":52385901}],"con":true,"img":false}]}
{"op":"mcm","clk":"11449545108","pt":1717310708609,"mc":[{"id":"1.229554912","rc":[{"atb":[[260,0],[310,0],[360,0],[210,0]],"id":52385890},{"atb":[[310,0],[360,0],[410,0],[460,0]],"id":52385900},{"atb":[[260,0],[310,0],[360,0],[210,0]],"id":52385926},{"atb":[[540,0],[590,0],[640,0],[490,0]],"id":52385897},{"atb":[[540,0],[590,0],[640,0],[490,0]],"id":52385901}],"con":true,"img":false}]}
{"op":"mcm","clk":"11449545116","pt":1717310708670,"mc":[{"id":"1.229554912","rc":[{"atb":[[32,0],[18,0],[21,0],[26,0]],"id":52385922}],"con":true,"img":false}]}
{"op":"mcm","clk":"11449545154","pt":1717310709277,"mc":[{"id":"1.229554912","rc":[{"atb":[[270,0.29],[320,0.16],[370,0.07],[220,0.48]],"id":52385890},{"atb":[[300,0.35],[350,0.23],[400,0.13],[450,0.06]],"id":52385900},{"atb":[[270,0.29],[320,0.16],[370,0.07],[220,0.48]],"id":52385926},{"atb":[[550,0.59],[600,0.09],[650,0.2],[500,0.21]],"id":52385897},{"atb":[[550,0.59],[600,0.09],[650,0.2],[500,0.21]],"id":52385901}],"con":true,"img":false}]}
{"op":"mcm","clk":"11449545164","pt":1717310709380,"mc":[{"id":"1.229554912","rc":[{"atb":[[17.5,6.34],[20,4.13],[25,2.18],[30,0.9]],"id":52385922}],"con":true,"img":false}]}
{"op":"mcm","clk":"11449558893","pt":1717310947802,"mc":[{"id":"1.229554912","rc":[{"atb":[[8.6,0],[5.8,0],[7.6,0],[6.6,0]],"id":52385882}],"con":true,"img":false}]}
{"op":"mcm","clk":"11449558902","pt":1717310947927,"mc":[{"id":"1.229554912","rc":[{"atb":[[16.5,0],[19,0],[23,0],[14,0]],"id":52385918},{"atb":[[38,0],[48,0],[24,0],[29,0]],"id":52385894},{"atb":[[17,0],[19.5,0],[12,0],[14.5,0]],"id":52385921}],"con":true,"img":false}]}
{"op":"mcm","clk":"11449558934","pt":1717310948516,"mc":[{"id":"1.229554912","rc":[{"atb":[[8.6,3.44],[5.8,21.8],[7.6,7.93],[6.6,14.02]],"id":52385882}],"con":true,"img":false}]}
{"op":"mcm","clk":"11449558941","pt":1717310948618,"mc":[{"id":"1.229554912","rc":[{"atb":[[16.5,5.06],[19,2.91],[23,1.19],[14,8.05]],"id":52385918},{"atb":[[17,3.27],[19.5,1.41],[12,9.51],[14.5,5.81]],"id":52385921}],"con":true,"img":false}]}
{"op":"mcm","clk":"11449558947","pt":1717310948721,"mc":[{"id":"1.229554912","rc":[{"atb":[[38,1.41],[48,0.55],[24,4.55],[29,2.8]],"id":52385894}],"con":true,"img":false}]}
{"op":"mcm","clk":"11449584893","pt":1717311411368,"mc":[{"id":"1.229554912","rc":[{"atb":[[4.8,0],[3.9,0]],"id":52385910},{"atb":[[150,0],[250,0]],"id":52385912},{"atb":[[8.6,0],[11.5,0]],"id":52385918},{"atb":[[3.95,0],[4.9,0]],"id":52385887},{"atb":[[5.3,0],[6.6,0]],"id":52385889},{"atb":[[6.8,0],[8.8,0]],"id":52385914},{"atb":[[16,0],[22,0]],"id":52385883},{"atb":[[3.2,0],[3.7,0]],"id":52385885},{"atb":[[10,0],[15,0]],"id":52385894},{"atb":[[38,0],[24,0]],"id":52385896},{"atb":[[12,0],[8.8,0]],"id":52385929},{"atb":[[540,0],[640,0]],"id":52385890},{"atb":[[12,0],[8.8,0]],"id":52385892},{"atb":[[10,0],[15,0]],"id":52385925},{"atb":[[280,0],[380,0]],"id":52385900},{"atb":[[11,0],[8.4,0]],"id":52385911},{"atb":[[3.25,0],[3.75,0]],"id":52385886},{"atb":[[260,0],[160,0]],"id":52385919},{"atb":[[6.8,0],[8.8,0]],"id":52385921},{"atb":[[3.95,0],[4.9,0]],"id":52385882},{"atb":[[11,0],[8.4,0]],"id":52385915},{"atb":[[4.8,0],[3.9,0]],"id":52385917},{"atb":[[540,0],[640,0]],"id":52385926},{"atb":[[12,0],[8.8,0]],"id":52385928},{"atb":[[550,0.14],[650,0.04]],"id":52385897},{"atb":[[8.6,0],[11.5,0]],"id":52385922},{"atb":[[5.3,0],[6.6,0]],"id":52385924},{"atb":[[12,0],[8.8,0]],"id":52385893},{"atb":[[260,0],[360,0]],"id":52385899},{"atb":[[550,0.14],[650,0.04]],"id":52385901}],"con":true,"img":false}]}
{"op":"mcm","clk":"11449585319","pt":1717311419789,"mc":[{"id":"1.229554912","rc":[{"atb":[[4.8,27.5],[3.9,84.1]],"id":52385910},{"atb":[[150,1.63],[250,0.41]],"id":52385912},{"atb":[[8.6,32.09],[11.5,9.95]],"id":52385918},{"atb":[[6.8,42.05],[8.8,13.4]],"id":52385914},{"atb":[[12,9.5],[8.8,31.27]],"id":52385929},{"atb":[[10,27.1],[15,7.46]],"id":52385925},{"atb":[[11,10.45],[8.4,32.96]],"id":52385911},{"atb":[[260,0.4],[160,1.53]],"id":52385919},{"atb":[[6.8,42.05],[8.8,13.4]],"id":52385921},{"atb":[[11,10.45],[8.4,32.96]],"id":52385915},{"atb":[[4.8,27.5],[3.9,84.1]],"id":52385917},{"atb":[[540,0.44],[640,0.16]],"id":52385926},{"atb":[[12,9.5],[8.8,31.27]],"id":52385928},{"atb":[[8.6,32.09],[11.5,9.95]],"id":52385922},{"atb":[[5.3,56.72],[6.6,18.66]],"id":52385924}],"con":true,"img":false}]}
{"op":"mcm","clk":"11449585341","pt":1717311420046,"mc":[{"id":"1.229554912","rc":[{"atb":[[3.95,82.67],[4.9,26.8]],"id":52385887},{"atb":[[5.3,56.72],[6.6,18.66]],"id":52385889},{"atb":[[16,16.26],[22,4.97]],"id":52385883},{"atb":[[3.2,110.86],[3.7,38.71]],"id":52385885},{"atb":[[10,27.1],[15,7.46]],"id":52385894},{"atb":[[38,2.82],[24,10.6]],"id":52385896},{"atb":[[540,0.44],[640,0.16]],"id":52385890},{"atb":[[12,9.5],[8.8,31.27]],"id":52385892},{"atb":[[280,0.87],[380,0.27]],"id":52385900},{"atb":[[3.25,108.4],[3.75,38]],"id":52385886},{"atb":[[3.95,82.67],[4.9,26.8]],"id":52385882},{"atb":[[550,0.59],[650,0.2]],"id":52385897},{"atb":[[12,9.5],[8.8,31.27]],"id":52385893},{"atb":[[260,0.94],[360,0.29]],"id":52385899},{"atb":[[550,0.59],[650,0.2]],"id":52385901}],"con":true,"img":false}]}
{"op":"mcm","clk":"11449600167","pt":1717311693782,"mc":[{"id":"1.229554912","rc":[{"atb":[[5.6,0],[5.1,0],[4.6,0],[6.2,0]],"id":52385885},{"atb":[[130,0],[180,0],[90,0],[230,0]],"id":52385919}],"con":true,"img":false}]}
{"op":"mcm","clk":"11449600213","pt":1717311694605,"mc":[{"id":"1.229554912","rc":[{"atb":[[6.4,4.84],[5.2,18.68],[5.7,11.13],[4.7,28.28]],"id":52385885},{"atb":[[170,0.31],[85,1.25],[220,0.12],[120,0.66]],"id":52385919}],"con":true,"img":false}]}
{"op":"mcm","clk":"11449623621","pt":1717312148206,"mc":[{"id":"1.229554912","rc":[{"atb":[[16.5,0],[19,0],[23,0],[14,0]],"id":52385918},{"atb":[[38,0],[48,0],[24,0],[29,0]],"id":52385894},{"atb":[[17,0],[19.5,0],[12,0],[14.5,0]],"id":52385921},{"atb":[[8.6,0],[5.8,0],[7.6,0],[6.6,0]],"id":52385882}],"con":true,"img":false}]}
{"op":"mcm","clk":"11449623641","pt":1717312148876,"mc":[{"id":"1.229554912","rc":[{"atb":[[16.5,5.06],[19,2.91],[23,1.19],[14,8.05]],"id":52385918},{"atb":[[38,1.41],[48,0.55],[24,4.55],[29,2.8]],"id":52385894},{"atb":[[17,3.27],[19.5,1.41],[12,9.51],[14.5,5.81]],"id":52385921},{"atb":[[8.6,3.44],[5.8,21.8],[7.6,7.93],[6.6,14.02]],"id":52385882}],"con":true,"img":false}]}
{"op":"mcm","clk":"11449637274","pt":1717312502775,"mc":[{"id":"1.229554912","rc":[{"atb":[[4.8,0],[3.9,0]],"id":52385910},{"atb":[[150,0],[250,0]],"id":52385912},{"atb":[[8.6,0],[11.5,0]],"id":52385918},{"atb":[[3.95,0],[4.9,0]],"id":52385887},{"atb":[[5.3,0],[6.6,0]],"id":52385889},{"atb":[[6.8,0],[8.8,0]],"id":52385914},{"atb":[[16,0],[22,0]],"id":52385883},{"atb":[[3.2,0],[3.7,0]],"id":52385885},{"atb":[[10,0],[15,0]],"id":52385894},{"atb":[[38,0],[24,0]],"id":52385896},{"atb":[[12,0],[8.8,0]],"id":52385929},{"atb":[[540,0],[640,0]],"id":52385890},{"atb":[[12,0],[8.8,0]],"id":52385892},{"atb":[[10,0],[15,0]],"id":52385925},{"atb":[[280,0],[380,0]],"id":52385900},{"atb":[[11,0],[8.4,0]],"id":52385911},{"atb":[[3.25,0],[3.75,0]],"id":52385886},{"atb":[[260,0],[160,0]],"id":52385919},{"atb":[[6.8,0],[8.8,0]],"id":52385921},{"atb":[[3.95,0],[4.9,0]],"id":52385882},{"atb":[[11,0],[8.4,0]],"id":52385915},{"atb":[[4.8,0],[3.9,0]],"id":52385917},{"atb":[[540,0],[640,0]],"id":52385926},{"atb":[[12,0],[8.8,0]],"id":52385928},{"atb":[[550,0.14],[650,0.04]],"id":52385897},{"atb":[[8.6,0],[11.5,0]],"id":52385922},{"atb":[[5.3,0],[6.6,0]],"id":52385924},{"atb":[[12,0],[8.8,0]],"id":52385893},{"atb":[[260,0],[360,0]],"id":52385899},{"atb":[[550,0.14],[650,0.04]],"id":52385901}],"con":true,"img":false}]}
{"op":"mcm","clk":"11449638382","pt":1717312529087,"mc":[{"id":"1.229554912","rc":[{"atb":[[3.95,82.67],[4.9,26.8]],"id":52385887},{"atb":[[5.3,56.72],[6.6,18.66]],"id":52385889},{"atb":[[16,16.26],[22,4.97]],"id":52385883},{"atb":[[3.2,110.86],[3.7,38.71]],"id":52385885},{"atb":[[10,27.1],[15,7.46]],"id":52385894},{"atb":[[38,2.82],[24,10.6]],"id":52385896},{"atb":[[540,0.44],[640,0.16]],"id":52385890},{"atb":[[12,9.5],[8.8,31.27]],"id":52385892},{"atb":[[280,0.87],[380,0.27]],"id":52385900},{"atb":[[3.25,108.4],[3.75,38]],"id":52385886},{"atb":[[3.95,82.67],[4.9,26.8]],"id":52385882},{"atb":[[550,0.59],[650,0.2]],"id":52385897},{"atb":[[12,9.5],[8.8,31.27]],"id":52385893},{"atb":[[260,0.94],[360,0.29]],"id":52385899},{"atb":[[550,0.59],[650,0.2]],"id":52385901}],"con":true,"img":false}]}
{"op":"mcm","clk":"11449638387","pt":1717312529190,"mc":[{"id":"1.229554912","rc":[{"atb":[[4.8,27.5],[3.9,84.1]],"id":52385910},{"atb":[[150,1.63],[250,0.41]],"id":52385912},{"atb":[[8.6,32.09],[11.5,9.95]],"id":52385918},{"atb":[[6.8,42.05],[8.8,13.4]],"id":52385914},{"atb":[[12,9.5],[8.8,31.27]],"id":52385929},{"atb":[[10,27.1],[15,7.46]],"id":52385925},{"atb":[[11,10.45],[8.4,32.96]],"id":52385911},{"atb":[[260,0.4],[160,1.53]],"id":52385919},{"atb":[[6.8,42.05],[8.8,13.4]],"id":52385921},{"atb":[[11,10.45],[8.4,32.96]],"id":52385915},{"atb":[[4.8,27.5],[3.9,84.1]],"id":52385917},{"atb":[[540,0.44],[640,0.16]],"id":52385926},{"atb":[[12,9.5],[8.8,31.27]],"id":52385928},{"atb":[[8.6,32.09],[11.5,9.95]],"id":52385922},{"atb":[[5.3,56.72],[6.6,18.66]],"id":52385924}],"con":true,"img":false}]}
{"op":"mcm","clk":"11449674181","pt":1717313349007,"mc":[{"id":"1.229554912","rc":[{"atb":[[16.5,0],[19,0],[23,0],[14,0]],"id":52385918},{"atb":[[38,0],[48,0],[24,0],[29,0]],"id":52385894},{"atb":[[17,0],[19.5,0],[12,0],[14.5,0]],"id":52385921},{"atb":[[8.6,0],[5.8,0],[7.6,0],[6.6,0]],"id":52385882}],"con":true,"img":false}]}
{"op":"mcm","clk":"11449674218","pt":1717313349683,"mc":[{"id":"1.229554912","rc":[{"atb":[[16.5,5.06],[19,2.91],[23,1.19],[14,8.05]],"id":52385918},{"atb":[[38,1.41],[48,0.55],[24,4.55],[29,2.8]],"id":52385894},{"atb":[[17,3.27],[19.5,1.41],[12,9.51],[14.5,5.81]],"id":52385921},{"atb":[[8.6,3.44],[5.8,21.8],[7.6,7.93],[6.6,14.02]],"id":52385882}],"con":true,"img":false}]}
{"op":"mcm","clk":"11449693432","pt":1717313604723,"mc":[{"id":"1.229554912","rc":[{"atb":[[4.8,0],[3.9,0]],"id":52385910},{"atb":[[150,0],[250,0]],"id":52385912},{"atb":[[8.6,0],[11.5,0]],"id":52385918},{"atb":[[3.95,0],[4.9,0]],"id":52385887},{"atb":[[5.3,0],[6.6,0]],"id":52385889},{"atb":[[6.8,0],[8.8,0]],"id":52385914},{"atb":[[16,0],[22,0]],"id":52385883},{"atb":[[3.2,0],[3.7,0]],"id":52385885},{"atb":[[10,0],[15,0]],"id":52385894},{"atb":[[38,0],[24,0]],"id":52385896},{"atb":[[12,0],[8.8,0]],"id":52385929},{"atb":[[540,0],[640,0]],"id":52385890},{"atb":[[12,0],[8.8,0]],"id":52385892},{"atb":[[10,0],[15,0]],"id":52385925},{"atb":[[280,0],[380,0]],"id":52385900},{"atb":[[11,0],[8.4,0]],"id":52385911},{"atb":[[3.25,0],[3.75,0]],"id":52385886},{"atb":[[260,0],[160,0]],"id":52385919},{"atb":[[6.8,0],[8.8,0]],"id":52385921},{"atb":[[3.95,0],[4.9,0]],"id":52385882},{"atb":[[11,0],[8.4,0]],"id":52385915},{"atb":[[4.8,0],[3.9,0]],"id":52385917},{"atb":[[540,0],[640,0]],"id":52385926},{"atb":[[12,0],[8.8,0]],"id":52385928},{"atb":[[550,0.14],[650,0.04]],"id":52385897},{"atb":[[8.6,0],[11.5,0]],"id":52385922},{"atb":[[5.3,0],[6.6,0]],"id":52385924},{"atb":[[12,0],[8.8,0]],"id":52385893},{"atb":[[260,0],[360,0]],"id":52385899},{"atb":[[550,0.14],[650,0.04]],"id":52385901}],"con":true,"img":false}]}
{"op":"mcm","clk":"11449696048","pt":1717313635048,"mc":[{"id":"1.229554912","rc":[{"atb":[[4.8,27.5],[3.9,84.1]],"id":52385910},{"atb":[[150,1.63],[250,0.41]],"id":52385912},{"atb":[[8.6,32.09],[11.5,9.95]],"id":52385918},{"atb":[[6.8,42.05],[8.8,13.4]],"id":52385914},{"atb":[[12,9.5],[8.8,31.27]],"id":52385929},{"atb":[[10,27.1],[15,7.46]],"id":52385925},{"atb":[[11,10.45],[8.4,32.96]],"id":52385911},{"atb":[[260,0.4],[160,1.53]],"id":52385919},{"atb":[[6.8,42.05],[8.8,13.4]],"id":52385921},{"atb":[[11,10.45],[8.4,32.96]],"id":52385915},{"atb":[[4.8,27.5],[3.9,84.1]],"id":52385917},{"atb":[[540,0.44],[640,0.16]],"id":52385926},{"atb":[[12,9.5],[8.8,31.27]],"id":52385928},{"atb":[[8.6,32.09],[11.5,9.95]],"id":52385922},{"atb":[[5.3,56.72],[6.6,18.66]],"id":52385924}],"con":true,"img":false}]}
{"op":"mcm","clk":"11449696057","pt":1717313635100,"mc":[{"id":"1.229554912","rc":[{"atb":[[3.95,82.67],[4.9,26.8]],"id":52385887},{"atb":[[5.3,56.72],[6.6,18.66]],"id":52385889},{"atb":[[16,16.26],[22,4.97]],"id":52385883},{"atb":[[3.2,110.86],[3.7,38.71]],"id":52385885},{"atb":[[10,27.1],[15,7.46]],"id":52385894},{"atb":[[38,2.82],[24,10.6]],"id":52385896},{"atb":[[540,0.44],[640,0.16]],"id":52385890},{"atb":[[12,9.5],[8.8,31.27]],"id":52385892},{"atb":[[280,0.87],[380,0.27]],"id":52385900},{"atb":[[3.25,108.4],[3.75,38]],"id":52385886},{"atb":[[3.95,82.67],[4.9,26.8]],"id":52385882},{"atb":[[550,0.59],[650,0.2]],"id":52385897},{"atb":[[12,9.5],[8.8,31.27]],"id":52385893},{"atb":[[260,0.94],[360,0.29]],"id":52385899},{"atb":[[550,0.59],[650,0.2]],"id":52385901}],"con":true,"img":false}]}
{"op":"mcm","clk":"11449703788","pt":1717313734151,"mc":[{"id":"1.229554912","rc":[{"atb":[[4.8,0],[3.9,0]],"id":52385910},{"atb":[[150,0],[250,0]],"id":52385912},{"atb":[[8.6,0],[11.5,0]],"id":52385918},{"atb":[[3.95,0],[4.9,0]],"id":52385887},{"atb":[[5.3,0],[6.6,0]],"id":52385889},{"atb":[[6.8,0],[8.8,0]],"id":52385914},{"atb":[[16,0],[22,0]],"id":52385883},{"atb":[[3.2,0],[3.7,0]],"id":52385885},{"atb":[[10,0],[15,0]],"id":52385894},{"atb":[[38,0],[24,0]],"id":52385896},{"atb":[[12,0],[8.8,0]],"id":52385929},{"atb":[[540,0],[640,0]],"id":52385890},{"atb":[[12,0],[8.8,0]],"id":52385892},{"atb":[[10,0],[15,0]],"id":52385925},{"atb":[[280,0],[380,0]],"id":52385900},{"atb":[[11,0],[8.4,0]],"id":52385911},{"atb":[[3.25,0],[3.75,0]],"id":52385886},{"atb":[[260,0],[160,0]],"id":52385919},{"atb":[[6.8,0],[8.8,0]],"id":52385921},{"atb":[[3.95,0],[4.9,0]],"id":52385882},{"atb":[[11,0],[8.4,0]],"id":52385915},{"atb":[[4.8,0],[3.9,0]],"id":52385917},{"atb":[[540,0],[640,0]],"id":52385926},{"atb":[[12,0],[8.8,0]],"id":52385928},{"atb":[[550,0.14],[650,0.04]],"id":52385897},{"atb":[[8.6,0],[11.5,0]],"id":52385922},{"atb":[[5.3,0],[6.6,0]],"id":52385924},{"atb":[[12,0],[8.8,0]],"id":52385893},{"atb":[[260,0],[360,0]],"id":52385899},{"atb":[[550,0.14],[650,0.04]],"id":52385901}],"con":true,"img":false}]}
{"op":"mcm","clk":"11449706177","pt":1717313763450,"mc":[{"id":"1.229554912","rc":[{"atb":[[4.8,27.5],[3.9,84.1]],"id":52385910},{"atb":[[340,0.3],[240,1.02]],"id":52385912},{"atb":[[8.6,32.09],[11.5,9.95]],"id":52385918},{"atb":[[3.95,82.67],[4.9,26.8]],"id":52385887},{"atb":[[5.3,56.72],[6.6,18.66]],"id":52385889},{"atb":[[6.8,42.05],[8.8,13.4]],"id":52385914},{"atb":[[17,15.24],[24,4.54]],"id":52385883},{"atb":[[3.2,110.86],[3.7,38.71]],"id":52385885},{"atb":[[10,27.1],[15,7.46]],"id":52385894},{"atb":[[46,2.32],[28,9.03]],"id":52385896},{"atb":[[12,9.5],[8.8,31.27]],"id":52385929},{"atb":[[550,0.44],[650,0.16]],"id":52385890},{"atb":[[12,9.5],[8.8,31.27]],"id":52385892},{"atb":[[10,27.1],[15,7.46]],"id":52385925},{"atb":[[390,0.62],[490,0.21]],"id":52385900},{"atb":[[11,10.45],[8.4,32.96]],"id":52385911},{"atb":[[3.25,108.4],[3.75,38]],"id":52385886},{"atb":[[260,0.94],[360,0.29]],"id":52385919},{"atb":[[6.8,42.05],[8.8,13.4]],"id":52385921},{"atb":[[3.95,82.67],[4.9,26.8]],"id":52385882},{"atb":[[11,10.45],[8.4,32.96]],"id":52385915},{"atb":[[4.8,27.5],[3.9,84.1]],"id":52385917},{"atb":[[550,0.44],[650,0.16]],"id":52385926},{"atb":[[12,9.5],[8.8,31.27]],"id":52385928},{"atb":[[550,0.59],[650,0.2]],"id":52385897},{"atb":[[8.6,32.09],[11.5,9.95]],"id":52385922},{"atb":[[5.3,56.72],[6.6,18.66]],"id":52385924},{"atb":[[12,9.5],[8.8,31.27]],"id":52385893},{"atb":[[370,0.65],[470,0.22]],"id":52385899},{"atb":[[550,0.59],[650,0.2]],"id":52385901}],"con":true,"img":false}]}
{"op":"mcm","clk":"11449714651","pt":1717313859074,"mc":[{"id":"1.229554912","rc":[{"atb":[[16.5,0],[19,0],[23,0],[14,0]],"id":52385918},{"atb":[[34,0],[44,0],[22,0],[27,0]],"id":52385925},{"atb":[[17,0],[12,0],[9.8,0],[14.5,0]],"id":52385911},{"atb":[[17,0],[19.5,0],[12,0],[14.5,0]],"id":52385921}],"con":true,"img":false}]}
{"op":"mcm","clk":"11449714709","pt":1717313859794,"mc":[{"id":"1.229554912","rc":[{"atb":[[17,4.9],[19.5,2.83],[24,1.14],[14.5,7.75]],"id":52385918},{"atb":[[36,1.5],[46,0.58],[23,4.76],[28,2.91]],"id":52385925},{"atb":[[16.5,1.69],[9.6,12.17],[11.5,7.48],[14,4.02]],"id":52385911},{"atb":[[17.5,3.17],[20,1.38],[12.5,9.1],[15,5.6]],"id":52385921}],"con":true,"img":false}]}
{"op":"mcm","clk":"11449716968","pt":1717313886283,"mc":[{"id":"1.229554912","rc":[{"atb":[[170,0],[85,0],[220,0],[120,0]],"id":52385912},{"atb":[[70,0],[38,0],[48,0],[29,0]],"id":52385883},{"atb":[[6.4,0],[5.2,0],[5.7,0],[4.7,0]],"id":52385885},{"atb":[[170,0],[85,0],[220,0],[120,0]],"id":52385896},{"atb":[[270,0],[320,0],[370,0],[220,0]],"id":52385890},{"atb":[[300,0],[350,0],[400,0],[450,0]],"id":52385900},{"atb":[[170,0],[85,0],[220,0],[120,0]],"id":52385919},{"atb":[[270,0],[320,0],[370,0],[220,0]],"id":52385926},{"atb":[[550,0.44],[600,0],[650,0.16],[500,0]],"id":52385897},{"atb":[[290,0],[340,0],[390,0],[440,0]],"id":52385899},{"atb":[[550,0.44],[600,0],[650,0.16],[500,0]],"id":52385901}],"con":true,"img":false}]}
{"op":"mcm","clk":"11449717021","pt":1717313887008,"mc":[{"id":"1.229554912","rc":[{"atb":[[140,0.57],[190,0.28],[95,1.11],[240,1.13]],"id":52385912},{"atb":[[75,0.36],[40,2.01],[50,1.07],[30,3.61]],"id":52385883},{"atb":[[5.6,11.37],[5.1,19.14],[4.6,29.07],[6.2,5.03]],"id":52385885},{"atb":[[140,0.57],[190,0.28],[95,1.11],[240,0.11]],"id":52385896},{"atb":[[300,0.26],[350,0.15],[400,0.07],[250,0.42]],"id":52385890},{"atb":[[360,0.29],[410,0.19],[460,0.12],[510,0.05]],"id":52385900},{"atb":[[140,0.57],[190,0.28],[95,1.11],[240,0.11]],"id":52385919},{"atb":[[300,0.26],[350,0.15],[400,0.07],[250,0.42]],"id":52385926},{"atb":[[570,0.18],[620,0.13],[670,0.08],[720,0.04]],"id":52385897},{"atb":[[350,0.3],[400,0.2],[450,0.12],[500,0.05]],"id":52385899},{"atb":[[570,0.18],[620,0.13],[670,0.08],[720,0.04]],"id":52385901}],"con":true,"img":false}]}
{"op":"mcm","clk":"11449747805","pt":1717314220761,"mc":[{"id":"1.229554912","rc":[{"atb":[[17.5,0],[20,0],[25,0],[30,0]],"id":52385922}],"con":true,"img":false}]}
{"op":"mcm","clk":"11449747888","pt":1717314221577,"mc":[{"id":"1.229554912","rc":[{"atb":[[32,0.84],[18,6.15],[21,3.92],[26,2.09]],"id":52385922}],"con":true,"img":false}]}
{"op":"mcm","clk":"11449766663","pt":1717314431839,"mc":[{"id":"1.229554912","rc":[{"atb":[[4.8,0],[3.9,0]],"id":52385910},{"atb":[[340,0],[240,0.11]],"id":52385912},{"atb":[[8.6,0],[11.5,0]],"id":52385918},{"atb":[[3.95,0],[4.9,0]],"id":52385887},{"atb":[[5.3,0],[6.6,0]],"id":52385889},{"atb":[[6.8,0],[8.8,0]],"id":52385914},{"atb":[[17,0],[24,0]],"id":52385883},{"atb":[[3.2,0],[3.7,0]],"id":52385885},{"atb":[[10,0],[15,0]],"id":52385894},{"atb":[[46,0],[28,0]],"id":52385896},{"atb":[[12,0],[8.8,0]],"id":52385929},{"atb":[[550,0],[650,0]],"id":52385890},{"atb":[[12,0],[8.8,0]],"id":52385892},{"atb":[[10,0],[15,0]],"id":52385925},{"atb":[[390,0],[490,0]],"id":52385900},{"atb":[[11,0],[8.4,0]],"id":52385911},{"atb":[[3.25,0],[3.75,0]],"id":52385886},{"atb":[[260,0],[360,0]],"id":52385919},{"atb":[[6.8,0],[8.8,0]],"id":52385921},{"atb":[[3.95,0],[4.9,0]],"id":52385882},{"atb":[[11,0],[8.4,0]],"id":52385915},{"atb":[[4.8,0],[3.9,0]],"id":52385917},{"atb":[[550,0],[650,0]],"id":52385926},{"atb":[[12,0],[8.8,0]],"id":52385928},{"atb":[[550,0],[650,0]],"id":52385897},{"atb":[[8.6,0],[11.5,0]],"id":52385922},{"atb":[[5.3,0],[6.6,0]],"id":52385924},{"atb":[[12,0],[8.8,0]],"id":52385893},{"atb":[[370,0],[470,0]],"id":52385899},{"atb":[[550,0],[650,0]],"id":52385901}],"con":true,"img":false}]}
{"op":"mcm","clk":"11449768892","pt":1717314457509,"mc":[{"id":"1.229554912","rc":[{"atb":[[4.8,27.5],[3.9,84.1]],"id":52385910},{"atb":[[340,0.3],[240,1.13]],"id":52385912},{"atb":[[8.6,32.09],[11.5,9.95]],"id":52385918},{"atb":[[6.8,42.05],[8.8,13.4]],"id":52385914},{"atb":[[12,9.5],[8.8,31.27]],"id":52385929},{"atb":[[10,27.1],[15,7.46]],"id":52385925},{"atb":[[11,10.45],[8.4,32.96]],"id":52385911},{"atb":[[260,0.94],[360,0.29]],"id":52385919},{"atb":[[6.8,42.05],[8.8,13.4]],"id":52385921},{"atb":[[11,10.45],[8.4,32.96]],"id":52385915},{"atb":[[4.8,27.5],[3.9,84.1]],"id":52385917},{"atb":[[550,0.44],[650,0.16]],"id":52385926},{"atb":[[12,9.5],[8.8,31.27]],"id":52385928},{"atb":[[8.6,32.09],[11.5,9.95]],"id":52385922},{"atb":[[5.3,56.72],[6.6,18.66]],"id":52385924}],"con":true,"img":false}]}
{"op":"mcm","clk":"11449768900","pt":1717314457618,"mc":[{"id":"1.229554912","rc":[{"atb":[[3.95,82.67],[4.9,26.8]],"id":52385887},{"atb":[[5.3,56.72],[6.6,18.66]],"id":52385889},{"atb":[[17,15.24],[24,4.54]],"id":52385883},{"atb":[[3.2,110.86],[3.7,38.71]],"id":52385885},{"atb":[[10,27.1],[15,7.46]],"id":52385894},{"atb":[[46,2.32],[28,9.03]],"id":52385896},{"atb":[[550,0.44],[650,0.16]],"id":52385890},{"atb":[[12,9.5],[8.8,31.27]],"id":52385892},{"atb":[[390,0.62],[490,0.21]],"id":52385900},{"atb":[[3.25,108.4],[3.75,38]],"id":52385886},{"atb":[[3.95,82.67],[4.9,26.8]],"id":52385882},{"atb":[[550,0.44],[650,0.16]],"id":52385897},{"atb":[[12,9.5],[8.8,31.27]],"id":52385893},{"atb":[[370,0.65],[470,0.22]],"id":52385899},{"atb":[[550,0.44],[650,0.16]],"id":52385901}],"con":true,"img":false}]}
{"op":"mcm","clk":"11449777406","pt":1717314549702,"mc":[{"id":"1.229554912","rc":[{"atb":[[17,0],[19.5,0],[24,0],[14.5,0]],"id":52385918},{"atb":[[38,0],[48,0],[24,0],[29,0]],"id":52385894},{"atb":[[36,0],[46,0],[23,0],[28,0]],"id":52385925},{"atb":[[16.5,0],[9.6,0],[11.5,0],[14,0]],"id":52385911},{"atb":[[17.5,0],[20,0],[12.5,0],[15,0]],"id":52385921},{"atb":[[8.6,0],[5.8,0],[7.6,0],[6.6,0]],"id":52385882}],"con":true,"img":false}]}
{"op":"mcm","clk":"11449777474","pt":1717314550376,"mc":[{"id":"1.229554912","rc":[{"atb":[[16.5,5.06],[19,2.91],[23,1.19],[14,8.05]],"id":52385918},{"atb":[[38,1.41],[48,0.55],[24,4.55],[29,2.8]],"id":52385894},{"atb":[[34,1.59],[44,0.61],[22,4.98],[27,3.02]],"id":52385925},{"atb":[[17,1.64],[12,7.14],[9.8,11.89],[14.5,3.88]],"id":52385911},{"atb":[[17,3.27],[19.5,1.41],[12,9.51],[14.5,5.81]],"id":52385921},{"atb":[[8.6,3.44],[5.8,21.8],[7.6,7.93],[6.6,14.02]],"id":52385882}],"con":true,"img":false}]}
{"op":"mcm","clk":"11449777798","pt":1717314554005,"mc":[{"id":"1.229554912","rc":[{"atb":[[17,0],[12,0],[9.8,0],[14.5,0]],"id":52385911}],"con":true,"img":false}]}
{"op":"mcm","clk":"11449777808","pt":1717314554104,"mc":[{"id":"1.229554912","rc":[{"atb":[[16.5,0],[19,0],[23,0],[14,0]],"id":52385918},{"atb":[[34,0],[44,0],[22,0],[27,0]],"id":52385925},{"atb":[[17,0],[19.5,0],[12,0],[14.5,0]],"id":52385921}],"con":true,"img":false}]}
{"op":"mcm","clk":"11449777867","pt":1717314554728,"mc":[{"id":"1.229554912","rc":[{"atb":[[16.5,1.69],[9.6,12.17],[11.5,7.48],[14,4.02]],"id":52385911}],"con":true,"img":false}]}
{"op":"mcm","clk":"11449777879","pt":1717314554784,"mc":[{"id":"1.229554912","rc":[{"atb":[[17.5,3.17],[20,1.38],[12.5,9.1],[15,5.6]],"id":52385921}],"con":true,"img":false}]}
{"op":"mcm","clk":"11449777891","pt":1717314554888,"mc":[{"id":"1.229554912","rc":[{"atb":[[17,4.9],[19.5,2.83],[24,1.14],[14.5,7.75]],"id":52385918},{"atb":[[36,1.5],[46,0.58],[23,4.76],[28,2.91]],"id":52385925}],"con":true,"img":false}]}
{"op":"mcm","clk":"11449782625","pt":1717314612085,"mc":[{"id":"1.229554912","rc":[{"atb":[[140,0],[190,0],[95,0],[240,0]],"id":52385919}],"con":true,"img":false}]}
{"op":"mcm","clk":"11449782687","pt":1717314612811,"mc":[{"id":"1.229554912","rc":[{"atb":[[150,0.53],[200,0.26],[100,1.06],[250,0.1]],"id":52385919}],"con":true,"img":false}]}
{"op":"mcm","clk":"11449785783","pt":1717314651778,"mc":[{"id":"1.229554912","rc":[{"atb":[[150,0],[200,0],[100,0],[250,0]],"id":52385919},{"atb":[[32,0],[18,0],[21,0],[26,0]],"id":52385922}],"con":true,"img":false}]}
{"op":"mcm","clk":"11449785832","pt":1717314652495,"mc":[{"id":"1.229554912","rc":[{"atb":[[140,0.57],[190,0.28],[95,1.11],[240,0.11]],"id":52385919},{"atb":[[17.5,6.34],[20,4.13],[25,2.18],[30,0.9]],"id":52385922}],"con":true,"img":false}]}
{"op":"mcm","clk":"11449851235","pt":1717315295993,"mc":[{"id":"1.229554912","rc":[{"atb":[[4.8,0],[3.9,0]],"id":52385910},{"atb":[[340,0],[240,0.11]],"id":52385912},{"atb":[[8.6,0],[11.5,0]],"id":52385918},{"atb":[[3.95,0],[4.9,0]],"id":52385887},{"atb":[[5.3,0],[6.6,0]],"id":52385889},{"atb":[[6.8,0],[8.8,0]],"id":52385914},{"atb":[[17,0],[24,0]],"id":52385883},{"atb":[[3.2,0],[3.7,0]],"id":52385885},{"atb":[[10,0],[15,0]],"id":52385894},{"atb":[[46,0],[28,0]],"id":52385896},{"atb":[[12,0],[8.8,0]],"id":52385929},{"atb":[[550,0],[650,0]],"id":52385890},{"atb":[[12,0],[8.8,0]],"id":52385892},{"atb":[[10,0],[15,0]],"id":52385925},{"atb":[[390,0],[490,0]],"id":52385900},{"atb":[[11,0],[8.4,0]],"id":52385911},{"atb":[[3.25,0],[3.75,0]],"id":52385886},{"atb":[[260,0],[360,0]],"id":52385919},{"atb":[[6.8,0],[8.8,0]],"id":52385921},{"atb":[[3.95,0],[4.9,0]],"id":52385882},{"atb":[[11,0],[8.4,0]],"id":52385915},{"atb":[[4.8,0],[3.9,0]],"id":52385917},{"atb":[[550,0],[650,0]],"id":52385926},{"atb":[[12,0],[8.8,0]],"id":52385928},{"atb":[[550,0],[650,0]],"id":52385897},{"atb":[[8.6,0],[11.5,0]],"id":52385922},{"atb":[[5.3,0],[6.6,0]],"id":52385924},{"atb":[[12,0],[8.8,0]],"id":52385893},{"atb":[[370,0],[470,0]],"id":52385899},{"atb":[[550,0],[650,0]],"id":52385901}],"con":true,"img":false}]}
{"op":"mcm","clk":"11449854732","pt":1717315331455,"mc":[{"id":"1.229554912","rc":[{"atb":[[3.95,82.67],[4.9,26.8]],"id":52385887},{"atb":[[5.3,56.72],[6.6,18.66]],"id":52385889},{"atb":[[17,15.24],[24,4.54]],"id":52385883},{"atb":[[3.2,110.86],[3.7,38.71]],"id":52385885},{"atb":[[10,27.1],[15,7.46]],"id":52385894},{"atb":[[46,2.32],[28,9.03]],"id":52385896},{"atb":[[550,0.44],[650,0.16]],"id":52385890},{"atb":[[12,9.5],[8.8,31.27]],"id":52385892},{"atb":[[390,0.62],[490,0.21]],"id":52385900},{"atb":[[3.25,108.4],[3.75,38]],"id":52385886},{"atb":[[3.95,82.67],[4.9,26.8]],"id":52385882},{"atb":[[550,0.44],[650,0.16]],"id":52385897},{"atb":[[12,9.5],[8.8,31.27]],"id":52385893},{"atb":[[370,0.65],[470,0.22]],"id":52385899},{"atb":[[550,0.44],[650,0.16]],"id":52385901}],"con":true,"img":false}]}
{"op":"mcm","clk":"11449855885","pt":1717315342157,"mc":[{"id":"1.229554912","rc":[{"atb":[[4.8,27.5],[3.9,84.1]],"id":52385910},{"atb":[[340,0.3],[240,1.13]],"id":52385912},{"atb":[[8.6,32.09],[11.5,9.95]],"id":52385918},{"atb":[[6.8,42.05],[8.8,13.4]],"id":52385914},{"atb":[[12,9.5],[8.8,31.27]],"id":52385929},{"atb":[[10,27.1],[15,7.46]],"id":52385925},{"atb":[[11,10.45],[8.4,32.96]],"id":52385911},{"atb":[[260,0.94],[360,0.29]],"id":52385919},{"atb":[[6.8,42.05],[8.8,13.4]],"id":52385921},{"atb":[[11,10.45],[8.4,32.96]],"id":52385915},{"atb":[[4.8,27.5],[3.9,84.1]],"id":52385917},{"atb":[[550,0.44],[650,0.16]],"id":52385926},{"atb":[[12,9.5],[8.8,31.27]],"id":52385928},{"atb":[[8.6,32.09],[11.5,9.95]],"id":52385922},{"atb":[[5.3,56.72],[6.6,18.66]],"id":52385924}],"con":true,"img":false}]}
{"op":"mcm","clk":"11449883429","pt":1717315612465,"mc":[{"id":"1.229554912","rc":[{"atb":[[140,0],[190,0],[95,0],[240,0]],"id":52385919}],"con":true,"img":false}]}
{"op":"mcm","clk":"11449883514","pt":1717315613157,"mc":[{"id":"1.229554912","rc":[{"atb":[[150,0.53],[200,0.26],[100,1.06],[250,0.1]],"id":52385919}],"con":true,"img":false}]}
{"op":"mcm","clk":"11449884975","pt":1717315626961,"mc":[{"id":"1.229554912","rc":[{"atb":[[150,0],[200,0],[100,0],[250,0]],"id":52385919}],"con":true,"img":false}]}
{"op":"mcm","clk":"11449885046","pt":1717315627689,"mc":[{"id":"1.229554912","rc":[{"atb":[[140,0.57],[190,0.28],[95,1.11],[240,0.11]],"id":52385919}],"con":true,"img":false}]}
{"op":"mcm","clk":"11449886040","pt":1717315637592,"mc":[{"id":"1.229554912","rc":[{"atb":[[140,0],[190,0],[95,0],[240,0]],"id":52385919}],"con":true,"img":false}]}
{"op":"mcm","clk":"11449886113","pt":1717315638272,"mc":[{"id":"1.229554912","rc":[{"atb":[[140,0.57],[190,0.28],[95,1.11],[240,0.11]],"id":52385919}],"con":true,"img":false}]}
{"op":"mcm","clk":"11449888066","pt":1717315657618,"mc":[{"id":"1.229554912","rc":[{"atb":[[140,0],[190,0],[95,0],[240,1.02]],"id":52385912},{"atb":[[5.6,0],[5.1,0],[4.6,0],[6.2,0]],"id":52385885},{"atb":[[140,0],[190,0],[95,0],[240,0]],"id":52385896},{"atb":[[300,0],[350,0],[400,0],[250,0]],"id":52385890},{"atb":[[360,0],[410,0],[460,0],[510,0]],"id":52385900},{"atb":[[300,0],[350,0],[400,0],[250,0]],"id":52385926},{"atb":[[350,0],[400,0],[450,0],[500,0]],"id":52385899}],"con":true,"img":false}]}
{"op":"mcm","clk":"11449888131","pt":1717315658290,"mc":[{"id":"1.229554912","rc":[{"atb":[[130,0.61],[180,0.29],[90,1.18],[230,0.12]],"id":52385912},{"atb":[[6.4,4.84],[5.2,18.68],[5.7,11.13],[4.7,28.28]],"id":52385885},{"atb":[[150,0.53],[200,0.26],[100,1.06],[250,0.1]],"id":52385896},{"atb":[[290,0.27],[340,0.15],[390,0.07],[240,0.44]],"id":52385890},{"atb":[[350,0.3],[400,0.2],[450,0.12],[500,0.05]],"id":52385900},{"atb":[[290,0.27],[340,0.15],[390,0.07],[240,0.44]],"id":52385926},{"atb":[[340,0.31],[390,0.2],[440,0.12],[490,0.05]],"id":52385899}],"con":true,"img":false}]}
{"op":"mcm","clk":"11449897644","pt":1717315749690,"mc":[{"id":"1.229554912","rc":[{"atb":[[17,0],[19.5,0],[24,0],[14.5,0]],"id":52385918},{"atb":[[38,0],[48,0],[24,0],[29,0]],"id":52385894},{"atb":[[36,0],[46,0],[23,0],[28,0]],"id":52385925},{"atb":[[16.5,0],[9.6,0],[11.5,0],[14,0]],"id":52385911},{"atb":[[17.5,0],[20,0],[12.5,0],[15,0]],"id":52385921},{"atb":[[8.6,0],[5.8,0],[7.6,0],[6.6,0]],"id":52385882}],"con":true,"img":false}]}
{"op":"mcm","clk":"11449897718","pt":1717315750367,"mc":[{"id":"1.229554912","rc":[{"atb":[[16.5,5.06],[19,2.91],[23,1.19],[14,8.05]],"id":52385918},{"atb":[[38,1.41],[48,0.55],[24,4.55],[29,2.8]],"id":52385894},{"atb":[[34,1.59],[44,0.61],[22,4.98],[27,3.02]],"id":52385925},{"atb":[[17,1.64],[12,7.14],[9.8,11.89],[14.5,3.88]],"id":52385911},{"atb":[[17,3.27],[19.5,1.41],[12,9.51],[14.5,5.81]],"id":52385921},{"atb":[[8.6,3.44],[5.8,21.8],[7.6,7.93],[6.6,14.02]],"id":52385882}],"con":true,"img":false}]}
{"op":"mcm","clk":"11449898449","pt":1717315757095,"mc":[{"id":"1.229554912","rc":[{"atb":[[17,0],[12,0],[9.8,0],[14.5,0]],"id":52385911}],"con":true,"img":false}]}
{"op":"mcm","clk":"11449900623","pt":1717315778029,"mc":[{"id":"1.229554912","rc":[{"atb":[[16.5,1.69],[9.6,12.17],[11.5,7.48],[14,4.02]],"id":52385911}],"con":true,"img":false}]}
{"op":"mcm","clk":"11449936825","pt":1717316137930,"mc":[{"id":"1.229554912","rc":[{"atb":[[4.8,0],[3.9,0]],"id":52385910},{"atb":[[340,0],[240,0]],"id":52385912},{"atb":[[8.6,0],[11.5,0]],"id":52385918},{"atb":[[3.95,0],[4.9,0]],"id":52385887},{"atb":[[5.3,0],[6.6,0]],"id":52385889},{"atb":[[6.8,0],[8.8,0]],"id":52385914},{"atb":[[17,0],[24,0]],"id":52385883},{"atb":[[3.2,0],[3.7,0]],"id":52385885},{"atb":[[10,0],[15,0]],"id":52385894},{"atb":[[46,0],[28,0]],"id":52385896},{"atb":[[12,0],[8.8,0]],"id":52385929},{"atb":[[550,0],[650,0]],"id":52385890},{"atb":[[12,0],[8.8,0]],"id":52385892},{"atb":[[10,0],[15,0]],"id":52385925},{"atb":[[390,0],[490,0]],"id":52385900},{"atb":[[11,0],[8.4,0]],"id":52385911},{"atb":[[3.25,0],[3.75,0]],"id":52385886},{"atb":[[260,0],[360,0]],"id":52385919},{"atb":[[6.8,0],[8.8,0]],"id":52385921},{"atb":[[3.95,0],[4.9,0]],"id":52385882},{"atb":[[11,0],[8.4,0]],"id":52385915},{"atb":[[4.8,0],[3.9,0]],"id":52385917},{"atb":[[550,0],[650,0]],"id":52385926},{"atb":[[12,0],[8.8,0]],"id":52385928},{"atb":[[550,0],[650,0]],"id":52385897},{"atb":[[8.6,0],[11.5,0]],"id":52385922},{"atb":[[5.3,0],[6.6,0]],"id":52385924},{"atb":[[12,0],[8.8,0]],"id":52385893},{"atb":[[370,0],[470,0]],"id":52385899},{"atb":[[550,0],[650,0]],"id":52385901}],"con":true,"img":false}]}
{"op":"mcm","clk":"11449939385","pt":1717316165470,"mc":[{"id":"1.229554912","rc":[{"atb":[[4.8,27.5],[3.9,84.1]],"id":52385910},{"atb":[[340,0.3],[240,1.02]],"id":52385912},{"atb":[[8.6,32.09],[11.5,9.95]],"id":52385918},{"atb":[[3.95,82.67],[4.9,26.8]],"id":52385887},{"atb":[[5.3,56.72],[6.6,18.66]],"id":52385889},{"atb":[[6.8,42.05],[8.8,13.4]],"id":52385914},{"atb":[[17,15.24],[24,4.54]],"id":52385883},{"atb":[[3.2,110.86],[3.7,38.71]],"id":52385885},{"atb":[[10,27.1],[15,7.46]],"id":52385894},{"atb":[[46,2.32],[28,9.03]],"id":52385896},{"atb":[[12,9.5],[8.8,31.27]],"id":52385929},{"atb":[[550,0.44],[650,0.16]],"id":52385890},{"atb":[[12,9.5],[8.8,31.27]],"id":52385892},{"atb":[[10,27.1],[15,7.46]],"id":52385925},{"atb":[[390,0.62],[490,0.21]],"id":52385900},{"atb":[[11,10.45],[8.4,32.96]],"id":52385911},{"atb":[[3.25,108.4],[3.75,38]],"id":52385886},{"atb":[[260,0.94],[360,0.29]],"id":52385919},{"atb":[[6.8,42.05],[8.8,13.4]],"id":52385921},{"atb":[[3.95,82.67],[4.9,26.8]],"id":52385882},{"atb":[[11,10.45],[8.4,32.96]],"id":52385915},{"atb":[[4.8,27.5],[3.9,84.1]],"id":52385917},{"atb":[[550,0.44],[650,0.16]],"id":52385926},{"atb":[[12,9.5],[8.8,31.27]],"id":52385928},{"atb":[[550,0.44],[650,0.16]],"id":52385897},{"atb":[[8.6,32.09],[11.5,9.95]],"id":52385922},{"atb":[[5.3,56.72],[6.6,18.66]],"id":52385924},{"atb":[[12,9.5],[8.8,31.27]],"id":52385893},{"atb":[[370,0.65],[470,0.22]],"id":52385899},{"atb":[[550,0.44],[650,0.16]],"id":52385901}],"con":true,"img":false}]}
{"op":"mcm","clk":"11449941955","pt":1717316192393,"mc":[{"id":"1.229554912","rc":[{"atb":[[4.8,0],[3.9,0]],"id":52385910},{"atb":[[340,0],[240,0]],"id":52385912},{"atb":[[8.6,0],[11.5,0]],"id":52385918},{"atb":[[3.95,0],[4.9,0]],"id":52385887},{"atb":[[5.3,0],[6.6,0]],"id":52385889},{"atb":[[6.8,0],[8.8,0]],"id":52385914},{"atb":[[17,0],[24,0]],"id":52385883},{"atb":[[3.2,0],[3.7,0]],"id":52385885},{"atb":[[10,0],[15,0]],"id":52385894},{"atb":[[46,0],[28,0]],"id":52385896},{"atb":[[12,0],[8.8,0]],"id":52385929},{"atb":[[550,0],[650,0]],"id":52385890},{"atb":[[12,0],[8.8,0]],"id":52385892},{"atb":[[10,0],[15,0]],"id":52385925},{"atb":[[390,0],[490,0]],"id":52385900},{"atb":[[11,0],[8.4,0]],"id":52385911},{"atb":[[3.25,0],[3.75,0]],"id":52385886},{"atb":[[260,0],[360,0]],"id":52385919},{"atb":[[6.8,0],[8.8,0]],"id":52385921},{"atb":[[3.95,0],[4.9,0]],"id":52385882},{"atb":[[11,0],[8.4,0]],"id":52385915},{"atb":[[4.8,0],[3.9,0]],"id":52385917},{"atb":[[550,0],[650,0]],"id":52385926},{"atb":[[12,0],[8.8,0]],"id":52385928},{"atb":[[550,0],[650,0]],"id":52385897},{"atb":[[8.6,0],[11.5,0]],"id":52385922},{"atb":[[5.3,0],[6.6,0]],"id":52385924},{"atb":[[12,0],[8.8,0]],"id":52385893},{"atb":[[370,0],[470,0]],"id":52385899},{"atb":[[550,0],[650,0]],"id":52385901}],"con":true,"img":false}]}
{"op":"mcm","clk":"11449942980","pt":1717316203690,"mc":[{"id":"1.229554912","rc":[{"atb":[[4.8,27.5],[3.9,84.1]],"id":52385910},{"atb":[[340,0.3],[240,1.02]],"id":52385912},{"atb":[[8.6,32.09],[11.5,9.95]],"id":52385918},{"atb":[[3.95,82.67],[4.9,26.8]],"id":52385887},{"atb":[[5.3,56.72],[6.6,18.66]],"id":52385889},{"atb":[[6.8,42.05],[8.8,13.4]],"id":52385914},{"atb":[[17,15.24],[24,4.54]],"id":52385883},{"atb":[[3.2,110.86],[3.7,38.71]],"id":52385885},{"atb":[[10,27.1],[15,7.46]],"id":52385894},{"atb":[[46,2.32],[28,9.03]],"id":52385896},{"atb":[[12,9.5],[8.8,31.27]],"id":52385929},{"atb":[[550,0.44],[650,0.16]],"id":52385890},{"atb":[[12,9.5],[8.8,31.27]],"id":52385892},{"atb":[[10,27.1],[15,7.46]],"id":52385925},{"atb":[[390,0.62],[490,0.21]],"id":52385900},{"atb":[[11,10.45],[8.4,32.96]],"id":52385911},{"atb":[[3.25,108.4],[3.75,38]],"id":52385886},{"atb":[[260,0.94],[360,0.29]],"id":52385919},{"atb":[[6.8,42.05],[8.8,13.4]],"id":52385921},{"atb":[[3.95,82.67],[4.9,26.8]],"id":52385882},{"atb":[[11,10.45],[8.4,32.96]],"id":52385915},{"atb":[[4.8,27.5],[3.9,84.1]],"id":52385917},{"atb":[[550,0.44],[650,0.16]],"id":52385926},{"atb":[[12,9.5],[8.8,31.27]],"id":52385928},{"atb":[[550,0.44],[650,0.16]],"id":52385897},{"atb":[[8.6,32.09],[11.5,9.95]],"id":52385922},{"atb":[[5.3,56.72],[6.6,18.66]],"id":52385924},{"atb":[[12,9.5],[8.8,31.27]],"id":52385893},{"atb":[[370,0.65],[470,0.22]],"id":52385899},{"atb":[[550,0.44],[650,0.16]],"id":52385901}],"con":true,"img":false}]}
{"op":"mcm","clk":"11449950456","pt":1717316289118,"mc":[{"id":"1.229554912","rc":[{"atb":[[16.5,0],[19,0],[23,0],[14,0]],"id":52385918},{"atb":[[34,0],[44,0],[22,0],[27,0]],"id":52385925},{"atb":[[17,0],[19.5,0],[12,0],[14.5,0]],"id":52385921}],"con":true,"img":false}]}
{"op":"mcm","clk":"11449950510","pt":1717316289837,"mc":[{"id":"1.229554912","rc":[{"atb":[[17,4.9],[19.5,2.83],[24,1.14],[14.5,7.75]],"id":52385918},{"atb":[[36,1.5],[46,0.58],[23,4.76],[28,2.91]],"id":52385925},{"atb":[[17.5,3.17],[12.5,9.1],[15,5.6]],"id":52385921}],"con":true,"img":false}]}
{"op":"mcm","clk":"11449950518","pt":1717316289891,"mc":[{"id":"1.229554912","rc":[{"atb":[[20,1.38]],"id":52385921}],"con":true,"img":false}]}
{"op":"mcm","clk":"11449998611","pt":1717316929745,"mc":[{"id":"1.229554912","rc":[{"atb":[[6.4,0],[7.4,0],[8.4,0],[9.4,0]],"id":52385887}],"con":true,"img":false}]}
{"op":"mcm","clk":"11449998669","pt":1717316930412,"mc":[{"id":"1.229554912","rc":[{"atb":[[7.2,12.66],[9.2,3.19],[6.2,20.12],[8.2,7.27]],"id":52385887}],"con":true,"img":false}]}
{"op":"mcm","clk":"11450003956","pt":1717316992244,"mc":[{"id":"1.229554912","rc":[{"atb":[[4.8,0],[3.9,0]],"id":52385910},{"atb":[[340,0],[240,0]],"id":52385912},{"atb":[[8.6,0],[11.5,0]],"id":52385918},{"atb":[[3.95,0],[4.9,0]],"id":52385887},{"atb":[[5.3,0],[6.6,0]],"id":52385889},{"atb":[[6.8,0],[8.8,0]],"id":52385914},{"atb":[[17,0],[24,0]],"id":52385883},{"atb":[[3.2,0],[3.7,0]],"id":52385885},{"atb":[[10,0],[15,0]],"id":52385894},{"atb":[[46,0],[28,0]],"id":52385896},{"atb":[[12,0],[8.8,0]],"id":52385929},{"atb":[[550,0],[650,0]],"id":52385890},{"atb":[[12,0],[8.8,0]],"id":52385892},{"atb":[[10,0],[15,0]],"id":52385925},{"atb":[[390,0],[490,0]],"id":52385900},{"atb":[[11,0],[8.4,0]],"id":52385911},{"atb":[[3.25,0],[3.75,0]],"id":52385886},{"atb":[[260,0],[360,0]],"id":52385919},{"atb":[[6.8,0],[8.8,0]],"id":52385921},{"atb":[[3.95,0],[4.9,0]],"id":52385882},{"atb":[[11,0],[8.4,0]],"id":52385915},{"atb":[[4.8,0],[3.9,0]],"id":52385917},{"atb":[[550,0],[650,0]],"id":52385926},{"atb":[[12,0],[8.8,0]],"id":52385928},{"atb":[[550,0],[650,0]],"id":52385897},{"atb":[[8.6,0],[11.5,0]],"id":52385922},{"atb":[[5.3,0],[6.6,0]],"id":52385924},{"atb":[[12,0],[8.8,0]],"id":52385893},{"atb":[[370,0],[470,0]],"id":52385899},{"atb":[[550,0],[650,0]],"id":52385901}],"con":true,"img":false}]}
{"op":"mcm","clk":"11450007767","pt":1717317031597,"mc":[{"id":"1.229554912","rc":[{"atb":[[4.8,27.5],[3.9,84.1]],"id":52385910},{"atb":[[340,0.3],[240,1.02]],"id":52385912},{"atb":[[8.6,32.09],[11.5,9.95]],"id":52385918},{"atb":[[3.95,82.67],[4.9,26.8]],"id":52385887},{"atb":[[5.3,56.72],[6.6,18.66]],"id":52385889},{"atb":[[6.8,42.05],[8.8,13.4]],"id":52385914},{"atb":[[17,15.24],[24,4.54]],"id":52385883},{"atb":[[3.2,110.86],[3.7,38.71]],"id":52385885},{"atb":[[10,27.1],[15,7.46]],"id":52385894},{"atb":[[46,2.32],[28,9.03]],"id":52385896},{"atb":[[12,9.5],[8.8,31.27]],"id":52385929},{"atb":[[550,0.44],[650,0.16]],"id":52385890},{"atb":[[12,9.5],[8.8,31.27]],"id":52385892},{"atb":[[10,27.1],[15,7.46]],"id":52385925},{"atb":[[390,0.62],[490,0.21]],"id":52385900},{"atb":[[11,10.45],[8.4,32.96]],"id":52385911},{"atb":[[3.25,108.4],[3.75,38]],"id":52385886},{"atb":[[260,0.94],[360,0.29]],"id":52385919},{"atb":[[6.8,42.05],[8.8,13.4]],"id":52385921},{"atb":[[3.95,82.67],[4.9,26.8]],"id":52385882},{"atb":[[11,10.45],[8.4,32.96]],"id":52385915},{"atb":[[4.8,27.5],[3.9,84.1]],"id":52385917},{"atb":[[550,0.44],[650,0.16]],"id":52385926},{"atb":[[12,9.5],[8.8,31.27]],"id":52385928},{"atb":[[550,0.44],[650,0.16]],"id":52385897},{"atb":[[8.6,32.09],[11.5,9.95]],"id":52385922},{"atb":[[5.3,56.72],[6.6,18.66]],"id":52385924},{"atb":[[12,9.5],[8.8,31.27]],"id":52385893},{"atb":[[370,0.65],[470,0.22]],"id":52385899},{"atb":[[550,0.44],[650,0.16]],"id":52385901}],"con":true,"img":false}]}
{"op":"mcm","clk":"11450028903","pt":1717317245529,"mc":[{"id":"1.229554912","rc":[{"atb":[[7.2,0],[9.2,0],[6.2,0],[8.2,0]],"id":52385887},{"atb":[[290,0],[340,0],[390,0],[240,0]],"id":52385890},{"atb":[[350,0],[400,0],[450,0],[500,0]],"id":52385900},{"atb":[[290,0],[340,0],[390,0],[240,0]],"id":52385926}],"con":true,"img":false}]}
{"op":"mcm","clk":"11450028970","pt":1717317246252,"mc":[{"id":"1.229554912","rc":[{"atb":[[6.4,19.38],[7.4,12.26],[8.4,7.07],[9.4,3.11]],"id":52385887},{"atb":[[280,0.28],[330,0.16],[380,0.07],[230,0.46]],"id":52385890},{"atb":[[360,0.29],[410,0.19],[460,0.12],[510,0.05]],"id":52385900},{"atb":[[280,0.28],[330,0.16],[380,0.07],[230,0.46]],"id":52385926}],"con":true,"img":false}]}
{"op":"mcm","clk":"11450029072","pt":1717317247450,"mc":[{"id":"1.229554912","rc":[{"atb":[[17,0],[19.5,0],[24,0],[14.5,0]],"id":52385918},{"atb":[[38,0],[48,0],[24,0],[29,0]],"id":52385894},{"atb":[[36,0],[46,0],[23,0],[28,0]],"id":52385925},{"atb":[[16.5,0],[9.6,0],[11.5,0],[14,0]],"id":52385911},{"atb":[[17.5,0],[20,0],[12.5,0],[15,0]],"id":52385921},{"atb":[[8.6,0],[5.8,0],[7.6,0],[6.6,0]],"id":52385882},{"atb":[[570,0],[620,0],[670,0],[720,0]],"id":52385897},{"atb":[[570,0],[620,0],[670,0],[720,0]],"id":52385901}],"con":true,"img":false}]}
{"op":"mcm","clk":"11450029149","pt":1717317248169,"mc":[{"id":"1.229554912","rc":[{"atb":[[16.5,5.06],[19,2.91],[23,1.19],[14,8.05]],"id":52385918},{"atb":[[38,1.41],[48,0.55],[24,4.55],[29,2.8]],"id":52385894},{"atb":[[34,1.59],[44,0.61],[22,4.98],[27,3.02]],"id":52385925},{"atb":[[17,1.64],[12,7.14],[9.8,11.89],[14.5,3.88]],"id":52385911},{"atb":[[17,3.27],[19.5,1.41],[12,9.51],[14.5,5.81]],"id":52385921},{"atb":[[8.6,3.44],[5.8,21.8],[7.6,7.93],[6.6,14.02]],"id":52385882},{"atb":[[560,0.19],[610,0.13],[660,0.08],[710,0.04]],"id":52385897},{"atb":[[560,0.19],[610,0.13],[660,0.08],[710,0.04]],"id":52385901}],"con":true,"img":false}]}
{"op":"mcm","clk":"11450029483","pt":1717317251643,"mc":[{"id":"1.229554912","rc":[{"atb":[[16.5,0],[19,0],[23,0],[14,0]],"id":52385918},{"atb":[[34,0],[44,0],[22,0],[27,0]],"id":52385925},{"atb":[[17,0],[12,0],[9.8,0],[14.5,0]],"id":52385911},{"atb":[[17,0],[19.5,0],[12,0],[14.5,0]],"id":52385921}],"con":true,"img":false}]}
{"op":"mcm","clk":"11450030125","pt":1717317258067,"mc":[{"id":"1.229554912","rc":[{"atb":[[17,4.9],[19.5,2.83],[24,1.14],[14.5,7.75]],"id":52385918},{"atb":[[36,1.5],[46,0.58],[23,4.76],[28,2.91]],"id":52385925},{"atb":[[16.5,1.69],[9.6,12.17],[11.5,7.48],[14,4.02]],"id":52385911},{"atb":[[17.5,3.17],[20,1.38],[12.5,9.1],[15,5.6]],"id":52385921}],"con":true,"img":false}]}
{"op":"mcm","clk":"11450041561","pt":1717317364373,"mc":[{"id":"1.229554912","rc":[{"atb":[[130,0],[180,0],[90,0],[230,0]],"id":52385912},{"atb":[[280,0],[330,0],[380,0],[230,0]],"id":52385890},{"atb":[[4.8,0],[5.8,0],[5.3,0],[6.6,0]],"id":52385886},{"atb":[[7.2,0],[9.2,0],[10.5,0],[8.2,0]],"id":52385917},{"atb":[[280,0],[330,0],[380,0],[230,0]],"id":52385926},{"atb":[[560,0],[610,0],[660,0],[710,0]],"id":52385897},{"atb":[[560,0],[610,0],[660,0],[710,0]],"id":52385901}],"con":true,"img":false}]}
{"op":"mcm","clk":"11450041635","pt":1717317365088,"mc":[{"id":"1.229554912","rc":[{"atb":[[170,0.31],[85,1.25],[220,0.12],[120,0.66]],"id":52385912},{"atb":[[270,0.29],[320,0.16],[370,0.07],[220,0.48]],"id":52385890},{"atb":[[6.8,4.51],[4.9,26.83],[5.9,10.68],[5.4,17.84]],"id":52385886},{"atb":[[11,2.62],[7.4,16.35],[8.4,10.61],[9.4,6.23]],"id":52385917},{"atb":[[270,0.29],[320,0.16],[370,0.07],[220,0.48]],"id":52385926},{"atb":[[550,0.63],[600,0.13],[650,0.24],[700,0.04]],"id":52385897}],"con":true,"img":false}]}
{"op":"mcm","clk":"11450041644","pt":1717317365145,"mc":[{"id":"1.229554912","rc":[{"atb":[[550,0.63],[600,0.13],[650,0.24],[700,0.04]],"id":52385901}],"con":true,"img":false}]}
{"op":"mcm","clk":"11450053117","pt":1717317477183,"mc":[{"id":"1.229554912","rc":[{"atb":[[360,0],[410,0],[460,0],[510,0]],"id":52385900}],"con":true,"img":false}]}
{"op":"mcm","clk":"11450053167","pt":1717317477850,"mc":[{"id":"1.229554912","rc":[{"atb":[[350,0.3],[400,0.2],[450,0.12],[500,0.05]],"id":52385900}],"con":true,"img":false}]}
{"op":"mcm","clk":"11450053404","pt":1717317480394,"mc":[{"id":"1.229554912","rc":[{"atb":[[4.8,53.82]],"id":52385910},{"atl":[[360,2]],"id":52385910},{"atb":[[110,2]],"id":52385912},{"atb":[[14.5,15.16]],"id":52385918},{"atb":[[1.35,31.65]],"id":52385887},{"atl":[[300,2]],"id":52385887},{"atb":[[8.2,13.89]],"id":52385889},{"atl":[[460,2]],"id":52385889},{"atb":[[10,11.11]],"id":52385914},{"atl":[[480,2]],"id":52385914},{"atb":[[36,2.86]],"id":52385883},{"atb":[[3.15,46.51]],"id":52385885},{"atl":[[210,2]],"id":52385885},{"atb":[[24,8.9]],"id":52385894},{"atb":[[120,2]],"id":52385896},{"atb":[[17,6.25]],"id":52385929},{"atb":[[190,2]],"id":52385890},{"atb":[[16.5,6.45]],"id":52385892},{"atb":[[24,4.35]],"id":52385925},{"atb":[[240,2]],"id":52385900},{"atb":[[14,11.5]],"id":52385911},{"atb":[[3.2,44.67]],"id":52385886},{"atl":[[220,2]],"id":52385886},{"atb":[[110,2]],"id":52385919},{"atb":[[10,11.11]],"id":52385921},{"atb":[[4.5,28.57]],"id":52385882},{"atl":[[300,2]],"id":52385882},{"atb":[[14,7.69]],"id":52385915},{"atb":[[4.9,25.64]],"id":52385917},{"atl":[[380,2]],"id":52385917},{"atb":[[190,2]],"id":52385926},{"atb":[[16.5,6.45]],"id":52385928},{"atb":[[350,2]],"id":52385897},{"atb":[[14.5,7.41]],"id":52385922},{"atb":[[1.35,19.04]],"id":52385924},{"atb":[[17,6.25]],"id":52385893},{"atb":[[240,2]],"id":52385899},{"atb":[[350,2]],"id":52385901}],"con":true,"img":false}]}
{"op":"mcm","clk":"11450053870","pt":1717317485471,"mc":[{"id":"1.229554912","rc":[{"atb":[[13.5,8],[14,4.02]],"id":52385911}],"con":true,"img":false}]}
{"op":"mcm","clk":"11450056661","pt":1717317517514,"mc":[{"id":"1.229554912","rc":[{"atb":[[13.5,0],[14,11.5]],"id":52385911}],"con":true,"img":false}]}
{"op":"mcm","clk":"11450063886","pt":1717317597698,"mc":[{"id":"1.229554912","rc":[{"atb":[[4.8,26.32],[3.9,0]],"id":52385910},{"atb":[[340,0],[240,0]],"id":52385912},{"atb":[[8.6,0],[11.5,0]],"id":52385918},{"atb":[[3.95,0],[4.9,0]],"id":52385887},{"atb":[[5.3,0],[6.6,0]],"id":52385889},{"atb":[[6.8,0],[8.8,0]],"id":52385914},{"atb":[[17,0],[24,0]],"id":52385883},{"atb":[[3.2,0],[3.7,0]],"id":52385885},{"atb":[[10,0],[15,0]],"id":52385894},{"atb":[[46,0],[28,0]],"id":52385896},{"atb":[[12,0],[8.8,0]],"id":52385929},{"atb":[[550,0],[650,0]],"id":52385890},{"atb":[[12,0],[8.8,0]],"id":52385892},{"atb":[[10,0],[15,0]],"id":52385925},{"atb":[[390,0],[490,0]],"id":52385900},{"atb":[[11,0],[8.4,0]],"id":52385911},{"atb":[[3.25,0],[3.75,0]],"id":52385886},{"atb":[[260,0],[360,0]],"id":52385919},{"atb":[[6.8,0],[8.8,0]],"id":52385921},{"atb":[[3.95,0],[4.9,0]],"id":52385882},{"atb":[[11,0],[8.4,0]],"id":52385915},{"atb":[[4.8,0],[3.9,0]],"id":52385917},{"atb":[[550,0],[650,0]],"id":52385926},{"atb":[[12,0],[8.8,0]],"id":52385928},{"atb":[[550,0.19],[650,0.08]],"id":52385897},{"atb":[[8.6,0],[11.5,0]],"id":52385922},{"atb":[[5.3,0],[6.6,0]],"id":52385924},{"atb":[[12,0],[8.8,0]],"id":52385893},{"atb":[[370,0],[470,0]],"id":52385899},{"atb":[[550,0.19],[650,0.08]],"id":52385901}],"con":true,"img":false}]}
{"op":"mcm","clk":"11450066172","pt":1717317622833,"mc":[{"id":"1.229554912","rc":[{"atb":[[4.8,53.82],[3.9,84.1]],"id":52385910},{"atb":[[340,0.3],[240,1.02]],"id":52385912},{"atb":[[8.6,32.09],[11.5,9.95]],"id":52385918},{"atb":[[3.95,82.67],[4.9,26.8]],"id":52385887},{"atb":[[5.3,56.72],[6.6,18.66]],"id":52385889},{"atb":[[6.8,42.05],[8.8,13.4]],"id":52385914},{"atb":[[17,15.24],[24,4.54]],"id":52385883},{"atb":[[3.2,110.86],[3.7,38.71]],"id":52385885},{"atb":[[10,27.1],[15,7.46]],"id":52385894},{"atb":[[46,2.32],[28,9.03]],"id":52385896},{"atb":[[12,9.5],[8.8,31.27]],"id":52385929},{"atb":[[550,0.44],[650,0.16]],"id":52385890},{"atb":[[12,9.5],[8.8,31.27]],"id":52385892},{"atb":[[10,27.1],[15,7.46]],"id":52385925},{"atb":[[390,0.62],[490,0.21]],"id":52385900},{"atb":[[11,10.45],[8.4,32.96]],"id":52385911},{"atb":[[3.25,108.4],[3.75,38]],"id":52385886},{"atb":[[260,0.94],[360,0.29]],"id":52385919},{"atb":[[6.8,42.05],[8.8,13.4]],"id":52385921},{"atb":[[3.95,82.67],[4.9,26.8]],"id":52385882},{"atb":[[11,10.45],[8.4,32.96]],"id":52385915},{"atb":[[4.8,27.5],[3.9,84.1]],"id":52385917},{"atb":[[550,0.44],[650,0.16]],"id":52385926},{"atb":[[12,9.5],[8.8,31.27]],"id":52385928},{"atb":[[550,0.63],[650,0.24]],"id":52385897},{"atb":[[8.6,32.09],[11.5,9.95]],"id":52385922},{"atb":[[5.3,56.72],[6.6,18.66]],"id":52385924},{"atb":[[12,9.5],[8.8,31.27]],"id":52385893},{"atb":[[370,0.65],[470,0.22]],"id":52385899},{"atb":[[550,0.63],[650,0.24]],"id":52385901}],"con":true,"img":false}]}
{"op":"mcm","clk":"11450077139","pt":1717317742256,"mc":[{"id":"1.229554912","rc":[{"atb":[[170,0],[85,0],[220,0],[120,0]],"id":52385912},{"atb":[[270,0],[320,0],[370,0],[220,0]],"id":52385890},{"atb":[[270,0],[320,0],[370,0],[220,0]],"id":52385926},{"atb":[[550,0.44],[600,0],[650,0.16],[700,0]],"id":52385897}],"con":true,"img":false}]}
{"op":"mcm","clk":"11450077159","pt":1717317742450,"mc":[{"id":"1.229554912","rc":[{"atb":[[550,0.44],[600,0],[650,0.16],[700,0]],"id":52385901}],"con":true,"img":false}]}
{"op":"mcm","clk":"11450077215","pt":1717317742913,"mc":[{"id":"1.229554912","rc":[{"atb":[[130,0.61],[180,0.29],[90,1.18],[230,0.12]],"id":52385912},{"atb":[[280,0.28],[330,0.16],[380,0.07],[230,0.46]],"id":52385890},{"atb":[[280,0.28],[330,0.16],[380,0.07],[230,0.46]],"id":52385926},{"atb":[[560,0.19],[610,0.13],[660,0.08],[710,0.04]],"id":52385897}],"con":true,"img":false}]}
{"op":"mcm","clk":"11450077237","pt":1717317743117,"mc":[{"id":"1.229554912","rc":[{"atb":[[660,0.08]],"id":52385901}],"con":true,"img":false}]}
{"op":"mcm","clk":"11450077245","pt":1717317743228,"mc":[{"id":"1.229554912","rc":[{"atb":[[560,0.19],[610,0.13],[710,0.04]],"id":52385901}],"con":true,"img":false}]}
{"op":"mcm","clk":"11450081033","pt":1717317785342,"mc":[{"id":"1.229554912","rc":[{"atb":[[130,0]],"id":52385912},{"atb":[[75,0],[40,0],[50,0],[30,0]],"id":52385883},{"atb":[[150,0],[200,0],[100,0],[250,0]],"id":52385896},{"atb":[[140,0],[190,0],[95,0],[240,0]],"id":52385919},{"atb":[[340,0],[390,0],[440,0],[490,0]],"id":52385899},{"atb":[[560,0],[610,0],[660,0],[710,0]],"id":52385901}],"con":true,"img":false}]}
{"op":"mcm","clk":"11450081048","pt":1717317785548,"mc":[{"id":"1.229554912","rc":[{"atb":[[25,4.17]],"id":52385883},{"atb":[[46,4.54],[120,0]],"id":52385896}],"con":true,"img":false}]}
{"op":"mcm","clk":"11450081056","pt":1717317785651,"mc":[{"id":"1.229554912","rc":[{"atb":[[36,0]],"id":52385883}],"con":true,"img":false}]}
{"op":"mcm","clk":"11450081094","pt":1717317786065,"mc":[{"id":"1.229554912","rc":[{"atb":[[140,0.57]],"id":52385912},{"atb":[[32,3.37],[80,0.33],[42,1.92],[55,0.97]],"id":52385883},{"atb":[[270,0.1],[170,0.47],[220,0.24],[120,0.88]],"id":52385896},{"atb":[[260,1.04],[160,0.49],[210,0.25],[110,2.96]],"id":52385919},{"atb":[[540,0.05],[390,0.27],[440,0.18],[490,0.1]],"id":52385899},{"atb":[[640,0.16],[690,0.12],[740,0.07],[790,0.03]],"id":52385901}],"con":true,"img":false}]}
{"op":"mcm","clk":"11450083952","pt":1717317819644,"mc":[{"id":"1.229554912","rc":[{"atb":[[38,2.7]],"id":52385883},{"atb":[[130,2]],"id":52385896}],"con":true,"img":false}]}
{"op":"mcm","clk":"11450083959","pt":1717317819747,"mc":[{"id":"1.229554912","rc":[{"atb":[[25,0]],"id":52385883},{"atb":[[46,2.32]],"id":52385896}],"con":true,"img":false}]}
{"op":"mcm","clk":"11450101205","pt":1717318020878,"mc":[{"id":"1.229554912","rc":[{"atb":[[6.4,0],[7.4,0],[8.4,0],[9.4,0]],"id":52385887},{"atb":[[6.8,0],[4.9,0],[5.9,0],[5.4,0]],"id":52385886}],"con":true,"img":false}]}
{"op":"mcm","clk":"11450101257","pt":1717318021561,"mc":[{"id":"1.229554912","rc":[{"atb":[[7.2,12.66],[9.2,3.19],[6.2,20.12],[8.2,7.27]],"id":52385887},{"atb":[[4.8,27.54],[5.8,10.9],[5.3,18.25],[6.6,4.67]],"id":52385886}],"con":true,"img":false}]}
{"op":"mcm","clk":"11450104907","pt":1717318060524,"mc":[{"id":"1.229554912","rc":[{"atb":[[4.8,26.32],[3.9,0]],"id":52385910},{"atb":[[340,0],[240,0]],"id":52385912},{"atb":[[8.6,0],[11.5,0]],"id":52385918},{"atb":[[3.95,0],[4.9,0]],"id":52385887},{"atb":[[5.3,0],[6.6,0]],"id":52385889},{"atb":[[6.8,0],[8.8,0]],"id":52385914},{"atb":[[17,0],[24,0]],"id":52385883},{"atb":[[3.2,0],[3.7,0]],"id":52385885},{"atb":[[10,0],[15,0]],"id":52385894},{"atb":[[46,0],[28,0]],"id":52385896},{"atb":[[12,0],[8.8,0]],"id":52385929},{"atb":[[550,0],[650,0]],"id":52385890},{"atb":[[12,0],[8.8,0]],"id":52385892},{"atb":[[10,0],[15,0]],"id":52385925},{"atb":[[390,0],[490,0]],"id":52385900},{"atb":[[11,0],[8.4,0]],"id":52385911},{"atb":[[3.25,0],[3.75,0]],"id":52385886},{"atb":[[260,0.1],[360,0]],"id":52385919},{"atb":[[6.8,0],[8.8,0]],"id":52385921},{"atb":[[3.95,0],[4.9,0]],"id":52385882},{"atb":[[11,0],[8.4,0]],"id":52385915},{"atb":[[4.8,0],[3.9,0]],"id":52385917},{"atb":[[550,0],[650,0]],"id":52385926},{"atb":[[12,0],[8.8,0]],"id":52385928},{"atb":[[550,0],[650,0]],"id":52385897},{"atb":[[8.6,0],[11.5,0]],"id":52385922},{"atb":[[5.3,0],[6.6,0]],"id":52385924},{"atb":[[12,0],[8.8,0]],"id":52385893},{"atb":[[370,0],[470,0]],"id":52385899},{"atb":[[550,0],[650,0]],"id":52385901}],"con":true,"img":false}]}
{"op":"mcm","clk":"11450106956","pt":1717318082448,"mc":[{"id":"1.229554912","rc":[{"atb":[[180,0],[90,0],[230,0]],"id":52385912},{"atb":[[280,0],[330,0],[380,0],[230,0]],"id":52385890},{"atb":[[280,0],[330,0],[380,0],[230,0]],"id":52385926},{"atb":[[560,0],[610,0],[660,0],[710,0]],"id":52385897}],"con":true,"img":false}]}
{"op":"mcm","clk":"11450107020","pt":1717318083132,"mc":[{"id":"1.229554912","rc":[{"atb":[[190,0.28],[95,1.11],[240,0.11]],"id":52385912},{"atb":[[260,0.4],[310,0.26],[360,0.15],[410,0.06]],"id":52385890},{"atb":[[260,0.4],[310,0.26],[360,0.15],[410,0.06]],"id":52385926},{"atb":[[640,0.16],[690,0.12],[740,0.07],[790,0.03]],"id":52385897}],"con":true,"img":false}]}
{"op":"mcm","clk":"11450107630","pt":1717318089760,"mc":[{"id":"1.229554912","rc":[{"atb":[[4.8,53.82],[3.9,84.1]],"id":52385910},{"atb":[[340,0.3],[240,1.13]],"id":52385912},{"atb":[[8.6,32.09],[11.5,9.95]],"id":52385918},{"atb":[[3.95,82.67],[4.9,26.8]],"id":52385887},{"atb":[[5.3,56.72],[6.6,18.66]],"id":52385889},{"atb":[[6.8,42.05],[8.8,13.4]],"id":52385914},{"atb":[[17,15.24],[24,4.54]],"id":52385883},{"atb":[[3.2,110.86],[3.7,38.71]],"id":52385885},{"atb":[[10,27.1],[15,7.46]],"id":52385894},{"atb":[[46,2.32],[28,9.03]],"id":52385896},{"atb":[[12,9.5],[8.8,31.27]],"id":52385929},{"atb":[[550,0.44],[650,0.16]],"id":52385890},{"atb":[[12,9.5],[8.8,31.27]],"id":52385892},{"atb":[[10,27.1],[15,7.46]],"id":52385925},{"atb":[[390,0.62],[490,0.21]],"id":52385900},{"atb":[[11,10.45],[8.4,32.96]],"id":52385911},{"atb":[[3.25,108.4],[3.75,38]],"id":52385886},{"atb":[[260,1.04],[360,0.29]],"id":52385919},{"atb":[[6.8,42.05],[8.8,13.4]],"id":52385921},{"atb":[[3.95,82.67],[4.9,26.8]],"id":52385882},{"atb":[[11,10.45],[8.4,32.96]],"id":52385915},{"atb":[[4.8,27.5],[3.9,84.1]],"id":52385917},{"atb":[[550,0.44],[650,0.16]],"id":52385926},{"atb":[[12,9.5],[8.8,31.27]],"id":52385928},{"atb":[[550,0.44],[650,0.16]],"id":52385897},{"atb":[[8.6,32.09],[11.5,9.95]],"id":52385922},{"atb":[[5.3,56.72],[6.6,18.66]],"id":52385924},{"atb":[[12,9.5],[8.8,31.27]],"id":52385893},{"atb":[[370,0.65],[470,0.22]],"id":52385899},{"atb":[[550,0.44],[650,0.16]],"id":52385901}],"con":true,"img":false}]}
{"op":"mcm","clk":"11450115083","pt":1717318173359,"mc":[{"id":"1.229554912","rc":[{"atb":[[140,0],[190,0],[95,0],[240,1.02]],"id":52385912},{"atb":[[260,0],[310,0],[360,0],[410,0]],"id":52385890},{"atb":[[260,0],[310,0],[360,0],[410,0]],"id":52385926},{"atb":[[640,0],[690,0],[740,0],[790,0]],"id":52385897},{"atb":[[540,0],[390,0],[440,0],[490,0]],"id":52385899},{"atb":[[640,0],[690,0],[740,0],[790,0]],"id":52385901}],"con":true,"img":false}]}
{"op":"mcm","clk":"11450115148","pt":1717318174033,"mc":[{"id":"1.229554912","rc":[{"atb":[[150,0.53],[200,0.26],[100,1.06],[250,0.1]],"id":52385912},{"atb":[[270,0.39],[320,0.25],[370,0.14],[420,0.06]],"id":52385890},{"atb":[[270,0.39],[320,0.25],[370,0.14],[420,0.06]],"id":52385926},{"atb":[[650,0.32],[700,0.11],[750,0.07],[800,0.03]],"id":52385897},{"atb":[[550,0.05],[400,0.26],[450,0.17],[500,0.1]],"id":52385899},{"atb":[[650,0.32],[700,0.11],[750,0.07],[800,0.03]],"id":52385901}],"con":true,"img":false}]}
{"op":"mcm","clk":"11450115589","pt":1717318179724,"mc":[{"id":"1.229554912","rc":[{"atb":[[150,0],[200,0],[100,0],[250,0]],"id":52385912},{"atb":[[270,0],[320,0],[370,0],[420,0]],"id":52385890},{"atb":[[270,0],[320,0],[370,0],[420,0]],"id":52385926},{"atb":[[650,0.16],[700,0],[750,0],[800,0]],"id":52385897},{"atb":[[550,0],[400,0],[450,0],[500,0]],"id":52385899},{"atb":[[650,0.16],[700,0],[750,0],[800,0]],"id":52385901}],"con":true,"img":false}]}
{"op":"mcm","clk":"11450115653","pt":1717318180451,"mc":[{"id":"1.229554912","rc":[{"atb":[[140,0.57],[190,0.28],[95,1.11],[240,1.13]],"id":52385912},{"atb":[[260,0.4],[310,0.26],[360,0.15],[410,0.06]],"id":52385890},{"atb":[[260,0.4],[310,0.26],[360,0.15],[410,0.06]],"id":52385926},{"atb":[[640,0.16],[690,0.12],[740,0.07],[790,0.03]],"id":52385897},{"atb":[[540,0.05],[390,0.27],[440,0.18],[490,0.1]],"id":52385899},{"atb":[[640,0.16],[690,0.12],[740,0.07],[790,0.03]],"id":52385901}],"con":true,"img":false}]}
{"op":"mcm","clk":"11450137034","pt":1717318427983,"mc":[{"id":"1.229554912","rc":[{"atb":[[4.8,26.32],[3.9,0]],"id":52385910},{"atb":[[340,0],[240,0.11]],"id":52385912},{"atb":[[8.6,0],[11.5,0]],"id":52385918},{"atb":[[3.95,0],[4.9,0]],"id":52385887},{"atb":[[5.3,0],[6.6,0]],"id":52385889},{"atb":[[6.8,0],[8.8,0]],"id":52385914},{"atb":[[17,0],[24,0]],"id":52385883},{"atb":[[3.2,0],[3.7,0]],"id":52385885},{"atb":[[10,0],[15,0]],"id":52385894},{"atb":[[46,0],[28,0]],"id":52385896},{"atb":[[12,0],[8.8,0]],"id":52385929},{"atb":[[550,0],[650,0]],"id":52385890},{"atb":[[12,0],[8.8,0]],"id":52385892},{"atb":[[10,0],[15,0]],"id":52385925},{"atb":[[390,0],[490,0]],"id":52385900},{"atb":[[11,0],[8.4,0]],"id":52385911},{"atb":[[3.25,0],[3.75,0]],"id":52385886},{"atb":[[260,0.1],[360,0]],"id":52385919},{"atb":[[6.8,0],[8.8,0]],"id":52385921},{"atb":[[3.95,0],[4.9,0]],"id":52385882},{"atb":[[11,0],[8.4,0]],"id":52385915},{"atb":[[4.8,0],[3.9,0]],"id":52385917},{"atb":[[550,0],[650,0]],"id":52385926},{"atb":[[12,0],[8.8,0]],"id":52385928},{"atb":[[550,0],[650,0]],"id":52385897},{"atb":[[8.6,0],[11.5,0]],"id":52385922},{"atb":[[5.3,0],[6.6,0]],"id":52385924},{"atb":[[12,0],[8.8,0]],"id":52385893},{"atb":[[370,0],[470,0]],"id":52385899},{"atb":[[550,0],[650,0]],"id":52385901}],"con":true,"img":false}]}
{"op":"mcm","clk":"11450138390","pt":1717318442568,"mc":[{"id":"1.229554912","rc":[{"atb":[[3.95,82.67],[4.9,26.8]],"id":52385887},{"atb":[[5.3,56.72],[6.6,18.66]],"id":52385889},{"atb":[[17,15.24],[24,4.54]],"id":52385883},{"atb":[[3.2,110.86],[3.7,38.71]],"id":52385885},{"atb":[[10,27.1],[15,7.46]],"id":52385894},{"atb":[[46,2.32],[28,9.03]],"id":52385896},{"atb":[[550,0.44],[650,0.16]],"id":52385890},{"atb":[[12,9.5],[8.8,31.27]],"id":52385892},{"atb":[[390,0.62],[490,0.21]],"id":52385900},{"atb":[[3.25,108.4],[3.75,38]],"id":52385886},{"atb":[[3.95,82.67],[4.9,26.8]],"id":52385882},{"atb":[[550,0.44],[650,0.16]],"id":52385897},{"atb":[[12,9.5],[8.8,31.27]],"id":52385893},{"atb":[[370,0.65],[470,0.22]],"id":52385899},{"atb":[[550,0.44],[650,0.16]],"id":52385901}],"con":true,"img":false}]}
{"op":"mcm","clk":"11450138825","pt":1717318447985,"mc":[{"id":"1.229554912","rc":[{"atb":[[17,0],[19.5,0],[24,0],[14.5,7.41]],"id":52385918},{"atb":[[38,0],[48,0],[24,4.35],[29,0]],"id":52385894},{"atb":[[36,0],[46,0],[23,0],[28,0]],"id":52385925},{"atb":[[16.5,0],[9.6,0],[11.5,0],[14,7.48]],"id":52385911},{"atb":[[17.5,0],[20,0],[12.5,0],[15,0]],"id":52385921},{"atb":[[8.6,0],[5.8,0],[7.6,0],[6.6,0]],"id":52385882}],"con":true,"img":false}]}
{"op":"mcm","clk":"11450138842","pt":1717318448197,"mc":[{"id":"1.229554912","rc":[{"atb":[[24,0],[15.5,6.9]],"id":52385894}],"con":true,"img":false}]}
{"op":"mcm","clk":"11450138887","pt":1717318448713,"mc":[{"id":"1.229554912","rc":[{"atb":[[16.5,5.06],[19,2.91],[23,1.19],[14,8.05]],"id":52385918},{"atb":[[38,1.41],[48,0.55],[24,4.55],[29,2.8]],"id":52385894},{"atb":[[34,1.59],[44,0.61],[22,4.98],[27,3.02]],"id":52385925},{"atb":[[17,1.64],[12,7.14],[9.8,11.89],[14.5,3.88]],"id":52385911},{"atb":[[17,3.27],[19.5,1.41],[12,9.51],[14.5,5.81]],"id":52385921},{"atb":[[8.6,3.44],[5.8,21.8],[7.6,7.93],[6.6,14.02]],"id":52385882}],"con":true,"img":false}]}
{"op":"mcm","clk":"11450139265","pt":1717318453310,"mc":[{"id":"1.229554912","rc":[{"atb":[[4.8,53.82],[3.9,84.1]],"id":52385910},{"atb":[[340,0.3],[240,1.13]],"id":52385912},{"atb":[[8.6,32.09],[11.5,9.95]],"id":52385918},{"atb":[[6.8,42.05],[8.8,13.4]],"id":52385914},{"atb":[[12,9.5],[8.8,31.27]],"id":52385929},{"atb":[[10,27.1],[15,7.46]],"id":52385925},{"atb":[[11,10.45],[8.4,32.96]],"id":52385911},{"atb":[[260,1.04],[360,0.29]],"id":52385919},{"atb":[[6.8,42.05],[8.8,13.4]],"id":52385921},{"atb":[[11,10.45],[8.4,32.96]],"id":52385915},{"atb":[[4.8,27.5],[3.9,84.1]],"id":52385917},{"atb":[[550,0.44],[650,0.16]],"id":52385926},{"atb":[[12,9.5],[8.8,31.27]],"id":52385928},{"atb":[[8.6,32.09],[11.5,9.95]],"id":52385922},{"atb":[[5.3,56.72],[6.6,18.66]],"id":52385924}],"con":true,"img":false}]}
{"op":"mcm","clk":"11450139372","pt":1717318454292,"mc":[{"id":"1.229554912","rc":[{"atb":[[16.5,0],[19,0],[23,0],[14,0]],"id":52385918},{"atb":[[34,0],[44,0],[22,0],[27,0]],"id":52385925},{"atb":[[17,0],[12,0],[9.8,0],[14.5,0]],"id":52385911},{"atb":[[17,0],[19.5,0],[12,0],[14.5,0]],"id":52385921}],"con":true,"img":false}]}
{"op":"mcm","clk":"11450139390","pt":1717318454502,"mc":[{"id":"1.229554912","rc":[{"atb":[[12,9.09],[14.5,0]],"id":52385918},{"atb":[[24,0],[15.5,6.9]],"id":52385925},{"atb":[[11.5,9.52],[14,0]],"id":52385911},{"atb":[[9,12.5],[10,0]],"id":52385921}],"con":true,"img":false}]}
{"op":"mcm","clk":"11450139439","pt":1717318455016,"mc":[{"id":"1.229554912","rc":[{"atb":[[17,4.9],[19.5,2.83],[24,1.14],[14.5,7.75]],"id":52385918},{"atb":[[36,1.5],[46,0.58],[23,4.76],[28,2.91]],"id":52385925},{"atb":[[16.5,1.69],[9.6,12.17],[11.5,17],[14,4.02]],"id":52385911},{"atb":[[17.5,3.17],[20,1.38],[12.5,9.1],[15,5.6]],"id":52385921}],"con":true,"img":false}]}
{"op":"mcm","clk":"11450139450","pt":1717318455071,"mc":[{"id":"1.229554912","rc":[{"atb":[[12,0],[14.5,15.16]],"id":52385918},{"atb":[[24,4.35],[15.5,0]],"id":52385925},{"atb":[[11.5,7.48],[14,11.71]],"id":52385911},{"atb":[[9,0],[10,11.11]],"id":52385921}],"con":true,"img":false}]}
{"op":"mcm","clk":"11450141263","pt":1717318475610,"mc":[{"id":"1.229554912","rc":[{"atb":[[24,8.9],[15.5,0]],"id":52385894}],"con":true,"img":false}]}
{"op":"mcm","clk":"11450148209","pt":1717318555526,"mc":[{"id":"1.229554912","rc":[{"atb":[[190,0]],"id":52385912},{"atb":[[260,0],[310,0],[410,0]],"id":52385890},{"atb":[[260,0],[310,0],[360,0],[410,0]],"id":52385926},{"atb":[[690,0],[740,0],[790,0]],"id":52385897},{"atb":[[540,0],[440,0],[490,0]],"id":52385899},{"atb":[[640,0],[690,0],[740,0],[790,0]],"id":52385901}],"con":true,"img":false}]}
{"op":"mcm","clk":"11450148274","pt":1717318556203,"mc":[{"id":"1.229554912","rc":[{"atb":[[190,0.28]],"id":52385912},{"atb":[[260,0.4],[310,0.26],[410,0.06]],"id":52385890},{"atb":[[260,0.4],[310,0.26],[360,0.15],[410,0.06]],"id":52385926},{"atb":[[690,0.12],[740,0.07],[790,0.03]],"id":52385897},{"atb":[[540,0.05],[440,0.18],[490,0.1]],"id":52385899},{"atb":[[640,0.16],[690,0.12],[740,0.07],[790,0.03]],"id":52385901}],"con":true,"img":false}]}
{"op":"mcm","clk":"11450159934","pt":1717318674446,"mc":[{"id":"1.229554912","rc":[{"atb":[[4.8,0],[5.8,0],[5.3,0],[6.6,0]],"id":52385886},{"atb":[[260,0.94],[160,0],[210,0],[110,2]],"id":52385919}],"con":true,"img":false}]}
{"op":"mcm","clk":"11450159943","pt":1717318674548,"mc":[{"id":"1.229554912","rc":[{"atb":[[3.3,43.48]],"id":52385886}],"con":true,"img":false}]}
{"op":"mcm","clk":"11450159952","pt":1717318674605,"mc":[{"id":"1.229554912","rc":[{"atb":[[3.2,0]],"id":52385886}],"con":true,"img":false}]}
{"op":"mcm","clk":"11450159996","pt":1717318675125,"mc":[{"id":"1.229554912","rc":[{"atb":[[6.8,4.51],[4.9,26.83],[5.9,10.68],[5.4,17.84]],"id":52385886},{"atb":[[270,0.1],[170,0.47],[220,0.24],[120,0.88]],"id":52385919}],"con":true,"img":false}]}
{"op":"mcm","clk":"11450160114","pt":1717318676204,"mc":[{"id":"1.229554912","rc":[{"atb":[[270,0],[170,0],[220,0],[120,0]],"id":52385919}],"con":true,"img":false}]}
{"op":"mcm","clk":"11450160180","pt":1717318676923,"mc":[{"id":"1.229554912","rc":[{"atb":[[260,1.04],[160,0.49],[210,0.25],[110,2.96]],"id":52385919}],"con":true,"img":false}]}
{"op":"mcm","clk":"11450171396","pt":1717318799673,"mc":[{"id":"1.229554912","rc":[{"atb":[[4.8,26.32],[3.9,0]],"id":52385910},{"atb":[[340,0],[240,0.11]],"id":52385912},{"atb":[[8.6,0],[11.5,0]],"id":52385918},{"atb":[[3.95,0],[4.9,0]],"id":52385887},{"atb":[[5.3,0],[6.6,0]],"id":52385889},{"atb":[[6.8,0],[8.8,0]],"id":52385914},{"atb":[[17,0],[24,0]],"id":52385883},{"atb":[[3.2,0],[3.7,0]],"id":52385885},{"atb":[[10,0],[15,0]],"id":52385894},{"atb":[[46,0],[28,0]],"id":52385896},{"atb":[[12,0],[8.8,0]],"id":52385929},{"atb":[[550,0],[650,0]],"id":52385890},{"atb":[[12,0],[8.8,0]],"id":52385892},{"atb":[[10,0],[15,0]],"id":52385925},{"atb":[[390,0],[490,0]],"id":52385900},{"atb":[[11,0],[8.4,0]],"id":52385911},{"atb":[[3.25,0],[3.75,0]],"id":52385886},{"atb":[[260,0.1],[360,0]],"id":52385919},{"atb":[[6.8,0],[8.8,0]],"id":52385921},{"atb":[[3.95,0],[4.9,0]],"id":52385882},{"atb":[[11,0],[8.4,0]],"id":52385915},{"atb":[[4.8,0],[3.9,0]],"id":52385917},{"atb":[[550,0],[650,0]],"id":52385926},{"atb":[[12,0],[8.8,0]],"id":52385928},{"atb":[[550,0],[650,0]],"id":52385897},{"atb":[[8.6,0],[11.5,0]],"id":52385922},{"atb":[[5.3,0],[6.6,0]],"id":52385924},{"atb":[[12,0],[8.8,0]],"id":52385893},{"atb":[[370,0],[470,0]],"id":52385899},{"atb":[[550,0],[650,0]],"id":52385901}],"con":true,"img":false}]}
{"op":"mcm","clk":"11450172943","pt":1717318814293,"mc":[{"id":"1.229554912","rc":[{"atb":[[190,0]],"id":52385912},{"atb":[[260,0],[310,0],[410,0]],"id":52385890},{"atb":[[260,0],[310,0],[360,0],[410,0]],"id":52385926},{"atb":[[540,0],[440,0],[490,0]],"id":52385899}],"con":true,"img":false}]}
{"op":"mcm","clk":"11450173043","pt":1717318815184,"mc":[{"id":"1.229554912","rc":[{"atb":[[200,0.26]],"id":52385912},{"atb":[[270,0.39],[320,0.25],[420,0.06]],"id":52385890},{"atb":[[270,0.39],[320,0.25],[370,0.14],[420,0.06]],"id":52385926},{"atb":[[550,0.05],[450,0.17],[500,0.1]],"id":52385899}],"con":true,"img":false}]}
{"op":"mcm","clk":"11450173210","pt":1717318816690,"mc":[{"id":"1.229554912","rc":[{"atb":[[3.95,82.67],[4.9,26.8]],"id":52385887},{"atb":[[5.3,56.72],[6.6,18.66]],"id":52385889},{"atb":[[17,15.24],[24,4.54]],"id":52385883},{"atb":[[3.2,110.86],[3.7,38.71]],"id":52385885},{"atb":[[10,27.1],[15,7.46]],"id":52385894},{"atb":[[46,2.32],[28,9.03]],"id":52385896},{"atb":[[550,0.44],[650,0.16]],"id":52385890},{"atb":[[12,9.5],[8.8,31.27]],"id":52385892},{"atb":[[390,0.62],[490,0.21]],"id":52385900},{"atb":[[3.25,108.4],[3.75,38]],"id":52385886},{"atb":[[3.95,82.67],[4.9,26.8]],"id":52385882},{"atb":[[550,0.44],[650,0.16]],"id":52385897},{"atb":[[12,9.5],[8.8,31.27]],"id":52385893},{"atb":[[370,0.65],[470,0.22]],"id":52385899},{"atb":[[550,0.44],[650,0.16]],"id":52385901}],"con":true,"img":false}]}
{"op":"mcm","clk":"11450174178","pt":1717318827324,"mc":[{"id":"1.229554912","rc":[{"atb":[[4.8,53.82],[3.9,84.1]],"id":52385910},{"atb":[[340,0.3],[240,1.13]],"id":52385912},{"atb":[[8.6,32.09],[11.5,9.95]],"id":52385918},{"atb":[[6.8,42.05],[8.8,13.4]],"id":52385914},{"atb":[[12,9.5],[8.8,31.27]],"id":52385929},{"atb":[[10,27.1],[15,7.46]],"id":52385925},{"atb":[[11,10.45],[8.4,32.96]],"id":52385911},{"atb":[[260,1.04],[360,0.29]],"id":52385919},{"atb":[[6.8,42.05],[8.8,13.4]],"id":52385921},{"atb":[[11,10.45],[8.4,32.96]],"id":52385915},{"atb":[[4.8,27.5],[3.9,84.1]],"id":52385917},{"atb":[[550,0.44],[650,0.16]],"id":52385926},{"atb":[[12,9.5],[8.8,31.27]],"id":52385928},{"atb":[[8.6,32.09],[11.5,9.95]],"id":52385922},{"atb":[[5.3,56.72],[6.6,18.66]],"id":52385924}],"con":true,"img":false}]}
{"op":"mcm","clk":"11450175714","pt":1717318844497,"mc":[{"id":"1.229554912","rc":[{"atb":[[200,0]],"id":52385912},{"atb":[[270,0],[320,0],[420,0]],"id":52385890},{"atb":[[270,0],[320,0],[370,0],[420,0]],"id":52385926},{"atb":[[550,0],[450,0],[500,0]],"id":52385899}],"con":true,"img":false}]}
{"op":"mcm","clk":"11450175775","pt":1717318845225,"mc":[{"id":"1.229554912","rc":[{"atb":[[200,0.26]],"id":52385912},{"atb":[[270,0.39],[320,0.25],[420,0.06]],"id":52385890},{"atb":[[270,0.39],[320,0.25],[370,0.14],[420,0.06]],"id":52385926},{"atb":[[550,0.05],[450,0.17],[500,0.1]],"id":52385899}],"con":true,"img":false}]}
{"op":"mcm","clk":"11450175838","pt":1717318845944,"mc":[{"id":"1.229554912","rc":[{"atb":[[200,0]],"id":52385912},{"atb":[[270,0],[320,0],[420,0]],"id":52385890},{"atb":[[270,0],[320,0],[370,0],[420,0]],"id":52385926},{"atb":[[550,0],[450,0],[500,0]],"id":52385899}],"con":true,"img":false}]}
{"op":"mcm","clk":"11450175904","pt":1717318846613,"mc":[{"id":"1.229554912","rc":[{"atb":[[190,0.28]],"id":52385912},{"atb":[[260,0.4],[310,0.26],[410,0.06]],"id":52385890},{"atb":[[260,0.4],[310,0.26],[360,0.15],[410,0.06]],"id":52385926},{"atb":[[540,0.05],[440,0.18],[490,0.1]],"id":52385899}],"con":true,"img":false}]}
{"op":"mcm","clk":"11450195579","pt":1717319052258,"mc":[{"id":"1.229554912","rc":[{"atb":[[260,0],[310,0],[360,0],[410,0]],"id":52385890},{"atb":[[260,0],[310,0],[360,0],[410,0]],"id":52385926},{"atb":[[640,0],[690,0],[740,0],[790,0]],"id":52385897},{"atb":[[640,0],[690,0],[740,0],[790,0]],"id":52385901}],"con":true,"img":false}]}
{"op":"mcm","clk":"11450195694","pt":1717319052981,"mc":[{"id":"1.229554912","rc":[{"atb":[[300,0.26],[350,0.15],[400,0.07],[250,0.42]],"id":52385890},{"atb":[[300,0.26],[350,0.15],[400,0.07],[250,0.42]],"id":52385926},{"atb":[[630,0.17],[680,0.12],[730,0.07],[780,0.03]],"id":52385897},{"atb":[[630,0.17],[680,0.12],[730,0.07],[780,0.03]],"id":52385901}],"con":true,"img":false}]}
{"op":"mcm","clk":"11450208375","pt":1717319182926,"mc":[{"id":"1.229554912","rc":[{"atb":[[4.8,26.32],[3.9,0]],"id":52385910},{"atb":[[340,0],[240,0.11]],"id":52385912},{"atb":[[8.6,0],[11.5,0]],"id":52385918},{"atb":[[3.95,0],[4.9,0]],"id":52385887},{"atb":[[5.3,0],[6.6,0]],"id":52385889},{"atb":[[6.8,0],[8.8,0]],"id":52385914},{"atb":[[17,0],[24,0]],"id":52385883},{"atb":[[3.2,0],[3.7,0]],"id":52385885},{"atb":[[10,0],[15,0]],"id":52385894},{"atb":[[46,0],[28,0]],"id":52385896},{"atb":[[12,0],[8.8,0]],"id":52385929},{"atb":[[550,0],[650,0]],"id":52385890},{"atb":[[12,0],[8.8,0]],"id":52385892},{"atb":[[10,0],[15,0]],"id":52385925},{"atb":[[390,0],[490,0]],"id":52385900},{"atb":[[11,0],[8.4,0]],"id":52385911},{"atb":[[3.25,0],[3.75,0]],"id":52385886},{"atb":[[260,0.1],[360,0]],"id":52385919},{"atb":[[6.8,0],[8.8,0]],"id":52385921},{"atb":[[3.95,0],[4.9,0]],"id":52385882},{"atb":[[11,0],[8.4,0]],"id":52385915},{"atb":[[4.8,0],[3.9,0]],"id":52385917},{"atb":[[550,0],[650,0]],"id":52385926},{"atb":[[12,0],[8.8,0]],"id":52385928},{"atb":[[550,0],[650,0]],"id":52385897},{"atb":[[8.6,0],[11.5,0]],"id":52385922},{"atb":[[5.3,0],[6.6,0]],"id":52385924},{"atb":[[12,0],[8.8,0]],"id":52385893},{"atb":[[370,0],[470,0]],"id":52385899},{"atb":[[550,0],[650,0]],"id":52385901}],"con":true,"img":false}]}
{"op":"mcm","clk":"11450211546","pt":1717319214150,"mc":[{"id":"1.229554912","rc":[{"atb":[[4.8,53.82],[3.9,84.1]],"id":52385910},{"atb":[[340,0.3],[240,1.13]],"id":52385912},{"atb":[[8.6,32.09],[11.5,9.95]],"id":52385918},{"atb":[[3.95,82.67],[4.9,26.8]],"id":52385887},{"atb":[[5.3,56.72],[6.6,18.66]],"id":52385889},{"atb":[[6.8,42.05],[8.8,13.4]],"id":52385914},{"atb":[[17,15.24],[24,4.54]],"id":52385883},{"atb":[[3.2,110.86],[3.7,38.71]],"id":52385885},{"atb":[[10,27.1],[15,7.46]],"id":52385894},{"atb":[[46,2.32],[28,9.03]],"id":52385896},{"atb":[[12,9.5],[8.8,31.27]],"id":52385929},{"atb":[[550,0.44],[650,0.16]],"id":52385890},{"atb":[[12,9.5],[8.8,31.27]],"id":52385892},{"atb":[[10,27.1],[15,7.46]],"id":52385925},{"atb":[[390,0.62],[490,0.21]],"id":52385900},{"atb":[[11,10.45],[8.4,32.96]],"id":52385911},{"atb":[[3.25,108.4],[3.75,38]],"id":52385886},{"atb":[[260,1.04],[360,0.29]],"id":52385919},{"atb":[[6.8,42.05],[8.8,13.4]],"id":52385921},{"atb":[[3.95,82.67],[4.9,26.8]],"id":52385882},{"atb":[[11,10.45],[8.4,32.96]],"id":52385915},{"atb":[[4.8,27.5],[3.9,84.1]],"id":52385917},{"atb":[[550,0.44],[650,0.16]],"id":52385926},{"atb":[[12,9.5],[8.8,31.27]],"id":52385928},{"atb":[[550,0.44],[650,0.16]],"id":52385897},{"atb":[[8.6,32.09],[11.5,9.95]],"id":52385922},{"atb":[[5.3,56.72],[6.6,18.66]],"id":52385924},{"atb":[[12,9.5],[8.8,31.27]],"id":52385893},{"atb":[[370,0.65],[470,0.22]],"id":52385899},{"atb":[[550,0.44],[650,0.16]],"id":52385901}],"con":true,"img":false}]}
{"op":"mcm","clk":"11450216518","pt":1717319261888,"mc":[{"id":"1.229554912","rc":[{"atb":[[260,0.94],[160,0],[210,0],[110,2]],"id":52385919},{"atb":[[680,0],[730,0],[780,0]],"id":52385897},{"atb":[[630,0],[680,0],[730,0],[780,0]],"id":52385901}],"con":true,"img":false}]}
{"op":"mcm","clk":"11450216591","pt":1717319262688,"mc":[{"id":"1.229554912","rc":[{"atb":[[270,0.1],[170,0.47],[220,0.24],[120,0.88]],"id":52385919},{"atb":[[690,0.12],[740,0.07],[790,0.03]],"id":52385897}],"con":true,"img":false}]}
{"op":"mcm","clk":"11450216610","pt":1717319262892,"mc":[{"id":"1.229554912","rc":[{"atb":[[640,0.16],[690,0.12],[740,0.07],[790,0.03]],"id":52385901}],"con":true,"img":false}]}
{"op":"mcm","clk":"11450217235","pt":1717319268810,"mc":[{"id":"1.229554912","rc":[{"atb":[[270,0]],"id":52385919}],"con":true,"img":false}]}
{"op":"mcm","clk":"11450217246","pt":1717319268915,"mc":[{"id":"1.229554912","rc":[{"atb":[[170,0],[220,0],[120,0]],"id":52385919}],"con":true,"img":false}]}
{"op":"mcm","clk":"11450217312","pt":1717319269487,"mc":[{"id":"1.229554912","rc":[{"atb":[[260,1.04]],"id":52385919}],"con":true,"img":false}]}
{"op":"mcm","clk":"11450217322","pt":1717319269586,"mc":[{"id":"1.229554912","rc":[{"atb":[[160,0.49],[210,0.25],[110,2.96]],"id":52385919}],"con":true,"img":false}]}
{"op":"mcm","clk":"11450217931","pt":1717319276207,"mc":[{"id":"1.229554912","rc":[{"atb":[[690,0],[740,0],[790,0]],"id":52385897},{"atb":[[640,0],[690,0],[740,0],[790,0]],"id":52385901}],"con":true,"img":false}]}
{"op":"mcm","clk":"11450218009","pt":1717319276890,"mc":[{"id":"1.229554912","rc":[{"atb":[[690,0.12],[740,0.07],[790,0.03]],"id":52385897},{"atb":[[640,0.16],[690,0.12],[740,0.07],[790,0.03]],"id":52385901}],"con":true,"img":false}]}
{"op":"mcm","clk":"11450218374","pt":1717319280633,"mc":[{"id":"1.229554912","rc":[{"atl":[[430,4.36],[450,4.67]],"id":52385912},{"atb":[[10.5,3.46],[11.5,2.65]],"id":52385889},{"atl":[[34,3.04],[38,3.54]],"id":52385889},{"atb":[[34,3.35],[38,6.01]],"id":52385883},{"atl":[[130,4.2],[110,4.04]],"id":52385883},{"atb":[[140,4.41],[120,3.81]],"id":52385896},{"atb":[[10.5,4.05],[11.5,10.58]],"id":52385911},{"atl":[[65,3.67],[55,3.26]],"id":52385911},{"atb":[[5.6,3.69],[5.4,21.56]],"id":52385886},{"atl":[[14,3.28],[15,3.96]],"id":52385886},{"atl":[[48,4.32],[55,4.57]],"id":52385924}],"con":true,"img":false}]}
{"op":"mcm","clk":"11450218385","pt":1717319280723,"mc":[{"id":"1.229554912","rc":[{"atb":[[7.2,3.13],[7.6,3.93]],"id":52385910},{"atl":[[18,2.96],[19,4]],"id":52385910},{"atb":[[16,3.11],[15,4.11]],"id":52385918},{"atl":[[70,2.88],[60,4.17]],"id":52385918},{"atl":[[17.5,3.67],[18.5,4.39]],"id":52385887},{"atl":[[80,2],[460,0]],"id":52385889},{"atb":[[12.5,11.84],[13.5,4.22]],"id":52385914},{"atl":[[38,3.15],[42,2.84]],"id":52385914},{"atb":[[5.1,3.5],[5.3,3.15]],"id":52385885},{"atl":[[9,4.31],[9.4,2.78]],"id":52385885},{"atb":[[26,4.4],[28,2.85]],"id":52385894},{"atl":[[95,4.38],[110,3.93]],"id":52385894},{"atb":[[20,3.08],[22,3.54]],"id":52385929},{"atl":[[75,3.41],[85,4.35]],"id":52385929},{"atl":[[790,2.87],[810,4.31]],"id":52385890},{"atb":[[16.5,10.21],[15.5,4.49]],"id":52385892},{"atl":[[70,2.69],[80,2.73]],"id":52385892},{"atb":[[25,4.61],[27,4.3]],"id":52385925},{"atl":[[95,4.54],[110,4.54]],"id":52385925},{"atl":[[22,4.76],[220,0]],"id":52385886},{"atl":[[470,3.8],[490,3.33]],"id":52385919},{"atb":[[12.5,13.68],[13.5,4.57]],"id":52385921},{"atl":[[40,3.23],[44,3.88]],"id":52385921},{"atb":[[6.6,18.19],[7,2.72]],"id":52385882},{"atl":[[13,3.22],[14,4.22]],"id":52385882},{"atb":[[16.5,3.23],[17.5,4.01]],"id":52385915},{"atl":[[65,3.7],[55,3.6]],"id":52385915},{"atb":[[8.2,4.66],[7.8,2.67]],"id":52385917},{"atl":[[25,3.65],[27,4.14]],"id":52385917},{"atl":[[790,4.56],[810,4.04]],"id":52385926},{"atb":[[19.5,3.73],[21,4.12]],"id":52385928},{"atl":[[70,4.51],[80,3.09]],"id":52385928},{"atb":[[18.5,4.09],[19.5,4.03]],"id":52385922},{"atl":[[70,4.59],[60,4.37]],"id":52385922},{"atb":[[20,4.56],[22,2.99]],"id":52385893},{"atl":[[75,2.79],[85,2.73]],"id":52385893}],"con":true,"img":false}]}
{"op":"mcm","clk":"11450218399","pt":1717319280827,"mc":[{"id":"1.229554912","rc":[{"atl":[[42,2.44],[360,0]],"id":52385910},{"atl":[[300,0],[30,3.45]],"id":52385887},{"atl":[[90,2],[480,0]],"id":52385914},{"atl":[[21,5],[210,0]],"id":52385885},{"atl":[[30,3.45]],"id":52385882},{"atl":[[380,0],[46,2.22]],"id":52385917}],"con":true,"img":false}]}
{"op":"mcm","clk":"11450218407","pt":1717319280930,"mc":[{"id":"1.229554912","rc":[{"atl":[[300,0]],"id":52385882}],"con":true,"img":false}]}
{"op":"mcm","clk":"11450218419","pt":1717319281039,"mc":[{"id":"1.229554912","rc":[{"atb":[[5.5,4.58],[5.3,2.84]],"id":52385886},{"atb":[[8,4.69],[7.6,2.64]],"id":52385917},{"atb":[[18,4],[19,3.46]],"id":52385922}],"con":true,"img":false}]}
{"op":"mcm","clk":"11450218505","pt":1717319281923,"mc":[{"id":"1.229554912","rc":[{"atb":[[5.6,0]],"id":52385886},{"atb":[[8.2,0]],"id":52385917},{"atb":[[19.5,0]],"id":52385922}],"con":true,"img":false}]}
{"op":"mcm","clk":"11450218874","pt":1717319285713,"mc":[{"id":"1.229554912","rc":[{"atb":[[5.6,3.59],[5.5,0],[5.3,0]],"id":52385886},{"atb":[[8,0],[8.2,2.74],[7.6,0]],"id":52385917},{"atb":[[18,0],[19,0],[19.5,4.55]],"id":52385922}],"con":true,"img":false}]}
{"op":"mcm","clk":"11450219118","pt":1717319288246,"mc":[{"id":"1.229554912","rc":[{"atb":[[5.6,0],[5.5,4.23]],"id":52385886},{"atb":[[8,3.08],[8.2,0]],"id":52385917},{"atb":[[19.5,0],[19,3.08]],"id":52385922}],"con":true,"img":false}]}
{"op":"mcm","clk":"11450235129","pt":1717319459784,"mc":[{"id":"1.229554912","rc":[{"atb":[[5.6,4.49],[5.5,0]],"id":52385886},{"atb":[[160,0],[210,0],[110,2]],"id":52385919},{"atb":[[8.2,2.96]],"id":52385917},{"atb":[[19.5,2.94]],"id":52385922}],"con":true,"img":false}]}
{"op":"mcm","clk":"11450235140","pt":1717319459873,"mc":[{"id":"1.229554912","rc":[{"atb":[[8,0]],"id":52385917},{"atb":[[19,0]],"id":52385922}],"con":true,"img":false}]}
{"op":"mcm","clk":"11450235186","pt":1717319460505,"mc":[{"id":"1.229554912","rc":[{"atb":[[170,0.47],[220,0.24],[120,0.88]],"id":52385919}],"con":true,"img":false}]}
{"op":"mcm","clk":"11450244642","pt":1717319563302,"mc":[{"id":"1.229554912","rc":[{"atb":[[38,2.7]],"id":52385883}],"con":true,"img":false}]}
{"op":"mcm","clk":"11450244654","pt":1717319563407,"mc":[{"id":"1.229554912","rc":[{"atb":[[42,5.78]],"id":52385883},{"atl":[[9,0],[10.5,2.93],[9.4,0]],"id":52385885},{"atl":[[13,0],[13.5,4.57]],"id":52385882}],"con":true,"img":false}]}
{"op":"mcm","clk":"11450244703","pt":1717319563872,"mc":[{"id":"1.229554912","rc":[{"atb":[[36,2.88]],"id":52385883}],"con":true,"img":false}]}
{"op":"mcm","clk":"11450244799","pt":1717319564961,"mc":[{"id":"1.229554912","rc":[{"atl":[[13,3.02],[13.5,0]],"id":52385882}],"con":true,"img":false}]}
{"op":"mcm","clk":"11450244810","pt":1717319565068,"mc":[{"id":"1.229554912","rc":[{"atb":[[38,7.22],[42,1.92]],"id":52385883},{"atl":[[9,2.87]],"id":52385885}],"con":true,"img":false}]}
{"op":"mcm","clk":"11450244959","pt":1717319566682,"mc":[{"id":"1.229554912","rc":[{"atb":[[34,0]],"id":52385883}],"con":true,"img":false}]}
{"op":"mcm","clk":"11450245732","pt":1717319575007,"mc":[{"id":"1.229554912","rc":[{"atl":[[9.4,4.7]],"id":52385885}],"con":true,"img":false}]}
{"op":"mcm","clk":"11450246436","pt":1717319582743,"mc":[{"id":"1.229554912","rc":[{"atb":[[4.8,26.32],[3.9,0]],"id":52385910},{"atb":[[340,0],[240,0.11]],"id":52385912},{"atb":[[8.6,0],[11.5,0]],"id":52385918},{"atb":[[3.95,0],[4.9,0]],"id":52385887},{"atb":[[5.3,0],[6.6,0]],"id":52385889},{"atb":[[6.8,0],[8.8,0]],"id":52385914},{"atb":[[17,0],[24,0]],"id":52385883},{"atb":[[3.2,0],[3.7,0]],"id":52385885},{"atb":[[10,0],[15,0]],"id":52385894},{"atb":[[46,0],[28,0]],"id":52385896},{"atb":[[12,0],[8.8,0]],"id":52385929},{"atb":[[550,0],[650,0]],"id":52385890},{"atb":[[12,0],[8.8,0]],"id":52385892},{"atb":[[10,0],[15,0]],"id":52385925},{"atb":[[390,0],[490,0]],"id":52385900},{"atb":[[11,0],[8.4,0]],"id":52385911},{"atb":[[3.25,0],[3.75,0]],"id":52385886},{"atb":[[260,0.1],[360,0]],"id":52385919},{"atb":[[6.8,0],[8.8,0]],"id":52385921},{"atb":[[3.95,0],[4.9,0]],"id":52385882},{"atb":[[11,0],[8.4,0]],"id":52385915},{"atb":[[4.8,0],[3.9,0]],"id":52385917},{"atb":[[550,0],[650,0]],"id":52385926},{"atb":[[12,0],[8.8,0]],"id":52385928},{"atb":[[550,0],[650,0]],"id":52385897},{"atb":[[8.6,0],[11.5,0]],"id":52385922},{"atb":[[5.3,0],[6.6,0]],"id":52385924},{"atb":[[12,0],[8.8,0]],"id":52385893},{"atb":[[370,0],[470,0]],"id":52385899},{"atb":[[550,0],[650,0]],"id":52385901}],"con":true,"img":false}]}
{"op":"mcm","clk":"11450246480","pt":1717319583006,"mc":[{"id":"1.229554912","rc":[{"atl":[[10.5,0]],"id":52385885}],"con":true,"img":false}]}
{"op":"mcm","clk":"11450246734","pt":1717319585608,"mc":[{"id":"1.229554912","rc":[{"atb":[[130,3.68],[110,5.8]],"id":52385912},{"atb":[[1.45,34.88],[1.43,36.5]],"id":52385887},{"atb":[[150,4.66],[170,4.19]],"id":52385890},{"atb":[[170,3.63],[190,3.77]],"id":52385900},{"atb":[[130,3.94],[110,5.83]],"id":52385919},{"atb":[[150,4.12],[170,3.13]],"id":52385926},{"atb":[[190,4.05],[210,2.63]],"id":52385897},{"atb":[[1.45,34.88],[1.43,36.5]],"id":52385924},{"atb":[[170,3.56],[190,3.05]],"id":52385899},{"atb":[[190,3.43],[210,3.76]],"id":52385901}],"con":true,"img":false}]}
{"op":"mcm","clk":"11450246816","pt":1717319586492,"mc":[{"id":"1.229554912","rc":[{"atb":[[38,2.7],[40,3.63]],"id":52385883}],"con":true,"img":false}]}
{"op":"mcm","clk":"11450247605","pt":1717319595636,"mc":[{"id":"1.229554912","rc":[{"atb":[[3.95,82.67],[4.9,26.8]],"id":52385887},{"atb":[[5.3,56.72],[6.6,18.66]],"id":52385889},{"atb":[[17,15.24],[24,4.54]],"id":52385883},{"atb":[[3.2,110.86],[3.7,38.71]],"id":52385885},{"atb":[[10,27.1],[15,7.46]],"id":52385894},{"atb":[[46,2.32],[28,9.03]],"id":52385896},{"atb":[[550,0.44],[650,0.16]],"id":52385890},{"atb":[[12,9.5],[8.8,31.27]],"id":52385892},{"atb":[[390,0.62],[490,0.21]],"id":52385900},{"atb":[[3.25,108.4],[3.75,38]],"id":52385886},{"atb":[[3.95,82.67],[4.9,26.8]],"id":52385882},{"atb":[[550,0.44],[650,0.16]],"id":52385897},{"atb":[[12,9.5],[8.8,31.27]],"id":52385893},{"atb":[[370,0.65],[470,0.22]],"id":52385899},{"atb":[[550,0.44],[650,0.16]],"id":52385901}],"con":true,"img":false}]}
{"op":"mcm","clk":"11450247617","pt":1717319595742,"mc":[{"id":"1.229554912","rc":[{"atb":[[4.8,53.82],[3.9,84.1]],"id":52385910},{"atb":[[340,0.3],[240,1.13]],"id":52385912},{"atb":[[8.6,32.09],[11.5,9.95]],"id":52385918},{"atb":[[6.8,42.05],[8.8,13.4]],"id":52385914},{"atb":[[12,9.5],[8.8,31.27]],"id":52385929},{"atb":[[10,27.1],[15,7.46]],"id":52385925},{"atb":[[11,10.45],[8.4,32.96]],"id":52385911},{"atb":[[260,1.04],[360,0.29]],"id":52385919},{"atb":[[6.8,42.05],[8.8,13.4]],"id":52385921},{"atb":[[11,10.45],[8.4,32.96]],"id":52385915},{"atb":[[4.8,27.5],[3.9,84.1]],"id":52385917},{"atb":[[550,0.44],[650,0.16]],"id":52385926},{"atb":[[12,9.5],[8.8,31.27]],"id":52385928},{"atb":[[8.6,32.09],[11.5,9.95]],"id":52385922},{"atb":[[5.3,56.72],[6.6,18.66]],"id":52385924}],"con":true,"img":false}]}
{"op":"mcm","clk":"11450247646","pt":1717319596003,"mc":[{"id":"1.229554912","rc":[{"atb":[[38,6.66],[40,0]],"id":52385883}],"con":true,"img":false}]}
{"op":"mcm","clk":"11450271738","pt":1717319871875,"mc":[{"id":"1.229554912","rc":[{"atb":[[5.6,0],[5.5,3.75]],"id":52385886},{"atb":[[170,0],[220,0],[120,0]],"id":52385919},{"atb":[[8,2.64],[8.2,0]],"id":52385917},{"atb":[[19.5,0],[19,2.75]],"id":52385922}],"con":true,"img":false}]}
{"op":"mcm","clk":"11450271751","pt":1717319871994,"mc":[{"id":"1.229554912","rc":[{"atl":[[18,0],[18.5,2.95]],"id":52385910},{"atl":[[17.5,0],[18,4.3]],"id":52385887},{"atl":[[9.6,2.89]],"id":52385885},{"atb":[[16.5,0],[9.6,0],[11.5,3.1],[12,2.73],[14,7.69]],"id":52385911},{"atl":[[23,3.56],[25,0]],"id":52385917}],"con":true,"img":false}]}
{"op":"mcm","clk":"11450271759","pt":1717319872087,"mc":[{"id":"1.229554912","rc":[{"atb":[[16,0],[17,0],[19.5,0],[24,0],[14.5,11.16]],"id":52385918},{"atl":[[9,0]],"id":52385885},{"atb":[[38,0],[48,0],[24,4.35],[29,0]],"id":52385894},{"atb":[[36,0],[46,0],[23,0],[28,0]],"id":52385925},{"atb":[[11.5,0]],"id":52385911},{"atb":[[17.5,0],[20,0],[12.5,4.57],[13,2.98],[13.5,0],[15,0]],"id":52385921},{"atb":[[8.6,0],[5.8,0],[7.6,0],[6.6,4.16]],"id":52385882},{"atb":[[17.5,0],[18,3.29]],"id":52385915},{"atl":[[24,3.05]],"id":52385917}],"con":true,"img":false}]}
{"op":"mcm","clk":"11450271765","pt":1717319872188,"mc":[{"id":"1.229554912","rc":[{"atb":[[12,11.82],[14,0]],"id":52385911}],"con":true,"img":false}]}
{"op":"mcm","clk":"11450271774","pt":1717319872293,"mc":[{"id":"1.229554912","rc":[{"atb":[[11.5,9.52],[12,2.73]],"id":52385911}],"con":true,"img":false}]}
{"op":"mcm","clk":"11450271797","pt":1717319872561,"mc":[{"id":"1.229554912","rc":[{"atb":[[160,0.49],[210,0.25],[110,6.79]],"id":52385919}],"con":true,"img":false}]}
{"op":"mcm","clk":"11450271818","pt":1717319872662,"mc":[{"id":"1.229554912","rc":[{"atb":[[17,1.64],[12,9.87],[9.8,11.89],[14.5,3.88]],"id":52385911}],"con":true,"img":false}]}
{"op":"mcm","clk":"11450271822","pt":1717319872766,"mc":[{"id":"1.229554912","rc":[{"atb":[[16.5,5.06],[19,2.91],[23,1.19],[14,8.05]],"id":52385918},{"atb":[[11.5,0],[14,7.69]],"id":52385911}],"con":true,"img":false}]}
{"op":"mcm","clk":"11450271829","pt":1717319872869,"mc":[{"id":"1.229554912","rc":[{"atb":[[38,1.41],[24,8.9],[48,0.55],[29,2.8]],"id":52385894},{"atb":[[34,1.59],[44,0.61],[22,4.98],[27,7.32]],"id":52385925},{"atb":[[17,3.27],[19.5,1.41],[12,9.51],[14.5,5.81]],"id":52385921},{"atb":[[8.6,3.44],[5.8,21.8],[7.6,7.93],[6.6,18.19]],"id":52385882}],"con":true,"img":false}]}
{"op":"mcm","clk":"11450271888","pt":1717319873587,"mc":[{"id":"1.229554912","rc":[{"atl":[[18.5,0],[18,3.87]],"id":52385910},{"atb":[[11.5,4.03],[12,7.14]],"id":52385911},{"atb":[[5.6,2.98],[5.5,0]],"id":52385886},{"atb":[[160,0],[210,0],[110,5.83]],"id":52385919},{"atb":[[8,0],[8.2,3.45]],"id":52385917},{"atl":[[23,0],[27,0]],"id":52385917},{"atb":[[19,0],[19.5,3.54]],"id":52385922}],"con":true,"img":false}]}
{"op":"mcm","clk":"11450271939","pt":1717319874261,"mc":[{"id":"1.229554912","rc":[{"atb":[[170,0.47],[220,0.24],[120,0.88]],"id":52385919}],"con":true,"img":false}]}
{"op":"mcm","clk":"11450271993","pt":1717319874876,"mc":[{"id":"1.229554912","rc":[{"atb":[[5.6,0],[5.5,4.68]],"id":52385886},{"atb":[[8,2.74],[8.2,0]],"id":52385917},{"atb":[[19.5,0],[19,4.47]],"id":52385922}],"con":true,"img":false}]}
{"op":"mcm","clk":"11450272134","pt":1717319876685,"mc":[{"id":"1.229554912","rc":[{"atb":[[8.2,4.06]],"id":52385917}],"con":true,"img":false}]}
{"op":"mcm","clk":"11450272144","pt":1717319876783,"mc":[{"id":"1.229554912","rc":[{"atb":[[5.6,3.22],[5.5,0]],"id":52385886},{"atb":[[8,0]],"id":52385917},{"atb":[[19,0],[19.5,3.11]],"id":52385922}],"con":true,"img":false}]}
{"op":"mcm","clk":"11450272327","pt":1717319879176,"mc":[{"id":"1.229554912","rc":[{"atb":[[5.6,0],[5.5,2.84]],"id":52385886},{"atb":[[8,4.07],[8.2,0]],"id":52385917},{"atb":[[19.5,0],[19,4.02]],"id":52385922}],"con":true,"img":false}]}
{"op":"mcm","clk":"11450272385","pt":1717319880096,"mc":[{"id":"1.229554912","rc":[{"atb":[[170,0],[220,0],[120,0]],"id":52385919}],"con":true,"img":false}]}
{"op":"mcm","clk":"11450272446","pt":1717319880778,"mc":[{"id":"1.229554912","rc":[{"atb":[[160,0.49],[210,0.25],[110,6.79]],"id":52385919}],"con":true,"img":false}]}
{"op":"mcm","clk":"11450273093","pt":1717319888960,"mc":[{"id":"1.229554912","rc":[{"atb":[[16.5,0],[16,3.93],[19,0],[23,0],[14,0],[15,0]],"id":52385918},{"atl":[[17.5,4.65],[18,0]],"id":52385887},{"atl":[[9,3.08],[9.4,0]],"id":52385885},{"atb":[[17,0],[12,0],[9.8,0],[14.5,0]],"id":52385911},{"atb":[[17,0],[19.5,0],[12,0],[13,0],[13.5,3.51],[14.5,0]],"id":52385921},{"atb":[[17.5,4.14],[18,0]],"id":52385915},{"atl":[[24,0],[25,3.07]],"id":52385917}],"con":true,"img":false}]}
{"op":"mcm","clk":"11450273104","pt":1717319889015,"mc":[{"id":"1.229554912","rc":[{"atb":[[34,0],[44,0],[22,0],[27,4.3]],"id":52385925},{"atb":[[12,9.09]],"id":52385911}],"con":true,"img":false}]}
{"op":"mcm","clk":"11450273108","pt":1717319889112,"mc":[{"id":"1.229554912","rc":[{"atb":[[14,0]],"id":52385911}],"con":true,"img":false}]}
{"op":"mcm","clk":"11450273145","pt":1717319889589,"mc":[{"id":"1.229554912","rc":[{"atb":[[17,4.9],[19.5,2.83],[24,1.14],[14.5,18.91]],"id":52385918},{"atb":[[16.5,1.69],[9.6,12.17],[11.5,11.52],[14,4.02]],"id":52385911},{"atb":[[17.5,3.17],[20,1.38],[12.5,13.68],[15,5.6]],"id":52385921}],"con":true,"img":false}]}
{"op":"mcm","clk":"11450273156","pt":1717319889691,"mc":[{"id":"1.229554912","rc":[{"atb":[[36,1.5],[46,0.58],[23,4.76],[28,2.91]],"id":52385925}],"con":true,"img":false}]}
{"op":"mcm","clk":"11450273893","pt":1717319898935,"mc":[{"id":"1.229554912","rc":[{"atl":[[27,3.59]],"id":52385917}],"con":true,"img":false}]}
{"op":"mcm","clk":"11450274104","pt":1717319902044,"mc":[{"id":"1.229554912","rc":[{"atb":[[12,0],[14,11.71]],"id":52385911}],"con":true,"img":false}]}
{"op":"mcm","clk":"11450276243","pt":1717319929600,"mc":[{"id":"1.229554912","rc":[{"atb":[[4.8,26.32],[3.9,0]],"id":52385910},{"atb":[[340,0],[240,0.11]],"id":52385912},{"atb":[[8.6,0],[11.5,0]],"id":52385918},{"atb":[[3.95,0],[4.9,0]],"id":52385887},{"atb":[[5.3,0],[6.6,0]],"id":52385889},{"atb":[[6.8,0],[8.8,0]],"id":52385914},{"atb":[[17,0],[24,0]],"id":52385883},{"atb":[[3.2,0],[3.7,0]],"id":52385885},{"atb":[[10,0],[15,0]],"id":52385894},{"atb":[[46,0],[28,0]],"id":52385896},{"atb":[[12,0],[8.8,0]],"id":52385929},{"atb":[[550,0],[650,0]],"id":52385890},{"atb":[[12,0],[8.8,0]],"id":52385892},{"atb":[[10,0],[15,0]],"id":52385925},{"atb":[[390,0],[490,0]],"id":52385900},{"atb":[[11,0],[8.4,0]],"id":52385911},{"atb":[[3.25,0],[3.75,0]],"id":52385886},{"atb":[[260,0.1],[360,0]],"id":52385919},{"atb":[[6.8,0],[8.8,0]],"id":52385921},{"atb":[[3.95,0],[4.9,0]],"id":52385882},{"atb":[[11,0],[8.4,0]],"id":52385915},{"atb":[[4.8,0],[3.9,0]],"id":52385917},{"atb":[[550,0],[650,0]],"id":52385926},{"atb":[[12,0],[8.8,0]],"id":52385928},{"atb":[[550,0],[650,0]],"id":52385897},{"atb":[[8.6,0],[11.5,0]],"id":52385922},{"atb":[[5.3,0],[6.6,0]],"id":52385924},{"atb":[[12,0],[8.8,0]],"id":52385893},{"atb":[[370,0],[470,0]],"id":52385899},{"atb":[[550,0],[650,0]],"id":52385901}],"con":true,"img":false}]}
{"op":"mcm","clk":"11450276472","pt":1717319932786,"mc":[{"id":"1.229554912","rc":[{"atb":[[38,2.7],[40,3.44]],"id":52385883}],"con":true,"img":false}]}
{"op":"mcm","clk":"11450276990","pt":1717319939602,"mc":[{"id":"1.229554912","rc":[{"atb":[[4.8,53.82],[3.9,84.1]],"id":52385910},{"atb":[[340,0.3],[240,1.13]],"id":52385912},{"atb":[[8.6,32.09],[11.5,9.95]],"id":52385918},{"atb":[[6.8,42.05],[8.8,13.4]],"id":52385914},{"atb":[[12,9.5],[8.8,31.27]],"id":52385929},{"atb":[[10,27.1],[15,7.46]],"id":52385925},{"atb":[[11,10.45],[8.4,32.96]],"id":52385911},{"atb":[[260,1.04],[360,0.29]],"id":52385919},{"atb":[[6.8,42.05],[8.8,13.4]],"id":52385921},{"atb":[[11,10.45],[8.4,32.96]],"id":52385915},{"atb":[[4.8,27.5],[3.9,84.1]],"id":52385917},{"atb":[[550,0.44],[650,0.16]],"id":52385926},{"atb":[[12,9.5],[8.8,31.27]],"id":52385928},{"atb":[[8.6,32.09],[11.5,9.95]],"id":52385922},{"atb":[[5.3,56.72],[6.6,18.66]],"id":52385924}],"con":true,"img":false}]}
{"op":"mcm","clk":"11450276997","pt":1717319939703,"mc":[{"id":"1.229554912","rc":[{"atb":[[3.95,82.67],[4.9,26.8]],"id":52385887},{"atb":[[5.3,56.72],[6.6,18.66]],"id":52385889},{"atb":[[17,15.24],[24,4.54]],"id":52385883},{"atb":[[3.2,110.86],[3.7,38.71]],"id":52385885},{"atb":[[10,27.1],[15,7.46]],"id":52385894},{"atb":[[46,2.32],[28,9.03]],"id":52385896},{"atb":[[550,0.44],[650,0.16]],"id":52385890},{"atb":[[12,9.5],[8.8,31.27]],"id":52385892},{"atb":[[390,0.62],[490,0.21]],"id":52385900},{"atb":[[3.25,108.4],[3.75,38]],"id":52385886},{"atb":[[3.95,82.67],[4.9,26.8]],"id":52385882},{"atb":[[550,0.44],[650,0.16]],"id":52385897},{"atb":[[12,9.5],[8.8,31.27]],"id":52385893},{"atb":[[370,0.65],[470,0.22]],"id":52385899},{"atb":[[550,0.44],[650,0.16]],"id":52385901}],"con":true,"img":false}]}
{"op":"mcm","clk":"11450277028","pt":1717319940115,"mc":[{"id":"1.229554912","rc":[{"atb":[[38,6.6],[40,0]],"id":52385883}],"con":true,"img":false}]}
{"op":"mcm","clk":"11450277954","pt":1717319950710,"mc":[{"id":"1.229554912","rc":[{"atl":[[18,0],[18.5,3.98]],"id":52385910},{"atl":[[38,0],[40,4.66]],"id":52385914}],"con":true,"img":false}]}
{"op":"mcm","clk":"11450277961","pt":1717319950815,"mc":[{"id":"1.229554912","rc":[{"atl":[[9,0],[9.4,4.26]],"id":52385885}],"con":true,"img":false}]}
{"op":"mcm","clk":"11450279798","pt":1717319974338,"mc":[{"id":"1.229554912","rc":[{"atb":[[5.6,4.7],[5.5,0]],"id":52385886},{"atb":[[8.2,3.74]],"id":52385917},{"atb":[[19,0],[19.5,4.68]],"id":52385922}],"con":true,"img":false}]}
{"op":"mcm","clk":"11450279807","pt":1717319974438,"mc":[{"id":"1.229554912","rc":[{"atb":[[8,0]],"id":52385917}],"con":true,"img":false}]}
{"op":"mcm","clk":"11450279860","pt":1717319975160,"mc":[{"id":"1.229554912","rc":[{"atb":[[7.8,0]],"id":52385917}],"con":true,"img":false}]}
{"op":"mcm","clk":"11450280095","pt":1717319977955,"mc":[{"id":"1.229554912","rc":[{"atb":[[5.6,0],[5.5,3.74]],"id":52385886},{"atb":[[8,3.17],[8.2,0]],"id":52385917},{"atb":[[19.5,0],[19,3.52]],"id":52385922}],"con":true,"img":false}]}
{"op":"mcm","clk":"11450280866","pt":1717319987975,"mc":[{"id":"1.229554912","rc":[{"atb":[[7.6,3.41]],"id":52385917}],"con":true,"img":false}]}
{"op":"mcm","clk":"11450283067","pt":1717320014495,"mc":[{"id":"1.229554912","rc":[{"atb":[[38,2.7]],"id":52385883}],"con":true,"img":false}]}
{"op":"mcm","clk":"11450283534","pt":1717320020614,"mc":[{"id":"1.229554912","rc":[{"atb":[[32,6.23]],"id":52385883}],"con":true,"img":false}]}
{"op":"mcm","clk":"11450283598","pt":1717320021639,"mc":[{"id":"1.229554912","rc":[{"atb":[[36,0],[38,5.34]],"id":52385883}],"con":true,"img":false}]}
{"op":"mcm","clk":"11450285648","pt":1717320052046,"mc":[{"id":"1.229554912","rc":[{"atb":[[7.6,0],[6.8,0],[9.8,0],[8.8,0],[7.8,3.79]],"id":52385910},{"atb":[[5.3,0],[5.4,4.47]],"id":52385885},{"atb":[[5.5,0]],"id":52385886}],"con":true,"img":false}]}
{"op":"mcm","clk":"11450285674","pt":1717320052662,"mc":[{"id":"1.229554912","rc":[{"atb":[[5.2,3.88]],"id":52385886}],"con":true,"img":false}]}
{"op":"mcm","clk":"11450285677","pt":1717320052768,"mc":[{"id":"1.229554912","rc":[{"atb":[[8,11.21],[9,6.54],[10,2.91],[7,17.44]],"id":52385910}],"con":true,"img":false}]}
{"op":"mcm","clk":"11450285783","pt":1717320054474,"mc":[{"id":"1.229554912","rc":[{"atb":[[7.6,4.24],[7.8,0]],"id":52385910},{"atb":[[5.3,3.36],[5.4,0]],"id":52385885},{"atb":[[5.5,2.74],[5.4,17.84]],"id":52385886}],"con":true,"img":false}]}
{"op":"mcm","clk":"11450287377","pt":1717320078596,"mc":[{"id":"1.229554912","rc":[{"atb":[[7.6,0],[7.8,4.69]],"id":52385910},{"atb":[[5.3,0],[5.4,2.97]],"id":52385885},{"atb":[[5.5,0],[5.4,21.14]],"id":52385886}],"con":true,"img":false}]}
{"op":"mcm","clk":"11450287651","pt":1717320083198,"mc":[{"id":"1.229554912","rc":[{"atb":[[7.6,4.2],[7.8,0]],"id":52385910},{"atb":[[5.3,3.16],[5.4,0]],"id":52385885},{"atb":[[5.5,3.04],[5.4,17.84]],"id":52385886}],"con":true,"img":false}]}
{"op":"mcm","clk":"11450287742","pt":1717320084796,"mc":[{"id":"1.229554912","rc":[{"atb":[[7.6,0],[7.8,2.77]],"id":52385910},{"atb":[[5.3,0],[5.4,2.9]],"id":52385885},{"atb":[[5.5,0],[5.4,21.63]],"id":52385886}],"con":true,"img":false}]}
{"op":"mcm","clk":"11450288012","pt":1717320088410,"mc":[{"id":"1.229554912","rc":[{"atb":[[16,0],[17,0],[19.5,0],[24,0],[14.5,11.16],[15,3.57]],"id":52385918},{"atb":[[38,0],[48,0],[24,4.35],[29,0]],"id":52385894},{"atb":[[36,0],[46,0],[23,0],[28,0]],"id":52385925},{"atb":[[16.5,0],[9.6,0],[11.5,0],[12,3.5],[14,7.69]],"id":52385911},{"atl":[[13.5,2.73],[14,0]],"id":52385886},{"atb":[[17.5,0],[20,0],[12.5,4.57],[13,3.08],[13.5,0],[15,0]],"id":52385921},{"atb":[[6.8,3.64],[7,0]],"id":52385882},{"atb":[[16,0],[17.5,0],[18.5,4.29],[22,0],[27,0]],"id":52385915},{"atl":[[24,4],[25,0]],"id":52385917}],"con":true,"img":false}]}
{"op":"mcm","clk":"11450288028","pt":1717320088614,"mc":[{"id":"1.229554912","rc":[{"atb":[[12.5,8.7],[14,0]],"id":52385911}],"con":true,"img":false}]}
{"op":"mcm","clk":"11450288059","pt":1717320089082,"mc":[{"id":"1.229554912","rc":[{"atb":[[16,5.23],[18.5,2.99],[22,1.25],[13.5,8.37]],"id":52385918},{"atb":[[36,1.5],[46,0.58],[23,4.76],[28,5.76]],"id":52385894},{"atb":[[34,1.59],[44,0.61],[22,4.98],[27,7.32]],"id":52385925},{"atb":[[17.5,1.59],[10,11.63],[12.5,15.52],[15,3.74]],"id":52385911},{"atb":[[17,3.27],[19.5,1.41],[12,9.51],[14.5,5.81]],"id":52385921},{"atb":[[16.5,9.99],[19,4.36],[23,2.38],[28,0.97]],"id":52385915}],"con":true,"img":false}]}
{"op":"mcm","clk":"11450288065","pt":1717320089181,"mc":[{"id":"1.229554912","rc":[{"atb":[[14,7.69]],"id":52385911}],"con":true,"img":false}]}
{"op":"mcm","clk":"11450288073","pt":1717320089286,"mc":[{"id":"1.229554912","rc":[{"atb":[[12.5,6.82]],"id":52385911}],"con":true,"img":false}]}
{"op":"mcm","clk":"11450288647","pt":1717320098397,"mc":[{"id":"1.229554912","rc":[{"atb":[[17.5,2.96]],"id":52385915}],"con":true,"img":false}]}
{"op":"mcm","clk":"11450288681","pt":1717320098915,"mc":[{"id":"1.229554912","rc":[{"atl":[[70,4.68],[75,0]],"id":52385929},{"atl":[[790,0],[770,3.52]],"id":52385890},{"atl":[[460,4.15],[470,0]],"id":52385919},{"atl":[[790,0],[770,4]],"id":52385926},{"atl":[[70,2.78],[75,0]],"id":52385893}],"con":true,"img":false}]}
{"op":"mcm","clk":"11450288692","pt":1717320099015,"mc":[{"id":"1.229554912","rc":[{"atb":[[16,9.64],[15,0]],"id":52385918},{"atb":[[17.5,0],[10,0],[11.5,3.57],[12,0],[12.5,0],[15,0]],"id":52385911},{"atl":[[13.5,0],[14,4.29]],"id":52385886},{"atb":[[13,0],[13.5,4.06]],"id":52385921},{"atb":[[6.8,0],[7,4.55]],"id":52385882},{"atb":[[16.5,3.23],[18.5,0],[19,0],[23,0],[28,0]],"id":52385915},{"atl":[[24,0],[25,3.53]],"id":52385917}],"con":true,"img":false}]}
{"op":"mcm","clk":"11450288701","pt":1717320099117,"mc":[{"id":"1.229554912","rc":[{"atb":[[12,9.09],[14,0]],"id":52385911}],"con":true,"img":false}]}
{"op":"mcm","clk":"11450288736","pt":1717320099690,"mc":[{"id":"1.229554912","rc":[{"atb":[[16.5,1.69],[9.6,12.17],[11.5,11.05],[14,4.02]],"id":52385911},{"atb":[[16,6.97],[18.5,4.48],[22,2.49],[27,1]],"id":52385915}],"con":true,"img":false}]}
{"op":"mcm","clk":"11450288766","pt":1717320100205,"mc":[{"id":"1.229554912","rc":[{"atb":[[12,0],[14,11.71]],"id":52385911}],"con":true,"img":false}]}
{"op":"mcm","clk":"11450289321","pt":1717320108933,"mc":[{"id":"1.229554912","rc":[{"atl":[[790,3.3]],"id":52385890},{"atl":[[790,3.17]],"id":52385926}],"con":true,"img":false}]}
{"op":"mcm","clk":"11450289458","pt":1717320111113,"mc":[{"id":"1.229554912","rc":[{"atb":[[7.6,2.8],[7.8,0]],"id":52385910},{"atl":[[18,4.04]],"id":52385887},{"atb":[[5.3,3.34],[5.4,0]],"id":52385885},{"atl":[[70,0],[75,4.41]],"id":52385929},{"atl":[[770,0],[810,0]],"id":52385890},{"atb":[[5.5,4.15],[5.4,17.84]],"id":52385886},{"atl":[[460,0],[470,3.9]],"id":52385919},{"atl":[[770,0],[810,0]],"id":52385926},{"atl":[[70,0],[75,3.1]],"id":52385893}],"con":true,"img":false}]}
{"op":"mcm","clk":"11450289465","pt":1717320111210,"mc":[{"id":"1.229554912","rc":[{"atb":[[16,5.23],[15,3.31]],"id":52385918},{"atl":[[17.5,0]],"id":52385887},{"atb":[[13,2.98],[13.5,0]],"id":52385921},{"atb":[[17.5,0],[18,4.65]],"id":52385915},{"atl":[[24,4.63],[25,0]],"id":52385917}],"con":true,"img":false}]}
{"op":"mcm","clk":"11450289682","pt":1717320114429,"mc":[{"id":"1.229554912","rc":[{"atb":[[4.8,26.32],[3.9,0]],"id":52385910},{"atb":[[340,0],[240,0.11]],"id":52385912},{"atb":[[8.6,0],[11.5,0]],"id":52385918},{"atb":[[3.95,0],[4.9,0]],"id":52385887},{"atb":[[5.3,0],[6.6,0]],"id":52385889},{"atb":[[6.8,0],[8.8,0]],"id":52385914},{"atb":[[17,0],[24,0]],"id":52385883},{"atb":[[3.2,0],[3.7,0]],"id":52385885},{"atb":[[10,0],[15,0]],"id":52385894},{"atb":[[46,0],[28,0]],"id":52385896},{"atb":[[12,0],[8.8,0]],"id":52385929},{"atb":[[550,0],[650,0]],"id":52385890},{"atb":[[12,0],[8.8,0]],"id":52385892},{"atb":[[10,0],[15,0]],"id":52385925},{"atb":[[390,0],[490,0]],"id":52385900},{"atb":[[11,0],[8.4,0]],"id":52385911},{"atb":[[3.25,0],[3.75,0]],"id":52385886},{"atb":[[260,0.1],[360,0]],"id":52385919},{"atb":[[6.8,0],[8.8,0]],"id":52385921},{"atb":[[3.95,0],[4.9,0]],"id":52385882},{"atb":[[11,0],[8.4,0]],"id":52385915},{"atb":[[4.8,0],[3.9,0]],"id":52385917},{"atb":[[550,0],[650,0]],"id":52385926},{"atb":[[12,0],[8.8,0]],"id":52385928},{"atb":[[550,0],[650,0]],"id":52385897},{"atb":[[8.6,0],[11.5,0]],"id":52385922},{"atb":[[5.3,0],[6.6,0]],"id":52385924},{"atb":[[12,0],[8.8,0]],"id":52385893},{"atb":[[370,0],[470,0]],"id":52385899},{"atb":[[550,0],[650,0]],"id":52385901}],"con":true,"img":false}]}
{"op":"mcm","clk":"11450289910","pt":1717320117532,"mc":[{"id":"1.229554912","rc":[{"atb":[[7.6,0],[7.8,3.67]],"id":52385910},{"atb":[[5.3,0],[5.4,2.71]],"id":52385885},{"atl":[[70,3.19],[75,0]],"id":52385929},{"atl":[[770,4.24]],"id":52385890},{"atb":[[5.5,0],[5.4,20.61]],"id":52385886},{"atl":[[460,3.25],[470,0]],"id":52385919},{"atl":[[770,2.95]],"id":52385926},{"atl":[[70,3.84],[75,0]],"id":52385893}],"con":true,"img":false}]}
{"op":"mcm","clk":"11450290273","pt":1717320122461,"mc":[{"id":"1.229554912","rc":[{"atb":[[7.6,4.44],[7.8,0]],"id":52385910},{"atb":[[5.3,2.8],[5.4,0]],"id":52385885},{"atb":[[5.5,4.52],[5.4,17.84]],"id":52385886}],"con":true,"img":false}]}
{"op":"mcm","clk":"11450290285","pt":1717320122597,"mc":[{"id":"1.229554912","rc":[{"atl":[[17.5,4.49],[18,0]],"id":52385887},{"atb":[[11.5,7.48],[12,3.11]],"id":52385911},{"atl":[[13.5,4.16],[14,0]],"id":52385886},{"atb":[[6.8,4.26],[7,0]],"id":52385882},{"atb":[[18.5,7.84],[18,0]],"id":52385915}],"con":true,"img":false}]}
{"op":"mcm","clk":"11450290749","pt":1717320129045,"mc":[{"id":"1.229554912","rc":[{"atb":[[7.6,0],[7.8,3.42]],"id":52385910},{"atl":[[18.5,0],[19.5,3.74]],"id":52385910},{"atb":[[16,8.61],[15,0]],"id":52385918},{"atb":[[5.3,0],[5.4,3.38]],"id":52385885},{"atl":[[9.4,0]],"id":52385885},{"atb":[[11.5,11.08],[12,0]],"id":52385911},{"atb":[[5.5,0],[5.4,21.27]],"id":52385886},{"atl":[[13.5,0],[14,4.63]],"id":52385886},{"atb":[[13,0],[13.5,3.69]],"id":52385921},{"atl":[[40,0],[42,4.07]],"id":52385921},{"atb":[[6.8,0],[7,3.8]],"id":52385882},{"atb":[[17.5,3.81],[18.5,4.48]],"id":52385915},{"atl":[[24,0],[25,3.37]],"id":52385917}],"con":true,"img":false}]}
{"op":"mcm","clk":"11450290825","pt":1717320129869,"mc":[{"id":"1.229554912","rc":[{"atb":[[4.8,53.82],[3.9,84.1]],"id":52385910},{"atl":[[19,0]],"id":52385910},{"atb":[[340,0.3],[240,1.13]],"id":52385912},{"atb":[[8.6,32.09],[11.5,9.95]],"id":52385918},{"atb":[[6.8,42.05],[8.8,13.4]],"id":52385914},{"atb":[[12,9.5],[8.8,31.27]],"id":52385929},{"atb":[[10,27.1],[15,7.46]],"id":52385925},{"atb":[[11,10.45],[8.4,32.96]],"id":52385911},{"atb":[[260,1.04],[360,0.29]],"id":52385919},{"atb":[[6.8,42.05],[8.8,13.4]],"id":52385921},{"atb":[[11,10.45],[8.4,32.96]],"id":52385915},{"atb":[[4.8,27.5],[3.9,84.1]],"id":52385917},{"atb":[[550,0.44],[650,0.16]],"id":52385926},{"atb":[[12,9.5],[8.8,31.27]],"id":52385928},{"atb":[[8.6,32.09],[11.5,9.95]],"id":52385922},{"atb":[[5.3,56.72],[6.6,18.66]],"id":52385924}],"con":true,"img":false}]}
{"op":"mcm","clk":"11450290837","pt":1717320129973,"mc":[{"id":"1.229554912","rc":[{"atb":[[3.95,82.67],[4.9,26.8]],"id":52385887},{"atb":[[5.3,56.72],[6.6,18.66]],"id":52385889},{"atb":[[17,15.24],[24,4.54]],"id":52385883},{"atb":[[3.2,110.86],[3.7,38.71]],"id":52385885},{"atb":[[10,27.1],[15,7.46]],"id":52385894},{"atb":[[46,2.32],[28,9.03]],"id":52385896},{"atb":[[550,0.44],[650,0.16]],"id":52385890},{"atb":[[12,9.5],[8.8,31.27]],"id":52385892},{"atb":[[390,0.62],[490,0.21]],"id":52385900},{"atb":[[3.25,108.4],[3.75,38]],"id":52385886},{"atb":[[3.95,82.67],[4.9,26.8]],"id":52385882},{"atb":[[550,0.44],[650,0.16]],"id":52385897},{"atb":[[12,9.5],[8.8,31.27]],"id":52385893},{"atb":[[370,0.65],[470,0.22]],"id":52385899},{"atb":[[550,0.44],[650,0.16]],"id":52385901}],"con":true,"img":false}]}
{"op":"mcm","clk":"11450291176","pt":1717320134880,"mc":[{"id":"1.229554912","rc":[{"atb":[[7.6,2.94],[7.8,0]],"id":52385910},{"atb":[[5.3,3.06]],"id":52385885},{"atb":[[5.5,3.17]],"id":52385886}],"con":true,"img":false}]}
{"op":"mcm","clk":"11450291183","pt":1717320134936,"mc":[{"id":"1.229554912","rc":[{"atb":[[5.4,0]],"id":52385885}],"con":true,"img":false}]}
{"op":"mcm","clk":"11450291189","pt":1717320135043,"mc":[{"id":"1.229554912","rc":[{"atb":[[5.4,17.84]],"id":52385886}],"con":true,"img":false}]}
{"op":"mcm","clk":"11450291897","pt":1717320144890,"mc":[{"id":"1.229554912","rc":[{"atl":[[21,3.25]],"id":52385910},{"atl":[[10,3.94]],"id":52385885}],"con":true,"img":false}]}
{"op":"mcm","clk":"11450294900","pt":1717320188735,"mc":[{"id":"1.229554912","rc":[{"atb":[[36,3.43]],"id":52385883}],"con":true,"img":false}]}
{"op":"mcm","clk":"11450294908","pt":1717320188836,"mc":[{"id":"1.229554912","rc":[{"atb":[[38,2.7]],"id":52385883}],"con":true,"img":false}]}
{"op":"mcm","clk":"11450294953","pt":1717320189656,"mc":[{"id":"1.229554912","rc":[{"atb":[[32,3.37],[36,0],[38,5.39]],"id":52385883}],"con":true,"img":false}]}
{"op":"mcm","clk":"11450295023","pt":1717320190951,"mc":[{"id":"1.229554912","rc":[{"atb":[[36,3.76],[38,2.7]],"id":52385883}],"con":true,"img":false}]}
{"op":"mcm","clk":"11450295203","pt":1717320193441,"mc":[{"id":"1.229554912","rc":[{"atb":[[38,7.04]],"id":52385883}],"con":true,"img":false}]}
{"op":"mcm","clk":"11450295235","pt":1717320193961,"mc":[{"id":"1.229554912","rc":[{"atb":[[16,3.37],[18.5,0],[22,0],[13.5,0]],"id":52385918},{"atb":[[36,0],[46,0],[23,0],[28,2.85]],"id":52385894},{"atb":[[34,0],[44,0],[22,0],[27,4.3]],"id":52385925},{"atb":[[17,0],[19.5,0],[12,0],[14.5,0]],"id":52385921}],"con":true,"img":false}]}
{"op":"mcm","clk":"11450295296","pt":1717320194638,"mc":[{"id":"1.229554912","rc":[{"atb":[[17,4.9],[19.5,2.83],[24,1.14],[14.5,18.91]],"id":52385918},{"atb":[[38,1.41],[24,8.9],[48,0.55],[29,2.8]],"id":52385894},{"atb":[[36,1.5],[46,0.58],[23,4.76],[28,2.91]],"id":52385925},{"atb":[[17.5,3.17],[20,1.38],[12.5,13.68],[15,5.6]],"id":52385921}],"con":true,"img":false}]}
{"op":"mcm","clk":"11450296984","pt":1717320221878,"mc":[{"id":"1.229554912","rc":[{"atb":[[38,2.7]],"id":52385883}],"con":true,"img":false}]}
{"op":"mcm","clk":"11450297043","pt":1717320222595,"mc":[{"id":"1.229554912","rc":[{"atb":[[38,6.42]],"id":52385883}],"con":true,"img":false}]}
{"op":"mcm","clk":"11450297125","pt":1717320223692,"mc":[{"id":"1.229554912","rc":[{"atb":[[38,2.7]],"id":52385883}],"con":true,"img":false}]}
{"op":"mcm","clk":"11450297257","pt":1717320225212,"mc":[{"id":"1.229554912","rc":[{"atb":[[38,6.57]],"id":52385883}],"con":true,"img":false}]}
{"op":"mcm","clk":"11450297343","pt":1717320226313,"mc":[{"id":"1.229554912","rc":[{"atb":[[38,2.7]],"id":52385883}],"con":true,"img":false}]}
{"op":"mcm","clk":"11450297406","pt":1717320227207,"mc":[{"id":"1.229554912","rc":[{"atb":[[38,6.21]],"id":52385883}],"con":true,"img":false}]}
{"op":"mcm","clk":"11450297610","pt":1717320230508,"mc":[{"id":"1.229554912","rc":[{"atb":[[38,2.7]],"id":52385883}],"con":true,"img":false}]}
{"op":"mcm","clk":"11450297648","pt":1717320231301,"mc":[{"id":"1.229554912","rc":[{"atb":[[38,5.82]],"id":52385883}],"con":true,"img":false}]}
{"op":"mcm","clk":"11450297704","pt":1717320232124,"mc":[{"id":"1.229554912","rc":[{"atb":[[38,2.7]],"id":52385883}],"con":true,"img":false}]}
{"op":"mcm","clk":"11450298061","pt":1717320237603,"mc":[{"id":"1.229554912","rc":[{"atb":[[38,5.95]],"id":52385883}],"con":true,"img":false}]}
{"op":"mcm","clk":"11450298256","pt":1717320241039,"mc":[{"id":"1.229554912","rc":[{"atb":[[38,2.7]],"id":52385883}],"con":true,"img":false}]}
{"op":"mcm","clk":"11450298724","pt":1717320247618,"mc":[{"id":"1.229554912","rc":[{"atb":[[32,7.97]],"id":52385883}],"con":true,"img":false}]}
{"op":"mcm","clk":"11450299240","pt":1717320255107,"mc":[{"id":"1.229554912","rc":[{"atb":[[36,0],[38,6.42]],"id":52385883}],"con":true,"img":false}]}
{"op":"mcm","clk":"11450299375","pt":1717320257141,"mc":[{"id":"1.229554912","rc":[{"atb":[[7.4,15.62],[1.35,0]],"id":52385924}],"con":true,"img":false}]}
{"op":"mcm","clk":"11450299396","pt":1717320257446,"mc":[{"id":"1.229554912","rc":[{"atb":[[7.2,16.92]],"id":52385887},{"atb":[[11.5,4.13]],"id":52385924}],"con":true,"img":false}]}
{"op":"mcm","clk":"11450299403","pt":1717320257542,"mc":[{"id":"1.229554912","rc":[{"atb":[[1.45,0]],"id":52385887},{"atb":[[1.45,0]],"id":52385924}],"con":true,"img":false}]}
{"op":"mcm","clk":"11450299474","pt":1717320258538,"mc":[{"id":"1.229554912","rc":[{"atb":[[36,4.13],[38,2.7]],"id":52385883}],"con":true,"img":false}]}
{"op":"mcm","clk":"11450299747","pt":1717320262641,"mc":[{"id":"1.229554912","rc":[{"atb":[[36,0],[38,6.14]],"id":52385883}],"con":true,"img":false}]}
{"op":"mcm","clk":"11450299874","pt":1717320264453,"mc":[{"id":"1.229554912","rc":[{"atb":[[36,2.97],[38,2.7]],"id":52385883}],"con":true,"img":false}]}
{"op":"mcm","clk":"11450300080","pt":1717320267313,"mc":[{"id":"1.229554912","rc":[{"atb":[[4.5,28.57],[1.35,0]],"id":52385887}],"con":true,"img":false}]}
{"op":"mcm","clk":"11450300088","pt":1717320267416,"mc":[{"id":"1.229554912","rc":[{"atb":[[6.8,4.04]],"id":52385887},{"atb":[[10.5,3.55]],"id":52385924}],"con":true,"img":false}]}
{"op":"mcm","clk":"11450300280","pt":1717320269928,"mc":[{"id":"1.229554912","rc":[{"atb":[[1.43,0]],"id":52385887},{"atb":[[1.43,0]],"id":52385924}],"con":true,"img":false}]}
{"op":"mcm","clk":"11450300295","pt":1717320270244,"mc":[{"id":"1.229554912","rc":[{"atb":[[38,6.63]],"id":52385883}],"con":true,"img":false}]}
{"op":"mcm","clk":"11450300305","pt":1717320270344,"mc":[{"id":"1.229554912","rc":[{"atb":[[36,0]],"id":52385883}],"con":true,"img":false}]}
{"op":"mcm","clk":"11450300355","pt":1717320271225,"mc":[{"id":"1.229554912","rc":[{"atb":[[36,3.88],[38,2.7]],"id":52385883}],"con":true,"img":false}]}
{"op":"mcm","clk":"11450300929","pt":1717320279643,"mc":[{"id":"1.229554912","rc":[{"atb":[[36,0],[38,5.76]],"id":52385883}],"con":true,"img":false}]}
{"op":"mcm","clk":"11450301036","pt":1717320281471,"mc":[{"id":"1.229554912","rc":[{"atb":[[36,3.9],[38,2.7]],"id":52385883}],"con":true,"img":false}]}
{"op":"mcm","clk":"11450301916","pt":1717320295251,"mc":[{"id":"1.229554912","rc":[{"atb":[[36,0],[38,6.46]],"id":52385883}],"con":true,"img":false}]}
{"op":"mcm","clk":"11450302122","pt":1717320298792,"mc":[{"id":"1.229554912","rc":[{"atb":[[36,3.07],[38,2.7]],"id":52385883}],"con":true,"img":false}]}
{"op":"mcm","clk":"11450302217","pt":1717320300462,"mc":[{"id":"1.229554912","rc":[{"atb":[[38,6.22]],"id":52385883}],"con":true,"img":false}]}
{"op":"mcm","clk":"11450302225","pt":1717320300561,"mc":[{"id":"1.229554912","rc":[{"atb":[[36,0]],"id":52385883}],"con":true,"img":false}]}
{"op":"mcm","clk":"11450302360","pt":1717320302804,"mc":[{"id":"1.229554912","rc":[{"atb":[[36,3.37],[38,2.7]],"id":52385883}],"con":true,"img":false}]}
{"op":"mcm","clk":"11450302610","pt":1717320306195,"mc":[{"id":"1.229554912","rc":[{"atb":[[4.8,26.32],[3.9,0]],"id":52385910},{"atb":[[340,0],[240,0.11]],"id":52385912},{"atb":[[8.6,0],[11.5,0]],"id":52385918},{"atb":[[3.95,0],[4.9,0]],"id":52385887},{"atb":[[5.3,0],[6.6,0]],"id":52385889},{"atb":[[6.8,0],[8.8,0]],"id":52385914},{"atb":[[17,0],[24,0]],"id":52385883},{"atb":[[3.2,0],[3.7,0]],"id":52385885},{"atb":[[10,0],[15,0]],"id":52385894},{"atb":[[46,0],[28,0]],"id":52385896},{"atb":[[12,0],[8.8,0]],"id":52385929},{"atb":[[550,0],[650,0]],"id":52385890},{"atb":[[12,0],[8.8,0]],"id":52385892},{"atb":[[10,0],[15,0]],"id":52385925},{"atb":[[390,0],[490,0]],"id":52385900},{"atb":[[11,0],[8.4,0]],"id":52385911},{"atb":[[3.25,0],[3.75,0]],"id":52385886},{"atb":[[260,0.1],[360,0]],"id":52385919},{"atb":[[6.8,0],[8.8,0]],"id":52385921},{"atb":[[3.95,0],[4.9,0]],"id":52385882},{"atb":[[11,0],[8.4,0]],"id":52385915},{"atb":[[4.8,0],[3.9,0]],"id":52385917},{"atb":[[550,0],[650,0]],"id":52385926},{"atb":[[12,0],[8.8,0]],"id":52385928},{"atb":[[550,0],[650,0]],"id":52385897},{"atb":[[8.6,0],[11.5,0]],"id":52385922},{"atb":[[5.3,0],[6.6,0]],"id":52385924},{"atb":[[12,0],[8.8,0]],"id":52385893},{"atb":[[370,0],[470,0]],"id":52385899},{"atb":[[550,0],[650,0]],"id":52385901}],"con":true,"img":false}]}
{"op":"mcm","clk":"11450302890","pt":1717320310477,"mc":[{"id":"1.229554912","rc":[{"atb":[[36,0],[38,6.45]],"id":52385883}],"con":true,"img":false}]}
{"op":"mcm","clk":"11450303021","pt":1717320312296,"mc":[{"id":"1.229554912","rc":[{"atb":[[36,3.34],[38,2.7]],"id":52385883}],"con":true,"img":false}]}
{"op":"mcm","clk":"11450303925","pt":1717320326716,"mc":[{"id":"1.229554912","rc":[{"atb":[[4.8,53.82],[3.9,84.1]],"id":52385910},{"atb":[[340,0.3],[240,1.13]],"id":52385912},{"atb":[[8.6,32.09],[11.5,9.95]],"id":52385918},{"atb":[[3.95,82.67],[4.9,26.8]],"id":52385887},{"atb":[[5.3,56.72],[6.6,18.66]],"id":52385889},{"atb":[[6.8,42.05],[8.8,13.4]],"id":52385914},{"atb":[[17,15.24],[24,4.54]],"id":52385883},{"atb":[[3.2,110.86],[3.7,38.71]],"id":52385885},{"atb":[[10,27.1],[15,7.46]],"id":52385894},{"atb":[[46,2.32],[28,9.03]],"id":52385896},{"atb":[[12,9.5],[8.8,31.27]],"id":52385929},{"atb":[[550,0.44],[650,0.16]],"id":52385890},{"atb":[[12,9.5],[8.8,31.27]],"id":52385892},{"atb":[[10,27.1],[15,7.46]],"id":52385925},{"atb":[[390,0.62],[490,0.21]],"id":52385900},{"atb":[[11,10.45],[8.4,32.96]],"id":52385911},{"atb":[[3.25,108.4],[3.75,38]],"id":52385886},{"atb":[[260,1.04],[360,0.29]],"id":52385919},{"atb":[[6.8,42.05],[8.8,13.4]],"id":52385921},{"atb":[[3.95,82.67],[4.9,26.8]],"id":52385882},{"atb":[[11,10.45],[8.4,32.96]],"id":52385915},{"atb":[[4.8,27.5],[3.9,84.1]],"id":52385917},{"atb":[[550,0.44],[650,0.16]],"id":52385926},{"atb":[[12,9.5],[8.8,31.27]],"id":52385928},{"atb":[[550,0.44],[650,0.16]],"id":52385897},{"atb":[[8.6,32.09],[11.5,9.95]],"id":52385922},{"atb":[[5.3,56.72],[6.6,18.66]],"id":52385924},{"atb":[[12,9.5],[8.8,31.27]],"id":52385893},{"atb":[[370,0.65],[470,0.22]],"id":52385899},{"atb":[[550,0.44],[650,0.16]],"id":52385901}],"con":true,"img":false}]}
{"op":"mcm","clk":"11450307297","pt":1717320385476,"mc":[{"id":"1.229554912","rc":[{"atb":[[16,10.04],[14.5,11.5]],"id":52385918},{"atb":[[2.88,37.38],[3.15,0]],"id":52385885},{"atb":[[290,2]],"id":52385900},{"atb":[[14,4.02],[14.5,7.41]],"id":52385911},{"atb":[[2.98,35.68],[3.3,0]],"id":52385886},{"atb":[[350,0],[410,2]],"id":52385897},{"atb":[[350,0],[410,2]],"id":52385901}],"con":true,"img":false}]}
{"op":"mcm","clk":"11450307309","pt":1717320385583,"mc":[{"id":"1.229554912","rc":[{"atb":[[3.1,37.38]],"id":52385885},{"atb":[[240,0]],"id":52385900}],"con":true,"img":false}]}
{"op":"mcm","clk":"11450307317","pt":1717320385681,"mc":[{"id":"1.229554912","rc":[{"atb":[[2.88,0]],"id":52385885},{"atb":[[3.25,152.84],[2.98,0]],"id":52385886}],"con":true,"img":false}]}
{"op":"mcm","clk":"11450307326","pt":1717320385785,"mc":[{"id":"1.229554912","rc":[{"atb":[[7.6,0]],"id":52385910},{"atb":[[7.2,12.66]],"id":52385887},{"atb":[[11,4.08],[11.5,0]],"id":52385889},{"atl":[[34,0],[36,4.32]],"id":52385889},{"atb":[[13.5,0],[14,4.59]],"id":52385914},{"atb":[[6.4,0],[5.3,0],[5.2,0],[4.9,3.07],[5.7,0],[4.7,0]],"id":52385885},{"atl":[[95,0],[100,2.67]],"id":52385894},{"atb":[[270,0],[130,5.13],[140,0],[170,0],[220,0],[120,2.93]],"id":52385896},{"atb":[[36,0],[19,0],[22,0],[23,3.98],[28,0]],"id":52385929},{"atl":[[70,0],[75,3.49]],"id":52385892},{"atl":[[55,0],[60,2.9]],"id":52385911},{"atb":[[5.1,4.23],[5.5,0]],"id":52385886},{"atl":[[40,4.57]],"id":52385921},{"atb":[[6.8,3.18],[7,0]],"id":52385882},{"atl":[[13,0],[13.5,2.79]],"id":52385882},{"atb":[[8,0],[7.8,3.55]],"id":52385917},{"atb":[[34,0],[18.5,0],[21,0],[22,3.58],[27,0]],"id":52385928},{"atb":[[690,0],[740,0],[790,0]],"id":52385897},{"atb":[[19,0],[20,7.44]],"id":52385922},{"atb":[[11,3.63],[11.5,0]],"id":52385924},{"atb":[[36,0],[19,0],[22,0],[23,2.68],[28,0]],"id":52385893},{"atl":[[70,0],[75,3.74]],"id":52385893},{"atb":[[640,0],[690,0],[740,0],[790,0]],"id":52385901}],"con":true,"img":false}]}
{"op":"mcm","clk":"11450307335","pt":1717320385885,"mc":[{"id":"1.229554912","rc":[{"atl":[[9.6,0],[9.4,4.38]],"id":52385885},{"atb":[[130,3.13],[120,4.93]],"id":52385896},{"atb":[[17,0],[18,5.88]],"id":52385929},{"atl":[[70,0],[75,2.71]],"id":52385929},{"atl":[[95,0]],"id":52385925},{"atl":[[42,0]],"id":52385921},{"atl":[[70,0],[75,2.88]],"id":52385928},{"atb":[[17,0],[18,5.88]],"id":52385893}],"con":true,"img":false}]}
{"op":"mcm","clk":"11450307355","pt":1717320386197,"mc":[{"id":"1.229554912","rc":[{"atl":[[100,3.25]],"id":52385925},{"atl":[[55,0],[60,2.94]],"id":52385915}],"con":true,"img":false}]}
{"op":"mcm","clk":"11450307360","pt":1717320386297,"mc":[{"id":"1.229554912","rc":[{"atb":[[120,2]],"id":52385896}],"con":true,"img":false}]}
{"op":"mcm","clk":"11450307386","pt":1717320386664,"mc":[{"id":"1.229554912","rc":[{"atb":[[4.8,20.65],[4.3,31.71],[5.8,5.45],[5.3,12.17]],"id":52385885}],"con":true,"img":false}]}
{"op":"mcm","clk":"11450307392","pt":1717320386768,"mc":[{"id":"1.229554912","rc":[{"atb":[[260,0.1],[160,0.49],[210,0.25],[110,0.96]],"id":52385896},{"atb":[[36,0.75],[19,5.81],[23,3.57],[28,1.94]],"id":52385928},{"atb":[[720,0.11],[770,0.07],[820,0.03]],"id":52385897},{"atb":[[38,0.71],[19.5,5.66],[24,3.41],[29,1.87]],"id":52385893}],"con":true,"img":false}]}
{"op":"mcm","clk":"11450307433","pt":1717320387620,"mc":[{"id":"1.229554912","rc":[{"atb":[[7.6,3.62]],"id":52385910},{"atb":[[7.2,16.22]],"id":52385887},{"atb":[[11,0],[11.5,3.37]],"id":52385889},{"atb":[[13.5,4.13],[14,0]],"id":52385914},{"atb":[[4.8,0],[5.1,0],[4.3,0],[5.8,0],[5.3,4.27]],"id":52385885},{"atl":[[100,0]],"id":52385894},{"atb":[[260,0],[140,3.57],[160,0],[210,0],[110,0]],"id":52385896},{"atb":[[23,0]],"id":52385929},{"atl":[[100,0]],"id":52385925},{"atl":[[55,2.69],[60,0]],"id":52385911},{"atb":[[5.5,4.43],[5.2,0]],"id":52385886},{"atb":[[6.8,0],[7,3.75]],"id":52385882},{"atl":[[55,3.88],[60,0]],"id":52385915},{"atb":[[8,3.8],[7.8,0]],"id":52385917},{"atb":[[36,0],[19,0],[21,4.19],[22,0],[23,0],[28,0]],"id":52385928},{"atb":[[720,0],[770,0],[820,0]],"id":52385897},{"atb":[[19,3.86],[20,4.13]],"id":52385922},{"atb":[[11,0],[11.5,4.49]],"id":52385924},{"atb":[[22,4.55],[23,0]],"id":52385893}],"con":true,"img":false}]}
{"op":"mcm","clk":"11450307482","pt":1717320388299,"mc":[{"id":"1.229554912","rc":[{"atb":[[6.4,4.84],[5.2,18.68],[5.7,11.13],[4.7,28.28]],"id":52385885},{"atb":[[270,0.1],[170,0.47],[220,0.24],[120,2.88]],"id":52385896},{"atb":[[34,0.8],[18.5,5.98],[22,3.74],[27,2.01]],"id":52385928},{"atb":[[690,0.12],[740,0.07],[790,0.03]],"id":52385897}],"con":true,"img":false}]}
{"op":"mcm","clk":"11450307602","pt":1717320390683,"mc":[{"id":"1.229554912","rc":[{"atb":[[14,11.71],[14.5,0]],"id":52385911}],"con":true,"img":false}]}
{"op":"mcm","clk":"11450307623","pt":1717320390991,"mc":[{"id":"1.229554912","rc":[{"atb":[[17,6.25],[18,0]],"id":52385929}],"con":true,"img":false}]}
{"op":"mcm","clk":"11450307648","pt":1717320391512,"mc":[{"id":"1.229554912","rc":[{"atb":[[36,0.75],[19,5.81],[23,3.57],[28,1.94]],"id":52385929}],"con":true,"img":false}]}
{"op":"mcm","clk":"11450307657","pt":1717320391614,"mc":[{"id":"1.229554912","rc":[{"atb":[[640,0.16],[690,0.12],[740,0.07],[790,0.03]],"id":52385901}],"con":true,"img":false}]}
{"op":"mcm","clk":"11450307722","pt":1717320392605,"mc":[{"id":"1.229554912","rc":[{"atb":[[38,0],[19.5,0],[24,0],[29,0]],"id":52385893}],"con":true,"img":false}]}
{"op":"mcm","clk":"11450307755","pt":1717320393277,"mc":[{"id":"1.229554912","rc":[{"atb":[[36,0.75],[19,5.81],[23,3.57],[28,1.94]],"id":52385893}],"con":true,"img":false}]}
{"op":"mcm","clk":"11450307871","pt":1717320395809,"mc":[{"id":"1.229554912","rc":[{"atl":[[95,2.8]],"id":52385894},{"atl":[[70,3.91],[75,0]],"id":52385892},{"atl":[[40,0],[42,3.56]],"id":52385921}],"con":true,"img":false}]}
{"op":"mcm","clk":"11450307875","pt":1717320395912,"mc":[{"id":"1.229554912","rc":[{"atb":[[22,3.89]],"id":52385929},{"atl":[[70,2.89],[75,0]],"id":52385929}],"con":true,"img":false}]}
{"op":"mcm","clk":"11450307890","pt":1717320396172,"mc":[{"id":"1.229554912","rc":[{"atl":[[95,3.91]],"id":52385925}],"con":true,"img":false}]}
{"op":"mcm","clk":"11450307952","pt":1717320397518,"mc":[{"id":"1.229554912","rc":[{"atl":[[34,4.29],[36,0]],"id":52385889},{"atl":[[9.4,0]],"id":52385885},{"atl":[[70,3.23],[75,0]],"id":52385928},{"atl":[[70,4.35]],"id":52385893}],"con":true,"img":false}]}
{"op":"mcm","clk":"11450307960","pt":1717320397614,"mc":[{"id":"1.229554912","rc":[{"atb":[[5.1,3.69]],"id":52385885},{"atl":[[9.6,4.17]],"id":52385885},{"atb":[[5.3,3.57]],"id":52385886},{"atl":[[13,2.76],[13.5,0]],"id":52385882},{"atl":[[75,0]],"id":52385893}],"con":true,"img":false}]}
{"op":"mcm","clk":"11450308005","pt":1717320398394,"mc":[{"id":"1.229554912","rc":[{"atl":[[34,0],[36,3.9]],"id":52385889},{"atb":[[6.4,0],[5.3,0],[5.2,3.29],[5.7,0],[4.7,0]],"id":52385885},{"atl":[[9.6,0],[9.4,3.44]],"id":52385885},{"atl":[[95,0]],"id":52385894},{"atl":[[70,0],[75,4.16]],"id":52385929},{"atl":[[70,0],[75,2.62]],"id":52385892},{"atl":[[95,0]],"id":52385925},{"atb":[[5.5,0],[5.4,22.1]],"id":52385886},{"atl":[[40,3.32],[42,0]],"id":52385921},{"atl":[[13,0],[13.5,3.71]],"id":52385882},{"atb":[[8,0],[7.8,4.65]],"id":52385917},{"atl":[[70,0],[75,3.32]],"id":52385928},{"atb":[[19,0],[19.5,3.85]],"id":52385922},{"atl":[[70,0],[75,3.24]],"id":52385893}],"con":true,"img":false}]}
{"op":"mcm","clk":"11450308027","pt":1717320398836,"mc":[{"id":"1.229554912","rc":[{"atb":[[2.86,41.08],[3.1,0]],"id":52385885},{"atb":[[14,4.02],[14.5,7.41]],"id":52385911}],"con":true,"img":false}]}
{"op":"mcm","clk":"11450308049","pt":1717320399099,"mc":[{"id":"1.229554912","rc":[{"atb":[[7.6,0]],"id":52385910},{"atb":[[7.2,12.66]],"id":52385887},{"atb":[[11,3.14],[11.5,0]],"id":52385889},{"atb":[[13.5,0],[14,4.37]],"id":52385914},{"atb":[[4.8,20.65],[5.1,0],[4.3,31.71],[5.8,5.45],[5.3,12.17]],"id":52385885},{"atb":[[270,0],[140,0],[170,0],[220,0],[120,2]],"id":52385896},{"atb":[[22,0],[23,8.01]],"id":52385929},{"atb":[[5.3,0],[5.2,4.3]],"id":52385886},{"atb":[[6.8,4.15],[7,0]],"id":52385882},{"atb":[[21,0],[22,7.76]],"id":52385928},{"atb":[[20,7.47]],"id":52385922},{"atb":[[11,4.64],[11.5,0]],"id":52385924},{"atb":[[22,0],[23,6.34]],"id":52385893}],"con":true,"img":false}]}
{"op":"mcm","clk":"11450308093","pt":1717320399817,"mc":[{"id":"1.229554912","rc":[{"atb":[[260,0.1],[160,0.49],[210,0.25],[110,0.96]],"id":52385896}],"con":true,"img":false}]}
{"op":"mcm","clk":"11450308123","pt":1717320400340,"mc":[{"id":"1.229554912","rc":[{"atb":[[2.86,0],[3.05,41.08]],"id":52385885},{"atb":[[14,11.71],[14.5,0]],"id":52385911}],"con":true,"img":false}]}
{"op":"mcm","clk":"11450308144","pt":1717320400600,"mc":[{"id":"1.229554912","rc":[{"atb":[[7.6,2.94]],"id":52385910},{"atb":[[7.2,16.16]],"id":52385887},{"atb":[[11,0],[11.5,2.91]],"id":52385889},{"atb":[[13.5,4.23]],"id":52385914},{"atb":[[140,4.15]],"id":52385896},{"atb":[[22,4.11],[23,3.57]],"id":52385929},{"atb":[[5.1,0]],"id":52385886},{"atb":[[6.8,0],[7,3.66]],"id":52385882},{"atb":[[21,4.46],[22,3.74]],"id":52385928},{"atb":[[20,4.13]],"id":52385922},{"atb":[[11,0],[11.5,2.92]],"id":52385924},{"atb":[[22,3.56],[23,3.57]],"id":52385893}],"con":true,"img":false}]}
{"op":"mcm","clk":"11450308154","pt":1717320400704,"mc":[{"id":"1.229554912","rc":[{"atb":[[14,0]],"id":52385914}],"con":true,"img":false}]}
{"op":"mcm","clk":"11450308510","pt":1717320405919,"mc":[{"id":"1.229554912","rc":[{"atl":[[130,3.16]],"id":52385894}],"con":true,"img":false}]}
{"op":"mcm","clk":"11450308525","pt":1717320406228,"mc":[{"id":"1.229554912","rc":[{"atl":[[130,2.81]],"id":52385925}],"con":true,"img":false}]}
{"op":"mcm","clk":"11450308597","pt":1717320407418,"mc":[{"id":"1.229554912","rc":[{"atb":[[2.86,41.32]],"id":52385885},{"atb":[[14,4.02],[14.5,7.41]],"id":52385911}],"con":true,"img":false}]}
{"op":"mcm","clk":"11450308602","pt":1717320407521,"mc":[{"id":"1.229554912","rc":[{"atb":[[3.05,0]],"id":52385885}],"con":true,"img":false}]}
{"op":"mcm","clk":"11450308618","pt":1717320407724,"mc":[{"id":"1.229554912","rc":[{"atb":[[7.6,0]],"id":52385910},{"atb":[[7.2,12.66]],"id":52385887},{"atb":[[11,3.23],[11.5,0]],"id":52385889},{"atb":[[13.5,0],[14,4.16]],"id":52385914},{"atb":[[140,0]],"id":52385896},{"atb":[[22,0],[23,8.27]],"id":52385929},{"atb":[[5.4,17.84]],"id":52385886},{"atb":[[6.8,3.2],[7,0]],"id":52385882},{"atb":[[21,0],[22,6.73]],"id":52385928},{"atb":[[19.5,0],[20,7.66]],"id":52385922},{"atb":[[11,2.67],[11.5,0]],"id":52385924},{"atb":[[22,0],[23,7.78]],"id":52385893}],"con":true,"img":false}]}
{"op":"mcm","clk":"11450308624","pt":1717320407825,"mc":[{"id":"1.229554912","rc":[{"atb":[[5.2,0]],"id":52385885}],"con":true,"img":false}]}
{"op":"mcm","clk":"11450308698","pt":1717320409122,"mc":[{"id":"1.229554912","rc":[{"atb":[[7.6,4.34]],"id":52385910},{"atb":[[7.2,17.31]],"id":52385887},{"atb":[[11,0],[11.5,3.34]],"id":52385889},{"atb":[[13.5,2.7],[14,0]],"id":52385914},{"atb":[[5.3,14.88]],"id":52385885},{"atb":[[140,4.23]],"id":52385896},{"atb":[[22,2.78],[23,3.57]],"id":52385929},{"atb":[[5.4,21.81]],"id":52385886},{"atb":[[6.8,0],[7,2.64]],"id":52385882},{"atb":[[21,3.42],[22,3.74]],"id":52385928},{"atb":[[19.5,4.5],[20,4.13]],"id":52385922},{"atb":[[11,0],[11.5,3.04]],"id":52385924},{"atb":[[22,3.93],[23,3.57]],"id":52385893}],"con":true,"img":false}]}
{"op":"mcm","clk":"11450308704","pt":1717320409226,"mc":[{"id":"1.229554912","rc":[{"atl":[[90,0]],"id":52385914}],"con":true,"img":false}]}
{"op":"mcm","clk":"11450308718","pt":1717320409430,"mc":[{"id":"1.229554912","rc":[{"atb":[[16,6.67],[16.5,2.96],[17,0],[19.5,0],[24,0],[14.5,3.75]],"id":52385918},{"atl":[[16,2.73],[17.5,0]],"id":52385887},{"atb":[[38,0],[48,0],[24,4.35],[29,0]],"id":52385894},{"atb":[[16.5,6.45],[17.5,0],[18.5,2.71],[20,0],[25,0],[15,0]],"id":52385892},{"atb":[[36,0],[46,0],[23,0],[27,0],[28,2.74]],"id":52385925},{"atb":[[16.5,0],[9.6,0],[11.5,0],[13,3.72],[14,0]],"id":52385911},{"atl":[[12.5,4.64],[14,0]],"id":52385886},{"atb":[[17.5,0],[20,0],[12.5,4.57],[13.5,0],[14,4.38],[15,0]],"id":52385921},{"atb":[[8.6,0],[6.4,4.25],[5.8,0],[7.6,0],[6.6,4.16]],"id":52385882},{"atb":[[16,0],[18.5,0],[19,2.74],[22,0],[27,0]],"id":52385915},{"atl":[[24,4.61],[25,0]],"id":52385917},{"atl":[[48,0],[50,4.39]],"id":52385924}],"con":true,"img":false}]}
{"op":"mcm","clk":"11450308724","pt":1717320409533,"mc":[{"id":"1.229554912","rc":[{"atb":[[7.4,3.29]],"id":52385910},{"atl":[[430,0]],"id":52385912},{"atb":[[14.5,3.68]],"id":52385914},{"atl":[[40,0]],"id":52385914},{"atb":[[5,2.81]],"id":52385885},{"atb":[[28,0],[29,2.63]],"id":52385894},{"atl":[[760,3.15],[770,0]],"id":52385890},{"atb":[[16.5,0],[17,6.25]],"id":52385892},{"atb":[[29,4.56]],"id":52385925},{"atl":[[55,0],[60,3.82]],"id":52385911},{"atl":[[460,0],[450,3.98]],"id":52385919},{"atb":[[10,0],[11,10]],"id":52385921},{"atl":[[40,0],[42,3.47]],"id":52385921},{"atb":[[17.5,0],[19.5,2.92],[14,0],[15,7.14]],"id":52385915},{"atl":[[55,0],[60,4.16]],"id":52385915},{"atl":[[760,4.51],[770,0]],"id":52385926}],"con":true,"img":false}]}
{"op":"mcm","clk":"11450308762","pt":1717320410110,"mc":[{"id":"1.229554912","rc":[{"atb":[[17.5,4.76],[20,2.75],[25,1.09],[15,7.48]],"id":52385918},{"atb":[[40,1.34],[50,0.53],[25,4.36],[30,2.71]],"id":52385894},{"atb":[[16.5,6.75],[19,4.36],[23,2.38],[28,0.97]],"id":52385892},{"atb":[[40,1.34],[25,8.97],[50,0.53],[30,2.71]],"id":52385925},{"atb":[[16.5,3.37],[19,1.45],[11.5,9.97],[14,6.04]],"id":52385911},{"atb":[[18,3.08],[21,1.31],[13,8.72],[15.5,5.41]],"id":52385921},{"atb":[[17.5,6.34],[20,4.13],[25,2.18],[30,0.9]],"id":52385915}],"con":true,"img":false}]}
{"op":"mcm","clk":"11450308768","pt":1717320410213,"mc":[{"id":"1.229554912","rc":[{"atb":[[6.8,9.02],[7.8,3.85],[5.9,16.01],[5.4,23.78]],"id":52385882}],"con":true,"img":false}]}
{"op":"mcm","clk":"11450309109","pt":1717320416072,"mc":[{"id":"1.229554912","rc":[{"atb":[[7.6,0]],"id":52385910},{"atl":[[430,4.05]],"id":52385912},{"atb":[[7.2,12.66]],"id":52385887},{"atb":[[11,4.34],[11.5,0]],"id":52385889},{"atb":[[12.5,9.1]],"id":52385914},{"atl":[[40,2.84]],"id":52385914},{"atl":[[100,4.23],[110,0]],"id":52385883},{"atb":[[5.3,12.17]],"id":52385885},{"atb":[[140,0]],"id":52385896},{"atb":[[22,0],[23,6.56]],"id":52385929},{"atl":[[760,0],[800,3.73]],"id":52385890},{"atb":[[25,4.36]],"id":52385925},{"atb":[[5.4,17.84]],"id":52385886},{"atl":[[430,3.52],[450,0]],"id":52385919},{"atl":[[40,4.36],[42,0]],"id":52385921},{"atb":[[7,0],[6.6,0]],"id":52385882},{"atb":[[16.5,0]],"id":52385915},{"atl":[[760,0],[800,3.79]],"id":52385926},{"atb":[[21,0],[22,6.83]],"id":52385928},{"atb":[[19.5,0],[20,8.46]],"id":52385922},{"atb":[[11,3.6],[11.5,0]],"id":52385924},{"atl":[[48,4.2],[50,0]],"id":52385924},{"atb":[[22,0],[23,6.62]],"id":52385893}],"con":true,"img":false}]}
{"op":"mcm","clk":"11450309281","pt":1717320419076,"mc":[{"id":"1.229554912","rc":[{"atb":[[110,4.03]],"id":52385896}],"con":true,"img":false}]}
{"op":"mcm","clk":"11450309310","pt":1717320419490,"mc":[{"id":"1.229554912","rc":[{"atb":[[15.5,4.31]],"id":52385918},{"atb":[[6.4,3.75]],"id":52385887},{"atl":[[17,3.96]],"id":52385887},{"atb":[[17.5,4.08]],"id":52385892},{"atb":[[12,3.4]],"id":52385911},{"atb":[[5,3.68]],"id":52385886},{"atl":[[13.5,3.18]],"id":52385886},{"atb":[[6,4.2]],"id":52385882}],"con":true,"img":false}]}
{"op":"mcm","clk":"11450309765","pt":1717320425999,"mc":[{"id":"1.229554912","rc":[{"atl":[[450,3.69]],"id":52385919},{"atl":[[820,2.68]],"id":52385926}],"con":true,"img":false}]}
{"op":"mcm","clk":"11450309772","pt":1717320426104,"mc":[{"id":"1.229554912","rc":[{"atl":[[790,0],[820,3.82]],"id":52385890},{"atl":[[790,0]],"id":52385926}],"con":true,"img":false}]}
{"op":"mcm","clk":"11450309885","pt":1717320427501,"mc":[{"id":"1.229554912","rc":[{"atb":[[2.86,0],[3,41.32]],"id":52385885},{"atb":[[14.5,0],[15.5,6.04]],"id":52385911},{"atb":[[290,2]],"id":52385899}],"con":true,"img":false}]}
{"op":"mcm","clk":"11450309897","pt":1717320427618,"mc":[{"id":"1.229554912","rc":[{"atb":[[240,0]],"id":52385899}],"con":true,"img":false}]}
{"op":"mcm","clk":"11450309917","pt":1717320427925,"mc":[{"id":"1.229554912","rc":[{"atb":[[7.4,0],[7.8,2.83]],"id":52385910},{"atb":[[14.5,0]],"id":52385918},{"atb":[[6.8,0],[6.6,4.59]],"id":52385887},{"atl":[[18.5,0]],"id":52385887},{"atb":[[14.5,0],[15,8.95]],"id":52385914},{"atb":[[5.1,4.18],[5,0]],"id":52385885},{"atb":[[22,4.6]],"id":52385929},{"atb":[[15.5,0]],"id":52385892},{"atb":[[10.5,0]],"id":52385911},{"atb":[[5.1,4.39],[5.2,0]],"id":52385886},{"atl":[[15,0]],"id":52385886},{"atb":[[19.5,0],[20,7.66]],"id":52385915},{"atb":[[22,4.14]],"id":52385893}],"con":true,"img":false}]}
{"op":"mcm","clk":"11450309925","pt":1717320427977,"mc":[{"id":"1.229554912","rc":[{"atb":[[32,4.59],[80,0],[42,0],[55,0]],"id":52385883},{"atb":[[23,3.57]],"id":52385929},{"atl":[[490,0]],"id":52385919},{"atb":[[23,3.57]],"id":52385893}],"con":true,"img":false}]}
{"op":"mcm","clk":"11450309932","pt":1717320428136,"mc":[{"id":"1.229554912","rc":[{"atb":[[36,6.2],[38,0]],"id":52385883}],"con":true,"img":false}]}
{"op":"mcm","clk":"11450309982","pt":1717320428809,"mc":[{"id":"1.229554912","rc":[{"atb":[[75,0.36],[40,2.01],[50,1.07],[30,3.61]],"id":52385883}],"con":true,"img":false}]}
{"op":"mcm","clk":"11450310100","pt":1717320430628,"mc":[{"id":"1.229554912","rc":[{"atb":[[24,0],[27,3.85]],"id":52385894},{"atb":[[18.5,7.49]],"id":52385892},{"atb":[[24,0],[27,3.85]],"id":52385925},{"atb":[[16,6.04],[15.5,0]],"id":52385911},{"atb":[[3.25,108.4],[2.94,28.52]],"id":52385886},{"atb":[[18.5,11.69]],"id":52385928}],"con":true,"img":false}]}
{"op":"mcm","clk":"11450310113","pt":1717320430725,"mc":[{"id":"1.229554912","rc":[{"atb":[[17,0]],"id":52385892},{"atb":[[16.5,0]],"id":52385928}],"con":true,"img":false}]}
{"op":"mcm","clk":"11450310137","pt":1717320431033,"mc":[{"id":"1.229554912","rc":[{"atb":[[6.8,3.75],[6.6,0]],"id":52385887},{"atb":[[11,0],[11.5,3.15]],"id":52385889},{"atb":[[14.5,3.54],[15,5.6]],"id":52385914},{"atb":[[75,0],[40,0],[50,0],[30,0]],"id":52385883},{"atb":[[5.1,0],[5,4.62]],"id":52385885},{"atb":[[29,0],[30,6.15]],"id":52385894},{"atb":[[22,0],[23,6.82]],"id":52385929},{"atb":[[5.1,0]],"id":52385886},{"atb":[[22,3.74],[23,2.61]],"id":52385928},{"atb":[[20,4.13],[21,4.12]],"id":52385922},{"atb":[[11,0],[11.5,2.81]],"id":52385924},{"atb":[[22,0],[23,7.39]],"id":52385893}],"con":true,"img":false}]}
{"op":"mcm","clk":"11450310194","pt":1717320431710,"mc":[{"id":"1.229554912","rc":[{"atb":[[70,0.38],[38,2.12],[48,1.11],[29,3.74]],"id":52385883}],"con":true,"img":false}]}
{"op":"mcm","clk":"11450310208","pt":1717320432024,"mc":[{"id":"1.229554912","rc":[{"atl":[[19.5,0],[19,4.64]],"id":52385910},{"atl":[[9.2,3.19]],"id":52385885},{"atl":[[13.5,0]],"id":52385882}],"con":true,"img":false}]}
{"op":"mcm","clk":"11450310214","pt":1717320432117,"mc":[{"id":"1.229554912","rc":[{"atb":[[36,2.86]],"id":52385883},{"atl":[[9.4,0]],"id":52385885},{"atl":[[13,4.38]],"id":52385882}],"con":true,"img":false}]}
{"op":"mcm","clk":"11450310309","pt":1717320433318,"mc":[{"id":"1.229554912","rc":[{"atb":[[36,6.58]],"id":52385883}],"con":true,"img":false}]}
{"op":"mcm","clk":"11450310528","pt":1717320436895,"mc":[{"id":"1.229554912","rc":[{"atb":[[4.8,26.32],[3.9,0]],"id":52385910},{"atb":[[340,0],[240,0.11]],"id":52385912},{"atb":[[8.6,0],[11.5,0]],"id":52385918},{"atb":[[3.95,0],[4.9,0]],"id":52385887},{"atb":[[5.3,0],[6.6,0]],"id":52385889},{"atb":[[6.8,0],[8.8,0]],"id":52385914},{"atb":[[17,0],[24,0]],"id":52385883},{"atb":[[3.2,0],[3.7,0]],"id":52385885},{"atb":[[10,0],[15,0]],"id":52385894},{"atb":[[46,0],[28,0]],"id":52385896},{"atb":[[12,0],[8.8,0]],"id":52385929},{"atb":[[550,0],[650,0]],"id":52385890},{"atb":[[12,0],[8.8,0]],"id":52385892},{"atb":[[10,0],[15,0]],"id":52385925},{"atb":[[390,0],[490,0]],"id":52385900},{"atb":[[11,0],[8.4,0]],"id":52385911},{"atb":[[3.25,0],[3.75,0]],"id":52385886},{"atb":[[260,0.1],[360,0]],"id":52385919},{"atb":[[6.8,0],[8.8,0]],"id":52385921},{"atb":[[3.95,0],[4.9,0]],"id":52385882},{"atb":[[11,0],[8.4,0]],"id":52385915},{"atb":[[4.8,0],[3.9,0]],"id":52385917},{"atb":[[550,0],[650,0]],"id":52385926},{"atb":[[12,0],[8.8,0]],"id":52385928},{"atb":[[550,0],[650,0]],"id":52385897},{"atb":[[8.6,0],[11.5,0]],"id":52385922},{"atb":[[5.3,0],[6.6,0]],"id":52385924},{"atb":[[12,0],[8.8,0]],"id":52385893},{"atb":[[370,0],[470,0]],"id":52385899},{"atb":[[550,0],[650,0]],"id":52385901}],"con":true,"img":false}]}
{"op":"mcm","clk":"11450310547","pt":1717320437310,"mc":[{"id":"1.229554912","rc":[{"atb":[[210,0],[220,4.57]],"id":52385897},{"atb":[[220,2.71]],"id":52385901}],"con":true,"img":false}]}
{"op":"mcm","clk":"11450310555","pt":1717320437413,"mc":[{"id":"1.229554912","rc":[{"atb":[[130,0],[140,4.19]],"id":52385912},{"atb":[[130,0],[140,3.79]],"id":52385919},{"atb":[[210,0]],"id":52385901}],"con":true,"img":false}]}
{"op":"mcm","clk":"11450310573","pt":1717320437781,"mc":[{"id":"1.229554912","rc":[{"atb":[[4.8,3.8]],"id":52385886}],"con":true,"img":false}]}
{"op":"mcm","clk":"11450310630","pt":1717320438780,"mc":[{"id":"1.229554912","rc":[{"atb":[[2.88,24.34]],"id":52385885}],"con":true,"img":false}]}
{"op":"mcm","clk":"11450310635","pt":1717320438884,"mc":[{"id":"1.229554912","rc":[{"atb":[[3,0]],"id":52385885},{"atb":[[17,0],[19,11.37]],"id":52385929}],"con":true,"img":false}]}
{"op":"mcm","clk":"11450310654","pt":1717320439197,"mc":[{"id":"1.229554912","rc":[{"atb":[[130,4.3],[140,0.57]],"id":52385912},{"atb":[[70,0],[38,0],[48,0],[29,0]],"id":52385883},{"atb":[[23,3.57],[24,3.11]],"id":52385929},{"atb":[[170,0],[180,3.63]],"id":52385890},{"atb":[[170,0],[180,3.93]],"id":52385926},{"atb":[[23,3.57],[24,4.15]],"id":52385893}],"con":true,"img":false}]}
{"op":"mcm","clk":"11450310663","pt":1717320439306,"mc":[{"id":"1.229554912","rc":[{"atb":[[7.6,3.31],[7.8,0]],"id":52385910},{"atb":[[5,0]],"id":52385885}],"con":true,"img":false}]}
{"op":"mcm","clk":"11450310672","pt":1717320439412,"mc":[{"id":"1.229554912","rc":[{"atb":[[34,3.03],[36,3.72]],"id":52385883}],"con":true,"img":false}]}
{"op":"mcm","clk":"11450310703","pt":1717320439826,"mc":[{"id":"1.229554912","rc":[{"atl":[[40,0]],"id":52385914},{"atb":[[36,0]],"id":52385883},{"atl":[[95,4.35],[100,0]],"id":52385883},{"atl":[[9,3.12],[9.2,0]],"id":52385885},{"atl":[[40,0],[42,4.61]],"id":52385921}],"con":true,"img":false}]}
{"op":"mcm","clk":"11450310711","pt":1717320439930,"mc":[{"id":"1.229554912","rc":[{"atb":[[75,0.36],[40,2.01],[50,1.07],[30,3.61]],"id":52385883}],"con":true,"img":false}]}
{"op":"mcm","clk":"11450310790","pt":1717320440921,"mc":[{"id":"1.229554912","rc":[{"atl":[[46,4.1]],"id":52385914},{"atb":[[28,3.31]],"id":52385894},{"atb":[[21,4.35]],"id":52385928},{"atb":[[19.5,3.98]],"id":52385922}],"con":true,"img":false}]}
{"op":"mcm","clk":"11450310861","pt":1717320441806,"mc":[{"id":"1.229554912","rc":[{"atb":[[36,3.98]],"id":52385883},{"atb":[[26,0]],"id":52385894},{"atb":[[19.5,0]],"id":52385928},{"atb":[[18.5,0]],"id":52385922}],"con":true,"img":false}]}
{"op":"mcm","clk":"11450311032","pt":1717320444142,"mc":[{"id":"1.229554912","rc":[{"atl":[[19,0],[19.5,3.29]],"id":52385910},{"atl":[[430,0],[460,2.72]],"id":52385912},{"atl":[[36,0]],"id":52385889},{"atl":[[95,0],[100,4.24]],"id":52385883},{"atl":[[9,0],[9.2,3.04]],"id":52385885},{"atl":[[75,0],[80,3.14]],"id":52385929},{"atl":[[800,0],[860,4.61]],"id":52385890},{"atl":[[75,0]],"id":52385892},{"atl":[[430,0],[460,4.52]],"id":52385919},{"atl":[[800,0],[860,3.35]],"id":52385926},{"atl":[[75,0]],"id":52385928},{"atl":[[75,0],[80,2.64]],"id":52385893}],"con":true,"img":false}]}
{"op":"mcm","clk":"11450311473","pt":1717320450885,"mc":[{"id":"1.229554912","rc":[{"atl":[[90,2.8]],"id":52385928}],"con":true,"img":false}]}
{"op":"mcm","clk":"11450311508","pt":1717320451512,"mc":[{"id":"1.229554912","rc":[{"atl":[[450,0]],"id":52385912},{"atl":[[820,0]],"id":52385890},{"atl":[[450,0]],"id":52385919},{"atl":[[820,0]],"id":52385926}],"con":true,"img":false}]}
{"op":"mcm","clk":"11450311519","pt":1717320451715,"mc":[{"id":"1.229554912","rc":[{"atl":[[42,2.77]],"id":52385889}],"con":true,"img":false}]}
{"op":"mcm","clk":"11450311528","pt":1717320451821,"mc":[{"id":"1.229554912","rc":[{"atl":[[90,2.68]],"id":52385892}],"con":true,"img":false}]}
{"op":"mcm","clk":"11450311677","pt":1717320454113,"mc":[{"id":"1.229554912","rc":[{"atl":[[480,3.35]],"id":52385912},{"atb":[[4.7,4.34]],"id":52385885},{"atl":[[9.6,3.93]],"id":52385885},{"atb":[[22,2.62]],"id":52385929},{"atl":[[880,3.19]],"id":52385890},{"atl":[[480,4.34]],"id":52385919},{"atl":[[880,4.1]],"id":52385926},{"atb":[[22,4.7]],"id":52385893}],"con":true,"img":false}]}
{"op":"mcm","clk":"11450311739","pt":1717320455319,"mc":[{"id":"1.229554912","rc":[{"atb":[[4.8,53.82],[3.9,84.1]],"id":52385910},{"atb":[[280,0.87],[380,0.27]],"id":52385912},{"atb":[[12,9.5],[8.8,31.27]],"id":52385918},{"atb":[[4.8,27.5],[3.9,84.1]],"id":52385887},{"atb":[[6.4,19.35],[5.2,58.07]],"id":52385889},{"atb":[[7.2,39.33],[9.2,12.74]],"id":52385914},{"atb":[[17,15.24],[24,4.54]],"id":52385883},{"atb":[[3.15,113.44],[3.65,39.44]],"id":52385885},{"atb":[[10.5,25.67],[15.5,7.2]],"id":52385894},{"atb":[[46,2.32],[28,9.03]],"id":52385896},{"atb":[[9,30.48],[12.5,9.08]],"id":52385929},{"atb":[[550,0.44],[650,0.16]],"id":52385890},{"atb":[[9,30.48],[12.5,9.08]],"id":52385892},{"atb":[[10.5,25.67],[15.5,7.2]],"id":52385925},{"atb":[[520,0.19],[420,0.58]],"id":52385900},{"atb":[[12,12.9],[8.8,31.27]],"id":52385911},{"atb":[[3.15,113.44],[3.65,39.44]],"id":52385886},{"atb":[[280,0.87],[380,0.27]],"id":52385919},{"atb":[[7.2,39.33],[9.2,12.74]],"id":52385921},{"atb":[[4.8,27.5],[3.9,84.1]],"id":52385882},{"atb":[[12,9.5],[8.8,31.27]],"id":52385915},{"atb":[[4.8,27.5],[3.9,84.1]],"id":52385917},{"atb":[[550,0.44],[650,0.16]],"id":52385926},{"atb":[[9,30.48],[12.5,9.08]],"id":52385928},{"atb":[[550,0.44],[650,0.16]],"id":52385897},{"atb":[[12,9.5],[8.8,31.27]],"id":52385922},{"atb":[[6.4,19.35],[5.2,58.07]],"id":52385924},{"atb":[[9,30.48],[12.5,9.08]],"id":52385893},{"atb":[[520,0.19],[420,0.58]],"id":52385899},{"atb":[[550,0.44],[650,0.16]],"id":52385901}],"con":true,"img":false}]}
{"op":"mcm","clk":"11450311760","pt":1717320455627,"mc":[{"id":"1.229554912","rc":[{"atl":[[10,0]],"id":52385885},{"atb":[[20,0]],"id":52385929},{"atb":[[20,0]],"id":52385893}],"con":true,"img":false}]}
{"op":"mcm","clk":"11450312208","pt":1717320463151,"mc":[{"id":"1.229554912","rc":[{"atb":[[34,0],[18.5,5.71],[22,0],[27,0]],"id":52385928},{"atb":[[690,0],[740,0],[790,0]],"id":52385897}],"con":true,"img":false}]}
{"op":"mcm","clk":"11450312249","pt":1717320463831,"mc":[{"id":"1.229554912","rc":[{"atb":[[38,0.71],[19.5,5.66],[24,3.41],[29,1.87]],"id":52385928},{"atb":[[740,0.1],[790,0.07],[840,0.03]],"id":52385897}],"con":true,"img":false}]}
{"op":"mcm","clk":"11450312267","pt":1717320464132,"mc":[{"id":"1.229554912","rc":[{"atl":[[9,2.83],[9.2,0]],"id":52385885}],"con":true,"img":false}]}
{"op":"mcm","clk":"11450312374","pt":1717320465651,"mc":[{"id":"1.229554912","rc":[{"atl":[[19.5,0],[20,2.68]],"id":52385910},{"atl":[[12.5,3.36],[13,0]],"id":52385882}],"con":true,"img":false}]}
{"op":"mcm","clk":"11450312428","pt":1717320466045,"mc":[{"id":"1.229554912","rc":[{"atb":[[36,0],[19,5.56],[23,0],[28,0]],"id":52385929}],"con":true,"img":false}]}
{"op":"mcm","clk":"11450312435","pt":1717320466155,"mc":[{"id":"1.229554912","rc":[{"atb":[[640,0],[690,0],[740,0],[790,0]],"id":52385901}],"con":true,"img":false}]}
{"op":"mcm","clk":"11450312478","pt":1717320466724,"mc":[{"id":"1.229554912","rc":[{"atb":[[40,0.67],[20,5.51],[25,3.27],[30,1.81]],"id":52385929}],"con":true,"img":false}]}
{"op":"mcm","clk":"11450312484","pt":1717320466832,"mc":[{"id":"1.229554912","rc":[{"atb":[[690,0.15],[740,0.1],[790,0.07],[840,0.03]],"id":52385901}],"con":true,"img":false}]}
{"op":"mcm","clk":"11450312818","pt":1717320473058,"mc":[{"id":"1.229554912","rc":[{"atl":[[36,4.19],[38,0]],"id":52385889},{"atl":[[42,0],[44,2.96]],"id":52385914},{"atl":[[42,0]],"id":52385921}],"con":true,"img":false}]}
{"op":"mcm","clk":"11450313355","pt":1717320483046,"mc":[{"id":"1.229554912","rc":[{"atl":[[48,2.95],[1000,0.16]],"id":52385921}],"con":true,"img":false}]}
{"op":"mcm","clk":"11450313382","pt":1717320483457,"mc":[{"id":"1.229554912","rc":[{"atb":[[14,9.39]],"id":52385921},{"atl":[[30,5]],"id":52385921}],"con":true,"img":false}]}
{"op":"mcm","clk":"11450313410","pt":1717320483875,"mc":[{"id":"1.229554912","rc":[{"atb":[[10,12.17],[10.5,5]],"id":52385910},{"atl":[[18,5],[21,11.26]],"id":52385910},{"atb":[[17.5,9.76]],"id":52385918},{"atl":[[42,5]],"id":52385918},{"atb":[[9.2,14.34],[9.4,5]],"id":52385887},{"atl":[[16,13.41],[16.5,5]],"id":52385887},{"atb":[[16,5],[17,11.64]],"id":52385889},{"atl":[[36,8.77],[30,5]],"id":52385889},{"atb":[[15.5,5]],"id":52385914},{"atl":[[44,6.69],[30,5]],"id":52385914},{"atb":[[5.8,15.98],[6,5]],"id":52385885},{"atl":[[9,13.36],[8.4,5]],"id":52385885},{"atb":[[32,5]],"id":52385894},{"atl":[[70,5],[100,1.61]],"id":52385894},{"atb":[[32,5]],"id":52385929},{"atl":[[80,8.15]],"id":52385929},{"atb":[[19.5,5]],"id":52385892},{"atl":[[75,2.16],[50,5]],"id":52385892},{"atl":[[75,5]],"id":52385925},{"atl":[[40,5]],"id":52385911},{"atb":[[6.8,18.65],[7.6,5]],"id":52385886},{"atl":[[12.5,23.58]],"id":52385886},{"atb":[[6.2,5]],"id":52385882},{"atl":[[10.5,5],[12,12.13]],"id":52385882},{"atb":[[20,12.67]],"id":52385915},{"atl":[[42,5]],"id":52385915},{"atb":[[12,5]],"id":52385917},{"atl":[[24,9.62]],"id":52385917},{"atb":[[29,6.87]],"id":52385928},{"atl":[[75,2.16],[55,5]],"id":52385928},{"atb":[[22,5]],"id":52385922},{"atl":[[50,5]],"id":52385922},{"atb":[[17.5,9.71],[24,5]],"id":52385924},{"atl":[[48,12.61]],"id":52385924},{"atb":[[25,5]],"id":52385893},{"atl":[[75,2.16],[55,5]],"id":52385893}],"con":true,"img":false}]}
{"op":"mcm","clk":"11450313416","pt":1717320483974,"mc":[{"id":"1.229554912","rc":[{"atl":[[55,2.96]],"id":52385918},{"atl":[[100,1.61]],"id":52385925},{"atl":[[55,2.96]],"id":52385911},{"atl":[[55,2.96]],"id":52385915},{"atb":[[11,14.95]],"id":52385917},{"atl":[[24,16.58]],"id":52385917},{"atl":[[55,2.96]],"id":52385922}],"con":true,"img":false}]}
{"op":"mcm","clk":"11450313723","pt":1717320489753,"mc":[{"id":"1.229554912","rc":[{"atl":[[50,0],[55,5]],"id":52385892}],"con":true,"img":false}]}
{"op":"mcm","clk":"11450313886","pt":1717320492782,"mc":[{"id":"1.229554912","rc":[{"atb":[[2.88,0],[3,31.98]],"id":52385885}],"con":true,"img":false}]}
{"op":"mcm","clk":"11450313913","pt":1717320493082,"mc":[{"id":"1.229554912","rc":[{"atb":[[7.6,0],[7.8,3.93]],"id":52385910},{"atb":[[6.8,0],[7,4.47]],"id":52385887},{"atb":[[75,0],[40,0],[50,0],[30,0]],"id":52385883},{"atb":[[5.1,2.77]],"id":52385885},{"atb":[[23,2.92],[24,0]],"id":52385929},{"atb":[[180,0]],"id":52385890},{"atb":[[5.1,2.79],[5,0]],"id":52385886},{"atb":[[140,0]],"id":52385919},{"atb":[[740,0],[790,0],[840,0]],"id":52385897},{"atb":[[20,7.92],[21,0]],"id":52385922},{"atb":[[23,7.03],[24,0]],"id":52385893},{"atb":[[690,0],[740,0],[790,0],[840,0]],"id":52385901}],"con":true,"img":false}]}
{"op":"mcm","clk":"11450313918","pt":1717320493183,"mc":[{"id":"1.229554912","rc":[{"atb":[[4.9,0]],"id":52385885},{"atb":[[180,0]],"id":52385926}],"con":true,"img":false}]}
{"op":"mcm","clk":"11450313936","pt":1717320493496,"mc":[{"id":"1.229554912","rc":[{"atb":[[4.8,26.32],[3.9,0]],"id":52385910},{"atb":[[280,0],[380,0]],"id":52385912},{"atb":[[12,0],[8.8,0]],"id":52385918},{"atb":[[4.8,0],[3.9,0]],"id":52385887},{"atb":[[6.4,0],[5.2,0]],"id":52385889},{"atb":[[7.2,0],[9.2,0]],"id":52385914},{"atb":[[17,0],[24,0]],"id":52385883},{"atb":[[3.15,0],[3.65,0]],"id":52385885},{"atb":[[10.5,0],[15.5,0]],"id":52385894},{"atb":[[46,0],[28,0]],"id":52385896},{"atb":[[9,0],[12.5,0]],"id":52385929},{"atb":[[550,0],[650,0]],"id":52385890},{"atb":[[9,0],[12.5,0]],"id":52385892},{"atb":[[10.5,0],[15.5,0]],"id":52385925},{"atb":[[520,0],[420,0]],"id":52385900},{"atb":[[12,3.4],[8.8,0]],"id":52385911},{"atb":[[3.15,0],[3.65,0]],"id":52385886},{"atb":[[280,0],[380,0]],"id":52385919},{"atb":[[7.2,0],[9.2,0]],"id":52385921},{"atb":[[4.8,0],[3.9,0]],"id":52385882},{"atb":[[12,0],[8.8,0]],"id":52385915},{"atb":[[4.8,0],[3.9,0]],"id":52385917},{"atb":[[550,0],[650,0]],"id":52385926},{"atb":[[9,0],[12.5,0]],"id":52385928},{"atb":[[550,0],[650,0]],"id":52385897},{"atb":[[12,0],[8.8,0]],"id":52385922},{"atb":[[6.4,0],[5.2,0]],"id":52385924},{"atb":[[9,0],[12.5,0]],"id":52385893},{"atb":[[520,0],[420,0]],"id":52385899},{"atb":[[550,0],[650,0]],"id":52385901}],"con":true,"img":false}]}
{"op":"mcm","clk":"11450313942","pt":1717320493600,"mc":[{"id":"1.229554912","rc":[{"atb":[[410,0],[230,2]],"id":52385897},{"atb":[[410,0],[220,4.71]],"id":52385901}],"con":true,"img":false}]}
{"op":"mcm","clk":"11450313948","pt":1717320493702,"mc":[{"id":"1.229554912","rc":[{"atb":[[200,2]],"id":52385901}],"con":true,"img":false}]}
{"op":"mcm","clk":"11450313956","pt":1717320493810,"mc":[{"id":"1.229554912","rc":[{"atb":[[70,0.38],[38,2.12],[48,1.11],[29,3.74]],"id":52385883},{"atb":[[720,0.11],[770,0.07],[820,0.03]],"id":52385897},{"atb":[[670,0.16],[720,0.11],[770,0.07],[820,0.03],[220,2.71]],"id":52385901}],"con":true,"img":false}]}
{"op":"mcm","clk":"11450313973","pt":1717320493979,"mc":[{"id":"1.229554912","rc":[{"atl":[[42,4.23],[44,0]],"id":52385921},{"atb":[[400,2],[230,0]],"id":52385897},{"atb":[[200,0],[220,4.71]],"id":52385901}],"con":true,"img":false}]}
{"op":"mcm","clk":"11450313979","pt":1717320494080,"mc":[{"id":"1.229554912","rc":[{"atb":[[400,2],[220,2.71]],"id":52385901}],"con":true,"img":false}]}
{"op":"mcm","clk":"11450314099","pt":1717320495964,"mc":[{"id":"1.229554912","rc":[{"atl":[[9,10.53],[9.2,2.77]],"id":52385885},{"atb":[[170,3.06]],"id":52385890},{"atb":[[130,4.06]],"id":52385919},{"atb":[[170,2.71]],"id":52385926}],"con":true,"img":false}]}
{"op":"mcm","clk":"11450314221","pt":1717320497895,"mc":[{"id":"1.229554912","rc":[{"atb":[[2.88,28.16]],"id":52385885}],"con":true,"img":false}]}
{"op":"mcm","clk":"11450314229","pt":1717320498000,"mc":[{"id":"1.229554912","rc":[{"atb":[[3,0]],"id":52385885}],"con":true,"img":false}]}
{"op":"mcm","clk":"11450314234","pt":1717320498107,"mc":[{"id":"1.229554912","rc":[{"atb":[[7.6,4.01],[7.8,0]],"id":52385910},{"atb":[[6.8,3.09],[7,0]],"id":52385887},{"atb":[[5.1,0],[4.9,4.26]],"id":52385885},{"atb":[[23,0],[24,4.29]],"id":52385929},{"atb":[[170,0],[180,4.16]],"id":52385890},{"atb":[[5.1,0],[5,3.15]],"id":52385886},{"atb":[[130,0],[140,4.68]],"id":52385919},{"atb":[[170,0],[180,3.86]],"id":52385926},{"atb":[[20,4.13],[21,2.71]],"id":52385922},{"atb":[[23,3.57],[24,3.46]],"id":52385893}],"con":true,"img":false}]}
{"op":"mcm","clk":"11450314254","pt":1717320498371,"mc":[{"id":"1.229554912","rc":[{"atl":[[9,15.08],[9.2,0]],"id":52385885},{"atl":[[42,0],[44,2.93]],"id":52385921}],"con":true,"img":false}]}
{"op":"mcm","clk":"11450314267","pt":1717320498683,"mc":[{"id":"1.229554912","rc":[{"atl":[[30,10.53]],"id":52385921}],"con":true,"img":false}]}
{"op":"mcm","clk":"11450314303","pt":1717320499402,"mc":[{"id":"1.229554912","rc":[{"atl":[[30,5],[1000,0]],"id":52385921}],"con":true,"img":false}]}
{"op":"mcm","clk":"11450314309","pt":1717320499465,"mc":[{"id":"1.229554912","rc":[{"atb":[[10.5,21.86]],"id":52385910},{"atl":[[18,14.42]],"id":52385910},{"atl":[[30,10.53]],"id":52385889},{"atb":[[6,30.8]],"id":52385885},{"atl":[[8.4,26.65]],"id":52385885},{"atl":[[55,7.97]],"id":52385892},{"atl":[[10.5,18.92]],"id":52385882},{"atb":[[24,11.97]],"id":52385924},{"atl":[[55,7.97]],"id":52385893}],"con":true,"img":false}]}
{"op":"mcm","clk":"11450314313","pt":1717320499562,"mc":[{"id":"1.229554912","rc":[{"atl":[[42,8.91]],"id":52385918},{"atb":[[9.4,23.44]],"id":52385887},{"atl":[[75,7.17]],"id":52385925},{"atl":[[40,9.11]],"id":52385911},{"atb":[[7.6,28.57]],"id":52385886},{"atl":[[42,8.91]],"id":52385915},{"atb":[[12,19.57]],"id":52385917}],"con":true,"img":false}]}
{"op":"mcm","clk":"11450314322","pt":1717320499776,"mc":[{"id":"1.229554912","rc":[{"atb":[[2.88,0],[3,31.98]],"id":52385885}],"con":true,"img":false}]}
{"op":"mcm","clk":"11450314336","pt":1717320500082,"mc":[{"id":"1.229554912","rc":[{"atl":[[42,3.9]],"id":52385921}],"con":true,"img":false}]}
{"op":"mcm","clk":"11450314344","pt":1717320500188,"mc":[{"id":"1.229554912","rc":[{"atb":[[10,2.91]],"id":52385910},{"atl":[[21,3.25]],"id":52385910},{"atl":[[36,4.19],[30,5]],"id":52385889},{"atb":[[5.8,5.45]],"id":52385885},{"atl":[[9,4.55]],"id":52385885},{"atl":[[12,0]],"id":52385882},{"atb":[[17.5,0]],"id":52385924},{"atl":[[75,0]],"id":52385893}],"con":true,"img":false}]}
{"op":"mcm","clk":"11450314352","pt":1717320500286,"mc":[{"id":"1.229554912","rc":[{"atl":[[55,0]],"id":52385918},{"atb":[[9.2,3.19]],"id":52385887},{"atl":[[75,0]],"id":52385892},{"atl":[[55,0]],"id":52385911},{"atb":[[6.8,4.51]],"id":52385886},{"atl":[[55,0]],"id":52385915},{"atb":[[11,2.62]],"id":52385917}],"con":true,"img":false}]}
{"op":"mcm","clk":"11450314368","pt":1717320500496,"mc":[{"id":"1.229554912","rc":[{"atb":[[7.6,0]],"id":52385910},{"atl":[[42,0],[44,5]],"id":52385918},{"atb":[[23,2.67],[24,0]],"id":52385929},{"atb":[[130,3.08]],"id":52385919},{"atl":[[44,0]],"id":52385921},{"atb":[[180,0]],"id":52385926},{"atb":[[20,7.99]],"id":52385922}],"con":true,"img":false}]}
{"op":"mcm","clk":"11450314376","pt":1717320500602,"mc":[{"id":"1.229554912","rc":[{"atb":[[7.8,3.4]],"id":52385910},{"atb":[[6.8,0],[7,3.87]],"id":52385887},{"atb":[[5.1,3.87],[4.9,0]],"id":52385885},{"atl":[[9,0],[9.2,4.41]],"id":52385885},{"atb":[[180,0]],"id":52385890},{"atb":[[5.1,3.41],[5,0]],"id":52385886},{"atb":[[140,0]],"id":52385919},{"atl":[[42,8.03]],"id":52385921},{"atb":[[21,0]],"id":52385922},{"atb":[[23,6.5],[24,0]],"id":52385893}],"con":true,"img":false}]}
{"op":"mcm","clk":"11450314396","pt":1717320500862,"mc":[{"id":"1.229554912","rc":[{"atl":[[40,4.1]],"id":52385889}],"con":true,"img":false}]}
{"op":"mcm","clk":"11450314419","pt":1717320501172,"mc":[{"id":"1.229554912","rc":[{"atl":[[65,2.5]],"id":52385918}],"con":true,"img":false}]}
{"op":"mcm","clk":"11450314538","pt":1717320503174,"mc":[{"id":"1.229554912","rc":[{"atb":[[2.88,32.83],[3,0]],"id":52385885}],"con":true,"img":false}]}
{"op":"mcm","clk":"11450314557","pt":1717320503484,"mc":[{"id":"1.229554912","rc":[{"atb":[[7.6,3.9],[7.8,0]],"id":52385910},{"atb":[[6.8,2.95],[7,0]],"id":52385887},{"atb":[[4.9,2.92]],"id":52385885},{"atb":[[23,0],[24,4.41]],"id":52385929},{"atb":[[180,3.98]],"id":52385890},{"atb":[[5.1,0],[5,4.61]],"id":52385886},{"atb":[[130,0],[140,3.35]],"id":52385919},{"atb":[[180,2.79]],"id":52385926},{"atb":[[20,4.13],[21,3.47]],"id":52385922},{"atb":[[23,3.57],[24,2.95]],"id":52385893}],"con":true,"img":false}]}
{"op":"mcm","clk":"11450314558","pt":1717320503583,"mc":[{"id":"1.229554912","rc":[{"atb":[[5.1,0]],"id":52385885}],"con":true,"img":false}]}
{"op":"mcm","clk":"11450314567","pt":1717320503692,"mc":[{"id":"1.229554912","rc":[{"atl":[[9,4.52],[9.2,0]],"id":52385885},{"atl":[[42,3.9],[44,4.26]],"id":52385921}],"con":true,"img":false}]}
{"op":"mcm","clk":"11450314586","pt":1717320503995,"mc":[{"id":"1.229554912","rc":[{"atl":[[100,0]],"id":52385925}],"con":true,"img":false}]}
{"op":"mcm","clk":"11450314890","pt":1717320508871,"mc":[{"id":"1.229554912","rc":[{"atl":[[9,0],[9.2,3.49]],"id":52385885},{"atl":[[42,8.5]],"id":52385921}],"con":true,"img":false}]}
{"op":"mcm","clk":"11450314898","pt":1717320508972,"mc":[{"id":"1.229554912","rc":[{"atl":[[44,0]],"id":52385921}],"con":true,"img":false}]}
{"op":"mcm","clk":"11450314907","pt":1717320509082,"mc":[{"id":"1.229554912","rc":[{"atb":[[7.6,0],[7.8,4.21]],"id":52385910},{"atb":[[6.8,0],[7,4.3]],"id":52385887},{"atb":[[5.1,2.8],[4.9,0]],"id":52385885},{"atb":[[23,3.09],[24,0]],"id":52385929},{"atb":[[180,0]],"id":52385890},{"atb":[[5.1,2.73],[5,0]],"id":52385886},{"atb":[[130,3.14],[140,0]],"id":52385919},{"atb":[[180,0]],"id":52385926},{"atb":[[20,8.39],[21,0]],"id":52385922},{"atb":[[23,7.2],[24,0]],"id":52385893}],"con":true,"img":false}]}
{"op":"mcm","clk":"11450314972","pt":1717320510123,"mc":[{"id":"1.229554912","rc":[{"atb":[[2.88,0],[3,32.83]],"id":52385885}],"con":true,"img":false}]}
{"op":"mcm","clk":"11450314990","pt":1717320510329,"mc":[{"id":"1.229554912","rc":[{"atb":[[10.5,0]],"id":52385910},{"atl":[[18,0]],"id":52385910},{"atb":[[17.5,4.76]],"id":52385918},{"atl":[[65,0],[44,0]],"id":52385918},{"atb":[[7.2,0],[9.2,0],[6.2,0],[8.2,0],[9.4,0]],"id":52385887},{"atl":[[16,2.73],[16.5,0]],"id":52385887},{"atb":[[16,0],[17,1.64]],"id":52385889},{"atl":[[40,0],[30,0]],"id":52385889},{"atb":[[15.5,0]],"id":52385914},{"atl":[[44,2.96],[30,0]],"id":52385914},{"atb":[[6,0]],"id":52385885},{"atl":[[8.4,0]],"id":52385885},{"atb":[[32,0]],"id":52385894},{"atl":[[70,0],[100,0]],"id":52385894},{"atb":[[32,0]],"id":52385929},{"atl":[[80,3.14]],"id":52385929},{"atb":[[19.5,0]],"id":52385892},{"atl":[[55,0]],"id":52385892},{"atl":[[75,0]],"id":52385925},{"atl":[[40,0]],"id":52385911},{"atb":[[7.6,0],[6.8,0],[4.9,0],[5.9,0],[5.4,0]],"id":52385886},{"atl":[[12.5,4.64]],"id":52385886},{"atb":[[14,4.38]],"id":52385921},{"atl":[[42,4.59],[30,0]],"id":52385921},{"atb":[[6.2,0]],"id":52385882},{"atl":[[10.5,0]],"id":52385882},{"atb":[[20,7.66]],"id":52385915},{"atl":[[42,0]],"id":52385915},{"atb":[[12,0]],"id":52385917},{"atl":[[24,4.61]],"id":52385917},{"atb":[[29,1.87]],"id":52385928},{"atl":[[75,0],[55,0]],"id":52385928},{"atb":[[22,0]],"id":52385922},{"atl":[[50,0],[55,0]],"id":52385922},{"atb":[[24,0]],"id":52385924},{"atl":[[48,4.2]],"id":52385924},{"atb":[[25,0]],"id":52385893},{"atl":[[55,0]],"id":52385893}],"con":true,"img":false}]}
{"op":"mcm","clk":"11450315054","pt":1717320510978,"mc":[{"id":"1.229554912","rc":[{"atb":[[6.8,13.53],[8.8,3.35],[7.8,7.7],[5.9,21.36]],"id":52385887},{"atb":[[5.6,11.37],[5.1,21.88],[4.6,29.07],[6.2,5.03]],"id":52385886}],"con":true,"img":false}]}
{"op":"mcm","clk":"11450315083","pt":1717320511391,"mc":[{"id":"1.229554912","rc":[{"atb":[[40,0],[20,0],[25,0],[30,0]],"id":52385929}],"con":true,"img":false}]}
{"op":"mcm","clk":"11450315090","pt":1717320511494,"mc":[{"id":"1.229554912","rc":[{"atb":[[18.5,5.71],[19,0]],"id":52385929}],"con":true,"img":false}]}
{"op":"mcm","clk":"11450315129","pt":1717320512074,"mc":[{"id":"1.229554912","rc":[{"atb":[[38,0.71],[19.5,5.66],[24,3.41],[29,1.87]],"id":52385929}],"con":true,"img":false}]}
{"op":"mcm","clk":"11450315171","pt":1717320512600,"mc":[{"id":"1.229554912","rc":[{"atb":[[4.8,53.82],[3.9,84.1]],"id":52385910},{"atb":[[280,0.87],[380,0.27]],"id":52385912},{"atb":[[9,30.48],[12.5,9.08]],"id":52385918},{"atb":[[4.8,27.5],[3.9,84.1]],"id":52385887},{"atb":[[5.3,56.72],[6.6,18.66]],"id":52385889},{"atb":[[7.4,38.1],[9.4,12.44]],"id":52385914},{"atb":[[16,16.26],[22,4.97]],"id":52385883},{"atb":[[3.6,40.2],[3.1,116.14]],"id":52385885},{"atb":[[16,6.96],[11,24.39]],"id":52385894},{"atb":[[40,2.67],[25,10.16]],"id":52385896},{"atb":[[9.2,29.74],[13,8.71]],"id":52385929},{"atb":[[550,0.44],[650,0.16]],"id":52385890},{"atb":[[9.2,29.74],[13,8.71]],"id":52385892},{"atb":[[16,6.96],[11,24.39]],"id":52385925},{"atb":[[410,0.59],[510,0.2]],"id":52385900},{"atb":[[9,30.48],[12.5,9.08]],"id":52385911},{"atb":[[3.6,40.2],[3.1,116.14]],"id":52385886},{"atb":[[280,0.87],[380,0.27]],"id":52385919},{"atb":[[7.4,38.1],[9.4,12.44]],"id":52385921},{"atb":[[4.8,27.5],[3.9,84.1]],"id":52385882},{"atb":[[9,30.48],[12.5,9.08]],"id":52385915},{"atb":[[4.8,27.5],[3.9,84.1]],"id":52385917},{"atb":[[550,0.44],[650,0.16]],"id":52385926},{"atb":[[9.2,29.74],[13,8.71]],"id":52385928},{"atb":[[550,0.44],[650,0.16]],"id":52385897},{"atb":[[9,30.48],[12.5,9.08]],"id":52385922},{"atb":[[5.3,56.72],[6.6,18.66]],"id":52385924},{"atb":[[9.2,29.74],[13,8.71]],"id":52385893},{"atb":[[410,0.59],[510,0.2]],"id":52385899},{"atb":[[550,0.44],[650,0.16]],"id":52385901}],"con":true,"img":false}]}
{"op":"mcm","clk":"11450315308","pt":1717320514406,"mc":[{"id":"1.229554912","rc":[{"atb":[[7.8,0]],"id":52385910},{"atb":[[6.8,16.68],[7,0]],"id":52385887},{"atb":[[5.1,0],[4.9,3.57]],"id":52385885},{"atb":[[23,0],[24,7.66]],"id":52385929},{"atb":[[5.1,19.14],[5,3.9]],"id":52385886},{"atb":[[21,4.27]],"id":52385922},{"atb":[[23,3.57],[24,3.2]],"id":52385893}],"con":true,"img":false}]}
{"op":"mcm","clk":"11450315316","pt":1717320514503,"mc":[{"id":"1.229554912","rc":[{"atb":[[7.6,3.75]],"id":52385910},{"atl":[[9,2.79],[9.2,0]],"id":52385885},{"atl":[[44,3.11]],"id":52385921},{"atb":[[20,4.13]],"id":52385922}],"con":true,"img":false}]}
{"op":"mcm","clk":"11450315325","pt":1717320514609,"mc":[{"id":"1.229554912","rc":[{"atl":[[42,0]],"id":52385921}],"con":true,"img":false}]}
{"op":"mcm","clk":"11450315413","pt":1717320515809,"mc":[{"id":"1.229554912","rc":[{"atb":[[7.6,0],[7.8,3.12]],"id":52385910},{"atb":[[6.8,13.53],[7,4.57]],"id":52385887},{"atb":[[5.1,3.99],[4.9,0]],"id":52385885},{"atl":[[9,0],[9.2,3.29]],"id":52385885},{"atb":[[23,3.99],[24,3.41]],"id":52385929},{"atb":[[5.1,23.45],[5,0]],"id":52385886},{"atl":[[42,2.76],[44,0]],"id":52385921},{"atb":[[20,8.36],[21,0]],"id":52385922},{"atb":[[23,7.39],[24,0]],"id":52385893}],"con":true,"img":false}]}
{"op":"mcm","clk":"11450315633","pt":1717320519310,"mc":[{"id":"1.229554912","rc":[{"atb":[[2.88,41.32],[3,0]],"id":52385885}],"con":true,"img":false}]}
{"op":"mcm","clk":"11450315658","pt":1717320519626,"mc":[{"id":"1.229554912","rc":[{"atb":[[7.6,3.32],[7.8,0]],"id":52385910},{"atb":[[6.8,2.66],[8.8,0],[7.8,0],[7,0],[5.9,0]],"id":52385887},{"atb":[[5.1,0],[2.88,0],[3,41.32],[4.9,4.44]],"id":52385885},{"atl":[[9,3.35]],"id":52385885},{"atb":[[23,0],[24,7.09]],"id":52385929},{"atb":[[5.6,0],[5.1,0],[4.6,0],[5,4.67],[6.2,0]],"id":52385886},{"atb":[[20,4.13],[21,3.96]],"id":52385922},{"atb":[[23,3.57],[24,4.52]],"id":52385893}],"con":true,"img":false}]}
{"op":"mcm","clk":"11450315664","pt":1717320519690,"mc":[{"id":"1.229554912","rc":[{"atb":[[2.88,41.32],[3,0]],"id":52385885},{"atl":[[9.2,0]],"id":52385885},{"atl":[[42,0],[44,3.12]],"id":52385921}],"con":true,"img":false}]}
{"op":"mcm","clk":"11450315673","pt":1717320519892,"mc":[{"id":"1.229554912","rc":[{"atb":[[2.88,0],[3,41.32]],"id":52385885}],"con":true,"img":false}]}
{"op":"mcm","clk":"11450315699","pt":1717320520308,"mc":[{"id":"1.229554912","rc":[{"atb":[[6.8,16.2],[8.8,3.35],[7.8,7.7],[5.9,21.36]],"id":52385887},{"atb":[[5.6,11.37],[5.1,19.14],[4.6,29.07],[6.2,5.03]],"id":52385886}],"con":true,"img":false}]}
{"op":"mcm","clk":"11450315748","pt":1717320521193,"mc":[{"id":"1.229554912","rc":[{"atb":[[7.6,0],[7.8,4.18]],"id":52385910},{"atb":[[6.8,13.53],[7,3.41]],"id":52385887},{"atb":[[5.1,3.43],[4.9,0]],"id":52385885},{"atl":[[9,0],[9.2,2.88]],"id":52385885},{"atb":[[23,4.53],[24,3.41]],"id":52385929},{"atb":[[5.1,23.3],[5,0]],"id":52385886},{"atl":[[42,4.03],[44,0]],"id":52385921},{"atb":[[20,6.93],[21,0]],"id":52385922},{"atb":[[23,7.24],[24,0]],"id":52385893}],"con":true,"img":false}]}
{"op":"mcm","clk":"11450315762","pt":1717320521406,"mc":[{"id":"1.229554912","rc":[{"atb":[[10,12.17],[10.5,5]],"id":52385910},{"atl":[[18,5],[20,11.11]],"id":52385910},{"atb":[[17.5,9.76]],"id":52385918},{"atl":[[44,5],[55,2.96]],"id":52385918},{"atb":[[8.8,14.5],[9.4,5]],"id":52385887},{"atl":[[16,13.41],[16.5,5]],"id":52385887},{"atb":[[16,5],[17,11.64]],"id":52385889},{"atl":[[36,8.77],[30,5]],"id":52385889},{"atb":[[15.5,5]],"id":52385914},{"atl":[[42,3.9],[30,5]],"id":52385914},{"atb":[[5.8,18.04],[6,5]],"id":52385885},{"atl":[[9,12.58],[8.4,5]],"id":52385885},{"atb":[[32,5]],"id":52385894},{"atl":[[70,5],[100,1.61]],"id":52385894},{"atb":[[32,5],[38,5.04]],"id":52385929},{"atl":[[80,10.18]],"id":52385929},{"atb":[[19.5,5]],"id":52385892},{"atl":[[75,2.16],[55,5]],"id":52385892},{"atl":[[70,5],[100,1.61]],"id":52385925},{"atl":[[42,5],[55,2.96]],"id":52385911},{"atb":[[6.2,19.75],[7.6,5]],"id":52385886},{"atl":[[12.5,23.58]],"id":52385886},{"atb":[[14,9.39]],"id":52385921},{"atl":[[32,5],[46,3.56]],"id":52385921},{"atb":[[6.2,5]],"id":52385882},{"atl":[[10.5,5],[12,12.13]],"id":52385882},{"atb":[[20,12.67]],"id":52385915},{"atl":[[42,5],[55,2.96]],"id":52385915},{"atb":[[11,14.95],[12,5]],"id":52385917},{"atl":[[24,16.58]],"id":52385917},{"atb":[[29,6.87]],"id":52385928},{"atl":[[75,2.16],[55,5]],"id":52385928},{"atb":[[22,5]],"id":52385922},{"atl":[[50,5],[55,2.96]],"id":52385922},{"atb":[[17.5,9.71],[24,5]],"id":52385924},{"atl":[[48,12.61]],"id":52385924},{"atb":[[25,5]],"id":52385893},{"atl":[[75,2.16],[55,5]],"id":52385893}],"con":true,"img":false}]}
{"op":"mcm","clk":"11450315792","pt":1717320521822,"mc":[{"id":"1.229554912","rc":[{"atb":[[2.88,38.7],[3,0]],"id":52385885}],"con":true,"img":false}]}
{"op":"mcm","clk":"11450315807","pt":1717320522038,"mc":[{"id":"1.229554912","rc":[{"atb":[[7,0]],"id":52385887},{"atb":[[5.1,0]],"id":52385885},{"atb":[[5.1,19.14]],"id":52385886},{"atb":[[20,4.13],[21,3.8]],"id":52385922}],"con":true,"img":false}]}
{"op":"mcm","clk":"11450315815","pt":1717320522133,"mc":[{"id":"1.229554912","rc":[{"atb":[[7.8,0]],"id":52385910},{"atb":[[23,3.57],[24,3.9]],"id":52385893}],"con":true,"img":false}]}
{"op":"mcm","clk":"11450315821","pt":1717320522206,"mc":[{"id":"1.229554912","rc":[{"atl":[[32,5],[30,0]],"id":52385914}],"con":true,"img":false}]}
{"op":"mcm","clk":"11450315829","pt":1717320522294,"mc":[{"id":"1.229554912","rc":[{"atb":[[2.88,0],[3,38.7]],"id":52385885}],"con":true,"img":false}]}
{"op":"mcm","clk":"11450315851","pt":1717320522610,"mc":[{"id":"1.229554912","rc":[{"atl":[[9,15.84],[9.2,0]],"id":52385885},{"atl":[[42,0],[44,2.9]],"id":52385921}],"con":true,"img":false}]}
{"op":"mcm","clk":"11450315871","pt":1717320522913,"mc":[{"id":"1.229554912","rc":[{"atb":[[7.6,4.38]],"id":52385910},{"atb":[[6.8,17.61]],"id":52385887},{"atb":[[4.9,4.46]],"id":52385885},{"atb":[[23,0],[24,6.42]],"id":52385929},{"atb":[[5,4.41]],"id":52385886}],"con":true,"img":false}]}
{"op":"mcm","clk":"11450315896","pt":1717320523241,"mc":[{"id":"1.229554912","rc":[{"atl":[[42,0],[60,2]],"id":52385910},{"atb":[[36,2],[110,3.8]],"id":52385912},{"atb":[[16,0],[5.4,13.34]],"id":52385918},{"atl":[[100,2]],"id":52385918},{"atl":[[42,2.44],[30,0]],"id":52385887},{"atb":[[5.6,21.74],[8.2,0]],"id":52385889},{"atb":[[10,0],[5.5,10.62]],"id":52385914},{"atl":[[110,2]],"id":52385914},{"atl":[[17.5,6.06],[21,0]],"id":52385885},{"atb":[[8.6,8.72],[27,0]],"id":52385894},{"atl":[[280,2]],"id":52385894},{"atb":[[38,2.7],[120,0]],"id":52385896},{"atb":[[18.5,0],[9,11.32]],"id":52385929},{"atl":[[320,2]],"id":52385929},{"atb":[[38,2],[190,0]],"id":52385890},{"atb":[[18.5,2.71],[6,10.02]],"id":52385892},{"atl":[[120,2]],"id":52385892},{"atb":[[8,7.7],[27,0]],"id":52385925},{"atl":[[220,2]],"id":52385925},{"atb":[[290,0],[38,2]],"id":52385900},{"atb":[[16,0],[4.5,12.08]],"id":52385911},{"atl":[[75,2]],"id":52385911},{"atb":[[3.8,35.71],[2.94,0]],"id":52385886},{"atl":[[32,3.23],[22,0]],"id":52385886},{"atb":[[36,2],[110,4.79]],"id":52385919},{"atb":[[5,17.46],[11,0]],"id":52385921},{"atl":[[90,2]],"id":52385921},{"atb":[[4.5,0],[3.25,25.04]],"id":52385882},{"atl":[[18.5,5.71],[30,0]],"id":52385882},{"atb":[[6.6,13.49],[15,0]],"id":52385915},{"atl":[[140,2]],"id":52385915},{"atl":[[85,2],[46,0]],"id":52385917},{"atb":[[38,2],[190,0]],"id":52385926},{"atb":[[18.5,0],[7.8,11.32]],"id":52385928},{"atl":[[200,2]],"id":52385928},{"atb":[[38,2],[400,0]],"id":52385897},{"atb":[[7.6,9.14],[14.5,0]],"id":52385922},{"atl":[[190,2]],"id":52385922},{"atl":[[180,2]],"id":52385924},{"atb":[[18,0],[7.8,9.72]],"id":52385893},{"atl":[[200,2]],"id":52385893},{"atb":[[290,0],[38,2]],"id":52385899},{"atb":[[38,2],[400,0]],"id":52385901}],"con":true,"img":false}]}
{"op":"mcm","clk":"11450315917","pt":1717320523399,"mc":[{"id":"1.229554912","rc":[{"atb":[[7.8,4.34]],"id":52385910},{"atb":[[5,3.28]],"id":52385885},{"atb":[[23,6.46],[24,0]],"id":52385893}],"con":true,"img":false}]}
{"op":"mcm","clk":"11450315922","pt":1717320523544,"mc":[{"id":"1.229554912","rc":[{"atl":[[18,0],[18.5,5]],"id":52385910},{"atl":[[820,4.64],[460,0],[480,0]],"id":52385912},{"atb":[[16.5,0],[16,3.84],[17.5,5],[20,0],[25,0],[15,0]],"id":52385918},{"atl":[[16,10.68],[16.5,9.4]],"id":52385887},{"atb":[[46,5]],"id":52385883},{"atl":[[130,0],[330,3.13],[100,0]],"id":52385883},{"atl":[[9,12.58],[9.2,4.08]],"id":52385885},{"atb":[[270,0.59],[160,5.5]],"id":52385896},{"atl":[[860,0],[880,0]],"id":52385890},{"atb":[[40,0],[50,0],[25,0],[27,2.79],[29,0],[30,0]],"id":52385925},{"atb":[[16.5,0],[19,0],[11.5,0],[12.5,12.25],[13,0],[14,0]],"id":52385911},{"atl":[[12.5,18.93],[13,4.39]],"id":52385886},{"atl":[[460,0],[480,0]],"id":52385919},{"atb":[[18,0],[21,0],[13,0],[14,5],[14.5,3.73],[15.5,0]],"id":52385921},{"atl":[[32,0],[34,5],[42,2.81],[44,0]],"id":52385921},{"atb":[[6.4,0],[6.2,7.89],[6.8,0],[7.8,0],[5.9,0],[5.4,0]],"id":52385882},{"atb":[[17.5,0],[20,5],[21,4.05],[25,0],[30,0]],"id":52385915},{"atl":[[24,6.96],[25,5],[26,3.47]],"id":52385917},{"atl":[[860,0],[880,0]],"id":52385926},{"atb":[[28,5],[29,1.87]],"id":52385928}],"con":true,"img":false}]}
{"op":"mcm","clk":"11450315930","pt":1717320523601,"mc":[{"id":"1.229554912","rc":[{"atb":[[20,6.85]],"id":52385922}],"con":true,"img":false}]}
{"op":"mcm","clk":"11450315940","pt":1717320523708,"mc":[{"id":"1.229554912","rc":[{"atb":[[7.6,0]],"id":52385910},{"atb":[[6.8,13.53],[7,4.14]],"id":52385887},{"atb":[[5.1,3.21],[4.9,0]],"id":52385885},{"atb":[[23,4.54],[24,3.41]],"id":52385929},{"atb":[[5.1,22.14],[5,0]],"id":52385886},{"atb":[[21,0]],"id":52385922}],"con":true,"img":false}]}
{"op":"mcm","clk":"11450315946","pt":1717320523834,"mc":[{"id":"1.229554912","rc":[{"atl":[[130,2],[80,0]],"id":52385889},{"atl":[[32,0],[34,5]],"id":52385914},{"atl":[[42,0],[44,5]],"id":52385911},{"atb":[[7.4,5],[7.6,0]],"id":52385886},{"atl":[[42,0],[44,5]],"id":52385915}],"con":true,"img":false}]}
{"op":"mcm","clk":"11450315959","pt":1717320523934,"mc":[{"id":"1.229554912","rc":[{"atb":[[17.5,14.71]],"id":52385918},{"atl":[[330,3.62]],"id":52385883},{"atb":[[26,5],[28,5.17]],"id":52385925},{"atb":[[12.5,16.72]],"id":52385911},{"atb":[[14.5,4.9]],"id":52385921},{"atb":[[6.2,12.95]],"id":52385882},{"atb":[[21,12.06]],"id":52385915}],"con":true,"img":false}]}
{"op":"mcm","clk":"11450315986","pt":1717320524219,"mc":[{"id":"1.229554912","rc":[{"atb":[[7.2,0]],"id":52385910},{"atb":[[17,4.9],[19.5,2.83],[24,1.14],[14.5,7.75]],"id":52385918},{"atb":[[5,0],[4.7,0]],"id":52385885},{"atb":[[36,1.5],[46,0.58],[23,4.76],[28,8.08]],"id":52385925},{"atb":[[18,1.54],[10.5,11.01],[13,6.54],[15.5,3.61]],"id":52385911},{"atb":[[16,5.23],[18.5,2.99],[22,1.25],[13.5,8.37]],"id":52385921},{"atb":[[6.4,9.69],[7.4,4.09],[5.2,24.91],[5.7,16.69]],"id":52385882},{"atb":[[32,0.84],[18,6.15],[21,15.99],[26,2.09]],"id":52385915}],"con":true,"img":false}]}
{"op":"mcm","clk":"11450315998","pt":1717320524424,"mc":[{"id":"1.229554912","rc":[{"atb":[[28,5.34]],"id":52385925},{"atb":[[20,8.36],[21,11.93]],"id":52385915}],"con":true,"img":false}]}
{"op":"mcm","clk":"11450316005","pt":1717320524528,"mc":[{"id":"1.229554912","rc":[{"atb":[[12.5,21.72]],"id":52385911}],"con":true,"img":false}]}
{"op":"mcm","clk":"11450316055","pt":1717320525211,"mc":[{"id":"1.229554912","rc":[{"atb":[[6.8,16.38],[7,0]],"id":52385887},{"atb":[[5.1,0]],"id":52385885},{"atb":[[5.1,19.14],[5,4.19]],"id":52385886},{"atb":[[20,5],[21,15.8]],"id":52385915},{"atb":[[20,4.13],[21,2.78]],"id":52385922}],"con":true,"img":false}]}
{"op":"mcm","clk":"11450316065","pt":1717320525308,"mc":[{"id":"1.229554912","rc":[{"atb":[[5,3.32]],"id":52385885}],"con":true,"img":false}]}
{"op":"mcm","clk":"11450316162","pt":1717320526611,"mc":[{"id":"1.229554912","rc":[{"atl":[[44,0],[46,5]],"id":52385915}],"con":true,"img":false}]}
{"op":"mcm","clk":"11450323556","pt":1717320533719,"mc":[{"id":"1.229554912","rc":[{"atb":[[7.4,3.92]],"id":52385910},{"atl":[[840,4.01]],"id":52385912},{"atl":[[350,4.13]],"id":52385883},{"atb":[[25,3.29]],"id":52385925},{"atb":[[13.5,11.93]],"id":52385921}],"con":true,"img":false}]}
{"op":"mcm","clk":"11450323654","pt":1717320534910,"mc":[{"id":"1.229554912","rc":[{"atb":[[12.5,0]],"id":52385921}],"con":true,"img":false}]}
{"op":"mcm","clk":"11450323695","pt":1717320535523,"mc":[{"id":"1.229554912","rc":[{"atb":[[4.8,23.93]],"id":52385885}],"con":true,"img":false}]}
{"op":"mcm","clk":"11450323746","pt":1717320536345,"mc":[{"id":"1.229554912","rc":[{"atb":[[10.5,21.86]],"id":52385910},{"atl":[[18.5,14.16]],"id":52385910},{"atl":[[42,3.9]],"id":52385918},{"atb":[[9.4,24.08]],"id":52385887},{"atl":[[30,10.53]],"id":52385889},{"atl":[[40,4.1]],"id":52385914},{"atb":[[6,30.8]],"id":52385885},{"atl":[[8.4,26.65]],"id":52385885},{"atl":[[55,7.97]],"id":52385892},{"atl":[[44,8.73]],"id":52385911},{"atb":[[7.4,29.62]],"id":52385886},{"atl":[[32,5.16]],"id":52385921},{"atl":[[10.5,21.86]],"id":52385882},{"atl":[[50,3.26]],"id":52385915},{"atb":[[12,19.57]],"id":52385917},{"atb":[[24,11.97]],"id":52385924}],"con":true,"img":false}]}
{"op":"mcm","clk":"11450323761","pt":1717320536565,"mc":[{"id":"1.229554912","rc":[{"atl":[[70,7.32]],"id":52385925}],"con":true,"img":false}]}
{"op":"mcm","clk":"11450323800","pt":1717320537131,"mc":[{"id":"1.229554912","rc":[{"atb":[[10,2.91]],"id":52385910},{"atl":[[20,2.68]],"id":52385910},{"atl":[[55,0]],"id":52385918},{"atb":[[8.8,3.35]],"id":52385887},{"atl":[[36,4.19],[30,5]],"id":52385889},{"atl":[[42,0]],"id":52385914},{"atb":[[5.8,5.45]],"id":52385885},{"atl":[[9,0]],"id":52385885},{"atl":[[75,0]],"id":52385892},{"atl":[[55,0]],"id":52385911},{"atb":[[6.2,5.03]],"id":52385886},{"atl":[[46,0]],"id":52385921},{"atl":[[12,0]],"id":52385882},{"atl":[[55,0]],"id":52385915},{"atb":[[11,2.62]],"id":52385917},{"atb":[[17.5,0]],"id":52385924}],"con":true,"img":false}]}
{"op":"mcm","clk":"11450323808","pt":1717320537239,"mc":[{"id":"1.229554912","rc":[{"atl":[[100,0]],"id":52385925}],"con":true,"img":false}]}
{"op":"mcm","clk":"11450323849","pt":1717320537851,"mc":[{"id":"1.229554912","rc":[{"atl":[[40,4.1]],"id":52385889}],"con":true,"img":false}]}
{"op":"mcm","clk":"11450324275","pt":1717320543331,"mc":[{"id":"1.229554912","rc":[{"atb":[[14,0],[14.5,9.9]],"id":52385921}],"con":true,"img":false}]}
{"op":"mcm","clk":"11450324312","pt":1717320543743,"mc":[{"id":"1.229554912","rc":[{"atl":[[40,5],[44,0]],"id":52385918},{"atb":[[9.8,5],[9.4,19.07]],"id":52385887},{"atb":[[16,5],[15.5,0]],"id":52385914},{"atb":[[32,0],[34,5]],"id":52385929},{"atl":[[10,5],[10.5,16.86]],"id":52385882},{"atl":[[44,5],[46,0]],"id":52385915},{"atb":[[12,14.56],[13,5]],"id":52385917},{"atb":[[22,0],[23,5]],"id":52385922}],"con":true,"img":false}]}
{"op":"mcm","clk":"11450324333","pt":1717320544053,"mc":[{"id":"1.229554912","rc":[{"atl":[[34,0],[30,5]],"id":52385921}],"con":true,"img":false}]}
{"op":"mcm","clk":"11450324358","pt":1717320544419,"mc":[{"id":"1.229554912","rc":[{"atl":[[44,0],[46,5]],"id":52385915}],"con":true,"img":false}]}
{"op":"mcm","clk":"11450324464","pt":1717320546019,"mc":[{"id":"1.229554912","rc":[{"atl":[[32,5],[34,0]],"id":52385914}],"con":true,"img":false}]}
{"op":"mcm","clk":"11450324509","pt":1717320546740,"mc":[{"id":"1.229554912","rc":[{"atl":[[32,0]],"id":52385914}],"con":true,"img":false}]}
{"op":"mcm","clk":"11450324524","pt":1717320546942,"mc":[{"id":"1.229554912","rc":[{"atl":[[34,5]],"id":52385914}],"con":true,"img":false}]}
{"op":"mcm","clk":"11450324881","pt":1717320550853,"mc":[{"id":"1.229554912","rc":[{"atl":[[40,9.11]],"id":52385918},{"atl":[[30,10.53]],"id":52385889},{"atl":[[30,10.53]],"id":52385921},{"atl":[[48,3.41]],"id":52385915},{"atb":[[13,18.35]],"id":52385917}],"con":true,"img":false}]}
{"op":"mcm","clk":"11450324890","pt":1717320550957,"mc":[{"id":"1.229554912","rc":[{"atb":[[9.8,23.21]],"id":52385887},{"atl":[[38,4.33]],"id":52385914},{"atl":[[10,22.81]],"id":52385882}],"con":true,"img":false}]}
{"op":"mcm","clk":"11450324931","pt":1717320551528,"mc":[{"id":"1.229554912","rc":[{"atl":[[42,0]],"id":52385918},{"atl":[[32,0]],"id":52385921},{"atl":[[50,0]],"id":52385915}],"con":true,"img":false}]}
{"op":"mcm","clk":"11450324938","pt":1717320551637,"mc":[{"id":"1.229554912","rc":[{"atb":[[9.4,0]],"id":52385887},{"atl":[[40,0],[30,5]],"id":52385889},{"atl":[[40,0]],"id":52385914},{"atb":[[12,0]],"id":52385917}],"con":true,"img":false}]}
{"op":"mcm","clk":"11450324947","pt":1717320551736,"mc":[{"id":"1.229554912","rc":[{"atl":[[10.5,0]],"id":52385882}],"con":true,"img":false}]}
{"op":"mcm","clk":"11450324983","pt":1717320552152,"mc":[{"id":"1.229554912","rc":[{"atl":[[50,5],[55,2.96]],"id":52385892},{"atl":[[42,5],[44,3.72]],"id":52385911}],"con":true,"img":false}]}
{"op":"mcm","clk":"11450325004","pt":1717320552355,"mc":[{"id":"1.229554912","rc":[{"atl":[[36,8.77]],"id":52385889}],"con":true,"img":false}]}
{"op":"mcm","clk":"11450325026","pt":1717320552566,"mc":[{"id":"1.229554912","rc":[{"atl":[[50,8.27]],"id":52385892},{"atl":[[42,8.91]],"id":52385911}],"con":true,"img":false}]}
{"op":"mcm","clk":"11450325049","pt":1717320552825,"mc":[{"id":"1.229554912","rc":[{"atl":[[50,3.26],[55,7.97]],"id":52385892},{"atl":[[42,3.9],[44,8.73]],"id":52385911}],"con":true,"img":false}]}
{"op":"mcm","clk":"11450325100","pt":1717320553356,"mc":[{"id":"1.229554912","rc":[{"atl":[[50,0],[55,5]],"id":52385892},{"atl":[[42,0],[44,5]],"id":52385911}],"con":true,"img":false}]}
{"op":"mcm","clk":"11450325158","pt":1717320554028,"mc":[{"id":"1.229554912","rc":[{"atl":[[9,3.77],[9.2,0]],"id":52385885},{"atl":[[75,2.16]],"id":52385892},{"atl":[[55,2.96]],"id":52385911},{"atl":[[42,0],[44,4.68]],"id":52385921}],"con":true,"img":false}]}
{"op":"mcm","clk":"11450325165","pt":1717320554133,"mc":[{"id":"1.229554912","rc":[{"atb":[[7.2,5],[7.4,0]],"id":52385886}],"con":true,"img":false}]}
{"op":"mcm","clk":"11450325198","pt":1717320554541,"mc":[{"id":"1.229554912","rc":[{"atl":[[30,5]],"id":52385921}],"con":true,"img":false}]}
{"op":"mcm","clk":"11450325228","pt":1717320554848,"mc":[{"id":"1.229554912","rc":[{"atb":[[7.2,0],[6.2,19.17],[7.4,5]],"id":52385886}],"con":true,"img":false}]}
{"op":"mcm","clk":"11450325269","pt":1717320555264,"mc":[{"id":"1.229554912","rc":[{"atl":[[42,3.9]],"id":52385921}],"con":true,"img":false}]}
{"op":"mcm","clk":"11450325290","pt":1717320555533,"mc":[{"id":"1.229554912","rc":[{"atb":[[7.2,5],[7.4,0]],"id":52385886}],"con":true,"img":false}]}
{"op":"mcm","clk":"11450325363","pt":1717320556564,"mc":[{"id":"1.229554912","rc":[{"atl":[[330,0.48],[340,3.34]],"id":52385883}],"con":true,"img":false}]}
{"op":"mcm","clk":"11450325509","pt":1717320558134,"mc":[{"id":"1.229554912","rc":[{"atb":[[720,0],[770,0],[820,0]],"id":52385897},{"atb":[[670,0],[720,0],[770,0],[820,0]],"id":52385901}],"con":true,"img":false}]}
{"op":"mcm","clk":"11450325539","pt":1717320558446,"mc":[{"id":"1.229554912","rc":[{"atl":[[55,0],[60,5]],"id":52385928}],"con":true,"img":false}]}
{"op":"mcm","clk":"11450325575","pt":1717320558858,"mc":[{"id":"1.229554912","rc":[{"atb":[[730,0.11],[780,0.07],[830,0.03]],"id":52385897},{"atb":[[680,0.15],[730,0.11],[780,0.07],[830,0.03]],"id":52385901}],"con":true,"img":false}]}
{"op":"mcm","clk":"11450325582","pt":1717320558954,"mc":[{"id":"1.229554912","rc":[{"atl":[[60,7.72]],"id":52385928}],"con":true,"img":false}]}
{"op":"mcm","clk":"11450325633","pt":1717320559628,"mc":[{"id":"1.229554912","rc":[{"atl":[[75,0]],"id":52385928}],"con":true,"img":false}]}
{"op":"mcm","clk":"11450325724","pt":1717320560969,"mc":[{"id":"1.229554912","rc":[{"atl":[[10,17.8],[10.5,5]],"id":52385882},{"atl":[[55,5],[60,2.71]],"id":52385928}],"con":true,"img":false}]}
{"op":"mcm","clk":"11450325729","pt":1717320561073,"mc":[{"id":"1.229554912","rc":[{"atl":[[65,5],[70,0]],"id":52385894},{"atl":[[10,0]],"id":52385882}],"con":true,"img":false}]}
{"op":"mcm","clk":"11450325773","pt":1717320561649,"mc":[{"id":"1.229554912","rc":[{"atl":[[55,0],[60,7.72]],"id":52385928}],"con":true,"img":false}]}
{"op":"mcm","clk":"11450325779","pt":1717320561753,"mc":[{"id":"1.229554912","rc":[{"atl":[[65,0],[70,5]],"id":52385894},{"atl":[[12,13.67]],"id":52385882}],"con":true,"img":false}]}
{"op":"mcm","clk":"11450325836","pt":1717320562475,"mc":[{"id":"1.229554912","rc":[{"atl":[[95,1.7]],"id":52385894}],"con":true,"img":false}]}
{"op":"mcm","clk":"11450325894","pt":1717320563151,"mc":[{"id":"1.229554912","rc":[{"atl":[[100,0]],"id":52385894}],"con":true,"img":false}]}
{"op":"mcm","clk":"11450325969","pt":1717320564237,"mc":[{"id":"1.229554912","rc":[{"atl":[[44,0],[46,5]],"id":52385911}],"con":true,"img":false}]}
{"op":"mcm","clk":"11450325978","pt":1717320564342,"mc":[{"id":"1.229554912","rc":[{"atl":[[46,0],[48,8.41]],"id":52385915}],"con":true,"img":false}]}
{"op":"mcm","clk":"11450326028","pt":1717320565172,"mc":[{"id":"1.229554912","rc":[{"atl":[[30,10.53]],"id":52385889},{"atl":[[30,10.53]],"id":52385921},{"atl":[[55,2.96]],"id":52385915}],"con":true,"img":false}]}
