{"op":"mcm","clk":"11448127645","pt":1717286034980,"mc":[{"id":"1.229554896","marketDefinition":{"bspMarket":true,"turnInPlayEnabled":false,"persistenceEnabled":false,"marketBaseRate":7.0,"eventId":"33318908","eventTypeId":"4339","numberOfWinners":2,"bettingType":"ODDS","marketType":"PLACE","marketTime":"2024-06-02T08:41:00.000Z","suspendTime":"2024-06-02T08:41:00.000Z","bspReconciled":false,"complete":true,"inPlay":false,"crossMatching":true,"runnersVoidable":false,"numberOfActiveRunners":5,"betDelay":0,"status":"OPEN","runners":[{"status":"ACTIVE","sortPriority":1,"id":58069703,"name":"1. Dookie"},{"status":"ACTIVE","sortPriority":2,"id":65732558,"name":"2. All The Sass"},{"status":"ACTIVE","sortPriority":3,"id":63161712,"name":"4. Dirty Dash"},{"status":"ACTIVE","sortPriority":4,"id":61028210,"name":"6. Banjo Bob"},{"status":"ACTIVE","sortPriority":5,"id":50605162,"name":"8. Boy From Hill"}],"regulators":["MR_INT"],"venue":"Murray Bridge","countryCode":"AU","discountAllowed":true,"timezone":"Australia/Adelaide","openDate":"2024-06-02T08:21:00.000Z","version":5962317629,"name":"To Be Placed","eventName":"Murray Bridge (AUS) 2nd Jun"},"rc":[],"con":true,"img":false}]}
{"op":"mcm","clk":"11448254110","pt":1717287816975,"mc":[{"id":"1.229554896","rc":[{"atb":[[1.01,5807.26]],"id":63161712},{"atl":[[2.66,0.31]],"id":63161712},{"spn":1.83,"spf":"NaN","id":63161712},{"atb":[[3.1,11.05],[2.84,18.93]],"id":58069703},{"spn":"Infinity","spf":"NaN","id":58069703},{"atb":[[3.85,12.22],[4.7,6.27]],"id":50605162},{"spn":"Infinity","spf":"NaN","id":50605162},{"atb":[[1.01,3484.35],[1.07,331.84]],"id":65732558},{"atl":[[2.88,0.27]],"id":65732558},{"spn":1.97,"spf":"NaN","id":65732558},{"atb":[[2.3,17.86],[2.1,31.67]],"id":61028210},{"atl":[[10.5,0.05]],"id":61028210},{"spn":6.4,"spf":"NaN","id":61028210}],"con":true,"img":false}]}
{"op":"mcm","clk":"11448254832","pt":1717287826289,"mc":[{"id":"1.229554896","rc":[{"atb":[[1.01,0]],"id":63161712},{"atl":[[2.66,0]],"id":63161712},{"atb":[[3.1,0],[2.84,0]],"id":58069703},{"atb":[[1.01,0],[1.07,0]],"id":65732558},{"atl":[[2.88,0]],"id":65732558},{"atb":[[2.3,0],[2.1,0]],"id":61028210},{"atl":[[10.5,0]],"id":61028210}],"con":true,"img":false}]}
{"op":"mcm","clk":"11448255283","pt":1717287833098,"mc":[{"id":"1.229554896","rc":[{"atb":[[1.01,5807.26]],"id":63161712},{"atl":[[2.66,0.31]],"id":63161712},{"atb":[[3.1,11.05],[2.84,18.93]],"id":58069703},{"atb":[[1.01,3484.35],[1.03,774.3]],"id":65732558},{"atl":[[2.84,0.28]],"id":65732558},{"atb":[[2.14,30.56],[2.34,17.33]],"id":61028210},{"atl":[[10.5,0.05]],"id":61028210}],"con":true,"img":false}]}
{"op":"mcm","clk":"11448255868","pt":1717287841600,"mc":[{"id":"1.229554896","rc":[{"atb":[[3.85,0],[4.7,0]],"id":50605162}],"con":true,"img":false}]}
{"op":"mcm","clk":"11448256290","pt":1717287847599,"mc":[{"id":"1.229554896","rc":[{"atb":[[3.85,12.22],[4.7,6.27]],"id":50605162}],"con":true,"img":false}]}
{"op":"mcm","clk":"11448257231","pt":1717287860833,"mc":[{"id":"1.229554896","rc":[{"atb":[[1.01,0]],"id":63161712},{"atl":[[2.66,0]],"id":63161712},{"atb":[[3.1,0],[2.84,0]],"id":58069703},{"atb":[[3.85,0],[4.7,0]],"id":50605162},{"atb":[[1.01,0],[1.03,0]],"id":65732558},{"atl":[[2.84,0]],"id":65732558},{"atb":[[2.14,0],[2.34,0]],"id":61028210},{"atl":[[10.5,0]],"id":61028210}],"con":true,"img":false}]}
{"op":"mcm","clk":"11448258036","pt":1717287872067,"mc":[{"id":"1.229554896","rc":[{"atb":[[1.01,5807.26]],"id":63161712},{"atl":[[2.46,0.35]],"id":63161712},{"atb":[[3.35,9.88],[2.94,17.96]],"id":58069703},{"atb":[[4.4,10.24],[5.4,5.27]],"id":50605162},{"atb":[[1.01,3484.35],[1.02,1161.45]],"id":65732558},{"atl":[[2.82,0.28]],"id":65732558},{"atb":[[2.46,15.9],[2.26,27.65]],"id":61028210},{"atl":[[12.5,0.04]],"id":61028210}],"con":true,"img":false}]}
{"op":"mcm","clk":"11448259639","pt":1717287895189,"mc":[{"id":"1.229554896","rc":[{"atb":[[1.01,0]],"id":63161712},{"atl":[[2.46,0]],"id":63161712},{"spn":"NaN","spf":"NaN","id":63161712},{"atb":[[3.35,0],[2.94,0]],"id":58069703},{"spn":"NaN","spf":"NaN","id":58069703},{"atb":[[4.4,0],[5.4,0]],"id":50605162},{"spn":"NaN","spf":"NaN","id":50605162},{"atb":[[1.01,0],[1.02,0]],"id":65732558},{"atl":[[2.82,0]],"id":65732558},{"spn":"NaN","spf":"NaN","id":65732558},{"atb":[[2.46,0],[2.26,0]],"id":61028210},{"atl":[[12.5,0]],"id":61028210},{"spn":"NaN","spf":"NaN","id":61028210}],"con":true,"img":false}]}
{"op":"mcm","clk":"11448260594","pt":1717287908430,"mc":[{"id":"1.229554896","rc":[{"atb":[[1.01,5807.26]],"id":63161712},{"atl":[[2.46,0.35]],"id":63161712},{"atb":[[3.35,9.88],[2.94,17.96]],"id":58069703},{"atb":[[5.1,5.66],[4.1,11.23]],"id":50605162},{"atb":[[1.01,3484.35],[1.05,464.58]],"id":65732558},{"atl":[[2.86,0.28]],"id":65732558},{"atb":[[2.4,16.58],[2.2,29.03]],"id":61028210},{"atl":[[11,0.05]],"id":61028210}],"con":true,"img":false}]}
{"op":"mcm","clk":"11448262192","pt":1717287930135,"mc":[{"id":"1.229554896","rc":[{"atb":[[1.01,0],[1.05,0]],"id":65732558},{"atl":[[2.86,0]],"id":65732558}],"con":true,"img":false}]}
{"op":"mcm","clk":"11448262804","pt":1717287939632,"mc":[{"id":"1.229554896","rc":[{"atb":[[1.01,3484.35],[1.04,580.72]],"id":65732558},{"atl":[[2.84,0.28]],"id":65732558}],"con":true,"img":false}]}
{"op":"mcm","clk":"11448264303","pt":1717287962255,"mc":[{"id":"1.229554896","rc":[{"spn":1.73,"spf":"NaN","id":63161712},{"atb":[[3.35,0],[2.94,0]],"id":58069703},{"spn":"Infinity","spf":"NaN","id":50605162},{"atb":[[1.01,0],[1.04,0]],"id":65732558},{"atl":[[2.84,0]],"id":65732558},{"atb":[[2.4,0],[2.2,0]],"id":61028210},{"atl":[[11,0]],"id":61028210}],"con":true,"img":false}]}
{"op":"mcm","clk":"11448265018","pt":1717287972318,"mc":[{"id":"1.229554896","rc":[{"atb":[[3.4,9.67],[2.96,17.77]],"id":58069703},{"atb":[[1.01,3484.35],[1.05,464.58]],"id":65732558},{"atl":[[2.86,0.28]],"id":65732558},{"atb":[[2.42,16.35],[2.22,28.56]],"id":61028210},{"atl":[[11.5,0.05]],"id":61028210}],"con":true,"img":false}]}
{"op":"mcm","clk":"11448270133","pt":1717288057118,"mc":[{"id":"1.229554896","rc":[{"atb":[[1.01,0]],"id":63161712},{"atl":[[2.46,0]],"id":63161712},{"spn":"NaN","spf":"NaN","id":63161712},{"atb":[[3.4,0],[2.96,0]],"id":58069703},{"atb":[[5.1,0],[4.1,0]],"id":50605162},{"spn":"NaN","spf":"NaN","id":50605162},{"atb":[[1.01,0],[1.05,0]],"id":65732558},{"atl":[[2.86,0]],"id":65732558},{"atb":[[2.42,0],[2.22,0]],"id":61028210},{"atl":[[11.5,0]],"id":61028210}],"con":true,"img":false}]}
{"op":"mcm","clk":"11448270978","pt":1717288067734,"mc":[{"id":"1.229554896","rc":[{"atb":[[1.01,5807.26]],"id":63161712},{"atl":[[2.46,0.35]],"id":63161712},{"atb":[[3.45,9.47],[2.98,17.59]],"id":58069703},{"atb":[[5.1,5.66],[4.1,11.23]],"id":50605162},{"atb":[[1.01,3484.35],[1.03,774.3]],"id":65732558},{"atl":[[2.84,0.28]],"id":65732558},{"atb":[[2.42,16.35],[2.22,28.56]],"id":61028210},{"atl":[[11.5,0.05]],"id":61028210}],"con":true,"img":false}]}
{"op":"mcm","clk":"11448277215","pt":1717288128427,"mc":[{"id":"1.229554896","marketDefinition":{"bspMarket":true,"turnInPlayEnabled":false,"persistenceEnabled":false,"marketBaseRate":7.0,"eventId":"33318908","eventTypeId":"4339","numberOfWinners":2,"bettingType":"ODDS","marketType":"PLACE","marketTime":"2024-06-02T08:41:00.000Z","suspendTime":"2024-06-02T08:41:00.000Z","bspReconciled":false,"complete":true,"inPlay":false,"crossMatching":true,"runnersVoidable":false,"numberOfActiveRunners":5,"betDelay":0,"status":"OPEN","runners":[{"status":"ACTIVE","sortPriority":1,"id":58069703,"name":"1. Dookie"},{"status":"ACTIVE","sortPriority":2,"id":65732558,"name":"2. All The Sass"},{"status":"ACTIVE","sortPriority":3,"id":63161712,"name":"4. Dirty Dash"},{"status":"ACTIVE","sortPriority":4,"id":61028210,"name":"6. Banjo Bob"},{"status":"ACTIVE","sortPriority":5,"id":50605162,"name":"8. Boy From Hill"}],"regulators":["MR_INT"],"venue":"Murray Bridge","countryCode":"AU","discountAllowed":true,"timezone":"Australia/Adelaide","openDate":"2024-06-02T08:21:00.000Z","version":5962317629,"name":"To Be Placed","eventName":"Murray Bridge (AUS) 2nd Jun"},"rc":[{"atb":[[1.01,5807.26]],"id":63161712},{"atl":[[2.46,0.35]],"id":63161712},{"spn":1.73,"spf":"NaN","id":63161712},{"atb":[[3.45,9.47],[2.98,17.59]],"id":58069703},{"spn":"Infinity","spf":"NaN","id":58069703},{"atb":[[5.1,5.66],[4.1,11.23]],"id":50605162},{"spn":"Infinity","spf":"NaN","id":50605162},{"atb":[[1.01,3484.35],[1.03,774.3]],"id":65732558},{"atl":[[2.84,0.28]],"id":65732558},{"spn":1.93,"spf":"NaN","id":65732558},{"atb":[[2.42,16.35],[2.22,28.56]],"id":61028210},{"atl":[[11.5,0.05]],"id":61028210},{"spn":6.96,"spf":"NaN","id":61028210}],"con":true,"img":true}]}
{"op":"mcm","clk":"11448289496","pt":1717288232637,"mc":[{"id":"1.229554896","rc":[{"atb":[[1.01,0]],"id":63161712},{"atl":[[2.46,0]],"id":63161712},{"atb":[[3.45,0],[2.98,0]],"id":58069703},{"spn":"Infinity","spf":"NaN","id":50605162},{"atb":[[1.01,0],[1.03,0]],"id":65732558},{"atl":[[2.84,0]],"id":65732558},{"atb":[[2.42,0],[2.22,0]],"id":61028210},{"atl":[[11.5,0]],"id":61028210}],"con":true,"img":false}]}
{"op":"mcm","clk":"11448290414","pt":1717288245743,"mc":[{"id":"1.229554896","rc":[{"atb":[[1.01,5807.26]],"id":63161712},{"atl":[[2.46,0.35]],"id":63161712},{"atb":[[3.35,9.88],[2.94,17.96]],"id":58069703},{"atb":[[1.01,5807.26]],"id":65732558},{"atl":[[2.82,0.28]],"id":65732558},{"atb":[[2.28,27.22],[2.48,15.69]],"id":61028210},{"atl":[[13.5,0.04]],"id":61028210}],"con":true,"img":false}]}
{"op":"mcm","clk":"11448292450","pt":1717288273746,"mc":[{"id":"1.229554896","rc":[{"atb":[[1.01,0]],"id":63161712},{"atl":[[2.46,0]],"id":63161712},{"atb":[[3.35,0],[2.94,0]],"id":58069703},{"atb":[[5.1,0],[4.1,0]],"id":50605162},{"atb":[[1.01,0]],"id":65732558},{"atl":[[2.82,0]],"id":65732558},{"atb":[[2.28,0],[2.48,0]],"id":61028210},{"atl":[[13.5,0]],"id":61028210}],"con":true,"img":false}]}
{"op":"mcm","clk":"11448293804","pt":1717288291623,"mc":[{"id":"1.229554896","rc":[{"atb":[[1.01,5807.26]],"id":63161712},{"atl":[[2.44,0.36]],"id":63161712},{"atb":[[3.55,9.1],[3.05,16.99]],"id":58069703},{"atb":[[3.95,11.81],[4.9,5.95]],"id":50605162},{"atb":[[1.01,5807.26]],"id":65732558},{"atl":[[2.78,0.29]],"id":65732558},{"atb":[[2.38,25.24],[2.58,14.7]],"id":61028210},{"atl":[[13.5,0.04]],"id":61028210}],"con":true,"img":false}]}
{"op":"mcm","clk":"11448298261","pt":1717288351278,"mc":[{"id":"1.229554896","rc":[{"spn":1.72,"spf":"NaN","id":63161712},{"atb":[[3.55,0],[3.05,0]],"id":58069703},{"atb":[[1.01,0]],"id":65732558},{"atl":[[2.78,0]],"id":65732558},{"atb":[[2.38,0],[2.58,0]],"id":61028210},{"atl":[[13.5,0]],"id":61028210}],"con":true,"img":false}]}
{"op":"mcm","clk":"11448300795","pt":1717288383947,"mc":[{"id":"1.229554896","rc":[{"atb":[[3.25,15.48],[3.75,8.44]],"id":58069703},{"atb":[[1.01,5807.26]],"id":65732558},{"atl":[[2.78,0.29]],"id":65732558},{"atb":[[2.56,14.88],[2.36,25.61]],"id":61028210},{"atl":[[15.5,0.03]],"id":61028210}],"con":true,"img":false}]}
{"op":"mcm","clk":"11448470639","pt":1717290837881,"mc":[{"id":"1.229554896","rc":[{"atb":[[1.01,0]],"id":63161712},{"atl":[[2.44,0]],"id":63161712},{"spn":"NaN","spf":"NaN","id":63161712},{"atb":[[3.25,0],[3.75,0]],"id":58069703},{"atb":[[3.95,0],[4.9,0]],"id":50605162},{"spn":"NaN","spf":"NaN","id":50605162},{"atb":[[1.01,0]],"id":65732558},{"atl":[[2.78,0]],"id":65732558},{"atb":[[2.56,0],[2.36,0]],"id":61028210},{"atl":[[15.5,0]],"id":61028210}],"con":true,"img":false}]}
{"op":"mcm","clk":"11448473596","pt":1717290892695,"mc":[{"id":"1.229554896","rc":[{"atb":[[1.01,5807.26]],"id":63161712},{"atl":[[2.42,0.36]],"id":63161712},{"atb":[[3.15,16.2],[3.65,8.76]],"id":58069703},{"atb":[[4.4,10.24],[5.4,5.27]],"id":50605162},{"atb":[[1.01,5807.26]],"id":65732558},{"atl":[[2.76,0.29]],"id":65732558},{"atb":[[2.42,24.53],[2.62,14.34]],"id":61028210},{"atl":[[17,0.03]],"id":61028210}],"con":true,"img":false}]}
{"op":"mcm","clk":"11448474826","pt":1717290912477,"mc":[{"id":"1.229554896","rc":[{"spn":1.71,"spf":"NaN","id":63161712},{"atb":[[3.15,0],[3.65,0]],"id":58069703},{"atb":[[4.4,0],[5.4,0]],"id":50605162},{"spn":1.88,"spf":"NaN","id":65732558},{"atb":[[2.42,0],[2.62,0]],"id":61028210},{"atl":[[17,0]],"id":61028210}],"con":true,"img":false}]}
{"op":"mcm","clk":"11448475142","pt":1717290917393,"mc":[{"id":"1.229554896","rc":[{"atb":[[3.8,8.29],[3.3,15.15]],"id":58069703},{"atb":[[5.6,5.04],[4.6,9.67]],"id":50605162},{"atb":[[2.46,23.86],[2.66,13.99]],"id":61028210},{"atl":[[18,0.03]],"id":61028210}],"con":true,"img":false}]}
{"op":"mcm","clk":"11448476918","pt":1717290945627,"mc":[{"id":"1.229554896","rc":[{"atb":[[1.01,0]],"id":63161712},{"atl":[[2.42,0]],"id":63161712},{"atb":[[3.8,0],[3.3,0]],"id":58069703},{"atb":[[5.6,0],[4.6,0]],"id":50605162},{"atb":[[1.01,0]],"id":65732558},{"atl":[[2.76,0]],"id":65732558},{"atb":[[2.46,0],[2.66,0]],"id":61028210},{"atl":[[18,0]],"id":61028210}],"con":true,"img":false}]}
{"op":"mcm","clk":"11448629943","pt":1717293528418,"mc":[{"id":"1.229554896","marketDefinition":{"bspMarket":true,"turnInPlayEnabled":false,"persistenceEnabled":false,"marketBaseRate":7.0,"eventId":"33318908","eventTypeId":"4339","numberOfWinners":2,"bettingType":"ODDS","marketType":"PLACE","marketTime":"2024-06-02T08:41:00.000Z","suspendTime":"2024-06-02T08:41:00.000Z","bspReconciled":false,"complete":true,"inPlay":false,"crossMatching":true,"runnersVoidable":false,"numberOfActiveRunners":5,"betDelay":0,"status":"OPEN","runners":[{"status":"ACTIVE","sortPriority":1,"id":58069703,"name":"1. Dookie"},{"status":"ACTIVE","sortPriority":2,"id":65732558,"name":"2. All The Sass"},{"status":"ACTIVE","sortPriority":3,"id":63161712,"name":"4. Dirty Dash"},{"status":"ACTIVE","sortPriority":4,"id":61028210,"name":"6. Banjo Bob"},{"status":"ACTIVE","sortPriority":5,"id":50605162,"name":"8. Boy From Hill"}],"regulators":["MR_INT"],"venue":"Murray Bridge","countryCode":"AU","discountAllowed":true,"timezone":"Australia/Adelaide","openDate":"2024-06-02T08:21:00.000Z","version":5962317629,"name":"To Be Placed","eventName":"Murray Bridge (AUS) 2nd Jun"},"rc":[{"spn":"NaN","spf":"NaN","id":63161712},{"spn":"NaN","spf":"NaN","id":58069703},{"spn":"NaN","spf":"NaN","id":50605162},{"spn":"NaN","spf":"NaN","id":65732558},{"spn":"NaN","spf":"NaN","id":61028210}],"con":true,"img":true}]}
{"op":"mcm","clk":"11448954088","pt":1717300723413,"mc":[{"id":"1.229554896","rc":[{"atb":[[1.01,5807.26]],"id":63161712},{"atl":[[2.4,0.37]],"id":63161712},{"spn":1.7,"spf":"NaN","id":63161712},{"atb":[[4,7.74],[3.5,13.93]],"id":58069703},{"spn":"Infinity","spf":"NaN","id":58069703},{"atb":[[5.2,5.52],[4.2,10.88]],"id":50605162},{"spn":"Infinity","spf":"NaN","id":50605162},{"atb":[[1.01,5807.26]],"id":65732558},{"atl":[[2.68,0.31]],"id":65732558},{"spn":1.84,"spf":"NaN","id":65732558},{"atb":[[2.5,23.22],[2.7,13.66]],"id":61028210},{"atl":[[19,0.03]],"id":61028210},{"spn":10.85,"spf":"NaN","id":61028210}],"con":true,"img":false}]}
{"op":"mcm","clk":"11448957702","pt":1717300805016,"mc":[{"id":"1.229554896","rc":[{"atb":[[1.01,0]],"id":63161712},{"atl":[[2.4,0]],"id":63161712},{"spn":"NaN","spf":"NaN","id":63161712},{"atb":[[4,0],[3.5,0]],"id":58069703},{"spn":"NaN","spf":"NaN","id":58069703},{"atb":[[5.2,0],[4.2,0]],"id":50605162},{"spn":"NaN","spf":"NaN","id":50605162},{"atb":[[1.01,0]],"id":65732558},{"atl":[[2.68,0]],"id":65732558},{"spn":"NaN","spf":"NaN","id":65732558},{"atb":[[2.5,0],[2.7,0]],"id":61028210},{"atl":[[19,0]],"id":61028210},{"spn":"NaN","spf":"NaN","id":61028210}],"con":true,"img":false}]}
{"op":"mcm","clk":"11448958449","pt":1717300819077,"mc":[{"id":"1.229554896","rc":[{"atb":[[1.01,5807.26]],"id":63161712},{"atl":[[2.36,0.38]],"id":63161712},{"atb":[[3.4,14.51],[3.9,8]],"id":58069703},{"atb":[[4.9,8.93],[5.9,4.73]],"id":50605162},{"atb":[[1.01,5807.26]],"id":65732558},{"atl":[[2.68,0.31]],"id":65732558},{"atb":[[2.56,22.33],[2.76,13.19]],"id":61028210}],"con":true,"img":false}]}
{"op":"mcm","clk":"11448963905","pt":1717300914322,"mc":[{"id":"1.229554896","rc":[{"atb":[[1.01,0]],"id":63161712},{"atl":[[2.36,0]],"id":63161712},{"atb":[[3.4,0],[3.9,0]],"id":58069703},{"atb":[[4.9,0],[5.9,0]],"id":50605162},{"atb":[[1.01,0]],"id":65732558},{"atl":[[2.68,0]],"id":65732558},{"atb":[[2.56,0],[2.76,0]],"id":61028210}],"con":true,"img":false}]}
{"op":"mcm","clk":"11448965590","pt":1717300946049,"mc":[{"id":"1.229554896","rc":[{"atb":[[1.01,5807.26]],"id":63161712},{"atl":[[2.32,0.39]],"id":63161712},{"atb":[[3.85,8.15],[3.35,14.82]],"id":58069703},{"atb":[[5,8.71],[6,4.64]],"id":50605162},{"atb":[[1.01,5807.26]],"id":65732558},{"atl":[[2.68,0.31]],"id":65732558},{"atb":[[2.58,22.05],[2.78,13.04]],"id":61028210}],"con":true,"img":false}]}
{"op":"mcm","clk":"11449119129","pt":1717304328431,"mc":[{"id":"1.229554896","marketDefinition":{"bspMarket":true,"turnInPlayEnabled":false,"persistenceEnabled":false,"marketBaseRate":7.0,"eventId":"33318908","eventTypeId":"4339","numberOfWinners":2,"bettingType":"ODDS","marketType":"PLACE","marketTime":"2024-06-02T08:41:00.000Z","suspendTime":"2024-06-02T08:41:00.000Z","bspReconciled":false,"complete":true,"inPlay":false,"crossMatching":true,"runnersVoidable":false,"numberOfActiveRunners":5,"betDelay":0,"status":"OPEN","runners":[{"status":"ACTIVE","sortPriority":1,"id":58069703,"name":"1. Dookie"},{"status":"ACTIVE","sortPriority":2,"id":65732558,"name":"2. All The Sass"},{"status":"ACTIVE","sortPriority":3,"id":63161712,"name":"4. Dirty Dash"},{"status":"ACTIVE","sortPriority":4,"id":61028210,"name":"6. Banjo Bob"},{"status":"ACTIVE","sortPriority":5,"id":50605162,"name":"8. Boy From Hill"}],"regulators":["MR_INT"],"venue":"Murray Bridge","countryCode":"AU","discountAllowed":true,"timezone":"Australia/Adelaide","openDate":"2024-06-02T08:21:00.000Z","version":5962317629,"name":"To Be Placed","eventName":"Murray Bridge (AUS) 2nd Jun"},"rc":[{"atb":[[1.01,5807.26]],"id":63161712},{"atl":[[2.32,0.39]],"id":63161712},{"spn":1.66,"spf":"NaN","id":63161712},{"atb":[[3.85,8.15],[3.35,14.82]],"id":58069703},{"spn":"Infinity","spf":"NaN","id":58069703},{"atb":[[5,8.71],[6,4.64]],"id":50605162},{"spn":"Infinity","spf":"NaN","id":50605162},{"atb":[[1.01,5807.26]],"id":65732558},{"atl":[[2.68,0.31]],"id":65732558},{"spn":1.84,"spf":"NaN","id":65732558},{"atb":[[2.58,22.05],[2.78,13.04]],"id":61028210},{"spn":"Infinity","spf":"NaN","id":61028210}],"con":true,"img":true}]}
{"op":"mcm","clk":"11449308154","pt":1717306957803,"mc":[{"id":"1.229554896","rc":[{"atb":[[1.01,0]],"id":63161712},{"atl":[[2.32,0]],"id":63161712},{"spn":"Infinity","spf":"NaN","id":58069703},{"spn":"Infinity","spf":"NaN","id":50605162},{"atb":[[1.01,0]],"id":65732558},{"atl":[[2.68,0]],"id":65732558},{"atb":[[2.58,0],[2.78,0]],"id":61028210}],"con":true,"img":false}]}
{"op":"mcm","clk":"11449308938","pt":1717306969019,"mc":[{"id":"1.229554896","rc":[{"atb":[[1.01,5807.26]],"id":63161712},{"atl":[[2.34,0.39]],"id":63161712},{"atb":[[1.01,5807.26]],"id":65732558},{"atl":[[2.64,0.31]],"id":65732558},{"atb":[[2.86,12.48],[2.66,20.98]],"id":61028210}],"con":true,"img":false}]}
{"op":"mcm","clk":"11449311178","pt":1717307001724,"mc":[{"id":"1.229554896","rc":[{"atb":[[5,0],[6,0]],"id":50605162}],"con":true,"img":false}]}
{"op":"mcm","clk":"11449313154","pt":1717307031054,"mc":[{"id":"1.229554896","rc":[{"spn":1.67,"spf":"NaN","id":63161712},{"atb":[[5,8.71],[6,4.64]],"id":50605162},{"spn":1.82,"spf":"NaN","id":65732558},{"spn":"Infinity","spf":"NaN","id":61028210}],"con":true,"img":false}]}
{"op":"mcm","clk":"11449319003","pt":1717307115740,"mc":[{"id":"1.229554896","rc":[{"atb":[[1.01,0]],"id":63161712},{"atl":[[2.34,0]],"id":63161712},{"spn":"NaN","spf":"NaN","id":63161712},{"atb":[[1.01,0]],"id":65732558},{"atl":[[2.64,0]],"id":65732558},{"spn":"NaN","spf":"NaN","id":65732558},{"atb":[[2.86,0],[2.66,0]],"id":61028210},{"spn":"NaN","spf":"NaN","id":61028210}],"con":true,"img":false}]}
{"op":"mcm","clk":"11449319872","pt":1717307127037,"mc":[{"id":"1.229554896","rc":[{"atb":[[1.01,5807.26]],"id":63161712},{"atl":[[2.34,0.39]],"id":63161712},{"atb":[[1.01,5807.26]],"id":65732558},{"atl":[[2.64,0.31]],"id":65732558},{"atb":[[2.86,12.48],[2.66,20.98]],"id":61028210}],"con":true,"img":false}]}
{"op":"mcm","clk":"11449321791","pt":1717307154369,"mc":[{"id":"1.229554896","rc":[{"atb":[[1.01,0]],"id":63161712},{"atl":[[2.34,0]],"id":63161712},{"atb":[[3.85,0],[3.35,0]],"id":58069703},{"atb":[[5,0],[6,0]],"id":50605162},{"atb":[[1.01,0]],"id":65732558},{"atl":[[2.64,0]],"id":65732558},{"atb":[[2.86,0],[2.66,0]],"id":61028210}],"con":true,"img":false}]}
{"op":"mcm","clk":"11449322426","pt":1717307163106,"mc":[{"id":"1.229554896","rc":[{"atb":[[1.01,5807.26]],"id":63161712},{"atl":[[2.32,0.39]],"id":63161712},{"atb":[[3.2,15.83],[3.7,8.6]],"id":58069703},{"atb":[[6.8,4],[5.4,7.92]],"id":50605162},{"atb":[[1.01,5807.26]],"id":65732558},{"atl":[[2.64,0.31]],"id":65732558},{"atb":[[2.88,12.35],[2.68,20.73]],"id":61028210}],"con":true,"img":false}]}
{"op":"mcm","clk":"11449368314","pt":1717308059014,"mc":[{"id":"1.229554896","rc":[{"spn":1.66,"spf":"NaN","id":63161712},{"atb":[[6.8,0],[5.4,0]],"id":50605162},{"spn":"NaN","spf":"NaN","id":50605162},{"spn":1.82,"spf":"NaN","id":65732558},{"spn":"Infinity","spf":"NaN","id":61028210}],"con":true,"img":false}]}
{"op":"mcm","clk":"11449369772","pt":1717308089019,"mc":[{"id":"1.229554896","rc":[{"atb":[[5.1,8.49],[6.2,4.46]],"id":50605162}],"con":true,"img":false}]}
{"op":"mcm","clk":"11449440317","pt":1717309173868,"mc":[{"id":"1.229554896","rc":[{"atb":[[5.1,0],[6.2,0]],"id":50605162}],"con":true,"img":false}]}
{"op":"mcm","clk":"11449440885","pt":1717309182656,"mc":[{"id":"1.229554896","rc":[{"atb":[[6.4,4.3],[5.2,8.29]],"id":50605162}],"con":true,"img":false}]}
{"op":"mcm","clk":"11449459024","pt":1717309459898,"mc":[{"id":"1.229554896","rc":[{"atb":[[1.01,0]],"id":63161712},{"atl":[[2.32,0]],"id":63161712},{"spn":"NaN","spf":"NaN","id":63161712},{"atb":[[3.2,0],[3.7,0]],"id":58069703},{"spn":"NaN","spf":"NaN","id":58069703},{"atb":[[6.4,0],[5.2,0]],"id":50605162},{"atb":[[1.01,0]],"id":65732558},{"atl":[[2.64,0]],"id":65732558},{"spn":"NaN","spf":"NaN","id":65732558},{"atb":[[2.88,0],[2.68,0]],"id":61028210},{"spn":"NaN","spf":"NaN","id":61028210}],"con":true,"img":false}]}
{"op":"mcm","clk":"11449460680","pt":1717309485424,"mc":[{"id":"1.229554896","rc":[{"atb":[[1.01,5807.26]],"id":63161712},{"atl":[[2.34,0.39]],"id":63161712},{"atb":[[3.25,15.48],[3.75,8.44]],"id":58069703},{"atb":[[5.5,7.74],[7,3.87]],"id":50605162},{"atb":[[1.01,5807.26]],"id":65732558},{"atl":[[2.56,0.33]],"id":65732558},{"atb":[[2.74,20.02],[2.94,11.97]],"id":61028210}],"con":true,"img":false}]}
{"op":"mcm","clk":"11449480333","pt":1717309728419,"mc":[{"id":"1.229554896","marketDefinition":{"bspMarket":true,"turnInPlayEnabled":false,"persistenceEnabled":false,"marketBaseRate":7.0,"eventId":"33318908","eventTypeId":"4339","numberOfWinners":2,"bettingType":"ODDS","marketType":"PLACE","marketTime":"2024-06-02T08:41:00.000Z","suspendTime":"2024-06-02T08:41:00.000Z","bspReconciled":false,"complete":true,"inPlay":false,"crossMatching":true,"runnersVoidable":false,"numberOfActiveRunners":5,"betDelay":0,"status":"OPEN","runners":[{"status":"ACTIVE","sortPriority":1,"id":58069703,"name":"1. Dookie"},{"status":"ACTIVE","sortPriority":2,"id":65732558,"name":"2. All The Sass"},{"status":"ACTIVE","sortPriority":3,"id":63161712,"name":"4. Dirty Dash"},{"status":"ACTIVE","sortPriority":4,"id":61028210,"name":"6. Banjo Bob"},{"status":"ACTIVE","sortPriority":5,"id":50605162,"name":"8. Boy From Hill"}],"regulators":["MR_INT"],"venue":"Murray Bridge","countryCode":"AU","discountAllowed":true,"timezone":"Australia/Adelaide","openDate":"2024-06-02T08:21:00.000Z","version":5962317629,"name":"To Be Placed","eventName":"Murray Bridge (AUS) 2nd Jun"},"rc":[{"atb":[[1.01,5807.26]],"id":63161712},{"atl":[[2.34,0.39]],"id":63161712},{"spn":1.67,"spf":"NaN","id":63161712},{"atb":[[3.25,15.48],[3.75,8.44]],"id":58069703},{"spn":"Infinity","spf":"NaN","id":58069703},{"atb":[[5.5,7.74],[7,3.87]],"id":50605162},{"spn":"Infinity","spf":"NaN","id":50605162},{"atb":[[1.01,5807.26]],"id":65732558},{"atl":[[2.56,0.33]],"id":65732558},{"spn":1.78,"spf":"NaN","id":65732558},{"atb":[[2.74,20.02],[2.94,11.97]],"id":61028210},{"spn":"Infinity","spf":"NaN","id":61028210}],"con":true,"img":true}]}
{"op":"mcm","clk":"11449520989","pt":1717310304147,"mc":[{"id":"1.229554896","rc":[{"spn":1.67,"spf":"NaN","id":63161712},{"spn":"Infinity","spf":"NaN","id":58069703},{"atb":[[5.5,0],[7,0]],"id":50605162},{"spn":1.78,"spf":"NaN","id":65732558},{"spn":"Infinity","spf":"NaN","id":61028210}],"con":true,"img":false}]}
{"op":"mcm","clk":"11449521986","pt":1717310319875,"mc":[{"id":"1.229554896","rc":[{"atb":[[6.8,4],[5.4,7.92]],"id":50605162}],"con":true,"img":false}]}
{"op":"mcm","clk":"11449569991","pt":1717311155355,"mc":[{"id":"1.229554896","rc":[{"atb":[[6.8,0],[5.4,0]],"id":50605162}],"con":true,"img":false}]}
{"op":"mcm","clk":"11449570789","pt":1717311169967,"mc":[{"id":"1.229554896","rc":[{"atb":[[6.8,4],[5.4,7.92]],"id":50605162}],"con":true,"img":false}]}
{"op":"mcm","clk":"11449586492","pt":1717311439541,"mc":[{"id":"1.229554896","rc":[{"atb":[[1.02,8.94]],"id":63161712},{"atl":[[1000,0.85]],"id":63161712},{"spn":1.68,"spf":"NaN","id":63161712},{"atb":[[1.02,8.94]],"id":58069703},{"atl":[[1000,0.85]],"id":58069703},{"spn":501.87,"spf":"NaN","id":58069703},{"atb":[[1.01,17.89]],"id":50605162},{"atl":[[990,0.85]],"id":50605162},{"spn":498.4,"spf":"NaN","id":50605162},{"atb":[[1.01,5825.15]],"id":65732558},{"atl":[[1000,0.85]],"id":65732558},{"atb":[[1.03,5.96]],"id":61028210},{"atl":[[990,0.85]],"id":61028210},{"spn":496.47,"spf":"NaN","id":61028210}],"con":true,"img":false}]}
{"op":"mcm","clk":"11449617486","pt":1717312015934,"mc":[{"id":"1.229554896","rc":[{"atb":[[6.8,0],[5.4,0]],"id":50605162},{"spn":495.5,"spf":"NaN","id":50605162}],"con":true,"img":false}]}
{"op":"mcm","clk":"11449618500","pt":1717312035275,"mc":[{"id":"1.229554896","rc":[{"atb":[[5.5,7.74],[7,3.87]],"id":50605162}],"con":true,"img":false}]}
{"op":"mcm","clk":"11449631534","pt":1717312345872,"mc":[{"id":"1.229554896","rc":[{"atb":[[1.05,229.23],[1.04,1409.3]],"id":63161712},{"atl":[[2.82,30.97],[2.58,26.48]],"id":63161712},{"spn":1.69,"spf":"NaN","id":63161712},{"atb":[[3.35,17.8],[3,31.39]],"id":58069703},{"atl":[[38,5.23]],"id":58069703},{"spn":20.87,"spf":"NaN","id":58069703},{"atb":[[5.6,12.73],[6.2,8.04]],"id":50605162},{"atl":[[95,0.44],[100,2.61]],"id":50605162},{"spn":51.0,"spf":"NaN","id":50605162},{"atb":[[1.09,606.01],[1.1,167.41]],"id":65732558},{"atl":[[3.45,22.26],[3.15,19.46]],"id":65732558},{"spn":1.83,"spf":"NaN","id":65732558},{"atb":[[2.24,33.75],[2.06,49.23]],"id":61028210},{"atl":[[21,2.61],[22,2.61]],"id":61028210},{"spn":11.97,"spf":"NaN","id":61028210}],"con":true,"img":false}]}
{"op":"mcm","clk":"11449632511","pt":1717312373315,"mc":[{"id":"1.229554896","rc":[{"atb":[[1.05,103.08]],"id":63161712},{"atb":[[1.1,98.4]],"id":65732558}],"con":true,"img":false}]}
{"op":"mcm","clk":"11449634550","pt":1717312428778,"mc":[{"id":"1.229554896","rc":[{"atb":[[2.76,23.77]],"id":61028210}],"con":true,"img":false}]}
{"op":"mcm","clk":"11449634555","pt":1717312428880,"mc":[{"id":"1.229554896","rc":[{"atb":[[3.35,0],[3,0]],"id":58069703},{"atb":[[2.24,0]],"id":61028210}],"con":true,"img":false}]}
{"op":"mcm","clk":"11449634562","pt":1717312428982,"mc":[{"id":"1.229554896","rc":[{"atb":[[3.8,17.8],[3.3,31.39]],"id":58069703}],"con":true,"img":false}]}
{"op":"mcm","clk":"11449637565","pt":1717312509689,"mc":[{"id":"1.229554896","rc":[{"spn":20.9,"spf":"NaN","id":58069703},{"atb":[[6.2,0]],"id":50605162}],"con":true,"img":false}]}
{"op":"mcm","clk":"11449637572","pt":1717312509788,"mc":[{"id":"1.229554896","rc":[{"atb":[[6.4,8.04]],"id":50605162}],"con":true,"img":false}]}
{"op":"mcm","clk":"11449652142","pt":1717312862827,"mc":[{"id":"1.229554896","rc":[{"atb":[[5.5,0],[7,0]],"id":50605162},{"spn":50.7,"spf":"NaN","id":50605162}],"con":true,"img":false}]}
{"op":"mcm","clk":"11449652922","pt":1717312879671,"mc":[{"id":"1.229554896","rc":[{"atb":[[7.4,3.63],[5.7,7.41]],"id":50605162}],"con":true,"img":false}]}
{"op":"mcm","clk":"11449656911","pt":1717312976641,"mc":[{"id":"1.229554896","rc":[{"atb":[[5.6,0]],"id":50605162},{"spn":51.2,"spf":"NaN","id":50605162}],"con":true,"img":false}]}
{"op":"mcm","clk":"11449656914","pt":1717312976696,"mc":[{"id":"1.229554896","rc":[{"atb":[[5.8,12.73]],"id":50605162}],"con":true,"img":false}]}
{"op":"mcm","clk":"11449703761","pt":1717313733840,"mc":[{"id":"1.229554896","rc":[{"atb":[[7.4,0],[5.7,0]],"id":50605162},{"spn":50.7,"spf":"NaN","id":50605162}],"con":true,"img":false}]}
{"op":"mcm","clk":"11449705303","pt":1717313752774,"mc":[{"id":"1.229554896","rc":[{"atb":[[5.6,7.57],[7.2,3.74]],"id":50605162}],"con":true,"img":false}]}
{"op":"mcm","clk":"11449733443","pt":1717314060376,"mc":[{"id":"1.229554896","rc":[{"atb":[[1.02,2917.04]],"id":63161712},{"atl":[[1.64,26.49]],"id":63161712},{"spn":1.34,"spf":"NaN","id":63161712},{"atb":[[3.25,51.1]],"id":58069703},{"atl":[[36,2.86]],"id":58069703},{"spn":19.9,"spf":"NaN","id":58069703},{"atb":[[5.7,16.1]],"id":50605162},{"atl":[[160,2]],"id":50605162},{"spn":51.1,"spf":"NaN","id":50605162},{"atb":[[1.11,606.01]],"id":65732558},{"atl":[[2.56,19.8]],"id":65732558},{"spn":1.83,"spf":"NaN","id":65732558},{"atb":[[2.24,40.06]],"id":61028210},{"atl":[[21,5.23]],"id":61028210}],"con":true,"img":false}]}
{"op":"mcm","clk":"11449734065","pt":1717314066752,"mc":[{"id":"1.229554896","rc":[{"atl":[[1.64,0],[1.68,52.98]],"id":63161712},{"atl":[[36,0],[42,2.44]],"id":58069703},{"atl":[[190,2]],"id":50605162},{"atl":[[2.56,0.33],[2.8,39.6]],"id":65732558}],"con":true,"img":false}]}
{"op":"mcm","clk":"11449734076","pt":1717314066857,"mc":[{"id":"1.229554896","rc":[{"atl":[[160,0]],"id":50605162}],"con":true,"img":false}]}
{"op":"mcm","clk":"11449735179","pt":1717314079109,"mc":[{"id":"1.229554896","rc":[{"atb":[[3.8,0]],"id":58069703},{"atb":[[2.76,0]],"id":61028210}],"con":true,"img":false}]}
{"op":"mcm","clk":"11449735189","pt":1717314079213,"mc":[{"id":"1.229554896","rc":[{"atb":[[3.35,17.8]],"id":58069703},{"atb":[[2.26,23.77]],"id":61028210}],"con":true,"img":false}]}
{"op":"mcm","clk":"11449735755","pt":1717314085602,"mc":[{"id":"1.229554896","rc":[{"atl":[[2.82,0],[3.8,20.13]],"id":63161712},{"atb":[[2.18,53.88],[3.3,0]],"id":58069703},{"atb":[[6.4,0],[5.8,0],[2.64,35.72],[3.05,20.41]],"id":50605162},{"atl":[[4.8,14.35],[3.45,0]],"id":65732558}],"con":true,"img":false}]}
{"op":"mcm","clk":"11449735764","pt":1717314085690,"mc":[{"id":"1.229554896","rc":[{"atb":[[2.06,0]],"id":61028210}],"con":true,"img":false}]}
{"op":"mcm","clk":"11449735775","pt":1717314085796,"mc":[{"id":"1.229554896","rc":[{"atb":[[1.94,49.23]],"id":61028210}],"con":true,"img":false}]}
{"op":"mcm","clk":"11449736897","pt":1717314098482,"mc":[{"id":"1.229554896","rc":[{"atb":[[3.35,0],[2.46,28.66]],"id":58069703}],"con":true,"img":false}]}
{"op":"mcm","clk":"11449736905","pt":1717314098587,"mc":[{"id":"1.229554896","rc":[{"atl":[[2.58,0]],"id":63161712},{"atl":[[3.15,0]],"id":65732558}],"con":true,"img":false}]}
{"op":"mcm","clk":"11449736912","pt":1717314098692,"mc":[{"id":"1.229554896","rc":[{"atl":[[3.2,26.48]],"id":63161712},{"atl":[[3.95,19.46]],"id":65732558}],"con":true,"img":false}]}
{"op":"mcm","clk":"11449737135","pt":1717314101485,"mc":[{"id":"1.229554896","rc":[{"atb":[[1.01,2.35]],"id":58069703},{"atb":[[2.28,3.06]],"id":61028210}],"con":true,"img":false}]}
{"op":"mcm","clk":"11449737162","pt":1717314101795,"mc":[{"id":"1.229554896","rc":[{"atb":[[1.01,1.67]],"id":58069703}],"con":true,"img":false}]}
{"op":"mcm","clk":"11449737248","pt":1717314102737,"mc":[{"id":"1.229554896","rc":[{"atb":[[1.01,0]],"id":58069703}],"con":true,"img":false}]}
{"op":"mcm","clk":"11449737259","pt":1717314102782,"mc":[{"id":"1.229554896","rc":[{"atb":[[3.35,1.67]],"id":58069703}],"con":true,"img":false}]}
{"op":"mcm","clk":"11449737413","pt":1717314104427,"mc":[{"id":"1.229554896","rc":[{"atb":[[1.01,11614.52],[1.02,8.94]],"id":63161712},{"atl":[[1.68,0],[1.66,26.49]],"id":63161712},{"atb":[[2.42,37.11],[3.25,15.48]],"id":58069703},{"atl":[[42,0],[46,2.22]],"id":58069703},{"atb":[[5.7,0],[3.3,20.41]],"id":50605162},{"atb":[[1.11,0],[1.1,1098.4]],"id":65732558},{"atl":[[2.8,0],[2.6,19.47]],"id":65732558},{"atb":[[2.24,0],[2.06,40.06]],"id":61028210}],"con":true,"img":false}]}
{"op":"mcm","clk":"11449737425","pt":1717314104530,"mc":[{"id":"1.229554896","rc":[{"atl":[[1.66,0],[1.65,26.49]],"id":63161712},{"atb":[[2.42,0],[3.55,28.66]],"id":58069703},{"atb":[[6.2,16.1],[3.3,0]],"id":50605162},{"atl":[[2.52,19.47],[2.6,0]],"id":65732558},{"atb":[[2.4,32.01],[2.06,0]],"id":61028210}],"con":true,"img":false}]}
{"op":"mcm","clk":"11449738453","pt":1717314115828,"mc":[{"id":"1.229554896","rc":[{"atl":[[38,2.61]],"id":58069703},{"atl":[[95,0],[29,2.61]],"id":50605162},{"atb":[[1.1,1000]],"id":65732558},{"atl":[[21,2.62]],"id":61028210}],"con":true,"img":false}]}
{"op":"mcm","clk":"11449738465","pt":1717314115931,"mc":[{"id":"1.229554896","rc":[{"atl":[[21,2.61]],"id":58069703},{"atb":[[1.12,98.4]],"id":65732558},{"atl":[[17,2.61]],"id":61028210}],"con":true,"img":false}]}
{"op":"mcm","clk":"11449738475","pt":1717314116033,"mc":[{"id":"1.229554896","rc":[{"atl":[[21,0],[22,7.37]],"id":61028210}],"con":true,"img":false}]}
{"op":"mcm","clk":"11449738482","pt":1717314116134,"mc":[{"id":"1.229554896","rc":[{"atl":[[17,5.23],[22,2.61]],"id":61028210}],"con":true,"img":false}]}
{"op":"mcm","clk":"11449738536","pt":1717314116704,"mc":[{"id":"1.229554896","rc":[{"atb":[[2.28,0]],"id":61028210}],"con":true,"img":false}]}
{"op":"mcm","clk":"11449738558","pt":1717314116910,"mc":[{"id":"1.229554896","rc":[{"atb":[[2.46,2.69]],"id":61028210}],"con":true,"img":false}]}
{"op":"mcm","clk":"11449738746","pt":1717314118935,"mc":[{"id":"1.229554896","rc":[{"atl":[[120,0.35]],"id":50605162}],"con":true,"img":false}]}
{"op":"mcm","clk":"11449738754","pt":1717314119036,"mc":[{"id":"1.229554896","rc":[{"atl":[[21,0]],"id":58069703},{"atl":[[100,0],[29,0]],"id":50605162}],"con":true,"img":false}]}
{"op":"mcm","clk":"11449738764","pt":1717314119140,"mc":[{"id":"1.229554896","rc":[{"atl":[[36,2.61]],"id":58069703},{"atl":[[600,2],[120,2.96]],"id":50605162}],"con":true,"img":false}]}
{"op":"mcm","clk":"11449738797","pt":1717314119242,"mc":[{"id":"1.229554896","rc":[{"atl":[[190,0],[200,2]],"id":50605162}],"con":true,"img":false}]}
{"op":"mcm","clk":"11449738807","pt":1717314119346,"mc":[{"id":"1.229554896","rc":[{"atl":[[600,0]],"id":50605162}],"con":true,"img":false}]}
{"op":"mcm","clk":"11449739676","pt":1717314128624,"mc":[{"id":"1.229554896","rc":[{"atb":[[1.01,5807.26],[1.02,5008.94]],"id":63161712},{"atl":[[1.65,0],[1.66,52.98]],"id":63161712},{"spn":1.35,"spf":"NaN","id":63161712},{"atb":[[2.42,31.42],[3.55,0]],"id":58069703},{"atl":[[40,2.56],[46,0]],"id":58069703},{"spn":19.87,"spf":"NaN","id":58069703},{"atb":[[6.2,0],[3.3,20.41]],"id":50605162},{"atl":[[180,2],[200,0]],"id":50605162},{"spn":63.6,"spf":"NaN","id":50605162},{"atb":[[1.12,704.41],[1.1,0]],"id":65732558},{"atl":[[2.52,0],[2.6,19.8]],"id":65732558},{"spn":1.84,"spf":"NaN","id":65732558},{"atb":[[2.4,0],[2.06,40.06]],"id":61028210},{"spn":9.97,"spf":"NaN","id":61028210}],"con":true,"img":false}]}
{"op":"mcm","clk":"11449739688","pt":1717314128729,"mc":[{"id":"1.229554896","rc":[{"atb":[[2.42,0],[3.4,37.11]],"id":58069703},{"atb":[[6,20]],"id":50605162},{"atb":[[1.12,98.4],[1.1,1000]],"id":65732558},{"atl":[[2.6,0],[2.68,19.8]],"id":65732558},{"atb":[[2.06,0],[2.32,32.01]],"id":61028210}],"con":true,"img":false}]}
{"op":"mcm","clk":"11449739699","pt":1717314128828,"mc":[{"id":"1.229554896","rc":[{"atb":[[3.3,0]],"id":50605162}],"con":true,"img":false}]}
{"op":"mcm","clk":"11449740627","pt":1717314139069,"mc":[{"id":"1.229554896","rc":[{"atb":[[1.12,0]],"id":65732558}],"con":true,"img":false}]}
{"op":"mcm","clk":"11449740640","pt":1717314139123,"mc":[{"id":"1.229554896","rc":[{"atb":[[1.11,98.4]],"id":65732558}],"con":true,"img":false}]}
{"op":"mcm","clk":"11449741809","pt":1717314153384,"mc":[{"id":"1.229554896","rc":[{"atb":[[5.6,0],[7.2,0]],"id":50605162}],"con":true,"img":false}]}
{"op":"mcm","clk":"11449741821","pt":1717314153491,"mc":[{"id":"1.229554896","rc":[{"atb":[[3.1,40],[6,0]],"id":50605162}],"con":true,"img":false}]}
{"op":"mcm","clk":"11449742173","pt":1717314157864,"mc":[{"id":"1.229554896","rc":[{"atl":[[3.2,0]],"id":63161712},{"atb":[[3.45,17.08],[2.46,0]],"id":58069703},{"atb":[[6.8,7.21],[3.05,0]],"id":50605162},{"atl":[[3.95,0]],"id":65732558}],"con":true,"img":false}]}
{"op":"mcm","clk":"11449742180","pt":1717314157966,"mc":[{"id":"1.229554896","rc":[{"atl":[[2.3,26.48]],"id":63161712},{"atl":[[3.05,19.46]],"id":65732558}],"con":true,"img":false}]}
{"op":"mcm","clk":"11449742651","pt":1717314163984,"mc":[{"id":"1.229554896","rc":[{"atb":[[7.4,3.63],[5.7,7.41]],"id":50605162}],"con":true,"img":false}]}
{"op":"mcm","clk":"11449742763","pt":1717314165170,"mc":[{"id":"1.229554896","rc":[{"atb":[[1.12,606.01],[1.1,0]],"id":65732558}],"con":true,"img":false}]}
{"op":"mcm","clk":"11449743832","pt":1717314176482,"mc":[{"id":"1.229554896","rc":[{"atb":[[1.01,20.25]],"id":50605162}],"con":true,"img":false}]}
{"op":"mcm","clk":"11449743900","pt":1717314177204,"mc":[{"id":"1.229554896","rc":[{"atb":[[1.01,19.67]],"id":50605162}],"con":true,"img":false}]}
{"op":"mcm","clk":"11449743923","pt":1717314177412,"mc":[{"id":"1.229554896","rc":[{"atb":[[1.01,17.89]],"id":50605162}],"con":true,"img":false}]}
{"op":"mcm","clk":"11449743931","pt":1717314177515,"mc":[{"id":"1.229554896","rc":[{"atb":[[3.2,1.78]],"id":50605162}],"con":true,"img":false}]}
{"op":"mcm","clk":"11449743953","pt":1717314177830,"mc":[{"id":"1.229554896","rc":[{"atl":[[2.7,33.15]],"id":63161712},{"atb":[[3.05,30.86]],"id":58069703},{"atl":[[3.3,23.71]],"id":65732558},{"atb":[[1.94,0]],"id":61028210}],"con":true,"img":false}]}
{"op":"mcm","clk":"11449743959","pt":1717314177932,"mc":[{"id":"1.229554896","rc":[{"atl":[[3.8,0]],"id":63161712},{"atb":[[2.18,0]],"id":58069703},{"atl":[[4.8,0]],"id":65732558}],"con":true,"img":false}]}
{"op":"mcm","clk":"11449743967","pt":1717314177994,"mc":[{"id":"1.229554896","rc":[{"atb":[[2.08,49.23]],"id":61028210}],"con":true,"img":false}]}
{"op":"mcm","clk":"11449744994","pt":1717314189723,"mc":[{"id":"1.229554896","rc":[{"atb":[[3.1,0],[6,10.84]],"id":50605162},{"spn":63.7,"spf":"NaN","id":50605162}],"con":true,"img":false}]}
{"op":"mcm","clk":"11449745033","pt":1717314190234,"mc":[{"id":"1.229554896","rc":[{"atb":[[3.35,0]],"id":58069703}],"con":true,"img":false}]}
{"op":"mcm","clk":"11449745613","pt":1717314196820,"mc":[{"id":"1.229554896","rc":[{"atb":[[6,22.55]],"id":50605162},{"atl":[[120,2.61]],"id":50605162}],"con":true,"img":false}]}
{"op":"mcm","clk":"11449745622","pt":1717314196927,"mc":[{"id":"1.229554896","rc":[{"atb":[[2.64,0]],"id":50605162},{"atl":[[95,0.35]],"id":50605162}],"con":true,"img":false}]}
{"op":"mcm","clk":"11449745659","pt":1717314197335,"mc":[{"id":"1.229554896","rc":[{"atb":[[2.46,0]],"id":61028210}],"con":true,"img":false}]}
{"op":"mcm","clk":"11449746496","pt":1717314206378,"mc":[{"id":"1.229554896","rc":[{"atb":[[2.38,2.84]],"id":61028210}],"con":true,"img":false}]}
{"op":"mcm","clk":"11449747070","pt":1717314212655,"mc":[{"id":"1.229554896","rc":[{"atb":[[2.12,3.8]],"id":61028210}],"con":true,"img":false}]}
{"op":"mcm","clk":"11449747416","pt":1717314216461,"mc":[{"id":"1.229554896","rc":[{"atl":[[120,0]],"id":50605162},{"atb":[[2.26,0]],"id":61028210}],"con":true,"img":false}]}
{"op":"mcm","clk":"11449747425","pt":1717314216564,"mc":[{"id":"1.229554896","rc":[{"atl":[[580,2],[180,0],[100,2.61]],"id":50605162},{"atb":[[2.34,23.77]],"id":61028210}],"con":true,"img":false}]}
{"op":"mcm","clk":"11449747911","pt":1717314221785,"mc":[{"id":"1.229554896","rc":[{"atb":[[2.38,0]],"id":61028210}],"con":true,"img":false}]}
{"op":"mcm","clk":"11449747934","pt":1717314221945,"mc":[{"id":"1.229554896","rc":[{"atb":[[2.4,2.8]],"id":61028210}],"con":true,"img":false}]}
{"op":"mcm","clk":"11449749275","pt":1717314235606,"mc":[{"id":"1.229554896","rc":[{"atl":[[95,0],[100,0]],"id":50605162}],"con":true,"img":false}]}
{"op":"mcm","clk":"11449749285","pt":1717314235712,"mc":[{"id":"1.229554896","rc":[{"atl":[[120,2.96]],"id":50605162}],"con":true,"img":false}]}
{"op":"mcm","clk":"11449750516","pt":1717314248600,"mc":[{"id":"1.229554896","rc":[{"atl":[[1.68,105.96],[1.66,0]],"id":63161712},{"atb":[[3.4,0],[3.25,49.64]],"id":58069703},{"atl":[[40,0],[42,2.44]],"id":58069703},{"atb":[[6,11.71],[5.7,21.83]],"id":50605162},{"atb":[[1.12,0],[1.11,1007.49]],"id":65732558},{"atl":[[2.8,20.13],[2.68,0]],"id":65732558}],"con":true,"img":false}]}
{"op":"mcm","clk":"11449750526","pt":1717314248701,"mc":[{"id":"1.229554896","rc":[{"atb":[[1.11,98.4],[1.1,1000]],"id":65732558}],"con":true,"img":false}]}
{"op":"mcm","clk":"11449750653","pt":1717314250008,"mc":[{"id":"1.229554896","rc":[{"spn":1.36,"spf":"NaN","id":63161712},{"atb":[[3.35,1.81]],"id":58069703},{"spn":1.83,"spf":"NaN","id":65732558}],"con":true,"img":false}]}
{"op":"mcm","clk":"11449750802","pt":1717314251617,"mc":[{"id":"1.229554896","rc":[{"atb":[[3.2,0]],"id":50605162}],"con":true,"img":false}]}
{"op":"mcm","clk":"11449750848","pt":1717314252131,"mc":[{"id":"1.229554896","rc":[{"atl":[[580,0],[190,2]],"id":50605162}],"con":true,"img":false}]}
{"op":"mcm","clk":"11449752806","pt":1717314273235,"mc":[{"id":"1.229554896","rc":[{"atl":[[2.3,0],[3.75,20.49],[2.7,0]],"id":63161712},{"atb":[[3.45,0],[2.5,27.9],[2.18,53.88],[3.05,0]],"id":58069703},{"atb":[[2.8,32.55],[6.8,0],[6,0],[3.25,18.6]],"id":50605162},{"atl":[[4.9,13.98],[4.4,12.31],[3.3,0],[3.05,0]],"id":65732558},{"atb":[[2.34,0],[2.08,0]],"id":61028210}],"con":true,"img":false}]}
{"op":"mcm","clk":"11449752812","pt":1717314273331,"mc":[{"id":"1.229554896","rc":[{"atl":[[3.1,26.48]],"id":63161712},{"atb":[[1.94,49.23],[2.08,23.77]],"id":61028210}],"con":true,"img":false}]}
{"op":"mcm","clk":"11449753646","pt":1717314283965,"mc":[{"id":"1.229554896","rc":[{"atb":[[1.11,704.41]],"id":65732558}],"con":true,"img":false}]}
{"op":"mcm","clk":"11449753654","pt":1717314284067,"mc":[{"id":"1.229554896","rc":[{"atb":[[1.1,0]],"id":65732558}],"con":true,"img":false}]}
{"op":"mcm","clk":"11449753810","pt":1717314285735,"mc":[{"id":"1.229554896","rc":[{"atb":[[2.12,0]],"id":61028210}],"con":true,"img":false}]}
{"op":"mcm","clk":"11449754572","pt":1717314295496,"mc":[{"id":"1.229554896","rc":[{"atl":[[120,2.61]],"id":50605162}],"con":true,"img":false}]}
{"op":"mcm","clk":"11449754582","pt":1717314295554,"mc":[{"id":"1.229554896","rc":[{"atl":[[36,0]],"id":58069703},{"atl":[[32,2.61]],"id":50605162}],"con":true,"img":false}]}
{"op":"mcm","clk":"11449754590","pt":1717314295653,"mc":[{"id":"1.229554896","rc":[{"atl":[[21,2.61]],"id":58069703}],"con":true,"img":false}]}
{"op":"mcm","clk":"11449756011","pt":1717314311988,"mc":[{"id":"1.229554896","rc":[{"atb":[[1.01,2.35]],"id":58069703},{"spn":12.37,"spf":"NaN","id":58069703},{"spn":19.7,"spf":"NaN","id":50605162}],"con":true,"img":false}]}
{"op":"mcm","clk":"11449756097","pt":1717314312814,"mc":[{"id":"1.229554896","rc":[{"atb":[[1.01,1.67]],"id":58069703}],"con":true,"img":false}]}
{"op":"mcm","clk":"11449756113","pt":1717314313012,"mc":[{"id":"1.229554896","rc":[{"atb":[[1.01,0]],"id":58069703}],"con":true,"img":false}]}
{"op":"mcm","clk":"11449756127","pt":1717314313120,"mc":[{"id":"1.229554896","rc":[{"atb":[[3.35,3.48]],"id":58069703}],"con":true,"img":false}]}
{"op":"mcm","clk":"11449756781","pt":1717314320906,"mc":[{"id":"1.229554896","rc":[{"atl":[[38,0]],"id":58069703},{"atl":[[120,0]],"id":50605162},{"atl":[[22,0]],"id":61028210}],"con":true,"img":false}]}
{"op":"mcm","clk":"11449756789","pt":1717314321017,"mc":[{"id":"1.229554896","rc":[{"atl":[[22,2.61]],"id":58069703},{"atl":[[34,2.61]],"id":50605162},{"atl":[[18.5,2.61]],"id":61028210}],"con":true,"img":false}]}
{"op":"mcm","clk":"11449758512","pt":1717314341842,"mc":[{"id":"1.229554896","rc":[{"atb":[[2.4,0]],"id":61028210}],"con":true,"img":false}]}
{"op":"mcm","clk":"11449759815","pt":1717314356853,"mc":[{"id":"1.229554896","rc":[{"atb":[[2.38,2.84]],"id":61028210}],"con":true,"img":false}]}
{"op":"mcm","clk":"11449777970","pt":1717314555619,"mc":[{"id":"1.229554896","rc":[{"atb":[[7.4,0],[5.7,14.42]],"id":50605162},{"spn":18.85,"spf":"NaN","id":50605162}],"con":true,"img":false}]}
{"op":"mcm","clk":"11449777979","pt":1717314555718,"mc":[{"id":"1.229554896","rc":[{"atb":[[3.3,28.84]],"id":50605162}],"con":true,"img":false}]}
{"op":"mcm","clk":"11449777991","pt":1717314555822,"mc":[{"id":"1.229554896","rc":[{"atb":[[5.7,0]],"id":50605162}],"con":true,"img":false}]}
{"op":"mcm","clk":"11449779736","pt":1717314575423,"mc":[{"id":"1.229554896","rc":[{"atb":[[7.8,3.41],[5.9,7.1]],"id":50605162}],"con":true,"img":false}]}
{"op":"mcm","clk":"11449780742","pt":1717314587951,"mc":[{"id":"1.229554896","rc":[{"atb":[[5.7,21.28]],"id":50605162}],"con":true,"img":false}]}
{"op":"mcm","clk":"11449780751","pt":1717314588057,"mc":[{"id":"1.229554896","rc":[{"atb":[[3.3,0]],"id":50605162}],"con":true,"img":false}]}
{"op":"mcm","clk":"11449808484","pt":1717314914969,"mc":[{"id":"1.229554896","rc":[{"atb":[[7.8,0],[5.9,0]],"id":50605162}],"con":true,"img":false}]}
{"op":"mcm","clk":"11449808495","pt":1717314915068,"mc":[{"id":"1.229554896","rc":[{"atb":[[5.7,0],[3.3,42.56]],"id":50605162}],"con":true,"img":false}]}
{"op":"mcm","clk":"11449809465","pt":1717314925667,"mc":[{"id":"1.229554896","rc":[{"atl":[[1.72,138.89],[1.68,0]],"id":63161712},{"atl":[[2.8,0],[2.92,20.46]],"id":65732558}],"con":true,"img":false}]}
{"op":"mcm","clk":"11449810835","pt":1717314940922,"mc":[{"id":"1.229554896","rc":[{"atb":[[5.8,7.26],[7.6,3.52]],"id":50605162}],"con":true,"img":false}]}
{"op":"mcm","clk":"11449810846","pt":1717314941029,"mc":[{"id":"1.229554896","rc":[{"atb":[[5.7,21.28],[3.3,0]],"id":50605162}],"con":true,"img":false}]}
{"op":"mcm","clk":"11449811242","pt":1717314945609,"mc":[{"id":"1.229554896","rc":[{"atl":[[1.68,26.49]],"id":63161712},{"atl":[[2.8,13.98]],"id":65732558}],"con":true,"img":false}]}
{"op":"mcm","clk":"11449811252","pt":1717314945716,"mc":[{"id":"1.229554896","rc":[{"atl":[[1.72,0]],"id":63161712},{"atl":[[2.92,0]],"id":65732558}],"con":true,"img":false}]}
{"op":"mcm","clk":"11449811420","pt":1717314947829,"mc":[{"id":"1.229554896","rc":[{"atl":[[3.1,0],[3.4,17.43]],"id":63161712},{"atb":[[3.25,0]],"id":50605162}],"con":true,"img":false}]}
{"op":"mcm","clk":"11449811430","pt":1717314947887,"mc":[{"id":"1.229554896","rc":[{"atb":[[3.35,18.6]],"id":50605162}],"con":true,"img":false}]}
{"op":"mcm","clk":"11449814555","pt":1717314983275,"mc":[{"id":"1.229554896","rc":[{"spn":19.8,"spf":"NaN","id":50605162},{"atl":[[16.5,3.36],[18.5,0]],"id":61028210},{"spn":9.72,"spf":"NaN","id":61028210}],"con":true,"img":false}]}
{"op":"mcm","clk":"11449814568","pt":1717314983341,"mc":[{"id":"1.229554896","rc":[{"atl":[[16,3.37]],"id":61028210}],"con":true,"img":false}]}
{"op":"mcm","clk":"11449814577","pt":1717314983435,"mc":[{"id":"1.229554896","rc":[{"atl":[[17,2.61]],"id":61028210}],"con":true,"img":false}]}
{"op":"mcm","clk":"11449815448","pt":1717314992786,"mc":[{"id":"1.229554896","rc":[{"atl":[[980,1.38]],"id":63161712},{"atb":[[1.02,115.46]],"id":58069703},{"atl":[[970,1.53]],"id":58069703},{"atb":[[1.03,137.19]],"id":50605162},{"atl":[[970,0.86]],"id":50605162},{"atb":[[1.01,5982.8]],"id":65732558},{"atl":[[960,1.57]],"id":65732558},{"atb":[[1.02,98.84]],"id":61028210},{"atl":[[960,0.86]],"id":61028210}],"con":true,"img":false}]}
{"op":"mcm","clk":"11449816023","pt":1717314998990,"mc":[{"id":"1.229554896","rc":[{"atl":[[16.5,0]],"id":61028210}],"con":true,"img":false}]}
{"op":"mcm","clk":"11449816032","pt":1717314999095,"mc":[{"id":"1.229554896","rc":[{"atl":[[16,0],[17,8.86],[19,3.36]],"id":61028210}],"con":true,"img":false}]}
{"op":"mcm","clk":"11449816043","pt":1717314999197,"mc":[{"id":"1.229554896","rc":[{"atl":[[17,2.61],[55,2]],"id":61028210}],"con":true,"img":false}]}
{"op":"mcm","clk":"11449817170","pt":1717315011202,"mc":[{"id":"1.229554896","rc":[{"atl":[[17,5.23],[55,0]],"id":61028210}],"con":true,"img":false}]}
{"op":"mcm","clk":"11449817632","pt":1717315016626,"mc":[{"id":"1.229554896","rc":[{"atl":[[21,0],[22,0]],"id":58069703},{"atl":[[32,0],[34,0],[120,0.35]],"id":50605162},{"atl":[[17,2.62],[19,0],[21,2.61]],"id":61028210}],"con":true,"img":false}]}
{"op":"mcm","clk":"11449817644","pt":1717315016727,"mc":[{"id":"1.229554896","rc":[{"atl":[[36,2.61],[38,2.61],[42,0],[360,2]],"id":58069703},{"atl":[[590,2],[190,0],[120,2.96]],"id":50605162},{"atl":[[17,0],[19.5,2.61],[21,7.61]],"id":61028210}],"con":true,"img":false}]}
{"op":"mcm","clk":"11449817654","pt":1717315016829,"mc":[{"id":"1.229554896","rc":[{"atl":[[42,2.44],[360,0]],"id":58069703},{"atl":[[590,0],[190,2]],"id":50605162},{"atl":[[21,2.61],[55,2]],"id":61028210}],"con":true,"img":false}]}
{"op":"mcm","clk":"11449818761","pt":1717315028652,"mc":[{"id":"1.229554896","rc":[{"atl":[[1000,0.17]],"id":63161712},{"atl":[[1000,0.17]],"id":58069703},{"atl":[[990,0.17]],"id":50605162},{"atl":[[1000,0.17]],"id":65732558},{"atl":[[990,0.17]],"id":61028210}],"con":true,"img":false}]}
{"op":"mcm","clk":"11449819513","pt":1717315036461,"mc":[{"id":"1.229554896","rc":[{"atl":[[3.4,0],[2.48,28.27]],"id":63161712},{"atb":[[2.5,0],[3.35,21.68]],"id":58069703},{"atb":[[3.35,0],[6.8,7.21]],"id":50605162},{"atl":[[4.4,0],[3.05,20.41]],"id":65732558},{"atb":[[2.24,33.75],[2.08,0]],"id":61028210}],"con":true,"img":false}]}
{"op":"mcm","clk":"11449819759","pt":1717315038857,"mc":[{"id":"1.229554896","rc":[{"atl":[[19.5,5.23],[55,0]],"id":61028210}],"con":true,"img":false}]}
{"op":"mcm","clk":"11449821473","pt":1717315056275,"mc":[{"id":"1.229554896","rc":[{"atl":[[2.72,32.77],[3.75,0]],"id":63161712},{"spn":19.87,"spf":"NaN","id":58069703},{"spn":63.8,"spf":"NaN","id":50605162},{"atl":[[3.35,23.2],[4.9,0]],"id":65732558},{"atb":[[1.94,0]],"id":61028210},{"spn":11.22,"spf":"NaN","id":61028210}],"con":true,"img":false}]}
{"op":"mcm","clk":"11449821483","pt":1717315056379,"mc":[{"id":"1.229554896","rc":[{"atb":[[2.08,49.23]],"id":61028210}],"con":true,"img":false}]}
{"op":"mcm","clk":"11449823192","pt":1717315073810,"mc":[{"id":"1.229554896","rc":[{"atb":[[2.18,0],[3.3,27.72]],"id":58069703},{"atb":[[2.8,0],[6,11.71]],"id":50605162}],"con":true,"img":false}]}
{"op":"mcm","clk":"11449824531","pt":1717315089020,"mc":[{"id":"1.229554896","rc":[{"atb":[[2.24,0]],"id":61028210}],"con":true,"img":false}]}
{"op":"mcm","clk":"11449824539","pt":1717315089120,"mc":[{"id":"1.229554896","rc":[{"atb":[[2.34,33.75]],"id":61028210}],"con":true,"img":false}]}
{"op":"mcm","clk":"11449825003","pt":1717315094111,"mc":[{"id":"1.229554896","rc":[{"atb":[[3.35,19.86]],"id":58069703}],"con":true,"img":false}]}
{"op":"mcm","clk":"11449825032","pt":1717315094418,"mc":[{"id":"1.229554896","rc":[{"atb":[[2.12,3.8]],"id":61028210}],"con":true,"img":false}]}
{"op":"mcm","clk":"11449825049","pt":1717315094628,"mc":[{"id":"1.229554896","rc":[{"atb":[[2.38,0]],"id":61028210}],"con":true,"img":false}]}
{"op":"mcm","clk":"11449825899","pt":1717315103950,"mc":[{"id":"1.229554896","rc":[{"atl":[[21,0]],"id":61028210}],"con":true,"img":false}]}
{"op":"mcm","clk":"11449825910","pt":1717315104052,"mc":[{"id":"1.229554896","rc":[{"atl":[[19,2.61]],"id":61028210}],"con":true,"img":false}]}
{"op":"mcm","clk":"11449830279","pt":1717315128428,"mc":[{"id":"1.229554896","marketDefinition":{"bspMarket":true,"turnInPlayEnabled":false,"persistenceEnabled":false,"marketBaseRate":7.0,"eventId":"33318908","eventTypeId":"4339","numberOfWinners":2,"bettingType":"ODDS","marketType":"PLACE","marketTime":"2024-06-02T08:41:00.000Z","suspendTime":"2024-06-02T08:41:00.000Z","bspReconciled":false,"complete":true,"inPlay":false,"crossMatching":true,"runnersVoidable":false,"numberOfActiveRunners":5,"betDelay":0,"status":"OPEN","runners":[{"status":"ACTIVE","sortPriority":1,"id":58069703,"name":"1. Dookie"},{"status":"ACTIVE","sortPriority":2,"id":65732558,"name":"2. All The Sass"},{"status":"ACTIVE","sortPriority":3,"id":63161712,"name":"4. Dirty Dash"},{"status":"ACTIVE","sortPriority":4,"id":61028210,"name":"6. Banjo Bob"},{"status":"ACTIVE","sortPriority":5,"id":50605162,"name":"8. Boy From Hill"}],"regulators":["MR_INT"],"venue":"Murray Bridge","countryCode":"AU","discountAllowed":true,"timezone":"Australia/Adelaide","openDate":"2024-06-02T08:21:00.000Z","version":5962317629,"name":"To Be Placed","eventName":"Murray Bridge (AUS) 2nd Jun"},"rc":[{"atb":[[1.01,5807.26],[1.02,5008.94],[1.05,103.08],[1.04,1409.3]],"id":63161712},{"atl":[[2.72,32.77],[1.68,26.49],[2.34,0.39],[2.48,28.27],[980,1.38],[1000,0.17]],"id":63161712},{"spn":1.36,"spf":"NaN","id":63161712},{"atb":[[3.35,19.86],[1.02,115.46],[3.25,49.64],[3.3,27.72],[3.75,8.44]],"id":58069703},{"atl":[[36,2.61],[38,2.61],[42,2.44],[970,1.53],[1000,0.17]],"id":58069703},{"spn":19.87,"spf":"NaN","id":58069703},{"atb":[[1.01,17.89],[5.8,7.26],[1.03,137.19],[7.6,3.52],[6.8,7.21],[6,11.71],[5.7,21.28]],"id":50605162},{"atl":[[190,2],[120,2.96],[970,0.86],[990,0.17]],"id":50605162},{"spn":63.8,"spf":"NaN","id":50605162},{"atb":[[1.01,5982.8],[1.11,704.41],[1.09,606.01]],"id":65732558},{"atl":[[2.56,0.33],[2.8,13.98],[3.35,23.2],[3.05,20.41],[960,1.57],[1000,0.17]],"id":65732558},{"spn":1.83,"spf":"NaN","id":65732558},{"atb":[[2.74,20.02],[2.32,32.01],[1.03,5.96],[1.02,98.84],[2.12,3.8],[2.94,11.97],[2.34,33.75],[2.08,49.23]],"id":61028210},{"atl":[[19,2.61],[19.5,5.23],[960,0.86],[990,0.17]],"id":61028210},{"spn":10.97,"spf":"NaN","id":61028210}],"con":true,"img":true}]}
{"op":"mcm","clk":"11449835512","pt":1717315133961,"mc":[{"id":"1.229554896","rc":[{"atb":[[3.4,1.77]],"id":58069703},{"spn":10.97,"spf":"NaN","id":61028210}],"con":true,"img":false}]}
{"op":"mcm","clk":"11449843437","pt":1717315215576,"mc":[{"id":"1.229554896","rc":[{"atb":[[2.4,2.8]],"id":61028210}],"con":true,"img":false}]}
{"op":"mcm","clk":"11449844552","pt":1717315226613,"mc":[{"id":"1.229554896","rc":[{"atl":[[120,2.61]],"id":50605162}],"con":true,"img":false}]}
{"op":"mcm","clk":"11449844566","pt":1717315226726,"mc":[{"id":"1.229554896","rc":[{"atl":[[95,0.35]],"id":50605162}],"con":true,"img":false}]}
{"op":"mcm","clk":"11449846265","pt":1717315245344,"mc":[{"id":"1.229554896","rc":[{"atl":[[120,0]],"id":50605162}],"con":true,"img":false}]}
{"op":"mcm","clk":"11449846275","pt":1717315245396,"mc":[{"id":"1.229554896","rc":[{"atl":[[590,2],[190,0],[100,2.61]],"id":50605162}],"con":true,"img":false}]}
{"op":"mcm","clk":"11449847708","pt":1717315259865,"mc":[{"id":"1.229554896","rc":[{"atl":[[95,0],[100,0]],"id":50605162}],"con":true,"img":false}]}
{"op":"mcm","clk":"11449847717","pt":1717315259909,"mc":[{"id":"1.229554896","rc":[{"atl":[[120,2.96]],"id":50605162}],"con":true,"img":false}]}
{"op":"mcm","clk":"11449848770","pt":1717315270651,"mc":[{"id":"1.229554896","rc":[{"atl":[[190,2]],"id":50605162}],"con":true,"img":false}]}
{"op":"mcm","clk":"11449848777","pt":1717315270781,"mc":[{"id":"1.229554896","rc":[{"atl":[[590,0]],"id":50605162}],"con":true,"img":false}]}
{"op":"mcm","clk":"11449851196","pt":1717315295583,"mc":[{"id":"1.229554896","rc":[{"atb":[[5.8,0],[7.6,0]],"id":50605162},{"spn":63.4,"spf":"NaN","id":50605162}],"con":true,"img":false}]}
{"op":"mcm","clk":"11449853607","pt":1717315320659,"mc":[{"id":"1.229554896","rc":[{"atb":[[7.4,3.63],[5.7,28.69]],"id":50605162}],"con":true,"img":false}]}
{"op":"mcm","clk":"11449866506","pt":1717315447130,"mc":[{"id":"1.229554896","rc":[{"atb":[[1.01,11614.52],[1.02,8.94]],"id":63161712},{"atl":[[1.68,0],[1.66,26.49]],"id":63161712},{"spn":1.35,"spf":"NaN","id":63161712},{"atb":[[2.42,70.42],[3.25,15.48]],"id":58069703},{"atl":[[42,0],[46,2.22]],"id":58069703},{"atb":[[5.7,7.41],[3.3,43.48]],"id":50605162},{"spn":63.7,"spf":"NaN","id":50605162},{"atb":[[1.11,98.4],[1.1,1000]],"id":65732558},{"atl":[[2.8,0],[2.6,20.41]],"id":65732558},{"atb":[[2.32,0],[2.06,52.41]],"id":61028210}],"con":true,"img":false}]}
{"op":"mcm","clk":"11449866517","pt":1717315447234,"mc":[{"id":"1.229554896","rc":[{"atb":[[2.42,0],[3.55,19.87]],"id":58069703}],"con":true,"img":false}]}
{"op":"mcm","clk":"11449866531","pt":1717315447341,"mc":[{"id":"1.229554896","rc":[{"atb":[[6.2,11.72],[3.3,0]],"id":50605162}],"con":true,"img":false}]}
{"op":"mcm","clk":"11449866641","pt":1717315448473,"mc":[{"id":"1.229554896","rc":[{"atl":[[40,2.56],[46,0]],"id":58069703},{"atl":[[180,2]],"id":50605162}],"con":true,"img":false}]}
{"op":"mcm","clk":"11449866654","pt":1717315448526,"mc":[{"id":"1.229554896","rc":[{"atl":[[190,0]],"id":50605162}],"con":true,"img":false}]}
{"op":"mcm","clk":"11449866694","pt":1717315448953,"mc":[{"id":"1.229554896","rc":[{"atb":[[3.3,0]],"id":58069703}],"con":true,"img":false}]}
{"op":"mcm","clk":"11449866707","pt":1717315449042,"mc":[{"id":"1.229554896","rc":[{"atb":[[3.05,27.72]],"id":58069703}],"con":true,"img":false}]}
{"op":"mcm","clk":"11449867058","pt":1717315452236,"mc":[{"id":"1.229554896","rc":[{"atl":[[2.68,20.74]],"id":65732558}],"con":true,"img":false}]}
{"op":"mcm","clk":"11449867072","pt":1717315452344,"mc":[{"id":"1.229554896","rc":[{"atb":[[3.4,30.09]],"id":58069703},{"atl":[[2.6,0]],"id":65732558}],"con":true,"img":false}]}
{"op":"mcm","clk":"11449867084","pt":1717315452495,"mc":[{"id":"1.229554896","rc":[{"atb":[[3.55,0]],"id":58069703}],"con":true,"img":false}]}
{"op":"mcm","clk":"11449868942","pt":1717315470376,"mc":[{"id":"1.229554896","rc":[{"atb":[[1.02,5008.94]],"id":63161712},{"atb":[[1.12,606.01]],"id":65732558}],"con":true,"img":false}]}
{"op":"mcm","clk":"11449868956","pt":1717315470477,"mc":[{"id":"1.229554896","rc":[{"atb":[[1.01,5807.26]],"id":63161712},{"atb":[[1.1,0]],"id":65732558},{"atb":[[2.06,0],[2.32,49.23]],"id":61028210}],"con":true,"img":false}]}
{"op":"mcm","clk":"11449869291","pt":1717315473375,"mc":[{"id":"1.229554896","rc":[{"atb":[[3.4,28.32]],"id":58069703},{"atb":[[2.12,0]],"id":61028210}],"con":true,"img":false}]}
{"op":"mcm","clk":"11449870499","pt":1717315484191,"mc":[{"id":"1.229554896","rc":[{"atb":[[3.35,1.67]],"id":58069703}],"con":true,"img":false}]}
{"op":"mcm","clk":"11449870505","pt":1717315484295,"mc":[{"id":"1.229554896","rc":[{"atb":[[3.45,18.19]],"id":58069703}],"con":true,"img":false}]}
{"op":"mcm","clk":"11449873481","pt":1717315513329,"mc":[{"id":"1.229554896","rc":[{"spn":1.84,"spf":"NaN","id":65732558},{"atb":[[2.38,3.08]],"id":61028210}],"con":true,"img":false}]}
{"op":"mcm","clk":"11449877179","pt":1717315549775,"mc":[{"id":"1.229554896","rc":[{"atb":[[3.35,0]],"id":58069703}],"con":true,"img":false}]}
{"op":"mcm","clk":"11449878912","pt":1717315568522,"mc":[{"id":"1.229554896","rc":[{"atl":[[1.68,52.98],[1.66,0]],"id":63161712},{"atb":[[3.4,0],[3.25,51.88]],"id":58069703},{"atl":[[40,0],[42,2.44]],"id":58069703},{"atb":[[6.2,0],[5.7,26.34]],"id":50605162},{"atb":[[1.12,0],[1.11,1007.49]],"id":65732558},{"atl":[[2.8,21.07],[2.68,0]],"id":65732558}],"con":true,"img":false}]}
{"op":"mcm","clk":"11449879790","pt":1717315577203,"mc":[{"id":"1.229554896","rc":[{"spn":1.36,"spf":"NaN","id":63161712},{"spn":1.83,"spf":"NaN","id":65732558},{"atl":[[19,0]],"id":61028210},{"spn":11.22,"spf":"NaN","id":61028210}],"con":true,"img":false}]}
{"op":"mcm","clk":"11449879800","pt":1717315577306,"mc":[{"id":"1.229554896","rc":[{"atl":[[21,2.61]],"id":61028210}],"con":true,"img":false}]}
{"op":"mcm","clk":"11449880444","pt":1717315583326,"mc":[{"id":"1.229554896","rc":[{"atl":[[2.72,0],[3.75,20.49]],"id":63161712},{"atb":[[2.16,54.41],[3.05,0]],"id":58069703},{"atb":[[6.8,0],[6,0],[3.25,18.6],[2.78,32.91]],"id":50605162},{"atl":[[4.5,11.95],[5,13.63],[3.35,0],[3.05,0]],"id":65732558},{"atb":[[2.08,0]],"id":61028210}],"con":true,"img":false}]}
{"op":"mcm","clk":"11449880457","pt":1717315583435,"mc":[{"id":"1.229554896","rc":[{"atb":[[1.91,49.23]],"id":61028210}],"con":true,"img":false}]}
{"op":"mcm","clk":"11449880542","pt":1717315584213,"mc":[{"id":"1.229554896","rc":[{"atb":[[3.35,1.81]],"id":58069703}],"con":true,"img":false}]}
{"op":"mcm","clk":"11449880935","pt":1717315588194,"mc":[{"id":"1.229554896","rc":[{"atb":[[2.46,28.66]],"id":58069703}],"con":true,"img":false}]}
{"op":"mcm","clk":"11449880945","pt":1717315588312,"mc":[{"id":"1.229554896","rc":[{"atl":[[2.48,0]],"id":63161712},{"atb":[[3.45,0]],"id":58069703}],"con":true,"img":false}]}
{"op":"mcm","clk":"11449880957","pt":1717315588413,"mc":[{"id":"1.229554896","rc":[{"atl":[[2.7,28.27]],"id":63161712}],"con":true,"img":false}]}
{"op":"mcm","clk":"11449881713","pt":1717315595757,"mc":[{"id":"1.229554896","rc":[{"atb":[[1.01,2.35]],"id":58069703}],"con":true,"img":false}]}
{"op":"mcm","clk":"11449881739","pt":1717315596021,"mc":[{"id":"1.229554896","rc":[{"atb":[[1.01,1.67]],"id":58069703}],"con":true,"img":false}]}
{"op":"mcm","clk":"11449881769","pt":1717315596323,"mc":[{"id":"1.229554896","rc":[{"atb":[[1.01,0]],"id":58069703}],"con":true,"img":false}]}
{"op":"mcm","clk":"11449881780","pt":1717315596425,"mc":[{"id":"1.229554896","rc":[{"atb":[[3.35,3.48]],"id":58069703}],"con":true,"img":false}]}
{"op":"mcm","clk":"11449882206","pt":1717315601150,"mc":[{"id":"1.229554896","rc":[{"atl":[[3.15,19.46],[2.7,0]],"id":63161712}],"con":true,"img":false}]}
{"op":"mcm","clk":"11449882484","pt":1717315603754,"mc":[{"id":"1.229554896","rc":[{"atl":[[19.5,2.62]],"id":61028210}],"con":true,"img":false}]}
{"op":"mcm","clk":"11449882495","pt":1717315603860,"mc":[{"id":"1.229554896","rc":[{"atl":[[17.5,2.61],[21,7.61]],"id":61028210}],"con":true,"img":false}]}
{"op":"mcm","clk":"11449882507","pt":1717315603964,"mc":[{"id":"1.229554896","rc":[{"atl":[[19.5,0]],"id":61028210}],"con":true,"img":false}]}
{"op":"mcm","clk":"11449882987","pt":1717315608633,"mc":[{"id":"1.229554896","rc":[{"atl":[[36,0]],"id":58069703},{"atb":[[3.25,0]],"id":50605162},{"atl":[[32,2.61],[120,2.61]],"id":50605162}],"con":true,"img":false}]}
{"op":"mcm","clk":"11449882997","pt":1717315608737,"mc":[{"id":"1.229554896","rc":[{"atl":[[21,2.61]],"id":58069703},{"atb":[[2.98,18.6]],"id":50605162}],"con":true,"img":false}]}
{"op":"mcm","clk":"11449883207","pt":1717315610456,"mc":[{"id":"1.229554896","rc":[{"atb":[[3.35,1.81]],"id":58069703}],"con":true,"img":false}]}
{"op":"mcm","clk":"11449884812","pt":1717315625547,"mc":[{"id":"1.229554896","rc":[{"atl":[[17.5,5.23],[21,2.61]],"id":61028210}],"con":true,"img":false}]}
{"op":"mcm","clk":"11449884836","pt":1717315625759,"mc":[{"id":"1.229554896","rc":[{"atb":[[1.01,2.35]],"id":58069703}],"con":true,"img":false}]}
{"op":"mcm","clk":"11449884871","pt":1717315626069,"mc":[{"id":"1.229554896","rc":[{"atb":[[1.01,1.67]],"id":58069703}],"con":true,"img":false}]}
{"op":"mcm","clk":"11449884908","pt":1717315626381,"mc":[{"id":"1.229554896","rc":[{"atb":[[1.01,0]],"id":58069703}],"con":true,"img":false}]}
{"op":"mcm","clk":"11449884917","pt":1717315626499,"mc":[{"id":"1.229554896","rc":[{"atb":[[3.35,3.48]],"id":58069703}],"con":true,"img":false}]}
{"op":"mcm","clk":"11449887603","pt":1717315653112,"mc":[{"id":"1.229554896","rc":[{"atl":[[38,0]],"id":58069703},{"spn":12.37,"spf":"NaN","id":58069703},{"atl":[[120,0]],"id":50605162},{"spn":19.7,"spf":"NaN","id":50605162},{"spn":10.22,"spf":"NaN","id":61028210}],"con":true,"img":false}]}
{"op":"mcm","clk":"11449887619","pt":1717315653221,"mc":[{"id":"1.229554896","rc":[{"atl":[[23,2.61]],"id":58069703},{"atl":[[34,2.61]],"id":50605162}],"con":true,"img":false}]}
{"op":"mcm","clk":"11449890656","pt":1717315683663,"mc":[{"id":"1.229554896","rc":[{"atb":[[2.98,0]],"id":50605162}],"con":true,"img":false}]}
{"op":"mcm","clk":"11449890670","pt":1717315683767,"mc":[{"id":"1.229554896","rc":[{"atb":[[3.2,18.6]],"id":50605162}],"con":true,"img":false}]}
{"op":"mcm","clk":"11449893588","pt":1717315712098,"mc":[{"id":"1.229554896","rc":[{"atb":[[7.4,0],[5.7,18.93]],"id":50605162}],"con":true,"img":false}]}
{"op":"mcm","clk":"11449893610","pt":1717315712303,"mc":[{"id":"1.229554896","rc":[{"atb":[[3.25,37.86],[5.7,0]],"id":50605162}],"con":true,"img":false}]}
{"op":"mcm","clk":"11449893933","pt":1717315715380,"mc":[{"id":"1.229554896","rc":[{"atb":[[1.01,20.25]],"id":50605162},{"spn":17.62,"spf":"NaN","id":50605162}],"con":true,"img":false}]}
{"op":"mcm","clk":"11449893951","pt":1717315715591,"mc":[{"id":"1.229554896","rc":[{"atb":[[1.01,19.56]],"id":50605162}],"con":true,"img":false}]}
{"op":"mcm","clk":"11449893971","pt":1717315715796,"mc":[{"id":"1.229554896","rc":[{"atb":[[1.01,17.89]],"id":50605162}],"con":true,"img":false}]}
{"op":"mcm","clk":"11449893984","pt":1717315715900,"mc":[{"id":"1.229554896","rc":[{"atb":[[3.35,1.67]],"id":50605162}],"con":true,"img":false}]}
{"op":"mcm","clk":"11449894003","pt":1717315716057,"mc":[{"id":"1.229554896","rc":[{"atb":[[3.35,20.27],[3.25,0]],"id":50605162}],"con":true,"img":false}]}
{"op":"mcm","clk":"11449896887","pt":1717315742884,"mc":[{"id":"1.229554896","rc":[{"atb":[[6.2,6.7],[8.2,3.22]],"id":50605162}],"con":true,"img":false}]}
{"op":"mcm","clk":"11449896911","pt":1717315743088,"mc":[{"id":"1.229554896","rc":[{"atb":[[3.35,1.67],[5.7,20.27]],"id":50605162}],"con":true,"img":false}]}
{"op":"mcm","clk":"11449903490","pt":1717315805958,"mc":[{"id":"1.229554896","rc":[{"atb":[[3.35,0]],"id":50605162},{"spn":20.1,"spf":"NaN","id":50605162}],"con":true,"img":false}]}
{"op":"mcm","clk":"11449917169","pt":1717315936746,"mc":[{"id":"1.229554896","rc":[{"atl":[[1.68,0],[1.66,19.47]],"id":63161712},{"spn":1.35,"spf":"NaN","id":63161712},{"atb":[[3.35,32.14],[3.25,15.48]],"id":58069703},{"atb":[[6,20],[5.7,0]],"id":50605162},{"atl":[[2.8,0],[2.66,13.63]],"id":65732558}],"con":true,"img":false}]}
{"op":"mcm","clk":"11449917181","pt":1717315936807,"mc":[{"id":"1.229554896","rc":[{"atb":[[3.45,28.66],[3.35,3.48]],"id":58069703}],"con":true,"img":false}]}
{"op":"mcm","clk":"11449918143","pt":1717315946107,"mc":[{"id":"1.229554896","rc":[{"atb":[[3.35,1.67]],"id":58069703}],"con":true,"img":false}]}
{"op":"mcm","clk":"11449920707","pt":1717315970180,"mc":[{"id":"1.229554896","rc":[{"atl":[[21,0],[23,0]],"id":58069703},{"atl":[[32,0],[34,0]],"id":50605162},{"atl":[[17.5,2.62]],"id":61028210}],"con":true,"img":false}]}
{"op":"mcm","clk":"11449920718","pt":1717315970281,"mc":[{"id":"1.229554896","rc":[{"atl":[[36,2.61],[38,2.61]],"id":58069703},{"atl":[[100,2.61]],"id":50605162},{"atl":[[20,2.61]],"id":61028210}],"con":true,"img":false}]}
{"op":"mcm","clk":"11449920723","pt":1717315970382,"mc":[{"id":"1.229554896","rc":[{"atl":[[42,0],[350,2]],"id":58069703},{"atl":[[580,2],[180,0]],"id":50605162},{"atl":[[17.5,0],[21,7.61]],"id":61028210}],"con":true,"img":false}]}
{"op":"mcm","clk":"11449922725","pt":1717315988414,"mc":[{"id":"1.229554896","rc":[{"atl":[[40,2.56],[350,0]],"id":58069703},{"atl":[[580,0],[180,2]],"id":50605162}],"con":true,"img":false}]}
{"op":"mcm","clk":"11449922919","pt":1717315990225,"mc":[{"id":"1.229554896","rc":[{"atl":[[3.15,0]],"id":63161712},{"atl":[[32,2.61]],"id":50605162}],"con":true,"img":false}]}
{"op":"mcm","clk":"11449922929","pt":1717315990332,"mc":[{"id":"1.229554896","rc":[{"atl":[[3.5,19.46]],"id":63161712}],"con":true,"img":false}]}
{"op":"mcm","clk":"11449923885","pt":1717316000223,"mc":[{"id":"1.229554896","rc":[{"spn":19.87,"spf":"NaN","id":58069703},{"atl":[[32,0],[95,0.44]],"id":50605162},{"spn":51.6,"spf":"NaN","id":50605162},{"spn":11.47,"spf":"NaN","id":61028210}],"con":true,"img":false}]}
{"op":"mcm","clk":"11449923998","pt":1717316001198,"mc":[{"id":"1.229554896","rc":[{"atb":[[3.35,0]],"id":58069703}],"con":true,"img":false}]}
{"op":"mcm","clk":"11449925750","pt":1717316020133,"mc":[{"id":"1.229554896","rc":[{"atl":[[3.5,0]],"id":63161712},{"atb":[[2.46,0],[3.5,16.74]],"id":58069703},{"atb":[[3.2,0],[6.2,14.74]],"id":50605162},{"atl":[[4.5,0],[3.15,19.46]],"id":65732558}],"con":true,"img":false}]}
{"op":"mcm","clk":"11449925758","pt":1717316020230,"mc":[{"id":"1.229554896","rc":[{"atl":[[2.54,19.46]],"id":63161712}],"con":true,"img":false}]}
{"op":"mcm","clk":"11449927777","pt":1717316040189,"mc":[{"id":"1.229554896","rc":[{"atl":[[2.78,31.66],[3.75,0]],"id":63161712},{"atb":[[3,31.39],[2.16,0]],"id":58069703},{"atb":[[6.2,26.01],[2.78,0]],"id":50605162},{"atl":[[5,0],[3.4,22.72]],"id":65732558},{"atb":[[1.91,0]],"id":61028210}],"con":true,"img":false}]}
{"op":"mcm","clk":"11449927786","pt":1717316040295,"mc":[{"id":"1.229554896","rc":[{"atb":[[2.06,49.23]],"id":61028210}],"con":true,"img":false}]}
{"op":"mcm","clk":"11449929421","pt":1717316056772,"mc":[{"id":"1.229554896","rc":[{"atl":[[1.68,38.94],[1.66,0]],"id":63161712},{"atb":[[3.45,0],[3.25,48.96]],"id":58069703},{"atl":[[40,0],[42,2.44]],"id":58069703},{"atl":[[2.66,0],[2.78,19.47]],"id":65732558}],"con":true,"img":false}]}
{"op":"mcm","clk":"11449929725","pt":1717316060236,"mc":[{"id":"1.229554896","rc":[{"spn":1.36,"spf":"NaN","id":63161712},{"atb":[[3.5,0]],"id":58069703}],"con":true,"img":false}]}
{"op":"mcm","clk":"11449929738","pt":1717316060385,"mc":[{"id":"1.229554896","rc":[{"atb":[[3.3,16.74]],"id":58069703}],"con":true,"img":false}]}
{"op":"mcm","clk":"11449931915","pt":1717316084342,"mc":[{"id":"1.229554896","rc":[{"atb":[[6.2,19.31],[8.2,0]],"id":50605162}],"con":true,"img":false}]}
{"op":"mcm","clk":"11449931932","pt":1717316084548,"mc":[{"id":"1.229554896","rc":[{"atb":[[6,0],[5.7,21.28]],"id":50605162}],"con":true,"img":false}]}
{"op":"mcm","clk":"11449932480","pt":1717316090217,"mc":[{"id":"1.229554896","rc":[{"atb":[[6.2,8.04]],"id":50605162}],"con":true,"img":false}]}
{"op":"mcm","clk":"11449932491","pt":1717316090320,"mc":[{"id":"1.229554896","rc":[{"atb":[[5.6,11.26]],"id":50605162}],"con":true,"img":false}]}
{"op":"mcm","clk":"11449933162","pt":1717316098221,"mc":[{"id":"1.229554896","rc":[{"atb":[[6.4,4.3],[5.2,8.29]],"id":50605162}],"con":true,"img":false}]}
{"op":"mcm","clk":"11449933333","pt":1717316100254,"mc":[{"id":"1.229554896","rc":[{"atb":[[3,0]],"id":58069703}],"con":true,"img":false}]}
{"op":"mcm","clk":"11449933346","pt":1717316100360,"mc":[{"id":"1.229554896","rc":[{"atb":[[3.3,48.13]],"id":58069703}],"con":true,"img":false}]}
{"op":"mcm","clk":"11449933991","pt":1717316107039,"mc":[{"id":"1.229554896","rc":[{"atb":[[1.01,2.35]],"id":58069703}],"con":true,"img":false}]}
{"op":"mcm","clk":"11449934117","pt":1717316108278,"mc":[{"id":"1.229554896","rc":[{"atb":[[1.01,1.63]],"id":58069703}],"con":true,"img":false}]}
{"op":"mcm","clk":"11449934215","pt":1717316109451,"mc":[{"id":"1.229554896","rc":[{"atb":[[1.01,0]],"id":58069703}],"con":true,"img":false}]}
{"op":"mcm","clk":"11449934222","pt":1717316109527,"mc":[{"id":"1.229554896","rc":[{"atb":[[3.4,1.63]],"id":58069703}],"con":true,"img":false}]}
{"op":"mcm","clk":"11449934867","pt":1717316116788,"mc":[{"id":"1.229554896","rc":[{"atb":[[1.01,11614.52],[1.02,8.94]],"id":63161712},{"atl":[[1.68,0],[1.66,19.47]],"id":63161712},{"atb":[[3.45,40.82],[3.25,15.48]],"id":58069703},{"atl":[[40,2.56],[42,0]],"id":58069703},{"atb":[[6,12.35],[5.7,0]],"id":50605162},{"atl":[[2.66,19.47],[2.78,0]],"id":65732558}],"con":true,"img":false}]}
{"op":"mcm","clk":"11449935161","pt":1717316120157,"mc":[{"id":"1.229554896","rc":[{"atb":[[3.3,16.74]],"id":58069703}],"con":true,"img":false}]}
{"op":"mcm","clk":"11449935170","pt":1717316120254,"mc":[{"id":"1.229554896","rc":[{"spn":1.35,"spf":"NaN","id":63161712},{"atb":[[3,31.39]],"id":58069703},{"spn":50.7,"spf":"NaN","id":50605162}],"con":true,"img":false}]}
{"op":"mcm","clk":"11449936404","pt":1717316133309,"mc":[{"id":"1.229554896","rc":[{"atb":[[1.02,5008.94]],"id":63161712}],"con":true,"img":false}]}
{"op":"mcm","clk":"11449936411","pt":1717316133363,"mc":[{"id":"1.229554896","rc":[{"atb":[[1.01,5807.26]],"id":63161712}],"con":true,"img":false}]}
{"op":"mcm","clk":"11449937953","pt":1717316150210,"mc":[{"id":"1.229554896","rc":[{"atb":[[3.3,0]],"id":58069703}],"con":true,"img":false}]}
{"op":"mcm","clk":"11449937965","pt":1717316150316,"mc":[{"id":"1.229554896","rc":[{"atb":[[3.5,16.74]],"id":58069703}],"con":true,"img":false}]}
{"op":"mcm","clk":"11449942168","pt":1717316194481,"mc":[{"id":"1.229554896","rc":[{"atb":[[3.4,0]],"id":58069703}],"con":true,"img":false}]}
{"op":"mcm","clk":"11449945975","pt":1717316236818,"mc":[{"id":"1.229554896","rc":[{"atb":[[1.01,11614.52],[1.02,8.94]],"id":63161712},{"atl":[[1.68,38.94],[1.66,0]],"id":63161712},{"atb":[[3.45,0],[3.25,48.96]],"id":58069703},{"atl":[[40,0],[42,2.44]],"id":58069703},{"atb":[[6,0],[5.7,16.1]],"id":50605162},{"atl":[[2.66,0],[2.78,19.8]],"id":65732558}],"con":true,"img":false}]}
{"op":"mcm","clk":"11449946348","pt":1717316240266,"mc":[{"id":"1.229554896","rc":[{"atb":[[3.5,0]],"id":58069703}],"con":true,"img":false}]}
{"op":"mcm","clk":"11449946354","pt":1717316240318,"mc":[{"id":"1.229554896","rc":[{"atb":[[3.3,16.74]],"id":58069703}],"con":true,"img":false}]}
{"op":"mcm","clk":"11449946527","pt":1717316242254,"mc":[{"id":"1.229554896","rc":[{"atb":[[3.35,1.81]],"id":58069703}],"con":true,"img":false}]}
{"op":"mcm","clk":"11449946555","pt":1717316242516,"mc":[{"id":"1.229554896","rc":[{"atb":[[1.01,2.35]],"id":58069703}],"con":true,"img":false}]}
{"op":"mcm","clk":"11449946590","pt":1717316242823,"mc":[{"id":"1.229554896","rc":[{"atb":[[1.01,1.63]],"id":58069703}],"con":true,"img":false}]}
{"op":"mcm","clk":"11449946619","pt":1717316243133,"mc":[{"id":"1.229554896","rc":[{"atb":[[1.01,0]],"id":58069703}],"con":true,"img":false}]}
{"op":"mcm","clk":"11449946625","pt":1717316243236,"mc":[{"id":"1.229554896","rc":[{"atb":[[3.4,1.63]],"id":58069703}],"con":true,"img":false}]}
{"op":"mcm","clk":"11449949753","pt":1717316280307,"mc":[{"id":"1.229554896","rc":[{"spn":1.36,"spf":"NaN","id":63161712},{"atb":[[3,0]],"id":58069703}],"con":true,"img":false}]}
{"op":"mcm","clk":"11449949761","pt":1717316280410,"mc":[{"id":"1.229554896","rc":[{"atb":[[3.3,48.13]],"id":58069703}],"con":true,"img":false}]}
{"op":"mcm","clk":"11449952403","pt":1717316311128,"mc":[{"id":"1.229554896","rc":[{"atb":[[1.01,5807.26],[1.05,206.17]],"id":63161712},{"atl":[[1.68,0],[1.9,77.88]],"id":63161712},{"atb":[[1.97,103.09],[3.25,15.48]],"id":58069703},{"atl":[[36,5.23],[42,0]],"id":58069703},{"atb":[[3.25,44.44],[5.7,0]],"id":50605162},{"atl":[[180,0],[100,4.61]],"id":50605162},{"atb":[[1.11,98.4]],"id":65732558},{"atl":[[3.1,20.13],[2.78,0]],"id":65732558},{"atb":[[2.32,0],[1.62,52.41]],"id":61028210}],"con":true,"img":false}]}
{"op":"mcm","clk":"11449952414","pt":1717316311249,"mc":[{"id":"1.229554896","rc":[{"atb":[[1.11,1007.49]],"id":65732558}],"con":true,"img":false}]}
{"op":"mcm","clk":"11449953174","pt":1717316320168,"mc":[{"id":"1.229554896","rc":[{"atb":[[3.3,16.74]],"id":58069703}],"con":true,"img":false}]}
{"op":"mcm","clk":"11449953185","pt":1717316320261,"mc":[{"id":"1.229554896","rc":[{"atb":[[3,31.39]],"id":58069703}],"con":true,"img":false}]}
{"op":"mcm","clk":"11449953682","pt":1717316325762,"mc":[{"id":"1.229554896","rc":[{"atl":[[36,2.61],[21,2.62]],"id":58069703},{"atb":[[2.56,32.01],[1.62,0]],"id":61028210}],"con":true,"img":false}]}
{"op":"mcm","clk":"11449953751","pt":1717316326779,"mc":[{"id":"1.229554896","rc":[{"atb":[[3.35,1.81]],"id":50605162}],"con":true,"img":false}]}
{"op":"mcm","clk":"11449953761","pt":1717316326940,"mc":[{"id":"1.229554896","rc":[{"atb":[[3.35,0]],"id":58069703},{"atb":[[2.38,0]],"id":61028210}],"con":true,"img":false}]}
{"op":"mcm","clk":"11449954051","pt":1717316330194,"mc":[{"id":"1.229554896","rc":[{"atl":[[2.54,0],[3.85,19.78],[2.78,0]],"id":63161712},{"atb":[[2.36,30.77],[3,0],[2.18,53.88],[3.3,0]],"id":58069703},{"atb":[[5.6,0],[6.2,0],[3.3,18.19],[2.78,32.91]],"id":50605162},{"atl":[[4.5,11.95],[3.4,0],[4.9,13.98],[3.15,0]],"id":65732558},{"atb":[[2.06,0],[2.34,0]],"id":61028210}],"con":true,"img":false}]}
{"op":"mcm","clk":"11449954057","pt":1717316330297,"mc":[{"id":"1.229554896","rc":[{"atl":[[3.2,19.46]],"id":63161712},{"atl":[[4.4,20.46]],"id":65732558},{"atb":[[1.92,49.23],[2.06,33.75]],"id":61028210}],"con":true,"img":false}]}
{"op":"mcm","clk":"11449954064","pt":1717316330391,"mc":[{"id":"1.229554896","rc":[{"atl":[[3.1,0]],"id":65732558}],"con":true,"img":false}]}
{"op":"mcm","clk":"11449954466","pt":1717316336066,"mc":[{"id":"1.229554896","rc":[{"atb":[[2.4,0]],"id":61028210}],"con":true,"img":false}]}
{"op":"mcm","clk":"11449954472","pt":1717316336166,"mc":[{"id":"1.229554896","rc":[{"atb":[[1.01,20.25]],"id":50605162}],"con":true,"img":false}]}
{"op":"mcm","clk":"11449954490","pt":1717316336371,"mc":[{"id":"1.229554896","rc":[{"atb":[[2.62,2.42]],"id":61028210}],"con":true,"img":false}]}
{"op":"mcm","clk":"11449954500","pt":1717316336473,"mc":[{"id":"1.229554896","rc":[{"atb":[[1.01,19.52]],"id":50605162}],"con":true,"img":false}]}
{"op":"mcm","clk":"11449954583","pt":1717316337398,"mc":[{"id":"1.229554896","rc":[{"atb":[[1.01,17.89]],"id":50605162}],"con":true,"img":false}]}
{"op":"mcm","clk":"11449954592","pt":1717316337501,"mc":[{"id":"1.229554896","rc":[{"atb":[[3.4,1.63]],"id":50605162}],"con":true,"img":false}]}
{"op":"mcm","clk":"11449954808","pt":1717316340182,"mc":[{"id":"1.229554896","rc":[{"atb":[[1.05,103.09]],"id":63161712},{"atl":[[20,0]],"id":61028210}],"con":true,"img":false}]}
{"op":"mcm","clk":"11449954817","pt":1717316340286,"mc":[{"id":"1.229554896","rc":[{"atb":[[1.06,103.08]],"id":63161712},{"atl":[[17,2.61]],"id":61028210}],"con":true,"img":false}]}
{"op":"mcm","clk":"11449954823","pt":1717316340388,"mc":[{"id":"1.229554896","rc":[{"spn":1.48,"spf":"NaN","id":63161712},{"spn":12.37,"spf":"NaN","id":58069703},{"atl":[[17,5.23],[21,2.61]],"id":61028210},{"spn":9.97,"spf":"NaN","id":61028210}],"con":true,"img":false}]}
{"op":"mcm","clk":"11449954840","pt":1717316340493,"mc":[{"id":"1.229554896","rc":[{"atl":[[17,2.61],[21,7.61]],"id":61028210}],"con":true,"img":false}]}
{"op":"mcm","clk":"11449955586","pt":1717316350215,"mc":[{"id":"1.229554896","rc":[{"atl":[[36,0]],"id":58069703},{"atl":[[32,2.61],[95,0]],"id":50605162}],"con":true,"img":false}]}
{"op":"mcm","clk":"11449955595","pt":1717316350269,"mc":[{"id":"1.229554896","rc":[{"atl":[[22,2.61]],"id":58069703}],"con":true,"img":false}]}
{"op":"mcm","clk":"11449955601","pt":1717316350373,"mc":[{"id":"1.229554896","rc":[{"atl":[[32,5.23],[100,2.61]],"id":50605162}],"con":true,"img":false}]}
{"op":"mcm","clk":"11449955606","pt":1717316350476,"mc":[{"id":"1.229554896","rc":[{"atl":[[32,2.61],[100,4.61]],"id":50605162}],"con":true,"img":false}]}
{"op":"mcm","clk":"11449956292","pt":1717316360116,"mc":[{"id":"1.229554896","rc":[{"atl":[[38,0]],"id":58069703},{"atl":[[21,5]],"id":61028210}],"con":true,"img":false}]}
{"op":"mcm","clk":"11449956298","pt":1717316360224,"mc":[{"id":"1.229554896","rc":[{"atl":[[23,2.61]],"id":58069703},{"atl":[[17,5.23],[19,2.61],[21,0]],"id":61028210}],"con":true,"img":false}]}
{"op":"mcm","clk":"11449956305","pt":1717316360320,"mc":[{"id":"1.229554896","rc":[{"atl":[[85,2]],"id":61028210}],"con":true,"img":false}]}
{"op":"mcm","clk":"11449956312","pt":1717316360430,"mc":[{"id":"1.229554896","rc":[{"atl":[[17,2.61]],"id":61028210}],"con":true,"img":false}]}
{"op":"mcm","clk":"11449956322","pt":1717316360530,"mc":[{"id":"1.229554896","rc":[{"atl":[[17,5.23],[85,0]],"id":61028210}],"con":true,"img":false}]}
{"op":"mcm","clk":"11449956329","pt":1717316360633,"mc":[{"id":"1.229554896","rc":[{"atl":[[17,2.61],[19,7.85]],"id":61028210}],"con":true,"img":false}]}
{"op":"mcm","clk":"11449956338","pt":1717316360734,"mc":[{"id":"1.229554896","rc":[{"atl":[[17,5.23],[19,2.61]],"id":61028210}],"con":true,"img":false}]}
{"op":"mcm","clk":"11449956345","pt":1717316360849,"mc":[{"id":"1.229554896","rc":[{"atl":[[17,2.61],[19,7.85]],"id":61028210}],"con":true,"img":false}]}
{"op":"mcm","clk":"11449956670","pt":1717316364754,"mc":[{"id":"1.229554896","rc":[{"atb":[[2.62,5.05]],"id":61028210}],"con":true,"img":false}]}
{"op":"mcm","clk":"11449957098","pt":1717316370269,"mc":[{"id":"1.229554896","rc":[{"atl":[[100,2]],"id":50605162}],"con":true,"img":false}]}
{"op":"mcm","clk":"11449957106","pt":1717316370371,"mc":[{"id":"1.229554896","rc":[{"atl":[[32,4.61],[34,2.61],[100,0]],"id":50605162}],"con":true,"img":false}]}
{"op":"mcm","clk":"11449957297","pt":1717316372848,"mc":[{"id":"1.229554896","rc":[{"atl":[[1.89,19.47]],"id":63161712}],"con":true,"img":false}]}
{"op":"mcm","clk":"11449957305","pt":1717316372950,"mc":[{"id":"1.229554896","rc":[{"atl":[[1.9,0]],"id":63161712}],"con":true,"img":false}]}
{"op":"mcm","clk":"11449957473","pt":1717316374959,"mc":[{"id":"1.229554896","rc":[{"atl":[[17,5.23],[19,2.61]],"id":61028210}],"con":true,"img":false}]}
{"op":"mcm","clk":"11449957833","pt":1717316380160,"mc":[{"id":"1.229554896","rc":[{"atl":[[22,0],[23,0]],"id":58069703},{"atl":[[32,2],[34,0],[90,0.47]],"id":50605162},{"atl":[[3.4,22.72],[4.9,0]],"id":65732558},{"atl":[[17,2.62],[19,0]],"id":61028210}],"con":true,"img":false}]}
{"op":"mcm","clk":"11449957837","pt":1717316380266,"mc":[{"id":"1.229554896","rc":[{"atl":[[36,2.61],[38,2.61]],"id":58069703},{"atl":[[32,0],[310,2],[95,2.61]],"id":50605162},{"atl":[[3.35,20.46],[4.4,0]],"id":65732558},{"atl":[[17,0],[19.5,2.61],[21,2.61],[85,2]],"id":61028210}],"con":true,"img":false}]}
{"op":"mcm","clk":"11449958560","pt":1717316390190,"mc":[{"id":"1.229554896","rc":[{"atl":[[4.5,0],[3.1,19.93]],"id":65732558},{"atb":[[2.06,0]],"id":61028210}],"con":true,"img":false}]}
{"op":"mcm","clk":"11449958566","pt":1717316390293,"mc":[{"id":"1.229554896","rc":[{"atb":[[2.58,33.75]],"id":61028210}],"con":true,"img":false}]}
{"op":"mcm","clk":"11449958869","pt":1717316394178,"mc":[{"id":"1.229554896","rc":[{"atl":[[310,0],[95,4.61]],"id":50605162},{"atl":[[3.1,40.39],[3.35,0]],"id":65732558},{"atl":[[19.5,5.23],[85,0]],"id":61028210}],"con":true,"img":false}]}
{"op":"mcm","clk":"11449958991","pt":1717316395780,"mc":[{"id":"1.229554896","rc":[{"atb":[[3.4,0]],"id":58069703},{"atb":[[2.62,2.63]],"id":61028210}],"con":true,"img":false}]}
{"op":"mcm","clk":"11449959008","pt":1717316395986,"mc":[{"id":"1.229554896","rc":[{"atb":[[2.64,2.39]],"id":61028210}],"con":true,"img":false}]}
{"op":"mcm","clk":"11449959365","pt":1717316400206,"mc":[{"id":"1.229554896","rc":[{"atl":[[3.2,0],[2.52,27.53]],"id":63161712},{"atb":[[2.36,0],[3.3,18.19]],"id":58069703},{"atb":[[6.2,8.04],[3.3,0]],"id":50605162}],"con":true,"img":false}]}
{"op":"mcm","clk":"11449959648","pt":1717316403496,"mc":[{"id":"1.229554896","rc":[{"spn":1.47,"spf":"NaN","id":63161712},{"spn":48.2,"spf":"NaN","id":50605162},{"atb":[[2.62,0]],"id":61028210},{"spn":11.22,"spf":"NaN","id":61028210}],"con":true,"img":false}]}
{"op":"mcm","clk":"11449960291","pt":1717316411305,"mc":[{"id":"1.229554896","rc":[{"atb":[[1.01,2.35]],"id":58069703}],"con":true,"img":false}]}
{"op":"mcm","clk":"11449960333","pt":1717316411792,"mc":[{"id":"1.229554896","rc":[{"atb":[[1.01,1.63]],"id":58069703}],"con":true,"img":false}]}
{"op":"mcm","clk":"11449960361","pt":1717316412105,"mc":[{"id":"1.229554896","rc":[{"atb":[[1.01,0]],"id":58069703}],"con":true,"img":false}]}
{"op":"mcm","clk":"11449960370","pt":1717316412206,"mc":[{"id":"1.229554896","rc":[{"atb":[[3.4,1.63]],"id":58069703}],"con":true,"img":false}]}
{"op":"mcm","clk":"11449960810","pt":1717316417429,"mc":[{"id":"1.229554896","rc":[{"atl":[[1.89,0],[1.88,19.47]],"id":63161712},{"atl":[[21,0],[22,4.76]],"id":58069703}],"con":true,"img":false}]}
{"op":"mcm","clk":"11449961027","pt":1717316420119,"mc":[{"id":"1.229554896","rc":[{"atl":[[3.85,0],[2.76,32.02]],"id":63161712},{"atb":[[3,31.39],[2.18,0]],"id":58069703},{"atb":[[5.6,12.73],[2.78,0]],"id":50605162},{"atb":[[1.92,0]],"id":61028210}],"con":true,"img":false}]}
{"op":"mcm","clk":"11449961031","pt":1717316420223,"mc":[{"id":"1.229554896","rc":[{"atb":[[2.06,49.23]],"id":61028210}],"con":true,"img":false}]}
{"op":"mcm","clk":"11449962067","pt":1717316432563,"mc":[{"id":"1.229554896","rc":[{"atl":[[1.88,0],[1.86,19.47]],"id":63161712},{"atl":[[22,0],[23,4.55]],"id":58069703}],"con":true,"img":false}]}
{"op":"mcm","clk":"11449962072","pt":1717316432666,"mc":[{"id":"1.229554896","rc":[{"atl":[[1.84,19.47],[1.86,0]],"id":63161712}],"con":true,"img":false}]}
{"op":"mcm","clk":"11449962648","pt":1717316439862,"mc":[{"id":"1.229554896","rc":[{"atb":[[3.1,2.02]],"id":58069703}],"con":true,"img":false}]}
{"op":"mcm","clk":"11449962665","pt":1717316440170,"mc":[{"id":"1.229554896","rc":[{"atb":[[2.64,4.99]],"id":61028210}],"con":true,"img":false}]}
{"op":"mcm","clk":"11449963621","pt":1717316452777,"mc":[{"id":"1.229554896","rc":[{"atb":[[1.05,0],[1.04,2818.61]],"id":63161712},{"atl":[[23,0],[24,4.35]],"id":58069703}],"con":true,"img":false}]}
{"op":"mcm","clk":"11449964714","pt":1717316467981,"mc":[{"id":"1.229554896","rc":[{"atl":[[1.83,19.47],[1.84,0]],"id":63161712},{"spn":1.44,"spf":"NaN","id":63161712},{"spn":13.87,"spf":"NaN","id":58069703},{"atb":[[2.56,0],[2.64,37]],"id":61028210}],"con":true,"img":false}]}
{"op":"mcm","clk":"11449965030","pt":1717316472070,"mc":[{"id":"1.229554896","rc":[{"atb":[[2.64,34.6]],"id":61028210}],"con":true,"img":false}]}
{"op":"mcm","clk":"11449965053","pt":1717316472376,"mc":[{"id":"1.229554896","rc":[{"atb":[[2.64,32.01]],"id":61028210}],"con":true,"img":false}]}
{"op":"mcm","clk":"11449965064","pt":1717316472479,"mc":[{"id":"1.229554896","rc":[{"atb":[[1.01,2.35]],"id":61028210}],"con":true,"img":false}]}
{"op":"mcm","clk":"11449965112","pt":1717316473099,"mc":[{"id":"1.229554896","rc":[{"atb":[[1.01,2.3]],"id":61028210}],"con":true,"img":false}]}
{"op":"mcm","clk":"11449965159","pt":1717316473563,"mc":[{"id":"1.229554896","rc":[{"atb":[[1.01,0]],"id":61028210}],"con":true,"img":false}]}
{"op":"mcm","clk":"11449965170","pt":1717316473719,"mc":[{"id":"1.229554896","rc":[{"atb":[[2.7,2.3]],"id":61028210}],"con":true,"img":false}]}
{"op":"mcm","clk":"11449965627","pt":1717316480188,"mc":[{"id":"1.229554896","rc":[{"atb":[[3.4,0]],"id":50605162},{"atl":[[3.4,0]],"id":65732558}],"con":true,"img":false}]}
{"op":"mcm","clk":"11449965636","pt":1717316480294,"mc":[{"id":"1.229554896","rc":[{"atl":[[3.05,22.72]],"id":65732558}],"con":true,"img":false}]}
{"op":"mcm","clk":"11449966321","pt":1717316490091,"mc":[{"id":"1.229554896","rc":[{"atb":[[2.58,0]],"id":61028210}],"con":true,"img":false}]}
{"op":"mcm","clk":"11449966325","pt":1717316490197,"mc":[{"id":"1.229554896","rc":[{"atb":[[2.66,33.75]],"id":61028210}],"con":true,"img":false}]}
{"op":"mcm","clk":"11449966455","pt":1717316492028,"mc":[{"id":"1.229554896","rc":[{"atb":[[6.4,0],[5.2,0]],"id":50605162}],"con":true,"img":false}]}
{"op":"mcm","clk":"11449967145","pt":1717316501725,"mc":[{"id":"1.229554896","rc":[{"atb":[[2.7,0]],"id":61028210}],"con":true,"img":false}]}
{"op":"mcm","clk":"11449967157","pt":1717316501931,"mc":[{"id":"1.229554896","rc":[{"atb":[[1.01,2.35]],"id":61028210}],"con":true,"img":false}]}
{"op":"mcm","clk":"11449967190","pt":1717316502399,"mc":[{"id":"1.229554896","rc":[{"atb":[[1.01,2.28]],"id":61028210}],"con":true,"img":false}]}
{"op":"mcm","clk":"11449967230","pt":1717316502812,"mc":[{"id":"1.229554896","rc":[{"atb":[[1.01,0]],"id":61028210}],"con":true,"img":false}]}
{"op":"mcm","clk":"11449967238","pt":1717316502918,"mc":[{"id":"1.229554896","rc":[{"atb":[[2.72,2.28]],"id":61028210}],"con":true,"img":false}]}
{"op":"mcm","clk":"11449967698","pt":1717316509724,"mc":[{"id":"1.229554896","rc":[{"atb":[[3.35,0]],"id":50605162},{"atb":[[2.72,4.76]],"id":61028210}],"con":true,"img":false}]}
{"op":"mcm","clk":"11449967759","pt":1717316510810,"mc":[{"id":"1.229554896","rc":[{"atb":[[6.8,4],[5.4,7.92]],"id":50605162}],"con":true,"img":false}]}
{"op":"mcm","clk":"11449967805","pt":1717316511433,"mc":[{"id":"1.229554896","rc":[{"atb":[[1.03,2921.71]],"id":63161712},{"atl":[[1.76,19.47]],"id":63161712},{"atb":[[1.97,0]],"id":58069703},{"atl":[[24,0]],"id":58069703},{"atb":[[2.22,49.23],[2.64,0]],"id":61028210}],"con":true,"img":false}]}
{"op":"mcm","clk":"11449967809","pt":1717316511537,"mc":[{"id":"1.229554896","rc":[{"atb":[[1.04,1409.3]],"id":63161712},{"atl":[[1.73,19.47],[1.83,0],[1.76,0]],"id":63161712},{"atl":[[44,2.33]],"id":58069703},{"atb":[[3.25,0]],"id":50605162},{"atl":[[140,2],[95,2.61]],"id":50605162},{"atb":[[2.36,49.23],[2.22,0]],"id":61028210}],"con":true,"img":false}]}
{"op":"mcm","clk":"11449967821","pt":1717316511747,"mc":[{"id":"1.229554896","rc":[{"atl":[[40,2.56],[44,0]],"id":58069703}],"con":true,"img":false}]}
{"op":"mcm","clk":"11449968340","pt":1717316520220,"mc":[{"id":"1.229554896","rc":[{"atb":[[1.06,0]],"id":63161712},{"atb":[[2.66,0]],"id":61028210}],"con":true,"img":false}]}
{"op":"mcm","clk":"11449968349","pt":1717316520322,"mc":[{"id":"1.229554896","rc":[{"atb":[[1.05,103.08]],"id":63161712},{"atb":[[2.38,33.75]],"id":61028210}],"con":true,"img":false}]}
{"op":"mcm","clk":"11449969081","pt":1717316531364,"mc":[{"id":"1.229554896","rc":[{"atl":[[2.6,6.66]],"id":63161712},{"spn":1.39,"spf":"NaN","id":63161712},{"atb":[[3.2,4.68]],"id":58069703},{"spn":19.87,"spf":"NaN","id":58069703},{"spn":48.4,"spf":"NaN","id":50605162},{"atb":[[1.09,648.11]],"id":65732558},{"atl":[[3.25,4.78]],"id":65732558}],"con":true,"img":false}]}
{"op":"mcm","clk":"11449969156","pt":1717316532344,"mc":[{"id":"1.229554896","rc":[{"atb":[[1.03,3009.71]],"id":63161712}],"con":true,"img":false}]}
{"op":"mcm","clk":"11449969428","pt":1717316536180,"mc":[{"id":"1.229554896","rc":[{"atl":[[2.6,0]],"id":63161712}],"con":true,"img":false}]}
{"op":"mcm","clk":"11449969651","pt":1717316540143,"mc":[{"id":"1.229554896","rc":[{"atl":[[3.1,20.46]],"id":65732558}],"con":true,"img":false}]}
{"op":"mcm","clk":"11449969660","pt":1717316540248,"mc":[{"id":"1.229554896","rc":[{"atl":[[3.05,42.65]],"id":65732558}],"con":true,"img":false}]}
{"op":"mcm","clk":"11449970341","pt":1717316550177,"mc":[{"id":"1.229554896","rc":[{"atl":[[21,0]],"id":61028210}],"con":true,"img":false}]}
{"op":"mcm","clk":"11449970346","pt":1717316550275,"mc":[{"id":"1.229554896","rc":[{"atl":[[19,2.61]],"id":61028210}],"con":true,"img":false}]}
{"op":"mcm","clk":"11449970473","pt":1717316552247,"mc":[{"id":"1.229554896","rc":[{"atb":[[2.72,2.28]],"id":61028210}],"con":true,"img":false}]}
{"op":"mcm","clk":"11449970642","pt":1717316554594,"mc":[{"id":"1.229554896","rc":[{"atb":[[2.2,8.7]],"id":61028210}],"con":true,"img":false}]}
{"op":"mcm","clk":"11449971113","pt":1717316562280,"mc":[{"id":"1.229554896","rc":[{"atl":[[95,0]],"id":50605162},{"atl":[[3.05,19.93]],"id":65732558},{"atl":[[19,0]],"id":61028210}],"con":true,"img":false}]}
{"op":"mcm","clk":"11449971117","pt":1717316562380,"mc":[{"id":"1.229554896","rc":[{"atl":[[130,2.61],[530,2],[140,0]],"id":50605162},{"atl":[[3.5,22.72]],"id":65732558},{"atl":[[23,2.61]],"id":61028210}],"con":true,"img":false}]}
{"op":"mcm","clk":"11449971195","pt":1717316563369,"mc":[{"id":"1.229554896","rc":[{"atb":[[1.03,88],[1.02,2917.04]],"id":63161712},{"atl":[[1.73,0],[1.71,19.47]],"id":63161712},{"atl":[[40,0],[55,2]],"id":58069703},{"atb":[[1.11,98.4],[1.09,1759.22]],"id":65732558},{"atl":[[2.9,19.93],[3.1,0]],"id":65732558},{"atb":[[2.36,0],[2.68,33.76]],"id":61028210}],"con":true,"img":false}]}
{"op":"mcm","clk":"11449971201","pt":1717316563474,"mc":[{"id":"1.229554896","rc":[{"atb":[[1.03,0]],"id":63161712},{"atb":[[1.09,1717.12]],"id":65732558}],"con":true,"img":false}]}
{"op":"mcm","clk":"11449971463","pt":1717316567867,"mc":[{"id":"1.229554896","rc":[{"atl":[[130,2.94]],"id":50605162}],"con":true,"img":false}]}
{"op":"mcm","clk":"11449971469","pt":1717316567968,"mc":[{"id":"1.229554896","rc":[{"atl":[[90,0]],"id":50605162}],"con":true,"img":false}]}
{"op":"mcm","clk":"11449971901","pt":1717316574480,"mc":[{"id":"1.229554896","rc":[{"atl":[[180,2]],"id":50605162}],"con":true,"img":false}]}
{"op":"mcm","clk":"11449971911","pt":1717316574588,"mc":[{"id":"1.229554896","rc":[{"atl":[[530,0]],"id":50605162}],"con":true,"img":false}]}
{"op":"mcm","clk":"11449971983","pt":1717316575513,"mc":[{"id":"1.229554896","rc":[{"atl":[[1.68,19.47],[1.71,0]],"id":63161712},{"atb":[[1.09,606.01],[1.1,1000]],"id":65732558},{"atl":[[2.84,19.93]],"id":65732558}],"con":true,"img":false}]}
{"op":"mcm","clk":"11449971992","pt":1717316575614,"mc":[{"id":"1.229554896","rc":[{"atl":[[2.9,0]],"id":65732558}],"con":true,"img":false}]}
{"op":"mcm","clk":"11449972105","pt":1717316577113,"mc":[{"id":"1.229554896","rc":[{"atb":[[2.72,0]],"id":61028210}],"con":true,"img":false}]}
{"op":"mcm","clk":"11449972119","pt":1717316577320,"mc":[{"id":"1.229554896","rc":[{"atb":[[1.01,2.35]],"id":61028210}],"con":true,"img":false}]}
{"op":"mcm","clk":"11449972132","pt":1717316577524,"mc":[{"id":"1.229554896","rc":[{"atb":[[1.01,2.26]],"id":61028210}],"con":true,"img":false}]}
{"op":"mcm","clk":"11449972167","pt":1717316578097,"mc":[{"id":"1.229554896","rc":[{"atb":[[1.01,0]],"id":61028210}],"con":true,"img":false}]}
{"op":"mcm","clk":"11449972173","pt":1717316578198,"mc":[{"id":"1.229554896","rc":[{"atb":[[2.74,22.28]],"id":61028210}],"con":true,"img":false}]}
{"op":"mcm","clk":"11449972729","pt":1717316586391,"mc":[{"id":"1.229554896","rc":[{"atb":[[2.74,24.73]],"id":61028210}],"con":true,"img":false}]}
{"op":"mcm","clk":"11449972834","pt":1717316587838,"mc":[{"id":"1.229554896","rc":[{"atb":[[1.09,648.11]],"id":65732558}],"con":true,"img":false}]}
{"op":"mcm","clk":"11449972881","pt":1717316588410,"mc":[{"id":"1.229554896","rc":[{"atb":[[1.12,648.11]],"id":65732558},{"atl":[[2.84,0]],"id":65732558},{"atb":[[2.44,49.46]],"id":61028210}],"con":true,"img":false}]}
{"op":"mcm","clk":"11449972888","pt":1717316588512,"mc":[{"id":"1.229554896","rc":[{"atb":[[1.03,3333.33],[1.02,8.94]],"id":63161712},{"atl":[[1.68,0],[1.69,38.94]],"id":63161712},{"atl":[[40,2.56],[55,0]],"id":58069703},{"atl":[[150,2],[180,0]],"id":50605162},{"atb":[[1.1,0]],"id":65732558},{"atl":[[2.96,20.26]],"id":65732558},{"atb":[[2.68,0]],"id":61028210}],"con":true,"img":false}]}
{"op":"mcm","clk":"11449972921","pt":1717316588827,"mc":[{"id":"1.229554896","rc":[{"atl":[[2.6,6.66]],"id":63161712}],"con":true,"img":false}]}
{"op":"mcm","clk":"11449972986","pt":1717316589700,"mc":[{"id":"1.229554896","rc":[{"atb":[[1.03,3421.33]],"id":63161712}],"con":true,"img":false}]}
{"op":"mcm","clk":"11449973089","pt":1717316591146,"mc":[{"id":"1.229554896","rc":[{"atb":[[1.03,3419.08]],"id":63161712}],"con":true,"img":false}]}
{"op":"mcm","clk":"11449973105","pt":1717316591309,"mc":[{"id":"1.229554896","rc":[{"atb":[[2.2,0]],"id":61028210}],"con":true,"img":false}]}
{"op":"mcm","clk":"11449973142","pt":1717316591721,"mc":[{"id":"1.229554896","rc":[{"spn":1.37,"spf":"NaN","id":63161712},{"spn":68.4,"spf":"NaN","id":50605162},{"spn":1.84,"spf":"NaN","id":65732558},{"atb":[[2.74,22.47]],"id":61028210}],"con":true,"img":false}]}
{"op":"mcm","clk":"11449973170","pt":1717316592133,"mc":[{"id":"1.229554896","rc":[{"atb":[[1.01,2.35]],"id":61028210}],"con":true,"img":false}]}
{"op":"mcm","clk":"11449973193","pt":1717316592544,"mc":[{"id":"1.229554896","rc":[{"atb":[[1.01,2.18]],"id":61028210}],"con":true,"img":false}]}
{"op":"mcm","clk":"11449973208","pt":1717316592757,"mc":[{"id":"1.229554896","rc":[{"atb":[[1.01,0]],"id":61028210}],"con":true,"img":false}]}
{"op":"mcm","clk":"11449973218","pt":1717316592809,"mc":[{"id":"1.229554896","rc":[{"atb":[[2.8,2.18]],"id":61028210}],"con":true,"img":false}]}
{"op":"mcm","clk":"11449973271","pt":1717316593539,"mc":[{"id":"1.229554896","rc":[{"atl":[[3.25,0]],"id":65732558}],"con":true,"img":false}]}
{"op":"mcm","clk":"11449973283","pt":1717316593640,"mc":[{"id":"1.229554896","rc":[{"atl":[[1.7,77.88]],"id":63161712},{"atl":[[3.25,4.78]],"id":65732558}],"con":true,"img":false}]}
{"op":"mcm","clk":"11449973288","pt":1717316593743,"mc":[{"id":"1.229554896","rc":[{"atl":[[1.69,0]],"id":63161712}],"con":true,"img":false}]}
{"op":"mcm","clk":"11449973737","pt":1717316600125,"mc":[{"id":"1.229554896","rc":[{"atb":[[2.76,23.77]],"id":61028210}],"con":true,"img":false}]}
{"op":"mcm","clk":"11449973743","pt":1717316600227,"mc":[{"id":"1.229554896","rc":[{"atb":[[2.38,0]],"id":61028210}],"con":true,"img":false}]}
{"op":"mcm","clk":"11449974166","pt":1717316606325,"mc":[{"id":"1.229554896","rc":[{"atb":[[2.8,0]],"id":61028210}],"con":true,"img":false}]}
{"op":"mcm","clk":"11449974185","pt":1717316606530,"mc":[{"id":"1.229554896","rc":[{"atb":[[1.01,2.35]],"id":61028210}],"con":true,"img":false}]}
{"op":"mcm","clk":"11449974205","pt":1717316606739,"mc":[{"id":"1.229554896","rc":[{"atb":[[1.01,2.13]],"id":61028210}],"con":true,"img":false}]}
{"op":"mcm","clk":"11449974222","pt":1717316606950,"mc":[{"id":"1.229554896","rc":[{"atb":[[1.09,644.73]],"id":65732558},{"atb":[[1.01,0]],"id":61028210}],"con":true,"img":false}]}
{"op":"mcm","clk":"11449974228","pt":1717316607052,"mc":[{"id":"1.229554896","rc":[{"atb":[[2.84,2.13]],"id":61028210}],"con":true,"img":false}]}
{"op":"mcm","clk":"11449974450","pt":1717316610156,"mc":[{"id":"1.229554896","rc":[{"atl":[[3.2,19.02],[3.8,20.13]],"id":63161712},{"atb":[[2.32,31.7],[2.14,55.45]],"id":58069703},{"atb":[[2.74,33.67],[3,20.92]],"id":50605162},{"atl":[[5.2,12.98],[4.7,11.31]],"id":65732558}],"con":true,"img":false}]}
{"op":"mcm","clk":"11449974455","pt":1717316610260,"mc":[{"id":"1.229554896","rc":[{"atl":[[2.52,0],[2.76,0]],"id":63161712},{"atb":[[3,0],[3.3,0]],"id":58069703},{"atb":[[5.6,0],[6.2,0]],"id":50605162},{"atl":[[3.5,0],[3.05,0]],"id":65732558},{"atb":[[2.06,0],[2.76,0]],"id":61028210}],"con":true,"img":false}]}
{"op":"mcm","clk":"11449974461","pt":1717316610364,"mc":[{"id":"1.229554896","rc":[{"atl":[[2.6,0]],"id":63161712},{"atb":[[3.2,0]],"id":58069703},{"atl":[[3.25,0]],"id":65732558},{"atb":[[1.92,49.23],[2.46,23.77]],"id":61028210}],"con":true,"img":false}]}
{"op":"mcm","clk":"11449974522","pt":1717316611258,"mc":[{"id":"1.229554896","rc":[{"atb":[[2.36,8.7]],"id":61028210}],"con":true,"img":false}]}
{"op":"mcm","clk":"11449974529","pt":1717316611348,"mc":[{"id":"1.229554896","rc":[{"atb":[[2.94,5.37]],"id":50605162}],"con":true,"img":false}]}
{"op":"mcm","clk":"11449974625","pt":1717316612954,"mc":[{"id":"1.229554896","rc":[{"atb":[[2.26,6.55]],"id":58069703}],"con":true,"img":false}]}
{"op":"mcm","clk":"11449975008","pt":1717316618639,"mc":[{"id":"1.229554896","rc":[{"atl":[[1.7,0],[1.71,140.85]],"id":63161712},{"atl":[[130,4.94],[150,0]],"id":50605162}],"con":true,"img":false}]}
{"op":"mcm","clk":"11449975092","pt":1717316619941,"mc":[{"id":"1.229554896","rc":[{"atb":[[3.1,0]],"id":58069703},{"atb":[[2.74,20.02]],"id":61028210}],"con":true,"img":false}]}
{"op":"mcm","clk":"11449975099","pt":1717316620045,"mc":[{"id":"1.229554896","rc":[{"atb":[[1.01,0]],"id":63161712},{"atl":[[2.34,0]],"id":63161712},{"atb":[[3.25,0],[3.75,0]],"id":58069703},{"atb":[[6.8,0],[5.4,0]],"id":50605162},{"atb":[[1.01,175.54]],"id":65732558},{"atl":[[2.56,0]],"id":65732558},{"atb":[[2.74,0],[2.94,0]],"id":61028210}],"con":true,"img":false}]}
{"op":"mcm","clk":"11449975118","pt":1717316620256,"mc":[{"id":"1.229554896","rc":[{"atl":[[3,40.52],[2.96,0]],"id":65732558}],"con":true,"img":false}]}
{"op":"mcm","clk":"11449975142","pt":1717316620562,"mc":[{"id":"1.229554896","rc":[{"atl":[[3.4,7.24]],"id":65732558}],"con":true,"img":false}]}
{"op":"mcm","clk":"11449975195","pt":1717316621246,"mc":[{"id":"1.229554896","rc":[{"atl":[[40,0],[46,2.22]],"id":58069703}],"con":true,"img":false}]}
{"op":"mcm","clk":"11449975203","pt":1717316621355,"mc":[{"id":"1.229554896","rc":[{"atl":[[36,0]],"id":58069703},{"atl":[[130,4.61],[34,2.61]],"id":50605162}],"con":true,"img":false}]}
{"op":"mcm","clk":"11449975213","pt":1717316621461,"mc":[{"id":"1.229554896","rc":[{"atl":[[23,2.61]],"id":58069703}],"con":true,"img":false}]}
{"op":"mcm","clk":"11449975218","pt":1717316621564,"mc":[{"id":"1.229554896","rc":[{"atb":[[3.4,0]],"id":58069703}],"con":true,"img":false}]}
{"op":"mcm","clk":"11449975392","pt":1717316623787,"mc":[{"id":"1.229554896","rc":[{"atl":[[1.77,129.87],[1.71,0]],"id":63161712}],"con":true,"img":false}]}
{"op":"mcm","clk":"11449975524","pt":1717316625350,"mc":[{"id":"1.229554896","rc":[{"atl":[[3,0],[3.3,43.48]],"id":65732558}],"con":true,"img":false}]}
{"op":"mcm","clk":"11449976565","pt":1717316640093,"mc":[{"id":"1.229554896","rc":[{"atl":[[23,0]],"id":61028210}],"con":true,"img":false}]}
{"op":"mcm","clk":"11449976574","pt":1717316640201,"mc":[{"id":"1.229554896","rc":[{"atl":[[19.5,7.85]],"id":61028210}],"con":true,"img":false}]}
{"op":"mcm","clk":"11449976656","pt":1717316641397,"mc":[{"id":"1.229554896","rc":[{"atb":[[1.09,648.11]],"id":65732558}],"con":true,"img":false}]}
{"op":"mcm","clk":"11449976792","pt":1717316643281,"mc":[{"id":"1.229554896","rc":[{"atb":[[1.03,3421.33]],"id":63161712}],"con":true,"img":false}]}
{"op":"mcm","clk":"11449976802","pt":1717316643386,"mc":[{"id":"1.229554896","rc":[{"atl":[[3.65,4.05]],"id":63161712}],"con":true,"img":false}]}
{"op":"mcm","clk":"11449976997","pt":1717316645898,"mc":[{"id":"1.229554896","rc":[{"atl":[[38,0]],"id":58069703},{"atl":[[130,2]],"id":50605162}],"con":true,"img":false}]}
{"op":"mcm","clk":"11449977005","pt":1717316646006,"mc":[{"id":"1.229554896","rc":[{"atl":[[23,5.23]],"id":58069703},{"atl":[[36,2.61]],"id":50605162}],"con":true,"img":false}]}
{"op":"mcm","clk":"11449977013","pt":1717316646108,"mc":[{"id":"1.229554896","rc":[{"atb":[[1.01,5807.26]],"id":63161712},{"atl":[[2.3,0.4]],"id":63161712},{"atb":[[3.8,8.29],[3.3,15.15]],"id":58069703},{"atb":[[6.8,4],[5.4,7.92]],"id":50605162},{"atb":[[1.01,5982.8]],"id":65732558},{"atl":[[2.58,0.32]],"id":65732558},{"atb":[[2.74,20.02],[2.94,11.97]],"id":61028210}],"con":true,"img":false}]}
{"op":"mcm","clk":"11449977026","pt":1717316646214,"mc":[{"id":"1.229554896","rc":[{"atl":[[1.73,19.02],[1.77,0],[3.65,0]],"id":63161712},{"atl":[[40,2.56],[46,0]],"id":58069703},{"atl":[[3,11.31],[3.3,0]],"id":65732558}],"con":true,"img":false}]}
{"op":"mcm","clk":"11449977153","pt":1717316647613,"mc":[{"id":"1.229554896","rc":[{"atb":[[1.03,88],[1.02,2917.04]],"id":63161712},{"atb":[[1.12,0],[1.09,1759.22]],"id":65732558},{"atb":[[2.44,0],[2.68,23.96]],"id":61028210}],"con":true,"img":false}]}
{"op":"mcm","clk":"11449977161","pt":1717316647716,"mc":[{"id":"1.229554896","rc":[{"atb":[[1.03,0]],"id":63161712}],"con":true,"img":false}]}
{"op":"mcm","clk":"11449977351","pt":1717316650202,"mc":[{"id":"1.229554896","rc":[{"atl":[[23,0]],"id":58069703},{"atl":[[36,0]],"id":50605162},{"atb":[[2.36,0],[2.24,33.75],[2.46,0]],"id":61028210},{"atl":[[19.5,5.23]],"id":61028210}],"con":true,"img":false}]}
{"op":"mcm","clk":"11449977364","pt":1717316650309,"mc":[{"id":"1.229554896","rc":[{"atl":[[36,2.61],[38,2.61]],"id":58069703},{"atl":[[120,2.61]],"id":50605162},{"atl":[[22,2.61]],"id":61028210}],"con":true,"img":false}]}
{"op":"mcm","clk":"11449977555","pt":1717316652695,"mc":[{"id":"1.229554896","rc":[{"spn":1.39,"spf":"NaN","id":63161712},{"spn":19.9,"spf":"NaN","id":58069703},{"atl":[[120,0]],"id":50605162},{"spn":20.4,"spf":"NaN","id":50605162},{"spn":1.84,"spf":"NaN","id":65732558},{"atb":[[2.44,33.76],[2.68,0]],"id":61028210}],"con":true,"img":false}]}
{"op":"mcm","clk":"11449977564","pt":1717316652797,"mc":[{"id":"1.229554896","rc":[{"atl":[[150,2.61]],"id":50605162}],"con":true,"img":false}]}
{"op":"mcm","clk":"11449977682","pt":1717316654296,"mc":[{"id":"1.229554896","rc":[{"atl":[[65,2],[40,0]],"id":58069703},{"atl":[[130,0],[200,2]],"id":50605162},{"atb":[[1.09,648.11],[1.08,1250]],"id":65732558}],"con":true,"img":false}]}
{"op":"mcm","clk":"11449977692","pt":1717316654502,"mc":[{"id":"1.229554896","rc":[{"atb":[[1.09,606.01]],"id":65732558}],"con":true,"img":false}]}
{"op":"mcm","clk":"11449977937","pt":1717316657515,"mc":[{"id":"1.229554896","rc":[{"atl":[[1.73,0],[1.67,19.02]],"id":63161712},{"atl":[[3,0],[2.7,11.31]],"id":65732558}],"con":true,"img":false}]}
{"op":"mcm","clk":"11449978039","pt":1717316658719,"mc":[{"id":"1.229554896","rc":[{"atb":[[2.5,2.83]],"id":61028210}],"con":true,"img":false}]}
{"op":"mcm","clk":"11449978047","pt":1717316658827,"mc":[{"id":"1.229554896","rc":[{"atb":[[2.76,20.03]],"id":61028210}],"con":true,"img":false}]}
{"op":"mcm","clk":"11449978057","pt":1717316658923,"mc":[{"id":"1.229554896","rc":[{"atb":[[2.44,0]],"id":61028210}],"con":true,"img":false}]}
{"op":"mcm","clk":"11449978089","pt":1717316659233,"mc":[{"id":"1.229554896","rc":[{"atl":[[120,0.35]],"id":50605162},{"atb":[[1.11,0]],"id":65732558},{"atl":[[3.05,20.41]],"id":65732558}],"con":true,"img":false}]}
{"op":"mcm","clk":"11449978097","pt":1717316659335,"mc":[{"id":"1.229554896","rc":[{"atl":[[34,0]],"id":50605162},{"atb":[[1.1,98.4]],"id":65732558},{"atl":[[4.7,0]],"id":65732558}],"con":true,"img":false}]}
{"op":"mcm","clk":"11449978162","pt":1717316660115,"mc":[{"id":"1.229554896","rc":[{"atl":[[120,0]],"id":50605162}],"con":true,"img":false}]}
{"op":"mcm","clk":"11449978171","pt":1717316660216,"mc":[{"id":"1.229554896","rc":[{"atl":[[140,0.35]],"id":50605162}],"con":true,"img":false}]}
{"op":"mcm","clk":"11449978184","pt":1717316660426,"mc":[{"id":"1.229554896","rc":[{"atb":[[2.26,0]],"id":58069703},{"atb":[[2.94,0]],"id":50605162}],"con":true,"img":false}]}
{"op":"mcm","clk":"11449978632","pt":1717316666329,"mc":[{"id":"1.229554896","rc":[{"atb":[[3.2,4.68]],"id":58069703}],"con":true,"img":false}]}
{"op":"mcm","clk":"11449978731","pt":1717316667546,"mc":[{"id":"1.229554896","rc":[{"atb":[[1.01,20.25]],"id":50605162}],"con":true,"img":false}]}
{"op":"mcm","clk":"11449978827","pt":1717316668720,"mc":[{"id":"1.229554896","rc":[{"atb":[[1.01,19.76]],"id":50605162}],"con":true,"img":false}]}
{"op":"mcm","clk":"11449978842","pt":1717316668925,"mc":[{"id":"1.229554896","rc":[{"atb":[[1.01,17.89]],"id":50605162}],"con":true,"img":false}]}
{"op":"mcm","clk":"11449978851","pt":1717316669029,"mc":[{"id":"1.229554896","rc":[{"atb":[[3.1,1.86]],"id":50605162}],"con":true,"img":false}]}
{"op":"mcm","clk":"11449978926","pt":1717316670109,"mc":[{"id":"1.229554896","rc":[{"atl":[[3.2,0],[2.5,27.9]],"id":63161712}],"con":true,"img":false}]}
{"op":"mcm","clk":"11449979046","pt":1717316671715,"mc":[{"id":"1.229554896","rc":[{"atb":[[2.32,0],[3.35,17.8]],"id":58069703}],"con":true,"img":false}]}
{"op":"mcm","clk":"11449979307","pt":1717316675434,"mc":[{"id":"1.229554896","rc":[{"atb":[[2.2,8.91]],"id":61028210}],"con":true,"img":false}]}
{"op":"mcm","clk":"11449979493","pt":1717316678339,"mc":[{"id":"1.229554896","rc":[{"atb":[[3,0],[7,6.97]],"id":50605162}],"con":true,"img":false}]}
{"op":"mcm","clk":"11449979512","pt":1717316678542,"mc":[{"id":"1.229554896","rc":[{"atl":[[1.67,0],[1.68,38.04]],"id":63161712},{"atl":[[65,0],[50,2.04]],"id":58069703},{"atl":[[160,2],[200,0]],"id":50605162},{"atb":[[1.1,704.41],[1.08,0]],"id":65732558},{"atl":[[2.82,12.99],[2.7,0]],"id":65732558},{"atb":[[2.52,32.01],[2.76,0]],"id":61028210}],"con":true,"img":false}]}
{"op":"mcm","clk":"11449979519","pt":1717316678643,"mc":[{"id":"1.229554896","rc":[{"atl":[[1.68,0],[1.69,38.04]],"id":63161712}],"con":true,"img":false}]}
{"op":"mcm","clk":"11449979695","pt":1717316681236,"mc":[{"id":"1.229554896","rc":[{"atl":[[3.15,5.01]],"id":65732558}],"con":true,"img":false}]}
{"op":"mcm","clk":"11449979748","pt":1717316682056,"mc":[{"id":"1.229554896","rc":[{"atb":[[2.84,0]],"id":61028210}],"con":true,"img":false}]}
{"op":"mcm","clk":"11449980335","pt":1717316690357,"mc":[{"id":"1.229554896","rc":[{"atb":[[2.2,0]],"id":61028210}],"con":true,"img":false}]}
{"op":"mcm","clk":"11449980727","pt":1717316696443,"mc":[{"id":"1.229554896","rc":[{"atb":[[2.5,0]],"id":61028210}],"con":true,"img":false}]}
{"op":"mcm","clk":"11449980853","pt":1717316698246,"mc":[{"id":"1.229554896","rc":[{"atb":[[1.09,648.11]],"id":65732558}],"con":true,"img":false}]}
{"op":"mcm","clk":"11449980930","pt":1717316699437,"mc":[{"id":"1.229554896","rc":[{"atb":[[1.03,88]],"id":63161712}],"con":true,"img":false}]}
{"op":"mcm","clk":"11449980971","pt":1717316700156,"mc":[{"id":"1.229554896","rc":[{"atl":[[2.72,32.77]],"id":63161712},{"atb":[[3.05,30.86]],"id":58069703},{"atb":[[6.2,11.26]],"id":50605162},{"atl":[[3.3,23.71]],"id":65732558}],"con":true,"img":false}]}
{"op":"mcm","clk":"11449980981","pt":1717316700256,"mc":[{"id":"1.229554896","rc":[{"atl":[[3.8,0]],"id":63161712},{"atb":[[2.14,0]],"id":58069703},{"atb":[[2.74,0]],"id":50605162},{"atl":[[5.2,0]],"id":65732558},{"atb":[[2.24,0],[1.92,0]],"id":61028210}],"con":true,"img":false}]}
{"op":"mcm","clk":"11449980990","pt":1717316700358,"mc":[{"id":"1.229554896","rc":[{"atb":[[2.54,33.75],[2.1,49.23]],"id":61028210}],"con":true,"img":false}]}
{"op":"mcm","clk":"11449981208","pt":1717316703363,"mc":[{"id":"1.229554896","rc":[{"atb":[[1.03,85.46]],"id":63161712}],"con":true,"img":false}]}
{"op":"mcm","clk":"11449981599","pt":1717316708750,"mc":[{"id":"1.229554896","rc":[{"atb":[[1.01,0]],"id":63161712},{"atl":[[2.3,0]],"id":63161712},{"atb":[[3.8,0],[3.3,0]],"id":58069703},{"atb":[[6.8,0],[5.4,0]],"id":50605162},{"atb":[[1.01,175.54]],"id":65732558},{"atl":[[2.58,0]],"id":65732558},{"atb":[[2.74,0],[2.94,0]],"id":61028210}],"con":true,"img":false}]}
{"op":"mcm","clk":"11449981606","pt":1717316708857,"mc":[{"id":"1.229554896","rc":[{"atl":[[2.82,0],[2.88,25.98]],"id":65732558}],"con":true,"img":false}]}
{"op":"mcm","clk":"11449981688","pt":1717316710152,"mc":[{"id":"1.229554896","rc":[{"atb":[[2.54,0]],"id":61028210}],"con":true,"img":false}]}
{"op":"mcm","clk":"11449981694","pt":1717316710256,"mc":[{"id":"1.229554896","rc":[{"atb":[[2.12,64.02],[2.26,33.75]],"id":61028210}],"con":true,"img":false}]}
{"op":"mcm","clk":"11449981702","pt":1717316710363,"mc":[{"id":"1.229554896","rc":[{"atb":[[2.52,0]],"id":61028210}],"con":true,"img":false}]}
{"op":"mcm","clk":"11449981895","pt":1717316712786,"mc":[{"id":"1.229554896","rc":[{"atl":[[1.73,76.08],[1.69,0]],"id":63161712},{"spn":19.67,"spf":"NaN","id":58069703},{"atl":[[160,0],[190,2]],"id":50605162},{"spn":73.5,"spf":"NaN","id":50605162},{"spn":1.99,"spf":"NaN","id":65732558},{"spn":10.88,"spf":"NaN","id":61028210}],"con":true,"img":false}]}
{"op":"mcm","clk":"11449981912","pt":1717316712993,"mc":[{"id":"1.229554896","rc":[{"atb":[[1.03,68.98]],"id":63161712}],"con":true,"img":false}]}
{"op":"mcm","clk":"11449981993","pt":1717316714076,"mc":[{"id":"1.229554896","rc":[{"atl":[[2.98,50.51]],"id":65732558}],"con":true,"img":false}]}
{"op":"mcm","clk":"11449982002","pt":1717316714179,"mc":[{"id":"1.229554896","rc":[{"atl":[[2.88,0]],"id":65732558}],"con":true,"img":false}]}
{"op":"mcm","clk":"11449982484","pt":1717316720866,"mc":[{"id":"1.229554896","rc":[{"atl":[[3.4,0]],"id":65732558},{"atb":[[2.28,49.23]],"id":61028210}],"con":true,"img":false}]}
{"op":"mcm","clk":"11449982488","pt":1717316720970,"mc":[{"id":"1.229554896","rc":[{"atb":[[2.12,0]],"id":61028210}],"con":true,"img":false}]}
{"op":"mcm","clk":"11449982528","pt":1717316721588,"mc":[{"id":"1.229554896","rc":[{"atb":[[1.01,5807.26]],"id":63161712},{"atl":[[2.26,0.41]],"id":63161712},{"atb":[[4.1,7.49],[3.55,13.66]],"id":58069703},{"atb":[[6.4,6.45],[8.4,3.13]],"id":50605162},{"atb":[[1.01,5982.8]],"id":65732558},{"atl":[[2.48,0.35]],"id":65732558},{"atb":[[2.86,18.73],[3.15,10.8]],"id":61028210}],"con":true,"img":false}]}
{"op":"mcm","clk":"11449982546","pt":1717316721801,"mc":[{"id":"1.229554896","rc":[{"atb":[[2.52,49.23],[2.28,0]],"id":61028210}],"con":true,"img":false}]}
{"op":"mcm","clk":"11449982722","pt":1717316724579,"mc":[{"id":"1.229554896","rc":[{"atl":[[3.4,17.43],[3.75,20.49]],"id":63161712},{"atb":[[2.36,30.77],[2.16,54.41]],"id":58069703},{"atb":[[2.8,32.55],[3.1,21.8]],"id":50605162},{"atl":[[4.8,14.35]],"id":65732558},{"atb":[[2.1,0]],"id":61028210}],"con":true,"img":false}]}
{"op":"mcm","clk":"11449982728","pt":1717316724686,"mc":[{"id":"1.229554896","rc":[{"atl":[[2.72,0],[2.5,0]],"id":63161712},{"atb":[[3.35,0],[3.05,0]],"id":58069703},{"atb":[[6.2,0],[7,0]],"id":50605162},{"atl":[[3.3,0]],"id":65732558},{"atb":[[1.96,49.23]],"id":61028210}],"con":true,"img":false}]}
{"op":"mcm","clk":"11449982787","pt":1717316725669,"mc":[{"id":"1.229554896","rc":[{"atb":[[2.22,8.7]],"id":61028210}],"con":true,"img":false}]}
{"op":"mcm","clk":"11449982829","pt":1717316726500,"mc":[{"id":"1.229554896","rc":[{"atl":[[3.15,0]],"id":65732558}],"con":true,"img":false}]}
{"op":"mcm","clk":"11449982899","pt":1717316727373,"mc":[{"id":"1.229554896","rc":[{"atb":[[3.1,19.93]],"id":50605162}],"con":true,"img":false}]}
{"op":"mcm","clk":"11449983096","pt":1717316730202,"mc":[{"id":"1.229554896","rc":[{"atb":[[2.26,0]],"id":61028210}],"con":true,"img":false}]}
{"op":"mcm","clk":"11449983102","pt":1717316730302,"mc":[{"id":"1.229554896","rc":[{"atb":[[2.22,0],[2.14,33.75]],"id":61028210}],"con":true,"img":false}]}
{"op":"mcm","clk":"11449983108","pt":1717316730402,"mc":[{"id":"1.229554896","rc":[{"atb":[[3.2,0]],"id":58069703}],"con":true,"img":false}]}
{"op":"mcm","clk":"11449983128","pt":1717316730670,"mc":[{"id":"1.229554896","rc":[{"atb":[[1.09,606.01]],"id":65732558}],"con":true,"img":false}]}
{"op":"mcm","clk":"11449983165","pt":1717316731285,"mc":[{"id":"1.229554896","rc":[{"atb":[[2.98,5.26]],"id":50605162}],"con":true,"img":false}]}
{"op":"mcm","clk":"11449983176","pt":1717316731492,"mc":[{"id":"1.229554896","rc":[{"atb":[[2.3,6.55]],"id":58069703}],"con":true,"img":false}]}
{"op":"mcm","clk":"11449983330","pt":1717316733405,"mc":[{"id":"1.229554896","rc":[{"atb":[[2.58,2.69]],"id":61028210}],"con":true,"img":false}]}
{"op":"mcm","clk":"11449983718","pt":1717316739511,"mc":[{"id":"1.229554896","rc":[{"atl":[[3.05,0]],"id":65732558}],"con":true,"img":false}]}
{"op":"mcm","clk":"11449983724","pt":1717316739638,"mc":[{"id":"1.229554896","rc":[{"atl":[[2.96,20.41]],"id":65732558}],"con":true,"img":false}]}
{"op":"mcm","clk":"11449983768","pt":1717316740211,"mc":[{"id":"1.229554896","rc":[{"atb":[[1.1,606.01]],"id":65732558}],"con":true,"img":false}]}
{"op":"mcm","clk":"11449983776","pt":1717316740310,"mc":[{"id":"1.229554896","rc":[{"atb":[[1.11,98.4]],"id":65732558}],"con":true,"img":false}]}
{"op":"mcm","clk":"11449983822","pt":1717316741200,"mc":[{"id":"1.229554896","rc":[{"atl":[[1.73,0],[1.69,17.44]],"id":63161712},{"atl":[[160,2],[190,0]],"id":50605162},{"atl":[[2.88,20.41],[2.98,0]],"id":65732558}],"con":true,"img":false}]}
{"op":"mcm","clk":"11449984128","pt":1717316745328,"mc":[{"id":"1.229554896","rc":[{"atb":[[1.03,60.21]],"id":63161712}],"con":true,"img":false}]}
{"op":"mcm","clk":"11449984207","pt":1717316746409,"mc":[{"id":"1.229554896","rc":[{"atb":[[1.09,648.11]],"id":65732558}],"con":true,"img":false}]}
{"op":"mcm","clk":"11449984288","pt":1717316747495,"mc":[{"id":"1.229554896","rc":[{"atb":[[1.03,88]],"id":63161712}],"con":true,"img":false}]}
{"op":"mcm","clk":"11449984478","pt":1717316750129,"mc":[{"id":"1.229554896","rc":[{"atl":[[2.44,29.06]],"id":63161712}],"con":true,"img":false}]}
{"op":"mcm","clk":"11449984482","pt":1717316750229,"mc":[{"id":"1.229554896","rc":[{"atl":[[3.4,0]],"id":63161712}],"con":true,"img":false}]}
{"op":"mcm","clk":"11449984546","pt":1717316751206,"mc":[{"id":"1.229554896","rc":[{"atl":[[2.5,6.84]],"id":63161712},{"atl":[[3.1,5.01]],"id":65732558}],"con":true,"img":false}]}
{"op":"mcm","clk":"11449984802","pt":1717316754902,"mc":[{"id":"1.229554896","rc":[{"atb":[[1.03,85.86]],"id":63161712}],"con":true,"img":false}]}
{"op":"mcm","clk":"11449985156","pt":1717316760223,"mc":[{"id":"1.229554896","rc":[{"atb":[[2.14,0]],"id":61028210}],"con":true,"img":false}]}
{"op":"mcm","clk":"11449985165","pt":1717316760328,"mc":[{"id":"1.229554896","rc":[{"atb":[[2.3,0]],"id":58069703},{"atb":[[2.98,0]],"id":50605162},{"atb":[[2.54,33.75]],"id":61028210}],"con":true,"img":false}]}
{"op":"mcm","clk":"11449985424","pt":1717316763444,"mc":[{"id":"1.229554896","rc":[{"atb":[[1.09,645.56]],"id":65732558}],"con":true,"img":false}]}
{"op":"mcm","clk":"11449985458","pt":1717316763765,"mc":[{"id":"1.229554896","rc":[{"atb":[[1.03,73.47]],"id":63161712},{"atl":[[2.5,0]],"id":63161712}],"con":true,"img":false}]}
{"op":"mcm","clk":"11449985988","pt":1717316770142,"mc":[{"id":"1.229554896","rc":[{"atb":[[3.35,17.8]],"id":58069703},{"atb":[[7,6.97]],"id":50605162}],"con":true,"img":false}]}
{"op":"mcm","clk":"11449985999","pt":1717316770245,"mc":[{"id":"1.229554896","rc":[{"atb":[[2.36,0]],"id":58069703},{"atb":[[3.1,0]],"id":50605162}],"con":true,"img":false}]}
{"op":"mcm","clk":"11449986011","pt":1717316770454,"mc":[{"id":"1.229554896","rc":[{"atb":[[2.58,0]],"id":61028210}],"con":true,"img":false}]}
{"op":"mcm","clk":"11449986248","pt":1717316773465,"mc":[{"id":"1.229554896","rc":[{"spn":1.37,"spf":"NaN","id":63161712},{"spn":20.05,"spf":"NaN","id":58069703},{"spn":74.2,"spf":"NaN","id":50605162},{"spn":1.79,"spf":"NaN","id":65732558},{"atb":[[2.44,8.7]],"id":61028210},{"spn":11.32,"spf":"NaN","id":61028210}],"con":true,"img":false}]}
{"op":"mcm","clk":"11449986640","pt":1717316778940,"mc":[{"id":"1.229554896","rc":[{"atb":[[3.25,4.58]],"id":58069703}],"con":true,"img":false}]}
{"op":"mcm","clk":"11449987354","pt":1717316788178,"mc":[{"id":"1.229554896","rc":[{"atl":[[2.62,34.79],[3.75,0]],"id":63161712},{"atb":[[2.16,0],[3.05,30.86]],"id":58069703},{"atl":[[4.8,0],[2.86,29.32]],"id":65732558},{"atb":[[1.96,0]],"id":61028210},{"atl":[[22,0]],"id":61028210}],"con":true,"img":false}]}
{"op":"mcm","clk":"11449987359","pt":1717316788279,"mc":[{"id":"1.229554896","rc":[{"atb":[[2.16,49.23]],"id":61028210},{"atl":[[24,2.61]],"id":61028210}],"con":true,"img":false}]}
{"op":"mcm","clk":"11449987366","pt":1717316788383,"mc":[{"id":"1.229554896","rc":[{"atl":[[3.1,0]],"id":65732558}],"con":true,"img":false}]}
{"op":"mcm","clk":"11449987488","pt":1717316790179,"mc":[{"id":"1.229554896","rc":[{"atb":[[2.8,0],[6.2,11.26]],"id":50605162}],"con":true,"img":false}]}
{"op":"mcm","clk":"11449987626","pt":1717316792092,"mc":[{"id":"1.229554896","rc":[{"atb":[[1.09,648.12]],"id":65732558}],"con":true,"img":false}]}
{"op":"mcm","clk":"11449988039","pt":1717316797669,"mc":[{"id":"1.229554896","rc":[{"atl":[[2.5,6.84]],"id":63161712}],"con":true,"img":false}]}
{"op":"mcm","clk":"11449988114","pt":1717316798599,"mc":[{"id":"1.229554896","rc":[{"atl":[[1.71,34.88],[1.69,0]],"id":63161712},{"atl":[[160,0],[180,2]],"id":50605162},{"atb":[[2.44,0]],"id":61028210}],"con":true,"img":false}]}
{"op":"mcm","clk":"11449988232","pt":1717316800375,"mc":[{"id":"1.229554896","rc":[{"atb":[[1.03,88]],"id":63161712}],"con":true,"img":false}]}
{"op":"mcm","clk":"11449988666","pt":1717316806282,"mc":[{"id":"1.229554896","rc":[{"atb":[[3.15,1.98]],"id":58069703}],"con":true,"img":false}]}
{"op":"mcm","clk":"11449988703","pt":1717316806903,"mc":[{"id":"1.229554896","rc":[{"atb":[[2.6,2.65]],"id":61028210}],"con":true,"img":false}]}
{"op":"mcm","clk":"11449989369","pt":1717316816171,"mc":[{"id":"1.229554896","rc":[{"atb":[[3.25,3.46]],"id":58069703}],"con":true,"img":false}]}
{"op":"mcm","clk":"11449989488","pt":1717316817778,"mc":[{"id":"1.229554896","rc":[{"atb":[[2.44,8.7]],"id":61028210}],"con":true,"img":false}]}
{"op":"mcm","clk":"11449989647","pt":1717316820210,"mc":[{"id":"1.229554896","rc":[{"atl":[[2.96,0]],"id":65732558}],"con":true,"img":false}]}
{"op":"mcm","clk":"11449989653","pt":1717316820307,"mc":[{"id":"1.229554896","rc":[{"atl":[[2.86,49.73]],"id":65732558}],"con":true,"img":false}]}
{"op":"mcm","clk":"11449989726","pt":1717316821432,"mc":[{"id":"1.229554896","rc":[{"atl":[[3.1,5.01]],"id":65732558}],"con":true,"img":false}]}
{"op":"mcm","clk":"11449989815","pt":1717316823016,"mc":[{"id":"1.229554896","rc":[{"atb":[[3.25,4.58]],"id":58069703}],"con":true,"img":false}]}
{"op":"mcm","clk":"11449989921","pt":1717316824513,"mc":[{"id":"1.229554896","rc":[{"atb":[[1.09,643.01]],"id":65732558}],"con":true,"img":false}]}
{"op":"mcm","clk":"11449990403","pt":1717316830233,"mc":[{"id":"1.229554896","rc":[{"atl":[[2.44,0]],"id":63161712}],"con":true,"img":false}]}
{"op":"mcm","clk":"11449990412","pt":1717316830291,"mc":[{"id":"1.229554896","rc":[{"atl":[[2.24,29.06]],"id":63161712}],"con":true,"img":false}]}
{"op":"mcm","clk":"11449993304","pt":1717316866458,"mc":[{"id":"1.229554896","rc":[{"spn":1.38,"spf":"NaN","id":63161712},{"atb":[[1.09,648.12]],"id":65732558}],"con":true,"img":false}]}
{"op":"mcm","clk":"11449993580","pt":1717316869952,"mc":[{"id":"1.229554896","rc":[{"atb":[[6.4,0],[8.4,0]],"id":50605162}],"con":true,"img":false}]}
{"op":"mcm","clk":"11449995437","pt":1717316891092,"mc":[{"id":"1.229554896","rc":[{"atb":[[6.2,17.97],[8.2,3.22]],"id":50605162}],"con":true,"img":false}]}
{"op":"mcm","clk":"11449997057","pt":1717316910132,"mc":[{"id":"1.229554896","rc":[{"atl":[[2.86,20.41],[3.25,24.23]],"id":65732558}],"con":true,"img":false}]}
{"op":"mcm","clk":"11449997219","pt":1717316912160,"mc":[{"id":"1.229554896","rc":[{"atl":[[3.1,0]],"id":65732558}],"con":true,"img":false}]}
{"op":"mcm","clk":"11449997320","pt":1717316913315,"mc":[{"id":"1.229554896","rc":[{"atl":[[3.1,5.01]],"id":65732558}],"con":true,"img":false}]}
{"op":"mcm","clk":"11450003826","pt":1717316990635,"mc":[{"id":"1.229554896","rc":[{"atb":[[1.05,197.74]],"id":63161712},{"atl":[[1.82,5],[2.5,0],[1.7,92.16],[1.78,2.5],[1.86,10]],"id":63161712},{"spn":1.37,"spf":"NaN","id":63161712},{"atb":[[3.7,10],[3.25,0],[3.9,5],[4.2,10.08]],"id":58069703},{"atl":[[34,2.42],[23,2.5],[27,5]],"id":58069703},{"spn":13.6,"spf":"NaN","id":58069703},{"atb":[[7.6,2.5],[6.8,5],[6,10],[8.4,4.39]],"id":50605162},{"atl":[[130,0.62],[55,2.5]],"id":50605162},{"spn":31.7,"spf":"NaN","id":50605162},{"atb":[[1.18,2.5],[1.11,187.51],[1.14,5],[1.09,645.62],[1.1,616.01]],"id":65732558},{"atl":[[2.24,10],[3.1,0],[2.84,43.48],[2.16,5],[2.08,2.5]],"id":65732558},{"spn":1.63,"spf":"NaN","id":65732558},{"atb":[[3.35,5],[2.44,0],[3.15,26.73],[3.55,2.5]],"id":61028210},{"atl":[[9,5],[19,4.44],[8.2,2.5],[9.8,10]],"id":61028210},{"spn":5.87,"spf":"NaN","id":61028210}],"con":true,"img":false}]}
{"op":"mcm","clk":"11450003837","pt":1717316990739,"mc":[{"id":"1.229554896","rc":[{"atl":[[2.24,30.41],[2.88,0]],"id":65732558},{"atl":[[19.5,2.61],[12,2.62]],"id":61028210}],"con":true,"img":false}]}
{"op":"mcm","clk":"11450003937","pt":1717316991935,"mc":[{"id":"1.229554896","rc":[{"atb":[[6.2,11.26],[8.2,0]],"id":50605162}],"con":true,"img":false}]}
{"op":"mcm","clk":"11450003947","pt":1717316992140,"mc":[{"id":"1.229554896","rc":[{"atb":[[8.4,0]],"id":50605162}],"con":true,"img":false}]}
{"op":"mcm","clk":"11450003956","pt":1717316992244,"mc":[{"id":"1.229554896","rc":[{"atb":[[7.2,2.34]],"id":50605162}],"con":true,"img":false}]}
{"op":"mcm","clk":"11450004102","pt":1717316993859,"mc":[{"id":"1.229554896","rc":[{"atb":[[1.03,81.35]],"id":63161712}],"con":true,"img":false}]}
{"op":"mcm","clk":"11450004607","pt":1717317000151,"mc":[{"id":"1.229554896","rc":[{"atb":[[1.04,0]],"id":63161712},{"atl":[[2.62,0]],"id":63161712},{"atb":[[3.05,0]],"id":58069703},{"atl":[[36,1.06],[38,0]],"id":58069703},{"atb":[[1.09,39.61]],"id":65732558},{"atl":[[3.25,0]],"id":65732558},{"atb":[[2.16,0]],"id":61028210},{"atl":[[24,0]],"id":61028210}],"con":true,"img":false}]}
{"op":"mcm","clk":"11450004624","pt":1717317000256,"mc":[{"id":"1.229554896","rc":[{"atb":[[1.02,3223.58],[1.05,94.66]],"id":63161712},{"atl":[[4,95.46]],"id":63161712},{"atb":[[2.72,42.3]],"id":58069703},{"atl":[[48,9.26]],"id":58069703},{"atl":[[150,0]],"id":50605162},{"atb":[[1.05,297.77]],"id":65732558},{"atl":[[4.1,84.25]],"id":65732558},{"atb":[[2,65.62]],"id":61028210},{"atl":[[34,13.07]],"id":61028210}],"con":true,"img":false}]}
{"op":"mcm","clk":"11450004639","pt":1717317000357,"mc":[{"id":"1.229554896","rc":[{"atb":[[1.03,0],[1.04,103.08]],"id":63161712},{"atl":[[170,2.61]],"id":50605162},{"atb":[[1.09,0]],"id":65732558}],"con":true,"img":false}]}
{"op":"mcm","clk":"11450005372","pt":1717317007136,"mc":[{"id":"1.229554896","rc":[{"atl":[[22,3.81]],"id":58069703},{"atb":[[7.8,3.63]],"id":50605162},{"atl":[[55,3.98]],"id":50605162},{"atb":[[1.18,10]],"id":65732558},{"atl":[[2.06,7.5]],"id":65732558},{"atb":[[3.55,10]],"id":61028210},{"atl":[[8,7.5]],"id":61028210}],"con":true,"img":false}]}
{"op":"mcm","clk":"11450005386","pt":1717317007238,"mc":[{"id":"1.229554896","rc":[{"atl":[[34,0]],"id":58069703},{"atb":[[7.2,0]],"id":50605162},{"atl":[[130,0]],"id":50605162},{"atb":[[1.11,98.4]],"id":65732558},{"atl":[[2.24,10],[2.84,0],[2.16,10]],"id":65732558},{"atb":[[3.15,20.8]],"id":61028210},{"atl":[[19,0]],"id":61028210}],"con":true,"img":false}]}
{"op":"mcm","clk":"11450005669","pt":1717317010126,"mc":[{"id":"1.229554896","rc":[{"atl":[[2.24,0],[4,0],[3.15,18.24]],"id":63161712},{"atb":[[2.72,0],[2.02,85.98],[3.35,0]],"id":58069703},{"atb":[[6.2,0],[2.42,78.17],[3.25,17.43],[7,0]],"id":50605162},{"atl":[[6.4,67.55],[2.86,0],[4.1,0],[4.4,11.54]],"id":65732558},{"atb":[[2,0],[1.81,88.66]],"id":61028210}],"con":true,"img":false}]}
{"op":"mcm","clk":"11450005674","pt":1717317010230,"mc":[{"id":"1.229554896","rc":[{"atl":[[4.9,95.46]],"id":63161712},{"atb":[[2.64,17.8]],"id":58069703}],"con":true,"img":false}]}
{"op":"mcm","clk":"11450006456","pt":1717317018448,"mc":[{"id":"1.229554896","rc":[{"atb":[[6.4,6.45],[8.4,3.13]],"id":50605162}],"con":true,"img":false}]}
{"op":"mcm","clk":"11450006471","pt":1717317018552,"mc":[{"id":"1.229554896","rc":[{"atb":[[1.02,315.48]],"id":63161712},{"atl":[[1.78,129.54],[1.71,0]],"id":63161712},{"atl":[[50,0],[27,8.85]],"id":58069703},{"atb":[[7.6,0],[6.8,0],[6,0],[3.25,61.87]],"id":50605162},{"atb":[[1.12,297.78],[1.1,10]],"id":65732558},{"atl":[[2.24,0],[2.16,0],[2.08,0],[2.48,17.85]],"id":65732558},{"atb":[[3.35,0],[2.52,0],[3.55,7.5],[3.15,10.8],[2.1,88.67]],"id":61028210},{"atl":[[9,15],[12,0]],"id":61028210}],"con":true,"img":false}]}
{"op":"mcm","clk":"11450006479","pt":1717317018653,"mc":[{"id":"1.229554896","rc":[{"atb":[[7.8,0]],"id":50605162},{"atb":[[3.55,0]],"id":61028210}],"con":true,"img":false}]}
{"op":"mcm","clk":"11450006487","pt":1717317018756,"mc":[{"id":"1.229554896","rc":[{"atl":[[1.7,0]],"id":63161712},{"atb":[[4.5,10],[5.3,2.5],[4.9,5]],"id":50605162},{"atl":[[2.06,0],[2.5,5],[2.42,2.5],[2.58,10]],"id":65732558},{"atb":[[2.74,2.5],[2.66,5],[3.15,24.53]],"id":61028210}],"con":true,"img":false}]}
{"op":"mcm","clk":"11450006495","pt":1717317018859,"mc":[{"id":"1.229554896","rc":[{"atl":[[1.72,111.11]],"id":63161712},{"atl":[[2.12,16.16]],"id":65732558}],"con":true,"img":false}]}
{"op":"mcm","clk":"11450006512","pt":1717317019066,"mc":[{"id":"1.229554896","rc":[{"atl":[[1.72,0]],"id":63161712},{"atl":[[2.12,0]],"id":65732558}],"con":true,"img":false}]}
{"op":"mcm","clk":"11450006519","pt":1717317019168,"mc":[{"id":"1.229554896","rc":[{"atl":[[1.78,232.1]],"id":63161712},{"atl":[[2.28,19.62]],"id":65732558}],"con":true,"img":false}]}
{"op":"mcm","clk":"11450006634","pt":1717317020150,"mc":[{"id":"1.229554896","rc":[{"atb":[[1.04,0]],"id":63161712},{"atl":[[36,0],[22,5.67]],"id":58069703},{"atl":[[140,0],[30,1.35]],"id":50605162},{"atb":[[2.54,0]],"id":61028210},{"atl":[[9.6,4.56],[19.5,0]],"id":61028210}],"con":true,"img":false}]}
{"op":"mcm","clk":"11450006644","pt":1717317020256,"mc":[{"id":"1.229554896","rc":[{"atb":[[1.06,103.08]],"id":63161712},{"atb":[[2.22,33.75]],"id":61028210}],"con":true,"img":false}]}
{"op":"mcm","clk":"11450006656","pt":1717317020359,"mc":[{"id":"1.229554896","rc":[{"atb":[[1.06,251.39]],"id":63161712},{"atl":[[22,10.43],[27,5]],"id":58069703},{"atl":[[180,0],[30,3.97]],"id":50605162}],"con":true,"img":false}]}
{"op":"mcm","clk":"11450006665","pt":1717317020463,"mc":[{"id":"1.229554896","rc":[{"atb":[[1.05,2.5]],"id":63161712}],"con":true,"img":false}]}
{"op":"mcm","clk":"11450006958","pt":1717317023360,"mc":[{"id":"1.229554896","rc":[{"atl":[[29,2.86]],"id":50605162}],"con":true,"img":false}]}
{"op":"mcm","clk":"11450006969","pt":1717317023464,"mc":[{"id":"1.229554896","rc":[{"atl":[[55,2.5]],"id":50605162}],"con":true,"img":false}]}
{"op":"mcm","clk":"11450006995","pt":1717317023672,"mc":[{"id":"1.229554896","rc":[{"atl":[[1.86,126.28]],"id":63161712},{"atl":[[2.28,0]],"id":65732558}],"con":true,"img":false}]}
{"op":"mcm","clk":"11450007005","pt":1717317023776,"mc":[{"id":"1.229554896","rc":[{"atl":[[1.78,105.06]],"id":63161712},{"atl":[[2.5,25.36],[2.32,20.9]],"id":65732558}],"con":true,"img":false}]}
{"op":"mcm","clk":"11450007015","pt":1717317023875,"mc":[{"id":"1.229554896","rc":[{"atl":[[2.48,0.35]],"id":65732558}],"con":true,"img":false}]}
{"op":"mcm","clk":"11450007021","pt":1717317023981,"mc":[{"id":"1.229554896","rc":[{"atl":[[2.32,0]],"id":65732558}],"con":true,"img":false}]}
{"op":"mcm","clk":"11450007029","pt":1717317024080,"mc":[{"id":"1.229554896","rc":[{"atl":[[2.42,13.75]],"id":65732558}],"con":true,"img":false}]}
{"op":"mcm","clk":"11450007244","pt":1717317026202,"mc":[{"id":"1.229554896","rc":[{"atb":[[3.7,37.04],[3.25,17.43]],"id":50605162},{"atb":[[2.28,78.13],[2.1,0]],"id":61028210}],"con":true,"img":false}]}
{"op":"mcm","clk":"11450007552","pt":1717317029465,"mc":[{"id":"1.229554896","rc":[{"atb":[[3.15,0]],"id":58069703},{"atb":[[2.6,0]],"id":61028210}],"con":true,"img":false}]}
{"op":"mcm","clk":"11450007621","pt":1717317030188,"mc":[{"id":"1.229554896","rc":[{"atl":[[22,8.57]],"id":58069703},{"atb":[[3.25,0],[5.4,8.92]],"id":50605162},{"atl":[[50,0.8],[30,2.62]],"id":50605162},{"atb":[[1.11,0]],"id":65732558},{"atl":[[4.4,0]],"id":65732558},{"atl":[[9.6,0],[34,0],[27,20.88],[15,2.8]],"id":61028210}],"con":true,"img":false}]}
{"op":"mcm","clk":"11450007629","pt":1717317030290,"mc":[{"id":"1.229554896","rc":[{"atl":[[22,3.81],[26,1.86],[27,8.85]],"id":58069703},{"atl":[[50,2.84],[30,0]],"id":50605162},{"atb":[[1.1,108.4]],"id":65732558},{"atl":[[3.5,11.54]],"id":65732558}],"con":true,"img":false}]}
{"op":"mcm","clk":"11450007660","pt":1717317030552,"mc":[{"id":"1.229554896","rc":[{"atl":[[25,4.17],[27,5]],"id":58069703},{"atl":[[29,0]],"id":50605162}],"con":true,"img":false}]}
{"op":"mcm","clk":"11450007668","pt":1717317030654,"mc":[{"id":"1.229554896","rc":[{"atl":[[32,2.58],[50,0.8],[55,4.5]],"id":50605162}],"con":true,"img":false}]}
{"op":"mcm","clk":"11450007706","pt":1717317031072,"mc":[{"id":"1.229554896","rc":[{"atl":[[32,0]],"id":50605162}],"con":true,"img":false}]}
{"op":"mcm","clk":"11450007718","pt":1717317031179,"mc":[{"id":"1.229554896","rc":[{"atl":[[36,2.29]],"id":50605162}],"con":true,"img":false}]}
{"op":"mcm","clk":"11450007729","pt":1717317031281,"mc":[{"id":"1.229554896","rc":[{"atl":[[36,0]],"id":50605162}],"con":true,"img":false}]}
{"op":"mcm","clk":"11450007744","pt":1717317031383,"mc":[{"id":"1.229554896","rc":[{"atl":[[48,1.7]],"id":50605162}],"con":true,"img":false}]}
{"op":"mcm","clk":"11450008573","pt":1717317040174,"mc":[{"id":"1.229554896","rc":[{"atb":[[1.06,148.31]],"id":63161712},{"atl":[[2.42,27.63],[3.15,0]],"id":63161712},{"atb":[[2.64,0]],"id":58069703},{"atl":[[170,0],[100,4.86]],"id":50605162},{"atb":[[2.22,0]],"id":61028210}],"con":true,"img":false}]}
{"op":"mcm","clk":"11450008582","pt":1717317040278,"mc":[{"id":"1.229554896","rc":[{"atb":[[1.04,103.08]],"id":63161712},{"atb":[[3.6,17.8]],"id":58069703},{"atb":[[2.36,33.75]],"id":61028210}],"con":true,"img":false}]}
{"op":"mcm","clk":"11450009601","pt":1717317050189,"mc":[{"id":"1.229554896","rc":[{"atl":[[26,0]],"id":58069703}],"con":true,"img":false}]}
{"op":"mcm","clk":"11450009614","pt":1717317050293,"mc":[{"id":"1.229554896","rc":[{"atl":[[24,1.86]],"id":58069703}],"con":true,"img":false}]}
{"op":"mcm","clk":"11450009626","pt":1717317050396,"mc":[{"id":"1.229554896","rc":[{"atl":[[23,7.05],[25,0]],"id":58069703}],"con":true,"img":false}]}
{"op":"mcm","clk":"11450009986","pt":1717317054084,"mc":[{"id":"1.229554896","rc":[{"atb":[[1.02,325.48],[1.06,153.31],[1.09,156.11],[1.1,2.5],[1.05,0]],"id":63161712},{"spn":1.44,"spf":"NaN","id":63161712},{"atb":[[4,5],[3.7,0],[3.8,10],[4.4,2.5],[3.9,0],[4.2,7.58]],"id":58069703},{"atl":[[11,8]],"id":58069703},{"spn":7.7,"spf":"NaN","id":58069703},{"atl":[[20,2.5],[22,3.81],[24,5],[55,2],[28,10]],"id":50605162},{"spn":14.2,"spf":"NaN","id":50605162},{"atb":[[1.18,7.5],[1.2,5],[1.16,10],[1.14,0],[1.1,98.4],[1.24,20.31]],"id":65732558},{"spn":1.83,"spf":"NaN","id":65732558},{"spn":5.57,"spf":"NaN","id":61028210}],"con":true,"img":false}]}
{"op":"mcm","clk":"11450009997","pt":1717317054221,"mc":[{"id":"1.229554896","rc":[{"atb":[[1.06,5]],"id":63161712},{"atl":[[10.5,2.5],[23,4.55],[12.5,5],[27,0],[14.5,10]],"id":58069703},{"atl":[[24,7],[55,0]],"id":50605162},{"atb":[[1.18,17.5],[1.12,0]],"id":65732558},{"atl":[[2.4,2.5],[2.56,10],[2.48,5.35]],"id":65732558}],"con":true,"img":false}]}
{"op":"mcm","clk":"11450010010","pt":1717317054293,"mc":[{"id":"1.229554896","rc":[{"atb":[[4.4,13.4]],"id":58069703},{"atl":[[22,0]],"id":58069703},{"atl":[[48,0]],"id":50605162},{"atb":[[1.18,10]],"id":65732558},{"atl":[[2.4,16.83],[2.5,20.36],[2.42,11.25],[2.58,0]],"id":65732558}],"con":true,"img":false}]}
{"op":"mcm","clk":"11450010017","pt":1717317054393,"mc":[{"id":"1.229554896","rc":[{"atl":[[2.42,0]],"id":65732558}],"con":true,"img":false}]}
{"op":"mcm","clk":"11450010029","pt":1717317054498,"mc":[{"id":"1.229554896","rc":[{"atb":[[4.2,0]],"id":58069703}],"con":true,"img":false}]}
{"op":"mcm","clk":"11450010079","pt":1717317055117,"mc":[{"id":"1.229554896","rc":[{"atb":[[1.03,49.26]],"id":63161712}],"con":true,"img":false}]}
{"op":"mcm","clk":"11450010288","pt":1717317057601,"mc":[{"id":"1.229554896","rc":[{"atl":[[23,0],[13,8.33]],"id":58069703}],"con":true,"img":false}]}
{"op":"mcm","clk":"11450010344","pt":1717317058125,"mc":[{"id":"1.229554896","rc":[{"atl":[[1.81,123.46],[1.86,10]],"id":63161712}],"con":true,"img":false}]}
{"op":"mcm","clk":"11450010530","pt":1717317060201,"mc":[{"id":"1.229554896","rc":[{"atl":[[4.9,0]],"id":63161712},{"atb":[[2.02,0],[2.62,46.23]],"id":58069703},{"atb":[[4.6,25.88],[2.42,0]],"id":50605162},{"atl":[[4.8,86.34],[6.4,0]],"id":65732558}],"con":true,"img":false}]}
{"op":"mcm","clk":"11450010545","pt":1717317060352,"mc":[{"id":"1.229554896","rc":[{"atl":[[4,95.46]],"id":63161712}],"con":true,"img":false}]}
{"op":"mcm","clk":"11450011470","pt":1717317069330,"mc":[{"id":"1.229554896","rc":[{"atb":[[1.1,85.04]],"id":63161712},{"atl":[[10,8.89]],"id":58069703},{"atl":[[19.5,4.32]],"id":50605162}],"con":true,"img":false}]}
{"op":"mcm","clk":"11450011479","pt":1717317069413,"mc":[{"id":"1.229554896","rc":[{"atb":[[1.09,0]],"id":63161712},{"atl":[[13,0]],"id":58069703},{"atl":[[22,4.76],[24,5]],"id":50605162}],"con":true,"img":false}]}
{"op":"mcm","clk":"11450011494","pt":1717317069620,"mc":[{"id":"1.229554896","rc":[{"atb":[[1.03,0]],"id":63161712}],"con":true,"img":false}]}
{"op":"mcm","clk":"11450011546","pt":1717317070141,"mc":[{"id":"1.229554896","rc":[{"atb":[[4.6,0]],"id":50605162}],"con":true,"img":false}]}
{"op":"mcm","clk":"11450011557","pt":1717317070249,"mc":[{"id":"1.229554896","rc":[{"atb":[[2.62,0]],"id":58069703},{"atb":[[3.85,21.3],[5.4,0]],"id":50605162}],"con":true,"img":false}]}
{"op":"mcm","clk":"11450011570","pt":1717317070298,"mc":[{"id":"1.229554896","rc":[{"atb":[[2.48,46.23]],"id":58069703},{"atb":[[4.6,8.92]],"id":50605162}],"con":true,"img":false}]}
{"op":"mcm","clk":"11450012344","pt":1717317077549,"mc":[{"id":"1.229554896","rc":[{"atb":[[1.17,100]],"id":58069703},{"atb":[[1.17,100]],"id":50605162},{"atb":[[1.17,100]],"id":61028210}],"con":true,"img":false}]}
{"op":"mcm","clk":"11450012614","pt":1717317080159,"mc":[{"id":"1.229554896","rc":[{"atb":[[1.04,0]],"id":63161712}],"con":true,"img":false}]}
{"op":"mcm","clk":"11450012628","pt":1717317080259,"mc":[{"id":"1.229554896","rc":[{"atb":[[1.05,103.08]],"id":63161712}],"con":true,"img":false}]}
{"op":"mcm","clk":"11450012727","pt":1717317081319,"mc":[{"id":"1.229554896","rc":[{"atb":[[2.86,24.75]],"id":61028210}],"con":true,"img":false}]}
{"op":"mcm","clk":"11450013550","pt":1717317090027,"mc":[{"id":"1.229554896","rc":[{"atl":[[11,10],[12,4.55],[13,6.25],[14,9.62]],"id":58069703},{"atl":[[36,1],[40,1.28],[44,1.74],[48,2.66]],"id":50605162},{"atl":[[5.6,4.35],[6.4,23.15],[5.8,10.42],[6,15]],"id":61028210}],"con":true,"img":false}]}
{"op":"mcm","clk":"11450013561","pt":1717317090131,"mc":[{"id":"1.229554896","rc":[{"atl":[[24,0],[14,12.83]],"id":58069703},{"atl":[[50,0],[27,2.61]],"id":50605162},{"atl":[[3.5,0],[2.78,23.51]],"id":65732558},{"atb":[[2.36,0],[2.88,22.26]],"id":61028210},{"atl":[[9,5],[7.8,7.5],[5.7,16.88]],"id":61028210}],"con":true,"img":false}]}
{"op":"mcm","clk":"11450013576","pt":1717317090335,"mc":[{"id":"1.229554896","rc":[{"atl":[[8,0]],"id":61028210}],"con":true,"img":false}]}
{"op":"mcm","clk":"11450013673","pt":1717317091267,"mc":[{"id":"1.229554896","rc":[{"atb":[[1.04,119.76]],"id":63161712}],"con":true,"img":false}]}
{"op":"mcm","clk":"11450014227","pt":1717317097343,"mc":[{"id":"1.229554896","rc":[{"atb":[[1.02,575.48],[1.04,369.76]],"id":63161712},{"atb":[[1.03,250],[1.09,222.22],[1.05,547.77],[1.07,250]],"id":65732558}],"con":true,"img":false}]}
{"op":"mcm","clk":"11450014281","pt":1717317097961,"mc":[{"id":"1.229554896","rc":[{"atb":[[1.01,6057.26],[1.02,325.48],[1.04,119.76]],"id":63161712},{"atb":[[1.09,0],[1.07,0],[1.05,297.77]],"id":65732558}],"con":true,"img":false}]}
{"op":"mcm","clk":"11450014362","pt":1717317098737,"mc":[{"id":"1.229554896","rc":[{"atb":[[1.04,369.76]],"id":63161712},{"atb":[[1.09,222.22]],"id":65732558}],"con":true,"img":false}]}
{"op":"mcm","clk":"11450014389","pt":1717317099052,"mc":[{"id":"1.229554896","rc":[{"atb":[[1.02,3516.85]],"id":63161712},{"atl":[[1.81,0],[1.77,105.06]],"id":63161712},{"atl":[[11,0],[13.5,8],[9.6,2.33],[9.8,9.09]],"id":58069703},{"atb":[[4.5,0],[5.3,0],[3.7,0],[3.35,42.55],[4.9,0]],"id":50605162},{"atl":[[36,0],[24,6]],"id":50605162},{"atl":[[2.4,14.33],[2.56,0],[2.54,10],[2.38,2.5],[2.46,5],[2.48,0.35]],"id":65732558},{"atb":[[2.94,5],[3.05,2.5],[2.56,64.1],[2.86,28.73],[2.74,0],[2.28,0],[2.66,0]],"id":61028210},{"atl":[[5.6,0],[5,5]],"id":61028210}],"con":true,"img":false}]}
{"op":"mcm","clk":"11450014394","pt":1717317099149,"mc":[{"id":"1.229554896","rc":[{"atl":[[1.77,208.96]],"id":63161712},{"atl":[[10,0]],"id":58069703},{"atb":[[4,5],[4.4,2.5]],"id":50605162},{"atl":[[2.5,0],[2.38,18.75]],"id":65732558}],"con":true,"img":false}]}
{"op":"mcm","clk":"11450014403","pt":1717317099255,"mc":[{"id":"1.229554896","rc":[{"atl":[[9.6,0],[10.5,2.11]],"id":58069703},{"atb":[[2.56,0],[2.86,18.73],[3.15,10.8],[2.94,0],[3.05,0]],"id":61028210}],"con":true,"img":false}]}
{"op":"mcm","clk":"11450014413","pt":1717317099363,"mc":[{"id":"1.229554896","rc":[{"atb":[[1.04,119.76]],"id":63161712},{"atl":[[1.78,2.5]],"id":63161712},{"atb":[[1.09,0]],"id":65732558},{"atl":[[2.4,0]],"id":65732558},{"atb":[[2.56,5],[2.64,2.5],[2.26,79.37],[2.96,11.56],[2.48,10]],"id":61028210}],"con":true,"img":false}]}
{"op":"mcm","clk":"11450014422","pt":1717317099461,"mc":[{"id":"1.229554896","rc":[{"atl":[[1.6,125],[1.58,86.21],[1.62,201.61],[1.56,35.71]],"id":63161712},{"atl":[[10.5,0],[11,2]],"id":58069703},{"atl":[[24,5]],"id":50605162},{"atl":[[5.6,4.35],[5,0]],"id":61028210}],"con":true,"img":false}]}
{"op":"mcm","clk":"11450014428","pt":1717317099564,"mc":[{"id":"1.229554896","rc":[{"atl":[[9.8,0]],"id":58069703}],"con":true,"img":false}]}
{"op":"mcm","clk":"11450014440","pt":1717317099668,"mc":[{"id":"1.229554896","rc":[{"atl":[[10.5,7.16]],"id":58069703}],"con":true,"img":false}]}
{"op":"mcm","clk":"11450014454","pt":1717317099874,"mc":[{"id":"1.229554896","rc":[{"atb":[[1.04,369.76]],"id":63161712},{"atb":[[1.09,222.22]],"id":65732558}],"con":true,"img":false}]}
{"op":"mcm","clk":"11450014481","pt":1717317100138,"mc":[{"id":"1.229554896","rc":[{"atb":[[1.02,3210.31],[1.05,1230.53]],"id":63161712},{"atl":[[4.8,0],[4.3,16.52],[2.78,0]],"id":65732558}],"con":true,"img":false}]}
{"op":"mcm","clk":"11450014492","pt":1717317100289,"mc":[{"id":"1.229554896","rc":[{"atb":[[1.04,119.76]],"id":63161712},{"atb":[[1.09,0]],"id":65732558},{"atl":[[3.05,23.51]],"id":65732558}],"con":true,"img":false}]}
{"op":"mcm","clk":"11450014590","pt":1717317101550,"mc":[{"id":"1.229554896","rc":[{"atb":[[1.04,106.07]],"id":63161712}],"con":true,"img":false}]}
{"op":"mcm","clk":"11450014597","pt":1717317101653,"mc":[{"id":"1.229554896","rc":[{"atb":[[1.04,356.07]],"id":63161712},{"atb":[[1.09,222.22]],"id":65732558},{"atl":[[3.2,22.73],[3.1,9.52],[3.4,52.08],[3.3,32.61]],"id":65732558}],"con":true,"img":false}]}
{"op":"mcm","clk":"11450014810","pt":1717317103974,"mc":[{"id":"1.229554896","rc":[{"atb":[[1.04,106.07]],"id":63161712}],"con":true,"img":false}]}
{"op":"mcm","clk":"11450014819","pt":1717317104075,"mc":[{"id":"1.229554896","rc":[{"atb":[[1.09,0]],"id":65732558}],"con":true,"img":false}]}
{"op":"mcm","clk":"11450014839","pt":1717317104285,"mc":[{"id":"1.229554896","rc":[{"atl":[[2.38,13.75],[2.48,24.1]],"id":65732558}],"con":true,"img":false}]}
{"op":"mcm","clk":"11450014874","pt":1717317104678,"mc":[{"id":"1.229554896","rc":[{"atl":[[5.6,21.12]],"id":61028210}],"con":true,"img":false}]}
{"op":"mcm","clk":"11450014888","pt":1717317104857,"mc":[{"id":"1.229554896","rc":[{"atl":[[5.7,0]],"id":61028210}],"con":true,"img":false}]}
{"op":"mcm","clk":"11450014979","pt":1717317105740,"mc":[{"id":"1.229554896","rc":[{"atl":[[1.6,291.67],[1.77,103.9]],"id":63161712}],"con":true,"img":false}]}
{"op":"mcm","clk":"11450015357","pt":1717317110179,"mc":[{"id":"1.229554896","rc":[{"atl":[[2.72,32.77],[4,0]],"id":63161712},{"atl":[[48,0],[26,2.61],[14,9.62]],"id":58069703},{"atl":[[46,2.61],[100,0]],"id":50605162},{"atb":[[1.09,606.01],[1.05,0]],"id":65732558},{"atl":[[3.05,0]],"id":65732558},{"atb":[[1.93,56.11],[2.88,0],[1.81,0]],"id":61028210},{"atl":[[16,3.47],[27,0]],"id":61028210}],"con":true,"img":false}]}
{"op":"mcm","clk":"11450015368","pt":1717317110276,"mc":[{"id":"1.229554896","rc":[{"atl":[[22,3.21]],"id":58069703},{"atl":[[3.25,23.51]],"id":65732558},{"atb":[[2.5,22.26]],"id":61028210}],"con":true,"img":false}]}
{"op":"mcm","clk":"11450015516","pt":1717317112007,"mc":[{"id":"1.229554896","rc":[{"atl":[[1.56,0],[1.54,37.04]],"id":63161712}],"con":true,"img":false}]}
{"op":"mcm","clk":"11450015523","pt":1717317112082,"mc":[{"id":"1.229554896","rc":[{"atl":[[1.58,258.62]],"id":63161712}],"con":true,"img":false}]}
{"op":"mcm","clk":"11450015532","pt":1717317112188,"mc":[{"id":"1.229554896","rc":[{"atl":[[1.6,125]],"id":63161712}],"con":true,"img":false}]}
{"op":"mcm","clk":"11450015541","pt":1717317112293,"mc":[{"id":"1.229554896","rc":[{"atl":[[1.6,291.67]],"id":63161712}],"con":true,"img":false}]}
{"op":"mcm","clk":"11450015548","pt":1717317112348,"mc":[{"id":"1.229554896","rc":[{"atl":[[1.58,86.21]],"id":63161712}],"con":true,"img":false}]}
{"op":"mcm","clk":"11450015638","pt":1717317113479,"mc":[{"id":"1.229554896","rc":[{"atl":[[1.54,165.48]],"id":63161712}],"con":true,"img":false}]}
{"op":"mcm","clk":"11450015658","pt":1717317113686,"mc":[{"id":"1.229554896","rc":[{"atl":[[1.77,0]],"id":63161712}],"con":true,"img":false}]}
{"op":"mcm","clk":"11450015725","pt":1717317114358,"mc":[{"id":"1.229554896","rc":[{"spn":1.32,"spf":"NaN","id":63161712},{"spn":7.45,"spf":"NaN","id":58069703},{"spn":13.95,"spf":"NaN","id":50605162},{"atb":[[1.2,0],[1.16,0],[1.25,2.5],[1.21,5],[1.24,17.81],[1.17,10]],"id":65732558},{"spn":1.81,"spf":"NaN","id":65732558},{"spn":4.37,"spf":"NaN","id":61028210}],"con":true,"img":false}]}
{"op":"mcm","clk":"11450015735","pt":1717317114461,"mc":[{"id":"1.229554896","rc":[{"atb":[[1.18,0],[1.2,10],[1.25,16.56]],"id":65732558}],"con":true,"img":false}]}
{"op":"mcm","clk":"11450015753","pt":1717317114665,"mc":[{"id":"1.229554896","rc":[{"atb":[[1.24,0]],"id":65732558}],"con":true,"img":false}]}
{"op":"mcm","clk":"11450016179","pt":1717317118785,"mc":[{"id":"1.229554896","rc":[{"atl":[[60,5]],"id":63161712},{"atl":[[60,5]],"id":65732558}],"con":true,"img":false}]}
{"op":"mcm","clk":"11450016259","pt":1717317119662,"mc":[{"id":"1.229554896","rc":[{"atb":[[1.04,119.76]],"id":63161712}],"con":true,"img":false}]}
{"op":"mcm","clk":"11450016305","pt":1717317120279,"mc":[{"id":"1.229554896","rc":[{"atl":[[27,0]],"id":50605162}],"con":true,"img":false}]}
{"op":"mcm","clk":"11450016316","pt":1717317120381,"mc":[{"id":"1.229554896","rc":[{"atl":[[40,3.89]],"id":50605162}],"con":true,"img":false}]}
{"op":"mcm","clk":"11450016489","pt":1717317122099,"mc":[{"id":"1.229554896","rc":[{"atl":[[1.56,89.29]],"id":63161712}],"con":true,"img":false}]}
{"op":"mcm","clk":"11450016499","pt":1717317122201,"mc":[{"id":"1.229554896","rc":[{"atl":[[1.6,125],[1.58,258.62]],"id":63161712}],"con":true,"img":false}]}
{"op":"mcm","clk":"11450016560","pt":1717317122721,"mc":[{"id":"1.229554896","rc":[{"atb":[[6.4,0],[8.4,0]],"id":50605162}],"con":true,"img":false}]}
{"op":"mcm","clk":"11450016574","pt":1717317122832,"mc":[{"id":"1.229554896","rc":[{"atb":[[4.6,15.73]],"id":50605162}],"con":true,"img":false}]}
{"op":"mcm","clk":"11450016580","pt":1717317122931,"mc":[{"id":"1.229554896","rc":[{"atl":[[36,1]],"id":50605162}],"con":true,"img":false}]}
{"op":"mcm","clk":"11450016621","pt":1717317123296,"mc":[{"id":"1.229554896","rc":[{"atl":[[13.5,0],[16.5,6.45]],"id":58069703}],"con":true,"img":false}]}
{"op":"mcm","clk":"11450016830","pt":1717317125222,"mc":[{"id":"1.229554896","rc":[{"atl":[[9.6,4.86]],"id":61028210}],"con":true,"img":false}]}
{"op":"mcm","clk":"11450016844","pt":1717317125332,"mc":[{"id":"1.229554896","rc":[{"atl":[[15,0]],"id":61028210}],"con":true,"img":false}]}
{"op":"mcm","clk":"11450017095","pt":1717317127726,"mc":[{"id":"1.229554896","rc":[{"atl":[[1.62,0]],"id":63161712}],"con":true,"img":false}]}
{"op":"mcm","clk":"11450017342","pt":1717317130108,"mc":[{"id":"1.229554896","rc":[{"atl":[[2.42,0]],"id":63161712}],"con":true,"img":false}]}
{"op":"mcm","clk":"11450017356","pt":1717317130210,"mc":[{"id":"1.229554896","rc":[{"atl":[[2.26,28.04]],"id":63161712}],"con":true,"img":false}]}
{"op":"mcm","clk":"11450018526","pt":1717317141932,"mc":[{"id":"1.229554896","rc":[{"atb":[[2.32,3.22]],"id":61028210}],"con":true,"img":false}]}
{"op":"mcm","clk":"11450018965","pt":1717317146745,"mc":[{"id":"1.229554896","rc":[{"atb":[[6.2,6.7],[8.2,3.22]],"id":50605162}],"con":true,"img":false}]}
{"op":"mcm","clk":"11450018991","pt":1717317147058,"mc":[{"id":"1.229554896","rc":[{"atl":[[14.5,17.41]],"id":58069703}],"con":true,"img":false}]}
{"op":"mcm","clk":"11450018997","pt":1717317147112,"mc":[{"id":"1.229554896","rc":[{"atl":[[16.5,0]],"id":58069703}],"con":true,"img":false}]}
{"op":"mcm","clk":"11450019290","pt":1717317150148,"mc":[{"id":"1.229554896","rc":[{"atb":[[2.72,36.62],[2.48,0]],"id":58069703},{"atl":[[4.3,0]],"id":65732558}],"con":true,"img":false}]}
{"op":"mcm","clk":"11450019305","pt":1717317150251,"mc":[{"id":"1.229554896","rc":[{"atl":[[3.9,16.52]],"id":65732558}],"con":true,"img":false}]}
{"op":"mcm","clk":"11450019617","pt":1717317153556,"mc":[{"id":"1.229554896","rc":[{"atb":[[1.03,250]],"id":63161712},{"atb":[[1.09,828.23]],"id":65732558}],"con":true,"img":false}]}
{"op":"mcm","clk":"11450019636","pt":1717317153762,"mc":[{"id":"1.229554896","rc":[{"atb":[[1.01,5807.26],[1.03,0]],"id":63161712},{"atb":[[1.09,606.01]],"id":65732558}],"con":true,"img":false}]}
{"op":"mcm","clk":"11450019660","pt":1717317153923,"mc":[{"id":"1.229554896","rc":[{"atb":[[1.01,6057.26]],"id":63161712}],"con":true,"img":false}]}
{"op":"mcm","clk":"11450019753","pt":1717317154851,"mc":[{"id":"1.229554896","rc":[{"atb":[[1.03,250]],"id":63161712},{"atb":[[1.09,828.23]],"id":65732558}],"con":true,"img":false}]}
{"op":"mcm","clk":"11450019833","pt":1717317155522,"mc":[{"id":"1.229554896","rc":[{"atb":[[1.01,5807.26],[1.03,0]],"id":63161712},{"atb":[[1.09,606.01]],"id":65732558}],"con":true,"img":false}]}
{"op":"mcm","clk":"11450020002","pt":1717317157274,"mc":[{"id":"1.229554896","rc":[{"atb":[[4,0],[4.6,18.23],[4.4,0]],"id":50605162}],"con":true,"img":false}]}
{"op":"mcm","clk":"11450020067","pt":1717317157849,"mc":[{"id":"1.229554896","rc":[{"atb":[[1.01,6057.26],[1.03,250]],"id":63161712},{"atl":[[10,2.22],[11,0]],"id":58069703},{"atl":[[36,0],[23,1]],"id":50605162},{"atb":[[1.09,828.23]],"id":65732558},{"atl":[[5.3,4.65],[5.6,16.77]],"id":61028210}],"con":true,"img":false}]}
{"op":"mcm","clk":"11450020080","pt":1717317157951,"mc":[{"id":"1.229554896","rc":[{"atl":[[10,11.11]],"id":58069703},{"atl":[[5.4,18.18]],"id":61028210}],"con":true,"img":false}]}
{"op":"mcm","clk":"11450020103","pt":1717317158158,"mc":[{"id":"1.229554896","rc":[{"atl":[[10.5,0]],"id":58069703},{"atl":[[5.6,0]],"id":61028210}],"con":true,"img":false}]}
{"op":"mcm","clk":"11450020221","pt":1717317159243,"mc":[{"id":"1.229554896","rc":[{"atb":[[1.01,5807.26],[1.03,0]],"id":63161712},{"atl":[[10,8.89],[11,2]],"id":58069703},{"atl":[[23,0]],"id":50605162},{"atb":[[1.09,606.01]],"id":65732558},{"atb":[[2.64,0],[2.48,0],[2.56,0],[2.66,2.5]],"id":61028210},{"atl":[[5.3,0],[5.6,4.35]],"id":61028210}],"con":true,"img":false}]}
{"op":"mcm","clk":"11450020236","pt":1717317159447,"mc":[{"id":"1.229554896","rc":[{"atl":[[10,0]],"id":58069703},{"atl":[[5.4,0]],"id":61028210}],"con":true,"img":false}]}
{"op":"mcm","clk":"11450020246","pt":1717317159552,"mc":[{"id":"1.229554896","rc":[{"atl":[[11,9.16]],"id":58069703},{"atl":[[5.6,20.27]],"id":61028210}],"con":true,"img":false}]}
{"op":"mcm","clk":"11450020303","pt":1717317160169,"mc":[{"id":"1.229554896","rc":[{"atb":[[3.85,0]],"id":50605162},{"atb":[[2.5,0],[2.28,32.69]],"id":61028210}],"con":true,"img":false}]}
{"op":"mcm","clk":"11450020313","pt":1717317160273,"mc":[{"id":"1.229554896","rc":[{"atb":[[4.2,21.3]],"id":50605162}],"con":true,"img":false}]}
{"op":"mcm","clk":"11450020947","pt":1717317166576,"mc":[{"id":"1.229554896","rc":[{"atl":[[36,1]],"id":50605162}],"con":true,"img":false}]}
{"op":"mcm","clk":"11450021007","pt":1717317167152,"mc":[{"id":"1.229554896","rc":[{"atb":[[1.01,6057.26]],"id":63161712}],"con":true,"img":false}]}
{"op":"mcm","clk":"11450022488","pt":1717317182062,"mc":[{"id":"1.229554896","rc":[{"spn":7.7,"spf":"NaN","id":58069703},{"spn":13.85,"spf":"NaN","id":50605162},{"atb":[[2.32,0]],"id":61028210}],"con":true,"img":false}]}
{"op":"mcm","clk":"11450022849","pt":1717317185892,"mc":[{"id":"1.229554896","rc":[{"atb":[[1.03,250]],"id":63161712},{"atl":[[34,1],[36,0]],"id":50605162},{"atb":[[1.2,0],[1.19,98.4],[1.09,828.23]],"id":65732558}],"con":true,"img":false}]}
{"op":"mcm","clk":"11450023047","pt":1717317187909,"mc":[{"id":"1.229554896","rc":[{"atb":[[1.01,5807.26],[1.03,0]],"id":63161712},{"atl":[[1.58,206.89],[1.54,128.44]],"id":63161712},{"atb":[[3.6,46.65],[3.7,18.52],[3.8,17.14],[3.5,50]],"id":58069703},{"atl":[[10,2.22],[10.5,8.42],[11,7.16]],"id":58069703},{"atb":[[1.09,606.01]],"id":65732558}],"con":true,"img":false}]}
{"op":"mcm","clk":"11450023063","pt":1717317188069,"mc":[{"id":"1.229554896","rc":[{"atl":[[11,0]],"id":58069703}],"con":true,"img":false}]}
{"op":"mcm","clk":"11450023289","pt":1717317190217,"mc":[{"id":"1.229554896","rc":[{"atb":[[1.01,6174.97],[1.05,103.08]],"id":63161712},{"atl":[[2.72,0],[5.1,99.52]],"id":63161712},{"atb":[[2.72,0],[2.48,54.35]],"id":58069703},{"atl":[[36,13.63],[26,0]],"id":58069703},{"atb":[[3.7,38.01],[4.2,0]],"id":50605162},{"atl":[[46,0],[95,4.88]],"id":50605162},{"atb":[[1.06,350.37],[1.09,0]],"id":65732558},{"atl":[[4.8,87.9],[3.9,0]],"id":65732558},{"atb":[[1.81,91.22],[1.93,0]],"id":61028210},{"atl":[[16,0],[21,21.4]],"id":61028210}],"con":true,"img":false}]}
{"op":"mcm","clk":"11450023297","pt":1717317190269,"mc":[{"id":"1.229554896","rc":[{"atb":[[1.04,0]],"id":63161712}],"con":true,"img":false}]}
{"op":"mcm","clk":"11450023313","pt":1717317190475,"mc":[{"id":"1.229554896","rc":[{"atb":[[1.01,6424.97],[1.03,250]],"id":63161712},{"atb":[[3.6,17.8],[3.7,0],[3.8,10],[3.5,0]],"id":58069703},{"atl":[[10,0],[11,2]],"id":58069703},{"atb":[[1.09,222.22]],"id":65732558}],"con":true,"img":false}]}
{"op":"mcm","clk":"11450023321","pt":1717317190584,"mc":[{"id":"1.229554896","rc":[{"atl":[[1.56,0]],"id":63161712},{"atl":[[19.5,5.66]],"id":50605162}],"con":true,"img":false}]}
{"op":"mcm","clk":"11450023329","pt":1717317190683,"mc":[{"id":"1.229554896","rc":[{"atl":[[1.6,291.67],[1.58,34.48]],"id":63161712},{"atl":[[19.5,10.42],[22,0]],"id":50605162}],"con":true,"img":false}]}
{"op":"mcm","clk":"11450023577","pt":1717317193016,"mc":[{"id":"1.229554896","rc":[{"atl":[[1.54,0]],"id":63161712}],"con":true,"img":false}]}
{"op":"mcm","clk":"11450023588","pt":1717317193110,"mc":[{"id":"1.229554896","rc":[{"atl":[[1.56,141.1]],"id":63161712}],"con":true,"img":false}]}
{"op":"mcm","clk":"11450023597","pt":1717317193214,"mc":[{"id":"1.229554896","rc":[{"atl":[[1.56,0],[1.6,125],[1.76,131.58]],"id":63161712}],"con":true,"img":false}]}
{"op":"mcm","clk":"11450023621","pt":1717317193432,"mc":[{"id":"1.229554896","rc":[{"atb":[[1.03,0]],"id":63161712},{"atl":[[1.6,291.67],[1.58,172.41],[1.76,0]],"id":63161712},{"atb":[[3.6,46.65],[3.7,18.52],[3.8,17.14],[3.5,50]],"id":58069703},{"atl":[[10,2.22],[11,0]],"id":58069703},{"atb":[[1.09,0]],"id":65732558}],"con":true,"img":false}]}
{"op":"mcm","clk":"11450023854","pt":1717317195704,"mc":[{"id":"1.229554896","rc":[{"atb":[[1.03,250]],"id":63161712},{"atb":[[3.6,17.8],[3.7,0],[3.8,10],[3.5,0]],"id":58069703},{"atl":[[10,0],[11,2]],"id":58069703},{"atb":[[1.09,222.22]],"id":65732558}],"con":true,"img":false}]}
{"op":"mcm","clk":"11450024122","pt":1717317198500,"mc":[{"id":"1.229554896","rc":[{"atl":[[1.6,125],[1.76,131.58]],"id":63161712}],"con":true,"img":false}]}
{"op":"mcm","clk":"11450024163","pt":1717317198909,"mc":[{"id":"1.229554896","rc":[{"atb":[[1.03,0]],"id":63161712},{"atb":[[1.09,0]],"id":65732558},{"atl":[[5.6,15.92],[5.2,4.76]],"id":61028210}],"con":true,"img":false}]}
{"op":"mcm","clk":"11450024176","pt":1717317199014,"mc":[{"id":"1.229554896","rc":[{"atl":[[5.5,16.77]],"id":61028210}],"con":true,"img":false}]}
{"op":"mcm","clk":"11450024188","pt":1717317199117,"mc":[{"id":"1.229554896","rc":[{"atl":[[5.6,0]],"id":61028210}],"con":true,"img":false}]}
{"op":"mcm","clk":"11450024284","pt":1717317200101,"mc":[{"id":"1.229554896","rc":[{"atb":[[3.6,0]],"id":58069703}],"con":true,"img":false}]}
{"op":"mcm","clk":"11450024295","pt":1717317200204,"mc":[{"id":"1.229554896","rc":[{"atb":[[3.75,17.8]],"id":58069703}],"con":true,"img":false}]}
{"op":"mcm","clk":"11450024360","pt":1717317201029,"mc":[{"id":"1.229554896","rc":[{"atb":[[1.03,250]],"id":63161712},{"atl":[[1.54,37.04]],"id":63161712},{"atb":[[1.09,222.22]],"id":65732558},{"atl":[[5.6,4.35],[5.2,0]],"id":61028210}],"con":true,"img":false}]}
{"op":"mcm","clk":"11450024401","pt":1717317201500,"mc":[{"id":"1.229554896","rc":[{"atb":[[1.09,0]],"id":65732558},{"atl":[[5.2,4.76]],"id":61028210}],"con":true,"img":false}]}
{"op":"mcm","clk":"11450024416","pt":1717317201607,"mc":[{"id":"1.229554896","rc":[{"atb":[[1.03,0]],"id":63161712},{"atl":[[1.54,0]],"id":63161712},{"atl":[[5.6,0]],"id":61028210}],"con":true,"img":false}]}
{"op":"mcm","clk":"11450024424","pt":1717317201709,"mc":[{"id":"1.229554896","rc":[{"atb":[[1.01,6174.97]],"id":63161712},{"atb":[[1.03,0]],"id":65732558},{"atl":[[6.4,0],[5.2,0]],"id":61028210}],"con":true,"img":false}]}
{"op":"mcm","clk":"11450024447","pt":1717317201913,"mc":[{"id":"1.229554896","rc":[{"atb":[[1.01,6424.97]],"id":63161712},{"atl":[[1.54,37.04]],"id":63161712},{"atl":[[5.8,0],[5.6,4.35],[6.2,3.85],[5.5,0]],"id":61028210}],"con":true,"img":false}]}
{"op":"mcm","clk":"11450024456","pt":1717317202014,"mc":[{"id":"1.229554896","rc":[{"atl":[[5.7,17.02]],"id":61028210}],"con":true,"img":false}]}
{"op":"mcm","clk":"11450024475","pt":1717317202221,"mc":[{"id":"1.229554896","rc":[{"atl":[[5.6,0]],"id":61028210}],"con":true,"img":false}]}
{"op":"mcm","clk":"11450024485","pt":1717317202327,"mc":[{"id":"1.229554896","rc":[{"atb":[[1.01,6174.97]],"id":63161712}],"con":true,"img":false}]}
{"op":"mcm","clk":"11450024521","pt":1717317202741,"mc":[{"id":"1.229554896","rc":[{"atb":[[1.01,6424.97]],"id":63161712},{"atl":[[6,0]],"id":61028210}],"con":true,"img":false}]}
{"op":"mcm","clk":"11450024532","pt":1717317202796,"mc":[{"id":"1.229554896","rc":[{"atl":[[5.7,0]],"id":61028210}],"con":true,"img":false}]}
{"op":"mcm","clk":"11450024544","pt":1717317202899,"mc":[{"id":"1.229554896","rc":[{"atl":[[5.8,16.67]],"id":61028210}],"con":true,"img":false}]}
{"op":"mcm","clk":"11450024697","pt":1717317204202,"mc":[{"id":"1.229554896","rc":[{"atl":[[1.6,291.67]],"id":63161712}],"con":true,"img":false}]}
{"op":"mcm","clk":"11450024711","pt":1717317204305,"mc":[{"id":"1.229554896","rc":[{"atl":[[1.76,0]],"id":63161712}],"con":true,"img":false}]}
{"op":"mcm","clk":"11450024846","pt":1717317205493,"mc":[{"id":"1.229554896","rc":[{"atl":[[1.54,178.14]],"id":63161712}],"con":true,"img":false}]}
{"op":"mcm","clk":"11450024858","pt":1717317205602,"mc":[{"id":"1.229554896","rc":[{"atl":[[1.58,34.48]],"id":63161712}],"con":true,"img":false}]}
{"op":"mcm","clk":"11450024889","pt":1717317205913,"mc":[{"id":"1.229554896","rc":[{"atb":[[1.05,0]],"id":63161712},{"atb":[[3.75,0]],"id":58069703}],"con":true,"img":false}]}
{"op":"mcm","clk":"11450024913","pt":1717317206110,"mc":[{"id":"1.229554896","rc":[{"atb":[[1.03,103.08]],"id":63161712},{"atb":[[3.65,17.8]],"id":58069703}],"con":true,"img":false}]}
{"op":"mcm","clk":"11450024939","pt":1717317206422,"mc":[{"id":"1.229554896","rc":[{"atb":[[1.03,353.08]],"id":63161712},{"atl":[[1.54,141.1]],"id":63161712},{"atb":[[1.03,250],[1.09,222.22],[1.07,250],[1.05,250]],"id":65732558},{"atl":[[5.6,4.35],[5.2,4.76]],"id":61028210}],"con":true,"img":false}]}
{"op":"mcm","clk":"11450024958","pt":1717317206629,"mc":[{"id":"1.229554896","rc":[{"atl":[[1.54,0]],"id":63161712}],"con":true,"img":false}]}
{"op":"mcm","clk":"11450024969","pt":1717317206731,"mc":[{"id":"1.229554896","rc":[{"atl":[[1.56,142.86],[1.6,125],[1.76,131.58]],"id":63161712}],"con":true,"img":false}]}
{"op":"mcm","clk":"11450024977","pt":1717317206789,"mc":[{"id":"1.229554896","rc":[{"atl":[[1.56,0],[1.6,193.96],[1.76,0]],"id":63161712}],"con":true,"img":false}]}
{"op":"mcm","clk":"11450024988","pt":1717317206894,"mc":[{"id":"1.229554896","rc":[{"atl":[[1.58,172.41],[1.76,131.58]],"id":63161712}],"con":true,"img":false}]}
{"op":"mcm","clk":"11450024999","pt":1717317207001,"mc":[{"id":"1.229554896","rc":[{"atl":[[1.6,125]],"id":63161712}],"con":true,"img":false}]}
{"op":"mcm","clk":"11450025782","pt":1717317215034,"mc":[{"id":"1.229554896","rc":[{"atl":[[1.54,37.04]],"id":63161712},{"atl":[[5.8,27.09],[5.2,0]],"id":61028210}],"con":true,"img":false}]}
{"op":"mcm","clk":"11450025788","pt":1717317215136,"mc":[{"id":"1.229554896","rc":[{"atb":[[1.03,103.08]],"id":63161712},{"atl":[[1.53,125],[1.76,0]],"id":63161712},{"atb":[[1.09,0],[1.07,0],[1.05,0]],"id":65732558},{"atl":[[5.5,16.77]],"id":61028210}],"con":true,"img":false}]}
{"op":"mcm","clk":"11450025798","pt":1717317215195,"mc":[{"id":"1.229554896","rc":[{"atl":[[1.58,334.45],[1.53,0]],"id":63161712}],"con":true,"img":false}]}
{"op":"mcm","clk":"11450025808","pt":1717317215297,"mc":[{"id":"1.229554896","rc":[{"atl":[[5.8,10.41]],"id":61028210}],"con":true,"img":false}]}
{"op":"mcm","clk":"11450026084","pt":1717317217728,"mc":[{"id":"1.229554896","rc":[{"atl":[[1.55,91.56]],"id":63161712}],"con":true,"img":false}]}
{"op":"mcm","clk":"11450026091","pt":1717317217830,"mc":[{"id":"1.229554896","rc":[{"atb":[[1.01,6174.97]],"id":63161712},{"atl":[[1.58,196.52]],"id":63161712},{"atb":[[1.03,0]],"id":65732558}],"con":true,"img":false}]}
{"op":"mcm","clk":"11450026104","pt":1717317217940,"mc":[{"id":"1.229554896","rc":[{"atl":[[5.6,0]],"id":61028210}],"con":true,"img":false}]}
{"op":"mcm","clk":"11450026127","pt":1717317218094,"mc":[{"id":"1.229554896","rc":[{"atl":[[5.5,0]],"id":61028210}],"con":true,"img":false}]}
{"op":"mcm","clk":"11450026138","pt":1717317218196,"mc":[{"id":"1.229554896","rc":[{"atl":[[5.7,16.77]],"id":61028210}],"con":true,"img":false}]}
{"op":"mcm","clk":"11450026222","pt":1717317218929,"mc":[{"id":"1.229554896","rc":[{"atl":[[1.54,169.49]],"id":63161712}],"con":true,"img":false}]}
{"op":"mcm","clk":"11450026236","pt":1717317219029,"mc":[{"id":"1.229554896","rc":[{"atl":[[1.55,0]],"id":63161712}],"con":true,"img":false}]}
{"op":"mcm","clk":"11450026344","pt":1717317220120,"mc":[{"id":"1.229554896","rc":[{"atl":[[14,3.21]],"id":61028210}],"con":true,"img":false}]}
{"op":"mcm","clk":"11450026359","pt":1717317220224,"mc":[{"id":"1.229554896","rc":[{"atb":[[3.65,0]],"id":58069703},{"atl":[[40,1.28]],"id":50605162},{"atl":[[9.6,0]],"id":61028210}],"con":true,"img":false}]}
{"op":"mcm","clk":"11450026372","pt":1717317220327,"mc":[{"id":"1.229554896","rc":[{"atl":[[1.56,35.71],[1.54,132.45]],"id":63161712},{"atb":[[3.6,17.8]],"id":58069703},{"atl":[[11,0],[13.5,1.6],[14.5,10],[16.5,6.45]],"id":58069703},{"atb":[[4.6,8.92],[3.35,0],[2.68,59.52]],"id":50605162},{"atl":[[34,0],[27,2.61]],"id":50605162},{"atb":[[2.82,5],[2.26,0],[2.9,2.5],[2.74,10],[2.42,70.42],[2.66,0],[3.15,27.57]],"id":61028210},{"atl":[[5.6,4.35],[5.8,0]],"id":61028210}],"con":true,"img":false}]}
{"op":"mcm","clk":"11450026379","pt":1717317220433,"mc":[{"id":"1.229554896","rc":[{"atb":[[1.01,6424.97]],"id":63161712},{"atb":[[2.96,0]],"id":61028210}],"con":true,"img":false}]}
{"op":"mcm","clk":"11450026389","pt":1717317220530,"mc":[{"id":"1.229554896","rc":[{"atl":[[1.54,0]],"id":63161712},{"atl":[[10.5,0]],"id":58069703}],"con":true,"img":false}]}
{"op":"mcm","clk":"11450026403","pt":1717317220643,"mc":[{"id":"1.229554896","rc":[{"atl":[[1.56,126.27]],"id":63161712},{"atl":[[12,11.82]],"id":58069703}],"con":true,"img":false}]}
{"op":"mcm","clk":"11450026409","pt":1717317220738,"mc":[{"id":"1.229554896","rc":[{"atb":[[1.01,6174.97]],"id":63161712}],"con":true,"img":false}]}
{"op":"mcm","clk":"11450026421","pt":1717317220845,"mc":[{"id":"1.229554896","rc":[{"atl":[[1.6,291.67],[1.58,34.48]],"id":63161712}],"con":true,"img":false}]}
{"op":"mcm","clk":"11450026466","pt":1717317221212,"mc":[{"id":"1.229554896","rc":[{"atb":[[1.02,18.94]],"id":63161712},{"atl":[[1.55,36.36]],"id":63161712},{"atl":[[12,7.27]],"id":58069703},{"atb":[[1.19,0],[1.13,350.37]],"id":65732558},{"atl":[[9.2,10],[7.8,0]],"id":61028210}],"con":true,"img":false}]}
{"op":"mcm","clk":"11450026473","pt":1717317221317,"mc":[{"id":"1.229554896","rc":[{"atl":[[1.6,125],[1.58,206.89]],"id":63161712},{"atl":[[5.6,0]],"id":61028210}],"con":true,"img":false}]}
{"op":"mcm","clk":"11450026484","pt":1717317221442,"mc":[{"id":"1.229554896","rc":[{"atl":[[13,0]],"id":58069703},{"atl":[[5.6,4.36]],"id":61028210}],"con":true,"img":false}]}
{"op":"mcm","clk":"11450026500","pt":1717317221531,"mc":[{"id":"1.229554896","rc":[{"atb":[[1.01,6424.97]],"id":63161712},{"atl":[[5.6,20.21],[5.7,0]],"id":61028210}],"con":true,"img":false}]}
{"op":"mcm","clk":"11450026505","pt":1717317221626,"mc":[{"id":"1.229554896","rc":[{"atl":[[1.56,90.56],[1.6,0],[1.55,0],[1.58,172.41]],"id":63161712},{"atl":[[11.5,1.9]],"id":58069703},{"atl":[[3.1,0],[2.98,10.1]],"id":65732558},{"atl":[[5.6,24.56]],"id":61028210}],"con":true,"img":false}]}
{"op":"mcm","clk":"11450026524","pt":1717317221833,"mc":[{"id":"1.229554896","rc":[{"atl":[[1.56,0]],"id":63161712}],"con":true,"img":false}]}
{"op":"mcm","clk":"11450026532","pt":1717317221937,"mc":[{"id":"1.229554896","rc":[{"atl":[[1.58,239.94]],"id":63161712}],"con":true,"img":false}]}
{"op":"mcm","clk":"11450026545","pt":1717317222038,"mc":[{"id":"1.229554896","rc":[{"atl":[[2,50],[1.98,20.41],[2.04,72.12],[2.08,115.74]],"id":63161712},{"atl":[[5.6,20.21]],"id":61028210}],"con":true,"img":false}]}
{"op":"mcm","clk":"11450026568","pt":1717317222247,"mc":[{"id":"1.229554896","rc":[{"atl":[[5.6,15.85]],"id":61028210}],"con":true,"img":false}]}
{"op":"mcm","clk":"11450026576","pt":1717317222348,"mc":[{"id":"1.229554896","rc":[{"atb":[[1.01,6174.97]],"id":63161712},{"atl":[[5.6,4.35]],"id":61028210}],"con":true,"img":false}]}
{"op":"mcm","clk":"11450026588","pt":1717317222402,"mc":[{"id":"1.229554896","rc":[{"atl":[[5.9,6.15]],"id":61028210}],"con":true,"img":false}]}
{"op":"mcm","clk":"11450026675","pt":1717317223228,"mc":[{"id":"1.229554896","rc":[{"atl":[[5.6,9.4]],"id":61028210}],"con":true,"img":false}]}
{"op":"mcm","clk":"11450026945","pt":1717317225823,"mc":[{"id":"1.229554896","rc":[{"atl":[[15,7.14]],"id":58069703}],"con":true,"img":false}]}
{"op":"mcm","clk":"11450026954","pt":1717317225925,"mc":[{"id":"1.229554896","rc":[{"atl":[[16.5,0]],"id":58069703}],"con":true,"img":false}]}
{"op":"mcm","clk":"11450027002","pt":1717317226438,"mc":[{"id":"1.229554896","rc":[{"atl":[[1.82,126.95]],"id":63161712}],"con":true,"img":false}]}
{"op":"mcm","clk":"11450027012","pt":1717317226538,"mc":[{"id":"1.229554896","rc":[{"atl":[[1.58,67.53]],"id":63161712}],"con":true,"img":false}]}
{"op":"mcm","clk":"11450027032","pt":1717317226745,"mc":[{"id":"1.229554896","rc":[{"atl":[[1.58,0]],"id":63161712}],"con":true,"img":false}]}
{"op":"mcm","clk":"11450027041","pt":1717317226848,"mc":[{"id":"1.229554896","rc":[{"atl":[[1.79,67.53]],"id":63161712}],"con":true,"img":false}]}
{"op":"mcm","clk":"11450027053","pt":1717317226905,"mc":[{"id":"1.229554896","rc":[{"atl":[[1.78,70.03]],"id":63161712}],"con":true,"img":false}]}
{"op":"mcm","clk":"11450027060","pt":1717317227012,"mc":[{"id":"1.229554896","rc":[{"atl":[[1.82,5]],"id":63161712}],"con":true,"img":false}]}
{"op":"mcm","clk":"11450027070","pt":1717317227109,"mc":[{"id":"1.229554896","rc":[{"atl":[[5.6,21.06]],"id":61028210}],"con":true,"img":false}]}
{"op":"mcm","clk":"11450027080","pt":1717317227214,"mc":[{"id":"1.229554896","rc":[{"atl":[[5.9,0]],"id":61028210}],"con":true,"img":false}]}
{"op":"mcm","clk":"11450027095","pt":1717317227420,"mc":[{"id":"1.229554896","rc":[{"atl":[[5.6,16.01]],"id":61028210}],"con":true,"img":false}]}
{"op":"mcm","clk":"11450027126","pt":1717317227726,"mc":[{"id":"1.229554896","rc":[{"atl":[[11.5,0]],"id":58069703},{"atl":[[5.6,11.66]],"id":61028210}],"con":true,"img":false}]}
{"op":"mcm","clk":"11450027144","pt":1717317227955,"mc":[{"id":"1.229554896","rc":[{"atl":[[5.6,0]],"id":61028210}],"con":true,"img":false}]}
{"op":"mcm","clk":"11450027152","pt":1717317228036,"mc":[{"id":"1.229554896","rc":[{"atl":[[5.8,11.63]],"id":61028210}],"con":true,"img":false}]}
{"op":"mcm","clk":"11450027164","pt":1717317228139,"mc":[{"id":"1.229554896","rc":[{"atb":[[1.01,6424.97]],"id":63161712}],"con":true,"img":false}]}
{"op":"mcm","clk":"11450027176","pt":1717317228242,"mc":[{"id":"1.229554896","rc":[{"atl":[[5.8,5.11]],"id":61028210}],"con":true,"img":false}]}
{"op":"mcm","clk":"11450027182","pt":1717317228341,"mc":[{"id":"1.229554896","rc":[{"atl":[[6,11.61]],"id":61028210}],"con":true,"img":false}]}
{"op":"mcm","clk":"11450027309","pt":1717317229641,"mc":[{"id":"1.229554896","rc":[{"atl":[[1.78,172.59]],"id":63161712}],"con":true,"img":false}]}
{"op":"mcm","clk":"11450027337","pt":1717317229849,"mc":[{"id":"1.229554896","rc":[{"atl":[[1.79,0]],"id":63161712}],"con":true,"img":false}]}
{"op":"mcm","clk":"11450027348","pt":1717317229954,"mc":[{"id":"1.229554896","rc":[{"atl":[[11.5,1.9]],"id":58069703},{"atl":[[3.05,24.39]],"id":65732558}],"con":true,"img":false}]}
{"op":"mcm","clk":"11450027368","pt":1717317230153,"mc":[{"id":"1.229554896","rc":[{"atl":[[5.7,12.54]],"id":61028210}],"con":true,"img":false}]}
{"op":"mcm","clk":"11450027377","pt":1717317230210,"mc":[{"id":"1.229554896","rc":[{"atl":[[6,0]],"id":61028210}],"con":true,"img":false}]}
{"op":"mcm","clk":"11450027420","pt":1717317230623,"mc":[{"id":"1.229554896","rc":[{"atl":[[5.6,4.35]],"id":61028210}],"con":true,"img":false}]}
{"op":"mcm","clk":"11450027441","pt":1717317230829,"mc":[{"id":"1.229554896","rc":[{"atl":[[5.8,0]],"id":61028210}],"con":true,"img":false}]}
{"op":"mcm","clk":"11450027478","pt":1717317231141,"mc":[{"id":"1.229554896","rc":[{"atb":[[1.01,6174.97]],"id":63161712},{"atl":[[3.3,0],[3.2,0],[3.4,0]],"id":65732558}],"con":true,"img":false}]}
{"op":"mcm","clk":"11450027538","pt":1717317231753,"mc":[{"id":"1.229554896","rc":[{"atl":[[5.6,9.15]],"id":61028210}],"con":true,"img":false}]}
{"op":"mcm","clk":"11450027582","pt":1717317232125,"mc":[{"id":"1.229554896","rc":[{"atl":[[1.82,126.95],[1.78,105.06]],"id":63161712}],"con":true,"img":false}]}
{"op":"mcm","clk":"11450027632","pt":1717317232637,"mc":[{"id":"1.229554896","rc":[{"atl":[[11.5,9.52]],"id":58069703}],"con":true,"img":false}]}
{"op":"mcm","clk":"11450027655","pt":1717317232843,"mc":[{"id":"1.229554896","rc":[{"atl":[[12,0]],"id":58069703}],"con":true,"img":false}]}
{"op":"mcm","clk":"11450027713","pt":1717317233461,"mc":[{"id":"1.229554896","rc":[{"atl":[[5.6,25.43]],"id":61028210}],"con":true,"img":false}]}
{"op":"mcm","clk":"11450027742","pt":1717317233675,"mc":[{"id":"1.229554896","rc":[{"atl":[[5.7,0]],"id":61028210}],"con":true,"img":false}]}
{"op":"mcm","clk":"11450027881","pt":1717317234921,"mc":[{"id":"1.229554896","rc":[{"atb":[[6.2,0],[8.2,0]],"id":50605162}],"con":true,"img":false}]}
{"op":"mcm","clk":"11450027897","pt":1717317235132,"mc":[{"id":"1.229554896","rc":[{"atl":[[11.5,7.62]],"id":58069703},{"atb":[[3.2,5],[3.4,2.5],[3,10]],"id":50605162},{"atl":[[5.6,16.27]],"id":61028210}],"con":true,"img":false}]}
{"op":"mcm","clk":"11450027905","pt":1717317235234,"mc":[{"id":"1.229554896","rc":[{"atl":[[11.5,0]],"id":58069703},{"atl":[[5.6,0]],"id":61028210}],"con":true,"img":false}]}
{"op":"mcm","clk":"11450027917","pt":1717317235339,"mc":[{"id":"1.229554896","rc":[{"atl":[[12.5,11.96]],"id":58069703},{"atl":[[5.8,15.09]],"id":61028210}],"con":true,"img":false}]}
{"op":"mcm","clk":"11450027940","pt":1717317235547,"mc":[{"id":"1.229554896","rc":[{"atl":[[5.8,0]],"id":61028210}],"con":true,"img":false}]}
{"op":"mcm","clk":"11450027950","pt":1717317235651,"mc":[{"id":"1.229554896","rc":[{"atl":[[6.4,4.76]],"id":61028210}],"con":true,"img":false}]}
{"op":"mcm","clk":"11450027997","pt":1717317236169,"mc":[{"id":"1.229554896","rc":[{"atl":[[1.99,41.85]],"id":63161712},{"atl":[[6.2,8.69]],"id":61028210}],"con":true,"img":false}]}
{"op":"mcm","clk":"11450028011","pt":1717317236272,"mc":[{"id":"1.229554896","rc":[{"atl":[[2.26,0.41]],"id":63161712}],"con":true,"img":false}]}
{"op":"mcm","clk":"11450028047","pt":1717317236635,"mc":[{"id":"1.229554896","rc":[{"atl":[[18,5.88],[15,0]],"id":58069703}],"con":true,"img":false}]}
{"op":"mcm","clk":"11450028106","pt":1717317237260,"mc":[{"id":"1.229554896","rc":[{"atl":[[1.82,5],[1.86,126.28]],"id":63161712}],"con":true,"img":false}]}
{"op":"mcm","clk":"11450028170","pt":1717317238052,"mc":[{"id":"1.229554896","rc":[{"atl":[[14.5,13.7]],"id":58069703},{"atl":[[3.15,34.88]],"id":65732558}],"con":true,"img":false}]}
{"op":"mcm","clk":"11450028221","pt":1717317238773,"mc":[{"id":"1.229554896","rc":[{"atl":[[6.6,8.93]],"id":61028210}],"con":true,"img":false}]}
{"op":"mcm","clk":"11450028236","pt":1717317238978,"mc":[{"id":"1.229554896","rc":[{"atl":[[6,13.21]],"id":61028210}],"con":true,"img":false}]}
{"op":"mcm","clk":"11450028251","pt":1717317239136,"mc":[{"id":"1.229554896","rc":[{"atl":[[6.4,0]],"id":61028210}],"con":true,"img":false}]}
{"op":"mcm","clk":"11450028298","pt":1717317239760,"mc":[{"id":"1.229554896","rc":[{"atl":[[6.2,8.1]],"id":61028210}],"con":true,"img":false}]}
{"op":"mcm","clk":"11450028319","pt":1717317239968,"mc":[{"id":"1.229554896","rc":[{"atl":[[6.2,3.85]],"id":61028210}],"con":true,"img":false}]}
{"op":"mcm","clk":"11450028330","pt":1717317240021,"mc":[{"id":"1.229554896","rc":[{"atl":[[6,17.46]],"id":61028210}],"con":true,"img":false}]}
{"op":"mcm","clk":"11450028961","pt":1717317246149,"mc":[{"id":"1.229554896","rc":[{"spn":1.44,"spf":"NaN","id":63161712},{"atl":[[15.5,5.17]],"id":58069703},{"spn":8.45,"spf":"NaN","id":58069703},{"spn":12.05,"spf":"NaN","id":50605162},{"atl":[[3.25,79.07]],"id":65732558},{"spn":4.57,"spf":"NaN","id":61028210}],"con":true,"img":false}]}
{"op":"mcm","clk":"11450029022","pt":1717317246874,"mc":[{"id":"1.229554896","rc":[{"atl":[[7,12.5]],"id":61028210}],"con":true,"img":false}]}
{"op":"mcm","clk":"11450029119","pt":1717317247863,"mc":[{"id":"1.229554896","rc":[{"atb":[[2.28,0]],"id":61028210}],"con":true,"img":false}]}
{"op":"mcm","clk":"11450029129","pt":1717317247963,"mc":[{"id":"1.229554896","rc":[{"atb":[[2.44,32.69]],"id":61028210}],"con":true,"img":false}]}
{"op":"mcm","clk":"11450029786","pt":1717317254745,"mc":[{"id":"1.229554896","rc":[{"atl":[[7.4,19.53]],"id":61028210}],"con":true,"img":false}]}
{"op":"mcm","clk":"11450030267","pt":1717317259572,"mc":[{"id":"1.229554896","rc":[{"atb":[[7.8,3.41],[5.9,7.1]],"id":50605162}],"con":true,"img":false}]}
{"op":"mcm","clk":"11450030281","pt":1717317259671,"mc":[{"id":"1.229554896","rc":[{"atb":[[3.45,30.61],[3.35,53.19],[3.55,33.27],[3.65,7.55]],"id":58069703}],"con":true,"img":false}]}
{"op":"mcm","clk":"11450030314","pt":1717317259982,"mc":[{"id":"1.229554896","rc":[{"atl":[[1.82,126.95],[1.86,10]],"id":63161712},{"atl":[[18,0],[15,7.14]],"id":58069703}],"con":true,"img":false}]}
{"op":"mcm","clk":"11450030349","pt":1717317260240,"mc":[{"id":"1.229554896","rc":[{"atl":[[3.25,55.56]],"id":65732558}],"con":true,"img":false}]}
{"op":"mcm","clk":"11450030358","pt":1717317260345,"mc":[{"id":"1.229554896","rc":[{"atl":[[3.1,23.51]],"id":65732558}],"con":true,"img":false}]}
{"op":"mcm","clk":"11450030370","pt":1717317260448,"mc":[{"id":"1.229554896","rc":[{"atb":[[1.01,6424.97],[1.03,353.08]],"id":63161712},{"atb":[[1.02,250],[1.06,600.37],[1.08,250],[1.04,250]],"id":65732558}],"con":true,"img":false}]}
{"op":"mcm","clk":"11450030690","pt":1717317263247,"mc":[{"id":"1.229554896","rc":[{"atb":[[1.01,6174.97],[1.03,103.08]],"id":63161712},{"atb":[[1.02,0],[1.06,350.37],[1.08,0],[1.04,0]],"id":65732558}],"con":true,"img":false}]}
{"op":"mcm","clk":"11450030707","pt":1717317263450,"mc":[{"id":"1.229554896","rc":[{"atb":[[1.01,6424.97],[1.03,353.08]],"id":63161712},{"atb":[[1.02,250],[1.06,600.37],[1.08,250],[1.04,250]],"id":65732558}],"con":true,"img":false}]}
{"op":"mcm","clk":"11450030750","pt":1717317263976,"mc":[{"id":"1.229554896","rc":[{"atl":[[11.5,1.9],[13.5,0]],"id":58069703},{"atl":[[22,1]],"id":50605162},{"atl":[[5.3,4.65],[6.2,0]],"id":61028210}],"con":true,"img":false}]}
{"op":"mcm","clk":"11450030759","pt":1717317264072,"mc":[{"id":"1.229554896","rc":[{"atl":[[12,7.27]],"id":58069703},{"atl":[[5.4,18.18]],"id":61028210}],"con":true,"img":false}]}
{"op":"mcm","clk":"11450030768","pt":1717317264183,"mc":[{"id":"1.229554896","rc":[{"atl":[[12.5,5]],"id":58069703},{"atl":[[6,4.25]],"id":61028210}],"con":true,"img":false}]}
{"op":"mcm","clk":"11450030815","pt":1717317264746,"mc":[{"id":"1.229554896","rc":[{"atb":[[1.02,0],[1.06,350.37],[1.08,0],[1.04,0]],"id":65732558}],"con":true,"img":false}]}
{"op":"mcm","clk":"11450030821","pt":1717317264853,"mc":[{"id":"1.229554896","rc":[{"atb":[[1.01,6174.97],[1.03,103.08]],"id":63161712},{"atl":[[6,0]],"id":61028210}],"con":true,"img":false}]}
{"op":"mcm","clk":"11450030837","pt":1717317264954,"mc":[{"id":"1.229554896","rc":[{"atl":[[11.5,0],[13.5,1.6]],"id":58069703},{"atl":[[22,0]],"id":50605162},{"atl":[[5.3,0],[6.6,3.57]],"id":61028210}],"con":true,"img":false}]}
{"op":"mcm","clk":"11450030932","pt":1717317265883,"mc":[{"id":"1.229554896","rc":[{"atb":[[1.01,6424.97],[1.03,353.08]],"id":63161712},{"atb":[[1.02,250],[1.06,600.37],[1.08,250],[1.04,250]],"id":65732558}],"con":true,"img":false}]}
{"op":"mcm","clk":"11450030956","pt":1717317266085,"mc":[{"id":"1.229554896","rc":[{"atb":[[1.02,0],[1.06,350.37],[1.08,0],[1.04,0]],"id":65732558}],"con":true,"img":false}]}
{"op":"mcm","clk":"11450031244","pt":1717317268883,"mc":[{"id":"1.229554896","rc":[{"atb":[[1.02,250],[1.06,600.37],[1.08,250],[1.04,250]],"id":65732558}],"con":true,"img":false}]}
{"op":"mcm","clk":"11450031365","pt":1717317270176,"mc":[{"id":"1.229554896","rc":[{"atb":[[3.6,0]],"id":58069703},{"atl":[[22,0]],"id":58069703},{"atl":[[9,10.23],[14,0]],"id":61028210}],"con":true,"img":false}]}
{"op":"mcm","clk":"11450031377","pt":1717317270283,"mc":[{"id":"1.229554896","rc":[{"atb":[[3.7,17.8]],"id":58069703},{"atl":[[15,10.35]],"id":58069703},{"atl":[[5.4,0]],"id":61028210}],"con":true,"img":false}]}
{"op":"mcm","clk":"11450031385","pt":1717317270383,"mc":[{"id":"1.229554896","rc":[{"atl":[[6.2,15.38]],"id":61028210}],"con":true,"img":false}]}
{"op":"mcm","clk":"11450031394","pt":1717317270490,"mc":[{"id":"1.229554896","rc":[{"atl":[[6.2,4.78]],"id":61028210}],"con":true,"img":false}]}
{"op":"mcm","clk":"11450031403","pt":1717317270590,"mc":[{"id":"1.229554896","rc":[{"atl":[[6.4,14.81]],"id":61028210}],"con":true,"img":false}]}
{"op":"mcm","clk":"11450031474","pt":1717317271272,"mc":[{"id":"1.229554896","rc":[{"atb":[[1.01,6174.97],[1.03,103.08]],"id":63161712},{"atb":[[1.02,0],[1.06,350.37],[1.08,0],[1.04,0]],"id":65732558}],"con":true,"img":false}]}
{"op":"mcm","clk":"11450031490","pt":1717317271377,"mc":[{"id":"1.229554896","rc":[{"atb":[[1.01,6424.97],[1.03,353.08]],"id":63161712},{"atb":[[1.02,250],[1.06,600.37],[1.08,250],[1.04,250]],"id":65732558}],"con":true,"img":false}]}
{"op":"mcm","clk":"11450031524","pt":1717317271687,"mc":[{"id":"1.229554896","rc":[{"atl":[[22,1]],"id":50605162}],"con":true,"img":false}]}
{"op":"mcm","clk":"11450031584","pt":1717317272302,"mc":[{"id":"1.229554896","rc":[{"atb":[[2.82,0],[2.9,0],[2.86,23.73],[2.74,0],[2.94,2.5]],"id":61028210}],"con":true,"img":false}]}
{"op":"mcm","clk":"11450031615","pt":1717317272561,"mc":[{"id":"1.229554896","rc":[{"atl":[[11.5,1.9],[13.5,0]],"id":58069703},{"atl":[[5.3,4.65]],"id":61028210}],"con":true,"img":false}]}
{"op":"mcm","clk":"11450031665","pt":1717317273077,"mc":[{"id":"1.229554896","rc":[{"atb":[[1.01,6174.97],[1.03,103.08]],"id":63161712},{"atb":[[1.02,0],[1.06,350.37],[1.08,0],[1.04,0]],"id":65732558}],"con":true,"img":false}]}
{"op":"mcm","clk":"11450031885","pt":1717317275195,"mc":[{"id":"1.229554896","rc":[{"atl":[[11.5,9.52]],"id":58069703},{"atl":[[5.3,19.34]],"id":61028210}],"con":true,"img":false}]}
{"op":"mcm","clk":"11450031896","pt":1717317275299,"mc":[{"id":"1.229554896","rc":[{"atl":[[12,0]],"id":58069703},{"atl":[[6.4,0]],"id":61028210}],"con":true,"img":false}]}
{"op":"mcm","clk":"11450031955","pt":1717317275769,"mc":[{"id":"1.229554896","rc":[{"atb":[[1.04,49.26]],"id":63161712},{"atl":[[15,7.14]],"id":58069703},{"atl":[[9,5]],"id":61028210}],"con":true,"img":false}]}
{"op":"mcm","clk":"11450031970","pt":1717317275870,"mc":[{"id":"1.229554896","rc":[{"atl":[[21,3.21]],"id":58069703},{"atl":[[9.6,5.23]],"id":61028210}],"con":true,"img":false}]}
{"op":"mcm","clk":"11450032168","pt":1717317277572,"mc":[{"id":"1.229554896","rc":[{"atl":[[11.5,7.62],[13.5,1.6]],"id":58069703},{"atl":[[22,0]],"id":50605162},{"atl":[[5.3,14.69],[6.2,8.63]],"id":61028210}],"con":true,"img":false}]}
{"op":"mcm","clk":"11450032178","pt":1717317277681,"mc":[{"id":"1.229554896","rc":[{"atl":[[11.5,0]],"id":58069703},{"atl":[[5.3,0]],"id":61028210}],"con":true,"img":false}]}
{"op":"mcm","clk":"11450032192","pt":1717317277777,"mc":[{"id":"1.229554896","rc":[{"atl":[[12.5,11.96]],"id":58069703},{"atl":[[5.5,17.49]],"id":61028210}],"con":true,"img":false}]}
{"op":"mcm","clk":"11450032203","pt":1717317277884,"mc":[{"id":"1.229554896","rc":[{"atl":[[5.5,0]],"id":61028210}],"con":true,"img":false}]}
{"op":"mcm","clk":"11450032216","pt":1717317277985,"mc":[{"id":"1.229554896","rc":[{"atl":[[6,16]],"id":61028210}],"con":true,"img":false}]}
{"op":"mcm","clk":"11450032290","pt":1717317278607,"mc":[{"id":"1.229554896","rc":[{"atl":[[6.2,8.5]],"id":61028210}],"con":true,"img":false}]}
{"op":"mcm","clk":"11450032322","pt":1717317278870,"mc":[{"id":"1.229554896","rc":[{"atl":[[6.2,3.84]],"id":61028210}],"con":true,"img":false}]}
{"op":"mcm","clk":"11450032333","pt":1717317278971,"mc":[{"id":"1.229554896","rc":[{"atl":[[6,20.65]],"id":61028210}],"con":true,"img":false}]}
{"op":"mcm","clk":"11450032342","pt":1717317279073,"mc":[{"id":"1.229554896","rc":[{"atl":[[6.2,0]],"id":61028210}],"con":true,"img":false}]}
{"op":"mcm","clk":"11450032470","pt":1717317280272,"mc":[{"id":"1.229554896","rc":[{"atb":[[1.04,0]],"id":63161712}],"con":true,"img":false}]}
{"op":"mcm","clk":"11450032817","pt":1717317283481,"mc":[{"id":"1.229554896","rc":[{"atl":[[6.2,3.85]],"id":61028210}],"con":true,"img":false}]}
{"op":"mcm","clk":"11450033337","pt":1717317288596,"mc":[{"id":"1.229554896","rc":[{"atl":[[1.82,5],[1.81,123.46]],"id":63161712}],"con":true,"img":false}]}
{"op":"mcm","clk":"11450033439","pt":1717317289576,"mc":[{"id":"1.229554896","rc":[{"atl":[[1.83,7.62]],"id":63161712}],"con":true,"img":false}]}
{"op":"mcm","clk":"11450033447","pt":1717317289686,"mc":[{"id":"1.229554896","rc":[{"atl":[[1.83,0]],"id":63161712},{"atb":[[3.55,13.66],[3.65,0]],"id":58069703}],"con":true,"img":false}]}
{"op":"mcm","clk":"11450033826","pt":1717317293612,"mc":[{"id":"1.229554896","rc":[{"atl":[[21,0]],"id":58069703}],"con":true,"img":false}]}
{"op":"mcm","clk":"11450033839","pt":1717317293719,"mc":[{"id":"1.229554896","rc":[{"atl":[[15,10.35]],"id":58069703}],"con":true,"img":false}]}
{"op":"mcm","clk":"11450033967","pt":1717317295107,"mc":[{"id":"1.229554896","rc":[{"atl":[[6.2,0]],"id":61028210}],"con":true,"img":false}]}
{"op":"mcm","clk":"11450034049","pt":1717317295990,"mc":[{"id":"1.229554896","rc":[{"atb":[[1.03,152.34]],"id":63161712}],"con":true,"img":false}]}
{"op":"mcm","clk":"11450034496","pt":1717317299920,"mc":[{"id":"1.229554896","rc":[{"atb":[[3.7,0]],"id":58069703},{"atb":[[1.06,0],[1.1,0]],"id":65732558}],"con":true,"img":false}]}
{"op":"mcm","clk":"11450034506","pt":1717317300021,"mc":[{"id":"1.229554896","rc":[{"atb":[[3.6,17.8]],"id":58069703},{"atb":[[1.03,350.37],[1.06,98.4]],"id":65732558}],"con":true,"img":false}]}
{"op":"mcm","clk":"11450034752","pt":1717317302219,"mc":[{"id":"1.229554896","rc":[{"atl":[[7,8.33]],"id":61028210}],"con":true,"img":false}]}
{"op":"mcm","clk":"11450034820","pt":1717317302843,"mc":[{"id":"1.229554896","rc":[{"atb":[[3.95,6.78]],"id":58069703}],"con":true,"img":false}]}
{"op":"mcm","clk":"11450034899","pt":1717317303418,"mc":[{"id":"1.229554896","rc":[{"atb":[[3.8,0],[4.4,10.9],[4,0],[4.5,12.83],[4.6,2.5],[4.2,5]],"id":58069703}],"con":true,"img":false}]}
{"op":"mcm","clk":"11450034907","pt":1717317303518,"mc":[{"id":"1.229554896","rc":[{"atb":[[4.4,0]],"id":58069703}],"con":true,"img":false}]}
{"op":"mcm","clk":"11450034974","pt":1717317304099,"mc":[{"id":"1.229554896","rc":[{"atl":[[13,1.67],[13.5,0]],"id":58069703}],"con":true,"img":false}]}
{"op":"mcm","clk":"11450035142","pt":1717317305620,"mc":[{"id":"1.229554896","rc":[{"atb":[[1.01,367.71]],"id":63161712},{"atl":[[2.26,0]],"id":63161712},{"atb":[[4.1,0],[3.55,0]],"id":58069703},{"atb":[[7.8,0],[5.9,0]],"id":50605162},{"atb":[[1.01,175.54]],"id":65732558},{"atl":[[2.48,23.75]],"id":65732558},{"atb":[[2.86,5],[3.15,16.77]],"id":61028210}],"con":true,"img":false}]}
{"op":"mcm","clk":"11450035152","pt":1717317305719,"mc":[{"id":"1.229554896","rc":[{"atb":[[3.15,0]],"id":61028210}],"con":true,"img":false}]}
{"op":"mcm","clk":"11450035164","pt":1717317305823,"mc":[{"id":"1.229554896","rc":[{"atb":[[3.05,6.43]],"id":61028210}],"con":true,"img":false}]}
{"op":"mcm","clk":"11450035175","pt":1717317305929,"mc":[{"id":"1.229554896","rc":[{"atl":[[1.82,126.95],[1.81,0]],"id":63161712},{"atl":[[18,5.88],[12.5,6.96],[15,3.21]],"id":58069703}],"con":true,"img":false}]}
{"op":"mcm","clk":"11450035188","pt":1717317306028,"mc":[{"id":"1.229554896","rc":[{"atb":[[3.05,0]],"id":61028210}],"con":true,"img":false}]}
{"op":"mcm","clk":"11450035203","pt":1717317306131,"mc":[{"id":"1.229554896","rc":[{"atb":[[2.96,8.57]],"id":61028210}],"con":true,"img":false}]}
{"op":"mcm","clk":"11450035404","pt":1717317307909,"mc":[{"id":"1.229554896","rc":[{"spn":8.55,"spf":"NaN","id":58069703},{"atb":[[2.64,6.17]],"id":61028210},{"spn":4.48,"spf":"NaN","id":61028210}],"con":true,"img":false}]}
{"op":"mcm","clk":"11450035542","pt":1717317309213,"mc":[{"id":"1.229554896","rc":[{"atl":[[7.4,11.72]],"id":61028210}],"con":true,"img":false}]}
{"op":"mcm","clk":"11450035668","pt":1717317310302,"mc":[{"id":"1.229554896","rc":[{"atb":[[2.64,0]],"id":61028210}],"con":true,"img":false}]}
{"op":"mcm","clk":"11450035695","pt":1717317310613,"mc":[{"id":"1.229554896","rc":[{"atl":[[1.82,5],[1.86,126.28]],"id":63161712}],"con":true,"img":false}]}
{"op":"mcm","clk":"11450035735","pt":1717317311021,"mc":[{"id":"1.229554896","rc":[{"atb":[[3.85,17.54]],"id":58069703}],"con":true,"img":false}]}
{"op":"mcm","clk":"11450036030","pt":1717317313632,"mc":[{"id":"1.229554896","rc":[{"atb":[[4.7,8.97]],"id":58069703}],"con":true,"img":false}]}
{"op":"mcm","clk":"11450036041","pt":1717317313735,"mc":[{"id":"1.229554896","rc":[{"atb":[[4.5,0],[4.7,15.25]],"id":58069703},{"atl":[[12.5,8.81]],"id":58069703}],"con":true,"img":false}]}
{"op":"mcm","clk":"11450036293","pt":1717317316014,"mc":[{"id":"1.229554896","rc":[{"atl":[[7.8,18.38]],"id":61028210}],"con":true,"img":false}]}
{"op":"mcm","clk":"11450036503","pt":1717317317831,"mc":[{"id":"1.229554896","rc":[{"atb":[[3.75,27.27]],"id":58069703}],"con":true,"img":false}]}
{"op":"mcm","clk":"11450036759","pt":1717317320107,"mc":[{"id":"1.229554896","rc":[{"atl":[[15,0]],"id":58069703}],"con":true,"img":false}]}
{"op":"mcm","clk":"11450036770","pt":1717317320215,"mc":[{"id":"1.229554896","rc":[{"atl":[[17.5,3.21]],"id":58069703}],"con":true,"img":false}]}
{"op":"mcm","clk":"11450036825","pt":1717317320732,"mc":[{"id":"1.229554896","rc":[{"atb":[[1.02,268.94]],"id":63161712},{"atb":[[3.45,0],[3.85,0],[3.95,0],[3.35,0],[3.75,0]],"id":58069703},{"atl":[[13,0],[13.5,1.6]],"id":58069703},{"atb":[[1.01,425.54],[1.03,600.37],[1.07,250],[1.05,250]],"id":65732558}],"con":true,"img":false}]}
{"op":"mcm","clk":"11450036927","pt":1717317321717,"mc":[{"id":"1.229554896","rc":[{"atb":[[2.8,10],[2.88,5],[2.86,0],[2.98,10],[2.96,11.07],[2.94,0]],"id":61028210}],"con":true,"img":false}]}
{"op":"mcm","clk":"11450036940","pt":1717317321837,"mc":[{"id":"1.229554896","rc":[{"atb":[[2.96,2.5]],"id":61028210}],"con":true,"img":false}]}
{"op":"mcm","clk":"11450036950","pt":1717317321926,"mc":[{"id":"1.229554896","rc":[{"atb":[[3.8,4.89]],"id":58069703}],"con":true,"img":false}]}
{"op":"mcm","clk":"11450037053","pt":1717317322756,"mc":[{"id":"1.229554896","rc":[{"atl":[[5.7,4.26],[6.6,0]],"id":61028210}],"con":true,"img":false}]}
{"op":"mcm","clk":"11450037064","pt":1717317322858,"mc":[{"id":"1.229554896","rc":[{"atl":[[5.9,6.43]],"id":61028210}],"con":true,"img":false}]}
{"op":"mcm","clk":"11450037076","pt":1717317322914,"mc":[{"id":"1.229554896","rc":[{"atl":[[6,20.36]],"id":61028210}],"con":true,"img":false}]}
{"op":"mcm","clk":"11450037087","pt":1717317323015,"mc":[{"id":"1.229554896","rc":[{"atl":[[6,4.36]],"id":61028210}],"con":true,"img":false}]}
{"op":"mcm","clk":"11450037098","pt":1717317323120,"mc":[{"id":"1.229554896","rc":[{"atb":[[2.98,21.9]],"id":61028210},{"atl":[[6,0]],"id":61028210}],"con":true,"img":false}]}
{"op":"mcm","clk":"11450037110","pt":1717317323224,"mc":[{"id":"1.229554896","rc":[{"atl":[[5.7,8.62]],"id":61028210}],"con":true,"img":false}]}
{"op":"mcm","clk":"11450037220","pt":1717317324252,"mc":[{"id":"1.229554896","rc":[{"atl":[[12,1.82],[13.5,0]],"id":58069703},{"atl":[[21,1]],"id":50605162}],"con":true,"img":false}]}
{"op":"mcm","clk":"11450037230","pt":1717317324358,"mc":[{"id":"1.229554896","rc":[{"atl":[[12,7.44]],"id":58069703}],"con":true,"img":false}]}
{"op":"mcm","clk":"11450037248","pt":1717317324512,"mc":[{"id":"1.229554896","rc":[{"atl":[[12.5,1.85]],"id":58069703}],"con":true,"img":false}]}
{"op":"mcm","clk":"11450037659","pt":1717317328436,"mc":[{"id":"1.229554896","rc":[{"atb":[[3.6,0]],"id":58069703}],"con":true,"img":false}]}
{"op":"mcm","clk":"11450037674","pt":1717317328543,"mc":[{"id":"1.229554896","rc":[{"atb":[[3.9,17.8]],"id":58069703}],"con":true,"img":false}]}
{"op":"mcm","clk":"11450037688","pt":1717317328754,"mc":[{"id":"1.229554896","rc":[{"atb":[[3.8,0]],"id":58069703}],"con":true,"img":false}]}
{"op":"mcm","clk":"11450037753","pt":1717317329428,"mc":[{"id":"1.229554896","rc":[{"atl":[[5.9,16.63]],"id":61028210}],"con":true,"img":false}]}
{"op":"mcm","clk":"11450037788","pt":1717317329736,"mc":[{"id":"1.229554896","rc":[{"atl":[[7.8,0]],"id":61028210}],"con":true,"img":false}]}
{"op":"mcm","clk":"11450037837","pt":1717317330149,"mc":[{"id":"1.229554896","rc":[{"atl":[[15.5,2.88],[9.6,0]],"id":61028210}],"con":true,"img":false}]}
{"op":"mcm","clk":"11450037936","pt":1717317330829,"mc":[{"id":"1.229554896","rc":[{"atl":[[23,2.27]],"id":50605162}],"con":true,"img":false}]}
{"op":"mcm","clk":"11450038163","pt":1717317332748,"mc":[{"id":"1.229554896","rc":[{"atl":[[5.6,12.71]],"id":61028210}],"con":true,"img":false}]}
{"op":"mcm","clk":"11450038186","pt":1717317332952,"mc":[{"id":"1.229554896","rc":[{"atl":[[5.9,10.2]],"id":61028210}],"con":true,"img":false}]}
{"op":"mcm","clk":"11450038194","pt":1717317333059,"mc":[{"id":"1.229554896","rc":[{"atl":[[5.7,4.26]],"id":61028210}],"con":true,"img":false}]}
{"op":"mcm","clk":"11450038360","pt":1717317334562,"mc":[{"id":"1.229554896","rc":[{"atl":[[5.6,17.19]],"id":61028210}],"con":true,"img":false}]}
{"op":"mcm","clk":"11450038452","pt":1717317335445,"mc":[{"id":"1.229554896","rc":[{"atl":[[48,0]],"id":50605162},{"atl":[[9,0],[8.2,0],[9.8,0]],"id":61028210}],"con":true,"img":false}]}
{"op":"mcm","clk":"11450038459","pt":1717317335544,"mc":[{"id":"1.229554896","rc":[{"atb":[[1.13,0],[1.07,500]],"id":65732558}],"con":true,"img":false}]}
{"op":"mcm","clk":"11450038503","pt":1717317335948,"mc":[{"id":"1.229554896","rc":[{"atl":[[19,2.5],[20,0],[22,5],[24,0],[28,0]],"id":50605162},{"atb":[[1.29,2.5],[1.17,0]],"id":65732558},{"atl":[[6.2,14.42]],"id":61028210}],"con":true,"img":false}]}
{"op":"mcm","clk":"11450038517","pt":1717317336047,"mc":[{"id":"1.229554896","rc":[{"atl":[[19,6.94]],"id":50605162},{"atb":[[1.28,17.81]],"id":65732558}],"con":true,"img":false}]}
{"op":"mcm","clk":"11450038527","pt":1717317336155,"mc":[{"id":"1.229554896","rc":[{"atb":[[3.9,0]],"id":58069703},{"atl":[[19.5,6.1]],"id":50605162},{"atb":[[1.25,2.5]],"id":65732558}],"con":true,"img":false}]}
{"op":"mcm","clk":"11450038536","pt":1717317336253,"mc":[{"id":"1.229554896","rc":[{"atb":[[3.3,17.8]],"id":58069703}],"con":true,"img":false}]}
{"op":"mcm","clk":"11450038584","pt":1717317336726,"mc":[{"id":"1.229554896","rc":[{"atl":[[11.5,1.9]],"id":58069703}],"con":true,"img":false}]}
{"op":"mcm","clk":"11450038597","pt":1717317336826,"mc":[{"id":"1.229554896","rc":[{"atl":[[11.5,7.52],[12,5.62]],"id":58069703},{"atl":[[7.4,0]],"id":61028210}],"con":true,"img":false}]}
{"op":"mcm","clk":"11450038622","pt":1717317337036,"mc":[{"id":"1.229554896","rc":[{"atl":[[12,0],[12.5,0]],"id":58069703}],"con":true,"img":false}]}
{"op":"mcm","clk":"11450038650","pt":1717317337345,"mc":[{"id":"1.229554896","rc":[{"atl":[[25,3.12]],"id":50605162}],"con":true,"img":false}]}
{"op":"mcm","clk":"11450038885","pt":1717317339367,"mc":[{"id":"1.229554896","rc":[{"atl":[[1.83,110.06],[1.98,0],[1.56,35.71],[1.86,10]],"id":63161712},{"atb":[[2.58,63.29]],"id":61028210}],"con":true,"img":false}]}
{"op":"mcm","clk":"11450038898","pt":1717317339423,"mc":[{"id":"1.229554896","rc":[{"atl":[[1.57,140.35]],"id":63161712},{"atl":[[44,0]],"id":50605162},{"atl":[[2.98,0],[3.05,0],[3.15,0]],"id":65732558},{"atb":[[2.42,0]],"id":61028210}],"con":true,"img":false}]}
{"op":"mcm","clk":"11450038907","pt":1717317339525,"mc":[{"id":"1.229554896","rc":[{"atl":[[1.78,210.12]],"id":63161712}],"con":true,"img":false}]}
{"op":"mcm","clk":"11450038917","pt":1717317339626,"mc":[{"id":"1.229554896","rc":[{"atl":[[1.83,0],[1.78,107.56]],"id":63161712}],"con":true,"img":false}]}
{"op":"mcm","clk":"11450038935","pt":1717317339831,"mc":[{"id":"1.229554896","rc":[{"atb":[[3.8,4.89]],"id":58069703}],"con":true,"img":false}]}
{"op":"mcm","clk":"11450038964","pt":1717317340142,"mc":[{"id":"1.229554896","rc":[{"atl":[[27,0]],"id":50605162}],"con":true,"img":false}]}
{"op":"mcm","clk":"11450038974","pt":1717317340244,"mc":[{"id":"1.229554896","rc":[{"atb":[[1.03,103.08]],"id":63161712},{"atl":[[46,2.61]],"id":50605162}],"con":true,"img":false}]}
{"op":"mcm","clk":"11450039059","pt":1717317341122,"mc":[{"id":"1.229554896","rc":[{"atb":[[1.02,18.94]],"id":63161712},{"atl":[[3.2,9.09]],"id":65732558}],"con":true,"img":false}]}
{"op":"mcm","clk":"11450039070","pt":1717317341225,"mc":[{"id":"1.229554896","rc":[{"atb":[[1.02,268.94]],"id":63161712},{"atl":[[1.56,0],[1.54,37.04]],"id":63161712},{"atb":[[1.01,175.54],[1.03,350.37],[1.07,250],[1.05,0]],"id":65732558}],"con":true,"img":false}]}
{"op":"mcm","clk":"11450039081","pt":1717317341330,"mc":[{"id":"1.229554896","rc":[{"atb":[[1.04,49.26]],"id":63161712},{"atl":[[1.57,247.91]],"id":63161712}],"con":true,"img":false}]}
{"op":"mcm","clk":"11450039090","pt":1717317341435,"mc":[{"id":"1.229554896","rc":[{"atl":[[1.78,2.5]],"id":63161712}],"con":true,"img":false}]}
{"op":"mcm","clk":"11450039100","pt":1717317341537,"mc":[{"id":"1.229554896","rc":[{"atl":[[1.78,130.71],[1.57,140.35]],"id":63161712}],"con":true,"img":false}]}
{"op":"mcm","clk":"11450039138","pt":1717317341846,"mc":[{"id":"1.229554896","rc":[{"atb":[[1.02,18.94]],"id":63161712},{"atl":[[1.56,35.71],[1.54,0]],"id":63161712}],"con":true,"img":false}]}
{"op":"mcm","clk":"11450039153","pt":1717317341957,"mc":[{"id":"1.229554896","rc":[{"atl":[[1.78,2.5],[1.57,271.06]],"id":63161712},{"atl":[[11.5,5.62],[13.5,1.6]],"id":58069703},{"atl":[[21,0],[23,0],[25,0]],"id":50605162},{"atl":[[5.7,0],[6.6,3.57]],"id":61028210}],"con":true,"img":false}]}
{"op":"mcm","clk":"11450039166","pt":1717317342059,"mc":[{"id":"1.229554896","rc":[{"atl":[[1.78,130.71]],"id":63161712}],"con":true,"img":false}]}
{"op":"mcm","clk":"11450039178","pt":1717317342161,"mc":[{"id":"1.229554896","rc":[{"atl":[[1.57,140.35]],"id":63161712},{"atl":[[11.5,0]],"id":58069703}],"con":true,"img":false}]}
{"op":"mcm","clk":"11450039190","pt":1717317342268,"mc":[{"id":"1.229554896","rc":[{"atb":[[1.02,268.94]],"id":63161712},{"atl":[[1.56,0],[1.54,37.04]],"id":63161712},{"atl":[[12.5,6.96],[14,12.12],[14.5,3.7]],"id":58069703},{"atb":[[1.01,425.54],[1.03,600.37],[1.07,500],[1.05,250]],"id":65732558},{"atl":[[2.56,23.75],[2.54,0],[2.38,11.25],[2.46,0],[2.48,0]],"id":65732558},{"atl":[[5.9,0]],"id":61028210}],"con":true,"img":false}]}
{"op":"mcm","clk":"11450039202","pt":1717317342370,"mc":[{"id":"1.229554896","rc":[{"atl":[[1.78,2.5],[1.57,271.06]],"id":63161712},{"atl":[[2.8,10],[2.72,5],[2.64,2.5],[3.05,35],[2.56,0]],"id":65732558}],"con":true,"img":false}]}
{"op":"mcm","clk":"11450039214","pt":1717317342422,"mc":[{"id":"1.229554896","rc":[{"atl":[[1.78,130.71],[1.57,140.35]],"id":63161712},{"atl":[[12.5,0]],"id":58069703},{"atl":[[2.38,0]],"id":65732558}],"con":true,"img":false}]}
{"op":"mcm","clk":"11450039230","pt":1717317342577,"mc":[{"id":"1.229554896","rc":[{"atl":[[13.5,8]],"id":58069703},{"atl":[[2.42,5.62]],"id":65732558}],"con":true,"img":false}]}
{"op":"mcm","clk":"11450039255","pt":1717317342737,"mc":[{"id":"1.229554896","rc":[{"spl":[[1.01,2]],"id":63161712},{"atl":[[2.42,0]],"id":65732558}],"con":true,"img":false}]}
{"op":"mcm","clk":"11450039264","pt":1717317342835,"mc":[{"id":"1.229554896","rc":[{"atl":[[2.44,5.62]],"id":65732558}],"con":true,"img":false}]}
{"op":"mcm","clk":"11450039278","pt":1717317342941,"mc":[{"id":"1.229554896","rc":[{"atl":[[5.6,16.91]],"id":61028210}],"con":true,"img":false}]}
{"op":"mcm","clk":"11450039304","pt":1717317343146,"mc":[{"id":"1.229554896","rc":[{"atl":[[5.6,12.71]],"id":61028210}],"con":true,"img":false}]}
{"op":"mcm","clk":"11450039313","pt":1717317343251,"mc":[{"id":"1.229554896","rc":[{"atl":[[5.6,0],[6,4.2]],"id":61028210}],"con":true,"img":false}]}
{"op":"mcm","clk":"11450039326","pt":1717317343353,"mc":[{"id":"1.229554896","rc":[{"atl":[[5.8,13.28]],"id":61028210}],"con":true,"img":false}]}
{"op":"mcm","clk":"11450039339","pt":1717317343456,"mc":[{"id":"1.229554896","rc":[{"atl":[[5.8,0]],"id":61028210}],"con":true,"img":false}]}
{"op":"mcm","clk":"11450039354","pt":1717317343558,"mc":[{"id":"1.229554896","rc":[{"atl":[[5.9,13.71]],"id":61028210}],"con":true,"img":false}]}
{"op":"mcm","clk":"11450039375","pt":1717317343764,"mc":[{"id":"1.229554896","rc":[{"atl":[[21,1]],"id":50605162}],"con":true,"img":false}]}
{"op":"mcm","clk":"11450039478","pt":1717317344642,"mc":[{"id":"1.229554896","rc":[{"atb":[[1.02,18.94]],"id":63161712},{"atl":[[1.56,35.71],[1.54,0]],"id":63161712},{"atb":[[1.01,175.54],[1.03,350.37],[1.07,250],[1.05,0]],"id":65732558}],"con":true,"img":false}]}
{"op":"mcm","clk":"11450039485","pt":1717317344746,"mc":[{"id":"1.229554896","rc":[{"atl":[[1.78,2.5],[1.55,130.71]],"id":63161712}],"con":true,"img":false}]}
{"op":"mcm","clk":"11450039498","pt":1717317344854,"mc":[{"id":"1.229554896","rc":[{"atl":[[1.55,0],[1.57,271.06]],"id":63161712}],"con":true,"img":false}]}
{"op":"mcm","clk":"11450039512","pt":1717317344960,"mc":[{"id":"1.229554896","rc":[{"atl":[[1.78,130.71],[1.57,140.35]],"id":63161712}],"con":true,"img":false}]}
{"op":"mcm","clk":"11450039592","pt":1717317345623,"mc":[{"id":"1.229554896","rc":[{"atl":[[1.56,0],[1.54,37.04]],"id":63161712},{"atl":[[21,0]],"id":50605162},{"atb":[[1.29,8.12]],"id":65732558},{"atl":[[6.2,0]],"id":61028210}],"con":true,"img":false}]}
{"op":"mcm","clk":"11450039600","pt":1717317345727,"mc":[{"id":"1.229554896","rc":[{"atl":[[1.78,2.5],[1.53,130.71]],"id":63161712},{"atb":[[1.28,0]],"id":65732558}],"con":true,"img":false}]}
{"op":"mcm","clk":"11450039609","pt":1717317345829,"mc":[{"id":"1.229554896","rc":[{"atl":[[1.57,308.1]],"id":63161712}],"con":true,"img":false}]}
{"op":"mcm","clk":"11450039626","pt":1717317345985,"mc":[{"id":"1.229554896","rc":[{"atl":[[1.53,0]],"id":63161712}],"con":true,"img":false}]}
{"op":"mcm","clk":"11450039797","pt":1717317347435,"mc":[{"id":"1.229554896","rc":[{"atl":[[2.72,15]],"id":65732558}],"con":true,"img":false}]}
{"op":"mcm","clk":"11450039807","pt":1717317347540,"mc":[{"id":"1.229554896","rc":[{"atl":[[3.05,0]],"id":65732558}],"con":true,"img":false}]}
{"op":"mcm","clk":"11450039839","pt":1717317347851,"mc":[{"id":"1.229554896","rc":[{"atb":[[3.45,2.5],[3.2,0],[3.4,0],[3,0],[3.25,5]],"id":50605162}],"con":true,"img":false}]}
{"op":"mcm","clk":"11450039875","pt":1717317348263,"mc":[{"id":"1.229554896","rc":[{"atl":[[7.4,11.72]],"id":61028210}],"con":true,"img":false}]}
{"op":"mcm","clk":"11450039901","pt":1717317348576,"mc":[{"id":"1.229554896","rc":[{"atl":[[3.3,21.74]],"id":65732558}],"con":true,"img":false}]}
{"op":"mcm","clk":"11450039940","pt":1717317348932,"mc":[{"id":"1.229554896","rc":[{"atl":[[1.55,64.72]],"id":63161712}],"con":true,"img":false}]}
{"op":"mcm","clk":"11450039951","pt":1717317349036,"mc":[{"id":"1.229554896","rc":[{"atl":[[1.55,138.8],[1.57,140.35]],"id":63161712}],"con":true,"img":false}]}
{"op":"mcm","clk":"11450039961","pt":1717317349141,"mc":[{"id":"1.229554896","rc":[{"atl":[[1.57,0]],"id":63161712}],"con":true,"img":false}]}
{"op":"mcm","clk":"11450040002","pt":1717317349554,"mc":[{"id":"1.229554896","rc":[{"atl":[[3.1,0]],"id":65732558}],"con":true,"img":false}]}
{"op":"mcm","clk":"11450040012","pt":1717317349657,"mc":[{"id":"1.229554896","rc":[{"atl":[[3.2,32.6]],"id":65732558}],"con":true,"img":false}]}
{"op":"mcm","clk":"11450040073","pt":1717317350237,"mc":[{"id":"1.229554896","rc":[{"atb":[[1.04,0]],"id":63161712}],"con":true,"img":false}]}
{"op":"mcm","clk":"11450040148","pt":1717317350964,"mc":[{"id":"1.229554896","rc":[{"atb":[[1.06,0]],"id":65732558}],"con":true,"img":false}]}
