{"op":"mcm","clk":"11448127648","pt":1717286034983,"mc":[{"id":"1.229554920","marketDefinition":{"bspMarket":true,"turnInPlayEnabled":false,"persistenceEnabled":false,"marketBaseRate":7.0,"eventId":"33318908","eventTypeId":"4339","numberOfWinners":1,"bettingType":"ODDS","marketType":"WIN","marketTime":"2024-06-02T10:24:00.000Z","suspendTime":"2024-06-02T10:24:00.000Z","bspReconciled":false,"complete":true,"inPlay":false,"crossMatching":true,"runnersVoidable":false,"numberOfActiveRunners":7,"betDelay":0,"status":"OPEN","runners":[{"status":"ACTIVE","sortPriority":1,"id":65460404,"name":"1. Give Me Room"},{"status":"ACTIVE","sortPriority":2,"id":52671121,"name":"2. Elegant Ritzy"},{"status":"ACTIVE","sortPriority":3,"id":62262930,"name":"3. Canya Candy"},{"status":"ACTIVE","sortPriority":4,"id":69577417,"name":"4. Alpha Bloke"},{"status":"ACTIVE","sortPriority":5,"id":69421986,"name":"6. Back to Work"},{"status":"ACTIVE","sortPriority":6,"id":64546979,"name":"7. Sheas Entity"},{"status":"ACTIVE","sortPriority":7,"id":70003371,"name":"8. Yumali"}],"regulators":["MR_INT"],"venue":"Murray Bridge","countryCode":"AU","discountAllowed":true,"timezone":"Australia/Adelaide","openDate":"2024-06-02T08:21:00.000Z","version":5962317639,"name":"R7 455m Gr6","eventName":"Murray Bridge (AUS) 2nd Jun"},"rc":[],"con":true,"img":false}]}
{"op":"mcm","clk":"11448258036","pt":1717287872067,"mc":[{"id":"1.229554920","rc":[{"atb":[[3.4,87.1],[3.15,97.23],[3.65,39.44]],"id":52671121},{"atl":[[16.5,8.99],[23,9.5]],"id":52671121},{"spn":10.07,"spf":"NaN","id":52671121},{"atb":[[3.1,49.77],[2.84,113.61],[2.94,107.76]],"id":62262930},{"atl":[[16,13.93],[11,13.93]],"id":62262930},{"spn":7.05,"spf":"NaN","id":62262930},{"atb":[[8.6,13.75],[7.6,31.67],[6.6,37.33]],"id":69577417},{"atl":[[100,1.4],[200,1.05]],"id":69577417},{"spn":54.3,"spf":"NaN","id":69577417},{"atb":[[16.5,6.74],[11.5,19.91],[14,16.08]],"id":69421986},{"atl":[[350,0.59],[250,0.55]],"id":69421986},{"spn":133.25,"spf":"NaN","id":69421986},{"atb":[[3.6,40.2],[3.1,99.55],[3.35,88.96]],"id":65460404},{"atl":[[18.5,11.94],[13.5,11.14]],"id":65460404},{"spn":8.55,"spf":"NaN","id":65460404},{"atb":[[8.6,13.75],[7.6,31.67],[6.6,37.33]],"id":64546979},{"atl":[[100,1.4],[200,1.05]],"id":64546979},{"spn":54.3,"spf":"NaN","id":64546979},{"atb":[[2.8,116.14],[2.9,55.01],[2.7,122.97]],"id":70003371},{"atl":[[10,15.48],[15,14.93]],"id":70003371},{"spn":6.45,"spf":"NaN","id":70003371}],"con":true,"img":false}]}
{"op":"mcm","clk":"11448259658","pt":1717287895503,"mc":[{"id":"1.229554920","rc":[{"atb":[[3.4,0],[3.15,0],[3.65,0]],"id":52671121},{"atl":[[16.5,0],[23,0]],"id":52671121},{"atb":[[3.1,0],[2.84,0],[2.94,0]],"id":62262930},{"atl":[[16,0],[11,0]],"id":62262930},{"atb":[[8.6,0],[7.6,0],[6.6,0]],"id":69577417},{"atl":[[100,0],[200,0]],"id":69577417},{"atb":[[16.5,0],[11.5,0],[14,0]],"id":69421986},{"atl":[[350,0],[250,0]],"id":69421986},{"atb":[[3.6,0],[3.1,0],[3.35,0]],"id":65460404},{"atl":[[18.5,0],[13.5,0]],"id":65460404},{"atb":[[8.6,0],[7.6,0],[6.6,0]],"id":64546979},{"atl":[[100,0],[200,0]],"id":64546979},{"atb":[[2.8,0],[2.9,0],[2.7,0]],"id":70003371},{"atl":[[10,0],[15,0]],"id":70003371}],"con":true,"img":false}]}
{"op":"mcm","clk":"11448260604","pt":1717287908538,"mc":[{"id":"1.229554920","rc":[{"atb":[[3.4,87.1],[3.15,97.23],[3.65,39.44]],"id":52671121},{"atl":[[16.5,8.99],[23,9.5]],"id":52671121},{"atb":[[3.1,49.77],[2.84,113.61],[2.94,107.76]],"id":62262930},{"atl":[[16,13.93],[11,13.93]],"id":62262930},{"atb":[[8.6,13.75],[7.6,31.67],[6.6,37.33]],"id":69577417},{"atl":[[100,1.4],[200,1.05]],"id":69577417},{"atb":[[16.5,6.74],[11.5,19.91],[14,16.08]],"id":69421986},{"atl":[[350,0.59],[250,0.55]],"id":69421986},{"atb":[[3.6,40.2],[3.1,99.55],[3.35,88.96]],"id":65460404},{"atl":[[18.5,11.94],[13.5,11.14]],"id":65460404},{"atb":[[8.6,13.75],[7.6,31.67],[6.6,37.33]],"id":64546979},{"atl":[[100,1.4],[200,1.05]],"id":64546979},{"atb":[[2.8,116.14],[2.9,55.01],[2.7,122.97]],"id":70003371},{"atl":[[10,15.48],[15,14.93]],"id":70003371}],"con":true,"img":false}]}
{"op":"mcm","clk":"11448264328","pt":1717287962571,"mc":[{"id":"1.229554920","rc":[{"atb":[[3.4,0],[3.15,0],[3.65,0]],"id":52671121},{"atl":[[16.5,0],[23,0]],"id":52671121},{"spn":"NaN","spf":"NaN","id":52671121},{"atb":[[3.1,0],[2.84,0],[2.94,0]],"id":62262930},{"atl":[[16,0],[11,0]],"id":62262930},{"spn":"NaN","spf":"NaN","id":62262930},{"atb":[[8.6,0],[7.6,0],[6.6,0]],"id":69577417},{"atl":[[100,0],[200,0]],"id":69577417},{"spn":"NaN","spf":"NaN","id":69577417},{"atb":[[16.5,0],[11.5,0],[14,0]],"id":69421986},{"atl":[[350,0],[250,0]],"id":69421986},{"spn":"NaN","spf":"NaN","id":69421986},{"atb":[[3.6,0],[3.1,0],[3.35,0]],"id":65460404},{"atl":[[18.5,0],[13.5,0]],"id":65460404},{"spn":"NaN","spf":"NaN","id":65460404},{"atb":[[8.6,0],[7.6,0],[6.6,0]],"id":64546979},{"atl":[[100,0],[200,0]],"id":64546979},{"spn":"NaN","spf":"NaN","id":64546979},{"atb":[[2.8,0],[2.9,0],[2.7,0]],"id":70003371},{"atl":[[10,0],[15,0]],"id":70003371},{"spn":"NaN","spf":"NaN","id":70003371}],"con":true,"img":false}]}
{"op":"mcm","clk":"11448265018","pt":1717287972318,"mc":[{"id":"1.229554920","rc":[{"atb":[[3.4,87.1],[3.15,97.23],[3.65,39.44]],"id":52671121},{"atl":[[16.5,8.99],[23,9.5]],"id":52671121},{"atb":[[3.1,49.77],[2.84,113.61],[2.94,107.76]],"id":62262930},{"atl":[[16,13.93],[11,13.93]],"id":62262930},{"atb":[[8.6,13.75],[7.6,31.67],[6.6,37.33]],"id":69577417},{"atl":[[100,1.4],[200,1.05]],"id":69577417},{"atb":[[16.5,6.74],[11.5,19.91],[14,16.08]],"id":69421986},{"atl":[[350,0.59],[250,0.55]],"id":69421986},{"atb":[[3.6,40.2],[3.1,99.55],[3.35,88.96]],"id":65460404},{"atl":[[18.5,11.94],[13.5,11.14]],"id":65460404},{"atb":[[8.6,13.75],[7.6,31.67],[6.6,37.33]],"id":64546979},{"atl":[[100,1.4],[200,1.05]],"id":64546979},{"atb":[[2.8,116.14],[2.9,55.01],[2.7,122.97]],"id":70003371},{"atl":[[10,15.48],[15,14.93]],"id":70003371}],"con":true,"img":false}]}
{"op":"mcm","clk":"11448277246","pt":1717288128429,"mc":[{"id":"1.229554920","marketDefinition":{"bspMarket":true,"turnInPlayEnabled":false,"persistenceEnabled":false,"marketBaseRate":7.0,"eventId":"33318908","eventTypeId":"4339","numberOfWinners":1,"bettingType":"ODDS","marketType":"WIN","marketTime":"2024-06-02T10:24:00.000Z","suspendTime":"2024-06-02T10:24:00.000Z","bspReconciled":false,"complete":true,"inPlay":false,"crossMatching":true,"runnersVoidable":false,"numberOfActiveRunners":7,"betDelay":0,"status":"OPEN","runners":[{"status":"ACTIVE","sortPriority":1,"id":65460404,"name":"1. Give Me Room"},{"status":"ACTIVE","sortPriority":2,"id":52671121,"name":"2. Elegant Ritzy"},{"status":"ACTIVE","sortPriority":3,"id":62262930,"name":"3. Canya Candy"},{"status":"ACTIVE","sortPriority":4,"id":69577417,"name":"4. Alpha Bloke"},{"status":"ACTIVE","sortPriority":5,"id":69421986,"name":"6. Back to Work"},{"status":"ACTIVE","sortPriority":6,"id":64546979,"name":"7. Sheas Entity"},{"status":"ACTIVE","sortPriority":7,"id":70003371,"name":"8. Yumali"}],"regulators":["MR_INT"],"venue":"Murray Bridge","countryCode":"AU","discountAllowed":true,"timezone":"Australia/Adelaide","openDate":"2024-06-02T08:21:00.000Z","version":5962317639,"name":"R7 455m Gr6","eventName":"Murray Bridge (AUS) 2nd Jun"},"rc":[{"atb":[[3.4,87.1],[3.15,97.23],[3.65,39.44]],"id":52671121},{"atl":[[16.5,8.99],[23,9.5]],"id":52671121},{"spn":10.07,"spf":"NaN","id":52671121},{"atb":[[3.1,49.77],[2.84,113.61],[2.94,107.76]],"id":62262930},{"atl":[[16,13.93],[11,13.93]],"id":62262930},{"spn":7.05,"spf":"NaN","id":62262930},{"atb":[[8.6,13.75],[7.6,31.67],[6.6,37.33]],"id":69577417},{"atl":[[100,1.4],[200,1.05]],"id":69577417},{"spn":54.3,"spf":"NaN","id":69577417},{"atb":[[16.5,6.74],[11.5,19.91],[14,16.08]],"id":69421986},{"atl":[[350,0.59],[250,0.55]],"id":69421986},{"spn":133.25,"spf":"NaN","id":69421986},{"atb":[[3.6,40.2],[3.1,99.55],[3.35,88.96]],"id":65460404},{"atl":[[18.5,11.94],[13.5,11.14]],"id":65460404},{"spn":8.55,"spf":"NaN","id":65460404},{"atb":[[8.6,13.75],[7.6,31.67],[6.6,37.33]],"id":64546979},{"atl":[[100,1.4],[200,1.05]],"id":64546979},{"spn":54.3,"spf":"NaN","id":64546979},{"atb":[[2.8,116.14],[2.9,55.01],[2.7,122.97]],"id":70003371},{"atl":[[10,15.48],[15,14.93]],"id":70003371},{"spn":6.45,"spf":"NaN","id":70003371}],"con":true,"img":true}]}
{"op":"mcm","clk":"11448289496","pt":1717288232637,"mc":[{"id":"1.229554920","rc":[{"atb":[[3.4,0],[3.15,0],[3.65,0]],"id":52671121},{"atl":[[16.5,0],[23,0]],"id":52671121},{"spn":7.05,"spf":"NaN","id":62262930},{"atb":[[8.6,0],[7.6,0],[6.6,0]],"id":69577417},{"atl":[[100,0],[200,0]],"id":69577417},{"spn":133.25,"spf":"NaN","id":69421986},{"spn":8.55,"spf":"NaN","id":65460404},{"atb":[[8.6,0],[7.6,0],[6.6,0]],"id":64546979},{"atl":[[100,0],[200,0]],"id":64546979},{"spn":6.45,"spf":"NaN","id":70003371}],"con":true,"img":false}]}
{"op":"mcm","clk":"11448290414","pt":1717288245743,"mc":[{"id":"1.229554920","rc":[{"atb":[[3.4,87.1],[3.15,97.23],[3.65,39.44]],"id":52671121},{"atl":[[16.5,8.99],[23,9.5]],"id":52671121},{"atb":[[8.6,13.75],[7.6,31.67],[6.6,37.33]],"id":69577417},{"atl":[[100,1.4],[200,1.05]],"id":69577417},{"atb":[[8.6,13.75],[7.6,31.67],[6.6,37.33]],"id":64546979},{"atl":[[100,1.4],[200,1.05]],"id":64546979}],"con":true,"img":false}]}
{"op":"mcm","clk":"11448292481","pt":1717288274170,"mc":[{"id":"1.229554920","rc":[{"atb":[[3.4,0],[3.15,0],[3.65,0]],"id":52671121},{"atl":[[16.5,0],[23,0]],"id":52671121},{"atb":[[16.5,0],[11.5,0],[14,0]],"id":69421986},{"atl":[[350,0],[250,0]],"id":69421986},{"atb":[[8.6,0],[7.6,0],[6.6,0]],"id":64546979},{"atl":[[100,0],[200,0]],"id":64546979},{"atb":[[2.8,0],[2.9,0],[2.7,0]],"id":70003371},{"atl":[[10,0],[15,0]],"id":70003371}],"con":true,"img":false}]}
{"op":"mcm","clk":"11448293813","pt":1717288291678,"mc":[{"id":"1.229554920","rc":[{"atb":[[3.25,92.91],[3.5,83.62],[3.75,38]],"id":52671121},{"atl":[[17.5,8.44],[25,8.71]],"id":52671121},{"atb":[[17,6.53],[12,19],[14.5,15.48]],"id":69421986},{"atl":[[350,0.59],[250,0.55]],"id":69421986},{"atb":[[8,29.86],[9,13.06],[7,34.84]],"id":64546979},{"atl":[[210,0.99],[110,1.27]],"id":64546979},{"atb":[[2.86,56.19],[2.66,125.93],[2.76,118.78]],"id":70003371},{"atl":[[9.8,15.83],[14.5,15.48]],"id":70003371}],"con":true,"img":false}]}
{"op":"mcm","clk":"11448298280","pt":1717288351487,"mc":[{"id":"1.229554920","rc":[{"spn":10.62,"spf":"NaN","id":52671121},{"atb":[[8.6,0],[7.6,0],[6.6,0]],"id":69577417},{"atl":[[100,0],[200,0]],"id":69577417},{"spn":133.5,"spf":"NaN","id":69421986},{"spn":59.5,"spf":"NaN","id":64546979},{"atb":[[2.86,0],[2.66,0],[2.76,0]],"id":70003371},{"atl":[[9.8,0],[14.5,0]],"id":70003371},{"spn":"NaN","spf":"NaN","id":70003371}],"con":true,"img":false}]}
{"op":"mcm","clk":"11448300795","pt":1717288383947,"mc":[{"id":"1.229554920","rc":[{"atb":[[8.6,13.75],[7.6,31.67],[6.6,37.33]],"id":69577417},{"atl":[[100,1.4],[200,1.05]],"id":69577417},{"atb":[[2.86,56.19],[2.66,125.93],[2.76,118.78]],"id":70003371},{"atl":[[9.8,15.83],[14.5,15.48]],"id":70003371}],"con":true,"img":false}]}
{"op":"mcm","clk":"11448333303","pt":1717288850361,"mc":[{"id":"1.229554920","rc":[{"atb":[[3.25,0],[3.5,0],[3.75,0]],"id":52671121},{"atl":[[17.5,0],[25,0]],"id":52671121},{"spn":"NaN","spf":"NaN","id":52671121},{"spn":54.3,"spf":"NaN","id":69577417},{"atb":[[17,0],[12,0],[14.5,0]],"id":69421986},{"atl":[[350,0],[250,0]],"id":69421986},{"spn":"NaN","spf":"NaN","id":69421986},{"atb":[[8,0],[9,0],[7,0]],"id":64546979},{"atl":[[210,0],[110,0]],"id":64546979},{"spn":"NaN","spf":"NaN","id":64546979},{"spn":6.33,"spf":"NaN","id":70003371}],"con":true,"img":false}]}
{"op":"mcm","clk":"11448333846","pt":1717288858189,"mc":[{"id":"1.229554920","rc":[{"atb":[[3.25,92.91],[3.5,83.62],[3.75,38]],"id":52671121},{"atl":[[17.5,8.44],[25,8.71]],"id":52671121},{"atb":[[17,6.53],[12,19],[14.5,15.48]],"id":69421986},{"atl":[[350,0.59],[250,0.55]],"id":69421986},{"atb":[[8,29.86],[9,13.06],[7,34.84]],"id":64546979},{"atl":[[210,0.99],[110,1.27]],"id":64546979}],"con":true,"img":false}]}
{"op":"mcm","clk":"11448334383","pt":1717288864948,"mc":[{"id":"1.229554920","rc":[{"atb":[[3.25,0],[3.5,0],[3.75,0]],"id":52671121},{"atl":[[17.5,0],[25,0]],"id":52671121},{"atb":[[3.1,0],[2.84,0],[2.94,0]],"id":62262930},{"atl":[[16,0],[11,0]],"id":62262930},{"atb":[[8.6,0],[7.6,0],[6.6,0]],"id":69577417},{"atl":[[100,0],[200,0]],"id":69577417},{"atb":[[17,0],[12,0],[14.5,0]],"id":69421986},{"atl":[[350,0],[250,0]],"id":69421986},{"atb":[[8,0],[9,0],[7,0]],"id":64546979},{"atl":[[210,0],[110,0]],"id":64546979},{"atb":[[2.86,0],[2.66,0],[2.76,0]],"id":70003371},{"atl":[[9.8,0],[14.5,0]],"id":70003371}],"con":true,"img":false}]}
{"op":"mcm","clk":"11448334643","pt":1717288868471,"mc":[{"id":"1.229554920","rc":[{"atb":[[3.1,49.77],[2.84,113.61],[2.94,107.76]],"id":52671121},{"atl":[[16,13.93],[11,13.93]],"id":52671121},{"atb":[[3.1,49.77],[2.84,113.61],[2.94,107.76]],"id":62262930},{"atl":[[16,13.93],[11,13.93]],"id":62262930},{"atb":[[8.6,13.75],[7.6,31.67],[6.6,37.33]],"id":69577417},{"atl":[[100,1.4],[200,1.05]],"id":69577417},{"atb":[[17,6.53],[12,19],[14.5,15.48]],"id":69421986},{"atl":[[350,0.59],[250,0.55]],"id":69421986},{"atb":[[8,29.86],[9,13.06],[7,34.84]],"id":64546979},{"atl":[[210,0.99],[110,1.27]],"id":64546979},{"atb":[[2.86,56.19],[2.66,125.93],[2.76,118.78]],"id":70003371},{"atl":[[9.8,15.83],[14.5,15.48]],"id":70003371}],"con":true,"img":false}]}
{"op":"mcm","clk":"11448337342","pt":1717288902695,"mc":[{"id":"1.229554920","rc":[{"atb":[[3.1,0],[2.84,0],[2.94,0]],"id":52671121},{"atl":[[16,0],[11,0]],"id":52671121},{"atb":[[3.1,0],[2.84,0],[2.94,0]],"id":62262930},{"atl":[[16,0],[11,0]],"id":62262930},{"atb":[[17,0],[12,0],[14.5,0]],"id":69421986},{"atl":[[350,0],[250,0]],"id":69421986},{"atb":[[3.6,0],[3.1,0],[3.35,0]],"id":65460404},{"atl":[[18.5,0],[13.5,0]],"id":65460404},{"atb":[[8,0],[9,0],[7,0]],"id":64546979},{"atl":[[210,0],[110,0]],"id":64546979}],"con":true,"img":false}]}
{"op":"mcm","clk":"11448338017","pt":1717288911145,"mc":[{"id":"1.229554920","rc":[{"atb":[[3.1,49.77],[2.84,113.61],[2.94,107.76]],"id":52671121},{"atl":[[16,13.93],[11,13.93]],"id":52671121},{"spn":7.05,"spf":"NaN","id":52671121},{"atb":[[2.86,112.39],[3.15,48.61],[2.96,106.66]],"id":62262930},{"atl":[[16,13.93],[11,13.93]],"id":62262930},{"spn":7.07,"spf":"NaN","id":62262930},{"atb":[[17,6.53],[12,19],[14.5,15.48]],"id":69421986},{"atl":[[350,0.59],[250,0.55]],"id":69421986},{"spn":133.5,"spf":"NaN","id":69421986},{"atb":[[3.6,40.2],[3.1,99.55],[3.35,88.96]],"id":65460404},{"atl":[[18.5,11.94],[13.5,11.14]],"id":65460404},{"atb":[[8,29.86],[9,13.06],[7,34.84]],"id":64546979},{"atl":[[210,0.99],[110,1.27]],"id":64546979},{"spn":59.5,"spf":"NaN","id":64546979}],"con":true,"img":false}]}
{"op":"mcm","clk":"11448339995","pt":1717288935753,"mc":[{"id":"1.229554920","rc":[{"atb":[[3.1,0],[2.84,0],[2.94,0]],"id":52671121},{"atl":[[16,0],[11,0]],"id":52671121},{"atb":[[2.86,0],[3.15,0],[2.96,0]],"id":62262930},{"atl":[[16,0],[11,0]],"id":62262930},{"atb":[[17,0],[12,0],[14.5,0]],"id":69421986},{"atl":[[350,0],[250,0]],"id":69421986},{"atb":[[3.6,0],[3.1,0],[3.35,0]],"id":65460404},{"atl":[[18.5,0],[13.5,0]],"id":65460404}],"con":true,"img":false}]}
{"op":"mcm","clk":"11448341146","pt":1717288949762,"mc":[{"id":"1.229554920","rc":[{"atb":[[3.1,49.77],[2.84,113.61],[2.94,107.76]],"id":52671121},{"atl":[[16,13.93],[11,13.93]],"id":52671121},{"atb":[[2.86,112.39],[3.15,48.61],[2.96,106.66]],"id":62262930},{"atl":[[16,13.93],[11,13.93]],"id":62262930},{"atb":[[17,6.53],[12,19],[14.5,15.48]],"id":69421986},{"atl":[[350,0.59],[250,0.55]],"id":69421986},{"atb":[[3.6,40.2],[3.1,99.55],[3.35,88.96]],"id":65460404},{"atl":[[18.5,11.94],[13.5,11.14]],"id":65460404}],"con":true,"img":false}]}
{"op":"mcm","clk":"11448344112","pt":1717288986613,"mc":[{"id":"1.229554920","rc":[{"atb":[[3.1,0],[2.84,0],[2.94,0]],"id":52671121},{"atl":[[16,0],[11,0]],"id":52671121},{"spn":"NaN","spf":"NaN","id":52671121},{"atb":[[2.86,0],[3.15,0],[2.96,0]],"id":62262930},{"atl":[[16,0],[11,0]],"id":62262930},{"spn":"NaN","spf":"NaN","id":62262930},{"atb":[[8.6,0],[7.6,0],[6.6,0]],"id":69577417},{"atl":[[100,0],[200,0]],"id":69577417},{"spn":"NaN","spf":"NaN","id":69577417},{"atb":[[17,0],[12,0],[14.5,0]],"id":69421986},{"atl":[[350,0],[250,0]],"id":69421986},{"spn":"NaN","spf":"NaN","id":69421986},{"atb":[[3.6,0],[3.1,0],[3.35,0]],"id":65460404},{"atl":[[18.5,0],[13.5,0]],"id":65460404},{"spn":"NaN","spf":"NaN","id":65460404},{"atb":[[8,0],[9,0],[7,0]],"id":64546979},{"atl":[[210,0],[110,0]],"id":64546979},{"spn":"NaN","spf":"NaN","id":64546979}],"con":true,"img":false}]}
{"op":"mcm","clk":"11448345399","pt":1717289003637,"mc":[{"id":"1.229554920","rc":[{"atb":[[3.1,49.77],[2.84,113.61],[2.94,107.76]],"id":52671121},{"atl":[[16,13.93],[11,13.93]],"id":52671121},{"atb":[[2.9,110.03],[3,104.53],[3.25,46.45]],"id":62262930},{"atl":[[17,13.06],[12,12.67]],"id":62262930},{"atb":[[8.6,13.75],[7.6,31.67],[6.6,37.33]],"id":69577417},{"atl":[[100,1.4],[200,1.05]],"id":69577417},{"atb":[[17,13.06],[19.5,5.65],[14.5,15.48]],"id":69421986},{"atl":[[300,0.46],[400,0.52]],"id":69421986},{"atb":[[3.4,87.1],[3.15,97.23],[3.65,39.44]],"id":65460404},{"atl":[[16.5,8.99],[23,9.5]],"id":65460404},{"atb":[[7.4,32.66],[8.4,28.25],[9.4,12.44]],"id":64546979},{"atl":[[140,1],[240,0.87]],"id":64546979}],"con":true,"img":false}]}
{"op":"mcm","clk":"11448348091","pt":1717289037282,"mc":[{"id":"1.229554920","rc":[{"atb":[[3.1,0],[2.84,0],[2.94,0]],"id":52671121},{"atl":[[16,0],[11,0]],"id":52671121},{"atb":[[8.6,0],[7.6,0],[6.6,0]],"id":69577417},{"atl":[[100,0],[200,0]],"id":69577417}],"con":true,"img":false}]}
{"op":"mcm","clk":"11448348769","pt":1717289046211,"mc":[{"id":"1.229554920","rc":[{"atb":[[3.1,49.77],[2.84,113.61],[2.94,107.76]],"id":52671121},{"atl":[[16,13.93],[11,13.93]],"id":52671121},{"atb":[[8.6,13.75],[7.6,31.67],[6.6,37.33]],"id":69577417},{"atl":[[100,1.4],[200,1.05]],"id":69577417}],"con":true,"img":false}]}
{"op":"mcm","clk":"11448361840","pt":1717289213256,"mc":[{"id":"1.229554920","rc":[{"atb":[[3.1,0],[2.84,0],[2.94,0]],"id":52671121},{"atl":[[16,0],[11,0]],"id":52671121},{"atb":[[2.9,0],[3,0],[3.25,0]],"id":62262930},{"atl":[[17,0],[12,0]],"id":62262930},{"spn":54.3,"spf":"NaN","id":69577417},{"atb":[[17,0],[19.5,0],[14.5,0]],"id":69421986},{"atl":[[300,0],[400,0]],"id":69421986},{"spn":10.07,"spf":"NaN","id":65460404},{"spn":74.7,"spf":"NaN","id":64546979}],"con":true,"img":false}]}
{"op":"mcm","clk":"11448362206","pt":1717289218276,"mc":[{"id":"1.229554920","rc":[{"atb":[[2.8,116.14],[2.9,55.01],[2.7,122.97]],"id":52671121},{"atl":[[10,15.48],[15,14.93]],"id":52671121},{"atb":[[2.9,110.03],[3,104.53],[3.25,46.45]],"id":62262930},{"atl":[[17,13.06],[12,12.67]],"id":62262930},{"atb":[[17,13.06],[19.5,5.65],[14.5,15.48]],"id":69421986},{"atl":[[300,0.46],[400,0.52]],"id":69421986}],"con":true,"img":false}]}
{"op":"mcm","clk":"11448367939","pt":1717289300806,"mc":[{"id":"1.229554920","rc":[{"atb":[[2.8,0],[2.9,0],[2.7,0]],"id":52671121},{"atl":[[10,0],[15,0]],"id":52671121},{"atb":[[2.9,0],[3,0],[3.25,0]],"id":62262930},{"atl":[[17,0],[12,0]],"id":62262930},{"atb":[[8.6,0],[7.6,0],[6.6,0]],"id":69577417},{"atl":[[100,0],[200,0]],"id":69577417},{"spn":"NaN","spf":"NaN","id":69577417},{"atb":[[17,0],[19.5,0],[14.5,0]],"id":69421986},{"atl":[[300,0],[400,0]],"id":69421986},{"atb":[[3.4,0],[3.15,0],[3.65,0]],"id":65460404},{"atl":[[16.5,0],[23,0]],"id":65460404},{"spn":"NaN","spf":"NaN","id":65460404},{"atb":[[7.4,0],[8.4,0],[9.4,0]],"id":64546979},{"atl":[[140,0],[240,0]],"id":64546979},{"spn":"NaN","spf":"NaN","id":64546979}],"con":true,"img":false}]}
{"op":"mcm","clk":"11448368462","pt":1717289309031,"mc":[{"id":"1.229554920","rc":[{"atb":[[2.8,116.14],[2.9,55.01],[2.7,122.97]],"id":52671121},{"atl":[[10,15.48],[15,14.93]],"id":52671121},{"atb":[[2.9,110.03],[3,104.53],[3.25,46.45]],"id":62262930},{"atl":[[17,13.06],[12,12.67]],"id":62262930},{"atb":[[8.6,13.75],[7.6,31.67],[6.6,37.33]],"id":69577417},{"atl":[[100,1.4],[200,1.05]],"id":69577417},{"atb":[[17,13.06],[19.5,5.65],[14.5,15.48]],"id":69421986},{"atl":[[300,0.46],[400,0.52]],"id":69421986},{"atb":[[3.4,87.1],[3.15,97.23],[3.65,39.44]],"id":65460404},{"atl":[[16.5,8.99],[23,9.5]],"id":65460404},{"atb":[[7.4,32.66],[8.4,28.25],[9.4,12.44]],"id":64546979},{"atl":[[140,1],[240,0.87]],"id":64546979}],"con":true,"img":false}]}
{"op":"mcm","clk":"11448370206","pt":1717289334552,"mc":[{"id":"1.229554920","rc":[{"atb":[[2.8,0],[2.9,0],[2.7,0]],"id":52671121},{"atl":[[10,0],[15,0]],"id":52671121},{"atb":[[8.6,0],[7.6,0],[6.6,0]],"id":69577417},{"atl":[[100,0],[200,0]],"id":69577417},{"atb":[[17,0],[19.5,0],[14.5,0]],"id":69421986},{"atl":[[300,0],[400,0]],"id":69421986},{"atb":[[3.4,0],[3.15,0],[3.65,0]],"id":65460404},{"atl":[[16.5,0],[23,0]],"id":65460404},{"atb":[[7.4,0],[8.4,0],[9.4,0]],"id":64546979},{"atl":[[140,0],[240,0]],"id":64546979}],"con":true,"img":false}]}
{"op":"mcm","clk":"11448371094","pt":1717289347354,"mc":[{"id":"1.229554920","rc":[{"atb":[[2.8,116.14],[2.9,55.01],[2.7,122.97]],"id":52671121},{"atl":[[10,15.48],[15,14.93]],"id":52671121},{"atb":[[8.6,13.75],[7.6,31.67],[6.6,37.33]],"id":69577417},{"atl":[[100,1.4],[200,1.05]],"id":69577417},{"atb":[[17,13.06],[19.5,5.65],[14.5,15.48]],"id":69421986},{"atl":[[300,0.46],[400,0.52]],"id":69421986},{"atb":[[3.4,87.1],[3.15,97.23],[3.65,39.44]],"id":65460404},{"atl":[[16.5,8.99],[23,9.5]],"id":65460404},{"atb":[[7.4,32.66],[8.4,28.25],[9.4,12.44]],"id":64546979},{"atl":[[140,1],[240,0.87]],"id":64546979}],"con":true,"img":false}]}
{"op":"mcm","clk":"11448375264","pt":1717289407363,"mc":[{"id":"1.229554920","rc":[{"atb":[[2.8,0],[2.9,0],[2.7,0]],"id":52671121},{"atl":[[10,0],[15,0]],"id":52671121},{"spn":7.62,"spf":"NaN","id":62262930},{"spn":54.3,"spf":"NaN","id":69577417},{"spn":159.75,"spf":"NaN","id":69421986},{"atb":[[3.4,0],[3.15,0],[3.65,0]],"id":65460404},{"atl":[[16.5,0],[23,0]],"id":65460404},{"spn":74.7,"spf":"NaN","id":64546979}],"con":true,"img":false}]}
{"op":"mcm","clk":"11448375724","pt":1717289413579,"mc":[{"id":"1.229554920","rc":[{"atb":[[2.8,116.14],[2.9,55.01],[2.7,122.97]],"id":52671121},{"atl":[[10,15.48],[15,14.93]],"id":52671121},{"atb":[[3.4,87.1],[3.15,97.23],[3.65,39.44]],"id":65460404},{"atl":[[16.5,8.99],[23,9.5]],"id":65460404}],"con":true,"img":false}]}
{"op":"mcm","clk":"11448376622","pt":1717289426255,"mc":[{"id":"1.229554920","rc":[{"atb":[[8.6,0],[7.6,0],[6.6,0]],"id":69577417},{"atl":[[100,0],[200,0]],"id":69577417},{"atb":[[17,0],[19.5,0],[14.5,0]],"id":69421986},{"atl":[[300,0],[400,0]],"id":69421986}],"con":true,"img":false}]}
{"op":"mcm","clk":"11448377226","pt":1717289434418,"mc":[{"id":"1.229554920","rc":[{"atb":[[8.6,13.75],[7.6,31.67],[6.6,37.33]],"id":69577417},{"atl":[[100,1.4],[200,1.05]],"id":69577417},{"atb":[[17.5,12.67],[20,5.5],[15,14.93]],"id":69421986},{"atl":[[310,0.44],[410,0.51]],"id":69421986}],"con":true,"img":false}]}
{"op":"mcm","clk":"11448378852","pt":1717289456920,"mc":[{"id":"1.229554920","rc":[{"atb":[[2.8,0],[2.9,0],[2.7,0]],"id":52671121},{"atl":[[10,0],[15,0]],"id":52671121},{"atb":[[17.5,0],[20,0],[15,0]],"id":69421986},{"atl":[[310,0],[410,0]],"id":69421986},{"atb":[[3.4,0],[3.15,0],[3.65,0]],"id":65460404},{"atl":[[16.5,0],[23,0]],"id":65460404}],"con":true,"img":false}]}
{"op":"mcm","clk":"11448379529","pt":1717289465530,"mc":[{"id":"1.229554920","rc":[{"atb":[[2.8,116.14],[2.9,55.01],[2.7,122.97]],"id":52671121},{"atl":[[10,15.48],[15,14.93]],"id":52671121},{"atb":[[17.5,12.67],[20,5.5],[15,14.93]],"id":69421986},{"atl":[[310,0.44],[410,0.51]],"id":69421986},{"atb":[[3.4,87.1],[3.15,97.23],[3.65,39.44]],"id":65460404},{"atl":[[16.5,8.99],[23,9.5]],"id":65460404}],"con":true,"img":false}]}
{"op":"mcm","clk":"11448381065","pt":1717289487477,"mc":[{"id":"1.229554920","rc":[{"atb":[[2.8,0],[2.9,0],[2.7,0]],"id":52671121},{"atl":[[10,0],[15,0]],"id":52671121},{"atb":[[2.9,0],[3,0],[3.25,0]],"id":62262930},{"atl":[[17,0],[12,0]],"id":62262930},{"spn":"NaN","spf":"NaN","id":62262930},{"atb":[[8.6,0],[7.6,0],[6.6,0]],"id":69577417},{"atl":[[100,0],[200,0]],"id":69577417},{"spn":"NaN","spf":"NaN","id":69577417},{"atb":[[17.5,0],[20,0],[15,0]],"id":69421986},{"atl":[[310,0],[410,0]],"id":69421986},{"spn":"NaN","spf":"NaN","id":69421986},{"atb":[[3.4,0],[3.15,0],[3.65,0]],"id":65460404},{"atl":[[16.5,0],[23,0]],"id":65460404},{"atb":[[7.4,0],[8.4,0],[9.4,0]],"id":64546979},{"atl":[[140,0],[240,0]],"id":64546979},{"spn":"NaN","spf":"NaN","id":64546979},{"atb":[[2.86,0],[2.66,0],[2.76,0]],"id":70003371},{"atl":[[9.8,0],[14.5,0]],"id":70003371},{"spn":"NaN","spf":"NaN","id":70003371}],"con":true,"img":false}]}
{"op":"mcm","clk":"11448381758","pt":1717289496483,"mc":[{"id":"1.229554920","rc":[{"atb":[[2.8,116.14],[2.9,55.01],[2.7,122.97]],"id":52671121},{"atl":[[10,15.48],[15,14.93]],"id":52671121},{"atb":[[3.4,43.55],[3.15,97.23],[2.96,106.66]],"id":62262930},{"atl":[[19,11.61],[14,10.71]],"id":62262930},{"atb":[[8,29.86],[9,13.06],[7,34.84]],"id":69577417},{"atl":[[210,0.99],[110,1.27]],"id":69577417},{"atb":[[17.5,12.67],[20,5.5],[15,14.93]],"id":69421986},{"atl":[[310,0.44],[410,0.51]],"id":69421986},{"atb":[[3.25,92.91],[3.5,83.62],[3.75,38]],"id":65460404},{"atl":[[17.5,8.44],[25,8.71]],"id":65460404},{"atb":[[7.4,32.66],[8.4,28.25],[9.4,12.44]],"id":64546979},{"atl":[[140,1],[240,0.87]],"id":64546979},{"atb":[[2.86,56.19],[2.66,125.93],[2.76,118.78]],"id":70003371},{"atl":[[9.8,15.83],[14.5,15.48]],"id":70003371}],"con":true,"img":false}]}
{"op":"mcm","clk":"11448383596","pt":1717289521000,"mc":[{"id":"1.229554920","rc":[{"atb":[[2.8,0],[2.9,0],[2.7,0]],"id":52671121},{"atl":[[10,0],[15,0]],"id":52671121},{"atb":[[3.4,0],[3.15,0],[2.96,0]],"id":62262930},{"atl":[[19,0],[14,0]],"id":62262930},{"atb":[[17.5,0],[20,0],[15,0]],"id":69421986},{"atl":[[310,0],[410,0]],"id":69421986},{"atb":[[3.25,0],[3.5,0],[3.75,0]],"id":65460404},{"atl":[[17.5,0],[25,0]],"id":65460404}],"con":true,"img":false}]}
{"op":"mcm","clk":"11448384375","pt":1717289531138,"mc":[{"id":"1.229554920","rc":[{"atb":[[2.8,116.14],[2.9,55.01],[2.7,122.97]],"id":52671121},{"atl":[[10,15.48],[15,14.93]],"id":52671121},{"atb":[[3.45,42.66],[3.2,95.02],[2.98,105.58]],"id":62262930},{"atl":[[19.5,11.3],[14.5,10.32]],"id":62262930},{"atb":[[16,13.93],[18.5,11.94],[22,4.97]],"id":69421986},{"atl":[[320,0.43],[420,0.49]],"id":69421986},{"atb":[[3.25,92.91],[3.5,83.62],[3.75,38]],"id":65460404},{"atl":[[17.5,8.44],[25,8.71]],"id":65460404}],"con":true,"img":false}]}
{"op":"mcm","clk":"11448452965","pt":1717290537252,"mc":[{"id":"1.229554920","rc":[{"atb":[[2.8,0],[2.9,0],[2.7,0]],"id":52671121},{"atl":[[10,0],[15,0]],"id":52671121},{"atb":[[3.45,0],[3.2,0],[2.98,0]],"id":62262930},{"atl":[[19.5,0],[14.5,0]],"id":62262930},{"atb":[[8,0],[9,0],[7,0]],"id":69577417},{"atl":[[210,0],[110,0]],"id":69577417},{"atb":[[16,0],[18.5,0],[22,0]],"id":69421986},{"atl":[[320,0],[420,0]],"id":69421986},{"atb":[[3.25,0],[3.5,0],[3.75,0]],"id":65460404},{"atl":[[17.5,0],[25,0]],"id":65460404},{"atb":[[7.4,0],[8.4,0],[9.4,0]],"id":64546979},{"atl":[[140,0],[240,0]],"id":64546979},{"atb":[[2.86,0],[2.66,0],[2.76,0]],"id":70003371},{"atl":[[9.8,0],[14.5,0]],"id":70003371}],"con":true,"img":false}]}
{"op":"mcm","clk":"11448453477","pt":1717290545756,"mc":[{"id":"1.229554920","rc":[{"atb":[[2.8,116.14],[2.9,55.01],[2.7,122.97]],"id":52671121},{"atl":[[10,15.48],[15,14.93]],"id":52671121},{"atb":[[3.45,42.66],[3.2,95.02],[2.98,105.58]],"id":62262930},{"atl":[[19.5,11.3],[14.5,10.32]],"id":62262930},{"atb":[[8,29.86],[9,13.06],[7,34.84]],"id":69577417},{"atl":[[210,0.99],[110,1.27]],"id":69577417},{"atb":[[16,13.93],[18.5,11.94],[22,4.97]],"id":69421986},{"atl":[[320,0.43],[420,0.49]],"id":69421986},{"atb":[[2.88,111.2],[2.98,52.79],[2.78,117.44]],"id":65460404},{"atl":[[10.5,14.66],[15.5,14.41]],"id":65460404},{"atb":[[9.2,25.49],[10.5,11],[8.2,29.03]],"id":64546979},{"atl":[[280,0.74],[180,0.77]],"id":64546979},{"atb":[[2.86,56.19],[2.66,125.93],[2.76,118.78]],"id":70003371},{"atl":[[9.8,15.83],[14.5,15.48]],"id":70003371}],"con":true,"img":false}]}
{"op":"mcm","clk":"11448454336","pt":1717290557091,"mc":[{"id":"1.229554920","rc":[{"atb":[[2.8,0],[2.9,0],[2.7,0]],"id":52671121},{"atl":[[10,0],[15,0]],"id":52671121},{"atb":[[8,0],[9,0],[7,0]],"id":69577417},{"atl":[[210,0],[110,0]],"id":69577417},{"atb":[[16,0],[18.5,0],[22,0]],"id":69421986},{"atl":[[320,0],[420,0]],"id":69421986},{"atb":[[2.88,0],[2.98,0],[2.78,0]],"id":65460404},{"atl":[[10.5,0],[15.5,0]],"id":65460404},{"atb":[[9.2,0],[10.5,0],[8.2,0]],"id":64546979},{"atl":[[280,0],[180,0]],"id":64546979},{"atb":[[2.86,0],[2.66,0],[2.76,0]],"id":70003371},{"atl":[[9.8,0],[14.5,0]],"id":70003371}],"con":true,"img":false}]}
{"op":"mcm","clk":"11448454922","pt":1717290565164,"mc":[{"id":"1.229554920","rc":[{"atb":[[2.8,116.14],[2.9,55.01],[2.7,122.97]],"id":52671121},{"atl":[[10,15.48],[15,14.93]],"id":52671121},{"atb":[[8,29.86],[9,13.06],[7,34.84]],"id":69577417},{"atl":[[210,0.99],[110,1.27]],"id":69577417},{"atb":[[16,13.93],[18.5,11.94],[22,4.97]],"id":69421986},{"atl":[[320,0.43],[420,0.49]],"id":69421986},{"atb":[[2.88,111.2],[2.98,52.79],[2.78,117.44]],"id":65460404},{"atl":[[10.5,14.66],[15.5,14.41]],"id":65460404},{"atb":[[9.2,25.49],[10.5,11],[8.2,29.03]],"id":64546979},{"atl":[[280,0.74],[180,0.77]],"id":64546979},{"atb":[[2.86,56.19],[2.66,125.93],[2.76,118.78]],"id":70003371},{"atl":[[9.8,15.83],[14.5,15.48]],"id":70003371}],"con":true,"img":false}]}
{"op":"mcm","clk":"11448455687","pt":1717290577115,"mc":[{"id":"1.229554920","rc":[{"atb":[[2.8,0],[2.9,0],[2.7,0]],"id":52671121},{"atl":[[10,0],[15,0]],"id":52671121},{"atb":[[3.45,0],[3.2,0],[2.98,0]],"id":62262930},{"atl":[[19.5,0],[14.5,0]],"id":62262930},{"atb":[[8,0],[9,0],[7,0]],"id":69577417},{"atl":[[210,0],[110,0]],"id":69577417},{"atb":[[16,0],[18.5,0],[22,0]],"id":69421986},{"atl":[[320,0],[420,0]],"id":69421986},{"atb":[[2.88,0],[2.98,0],[2.78,0]],"id":65460404},{"atl":[[10.5,0],[15.5,0]],"id":65460404},{"atb":[[9.2,0],[10.5,0],[8.2,0]],"id":64546979},{"atl":[[280,0],[180,0]],"id":64546979}],"con":true,"img":false}]}
{"op":"mcm","clk":"11448456059","pt":1717290583604,"mc":[{"id":"1.229554920","rc":[{"atb":[[2.8,116.14],[2.9,55.01],[2.7,122.97]],"id":52671121},{"atl":[[10,15.48],[15,14.93]],"id":52671121},{"atb":[[3.45,42.66],[3.2,95.02],[2.98,105.58]],"id":62262930},{"atl":[[19.5,11.3],[14.5,10.32]],"id":62262930},{"atb":[[8,29.86],[9,13.06],[7,34.84]],"id":69577417},{"atl":[[210,0.99],[110,1.27]],"id":69577417},{"atb":[[16,13.93],[18.5,11.94],[22,4.97]],"id":69421986},{"atl":[[320,0.43],[420,0.49]],"id":69421986},{"atb":[[2.88,111.2],[2.98,52.79],[2.78,117.44]],"id":65460404},{"atl":[[10.5,14.66],[15.5,14.41]],"id":65460404},{"atb":[[9.2,25.49],[10.5,11],[8.2,29.03]],"id":64546979},{"atl":[[280,0.74],[180,0.77]],"id":64546979}],"con":true,"img":false}]}
{"op":"mcm","clk":"11448459589","pt":1717290647390,"mc":[{"id":"1.229554920","rc":[{"atb":[[2.8,0],[2.9,0],[2.7,0]],"id":52671121},{"atl":[[10,0],[15,0]],"id":52671121},{"atb":[[3.45,0],[3.2,0],[2.98,0]],"id":62262930},{"atl":[[19.5,0],[14.5,0]],"id":62262930},{"atb":[[8,0],[9,0],[7,0]],"id":69577417},{"atl":[[210,0],[110,0]],"id":69577417},{"atb":[[16,0],[18.5,0],[22,0]],"id":69421986},{"atl":[[320,0],[420,0]],"id":69421986},{"atb":[[2.88,0],[2.98,0],[2.78,0]],"id":65460404},{"atl":[[10.5,0],[15.5,0]],"id":65460404},{"atb":[[9.2,0],[10.5,0],[8.2,0]],"id":64546979},{"atl":[[280,0],[180,0]],"id":64546979},{"atb":[[2.86,0],[2.66,0],[2.76,0]],"id":70003371},{"atl":[[9.8,0],[14.5,0]],"id":70003371}],"con":true,"img":false}]}
{"op":"mcm","clk":"11448459972","pt":1717290655707,"mc":[{"id":"1.229554920","rc":[{"atb":[[2.8,116.14],[2.9,55.01],[2.7,122.97]],"id":52671121},{"atl":[[10,15.48],[15,14.93]],"id":52671121},{"atb":[[3.6,40.2],[3.1,99.55],[3.35,88.96]],"id":62262930},{"atl":[[18.5,11.94],[13.5,11.14]],"id":62262930},{"atb":[[7.4,32.66],[8.4,28.25],[9.4,12.44]],"id":69577417},{"atl":[[140,1],[240,0.87]],"id":69577417},{"atb":[[17,13.06],[19.5,11.3],[24,4.54]],"id":69421986},{"atl":[[340,0.41],[440,0.47]],"id":69421986},{"atb":[[2.88,111.2],[2.98,52.79],[2.78,117.44]],"id":65460404},{"atl":[[10.5,14.66],[15.5,14.41]],"id":65460404},{"atb":[[9.6,24.31],[8.6,27.5],[11.5,9.95]],"id":64546979},{"atl":[[300,0.7],[200,0.7]],"id":64546979},{"atb":[[2.8,116.14],[2.9,55.01],[2.7,122.97]],"id":70003371},{"atl":[[10,15.48],[15,14.93]],"id":70003371}],"con":true,"img":false}]}
{"op":"mcm","clk":"11448461417","pt":1717290680524,"mc":[{"id":"1.229554920","rc":[{"atb":[[17,0],[19.5,0],[24,0]],"id":69421986},{"atl":[[340,0],[440,0]],"id":69421986},{"atb":[[9.6,0],[8.6,0],[11.5,0]],"id":64546979},{"atl":[[300,0],[200,0]],"id":64546979}],"con":true,"img":false}]}
{"op":"mcm","clk":"11448462200","pt":1717290691801,"mc":[{"id":"1.229554920","rc":[{"atb":[[17.5,12.67],[20,11],[25,4.35]],"id":69421986},{"atl":[[350,0.39],[450,0.46]],"id":69421986},{"atb":[[9.6,24.31],[8.6,27.5],[11.5,9.95]],"id":64546979},{"atl":[[300,0.7],[200,0.7]],"id":64546979}],"con":true,"img":false}]}
{"op":"mcm","clk":"11448463739","pt":1717290717742,"mc":[{"id":"1.229554920","rc":[{"atb":[[2.8,0],[2.9,0],[2.7,0]],"id":52671121},{"atl":[[10,0],[15,0]],"id":52671121},{"atb":[[3.6,0],[3.1,0],[3.35,0]],"id":62262930},{"atl":[[18.5,0],[13.5,0]],"id":62262930},{"spn":74.7,"spf":"NaN","id":69577417},{"atb":[[17.5,0],[20,0],[25,0]],"id":69421986},{"atl":[[350,0],[450,0]],"id":69421986},{"atb":[[2.88,0],[2.98,0],[2.78,0]],"id":65460404},{"atl":[[10.5,0],[15.5,0]],"id":65460404},{"atb":[[9.6,0],[8.6,0],[11.5,0]],"id":64546979},{"atl":[[300,0],[200,0]],"id":64546979},{"atb":[[2.8,0],[2.9,0],[2.7,0]],"id":70003371},{"atl":[[10,0],[15,0]],"id":70003371}],"con":true,"img":false}]}
{"op":"mcm","clk":"11448464665","pt":1717290732764,"mc":[{"id":"1.229554920","rc":[{"atb":[[2.8,116.14],[2.9,55.01],[2.7,122.97]],"id":52671121},{"atl":[[10,15.48],[15,14.93]],"id":52671121},{"atb":[[3.6,40.2],[3.1,99.55],[3.35,88.96]],"id":62262930},{"atl":[[18.5,11.94],[13.5,11.14]],"id":62262930},{"atb":[[17.5,12.67],[20,11],[25,4.35]],"id":69421986},{"atl":[[350,0.39],[450,0.46]],"id":69421986},{"atb":[[2.88,111.2],[2.98,52.79],[2.78,117.44]],"id":65460404},{"atl":[[10.5,14.66],[15.5,14.41]],"id":65460404},{"atb":[[9.6,24.31],[8.6,27.5],[11.5,9.95]],"id":64546979},{"atl":[[300,0.7],[200,0.7]],"id":64546979},{"atb":[[2.8,116.14],[2.9,55.01],[2.7,122.97]],"id":70003371},{"atl":[[10,15.48],[15,14.93]],"id":70003371}],"con":true,"img":false}]}
{"op":"mcm","clk":"11448465960","pt":1717290755917,"mc":[{"id":"1.229554920","rc":[{"atb":[[2.8,0],[2.9,0],[2.7,0]],"id":52671121},{"atl":[[10,0],[15,0]],"id":52671121},{"atb":[[17.5,0],[20,0],[25,0]],"id":69421986},{"atl":[[350,0],[450,0]],"id":69421986},{"atb":[[2.88,0],[2.98,0],[2.78,0]],"id":65460404},{"atl":[[10.5,0],[15.5,0]],"id":65460404}],"con":true,"img":false}]}
{"op":"mcm","clk":"11448466615","pt":1717290765990,"mc":[{"id":"1.229554920","rc":[{"atb":[[2.86,112.39],[2.96,53.33],[2.76,118.78]],"id":52671121},{"atl":[[10.5,14.66],[15.5,14.41]],"id":52671121},{"atb":[[17,13.06],[19.5,11.3],[24,4.54]],"id":69421986},{"atl":[[340,0.41],[440,0.47]],"id":69421986},{"atb":[[2.88,111.2],[2.98,52.79],[2.78,117.44]],"id":65460404},{"atl":[[10.5,14.66],[15.5,14.41]],"id":65460404}],"con":true,"img":false}]}
{"op":"mcm","clk":"11448467888","pt":1717290786624,"mc":[{"id":"1.229554920","rc":[{"atb":[[2.86,0],[2.96,0],[2.76,0]],"id":52671121},{"atl":[[10.5,0],[15.5,0]],"id":52671121},{"atb":[[3.6,0],[3.1,0],[3.35,0]],"id":62262930},{"atl":[[18.5,0],[13.5,0]],"id":62262930},{"atb":[[17,0],[19.5,0],[24,0]],"id":69421986},{"atl":[[340,0],[440,0]],"id":69421986},{"atb":[[2.88,0],[2.98,0],[2.78,0]],"id":65460404},{"atl":[[10.5,0],[15.5,0]],"id":65460404},{"spn":105.75,"spf":"NaN","id":64546979},{"atb":[[2.8,0],[2.9,0],[2.7,0]],"id":70003371},{"atl":[[10,0],[15,0]],"id":70003371}],"con":true,"img":false}]}
{"op":"mcm","clk":"11448468353","pt":1717290794328,"mc":[{"id":"1.229554920","rc":[{"atb":[[2.86,112.39],[2.96,53.33],[2.76,118.78]],"id":52671121},{"atl":[[10.5,14.66],[15.5,14.41]],"id":52671121},{"atb":[[3.6,40.2],[3.1,99.55],[3.35,88.96]],"id":62262930},{"atl":[[18.5,11.94],[13.5,11.14]],"id":62262930},{"atb":[[17,13.06],[19.5,11.3],[24,4.54]],"id":69421986},{"atl":[[340,0.41],[440,0.47]],"id":69421986},{"atb":[[2.88,111.2],[2.98,52.79],[2.78,117.44]],"id":65460404},{"atl":[[10.5,14.66],[15.5,14.41]],"id":65460404},{"atb":[[2.8,116.14],[2.9,55.01],[2.7,122.97]],"id":70003371},{"atl":[[10,15.48],[15,14.93]],"id":70003371}],"con":true,"img":false}]}
{"op":"mcm","clk":"11448629978","pt":1717293528419,"mc":[{"id":"1.229554920","marketDefinition":{"bspMarket":true,"turnInPlayEnabled":false,"persistenceEnabled":false,"marketBaseRate":7.0,"eventId":"33318908","eventTypeId":"4339","numberOfWinners":1,"bettingType":"ODDS","marketType":"WIN","marketTime":"2024-06-02T10:24:00.000Z","suspendTime":"2024-06-02T10:24:00.000Z","bspReconciled":false,"complete":true,"inPlay":false,"crossMatching":true,"runnersVoidable":false,"numberOfActiveRunners":7,"betDelay":0,"status":"OPEN","runners":[{"status":"ACTIVE","sortPriority":1,"id":65460404,"name":"1. Give Me Room"},{"status":"ACTIVE","sortPriority":2,"id":52671121,"name":"2. Elegant Ritzy"},{"status":"ACTIVE","sortPriority":3,"id":62262930,"name":"3. Canya Candy"},{"status":"ACTIVE","sortPriority":4,"id":69577417,"name":"4. Alpha Bloke"},{"status":"ACTIVE","sortPriority":5,"id":69421986,"name":"6. Back to Work"},{"status":"ACTIVE","sortPriority":6,"id":64546979,"name":"7. Sheas Entity"},{"status":"ACTIVE","sortPriority":7,"id":70003371,"name":"8. Yumali"}],"regulators":["MR_INT"],"venue":"Murray Bridge","countryCode":"AU","discountAllowed":true,"timezone":"Australia/Adelaide","openDate":"2024-06-02T08:21:00.000Z","version":5962317639,"name":"R7 455m Gr6","eventName":"Murray Bridge (AUS) 2nd Jun"},"rc":[{"atb":[[2.86,112.39],[2.96,53.33],[2.76,118.78]],"id":52671121},{"atl":[[10.5,14.66],[15.5,14.41]],"id":52671121},{"spn":6.73,"spf":"NaN","id":52671121},{"atb":[[3.6,40.2],[3.1,99.55],[3.35,88.96]],"id":62262930},{"atl":[[18.5,11.94],[13.5,11.14]],"id":62262930},{"spn":8.55,"spf":"NaN","id":62262930},{"atb":[[7.4,32.66],[8.4,28.25],[9.4,12.44]],"id":69577417},{"atl":[[140,1],[240,0.87]],"id":69577417},{"spn":74.7,"spf":"NaN","id":69577417},{"atb":[[17,13.06],[19.5,11.3],[24,4.54]],"id":69421986},{"atl":[[340,0.41],[440,0.47]],"id":69421986},{"spn":182.0,"spf":"NaN","id":69421986},{"atb":[[2.88,111.2],[2.98,52.79],[2.78,117.44]],"id":65460404},{"atl":[[10.5,14.66],[15.5,14.41]],"id":65460404},{"spn":6.74,"spf":"NaN","id":65460404},{"atb":[[9.6,24.31],[8.6,27.5],[11.5,9.95]],"id":64546979},{"atl":[[300,0.7],[200,0.7]],"id":64546979},{"spn":105.75,"spf":"NaN","id":64546979},{"atb":[[2.8,116.14],[2.9,55.01],[2.7,122.97]],"id":70003371},{"atl":[[10,15.48],[15,14.93]],"id":70003371},{"spn":6.45,"spf":"NaN","id":70003371}],"con":true,"img":true}]}
{"op":"mcm","clk":"11449586935","pt":1717311447508,"mc":[{"id":"1.229554920","rc":[{"atb":[[1.02,8.67]],"id":52671121},{"atl":[[990,0.85]],"id":52671121},{"spn":6.73,"spf":"NaN","id":52671121},{"atb":[[1.01,17.35]],"id":62262930},{"atl":[[990,0.85]],"id":62262930},{"spn":8.55,"spf":"NaN","id":62262930},{"atb":[[1.02,8.67]],"id":69577417},{"atl":[[990,0.85]],"id":69577417},{"atb":[[1.01,17.35]],"id":69421986},{"atl":[[1000,0.85]],"id":69421986},{"spn":182.0,"spf":"NaN","id":69421986},{"atb":[[1.03,5.78]],"id":65460404},{"atl":[[1000,0.85]],"id":65460404},{"spn":6.74,"spf":"NaN","id":65460404},{"atb":[[1.01,17.35]],"id":64546979},{"atl":[[1000,0.85]],"id":64546979},{"atb":[[1.01,17.35]],"id":70003371},{"atl":[[990,0.85]],"id":70003371},{"spn":6.45,"spf":"NaN","id":70003371}],"con":true,"img":false}]}
{"op":"mcm","clk":"11449667342","pt":1717313215614,"mc":[{"id":"1.229554920","rc":[{"atb":[[2.86,0],[2.96,0],[2.76,0]],"id":52671121},{"atl":[[10.5,0],[15.5,0]],"id":52671121},{"spn":495.51,"spf":"NaN","id":52671121},{"atb":[[3.6,0],[3.1,0],[3.35,0]],"id":62262930},{"atl":[[18.5,0],[13.5,0]],"id":62262930},{"spn":495.5,"spf":"NaN","id":62262930},{"atb":[[7.4,0],[8.4,0],[9.4,0]],"id":69577417},{"atl":[[140,0],[240,0]],"id":69577417},{"spn":495.51,"spf":"NaN","id":69577417},{"atb":[[17,0],[19.5,0],[24,0]],"id":69421986},{"atl":[[340,0],[440,0]],"id":69421986},{"spn":500.5,"spf":"NaN","id":69421986},{"atb":[[2.88,0],[2.98,0],[2.78,0]],"id":65460404},{"atl":[[10.5,0],[15.5,0]],"id":65460404},{"spn":500.51,"spf":"NaN","id":65460404},{"atb":[[9.6,0],[8.6,0],[11.5,0]],"id":64546979},{"atl":[[300,0],[200,0]],"id":64546979},{"spn":500.5,"spf":"NaN","id":64546979},{"atb":[[2.8,0],[2.9,0],[2.7,0]],"id":70003371},{"atl":[[10,0],[15,0]],"id":70003371},{"spn":495.5,"spf":"NaN","id":70003371}],"con":true,"img":false}]}
{"op":"mcm","clk":"11449668025","pt":1717313230165,"mc":[{"id":"1.229554920","rc":[{"atb":[[2.86,112.39],[2.96,53.33],[2.76,118.78]],"id":52671121},{"atl":[[10.5,14.66],[15.5,14.41]],"id":52671121},{"atb":[[3.6,40.2],[3.1,99.55],[3.35,88.96]],"id":62262930},{"atl":[[18.5,11.94],[13.5,11.14]],"id":62262930},{"atb":[[7.4,32.66],[8.4,28.25],[9.4,12.44]],"id":69577417},{"atl":[[140,1],[240,0.87]],"id":69577417},{"atb":[[17,13.06],[19.5,11.3],[24,4.54]],"id":69421986},{"atl":[[340,0.41],[440,0.47]],"id":69421986},{"atb":[[2.88,111.2],[2.98,52.79],[2.78,117.44]],"id":65460404},{"atl":[[10.5,14.66],[15.5,14.41]],"id":65460404},{"atb":[[9,26.13],[10,23.22],[12.5,9.08]],"id":64546979},{"atl":[[310,0.67],[210,0.66]],"id":64546979},{"atb":[[2.86,112.39],[2.96,53.33],[2.76,118.78]],"id":70003371},{"atl":[[10.5,14.66],[15.5,14.41]],"id":70003371}],"con":true,"img":false}]}
{"op":"mcm","clk":"11449670111","pt":1717313273218,"mc":[{"id":"1.229554920","rc":[{"atb":[[2.86,0],[2.96,0],[2.76,0]],"id":52671121},{"atl":[[10.5,0],[15.5,0]],"id":52671121},{"atb":[[3.6,0],[3.1,0],[3.35,0]],"id":62262930},{"atl":[[18.5,0],[13.5,0]],"id":62262930},{"atb":[[7.4,0],[8.4,0],[9.4,0]],"id":69577417},{"atl":[[140,0],[240,0]],"id":69577417},{"atb":[[17,0],[19.5,0],[24,0]],"id":69421986},{"atl":[[340,0],[440,0]],"id":69421986},{"atb":[[2.88,0],[2.98,0],[2.78,0]],"id":65460404},{"atl":[[10.5,0],[15.5,0]],"id":65460404},{"atb":[[9,0],[10,0],[12.5,0]],"id":64546979},{"atl":[[310,0],[210,0]],"id":64546979}],"con":true,"img":false}]}
{"op":"mcm","clk":"11449671034","pt":1717313291048,"mc":[{"id":"1.229554920","rc":[{"atb":[[2.8,116.14],[2.9,55.01],[2.7,122.97]],"id":52671121},{"atl":[[10,15.48],[15,14.93]],"id":52671121},{"spn":6.45,"spf":"NaN","id":52671121},{"atb":[[3.4,87.1],[3.15,97.23],[3.65,39.44]],"id":62262930},{"atl":[[16.5,8.99],[23,9.5]],"id":62262930},{"spn":10.07,"spf":"NaN","id":62262930},{"atb":[[9.8,11.87],[8.8,26.8],[7.8,30.74]],"id":69577417},{"atl":[[260,0.8],[160,0.87]],"id":69577417},{"spn":84.9,"spf":"NaN","id":69577417},{"atb":[[17.5,12.67],[20,11],[25,4.35]],"id":69421986},{"atl":[[350,0.39],[450,0.46]],"id":69421986},{"spn":187.5,"spf":"NaN","id":69421986},{"atb":[[2.86,112.39],[2.96,53.33],[2.76,118.78]],"id":65460404},{"atl":[[10.5,14.66],[15.5,14.41]],"id":65460404},{"spn":6.73,"spf":"NaN","id":65460404},{"atb":[[9,26.13],[10,23.22],[12.5,9.08]],"id":64546979},{"atl":[[310,0.67],[210,0.66]],"id":64546979},{"spn":111.25,"spf":"NaN","id":64546979},{"spn":6.73,"spf":"NaN","id":70003371}],"con":true,"img":false}]}
{"op":"mcm","clk":"11449673061","pt":1717313329596,"mc":[{"id":"1.229554920","rc":[{"atb":[[3.4,0],[3.15,0],[3.65,0]],"id":62262930},{"atl":[[16.5,0],[23,0]],"id":62262930},{"atb":[[17.5,0],[20,0],[25,0]],"id":69421986},{"atl":[[350,0],[450,0]],"id":69421986},{"atb":[[9,0],[10,0],[12.5,0]],"id":64546979},{"atl":[[310,0],[210,0]],"id":64546979}],"con":true,"img":false}]}
{"op":"mcm","clk":"11449673642","pt":1717313340501,"mc":[{"id":"1.229554920","rc":[{"atb":[[3.4,87.1],[3.15,97.23],[3.65,39.44]],"id":62262930},{"atl":[[16.5,8.99],[23,9.5]],"id":62262930},{"atb":[[17.5,12.67],[20,11],[25,4.35]],"id":69421986},{"atl":[[350,0.39],[450,0.46]],"id":69421986},{"atb":[[11,20.9],[13.5,8.36],[9.4,24.88]],"id":64546979},{"atl":[[320,0.65],[220,0.63]],"id":64546979}],"con":true,"img":false}]}
{"op":"mcm","clk":"11449680084","pt":1717313441226,"mc":[{"id":"1.229554920","rc":[{"atb":[[11,0],[13.5,0],[9.4,0]],"id":64546979},{"atl":[[320,0],[220,0]],"id":64546979},{"spn":500.5,"spf":"NaN","id":64546979}],"con":true,"img":false}]}
{"op":"mcm","clk":"11449680658","pt":1717313449128,"mc":[{"id":"1.229554920","rc":[{"atb":[[12,19],[9.8,23.75],[14.5,7.74]],"id":64546979},{"atl":[[330,0.63],[230,0.6]],"id":64546979}],"con":true,"img":false}]}
{"op":"mcm","clk":"11449693440","pt":1717313604823,"mc":[{"id":"1.229554920","rc":[{"atb":[[3.4,0],[3.15,0],[3.65,0]],"id":62262930},{"atl":[[16.5,0],[23,0]],"id":62262930},{"spn":495.5,"spf":"NaN","id":62262930},{"spn":122.25,"spf":"NaN","id":64546979}],"con":true,"img":false}]}
{"op":"mcm","clk":"11449695107","pt":1717313624185,"mc":[{"id":"1.229554920","rc":[{"atb":[[3.25,92.91],[3.5,83.62],[3.75,38]],"id":62262930},{"atl":[[17.5,8.44],[25,8.71]],"id":62262930}],"con":true,"img":false}]}
{"op":"mcm","clk":"11449753595","pt":1717314283452,"mc":[{"id":"1.229554920","rc":[{"atb":[[2.8,0],[2.9,0],[2.7,0]],"id":52671121},{"atl":[[10,0],[15,0]],"id":52671121},{"spn":495.51,"spf":"NaN","id":52671121},{"atb":[[3.25,0],[3.5,0],[3.75,0]],"id":62262930},{"atl":[[17.5,0],[25,0]],"id":62262930},{"atb":[[9.8,0],[8.8,0],[7.8,0]],"id":69577417},{"atl":[[260,0],[160,0]],"id":69577417},{"spn":495.51,"spf":"NaN","id":69577417},{"atb":[[17.5,0],[20,0],[25,0]],"id":69421986},{"atl":[[350,0],[450,0]],"id":69421986},{"spn":500.5,"spf":"NaN","id":69421986},{"atb":[[2.86,0],[2.96,0],[2.76,0]],"id":65460404},{"atl":[[10.5,0],[15.5,0]],"id":65460404},{"spn":500.51,"spf":"NaN","id":65460404},{"atb":[[12,0],[9.8,0],[14.5,0]],"id":64546979},{"atl":[[330,0],[230,0]],"id":64546979},{"spn":500.5,"spf":"NaN","id":64546979},{"atb":[[2.86,0],[2.96,0],[2.76,0]],"id":70003371},{"atl":[[10.5,0],[15.5,0]],"id":70003371},{"spn":495.5,"spf":"NaN","id":70003371}],"con":true,"img":false}]}
{"op":"mcm","clk":"11449754572","pt":1717314295496,"mc":[{"id":"1.229554920","rc":[{"atb":[[2.8,116.14],[2.9,55.01],[2.7,122.97]],"id":52671121},{"atl":[[10,15.48],[15,14.93]],"id":52671121},{"atb":[[3.25,92.91],[3.5,83.62],[3.75,38]],"id":62262930},{"atl":[[17.5,8.44],[25,8.71]],"id":62262930},{"atb":[[9.8,11.87],[8.8,26.8],[7.8,30.74]],"id":69577417},{"atl":[[260,0.8],[160,0.87]],"id":69577417},{"atb":[[17.5,12.67],[20,11],[25,4.35]],"id":69421986},{"atl":[[350,0.39],[450,0.46]],"id":69421986},{"atb":[[2.86,112.39],[2.96,53.33],[2.76,118.78]],"id":65460404},{"atl":[[10.5,14.66],[15.5,14.41]],"id":65460404},{"atb":[[12,19],[9.8,23.75],[14.5,7.74]],"id":64546979},{"atl":[[330,0.63],[230,0.6]],"id":64546979},{"atb":[[2.86,112.39],[2.96,53.33],[2.76,118.78]],"id":70003371},{"atl":[[10.5,14.66],[15.5,14.41]],"id":70003371}],"con":true,"img":false}]}
{"op":"mcm","clk":"11449830312","pt":1717315128434,"mc":[{"id":"1.229554920","marketDefinition":{"bspMarket":true,"turnInPlayEnabled":false,"persistenceEnabled":false,"marketBaseRate":7.0,"eventId":"33318908","eventTypeId":"4339","numberOfWinners":1,"bettingType":"ODDS","marketType":"WIN","marketTime":"2024-06-02T10:24:00.000Z","suspendTime":"2024-06-02T10:24:00.000Z","bspReconciled":false,"complete":true,"inPlay":false,"crossMatching":true,"runnersVoidable":false,"numberOfActiveRunners":7,"betDelay":0,"status":"OPEN","runners":[{"status":"ACTIVE","sortPriority":1,"id":65460404,"name":"1. Give Me Room"},{"status":"ACTIVE","sortPriority":2,"id":52671121,"name":"2. Elegant Ritzy"},{"status":"ACTIVE","sortPriority":3,"id":62262930,"name":"3. Canya Candy"},{"status":"ACTIVE","sortPriority":4,"id":69577417,"name":"4. Alpha Bloke"},{"status":"ACTIVE","sortPriority":5,"id":69421986,"name":"6. Back to Work"},{"status":"ACTIVE","sortPriority":6,"id":64546979,"name":"7. Sheas Entity"},{"status":"ACTIVE","sortPriority":7,"id":70003371,"name":"8. Yumali"}],"regulators":["MR_INT"],"venue":"Murray Bridge","countryCode":"AU","discountAllowed":true,"timezone":"Australia/Adelaide","openDate":"2024-06-02T08:21:00.000Z","version":5962317639,"name":"R7 455m Gr6","eventName":"Murray Bridge (AUS) 2nd Jun"},"rc":[{"atb":[[2.8,116.14],[2.9,55.01],[1.02,8.67],[2.7,122.97]],"id":52671121},{"atl":[[10,15.48],[15,14.93],[990,0.85]],"id":52671121},{"spn":6.45,"spf":"NaN","id":52671121},{"atb":[[1.01,17.35],[3.25,92.91],[3.5,83.62],[3.75,38]],"id":62262930},{"atl":[[17.5,8.44],[25,8.71],[990,0.85]],"id":62262930},{"spn":10.62,"spf":"NaN","id":62262930},{"atb":[[1.02,8.67],[9.8,11.87],[8.8,26.8],[7.8,30.74]],"id":69577417},{"atl":[[260,0.8],[160,0.87],[990,0.85]],"id":69577417},{"spn":84.9,"spf":"NaN","id":69577417},{"atb":[[17.5,12.67],[1.01,17.35],[20,11],[25,4.35]],"id":69421986},{"atl":[[350,0.39],[450,0.46],[1000,0.85]],"id":69421986},{"spn":187.5,"spf":"NaN","id":69421986},{"atb":[[2.86,112.39],[1.03,5.78],[2.96,53.33],[2.76,118.78]],"id":65460404},{"atl":[[10.5,14.66],[15.5,14.41],[1000,0.85]],"id":65460404},{"spn":6.73,"spf":"NaN","id":65460404},{"atb":[[1.01,17.35],[12,19],[9.8,23.75],[14.5,7.74]],"id":64546979},{"atl":[[330,0.63],[230,0.6],[1000,0.85]],"id":64546979},{"spn":122.25,"spf":"NaN","id":64546979},{"atb":[[1.01,17.35],[2.86,112.39],[2.96,53.33],[2.76,118.78]],"id":70003371},{"atl":[[10.5,14.66],[990,0.85],[15.5,14.41]],"id":70003371},{"spn":6.73,"spf":"NaN","id":70003371}],"con":true,"img":true}]}
{"op":"mcm","clk":"11449839664","pt":1717315178766,"mc":[{"id":"1.229554920","rc":[{"atl":[[34,10]],"id":52671121},{"spn":6.45,"spf":"NaN","id":52671121},{"spn":10.62,"spf":"NaN","id":62262930},{"spn":84.9,"spf":"NaN","id":69577417},{"spn":187.5,"spf":"NaN","id":69421986},{"atl":[[34,10]],"id":65460404},{"spn":6.73,"spf":"NaN","id":65460404},{"spn":122.25,"spf":"NaN","id":64546979},{"atl":[[34,10]],"id":70003371},{"spn":6.73,"spf":"NaN","id":70003371}],"con":true,"img":false}]}
{"op":"mcm","clk":"11449846040","pt":1717315242914,"mc":[{"id":"1.229554920","rc":[{"atb":[[1.51,98.04]],"id":62262930},{"atb":[[2.12,44.64],[1.51,98.04],[3.05,24.39]],"id":69577417},{"atb":[[6.2,9.62],[4.1,16.13],[2.12,44.64],[1.51,98.04],[3.05,24.39]],"id":69421986},{"atb":[[4.1,16.13],[2.12,44.64],[1.51,98.04],[3.05,24.39]],"id":64546979}],"con":true,"img":false}]}
{"op":"mcm","clk":"11449862803","pt":1717315411973,"mc":[{"id":"1.229554920","rc":[{"atb":[[2.8,0],[2.9,0],[2.7,0]],"id":52671121},{"atl":[[10,0],[15,0]],"id":52671121},{"spn":17.51,"spf":"NaN","id":52671121},{"atb":[[3.25,0],[3.5,0],[3.75,0]],"id":62262930},{"atl":[[17.5,0],[25,0]],"id":62262930},{"spn":495.75,"spf":"NaN","id":62262930},{"atb":[[9.8,0],[8.8,0],[7.8,0]],"id":69577417},{"atl":[[260,0],[160,0]],"id":69577417},{"spn":496.52,"spf":"NaN","id":69577417},{"atb":[[17.5,0],[20,0],[25,0]],"id":69421986},{"atl":[[350,0],[450,0]],"id":69421986},{"spn":503.1,"spf":"NaN","id":69421986},{"atb":[[2.86,0],[2.96,0],[2.76,0]],"id":65460404},{"atl":[[10.5,0],[15.5,0]],"id":65460404},{"spn":17.51,"spf":"NaN","id":65460404},{"atb":[[12,0],[9.8,0],[14.5,0]],"id":64546979},{"atl":[[330,0],[230,0]],"id":64546979},{"spn":502.05,"spf":"NaN","id":64546979},{"atb":[[2.86,0],[2.96,0],[2.76,0]],"id":70003371},{"atl":[[10.5,0],[15.5,0]],"id":70003371},{"spn":17.5,"spf":"NaN","id":70003371}],"con":true,"img":false}]}
{"op":"mcm","clk":"11449865331","pt":1717315436507,"mc":[{"id":"1.229554920","rc":[{"atb":[[2.8,116.14],[2.9,55.01],[2.7,122.97]],"id":52671121},{"atl":[[10,15.48],[15,14.93]],"id":52671121},{"atb":[[3.25,92.91],[3.5,83.62],[3.75,38]],"id":62262930},{"atl":[[17.5,8.44],[25,8.71]],"id":62262930},{"atb":[[9.8,11.87],[8.8,26.8],[7.8,30.74]],"id":69577417},{"atl":[[260,0.8],[160,0.87]],"id":69577417},{"atb":[[17.5,12.67],[20,11],[25,4.35]],"id":69421986},{"atl":[[350,0.39],[450,0.46]],"id":69421986},{"atb":[[2.86,112.39],[2.96,53.33],[2.76,118.78]],"id":65460404},{"atl":[[10.5,14.66],[15.5,14.41]],"id":65460404},{"atb":[[12,19],[9.8,23.75],[14.5,7.74]],"id":64546979},{"atl":[[330,0.63],[230,0.6]],"id":64546979},{"atb":[[2.86,112.39],[2.96,53.33],[2.76,118.78]],"id":70003371},{"atl":[[10.5,14.66],[15.5,14.41]],"id":70003371}],"con":true,"img":false}]}
{"op":"mcm","clk":"11449893681","pt":1717315712900,"mc":[{"id":"1.229554920","rc":[{"atb":[[2.8,0],[2.9,0],[2.7,0]],"id":52671121},{"atl":[[10,0],[15,0]],"id":52671121},{"atb":[[3.25,0],[3.5,0],[3.75,0]],"id":62262930},{"atl":[[17.5,0],[25,0]],"id":62262930},{"spn":84.9,"spf":"NaN","id":69577417},{"atb":[[17.5,0],[20,0],[25,0]],"id":69421986},{"atl":[[350,0],[450,0]],"id":69421986},{"atb":[[2.86,0],[2.96,0],[2.76,0]],"id":65460404},{"atl":[[10.5,0],[15.5,0]],"id":65460404},{"spn":122.25,"spf":"NaN","id":64546979},{"spn":6.73,"spf":"NaN","id":70003371}],"con":true,"img":false}]}
{"op":"mcm","clk":"11449896911","pt":1717315743088,"mc":[{"id":"1.229554920","rc":[{"atb":[[2.8,116.14],[2.9,55.01],[2.7,122.97]],"id":52671121},{"atl":[[10,15.48],[15,14.93]],"id":52671121},{"atb":[[3.25,92.91],[3.5,83.62],[3.75,38]],"id":62262930},{"atl":[[17.5,8.44],[25,8.71]],"id":62262930},{"atb":[[19.5,11.3],[24,9.08],[29,3.73]],"id":69421986},{"atl":[[400,0.35],[500,0.41]],"id":69421986},{"atb":[[2.86,112.39],[2.96,53.33],[2.76,118.78]],"id":65460404},{"atl":[[10.5,14.66],[15.5,14.41]],"id":65460404}],"con":true,"img":false}]}
{"op":"mcm","clk":"11449970486","pt":1717316552457,"mc":[{"id":"1.229554920","rc":[{"atb":[[2.8,0],[2.9,0],[2.7,0]],"id":52671121},{"atl":[[10,0],[15,0]],"id":52671121},{"atb":[[3.25,0],[3.5,0],[3.75,0]],"id":62262930},{"atl":[[17.5,0],[25,0]],"id":62262930},{"atb":[[9.8,0],[8.8,0],[7.8,0]],"id":69577417},{"atl":[[260,0],[160,0]],"id":69577417},{"spn":496.52,"spf":"NaN","id":69577417},{"atb":[[19.5,0],[24,0],[29,0]],"id":69421986},{"atl":[[400,0],[500,0]],"id":69421986},{"atb":[[2.86,0],[2.96,0],[2.76,0]],"id":65460404},{"atl":[[10.5,0],[15.5,0]],"id":65460404},{"atb":[[12,0],[9.8,0],[14.5,0]],"id":64546979},{"atl":[[330,0],[230,0]],"id":64546979},{"spn":502.05,"spf":"NaN","id":64546979},{"atb":[[2.86,0],[2.96,0],[2.76,0]],"id":70003371},{"atl":[[10.5,0],[15.5,0]],"id":70003371},{"spn":17.5,"spf":"NaN","id":70003371}],"con":true,"img":false}]}
{"op":"mcm","clk":"11449971651","pt":1717316571019,"mc":[{"id":"1.229554920","rc":[{"atb":[[2.8,116.14],[2.9,55.01],[2.7,122.97]],"id":52671121},{"atl":[[10,15.48],[15,14.93]],"id":52671121},{"atb":[[3.25,92.91],[3.5,83.62],[3.75,38]],"id":62262930},{"atl":[[17.5,8.44],[25,8.71]],"id":62262930},{"atb":[[9.8,11.87],[8.8,26.8],[7.8,30.74]],"id":69577417},{"atl":[[260,0.8],[160,0.87]],"id":69577417},{"atb":[[19.5,11.3],[24,9.08],[29,3.73]],"id":69421986},{"atl":[[400,0.35],[500,0.41]],"id":69421986},{"atb":[[2.86,112.39],[2.96,53.33],[2.76,118.78]],"id":65460404},{"atl":[[10.5,14.66],[15.5,14.41]],"id":65460404},{"atb":[[12,19],[9.8,23.75],[14.5,7.74]],"id":64546979},{"atl":[[330,0.63],[230,0.6]],"id":64546979},{"atb":[[2.86,112.39],[2.96,53.33],[2.76,118.78]],"id":70003371},{"atl":[[10.5,14.66],[15.5,14.41]],"id":70003371}],"con":true,"img":false}]}
{"op":"mcm","clk":"11449998188","pt":1717316924230,"mc":[{"id":"1.229554920","rc":[{"atl":[[1000,1]],"id":52671121},{"spn":6.45,"spf":"NaN","id":52671121},{"atl":[[1000,1]],"id":62262930},{"spn":10.62,"spf":"NaN","id":62262930},{"atl":[[1000,1]],"id":69577417},{"spn":84.9,"spf":"NaN","id":69577417},{"atl":[[1000,1.85]],"id":69421986},{"spn":214.5,"spf":"NaN","id":69421986},{"atl":[[1000,1.85]],"id":65460404},{"spn":6.73,"spf":"NaN","id":65460404},{"atl":[[1000,1.85]],"id":64546979},{"spn":122.25,"spf":"NaN","id":64546979},{"atl":[[1000,1]],"id":70003371},{"spn":6.73,"spf":"NaN","id":70003371}],"con":true,"img":false}]}
{"op":"mcm","clk":"11450051667","pt":1717317460704,"mc":[{"id":"1.229554920","rc":[{"atb":[[2.8,0],[2.9,0],[2.7,0]],"id":52671121},{"atl":[[10,0],[15,0]],"id":52671121},{"spn":17.51,"spf":"NaN","id":52671121},{"atb":[[3.25,0],[3.5,0],[3.75,0]],"id":62262930},{"atl":[[17.5,0],[25,0]],"id":62262930},{"spn":495.75,"spf":"NaN","id":62262930},{"atb":[[9.8,0],[8.8,0],[7.8,0]],"id":69577417},{"atl":[[260,0],[160,0]],"id":69577417},{"spn":496.52,"spf":"NaN","id":69577417},{"atb":[[19.5,0],[24,0],[29,0]],"id":69421986},{"atl":[[400,0],[500,0]],"id":69421986},{"spn":503.1,"spf":"NaN","id":69421986},{"atb":[[2.86,0],[2.96,0],[2.76,0]],"id":65460404},{"atl":[[10.5,0],[15.5,0]],"id":65460404},{"spn":17.51,"spf":"NaN","id":65460404},{"atb":[[12,0],[9.8,0],[14.5,0]],"id":64546979},{"atl":[[330,0],[230,0]],"id":64546979},{"spn":502.05,"spf":"NaN","id":64546979},{"atb":[[2.86,0],[2.96,0],[2.76,0]],"id":70003371},{"atl":[[10.5,0],[15.5,0]],"id":70003371},{"spn":17.5,"spf":"NaN","id":70003371}],"con":true,"img":false}]}
{"op":"mcm","clk":"11450053353","pt":1717317479872,"mc":[{"id":"1.229554920","rc":[{"atb":[[2.8,116.14],[2.9,55.01],[2.7,122.97]],"id":52671121},{"atl":[[10,15.48],[15,14.93]],"id":52671121},{"atb":[[3.25,92.91],[3.5,83.62],[3.75,38]],"id":62262930},{"atl":[[17.5,8.44],[25,8.71]],"id":62262930},{"atb":[[9.8,11.87],[8.8,26.8],[7.8,30.74]],"id":69577417},{"atl":[[260,0.8],[160,0.87]],"id":69577417},{"atb":[[19.5,11.3],[24,9.08],[29,3.73]],"id":69421986},{"atl":[[400,0.35],[500,0.41]],"id":69421986},{"atb":[[2.86,112.39],[2.96,53.33],[2.76,118.78]],"id":65460404},{"atl":[[10.5,14.66],[15.5,14.41]],"id":65460404},{"atb":[[12,19],[9.8,23.75],[14.5,7.74]],"id":64546979},{"atl":[[330,0.63],[230,0.6]],"id":64546979},{"atb":[[2.86,112.39],[2.96,53.33],[2.76,118.78]],"id":70003371},{"atl":[[10.5,14.66],[15.5,14.41]],"id":70003371}],"con":true,"img":false}]}
{"op":"mcm","clk":"11450128152","pt":1717318323973,"mc":[{"id":"1.229554920","rc":[{"atb":[[2.8,0],[2.9,0],[2.7,0]],"id":52671121},{"atl":[[10,0],[15,0]],"id":52671121},{"atb":[[3.25,0],[3.5,0],[3.75,0]],"id":62262930},{"atl":[[17.5,0],[25,0]],"id":62262930},{"atb":[[9.8,0],[8.8,0],[7.8,0]],"id":69577417},{"atl":[[260,0],[160,0]],"id":69577417},{"atb":[[19.5,0],[24,0],[29,0]],"id":69421986},{"atl":[[400,0],[500,0]],"id":69421986},{"atb":[[2.86,0],[2.96,0],[2.76,0]],"id":65460404},{"atl":[[10.5,0],[15.5,0]],"id":65460404},{"atb":[[12,0],[9.8,0],[14.5,0]],"id":64546979},{"atl":[[330,0],[230,0]],"id":64546979},{"atb":[[2.86,0],[2.96,0],[2.76,0]],"id":70003371},{"atl":[[10.5,0],[15.5,0]],"id":70003371}],"con":true,"img":false}]}
{"op":"mcm","clk":"11450129253","pt":1717318335990,"mc":[{"id":"1.229554920","rc":[{"atb":[[2.8,116.14],[2.9,55.01],[2.7,122.97]],"id":52671121},{"atl":[[10,15.48],[15,14.93]],"id":52671121},{"atb":[[3.25,92.91],[3.5,83.62],[3.75,38]],"id":62262930},{"atl":[[17.5,8.44],[25,8.71]],"id":62262930},{"atb":[[9.8,11.87],[8.8,26.8],[7.8,30.74]],"id":69577417},{"atl":[[260,0.8],[160,0.87]],"id":69577417},{"atb":[[19.5,11.3],[24,9.08],[29,3.73]],"id":69421986},{"atl":[[400,0.35],[500,0.41]],"id":69421986},{"atb":[[2.86,112.39],[2.96,53.33],[2.76,118.78]],"id":65460404},{"atl":[[10.5,14.66],[15.5,14.41]],"id":65460404},{"atb":[[12,19],[9.8,23.75],[14.5,7.74]],"id":64546979},{"atl":[[330,0.63],[230,0.6]],"id":64546979},{"atb":[[2.86,112.39],[2.96,53.33],[2.76,118.78]],"id":70003371},{"atl":[[10.5,14.66],[15.5,14.41]],"id":70003371}],"con":true,"img":false}]}
{"op":"mcm","clk":"11450149867","pt":1717318573541,"mc":[{"id":"1.229554920","rc":[{"atb":[[2.82,66.44],[2.98,28.34]],"id":52671121},{"atl":[[9.6,6.52],[9.8,13.6]],"id":52671121},{"spn":6.29,"spf":"NaN","id":52671121},{"atb":[[3.55,43.49],[3.65,21.17]],"id":62262930},{"atl":[[17,6.93],[13,4.67]],"id":62262930},{"spn":8.37,"spf":"NaN","id":62262930},{"atb":[[11.5,5.34],[9.8,23.73]],"id":69577417},{"atl":[[70,2.61],[90,2.61]],"id":69577417},{"spn":40.75,"spf":"NaN","id":69577417},{"atb":[[22,6.27],[26,2.61]],"id":69421986},{"atl":[[340,0.16],[390,2.61]],"id":69421986},{"spn":184.5,"spf":"NaN","id":69421986},{"atb":[[2.98,28.34],[2.78,70.1]],"id":65460404},{"atl":[[9.2,6.84],[10,13.6]],"id":65460404},{"spn":6.09,"spf":"NaN","id":65460404},{"atb":[[12.5,10.98],[14.5,11.89]],"id":64546979},{"atl":[[130,2.61],[110,2.61]],"id":64546979},{"spn":62.25,"spf":"NaN","id":64546979},{"atb":[[2.98,28.34],[2.78,64.95]],"id":70003371},{"atl":[[9.2,6.84],[10,12.84]],"id":70003371},{"spn":6.09,"spf":"NaN","id":70003371}],"con":true,"img":false}]}
{"op":"mcm","clk":"11450156115","pt":1717318637197,"mc":[{"id":"1.229554920","rc":[{"atl":[[990,0.17]],"id":52671121},{"atl":[[990,0.17]],"id":62262930},{"atl":[[990,0.17]],"id":69577417},{"atl":[[1000,1.17]],"id":69421986},{"atl":[[1000,1.17]],"id":65460404},{"atl":[[1000,1.17]],"id":64546979},{"atl":[[990,0.17]],"id":70003371}],"con":true,"img":false}]}
{"op":"mcm","clk":"11450157250","pt":1717318647605,"mc":[{"id":"1.229554920","rc":[{"atb":[[2.82,0]],"id":52671121},{"atb":[[3.65,0]],"id":62262930},{"atb":[[22,0]],"id":69421986},{"atb":[[14.5,7.74]],"id":64546979}],"con":true,"img":false}]}
{"op":"mcm","clk":"11450157259","pt":1717318647705,"mc":[{"id":"1.229554920","rc":[{"atb":[[2.92,66.44]],"id":52671121},{"atb":[[3.8,21.17]],"id":62262930},{"atb":[[25,6.27]],"id":69421986},{"atb":[[15,4.15]],"id":64546979}],"con":true,"img":false}]}
{"op":"mcm","clk":"11450165021","pt":1717318727975,"mc":[{"id":"1.229554920","rc":[{"spn":8.4,"spf":"NaN","id":62262930},{"atb":[[26,0]],"id":69421986},{"spn":62.5,"spf":"NaN","id":64546979}],"con":true,"img":false}]}
{"op":"mcm","clk":"11450165030","pt":1717318728077,"mc":[{"id":"1.229554920","rc":[{"atb":[[30,2.61]],"id":69421986}],"con":true,"img":false}]}
{"op":"mcm","clk":"11450208375","pt":1717319182926,"mc":[{"id":"1.229554920","rc":[{"atb":[[2.8,0],[2.9,0],[2.7,0]],"id":52671121},{"atl":[[10,0],[15,0]],"id":52671121},{"atb":[[3.25,0],[3.5,0],[3.75,0]],"id":62262930},{"atl":[[17.5,0],[25,0]],"id":62262930},{"atb":[[9.8,11.86],[8.8,0],[7.8,0]],"id":69577417},{"atl":[[260,0],[160,0]],"id":69577417},{"atb":[[19.5,0],[24,0],[29,0]],"id":69421986},{"atl":[[400,0],[500,0]],"id":69421986},{"spn":185.0,"spf":"NaN","id":69421986},{"atb":[[2.86,0],[2.96,0],[2.76,0]],"id":65460404},{"atl":[[10.5,0],[15.5,0]],"id":65460404},{"atb":[[12,0],[9.8,0],[14.5,0]],"id":64546979},{"atl":[[330,0],[230,0]],"id":64546979},{"atb":[[2.86,0],[2.96,0],[2.76,0]],"id":70003371},{"atl":[[10.5,0],[15.5,0]],"id":70003371}],"con":true,"img":false}]}
{"op":"mcm","clk":"11450209773","pt":1717319196412,"mc":[{"id":"1.229554920","rc":[{"atl":[[12.5,10.46]],"id":52671121},{"atl":[[12,10.51]],"id":70003371}],"con":true,"img":false}]}
{"op":"mcm","clk":"11450209784","pt":1717319196514,"mc":[{"id":"1.229554920","rc":[{"atb":[[2.92,0]],"id":52671121},{"atl":[[9.8,0]],"id":52671121},{"atb":[[3.8,0],[3.55,0]],"id":62262930},{"atb":[[25,0],[30,0]],"id":69421986},{"atl":[[390,0]],"id":69421986},{"atb":[[2.98,0],[2.78,0]],"id":65460404},{"atl":[[10,0]],"id":65460404},{"atb":[[2.98,0],[2.78,0]],"id":70003371},{"atl":[[10,0]],"id":70003371}],"con":true,"img":false}]}
{"op":"mcm","clk":"11450209795","pt":1717319196621,"mc":[{"id":"1.229554920","rc":[{"atb":[[2.68,66.44]],"id":52671121},{"atb":[[3.25,43.49],[3.65,21.17]],"id":62262930},{"atb":[[22,6.27],[26,2.61]],"id":69421986},{"atl":[[450,2.61]],"id":69421986},{"atb":[[2.86,28.34],[2.58,70.1]],"id":65460404},{"atl":[[11.5,13.6]],"id":65460404},{"atb":[[2.86,28.34],[2.58,64.95]],"id":70003371}],"con":true,"img":false}]}
{"op":"mcm","clk":"11450210471","pt":1717319203311,"mc":[{"id":"1.229554920","rc":[{"atb":[[2.8,116.14],[2.9,55.01],[2.7,122.97]],"id":52671121},{"atl":[[10,15.48],[15,14.93]],"id":52671121},{"atb":[[3.25,136.41],[3.5,83.62],[3.75,38]],"id":62262930},{"atl":[[17.5,8.44],[25,8.71]],"id":62262930},{"atb":[[9.8,23.73],[8.8,26.8],[7.8,30.74]],"id":69577417},{"atl":[[260,0.8],[160,0.87]],"id":69577417},{"atb":[[19.5,11.3],[24,9.08],[29,3.73]],"id":69421986},{"atl":[[400,0.35],[500,0.41]],"id":69421986},{"atb":[[2.86,140.73],[2.96,53.33],[2.76,118.78]],"id":65460404},{"atl":[[10.5,14.66],[15.5,14.41]],"id":65460404},{"atb":[[12,19],[9.8,23.75],[14.5,7.74]],"id":64546979},{"atl":[[330,0.63],[230,0.6]],"id":64546979},{"atb":[[2.86,140.73],[2.96,53.33],[2.76,118.78]],"id":70003371},{"atl":[[10.5,14.66],[15.5,14.41]],"id":70003371}],"con":true,"img":false}]}
{"op":"mcm","clk":"11450217830","pt":1717319275219,"mc":[{"id":"1.229554920","rc":[{"atl":[[9.8,13.6]],"id":52671121},{"spn":8.37,"spf":"NaN","id":62262930},{"spn":184.5,"spf":"NaN","id":69421986},{"spn":6.08,"spf":"NaN","id":65460404},{"atl":[[10,12.84]],"id":70003371},{"spn":6.08,"spf":"NaN","id":70003371}],"con":true,"img":false}]}
{"op":"mcm","clk":"11450217840","pt":1717319275323,"mc":[{"id":"1.229554920","rc":[{"atb":[[2.68,0]],"id":52671121},{"atl":[[12.5,0]],"id":52671121},{"atb":[[3.25,92.91],[3.65,0]],"id":62262930},{"atb":[[22,0]],"id":69421986},{"atl":[[450,0]],"id":69421986},{"atb":[[2.86,112.39],[2.58,0]],"id":65460404},{"atl":[[11.5,0]],"id":65460404},{"atb":[[2.86,112.39],[2.58,0]],"id":70003371},{"atl":[[12,0]],"id":70003371}],"con":true,"img":false}]}
{"op":"mcm","clk":"11450217853","pt":1717319275380,"mc":[{"id":"1.229554920","rc":[{"atb":[[2.92,66.44]],"id":52671121},{"atb":[[3.8,21.17],[3.55,43.49]],"id":62262930},{"atb":[[25,6.27]],"id":69421986},{"atl":[[390,2.61]],"id":69421986},{"atb":[[2.98,28.34],[2.78,70.1]],"id":65460404},{"atl":[[10,13.6]],"id":65460404},{"atb":[[2.98,28.34],[2.78,64.95]],"id":70003371}],"con":true,"img":false}]}
{"op":"mcm","clk":"11450225312","pt":1717319353731,"mc":[{"id":"1.229554920","rc":[{"spn":8.4,"spf":"NaN","id":62262930},{"atb":[[26,0]],"id":69421986},{"spn":6.09,"spf":"NaN","id":65460404},{"spn":6.09,"spf":"NaN","id":70003371}],"con":true,"img":false}]}
{"op":"mcm","clk":"11450225319","pt":1717319353833,"mc":[{"id":"1.229554920","rc":[{"atb":[[30,2.61]],"id":69421986}],"con":true,"img":false}]}
{"op":"mcm","clk":"11450236617","pt":1717319476388,"mc":[{"id":"1.229554920","rc":[{"atb":[[4.1,16.13]],"id":69577417},{"spn":185.0,"spf":"NaN","id":69421986}],"con":true,"img":false}]}
{"op":"mcm","clk":"11450279069","pt":1717319964945,"mc":[{"id":"1.229554920","rc":[{"atb":[[2.8,0],[2.9,0],[2.7,0]],"id":52671121},{"atl":[[10,0],[15,0]],"id":52671121},{"atb":[[3.25,0],[3.5,0],[3.75,0]],"id":62262930},{"atl":[[17.5,0],[25,0]],"id":62262930},{"atb":[[9.8,11.86],[8.8,0],[7.8,0]],"id":69577417},{"atl":[[260,0],[160,0]],"id":69577417},{"atb":[[2.86,0],[2.96,0],[2.76,0]],"id":65460404},{"atl":[[10.5,0],[15.5,0]],"id":65460404},{"atb":[[12,0],[9.8,0],[14.5,0]],"id":64546979},{"atl":[[330,0],[230,0]],"id":64546979}],"con":true,"img":false}]}
{"op":"mcm","clk":"11450279412","pt":1717319969068,"mc":[{"id":"1.229554920","rc":[{"atb":[[2.92,0]],"id":52671121},{"atl":[[9.8,0],[12.5,10.46]],"id":52671121},{"atb":[[3.8,0],[3.55,0]],"id":62262930},{"atb":[[2.98,0],[2.78,0]],"id":65460404},{"atl":[[10,0]],"id":65460404}],"con":true,"img":false}]}
{"op":"mcm","clk":"11450279421","pt":1717319969173,"mc":[{"id":"1.229554920","rc":[{"atb":[[2.68,66.44]],"id":52671121},{"atb":[[3.25,43.49],[3.65,21.17]],"id":62262930},{"atb":[[2.86,28.34],[2.58,70.1]],"id":65460404},{"atl":[[11.5,13.6]],"id":65460404}],"con":true,"img":false}]}
{"op":"mcm","clk":"11450280020","pt":1717319977073,"mc":[{"id":"1.229554920","rc":[{"atb":[[2.58,132.31],[2.78,58.72],[2.68,190.88]],"id":52671121},{"atl":[[13.5,16.72],[9.4,16.58]],"id":52671121},{"atb":[[3.25,136.41],[3.5,83.62],[3.75,38]],"id":62262930},{"atl":[[17.5,8.44],[25,8.71]],"id":62262930},{"atb":[[9.2,25.49],[10.5,11],[8.2,29.03]],"id":69577417},{"atl":[[280,0.74],[180,0.77]],"id":69577417},{"atb":[[2.86,140.73],[2.96,53.33],[2.76,118.78]],"id":65460404},{"atl":[[10.5,14.66],[15.5,14.41]],"id":65460404},{"atb":[[10.5,22],[13,17.42],[15.5,7.2]],"id":64546979},{"atl":[[340,0.61],[240,0.58]],"id":64546979}],"con":true,"img":false}]}
{"op":"mcm","clk":"11450280832","pt":1717319987555,"mc":[{"id":"1.229554920","rc":[{"atb":[[2.98,0]],"id":52671121}],"con":true,"img":false}]}
{"op":"mcm","clk":"11450280839","pt":1717319987661,"mc":[{"id":"1.229554920","rc":[{"atb":[[2.9,28.34]],"id":52671121}],"con":true,"img":false}]}
{"op":"mcm","clk":"11450282035","pt":1717320001904,"mc":[{"id":"1.229554920","rc":[{"atb":[[30,0]],"id":69421986}],"con":true,"img":false}]}
{"op":"mcm","clk":"11450282043","pt":1717320002007,"mc":[{"id":"1.229554920","rc":[{"atb":[[26,2.61]],"id":69421986}],"con":true,"img":false}]}
{"op":"mcm","clk":"11450282277","pt":1717320004919,"mc":[{"id":"1.229554920","rc":[{"atb":[[2.58,0],[2.78,0],[2.68,66.44]],"id":52671121},{"atl":[[13.5,0],[9.4,0]],"id":52671121},{"atb":[[3.25,43.49],[3.5,0],[3.75,0]],"id":62262930},{"atl":[[17.5,0],[25,0]],"id":62262930},{"atb":[[9.2,0],[10.5,0],[8.2,0]],"id":69577417},{"atl":[[280,0],[180,0]],"id":69577417},{"atb":[[19.5,0],[24,0],[29,0]],"id":69421986},{"atl":[[400,0],[500,0]],"id":69421986},{"atb":[[2.86,28.34],[2.96,0],[2.76,0]],"id":65460404},{"atl":[[10.5,0],[15.5,0]],"id":65460404},{"atb":[[10.5,0],[13,0],[15.5,0]],"id":64546979},{"atl":[[340,0],[240,0]],"id":64546979},{"atb":[[2.86,0],[2.96,0],[2.76,0]],"id":70003371},{"atl":[[10.5,0],[15.5,0]],"id":70003371}],"con":true,"img":false}]}
{"op":"mcm","clk":"11450283138","pt":1717320015425,"mc":[{"id":"1.229554920","rc":[{"atb":[[2.38,151.49],[2.58,66.16],[2.48,141.25]],"id":52671121},{"atl":[[11,20.9],[8.4,18.83]],"id":52671121},{"atb":[[3.25,136.41],[3.5,83.62],[3.75,38]],"id":62262930},{"atl":[[17.5,8.44],[25,8.71]],"id":62262930},{"atb":[[9.6,24.31],[8.6,27.5],[11.5,15.29]],"id":69577417},{"atl":[[300,0.7],[200,0.7]],"id":69577417},{"atb":[[19.5,11.3],[24,9.08],[29,3.73]],"id":69421986},{"atl":[[400,0.35],[500,0.41]],"id":69421986},{"atb":[[2.88,111.2],[2.98,52.79],[2.78,117.44]],"id":65460404},{"atl":[[10.5,14.66],[15.5,14.41]],"id":65460404},{"atb":[[16.5,6.74],[11.5,19.91],[14,16.08]],"id":64546979},{"atl":[[350,0.59],[250,0.55]],"id":64546979},{"atb":[[2.86,112.39],[2.96,53.33],[2.76,118.78]],"id":70003371},{"atl":[[10.5,14.66],[15.5,14.41]],"id":70003371}],"con":true,"img":false}]}
{"op":"mcm","clk":"11450283291","pt":1717320017340,"mc":[{"id":"1.229554920","rc":[{"atl":[[9.6,0]],"id":52671121}],"con":true,"img":false}]}
{"op":"mcm","clk":"11450283299","pt":1717320017397,"mc":[{"id":"1.229554920","rc":[{"atl":[[9.2,6.52]],"id":52671121}],"con":true,"img":false}]}
{"op":"mcm","clk":"11450283849","pt":1717320025116,"mc":[{"id":"1.229554920","rc":[{"spn":5.65,"spf":"NaN","id":52671121},{"atb":[[3.65,0]],"id":62262930},{"spn":8.37,"spf":"NaN","id":62262930},{"spn":184.5,"spf":"NaN","id":69421986},{"atb":[[2.86,0]],"id":65460404},{"spn":63.25,"spf":"NaN","id":64546979}],"con":true,"img":false}]}
{"op":"mcm","clk":"11450283860","pt":1717320025216,"mc":[{"id":"1.229554920","rc":[{"atb":[[3.8,21.17]],"id":62262930},{"atb":[[3,28.34]],"id":65460404}],"con":true,"img":false}]}
{"op":"mcm","clk":"11450284448","pt":1717320032614,"mc":[{"id":"1.229554920","rc":[{"atl":[[12.5,0]],"id":52671121},{"atb":[[3.25,92.91]],"id":62262930},{"atb":[[2.58,0]],"id":65460404},{"atl":[[11.5,0]],"id":65460404}],"con":true,"img":false}]}
{"op":"mcm","clk":"11450284456","pt":1717320032714,"mc":[{"id":"1.229554920","rc":[{"atl":[[10.5,10.46]],"id":52671121},{"atb":[[3.55,43.49]],"id":62262930},{"atb":[[2.8,70.1]],"id":65460404},{"atl":[[10,13.6]],"id":65460404}],"con":true,"img":false}]}
{"op":"mcm","clk":"11450284713","pt":1717320037222,"mc":[{"id":"1.229554920","rc":[{"atb":[[2.38,0],[2.58,0],[2.48,0]],"id":52671121},{"atl":[[11,0],[8.4,0]],"id":52671121},{"atb":[[19.5,0],[24,0],[29,0]],"id":69421986},{"atl":[[400,0],[500,0]],"id":69421986},{"atb":[[2.88,0],[2.98,0],[2.78,0]],"id":65460404},{"atl":[[10.5,0],[15.5,0]],"id":65460404},{"atb":[[2.86,0],[2.96,0],[2.76,0]],"id":70003371},{"atl":[[10.5,0],[15.5,0]],"id":70003371}],"con":true,"img":false}]}
{"op":"mcm","clk":"11450284773","pt":1717320038357,"mc":[{"id":"1.229554920","rc":[{"atl":[[9.2,0],[10.5,0]],"id":52671121},{"atb":[[25,0]],"id":69421986},{"atl":[[390,0]],"id":69421986},{"atb":[[2.8,0],[3,0]],"id":65460404},{"atl":[[10,0]],"id":65460404},{"atb":[[15,0]],"id":64546979},{"atb":[[2.98,0],[2.78,0]],"id":70003371},{"atl":[[12,10.51]],"id":70003371}],"con":true,"img":false}]}
{"op":"mcm","clk":"11450284785","pt":1717320038459,"mc":[{"id":"1.229554920","rc":[{"atl":[[9.6,6.52],[12.5,10.46]],"id":52671121},{"atb":[[22,6.27]],"id":69421986},{"atl":[[450,2.61]],"id":69421986},{"atb":[[2.86,28.34],[2.58,70.1]],"id":65460404},{"atl":[[11.5,13.6]],"id":65460404},{"atb":[[17,4.15]],"id":64546979},{"atb":[[2.84,28.34],[2.58,64.95]],"id":70003371},{"atl":[[10,0]],"id":70003371}],"con":true,"img":false}]}
{"op":"mcm","clk":"11450285282","pt":1717320045750,"mc":[{"id":"1.229554920","rc":[{"atb":[[2.38,151.49],[2.58,66.16],[2.48,141.25]],"id":52671121},{"atl":[[11,20.9],[8.4,18.83]],"id":52671121},{"atb":[[19.5,11.3],[24,9.08],[29,3.73]],"id":69421986},{"atl":[[400,0.35],[500,0.41]],"id":69421986},{"atb":[[2.88,111.2],[2.98,52.79],[2.78,117.44]],"id":65460404},{"atl":[[10.5,14.66],[15.5,14.41]],"id":65460404},{"atb":[[2.86,112.39],[2.96,53.33],[2.76,118.78]],"id":70003371},{"atl":[[10.5,14.66],[15.5,14.41]],"id":70003371}],"con":true,"img":false}]}
{"op":"mcm","clk":"11450285949","pt":1717320056949,"mc":[{"id":"1.229554920","rc":[{"atb":[[12.5,0]],"id":64546979}],"con":true,"img":false}]}
{"op":"mcm","clk":"11450285959","pt":1717320057054,"mc":[{"id":"1.229554920","rc":[{"atb":[[14.5,10.98]],"id":64546979}],"con":true,"img":false}]}
{"op":"mcm","clk":"11450286104","pt":1717320059471,"mc":[{"id":"1.229554920","rc":[{"atb":[[2.9,0]],"id":52671121},{"atl":[[9.2,0]],"id":70003371}],"con":true,"img":false}]}
{"op":"mcm","clk":"11450286111","pt":1717320059576,"mc":[{"id":"1.229554920","rc":[{"atb":[[2.96,28.34]],"id":52671121},{"atl":[[9,6.84]],"id":70003371}],"con":true,"img":false}]}
{"op":"mcm","clk":"11450286909","pt":1717320072505,"mc":[{"id":"1.229554920","rc":[{"atb":[[2.38,0],[2.58,0],[2.48,0]],"id":52671121},{"atl":[[11,0],[8.4,0]],"id":52671121},{"atb":[[3.25,0],[3.5,0],[3.75,0]],"id":62262930},{"atl":[[17.5,0],[25,0]],"id":62262930},{"atb":[[9.6,0],[8.6,0],[11.5,5.34]],"id":69577417},{"atl":[[300,0],[200,0]],"id":69577417},{"atb":[[2.88,0],[2.98,0],[2.78,0]],"id":65460404},{"atl":[[10.5,0],[15.5,0]],"id":65460404},{"atb":[[16.5,0],[11.5,0],[14,0]],"id":64546979},{"atl":[[350,0],[250,0]],"id":64546979},{"atb":[[2.86,0],[2.96,0],[2.76,0]],"id":70003371},{"atl":[[10.5,0],[15.5,0]],"id":70003371}],"con":true,"img":false}]}
{"op":"mcm","clk":"11450287239","pt":1717320076886,"mc":[{"id":"1.229554920","rc":[{"atb":[[2.86,0]],"id":65460404},{"atb":[[2.84,0]],"id":70003371}],"con":true,"img":false}]}
{"op":"mcm","clk":"11450287246","pt":1717320076993,"mc":[{"id":"1.229554920","rc":[{"atb":[[3,28.34]],"id":65460404},{"atb":[[2.98,28.34]],"id":70003371}],"con":true,"img":false}]}
{"op":"mcm","clk":"11450287958","pt":1717320087503,"mc":[{"id":"1.229554920","rc":[{"atb":[[2.38,151.49],[2.58,66.16],[2.48,141.25]],"id":52671121},{"atl":[[11,20.9],[8.4,18.83]],"id":52671121},{"spn":5.68,"spf":"NaN","id":52671121},{"atb":[[3.4,87.1],[3.9,36.04],[3.65,78.88]],"id":62262930},{"atl":[[19,7.74],[28,7.74]],"id":62262930},{"spn":8.45,"spf":"NaN","id":62262930},{"atb":[[9.6,24.31],[8.6,27.5],[11.5,15.29]],"id":69577417},{"atl":[[300,0.7],[200,0.7]],"id":69577417},{"atb":[[2.88,111.2],[2.98,52.79],[2.78,117.44]],"id":65460404},{"atl":[[10.5,14.66],[15.5,14.41]],"id":65460404},{"spn":6.1,"spf":"NaN","id":65460404},{"atb":[[16.5,6.74],[11.5,19.91],[14,16.08]],"id":64546979},{"atl":[[350,0.59],[250,0.55]],"id":64546979},{"spn":63.5,"spf":"NaN","id":64546979},{"atb":[[2.86,112.39],[2.96,53.33],[2.76,118.78]],"id":70003371},{"atl":[[10.5,14.66],[15.5,14.41]],"id":70003371},{"spn":5.99,"spf":"NaN","id":70003371}],"con":true,"img":false}]}
{"op":"mcm","clk":"11450288313","pt":1717320092398,"mc":[{"id":"1.229554920","rc":[{"atb":[[2.5,80.56],[2.96,0],[2.68,0]],"id":52671121},{"atl":[[9.6,0]],"id":52671121},{"atl":[[70,0]],"id":69577417},{"atl":[[9.2,0]],"id":65460404},{"atl":[[130,0]],"id":64546979}],"con":true,"img":false}]}
{"op":"mcm","clk":"11450288325","pt":1717320092503,"mc":[{"id":"1.229554920","rc":[{"atb":[[2.6,28.34]],"id":52671121},{"atl":[[8.2,6.52]],"id":52671121},{"atl":[[75,2.61]],"id":69577417},{"atl":[[9.6,6.84]],"id":65460404},{"atl":[[150,2.61]],"id":64546979}],"con":true,"img":false}]}
{"op":"mcm","clk":"11450288823","pt":1717320101402,"mc":[{"id":"1.229554920","rc":[{"atl":[[450,0]],"id":69421986},{"atl":[[11.5,0]],"id":65460404},{"atb":[[2.58,0]],"id":70003371},{"atl":[[10,12.84],[12,0]],"id":70003371}],"con":true,"img":false}]}
{"op":"mcm","clk":"11450288831","pt":1717320101501,"mc":[{"id":"1.229554920","rc":[{"atl":[[390,2.61]],"id":69421986},{"atl":[[10,13.6]],"id":65460404},{"atb":[[2.78,64.95]],"id":70003371}],"con":true,"img":false}]}
{"op":"mcm","clk":"11450289692","pt":1717320114535,"mc":[{"id":"1.229554920","rc":[{"atb":[[2.38,0],[2.58,0],[2.48,0]],"id":52671121},{"atl":[[11,0],[8.4,0]],"id":52671121},{"atb":[[3.4,0],[3.9,0],[3.65,0]],"id":62262930},{"atl":[[19,0],[28,0]],"id":62262930},{"atb":[[9.6,0],[8.6,0],[11.5,5.34]],"id":69577417},{"atl":[[300,0],[200,0]],"id":69577417},{"atb":[[19.5,0],[24,0],[29,0]],"id":69421986},{"atl":[[400,0],[500,0]],"id":69421986},{"atb":[[2.88,0],[2.98,0],[2.78,0]],"id":65460404},{"atl":[[10.5,0],[15.5,0]],"id":65460404},{"atb":[[16.5,0],[11.5,0],[14,0]],"id":64546979},{"atl":[[350,0],[250,0]],"id":64546979}],"con":true,"img":false}]}
{"op":"mcm","clk":"11450289796","pt":1717320116048,"mc":[{"id":"1.229554920","rc":[{"atl":[[12.5,10.98]],"id":65460404}],"con":true,"img":false}]}
{"op":"mcm","clk":"11450289802","pt":1717320116146,"mc":[{"id":"1.229554920","rc":[{"atb":[[2.5,0]],"id":52671121},{"atl":[[12.5,0]],"id":52671121},{"atb":[[11.5,0]],"id":69577417},{"atl":[[390,0]],"id":69421986},{"atl":[[10,0]],"id":65460404},{"atb":[[17,0],[14.5,0]],"id":64546979}],"con":true,"img":false}]}
{"op":"mcm","clk":"11450289810","pt":1717320116253,"mc":[{"id":"1.229554920","rc":[{"atb":[[2.32,80.56]],"id":52671121},{"atl":[[10.5,10.46]],"id":52671121},{"atb":[[12,5.34]],"id":69577417},{"atl":[[450,2.61]],"id":69421986},{"atb":[[13,10.98],[15,4.15]],"id":64546979}],"con":true,"img":false}]}
{"op":"mcm","clk":"11450290812","pt":1717320129762,"mc":[{"id":"1.229554920","rc":[{"atb":[[2.38,151.49],[2.58,66.16],[2.48,141.25]],"id":52671121},{"atl":[[11,20.9],[8.4,18.83]],"id":52671121},{"atb":[[3.4,87.1],[3.9,36.04],[3.65,78.88]],"id":62262930},{"atl":[[19,7.74],[28,7.74]],"id":62262930},{"atb":[[9.6,24.31],[8.6,27.5],[11.5,9.95]],"id":69577417},{"atl":[[300,0.7],[200,0.7]],"id":69577417},{"atb":[[19.5,11.3],[24,9.08],[29,3.73]],"id":69421986},{"atl":[[400,0.35],[500,0.41]],"id":69421986},{"atb":[[2.88,111.2],[2.98,52.79],[2.78,117.44]],"id":65460404},{"atl":[[10.5,14.66],[15.5,14.41]],"id":65460404},{"atb":[[17,6.53],[12,19],[14.5,15.48]],"id":64546979},{"atl":[[350,0.59],[250,0.55]],"id":64546979}],"con":true,"img":false}]}
{"op":"mcm","clk":"11450293310","pt":1717320164921,"mc":[{"id":"1.229554920","rc":[{"spn":5.4,"spf":"NaN","id":52671121},{"atb":[[9.8,0]],"id":69577417},{"spn":43.5,"spf":"NaN","id":69577417},{"spn":6.3,"spf":"NaN","id":65460404}],"con":true,"img":false}]}
{"op":"mcm","clk":"11450293316","pt":1717320165012,"mc":[{"id":"1.229554920","rc":[{"atb":[[10.5,11.86]],"id":69577417}],"con":true,"img":false}]}
{"op":"mcm","clk":"11450294841","pt":1717320187950,"mc":[{"id":"1.229554920","rc":[{"atb":[[2.32,0],[2.6,0]],"id":52671121},{"atl":[[10.5,0],[8.2,23.26]],"id":52671121},{"atb":[[3.8,0],[3.55,0]],"id":62262930},{"atb":[[22,0]],"id":69421986},{"atl":[[450,0]],"id":69421986},{"atb":[[2.58,0]],"id":65460404},{"atl":[[10,13.6],[12.5,0]],"id":65460404},{"atb":[[13,0],[15,13.04]],"id":64546979}],"con":true,"img":false}]}
{"op":"mcm","clk":"11450294848","pt":1717320188049,"mc":[{"id":"1.229554920","rc":[{"atb":[[2.74,28.34],[2.6,80.56]],"id":52671121},{"atb":[[3.95,21.17],[3.7,43.49]],"id":62262930},{"atb":[[25,6.27]],"id":69421986},{"atl":[[390,2.61]],"id":69421986},{"atb":[[2.9,70.1]],"id":65460404}],"con":true,"img":false}]}
{"op":"mcm","clk":"11450296500","pt":1717320212666,"mc":[{"id":"1.229554920","rc":[{"atl":[[90,0]],"id":69577417}],"con":true,"img":false}]}
{"op":"mcm","clk":"11450296507","pt":1717320212768,"mc":[{"id":"1.229554920","rc":[{"atl":[[100,2.61]],"id":69577417}],"con":true,"img":false}]}
{"op":"mcm","clk":"11450297380","pt":1717320226882,"mc":[{"id":"1.229554920","rc":[{"spn":5.47,"spf":"NaN","id":52671121},{"spn":8.47,"spf":"NaN","id":62262930},{"atb":[[15,8.89]],"id":64546979}],"con":true,"img":false}]}
{"op":"mcm","clk":"11450297388","pt":1717320226984,"mc":[{"id":"1.229554920","rc":[{"atb":[[17.5,4.15]],"id":64546979}],"con":true,"img":false}]}
{"op":"mcm","clk":"11450298222","pt":1717320240412,"mc":[{"id":"1.229554920","rc":[{"atb":[[2.14,87.72]],"id":52671121},{"atl":[[13.5,8]],"id":52671121},{"atb":[[2.36,73.53]],"id":62262930},{"atl":[[14,7.69]],"id":62262930},{"atb":[[2.6,44.64]],"id":69577417},{"atl":[[180,2]],"id":69577417},{"atb":[[5.3,23.26]],"id":69421986},{"atl":[[390,4.61]],"id":69421986},{"atb":[[2.5,66.67]],"id":65460404},{"atl":[[14,7.69]],"id":65460404},{"atb":[[4,33.33]],"id":64546979},{"atl":[[130,2]],"id":64546979},{"atb":[[2.02,98.04]],"id":70003371},{"atl":[[8.8,12.82]],"id":70003371}],"con":true,"img":false}]}
{"op":"mcm","clk":"11450298380","pt":1717320242695,"mc":[{"id":"1.229554920","rc":[{"atb":[[2.74,0]],"id":52671121},{"atb":[[12,0]],"id":69577417},{"atb":[[26,0]],"id":69421986}],"con":true,"img":false}]}
{"op":"mcm","clk":"11450298387","pt":1717320242801,"mc":[{"id":"1.229554920","rc":[{"atb":[[2.68,28.34]],"id":52671121},{"atb":[[12.5,5.34]],"id":69577417},{"atb":[[30,2.61]],"id":69421986}],"con":true,"img":false}]}
{"op":"mcm","clk":"11450298571","pt":1717320245499,"mc":[{"id":"1.229554920","rc":[{"atl":[[23,4.55]],"id":62262930},{"atb":[[2.24,80.65],[2.5,0]],"id":65460404},{"atl":[[11.5,9.52],[8.8,0]],"id":70003371}],"con":true,"img":false}]}
{"op":"mcm","clk":"11450298576","pt":1717320245600,"mc":[{"id":"1.229554920","rc":[{"atl":[[14,0]],"id":62262930}],"con":true,"img":false}]}
{"op":"mcm","clk":"11450298894","pt":1717320249802,"mc":[{"id":"1.229554920","rc":[{"atb":[[1.43,48.7]],"id":69577417}],"con":true,"img":false}]}
{"op":"mcm","clk":"11450298900","pt":1717320249909,"mc":[{"id":"1.229554920","rc":[{"atb":[[2.6,0]],"id":69577417}],"con":true,"img":false}]}
{"op":"mcm","clk":"11450299793","pt":1717320263423,"mc":[{"id":"1.229554920","rc":[{"atl":[[8.2,16.74]],"id":52671121}],"con":true,"img":false}]}
{"op":"mcm","clk":"11450299802","pt":1717320263528,"mc":[{"id":"1.229554920","rc":[{"atl":[[7.8,6.52]],"id":52671121}],"con":true,"img":false}]}
{"op":"mcm","clk":"11450300430","pt":1717320272532,"mc":[{"id":"1.229554920","rc":[{"atl":[[75,0]],"id":69577417}],"con":true,"img":false}]}
{"op":"mcm","clk":"11450300436","pt":1717320272642,"mc":[{"id":"1.229554920","rc":[{"atl":[[80,2.61]],"id":69577417}],"con":true,"img":false}]}
{"op":"mcm","clk":"11450300807","pt":1717320277574,"mc":[{"id":"1.229554920","rc":[{"atl":[[8.6,13.16],[13.5,0]],"id":52671121},{"atb":[[2.36,0],[2.46,68.49]],"id":62262930},{"atb":[[6.4,16.13],[5.3,0]],"id":69421986},{"atl":[[130,0],[120,2]],"id":64546979}],"con":true,"img":false}]}
{"op":"mcm","clk":"11450301402","pt":1717320286879,"mc":[{"id":"1.229554920","rc":[{"atb":[[1.43,0],[3.05,69.03]],"id":69577417}],"con":true,"img":false}]}
{"op":"mcm","clk":"11450302616","pt":1717320306302,"mc":[{"id":"1.229554920","rc":[{"atb":[[2.38,0],[2.58,0],[2.48,0]],"id":52671121},{"atl":[[11,0],[8.4,0]],"id":52671121},{"spn":5.24,"spf":"NaN","id":52671121},{"spn":46.25,"spf":"NaN","id":69577417},{"atb":[[19.5,0],[24,0],[29,0]],"id":69421986},{"atl":[[400,0],[500,0]],"id":69421986},{"spn":185.0,"spf":"NaN","id":69421986},{"atb":[[2.88,0],[2.98,0],[2.78,0]],"id":65460404},{"atl":[[10.5,0],[15.5,0]],"id":65460404},{"atb":[[17,0],[12,0],[14.5,0]],"id":64546979},{"atl":[[350,0],[250,0]],"id":64546979},{"spn":63.75,"spf":"NaN","id":64546979}],"con":true,"img":false}]}
{"op":"mcm","clk":"11450302938","pt":1717320311199,"mc":[{"id":"1.229554920","rc":[{"atl":[[12.5,9.94]],"id":65460404}],"con":true,"img":false}]}
{"op":"mcm","clk":"11450302946","pt":1717320311303,"mc":[{"id":"1.229554920","rc":[{"atb":[[2.6,0]],"id":52671121},{"atl":[[8.2,0]],"id":52671121},{"atb":[[25,0]],"id":69421986},{"atb":[[2.9,0]],"id":65460404},{"atl":[[10,0]],"id":65460404},{"atb":[[17.5,0],[15,0]],"id":64546979}],"con":true,"img":false}]}
{"op":"mcm","clk":"11450302952","pt":1717320311411,"mc":[{"id":"1.229554920","rc":[{"atb":[[2.4,80.56]],"id":52671121},{"atl":[[8.4,16.74]],"id":52671121},{"atb":[[22,6.27]],"id":69421986},{"atb":[[2.72,70.1]],"id":65460404},{"atb":[[4,0],[13.5,8.89],[4.2,24.39],[15.5,4.15]],"id":64546979}],"con":true,"img":false}]}
{"op":"mcm","clk":"11450303916","pt":1717320326605,"mc":[{"id":"1.229554920","rc":[{"atb":[[2.38,151.49],[2.58,66.16],[2.48,141.25]],"id":52671121},{"atl":[[11,20.9],[8.4,35.57]],"id":52671121},{"atb":[[19.5,11.3],[24,9.08],[29,3.73]],"id":69421986},{"atl":[[400,0.35],[500,0.41]],"id":69421986},{"atb":[[2.88,111.2],[2.98,52.79],[2.78,117.44]],"id":65460404},{"atl":[[10.5,14.66],[15.5,14.41]],"id":65460404},{"atb":[[17,6.53],[12,19],[14.5,15.48]],"id":64546979},{"atl":[[350,0.59],[250,0.55]],"id":64546979}],"con":true,"img":false}]}
{"op":"mcm","clk":"11450306340","pt":1717320369783,"mc":[{"id":"1.229554920","rc":[{"atl":[[8.6,0],[9,12.5]],"id":52671121},{"atl":[[16,6.67],[14,0]],"id":65460404},{"atl":[[130,2],[120,0]],"id":64546979},{"spn":63.5,"spf":"NaN","id":64546979}],"con":true,"img":false}]}
{"op":"mcm","clk":"11450306603","pt":1717320374487,"mc":[{"id":"1.229554920","rc":[{"atb":[[2.4,0]],"id":52671121},{"atl":[[8.4,18.83]],"id":52671121},{"atb":[[22,0]],"id":69421986},{"atb":[[2.72,0]],"id":65460404},{"atl":[[10,13.6],[12.5,0]],"id":65460404},{"atb":[[13.5,0],[15.5,0]],"id":64546979},{"atl":[[110,0]],"id":64546979}],"con":true,"img":false}]}
{"op":"mcm","clk":"11450306606","pt":1717320374587,"mc":[{"id":"1.229554920","rc":[{"atb":[[2.6,80.56]],"id":52671121},{"atl":[[8.2,16.74]],"id":52671121},{"atb":[[25,6.27]],"id":69421986},{"atb":[[3,98.44]],"id":65460404},{"atb":[[17.5,4.15],[15,8.89]],"id":64546979},{"atl":[[130,0],[150,4.61],[120,2.61]],"id":64546979}],"con":true,"img":false}]}
{"op":"mcm","clk":"11450308114","pt":1717320400182,"mc":[{"id":"1.229554920","rc":[{"atb":[[2.38,0],[2.58,0],[2.48,0]],"id":52671121},{"atl":[[11,0],[8.4,0]],"id":52671121},{"atb":[[3.4,0],[3.9,0],[3.65,0]],"id":62262930},{"atl":[[19,0],[28,0]],"id":62262930},{"atb":[[9.6,0],[8.6,0],[11.5,0]],"id":69577417},{"atl":[[300,0],[200,0]],"id":69577417},{"atb":[[19.5,0],[24,0],[29,0]],"id":69421986},{"atl":[[400,0],[500,0]],"id":69421986},{"atb":[[2.88,0],[2.98,0],[2.78,0]],"id":65460404},{"atl":[[10.5,0],[15.5,0]],"id":65460404},{"atb":[[17,0],[12,0],[14.5,0]],"id":64546979},{"atl":[[350,0],[250,0]],"id":64546979},{"atb":[[2.86,0],[2.96,0],[2.76,0]],"id":70003371},{"atl":[[10.5,0],[15.5,0]],"id":70003371}],"con":true,"img":false}]}
{"op":"mcm","clk":"11450308771","pt":1717320410318,"mc":[{"id":"1.229554920","rc":[{"atl":[[130,2]],"id":64546979}],"con":true,"img":false}]}
{"op":"mcm","clk":"11450308779","pt":1717320410467,"mc":[{"id":"1.229554920","rc":[{"atl":[[150,2.61]],"id":64546979}],"con":true,"img":false}]}
{"op":"mcm","clk":"11450308800","pt":1717320410888,"mc":[{"id":"1.229554920","rc":[{"atb":[[2.38,151.49],[2.58,66.16],[2.48,141.25]],"id":52671121},{"atl":[[11,20.9],[8.4,18.83]],"id":52671121},{"atb":[[3.4,87.1],[3.9,36.04],[3.65,78.88]],"id":62262930},{"atl":[[19,7.74],[28,7.74]],"id":62262930},{"atb":[[9.6,24.31],[8.6,27.5],[11.5,9.95]],"id":69577417},{"atl":[[300,0.7],[200,0.7]],"id":69577417},{"atb":[[19.5,11.3],[24,9.08],[29,3.73]],"id":69421986},{"atl":[[400,0.35],[500,0.41]],"id":69421986},{"atb":[[2.88,111.2],[2.98,52.79],[2.78,117.44]],"id":65460404},{"atl":[[10.5,14.66],[15.5,14.41]],"id":65460404},{"atb":[[17,6.53],[12,19],[14.5,15.48]],"id":64546979},{"atl":[[350,0.59],[250,0.55]],"id":64546979},{"atb":[[2.86,112.39],[2.96,53.33],[2.76,118.78]],"id":70003371},{"atl":[[10.5,14.66],[15.5,14.41]],"id":70003371}],"con":true,"img":false}]}
{"op":"mcm","clk":"11450318672","pt":1717320528417,"mc":[{"id":"1.229554920","marketDefinition":{"bspMarket":true,"turnInPlayEnabled":false,"persistenceEnabled":false,"marketBaseRate":7.0,"eventId":"33318908","eventTypeId":"4339","numberOfWinners":1,"bettingType":"ODDS","marketType":"WIN","marketTime":"2024-06-02T10:24:00.000Z","suspendTime":"2024-06-02T10:24:00.000Z","bspReconciled":false,"complete":true,"inPlay":false,"crossMatching":true,"runnersVoidable":false,"numberOfActiveRunners":7,"betDelay":0,"status":"OPEN","runners":[{"status":"ACTIVE","sortPriority":1,"id":65460404,"name":"1. Give Me Room"},{"status":"ACTIVE","sortPriority":2,"id":52671121,"name":"2. Elegant Ritzy"},{"status":"ACTIVE","sortPriority":3,"id":62262930,"name":"3. Canya Candy"},{"status":"ACTIVE","sortPriority":4,"id":69577417,"name":"4. Alpha Bloke"},{"status":"ACTIVE","sortPriority":5,"id":69421986,"name":"6. Back to Work"},{"status":"ACTIVE","sortPriority":6,"id":64546979,"name":"7. Sheas Entity"},{"status":"ACTIVE","sortPriority":7,"id":70003371,"name":"8. Yumali"}],"regulators":["MR_INT"],"venue":"Murray Bridge","countryCode":"AU","discountAllowed":true,"timezone":"Australia/Adelaide","openDate":"2024-06-02T08:21:00.000Z","version":5962317639,"name":"R7 455m Gr6","eventName":"Murray Bridge (AUS) 2nd Jun"},"rc":[{"atb":[[2.38,151.49],[1.02,8.67],[2.6,80.56],[2.58,66.16],[2.68,28.34],[2.14,87.72],[2.48,141.25]],"id":52671121},{"atl":[[34,10],[9,12.5],[8.2,16.74],[11,20.9],[7.8,6.52],[8.4,18.83],[990,0.17],[1000,1]],"id":52671121},{"spn":5.24,"spf":"NaN","id":52671121},{"atb":[[1.01,17.35],[3.95,21.17],[3.7,43.49],[3.4,87.1],[2.46,68.49],[1.51,98.04],[3.9,36.04],[3.65,78.88]],"id":62262930},{"atl":[[17,6.93],[19,7.74],[23,4.55],[13,4.67],[28,7.74],[990,0.17],[1000,1]],"id":62262930},{"spn":8.47,"spf":"NaN","id":62262930},{"atb":[[9.6,24.31],[8.6,27.5],[10.5,11.86],[4.1,16.13],[11.5,9.95],[1.02,8.67],[2.12,44.64],[12.5,5.34],[1.51,98.04],[3.05,69.03]],"id":69577417},{"atl":[[300,0.7],[80,2.61],[180,2],[100,2.61],[200,0.7],[990,0.17],[1000,1]],"id":69577417},{"spn":46.25,"spf":"NaN","id":69577417},{"atb":[[19.5,11.3],[6.4,16.13],[1.01,17.35],[6.2,9.62],[4.1,16.13],[24,9.08],[2.12,44.64],[25,6.27],[1.51,98.04],[29,3.73],[30,2.61],[3.05,24.39]],"id":69421986},{"atl":[[340,0.16],[390,4.61],[400,0.35],[500,0.41],[1000,1.17]],"id":69421986},{"spn":185.0,"spf":"NaN","id":69421986},{"atb":[[2.24,80.65],[2.88,111.2],[1.03,5.78],[3,98.44],[2.98,52.79],[2.78,117.44]],"id":65460404},{"atl":[[9.6,6.84],[16,6.67],[34,10],[10,13.6],[10.5,14.66],[15.5,14.41],[1000,1.17]],"id":65460404},{"spn":6.3,"spf":"NaN","id":65460404},{"atb":[[17.5,4.15],[17,6.53],[1.01,17.35],[4.1,16.13],[12,19],[2.12,44.64],[1.51,98.04],[14.5,15.48],[4.2,24.39],[15,8.89],[3.05,24.39]],"id":64546979},{"atl":[[130,2],[150,2.61],[350,0.59],[120,2.61],[250,0.55],[1000,1.17]],"id":64546979},{"spn":68.75,"spf":"NaN","id":64546979},{"atb":[[2.02,98.04],[1.01,17.35],[2.86,112.39],[2.98,28.34],[2.96,53.33],[2.78,64.95],[2.76,118.78]],"id":70003371},{"atl":[[34,10],[9,6.84],[10,12.84],[10.5,14.66],[11.5,9.52],[990,0.17],[15.5,14.41],[1000,1]],"id":70003371},{"spn":5.99,"spf":"NaN","id":70003371}],"con":true,"img":true}]}
{"op":"mcm","clk":"11450325371","pt":1717320556670,"mc":[{"id":"1.229554920","rc":[{"atl":[[9,0],[8.6,13.16]],"id":52671121},{"spn":68.75,"spf":"NaN","id":64546979}],"con":true,"img":false}]}
{"op":"mcm","clk":"11450329206","pt":1717320607883,"mc":[{"id":"1.229554920","rc":[{"atl":[[1000,1.85]],"id":62262930}],"con":true,"img":false}]}
{"op":"mcm","clk":"11450329240","pt":1717320608397,"mc":[{"id":"1.229554920","rc":[{"atl":[[9.4,0.9]],"id":65460404}],"con":true,"img":false}]}
{"op":"mcm","clk":"11450329244","pt":1717320608452,"mc":[{"id":"1.229554920","rc":[{"atl":[[8.8,0.97]],"id":70003371}],"con":true,"img":false}]}
{"op":"mcm","clk":"11450329271","pt":1717320608977,"mc":[{"id":"1.229554920","rc":[{"atl":[[1000,1.68]],"id":62262930}],"con":true,"img":false}]}
{"op":"mcm","clk":"11450329350","pt":1717320610060,"mc":[{"id":"1.229554920","rc":[{"atl":[[1000,1.85]],"id":69577417}],"con":true,"img":false}]}
{"op":"mcm","clk":"11450329432","pt":1717320611365,"mc":[{"id":"1.229554920","rc":[{"atl":[[1000,1]],"id":62262930}],"con":true,"img":false}]}
{"op":"mcm","clk":"11450329438","pt":1717320611456,"mc":[{"id":"1.229554920","rc":[{"atl":[[12.5,0.68]],"id":62262930}],"con":true,"img":false}]}
{"op":"mcm","clk":"11450329668","pt":1717320614366,"mc":[{"id":"1.229554920","rc":[{"atl":[[1000,1.11]],"id":69577417}],"con":true,"img":false}]}
{"op":"mcm","clk":"11450329820","pt":1717320616385,"mc":[{"id":"1.229554920","rc":[{"atl":[[1000,1]],"id":69577417}],"con":true,"img":false}]}
{"op":"mcm","clk":"11450329825","pt":1717320616486,"mc":[{"id":"1.229554920","rc":[{"atl":[[75,0.11]],"id":69577417}],"con":true,"img":false}]}
{"op":"mcm","clk":"11450334592","pt":1717320676667,"mc":[{"id":"1.229554920","rc":[{"atl":[[8.6,0],[9,12.5]],"id":52671121},{"spn":8.22,"spf":"NaN","id":62262930},{"spn":43.75,"spf":"NaN","id":69577417},{"spn":6.2,"spf":"NaN","id":65460404},{"spn":5.89,"spf":"NaN","id":70003371}],"con":true,"img":false}]}
{"op":"mcm","clk":"11450344103","pt":1717320794046,"mc":[{"id":"1.229554920","rc":[{"atb":[[2.38,0],[2.58,0],[2.48,0]],"id":52671121},{"atl":[[11,0],[8.4,0]],"id":52671121},{"atb":[[3.4,0],[3.9,0],[3.65,0]],"id":62262930},{"atl":[[19,0],[28,0]],"id":62262930},{"atb":[[9.6,0],[8.6,0],[11.5,0]],"id":69577417},{"atl":[[300,0],[200,0]],"id":69577417},{"atb":[[19.5,0],[24,0],[29,0]],"id":69421986},{"atl":[[400,0],[500,0]],"id":69421986},{"atb":[[2.88,0],[2.98,0],[2.78,0]],"id":65460404},{"atl":[[10.5,0],[15.5,0]],"id":65460404},{"atb":[[17,0],[12,0],[14.5,0]],"id":64546979},{"atl":[[350,0],[250,0]],"id":64546979},{"atb":[[2.86,0],[2.96,0],[2.76,0]],"id":70003371},{"atl":[[10.5,0],[15.5,0]],"id":70003371}],"con":true,"img":false}]}
{"op":"mcm","clk":"11450345090","pt":1717320806649,"mc":[{"id":"1.229554920","rc":[{"atb":[[2.6,0]],"id":52671121},{"atl":[[8.2,0]],"id":52671121},{"atb":[[3.95,0],[3.7,0]],"id":62262930},{"atb":[[25,0]],"id":69421986},{"atb":[[3,28.34]],"id":65460404},{"atl":[[10,0],[12.5,10.98]],"id":65460404},{"atb":[[17.5,0],[15,0]],"id":64546979},{"atb":[[2.98,0],[2.78,0]],"id":70003371},{"atl":[[10,0]],"id":70003371}],"con":true,"img":false}]}
{"op":"mcm","clk":"11450345097","pt":1717320806752,"mc":[{"id":"1.229554920","rc":[{"atb":[[2.4,80.56]],"id":52671121},{"atl":[[8.8,16.74]],"id":52671121},{"atb":[[1.79,126.58],[3.7,21.17],[2.46,0],[3.3,43.49]],"id":62262930},{"atb":[[22,6.27]],"id":69421986},{"atb":[[2.72,70.1]],"id":65460404},{"atb":[[4.1,48.39],[13.5,8.89],[4.2,0],[15.5,4.15]],"id":64546979},{"atb":[[2.02,0],[2.86,28.34],[2.58,64.95],[1.61,163.93]],"id":70003371},{"atl":[[11,12.84]],"id":70003371}],"con":true,"img":false}]}
{"op":"mcm","clk":"11450345295","pt":1717320809084,"mc":[{"id":"1.229554920","rc":[{"atb":[[2.38,151.49],[2.58,66.16],[2.48,141.25]],"id":52671121},{"atl":[[11,20.9],[8.4,18.83]],"id":52671121},{"atb":[[3.4,87.1],[3.9,36.04],[3.65,78.88]],"id":62262930},{"atl":[[19,7.74],[28,7.74]],"id":62262930},{"atb":[[9.6,24.31],[8.6,27.5],[11.5,9.95]],"id":69577417},{"atl":[[300,0.7],[200,0.7]],"id":69577417},{"atb":[[19.5,11.3],[24,9.08],[29,3.73]],"id":69421986},{"atl":[[400,0.35],[500,0.41]],"id":69421986},{"atb":[[2.88,111.2],[2.98,52.79],[2.78,117.44]],"id":65460404},{"atl":[[10.5,14.66],[15.5,14.41]],"id":65460404},{"atb":[[17,6.53],[12,19],[14.5,15.48]],"id":64546979},{"atl":[[350,0.59],[250,0.55]],"id":64546979},{"atb":[[2.86,140.73],[2.96,53.33],[2.76,118.78]],"id":70003371},{"atl":[[10.5,14.66],[15.5,14.41]],"id":70003371}],"con":true,"img":false}]}
{"op":"mcm","clk":"11450347675","pt":1717320838219,"mc":[{"id":"1.229554920","rc":[{"atb":[[1.79,0],[2.38,72.46]],"id":62262930},{"atb":[[2.02,98.04]],"id":70003371}],"con":true,"img":false}]}
{"op":"mcm","clk":"11450347684","pt":1717320838271,"mc":[{"id":"1.229554920","rc":[{"atb":[[1.61,0]],"id":70003371}],"con":true,"img":false}]}
{"op":"mcm","clk":"11450349418","pt":1717320856907,"mc":[{"id":"1.229554920","rc":[{"atb":[[3.7,0]],"id":62262930},{"spn":8.2,"spf":"NaN","id":62262930},{"spn":68.5,"spf":"NaN","id":64546979},{"atb":[[2.86,112.39]],"id":70003371},{"spn":5.88,"spf":"NaN","id":70003371}],"con":true,"img":false}]}
{"op":"mcm","clk":"11450349426","pt":1717320857009,"mc":[{"id":"1.229554920","rc":[{"atb":[[3.95,21.17]],"id":62262930},{"atb":[[2.98,28.34]],"id":70003371}],"con":true,"img":false}]}
{"op":"mcm","clk":"11450349918","pt":1717320862932,"mc":[{"id":"1.229554920","rc":[{"atl":[[9,0],[8.4,32.34]],"id":52671121},{"atl":[[16,0],[14.5,7.41]],"id":65460404},{"atb":[[4.1,16.13],[1.3,38.02]],"id":64546979},{"atl":[[130,0],[140,2]],"id":64546979}],"con":true,"img":false}]}
{"op":"mcm","clk":"11450350470","pt":1717320869318,"mc":[{"id":"1.229554920","rc":[{"atb":[[2.5,66.67],[2.38,0]],"id":62262930}],"con":true,"img":false}]}
{"op":"mcm","clk":"11450351182","pt":1717320877350,"mc":[{"id":"1.229554920","rc":[{"atl":[[10,13.6]],"id":65460404}],"con":true,"img":false}]}
{"op":"mcm","clk":"11450351191","pt":1717320877456,"mc":[{"id":"1.229554920","rc":[{"atb":[[2.4,0]],"id":52671121},{"atl":[[8.8,0]],"id":52671121},{"atb":[[3.3,0]],"id":62262930},{"atb":[[22,0]],"id":69421986},{"atb":[[2.72,0]],"id":65460404},{"atl":[[12.5,0]],"id":65460404},{"atb":[[13.5,0]],"id":64546979},{"atb":[[2.58,0]],"id":70003371},{"atl":[[11,0]],"id":70003371}],"con":true,"img":false}]}
{"op":"mcm","clk":"11450351198","pt":1717320877567,"mc":[{"id":"1.229554920","rc":[{"atb":[[2.6,80.56]],"id":52671121},{"atl":[[8.2,16.74]],"id":52671121},{"atb":[[3.7,43.49]],"id":62262930},{"atb":[[25,6.27]],"id":69421986},{"atb":[[3,98.44]],"id":65460404},{"atl":[[9.4,0]],"id":65460404},{"atb":[[15,8.89]],"id":64546979},{"atb":[[2.78,64.95]],"id":70003371},{"atl":[[10,12.84]],"id":70003371}],"con":true,"img":false}]}
{"op":"mcm","clk":"11450351224","pt":1717320877926,"mc":[{"id":"1.229554920","rc":[{"atl":[[8.8,0]],"id":70003371}],"con":true,"img":false}]}
{"op":"mcm","clk":"11450351262","pt":1717320878441,"mc":[{"id":"1.229554920","rc":[{"atb":[[2.14,0]],"id":52671121},{"atl":[[8.4,18.83]],"id":52671121}],"con":true,"img":false}]}
{"op":"mcm","clk":"11450351272","pt":1717320878544,"mc":[{"id":"1.229554920","rc":[{"atb":[[1.99,101.01]],"id":52671121},{"atl":[[8.6,13.16]],"id":52671121}],"con":true,"img":false}]}
{"op":"mcm","clk":"11450352581","pt":1717320893863,"mc":[{"id":"1.229554920","rc":[{"atb":[[4.3,24.39]],"id":64546979},{"atl":[[120,4.61]],"id":64546979}],"con":true,"img":false}]}
{"op":"mcm","clk":"11450352589","pt":1717320893919,"mc":[{"id":"1.229554920","rc":[{"atb":[[1.3,0]],"id":64546979},{"atl":[[140,0]],"id":64546979}],"con":true,"img":false}]}
{"op":"mcm","clk":"11450353873","pt":1717320909256,"mc":[{"id":"1.229554920","rc":[{"atb":[[1.99,0],[2.12,89.29]],"id":52671121}],"con":true,"img":false}]}
{"op":"mcm","clk":"11450355982","pt":1717320935202,"mc":[{"id":"1.229554920","rc":[{"spn":8.22,"spf":"NaN","id":62262930},{"spn":6.3,"spf":"NaN","id":65460404},{"atb":[[15.5,0]],"id":64546979},{"spn":5.99,"spf":"NaN","id":70003371}],"con":true,"img":false}]}
{"op":"mcm","clk":"11450355988","pt":1717320935305,"mc":[{"id":"1.229554920","rc":[{"atb":[[17.5,4.15]],"id":64546979}],"con":true,"img":false}]}
{"op":"mcm","clk":"11450367334","pt":1717321082057,"mc":[{"id":"1.229554920","rc":[{"atl":[[8.6,0],[8.8,12.82]],"id":52671121},{"spn":68.75,"spf":"NaN","id":64546979}],"con":true,"img":false}]}
{"op":"mcm","clk":"11450370514","pt":1717321128728,"mc":[{"id":"1.229554920","rc":[{"atl":[[8.6,13.16]],"id":52671121},{"atl":[[130,2]],"id":64546979}],"con":true,"img":false}]}
{"op":"mcm","clk":"11450370519","pt":1717321128829,"mc":[{"id":"1.229554920","rc":[{"atl":[[8.8,0]],"id":52671121},{"atl":[[120,2.61]],"id":64546979}],"con":true,"img":false}]}
{"op":"mcm","clk":"11450370837","pt":1717321133821,"mc":[{"id":"1.229554920","rc":[{"atl":[[140,2]],"id":64546979}],"con":true,"img":false}]}
{"op":"mcm","clk":"11450370844","pt":1717321133922,"mc":[{"id":"1.229554920","rc":[{"atl":[[130,0]],"id":64546979}],"con":true,"img":false}]}
{"op":"mcm","clk":"11450372150","pt":1717321151965,"mc":[{"id":"1.229554920","rc":[{"atb":[[2.22,81.97],[2.12,0]],"id":52671121},{"atl":[[8.6,0],[8.4,32.34]],"id":52671121},{"atb":[[2.5,0],[2.62,61.73]],"id":62262930},{"atl":[[180,0],[120,2]],"id":69577417},{"atb":[[6.4,0]],"id":69421986},{"atl":[[520,2],[390,2.61]],"id":69421986},{"atl":[[13,8.33],[14.5,0]],"id":65460404},{"atb":[[2.02,0],[1.85,117.65]],"id":70003371}],"con":true,"img":false}]}
{"op":"mcm","clk":"11450372505","pt":1717321156953,"mc":[{"id":"1.229554920","rc":[{"atl":[[140,0],[120,4.61]],"id":64546979}],"con":true,"img":false}]}
{"op":"mcm","clk":"11450372559","pt":1717321157883,"mc":[{"id":"1.229554920","rc":[{"atb":[[2.38,0],[2.58,0],[2.48,0]],"id":52671121},{"atl":[[11,0],[8.4,13.51]],"id":52671121},{"atb":[[3.4,0],[3.9,0],[3.65,0]],"id":62262930},{"atl":[[19,0],[28,0]],"id":62262930},{"atb":[[9.6,0],[8.6,0],[11.5,0]],"id":69577417},{"atl":[[300,0],[200,0]],"id":69577417},{"atb":[[19.5,0],[24,0],[29,0]],"id":69421986},{"atl":[[400,0],[500,0]],"id":69421986},{"atb":[[2.88,0],[2.98,0],[2.78,0]],"id":65460404},{"atl":[[10.5,0],[15.5,0]],"id":65460404},{"atb":[[17,0],[12,0],[14.5,0]],"id":64546979},{"atl":[[350,0],[250,0]],"id":64546979},{"atb":[[2.86,0],[2.96,0],[2.76,0]],"id":70003371},{"atl":[[10.5,0],[15.5,0]],"id":70003371}],"con":true,"img":false}]}
{"op":"mcm","clk":"11450372720","pt":1717321159966,"mc":[{"id":"1.229554920","rc":[{"atb":[[2.6,0]],"id":52671121},{"atb":[[3.95,0],[3.7,0]],"id":62262930},{"atb":[[25,0]],"id":69421986},{"atl":[[390,0]],"id":69421986},{"atb":[[3,28.34]],"id":65460404},{"atl":[[10,0],[12.5,10.98]],"id":65460404},{"atb":[[17.5,0],[15,0]],"id":64546979},{"atb":[[2.98,0],[2.78,0]],"id":70003371},{"atl":[[10,0]],"id":70003371}],"con":true,"img":false}]}
{"op":"mcm","clk":"11450372726","pt":1717321160072,"mc":[{"id":"1.229554920","rc":[{"atb":[[2.4,80.56]],"id":52671121},{"atb":[[3.7,21.17],[1.91,109.89],[2.62,0],[3.3,43.49]],"id":62262930},{"atb":[[22,6.27]],"id":69421986},{"atl":[[520,0],[870,2],[460,2.61]],"id":69421986},{"atb":[[2.72,70.1]],"id":65460404},{"atb":[[4.3,0],[13.5,8.89],[4.2,31.25],[15.5,4.15]],"id":64546979},{"atb":[[2.86,28.34],[1.58,172.41],[2.58,64.95]],"id":70003371},{"atl":[[11,12.84]],"id":70003371}],"con":true,"img":false}]}
{"op":"mcm","clk":"11450372735","pt":1717321160175,"mc":[{"id":"1.229554920","rc":[{"atb":[[4.7,24.39]],"id":64546979},{"atb":[[1.85,0],[1.86,5.07]],"id":70003371}],"con":true,"img":false}]}
{"op":"mcm","clk":"11450372744","pt":1717321160278,"mc":[{"id":"1.229554920","rc":[{"atb":[[4.2,0]],"id":64546979}],"con":true,"img":false}]}
{"op":"mcm","clk":"11450372983","pt":1717321163302,"mc":[{"id":"1.229554920","rc":[{"atb":[[1.86,0]],"id":70003371}],"con":true,"img":false}]}
{"op":"mcm","clk":"11450373732","pt":1717321174803,"mc":[{"id":"1.229554920","rc":[{"atb":[[2.38,151.49],[2.58,66.16],[2.48,141.25]],"id":52671121},{"atl":[[11,20.9],[8.4,32.34]],"id":52671121},{"atb":[[3.4,87.1],[3.9,36.04],[3.65,78.88]],"id":62262930},{"atl":[[19,7.74],[28,7.74]],"id":62262930},{"atb":[[9.6,24.31],[8.6,27.5],[11.5,9.95]],"id":69577417},{"atl":[[300,0.7],[200,0.7]],"id":69577417},{"atb":[[19.5,11.3],[24,9.08],[29,3.73]],"id":69421986},{"atl":[[400,0.35],[500,0.41]],"id":69421986},{"atb":[[2.88,111.2],[2.98,52.79],[2.78,117.44]],"id":65460404},{"atl":[[10.5,14.66],[15.5,14.41]],"id":65460404},{"atb":[[17,6.53],[12,19],[14.5,15.48]],"id":64546979},{"atl":[[350,0.59],[250,0.55]],"id":64546979},{"atb":[[2.86,140.73],[2.96,53.33],[2.76,118.78]],"id":70003371},{"atl":[[10.5,14.66],[15.5,14.41]],"id":70003371}],"con":true,"img":false}]}
{"op":"mcm","clk":"11450374075","pt":1717321179986,"mc":[{"id":"1.229554920","rc":[{"atl":[[7.8,21.23],[8.4,18.83]],"id":52671121},{"atb":[[1.91,0],[2.62,61.73]],"id":62262930},{"atl":[[110,2],[120,0]],"id":69577417},{"atl":[[870,0],[470,2]],"id":69421986},{"atb":[[1.98,102.04],[1.58,0]],"id":70003371}],"con":true,"img":false}]}
{"op":"mcm","clk":"11450375776","pt":1717321208865,"mc":[{"id":"1.229554920","rc":[{"atb":[[3.7,0]],"id":62262930},{"atb":[[2.86,112.39]],"id":70003371}],"con":true,"img":false}]}
{"op":"mcm","clk":"11450375782","pt":1717321208965,"mc":[{"id":"1.229554920","rc":[{"atb":[[3.95,21.17]],"id":62262930},{"atb":[[2.98,28.34]],"id":70003371}],"con":true,"img":false}]}
{"op":"mcm","clk":"11450376122","pt":1717321215384,"mc":[{"id":"1.229554920","rc":[{"atl":[[9.4,0.9]],"id":65460404},{"spn":6.2,"spf":"NaN","id":65460404},{"spn":68.5,"spf":"NaN","id":64546979}],"con":true,"img":false}]}
{"op":"mcm","clk":"11450376133","pt":1717321215482,"mc":[{"id":"1.229554920","rc":[{"atl":[[8.8,0.97]],"id":70003371}],"con":true,"img":false}]}
{"op":"mcm","clk":"11450376610","pt":1717321223912,"mc":[{"id":"1.229554920","rc":[{"atl":[[10,13.6],[12.5,0]],"id":65460404}],"con":true,"img":false}]}
{"op":"mcm","clk":"11450376619","pt":1717321224016,"mc":[{"id":"1.229554920","rc":[{"atb":[[2.4,0]],"id":52671121},{"atb":[[3.3,0]],"id":62262930},{"atb":[[22,0]],"id":69421986},{"atl":[[460,0]],"id":69421986},{"atb":[[2.72,0]],"id":65460404},{"atb":[[13.5,0]],"id":64546979},{"atb":[[2.58,0]],"id":70003371},{"atl":[[11,0]],"id":70003371}],"con":true,"img":false}]}
{"op":"mcm","clk":"11450376629","pt":1717321224072,"mc":[{"id":"1.229554920","rc":[{"atb":[[2.6,80.56]],"id":52671121},{"atb":[[3.7,43.49]],"id":62262930},{"atb":[[25,6.27]],"id":69421986},{"atl":[[390,2.61]],"id":69421986},{"atb":[[3,98.44]],"id":65460404},{"atb":[[15,8.89]],"id":64546979},{"atb":[[2.78,64.95]],"id":70003371},{"atl":[[10,12.84]],"id":70003371}],"con":true,"img":false}]}
{"op":"mcm","clk":"11450379602","pt":1717321271933,"mc":[{"id":"1.229554920","rc":[{"atl":[[8.2,30.63],[7.8,6.52]],"id":52671121},{"atb":[[2.5,66.67],[2.62,0]],"id":62262930},{"atb":[[1.98,0],[1.89,112.36]],"id":70003371}],"con":true,"img":false}]}
{"op":"mcm","clk":"11450381263","pt":1717321296476,"mc":[{"id":"1.229554920","rc":[{"atb":[[15.5,0]],"id":64546979},{"spn":5.89,"spf":"NaN","id":70003371}],"con":true,"img":false}]}
{"op":"mcm","clk":"11450381271","pt":1717321296584,"mc":[{"id":"1.229554920","rc":[{"atb":[[17.5,4.15]],"id":64546979}],"con":true,"img":false}]}
{"op":"mcm","clk":"11450388501","pt":1717321415091,"mc":[{"id":"1.229554920","rc":[{"atl":[[7.6,5.11]],"id":52671121},{"spn":5.14,"spf":"NaN","id":52671121},{"spn":68.75,"spf":"NaN","id":64546979}],"con":true,"img":false}]}
{"op":"mcm","clk":"11450388520","pt":1717321415327,"mc":[{"id":"1.229554920","rc":[{"atl":[[8.8,6.08]],"id":70003371}],"con":true,"img":false}]}
{"op":"mcm","clk":"11450388532","pt":1717321415536,"mc":[{"id":"1.229554920","rc":[{"atl":[[9.4,6.01]],"id":65460404}],"con":true,"img":false}]}
{"op":"mcm","clk":"11450388540","pt":1717321415741,"mc":[{"id":"1.229554920","rc":[{"atl":[[17,12.04]],"id":62262930}],"con":true,"img":false}]}
{"op":"mcm","clk":"11450388554","pt":1717321415948,"mc":[{"id":"1.229554920","rc":[{"atl":[[140,5.11]],"id":69577417}],"con":true,"img":false}]}
{"op":"mcm","clk":"11450388561","pt":1717321416049,"mc":[{"id":"1.229554920","rc":[{"atl":[[12.5,0]],"id":62262930}],"con":true,"img":false}]}
{"op":"mcm","clk":"11450388572","pt":1717321416252,"mc":[{"id":"1.229554920","rc":[{"atl":[[200,5.11]],"id":64546979}],"con":true,"img":false}]}
{"op":"mcm","clk":"11450388587","pt":1717321416568,"mc":[{"id":"1.229554920","rc":[{"atb":[[2.38,160.86]],"id":52671121}],"con":true,"img":false}]}
{"op":"mcm","clk":"11450388602","pt":1717321416831,"mc":[{"id":"1.229554920","rc":[{"atb":[[2.66,9.37]],"id":70003371}],"con":true,"img":false}]}
{"op":"mcm","clk":"11450388612","pt":1717321417039,"mc":[{"id":"1.229554920","rc":[{"atb":[[2.88,120.57]],"id":65460404}],"con":true,"img":false}]}
{"op":"mcm","clk":"11450388628","pt":1717321417346,"mc":[{"id":"1.229554920","rc":[{"atb":[[3.6,9.37]],"id":62262930}],"con":true,"img":false}]}
{"op":"mcm","clk":"11450388639","pt":1717321417559,"mc":[{"id":"1.229554920","rc":[{"atb":[[13,9.37]],"id":69577417}],"con":true,"img":false}]}
{"op":"mcm","clk":"11450388663","pt":1717321417867,"mc":[{"id":"1.229554920","rc":[{"atb":[[16.5,9.37]],"id":64546979}],"con":true,"img":false}]}
{"op":"mcm","clk":"11450388687","pt":1717321418174,"mc":[{"id":"1.229554920","rc":[{"atb":[[32,9.37]],"id":69421986}],"con":true,"img":false}]}
{"op":"mcm","clk":"11450391172","pt":1717321459183,"mc":[{"id":"1.229554920","rc":[{"atb":[[12.5,0]],"id":69577417},{"atb":[[30,0]],"id":69421986}],"con":true,"img":false}]}
{"op":"mcm","clk":"11450391180","pt":1717321459287,"mc":[{"id":"1.229554920","rc":[{"atb":[[13.5,5.34]],"id":69577417},{"atb":[[34,2.61]],"id":69421986}],"con":true,"img":false}]}
{"op":"mcm","clk":"11450391235","pt":1717321460067,"mc":[{"id":"1.229554920","rc":[{"atb":[[13,0]],"id":69577417}],"con":true,"img":false}]}
{"op":"mcm","clk":"11450391239","pt":1717321460169,"mc":[{"id":"1.229554920","rc":[{"atb":[[12,9.37]],"id":69577417}],"con":true,"img":false}]}
{"op":"mcm","clk":"11450391263","pt":1717321460483,"mc":[{"id":"1.229554920","rc":[{"atb":[[32,0]],"id":69421986}],"con":true,"img":false}]}
{"op":"mcm","clk":"11450391269","pt":1717321460583,"mc":[{"id":"1.229554920","rc":[{"atb":[[30,9.37]],"id":69421986}],"con":true,"img":false}]}
{"op":"mcm","clk":"11450391325","pt":1717321461469,"mc":[{"id":"1.229554920","rc":[{"atb":[[12,0]],"id":69577417}],"con":true,"img":false}]}
{"op":"mcm","clk":"11450391331","pt":1717321461576,"mc":[{"id":"1.229554920","rc":[{"atb":[[13.5,14.71]],"id":69577417}],"con":true,"img":false}]}
{"op":"mcm","clk":"11450391355","pt":1717321461993,"mc":[{"id":"1.229554920","rc":[{"atb":[[30,0]],"id":69421986}],"con":true,"img":false}]}
{"op":"mcm","clk":"11450391362","pt":1717321462095,"mc":[{"id":"1.229554920","rc":[{"atb":[[34,11.98]],"id":69421986}],"con":true,"img":false}]}
{"op":"mcm","clk":"11450393235","pt":1717321491025,"mc":[{"id":"1.229554920","rc":[{"spn":8.47,"spf":"NaN","id":62262930},{"spn":44.25,"spf":"NaN","id":69577417},{"spn":187.0,"spf":"NaN","id":69421986},{"atb":[[17.5,0]],"id":64546979},{"spn":68.5,"spf":"NaN","id":64546979}],"con":true,"img":false}]}
{"op":"mcm","clk":"11450393244","pt":1717321491127,"mc":[{"id":"1.229554920","rc":[{"atb":[[17,10.68]],"id":64546979}],"con":true,"img":false}]}
{"op":"mcm","clk":"11450394585","pt":1717321511445,"mc":[{"id":"1.229554920","rc":[{"atb":[[2.38,9.37],[2.58,0],[2.48,0]],"id":52671121},{"atl":[[11,0],[8.4,0]],"id":52671121},{"atb":[[3.4,0],[3.9,0],[3.65,0]],"id":62262930},{"atl":[[19,0],[28,0]],"id":62262930},{"atb":[[9.6,0],[8.6,0],[11.5,0]],"id":69577417},{"atl":[[300,0],[200,0]],"id":69577417},{"atb":[[19.5,0],[24,0],[29,0]],"id":69421986},{"atl":[[400,0],[500,0]],"id":69421986},{"atb":[[2.88,9.37],[2.98,0],[2.78,0]],"id":65460404},{"atl":[[10.5,0],[15.5,0]],"id":65460404},{"atb":[[17,4.15],[12,0],[14.5,0]],"id":64546979},{"atl":[[350,0],[250,0]],"id":64546979},{"atb":[[2.86,0],[2.96,0],[2.76,0]],"id":70003371},{"atl":[[10.5,0],[15.5,0]],"id":70003371}],"con":true,"img":false}]}
{"op":"mcm","clk":"11450395223","pt":1717321520147,"mc":[{"id":"1.229554920","rc":[{"atb":[[2.6,0]],"id":52671121},{"atb":[[3.95,0],[3.7,0]],"id":62262930},{"atb":[[13.5,9.37]],"id":69577417},{"atb":[[34,9.37],[25,0]],"id":69421986},{"atl":[[390,0]],"id":69421986},{"atb":[[3,28.34]],"id":65460404},{"atl":[[12.5,10.98]],"id":65460404},{"atb":[[15,0]],"id":64546979},{"atb":[[2.98,0],[2.78,0]],"id":70003371},{"atl":[[10,0]],"id":70003371}],"con":true,"img":false}]}
{"op":"mcm","clk":"11450395228","pt":1717321520252,"mc":[{"id":"1.229554920","rc":[{"atb":[[2.4,80.56]],"id":52671121},{"atb":[[3.7,21.17],[3.3,43.49]],"id":62262930},{"atb":[[14,5.34]],"id":69577417},{"atb":[[36,2.61],[22,6.27]],"id":69421986},{"atl":[[460,2.61],[910,2],[470,0]],"id":69421986},{"atb":[[2.72,70.1]],"id":65460404},{"atl":[[10,0]],"id":65460404},{"atb":[[13.5,8.89]],"id":64546979},{"atb":[[2.86,28.34],[2.58,64.95]],"id":70003371},{"atl":[[11,12.84]],"id":70003371}],"con":true,"img":false}]}
{"op":"mcm","clk":"11450395237","pt":1717321520356,"mc":[{"id":"1.229554920","rc":[{"atl":[[910,0]],"id":69421986}],"con":true,"img":false}]}
{"op":"mcm","clk":"11450395241","pt":1717321520456,"mc":[{"id":"1.229554920","rc":[{"atl":[[510,2]],"id":69421986}],"con":true,"img":false}]}
{"op":"mcm","clk":"11450396044","pt":1717321532180,"mc":[{"id":"1.229554920","rc":[{"atb":[[2.38,160.86],[2.58,66.16],[2.48,141.25]],"id":52671121},{"atl":[[11,20.9],[8.4,18.83]],"id":52671121},{"atb":[[3.4,87.1],[3.9,36.04],[3.65,78.88]],"id":62262930},{"atl":[[19,7.74],[28,7.74]],"id":62262930},{"atb":[[9.6,24.31],[8.6,27.5],[11.5,9.95]],"id":69577417},{"atl":[[300,0.7],[200,0.7]],"id":69577417},{"atb":[[19.5,11.3],[24,9.08],[29,3.73]],"id":69421986},{"atl":[[400,0.35],[500,0.41]],"id":69421986},{"atb":[[2.88,120.57],[2.98,52.79],[2.78,117.44]],"id":65460404},{"atl":[[10.5,14.66],[15.5,14.41]],"id":65460404},{"atb":[[17,10.68],[12,19],[14.5,15.48]],"id":64546979},{"atl":[[350,0.59],[250,0.55]],"id":64546979},{"atb":[[2.86,140.73],[2.96,53.33],[2.76,118.78]],"id":70003371},{"atl":[[10.5,14.66],[15.5,14.41]],"id":70003371}],"con":true,"img":false}]}
{"op":"mcm","clk":"11450399748","pt":1717321584667,"mc":[{"id":"1.229554920","rc":[{"atb":[[2.4,0]],"id":52671121},{"atb":[[3.7,0],[3.3,0]],"id":62262930},{"spn":8.45,"spf":"NaN","id":62262930},{"spn":44.5,"spf":"NaN","id":69577417},{"atb":[[22,0]],"id":69421986},{"atl":[[460,0]],"id":69421986},{"spn":188.0,"spf":"NaN","id":69421986},{"atb":[[2.72,0]],"id":65460404},{"atl":[[10,13.6],[12.5,0]],"id":65460404},{"atb":[[13.5,0]],"id":64546979},{"atb":[[2.86,112.39],[2.58,0]],"id":70003371},{"atl":[[11,0]],"id":70003371},{"spn":5.88,"spf":"NaN","id":70003371}],"con":true,"img":false}]}
{"op":"mcm","clk":"11450399757","pt":1717321584768,"mc":[{"id":"1.229554920","rc":[{"atb":[[2.6,80.56]],"id":52671121},{"atb":[[3.95,21.17],[3.7,43.49]],"id":62262930},{"atb":[[25,6.27]],"id":69421986},{"atl":[[390,2.61]],"id":69421986},{"atb":[[3,98.44]],"id":65460404},{"atb":[[15,8.89]],"id":64546979},{"atb":[[2.98,28.34],[2.78,64.95]],"id":70003371},{"atl":[[10,12.84]],"id":70003371}],"con":true,"img":false}]}
{"op":"mcm","clk":"11450417964","pt":1717321812856,"mc":[{"id":"1.229554920","rc":[{"atl":[[1000,1.85]],"id":62262930},{"spn":8.47,"spf":"NaN","id":62262930},{"spn":5.89,"spf":"NaN","id":70003371}],"con":true,"img":false}]}
{"op":"mcm","clk":"11450418364","pt":1717321816780,"mc":[{"id":"1.229554920","rc":[{"atl":[[1000,1.68]],"id":62262930}],"con":true,"img":false}]}
{"op":"mcm","clk":"11450418938","pt":1717321822978,"mc":[{"id":"1.229554920","rc":[{"atl":[[1000,1]],"id":62262930}],"con":true,"img":false}]}
{"op":"mcm","clk":"11450418945","pt":1717321823078,"mc":[{"id":"1.229554920","rc":[{"atl":[[12.5,0.68]],"id":62262930}],"con":true,"img":false}]}
{"op":"mcm","clk":"11450421260","pt":1717321850344,"mc":[{"id":"1.229554920","rc":[{"atb":[[2.38,9.37],[2.58,0],[2.48,0]],"id":52671121},{"atl":[[11,0],[8.4,0]],"id":52671121},{"atb":[[3.4,0],[3.9,0],[3.65,0]],"id":62262930},{"atl":[[19,0],[28,0]],"id":62262930},{"atb":[[9.6,0],[8.6,0],[11.5,0]],"id":69577417},{"atl":[[300,0],[200,0]],"id":69577417},{"atb":[[19.5,0],[24,0],[29,0]],"id":69421986},{"atl":[[400,0],[500,0]],"id":69421986},{"atb":[[2.88,9.37],[2.98,0],[2.78,0]],"id":65460404},{"atl":[[10.5,0],[15.5,0]],"id":65460404},{"atb":[[17,4.15],[12,0],[14.5,0]],"id":64546979},{"atl":[[350,0],[250,0]],"id":64546979},{"atb":[[2.86,0],[2.96,0],[2.76,0]],"id":70003371},{"atl":[[10.5,0],[15.5,0]],"id":70003371}],"con":true,"img":false}]}
{"op":"mcm","clk":"11450422272","pt":1717321862536,"mc":[{"id":"1.229554920","rc":[{"atb":[[2.6,0]],"id":52671121},{"atb":[[3.95,0],[3.7,0]],"id":62262930},{"atb":[[25,0]],"id":69421986},{"atl":[[390,0]],"id":69421986},{"atb":[[3,28.34]],"id":65460404},{"atl":[[12.5,10.98]],"id":65460404},{"atb":[[15,0]],"id":64546979},{"atb":[[2.98,0],[2.78,0]],"id":70003371},{"atl":[[10,0]],"id":70003371}],"con":true,"img":false}]}
{"op":"mcm","clk":"11450422281","pt":1717321862642,"mc":[{"id":"1.229554920","rc":[{"atb":[[2.4,80.56]],"id":52671121},{"atb":[[3.7,21.17],[3.3,43.49]],"id":62262930},{"atb":[[22,6.27]],"id":69421986},{"atl":[[460,2.61]],"id":69421986},{"atb":[[2.72,70.1]],"id":65460404},{"atl":[[10,0]],"id":65460404},{"atb":[[13.5,8.89]],"id":64546979},{"atb":[[2.86,28.34],[2.58,64.95]],"id":70003371},{"atl":[[11,12.84]],"id":70003371}],"con":true,"img":false}]}
{"op":"mcm","clk":"11450422292","pt":1717321862747,"mc":[{"id":"1.229554920","rc":[{"atl":[[910,2],[510,0]],"id":69421986}],"con":true,"img":false}]}
{"op":"mcm","clk":"11450422882","pt":1717321869337,"mc":[{"id":"1.229554920","rc":[{"atb":[[2.38,160.86],[2.58,66.16],[2.48,141.25]],"id":52671121},{"atl":[[11,20.9],[8.4,18.83]],"id":52671121},{"atb":[[3.4,87.1],[3.9,36.04],[3.65,78.88]],"id":62262930},{"atl":[[19,7.74],[28,7.74]],"id":62262930},{"atb":[[9.6,24.31],[8.6,27.5],[11.5,9.95]],"id":69577417},{"atl":[[300,0.7],[200,0.7]],"id":69577417},{"atb":[[19.5,11.3],[24,9.08],[29,3.73]],"id":69421986},{"atl":[[400,0.35],[500,0.41]],"id":69421986},{"atb":[[2.88,120.57],[2.98,52.79],[2.78,117.44]],"id":65460404},{"atl":[[10.5,14.66],[15.5,14.41]],"id":65460404},{"atb":[[17,10.68],[12,19],[14.5,15.48]],"id":64546979},{"atl":[[350,0.59],[250,0.55]],"id":64546979},{"atb":[[2.86,140.73],[2.96,53.33],[2.76,118.78]],"id":70003371},{"atl":[[10.5,14.66],[15.5,14.41]],"id":70003371}],"con":true,"img":false}]}
{"op":"mcm","clk":"11450423548","pt":1717321877540,"mc":[{"id":"1.229554920","rc":[{"spn":8.2,"spf":"NaN","id":62262930},{"atl":[[9,0]],"id":70003371},{"spn":5.88,"spf":"NaN","id":70003371}],"con":true,"img":false}]}
{"op":"mcm","clk":"11450423558","pt":1717321877646,"mc":[{"id":"1.229554920","rc":[{"atl":[[9.4,6.84]],"id":70003371}],"con":true,"img":false}]}
{"op":"mcm","clk":"11450423624","pt":1717321878369,"mc":[{"id":"1.229554920","rc":[{"atl":[[8.8,0.97]],"id":70003371}],"con":true,"img":false}]}
{"op":"mcm","clk":"11450423632","pt":1717321878473,"mc":[{"id":"1.229554920","rc":[{"atl":[[9.2,5.11]],"id":70003371}],"con":true,"img":false}]}
{"op":"mcm","clk":"11450424037","pt":1717321883648,"mc":[{"id":"1.229554920","rc":[{"atl":[[510,2]],"id":69421986}],"con":true,"img":false}]}
{"op":"mcm","clk":"11450424049","pt":1717321883757,"mc":[{"id":"1.229554920","rc":[{"atl":[[910,0]],"id":69421986}],"con":true,"img":false}]}
{"op":"mcm","clk":"11450425358","pt":1717321900072,"mc":[{"id":"1.229554920","rc":[{"atl":[[8.8,0]],"id":70003371}],"con":true,"img":false}]}
{"op":"mcm","clk":"11450425367","pt":1717321900173,"mc":[{"id":"1.229554920","rc":[{"atl":[[9,0.97]],"id":70003371}],"con":true,"img":false}]}
{"op":"mcm","clk":"11450425655","pt":1717321903399,"mc":[{"id":"1.229554920","rc":[{"atb":[[2.38,9.37],[2.58,0],[2.48,0]],"id":52671121},{"atl":[[11,0],[8.4,0]],"id":52671121},{"atb":[[9.6,0],[8.6,0],[11.5,0]],"id":69577417},{"atl":[[300,0],[200,0]],"id":69577417},{"atb":[[19.5,0],[24,0],[29,0]],"id":69421986},{"atl":[[400,0],[500,0]],"id":69421986},{"atb":[[2.88,9.37],[2.98,0],[2.78,0]],"id":65460404},{"atl":[[10.5,0],[15.5,0]],"id":65460404},{"atb":[[17,4.15],[12,0],[14.5,0]],"id":64546979},{"atl":[[350,0],[250,0]],"id":64546979},{"atb":[[2.86,28.34],[2.96,0],[2.76,0]],"id":70003371},{"atl":[[10.5,0],[15.5,0]],"id":70003371}],"con":true,"img":false}]}
{"op":"mcm","clk":"11450426022","pt":1717321907460,"mc":[{"id":"1.229554920","rc":[{"atb":[[3.7,0]],"id":62262930},{"atb":[[2.86,0]],"id":70003371}],"con":true,"img":false}]}
{"op":"mcm","clk":"11450426033","pt":1717321907560,"mc":[{"id":"1.229554920","rc":[{"atb":[[3.95,21.17]],"id":62262930},{"atb":[[2.92,28.34]],"id":70003371}],"con":true,"img":false}]}
{"op":"mcm","clk":"11450426478","pt":1717321913596,"mc":[{"id":"1.229554920","rc":[{"atb":[[2.38,160.86],[2.58,66.16],[2.48,141.25]],"id":52671121},{"atl":[[11,20.9],[8.4,18.83]],"id":52671121},{"atb":[[9.6,24.31],[8.6,27.5],[11.5,9.95]],"id":69577417},{"atl":[[300,0.7],[200,0.7]],"id":69577417},{"atb":[[19.5,11.3],[24,9.08],[29,3.73]],"id":69421986},{"atl":[[400,0.35],[500,0.41]],"id":69421986},{"atb":[[2.88,120.57],[2.98,52.79],[2.78,117.44]],"id":65460404},{"atl":[[10.5,14.66],[15.5,14.41]],"id":65460404},{"atb":[[17,10.68],[12,19],[14.5,15.48]],"id":64546979},{"atl":[[350,0.59],[250,0.55]],"id":64546979},{"atb":[[2.88,111.2],[2.98,52.79],[2.78,117.44]],"id":70003371},{"atl":[[10.5,14.66],[15.5,14.41]],"id":70003371}],"con":true,"img":false}]}
{"op":"mcm","clk":"11450426941","pt":1717321918890,"mc":[{"id":"1.229554920","rc":[{"atb":[[2.66,0]],"id":70003371}],"con":true,"img":false}]}
{"op":"mcm","clk":"11450426950","pt":1717321918989,"mc":[{"id":"1.229554920","rc":[{"atb":[[2.68,9.37]],"id":70003371}],"con":true,"img":false}]}
{"op":"mcm","clk":"11450427537","pt":1717321924509,"mc":[{"id":"1.229554920","rc":[{"atb":[[3.3,0]],"id":62262930}],"con":true,"img":false}]}
{"op":"mcm","clk":"11450427557","pt":1717321924714,"mc":[{"id":"1.229554920","rc":[{"atb":[[3.7,43.49]],"id":62262930}],"con":true,"img":false}]}
{"op":"mcm","clk":"11450430795","pt":1717321958723,"mc":[{"id":"1.229554920","rc":[{"spn":8.22,"spf":"NaN","id":62262930},{"atb":[[2.92,0]],"id":70003371},{"spn":5.99,"spf":"NaN","id":70003371}],"con":true,"img":false}]}
{"op":"mcm","clk":"11450430803","pt":1717321958828,"mc":[{"id":"1.229554920","rc":[{"atb":[[3,28.34]],"id":70003371}],"con":true,"img":false}]}
{"op":"mcm","clk":"11450432156","pt":1717321975772,"mc":[{"id":"1.229554920","rc":[{"atb":[[2.4,0]],"id":52671121},{"atb":[[22,0]],"id":69421986},{"atl":[[460,0]],"id":69421986},{"atb":[[2.72,0]],"id":65460404},{"atl":[[10,13.6],[12.5,0]],"id":65460404},{"atb":[[13.5,0]],"id":64546979},{"atb":[[2.58,0]],"id":70003371},{"atl":[[11,0]],"id":70003371}],"con":true,"img":false}]}
{"op":"mcm","clk":"11450432166","pt":1717321975873,"mc":[{"id":"1.229554920","rc":[{"atb":[[2.6,80.56]],"id":52671121},{"atb":[[25,6.27]],"id":69421986},{"atl":[[390,2.61]],"id":69421986},{"atb":[[3,98.44]],"id":65460404},{"atb":[[15,8.89]],"id":64546979},{"atb":[[2.9,64.95]],"id":70003371},{"atl":[[10,12.84]],"id":70003371}],"con":true,"img":false}]}
{"op":"mcm","clk":"11450437081","pt":1717322034466,"mc":[{"id":"1.229554920","rc":[{"atb":[[34,0]],"id":69421986},{"spn":6.0,"spf":"NaN","id":70003371}],"con":true,"img":false}]}
{"op":"mcm","clk":"11450437089","pt":1717322034519,"mc":[{"id":"1.229554920","rc":[{"atb":[[32,9.37]],"id":69421986}],"con":true,"img":false}]}
{"op":"mcm","clk":"11450437159","pt":1717322035343,"mc":[{"id":"1.229554920","rc":[{"atb":[[2.38,151.49]],"id":52671121}],"con":true,"img":false}]}
{"op":"mcm","clk":"11450437169","pt":1717322035448,"mc":[{"id":"1.229554920","rc":[{"atb":[[2.26,9.37]],"id":52671121}],"con":true,"img":false}]}
{"op":"mcm","clk":"11450437198","pt":1717322035755,"mc":[{"id":"1.229554920","rc":[{"atb":[[2.68,0]],"id":70003371}],"con":true,"img":false}]}
{"op":"mcm","clk":"11450437207","pt":1717322035858,"mc":[{"id":"1.229554920","rc":[{"atb":[[2.54,9.37]],"id":70003371}],"con":true,"img":false}]}
{"op":"mcm","clk":"11450437235","pt":1717322036170,"mc":[{"id":"1.229554920","rc":[{"atb":[[2.88,111.2]],"id":65460404}],"con":true,"img":false}]}
{"op":"mcm","clk":"11450437243","pt":1717322036228,"mc":[{"id":"1.229554920","rc":[{"atb":[[2.74,9.37]],"id":65460404}],"con":true,"img":false}]}
{"op":"mcm","clk":"11450437271","pt":1717322036544,"mc":[{"id":"1.229554920","rc":[{"atb":[[3.6,0]],"id":62262930}],"con":true,"img":false}]}
{"op":"mcm","clk":"11450437284","pt":1717322036641,"mc":[{"id":"1.229554920","rc":[{"atb":[[3.45,9.37]],"id":62262930}],"con":true,"img":false}]}
{"op":"mcm","clk":"11450437314","pt":1717322036958,"mc":[{"id":"1.229554920","rc":[{"atb":[[13.5,0]],"id":69577417}],"con":true,"img":false}]}
{"op":"mcm","clk":"11450437324","pt":1717322037054,"mc":[{"id":"1.229554920","rc":[{"atb":[[13,9.37]],"id":69577417}],"con":true,"img":false}]}
{"op":"mcm","clk":"11450437342","pt":1717322037264,"mc":[{"id":"1.229554920","rc":[{"atb":[[16.5,0]],"id":64546979}],"con":true,"img":false}]}
{"op":"mcm","clk":"11450437351","pt":1717322037318,"mc":[{"id":"1.229554920","rc":[{"atb":[[15.5,9.37]],"id":64546979}],"con":true,"img":false}]}
{"op":"mcm","clk":"11450437370","pt":1717322037631,"mc":[{"id":"1.229554920","rc":[{"atb":[[2.24,0],[2.42,70.42]],"id":65460404},{"atb":[[1.89,0],[1.98,102.04]],"id":70003371},{"atl":[[9,6.08],[11.5,0]],"id":70003371}],"con":true,"img":false}]}
{"op":"mcm","clk":"11450437469","pt":1717322038718,"mc":[{"id":"1.229554920","rc":[{"atl":[[9.2,0]],"id":70003371}],"con":true,"img":false}]}
{"op":"mcm","clk":"11450437478","pt":1717322038828,"mc":[{"id":"1.229554920","rc":[{"atl":[[9,0.97],[9.2,12.2],[8.8,5.11]],"id":70003371}],"con":true,"img":false}]}
{"op":"mcm","clk":"11450437574","pt":1717322039963,"mc":[{"id":"1.229554920","rc":[{"atl":[[8.8,0]],"id":70003371}],"con":true,"img":false}]}
{"op":"mcm","clk":"11450437583","pt":1717322040065,"mc":[{"id":"1.229554920","rc":[{"atl":[[9,6.08]],"id":70003371}],"con":true,"img":false}]}
{"op":"mcm","clk":"11450438062","pt":1717322045432,"mc":[{"id":"1.229554920","rc":[{"atb":[[14,0]],"id":69577417},{"atb":[[36,0]],"id":69421986}],"con":true,"img":false}]}
{"op":"mcm","clk":"11450438073","pt":1717322045534,"mc":[{"id":"1.229554920","rc":[{"atb":[[13.5,5.34]],"id":69577417},{"atb":[[34,2.61]],"id":69421986}],"con":true,"img":false}]}
{"op":"mcm","clk":"11450439177","pt":1717322057991,"mc":[{"id":"1.229554920","rc":[{"atl":[[9.2,0],[8.8,6.84]],"id":70003371}],"con":true,"img":false}]}
{"op":"mcm","clk":"11450439210","pt":1717322058397,"mc":[{"id":"1.229554920","rc":[{"atl":[[9,0.97]],"id":70003371}],"con":true,"img":false}]}
{"op":"mcm","clk":"11450439223","pt":1717322058453,"mc":[{"id":"1.229554920","rc":[{"atl":[[8.6,5.11]],"id":70003371}],"con":true,"img":false}]}
{"op":"mcm","clk":"11450439232","pt":1717322058559,"mc":[{"id":"1.229554920","rc":[{"atl":[[9.2,12.2],[8.8,0]],"id":70003371}],"con":true,"img":false}]}
{"op":"mcm","clk":"11450439328","pt":1717322059550,"mc":[{"id":"1.229554920","rc":[{"atl":[[8.6,0]],"id":70003371}],"con":true,"img":false}]}
{"op":"mcm","clk":"11450439336","pt":1717322059652,"mc":[{"id":"1.229554920","rc":[{"atl":[[9,6.08]],"id":70003371}],"con":true,"img":false}]}
{"op":"mcm","clk":"11450439792","pt":1717322064408,"mc":[{"id":"1.229554920","rc":[{"atb":[[2.5,0],[2.34,74.63]],"id":62262930},{"atl":[[470,2],[510,0]],"id":69421986},{"atl":[[12,9.09],[13,0]],"id":65460404},{"atb":[[1.64,57.7],[4.7,0]],"id":64546979},{"atl":[[130,2],[120,2.61]],"id":64546979},{"atb":[[1.98,0],[2.06,94.34]],"id":70003371}],"con":true,"img":false}]}
{"op":"mcm","clk":"11450439810","pt":1717322064608,"mc":[{"id":"1.229554920","rc":[{"atb":[[2.6,62.5],[2.34,0]],"id":62262930},{"atb":[[1.64,0],[5.2,23.81]],"id":64546979},{"atl":[[130,0],[140,2]],"id":64546979}],"con":true,"img":false}]}
{"op":"mcm","clk":"11450439829","pt":1717322064770,"mc":[{"id":"1.229554920","rc":[{"atl":[[130,2],[140,0]],"id":64546979}],"con":true,"img":false}]}
{"op":"mcm","clk":"11450439902","pt":1717322065491,"mc":[{"id":"1.229554920","rc":[{"atl":[[9.4,0]],"id":70003371}],"con":true,"img":false}]}
{"op":"mcm","clk":"11450439914","pt":1717322065599,"mc":[{"id":"1.229554920","rc":[{"atl":[[9,12.92]],"id":70003371}],"con":true,"img":false}]}
{"op":"mcm","clk":"11450440021","pt":1717322066589,"mc":[{"id":"1.229554920","rc":[{"atl":[[9,7.81]],"id":70003371}],"con":true,"img":false}]}
{"op":"mcm","clk":"11450440032","pt":1717322066690,"mc":[{"id":"1.229554920","rc":[{"atl":[[8.8,5.11]],"id":70003371}],"con":true,"img":false}]}
{"op":"mcm","clk":"11450441204","pt":1717322077491,"mc":[{"id":"1.229554920","rc":[{"atl":[[8.6,7.81]],"id":70003371}],"con":true,"img":false}]}
{"op":"mcm","clk":"11450441217","pt":1717322077593,"mc":[{"id":"1.229554920","rc":[{"atl":[[9.2,0]],"id":70003371}],"con":true,"img":false}]}
{"op":"mcm","clk":"11450441291","pt":1717322078271,"mc":[{"id":"1.229554920","rc":[{"atl":[[8.8,0]],"id":70003371}],"con":true,"img":false}]}
{"op":"mcm","clk":"11450441299","pt":1717322078378,"mc":[{"id":"1.229554920","rc":[{"atl":[[8.8,12.82],[8.4,5.11]],"id":70003371}],"con":true,"img":false}]}
{"op":"mcm","clk":"11450441308","pt":1717322078478,"mc":[{"id":"1.229554920","rc":[{"atl":[[8.6,0]],"id":70003371}],"con":true,"img":false}]}
{"op":"mcm","clk":"11450441420","pt":1717322079526,"mc":[{"id":"1.229554920","rc":[{"atl":[[8.4,0]],"id":70003371}],"con":true,"img":false}]}
{"op":"mcm","clk":"11450441439","pt":1717322079710,"mc":[{"id":"1.229554920","rc":[{"atl":[[8.6,5.11]],"id":70003371}],"con":true,"img":false}]}
{"op":"mcm","clk":"11450442669","pt":1717322095482,"mc":[{"id":"1.229554920","rc":[{"spn":44.25,"spf":"NaN","id":69577417},{"spn":187.0,"spf":"NaN","id":69421986},{"atl":[[150,0]],"id":64546979},{"spn":5.8,"spf":"NaN","id":70003371}],"con":true,"img":false}]}
{"op":"mcm","clk":"11450442679","pt":1717322095585,"mc":[{"id":"1.229554920","rc":[{"atl":[[120,5.23]],"id":64546979}],"con":true,"img":false}]}
{"op":"mcm","clk":"11450442686","pt":1717322095690,"mc":[{"id":"1.229554920","rc":[{"atl":[[110,2]],"id":64546979}],"con":true,"img":false}]}
{"op":"mcm","clk":"11450442693","pt":1717322095791,"mc":[{"id":"1.229554920","rc":[{"atl":[[130,0]],"id":64546979}],"con":true,"img":false}]}
{"op":"mcm","clk":"11450442777","pt":1717322097093,"mc":[{"id":"1.229554920","rc":[{"atl":[[8.4,7.81]],"id":70003371}],"con":true,"img":false}]}
{"op":"mcm","clk":"11450442785","pt":1717322097197,"mc":[{"id":"1.229554920","rc":[{"atl":[[8.8,0]],"id":70003371}],"con":true,"img":false}]}
{"op":"mcm","clk":"11450442839","pt":1717322098019,"mc":[{"id":"1.229554920","rc":[{"atl":[[8.6,0]],"id":70003371}],"con":true,"img":false}]}
{"op":"mcm","clk":"11450442851","pt":1717322098121,"mc":[{"id":"1.229554920","rc":[{"atl":[[8.2,5.11]],"id":70003371}],"con":true,"img":false}]}
{"op":"mcm","clk":"11450443472","pt":1717322105522,"mc":[{"id":"1.229554920","rc":[{"atl":[[120,2.61]],"id":64546979},{"atl":[[9,0.97]],"id":70003371}],"con":true,"img":false}]}
{"op":"mcm","clk":"11450443480","pt":1717322105627,"mc":[{"id":"1.229554920","rc":[{"atl":[[160,2.61]],"id":64546979},{"atl":[[8.6,6.84]],"id":70003371}],"con":true,"img":false}]}
{"op":"mcm","clk":"11450443485","pt":1717322105729,"mc":[{"id":"1.229554920","rc":[{"atl":[[110,0],[120,4.61]],"id":64546979}],"con":true,"img":false}]}
{"op":"mcm","clk":"11450443492","pt":1717322105831,"mc":[{"id":"1.229554920","rc":[{"atl":[[150,2]],"id":64546979}],"con":true,"img":false}]}
{"op":"mcm","clk":"11450443503","pt":1717322105885,"mc":[{"id":"1.229554920","rc":[{"atl":[[120,2.61]],"id":64546979}],"con":true,"img":false}]}
{"op":"mcm","clk":"11450443511","pt":1717322105991,"mc":[{"id":"1.229554920","rc":[{"atl":[[150,0],[120,4.61]],"id":64546979}],"con":true,"img":false}]}
{"op":"mcm","clk":"11450443521","pt":1717322106100,"mc":[{"id":"1.229554920","rc":[{"atl":[[150,2],[120,2.61]],"id":64546979}],"con":true,"img":false}]}
{"op":"mcm","clk":"11450444319","pt":1717322115502,"mc":[{"id":"1.229554920","rc":[{"atl":[[8.6,0]],"id":70003371}],"con":true,"img":false}]}
{"op":"mcm","clk":"11450444329","pt":1717322115609,"mc":[{"id":"1.229554920","rc":[{"atl":[[9.2,6.84],[8.2,11.95],[8.4,0]],"id":70003371}],"con":true,"img":false}]}
{"op":"mcm","clk":"11450444335","pt":1717322115707,"mc":[{"id":"1.229554920","rc":[{"atl":[[9,13.47],[8.2,5.11]],"id":70003371}],"con":true,"img":false}]}
{"op":"mcm","clk":"11450444412","pt":1717322116639,"mc":[{"id":"1.229554920","rc":[{"atl":[[8.2,0]],"id":70003371}],"con":true,"img":false}]}
{"op":"mcm","clk":"11450444422","pt":1717322116741,"mc":[{"id":"1.229554920","rc":[{"atl":[[8.8,5.11]],"id":70003371}],"con":true,"img":false}]}
{"op":"mcm","clk":"11450445141","pt":1717322124544,"mc":[{"id":"1.229554920","rc":[{"atl":[[120,4.61]],"id":64546979}],"con":true,"img":false}]}
{"op":"mcm","clk":"11450445150","pt":1717322124650,"mc":[{"id":"1.229554920","rc":[{"atl":[[150,0]],"id":64546979}],"con":true,"img":false}]}
{"op":"mcm","clk":"11450445936","pt":1717322134146,"mc":[{"id":"1.229554920","rc":[{"atl":[[9,0.97],[8.6,6.84]],"id":70003371}],"con":true,"img":false}]}
{"op":"mcm","clk":"11450445977","pt":1717322134562,"mc":[{"id":"1.229554920","rc":[{"atl":[[8.8,0]],"id":70003371}],"con":true,"img":false}]}
{"op":"mcm","clk":"11450445990","pt":1717322134667,"mc":[{"id":"1.229554920","rc":[{"atl":[[8.6,0],[9,13.47],[8.4,5.11]],"id":70003371}],"con":true,"img":false}]}
{"op":"mcm","clk":"11450446000","pt":1717322134770,"mc":[{"id":"1.229554920","rc":[{"atl":[[8.2,6.84]],"id":70003371}],"con":true,"img":false}]}
{"op":"mcm","clk":"11450446010","pt":1717322134872,"mc":[{"id":"1.229554920","rc":[{"atl":[[9,0.97]],"id":70003371}],"con":true,"img":false}]}
{"op":"mcm","clk":"11450446104","pt":1717322135768,"mc":[{"id":"1.229554920","rc":[{"atl":[[8.4,0]],"id":70003371}],"con":true,"img":false}]}
{"op":"mcm","clk":"11450446111","pt":1717322135858,"mc":[{"id":"1.229554920","rc":[{"atl":[[8,5.11]],"id":70003371}],"con":true,"img":false}]}
{"op":"mcm","clk":"11450446121","pt":1717322135964,"mc":[{"id":"1.229554920","rc":[{"atl":[[9,13.47],[8.2,0]],"id":70003371}],"con":true,"img":false}]}
{"op":"mcm","clk":"11450446133","pt":1717322136067,"mc":[{"id":"1.229554920","rc":[{"atl":[[9,0.97],[8.2,10.22]],"id":70003371}],"con":true,"img":false}]}
{"op":"mcm","clk":"11450447599","pt":1717322154448,"mc":[{"id":"1.229554920","rc":[{"atb":[[2.26,0]],"id":52671121}],"con":true,"img":false}]}
{"op":"mcm","clk":"11450447610","pt":1717322154554,"mc":[{"id":"1.229554920","rc":[{"atb":[[2.32,9.37]],"id":52671121}],"con":true,"img":false}]}
{"op":"mcm","clk":"11450447638","pt":1717322154861,"mc":[{"id":"1.229554920","rc":[{"atb":[[2.54,0]],"id":70003371}],"con":true,"img":false}]}
{"op":"mcm","clk":"11450447644","pt":1717322154973,"mc":[{"id":"1.229554920","rc":[{"atb":[[2.62,9.37]],"id":70003371}],"con":true,"img":false}]}
{"op":"mcm","clk":"11450447672","pt":1717322155281,"mc":[{"id":"1.229554920","rc":[{"atb":[[2.74,0]],"id":65460404}],"con":true,"img":false}]}
{"op":"mcm","clk":"11450447680","pt":1717322155412,"mc":[{"id":"1.229554920","rc":[{"atb":[[2.82,9.37]],"id":65460404}],"con":true,"img":false}]}
{"op":"mcm","clk":"11450447702","pt":1717322155649,"mc":[{"id":"1.229554920","rc":[{"atb":[[3.45,0]],"id":62262930},{"spn":5.5,"spf":"NaN","id":70003371}],"con":true,"img":false}]}
{"op":"mcm","clk":"11450447708","pt":1717322155752,"mc":[{"id":"1.229554920","rc":[{"atb":[[3.55,9.37]],"id":62262930}],"con":true,"img":false}]}
{"op":"mcm","clk":"11450447728","pt":1717322156060,"mc":[{"id":"1.229554920","rc":[{"atb":[[13,0]],"id":69577417}],"con":true,"img":false}]}
{"op":"mcm","clk":"11450447734","pt":1717322156164,"mc":[{"id":"1.229554920","rc":[{"atb":[[13.5,14.71]],"id":69577417}],"con":true,"img":false}]}
{"op":"mcm","clk":"11450447758","pt":1717322156474,"mc":[{"id":"1.229554920","rc":[{"atb":[[15.5,0]],"id":64546979}],"con":true,"img":false}]}
{"op":"mcm","clk":"11450447768","pt":1717322156581,"mc":[{"id":"1.229554920","rc":[{"atb":[[16,9.37]],"id":64546979}],"con":true,"img":false}]}
{"op":"mcm","clk":"11450448435","pt":1717322163679,"mc":[{"id":"1.229554920","rc":[{"atb":[[2.76,2.11]],"id":52671121},{"atb":[[3.2,2.11]],"id":65460404},{"atb":[[3.2,2.11]],"id":70003371}],"con":true,"img":false}]}
{"op":"mcm","clk":"11450449658","pt":1717322176881,"mc":[{"id":"1.229554920","rc":[{"atl":[[8.6,2.24]],"id":65460404}],"con":true,"img":false}]}
{"op":"mcm","clk":"11450449676","pt":1717322177094,"mc":[{"id":"1.229554920","rc":[{"atl":[[7.6,7.65]],"id":52671121}],"con":true,"img":false}]}
{"op":"mcm","clk":"11450449686","pt":1717322177192,"mc":[{"id":"1.229554920","rc":[{"atl":[[12,1.61]],"id":62262930},{"atl":[[9.4,0.9]],"id":65460404}],"con":true,"img":false}]}
{"op":"mcm","clk":"11450449692","pt":1717322177291,"mc":[{"id":"1.229554920","rc":[{"atl":[[8.4,5.11]],"id":65460404}],"con":true,"img":false}]}
{"op":"mcm","clk":"11450449713","pt":1717322177503,"mc":[{"id":"1.229554920","rc":[{"atl":[[7.6,2.53]],"id":70003371}],"con":true,"img":false}]}
{"op":"mcm","clk":"11450449776","pt":1717322178181,"mc":[{"id":"1.229554920","rc":[{"atl":[[7.6,2.53]],"id":52671121}],"con":true,"img":false}]}
{"op":"mcm","clk":"11450449783","pt":1717322178286,"mc":[{"id":"1.229554920","rc":[{"atl":[[7.4,5.11]],"id":52671121}],"con":true,"img":false}]}
{"op":"mcm","clk":"11450449808","pt":1717322178598,"mc":[{"id":"1.229554920","rc":[{"atl":[[8,0]],"id":70003371}],"con":true,"img":false}]}
{"op":"mcm","clk":"11450449815","pt":1717322178699,"mc":[{"id":"1.229554920","rc":[{"atl":[[7.6,7.65]],"id":70003371}],"con":true,"img":false}]}
{"op":"mcm","clk":"11450451530","pt":1717322198430,"mc":[{"id":"1.229554920","rc":[{"atb":[[5.2,0],[4.4,26.18]],"id":64546979},{"atl":[[8.6,13.16],[8.2,0]],"id":70003371}],"con":true,"img":false}]}
{"op":"mcm","clk":"11450452371","pt":1717322207247,"mc":[{"id":"1.229554920","rc":[{"atb":[[2.38,0],[2.58,0],[2.48,0]],"id":52671121},{"atl":[[11,0],[8.4,0]],"id":52671121},{"atb":[[3.4,0],[3.9,0],[3.65,0]],"id":62262930},{"atl":[[19,0],[28,0]],"id":62262930},{"atb":[[9.6,0],[8.6,0],[11.5,0]],"id":69577417},{"atl":[[300,0],[200,0]],"id":69577417},{"atb":[[19.5,0],[24,0],[29,0]],"id":69421986},{"atl":[[400,0],[500,0]],"id":69421986},{"atb":[[2.88,0],[2.98,0],[2.78,0]],"id":65460404},{"atl":[[10.5,0],[15.5,0]],"id":65460404},{"atb":[[17,4.15],[12,0],[14.5,0]],"id":64546979},{"atl":[[350,0],[250,0]],"id":64546979},{"atb":[[2.88,0],[2.98,0],[2.78,0]],"id":70003371},{"atl":[[10.5,0],[15.5,0]],"id":70003371}],"con":true,"img":false}]}
{"op":"mcm","clk":"11450453045","pt":1717322214342,"mc":[{"id":"1.229554920","rc":[{"atb":[[3.55,0]],"id":62262930}],"con":true,"img":false}]}
{"op":"mcm","clk":"11450453052","pt":1717322214443,"mc":[{"id":"1.229554920","rc":[{"atb":[[3.6,9.37]],"id":62262930}],"con":true,"img":false}]}
{"op":"mcm","clk":"11450453081","pt":1717322214752,"mc":[{"id":"1.229554920","rc":[{"atb":[[16,0]],"id":64546979}],"con":true,"img":false}]}
{"op":"mcm","clk":"11450453090","pt":1717322214857,"mc":[{"id":"1.229554920","rc":[{"atb":[[16.5,9.37]],"id":64546979}],"con":true,"img":false}]}
{"op":"mcm","clk":"11450453123","pt":1717322215147,"mc":[{"id":"1.229554920","rc":[{"atb":[[32,0]],"id":69421986}],"con":true,"img":false}]}
{"op":"mcm","clk":"11450453134","pt":1717322215225,"mc":[{"id":"1.229554920","rc":[{"atb":[[34,11.98]],"id":69421986}],"con":true,"img":false}]}
{"op":"mcm","clk":"11450453155","pt":1717322215436,"mc":[{"id":"1.229554920","rc":[{"atb":[[2.6,0]],"id":52671121},{"atb":[[3.95,0],[3.7,0]],"id":62262930},{"atb":[[25,0]],"id":69421986},{"atl":[[390,0]],"id":69421986},{"atb":[[3,28.34]],"id":65460404},{"atl":[[10,0]],"id":65460404},{"atb":[[15,0]],"id":64546979},{"atb":[[2.9,0],[3,0]],"id":70003371},{"atl":[[10,0],[12,10.51]],"id":70003371}],"con":true,"img":false}]}
{"op":"mcm","clk":"11450453165","pt":1717322215536,"mc":[{"id":"1.229554920","rc":[{"atb":[[2.4,80.56]],"id":52671121},{"atb":[[3.7,21.17],[3.3,43.49]],"id":62262930},{"atb":[[22,6.27]],"id":69421986},{"atl":[[460,2.61],[910,2],[470,0]],"id":69421986},{"atb":[[2.7,70.1]],"id":65460404},{"atl":[[11.5,13.6]],"id":65460404},{"atb":[[13,8.89]],"id":64546979},{"atb":[[2.92,28.34],[2.64,64.95]],"id":70003371}],"con":true,"img":false}]}
{"op":"mcm","clk":"11450453191","pt":1717322215948,"mc":[{"id":"1.229554920","rc":[{"atb":[[2.32,0]],"id":52671121},{"spn":5.08,"spf":"NaN","id":52671121},{"spn":7.85,"spf":"NaN","id":62262930},{"spn":5.8,"spf":"NaN","id":65460404},{"spn":5.4,"spf":"NaN","id":70003371}],"con":true,"img":false}]}
{"op":"mcm","clk":"11450453199","pt":1717322216049,"mc":[{"id":"1.229554920","rc":[{"atb":[[2.38,9.37]],"id":52671121}],"con":true,"img":false}]}
{"op":"mcm","clk":"11450453231","pt":1717322216374,"mc":[{"id":"1.229554920","rc":[{"atb":[[2.62,0]],"id":70003371}],"con":true,"img":false}]}
{"op":"mcm","clk":"11450453240","pt":1717322216420,"mc":[{"id":"1.229554920","rc":[{"atb":[[2.68,9.37]],"id":70003371}],"con":true,"img":false}]}
{"op":"mcm","clk":"11450453268","pt":1717322216730,"mc":[{"id":"1.229554920","rc":[{"atb":[[2.82,0]],"id":65460404}],"con":true,"img":false}]}
{"op":"mcm","clk":"11450453279","pt":1717322216834,"mc":[{"id":"1.229554920","rc":[{"atb":[[2.88,9.37]],"id":65460404}],"con":true,"img":false}]}
{"op":"mcm","clk":"11450454069","pt":1717322225361,"mc":[{"id":"1.229554920","rc":[{"atb":[[2.38,160.86],[2.58,66.16],[2.48,141.25]],"id":52671121},{"atl":[[11,20.9],[8.4,18.83]],"id":52671121},{"atb":[[3.4,87.1],[3.9,36.04],[3.65,78.88]],"id":62262930},{"atl":[[19,7.74],[28,7.74]],"id":62262930},{"atb":[[9.6,24.31],[8.6,27.5],[11.5,9.95]],"id":69577417},{"atl":[[300,0.7],[200,0.7]],"id":69577417},{"atb":[[19.5,11.3],[24,9.08],[29,3.73]],"id":69421986},{"atl":[[400,0.35],[500,0.41]],"id":69421986},{"atb":[[2.88,120.57],[2.98,52.79],[2.78,117.44]],"id":65460404},{"atl":[[10.5,14.66],[15.5,14.41]],"id":65460404},{"atb":[[17,10.68],[12,19],[14.5,15.48]],"id":64546979},{"atl":[[350,0.59],[250,0.55]],"id":64546979},{"atb":[[2.88,111.2],[2.98,52.79],[2.78,117.44]],"id":70003371},{"atl":[[10.5,14.66],[15.5,14.41]],"id":70003371}],"con":true,"img":false}]}
{"op":"mcm","clk":"11450454820","pt":1717322232974,"mc":[{"id":"1.229554920","rc":[{"atl":[[910,0],[510,2]],"id":69421986}],"con":true,"img":false}]}
{"op":"mcm","clk":"11450457060","pt":1717322255493,"mc":[{"id":"1.229554920","rc":[{"atb":[[2.92,0]],"id":70003371}],"con":true,"img":false}]}
{"op":"mcm","clk":"11450457071","pt":1717322255592,"mc":[{"id":"1.229554920","rc":[{"atb":[[3,28.34]],"id":70003371}],"con":true,"img":false}]}
{"op":"mcm","clk":"11450458029","pt":1717322265509,"mc":[{"id":"1.229554920","rc":[{"atb":[[3.7,0]],"id":62262930},{"atl":[[460,0]],"id":69421986}],"con":true,"img":false}]}
{"op":"mcm","clk":"11450458041","pt":1717322265609,"mc":[{"id":"1.229554920","rc":[{"atb":[[3.95,21.17]],"id":62262930},{"atl":[[390,2.61]],"id":69421986}],"con":true,"img":false}]}
{"op":"mcm","clk":"11450458808","pt":1717322275514,"mc":[{"id":"1.229554920","rc":[{"atb":[[2.4,0]],"id":52671121},{"atb":[[3.3,0]],"id":62262930},{"atb":[[22,0]],"id":69421986},{"atb":[[2.7,0]],"id":65460404},{"atl":[[11.5,0]],"id":65460404},{"atb":[[13,0]],"id":64546979},{"atb":[[2.64,0]],"id":70003371},{"atl":[[10,12.84],[12,0]],"id":70003371}],"con":true,"img":false}]}
{"op":"mcm","clk":"11450458819","pt":1717322275609,"mc":[{"id":"1.229554920","rc":[{"atb":[[2.6,80.56]],"id":52671121},{"atb":[[3.7,43.49]],"id":62262930},{"atb":[[25,6.27]],"id":69421986},{"atb":[[3,98.44]],"id":65460404},{"atl":[[10,13.6]],"id":65460404},{"atb":[[15,8.89]],"id":64546979},{"atb":[[2.9,64.95]],"id":70003371}],"con":true,"img":false}]}
{"op":"mcm","clk":"11450467628","pt":1717322379194,"mc":[{"id":"1.229554920","rc":[{"spn":7.97,"spf":"NaN","id":62262930},{"atl":[[8.6,0]],"id":65460404}],"con":true,"img":false}]}
{"op":"mcm","clk":"11450467718","pt":1717322380286,"mc":[{"id":"1.229554920","rc":[{"atl":[[8.4,0]],"id":65460404}],"con":true,"img":false}]}
{"op":"mcm","clk":"11450467728","pt":1717322380394,"mc":[{"id":"1.229554920","rc":[{"atl":[[12,0],[14,7.69],[9.4,6.01]],"id":65460404}],"con":true,"img":false}]}
{"op":"mcm","clk":"11450470605","pt":1717322410544,"mc":[{"id":"1.229554920","rc":[{"atl":[[7.6,0]],"id":52671121}],"con":true,"img":false}]}
{"op":"mcm","clk":"11450470624","pt":1717322410712,"mc":[{"id":"1.229554920","rc":[{"atl":[[7.4,0]],"id":52671121}],"con":true,"img":false}]}
{"op":"mcm","clk":"11450470631","pt":1717322410845,"mc":[{"id":"1.229554920","rc":[{"atl":[[7.6,5.11]],"id":52671121}],"con":true,"img":false}]}
{"op":"mcm","clk":"11450470840","pt":1717322412760,"mc":[{"id":"1.229554920","rc":[{"atl":[[1000,1.85]],"id":62262930}],"con":true,"img":false}]}
{"op":"mcm","clk":"11450470925","pt":1717322413546,"mc":[{"id":"1.229554920","rc":[{"atl":[[1000,3.35]],"id":52671121},{"atl":[[1000,4.2]],"id":62262930},{"atl":[[1000,3.52]],"id":65460404},{"atl":[[1000,3.35]],"id":70003371}],"con":true,"img":false}]}
{"op":"mcm","clk":"11450470940","pt":1717322413750,"mc":[{"id":"1.229554920","rc":[{"atb":[[2.64,4.78]],"id":52671121}],"con":true,"img":false}]}
{"op":"mcm","clk":"11450470967","pt":1717322414017,"mc":[{"id":"1.229554920","rc":[{"atl":[[1000,2.9]],"id":70003371}],"con":true,"img":false}]}
{"op":"mcm","clk":"11450470976","pt":1717322414120,"mc":[{"id":"1.229554920","rc":[{"atl":[[1000,2.85]],"id":52671121}],"con":true,"img":false}]}
{"op":"mcm","clk":"11450471001","pt":1717322414435,"mc":[{"id":"1.229554920","rc":[{"atl":[[12.5,0],[1000,2.96]],"id":62262930},{"atl":[[1000,2.72]],"id":65460404},{"atl":[[1000,1]],"id":70003371}],"con":true,"img":false}]}
{"op":"mcm","clk":"11450471011","pt":1717322414533,"mc":[{"id":"1.229554920","rc":[{"atl":[[7,1.9]],"id":70003371}],"con":true,"img":false}]}
{"op":"mcm","clk":"11450471039","pt":1717322414844,"mc":[{"id":"1.229554920","rc":[{"atl":[[1000,1]],"id":52671121}],"con":true,"img":false}]}
{"op":"mcm","clk":"11450471048","pt":1717322414950,"mc":[{"id":"1.229554920","rc":[{"atl":[[7.2,1.85]],"id":52671121}],"con":true,"img":false}]}
{"op":"mcm","clk":"11450471069","pt":1717322415154,"mc":[{"id":"1.229554920","rc":[{"atl":[[1000,1.17]],"id":65460404}],"con":true,"img":false}]}
{"op":"mcm","clk":"11450471081","pt":1717322415258,"mc":[{"id":"1.229554920","rc":[{"atl":[[8.6,1.55]],"id":65460404}],"con":true,"img":false}]}
{"op":"mcm","clk":"11450471103","pt":1717322415469,"mc":[{"id":"1.229554920","rc":[{"atl":[[7.6,0]],"id":52671121},{"atl":[[1000,1.85]],"id":62262930}],"con":true,"img":false}]}
{"op":"mcm","clk":"11450471112","pt":1717322415527,"mc":[{"id":"1.229554920","rc":[{"atl":[[7,5.11]],"id":52671121}],"con":true,"img":false}]}
{"op":"mcm","clk":"11450471125","pt":1717322415631,"mc":[{"id":"1.229554920","rc":[{"atl":[[12,2.72]],"id":62262930}],"con":true,"img":false}]}
{"op":"mcm","clk":"11450471137","pt":1717322415737,"mc":[{"id":"1.229554920","rc":[{"atl":[[1000,1.74]],"id":62262930}],"con":true,"img":false}]}
{"op":"mcm","clk":"11450471256","pt":1717322416732,"mc":[{"id":"1.229554920","rc":[{"atl":[[9.4,0.9]],"id":65460404}],"con":true,"img":false}]}
{"op":"mcm","clk":"11450471267","pt":1717322416836,"mc":[{"id":"1.229554920","rc":[{"atl":[[9.2,5.11]],"id":65460404}],"con":true,"img":false}]}
{"op":"mcm","clk":"11450471735","pt":1717322421231,"mc":[{"id":"1.229554920","rc":[{"atl":[[1000,1]],"id":62262930}],"con":true,"img":false}]}
{"op":"mcm","clk":"11450471745","pt":1717322421332,"mc":[{"id":"1.229554920","rc":[{"atl":[[11.5,0.74]],"id":62262930}],"con":true,"img":false}]}
{"op":"mcm","clk":"11450473836","pt":1717322442569,"mc":[{"id":"1.229554920","rc":[{"spn":4.88,"spf":"NaN","id":52671121},{"atl":[[12,1.11]],"id":62262930},{"spn":7.72,"spf":"NaN","id":62262930},{"spn":5.9,"spf":"NaN","id":65460404},{"spn":5.1,"spf":"NaN","id":70003371}],"con":true,"img":false}]}
{"op":"mcm","clk":"11450478117","pt":1717322490363,"mc":[{"id":"1.229554920","rc":[{"atl":[[7.6,5.11]],"id":70003371}],"con":true,"img":false}]}
{"op":"mcm","clk":"11450480968","pt":1717322525887,"mc":[{"id":"1.229554920","rc":[{"atl":[[7.6,2.53]],"id":52671121},{"atl":[[12,2.72]],"id":62262930}],"con":true,"img":false}]}
{"op":"mcm","clk":"11450480992","pt":1717322526192,"mc":[{"id":"1.229554920","rc":[{"atl":[[8.8,2.19]],"id":65460404}],"con":true,"img":false}]}
{"op":"mcm","clk":"11450481024","pt":1717322526495,"mc":[{"id":"1.229554920","rc":[{"atl":[[8,2.4]],"id":70003371}],"con":true,"img":false}]}
{"op":"mcm","clk":"11450481068","pt":1717322526965,"mc":[{"id":"1.229554920","rc":[{"atl":[[9.2,0]],"id":65460404}],"con":true,"img":false}]}
{"op":"mcm","clk":"11450481076","pt":1717322527075,"mc":[{"id":"1.229554920","rc":[{"atl":[[8.6,6.66]],"id":65460404}],"con":true,"img":false}]}
{"op":"mcm","clk":"11450484017","pt":1717322565886,"mc":[{"id":"1.229554920","rc":[{"atl":[[8.6,3.02]],"id":52671121}],"con":true,"img":false}]}
{"op":"mcm","clk":"11450484305","pt":1717322570105,"mc":[{"id":"1.229554920","rc":[{"atl":[[8.6,0]],"id":52671121}],"con":true,"img":false}]}
{"op":"mcm","clk":"11450485412","pt":1717322584114,"mc":[{"id":"1.229554920","rc":[{"atb":[[2.38,9.37],[2.58,0],[2.48,0]],"id":52671121},{"atl":[[11,0],[8.4,0]],"id":52671121},{"atb":[[3.4,0],[3.9,0],[3.65,0]],"id":62262930},{"atl":[[19,0],[28,0]],"id":62262930},{"atb":[[9.6,0],[8.6,0],[11.5,0]],"id":69577417},{"atl":[[300,0],[200,0]],"id":69577417},{"atb":[[19.5,0],[24,0],[29,0]],"id":69421986},{"atl":[[400,0],[500,0]],"id":69421986},{"atb":[[2.88,9.37],[2.98,0],[2.78,0]],"id":65460404},{"atl":[[10.5,0],[15.5,0]],"id":65460404},{"atb":[[17,4.15],[12,0],[14.5,0]],"id":64546979},{"atl":[[350,0],[250,0]],"id":64546979},{"atb":[[2.88,0],[2.98,0],[2.78,0]],"id":70003371},{"atl":[[10.5,0],[15.5,0]],"id":70003371}],"con":true,"img":false}]}
{"op":"mcm","clk":"11450485528","pt":1717322585528,"mc":[{"id":"1.229554920","rc":[{"atb":[[2.6,0]],"id":52671121},{"atb":[[3.95,0],[3.7,0]],"id":62262930},{"atb":[[25,0]],"id":69421986},{"atl":[[390,0]],"id":69421986},{"atb":[[3,28.34]],"id":65460404},{"atl":[[10,0],[12.5,9.94]],"id":65460404},{"atb":[[15,0]],"id":64546979},{"atb":[[2.9,0],[3,0]],"id":70003371},{"atl":[[10,0],[12,10.51]],"id":70003371}],"con":true,"img":false}]}
{"op":"mcm","clk":"11450485534","pt":1717322585631,"mc":[{"id":"1.229554920","rc":[{"atb":[[2.4,80.56]],"id":52671121},{"atb":[[3.7,21.17],[3.3,43.49]],"id":62262930},{"atb":[[22,6.27]],"id":69421986},{"atl":[[460,2.61]],"id":69421986},{"atb":[[2.7,70.1]],"id":65460404},{"atb":[[13,8.89]],"id":64546979},{"atb":[[2.92,28.34],[2.64,64.95]],"id":70003371}],"con":true,"img":false}]}
{"op":"mcm","clk":"11450485537","pt":1717322585686,"mc":[{"id":"1.229554920","rc":[{"atl":[[910,2],[510,0]],"id":69421986}],"con":true,"img":false}]}
{"op":"mcm","clk":"11450485544","pt":1717322585788,"mc":[{"id":"1.229554920","rc":[{"atl":[[510,2]],"id":69421986}],"con":true,"img":false}]}
{"op":"mcm","clk":"11450485553","pt":1717322585894,"mc":[{"id":"1.229554920","rc":[{"spn":7.6,"spf":"NaN","id":62262930},{"atl":[[910,0]],"id":69421986}],"con":true,"img":false}]}
{"op":"mcm","clk":"11450486807","pt":1717322599817,"mc":[{"id":"1.229554920","rc":[{"spl":[[1.01,1.04]],"id":69577417},{"spl":[[1.01,1.56]],"id":69421986},{"spl":[[1.01,1.56]],"id":64546979}],"con":true,"img":false}]}
{"op":"mcm","clk":"11450486952","pt":1717322601544,"mc":[{"id":"1.229554920","rc":[{"atb":[[2.38,160.86],[2.58,66.16],[2.48,141.25]],"id":52671121},{"atl":[[11,20.9],[8.4,18.83]],"id":52671121},{"atb":[[3.4,87.1],[3.9,36.04],[3.65,78.88]],"id":62262930},{"atl":[[19,7.74],[28,7.74]],"id":62262930},{"atb":[[9.6,24.31],[8.6,27.5],[11.5,9.95]],"id":69577417},{"atl":[[300,0.7],[200,0.7]],"id":69577417},{"atb":[[19.5,11.3],[24,9.08],[29,3.73]],"id":69421986},{"atl":[[400,0.35],[500,0.41]],"id":69421986},{"atb":[[2.88,120.57],[2.98,52.79],[2.78,117.44]],"id":65460404},{"atl":[[10.5,14.66],[15.5,14.41]],"id":65460404},{"atb":[[17,10.68],[12,19],[14.5,15.48]],"id":64546979},{"atl":[[350,0.59],[250,0.55]],"id":64546979},{"atb":[[2.88,111.2],[2.98,52.79],[2.78,117.44]],"id":70003371},{"atl":[[10.5,14.66],[15.5,14.41]],"id":70003371}],"con":true,"img":false}]}
{"op":"mcm","clk":"11450487035","pt":1717322602543,"mc":[{"id":"1.229554920","rc":[{"atl":[[8.6,5.11]],"id":65460404}],"con":true,"img":false}]}
{"op":"mcm","clk":"11450489051","pt":1717322623900,"mc":[{"id":"1.229554920","rc":[{"atl":[[7.2,0]],"id":52671121}],"con":true,"img":false}]}
{"op":"mcm","clk":"11450489131","pt":1717322624554,"mc":[{"id":"1.229554920","rc":[{"atl":[[7,0]],"id":52671121}],"con":true,"img":false}]}
{"op":"mcm","clk":"11450489141","pt":1717322624655,"mc":[{"id":"1.229554920","rc":[{"atl":[[7.4,5.11]],"id":52671121}],"con":true,"img":false}]}
{"op":"mcm","clk":"11450489220","pt":1717322625450,"mc":[{"id":"1.229554920","rc":[{"atb":[[2.92,0]],"id":70003371}],"con":true,"img":false}]}
{"op":"mcm","clk":"11450489232","pt":1717322625549,"mc":[{"id":"1.229554920","rc":[{"atb":[[3,28.34]],"id":70003371}],"con":true,"img":false}]}
{"op":"mcm","clk":"11450489843","pt":1717322633160,"mc":[{"id":"1.229554920","rc":[{"atl":[[12,1.61]],"id":62262930}],"con":true,"img":false}]}
{"op":"mcm","clk":"11450490000","pt":1717322635188,"mc":[{"id":"1.229554920","rc":[{"atl":[[7.4,0]],"id":52671121}],"con":true,"img":false}]}
{"op":"mcm","clk":"11450490009","pt":1717322635290,"mc":[{"id":"1.229554920","rc":[{"atl":[[9.6,5.11]],"id":52671121}],"con":true,"img":false}]}
{"op":"mcm","clk":"11450490032","pt":1717322635552,"mc":[{"id":"1.229554920","rc":[{"atb":[[3.7,0]],"id":62262930},{"atl":[[460,0]],"id":69421986}],"con":true,"img":false}]}
{"op":"mcm","clk":"11450490044","pt":1717322635665,"mc":[{"id":"1.229554920","rc":[{"atb":[[3.95,21.17]],"id":62262930},{"atl":[[390,2.61]],"id":69421986},{"atl":[[7.6,0]],"id":70003371}],"con":true,"img":false}]}
{"op":"mcm","clk":"11450490049","pt":1717322635761,"mc":[{"id":"1.229554920","rc":[{"atl":[[11.5,5.11]],"id":70003371}],"con":true,"img":false}]}
{"op":"mcm","clk":"11450490083","pt":1717322636187,"mc":[{"id":"1.229554920","rc":[{"atl":[[8.6,0]],"id":65460404}],"con":true,"img":false}]}
{"op":"mcm","clk":"11450490094","pt":1717322636283,"mc":[{"id":"1.229554920","rc":[{"atl":[[12.5,15.05]],"id":65460404}],"con":true,"img":false}]}
{"op":"mcm","clk":"11450490256","pt":1717322638280,"mc":[{"id":"1.229554920","rc":[{"atl":[[21,5],[8.2,16.74]],"id":52671121},{"atl":[[65,2],[23,0]],"id":62262930},{"atb":[[2.42,0],[2.66,60.24]],"id":65460404},{"atb":[[2.06,0],[1.08,117.75]],"id":70003371}],"con":true,"img":false}]}
{"op":"mcm","clk":"11450490567","pt":1717322642215,"mc":[{"id":"1.229554920","rc":[{"atb":[[15,2]],"id":69577417},{"atl":[[80,4.61]],"id":69577417},{"atl":[[390,4.61]],"id":69421986},{"atl":[[120,6.61]],"id":64546979}],"con":true,"img":false}]}
{"op":"mcm","clk":"11450490578","pt":1717322642299,"mc":[{"id":"1.229554920","rc":[{"atl":[[160,4.61],[120,4.61]],"id":64546979}],"con":true,"img":false}]}
{"op":"mcm","clk":"11450490947","pt":1717322645504,"mc":[{"id":"1.229554920","rc":[{"atb":[[2.4,0]],"id":52671121},{"atb":[[3.3,0]],"id":62262930},{"atb":[[22,0]],"id":69421986},{"atb":[[2.7,0]],"id":65460404},{"atl":[[10,13.6],[12.5,5.11]],"id":65460404},{"atb":[[13,0]],"id":64546979},{"atb":[[2.64,0]],"id":70003371},{"atl":[[10,12.84],[12,0]],"id":70003371}],"con":true,"img":false}]}
{"op":"mcm","clk":"11450490959","pt":1717322645568,"mc":[{"id":"1.229554920","rc":[{"atb":[[2.6,80.56]],"id":52671121},{"atb":[[3.7,43.49]],"id":62262930},{"atb":[[25,6.27]],"id":69421986},{"atb":[[3,98.44]],"id":65460404},{"atb":[[15,8.89]],"id":64546979},{"atb":[[2.9,64.95]],"id":70003371}],"con":true,"img":false}]}
{"op":"mcm","clk":"11450491670","pt":1717322653473,"mc":[{"id":"1.229554920","rc":[{"spn":5.18,"spf":"NaN","id":52671121},{"spn":7.72,"spf":"NaN","id":62262930},{"spn":15.0,"spf":1.0,"id":69577417},{"spn":34.0,"spf":1.0,"id":69421986},{"spn":6.0,"spf":"NaN","id":65460404},{"spn":17.0,"spf":1.0,"id":64546979},{"atl":[[7,0]],"id":70003371},{"spn":5.6,"spf":"NaN","id":70003371}],"con":true,"img":false}]}
{"op":"mcm","clk":"11450491680","pt":1717322653577,"mc":[{"id":"1.229554920","rc":[{"atl":[[8.6,0],[9,13.47]],"id":70003371}],"con":true,"img":false}]}
{"op":"mcm","clk":"11450491822","pt":1717322655397,"mc":[{"id":"1.229554920","rc":[{"atl":[[160,2.61],[120,6.61]],"id":64546979}],"con":true,"img":false}]}
{"op":"mcm","clk":"11450492019","pt":1717322657711,"mc":[{"id":"1.229554920","rc":[{"atl":[[17,6.93]],"id":62262930}],"con":true,"img":false}]}
{"op":"mcm","clk":"11450492043","pt":1717322657971,"mc":[{"id":"1.229554920","rc":[{"atl":[[140,0]],"id":69577417}],"con":true,"img":false}]}
{"op":"mcm","clk":"11450492062","pt":1717322658279,"mc":[{"id":"1.229554920","rc":[{"atl":[[200,0]],"id":64546979}],"con":true,"img":false}]}
{"op":"mcm","clk":"11450492079","pt":1717322658590,"mc":[{"id":"1.229554920","rc":[{"atb":[[13.5,5.34]],"id":69577417}],"con":true,"img":false}]}
{"op":"mcm","clk":"11450492105","pt":1717322658910,"mc":[{"id":"1.229554920","rc":[{"atb":[[3.6,0]],"id":62262930}],"con":true,"img":false}]}
{"op":"mcm","clk":"11450492136","pt":1717322659218,"mc":[{"id":"1.229554920","rc":[{"atb":[[16.5,0]],"id":64546979}],"con":true,"img":false}]}
{"op":"mcm","clk":"11450492151","pt":1717322659379,"mc":[{"id":"1.229554920","rc":[{"atb":[[34,2.61]],"id":69421986}],"con":true,"img":false}]}
{"op":"mcm","clk":"11450492175","pt":1717322659692,"mc":[{"id":"1.229554920","rc":[{"atb":[[2.38,151.49]],"id":52671121}],"con":true,"img":false}]}
{"op":"mcm","clk":"11450492202","pt":1717322660005,"mc":[{"id":"1.229554920","rc":[{"atb":[[2.68,0]],"id":70003371}],"con":true,"img":false}]}
{"op":"mcm","clk":"11450492227","pt":1717322660319,"mc":[{"id":"1.229554920","rc":[{"atb":[[2.88,111.2]],"id":65460404}],"con":true,"img":false}]}
{"op":"mcm","clk":"11450492257","pt":1717322660581,"mc":[{"id":"1.229554920","rc":[{"atl":[[9.6,0]],"id":52671121}],"con":true,"img":false}]}
{"op":"mcm","clk":"11450492277","pt":1717322660794,"mc":[{"id":"1.229554920","rc":[{"atl":[[11.5,0]],"id":70003371}],"con":true,"img":false}]}
{"op":"mcm","clk":"11450492301","pt":1717322661106,"mc":[{"id":"1.229554920","rc":[{"atl":[[12.5,0]],"id":65460404}],"con":true,"img":false}]}
{"op":"mcm","clk":"11450492639","pt":1717322665330,"mc":[{"id":"1.229554920","rc":[{"atb":[[2,100],[2.22,0]],"id":52671121},{"atb":[[4.1,48.39],[3.05,24.39]],"id":69577417},{"atl":[[470,2],[510,0]],"id":69421986},{"atb":[[2.5,66.67],[2.66,0]],"id":65460404},{"atl":[[11.5,9.52],[14,0]],"id":65460404},{"atb":[[18.5,2],[5.8,20.83],[4.4,0]],"id":64546979}],"con":true,"img":false}]}
{"op":"mcm","clk":"11450492651","pt":1717322665384,"mc":[{"id":"1.229554920","rc":[{"atb":[[2,0]],"id":52671121},{"atl":[[130,2],[120,4.61]],"id":64546979}],"con":true,"img":false}]}
{"op":"mcm","clk":"11450492662","pt":1717322665491,"mc":[{"id":"1.229554920","rc":[{"atb":[[2.16,86.21]],"id":52671121},{"atb":[[4.6,27.78],[4.1,16.13],[13.5,0]],"id":69577417},{"atl":[[80,2]],"id":69577417},{"atb":[[18.5,0],[19.5,2]],"id":64546979},{"atl":[[9.2,0]],"id":70003371}],"con":true,"img":false}]}
{"op":"mcm","clk":"11450492669","pt":1717322665591,"mc":[{"id":"1.229554920","rc":[{"atb":[[12.5,5.34]],"id":69577417},{"atl":[[75,2.72]],"id":69577417},{"atl":[[8.8,6.84]],"id":70003371}],"con":true,"img":false}]}
{"op":"mcm","clk":"11450492681","pt":1717322665695,"mc":[{"id":"1.229554920","rc":[{"atl":[[80,0],[100,4.61]],"id":69577417}],"con":true,"img":false}]}
{"op":"mcm","clk":"11450492695","pt":1717322665800,"mc":[{"id":"1.229554920","rc":[{"atl":[[75,4.72],[100,2.61]],"id":69577417}],"con":true,"img":false}]}
{"op":"mcm","clk":"11450492706","pt":1717322666005,"mc":[{"id":"1.229554920","rc":[{"atl":[[75,2.72]],"id":69577417}],"con":true,"img":false}]}
{"op":"mcm","clk":"11450492713","pt":1717322666109,"mc":[{"id":"1.229554920","rc":[{"atl":[[100,4.61]],"id":69577417}],"con":true,"img":false}]}
{"op":"mcm","clk":"11450493119","pt":1717322670923,"mc":[{"id":"1.229554920","rc":[{"atl":[[75,4.72]],"id":69577417}],"con":true,"img":false}]}
{"op":"mcm","clk":"11450493126","pt":1717322671005,"mc":[{"id":"1.229554920","rc":[{"atl":[[100,2.61]],"id":69577417}],"con":true,"img":false}]}
{"op":"mcm","clk":"11450493550","pt":1717322675645,"mc":[{"id":"1.229554920","rc":[{"atb":[[34,0]],"id":69421986},{"atl":[[390,2]],"id":69421986}],"con":true,"img":false}]}
{"op":"mcm","clk":"11450493560","pt":1717322675745,"mc":[{"id":"1.229554920","rc":[{"atb":[[30,2.61]],"id":69421986},{"atl":[[380,2.61],[500,2.41]],"id":69421986}],"con":true,"img":false}]}
{"op":"mcm","clk":"11450493575","pt":1717322675801,"mc":[{"id":"1.229554920","rc":[{"atl":[[390,0]],"id":69421986}],"con":true,"img":false}]}
{"op":"mcm","clk":"11450493581","pt":1717322675912,"mc":[{"id":"1.229554920","rc":[{"atl":[[500,0.41]],"id":69421986}],"con":true,"img":false}]}
{"op":"mcm","clk":"11450493593","pt":1717322676013,"mc":[{"id":"1.229554920","rc":[{"atl":[[380,4.61]],"id":69421986}],"con":true,"img":false}]}
{"op":"mcm","clk":"11450493641","pt":1717322676534,"mc":[{"id":"1.229554920","rc":[{"atb":[[9.6,0],[8.6,0],[11.5,0]],"id":69577417},{"atl":[[300,0],[200,0]],"id":69577417}],"con":true,"img":false}]}
{"op":"mcm","clk":"11450493821","pt":1717322678530,"mc":[{"id":"1.229554920","rc":[{"atb":[[2.72,58.14],[2.5,0]],"id":65460404},{"atb":[[5.8,0],[3.95,33.9]],"id":64546979},{"atl":[[9,0.97],[8.6,12.85]],"id":70003371}],"con":true,"img":false}]}
{"op":"mcm","clk":"11450493835","pt":1717322678632,"mc":[{"id":"1.229554920","rc":[{"atb":[[5.7,21.28]],"id":64546979}],"con":true,"img":false}]}
{"op":"mcm","clk":"11450493845","pt":1717322678740,"mc":[{"id":"1.229554920","rc":[{"atb":[[3.95,0]],"id":64546979}],"con":true,"img":false}]}
{"op":"mcm","clk":"11450493981","pt":1717322680357,"mc":[{"id":"1.229554920","rc":[{"atl":[[75,2.11]],"id":69577417},{"atl":[[8.8,0]],"id":70003371}],"con":true,"img":false}]}
{"op":"mcm","clk":"11450493990","pt":1717322680464,"mc":[{"id":"1.229554920","rc":[{"atl":[[80,2.61],[100,4.61]],"id":69577417},{"atl":[[9.4,6.84]],"id":70003371}],"con":true,"img":false}]}
{"op":"mcm","clk":"11450494001","pt":1717322680522,"mc":[{"id":"1.229554920","rc":[{"atl":[[75,0.11]],"id":69577417}],"con":true,"img":false}]}
{"op":"mcm","clk":"11450494011","pt":1717322680628,"mc":[{"id":"1.229554920","rc":[{"atl":[[100,2.61]],"id":69577417}],"con":true,"img":false}]}
{"op":"mcm","clk":"11450494017","pt":1717322680733,"mc":[{"id":"1.229554920","rc":[{"atl":[[80,4.61]],"id":69577417}],"con":true,"img":false}]}
{"op":"mcm","clk":"11450494152","pt":1717322682452,"mc":[{"id":"1.229554920","rc":[{"atl":[[1000,3.35]],"id":52671121},{"atl":[[1000,3.35]],"id":62262930},{"atl":[[1000,3.52]],"id":65460404},{"atl":[[1000,3.35]],"id":70003371}],"con":true,"img":false}]}
{"op":"mcm","clk":"11450494172","pt":1717322682656,"mc":[{"id":"1.229554920","rc":[{"atl":[[1000,2.85]],"id":52671121}],"con":true,"img":false}]}
{"op":"mcm","clk":"11450494201","pt":1717322682967,"mc":[{"id":"1.229554920","rc":[{"atl":[[1000,2.11]],"id":62262930},{"atl":[[1000,2.68]],"id":65460404},{"atl":[[1000,2.66]],"id":70003371}],"con":true,"img":false}]}
{"op":"mcm","clk":"11450494365","pt":1717322684480,"mc":[{"id":"1.229554920","rc":[{"atl":[[1000,1]],"id":52671121}],"con":true,"img":false}]}
{"op":"mcm","clk":"11450494372","pt":1717322684547,"mc":[{"id":"1.229554920","rc":[{"atl":[[7.2,1.85]],"id":52671121}],"con":true,"img":false}]}
{"op":"mcm","clk":"11450494397","pt":1717322684854,"mc":[{"id":"1.229554920","rc":[{"atl":[[1000,1]],"id":70003371}],"con":true,"img":false}]}
{"op":"mcm","clk":"11450494407","pt":1717322684957,"mc":[{"id":"1.229554920","rc":[{"atl":[[8,4.06]],"id":70003371}],"con":true,"img":false}]}
{"op":"mcm","clk":"11450494434","pt":1717322685269,"mc":[{"id":"1.229554920","rc":[{"atl":[[1000,1.17]],"id":65460404}],"con":true,"img":false}]}
{"op":"mcm","clk":"11450494439","pt":1717322685331,"mc":[{"id":"1.229554920","rc":[{"atl":[[8.8,3.7]],"id":65460404}],"con":true,"img":false}]}
{"op":"mcm","clk":"11450494467","pt":1717322685649,"mc":[{"id":"1.229554920","rc":[{"atl":[[1000,1]],"id":62262930}],"con":true,"img":false}]}
{"op":"mcm","clk":"11450494478","pt":1717322685745,"mc":[{"id":"1.229554920","rc":[{"atl":[[12,2.72]],"id":62262930}],"con":true,"img":false}]}
{"op":"mcm","clk":"11450494713","pt":1717322688875,"mc":[{"id":"1.229554920","rc":[{"atb":[[9,26.13],[10,23.22],[12.5,14.42]],"id":69577417},{"atl":[[310,0.67],[210,0.66]],"id":69577417}],"con":true,"img":false}]}
{"op":"mcm","clk":"11450496170","pt":1717322705579,"mc":[{"id":"1.229554920","rc":[{"atl":[[80,2]],"id":69577417},{"atl":[[9.4,0]],"id":70003371}],"con":true,"img":false}]}
{"op":"mcm","clk":"11450496179","pt":1717322705688,"mc":[{"id":"1.229554920","rc":[{"atl":[[75,2.72],[80,0],[100,4.61]],"id":69577417},{"atl":[[9.2,6.84]],"id":70003371}],"con":true,"img":false}]}
{"op":"mcm","clk":"11450496265","pt":1717322706680,"mc":[{"id":"1.229554920","rc":[{"atb":[[2.56,6.7]],"id":52671121},{"atb":[[3.55,4.05]],"id":62262930},{"atb":[[2.9,5.48]],"id":65460404},{"atb":[[2.84,5.69]],"id":70003371}],"con":true,"img":false}]}
{"op":"mcm","clk":"11450496273","pt":1717322706787,"mc":[{"id":"1.229554920","rc":[{"atb":[[2.9,0]],"id":65460404}],"con":true,"img":false}]}
{"op":"mcm","clk":"11450496575","pt":1717322710119,"mc":[{"id":"1.229554920","rc":[{"atb":[[2.38,0],[2.58,0],[2.48,0]],"id":52671121},{"atl":[[11,0],[8.4,0]],"id":52671121},{"atb":[[9,0],[10,0],[12.5,5.34]],"id":69577417},{"atl":[[310,0],[210,0]],"id":69577417},{"atb":[[2.88,0],[2.98,0],[2.78,0]],"id":65460404},{"atl":[[10.5,0],[15.5,0]],"id":65460404},{"atb":[[17,4.15],[12,0],[14.5,0]],"id":64546979},{"atl":[[350,0],[250,0]],"id":64546979}],"con":true,"img":false}]}
{"op":"mcm","clk":"11450496641","pt":1717322710806,"mc":[{"id":"1.229554920","rc":[{"atl":[[75,4.72],[100,2.61]],"id":69577417}],"con":true,"img":false}]}
{"op":"mcm","clk":"11450496653","pt":1717322710903,"mc":[{"id":"1.229554920","rc":[{"atl":[[75,2.72],[100,4.61]],"id":69577417}],"con":true,"img":false}]}
{"op":"mcm","clk":"11450497076","pt":1717322715518,"mc":[{"id":"1.229554920","rc":[{"atb":[[2.6,0]],"id":52671121},{"atl":[[10,13.6],[8.2,0]],"id":52671121},{"spn":4.98,"spf":"NaN","id":52671121},{"atl":[[75,0.11]],"id":69577417},{"spn":30.0,"spf":1.0,"id":69421986},{"atb":[[3,28.34]],"id":65460404},{"atl":[[10,0]],"id":65460404},{"atb":[[15,0]],"id":64546979},{"atl":[[160,0]],"id":64546979},{"spn":19.5,"spf":1.0,"id":64546979}],"con":true,"img":false}]}
{"op":"mcm","clk":"11450497088","pt":1717322715615,"mc":[{"id":"1.229554920","rc":[{"atb":[[2.4,80.56]],"id":52671121},{"atl":[[80,2.61]],"id":69577417},{"atb":[[2.74,70.1]],"id":65460404},{"atl":[[11,13.6]],"id":65460404},{"atb":[[13.5,8.89]],"id":64546979},{"atl":[[120,7.23]],"id":64546979}],"con":true,"img":false}]}
{"op":"mcm","clk":"11450497101","pt":1717322715721,"mc":[{"id":"1.229554920","rc":[{"atl":[[80,4.61],[100,2.61]],"id":69577417},{"atl":[[130,0],[120,9.23]],"id":64546979}],"con":true,"img":false}]}
{"op":"mcm","clk":"11450497357","pt":1717322718342,"mc":[{"id":"1.229554920","rc":[{"atb":[[2.38,151.49],[2.58,66.16],[2.48,141.25]],"id":52671121},{"atl":[[11,20.9],[8.4,18.83]],"id":52671121},{"atb":[[11,20.9],[13.5,8.36],[9.4,24.88]],"id":69577417},{"atl":[[320,0.65],[220,0.63]],"id":69577417},{"atb":[[2.86,112.39],[2.96,53.33],[2.76,118.78]],"id":65460404},{"atl":[[10.5,14.66],[15.5,14.41]],"id":65460404},{"atb":[[18,6.14],[13,17.42],[15.5,14.41]],"id":64546979},{"atl":[[260,0.53],[360,0.58]],"id":64546979}],"con":true,"img":false}]}
{"op":"mcm","clk":"11450497384","pt":1717322718609,"mc":[{"id":"1.229554920","rc":[{"atb":[[2.7,2.61]],"id":52671121},{"atb":[[4.4,2.61]],"id":62262930},{"atb":[[3.2,4.72]],"id":65460404},{"atb":[[3.4,2.61]],"id":70003371}],"con":true,"img":false}]}
{"op":"mcm","clk":"11450497498","pt":1717322719814,"mc":[{"id":"1.229554920","rc":[{"atl":[[95,2],[110,0]],"id":69577417},{"atl":[[400,2.35],[470,0]],"id":69421986},{"atl":[[10,11.11],[11.5,0]],"id":65460404},{"atl":[[8.6,0],[7.8,4.07]],"id":70003371}],"con":true,"img":false}]}
{"op":"mcm","clk":"11450497885","pt":1717322723718,"mc":[{"id":"1.229554920","rc":[{"atl":[[380,2]],"id":69421986}],"con":true,"img":false}]}
{"op":"mcm","clk":"11450497892","pt":1717322723817,"mc":[{"id":"1.229554920","rc":[{"atl":[[370,2.61],[500,2.41]],"id":69421986}],"con":true,"img":false}]}
{"op":"mcm","clk":"11450497905","pt":1717322723920,"mc":[{"id":"1.229554920","rc":[{"atl":[[380,0]],"id":69421986}],"con":true,"img":false}]}
{"op":"mcm","clk":"11450498063","pt":1717322725542,"mc":[{"id":"1.229554920","rc":[{"atl":[[370,0]],"id":69421986},{"atl":[[120,6.61]],"id":64546979}],"con":true,"img":false}]}
{"op":"mcm","clk":"11450498074","pt":1717322725645,"mc":[{"id":"1.229554920","rc":[{"atl":[[390,2.61],[400,0.35],[500,4.41]],"id":69421986},{"atl":[[160,2.61]],"id":64546979}],"con":true,"img":false}]}
{"op":"mcm","clk":"11450498166","pt":1717322726647,"mc":[{"id":"1.229554920","rc":[{"atl":[[8.8,1.51]],"id":65460404}],"con":true,"img":false}]}
{"op":"mcm","clk":"11450498429","pt":1717322728945,"mc":[{"id":"1.229554920","rc":[{"atl":[[390,4.61]],"id":69421986}],"con":true,"img":false}]}
{"op":"mcm","clk":"11450498439","pt":1717322729050,"mc":[{"id":"1.229554920","rc":[{"atl":[[500,2.41]],"id":69421986}],"con":true,"img":false}]}
{"op":"mcm","clk":"11450498449","pt":1717322729154,"mc":[{"id":"1.229554920","rc":[{"atl":[[390,2.61]],"id":69421986}],"con":true,"img":false}]}
{"op":"mcm","clk":"11450498460","pt":1717322729213,"mc":[{"id":"1.229554920","rc":[{"atl":[[390,4.61]],"id":69421986}],"con":true,"img":false}]}
{"op":"mcm","clk":"11450498504","pt":1717322729626,"mc":[{"id":"1.229554920","rc":[{"atb":[[2.64,0]],"id":52671121},{"atb":[[3,32.26]],"id":65460404}],"con":true,"img":false}]}
{"op":"mcm","clk":"11450499297","pt":1717322737857,"mc":[{"id":"1.229554920","rc":[{"atl":[[400,2.35]],"id":69421986}],"con":true,"img":false}]}
{"op":"mcm","clk":"11450499311","pt":1717322738058,"mc":[{"id":"1.229554920","rc":[{"atl":[[500,0.41]],"id":69421986}],"con":true,"img":false}]}
{"op":"mcm","clk":"11450499526","pt":1717322740354,"mc":[{"id":"1.229554920","rc":[{"atb":[[2.38,0],[2.58,0],[2.48,0]],"id":52671121},{"atl":[[11,0],[8.4,0]],"id":52671121},{"atb":[[19.5,0],[24,0],[29,0]],"id":69421986},{"atl":[[400,2],[500,0]],"id":69421986},{"atb":[[2.86,0],[2.96,0],[2.76,0]],"id":65460404},{"atl":[[10.5,0],[15.5,0]],"id":65460404}],"con":true,"img":false}]}
{"op":"mcm","clk":"11450500019","pt":1717322745475,"mc":[{"id":"1.229554920","rc":[{"atl":[[80,2]],"id":69577417},{"atb":[[25,0],[30,0]],"id":69421986},{"atl":[[11,0],[12.5,10.98]],"id":65460404}],"con":true,"img":false}]}
{"op":"mcm","clk":"11450500028","pt":1717322745580,"mc":[{"id":"1.229554920","rc":[{"atl":[[75,2.72],[80,0],[100,4.61]],"id":69577417},{"atb":[[22,6.27],[26,2.61]],"id":69421986}],"con":true,"img":false}]}
{"op":"mcm","clk":"11450500039","pt":1717322745683,"mc":[{"id":"1.229554920","rc":[{"atl":[[220,2.63]],"id":69577417}],"con":true,"img":false}]}
{"op":"mcm","clk":"11450500049","pt":1717322745743,"mc":[{"id":"1.229554920","rc":[{"atl":[[75,4.72],[100,2.61]],"id":69577417}],"con":true,"img":false}]}
{"op":"mcm","clk":"11450500062","pt":1717322745847,"mc":[{"id":"1.229554920","rc":[{"atl":[[220,0.63]],"id":69577417}],"con":true,"img":false}]}
{"op":"mcm","clk":"11450500321","pt":1717322748782,"mc":[{"id":"1.229554920","rc":[{"atb":[[3.55,0]],"id":62262930}],"con":true,"img":false}]}
{"op":"mcm","clk":"11450500358","pt":1717322749256,"mc":[{"id":"1.229554920","rc":[{"atl":[[95,0],[110,2]],"id":69577417},{"atl":[[400,0],[470,2]],"id":69421986},{"atl":[[10,0],[11.5,9.52]],"id":65460404},{"atl":[[8.6,8.14],[7.8,0]],"id":70003371}],"con":true,"img":false}]}
{"op":"mcm","clk":"11450500402","pt":1717322749776,"mc":[{"id":"1.229554920","rc":[{"atb":[[2.38,151.49],[2.58,66.16],[2.48,141.25]],"id":52671121},{"atl":[[11,20.9],[8.4,18.83]],"id":52671121},{"atb":[[19.5,11.3],[24,9.08],[29,3.73]],"id":69421986},{"atl":[[400,0.35],[500,0.41]],"id":69421986},{"atb":[[2.86,112.39],[2.96,53.33],[2.76,118.78]],"id":65460404},{"atl":[[10.5,14.66],[15.5,14.41]],"id":65460404}],"con":true,"img":false}]}
{"op":"mcm","clk":"11450500486","pt":1717322750668,"mc":[{"id":"1.229554920","rc":[{"atb":[[2.62,4.84]],"id":52671121}],"con":true,"img":false}]}
{"op":"mcm","clk":"11450500915","pt":1717322755470,"mc":[{"id":"1.229554920","rc":[{"atb":[[12.5,0]],"id":69577417},{"atl":[[75,2.11]],"id":69577417},{"atb":[[17,0]],"id":64546979}],"con":true,"img":false}]}
{"op":"mcm","clk":"11450500925","pt":1717322755568,"mc":[{"id":"1.229554920","rc":[{"atb":[[14,5.34]],"id":69577417},{"atl":[[75,0.11],[85,2.61],[100,4.61]],"id":69577417},{"atb":[[18.5,4.15]],"id":64546979}],"con":true,"img":false}]}
{"op":"mcm","clk":"11450501276","pt":1717322759598,"mc":[{"id":"1.229554920","rc":[{"atl":[[95,2],[110,0]],"id":69577417},{"atl":[[400,2.35],[470,0]],"id":69421986},{"atl":[[10,10.99],[11.5,0]],"id":65460404},{"atl":[[8.6,0],[7.8,4.07]],"id":70003371}],"con":true,"img":false}]}
{"op":"mcm","clk":"11450501330","pt":1717322760069,"mc":[{"id":"1.229554920","rc":[{"atl":[[7,3]],"id":52671121}],"con":true,"img":false}]}
{"op":"mcm","clk":"11450501382","pt":1717322760705,"mc":[{"id":"1.229554920","rc":[{"atl":[[7.6,0]],"id":52671121},{"atl":[[85,4.61]],"id":69577417}],"con":true,"img":false}]}
{"op":"mcm","clk":"11450501395","pt":1717322760806,"mc":[{"id":"1.229554920","rc":[{"atl":[[100,2.61]],"id":69577417}],"con":true,"img":false}]}
{"op":"mcm","clk":"11450501405","pt":1717322760866,"mc":[{"id":"1.229554920","rc":[{"atl":[[85,2.61]],"id":69577417}],"con":true,"img":false}]}
{"op":"mcm","clk":"11450501416","pt":1717322760970,"mc":[{"id":"1.229554920","rc":[{"atl":[[85,4.61]],"id":69577417}],"con":true,"img":false}]}
{"op":"mcm","clk":"11450501677","pt":1717322763380,"mc":[{"id":"1.229554920","rc":[{"atb":[[2.9,5.48]],"id":65460404}],"con":true,"img":false}]}
{"op":"mcm","clk":"11450501810","pt":1717322764581,"mc":[{"id":"1.229554920","rc":[{"atb":[[2.84,0]],"id":70003371}],"con":true,"img":false}]}
{"op":"mcm","clk":"11450501909","pt":1717322765628,"mc":[{"id":"1.229554920","rc":[{"atl":[[390,2]],"id":69421986}],"con":true,"img":false}]}
{"op":"mcm","clk":"11450501925","pt":1717322765678,"mc":[{"id":"1.229554920","rc":[{"atl":[[380,2.61],[500,2.41]],"id":69421986}],"con":true,"img":false}]}
{"op":"mcm","clk":"11450501937","pt":1717322765782,"mc":[{"id":"1.229554920","rc":[{"atl":[[390,0]],"id":69421986}],"con":true,"img":false}]}
{"op":"mcm","clk":"11450502419","pt":1717322770794,"mc":[{"id":"1.229554920","rc":[{"atl":[[380,4.61]],"id":69421986}],"con":true,"img":false}]}
{"op":"mcm","clk":"11450502427","pt":1717322770899,"mc":[{"id":"1.229554920","rc":[{"atl":[[380,2.61],[400,4.35],[500,0.41]],"id":69421986}],"con":true,"img":false}]}
{"op":"mcm","clk":"11450502435","pt":1717322771003,"mc":[{"id":"1.229554920","rc":[{"atl":[[380,4.61]],"id":69421986}],"con":true,"img":false}]}
{"op":"mcm","clk":"11450502444","pt":1717322771108,"mc":[{"id":"1.229554920","rc":[{"atl":[[400,2.35]],"id":69421986}],"con":true,"img":false}]}
{"op":"mcm","clk":"11450502522","pt":1717322772104,"mc":[{"id":"1.229554920","rc":[{"atl":[[75,0]],"id":69577417}],"con":true,"img":false}]}
{"op":"mcm","clk":"11450502853","pt":1717322775306,"mc":[{"id":"1.229554920","rc":[{"atl":[[7,0]],"id":52671121}],"con":true,"img":false}]}
{"op":"mcm","clk":"11450502874","pt":1717322775508,"mc":[{"id":"1.229554920","rc":[{"atb":[[10.5,0]],"id":69577417},{"atl":[[85,2]],"id":69577417}],"con":true,"img":false}]}
{"op":"mcm","clk":"11450502888","pt":1717322775619,"mc":[{"id":"1.229554920","rc":[{"spn":7.95,"spf":"NaN","id":62262930},{"atb":[[11.5,11.86]],"id":69577417},{"atl":[[80,2.61],[100,4.61]],"id":69577417},{"spn":29.0,"spf":1.0,"id":69421986}],"con":true,"img":false}]}
{"op":"mcm","clk":"11450502896","pt":1717322775713,"mc":[{"id":"1.229554920","rc":[{"atl":[[320,2.65],[85,0],[95,0],[100,6.61]],"id":69577417}],"con":true,"img":false}]}
{"op":"mcm","clk":"11450502904","pt":1717322775820,"mc":[{"id":"1.229554920","rc":[{"atl":[[100,4.61]],"id":69577417}],"con":true,"img":false}]}
{"op":"mcm","clk":"11450502914","pt":1717322775879,"mc":[{"id":"1.229554920","rc":[{"atl":[[320,0.65]],"id":69577417}],"con":true,"img":false}]}
{"op":"mcm","clk":"11450502922","pt":1717322776026,"mc":[{"id":"1.229554920","rc":[{"atl":[[80,4.61]],"id":69577417}],"con":true,"img":false}]}
{"op":"mcm","clk":"11450503477","pt":1717322781905,"mc":[{"id":"1.229554920","rc":[{"atl":[[7,3]],"id":52671121}],"con":true,"img":false}]}
{"op":"mcm","clk":"11450503829","pt":1717322785504,"mc":[{"id":"1.229554920","rc":[{"atl":[[80,2]],"id":69577417},{"atb":[[26,0]],"id":69421986}],"con":true,"img":false}]}
{"op":"mcm","clk":"11450503841","pt":1717322785612,"mc":[{"id":"1.229554920","rc":[{"atl":[[80,0],[85,2.61],[100,6.61]],"id":69577417},{"atb":[[30,2.61]],"id":69421986}],"con":true,"img":false}]}
{"op":"mcm","clk":"11450503856","pt":1717322785717,"mc":[{"id":"1.229554920","rc":[{"atl":[[100,4.61],[220,2.63]],"id":69577417}],"con":true,"img":false}]}
{"op":"mcm","clk":"11450504261","pt":1717322790320,"mc":[{"id":"1.229554920","rc":[{"atl":[[12,1.11]],"id":62262930}],"con":true,"img":false}]}
{"op":"mcm","clk":"11450504304","pt":1717322790734,"mc":[{"id":"1.229554920","rc":[{"atl":[[85,4.61]],"id":69577417}],"con":true,"img":false}]}
{"op":"mcm","clk":"11450504312","pt":1717322790833,"mc":[{"id":"1.229554920","rc":[{"atl":[[100,2.61]],"id":69577417}],"con":true,"img":false}]}
{"op":"mcm","clk":"11450504319","pt":1717322790934,"mc":[{"id":"1.229554920","rc":[{"atl":[[85,2.61]],"id":69577417}],"con":true,"img":false}]}
{"op":"mcm","clk":"11450504329","pt":1717322791042,"mc":[{"id":"1.229554920","rc":[{"atl":[[85,4.61]],"id":69577417}],"con":true,"img":false}]}
{"op":"mcm","clk":"11450504759","pt":1717322795530,"mc":[{"id":"1.229554920","rc":[{"atb":[[2.4,0]],"id":52671121},{"atl":[[10,0],[8.2,16.74]],"id":52671121},{"atb":[[22,0]],"id":69421986},{"atb":[[2.74,0]],"id":65460404},{"atl":[[10,24.59],[12.5,0]],"id":65460404}],"con":true,"img":false}]}
{"op":"mcm","clk":"11450504771","pt":1717322795633,"mc":[{"id":"1.229554920","rc":[{"atb":[[2.6,80.56]],"id":52671121},{"atb":[[25,6.27]],"id":69421986},{"atb":[[2.98,70.1]],"id":65460404}],"con":true,"img":false}]}
{"op":"mcm","clk":"11450504921","pt":1717322797140,"mc":[{"id":"1.229554920","rc":[{"atl":[[7,0]],"id":52671121}],"con":true,"img":false}]}
{"op":"mcm","clk":"11450504944","pt":1717322797446,"mc":[{"id":"1.229554920","rc":[{"atl":[[95,2],[220,0.63]],"id":69577417}],"con":true,"img":false}]}
{"op":"mcm","clk":"11450505048","pt":1717322798551,"mc":[{"id":"1.229554920","rc":[{"atl":[[95,0],[110,2]],"id":69577417},{"atl":[[400,0.35],[430,2]],"id":69421986},{"atb":[[2.72,0],[2.58,63.29]],"id":65460404},{"atl":[[8.2,8.14],[7.8,0]],"id":70003371}],"con":true,"img":false}]}
{"op":"mcm","clk":"11450505532","pt":1717322803746,"mc":[{"id":"1.229554920","rc":[{"atl":[[7,3]],"id":52671121}],"con":true,"img":false}]}
{"op":"mcm","clk":"11450505715","pt":1717322805472,"mc":[{"id":"1.229554920","rc":[{"atl":[[380,2]],"id":69421986}],"con":true,"img":false}]}
{"op":"mcm","clk":"11450505727","pt":1717322805577,"mc":[{"id":"1.229554920","rc":[{"atl":[[380,0],[370,2.61],[500,2.41]],"id":69421986}],"con":true,"img":false}]}
{"op":"mcm","clk":"11450506144","pt":1717322810771,"mc":[{"id":"1.229554920","rc":[{"atl":[[370,4.61],[500,0.41]],"id":69421986}],"con":true,"img":false}]}
{"op":"mcm","clk":"11450506836","pt":1717322818871,"mc":[{"id":"1.229554920","rc":[{"atl":[[7,0]],"id":52671121},{"atl":[[8,1.66]],"id":70003371}],"con":true,"img":false}]}
{"op":"mcm","clk":"11450507461","pt":1717322825483,"mc":[{"id":"1.229554920","rc":[{"atl":[[85,2]],"id":69577417}],"con":true,"img":false}]}
{"op":"mcm","clk":"11450507472","pt":1717322825587,"mc":[{"id":"1.229554920","rc":[{"atl":[[7,3]],"id":52671121},{"atl":[[80,2.61],[85,0],[100,4.61]],"id":69577417}],"con":true,"img":false}]}
{"op":"mcm","clk":"11450507480","pt":1717322825689,"mc":[{"id":"1.229554920","rc":[{"atl":[[320,2.65]],"id":69577417}],"con":true,"img":false}]}
{"op":"mcm","clk":"11450507488","pt":1717322825793,"mc":[{"id":"1.229554920","rc":[{"atl":[[100,2.61]],"id":69577417}],"con":true,"img":false}]}
{"op":"mcm","clk":"11450507613","pt":1717322827357,"mc":[{"id":"1.229554920","rc":[{"atb":[[2.56,0]],"id":52671121}],"con":true,"img":false}]}
{"op":"mcm","clk":"11450507899","pt":1717322830773,"mc":[{"id":"1.229554920","rc":[{"atl":[[80,4.61],[320,0.65]],"id":69577417}],"con":true,"img":false}]}
{"op":"mcm","clk":"11450508932","pt":1717322840784,"mc":[{"id":"1.229554920","rc":[{"atl":[[7,0]],"id":52671121},{"spn":30.0,"spf":1.0,"id":69421986},{"spn":5.7,"spf":"NaN","id":70003371}],"con":true,"img":false}]}
{"op":"mcm","clk":"11450509040","pt":1717322842099,"mc":[{"id":"1.229554920","rc":[{"atb":[[2.56,6.7]],"id":52671121}],"con":true,"img":false}]}
{"op":"mcm","clk":"11450509357","pt":1717322845517,"mc":[{"id":"1.229554920","rc":[{"atl":[[370,2]],"id":69421986},{"atl":[[10,10.99]],"id":65460404}],"con":true,"img":false}]}
{"op":"mcm","clk":"11450509363","pt":1717322845574,"mc":[{"id":"1.229554920","rc":[{"atl":[[360,2.61]],"id":69421986},{"atl":[[9.8,13.6]],"id":65460404}],"con":true,"img":false}]}
{"op":"mcm","clk":"11450509371","pt":1717322845683,"mc":[{"id":"1.229554920","rc":[{"atl":[[370,0],[500,2.41]],"id":69421986}],"con":true,"img":false}]}
{"op":"mcm","clk":"11450509501","pt":1717322847397,"mc":[{"id":"1.229554920","rc":[{"atl":[[7,3]],"id":52671121}],"con":true,"img":false}]}
{"op":"mcm","clk":"11450509824","pt":1717322850850,"mc":[{"id":"1.229554920","rc":[{"atl":[[360,4.61],[500,0.41]],"id":69421986}],"con":true,"img":false}]}
{"op":"mcm","clk":"11450510252","pt":1717322855487,"mc":[{"id":"1.229554920","rc":[{"atl":[[80,2]],"id":69577417}],"con":true,"img":false}]}
{"op":"mcm","clk":"11450510261","pt":1717322855593,"mc":[{"id":"1.229554920","rc":[{"atl":[[75,2.61],[80,0],[100,4.61]],"id":69577417}],"con":true,"img":false}]}
{"op":"mcm","clk":"11450510281","pt":1717322855805,"mc":[{"id":"1.229554920","rc":[{"atl":[[75,4.61],[100,2.61]],"id":69577417}],"con":true,"img":false}]}
{"op":"mcm","clk":"11450510317","pt":1717322856166,"mc":[{"id":"1.229554920","rc":[{"atl":[[8.8,3.7]],"id":65460404}],"con":true,"img":false}]}
{"op":"mcm","clk":"11450510325","pt":1717322856272,"mc":[{"id":"1.229554920","rc":[{"atl":[[7.6,2.53]],"id":52671121}],"con":true,"img":false}]}
{"op":"mcm","clk":"11450510358","pt":1717322856585,"mc":[{"id":"1.229554920","rc":[{"atl":[[12,2.72]],"id":62262930}],"con":true,"img":false}]}
{"op":"mcm","clk":"11450510383","pt":1717322856847,"mc":[{"id":"1.229554920","rc":[{"atl":[[7.6,2.53]],"id":70003371}],"con":true,"img":false}]}
{"op":"mcm","clk":"11450510913","pt":1717322862559,"mc":[{"id":"1.229554920","rc":[{"atl":[[7,0]],"id":52671121}],"con":true,"img":false}]}
{"op":"mcm","clk":"11450511610","pt":1717322869177,"mc":[{"id":"1.229554920","rc":[{"atl":[[7,3]],"id":52671121}],"con":true,"img":false}]}
{"op":"mcm","clk":"11450511979","pt":1717322872460,"mc":[{"id":"1.229554920","rc":[{"atl":[[8.8,2.19]],"id":65460404}],"con":true,"img":false}]}
{"op":"mcm","clk":"11450512313","pt":1717322875474,"mc":[{"id":"1.229554920","rc":[{"atl":[[75,2]],"id":69577417}],"con":true,"img":false}]}
{"op":"mcm","clk":"11450512327","pt":1717322875579,"mc":[{"id":"1.229554920","rc":[{"atl":[[75,0],[85,2.61],[100,4.61]],"id":69577417}],"con":true,"img":false}]}
{"op":"mcm","clk":"11450512342","pt":1717322875683,"mc":[{"id":"1.229554920","rc":[{"atl":[[320,2.65]],"id":69577417}],"con":true,"img":false}]}
{"op":"mcm","clk":"11450512352","pt":1717322875785,"mc":[{"id":"1.229554920","rc":[{"atl":[[320,0.65],[85,4.61],[100,2.61]],"id":69577417}],"con":true,"img":false}]}
{"op":"mcm","clk":"11450512685","pt":1717322878971,"mc":[{"id":"1.229554920","rc":[{"atb":[[2.56,0]],"id":52671121}],"con":true,"img":false}]}
{"op":"mcm","clk":"11450513249","pt":1717322884286,"mc":[{"id":"1.229554920","rc":[{"atl":[[7,0]],"id":52671121}],"con":true,"img":false}]}
{"op":"mcm","clk":"11450513384","pt":1717322885483,"mc":[{"id":"1.229554920","rc":[{"atl":[[360,2]],"id":69421986}],"con":true,"img":false}]}
{"op":"mcm","clk":"11450513395","pt":1717322885584,"mc":[{"id":"1.229554920","rc":[{"atl":[[350,2.61],[360,0],[500,2.41]],"id":69421986}],"con":true,"img":false}]}
{"op":"mcm","clk":"11450513936","pt":1717322890706,"mc":[{"id":"1.229554920","rc":[{"atl":[[350,4.61],[500,0.41]],"id":69421986}],"con":true,"img":false}]}
{"op":"mcm","clk":"11450513951","pt":1717322890818,"mc":[{"id":"1.229554920","rc":[{"atl":[[400,2.35]],"id":69421986}],"con":true,"img":false}]}
{"op":"mcm","clk":"11450513964","pt":1717322890913,"mc":[{"id":"1.229554920","rc":[{"atl":[[350,2.61]],"id":69421986}],"con":true,"img":false}]}
{"op":"mcm","clk":"11450513978","pt":1717322891015,"mc":[{"id":"1.229554920","rc":[{"atl":[[350,4.61]],"id":69421986}],"con":true,"img":false}]}
{"op":"mcm","clk":"11450513990","pt":1717322891117,"mc":[{"id":"1.229554920","rc":[{"atl":[[400,0.35]],"id":69421986}],"con":true,"img":false}]}
{"op":"mcm","clk":"11450514002","pt":1717322891221,"mc":[{"id":"1.229554920","rc":[{"atl":[[7,3]],"id":52671121}],"con":true,"img":false}]}
{"op":"mcm","clk":"11450514297","pt":1717322894121,"mc":[{"id":"1.229554920","rc":[{"atb":[[2.62,0]],"id":52671121},{"atl":[[7.2,0]],"id":52671121},{"atb":[[3,28.34]],"id":65460404}],"con":true,"img":false}]}
{"op":"mcm","clk":"11450514431","pt":1717322895326,"mc":[{"id":"1.229554920","rc":[{"atb":[[2.56,6.7]],"id":52671121}],"con":true,"img":false}]}
{"op":"mcm","clk":"11450514454","pt":1717322895535,"mc":[{"id":"1.229554920","rc":[{"atl":[[85,2]],"id":69577417}],"con":true,"img":false}]}
{"op":"mcm","clk":"11450514467","pt":1717322895640,"mc":[{"id":"1.229554920","rc":[{"atl":[[80,2.61],[85,0],[100,4.61]],"id":69577417}],"con":true,"img":false}]}
{"op":"mcm","clk":"11450514477","pt":1717322895694,"mc":[{"id":"1.229554920","rc":[{"atl":[[80,4.61]],"id":69577417}],"con":true,"img":false}]}
{"op":"mcm","clk":"11450514489","pt":1717322895809,"mc":[{"id":"1.229554920","rc":[{"atl":[[100,2.61]],"id":69577417}],"con":true,"img":false}]}
{"op":"mcm","clk":"11450514968","pt":1717322900416,"mc":[{"id":"1.229554920","rc":[{"atl":[[55,2]],"id":52671121},{"atb":[[1.17,106]],"id":62262930},{"atl":[[12,7.4]],"id":62262930},{"atl":[[95,2]],"id":69577417},{"atl":[[400,2.35]],"id":69421986},{"atb":[[5.7,0]],"id":64546979},{"atb":[[1.98,102.04]],"id":70003371},{"atl":[[7.8,5.08]],"id":70003371}],"con":true,"img":false}]}
{"op":"mcm","clk":"11450514982","pt":1717322900522,"mc":[{"id":"1.229554920","rc":[{"atl":[[21,0]],"id":52671121},{"atb":[[2.6,0]],"id":62262930},{"atl":[[65,0]],"id":62262930},{"atl":[[110,0]],"id":69577417},{"atl":[[430,0]],"id":69421986},{"atl":[[19.5,5.41],[10,0]],"id":65460404},{"atb":[[4.8,24.39]],"id":64546979},{"atb":[[1.08,0]],"id":70003371},{"atl":[[8.2,0]],"id":70003371}],"con":true,"img":false}]}
{"op":"mcm","clk":"11450515530","pt":1717322905633,"mc":[{"id":"1.229554920","rc":[{"spn":4.88,"spf":"NaN","id":52671121},{"atl":[[9.8,0]],"id":65460404},{"spn":5.5,"spf":"NaN","id":70003371}],"con":true,"img":false}]}
{"op":"mcm","clk":"11450515542","pt":1717322905737,"mc":[{"id":"1.229554920","rc":[{"atl":[[10,13.6]],"id":65460404}],"con":true,"img":false}]}
{"op":"mcm","clk":"11450515609","pt":1717322906318,"mc":[{"id":"1.229554920","rc":[{"atl":[[7,0]],"id":52671121}],"con":true,"img":false}]}
{"op":"mcm","clk":"11450516326","pt":1717322912537,"mc":[{"id":"1.229554920","rc":[{"atl":[[7.4,3]],"id":52671121}],"con":true,"img":false}]}
{"op":"mcm","clk":"11450516579","pt":1717322914731,"mc":[{"id":"1.229554920","rc":[{"atb":[[2.64,4.78]],"id":52671121}],"con":true,"img":false}]}
{"op":"mcm","clk":"11450516591","pt":1717322914833,"mc":[{"id":"1.229554920","rc":[{"atl":[[12,6.29]],"id":62262930}],"con":true,"img":false}]}
{"op":"mcm","clk":"11450517734","pt":1717322925546,"mc":[{"id":"1.229554920","rc":[{"atl":[[80,2]],"id":69577417},{"atl":[[350,2]],"id":69421986}],"con":true,"img":false}]}
{"op":"mcm","clk":"11450517747","pt":1717322925695,"mc":[{"id":"1.229554920","rc":[{"atl":[[75,2.61],[80,0],[100,4.61]],"id":69577417},{"atl":[[340,2.78],[350,0],[500,2.41]],"id":69421986}],"con":true,"img":false}]}
{"op":"mcm","clk":"11450517763","pt":1717322925757,"mc":[{"id":"1.229554920","rc":[{"atl":[[320,2.65],[95,0]],"id":69577417},{"atl":[[990,2],[500,0.41]],"id":69421986}],"con":true,"img":false}]}
{"op":"mcm","clk":"11450517777","pt":1717322925866,"mc":[{"id":"1.229554920","rc":[{"atl":[[75,4.61],[320,0.65],[95,2],[100,2.61]],"id":69577417},{"atl":[[340,4.78],[990,0]],"id":69421986}],"con":true,"img":false}]}
{"op":"mcm","clk":"11450517788","pt":1717322926016,"mc":[{"id":"1.229554920","rc":[{"atl":[[100,4.61]],"id":69577417},{"atl":[[500,4.41]],"id":69421986}],"con":true,"img":false}]}
{"op":"mcm","clk":"11450517802","pt":1717322926066,"mc":[{"id":"1.229554920","rc":[{"atl":[[75,2.61]],"id":69577417},{"atl":[[340,2.78],[400,0.35]],"id":69421986}],"con":true,"img":false}]}
{"op":"mcm","clk":"11450517811","pt":1717322926174,"mc":[{"id":"1.229554920","rc":[{"atl":[[100,2.61]],"id":69577417},{"atl":[[500,2.41]],"id":69421986}],"con":true,"img":false}]}
{"op":"mcm","clk":"11450517823","pt":1717322926278,"mc":[{"id":"1.229554920","rc":[{"atl":[[100,4.61]],"id":69577417},{"atl":[[990,2]],"id":69421986}],"con":true,"img":false}]}
{"op":"mcm","clk":"11450517912","pt":1717322927077,"mc":[{"id":"1.229554920","rc":[{"atb":[[2.56,0]],"id":52671121}],"con":true,"img":false}]}
{"op":"mcm","clk":"11450517990","pt":1717322927759,"mc":[{"id":"1.229554920","rc":[{"atl":[[7.4,0]],"id":52671121}],"con":true,"img":false}]}
{"op":"mcm","clk":"11450518041","pt":1717322928278,"mc":[{"id":"1.229554920","rc":[{"atb":[[2.38,0],[2.58,0],[2.48,0]],"id":52671121},{"atl":[[11,0],[8.4,0]],"id":52671121},{"atb":[[3.4,0],[3.9,0],[3.65,0]],"id":62262930},{"atl":[[19,0],[28,0]],"id":62262930},{"atb":[[11,0],[13.5,0],[9.4,0]],"id":69577417},{"atl":[[320,0],[220,0]],"id":69577417},{"atb":[[19.5,0],[24,0],[29,0]],"id":69421986},{"atl":[[400,0],[500,2]],"id":69421986},{"atb":[[2.86,0],[2.96,0],[2.76,0]],"id":65460404},{"atl":[[10.5,0],[15.5,0]],"id":65460404},{"atb":[[18,0],[13,0],[15.5,0]],"id":64546979},{"atl":[[260,0],[360,0]],"id":64546979},{"atb":[[2.88,0],[2.98,0],[2.78,0]],"id":70003371},{"atl":[[10.5,0],[15.5,0]],"id":70003371}],"con":true,"img":false}]}
{"op":"mcm","clk":"11450518150","pt":1717322929459,"mc":[{"id":"1.229554920","rc":[{"atb":[[3.55,4.05]],"id":62262930}],"con":true,"img":false}]}
{"op":"mcm","clk":"11450518236","pt":1717322930484,"mc":[{"id":"1.229554920","rc":[{"atb":[[2.84,5.69]],"id":70003371}],"con":true,"img":false}]}
{"op":"mcm","clk":"11450518305","pt":1717322931172,"mc":[{"id":"1.229554920","rc":[{"atl":[[75,4.61],[100,2.61]],"id":69577417}],"con":true,"img":false}]}
{"op":"mcm","clk":"11450518325","pt":1717322931386,"mc":[{"id":"1.229554920","rc":[{"atl":[[340,4.78],[990,0]],"id":69421986}],"con":true,"img":false}]}
{"op":"mcm","clk":"11450518334","pt":1717322931485,"mc":[{"id":"1.229554920","rc":[{"atl":[[340,2.78],[500,0],[1000,3.17]],"id":69421986}],"con":true,"img":false}]}
{"op":"mcm","clk":"11450518348","pt":1717322931597,"mc":[{"id":"1.229554920","rc":[{"atl":[[340,4.78],[800,2],[1000,1.17]],"id":69421986}],"con":true,"img":false}]}
{"op":"mcm","clk":"11450518368","pt":1717322931761,"mc":[{"id":"1.229554920","rc":[{"atl":[[340,2.78],[1000,3.17]],"id":69421986}],"con":true,"img":false}]}
{"op":"mcm","clk":"11450518595","pt":1717322933964,"mc":[{"id":"1.229554920","rc":[{"atl":[[7.4,3]],"id":52671121}],"con":true,"img":false}]}
{"op":"mcm","clk":"11450518742","pt":1717322935472,"mc":[{"id":"1.229554920","rc":[{"atl":[[10,13.6]],"id":52671121},{"atl":[[12.5,10.98]],"id":65460404},{"atl":[[12,10.51]],"id":70003371}],"con":true,"img":false}]}
{"op":"mcm","clk":"11450518751","pt":1717322935575,"mc":[{"id":"1.229554920","rc":[{"atb":[[2.6,0]],"id":52671121},{"atl":[[8.2,0]],"id":52671121},{"atb":[[3.95,0],[3.7,0]],"id":62262930},{"atb":[[14,0]],"id":69577417},{"atl":[[100,0]],"id":69577417},{"atb":[[25,0],[30,0]],"id":69421986},{"atl":[[340,0.16]],"id":69421986},{"atb":[[2.98,0]],"id":65460404},{"atl":[[10,0]],"id":65460404},{"atb":[[18.5,0]],"id":64546979},{"atb":[[2.9,0],[3,0]],"id":70003371},{"atl":[[10,0]],"id":70003371}],"con":true,"img":false}]}
{"op":"mcm","clk":"11450518761","pt":1717322935674,"mc":[{"id":"1.229554920","rc":[{"atb":[[2.38,80.56]],"id":52671121},{"atb":[[3.7,21.17],[3.3,43.49]],"id":62262930},{"atb":[[13,5.34]],"id":69577417},{"atl":[[90,2.61]],"id":69577417},{"atb":[[22,6.27],[26,2.61]],"id":69421986},{"atl":[[450,2.61]],"id":69421986},{"atb":[[2.7,70.1]],"id":65460404},{"atb":[[15.5,4.15]],"id":64546979},{"atb":[[2.92,28.34],[2.64,64.95]],"id":70003371}],"con":true,"img":false}]}
{"op":"mcm","clk":"11450518786","pt":1717322935888,"mc":[{"id":"1.229554920","rc":[{"atb":[[1.72,2.11]],"id":62262930}],"con":true,"img":false}]}
{"op":"mcm","clk":"11450518804","pt":1717322936091,"mc":[{"id":"1.229554920","rc":[{"atl":[[8,0]],"id":70003371}],"con":true,"img":false}]}
{"op":"mcm","clk":"11450518819","pt":1717322936255,"mc":[{"id":"1.229554920","rc":[{"atl":[[450,4.61]],"id":69421986}],"con":true,"img":false}]}
{"op":"mcm","clk":"11450518828","pt":1717322936357,"mc":[{"id":"1.229554920","rc":[{"atl":[[800,0]],"id":69421986}],"con":true,"img":false}]}
{"op":"mcm","clk":"11450518839","pt":1717322936468,"mc":[{"id":"1.229554920","rc":[{"atl":[[12,1.61],[13.5,8]],"id":62262930},{"atl":[[95,0],[110,2]],"id":69577417},{"atl":[[140,2],[120,4.61]],"id":64546979},{"atl":[[8.6,7.62],[7.8,0]],"id":70003371}],"con":true,"img":false}]}
{"op":"mcm","clk":"11450518889","pt":1717322936880,"mc":[{"id":"1.229554920","rc":[{"atl":[[450,6.61],[1000,1.17]],"id":69421986}],"con":true,"img":false}]}
{"op":"mcm","clk":"11450518901","pt":1717322936983,"mc":[{"id":"1.229554920","rc":[{"atl":[[990,2]],"id":69421986}],"con":true,"img":false}]}
{"op":"mcm","clk":"11450518914","pt":1717322937087,"mc":[{"id":"1.229554920","rc":[{"atl":[[450,4.61]],"id":69421986}],"con":true,"img":false}]}
{"op":"mcm","clk":"11450519370","pt":1717322941392,"mc":[{"id":"1.229554920","rc":[{"atl":[[870,2],[450,2.61]],"id":69421986}],"con":true,"img":false}]}
{"op":"mcm","clk":"11450519381","pt":1717322941490,"mc":[{"id":"1.229554920","rc":[{"atl":[[860,2],[990,0]],"id":69421986}],"con":true,"img":false}]}
{"op":"mcm","clk":"11450519396","pt":1717322941597,"mc":[{"id":"1.229554920","rc":[{"atl":[[990,2]],"id":69421986}],"con":true,"img":false}]}
{"op":"mcm","clk":"11450519410","pt":1717322941695,"mc":[{"id":"1.229554920","rc":[{"atl":[[860,0],[990,0]],"id":69421986}],"con":true,"img":false}]}
{"op":"mcm","clk":"11450519422","pt":1717322941757,"mc":[{"id":"1.229554920","rc":[{"atl":[[450,4.61]],"id":69421986}],"con":true,"img":false}]}
{"op":"mcm","clk":"11450519507","pt":1717322942496,"mc":[{"id":"1.229554920","rc":[{"atb":[[2.38,232.06],[2.58,66.16],[2.48,141.25]],"id":52671121},{"atl":[[11,20.9],[8.4,18.83]],"id":52671121},{"atb":[[3.4,87.1],[3.9,36.04],[3.65,78.88]],"id":62262930},{"atl":[[19,7.74],[28,7.74]],"id":62262930},{"atb":[[11,20.9],[13.5,8.36],[9.4,24.88]],"id":69577417},{"atl":[[320,0.65],[220,0.63]],"id":69577417},{"atb":[[19.5,11.3],[24,9.08],[29,3.73]],"id":69421986},{"atl":[[400,0.35],[500,0.41]],"id":69421986},{"atb":[[2.86,112.39],[2.96,53.33],[2.76,118.78]],"id":65460404},{"atl":[[10.5,14.66],[15.5,14.41]],"id":65460404},{"atb":[[18,6.14],[13,17.42],[15.5,18.57]],"id":64546979},{"atl":[[260,0.53],[360,0.58]],"id":64546979},{"atb":[[2.88,111.2],[2.98,52.79],[2.78,117.44]],"id":70003371},{"atl":[[10.5,14.66],[15.5,14.41]],"id":70003371}],"con":true,"img":false}]}
{"op":"mcm","clk":"11450519629","pt":1717322943593,"mc":[{"id":"1.229554920","rc":[{"atb":[[2.56,6.7]],"id":52671121}],"con":true,"img":false}]}
{"op":"mcm","clk":"11450519815","pt":1717322945280,"mc":[{"id":"1.229554920","rc":[{"atb":[[1.04,1.7]],"id":62262930},{"atb":[[1.03,7.49]],"id":65460404}],"con":true,"img":false}]}
{"op":"mcm","clk":"11450519837","pt":1717322945495,"mc":[{"id":"1.229554920","rc":[{"atl":[[75,2],[90,0]],"id":69577417},{"atb":[[1.27,1.7]],"id":69421986}],"con":true,"img":false}]}
{"op":"mcm","clk":"11450519848","pt":1717322945597,"mc":[{"id":"1.229554920","rc":[{"atb":[[1.03,1.7]],"id":52671121},{"atl":[[85,2.61],[100,2.61]],"id":69577417}],"con":true,"img":false}]}
{"op":"mcm","clk":"11450519863","pt":1717322945697,"mc":[{"id":"1.229554920","rc":[{"atl":[[75,0],[110,0],[220,2.63],[990,2.17]],"id":69577417},{"atb":[[1.03,1.7]],"id":70003371}],"con":true,"img":false}]}
{"op":"mcm","clk":"11450519886","pt":1717322945914,"mc":[{"id":"1.229554920","rc":[{"atb":[[1.14,1.7]],"id":69577417}],"con":true,"img":false}]}
{"op":"mcm","clk":"11450519909","pt":1717322946077,"mc":[{"id":"1.229554920","rc":[{"atl":[[1000,2.7]],"id":69577417}],"con":true,"img":false}]}
{"op":"mcm","clk":"11450519923","pt":1717322946174,"mc":[{"id":"1.229554920","rc":[{"atb":[[1.16,1.7]],"id":64546979}],"con":true,"img":false}]}
{"op":"mcm","clk":"11450519945","pt":1717322946382,"mc":[{"id":"1.229554920","rc":[{"atb":[[1.04,0.18]],"id":62262930}],"con":true,"img":false}]}
{"op":"mcm","clk":"11450519958","pt":1717322946485,"mc":[{"id":"1.229554920","rc":[{"atl":[[870,0],[440,2]],"id":69421986},{"atl":[[1000,2.87]],"id":65460404}],"con":true,"img":false}]}
{"op":"mcm","clk":"11450519986","pt":1717322946692,"mc":[{"id":"1.229554920","rc":[{"atl":[[12,6.29],[13.5,0],[1000,2.7]],"id":62262930},{"atb":[[1.27,0.02]],"id":69421986},{"atl":[[140,0],[120,6.61]],"id":64546979},{"atl":[[8.6,0],[7.8,6.84]],"id":70003371}],"con":true,"img":false}]}
{"op":"mcm","clk":"11450519998","pt":1717322946802,"mc":[{"id":"1.229554920","rc":[{"atl":[[160,4.61],[120,4.61]],"id":64546979}],"con":true,"img":false}]}
{"op":"mcm","clk":"11450520017","pt":1717322947001,"mc":[{"id":"1.229554920","rc":[{"atb":[[1.03,0.24]],"id":70003371},{"atl":[[1000,2.7]],"id":70003371}],"con":true,"img":false}]}
{"op":"mcm","clk":"11450520042","pt":1717322947264,"mc":[{"id":"1.229554920","rc":[{"atl":[[1000,2.7]],"id":52671121},{"atb":[[1.03,6.05]],"id":65460404}],"con":true,"img":false}]}
{"op":"mcm","clk":"11450520076","pt":1717322947684,"mc":[{"id":"1.229554920","rc":[{"atb":[[1.03,0.3]],"id":52671121},{"atl":[[1000,1]],"id":69577417}],"con":true,"img":false}]}
{"op":"mcm","clk":"11450520092","pt":1717322947894,"mc":[{"id":"1.229554920","rc":[{"atb":[[1.14,0.05]],"id":69577417},{"atb":[[1.16,0.04]],"id":64546979}],"con":true,"img":false}]}
{"op":"mcm","clk":"11450520124","pt":1717322948267,"mc":[{"id":"1.229554920","rc":[{"atb":[[1.04,0]],"id":62262930}],"con":true,"img":false}]}
{"op":"mcm","clk":"11450520138","pt":1717322948373,"mc":[{"id":"1.229554920","rc":[{"atb":[[4.5,0.18]],"id":62262930}],"con":true,"img":false}]}
{"op":"mcm","clk":"11450520199","pt":1717322948896,"mc":[{"id":"1.229554920","rc":[{"atb":[[1.27,0]],"id":69421986}],"con":true,"img":false}]}
{"op":"mcm","clk":"11450520211","pt":1717322948999,"mc":[{"id":"1.229554920","rc":[{"atb":[[30,0.02]],"id":69421986}],"con":true,"img":false}]}
{"op":"mcm","clk":"11450520225","pt":1717322949165,"mc":[{"id":"1.229554920","rc":[{"atl":[[7.4,0]],"id":52671121}],"con":true,"img":false}]}
{"op":"mcm","clk":"11450520253","pt":1717322949474,"mc":[{"id":"1.229554920","rc":[{"atb":[[1.03,0]],"id":70003371}],"con":true,"img":false}]}
{"op":"mcm","clk":"11450520264","pt":1717322949585,"mc":[{"id":"1.229554920","rc":[{"atb":[[3.45,0.24]],"id":70003371}],"con":true,"img":false}]}
{"op":"mcm","clk":"11450520332","pt":1717322950200,"mc":[{"id":"1.229554920","rc":[{"atl":[[1000,1.11]],"id":52671121},{"atb":[[1.03,5.78]],"id":65460404}],"con":true,"img":false}]}
{"op":"mcm","clk":"11450520341","pt":1717322950298,"mc":[{"id":"1.229554920","rc":[{"atb":[[3.25,0.26]],"id":65460404}],"con":true,"img":false}]}
{"op":"mcm","clk":"11450520389","pt":1717322950668,"mc":[{"id":"1.229554920","rc":[{"atb":[[1.03,0]],"id":52671121}],"con":true,"img":false}]}
{"op":"mcm","clk":"11450520399","pt":1717322950777,"mc":[{"id":"1.229554920","rc":[{"atb":[[2.78,0.3]],"id":52671121},{"atl":[[85,4.61],[990,0.17]],"id":69577417}],"con":true,"img":false}]}
{"op":"mcm","clk":"11450520411","pt":1717322950879,"mc":[{"id":"1.229554920","rc":[{"atl":[[85,2.61],[100,4.61]],"id":69577417}],"con":true,"img":false}]}
{"op":"mcm","clk":"11450520420","pt":1717322950980,"mc":[{"id":"1.229554920","rc":[{"atl":[[85,4.61],[100,2.61]],"id":69577417}],"con":true,"img":false}]}
