{"op":"mcm","clk":"11449075392","pt":1717303241532,"mc":[{"id":"1.229554913","marketDefinition":{"bspMarket":false,"turnInPlayEnabled":false,"persistenceEnabled":false,"marketBaseRate":7.0,"eventId":"33318908","eventTypeId":"4339","numberOfWinners":1,"bettingType":"ODDS","marketType":"QUINELLA","marketTime":"2024-06-02T09:38:00.000Z","suspendTime":"2024-06-02T09:38:00.000Z","bspReconciled":false,"complete":true,"inPlay":false,"crossMatching":true,"runnersVoidable":false,"numberOfActiveRunners":15,"betDelay":0,"status":"OPEN","runners":[{"status":"ACTIVE","sortPriority":1,"id":52671542,"name":"1 - 2 / 2 - 1"},{"status":"ACTIVE","sortPriority":2,"id":52671543,"name":"1 - 3 / 3 - 1"},{"status":"ACTIVE","sortPriority":3,"id":52237612,"name":"1 - 5 / 5 - 1"},{"status":"ACTIVE","sortPriority":4,"id":52671545,"name":"1 - 6 / 6 - 1"},{"status":"ACTIVE","sortPriority":5,"id":52671560,"name":"1 - 7 / 7 - 1"},{"status":"ACTIVE","sortPriority":6,"id":52671547,"name":"2 - 3 / 3 - 2"},{"status":"ACTIVE","sortPriority":7,"id":52237617,"name":"2 - 5 / 5 - 2"},{"status":"ACTIVE","sortPriority":8,"id":52671549,"name":"2 - 6 / 6 - 2"},{"status":"ACTIVE","sortPriority":9,"id":52671561,"name":"2 - 7 / 7 - 2"},{"status":"ACTIVE","sortPriority":10,"id":52237621,"name":"3 - 5 / 5 - 3"},{"status":"ACTIVE","sortPriority":11,"id":52671552,"name":"3 - 6 / 6 - 3"},{"status":"ACTIVE","sortPriority":12,"id":52671562,"name":"3 - 7 / 7 - 3"},{"status":"ACTIVE","sortPriority":13,"id":52237634,"name":"5 - 6 / 6 - 5"},{"status":"ACTIVE","sortPriority":14,"id":52237627,"name":"5 - 7 / 7 - 5"},{"status":"ACTIVE","sortPriority":15,"id":52671564,"name":"6 - 7 / 7 - 6"}],"regulators":["MR_INT"],"venue":"Murray Bridge","countryCode":"AU","discountAllowed":true,"timezone":"Australia/Adelaide","openDate":"2024-06-02T08:21:00.000Z","version":5962801935,"name":"Quinella","eventName":"Murray Bridge (AUS) 2nd Jun"},"rc":[],"con":true,"img":false}]}
{"op":"mcm","clk":"11449095047","pt":1717303714043,"mc":[{"id":"1.229554913","rc":[{"atb":[[3.8,9.34],[3.55,20.52],[3.3,34.12],[3.05,51.04]],"id":52237612},{"atb":[[150,0.18],[75,1.06],[100,0.53],[50,2.13]],"id":52671552},{"atb":[[130,0.61],[180,0.29],[90,1.18],[230,0.12]],"id":52671547},{"atb":[[4.5,29.89],[5,19.62],[5.5,11.63],[6,5.23]],"id":52671542},{"atb":[[16.5,5.06],[19,2.91],[23,1.19],[14,8.05]],"id":52671561}],"con":true,"img":false}]}
{"op":"mcm","clk":"11449095056","pt":1717303714149,"mc":[{"id":"1.229554913","rc":[{"atb":[[12,4.76],[9.8,8.92],[8.8,13.41],[14.5,1.94]],"id":52237627},{"atb":[[130,0.61],[180,0.29],[90,1.18],[230,0.12]],"id":52671562},{"atb":[[16,1.74],[11,7.85],[13.5,4.19],[9.4,12.46]],"id":52671564},{"atb":[[140,0.19],[70,1.14],[95,0.55],[48,2.23]],"id":52237621},{"atb":[[4.5,29.89],[5,19.62],[5.5,11.63],[6,5.23]],"id":52671560},{"atb":[[7.2,16.88],[9.2,6.38],[10.5,2.75],[8.2,10.9]],"id":52237617},{"atb":[[12,4.76],[9.8,8.92],[8.8,13.41],[14.5,1.94]],"id":52671549},{"atb":[[32,2.53],[42,1.28],[26,4.19],[55,0.49]],"id":52671543},{"atb":[[3.45,32.03],[3.2,47.56],[3.95,8.87],[3.7,19.38]],"id":52671545},{"atb":[[6.4,19.38],[7.4,12.26],[8.4,7.07],[9.4,3.11]],"id":52237634}],"con":true,"img":false}]}
{"op":"mcm","clk":"11449099382","pt":1717303849562,"mc":[{"id":"1.229554913","rc":[{"atb":[[5.8,50.81],[7.6,15.83]],"id":52237627},{"atb":[[180,0.88],[90,3.92]],"id":52671562},{"atb":[[7.8,15.37],[5.9,49.77]],"id":52671564},{"atb":[[46,2.32],[28,9.03]],"id":52237621},{"atb":[[9.8,11.87],[7.8,35.86]],"id":52671561},{"atb":[[3.6,40.2],[3.1,116.14]],"id":52671560},{"atb":[[2.82,57.43],[2.62,150.55]],"id":52237612},{"atb":[[46,2.32],[28,9.03]],"id":52671552},{"atb":[[180,0.88],[90,3.92]],"id":52671547},{"atb":[[5.8,50.81],[7.6,15.83]],"id":52237617},{"atb":[[7.8,15.37],[5.9,49.77]],"id":52671549},{"atb":[[18,6.14],[13,20.32]],"id":52671543},{"atb":[[3.6,40.2],[3.1,116.14]],"id":52671542},{"atb":[[2.64,148.72],[2.84,56.81]],"id":52671545},{"atb":[[4.4,71.73],[5.4,23.75]],"id":52237634}],"con":true,"img":false}]}
{"op":"mcm","clk":"11449105759","pt":1717304051610,"mc":[{"id":"1.229554913","rc":[{"atb":[[12,0],[9.8,0],[8.8,0],[14.5,0]],"id":52671549},{"atb":[[6.4,0],[7.4,0],[8.4,0],[9.4,0]],"id":52237634}],"con":true,"img":false}]}
{"op":"mcm","clk":"11449105789","pt":1717304052278,"mc":[{"id":"1.229554913","rc":[{"atb":[[12,4.76],[9.8,8.92],[8.8,13.41],[14.5,1.94]],"id":52671549},{"atb":[[6.4,19.38],[7.4,12.26],[8.4,7.07],[9.4,3.11]],"id":52237634}],"con":true,"img":false}]}
{"op":"mcm","clk":"11449115276","pt":1717304291307,"mc":[{"id":"1.229554913","rc":[{"atb":[[16,0],[11,0],[13.5,0],[9.4,0]],"id":52671564},{"atb":[[3.8,0],[3.55,0],[3.3,0],[3.05,0]],"id":52237612},{"atb":[[3.45,0],[3.2,0],[3.95,0],[3.7,0]],"id":52671545}],"con":true,"img":false}]}
{"op":"mcm","clk":"11449115324","pt":1717304292179,"mc":[{"id":"1.229554913","rc":[{"atb":[[16.5,1.69],[9.6,12.17],[11.5,7.48],[14,4.02]],"id":52671564},{"atb":[[3.4,32.7],[3.15,48.67],[3.9,9.02],[3.65,19.74]],"id":52237612},{"atb":[[4.1,8.44],[3.8,18.68],[3.55,30.77],[3.3,45.5]],"id":52671545}],"con":true,"img":false}]}
{"op":"mcm","clk":"11449124733","pt":1717304346070,"mc":[{"id":"1.229554913","rc":[{"atb":[[16.5,0],[9.6,0],[11.5,0],[14,0]],"id":52671564}],"con":true,"img":false}]}
{"op":"mcm","clk":"11449124766","pt":1717304346738,"mc":[{"id":"1.229554913","rc":[{"atb":[[16,1.74],[11,7.85],[13.5,4.19],[9.4,12.46]],"id":52671564}],"con":true,"img":false}]}
{"op":"mcm","clk":"11449204163","pt":1717305549629,"mc":[{"id":"1.229554913","rc":[{"atb":[[12,0],[9.8,0],[8.8,0],[14.5,0]],"id":52671549},{"atb":[[6.4,0],[7.4,0],[8.4,0],[9.4,0]],"id":52237634}],"con":true,"img":false}]}
{"op":"mcm","clk":"11449204221","pt":1717305550303,"mc":[{"id":"1.229554913","rc":[{"atb":[[12,4.76],[9.8,8.92],[8.8,13.41],[14.5,1.94]],"id":52671549},{"atb":[[6.4,19.38],[7.4,12.26],[8.4,7.07],[9.4,3.11]],"id":52237634}],"con":true,"img":false}]}
{"op":"mcm","clk":"11449308294","pt":1717306959766,"mc":[{"id":"1.229554913","rc":[{"atb":[[12,0],[9.8,0],[8.8,0],[14.5,0]],"id":52671549},{"atb":[[6.4,0],[7.4,0],[8.4,0],[9.4,0]],"id":52237634}],"con":true,"img":false}]}
{"op":"mcm","clk":"11449308338","pt":1717306960487,"mc":[{"id":"1.229554913","rc":[{"atb":[[12,4.76],[9.8,8.92],[8.8,13.41],[14.5,1.94]],"id":52671549},{"atb":[[6.4,19.38],[7.4,12.26],[8.4,7.07],[9.4,3.11]],"id":52237634}],"con":true,"img":false}]}
{"op":"mcm","clk":"11449376907","pt":1717308250434,"mc":[{"id":"1.229554913","rc":[{"atb":[[12,0],[9.8,0],[8.8,0],[14.5,0]],"id":52671549},{"atb":[[6.4,0],[7.4,0],[8.4,0],[9.4,0]],"id":52237634}],"con":true,"img":false}]}
{"op":"mcm","clk":"11449376934","pt":1717308251157,"mc":[{"id":"1.229554913","rc":[{"atb":[[12,4.76],[9.8,8.92],[8.8,13.41],[14.5,1.94]],"id":52671549},{"atb":[[6.4,19.38],[7.4,12.26],[8.4,7.07],[9.4,3.11]],"id":52237634}],"con":true,"img":false}]}
{"op":"mcm","clk":"11449473391","pt":1717309665273,"mc":[{"id":"1.229554913","rc":[{"atb":[[12,0],[9.8,0],[8.8,0],[14.5,0]],"id":52671549},{"atb":[[6.4,0],[7.4,0],[8.4,0],[9.4,0]],"id":52237634}],"con":true,"img":false}]}
{"op":"mcm","clk":"11449473435","pt":1717309665990,"mc":[{"id":"1.229554913","rc":[{"atb":[[12,4.76],[9.8,8.92],[8.8,13.41],[14.5,1.94]],"id":52671549},{"atb":[[6.4,19.38],[7.4,12.26],[8.4,7.07],[9.4,3.11]],"id":52237634}],"con":true,"img":false}]}
{"op":"mcm","clk":"11449523474","pt":1717310343599,"mc":[{"id":"1.229554913","rc":[{"atb":[[140,0],[70,0],[95,0],[48,0]],"id":52237621},{"atb":[[4.5,0],[5,0],[5.5,0],[6,0]],"id":52671542}],"con":true,"img":false}]}
{"op":"mcm","clk":"11449523516","pt":1717310344323,"mc":[{"id":"1.229554913","rc":[{"atb":[[150,0.18],[75,1.06],[100,0.53],[50,2.13]],"id":52237621},{"atb":[[4.8,20.65],[4.3,31.71],[5.8,5.45],[5.3,12.17]],"id":52671542}],"con":true,"img":false}]}
{"op":"mcm","clk":"11449524704","pt":1717310363066,"mc":[{"id":"1.229554913","rc":[{"atb":[[5.8,0],[7.6,0]],"id":52237627},{"atb":[[180,0.29],[90,1.18]],"id":52671562},{"atb":[[7.8,0],[5.9,0]],"id":52671564},{"atb":[[46,0],[28,0]],"id":52237621},{"atb":[[9.8,0],[7.8,0]],"id":52671561},{"atb":[[3.6,0],[3.1,0]],"id":52671560},{"atb":[[2.82,0],[2.62,0]],"id":52237612},{"atb":[[46,0],[28,0]],"id":52671552},{"atb":[[180,0.29],[90,1.18]],"id":52671547},{"atb":[[5.8,0],[7.6,0]],"id":52237617},{"atb":[[7.8,0],[5.9,0]],"id":52671549},{"atb":[[18,0],[13,0]],"id":52671543},{"atb":[[3.6,0],[3.1,0]],"id":52671542},{"atb":[[2.64,0],[2.84,0]],"id":52671545},{"atb":[[4.4,0],[5.4,0]],"id":52237634}],"con":true,"img":false}]}
{"op":"mcm","clk":"11449527131","pt":1717310402797,"mc":[{"id":"1.229554913","rc":[{"atb":[[5.8,50.81],[7.6,15.83]],"id":52237627},{"atb":[[180,0.88],[90,3.92]],"id":52671562},{"atb":[[7.8,15.37],[5.9,49.77]],"id":52671564},{"atb":[[46,2.32],[28,9.03]],"id":52237621},{"atb":[[9.8,11.87],[7.8,35.86]],"id":52671561},{"atb":[[3.6,40.2],[3.1,116.14]],"id":52671560},{"atb":[[2.82,57.43],[2.62,150.55]],"id":52237612},{"atb":[[46,2.32],[28,9.03]],"id":52671552},{"atb":[[180,0.88],[90,3.92]],"id":52671547},{"atb":[[5.8,50.81],[7.6,15.83]],"id":52237617},{"atb":[[7.8,15.37],[5.9,49.77]],"id":52671549},{"atb":[[18,6.14],[13,20.32]],"id":52671543},{"atb":[[3.6,40.2],[3.1,116.14]],"id":52671542},{"atb":[[2.64,148.72],[2.84,56.81]],"id":52671545},{"atb":[[4.4,71.73],[5.4,23.75]],"id":52237634}],"con":true,"img":false}]}
{"op":"mcm","clk":"11449545108","pt":1717310708609,"mc":[{"id":"1.229554913","rc":[{"atb":[[130,0],[180,0.58],[90,2.74],[230,0]],"id":52671562},{"atb":[[130,0],[180,0.58],[90,2.74],[230,0]],"id":52671547}],"con":true,"img":false}]}
{"op":"mcm","clk":"11449545116","pt":1717310708670,"mc":[{"id":"1.229554913","rc":[{"atb":[[4.8,0],[4.3,0],[5.8,0],[5.3,0]],"id":52671542}],"con":true,"img":false}]}
{"op":"mcm","clk":"11449545154","pt":1717310709277,"mc":[{"id":"1.229554913","rc":[{"atb":[[140,0.57],[190,0.28],[95,1.11],[240,0.11]],"id":52671562},{"atb":[[140,0.57],[190,0.28],[95,1.11],[240,0.11]],"id":52671547}],"con":true,"img":false}]}
{"op":"mcm","clk":"11449545164","pt":1717310709380,"mc":[{"id":"1.229554913","rc":[{"atb":[[4.9,20.12],[4.4,30.77],[5.9,5.34],[5.4,11.89]],"id":52671542}],"con":true,"img":false}]}
{"op":"mcm","clk":"11449558902","pt":1717310947927,"mc":[{"id":"1.229554913","rc":[{"atb":[[12,0],[9.8,0],[8.8,0],[14.5,0]],"id":52671549},{"atb":[[6.4,0],[7.4,0],[8.4,0],[9.4,0]],"id":52237634}],"con":true,"img":false}]}
{"op":"mcm","clk":"11449558941","pt":1717310948618,"mc":[{"id":"1.229554913","rc":[{"atb":[[12,4.76],[9.8,8.92],[8.8,13.41],[14.5,1.94]],"id":52671549},{"atb":[[6.4,19.38],[7.4,12.26],[8.4,7.07],[9.4,3.11]],"id":52237634}],"con":true,"img":false}]}
{"op":"mcm","clk":"11449584906","pt":1717311411574,"mc":[{"id":"1.229554913","rc":[{"atb":[[5.8,0],[7.6,0]],"id":52237627},{"atb":[[180,0],[90,0]],"id":52671562},{"atb":[[7.8,0],[5.9,0]],"id":52671564},{"atb":[[46,0],[28,0]],"id":52237621},{"atb":[[9.8,0],[7.8,0]],"id":52671561},{"atb":[[3.6,0],[3.1,0]],"id":52671560},{"atb":[[2.82,0],[2.62,0]],"id":52237612},{"atb":[[46,0],[28,0]],"id":52671552},{"atb":[[180,0],[90,0]],"id":52671547},{"atb":[[5.8,0],[7.6,0]],"id":52237617},{"atb":[[7.8,0],[5.9,0]],"id":52671549},{"atb":[[18,0],[13,0]],"id":52671543},{"atb":[[3.6,0],[3.1,0]],"id":52671542},{"atb":[[2.64,0],[2.84,0]],"id":52671545},{"atb":[[4.4,0],[5.4,0]],"id":52237634}],"con":true,"img":false}]}
{"op":"mcm","clk":"11449585319","pt":1717311419789,"mc":[{"id":"1.229554913","rc":[{"atb":[[5.8,50.81],[7.6,15.83]],"id":52237627},{"atb":[[180,0.58],[90,2.74]],"id":52671562},{"atb":[[7.8,15.37],[5.9,49.77]],"id":52671564},{"atb":[[46,2.32],[28,9.03]],"id":52237621},{"atb":[[9.8,11.87],[7.8,35.86]],"id":52671561},{"atb":[[3.6,40.2],[3.1,116.14]],"id":52671560},{"atb":[[2.82,57.43],[2.62,150.55]],"id":52237612},{"atb":[[46,2.32],[28,9.03]],"id":52671552},{"atb":[[180,0.58],[90,2.74]],"id":52671547},{"atb":[[5.8,50.81],[7.6,15.83]],"id":52237617},{"atb":[[7.8,15.37],[5.9,49.77]],"id":52671549},{"atb":[[18,6.14],[13,20.32]],"id":52671543},{"atb":[[3.6,40.2],[3.1,116.14]],"id":52671542},{"atb":[[2.64,148.72],[2.84,56.81]],"id":52671545},{"atb":[[4.4,71.73],[5.4,23.75]],"id":52237634}],"con":true,"img":false}]}
{"op":"mcm","clk":"11449623621","pt":1717312148206,"mc":[{"id":"1.229554913","rc":[{"atb":[[12,0],[9.8,0],[8.8,0],[14.5,0]],"id":52671549},{"atb":[[6.4,0],[7.4,0],[8.4,0],[9.4,0]],"id":52237634}],"con":true,"img":false}]}
{"op":"mcm","clk":"11449623641","pt":1717312148876,"mc":[{"id":"1.229554913","rc":[{"atb":[[12,4.76],[9.8,8.92],[8.8,13.41],[14.5,1.94]],"id":52671549},{"atb":[[6.4,19.38],[7.4,12.26],[8.4,7.07],[9.4,3.11]],"id":52237634}],"con":true,"img":false}]}
{"op":"mcm","clk":"11449637279","pt":1717312502875,"mc":[{"id":"1.229554913","rc":[{"atb":[[5.8,0],[7.6,0]],"id":52237627},{"atb":[[180,0],[90,0]],"id":52671562},{"atb":[[7.8,0],[5.9,0]],"id":52671564},{"atb":[[46,0],[28,0]],"id":52237621},{"atb":[[9.8,0],[7.8,0]],"id":52671561},{"atb":[[3.6,0],[3.1,0]],"id":52671560},{"atb":[[2.82,0],[2.62,0]],"id":52237612},{"atb":[[46,0],[28,0]],"id":52671552},{"atb":[[180,0],[90,0]],"id":52671547},{"atb":[[5.8,0],[7.6,0]],"id":52237617},{"atb":[[7.8,0],[5.9,0]],"id":52671549},{"atb":[[18,0],[13,0]],"id":52671543},{"atb":[[3.6,0],[3.1,0]],"id":52671542},{"atb":[[2.64,0],[2.84,0]],"id":52671545},{"atb":[[4.4,0],[5.4,0]],"id":52237634}],"con":true,"img":false}]}
{"op":"mcm","clk":"11449638387","pt":1717312529190,"mc":[{"id":"1.229554913","rc":[{"atb":[[5.8,50.81],[7.6,15.83]],"id":52237627},{"atb":[[180,0.58],[90,2.74]],"id":52671562},{"atb":[[7.8,15.37],[5.9,49.77]],"id":52671564},{"atb":[[46,2.32],[28,9.03]],"id":52237621},{"atb":[[9.8,11.87],[7.8,35.86]],"id":52671561},{"atb":[[3.6,40.2],[3.1,116.14]],"id":52671560},{"atb":[[2.82,57.43],[2.62,150.55]],"id":52237612},{"atb":[[46,2.32],[28,9.03]],"id":52671552},{"atb":[[180,0.58],[90,2.74]],"id":52671547},{"atb":[[5.8,50.81],[7.6,15.83]],"id":52237617},{"atb":[[7.8,15.37],[5.9,49.77]],"id":52671549},{"atb":[[18,6.14],[13,20.32]],"id":52671543},{"atb":[[3.6,40.2],[3.1,116.14]],"id":52671542},{"atb":[[2.64,148.72],[2.84,56.81]],"id":52671545},{"atb":[[4.4,71.73],[5.4,23.75]],"id":52237634}],"con":true,"img":false}]}
{"op":"mcm","clk":"11449674181","pt":1717313349007,"mc":[{"id":"1.229554913","rc":[{"atb":[[12,0],[9.8,0],[8.8,0],[14.5,0]],"id":52671549},{"atb":[[6.4,0],[7.4,0],[8.4,0],[9.4,0]],"id":52237634}],"con":true,"img":false}]}
{"op":"mcm","clk":"11449674218","pt":1717313349683,"mc":[{"id":"1.229554913","rc":[{"atb":[[12,4.76],[9.8,8.92],[8.8,13.41],[14.5,1.94]],"id":52671549},{"atb":[[6.4,19.38],[7.4,12.26],[8.4,7.07],[9.4,3.11]],"id":52237634}],"con":true,"img":false}]}
{"op":"mcm","clk":"11449693432","pt":1717313604723,"mc":[{"id":"1.229554913","rc":[{"atb":[[5.8,0],[7.6,0]],"id":52237627},{"atb":[[180,0],[90,0]],"id":52671562},{"atb":[[7.8,0],[5.9,0]],"id":52671564},{"atb":[[46,0],[28,0]],"id":52237621},{"atb":[[9.8,0],[7.8,0]],"id":52671561},{"atb":[[3.6,0],[3.1,0]],"id":52671560},{"atb":[[2.82,0],[2.62,0]],"id":52237612},{"atb":[[46,0],[28,0]],"id":52671552},{"atb":[[180,0],[90,0]],"id":52671547},{"atb":[[5.8,0],[7.6,0]],"id":52237617},{"atb":[[7.8,0],[5.9,0]],"id":52671549},{"atb":[[18,0],[13,0]],"id":52671543},{"atb":[[3.6,0],[3.1,0]],"id":52671542},{"atb":[[2.64,0],[2.84,0]],"id":52671545},{"atb":[[4.4,0],[5.4,0]],"id":52237634}],"con":true,"img":false}]}
{"op":"mcm","clk":"11449696048","pt":1717313635048,"mc":[{"id":"1.229554913","rc":[{"atb":[[3.6,40.2],[3.1,116.14]],"id":52671560},{"atb":[[2.82,57.43],[2.62,150.55]],"id":52237612},{"atb":[[180,0.58],[90,2.74]],"id":52671547},{"atb":[[5.8,50.81],[7.6,15.83]],"id":52237617},{"atb":[[18,6.14],[13,20.32]],"id":52671543},{"atb":[[3.6,40.2],[3.1,116.14]],"id":52671542},{"atb":[[2.64,148.72],[2.84,56.81]],"id":52671545}],"con":true,"img":false}]}
{"op":"mcm","clk":"11449696057","pt":1717313635100,"mc":[{"id":"1.229554913","rc":[{"atb":[[5.8,50.81],[7.6,15.83]],"id":52237627},{"atb":[[180,0.58],[90,2.74]],"id":52671562},{"atb":[[7.8,15.37],[5.9,49.77]],"id":52671564},{"atb":[[46,2.32],[28,9.03]],"id":52237621},{"atb":[[9.8,11.87],[7.8,35.86]],"id":52671561},{"atb":[[46,2.32],[28,9.03]],"id":52671552},{"atb":[[7.8,15.37],[5.9,49.77]],"id":52671549},{"atb":[[4.4,71.73],[5.4,23.75]],"id":52237634}],"con":true,"img":false}]}
{"op":"mcm","clk":"11449703797","pt":1717313734206,"mc":[{"id":"1.229554913","rc":[{"atb":[[5.8,0],[7.6,0]],"id":52237627},{"atb":[[180,0],[90,0]],"id":52671562},{"atb":[[7.8,0],[5.9,0]],"id":52671564},{"atb":[[46,0],[28,0]],"id":52237621},{"atb":[[9.8,0],[7.8,0]],"id":52671561},{"atb":[[3.6,0],[3.1,0]],"id":52671560},{"atb":[[2.82,0],[2.62,0]],"id":52237612},{"atb":[[46,0],[28,0]],"id":52671552},{"atb":[[180,0],[90,0]],"id":52671547},{"atb":[[5.8,0],[7.6,0]],"id":52237617},{"atb":[[7.8,0],[5.9,0]],"id":52671549},{"atb":[[18,0],[13,0]],"id":52671543},{"atb":[[3.6,0],[3.1,0]],"id":52671542},{"atb":[[2.64,0],[2.84,0]],"id":52671545},{"atb":[[4.4,0],[5.4,0]],"id":52237634}],"con":true,"img":false}]}
{"op":"mcm","clk":"11449706177","pt":1717313763450,"mc":[{"id":"1.229554913","rc":[{"atb":[[5.8,50.81],[7.6,15.83]],"id":52237627},{"atb":[[260,0.4],[160,1.53]],"id":52671562},{"atb":[[7.8,15.37],[5.9,49.77]],"id":52671564},{"atb":[[65,1.63],[36,6.96]],"id":52237621},{"atb":[[9.8,11.87],[7.8,35.86]],"id":52671561},{"atb":[[3.6,40.2],[3.1,116.14]],"id":52671560},{"atb":[[2.82,57.43],[2.62,150.55]],"id":52237612},{"atb":[[70,1.51],[38,6.59]],"id":52671552},{"atb":[[260,0.4],[160,1.53]],"id":52671547},{"atb":[[5.8,50.81],[7.6,15.83]],"id":52237617},{"atb":[[7.8,15.37],[5.9,49.77]],"id":52671549},{"atb":[[18.5,5.97],[13.5,19.51]],"id":52671543},{"atb":[[3.6,40.2],[3.1,116.14]],"id":52671542},{"atb":[[2.64,148.72],[2.84,56.81]],"id":52671545},{"atb":[[4.4,71.73],[5.4,23.75]],"id":52237634}],"con":true,"img":false}]}
{"op":"mcm","clk":"11449714651","pt":1717313859074,"mc":[{"id":"1.229554913","rc":[{"atb":[[16.5,0],[19,0],[23,0],[14,0]],"id":52671561},{"atb":[[7.2,0],[9.2,0],[10.5,0],[8.2,0]],"id":52237617},{"atb":[[12,0],[9.8,0],[8.8,0],[14.5,0]],"id":52671549}],"con":true,"img":false}]}
{"op":"mcm","clk":"11449714709","pt":1717313859794,"mc":[{"id":"1.229554913","rc":[{"atb":[[17,4.9],[19.5,2.83],[24,1.14],[14.5,7.75]],"id":52671561},{"atb":[[8,11.21],[9,6.54],[10,2.91],[7,17.44]],"id":52237617},{"atb":[[9.2,12.76],[10.5,8.26],[13,4.36],[15.5,1.81]],"id":52671549}],"con":true,"img":false}]}
{"op":"mcm","clk":"11449716968","pt":1717313886283,"mc":[{"id":"1.229554913","rc":[{"atb":[[140,0],[190,0],[95,0],[240,0]],"id":52671562},{"atb":[[150,0],[75,0],[100,0],[50,0]],"id":52237621},{"atb":[[150,0],[75,0],[100,0],[50,0]],"id":52671552},{"atb":[[140,0],[190,0],[95,0],[240,0]],"id":52671547},{"atb":[[32,0],[42,0],[26,0],[55,0]],"id":52671543}],"con":true,"img":false}]}
{"op":"mcm","clk":"11449717021","pt":1717313887008,"mc":[{"id":"1.229554913","rc":[{"atb":[[260,0.5],[160,2.02],[210,0.25],[110,0.96]],"id":52671562},{"atb":[[160,0.16],[80,0.99],[110,0.48],[55,1.94]],"id":52237621},{"atb":[[170,0.16],[85,0.94],[120,0.44],[60,1.77]],"id":52671552},{"atb":[[260,0.5],[160,2.02],[210,0.25],[110,0.96]],"id":52671547},{"atb":[[34,2.38],[44,1.22],[27,4.02],[60,0.44]],"id":52671543}],"con":true,"img":false}]}
{"op":"mcm","clk":"11449747805","pt":1717314220761,"mc":[{"id":"1.229554913","rc":[{"atb":[[4.9,0],[4.4,0],[5.9,0],[5.4,0]],"id":52671542}],"con":true,"img":false}]}
{"op":"mcm","clk":"11449747876","pt":1717314221476,"mc":[{"id":"1.229554913","rc":[{"atb":[[4.8,20.65],[4.3,31.71],[5.8,5.45],[5.3,12.17]],"id":52671542}],"con":true,"img":false}]}
{"op":"mcm","clk":"11449766676","pt":1717314431940,"mc":[{"id":"1.229554913","rc":[{"atb":[[5.8,0],[7.6,0]],"id":52237627},{"atb":[[260,0.1],[160,0.49]],"id":52671562},{"atb":[[7.8,0],[5.9,0]],"id":52671564},{"atb":[[65,0],[36,0]],"id":52237621},{"atb":[[9.8,0],[7.8,0]],"id":52671561},{"atb":[[3.6,0],[3.1,0]],"id":52671560},{"atb":[[2.82,0],[2.62,0]],"id":52237612},{"atb":[[70,0],[38,0]],"id":52671552},{"atb":[[260,0.1],[160,0.49]],"id":52671547},{"atb":[[5.8,0],[7.6,0]],"id":52237617},{"atb":[[7.8,0],[5.9,0]],"id":52671549},{"atb":[[18.5,0],[13.5,0]],"id":52671543},{"atb":[[3.6,0],[3.1,0]],"id":52671542},{"atb":[[2.64,0],[2.84,0]],"id":52671545},{"atb":[[4.4,0],[5.4,0]],"id":52237634}],"con":true,"img":false}]}
{"op":"mcm","clk":"11449768892","pt":1717314457509,"mc":[{"id":"1.229554913","rc":[{"atb":[[5.8,50.81],[7.6,15.83]],"id":52237627},{"atb":[[260,0.5],[160,2.02]],"id":52671562},{"atb":[[7.8,15.37],[5.9,49.77]],"id":52671564},{"atb":[[65,1.63],[36,6.96]],"id":52237621},{"atb":[[9.8,11.87],[7.8,35.86]],"id":52671561},{"atb":[[70,1.51],[38,6.59]],"id":52671552},{"atb":[[7.8,15.37],[5.9,49.77]],"id":52671549},{"atb":[[4.4,71.73],[5.4,23.75]],"id":52237634}],"con":true,"img":false}]}
{"op":"mcm","clk":"11449768900","pt":1717314457618,"mc":[{"id":"1.229554913","rc":[{"atb":[[3.6,40.2],[3.1,116.14]],"id":52671560},{"atb":[[2.82,57.43],[2.62,150.55]],"id":52237612},{"atb":[[260,0.5],[160,2.02]],"id":52671547},{"atb":[[5.8,50.81],[7.6,15.83]],"id":52237617},{"atb":[[18.5,5.97],[13.5,19.51]],"id":52671543},{"atb":[[3.6,40.2],[3.1,116.14]],"id":52671542},{"atb":[[2.64,148.72],[2.84,56.81]],"id":52671545}],"con":true,"img":false}]}
{"op":"mcm","clk":"11449777418","pt":1717314549802,"mc":[{"id":"1.229554913","rc":[{"atb":[[17,0],[19.5,0],[24,0],[14.5,0]],"id":52671561},{"atb":[[8,0],[9,0],[10,0],[7,0]],"id":52237617},{"atb":[[9.2,0],[10.5,0],[13,0],[15.5,0]],"id":52671549},{"atb":[[6.4,0],[7.4,0],[8.4,0],[9.4,0]],"id":52237634}],"con":true,"img":false}]}
{"op":"mcm","clk":"11449777480","pt":1717314550474,"mc":[{"id":"1.229554913","rc":[{"atb":[[16.5,5.06],[19,2.91],[23,1.19],[14,8.05]],"id":52671561},{"atb":[[7.2,16.88],[9.2,6.38],[10.5,2.75],[8.2,10.9]],"id":52237617},{"atb":[[12,4.76],[9.8,8.92],[8.8,13.41],[14.5,1.94]],"id":52671549},{"atb":[[6.4,19.38],[7.4,12.26],[8.4,7.07],[9.4,3.11]],"id":52237634}],"con":true,"img":false}]}
{"op":"mcm","clk":"11449777820","pt":1717314554210,"mc":[{"id":"1.229554913","rc":[{"atb":[[16.5,0],[19,0],[23,0],[14,0]],"id":52671561}],"con":true,"img":false}]}
{"op":"mcm","clk":"11449777836","pt":1717314554311,"mc":[{"id":"1.229554913","rc":[{"atb":[[12,0],[9.8,0],[8.8,0],[14.5,0]],"id":52671549}],"con":true,"img":false}]}
{"op":"mcm","clk":"11449777891","pt":1717314554888,"mc":[{"id":"1.229554913","rc":[{"atb":[[17,4.9],[19.5,2.83],[24,1.14],[14.5,7.75]],"id":52671561}],"con":true,"img":false}]}
{"op":"mcm","clk":"11449777905","pt":1717314554988,"mc":[{"id":"1.229554913","rc":[{"atb":[[9.2,12.76],[10.5,8.26],[13,4.36],[15.5,1.81]],"id":52671549}],"con":true,"img":false}]}
{"op":"mcm","clk":"11449778034","pt":1717314556291,"mc":[{"id":"1.229554913","rc":[{"atb":[[7.2,0],[9.2,0],[10.5,0],[8.2,0]],"id":52237617}],"con":true,"img":false}]}
{"op":"mcm","clk":"11449778114","pt":1717314557117,"mc":[{"id":"1.229554913","rc":[{"atb":[[8,11.21],[9,6.54],[10,2.91],[7,17.44]],"id":52237617}],"con":true,"img":false}]}
{"op":"mcm","clk":"11449808297","pt":1717314913166,"mc":[{"id":"1.229554913","rc":[{"atb":[[4.8,0],[4.3,0],[5.8,0],[5.3,0]],"id":52671542}],"con":true,"img":false}]}
{"op":"mcm","clk":"11449808374","pt":1717314913874,"mc":[{"id":"1.229554913","rc":[{"atb":[[4.9,20.12],[4.4,30.77],[5.9,5.34],[5.4,11.89]],"id":52671542}],"con":true,"img":false}]}
{"op":"mcm","clk":"11449851245","pt":1717315296108,"mc":[{"id":"1.229554913","rc":[{"atb":[[5.8,0],[7.6,0]],"id":52237627},{"atb":[[260,0.1],[160,0.49]],"id":52671562},{"atb":[[7.8,0],[5.9,0]],"id":52671564},{"atb":[[65,0],[36,0]],"id":52237621},{"atb":[[9.8,0],[7.8,0]],"id":52671561},{"atb":[[3.6,0],[3.1,0]],"id":52671560},{"atb":[[2.82,0],[2.62,0]],"id":52237612},{"atb":[[70,0],[38,0]],"id":52671552},{"atb":[[260,0.1],[160,0.49]],"id":52671547},{"atb":[[5.8,0],[7.6,0]],"id":52237617},{"atb":[[7.8,0],[5.9,0]],"id":52671549},{"atb":[[18.5,0],[13.5,0]],"id":52671543},{"atb":[[3.6,0],[3.1,0]],"id":52671542},{"atb":[[2.64,0],[2.84,0]],"id":52671545},{"atb":[[4.4,0],[5.4,0]],"id":52237634}],"con":true,"img":false}]}
{"op":"mcm","clk":"11449855873","pt":1717315342051,"mc":[{"id":"1.229554913","rc":[{"atb":[[3.6,40.2],[3.1,116.14]],"id":52671560},{"atb":[[2.82,57.43],[2.62,150.55]],"id":52237612},{"atb":[[260,0.5],[160,2.02]],"id":52671547},{"atb":[[5.8,50.81],[7.6,15.83]],"id":52237617},{"atb":[[18.5,5.97],[13.5,19.51]],"id":52671543},{"atb":[[3.6,40.2],[3.1,116.14]],"id":52671542},{"atb":[[2.64,148.72],[2.84,56.81]],"id":52671545}],"con":true,"img":false}]}
{"op":"mcm","clk":"11449855885","pt":1717315342157,"mc":[{"id":"1.229554913","rc":[{"atb":[[5.8,50.81],[7.6,15.83]],"id":52237627},{"atb":[[260,0.5],[160,2.02]],"id":52671562},{"atb":[[7.8,15.37],[5.9,49.77]],"id":52671564},{"atb":[[65,1.63],[36,6.96]],"id":52237621},{"atb":[[9.8,11.87],[7.8,35.86]],"id":52671561},{"atb":[[70,1.51],[38,6.59]],"id":52671552},{"atb":[[7.8,15.37],[5.9,49.77]],"id":52671549},{"atb":[[4.4,71.73],[5.4,23.75]],"id":52237634}],"con":true,"img":false}]}
{"op":"mcm","clk":"11449883429","pt":1717315612465,"mc":[{"id":"1.229554913","rc":[{"atb":[[4.9,0],[4.4,0],[5.9,0],[5.4,0]],"id":52671542}],"con":true,"img":false}]}
{"op":"mcm","clk":"11449883514","pt":1717315613157,"mc":[{"id":"1.229554913","rc":[{"atb":[[4.8,20.65],[4.3,31.71],[5.8,5.45],[5.3,12.17]],"id":52671542}],"con":true,"img":false}]}
{"op":"mcm","clk":"11449884975","pt":1717315626961,"mc":[{"id":"1.229554913","rc":[{"atb":[[4.8,0],[4.3,0],[5.8,0],[5.3,0]],"id":52671542}],"con":true,"img":false}]}
{"op":"mcm","clk":"11449885046","pt":1717315627689,"mc":[{"id":"1.229554913","rc":[{"atb":[[4.9,20.12],[4.4,30.77],[5.9,5.34],[5.4,11.89]],"id":52671542}],"con":true,"img":false}]}
{"op":"mcm","clk":"11449886040","pt":1717315637592,"mc":[{"id":"1.229554913","rc":[{"atb":[[4.9,0],[4.4,0],[5.9,0],[5.4,0]],"id":52671542}],"con":true,"img":false}]}
{"op":"mcm","clk":"11449886113","pt":1717315638272,"mc":[{"id":"1.229554913","rc":[{"atb":[[4.9,20.12],[4.4,30.77],[5.9,5.34],[5.4,11.89]],"id":52671542}],"con":true,"img":false}]}
{"op":"mcm","clk":"11449888066","pt":1717315657618,"mc":[{"id":"1.229554913","rc":[{"atb":[[170,0],[85,0],[120,0],[60,0]],"id":52671552},{"atb":[[4.9,0],[4.4,0],[5.9,0],[5.4,0]],"id":52671542}],"con":true,"img":false}]}
{"op":"mcm","clk":"11449888131","pt":1717315658290,"mc":[{"id":"1.229554913","rc":[{"atb":[[160,0.16],[80,0.99],[110,0.48],[55,1.94]],"id":52671552},{"atb":[[4.5,29.89],[5,19.62],[5.5,11.63],[6,5.23]],"id":52671542}],"con":true,"img":false}]}
{"op":"mcm","clk":"11449897644","pt":1717315749690,"mc":[{"id":"1.229554913","rc":[{"atb":[[17,0],[19.5,0],[24,0],[14.5,0]],"id":52671561},{"atb":[[8,0],[9,0],[10,0],[7,0]],"id":52237617},{"atb":[[9.2,0],[10.5,0],[13,0],[15.5,0]],"id":52671549},{"atb":[[6.4,0],[7.4,0],[8.4,0],[9.4,0]],"id":52237634}],"con":true,"img":false}]}
{"op":"mcm","clk":"11449897718","pt":1717315750367,"mc":[{"id":"1.229554913","rc":[{"atb":[[16.5,5.06],[19,2.91],[23,1.19],[14,8.05]],"id":52671561},{"atb":[[7.2,16.88],[9.2,6.38],[10.5,2.75],[8.2,10.9]],"id":52237617},{"atb":[[12,4.76],[9.8,8.92],[8.8,13.41],[14.5,1.94]],"id":52671549},{"atb":[[6.4,19.38],[7.4,12.26],[8.4,7.07],[9.4,3.11]],"id":52237634}],"con":true,"img":false}]}
{"op":"mcm","clk":"11449898449","pt":1717315757095,"mc":[{"id":"1.229554913","rc":[{"atb":[[7.2,0],[9.2,0],[10.5,0],[8.2,0]],"id":52237617}],"con":true,"img":false}]}
{"op":"mcm","clk":"11449898526","pt":1717315757778,"mc":[{"id":"1.229554913","rc":[{"atb":[[8,11.21],[9,6.54],[10,2.91],[7,17.44]],"id":52237617}],"con":true,"img":false}]}
{"op":"mcm","clk":"11449936832","pt":1717316137988,"mc":[{"id":"1.229554913","rc":[{"atb":[[5.8,0],[7.6,0]],"id":52237627},{"atb":[[260,0.1],[160,0.49]],"id":52671562},{"atb":[[7.8,0],[5.9,0]],"id":52671564},{"atb":[[65,0],[36,0]],"id":52237621},{"atb":[[9.8,0],[7.8,0]],"id":52671561},{"atb":[[3.6,0],[3.1,0]],"id":52671560},{"atb":[[2.82,0],[2.62,0]],"id":52237612},{"atb":[[70,0],[38,0]],"id":52671552},{"atb":[[260,0.1],[160,0.49]],"id":52671547},{"atb":[[5.8,0],[7.6,0]],"id":52237617},{"atb":[[7.8,0],[5.9,0]],"id":52671549},{"atb":[[18.5,0],[13.5,0]],"id":52671543},{"atb":[[3.6,0],[3.1,0]],"id":52671542},{"atb":[[2.64,0],[2.84,0]],"id":52671545},{"atb":[[4.4,0],[5.4,0]],"id":52237634}],"con":true,"img":false}]}
{"op":"mcm","clk":"11449939385","pt":1717316165470,"mc":[{"id":"1.229554913","rc":[{"atb":[[5.8,50.81],[7.6,15.83]],"id":52237627},{"atb":[[260,0.5],[160,2.02]],"id":52671562},{"atb":[[7.8,15.37],[5.9,49.77]],"id":52671564},{"atb":[[65,1.63],[36,6.96]],"id":52237621},{"atb":[[9.8,11.87],[7.8,35.86]],"id":52671561},{"atb":[[3.6,40.2],[3.1,116.14]],"id":52671560},{"atb":[[2.82,57.43],[2.62,150.55]],"id":52237612},{"atb":[[70,1.51],[38,6.59]],"id":52671552},{"atb":[[260,0.5],[160,2.02]],"id":52671547},{"atb":[[5.8,50.81],[7.6,15.83]],"id":52237617},{"atb":[[7.8,15.37],[5.9,49.77]],"id":52671549},{"atb":[[18.5,5.97],[13.5,19.51]],"id":52671543},{"atb":[[3.6,40.2],[3.1,116.14]],"id":52671542},{"atb":[[2.64,148.72],[2.84,56.81]],"id":52671545},{"atb":[[4.4,71.73],[5.4,23.75]],"id":52237634}],"con":true,"img":false}]}
{"op":"mcm","clk":"11449941962","pt":1717316192498,"mc":[{"id":"1.229554913","rc":[{"atb":[[5.8,0],[7.6,0]],"id":52237627},{"atb":[[260,0.1],[160,0.49]],"id":52671562},{"atb":[[7.8,0],[5.9,0]],"id":52671564},{"atb":[[65,0],[36,0]],"id":52237621},{"atb":[[9.8,0],[7.8,0]],"id":52671561},{"atb":[[3.6,0],[3.1,0]],"id":52671560},{"atb":[[2.82,0],[2.62,0]],"id":52237612},{"atb":[[70,0],[38,0]],"id":52671552},{"atb":[[260,0.1],[160,0.49]],"id":52671547},{"atb":[[5.8,0],[7.6,0]],"id":52237617},{"atb":[[7.8,0],[5.9,0]],"id":52671549},{"atb":[[18.5,0],[13.5,0]],"id":52671543},{"atb":[[3.6,0],[3.1,0]],"id":52671542},{"atb":[[2.64,0],[2.84,0]],"id":52671545},{"atb":[[4.4,0],[5.4,0]],"id":52237634}],"con":true,"img":false}]}
{"op":"mcm","clk":"11449942980","pt":1717316203690,"mc":[{"id":"1.229554913","rc":[{"atb":[[5.8,50.81],[7.6,15.83]],"id":52237627},{"atb":[[260,0.5],[160,2.02]],"id":52671562},{"atb":[[7.8,15.37],[5.9,49.77]],"id":52671564},{"atb":[[65,1.63],[36,6.96]],"id":52237621},{"atb":[[9.8,11.87],[7.8,35.86]],"id":52671561},{"atb":[[3.6,40.2],[3.1,116.14]],"id":52671560},{"atb":[[2.82,57.43],[2.62,150.55]],"id":52237612},{"atb":[[70,1.51],[38,6.59]],"id":52671552},{"atb":[[260,0.5],[160,2.02]],"id":52671547},{"atb":[[5.8,50.81],[7.6,15.83]],"id":52237617},{"atb":[[7.8,15.37],[5.9,49.77]],"id":52671549},{"atb":[[18.5,5.97],[13.5,19.51]],"id":52671543},{"atb":[[3.6,40.2],[3.1,116.14]],"id":52671542},{"atb":[[2.64,148.72],[2.84,56.81]],"id":52671545},{"atb":[[4.4,71.73],[5.4,23.75]],"id":52237634}],"con":true,"img":false}]}
{"op":"mcm","clk":"11449950456","pt":1717316289118,"mc":[{"id":"1.229554913","rc":[{"atb":[[16.5,0],[19,0],[23,0],[14,0]],"id":52671561},{"atb":[[12,0],[9.8,0],[8.8,0],[14.5,0]],"id":52671549}],"con":true,"img":false}]}
{"op":"mcm","clk":"11449950510","pt":1717316289837,"mc":[{"id":"1.229554913","rc":[{"atb":[[17,4.9],[19.5,2.83],[24,1.14],[14.5,7.75]],"id":52671561},{"atb":[[9.2,12.76],[10.5,8.26],[13,4.36],[15.5,1.81]],"id":52671549}],"con":true,"img":false}]}
{"op":"mcm","clk":"11449998611","pt":1717316929745,"mc":[{"id":"1.229554913","rc":[{"atb":[[3.4,0],[3.15,0],[3.9,0],[3.65,0]],"id":52237612},{"atb":[[4.1,0],[3.8,0],[3.55,0],[3.3,0]],"id":52671545}],"con":true,"img":false}]}
{"op":"mcm","clk":"11449998669","pt":1717316930412,"mc":[{"id":"1.229554913","rc":[{"atb":[[3.6,20.12],[3.85,9.18],[3.1,49.83],[3.35,33.39]],"id":52237612},{"atb":[[3.45,32.03],[3.2,47.56],[3.95,8.87],[3.7,19.38]],"id":52671545}],"con":true,"img":false}]}
{"op":"mcm","clk":"11450003961","pt":1717316992343,"mc":[{"id":"1.229554913","rc":[{"atb":[[5.8,0],[7.6,0]],"id":52237627},{"atb":[[260,0.1],[160,0.49]],"id":52671562},{"atb":[[7.8,0],[5.9,0]],"id":52671564},{"atb":[[65,0],[36,0]],"id":52237621},{"atb":[[9.8,0],[7.8,0]],"id":52671561},{"atb":[[3.6,0],[3.1,0]],"id":52671560},{"atb":[[2.82,0],[2.62,0]],"id":52237612},{"atb":[[70,0],[38,0]],"id":52671552},{"atb":[[260,0.1],[160,0.49]],"id":52671547},{"atb":[[5.8,0],[7.6,0]],"id":52237617},{"atb":[[7.8,0],[5.9,0]],"id":52671549},{"atb":[[18.5,0],[13.5,0]],"id":52671543},{"atb":[[3.6,0],[3.1,0]],"id":52671542},{"atb":[[2.64,0],[2.84,0]],"id":52671545},{"atb":[[4.4,0],[5.4,0]],"id":52237634}],"con":true,"img":false}]}
{"op":"mcm","clk":"11450007767","pt":1717317031597,"mc":[{"id":"1.229554913","rc":[{"atb":[[5.8,50.81],[7.6,15.83]],"id":52237627},{"atb":[[260,0.5],[160,2.02]],"id":52671562},{"atb":[[7.8,15.37],[5.9,49.77]],"id":52671564},{"atb":[[65,1.63],[36,6.96]],"id":52237621},{"atb":[[9.8,11.87],[7.8,35.86]],"id":52671561},{"atb":[[3.6,40.2],[3.1,116.14]],"id":52671560},{"atb":[[2.82,57.43],[2.62,150.55]],"id":52237612},{"atb":[[70,1.51],[38,6.59]],"id":52671552},{"atb":[[260,0.5],[160,2.02]],"id":52671547},{"atb":[[5.8,50.81],[7.6,15.83]],"id":52237617},{"atb":[[7.8,15.37],[5.9,49.77]],"id":52671549},{"atb":[[18.5,5.97],[13.5,19.51]],"id":52671543},{"atb":[[3.6,40.2],[3.1,116.14]],"id":52671542},{"atb":[[2.64,148.72],[2.84,56.81]],"id":52671545},{"atb":[[4.4,71.73],[5.4,23.75]],"id":52237634}],"con":true,"img":false}]}
{"op":"mcm","clk":"11450028903","pt":1717317245529,"mc":[{"id":"1.229554913","rc":[{"atb":[[260,0.4],[160,1.53],[210,0],[110,0]],"id":52671562},{"atb":[[260,0.4],[160,1.53],[210,0],[110,0]],"id":52671547},{"atb":[[3.45,0],[3.2,0],[3.95,0],[3.7,0]],"id":52671545}],"con":true,"img":false}]}
{"op":"mcm","clk":"11450028970","pt":1717317246252,"mc":[{"id":"1.229554913","rc":[{"atb":[[150,0.53],[200,0.26],[100,1.06],[250,0.1]],"id":52671562},{"atb":[[150,0.53],[200,0.26],[100,1.06],[250,0.1]],"id":52671547},{"atb":[[4.1,8.44],[3.8,18.68],[3.55,30.77],[3.3,45.5]],"id":52671545}],"con":true,"img":false}]}
{"op":"mcm","clk":"11450029072","pt":1717317247450,"mc":[{"id":"1.229554913","rc":[{"atb":[[17,0],[19.5,0],[24,0],[14.5,0]],"id":52671561},{"atb":[[9.2,0],[10.5,0],[13,0],[15.5,0]],"id":52671549},{"atb":[[6.4,0],[7.4,0],[8.4,0],[9.4,0]],"id":52237634}],"con":true,"img":false}]}
{"op":"mcm","clk":"11450029149","pt":1717317248169,"mc":[{"id":"1.229554913","rc":[{"atb":[[16.5,5.06],[19,2.91],[23,1.19],[14,8.05]],"id":52671561},{"atb":[[12,4.76],[9.8,8.92],[8.8,13.41],[14.5,1.94]],"id":52671549},{"atb":[[6.4,19.38],[7.4,12.26],[8.4,7.07],[9.4,3.11]],"id":52237634}],"con":true,"img":false}]}
{"op":"mcm","clk":"11450029483","pt":1717317251643,"mc":[{"id":"1.229554913","rc":[{"atb":[[16.5,0],[19,0],[23,0],[14,0]],"id":52671561},{"atb":[[12,0],[9.8,0],[8.8,0],[14.5,0]],"id":52671549}],"con":true,"img":false}]}
{"op":"mcm","clk":"11450030125","pt":1717317258067,"mc":[{"id":"1.229554913","rc":[{"atb":[[17,4.9],[19.5,2.83],[24,1.14],[14.5,7.75]],"id":52671561},{"atb":[[9.2,12.76],[10.5,8.26],[13,4.36],[15.5,1.81]],"id":52671549}],"con":true,"img":false}]}
{"op":"mcm","clk":"11450041561","pt":1717317364373,"mc":[{"id":"1.229554913","rc":[{"atb":[[160,0],[80,0],[110,0],[55,0]],"id":52237621},{"atb":[[160,0],[80,0],[110,0],[55,0]],"id":52671552},{"atb":[[34,0],[44,0],[27,0],[60,0]],"id":52671543},{"atb":[[4.5,0],[5,0],[5.5,0],[6,0]],"id":52671542}],"con":true,"img":false}]}
{"op":"mcm","clk":"11450041635","pt":1717317365088,"mc":[{"id":"1.229554913","rc":[{"atb":[[150,0.18],[75,1.06],[100,0.53],[50,2.13]],"id":52237621},{"atb":[[170,0.16],[85,0.94],[120,0.44],[60,1.77]],"id":52671552},{"atb":[[32,2.53],[42,1.28],[26,4.19],[55,0.49]],"id":52671543},{"atb":[[4.9,20.12],[4.4,30.77],[5.9,5.34],[5.4,11.89]],"id":52671542}],"con":true,"img":false}]}
{"op":"mcm","clk":"11450042310","pt":1717317371555,"mc":[{"id":"1.229554913","rc":[{"atb":[[170,0],[85,0],[120,0],[60,0]],"id":52671552}],"con":true,"img":false}]}
{"op":"mcm","clk":"11450042379","pt":1717317372278,"mc":[{"id":"1.229554913","rc":[{"atb":[[160,0.16],[80,0.99],[110,0.48],[55,1.94]],"id":52671552}],"con":true,"img":false}]}
{"op":"mcm","clk":"11450053394","pt":1717317480288,"mc":[{"id":"1.229554913","rc":[{"atb":[[7.6,30.98]],"id":52237627},{"atl":[[440,2]],"id":52237627},{"atb":[[120,2]],"id":52671562},{"atb":[[7.8,30.08]],"id":52671564},{"atl":[[450,2]],"id":52671564},{"atb":[[75,3.06]],"id":52237621},{"atb":[[12,9.09]],"id":52671561},{"atb":[[2.94,49.52]],"id":52671560},{"atl":[[220,2]],"id":52671560},{"atb":[[1.91,83.23]],"id":52237612},{"atl":[[90,2]],"id":52237612},{"atb":[[75,2]],"id":52671552},{"atb":[[120,2]],"id":52671547},{"atb":[[7.6,30.98]],"id":52237617},{"atl":[[440,2]],"id":52237617},{"atb":[[1.44,21.04]],"id":52671549},{"atl":[[450,2]],"id":52671549},{"atb":[[1.44,6.73]],"id":52671543},{"atb":[[2.94,50.91]],"id":52671542},{"atl":[[220,2]],"id":52671542},{"atb":[[1.95,76.28]],"id":52671545},{"atl":[[100,2]],"id":52671545},{"atb":[[5,25]],"id":52237634},{"atl":[[380,2]],"id":52237634}],"con":true,"img":false}]}
{"op":"mcm","clk":"11450056654","pt":1717317517407,"mc":[{"id":"1.229554913","rc":[{"atb":[[2,76.28],[1.95,0]],"id":52671545}],"con":true,"img":false}]}
{"op":"mcm","clk":"11450063886","pt":1717317597698,"mc":[{"id":"1.229554913","rc":[{"atb":[[5.8,0],[7.6,15.15]],"id":52237627},{"atb":[[260,0],[160,0]],"id":52671562},{"atb":[[7.8,14.71],[5.9,0]],"id":52671564},{"atb":[[65,0],[36,0]],"id":52237621},{"atb":[[9.8,0],[7.8,0]],"id":52671561},{"atb":[[3.6,0],[3.1,0]],"id":52671560},{"atb":[[2.82,0],[2.62,0]],"id":52237612},{"atb":[[70,0],[38,0]],"id":52671552},{"atb":[[260,0],[160,0]],"id":52671547},{"atb":[[5.8,0],[7.6,15.15]],"id":52237617},{"atb":[[7.8,0],[5.9,0]],"id":52671549},{"atb":[[18.5,0],[13.5,0]],"id":52671543},{"atb":[[3.6,0],[3.1,0]],"id":52671542},{"atb":[[2.64,0],[2.84,0]],"id":52671545},{"atb":[[4.4,0],[5.4,0]],"id":52237634}],"con":true,"img":false}]}
{"op":"mcm","clk":"11450066172","pt":1717317622833,"mc":[{"id":"1.229554913","rc":[{"atb":[[5.8,50.81],[7.6,30.98]],"id":52237627},{"atb":[[260,0.4],[160,1.53]],"id":52671562},{"atb":[[7.8,30.08],[5.9,49.77]],"id":52671564},{"atb":[[65,1.63],[36,6.96]],"id":52237621},{"atb":[[9.8,11.87],[7.8,35.86]],"id":52671561},{"atb":[[3.6,40.2],[3.1,116.14]],"id":52671560},{"atb":[[2.82,57.43],[2.62,150.55]],"id":52237612},{"atb":[[70,1.51],[38,6.59]],"id":52671552},{"atb":[[260,0.4],[160,1.53]],"id":52671547},{"atb":[[5.8,50.81],[7.6,30.98]],"id":52237617},{"atb":[[7.8,15.37],[5.9,49.77]],"id":52671549},{"atb":[[18.5,5.97],[13.5,19.51]],"id":52671543},{"atb":[[3.6,40.2],[3.1,116.14]],"id":52671542},{"atb":[[2.64,148.72],[2.84,56.81]],"id":52671545},{"atb":[[4.4,71.73],[5.4,23.75]],"id":52237634}],"con":true,"img":false}]}
{"op":"mcm","clk":"11450077139","pt":1717317742256,"mc":[{"id":"1.229554913","rc":[{"atb":[[150,0],[75,2],[100,0],[50,0]],"id":52237621},{"atb":[[32,0],[42,0],[26,0],[55,0]],"id":52671543},{"atb":[[4.9,0],[4.4,0],[5.9,0],[5.4,0]],"id":52671542}],"con":true,"img":false}]}
{"op":"mcm","clk":"11450077159","pt":1717317742450,"mc":[{"id":"1.229554913","rc":[{"atb":[[65,3.63],[75,0]],"id":52237621}],"con":true,"img":false}]}
{"op":"mcm","clk":"11450077215","pt":1717317742913,"mc":[{"id":"1.229554913","rc":[{"atb":[[160,0.16],[80,0.99],[110,0.48],[55,1.94]],"id":52237621},{"atb":[[34,2.38],[44,1.22],[27,4.02],[60,0.44]],"id":52671543},{"atb":[[4.5,29.89],[5,19.62],[5.5,11.63],[6,5.23]],"id":52671542}],"con":true,"img":false}]}
{"op":"mcm","clk":"11450081009","pt":1717317785082,"mc":[{"id":"1.229554913","rc":[{"atb":[[65,1.63],[80,2.99]],"id":52237621},{"atb":[[75,0],[85,2]],"id":52671552}],"con":true,"img":false}]}
{"op":"mcm","clk":"11450081033","pt":1717317785342,"mc":[{"id":"1.229554913","rc":[{"atb":[[150,0],[200,0],[100,0],[250,0]],"id":52671562},{"atb":[[160,0],[80,0],[110,0],[55,0]],"id":52671552},{"atb":[[150,0],[200,0],[100,0],[250,0]],"id":52671547},{"atb":[[44,0]],"id":52671543}],"con":true,"img":false}]}
{"op":"mcm","clk":"11450081094","pt":1717317786065,"mc":[{"id":"1.229554913","rc":[{"atb":[[270,0.1],[170,0.47],[220,0.24],[120,2.88]],"id":52671562},{"atb":[[130,0.41],[65,1.64],[180,0.15],[90,0.88]],"id":52671552},{"atb":[[270,0.1],[170,0.47],[220,0.24],[120,2.88]],"id":52671547},{"atb":[[46,1.16]],"id":52671543}],"con":true,"img":false}]}
{"op":"mcm","clk":"11450104907","pt":1717318060524,"mc":[{"id":"1.229554913","rc":[{"atb":[[5.8,0],[7.6,15.15]],"id":52237627},{"atb":[[260,0],[160,0]],"id":52671562},{"atb":[[7.8,14.71],[5.9,0]],"id":52671564},{"atb":[[65,0],[36,0]],"id":52237621},{"atb":[[9.8,0],[7.8,0]],"id":52671561},{"atb":[[3.6,0],[3.1,0]],"id":52671560},{"atb":[[2.82,0],[2.62,0]],"id":52237612},{"atb":[[70,0],[38,0]],"id":52671552},{"atb":[[260,0],[160,0]],"id":52671547},{"atb":[[5.8,0],[7.6,15.15]],"id":52237617},{"atb":[[7.8,0],[5.9,0]],"id":52671549},{"atb":[[18.5,0],[13.5,0]],"id":52671543},{"atb":[[3.6,0],[3.1,0]],"id":52671542},{"atb":[[2.64,0],[2.84,0]],"id":52671545},{"atb":[[4.4,0],[5.4,0]],"id":52237634}],"con":true,"img":false}]}
{"op":"mcm","clk":"11450106956","pt":1717318082448,"mc":[{"id":"1.229554913","rc":[{"atb":[[160,0],[80,2],[110,0],[55,0]],"id":52237621},{"atb":[[34,0],[27,0],[60,0]],"id":52671543}],"con":true,"img":false}]}
{"op":"mcm","clk":"11450107020","pt":1717318083132,"mc":[{"id":"1.229554913","rc":[{"atb":[[65,0.41],[36,2.24],[28,3.88]],"id":52671543}],"con":true,"img":false}]}
{"op":"mcm","clk":"11450107033","pt":1717318083236,"mc":[{"id":"1.229554913","rc":[{"atb":[[170,0.16],[85,0.94],[120,0.44],[60,1.77]],"id":52237621}],"con":true,"img":false}]}
{"op":"mcm","clk":"11450107619","pt":1717318089661,"mc":[{"id":"1.229554913","rc":[{"atb":[[3.6,40.2],[3.1,116.14]],"id":52671560},{"atb":[[2.82,57.43],[2.62,150.55]],"id":52237612},{"atb":[[260,0.4],[160,1.53]],"id":52671547},{"atb":[[5.8,50.81],[7.6,30.98]],"id":52237617},{"atb":[[18.5,5.97],[13.5,19.51]],"id":52671543},{"atb":[[3.6,40.2],[3.1,116.14]],"id":52671542},{"atb":[[2.64,148.72],[2.84,56.81]],"id":52671545}],"con":true,"img":false}]}
{"op":"mcm","clk":"11450107630","pt":1717318089760,"mc":[{"id":"1.229554913","rc":[{"atb":[[5.8,50.81],[7.6,30.98]],"id":52237627},{"atb":[[260,0.4],[160,1.53]],"id":52671562},{"atb":[[7.8,30.08],[5.9,49.77]],"id":52671564},{"atb":[[65,1.63],[36,6.96]],"id":52237621},{"atb":[[9.8,11.87],[7.8,35.86]],"id":52671561},{"atb":[[70,1.51],[38,6.59]],"id":52671552},{"atb":[[7.8,15.37],[5.9,49.77]],"id":52671549},{"atb":[[4.4,71.73],[5.4,23.75]],"id":52237634}],"con":true,"img":false}]}
{"op":"mcm","clk":"11450115083","pt":1717318173359,"mc":[{"id":"1.229554913","rc":[{"atb":[[270,0],[170,0],[220,0],[120,2]],"id":52671562},{"atb":[[270,0],[170,0],[220,0],[120,2]],"id":52671547},{"atb":[[4.5,0],[5,0],[5.5,0],[6,0]],"id":52671542}],"con":true,"img":false}]}
{"op":"mcm","clk":"11450115148","pt":1717318174033,"mc":[{"id":"1.229554913","rc":[{"atb":[[130,0.81],[280,0.09],[180,0.44],[230,0.23]],"id":52671562},{"atb":[[130,0.81],[280,0.09],[180,0.44],[230,0.23]],"id":52671547},{"atb":[[4.9,20.12],[4.4,30.77],[5.9,5.34],[5.4,11.89]],"id":52671542}],"con":true,"img":false}]}
{"op":"mcm","clk":"11450115589","pt":1717318179724,"mc":[{"id":"1.229554913","rc":[{"atb":[[130,0],[280,0],[180,0],[230,0]],"id":52671562},{"atb":[[130,0],[280,0],[180,0],[230,0]],"id":52671547}],"con":true,"img":false}]}
{"op":"mcm","clk":"11450115653","pt":1717318180451,"mc":[{"id":"1.229554913","rc":[{"atb":[[270,0.1],[170,0.47],[220,0.24],[120,2.88]],"id":52671562},{"atb":[[270,0.1],[170,0.47],[220,0.24],[120,2.88]],"id":52671547}],"con":true,"img":false}]}
{"op":"mcm","clk":"11450137042","pt":1717318428088,"mc":[{"id":"1.229554913","rc":[{"atb":[[5.8,0],[7.6,15.15]],"id":52237627},{"atb":[[260,0],[160,0]],"id":52671562},{"atb":[[7.8,14.71],[5.9,0]],"id":52671564},{"atb":[[65,0],[36,0]],"id":52237621},{"atb":[[9.8,0],[7.8,0]],"id":52671561},{"atb":[[3.6,0],[3.1,0]],"id":52671560},{"atb":[[2.82,0],[2.62,0]],"id":52237612},{"atb":[[70,0],[38,0]],"id":52671552},{"atb":[[260,0],[160,0]],"id":52671547},{"atb":[[5.8,0],[7.6,15.15]],"id":52237617},{"atb":[[7.8,0],[5.9,0]],"id":52671549},{"atb":[[18.5,0],[13.5,0]],"id":52671543},{"atb":[[3.6,0],[3.1,0]],"id":52671542},{"atb":[[2.64,0],[2.84,0]],"id":52671545},{"atb":[[4.4,0],[5.4,0]],"id":52237634}],"con":true,"img":false}]}
{"op":"mcm","clk":"11450138825","pt":1717318447985,"mc":[{"id":"1.229554913","rc":[{"atb":[[17,0],[19.5,0],[24,0],[14.5,0]],"id":52671561},{"atb":[[9.2,0],[10.5,0],[13,0],[15.5,0]],"id":52671549},{"atb":[[6.4,0],[7.4,0],[8.4,0],[9.4,0]],"id":52237634}],"con":true,"img":false}]}
{"op":"mcm","clk":"11450138887","pt":1717318448713,"mc":[{"id":"1.229554913","rc":[{"atb":[[16.5,5.06],[19,2.91],[23,1.19],[14,8.05]],"id":52671561},{"atb":[[12,4.76],[9.8,8.92],[8.8,13.41],[14.5,1.94]],"id":52671549},{"atb":[[6.4,19.38],[7.4,12.26],[8.4,7.07],[9.4,3.11]],"id":52237634}],"con":true,"img":false}]}
{"op":"mcm","clk":"11450139265","pt":1717318453310,"mc":[{"id":"1.229554913","rc":[{"atb":[[3.6,40.2],[3.1,116.14]],"id":52671560},{"atb":[[2.82,57.43],[2.62,150.55]],"id":52237612},{"atb":[[260,0.4],[160,1.53]],"id":52671547},{"atb":[[5.8,50.81],[7.6,30.98]],"id":52237617},{"atb":[[18.5,5.97],[13.5,19.51]],"id":52671543},{"atb":[[3.6,40.2],[3.1,116.14]],"id":52671542},{"atb":[[2.64,148.72],[2.84,56.81]],"id":52671545}],"con":true,"img":false}]}
{"op":"mcm","clk":"11450139279","pt":1717318453413,"mc":[{"id":"1.229554913","rc":[{"atb":[[5.8,50.81],[7.6,30.98]],"id":52237627},{"atb":[[260,0.4],[160,1.53]],"id":52671562},{"atb":[[7.8,30.08],[5.9,49.77]],"id":52671564},{"atb":[[65,1.63],[36,6.96]],"id":52237621},{"atb":[[9.8,11.87],[7.8,35.86]],"id":52671561},{"atb":[[70,1.51],[38,6.59]],"id":52671552},{"atb":[[7.8,15.37],[5.9,49.77]],"id":52671549},{"atb":[[4.4,71.73],[5.4,23.75]],"id":52237634}],"con":true,"img":false}]}
{"op":"mcm","clk":"11450139372","pt":1717318454292,"mc":[{"id":"1.229554913","rc":[{"atb":[[12,0],[9.8,0],[8.8,0],[14.5,0]],"id":52671549}],"con":true,"img":false}]}
{"op":"mcm","clk":"11450139381","pt":1717318454396,"mc":[{"id":"1.229554913","rc":[{"atb":[[16.5,0],[19,0],[23,0],[14,0]],"id":52671561}],"con":true,"img":false}]}
{"op":"mcm","clk":"11450139390","pt":1717318454502,"mc":[{"id":"1.229554913","rc":[{"atb":[[10,11.11],[12,0]],"id":52671561}],"con":true,"img":false}]}
{"op":"mcm","clk":"11450139439","pt":1717318455016,"mc":[{"id":"1.229554913","rc":[{"atb":[[9.2,12.76],[10.5,8.26],[13,4.36],[15.5,1.81]],"id":52671549}],"con":true,"img":false}]}
{"op":"mcm","clk":"11450139450","pt":1717318455071,"mc":[{"id":"1.229554913","rc":[{"atb":[[17,4.9],[19.5,2.83],[24,1.14],[14.5,7.75]],"id":52671561}],"con":true,"img":false}]}
{"op":"mcm","clk":"11450140788","pt":1717318470305,"mc":[{"id":"1.229554913","rc":[{"atb":[[5.9,0]],"id":52671542}],"con":true,"img":false}]}
{"op":"mcm","clk":"11450140798","pt":1717318470407,"mc":[{"id":"1.229554913","rc":[{"atb":[[4.9,0],[4.4,0],[5.4,0]],"id":52671542}],"con":true,"img":false}]}
{"op":"mcm","clk":"11450140849","pt":1717318471025,"mc":[{"id":"1.229554913","rc":[{"atb":[[6,5.23]],"id":52671542}],"con":true,"img":false}]}
{"op":"mcm","clk":"11450140863","pt":1717318471130,"mc":[{"id":"1.229554913","rc":[{"atb":[[4.5,29.89],[5,19.62],[5.5,11.63]],"id":52671542}],"con":true,"img":false}]}
{"op":"mcm","clk":"11450148209","pt":1717318555526,"mc":[{"id":"1.229554913","rc":[{"atb":[[270,0],[170,0],[220,0],[120,2]],"id":52671562},{"atb":[[270,0],[170,0],[220,0],[120,2]],"id":52671547},{"atb":[[4.5,0],[5,0],[5.5,0],[6,0]],"id":52671542}],"con":true,"img":false}]}
{"op":"mcm","clk":"11450148274","pt":1717318556203,"mc":[{"id":"1.229554913","rc":[{"atb":[[270,0.1],[170,0.47],[220,0.24],[120,2.88]],"id":52671562},{"atb":[[270,0.1],[170,0.47],[220,0.24],[120,2.88]],"id":52671547},{"atb":[[4.5,29.89],[5,19.62],[5.5,11.63],[6,5.23]],"id":52671542}],"con":true,"img":false}]}
{"op":"mcm","clk":"11450152044","pt":1717318595741,"mc":[{"id":"1.229554913","rc":[{"atb":[[4.5,0],[5,0],[5.5,0],[6,0]],"id":52671542}],"con":true,"img":false}]}
{"op":"mcm","clk":"11450152111","pt":1717318596462,"mc":[{"id":"1.229554913","rc":[{"atb":[[4.9,20.12],[4.4,30.77],[5.9,5.34],[5.4,11.89]],"id":52671542}],"con":true,"img":false}]}
{"op":"mcm","clk":"11450153711","pt":1717318613456,"mc":[{"id":"1.229554913","rc":[{"atb":[[1.03,120.15]],"id":52237627},{"atb":[[1.03,155.09]],"id":52671562},{"atb":[[1.03,86.91]],"id":52671564},{"atb":[[1.04,84.36]],"id":52237621},{"atb":[[1.02,101.4]],"id":52671561},{"atb":[[1.03,95.44]],"id":52671560},{"atb":[[1.02,69.87]],"id":52237612},{"atb":[[1.03,107.37]],"id":52671552},{"atb":[[1.04,75.84]],"id":52671547},{"atb":[[1.04,161.9]],"id":52237617},{"atb":[[1.04,105.66]],"id":52671549},{"atb":[[1.03,79.25]],"id":52671543},{"atb":[[1.03,103.11]],"id":52671542},{"atb":[[1.03,76.69]],"id":52671545},{"atb":[[1.03,79.25]],"id":52237634}],"con":true,"img":false}]}
{"op":"mcm","clk":"11450159934","pt":1717318674446,"mc":[{"id":"1.229554913","rc":[{"atb":[[65,0],[36,0],[46,0],[28,0]],"id":52671543}],"con":true,"img":false}]}
{"op":"mcm","clk":"11450159996","pt":1717318675125,"mc":[{"id":"1.229554913","rc":[{"atb":[[34,2.38],[44,1.22],[27,4.02],[60,0.44]],"id":52671543}],"con":true,"img":false}]}
{"op":"mcm","clk":"11450160114","pt":1717318676204,"mc":[{"id":"1.229554913","rc":[{"atb":[[34,0],[44,0],[27,0],[60,0]],"id":52671543}],"con":true,"img":false}]}
{"op":"mcm","clk":"11450160180","pt":1717318676923,"mc":[{"id":"1.229554913","rc":[{"atb":[[65,0.41],[36,2.24],[46,1.16],[28,3.88]],"id":52671543}],"con":true,"img":false}]}
{"op":"mcm","clk":"11450171413","pt":1717318799880,"mc":[{"id":"1.229554913","rc":[{"atb":[[5.8,0],[7.6,15.15]],"id":52237627},{"atb":[[260,0],[160,0]],"id":52671562},{"atb":[[7.8,14.71],[5.9,0]],"id":52671564},{"atb":[[65,0],[36,0]],"id":52237621},{"atb":[[9.8,0],[7.8,0]],"id":52671561},{"atb":[[3.6,0],[3.1,0]],"id":52671560},{"atb":[[2.82,0],[2.62,0]],"id":52237612},{"atb":[[70,0],[38,0]],"id":52671552},{"atb":[[260,0],[160,0]],"id":52671547},{"atb":[[5.8,0],[7.6,15.15]],"id":52237617},{"atb":[[7.8,0],[5.9,0]],"id":52671549},{"atb":[[18.5,0],[13.5,0]],"id":52671543},{"atb":[[3.6,0],[3.1,0]],"id":52671542},{"atb":[[2.64,0],[2.84,0]],"id":52671545},{"atb":[[4.4,0],[5.4,0]],"id":52237634}],"con":true,"img":false}]}
{"op":"mcm","clk":"11450172943","pt":1717318814293,"mc":[{"id":"1.229554913","rc":[{"atb":[[270,0],[170,0],[220,0],[120,2]],"id":52671562},{"atb":[[270,0],[170,0],[220,0],[120,2]],"id":52671547}],"con":true,"img":false}]}
{"op":"mcm","clk":"11450172966","pt":1717318814503,"mc":[{"id":"1.229554913","rc":[{"atb":[[16.5,6.45],[120,0]],"id":52671562},{"atb":[[16.5,6.45],[120,0]],"id":52671547}],"con":true,"img":false}]}
{"op":"mcm","clk":"11450173043","pt":1717318815184,"mc":[{"id":"1.229554913","rc":[{"atb":[[130,0.81],[280,0.09],[180,0.44],[230,0.23]],"id":52671562},{"atb":[[130,0.81],[280,0.09],[180,0.44],[230,0.23]],"id":52671547}],"con":true,"img":false}]}
{"op":"mcm","clk":"11450173054","pt":1717318815294,"mc":[{"id":"1.229554913","rc":[{"atb":[[16.5,0]],"id":52671562},{"atb":[[130,2.81]],"id":52671547}],"con":true,"img":false}]}
{"op":"mcm","clk":"11450173067","pt":1717318815388,"mc":[{"id":"1.229554913","rc":[{"atb":[[130,2.81]],"id":52671562},{"atb":[[16.5,0]],"id":52671547}],"con":true,"img":false}]}
{"op":"mcm","clk":"11450174178","pt":1717318827324,"mc":[{"id":"1.229554913","rc":[{"atb":[[5.8,50.81],[7.6,30.98]],"id":52237627},{"atb":[[260,0.4],[160,1.53]],"id":52671562},{"atb":[[7.8,30.08],[5.9,49.77]],"id":52671564},{"atb":[[65,1.63],[36,6.96]],"id":52237621},{"atb":[[9.8,11.87],[7.8,35.86]],"id":52671561},{"atb":[[70,1.51],[38,6.59]],"id":52671552},{"atb":[[7.8,15.37],[5.9,49.77]],"id":52671549},{"atb":[[4.4,71.73],[5.4,23.75]],"id":52237634}],"con":true,"img":false}]}
{"op":"mcm","clk":"11450174189","pt":1717318827382,"mc":[{"id":"1.229554913","rc":[{"atb":[[3.6,40.2],[3.1,116.14]],"id":52671560},{"atb":[[2.82,57.43],[2.62,150.55]],"id":52237612},{"atb":[[260,0.4],[160,1.53]],"id":52671547},{"atb":[[5.8,50.81],[7.6,30.98]],"id":52237617},{"atb":[[18.5,5.97],[13.5,19.51]],"id":52671543},{"atb":[[3.6,40.2],[3.1,116.14]],"id":52671542},{"atb":[[2.64,148.72],[2.84,56.81]],"id":52671545}],"con":true,"img":false}]}
{"op":"mcm","clk":"11450175714","pt":1717318844497,"mc":[{"id":"1.229554913","rc":[{"atb":[[130,2],[280,0],[180,0],[230,0]],"id":52671562},{"atb":[[130,2],[280,0],[180,0],[230,0]],"id":52671547},{"atb":[[65,0],[36,0],[46,0],[28,0]],"id":52671543}],"con":true,"img":false}]}
{"op":"mcm","clk":"11450175775","pt":1717318845225,"mc":[{"id":"1.229554913","rc":[{"atb":[[130,2.81],[280,0.09],[180,0.44],[230,0.23]],"id":52671562},{"atb":[[130,2.81],[280,0.09],[180,0.44],[230,0.23]],"id":52671547},{"atb":[[65,0.41],[36,2.24],[46,1.16],[28,3.88]],"id":52671543}],"con":true,"img":false}]}
{"op":"mcm","clk":"11450175838","pt":1717318845944,"mc":[{"id":"1.229554913","rc":[{"atb":[[130,2],[280,0],[180,0],[230,0]],"id":52671562},{"atb":[[130,2],[280,0],[180,0],[230,0]],"id":52671547},{"atb":[[65,0],[36,0],[46,0],[28,0]],"id":52671543}],"con":true,"img":false}]}
{"op":"mcm","clk":"11450175904","pt":1717318846613,"mc":[{"id":"1.229554913","rc":[{"atb":[[270,0.1],[170,0.47],[220,0.24],[120,0.88]],"id":52671562},{"atb":[[270,0.1],[170,0.47],[220,0.24],[120,0.88]],"id":52671547},{"atb":[[34,2.38],[44,1.22],[27,4.02],[60,0.44]],"id":52671543}],"con":true,"img":false}]}
{"op":"mcm","clk":"11450176203","pt":1717318849921,"mc":[{"id":"1.229554913","rc":[{"atb":[[120,0]],"id":52671547}],"con":true,"img":false}]}
{"op":"mcm","clk":"11450176293","pt":1717318850946,"mc":[{"id":"1.229554913","rc":[{"atb":[[130,2.81]],"id":52671547}],"con":true,"img":false}]}
{"op":"mcm","clk":"11450195579","pt":1717319052258,"mc":[{"id":"1.229554913","rc":[{"atb":[[130,2]],"id":52671547},{"atb":[[4.1,0],[3.8,0],[3.55,0],[3.3,0]],"id":52671545}],"con":true,"img":false}]}
{"op":"mcm","clk":"11450195694","pt":1717319052981,"mc":[{"id":"1.229554913","rc":[{"atb":[[3.6,30.18],[3.85,18.36],[3.35,44.53],[4.2,8.18]],"id":52671545}],"con":true,"img":false}]}
{"op":"mcm","clk":"11450208077","pt":1717319180269,"mc":[{"id":"1.229554913","rc":[{"atb":[[4.5,0],[5,0],[5.5,0],[6,0]],"id":52671560}],"con":true,"img":false}]}
{"op":"mcm","clk":"11450208148","pt":1717319180990,"mc":[{"id":"1.229554913","rc":[{"atb":[[4.9,20.12],[4.4,30.77],[5.9,5.34],[5.4,11.89]],"id":52671560}],"con":true,"img":false}]}
{"op":"mcm","clk":"11450208375","pt":1717319182926,"mc":[{"id":"1.229554913","rc":[{"atb":[[5.8,0],[7.6,15.15]],"id":52237627},{"atb":[[260,0],[160,0]],"id":52671562},{"atb":[[7.8,14.71],[5.9,0]],"id":52671564},{"atb":[[65,0],[36,0]],"id":52237621},{"atb":[[9.8,0],[7.8,0]],"id":52671561},{"atb":[[3.6,0],[3.1,0]],"id":52671560},{"atb":[[2.82,0],[2.62,0]],"id":52237612},{"atb":[[70,0],[38,0]],"id":52671552},{"atb":[[260,0],[160,0]],"id":52671547},{"atb":[[5.8,0],[7.6,15.15]],"id":52237617},{"atb":[[7.8,0],[5.9,0]],"id":52671549},{"atb":[[18.5,0],[13.5,0]],"id":52671543},{"atb":[[3.6,0],[3.1,0]],"id":52671542},{"atb":[[2.64,0],[2.84,0]],"id":52671545},{"atb":[[4.4,0],[5.4,0]],"id":52237634}],"con":true,"img":false}]}
{"op":"mcm","clk":"11450208434","pt":1717319183393,"mc":[{"id":"1.229554913","rc":[{"atb":[[120,0.88]],"id":52671547}],"con":true,"img":false}]}
{"op":"mcm","clk":"11450211546","pt":1717319214150,"mc":[{"id":"1.229554913","rc":[{"atb":[[5.8,50.81],[7.6,30.98]],"id":52237627},{"atb":[[260,0.4],[160,1.53]],"id":52671562},{"atb":[[7.8,30.08],[5.9,49.77]],"id":52671564},{"atb":[[65,1.63],[36,6.96]],"id":52237621},{"atb":[[9.8,11.87],[7.8,35.86]],"id":52671561},{"atb":[[3.6,40.2],[3.1,116.14]],"id":52671560},{"atb":[[2.82,57.43],[2.62,150.55]],"id":52237612},{"atb":[[70,1.51],[38,6.59]],"id":52671552},{"atb":[[260,0.4],[160,1.53]],"id":52671547},{"atb":[[5.8,50.81],[7.6,30.98]],"id":52237617},{"atb":[[7.8,15.37],[5.9,49.77]],"id":52671549},{"atb":[[18.5,5.97],[13.5,19.51]],"id":52671543},{"atb":[[3.6,40.2],[3.1,116.14]],"id":52671542},{"atb":[[2.64,148.72],[2.84,56.81]],"id":52671545},{"atb":[[4.4,71.73],[5.4,23.75]],"id":52237634}],"con":true,"img":false}]}
{"op":"mcm","clk":"11450216518","pt":1717319261888,"mc":[{"id":"1.229554913","rc":[{"atb":[[3.6,0],[3.85,0],[3.1,0],[3.35,0]],"id":52237612},{"atb":[[3.6,0],[3.85,0],[3.35,0],[4.2,0]],"id":52671545}],"con":true,"img":false}]}
{"op":"mcm","clk":"11450216591","pt":1717319262688,"mc":[{"id":"1.229554913","rc":[{"atb":[[3.8,9.34],[3.55,20.52],[3.3,34.12],[3.05,51.04]],"id":52237612},{"atb":[[4.1,8.44],[3.8,18.68],[3.55,30.77],[3.3,45.5]],"id":52671545}],"con":true,"img":false}]}
{"op":"mcm","clk":"11450218374","pt":1717319280633,"mc":[{"id":"1.229554913","rc":[{"atb":[[140,3.64],[120,3.76]],"id":52671562},{"atl":[[630,3.15],[650,4.35]],"id":52671562},{"atb":[[14.5,12.17],[15.5,4.44]],"id":52671561},{"atl":[[48,2.99],[55,2.89]],"id":52671561},{"atb":[[4.8,3.58],[5,4.18]],"id":52671560},{"atl":[[13,3.89],[14,4.47]],"id":52671560},{"atb":[[95,3.56],[110,3.65]],"id":52671552},{"atl":[[390,4.34],[410,4.45]],"id":52671552},{"atb":[[8.2,4.33],[7.8,3.64]],"id":52237617},{"atl":[[32,2.84],[29,2.86]],"id":52237617},{"atl":[[32,3.2],[36,4.46]],"id":52671549},{"atl":[[100,3.44],[120,4.5]],"id":52671543},{"atb":[[3.55,36.93],[3.65,5.92]],"id":52671545},{"atl":[[9.2,3.25],[8.8,2.63]],"id":52671545}],"con":true,"img":false}]}
{"op":"mcm","clk":"11450218385","pt":1717319280723,"mc":[{"id":"1.229554913","rc":[{"atb":[[10.5,4.35],[9.8,12.92]],"id":52237627},{"atl":[[32,3.77],[29,3.75]],"id":52237627},{"atb":[[10.5,2.69],[11.5,3.65]],"id":52671564},{"atl":[[32,4.45],[36,3.44]],"id":52671564},{"atb":[[90,4.61],[100,4.35]],"id":52237621},{"atl":[[360,4.49],[380,3.45]],"id":52237621},{"atl":[[22,4.76],[220,0]],"id":52671560},{"atb":[[3.4,6.53],[3.3,40.94]],"id":52237612},{"atl":[[6.2,3.64],[6.6,4.46]],"id":52237612},{"atb":[[140,4.12],[120,5.16]],"id":52671547},{"atl":[[630,3.89],[650,3.82]],"id":52671547},{"atl":[[70,2],[440,0]],"id":52237617},{"atl":[[75,2],[450,0]],"id":52671549},{"atb":[[4.8,4.13],[5,4.37]],"id":52671542},{"atl":[[9.6,3.43],[9.2,4.57]],"id":52671542},{"atl":[[100,0],[15,5.88]],"id":52671545},{"atb":[[7.2,4.35],[7.6,4.61]],"id":52237634},{"atl":[[19.5,4.03],[21,4.18]],"id":52237634}],"con":true,"img":false}]}
{"op":"mcm","clk":"11450218399","pt":1717319280827,"mc":[{"id":"1.229554913","rc":[{"atl":[[70,2],[440,0]],"id":52237627},{"atl":[[75,2],[450,0]],"id":52671564},{"atl":[[90,0],[14,7.69]],"id":52237612},{"atl":[[22,4.76],[220,0]],"id":52671542},{"atl":[[46,2.22]],"id":52237634}],"con":true,"img":false}]}
{"op":"mcm","clk":"11450218407","pt":1717319280930,"mc":[{"id":"1.229554913","rc":[{"atl":[[380,0]],"id":52237634}],"con":true,"img":false}]}
{"op":"mcm","clk":"11450218419","pt":1717319281039,"mc":[{"id":"1.229554913","rc":[{"atb":[[10,3.13],[11,10.58]],"id":52671564},{"atb":[[3.45,6.4],[3.35,6.68]],"id":52237612},{"atb":[[3.45,6.4]],"id":52671545}],"con":true,"img":false}]}
{"op":"mcm","clk":"11450218505","pt":1717319281923,"mc":[{"id":"1.229554913","rc":[{"atb":[[11.5,0]],"id":52671564},{"atb":[[3.45,0]],"id":52237612},{"atb":[[120,4.28]],"id":52671547},{"atb":[[3.65,0]],"id":52671545}],"con":true,"img":false}]}
{"op":"mcm","clk":"11450218874","pt":1717319285713,"mc":[{"id":"1.229554913","rc":[{"atb":[[10,0],[11,7.85],[11.5,3.66]],"id":52671564},{"atb":[[3.3,34.12]],"id":52237612},{"atb":[[3.6,6.03]],"id":52671545}],"con":true,"img":false}]}
{"op":"mcm","clk":"11450218882","pt":1717319285816,"mc":[{"id":"1.229554913","rc":[{"atb":[[3.55,30.77]],"id":52671545}],"con":true,"img":false}]}
{"op":"mcm","clk":"11450219118","pt":1717319288246,"mc":[{"id":"1.229554913","rc":[{"atb":[[11,11.87],[11.5,0]],"id":52671564},{"atb":[[3.6,0],[3.55,36.93]],"id":52671545}],"con":true,"img":false}]}
{"op":"mcm","clk":"11450234161","pt":1717319450084,"mc":[{"id":"1.229554913","rc":[{"atb":[[3.8,0],[3.55,0],[3.3,0],[3.05,0]],"id":52237612}],"con":true,"img":false}]}
{"op":"mcm","clk":"11450234242","pt":1717319450895,"mc":[{"id":"1.229554913","rc":[{"atb":[[3.6,20.12],[3.85,9.18],[3.1,49.83],[3.35,40.08]],"id":52237612}],"con":true,"img":false}]}
{"op":"mcm","clk":"11450235129","pt":1717319459784,"mc":[{"id":"1.229554913","rc":[{"atb":[[11,7.85],[11.5,3.58]],"id":52671564},{"atb":[[3.6,6.03],[3.55,30.77]],"id":52671545}],"con":true,"img":false}]}
{"op":"mcm","clk":"11450242265","pt":1717319538034,"mc":[{"id":"1.229554913","rc":[{"atb":[[3.6,0],[3.85,0],[3.1,0],[3.35,6.68]],"id":52237612}],"con":true,"img":false}]}
{"op":"mcm","clk":"11450242337","pt":1717319538709,"mc":[{"id":"1.229554913","rc":[{"atb":[[3.8,9.34],[3.55,20.52],[3.3,34.12],[3.05,51.04]],"id":52237612}],"con":true,"img":false}]}
{"op":"mcm","clk":"11450244642","pt":1717319563302,"mc":[{"id":"1.229554913","rc":[{"atb":[[85,4.11]],"id":52237621}],"con":true,"img":false}]}
{"op":"mcm","clk":"11450244654","pt":1717319563407,"mc":[{"id":"1.229554913","rc":[{"atb":[[100,0]],"id":52237621},{"atb":[[110,0]],"id":52671552},{"atb":[[140,0]],"id":52671547}],"con":true,"img":false}]}
{"op":"mcm","clk":"11450244799","pt":1717319564961,"mc":[{"id":"1.229554913","rc":[{"atb":[[110,3.2]],"id":52671552}],"con":true,"img":false}]}
{"op":"mcm","clk":"11450244810","pt":1717319565068,"mc":[{"id":"1.229554913","rc":[{"atb":[[90,0],[100,3.48]],"id":52237621},{"atb":[[140,4.44]],"id":52671547}],"con":true,"img":false}]}
{"op":"mcm","clk":"11450246436","pt":1717319582743,"mc":[{"id":"1.229554913","rc":[{"atb":[[5.8,0],[7.6,15.15]],"id":52237627},{"atb":[[260,0],[160,0]],"id":52671562},{"atb":[[7.8,14.71],[5.9,0]],"id":52671564},{"atb":[[65,0],[36,0]],"id":52237621},{"atb":[[9.8,0],[7.8,0]],"id":52671561},{"atb":[[3.6,0],[3.1,0]],"id":52671560},{"atb":[[2.82,0],[2.62,0]],"id":52237612},{"atb":[[70,0],[38,0]],"id":52671552},{"atb":[[260,0],[160,0]],"id":52671547},{"atb":[[5.8,0],[7.6,15.15]],"id":52237617},{"atb":[[7.8,0],[5.9,0]],"id":52671549},{"atb":[[18.5,0],[13.5,0]],"id":52671543},{"atb":[[3.6,0],[3.1,0]],"id":52671542},{"atb":[[2.64,0],[2.84,0]],"id":52671545},{"atb":[[4.4,0],[5.4,0]],"id":52237634}],"con":true,"img":false}]}
{"op":"mcm","clk":"11450246500","pt":1717319583210,"mc":[{"id":"1.229554913","rc":[{"atb":[[120,5.16]],"id":52671547}],"con":true,"img":false}]}
{"op":"mcm","clk":"11450246734","pt":1717319585608,"mc":[{"id":"1.229554913","rc":[{"atb":[[1.54,29.06],[1.52,30.18]],"id":52671549},{"atb":[[1.54,29.06],[1.52,30.18]],"id":52671543}],"con":true,"img":false}]}
{"op":"mcm","clk":"11450247605","pt":1717319595636,"mc":[{"id":"1.229554913","rc":[{"atb":[[3.6,40.2],[3.1,116.14]],"id":52671560},{"atb":[[2.82,57.43],[2.62,150.55]],"id":52237612},{"atb":[[260,0.4],[160,1.53]],"id":52671547},{"atb":[[5.8,50.81],[7.6,30.98]],"id":52237617},{"atb":[[18.5,5.97],[13.5,19.51]],"id":52671543},{"atb":[[3.6,40.2],[3.1,116.14]],"id":52671542},{"atb":[[2.64,148.72],[2.84,56.81]],"id":52671545}],"con":true,"img":false}]}
{"op":"mcm","clk":"11450247627","pt":1717319595842,"mc":[{"id":"1.229554913","rc":[{"atb":[[5.8,50.81],[7.6,30.98]],"id":52237627},{"atb":[[260,0.4],[160,1.53]],"id":52671562},{"atb":[[7.8,30.08],[5.9,49.77]],"id":52671564},{"atb":[[65,1.63],[36,6.96]],"id":52237621},{"atb":[[9.8,11.87],[7.8,35.86]],"id":52671561},{"atb":[[70,1.51],[38,6.59]],"id":52671552},{"atb":[[7.8,15.37],[5.9,49.77]],"id":52671549},{"atb":[[4.4,71.73],[5.4,23.75]],"id":52237634}],"con":true,"img":false}]}
{"op":"mcm","clk":"11450271738","pt":1717319871875,"mc":[{"id":"1.229554913","rc":[{"atb":[[11,10.99],[11.5,0]],"id":52671564},{"atb":[[120,4.28]],"id":52671547},{"atb":[[3.6,0],[3.55,36.93]],"id":52671545}],"con":true,"img":false}]}
{"op":"mcm","clk":"11450271759","pt":1717319872087,"mc":[{"id":"1.229554913","rc":[{"atb":[[17,0],[19.5,0],[24,0],[14.5,4.42]],"id":52671561},{"atl":[[6.4,3.4],[6.2,0]],"id":52237612},{"atb":[[9.2,0],[10.5,0],[13,0],[15.5,0]],"id":52671549},{"atl":[[8.6,3.59],[8.8,0]],"id":52671545},{"atb":[[6.4,0],[7.4,2.98],[7.6,0],[8.4,0],[9.4,0]],"id":52237634}],"con":true,"img":false}]}
{"op":"mcm","clk":"11450271774","pt":1717319872293,"mc":[{"id":"1.229554913","rc":[{"atb":[[10,0],[12,9.09]],"id":52671561}],"con":true,"img":false}]}
{"op":"mcm","clk":"11450271822","pt":1717319872766,"mc":[{"id":"1.229554913","rc":[{"atb":[[12,4.76],[9.8,8.92],[8.8,13.41],[14.5,1.94]],"id":52671549}],"con":true,"img":false}]}
{"op":"mcm","clk":"11450271829","pt":1717319872869,"mc":[{"id":"1.229554913","rc":[{"atb":[[16.5,5.06],[19,2.91],[23,1.19],[14,8.05]],"id":52671561},{"atb":[[6.4,19.38],[7.4,15.25],[8.4,7.07],[9.4,3.11]],"id":52237634}],"con":true,"img":false}]}
{"op":"mcm","clk":"11450271888","pt":1717319873587,"mc":[{"id":"1.229554913","rc":[{"atb":[[11,7.85],[11.5,4.51]],"id":52671564},{"atb":[[3.6,6.03],[3.55,30.77]],"id":52671545}],"con":true,"img":false}]}
{"op":"mcm","clk":"11450271989","pt":1717319874773,"mc":[{"id":"1.229554913","rc":[{"atb":[[3.55,36.93]],"id":52671545}],"con":true,"img":false}]}
{"op":"mcm","clk":"11450271993","pt":1717319874876,"mc":[{"id":"1.229554913","rc":[{"atb":[[11,11.92],[11.5,0]],"id":52671564},{"atb":[[3.6,0]],"id":52671545}],"con":true,"img":false}]}
{"op":"mcm","clk":"11450272108","pt":1717319876375,"mc":[{"id":"1.229554913","rc":[{"atb":[[8.8,12.82]],"id":52671543}],"con":true,"img":false}]}
{"op":"mcm","clk":"11450272117","pt":1717319876474,"mc":[{"id":"1.229554913","rc":[{"atb":[[1.44,0],[8.2,13.89]],"id":52671549},{"atb":[[1.44,0]],"id":52671543},{"atb":[[2,0]],"id":52671545}],"con":true,"img":false}]}
{"op":"mcm","clk":"11450272134","pt":1717319876685,"mc":[{"id":"1.229554913","rc":[{"atb":[[8.6,3.92]],"id":52671549}],"con":true,"img":false}]}
{"op":"mcm","clk":"11450272144","pt":1717319876783,"mc":[{"id":"1.229554913","rc":[{"atb":[[11,7.85],[11.5,4.23]],"id":52671564},{"atb":[[1.54,0]],"id":52671549},{"atb":[[3.6,6.03],[3.55,30.77]],"id":52671545}],"con":true,"img":false}]}
{"op":"mcm","clk":"11450272327","pt":1717319879176,"mc":[{"id":"1.229554913","rc":[{"atb":[[11,11.92],[11.5,0]],"id":52671564},{"atb":[[3.6,0],[3.55,36.93]],"id":52671545}],"con":true,"img":false}]}
{"op":"mcm","clk":"11450272934","pt":1717319886716,"mc":[{"id":"1.229554913","rc":[{"atb":[[8.2,17.81]],"id":52671549}],"con":true,"img":false}]}
{"op":"mcm","clk":"11450273093","pt":1717319888960,"mc":[{"id":"1.229554913","rc":[{"atb":[[16.5,0],[19,0],[23,0],[14,0]],"id":52671561},{"atl":[[6.4,0],[6.2,2.73]],"id":52237612},{"atl":[[8.6,0],[8.8,3.42]],"id":52671545},{"atb":[[7.6,4.44]],"id":52237634}],"con":true,"img":false}]}
{"op":"mcm","clk":"11450273104","pt":1717319889015,"mc":[{"id":"1.229554913","rc":[{"atb":[[12,0],[9.8,0],[8.8,0],[14.5,0],[1.52,0]],"id":52671549},{"atb":[[7.4,12.26]],"id":52237634}],"con":true,"img":false}]}
{"op":"mcm","clk":"11450273108","pt":1717319889112,"mc":[{"id":"1.229554913","rc":[{"atb":[[8,14.29]],"id":52671549}],"con":true,"img":false}]}
{"op":"mcm","clk":"11450273121","pt":1717319889219,"mc":[{"id":"1.229554913","rc":[{"atb":[[8.2,3.92]],"id":52671549}],"con":true,"img":false}]}
{"op":"mcm","clk":"11450273145","pt":1717319889589,"mc":[{"id":"1.229554913","rc":[{"atb":[[17,4.9],[19.5,2.83],[24,1.14],[14.5,12.17]],"id":52671561}],"con":true,"img":false}]}
{"op":"mcm","clk":"11450273156","pt":1717319889691,"mc":[{"id":"1.229554913","rc":[{"atb":[[9.2,12.76],[10.5,8.26],[13,4.36],[15.5,1.81]],"id":52671549}],"con":true,"img":false}]}
{"op":"mcm","clk":"11450276257","pt":1717319929706,"mc":[{"id":"1.229554913","rc":[{"atb":[[5.8,0],[7.6,15.15]],"id":52237627},{"atb":[[260,0],[160,0]],"id":52671562},{"atb":[[7.8,14.71],[5.9,0]],"id":52671564},{"atb":[[65,0],[36,0]],"id":52237621},{"atb":[[9.8,0],[7.8,0]],"id":52671561},{"atb":[[3.6,0],[3.1,0]],"id":52671560},{"atb":[[2.82,0],[2.62,0]],"id":52237612},{"atb":[[70,0],[38,0]],"id":52671552},{"atb":[[260,0],[160,0]],"id":52671547},{"atb":[[5.8,0],[7.6,15.15]],"id":52237617},{"atb":[[7.8,0],[5.9,0]],"id":52671549},{"atb":[[18.5,0],[13.5,0]],"id":52671543},{"atb":[[3.6,0],[3.1,0]],"id":52671542},{"atb":[[2.64,0],[2.84,0]],"id":52671545},{"atb":[[4.4,0],[5.4,0]],"id":52237634}],"con":true,"img":false}]}
{"op":"mcm","clk":"11450276300","pt":1717319930174,"mc":[{"id":"1.229554913","rc":[{"atb":[[130,2.81]],"id":52671547}],"con":true,"img":false}]}
{"op":"mcm","clk":"11450276314","pt":1717319930379,"mc":[{"id":"1.229554913","rc":[{"atb":[[8.6,4.56],[1.54,0]],"id":52671543}],"con":true,"img":false}]}
{"op":"mcm","clk":"11450276990","pt":1717319939602,"mc":[{"id":"1.229554913","rc":[{"atb":[[5.8,50.81],[7.6,30.98]],"id":52237627},{"atb":[[260,0.4],[160,1.53]],"id":52671562},{"atb":[[7.8,30.08],[5.9,49.77]],"id":52671564},{"atb":[[65,1.63],[36,6.96]],"id":52237621},{"atb":[[9.8,11.87],[7.8,35.86]],"id":52671561},{"atb":[[3.6,40.2],[3.1,116.14]],"id":52671560},{"atb":[[2.82,57.43],[2.62,150.55]],"id":52237612},{"atb":[[70,1.51],[38,6.59]],"id":52671552},{"atb":[[260,0.4],[160,1.53]],"id":52671547},{"atb":[[5.8,50.81],[7.6,30.98]],"id":52237617},{"atb":[[7.8,15.37],[5.9,49.77]],"id":52671549},{"atb":[[18.5,5.97],[13.5,19.51]],"id":52671543},{"atb":[[3.6,40.2],[3.1,116.14]],"id":52671542},{"atb":[[2.64,148.72],[2.84,56.81]],"id":52671545},{"atb":[[4.4,71.73],[5.4,23.75]],"id":52237634}],"con":true,"img":false}]}
{"op":"mcm","clk":"11450277954","pt":1717319950710,"mc":[{"id":"1.229554913","rc":[{"atl":[[6.4,3.94],[6.2,0]],"id":52237612},{"atl":[[9.2,0],[9.4,3.29]],"id":52671542}],"con":true,"img":false}]}
{"op":"mcm","clk":"11450279798","pt":1717319974338,"mc":[{"id":"1.229554913","rc":[{"atb":[[11,7.85],[11.5,2.76]],"id":52671564},{"atb":[[130,2]],"id":52671547},{"atb":[[3.6,6.03],[3.55,30.77]],"id":52671545}],"con":true,"img":false}]}
{"op":"mcm","clk":"11450280089","pt":1717319977859,"mc":[{"id":"1.229554913","rc":[{"atb":[[11,12.06]],"id":52671564},{"atb":[[3.55,36.93]],"id":52671545}],"con":true,"img":false}]}
{"op":"mcm","clk":"11450280095","pt":1717319977955,"mc":[{"id":"1.229554913","rc":[{"atb":[[11.5,0]],"id":52671564},{"atb":[[3.6,0]],"id":52671545}],"con":true,"img":false}]}
{"op":"mcm","clk":"11450285648","pt":1717320052046,"mc":[{"id":"1.229554913","rc":[{"atb":[[3.45,6.4]],"id":52237612}],"con":true,"img":false}]}
{"op":"mcm","clk":"11450285657","pt":1717320052155,"mc":[{"id":"1.229554913","rc":[{"atb":[[3.4,0]],"id":52237612}],"con":true,"img":false}]}
{"op":"mcm","clk":"11450285783","pt":1717320054474,"mc":[{"id":"1.229554913","rc":[{"atb":[[3.45,0],[3.4,6.53]],"id":52237612}],"con":true,"img":false}]}
{"op":"mcm","clk":"11450287377","pt":1717320078596,"mc":[{"id":"1.229554913","rc":[{"atb":[[3.45,6.4]],"id":52237612}],"con":true,"img":false}]}
{"op":"mcm","clk":"11450287385","pt":1717320078698,"mc":[{"id":"1.229554913","rc":[{"atb":[[3.4,0]],"id":52237612}],"con":true,"img":false}]}
{"op":"mcm","clk":"11450287651","pt":1717320083198,"mc":[{"id":"1.229554913","rc":[{"atb":[[3.45,0],[3.4,6.53]],"id":52237612}],"con":true,"img":false}]}
{"op":"mcm","clk":"11450287742","pt":1717320084796,"mc":[{"id":"1.229554913","rc":[{"atb":[[3.45,6.4],[3.4,0]],"id":52237612}],"con":true,"img":false}]}
{"op":"mcm","clk":"11450288012","pt":1717320088410,"mc":[{"id":"1.229554913","rc":[{"atb":[[12,0],[9.8,4],[8.8,0],[14.5,0]],"id":52237627},{"atb":[[15,3.49],[15.5,0]],"id":52671561},{"atb":[[8.2,0],[8.4,3.13]],"id":52237617},{"atl":[[8.6,2.73],[8.8,0]],"id":52671545}],"con":true,"img":false}]}
{"op":"mcm","clk":"11450288018","pt":1717320088505,"mc":[{"id":"1.229554913","rc":[{"atb":[[17,0],[19.5,0],[24,0],[14.5,4.42]],"id":52671561},{"atb":[[6.4,0],[7.4,0],[8.4,0],[9.4,0]],"id":52237634}],"con":true,"img":false}]}
{"op":"mcm","clk":"11450288028","pt":1717320088614,"mc":[{"id":"1.229554913","rc":[{"atb":[[9.2,0],[10.5,0],[13,0],[15.5,0]],"id":52671549}],"con":true,"img":false}]}
{"op":"mcm","clk":"11450288033","pt":1717320088714,"mc":[{"id":"1.229554913","rc":[{"atb":[[7.8,30.08]],"id":52671549}],"con":true,"img":false}]}
{"op":"mcm","clk":"11450288039","pt":1717320088769,"mc":[{"id":"1.229554913","rc":[{"atb":[[8,0]],"id":52671549}],"con":true,"img":false}]}
{"op":"mcm","clk":"11450288059","pt":1717320089082,"mc":[{"id":"1.229554913","rc":[{"atb":[[9,13.08],[10,8.72],[12.5,4.55],[15,1.87]],"id":52237627}],"con":true,"img":false}]}
{"op":"mcm","clk":"11450288065","pt":1717320089181,"mc":[{"id":"1.229554913","rc":[{"atb":[[16.5,5.06],[19,2.91],[23,1.19],[14,8.05]],"id":52671561},{"atb":[[9.6,3.04],[8.6,6.89],[7.6,16.34],[6.6,18.68]],"id":52237634}],"con":true,"img":false}]}
{"op":"mcm","clk":"11450288073","pt":1717320089286,"mc":[{"id":"1.229554913","rc":[{"atb":[[12,4.76],[9.8,8.92],[8.8,13.41],[14.5,1.94]],"id":52671549}],"con":true,"img":false}]}
{"op":"mcm","clk":"11450288681","pt":1717320098915,"mc":[{"id":"1.229554913","rc":[{"atl":[[29,0]],"id":52237627},{"atl":[[630,0],[620,4.06]],"id":52671562},{"atl":[[380,3.07],[390,0]],"id":52671552},{"atl":[[620,3.51]],"id":52671547},{"atl":[[29,0],[30,3.19]],"id":52237617},{"atl":[[19.5,0],[20,2.66]],"id":52237634}],"con":true,"img":false}]}
{"op":"mcm","clk":"11450288692","pt":1717320099015,"mc":[{"id":"1.229554913","rc":[{"atb":[[9,0],[10,0],[12.5,0],[15,0]],"id":52237627},{"atl":[[30,2.87]],"id":52237627},{"atb":[[15,0],[15.5,4.13]],"id":52671561},{"atl":[[6.2,2.84]],"id":52237612},{"atl":[[630,0]],"id":52671547},{"atb":[[8.2,4.69],[8.4,0]],"id":52237617},{"atl":[[8.6,0],[8.8,4.6]],"id":52671545},{"atb":[[9.6,0],[8.6,0],[7.6,4.44],[6.6,0]],"id":52237634}],"con":true,"img":false}]}
{"op":"mcm","clk":"11450288701","pt":1717320099117,"mc":[{"id":"1.229554913","rc":[{"atl":[[6.4,0]],"id":52237612}],"con":true,"img":false}]}
{"op":"mcm","clk":"11450288736","pt":1717320099690,"mc":[{"id":"1.229554913","rc":[{"atb":[[12,4.76],[9.8,12.92],[8.8,13.41],[14.5,1.94]],"id":52237627},{"atb":[[6.4,19.38],[7.4,12.26],[8.4,7.07],[9.4,3.11]],"id":52237634}],"con":true,"img":false}]}
{"op":"mcm","clk":"11450289458","pt":1717320111113,"mc":[{"id":"1.229554913","rc":[{"atl":[[29,3.34],[30,0]],"id":52237627},{"atl":[[620,0],[630,2.96]],"id":52671562},{"atb":[[3.45,0],[3.4,6.53]],"id":52237612},{"atl":[[6.4,3.3],[6.2,0]],"id":52237612},{"atl":[[380,0],[390,3.66]],"id":52671552},{"atl":[[620,0],[630,3.37]],"id":52671547},{"atl":[[29,3.55],[30,0]],"id":52237617},{"atl":[[19.5,2.78],[20,0]],"id":52237634}],"con":true,"img":false}]}
{"op":"mcm","clk":"11450289465","pt":1717320111210,"mc":[{"id":"1.229554913","rc":[{"atl":[[8.6,4.22],[8.8,0]],"id":52671545},{"atb":[[7.4,15.09],[7.6,0]],"id":52237634}],"con":true,"img":false}]}
{"op":"mcm","clk":"11450289692","pt":1717320114535,"mc":[{"id":"1.229554913","rc":[{"atb":[[5.8,0],[7.6,15.15]],"id":52237627},{"atb":[[260,0],[160,0]],"id":52671562},{"atb":[[7.8,14.71],[5.9,0]],"id":52671564},{"atb":[[65,0],[36,0]],"id":52237621},{"atb":[[9.8,0],[7.8,0]],"id":52671561},{"atb":[[3.6,0],[3.1,0]],"id":52671560},{"atb":[[2.82,0],[2.62,0]],"id":52237612},{"atb":[[70,0],[38,0]],"id":52671552},{"atb":[[260,0],[160,0]],"id":52671547},{"atb":[[5.8,0],[7.6,15.15]],"id":52237617},{"atb":[[7.8,14.71],[5.9,0]],"id":52671549},{"atb":[[18.5,0],[13.5,0]],"id":52671543},{"atb":[[3.6,0],[3.1,0]],"id":52671542},{"atb":[[2.64,0],[2.84,0]],"id":52671545},{"atb":[[4.4,0],[5.4,0]],"id":52237634}],"con":true,"img":false}]}
{"op":"mcm","clk":"11450289722","pt":1717320115003,"mc":[{"id":"1.229554913","rc":[{"atb":[[130,2.81]],"id":52671547}],"con":true,"img":false}]}
{"op":"mcm","clk":"11450289910","pt":1717320117532,"mc":[{"id":"1.229554913","rc":[{"atl":[[29,0],[30,2.95]],"id":52237627},{"atl":[[630,0],[620,4.45]],"id":52671562},{"atb":[[3.45,6.4],[3.4,0]],"id":52237612},{"atl":[[380,2.69],[390,0]],"id":52671552},{"atb":[[130,2]],"id":52671547},{"atl":[[630,0],[620,4.51]],"id":52671547},{"atl":[[29,0],[30,3.58]],"id":52237617},{"atl":[[19.5,0],[20,3.94]],"id":52237634}],"con":true,"img":false}]}
{"op":"mcm","clk":"11450289971","pt":1717320118251,"mc":[{"id":"1.229554913","rc":[{"atb":[[130,2.81]],"id":52671547}],"con":true,"img":false}]}
{"op":"mcm","clk":"11450290170","pt":1717320121150,"mc":[{"id":"1.229554913","rc":[{"atb":[[8.2,3.58]],"id":52671543}],"con":true,"img":false}]}
{"op":"mcm","clk":"11450290273","pt":1717320122461,"mc":[{"id":"1.229554913","rc":[{"atb":[[3.45,0],[3.4,6.53]],"id":52237612},{"atb":[[130,2]],"id":52671547},{"atb":[[1.52,0]],"id":52671543}],"con":true,"img":false}]}
{"op":"mcm","clk":"11450290285","pt":1717320122597,"mc":[{"id":"1.229554913","rc":[{"atb":[[15,2.73]],"id":52671561},{"atb":[[8.2,0],[8.4,4.61]],"id":52237617}],"con":true,"img":false}]}
{"op":"mcm","clk":"11450290291","pt":1717320122664,"mc":[{"id":"1.229554913","rc":[{"atb":[[15.5,0]],"id":52671561},{"atb":[[7.4,12.26],[7.6,3.8]],"id":52237634}],"con":true,"img":false}]}
{"op":"mcm","clk":"11450290333","pt":1717320123134,"mc":[{"id":"1.229554913","rc":[{"atb":[[120,5.16]],"id":52671547}],"con":true,"img":false}]}
{"op":"mcm","clk":"11450290749","pt":1717320129045,"mc":[{"id":"1.229554913","rc":[{"atb":[[15,0],[15.5,4.62]],"id":52671561},{"atb":[[3.45,6.4],[3.4,0]],"id":52237612},{"atl":[[6.4,0]],"id":52237612},{"atb":[[8.2,3.1],[8.4,0]],"id":52237617},{"atl":[[8.6,0],[8.8,4.11]],"id":52671545}],"con":true,"img":false}]}
{"op":"mcm","clk":"11450290766","pt":1717320129241,"mc":[{"id":"1.229554913","rc":[{"atl":[[95,3.91],[100,0]],"id":52671543}],"con":true,"img":false}]}
{"op":"mcm","clk":"11450290825","pt":1717320129869,"mc":[{"id":"1.229554913","rc":[{"atb":[[5.8,50.81],[7.6,30.98]],"id":52237627},{"atb":[[260,0.4],[160,1.53]],"id":52671562},{"atb":[[7.8,30.08],[5.9,49.77]],"id":52671564},{"atb":[[65,1.63],[36,6.96]],"id":52237621},{"atb":[[9.8,11.87],[7.8,35.86]],"id":52671561},{"atb":[[3.6,40.2],[3.1,116.14]],"id":52671560},{"atb":[[2.82,57.43],[2.62,150.55]],"id":52237612},{"atb":[[70,1.51],[38,6.59]],"id":52671552},{"atb":[[260,0.4],[160,1.53]],"id":52671547},{"atb":[[5.8,50.81],[7.6,30.98]],"id":52237617},{"atb":[[7.8,30.08],[5.9,49.77]],"id":52671549},{"atb":[[18.5,5.97],[13.5,19.51]],"id":52671543},{"atb":[[3.6,40.2],[3.1,116.14]],"id":52671542},{"atb":[[2.64,148.72],[2.84,56.81]],"id":52671545},{"atb":[[4.4,71.73],[5.4,23.75]],"id":52237634}],"con":true,"img":false}]}
{"op":"mcm","clk":"11450291176","pt":1717320134880,"mc":[{"id":"1.229554913","rc":[{"atb":[[3.45,0],[3.4,6.53]],"id":52237612}],"con":true,"img":false}]}
{"op":"mcm","clk":"11450291897","pt":1717320144890,"mc":[{"id":"1.229554913","rc":[{"atl":[[7,3.31]],"id":52237612}],"con":true,"img":false}]}
{"op":"mcm","clk":"11450293000","pt":1717320161298,"mc":[{"id":"1.229554913","rc":[{"atb":[[80,0],[23,4.55]],"id":52237621},{"atl":[[14,0],[29,3.57]],"id":52237612},{"atb":[[130,0],[23,4.55]],"id":52671547},{"atl":[[29,3.57]],"id":52671542},{"atb":[[1.17,76.69]],"id":52671545}],"con":true,"img":false}]}
{"op":"mcm","clk":"11450293008","pt":1717320161400,"mc":[{"id":"1.229554913","rc":[{"atl":[[22,0]],"id":52671542}],"con":true,"img":false}]}
{"op":"mcm","clk":"11450293015","pt":1717320161609,"mc":[{"id":"1.229554913","rc":[{"atb":[[85,0.94],[100,0]],"id":52237621},{"atl":[[29,6.7]],"id":52237612},{"atb":[[140,0],[120,0.88]],"id":52671547},{"atb":[[11,2.74]],"id":52671549},{"atl":[[9.6,0],[29,6.48],[9.4,0]],"id":52671542},{"atb":[[3.45,0],[3.55,30.77]],"id":52671545}],"con":true,"img":false}]}
{"op":"mcm","clk":"11450293022","pt":1717320161705,"mc":[{"id":"1.229554913","rc":[{"atl":[[6.6,0],[7,0]],"id":52237612},{"atb":[[8.6,0]],"id":52671549},{"atb":[[8.6,0],[8.2,0]],"id":52671543}],"con":true,"img":false}]}
{"op":"mcm","clk":"11450293743","pt":1717320171621,"mc":[{"id":"1.229554913","rc":[{"atl":[[32,2.85]],"id":52237612},{"atb":[[10,3.96]],"id":52671549},{"atl":[[32,3.88]],"id":52671542}],"con":true,"img":false}]}
{"op":"mcm","clk":"11450294061","pt":1717320176624,"mc":[{"id":"1.229554913","rc":[{"atb":[[8.2,0]],"id":52671549}],"con":true,"img":false}]}
{"op":"mcm","clk":"11450295235","pt":1717320193961,"mc":[{"id":"1.229554913","rc":[{"atb":[[16.5,0],[19,0],[23,0],[14,0]],"id":52671561}],"con":true,"img":false}]}
{"op":"mcm","clk":"11450295246","pt":1717320194061,"mc":[{"id":"1.229554913","rc":[{"atb":[[9.8,0],[14.5,0]],"id":52671549}],"con":true,"img":false}]}
{"op":"mcm","clk":"11450295254","pt":1717320194165,"mc":[{"id":"1.229554913","rc":[{"atb":[[12,0],[8.8,0]],"id":52671549}],"con":true,"img":false}]}
{"op":"mcm","clk":"11450295296","pt":1717320194638,"mc":[{"id":"1.229554913","rc":[{"atb":[[17,4.9],[19.5,2.83],[24,1.14],[14.5,12.17]],"id":52671561}],"con":true,"img":false}]}
{"op":"mcm","clk":"11450295303","pt":1717320194740,"mc":[{"id":"1.229554913","rc":[{"atb":[[10.5,8.26],[15.5,1.81]],"id":52671549}],"con":true,"img":false}]}
{"op":"mcm","clk":"11450295311","pt":1717320194843,"mc":[{"id":"1.229554913","rc":[{"atb":[[9.2,12.76],[13,4.36]],"id":52671549}],"con":true,"img":false}]}
{"op":"mcm","clk":"11450297195","pt":1717320224489,"mc":[{"id":"1.229554913","rc":[{"atb":[[120,0]],"id":52671547}],"con":true,"img":false}]}
{"op":"mcm","clk":"11450297257","pt":1717320225212,"mc":[{"id":"1.229554913","rc":[{"atb":[[130,0.81]],"id":52671547}],"con":true,"img":false}]}
{"op":"mcm","clk":"11450302610","pt":1717320306195,"mc":[{"id":"1.229554913","rc":[{"atb":[[5.8,0],[7.6,15.15]],"id":52237627},{"atb":[[260,0],[160,0]],"id":52671562},{"atb":[[7.8,14.71],[5.9,0]],"id":52671564},{"atb":[[65,0],[36,0]],"id":52237621},{"atb":[[9.8,0],[7.8,0]],"id":52671561},{"atb":[[3.6,0],[3.1,0]],"id":52671560},{"atb":[[2.82,0],[2.62,0]],"id":52237612},{"atb":[[70,0],[38,0]],"id":52671552},{"atb":[[260,0],[160,0]],"id":52671547},{"atb":[[5.8,0],[7.6,15.15]],"id":52237617},{"atb":[[7.8,14.71],[5.9,0]],"id":52671549},{"atb":[[18.5,0],[13.5,0]],"id":52671543},{"atb":[[3.6,0],[3.1,0]],"id":52671542},{"atb":[[2.64,0],[2.84,0]],"id":52671545},{"atb":[[4.4,0],[5.4,0]],"id":52237634}],"con":true,"img":false}]}
{"op":"mcm","clk":"11450302822","pt":1717320309491,"mc":[{"id":"1.229554913","rc":[{"atb":[[19,2.89],[20,3.94]],"id":52237621},{"atb":[[19,4.1],[20,2.74]],"id":52671547},{"atb":[[7.2,3.55],[7.6,3.67]],"id":52671543},{"atb":[[1.27,58.13],[1.25,62.78]],"id":52671545}],"con":true,"img":false}]}
{"op":"mcm","clk":"11450303925","pt":1717320326716,"mc":[{"id":"1.229554913","rc":[{"atb":[[5.8,50.81],[7.6,30.98]],"id":52237627},{"atb":[[260,0.4],[160,1.53]],"id":52671562},{"atb":[[7.8,30.08],[5.9,49.77]],"id":52671564},{"atb":[[65,1.63],[36,6.96]],"id":52237621},{"atb":[[9.8,11.87],[7.8,35.86]],"id":52671561},{"atb":[[3.6,40.2],[3.1,116.14]],"id":52671560},{"atb":[[2.82,57.43],[2.62,150.55]],"id":52237612},{"atb":[[70,1.51],[38,6.59]],"id":52671552},{"atb":[[260,0.4],[160,1.53]],"id":52671547},{"atb":[[5.8,50.81],[7.6,30.98]],"id":52237617},{"atb":[[7.8,30.08],[5.9,49.77]],"id":52671549},{"atb":[[18.5,5.97],[13.5,19.51]],"id":52671543},{"atb":[[3.6,40.2],[3.1,116.14]],"id":52671542},{"atb":[[2.64,148.72],[2.84,56.81]],"id":52671545},{"atb":[[4.4,71.73],[5.4,23.75]],"id":52237634}],"con":true,"img":false}]}
{"op":"mcm","clk":"11450307297","pt":1717320385476,"mc":[{"id":"1.229554913","rc":[{"atb":[[2.74,57.47],[2.94,0]],"id":52671560},{"atb":[[1.91,0],[1.77,69.88]],"id":52237612},{"atb":[[85,0],[95,5.56]],"id":52671552},{"atb":[[2.74,57.47],[2.94,0]],"id":52671542}],"con":true,"img":false}]}
{"op":"mcm","clk":"11450307317","pt":1717320385681,"mc":[{"id":"1.229554913","rc":[{"atb":[[2.92,52.08],[2.74,0]],"id":52671542}],"con":true,"img":false}]}
{"op":"mcm","clk":"11450307326","pt":1717320385785,"mc":[{"id":"1.229554913","rc":[{"atb":[[170,0],[85,0],[120,0],[60,0]],"id":52237621},{"atl":[[48,0],[50,4.65]],"id":52671561},{"atb":[[5,0],[4.7,4.52]],"id":52671560},{"atb":[[3.2,7.13],[3.4,0]],"id":52237612},{"atb":[[130,0],[65,0],[180,0],[90,0]],"id":52671552},{"atb":[[130,0]],"id":52671547},{"atl":[[30,0]],"id":52237617},{"atb":[[5,0],[4.9,0],[4.4,0],[5.9,0],[5.4,0],[4.7,3.34]],"id":52671542}],"con":true,"img":false}]}
{"op":"mcm","clk":"11450307335","pt":1717320385885,"mc":[{"id":"1.229554913","rc":[{"atl":[[30,0]],"id":52237627}],"con":true,"img":false}]}
{"op":"mcm","clk":"11450307343","pt":1717320385988,"mc":[{"id":"1.229554913","rc":[{"atb":[[85,2],[95,3.56]],"id":52671552}],"con":true,"img":false}]}
{"op":"mcm","clk":"11450307360","pt":1717320386297,"mc":[{"id":"1.229554913","rc":[{"atb":[[110,0]],"id":52671552}],"con":true,"img":false}]}
{"op":"mcm","clk":"11450307433","pt":1717320387620,"mc":[{"id":"1.229554913","rc":[{"atl":[[50,0]],"id":52671561},{"atb":[[4.8,0],[5,3.08]],"id":52671560},{"atb":[[3.35,0],[3.4,6.53]],"id":52237612},{"atb":[[85,5.69],[95,0]],"id":52671552},{"atb":[[4.8,0],[5,3.55]],"id":52671542}],"con":true,"img":false}]}
{"op":"mcm","clk":"11450307468","pt":1717320387994,"mc":[{"id":"1.229554913","rc":[{"atb":[[130,0.81]],"id":52671547}],"con":true,"img":false}]}
{"op":"mcm","clk":"11450307657","pt":1717320391614,"mc":[{"id":"1.229554913","rc":[{"atb":[[170,0.16],[85,0.94],[120,0.44],[60,1.77]],"id":52237621},{"atb":[[130,0.41],[65,1.64],[180,0.15],[90,0.88]],"id":52671552},{"atb":[[4.9,20.12],[4.4,30.77],[5.9,5.34],[5.4,11.89]],"id":52671542}],"con":true,"img":false}]}
{"op":"mcm","clk":"11450307771","pt":1717320393590,"mc":[{"id":"1.229554913","rc":[{"atb":[[2.92,52.08],[2.74,0]],"id":52671560},{"atb":[[1.9,69.88],[1.77,0]],"id":52237612}],"con":true,"img":false}]}
{"op":"mcm","clk":"11450307871","pt":1717320395809,"mc":[{"id":"1.229554913","rc":[{"atl":[[30,2.8]],"id":52237627},{"atl":[[48,4.32]],"id":52671561},{"atl":[[30,3.28]],"id":52237617}],"con":true,"img":false}]}
{"op":"mcm","clk":"11450307952","pt":1717320397518,"mc":[{"id":"1.229554913","rc":[{"atb":[[3.3,40.94]],"id":52237612},{"atb":[[110,2.88]],"id":52671552}],"con":true,"img":false}]}
{"op":"mcm","clk":"11450308005","pt":1717320398394,"mc":[{"id":"1.229554913","rc":[{"atl":[[30,0]],"id":52237627},{"atl":[[48,0]],"id":52671561},{"atb":[[5,0],[4.9,24.26]],"id":52671560},{"atb":[[3.35,6.68],[3.4,0]],"id":52237612},{"atl":[[30,0]],"id":52237617},{"atb":[[5,0],[4.9,3.89],[4.4,0],[5.9,0],[5.4,0]],"id":52671542}],"con":true,"img":false}]}
{"op":"mcm","clk":"11450308027","pt":1717320398836,"mc":[{"id":"1.229554913","rc":[{"atb":[[2.72,58.14]],"id":52671560},{"atb":[[1.76,81.9]],"id":52237612},{"atb":[[85,3.69],[95,2]],"id":52671552},{"atb":[[2.92,0],[2.72,58.14]],"id":52671542}],"con":true,"img":false}]}
{"op":"mcm","clk":"11450308036","pt":1717320398894,"mc":[{"id":"1.229554913","rc":[{"atb":[[2.92,0]],"id":52671560},{"atb":[[1.9,0]],"id":52237612}],"con":true,"img":false}]}
{"op":"mcm","clk":"11450308049","pt":1717320399099,"mc":[{"id":"1.229554913","rc":[{"atb":[[3.3,34.12]],"id":52237612},{"atb":[[4,34.88],[4.5,22.42],[5,13.08],[5.5,5.81]],"id":52671542}],"con":true,"img":false}]}
{"op":"mcm","clk":"11450308123","pt":1717320400340,"mc":[{"id":"1.229554913","rc":[{"atb":[[2.72,0],[2.88,53.19]],"id":52671560},{"atb":[[2.72,0],[2.88,53.19]],"id":52671542}],"con":true,"img":false}]}
{"op":"mcm","clk":"11450308209","pt":1717320401600,"mc":[{"id":"1.229554913","rc":[{"atb":[[1.87,75.89]],"id":52237612}],"con":true,"img":false}]}
{"op":"mcm","clk":"11450308217","pt":1717320401699,"mc":[{"id":"1.229554913","rc":[{"atb":[[1.76,0]],"id":52237612}],"con":true,"img":false}]}
{"op":"mcm","clk":"11450308504","pt":1717320405808,"mc":[{"id":"1.229554913","rc":[{"atl":[[36,3.28]],"id":52237627},{"atl":[[65,4.38]],"id":52671561},{"atl":[[36,3.93]],"id":52237617}],"con":true,"img":false}]}
{"op":"mcm","clk":"11450308597","pt":1717320407418,"mc":[{"id":"1.229554913","rc":[{"atb":[[2.72,58.14],[2.88,0]],"id":52671560},{"atb":[[1.87,0],[1.76,69.88]],"id":52237612},{"atb":[[2.72,58.14],[2.88,0]],"id":52671542}],"con":true,"img":false}]}
{"op":"mcm","clk":"11450308611","pt":1717320407625,"mc":[{"id":"1.229554913","rc":[{"atb":[[95,6.38]],"id":52671552}],"con":true,"img":false}]}
{"op":"mcm","clk":"11450308618","pt":1717320407724,"mc":[{"id":"1.229554913","rc":[{"atb":[[4.9,20.12]],"id":52671560},{"atb":[[3.35,0]],"id":52237612},{"atb":[[4.9,0]],"id":52671542}],"con":true,"img":false}]}
{"op":"mcm","clk":"11450308698","pt":1717320409122,"mc":[{"id":"1.229554913","rc":[{"atb":[[4.9,23.86]],"id":52671560},{"atb":[[3.4,6.53]],"id":52237612},{"atb":[[85,0]],"id":52671552},{"atb":[[4.9,3.77]],"id":52671542}],"con":true,"img":false}]}
{"op":"mcm","clk":"11450308704","pt":1717320409226,"mc":[{"id":"1.229554913","rc":[{"atb":[[8,22.43],[7.6,15.83]],"id":52237617},{"atb":[[5,0],[5.5,22.22]],"id":52237634}],"con":true,"img":false}]}
{"op":"mcm","clk":"11450308718","pt":1717320409430,"mc":[{"id":"1.229554913","rc":[{"atb":[[8.2,0],[8.8,2.93]],"id":52237617},{"atl":[[8,4.39]],"id":52671545}],"con":true,"img":false}]}
{"op":"mcm","clk":"11450308724","pt":1717320409533,"mc":[{"id":"1.229554913","rc":[{"atb":[[10.5,0],[11,3.99],[12,0],[9.8,4],[8.8,0],[14.5,0]],"id":52237627},{"atl":[[620,0],[610,4.36]],"id":52671562},{"atl":[[360,0]],"id":52237621},{"atb":[[16,2.74],[17,0],[19.5,0],[24,0],[14.5,4.42],[15.5,0]],"id":52671561},{"atl":[[12.5,2.76],[13,0]],"id":52671560},{"atb":[[3.25,6.97]],"id":52237612},{"atl":[[620,0],[610,2.78]],"id":52671547},{"atb":[[9,9.51]],"id":52237617},{"atl":[[8.8,0]],"id":52671545},{"atb":[[8,3.47],[6.4,0],[7.4,0],[7.6,0],[7.8,2.75],[8.4,0],[9.4,0]],"id":52237634},{"atl":[[20,0]],"id":52237634}],"con":true,"img":false}]}
{"op":"mcm","clk":"11450308768","pt":1717320410213,"mc":[{"id":"1.229554913","rc":[{"atb":[[16,1.74],[11,11.84],[13.5,4.19],[9.4,12.46]],"id":52237627},{"atb":[[17.5,4.76],[20,2.75],[25,1.09],[15,7.48]],"id":52671561},{"atb":[[8,14.69],[9,6.54],[10,2.91],[7,17.44]],"id":52237634}],"con":true,"img":false}]}
{"op":"mcm","clk":"11450309109","pt":1717320416072,"mc":[{"id":"1.229554913","rc":[{"atl":[[610,0],[640,4.11]],"id":52671562},{"atl":[[360,3.84]],"id":52237621},{"atb":[[4.9,20.12]],"id":52671560},{"atb":[[3.4,0]],"id":52237612},{"atl":[[360,3.57],[380,0]],"id":52671552},{"atl":[[610,0],[640,3.6]],"id":52671547},{"atb":[[7.8,0]],"id":52237617},{"atl":[[90,3.69],[95,0]],"id":52671543},{"atb":[[4.9,0]],"id":52671542},{"atb":[[7.2,0]],"id":52237634},{"atl":[[20,2.75]],"id":52237634}],"con":true,"img":false}]}
{"op":"mcm","clk":"11450309281","pt":1717320419076,"mc":[{"id":"1.229554913","rc":[{"atb":[[4.5,26.07]],"id":52671542}],"con":true,"img":false}]}
{"op":"mcm","clk":"11450309310","pt":1717320419490,"mc":[{"id":"1.229554913","rc":[{"atb":[[4.5,2.95]],"id":52671560},{"atl":[[8.4,4.58]],"id":52671545}],"con":true,"img":false}]}
{"op":"mcm","clk":"11450309772","pt":1717320426104,"mc":[{"id":"1.229554913","rc":[{"atl":[[380,4.19]],"id":52671552},{"atl":[[100,4.06]],"id":52671543}],"con":true,"img":false}]}
{"op":"mcm","clk":"11450309885","pt":1717320427501,"mc":[{"id":"1.229554913","rc":[{"atb":[[1.87,69.88]],"id":52237612},{"atb":[[8,11.21],[8.4,13.51]],"id":52237617}],"con":true,"img":false}]}
{"op":"mcm","clk":"11450309897","pt":1717320427618,"mc":[{"id":"1.229554913","rc":[{"atb":[[1.76,0]],"id":52237612}],"con":true,"img":false}]}
{"op":"mcm","clk":"11450309917","pt":1717320427925,"mc":[{"id":"1.229554913","rc":[{"atb":[[11,7.85],[11.5,3.19]],"id":52237627},{"atb":[[4.6,3.73]],"id":52671560},{"atb":[[3.35,6.68]],"id":52237612},{"atl":[[410,0]],"id":52671552},{"atl":[[120,0]],"id":52671543},{"atb":[[4,0],[4.5,3.64],[5,0],[4.6,4],[5.5,0],[4.7,0]],"id":52671542}],"con":true,"img":false}]}
{"op":"mcm","clk":"11450309925","pt":1717320427977,"mc":[{"id":"1.229554913","rc":[{"atb":[[4.7,0]],"id":52671560},{"atb":[[3.25,0]],"id":52237612},{"atl":[[9.2,0]],"id":52671545}],"con":true,"img":false}]}
{"op":"mcm","clk":"11450309982","pt":1717320428809,"mc":[{"id":"1.229554913","rc":[{"atb":[[3.95,35.47],[4.9,13.41],[4.4,23.08],[5.4,5.94]],"id":52671542}],"con":true,"img":false}]}
{"op":"mcm","clk":"11450310100","pt":1717320430628,"mc":[{"id":"1.229554913","rc":[{"atb":[[8.6,13.16],[7.6,15.83]],"id":52237627}],"con":true,"img":false}]}
{"op":"mcm","clk":"11450310137","pt":1717320431033,"mc":[{"id":"1.229554913","rc":[{"atb":[[16,0],[17,2.99]],"id":52671561},{"atb":[[4.8,4.14],[4.6,0]],"id":52671560},{"atb":[[3.35,0],[3.3,40.94]],"id":52237612},{"atb":[[34,0],[44,0],[27,0],[60,0]],"id":52671543},{"atb":[[4.8,2.86],[4.6,0]],"id":52671542}],"con":true,"img":false}]}
{"op":"mcm","clk":"11450310194","pt":1717320431710,"mc":[{"id":"1.229554913","rc":[{"atb":[[32,2.53],[42,1.28],[26,4.19],[55,0.49]],"id":52671543}],"con":true,"img":false}]}
{"op":"mcm","clk":"11450310528","pt":1717320436895,"mc":[{"id":"1.229554913","rc":[{"atb":[[5.8,0],[7.6,0]],"id":52237627},{"atb":[[260,0],[160,0]],"id":52671562},{"atb":[[7.8,14.71],[5.9,0]],"id":52671564},{"atb":[[65,0],[36,0]],"id":52237621},{"atb":[[9.8,0],[7.8,0]],"id":52671561},{"atb":[[3.6,0],[3.1,0]],"id":52671560},{"atb":[[2.82,0],[2.62,0]],"id":52237612},{"atb":[[70,0],[38,0]],"id":52671552},{"atb":[[260,0],[160,0]],"id":52671547},{"atb":[[5.8,0],[7.6,0]],"id":52237617},{"atb":[[7.8,14.71],[5.9,0]],"id":52671549},{"atb":[[18.5,0],[13.5,0]],"id":52671543},{"atb":[[3.6,0],[3.1,0]],"id":52671542},{"atb":[[2.64,0],[2.84,0]],"id":52671545},{"atb":[[4.4,0],[5.4,0]],"id":52237634}],"con":true,"img":false}]}
{"op":"mcm","clk":"11450310573","pt":1717320437781,"mc":[{"id":"1.229554913","rc":[{"atb":[[10.5,4.68]],"id":52237627}],"con":true,"img":false}]}
{"op":"mcm","clk":"11450310635","pt":1717320438884,"mc":[{"id":"1.229554913","rc":[{"atb":[[8.8,12.82],[7.8,0]],"id":52671564},{"atb":[[2.82,54.95],[2.72,0]],"id":52671560},{"atb":[[1.8,69.88],[1.87,0]],"id":52237612},{"atb":[[8.8,12.82],[7.8,0]],"id":52671549},{"atb":[[2.82,54.95],[2.72,0]],"id":52671542}],"con":true,"img":false}]}
{"op":"mcm","clk":"11450310654","pt":1717320439197,"mc":[{"id":"1.229554913","rc":[{"atb":[[9.8,0]],"id":52237627},{"atb":[[3.25,6.97]],"id":52237612}],"con":true,"img":false}]}
{"op":"mcm","clk":"11450310663","pt":1717320439306,"mc":[{"id":"1.229554913","rc":[{"atb":[[3.3,34.12]],"id":52237612}],"con":true,"img":false}]}
{"op":"mcm","clk":"11450310703","pt":1717320439826,"mc":[{"id":"1.229554913","rc":[{"atl":[[32,0],[34,3.83]],"id":52671564},{"atl":[[32,0],[34,4.35]],"id":52671549},{"atl":[[20,0]],"id":52237634}],"con":true,"img":false}]}
{"op":"mcm","clk":"11450310790","pt":1717320440921,"mc":[{"id":"1.229554913","rc":[{"atb":[[16,4.62]],"id":52671561}],"con":true,"img":false}]}
{"op":"mcm","clk":"11450310861","pt":1717320441806,"mc":[{"id":"1.229554913","rc":[{"atb":[[14.5,0]],"id":52671561}],"con":true,"img":false}]}
{"op":"mcm","clk":"11450311032","pt":1717320444142,"mc":[{"id":"1.229554913","rc":[{"atl":[[32,0],[34,4.62]],"id":52237627},{"atl":[[640,0],[690,3.47]],"id":52671562},{"atl":[[360,0],[390,2.74]],"id":52237621},{"atl":[[360,0],[390,4.47]],"id":52671552},{"atl":[[640,0],[690,3.73]],"id":52671547},{"atl":[[32,0],[34,3.16]],"id":52237617}],"con":true,"img":false}]}
{"op":"mcm","clk":"11450311369","pt":1717320449222,"mc":[{"id":"1.229554913","rc":[{"atl":[[23,3.54]],"id":52237634}],"con":true,"img":false}]}
{"op":"mcm","clk":"11450311508","pt":1717320451512,"mc":[{"id":"1.229554913","rc":[{"atl":[[650,0]],"id":52671562},{"atl":[[380,0]],"id":52237621},{"atl":[[380,0]],"id":52671552},{"atl":[[650,0]],"id":52671547}],"con":true,"img":false}]}
{"op":"mcm","clk":"11450311677","pt":1717320454113,"mc":[{"id":"1.229554913","rc":[{"atl":[[710,3.18]],"id":52671562},{"atl":[[410,3.11]],"id":52237621},{"atl":[[410,4]],"id":52671552},{"atl":[[710,3.24]],"id":52671547}],"con":true,"img":false}]}
{"op":"mcm","clk":"11450311734","pt":1717320455216,"mc":[{"id":"1.229554913","rc":[{"atb":[[7.8,15.37],[5.9,49.77]],"id":52237627},{"atb":[[280,0.37],[180,1.36]],"id":52671562},{"atb":[[7.8,15.37],[5.9,49.77]],"id":52671564},{"atb":[[75,1.41],[40,6.25]],"id":52237621},{"atb":[[9.8,11.87],[7.8,35.86]],"id":52671561},{"atb":[[3.55,40.99],[3.05,118.97]],"id":52671560},{"atb":[[2.82,57.43],[2.62,150.55]],"id":52237612},{"atb":[[75,1.41],[40,6.25]],"id":52671552},{"atb":[[280,0.37],[180,1.36]],"id":52671547},{"atb":[[7.8,15.37],[5.9,49.77]],"id":52237617},{"atb":[[7.8,15.37],[5.9,49.77]],"id":52671549},{"atb":[[18.5,5.97],[13.5,19.51]],"id":52671543},{"atb":[[3.55,40.99],[3.05,118.97]],"id":52671542},{"atb":[[2.82,57.43],[2.62,150.55]],"id":52671545},{"atb":[[5.6,22.72],[4.6,67.75]],"id":52237634}],"con":true,"img":false}]}
{"op":"mcm","clk":"11450312203","pt":1717320463046,"mc":[{"id":"1.229554913","rc":[{"atb":[[130,0]],"id":52671547}],"con":true,"img":false}]}
{"op":"mcm","clk":"11450312239","pt":1717320463730,"mc":[{"id":"1.229554913","rc":[{"atb":[[150,0.7]],"id":52671547}],"con":true,"img":false}]}
{"op":"mcm","clk":"11450312435","pt":1717320466155,"mc":[{"id":"1.229554913","rc":[{"atb":[[170,0],[85,0],[120,0],[60,0]],"id":52237621},{"atb":[[130,0],[65,0],[180,0],[90,0]],"id":52671552}],"con":true,"img":false}]}
{"op":"mcm","clk":"11450312449","pt":1717320466357,"mc":[{"id":"1.229554913","rc":[{"atb":[[90,2],[95,4.38]],"id":52671552}],"con":true,"img":false}]}
{"op":"mcm","clk":"11450312484","pt":1717320466832,"mc":[{"id":"1.229554913","rc":[{"atb":[[130,0.41],[65,1.64],[180,0.15],[90,0.88]],"id":52237621},{"atb":[[140,0.38],[70,1.52],[95,5.23],[190,0.14]],"id":52671552}],"con":true,"img":false}]}
{"op":"mcm","clk":"11450312818","pt":1717320473058,"mc":[{"id":"1.229554913","rc":[{"atl":[[21,0],[22,2.91]],"id":52237634}],"con":true,"img":false}]}
{"op":"mcm","clk":"11450313723","pt":1717320489753,"mc":[{"id":"1.229554913","rc":[{"atb":[[11,12.85]],"id":52237627},{"atl":[[22,5]],"id":52237627},{"atb":[[13,5]],"id":52671564},{"atl":[[26,5]],"id":52671564},{"atb":[[17,8]],"id":52671561},{"atl":[[36,5]],"id":52671561},{"atb":[[7.2,5]],"id":52671560},{"atl":[[12,5]],"id":52671560},{"atb":[[4.4,5]],"id":52237612},{"atl":[[5.8,5]],"id":52237612},{"atb":[[8.8,7.94]],"id":52237617},{"atl":[[22,5]],"id":52237617},{"atb":[[11.5,5]],"id":52671549},{"atl":[[22,5]],"id":52671549},{"atb":[[5.3,5]],"id":52671542},{"atl":[[7.8,5]],"id":52671542},{"atb":[[5.1,5]],"id":52671545},{"atl":[[8.2,5]],"id":52671545},{"atb":[[8.4,5]],"id":52237634},{"atl":[[15,5]],"id":52237634}],"con":true,"img":false}]}
{"op":"mcm","clk":"11450313886","pt":1717320492782,"mc":[{"id":"1.229554913","rc":[{"atb":[[1.8,0],[1.87,69.88]],"id":52237612}],"con":true,"img":false}]}
{"op":"mcm","clk":"11450313913","pt":1717320493082,"mc":[{"id":"1.229554913","rc":[{"atb":[[4.8,0],[4.9,22.74]],"id":52671560},{"atb":[[3.35,6.68],[3.25,0]],"id":52237612},{"atb":[[140,0],[70,0],[190,0],[95,4.38]],"id":52671552},{"atb":[[150,0]],"id":52671547},{"atb":[[4.8,0],[4.9,17.5]],"id":52671542}],"con":true,"img":false}]}
{"op":"mcm","clk":"11450313918","pt":1717320493183,"mc":[{"id":"1.229554913","rc":[{"atb":[[85,2],[90,0]],"id":52671552}],"con":true,"img":false}]}
{"op":"mcm","clk":"11450313936","pt":1717320493496,"mc":[{"id":"1.229554913","rc":[{"atb":[[7.8,0],[5.9,0]],"id":52237627},{"atb":[[280,0],[180,0]],"id":52671562},{"atb":[[7.8,0],[5.9,0]],"id":52671564},{"atb":[[75,0],[40,0]],"id":52237621},{"atb":[[9.8,0],[7.8,0]],"id":52671561},{"atb":[[3.55,0],[3.05,0]],"id":52671560},{"atb":[[2.82,0],[2.62,0]],"id":52237612},{"atb":[[75,0],[40,0]],"id":52671552},{"atb":[[280,0],[180,0]],"id":52671547},{"atb":[[7.8,0],[5.9,0]],"id":52237617},{"atb":[[7.8,0],[5.9,0]],"id":52671549},{"atb":[[18.5,0],[13.5,0]],"id":52671543},{"atb":[[3.55,0],[3.05,0]],"id":52671542},{"atb":[[2.82,0],[2.62,0]],"id":52671545},{"atb":[[5.6,0],[4.6,0]],"id":52237634}],"con":true,"img":false}]}
{"op":"mcm","clk":"11450313956","pt":1717320493810,"mc":[{"id":"1.229554913","rc":[{"atb":[[130,0.41],[65,1.64],[180,0.15],[90,0.88]],"id":52671552},{"atb":[[140,0.75]],"id":52671547}],"con":true,"img":false}]}
{"op":"mcm","clk":"11450314130","pt":1717320496484,"mc":[{"id":"1.229554913","rc":[{"atl":[[22,0],[23,5]],"id":52671549}],"con":true,"img":false}]}
{"op":"mcm","clk":"11450314221","pt":1717320497895,"mc":[{"id":"1.229554913","rc":[{"atb":[[1.8,69.88]],"id":52237612}],"con":true,"img":false}]}
{"op":"mcm","clk":"11450314229","pt":1717320498000,"mc":[{"id":"1.229554913","rc":[{"atb":[[1.87,0]],"id":52237612}],"con":true,"img":false}]}
{"op":"mcm","clk":"11450314234","pt":1717320498107,"mc":[{"id":"1.229554913","rc":[{"atb":[[4.8,4.25],[4.9,20.12]],"id":52671560},{"atb":[[3.35,0],[3.25,6.97]],"id":52237612},{"atb":[[4.8,3.54],[4.9,13.41]],"id":52671542}],"con":true,"img":false}]}
{"op":"mcm","clk":"11450314322","pt":1717320499776,"mc":[{"id":"1.229554913","rc":[{"atb":[[1.8,0],[1.87,69.88]],"id":52237612}],"con":true,"img":false}]}
{"op":"mcm","clk":"11450314368","pt":1717320500496,"mc":[{"id":"1.229554913","rc":[{"atb":[[4.8,0],[4.9,24.19]],"id":52671560},{"atb":[[3.35,6.68],[3.25,0]],"id":52237612},{"atb":[[4.9,17.57]],"id":52671542}],"con":true,"img":false}]}
{"op":"mcm","clk":"11450314376","pt":1717320500602,"mc":[{"id":"1.229554913","rc":[{"atb":[[4.8,0]],"id":52671542}],"con":true,"img":false}]}
{"op":"mcm","clk":"11450314538","pt":1717320503174,"mc":[{"id":"1.229554913","rc":[{"atb":[[1.8,69.88],[1.87,0]],"id":52237612}],"con":true,"img":false}]}
{"op":"mcm","clk":"11450314557","pt":1717320503484,"mc":[{"id":"1.229554913","rc":[{"atb":[[4.8,4.61],[4.9,20.12]],"id":52671560},{"atb":[[3.25,6.97]],"id":52237612},{"atb":[[4.8,3.53]],"id":52671542}],"con":true,"img":false}]}
{"op":"mcm","clk":"11450314558","pt":1717320503583,"mc":[{"id":"1.229554913","rc":[{"atb":[[3.35,0]],"id":52237612},{"atb":[[4.9,13.41]],"id":52671542}],"con":true,"img":false}]}
{"op":"mcm","clk":"11450314907","pt":1717320509082,"mc":[{"id":"1.229554913","rc":[{"atb":[[4.8,0],[4.9,23.72]],"id":52671560},{"atb":[[3.35,6.68],[3.25,0]],"id":52237612},{"atb":[[4.8,0],[4.9,16.22]],"id":52671542}],"con":true,"img":false}]}
{"op":"mcm","clk":"11450314931","pt":1717320509484,"mc":[{"id":"1.229554913","rc":[{"atl":[[22,12.63]],"id":52237627},{"atl":[[36,9.58]],"id":52671561},{"atb":[[7.2,20.05]],"id":52671560},{"atl":[[12,19.57]],"id":52671560},{"atb":[[4.4,22.61]],"id":52237612},{"atl":[[5.8,22.61]],"id":52237612},{"atl":[[22,12.63]],"id":52237617},{"atb":[[5.1,20.05]],"id":52671545},{"atl":[[8,19.45]],"id":52671545},{"atl":[[15,16.44]],"id":52237634}],"con":true,"img":false}]}
{"op":"mcm","clk":"11450314936","pt":1717320509596,"mc":[{"id":"1.229554913","rc":[{"atl":[[32,5.16]],"id":52671549},{"atb":[[5.4,22.41]],"id":52671542},{"atl":[[7.8,21.47]],"id":52671542}],"con":true,"img":false}]}
{"op":"mcm","clk":"11450314972","pt":1717320510123,"mc":[{"id":"1.229554913","rc":[{"atb":[[1.8,0],[1.87,69.88]],"id":52237612}],"con":true,"img":false}]}
{"op":"mcm","clk":"11450314990","pt":1717320510329,"mc":[{"id":"1.229554913","rc":[{"atb":[[11,7.85]],"id":52237627},{"atl":[[22,0]],"id":52237627},{"atb":[[13,0]],"id":52671564},{"atl":[[26,0]],"id":52671564},{"atb":[[17,2.99]],"id":52671561},{"atl":[[36,0]],"id":52671561},{"atb":[[7.2,0],[4.9,3.59],[4.4,0],[5.9,0],[5.4,0]],"id":52671560},{"atl":[[12,0]],"id":52671560},{"atb":[[4.4,0]],"id":52237612},{"atl":[[5.8,0]],"id":52237612},{"atb":[[8.8,2.93]],"id":52237617},{"atl":[[22,0]],"id":52237617},{"atb":[[11.5,0]],"id":52671549},{"atl":[[23,0]],"id":52671549},{"atb":[[5.3,0]],"id":52671542},{"atl":[[7.8,16.46]],"id":52671542},{"atb":[[5.1,0],[4.1,0],[3.8,0],[3.55,0],[3.3,0]],"id":52671545},{"atl":[[8,4.39],[8.2,0]],"id":52671545},{"atb":[[8.4,0]],"id":52237634},{"atl":[[15,0]],"id":52237634}],"con":true,"img":false}]}
{"op":"mcm","clk":"11450315003","pt":1717320510396,"mc":[{"id":"1.229554913","rc":[{"atl":[[32,0]],"id":52671549},{"atb":[[5.4,5.94]],"id":52671542},{"atl":[[7.8,0]],"id":52671542}],"con":true,"img":false}]}
{"op":"mcm","clk":"11450315054","pt":1717320510978,"mc":[{"id":"1.229554913","rc":[{"atb":[[4.8,20.65],[4.3,31.71],[5.8,5.45],[5.3,12.17]],"id":52671560},{"atb":[[3.8,9.34],[3.55,20.52],[3.3,34.12],[3.05,51.04]],"id":52671545}],"con":true,"img":false}]}
{"op":"mcm","clk":"11450315165","pt":1717320512492,"mc":[{"id":"1.229554913","rc":[{"atb":[[6.2,46.9],[8.2,14.51]],"id":52237627},{"atb":[[290,0.36],[190,1.29]],"id":52671562},{"atb":[[6.2,46.9],[8.2,14.51]],"id":52671564},{"atb":[[75,1.41],[40,6.25]],"id":52237621},{"atb":[[10.5,11],[8.2,33.87]],"id":52671561},{"atb":[[75,1.41],[40,6.25]],"id":52671552},{"atb":[[6.2,46.9],[8.2,14.51]],"id":52671549},{"atb":[[4.8,64.18],[5.8,21.77]],"id":52237634}],"con":true,"img":false}]}
{"op":"mcm","clk":"11450315171","pt":1717320512600,"mc":[{"id":"1.229554913","rc":[{"atb":[[3,121.95],[3.5,41.81]],"id":52671560},{"atb":[[2.58,154.36],[2.78,58.72]],"id":52237612},{"atb":[[290,0.36],[190,1.29]],"id":52671547},{"atb":[[6.2,46.9],[8.2,14.51]],"id":52237617},{"atb":[[18,6.14],[13,20.32]],"id":52671543},{"atb":[[3,121.95],[3.5,41.81]],"id":52671542},{"atb":[[2.58,154.36],[2.78,58.72]],"id":52671545}],"con":true,"img":false}]}
{"op":"mcm","clk":"11450315308","pt":1717320514406,"mc":[{"id":"1.229554913","rc":[{"atb":[[4.8,24.61],[4.9,0]],"id":52671560},{"atb":[[3.35,0],[3.8,0],[3.55,0],[3.25,6.97],[3.3,0],[3.05,0]],"id":52237612},{"atb":[[4.8,4.68],[4.9,13.41]],"id":52671542}],"con":true,"img":false}]}
{"op":"mcm","clk":"11450315374","pt":1717320515188,"mc":[{"id":"1.229554913","rc":[{"atb":[[3.8,9.34],[3.55,20.52],[3.3,34.12],[3.05,51.04]],"id":52237612}],"con":true,"img":false}]}
{"op":"mcm","clk":"11450315413","pt":1717320515809,"mc":[{"id":"1.229554913","rc":[{"atb":[[4.8,20.65],[4.9,4.7]],"id":52671560},{"atb":[[3.35,6.68],[3.25,0]],"id":52237612},{"atb":[[4.8,0],[4.9,16.82]],"id":52671542}],"con":true,"img":false}]}
{"op":"mcm","clk":"11450315633","pt":1717320519310,"mc":[{"id":"1.229554913","rc":[{"atb":[[1.8,69.88],[1.87,0]],"id":52237612}],"con":true,"img":false}]}
{"op":"mcm","clk":"11450315658","pt":1717320519626,"mc":[{"id":"1.229554913","rc":[{"atb":[[4.8,4.64],[4.3,0],[5.8,0],[5.3,0],[4.9,0]],"id":52671560},{"atb":[[1.8,0],[3.35,0],[3.8,0],[3.55,0],[3.25,6.97],[3.3,0],[1.87,69.88],[3.05,0]],"id":52237612},{"atb":[[4.8,4.26],[4.9,13.41]],"id":52671542},{"atb":[[3.8,0],[3.55,0],[3.3,0],[3.05,0]],"id":52671545}],"con":true,"img":false}]}
{"op":"mcm","clk":"11450315664","pt":1717320519690,"mc":[{"id":"1.229554913","rc":[{"atb":[[1.8,69.88],[1.87,0]],"id":52237612}],"con":true,"img":false}]}
{"op":"mcm","clk":"11450315673","pt":1717320519892,"mc":[{"id":"1.229554913","rc":[{"atb":[[1.8,0],[1.87,69.88]],"id":52237612}],"con":true,"img":false}]}
{"op":"mcm","clk":"11450315699","pt":1717320520308,"mc":[{"id":"1.229554913","rc":[{"atb":[[4.8,25.3],[4.3,31.71],[5.8,5.45],[5.3,12.17]],"id":52671560},{"atb":[[3.8,9.34],[3.55,20.52],[3.3,34.12],[3.05,51.04]],"id":52237612},{"atb":[[3.8,9.34],[3.55,20.52],[3.3,34.12],[3.05,51.04]],"id":52671545}],"con":true,"img":false}]}
{"op":"mcm","clk":"11450315748","pt":1717320521193,"mc":[{"id":"1.229554913","rc":[{"atb":[[4.8,20.65],[4.9,2.78]],"id":52671560},{"atb":[[3.35,6.68],[3.25,0]],"id":52237612},{"atb":[[4.8,0],[4.9,16.68]],"id":52671542}],"con":true,"img":false}]}
{"op":"mcm","clk":"11450315762","pt":1717320521406,"mc":[{"id":"1.229554913","rc":[{"atb":[[11,12.85]],"id":52237627},{"atl":[[22,5]],"id":52237627},{"atb":[[13,5]],"id":52671564},{"atl":[[32,5.16],[26,5]],"id":52671564},{"atb":[[17,8]],"id":52671561},{"atl":[[36,5]],"id":52671561},{"atb":[[7.2,5]],"id":52671560},{"atl":[[12,5]],"id":52671560},{"atb":[[4.4,5]],"id":52237612},{"atl":[[5.8,5]],"id":52237612},{"atb":[[8.8,7.94]],"id":52237617},{"atl":[[22,5]],"id":52237617},{"atb":[[11.5,5]],"id":52671549},{"atl":[[23,5]],"id":52671549},{"atb":[[5,5]],"id":52671545},{"atl":[[8.2,5]],"id":52671545},{"atb":[[8.4,5]],"id":52237634},{"atl":[[15,5]],"id":52237634}],"con":true,"img":false}]}
{"op":"mcm","clk":"11450315772","pt":1717320521511,"mc":[{"id":"1.229554913","rc":[{"atb":[[5.3,5]],"id":52671542},{"atl":[[7.8,5]],"id":52671542}],"con":true,"img":false}]}
{"op":"mcm","clk":"11450315792","pt":1717320521822,"mc":[{"id":"1.229554913","rc":[{"atb":[[1.8,69.88],[1.87,0]],"id":52237612}],"con":true,"img":false}]}
{"op":"mcm","clk":"11450315807","pt":1717320522038,"mc":[{"id":"1.229554913","rc":[{"atb":[[4.9,0]],"id":52671560},{"atb":[[3.35,0]],"id":52237612},{"atb":[[4.8,3.54],[4.9,13.41]],"id":52671542}],"con":true,"img":false}]}
{"op":"mcm","clk":"11450315815","pt":1717320522133,"mc":[{"id":"1.229554913","rc":[{"atl":[[22,0],[23,5]],"id":52237627},{"atl":[[15.5,5]],"id":52237634}],"con":true,"img":false}]}
{"op":"mcm","clk":"11450315821","pt":1717320522206,"mc":[{"id":"1.229554913","rc":[{"atb":[[7.2,0],[7,5]],"id":52671560},{"atl":[[15,0]],"id":52237634}],"con":true,"img":false}]}
{"op":"mcm","clk":"11450315829","pt":1717320522294,"mc":[{"id":"1.229554913","rc":[{"atb":[[1.8,0],[1.87,69.88]],"id":52237612}],"con":true,"img":false}]}
{"op":"mcm","clk":"11450315871","pt":1717320522913,"mc":[{"id":"1.229554913","rc":[{"atb":[[3.25,6.97]],"id":52237612}],"con":true,"img":false}]}
{"op":"mcm","clk":"11450315896","pt":1717320523241,"mc":[{"id":"1.229554913","rc":[{"atb":[[8.6,0],[4.4,29.41]],"id":52237627},{"atb":[[130,0],[36,2.86]],"id":52671562},{"atb":[[5.2,23.81],[8.8,0]],"id":52671564},{"atb":[[5.5,22.22],[12,0]],"id":52671561},{"atl":[[100,2]],"id":52671561},{"atb":[[2.82,0],[3.75,36.36]],"id":52671560},{"atl":[[22,0],[30,3.45]],"id":52671560},{"atb":[[36,2.86],[85,0]],"id":52671552},{"atb":[[3.85,35.09],[8.4,0]],"id":52237617},{"atl":[[32,3.23],[70,0]],"id":52237617},{"atb":[[8.8,0],[4.7,27.03]],"id":52671549},{"atl":[[75,0],[50,2.04]],"id":52671549},{"atb":[[3.85,35.09],[5.5,0]],"id":52237634},{"atl":[[32,3.23],[46,0]],"id":52237634}],"con":true,"img":false}]}
{"op":"mcm","clk":"11450315917","pt":1717320523399,"mc":[{"id":"1.229554913","rc":[{"atb":[[4.8,23.74]],"id":52671560},{"atb":[[3.3,40.94]],"id":52237612}],"con":true,"img":false}]}
{"op":"mcm","clk":"11450315922","pt":1717320523544,"mc":[{"id":"1.229554913","rc":[{"atb":[[16,0],[11,5],[13.5,0],[9.4,0]],"id":52237627},{"atl":[[690,0],[710,0]],"id":52671562},{"atb":[[16,12.43]],"id":52671564},{"atl":[[26,0],[29,5]],"id":52671564},{"atb":[[140,5]],"id":52237621},{"atl":[[610,2.63],[390,0],[410,0]],"id":52237621},{"atb":[[16.5,3.22],[17,5]],"id":52671561},{"atl":[[12,0],[12.5,5],[13,2.67]],"id":52671560},{"atb":[[140,5]],"id":52671552},{"atl":[[390,0],[410,0],[820,2.68]],"id":52671552},{"atl":[[690,0],[780,4.2]],"id":52671547},{"atb":[[9,6.54],[8.4,3.85]],"id":52237617},{"atb":[[40,5]],"id":52671543},{"atl":[[320,3.55],[90,0],[100,0]],"id":52671543},{"atb":[[5.3,0],[4.9,18.42]],"id":52671542},{"atl":[[8,0],[9,5],[8.2,0],[8.8,3.93]],"id":52671545},{"atb":[[8,0],[9,0],[10,0],[7,0],[8.4,7.83]],"id":52237634}],"con":true,"img":false}]}
{"op":"mcm","clk":"11450315940","pt":1717320523708,"mc":[{"id":"1.229554913","rc":[{"atb":[[4.9,4.22]],"id":52671560},{"atb":[[3.35,6.68],[3.25,0]],"id":52237612},{"atb":[[4.8,0],[4.9,22.24]],"id":52671542}],"con":true,"img":false}]}
{"op":"mcm","clk":"11450315946","pt":1717320523834,"mc":[{"id":"1.229554913","rc":[{"atl":[[22,0],[23,5]],"id":52237617},{"atl":[[18,5.88],[15,0]],"id":52671545}],"con":true,"img":false}]}
{"op":"mcm","clk":"11450315959","pt":1717320523934,"mc":[{"id":"1.229554913","rc":[{"atb":[[11.5,12.92]],"id":52237627},{"atl":[[610,2.89]],"id":52237621},{"atl":[[820,2.87]],"id":52671552},{"atl":[[320,4.05]],"id":52671543},{"atb":[[8.4,17.55]],"id":52237634}],"con":true,"img":false}]}
{"op":"mcm","clk":"11450315986","pt":1717320524219,"mc":[{"id":"1.229554913","rc":[{"atb":[[17,1.64],[12,7.14],[9.8,11.89],[14.5,3.88]],"id":52237627},{"atb":[[4.8,20.65]],"id":52671560},{"atb":[[3.2,0],[3.3,34.12]],"id":52237612},{"atb":[[5,0],[4.9,5]],"id":52671545},{"atb":[[7.2,16.88],[9.2,6.38],[10.5,2.75],[8.2,10.9]],"id":52237634}],"con":true,"img":false}]}
{"op":"mcm","clk":"11450315992","pt":1717320524318,"mc":[{"id":"1.229554913","rc":[{"atb":[[8.8,5]],"id":52237617}],"con":true,"img":false}]}
{"op":"mcm","clk":"11450315998","pt":1717320524424,"mc":[{"id":"1.229554913","rc":[{"atl":[[710,0]],"id":52671547},{"atl":[[8.4,0]],"id":52671545}],"con":true,"img":false}]}
{"op":"mcm","clk":"11450316011","pt":1717320524586,"mc":[{"id":"1.229554913","rc":[{"atl":[[23,12.28]],"id":52237627},{"atl":[[36,9.58]],"id":52671561},{"atb":[[7,20.05]],"id":52671560},{"atl":[[13,16.03]],"id":52671560},{"atb":[[4.4,22.61]],"id":52237612},{"atl":[[5.8,22.61]],"id":52237612},{"atl":[[30,5.52]],"id":52237617},{"atl":[[8.4,15.05]],"id":52671545},{"atl":[[15.5,16.05]],"id":52237634}],"con":true,"img":false}]}
{"op":"mcm","clk":"11450316019","pt":1717320524689,"mc":[{"id":"1.229554913","rc":[{"atb":[[4.5,0]],"id":52671560},{"atl":[[23,12.28]],"id":52671549},{"atl":[[7.8,21.47]],"id":52671542},{"atb":[[4.9,19.42]],"id":52671545}],"con":true,"img":false}]}
{"op":"mcm","clk":"11450316030","pt":1717320524898,"mc":[{"id":"1.229554913","rc":[{"atb":[[4.9,14.41]],"id":52671545}],"con":true,"img":false}]}
{"op":"mcm","clk":"11450316038","pt":1717320525003,"mc":[{"id":"1.229554913","rc":[{"atb":[[4.8,5]],"id":52671545}],"con":true,"img":false}]}
{"op":"mcm","clk":"11450316055","pt":1717320525211,"mc":[{"id":"1.229554913","rc":[{"atb":[[4.9,0]],"id":52671560},{"atb":[[3.35,0]],"id":52237612},{"atb":[[4.8,3.55],[4.9,18.42]],"id":52671542}],"con":true,"img":false}]}
{"op":"mcm","clk":"11450316070","pt":1717320525419,"mc":[{"id":"1.229554913","rc":[{"atb":[[4.9,0]],"id":52671545}],"con":true,"img":false}]}
{"op":"mcm","clk":"11450316117","pt":1717320526042,"mc":[{"id":"1.229554913","rc":[{"atb":[[4.8,24.9]],"id":52671560},{"atb":[[3.3,40.94]],"id":52237612}],"con":true,"img":false}]}
{"op":"mcm","clk":"11450316129","pt":1717320526198,"mc":[{"id":"1.229554913","rc":[{"atb":[[3.8,24.4]],"id":52671545}],"con":true,"img":false}]}
{"op":"mcm","clk":"11450316162","pt":1717320526611,"mc":[{"id":"1.229554913","rc":[{"atl":[[23,0],[24,5]],"id":52237627},{"atb":[[4.6,2.75]],"id":52671560},{"atb":[[3.2,7.13]],"id":52237612}],"con":true,"img":false}]}
{"op":"mcm","clk":"11450316220","pt":1717320527326,"mc":[{"id":"1.229554913","rc":[{"atl":[[32,5.16]],"id":52237627}],"con":true,"img":false}]}
{"op":"mcm","clk":"11450323228","pt":1717320528993,"mc":[{"id":"1.229554913","rc":[{"atb":[[2.62,61.73]],"id":52237612}],"con":true,"img":false}]}
{"op":"mcm","clk":"11450323234","pt":1717320529094,"mc":[{"id":"1.229554913","rc":[{"atb":[[1.87,0]],"id":52237612}],"con":true,"img":false}]}
{"op":"mcm","clk":"11450323556","pt":1717320533719,"mc":[{"id":"1.229554913","rc":[{"atl":[[630,3.84]],"id":52237621},{"atl":[[840,3.76]],"id":52671552},{"atl":[[800,4.49]],"id":52671547},{"atb":[[8,15.02]],"id":52237617},{"atl":[[340,4.54]],"id":52671543},{"atl":[[9.2,3.74]],"id":52671545}],"con":true,"img":false}]}
{"op":"mcm","clk":"11450323566","pt":1717320533836,"mc":[{"id":"1.229554913","rc":[{"atb":[[130,0],[65,0],[180,0],[90,0]],"id":52237621}],"con":true,"img":false}]}
{"op":"mcm","clk":"11450323595","pt":1717320534243,"mc":[{"id":"1.229554913","rc":[{"atb":[[150,1.07]],"id":52237621}],"con":true,"img":false}]}
{"op":"mcm","clk":"11450323619","pt":1717320534558,"mc":[{"id":"1.229554913","rc":[{"atb":[[140,5.38],[70,1.52],[190,0.14],[95,0.84]],"id":52237621}],"con":true,"img":false}]}
{"op":"mcm","clk":"11450323967","pt":1717320539449,"mc":[{"id":"1.229554913","rc":[{"atl":[[24,11.97]],"id":52237627},{"atl":[[12.5,18.93]],"id":52671560},{"atl":[[22,7.62]],"id":52237617}],"con":true,"img":false}]}
{"op":"mcm","clk":"11450323971","pt":1717320539505,"mc":[{"id":"1.229554913","rc":[{"atb":[[4.8,35.13]],"id":52671545}],"con":true,"img":false}]}
{"op":"mcm","clk":"11450324018","pt":1717320540124,"mc":[{"id":"1.229554913","rc":[{"atl":[[32,0]],"id":52237627},{"atl":[[13,2.67]],"id":52671560}],"con":true,"img":false}]}
{"op":"mcm","clk":"11450324025","pt":1717320540242,"mc":[{"id":"1.229554913","rc":[{"atl":[[22,0],[30,0]],"id":52237617}],"con":true,"img":false}]}
{"op":"mcm","clk":"11450324033","pt":1717320540336,"mc":[{"id":"1.229554913","rc":[{"atb":[[3.8,9.34]],"id":52671545}],"con":true,"img":false}]}
{"op":"mcm","clk":"11450324075","pt":1717320540968,"mc":[{"id":"1.229554913","rc":[{"atl":[[32,8.39]],"id":52237617}],"con":true,"img":false}]}
{"op":"mcm","clk":"11450324739","pt":1717320549032,"mc":[{"id":"1.229554913","rc":[{"atl":[[24,6.96]],"id":52237627},{"atb":[[13,0],[14.5,5]],"id":52671564},{"atl":[[34,5]],"id":52671561},{"atb":[[7.2,5],[7,15.05]],"id":52671560},{"atl":[[22,5],[23,0]],"id":52237617},{"atl":[[7.2,5]],"id":52671542},{"atb":[[9,5],[8.4,12.54]],"id":52237634}],"con":true,"img":false}]}
{"op":"mcm","clk":"11450324745","pt":1717320549129,"mc":[{"id":"1.229554913","rc":[{"atl":[[23,5]],"id":52237627},{"atl":[[36,4.57]],"id":52671561},{"atl":[[21,5],[23,7.28]],"id":52671549},{"atl":[[7.8,16.46]],"id":52671542}],"con":true,"img":false}]}
{"op":"mcm","clk":"11450324765","pt":1717320549444,"mc":[{"id":"1.229554913","rc":[{"atl":[[34,9.86]],"id":52671561},{"atl":[[7.2,23.67]],"id":52671542}],"con":true,"img":false}]}
{"op":"mcm","clk":"11450324776","pt":1717320549546,"mc":[{"id":"1.229554913","rc":[{"atl":[[29,10.73]],"id":52671564},{"atb":[[7.2,20.73]],"id":52671560},{"atl":[[21,13.01]],"id":52671549}],"con":true,"img":false}]}
{"op":"mcm","clk":"11450324796","pt":1717320549758,"mc":[{"id":"1.229554913","rc":[{"atl":[[22,0],[23,5]],"id":52237617},{"atl":[[15,5],[15.5,11.04]],"id":52237634}],"con":true,"img":false}]}
{"op":"mcm","clk":"11450324804","pt":1717320549861,"mc":[{"id":"1.229554913","rc":[{"atl":[[23,0],[24,11.97]],"id":52237627}],"con":true,"img":false}]}
{"op":"mcm","clk":"11450324828","pt":1717320550125,"mc":[{"id":"1.229554913","rc":[{"atl":[[36,0]],"id":52671561},{"atl":[[7.8,0]],"id":52671542}],"con":true,"img":false}]}
{"op":"mcm","clk":"11450324835","pt":1717320550222,"mc":[{"id":"1.229554913","rc":[{"atl":[[32,0]],"id":52671564},{"atb":[[7,0]],"id":52671560},{"atl":[[23,0]],"id":52671549},{"atl":[[15,16.44]],"id":52237634}],"con":true,"img":false}]}
{"op":"mcm","clk":"11450324899","pt":1717320551054,"mc":[{"id":"1.229554913","rc":[{"atl":[[15.5,0]],"id":52237634}],"con":true,"img":false}]}
{"op":"mcm","clk":"11450324983","pt":1717320552152,"mc":[{"id":"1.229554913","rc":[{"atl":[[22,5],[23,0]],"id":52237617}],"con":true,"img":false}]}
{"op":"mcm","clk":"11450325149","pt":1717320553969,"mc":[{"id":"1.229554913","rc":[{"atl":[[22,12.63]],"id":52237617}],"con":true,"img":false}]}
{"op":"mcm","clk":"11450325158","pt":1717320554028,"mc":[{"id":"1.229554913","rc":[{"atl":[[23,5]],"id":52237617},{"atl":[[15,11.44]],"id":52237634}],"con":true,"img":false}]}
{"op":"mcm","clk":"11450325165","pt":1717320554133,"mc":[{"id":"1.229554913","rc":[{"atl":[[22,7.62]],"id":52237617},{"atl":[[15,0],[15.5,5]],"id":52237634}],"con":true,"img":false}]}
{"op":"mcm","clk":"11450325208","pt":1717320554641,"mc":[{"id":"1.229554913","rc":[{"atl":[[32,3.23],[22,0]],"id":52237617}],"con":true,"img":false}]}
{"op":"mcm","clk":"11450325228","pt":1717320554848,"mc":[{"id":"1.229554913","rc":[{"atl":[[21,8]],"id":52237634}],"con":true,"img":false}]}
{"op":"mcm","clk":"11450325277","pt":1717320555368,"mc":[{"id":"1.229554913","rc":[{"atl":[[32,8.39]],"id":52237617}],"con":true,"img":false}]}
{"op":"mcm","clk":"11450325402","pt":1717320556939,"mc":[{"id":"1.229554913","rc":[{"atl":[[34,0],[36,5]],"id":52671561}],"con":true,"img":false}]}
{"op":"mcm","clk":"11450325469","pt":1717320557666,"mc":[{"id":"1.229554913","rc":[{"atl":[[34,5],[36,0],[50,3.26]],"id":52671561}],"con":true,"img":false}]}
{"op":"mcm","clk":"11450325509","pt":1717320558134,"mc":[{"id":"1.229554913","rc":[{"atb":[[130,0],[65,0],[180,0],[90,0]],"id":52671552}],"con":true,"img":false}]}
{"op":"mcm","clk":"11450325550","pt":1717320558553,"mc":[{"id":"1.229554913","rc":[{"atb":[[150,1.07]],"id":52671552}],"con":true,"img":false}]}
{"op":"mcm","clk":"11450325575","pt":1717320558858,"mc":[{"id":"1.229554913","rc":[{"atb":[[140,5.38],[70,1.52],[95,5.23],[190,0.14]],"id":52671552}],"con":true,"img":false}]}
{"op":"mcm","clk":"11450325609","pt":1717320559366,"mc":[{"id":"1.229554913","rc":[{"atl":[[20,5],[21,8]],"id":52671549}],"con":true,"img":false}]}
{"op":"mcm","clk":"11450325659","pt":1717320560041,"mc":[{"id":"1.229554913","rc":[{"atl":[[20,0],[21,13.01]],"id":52671549}],"con":true,"img":false}]}
{"op":"mcm","clk":"11450325724","pt":1717320560969,"mc":[{"id":"1.229554913","rc":[{"atl":[[23,5],[24,6.96]],"id":52237627},{"atb":[[7.2,15.72]],"id":52671560},{"atb":[[150,0]],"id":52671552},{"atb":[[4.8,30.12],[4.9,5]],"id":52671545}],"con":true,"img":false}]}
{"op":"mcm","clk":"11450325729","pt":1717320561073,"mc":[{"id":"1.229554913","rc":[{"atb":[[7.4,5]],"id":52671560}],"con":true,"img":false}]}
{"op":"mcm","clk":"11450325773","pt":1717320561649,"mc":[{"id":"1.229554913","rc":[{"atl":[[23,0],[24,11.97]],"id":52237627},{"atb":[[4.8,35.13],[4.9,0]],"id":52671545}],"con":true,"img":false}]}
{"op":"mcm","clk":"11450325779","pt":1717320561753,"mc":[{"id":"1.229554913","rc":[{"atb":[[7.2,20.73],[7.4,0]],"id":52671560}],"con":true,"img":false}]}
{"op":"mcm","clk":"11450325936","pt":1717320563776,"mc":[{"id":"1.229554913","rc":[{"atl":[[34,9.86]],"id":52671561}],"con":true,"img":false}]}
{"op":"mcm","clk":"11450325969","pt":1717320564237,"mc":[{"id":"1.229554913","rc":[{"atl":[[24,0],[25,5]],"id":52237627}],"con":true,"img":false}]}
{"op":"mcm","clk":"11450325983","pt":1717320564441,"mc":[{"id":"1.229554913","rc":[{"atl":[[50,0]],"id":52671561}],"con":true,"img":false}]}
{"op":"mcm","clk":"11450325990","pt":1717320564554,"mc":[{"id":"1.229554913","rc":[{"atl":[[15.5,16.05]],"id":52237634}],"con":true,"img":false}]}
{"op":"mcm","clk":"11450326017","pt":1717320564964,"mc":[{"id":"1.229554913","rc":[{"atl":[[32,5.16]],"id":52237627}],"con":true,"img":false}]}
{"op":"mcm","clk":"11450326047","pt":1717320565374,"mc":[{"id":"1.229554913","rc":[{"atl":[[21,0]],"id":52237634}],"con":true,"img":false}]}
{"op":"mcm","clk":"11450326210","pt":1717320567447,"mc":[{"id":"1.229554913","rc":[{"atb":[[4.7,5]],"id":52671545}],"con":true,"img":false}]}
{"op":"mcm","clk":"11450326221","pt":1717320567558,"mc":[{"id":"1.229554913","rc":[{"atb":[[4.8,0]],"id":52671545}],"con":true,"img":false}]}
{"op":"mcm","clk":"11450326285","pt":1717320568178,"mc":[{"id":"1.229554913","rc":[{"atl":[[23,12.28]],"id":52237617}],"con":true,"img":false}]}
{"op":"mcm","clk":"11450326296","pt":1717320568336,"mc":[{"id":"1.229554913","rc":[{"atb":[[3.8,24.4]],"id":52671545}],"con":true,"img":false}]}
{"op":"mcm","clk":"11450326330","pt":1717320568859,"mc":[{"id":"1.229554913","rc":[{"atl":[[32,3.23]],"id":52237617}],"con":true,"img":false}]}
{"op":"mcm","clk":"11450326457","pt":1717320570561,"mc":[{"id":"1.229554913","rc":[{"atl":[[1000,0.16]],"id":52671562}],"con":true,"img":false}]}
{"op":"mcm","clk":"11450327048","pt":1717320578996,"mc":[{"id":"1.229554913","rc":[{"atl":[[25,11.68]],"id":52237627}],"con":true,"img":false}]}
{"op":"mcm","clk":"11450327082","pt":1717320579409,"mc":[{"id":"1.229554913","rc":[{"atb":[[4.8,5],[4.7,0]],"id":52671545}],"con":true,"img":false}]}
{"op":"mcm","clk":"11450327105","pt":1717320579676,"mc":[{"id":"1.229554913","rc":[{"atl":[[32,0]],"id":52237627}],"con":true,"img":false}]}
{"op":"mcm","clk":"11450327231","pt":1717320581285,"mc":[{"id":"1.229554913","rc":[{"atb":[[160,5]],"id":52237621},{"atb":[[46,5]],"id":52671543}],"con":true,"img":false}]}
{"op":"mcm","clk":"11450327241","pt":1717320581382,"mc":[{"id":"1.229554913","rc":[{"atb":[[140,0.38]],"id":52237621},{"atb":[[140,0.38],[160,5]],"id":52671552},{"atb":[[40,0]],"id":52671543}],"con":true,"img":false}]}
{"op":"mcm","clk":"11450327307","pt":1717320582275,"mc":[{"id":"1.229554913","rc":[{"atb":[[4.8,20.05]],"id":52671545}],"con":true,"img":false}]}
{"op":"mcm","clk":"11450327366","pt":1717320582999,"mc":[{"id":"1.229554913","rc":[{"atb":[[3.8,9.34]],"id":52671545}],"con":true,"img":false}]}
{"op":"mcm","clk":"11450327571","pt":1717320586014,"mc":[{"id":"1.229554913","rc":[{"atl":[[24,5],[25,6.67]],"id":52237627}],"con":true,"img":false}]}
{"op":"mcm","clk":"11450327636","pt":1717320587000,"mc":[{"id":"1.229554913","rc":[{"atb":[[7.2,0],[7,5]],"id":52671560}],"con":true,"img":false}]}
{"op":"mcm","clk":"11450327679","pt":1717320587716,"mc":[{"id":"1.229554913","rc":[{"atb":[[5.8,19.69]],"id":52671560}],"con":true,"img":false}]}
{"op":"mcm","clk":"11450327718","pt":1717320588400,"mc":[{"id":"1.229554913","rc":[{"atl":[[16,5],[15.5,0]],"id":52237634}],"con":true,"img":false}]}
{"op":"mcm","clk":"11450327775","pt":1717320589119,"mc":[{"id":"1.229554913","rc":[{"atl":[[21,8]],"id":52237634}],"con":true,"img":false}]}
{"op":"mcm","clk":"11450327908","pt":1717320590936,"mc":[{"id":"1.229554913","rc":[{"atb":[[5.8,20.83],[4.4,0]],"id":52237627},{"atb":[[36,0],[18.5,5.71]],"id":52671562},{"atl":[[900,2]],"id":52671562},{"atb":[[6,20],[5.2,0]],"id":52671564},{"atl":[[75,0],[55,2]],"id":52671564},{"atl":[[690,2]],"id":52237621},{"atb":[[4,33.33],[5.5,0]],"id":52671561},{"atl":[[38,2.7],[100,0]],"id":52671561},{"atb":[[4,33.33],[3.75,0]],"id":52671560},{"atl":[[23,4.55],[30,0]],"id":52671560},{"atb":[[3.4,41.04],[2.62,0]],"id":52237612},{"atl":[[820,4.87]],"id":52671552},{"atb":[[23,0],[13,8.33]],"id":52671547},{"atl":[[770,2]],"id":52671547},{"atb":[[3.85,0],[4.7,27.03]],"id":52237617},{"atl":[[32,0],[40,2.56]],"id":52237617},{"atb":[[4.7,0],[5.4,22.73]],"id":52671549},{"atl":[[40,2.56],[50,0]],"id":52671549},{"atl":[[310,2]],"id":52671543},{"atb":[[2.82,0],[2.52,65.79]],"id":52671542},{"atb":[[3.85,0],[6,20]],"id":52237634},{"atl":[[32,0],[120,2]],"id":52237634}],"con":true,"img":false}]}
{"op":"mcm","clk":"11450327935","pt":1717320591304,"mc":[{"id":"1.229554913","rc":[{"atb":[[17,0],[11,0],[11.5,9.73],[12,2.95],[9.8,0],[13,5],[14.5,0]],"id":52237627},{"atl":[[25,0]],"id":52237627},{"atb":[[270,0],[140,0],[170,0],[220,0],[120,0]],"id":52671562},{"atl":[[310,5],[690,3.39],[710,4.53]],"id":52671562},{"atb":[[16,1.74],[11.5,5],[14.5,0]],"id":52671564},{"atl":[[23,5],[29,5.72]],"id":52671564},{"atb":[[140,0],[70,0],[150,0],[160,0],[190,0],[95,0]],"id":52237621},{"atl":[[610,0.26],[390,3.59],[210,5]],"id":52237621},{"atb":[[16.5,0],[16,0],[17.5,0],[17,0],[20,0],[25,0],[15,0]],"id":52671561},{"atl":[[10.5,5],[11,3.35],[12.5,13.93],[13,0]],"id":52671560},{"atb":[[5.2,5],[4.4,17.6]],"id":52237612},{"atl":[[5.8,0],[9.8,5]],"id":52237612},{"atb":[[140,0],[70,0],[160,0],[190,0],[95,4.38],[110,7.89]],"id":52671552},{"atl":[[390,3.92],[820,2.19],[220,5]],"id":52671552},{"atb":[[270,0],[140,0],[170,0],[220,0]],"id":52671547},{"atl":[[300,5],[690,3.13],[770,2.2],[780,0]],"id":52671547},{"atb":[[10,15.29],[9.2,5],[8.8,0],[8.4,0],[9.4,4.2]],"id":52237617},{"atb":[[9.2,0],[10.5,0],[11,0],[11.5,0],[13,0],[15.5,0]],"id":52671549},{"atb":[[46,0]],"id":52671543},{"atl":[[75,5],[320,0.5],[90,3.47]],"id":52671543},{"atb":[[4.8,0],[4,5.23],[4.5,0],[3.95,0],[4.9,0],[4.4,0],[5.4,0]],"id":52671542},{"atl":[[7.2,18.67],[6.8,5]],"id":52671542},{"atl":[[9,0],[9.8,3.12],[8.8,0]],"id":52671545},{"atb":[[9,0],[9.2,0],[10.5,0],[8.2,0],[11,15.05],[8.4,9.71],[15.5,5],[7.2,0],[8.6,4.58]],"id":52237634},{"atl":[[16,0],[34,4],[21,0],[22,0],[23,0]],"id":52237634}],"con":true,"img":false}]}
{"op":"mcm","clk":"11450327942","pt":1717320591410,"mc":[{"id":"1.229554913","rc":[{"atl":[[890,0.17]],"id":52671562},{"atl":[[300,0.53]],"id":52671543}],"con":true,"img":false}]}
{"op":"mcm","clk":"11450327968","pt":1717320591815,"mc":[{"id":"1.229554913","rc":[{"atb":[[13,11.94]],"id":52237627},{"atl":[[23,12.28]],"id":52671564},{"atb":[[9.4,5]],"id":52671561},{"atl":[[10,17.8]],"id":52671560},{"atb":[[5.2,22.61]],"id":52237612},{"atb":[[110,9.36]],"id":52671552},{"atb":[[10,15.5]],"id":52671549},{"atb":[[4,12.75]],"id":52671542},{"atl":[[6.8,12.53]],"id":52671542},{"atl":[[9.8,8.13]],"id":52671545}],"con":true,"img":false}]}
{"op":"mcm","clk":"11450327988","pt":1717320592127,"mc":[{"id":"1.229554913","rc":[{"atb":[[18,1.54],[10.5,15.7],[13,18.48],[15.5,3.61]],"id":52237627},{"atb":[[65,5],[80,0.66],[42,2.55],[110,0.24],[55,1.45]],"id":52671562},{"atb":[[11.5,17.05]],"id":52671564},{"atb":[[160,0.16],[80,0.99],[42,0.39],[100,5],[110,0.48],[55,1.94]],"id":52237621},{"atb":[[12,2.38],[9.8,5.94],[8.8,10.06],[7.8,15.39],[8.4,4.05]],"id":52671561},{"atl":[[28,5.93]],"id":52237612},{"atb":[[130,0.41],[65,1.64],[180,0.15],[90,0.88]],"id":52671552},{"atb":[[34,3.17],[85,0.31],[44,6.83],[60,0.88]],"id":52671547},{"atb":[[11,5.23],[13.5,2.09],[8.4,14.14],[9.4,9.34]],"id":52671549},{"atb":[[30,5]],"id":52671543},{"atl":[[320,0]],"id":52671543},{"atb":[[4,30.19],[4.5,7.48],[3.95,5],[3.5,83.67],[3.75,28.54]],"id":52671542},{"atb":[[9.6,6.08],[8.6,14.91],[11.5,2.49],[7.6,15.85],[8.4,0]],"id":52237634},{"atl":[[34,4.48],[36,5]],"id":52237634}],"con":true,"img":false}]}
{"op":"mcm","clk":"11450327997","pt":1717320592188,"mc":[{"id":"1.229554913","rc":[{"atl":[[1000,0]],"id":52671562}],"con":true,"img":false}]}
{"op":"mcm","clk":"11450328007","pt":1717320592294,"mc":[{"id":"1.229554913","rc":[{"atl":[[24,11.97]],"id":52237627},{"atl":[[220,5.73]],"id":52671552}],"con":true,"img":false}]}
{"op":"mcm","clk":"11450328025","pt":1717320592600,"mc":[{"id":"1.229554913","rc":[{"atb":[[11.5,0]],"id":52237627},{"atl":[[29,0]],"id":52671564},{"atl":[[12.5,0]],"id":52671560},{"atb":[[4.4,0]],"id":52237612},{"atl":[[7.2,0]],"id":52671542}],"con":true,"img":false}]}
{"op":"mcm","clk":"11450328063","pt":1717320593121,"mc":[{"id":"1.229554913","rc":[{"atl":[[24,5]],"id":52237627},{"atb":[[9.2,2.64],[8.8,12.97]],"id":52671561},{"atl":[[820,2],[220,5]],"id":52671552}],"con":true,"img":false}]}
{"op":"mcm","clk":"11450328069","pt":1717320593218,"mc":[{"id":"1.229554913","rc":[{"atl":[[9.2,0]],"id":52671545}],"con":true,"img":false}]}
{"op":"mcm","clk":"11450328117","pt":1717320593796,"mc":[{"id":"1.229554913","rc":[{"atl":[[32,5.16]],"id":52237627}],"con":true,"img":false}]}
{"op":"mcm","clk":"11450328171","pt":1717320594616,"mc":[{"id":"1.229554913","rc":[{"atb":[[6.8,5],[7,0]],"id":52671560},{"atl":[[21,0],[22,5]],"id":52671549}],"con":true,"img":false}]}
{"op":"mcm","clk":"11450328177","pt":1717320594719,"mc":[{"id":"1.229554913","rc":[{"atb":[[5.1,5],[5.2,0]],"id":52237612}],"con":true,"img":false}]}
{"op":"mcm","clk":"11450328214","pt":1717320595198,"mc":[{"id":"1.229554913","rc":[{"atb":[[9.6,3.27]],"id":52671549}],"con":true,"img":false}]}
{"op":"mcm","clk":"11450328219","pt":1717320595302,"mc":[{"id":"1.229554913","rc":[{"atl":[[32,5.16]],"id":52671549}],"con":true,"img":false}]}
{"op":"mcm","clk":"11450328229","pt":1717320595403,"mc":[{"id":"1.229554913","rc":[{"atb":[[3.85,16.43]],"id":52237612}],"con":true,"img":false}]}
{"op":"mcm","clk":"11450328246","pt":1717320595712,"mc":[{"id":"1.229554913","rc":[{"atl":[[21,5],[22,0]],"id":52671549},{"atl":[[7,5]],"id":52671542}],"con":true,"img":false}]}
{"op":"mcm","clk":"11450328252","pt":1717320595815,"mc":[{"id":"1.229554913","rc":[{"atl":[[6.8,0]],"id":52671542}],"con":true,"img":false}]}
{"op":"mcm","clk":"11450328287","pt":1717320596431,"mc":[{"id":"1.229554913","rc":[{"atl":[[7,0]],"id":52671542}],"con":true,"img":false}]}
{"op":"mcm","clk":"11450328293","pt":1717320596490,"mc":[{"id":"1.229554913","rc":[{"atl":[[28,5.93]],"id":52671542}],"con":true,"img":false}]}
{"op":"mcm","clk":"11450328318","pt":1717320596912,"mc":[{"id":"1.229554913","rc":[{"atb":[[3.4,0],[3.9,16.43]],"id":52237612},{"atl":[[620,2],[820,0]],"id":52671552}],"con":true,"img":false}]}
{"op":"mcm","clk":"11450328326","pt":1717320597016,"mc":[{"id":"1.229554913","rc":[{"atb":[[18.5,0],[23,4.55]],"id":52671562},{"atl":[[400,2],[900,0]],"id":52671562},{"atl":[[44,2.33],[55,0]],"id":52671564},{"atl":[[560,2],[690,0]],"id":52237621},{"atb":[[4,0],[4.7,27.03]],"id":52671561},{"atl":[[32,2.9],[38,0]],"id":52671561},{"atl":[[19,5.56],[23,0]],"id":52671560},{"atb":[[16.5,6.45],[13,0]],"id":52671547},{"atl":[[330,2],[770,0.2]],"id":52671547},{"atl":[[32,3.23],[40,0]],"id":52237617},{"atl":[[32,8.39],[40,0]],"id":52671549},{"atl":[[310,0],[240,2]],"id":52671543},{"atb":[[2.52,0],[2.78,56.18]],"id":52671542},{"atb":[[7.4,15.62],[6,0]],"id":52237634}],"con":true,"img":false}]}
{"op":"mcm","clk":"11450328334","pt":1717320597121,"mc":[{"id":"1.229554913","rc":[{"atl":[[6.8,5]],"id":52671542}],"con":true,"img":false}]}
{"op":"mcm","clk":"11450328377","pt":1717320597838,"mc":[{"id":"1.229554913","rc":[{"atl":[[6.8,0],[7,5]],"id":52671542}],"con":true,"img":false}]}
{"op":"mcm","clk":"11450328555","pt":1717320600350,"mc":[{"id":"1.229554913","rc":[{"atl":[[410,3.55]],"id":52237621},{"atl":[[12,4.45]],"id":52671560},{"atl":[[410,2.62]],"id":52671552},{"atl":[[710,3.86]],"id":52671547},{"atb":[[9,10.68]],"id":52237617},{"atl":[[100,3.61]],"id":52671543},{"atb":[[3.9,5.4]],"id":52671542},{"atl":[[10.5,4.55]],"id":52671545},{"atb":[[8.2,2.99]],"id":52237634},{"atl":[[38,4.59]],"id":52237634}],"con":true,"img":false}]}
{"op":"mcm","clk":"11450328637","pt":1717320601253,"mc":[{"id":"1.229554913","rc":[{"atb":[[6.8,30.8]],"id":52671560}],"con":true,"img":false}]}
{"op":"mcm","clk":"11450328705","pt":1717320601977,"mc":[{"id":"1.229554913","rc":[{"atb":[[5.8,5.45]],"id":52671560}],"con":true,"img":false}]}
{"op":"mcm","clk":"11450328929","pt":1717320604496,"mc":[{"id":"1.229554913","rc":[{"atb":[[6.2,0],[8.2,0]],"id":52237627},{"atb":[[290,0],[190,0]],"id":52671562},{"atb":[[6.2,0],[8.2,0]],"id":52671564},{"atb":[[75,0],[40,0]],"id":52237621},{"atb":[[10.5,0],[8.2,0]],"id":52671561},{"atb":[[3,0],[3.5,0]],"id":52671560},{"atb":[[2.58,0],[2.78,0]],"id":52237612},{"atb":[[75,0],[40,0]],"id":52671552},{"atb":[[290,0],[190,0]],"id":52671547},{"atb":[[6.2,0],[8.2,0]],"id":52237617},{"atb":[[6.2,0],[8.2,0]],"id":52671549},{"atb":[[18,0],[13,0]],"id":52671543},{"atb":[[3,0],[3.5,41.85]],"id":52671542},{"atb":[[2.58,0],[2.78,0]],"id":52671545},{"atb":[[4.8,0],[5.8,0]],"id":52237634}],"con":true,"img":false}]}
{"op":"mcm","clk":"11450328949","pt":1717320604656,"mc":[{"id":"1.229554913","rc":[{"atl":[[330,0],[360,2]],"id":52671547}],"con":true,"img":false}]}
{"op":"mcm","clk":"11450328959","pt":1717320604759,"mc":[{"id":"1.229554913","rc":[{"atl":[[310,0]],"id":52671562},{"atl":[[630,0],[210,0],[220,5]],"id":52237621},{"atl":[[14,0]],"id":52671560},{"atl":[[840,0]],"id":52671552},{"atl":[[800,0]],"id":52671547},{"atb":[[8,11.21]],"id":52237617},{"atl":[[340,0]],"id":52671543},{"atb":[[7.8,0]],"id":52237634}],"con":true,"img":false}]}
{"op":"mcm","clk":"11450328968","pt":1717320604863,"mc":[{"id":"1.229554913","rc":[{"atl":[[680,2],[400,0]],"id":52671562},{"atl":[[300,5.54]],"id":52671547},{"atb":[[15.5,16.05]],"id":52237634}],"con":true,"img":false}]}
{"op":"mcm","clk":"11450328976","pt":1717320604967,"mc":[{"id":"1.229554913","rc":[{"atl":[[34,0]],"id":52237627},{"atb":[[65,8.18],[55,4.36]],"id":52671562},{"atl":[[690,0]],"id":52671562},{"atl":[[34,0]],"id":52671564},{"atl":[[390,0],[410,0],[400,2.81]],"id":52237621},{"atl":[[55,0],[60,2.86]],"id":52671561},{"atl":[[390,0],[410,0],[400,3.11]],"id":52671552},{"atl":[[690,0]],"id":52671547},{"atl":[[34,0]],"id":52237617},{"atl":[[34,0]],"id":52671549}],"con":true,"img":false}]}
{"op":"mcm","clk":"11450328982","pt":1717320605069,"mc":[{"id":"1.229554913","rc":[{"atl":[[680,0],[700,2]],"id":52671562}],"con":true,"img":false}]}
{"op":"mcm","clk":"11450328997","pt":1717320605276,"mc":[{"id":"1.229554913","rc":[{"atl":[[390,0.41]],"id":52671562},{"atl":[[220,5.73]],"id":52237621},{"atb":[[5.1,23.99]],"id":52237612},{"atl":[[6.8,18.64]],"id":52671542}],"con":true,"img":false}]}
{"op":"mcm","clk":"11450329012","pt":1717320605484,"mc":[{"id":"1.229554913","rc":[{"atl":[[320,5]],"id":52671562}],"con":true,"img":false}]}
{"op":"mcm","clk":"11450329017","pt":1717320605542,"mc":[{"id":"1.229554913","rc":[{"atl":[[9.8,23.21]],"id":52237612}],"con":true,"img":false}]}
{"op":"mcm","clk":"11450329024","pt":1717320605647,"mc":[{"id":"1.229554913","rc":[{"atl":[[770,0]],"id":52671547},{"atl":[[6.8,23.64]],"id":52671542},{"atb":[[11,0]],"id":52237634}],"con":true,"img":false}]}
{"op":"mcm","clk":"11450329032","pt":1717320605797,"mc":[{"id":"1.229554913","rc":[{"atl":[[7,0]],"id":52671542}],"con":true,"img":false}]}
{"op":"mcm","clk":"11450329044","pt":1717320605961,"mc":[{"id":"1.229554913","rc":[{"atl":[[890,0]],"id":52671562},{"atl":[[610,0]],"id":52237621},{"atb":[[3.85,0]],"id":52237612},{"atl":[[28,0]],"id":52671542}],"con":true,"img":false}]}
{"op":"mcm","clk":"11450329089","pt":1717320606139,"mc":[{"id":"1.229554913","rc":[{"atl":[[6.8,5]],"id":52671542},{"atb":[[15.5,0]],"id":52237634}],"con":true,"img":false}]}
{"op":"mcm","clk":"11450329096","pt":1717320606187,"mc":[{"id":"1.229554913","rc":[{"atb":[[15,5]],"id":52237634}],"con":true,"img":false}]}
{"op":"mcm","clk":"11450329113","pt":1717320606385,"mc":[{"id":"1.229554913","rc":[{"atl":[[28,0]],"id":52237612},{"atb":[[4.8,0],[4.7,5]],"id":52671545}],"con":true,"img":false}]}
{"op":"mcm","clk":"11450329142","pt":1717320606793,"mc":[{"id":"1.229554913","rc":[{"atl":[[30,5.52]],"id":52671542},{"atb":[[12,13.62]],"id":52237634}],"con":true,"img":false}]}
{"op":"mcm","clk":"11450329147","pt":1717320606849,"mc":[{"id":"1.229554913","rc":[{"atb":[[15,0]],"id":52237634}],"con":true,"img":false}]}
{"op":"mcm","clk":"11450329152","pt":1717320606950,"mc":[{"id":"1.229554913","rc":[{"atb":[[15.5,5]],"id":52237634}],"con":true,"img":false}]}
{"op":"mcm","clk":"11450329164","pt":1717320607160,"mc":[{"id":"1.229554913","rc":[{"atb":[[3.85,19.73]],"id":52671545}],"con":true,"img":false}]}
{"op":"mcm","clk":"11450329257","pt":1717320608661,"mc":[{"id":"1.229554913","rc":[{"atl":[[21,13.01]],"id":52671549}],"con":true,"img":false}]}
{"op":"mcm","clk":"11450329298","pt":1717320609382,"mc":[{"id":"1.229554913","rc":[{"atl":[[730,3]],"id":52671547},{"atl":[[40,4.07]],"id":52237617}],"con":true,"img":false}]}
{"op":"mcm","clk":"11450329304","pt":1717320609489,"mc":[{"id":"1.229554913","rc":[{"atl":[[32,3.23]],"id":52671549}],"con":true,"img":false}]}
{"op":"mcm","clk":"11450329329","pt":1717320609859,"mc":[{"id":"1.229554913","rc":[{"atl":[[6.8,23.03]],"id":52671542}],"con":true,"img":false}]}
{"op":"mcm","clk":"11450329381","pt":1717320610679,"mc":[{"id":"1.229554913","rc":[{"atl":[[30,0]],"id":52671542}],"con":true,"img":false}]}
{"op":"mcm","clk":"11450329401","pt":1717320610989,"mc":[{"id":"1.229554913","rc":[{"atl":[[700,0],[420,2]],"id":52671562}],"con":true,"img":false}]}
{"op":"mcm","clk":"11450329563","pt":1717320612969,"mc":[{"id":"1.229554913","rc":[{"atl":[[24,0],[25,5]],"id":52237627},{"atl":[[300,0],[310,5]],"id":52671547},{"atl":[[23,0],[24,5]],"id":52237617}],"con":true,"img":false}]}
{"op":"mcm","clk":"11450329618","pt":1717320613687,"mc":[{"id":"1.229554913","rc":[{"atl":[[40,3.76],[30,5.52]],"id":52237627},{"atl":[[310,5.52]],"id":52671547},{"atl":[[30,5.52]],"id":52237617},{"atl":[[40,4.52]],"id":52671549}],"con":true,"img":false}]}
{"op":"mcm","clk":"11450329631","pt":1717320613900,"mc":[{"id":"1.229554913","rc":[{"atl":[[730,3.97]],"id":52671562},{"atl":[[40,3.56]],"id":52671564},{"atl":[[420,4.26]],"id":52237621},{"atl":[[420,3.66]],"id":52671552}],"con":true,"img":false}]}
{"op":"mcm","clk":"11450329679","pt":1717320614469,"mc":[{"id":"1.229554913","rc":[{"atl":[[32,0]],"id":52237627}],"con":true,"img":false}]}
{"op":"mcm","clk":"11450329689","pt":1717320614576,"mc":[{"id":"1.229554913","rc":[{"atl":[[23,5],[24,0]],"id":52237617}],"con":true,"img":false}]}
{"op":"mcm","clk":"11450329741","pt":1717320615292,"mc":[{"id":"1.229554913","rc":[{"atl":[[710,0],[750,4.33]],"id":52671562},{"atl":[[400,0]],"id":52237621},{"atl":[[400,0]],"id":52671552},{"atl":[[710,0],[750,2.84]],"id":52671547}],"con":true,"img":false}]}
{"op":"mcm","clk":"11450329750","pt":1717320615398,"mc":[{"id":"1.229554913","rc":[{"atl":[[23,0],[24,5]],"id":52237617}],"con":true,"img":false}]}
{"op":"mcm","clk":"11450329800","pt":1717320616079,"mc":[{"id":"1.229554913","rc":[{"atl":[[730,0]],"id":52671562},{"atl":[[730,0]],"id":52671547}],"con":true,"img":false}]}
{"op":"mcm","clk":"11450329870","pt":1717320616959,"mc":[{"id":"1.229554913","rc":[{"atb":[[4.8,5],[4.7,0]],"id":52671545}],"con":true,"img":false}]}
{"op":"mcm","clk":"11450329910","pt":1717320617581,"mc":[{"id":"1.229554913","rc":[{"atl":[[10.5,9.48]],"id":52671560},{"atb":[[9.6,3.19]],"id":52237617},{"atb":[[10,10.5],[10.5,5]],"id":52671549},{"atl":[[36,7.96]],"id":52237634}],"con":true,"img":false}]}
{"op":"mcm","clk":"11450329920","pt":1717320617683,"mc":[{"id":"1.229554913","rc":[{"atl":[[11,0]],"id":52671560},{"atb":[[9.4,0]],"id":52237617},{"atl":[[34,0.48]],"id":52237634}],"con":true,"img":false}]}
{"op":"mcm","clk":"11450329956","pt":1717320618098,"mc":[{"id":"1.229554913","rc":[{"atb":[[15.5,16.05]],"id":52237634}],"con":true,"img":false}]}
{"op":"mcm","clk":"11450329981","pt":1717320618460,"mc":[{"id":"1.229554913","rc":[{"atl":[[320,5.5]],"id":52671562}],"con":true,"img":false}]}
{"op":"mcm","clk":"11450330015","pt":1717320618980,"mc":[{"id":"1.229554913","rc":[{"atb":[[12,0]],"id":52237634}],"con":true,"img":false}]}
{"op":"mcm","clk":"11450330029","pt":1717320619186,"mc":[{"id":"1.229554913","rc":[{"atl":[[390,0]],"id":52671562}],"con":true,"img":false}]}
{"op":"mcm","clk":"11450330131","pt":1717320620374,"mc":[{"id":"1.229554913","rc":[{"atb":[[4.8,24.74]],"id":52671545}],"con":true,"img":false}]}
{"op":"mcm","clk":"11450330190","pt":1717320621154,"mc":[{"id":"1.229554913","rc":[{"atb":[[3.85,0]],"id":52671545}],"con":true,"img":false}]}
{"op":"mcm","clk":"11450330326","pt":1717320622768,"mc":[{"id":"1.229554913","rc":[{"atl":[[440,4.13]],"id":52237621},{"atl":[[440,2.87]],"id":52671552}],"con":true,"img":false}]}
{"op":"mcm","clk":"11450330409","pt":1717320623700,"mc":[{"id":"1.229554913","rc":[{"atb":[[6.2,46.9],[8.2,14.51]],"id":52237627},{"atb":[[290,0.36],[190,1.29]],"id":52671562},{"atb":[[6.2,46.9],[8.2,14.51]],"id":52671564},{"atb":[[75,1.41],[40,6.25]],"id":52237621},{"atb":[[10.5,11],[8.2,33.87]],"id":52671561},{"atb":[[3,121.95],[3.5,41.81]],"id":52671560},{"atb":[[2.58,154.36],[2.78,58.72]],"id":52237612},{"atb":[[75,1.41],[40,6.25]],"id":52671552},{"atb":[[290,0.36],[190,1.29]],"id":52671547},{"atb":[[6.2,46.9],[8.2,14.51]],"id":52237617},{"atb":[[6.2,46.9],[8.2,14.51]],"id":52671549},{"atb":[[18,6.14],[13,20.32]],"id":52671543},{"atb":[[3,121.95],[3.5,83.67]],"id":52671542},{"atb":[[2.58,154.36],[2.78,58.72]],"id":52671545},{"atb":[[4.8,64.18],[5.8,21.77]],"id":52237634}],"con":true,"img":false}]}
{"op":"mcm","clk":"11450330437","pt":1717320624009,"mc":[{"id":"1.229554913","rc":[{"atl":[[770,4.44]],"id":52671562},{"atl":[[770,3.24]],"id":52671547}],"con":true,"img":false}]}
{"op":"mcm","clk":"11450330446","pt":1717320624063,"mc":[{"id":"1.229554913","rc":[{"atl":[[350,2],[360,0]],"id":52671547}],"con":true,"img":false}]}
{"op":"mcm","clk":"11450330462","pt":1717320624270,"mc":[{"id":"1.229554913","rc":[{"atl":[[34,0],[36,5]],"id":52671561}],"con":true,"img":false}]}
{"op":"mcm","clk":"11450330472","pt":1717320624377,"mc":[{"id":"1.229554913","rc":[{"atl":[[32,0],[34,3.03]],"id":52671561},{"atl":[[10.5,5],[11,3.37]],"id":52671560}],"con":true,"img":false}]}
{"op":"mcm","clk":"11450330504","pt":1717320624734,"mc":[{"id":"1.229554913","rc":[{"atb":[[4.8,0],[4.7,5]],"id":52671545}],"con":true,"img":false}]}
{"op":"mcm","clk":"11450330533","pt":1717320624997,"mc":[{"id":"1.229554913","rc":[{"atl":[[36,9.58]],"id":52671561}],"con":true,"img":false}]}
{"op":"mcm","clk":"11450330574","pt":1717320625408,"mc":[{"id":"1.229554913","rc":[{"atb":[[3.85,19.73]],"id":52671545}],"con":true,"img":false}]}
{"op":"mcm","clk":"11450330690","pt":1717320626809,"mc":[{"id":"1.229554913","rc":[{"atl":[[23,7.28]],"id":52237617}],"con":true,"img":false}]}
{"op":"mcm","clk":"11450330698","pt":1717320626913,"mc":[{"id":"1.229554913","rc":[{"atl":[[720,4.18],[750,0]],"id":52671562},{"atl":[[420,0],[430,2.95]],"id":52237621},{"atl":[[400,3.07],[420,0]],"id":52671552},{"atl":[[720,2.69],[750,0]],"id":52671547}],"con":true,"img":false}]}
{"op":"mcm","clk":"11450330754","pt":1717320627587,"mc":[{"id":"1.229554913","rc":[{"atl":[[30,0]],"id":52237617}],"con":true,"img":false}]}
{"op":"mcm","clk":"11450330798","pt":1717320628104,"mc":[{"id":"1.229554913","rc":[{"atl":[[34,8.03],[36,4.57]],"id":52671561},{"atl":[[23,0]],"id":52237617}],"con":true,"img":false}]}
{"op":"mcm","clk":"11450330857","pt":1717320628782,"mc":[{"id":"1.229554913","rc":[{"atl":[[30,5.52]],"id":52237617}],"con":true,"img":false}]}
{"op":"mcm","clk":"11450330885","pt":1717320629092,"mc":[{"id":"1.229554913","rc":[{"atl":[[36,0],[38,2.99]],"id":52237627},{"atl":[[36,0],[38,3.81]],"id":52671564},{"atl":[[34,3.03],[70,4.45],[36,9.58],[60,0]],"id":52671561},{"atl":[[36,0],[38,3.8]],"id":52237617},{"atl":[[36,0],[38,3.69]],"id":52671549}],"con":true,"img":false}]}
{"op":"mcm","clk":"11450330953","pt":1717320629811,"mc":[{"id":"1.229554913","rc":[{"atl":[[700,2.63],[720,0]],"id":52671562},{"atl":[[410,3.57],[430,0]],"id":52237621},{"atl":[[400,0],[410,3.03]],"id":52671552},{"atl":[[700,2.79],[720,0]],"id":52671547},{"atl":[[85,4.22],[90,0]],"id":52671543}],"con":true,"img":false}]}
{"op":"mcm","clk":"11450330980","pt":1717320630073,"mc":[{"id":"1.229554913","rc":[{"atl":[[65,0]],"id":52671561},{"atl":[[9.6,3.77],[9.8,5]],"id":52671545}],"con":true,"img":false}]}
{"op":"mcm","clk":"11450330993","pt":1717320630280,"mc":[{"id":"1.229554913","rc":[{"atl":[[690,3.29]],"id":52671562},{"atl":[[36,4.3],[38,0]],"id":52671564},{"atl":[[60,4.08]],"id":52671561}],"con":true,"img":false}]}
{"op":"mcm","clk":"11450331001","pt":1717320630384,"mc":[{"id":"1.229554913","rc":[{"atl":[[36,3.39],[38,0]],"id":52237627},{"atl":[[690,3.21]],"id":52671547},{"atl":[[36,3.92],[38,0]],"id":52237617},{"atl":[[36,4.63],[38,0]],"id":52671549}],"con":true,"img":false}]}
{"op":"mcm","clk":"11450331040","pt":1717320630905,"mc":[{"id":"1.229554913","rc":[{"atl":[[700,0]],"id":52671562},{"atb":[[4.8,20.65],[4.7,3.37]],"id":52671560},{"atl":[[700,0]],"id":52671547},{"atb":[[9.6,0],[8.6,0],[11.5,0],[7.6,0],[8.8,3.29]],"id":52237634}],"con":true,"img":false}]}
{"op":"mcm","clk":"11450331108","pt":1717320631681,"mc":[{"id":"1.229554913","rc":[{"atb":[[12,2.38],[9.8,5.94],[8.8,13.36],[7.8,15.39]],"id":52237634}],"con":true,"img":false}]}
{"op":"mcm","clk":"11450331137","pt":1717320631997,"mc":[{"id":"1.229554913","rc":[{"atb":[[15,5],[15.5,0]],"id":52237634}],"con":true,"img":false}]}
{"op":"mcm","clk":"11450331202","pt":1717320632671,"mc":[{"id":"1.229554913","rc":[{"atb":[[12.5,10.48]],"id":52237634}],"con":true,"img":false}]}
{"op":"mcm","clk":"11450331245","pt":1717320633290,"mc":[{"id":"1.229554913","rc":[{"atb":[[4.7,26.57]],"id":52671545}],"con":true,"img":false}]}
{"op":"mcm","clk":"11450331305","pt":1717320634018,"mc":[{"id":"1.229554913","rc":[{"atb":[[3.85,0]],"id":52671545}],"con":true,"img":false}]}
{"op":"mcm","clk":"11450331483","pt":1717320636305,"mc":[{"id":"1.229554913","rc":[{"atl":[[210,5],[220,0.73]],"id":52237621}],"con":true,"img":false}]}
{"op":"mcm","clk":"11450331639","pt":1717320638294,"mc":[{"id":"1.229554913","rc":[{"atl":[[34,7.88]],"id":52671561},{"atb":[[4.8,5]],"id":52671545}],"con":true,"img":false}]}
{"op":"mcm","clk":"11450331649","pt":1717320638394,"mc":[{"id":"1.229554913","rc":[{"atb":[[4.7,21.57]],"id":52671545}],"con":true,"img":false}]}
{"op":"mcm","clk":"11450331678","pt":1717320638811,"mc":[{"id":"1.229554913","rc":[{"atl":[[710,3.08]],"id":52671562},{"atl":[[710,3.78]],"id":52671547},{"atb":[[4.8,26.57]],"id":52671545}],"con":true,"img":false}]}
{"op":"mcm","clk":"11450331698","pt":1717320639014,"mc":[{"id":"1.229554913","rc":[{"atl":[[36,5]],"id":52671561}],"con":true,"img":false}]}
{"op":"mcm","clk":"11450331746","pt":1717320639585,"mc":[{"id":"1.229554913","rc":[{"atl":[[23,7.28]],"id":52237617},{"atb":[[4.7,0]],"id":52671545}],"con":true,"img":false}]}
{"op":"mcm","clk":"11450331796","pt":1717320640284,"mc":[{"id":"1.229554913","rc":[{"atl":[[30,0]],"id":52237617}],"con":true,"img":false}]}
{"op":"mcm","clk":"11450331825","pt":1717320640700,"mc":[{"id":"1.229554913","rc":[{"atl":[[560,0],[780,2]],"id":52237621},{"atl":[[17.5,6.06],[19,0]],"id":52671560},{"atl":[[620,0],[920,2]],"id":52671552},{"atb":[[16.5,0],[21,4.1]],"id":52671547},{"atl":[[350,0],[400,2]],"id":52671547},{"atl":[[300,2.53],[240,0]],"id":52671543}],"con":true,"img":false}]}
{"op":"mcm","clk":"11450331834","pt":1717320640804,"mc":[{"id":"1.229554913","rc":[{"atb":[[12,0],[12.5,3.16]],"id":52237627},{"atl":[[770,0]],"id":52671562},{"atb":[[3.4,6.53],[3.3,34.12]],"id":52237612},{"atl":[[770,0]],"id":52671547},{"atb":[[9,3.6],[8.8,10.06]],"id":52237634}],"con":true,"img":false}]}
{"op":"mcm","clk":"11450331860","pt":1717320641117,"mc":[{"id":"1.229554913","rc":[{"atl":[[36,0],[38,3.18],[25,11.68]],"id":52237627},{"atl":[[690,0],[700,4.13],[710,0]],"id":52671562},{"atl":[[36,0],[38,2.91]],"id":52671564},{"atb":[[100,0],[110,5.49]],"id":52237621},{"atl":[[210,0],[220,0],[240,5]],"id":52237621},{"atb":[[9.2,0],[12,0],[9.8,0],[8.8,0],[7.8,0],[9.4,0]],"id":52671561},{"atl":[[60,0]],"id":52671561},{"atl":[[9.6,2.88],[11,0]],"id":52671560},{"atl":[[10,5],[9.8,18.2]],"id":52237612},{"atb":[[130,5.42],[110,4.35]],"id":52671552},{"atl":[[270,5],[220,0]],"id":52671552},{"atl":[[690,0],[700,3.79],[710,0]],"id":52671547},{"atb":[[9.6,0],[9.8,4.03]],"id":52237617},{"atl":[[36,0],[38,3.97]],"id":52237617},{"atb":[[10,6.53],[10.5,8.99]],"id":52671549},{"atl":[[36,0],[38,3.05]],"id":52671549},{"atb":[[34,5],[30,0]],"id":52671543},{"atl":[[75,0],[85,9.23]],"id":52671543},{"atl":[[9.6,0]],"id":52671545},{"atl":[[36,5]],"id":52237634}],"con":true,"img":false}]}
{"op":"mcm","clk":"11450331905","pt":1717320641686,"mc":[{"id":"1.229554913","rc":[{"atb":[[8.6,5]],"id":52671561},{"atl":[[9.4,19.07]],"id":52671560}],"con":true,"img":false}]}
{"op":"mcm","clk":"11450331915","pt":1717320641793,"mc":[{"id":"1.229554913","rc":[{"atb":[[12,4.39],[12.5,0]],"id":52237627},{"atl":[[30,0]],"id":52237627},{"atl":[[400,0.25]],"id":52237621},{"atb":[[11,2.62],[7.4,16.35],[8.4,14.66],[9.4,6.23]],"id":52671561},{"atl":[[9.8,4.35]],"id":52671560},{"atb":[[3.4,0],[3.3,40.94]],"id":52237612},{"atl":[[400,0.4]],"id":52671552},{"atl":[[730,3.21]],"id":52671547},{"atl":[[100,5.23]],"id":52671543},{"atb":[[4,24.96],[4.1,5.06]],"id":52671542},{"atb":[[9,0],[8.8,13.89]],"id":52237634}],"con":true,"img":false}]}
{"op":"mcm","clk":"11450331931","pt":1717320642001,"mc":[{"id":"1.229554913","rc":[{"atl":[[9.6,0]],"id":52671560},{"atb":[[9.6,3.79],[9.8,0]],"id":52237617}],"con":true,"img":false}]}
{"op":"mcm","clk":"11450331970","pt":1717320642521,"mc":[{"id":"1.229554913","rc":[{"atl":[[10,0]],"id":52671560}],"con":true,"img":false}]}
{"op":"mcm","clk":"11450331978","pt":1717320642622,"mc":[{"id":"1.229554913","rc":[{"atl":[[300,2]],"id":52671543}],"con":true,"img":false}]}
{"op":"mcm","clk":"11450332049","pt":1717320643404,"mc":[{"id":"1.229554913","rc":[{"atb":[[8,3.46],[8.4,18.11]],"id":52671561}],"con":true,"img":false}]}
{"op":"mcm","clk":"11450332144","pt":1717320644497,"mc":[{"id":"1.229554913","rc":[{"atb":[[12,0],[12.5,3.13]],"id":52237627},{"atl":[[36,3.49],[38,0]],"id":52237627},{"atl":[[690,3.97]],"id":52671562},{"atl":[[36,2.9],[38,0]],"id":52671564},{"atl":[[60,4.59]],"id":52671561},{"atb":[[3.4,6.53],[3.3,34.12]],"id":52237612},{"atl":[[700,0],[690,3.97]],"id":52671547},{"atl":[[36,3.62],[38,0]],"id":52237617},{"atl":[[36,3.75],[38,0]],"id":52671549},{"atb":[[9,2.74],[8.8,10.06]],"id":52237634}],"con":true,"img":false}]}
{"op":"mcm","clk":"11450332206","pt":1717320645382,"mc":[{"id":"1.229554913","rc":[{"atb":[[15,16.44]],"id":52237634}],"con":true,"img":false}]}
{"op":"mcm","clk":"11450332225","pt":1717320645588,"mc":[{"id":"1.229554913","rc":[{"atl":[[310,5],[320,0.5]],"id":52671562},{"atl":[[10.5,0],[9.4,24.08]],"id":52671560},{"atb":[[5.1,18.98],[5.2,5]],"id":52237612},{"atl":[[300,5],[310,0.51]],"id":52671547},{"atb":[[9.2,0],[9.4,5]],"id":52237617}],"con":true,"img":false}]}
{"op":"mcm","clk":"11450332257","pt":1717320645999,"mc":[{"id":"1.229554913","rc":[{"atl":[[310,5.52]],"id":52671562},{"atb":[[5.2,39.76]],"id":52237612},{"atl":[[300,5.54]],"id":52671547}],"con":true,"img":false}]}
{"op":"mcm","clk":"11450332276","pt":1717320646206,"mc":[{"id":"1.229554913","rc":[{"atb":[[12.5,0]],"id":52237634}],"con":true,"img":false}]}
{"op":"mcm","clk":"11450332304","pt":1717320646524,"mc":[{"id":"1.229554913","rc":[{"atb":[[65,3.17]],"id":52671562},{"atb":[[44,1.83]],"id":52671547},{"atb":[[4,29.97],[3.95,0]],"id":52671542}],"con":true,"img":false}]}
{"op":"mcm","clk":"11450332313","pt":1717320646634,"mc":[{"id":"1.229554913","rc":[{"atb":[[160,0],[80,0],[110,5],[55,0]],"id":52237621},{"atb":[[130,5],[65,0],[180,0],[90,0]],"id":52671552},{"atb":[[34,0],[85,0],[44,0],[60,0]],"id":52671547},{"atb":[[11,0],[13.5,0],[8.4,0],[9.4,0]],"id":52671549},{"atb":[[4,12.53],[4.5,0],[3.5,41.81],[3.75,0]],"id":52671542}],"con":true,"img":false}]}
{"op":"mcm","clk":"11450332331","pt":1717320646829,"mc":[{"id":"1.229554913","rc":[{"atl":[[320,0]],"id":52671562},{"atb":[[5.1,0]],"id":52237612},{"atl":[[310,0]],"id":52671547}],"con":true,"img":false}]}
{"op":"mcm","clk":"11450332347","pt":1717320646990,"mc":[{"id":"1.229554913","rc":[{"atb":[[110,6.47]],"id":52237621},{"atb":[[130,6.24]],"id":52671552},{"atb":[[55,5]],"id":52671547},{"atb":[[10.5,19.49]],"id":52671549},{"atb":[[4.1,22.39]],"id":52671542}],"con":true,"img":false}]}
{"op":"mcm","clk":"11450332366","pt":1717320647300,"mc":[{"id":"1.229554913","rc":[{"atb":[[140,0.38],[70,1.52],[190,0.14],[95,0.84]],"id":52237621},{"atb":[[140,0.38],[70,1.52],[95,5.23],[190,0.14]],"id":52671552},{"atb":[[75,0.71],[40,2.68],[100,0.27],[50,1.6]],"id":52671547},{"atb":[[12,4.76],[9.8,8.92],[8.8,13.41],[14.5,1.94]],"id":52671549},{"atb":[[4.6,7.27],[4.1,39.28],[3.8,28.03],[3.55,41.03]],"id":52671542}],"con":true,"img":false}]}
{"op":"mcm","clk":"11450332392","pt":1717320647719,"mc":[{"id":"1.229554913","rc":[{"atb":[[42,0]],"id":52237621},{"atl":[[730,2],[780,0]],"id":52237621},{"atb":[[110,2.88]],"id":52671552},{"atl":[[860,2],[920,0]],"id":52671552},{"atl":[[380,2],[400,0]],"id":52671547},{"atb":[[10,0]],"id":52671549},{"atb":[[4,5]],"id":52671542}],"con":true,"img":false}]}
{"op":"mcm","clk":"11450332485","pt":1717320649115,"mc":[{"id":"1.229554913","rc":[{"atl":[[11.5,3.1]],"id":52671545}],"con":true,"img":false}]}
{"op":"mcm","clk":"11450332546","pt":1717320650104,"mc":[{"id":"1.229554913","rc":[{"atl":[[10.5,2.68]],"id":52671560}],"con":true,"img":false}]}
{"op":"mcm","clk":"11450332721","pt":1717320652808,"mc":[{"id":"1.229554913","rc":[{"atb":[[12,4.17],[12.5,0]],"id":52237627},{"atb":[[3.4,0]],"id":52237612},{"atl":[[710,4.3]],"id":52671547},{"atb":[[9,0],[8.8,13.45]],"id":52237634},{"atl":[[42,3.54]],"id":52237634}],"con":true,"img":false}]}
{"op":"mcm","clk":"11450333125","pt":1717320658328,"mc":[{"id":"1.229554913","rc":[{"atl":[[12,0]],"id":52671560}],"con":true,"img":false}]}
{"op":"mcm","clk":"11450333248","pt":1717320660052,"mc":[{"id":"1.229554913","rc":[{"atb":[[140,0],[70,0],[190,0],[95,0]],"id":52237621},{"atb":[[140,0],[70,0],[190,0],[95,4.38],[110,0]],"id":52671552},{"atl":[[730,0]],"id":52671547}],"con":true,"img":false}]}
{"op":"mcm","clk":"11450333276","pt":1717320660323,"mc":[{"id":"1.229554913","rc":[{"atb":[[6.2,0],[8.2,0]],"id":52237627},{"atb":[[290,0],[190,0]],"id":52671562},{"atb":[[6.2,0],[8.2,0]],"id":52671564},{"atb":[[75,0],[40,0]],"id":52237621},{"atb":[[10.5,0],[8.2,0]],"id":52671561},{"atb":[[3,0],[3.5,0]],"id":52671560},{"atb":[[2.58,0],[2.78,0]],"id":52237612},{"atb":[[75,0],[40,0]],"id":52671552},{"atb":[[290,0],[190,0]],"id":52671547},{"atb":[[6.2,0],[8.2,0]],"id":52237617},{"atb":[[6.2,0],[8.2,0]],"id":52671549},{"atb":[[18,0],[13,0]],"id":52671543},{"atb":[[3,0],[3.5,0]],"id":52671542},{"atb":[[2.58,0],[2.78,0]],"id":52671545},{"atb":[[4.8,0],[5.8,0]],"id":52237634}],"con":true,"img":false}]}
{"op":"mcm","clk":"11450333309","pt":1717320660743,"mc":[{"id":"1.229554913","rc":[{"atb":[[70,5]],"id":52671562},{"atb":[[170,0.16],[85,0.94],[120,0.44],[60,1.77]],"id":52237621},{"atl":[[240,5.67]],"id":52237621},{"atb":[[170,0.16],[85,0.94],[120,0.44],[60,1.77]],"id":52671552},{"atl":[[270,5.6]],"id":52671552}],"con":true,"img":false}]}
{"op":"mcm","clk":"11450333315","pt":1717320660844,"mc":[{"id":"1.229554913","rc":[{"atl":[[860,0],[920,2]],"id":52671552}],"con":true,"img":false}]}
{"op":"mcm","clk":"11450333336","pt":1717320661156,"mc":[{"id":"1.229554913","rc":[{"atb":[[18,0],[10.5,4.68],[12,0],[12.5,3.45],[13,11.94],[15.5,0]],"id":52237627},{"atb":[[65,0],[70,8.09]],"id":52671562},{"atb":[[3.4,6.53]],"id":52237612},{"atb":[[100,3.92]],"id":52671552},{"atb":[[9,3.09],[8.8,10.06]],"id":52237634}],"con":true,"img":false}]}
{"op":"mcm","clk":"11450333357","pt":1717320661421,"mc":[{"id":"1.229554913","rc":[{"atl":[[36,0],[38,3.92]],"id":52237627},{"atl":[[690,0]],"id":52671562},{"atl":[[36,0],[38,2.78]],"id":52671564},{"atb":[[8.6,9.47],[8.4,14.66]],"id":52671561},{"atl":[[60,0]],"id":52671561},{"atl":[[690,0],[700,3.42]],"id":52671547},{"atl":[[36,0],[38,3.08]],"id":52237617},{"atl":[[36,0],[38,4.05]],"id":52671549}],"con":true,"img":false}]}
{"op":"mcm","clk":"11450333370","pt":1717320661529,"mc":[{"id":"1.229554913","rc":[{"atb":[[170,0],[85,0],[120,0],[60,0]],"id":52237621},{"atl":[[400,0],[240,5]],"id":52237621},{"atl":[[270,5],[400,0]],"id":52671552}],"con":true,"img":false}]}
{"op":"mcm","clk":"11450333398","pt":1717320661837,"mc":[{"id":"1.229554913","rc":[{"atb":[[16,3.49],[18.5,1.5],[11,10.46],[13.5,6.28]],"id":52237627}],"con":true,"img":false}]}
{"op":"mcm","clk":"11450333425","pt":1717320662261,"mc":[{"id":"1.229554913","rc":[{"atb":[[130,0.41],[65,1.64],[180,0.15],[90,0.88]],"id":52237621}],"con":true,"img":false}]}
{"op":"mcm","clk":"11450333489","pt":1717320663050,"mc":[{"id":"1.229554913","rc":[{"atl":[[690,4.1]],"id":52671562},{"atl":[[380,4.27]],"id":52237621},{"atl":[[65,3.82]],"id":52671561},{"atl":[[380,4.52],[410,0]],"id":52671552},{"atl":[[690,4.12]],"id":52671547}],"con":true,"img":false}]}
{"op":"mcm","clk":"11450333497","pt":1717320663149,"mc":[{"id":"1.229554913","rc":[{"atl":[[410,0]],"id":52237621},{"atl":[[700,0]],"id":52671547}],"con":true,"img":false}]}
{"op":"mcm","clk":"11450333869","pt":1717320667826,"mc":[{"id":"1.229554913","rc":[{"atl":[[23,12.28],[24,0]],"id":52237617}],"con":true,"img":false}]}
{"op":"mcm","clk":"11450333963","pt":1717320669131,"mc":[{"id":"1.229554913","rc":[{"atb":[[3.3,40.94]],"id":52237612},{"atb":[[8.6,3.43]],"id":52237634}],"con":true,"img":false}]}
{"op":"mcm","clk":"11450334001","pt":1717320669447,"mc":[{"id":"1.229554913","rc":[{"atb":[[11.5,3.18]],"id":52237627}],"con":true,"img":false}]}
{"op":"mcm","clk":"11450334087","pt":1717320670735,"mc":[{"id":"1.229554913","rc":[{"atb":[[10.5,14.49],[11,5]],"id":52671549}],"con":true,"img":false}]}
{"op":"mcm","clk":"11450334101","pt":1717320670945,"mc":[{"id":"1.229554913","rc":[{"atl":[[400,3.85]],"id":52237621},{"atl":[[400,4.41]],"id":52671552}],"con":true,"img":false}]}
{"op":"mcm","clk":"11450334365","pt":1717320674090,"mc":[{"id":"1.229554913","rc":[{"atb":[[6.2,46.9],[8.2,14.51]],"id":52237627},{"atb":[[290,0.36],[190,1.29]],"id":52671562},{"atb":[[6.2,46.9],[8.2,14.51]],"id":52671564},{"atb":[[75,1.41],[40,6.25]],"id":52237621},{"atb":[[10.5,11],[8.2,33.87]],"id":52671561},{"atb":[[3,121.95],[3.5,41.81]],"id":52671560},{"atb":[[2.58,154.36],[2.78,58.72]],"id":52237612},{"atb":[[75,1.41],[40,6.25]],"id":52671552},{"atb":[[290,0.36],[190,1.29]],"id":52671547},{"atb":[[6.2,46.9],[8.2,14.51]],"id":52237617},{"atb":[[6.2,46.9],[8.2,14.51]],"id":52671549},{"atb":[[18,6.14],[13,20.32]],"id":52671543},{"atb":[[3,121.95],[3.5,41.81]],"id":52671542},{"atb":[[2.58,154.36],[2.78,58.72]],"id":52671545},{"atb":[[4.8,64.18],[5.8,21.77]],"id":52237634}],"con":true,"img":false}]}
{"op":"mcm","clk":"11450334405","pt":1717320674432,"mc":[{"id":"1.229554913","rc":[{"atb":[[10.5,0]],"id":52237627},{"atl":[[690,0],[680,3.09]],"id":52671562},{"atl":[[360,3.9],[380,0],[440,0]],"id":52237621},{"atb":[[3.2,0]],"id":52237612},{"atl":[[360,3.06],[380,0],[850,2],[440,0],[920,0]],"id":52671552},{"atl":[[690,0],[680,3.87]],"id":52671547},{"atb":[[8.2,0]],"id":52237634}],"con":true,"img":false}]}
{"op":"mcm","clk":"11450334815","pt":1717320678850,"mc":[{"id":"1.229554913","rc":[{"atl":[[34,3.03]],"id":52671561},{"atb":[[5.1,5],[5.2,0]],"id":52237612}],"con":true,"img":false}]}
{"op":"mcm","clk":"11450334836","pt":1717320679154,"mc":[{"id":"1.229554913","rc":[{"atl":[[38,0]],"id":52237627},{"atl":[[310,0],[320,5],[680,0],[690,3.09]],"id":52671562},{"atl":[[36,3.67],[38,0]],"id":52671564},{"atb":[[130,0],[65,0],[180,0],[90,0]],"id":52237621},{"atl":[[360,0],[380,3.8]],"id":52237621},{"atb":[[4.9,4.01],[4.7,0]],"id":52671560},{"atb":[[3.35,6.68],[3.4,0]],"id":52237612},{"atl":[[360,0],[380,4.48]],"id":52671552},{"atl":[[680,0],[690,4.37]],"id":52671547},{"atl":[[38,0]],"id":52237617},{"atl":[[36,3.63],[38,0]],"id":52671549}],"con":true,"img":false}]}
{"op":"mcm","clk":"11450334844","pt":1717320679257,"mc":[{"id":"1.229554913","rc":[{"atb":[[4.8,0],[4.7,5]],"id":52671545}],"con":true,"img":false}]}
{"op":"mcm","clk":"11450334863","pt":1717320679668,"mc":[{"id":"1.229554913","rc":[{"atl":[[36,9.58]],"id":52671561},{"atb":[[3.95,17.6]],"id":52237612}],"con":true,"img":false}]}
{"op":"mcm","clk":"11450334869","pt":1717320679775,"mc":[{"id":"1.229554913","rc":[{"atb":[[12,0],[9.8,0],[8.8,0],[14.5,0]],"id":52671549}],"con":true,"img":false}]}
{"op":"mcm","clk":"11450334876","pt":1717320679878,"mc":[{"id":"1.229554913","rc":[{"atl":[[410,0.39]],"id":52671562},{"atb":[[16,0],[11,4.21],[13.5,0],[9.4,0]],"id":52671564},{"atb":[[170,0.16],[85,0.94],[120,0.44],[60,1.77]],"id":52237621},{"atl":[[270,0],[260,5]],"id":52671552}],"con":true,"img":false}]}
{"op":"mcm","clk":"11450334881","pt":1717320679981,"mc":[{"id":"1.229554913","rc":[{"atl":[[310,5],[320,0]],"id":52671562},{"atb":[[4.8,5],[3.85,15.05],[4.7,0]],"id":52671545}],"con":true,"img":false}]}
{"op":"mcm","clk":"11450334899","pt":1717320680142,"mc":[{"id":"1.229554913","rc":[{"atb":[[11,15.32]],"id":52671549}],"con":true,"img":false}]}
{"op":"mcm","clk":"11450334922","pt":1717320680452,"mc":[{"id":"1.229554913","rc":[{"atb":[[9.6,12.4],[8.6,13.77],[11.5,4.98],[14,2.01]],"id":52671549}],"con":true,"img":false}]}
{"op":"mcm","clk":"11450334930","pt":1717320680553,"mc":[{"id":"1.229554913","rc":[{"atb":[[9.2,12.76],[10.5,10.96],[13,4.36],[15.5,1.81]],"id":52671564}],"con":true,"img":false}]}
{"op":"mcm","clk":"11450334939","pt":1717320680656,"mc":[{"id":"1.229554913","rc":[{"atl":[[320,5]],"id":52671562},{"atb":[[4.8,0],[4.7,5]],"id":52671545}],"con":true,"img":false}]}
{"op":"mcm","clk":"11450334945","pt":1717320680763,"mc":[{"id":"1.229554913","rc":[{"atl":[[310,0]],"id":52671562}],"con":true,"img":false}]}
{"op":"mcm","clk":"11450334957","pt":1717320680878,"mc":[{"id":"1.229554913","rc":[{"atb":[[10.5,3.99]],"id":52671549}],"con":true,"img":false}]}
{"op":"mcm","clk":"11450334967","pt":1717320680968,"mc":[{"id":"1.229554913","rc":[{"atl":[[36,0],[38,2.89]],"id":52671564},{"atl":[[34,8.03],[36,4.57]],"id":52671561},{"atb":[[3.35,0],[3.3,34.12]],"id":52237612},{"atl":[[38,4.35]],"id":52237617},{"atb":[[9,0],[8.8,13.47]],"id":52237634}],"con":true,"img":false}]}
{"op":"mcm","clk":"11450335007","pt":1717320681453,"mc":[{"id":"1.229554913","rc":[{"atl":[[320,0]],"id":52671562}],"con":true,"img":false}]}
{"op":"mcm","clk":"11450335012","pt":1717320681564,"mc":[{"id":"1.229554913","rc":[{"atl":[[680,2],[420,0]],"id":52671562},{"atl":[[22,5],[23,7.28]],"id":52671564},{"atl":[[6.8,0],[7,5]],"id":52671542}],"con":true,"img":false}]}
{"op":"mcm","clk":"11450335019","pt":1717320681662,"mc":[{"id":"1.229554913","rc":[{"atl":[[34,3.03],[36,9.58]],"id":52671561}],"con":true,"img":false}]}
{"op":"mcm","clk":"11450335058","pt":1717320682171,"mc":[{"id":"1.229554913","rc":[{"atl":[[310,5]],"id":52671562},{"atl":[[22,12.63]],"id":52671564}],"con":true,"img":false}]}
{"op":"mcm","clk":"11450335063","pt":1717320682275,"mc":[{"id":"1.229554913","rc":[{"atl":[[6.8,5],[7,0],[28,5.93]],"id":52671542}],"con":true,"img":false}]}
{"op":"mcm","clk":"11450335070","pt":1717320682379,"mc":[{"id":"1.229554913","rc":[{"atl":[[680,0],[440,2]],"id":52671562}],"con":true,"img":false}]}
{"op":"mcm","clk":"11450335079","pt":1717320682439,"mc":[{"id":"1.229554913","rc":[{"atl":[[22,7.62],[23,12.28]],"id":52671564}],"con":true,"img":false}]}
{"op":"mcm","clk":"11450335087","pt":1717320682588,"mc":[{"id":"1.229554913","rc":[{"atb":[[15,11.44],[15.5,5]],"id":52237634}],"con":true,"img":false}]}
{"op":"mcm","clk":"11450335119","pt":1717320682952,"mc":[{"id":"1.229554913","rc":[{"atl":[[22,0],[23,5]],"id":52671564}],"con":true,"img":false}]}
{"op":"mcm","clk":"11450335127","pt":1717320683074,"mc":[{"id":"1.229554913","rc":[{"atb":[[15.5,16.05]],"id":52237634}],"con":true,"img":false}]}
{"op":"mcm","clk":"11450335181","pt":1717320683670,"mc":[{"id":"1.229554913","rc":[{"atl":[[36,4.57]],"id":52671564}],"con":true,"img":false}]}
{"op":"mcm","clk":"11450335188","pt":1717320683774,"mc":[{"id":"1.229554913","rc":[{"atb":[[15,0]],"id":52237634}],"con":true,"img":false}]}
{"op":"mcm","clk":"11450335244","pt":1717320684661,"mc":[{"id":"1.229554913","rc":[{"atl":[[850,0],[910,2]],"id":52671552}],"con":true,"img":false}]}
{"op":"mcm","clk":"11450335263","pt":1717320684974,"mc":[{"id":"1.229554913","rc":[{"atl":[[9.6,4.44],[9.8,0]],"id":52671560},{"atb":[[290,0]],"id":52671547},{"trd":[[290,0.72]],"ltp":290.0,"tv":0.72,"id":52671547},{"atb":[[9.6,0],[9.8,4.57]],"id":52237617}],"con":true,"img":false}]}
{"op":"mcm","clk":"11450335297","pt":1717320685449,"mc":[{"id":"1.229554913","rc":[{"atb":[[75,0],[40,0],[100,0],[50,0]],"id":52671547}],"con":true,"img":false}]}
{"op":"mcm","clk":"11450335355","pt":1717320686170,"mc":[{"id":"1.229554913","rc":[{"atb":[[32,2.53],[42,1.28],[26,4.19],[55,5.49]],"id":52671547}],"con":true,"img":false}]}
{"op":"mcm","clk":"11450335391","pt":1717320686539,"mc":[{"id":"1.229554913","rc":[{"atl":[[44,3.39]],"id":52237627}],"con":true,"img":false}]}
{"op":"mcm","clk":"11450335518","pt":1717320688247,"mc":[{"id":"1.229554913","rc":[{"atl":[[24,5],[25,6.67]],"id":52237627},{"atb":[[15,5],[15.5,0]],"id":52237634}],"con":true,"img":false}]}
{"op":"mcm","clk":"11450335558","pt":1717320688773,"mc":[{"id":"1.229554913","rc":[{"atl":[[24,11.97]],"id":52237627}],"con":true,"img":false}]}
{"op":"mcm","clk":"11450335582","pt":1717320689086,"mc":[{"id":"1.229554913","rc":[{"atb":[[12.5,10.48]],"id":52237634}],"con":true,"img":false}]}
{"op":"mcm","clk":"11450335623","pt":1717320689560,"mc":[{"id":"1.229554913","rc":[{"atl":[[25,0]],"id":52237627}],"con":true,"img":false}]}
{"op":"mcm","clk":"11450335689","pt":1717320690451,"mc":[{"id":"1.229554913","rc":[{"atb":[[4.9,5],[4.7,0]],"id":52671545}],"con":true,"img":false}]}
{"op":"mcm","clk":"11450335753","pt":1717320691385,"mc":[{"id":"1.229554913","rc":[{"atl":[[34,7.88]],"id":52671561},{"atb":[[5.1,39.76]],"id":52237612}],"con":true,"img":false}]}
{"op":"mcm","clk":"11450335765","pt":1717320691584,"mc":[{"id":"1.229554913","rc":[{"atl":[[300,0.53]],"id":52671562}],"con":true,"img":false}]}
{"op":"mcm","clk":"11450335772","pt":1717320691688,"mc":[{"id":"1.229554913","rc":[{"atb":[[4.9,20.05]],"id":52671545}],"con":true,"img":false}]}
{"op":"mcm","clk":"11450335792","pt":1717320691951,"mc":[{"id":"1.229554913","rc":[{"atb":[[290,0]],"id":52671562},{"trd":[[290,0.72]],"ltp":290.0,"tv":0.72,"id":52671562}],"con":true,"img":false}]}
{"op":"mcm","clk":"11450335808","pt":1717320692160,"mc":[{"id":"1.229554913","rc":[{"atl":[[36,5]],"id":52671561},{"atb":[[3.95,0]],"id":52237612}],"con":true,"img":false}]}
{"op":"mcm","clk":"11450335812","pt":1717320692263,"mc":[{"id":"1.229554913","rc":[{"atl":[[410,0]],"id":52671562}],"con":true,"img":false}]}
{"op":"mcm","clk":"11450335830","pt":1717320692467,"mc":[{"id":"1.229554913","rc":[{"atb":[[80,0],[42,0],[110,0],[55,2.9]],"id":52671562},{"atb":[[3.85,0]],"id":52671545}],"con":true,"img":false}]}
{"op":"mcm","clk":"11450335838","pt":1717320692576,"mc":[{"id":"1.229554913","rc":[{"atb":[[9.4,9.34]],"id":52237617}],"con":true,"img":false}]}
{"op":"mcm","clk":"11450335878","pt":1717320693194,"mc":[{"id":"1.229554913","rc":[{"atb":[[70,8.47],[38,2.12],[48,1.11],[29,3.74]],"id":52671562}],"con":true,"img":false}]}
{"op":"mcm","clk":"11450335943","pt":1717320693874,"mc":[{"id":"1.229554913","rc":[{"atl":[[23,12.28]],"id":52671564}],"con":true,"img":false}]}
{"op":"mcm","clk":"11450335953","pt":1717320693976,"mc":[{"id":"1.229554913","rc":[{"atl":[[6.8,21.43]],"id":52671542}],"con":true,"img":false}]}
{"op":"mcm","clk":"11450335958","pt":1717320694079,"mc":[{"id":"1.229554913","rc":[{"atb":[[170,0],[85,0],[100,0],[110,4.65],[120,0],[60,0]],"id":52671552},{"atb":[[9,6.54]],"id":52237617}],"con":true,"img":false}]}
{"op":"mcm","clk":"11450335992","pt":1717320694553,"mc":[{"id":"1.229554913","rc":[{"atl":[[36,0]],"id":52671564}],"con":true,"img":false}]}
{"op":"mcm","clk":"11450336000","pt":1717320694679,"mc":[{"id":"1.229554913","rc":[{"atl":[[28,0]],"id":52671542},{"atb":[[15.5,11.04]],"id":52237634}],"con":true,"img":false}]}
{"op":"mcm","clk":"11450336007","pt":1717320694760,"mc":[{"id":"1.229554913","rc":[{"atb":[[140,0.38],[70,1.52],[95,5.23],[190,0.14]],"id":52671552}],"con":true,"img":false}]}
{"op":"mcm","clk":"11450336054","pt":1717320695372,"mc":[{"id":"1.229554913","rc":[{"atb":[[12.5,0]],"id":52237634}],"con":true,"img":false}]}
{"op":"mcm","clk":"11450336136","pt":1717320696669,"mc":[{"id":"1.229554913","rc":[{"atl":[[410,2],[440,0]],"id":52671562},{"atl":[[850,2],[910,0]],"id":52671552}],"con":true,"img":false}]}
{"op":"mcm","clk":"11450336158","pt":1717320696977,"mc":[{"id":"1.229554913","rc":[{"atb":[[140,0],[70,0],[190,0],[95,4.38],[100,4.59],[110,0]],"id":52671552}],"con":true,"img":false}]}
{"op":"mcm","clk":"11450336180","pt":1717320697387,"mc":[{"id":"1.229554913","rc":[{"atl":[[290,5],[310,0]],"id":52671562},{"atb":[[5.1,34.75],[5.3,5]],"id":52237612},{"atl":[[300,0.53],[290,5]],"id":52671547},{"atb":[[9.6,5],[9.4,4.33]],"id":52237617}],"con":true,"img":false}]}
{"op":"mcm","clk":"11450336188","pt":1717320697494,"mc":[{"id":"1.229554913","rc":[{"atl":[[850,0],[910,2]],"id":52671552}],"con":true,"img":false}]}
{"op":"mcm","clk":"11450336197","pt":1717320697596,"mc":[{"id":"1.229554913","rc":[{"atl":[[850,2],[910,0]],"id":52671552}],"con":true,"img":false}]}
{"op":"mcm","clk":"11450336213","pt":1717320697762,"mc":[{"id":"1.229554913","rc":[{"atl":[[42,3.67]],"id":52237627},{"atl":[[690,0],[700,0]],"id":52671562},{"atl":[[380,0]],"id":52237621},{"atl":[[280,0.57]],"id":52671547},{"atl":[[38,0]],"id":52237617}],"con":true,"img":false}]}
{"op":"mcm","clk":"11450336219","pt":1717320697864,"mc":[{"id":"1.229554913","rc":[{"atl":[[40,0]],"id":52237627},{"atb":[[140,0.38],[70,1.52],[95,5.23],[190,0.14]],"id":52671552},{"atl":[[690,0],[710,0]],"id":52671547}],"con":true,"img":false}]}
{"op":"mcm","clk":"11450336226","pt":1717320697966,"mc":[{"id":"1.229554913","rc":[{"atl":[[260,5.62]],"id":52671552}],"con":true,"img":false}]}
{"op":"mcm","clk":"11450336264","pt":1717320698486,"mc":[{"id":"1.229554913","rc":[{"atl":[[300,0]],"id":52671547}],"con":true,"img":false}]}
{"op":"mcm","clk":"11450336281","pt":1717320698694,"mc":[{"id":"1.229554913","rc":[{"atl":[[260,5]],"id":52671552}],"con":true,"img":false}]}
{"op":"mcm","clk":"11450336385","pt":1717320700097,"mc":[{"id":"1.229554913","rc":[{"atl":[[44,4.19]],"id":52237617}],"con":true,"img":false}]}
{"op":"mcm","clk":"11450336567","pt":1717320702181,"mc":[{"id":"1.229554913","rc":[{"atb":[[6.2,0],[8.2,0]],"id":52237627},{"atb":[[190,0]],"id":52671562},{"atb":[[6.2,0],[8.2,0]],"id":52671564},{"atb":[[75,0],[40,0]],"id":52237621},{"atb":[[10.5,0],[8.2,0]],"id":52671561},{"atb":[[3,0],[3.5,0]],"id":52671560},{"atb":[[2.58,0],[2.78,0]],"id":52237612},{"atb":[[75,0],[40,0]],"id":52671552},{"atb":[[190,0]],"id":52671547},{"atb":[[6.2,0],[8.2,0]],"id":52237617},{"atb":[[6.2,0],[8.2,0]],"id":52671549},{"atb":[[18,0],[13,0]],"id":52671543},{"atb":[[3,0],[3.5,0]],"id":52671542},{"atb":[[2.58,0],[2.78,0]],"id":52671545},{"atb":[[4.8,0],[5.8,0]],"id":52237634}],"con":true,"img":false}]}
{"op":"mcm","clk":"11450336589","pt":1717320702491,"mc":[{"id":"1.229554913","rc":[{"atl":[[720,3.71],[740,2.89]],"id":52671562},{"atb":[[5.3,0],[5.2,5]],"id":52237612},{"atb":[[100,0],[110,2.78]],"id":52671552},{"atl":[[720,4.19],[740,2.84]],"id":52671547}],"con":true,"img":false}]}
{"op":"mcm","clk":"11450336602","pt":1717320702701,"mc":[{"id":"1.229554913","rc":[{"atl":[[40,3.76],[42,0]],"id":52237627},{"atb":[[70,10.79],[75,0.38]],"id":52671562},{"atl":[[730,3.99],[750,2.75]],"id":52671562},{"atl":[[65,0]],"id":52671561},{"atb":[[55,8.46],[60,0.38]],"id":52671547},{"atl":[[730,4.7],[750,3.94]],"id":52671547},{"atl":[[36,0],[38,3.14]],"id":52671549}],"con":true,"img":false}]}
{"op":"mcm","clk":"11450336617","pt":1717320702869,"mc":[{"id":"1.229554913","rc":[{"atb":[[5.2,22.61]],"id":52237612}],"con":true,"img":false}]}
{"op":"mcm","clk":"11450336633","pt":1717320703077,"mc":[{"id":"1.229554913","rc":[{"atl":[[280,0.57]],"id":52671562}],"con":true,"img":false}]}
{"op":"mcm","clk":"11450336686","pt":1717320703593,"mc":[{"id":"1.229554913","rc":[{"atb":[[5.1,0]],"id":52237612}],"con":true,"img":false}]}
{"op":"mcm","clk":"11450336693","pt":1717320703697,"mc":[{"id":"1.229554913","rc":[{"atl":[[850,0],[910,2]],"id":52671552}],"con":true,"img":false}]}
{"op":"mcm","clk":"11450336702","pt":1717320703799,"mc":[{"id":"1.229554913","rc":[{"atl":[[300,0]],"id":52671562}],"con":true,"img":false}]}
{"op":"mcm","clk":"11450336759","pt":1717320704387,"mc":[{"id":"1.229554913","rc":[{"atl":[[420,4.32]],"id":52237621}],"con":true,"img":false}]}
{"op":"mcm","clk":"11450337219","pt":1717320709771,"mc":[{"id":"1.229554913","rc":[{"atl":[[80,4.36]],"id":52671561}],"con":true,"img":false}]}
{"op":"mcm","clk":"11450337233","pt":1717320709982,"mc":[{"id":"1.229554913","rc":[{"atl":[[720,0],[740,0]],"id":52671562},{"atl":[[720,0],[740,0]],"id":52671547}],"con":true,"img":false}]}
{"op":"mcm","clk":"11450337256","pt":1717320710289,"mc":[{"id":"1.229554913","rc":[{"atl":[[40,0],[42,4.35]],"id":52237627},{"atl":[[730,0],[750,0]],"id":52671562},{"atl":[[36,2.8],[38,0]],"id":52671564},{"atl":[[65,3.82]],"id":52671561},{"atl":[[730,0],[750,0]],"id":52671547},{"atl":[[40,0],[42,2.72]],"id":52237617},{"atl":[[36,4.42],[38,0]],"id":52671549}],"con":true,"img":false}]}
{"op":"mcm","clk":"11450337844","pt":1717320717404,"mc":[{"id":"1.229554913","rc":[{"atl":[[720,3.38],[740,4.56]],"id":52671562},{"atl":[[70,0],[75,3.8],[80,0]],"id":52671561},{"atl":[[720,3.81],[740,4.29]],"id":52671547}],"con":true,"img":false}]}
{"op":"mcm","clk":"11450337870","pt":1717320717708,"mc":[{"id":"1.229554913","rc":[{"atl":[[40,4.5]],"id":52237617}],"con":true,"img":false}]}
{"op":"mcm","clk":"11450337880","pt":1717320717809,"mc":[{"id":"1.229554913","rc":[{"atl":[[760,2.88]],"id":52671562},{"atl":[[36,0],[38,3.66]],"id":52671564},{"atl":[[390,3.55],[400,0]],"id":52237621},{"atb":[[140,0],[70,0],[190,0],[95,4.38],[100,4.03],[110,0]],"id":52671552},{"atl":[[360,3.67],[380,0]],"id":52671552},{"atl":[[690,2.66],[710,4.06]],"id":52671547},{"atl":[[42,0]],"id":52237617},{"atb":[[8.8,10.06]],"id":52237634}],"con":true,"img":false}]}
{"op":"mcm","clk":"11450337943","pt":1717320718497,"mc":[{"id":"1.229554913","rc":[{"atb":[[170,0.16],[85,0.94],[120,0.44],[60,1.77]],"id":52671552},{"atl":[[22,5],[23,7.28]],"id":52237617}],"con":true,"img":false}]}
{"op":"mcm","clk":"11450337984","pt":1717320718905,"mc":[{"id":"1.229554913","rc":[{"atl":[[22,12.63]],"id":52237617}],"con":true,"img":false}]}
{"op":"mcm","clk":"11450338039","pt":1717320719580,"mc":[{"id":"1.229554913","rc":[{"atl":[[23,0]],"id":52237617}],"con":true,"img":false}]}
{"op":"mcm","clk":"11450338357","pt":1717320723328,"mc":[{"id":"1.229554913","rc":[{"atl":[[720,0],[760,0]],"id":52671562},{"atb":[[3.55,41.07],[3.05,119.22]],"id":52671560},{"atb":[[2.8,58.19],[2.6,152.75]],"id":52237612},{"atb":[[200,0.36],[100,1.72]],"id":52671547},{"atl":[[720,0],[740,0]],"id":52671547},{"atb":[[6.2,47],[8.2,14.54]],"id":52237617},{"atb":[[17,6.54],[12,22.21]],"id":52671543},{"atb":[[3.55,82.11],[3.05,119.22]],"id":52671542},{"atb":[[2.8,58.19],[2.6,152.75]],"id":52671545},{"atb":[[8.8,14.73]],"id":52237634}],"con":true,"img":false}]}
{"op":"mcm","clk":"11450338366","pt":1717320723431,"mc":[{"id":"1.229554913","rc":[{"atb":[[3.35,6.68],[3.25,6.97]],"id":52237612}],"con":true,"img":false}]}
{"op":"mcm","clk":"11450338391","pt":1717320723705,"mc":[{"id":"1.229554913","rc":[{"atl":[[40,3.85],[42,0]],"id":52237627},{"atl":[[380,2.68],[390,0]],"id":52237621}],"con":true,"img":false}]}
{"op":"mcm","clk":"11450338486","pt":1717320724792,"mc":[{"id":"1.229554913","rc":[{"atl":[[760,4.11]],"id":52671562},{"atl":[[380,4.35]],"id":52671552}],"con":true,"img":false}]}
{"op":"mcm","clk":"11450338531","pt":1717320725307,"mc":[{"id":"1.229554913","rc":[{"atb":[[75,2.54]],"id":52671562}],"con":true,"img":false}]}
{"op":"mcm","clk":"11450338586","pt":1717320725987,"mc":[{"id":"1.229554913","rc":[{"atb":[[70,8.47]],"id":52671562}],"con":true,"img":false}]}
{"op":"mcm","clk":"11450338593","pt":1717320726086,"mc":[{"id":"1.229554913","rc":[{"atb":[[9.6,3.27],[8.6,0],[11.5,0],[14,0]],"id":52671549}],"con":true,"img":false}]}
{"op":"mcm","clk":"11450338607","pt":1717320726297,"mc":[{"id":"1.229554913","rc":[{"atl":[[400,0]],"id":52671552}],"con":true,"img":false}]}
{"op":"mcm","clk":"11450338642","pt":1717320726804,"mc":[{"id":"1.229554913","rc":[{"atb":[[12,4.76],[9.8,8.92],[8.8,13.41],[14.5,1.94]],"id":52671549}],"con":true,"img":false}]}
{"op":"mcm","clk":"11450338952","pt":1717320730592,"mc":[{"id":"1.229554913","rc":[{"atl":[[400,4.09]],"id":52237621}],"con":true,"img":false}]}
{"op":"mcm","clk":"11450338983","pt":1717320731001,"mc":[{"id":"1.229554913","rc":[{"atl":[[34,12.89],[36,0]],"id":52671561}],"con":true,"img":false}]}
{"op":"mcm","clk":"11450339012","pt":1717320731412,"mc":[{"id":"1.229554913","rc":[{"atl":[[420,0]],"id":52237621}],"con":true,"img":false}]}
{"op":"mcm","clk":"11450339091","pt":1717320732398,"mc":[{"id":"1.229554913","rc":[{"atb":[[15,0],[15.5,16.05]],"id":52237634}],"con":true,"img":false}]}
{"op":"mcm","clk":"11450339210","pt":1717320733906,"mc":[{"id":"1.229554913","rc":[{"atb":[[6.2,47],[8.2,14.54]],"id":52237627},{"atb":[[200,0.36],[100,1.72]],"id":52671562},{"atb":[[6.2,47],[8.2,14.54]],"id":52671564},{"atb":[[48,2.22],[29,8.72]],"id":52237621},{"atb":[[10.5,11.02],[8.2,33.94]],"id":52671561},{"atb":[[48,2.22],[29,8.72]],"id":52671552},{"atb":[[6.2,47],[8.2,14.54]],"id":52671549},{"atb":[[4.8,64.31],[5.8,21.82]],"id":52237634}],"con":true,"img":false}]}
{"op":"mcm","clk":"11450339238","pt":1717320734214,"mc":[{"id":"1.229554913","rc":[{"atl":[[850,2],[910,0]],"id":52671552}],"con":true,"img":false}]}
{"op":"mcm","clk":"11450340062","pt":1717320743844,"mc":[{"id":"1.229554913","rc":[{"atl":[[24,5],[25,5]],"id":52237627},{"atl":[[22,0],[23,5]],"id":52237617}],"con":true,"img":false}]}
{"op":"mcm","clk":"11450340075","pt":1717320743941,"mc":[{"id":"1.229554913","rc":[{"atl":[[24,0]],"id":52237627}],"con":true,"img":false}]}
{"op":"mcm","clk":"11450340125","pt":1717320744517,"mc":[{"id":"1.229554913","rc":[{"atl":[[38,4.33]],"id":52237627},{"atl":[[30,5.52]],"id":52237617}],"con":true,"img":false}]}
{"op":"mcm","clk":"11450340159","pt":1717320745034,"mc":[{"id":"1.229554913","rc":[{"atb":[[11,0]],"id":52671549},{"atl":[[21,0]],"id":52671549}],"con":true,"img":false}]}
{"op":"mcm","clk":"11450340167","pt":1717320745140,"mc":[{"id":"1.229554913","rc":[{"atb":[[13,0]],"id":52237627},{"atl":[[25,0]],"id":52237627},{"atb":[[70,3.08],[75,0],[38,0],[48,0],[29,0]],"id":52671562},{"atl":[[280,0],[290,0]],"id":52671562},{"atb":[[11.5,0]],"id":52671564},{"atl":[[23,0]],"id":52671564},{"atb":[[110,0]],"id":52237621},{"atl":[[240,0]],"id":52237621},{"atb":[[8.6,4.46],[8.4,10.61]],"id":52671561},{"atl":[[34,3.03]],"id":52671561},{"atb":[[6.8,0]],"id":52671560},{"atl":[[9.4,0]],"id":52671560},{"atb":[[3.8,0],[5.2,0],[3.55,0],[3.3,0],[3.05,0]],"id":52237612},{"atl":[[10,0],[9.8,0]],"id":52237612},{"atb":[[130,0],[170,0],[85,0],[120,0],[60,0]],"id":52671552},{"atl":[[260,0]],"id":52671552},{"atb":[[55,0.49],[60,0]],"id":52671547},{"atl":[[280,0],[290,0]],"id":52671547},{"atb":[[9.6,0],[10,2.91]],"id":52237617},{"atl":[[23,0]],"id":52237617},{"atb":[[32,0],[34,0],[42,0],[26,0],[55,0]],"id":52671543},{"atl":[[85,4.22],[100,3.61]],"id":52671543},{"atb":[[4,0],[4.1,21.94]],"id":52671542},{"atl":[[6.8,0]],"id":52671542},{"atb":[[3.8,0],[4.9,0],[3.55,0],[3.3,0],[3.05,0]],"id":52671545},{"atl":[[9.8,0],[8.4,0]],"id":52671545},{"atb":[[15.5,0]],"id":52237634},{"atl":[[34,0],[36,0]],"id":52237634}],"con":true,"img":false}]}
{"op":"mcm","clk":"11450340176","pt":1717320745247,"mc":[{"id":"1.229554913","rc":[{"atl":[[38,0]],"id":52237627},{"atb":[[32,0],[42,0],[26,0],[55,0]],"id":52671547},{"atl":[[30,0]],"id":52237617},{"atl":[[32,0],[36,7.28]],"id":52671549}],"con":true,"img":false}]}
{"op":"mcm","clk":"11450340186","pt":1717320745353,"mc":[{"id":"1.229554913","rc":[{"atl":[[70,0],[60,2]],"id":52237627},{"atl":[[730,2],[410,0]],"id":52671562},{"atl":[[40,6.12],[44,0]],"id":52671564},{"atl":[[34,0],[60,2]],"id":52671561},{"atb":[[3.4,32.86],[3.9,0]],"id":52237612},{"atb":[[36,0],[42,2.44]],"id":52671552},{"atl":[[690,4.66],[380,0]],"id":52671547},{"atl":[[32,0],[34,3.03]],"id":52237617}],"con":true,"img":false}]}
{"op":"mcm","clk":"11450340194","pt":1717320745451,"mc":[{"id":"1.229554913","rc":[{"atl":[[690,2.66],[700,2]],"id":52671547},{"atl":[[34,0],[38,2.7]],"id":52237617}],"con":true,"img":false}]}
{"op":"mcm","clk":"11450340229","pt":1717320745824,"mc":[{"id":"1.229554913","rc":[{"atb":[[80,0.66],[42,2.55],[55,4.36],[110,0.24]],"id":52671562},{"atb":[[3,52.32],[3.25,41.85],[3.5,20.93],[3.75,9.51]],"id":52237612},{"atb":[[160,0.16],[80,0.99],[110,0.48],[55,1.94]],"id":52671552},{"atb":[[38,1.41],[48,0.55],[24,4.55],[29,2.8]],"id":52671543},{"atb":[[3.6,10.06],[3.1,37.37],[3.35,22.26],[2.94,53.93]],"id":52671545}],"con":true,"img":false}]}
{"op":"mcm","clk":"11450340236","pt":1717320745928,"mc":[{"id":"1.229554913","rc":[{"atb":[[3.4,0],[3.8,20.93]],"id":52237612},{"atb":[[75,0.71],[40,2.68],[100,1.99],[50,1.6]],"id":52671547}],"con":true,"img":false}]}
{"op":"mcm","clk":"11450340936","pt":1717320754738,"mc":[{"id":"1.229554913","rc":[{"atb":[[5.8,0],[5.2,23.81]],"id":52237627},{"atl":[[75,2],[60,0]],"id":52237627},{"atl":[[40,3.56],[55,2]],"id":52671564},{"atl":[[730,0],[950,2]],"id":52237621},{"atb":[[4,0],[3.7,37.04]],"id":52671560},{"atl":[[17.5,0],[21,5]],"id":52671560},{"atl":[[850,0]],"id":52671552},{"atl":[[38,0],[44,6.52]],"id":52237617},{"atl":[[36,4.42],[46,2.22]],"id":52671549},{"atl":[[300,0],[370,2]],"id":52671543},{"atl":[[18,0],[22,4.76]],"id":52671545}],"con":true,"img":false}]}
{"op":"mcm","clk":"11450340964","pt":1717320755051,"mc":[{"id":"1.229554913","rc":[{"atl":[[720,0.22]],"id":52671562},{"atb":[[8.6,9.47]],"id":52671561},{"atl":[[34,5]],"id":52671561},{"atb":[[6.4,5]],"id":52671560},{"atl":[[9.4,5]],"id":52671560},{"atb":[[9.6,5]],"id":52237617},{"atl":[[23,5]],"id":52237617},{"atb":[[34,5]],"id":52671543},{"atl":[[85,9.23]],"id":52671543}],"con":true,"img":false}]}
{"op":"mcm","clk":"11450340972","pt":1717320755150,"mc":[{"id":"1.229554913","rc":[{"atl":[[42,3.9],[25,5]],"id":52237627},{"atb":[[80,0],[42,0],[110,0],[55,2.9]],"id":52671562},{"atl":[[290,5]],"id":52671562},{"atb":[[11,9.21]],"id":52671564},{"atl":[[38,7.99],[23,5]],"id":52671564},{"atb":[[110,5]],"id":52237621},{"atl":[[390,0.41],[240,5]],"id":52237621},{"atl":[[60,4.71]],"id":52671561},{"atb":[[5.3,22.88]],"id":52671560},{"atl":[[10.5,13.39]],"id":52671560},{"atb":[[3.85,28.59],[5.2,5]],"id":52237612},{"atl":[[10,5],[28,5.93]],"id":52237612},{"atb":[[130,5]],"id":52671552},{"atl":[[270,5],[350,0.46]],"id":52671552},{"atb":[[75,0],[40,0],[100,1.72],[50,0],[55,5]],"id":52671547},{"atl":[[290,5],[680,0.23]],"id":52671547},{"atb":[[10,13.8]],"id":52237617},{"atl":[[38,4.33]],"id":52237617},{"atb":[[11,5]],"id":52671549},{"atl":[[38,2.91],[21,5]],"id":52671549},{"atl":[[85,11.14]],"id":52671543},{"atb":[[4,5]],"id":52671542},{"atl":[[6.8,5],[30,5.52]],"id":52671542},{"atb":[[4.9,5],[3.65,23.95]],"id":52671545},{"atl":[[10.5,26.42]],"id":52671545},{"atb":[[16,5],[10,3.58]],"id":52237634},{"atl":[[38,9.6],[42,7.13]],"id":52237634}],"con":true,"img":false}]}
{"op":"mcm","clk":"11450340978","pt":1717320755250,"mc":[{"id":"1.229554913","rc":[{"atl":[[540,2]],"id":52671562},{"atl":[[34,8.03],[60,2.71]],"id":52671561},{"atl":[[500,2]],"id":52671547}],"con":true,"img":false}]}
{"op":"mcm","clk":"11450340990","pt":1717320755355,"mc":[{"id":"1.229554913","rc":[{"atl":[[730,0]],"id":52671562},{"atl":[[700,0]],"id":52671547}],"con":true,"img":false}]}
{"op":"mcm","clk":"11450341034","pt":1717320755827,"mc":[{"id":"1.229554913","rc":[{"atb":[[65,5],[70,3.46],[38,2.12],[48,1.11],[29,3.74]],"id":52671562},{"atb":[[32,2.53],[42,1.28],[26,4.19],[55,5.49]],"id":52671547}],"con":true,"img":false}]}
{"op":"mcm","clk":"11450341148","pt":1717320757332,"mc":[{"id":"1.229554913","rc":[{"atb":[[6.2,0],[8.2,0]],"id":52237627},{"atb":[[200,0],[100,0]],"id":52671562},{"atb":[[6.2,0],[8.2,0]],"id":52671564},{"atb":[[48,0],[29,0]],"id":52237621},{"atb":[[10.5,0],[8.2,0]],"id":52671561},{"atb":[[3.55,0],[3.05,0]],"id":52671560},{"atb":[[2.8,0],[2.6,0]],"id":52237612},{"atb":[[48,0],[29,0]],"id":52671552},{"atb":[[200,0],[100,0]],"id":52671547},{"atb":[[6.2,0],[8.2,0]],"id":52237617},{"atb":[[6.2,0],[8.2,0]],"id":52671549},{"atb":[[17,0],[12,0]],"id":52671543},{"atb":[[3.55,41.03],[3.05,0]],"id":52671542},{"atb":[[2.8,0],[2.6,0]],"id":52671545},{"atb":[[4.8,0],[5.8,0]],"id":52237634}],"con":true,"img":false}]}
{"op":"mcm","clk":"11450341179","pt":1717320757743,"mc":[{"id":"1.229554913","rc":[{"atb":[[55,8.46]],"id":52671547}],"con":true,"img":false}]}
{"op":"mcm","clk":"11450341189","pt":1717320757850,"mc":[{"id":"1.229554913","rc":[{"atb":[[70,5.79],[75,0.38]],"id":52671562},{"atb":[[60,0.38]],"id":52671547}],"con":true,"img":false}]}
{"op":"mcm","clk":"11450341366","pt":1717320759956,"mc":[{"id":"1.229554913","rc":[{"atl":[[44,2.33],[55,0]],"id":52671564},{"atl":[[770,2],[950,0]],"id":52237621},{"atl":[[17.5,6.06],[21,0]],"id":52671560},{"atb":[[3.95,20.93],[3.8,0]],"id":52237612},{"atl":[[910,2]],"id":52671552},{"atl":[[36,2.86],[44,4.19]],"id":52237617},{"atl":[[38,5.61],[46,0]],"id":52671549},{"atl":[[300,2],[370,0]],"id":52671543}],"con":true,"img":false}]}
{"op":"mcm","clk":"11450341400","pt":1717320760368,"mc":[{"id":"1.229554913","rc":[{"atl":[[540,0],[440,2]],"id":52671562},{"atl":[[400,2],[500,0]],"id":52671547}],"con":true,"img":false}]}
{"op":"mcm","clk":"11450341507","pt":1717320761670,"mc":[{"id":"1.229554913","rc":[{"atb":[[23,0],[28,3.7]],"id":52671562}],"con":true,"img":false}]}
{"op":"mcm","clk":"11450341533","pt":1717320761936,"mc":[{"id":"1.229554913","rc":[{"atl":[[21,0],[22,5]],"id":52671549},{"atb":[[16,0],[15.5,5]],"id":52237634}],"con":true,"img":false}]}
{"op":"mcm","clk":"11450341538","pt":1717320762035,"mc":[{"id":"1.229554913","rc":[{"atb":[[70,2.7],[75,4.45]],"id":52671562},{"atb":[[8.6,5],[9,4.21],[11,0],[7.4,0],[8.4,0],[9.4,0]],"id":52671561},{"atl":[[9.6,5],[10,4.46],[9.4,0]],"id":52671560},{"atl":[[270,0],[280,5]],"id":52671552},{"atb":[[9.8,0]],"id":52237617},{"atl":[[36,4],[38,5]],"id":52237634}],"con":true,"img":false}]}
{"op":"mcm","clk":"11450341546","pt":1717320762146,"mc":[{"id":"1.229554913","rc":[{"atb":[[5.1,5],[5.2,0]],"id":52237612}],"con":true,"img":false}]}
{"op":"mcm","clk":"11450341568","pt":1717320762453,"mc":[{"id":"1.229554913","rc":[{"atb":[[9,14.04]],"id":52671561}],"con":true,"img":false}]}
{"op":"mcm","clk":"11450341588","pt":1717320762767,"mc":[{"id":"1.229554913","rc":[{"atb":[[9.6,6.08],[8.6,15.33],[11.5,2.49],[7.6,15.85]],"id":52671561},{"atb":[[15.5,0]],"id":52237634}],"con":true,"img":false}]}
{"op":"mcm","clk":"11450341657","pt":1717320763546,"mc":[{"id":"1.229554913","rc":[{"atb":[[16,5]],"id":52237634}],"con":true,"img":false}]}
{"op":"mcm","clk":"11450341710","pt":1717320764269,"mc":[{"id":"1.229554913","rc":[{"atl":[[910,0],[970,2]],"id":52671552}],"con":true,"img":false}]}
{"op":"mcm","clk":"11450341791","pt":1717320765259,"mc":[{"id":"1.229554913","rc":[{"atl":[[280,0.57]],"id":52671562}],"con":true,"img":false}]}
{"op":"mcm","clk":"11450341798","pt":1717320765356,"mc":[{"id":"1.229554913","rc":[{"atl":[[25,11.68]],"id":52237627},{"atl":[[23,12.28]],"id":52671564},{"atl":[[240,5.67]],"id":52237621},{"atl":[[34,12.89]],"id":52671561},{"atb":[[6.4,20.05]],"id":52671560},{"atl":[[10,19.51]],"id":52671560},{"atb":[[4,16.43]],"id":52237612},{"atl":[[10,21.43]],"id":52237612},{"atl":[[280,5.58]],"id":52671552},{"atl":[[280,0.57]],"id":52671547},{"atl":[[23,12.28]],"id":52237617},{"atl":[[34,4.85]],"id":52671549},{"atl":[[6.8,23.03]],"id":52671542},{"atb":[[4.9,27.65]],"id":52671545},{"atb":[[16,15.69]],"id":52237634},{"atl":[[36,8.58]],"id":52237634}],"con":true,"img":false}]}
{"op":"mcm","clk":"11450341840","pt":1717320765931,"mc":[{"id":"1.229554913","rc":[{"atl":[[720,0]],"id":52671562}],"con":true,"img":false}]}
{"op":"mcm","clk":"11450341846","pt":1717320766038,"mc":[{"id":"1.229554913","rc":[{"atl":[[42,0]],"id":52237627},{"atl":[[38,3.66]],"id":52671564},{"atl":[[390,0]],"id":52237621},{"atl":[[60,0]],"id":52671561},{"atb":[[5.3,12.17]],"id":52671560},{"atl":[[10.5,2.68]],"id":52671560},{"atb":[[3.85,0]],"id":52237612},{"atl":[[28,0]],"id":52237612},{"atl":[[350,0]],"id":52671552},{"atl":[[680,0]],"id":52671547},{"atl":[[38,0]],"id":52237617},{"atl":[[38,2.7]],"id":52671549},{"atl":[[30,0]],"id":52671542},{"atb":[[3.65,0]],"id":52671545},{"atb":[[10,0]],"id":52237634},{"atl":[[42,3.54]],"id":52237634}],"con":true,"img":false}]}
{"op":"mcm","clk":"11450341880","pt":1717320766499,"mc":[{"id":"1.229554913","rc":[{"atl":[[23,0],[24,5]],"id":52237617}],"con":true,"img":false}]}
{"op":"mcm","clk":"11450341908","pt":1717320766903,"mc":[{"id":"1.229554913","rc":[{"atb":[[4.8,5]],"id":52671545}],"con":true,"img":false}]}
{"op":"mcm","clk":"11450341913","pt":1717320767007,"mc":[{"id":"1.229554913","rc":[{"atb":[[4.9,0]],"id":52671545}],"con":true,"img":false}]}
{"op":"mcm","clk":"11450341931","pt":1717320767216,"mc":[{"id":"1.229554913","rc":[{"atl":[[34,4.85]],"id":52237617}],"con":true,"img":false}]}
{"op":"mcm","clk":"11450341975","pt":1717320767734,"mc":[{"id":"1.229554913","rc":[{"atb":[[3.65,14.67]],"id":52671545}],"con":true,"img":false}]}
{"op":"mcm","clk":"11450341983","pt":1717320767788,"mc":[{"id":"1.229554913","rc":[{"atb":[[12,0],[9.8,0],[8.8,0],[14.5,0]],"id":52671549}],"con":true,"img":false}]}
{"op":"mcm","clk":"11450342003","pt":1717320768054,"mc":[{"id":"1.229554913","rc":[{"atb":[[8.6,13.78],[6.6,43.64]],"id":52237627},{"atb":[[210,0.35],[110,1.56]],"id":52671562},{"atb":[[6.4,45.26],[8.4,14.15]],"id":52671564},{"atb":[[48,2.22],[29,8.72]],"id":52237621},{"atb":[[8.6,47.49],[11.5,12.47]],"id":52671561},{"atb":[[3.55,41.07],[3.05,119.22]],"id":52671560},{"atb":[[2.58,154.68],[2.78,58.84]],"id":52237612},{"atb":[[46,2.32],[28,9.05]],"id":52671552},{"atb":[[210,0.35],[110,1.56]],"id":52671547},{"atb":[[8.6,13.78],[6.6,43.64]],"id":52237617},{"atb":[[6.4,45.26],[8.4,14.15]],"id":52671549},{"atb":[[16.5,6.75],[11.5,23.27]],"id":52671543},{"atb":[[3.55,82.11],[3.05,119.22]],"id":52671542},{"atb":[[2.56,156.67],[2.76,59.51]],"id":52671545},{"atb":[[4.8,64.31],[5.8,21.82]],"id":52237634}],"con":true,"img":false}]}
{"op":"mcm","clk":"11450342022","pt":1717320768212,"mc":[{"id":"1.229554913","rc":[{"atl":[[40,0],[42,2.67]],"id":52237627},{"atb":[[75,6.62]],"id":52671562},{"atl":[[380,0],[390,3.77]],"id":52237621},{"atb":[[60,3.09]],"id":52671547},{"atb":[[9,10.22]],"id":52237617},{"atb":[[11,18.94]],"id":52671549}],"con":true,"img":false}]}
{"op":"mcm","clk":"11450342031","pt":1717320768315,"mc":[{"id":"1.229554913","rc":[{"atb":[[65,9.41]],"id":52671562},{"atb":[[8.6,51.29]],"id":52671561}],"con":true,"img":false}]}
{"op":"mcm","clk":"11450342046","pt":1717320768523,"mc":[{"id":"1.229554913","rc":[{"atb":[[9,13.08],[10,8.72],[12.5,4.55],[15,1.87]],"id":52671549}],"con":true,"img":false}]}
{"op":"mcm","clk":"11450342108","pt":1717320769303,"mc":[{"id":"1.229554913","rc":[{"atb":[[70,0.38]],"id":52671562},{"atb":[[55,5.49]],"id":52671547}],"con":true,"img":false}]}
{"op":"mcm","clk":"11450342123","pt":1717320769507,"mc":[{"id":"1.229554913","rc":[{"atb":[[55,0]],"id":52671562},{"atb":[[8,0]],"id":52671561}],"con":true,"img":false}]}
{"op":"mcm","clk":"11450342397","pt":1717320772925,"mc":[{"id":"1.229554913","rc":[{"atb":[[7.4,15.62],[5.2,0]],"id":52237627},{"atb":[[40,2.56],[28,0]],"id":52671562},{"atl":[[600,2],[440,0]],"id":52671562},{"atl":[[85,2],[44,0]],"id":52671564},{"atl":[[600,2],[770,0]],"id":52237621},{"atb":[[5.2,23.81],[4.7,0]],"id":52671561},{"atl":[[34,9.86],[48,2.13]],"id":52671561},{"atb":[[4.5,28.57],[3.7,0]],"id":52671560},{"atl":[[17.5,0],[28,3.7]],"id":52671560},{"atb":[[3.95,0],[3.65,25.95]],"id":52237612},{"atl":[[760,2],[970,0]],"id":52671552},{"atb":[[16,6.67],[21,0]],"id":52671547},{"atl":[[350,2],[400,0]],"id":52671547},{"atl":[[36,0],[25,5],[29,3.57]],"id":52237617},{"atl":[[32,3.23],[38,0]],"id":52671549},{"atl":[[300,0],[230,2]],"id":52671543},{"atb":[[2.52,65.79],[2.78,0]],"id":52671542},{"atl":[[16.5,6.45],[22,0]],"id":52671545}],"con":true,"img":false}]}
{"op":"mcm","clk":"11450342406","pt":1717320773031,"mc":[{"id":"1.229554913","rc":[{"atl":[[24,0]],"id":52237617}],"con":true,"img":false}]}
{"op":"mcm","clk":"11450342433","pt":1717320773342,"mc":[{"id":"1.229554913","rc":[{"atb":[[16,0],[17,5],[18.5,9.15],[11,0],[12.5,0],[13,3.13],[13.5,0]],"id":52237627},{"atl":[[34,5],[25,0]],"id":52237627},{"atb":[[75,2.54],[100,4.16]],"id":52671562},{"atb":[[15.5,12.85]],"id":52671564},{"atl":[[32,5],[23,7.28]],"id":52671564},{"atb":[[9,9.83],[11,3.01],[12,14.56]],"id":52671561},{"atl":[[9.6,0],[10,15.05],[10.5,0],[13,5],[13.5,3.32]],"id":52671560},{"atb":[[55,0.49]],"id":52671547},{"atb":[[8.6,17.27],[10,2.91],[9.4,0]],"id":52237617},{"atb":[[10.5,0],[11,13.93],[9.8,3.66]],"id":52671549},{"atl":[[80,3.31],[85,6.91]],"id":52671543},{"atb":[[4,0],[4.6,0],[4.1,0],[3.8,0],[3.55,41.07],[3.9,0]],"id":52671542},{"atl":[[9.2,2.87],[10.5,21.86]],"id":52671545},{"atl":[[34,2.71],[36,4.57]],"id":52237634}],"con":true,"img":false}]}
{"op":"mcm","clk":"11450342472","pt":1717320773707,"mc":[{"id":"1.229554913","rc":[{"atb":[[9.6,0]],"id":52237617},{"atl":[[75,2.16]],"id":52671543}],"con":true,"img":false}]}
{"op":"mcm","clk":"11450342482","pt":1717320773811,"mc":[{"id":"1.229554913","rc":[{"atb":[[10,13.73]],"id":52671549},{"atb":[[3.4,5],[3.55,46.92]],"id":52671542},{"atl":[[9,20.02]],"id":52671545}],"con":true,"img":false}]}
{"op":"mcm","clk":"11450342499","pt":1717320774018,"mc":[{"id":"1.229554913","rc":[{"atb":[[9.6,12.66]],"id":52237617},{"atb":[[3.6,20.12],[3.85,9.18],[3.1,49.83],[3.35,33.39]],"id":52671542}],"con":true,"img":false}]}
{"op":"mcm","clk":"11450342508","pt":1717320774123,"mc":[{"id":"1.229554913","rc":[{"atb":[[17,8.28],[19.5,1.41],[12,9.51],[14.5,5.81]],"id":52237627},{"atl":[[34,9.86]],"id":52237627},{"atb":[[9,0]],"id":52671561}],"con":true,"img":false}]}
{"op":"mcm","clk":"11450342517","pt":1717320774229,"mc":[{"id":"1.229554913","rc":[{"atb":[[8.4,5]],"id":52237617}],"con":true,"img":false}]}
{"op":"mcm","clk":"11450342525","pt":1717320774330,"mc":[{"id":"1.229554913","rc":[{"atb":[[9,0]],"id":52671549}],"con":true,"img":false}]}
{"op":"mcm","clk":"11450342543","pt":1717320774434,"mc":[{"id":"1.229554913","rc":[{"atb":[[10,5],[12.5,0],[15,0]],"id":52671549},{"atl":[[85,5]],"id":52671543}],"con":true,"img":false}]}
{"op":"mcm","clk":"11450342556","pt":1717320774642,"mc":[{"id":"1.229554913","rc":[{"atl":[[10.5,5]],"id":52671545}],"con":true,"img":false}]}
{"op":"mcm","clk":"11450342562","pt":1717320774748,"mc":[{"id":"1.229554913","rc":[{"atb":[[3.4,11.54],[3.5,6.27]],"id":52671542}],"con":true,"img":false}]}
{"op":"mcm","clk":"11450342585","pt":1717320775009,"mc":[{"id":"1.229554913","rc":[{"atb":[[8.2,14.53]],"id":52671549}],"con":true,"img":false}]}
{"op":"mcm","clk":"11450342593","pt":1717320775113,"mc":[{"id":"1.229554913","rc":[{"atb":[[9.2,9.57],[10.5,5.51],[13,2.18]],"id":52671549}],"con":true,"img":false}]}
{"op":"mcm","clk":"11450342606","pt":1717320775320,"mc":[{"id":"1.229554913","rc":[{"atl":[[13.5,16.14]],"id":52671560},{"atb":[[5.1,29.38]],"id":52237612},{"atl":[[25,11.68]],"id":52237617},{"atl":[[22,12.63]],"id":52671549},{"atb":[[4.8,27.65]],"id":52671545},{"atl":[[34,7.57]],"id":52237634}],"con":true,"img":false}]}
{"op":"mcm","clk":"11450342635","pt":1717320775736,"mc":[{"id":"1.229554913","rc":[{"atb":[[100,0],[110,3.39]],"id":52671552},{"atb":[[9,6.54]],"id":52237617}],"con":true,"img":false}]}
{"op":"mcm","clk":"11450342656","pt":1717320776048,"mc":[{"id":"1.229554913","rc":[{"atl":[[13.5,3.32]],"id":52671560},{"atb":[[4,0]],"id":52237612},{"atl":[[34,0]],"id":52237617},{"atl":[[34,0]],"id":52671549},{"atb":[[3.65,0]],"id":52671545},{"atl":[[36,0]],"id":52237634}],"con":true,"img":false}]}
{"op":"mcm","clk":"11450342921","pt":1717320779317,"mc":[{"id":"1.229554913","rc":[{"atb":[[90,4.61]],"id":52671562},{"atb":[[10,4.31]],"id":52671561},{"atl":[[14.5,2.66]],"id":52671560},{"atb":[[8.2,3.66]],"id":52237617},{"atl":[[90,3.71]],"id":52671543},{"atl":[[9.6,3.93]],"id":52671545},{"atl":[[38,8.27]],"id":52237634}],"con":true,"img":false}]}
{"op":"mcm","clk":"11450342956","pt":1717320779833,"mc":[{"id":"1.229554913","rc":[{"atb":[[16,10.68],[16.5,5]],"id":52237634}],"con":true,"img":false}]}
{"op":"mcm","clk":"11450342974","pt":1717320780039,"mc":[{"id":"1.229554913","rc":[{"atb":[[65,5]],"id":52671562},{"atb":[[8.6,47.49]],"id":52671561},{"atl":[[42,0]],"id":52237634}],"con":true,"img":false}]}
{"op":"mcm","clk":"11450342991","pt":1717320780250,"mc":[{"id":"1.229554913","rc":[{"atb":[[16.5,15.34]],"id":52237634}],"con":true,"img":false}]}
{"op":"mcm","clk":"11450343001","pt":1717320780351,"mc":[{"id":"1.229554913","rc":[{"atl":[[100,0]],"id":52671543},{"atl":[[11.5,0]],"id":52671545}],"con":true,"img":false}]}
{"op":"mcm","clk":"11450343066","pt":1717320781033,"mc":[{"id":"1.229554913","rc":[{"atb":[[16,0]],"id":52237634}],"con":true,"img":false}]}
{"op":"mcm","clk":"11450343261","pt":1717320783221,"mc":[{"id":"1.229554913","rc":[{"atb":[[19.5,10.07]],"id":52237627}],"con":true,"img":false}]}
{"op":"mcm","clk":"11450343325","pt":1717320784052,"mc":[{"id":"1.229554913","rc":[{"atb":[[18.5,0]],"id":52237627}],"con":true,"img":false}]}
{"op":"mcm","clk":"11450343392","pt":1717320784937,"mc":[{"id":"1.229554913","rc":[{"atb":[[160,0],[80,0],[110,2.9],[55,0]],"id":52671552},{"atb":[[38,0],[24,0],[29,0]],"id":52671543}],"con":true,"img":false}]}
{"op":"mcm","clk":"11450343399","pt":1717320785038,"mc":[{"id":"1.229554913","rc":[{"atb":[[48,0]],"id":52671543}],"con":true,"img":false}]}
{"op":"mcm","clk":"11450343407","pt":1717320785141,"mc":[{"id":"1.229554913","rc":[{"atb":[[3.6,0],[3.85,0],[3.1,0],[3.35,0]],"id":52671542}],"con":true,"img":false}]}
{"op":"mcm","clk":"11450343432","pt":1717320785451,"mc":[{"id":"1.229554913","rc":[{"atb":[[130,6.24]],"id":52671552}],"con":true,"img":false}]}
{"op":"mcm","clk":"11450343436","pt":1717320785552,"mc":[{"id":"1.229554913","rc":[{"atb":[[34,9.86]],"id":52671543}],"con":true,"img":false}]}
{"op":"mcm","clk":"11450343444","pt":1717320785659,"mc":[{"id":"1.229554913","rc":[{"atb":[[130,6.66]],"id":52671552},{"atb":[[32,2.53],[42,1.28],[26,4.19]],"id":52671543}],"con":true,"img":false}]}
{"op":"mcm","clk":"11450343454","pt":1717320785760,"mc":[{"id":"1.229554913","rc":[{"atb":[[65,1.64],[180,0.15],[90,0.88]],"id":52671552},{"atb":[[55,0.49]],"id":52671543}],"con":true,"img":false}]}
{"op":"mcm","clk":"11450343464","pt":1717320785865,"mc":[{"id":"1.229554913","rc":[{"atb":[[3.4,44.25],[3.15,48.67],[3.5,21.85],[3.9,9.02],[3.65,19.74]],"id":52671542}],"con":true,"img":false}]}
{"op":"mcm","clk":"11450343512","pt":1717320786532,"mc":[{"id":"1.229554913","rc":[{"atb":[[3.5,6.27]],"id":52671542}],"con":true,"img":false}]}
{"op":"mcm","clk":"11450343820","pt":1717320790365,"mc":[{"id":"1.229554913","rc":[{"atb":[[3.45,6.4],[3.5,0]],"id":52671542},{"atl":[[34,4.85],[36,4.26]],"id":52237634}],"con":true,"img":false}]}
