{"op":"mcm","clk":"11448351863","pt":1717289088271,"mc":[{"id":"1.229554929","marketDefinition":{"bspMarket":false,"turnInPlayEnabled":false,"persistenceEnabled":false,"marketBaseRate":7.0,"eventId":"33318908","eventTypeId":"4339","numberOfWinners":1,"bettingType":"ODDS","marketType":"MATCH_BET","marketTime":"2024-06-02T10:41:00.000Z","suspendTime":"2024-06-02T10:41:00.000Z","bspReconciled":false,"complete":true,"inPlay":false,"crossMatching":true,"runnersVoidable":false,"numberOfActiveRunners":2,"betDelay":0,"status":"OPEN","runners":[{"status":"ACTIVE","sortPriority":1,"id":47148562,"name":"2. Under Siege"},{"status":"ACTIVE","sortPriority":2,"id":49546922,"name":"4. Uno Whiskey"}],"regulators":["MR_INT"],"venue":"Murray Bridge","countryCode":"AU","discountAllowed":true,"timezone":"Australia/Adelaide","openDate":"2024-06-02T08:21:00.000Z","version":5962433793,"name":"Under Siege v Uno Whiskey","eventName":"Murray Bridge (AUS) 2nd Jun"},"rc":[],"con":true,"img":false}]}
{"op":"mcm","clk":"11448366403","pt":1717289278043,"mc":[{"id":"1.229554929","rc":[{"atb":[[1.97,8.08],[1.87,9.01]],"id":47148562},{"atb":[[1.73,10.75],[1.63,12.45]],"id":49546922}],"con":true,"img":false}]}
{"op":"mcm","clk":"11448516312","pt":1717291543831,"mc":[{"id":"1.229554929","rc":[{"atb":[[1.97,0],[1.87,0]],"id":47148562},{"atb":[[1.73,0],[1.63,0]],"id":49546922}],"con":true,"img":false}]}
{"op":"mcm","clk":"11448516748","pt":1717291550972,"mc":[{"id":"1.229554929","rc":[{"atb":[[1.96,8.17],[1.86,9.12]],"id":47148562},{"atb":[[1.75,10.46],[1.65,12.07]],"id":49546922}],"con":true,"img":false}]}
{"op":"mcm","clk":"11448517449","pt":1717291562388,"mc":[{"id":"1.229554929","rc":[{"atb":[[1.96,0],[1.86,0]],"id":47148562},{"atb":[[1.75,0],[1.65,0]],"id":49546922}],"con":true,"img":false}]}
{"op":"mcm","clk":"11448517838","pt":1717291568298,"mc":[{"id":"1.229554929","rc":[{"atb":[[1.99,7.92],[1.89,8.81]],"id":47148562},{"atb":[[1.71,11.05],[1.61,12.86]],"id":49546922}],"con":true,"img":false}]}
{"op":"mcm","clk":"11448522288","pt":1717291645993,"mc":[{"id":"1.229554929","rc":[{"atb":[[1.99,0],[1.89,0]],"id":47148562},{"atb":[[1.71,0],[1.61,0]],"id":49546922}],"con":true,"img":false}]}
{"op":"mcm","clk":"11448522564","pt":1717291651915,"mc":[{"id":"1.229554929","rc":[{"atb":[[1.99,7.92],[1.89,8.81]],"id":47148562},{"atb":[[1.71,11.05],[1.61,12.86]],"id":49546922}],"con":true,"img":false}]}
{"op":"mcm","clk":"11448523124","pt":1717291661917,"mc":[{"id":"1.229554929","rc":[{"atb":[[1.99,0],[1.89,0]],"id":47148562},{"atb":[[1.71,0],[1.61,0]],"id":49546922}],"con":true,"img":false}]}
{"op":"mcm","clk":"11448523428","pt":1717291667331,"mc":[{"id":"1.229554929","rc":[{"atb":[[1.99,7.92],[1.89,8.81]],"id":47148562},{"atb":[[1.71,11.05],[1.61,12.86]],"id":49546922}],"con":true,"img":false}]}
{"op":"mcm","clk":"11448527341","pt":1717291733198,"mc":[{"id":"1.229554929","rc":[{"atb":[[1.99,0],[1.89,0]],"id":47148562},{"atb":[[1.71,0],[1.61,0]],"id":49546922}],"con":true,"img":false}]}
{"op":"mcm","clk":"11448527774","pt":1717291740829,"mc":[{"id":"1.229554929","rc":[{"atb":[[1.99,7.92],[1.89,8.81]],"id":47148562},{"atb":[[1.71,11.05],[1.61,12.86]],"id":49546922}],"con":true,"img":false}]}
{"op":"mcm","clk":"11448528407","pt":1717291751125,"mc":[{"id":"1.229554929","rc":[{"atb":[[1.99,0],[1.89,0]],"id":47148562},{"atb":[[1.71,0],[1.61,0]],"id":49546922}],"con":true,"img":false}]}
{"op":"mcm","clk":"11448528857","pt":1717291758159,"mc":[{"id":"1.229554929","rc":[{"atb":[[2,7.84],[1.9,8.72]],"id":47148562},{"atb":[[1.6,13.07],[1.7,11.21]],"id":49546922}],"con":true,"img":false}]}
{"op":"mcm","clk":"11448951018","pt":1717300630652,"mc":[{"id":"1.229554929","rc":[{"atb":[[1.01,17.19]],"id":47148562},{"atl":[[990,0.85]],"id":47148562},{"atb":[[1.03,5.73]],"id":49546922},{"atl":[[990,0.85]],"id":49546922}],"con":true,"img":false}]}
{"op":"mcm","clk":"11449585828","pt":1717311428269,"mc":[{"id":"1.229554929","rc":[{"atl":[[990,0.17]],"id":47148562},{"atl":[[990,0.17]],"id":49546922}],"con":true,"img":false}]}
{"op":"mcm","clk":"11449741850","pt":1717314153752,"mc":[{"id":"1.229554929","rc":[{"atb":[[2,0],[1.9,0]],"id":47148562},{"atb":[[1.6,0],[1.7,0]],"id":49546922}],"con":true,"img":false}]}
{"op":"mcm","clk":"11449742651","pt":1717314163984,"mc":[{"id":"1.229554929","rc":[{"atb":[[2,7.84],[1.9,8.72]],"id":47148562},{"atb":[[1.6,13.07],[1.7,11.21]],"id":49546922}],"con":true,"img":false}]}
{"op":"mcm","clk":"11449851305","pt":1717315296778,"mc":[{"id":"1.229554929","rc":[{"atb":[[2,0],[1.9,0]],"id":47148562},{"atb":[[1.6,0],[1.7,0]],"id":49546922}],"con":true,"img":false}]}
{"op":"mcm","clk":"11449854719","pt":1717315331356,"mc":[{"id":"1.229554929","rc":[{"atb":[[2,7.84],[1.9,8.72]],"id":47148562},{"atb":[[1.6,13.07],[1.7,11.21]],"id":49546922}],"con":true,"img":false}]}
{"op":"mcm","clk":"11449893743","pt":1717315713497,"mc":[{"id":"1.229554929","rc":[{"atb":[[2,0],[1.9,0]],"id":47148562},{"atb":[[1.6,0],[1.7,0]],"id":49546922}],"con":true,"img":false}]}
{"op":"mcm","clk":"11449898095","pt":1717315753812,"mc":[{"id":"1.229554929","rc":[{"atb":[[2,7.84],[1.9,8.72]],"id":47148562},{"atb":[[1.6,13.07],[1.7,11.21]],"id":49546922}],"con":true,"img":false}]}
{"op":"mcm","clk":"11449959215","pt":1717316398585,"mc":[{"id":"1.229554929","rc":[{"atb":[[2,0],[1.9,0]],"id":47148562},{"atb":[[1.6,0],[1.7,0]],"id":49546922}],"con":true,"img":false}]}
{"op":"mcm","clk":"11449960619","pt":1717316415047,"mc":[{"id":"1.229554929","rc":[{"atb":[[2,7.84],[1.9,8.72]],"id":47148562},{"atb":[[1.6,13.07],[1.7,11.21]],"id":49546922}],"con":true,"img":false}]}
{"op":"mcm","clk":"11450057451","pt":1717317526843,"mc":[{"id":"1.229554929","rc":[{"atb":[[2,0],[1.9,0]],"id":47148562},{"atb":[[1.6,0],[1.7,0]],"id":49546922}],"con":true,"img":false}]}
{"op":"mcm","clk":"11450060536","pt":1717317560943,"mc":[{"id":"1.229554929","rc":[{"atb":[[2,7.84],[1.9,8.72]],"id":47148562},{"atb":[[1.6,13.07],[1.7,11.21]],"id":49546922}],"con":true,"img":false}]}
{"op":"mcm","clk":"11450133833","pt":1717318390220,"mc":[{"id":"1.229554929","rc":[{"atb":[[2,0],[1.9,0]],"id":47148562},{"atb":[[1.6,0],[1.7,0]],"id":49546922}],"con":true,"img":false}]}
{"op":"mcm","clk":"11450134730","pt":1717318401243,"mc":[{"id":"1.229554929","rc":[{"atb":[[2,7.84],[1.9,8.72]],"id":47148562},{"atb":[[1.6,13.07],[1.7,11.21]],"id":49546922}],"con":true,"img":false}]}
{"op":"mcm","clk":"11450214766","pt":1717319245838,"mc":[{"id":"1.229554929","rc":[{"atb":[[2,0],[1.9,0]],"id":47148562},{"atb":[[1.6,0],[1.7,0]],"id":49546922}],"con":true,"img":false}]}
{"op":"mcm","clk":"11450217194","pt":1717319268395,"mc":[{"id":"1.229554929","rc":[{"atb":[[2,7.84],[1.9,8.72]],"id":47148562},{"atb":[[1.6,13.07],[1.7,11.21]],"id":49546922}],"con":true,"img":false}]}
{"op":"mcm","clk":"11450286947","pt":1717320073091,"mc":[{"id":"1.229554929","rc":[{"atb":[[2,0],[1.9,0]],"id":47148562},{"atb":[[1.6,0],[1.7,0]],"id":49546922}],"con":true,"img":false}]}
{"op":"mcm","clk":"11450287949","pt":1717320087390,"mc":[{"id":"1.229554929","rc":[{"atb":[[2,7.84],[1.9,8.72]],"id":47148562},{"atb":[[1.6,13.07],[1.7,11.21]],"id":49546922}],"con":true,"img":false}]}
{"op":"mcm","clk":"11450360431","pt":1717320990956,"mc":[{"id":"1.229554929","rc":[{"atb":[[2,0],[1.9,0]],"id":47148562},{"atb":[[1.6,0],[1.7,0]],"id":49546922}],"con":true,"img":false}]}
{"op":"mcm","clk":"11450362078","pt":1717321011721,"mc":[{"id":"1.229554929","rc":[{"atb":[[2,7.84],[1.9,8.72]],"id":47148562},{"atb":[[1.6,13.07],[1.7,11.21]],"id":49546922}],"con":true,"img":false}]}
{"op":"mcm","clk":"11450378801","pt":1717321260440,"mc":[{"id":"1.229554929","rc":[{"atb":[[1.53,17.2]],"id":47148562},{"atl":[[7,2]],"id":47148562},{"atb":[[1.27,24.29]],"id":49546922},{"atl":[[3.75,2]],"id":49546922}],"con":true,"img":false}]}
{"op":"mcm","clk":"11450378814","pt":1717321260647,"mc":[{"id":"1.229554929","rc":[{"atl":[[2.8,11.11],[2.88,15.96],[2.84,13.59],[2.76,8.52]],"id":47148562},{"atl":[[2.42,17.61],[2.38,14.49],[2.46,20.55],[2.34,11.19]],"id":49546922}],"con":true,"img":false}]}
{"op":"mcm","clk":"11450378823","pt":1717321260702,"mc":[{"id":"1.229554929","rc":[{"atl":[[2.5,32.1],[3.75,0]],"id":49546922}],"con":true,"img":false}]}
{"op":"mcm","clk":"11450378955","pt":1717321262522,"mc":[{"id":"1.229554929","rc":[{"atb":[[1.27,0],[1.32,24.29]],"id":49546922}],"con":true,"img":false}]}
{"op":"mcm","clk":"11450379504","pt":1717321270640,"mc":[{"id":"1.229554929","rc":[{"atl":[[2.36,11.03],[2.34,0]],"id":49546922}],"con":true,"img":false}]}
{"op":"mcm","clk":"11450379602","pt":1717321271933,"mc":[{"id":"1.229554929","rc":[{"atl":[[2.5,0],[2.62,35.22]],"id":49546922}],"con":true,"img":false}]}
{"op":"mcm","clk":"11450381326","pt":1717321297568,"mc":[{"id":"1.229554929","rc":[{"atb":[[1.58,17.2]],"id":47148562},{"atl":[[3.4,24.7],[7,0]],"id":47148562}],"con":true,"img":false}]}
{"op":"mcm","clk":"11450381332","pt":1717321297668,"mc":[{"id":"1.229554929","rc":[{"atb":[[1.53,0]],"id":47148562}],"con":true,"img":false}]}
{"op":"mcm","clk":"11450382317","pt":1717321314587,"mc":[{"id":"1.229554929","rc":[{"atb":[[2,0],[1.9,0]],"id":47148562},{"atb":[[1.6,0],[1.7,0]],"id":49546922}],"con":true,"img":false}]}
{"op":"mcm","clk":"11450382320","pt":1717321314691,"mc":[{"id":"1.229554929","rc":[{"atb":[[1.18,34.4]],"id":47148562},{"atb":[[1.32,0],[1.04,48.58]],"id":49546922}],"con":true,"img":false}]}
{"op":"mcm","clk":"11450382325","pt":1717321314794,"mc":[{"id":"1.229554929","rc":[{"atb":[[1.58,0]],"id":47148562}],"con":true,"img":false}]}
{"op":"mcm","clk":"11450382395","pt":1717321316098,"mc":[{"id":"1.229554929","rc":[{"atb":[[1.41,73.17],[1.45,44.44],[1.43,58.14],[1.47,31.91]],"id":47148562},{"atl":[[4.1,27.18]],"id":47148562},{"atb":[[1.41,36.59],[1.37,67.57],[1.39,51.28],[1.35,85.71]],"id":49546922},{"atl":[[3.2,35.22]],"id":49546922}],"con":true,"img":false}]}
{"op":"mcm","clk":"11450382401","pt":1717321316199,"mc":[{"id":"1.229554929","rc":[{"atb":[[1.43,83.94]],"id":47148562},{"atl":[[3.4,0]],"id":47148562},{"atb":[[1.3,27.16]],"id":49546922},{"atl":[[2.62,0]],"id":49546922}],"con":true,"img":false}]}
{"op":"mcm","clk":"11450382411","pt":1717321316306,"mc":[{"id":"1.229554929","rc":[{"atb":[[1.18,0]],"id":47148562},{"atb":[[1.04,0]],"id":49546922}],"con":true,"img":false}]}
{"op":"mcm","clk":"11450382475","pt":1717321317189,"mc":[{"id":"1.229554929","rc":[{"atb":[[1.49,30.61]],"id":47148562},{"atb":[[1.41,0],[1.43,34.88]],"id":49546922}],"con":true,"img":false}]}
{"op":"mcm","clk":"11450382483","pt":1717321317294,"mc":[{"id":"1.229554929","rc":[{"atb":[[1.43,58.14],[1.5,31.91],[1.47,0]],"id":47148562}],"con":true,"img":false}]}
{"op":"mcm","clk":"11450382489","pt":1717321317402,"mc":[{"id":"1.229554929","rc":[{"atb":[[1.5,0],[1.47,62.52]],"id":47148562}],"con":true,"img":false}]}
{"op":"mcm","clk":"11450382498","pt":1717321317505,"mc":[{"id":"1.229554929","rc":[{"atb":[[1.45,137.57],[1.47,0]],"id":47148562}],"con":true,"img":false}]}
{"op":"mcm","clk":"11450382507","pt":1717321317606,"mc":[{"id":"1.229554929","rc":[{"atb":[[1.45,44.44],[1.43,226.32]],"id":47148562}],"con":true,"img":false}]}
{"op":"mcm","clk":"11450382527","pt":1717321317917,"mc":[{"id":"1.229554929","rc":[{"atb":[[1.49,0],[1.47,31.91]],"id":47148562},{"atb":[[1.41,36.59],[1.43,0]],"id":49546922}],"con":true,"img":false}]}
{"op":"mcm","clk":"11450382537","pt":1717321318022,"mc":[{"id":"1.229554929","rc":[{"atb":[[1.43,58.14],[1.48,44.44]],"id":47148562}],"con":true,"img":false}]}
{"op":"mcm","clk":"11450382544","pt":1717321318126,"mc":[{"id":"1.229554929","rc":[{"atb":[[1.45,120.79]],"id":47148562}],"con":true,"img":false}]}
{"op":"mcm","clk":"11450382550","pt":1717321318180,"mc":[{"id":"1.229554929","rc":[{"atb":[[1.48,0]],"id":47148562}],"con":true,"img":false}]}
{"op":"mcm","clk":"11450382557","pt":1717321318284,"mc":[{"id":"1.229554929","rc":[{"atb":[[1.45,44.44],[1.43,210.84]],"id":47148562}],"con":true,"img":false}]}
{"op":"mcm","clk":"11450382654","pt":1717321319575,"mc":[{"id":"1.229554929","rc":[{"atb":[[1.49,30.61],[1.47,0]],"id":47148562},{"atb":[[1.41,0],[1.43,34.88]],"id":49546922}],"con":true,"img":false}]}
{"op":"mcm","clk":"11450382658","pt":1717321319680,"mc":[{"id":"1.229554929","rc":[{"atb":[[1.45,117.61]],"id":47148562}],"con":true,"img":false}]}
{"op":"mcm","clk":"11450382663","pt":1717321319781,"mc":[{"id":"1.229554929","rc":[{"atb":[[1.43,58.14]],"id":47148562}],"con":true,"img":false}]}
{"op":"mcm","clk":"11450382671","pt":1717321319886,"mc":[{"id":"1.229554929","rc":[{"atb":[[1.43,206.36]],"id":47148562}],"con":true,"img":false}]}
{"op":"mcm","clk":"11450382674","pt":1717321319987,"mc":[{"id":"1.229554929","rc":[{"atb":[[1.45,44.44]],"id":47148562}],"con":true,"img":false}]}
{"op":"mcm","clk":"11450383247","pt":1717321329646,"mc":[{"id":"1.229554929","rc":[{"atb":[[1.47,42.55]],"id":47148562},{"atb":[[1.41,48.78]],"id":49546922}],"con":true,"img":false}]}
{"op":"mcm","clk":"11450383253","pt":1717321329749,"mc":[{"id":"1.229554929","rc":[{"atb":[[1.45,117.61]],"id":47148562}],"con":true,"img":false}]}
{"op":"mcm","clk":"11450383261","pt":1717321329852,"mc":[{"id":"1.229554929","rc":[{"atb":[[1.43,58.14]],"id":47148562}],"con":true,"img":false}]}
{"op":"mcm","clk":"11450383347","pt":1717321331146,"mc":[{"id":"1.229554929","rc":[{"atb":[[1.41,0]],"id":47148562},{"atb":[[1.35,0]],"id":49546922}],"con":true,"img":false}]}
{"op":"mcm","clk":"11450383477","pt":1717321333068,"mc":[{"id":"1.229554929","rc":[{"atb":[[2,7.84],[1.9,8.72]],"id":47148562},{"atb":[[1.6,13.07],[1.7,11.21]],"id":49546922}],"con":true,"img":false}]}
{"op":"mcm","clk":"11450383490","pt":1717321333276,"mc":[{"id":"1.229554929","rc":[{"atl":[[4.1,0],[3.4,24.7]],"id":47148562},{"atl":[[3.2,0],[2.62,32.1]],"id":49546922}],"con":true,"img":false}]}
{"op":"mcm","clk":"11450385412","pt":1717321366177,"mc":[{"id":"1.229554929","rc":[{"atb":[[1.58,42.55]],"id":47148562}],"con":true,"img":false}]}
{"op":"mcm","clk":"11450385416","pt":1717321366279,"mc":[{"id":"1.229554929","rc":[{"atb":[[1.45,44.44]],"id":47148562}],"con":true,"img":false}]}
{"op":"mcm","clk":"11450406735","pt":1717321679445,"mc":[{"id":"1.229554929","rc":[{"atb":[[2,0],[1.9,0]],"id":47148562},{"atb":[[1.6,0],[1.7,0]],"id":49546922}],"con":true,"img":false}]}
{"op":"mcm","clk":"11450406740","pt":1717321679548,"mc":[{"id":"1.229554929","rc":[{"atb":[[1.58,0],[1.47,115.71]],"id":47148562}],"con":true,"img":false}]}
{"op":"mcm","clk":"11450406746","pt":1717321679634,"mc":[{"id":"1.229554929","rc":[{"atl":[[3.4,0],[3.75,27.18]],"id":47148562},{"atl":[[2.9,35.22],[2.62,0]],"id":49546922}],"con":true,"img":false}]}
{"op":"mcm","clk":"11450406752","pt":1717321679710,"mc":[{"id":"1.229554929","rc":[{"atb":[[1.45,190.76],[1.47,42.55]],"id":47148562}],"con":true,"img":false}]}
{"op":"mcm","clk":"11450406758","pt":1717321679817,"mc":[{"id":"1.229554929","rc":[{"atl":[[4.1,27.18],[3.75,0]],"id":47148562},{"atl":[[3.2,35.22],[2.9,0]],"id":49546922}],"con":true,"img":false}]}
{"op":"mcm","clk":"11450408145","pt":1717321698386,"mc":[{"id":"1.229554929","rc":[{"atb":[[2,7.84],[1.9,8.72]],"id":47148562},{"atb":[[1.6,13.07],[1.7,11.21]],"id":49546922}],"con":true,"img":false}]}
{"op":"mcm","clk":"11450408161","pt":1717321698547,"mc":[{"id":"1.229554929","rc":[{"atb":[[1.45,44.44],[1.58,42.55]],"id":47148562}],"con":true,"img":false}]}
{"op":"mcm","clk":"11450408408","pt":1717321701695,"mc":[{"id":"1.229554929","rc":[{"atl":[[3.4,24.7]],"id":47148562},{"atl":[[2.62,32.1]],"id":49546922}],"con":true,"img":false}]}
{"op":"mcm","clk":"11450408417","pt":1717321701746,"mc":[{"id":"1.229554929","rc":[{"atl":[[4.1,0]],"id":47148562},{"atl":[[3.2,0]],"id":49546922}],"con":true,"img":false}]}
{"op":"mcm","clk":"11450430371","pt":1717321953705,"mc":[{"id":"1.229554929","rc":[{"atb":[[1.49,0],[1.47,0]],"id":47148562},{"atb":[[1.41,0],[1.43,0]],"id":49546922}],"con":true,"img":false}]}
{"op":"mcm","clk":"11450438283","pt":1717322047773,"mc":[{"id":"1.229554929","rc":[{"atb":[[1.58,0],[1.66,44.44]],"id":47148562},{"atl":[[2.84,8.15],[2.76,0]],"id":47148562},{"atl":[[2.46,49.53],[2.62,0]],"id":49546922}],"con":true,"img":false}]}
{"op":"mcm","clk":"11450438385","pt":1717322048863,"mc":[{"id":"1.229554929","rc":[{"atl":[[3.25,22.22],[2.76,8.52]],"id":47148562}],"con":true,"img":false}]}
{"op":"mcm","clk":"11450438392","pt":1717322048971,"mc":[{"id":"1.229554929","rc":[{"atl":[[3.4,0]],"id":47148562}],"con":true,"img":false}]}
{"op":"mcm","clk":"11450440040","pt":1717322066795,"mc":[{"id":"1.229554929","rc":[{"atb":[[2,0],[1.9,0]],"id":47148562},{"atb":[[1.6,0],[1.7,0]],"id":49546922}],"con":true,"img":false}]}
{"op":"mcm","clk":"11450440076","pt":1717322067000,"mc":[{"id":"1.229554929","rc":[{"atb":[[1.43,147.02],[1.5,30],[1.66,0]],"id":47148562},{"atl":[[3.6,22.22],[3.25,0]],"id":47148562},{"atb":[[1.41,36.59]],"id":49546922},{"atl":[[2.46,20.55],[2.76,32.1]],"id":49546922}],"con":true,"img":false}]}
{"op":"mcm","clk":"11450440084","pt":1717322067106,"mc":[{"id":"1.229554929","rc":[{"atb":[[1.3,0],[1.32,118.85]],"id":49546922}],"con":true,"img":false}]}
{"op":"mcm","clk":"11450441147","pt":1717322077022,"mc":[{"id":"1.229554929","rc":[{"atb":[[1.48,41.67]],"id":47148562},{"atb":[[1.35,85.71]],"id":49546922}],"con":true,"img":false}]}
{"op":"mcm","clk":"11450441160","pt":1717322077078,"mc":[{"id":"1.229554929","rc":[{"atb":[[1.45,104.44],[1.43,58.14]],"id":47148562}],"con":true,"img":false}]}
{"op":"mcm","clk":"11450441276","pt":1717322078115,"mc":[{"id":"1.229554929","rc":[{"atl":[[3.6,0],[3.95,22.22]],"id":47148562},{"atb":[[1.41,0],[1.4,37.5]],"id":49546922},{"atl":[[3.05,35.22],[2.76,0]],"id":49546922}],"con":true,"img":false}]}
{"op":"mcm","clk":"11450441776","pt":1717322083405,"mc":[{"id":"1.229554929","rc":[{"atb":[[2,7.84],[1.9,8.72]],"id":47148562},{"atb":[[1.6,13.07],[1.7,11.21]],"id":49546922}],"con":true,"img":false}]}
{"op":"mcm","clk":"11450441799","pt":1717322083611,"mc":[{"id":"1.229554929","rc":[{"atb":[[1.63,41.67],[1.45,44.44]],"id":47148562}],"con":true,"img":false}]}
{"op":"mcm","clk":"11450441809","pt":1717322083670,"mc":[{"id":"1.229554929","rc":[{"atl":[[3.95,0],[3.25,19.63]],"id":47148562},{"atl":[[2.5,32.1],[3.05,0]],"id":49546922}],"con":true,"img":false}]}
{"op":"mcm","clk":"11450448635","pt":1717322165859,"mc":[{"id":"1.229554929","rc":[{"atb":[[1.5,0],[1.48,0]],"id":47148562}],"con":true,"img":false}]}
{"op":"mcm","clk":"11450448899","pt":1717322168883,"mc":[{"id":"1.229554929","rc":[{"atl":[[2.5,0],[2.62,35.22]],"id":49546922}],"con":true,"img":false}]}
{"op":"mcm","clk":"11450476042","pt":1717322465123,"mc":[{"id":"1.229554929","rc":[{"atl":[[2.4,10.71]],"id":49546922}],"con":true,"img":false}]}
{"op":"mcm","clk":"11450476057","pt":1717322465195,"mc":[{"id":"1.229554929","rc":[{"atl":[[2.36,0]],"id":49546922}],"con":true,"img":false}]}
{"op":"mcm","clk":"11450476587","pt":1717322471333,"mc":[{"id":"1.229554929","rc":[{"atb":[[2,0],[1.9,0]],"id":47148562},{"atb":[[1.6,0],[1.7,0]],"id":49546922},{"atl":[[2.38,0]],"id":49546922}],"con":true,"img":false}]}
{"op":"mcm","clk":"11450476596","pt":1717322471436,"mc":[{"id":"1.229554929","rc":[{"atb":[[1.63,0],[1.43,144.25]],"id":47148562}],"con":true,"img":false}]}
{"op":"mcm","clk":"11450476637","pt":1717322471910,"mc":[{"id":"1.229554929","rc":[{"atb":[[1.52,28.85]],"id":47148562},{"atl":[[4.1,22.22],[3.25,0]],"id":47148562},{"atb":[[1.4,0],[1.42,35.71]],"id":49546922},{"atl":[[3.2,38.16],[2.62,0]],"id":49546922}],"con":true,"img":false}]}
{"op":"mcm","clk":"11450476644","pt":1717322472012,"mc":[{"id":"1.229554929","rc":[{"atb":[[1.45,88.88],[1.43,58.14]],"id":47148562}],"con":true,"img":false}]}
{"op":"mcm","clk":"11450477434","pt":1717322481944,"mc":[{"id":"1.229554929","rc":[{"atb":[[1.5,40]],"id":47148562},{"atl":[[2.44,13.89]],"id":49546922}],"con":true,"img":false}]}
{"op":"mcm","clk":"11450478104","pt":1717322490254,"mc":[{"id":"1.229554929","rc":[{"atb":[[2,7.84],[1.9,8.72]],"id":47148562},{"atb":[[1.6,13.07],[1.7,11.21]],"id":49546922}],"con":true,"img":false}]}
{"op":"mcm","clk":"11450478646","pt":1717322496933,"mc":[{"id":"1.229554929","rc":[{"atl":[[4.1,0],[3.4,19.63]],"id":47148562},{"atl":[[3.2,0],[2.62,31.5]],"id":49546922}],"con":true,"img":false}]}
{"op":"mcm","clk":"11450478654","pt":1717322497033,"mc":[{"id":"1.229554929","rc":[{"atb":[[1.45,44.44],[1.58,40]],"id":47148562}],"con":true,"img":false}]}
{"op":"mcm","clk":"11450481136","pt":1717322527904,"mc":[{"id":"1.229554929","rc":[{"atb":[[2,0],[1.9,0]],"id":47148562},{"atb":[[1.6,0],[1.7,0]],"id":49546922}],"con":true,"img":false}]}
{"op":"mcm","clk":"11450481141","pt":1717322528007,"mc":[{"id":"1.229554929","rc":[{"atb":[[1.58,0],[1.5,108.85]],"id":47148562}],"con":true,"img":false}]}
{"op":"mcm","clk":"11450481551","pt":1717322533116,"mc":[{"id":"1.229554929","rc":[{"atb":[[1.45,182.14],[1.5,40]],"id":47148562}],"con":true,"img":false}]}
{"op":"mcm","clk":"11450481715","pt":1717322534993,"mc":[{"id":"1.229554929","rc":[{"atl":[[4.1,22.22],[3.4,0]],"id":47148562},{"atl":[[3.2,35.22],[2.62,0]],"id":49546922}],"con":true,"img":false}]}
{"op":"mcm","clk":"11450481971","pt":1717322537904,"mc":[{"id":"1.229554929","rc":[{"atb":[[1.48,52.08]],"id":47148562}],"con":true,"img":false}]}
{"op":"mcm","clk":"11450482243","pt":1717322541413,"mc":[{"id":"1.229554929","rc":[{"atb":[[1.43,0]],"id":47148562}],"con":true,"img":false}]}
{"op":"mcm","clk":"11450482356","pt":1717322542828,"mc":[{"id":"1.229554929","rc":[{"atb":[[2,7.84],[1.9,8.72]],"id":47148562},{"atb":[[1.6,13.07],[1.7,11.21]],"id":49546922}],"con":true,"img":false}]}
{"op":"mcm","clk":"11450482397","pt":1717322543242,"mc":[{"id":"1.229554929","rc":[{"atl":[[4.1,0],[3.4,19.63]],"id":47148562},{"atl":[[3.2,0],[2.62,31.5]],"id":49546922}],"con":true,"img":false}]}
{"op":"mcm","clk":"11450483065","pt":1717322552463,"mc":[{"id":"1.229554929","rc":[{"atb":[[1.45,44.44],[1.58,40]],"id":47148562}],"con":true,"img":false}]}
{"op":"mcm","clk":"11450485462","pt":1717322584695,"mc":[{"id":"1.229554929","rc":[{"atb":[[2,0],[1.9,0]],"id":47148562},{"atb":[[1.6,0],[1.7,0]],"id":49546922}],"con":true,"img":false}]}
{"op":"mcm","clk":"11450485474","pt":1717322584805,"mc":[{"id":"1.229554929","rc":[{"atb":[[1.58,0],[1.5,108.85]],"id":47148562}],"con":true,"img":false}]}
{"op":"mcm","clk":"11450485553","pt":1717322585894,"mc":[{"id":"1.229554929","rc":[{"atl":[[3.4,0]],"id":47148562},{"atl":[[3.2,35.22],[2.62,0]],"id":49546922}],"con":true,"img":false}]}
{"op":"mcm","clk":"11450485559","pt":1717322585995,"mc":[{"id":"1.229554929","rc":[{"atl":[[4.1,22.22]],"id":47148562}],"con":true,"img":false}]}
{"op":"mcm","clk":"11450485868","pt":1717322589915,"mc":[{"id":"1.229554929","rc":[{"atb":[[1.5,40],[1.48,189.78]],"id":47148562}],"con":true,"img":false}]}
{"op":"mcm","clk":"11450486967","pt":1717322601652,"mc":[{"id":"1.229554929","rc":[{"atb":[[2,7.84],[1.9,8.72]],"id":47148562},{"atb":[[1.6,13.07],[1.7,11.21]],"id":49546922}],"con":true,"img":false}]}
{"op":"mcm","clk":"11450487688","pt":1717322609744,"mc":[{"id":"1.229554929","rc":[{"atl":[[3.2,0],[2.62,31.5]],"id":49546922}],"con":true,"img":false}]}
{"op":"mcm","clk":"11450487697","pt":1717322609839,"mc":[{"id":"1.229554929","rc":[{"atl":[[4.1,0],[3.4,19.63]],"id":47148562}],"con":true,"img":false}]}
{"op":"mcm","clk":"11450488025","pt":1717322613767,"mc":[{"id":"1.229554929","rc":[{"atb":[[1.58,40],[1.48,52.08]],"id":47148562}],"con":true,"img":false}]}
{"op":"mcm","clk":"11450489776","pt":1717322632388,"mc":[{"id":"1.229554929","rc":[{"atb":[[1.5,0],[1.48,0],[1.52,0]],"id":47148562},{"atb":[[1.42,0]],"id":49546922}],"con":true,"img":false}]}
{"op":"mcm","clk":"11450490356","pt":1717322639593,"mc":[{"id":"1.229554929","rc":[{"atb":[[2,0],[1.9,0]],"id":47148562},{"atb":[[1.6,0],[1.7,0]],"id":49546922}],"con":true,"img":false}]}
{"op":"mcm","clk":"11450490371","pt":1717322639792,"mc":[{"id":"1.229554929","rc":[{"atb":[[1.18,84.44],[1.58,0]],"id":47148562}],"con":true,"img":false}]}
{"op":"mcm","clk":"11450490773","pt":1717322643983,"mc":[{"id":"1.229554929","rc":[{"atb":[[1.52,28.85]],"id":47148562},{"atb":[[1.42,35.71]],"id":49546922}],"con":true,"img":false}]}
{"op":"mcm","clk":"11450490787","pt":1717322644087,"mc":[{"id":"1.229554929","rc":[{"atb":[[1.18,0],[1.53,44.44]],"id":47148562}],"con":true,"img":false}]}
{"op":"mcm","clk":"11450490813","pt":1717322644308,"mc":[{"id":"1.229554929","rc":[{"atb":[[1.18,73.29],[1.53,0]],"id":47148562}],"con":true,"img":false}]}
{"op":"mcm","clk":"11450490828","pt":1717322644504,"mc":[{"id":"1.229554929","rc":[{"atb":[[1.18,0],[1.45,102.14]],"id":47148562}],"con":true,"img":false}]}
{"op":"mcm","clk":"11450490849","pt":1717322644658,"mc":[{"id":"1.229554929","rc":[{"atb":[[1.18,130.99],[1.45,44.44]],"id":47148562}],"con":true,"img":false}]}
{"op":"mcm","clk":"11450491510","pt":1717322651899,"mc":[{"id":"1.229554929","rc":[{"atb":[[2,7.84],[1.9,8.72]],"id":47148562},{"atb":[[1.6,13.07],[1.7,11.21]],"id":49546922}],"con":true,"img":false}]}
{"op":"mcm","clk":"11450491515","pt":1717322652008,"mc":[{"id":"1.229554929","rc":[{"atb":[[1.58,44.44]],"id":47148562}],"con":true,"img":false}]}
{"op":"mcm","clk":"11450491523","pt":1717322652112,"mc":[{"id":"1.229554929","rc":[{"atb":[[1.18,0]],"id":47148562}],"con":true,"img":false}]}
{"op":"mcm","clk":"11450505673","pt":1717322805054,"mc":[{"id":"1.229554929","rc":[{"atb":[[1.52,0]],"id":47148562}],"con":true,"img":false}]}
{"op":"mcm","clk":"11450505727","pt":1717322805577,"mc":[{"id":"1.229554929","rc":[{"atb":[[2,0],[1.9,0]],"id":47148562},{"atb":[[1.6,0],[1.7,0]],"id":49546922}],"con":true,"img":false}]}
{"op":"mcm","clk":"11450505734","pt":1717322805645,"mc":[{"id":"1.229554929","rc":[{"atb":[[1.18,88.88],[1.58,0],[1.49,30.61]],"id":47148562},{"atl":[[3.75,22.22]],"id":47148562}],"con":true,"img":false}]}
{"op":"mcm","clk":"11450505747","pt":1717322805747,"mc":[{"id":"1.229554929","rc":[{"atb":[[1.45,133.32]],"id":47148562},{"atl":[[3.4,0]],"id":47148562},{"atb":[[1.43,34.88],[1.42,0]],"id":49546922},{"atl":[[2.9,35.22],[2.62,0]],"id":49546922}],"con":true,"img":false}]}
{"op":"mcm","clk":"11450505755","pt":1717322805846,"mc":[{"id":"1.229554929","rc":[{"atb":[[1.18,0]],"id":47148562}],"con":true,"img":false}]}
{"op":"mcm","clk":"11450505764","pt":1717322805950,"mc":[{"id":"1.229554929","rc":[{"atb":[[1.18,163.93]],"id":47148562},{"atl":[[4.1,22.22],[3.75,0]],"id":47148562}],"con":true,"img":false}]}
{"op":"mcm","clk":"11450505777","pt":1717322806057,"mc":[{"id":"1.229554929","rc":[{"atb":[[1.45,44.44]],"id":47148562}],"con":true,"img":false}]}
{"op":"mcm","clk":"11450506152","pt":1717322810872,"mc":[{"id":"1.229554929","rc":[{"atl":[[3.2,35.22],[2.9,0]],"id":49546922}],"con":true,"img":false}]}
{"op":"mcm","clk":"11450506581","pt":1717322815673,"mc":[{"id":"1.229554929","rc":[{"atb":[[1.47,42.55]],"id":47148562}],"con":true,"img":false}]}
{"op":"mcm","clk":"11450506593","pt":1717322815776,"mc":[{"id":"1.229554929","rc":[{"atb":[[1.48,61.22]],"id":47148562},{"atb":[[1.41,48.78]],"id":49546922}],"con":true,"img":false}]}
{"op":"mcm","clk":"11450506603","pt":1717322815882,"mc":[{"id":"1.229554929","rc":[{"atb":[[1.18,0]],"id":47148562}],"con":true,"img":false}]}
{"op":"mcm","clk":"11450506772","pt":1717322818082,"mc":[{"id":"1.229554929","rc":[{"atb":[[1.35,0]],"id":49546922}],"con":true,"img":false}]}
{"op":"mcm","clk":"11450507006","pt":1717322820789,"mc":[{"id":"1.229554929","rc":[{"atb":[[2,7.84],[1.9,8.72]],"id":47148562},{"atb":[[1.6,13.07],[1.7,11.21]],"id":49546922}],"con":true,"img":false}]}
{"op":"mcm","clk":"11450507017","pt":1717322820895,"mc":[{"id":"1.229554929","rc":[{"atb":[[1.48,0],[1.47,134.38]],"id":47148562}],"con":true,"img":false}]}
{"op":"mcm","clk":"11450507613","pt":1717322827357,"mc":[{"id":"1.229554929","rc":[{"atl":[[2.62,31.5]],"id":49546922}],"con":true,"img":false}]}
{"op":"mcm","clk":"11450507622","pt":1717322827461,"mc":[{"id":"1.229554929","rc":[{"atl":[[3.2,0]],"id":49546922}],"con":true,"img":false}]}
{"op":"mcm","clk":"11450507629","pt":1717322827562,"mc":[{"id":"1.229554929","rc":[{"atl":[[3.4,19.63]],"id":47148562}],"con":true,"img":false}]}
{"op":"mcm","clk":"11450507638","pt":1717322827676,"mc":[{"id":"1.229554929","rc":[{"atl":[[4.1,0]],"id":47148562}],"con":true,"img":false}]}
{"op":"mcm","clk":"11450508622","pt":1717322837388,"mc":[{"id":"1.229554929","rc":[{"atb":[[1.58,44.44],[1.47,42.55]],"id":47148562}],"con":true,"img":false}]}
{"op":"mcm","clk":"11450519258","pt":1717322940496,"mc":[{"id":"1.229554929","rc":[{"atb":[[1.43,0]],"id":49546922}],"con":true,"img":false}]}
{"op":"mcm","clk":"11450520355","pt":1717322950404,"mc":[{"id":"1.229554929","rc":[{"atl":[[2.36,11.03]],"id":49546922}],"con":true,"img":false}]}
{"op":"mcm","clk":"11450520369","pt":1717322950508,"mc":[{"id":"1.229554929","rc":[{"atl":[[2.4,0]],"id":49546922}],"con":true,"img":false}]}
{"op":"mcm","clk":"11450531652","pt":1717323066094,"mc":[{"id":"1.229554929","rc":[{"atl":[[2.4,10.71]],"id":49546922}],"con":true,"img":false}]}
{"op":"mcm","clk":"11450531661","pt":1717323066212,"mc":[{"id":"1.229554929","rc":[{"atl":[[2.36,0]],"id":49546922}],"con":true,"img":false}]}
{"op":"mcm","clk":"11450539341","pt":1717323141666,"mc":[{"id":"1.229554929","rc":[{"atb":[[2,0],[1.9,0]],"id":47148562},{"atb":[[1.6,0],[1.7,0]],"id":49546922}],"con":true,"img":false}]}
{"op":"mcm","clk":"11450539363","pt":1717323141882,"mc":[{"id":"1.229554929","rc":[{"atb":[[1.58,0],[1.47,117.6]],"id":47148562}],"con":true,"img":false}]}
{"op":"mcm","clk":"11450539499","pt":1717323142882,"mc":[{"id":"1.229554929","rc":[{"atb":[[1.51,29.41]],"id":47148562},{"atl":[[4.1,22.22],[3.4,0]],"id":47148562},{"atb":[[1.42,35.71]],"id":49546922},{"atl":[[3.2,35.22],[2.62,0]],"id":49546922}],"con":true,"img":false}]}
{"op":"mcm","clk":"11450540612","pt":1717323152809,"mc":[{"id":"1.229554929","rc":[{"atb":[[2,7.84],[1.9,8.72]],"id":47148562},{"atb":[[1.6,13.07],[1.7,11.21]],"id":49546922}],"con":true,"img":false}]}
{"op":"mcm","clk":"11450541477","pt":1717323160190,"mc":[{"id":"1.229554929","rc":[{"atb":[[1.58,30.61],[1.47,42.55]],"id":47148562}],"con":true,"img":false}]}
{"op":"mcm","clk":"11450541589","pt":1717323161186,"mc":[{"id":"1.229554929","rc":[{"atl":[[4.1,0],[3.4,19.63]],"id":47148562},{"atl":[[3.2,0],[2.62,31.5]],"id":49546922}],"con":true,"img":false}]}
{"op":"mcm","clk":"11450551194","pt":1717323248091,"mc":[{"id":"1.229554929","rc":[{"atl":[[2.46,48.33],[2.62,0]],"id":49546922}],"con":true,"img":false}]}
{"op":"mcm","clk":"11450551202","pt":1717323248133,"mc":[{"id":"1.229554929","rc":[{"atb":[[1.58,0],[1.66,30.61]],"id":47148562},{"atl":[[2.76,0]],"id":47148562}],"con":true,"img":false}]}
{"op":"mcm","clk":"11450551315","pt":1717323249268,"mc":[{"id":"1.229554929","rc":[{"atl":[[3.4,0],[3.25,22.22],[2.76,8.52]],"id":47148562},{"atl":[[2.46,20.55],[2.48,31.5]],"id":49546922}],"con":true,"img":false}]}
{"op":"mcm","clk":"11450551338","pt":1717323249423,"mc":[{"id":"1.229554929","rc":[{"atl":[[2.5,35.22],[2.48,0]],"id":49546922}],"con":true,"img":false}]}
{"op":"mcm","clk":"11450564619","pt":1717323369258,"mc":[{"id":"1.229554929","rc":[{"atb":[[1.58,30.61],[1.66,0]],"id":47148562},{"atl":[[2.5,0],[2.62,35.22]],"id":49546922}],"con":true,"img":false}]}
{"op":"mcm","clk":"11450569289","pt":1717323407080,"mc":[{"id":"1.229554929","rc":[{"atb":[[1.49,0],[1.51,0]],"id":47148562}],"con":true,"img":false}]}
{"op":"mcm","clk":"11450578815","pt":1717323487451,"mc":[{"id":"1.229554929","rc":[{"atb":[[2,0],[1.9,0]],"id":47148562},{"atb":[[1.6,0],[1.7,0]],"id":49546922}],"con":true,"img":false}]}
{"op":"mcm","clk":"11450578831","pt":1717323487511,"mc":[{"id":"1.229554929","rc":[{"atb":[[1.45,117.6]],"id":47148562}],"con":true,"img":false}]}
{"op":"mcm","clk":"11450578844","pt":1717323487618,"mc":[{"id":"1.229554929","rc":[{"atb":[[1.58,0]],"id":47148562}],"con":true,"img":false}]}
{"op":"mcm","clk":"11450579201","pt":1717323490813,"mc":[{"id":"1.229554929","rc":[{"atl":[[4.1,22.22],[3.25,0]],"id":47148562},{"atl":[[3.2,35.22],[2.62,0]],"id":49546922}],"con":true,"img":false}]}
{"op":"mcm","clk":"11450579380","pt":1717323492651,"mc":[{"id":"1.229554929","rc":[{"atb":[[1.18,160.15],[1.45,44.44]],"id":47148562}],"con":true,"img":false}]}
{"op":"mcm","clk":"11450579871","pt":1717323497097,"mc":[{"id":"1.229554929","rc":[{"atb":[[2,7.84],[1.9,8.72]],"id":47148562},{"atb":[[1.6,13.07],[1.7,11.21]],"id":49546922}],"con":true,"img":false}]}
{"op":"mcm","clk":"11450579886","pt":1717323497169,"mc":[{"id":"1.229554929","rc":[{"atb":[[1.49,30.61]],"id":47148562}],"con":true,"img":false}]}
{"op":"mcm","clk":"11450580788","pt":1717323505631,"mc":[{"id":"1.229554929","rc":[{"atl":[[4.1,0],[3.4,19.63]],"id":47148562},{"atl":[[3.2,0],[2.62,31.5]],"id":49546922}],"con":true,"img":false}]}
{"op":"mcm","clk":"11450580951","pt":1717323507469,"mc":[{"id":"1.229554929","rc":[{"atb":[[1.18,0],[1.58,42.55]],"id":47148562}],"con":true,"img":false}]}
{"op":"mcm","clk":"11450600797","pt":1717323710511,"mc":[{"id":"1.229554929","rc":[{"atl":[[2.4,0],[2.36,11.03]],"id":49546922}],"con":true,"img":false}]}
{"op":"mcm","clk":"11450606552","pt":1717323769427,"mc":[{"id":"1.229554929","rc":[{"atl":[[2.36,0],[2.4,10.71]],"id":49546922}],"con":true,"img":false}]}
{"op":"mcm","clk":"11450614327","pt":1717323847894,"mc":[{"id":"1.229554929","rc":[{"atb":[[2,0],[1.9,0]],"id":47148562},{"atb":[[1.6,0],[1.7,0]],"id":49546922}],"con":true,"img":false}]}
{"op":"mcm","clk":"11450614343","pt":1717323847995,"mc":[{"id":"1.229554929","rc":[{"atb":[[1.58,0],[1.47,115.71]],"id":47148562}],"con":true,"img":false}]}
{"op":"mcm","clk":"11450614920","pt":1717323853097,"mc":[{"id":"1.229554929","rc":[{"atb":[[1.45,190.76],[1.47,42.55]],"id":47148562}],"con":true,"img":false}]}
{"op":"mcm","clk":"11450615052","pt":1717323854190,"mc":[{"id":"1.229554929","rc":[{"atb":[[1.51,29.41]],"id":47148562},{"atl":[[4.1,22.22],[3.4,0]],"id":47148562},{"atl":[[3.2,35.22],[2.62,0]],"id":49546922}],"con":true,"img":false}]}
{"op":"mcm","clk":"11450616149","pt":1717323863247,"mc":[{"id":"1.229554929","rc":[{"atb":[[2,7.84],[1.9,8.72]],"id":47148562},{"atb":[[1.6,13.07],[1.7,11.21]],"id":49546922}],"con":true,"img":false}]}
{"op":"mcm","clk":"11450616290","pt":1717323864303,"mc":[{"id":"1.229554929","rc":[{"atb":[[1.45,44.44],[1.58,30.61]],"id":47148562}],"con":true,"img":false}]}
{"op":"mcm","clk":"11450616438","pt":1717323865393,"mc":[{"id":"1.229554929","rc":[{"atl":[[4.1,0],[3.4,19.63]],"id":47148562},{"atl":[[3.2,0],[2.62,31.5]],"id":49546922}],"con":true,"img":false}]}
{"op":"mcm","clk":"11450622607","pt":1717323926979,"mc":[{"id":"1.229554929","rc":[{"atb":[[1.51,0]],"id":47148562},{"atb":[[1.41,0],[1.42,0]],"id":49546922}],"con":true,"img":false}]}
{"op":"mcm","clk":"11450623311","pt":1717323934011,"mc":[{"id":"1.229554929","rc":[{"atl":[[2.4,0],[2.38,10.87]],"id":49546922}],"con":true,"img":false}]}
{"op":"mcm","clk":"11450623408","pt":1717323935102,"mc":[{"id":"1.229554929","rc":[{"atl":[[2.4,10.71],[2.38,0]],"id":49546922}],"con":true,"img":false}]}
{"op":"mcm","clk":"11450623446","pt":1717323935615,"mc":[{"id":"1.229554929","rc":[{"atl":[[2.4,0],[2.38,10.87]],"id":49546922}],"con":true,"img":false}]}
{"op":"mcm","clk":"11450623687","pt":1717323938217,"mc":[{"id":"1.229554929","rc":[{"atl":[[2.4,10.71],[2.38,0]],"id":49546922}],"con":true,"img":false}]}
{"op":"mcm","clk":"11450623705","pt":1717323938385,"mc":[{"id":"1.229554929","rc":[{"atl":[[2.4,0],[2.38,10.87]],"id":49546922}],"con":true,"img":false}]}
{"op":"mcm","clk":"11450623723","pt":1717323938498,"mc":[{"id":"1.229554929","rc":[{"atl":[[2.4,10.71]],"id":49546922}],"con":true,"img":false}]}
{"op":"mcm","clk":"11450623727","pt":1717323938599,"mc":[{"id":"1.229554929","rc":[{"atl":[[2.38,0]],"id":49546922}],"con":true,"img":false}]}
{"op":"mcm","clk":"11450623738","pt":1717323938714,"mc":[{"id":"1.229554929","rc":[{"atl":[[2.38,10.87]],"id":49546922}],"con":true,"img":false}]}
{"op":"mcm","clk":"11450623749","pt":1717323938814,"mc":[{"id":"1.229554929","rc":[{"atl":[[2.4,0]],"id":49546922}],"con":true,"img":false}]}
{"op":"mcm","clk":"11450623795","pt":1717323939324,"mc":[{"id":"1.229554929","rc":[{"atl":[[2.4,10.71],[2.38,0]],"id":49546922}],"con":true,"img":false}]}
{"op":"mcm","clk":"11450623869","pt":1717323940106,"mc":[{"id":"1.229554929","rc":[{"atl":[[2.4,0],[2.38,10.87]],"id":49546922}],"con":true,"img":false}]}
{"op":"mcm","clk":"11450623949","pt":1717323940935,"mc":[{"id":"1.229554929","rc":[{"atb":[[2.02,2],[1.63,30.61],[1.58,0]],"id":47148562},{"atl":[[2.5,2]],"id":47148562},{"atb":[[1.67,2]],"id":49546922},{"atl":[[2.3,2],[2.5,31.5],[2.62,0]],"id":49546922}],"con":true,"img":false}]}
{"op":"mcm","clk":"11450623970","pt":1717323941110,"mc":[{"id":"1.229554929","rc":[{"atb":[[1.37,135.14],[1.32,0]],"id":49546922}],"con":true,"img":false}]}
{"op":"mcm","clk":"11450624011","pt":1717323941511,"mc":[{"id":"1.229554929","rc":[{"atl":[[2.4,10.71],[2.38,0]],"id":49546922}],"con":true,"img":false}]}
{"op":"mcm","clk":"11450624469","pt":1717323946030,"mc":[{"id":"1.229554929","rc":[{"atl":[[2.3,0],[2.28,2]],"id":49546922}],"con":true,"img":false}]}
{"op":"mcm","clk":"11450624504","pt":1717323946301,"mc":[{"id":"1.229554929","rc":[{"atl":[[2.9,7.89]],"id":47148562},{"atl":[[2.4,0],[2.38,10.87]],"id":49546922}],"con":true,"img":false}]}
{"op":"mcm","clk":"11450624515","pt":1717323946401,"mc":[{"id":"1.229554929","rc":[{"atl":[[2.54,2],[2.5,0],[2.76,0]],"id":47148562},{"atb":[[1.67,0],[1.62,2]],"id":49546922}],"con":true,"img":false}]}
{"op":"mcm","clk":"11450624524","pt":1717323946508,"mc":[{"id":"1.229554929","rc":[{"atl":[[2.86,8.06]],"id":47148562}],"con":true,"img":false}]}
{"op":"mcm","clk":"11450624534","pt":1717323946608,"mc":[{"id":"1.229554929","rc":[{"atl":[[2.8,0]],"id":47148562}],"con":true,"img":false}]}
{"op":"mcm","clk":"11450624621","pt":1717323947795,"mc":[{"id":"1.229554929","rc":[{"atl":[[2.84,0]],"id":47148562},{"atl":[[2.4,10.71],[2.38,0]],"id":49546922}],"con":true,"img":false}]}
{"op":"mcm","clk":"11450624797","pt":1717323950039,"mc":[{"id":"1.229554929","rc":[{"atl":[[2.4,0],[2.38,10.87]],"id":49546922}],"con":true,"img":false}]}
{"op":"mcm","clk":"11450624844","pt":1717323950611,"mc":[{"id":"1.229554929","rc":[{"atl":[[2.4,10.71]],"id":49546922}],"con":true,"img":false}]}
{"op":"mcm","clk":"11450624850","pt":1717323950716,"mc":[{"id":"1.229554929","rc":[{"atl":[[2.38,0]],"id":49546922}],"con":true,"img":false}]}
{"op":"mcm","clk":"11450624897","pt":1717323951188,"mc":[{"id":"1.229554929","rc":[{"atb":[[1.63,0],[1.75,30.61]],"id":47148562},{"atl":[[2.5,0],[2.42,35.22]],"id":49546922}],"con":true,"img":false}]}
{"op":"mcm","clk":"11450624924","pt":1717323951501,"mc":[{"id":"1.229554929","rc":[{"atl":[[2.52,2]],"id":47148562}],"con":true,"img":false}]}
{"op":"mcm","clk":"11450624937","pt":1717323951607,"mc":[{"id":"1.229554929","rc":[{"atl":[[2.54,0]],"id":47148562}],"con":true,"img":false}]}
{"op":"mcm","clk":"11450625058","pt":1717323953012,"mc":[{"id":"1.229554929","rc":[{"atl":[[2.38,10.87]],"id":49546922}],"con":true,"img":false}]}
{"op":"mcm","clk":"11450625069","pt":1717323953109,"mc":[{"id":"1.229554929","rc":[{"atl":[[2.4,0]],"id":49546922}],"con":true,"img":false}]}
{"op":"mcm","clk":"11450625346","pt":1717323956535,"mc":[{"id":"1.229554929","rc":[{"atl":[[2.9,10.53]],"id":47148562}],"con":true,"img":false}]}
{"op":"mcm","clk":"11450625691","pt":1717323960535,"mc":[{"id":"1.229554929","rc":[{"atl":[[2.4,10.71],[2.38,0]],"id":49546922}],"con":true,"img":false}]}
{"op":"mcm","clk":"11450626156","pt":1717323966524,"mc":[{"id":"1.229554929","rc":[{"atl":[[2.94,12.89]],"id":47148562}],"con":true,"img":false}]}
{"op":"mcm","clk":"11450626520","pt":1717323970432,"mc":[{"id":"1.229554929","rc":[{"atl":[[2.4,0],[2.38,10.87]],"id":49546922}],"con":true,"img":false}]}
{"op":"mcm","clk":"11450626665","pt":1717323971740,"mc":[{"id":"1.229554929","rc":[{"atb":[[2,0],[1.9,0]],"id":47148562},{"atb":[[1.6,0],[1.7,0]],"id":49546922}],"con":true,"img":false}]}
{"op":"mcm","clk":"11450626672","pt":1717323971848,"mc":[{"id":"1.229554929","rc":[{"atb":[[2.02,0],[1.49,73.16],[1.75,0],[1.76,2]],"id":47148562},{"atb":[[1.63,2],[1.62,0]],"id":49546922}],"con":true,"img":false}]}
{"op":"mcm","clk":"11450626683","pt":1717323971952,"mc":[{"id":"1.229554929","rc":[{"atb":[[1.49,30.61],[1.75,30.61]],"id":47148562},{"atb":[[1.35,102.56]],"id":49546922}],"con":true,"img":false}]}
{"op":"mcm","clk":"11450626694","pt":1717323972061,"mc":[{"id":"1.229554929","rc":[{"atb":[[1.49,73.16],[1.75,0]],"id":47148562},{"atb":[[1.37,67.57]],"id":49546922}],"con":true,"img":false}]}
{"op":"mcm","clk":"11450626772","pt":1717323972850,"mc":[{"id":"1.229554929","rc":[{"atb":[[1.43,34.88]],"id":49546922},{"atl":[[2.4,10.71]],"id":49546922}],"con":true,"img":false}]}
{"op":"mcm","clk":"11450626792","pt":1717323972955,"mc":[{"id":"1.229554929","rc":[{"atl":[[2.38,0]],"id":49546922}],"con":true,"img":false}]}
{"op":"mcm","clk":"11450626852","pt":1717323973648,"mc":[{"id":"1.229554929","rc":[{"atb":[[1.77,2]],"id":47148562}],"con":true,"img":false}]}
{"op":"mcm","clk":"11450626863","pt":1717323973752,"mc":[{"id":"1.229554929","rc":[{"atb":[[1.49,30.61],[1.75,44.44],[1.76,0]],"id":47148562},{"atl":[[2.28,0],[2.26,2]],"id":49546922}],"con":true,"img":false}]}
{"op":"mcm","clk":"11450626951","pt":1717323974543,"mc":[{"id":"1.229554929","rc":[{"atb":[[1.77,0],[1.76,2]],"id":47148562},{"atl":[[2.28,2],[2.26,0]],"id":49546922}],"con":true,"img":false}]}
{"op":"mcm","clk":"11450627024","pt":1717323975432,"mc":[{"id":"1.229554929","rc":[{"atb":[[1.41,36.59],[1.43,0]],"id":49546922},{"atl":[[2.4,0],[2.42,28.17]],"id":49546922}],"con":true,"img":false}]}
{"op":"mcm","clk":"11450627074","pt":1717323975847,"mc":[{"id":"1.229554929","rc":[{"atl":[[2.38,10.87]],"id":49546922}],"con":true,"img":false}]}
{"op":"mcm","clk":"11450627150","pt":1717323976532,"mc":[{"id":"1.229554929","rc":[{"atb":[[1.45,100]],"id":47148562}],"con":true,"img":false}]}
{"op":"mcm","clk":"11450627161","pt":1717323976636,"mc":[{"id":"1.229554929","rc":[{"atb":[[1.45,55.56]],"id":47148562}],"con":true,"img":false}]}
{"op":"mcm","clk":"11450627171","pt":1717323976743,"mc":[{"id":"1.229554929","rc":[{"atb":[[1.49,77.05],[1.75,0]],"id":47148562}],"con":true,"img":false}]}
{"op":"mcm","clk":"11450627251","pt":1717323977725,"mc":[{"id":"1.229554929","rc":[{"atl":[[2.4,10.71],[2.38,0]],"id":49546922}],"con":true,"img":false}]}
{"op":"mcm","clk":"11450627370","pt":1717323978876,"mc":[{"id":"1.229554929","rc":[{"atb":[[1.5,30]],"id":47148562},{"atb":[[1.42,35.71]],"id":49546922}],"con":true,"img":false}]}
{"op":"mcm","clk":"11450627447","pt":1717323979658,"mc":[{"id":"1.229554929","rc":[{"atb":[[1.75,2],[1.76,0]],"id":47148562},{"atl":[[2.3,2],[2.28,0]],"id":49546922}],"con":true,"img":false}]}
{"op":"mcm","clk":"11450627461","pt":1717323979763,"mc":[{"id":"1.229554929","rc":[{"atb":[[1.75,32]],"id":47148562}],"con":true,"img":false}]}
{"op":"mcm","clk":"11450627470","pt":1717323979871,"mc":[{"id":"1.229554929","rc":[{"atb":[[1.49,30.61]],"id":47148562}],"con":true,"img":false}]}
{"op":"mcm","clk":"11450627479","pt":1717323979974,"mc":[{"id":"1.229554929","rc":[{"atb":[[1.49,92.61]],"id":47148562}],"con":true,"img":false}]}
{"op":"mcm","clk":"11450627492","pt":1717323980071,"mc":[{"id":"1.229554929","rc":[{"atb":[[1.75,2]],"id":47148562}],"con":true,"img":false}]}
{"op":"mcm","clk":"11450627552","pt":1717323980962,"mc":[{"id":"1.229554929","rc":[{"atb":[[2,7.84],[1.9,8.72]],"id":47148562},{"atb":[[1.6,13.07],[1.7,11.21]],"id":49546922}],"con":true,"img":false}]}
{"op":"mcm","clk":"11450627565","pt":1717323981077,"mc":[{"id":"1.229554929","rc":[{"atb":[[2.02,2],[1.49,30.61],[1.75,30]],"id":47148562}],"con":true,"img":false}]}
{"op":"mcm","clk":"11450627570","pt":1717323981176,"mc":[{"id":"1.229554929","rc":[{"atl":[[2.54,2],[2.52,0]],"id":47148562},{"atl":[[2.4,0],[2.32,11.36]],"id":49546922}],"con":true,"img":false}]}
{"op":"mcm","clk":"11450627888","pt":1717323984578,"mc":[{"id":"1.229554929","rc":[{"atl":[[2.56,2],[2.54,0]],"id":47148562}],"con":true,"img":false}]}
{"op":"mcm","clk":"11450627920","pt":1717323984943,"mc":[{"id":"1.229554929","rc":[{"atb":[[1.5,0],[1.49,0]],"id":47148562},{"atb":[[1.41,0],[1.42,0]],"id":49546922},{"atl":[[2.32,0],[2.38,10.87],[2.34,11.19]],"id":49546922}],"con":true,"img":false}]}
{"op":"mcm","clk":"11450628456","pt":1717323991492,"mc":[{"id":"1.229554929","rc":[{"atl":[[2.44,0],[2.34,0]],"id":49546922}],"con":true,"img":false}]}
{"op":"mcm","clk":"11450628571","pt":1717323992587,"mc":[{"id":"1.229554929","rc":[{"atl":[[2.32,11.36],[2.34,11.19]],"id":49546922}],"con":true,"img":false}]}
{"op":"mcm","clk":"11450628738","pt":1717323994161,"mc":[{"id":"1.229554929","rc":[{"atl":[[2.28,2]],"id":49546922}],"con":true,"img":false}]}
{"op":"mcm","clk":"11450628743","pt":1717323994266,"mc":[{"id":"1.229554929","rc":[{"atl":[[2.3,0],[2.32,0],[2.34,0]],"id":49546922}],"con":true,"img":false}]}
{"op":"mcm","clk":"11450628966","pt":1717323996772,"mc":[{"id":"1.229554929","rc":[{"atl":[[2.3,2]],"id":49546922}],"con":true,"img":false}]}
{"op":"mcm","clk":"11450628975","pt":1717323996866,"mc":[{"id":"1.229554929","rc":[{"atl":[[2.28,0]],"id":49546922}],"con":true,"img":false}]}
{"op":"mcm","clk":"11450629226","pt":1717323999813,"mc":[{"id":"1.229554929","rc":[{"atb":[[2,0],[1.9,0]],"id":47148562},{"atl":[[2.52,2]],"id":47148562},{"atb":[[1.6,0],[1.7,0]],"id":49546922}],"con":true,"img":false}]}
{"op":"mcm","clk":"11450629233","pt":1717323999870,"mc":[{"id":"1.229554929","rc":[{"atl":[[2.56,0]],"id":47148562}],"con":true,"img":false}]}
{"op":"mcm","clk":"11450629242","pt":1717323999977,"mc":[{"id":"1.229554929","rc":[{"atb":[[2.02,0],[1.74,2],[1.5,30],[1.75,0],[1.47,85.1]],"id":47148562},{"atb":[[1.42,35.71]],"id":49546922}],"con":true,"img":false}]}
{"op":"mcm","clk":"11450629735","pt":1717324004825,"mc":[{"id":"1.229554929","rc":[{"atb":[[1.98,8],[1.88,8.92]],"id":47148562},{"atb":[[1.72,10.89],[1.62,12.65]],"id":49546922}],"con":true,"img":false}]}
{"op":"mcm","clk":"11450629753","pt":1717324004977,"mc":[{"id":"1.229554929","rc":[{"atl":[[2.56,2],[2.52,0]],"id":47148562}],"con":true,"img":false}]}
{"op":"mcm","clk":"11450629763","pt":1717324005080,"mc":[{"id":"1.229554929","rc":[{"atb":[[1.99,2],[1.74,0]],"id":47148562}],"con":true,"img":false}]}
{"op":"mcm","clk":"11450630014","pt":1717324007998,"mc":[{"id":"1.229554929","rc":[{"atl":[[2.32,2]],"id":49546922}],"con":true,"img":false}]}
{"op":"mcm","clk":"11450630026","pt":1717324008104,"mc":[{"id":"1.229554929","rc":[{"atl":[[2.3,0]],"id":49546922}],"con":true,"img":false}]}
{"op":"mcm","clk":"11450630175","pt":1717324009718,"mc":[{"id":"1.229554929","rc":[{"atb":[[1.75,55.56]],"id":47148562}],"con":true,"img":false}]}
{"op":"mcm","clk":"11450630182","pt":1717324009818,"mc":[{"id":"1.229554929","rc":[{"atb":[[1.47,42.55]],"id":47148562}],"con":true,"img":false}]}
{"op":"mcm","clk":"11450630199","pt":1717324009979,"mc":[{"id":"1.229554929","rc":[{"atl":[[2.42,42.25]],"id":49546922}],"con":true,"img":false}]}
{"op":"mcm","clk":"11450630205","pt":1717324010089,"mc":[{"id":"1.229554929","rc":[{"atl":[[2.42,31.69]],"id":49546922}],"con":true,"img":false}]}
{"op":"mcm","clk":"11450630471","pt":1717324013112,"mc":[{"id":"1.229554929","rc":[{"atl":[[2.32,0],[2.28,2]],"id":49546922}],"con":true,"img":false}]}
{"op":"mcm","clk":"11450630898","pt":1717324018220,"mc":[{"id":"1.229554929","rc":[{"atl":[[2.3,2],[2.28,0]],"id":49546922}],"con":true,"img":false}]}
{"op":"mcm","clk":"11450630999","pt":1717324019534,"mc":[{"id":"1.229554929","rc":[{"atl":[[2.3,0],[2.28,2]],"id":49546922}],"con":true,"img":false}]}
{"op":"mcm","clk":"11450631033","pt":1717324020006,"mc":[{"id":"1.229554929","rc":[{"atl":[[2.46,17.12]],"id":49546922}],"con":true,"img":false}]}
{"op":"mcm","clk":"11450631966","pt":1717324030049,"mc":[{"id":"1.229554929","rc":[{"atl":[[2.5,20]],"id":49546922}],"con":true,"img":false}]}
{"op":"mcm","clk":"11450632500","pt":1717324037156,"mc":[{"id":"1.229554929","rc":[{"atl":[[2.24,2],[2.28,0]],"id":49546922}],"con":true,"img":false}]}
{"op":"mcm","clk":"11450632927","pt":1717324042249,"mc":[{"id":"1.229554929","rc":[{"atl":[[2.24,0],[2.26,2]],"id":49546922}],"con":true,"img":false}]}
{"op":"mcm","clk":"11450633392","pt":1717324047367,"mc":[{"id":"1.229554929","rc":[{"atl":[[2.24,2],[2.26,0]],"id":49546922}],"con":true,"img":false}]}
{"op":"mcm","clk":"11450633989","pt":1717324054042,"mc":[{"id":"1.229554929","rc":[{"atl":[[2.24,0],[2.26,2]],"id":49546922}],"con":true,"img":false}]}
{"op":"mcm","clk":"11450634243","pt":1717324056995,"mc":[{"id":"1.229554929","rc":[{"atl":[[2.24,2],[2.26,0]],"id":49546922}],"con":true,"img":false}]}
{"op":"mcm","clk":"11450634694","pt":1717324062495,"mc":[{"id":"1.229554929","rc":[{"atl":[[2.24,0],[2.26,2]],"id":49546922}],"con":true,"img":false}]}
{"op":"mcm","clk":"11450635027","pt":1717324066154,"mc":[{"id":"1.229554929","rc":[{"atl":[[2.24,2]],"id":49546922}],"con":true,"img":false}]}
{"op":"mcm","clk":"11450635038","pt":1717324066253,"mc":[{"id":"1.229554929","rc":[{"atl":[[2.26,0]],"id":49546922}],"con":true,"img":false}]}
{"op":"mcm","clk":"11450635066","pt":1717324066519,"mc":[{"id":"1.229554929","rc":[{"atl":[[2.54,34.24],[2.42,14.08]],"id":49546922}],"con":true,"img":false}]}
{"op":"mcm","clk":"11450635149","pt":1717324067353,"mc":[{"id":"1.229554929","rc":[{"atl":[[2.56,0],[2.54,2]],"id":47148562}],"con":true,"img":false}]}
{"op":"mcm","clk":"11450635584","pt":1717324071934,"mc":[{"id":"1.229554929","rc":[{"atl":[[2.24,0],[2.26,2]],"id":49546922}],"con":true,"img":false}]}
{"op":"mcm","clk":"11450635874","pt":1717324075243,"mc":[{"id":"1.229554929","rc":[{"atl":[[2.56,2],[2.54,0]],"id":47148562}],"con":true,"img":false}]}
{"op":"mcm","clk":"11450636031","pt":1717324077061,"mc":[{"id":"1.229554929","rc":[{"atl":[[2.24,2],[2.26,0]],"id":49546922}],"con":true,"img":false}]}
{"op":"mcm","clk":"11450636455","pt":1717324082165,"mc":[{"id":"1.229554929","rc":[{"atl":[[2.24,0],[2.26,2]],"id":49546922}],"con":true,"img":false}]}
{"op":"mcm","clk":"11450636572","pt":1717324083258,"mc":[{"id":"1.229554929","rc":[{"atl":[[2.24,2],[2.26,0]],"id":49546922}],"con":true,"img":false}]}
{"op":"mcm","clk":"11450636603","pt":1717324083568,"mc":[{"id":"1.229554929","rc":[{"atb":[[1.99,0]],"id":47148562},{"atl":[[2.56,0]],"id":47148562},{"atb":[[1.63,0]],"id":49546922},{"atl":[[2.24,0]],"id":49546922}],"con":true,"img":false}]}
{"op":"mcm","clk":"11450636655","pt":1717324084049,"mc":[{"id":"1.229554929","rc":[{"atb":[[1.62,42.55],[1.75,0]],"id":47148562},{"atb":[[1.28,86.99]],"id":49546922}],"con":true,"img":false}]}
{"op":"mcm","clk":"11450636664","pt":1717324084148,"mc":[{"id":"1.229554929","rc":[{"atb":[[1.35,0]],"id":49546922}],"con":true,"img":false}]}
{"op":"mcm","clk":"11450636998","pt":1717324088149,"mc":[{"id":"1.229554929","rc":[{"atb":[[1.98,0],[1.88,0]],"id":47148562},{"atb":[[1.72,0],[1.62,0]],"id":49546922}],"con":true,"img":false}]}
{"op":"mcm","clk":"11450637007","pt":1717324088252,"mc":[{"id":"1.229554929","rc":[{"atb":[[1.62,0],[1.47,115.1]],"id":47148562}],"con":true,"img":false}]}
{"op":"mcm","clk":"11450637017","pt":1717324088352,"mc":[{"id":"1.229554929","rc":[{"atb":[[1.45,200.66]],"id":47148562}],"con":true,"img":false}]}
{"op":"mcm","clk":"11450637026","pt":1717324088460,"mc":[{"id":"1.229554929","rc":[{"atb":[[1.47,42.55]],"id":47148562}],"con":true,"img":false}]}
{"op":"mcm","clk":"11450637186","pt":1717324090379,"mc":[{"id":"1.229554929","rc":[{"atl":[[3.4,0],[4.2,25.78]],"id":47148562},{"atl":[[2.54,0],[3.05,34.24]],"id":49546922}],"con":true,"img":false}]}
{"op":"mcm","clk":"11450637494","pt":1717324093977,"mc":[{"id":"1.229554929","rc":[{"atb":[[1.98,8],[1.88,8.92]],"id":47148562},{"atb":[[1.72,10.89],[1.62,12.65]],"id":49546922}],"con":true,"img":false}]}
{"op":"mcm","clk":"11450637502","pt":1717324094082,"mc":[{"id":"1.229554929","rc":[{"atl":[[3.45,23.42],[4.2,0]],"id":47148562},{"atl":[[2.54,31.2],[3.05,0]],"id":49546922}],"con":true,"img":false}]}
{"op":"mcm","clk":"11450637772","pt":1717324097156,"mc":[{"id":"1.229554929","rc":[{"atb":[[1.62,42.55]],"id":47148562}],"con":true,"img":false}]}
{"op":"mcm","clk":"11450637781","pt":1717324097259,"mc":[{"id":"1.229554929","rc":[{"atb":[[1.45,55.56]],"id":47148562}],"con":true,"img":false}]}
{"op":"mcm","clk":"11450647675","pt":1717324201634,"mc":[{"id":"1.229554929","rc":[{"atb":[[1.98,0],[1.88,0]],"id":47148562},{"atb":[[1.72,0],[1.62,0]],"id":49546922}],"con":true,"img":false}]}
{"op":"mcm","clk":"11450647704","pt":1717324201829,"mc":[{"id":"1.229554929","rc":[{"atb":[[1.62,0],[1.47,115.1]],"id":47148562}],"con":true,"img":false}]}
{"op":"mcm","clk":"11450647863","pt":1717324202941,"mc":[{"id":"1.229554929","rc":[{"atl":[[3.45,0],[4.2,25.78]],"id":47148562},{"atl":[[2.54,0],[3.05,34.24]],"id":49546922}],"con":true,"img":false}]}
{"op":"mcm","clk":"11450647876","pt":1717324203036,"mc":[{"id":"1.229554929","rc":[{"atb":[[1.45,200.66],[1.47,42.55]],"id":47148562}],"con":true,"img":false}]}
{"op":"mcm","clk":"11450648483","pt":1717324208859,"mc":[{"id":"1.229554929","rc":[{"atb":[[1.98,8],[1.88,8.92]],"id":47148562},{"atb":[[1.72,10.89],[1.62,12.65]],"id":49546922}],"con":true,"img":false}]}
{"op":"mcm","clk":"11450648662","pt":1717324210759,"mc":[{"id":"1.229554929","rc":[{"atb":[[1.45,55.56],[1.62,42.55]],"id":47148562}],"con":true,"img":false}]}
{"op":"mcm","clk":"11450649190","pt":1717324216201,"mc":[{"id":"1.229554929","rc":[{"atl":[[3.45,23.42],[4.2,0]],"id":47148562},{"atl":[[2.54,31.2],[3.05,0]],"id":49546922}],"con":true,"img":false}]}
{"op":"mcm","clk":"11450654448","pt":1717324266117,"mc":[{"id":"1.229554929","rc":[{"atb":[[1.99,2],[1.62,0],[1.52,42.55]],"id":47148562},{"atl":[[2.56,2],[3.45,0],[2.86,0],[2.58,9.49],[3.3,23.42]],"id":47148562},{"atb":[[1.63,2]],"id":49546922},{"atl":[[2.54,0],[2.26,2],[2.68,34.24]],"id":49546922}],"con":true,"img":false}]}
{"op":"mcm","clk":"11450654461","pt":1717324266270,"mc":[{"id":"1.229554929","rc":[{"atl":[[2.88,0],[2.94,0]],"id":47148562},{"atb":[[1.28,0],[1.4,67.57]],"id":49546922},{"atl":[[2.3,2],[2.26,0]],"id":49546922}],"con":true,"img":false}]}
{"op":"mcm","clk":"11450654620","pt":1717324268001,"mc":[{"id":"1.229554929","rc":[{"atl":[[2.3,0],[2.32,2]],"id":49546922}],"con":true,"img":false}]}
{"op":"mcm","clk":"11450654985","pt":1717324271294,"mc":[{"id":"1.229554929","rc":[{"atl":[[2.56,0],[2.48,2]],"id":47148562}],"con":true,"img":false}]}
{"op":"mcm","clk":"11450655176","pt":1717324273173,"mc":[{"id":"1.229554929","rc":[{"atb":[[1.72,42.55],[1.52,0]],"id":47148562},{"atl":[[2.92,18.98],[3.3,0]],"id":47148562},{"atl":[[2.42,31.2],[2.68,0]],"id":49546922}],"con":true,"img":false}]}
{"op":"mcm","clk":"11450655302","pt":1717324274162,"mc":[{"id":"1.229554929","rc":[{"atl":[[2.32,0],[2.34,2]],"id":49546922}],"con":true,"img":false}]}
{"op":"mcm","clk":"11450655592","pt":1717324276983,"mc":[{"id":"1.229554929","rc":[{"atl":[[2.62,12.35]],"id":47148562}],"con":true,"img":false}]}
{"op":"mcm","clk":"11450655910","pt":1717324280211,"mc":[{"id":"1.229554929","rc":[{"atl":[[2.42,14.08],[2.38,27.99]],"id":49546922}],"con":true,"img":false}]}
{"op":"mcm","clk":"11450656366","pt":1717324284603,"mc":[{"id":"1.229554929","rc":[{"atl":[[2.32,2],[2.34,0]],"id":49546922}],"con":true,"img":false}]}
{"op":"mcm","clk":"11450656440","pt":1717324285430,"mc":[{"id":"1.229554929","rc":[{"atl":[[2.42,44.07],[2.38,10.87]],"id":49546922}],"con":true,"img":false}]}
{"op":"mcm","clk":"11450656654","pt":1717324287716,"mc":[{"id":"1.229554929","rc":[{"atl":[[2.66,15.06]],"id":47148562}],"con":true,"img":false}]}
{"op":"mcm","clk":"11450657760","pt":1717324298226,"mc":[{"id":"1.229554929","rc":[{"atl":[[2.7,17.65]],"id":47148562}],"con":true,"img":false}]}
{"op":"mcm","clk":"11450657889","pt":1717324299433,"mc":[{"id":"1.229554929","rc":[{"atl":[[2.9,0]],"id":47148562}],"con":true,"img":false}]}
{"op":"mcm","clk":"11450657925","pt":1717324299741,"mc":[{"id":"1.229554929","rc":[{"atl":[[2.6,9.38],[2.58,0]],"id":47148562}],"con":true,"img":false}]}
{"op":"mcm","clk":"11450658256","pt":1717324302765,"mc":[{"id":"1.229554929","rc":[{"atb":[[1.98,0],[1.88,0]],"id":47148562},{"atb":[[1.72,0],[1.62,0]],"id":49546922}],"con":true,"img":false}]}
{"op":"mcm","clk":"11450658264","pt":1717324302819,"mc":[{"id":"1.229554929","rc":[{"atb":[[1.73,2]],"id":47148562}],"con":true,"img":false}]}
{"op":"mcm","clk":"11450658273","pt":1717324302921,"mc":[{"id":"1.229554929","rc":[{"atb":[[1.72,0],[1.99,0],[1.5,74.55]],"id":47148562}],"con":true,"img":false}]}
{"op":"mcm","clk":"11450658285","pt":1717324303026,"mc":[{"id":"1.229554929","rc":[{"atb":[[1.72,42.55],[1.5,30]],"id":47148562}],"con":true,"img":false}]}
{"op":"mcm","clk":"11450658299","pt":1717324303135,"mc":[{"id":"1.229554929","rc":[{"atb":[[1.73,0],[1.72,0],[1.74,2],[1.5,74.55]],"id":47148562}],"con":true,"img":false}]}
{"op":"mcm","clk":"11450658323","pt":1717324303344,"mc":[{"id":"1.229554929","rc":[{"atb":[[1.73,2],[1.72,42.55],[1.74,0],[1.5,30]],"id":47148562}],"con":true,"img":false}]}
{"op":"mcm","clk":"11450658646","pt":1717324306020,"mc":[{"id":"1.229554929","rc":[{"atl":[[2.42,40.55],[2.38,0]],"id":49546922}],"con":true,"img":false}]}
{"op":"mcm","clk":"11450659243","pt":1717324311238,"mc":[{"id":"1.229554929","rc":[{"atb":[[1.73,0],[1.72,44.55]],"id":47148562},{"atl":[[2.36,2],[2.32,0]],"id":49546922}],"con":true,"img":false}]}
{"op":"mcm","clk":"11450659257","pt":1717324311342,"mc":[{"id":"1.229554929","rc":[{"atb":[[1.72,2],[1.5,119.1],[1.51,29.41]],"id":47148562},{"atl":[[2.36,17.12],[2.42,0],[2.44,10.42],[2.34,2]],"id":49546922}],"con":true,"img":false}]}
{"op":"mcm","clk":"11450659271","pt":1717324311442,"mc":[{"id":"1.229554929","rc":[{"atl":[[2.36,0],[2.42,19.12]],"id":49546922}],"con":true,"img":false}]}
{"op":"mcm","clk":"11450659281","pt":1717324311549,"mc":[{"id":"1.229554929","rc":[{"atb":[[1.72,0],[1.71,2]],"id":47148562},{"atl":[[2.36,2],[2.34,0]],"id":49546922}],"con":true,"img":false}]}
{"op":"mcm","clk":"11450659292","pt":1717324311652,"mc":[{"id":"1.229554929","rc":[{"atb":[[1.5,30],[1.71,31.41]],"id":47148562},{"atl":[[2.36,12.42],[2.42,0]],"id":49546922}],"con":true,"img":false}]}
{"op":"mcm","clk":"11450659312","pt":1717324311861,"mc":[{"id":"1.229554929","rc":[{"atb":[[1.5,90.82],[1.71,2]],"id":47148562},{"atl":[[2.36,2],[2.44,35.26]],"id":49546922}],"con":true,"img":false}]}
{"op":"mcm","clk":"11450659336","pt":1717324312023,"mc":[{"id":"1.229554929","rc":[{"atl":[[2.46,54.38],[2.44,10.42]],"id":49546922}],"con":true,"img":false}]}
{"op":"mcm","clk":"11450659471","pt":1717324313275,"mc":[{"id":"1.229554929","rc":[{"atb":[[1.98,8],[1.88,8.92]],"id":47148562},{"atb":[[1.72,10.89],[1.62,12.65]],"id":49546922}],"con":true,"img":false}]}
{"op":"mcm","clk":"11450659483","pt":1717324313381,"mc":[{"id":"1.229554929","rc":[{"atb":[[1.74,29.41]],"id":47148562}],"con":true,"img":false}]}
{"op":"mcm","clk":"11450659493","pt":1717324313440,"mc":[{"id":"1.229554929","rc":[{"atb":[[1.5,30]],"id":47148562}],"con":true,"img":false}]}
{"op":"mcm","clk":"11450659819","pt":1717324316464,"mc":[{"id":"1.229554929","rc":[{"atb":[[1.5,0],[1.51,0]],"id":47148562},{"atb":[[1.42,0]],"id":49546922}],"con":true,"img":false}]}
{"op":"mcm","clk":"11450659831","pt":1717324316568,"mc":[{"id":"1.229554929","rc":[{"atl":[[2.36,13.03]],"id":49546922}],"con":true,"img":false}]}
{"op":"mcm","clk":"11450659838","pt":1717324316672,"mc":[{"id":"1.229554929","rc":[{"atb":[[1.99,2]],"id":47148562}],"con":true,"img":false}]}
{"op":"mcm","clk":"11450659848","pt":1717324316778,"mc":[{"id":"1.229554929","rc":[{"atb":[[1.71,0]],"id":47148562},{"atl":[[2.36,11.03],[2.34,2]],"id":49546922}],"con":true,"img":false}]}
{"op":"mcm","clk":"11450659994","pt":1717324318338,"mc":[{"id":"1.229554929","rc":[{"atl":[[2.5,2],[2.48,0]],"id":47148562}],"con":true,"img":false}]}
{"op":"mcm","clk":"11450660003","pt":1717324318440,"mc":[{"id":"1.229554929","rc":[{"atl":[[2.6,0],[2.62,9.26]],"id":47148562}],"con":true,"img":false}]}
{"op":"mcm","clk":"11450660131","pt":1717324319849,"mc":[{"id":"1.229554929","rc":[{"atl":[[2.36,0],[2.42,10.56]],"id":49546922}],"con":true,"img":false}]}
{"op":"mcm","clk":"11450660141","pt":1717324319954,"mc":[{"id":"1.229554929","rc":[{"atl":[[2.4,10.56],[2.46,17.12]],"id":49546922}],"con":true,"img":false}]}
{"op":"mcm","clk":"11450660152","pt":1717324320056,"mc":[{"id":"1.229554929","rc":[{"atl":[[2.4,0],[2.42,21.12]],"id":49546922}],"con":true,"img":false}]}
{"op":"mcm","clk":"11450660214","pt":1717324320694,"mc":[{"id":"1.229554929","rc":[{"atl":[[2.42,10.56],[2.34,13.19]],"id":49546922}],"con":true,"img":false}]}
{"op":"mcm","clk":"11450660236","pt":1717324320858,"mc":[{"id":"1.229554929","rc":[{"atl":[[2.42,0],[2.44,34.17]],"id":49546922}],"con":true,"img":false}]}
{"op":"mcm","clk":"11450660333","pt":1717324321858,"mc":[{"id":"1.229554929","rc":[{"atl":[[2.22,2],[2.34,11.19]],"id":49546922}],"con":true,"img":false}]}
{"op":"mcm","clk":"11450660342","pt":1717324321958,"mc":[{"id":"1.229554929","rc":[{"atl":[[2.44,10.42],[2.34,28.31]],"id":49546922}],"con":true,"img":false}]}
{"op":"mcm","clk":"11450660448","pt":1717324323055,"mc":[{"id":"1.229554929","rc":[{"atl":[[2.22,0],[2.14,2]],"id":49546922}],"con":true,"img":false}]}
{"op":"mcm","clk":"11450660498","pt":1717324323575,"mc":[{"id":"1.229554929","rc":[{"atl":[[2.56,2],[2.5,0]],"id":47148562}],"con":true,"img":false}]}
{"op":"mcm","clk":"11450660508","pt":1717324323636,"mc":[{"id":"1.229554929","rc":[{"atl":[[2.64,9.15]],"id":47148562}],"con":true,"img":false}]}
{"op":"mcm","clk":"11450660521","pt":1717324323789,"mc":[{"id":"1.229554929","rc":[{"atl":[[2.62,0]],"id":47148562}],"con":true,"img":false}]}
{"op":"mcm","clk":"11450660552","pt":1717324324059,"mc":[{"id":"1.229554929","rc":[{"atl":[[2.14,0],[2.08,2]],"id":49546922}],"con":true,"img":false}]}
{"op":"mcm","clk":"11450660641","pt":1717324324747,"mc":[{"id":"1.229554929","rc":[{"atl":[[2.24,2]],"id":49546922}],"con":true,"img":false}]}
{"op":"mcm","clk":"11450660648","pt":1717324324856,"mc":[{"id":"1.229554929","rc":[{"atl":[[2.08,0]],"id":49546922}],"con":true,"img":false}]}
{"op":"mcm","clk":"11450660671","pt":1717324325062,"mc":[{"id":"1.229554929","rc":[{"atl":[[2.42,10.56],[2.34,17.12]],"id":49546922}],"con":true,"img":false}]}
{"op":"mcm","clk":"11450660691","pt":1717324325268,"mc":[{"id":"1.229554929","rc":[{"atl":[[2.42,0],[2.34,28.31]],"id":49546922}],"con":true,"img":false}]}
{"op":"mcm","clk":"11450660907","pt":1717324327096,"mc":[{"id":"1.229554929","rc":[{"atl":[[2.44,40.73],[2.34,11.19]],"id":49546922}],"con":true,"img":false}]}
{"op":"mcm","clk":"11450660979","pt":1717324327771,"mc":[{"id":"1.229554929","rc":[{"atl":[[2.56,0],[2.58,2]],"id":47148562}],"con":true,"img":false}]}
{"op":"mcm","clk":"11450661035","pt":1717324328393,"mc":[{"id":"1.229554929","rc":[{"atl":[[2.6,2]],"id":47148562}],"con":true,"img":false}]}
{"op":"mcm","clk":"11450661046","pt":1717324328501,"mc":[{"id":"1.229554929","rc":[{"atl":[[2.58,0]],"id":47148562}],"con":true,"img":false}]}
{"op":"mcm","clk":"11450661114","pt":1717324329135,"mc":[{"id":"1.229554929","rc":[{"atl":[[2.64,0],[2.66,9.04]],"id":47148562}],"con":true,"img":false}]}
{"op":"mcm","clk":"11450661208","pt":1717324329913,"mc":[{"id":"1.229554929","rc":[{"atl":[[2.24,0],[2.22,2]],"id":49546922}],"con":true,"img":false}]}
{"op":"mcm","clk":"11450661218","pt":1717324330018,"mc":[{"id":"1.229554929","rc":[{"atl":[[2.44,10.42],[2.34,28.31]],"id":49546922}],"con":true,"img":false}]}
{"op":"mcm","clk":"11450661230","pt":1717324330121,"mc":[{"id":"1.229554929","rc":[{"atl":[[2.44,30.42],[2.34,11.19]],"id":49546922}],"con":true,"img":false}]}
{"op":"mcm","clk":"11450661265","pt":1717324330385,"mc":[{"id":"1.229554929","rc":[{"atl":[[2.6,0],[2.58,2]],"id":47148562}],"con":true,"img":false}]}
{"op":"mcm","clk":"11450661275","pt":1717324330491,"mc":[{"id":"1.229554929","rc":[{"atl":[[2.6,2],[2.58,0]],"id":47148562}],"con":true,"img":false}]}
{"op":"mcm","clk":"11450661318","pt":1717324330906,"mc":[{"id":"1.229554929","rc":[{"atl":[[2.6,0],[2.58,2]],"id":47148562}],"con":true,"img":false}]}
{"op":"mcm","clk":"11450661763","pt":1717324333899,"mc":[{"id":"1.229554929","rc":[{"atl":[[2.6,2],[2.58,0]],"id":47148562}],"con":true,"img":false}]}
{"op":"mcm","clk":"11450661904","pt":1717324334799,"mc":[{"id":"1.229554929","rc":[{"atl":[[2.4,10.71],[2.34,0]],"id":49546922}],"con":true,"img":false}]}
{"op":"mcm","clk":"11450661919","pt":1717324334906,"mc":[{"id":"1.229554929","rc":[{"atl":[[2.38,17.12]],"id":49546922}],"con":true,"img":false}]}
{"op":"mcm","clk":"11450661970","pt":1717324335013,"mc":[{"id":"1.229554929","rc":[{"atl":[[2.44,10.42]],"id":49546922}],"con":true,"img":false}]}
{"op":"mcm","clk":"11450662426","pt":1717324338898,"mc":[{"id":"1.229554929","rc":[{"atl":[[2.7,11.76]],"id":47148562}],"con":true,"img":false}]}
{"op":"mcm","clk":"11450662643","pt":1717324340618,"mc":[{"id":"1.229554929","rc":[{"atl":[[2.6,0],[2.62,2]],"id":47148562}],"con":true,"img":false}]}
{"op":"mcm","clk":"11450662877","pt":1717324342601,"mc":[{"id":"1.229554929","rc":[{"atl":[[2.64,2],[2.62,0]],"id":47148562}],"con":true,"img":false}]}
{"op":"mcm","clk":"11450663189","pt":1717324344792,"mc":[{"id":"1.229554929","rc":[{"atb":[[1.79,42.55],[1.74,0]],"id":47148562},{"atl":[[2.66,0],[2.68,8.93]],"id":47148562}],"con":true,"img":false}]}
{"op":"mcm","clk":"11450663472","pt":1717324347152,"mc":[{"id":"1.229554929","rc":[{"atl":[[2.4,0],[2.42,10.56]],"id":49546922}],"con":true,"img":false}]}
{"op":"mcm","clk":"11450663567","pt":1717324347931,"mc":[{"id":"1.229554929","rc":[{"atl":[[2.4,10.71],[2.42,0]],"id":49546922}],"con":true,"img":false}]}
{"op":"mcm","clk":"11450663605","pt":1717324348301,"mc":[{"id":"1.229554929","rc":[{"atl":[[2.64,0],[2.62,2]],"id":47148562}],"con":true,"img":false}]}
{"op":"mcm","clk":"11450663794","pt":1717324349920,"mc":[{"id":"1.229554929","rc":[{"atl":[[2.66,9.04]],"id":47148562}],"con":true,"img":false}]}
{"op":"mcm","clk":"11450664054","pt":1717324352115,"mc":[{"id":"1.229554929","rc":[{"atl":[[2.4,0],[2.42,10.56]],"id":49546922}],"con":true,"img":false}]}
{"op":"mcm","clk":"11450664074","pt":1717324352325,"mc":[{"id":"1.229554929","rc":[{"atl":[[2.4,10.71],[2.42,0]],"id":49546922}],"con":true,"img":false}]}
{"op":"mcm","clk":"11450664111","pt":1717324352637,"mc":[{"id":"1.229554929","rc":[{"atl":[[2.42,10.56]],"id":49546922}],"con":true,"img":false}]}
{"op":"mcm","clk":"11450664121","pt":1717324352740,"mc":[{"id":"1.229554929","rc":[{"atl":[[2.4,0]],"id":49546922}],"con":true,"img":false}]}
{"op":"mcm","clk":"11450664227","pt":1717324353628,"mc":[{"id":"1.229554929","rc":[{"atl":[[2.6,2],[2.62,0]],"id":47148562}],"con":true,"img":false}]}
{"op":"mcm","clk":"11450664286","pt":1717324354204,"mc":[{"id":"1.229554929","rc":[{"atl":[[2.6,0],[2.66,0],[2.62,2]],"id":47148562}],"con":true,"img":false}]}
{"op":"mcm","clk":"11450664295","pt":1717324354364,"mc":[{"id":"1.229554929","rc":[{"atl":[[2.66,9.04]],"id":47148562}],"con":true,"img":false}]}
{"op":"mcm","clk":"11450664345","pt":1717324354735,"mc":[{"id":"1.229554929","rc":[{"atl":[[2.6,2],[2.62,0]],"id":47148562}],"con":true,"img":false}]}
{"op":"mcm","clk":"11450664410","pt":1717324355314,"mc":[{"id":"1.229554929","rc":[{"atl":[[2.6,0],[2.62,2]],"id":47148562}],"con":true,"img":false}]}
{"op":"mcm","clk":"11450664436","pt":1717324355533,"mc":[{"id":"1.229554929","rc":[{"atl":[[2.6,2],[2.62,0]],"id":47148562}],"con":true,"img":false}]}
{"op":"mcm","clk":"11450664494","pt":1717324356184,"mc":[{"id":"1.229554929","rc":[{"atl":[[2.6,0],[2.58,2]],"id":47148562}],"con":true,"img":false}]}
{"op":"mcm","clk":"11450664624","pt":1717324357445,"mc":[{"id":"1.229554929","rc":[{"atl":[[2.56,2],[2.58,0]],"id":47148562}],"con":true,"img":false}]}
{"op":"mcm","clk":"11450664961","pt":1717324360434,"mc":[{"id":"1.229554929","rc":[{"atb":[[1.9,42.55]],"id":47148562},{"atl":[[3.05,7.32]],"id":47148562},{"atb":[[1.57,2]],"id":49546922}],"con":true,"img":false}]}
{"op":"mcm","clk":"11450664969","pt":1717324360527,"mc":[{"id":"1.229554929","rc":[{"atb":[[1.79,0]],"id":47148562},{"atl":[[2.56,0],[2.66,0]],"id":47148562},{"atb":[[1.63,0]],"id":49546922}],"con":true,"img":false}]}
{"op":"mcm","clk":"11450664979","pt":1717324360630,"mc":[{"id":"1.229554929","rc":[{"atl":[[2.64,2]],"id":47148562}],"con":true,"img":false}]}
{"op":"mcm","clk":"11450664989","pt":1717324360733,"mc":[{"id":"1.229554929","rc":[{"atl":[[2.68,0]],"id":47148562},{"atl":[[2.22,0],[2.18,2]],"id":49546922}],"con":true,"img":false}]}
{"op":"mcm","clk":"11450665011","pt":1717324360944,"mc":[{"id":"1.229554929","rc":[{"atl":[[2.38,0],[2.18,12.56]],"id":49546922}],"con":true,"img":false}]}
{"op":"mcm","clk":"11450665029","pt":1717324361151,"mc":[{"id":"1.229554929","rc":[{"atl":[[2.7,0]],"id":47148562},{"atl":[[2.18,10.56],[2.2,2]],"id":49546922}],"con":true,"img":false}]}
{"op":"mcm","clk":"11450665267","pt":1717324363189,"mc":[{"id":"1.229554929","rc":[{"atl":[[2.18,12.56],[2.2,0]],"id":49546922}],"con":true,"img":false}]}
{"op":"mcm","clk":"11450665512","pt":1717324365333,"mc":[{"id":"1.229554929","rc":[{"atl":[[2.42,0],[2.34,11.19]],"id":49546922}],"con":true,"img":false}]}
{"op":"mcm","clk":"11450665532","pt":1717324365547,"mc":[{"id":"1.229554929","rc":[{"atl":[[2.92,0]],"id":47148562}],"con":true,"img":false}]}
{"op":"mcm","clk":"11450665543","pt":1717324365652,"mc":[{"id":"1.229554929","rc":[{"atl":[[3.05,28.3]],"id":47148562}],"con":true,"img":false}]}
{"op":"mcm","clk":"11450665549","pt":1717324365747,"mc":[{"id":"1.229554929","rc":[{"atl":[[6.2,9.32],[2.64,0],[2.66,2]],"id":47148562}],"con":true,"img":false}]}
{"op":"mcm","clk":"11450665557","pt":1717324365850,"mc":[{"id":"1.229554929","rc":[{"atl":[[3.05,7.32]],"id":47148562}],"con":true,"img":false}]}
{"op":"mcm","clk":"11450665578","pt":1717324366062,"mc":[{"id":"1.229554929","rc":[{"atl":[[2.44,34.17]],"id":49546922}],"con":true,"img":false}]}
{"op":"mcm","clk":"11450665586","pt":1717324366164,"mc":[{"id":"1.229554929","rc":[{"atl":[[2.38,10.87],[2.18,2],[2.34,0]],"id":49546922}],"con":true,"img":false}]}
{"op":"mcm","clk":"11450665957","pt":1717324369823,"mc":[{"id":"1.229554929","rc":[{"atl":[[3.15,9.3]],"id":47148562}],"con":true,"img":false}]}
{"op":"mcm","clk":"11450665972","pt":1717324369927,"mc":[{"id":"1.229554929","rc":[{"atl":[[6.2,0],[3.15,18.62]],"id":47148562}],"con":true,"img":false}]}
{"op":"mcm","clk":"11450666055","pt":1717324370658,"mc":[{"id":"1.229554929","rc":[{"atb":[[1.98,0],[1.88,0]],"id":47148562},{"atb":[[1.72,0],[1.62,0]],"id":49546922}],"con":true,"img":false}]}
{"op":"mcm","clk":"11450666081","pt":1717324370968,"mc":[{"id":"1.229554929","rc":[{"atb":[[1.99,0],[1.84,2],[1.9,0],[1.5,44.55],[1.49,30.61]],"id":47148562},{"atb":[[1.56,2],[1.41,36.59]],"id":49546922}],"con":true,"img":false}]}
{"op":"mcm","clk":"11450666090","pt":1717324371032,"mc":[{"id":"1.229554929","rc":[{"atb":[[1.57,0]],"id":49546922}],"con":true,"img":false}]}
{"op":"mcm","clk":"11450666677","pt":1717324376443,"mc":[{"id":"1.229554929","rc":[{"atb":[[1.57,2]],"id":49546922}],"con":true,"img":false}]}
{"op":"mcm","clk":"11450666685","pt":1717324376545,"mc":[{"id":"1.229554929","rc":[{"atb":[[1.56,0]],"id":49546922}],"con":true,"img":false}]}
{"op":"mcm","clk":"11450666721","pt":1717324376959,"mc":[{"id":"1.229554929","rc":[{"atb":[[1.84,32.61],[1.5,0]],"id":47148562}],"con":true,"img":false}]}
{"op":"mcm","clk":"11450666731","pt":1717324377066,"mc":[{"id":"1.229554929","rc":[{"atb":[[1.84,2],[1.5,65.22]],"id":47148562}],"con":true,"img":false}]}
{"op":"mcm","clk":"11450666787","pt":1717324377642,"mc":[{"id":"1.229554929","rc":[{"atb":[[1.85,2]],"id":47148562}],"con":true,"img":false}]}
{"op":"mcm","clk":"11450666802","pt":1717324377799,"mc":[{"id":"1.229554929","rc":[{"atb":[[1.84,0]],"id":47148562}],"con":true,"img":false}]}
{"op":"mcm","clk":"11450667028","pt":1717324379970,"mc":[{"id":"1.229554929","rc":[{"atl":[[2.18,0],[2.2,2]],"id":49546922}],"con":true,"img":false}]}
{"op":"mcm","clk":"11450667039","pt":1717324380073,"mc":[{"id":"1.229554929","rc":[{"atl":[[2.38,27.99],[2.44,10.42]],"id":49546922}],"con":true,"img":false}]}
{"op":"mcm","clk":"11450667049","pt":1717324380175,"mc":[{"id":"1.229554929","rc":[{"atb":[[1.43,69.77]],"id":47148562},{"atl":[[3.25,11.11]],"id":47148562},{"atb":[[1.35,85.71]],"id":49546922}],"con":true,"img":false}]}
{"op":"mcm","clk":"11450667179","pt":1717324381459,"mc":[{"id":"1.229554929","rc":[{"atb":[[1.41,0],[1.43,34.88]],"id":49546922},{"atl":[[2.36,11.03],[2.38,17.12]],"id":49546922}],"con":true,"img":false}]}
{"op":"mcm","clk":"11450667342","pt":1717324382882,"mc":[{"id":"1.229554929","rc":[{"atb":[[1.82,2],[1.85,0]],"id":47148562}],"con":true,"img":false}]}
{"op":"mcm","clk":"11450667538","pt":1717324384561,"mc":[{"id":"1.229554929","rc":[{"atb":[[1.55,2]],"id":49546922}],"con":true,"img":false}]}
{"op":"mcm","clk":"11450667548","pt":1717324384666,"mc":[{"id":"1.229554929","rc":[{"atb":[[1.57,0]],"id":49546922}],"con":true,"img":false}]}
{"op":"mcm","clk":"11450667795","pt":1717324386883,"mc":[{"id":"1.229554929","rc":[{"atl":[[3.1,7.14],[2.66,0],[2.68,2],[3.05,0]],"id":47148562}],"con":true,"img":false}]}
{"op":"mcm","clk":"11450667801","pt":1717324386974,"mc":[{"id":"1.229554929","rc":[{"atl":[[3.1,18.25],[3.15,9.3]],"id":47148562}],"con":true,"img":false}]}
{"op":"mcm","clk":"11450667829","pt":1717324387198,"mc":[{"id":"1.229554929","rc":[{"atb":[[2,7.84],[1.9,8.72]],"id":47148562},{"atb":[[1.6,13.07],[1.7,11.21]],"id":49546922}],"con":true,"img":false}]}
{"op":"mcm","clk":"11450667850","pt":1717324387353,"mc":[{"id":"1.229554929","rc":[{"atb":[[1.5,0],[1.87,30.61]],"id":47148562}],"con":true,"img":false}]}
{"op":"mcm","clk":"11450667923","pt":1717324387978,"mc":[{"id":"1.229554929","rc":[{"atb":[[1.82,0],[2.02,2]],"id":47148562}],"con":true,"img":false}]}
{"op":"mcm","clk":"11450668438","pt":1717324392286,"mc":[{"id":"1.229554929","rc":[{"atl":[[2.68,0],[2.7,2]],"id":47148562}],"con":true,"img":false}]}
{"op":"mcm","clk":"11450668469","pt":1717324392513,"mc":[{"id":"1.229554929","rc":[{"atl":[[3.1,7.14],[3.15,29.55]],"id":47148562}],"con":true,"img":false}]}
{"op":"mcm","clk":"11450668605","pt":1717324393606,"mc":[{"id":"1.229554929","rc":[{"atl":[[2.18,2],[2.2,0]],"id":49546922}],"con":true,"img":false}]}
{"op":"mcm","clk":"11450668849","pt":1717324395748,"mc":[{"id":"1.229554929","rc":[{"atl":[[3.2,9.09]],"id":47148562}],"con":true,"img":false}]}
{"op":"mcm","clk":"11450669072","pt":1717324397799,"mc":[{"id":"1.229554929","rc":[{"atl":[[2.72,2],[2.7,0]],"id":47148562}],"con":true,"img":false}]}
{"op":"mcm","clk":"11450669258","pt":1717324399280,"mc":[{"id":"1.229554929","rc":[{"atb":[[1.49,0]],"id":47148562},{"atb":[[1.43,0]],"id":49546922},{"atl":[[2.36,0],[2.4,10.71]],"id":49546922}],"con":true,"img":false}]}
{"op":"mcm","clk":"11450669364","pt":1717324400079,"mc":[{"id":"1.229554929","rc":[{"atl":[[2.18,0],[2.2,2]],"id":49546922}],"con":true,"img":false}]}
{"op":"mcm","clk":"11450669376","pt":1717324400179,"mc":[{"id":"1.229554929","rc":[{"atl":[[2.38,0],[2.2,12.71]],"id":49546922}],"con":true,"img":false}]}
{"op":"mcm","clk":"11450669692","pt":1717324402909,"mc":[{"id":"1.229554929","rc":[{"atl":[[2.72,0],[2.7,2]],"id":47148562},{"atl":[[2.4,0],[2.38,10.87]],"id":49546922}],"con":true,"img":false}]}
{"op":"mcm","clk":"11450669856","pt":1717324404166,"mc":[{"id":"1.229554929","rc":[{"atl":[[2.4,10.71],[2.38,0]],"id":49546922}],"con":true,"img":false}]}
{"op":"mcm","clk":"11450669994","pt":1717324405305,"mc":[{"id":"1.229554929","rc":[{"atl":[[2.44,33.84]],"id":49546922}],"con":true,"img":false}]}
{"op":"mcm","clk":"11450670002","pt":1717324405412,"mc":[{"id":"1.229554929","rc":[{"atl":[[2.2,2]],"id":49546922}],"con":true,"img":false}]}
{"op":"mcm","clk":"11450670208","pt":1717324407283,"mc":[{"id":"1.229554929","rc":[{"atl":[[2.18,2],[2.2,0]],"id":49546922}],"con":true,"img":false}]}
{"op":"mcm","clk":"11450670627","pt":1717324410903,"mc":[{"id":"1.229554929","rc":[{"atl":[[2.4,0],[2.38,10.87]],"id":49546922}],"con":true,"img":false}]}
{"op":"mcm","clk":"11450671470","pt":1717324418388,"mc":[{"id":"1.229554929","rc":[{"atl":[[2.72,2],[2.7,0]],"id":47148562}],"con":true,"img":false}]}
{"op":"mcm","clk":"11450671662","pt":1717324420026,"mc":[{"id":"1.229554929","rc":[{"atb":[[2,0],[1.9,0]],"id":47148562},{"atb":[[1.6,0],[1.7,0]],"id":49546922}],"con":true,"img":false}]}
{"op":"mcm","clk":"11450671675","pt":1717324420130,"mc":[{"id":"1.229554929","rc":[{"atb":[[2.02,0],[1.84,2],[1.87,0],[1.47,98.11]],"id":47148562}],"con":true,"img":false}]}
{"op":"mcm","clk":"11450671688","pt":1717324420230,"mc":[{"id":"1.229554929","rc":[{"atb":[[1.84,57.56],[1.47,42.55]],"id":47148562}],"con":true,"img":false}]}
{"op":"mcm","clk":"11450671745","pt":1717324420612,"mc":[{"id":"1.229554929","rc":[{"atb":[[1.52,28.85]],"id":47148562},{"atb":[[1.4,105.07]],"id":49546922}],"con":true,"img":false}]}
{"op":"mcm","clk":"11450671790","pt":1717324421037,"mc":[{"id":"1.229554929","rc":[{"atb":[[1.84,55.56],[1.85,2]],"id":47148562}],"con":true,"img":false}]}
{"op":"mcm","clk":"11450671809","pt":1717324421196,"mc":[{"id":"1.229554929","rc":[{"atl":[[2.16,2]],"id":49546922}],"con":true,"img":false}]}
{"op":"mcm","clk":"11450671821","pt":1717324421351,"mc":[{"id":"1.229554929","rc":[{"atl":[[2.18,0]],"id":49546922}],"con":true,"img":false}]}
{"op":"mcm","clk":"11450671831","pt":1717324421407,"mc":[{"id":"1.229554929","rc":[{"atl":[[2.38,27.99],[2.44,10.42]],"id":49546922}],"con":true,"img":false}]}
{"op":"mcm","clk":"11450672000","pt":1717324422988,"mc":[{"id":"1.229554929","rc":[{"atl":[[2.18,2],[2.16,0]],"id":49546922}],"con":true,"img":false}]}
{"op":"mcm","clk":"11450672016","pt":1717324423095,"mc":[{"id":"1.229554929","rc":[{"atl":[[2.38,10.87],[2.18,12.42]],"id":49546922}],"con":true,"img":false}]}
{"op":"mcm","clk":"11450672121","pt":1717324423900,"mc":[{"id":"1.229554929","rc":[{"atl":[[2.18,10.42],[2.16,2]],"id":49546922}],"con":true,"img":false}]}
{"op":"mcm","clk":"11450672251","pt":1717324424899,"mc":[{"id":"1.229554929","rc":[{"atb":[[1.54,2]],"id":49546922}],"con":true,"img":false}]}
{"op":"mcm","clk":"11450672264","pt":1717324425006,"mc":[{"id":"1.229554929","rc":[{"atb":[[1.55,0]],"id":49546922}],"con":true,"img":false}]}
{"op":"mcm","clk":"11450672279","pt":1717324425111,"mc":[{"id":"1.229554929","rc":[{"atl":[[2.72,0],[2.68,2]],"id":47148562}],"con":true,"img":false}]}
{"op":"mcm","clk":"11450672306","pt":1717324425317,"mc":[{"id":"1.229554929","rc":[{"atb":[[1.84,0],[1.52,86.41]],"id":47148562}],"con":true,"img":false}]}
{"op":"mcm","clk":"11450672380","pt":1717324425899,"mc":[{"id":"1.229554929","rc":[{"atl":[[2.36,11.03],[2.38,0]],"id":49546922}],"con":true,"img":false}]}
{"op":"mcm","clk":"11450672392","pt":1717324425998,"mc":[{"id":"1.229554929","rc":[{"atb":[[1.55,2],[1.54,0]],"id":49546922}],"con":true,"img":false}]}
{"op":"mcm","clk":"11450672605","pt":1717324427649,"mc":[{"id":"1.229554929","rc":[{"atb":[[1.55,27.27],[1.52,57.56]],"id":47148562},{"atb":[[1.4,67.57],[1.41,36.59]],"id":49546922},{"atl":[[2.36,0],[2.38,10.87],[2.34,11.19]],"id":49546922}],"con":true,"img":false}]}
{"op":"mcm","clk":"11450672674","pt":1717324428218,"mc":[{"id":"1.229554929","rc":[{"atl":[[2.18,0],[2.34,23.61]],"id":49546922}],"con":true,"img":false}]}
{"op":"mcm","clk":"11450672719","pt":1717324428640,"mc":[{"id":"1.229554929","rc":[{"atl":[[2.44,0],[2.34,12.42]],"id":49546922}],"con":true,"img":false}]}
{"op":"mcm","clk":"11450672790","pt":1717324429215,"mc":[{"id":"1.229554929","rc":[{"atl":[[2.18,2],[2.16,0]],"id":49546922}],"con":true,"img":false}]}
{"op":"mcm","clk":"11450672940","pt":1717324430360,"mc":[{"id":"1.229554929","rc":[{"atb":[[1.55,0],[1.54,27.78]],"id":47148562},{"atb":[[1.41,0],[1.42,35.71]],"id":49546922}],"con":true,"img":false}]}
{"op":"mcm","clk":"11450672962","pt":1717324430527,"mc":[{"id":"1.229554929","rc":[{"atb":[[2,7.84],[1.9,8.72]],"id":47148562},{"atb":[[1.6,13.07],[1.7,11.21]],"id":49546922}],"con":true,"img":false}]}
{"op":"mcm","clk":"11450672988","pt":1717324430742,"mc":[{"id":"1.229554929","rc":[{"atb":[[2.02,2],[1.85,0]],"id":47148562}],"con":true,"img":false}]}
{"op":"mcm","clk":"11450673004","pt":1717324430843,"mc":[{"id":"1.229554929","rc":[{"atb":[[1.88,27.78],[1.52,0]],"id":47148562}],"con":true,"img":false}]}
{"op":"mcm","clk":"11450673132","pt":1717324431832,"mc":[{"id":"1.229554929","rc":[{"atl":[[2.18,0],[2.16,2]],"id":49546922}],"con":true,"img":false}]}
{"op":"mcm","clk":"11450673443","pt":1717324434240,"mc":[{"id":"1.229554929","rc":[{"atl":[[3.1,0],[2.66,2],[2.96,7.65],[2.68,0]],"id":47148562},{"atb":[[1.59,2],[1.55,0]],"id":49546922}],"con":true,"img":false}]}
{"op":"mcm","clk":"11450673452","pt":1717324434339,"mc":[{"id":"1.229554929","rc":[{"atl":[[3,9.09],[3.15,9.3]],"id":47148562}],"con":true,"img":false}]}
{"op":"mcm","clk":"11450673474","pt":1717324434552,"mc":[{"id":"1.229554929","rc":[{"atb":[[1.54,0]],"id":47148562},{"atb":[[1.42,0],[1.39,0]],"id":49546922}],"con":true,"img":false}]}
{"op":"mcm","clk":"11450673589","pt":1717324435339,"mc":[{"id":"1.229554929","rc":[{"atl":[[2.36,11.03]],"id":49546922}],"con":true,"img":false}]}
{"op":"mcm","clk":"11450673615","pt":1717324435544,"mc":[{"id":"1.229554929","rc":[{"atl":[[2.36,0]],"id":49546922}],"con":true,"img":false}]}
{"op":"mcm","clk":"11450674078","pt":1717324439412,"mc":[{"id":"1.229554929","rc":[{"atb":[[1.88,0],[1.94,27.78]],"id":47148562},{"atl":[[2.36,11.03]],"id":49546922}],"con":true,"img":false}]}
{"op":"mcm","clk":"11450674204","pt":1717324440333,"mc":[{"id":"1.229554929","rc":[{"atl":[[2.18,2],[2.16,0]],"id":49546922}],"con":true,"img":false}]}
{"op":"mcm","clk":"11450674238","pt":1717324440598,"mc":[{"id":"1.229554929","rc":[{"atl":[[2.18,13.03],[2.34,0]],"id":49546922}],"con":true,"img":false}]}
{"op":"mcm","clk":"11450674260","pt":1717324440706,"mc":[{"id":"1.229554929","rc":[{"atl":[[2.66,0],[2.68,2]],"id":47148562},{"atl":[[2.36,37.09],[2.18,2]],"id":49546922}],"con":true,"img":false}]}
{"op":"mcm","clk":"11450674863","pt":1717324445427,"mc":[{"id":"1.229554929","rc":[{"atl":[[2.16,2]],"id":49546922}],"con":true,"img":false}]}
{"op":"mcm","clk":"11450674876","pt":1717324445527,"mc":[{"id":"1.229554929","rc":[{"atl":[[2.24,12.1],[2.18,0]],"id":49546922}],"con":true,"img":false}]}
{"op":"mcm","clk":"11450674886","pt":1717324445637,"mc":[{"id":"1.229554929","rc":[{"atl":[[2.36,26.06]],"id":49546922}],"con":true,"img":false}]}
{"op":"mcm","clk":"11450674910","pt":1717324445843,"mc":[{"id":"1.229554929","rc":[{"atl":[[2.5,0],[2.38,0],[2.46,0]],"id":49546922}],"con":true,"img":false}]}
{"op":"mcm","clk":"11450675849","pt":1717324453556,"mc":[{"id":"1.229554929","rc":[{"atl":[[2.28,15.63]],"id":49546922}],"con":true,"img":false}]}
{"op":"mcm","clk":"11450675863","pt":1717324453656,"mc":[{"id":"1.229554929","rc":[{"atl":[[2.36,0],[2.28,29.73]],"id":49546922}],"con":true,"img":false}]}
{"op":"mcm","clk":"11450675909","pt":1717324453972,"mc":[{"id":"1.229554929","rc":[{"atb":[[2,0],[1.9,0]],"id":47148562},{"atb":[[1.6,0],[1.7,0]],"id":49546922}],"con":true,"img":false}]}
{"op":"mcm","clk":"11450675935","pt":1717324454136,"mc":[{"id":"1.229554929","rc":[{"atb":[[2.02,0],[1.54,55.56],[1.86,2],[1.94,0]],"id":47148562},{"atb":[[1.59,0],[1.53,2]],"id":49546922}],"con":true,"img":false}]}
{"op":"mcm","clk":"11450675948","pt":1717324454246,"mc":[{"id":"1.229554929","rc":[{"atb":[[1.55,27.27],[1.54,0],[1.87,42.55]],"id":47148562},{"atb":[[1.37,40.54]],"id":49546922}],"con":true,"img":false}]}
{"op":"mcm","clk":"11450675961","pt":1717324454354,"mc":[{"id":"1.229554929","rc":[{"atb":[[1.88,2]],"id":47148562}],"con":true,"img":false}]}
{"op":"mcm","clk":"11450675977","pt":1717324454458,"mc":[{"id":"1.229554929","rc":[{"atb":[[1.55,71.82],[1.86,0],[1.87,0]],"id":47148562}],"con":true,"img":false}]}
{"op":"mcm","clk":"11450675990","pt":1717324454558,"mc":[{"id":"1.229554929","rc":[{"atb":[[1.88,0],[1.86,2]],"id":47148562}],"con":true,"img":false}]}
{"op":"mcm","clk":"11450676428","pt":1717324457564,"mc":[{"id":"1.229554929","rc":[{"atl":[[2.68,0],[2.7,2]],"id":47148562},{"atb":[[1.53,0],[1.52,2]],"id":49546922}],"con":true,"img":false}]}
{"op":"mcm","clk":"11450676451","pt":1717324457730,"mc":[{"id":"1.229554929","rc":[{"atl":[[2.98,7.58],[2.96,0]],"id":47148562}],"con":true,"img":false}]}
{"op":"mcm","clk":"11450676589","pt":1717324458822,"mc":[{"id":"1.229554929","rc":[{"atb":[[1.38,39.47]],"id":49546922},{"atl":[[2.24,0],[2.3,11.54],[2.22,12.3]],"id":49546922}],"con":true,"img":false}]}
{"op":"mcm","clk":"11450676605","pt":1717324458930,"mc":[{"id":"1.229554929","rc":[{"atl":[[2.28,15.63],[2.2,12.3]],"id":49546922}],"con":true,"img":false}]}
{"op":"mcm","clk":"11450676629","pt":1717324459140,"mc":[{"id":"1.229554929","rc":[{"atl":[[2.22,26.6],[2.2,0]],"id":49546922}],"con":true,"img":false}]}
{"op":"mcm","clk":"11450676640","pt":1717324459244,"mc":[{"id":"1.229554929","rc":[{"atl":[[2.28,44.23]],"id":49546922}],"con":true,"img":false}]}
{"op":"mcm","clk":"11450676651","pt":1717324459341,"mc":[{"id":"1.229554929","rc":[{"atl":[[2.22,12.3]],"id":49546922}],"con":true,"img":false}]}
{"op":"mcm","clk":"11450676724","pt":1717324459962,"mc":[{"id":"1.229554929","rc":[{"atb":[[1.38,0]],"id":49546922},{"atl":[[2.22,0]],"id":49546922}],"con":true,"img":false}]}
{"op":"mcm","clk":"11450676790","pt":1717324460539,"mc":[{"id":"1.229554929","rc":[{"atl":[[2.28,28.6]],"id":49546922}],"con":true,"img":false}]}
{"op":"mcm","clk":"11450676885","pt":1717324461273,"mc":[{"id":"1.229554929","rc":[{"atb":[[1.55,44.55],[1.57,26.32]],"id":47148562},{"atb":[[1.38,39.47]],"id":49546922}],"con":true,"img":false}]}
{"op":"mcm","clk":"11450677428","pt":1717324465365,"mc":[{"id":"1.229554929","rc":[{"atb":[[1.57,0],[1.55,71.82]],"id":47148562},{"atb":[[1.38,0]],"id":49546922}],"con":true,"img":false}]}
{"op":"mcm","clk":"11450677467","pt":1717324465683,"mc":[{"id":"1.229554929","rc":[{"atb":[[2.06,7.4],[1.93,8.43]],"id":47148562},{"atb":[[1.56,14.01],[1.66,11.89]],"id":49546922}],"con":true,"img":false}]}
{"op":"mcm","clk":"11450677495","pt":1717324465859,"mc":[{"id":"1.229554929","rc":[{"atb":[[1.55,27.27],[1.86,0],[1.94,14.8],[2.08,2]],"id":47148562},{"atb":[[1.59,2],[1.52,0]],"id":49546922}],"con":true,"img":false}]}
{"op":"mcm","clk":"11450677508","pt":1717324465947,"mc":[{"id":"1.229554929","rc":[{"atb":[[1.96,14.8],[1.94,0]],"id":47148562}],"con":true,"img":false}]}
{"op":"mcm","clk":"11450677537","pt":1717324466259,"mc":[{"id":"1.229554929","rc":[{"atl":[[2.3,0],[2.32,11.36]],"id":49546922}],"con":true,"img":false}]}
{"op":"mcm","clk":"11450677795","pt":1717324468151,"mc":[{"id":"1.229554929","rc":[{"atl":[[2.32,0],[2.34,11.19]],"id":49546922}],"con":true,"img":false}]}
{"op":"mcm","clk":"11450677808","pt":1717324468254,"mc":[{"id":"1.229554929","rc":[{"atl":[[2.28,0],[2.34,41.79]],"id":49546922}],"con":true,"img":false}]}
{"op":"mcm","clk":"11450677835","pt":1717324468466,"mc":[{"id":"1.229554929","rc":[{"atb":[[1.37,0]],"id":49546922},{"atl":[[2.32,11.36]],"id":49546922}],"con":true,"img":false}]}
{"op":"mcm","clk":"11450678784","pt":1717324475943,"mc":[{"id":"1.229554929","rc":[{"atl":[[2.36,14.71]],"id":49546922}],"con":true,"img":false}]}
{"op":"mcm","clk":"11450679348","pt":1717324480486,"mc":[{"id":"1.229554929","rc":[{"atl":[[2.24,12.1]],"id":49546922}],"con":true,"img":false}]}
{"op":"mcm","clk":"11450679405","pt":1717324480960,"mc":[{"id":"1.229554929","rc":[{"atb":[[1.55,0]],"id":47148562}],"con":true,"img":false}]}
{"op":"mcm","clk":"11450679504","pt":1717324481647,"mc":[{"id":"1.229554929","rc":[{"atl":[[2.24,0]],"id":49546922}],"con":true,"img":false}]}
{"op":"mcm","clk":"11450679530","pt":1717324481850,"mc":[{"id":"1.229554929","rc":[{"atl":[[2.24,12.1]],"id":49546922}],"con":true,"img":false}]}
{"op":"mcm","clk":"11450679555","pt":1717324482058,"mc":[{"id":"1.229554929","rc":[{"atl":[[2.24,0]],"id":49546922}],"con":true,"img":false}]}
{"op":"mcm","clk":"11450679869","pt":1717324484541,"mc":[{"id":"1.229554929","rc":[{"atl":[[2.24,12.1]],"id":49546922}],"con":true,"img":false}]}
{"op":"mcm","clk":"11450679905","pt":1717324484855,"mc":[{"id":"1.229554929","rc":[{"atl":[[2.78,2],[2.7,0]],"id":47148562}],"con":true,"img":false}]}
{"op":"mcm","clk":"11450679946","pt":1717324485166,"mc":[{"id":"1.229554929","rc":[{"atl":[[2.98,0],[3.05,7.32]],"id":47148562}],"con":true,"img":false}]}
{"op":"mcm","clk":"11450680199","pt":1717324486953,"mc":[{"id":"1.229554929","rc":[{"atb":[[2.06,0],[1.93,0]],"id":47148562},{"atb":[[1.56,0],[1.66,0]],"id":49546922}],"con":true,"img":false}]}
{"op":"mcm","clk":"11450680231","pt":1717324487163,"mc":[{"id":"1.229554929","rc":[{"atb":[[1.56,55.56],[1.96,0],[1.86,2],[2.08,0]],"id":47148562},{"atb":[[1.59,0],[1.49,2]],"id":49546922}],"con":true,"img":false}]}
{"op":"mcm","clk":"11450680246","pt":1717324487264,"mc":[{"id":"1.229554929","rc":[{"atb":[[1.56,0],[1.86,57.56]],"id":47148562}],"con":true,"img":false}]}
{"op":"mcm","clk":"11450680260","pt":1717324487369,"mc":[{"id":"1.229554929","rc":[{"atb":[[1.56,115.12],[1.59,25.42],[1.86,0],[1.87,2]],"id":47148562},{"atl":[[3,0],[3.3,18.18]],"id":47148562},{"atb":[[1.4,0],[1.37,40.54],[1.35,155.28]],"id":49546922}],"con":true,"img":false}]}
{"op":"mcm","clk":"11450680271","pt":1717324487426,"mc":[{"id":"1.229554929","rc":[{"atb":[[1.87,27.42]],"id":47148562},{"atb":[[1.35,85.71],[1.38,40.54]],"id":49546922}],"con":true,"img":false}]}
{"op":"mcm","clk":"11450680284","pt":1717324487580,"mc":[{"id":"1.229554929","rc":[{"atb":[[1.56,0]],"id":47148562}],"con":true,"img":false}]}
{"op":"mcm","clk":"11450680436","pt":1717324488842,"mc":[{"id":"1.229554929","rc":[{"atb":[[1.86,2],[1.87,25.42]],"id":47148562}],"con":true,"img":false}]}
{"op":"mcm","clk":"11450680542","pt":1717324489770,"mc":[{"id":"1.229554929","rc":[{"atb":[[1.59,0],[1.58,25.86]],"id":47148562},{"atb":[[1.36,41.67],[1.37,0]],"id":49546922}],"con":true,"img":false}]}
{"op":"mcm","clk":"11450680683","pt":1717324490974,"mc":[{"id":"1.229554929","rc":[{"atl":[[2.24,0],[2.28,11.72]],"id":49546922}],"con":true,"img":false}]}
{"op":"mcm","clk":"11450680696","pt":1717324491078,"mc":[{"id":"1.229554929","rc":[{"atl":[[2.28,26.43],[2.34,11.19]],"id":49546922}],"con":true,"img":false}]}
{"op":"mcm","clk":"11450680832","pt":1717324492273,"mc":[{"id":"1.229554929","rc":[{"atb":[[1.58,68.41],[1.87,0]],"id":47148562}],"con":true,"img":false}]}
{"op":"mcm","clk":"11450681102","pt":1717324494364,"mc":[{"id":"1.229554929","rc":[{"atb":[[1.5,2],[1.49,0]],"id":49546922}],"con":true,"img":false}]}
{"op":"mcm","clk":"11450681159","pt":1717324494793,"mc":[{"id":"1.229554929","rc":[{"atb":[[1.97,8.08],[1.86,0],[1.87,2],[2.14,6.88]],"id":47148562},{"atb":[[1.51,15.38],[1.61,12.86]],"id":49546922}],"con":true,"img":false}]}
{"op":"mcm","clk":"11450681190","pt":1717324494950,"mc":[{"id":"1.229554929","rc":[{"atb":[[1.58,25.86],[1.96,42.55],[1.87,0],[2.16,2]],"id":47148562},{"atl":[[3.15,18.62],[3.3,0]],"id":47148562},{"atb":[[1.57,2],[1.5,0]],"id":49546922}],"con":true,"img":false}]}
{"op":"mcm","clk":"11450681309","pt":1717324495840,"mc":[{"id":"1.229554929","rc":[{"atl":[[2.16,0],[2.14,2]],"id":49546922}],"con":true,"img":false}]}
{"op":"mcm","clk":"11450681321","pt":1717324495943,"mc":[{"id":"1.229554929","rc":[{"atl":[[2.28,11.72],[2.14,13.36]],"id":49546922}],"con":true,"img":false}]}
{"op":"mcm","clk":"11450681434","pt":1717324497036,"mc":[{"id":"1.229554929","rc":[{"atl":[[2.16,2]],"id":49546922}],"con":true,"img":false}]}
{"op":"mcm","clk":"11450681443","pt":1717324497146,"mc":[{"id":"1.229554929","rc":[{"atl":[[2.14,11.36]],"id":49546922}],"con":true,"img":false}]}
{"op":"mcm","clk":"11450681863","pt":1717324500742,"mc":[{"id":"1.229554929","rc":[{"atl":[[2.28,25.08],[2.14,0]],"id":49546922}],"con":true,"img":false}]}
{"op":"mcm","clk":"11450681873","pt":1717324500845,"mc":[{"id":"1.229554929","rc":[{"atb":[[1.98,4.03]],"id":47148562},{"atl":[[2.78,5.87]],"id":47148562},{"atb":[[1.62,5.03]],"id":49546922},{"atl":[[2.16,6.8]],"id":49546922}],"con":true,"img":false}]}
{"op":"mcm","clk":"11450681907","pt":1717324501160,"mc":[{"id":"1.229554929","rc":[{"atl":[[2.28,11.72],[2.14,11.36]],"id":49546922}],"con":true,"img":false}]}
{"op":"mcm","clk":"11450682110","pt":1717324502878,"mc":[{"id":"1.229554929","rc":[{"atl":[[2.78,3.87],[2.76,2]],"id":47148562}],"con":true,"img":false}]}
{"op":"mcm","clk":"11450682136","pt":1717324503087,"mc":[{"id":"1.229554929","rc":[{"atl":[[2.14,13.76],[2.16,4.8]],"id":49546922}],"con":true,"img":false}]}
{"op":"mcm","clk":"11450682274","pt":1717324504291,"mc":[{"id":"1.229554929","rc":[{"atb":[[1.58,0]],"id":47148562},{"atl":[[2.28,0],[2.26,11.9]],"id":49546922}],"con":true,"img":false}]}
{"op":"mcm","clk":"11450682554","pt":1717324506692,"mc":[{"id":"1.229554929","rc":[{"atb":[[1.57,0],[1.58,2.4]],"id":49546922}],"con":true,"img":false}]}
{"op":"mcm","clk":"11450683216","pt":1717324512881,"mc":[{"id":"1.229554929","rc":[{"atl":[[3.05,0]],"id":47148562},{"atb":[[1.58,0],[1.55,2.4]],"id":49546922}],"con":true,"img":false}]}
{"op":"mcm","clk":"11450683905","pt":1717324518904,"mc":[{"id":"1.229554929","rc":[{"atb":[[1.97,0],[2.14,0]],"id":47148562},{"atb":[[1.51,0],[1.61,0]],"id":49546922}],"con":true,"img":false}]}
{"op":"mcm","clk":"11450683931","pt":1717324519080,"mc":[{"id":"1.229554929","rc":[{"atb":[[1.99,2],[2.16,0]],"id":47148562}],"con":true,"img":false}]}
{"op":"mcm","clk":"11450683948","pt":1717324519183,"mc":[{"id":"1.229554929","rc":[{"atb":[[1.96,0],[1.94,55.56]],"id":47148562}],"con":true,"img":false}]}
{"op":"mcm","clk":"11450684497","pt":1717324524210,"mc":[{"id":"1.229554929","rc":[{"atl":[[2.24,12.1],[2.26,0]],"id":49546922}],"con":true,"img":false}]}
{"op":"mcm","clk":"11450684758","pt":1717324526598,"mc":[{"id":"1.229554929","rc":[{"atb":[[1.36,0],[1.35,0]],"id":49546922}],"con":true,"img":false}]}
{"op":"mcm","clk":"11450684799","pt":1717324526965,"mc":[{"id":"1.229554929","rc":[{"atl":[[2.24,0],[2.22,12.3]],"id":49546922}],"con":true,"img":false}]}
{"op":"mcm","clk":"11450684965","pt":1717324528701,"mc":[{"id":"1.229554929","rc":[{"atb":[[1.97,8.08],[2.14,6.88]],"id":47148562},{"atb":[[1.51,15.38],[1.61,12.86]],"id":49546922}],"con":true,"img":false}]}
{"op":"mcm","clk":"11450684972","pt":1717324528803,"mc":[{"id":"1.229554929","rc":[{"atb":[[1.99,0],[2.16,2]],"id":47148562}],"con":true,"img":false}]}
{"op":"mcm","clk":"11450685219","pt":1717324531194,"mc":[{"id":"1.229554929","rc":[{"atl":[[2.24,12.1]],"id":49546922}],"con":true,"img":false}]}
{"op":"mcm","clk":"11450685229","pt":1717324531297,"mc":[{"id":"1.229554929","rc":[{"atl":[[2.22,0]],"id":49546922}],"con":true,"img":false}]}
{"op":"mcm","clk":"11450685346","pt":1717324532284,"mc":[{"id":"1.229554929","rc":[{"atb":[[2.16,5.89]],"id":47148562},{"atl":[[2.22,12.3],[2.12,4.99]],"id":49546922}],"con":true,"img":false}]}
{"op":"mcm","clk":"11450685359","pt":1717324532387,"mc":[{"id":"1.229554929","rc":[{"atl":[[2.24,0],[2.14,0],[2.1,9.9]],"id":49546922}],"con":true,"img":false}]}
{"op":"mcm","clk":"11450685687","pt":1717324535284,"mc":[{"id":"1.229554929","rc":[{"atb":[[1.56,4.9],[1.55,0]],"id":49546922}],"con":true,"img":false}]}
{"op":"mcm","clk":"11450685741","pt":1717324535801,"mc":[{"id":"1.229554929","rc":[{"atl":[[2.24,12.1],[2.22,0]],"id":49546922}],"con":true,"img":false}]}
{"op":"mcm","clk":"11450685750","pt":1717324535902,"mc":[{"id":"1.229554929","rc":[{"atl":[[2.2,12.5]],"id":49546922}],"con":true,"img":false}]}
{"op":"mcm","clk":"11450685790","pt":1717324536322,"mc":[{"id":"1.229554929","rc":[{"atl":[[2.24,0],[2.36,0],[2.32,0],[2.22,12.3],[2.2,0]],"id":49546922}],"con":true,"img":false}]}
{"op":"mcm","clk":"11450685801","pt":1717324536425,"mc":[{"id":"1.229554929","rc":[{"atb":[[1.99,12.78],[1.94,0]],"id":47148562}],"con":true,"img":false}]}
{"op":"mcm","clk":"11450685849","pt":1717324536797,"mc":[{"id":"1.229554929","rc":[{"atl":[[2.2,12.5]],"id":49546922}],"con":true,"img":false}]}
{"op":"mcm","clk":"11450685907","pt":1717324537312,"mc":[{"id":"1.229554929","rc":[{"atl":[[2.24,12.1]],"id":49546922}],"con":true,"img":false}]}
{"op":"mcm","clk":"11450685918","pt":1717324537415,"mc":[{"id":"1.229554929","rc":[{"atl":[[2.2,0]],"id":49546922}],"con":true,"img":false}]}
{"op":"mcm","clk":"11450685998","pt":1717324538223,"mc":[{"id":"1.229554929","rc":[{"atl":[[2.22,0]],"id":49546922}],"con":true,"img":false}]}
{"op":"mcm","clk":"11450686248","pt":1717324540220,"mc":[{"id":"1.229554929","rc":[{"atl":[[2.22,12.3]],"id":49546922}],"con":true,"img":false}]}
{"op":"mcm","clk":"11450686310","pt":1717324540795,"mc":[{"id":"1.229554929","rc":[{"atl":[[2.22,0]],"id":49546922}],"con":true,"img":false}]}
{"op":"mcm","clk":"11450686893","pt":1717324546523,"mc":[{"id":"1.229554929","rc":[{"atl":[[2.24,0],[2.26,11.9]],"id":49546922}],"con":true,"img":false}]}
{"op":"mcm","clk":"11450687417","pt":1717324551944,"mc":[{"id":"1.229554929","rc":[{"atb":[[1.99,0],[2.02,12.78]],"id":47148562}],"con":true,"img":false}]}
{"op":"mcm","clk":"11450687499","pt":1717324552717,"mc":[{"id":"1.229554929","rc":[{"atl":[[2.3,15.38]],"id":49546922}],"con":true,"img":false}]}
{"op":"mcm","clk":"11450687581","pt":1717324553606,"mc":[{"id":"1.229554929","rc":[{"atb":[[1.97,0],[2.14,0]],"id":47148562},{"atb":[[1.51,0],[1.61,0]],"id":49546922}],"con":true,"img":false}]}
{"op":"mcm","clk":"11450687794","pt":1717324555749,"mc":[{"id":"1.229554929","rc":[{"atl":[[2.24,12.1]],"id":49546922}],"con":true,"img":false}]}
{"op":"mcm","clk":"11450687817","pt":1717324555903,"mc":[{"id":"1.229554929","rc":[{"atl":[[2.1,4.99],[2.08,2.4]],"id":49546922}],"con":true,"img":false}]}
{"op":"mcm","clk":"11450688344","pt":1717324560758,"mc":[{"id":"1.229554929","rc":[{"atb":[[1.97,8.08],[2.14,6.88]],"id":47148562},{"atb":[[1.51,15.38],[1.61,12.86]],"id":49546922}],"con":true,"img":false}]}
{"op":"mcm","clk":"11450688736","pt":1717324564226,"mc":[{"id":"1.229554929","rc":[{"atl":[[2.24,0],[2.16,17.73]],"id":49546922}],"con":true,"img":false}]}
{"op":"mcm","clk":"11450689183","pt":1717324568439,"mc":[{"id":"1.229554929","rc":[{"atl":[[2.1,7.5],[2.08,0]],"id":49546922}],"con":true,"img":false}]}
{"op":"mcm","clk":"11450689302","pt":1717324569535,"mc":[{"id":"1.229554929","rc":[{"atb":[[1.97,0],[2.14,0]],"id":47148562},{"atb":[[1.51,0],[1.61,0]],"id":49546922}],"con":true,"img":false}]}
{"op":"mcm","clk":"11450689370","pt":1717324570163,"mc":[{"id":"1.229554929","rc":[{"atl":[[2.2,16.67]],"id":49546922}],"con":true,"img":false}]}
{"op":"mcm","clk":"11450689456","pt":1717324570849,"mc":[{"id":"1.229554929","rc":[{"atl":[[2.3,0],[2.26,0],[2.34,0]],"id":49546922}],"con":true,"img":false}]}
{"op":"mcm","clk":"11450689761","pt":1717324573554,"mc":[{"id":"1.229554929","rc":[{"atl":[[2.08,2.4]],"id":49546922}],"con":true,"img":false}]}
{"op":"mcm","clk":"11450689772","pt":1717324573670,"mc":[{"id":"1.229554929","rc":[{"atl":[[2.1,5]],"id":49546922}],"con":true,"img":false}]}
{"op":"mcm","clk":"11450689915","pt":1717324574761,"mc":[{"id":"1.229554929","rc":[{"atb":[[1.97,8.08],[2.14,6.88]],"id":47148562},{"atb":[[1.51,15.38],[1.61,12.86]],"id":49546922}],"con":true,"img":false}]}
{"op":"mcm","clk":"11450690050","pt":1717324575962,"mc":[{"id":"1.229554929","rc":[{"atl":[[2.24,20.16]],"id":49546922}],"con":true,"img":false}]}
{"op":"mcm","clk":"11450690176","pt":1717324576947,"mc":[{"id":"1.229554929","rc":[{"atl":[[2.1,7.5],[2.08,0]],"id":49546922}],"con":true,"img":false}]}
{"op":"mcm","clk":"11450690683","pt":1717324581669,"mc":[{"id":"1.229554929","rc":[{"atl":[[2.28,23.44]],"id":49546922}],"con":true,"img":false}]}
{"op":"mcm","clk":"11450690727","pt":1717324582079,"mc":[{"id":"1.229554929","rc":[{"atl":[[2.1,5],[2.08,4.9]],"id":49546922}],"con":true,"img":false}]}
{"op":"mcm","clk":"11450690839","pt":1717324582973,"mc":[{"id":"1.229554929","rc":[{"atl":[[2.2,12.5],[2.16,4.8]],"id":49546922}],"con":true,"img":false}]}
{"op":"mcm","clk":"11450690965","pt":1717324583971,"mc":[{"id":"1.229554929","rc":[{"atl":[[2.06,4.99]],"id":49546922}],"con":true,"img":false}]}
{"op":"mcm","clk":"11450690977","pt":1717324584069,"mc":[{"id":"1.229554929","rc":[{"atl":[[2.06,9.98],[2.04,2.5],[2.1,0],[2.08,0]],"id":49546922}],"con":true,"img":false}]}
{"op":"mcm","clk":"11450690987","pt":1717324584176,"mc":[{"id":"1.229554929","rc":[{"atl":[[2.06,4.99],[2.04,0],[2.08,11.98]],"id":49546922}],"con":true,"img":false}]}
{"op":"mcm","clk":"11450690998","pt":1717324584238,"mc":[{"id":"1.229554929","rc":[{"atl":[[2.06,9.99],[2.04,5],[2.08,0]],"id":49546922}],"con":true,"img":false}]}
{"op":"mcm","clk":"11450691011","pt":1717324584388,"mc":[{"id":"1.229554929","rc":[{"atl":[[2.06,4.99],[2.04,0],[2.08,11.98]],"id":49546922}],"con":true,"img":false}]}
{"op":"mcm","clk":"11450691024","pt":1717324584444,"mc":[{"id":"1.229554929","rc":[{"atl":[[2.06,14.99],[2.08,0]],"id":49546922}],"con":true,"img":false}]}
{"op":"mcm","clk":"11450691038","pt":1717324584554,"mc":[{"id":"1.229554929","rc":[{"atl":[[2.04,5],[2.1,16.97]],"id":49546922}],"con":true,"img":false}]}
{"op":"mcm","clk":"11450691050","pt":1717324584650,"mc":[{"id":"1.229554929","rc":[{"atl":[[2.06,4.99]],"id":49546922}],"con":true,"img":false}]}
{"op":"mcm","clk":"11450691062","pt":1717324584761,"mc":[{"id":"1.229554929","rc":[{"atl":[[2.02,5],[2.06,19.98],[2.1,0]],"id":49546922}],"con":true,"img":false}]}
{"op":"mcm","clk":"11450691072","pt":1717324584865,"mc":[{"id":"1.229554929","rc":[{"atl":[[2.04,0],[2.08,2]],"id":49546922}],"con":true,"img":false}]}
{"op":"mcm","clk":"11450691083","pt":1717324584986,"mc":[{"id":"1.229554929","rc":[{"atl":[[2,5],[2.08,0]],"id":49546922}],"con":true,"img":false}]}
{"op":"mcm","clk":"11450691504","pt":1717324588569,"mc":[{"id":"1.229554929","rc":[{"atl":[[2.24,16.13]],"id":49546922}],"con":true,"img":false}]}
{"op":"mcm","clk":"11450691665","pt":1717324589876,"mc":[{"id":"1.229554929","rc":[{"atl":[[2.04,10]],"id":49546922}],"con":true,"img":false}]}
{"op":"mcm","clk":"11450691679","pt":1717324589987,"mc":[{"id":"1.229554929","rc":[{"atl":[[2.06,4.99]],"id":49546922}],"con":true,"img":false}]}
{"op":"mcm","clk":"11450691738","pt":1717324590455,"mc":[{"id":"1.229554929","rc":[{"atl":[[2.24,0],[2.2,0]],"id":49546922}],"con":true,"img":false}]}
{"op":"mcm","clk":"11450692672","pt":1717324598095,"mc":[{"id":"1.229554929","rc":[{"atb":[[1.97,0],[2.14,0]],"id":47148562},{"atb":[[1.51,0],[1.61,0]],"id":49546922}],"con":true,"img":false}]}
{"op":"mcm","clk":"11450692961","pt":1717324600179,"mc":[{"id":"1.229554929","rc":[{"atb":[[2.02,0],[1.75,55.56]],"id":47148562},{"atl":[[4.8,18.18],[3.2,0],[3.15,0],[3.25,0],[3.9,2],[2.76,0]],"id":47148562},{"atb":[[1.23,10.06],[1.33,2],[1.38,0]],"id":49546922},{"atl":[[2,10],[2.04,0]],"id":49546922}],"con":true,"img":false}]}
{"op":"mcm","clk":"11450692971","pt":1717324600286,"mc":[{"id":"1.229554929","rc":[{"atb":[[1.56,0]],"id":49546922}],"con":true,"img":false}]}
{"op":"mcm","clk":"11450693281","pt":1717324602903,"mc":[{"id":"1.229554929","rc":[{"atb":[[2.24,6.33],[2.04,7.54]],"id":47148562},{"atb":[[1.57,13.77],[1.47,16.69]],"id":49546922}],"con":true,"img":false}]}
{"op":"mcm","clk":"11450693300","pt":1717324603106,"mc":[{"id":"1.229554929","rc":[{"atb":[[2.18,3.88],[2.16,3.89]],"id":47148562}],"con":true,"img":false}]}
{"op":"mcm","clk":"11450694385","pt":1717324612349,"mc":[{"id":"1.229554929","rc":[{"atb":[[1.75,0]],"id":47148562}],"con":true,"img":false}]}
{"op":"mcm","clk":"11450694397","pt":1717324612399,"mc":[{"id":"1.229554929","rc":[{"atb":[[1.8,55.56]],"id":47148562}],"con":true,"img":false}]}
{"op":"mcm","clk":"11450695686","pt":1717324623219,"mc":[{"id":"1.229554929","rc":[{"atl":[[2.2,12.5]],"id":49546922}],"con":true,"img":false}]}
{"op":"mcm","clk":"11450695870","pt":1717324624789,"mc":[{"id":"1.229554929","rc":[{"atb":[[1.8,0],[1.85,55.56]],"id":47148562}],"con":true,"img":false}]}
{"op":"mcm","clk":"11450695979","pt":1717324625727,"mc":[{"id":"1.229554929","rc":[{"atb":[[2.18,7.75]],"id":47148562},{"atl":[[1.99,5.02],[2.18,12.71],[2.16,0]],"id":49546922}],"con":true,"img":false}]}
{"op":"mcm","clk":"11450695987","pt":1717324625833,"mc":[{"id":"1.229554929","rc":[{"atl":[[2,0],[1.98,10.06]],"id":49546922}],"con":true,"img":false}]}
{"op":"mcm","clk":"11450696008","pt":1717324625994,"mc":[{"id":"1.229554929","rc":[{"atb":[[2.24,0],[2.04,0]],"id":47148562},{"atb":[[1.57,0],[1.47,0]],"id":49546922}],"con":true,"img":false}]}
{"op":"mcm","clk":"11450696899","pt":1717324633745,"mc":[{"id":"1.229554929","rc":[{"atb":[[2.24,6.33],[2.04,7.54]],"id":47148562},{"atb":[[1.57,13.77],[1.47,16.69]],"id":49546922}],"con":true,"img":false}]}
{"op":"mcm","clk":"11450697518","pt":1717324638921,"mc":[{"id":"1.229554929","rc":[{"atb":[[1.85,0],[1.9,55.56]],"id":47148562}],"con":true,"img":false}]}
{"op":"mcm","clk":"11450697818","pt":1717324641428,"mc":[{"id":"1.229554929","rc":[{"atl":[[2.18,0],[2.2,0],[2.16,12.93]],"id":49546922}],"con":true,"img":false}]}
{"op":"mcm","clk":"11450698294","pt":1717324645252,"mc":[{"id":"1.229554929","rc":[{"atl":[[2.16,0]],"id":49546922}],"con":true,"img":false}]}
{"op":"mcm","clk":"11450698329","pt":1717324645563,"mc":[{"id":"1.229554929","rc":[{"atb":[[2.24,0],[2.04,0]],"id":47148562},{"atb":[[1.57,0],[1.47,0]],"id":49546922}],"con":true,"img":false}]}
{"op":"mcm","clk":"11450698799","pt":1717324649571,"mc":[{"id":"1.229554929","rc":[{"atb":[[1.9,0],[1.94,55.56]],"id":47148562}],"con":true,"img":false}]}
{"op":"mcm","clk":"11450699423","pt":1717324654758,"mc":[{"id":"1.229554929","rc":[{"atb":[[2.24,6.33],[2.04,7.54]],"id":47148562},{"atb":[[1.57,13.77],[1.47,16.69]],"id":49546922}],"con":true,"img":false}]}
{"op":"mcm","clk":"11450699439","pt":1717324654857,"mc":[{"id":"1.229554929","rc":[{"atb":[[1.97,55.56],[1.94,0]],"id":47148562}],"con":true,"img":false}]}
{"op":"mcm","clk":"11450699457","pt":1717324654967,"mc":[{"id":"1.229554929","rc":[{"atb":[[2.18,3.87],[2.2,3.88]],"id":47148562}],"con":true,"img":false}]}
{"op":"mcm","clk":"11450699470","pt":1717324655075,"mc":[{"id":"1.229554929","rc":[{"atb":[[2.18,7.75],[2.2,0]],"id":47148562}],"con":true,"img":false}]}
{"op":"mcm","clk":"11450699706","pt":1717324657154,"mc":[{"id":"1.229554929","rc":[{"atl":[[1.72,15],[1.79,33],[1.84,50],[1.7,10],[1.75,22]],"id":49546922}],"con":true,"img":false}]}
{"op":"mcm","clk":"11450699718","pt":1717324657257,"mc":[{"id":"1.229554929","rc":[{"atl":[[1.98,0],[1.8,37],[1.74,14.38]],"id":49546922}],"con":true,"img":false}]}
{"op":"mcm","clk":"11450700084","pt":1717324660591,"mc":[{"id":"1.229554929","rc":[{"atb":[[2,42.55],[1.97,0],[2.18,3.87],[2.2,3.88]],"id":47148562}],"con":true,"img":false}]}
{"op":"mcm","clk":"11450700152","pt":1717324661286,"mc":[{"id":"1.229554929","rc":[{"atb":[[2.24,10.08]],"id":47148562}],"con":true,"img":false}]}
{"op":"mcm","clk":"11450701438","pt":1717324672593,"mc":[{"id":"1.229554929","rc":[{"atb":[[2,0],[2.04,15.31]],"id":47148562}],"con":true,"img":false}]}
{"op":"mcm","clk":"11450701786","pt":1717324675489,"mc":[{"id":"1.229554929","rc":[{"atb":[[2.18,5.87],[2.2,0]],"id":47148562},{"atl":[[1.78,37],[1.8,0]],"id":49546922}],"con":true,"img":false}]}
{"op":"mcm","clk":"11450701807","pt":1717324675696,"mc":[{"id":"1.229554929","rc":[{"atb":[[2.5,10],[2.32,33],[2.22,50],[2.4,22],[2.46,15]],"id":47148562}],"con":true,"img":false}]}
{"op":"mcm","clk":"11450702005","pt":1717324677514,"mc":[{"id":"1.229554929","rc":[{"atb":[[2.04,7.77],[2.24,3.75]],"id":47148562},{"atb":[[1.57,0],[1.47,0]],"id":49546922}],"con":true,"img":false}]}
{"op":"mcm","clk":"11450702382","pt":1717324680572,"mc":[{"id":"1.229554929","rc":[{"atb":[[2.24,5.75],[2.18,3.87]],"id":47148562}],"con":true,"img":false}]}
{"op":"mcm","clk":"11450703011","pt":1717324685716,"mc":[{"id":"1.229554929","rc":[{"atl":[[1.78,0],[1.76,37]],"id":49546922}],"con":true,"img":false}]}
{"op":"mcm","clk":"11450703127","pt":1717324686715,"mc":[{"id":"1.229554929","rc":[{"atb":[[2.04,15.31],[2.24,12.08]],"id":47148562},{"atb":[[1.57,13.77],[1.47,16.69]],"id":49546922}],"con":true,"img":false}]}
{"op":"mcm","clk":"11450703883","pt":1717324693597,"mc":[{"id":"1.229554929","rc":[{"atb":[[2.04,7.54],[2.14,27.09]],"id":47148562}],"con":true,"img":false}]}
{"op":"mcm","clk":"11450705143","pt":1717324706133,"mc":[{"id":"1.229554929","rc":[{"atl":[[4.8,0],[4.3,9.18],[3.55,2],[3.9,0]],"id":47148562},{"atb":[[1.33,0],[1.38,2.52]],"id":49546922},{"atl":[[1.76,0],[1.79,66]],"id":49546922}],"con":true,"img":false}]}
{"op":"mcm","clk":"11450705769","pt":1717324711951,"mc":[{"id":"1.229554929","rc":[{"atb":[[2.42,21]],"id":47148562}],"con":true,"img":false}]}
{"op":"mcm","clk":"11450705808","pt":1717324712379,"mc":[{"id":"1.229554929","rc":[{"atb":[[2.04,0],[2.24,5.75]],"id":47148562},{"atb":[[1.57,0],[1.47,0]],"id":49546922}],"con":true,"img":false}]}
{"op":"mcm","clk":"11450705855","pt":1717324712841,"mc":[{"id":"1.229554929","rc":[{"atb":[[2.42,0]],"id":47148562}],"con":true,"img":false}]}
{"op":"mcm","clk":"11450706227","pt":1717324716958,"mc":[{"id":"1.229554929","rc":[{"atb":[[2.14,0],[2.2,37]],"id":47148562}],"con":true,"img":false}]}
{"op":"mcm","clk":"11450707053","pt":1717324725487,"mc":[{"id":"1.229554929","rc":[{"atb":[[2.04,7.54],[2.24,12.08]],"id":47148562},{"atb":[[1.57,13.77],[1.47,16.69]],"id":49546922}],"con":true,"img":false}]}
{"op":"mcm","clk":"11450707102","pt":1717324725860,"mc":[{"id":"1.229554929","rc":[{"atb":[[2.42,21]],"id":47148562}],"con":true,"img":false}]}
{"op":"mcm","clk":"11450707212","pt":1717324726747,"mc":[{"id":"1.229554929","rc":[{"atb":[[2.3,2],[2.24,10.08]],"id":47148562},{"atl":[[1.79,33],[1.77,50]],"id":49546922}],"con":true,"img":false}]}
{"op":"mcm","clk":"11450708174","pt":1717324736470,"mc":[{"id":"1.229554929","rc":[{"atl":[[1.76,50],[1.77,0]],"id":49546922}],"con":true,"img":false}]}
{"op":"mcm","clk":"11450709296","pt":1717324746980,"mc":[{"id":"1.229554929","rc":[{"atb":[[2.04,0],[2.24,3.75]],"id":47148562},{"atb":[[1.57,0],[1.47,0]],"id":49546922}],"con":true,"img":false}]}
{"op":"mcm","clk":"11450709326","pt":1717324747293,"mc":[{"id":"1.229554929","rc":[{"atb":[[2.42,0]],"id":47148562},{"atl":[[1.76,0],[1.75,55]],"id":49546922}],"con":true,"img":false}]}
{"op":"mcm","clk":"11450710039","pt":1717324754036,"mc":[{"id":"1.229554929","rc":[{"atb":[[2.48,5.3],[2.28,6.13]],"id":47148562},{"atb":[[1.37,21.2],[1.47,16.69]],"id":49546922}],"con":true,"img":false}]}
{"op":"mcm","clk":"11450710073","pt":1717324754299,"mc":[{"id":"1.229554929","rc":[{"atb":[[2.42,21]],"id":47148562}],"con":true,"img":false}]}
{"op":"mcm","clk":"11450711185","pt":1717324764681,"mc":[{"id":"1.229554929","rc":[{"atb":[[2.48,0],[2.28,0]],"id":47148562},{"atb":[[1.37,0],[1.47,0]],"id":49546922}],"con":true,"img":false}]}
{"op":"mcm","clk":"11450711253","pt":1717324765413,"mc":[{"id":"1.229554929","rc":[{"atb":[[2.42,0]],"id":47148562}],"con":true,"img":false}]}
{"op":"mcm","clk":"11450711325","pt":1717324766089,"mc":[{"id":"1.229554929","rc":[{"atl":[[3.55,0]],"id":47148562},{"atb":[[1.38,0]],"id":49546922}],"con":true,"img":false}]}
{"op":"mcm","clk":"11450711337","pt":1717324766194,"mc":[{"id":"1.229554929","rc":[{"atl":[[3.65,2]],"id":47148562},{"atb":[[1.36,2]],"id":49546922}],"con":true,"img":false}]}
{"op":"mcm","clk":"11450711856","pt":1717324771092,"mc":[{"id":"1.229554929","rc":[{"atb":[[2.48,5.3],[2.28,6.13]],"id":47148562},{"atb":[[1.37,21.2],[1.47,16.69]],"id":49546922}],"con":true,"img":false}]}
{"op":"mcm","clk":"11450711877","pt":1717324771300,"mc":[{"id":"1.229554929","rc":[{"atb":[[2.42,21]],"id":47148562}],"con":true,"img":false}]}
{"op":"mcm","clk":"11450711923","pt":1717324771777,"mc":[{"id":"1.229554929","rc":[{"atb":[[2.5,8]],"id":47148562},{"trd":[[2.5,2]],"ltp":2.5,"tv":2.0,"id":47148562},{"trd":[[1.67,3]],"ltp":1.67,"tv":3.0,"id":49546922}],"con":true,"img":false}]}
{"op":"mcm","clk":"11450712037","pt":1717324772870,"mc":[{"id":"1.229554929","rc":[{"atb":[[1.02,3.25],[1.05,2.7]],"id":47148562},{"atb":[[1.02,4.21],[1.05,2.7]],"id":49546922}],"con":true,"img":false}]}
{"op":"mcm","clk":"11450712171","pt":1717324773805,"mc":[{"id":"1.229554929","rc":[{"atb":[[1.05,0.08]],"id":49546922}],"con":true,"img":false}]}
{"op":"mcm","clk":"11450712182","pt":1717324773903,"mc":[{"id":"1.229554929","rc":[{"atb":[[1.02,0.64],[1.05,0.08]],"id":47148562},{"atb":[[1.02,1.6]],"id":49546922}],"con":true,"img":false}]}
{"op":"mcm","clk":"11450712286","pt":1717324774792,"mc":[{"id":"1.229554929","rc":[{"atb":[[1.05,0]],"id":49546922}],"con":true,"img":false}]}
{"op":"mcm","clk":"11450712300","pt":1717324774893,"mc":[{"id":"1.229554929","rc":[{"atb":[[1.02,0],[1.05,0]],"id":47148562},{"atb":[[1.57,0.08],[1.02,0]],"id":49546922}],"con":true,"img":false}]}
{"op":"mcm","clk":"11450712312","pt":1717324774996,"mc":[{"id":"1.229554929","rc":[{"atb":[[2.42,21.73]],"id":47148562},{"atb":[[1.57,1.68]],"id":49546922}],"con":true,"img":false}]}
{"op":"mcm","clk":"11450712954","pt":1717324781376,"mc":[{"id":"1.229554929","rc":[{"atb":[[2.48,0],[2.28,0]],"id":47148562},{"atb":[[1.37,0],[1.47,0]],"id":49546922}],"con":true,"img":false}]}
{"op":"mcm","clk":"11450713005","pt":1717324781812,"mc":[{"id":"1.229554929","rc":[{"atb":[[2.42,0.73]],"id":47148562}],"con":true,"img":false}]}
{"op":"mcm","clk":"11450713625","pt":1717324787519,"mc":[{"id":"1.229554929","rc":[{"atb":[[1.63,2]],"id":49546922}],"con":true,"img":false}]}
{"op":"mcm","clk":"11450713761","pt":1717324788804,"mc":[{"id":"1.229554929","rc":[{"atb":[[2.42,0.64]],"id":47148562}],"con":true,"img":false}]}
{"op":"mcm","clk":"11450713772","pt":1717324788907,"mc":[{"id":"1.229554929","rc":[{"atb":[[2.4,22.08]],"id":47148562}],"con":true,"img":false}]}
{"op":"mcm","clk":"11450713833","pt":1717324789525,"mc":[{"id":"1.229554929","rc":[{"atb":[[2.48,5.3],[2.28,6.13]],"id":47148562},{"atb":[[1.37,21.2],[1.47,16.69]],"id":49546922}],"con":true,"img":false}]}
{"op":"mcm","clk":"11450713862","pt":1717324789804,"mc":[{"id":"1.229554929","rc":[{"atb":[[2.42,21.64]],"id":47148562}],"con":true,"img":false}]}
{"op":"mcm","clk":"11450713905","pt":1717324790218,"mc":[{"id":"1.229554929","rc":[{"atb":[[2.42,21]],"id":47148562}],"con":true,"img":false}]}
{"op":"mcm","clk":"11450713909","pt":1717324790319,"mc":[{"id":"1.229554929","rc":[{"atb":[[2.4,22.73]],"id":47148562}],"con":true,"img":false}]}
{"op":"mcm","clk":"11450713984","pt":1717324791011,"mc":[{"id":"1.229554929","rc":[{"atb":[[2.3,0],[2.34,2]],"id":47148562},{"atl":[[3.6,7.76],[4.3,0],[3.65,0],[3.05,2]],"id":47148562},{"atb":[[1.36,0],[1.46,2],[1.23,0],[1.32,7.9]],"id":49546922},{"atl":[[1.86,48],[1.75,22]],"id":49546922}],"con":true,"img":false}]}
{"op":"mcm","clk":"11450714034","pt":1717324791524,"mc":[{"id":"1.229554929","rc":[{"atb":[[2.5,0.72]],"id":47148562},{"trd":[[2.5,16.56]],"ltp":2.5,"tv":16.56,"id":47148562},{"atb":[[1.63,7.42]],"id":49546922}],"con":true,"img":false}]}
{"op":"mcm","clk":"11450714053","pt":1717324791689,"mc":[{"id":"1.229554929","rc":[{"atb":[[2.5,0]],"id":47148562},{"trd":[[2.5,18]],"ltp":2.5,"tv":18.0,"id":47148562}],"con":true,"img":false}]}
{"op":"mcm","clk":"11450714067","pt":1717324791795,"mc":[{"id":"1.229554929","rc":[{"atb":[[2.42,0]],"id":47148562}],"con":true,"img":false}]}
{"op":"mcm","clk":"11450714126","pt":1717324792313,"mc":[{"id":"1.229554929","rc":[{"atb":[[2.48,0],[2.4,44.03]],"id":47148562},{"trd":[[2.48,10.61]],"ltp":2.48,"tv":10.61,"id":47148562}],"con":true,"img":false}]}
{"op":"mcm","clk":"11450714180","pt":1717324792929,"mc":[{"id":"1.229554929","rc":[{"atb":[[2.4,22.73]],"id":47148562},{"atb":[[1.57,1.6]],"id":49546922}],"con":true,"img":false}]}
{"op":"mcm","clk":"11450714190","pt":1717324792983,"mc":[{"id":"1.229554929","rc":[{"atb":[[1.58,0.08]],"id":49546922}],"con":true,"img":false}]}
{"op":"mcm","clk":"11450714218","pt":1717324793298,"mc":[{"id":"1.229554929","rc":[{"atb":[[2.38,21.61]],"id":47148562}],"con":true,"img":false}]}
{"op":"mcm","clk":"11450714310","pt":1717324794219,"mc":[{"id":"1.229554929","rc":[{"atb":[[1.58,0]],"id":49546922}],"con":true,"img":false}]}
{"op":"mcm","clk":"11450714323","pt":1717324794337,"mc":[{"id":"1.229554929","rc":[{"atb":[[1.59,0.08]],"id":49546922}],"con":true,"img":false}]}
{"op":"mcm","clk":"11450714438","pt":1717324795416,"mc":[{"id":"1.229554929","rc":[{"atb":[[1.57,0]],"id":49546922}],"con":true,"img":false}]}
{"op":"mcm","clk":"11450714449","pt":1717324795521,"mc":[{"id":"1.229554929","rc":[{"atb":[[1.59,1.68]],"id":49546922}],"con":true,"img":false}]}
{"op":"mcm","clk":"11450714503","pt":1717324796155,"mc":[{"id":"1.229554929","rc":[{"atb":[[2.34,0],[2.36,2]],"id":47148562}],"con":true,"img":false}]}
{"op":"mcm","clk":"11450714716","pt":1717324798439,"mc":[{"id":"1.229554929","rc":[{"atb":[[2.28,0]],"id":47148562},{"atb":[[1.37,0],[1.47,0]],"id":49546922}],"con":true,"img":false}]}
{"op":"mcm","clk":"11450714761","pt":1717324798915,"mc":[{"id":"1.229554929","rc":[{"atb":[[2.38,0]],"id":47148562}],"con":true,"img":false}]}
{"op":"mcm","clk":"11450714939","pt":1717324800532,"mc":[{"id":"1.229554929","rc":[{"atb":[[2.32,0],[2.22,0],[2.4,0.73],[2.46,0]],"id":47148562},{"atl":[[1.84,0],[1.7,0],[1.72,0],[1.79,0],[1.75,0]],"id":49546922}],"con":true,"img":false}]}
{"op":"mcm","clk":"11450714944","pt":1717324800634,"mc":[{"id":"1.229554929","rc":[{"atb":[[2.2,0],[2.26,2]],"id":47148562},{"atl":[[1.86,0],[2.08,29.38]],"id":49546922}],"con":true,"img":false}]}
{"op":"mcm","clk":"11450714953","pt":1717324800738,"mc":[{"id":"1.229554929","rc":[{"atb":[[2.36,0],[2.16,11.41]],"id":47148562},{"atl":[[1.98,3.36],[1.74,0],[2.1,13.64]],"id":49546922}],"con":true,"img":false}]}
{"op":"mcm","clk":"11450715071","pt":1717324801944,"mc":[{"id":"1.229554929","rc":[{"atb":[[1.59,1.6]],"id":49546922}],"con":true,"img":false}]}
{"op":"mcm","clk":"11450715084","pt":1717324801998,"mc":[{"id":"1.229554929","rc":[{"atb":[[1.7,0.08]],"id":49546922}],"con":true,"img":false}]}
{"op":"mcm","clk":"11450715128","pt":1717324802470,"mc":[{"id":"1.229554929","rc":[{"atb":[[1.86,4.56],[1.76,5.15]],"id":47148562},{"atb":[[1.37,28.37],[1.47,22.33]],"id":49546922}],"con":true,"img":false}]}
{"op":"mcm","clk":"11450715134","pt":1717324802526,"mc":[{"id":"1.229554929","rc":[{"atb":[[2.28,7.41]],"id":47148562},{"atl":[[2.58,5.39]],"id":47148562}],"con":true,"img":false}]}
{"op":"mcm","clk":"11450715156","pt":1717324802731,"mc":[{"id":"1.229554929","rc":[{"atl":[[2.14,17.54]],"id":49546922}],"con":true,"img":false}]}
{"op":"mcm","clk":"11450715191","pt":1717324803145,"mc":[{"id":"1.229554929","rc":[{"atb":[[2.28,0]],"id":47148562}],"con":true,"img":false}]}
{"op":"mcm","clk":"11450715203","pt":1717324803246,"mc":[{"id":"1.229554929","rc":[{"atb":[[1.59,0]],"id":49546922}],"con":true,"img":false}]}
{"op":"mcm","clk":"11450715209","pt":1717324803353,"mc":[{"id":"1.229554929","rc":[{"atb":[[1.7,1.68]],"id":49546922}],"con":true,"img":false}]}
{"op":"mcm","clk":"11450715273","pt":1717324803926,"mc":[{"id":"1.229554929","rc":[{"atl":[[2.1,0],[2.14,0]],"id":49546922}],"con":true,"img":false}]}
{"op":"mcm","clk":"11450715385","pt":1717324805123,"mc":[{"id":"1.229554929","rc":[{"atb":[[2.28,7.42]],"id":47148562},{"atb":[[1.7,0]],"id":49546922},{"trd":[[1.7,3.37]],"ltp":1.7,"tv":3.37,"id":49546922}],"con":true,"img":false}]}
{"op":"mcm","clk":"11450715393","pt":1717324805229,"mc":[{"id":"1.229554929","rc":[{"atl":[[1.97,5.21],[2.12,0]],"id":49546922}],"con":true,"img":false}]}
{"op":"mcm","clk":"11450715402","pt":1717324805332,"mc":[{"id":"1.229554929","rc":[{"atb":[[2.18,29.14]],"id":47148562}],"con":true,"img":false}]}
{"op":"mcm","clk":"11450715430","pt":1717324805742,"mc":[{"id":"1.229554929","rc":[{"atb":[[2.3,2.3],[2.26,0]],"id":47148562},{"atl":[[2.04,23.44],[2.08,0]],"id":49546922}],"con":true,"img":false}]}
{"op":"mcm","clk":"11450715438","pt":1717324805846,"mc":[{"id":"1.229554929","rc":[{"atb":[[2.22,11.41]],"id":47148562},{"atl":[[1.96,5.12]],"id":49546922}],"con":true,"img":false}]}
{"op":"mcm","clk":"11450715446","pt":1717324805903,"mc":[{"id":"1.229554929","rc":[{"atb":[[2.28,0],[2.16,3.89]],"id":47148562},{"atl":[[1.98,0]],"id":49546922}],"con":true,"img":false}]}
{"op":"mcm","clk":"11450715454","pt":1717324806054,"mc":[{"id":"1.229554929","rc":[{"atl":[[1.95,5.21]],"id":49546922}],"con":true,"img":false}]}
{"op":"mcm","clk":"11450715466","pt":1717324806158,"mc":[{"id":"1.229554929","rc":[{"atb":[[2.22,0]],"id":47148562},{"atl":[[2.82,2.24],[3.6,0],[3.3,7.76],[3.05,0]],"id":47148562},{"atb":[[1.46,0],[1.52,5.12]],"id":49546922},{"atl":[[2.06,0]],"id":49546922}],"con":true,"img":false}]}
{"op":"mcm","clk":"11450715485","pt":1717324806316,"mc":[{"id":"1.229554929","rc":[{"atb":[[2.16,11.41]],"id":47148562}],"con":true,"img":false}]}
{"op":"mcm","clk":"11450715492","pt":1717324806421,"mc":[{"id":"1.229554929","rc":[{"atb":[[2.18,3.87]],"id":47148562}],"con":true,"img":false}]}
{"op":"mcm","clk":"11450715504","pt":1717324806524,"mc":[{"id":"1.229554929","rc":[{"atl":[[2,23.44],[2.04,0],[1.96,0],[1.94,5.9]],"id":49546922}],"con":true,"img":false}]}
{"op":"mcm","clk":"11450715510","pt":1717324806629,"mc":[{"id":"1.229554929","rc":[{"atl":[[2,0],[1.98,10.44]],"id":49546922}],"con":true,"img":false}]}
{"op":"mcm","clk":"11450715558","pt":1717324807148,"mc":[{"id":"1.229554929","rc":[{"atl":[[1.94,5.77]],"id":49546922}],"con":true,"img":false}]}
{"op":"mcm","clk":"11450715603","pt":1717324807627,"mc":[{"id":"1.229554929","rc":[{"atb":[[2.26,7.29]],"id":47148562},{"atl":[[2.6,3.1]],"id":47148562},{"atl":[[1.76,8.04]],"id":49546922}],"con":true,"img":false}]}
{"op":"mcm","clk":"11450715626","pt":1717324807825,"mc":[{"id":"1.229554929","rc":[{"atb":[[2.3,0],[2.28,3.49]],"id":47148562},{"atl":[[2.02,0],[1.94,0],[1.75,5.12],[1.93,5.24]],"id":49546922}],"con":true,"img":false}]}
{"op":"mcm","clk":"11450715636","pt":1717324807932,"mc":[{"id":"1.229554929","rc":[{"atl":[[1000,0.65]],"id":49546922}],"con":true,"img":false}]}
{"op":"mcm","clk":"11450715647","pt":1717324808034,"mc":[{"id":"1.229554929","rc":[{"atb":[[1.98,0],[2.26,11.01]],"id":47148562}],"con":true,"img":false}]}
{"op":"mcm","clk":"11450715682","pt":1717324808340,"mc":[{"id":"1.229554929","rc":[{"atb":[[2.24,0],[2.28,26.78],[2.26,7.29]],"id":47148562}],"con":true,"img":false}]}
{"op":"mcm","clk":"11450715701","pt":1717324808552,"mc":[{"id":"1.229554929","rc":[{"atb":[[1.63,7.32]],"id":49546922},{"trd":[[1.63,0.2]],"ltp":1.63,"tv":0.2,"id":49546922}],"con":true,"img":false}]}
{"op":"mcm","clk":"11450715723","pt":1717324808814,"mc":[{"id":"1.229554929","rc":[{"atb":[[2.28,3.49]],"id":47148562}],"con":true,"img":false}]}
{"op":"mcm","clk":"11450715770","pt":1717324809328,"mc":[{"id":"1.229554929","rc":[{"atb":[[2.2,24.85]],"id":47148562}],"con":true,"img":false}]}
{"op":"mcm","clk":"11450715788","pt":1717324809634,"mc":[{"id":"1.229554929","rc":[{"atb":[[2.32,3.7]],"id":47148562},{"atl":[[2.62,3.86]],"id":47148562}],"con":true,"img":false}]}
{"op":"mcm","clk":"11450715801","pt":1717324809738,"mc":[{"id":"1.229554929","rc":[{"atb":[[2.34,3.4]],"id":47148562}],"con":true,"img":false}]}
{"op":"mcm","clk":"11450715806","pt":1717324809841,"mc":[{"id":"1.229554929","rc":[{"atb":[[2.32,0],[2.28,0]],"id":47148562}],"con":true,"img":false}]}
{"op":"mcm","clk":"11450715815","pt":1717324809943,"mc":[{"id":"1.229554929","rc":[{"atb":[[2.34,0],[2.28,2]],"id":47148562}],"con":true,"img":false}]}
{"op":"mcm","clk":"11450715859","pt":1717324810314,"mc":[{"id":"1.229554929","rc":[{"atb":[[1.86,0],[1.76,0]],"id":47148562},{"atb":[[1.37,0],[1.47,0]],"id":49546922}],"con":true,"img":false}]}
{"op":"mcm","clk":"11450715966","pt":1717324811351,"mc":[{"id":"1.229554929","rc":[{"atl":[[2.82,0]],"id":47148562},{"atb":[[1.52,0]],"id":49546922}],"con":true,"img":false}]}
{"op":"mcm","clk":"11450715973","pt":1717324811453,"mc":[{"id":"1.229554929","rc":[{"atl":[[2.9,3.49]],"id":47148562},{"atb":[[1.49,5.14]],"id":49546922}],"con":true,"img":false}]}
{"op":"mcm","clk":"11450716023","pt":1717324812034,"mc":[{"id":"1.229554929","rc":[{"atl":[[2.9,0],[3.1,3.49],[3.3,0],[3.65,7.75]],"id":47148562},{"atb":[[1.49,0]],"id":49546922}],"con":true,"img":false}]}
{"op":"mcm","clk":"11450716031","pt":1717324812140,"mc":[{"id":"1.229554929","rc":[{"atb":[[2.26,11]],"id":47148562},{"atb":[[1.46,5.14]],"id":49546922}],"con":true,"img":false}]}
{"op":"mcm","clk":"11450716052","pt":1717324812349,"mc":[{"id":"1.229554929","rc":[{"atb":[[2.2,0]],"id":47148562}],"con":true,"img":false}]}
{"op":"mcm","clk":"11450716090","pt":1717324812764,"mc":[{"id":"1.229554929","rc":[{"atb":[[2.34,10.21]],"id":47148562},{"atb":[[1.64,14.8]],"id":49546922}],"con":true,"img":false}]}
{"op":"mcm","clk":"11450716101","pt":1717324812825,"mc":[{"id":"1.229554929","rc":[{"atb":[[2.28,23.29],[2.16,3.89]],"id":47148562}],"con":true,"img":false}]}
{"op":"mcm","clk":"11450716111","pt":1717324812927,"mc":[{"id":"1.229554929","rc":[{"atb":[[2.22,12.22],[2.34,3.49]],"id":47148562}],"con":true,"img":false}]}
{"op":"mcm","clk":"11450716133","pt":1717324813143,"mc":[{"id":"1.229554929","rc":[{"atb":[[2.3,3.49],[2.34,0]],"id":47148562}],"con":true,"img":false}]}
{"op":"mcm","clk":"11450716160","pt":1717324813351,"mc":[{"id":"1.229554929","rc":[{"atb":[[2.3,4.37]],"id":47148562}],"con":true,"img":false}]}
{"op":"mcm","clk":"11450716209","pt":1717324813859,"mc":[{"id":"1.229554929","rc":[{"atb":[[1.57,52.32]],"id":49546922}],"con":true,"img":false}]}
{"op":"mcm","clk":"11450716242","pt":1717324814128,"mc":[{"id":"1.229554929","rc":[{"atb":[[1.78,5.02],[1.88,4.45]],"id":47148562},{"atb":[[1.46,27.96],[1.36,29.16]],"id":49546922}],"con":true,"img":false}]}
{"op":"mcm","clk":"11450716389","pt":1717324815635,"mc":[{"id":"1.229554929","rc":[{"atb":[[2.34,10.21]],"id":47148562}],"con":true,"img":false}]}
{"op":"mcm","clk":"11450716458","pt":1717324816358,"mc":[{"id":"1.229554929","rc":[{"atb":[[2.3,3.49],[2.32,22.59]],"id":47148562}],"con":true,"img":false}]}
{"op":"mcm","clk":"11450716469","pt":1717324816460,"mc":[{"id":"1.229554929","rc":[{"atb":[[2.34,11.1]],"id":47148562}],"con":true,"img":false}]}
{"op":"mcm","clk":"11450716511","pt":1717324816833,"mc":[{"id":"1.229554929","rc":[{"atb":[[1.64,0]],"id":49546922}],"con":true,"img":false}]}
{"op":"mcm","clk":"11450716576","pt":1717324817346,"mc":[{"id":"1.229554929","rc":[{"atb":[[1.57,0]],"id":49546922}],"con":true,"img":false}]}
{"op":"mcm","clk":"11450716615","pt":1717324817759,"mc":[{"id":"1.229554929","rc":[{"atl":[[2.58,0]],"id":47148562}],"con":true,"img":false}]}
{"op":"mcm","clk":"11450716635","pt":1717324817967,"mc":[{"id":"1.229554929","rc":[{"atl":[[2.6,0]],"id":47148562}],"con":true,"img":false}]}
{"op":"mcm","clk":"11450716653","pt":1717324818072,"mc":[{"id":"1.229554929","rc":[{"atb":[[1.46,22.82]],"id":49546922}],"con":true,"img":false}]}
{"op":"mcm","clk":"11450716658","pt":1717324818127,"mc":[{"id":"1.229554929","rc":[{"atb":[[1.44,6.28]],"id":49546922}],"con":true,"img":false}]}
{"op":"mcm","clk":"11450716671","pt":1717324818231,"mc":[{"id":"1.229554929","rc":[{"atb":[[2.3,0],[2.34,14.98]],"id":47148562}],"con":true,"img":false}]}
{"op":"mcm","clk":"11450716715","pt":1717324818753,"mc":[{"id":"1.229554929","rc":[{"atl":[[2.62,0]],"id":47148562}],"con":true,"img":false}]}
{"op":"mcm","clk":"11450716785","pt":1717324819334,"mc":[{"id":"1.229554929","rc":[{"atb":[[2.32,0],[2.26,34.67],[2.28,0]],"id":47148562}],"con":true,"img":false}]}
{"op":"mcm","clk":"11450716851","pt":1717324820060,"mc":[{"id":"1.229554929","rc":[{"atb":[[2.28,3.68]],"id":47148562}],"con":true,"img":false}]}
{"op":"mcm","clk":"11450716923","pt":1717324820846,"mc":[{"id":"1.229554929","rc":[{"atb":[[2.32,8.21]],"id":47148562}],"con":true,"img":false}]}
{"op":"mcm","clk":"11450716971","pt":1717324821355,"mc":[{"id":"1.229554929","rc":[{"atl":[[3.1,0],[2.98,2.3]],"id":47148562}],"con":true,"img":false}]}
{"op":"mcm","clk":"11450717074","pt":1717324822357,"mc":[{"id":"1.229554929","rc":[{"atb":[[1.78,0],[1.88,0]],"id":47148562},{"atb":[[1.46,0],[1.36,0]],"id":49546922}],"con":true,"img":false}]}
{"op":"mcm","clk":"11450717124","pt":1717324822873,"mc":[{"id":"1.229554929","rc":[{"atb":[[2.26,11]],"id":47148562}],"con":true,"img":false}]}
{"op":"mcm","clk":"11450717159","pt":1717324823239,"mc":[{"id":"1.229554929","rc":[{"atb":[[1.44,0],[1.48,5.14]],"id":49546922}],"con":true,"img":false}]}
{"op":"mcm","clk":"11450717320","pt":1717324824963,"mc":[{"id":"1.229554929","rc":[{"atb":[[1.64,13.59]],"id":49546922}],"con":true,"img":false}]}
{"op":"mcm","clk":"11450717369","pt":1717324825377,"mc":[{"id":"1.229554929","rc":[{"atb":[[2.26,34.67]],"id":47148562}],"con":true,"img":false}]}
{"op":"mcm","clk":"11450717451","pt":1717324826263,"mc":[{"id":"1.229554929","rc":[{"atb":[[1.76,5.15],[1.86,4.56]],"id":47148562},{"atb":[[1.37,28.37],[1.47,22.33]],"id":49546922}],"con":true,"img":false}]}
{"op":"mcm","clk":"11450717486","pt":1717324826673,"mc":[{"id":"1.229554929","rc":[{"atl":[[2.98,0]],"id":47148562},{"atb":[[1.48,0]],"id":49546922}],"con":true,"img":false}]}
{"op":"mcm","clk":"11450717495","pt":1717324826774,"mc":[{"id":"1.229554929","rc":[{"atl":[[3.05,2.3]],"id":47148562},{"atb":[[1.46,6.28]],"id":49546922}],"con":true,"img":false}]}
{"op":"mcm","clk":"11450717501","pt":1717324826877,"mc":[{"id":"1.229554929","rc":[{"atb":[[2.34,37.24]],"id":47148562}],"con":true,"img":false}]}
{"op":"mcm","clk":"11450717879","pt":1717324830471,"mc":[{"id":"1.229554929","rc":[{"atl":[[1000,1.55]],"id":49546922}],"con":true,"img":false}]}
{"op":"mcm","clk":"11450717923","pt":1717324830876,"mc":[{"id":"1.229554929","rc":[{"atl":[[1000,0.8]],"id":49546922}],"con":true,"img":false}]}
{"op":"mcm","clk":"11450717966","pt":1717324831289,"mc":[{"id":"1.229554929","rc":[{"atl":[[1000,0.65]],"id":49546922}],"con":true,"img":false}]}
{"op":"mcm","clk":"11450717976","pt":1717324831353,"mc":[{"id":"1.229554929","rc":[{"atb":[[1.64,13.43]],"id":49546922},{"trd":[[1.64,0.3]],"ltp":1.64,"tv":0.3,"id":49546922}],"con":true,"img":false}]}
{"op":"mcm","clk":"11450718013","pt":1717324831763,"mc":[{"id":"1.229554929","rc":[{"atb":[[1.64,0]],"id":49546922}],"con":true,"img":false}]}
{"op":"mcm","clk":"11450718100","pt":1717324832487,"mc":[{"id":"1.229554929","rc":[{"atb":[[2.34,14.98]],"id":47148562}],"con":true,"img":false}]}
{"op":"mcm","clk":"11450718347","pt":1717324835091,"mc":[{"id":"1.229554929","rc":[{"atb":[[2.22,0],[2.28,20.1]],"id":47148562}],"con":true,"img":false}]}
{"op":"mcm","clk":"11450718358","pt":1717324835195,"mc":[{"id":"1.229554929","rc":[{"atb":[[2.28,3.68],[2.18,24.3]],"id":47148562}],"con":true,"img":false}]}
{"op":"mcm","clk":"11450718368","pt":1717324835254,"mc":[{"id":"1.229554929","rc":[{"atb":[[2.28,23.79],[2.18,3.87]],"id":47148562}],"con":true,"img":false}]}
{"op":"mcm","clk":"11450718379","pt":1717324835406,"mc":[{"id":"1.229554929","rc":[{"atb":[[1.76,0],[1.86,0]],"id":47148562},{"atb":[[1.37,0],[1.47,0]],"id":49546922}],"con":true,"img":false}]}
{"op":"mcm","clk":"11450718436","pt":1717324835900,"mc":[{"id":"1.229554929","rc":[{"atb":[[2.28,3.68],[2.18,33.83],[2.26,11]],"id":47148562}],"con":true,"img":false}]}
{"op":"mcm","clk":"11450718947","pt":1717324841000,"mc":[{"id":"1.229554929","rc":[{"atb":[[2.28,20.1],[2.18,3.87]],"id":47148562}],"con":true,"img":false}]}
{"op":"mcm","clk":"11450719066","pt":1717324842190,"mc":[{"id":"1.229554929","rc":[{"atb":[[2.28,16.42]],"id":47148562}],"con":true,"img":false}]}
{"op":"mcm","clk":"11450719089","pt":1717324842502,"mc":[{"id":"1.229554929","rc":[{"atb":[[1.78,5.02],[2.26,7.29],[1.88,4.45]],"id":47148562},{"atb":[[1.46,29.1],[1.36,29.16]],"id":49546922}],"con":true,"img":false}]}
{"op":"mcm","clk":"11450719096","pt":1717324842618,"mc":[{"id":"1.229554929","rc":[{"atb":[[2.34,18.57]],"id":47148562},{"atl":[[1.99,0],[1.75,10.61]],"id":49546922}],"con":true,"img":false}]}
{"op":"mcm","clk":"11450719119","pt":1717324842874,"mc":[{"id":"1.229554929","rc":[{"atb":[[2.26,30.96]],"id":47148562}],"con":true,"img":false}]}
{"op":"mcm","clk":"11450719152","pt":1717324843188,"mc":[{"id":"1.229554929","rc":[{"atb":[[2.34,14.98]],"id":47148562},{"atl":[[1.75,5.12]],"id":49546922}],"con":true,"img":false}]}
{"op":"mcm","clk":"11450719198","pt":1717324843707,"mc":[{"id":"1.229554929","rc":[{"atb":[[2.28,0],[2.18,33.83]],"id":47148562}],"con":true,"img":false}]}
{"op":"mcm","clk":"11450719217","pt":1717324843872,"mc":[{"id":"1.229554929","rc":[{"atb":[[2.28,3.65]],"id":47148562}],"con":true,"img":false}]}
{"op":"mcm","clk":"11450719422","pt":1717324846106,"mc":[{"id":"1.229554929","rc":[{"atb":[[2.28,34.62],[2.18,3.87]],"id":47148562}],"con":true,"img":false}]}
{"op":"mcm","clk":"11450719489","pt":1717324846789,"mc":[{"id":"1.229554929","rc":[{"atb":[[2.28,3.65],[2.2,29.96]],"id":47148562}],"con":true,"img":false}]}
{"op":"mcm","clk":"11450719529","pt":1717324847095,"mc":[{"id":"1.229554929","rc":[{"atb":[[2.28,33.61],[2.2,0]],"id":47148562},{"atb":[[1.63,5.42]],"id":49546922}],"con":true,"img":false}]}
{"op":"mcm","clk":"11450719541","pt":1717324847200,"mc":[{"id":"1.229554929","rc":[{"atb":[[1.67,1.9]],"id":49546922}],"con":true,"img":false}]}
{"op":"mcm","clk":"11450719632","pt":1717324848193,"mc":[{"id":"1.229554929","rc":[{"atb":[[2.3,3.65]],"id":47148562}],"con":true,"img":false}]}
{"op":"mcm","clk":"11450719643","pt":1717324848304,"mc":[{"id":"1.229554929","rc":[{"atl":[[3.05,0]],"id":47148562},{"atb":[[1.46,22.82]],"id":49546922}],"con":true,"img":false}]}
{"op":"mcm","clk":"11450719661","pt":1717324848507,"mc":[{"id":"1.229554929","rc":[{"atl":[[3.15,2.3]],"id":47148562},{"atb":[[1.44,5.14]],"id":49546922}],"con":true,"img":false}]}
{"op":"mcm","clk":"11450719734","pt":1717324849190,"mc":[{"id":"1.229554929","rc":[{"atb":[[2.28,3.65],[2.18,27.06]],"id":47148562}],"con":true,"img":false}]}
{"op":"mcm","clk":"11450720019","pt":1717324852215,"mc":[{"id":"1.229554929","rc":[{"atb":[[2.28,30.71],[2.18,3.87]],"id":47148562}],"con":true,"img":false}]}
{"op":"mcm","clk":"11450720111","pt":1717324853100,"mc":[{"id":"1.229554929","rc":[{"atb":[[2.32,0],[2.34,4.76]],"id":47148562}],"con":true,"img":false}]}
{"op":"mcm","clk":"11450720119","pt":1717324853201,"mc":[{"id":"1.229554929","rc":[{"atb":[[2.32,2],[2.34,0.88]],"id":47148562}],"con":true,"img":false}]}
{"op":"mcm","clk":"11450720197","pt":1717324853931,"mc":[{"id":"1.229554929","rc":[{"atb":[[1.78,0],[2.34,0],[1.88,0]],"id":47148562},{"atb":[[1.46,0],[1.36,0]],"id":49546922}],"con":true,"img":false}]}
{"op":"mcm","clk":"11450720204","pt":1717324853986,"mc":[{"id":"1.229554929","rc":[{"atb":[[2.3,4.53]],"id":47148562}],"con":true,"img":false}]}
{"op":"mcm","clk":"11450720215","pt":1717324854106,"mc":[{"id":"1.229554929","rc":[{"atb":[[2.28,3.65]],"id":47148562}],"con":true,"img":false}]}
{"op":"mcm","clk":"11450720223","pt":1717324854205,"mc":[{"id":"1.229554929","rc":[{"atb":[[2.26,37.5]],"id":47148562}],"con":true,"img":false}]}
{"op":"mcm","clk":"11450720239","pt":1717324854411,"mc":[{"id":"1.229554929","rc":[{"atb":[[2.26,13.83]],"id":47148562}],"con":true,"img":false}]}
{"op":"mcm","clk":"11450720252","pt":1717324854512,"mc":[{"id":"1.229554929","rc":[{"atb":[[2.3,3.65]],"id":47148562}],"con":true,"img":false}]}
{"op":"mcm","clk":"11450720259","pt":1717324854613,"mc":[{"id":"1.229554929","rc":[{"atb":[[2.32,2.88]],"id":47148562}],"con":true,"img":false}]}
{"op":"mcm","clk":"11450720487","pt":1717324856913,"mc":[{"id":"1.229554929","rc":[{"atb":[[2.32,5.66]],"id":47148562}],"con":true,"img":false}]}
{"op":"mcm","clk":"11450720521","pt":1717324857230,"mc":[{"id":"1.229554929","rc":[{"atb":[[2.3,0]],"id":47148562}],"con":true,"img":false}]}
{"op":"mcm","clk":"11450720666","pt":1717324858531,"mc":[{"id":"1.229554929","rc":[{"atb":[[1.63,4.7],[1.67,0]],"id":49546922},{"trd":[[1.63,1.63],[1.67,6.79]],"ltp":1.63,"tv":8.42,"id":49546922}],"con":true,"img":false}]}
{"op":"mcm","clk":"11450720687","pt":1717324858685,"mc":[{"id":"1.229554929","rc":[{"atb":[[2.32,4.77]],"id":47148562}],"con":true,"img":false}]}
{"op":"mcm","clk":"11450720713","pt":1717324858896,"mc":[{"id":"1.229554929","rc":[{"atb":[[2.3,2.77],[2.28,0]],"id":47148562}],"con":true,"img":false}]}
{"op":"mcm","clk":"11450720751","pt":1717324859308,"mc":[{"id":"1.229554929","rc":[{"atb":[[2.28,5.56],[2.26,7.29]],"id":47148562}],"con":true,"img":false}]}
{"op":"mcm","clk":"11450720869","pt":1717324860610,"mc":[{"id":"1.229554929","rc":[{"atl":[[1.98,0],[1.78,13.16]],"id":49546922}],"con":true,"img":false}]}
{"op":"mcm","clk":"11450721027","pt":1717324862124,"mc":[{"id":"1.229554929","rc":[{"atl":[[1.81,16.08],[1.78,0]],"id":49546922}],"con":true,"img":false}]}
{"op":"mcm","clk":"11450721044","pt":1717324862332,"mc":[{"id":"1.229554929","rc":[{"atl":[[1.8,5.28]],"id":49546922}],"con":true,"img":false}]}
{"op":"mcm","clk":"11450721064","pt":1717324862536,"mc":[{"id":"1.229554929","rc":[{"atl":[[2.6,1.34]],"id":47148562}],"con":true,"img":false}]}
{"op":"mcm","clk":"11450721081","pt":1717324862700,"mc":[{"id":"1.229554929","rc":[{"atb":[[2.28,9.25]],"id":47148562}],"con":true,"img":false}]}
{"op":"mcm","clk":"11450721134","pt":1717324863227,"mc":[{"id":"1.229554929","rc":[{"atb":[[1.76,5.15],[1.86,4.56]],"id":47148562},{"atb":[[1.37,28.37],[1.47,22.33]],"id":49546922}],"con":true,"img":false}]}
{"op":"mcm","clk":"11450721242","pt":1717324864426,"mc":[{"id":"1.229554929","rc":[{"atb":[[2.3,10.06],[2.28,3.69]],"id":47148562}],"con":true,"img":false}]}
{"op":"mcm","clk":"11450721263","pt":1717324864636,"mc":[{"id":"1.229554929","rc":[{"atb":[[2.32,10.04]],"id":47148562},{"atl":[[2.62,3.08]],"id":47148562}],"con":true,"img":false}]}
{"op":"mcm","clk":"11450721282","pt":1717324864841,"mc":[{"id":"1.229554929","rc":[{"atb":[[2.24,24.05]],"id":47148562}],"con":true,"img":false}]}
{"op":"mcm","clk":"11450721326","pt":1717324865316,"mc":[{"id":"1.229554929","rc":[{"atb":[[2.32,10.89]],"id":47148562}],"con":true,"img":false}]}
{"op":"mcm","clk":"11450721350","pt":1717324865634,"mc":[{"id":"1.229554929","rc":[{"atb":[[2.28,0]],"id":47148562}],"con":true,"img":false}]}
{"op":"mcm","clk":"11450721432","pt":1717324866410,"mc":[{"id":"1.229554929","rc":[{"atb":[[2.3,2.77],[2.28,20.14]],"id":47148562}],"con":true,"img":false}]}
{"op":"mcm","clk":"11450721454","pt":1717324866765,"mc":[{"id":"1.229554929","rc":[{"atl":[[1.8,0]],"id":49546922}],"con":true,"img":false}]}
{"op":"mcm","clk":"11450721472","pt":1717324866926,"mc":[{"id":"1.229554929","rc":[{"atb":[[2.32,2.85],[2.3,8.26]],"id":47148562}],"con":true,"img":false}]}
{"op":"mcm","clk":"11450721487","pt":1717324867147,"mc":[{"id":"1.229554929","rc":[{"atl":[[1.81,0],[1.84,16.08]],"id":49546922}],"con":true,"img":false}]}
{"op":"mcm","clk":"11450721540","pt":1717324867715,"mc":[{"id":"1.229554929","rc":[{"atb":[[2.28,0],[2.2,15.56]],"id":47148562}],"con":true,"img":false}]}
{"op":"mcm","clk":"11450721633","pt":1717324868647,"mc":[{"id":"1.229554929","rc":[{"atb":[[2.26,11.34]],"id":47148562},{"atl":[[2.6,3.16]],"id":47148562}],"con":true,"img":false}]}
{"op":"mcm","clk":"11450721789","pt":1717324870018,"mc":[{"id":"1.229554929","rc":[{"atb":[[2.3,0]],"id":47148562}],"con":true,"img":false}]}
{"op":"mcm","clk":"11450721811","pt":1717324870220,"mc":[{"id":"1.229554929","rc":[{"atb":[[2.32,0.85],[2.28,3.12]],"id":47148562}],"con":true,"img":false}]}
{"op":"mcm","clk":"11450721831","pt":1717324870431,"mc":[{"id":"1.229554929","rc":[{"atb":[[2.28,26.41]],"id":47148562}],"con":true,"img":false}]}
{"op":"mcm","clk":"11450721861","pt":1717324870743,"mc":[{"id":"1.229554929","rc":[{"atb":[[2.32,0],[2.34,11.34]],"id":47148562}],"con":true,"img":false}]}
{"op":"mcm","clk":"11450721872","pt":1717324870839,"mc":[{"id":"1.229554929","rc":[{"atb":[[2.3,0.85]],"id":47148562}],"con":true,"img":false}]}
{"op":"mcm","clk":"11450721881","pt":1717324870941,"mc":[{"id":"1.229554929","rc":[{"atb":[[2.34,0],[2.36,3.52],[2.28,23.29]],"id":47148562}],"con":true,"img":false}]}
{"op":"mcm","clk":"11450722029","pt":1717324872239,"mc":[{"id":"1.229554929","rc":[{"atl":[[1.81,13.16]],"id":49546922}],"con":true,"img":false}]}
{"op":"mcm","clk":"11450722035","pt":1717324872342,"mc":[{"id":"1.229554929","rc":[{"atl":[[1.84,0]],"id":49546922}],"con":true,"img":false}]}
{"op":"mcm","clk":"11450722094","pt":1717324872827,"mc":[{"id":"1.229554929","rc":[{"atb":[[2.24,39.61],[2.2,0]],"id":47148562}],"con":true,"img":false}]}
{"op":"mcm","clk":"11450722104","pt":1717324872919,"mc":[{"id":"1.229554929","rc":[{"atb":[[2.32,9.24]],"id":47148562},{"atb":[[1.64,16.42]],"id":49546922},{"atl":[[1.73,6.91]],"id":49546922}],"con":true,"img":false}]}
{"op":"mcm","clk":"11450722113","pt":1717324873024,"mc":[{"id":"1.229554929","rc":[{"atl":[[1.72,5.97]],"id":49546922}],"con":true,"img":false}]}
{"op":"mcm","clk":"11450722127","pt":1717324873132,"mc":[{"id":"1.229554929","rc":[{"atb":[[1.64,0]],"id":49546922},{"atl":[[1.75,0]],"id":49546922}],"con":true,"img":false}]}
{"op":"mcm","clk":"11450722133","pt":1717324873228,"mc":[{"id":"1.229554929","rc":[{"atb":[[2.3,0]],"id":47148562}],"con":true,"img":false}]}
{"op":"mcm","clk":"11450722152","pt":1717324873367,"mc":[{"id":"1.229554929","rc":[{"atb":[[2.3,22.93],[2.36,4.37]],"id":47148562},{"atb":[[1.45,66.28]],"id":49546922},{"atl":[[1.8,5.34]],"id":49546922}],"con":true,"img":false}]}
{"op":"mcm","clk":"11450722203","pt":1717324873906,"mc":[{"id":"1.229554929","rc":[{"atl":[[2.6,0]],"id":47148562}],"con":true,"img":false}]}
{"op":"mcm","clk":"11450722230","pt":1717324874119,"mc":[{"id":"1.229554929","rc":[{"atl":[[2.62,0]],"id":47148562}],"con":true,"img":false}]}
{"op":"mcm","clk":"11450722247","pt":1717324874328,"mc":[{"id":"1.229554929","rc":[{"atb":[[1.45,0]],"id":49546922}],"con":true,"img":false}]}
{"op":"mcm","clk":"11450722326","pt":1717324875007,"mc":[{"id":"1.229554929","rc":[{"atb":[[2.32,10.27]],"id":47148562}],"con":true,"img":false}]}
{"op":"mcm","clk":"11450722428","pt":1717324876043,"mc":[{"id":"1.229554929","rc":[{"atb":[[2.34,2],[2.36,0.85]],"id":47148562}],"con":true,"img":false}]}
{"op":"mcm","clk":"11450722504","pt":1717324876726,"mc":[{"id":"1.229554929","rc":[{"atb":[[2.36,0]],"id":47148562}],"con":true,"img":false}]}
{"op":"mcm","clk":"11450722515","pt":1717324876829,"mc":[{"id":"1.229554929","rc":[{"atb":[[2.32,11.12]],"id":47148562}],"con":true,"img":false}]}
{"op":"mcm","clk":"11450722532","pt":1717324877037,"mc":[{"id":"1.229554929","rc":[{"atl":[[2.62,4.4]],"id":47148562}],"con":true,"img":false}]}
{"op":"mcm","clk":"11450722542","pt":1717324877140,"mc":[{"id":"1.229554929","rc":[{"atl":[[1.8,0]],"id":49546922}],"con":true,"img":false}]}
{"op":"mcm","clk":"11450722549","pt":1717324877248,"mc":[{"id":"1.229554929","rc":[{"atb":[[1.44,0],[1.48,5.97]],"id":49546922},{"atl":[[1.81,0],[1.86,13.82]],"id":49546922}],"con":true,"img":false}]}
{"op":"mcm","clk":"11450722561","pt":1717324877350,"mc":[{"id":"1.229554929","rc":[{"atb":[[2.32,1.03]],"id":47148562}],"con":true,"img":false}]}
{"op":"mcm","clk":"11450722573","pt":1717324877406,"mc":[{"id":"1.229554929","rc":[{"atb":[[2.34,2.85]],"id":47148562}],"con":true,"img":false}]}
{"op":"mcm","clk":"11450722621","pt":1717324877921,"mc":[{"id":"1.229554929","rc":[{"atb":[[2.3,0]],"id":47148562}],"con":true,"img":false}]}
{"op":"mcm","clk":"11450722633","pt":1717324878026,"mc":[{"id":"1.229554929","rc":[{"atl":[[2.6,4.49]],"id":47148562}],"con":true,"img":false}]}
{"op":"mcm","clk":"11450722660","pt":1717324878338,"mc":[{"id":"1.229554929","rc":[{"atl":[[1.76,13.48]],"id":49546922}],"con":true,"img":false}]}
{"op":"mcm","clk":"11450722671","pt":1717324878449,"mc":[{"id":"1.229554929","rc":[{"atb":[[2.32,4.65]],"id":47148562}],"con":true,"img":false}]}
{"op":"mcm","clk":"11450722692","pt":1717324878652,"mc":[{"id":"1.229554929","rc":[{"atb":[[2.32,1.03]],"id":47148562},{"atl":[[1.76,8.04]],"id":49546922}],"con":true,"img":false}]}
{"op":"mcm","clk":"11450722822","pt":1717324880150,"mc":[{"id":"1.229554929","rc":[{"atl":[[2.6,7.47]],"id":47148562}],"con":true,"img":false}]}
{"op":"mcm","clk":"11450722921","pt":1717324881038,"mc":[{"id":"1.229554929","rc":[{"atb":[[2.32,0]],"id":47148562}],"con":true,"img":false}]}
{"op":"mcm","clk":"11450722929","pt":1717324881147,"mc":[{"id":"1.229554929","rc":[{"atb":[[2.26,0]],"id":47148562}],"con":true,"img":false}]}
{"op":"mcm","clk":"11450722934","pt":1717324881243,"mc":[{"id":"1.229554929","rc":[{"atb":[[2.3,4.14],[2.34,0.85]],"id":47148562}],"con":true,"img":false}]}
{"op":"mcm","clk":"11450722952","pt":1717324881460,"mc":[{"id":"1.229554929","rc":[{"atb":[[2.28,0]],"id":47148562}],"con":true,"img":false}]}
{"op":"mcm","clk":"11450722963","pt":1717324881563,"mc":[{"id":"1.229554929","rc":[{"atb":[[2.34,0]],"id":47148562}],"con":true,"img":false}]}
{"op":"mcm","clk":"11450722971","pt":1717324881657,"mc":[{"id":"1.229554929","rc":[{"atb":[[2.3,4.99]],"id":47148562}],"con":true,"img":false}]}
{"op":"mcm","clk":"11450723043","pt":1717324882351,"mc":[{"id":"1.229554929","rc":[{"atl":[[2.88,4.14],[3.35,8.29],[3.15,0],[3.65,0]],"id":47148562}],"con":true,"img":false}]}
{"op":"mcm","clk":"11450723129","pt":1717324883259,"mc":[{"id":"1.229554929","rc":[{"atl":[[1.85,5.07]],"id":49546922}],"con":true,"img":false}]}
{"op":"mcm","clk":"11450723139","pt":1717324883309,"mc":[{"id":"1.229554929","rc":[{"atb":[[2.24,24.05],[2.12,7.78]],"id":47148562},{"atb":[[1.55,10],[1.32,0],[1.48,0],[1.38,11]],"id":49546922},{"atl":[[1.73,16.91],[2,11.94],[1.72,0],[1.86,0]],"id":49546922}],"con":true,"img":false}]}
{"op":"mcm","clk":"11450723146","pt":1717324883414,"mc":[{"id":"1.229554929","rc":[{"atl":[[3.35,0],[3.05,8.55]],"id":47148562},{"atl":[[1.73,6.91],[1.75,4.86]],"id":49546922}],"con":true,"img":false}]}
{"op":"mcm","clk":"11450723185","pt":1717324883828,"mc":[{"id":"1.229554929","rc":[{"atb":[[2.24,0],[2.2,24.85]],"id":47148562},{"atb":[[1.54,55.22]],"id":49546922}],"con":true,"img":false}]}
{"op":"mcm","clk":"11450723197","pt":1717324883934,"mc":[{"id":"1.229554929","rc":[{"atb":[[2.3,0.85],[2.22,10]],"id":47148562},{"atl":[[2.58,8.29]],"id":47148562},{"atl":[[1.73,0]],"id":49546922}],"con":true,"img":false}]}
{"op":"mcm","clk":"11450723207","pt":1717324884038,"mc":[{"id":"1.229554929","rc":[{"atb":[[2.3,0],[1.76,0],[1.86,0]],"id":47148562},{"atb":[[1.37,0],[1.47,0]],"id":49546922}],"con":true,"img":false}]}
{"op":"mcm","clk":"11450723214","pt":1717324884141,"mc":[{"id":"1.229554929","rc":[{"atl":[[2.58,0]],"id":47148562}],"con":true,"img":false}]}
{"op":"mcm","clk":"11450723242","pt":1717324884558,"mc":[{"id":"1.229554929","rc":[{"atb":[[2.22,10.91]],"id":47148562}],"con":true,"img":false}]}
{"op":"mcm","clk":"11450723387","pt":1717324885860,"mc":[{"id":"1.229554929","rc":[{"atl":[[1.75,0],[1.76,12.9]],"id":49546922}],"con":true,"img":false}]}
{"op":"mcm","clk":"11450723438","pt":1717324886232,"mc":[{"id":"1.229554929","rc":[{"atb":[[2.18,0]],"id":47148562},{"atl":[[1.85,0]],"id":49546922}],"con":true,"img":false}]}
{"op":"mcm","clk":"11450723456","pt":1717324886442,"mc":[{"id":"1.229554929","rc":[{"atb":[[2.16,0]],"id":47148562}],"con":true,"img":false}]}
{"op":"mcm","clk":"11450723493","pt":1717324886850,"mc":[{"id":"1.229554929","rc":[{"atb":[[2.2,0]],"id":47148562}],"con":true,"img":false}]}
{"op":"mcm","clk":"11450723504","pt":1717324886955,"mc":[{"id":"1.229554929","rc":[{"atb":[[2.12,17.78]],"id":47148562},{"atb":[[1.64,21.05]],"id":49546922}],"con":true,"img":false}]}
{"op":"mcm","clk":"11450723511","pt":1717324887057,"mc":[{"id":"1.229554929","rc":[{"atb":[[2.22,0.91]],"id":47148562}],"con":true,"img":false}]}
{"op":"mcm","clk":"11450723529","pt":1717324887266,"mc":[{"id":"1.229554929","rc":[{"atb":[[2.14,3.94]],"id":47148562}],"con":true,"img":false}]}
{"op":"mcm","clk":"11450723539","pt":1717324887392,"mc":[{"id":"1.229554929","rc":[{"atb":[[2.22,0],[2.12,10],[2.14,30.11]],"id":47148562},{"atb":[[1.6,49.7]],"id":49546922},{"atl":[[1.78,5.23],[1.76,8.04]],"id":49546922}],"con":true,"img":false}]}
{"op":"mcm","clk":"11450723553","pt":1717324887472,"mc":[{"id":"1.229554929","rc":[{"atb":[[2.04,55.56]],"id":47148562},{"atl":[[2.72,3.92],[2.88,0]],"id":47148562}],"con":true,"img":false}]}
{"op":"mcm","clk":"11450723594","pt":1717324887949,"mc":[{"id":"1.229554929","rc":[{"atb":[[2.16,2.44]],"id":47148562},{"atl":[[1.76,0]],"id":49546922}],"con":true,"img":false}]}
{"op":"mcm","clk":"11450723631","pt":1717324888366,"mc":[{"id":"1.229554929","rc":[{"atb":[[2.14,3.94],[2.08,27.61]],"id":47148562}],"con":true,"img":false}]}
{"op":"mcm","clk":"11450723639","pt":1717324888465,"mc":[{"id":"1.229554929","rc":[{"atb":[[2.16,6.33]],"id":47148562}],"con":true,"img":false}]}
{"op":"mcm","clk":"11450723650","pt":1717324888577,"mc":[{"id":"1.229554929","rc":[{"atb":[[2.12,0],[2.18,4.18],[2.16,5.39]],"id":47148562}],"con":true,"img":false}]}
{"op":"mcm","clk":"11450723658","pt":1717324888673,"mc":[{"id":"1.229554929","rc":[{"atb":[[2.14,4.89]],"id":47148562}],"con":true,"img":false}]}
{"op":"mcm","clk":"11450723692","pt":1717324888934,"mc":[{"id":"1.229554929","rc":[{"atb":[[2.08,0]],"id":47148562}],"con":true,"img":false}]}
{"op":"mcm","clk":"11450723713","pt":1717324889144,"mc":[{"id":"1.229554929","rc":[{"atb":[[2.16,3.89]],"id":47148562}],"con":true,"img":false}]}
{"op":"mcm","clk":"11450723737","pt":1717324889352,"mc":[{"id":"1.229554929","rc":[{"atb":[[2.06,28.13]],"id":47148562}],"con":true,"img":false}]}
{"op":"mcm","clk":"11450723770","pt":1717324889763,"mc":[{"id":"1.229554929","rc":[{"atb":[[2.14,3.94]],"id":47148562}],"con":true,"img":false}]}
{"op":"mcm","clk":"11450723781","pt":1717324889871,"mc":[{"id":"1.229554929","rc":[{"atb":[[2.18,5.12]],"id":47148562}],"con":true,"img":false}]}
{"op":"mcm","clk":"11450723841","pt":1717324890338,"mc":[{"id":"1.229554929","rc":[{"atb":[[1.64,17.12]],"id":49546922},{"trd":[[1.64,8.15]],"ltp":1.64,"tv":8.15,"id":49546922}],"con":true,"img":false}]}
{"op":"mcm","clk":"11450723862","pt":1717324890547,"mc":[{"id":"1.229554929","rc":[{"atb":[[2.18,8.99]],"id":47148562}],"con":true,"img":false}]}
{"op":"mcm","clk":"11450723895","pt":1717324890857,"mc":[{"id":"1.229554929","rc":[{"atb":[[1.6,0]],"id":49546922}],"con":true,"img":false}]}
{"op":"mcm","clk":"11450723912","pt":1717324890971,"mc":[{"id":"1.229554929","rc":[{"atb":[[2.18,5.12],[1.86,4.56],[1.76,5.15]],"id":47148562},{"atb":[[1.37,28.37],[1.47,22.33]],"id":49546922}],"con":true,"img":false}]}
{"op":"mcm","clk":"11450723955","pt":1717324891332,"mc":[{"id":"1.229554929","rc":[{"atb":[[1.59,50.54]],"id":49546922}],"con":true,"img":false}]}
{"op":"mcm","clk":"11450724007","pt":1717324891825,"mc":[{"id":"1.229554929","rc":[{"atb":[[2.3,15.17]],"id":47148562},{"atb":[[1.55,0],[1.57,5.12]],"id":49546922}],"con":true,"img":false}]}
{"op":"mcm","clk":"11450724072","pt":1717324892450,"mc":[{"id":"1.229554929","rc":[{"atb":[[2.06,0],[2.2,24.85]],"id":47148562},{"atl":[[1.92,5.12],[1.78,0]],"id":49546922}],"con":true,"img":false}]}
{"op":"mcm","clk":"11450724085","pt":1717324892553,"mc":[{"id":"1.229554929","rc":[{"atb":[[2.04,0],[2.1,28.14]],"id":47148562},{"atl":[[2.72,0],[2.66,2.68]],"id":47148562}],"con":true,"img":false}]}
{"op":"mcm","clk":"11450724106","pt":1717324892762,"mc":[{"id":"1.229554929","rc":[{"atb":[[1.65,0.86]],"id":49546922}],"con":true,"img":false}]}
{"op":"mcm","clk":"11450724116","pt":1717324892867,"mc":[{"id":"1.229554929","rc":[{"atb":[[2.2,0]],"id":47148562}],"con":true,"img":false}]}
{"op":"mcm","clk":"11450724144","pt":1717324893075,"mc":[{"id":"1.229554929","rc":[{"atb":[[2.3,0],[2.2,3.7]],"id":47148562},{"atl":[[1.91,5.28]],"id":49546922}],"con":true,"img":false}]}
{"op":"mcm","clk":"11450724153","pt":1717324893179,"mc":[{"id":"1.229554929","rc":[{"atl":[[1.92,0],[1.9,4.97]],"id":49546922}],"con":true,"img":false}]}
{"op":"mcm","clk":"11450724174","pt":1717324893341,"mc":[{"id":"1.229554929","rc":[{"atb":[[2.12,26.62]],"id":47148562},{"atb":[[1.6,49.7]],"id":49546922}],"con":true,"img":false}]}
{"op":"mcm","clk":"11450724180","pt":1717324893443,"mc":[{"id":"1.229554929","rc":[{"atl":[[1.89,5.29],[1.97,0]],"id":49546922}],"con":true,"img":false}]}
{"op":"mcm","clk":"11450724204","pt":1717324893651,"mc":[{"id":"1.229554929","rc":[{"atb":[[2.22,2.33],[2.18,0.94]],"id":47148562}],"con":true,"img":false}]}
{"op":"mcm","clk":"11450724235","pt":1717324893964,"mc":[{"id":"1.229554929","rc":[{"atb":[[2.18,0]],"id":47148562},{"atl":[[2.58,0.78]],"id":47148562},{"atl":[[1000,0]],"id":49546922}],"con":true,"img":false}]}
{"op":"mcm","clk":"11450724246","pt":1717324894071,"mc":[{"id":"1.229554929","rc":[{"atb":[[2.22,3.27]],"id":47148562},{"atl":[[1.88,0.65]],"id":49546922}],"con":true,"img":false}]}
{"op":"mcm","clk":"11450724295","pt":1717324894593,"mc":[{"id":"1.229554929","rc":[{"atl":[[2.58,0.65]],"id":47148562}],"con":true,"img":false}]}
{"op":"mcm","clk":"11450724303","pt":1717324894692,"mc":[{"id":"1.229554929","rc":[{"atb":[[2.24,11.16]],"id":47148562}],"con":true,"img":false}]}
{"op":"mcm","clk":"11450724358","pt":1717324895207,"mc":[{"id":"1.229554929","rc":[{"atb":[[2.22,2.33]],"id":47148562}],"con":true,"img":false}]}
{"op":"mcm","clk":"11450724371","pt":1717324895313,"mc":[{"id":"1.229554929","rc":[{"atb":[[2.24,12.1]],"id":47148562}],"con":true,"img":false}]}
{"op":"mcm","clk":"11450724378","pt":1717324895411,"mc":[{"id":"1.229554929","rc":[{"atb":[[2.16,29.6]],"id":47148562}],"con":true,"img":false}]}
{"op":"mcm","clk":"11450724393","pt":1717324895620,"mc":[{"id":"1.229554929","rc":[{"atb":[[2.26,3.69]],"id":47148562},{"atl":[[1.88,5.96]],"id":49546922}],"con":true,"img":false}]}
{"op":"mcm","clk":"11450724401","pt":1717324895677,"mc":[{"id":"1.229554929","rc":[{"atl":[[1.95,0]],"id":49546922}],"con":true,"img":false}]}
{"op":"mcm","clk":"11450724472","pt":1717324896428,"mc":[{"id":"1.229554929","rc":[{"atb":[[2.24,11.16]],"id":47148562}],"con":true,"img":false}]}
{"op":"mcm","clk":"11450724484","pt":1717324896506,"mc":[{"id":"1.229554929","rc":[{"atb":[[2.26,4.64]],"id":47148562}],"con":true,"img":false}]}
{"op":"mcm","clk":"11450724581","pt":1717324897491,"mc":[{"id":"1.229554929","rc":[{"atb":[[2.28,10.98]],"id":47148562},{"atl":[[2.66,0]],"id":47148562},{"atb":[[1.57,0]],"id":49546922},{"atl":[[2,0],[1.97,11.94]],"id":49546922}],"con":true,"img":false}]}
{"op":"mcm","clk":"11450724588","pt":1717324897598,"mc":[{"id":"1.229554929","rc":[{"atl":[[2.76,4.53]],"id":47148562},{"atb":[[1.54,60.22]],"id":49546922}],"con":true,"img":false}]}
{"op":"mcm","clk":"11450724599","pt":1717324897704,"mc":[{"id":"1.229554929","rc":[{"atb":[[2.1,0],[2.16,56.23]],"id":47148562},{"atl":[[2.58,0],[3.05,0],[2.76,0]],"id":47148562},{"atb":[[1.54,55.22]],"id":49546922},{"atl":[[1.97,0],[1.94,11.94]],"id":49546922}],"con":true,"img":false}]}
{"op":"mcm","clk":"11450724609","pt":1717324897814,"mc":[{"id":"1.229554929","rc":[{"atl":[[2.82,4.53],[3.3,8.94],[1000,0.65]],"id":47148562},{"atb":[[1.52,5]],"id":49546922}],"con":true,"img":false}]}
{"op":"mcm","clk":"11450724620","pt":1717324897917,"mc":[{"id":"1.229554929","rc":[{"atb":[[2.26,28.31]],"id":47148562},{"atb":[[1.59,0],[1.6,0],[1.57,52.32],[1.54,0]],"id":49546922}],"con":true,"img":false}]}
{"op":"mcm","clk":"11450724647","pt":1717324898221,"mc":[{"id":"1.229554929","rc":[{"atb":[[2.26,27.37]],"id":47148562}],"con":true,"img":false}]}
{"op":"mcm","clk":"11450724656","pt":1717324898332,"mc":[{"id":"1.229554929","rc":[{"atb":[[2.28,11.93]],"id":47148562},{"atl":[[1.9,0],[1.87,5]],"id":49546922}],"con":true,"img":false}]}
{"op":"mcm","clk":"11450724702","pt":1717324898809,"mc":[{"id":"1.229554929","rc":[{"atb":[[2.3,5.94],[2.22,0]],"id":47148562}],"con":true,"img":false}]}
{"op":"mcm","clk":"11450724711","pt":1717324898916,"mc":[{"id":"1.229554929","rc":[{"atl":[[1.88,5.3]],"id":49546922}],"con":true,"img":false}]}
{"op":"mcm","clk":"11450724721","pt":1717324899019,"mc":[{"id":"1.229554929","rc":[{"atb":[[2.32,3.56],[2.14,0]],"id":47148562},{"atl":[[1.86,5.55],[1.87,5.65],[1.93,0]],"id":49546922}],"con":true,"img":false}]}
{"op":"mcm","clk":"11450724753","pt":1717324899325,"mc":[{"id":"1.229554929","rc":[{"atb":[[2.28,10.98]],"id":47148562}],"con":true,"img":false}]}
{"op":"mcm","clk":"11450724764","pt":1717324899429,"mc":[{"id":"1.229554929","rc":[{"atb":[[2.32,4.5],[2.12,0]],"id":47148562}],"con":true,"img":false}]}
{"op":"mcm","clk":"11450724774","pt":1717324899491,"mc":[{"id":"1.229554929","rc":[{"atl":[[1.87,5]],"id":49546922}],"con":true,"img":false}]}
{"op":"mcm","clk":"11450724784","pt":1717324899594,"mc":[{"id":"1.229554929","rc":[{"atl":[[1000,0.65]],"id":49546922}],"con":true,"img":false}]}
{"op":"mcm","clk":"11450724845","pt":1717324900321,"mc":[{"id":"1.229554929","rc":[{"atb":[[2.34,9.04]],"id":47148562}],"con":true,"img":false}]}
{"op":"mcm","clk":"11450724888","pt":1717324900796,"mc":[{"id":"1.229554929","rc":[{"atb":[[1.64,15.37],[1.65,0]],"id":49546922},{"trd":[[1.64,11.66],[1.65,1.72]],"ltp":1.64,"tv":13.38,"id":49546922}],"con":true,"img":false}]}
{"op":"mcm","clk":"11450724896","pt":1717324900901,"mc":[{"id":"1.229554929","rc":[{"atb":[[2.3,28.87]],"id":47148562}],"con":true,"img":false}]}
{"op":"mcm","clk":"11450724917","pt":1717324901112,"mc":[{"id":"1.229554929","rc":[{"atl":[[1.85,0.85]],"id":49546922}],"con":true,"img":false}]}
{"op":"mcm","clk":"11450725055","pt":1717324902612,"mc":[{"id":"1.229554929","rc":[{"atl":[[2.82,0]],"id":47148562},{"atb":[[1.52,0]],"id":49546922}],"con":true,"img":false}]}
{"op":"mcm","clk":"11450725065","pt":1717324902717,"mc":[{"id":"1.229554929","rc":[{"atl":[[2.9,4.46]],"id":47148562},{"atb":[[1.49,4.86]],"id":49546922}],"con":true,"img":false}]}
{"op":"mcm","clk":"11450725074","pt":1717324902825,"mc":[{"id":"1.229554929","rc":[{"atb":[[1.76,0],[1.86,0],[2.2,25.66],[2.16,29.6]],"id":47148562},{"atb":[[1.37,0],[1.47,0]],"id":49546922},{"atl":[[1.89,15.6],[1.94,0]],"id":49546922}],"con":true,"img":false}]}
{"op":"mcm","clk":"11450725081","pt":1717324902934,"mc":[{"id":"1.229554929","rc":[{"atb":[[2.32,3.56]],"id":47148562},{"atl":[[1.85,0.8]],"id":49546922}],"con":true,"img":false}]}
{"op":"mcm","clk":"11450725092","pt":1717324903035,"mc":[{"id":"1.229554929","rc":[{"atb":[[2.34,9.99]],"id":47148562}],"con":true,"img":false}]}
{"op":"mcm","clk":"11450725136","pt":1717324903401,"mc":[{"id":"1.229554929","rc":[{"atl":[[1.85,5.66],[1.87,0]],"id":49546922}],"con":true,"img":false}]}
{"op":"mcm","clk":"11450725177","pt":1717324903929,"mc":[{"id":"1.229554929","rc":[{"atb":[[2.3,22.93],[2.34,14.13]],"id":47148562}],"con":true,"img":false}]}
{"op":"mcm","clk":"11450725299","pt":1717324905236,"mc":[{"id":"1.229554929","rc":[{"atb":[[2.24,0]],"id":47148562}],"con":true,"img":false}]}
{"op":"mcm","clk":"11450725559","pt":1717324908104,"mc":[{"id":"1.229554929","marketDefinition":{"bspMarket":false,"turnInPlayEnabled":false,"persistenceEnabled":false,"marketBaseRate":7.0,"eventId":"33318908","eventTypeId":"4339","numberOfWinners":1,"bettingType":"ODDS","marketType":"MATCH_BET","marketTime":"2024-06-02T10:41:00.000Z","suspendTime":"2024-06-02T10:41:00.000Z","bspReconciled":false,"complete":true,"inPlay":false,"crossMatching":true,"runnersVoidable":false,"numberOfActiveRunners":2,"betDelay":0,"status":"SUSPENDED","runners":[{"status":"ACTIVE","sortPriority":1,"id":47148562,"name":"2. Under Siege"},{"status":"ACTIVE","sortPriority":2,"id":49546922,"name":"4. Uno Whiskey"}],"regulators":["MR_INT"],"venue":"Murray Bridge","countryCode":"AU","discountAllowed":true,"timezone":"Australia/Adelaide","openDate":"2024-06-02T08:21:00.000Z","version":5963144070,"name":"Under Siege v Uno Whiskey","eventName":"Murray Bridge (AUS) 2nd Jun"},"rc":[],"con":true,"img":false}]}
{"op":"mcm","clk":"11450725568","pt":1717324908165,"mc":[{"id":"1.229554929","rc":[{"atb":[[2.4,0],[1.01,0],[2.32,0],[2.3,0],[1.45,0],[1.43,0],[2.28,0],[2.26,0],[2.2,0],[2.16,0],[1.47,0],[2.34,0]],"id":47148562},{"atl":[[2.9,0],[2.6,0],[2.62,0],[2.78,0],[3.3,0],[990,0],[1000,0]],"id":47148562},{"atb":[[1.64,0],[1.63,0],[1.03,0],[1.57,0],[1.62,0],[1.49,0],[1.38,0]],"id":49546922},{"atl":[[1.89,0],[1.85,0],[1.88,0],[1.91,0],[2.28,0],[1.86,0],[990,0],[1000,0]],"id":49546922}],"con":true,"img":false}]}
{"op":"mcm","clk":"11450735522","pt":1717325014675,"mc":[{"id":"1.229554929","rc":[{"trd":[[2.5,0],[2.48,0]],"ltp":2.5,"tv":0.0,"id":47148562},{"trd":[[1.64,0],[1.63,0],[1.67,0],[1.7,0],[1.65,0]],"ltp":1.64,"tv":0.0,"id":49546922}],"con":true,"img":false}]}
{"op":"mcm","clk":"11450735688","pt":1717325016305,"mc":[{"id":"1.229554929","marketDefinition":{"bspMarket":false,"turnInPlayEnabled":false,"persistenceEnabled":false,"marketBaseRate":7.0,"eventId":"33318908","eventTypeId":"4339","numberOfWinners":1,"bettingType":"ODDS","marketType":"MATCH_BET","marketTime":"2024-06-02T10:41:00.000Z","suspendTime":"2024-06-02T10:41:00.000Z","bspReconciled":false,"complete":true,"inPlay":false,"crossMatching":false,"runnersVoidable":false,"numberOfActiveRunners":0,"betDelay":0,"status":"CLOSED","settledTime":"2024-06-02T10:43:33.000Z","runners":[{"status":"LOSER","sortPriority":1,"id":47148562,"name":"2. Under Siege"},{"status":"WINNER","sortPriority":2,"id":49546922,"name":"4. Uno Whiskey"}],"regulators":["MR_INT"],"venue":"Murray Bridge","countryCode":"AU","discountAllowed":true,"timezone":"Australia/Adelaide","openDate":"2024-06-02T08:21:00.000Z","version":5963146066,"name":"Under Siege v Uno Whiskey","eventName":"Murray Bridge (AUS) 2nd Jun"},"rc":[],"con":true,"img":false}]}
