{"op":"mcm","clk":"11448351871","pt":1717289088271,"mc":[{"id":"1.229554919","marketDefinition":{"bspMarket":false,"turnInPlayEnabled":false,"persistenceEnabled":false,"marketBaseRate":7.0,"eventId":"33318908","eventTypeId":"4339","numberOfWinners":1,"bettingType":"ODDS","marketType":"MATCH_BET","marketTime":"2024-06-02T10:03:00.000Z","suspendTime":"2024-06-02T10:03:00.000Z","bspReconciled":false,"complete":true,"inPlay":false,"crossMatching":true,"runnersVoidable":false,"numberOfActiveRunners":2,"betDelay":0,"status":"OPEN","runners":[{"status":"ACTIVE","sortPriority":1,"id":46292327,"name":"5. Immense"},{"status":"ACTIVE","sortPriority":2,"id":65788088,"name":"6. Bundy Baz"}],"regulators":["MR_INT"],"venue":"Murray Bridge","countryCode":"AU","discountAllowed":true,"timezone":"Australia/Adelaide","openDate":"2024-06-02T08:21:00.000Z","version":5962433802,"name":"Immense v Bundy Baz","eventName":"Murray Bridge (AUS) 2nd Jun"},"rc":[],"con":true,"img":false}]}
{"op":"mcm","clk":"11448366403","pt":1717289278043,"mc":[{"id":"1.229554919","rc":[{"atb":[[1.27,29.06],[1.37,21.2]],"id":46292327},{"atb":[[2.58,4.96],[2.78,4.41]],"id":65788088}],"con":true,"img":false}]}
{"op":"mcm","clk":"11448494247","pt":1717291211930,"mc":[{"id":"1.229554919","rc":[{"atb":[[1.27,0],[1.37,0]],"id":46292327},{"atb":[[2.58,0],[2.78,0]],"id":65788088}],"con":true,"img":false}]}
{"op":"mcm","clk":"11448494993","pt":1717291222496,"mc":[{"id":"1.229554919","rc":[{"atb":[[1.27,29.06],[1.37,21.2]],"id":46292327},{"atb":[[2.58,4.96],[2.78,4.41]],"id":65788088}],"con":true,"img":false}]}
{"op":"mcm","clk":"11449358079","pt":1717307827566,"mc":[{"id":"1.229554919","rc":[{"atb":[[1.01,17.76]],"id":46292327},{"atl":[[1000,0.85]],"id":46292327},{"atb":[[1.02,8.87]],"id":65788088},{"atl":[[990,0.85]],"id":65788088}],"con":true,"img":false}]}
{"op":"mcm","clk":"11449383836","pt":1717308365181,"mc":[{"id":"1.229554919","rc":[{"atb":[[1.27,0],[1.37,0]],"id":46292327},{"atb":[[2.58,0],[2.78,0]],"id":65788088}],"con":true,"img":false}]}
{"op":"mcm","clk":"11449385924","pt":1717308397791,"mc":[{"id":"1.229554919","rc":[{"atb":[[1.23,34.12],[1.33,23.77]],"id":46292327},{"atb":[[2.86,4.21],[2.66,4.72]],"id":65788088}],"con":true,"img":false}]}
{"op":"mcm","clk":"11449546570","pt":1717310733145,"mc":[{"id":"1.229554919","rc":[{"atb":[[1.23,0],[1.33,0]],"id":46292327},{"atb":[[2.86,0],[2.66,0]],"id":65788088}],"con":true,"img":false}]}
{"op":"mcm","clk":"11449548297","pt":1717310761849,"mc":[{"id":"1.229554919","rc":[{"atb":[[1.23,34.12],[1.33,23.77]],"id":46292327},{"atb":[[2.86,4.21],[2.66,4.72]],"id":65788088}],"con":true,"img":false}]}
{"op":"mcm","clk":"11449550512","pt":1717310797293,"mc":[{"id":"1.229554919","rc":[{"atb":[[1.23,0],[1.33,0]],"id":46292327},{"atb":[[2.86,0],[2.66,0]],"id":65788088}],"con":true,"img":false}]}
{"op":"mcm","clk":"11449552522","pt":1717310833683,"mc":[{"id":"1.229554919","rc":[{"atb":[[1.23,34.12],[1.33,23.77]],"id":46292327},{"atb":[[2.86,4.21],[2.66,4.72]],"id":65788088}],"con":true,"img":false}]}
{"op":"mcm","clk":"11449586028","pt":1717311431795,"mc":[{"id":"1.229554919","rc":[{"atl":[[1000,0.17]],"id":46292327},{"atl":[[990,0.17]],"id":65788088}],"con":true,"img":false}]}
{"op":"mcm","clk":"11449609377","pt":1717311864809,"mc":[{"id":"1.229554919","rc":[{"atb":[[1.23,0],[1.33,0]],"id":46292327},{"atb":[[2.86,0],[2.66,0]],"id":65788088}],"con":true,"img":false}]}
{"op":"mcm","clk":"11449610115","pt":1717311877557,"mc":[{"id":"1.229554919","rc":[{"atb":[[1.23,34.12],[1.33,23.77]],"id":46292327},{"atb":[[2.86,4.21],[2.66,4.72]],"id":65788088}],"con":true,"img":false}]}
{"op":"mcm","clk":"11449655976","pt":1717312956393,"mc":[{"id":"1.229554919","rc":[{"atb":[[1.23,0],[1.33,0]],"id":46292327},{"atb":[[2.86,0],[2.66,0]],"id":65788088}],"con":true,"img":false}]}
{"op":"mcm","clk":"11449656393","pt":1717312966043,"mc":[{"id":"1.229554919","rc":[{"atb":[[1.23,34.12],[1.33,23.77]],"id":46292327},{"atb":[[2.86,4.21],[2.66,4.72]],"id":65788088}],"con":true,"img":false}]}
{"op":"mcm","clk":"11449736747","pt":1717314096812,"mc":[{"id":"1.229554919","rc":[{"atb":[[1.23,0],[1.33,0]],"id":46292327},{"atb":[[2.86,0],[2.66,0]],"id":65788088}],"con":true,"img":false}]}
{"op":"mcm","clk":"11449739258","pt":1717314124126,"mc":[{"id":"1.229554919","rc":[{"atb":[[1.23,34.12],[1.33,23.77]],"id":46292327},{"atb":[[2.86,4.21],[2.66,4.72]],"id":65788088}],"con":true,"img":false}]}
{"op":"mcm","clk":"11449745221","pt":1717314192419,"mc":[{"id":"1.229554919","rc":[{"atb":[[1.23,0],[1.33,0]],"id":46292327},{"atb":[[2.86,0],[2.66,0]],"id":65788088}],"con":true,"img":false}]}
{"op":"mcm","clk":"11449746551","pt":1717314206858,"mc":[{"id":"1.229554919","rc":[{"atb":[[1.23,34.12],[1.33,23.77]],"id":46292327},{"atb":[[2.86,4.21],[2.66,4.72]],"id":65788088}],"con":true,"img":false}]}
{"op":"mcm","clk":"11449837969","pt":1717315161548,"mc":[{"id":"1.229554919","rc":[{"atb":[[1.23,0],[1.33,0]],"id":46292327},{"atb":[[2.86,0],[2.66,0]],"id":65788088}],"con":true,"img":false}]}
{"op":"mcm","clk":"11449841704","pt":1717315200095,"mc":[{"id":"1.229554919","rc":[{"atb":[[1.23,34.12],[1.33,23.77]],"id":46292327},{"atb":[[2.86,4.21],[2.66,4.72]],"id":65788088}],"con":true,"img":false}]}
{"op":"mcm","clk":"11449851287","pt":1717315296619,"mc":[{"id":"1.229554919","rc":[{"atb":[[1.23,0],[1.33,0]],"id":46292327},{"atb":[[2.86,0],[2.66,0]],"id":65788088}],"con":true,"img":false}]}
{"op":"mcm","clk":"11449854719","pt":1717315331356,"mc":[{"id":"1.229554919","rc":[{"atb":[[1.23,34.12],[1.33,23.77]],"id":46292327},{"atb":[[2.86,4.21],[2.66,4.72]],"id":65788088}],"con":true,"img":false}]}
{"op":"mcm","clk":"11449893681","pt":1717315712900,"mc":[{"id":"1.229554919","rc":[{"atb":[[1.23,0],[1.33,0]],"id":46292327},{"atb":[[2.86,0],[2.66,0]],"id":65788088}],"con":true,"img":false}]}
{"op":"mcm","clk":"11449898095","pt":1717315753812,"mc":[{"id":"1.229554919","rc":[{"atb":[[1.23,34.12],[1.33,23.77]],"id":46292327},{"atb":[[2.86,4.21],[2.66,4.72]],"id":65788088}],"con":true,"img":false}]}
{"op":"mcm","clk":"11449924833","pt":1717316010137,"mc":[{"id":"1.229554919","rc":[{"atb":[[1.23,0],[1.33,0]],"id":46292327},{"atb":[[2.86,0],[2.66,0]],"id":65788088}],"con":true,"img":false}]}
{"op":"mcm","clk":"11449928201","pt":1717316044386,"mc":[{"id":"1.229554919","rc":[{"atb":[[1.23,34.12],[1.33,23.77]],"id":46292327},{"atb":[[2.86,4.21],[2.66,4.72]],"id":65788088}],"con":true,"img":false}]}
{"op":"mcm","clk":"11449993640","pt":1717316870574,"mc":[{"id":"1.229554919","rc":[{"atb":[[1.23,0],[1.33,0]],"id":46292327},{"atb":[[2.86,0],[2.66,0]],"id":65788088}],"con":true,"img":false}]}
{"op":"mcm","clk":"11449996389","pt":1717316901784,"mc":[{"id":"1.229554919","rc":[{"atb":[[1.23,34.12],[1.33,23.77]],"id":46292327},{"atb":[[2.86,4.21],[2.66,4.72]],"id":65788088}],"con":true,"img":false}]}
{"op":"mcm","clk":"11450004007","pt":1717316992820,"mc":[{"id":"1.229554919","rc":[{"atb":[[1.23,0],[1.33,0]],"id":46292327},{"atb":[[2.86,0],[2.66,0]],"id":65788088}],"con":true,"img":false}]}
{"op":"mcm","clk":"11450007767","pt":1717317031597,"mc":[{"id":"1.229554919","rc":[{"atb":[[1.23,34.12],[1.33,23.77]],"id":46292327},{"atb":[[2.86,4.21],[2.66,4.72]],"id":65788088}],"con":true,"img":false}]}
{"op":"mcm","clk":"11450076107","pt":1717317730855,"mc":[{"id":"1.229554919","rc":[{"atb":[[1.23,0],[1.33,0]],"id":46292327},{"atb":[[2.86,0],[2.66,0]],"id":65788088}],"con":true,"img":false}]}
{"op":"mcm","clk":"11450079204","pt":1717317764759,"mc":[{"id":"1.229554919","rc":[{"atb":[[1.23,34.12],[1.33,23.77]],"id":46292327},{"atb":[[2.86,4.21],[2.66,4.72]],"id":65788088}],"con":true,"img":false}]}
{"op":"mcm","clk":"11450088150","pt":1717317870087,"mc":[{"id":"1.229554919","rc":[{"atb":[[1.23,0],[1.33,0]],"id":46292327},{"atb":[[2.86,0],[2.66,0]],"id":65788088}],"con":true,"img":false}]}
{"op":"mcm","clk":"11450089853","pt":1717317888807,"mc":[{"id":"1.229554919","rc":[{"atb":[[1.23,34.12],[1.33,23.77]],"id":46292327},{"atb":[[2.86,4.21],[2.66,4.72]],"id":65788088}],"con":true,"img":false}]}
{"op":"mcm","clk":"11450150266","pt":1717318577907,"mc":[{"id":"1.229554919","rc":[{"atb":[[1.23,0],[1.33,0]],"id":46292327},{"atb":[[2.86,0],[2.66,0]],"id":65788088}],"con":true,"img":false}]}
{"op":"mcm","clk":"11450151751","pt":1717318593147,"mc":[{"id":"1.229554919","rc":[{"atb":[[1.23,34.12],[1.33,23.77]],"id":46292327},{"atb":[[2.86,4.21],[2.66,4.72]],"id":65788088}],"con":true,"img":false}]}
{"op":"mcm","clk":"11450164003","pt":1717318717352,"mc":[{"id":"1.229554919","rc":[{"atb":[[1.03,117.59]],"id":46292327},{"atl":[[970,1.21]],"id":46292327},{"atb":[[1.03,201.1]],"id":65788088},{"atl":[[960,1.94]],"id":65788088}],"con":true,"img":false}]}
{"op":"mcm","clk":"11450164687","pt":1717318724496,"mc":[{"id":"1.229554919","rc":[{"atb":[[1.23,0],[1.33,0]],"id":46292327},{"atb":[[2.86,0],[2.66,0]],"id":65788088}],"con":true,"img":false}]}
{"op":"mcm","clk":"11450166303","pt":1717318742709,"mc":[{"id":"1.229554919","rc":[{"atb":[[1.23,34.12],[1.33,23.77]],"id":46292327},{"atb":[[2.86,4.21],[2.66,4.72]],"id":65788088}],"con":true,"img":false}]}
{"op":"mcm","clk":"11450188856","pt":1717318980254,"mc":[{"id":"1.229554919","rc":[{"atl":[[16.5,2]],"id":46292327},{"atl":[[25,2]],"id":65788088}],"con":true,"img":false}]}
{"op":"mcm","clk":"11450188893","pt":1717318980666,"mc":[{"id":"1.229554919","rc":[{"atb":[[1.28,53.57],[1.26,76.92],[1.22,136.36],[1.24,104.17]],"id":46292327},{"atl":[[4.8,6.58],[4.6,5.56],[5,7.5],[4.4,4.41]],"id":46292327},{"atl":[[3.35,12.77],[3.15,9.3],[3.25,11.11],[3.05,7.32]],"id":65788088}],"con":true,"img":false}]}
{"op":"mcm","clk":"11450188903","pt":1717318980767,"mc":[{"id":"1.229554919","rc":[{"atl":[[5.3,2]],"id":46292327},{"atl":[[7,2]],"id":65788088}],"con":true,"img":false}]}
{"op":"mcm","clk":"11450188919","pt":1717318980875,"mc":[{"id":"1.229554919","rc":[{"atl":[[16.5,0]],"id":46292327},{"atl":[[25,0]],"id":65788088}],"con":true,"img":false}]}
{"op":"mcm","clk":"11450190722","pt":1717318999590,"mc":[{"id":"1.229554919","rc":[{"atb":[[1.28,0],[1.26,0],[1.24,0]],"id":46292327}],"con":true,"img":false}]}
{"op":"mcm","clk":"11450191025","pt":1717319003171,"mc":[{"id":"1.229554919","rc":[{"atb":[[1.28,53.57]],"id":46292327}],"con":true,"img":false}]}
{"op":"mcm","clk":"11450191597","pt":1717319009415,"mc":[{"id":"1.229554919","rc":[{"atb":[[1.28,0]],"id":46292327}],"con":true,"img":false}]}
{"op":"mcm","clk":"11450193598","pt":1717319029546,"mc":[{"id":"1.229554919","rc":[{"atl":[[3,7.5]],"id":65788088}],"con":true,"img":false}]}
{"op":"mcm","clk":"11450193607","pt":1717319029659,"mc":[{"id":"1.229554919","rc":[{"atb":[[1.23,0],[1.33,0]],"id":46292327},{"atb":[[2.86,0],[2.66,0]],"id":65788088},{"atl":[[3.05,0]],"id":65788088}],"con":true,"img":false}]}
{"op":"mcm","clk":"11450193657","pt":1717319030120,"mc":[{"id":"1.229554919","rc":[{"atb":[[1.23,65.22]],"id":46292327}],"con":true,"img":false}]}
{"op":"mcm","clk":"11450193879","pt":1717319032616,"mc":[{"id":"1.229554919","rc":[{"atb":[[1.28,89.29],[1.26,115.38],[1.32,46.87],[1.3,66.67]],"id":65788088}],"con":true,"img":false}]}
{"op":"mcm","clk":"11450194001","pt":1717319033919,"mc":[{"id":"1.229554919","rc":[{"atb":[[1.28,53.57]],"id":46292327}],"con":true,"img":false}]}
{"op":"mcm","clk":"11450194525","pt":1717319039867,"mc":[{"id":"1.229554919","rc":[{"atb":[[1.28,0]],"id":46292327}],"con":true,"img":false}]}
{"op":"mcm","clk":"11450194927","pt":1717319043969,"mc":[{"id":"1.229554919","rc":[{"atb":[[1.21,95.24]],"id":46292327}],"con":true,"img":false}]}
{"op":"mcm","clk":"11450195243","pt":1717319047750,"mc":[{"id":"1.229554919","rc":[{"atb":[[1.23,99.34],[1.33,23.77]],"id":46292327},{"atb":[[2.86,4.21],[2.66,4.72]],"id":65788088},{"atl":[[3.05,7.32]],"id":65788088}],"con":true,"img":false}]}
{"op":"mcm","clk":"11450195252","pt":1717319047860,"mc":[{"id":"1.229554919","rc":[{"atl":[[3,0]],"id":65788088}],"con":true,"img":false}]}
{"op":"mcm","clk":"11450198610","pt":1717319085526,"mc":[{"id":"1.229554919","rc":[{"atl":[[3,7.5]],"id":65788088}],"con":true,"img":false}]}
{"op":"mcm","clk":"11450198622","pt":1717319085635,"mc":[{"id":"1.229554919","rc":[{"atl":[[3.05,0]],"id":65788088}],"con":true,"img":false}]}
{"op":"mcm","clk":"11450198630","pt":1717319085701,"mc":[{"id":"1.229554919","rc":[{"atb":[[1.23,65.22],[1.33,0]],"id":46292327},{"atb":[[2.86,0],[2.66,0]],"id":65788088}],"con":true,"img":false}]}
{"op":"mcm","clk":"11450199229","pt":1717319091782,"mc":[{"id":"1.229554919","rc":[{"atb":[[1.19,131.58]],"id":46292327}],"con":true,"img":false}]}
{"op":"mcm","clk":"11450200052","pt":1717319100348,"mc":[{"id":"1.229554919","rc":[{"atb":[[1.23,99.34],[1.33,23.77]],"id":46292327},{"atb":[[2.86,4.21],[2.66,4.72]],"id":65788088}],"con":true,"img":false}]}
{"op":"mcm","clk":"11450200060","pt":1717319100401,"mc":[{"id":"1.229554919","rc":[{"atl":[[3,0],[3.05,7.32]],"id":65788088}],"con":true,"img":false}]}
{"op":"mcm","clk":"11450218882","pt":1717319285816,"mc":[{"id":"1.229554919","rc":[{"atb":[[1.23,34.12],[1.24,62.5]],"id":46292327}],"con":true,"img":false}]}
{"op":"mcm","clk":"11450231426","pt":1717319422429,"mc":[{"id":"1.229554919","rc":[{"atl":[[3.1,7.14],[3.05,0]],"id":65788088}],"con":true,"img":false}]}
{"op":"mcm","clk":"11450232011","pt":1717319427869,"mc":[{"id":"1.229554919","rc":[{"atl":[[3.05,7.32]],"id":65788088}],"con":true,"img":false}]}
{"op":"mcm","clk":"11450232018","pt":1717319427925,"mc":[{"id":"1.229554919","rc":[{"atl":[[3.1,0]],"id":65788088}],"con":true,"img":false}]}
{"op":"mcm","clk":"11450232770","pt":1717319435359,"mc":[{"id":"1.229554919","rc":[{"atb":[[1.28,53.57],[1.24,0]],"id":46292327}],"con":true,"img":false}]}
{"op":"mcm","clk":"11450233736","pt":1717319445375,"mc":[{"id":"1.229554919","rc":[{"atb":[[1.26,76.92]],"id":46292327}],"con":true,"img":false}]}
{"op":"mcm","clk":"11450233818","pt":1717319446163,"mc":[{"id":"1.229554919","rc":[{"atb":[[1.19,0],[1.23,0],[1.33,0]],"id":46292327},{"atb":[[2.86,0],[2.66,0]],"id":65788088}],"con":true,"img":false}]}
{"op":"mcm","clk":"11450234049","pt":1717319448880,"mc":[{"id":"1.229554919","rc":[{"atl":[[3.1,7.14]],"id":65788088}],"con":true,"img":false}]}
{"op":"mcm","clk":"11450234058","pt":1717319448982,"mc":[{"id":"1.229554919","rc":[{"atl":[[3.05,0]],"id":65788088}],"con":true,"img":false}]}
{"op":"mcm","clk":"11450234065","pt":1717319449081,"mc":[{"id":"1.229554919","rc":[{"atl":[[3.1,0],[3.35,0]],"id":65788088}],"con":true,"img":false}]}
{"op":"mcm","clk":"11450234074","pt":1717319449200,"mc":[{"id":"1.229554919","rc":[{"atl":[[3.05,7.32]],"id":65788088}],"con":true,"img":false}]}
{"op":"mcm","clk":"11450234115","pt":1717319449595,"mc":[{"id":"1.229554919","rc":[{"atl":[[3.1,7.14]],"id":65788088}],"con":true,"img":false}]}
{"op":"mcm","clk":"11450234120","pt":1717319449700,"mc":[{"id":"1.229554919","rc":[{"atl":[[3.05,0]],"id":65788088}],"con":true,"img":false}]}
{"op":"mcm","clk":"11450234686","pt":1717319455299,"mc":[{"id":"1.229554919","rc":[{"atl":[[3.05,7.32]],"id":65788088}],"con":true,"img":false}]}
{"op":"mcm","clk":"11450235969","pt":1717319469510,"mc":[{"id":"1.229554919","rc":[{"atl":[[3.05,0]],"id":65788088}],"con":true,"img":false}]}
{"op":"mcm","clk":"11450236023","pt":1717319470023,"mc":[{"id":"1.229554919","rc":[{"atl":[[3,7.5]],"id":65788088}],"con":true,"img":false}]}
{"op":"mcm","clk":"11450238749","pt":1717319500761,"mc":[{"id":"1.229554919","rc":[{"atb":[[1.23,34.12],[1.33,23.77]],"id":46292327},{"atb":[[2.86,4.21],[2.66,4.72]],"id":65788088}],"con":true,"img":false}]}
{"op":"mcm","clk":"11450238798","pt":1717319501130,"mc":[{"id":"1.229554919","rc":[{"atl":[[3,0],[3.05,7.32]],"id":65788088}],"con":true,"img":false}]}
{"op":"mcm","clk":"11450243998","pt":1717319556267,"mc":[{"id":"1.229554919","rc":[{"atl":[[4.3,4.55],[4.4,0]],"id":46292327}],"con":true,"img":false}]}
{"op":"mcm","clk":"11450258536","pt":1717319718271,"mc":[{"id":"1.229554919","rc":[{"atb":[[1.28,0],[1.24,62.5]],"id":46292327}],"con":true,"img":false}]}
{"op":"mcm","clk":"11450258635","pt":1717319719153,"mc":[{"id":"1.229554919","rc":[{"atb":[[1.26,0]],"id":46292327}],"con":true,"img":false}]}
{"op":"mcm","clk":"11450258648","pt":1717319719267,"mc":[{"id":"1.229554919","rc":[{"atl":[[4.3,0],[4.2,4.69]],"id":46292327}],"con":true,"img":false}]}
{"op":"mcm","clk":"11450259629","pt":1717319729306,"mc":[{"id":"1.229554919","rc":[{"atb":[[1.22,90.91]],"id":46292327},{"atl":[[4.4,5.88]],"id":46292327}],"con":true,"img":false}]}
{"op":"mcm","clk":"11450260472","pt":1717319738579,"mc":[{"id":"1.229554919","rc":[{"atl":[[4.3,4.55]],"id":46292327}],"con":true,"img":false}]}
{"op":"mcm","clk":"11450260483","pt":1717319738695,"mc":[{"id":"1.229554919","rc":[{"atl":[[4.8,0],[4.6,0],[5,0],[4.4,0],[4.2,0]],"id":46292327}],"con":true,"img":false}]}
{"op":"mcm","clk":"11450260491","pt":1717319738820,"mc":[{"id":"1.229554919","rc":[{"atl":[[16.5,6.45]],"id":46292327}],"con":true,"img":false}]}
{"op":"mcm","clk":"11450260500","pt":1717319738917,"mc":[{"id":"1.229554919","rc":[{"atl":[[5.3,0]],"id":46292327}],"con":true,"img":false}]}
{"op":"mcm","clk":"11450260600","pt":1717319740077,"mc":[{"id":"1.229554919","rc":[{"atb":[[1.28,53.57]],"id":46292327}],"con":true,"img":false}]}
{"op":"mcm","clk":"11450261467","pt":1717319749910,"mc":[{"id":"1.229554919","rc":[{"atb":[[1.28,0]],"id":46292327}],"con":true,"img":false}]}
{"op":"mcm","clk":"11450261481","pt":1717319750117,"mc":[{"id":"1.229554919","rc":[{"atb":[[1.2,125]],"id":46292327},{"atl":[[4.5,5.71]],"id":46292327}],"con":true,"img":false}]}
{"op":"mcm","clk":"11450261489","pt":1717319750220,"mc":[{"id":"1.229554919","rc":[{"atl":[[16.5,0],[5.3,10.26]],"id":46292327}],"con":true,"img":false}]}
{"op":"mcm","clk":"11450262290","pt":1717319760107,"mc":[{"id":"1.229554919","rc":[{"atl":[[4.7,6.76]],"id":46292327}],"con":true,"img":false}]}
{"op":"mcm","clk":"11450263125","pt":1717319770120,"mc":[{"id":"1.229554919","rc":[{"atl":[[4.9,7.69]],"id":46292327}],"con":true,"img":false}]}
{"op":"mcm","clk":"11450263147","pt":1717319770432,"mc":[{"id":"1.229554919","rc":[{"atb":[[1.28,53.57]],"id":46292327}],"con":true,"img":false}]}
{"op":"mcm","clk":"11450263153","pt":1717319770533,"mc":[{"id":"1.229554919","rc":[{"atb":[[1.24,0]],"id":46292327}],"con":true,"img":false}]}
{"op":"mcm","clk":"11450264017","pt":1717319780151,"mc":[{"id":"1.229554919","rc":[{"atb":[[1.28,0],[1.24,62.5]],"id":46292327}],"con":true,"img":false}]}
{"op":"mcm","clk":"11450264909","pt":1717319790868,"mc":[{"id":"1.229554919","rc":[{"atl":[[3,7.5],[3.05,0]],"id":65788088}],"con":true,"img":false}]}
{"op":"mcm","clk":"11450264927","pt":1717319791076,"mc":[{"id":"1.229554919","rc":[{"atb":[[1.23,0],[1.33,0]],"id":46292327},{"atb":[[2.86,0],[2.66,0]],"id":65788088}],"con":true,"img":false}]}
{"op":"mcm","clk":"11450264939","pt":1717319791283,"mc":[{"id":"1.229554919","rc":[{"atb":[[1.32,0],[1.33,45.45]],"id":65788088},{"atl":[[3,0],[3.05,7.32]],"id":65788088}],"con":true,"img":false}]}
{"op":"mcm","clk":"11450265128","pt":1717319793266,"mc":[{"id":"1.229554919","rc":[{"atl":[[3,7.5],[3.05,0]],"id":65788088}],"con":true,"img":false}]}
{"op":"mcm","clk":"11450265801","pt":1717319800979,"mc":[{"id":"1.229554919","rc":[{"atb":[[1.28,53.57],[1.24,0]],"id":46292327}],"con":true,"img":false}]}
{"op":"mcm","clk":"11450266072","pt":1717319803785,"mc":[{"id":"1.229554919","rc":[{"atb":[[1.23,34.12],[1.33,23.77]],"id":46292327},{"atb":[[2.86,4.21],[2.66,4.72]],"id":65788088}],"con":true,"img":false}]}
{"op":"mcm","clk":"11450266079","pt":1717319803889,"mc":[{"id":"1.229554919","rc":[{"atl":[[3,0],[3.05,7.32]],"id":65788088}],"con":true,"img":false}]}
{"op":"mcm","clk":"11450266706","pt":1717319810604,"mc":[{"id":"1.229554919","rc":[{"atb":[[1.24,62.5]],"id":46292327}],"con":true,"img":false}]}
{"op":"mcm","clk":"11450266714","pt":1717319810713,"mc":[{"id":"1.229554919","rc":[{"atb":[[1.28,0]],"id":46292327}],"con":true,"img":false}]}
{"op":"mcm","clk":"11450268471","pt":1717319831312,"mc":[{"id":"1.229554919","rc":[{"atb":[[1.28,53.57],[1.24,0]],"id":46292327}],"con":true,"img":false}]}
{"op":"mcm","clk":"11450269285","pt":1717319841055,"mc":[{"id":"1.229554919","rc":[{"atb":[[1.28,0],[1.24,62.5]],"id":46292327}],"con":true,"img":false}]}
{"op":"mcm","clk":"11450270914","pt":1717319861676,"mc":[{"id":"1.229554919","rc":[{"atb":[[1.28,53.57],[1.24,0]],"id":46292327}],"con":true,"img":false}]}
{"op":"mcm","clk":"11450271701","pt":1717319871365,"mc":[{"id":"1.229554919","rc":[{"atb":[[1.24,62.5]],"id":46292327}],"con":true,"img":false}]}
{"op":"mcm","clk":"11450271710","pt":1717319871478,"mc":[{"id":"1.229554919","rc":[{"atb":[[1.28,0]],"id":46292327}],"con":true,"img":false}]}
{"op":"mcm","clk":"11450273348","pt":1717319892127,"mc":[{"id":"1.229554919","rc":[{"atb":[[1.28,53.57],[1.24,0]],"id":46292327}],"con":true,"img":false}]}
{"op":"mcm","clk":"11450274020","pt":1717319900654,"mc":[{"id":"1.229554919","rc":[{"atb":[[1.28,0],[1.24,62.5]],"id":46292327}],"con":true,"img":false}]}
{"op":"mcm","clk":"11450275650","pt":1717319922504,"mc":[{"id":"1.229554919","rc":[{"atb":[[1.28,53.57],[1.24,0]],"id":46292327}],"con":true,"img":false}]}
{"op":"mcm","clk":"11450276431","pt":1717319932217,"mc":[{"id":"1.229554919","rc":[{"atb":[[1.28,0],[1.24,62.5]],"id":46292327}],"con":true,"img":false}]}
{"op":"mcm","clk":"11450278145","pt":1717319952933,"mc":[{"id":"1.229554919","rc":[{"atb":[[1.28,53.57],[1.24,0]],"id":46292327}],"con":true,"img":false}]}
{"op":"mcm","clk":"11450278897","pt":1717319962557,"mc":[{"id":"1.229554919","rc":[{"atb":[[1.24,62.5]],"id":46292327}],"con":true,"img":false}]}
{"op":"mcm","clk":"11450278900","pt":1717319962611,"mc":[{"id":"1.229554919","rc":[{"atb":[[1.28,0]],"id":46292327}],"con":true,"img":false}]}
{"op":"mcm","clk":"11450280515","pt":1717319983377,"mc":[{"id":"1.229554919","rc":[{"atb":[[1.28,53.57],[1.24,0]],"id":46292327}],"con":true,"img":false}]}
{"op":"mcm","clk":"11450281305","pt":1717319993392,"mc":[{"id":"1.229554919","rc":[{"atb":[[1.26,76.92]],"id":46292327}],"con":true,"img":false}]}
{"op":"mcm","clk":"11450281318","pt":1717319993499,"mc":[{"id":"1.229554919","rc":[{"atb":[[1.28,0],[1.24,62.5]],"id":46292327}],"con":true,"img":false}]}
{"op":"mcm","clk":"11450282166","pt":1717320003512,"mc":[{"id":"1.229554919","rc":[{"atb":[[1.18,166.67],[1.26,0]],"id":46292327}],"con":true,"img":false}]}
{"op":"mcm","clk":"11450282996","pt":1717320013512,"mc":[{"id":"1.229554919","rc":[{"atb":[[1.18,0]],"id":46292327}],"con":true,"img":false}]}
{"op":"mcm","clk":"11450283016","pt":1717320013817,"mc":[{"id":"1.229554919","rc":[{"atb":[[1.28,53.57],[1.24,0]],"id":46292327}],"con":true,"img":false}]}
{"op":"mcm","clk":"11450283722","pt":1717320023412,"mc":[{"id":"1.229554919","rc":[{"atb":[[1.28,0],[1.24,62.5]],"id":46292327}],"con":true,"img":false}]}
{"op":"mcm","clk":"11450285184","pt":1717320044248,"mc":[{"id":"1.229554919","rc":[{"atb":[[1.28,53.57],[1.24,0]],"id":46292327}],"con":true,"img":false}]}
{"op":"mcm","clk":"11450285775","pt":1717320054262,"mc":[{"id":"1.229554919","rc":[{"atb":[[1.26,76.92]],"id":46292327}],"con":true,"img":false}]}
{"op":"mcm","clk":"11450285783","pt":1717320054474,"mc":[{"id":"1.229554919","rc":[{"atb":[[1.28,0],[1.26,0],[1.24,62.5]],"id":46292327}],"con":true,"img":false}]}
{"op":"mcm","clk":"11450286165","pt":1717320060764,"mc":[{"id":"1.229554919","rc":[{"atb":[[1.28,53.57]],"id":46292327}],"con":true,"img":false}]}
{"op":"mcm","clk":"11450286171","pt":1717320060869,"mc":[{"id":"1.229554919","rc":[{"atb":[[1.24,0]],"id":46292327}],"con":true,"img":false}]}
{"op":"mcm","clk":"11450286517","pt":1717320066579,"mc":[{"id":"1.229554919","rc":[{"atb":[[1.28,0],[1.24,62.5]],"id":46292327}],"con":true,"img":false}]}
{"op":"mcm","clk":"11450286719","pt":1717320069570,"mc":[{"id":"1.229554919","rc":[{"atb":[[1.28,53.57]],"id":46292327}],"con":true,"img":false}]}
{"op":"mcm","clk":"11450286726","pt":1717320069670,"mc":[{"id":"1.229554919","rc":[{"atb":[[1.24,0]],"id":46292327}],"con":true,"img":false}]}
{"op":"mcm","clk":"11450287042","pt":1717320074287,"mc":[{"id":"1.229554919","rc":[{"atb":[[1.28,0],[1.24,62.5]],"id":46292327}],"con":true,"img":false}]}
{"op":"mcm","clk":"11450287060","pt":1717320074596,"mc":[{"id":"1.229554919","rc":[{"atb":[[1.28,53.57]],"id":46292327}],"con":true,"img":false}]}
{"op":"mcm","clk":"11450287066","pt":1717320074695,"mc":[{"id":"1.229554919","rc":[{"atb":[[1.24,0]],"id":46292327}],"con":true,"img":false}]}
{"op":"mcm","clk":"11450287476","pt":1717320079994,"mc":[{"id":"1.229554919","rc":[{"atb":[[1.28,0],[1.24,62.5]],"id":46292327}],"con":true,"img":false}]}
{"op":"mcm","clk":"11450288133","pt":1717320090113,"mc":[{"id":"1.229554919","rc":[{"atb":[[1.28,53.57],[1.24,0]],"id":46292327}],"con":true,"img":false}]}
{"op":"mcm","clk":"11450288429","pt":1717320094100,"mc":[{"id":"1.229554919","rc":[{"atb":[[1.24,62.5]],"id":46292327}],"con":true,"img":false}]}
{"op":"mcm","clk":"11450288434","pt":1717320094202,"mc":[{"id":"1.229554919","rc":[{"atb":[[1.28,0]],"id":46292327}],"con":true,"img":false}]}
{"op":"mcm","clk":"11450293008","pt":1717320161400,"mc":[{"id":"1.229554919","rc":[{"atb":[[1.28,53.57],[1.24,0]],"id":46292327}],"con":true,"img":false}]}
{"op":"mcm","clk":"11450293382","pt":1717320165900,"mc":[{"id":"1.229554919","rc":[{"atb":[[1.24,62.5]],"id":46292327}],"con":true,"img":false}]}
{"op":"mcm","clk":"11450293388","pt":1717320166010,"mc":[{"id":"1.229554919","rc":[{"atb":[[1.28,0]],"id":46292327}],"con":true,"img":false}]}
{"op":"mcm","clk":"11450293550","pt":1717320168300,"mc":[{"id":"1.229554919","rc":[{"atb":[[1.23,0],[1.33,0]],"id":46292327},{"atb":[[2.86,0],[2.66,0]],"id":65788088}],"con":true,"img":false}]}
{"op":"mcm","clk":"11450293638","pt":1717320170115,"mc":[{"id":"1.229554919","rc":[{"atl":[[3.05,0]],"id":65788088}],"con":true,"img":false}]}
{"op":"mcm","clk":"11450293651","pt":1717320170324,"mc":[{"id":"1.229554919","rc":[{"atl":[[3.05,7.32]],"id":65788088}],"con":true,"img":false}]}
{"op":"mcm","clk":"11450293663","pt":1717320170524,"mc":[{"id":"1.229554919","rc":[{"atl":[[3.05,0]],"id":65788088}],"con":true,"img":false}]}
{"op":"mcm","clk":"11450294303","pt":1717320180417,"mc":[{"id":"1.229554919","rc":[{"atl":[[3.2,9.09]],"id":65788088}],"con":true,"img":false}]}
{"op":"mcm","clk":"11450294715","pt":1717320186347,"mc":[{"id":"1.229554919","rc":[{"atb":[[1.23,34.12],[1.33,23.77]],"id":46292327},{"atb":[[2.86,4.21],[2.66,4.72]],"id":65788088}],"con":true,"img":false}]}
{"op":"mcm","clk":"11450297249","pt":1717320225104,"mc":[{"id":"1.229554919","rc":[{"atl":[[3.15,16.28]],"id":65788088}],"con":true,"img":false}]}
{"op":"mcm","clk":"11450297257","pt":1717320225212,"mc":[{"id":"1.229554919","rc":[{"atl":[[3.1,0],[3.15,6.97]],"id":65788088}],"con":true,"img":false}]}
{"op":"mcm","clk":"11450297885","pt":1717320235124,"mc":[{"id":"1.229554919","rc":[{"atl":[[3.25,20]],"id":65788088}],"con":true,"img":false}]}
{"op":"mcm","clk":"11450297894","pt":1717320235231,"mc":[{"id":"1.229554919","rc":[{"atl":[[3.25,8.89]],"id":65788088}],"con":true,"img":false}]}
{"op":"mcm","clk":"11450298542","pt":1717320245131,"mc":[{"id":"1.229554919","rc":[{"atl":[[3.35,10.64]],"id":65788088}],"con":true,"img":false}]}
{"op":"mcm","clk":"11450304756","pt":1717320340848,"mc":[{"id":"1.229554919","rc":[{"atb":[[1.28,53.57],[1.24,0]],"id":46292327}],"con":true,"img":false}]}
{"op":"mcm","clk":"11450305165","pt":1717320347456,"mc":[{"id":"1.229554919","rc":[{"atb":[[1.28,0],[1.24,62.5]],"id":46292327}],"con":true,"img":false}]}
{"op":"mcm","clk":"11450307997","pt":1717320398295,"mc":[{"id":"1.229554919","rc":[{"atb":[[1.27,55.56],[1.24,0]],"id":46292327}],"con":true,"img":false}]}
{"op":"mcm","clk":"11450308010","pt":1717320398497,"mc":[{"id":"1.229554919","rc":[{"atb":[[1.27,0]],"id":46292327}],"con":true,"img":false}]}
{"op":"mcm","clk":"11450308291","pt":1717320402736,"mc":[{"id":"1.229554919","rc":[{"atb":[[1.2,0],[1.21,0],[1.22,0]],"id":46292327}],"con":true,"img":false}]}
{"op":"mcm","clk":"11450308341","pt":1717320403323,"mc":[{"id":"1.229554919","rc":[{"atb":[[1.2,125],[1.18,166.67],[1.22,90.91],[1.24,62.5]],"id":46292327}],"con":true,"img":false}]}
{"op":"mcm","clk":"11450308377","pt":1717320403830,"mc":[{"id":"1.229554919","rc":[{"atb":[[1.24,0]],"id":46292327}],"con":true,"img":false}]}
{"op":"mcm","clk":"11450308724","pt":1717320409533,"mc":[{"id":"1.229554919","rc":[{"atb":[[1.24,62.5]],"id":46292327}],"con":true,"img":false}]}
{"op":"mcm","clk":"11450309751","pt":1717320425792,"mc":[{"id":"1.229554919","rc":[{"atb":[[1.24,0]],"id":46292327}],"con":true,"img":false}]}
{"op":"mcm","clk":"11450310364","pt":1717320434206,"mc":[{"id":"1.229554919","rc":[{"atb":[[1.24,62.5]],"id":46292327}],"con":true,"img":false}]}
{"op":"mcm","clk":"11450310672","pt":1717320439412,"mc":[{"id":"1.229554919","rc":[{"atb":[[1.2,0],[1.18,0],[1.22,0],[1.24,0]],"id":46292327}],"con":true,"img":false}]}
{"op":"mcm","clk":"11450310711","pt":1717320439930,"mc":[{"id":"1.229554919","rc":[{"atb":[[1.2,125],[1.18,166.67],[1.22,90.91],[1.24,62.5]],"id":46292327}],"con":true,"img":false}]}
{"op":"mcm","clk":"11450311362","pt":1717320449014,"mc":[{"id":"1.229554919","rc":[{"atl":[[4.2,4.69]],"id":46292327}],"con":true,"img":false}]}
{"op":"mcm","clk":"11450311365","pt":1717320449117,"mc":[{"id":"1.229554919","rc":[{"atl":[[4.3,0]],"id":46292327}],"con":true,"img":false}]}
{"op":"mcm","clk":"11450311369","pt":1717320449222,"mc":[{"id":"1.229554919","rc":[{"atl":[[4.5,0],[4.9,0],[4.7,0]],"id":46292327}],"con":true,"img":false}]}
{"op":"mcm","clk":"11450311375","pt":1717320449324,"mc":[{"id":"1.229554919","rc":[{"atl":[[16.5,6.45]],"id":46292327}],"con":true,"img":false}]}
{"op":"mcm","clk":"11450311381","pt":1717320449429,"mc":[{"id":"1.229554919","rc":[{"atl":[[5.3,0]],"id":46292327}],"con":true,"img":false}]}
{"op":"mcm","clk":"11450311987","pt":1717320459060,"mc":[{"id":"1.229554919","rc":[{"atl":[[4.4,5.88]],"id":46292327}],"con":true,"img":false}]}
{"op":"mcm","clk":"11450312275","pt":1717320464242,"mc":[{"id":"1.229554919","rc":[{"atb":[[1.2,0],[1.18,0],[1.22,0],[1.24,0]],"id":46292327}],"con":true,"img":false}]}
{"op":"mcm","clk":"11450312580","pt":1717320469055,"mc":[{"id":"1.229554919","rc":[{"atl":[[4.6,6.94]],"id":46292327}],"con":true,"img":false}]}
{"op":"mcm","clk":"11450312587","pt":1717320469162,"mc":[{"id":"1.229554919","rc":[{"atl":[[5.3,10.57]],"id":46292327}],"con":true,"img":false}]}
{"op":"mcm","clk":"11450312595","pt":1717320469262,"mc":[{"id":"1.229554919","rc":[{"atl":[[16.5,0]],"id":46292327}],"con":true,"img":false}]}
{"op":"mcm","clk":"11450312650","pt":1717320470259,"mc":[{"id":"1.229554919","rc":[{"atb":[[1.2,125],[1.18,166.67],[1.22,90.91],[1.24,62.5]],"id":46292327}],"con":true,"img":false}]}
{"op":"mcm","clk":"11450312714","pt":1717320471247,"mc":[{"id":"1.229554919","rc":[{"atb":[[1.22,0],[1.24,0]],"id":46292327}],"con":true,"img":false}]}
{"op":"mcm","clk":"11450312813","pt":1717320472954,"mc":[{"id":"1.229554919","rc":[{"atb":[[1.2,0],[1.18,0]],"id":46292327}],"con":true,"img":false}]}
{"op":"mcm","clk":"11450313197","pt":1717320480170,"mc":[{"id":"1.229554919","rc":[{"atl":[[4.8,7.89]],"id":46292327}],"con":true,"img":false}]}
{"op":"mcm","clk":"11450313973","pt":1717320493979,"mc":[{"id":"1.229554919","rc":[{"atb":[[1.23,0],[1.33,0]],"id":46292327},{"atb":[[2.86,0],[2.66,0]],"id":65788088}],"con":true,"img":false}]}
{"op":"mcm","clk":"11450314020","pt":1717320494756,"mc":[{"id":"1.229554919","rc":[{"atb":[[1.18,83.33],[1.12,250],[1.16,125],[1.14,178.57]],"id":46292327},{"atb":[[1.33,0],[1.34,44.12]],"id":65788088}],"con":true,"img":false}]}
{"op":"mcm","clk":"11450314626","pt":1717320504778,"mc":[{"id":"1.229554919","rc":[{"atb":[[1.32,62.5]],"id":65788088}],"con":true,"img":false}]}
{"op":"mcm","clk":"11450314837","pt":1717320507878,"mc":[{"id":"1.229554919","rc":[{"atb":[[1.26,0]],"id":65788088}],"con":true,"img":false}]}
{"op":"mcm","clk":"11450315165","pt":1717320512492,"mc":[{"id":"1.229554919","rc":[{"atb":[[1.19,41.3],[1.29,27.05]],"id":46292327},{"atb":[[2.74,4.5],[2.94,4.04]],"id":65788088}],"con":true,"img":false}]}
{"op":"mcm","clk":"11450323775","pt":1717320536771,"mc":[{"id":"1.229554919","rc":[{"atl":[[3.2,6.82],[3.15,0]],"id":65788088}],"con":true,"img":false}]}
{"op":"mcm","clk":"11450323980","pt":1717320539715,"mc":[{"id":"1.229554919","rc":[{"atl":[[3.15,6.98]],"id":65788088}],"con":true,"img":false}]}
{"op":"mcm","clk":"11450324176","pt":1717320542159,"mc":[{"id":"1.229554919","rc":[{"atl":[[3.15,0],[3.25,6.67]],"id":65788088}],"con":true,"img":false}]}
{"op":"mcm","clk":"11450324193","pt":1717320542359,"mc":[{"id":"1.229554919","rc":[{"atl":[[5.1,12.82],[5.3,0]],"id":46292327},{"atl":[[3.2,0],[3.4,6.25],[3.5,6]],"id":65788088}],"con":true,"img":false}]}
{"op":"mcm","clk":"11450324210","pt":1717320542551,"mc":[{"id":"1.229554919","rc":[{"atl":[[3.25,0]],"id":65788088}],"con":true,"img":false}]}
{"op":"mcm","clk":"11450324301","pt":1717320543637,"mc":[{"id":"1.229554919","rc":[{"atl":[[3.2,6.82],[3.35,0]],"id":65788088}],"con":true,"img":false}]}
{"op":"mcm","clk":"11450324312","pt":1717320543743,"mc":[{"id":"1.229554919","rc":[{"atl":[[3.25,6.67]],"id":65788088}],"con":true,"img":false}]}
{"op":"mcm","clk":"11450324765","pt":1717320549444,"mc":[{"id":"1.229554919","rc":[{"atl":[[3.2,0]],"id":65788088}],"con":true,"img":false}]}
{"op":"mcm","clk":"11450324796","pt":1717320549758,"mc":[{"id":"1.229554919","rc":[{"atl":[[3.25,0]],"id":65788088}],"con":true,"img":false}]}
{"op":"mcm","clk":"11450324804","pt":1717320549861,"mc":[{"id":"1.229554919","rc":[{"atb":[[1.19,0],[1.29,0]],"id":46292327},{"atb":[[2.74,0],[2.94,0]],"id":65788088}],"con":true,"img":false}]}
{"op":"mcm","clk":"11450324835","pt":1717320550222,"mc":[{"id":"1.229554919","rc":[{"atl":[[3.2,6.82],[3.4,0]],"id":65788088}],"con":true,"img":false}]}
{"op":"mcm","clk":"11450325363","pt":1717320556564,"mc":[{"id":"1.229554919","rc":[{"atb":[[1.33,45.45],[1.34,0]],"id":65788088}],"con":true,"img":false}]}
{"op":"mcm","clk":"11450325724","pt":1717320560969,"mc":[{"id":"1.229554919","rc":[{"atl":[[3.2,0],[3.3,6.52]],"id":65788088}],"con":true,"img":false}]}
{"op":"mcm","clk":"11450326232","pt":1717320567665,"mc":[{"id":"1.229554919","rc":[{"atb":[[1.19,41.3],[1.29,27.05]],"id":46292327},{"atb":[[2.74,4.5],[2.94,4.04]],"id":65788088}],"con":true,"img":false}]}
{"op":"mcm","clk":"11450326389","pt":1717320569584,"mc":[{"id":"1.229554919","rc":[{"atl":[[3.35,6.38],[3.3,0]],"id":65788088}],"con":true,"img":false}]}
{"op":"mcm","clk":"11450326475","pt":1717320570771,"mc":[{"id":"1.229554919","rc":[{"atl":[[4.1,4.84],[4.2,0]],"id":46292327},{"atl":[[3.35,0]],"id":65788088}],"con":true,"img":false}]}
{"op":"mcm","clk":"11450326483","pt":1717320570873,"mc":[{"id":"1.229554919","rc":[{"atl":[[27,3.85]],"id":65788088}],"con":true,"img":false}]}
{"op":"mcm","clk":"11450326491","pt":1717320570971,"mc":[{"id":"1.229554919","rc":[{"atl":[[7,0]],"id":65788088}],"con":true,"img":false}]}
{"op":"mcm","clk":"11450327013","pt":1717320578574,"mc":[{"id":"1.229554919","rc":[{"atl":[[4.1,0],[4.2,4.69]],"id":46292327}],"con":true,"img":false}]}
{"op":"mcm","clk":"11450327098","pt":1717320579571,"mc":[{"id":"1.229554919","rc":[{"atl":[[3.6,7.69]],"id":65788088}],"con":true,"img":false}]}
{"op":"mcm","clk":"11450327811","pt":1717320589596,"mc":[{"id":"1.229554919","rc":[{"atl":[[3.7,9.26]],"id":65788088}],"con":true,"img":false}]}
{"op":"mcm","clk":"11450327818","pt":1717320589721,"mc":[{"id":"1.229554919","rc":[{"atl":[[7.4,13.69]],"id":65788088}],"con":true,"img":false}]}
{"op":"mcm","clk":"11450327827","pt":1717320589802,"mc":[{"id":"1.229554919","rc":[{"atl":[[27,0]],"id":65788088}],"con":true,"img":false}]}
{"op":"mcm","clk":"11450328501","pt":1717320599615,"mc":[{"id":"1.229554919","rc":[{"atl":[[3.8,10.71],[3.65,5.66]],"id":65788088}],"con":true,"img":false}]}
{"op":"mcm","clk":"11450328509","pt":1717320599720,"mc":[{"id":"1.229554919","rc":[{"atl":[[3.5,0]],"id":65788088}],"con":true,"img":false}]}
{"op":"mcm","clk":"11450328959","pt":1717320604759,"mc":[{"id":"1.229554919","rc":[{"atl":[[3.6,0]],"id":65788088}],"con":true,"img":false}]}
{"op":"mcm","clk":"11450328976","pt":1717320604967,"mc":[{"id":"1.229554919","rc":[{"atb":[[1.19,0],[1.29,0]],"id":46292327},{"atb":[[2.74,0],[2.94,0]],"id":65788088}],"con":true,"img":false}]}
{"op":"mcm","clk":"11450329089","pt":1717320606139,"mc":[{"id":"1.229554919","rc":[{"atb":[[1.33,0],[1.34,44.12]],"id":65788088}],"con":true,"img":false}]}
{"op":"mcm","clk":"11450329793","pt":1717320615976,"mc":[{"id":"1.229554919","rc":[{"atl":[[3.75,7.27]],"id":65788088}],"con":true,"img":false}]}
{"op":"mcm","clk":"11450330398","pt":1717320623597,"mc":[{"id":"1.229554919","rc":[{"atb":[[1.23,34.12],[1.13,60.36]],"id":46292327},{"atb":[[3.35,3.33],[2.94,4.04]],"id":65788088}],"con":true,"img":false}]}
{"op":"mcm","clk":"11450333309","pt":1717320660743,"mc":[{"id":"1.229554919","rc":[{"atb":[[1.23,0],[1.13,0]],"id":46292327},{"atb":[[3.35,0],[2.94,0]],"id":65788088}],"con":true,"img":false}]}
{"op":"mcm","clk":"11450334351","pt":1717320673955,"mc":[{"id":"1.229554919","rc":[{"atb":[[1.21,37.37],[1.11,71.34]],"id":46292327},{"atb":[[3.45,3.2],[2.98,3.96]],"id":65788088}],"con":true,"img":false}]}
{"op":"mcm","clk":"11450343102","pt":1717320781447,"mc":[{"id":"1.229554919","rc":[{"atb":[[1.18,0],[1.2,75]],"id":46292327},{"atl":[[3.6,5.77],[3.65,0]],"id":65788088}],"con":true,"img":false}]}
{"op":"mcm","clk":"11450343340","pt":1717320784260,"mc":[{"id":"1.229554919","rc":[{"atb":[[1.2,0],[1.19,78.95]],"id":46292327}],"con":true,"img":false}]}
{"op":"mcm","clk":"11450346022","pt":1717320818109,"mc":[{"id":"1.229554919","rc":[{"atl":[[3.6,0],[3.7,5.56]],"id":65788088}],"con":true,"img":false}]}
{"op":"mcm","clk":"11450346819","pt":1717320828093,"mc":[{"id":"1.229554919","rc":[{"atl":[[3.8,7.14]],"id":65788088}],"con":true,"img":false}]}
{"op":"mcm","clk":"11450347666","pt":1717320838115,"mc":[{"id":"1.229554919","rc":[{"atl":[[3.9,8.62]],"id":65788088}],"con":true,"img":false}]}
{"op":"mcm","clk":"11450347765","pt":1717320839108,"mc":[{"id":"1.229554919","rc":[{"atl":[[3.7,0],[3.8,5.36]],"id":65788088}],"con":true,"img":false}]}
{"op":"mcm","clk":"11450348394","pt":1717320845631,"mc":[{"id":"1.229554919","rc":[{"atl":[[3.75,0]],"id":65788088}],"con":true,"img":false}]}
{"op":"mcm","clk":"11450348712","pt":1717320849114,"mc":[{"id":"1.229554919","rc":[{"atl":[[3.9,6.9]],"id":65788088}],"con":true,"img":false}]}
{"op":"mcm","clk":"11450349613","pt":1717320859091,"mc":[{"id":"1.229554919","rc":[{"atl":[[4,8.33]],"id":65788088}],"con":true,"img":false}]}
{"op":"mcm","clk":"11450350455","pt":1717320869113,"mc":[{"id":"1.229554919","rc":[{"atl":[[4.2,9.38]],"id":65788088}],"con":true,"img":false}]}
{"op":"mcm","clk":"11450357580","pt":1717320955095,"mc":[{"id":"1.229554919","rc":[{"atl":[[4.1,4.84],[4.2,0]],"id":46292327}],"con":true,"img":false}]}
{"op":"mcm","clk":"11450358676","pt":1717320968414,"mc":[{"id":"1.229554919","rc":[{"atl":[[4.1,0],[4.2,4.69]],"id":46292327}],"con":true,"img":false}]}
{"op":"mcm","clk":"11450359516","pt":1717320979327,"mc":[{"id":"1.229554919","rc":[{"atl":[[3.8,0],[3.75,5.45]],"id":65788088}],"con":true,"img":false}]}
{"op":"mcm","clk":"11450360410","pt":1717320990650,"mc":[{"id":"1.229554919","rc":[{"atb":[[1.21,0],[1.11,0]],"id":46292327},{"atb":[[3.45,0],[2.98,0]],"id":65788088}],"con":true,"img":false}]}
{"op":"mcm","clk":"11450362078","pt":1717321011721,"mc":[{"id":"1.229554919","rc":[{"atb":[[1.21,37.37],[1.11,71.34]],"id":46292327},{"atb":[[3.45,3.2],[2.98,3.96]],"id":65788088}],"con":true,"img":false}]}
{"op":"mcm","clk":"11450362168","pt":1717321012813,"mc":[{"id":"1.229554919","rc":[{"atl":[[3.8,5.36],[3.75,0]],"id":65788088}],"con":true,"img":false}]}
{"op":"mcm","clk":"11450362685","pt":1717321019075,"mc":[{"id":"1.229554919","rc":[{"atl":[[3.8,0],[3.75,5.45]],"id":65788088}],"con":true,"img":false}]}
{"op":"mcm","clk":"11450364395","pt":1717321039930,"mc":[{"id":"1.229554919","rc":[{"atl":[[3.8,5.36],[3.75,0]],"id":65788088}],"con":true,"img":false}]}
{"op":"mcm","clk":"11450364697","pt":1717321044348,"mc":[{"id":"1.229554919","rc":[{"atb":[[1.2,75],[1.19,0]],"id":46292327}],"con":true,"img":false}]}
{"op":"mcm","clk":"11450365078","pt":1717321049432,"mc":[{"id":"1.229554919","rc":[{"atl":[[3.8,0],[3.75,5.45]],"id":65788088}],"con":true,"img":false}]}
{"op":"mcm","clk":"11450365440","pt":1717321054343,"mc":[{"id":"1.229554919","rc":[{"atb":[[1.18,111.11]],"id":46292327}],"con":true,"img":false}]}
{"op":"mcm","clk":"11450365596","pt":1717321056566,"mc":[{"id":"1.229554919","rc":[{"atb":[[1.2,0],[1.12,0],[1.24,62.5]],"id":46292327}],"con":true,"img":false}]}
{"op":"mcm","clk":"11450365751","pt":1717321058855,"mc":[{"id":"1.229554919","rc":[{"atb":[[1.2,75],[1.24,0]],"id":46292327}],"con":true,"img":false}]}
{"op":"mcm","clk":"11450366178","pt":1717321064449,"mc":[{"id":"1.229554919","rc":[{"atb":[[1.24,62.5]],"id":46292327}],"con":true,"img":false}]}
{"op":"mcm","clk":"11450366183","pt":1717321064559,"mc":[{"id":"1.229554919","rc":[{"atb":[[1.2,0]],"id":46292327}],"con":true,"img":false}]}
{"op":"mcm","clk":"11450366846","pt":1717321074485,"mc":[{"id":"1.229554919","rc":[{"atb":[[1.22,90.91]],"id":46292327}],"con":true,"img":false}]}
{"op":"mcm","clk":"11450366990","pt":1717321076766,"mc":[{"id":"1.229554919","rc":[{"atb":[[1.14,0]],"id":46292327}],"con":true,"img":false}]}
{"op":"mcm","clk":"11450367200","pt":1717321080297,"mc":[{"id":"1.229554919","rc":[{"atl":[[3.8,5.36],[3.75,0]],"id":65788088}],"con":true,"img":false}]}
{"op":"mcm","clk":"11450367308","pt":1717321081694,"mc":[{"id":"1.229554919","rc":[{"atb":[[1.2,75],[1.24,0]],"id":46292327}],"con":true,"img":false}]}
{"op":"mcm","clk":"11450367331","pt":1717321082012,"mc":[{"id":"1.229554919","rc":[{"atb":[[1.22,0],[1.24,62.5]],"id":46292327}],"con":true,"img":false}]}
{"op":"mcm","clk":"11450367853","pt":1717321089489,"mc":[{"id":"1.229554919","rc":[{"atl":[[3.8,0],[3.75,5.45]],"id":65788088}],"con":true,"img":false}]}
{"op":"mcm","clk":"11450368020","pt":1717321091998,"mc":[{"id":"1.229554919","rc":[{"atb":[[1.22,90.91]],"id":46292327}],"con":true,"img":false}]}
{"op":"mcm","clk":"11450368098","pt":1717321093087,"mc":[{"id":"1.229554919","rc":[{"atb":[[1.16,0],[1.22,0],[1.24,0]],"id":46292327}],"con":true,"img":false}]}
{"op":"mcm","clk":"11450368633","pt":1717321100524,"mc":[{"id":"1.229554919","rc":[{"atb":[[1.23,65.22]],"id":46292327}],"con":true,"img":false}]}
{"op":"mcm","clk":"11450368824","pt":1717321103218,"mc":[{"id":"1.229554919","rc":[{"atb":[[1.19,78.95],[1.23,0]],"id":46292327}],"con":true,"img":false}]}
{"op":"mcm","clk":"11450368901","pt":1717321104407,"mc":[{"id":"1.229554919","rc":[{"atb":[[1.23,65.22]],"id":46292327}],"con":true,"img":false}]}
{"op":"mcm","clk":"11450369589","pt":1717321114638,"mc":[{"id":"1.229554919","rc":[{"atb":[[1.23,0]],"id":46292327}],"con":true,"img":false}]}
{"op":"mcm","clk":"11450369657","pt":1717321115835,"mc":[{"id":"1.229554919","rc":[{"atb":[[1.23,65.22]],"id":46292327}],"con":true,"img":false}]}
{"op":"mcm","clk":"11450369938","pt":1717321120339,"mc":[{"id":"1.229554919","rc":[{"atl":[[3.8,5.36],[3.75,0]],"id":65788088}],"con":true,"img":false}]}
{"op":"mcm","clk":"11450370391","pt":1717321127234,"mc":[{"id":"1.229554919","rc":[{"atb":[[1.23,0]],"id":46292327}],"con":true,"img":false}]}
{"op":"mcm","clk":"11450370508","pt":1717321128626,"mc":[{"id":"1.229554919","rc":[{"atb":[[1.23,65.22]],"id":46292327}],"con":true,"img":false}]}
{"op":"mcm","clk":"11450370573","pt":1717321129550,"mc":[{"id":"1.229554919","rc":[{"atl":[[3.75,5.45]],"id":65788088}],"con":true,"img":false}]}
{"op":"mcm","clk":"11450370581","pt":1717321129654,"mc":[{"id":"1.229554919","rc":[{"atl":[[4,0],[3.8,0],[3.9,0],[4.2,0]],"id":65788088}],"con":true,"img":false}]}
{"op":"mcm","clk":"11450370583","pt":1717321129756,"mc":[{"id":"1.229554919","rc":[{"atl":[[7.4,0],[28,3.7]],"id":65788088}],"con":true,"img":false}]}
{"op":"mcm","clk":"11450370981","pt":1717321135849,"mc":[{"id":"1.229554919","rc":[{"atb":[[1.23,0]],"id":46292327}],"con":true,"img":false}]}
{"op":"mcm","clk":"11450371123","pt":1717321137767,"mc":[{"id":"1.229554919","rc":[{"atb":[[1.2,0]],"id":46292327}],"con":true,"img":false}]}
{"op":"mcm","clk":"11450371196","pt":1717321138647,"mc":[{"id":"1.229554919","rc":[{"atb":[[1.17,117.65]],"id":46292327}],"con":true,"img":false}]}
{"op":"mcm","clk":"11450371265","pt":1717321139572,"mc":[{"id":"1.229554919","rc":[{"atl":[[3.85,7.02]],"id":65788088}],"con":true,"img":false}]}
{"op":"mcm","clk":"11450371935","pt":1717321148637,"mc":[{"id":"1.229554919","rc":[{"atb":[[1.15,166.67]],"id":46292327}],"con":true,"img":false}]}
{"op":"mcm","clk":"11450372002","pt":1717321149575,"mc":[{"id":"1.229554919","rc":[{"atl":[[3.95,8.47]],"id":65788088}],"con":true,"img":false}]}
{"op":"mcm","clk":"11450372011","pt":1717321149677,"mc":[{"id":"1.229554919","rc":[{"atl":[[7.6,14.04]],"id":65788088}],"con":true,"img":false}]}
{"op":"mcm","clk":"11450372019","pt":1717321149779,"mc":[{"id":"1.229554919","rc":[{"atl":[[28,0]],"id":65788088}],"con":true,"img":false}]}
{"op":"mcm","clk":"11450372143","pt":1717321151905,"mc":[{"id":"1.229554919","rc":[{"atl":[[4.1,4.84],[4.2,0]],"id":46292327}],"con":true,"img":false}]}
{"op":"mcm","clk":"11450372693","pt":1717321159552,"mc":[{"id":"1.229554919","rc":[{"atl":[[4.1,9.68]],"id":65788088}],"con":true,"img":false}]}
{"op":"mcm","clk":"11450372713","pt":1717321159864,"mc":[{"id":"1.229554919","rc":[{"atl":[[3.8,5.36],[3.75,0]],"id":65788088}],"con":true,"img":false}]}
{"op":"mcm","clk":"11450373416","pt":1717321170092,"mc":[{"id":"1.229554919","rc":[{"atl":[[3.8,0],[3.75,5.45]],"id":65788088}],"con":true,"img":false}]}
{"op":"mcm","clk":"11450375302","pt":1717321200875,"mc":[{"id":"1.229554919","rc":[{"atl":[[3.8,5.36]],"id":65788088}],"con":true,"img":false}]}
{"op":"mcm","clk":"11450375310","pt":1717321200982,"mc":[{"id":"1.229554919","rc":[{"atl":[[3.75,0]],"id":65788088}],"con":true,"img":false}]}
{"op":"mcm","clk":"11450375933","pt":1717321212471,"mc":[{"id":"1.229554919","rc":[{"atb":[[1.2,75],[1.19,0]],"id":46292327}],"con":true,"img":false}]}
{"op":"mcm","clk":"11450375961","pt":1717321212988,"mc":[{"id":"1.229554919","rc":[{"atl":[[3.75,5.45]],"id":65788088}],"con":true,"img":false}]}
{"op":"mcm","clk":"11450375967","pt":1717321213092,"mc":[{"id":"1.229554919","rc":[{"atl":[[3.8,0]],"id":65788088}],"con":true,"img":false}]}
{"op":"mcm","clk":"11450376998","pt":1717321229824,"mc":[{"id":"1.229554919","rc":[{"atb":[[1.2,0],[1.19,78.95]],"id":46292327}],"con":true,"img":false}]}
{"op":"mcm","clk":"11450378076","pt":1717321248124,"mc":[{"id":"1.229554919","rc":[{"atl":[[3.8,5.36]],"id":65788088}],"con":true,"img":false}]}
{"op":"mcm","clk":"11450378079","pt":1717321248227,"mc":[{"id":"1.229554919","rc":[{"atl":[[3.75,0]],"id":65788088}],"con":true,"img":false}]}
{"op":"mcm","clk":"11450379813","pt":1717321274732,"mc":[{"id":"1.229554919","rc":[{"atl":[[3.75,5.45]],"id":65788088}],"con":true,"img":false}]}
{"op":"mcm","clk":"11450379822","pt":1717321274837,"mc":[{"id":"1.229554919","rc":[{"atl":[[3.8,0]],"id":65788088}],"con":true,"img":false}]}
{"op":"mcm","clk":"11450380246","pt":1717321281225,"mc":[{"id":"1.229554919","rc":[{"atl":[[3.85,12.28]],"id":65788088}],"con":true,"img":false}]}
{"op":"mcm","clk":"11450380251","pt":1717321281328,"mc":[{"id":"1.229554919","rc":[{"atl":[[3.85,5.26],[3.75,0]],"id":65788088}],"con":true,"img":false}]}
{"op":"mcm","clk":"11450380931","pt":1717321291283,"mc":[{"id":"1.229554919","rc":[{"atl":[[3.95,15.25]],"id":65788088}],"con":true,"img":false}]}
{"op":"mcm","clk":"11450380935","pt":1717321291391,"mc":[{"id":"1.229554919","rc":[{"atl":[[3.95,6.77]],"id":65788088}],"con":true,"img":false}]}
{"op":"mcm","clk":"11450381553","pt":1717321301273,"mc":[{"id":"1.229554919","rc":[{"atl":[[4.1,17.74]],"id":65788088}],"con":true,"img":false}]}
{"op":"mcm","clk":"11450381560","pt":1717321301380,"mc":[{"id":"1.229554919","rc":[{"atl":[[4.1,8.06]],"id":65788088}],"con":true,"img":false}]}
{"op":"mcm","clk":"11450381666","pt":1717321302986,"mc":[{"id":"1.229554919","rc":[{"atl":[[3.75,5.45]],"id":65788088}],"con":true,"img":false}]}
{"op":"mcm","clk":"11450382295","pt":1717321314219,"mc":[{"id":"1.229554919","rc":[{"atb":[[1.21,0],[1.11,0]],"id":46292327},{"atb":[[3.45,0],[2.98,0]],"id":65788088}],"con":true,"img":false}]}
{"op":"mcm","clk":"11450382471","pt":1717321317085,"mc":[{"id":"1.229554919","rc":[{"atb":[[1.34,0],[1.35,42.86]],"id":65788088}],"con":true,"img":false}]}
{"op":"mcm","clk":"11450383466","pt":1717321332960,"mc":[{"id":"1.229554919","rc":[{"atb":[[1.21,37.37],[1.11,71.34]],"id":46292327},{"atb":[[3.45,3.2],[2.98,3.96]],"id":65788088}],"con":true,"img":false}]}
{"op":"mcm","clk":"11450384332","pt":1717321347682,"mc":[{"id":"1.229554919","rc":[{"atb":[[1.19,0],[1.23,65.22]],"id":46292327}],"con":true,"img":false}]}
{"op":"mcm","clk":"11450384948","pt":1717321357690,"mc":[{"id":"1.229554919","rc":[{"atb":[[1.21,132.61]],"id":46292327}],"con":true,"img":false}]}
{"op":"mcm","clk":"11450385090","pt":1717321360298,"mc":[{"id":"1.229554919","rc":[{"atb":[[1.15,0]],"id":46292327}],"con":true,"img":false}]}
{"op":"mcm","clk":"11450385313","pt":1717321364398,"mc":[{"id":"1.229554919","rc":[{"atb":[[1.19,78.95],[1.23,0]],"id":46292327}],"con":true,"img":false}]}
{"op":"mcm","clk":"11450385341","pt":1717321364816,"mc":[{"id":"1.229554919","rc":[{"atb":[[1.23,65.22]],"id":46292327}],"con":true,"img":false}]}
{"op":"mcm","clk":"11450385349","pt":1717321364877,"mc":[{"id":"1.229554919","rc":[{"atb":[[1.21,37.37]],"id":46292327}],"con":true,"img":false}]}
{"op":"mcm","clk":"11450385372","pt":1717321365488,"mc":[{"id":"1.229554919","rc":[{"atb":[[1.23,0]],"id":46292327}],"con":true,"img":false}]}
{"op":"mcm","clk":"11450385657","pt":1717321369892,"mc":[{"id":"1.229554919","rc":[{"atb":[[1.23,65.22]],"id":46292327}],"con":true,"img":false}]}
{"op":"mcm","clk":"11450385745","pt":1717321371289,"mc":[{"id":"1.229554919","rc":[{"atb":[[1.23,0]],"id":46292327}],"con":true,"img":false}]}
{"op":"mcm","clk":"11450385940","pt":1717321374604,"mc":[{"id":"1.229554919","rc":[{"atb":[[1.2,75]],"id":46292327}],"con":true,"img":false}]}
{"op":"mcm","clk":"11450387771","pt":1717321402933,"mc":[{"id":"1.229554919","rc":[{"atb":[[1.2,0]],"id":46292327}],"con":true,"img":false}]}
{"op":"mcm","clk":"11450388361","pt":1717321412938,"mc":[{"id":"1.229554919","rc":[{"atb":[[1.15,166.67]],"id":46292327}],"con":true,"img":false}]}
{"op":"mcm","clk":"11450392057","pt":1717321473918,"mc":[{"id":"1.229554919","rc":[{"atb":[[1.23,65.22]],"id":46292327}],"con":true,"img":false}]}
{"op":"mcm","clk":"11450392065","pt":1717321474020,"mc":[{"id":"1.229554919","rc":[{"atb":[[1.19,0]],"id":46292327}],"con":true,"img":false}]}
{"op":"mcm","clk":"11450392140","pt":1717321475428,"mc":[{"id":"1.229554919","rc":[{"atb":[[1.19,78.95],[1.23,0]],"id":46292327}],"con":true,"img":false}]}
{"op":"mcm","clk":"11450398711","pt":1717321570909,"mc":[{"id":"1.229554919","rc":[{"atl":[[3.75,0]],"id":65788088}],"con":true,"img":false}]}
{"op":"mcm","clk":"11450399345","pt":1717321579048,"mc":[{"id":"1.229554919","rc":[{"atl":[[4.3,9.09]],"id":65788088}],"con":true,"img":false}]}
{"op":"mcm","clk":"11450399483","pt":1717321580869,"mc":[{"id":"1.229554919","rc":[{"atl":[[3.85,0],[4.1,4.84]],"id":65788088}],"con":true,"img":false}]}
{"op":"mcm","clk":"11450399492","pt":1717321580972,"mc":[{"id":"1.229554919","rc":[{"atl":[[3.75,5.45]],"id":65788088}],"con":true,"img":false}]}
{"op":"mcm","clk":"11450400184","pt":1717321590987,"mc":[{"id":"1.229554919","rc":[{"atl":[[3.85,7.02]],"id":65788088}],"con":true,"img":false}]}
{"op":"mcm","clk":"11450400331","pt":1717321592801,"mc":[{"id":"1.229554919","rc":[{"atl":[[4.3,0]],"id":65788088}],"con":true,"img":false}]}
{"op":"mcm","clk":"11450402129","pt":1717321617339,"mc":[{"id":"1.229554919","rc":[{"atl":[[3.8,5.36],[3.75,0]],"id":65788088}],"con":true,"img":false}]}
{"op":"mcm","clk":"11450402163","pt":1717321617918,"mc":[{"id":"1.229554919","rc":[{"atl":[[3.8,0],[3.75,5.45]],"id":65788088}],"con":true,"img":false}]}
{"op":"mcm","clk":"11450404643","pt":1717321651068,"mc":[{"id":"1.229554919","rc":[{"atb":[[1.19,0],[1.24,62.5]],"id":46292327}],"con":true,"img":false}]}
{"op":"mcm","clk":"11450405231","pt":1717321659388,"mc":[{"id":"1.229554919","rc":[{"atb":[[1.23,65.22],[1.24,0]],"id":46292327}],"con":true,"img":false}]}
{"op":"mcm","clk":"11450405414","pt":1717321661612,"mc":[{"id":"1.229554919","rc":[{"atb":[[1.23,0],[1.24,62.5]],"id":46292327}],"con":true,"img":false}]}
{"op":"mcm","clk":"11450405499","pt":1717321662809,"mc":[{"id":"1.229554919","rc":[{"atb":[[1.23,65.22],[1.24,0]],"id":46292327}],"con":true,"img":false}]}
{"op":"mcm","clk":"11450405551","pt":1717321663327,"mc":[{"id":"1.229554919","rc":[{"atb":[[1.31,10]],"id":46292327},{"atl":[[4.1,0],[3.7,10],[3.9,5.17]],"id":46292327},{"atb":[[1.35,52.86]],"id":65788088},{"atl":[[3.95,16.78]],"id":65788088}],"con":true,"img":false}]}
{"op":"mcm","clk":"11450405558","pt":1717321663391,"mc":[{"id":"1.229554919","rc":[{"atb":[[1.23,0],[1.24,62.5]],"id":46292327}],"con":true,"img":false}]}
{"op":"mcm","clk":"11450405578","pt":1717321663741,"mc":[{"id":"1.229554919","rc":[{"atb":[[1.2,75],[1.24,0]],"id":46292327}],"con":true,"img":false}]}
{"op":"mcm","clk":"11450405610","pt":1717321664209,"mc":[{"id":"1.229554919","rc":[{"atb":[[1.2,0],[1.24,62.5]],"id":46292327}],"con":true,"img":false}]}
{"op":"mcm","clk":"11450405758","pt":1717321666291,"mc":[{"id":"1.229554919","rc":[{"atl":[[3.8,5.36],[3.75,0]],"id":65788088}],"con":true,"img":false}]}
{"op":"mcm","clk":"11450405910","pt":1717321668415,"mc":[{"id":"1.229554919","rc":[{"atl":[[3.45,10],[3.7,0]],"id":46292327}],"con":true,"img":false}]}
{"op":"mcm","clk":"11450406274","pt":1717321672909,"mc":[{"id":"1.229554919","rc":[{"atb":[[1.2,75]],"id":46292327}],"con":true,"img":false}]}
{"op":"mcm","clk":"11450406281","pt":1717321673013,"mc":[{"id":"1.229554919","rc":[{"atb":[[1.24,0]],"id":46292327}],"con":true,"img":false}]}
{"op":"mcm","clk":"11450406314","pt":1717321673430,"mc":[{"id":"1.229554919","rc":[{"atb":[[1.24,62.5]],"id":46292327}],"con":true,"img":false}]}
{"op":"mcm","clk":"11450406320","pt":1717321673530,"mc":[{"id":"1.229554919","rc":[{"atb":[[1.2,0]],"id":46292327}],"con":true,"img":false}]}
{"op":"mcm","clk":"11450406380","pt":1717321674318,"mc":[{"id":"1.229554919","rc":[{"atb":[[1.2,75],[1.24,0]],"id":46292327}],"con":true,"img":false}]}
{"op":"mcm","clk":"11450406719","pt":1717321679237,"mc":[{"id":"1.229554919","rc":[{"atb":[[1.21,0],[1.11,0],[1.32,10]],"id":46292327},{"atb":[[3.45,0],[2.98,0]],"id":65788088},{"atl":[[3.8,0],[3.9,10],[3.75,5.45]],"id":65788088}],"con":true,"img":false}]}
{"op":"mcm","clk":"11450406729","pt":1717321679340,"mc":[{"id":"1.229554919","rc":[{"atb":[[1.31,0]],"id":46292327},{"atb":[[1.39,10]],"id":65788088},{"atl":[[3.95,6.78]],"id":65788088}],"con":true,"img":false}]}
{"op":"mcm","clk":"11450406735","pt":1717321679445,"mc":[{"id":"1.229554919","rc":[{"atb":[[1.35,42.86]],"id":65788088}],"con":true,"img":false}]}
{"op":"mcm","clk":"11450406740","pt":1717321679548,"mc":[{"id":"1.229554919","rc":[{"atb":[[1.35,0],[1.38,39.47]],"id":65788088}],"con":true,"img":false}]}
{"op":"mcm","clk":"11450407107","pt":1717321684313,"mc":[{"id":"1.229554919","rc":[{"atb":[[1.32,0],[1.34,10]],"id":46292327},{"atl":[[4,6.67]],"id":46292327},{"atl":[[3.7,10],[3.9,0]],"id":65788088}],"con":true,"img":false}]}
{"op":"mcm","clk":"11450407163","pt":1717321685239,"mc":[{"id":"1.229554919","rc":[{"atl":[[4.8,0]],"id":46292327}],"con":true,"img":false}]}
{"op":"mcm","clk":"11450407492","pt":1717321689558,"mc":[{"id":"1.229554919","rc":[{"atb":[[1.36,55.56]],"id":65788088}],"con":true,"img":false}]}
{"op":"mcm","clk":"11450407634","pt":1717321691323,"mc":[{"id":"1.229554919","rc":[{"atb":[[1.28,0]],"id":65788088}],"con":true,"img":false}]}
{"op":"mcm","clk":"11450407711","pt":1717321692146,"mc":[{"id":"1.229554919","rc":[{"atb":[[1.34,0],[1.35,10]],"id":46292327},{"atl":[[3.6,10],[3.7,0]],"id":65788088}],"con":true,"img":false}]}
{"op":"mcm","clk":"11450407886","pt":1717321694346,"mc":[{"id":"1.229554919","rc":[{"atl":[[4.2,7.81]],"id":46292327}],"con":true,"img":false}]}
{"op":"mcm","clk":"11450407898","pt":1717321694450,"mc":[{"id":"1.229554919","rc":[{"atl":[[4.6,0]],"id":46292327}],"con":true,"img":false}]}
{"op":"mcm","clk":"11450407950","pt":1717321695329,"mc":[{"id":"1.229554919","rc":[{"atb":[[1.34,10]],"id":46292327},{"atl":[[3.7,10]],"id":65788088}],"con":true,"img":false}]}
{"op":"mcm","clk":"11450407957","pt":1717321695435,"mc":[{"id":"1.229554919","rc":[{"atb":[[1.35,0]],"id":46292327},{"atl":[[3.6,0]],"id":65788088}],"con":true,"img":false}]}
{"op":"mcm","clk":"11450408145","pt":1717321698386,"mc":[{"id":"1.229554919","rc":[{"atb":[[1.21,37.37],[1.11,71.34]],"id":46292327},{"atb":[[3.45,3.2],[2.98,3.96]],"id":65788088}],"con":true,"img":false}]}
{"op":"mcm","clk":"11450408313","pt":1717321700456,"mc":[{"id":"1.229554919","rc":[{"atb":[[1.32,10],[1.34,0]],"id":46292327},{"atl":[[3.85,17.02],[3.7,0]],"id":65788088}],"con":true,"img":false}]}
{"op":"mcm","clk":"11450408323","pt":1717321700559,"mc":[{"id":"1.229554919","rc":[{"atl":[[3.85,7.02],[3.9,10]],"id":65788088}],"con":true,"img":false}]}
{"op":"mcm","clk":"11450409082","pt":1717321710558,"mc":[{"id":"1.229554919","rc":[{"atb":[[1.32,0],[1.31,10]],"id":46292327},{"atl":[[3.8,5.36],[3.75,0]],"id":65788088}],"con":true,"img":false}]}
{"op":"mcm","clk":"11450409520","pt":1717321716672,"mc":[{"id":"1.229554919","rc":[{"atl":[[3.8,0],[3.75,5.45]],"id":65788088}],"con":true,"img":false}]}
{"op":"mcm","clk":"11450409597","pt":1717321717703,"mc":[{"id":"1.229554919","rc":[{"atb":[[1.32,10],[1.31,0]],"id":46292327}],"con":true,"img":false}]}
{"op":"mcm","clk":"11450409642","pt":1717321718377,"mc":[{"id":"1.229554919","rc":[{"atl":[[3.85,17.02]],"id":65788088}],"con":true,"img":false}]}
{"op":"mcm","clk":"11450409649","pt":1717321718481,"mc":[{"id":"1.229554919","rc":[{"atl":[[3.9,0]],"id":65788088}],"con":true,"img":false}]}
{"op":"mcm","clk":"11450409747","pt":1717321719583,"mc":[{"id":"1.229554919","rc":[{"atb":[[1.32,0],[1.31,10]],"id":46292327},{"atl":[[3.85,7.02],[3.95,16.78]],"id":65788088}],"con":true,"img":false}]}
{"op":"mcm","clk":"11450409780","pt":1717321720000,"mc":[{"id":"1.229554919","rc":[{"atl":[[3.8,5.36],[3.75,0]],"id":65788088}],"con":true,"img":false}]}
{"op":"mcm","clk":"11450409792","pt":1717321720099,"mc":[{"id":"1.229554919","rc":[{"atl":[[3.85,17.02]],"id":65788088}],"con":true,"img":false}]}
{"op":"mcm","clk":"11450409798","pt":1717321720201,"mc":[{"id":"1.229554919","rc":[{"atl":[[3.95,6.78]],"id":65788088}],"con":true,"img":false}]}
{"op":"mcm","clk":"11450409823","pt":1717321720469,"mc":[{"id":"1.229554919","rc":[{"atb":[[1.33,10]],"id":46292327},{"atl":[[3.8,0],[3.75,5.45]],"id":65788088}],"con":true,"img":false}]}
{"op":"mcm","clk":"11450409831","pt":1717321720569,"mc":[{"id":"1.229554919","rc":[{"atb":[[1.31,0]],"id":46292327}],"con":true,"img":false}]}
{"op":"mcm","clk":"11450410052","pt":1717321723693,"mc":[{"id":"1.229554919","rc":[{"atb":[[1.31,10]],"id":46292327}],"con":true,"img":false}]}
{"op":"mcm","clk":"11450410064","pt":1717321723797,"mc":[{"id":"1.229554919","rc":[{"atb":[[1.33,0]],"id":46292327}],"con":true,"img":false}]}
{"op":"mcm","clk":"11450410190","pt":1717321725199,"mc":[{"id":"1.229554919","rc":[{"atl":[[3.95,16.78]],"id":65788088}],"con":true,"img":false}]}
{"op":"mcm","clk":"11450410203","pt":1717321725302,"mc":[{"id":"1.229554919","rc":[{"atl":[[3.85,7.02]],"id":65788088}],"con":true,"img":false}]}
{"op":"mcm","clk":"11450410315","pt":1717321726698,"mc":[{"id":"1.229554919","rc":[{"atl":[[3.8,5.36],[3.75,0]],"id":65788088}],"con":true,"img":false}]}
{"op":"mcm","clk":"11450410323","pt":1717321726802,"mc":[{"id":"1.229554919","rc":[{"atl":[[3.85,17.02],[3.95,6.78]],"id":65788088}],"con":true,"img":false}]}
{"op":"mcm","clk":"11450410333","pt":1717321726907,"mc":[{"id":"1.229554919","rc":[{"atl":[[3.85,7.02],[3.95,16.78]],"id":65788088}],"con":true,"img":false}]}
{"op":"mcm","clk":"11450410360","pt":1717321727216,"mc":[{"id":"1.229554919","rc":[{"atl":[[3.75,5.45]],"id":65788088}],"con":true,"img":false}]}
{"op":"mcm","clk":"11450410371","pt":1717321727327,"mc":[{"id":"1.229554919","rc":[{"atl":[[3.85,17.02],[3.8,0]],"id":65788088}],"con":true,"img":false}]}
{"op":"mcm","clk":"11450410383","pt":1717321727383,"mc":[{"id":"1.229554919","rc":[{"atl":[[3.95,6.78]],"id":65788088}],"con":true,"img":false}]}
{"op":"mcm","clk":"11450410391","pt":1717321727483,"mc":[{"id":"1.229554919","rc":[{"atl":[[3.95,16.78]],"id":65788088}],"con":true,"img":false}]}
{"op":"mcm","clk":"11450410399","pt":1717321727583,"mc":[{"id":"1.229554919","rc":[{"atl":[[3.85,7.02]],"id":65788088}],"con":true,"img":false}]}
{"op":"mcm","clk":"11450410726","pt":1717321731523,"mc":[{"id":"1.229554919","rc":[{"atl":[[3.8,5.36],[3.75,0]],"id":65788088}],"con":true,"img":false}]}
{"op":"mcm","clk":"11450410801","pt":1717321732418,"mc":[{"id":"1.229554919","rc":[{"atl":[[3.8,0],[3.75,5.45]],"id":65788088}],"con":true,"img":false}]}
{"op":"mcm","clk":"11450410891","pt":1717321733519,"mc":[{"id":"1.229554919","rc":[{"atl":[[3.8,5.36],[3.75,0]],"id":65788088}],"con":true,"img":false}]}
{"op":"mcm","clk":"11450410898","pt":1717321733621,"mc":[{"id":"1.229554919","rc":[{"atl":[[3.85,17.02],[3.95,6.78]],"id":65788088}],"con":true,"img":false}]}
{"op":"mcm","clk":"11450410905","pt":1717321733726,"mc":[{"id":"1.229554919","rc":[{"atl":[[3.95,16.78]],"id":65788088}],"con":true,"img":false}]}
{"op":"mcm","clk":"11450410914","pt":1717321733830,"mc":[{"id":"1.229554919","rc":[{"atl":[[3.85,7.02]],"id":65788088}],"con":true,"img":false}]}
{"op":"mcm","clk":"11450410926","pt":1717321733934,"mc":[{"id":"1.229554919","rc":[{"atl":[[3.8,0],[3.75,5.45]],"id":65788088}],"con":true,"img":false}]}
{"op":"mcm","clk":"11450410936","pt":1717321733993,"mc":[{"id":"1.229554919","rc":[{"atl":[[3.85,17.02],[3.95,6.78]],"id":65788088}],"con":true,"img":false}]}
{"op":"mcm","clk":"11450411133","pt":1717321736291,"mc":[{"id":"1.229554919","rc":[{"atl":[[3.8,5.36]],"id":65788088}],"con":true,"img":false}]}
{"op":"mcm","clk":"11450411141","pt":1717321736391,"mc":[{"id":"1.229554919","rc":[{"atl":[[3.75,0]],"id":65788088}],"con":true,"img":false}]}
{"op":"mcm","clk":"11450411189","pt":1717321737112,"mc":[{"id":"1.229554919","rc":[{"atl":[[3.8,0],[3.75,5.45]],"id":65788088}],"con":true,"img":false}]}
{"op":"mcm","clk":"11450411363","pt":1717321739098,"mc":[{"id":"1.229554919","rc":[{"atl":[[3.85,7.02],[3.95,16.78]],"id":65788088}],"con":true,"img":false}]}
{"op":"mcm","clk":"11450412714","pt":1717321753638,"mc":[{"id":"1.229554919","rc":[{"atb":[[1.32,10],[1.31,0]],"id":46292327},{"atl":[[3.95,6.78],[3.9,10]],"id":65788088}],"con":true,"img":false}]}
{"op":"mcm","clk":"11450412740","pt":1717321753948,"mc":[{"id":"1.229554919","rc":[{"atl":[[3.8,10],[3.9,0]],"id":65788088}],"con":true,"img":false}]}
{"op":"mcm","clk":"11450412830","pt":1717321755034,"mc":[{"id":"1.229554919","rc":[{"atb":[[1.32,0],[1.31,10]],"id":46292327}],"con":true,"img":false}]}
{"op":"mcm","clk":"11450412885","pt":1717321755656,"mc":[{"id":"1.229554919","rc":[{"atb":[[1.32,10],[1.31,0]],"id":46292327}],"con":true,"img":false}]}
{"op":"mcm","clk":"11450413305","pt":1717321760959,"mc":[{"id":"1.229554919","rc":[{"atl":[[3.85,17.02],[3.8,0]],"id":65788088}],"con":true,"img":false}]}
{"op":"mcm","clk":"11450413338","pt":1717321761333,"mc":[{"id":"1.229554919","rc":[{"atb":[[1.32,0],[1.31,10]],"id":46292327},{"atl":[[3.85,7.02],[3.95,16.78],[3.8,5.36],[3.75,0]],"id":65788088}],"con":true,"img":false}]}
{"op":"mcm","clk":"11450413367","pt":1717321761645,"mc":[{"id":"1.229554919","rc":[{"atl":[[3.8,0],[3.75,5.45]],"id":65788088}],"con":true,"img":false}]}
{"op":"mcm","clk":"11450413781","pt":1717321766419,"mc":[{"id":"1.229554919","rc":[{"atl":[[3.85,17.02]],"id":65788088}],"con":true,"img":false}]}
{"op":"mcm","clk":"11450413792","pt":1717321766529,"mc":[{"id":"1.229554919","rc":[{"atl":[[3.95,6.78]],"id":65788088}],"con":true,"img":false}]}
{"op":"mcm","clk":"11450413804","pt":1717321766624,"mc":[{"id":"1.229554919","rc":[{"atl":[[3.95,16.78]],"id":65788088}],"con":true,"img":false}]}
{"op":"mcm","clk":"11450413813","pt":1717321766726,"mc":[{"id":"1.229554919","rc":[{"atl":[[3.85,7.02]],"id":65788088}],"con":true,"img":false}]}
{"op":"mcm","clk":"11450414836","pt":1717321778450,"mc":[{"id":"1.229554919","rc":[{"atl":[[3.8,5.36],[3.75,0]],"id":65788088}],"con":true,"img":false}]}
{"op":"mcm","clk":"11450414847","pt":1717321778553,"mc":[{"id":"1.229554919","rc":[{"atl":[[3.85,17.02],[3.95,6.78]],"id":65788088}],"con":true,"img":false}]}
{"op":"mcm","clk":"11450414858","pt":1717321778660,"mc":[{"id":"1.229554919","rc":[{"atl":[[3.85,7.02],[3.95,16.78]],"id":65788088}],"con":true,"img":false}]}
{"op":"mcm","clk":"11450414883","pt":1717321778972,"mc":[{"id":"1.229554919","rc":[{"atl":[[3.75,5.45]],"id":65788088}],"con":true,"img":false}]}
{"op":"mcm","clk":"11450414891","pt":1717321779075,"mc":[{"id":"1.229554919","rc":[{"atl":[[3.7,10],[3.8,0]],"id":65788088}],"con":true,"img":false}]}
{"op":"mcm","clk":"11450414902","pt":1717321779178,"mc":[{"id":"1.229554919","rc":[{"atl":[[3.95,6.78],[3.8,10]],"id":65788088}],"con":true,"img":false}]}
{"op":"mcm","clk":"11450414914","pt":1717321779282,"mc":[{"id":"1.229554919","rc":[{"atl":[[3.7,0]],"id":65788088}],"con":true,"img":false}]}
{"op":"mcm","clk":"11450415262","pt":1717321782773,"mc":[{"id":"1.229554919","rc":[{"atb":[[1.21,0],[1.11,0],[1.33,10],[1.31,0]],"id":46292327},{"atb":[[3.45,0],[2.98,0]],"id":65788088},{"atl":[[3.8,0],[3.75,15.45]],"id":65788088}],"con":true,"img":false}]}
{"op":"mcm","clk":"11450415337","pt":1717321783557,"mc":[{"id":"1.229554919","rc":[{"atl":[[3.8,10],[3.75,5.45]],"id":65788088}],"con":true,"img":false}]}
{"op":"mcm","clk":"11450415450","pt":1717321784751,"mc":[{"id":"1.229554919","rc":[{"atl":[[3.7,10],[3.8,0]],"id":65788088}],"con":true,"img":false}]}
{"op":"mcm","clk":"11450415781","pt":1717321788984,"mc":[{"id":"1.229554919","rc":[{"atb":[[1.33,0],[1.34,10]],"id":46292327},{"atb":[[1.34,73.53]],"id":65788088},{"atl":[[3.65,10]],"id":65788088}],"con":true,"img":false}]}
{"op":"mcm","clk":"11450415790","pt":1717321789087,"mc":[{"id":"1.229554919","rc":[{"atl":[[3.7,0]],"id":65788088}],"con":true,"img":false}]}
{"op":"mcm","clk":"11450415931","pt":1717321790744,"mc":[{"id":"1.229554919","rc":[{"atb":[[1.3,0]],"id":65788088}],"con":true,"img":false}]}
{"op":"mcm","clk":"11450415986","pt":1717321791483,"mc":[{"id":"1.229554919","rc":[{"atb":[[1.21,37.37],[1.11,71.34]],"id":46292327},{"atb":[[3.45,3.2],[2.98,3.96]],"id":65788088}],"con":true,"img":false}]}
{"op":"mcm","clk":"11450416222","pt":1717321794079,"mc":[{"id":"1.229554919","rc":[{"atb":[[1.32,10],[1.34,0]],"id":46292327},{"atl":[[3.85,17.02],[3.65,0]],"id":65788088}],"con":true,"img":false}]}
{"op":"mcm","clk":"11450416447","pt":1717321796470,"mc":[{"id":"1.229554919","rc":[{"atb":[[1.32,0],[1.31,10]],"id":46292327},{"atl":[[3.8,5.36],[3.75,0]],"id":65788088}],"con":true,"img":false}]}
{"op":"mcm","clk":"11450416456","pt":1717321796576,"mc":[{"id":"1.229554919","rc":[{"atl":[[3.85,7.02],[3.75,10]],"id":65788088}],"con":true,"img":false}]}
{"op":"mcm","clk":"11450416462","pt":1717321796675,"mc":[{"id":"1.229554919","rc":[{"atl":[[3.85,17.02]],"id":65788088}],"con":true,"img":false}]}
{"op":"mcm","clk":"11450416468","pt":1717321796780,"mc":[{"id":"1.229554919","rc":[{"atl":[[3.75,0]],"id":65788088}],"con":true,"img":false}]}
{"op":"mcm","clk":"11450416478","pt":1717321796889,"mc":[{"id":"1.229554919","rc":[{"atl":[[3.95,16.78]],"id":65788088}],"con":true,"img":false}]}
{"op":"mcm","clk":"11450416488","pt":1717321796991,"mc":[{"id":"1.229554919","rc":[{"atl":[[3.85,7.02]],"id":65788088}],"con":true,"img":false}]}
{"op":"mcm","clk":"11450416517","pt":1717321797255,"mc":[{"id":"1.229554919","rc":[{"atb":[[1.32,10],[1.31,0]],"id":46292327},{"atl":[[3.75,5.45]],"id":65788088}],"con":true,"img":false}]}
{"op":"mcm","clk":"11450416525","pt":1717321797402,"mc":[{"id":"1.229554919","rc":[{"atl":[[3.8,0]],"id":65788088}],"con":true,"img":false}]}
{"op":"mcm","clk":"11450416605","pt":1717321798596,"mc":[{"id":"1.229554919","rc":[{"atb":[[1.32,0],[1.31,10]],"id":46292327}],"con":true,"img":false}]}
{"op":"mcm","clk":"11450416920","pt":1717321801988,"mc":[{"id":"1.229554919","rc":[{"atl":[[3.85,17.02],[3.95,6.78]],"id":65788088}],"con":true,"img":false}]}
{"op":"mcm","clk":"11450417092","pt":1717321803712,"mc":[{"id":"1.229554919","rc":[{"atb":[[1.33,10]],"id":46292327}],"con":true,"img":false}]}
{"op":"mcm","clk":"11450417102","pt":1717321803770,"mc":[{"id":"1.229554919","rc":[{"atb":[[1.31,0]],"id":46292327}],"con":true,"img":false}]}
{"op":"mcm","clk":"11450417115","pt":1717321803874,"mc":[{"id":"1.229554919","rc":[{"atb":[[1.33,0],[1.31,10]],"id":46292327}],"con":true,"img":false}]}
{"op":"mcm","clk":"11450417422","pt":1717321807102,"mc":[{"id":"1.229554919","rc":[{"atl":[[3.85,7.02],[3.95,16.78]],"id":65788088}],"con":true,"img":false}]}
{"op":"mcm","clk":"11450417473","pt":1717321807617,"mc":[{"id":"1.229554919","rc":[{"atb":[[1.31,0]],"id":46292327},{"atl":[[3.45,0]],"id":46292327},{"atb":[[1.39,0]],"id":65788088},{"atl":[[3.95,6.78]],"id":65788088}],"con":true,"img":false}]}
{"op":"mcm","clk":"11450420278","pt":1717321838680,"mc":[{"id":"1.229554919","rc":[{"atb":[[1.2,0],[1.23,65.22]],"id":46292327}],"con":true,"img":false}]}
{"op":"mcm","clk":"11450420297","pt":1717321838885,"mc":[{"id":"1.229554919","rc":[{"atb":[[1.2,75]],"id":46292327}],"con":true,"img":false}]}
{"op":"mcm","clk":"11450420306","pt":1717321839017,"mc":[{"id":"1.229554919","rc":[{"atb":[[1.23,0]],"id":46292327}],"con":true,"img":false}]}
{"op":"mcm","clk":"11450420359","pt":1717321839483,"mc":[{"id":"1.229554919","rc":[{"atb":[[1.2,0],[1.23,65.22]],"id":46292327}],"con":true,"img":false}]}
{"op":"mcm","clk":"11450420471","pt":1717321840893,"mc":[{"id":"1.229554919","rc":[{"atb":[[1.2,75],[1.23,0]],"id":46292327}],"con":true,"img":false}]}
{"op":"mcm","clk":"11450420559","pt":1717321841815,"mc":[{"id":"1.229554919","rc":[{"atb":[[1.2,0],[1.23,65.22]],"id":46292327}],"con":true,"img":false}]}
{"op":"mcm","clk":"11450420594","pt":1717321842187,"mc":[{"id":"1.229554919","rc":[{"atb":[[1.2,75],[1.23,0]],"id":46292327}],"con":true,"img":false}]}
{"op":"mcm","clk":"11450420612","pt":1717321842397,"mc":[{"id":"1.229554919","rc":[{"atb":[[1.2,0],[1.23,65.22]],"id":46292327}],"con":true,"img":false}]}
{"op":"mcm","clk":"11450420630","pt":1717321842598,"mc":[{"id":"1.229554919","rc":[{"atb":[[1.2,75],[1.23,0]],"id":46292327}],"con":true,"img":false}]}
{"op":"mcm","clk":"11450420766","pt":1717321844103,"mc":[{"id":"1.229554919","rc":[{"atb":[[1.31,10]],"id":46292327},{"atl":[[3.45,10]],"id":46292327},{"atb":[[1.39,10]],"id":65788088},{"atl":[[3.9,10]],"id":65788088}],"con":true,"img":false}]}
{"op":"mcm","clk":"11450425608","pt":1717321902971,"mc":[{"id":"1.229554919","rc":[{"atb":[[1.32,10]],"id":46292327},{"atl":[[3.85,17.02]],"id":65788088}],"con":true,"img":false}]}
{"op":"mcm","clk":"11450425618","pt":1717321903079,"mc":[{"id":"1.229554919","rc":[{"atb":[[1.31,0]],"id":46292327},{"atl":[[3.9,0]],"id":65788088}],"con":true,"img":false}]}
{"op":"mcm","clk":"11450425641","pt":1717321903286,"mc":[{"id":"1.229554919","rc":[{"atb":[[1.21,0],[1.11,0]],"id":46292327},{"atb":[[3.45,0],[2.98,0]],"id":65788088}],"con":true,"img":false}]}
{"op":"mcm","clk":"11450426490","pt":1717321913706,"mc":[{"id":"1.229554919","rc":[{"atb":[[1.21,37.37],[1.11,71.34]],"id":46292327},{"atb":[[3.45,3.2],[2.98,3.96]],"id":65788088}],"con":true,"img":false}]}
{"op":"mcm","clk":"11450427604","pt":1717321925083,"mc":[{"id":"1.229554919","rc":[{"atb":[[1.32,0],[1.31,10]],"id":46292327},{"atl":[[3.85,7.02],[3.9,10]],"id":65788088}],"con":true,"img":false}]}
{"op":"mcm","clk":"11450428246","pt":1717321931579,"mc":[{"id":"1.229554919","rc":[{"atl":[[3.8,10]],"id":65788088}],"con":true,"img":false}]}
{"op":"mcm","clk":"11450428259","pt":1717321931683,"mc":[{"id":"1.229554919","rc":[{"atb":[[1.32,10],[1.31,0]],"id":46292327},{"atl":[[3.9,0]],"id":65788088}],"con":true,"img":false}]}
{"op":"mcm","clk":"11450428822","pt":1717321936696,"mc":[{"id":"1.229554919","rc":[{"atl":[[3.85,17.02]],"id":65788088}],"con":true,"img":false}]}
{"op":"mcm","clk":"11450428834","pt":1717321936797,"mc":[{"id":"1.229554919","rc":[{"atb":[[1.32,0],[1.31,10]],"id":46292327},{"atl":[[3.8,0]],"id":65788088}],"con":true,"img":false}]}
{"op":"mcm","clk":"11450429150","pt":1717321939988,"mc":[{"id":"1.229554919","rc":[{"atb":[[1.32,10]],"id":46292327}],"con":true,"img":false}]}
{"op":"mcm","clk":"11450429160","pt":1717321940093,"mc":[{"id":"1.229554919","rc":[{"atb":[[1.32,0],[1.3,10],[1.31,0]],"id":46292327},{"atl":[[3.85,22.28]],"id":65788088}],"con":true,"img":false}]}
{"op":"mcm","clk":"11450429168","pt":1717321940192,"mc":[{"id":"1.229554919","rc":[{"atl":[[3.85,5.26],[3.95,16.78],[3.75,0]],"id":65788088}],"con":true,"img":false}]}
{"op":"mcm","clk":"11450429256","pt":1717321940977,"mc":[{"id":"1.229554919","rc":[{"atb":[[1.3,0],[1.32,10]],"id":46292327},{"atl":[[3.75,5.45]],"id":65788088}],"con":true,"img":false}]}
{"op":"mcm","clk":"11450429652","pt":1717321945282,"mc":[{"id":"1.229554919","rc":[{"atl":[[3.85,15.26],[3.95,6.78]],"id":65788088}],"con":true,"img":false}]}
{"op":"mcm","clk":"11450430442","pt":1717321954507,"mc":[{"id":"1.229554919","rc":[{"atb":[[1.32,0]],"id":46292327},{"atl":[[3.45,0]],"id":46292327},{"atb":[[1.39,0]],"id":65788088},{"atl":[[3.85,5.26]],"id":65788088}],"con":true,"img":false}]}
{"op":"mcm","clk":"11450434565","pt":1717322004719,"mc":[{"id":"1.229554919","rc":[{"atb":[[1.2,0],[1.19,78.95]],"id":46292327}],"con":true,"img":false}]}
{"op":"mcm","clk":"11450434649","pt":1717322005599,"mc":[{"id":"1.229554919","rc":[{"atb":[[1.19,0],[1.23,65.22]],"id":46292327}],"con":true,"img":false}]}
{"op":"mcm","clk":"11450434668","pt":1717322005805,"mc":[{"id":"1.229554919","rc":[{"atl":[[3.9,5.17],[3.75,0]],"id":65788088}],"con":true,"img":false}]}
{"op":"mcm","clk":"11450434864","pt":1717322008400,"mc":[{"id":"1.229554919","rc":[{"atl":[[3.85,0]],"id":65788088}],"con":true,"img":false}]}
{"op":"mcm","clk":"11450434934","pt":1717322009497,"mc":[{"id":"1.229554919","rc":[{"atb":[[1.19,78.95],[1.23,0]],"id":46292327}],"con":true,"img":false}]}
{"op":"mcm","clk":"11450435032","pt":1717322010894,"mc":[{"id":"1.229554919","rc":[{"atb":[[1.19,0],[1.23,65.22]],"id":46292327}],"con":true,"img":false}]}
{"op":"mcm","clk":"11450435383","pt":1717322014942,"mc":[{"id":"1.229554919","rc":[{"atb":[[1.19,78.95],[1.23,0]],"id":46292327}],"con":true,"img":false}]}
{"op":"mcm","clk":"11450435522","pt":1717322016400,"mc":[{"id":"1.229554919","rc":[{"atb":[[1.19,0],[1.23,65.22]],"id":46292327},{"atl":[[4,6.67]],"id":65788088}],"con":true,"img":false}]}
{"op":"mcm","clk":"11450435725","pt":1717322019403,"mc":[{"id":"1.229554919","rc":[{"atb":[[1.19,78.95],[1.23,0]],"id":46292327}],"con":true,"img":false}]}
{"op":"mcm","clk":"11450435757","pt":1717322019818,"mc":[{"id":"1.229554919","rc":[{"atb":[[1.19,0],[1.23,65.22]],"id":46292327}],"con":true,"img":false}]}
{"op":"mcm","clk":"11450435784","pt":1717322020242,"mc":[{"id":"1.229554919","rc":[{"atb":[[1.19,78.95],[1.23,0]],"id":46292327}],"con":true,"img":false}]}
{"op":"mcm","clk":"11450435827","pt":1717322020751,"mc":[{"id":"1.229554919","rc":[{"atb":[[1.19,0],[1.23,65.22]],"id":46292327}],"con":true,"img":false}]}
{"op":"mcm","clk":"11450435847","pt":1717322020910,"mc":[{"id":"1.229554919","rc":[{"atb":[[1.19,78.95],[1.23,0]],"id":46292327}],"con":true,"img":false}]}
{"op":"mcm","clk":"11450435912","pt":1717322021554,"mc":[{"id":"1.229554919","rc":[{"atb":[[1.19,0],[1.23,65.22]],"id":46292327}],"con":true,"img":false}]}
{"op":"mcm","clk":"11450435934","pt":1717322021708,"mc":[{"id":"1.229554919","rc":[{"atb":[[1.19,78.95],[1.23,0]],"id":46292327}],"con":true,"img":false}]}
{"op":"mcm","clk":"11450436068","pt":1717322023254,"mc":[{"id":"1.229554919","rc":[{"atb":[[1.19,0],[1.23,65.22]],"id":46292327}],"con":true,"img":false}]}
{"op":"mcm","clk":"11450436084","pt":1717322023448,"mc":[{"id":"1.229554919","rc":[{"atb":[[1.19,78.95],[1.23,0]],"id":46292327}],"con":true,"img":false}]}
{"op":"mcm","clk":"11450436865","pt":1717322032258,"mc":[{"id":"1.229554919","rc":[{"atb":[[1.21,0],[1.11,0]],"id":46292327},{"atb":[[3.45,0],[2.98,0]],"id":65788088}],"con":true,"img":false}]}
{"op":"mcm","clk":"11450437420","pt":1717322038148,"mc":[{"id":"1.229554919","rc":[{"atl":[[3.95,5.08],[3.9,0]],"id":65788088}],"con":true,"img":false}]}
{"op":"mcm","clk":"11450437654","pt":1717322040961,"mc":[{"id":"1.229554919","rc":[{"atb":[[1.21,37.37],[1.11,71.34]],"id":46292327},{"atb":[[3.45,3.2],[2.98,3.96]],"id":65788088}],"con":true,"img":false}]}
{"op":"mcm","clk":"11450438323","pt":1717322048136,"mc":[{"id":"1.229554919","rc":[{"atl":[[4.1,6.45]],"id":65788088}],"con":true,"img":false}]}
{"op":"mcm","clk":"11450439185","pt":1717322058086,"mc":[{"id":"1.229554919","rc":[{"atl":[[4.3,7.58]],"id":65788088}],"con":true,"img":false}]}
{"op":"mcm","clk":"11450439771","pt":1717322064186,"mc":[{"id":"1.229554919","rc":[{"atl":[[3.85,5.26],[3.95,0]],"id":65788088}],"con":true,"img":false}]}
{"op":"mcm","clk":"11450439865","pt":1717322065078,"mc":[{"id":"1.229554919","rc":[{"atl":[[3.85,0],[3.9,5.17]],"id":65788088}],"con":true,"img":false}]}
{"op":"mcm","clk":"11450440433","pt":1717322070585,"mc":[{"id":"1.229554919","rc":[{"atl":[[4.1,4.84],[3.9,0]],"id":65788088}],"con":true,"img":false}]}
{"op":"mcm","clk":"11450440496","pt":1717322071206,"mc":[{"id":"1.229554919","rc":[{"atl":[[4,0]],"id":65788088}],"con":true,"img":false}]}
{"op":"mcm","clk":"11450440651","pt":1717322072505,"mc":[{"id":"1.229554919","rc":[{"atl":[[3.9,5.17]],"id":65788088}],"con":true,"img":false}]}
{"op":"mcm","clk":"11450440688","pt":1717322072769,"mc":[{"id":"1.229554919","rc":[{"atl":[[3.9,0]],"id":65788088}],"con":true,"img":false}]}
{"op":"mcm","clk":"11450440844","pt":1717322074171,"mc":[{"id":"1.229554919","rc":[{"atl":[[4,5]],"id":65788088}],"con":true,"img":false}]}
{"op":"mcm","clk":"11450440901","pt":1717322074793,"mc":[{"id":"1.229554919","rc":[{"atb":[[1.19,0],[1.23,65.22]],"id":46292327}],"con":true,"img":false}]}
{"op":"mcm","clk":"11450440936","pt":1717322075203,"mc":[{"id":"1.229554919","rc":[{"atb":[[1.19,78.95],[1.23,0]],"id":46292327}],"con":true,"img":false}]}
{"op":"mcm","clk":"11450441040","pt":1717322075978,"mc":[{"id":"1.229554919","rc":[{"atl":[[3.95,5.08]],"id":65788088}],"con":true,"img":false}]}
{"op":"mcm","clk":"11450441119","pt":1717322076813,"mc":[{"id":"1.229554919","rc":[{"atb":[[1.19,0],[1.23,65.22]],"id":46292327}],"con":true,"img":false}]}
{"op":"mcm","clk":"11450441147","pt":1717322077022,"mc":[{"id":"1.229554919","rc":[{"atb":[[1.19,78.95]],"id":46292327}],"con":true,"img":false}]}
{"op":"mcm","clk":"11450441160","pt":1717322077078,"mc":[{"id":"1.229554919","rc":[{"atb":[[1.23,0]],"id":46292327}],"con":true,"img":false}]}
{"op":"mcm","clk":"11450441283","pt":1717322078162,"mc":[{"id":"1.229554919","rc":[{"atl":[[3.95,0]],"id":65788088}],"con":true,"img":false}]}
{"op":"mcm","clk":"11450441308","pt":1717322078478,"mc":[{"id":"1.229554919","rc":[{"atl":[[4,0]],"id":65788088}],"con":true,"img":false}]}
{"op":"mcm","clk":"11450441465","pt":1717322080034,"mc":[{"id":"1.229554919","rc":[{"atl":[[4,5]],"id":65788088}],"con":true,"img":false}]}
{"op":"mcm","clk":"11450441634","pt":1717322082001,"mc":[{"id":"1.229554919","rc":[{"atl":[[3.85,5.26]],"id":65788088}],"con":true,"img":false}]}
{"op":"mcm","clk":"11450441681","pt":1717322082466,"mc":[{"id":"1.229554919","rc":[{"atl":[[3.9,5.17]],"id":65788088}],"con":true,"img":false}]}
{"op":"mcm","clk":"11450441693","pt":1717322082618,"mc":[{"id":"1.229554919","rc":[{"atl":[[3.85,0]],"id":65788088}],"con":true,"img":false}]}
{"op":"mcm","clk":"11450443284","pt":1717322103227,"mc":[{"id":"1.229554919","rc":[{"atb":[[1.2,75],[1.19,0]],"id":46292327}],"con":true,"img":false}]}
{"op":"mcm","clk":"11450444501","pt":1717322117523,"mc":[{"id":"1.229554919","rc":[{"atb":[[1.2,0],[1.24,62.5]],"id":46292327}],"con":true,"img":false}]}
{"op":"mcm","clk":"11450444678","pt":1717322119445,"mc":[{"id":"1.229554919","rc":[{"atb":[[1.2,75],[1.24,0]],"id":46292327}],"con":true,"img":false}]}
{"op":"mcm","clk":"11450444995","pt":1717322122938,"mc":[{"id":"1.229554919","rc":[{"atb":[[1.2,0],[1.24,62.5]],"id":46292327}],"con":true,"img":false}]}
{"op":"mcm","clk":"11450445048","pt":1717322123555,"mc":[{"id":"1.229554919","rc":[{"atb":[[1.2,75],[1.24,0]],"id":46292327}],"con":true,"img":false}]}
{"op":"mcm","clk":"11450446524","pt":1717322141154,"mc":[{"id":"1.229554919","rc":[{"atb":[[1.29,10]],"id":46292327},{"atl":[[3.35,10],[2.18,12.71]],"id":46292327},{"atb":[[1.31,10]],"id":65788088},{"atl":[[4,15]],"id":65788088}],"con":true,"img":false}]}
{"op":"mcm","clk":"11450446532","pt":1717322141309,"mc":[{"id":"1.229554919","rc":[{"atb":[[1.22,75]],"id":46292327},{"atl":[[5.1,0],[3.9,0],[4.2,19.65]],"id":46292327},{"atb":[[1.37,62.5]],"id":65788088},{"atl":[[4,15.34],[4.1,14.84],[7.6,0]],"id":65788088}],"con":true,"img":false}]}
{"op":"mcm","clk":"11450446539","pt":1717322141361,"mc":[{"id":"1.229554919","rc":[{"atl":[[3.35,0],[2.08,10]],"id":46292327},{"atb":[[1.9,10],[1.31,0]],"id":65788088}],"con":true,"img":false}]}
{"op":"mcm","clk":"11450446550","pt":1717322141470,"mc":[{"id":"1.229554919","rc":[{"atl":[[4,0],[3.35,25.42],[4.4,0],[4.2,0],[2.1,10],[2.08,0]],"id":46292327},{"atl":[[4,5],[4.1,35.35]],"id":65788088}],"con":true,"img":false}]}
{"op":"mcm","clk":"11450446557","pt":1717322141569,"mc":[{"id":"1.229554919","rc":[{"atl":[[4,22.71]],"id":46292327}],"con":true,"img":false}]}
{"op":"mcm","clk":"11450446564","pt":1717322141673,"mc":[{"id":"1.229554919","rc":[{"atl":[[3.35,0]],"id":46292327}],"con":true,"img":false}]}
{"op":"mcm","clk":"11450446578","pt":1717322141880,"mc":[{"id":"1.229554919","rc":[{"atl":[[4,0],[3.35,22.71]],"id":46292327}],"con":true,"img":false}]}
{"op":"mcm","clk":"11450446720","pt":1717322143544,"mc":[{"id":"1.229554919","rc":[{"atb":[[1.3,10]],"id":46292327},{"atl":[[3.85,5.26]],"id":65788088}],"con":true,"img":false}]}
{"op":"mcm","clk":"11450446727","pt":1717322143646,"mc":[{"id":"1.229554919","rc":[{"atb":[[1.29,0]],"id":46292327},{"atl":[[3.9,0]],"id":65788088}],"con":true,"img":false}]}
{"op":"mcm","clk":"11450446733","pt":1717322143751,"mc":[{"id":"1.229554919","rc":[{"atl":[[4,0],[4.3,0]],"id":65788088}],"con":true,"img":false}]}
{"op":"mcm","clk":"11450446738","pt":1717322143853,"mc":[{"id":"1.229554919","rc":[{"atl":[[8,14.29],[4.1,14.84]],"id":65788088}],"con":true,"img":false}]}
{"op":"mcm","clk":"11450447205","pt":1717322149484,"mc":[{"id":"1.229554919","rc":[{"atl":[[2.22,16.39]],"id":46292327}],"con":true,"img":false}]}
{"op":"mcm","clk":"11450447211","pt":1717322149555,"mc":[{"id":"1.229554919","rc":[{"atl":[[2.74,25.42]],"id":46292327}],"con":true,"img":false}]}
{"op":"mcm","clk":"11450447216","pt":1717322149659,"mc":[{"id":"1.229554919","rc":[{"atl":[[3.35,0]],"id":46292327}],"con":true,"img":false}]}
{"op":"mcm","clk":"11450447383","pt":1717322151900,"mc":[{"id":"1.229554919","rc":[{"atl":[[3.95,6.78]],"id":65788088}],"con":true,"img":false}]}
{"op":"mcm","clk":"11450447394","pt":1717322152002,"mc":[{"id":"1.229554919","rc":[{"atl":[[8,0],[4.1,29.13]],"id":65788088}],"con":true,"img":false}]}
{"op":"mcm","clk":"11450447580","pt":1717322154185,"mc":[{"id":"1.229554919","rc":[{"atb":[[1.2,0],[1.21,108.8]],"id":46292327}],"con":true,"img":false}]}
{"op":"mcm","clk":"11450447599","pt":1717322154448,"mc":[{"id":"1.229554919","rc":[{"atl":[[4,10],[4.1,19.13],[3.8,5.36]],"id":65788088}],"con":true,"img":false}]}
{"op":"mcm","clk":"11450447610","pt":1717322154554,"mc":[{"id":"1.229554919","rc":[{"atb":[[1.3,0],[1.31,10]],"id":46292327},{"atl":[[4,0],[3.95,16.78],[3.75,5.45]],"id":65788088}],"con":true,"img":false}]}
{"op":"mcm","clk":"11450447619","pt":1717322154655,"mc":[{"id":"1.229554919","rc":[{"atl":[[3.85,15.26],[3.95,6.78]],"id":65788088}],"con":true,"img":false}]}
{"op":"mcm","clk":"11450447638","pt":1717322154861,"mc":[{"id":"1.229554919","rc":[{"atl":[[4.1,14.29],[3.8,0]],"id":65788088}],"con":true,"img":false}]}
{"op":"mcm","clk":"11450447654","pt":1717322155083,"mc":[{"id":"1.229554919","rc":[{"atl":[[3.85,5.26],[3.95,16.78]],"id":65788088}],"con":true,"img":false}]}
{"op":"mcm","clk":"11450447672","pt":1717322155281,"mc":[{"id":"1.229554919","rc":[{"atb":[[1.2,75],[1.21,37.37]],"id":46292327}],"con":true,"img":false}]}
{"op":"mcm","clk":"11450447680","pt":1717322155412,"mc":[{"id":"1.229554919","rc":[{"atb":[[1.3,10]],"id":46292327}],"con":true,"img":false}]}
{"op":"mcm","clk":"11450447686","pt":1717322155437,"mc":[{"id":"1.229554919","rc":[{"atb":[[1.31,0]],"id":46292327},{"atl":[[3.75,0]],"id":65788088}],"con":true,"img":false}]}
{"op":"mcm","clk":"11450447734","pt":1717322156164,"mc":[{"id":"1.229554919","rc":[{"atl":[[3.8,5.36]],"id":65788088}],"con":true,"img":false}]}
{"op":"mcm","clk":"11450447740","pt":1717322156265,"mc":[{"id":"1.229554919","rc":[{"atb":[[1.31,10]],"id":46292327},{"atl":[[3.75,5.45]],"id":65788088}],"con":true,"img":false}]}
{"op":"mcm","clk":"11450447753","pt":1717322156370,"mc":[{"id":"1.229554919","rc":[{"atb":[[1.3,0]],"id":46292327}],"con":true,"img":false}]}
{"op":"mcm","clk":"11450447835","pt":1717322157357,"mc":[{"id":"1.229554919","rc":[{"atl":[[3.85,19.55]],"id":65788088}],"con":true,"img":false}]}
{"op":"mcm","clk":"11450447840","pt":1717322157459,"mc":[{"id":"1.229554919","rc":[{"atl":[[4.1,0]],"id":65788088}],"con":true,"img":false}]}
{"op":"mcm","clk":"11450447859","pt":1717322157677,"mc":[{"id":"1.229554919","rc":[{"atb":[[1.2,0],[1.21,108.8]],"id":46292327}],"con":true,"img":false}]}
{"op":"mcm","clk":"11450448075","pt":1717322159976,"mc":[{"id":"1.229554919","rc":[{"atl":[[2.06,10],[2.12,13.39],[2.1,0]],"id":46292327}],"con":true,"img":false}]}
{"op":"mcm","clk":"11450448093","pt":1717322160182,"mc":[{"id":"1.229554919","rc":[{"atl":[[3.85,29.55],[3.95,6.78],[3.75,0]],"id":65788088}],"con":true,"img":false}]}
{"op":"mcm","clk":"11450448501","pt":1717322164352,"mc":[{"id":"1.229554919","rc":[{"atl":[[3.9,6.9]],"id":65788088}],"con":true,"img":false}]}
{"op":"mcm","clk":"11450448520","pt":1717322164557,"mc":[{"id":"1.229554919","rc":[{"atl":[[3.85,15.26],[3.9,41.38]],"id":65788088}],"con":true,"img":false}]}
{"op":"mcm","clk":"11450448585","pt":1717322165287,"mc":[{"id":"1.229554919","rc":[{"atl":[[3.85,5.26],[3.9,51.38]],"id":65788088}],"con":true,"img":false}]}
{"op":"mcm","clk":"11450448821","pt":1717322168100,"mc":[{"id":"1.229554919","rc":[{"atb":[[1.21,71.43],[1.11,0]],"id":46292327},{"atb":[[3.45,0],[2.98,0]],"id":65788088}],"con":true,"img":false}]}
{"op":"mcm","clk":"11450448832","pt":1717322168201,"mc":[{"id":"1.229554919","rc":[{"atb":[[1.9,0],[1.91,10]],"id":65788088}],"con":true,"img":false}]}
{"op":"mcm","clk":"11450448841","pt":1717322168301,"mc":[{"id":"1.229554919","rc":[{"atl":[[2.92,26.78],[2.74,0]],"id":46292327},{"atb":[[1.75,20],[1.38,0]],"id":65788088}],"con":true,"img":false}]}
{"op":"mcm","clk":"11450449090","pt":1717322170967,"mc":[{"id":"1.229554919","rc":[{"atb":[[1.3,2],[1.31,0]],"id":46292327},{"atl":[[3.8,0]],"id":65788088}],"con":true,"img":false}]}
{"op":"mcm","clk":"11450449095","pt":1717322171070,"mc":[{"id":"1.229554919","rc":[{"atb":[[1.21,182.54],[1.22,0]],"id":46292327}],"con":true,"img":false}]}
{"op":"mcm","clk":"11450449104","pt":1717322171173,"mc":[{"id":"1.229554919","rc":[{"atl":[[4,5],[3.85,0],[3.95,50.68],[3.9,6.9]],"id":65788088}],"con":true,"img":false}]}
{"op":"mcm","clk":"11450449279","pt":1717322173191,"mc":[{"id":"1.229554919","rc":[{"atl":[[3.9,0]],"id":65788088}],"con":true,"img":false}]}
{"op":"mcm","clk":"11450449309","pt":1717322173499,"mc":[{"id":"1.229554919","rc":[{"atl":[[3.95,43.9]],"id":65788088}],"con":true,"img":false}]}
{"op":"mcm","clk":"11450449377","pt":1717322174080,"mc":[{"id":"1.229554919","rc":[{"atl":[[4,0],[4.1,4.84]],"id":65788088}],"con":true,"img":false}]}
{"op":"mcm","clk":"11450449419","pt":1717322174492,"mc":[{"id":"1.229554919","rc":[{"atb":[[1.2,75],[1.21,111.11]],"id":46292327},{"atb":[[1.78,19.23],[1.75,0]],"id":65788088}],"con":true,"img":false}]}
{"op":"mcm","clk":"11450449432","pt":1717322174595,"mc":[{"id":"1.229554919","rc":[{"atl":[[4.3,4.55]],"id":65788088}],"con":true,"img":false}]}
{"op":"mcm","clk":"11450449445","pt":1717322174699,"mc":[{"id":"1.229554919","rc":[{"atl":[[4.1,0]],"id":65788088}],"con":true,"img":false}]}
{"op":"mcm","clk":"11450449584","pt":1717322176098,"mc":[{"id":"1.229554919","rc":[{"atb":[[1.26,2],[1.3,0]],"id":46292327}],"con":true,"img":false}]}
{"op":"mcm","clk":"11450449592","pt":1717322176200,"mc":[{"id":"1.229554919","rc":[{"atb":[[1.2,188.11]],"id":46292327}],"con":true,"img":false}]}
{"op":"mcm","clk":"11450449605","pt":1717322176306,"mc":[{"id":"1.229554919","rc":[{"atb":[[1.21,0]],"id":46292327},{"atl":[[4.6,10],[3.95,0],[8.4,13.51]],"id":65788088}],"con":true,"img":false}]}
{"op":"mcm","clk":"11450449713","pt":1717322177503,"mc":[{"id":"1.229554919","rc":[{"atb":[[1.16,49.04],[1.06,130.79]],"id":46292327},{"atb":[[3.2,3.56],[3.7,2.9]],"id":65788088}],"con":true,"img":false}]}
{"op":"mcm","clk":"11450449744","pt":1717322177815,"mc":[{"id":"1.229554919","rc":[{"atl":[[2.66,26.1]],"id":46292327},{"atl":[[4.2,4.69]],"id":65788088}],"con":true,"img":false}]}
{"op":"mcm","clk":"11450449749","pt":1717322177873,"mc":[{"id":"1.229554919","rc":[{"atl":[[2.92,0]],"id":46292327}],"con":true,"img":false}]}
{"op":"mcm","clk":"11450449879","pt":1717322179479,"mc":[{"id":"1.229554919","rc":[{"atb":[[1.78,0]],"id":65788088}],"con":true,"img":false}]}
{"op":"mcm","clk":"11450449931","pt":1717322180098,"mc":[{"id":"1.229554919","rc":[{"atl":[[4.2,0]],"id":65788088}],"con":true,"img":false}]}
{"op":"mcm","clk":"11450450386","pt":1717322185595,"mc":[{"id":"1.229554919","rc":[{"atl":[[4.5,5.71]],"id":65788088}],"con":true,"img":false}]}
{"op":"mcm","clk":"11450450396","pt":1717322185707,"mc":[{"id":"1.229554919","rc":[{"atl":[[4.6,0],[4.4,20],[8.4,0]],"id":65788088}],"con":true,"img":false}]}
{"op":"mcm","clk":"11450450808","pt":1717322190796,"mc":[{"id":"1.229554919","rc":[{"atl":[[4.5,40.26],[4.4,0]],"id":65788088}],"con":true,"img":false}]}
{"op":"mcm","clk":"11450450989","pt":1717322193126,"mc":[{"id":"1.229554919","rc":[{"atl":[[4.7,6.76]],"id":65788088}],"con":true,"img":false}]}
{"op":"mcm","clk":"11450451264","pt":1717322195830,"mc":[{"id":"1.229554919","rc":[{"atl":[[4.5,15.71],[4.2,4.69],[4.7,33.79]],"id":65788088}],"con":true,"img":false}]}
{"op":"mcm","clk":"11450451273","pt":1717322195883,"mc":[{"id":"1.229554919","rc":[{"atl":[[4.5,24.81],[4.7,6.76]],"id":65788088}],"con":true,"img":false}]}
{"op":"mcm","clk":"11450451378","pt":1717322196922,"mc":[{"id":"1.229554919","rc":[{"atb":[[1.27,10],[1.26,0]],"id":46292327}],"con":true,"img":false}]}
{"op":"mcm","clk":"11450451386","pt":1717322197029,"mc":[{"id":"1.229554919","rc":[{"atb":[[1.2,75],[1.18,301.22]],"id":46292327}],"con":true,"img":false}]}
{"op":"mcm","clk":"11450451573","pt":1717322199004,"mc":[{"id":"1.229554919","rc":[{"atl":[[4.5,14.81],[4.1,4.84],[4.4,10],[4.2,0]],"id":65788088}],"con":true,"img":false}]}
{"op":"mcm","clk":"11450451583","pt":1717322199110,"mc":[{"id":"1.229554919","rc":[{"atl":[[4.3,13.93]],"id":65788088}],"con":true,"img":false}]}
{"op":"mcm","clk":"11450451587","pt":1717322199211,"mc":[{"id":"1.229554919","rc":[{"atl":[[4.5,5.71]],"id":65788088}],"con":true,"img":false}]}
{"op":"mcm","clk":"11450451842","pt":1717322201639,"mc":[{"id":"1.229554919","rc":[{"atl":[[2.1,13.64]],"id":46292327}],"con":true,"img":false}]}
{"op":"mcm","clk":"11450451848","pt":1717322201742,"mc":[{"id":"1.229554919","rc":[{"atl":[[4.1,0],[4.2,4.69]],"id":65788088}],"con":true,"img":false}]}
{"op":"mcm","clk":"11450452074","pt":1717322204296,"mc":[{"id":"1.229554919","rc":[{"atl":[[4.1,4.84]],"id":65788088}],"con":true,"img":false}]}
{"op":"mcm","clk":"11450452088","pt":1717322204451,"mc":[{"id":"1.229554919","rc":[{"atl":[[4,14.84],[4.3,4.54],[4.4,0],[4.2,0]],"id":65788088}],"con":true,"img":false}]}
{"op":"mcm","clk":"11450452092","pt":1717322204510,"mc":[{"id":"1.229554919","rc":[{"atl":[[4,0],[4.2,29.68]],"id":65788088}],"con":true,"img":false}]}
{"op":"mcm","clk":"11450452131","pt":1717322204923,"mc":[{"id":"1.229554919","rc":[{"atb":[[1.28,2],[1.27,0]],"id":46292327}],"con":true,"img":false}]}
{"op":"mcm","clk":"11450452141","pt":1717322205046,"mc":[{"id":"1.229554919","rc":[{"atb":[[1.2,192.65],[1.18,111.11]],"id":46292327}],"con":true,"img":false}]}
{"op":"mcm","clk":"11450452211","pt":1717322205725,"mc":[{"id":"1.229554919","rc":[{"atl":[[4,5],[4.1,0]],"id":65788088}],"con":true,"img":false}]}
{"op":"mcm","clk":"11450452349","pt":1717322207029,"mc":[{"id":"1.229554919","rc":[{"atl":[[4,0],[4.1,4.84]],"id":65788088}],"con":true,"img":false}]}
{"op":"mcm","clk":"11450452359","pt":1717322207132,"mc":[{"id":"1.229554919","rc":[{"atb":[[1.16,0],[1.06,0]],"id":46292327},{"atb":[[3.2,0],[3.7,0]],"id":65788088}],"con":true,"img":false}]}
{"op":"mcm","clk":"11450452371","pt":1717322207247,"mc":[{"id":"1.229554919","rc":[{"atl":[[2.88,27.03],[2.66,0]],"id":46292327},{"atb":[[1.91,0],[1.93,10],[1.76,19.74]],"id":65788088}],"con":true,"img":false}]}
{"op":"mcm","clk":"11450452378","pt":1717322207338,"mc":[{"id":"1.229554919","rc":[{"atb":[[1.4,62.5],[1.37,0]],"id":65788088}],"con":true,"img":false}]}
{"op":"mcm","clk":"11450452498","pt":1717322208750,"mc":[{"id":"1.229554919","rc":[{"atb":[[1.2,117.65],[1.19,78.95]],"id":46292327},{"atb":[[1.68,22.06],[1.76,0]],"id":65788088}],"con":true,"img":false}]}
{"op":"mcm","clk":"11450452574","pt":1717322209442,"mc":[{"id":"1.229554919","rc":[{"atl":[[4.3,34.85],[4.2,10]],"id":65788088}],"con":true,"img":false}]}
{"op":"mcm","clk":"11450452586","pt":1717322209544,"mc":[{"id":"1.229554919","rc":[{"atb":[[1.18,83.33],[1.19,0]],"id":46292327},{"atb":[[1.68,0],[1.77,19.48]],"id":65788088}],"con":true,"img":false}]}
{"op":"mcm","clk":"11450452594","pt":1717322209650,"mc":[{"id":"1.229554919","rc":[{"atl":[[4.3,44.85],[4.2,0]],"id":65788088}],"con":true,"img":false}]}
{"op":"mcm","clk":"11450452603","pt":1717322209751,"mc":[{"id":"1.229554919","rc":[{"atl":[[4.1,0],[4.4,10]],"id":65788088}],"con":true,"img":false}]}
{"op":"mcm","clk":"11450452620","pt":1717322209872,"mc":[{"id":"1.229554919","rc":[{"atl":[[4.3,34.85]],"id":65788088}],"con":true,"img":false}]}
{"op":"mcm","clk":"11450452644","pt":1717322210051,"mc":[{"id":"1.229554919","rc":[{"atb":[[1.28,0],[1.27,2]],"id":46292327}],"con":true,"img":false}]}
{"op":"mcm","clk":"11450452833","pt":1717322212049,"mc":[{"id":"1.229554919","rc":[{"atl":[[4.5,15.71],[4.4,0]],"id":65788088}],"con":true,"img":false}]}
{"op":"mcm","clk":"11450453045","pt":1717322214342,"mc":[{"id":"1.229554919","rc":[{"atl":[[4.3,4.55],[4.7,33.79]],"id":65788088}],"con":true,"img":false}]}
{"op":"mcm","clk":"11450453268","pt":1717322216730,"mc":[{"id":"1.229554919","rc":[{"atb":[[1.16,125]],"id":46292327},{"atb":[[1.75,26.67]],"id":65788088},{"atl":[[4.9,7.69]],"id":65788088}],"con":true,"img":false}]}
{"op":"mcm","clk":"11450453434","pt":1717322218545,"mc":[{"id":"1.229554919","rc":[{"atb":[[1.27,0],[1.26,2]],"id":46292327},{"atb":[[1.32,0]],"id":65788088}],"con":true,"img":false}]}
{"op":"mcm","clk":"11450453643","pt":1717322220646,"mc":[{"id":"1.229554919","rc":[{"atl":[[4.5,5.71],[4.6,10]],"id":65788088}],"con":true,"img":false}]}
{"op":"mcm","clk":"11450453658","pt":1717322220750,"mc":[{"id":"1.229554919","rc":[{"atb":[[1.26,8.61]],"id":46292327},{"atl":[[2.04,5.93]],"id":46292327},{"atb":[[1.94,3.35]],"id":65788088},{"atl":[[4.2,3.14]],"id":65788088}],"con":true,"img":false}]}
{"op":"mcm","clk":"11450453665","pt":1717322220846,"mc":[{"id":"1.229554919","rc":[{"atb":[[1.27,83.33]],"id":46292327},{"atl":[[4.1,4.55]],"id":65788088}],"con":true,"img":false}]}
{"op":"mcm","clk":"11450453678","pt":1717322220955,"mc":[{"id":"1.229554919","rc":[{"atb":[[1.2,0]],"id":46292327},{"atl":[[4.7,6.76]],"id":65788088}],"con":true,"img":false}]}
{"op":"mcm","clk":"11450454069","pt":1717322225361,"mc":[{"id":"1.229554919","rc":[{"atb":[[1.16,174.04],[1.06,130.79]],"id":46292327},{"atb":[[3.2,3.56],[3.7,2.9]],"id":65788088}],"con":true,"img":false}]}
{"op":"mcm","clk":"11450454094","pt":1717322225573,"mc":[{"id":"1.229554919","rc":[{"atl":[[2.88,0],[2.64,26.1]],"id":46292327}],"con":true,"img":false}]}
{"op":"mcm","clk":"11450454116","pt":1717322225774,"mc":[{"id":"1.229554919","rc":[{"atl":[[4.6,0],[4.1,14.55]],"id":65788088}],"con":true,"img":false}]}
{"op":"mcm","clk":"11450454149","pt":1717322226045,"mc":[{"id":"1.229554919","rc":[{"atb":[[1.18,0],[1.19,78.95]],"id":46292327}],"con":true,"img":false}]}
{"op":"mcm","clk":"11450454794","pt":1717322232660,"mc":[{"id":"1.229554919","rc":[{"atl":[[4.3,0]],"id":65788088}],"con":true,"img":false}]}
{"op":"mcm","clk":"11450454810","pt":1717322232881,"mc":[{"id":"1.229554919","rc":[{"atl":[[4.4,4.41]],"id":65788088}],"con":true,"img":false}]}
{"op":"mcm","clk":"11450454862","pt":1717322233384,"mc":[{"id":"1.229554919","rc":[{"atb":[[1.27,85.33],[1.26,6.61]],"id":46292327}],"con":true,"img":false}]}
{"op":"mcm","clk":"11450455328","pt":1717322237454,"mc":[{"id":"1.229554919","rc":[{"atb":[[1.28,2],[1.27,83.33]],"id":46292327}],"con":true,"img":false}]}
{"op":"mcm","clk":"11450455381","pt":1717322238075,"mc":[{"id":"1.229554919","rc":[{"atl":[[4,3.14]],"id":65788088}],"con":true,"img":false}]}
{"op":"mcm","clk":"11450455395","pt":1717322238187,"mc":[{"id":"1.229554919","rc":[{"atb":[[1.28,8.62]],"id":46292327},{"atl":[[3.95,3.14]],"id":65788088}],"con":true,"img":false}]}
{"op":"mcm","clk":"11450455404","pt":1717322238287,"mc":[{"id":"1.229554919","rc":[{"atl":[[3.95,13.14],[4.1,0]],"id":65788088}],"con":true,"img":false}]}
{"op":"mcm","clk":"11450455409","pt":1717322238345,"mc":[{"id":"1.229554919","rc":[{"atb":[[1.27,0],[1.29,8.62]],"id":46292327}],"con":true,"img":false}]}
{"op":"mcm","clk":"11450455629","pt":1717322240848,"mc":[{"id":"1.229554919","rc":[{"atl":[[4.4,0],[4.2,7.83]],"id":65788088}],"con":true,"img":false}]}
{"op":"mcm","clk":"11450455851","pt":1717322243290,"mc":[{"id":"1.229554919","rc":[{"atl":[[4.4,4.41],[4.2,3.14]],"id":65788088}],"con":true,"img":false}]}
{"op":"mcm","clk":"11450456567","pt":1717322250391,"mc":[{"id":"1.229554919","rc":[{"atb":[[1.28,6.62],[1.35,2.96]],"id":46292327},{"atl":[[3.95,3.14],[3.75,10]],"id":65788088}],"con":true,"img":false}]}
{"op":"mcm","clk":"11450456611","pt":1717322250803,"mc":[{"id":"1.229554919","rc":[{"atb":[[1.34,2],[1.35,0]],"id":46292327}],"con":true,"img":false}]}
{"op":"mcm","clk":"11450456620","pt":1717322250907,"mc":[{"id":"1.229554919","rc":[{"atb":[[1.29,0],[1.31,6.62]],"id":46292327}],"con":true,"img":false}]}
{"op":"mcm","clk":"11450456756","pt":1717322252265,"mc":[{"id":"1.229554919","rc":[{"atl":[[3.95,13.14],[3.75,0]],"id":65788088}],"con":true,"img":false}]}
{"op":"mcm","clk":"11450456992","pt":1717322254912,"mc":[{"id":"1.229554919","rc":[{"atb":[[1.19,0]],"id":46292327}],"con":true,"img":false}]}
{"op":"mcm","clk":"11450457036","pt":1717322255279,"mc":[{"id":"1.229554919","rc":[{"atb":[[1.29,8.62],[1.31,0]],"id":46292327}],"con":true,"img":false}]}
{"op":"mcm","clk":"11450457111","pt":1717322255902,"mc":[{"id":"1.229554919","rc":[{"atb":[[1.3,2]],"id":46292327}],"con":true,"img":false}]}
{"op":"mcm","clk":"11450457120","pt":1717322256006,"mc":[{"id":"1.229554919","rc":[{"atb":[[1.34,0]],"id":46292327}],"con":true,"img":false}]}
{"op":"mcm","clk":"11450457151","pt":1717322256269,"mc":[{"id":"1.229554919","rc":[{"atl":[[4.4,0],[4.2,7.83]],"id":65788088}],"con":true,"img":false}]}
{"op":"mcm","clk":"11450457268","pt":1717322257412,"mc":[{"id":"1.229554919","rc":[{"atb":[[1.3,8.51]],"id":46292327},{"atl":[[3.9,3.17]],"id":65788088}],"con":true,"img":false}]}
{"op":"mcm","clk":"11450457280","pt":1717322257517,"mc":[{"id":"1.229554919","rc":[{"atb":[[1.29,0],[1.31,8.52]],"id":46292327},{"atl":[[3.85,13.18],[3.95,0]],"id":65788088}],"con":true,"img":false}]}
{"op":"mcm","clk":"11450457315","pt":1717322257891,"mc":[{"id":"1.229554919","rc":[{"atb":[[1.16,125],[1.06,0]],"id":46292327},{"atb":[[3.2,0],[3.7,0]],"id":65788088}],"con":true,"img":false}]}
{"op":"mcm","clk":"11450457333","pt":1717322258093,"mc":[{"id":"1.229554919","rc":[{"atl":[[2.88,26.78],[2.64,0]],"id":46292327}],"con":true,"img":false}]}
{"op":"mcm","clk":"11450457614","pt":1717322261266,"mc":[{"id":"1.229554919","rc":[{"atl":[[4.2,3.14],[4.7,4.05]],"id":65788088}],"con":true,"img":false}]}
{"op":"mcm","clk":"11450457657","pt":1717322261682,"mc":[{"id":"1.229554919","rc":[{"atl":[[4.5,0]],"id":65788088}],"con":true,"img":false}]}
{"op":"mcm","clk":"11450457686","pt":1717322262091,"mc":[{"id":"1.229554919","rc":[{"atl":[[4.7,0]],"id":65788088}],"con":true,"img":false}]}
{"op":"mcm","clk":"11450457982","pt":1717322265199,"mc":[{"id":"1.229554919","rc":[{"atb":[[1.15,218.98],[1.05,156.95]],"id":46292327},{"atb":[[3.8,2.8],[3.3,3.41]],"id":65788088}],"con":true,"img":false}]}
{"op":"mcm","clk":"11450458022","pt":1717322265401,"mc":[{"id":"1.229554919","rc":[{"atl":[[2.88,0],[2.64,26.1]],"id":46292327}],"con":true,"img":false}]}
{"op":"mcm","clk":"11450458314","pt":1717322269241,"mc":[{"id":"1.229554919","rc":[{"atl":[[4.9,0]],"id":65788088}],"con":true,"img":false}]}
{"op":"mcm","clk":"11450458857","pt":1717322276030,"mc":[{"id":"1.229554919","rc":[{"atb":[[1.15,166.67],[1.05,0]],"id":46292327},{"atb":[[3.8,0],[3.3,0]],"id":65788088}],"con":true,"img":false}]}
{"op":"mcm","clk":"11450458880","pt":1717322276185,"mc":[{"id":"1.229554919","rc":[{"atl":[[2.88,26.78],[2.64,0]],"id":46292327}],"con":true,"img":false}]}
{"op":"mcm","clk":"11450459240","pt":1717322280646,"mc":[{"id":"1.229554919","rc":[{"atb":[[1.12,65.39],[1.02,392.38]],"id":46292327},{"atb":[[3.5,3.13]],"id":65788088},{"trd":[[3.85,5.23]],"ltp":3.85,"tv":5.23,"id":65788088},{"atl":[[3.85,10.56]],"id":65788088}],"con":true,"img":false}]}
{"op":"mcm","clk":"11450459247","pt":1717322280703,"mc":[{"id":"1.229554919","rc":[{"atb":[[3.5,0]],"id":65788088},{"trd":[[3.5,6.27]],"ltp":3.5,"tv":6.27,"id":65788088}],"con":true,"img":false}]}
{"op":"mcm","clk":"11450459323","pt":1717322281435,"mc":[{"id":"1.229554919","rc":[{"atb":[[1.16,0],[1.15,0],[1.17,0]],"id":46292327}],"con":true,"img":false}]}
{"op":"mcm","clk":"11450462274","pt":1717322316228,"mc":[{"id":"1.229554919","rc":[{"atb":[[1.27,65.4],[1.31,0]],"id":46292327},{"atl":[[2.88,0],[2.06,0],[2.04,30.35],[2.1,0],[2.7,26.1]],"id":46292327},{"atb":[[1.4,0],[1.55,62.5]],"id":65788088}],"con":true,"img":false}]}
{"op":"mcm","clk":"11450462362","pt":1717322317420,"mc":[{"id":"1.229554919","rc":[{"atb":[[1.92,10],[1.93,0]],"id":65788088}],"con":true,"img":false}]}
{"op":"mcm","clk":"11450462676","pt":1717322321434,"mc":[{"id":"1.229554919","rc":[{"atb":[[1.27,0],[1.31,8.52]],"id":46292327},{"atl":[[2.48,29.78],[2.7,0]],"id":46292327}],"con":true,"img":false}]}
{"op":"mcm","clk":"11450462685","pt":1717322321588,"mc":[{"id":"1.229554919","rc":[{"atl":[[2.08,18.52]],"id":46292327}],"con":true,"img":false}]}
{"op":"mcm","clk":"11450462693","pt":1717322321691,"mc":[{"id":"1.229554919","rc":[{"atl":[[2.22,0],[2.18,0]],"id":46292327}],"con":true,"img":false}]}
{"op":"mcm","clk":"11450462767","pt":1717322322623,"mc":[{"id":"1.229554919","rc":[{"atb":[[1.93,10]],"id":65788088}],"con":true,"img":false}]}
{"op":"mcm","clk":"11450462775","pt":1717322322724,"mc":[{"id":"1.229554919","rc":[{"atb":[[1.92,0]],"id":65788088}],"con":true,"img":false}]}
{"op":"mcm","clk":"11450462852","pt":1717322323506,"mc":[{"id":"1.229554919","rc":[{"atl":[[2.02,14.71]],"id":46292327}],"con":true,"img":false}]}
{"op":"mcm","clk":"11450462892","pt":1717322323918,"mc":[{"id":"1.229554919","rc":[{"atl":[[2,7.02]],"id":46292327}],"con":true,"img":false}]}
{"op":"mcm","clk":"11450463249","pt":1717322327812,"mc":[{"id":"1.229554919","rc":[{"atb":[[1.92,10],[1.93,0]],"id":65788088}],"con":true,"img":false}]}
{"op":"mcm","clk":"11450463325","pt":1717322328694,"mc":[{"id":"1.229554919","rc":[{"atl":[[2.02,0]],"id":46292327},{"atb":[[1.77,0]],"id":65788088}],"con":true,"img":false}]}
{"op":"mcm","clk":"11450463334","pt":1717322328799,"mc":[{"id":"1.229554919","rc":[{"atl":[[2.12,22.32]],"id":46292327}],"con":true,"img":false}]}
{"op":"mcm","clk":"11450463658","pt":1717322332523,"mc":[{"id":"1.229554919","rc":[{"atl":[[2.06,14.15],[2.04,15.93]],"id":46292327},{"atb":[[1.75,0]],"id":65788088}],"con":true,"img":false}]}
{"op":"mcm","clk":"11450463783","pt":1717322334335,"mc":[{"id":"1.229554919","rc":[{"atb":[[1.12,0],[1.02,0]],"id":46292327}],"con":true,"img":false}]}
{"op":"mcm","clk":"11450463905","pt":1717322335614,"mc":[{"id":"1.229554919","rc":[{"atl":[[2.04,30.35]],"id":46292327}],"con":true,"img":false}]}
{"op":"mcm","clk":"11450464029","pt":1717322336750,"mc":[{"id":"1.229554919","rc":[{"atl":[[2,22.02],[2.02,14.71],[2.04,15.93]],"id":46292327}],"con":true,"img":false}]}
{"op":"mcm","clk":"11450464136","pt":1717322338107,"mc":[{"id":"1.229554919","rc":[{"atl":[[2,7.02],[2.02,0],[2.06,0],[2.04,30.35]],"id":46292327}],"con":true,"img":false}]}
{"op":"mcm","clk":"11450464368","pt":1717322340731,"mc":[{"id":"1.229554919","rc":[{"atl":[[1.95,15.79]],"id":46292327}],"con":true,"img":false}]}
{"op":"mcm","clk":"11450464384","pt":1717322340934,"mc":[{"id":"1.229554919","rc":[{"atl":[[1.96,15.62],[1.95,0]],"id":46292327}],"con":true,"img":false}]}
{"op":"mcm","clk":"11450464613","pt":1717322343327,"mc":[{"id":"1.229554919","rc":[{"atl":[[2,22.02],[1.96,0]],"id":46292327}],"con":true,"img":false}]}
{"op":"mcm","clk":"11450464926","pt":1717322346643,"mc":[{"id":"1.229554919","rc":[{"atl":[[1.98,15.31]],"id":46292327}],"con":true,"img":false}]}
{"op":"mcm","clk":"11450464936","pt":1717322346750,"mc":[{"id":"1.229554919","rc":[{"atl":[[2,7.02]],"id":46292327}],"con":true,"img":false}]}
{"op":"mcm","clk":"11450464963","pt":1717322347067,"mc":[{"id":"1.229554919","rc":[{"atl":[[1.98,0]],"id":46292327}],"con":true,"img":false}]}
{"op":"mcm","clk":"11450465255","pt":1717322350533,"mc":[{"id":"1.229554919","rc":[{"atb":[[1.6,62.5],[1.55,0]],"id":65788088}],"con":true,"img":false}]}
{"op":"mcm","clk":"11450465320","pt":1717322351357,"mc":[{"id":"1.229554919","rc":[{"atl":[[2.02,14.71]],"id":46292327}],"con":true,"img":false}]}
{"op":"mcm","clk":"11450465342","pt":1717322351665,"mc":[{"id":"1.229554919","rc":[{"atl":[[1.99,15.15],[2.02,0]],"id":46292327}],"con":true,"img":false}]}
{"op":"mcm","clk":"11450465438","pt":1717322352857,"mc":[{"id":"1.229554919","rc":[{"atl":[[1.99,0],[2.02,14.71]],"id":46292327}],"con":true,"img":false}]}
{"op":"mcm","clk":"11450465493","pt":1717322353531,"mc":[{"id":"1.229554919","rc":[{"atl":[[2.02,0]],"id":46292327}],"con":true,"img":false}]}
{"op":"mcm","clk":"11450465498","pt":1717322353642,"mc":[{"id":"1.229554919","rc":[{"atl":[[1.99,15.15]],"id":46292327}],"con":true,"img":false}]}
{"op":"mcm","clk":"11450465636","pt":1717322355351,"mc":[{"id":"1.229554919","rc":[{"atl":[[1.99,0],[2.02,14.71]],"id":46292327}],"con":true,"img":false}]}
{"op":"mcm","clk":"11450465676","pt":1717322355763,"mc":[{"id":"1.229554919","rc":[{"atl":[[2.02,0]],"id":46292327}],"con":true,"img":false}]}
{"op":"mcm","clk":"11450465730","pt":1717322356489,"mc":[{"id":"1.229554919","rc":[{"atl":[[2.02,14.71]],"id":46292327}],"con":true,"img":false}]}
{"op":"mcm","clk":"11450465811","pt":1717322357586,"mc":[{"id":"1.229554919","rc":[{"atl":[[1.98,15.31]],"id":46292327}],"con":true,"img":false}]}
{"op":"mcm","clk":"11450465818","pt":1717322357689,"mc":[{"id":"1.229554919","rc":[{"atl":[[2.02,0]],"id":46292327}],"con":true,"img":false}]}
{"op":"mcm","clk":"11450465880","pt":1717322358598,"mc":[{"id":"1.229554919","rc":[{"atl":[[2.02,3.26],[1.98,0],[2.04,20.35],[1.94,15.96]],"id":46292327}],"con":true,"img":false}]}
{"op":"mcm","clk":"11450465884","pt":1717322358665,"mc":[{"id":"1.229554919","rc":[{"atb":[[1.94,13.35]],"id":65788088}],"con":true,"img":false}]}
{"op":"mcm","clk":"11450465893","pt":1717322358776,"mc":[{"id":"1.229554919","rc":[{"atb":[[1.92,0]],"id":65788088}],"con":true,"img":false}]}
{"op":"mcm","clk":"11450466229","pt":1717322362965,"mc":[{"id":"1.229554919","rc":[{"atl":[[1.99,15.15],[1.94,0]],"id":46292327}],"con":true,"img":false}]}
{"op":"mcm","clk":"11450466388","pt":1717322364773,"mc":[{"id":"1.229554919","rc":[{"atl":[[1.99,0],[1.98,15.31]],"id":46292327}],"con":true,"img":false}]}
{"op":"mcm","clk":"11450466683","pt":1717322368194,"mc":[{"id":"1.229554919","rc":[{"atl":[[1.98,0],[1.97,15.46]],"id":46292327},{"atb":[[1.6,0],[1.65,62.5]],"id":65788088}],"con":true,"img":false}]}
{"op":"mcm","clk":"11450466692","pt":1717322368300,"mc":[{"id":"1.229554919","rc":[{"atl":[[1.94,15.96]],"id":46292327}],"con":true,"img":false}]}
{"op":"mcm","clk":"11450466698","pt":1717322368405,"mc":[{"id":"1.229554919","rc":[{"atl":[[1.97,0]],"id":46292327}],"con":true,"img":false}]}
{"op":"mcm","clk":"11450466718","pt":1717322368715,"mc":[{"id":"1.229554919","rc":[{"atl":[[2.38,34.48],[2.48,0]],"id":46292327}],"con":true,"img":false}]}
{"op":"mcm","clk":"11450467103","pt":1717322372774,"mc":[{"id":"1.229554919","rc":[{"atl":[[1.96,20.83]],"id":46292327}],"con":true,"img":false}]}
{"op":"mcm","clk":"11450467175","pt":1717322373601,"mc":[{"id":"1.229554919","rc":[{"atl":[[2.12,0]],"id":46292327}],"con":true,"img":false}]}
{"op":"mcm","clk":"11450467243","pt":1717322374395,"mc":[{"id":"1.229554919","rc":[{"atb":[[1.32,7.92]],"id":46292327},{"atl":[[3.8,2.78]],"id":65788088}],"con":true,"img":false}]}
{"op":"mcm","clk":"11450467252","pt":1717322374494,"mc":[{"id":"1.229554919","rc":[{"atb":[[1.33,3.26]],"id":46292327}],"con":true,"img":false}]}
{"op":"mcm","clk":"11450467261","pt":1717322374588,"mc":[{"id":"1.229554919","rc":[{"atb":[[1.3,6.51]],"id":46292327}],"con":true,"img":false}]}
{"op":"mcm","clk":"11450467275","pt":1717322374791,"mc":[{"id":"1.229554919","rc":[{"atb":[[1.03,475.09],[1.13,82.49]],"id":46292327},{"atb":[[2.4,0.14],[2.6,0.12]],"id":65788088}],"con":true,"img":false}]}
{"op":"mcm","clk":"11450467293","pt":1717322375004,"mc":[{"id":"1.229554919","rc":[{"atb":[[1.26,0],[1.34,7.91]],"id":46292327},{"atl":[[2.38,0],[2.18,34.48]],"id":46292327}],"con":true,"img":false}]}
{"op":"mcm","clk":"11450467310","pt":1717322375215,"mc":[{"id":"1.229554919","rc":[{"atl":[[1.94,0],[1.95,15.79]],"id":46292327}],"con":true,"img":false}]}
{"op":"mcm","clk":"11450467459","pt":1717322376874,"mc":[{"id":"1.229554919","rc":[{"atb":[[1.32,19.09]],"id":46292327}],"con":true,"img":false}]}
{"op":"mcm","clk":"11450467468","pt":1717322376979,"mc":[{"id":"1.229554919","rc":[{"atb":[[1.31,0]],"id":46292327}],"con":true,"img":false}]}
{"op":"mcm","clk":"11450467656","pt":1717322379606,"mc":[{"id":"1.229554919","rc":[{"atb":[[1.35,10]],"id":46292327},{"atl":[[1.97,20.62]],"id":46292327}],"con":true,"img":false}]}
{"op":"mcm","clk":"11450467663","pt":1717322379711,"mc":[{"id":"1.229554919","rc":[{"atb":[[1.33,0]],"id":46292327}],"con":true,"img":false}]}
{"op":"mcm","clk":"11450467702","pt":1717322380078,"mc":[{"id":"1.229554919","rc":[{"atl":[[2.04,5.93],[1.96,0],[2.08,0]],"id":46292327}],"con":true,"img":false}]}
{"op":"mcm","clk":"11450468007","pt":1717322383602,"mc":[{"id":"1.229554919","rc":[{"atl":[[1.96,15.62],[1.95,0]],"id":46292327}],"con":true,"img":false}]}
{"op":"mcm","clk":"11450468277","pt":1717322386704,"mc":[{"id":"1.229554919","rc":[{"atl":[[1.98,15.31]],"id":46292327}],"con":true,"img":false}]}
{"op":"mcm","clk":"11450468287","pt":1717322386811,"mc":[{"id":"1.229554919","rc":[{"atl":[[1.96,0]],"id":46292327}],"con":true,"img":false}]}
{"op":"mcm","clk":"11450468369","pt":1717322387900,"mc":[{"id":"1.229554919","rc":[{"atl":[[1.97,15.46]],"id":46292327}],"con":true,"img":false}]}
{"op":"mcm","clk":"11450468446","pt":1717322388901,"mc":[{"id":"1.229554919","rc":[{"atl":[[1.97,0]],"id":46292327}],"con":true,"img":false}]}
{"op":"mcm","clk":"11450468465","pt":1717322389103,"mc":[{"id":"1.229554919","rc":[{"atl":[[1.97,15.46]],"id":46292327}],"con":true,"img":false}]}
{"op":"mcm","clk":"11450468485","pt":1717322389312,"mc":[{"id":"1.229554919","rc":[{"atl":[[1.97,0]],"id":46292327}],"con":true,"img":false}]}
{"op":"mcm","clk":"11450468553","pt":1717322389889,"mc":[{"id":"1.229554919","rc":[{"atl":[[1.99,15.15],[1.98,0],[1.97,15.46]],"id":46292327}],"con":true,"img":false}]}
{"op":"mcm","clk":"11450468620","pt":1717322390817,"mc":[{"id":"1.229554919","rc":[{"atb":[[1.36,7.88]],"id":46292327},{"atl":[[1.98,15.31],[1.97,0],[1.96,7.59]],"id":46292327}],"con":true,"img":false}]}
{"op":"mcm","clk":"11450468628","pt":1717322390918,"mc":[{"id":"1.229554919","rc":[{"atb":[[1.28,0],[1.37,15.49],[1.35,0]],"id":46292327},{"atb":[[2.6,2.95]],"id":65788088}],"con":true,"img":false}]}
{"op":"mcm","clk":"11450468674","pt":1717322391604,"mc":[{"id":"1.229554919","rc":[{"atl":[[1.96,23.21]],"id":46292327}],"con":true,"img":false}]}
{"op":"mcm","clk":"11450468704","pt":1717322391914,"mc":[{"id":"1.229554919","rc":[{"atl":[[1.96,7.59]],"id":46292327}],"con":true,"img":false}]}
{"op":"mcm","clk":"11450468813","pt":1717322393104,"mc":[{"id":"1.229554919","rc":[{"atl":[[1.98,0]],"id":46292327}],"con":true,"img":false}]}
{"op":"mcm","clk":"11450468903","pt":1717322394045,"mc":[{"id":"1.229554919","rc":[{"atl":[[1.96,23.21]],"id":46292327},{"atb":[[1.7,62.5],[1.65,0]],"id":65788088}],"con":true,"img":false}]}
{"op":"mcm","clk":"11450468953","pt":1717322394612,"mc":[{"id":"1.229554919","rc":[{"atl":[[1.98,15.31],[1.96,7.59]],"id":46292327}],"con":true,"img":false}]}
{"op":"mcm","clk":"11450468975","pt":1717322394818,"mc":[{"id":"1.229554919","rc":[{"atl":[[1.96,23.21]],"id":46292327}],"con":true,"img":false}]}
{"op":"mcm","clk":"11450468983","pt":1717322394921,"mc":[{"id":"1.229554919","rc":[{"atb":[[1.38,7.85]],"id":46292327}],"con":true,"img":false}]}
{"op":"mcm","clk":"11450468989","pt":1717322395026,"mc":[{"id":"1.229554919","rc":[{"atb":[[1.37,0],[1.3,0],[1.39,10]],"id":46292327}],"con":true,"img":false}]}
{"op":"mcm","clk":"11450469080","pt":1717322396016,"mc":[{"id":"1.229554919","rc":[{"atb":[[1.4,7.82]],"id":46292327}],"con":true,"img":false}]}
{"op":"mcm","clk":"11450469091","pt":1717322396117,"mc":[{"id":"1.229554919","rc":[{"atb":[[1.32,11.17]],"id":46292327}],"con":true,"img":false}]}
{"op":"mcm","clk":"11450469126","pt":1717322396532,"mc":[{"id":"1.229554919","rc":[{"atl":[[1.96,7.59]],"id":46292327}],"con":true,"img":false}]}
{"op":"mcm","clk":"11450469189","pt":1717322397416,"mc":[{"id":"1.229554919","rc":[{"atl":[[1.98,0]],"id":46292327}],"con":true,"img":false}]}
{"op":"mcm","clk":"11450469254","pt":1717322398201,"mc":[{"id":"1.229554919","rc":[{"atl":[[1.97,15.46]],"id":46292327}],"con":true,"img":false}]}
{"op":"mcm","clk":"11450469292","pt":1717322398718,"mc":[{"id":"1.229554919","rc":[{"atl":[[2.02,17.97]],"id":46292327}],"con":true,"img":false}]}
{"op":"mcm","clk":"11450469300","pt":1717322398826,"mc":[{"id":"1.229554919","rc":[{"atl":[[1.97,0]],"id":46292327}],"con":true,"img":false}]}
{"op":"mcm","clk":"11450469412","pt":1717322400124,"mc":[{"id":"1.229554919","rc":[{"atb":[[1.41,14.63],[1.39,0]],"id":46292327}],"con":true,"img":false}]}
{"op":"mcm","clk":"11450469424","pt":1717322400235,"mc":[{"id":"1.229554919","rc":[{"atl":[[1.97,15.46]],"id":46292327}],"con":true,"img":false}]}
{"op":"mcm","clk":"11450469500","pt":1717322400746,"mc":[{"id":"1.229554919","rc":[{"atl":[[1.96,23.21]],"id":46292327}],"con":true,"img":false}]}
{"op":"mcm","clk":"11450470559","pt":1717322409924,"mc":[{"id":"1.229554919","rc":[{"atl":[[2.02,14.71],[1.98,10]],"id":46292327}],"con":true,"img":false}]}
{"op":"mcm","clk":"11450470615","pt":1717322410661,"mc":[{"id":"1.229554919","rc":[{"atb":[[1.42,7.65],[1.34,0]],"id":46292327}],"con":true,"img":false}]}
{"op":"mcm","clk":"11450470631","pt":1717322410845,"mc":[{"id":"1.229554919","rc":[{"atb":[[1.41,0],[1.43,10]],"id":46292327},{"atl":[[1.96,7.59]],"id":46292327}],"con":true,"img":false}]}
{"op":"mcm","clk":"11450470641","pt":1717322410924,"mc":[{"id":"1.229554919","rc":[{"atl":[[2,22.02]],"id":46292327},{"atb":[[1.99,10],[1.94,3.35]],"id":65788088}],"con":true,"img":false}]}
{"op":"mcm","clk":"11450470675","pt":1717322411239,"mc":[{"id":"1.229554919","rc":[{"atb":[[1.36,0],[1.43,17.58]],"id":46292327},{"atl":[[1.97,0]],"id":46292327}],"con":true,"img":false}]}
{"op":"mcm","clk":"11450470696","pt":1717322411445,"mc":[{"id":"1.229554919","rc":[{"atl":[[1.99,0]],"id":46292327},{"atb":[[1.7,0],[1.75,62.5]],"id":65788088}],"con":true,"img":false}]}
{"op":"mcm","clk":"11450470719","pt":1717322411661,"mc":[{"id":"1.229554919","rc":[{"atb":[[1.44,7.46],[1.38,0]],"id":46292327}],"con":true,"img":false}]}
{"op":"mcm","clk":"11450470726","pt":1717322411759,"mc":[{"id":"1.229554919","rc":[{"atb":[[1.34,82.5]],"id":46292327},{"atl":[[1.99,15.19]],"id":46292327}],"con":true,"img":false}]}
{"op":"mcm","clk":"11450470737","pt":1717322411820,"mc":[{"id":"1.229554919","rc":[{"atb":[[1.43,7.58],[1.45,15.05],[1.32,0]],"id":46292327},{"atl":[[1.98,0]],"id":46292327}],"con":true,"img":false}]}
{"op":"mcm","clk":"11450470861","pt":1717322412920,"mc":[{"id":"1.229554919","rc":[{"atb":[[1.4,0],[1.46,7.18]],"id":46292327}],"con":true,"img":false}]}
{"op":"mcm","clk":"11450470870","pt":1717322413025,"mc":[{"id":"1.229554919","rc":[{"atb":[[1.47,14.22]],"id":46292327}],"con":true,"img":false}]}
{"op":"mcm","clk":"11450470883","pt":1717322413129,"mc":[{"id":"1.229554919","rc":[{"atb":[[1.45,0]],"id":46292327}],"con":true,"img":false}]}
{"op":"mcm","clk":"11450470914","pt":1717322413441,"mc":[{"id":"1.229554919","rc":[{"atb":[[1.47,21.34]],"id":46292327}],"con":true,"img":false}]}
{"op":"mcm","clk":"11450470925","pt":1717322413546,"mc":[{"id":"1.229554919","rc":[{"atb":[[1.42,0]],"id":46292327}],"con":true,"img":false}]}
{"op":"mcm","clk":"11450471029","pt":1717322414747,"mc":[{"id":"1.229554919","rc":[{"atl":[[2.04,25.16]],"id":46292327}],"con":true,"img":false}]}
{"op":"mcm","clk":"11450471156","pt":1717322415947,"mc":[{"id":"1.229554919","rc":[{"atl":[[2,7.02],[2.04,20.35]],"id":46292327}],"con":true,"img":false}]}
{"op":"mcm","clk":"11450471194","pt":1717322416360,"mc":[{"id":"1.229554919","rc":[{"atl":[[2.02,0]],"id":46292327}],"con":true,"img":false}]}
{"op":"mcm","clk":"11450471289","pt":1717322417041,"mc":[{"id":"1.229554919","rc":[{"atb":[[1.43,0],[1.48,7.02]],"id":46292327}],"con":true,"img":false}]}
{"op":"mcm","clk":"11450471396","pt":1717322418132,"mc":[{"id":"1.229554919","rc":[{"atb":[[1.49,14.15]],"id":46292327}],"con":true,"img":false}]}
{"op":"mcm","clk":"11450471407","pt":1717322418268,"mc":[{"id":"1.229554919","rc":[{"atb":[[1.47,7.12]],"id":46292327}],"con":true,"img":false}]}
{"op":"mcm","clk":"11450471577","pt":1717322419660,"mc":[{"id":"1.229554919","rc":[{"atl":[[2.08,18.52]],"id":46292327}],"con":true,"img":false}]}
{"op":"mcm","clk":"11450471604","pt":1717322419969,"mc":[{"id":"1.229554919","rc":[{"atb":[[1.48,0]],"id":46292327}],"con":true,"img":false}]}
{"op":"mcm","clk":"11450471745","pt":1717322421332,"mc":[{"id":"1.229554919","rc":[{"atb":[[1.49,0]],"id":46292327},{"trd":[[1.49,28.3]],"ltp":1.49,"tv":28.3,"id":46292327},{"atl":[[1.48,0.9]],"id":46292327}],"con":true,"img":false}]}
{"op":"mcm","clk":"11450471757","pt":1717322421439,"mc":[{"id":"1.229554919","rc":[{"trd":[[1.48,1.81]],"ltp":1.48,"tv":1.81,"id":46292327},{"atl":[[1.48,0],[1.95,7.16]],"id":46292327}],"con":true,"img":false}]}
{"op":"mcm","clk":"11450471784","pt":1717322421660,"mc":[{"id":"1.229554919","rc":[{"atb":[[1.47,21.43]],"id":46292327}],"con":true,"img":false}]}
{"op":"mcm","clk":"11450471811","pt":1717322421853,"mc":[{"id":"1.229554919","rc":[{"atl":[[1.94,1.28]],"id":46292327},{"atl":[[3.75,1.45]],"id":65788088}],"con":true,"img":false}]}
{"op":"mcm","clk":"11450471822","pt":1717322421955,"mc":[{"id":"1.229554919","rc":[{"atl":[[3.85,0],[3.75,14.23]],"id":65788088}],"con":true,"img":false}]}
{"op":"mcm","clk":"11450471844","pt":1717322422165,"mc":[{"id":"1.229554919","rc":[{"atl":[[1.94,8.23]],"id":46292327}],"con":true,"img":false}]}
{"op":"mcm","clk":"11450471965","pt":1717322423362,"mc":[{"id":"1.229554919","rc":[{"atl":[[2.12,22.32]],"id":46292327}],"con":true,"img":false}]}
{"op":"mcm","clk":"11450472000","pt":1717322423631,"mc":[{"id":"1.229554919","rc":[{"atl":[[2.02,14.71],[1.95,0]],"id":46292327}],"con":true,"img":false}]}
{"op":"mcm","clk":"11450472278","pt":1717322426239,"mc":[{"id":"1.229554919","rc":[{"atl":[[2,22.02],[2.02,0]],"id":46292327}],"con":true,"img":false}]}
{"op":"mcm","clk":"11450472407","pt":1717322427670,"mc":[{"id":"1.229554919","rc":[{"atl":[[1.93,7.32]],"id":46292327}],"con":true,"img":false}]}
{"op":"mcm","clk":"11450472427","pt":1717322427878,"mc":[{"id":"1.229554919","rc":[{"atl":[[1.94,6.94]],"id":46292327}],"con":true,"img":false}]}
{"op":"mcm","clk":"11450472437","pt":1717322427934,"mc":[{"id":"1.229554919","rc":[{"atb":[[1.47,14.31]],"id":46292327},{"atl":[[1.92,8.33],[2.04,14.42]],"id":46292327}],"con":true,"img":false}]}
{"op":"mcm","clk":"11450472781","pt":1717322431275,"mc":[{"id":"1.229554919","rc":[{"atl":[[1.93,0]],"id":46292327}],"con":true,"img":false}]}
{"op":"mcm","clk":"11450472806","pt":1717322431490,"mc":[{"id":"1.229554919","rc":[{"atl":[[3.7,2.94],[4.2,0]],"id":65788088}],"con":true,"img":false}]}
{"op":"mcm","clk":"11450472872","pt":1717322432064,"mc":[{"id":"1.229554919","rc":[{"atl":[[3.75,12.78]],"id":65788088}],"con":true,"img":false}]}
{"op":"mcm","clk":"11450472884","pt":1717322432167,"mc":[{"id":"1.229554919","rc":[{"atl":[[3.65,1.45]],"id":65788088}],"con":true,"img":false}]}
{"op":"mcm","clk":"11450472893","pt":1717322432272,"mc":[{"id":"1.229554919","rc":[{"atl":[[3.65,14.39],[3.75,0]],"id":65788088}],"con":true,"img":false}]}
{"op":"mcm","clk":"11450473045","pt":1717322433783,"mc":[{"id":"1.229554919","rc":[{"atl":[[1.91,7.53]],"id":46292327}],"con":true,"img":false}]}
{"op":"mcm","clk":"11450473051","pt":1717322433834,"mc":[{"id":"1.229554919","rc":[{"atl":[[2,7.02],[1.99,30.34]],"id":46292327}],"con":true,"img":false}]}
{"op":"mcm","clk":"11450473117","pt":1717322434563,"mc":[{"id":"1.229554919","rc":[{"atl":[[1.92,7.04]],"id":46292327}],"con":true,"img":false}]}
{"op":"mcm","clk":"11450473127","pt":1717322434663,"mc":[{"id":"1.229554919","rc":[{"atl":[[1.9,1.28]],"id":46292327}],"con":true,"img":false}]}
{"op":"mcm","clk":"11450473175","pt":1717322435140,"mc":[{"id":"1.229554919","rc":[{"atb":[[1.39,82.5]],"id":46292327},{"atb":[[1.89,62.5]],"id":65788088}],"con":true,"img":false}]}
{"op":"mcm","clk":"11450473185","pt":1717322435242,"mc":[{"id":"1.229554919","rc":[{"atb":[[1.34,0]],"id":46292327},{"atb":[[1.75,0]],"id":65788088}],"con":true,"img":false}]}
{"op":"mcm","clk":"11450473200","pt":1717322435452,"mc":[{"id":"1.229554919","rc":[{"atl":[[2.04,0],[1.99,15.19]],"id":46292327}],"con":true,"img":false}]}
{"op":"mcm","clk":"11450473290","pt":1717322436385,"mc":[{"id":"1.229554919","rc":[{"atl":[[1.91,0]],"id":46292327}],"con":true,"img":false}]}
{"op":"mcm","clk":"11450473353","pt":1717322437063,"mc":[{"id":"1.229554919","rc":[{"atl":[[1.9,0]],"id":46292327}],"con":true,"img":false}]}
{"op":"mcm","clk":"11450473363","pt":1717322437167,"mc":[{"id":"1.229554919","rc":[{"atl":[[1.91,1.28]],"id":46292327}],"con":true,"img":false}]}
{"op":"mcm","clk":"11450473374","pt":1717322437270,"mc":[{"id":"1.229554919","rc":[{"atl":[[2.02,14.71]],"id":46292327}],"con":true,"img":false}]}
{"op":"mcm","clk":"11450473393","pt":1717322437482,"mc":[{"id":"1.229554919","rc":[{"atb":[[1.39,0],[1.34,82.5]],"id":46292327},{"atb":[[1.89,0],[1.77,73.53]],"id":65788088}],"con":true,"img":false}]}
{"op":"mcm","clk":"11450473583","pt":1717322439671,"mc":[{"id":"1.229554919","rc":[{"atl":[[1.9,7.12]],"id":46292327}],"con":true,"img":false}]}
{"op":"mcm","clk":"11450473614","pt":1717322440084,"mc":[{"id":"1.229554919","rc":[{"atl":[[1.91,0]],"id":46292327}],"con":true,"img":false}]}
{"op":"mcm","clk":"11450473622","pt":1717322440186,"mc":[{"id":"1.229554919","rc":[{"atl":[[1.89,1.28]],"id":46292327}],"con":true,"img":false}]}
{"op":"mcm","clk":"11450473658","pt":1717322440555,"mc":[{"id":"1.229554919","rc":[{"atl":[[2.02,0],[1.9,0]],"id":46292327}],"con":true,"img":false}]}
{"op":"mcm","clk":"11450473717","pt":1717322441188,"mc":[{"id":"1.229554919","rc":[{"atl":[[1.89,0]],"id":46292327}],"con":true,"img":false}]}
{"op":"mcm","clk":"11450473725","pt":1717322441281,"mc":[{"id":"1.229554919","rc":[{"atl":[[2.02,14.71],[1.91,1.28]],"id":46292327}],"con":true,"img":false}]}
{"op":"mcm","clk":"11450473780","pt":1717322441883,"mc":[{"id":"1.229554919","rc":[{"atb":[[1.12,89.37],[1.02,536.25]],"id":46292327},{"atb":[[2.64,0.12],[2.44,0.13]],"id":65788088}],"con":true,"img":false}]}
{"op":"mcm","clk":"11450473932","pt":1717322443464,"mc":[{"id":"1.229554919","rc":[{"atl":[[2.02,0]],"id":46292327}],"con":true,"img":false}]}
{"op":"mcm","clk":"11450474149","pt":1717322445459,"mc":[{"id":"1.229554919","rc":[{"atl":[[1.9,7.12]],"id":46292327}],"con":true,"img":false}]}
{"op":"mcm","clk":"11450474161","pt":1717322445572,"mc":[{"id":"1.229554919","rc":[{"atb":[[1.4,82.5],[1.34,0]],"id":46292327},{"atb":[[1.91,73.53]],"id":65788088}],"con":true,"img":false}]}
{"op":"mcm","clk":"11450474173","pt":1717322445678,"mc":[{"id":"1.229554919","rc":[{"atb":[[1.77,0]],"id":65788088}],"con":true,"img":false}]}
{"op":"mcm","clk":"11450475248","pt":1717322456805,"mc":[{"id":"1.229554919","rc":[{"atb":[[1.4,0],[1.41,82.5]],"id":46292327}],"con":true,"img":false}]}
{"op":"mcm","clk":"11450475282","pt":1717322457175,"mc":[{"id":"1.229554919","rc":[{"atb":[[1.48,6.71]],"id":46292327},{"atl":[[3.6,3.09]],"id":65788088}],"con":true,"img":false}]}
{"op":"mcm","clk":"11450475291","pt":1717322457288,"mc":[{"id":"1.229554919","rc":[{"atb":[[1.49,10],[1.47,0]],"id":46292327},{"atl":[[4,0],[3.55,13.09],[3.65,1.45]],"id":65788088}],"con":true,"img":false}]}
{"op":"mcm","clk":"11450475301","pt":1717322457383,"mc":[{"id":"1.229554919","rc":[{"atl":[[1.91,0]],"id":46292327},{"atl":[[3.65,0]],"id":65788088}],"con":true,"img":false}]}
{"op":"mcm","clk":"11450475307","pt":1717322457485,"mc":[{"id":"1.229554919","rc":[{"atb":[[1.42,71]],"id":46292327},{"atl":[[3.55,14.54]],"id":65788088}],"con":true,"img":false}]}
{"op":"mcm","clk":"11450475340","pt":1717322457899,"mc":[{"id":"1.229554919","rc":[{"atl":[[2,0],[1.89,6.66]],"id":46292327},{"atb":[[2.64,3.22]],"id":65788088}],"con":true,"img":false}]}
{"op":"mcm","clk":"11450475347","pt":1717322458003,"mc":[{"id":"1.229554919","rc":[{"atb":[[1.5,6.74]],"id":46292327},{"atl":[[3.9,0],[3.5,3.08]],"id":65788088}],"con":true,"img":false}]}
{"op":"mcm","clk":"11450475412","pt":1717322458584,"mc":[{"id":"1.229554919","rc":[{"atl":[[3.55,13.09]],"id":65788088}],"con":true,"img":false}]}
{"op":"mcm","clk":"11450475420","pt":1717322458695,"mc":[{"id":"1.229554919","rc":[{"atl":[[3.45,1.45]],"id":65788088}],"con":true,"img":false}]}
{"op":"mcm","clk":"11450475513","pt":1717322459722,"mc":[{"id":"1.229554919","rc":[{"atl":[[3.45,4.57],[3.8,0]],"id":65788088}],"con":true,"img":false}]}
{"op":"mcm","clk":"11450475566","pt":1717322460299,"mc":[{"id":"1.229554919","rc":[{"atb":[[1.49,0]],"id":46292327},{"atl":[[1.62,14.62]],"id":46292327},{"atl":[[3.55,3.09],[2.98,8.07]],"id":65788088}],"con":true,"img":false}]}
{"op":"mcm","clk":"11450475646","pt":1717322461010,"mc":[{"id":"1.229554919","rc":[{"atl":[[3.45,3.12]],"id":65788088}],"con":true,"img":false}]}
{"op":"mcm","clk":"11450475662","pt":1717322461113,"mc":[{"id":"1.229554919","rc":[{"atl":[[1.62,17.87],[1.9,0]],"id":46292327}],"con":true,"img":false}]}
{"op":"mcm","clk":"11450475739","pt":1717322461795,"mc":[{"id":"1.229554919","rc":[{"atb":[[1.02,540.62]],"id":46292327},{"atb":[[1.02,11.99]],"id":65788088}],"con":true,"img":false}]}
{"op":"mcm","clk":"11450475757","pt":1717322461999,"mc":[{"id":"1.229554919","rc":[{"atb":[[1.85,73.53],[1.91,0]],"id":65788088}],"con":true,"img":false}]}
{"op":"mcm","clk":"11450475796","pt":1717322462414,"mc":[{"id":"1.229554919","rc":[{"atl":[[2.98,11.19],[3.55,0]],"id":65788088}],"con":true,"img":false}]}
{"op":"mcm","clk":"11450475829","pt":1717322462794,"mc":[{"id":"1.229554919","rc":[{"atb":[[1.02,538]],"id":46292327},{"atb":[[1.02,9.38]],"id":65788088}],"con":true,"img":false}]}
{"op":"mcm","clk":"11450475921","pt":1717322463783,"mc":[{"id":"1.229554919","rc":[{"atb":[[1.02,536.25]],"id":46292327},{"atb":[[1.02,8.87]],"id":65788088},{"atl":[[3,2.82]],"id":65788088}],"con":true,"img":false}]}
{"op":"mcm","clk":"11450475930","pt":1717322463889,"mc":[{"id":"1.229554919","rc":[{"atb":[[1.51,1.75]],"id":46292327},{"atb":[[2.78,0.5]],"id":65788088}],"con":true,"img":false}]}
{"op":"mcm","clk":"11450476219","pt":1717322467010,"mc":[{"id":"1.229554919","rc":[{"atb":[[1.43,82.5],[1.41,0]],"id":46292327}],"con":true,"img":false}]}
{"op":"mcm","clk":"11450476237","pt":1717322467212,"mc":[{"id":"1.229554919","rc":[{"atb":[[2.64,0.12]],"id":65788088}],"con":true,"img":false}]}
{"op":"mcm","clk":"11450476257","pt":1717322467428,"mc":[{"id":"1.229554919","rc":[{"atb":[[1.44,75.24]],"id":46292327},{"atl":[[1.63,5.76]],"id":46292327}],"con":true,"img":false}]}
{"op":"mcm","clk":"11450476281","pt":1717322467739,"mc":[{"id":"1.229554919","rc":[{"atb":[[1.44,67.78],[1.51,8.13]],"id":46292327},{"atl":[[3.7,0],[2.96,3.2]],"id":65788088}],"con":true,"img":false}]}
{"op":"mcm","clk":"11450476291","pt":1717322467802,"mc":[{"id":"1.229554919","rc":[{"atl":[[2.98,8.07],[2.96,6.41]],"id":65788088}],"con":true,"img":false}]}
{"op":"mcm","clk":"11450476349","pt":1717322468414,"mc":[{"id":"1.229554919","rc":[{"atb":[[1.47,63.45]],"id":46292327},{"atb":[[2.14,26.16]],"id":65788088}],"con":true,"img":false}]}
{"op":"mcm","clk":"11450476444","pt":1717322469617,"mc":[{"id":"1.229554919","rc":[{"atb":[[1.52,1.03]],"id":46292327}],"con":true,"img":false}]}
{"op":"mcm","clk":"11450476510","pt":1717322470442,"mc":[{"id":"1.229554919","rc":[{"atb":[[1.46,0],[1.52,7.36]],"id":46292327},{"atl":[[3.6,0],[2.94,3.22]],"id":65788088}],"con":true,"img":false}]}
{"op":"mcm","clk":"11450476559","pt":1717322471016,"mc":[{"id":"1.229554919","rc":[{"atb":[[1.12,0],[1.02,0],[1.42,0]],"id":46292327},{"atb":[[2.64,0],[2.44,0]],"id":65788088}],"con":true,"img":false}]}
{"op":"mcm","clk":"11450476576","pt":1717322471226,"mc":[{"id":"1.229554919","rc":[{"atb":[[1.52,6.33]],"id":46292327}],"con":true,"img":false}]}
{"op":"mcm","clk":"11450476673","pt":1717322472325,"mc":[{"id":"1.229554919","rc":[{"atb":[[1.43,0],[1.45,82.5]],"id":46292327},{"atl":[[2.08,0]],"id":46292327},{"atb":[[1.99,0],[1.93,10]],"id":65788088}],"con":true,"img":false}]}
{"op":"mcm","clk":"11450476692","pt":1717322472539,"mc":[{"id":"1.229554919","rc":[{"atb":[[1.51,6.37]],"id":46292327}],"con":true,"img":false}]}
{"op":"mcm","clk":"11450476700","pt":1717322472643,"mc":[{"id":"1.229554919","rc":[{"atb":[[1.52,8.08]],"id":46292327}],"con":true,"img":false}]}
{"op":"mcm","clk":"11450476730","pt":1717322472911,"mc":[{"id":"1.229554919","rc":[{"atb":[[1.49,60.86]],"id":46292327},{"atl":[[2.92,6.42],[2.96,3.2]],"id":65788088}],"con":true,"img":false}]}
{"op":"mcm","clk":"11450476752","pt":1717322473224,"mc":[{"id":"1.229554919","rc":[{"atl":[[1.62,3.25]],"id":46292327}],"con":true,"img":false}]}
{"op":"mcm","clk":"11450476772","pt":1717322473532,"mc":[{"id":"1.229554919","rc":[{"atl":[[1.63,0]],"id":46292327},{"atb":[[2.14,0]],"id":65788088}],"con":true,"img":false}]}
{"op":"mcm","clk":"11450476810","pt":1717322473911,"mc":[{"id":"1.229554919","rc":[{"atb":[[2.06,28.13]],"id":65788088}],"con":true,"img":false}]}
{"op":"mcm","clk":"11450477115","pt":1717322477522,"mc":[{"id":"1.229554919","rc":[{"atl":[[1.62,0]],"id":46292327}],"con":true,"img":false}]}
{"op":"mcm","clk":"11450477121","pt":1717322477612,"mc":[{"id":"1.229554919","rc":[{"atl":[[1.88,6.85]],"id":46292327}],"con":true,"img":false}]}
{"op":"mcm","clk":"11450477131","pt":1717322477718,"mc":[{"id":"1.229554919","rc":[{"atl":[[2.9,3.22],[3.5,0]],"id":65788088}],"con":true,"img":false}]}
{"op":"mcm","clk":"11450477142","pt":1717322477922,"mc":[{"id":"1.229554919","rc":[{"atb":[[2.06,0],[2.08,27.61]],"id":65788088}],"con":true,"img":false}]}
{"op":"mcm","clk":"11450477153","pt":1717322478036,"mc":[{"id":"1.229554919","rc":[{"atl":[[2.92,0],[2.94,12.87]],"id":65788088}],"con":true,"img":false}]}
{"op":"mcm","clk":"11450477467","pt":1717322482348,"mc":[{"id":"1.229554919","rc":[{"atl":[[2.1,13.42]],"id":46292327}],"con":true,"img":false}]}
{"op":"mcm","clk":"11450477473","pt":1717322482464,"mc":[{"id":"1.229554919","rc":[{"atl":[[1.99,0]],"id":46292327}],"con":true,"img":false}]}
{"op":"mcm","clk":"11450478032","pt":1717322489322,"mc":[{"id":"1.229554919","rc":[{"atb":[[1.51,0],[1.52,0]],"id":46292327},{"trd":[[1.51,29.5],[1.52,22.32]],"ltp":1.51,"tv":51.82,"id":46292327},{"atb":[[2.6,2.45],[2.78,0]],"id":65788088},{"trd":[[2.6,1],[2.9,3.22],[2.78,1],[2.94,8.59]],"ltp":2.6,"tv":13.81,"id":65788088},{"atl":[[2.9,0],[2.94,4.28]],"id":65788088}],"con":true,"img":false}]}
{"op":"mcm","clk":"11450478039","pt":1717322489425,"mc":[{"id":"1.229554919","rc":[{"atb":[[1.44,189.52],[1.45,0],[1.53,13.42]],"id":46292327},{"atl":[[1.96,0],[1.87,6.41]],"id":46292327},{"atb":[[2.6,2.49]],"id":65788088},{"trd":[[2.6,5.9]],"ltp":2.6,"tv":5.9,"id":65788088}],"con":true,"img":false}]}
{"op":"mcm","clk":"11450478055","pt":1717322489629,"mc":[{"id":"1.229554919","rc":[{"atb":[[1.53,19.93]],"id":46292327},{"atb":[[2.62,3.17]],"id":65788088}],"con":true,"img":false}]}
{"op":"mcm","clk":"11450478075","pt":1717322489940,"mc":[{"id":"1.229554919","rc":[{"atb":[[1.44,121.74]],"id":46292327}],"con":true,"img":false}]}
{"op":"mcm","clk":"11450478086","pt":1717322490040,"mc":[{"id":"1.229554919","rc":[{"atb":[[1.53,20.79]],"id":46292327}],"con":true,"img":false}]}
{"op":"mcm","clk":"11450478104","pt":1717322490254,"mc":[{"id":"1.229554919","rc":[{"atb":[[1.03,832.6],[1.13,164.99]],"id":46292327},{"atb":[[2.4,0.28],[2.6,2.61]],"id":65788088}],"con":true,"img":false}]}
{"op":"mcm","clk":"11450478212","pt":1717322491452,"mc":[{"id":"1.229554919","rc":[{"atl":[[1.88,0],[1.86,6.9]],"id":46292327},{"atb":[[2.6,0.12],[2.62,5.64]],"id":65788088}],"con":true,"img":false}]}
{"op":"mcm","clk":"11450478236","pt":1717322491863,"mc":[{"id":"1.229554919","rc":[{"atb":[[1.53,20.72]],"id":46292327}],"con":true,"img":false}]}
{"op":"mcm","clk":"11450478245","pt":1717322491925,"mc":[{"id":"1.229554919","rc":[{"atb":[[1.5,66.39]],"id":46292327}],"con":true,"img":false}]}
{"op":"mcm","clk":"11450478710","pt":1717322497657,"mc":[{"id":"1.229554919","rc":[{"atl":[[2.96,11.76],[2.94,0]],"id":65788088}],"con":true,"img":false}]}
{"op":"mcm","clk":"11450478901","pt":1717322500450,"mc":[{"id":"1.229554919","rc":[{"atl":[[2.88,8.54]],"id":65788088}],"con":true,"img":false}]}
{"op":"mcm","clk":"11450478930","pt":1717322500859,"mc":[{"id":"1.229554919","rc":[{"atl":[[1.85,6.4],[1.94,0]],"id":46292327},{"atb":[[2.64,3.19]],"id":65788088}],"con":true,"img":false}]}
{"op":"mcm","clk":"11450478980","pt":1717322501439,"mc":[{"id":"1.229554919","rc":[{"atb":[[2.08,0]],"id":65788088}],"con":true,"img":false}]}
{"op":"mcm","clk":"11450479067","pt":1717322502748,"mc":[{"id":"1.229554919","rc":[{"atl":[[1.84,6.98],[1.86,0]],"id":46292327},{"atb":[[2.64,5.64],[2.62,3.17]],"id":65788088}],"con":true,"img":false}]}
{"op":"mcm","clk":"11450479108","pt":1717322502956,"mc":[{"id":"1.229554919","rc":[{"atb":[[2.16,25.7]],"id":65788088}],"con":true,"img":false}]}
{"op":"mcm","clk":"11450479466","pt":1717322506664,"mc":[{"id":"1.229554919","rc":[{"atl":[[2.94,7.64]],"id":65788088}],"con":true,"img":false}]}
{"op":"mcm","clk":"11450479633","pt":1717322507868,"mc":[{"id":"1.229554919","rc":[{"atl":[[2.9,3.82],[3,0]],"id":65788088}],"con":true,"img":false}]}
{"op":"mcm","clk":"11450479643","pt":1717322507972,"mc":[{"id":"1.229554919","rc":[{"atl":[[1.83,6.41],[1.92,0]],"id":46292327},{"atb":[[2.66,3.18]],"id":65788088},{"atl":[[2.96,3.2],[2.94,24.74]],"id":65788088}],"con":true,"img":false}]}
{"op":"mcm","clk":"11450479651","pt":1717322508078,"mc":[{"id":"1.229554919","rc":[{"atl":[[2.88,0]],"id":65788088}],"con":true,"img":false}]}
{"op":"mcm","clk":"11450479670","pt":1717322508286,"mc":[{"id":"1.229554919","rc":[{"atb":[[1.54,6.46]],"id":46292327}],"con":true,"img":false}]}
{"op":"mcm","clk":"11450479678","pt":1717322508387,"mc":[{"id":"1.229554919","rc":[{"atb":[[1.55,12.89],[1.53,7.3]],"id":46292327}],"con":true,"img":false}]}
{"op":"mcm","clk":"11450479686","pt":1717322508492,"mc":[{"id":"1.229554919","rc":[{"atb":[[1.54,0],[1.47,0]],"id":46292327},{"atb":[[2.2,24.85]],"id":65788088}],"con":true,"img":false}]}
{"op":"mcm","clk":"11450479694","pt":1717322508553,"mc":[{"id":"1.229554919","rc":[{"atb":[[1.54,12.83]],"id":46292327}],"con":true,"img":false}]}
{"op":"mcm","clk":"11450479703","pt":1717322508657,"mc":[{"id":"1.229554919","rc":[{"atb":[[1.55,0]],"id":46292327}],"con":true,"img":false}]}
{"op":"mcm","clk":"11450479770","pt":1717322509583,"mc":[{"id":"1.229554919","rc":[{"atl":[[2.84,7.68]],"id":65788088}],"con":true,"img":false}]}
{"op":"mcm","clk":"11450479813","pt":1717322509950,"mc":[{"id":"1.229554919","rc":[{"atb":[[1.51,58.48]],"id":46292327}],"con":true,"img":false}]}
{"op":"mcm","clk":"11450479949","pt":1717322511865,"mc":[{"id":"1.229554919","rc":[{"atl":[[2.88,7.68],[2.98,0]],"id":65788088}],"con":true,"img":false}]}
{"op":"mcm","clk":"11450480016","pt":1717322512861,"mc":[{"id":"1.229554919","rc":[{"atl":[[1.82,6.86],[1.84,0]],"id":46292327},{"atb":[[2.64,3.19],[2.66,5.61]],"id":65788088}],"con":true,"img":false}]}
{"op":"mcm","clk":"11450480039","pt":1717322513169,"mc":[{"id":"1.229554919","rc":[{"atl":[[2.9,5.75]],"id":65788088}],"con":true,"img":false}]}
{"op":"mcm","clk":"11450480270","pt":1717322516488,"mc":[{"id":"1.229554919","rc":[{"atl":[[2.96,18.58],[2.94,7.64]],"id":65788088}],"con":true,"img":false}]}
{"op":"mcm","clk":"11450480428","pt":1717322518566,"mc":[{"id":"1.229554919","rc":[{"atl":[[2.12,0]],"id":46292327}],"con":true,"img":false}]}
{"op":"mcm","clk":"11450480484","pt":1717322519283,"mc":[{"id":"1.229554919","rc":[{"atl":[[2.96,3.2],[2.94,23.02]],"id":65788088}],"con":true,"img":false}]}
{"op":"mcm","clk":"11450480511","pt":1717322519597,"mc":[{"id":"1.229554919","rc":[{"atl":[[1.89,0],[1.81,6.44]],"id":46292327},{"atb":[[2.68,3.18]],"id":65788088}],"con":true,"img":false}]}
{"op":"mcm","clk":"11450480520","pt":1717322519700,"mc":[{"id":"1.229554919","rc":[{"atb":[[1.94,0]],"id":65788088}],"con":true,"img":false}]}
{"op":"mcm","clk":"11450480535","pt":1717322520013,"mc":[{"id":"1.229554919","rc":[{"atb":[[2.24,24.05]],"id":65788088}],"con":true,"img":false}]}
{"op":"mcm","clk":"11450480549","pt":1717322520175,"mc":[{"id":"1.229554919","rc":[{"atl":[[2.94,15.38]],"id":65788088}],"con":true,"img":false}]}
{"op":"mcm","clk":"11450480554","pt":1717322520284,"mc":[{"id":"1.229554919","rc":[{"atb":[[2.68,0]],"id":65788088}],"con":true,"img":false}]}
{"op":"mcm","clk":"11450480564","pt":1717322520388,"mc":[{"id":"1.229554919","rc":[{"atb":[[1.54,19.28]],"id":46292327}],"con":true,"img":false}]}
{"op":"mcm","clk":"11450480572","pt":1717322520487,"mc":[{"id":"1.229554919","rc":[{"atl":[[1.82,0],[1.8,6.87]],"id":46292327},{"atb":[[2.24,0]],"id":65788088}],"con":true,"img":false}]}
{"op":"mcm","clk":"11450480591","pt":1717322520708,"mc":[{"id":"1.229554919","rc":[{"atb":[[2.66,2.43]],"id":65788088}],"con":true,"img":false}]}
{"op":"mcm","clk":"11450480653","pt":1717322521599,"mc":[{"id":"1.229554919","rc":[{"atl":[[1.56,13.6]],"id":46292327}],"con":true,"img":false}]}
{"op":"mcm","clk":"11450480666","pt":1717322521701,"mc":[{"id":"1.229554919","rc":[{"trd":[[1.56,27.2]],"ltp":1.56,"tv":27.2,"id":46292327},{"atl":[[1.56,0]],"id":46292327}],"con":true,"img":false}]}
{"op":"mcm","clk":"11450480675","pt":1717322521802,"mc":[{"id":"1.229554919","rc":[{"atl":[[1.79,6.36],[1.87,0]],"id":46292327},{"atl":[[2.84,0]],"id":65788088}],"con":true,"img":false}]}
{"op":"mcm","clk":"11450480688","pt":1717322521965,"mc":[{"id":"1.229554919","rc":[{"atb":[[2.24,24.05]],"id":65788088}],"con":true,"img":false}]}
{"op":"mcm","clk":"11450480703","pt":1717322522172,"mc":[{"id":"1.229554919","rc":[{"atl":[[2.84,11.34]],"id":65788088}],"con":true,"img":false}]}
{"op":"mcm","clk":"11450480779","pt":1717322523205,"mc":[{"id":"1.229554919","rc":[{"atl":[[1.8,0]],"id":46292327},{"atb":[[2.64,5.64],[2.66,0]],"id":65788088}],"con":true,"img":false}]}
{"op":"mcm","clk":"11450480796","pt":1717322523476,"mc":[{"id":"1.229554919","rc":[{"atb":[[2.24,0]],"id":65788088}],"con":true,"img":false}]}
{"op":"mcm","clk":"11450480874","pt":1717322524673,"mc":[{"id":"1.229554919","rc":[{"atl":[[1.78,6.44]],"id":46292327}],"con":true,"img":false}]}
{"op":"mcm","clk":"11450480898","pt":1717322524981,"mc":[{"id":"1.229554919","rc":[{"atb":[[2.24,24.05]],"id":65788088}],"con":true,"img":false}]}
{"op":"mcm","clk":"11450481115","pt":1717322527593,"mc":[{"id":"1.229554919","rc":[{"atb":[[1.03,475.09],[1.13,82.49]],"id":46292327},{"atb":[[2.6,0],[2.4,0.14]],"id":65788088}],"con":true,"img":false}]}
{"op":"mcm","clk":"11450481520","pt":1717322532806,"mc":[{"id":"1.229554919","rc":[{"atb":[[1.54,12.83]],"id":46292327}],"con":true,"img":false}]}
{"op":"mcm","clk":"11450481551","pt":1717322533116,"mc":[{"id":"1.229554919","rc":[{"atl":[[1.85,0],[1.77,6.52]],"id":46292327},{"atb":[[2.66,3.15]],"id":65788088}],"con":true,"img":false}]}
{"op":"mcm","clk":"11450481559","pt":1717322533180,"mc":[{"id":"1.229554919","rc":[{"atl":[[2.92,15.38],[2.94,0]],"id":65788088}],"con":true,"img":false}]}
{"op":"mcm","clk":"11450481586","pt":1717322533498,"mc":[{"id":"1.229554919","rc":[{"atb":[[2.16,0]],"id":65788088}],"con":true,"img":false}]}
{"op":"mcm","clk":"11450481685","pt":1717322534682,"mc":[{"id":"1.229554919","rc":[{"atl":[[1.78,0],[1.76,6.91]],"id":46292327},{"atb":[[2.66,5.58],[2.64,3.19]],"id":65788088}],"con":true,"img":false}]}
{"op":"mcm","clk":"11450481715","pt":1717322534993,"mc":[{"id":"1.229554919","rc":[{"atb":[[2.3,22.93]],"id":65788088}],"con":true,"img":false}]}
{"op":"mcm","clk":"11450482356","pt":1717322542828,"mc":[{"id":"1.229554919","rc":[{"atb":[[1.18,59.91],[1.08,134.81]],"id":46292327},{"atb":[[2.48,0.06],[2.28,0.07]],"id":65788088}],"con":true,"img":false}]}
{"op":"mcm","clk":"11450482374","pt":1717322543082,"mc":[{"id":"1.229554919","rc":[{"atl":[[2.84,0]],"id":65788088}],"con":true,"img":false}]}
{"op":"mcm","clk":"11450482458","pt":1717322544082,"mc":[{"id":"1.229554919","rc":[{"atb":[[1.54,19.28]],"id":46292327}],"con":true,"img":false}]}
{"op":"mcm","clk":"11450482617","pt":1717322546363,"mc":[{"id":"1.229554919","rc":[{"atb":[[1.54,12.83],[1.5,59.65],[1.53,0.78]],"id":46292327},{"atl":[[2.96,0]],"id":65788088}],"con":true,"img":false}]}
{"op":"mcm","clk":"11450482626","pt":1717322546469,"mc":[{"id":"1.229554919","rc":[{"atb":[[1.54,0]],"id":46292327}],"con":true,"img":false}]}
{"op":"mcm","clk":"11450482635","pt":1717322546575,"mc":[{"id":"1.229554919","rc":[{"atb":[[1.52,10]],"id":46292327}],"con":true,"img":false}]}
{"op":"mcm","clk":"11450482643","pt":1717322546679,"mc":[{"id":"1.229554919","rc":[{"atl":[[1.83,0],[1.75,6.71]],"id":46292327},{"atb":[[2.68,3.08]],"id":65788088},{"atl":[[2.88,0]],"id":65788088}],"con":true,"img":false}]}
{"op":"mcm","clk":"11450482657","pt":1717322546942,"mc":[{"id":"1.229554919","rc":[{"atb":[[1.5,0],[1.51,0]],"id":46292327},{"atb":[[2.34,22.25],[2.2,0]],"id":65788088}],"con":true,"img":false}]}
{"op":"mcm","clk":"11450482665","pt":1717322547045,"mc":[{"id":"1.229554919","rc":[{"atb":[[1.5,10]],"id":46292327}],"con":true,"img":false}]}
{"op":"mcm","clk":"11450482669","pt":1717322547149,"mc":[{"id":"1.229554919","rc":[{"atb":[[1.52,0]],"id":46292327}],"con":true,"img":false}]}
{"op":"mcm","clk":"11450482687","pt":1717322547456,"mc":[{"id":"1.229554919","rc":[{"atb":[[1.49,0]],"id":46292327},{"atb":[[2.24,0]],"id":65788088}],"con":true,"img":false}]}
{"op":"mcm","clk":"11450482690","pt":1717322547559,"mc":[{"id":"1.229554919","rc":[{"atb":[[1.5,0],[1.49,10]],"id":46292327}],"con":true,"img":false}]}
{"op":"mcm","clk":"11450482698","pt":1717322547665,"mc":[{"id":"1.229554919","rc":[{"atb":[[1.53,0]],"id":46292327}],"con":true,"img":false}]}
{"op":"mcm","clk":"11450482703","pt":1717322547766,"mc":[{"id":"1.229554919","rc":[{"atb":[[1.51,0.78]],"id":46292327}],"con":true,"img":false}]}
{"op":"mcm","clk":"11450482717","pt":1717322547976,"mc":[{"id":"1.229554919","rc":[{"atb":[[1.45,66.28]],"id":46292327}],"con":true,"img":false}]}
{"op":"mcm","clk":"11450482737","pt":1717322548240,"mc":[{"id":"1.229554919","rc":[{"atb":[[1.51,0]],"id":46292327}],"con":true,"img":false}]}
{"op":"mcm","clk":"11450482748","pt":1717322548393,"mc":[{"id":"1.229554919","rc":[{"atb":[[1.5,0.78]],"id":46292327},{"atl":[[1.74,6.72],[1.76,0]],"id":46292327},{"atb":[[1.85,0],[1.91,73.53],[2.66,3.15],[2.68,5.49]],"id":65788088},{"atl":[[2.92,0],[2.94,21.13]],"id":65788088}],"con":true,"img":false}]}
{"op":"mcm","clk":"11450482764","pt":1717322548549,"mc":[{"id":"1.229554919","rc":[{"atl":[[2.9,0]],"id":65788088}],"con":true,"img":false}]}
{"op":"mcm","clk":"11450482770","pt":1717322548658,"mc":[{"id":"1.229554919","rc":[{"atl":[[3.4,41.67],[2.94,0]],"id":65788088}],"con":true,"img":false}]}
{"op":"mcm","clk":"11450482779","pt":1717322548764,"mc":[{"id":"1.229554919","rc":[{"atl":[[4.3,7.26],[3.85,4.2],[3.95,5.42],[4.1,6.44]],"id":65788088}],"con":true,"img":false}]}
{"op":"mcm","clk":"11450482840","pt":1717322549489,"mc":[{"id":"1.229554919","rc":[{"atb":[[1.5,25.04]],"id":46292327}],"con":true,"img":false}]}
{"op":"mcm","clk":"11450482856","pt":1717322549645,"mc":[{"id":"1.229554919","rc":[{"atb":[[1.5,0.78]],"id":46292327}],"con":true,"img":false}]}
{"op":"mcm","clk":"11450482894","pt":1717322550338,"mc":[{"id":"1.229554919","rc":[{"atl":[[3.85,0],[3.8,4.28]],"id":65788088}],"con":true,"img":false}]}
{"op":"mcm","clk":"11450482904","pt":1717322550496,"mc":[{"id":"1.229554919","rc":[{"atl":[[3.85,4.2],[3.8,0]],"id":65788088}],"con":true,"img":false}]}
{"op":"mcm","clk":"11450482917","pt":1717322550583,"mc":[{"id":"1.229554919","rc":[{"atl":[[4.3,0],[3.85,0],[3.95,0],[4.1,0]],"id":65788088}],"con":true,"img":false}]}
{"op":"mcm","clk":"11450482927","pt":1717322550688,"mc":[{"id":"1.229554919","rc":[{"atl":[[3.8,4.28]],"id":65788088}],"con":true,"img":false}]}
{"op":"mcm","clk":"11450482937","pt":1717322550793,"mc":[{"id":"1.229554919","rc":[{"atb":[[1.5,7.44]],"id":46292327},{"atl":[[4,6.66],[3.9,5.51],[4.2,7.49]],"id":65788088}],"con":true,"img":false}]}
{"op":"mcm","clk":"11450482946","pt":1717322550851,"mc":[{"id":"1.229554919","rc":[{"atl":[[1000,1.06]],"id":46292327},{"atl":[[3.75,4.36]],"id":65788088}],"con":true,"img":false}]}
{"op":"mcm","clk":"11450482952","pt":1717322550952,"mc":[{"id":"1.229554919","rc":[{"atl":[[3.8,0]],"id":65788088}],"con":true,"img":false}]}
{"op":"mcm","clk":"11450482959","pt":1717322551056,"mc":[{"id":"1.229554919","rc":[{"atl":[[4,0],[3.8,4.28],[3.9,0],[4.2,0],[3.75,0]],"id":65788088}],"con":true,"img":false}]}
{"op":"mcm","clk":"11450482978","pt":1717322551264,"mc":[{"id":"1.229554919","rc":[{"atl":[[1000,0.32]],"id":46292327},{"atl":[[3.75,4.36]],"id":65788088}],"con":true,"img":false}]}
{"op":"mcm","clk":"11450483009","pt":1717322551678,"mc":[{"id":"1.229554919","rc":[{"atb":[[1.51,24.09]],"id":46292327},{"atl":[[1.6,11.52],[1000,0.17]],"id":46292327}],"con":true,"img":false}]}
{"op":"mcm","clk":"11450483014","pt":1717322551782,"mc":[{"id":"1.229554919","rc":[{"atb":[[1.51,23.94]],"id":46292327},{"trd":[[1.51,29.8]],"ltp":1.51,"tv":29.8,"id":46292327}],"con":true,"img":false}]}
{"op":"mcm","clk":"11450483023","pt":1717322551886,"mc":[{"id":"1.229554919","rc":[{"atb":[[1.51,0]],"id":46292327},{"atl":[[1.6,0]],"id":46292327}],"con":true,"img":false}]}
{"op":"mcm","clk":"11450483030","pt":1717322551991,"mc":[{"id":"1.229554919","rc":[{"atb":[[1.52,6.64]],"id":46292327},{"atl":[[1.6,3.29],[1.74,0]],"id":46292327},{"atb":[[2.3,0],[2.34,0],[2.66,21.11]],"id":65788088},{"atl":[[3.75,0]],"id":65788088}],"con":true,"img":false}]}
{"op":"mcm","clk":"11450483036","pt":1717322552095,"mc":[{"id":"1.229554919","rc":[{"atl":[[1.59,6.65],[1.6,0],[1.81,0]],"id":46292327},{"atb":[[2.62,0],[2.7,3.1]],"id":65788088},{"atl":[[3.9,4.13]],"id":65788088}],"con":true,"img":false}]}
{"op":"mcm","clk":"11450483040","pt":1717322552148,"mc":[{"id":"1.229554919","rc":[{"atb":[[1.52,0]],"id":46292327},{"atl":[[1.74,6.68]],"id":46292327},{"atl":[[3.8,0]],"id":65788088}],"con":true,"img":false}]}
{"op":"mcm","clk":"11450483050","pt":1717322552255,"mc":[{"id":"1.229554919","rc":[{"atl":[[1.59,9.97],[1.74,0]],"id":46292327},{"atl":[[3.9,0]],"id":65788088}],"con":true,"img":false}]}
{"op":"mcm","clk":"11450483065","pt":1717322552463,"mc":[{"id":"1.229554919","rc":[{"atb":[[1.5,6.66]],"id":46292327}],"con":true,"img":false}]}
{"op":"mcm","clk":"11450483071","pt":1717322552567,"mc":[{"id":"1.229554919","rc":[{"atb":[[1.44,122.52]],"id":46292327}],"con":true,"img":false}]}
{"op":"mcm","clk":"11450483077","pt":1717322552670,"mc":[{"id":"1.229554919","rc":[{"atb":[[1.49,0],[1.51,13.31]],"id":46292327},{"atl":[[1.79,0],[1.58,6.77]],"id":46292327}],"con":true,"img":false}]}
{"op":"mcm","clk":"11450483097","pt":1717322552980,"mc":[{"id":"1.229554919","rc":[{"atb":[[2.7,20.65]],"id":65788088}],"con":true,"img":false}]}
{"op":"mcm","clk":"11450483105","pt":1717322553086,"mc":[{"id":"1.229554919","rc":[{"atb":[[2.7,21.5]],"id":65788088}],"con":true,"img":false}]}
{"op":"mcm","clk":"11450483123","pt":1717322553294,"mc":[{"id":"1.229554919","rc":[{"atl":[[1.59,6.65],[1.58,10.11]],"id":46292327},{"atb":[[2.68,3.08],[2.7,23.9]],"id":65788088}],"con":true,"img":false}]}
{"op":"mcm","clk":"11450483163","pt":1717322553874,"mc":[{"id":"1.229554919","rc":[{"atb":[[1.51,28.58]],"id":46292327},{"atl":[[1.57,23.07]],"id":46292327}],"con":true,"img":false}]}
{"op":"mcm","clk":"11450483179","pt":1717322554081,"mc":[{"id":"1.229554919","rc":[{"atl":[[1.57,0]],"id":46292327}],"con":true,"img":false}]}
{"op":"mcm","clk":"11450483200","pt":1717322554295,"mc":[{"id":"1.229554919","rc":[{"atb":[[2.7,23.82]],"id":65788088}],"con":true,"img":false}]}
{"op":"mcm","clk":"11450483235","pt":1717322554660,"mc":[{"id":"1.229554919","rc":[{"atl":[[1.57,6.79],[1.77,0]],"id":46292327},{"atb":[[2.72,3.06],[2.64,0]],"id":65788088}],"con":true,"img":false}]}
{"op":"mcm","clk":"11450483297","pt":1717322555754,"mc":[{"id":"1.229554919","rc":[{"atl":[[1.57,10.15],[1.58,6.77]],"id":46292327}],"con":true,"img":false}]}
{"op":"mcm","clk":"11450483322","pt":1717322556168,"mc":[{"id":"1.229554919","rc":[{"atb":[[1.52,21.94]],"id":46292327},{"atl":[[1.58,26.66]],"id":46292327}],"con":true,"img":false}]}
{"op":"mcm","clk":"11450483328","pt":1717322556276,"mc":[{"id":"1.229554919","rc":[{"atb":[[1.51,15.27],[1.53,11.04]],"id":46292327},{"atl":[[1.56,6.8],[1.75,0]],"id":46292327},{"atl":[[4,5.33],[4.4,7.05],[3.9,4.13],[4.2,6.24]],"id":65788088}],"con":true,"img":false}]}
{"op":"mcm","clk":"11450483333","pt":1717322556378,"mc":[{"id":"1.229554919","rc":[{"atb":[[1.52,0]],"id":46292327}],"con":true,"img":false}]}
{"op":"mcm","clk":"11450483337","pt":1717322556480,"mc":[{"id":"1.229554919","rc":[{"atb":[[1.53,0],[1.52,6.8]],"id":46292327}],"con":true,"img":false}]}
{"op":"mcm","clk":"11450483362","pt":1717322556893,"mc":[{"id":"1.229554919","rc":[{"atl":[[1.56,10.18],[1.57,6.79]],"id":46292327},{"atb":[[2.72,5.44],[2.7,21.42]],"id":65788088}],"con":true,"img":false}]}
{"op":"mcm","clk":"11450483365","pt":1717322556946,"mc":[{"id":"1.229554919","rc":[{"atb":[[2.74,17.13]],"id":65788088}],"con":true,"img":false}]}
{"op":"mcm","clk":"11450483380","pt":1717322557156,"mc":[{"id":"1.229554919","rc":[{"atb":[[1.51,0]],"id":46292327}],"con":true,"img":false}]}
{"op":"mcm","clk":"11450483451","pt":1717322558292,"mc":[{"id":"1.229554919","rc":[{"atb":[[2.72,3.06],[2.74,19.49]],"id":65788088}],"con":true,"img":false}]}
{"op":"mcm","clk":"11450483457","pt":1717322558402,"mc":[{"id":"1.229554919","rc":[{"atb":[[1.5,25.05]],"id":46292327},{"atl":[[1.56,28.57]],"id":46292327}],"con":true,"img":false}]}
{"op":"mcm","clk":"11450483559","pt":1717322559797,"mc":[{"id":"1.229554919","rc":[{"atl":[[3.85,4.2],[3.9,0]],"id":65788088}],"con":true,"img":false}]}
{"op":"mcm","clk":"11450483574","pt":1717322559956,"mc":[{"id":"1.229554919","rc":[{"atb":[[1.49,21.72]],"id":46292327},{"atl":[[1.57,26.88],[1.58,6.77]],"id":46292327}],"con":true,"img":false}]}
{"op":"mcm","clk":"11450483586","pt":1717322560160,"mc":[{"id":"1.229554919","rc":[{"atl":[[3.85,0],[3.9,4.13]],"id":65788088}],"con":true,"img":false}]}
{"op":"mcm","clk":"11450483594","pt":1717322560265,"mc":[{"id":"1.229554919","rc":[{"trd":[[1.56,77.2]],"ltp":1.56,"tv":77.2,"id":46292327},{"atl":[[1.56,3.57]],"id":46292327}],"con":true,"img":false}]}
{"op":"mcm","clk":"11450483603","pt":1717322560372,"mc":[{"id":"1.229554919","rc":[{"atb":[[1.51,6.71]],"id":46292327}],"con":true,"img":false}]}
{"op":"mcm","clk":"11450483612","pt":1717322560473,"mc":[{"id":"1.229554919","rc":[{"atb":[[1.49,82.59]],"id":46292327}],"con":true,"img":false}]}
{"op":"mcm","clk":"11450483624","pt":1717322560684,"mc":[{"id":"1.229554919","rc":[{"atl":[[1.56,0]],"id":46292327}],"con":true,"img":false}]}
{"op":"mcm","clk":"11450483645","pt":1717322560991,"mc":[{"id":"1.229554919","rc":[{"atb":[[2.74,2.36]],"id":65788088}],"con":true,"img":false}]}
{"op":"mcm","clk":"11450483664","pt":1717322561199,"mc":[{"id":"1.229554919","rc":[{"atl":[[1.57,6.79]],"id":46292327}],"con":true,"img":false}]}
{"op":"mcm","clk":"11450483702","pt":1717322561774,"mc":[{"id":"1.229554919","rc":[{"atb":[[1.52,16.8]],"id":46292327}],"con":true,"img":false}]}
{"op":"mcm","clk":"11450483737","pt":1717322562295,"mc":[{"id":"1.229554919","rc":[{"atl":[[3.9,0]],"id":65788088}],"con":true,"img":false}]}
{"op":"mcm","clk":"11450483766","pt":1717322562709,"mc":[{"id":"1.229554919","rc":[{"atb":[[1.57,43.21]],"id":46292327},{"trd":[[1.57,13.58]],"ltp":1.57,"tv":13.58,"id":46292327},{"atl":[[1.57,0]],"id":46292327}],"con":true,"img":false}]}
{"op":"mcm","clk":"11450483775","pt":1717322562765,"mc":[{"id":"1.229554919","rc":[{"atb":[[1.57,56.57],[1.52,10]],"id":46292327},{"trd":[[1.58,7.87]],"ltp":1.58,"tv":7.87,"id":46292327},{"atl":[[1.58,2.83]],"id":46292327},{"atl":[[3.35,3.1],[3.9,4.13]],"id":65788088}],"con":true,"img":false}]}
{"op":"mcm","clk":"11450483781","pt":1717322562870,"mc":[{"id":"1.229554919","rc":[{"atb":[[1.52,16.61]],"id":46292327},{"atb":[[2.72,5.44],[2.74,0]],"id":65788088},{"atl":[[3.4,0],[3.3,3.12]],"id":65788088}],"con":true,"img":false}]}
{"op":"mcm","clk":"11450483790","pt":1717322562974,"mc":[{"id":"1.229554919","rc":[{"atb":[[1.54,55.22]],"id":46292327},{"atb":[[2.6,18.64],[2.66,3.15],[2.7,3.87]],"id":65788088},{"atl":[[3.9,0]],"id":65788088}],"con":true,"img":false}]}
{"op":"mcm","clk":"11450483808","pt":1717322563282,"mc":[{"id":"1.229554919","rc":[{"trd":[[1.58,10.71]],"ltp":1.58,"tv":10.71,"id":46292327},{"atl":[[1.58,0]],"id":46292327},{"atb":[[2.72,0]],"id":65788088},{"trd":[[2.72,12.53]],"ltp":2.72,"tv":12.53,"id":65788088}],"con":true,"img":false}]}
{"op":"mcm","clk":"11450483811","pt":1717322563386,"mc":[{"id":"1.229554919","rc":[{"atl":[[3.25,3.12]],"id":65788088}],"con":true,"img":false}]}
{"op":"mcm","clk":"11450483821","pt":1717322563494,"mc":[{"id":"1.229554919","rc":[{"atb":[[2.6,0]],"id":65788088}],"con":true,"img":false}]}
{"op":"mcm","clk":"11450483844","pt":1717322563859,"mc":[{"id":"1.229554919","rc":[{"atb":[[2.7,3.1]],"id":65788088}],"con":true,"img":false}]}
{"op":"mcm","clk":"11450483852","pt":1717322563960,"mc":[{"id":"1.229554919","rc":[{"atb":[[1.01,0.76],[1.94,31.72]],"id":65788088}],"con":true,"img":false}]}
{"op":"mcm","clk":"11450483863","pt":1717322564066,"mc":[{"id":"1.229554919","rc":[{"atb":[[1.48,0],[1.53,6.55]],"id":46292327}],"con":true,"img":false}]}
{"op":"mcm","clk":"11450484178","pt":1717322567865,"mc":[{"id":"1.229554919","rc":[{"atb":[[1.55,10]],"id":46292327}],"con":true,"img":false}]}
{"op":"mcm","clk":"11450484185","pt":1717322567966,"mc":[{"id":"1.229554919","rc":[{"atb":[[1.57,43.21]],"id":46292327},{"atb":[[2.7,0]],"id":65788088}],"con":true,"img":false}]}
{"op":"mcm","clk":"11450484191","pt":1717322568071,"mc":[{"id":"1.229554919","rc":[{"atl":[[3.2,3.12],[3.3,0]],"id":65788088}],"con":true,"img":false}]}
{"op":"mcm","clk":"11450484218","pt":1717322568492,"mc":[{"id":"1.229554919","rc":[{"atb":[[1.94,0]],"id":65788088}],"con":true,"img":false}]}
{"op":"mcm","clk":"11450484226","pt":1717322568701,"mc":[{"id":"1.229554919","rc":[{"atl":[[1.59,0]],"id":46292327},{"atl":[[3.15,3.17]],"id":65788088}],"con":true,"img":false}]}
{"op":"mcm","clk":"11450484233","pt":1717322568862,"mc":[{"id":"1.229554919","rc":[{"atb":[[1.37,82.5]],"id":46292327},{"atl":[[2.18,0],[2.96,47.9],[2.1,0],[2.08,10]],"id":46292327},{"atb":[[1.81,73.53]],"id":65788088},{"atl":[[3.2,0],[3.1,3.13]],"id":65788088}],"con":true,"img":false}]}
{"op":"mcm","clk":"11450484240","pt":1717322568965,"mc":[{"id":"1.229554919","rc":[{"atb":[[1.44,0.78]],"id":46292327},{"atb":[[1.91,0]],"id":65788088}],"con":true,"img":false}]}
{"op":"mcm","clk":"11450484246","pt":1717322569068,"mc":[{"id":"1.229554919","rc":[{"atl":[[2.3,23.08],[2.22,16.39],[2.18,12.71],[2.26,19.84]],"id":46292327}],"con":true,"img":false}]}
{"op":"mcm","clk":"11450484256","pt":1717322569272,"mc":[{"id":"1.229554919","rc":[{"trd":[[1.6,5.17]],"ltp":1.6,"tv":5.17,"id":46292327},{"atl":[[2.24,12.1],[2.22,12.3],[2.18,0]],"id":46292327},{"atb":[[2.68,0]],"id":65788088},{"trd":[[2.68,3.08]],"ltp":2.68,"tv":3.08,"id":65788088}],"con":true,"img":false}]}
{"op":"mcm","clk":"11450484261","pt":1717322569380,"mc":[{"id":"1.229554919","rc":[{"atl":[[3.45,0],[3.05,3.17]],"id":65788088}],"con":true,"img":false}]}
{"op":"mcm","clk":"11450484268","pt":1717322569487,"mc":[{"id":"1.229554919","rc":[{"atl":[[2.22,0],[2.2,12.5]],"id":46292327}],"con":true,"img":false}]}
{"op":"mcm","clk":"11450484279","pt":1717322569691,"mc":[{"id":"1.229554919","rc":[{"atl":[[2.22,12.3],[2.2,0]],"id":46292327}],"con":true,"img":false}]}
{"op":"mcm","clk":"11450484289","pt":1717322569795,"mc":[{"id":"1.229554919","rc":[{"atl":[[2.06,1.28]],"id":46292327}],"con":true,"img":false}]}
{"op":"mcm","clk":"11450484299","pt":1717322570004,"mc":[{"id":"1.229554919","rc":[{"atl":[[2.22,0]],"id":46292327}],"con":true,"img":false}]}
{"op":"mcm","clk":"11450484337","pt":1717322570476,"mc":[{"id":"1.229554919","rc":[{"atl":[[2.06,7.71]],"id":46292327}],"con":true,"img":false}]}
{"op":"mcm","clk":"11450484355","pt":1717322570790,"mc":[{"id":"1.229554919","rc":[{"atl":[[2.28,15.63]],"id":46292327}],"con":true,"img":false}]}
{"op":"mcm","clk":"11450484369","pt":1717322570995,"mc":[{"id":"1.229554919","rc":[{"atl":[[2.06,8.56],[2.04,6.61]],"id":46292327}],"con":true,"img":false}]}
{"op":"mcm","clk":"11450484409","pt":1717322571513,"mc":[{"id":"1.229554919","rc":[{"atl":[[2.24,0],[2.22,12.3]],"id":46292327}],"con":true,"img":false}]}
{"op":"mcm","clk":"11450484419","pt":1717322571569,"mc":[{"id":"1.229554919","rc":[{"atl":[[2.06,7.28]],"id":46292327}],"con":true,"img":false}]}
{"op":"mcm","clk":"11450484428","pt":1717322571674,"mc":[{"id":"1.229554919","rc":[{"atl":[[2.02,1.28]],"id":46292327}],"con":true,"img":false}]}
{"op":"mcm","clk":"11450484472","pt":1717322572191,"mc":[{"id":"1.229554919","rc":[{"atl":[[2.06,7.17]],"id":46292327}],"con":true,"img":false}]}
{"op":"mcm","clk":"11450484518","pt":1717322572815,"mc":[{"id":"1.229554919","rc":[{"atl":[[2.02,7.73],[2.06,6.42]],"id":46292327}],"con":true,"img":false}]}
{"op":"mcm","clk":"11450484528","pt":1717322572869,"mc":[{"id":"1.229554919","rc":[{"atl":[[2.02,8.47]],"id":46292327}],"con":true,"img":false}]}
{"op":"mcm","clk":"11450484566","pt":1717322573391,"mc":[{"id":"1.229554919","rc":[{"atl":[[2.02,7.18],[2.04,0]],"id":46292327}],"con":true,"img":false}]}
{"op":"mcm","clk":"11450484584","pt":1717322573707,"mc":[{"id":"1.229554919","rc":[{"atl":[[2.22,0]],"id":46292327}],"con":true,"img":false}]}
{"op":"mcm","clk":"11450484592","pt":1717322573807,"mc":[{"id":"1.229554919","rc":[{"atl":[[2.2,12.5]],"id":46292327}],"con":true,"img":false}]}
{"op":"mcm","clk":"11450484607","pt":1717322574016,"mc":[{"id":"1.229554919","rc":[{"atb":[[1.44,60.7],[1.37,0]],"id":46292327},{"atl":[[2.2,0],[2.96,0],[2.16,15.63]],"id":46292327},{"atb":[[1.81,0],[1.93,65.56]],"id":65788088},{"atl":[[3.1,0],[3,3.18]],"id":65788088}],"con":true,"img":false}]}
{"op":"mcm","clk":"11450484628","pt":1717322574220,"mc":[{"id":"1.229554919","rc":[{"atl":[[2,6.58]],"id":46292327}],"con":true,"img":false}]}
{"op":"mcm","clk":"11450484670","pt":1717322574690,"mc":[{"id":"1.229554919","rc":[{"atl":[[2.06,16.42],[2.08,0]],"id":46292327}],"con":true,"img":false}]}
{"op":"mcm","clk":"11450484831","pt":1717322576877,"mc":[{"id":"1.229554919","rc":[{"atl":[[2.2,12.5]],"id":46292327}],"con":true,"img":false}]}
{"op":"mcm","clk":"11450484874","pt":1717322577602,"mc":[{"id":"1.229554919","rc":[{"atl":[[1.99,6.43]],"id":46292327}],"con":true,"img":false}]}
{"op":"mcm","clk":"11450484897","pt":1717322578011,"mc":[{"id":"1.229554919","rc":[{"atl":[[2.2,0]],"id":46292327}],"con":true,"img":false}]}
{"op":"mcm","clk":"11450484920","pt":1717322578382,"mc":[{"id":"1.229554919","rc":[{"atl":[[2,0],[1.98,6.58]],"id":46292327}],"con":true,"img":false}]}
{"op":"mcm","clk":"11450485031","pt":1717322579695,"mc":[{"id":"1.229554919","rc":[{"atl":[[4,0]],"id":65788088}],"con":true,"img":false}]}
{"op":"mcm","clk":"11450485064","pt":1717322580007,"mc":[{"id":"1.229554919","rc":[{"atl":[[1.97,6.45]],"id":46292327}],"con":true,"img":false}]}
{"op":"mcm","clk":"11450485083","pt":1717322580241,"mc":[{"id":"1.229554919","rc":[{"atb":[[1.55,16.36],[1.5,18.39]],"id":46292327},{"atb":[[2.66,0]],"id":65788088},{"atl":[[3.35,0],[2.98,3.21]],"id":65788088}],"con":true,"img":false}]}
{"op":"mcm","clk":"11450485096","pt":1717322580324,"mc":[{"id":"1.229554919","rc":[{"atl":[[3,0],[2.96,3.18]],"id":65788088}],"con":true,"img":false}]}
{"op":"mcm","clk":"11450485103","pt":1717322580430,"mc":[{"id":"1.229554919","rc":[{"atb":[[1.73,20.55]],"id":65788088}],"con":true,"img":false}]}
{"op":"mcm","clk":"11450485106","pt":1717322580508,"mc":[{"id":"1.229554919","rc":[{"atb":[[1.44,59.92],[1.45,0],[1.54,0],[1.49,21.72]],"id":46292327},{"atb":[[1.01,0]],"id":65788088}],"con":true,"img":false}]}
{"op":"mcm","clk":"11450485114","pt":1717322580586,"mc":[{"id":"1.229554919","rc":[{"atb":[[1.58,0.78]],"id":46292327},{"atb":[[1.94,0.76]],"id":65788088}],"con":true,"img":false}]}
{"op":"mcm","clk":"11450485131","pt":1717322580804,"mc":[{"id":"1.229554919","rc":[{"atb":[[1.58,2.27]],"id":46292327},{"atb":[[1.94,2.4]],"id":65788088}],"con":true,"img":false}]}
{"op":"mcm","clk":"11450485144","pt":1717322580911,"mc":[{"id":"1.229554919","rc":[{"atb":[[1.58,12.27],[1.55,6.36]],"id":46292327},{"atl":[[3.25,0],[2.94,3.22]],"id":65788088}],"con":true,"img":false}]}
{"op":"mcm","clk":"11450485152","pt":1717322581013,"mc":[{"id":"1.229554919","rc":[{"atl":[[2.96,0],[2.94,6.43]],"id":65788088}],"con":true,"img":false}]}
{"op":"mcm","clk":"11450485163","pt":1717322581219,"mc":[{"id":"1.229554919","rc":[{"atl":[[2.92,1.45]],"id":65788088}],"con":true,"img":false}]}
{"op":"mcm","clk":"11450485186","pt":1717322581486,"mc":[{"id":"1.229554919","rc":[{"atl":[[1.98,0],[1.96,6.44]],"id":46292327},{"atb":[[1.73,0]],"id":65788088}],"con":true,"img":false}]}
{"op":"mcm","clk":"11450485221","pt":1717322581908,"mc":[{"id":"1.229554919","rc":[{"atl":[[2.06,10],[1.95,6.29]],"id":46292327},{"atb":[[2.48,3.3]],"id":65788088}],"con":true,"img":false}]}
{"op":"mcm","clk":"11450485233","pt":1717322582010,"mc":[{"id":"1.229554919","rc":[{"atb":[[1.95,31.39]],"id":65788088}],"con":true,"img":false}]}
{"op":"mcm","clk":"11450485263","pt":1717322582388,"mc":[{"id":"1.229554919","rc":[{"atl":[[2.92,0]],"id":65788088}],"con":true,"img":false}]}
{"op":"mcm","clk":"11450485271","pt":1717322582493,"mc":[{"id":"1.229554919","rc":[{"atb":[[1.95,0]],"id":65788088}],"con":true,"img":false}]}
{"op":"mcm","clk":"11450485279","pt":1717322582593,"mc":[{"id":"1.229554919","rc":[{"atb":[[1.94,0.76]],"id":65788088}],"con":true,"img":false}]}
{"op":"mcm","clk":"11450485287","pt":1717322582700,"mc":[{"id":"1.229554919","rc":[{"atb":[[1.96,1.63]],"id":65788088}],"con":true,"img":false}]}
{"op":"mcm","clk":"11450485330","pt":1717322583227,"mc":[{"id":"1.229554919","rc":[{"atb":[[1.96,0]],"id":65788088}],"con":true,"img":false}]}
{"op":"mcm","clk":"11450485336","pt":1717322583275,"mc":[{"id":"1.229554919","rc":[{"atb":[[1.94,2.4]],"id":65788088}],"con":true,"img":false}]}
{"op":"mcm","clk":"11450485347","pt":1717322583429,"mc":[{"id":"1.229554919","rc":[{"atl":[[2.92,3.23],[3.15,0]],"id":65788088}],"con":true,"img":false}]}
{"op":"mcm","clk":"11450485353","pt":1717322583535,"mc":[{"id":"1.229554919","rc":[{"atl":[[1.96,0]],"id":46292327}],"con":true,"img":false}]}
{"op":"mcm","clk":"11450485399","pt":1717322584020,"mc":[{"id":"1.229554919","rc":[{"atb":[[1.55,60.59]],"id":46292327},{"atb":[[1.99,30.12]],"id":65788088}],"con":true,"img":false}]}
{"op":"mcm","clk":"11450485412","pt":1717322584114,"mc":[{"id":"1.229554919","rc":[{"atb":[[1.18,0],[1.08,0]],"id":46292327},{"atb":[[2.28,0],[2.48,3.23]],"id":65788088}],"con":true,"img":false}]}
{"op":"mcm","clk":"11450485415","pt":1717322584217,"mc":[{"id":"1.229554919","rc":[{"atb":[[1.51,0],[1.56,6.23]],"id":46292327}],"con":true,"img":false}]}
{"op":"mcm","clk":"11450485439","pt":1717322584430,"mc":[{"id":"1.229554919","rc":[{"atb":[[1.94,0.76]],"id":65788088}],"con":true,"img":false}]}
{"op":"mcm","clk":"11450485448","pt":1717322584532,"mc":[{"id":"1.229554919","rc":[{"atl":[[1.94,6.37]],"id":46292327},{"atb":[[2,1.63]],"id":65788088}],"con":true,"img":false}]}
{"op":"mcm","clk":"11450485490","pt":1717322585000,"mc":[{"id":"1.229554919","rc":[{"atb":[[2,0],[2.02,29.23]],"id":65788088}],"con":true,"img":false}]}
{"op":"mcm","clk":"11450485569","pt":1717322586101,"mc":[{"id":"1.229554919","rc":[{"atl":[[2.92,6.47]],"id":65788088}],"con":true,"img":false}]}
{"op":"mcm","clk":"11450485576","pt":1717322586211,"mc":[{"id":"1.229554919","rc":[{"atl":[[2.94,3.22]],"id":65788088}],"con":true,"img":false}]}
{"op":"mcm","clk":"11450485585","pt":1717322586317,"mc":[{"id":"1.229554919","rc":[{"atl":[[2.9,3.26],[3.05,0]],"id":65788088}],"con":true,"img":false}]}
{"op":"mcm","clk":"11450486181","pt":1717322592932,"mc":[{"id":"1.229554919","rc":[{"atb":[[1.64,3]],"id":46292327}],"con":true,"img":false}]}
{"op":"mcm","clk":"11450486198","pt":1717322593035,"mc":[{"id":"1.229554919","rc":[{"atb":[[1.64,5.64],[1.58,18.38],[1.52,10]],"id":46292327}],"con":true,"img":false}]}
{"op":"mcm","clk":"11450486207","pt":1717322593140,"mc":[{"id":"1.229554919","rc":[{"atb":[[1.58,8.38]],"id":46292327}],"con":true,"img":false}]}
{"op":"mcm","clk":"11450486229","pt":1717322593397,"mc":[{"id":"1.229554919","rc":[{"atb":[[1.58,6.89]],"id":46292327}],"con":true,"img":false}]}
{"op":"mcm","clk":"11450486240","pt":1717322593505,"mc":[{"id":"1.229554919","rc":[{"atb":[[1.58,58.31]],"id":46292327}],"con":true,"img":false}]}
{"op":"mcm","clk":"11450486263","pt":1717322593926,"mc":[{"id":"1.229554919","rc":[{"atb":[[1.64,1.71]],"id":46292327},{"trd":[[1.64,7.85]],"ltp":1.64,"tv":7.85,"id":46292327}],"con":true,"img":false}]}
{"op":"mcm","clk":"11450486315","pt":1717322594498,"mc":[{"id":"1.229554919","rc":[{"atb":[[1.58,6.89],[1.57,95.53]],"id":46292327}],"con":true,"img":false}]}
{"op":"mcm","clk":"11450486719","pt":1717322598616,"mc":[{"id":"1.229554919","rc":[{"atl":[[2.92,3.23],[2.9,6.52]],"id":65788088}],"con":true,"img":false}]}
{"op":"mcm","clk":"11450486907","pt":1717322601022,"mc":[{"id":"1.229554919","rc":[{"atb":[[1.58,0.78]],"id":46292327}],"con":true,"img":false}]}
{"op":"mcm","clk":"11450486952","pt":1717322601544,"mc":[{"id":"1.229554919","rc":[{"atb":[[1.57,43.21]],"id":46292327},{"atb":[[1.99,0]],"id":65788088}],"con":true,"img":false}]}
{"op":"mcm","clk":"11450486967","pt":1717322601652,"mc":[{"id":"1.229554919","rc":[{"atb":[[1.12,89.87],[1.22,49.02]],"id":46292327},{"atb":[[2.4,0.21],[2.2,0.08]],"id":65788088}],"con":true,"img":false}]}
{"op":"mcm","clk":"11450487055","pt":1717322602748,"mc":[{"id":"1.229554919","rc":[{"atl":[[1.93,5.99]],"id":46292327}],"con":true,"img":false}]}
{"op":"mcm","clk":"11450487061","pt":1717322602812,"mc":[{"id":"1.229554919","rc":[{"atl":[[2.02,0.74]],"id":46292327}],"con":true,"img":false}]}
{"op":"mcm","clk":"11450487101","pt":1717322603218,"mc":[{"id":"1.229554919","rc":[{"atl":[[2.88,3.27],[2.98,0]],"id":65788088}],"con":true,"img":false}]}
{"op":"mcm","clk":"11450487144","pt":1717322603536,"mc":[{"id":"1.229554919","rc":[{"atb":[[1.58,6.92]],"id":46292327}],"con":true,"img":false}]}
{"op":"mcm","clk":"11450487156","pt":1717322603636,"mc":[{"id":"1.229554919","rc":[{"atl":[[1.94,0],[1.92,6.38]],"id":46292327},{"atl":[[2.92,13.03],[2.9,3.26]],"id":65788088}],"con":true,"img":false}]}
{"op":"mcm","clk":"11450487198","pt":1717322604050,"mc":[{"id":"1.229554919","rc":[{"atb":[[1.57,95.53]],"id":46292327}],"con":true,"img":false}]}
{"op":"mcm","clk":"11450487639","pt":1717322609069,"mc":[{"id":"1.229554919","rc":[{"atb":[[1.64,0],[1.59,6.14]],"id":46292327}],"con":true,"img":false}]}
{"op":"mcm","clk":"11450487649","pt":1717322609219,"mc":[{"id":"1.229554919","rc":[{"atl":[[2.68,5.95]],"id":65788088}],"con":true,"img":false}]}
{"op":"mcm","clk":"11450487658","pt":1717322609323,"mc":[{"id":"1.229554919","rc":[{"atb":[[1.58,6.14]],"id":46292327}],"con":true,"img":false}]}
{"op":"mcm","clk":"11450487668","pt":1717322609426,"mc":[{"id":"1.229554919","rc":[{"atb":[[1.59,6.92]],"id":46292327}],"con":true,"img":false}]}
{"op":"mcm","clk":"11450487675","pt":1717322609529,"mc":[{"id":"1.229554919","rc":[{"atb":[[1.56,59.49],[1.57,43.21]],"id":46292327}],"con":true,"img":false}]}
{"op":"mcm","clk":"11450487807","pt":1717322611249,"mc":[{"id":"1.229554919","rc":[{"atl":[[2.72,5.99]],"id":65788088}],"con":true,"img":false}]}
{"op":"mcm","clk":"11450487997","pt":1717322613455,"mc":[{"id":"1.229554919","rc":[{"atl":[[2.74,4.69]],"id":65788088}],"con":true,"img":false}]}
{"op":"mcm","clk":"11450488481","pt":1717322618243,"mc":[{"id":"1.229554919","rc":[{"atl":[[2.26,0],[2.28,0]],"id":46292327}],"con":true,"img":false}]}
{"op":"mcm","clk":"11450488498","pt":1717322618449,"mc":[{"id":"1.229554919","rc":[{"atl":[[2.3,0]],"id":46292327}],"con":true,"img":false}]}
{"op":"mcm","clk":"11450489027","pt":1717322623689,"mc":[{"id":"1.229554919","marketDefinition":{"bspMarket":false,"turnInPlayEnabled":false,"persistenceEnabled":false,"marketBaseRate":7.0,"eventId":"33318908","eventTypeId":"4339","numberOfWinners":1,"bettingType":"ODDS","marketType":"MATCH_BET","marketTime":"2024-06-02T10:03:00.000Z","suspendTime":"2024-06-02T10:03:00.000Z","bspReconciled":false,"complete":true,"inPlay":false,"crossMatching":true,"runnersVoidable":false,"numberOfActiveRunners":2,"betDelay":0,"status":"SUSPENDED","runners":[{"status":"ACTIVE","sortPriority":1,"id":46292327,"name":"5. Immense"},{"status":"ACTIVE","sortPriority":2,"id":65788088,"name":"6. Bundy Baz"}],"regulators":["MR_INT"],"venue":"Murray Bridge","countryCode":"AU","discountAllowed":true,"timezone":"Australia/Adelaide","openDate":"2024-06-02T08:21:00.000Z","version":5963102287,"name":"Immense v Bundy Baz","eventName":"Murray Bridge (AUS) 2nd Jun"},"rc":[],"con":true,"img":false}]}
{"op":"mcm","clk":"11450489027","pt":1717322623689,"mc":[{"id":"1.229554919","rc":[{"atb":[[1.12,0],[1.59,0],[1.44,0],[1.01,0],[1.03,0],[1.58,0],[1.53,0],[1.56,0],[1.57,0],[1.55,0],[1.5,0],[1.22,0],[1.49,0],[1.13,0],[1.52,0]],"id":46292327},{"atl":[[1.92,0],[1.99,0],[2.02,0],[2.06,0],[1.97,0],[1.93,0],[1.95,0],[2.16,0],[970,0],[1000,0]],"id":46292327},{"atb":[[2.4,0],[1.36,0],[2.02,0],[1.03,0],[1.02,0],[2.2,0],[1.94,0],[1.93,0],[1.34,0],[2.48,0]],"id":65788088},{"atl":[[2.72,0],[2.92,0],[2.88,0],[2.74,0],[2.9,0],[4.4,0],[2.68,0],[2.94,0],[4.2,0],[960,0],[990,0]],"id":65788088}],"con":true,"img":false}]}
{"op":"mcm","clk":"11450495720","pt":1717322700680,"mc":[{"id":"1.229554919","rc":[{"trd":[[1.56,0],[1.64,0],[1.6,0],[1.57,0],[1.58,0],[1.49,0],[1.51,0],[1.48,0],[1.52,0]],"ltp":1.56,"tv":0.0,"id":46292327},{"trd":[[2.72,0],[3.85,0],[2.9,0],[2.6,0],[2.78,0],[3.5,0],[2.68,0],[2.94,0]],"ltp":2.72,"tv":0.0,"id":65788088}],"con":true,"img":false}]}
{"op":"mcm","clk":"11450495866","pt":1717322702271,"mc":[{"id":"1.229554919","marketDefinition":{"bspMarket":false,"turnInPlayEnabled":false,"persistenceEnabled":false,"marketBaseRate":7.0,"eventId":"33318908","eventTypeId":"4339","numberOfWinners":1,"bettingType":"ODDS","marketType":"MATCH_BET","marketTime":"2024-06-02T10:03:00.000Z","suspendTime":"2024-06-02T10:03:00.000Z","bspReconciled":false,"complete":true,"inPlay":false,"crossMatching":false,"runnersVoidable":false,"numberOfActiveRunners":0,"betDelay":0,"status":"CLOSED","settledTime":"2024-06-02T10:04:58.000Z","runners":[{"status":"WINNER","sortPriority":1,"id":46292327,"name":"5. Immense"},{"status":"LOSER","sortPriority":2,"id":65788088,"name":"6. Bundy Baz"}],"regulators":["MR_INT"],"venue":"Murray Bridge","countryCode":"AU","discountAllowed":true,"timezone":"Australia/Adelaide","openDate":"2024-06-02T08:21:00.000Z","version":5963102643,"name":"Immense v Bundy Baz","eventName":"Murray Bridge (AUS) 2nd Jun"},"rc":[],"con":true,"img":false}]}
