{"op":"mcm","clk":"11449075379","pt":1717303241522,"mc":[{"id":"1.229554897","marketDefinition":{"bspMarket":false,"turnInPlayEnabled":false,"persistenceEnabled":false,"marketBaseRate":7.0,"eventId":"33318908","eventTypeId":"4339","numberOfWinners":1,"bettingType":"ODDS","marketType":"EXACTA","marketTime":"2024-06-02T08:41:00.000Z","suspendTime":"2024-06-02T08:41:00.000Z","bspReconciled":false,"complete":true,"inPlay":false,"crossMatching":false,"runnersVoidable":false,"numberOfActiveRunners":20,"betDelay":0,"status":"OPEN","runners":[{"status":"ACTIVE","sortPriority":1,"id":52385882,"name":"1 - 2"},{"status":"ACTIVE","sortPriority":2,"id":52385884,"name":"1 - 4"},{"status":"ACTIVE","sortPriority":3,"id":52385886,"name":"1 - 6"},{"status":"ACTIVE","sortPriority":4,"id":52385888,"name":"1 - 8"},{"status":"ACTIVE","sortPriority":5,"id":52385889,"name":"2 - 1"},{"status":"ACTIVE","sortPriority":6,"id":52385891,"name":"2 - 4"},{"status":"ACTIVE","sortPriority":7,"id":52385893,"name":"2 - 6"},{"status":"ACTIVE","sortPriority":8,"id":52385895,"name":"2 - 8"},{"status":"ACTIVE","sortPriority":9,"id":52385903,"name":"4 - 1"},{"status":"ACTIVE","sortPriority":10,"id":52385904,"name":"4 - 2"},{"status":"ACTIVE","sortPriority":11,"id":52385907,"name":"4 - 6"},{"status":"ACTIVE","sortPriority":12,"id":52385909,"name":"4 - 8"},{"status":"ACTIVE","sortPriority":13,"id":52385917,"name":"6 - 1"},{"status":"ACTIVE","sortPriority":14,"id":52385918,"name":"6 - 2"},{"status":"ACTIVE","sortPriority":15,"id":52385920,"name":"6 - 4"},{"status":"ACTIVE","sortPriority":16,"id":52385923,"name":"6 - 8"},{"status":"ACTIVE","sortPriority":17,"id":52385931,"name":"8 - 1"},{"status":"ACTIVE","sortPriority":18,"id":52385932,"name":"8 - 2"},{"status":"ACTIVE","sortPriority":19,"id":52385934,"name":"8 - 4"},{"status":"ACTIVE","sortPriority":20,"id":52385936,"name":"8 - 6"}],"regulators":["MR_INT"],"venue":"Murray Bridge","countryCode":"AU","discountAllowed":true,"timezone":"Australia/Adelaide","openDate":"2024-06-02T08:21:00.000Z","version":5962801930,"name":"Exacta","eventName":"Murray Bridge (AUS) 2nd Jun"},"rc":[],"con":true,"img":false}]}
{"op":"mcm","clk":"11449094250","pt":1717303691304,"mc":[{"id":"1.229554897","rc":[{"atb":[[8,3.74],[5.5,23.25],[6,15.7],[7,8.72]],"id":52385907},{"atb":[[17.5,4.76],[20,2.75],[25,1.09],[15,7.48]],"id":52385909},{"atb":[[130,0.41],[65,1.64],[180,0.15],[90,0.88]],"id":52385886},{"atb":[[16,6.97],[18.5,4.48],[22,2.49],[27,1]],"id":52385918},{"atb":[[550,0.05],[400,0.26],[450,0.17],[500,0.1]],"id":52385888},{"atb":[[17,3.27],[19.5,1.41],[12,9.51],[14.5,5.81]],"id":52385920},{"atb":[[17.5,4.76],[20,2.75],[25,1.09],[15,7.48]],"id":52385889},{"atb":[[32,2.53],[42,1.28],[26,4.19],[55,0.49]],"id":52385882},{"atb":[[40,0.67],[20,5.51],[25,3.27],[30,1.81]],"id":52385884},{"atb":[[150,0.18],[75,1.06],[100,0.53],[50,2.13]],"id":52385917},{"atb":[[36,1.5],[46,0.58],[23,4.76],[28,2.91]],"id":52385895},{"atb":[[130,0.81],[280,0.09],[180,0.44],[230,0.23]],"id":52385923},{"atb":[[3.2,11.89],[2.88,41.74],[2.98,26.43],[2.78,58.78]],"id":52385891},{"atb":[[9,13.08],[10,8.72],[12.5,4.55],[15,1.87]],"id":52385893},{"atb":[[34,3.17],[85,0.31],[44,1.83],[60,0.88]],"id":52385934},{"atb":[[11,5.23],[13.5,2.09],[8.4,14.14],[9.4,9.34]],"id":52385903},{"atb":[[300,0.26],[350,0.15],[400,0.07],[250,0.42]],"id":52385936},{"atb":[[2.38,18.95],[2.28,40.88],[2.18,66.51],[2.08,96.89]],"id":52385904},{"atb":[[560,0.14],[610,0.08],[660,0.04],[510,0.2]],"id":52385931},{"atb":[[85,0.62],[44,2.43],[120,0.22],[60,1.33]],"id":52385932}],"con":true,"img":false}]}
{"op":"mcm","clk":"11449095056","pt":1717303714149,"mc":[{"id":"1.229554897","rc":[{"atb":[[17.5,9.52],[20,5.51],[25,2.18],[15,14.96]],"id":52385909},{"atb":[[17,6.55],[19.5,2.83],[12,19.03],[14.5,11.63]],"id":52385920},{"atb":[[17.5,9.52],[20,5.51],[25,2.18],[15,14.96]],"id":52385889},{"atb":[[32,5.07],[42,2.56],[26,8.38],[55,0.98]],"id":52385882},{"atb":[[36,3],[46,1.17],[23,9.52],[28,5.82]],"id":52385895},{"atb":[[34,6.35],[85,0.63],[44,3.66],[60,1.77]],"id":52385934},{"atb":[[300,0.53],[350,0.31],[400,0.14],[250,0.84]],"id":52385936},{"atb":[[2.38,37.91],[2.28,81.76],[2.18,133.02],[2.08,193.78]],"id":52385904},{"atb":[[85,1.25],[44,4.87],[120,0.44],[60,2.66]],"id":52385932}],"con":true,"img":false}]}
{"op":"mcm","clk":"11449095079","pt":1717303714930,"mc":[{"id":"1.229554897","rc":[{"atb":[[17.5,4.76],[20,2.75],[25,1.09],[15,7.48]],"id":52385909},{"atb":[[17,3.27],[19.5,1.41],[12,9.51],[14.5,5.81]],"id":52385920},{"atb":[[17.5,4.76],[20,2.75],[25,1.09],[15,7.48]],"id":52385889},{"atb":[[36,1.5],[46,0.58],[23,4.76],[28,2.91]],"id":52385895},{"atb":[[34,3.17],[85,0.31],[44,1.83],[60,0.88]],"id":52385934},{"atb":[[300,0.26],[350,0.15],[400,0.07],[250,0.42]],"id":52385936},{"atb":[[85,0.62],[44,2.43],[120,0.22],[60,1.33]],"id":52385932}],"con":true,"img":false}]}
{"op":"mcm","clk":"11449095082","pt":1717303715031,"mc":[{"id":"1.229554897","rc":[{"atb":[[32,2.53],[42,1.28],[26,4.19],[55,0.49]],"id":52385882},{"atb":[[2.38,18.95],[2.28,40.88],[2.18,66.51],[2.08,96.89]],"id":52385904}],"con":true,"img":false}]}
{"op":"mcm","clk":"11449099376","pt":1717303849458,"mc":[{"id":"1.229554897","rc":[{"atb":[[44,2.43],[27,9.38]],"id":52385886},{"atb":[[550,0.49],[650,0.16]],"id":52385888},{"atb":[[9,30.48],[12.5,9.08]],"id":52385889},{"atb":[[10,27.1],[15,7.46]],"id":52385882},{"atb":[[12,9.5],[8.8,31.27]],"id":52385884},{"atb":[[18,6.14],[13,20.32]],"id":52385895},{"atb":[[2.38,176.74],[2.58,66.16]],"id":52385891},{"atb":[[8,14.93],[6,48.78]],"id":52385893},{"atb":[[7.8,15.37],[5.9,49.77]],"id":52385903},{"atb":[[1.99,105.58],[1.89,274.05]],"id":52385904}],"con":true,"img":false}]}
{"op":"mcm","clk":"11449099382","pt":1717303849562,"mc":[{"id":"1.229554897","rc":[{"atb":[[3.95,82.67],[4.9,26.8]],"id":52385907},{"atb":[[9,30.48],[12.5,9.08]],"id":52385909},{"atb":[[9.6,12.15],[7.6,36.95]],"id":52385918},{"atb":[[5.8,50.81],[7.6,15.83]],"id":52385920},{"atb":[[40,2.67],[25,10.16]],"id":52385917},{"atb":[[280,0.47],[180,1.8]],"id":52385923},{"atb":[[18,6.14],[13,20.32]],"id":52385934},{"atb":[[330,0.31],[230,1.06]],"id":52385936},{"atb":[[550,0.44],[650,0.16]],"id":52385931},{"atb":[[21,5.22],[15.5,16.82]],"id":52385932}],"con":true,"img":false}]}
{"op":"mcm","clk":"11449115773","pt":1717304301299,"mc":[{"id":"1.229554897","rc":[{"atb":[[8,0],[5.5,0],[6,0],[7,0]],"id":52385907},{"atb":[[17.5,0],[20,0],[25,0],[15,0]],"id":52385909},{"atb":[[130,0],[65,0],[180,0],[90,0]],"id":52385886},{"atb":[[550,0.44],[400,0],[450,0],[500,0]],"id":52385888},{"atb":[[17.5,0],[20,0],[25,0],[15,0]],"id":52385889},{"atb":[[32,0],[42,0],[26,0],[55,0]],"id":52385882},{"atb":[[40,0],[20,0],[25,0],[30,0]],"id":52385884},{"atb":[[150,0],[75,0],[100,0],[50,0]],"id":52385917},{"atb":[[130,0],[280,0.37],[180,1.36],[230,0]],"id":52385923},{"atb":[[3.2,0],[2.88,0],[2.98,0],[2.78,0]],"id":52385891},{"atb":[[300,0],[350,0],[400,0],[250,0]],"id":52385936},{"atb":[[2.38,0],[2.28,0],[2.18,0],[2.08,0]],"id":52385904},{"atb":[[560,0],[610,0],[660,0],[510,0]],"id":52385931}],"con":true,"img":false}]}
{"op":"mcm","clk":"11449115798","pt":1717304302021,"mc":[{"id":"1.229554897","rc":[{"atb":[[18,4.61],[21,2.62],[26,1.05],[15.5,7.21]],"id":52385889},{"atb":[[34,2.38],[44,1.22],[27,4.02],[60,0.44]],"id":52385882},{"atb":[[290,0.27],[340,0.15],[390,0.07],[240,0.44]],"id":52385936}],"con":true,"img":false}]}
{"op":"mcm","clk":"11449115803","pt":1717304302074,"mc":[{"id":"1.229554897","rc":[{"atb":[[17,4.9],[19.5,2.83],[24,1.14],[14.5,7.75]],"id":52385909},{"atb":[[2.4,18.68],[2.3,40.24],[2.2,65.4],[2.1,95.12]],"id":52385904}],"con":true,"img":false}]}
{"op":"mcm","clk":"11449128742","pt":1717304417739,"mc":[{"id":"1.229554897","rc":[{"atb":[[18,0],[21,0],[26,0],[15.5,0]],"id":52385889}],"con":true,"img":false}]}
{"op":"mcm","clk":"11449128749","pt":1717304417843,"mc":[{"id":"1.229554897","rc":[{"atb":[[2.4,0],[2.3,0],[2.2,0],[2.1,0]],"id":52385904}],"con":true,"img":false}]}
{"op":"mcm","clk":"11449128781","pt":1717304418458,"mc":[{"id":"1.229554897","rc":[{"atb":[[17.5,4.76],[20,2.75],[25,1.09],[15,7.48]],"id":52385889}],"con":true,"img":false}]}
{"op":"mcm","clk":"11449128786","pt":1717304418561,"mc":[{"id":"1.229554897","rc":[{"atb":[[2.38,18.95],[2.28,40.88],[2.18,66.51],[2.08,96.89]],"id":52385904}],"con":true,"img":false}]}
{"op":"mcm","clk":"11449219116","pt":1717305748455,"mc":[{"id":"1.229554897","rc":[{"atb":[[2.38,0],[2.28,0],[2.18,0],[2.08,0]],"id":52385904}],"con":true,"img":false}]}
{"op":"mcm","clk":"11449219169","pt":1717305749173,"mc":[{"id":"1.229554897","rc":[{"atb":[[2.4,18.68],[2.3,40.24],[2.2,65.4],[2.1,95.12]],"id":52385904}],"con":true,"img":false}]}
{"op":"mcm","clk":"11449232501","pt":1717305940320,"mc":[{"id":"1.229554897","rc":[{"atb":[[17,0],[19.5,0],[24,0],[14.5,0]],"id":52385909},{"atb":[[2.4,0],[2.3,0],[2.2,0],[2.1,0]],"id":52385904},{"atb":[[290,0],[340,0],[390,0],[240,0]],"id":52385936}],"con":true,"img":false}]}
{"op":"mcm","clk":"11449232544","pt":1717305940989,"mc":[{"id":"1.229554897","rc":[{"atb":[[17.5,4.76],[20,2.75],[25,1.09],[15,7.48]],"id":52385909},{"atb":[[300,0.26],[350,0.15],[400,0.07],[250,0.42]],"id":52385936},{"atb":[[2.38,18.95],[2.28,40.88],[2.18,66.51],[2.08,96.89]],"id":52385904}],"con":true,"img":false}]}
{"op":"mcm","clk":"11449238879","pt":1717306033922,"mc":[{"id":"1.229554897","rc":[{"atb":[[17.5,0],[20,0],[25,0],[15,0]],"id":52385909},{"atb":[[300,0],[350,0],[400,0],[250,0]],"id":52385936}],"con":true,"img":false}]}
{"op":"mcm","clk":"11449238917","pt":1717306034644,"mc":[{"id":"1.229554897","rc":[{"atb":[[17,4.9],[19.5,2.83],[24,1.14],[14.5,7.75]],"id":52385909},{"atb":[[290,0.27],[340,0.15],[390,0.07],[240,0.44]],"id":52385936}],"con":true,"img":false}]}
{"op":"mcm","clk":"11449301032","pt":1717306857049,"mc":[{"id":"1.229554897","rc":[{"atb":[[2.38,0],[2.28,0],[2.18,0],[2.08,0]],"id":52385904}],"con":true,"img":false}]}
{"op":"mcm","clk":"11449301081","pt":1717306857769,"mc":[{"id":"1.229554897","rc":[{"atb":[[1.73,35.83],[1.63,124.57],[1.58,180.41],[1.68,76.94]],"id":52385904}],"con":true,"img":false}]}
{"op":"mcm","clk":"11449308160","pt":1717306957906,"mc":[{"id":"1.229554897","rc":[{"atb":[[3.95,0],[4.9,0]],"id":52385907},{"atb":[[9,0],[12.5,0]],"id":52385909},{"atb":[[44,0],[27,0]],"id":52385886},{"atb":[[9.6,0],[7.6,0]],"id":52385918},{"atb":[[550,0],[650,0]],"id":52385888},{"atb":[[5.8,0],[7.6,0]],"id":52385920},{"atb":[[9,0],[12.5,0]],"id":52385889},{"atb":[[10,0],[15,0]],"id":52385882},{"atb":[[12,0],[8.8,0]],"id":52385884},{"atb":[[40,0],[25,0]],"id":52385917},{"atb":[[18,0],[13,0]],"id":52385895},{"atb":[[2.38,0],[2.58,0]],"id":52385891},{"atb":[[280,0],[180,0]],"id":52385923},{"atb":[[8,0],[6,0]],"id":52385893},{"atb":[[18,0],[13,0]],"id":52385934},{"atb":[[7.8,0],[5.9,0]],"id":52385903},{"atb":[[1.99,0],[1.89,0]],"id":52385904},{"atb":[[330,0],[230,0]],"id":52385936},{"atb":[[550,0],[650,0]],"id":52385931},{"atb":[[21,0],[15.5,0]],"id":52385932}],"con":true,"img":false}]}
{"op":"mcm","clk":"11449308955","pt":1717306969182,"mc":[{"id":"1.229554897","rc":[{"atb":[[5.1,25.49],[4.1,78.68]],"id":52385907},{"atb":[[12,9.5],[8.8,31.27]],"id":52385909},{"atb":[[48,2.22],[29,8.71]],"id":52385886},{"atb":[[9.8,11.87],[7.8,35.86]],"id":52385918},{"atb":[[550,0.44],[650,0.16]],"id":52385888},{"atb":[[8,14.93],[6,48.78]],"id":52385920},{"atb":[[9,30.48],[12.5,9.08]],"id":52385889},{"atb":[[10,27.1],[15,7.46]],"id":52385882},{"atb":[[12,9.5],[8.8,31.27]],"id":52385884},{"atb":[[46,2.32],[28,9.03]],"id":52385917},{"atb":[[18,6.14],[13,20.32]],"id":52385895},{"atb":[[2.56,67],[2.36,179.33]],"id":52385891},{"atb":[[340,0.3],[240,1.02]],"id":52385923},{"atb":[[6.4,45.16],[8.4,14.12]],"id":52385893},{"atb":[[17.5,6.33],[12.5,21.2]],"id":52385934},{"atb":[[5.8,50.81],[7.6,15.83]],"id":52385903},{"atb":[[280,0.87],[380,0.27]],"id":52385936},{"atb":[[1.96,108.88],[1.86,283.6]],"id":52385904},{"atb":[[550,0.44],[650,0.16]],"id":52385931},{"atb":[[21,5.22],[15.5,16.82]],"id":52385932}],"con":true,"img":false}]}
{"op":"mcm","clk":"11449311194","pt":1717307001936,"mc":[{"id":"1.229554897","rc":[{"atb":[[5.1,0],[4.1,0]],"id":52385907},{"atb":[[12,0],[8.8,0]],"id":52385909},{"atb":[[9.8,0],[7.8,0]],"id":52385918},{"atb":[[48,0],[29,0]],"id":52385886},{"atb":[[8,0],[6,0]],"id":52385920},{"atb":[[550,0],[650,0]],"id":52385888},{"atb":[[9,0],[12.5,0]],"id":52385889},{"atb":[[10,0],[15,0]],"id":52385882},{"atb":[[12,0],[8.8,0]],"id":52385884},{"atb":[[46,0],[28,0]],"id":52385917},{"atb":[[18,0],[13,0]],"id":52385895},{"atb":[[2.56,0],[2.36,0]],"id":52385891},{"atb":[[340,0],[240,0]],"id":52385923},{"atb":[[6.4,0],[8.4,0]],"id":52385893},{"atb":[[17.5,0],[12.5,0]],"id":52385934},{"atb":[[5.8,0],[7.6,0]],"id":52385903},{"atb":[[280,0],[380,0]],"id":52385936},{"atb":[[1.96,0],[1.86,0]],"id":52385904},{"atb":[[550,0],[650,0]],"id":52385931},{"atb":[[21,0],[15.5,0]],"id":52385932}],"con":true,"img":false}]}
{"op":"mcm","clk":"11449313172","pt":1717307031265,"mc":[{"id":"1.229554897","rc":[{"atb":[[5.1,25.49],[4.1,78.68]],"id":52385907},{"atb":[[12,9.5],[8.8,31.27]],"id":52385909},{"atb":[[48,2.22],[29,8.71]],"id":52385886},{"atb":[[9.8,11.87],[7.8,35.86]],"id":52385918},{"atb":[[550,0.44],[650,0.16]],"id":52385888},{"atb":[[8,14.93],[6,48.78]],"id":52385920},{"atb":[[9,30.48],[12.5,9.08]],"id":52385889},{"atb":[[10,27.1],[15,7.46]],"id":52385882},{"atb":[[12,9.5],[8.8,31.27]],"id":52385884},{"atb":[[46,2.32],[28,9.03]],"id":52385917},{"atb":[[18,6.14],[13,20.32]],"id":52385895},{"atb":[[2.56,67],[2.36,179.33]],"id":52385891},{"atb":[[340,0.3],[240,1.02]],"id":52385923},{"atb":[[6.4,45.16],[8.4,14.12]],"id":52385893},{"atb":[[17.5,6.33],[12.5,21.2]],"id":52385934},{"atb":[[5.8,50.81],[7.6,15.83]],"id":52385903},{"atb":[[280,0.87],[380,0.27]],"id":52385936},{"atb":[[1.96,108.88],[1.86,283.6]],"id":52385904},{"atb":[[550,0.44],[650,0.16]],"id":52385931},{"atb":[[21,5.22],[15.5,16.82]],"id":52385932}],"con":true,"img":false}]}
{"op":"mcm","clk":"11449316775","pt":1717307084349,"mc":[{"id":"1.229554897","rc":[{"atb":[[1.73,0],[1.63,0],[1.58,0],[1.68,0]],"id":52385904}],"con":true,"img":false}]}
{"op":"mcm","clk":"11449316817","pt":1717307085075,"mc":[{"id":"1.229554897","rc":[{"atb":[[1.64,81.75],[1.59,133.01],[1.54,193.77],[1.69,37.91]],"id":52385904}],"con":true,"img":false}]}
{"op":"mcm","clk":"11449319008","pt":1717307115842,"mc":[{"id":"1.229554897","rc":[{"atb":[[5.1,0],[4.1,0]],"id":52385907},{"atb":[[12,0],[8.8,0]],"id":52385909},{"atb":[[48,0],[29,0]],"id":52385886},{"atb":[[9.8,0],[7.8,0]],"id":52385918},{"atb":[[550,0],[650,0]],"id":52385888},{"atb":[[8,0],[6,0]],"id":52385920},{"atb":[[9,0],[12.5,0]],"id":52385889},{"atb":[[10,0],[15,0]],"id":52385882},{"atb":[[12,0],[8.8,0]],"id":52385884},{"atb":[[46,0],[28,0]],"id":52385917},{"atb":[[18,0],[13,0]],"id":52385895},{"atb":[[2.56,0],[2.36,0]],"id":52385891},{"atb":[[340,0],[240,0]],"id":52385923},{"atb":[[6.4,0],[8.4,0]],"id":52385893},{"atb":[[17.5,0],[12.5,0]],"id":52385934},{"atb":[[5.8,0],[7.6,0]],"id":52385903},{"atb":[[1.96,0],[1.86,0]],"id":52385904},{"atb":[[280,0],[380,0]],"id":52385936},{"atb":[[550,0],[650,0]],"id":52385931},{"atb":[[21,0],[15.5,0]],"id":52385932}],"con":true,"img":false}]}
{"op":"mcm","clk":"11449319896","pt":1717307127145,"mc":[{"id":"1.229554897","rc":[{"atb":[[5.1,25.49],[4.1,78.68]],"id":52385907},{"atb":[[9,30.48],[12.5,9.08]],"id":52385909},{"atb":[[9.8,11.87],[7.8,35.86]],"id":52385918},{"atb":[[8,14.93],[6,48.78]],"id":52385920},{"atb":[[48,2.22],[29,8.71]],"id":52385917},{"atb":[[350,0.29],[250,0.97]],"id":52385923},{"atb":[[18,6.14],[13,20.32]],"id":52385934},{"atb":[[290,1.11],[390,0.34]],"id":52385936},{"atb":[[550,0.44],[650,0.16]],"id":52385931},{"atb":[[21,5.22],[15.5,16.82]],"id":52385932}],"con":true,"img":false}]}
{"op":"mcm","clk":"11449319905","pt":1717307127251,"mc":[{"id":"1.229554897","rc":[{"atb":[[50,2.13],[30,8.41]],"id":52385886},{"atb":[[550,0.44],[650,0.16]],"id":52385888},{"atb":[[12,9.5],[8.8,31.27]],"id":52385889},{"atb":[[10,27.1],[15,7.46]],"id":52385882},{"atb":[[12,9.5],[8.8,31.27]],"id":52385884},{"atb":[[18,6.14],[13,20.32]],"id":52385895},{"atb":[[2.54,67.87],[2.34,182.01]],"id":52385891},{"atb":[[6.4,45.16],[8.4,14.12]],"id":52385893},{"atb":[[7.8,15.37],[5.9,49.77]],"id":52385903},{"atb":[[1.97,107.76],[1.87,280.34]],"id":52385904}],"con":true,"img":false}]}
{"op":"mcm","clk":"11449321804","pt":1717307154576,"mc":[{"id":"1.229554897","rc":[{"atb":[[5.1,0],[4.1,0]],"id":52385907},{"atb":[[9,0],[12.5,0]],"id":52385909},{"atb":[[50,0],[30,0]],"id":52385886},{"atb":[[9.8,0],[7.8,0]],"id":52385918},{"atb":[[550,0],[650,0]],"id":52385888},{"atb":[[8,0],[6,0]],"id":52385920},{"atb":[[12,0],[8.8,0]],"id":52385889},{"atb":[[10,0],[15,0]],"id":52385882},{"atb":[[12,0],[8.8,0]],"id":52385884},{"atb":[[48,0],[29,0]],"id":52385917},{"atb":[[18,0],[13,0]],"id":52385895},{"atb":[[2.54,0],[2.34,0]],"id":52385891},{"atb":[[350,0],[250,0]],"id":52385923},{"atb":[[6.4,0],[8.4,0]],"id":52385893},{"atb":[[18,0],[13,0]],"id":52385934},{"atb":[[7.8,0],[5.9,0]],"id":52385903},{"atb":[[1.97,0],[1.87,0]],"id":52385904},{"atb":[[290,0.27],[390,0.07]],"id":52385936},{"atb":[[550,0],[650,0]],"id":52385931},{"atb":[[21,0],[15.5,0]],"id":52385932}],"con":true,"img":false}]}
{"op":"mcm","clk":"11449323273","pt":1717307173917,"mc":[{"id":"1.229554897","rc":[{"atb":[[5.1,25.49],[4.1,78.68]],"id":52385907},{"atb":[[9.2,29.74],[13,8.71]],"id":52385909},{"atb":[[9.8,11.87],[7.8,35.86]],"id":52385918},{"atb":[[8,14.93],[6,48.78]],"id":52385920},{"atb":[[48,2.22],[29,8.71]],"id":52385917},{"atb":[[310,0.78],[410,0.25]],"id":52385923},{"atb":[[18,6.14],[13,20.32]],"id":52385934},{"atb":[[360,0.68],[460,0.23]],"id":52385936},{"atb":[[550,0.44],[650,0.16]],"id":52385931},{"atb":[[16,16.26],[22,4.97]],"id":52385932}],"con":true,"img":false}]}
{"op":"mcm","clk":"11449323283","pt":1717307174018,"mc":[{"id":"1.229554897","rc":[{"atb":[[50,2.13],[30,8.41]],"id":52385886},{"atb":[[550,0.44],[650,0.16]],"id":52385888},{"atb":[[12,9.5],[8.8,31.27]],"id":52385889},{"atb":[[10,27.1],[15,7.46]],"id":52385882},{"atb":[[12,9.5],[8.8,31.27]],"id":52385884},{"atb":[[18,6.14],[13,20.32]],"id":52385895},{"atb":[[2.54,67.87],[2.34,182.01]],"id":52385891},{"atb":[[6.4,45.16],[8.4,14.12]],"id":52385893},{"atb":[[7.8,15.37],[5.9,49.77]],"id":52385903},{"atb":[[1.96,108.88],[1.86,283.6]],"id":52385904}],"con":true,"img":false}]}
{"op":"mcm","clk":"11449325495","pt":1717307202836,"mc":[{"id":"1.229554897","rc":[{"atb":[[16,0],[18.5,0],[22,0],[27,0]],"id":52385918},{"atb":[[17,0],[19.5,0],[12,0],[14.5,0]],"id":52385920},{"atb":[[9,0],[10,0],[12.5,0],[15,0]],"id":52385893}],"con":true,"img":false}]}
{"op":"mcm","clk":"11449325504","pt":1717307202966,"mc":[{"id":"1.229554897","rc":[{"atb":[[290,0],[340,0],[390,0],[240,0]],"id":52385936}],"con":true,"img":false}]}
{"op":"mcm","clk":"11449325552","pt":1717307203538,"mc":[{"id":"1.229554897","rc":[{"atb":[[17,4.9],[19.5,2.83],[24,1.14],[14.5,7.75]],"id":52385920}],"con":true,"img":false}]}
{"op":"mcm","clk":"11449325561","pt":1717307203650,"mc":[{"id":"1.229554897","rc":[{"atb":[[290,0.36],[340,0.23],[390,0.14],[440,0.06]],"id":52385936}],"con":true,"img":false}]}
{"op":"mcm","clk":"11449342308","pt":1717307456848,"mc":[{"id":"1.229554897","rc":[{"atb":[[1.64,0],[1.59,0],[1.54,0],[1.69,0]],"id":52385904}],"con":true,"img":false}]}
{"op":"mcm","clk":"11449342351","pt":1717307457521,"mc":[{"id":"1.229554897","rc":[{"atb":[[1.63,83.04],[1.58,135.3],[1.68,38.47],[1.53,197.43]],"id":52385904}],"con":true,"img":false}]}
{"op":"mcm","clk":"11449368319","pt":1717308059112,"mc":[{"id":"1.229554897","rc":[{"atb":[[5.1,0],[4.1,0]],"id":52385907},{"atb":[[9.2,0],[13,0]],"id":52385909},{"atb":[[9.8,0],[7.8,0]],"id":52385918},{"atb":[[50,0],[30,0]],"id":52385886},{"atb":[[8,0],[6,0]],"id":52385920},{"atb":[[550,0],[650,0]],"id":52385888},{"atb":[[12,0],[8.8,0]],"id":52385889},{"atb":[[10,0],[15,0]],"id":52385882},{"atb":[[12,0],[8.8,0]],"id":52385884},{"atb":[[48,0],[29,0]],"id":52385917},{"atb":[[18,0],[13,0]],"id":52385895},{"atb":[[2.54,0],[2.34,0]],"id":52385891},{"atb":[[310,0],[410,0]],"id":52385923},{"atb":[[6.4,0],[8.4,0]],"id":52385893},{"atb":[[18,0],[13,0]],"id":52385934},{"atb":[[7.8,0],[5.9,0]],"id":52385903},{"atb":[[1.96,0],[1.86,0]],"id":52385904},{"atb":[[360,0],[460,0]],"id":52385936},{"atb":[[550,0],[650,0]],"id":52385931},{"atb":[[16,0],[22,0]],"id":52385932}],"con":true,"img":false}]}
{"op":"mcm","clk":"11449369784","pt":1717308089231,"mc":[{"id":"1.229554897","rc":[{"atb":[[5.1,25.49],[4.1,78.68]],"id":52385907},{"atb":[[9.2,29.74],[13,8.71]],"id":52385909},{"atb":[[9.8,11.87],[7.8,35.86]],"id":52385918},{"atb":[[50,2.13],[30,8.41]],"id":52385886},{"atb":[[8,14.93],[6,48.78]],"id":52385920},{"atb":[[550,0.44],[650,0.16]],"id":52385888},{"atb":[[12,9.5],[8.8,31.27]],"id":52385889},{"atb":[[10,27.1],[15,7.46]],"id":52385882},{"atb":[[12,9.5],[8.8,31.27]],"id":52385884},{"atb":[[48,2.22],[29,8.71]],"id":52385917},{"atb":[[18,6.14],[13,20.32]],"id":52385895},{"atb":[[310,0.78],[410,0.25]],"id":52385923},{"atb":[[2.54,67.87],[2.34,182.01]],"id":52385891},{"atb":[[6.4,45.16],[8.4,14.12]],"id":52385893},{"atb":[[18,6.14],[13,20.32]],"id":52385934},{"atb":[[7.8,15.37],[5.9,49.77]],"id":52385903},{"atb":[[360,0.68],[460,0.23]],"id":52385936},{"atb":[[1.96,108.88],[1.86,283.6]],"id":52385904},{"atb":[[550,0.44],[650,0.16]],"id":52385931},{"atb":[[16,16.26],[22,4.97]],"id":52385932}],"con":true,"img":false}]}
{"op":"mcm","clk":"11449404193","pt":1717308664187,"mc":[{"id":"1.229554897","rc":[{"atb":[[34,0],[85,0],[44,0],[60,0]],"id":52385934},{"atb":[[290,0],[340,0],[390,0],[440,0]],"id":52385936},{"atb":[[85,0],[44,0],[120,0],[60,0]],"id":52385932}],"con":true,"img":false}]}
{"op":"mcm","clk":"11449404241","pt":1717308664964,"mc":[{"id":"1.229554897","rc":[{"atb":[[80,0.66],[42,2.55],[110,0.24],[55,1.45]],"id":52385934},{"atb":[[520,0.05],[370,0.28],[420,0.19],[470,0.11]],"id":52385936},{"atb":[[150,0.18],[75,1.06],[100,0.53],[50,2.13]],"id":52385932}],"con":true,"img":false}]}
{"op":"mcm","clk":"11449405849","pt":1717308687575,"mc":[{"id":"1.229554897","rc":[{"atb":[[17,0],[19.5,0],[24,0],[14.5,0]],"id":52385909}],"con":true,"img":false}]}
{"op":"mcm","clk":"11449426987","pt":1717308975529,"mc":[{"id":"1.229554897","rc":[{"atb":[[17,4.9],[19.5,2.83],[24,1.14],[14.5,7.75]],"id":52385909},{"atb":[[34,3.17],[80,0],[42,0],[85,0.31],[44,1.83],[110,0],[55,0],[60,0.88]],"id":52385934},{"atb":[[520,0],[470,0]],"id":52385936},{"atb":[[150,0],[75,0],[85,0.62],[44,2.43],[100,0],[50,0],[120,0.22],[60,1.33]],"id":52385932}],"con":true,"img":false}]}
{"op":"mcm","clk":"11449427015","pt":1717308975940,"mc":[{"id":"1.229554897","rc":[{"atb":[[270,0.39],[320,0.25]],"id":52385936}],"con":true,"img":false}]}
{"op":"mcm","clk":"11449440123","pt":1717309170855,"mc":[{"id":"1.229554897","rc":[{"atb":[[370,0],[420,0]],"id":52385936}],"con":true,"img":false}]}
{"op":"mcm","clk":"11449440223","pt":1717309172562,"mc":[{"id":"1.229554897","rc":[{"atb":[[390,0.14],[440,0.06]],"id":52385936}],"con":true,"img":false}]}
{"op":"mcm","clk":"11449440323","pt":1717309173971,"mc":[{"id":"1.229554897","rc":[{"atb":[[5.1,0],[4.1,0]],"id":52385907},{"atb":[[9.2,0],[13,0]],"id":52385909},{"atb":[[9.8,0],[7.8,0]],"id":52385918},{"atb":[[50,0],[30,0]],"id":52385886},{"atb":[[8,0],[6,0]],"id":52385920},{"atb":[[550,0],[650,0]],"id":52385888},{"atb":[[12,0],[8.8,0]],"id":52385889},{"atb":[[10,0],[15,0]],"id":52385882},{"atb":[[12,0],[8.8,0]],"id":52385884},{"atb":[[48,0],[29,0]],"id":52385917},{"atb":[[18,0],[13,0]],"id":52385895},{"atb":[[310,0],[410,0]],"id":52385923},{"atb":[[2.54,0],[2.34,0]],"id":52385891},{"atb":[[6.4,0],[8.4,0]],"id":52385893},{"atb":[[18,0],[13,0]],"id":52385934},{"atb":[[7.8,0],[5.9,0]],"id":52385903},{"atb":[[360,0],[460,0]],"id":52385936},{"atb":[[1.96,0],[1.86,0]],"id":52385904},{"atb":[[550,0],[650,0]],"id":52385931},{"atb":[[16,0],[22,0]],"id":52385932}],"con":true,"img":false}]}
{"op":"mcm","clk":"11449440896","pt":1717309182713,"mc":[{"id":"1.229554897","rc":[{"atb":[[5.1,25.49],[4.1,78.68]],"id":52385907},{"atb":[[9.2,29.74],[13,8.71]],"id":52385909},{"atb":[[50,2.13],[30,8.41]],"id":52385886},{"atb":[[9.8,11.87],[7.8,35.86]],"id":52385918},{"atb":[[550,0.44],[650,0.16]],"id":52385888},{"atb":[[8,14.93],[6,48.78]],"id":52385920},{"atb":[[12,9.5],[8.8,31.27]],"id":52385889},{"atb":[[10,27.1],[15,7.46]],"id":52385882},{"atb":[[12,9.5],[8.8,31.27]],"id":52385884},{"atb":[[48,2.22],[29,8.71]],"id":52385917},{"atb":[[18,6.14],[13,20.32]],"id":52385895},{"atb":[[2.54,67.87],[2.34,182.01]],"id":52385891},{"atb":[[310,0.78],[410,0.25]],"id":52385923},{"atb":[[6.4,45.16],[8.4,14.12]],"id":52385893},{"atb":[[18,6.14],[13,20.32]],"id":52385934},{"atb":[[7.8,15.37],[5.9,49.77]],"id":52385903},{"atb":[[1.96,108.88],[1.86,283.6]],"id":52385904},{"atb":[[360,0.68],[460,0.23]],"id":52385936},{"atb":[[550,0.44],[650,0.16]],"id":52385931},{"atb":[[16,16.26],[22,4.97]],"id":52385932}],"con":true,"img":false}]}
{"op":"mcm","clk":"11449459031","pt":1717309460000,"mc":[{"id":"1.229554897","rc":[{"atb":[[5.1,0],[4.1,0]],"id":52385907},{"atb":[[9.2,0],[13,0]],"id":52385909},{"atb":[[9.8,0],[7.8,0]],"id":52385918},{"atb":[[50,0],[30,0]],"id":52385886},{"atb":[[8,0],[6,0]],"id":52385920},{"atb":[[550,0],[650,0]],"id":52385888},{"atb":[[12,0],[8.8,0]],"id":52385889},{"atb":[[10,0],[15,0]],"id":52385882},{"atb":[[12,0],[8.8,0]],"id":52385884},{"atb":[[48,0],[29,0]],"id":52385917},{"atb":[[18,0],[13,0]],"id":52385895},{"atb":[[310,0],[410,0]],"id":52385923},{"atb":[[2.54,0],[2.34,0]],"id":52385891},{"atb":[[6.4,0],[8.4,0]],"id":52385893},{"atb":[[18,0],[13,0]],"id":52385934},{"atb":[[7.8,0],[5.9,0]],"id":52385903},{"atb":[[360,0],[460,0]],"id":52385936},{"atb":[[1.96,0],[1.86,0]],"id":52385904},{"atb":[[550,0],[650,0]],"id":52385931},{"atb":[[16,0],[22,0]],"id":52385932}],"con":true,"img":false}]}
{"op":"mcm","clk":"11449460698","pt":1717309485629,"mc":[{"id":"1.229554897","rc":[{"atb":[[5.2,24.88],[4.2,76.22]],"id":52385907},{"atb":[[9.6,28.36],[14,8.04]],"id":52385909},{"atb":[[10.5,11],[8.2,33.87]],"id":52385918},{"atb":[[70,1.51],[38,6.59]],"id":52385886},{"atb":[[6.4,45.16],[8.4,14.12]],"id":52385920},{"atb":[[550,0.44],[650,0.16]],"id":52385888},{"atb":[[9,30.48],[12.5,9.08]],"id":52385889},{"atb":[[10,27.1],[15,7.46]],"id":52385882},{"atb":[[12,9.5],[8.8,31.27]],"id":52385884},{"atb":[[65,1.63],[36,6.96]],"id":52385917},{"atb":[[19,5.8],[14,18.76]],"id":52385895},{"atb":[[2.5,69.68],[2.3,187.62]],"id":52385891},{"atb":[[530,0.46],[630,0.16]],"id":52385923},{"atb":[[8.6,13.75],[6.6,43.55]],"id":52385893},{"atb":[[19,5.8],[14,18.76]],"id":52385934},{"atb":[[7.8,15.37],[5.9,49.77]],"id":52385903},{"atb":[[1.82,297.44],[1.92,113.61]],"id":52385904},{"atb":[[550,0.44],[650,0.16]],"id":52385936},{"atb":[[550,0.44],[650,0.16]],"id":52385931},{"atb":[[17.5,14.77],[25,4.35]],"id":52385932}],"con":true,"img":false}]}
{"op":"mcm","clk":"11449493647","pt":1717309850155,"mc":[{"id":"1.229554897","rc":[{"atb":[[270,0],[320,0]],"id":52385936}],"con":true,"img":false}]}
{"op":"mcm","clk":"11449493684","pt":1717309850883,"mc":[{"id":"1.229554897","rc":[{"atb":[[290,0.36],[340,0.23]],"id":52385936}],"con":true,"img":false}]}
{"op":"mcm","clk":"11449497950","pt":1717309919042,"mc":[{"id":"1.229554897","rc":[{"atb":[[11,0],[13.5,0],[8.4,0],[9.4,0]],"id":52385903}],"con":true,"img":false}]}
{"op":"mcm","clk":"11449520993","pt":1717310304249,"mc":[{"id":"1.229554897","rc":[{"atb":[[5.2,0],[4.2,0]],"id":52385907},{"atb":[[9.6,0],[14,0]],"id":52385909},{"atb":[[70,0],[38,0]],"id":52385886},{"atb":[[10.5,0],[8.2,0]],"id":52385918},{"atb":[[550,0],[650,0]],"id":52385888},{"atb":[[6.4,0],[8.4,0]],"id":52385920},{"atb":[[9,0],[12.5,0]],"id":52385889},{"atb":[[10,0],[15,0]],"id":52385882},{"atb":[[12,0],[8.8,0]],"id":52385884},{"atb":[[65,0],[36,0]],"id":52385917},{"atb":[[19,0],[14,0]],"id":52385895},{"atb":[[2.5,0],[2.3,0]],"id":52385891},{"atb":[[530,0],[630,0]],"id":52385923},{"atb":[[8.6,0],[6.6,0]],"id":52385893},{"atb":[[19,0],[14,0]],"id":52385934},{"atb":[[7.8,0],[5.9,0]],"id":52385903},{"atb":[[550,0],[650,0]],"id":52385936},{"atb":[[1.82,0],[1.92,0]],"id":52385904},{"atb":[[550,0],[650,0]],"id":52385931},{"atb":[[17.5,0],[25,0]],"id":52385932}],"con":true,"img":false}]}
{"op":"mcm","clk":"11449522629","pt":1717310330822,"mc":[{"id":"1.229554897","rc":[{"atb":[[5.2,24.88],[4.2,76.22]],"id":52385907},{"atb":[[9.6,28.36],[14,8.04]],"id":52385909},{"atb":[[10.5,11],[8.2,33.87]],"id":52385918},{"atb":[[70,1.51],[38,6.59]],"id":52385886},{"atb":[[6.4,45.16],[8.4,14.12]],"id":52385920},{"atb":[[550,0.44],[650,0.16]],"id":52385888},{"atb":[[9,30.48],[12.5,9.08]],"id":52385889},{"atb":[[10,27.1],[15,7.46]],"id":52385882},{"atb":[[12,9.5],[8.8,31.27]],"id":52385884},{"atb":[[65,1.63],[36,6.96]],"id":52385917},{"atb":[[19,5.8],[14,18.76]],"id":52385895},{"atb":[[530,0.46],[630,0.16]],"id":52385923},{"atb":[[2.5,69.68],[2.3,187.62]],"id":52385891},{"atb":[[8.6,13.75],[6.6,43.55]],"id":52385893},{"atb":[[19,5.8],[14,18.76]],"id":52385934},{"atb":[[7.8,15.37],[5.9,49.77]],"id":52385903},{"atb":[[550,0.44],[650,0.16]],"id":52385936},{"atb":[[1.82,297.44],[1.92,113.61]],"id":52385904},{"atb":[[550,0.44],[650,0.16]],"id":52385931},{"atb":[[17.5,14.77],[25,4.35]],"id":52385932}],"con":true,"img":false}]}
{"op":"mcm","clk":"11449529270","pt":1717310438544,"mc":[{"id":"1.229554897","rc":[{"atb":[[1.63,0],[1.58,0],[1.68,0],[1.53,0]],"id":52385904}],"con":true,"img":false}]}
{"op":"mcm","clk":"11449529312","pt":1717310439216,"mc":[{"id":"1.229554897","rc":[{"atb":[[1.64,122.62],[1.59,177.35],[1.74,35.35],[1.69,75.82]],"id":52385904}],"con":true,"img":false}]}
{"op":"mcm","clk":"11449569998","pt":1717311155456,"mc":[{"id":"1.229554897","rc":[{"atb":[[5.2,0],[4.2,0]],"id":52385907},{"atb":[[9.6,0],[14,0]],"id":52385909},{"atb":[[70,0],[38,0]],"id":52385886},{"atb":[[10.5,0],[8.2,0]],"id":52385918},{"atb":[[550,0],[650,0]],"id":52385888},{"atb":[[6.4,0],[8.4,0]],"id":52385920},{"atb":[[9,0],[12.5,0]],"id":52385889},{"atb":[[10,0],[15,0]],"id":52385882},{"atb":[[12,0],[8.8,0]],"id":52385884},{"atb":[[65,0],[36,0]],"id":52385917},{"atb":[[19,0],[14,0]],"id":52385895},{"atb":[[530,0],[630,0]],"id":52385923},{"atb":[[2.5,0],[2.3,0]],"id":52385891},{"atb":[[8.6,0],[6.6,0]],"id":52385893},{"atb":[[19,0],[14,0]],"id":52385934},{"atb":[[7.8,0],[5.9,0]],"id":52385903},{"atb":[[1.82,0],[1.92,0]],"id":52385904},{"atb":[[550,0],[650,0]],"id":52385936},{"atb":[[550,0],[650,0]],"id":52385931},{"atb":[[17.5,0],[25,0]],"id":52385932}],"con":true,"img":false}]}
{"op":"mcm","clk":"11449570640","pt":1717311167082,"mc":[{"id":"1.229554897","rc":[{"atb":[[1.64,0],[1.59,0],[1.74,0],[1.69,0]],"id":52385904}],"con":true,"img":false}]}
{"op":"mcm","clk":"11449570670","pt":1717311167856,"mc":[{"id":"1.229554897","rc":[{"atb":[[1.6,174.39],[1.7,74.74],[1.75,34.88],[1.65,120.73]],"id":52385904}],"con":true,"img":false}]}
{"op":"mcm","clk":"11449571351","pt":1717311180683,"mc":[{"id":"1.229554897","rc":[{"atb":[[70,1.51],[38,6.59]],"id":52385886},{"atb":[[550,0.44],[650,0.16]],"id":52385888},{"atb":[[9,30.48],[12.5,9.08]],"id":52385889},{"atb":[[10,27.1],[15,7.46]],"id":52385882},{"atb":[[12,9.5],[8.8,31.27]],"id":52385884},{"atb":[[19,5.8],[14,18.76]],"id":52385895},{"atb":[[2.5,69.68],[2.3,187.62]],"id":52385891},{"atb":[[8.6,13.75],[6.6,43.55]],"id":52385893},{"atb":[[7.8,15.37],[5.9,49.77]],"id":52385903},{"atb":[[1.82,297.44],[1.92,113.61]],"id":52385904}],"con":true,"img":false}]}
{"op":"mcm","clk":"11449571362","pt":1717311180795,"mc":[{"id":"1.229554897","rc":[{"atb":[[5.2,24.88],[4.2,76.22]],"id":52385907},{"atb":[[9.6,28.36],[14,8.04]],"id":52385909},{"atb":[[10.5,11],[8.2,33.87]],"id":52385918},{"atb":[[6.4,45.16],[8.4,14.12]],"id":52385920},{"atb":[[65,1.63],[36,6.96]],"id":52385917},{"atb":[[530,0.46],[630,0.16]],"id":52385923},{"atb":[[19,5.8],[14,18.76]],"id":52385934},{"atb":[[550,0.44],[650,0.16]],"id":52385936},{"atb":[[550,0.44],[650,0.16]],"id":52385931},{"atb":[[17.5,14.77],[25,4.35]],"id":52385932}],"con":true,"img":false}]}
{"op":"mcm","clk":"11449592384","pt":1717311549797,"mc":[{"id":"1.229554897","rc":[{"atb":[[1.6,0],[1.7,0],[1.75,0],[1.65,0]],"id":52385904}],"con":true,"img":false}]}
{"op":"mcm","clk":"11449593504","pt":1717311569966,"mc":[{"id":"1.229554897","rc":[{"atb":[[1.63,83.04],[1.58,135.3],[1.68,38.47],[1.53,197.43]],"id":52385904}],"con":true,"img":false}]}
{"op":"mcm","clk":"11449593555","pt":1717311570744,"mc":[{"id":"1.229554897","rc":[{"atb":[[1.63,0],[1.58,0],[1.68,0],[1.53,0]],"id":52385904}],"con":true,"img":false}]}
{"op":"mcm","clk":"11449593595","pt":1717311571457,"mc":[{"id":"1.229554897","rc":[{"atb":[[1.6,174.39],[1.7,74.74],[1.75,34.88],[1.65,120.73]],"id":52385904}],"con":true,"img":false}]}
{"op":"mcm","clk":"11449617492","pt":1717312016032,"mc":[{"id":"1.229554897","rc":[{"atb":[[5.2,0],[4.2,0]],"id":52385907},{"atb":[[9.6,0],[14,0]],"id":52385909},{"atb":[[10.5,0],[8.2,0]],"id":52385918},{"atb":[[70,0],[38,0]],"id":52385886},{"atb":[[6.4,0],[8.4,0]],"id":52385920},{"atb":[[550,0],[650,0]],"id":52385888},{"atb":[[9,0],[12.5,0]],"id":52385889},{"atb":[[10,0],[15,0]],"id":52385882},{"atb":[[12,0],[8.8,0]],"id":52385884},{"atb":[[65,0],[36,0]],"id":52385917},{"atb":[[19,0],[14,0]],"id":52385895},{"atb":[[530,0],[630,0]],"id":52385923},{"atb":[[2.5,0],[2.3,0]],"id":52385891},{"atb":[[8.6,0],[6.6,0]],"id":52385893},{"atb":[[19,0],[14,0]],"id":52385934},{"atb":[[7.8,0],[5.9,0]],"id":52385903},{"atb":[[1.82,0],[1.92,0]],"id":52385904},{"atb":[[550,0],[650,0]],"id":52385936},{"atb":[[550,0],[650,0]],"id":52385931},{"atb":[[17.5,0],[25,0]],"id":52385932}],"con":true,"img":false}]}
{"op":"mcm","clk":"11449619094","pt":1717312045863,"mc":[{"id":"1.229554897","rc":[{"atb":[[70,1.51],[38,6.59]],"id":52385886},{"atb":[[550,0.44],[650,0.16]],"id":52385888},{"atb":[[9,30.48],[12.5,9.08]],"id":52385889},{"atb":[[10,27.1],[15,7.46]],"id":52385882},{"atb":[[12,9.5],[8.8,31.27]],"id":52385884},{"atb":[[19,5.8],[14,18.76]],"id":52385895},{"atb":[[2.5,69.68],[2.3,187.62]],"id":52385891},{"atb":[[8.6,13.75],[6.6,43.55]],"id":52385893},{"atb":[[7.8,15.37],[5.9,49.77]],"id":52385903},{"atb":[[1.82,297.44],[1.92,113.61]],"id":52385904}],"con":true,"img":false}]}
{"op":"mcm","clk":"11449619101","pt":1717312045968,"mc":[{"id":"1.229554897","rc":[{"atb":[[5.2,24.88],[4.2,76.22]],"id":52385907},{"atb":[[9.6,28.36],[14,8.04]],"id":52385909},{"atb":[[10.5,11],[8.2,33.87]],"id":52385918},{"atb":[[6.4,45.16],[8.4,14.12]],"id":52385920},{"atb":[[65,1.63],[36,6.96]],"id":52385917},{"atb":[[530,0.46],[630,0.16]],"id":52385923},{"atb":[[19,5.8],[14,18.76]],"id":52385934},{"atb":[[550,0.44],[650,0.16]],"id":52385936},{"atb":[[550,0.44],[650,0.16]],"id":52385931},{"atb":[[17.5,14.77],[25,4.35]],"id":52385932}],"con":true,"img":false}]}
{"op":"mcm","clk":"11449649109","pt":1717312797957,"mc":[{"id":"1.229554897","rc":[{"atb":[[1.6,0],[1.7,0],[1.75,0],[1.65,0]],"id":52385904}],"con":true,"img":false}]}
{"op":"mcm","clk":"11449649139","pt":1717312798624,"mc":[{"id":"1.229554897","rc":[{"atb":[[1.63,83.04],[1.58,135.3],[1.68,38.47],[1.53,197.43]],"id":52385904}],"con":true,"img":false}]}
{"op":"mcm","clk":"11449652151","pt":1717312862930,"mc":[{"id":"1.229554897","rc":[{"atb":[[5.2,0],[4.2,0]],"id":52385907},{"atb":[[9.6,0],[14,0]],"id":52385909},{"atb":[[10.5,0],[8.2,0]],"id":52385918},{"atb":[[70,0],[38,0]],"id":52385886},{"atb":[[6.4,0],[8.4,0]],"id":52385920},{"atb":[[550,0],[650,0]],"id":52385888},{"atb":[[9,0],[12.5,0]],"id":52385889},{"atb":[[10,0],[15,0]],"id":52385882},{"atb":[[12,0],[8.8,0]],"id":52385884},{"atb":[[65,0],[36,0]],"id":52385917},{"atb":[[19,0],[14,0]],"id":52385895},{"atb":[[530,0],[630,0]],"id":52385923},{"atb":[[2.5,0],[2.3,0]],"id":52385891},{"atb":[[8.6,0],[6.6,0]],"id":52385893},{"atb":[[19,0],[14,0]],"id":52385934},{"atb":[[7.8,0],[5.9,0]],"id":52385903},{"atb":[[1.82,0],[1.92,0]],"id":52385904},{"atb":[[550,0],[650,0]],"id":52385936},{"atb":[[550,0],[650,0]],"id":52385931},{"atb":[[17.5,0],[25,0]],"id":52385932}],"con":true,"img":false}]}
{"op":"mcm","clk":"11449653366","pt":1717312890700,"mc":[{"id":"1.229554897","rc":[{"atb":[[5.2,24.88],[4.2,76.22]],"id":52385907},{"atb":[[9.6,28.36],[14,8.04]],"id":52385909},{"atb":[[10.5,11],[8.2,33.87]],"id":52385918},{"atb":[[70,1.51],[38,6.59]],"id":52385886},{"atb":[[6.4,45.16],[8.4,14.12]],"id":52385920},{"atb":[[550,0.44],[650,0.16]],"id":52385888},{"atb":[[9,30.48],[12.5,9.08]],"id":52385889},{"atb":[[10,27.1],[15,7.46]],"id":52385882},{"atb":[[12,9.5],[8.8,31.27]],"id":52385884},{"atb":[[65,1.63],[36,6.96]],"id":52385917},{"atb":[[19,5.8],[14,18.76]],"id":52385895},{"atb":[[2.5,69.68],[2.3,187.62]],"id":52385891},{"atb":[[530,0.46],[630,0.16]],"id":52385923},{"atb":[[8.6,13.75],[6.6,43.55]],"id":52385893},{"atb":[[19,5.8],[14,18.76]],"id":52385934},{"atb":[[7.8,15.37],[5.9,49.77]],"id":52385903},{"atb":[[1.82,297.44],[1.92,113.61]],"id":52385904},{"atb":[[550,0.44],[650,0.16]],"id":52385936},{"atb":[[550,0.44],[650,0.16]],"id":52385931},{"atb":[[17.5,14.77],[25,4.35]],"id":52385932}],"con":true,"img":false}]}
{"op":"mcm","clk":"11449662296","pt":1717313106827,"mc":[{"id":"1.229554897","rc":[{"atb":[[17,0],[19.5,0],[24,0],[14.5,0]],"id":52385909},{"atb":[[36,0],[46,0],[23,0],[28,0]],"id":52385895},{"atb":[[34,0],[85,0],[44,0],[60,0]],"id":52385934},{"atb":[[290,0],[340,0],[390,0],[440,0]],"id":52385936},{"atb":[[85,0],[44,0],[120,0],[60,0]],"id":52385932}],"con":true,"img":false}]}
{"op":"mcm","clk":"11449662336","pt":1717313107504,"mc":[{"id":"1.229554897","rc":[{"atb":[[16,6.97],[18.5,4.48],[22,2.49],[27,1]],"id":52385909},{"atb":[[32,2.53],[42,1.28],[26,4.19],[55,0.49]],"id":52385895},{"atb":[[80,0.66],[42,2.55],[110,0.24],[55,1.45]],"id":52385934},{"atb":[[540,0.05],[390,0.27],[440,0.18],[490,0.1]],"id":52385936},{"atb":[[150,0.18],[75,1.06],[100,0.53],[50,2.13]],"id":52385932}],"con":true,"img":false}]}
{"op":"mcm","clk":"11449671004","pt":1717313290523,"mc":[{"id":"1.229554897","rc":[{"atb":[[1.58,0]],"id":52385904}],"con":true,"img":false}]}
{"op":"mcm","clk":"11449671008","pt":1717313290626,"mc":[{"id":"1.229554897","rc":[{"atb":[[1.63,0],[1.68,0],[1.53,0]],"id":52385904}],"con":true,"img":false}]}
{"op":"mcm","clk":"11449671051","pt":1717313291200,"mc":[{"id":"1.229554897","rc":[{"atb":[[1.65,120.73]],"id":52385904}],"con":true,"img":false}]}
{"op":"mcm","clk":"11449671058","pt":1717313291304,"mc":[{"id":"1.229554897","rc":[{"atb":[[1.6,174.39],[1.7,74.74],[1.75,34.88]],"id":52385904}],"con":true,"img":false}]}
{"op":"mcm","clk":"11449687827","pt":1717313536538,"mc":[{"id":"1.229554897","rc":[{"atb":[[16,0],[18.5,0],[22,0],[27,0]],"id":52385909},{"atb":[[32,0],[42,0],[26,0],[55,0]],"id":52385895}],"con":true,"img":false}]}
{"op":"mcm","clk":"11449687925","pt":1717313537677,"mc":[{"id":"1.229554897","rc":[{"atb":[[17,4.9],[19.5,2.83],[24,1.14],[14.5,7.75]],"id":52385909},{"atb":[[34,1.59],[44,0.61],[22,4.98],[27,3.02]],"id":52385895}],"con":true,"img":false}]}
{"op":"mcm","clk":"11449688720","pt":1717313547173,"mc":[{"id":"1.229554897","rc":[{"atb":[[17,0],[19.5,0],[24,0],[14.5,0]],"id":52385909}],"con":true,"img":false}]}
{"op":"mcm","clk":"11449688777","pt":1717313547847,"mc":[{"id":"1.229554897","rc":[{"atb":[[16.5,5.06],[19,2.91],[23,1.19],[14,16.09]],"id":52385909}],"con":true,"img":false}]}
{"op":"mcm","clk":"11449703767","pt":1717313733941,"mc":[{"id":"1.229554897","rc":[{"atb":[[5.2,0],[4.2,0]],"id":52385907},{"atb":[[9.6,0],[14,8.05]],"id":52385909},{"atb":[[10.5,0],[8.2,0]],"id":52385918},{"atb":[[70,0],[38,0]],"id":52385886},{"atb":[[6.4,0],[8.4,0]],"id":52385920},{"atb":[[550,0],[650,0]],"id":52385888},{"atb":[[9,0],[12.5,0]],"id":52385889},{"atb":[[10,0],[15,0]],"id":52385882},{"atb":[[12,0],[8.8,0]],"id":52385884},{"atb":[[65,0],[36,0]],"id":52385917},{"atb":[[19,0],[14,0]],"id":52385895},{"atb":[[530,0],[630,0]],"id":52385923},{"atb":[[2.5,0],[2.3,0]],"id":52385891},{"atb":[[8.6,0],[6.6,0]],"id":52385893},{"atb":[[19,0],[14,0]],"id":52385934},{"atb":[[7.8,0],[5.9,0]],"id":52385903},{"atb":[[1.82,0],[1.92,0]],"id":52385904},{"atb":[[550,0],[650,0]],"id":52385936},{"atb":[[550,0],[650,0]],"id":52385931},{"atb":[[17.5,0],[25,0]],"id":52385932}],"con":true,"img":false}]}
{"op":"mcm","clk":"11449706177","pt":1717313763450,"mc":[{"id":"1.229554897","rc":[{"atb":[[5.2,24.88],[4.2,76.22]],"id":52385907},{"atb":[[9.6,28.36],[14,16.09]],"id":52385909},{"atb":[[10.5,11],[8.2,33.87]],"id":52385918},{"atb":[[70,1.51],[38,6.59]],"id":52385886},{"atb":[[6.4,45.16],[8.4,14.12]],"id":52385920},{"atb":[[550,0.44],[650,0.16]],"id":52385888},{"atb":[[9,30.48],[12.5,9.08]],"id":52385889},{"atb":[[10,27.1],[15,7.46]],"id":52385882},{"atb":[[12,9.5],[8.8,31.27]],"id":52385884},{"atb":[[65,1.63],[36,6.96]],"id":52385917},{"atb":[[19,5.8],[14,18.76]],"id":52385895},{"atb":[[2.5,69.68],[2.3,187.62]],"id":52385891},{"atb":[[530,0.46],[630,0.16]],"id":52385923},{"atb":[[8.6,13.75],[6.6,43.55]],"id":52385893},{"atb":[[19,5.8],[14,18.76]],"id":52385934},{"atb":[[7.8,15.37],[5.9,49.77]],"id":52385903},{"atb":[[1.82,297.44],[1.92,113.61]],"id":52385904},{"atb":[[550,0.44],[650,0.16]],"id":52385936},{"atb":[[550,0.44],[650,0.16]],"id":52385931},{"atb":[[17.5,14.77],[25,4.35]],"id":52385932}],"con":true,"img":false}]}
{"op":"mcm","clk":"11449732635","pt":1717314051925,"mc":[{"id":"1.229554897","rc":[{"atb":[[16.5,0],[19,0],[23,0],[14,8.04]],"id":52385909}],"con":true,"img":false}]}
{"op":"mcm","clk":"11449732715","pt":1717314052673,"mc":[{"id":"1.229554897","rc":[{"atb":[[16.5,5.06],[19,2.91],[23,1.19],[14,16.09]],"id":52385909}],"con":true,"img":false}]}
{"op":"mcm","clk":"11449733443","pt":1717314060376,"mc":[{"id":"1.229554897","rc":[{"atb":[[2.46,68.49]],"id":52385907},{"atl":[[210,2]],"id":52385907},{"atb":[[5.8,10.14]],"id":52385909},{"atl":[[760,2]],"id":52385909},{"atb":[[23,4.55]],"id":52385886},{"atb":[[6,20]],"id":52385918},{"atl":[[810,2]],"id":52385918},{"atb":[[24,2]],"id":52385888},{"atb":[[6,12.66]],"id":52385920},{"atl":[[810,2]],"id":52385920},{"atb":[[5.7,12.24]],"id":52385889},{"atl":[[970,2]],"id":52385889},{"atb":[[5.7,6.42]],"id":52385882},{"atb":[[5.7,21.28]],"id":52385884},{"atb":[[22,4.76]],"id":52385917},{"atb":[[2.78,8.01]],"id":52385895},{"atb":[[23,2]],"id":52385923},{"atb":[[2.52,65.79]],"id":52385891},{"atl":[[330,2]],"id":52385891},{"atb":[[5.1,24.39]],"id":52385893},{"atl":[[630,2]],"id":52385893},{"atb":[[23,4.55]],"id":52385934},{"atb":[[3.25,44.44]],"id":52385903},{"atl":[[470,2]],"id":52385903},{"atb":[[24,2]],"id":52385936},{"atb":[[1.21,234.36]],"id":52385904},{"atl":[[26,2]],"id":52385904},{"atb":[[24,2]],"id":52385931},{"atb":[[2.78,3.21]],"id":52385932}],"con":true,"img":false}]}
{"op":"mcm","clk":"11449737413","pt":1717314104427,"mc":[{"id":"1.229554897","rc":[{"atb":[[2.46,0],[2.62,61.73]],"id":52385907},{"atl":[[330,0],[320,2]],"id":52385891},{"atb":[[5.6,21.74],[5.1,0]],"id":52385893},{"atb":[[3.25,0],[3.5,40]],"id":52385903}],"con":true,"img":false}]}
{"op":"mcm","clk":"11449737444","pt":1717314104686,"mc":[{"id":"1.229554897","rc":[{"atb":[[1.6,0],[1.7,0],[1.75,0],[1.65,0]],"id":52385904}],"con":true,"img":false}]}
{"op":"mcm","clk":"11449737511","pt":1717314105407,"mc":[{"id":"1.229554897","rc":[{"atb":[[1.63,83.04],[1.58,135.3],[1.68,38.47],[1.53,197.43]],"id":52385904}],"con":true,"img":false}]}
{"op":"mcm","clk":"11449739654","pt":1717314128419,"mc":[{"id":"1.229554897","rc":[{"atl":[[190,2],[210,0]],"id":52385907},{"atl":[[760,0],[740,2]],"id":52385909},{"atl":[[780,2]],"id":52385918},{"atl":[[780,2]],"id":52385920},{"atl":[[930,2],[970,0]],"id":52385889},{"atl":[[630,0],[620,2]],"id":52385893},{"atl":[[460,2],[470,0]],"id":52385903}],"con":true,"img":false}]}
{"op":"mcm","clk":"11449739666","pt":1717314128524,"mc":[{"id":"1.229554897","rc":[{"atl":[[810,0]],"id":52385918},{"atl":[[810,0]],"id":52385920}],"con":true,"img":false}]}
{"op":"mcm","clk":"11449741821","pt":1717314153491,"mc":[{"id":"1.229554897","rc":[{"atb":[[5.2,0],[4.2,0]],"id":52385907},{"atb":[[9.6,0],[14,8.05]],"id":52385909},{"atb":[[10.5,0],[8.2,0]],"id":52385918},{"atb":[[70,0],[38,0]],"id":52385886},{"atb":[[6.4,0],[8.4,0]],"id":52385920},{"atb":[[550,0],[650,0]],"id":52385888},{"atb":[[9,0],[12.5,0]],"id":52385889},{"atb":[[10,0],[15,0]],"id":52385882},{"atb":[[12,0],[8.8,0]],"id":52385884},{"atb":[[65,0],[36,0]],"id":52385917},{"atb":[[19,0],[14,0]],"id":52385895},{"atb":[[2.5,0],[2.3,0]],"id":52385891},{"atb":[[530,0],[630,0]],"id":52385923},{"atb":[[8.6,0],[6.6,0]],"id":52385893},{"atb":[[19,0],[14,0]],"id":52385934},{"atb":[[7.8,0],[5.9,0]],"id":52385903},{"atb":[[1.82,0],[1.92,0]],"id":52385904},{"atb":[[550,0],[650,0]],"id":52385936},{"atb":[[550,0],[650,0]],"id":52385931},{"atb":[[17.5,0],[25,0]],"id":52385932}],"con":true,"img":false}]}
{"op":"mcm","clk":"11449741833","pt":1717314153599,"mc":[{"id":"1.229554897","rc":[{"atb":[[2.56,64.1]],"id":52385907},{"atb":[[3.45,40.82]],"id":52385903}],"con":true,"img":false}]}
{"op":"mcm","clk":"11449741840","pt":1717314153703,"mc":[{"id":"1.229554897","rc":[{"atb":[[2.62,0]],"id":52385907},{"atb":[[5.6,0],[5.4,22.73]],"id":52385893},{"atb":[[3.5,0]],"id":52385903}],"con":true,"img":false}]}
{"op":"mcm","clk":"11449743681","pt":1717314174823,"mc":[{"id":"1.229554897","rc":[{"atb":[[70,1.51],[38,6.59]],"id":52385886},{"atb":[[550,0.44],[650,0.16]],"id":52385888},{"atb":[[9,30.48],[12.5,9.08]],"id":52385889},{"atb":[[10,27.1],[15,7.46]],"id":52385882},{"atb":[[12,9.5],[8.8,31.27]],"id":52385884},{"atb":[[19,5.8],[14,18.76]],"id":52385895},{"atb":[[2.5,69.68],[2.3,187.62]],"id":52385891},{"atb":[[8.6,13.75],[6.6,43.55]],"id":52385893},{"atb":[[7.8,15.37],[5.9,49.77]],"id":52385903},{"atb":[[1.82,297.44],[1.92,113.61]],"id":52385904}],"con":true,"img":false}]}
{"op":"mcm","clk":"11449743692","pt":1717314174926,"mc":[{"id":"1.229554897","rc":[{"atb":[[5.2,24.88],[4.2,76.22]],"id":52385907},{"atb":[[9.6,28.36],[14,16.09]],"id":52385909},{"atb":[[10.5,11],[8.2,33.87]],"id":52385918},{"atb":[[6.4,45.16],[8.4,14.12]],"id":52385920},{"atb":[[65,1.63],[36,6.96]],"id":52385917},{"atb":[[530,0.46],[630,0.16]],"id":52385923},{"atb":[[19,5.8],[14,18.76]],"id":52385934},{"atb":[[550,0.44],[650,0.16]],"id":52385936},{"atb":[[550,0.44],[650,0.16]],"id":52385931},{"atb":[[17.5,14.77],[25,4.35]],"id":52385932}],"con":true,"img":false}]}
{"op":"mcm","clk":"11449760629","pt":1717314366200,"mc":[{"id":"1.229554897","rc":[{"atb":[[34,0],[44,0],[27,0],[60,0]],"id":52385882}],"con":true,"img":false}]}
{"op":"mcm","clk":"11449760688","pt":1717314366883,"mc":[{"id":"1.229554897","rc":[{"atb":[[65,0.41],[36,2.24],[46,1.16],[28,3.88]],"id":52385882}],"con":true,"img":false}]}
{"op":"mcm","clk":"11449765506","pt":1717314419129,"mc":[{"id":"1.229554897","rc":[{"atb":[[16.5,0],[19,0],[23,0],[14,8.04]],"id":52385909}],"con":true,"img":false}]}
{"op":"mcm","clk":"11449765568","pt":1717314419849,"mc":[{"id":"1.229554897","rc":[{"atb":[[16.5,6.75],[19,4.36],[23,2.38],[28,0.97]],"id":52385909}],"con":true,"img":false}]}
{"op":"mcm","clk":"11449769661","pt":1717314466581,"mc":[{"id":"1.229554897","rc":[{"atb":[[1.63,0],[1.58,0],[1.68,0],[1.53,0]],"id":52385904}],"con":true,"img":false}]}
{"op":"mcm","clk":"11449769714","pt":1717314467307,"mc":[{"id":"1.229554897","rc":[{"atb":[[1.6,174.39],[1.7,74.74],[1.75,34.88],[1.65,120.73]],"id":52385904}],"con":true,"img":false}]}
{"op":"mcm","clk":"11449777979","pt":1717314555718,"mc":[{"id":"1.229554897","rc":[{"atb":[[5.2,0],[4.2,0]],"id":52385907},{"atb":[[9.6,0],[14,0]],"id":52385909},{"atb":[[10.5,0],[8.2,0]],"id":52385918},{"atb":[[70,0],[38,0]],"id":52385886},{"atb":[[6.4,0],[8.4,0]],"id":52385920},{"atb":[[550,0],[650,0]],"id":52385888},{"atb":[[9,0],[12.5,0]],"id":52385889},{"atb":[[10,0],[15,0]],"id":52385882},{"atb":[[12,0],[8.8,0]],"id":52385884},{"atb":[[65,0],[36,0]],"id":52385917},{"atb":[[19,0],[14,0]],"id":52385895},{"atb":[[530,0],[630,0]],"id":52385923},{"atb":[[2.5,0],[2.3,0]],"id":52385891},{"atb":[[8.6,0],[6.6,0]],"id":52385893},{"atb":[[19,0],[14,0]],"id":52385934},{"atb":[[7.8,0],[5.9,0]],"id":52385903},{"atb":[[1.82,0],[1.92,0]],"id":52385904},{"atb":[[550,0],[650,0]],"id":52385936},{"atb":[[550,0],[650,0]],"id":52385931},{"atb":[[17.5,0],[25,0]],"id":52385932}],"con":true,"img":false}]}
{"op":"mcm","clk":"11449777991","pt":1717314555822,"mc":[{"id":"1.229554897","rc":[{"atb":[[2.56,0],[2.46,68.49]],"id":52385907},{"atb":[[5.1,24.39]],"id":52385893},{"atb":[[3.45,0],[3.25,44.44]],"id":52385903}],"con":true,"img":false}]}
{"op":"mcm","clk":"11449777999","pt":1717314555924,"mc":[{"id":"1.229554897","rc":[{"atb":[[5.4,0]],"id":52385893}],"con":true,"img":false}]}
{"op":"mcm","clk":"11449780665","pt":1717314586827,"mc":[{"id":"1.229554897","rc":[{"atb":[[70,1.51],[38,6.59]],"id":52385886},{"atb":[[550,0.44],[650,0.16]],"id":52385888},{"atb":[[9,30.48],[12.5,9.08]],"id":52385889},{"atb":[[10,27.1],[15,7.46]],"id":52385882},{"atb":[[12,9.5],[8.8,31.27]],"id":52385884},{"atb":[[19,5.8],[14,18.76]],"id":52385895},{"atb":[[2.5,69.68],[2.3,187.62]],"id":52385891},{"atb":[[8.6,13.75],[6.6,43.55]],"id":52385893},{"atb":[[7.8,15.37],[5.9,49.77]],"id":52385903},{"atb":[[1.82,297.44],[1.92,113.61]],"id":52385904}],"con":true,"img":false}]}
{"op":"mcm","clk":"11449780679","pt":1717314586977,"mc":[{"id":"1.229554897","rc":[{"atb":[[5.2,24.88],[4.2,76.22]],"id":52385907},{"atb":[[9.6,28.36],[14,8.04]],"id":52385909},{"atb":[[10.5,11],[8.2,33.87]],"id":52385918},{"atb":[[6.4,45.16],[8.4,14.12]],"id":52385920},{"atb":[[65,1.63],[36,6.96]],"id":52385917},{"atb":[[530,0.46],[630,0.16]],"id":52385923},{"atb":[[19,5.8],[14,18.76]],"id":52385934},{"atb":[[550,0.44],[650,0.16]],"id":52385936},{"atb":[[550,0.44],[650,0.16]],"id":52385931},{"atb":[[17.5,14.77],[25,4.35]],"id":52385932}],"con":true,"img":false}]}
{"op":"mcm","clk":"11449808495","pt":1717314915068,"mc":[{"id":"1.229554897","rc":[{"atb":[[5.2,0],[4.2,0]],"id":52385907},{"atb":[[9.6,0],[14,0]],"id":52385909},{"atb":[[10.5,0],[8.2,0]],"id":52385918},{"atb":[[70,0],[38,0]],"id":52385886},{"atb":[[6.4,0],[8.4,0]],"id":52385920},{"atb":[[550,0],[650,0]],"id":52385888},{"atb":[[9,0],[12.5,0]],"id":52385889},{"atb":[[10,0],[15,0]],"id":52385882},{"atb":[[12,0],[8.8,0]],"id":52385884},{"atb":[[65,0],[36,0]],"id":52385917},{"atb":[[19,0],[14,0]],"id":52385895},{"atb":[[530,0],[630,0]],"id":52385923},{"atb":[[2.5,0],[2.3,0]],"id":52385891},{"atb":[[8.6,0],[6.6,0]],"id":52385893},{"atb":[[19,0],[14,0]],"id":52385934},{"atb":[[7.8,0],[5.9,0]],"id":52385903},{"atb":[[550,0],[650,0]],"id":52385936},{"atb":[[1.82,0],[1.92,0]],"id":52385904},{"atb":[[550,0],[650,0]],"id":52385931},{"atb":[[17.5,0],[25,0]],"id":52385932}],"con":true,"img":false}]}
{"op":"mcm","clk":"11449812776","pt":1717314962523,"mc":[{"id":"1.229554897","rc":[{"atb":[[70,1.51],[38,6.59]],"id":52385886},{"atb":[[550,0.44],[650,0.16]],"id":52385888},{"atb":[[9,30.48],[12.5,9.08]],"id":52385889},{"atb":[[10,27.1],[15,7.46]],"id":52385882},{"atb":[[12,9.5],[8.8,31.27]],"id":52385884},{"atb":[[19,5.8],[14,18.76]],"id":52385895},{"atb":[[2.5,69.68],[2.3,187.62]],"id":52385891},{"atb":[[8.6,13.75],[6.6,43.55]],"id":52385893},{"atb":[[7.8,15.37],[5.9,49.77]],"id":52385903},{"atb":[[1.82,297.44],[1.92,113.61]],"id":52385904}],"con":true,"img":false}]}
{"op":"mcm","clk":"11449812789","pt":1717314962632,"mc":[{"id":"1.229554897","rc":[{"atb":[[5.2,24.88],[4.2,76.22]],"id":52385907},{"atb":[[9.6,28.36],[14,8.04]],"id":52385909},{"atb":[[10.5,11],[8.2,33.87]],"id":52385918},{"atb":[[6.4,45.16],[8.4,14.12]],"id":52385920},{"atb":[[65,1.63],[36,6.96]],"id":52385917},{"atb":[[530,0.46],[630,0.16]],"id":52385923},{"atb":[[19,5.8],[14,18.76]],"id":52385934},{"atb":[[550,0.44],[650,0.16]],"id":52385936},{"atb":[[550,0.44],[650,0.16]],"id":52385931},{"atb":[[17.5,14.77],[25,4.35]],"id":52385932}],"con":true,"img":false}]}
{"op":"mcm","clk":"11449851196","pt":1717315295583,"mc":[{"id":"1.229554897","rc":[{"atb":[[5.2,0],[4.2,0]],"id":52385907},{"atb":[[9.6,0],[14,0]],"id":52385909},{"atb":[[10.5,0],[8.2,0]],"id":52385918},{"atb":[[70,0],[38,0]],"id":52385886},{"atb":[[6.4,0],[8.4,0]],"id":52385920},{"atb":[[550,0],[650,0]],"id":52385888},{"atb":[[9,0],[12.5,0]],"id":52385889},{"atb":[[10,0],[15,0]],"id":52385882},{"atb":[[12,0],[8.8,0]],"id":52385884},{"atb":[[65,0],[36,0]],"id":52385917},{"atb":[[19,0],[14,0]],"id":52385895},{"atb":[[530,0],[630,0]],"id":52385923},{"atb":[[2.5,0],[2.3,0]],"id":52385891},{"atb":[[8.6,0],[6.6,0]],"id":52385893},{"atb":[[19,0],[14,0]],"id":52385934},{"atb":[[7.8,0],[5.9,0]],"id":52385903},{"atb":[[550,0],[650,0]],"id":52385936},{"atb":[[1.82,0],[1.92,0]],"id":52385904},{"atb":[[550,0],[650,0]],"id":52385931},{"atb":[[17.5,0],[25,0]],"id":52385932}],"con":true,"img":false}]}
{"op":"mcm","clk":"11449854732","pt":1717315331455,"mc":[{"id":"1.229554897","rc":[{"atb":[[70,1.51],[38,6.59]],"id":52385886},{"atb":[[550,0.44],[650,0.16]],"id":52385888},{"atb":[[9,30.48],[12.5,9.08]],"id":52385889},{"atb":[[10,27.1],[15,7.46]],"id":52385882},{"atb":[[12,9.5],[8.8,31.27]],"id":52385884},{"atb":[[19,5.8],[14,18.76]],"id":52385895},{"atb":[[2.5,69.68],[2.3,187.62]],"id":52385891},{"atb":[[8.6,13.75],[6.6,43.55]],"id":52385893},{"atb":[[7.8,15.37],[5.9,49.77]],"id":52385903},{"atb":[[1.82,297.44],[1.92,113.61]],"id":52385904}],"con":true,"img":false}]}
{"op":"mcm","clk":"11449854743","pt":1717315331558,"mc":[{"id":"1.229554897","rc":[{"atb":[[5.2,24.88],[4.2,76.22]],"id":52385907},{"atb":[[9.6,28.36],[14,8.04]],"id":52385909},{"atb":[[10.5,11],[8.2,33.87]],"id":52385918},{"atb":[[6.4,45.16],[8.4,14.12]],"id":52385920},{"atb":[[65,1.63],[36,6.96]],"id":52385917},{"atb":[[530,0.46],[630,0.16]],"id":52385923},{"atb":[[19,5.8],[14,18.76]],"id":52385934},{"atb":[[550,0.44],[650,0.16]],"id":52385936},{"atb":[[550,0.44],[650,0.16]],"id":52385931},{"atb":[[17.5,14.77],[25,4.35]],"id":52385932}],"con":true,"img":false}]}
{"op":"mcm","clk":"11449866498","pt":1717315447076,"mc":[{"id":"1.229554897","rc":[{"atb":[[2.46,0],[2.62,61.73]],"id":52385907},{"atb":[[5.6,21.74],[5.1,0]],"id":52385893},{"atb":[[3.25,0],[3.5,40]],"id":52385903}],"con":true,"img":false}]}
{"op":"mcm","clk":"11449866531","pt":1717315447341,"mc":[{"id":"1.229554897","rc":[{"atb":[[1.6,0],[1.7,0],[1.75,0],[1.65,0]],"id":52385904}],"con":true,"img":false}]}
{"op":"mcm","clk":"11449866604","pt":1717315448061,"mc":[{"id":"1.229554897","rc":[{"atb":[[1.63,83.04],[1.58,135.3],[1.68,38.47],[1.53,197.43]],"id":52385904}],"con":true,"img":false}]}
{"op":"mcm","clk":"11449878899","pt":1717315568422,"mc":[{"id":"1.229554897","rc":[{"atb":[[2.46,68.49],[2.62,0]],"id":52385907}],"con":true,"img":false}]}
{"op":"mcm","clk":"11449889731","pt":1717315674958,"mc":[{"id":"1.229554897","rc":[{"atb":[[1.63,0]],"id":52385904}],"con":true,"img":false}]}
{"op":"mcm","clk":"11449889742","pt":1717315675008,"mc":[{"id":"1.229554897","rc":[{"atb":[[1.58,0],[1.68,0],[1.53,0]],"id":52385904}],"con":true,"img":false}]}
{"op":"mcm","clk":"11449889802","pt":1717315675628,"mc":[{"id":"1.229554897","rc":[{"atb":[[1.7,74.74]],"id":52385904}],"con":true,"img":false}]}
{"op":"mcm","clk":"11449889812","pt":1717315675731,"mc":[{"id":"1.229554897","rc":[{"atb":[[1.6,174.39],[1.75,34.88],[1.65,120.73]],"id":52385904}],"con":true,"img":false}]}
{"op":"mcm","clk":"11449893599","pt":1717315712196,"mc":[{"id":"1.229554897","rc":[{"atb":[[5.2,0],[4.2,0]],"id":52385907},{"atb":[[9.6,0],[14,0]],"id":52385909},{"atb":[[10.5,0],[8.2,0]],"id":52385918},{"atb":[[70,0],[38,0]],"id":52385886},{"atb":[[6.4,0],[8.4,0]],"id":52385920},{"atb":[[550,0],[650,0]],"id":52385888},{"atb":[[9,0],[12.5,0]],"id":52385889},{"atb":[[10,0],[15,0]],"id":52385882},{"atb":[[12,0],[8.8,0]],"id":52385884},{"atb":[[65,0],[36,0]],"id":52385917},{"atb":[[19,0],[14,0]],"id":52385895},{"atb":[[530,0],[630,0]],"id":52385923},{"atb":[[2.5,0],[2.3,0]],"id":52385891},{"atb":[[8.6,0],[6.6,0]],"id":52385893},{"atb":[[19,0],[14,0]],"id":52385934},{"atb":[[7.8,0],[5.9,0]],"id":52385903},{"atb":[[1.82,0],[1.92,0]],"id":52385904},{"atb":[[550,0],[650,0]],"id":52385936},{"atb":[[550,0],[650,0]],"id":52385931},{"atb":[[17.5,0],[25,0]],"id":52385932}],"con":true,"img":false}]}
{"op":"mcm","clk":"11449893610","pt":1717315712303,"mc":[{"id":"1.229554897","rc":[{"atb":[[5.6,0],[5.1,24.39]],"id":52385893},{"atb":[[3.25,44.44],[3.5,0]],"id":52385903}],"con":true,"img":false}]}
{"op":"mcm","clk":"11449898108","pt":1717315753868,"mc":[{"id":"1.229554897","rc":[{"atb":[[70,1.51],[38,6.59]],"id":52385886},{"atb":[[550,0.44],[650,0.16]],"id":52385888},{"atb":[[9,30.48],[12.5,9.08]],"id":52385889},{"atb":[[10,27.1],[15,7.46]],"id":52385882},{"atb":[[12,9.5],[8.8,31.27]],"id":52385884},{"atb":[[19,5.8],[14,18.76]],"id":52385895},{"atb":[[2.5,69.68],[2.3,187.62]],"id":52385891},{"atb":[[8.6,13.75],[6.6,43.55]],"id":52385893},{"atb":[[7.8,15.37],[5.9,49.77]],"id":52385903},{"atb":[[1.82,297.44],[1.92,113.61]],"id":52385904}],"con":true,"img":false}]}
{"op":"mcm","clk":"11449899234","pt":1717315764715,"mc":[{"id":"1.229554897","rc":[{"atb":[[5.2,24.88],[4.2,76.22]],"id":52385907},{"atb":[[9.6,28.36],[14,8.04]],"id":52385909},{"atb":[[10.5,11],[8.2,33.87]],"id":52385918},{"atb":[[6.4,45.16],[8.4,14.12]],"id":52385920},{"atb":[[65,1.63],[36,6.96]],"id":52385917},{"atb":[[530,0.46],[630,0.16]],"id":52385923},{"atb":[[19,5.8],[14,18.76]],"id":52385934},{"atb":[[550,0.44],[650,0.16]],"id":52385936},{"atb":[[550,0.44],[650,0.16]],"id":52385931},{"atb":[[17.5,14.77],[25,4.35]],"id":52385932}],"con":true,"img":false}]}
{"op":"mcm","clk":"11449909200","pt":1717315861822,"mc":[{"id":"1.229554897","rc":[{"atb":[[5.6,4.69],[5.4,2.77]],"id":52385907},{"atl":[[13.5,3.1],[14.5,3.6]],"id":52385907},{"atb":[[16.5,10.29],[17.5,3.83]],"id":52385909},{"atl":[[65,3.41],[75,3.89]],"id":52385909},{"atb":[[17.5,4.03],[18.5,3.9]],"id":52385918},{"atl":[[90,4.16],[100,4.34]],"id":52385918},{"atb":[[100,4.52],[120,3.04]],"id":52385886},{"atl":[[770,3.74],[790,4.12]],"id":52385886},{"atb":[[13,4.7],[14,4.54]],"id":52385920},{"atl":[[70,4.08],[80,2.9]],"id":52385920},{"atb":[[180,4.07],[200,4.23]],"id":52385888},{"atl":[[95,4.22],[110,2.64]],"id":52385889},{"atl":[[270,3.98],[250,3.66]],"id":52385882},{"atl":[[300,3.19],[320,2.66]],"id":52385884},{"atb":[[90,4.31],[100,2.62]],"id":52385917},{"atl":[[540,2.69],[560,4.34]],"id":52385917},{"atl":[[300,4.24],[320,3.66]],"id":52385895},{"atb":[[140,3.47],[160,4]],"id":52385923},{"atb":[[2.82,8.62],[2.86,8.43]],"id":52385891},{"atl":[[12,4.56],[13,4.31]],"id":52385891},{"atb":[[10.5,4.47],[9.8,3.38]],"id":52385893},{"atl":[[46,3.2],[50,3.69]],"id":52385893},{"atb":[[50,4.02],[60,2.69]],"id":52385934},{"atl":[[22,4.54],[24,3.97]],"id":52385903},{"atl":[[7.2,2.81],[7.6,4.1]],"id":52385904},{"atb":[[200,3.81],[220,4.22]],"id":52385931},{"atl":[[950,3.65],[970,2.92]],"id":52385932}],"con":true,"img":false}]}
{"op":"mcm","clk":"11449909227","pt":1717315862032,"mc":[{"id":"1.229554897","rc":[{"atl":[[21,5],[190,0]],"id":52385907},{"atl":[[360,2],[740,0]],"id":52385909},{"atl":[[780,0],[410,2]],"id":52385918},{"atl":[[780,0],[410,2]],"id":52385920},{"atl":[[570,2],[930,0]],"id":52385889},{"atb":[[2.88,8.62],[2.52,0]],"id":52385891},{"atl":[[36,2.86],[320,0]],"id":52385891},{"atl":[[620,0],[230,2]],"id":52385893},{"atl":[[85,2],[460,0]],"id":52385903},{"atl":[[7.2,5.62],[26,0]],"id":52385904}],"con":true,"img":false}]}
{"op":"mcm","clk":"11449909367","pt":1717315863114,"mc":[{"id":"1.229554897","rc":[{"atb":[[2.46,0],[2.66,60.24]],"id":52385907},{"atb":[[5.8,0],[6.6,10.14]],"id":52385909},{"atb":[[5.1,0],[5.8,20.83]],"id":52385893},{"atb":[[23,0],[28,3.7]],"id":52385934},{"atb":[[3.6,38.46],[3.25,0]],"id":52385903}],"con":true,"img":false}]}
{"op":"mcm","clk":"11449909943","pt":1717315868557,"mc":[{"id":"1.229554897","rc":[{"atb":[[18.5,0],[20,3.56]],"id":52385918},{"atl":[[720,3.67],[770,0]],"id":52385886},{"atb":[[14,0],[15,4.3]],"id":52385920},{"atb":[[100,0],[110,2.73]],"id":52385917},{"atl":[[540,0],[530,4.02]],"id":52385917},{"atb":[[2.86,0],[2.84,8.52]],"id":52385891},{"atb":[[10.5,0],[11,3.21]],"id":52385893},{"atl":[[21,3.6],[22,0]],"id":52385903}],"con":true,"img":false}]}
{"op":"mcm","clk":"11449909962","pt":1717315868715,"mc":[{"id":"1.229554897","rc":[{"atb":[[2.88,0],[2.86,17.24]],"id":52385891}],"con":true,"img":false}]}
{"op":"mcm","clk":"11449911036","pt":1717315878566,"mc":[{"id":"1.229554897","rc":[{"atl":[[720,0],[770,3.66]],"id":52385886},{"atb":[[19,4.43]],"id":52385918},{"atb":[[14,4.04]],"id":52385920},{"atl":[[530,0],[540,2.93]],"id":52385917},{"atl":[[21,0],[22,2.77]],"id":52385903}],"con":true,"img":false}]}
{"op":"mcm","clk":"11449912099","pt":1717315888682,"mc":[{"id":"1.229554897","rc":[{"atb":[[17.5,0]],"id":52385918},{"atb":[[13,0]],"id":52385920}],"con":true,"img":false}]}
{"op":"mcm","clk":"11449917169","pt":1717315936746,"mc":[{"id":"1.229554897","rc":[{"atb":[[2.66,0],[2.78,56.18]],"id":52385907},{"atb":[[7.4,15.62],[6,0]],"id":52385918},{"atb":[[23,0],[30,3.45]],"id":52385886},{"atb":[[7.4,15.62],[6,0]],"id":52385920},{"atb":[[24,0],[30,3.45]],"id":52385888},{"atb":[[22,0],[29,3.57]],"id":52385917},{"atb":[[23,0],[30,3.45]],"id":52385923},{"atb":[[3.6,0],[3.85,35.09]],"id":52385903},{"atb":[[24,0],[30,2]],"id":52385936},{"atb":[[24,0],[30,3.45]],"id":52385931}],"con":true,"img":false}]}
{"op":"mcm","clk":"11449917204","pt":1717315937006,"mc":[{"id":"1.229554897","rc":[{"atl":[[740,3.33],[770,0]],"id":52385886},{"atl":[[260,4.16],[250,0]],"id":52385882},{"atl":[[540,0],[530,3.44]],"id":52385917},{"atl":[[21,2.86],[22,0]],"id":52385903},{"atl":[[950,0],[960,3.5]],"id":52385932}],"con":true,"img":false}]}
{"op":"mcm","clk":"11449917214","pt":1717315937111,"mc":[{"id":"1.229554897","rc":[{"atb":[[1.6,0],[1.7,0],[1.75,0],[1.65,0]],"id":52385904}],"con":true,"img":false}]}
{"op":"mcm","clk":"11449917292","pt":1717315937837,"mc":[{"id":"1.229554897","rc":[{"atb":[[1.64,122.62],[1.59,177.35],[1.74,35.35],[1.69,75.82]],"id":52385904}],"con":true,"img":false}]}
{"op":"mcm","clk":"11449918246","pt":1717315947052,"mc":[{"id":"1.229554897","rc":[{"atl":[[760,3.32]],"id":52385886}],"con":true,"img":false}]}
{"op":"mcm","clk":"11449919316","pt":1717315957165,"mc":[{"id":"1.229554897","rc":[{"atl":[[790,0]],"id":52385886}],"con":true,"img":false}]}
{"op":"mcm","clk":"11449925363","pt":1717316016052,"mc":[{"id":"1.229554897","rc":[{"atl":[[740,0],[770,3.32]],"id":52385886},{"atl":[[530,0],[540,2.88]],"id":52385917},{"atl":[[21,0],[22,2.79]],"id":52385903}],"con":true,"img":false}]}
{"op":"mcm","clk":"11449926156","pt":1717316024056,"mc":[{"id":"1.229554897","rc":[{"atl":[[760,0],[740,4.46]],"id":52385886},{"atl":[[540,0],[530,4.09]],"id":52385917},{"atl":[[21,4.35],[22,0]],"id":52385903}],"con":true,"img":false}]}
{"op":"mcm","clk":"11449929421","pt":1717316056772,"mc":[{"id":"1.229554897","rc":[{"atb":[[2.66,49.78],[2.78,0]],"id":52385907}],"con":true,"img":false}]}
{"op":"mcm","clk":"11449931925","pt":1717316084442,"mc":[{"id":"1.229554897","rc":[{"atb":[[5.2,0],[4.2,0]],"id":52385907},{"atb":[[9.6,0],[14,0]],"id":52385909},{"atb":[[70,0],[38,0]],"id":52385886},{"atb":[[10.5,0],[8.2,0]],"id":52385918},{"atb":[[6.4,0],[8.4,0]],"id":52385920},{"atb":[[550,0],[650,0]],"id":52385888},{"atb":[[9,0],[12.5,0]],"id":52385889},{"atb":[[10,0],[15,0]],"id":52385882},{"atb":[[12,0],[8.8,0]],"id":52385884},{"atb":[[65,0],[36,0]],"id":52385917},{"atb":[[19,0],[14,0]],"id":52385895},{"atb":[[530,0],[630,0]],"id":52385923},{"atb":[[2.5,0],[2.3,0]],"id":52385891},{"atb":[[8.6,0],[6.6,0]],"id":52385893},{"atb":[[19,0],[14,0]],"id":52385934},{"atb":[[7.8,0],[5.9,0]],"id":52385903},{"atb":[[1.82,0],[1.92,0]],"id":52385904},{"atb":[[550,0],[650,0]],"id":52385936},{"atb":[[550,0],[650,0]],"id":52385931},{"atb":[[17.5,0],[25,0]],"id":52385932}],"con":true,"img":false}]}
{"op":"mcm","clk":"11449931943","pt":1717316084654,"mc":[{"id":"1.229554897","rc":[{"atb":[[3.6,38.46],[3.85,0]],"id":52385903}],"con":true,"img":false}]}
{"op":"mcm","clk":"11449932905","pt":1717316094863,"mc":[{"id":"1.229554897","rc":[{"atl":[[740,0],[790,3.29]],"id":52385886},{"atb":[[5.6,3.89],[5.8,2.95]],"id":52385889},{"atb":[[5.6,4.17],[5.8,3.07]],"id":52385882},{"atb":[[5.6,3.25],[5.8,2.7]],"id":52385884},{"atl":[[530,0],[540,2.78]],"id":52385917},{"atb":[[2.92,8.17],[2.96,8]],"id":52385895},{"atb":[[5.6,2.8],[5.8,4.37]],"id":52385903},{"atl":[[21,0],[22,4.6]],"id":52385903},{"atb":[[1.6,26.15],[1.62,25.31]],"id":52385904},{"atb":[[2.92,8.17],[2.96,8]],"id":52385932}],"con":true,"img":false}]}
{"op":"mcm","clk":"11449933207","pt":1717316098751,"mc":[{"id":"1.229554897","rc":[{"atl":[[740,3.84],[770,0]],"id":52385886},{"atl":[[540,0],[530,4]],"id":52385917},{"atl":[[21,4.2],[22,0]],"id":52385903},{"atb":[[170,4.32],[190,3.51]],"id":52385936}],"con":true,"img":false}]}
{"op":"mcm","clk":"11449934164","pt":1717316108747,"mc":[{"id":"1.229554897","rc":[{"atl":[[760,4.27]],"id":52385886}],"con":true,"img":false}]}
{"op":"mcm","clk":"11449934186","pt":1717316109059,"mc":[{"id":"1.229554897","rc":[{"atb":[[5.2,24.88],[4.2,76.22]],"id":52385907},{"atb":[[9.6,28.36],[14,8.04]],"id":52385909},{"atb":[[10.5,11],[8.2,33.87]],"id":52385918},{"atb":[[6.4,45.16],[8.4,14.12]],"id":52385920},{"atb":[[65,1.63],[36,6.96]],"id":52385917},{"atb":[[530,0.46],[630,0.16]],"id":52385923},{"atb":[[19,5.8],[14,18.76]],"id":52385934},{"atb":[[550,0.44],[650,0.16]],"id":52385936},{"atb":[[550,0.44],[650,0.16]],"id":52385931},{"atb":[[17.5,14.77],[25,4.35]],"id":52385932}],"con":true,"img":false}]}
{"op":"mcm","clk":"11449934194","pt":1717316109167,"mc":[{"id":"1.229554897","rc":[{"atb":[[70,1.51],[38,6.59]],"id":52385886},{"atb":[[550,0.44],[650,0.16]],"id":52385888},{"atb":[[9,30.48],[12.5,9.08]],"id":52385889},{"atb":[[10,27.1],[15,7.46]],"id":52385882},{"atb":[[12,9.5],[8.8,31.27]],"id":52385884},{"atb":[[19,5.8],[14,18.76]],"id":52385895},{"atb":[[2.5,69.68],[2.3,187.62]],"id":52385891},{"atb":[[8.6,13.75],[6.6,43.55]],"id":52385893},{"atb":[[7.8,15.37],[5.9,49.77]],"id":52385903},{"atb":[[1.82,297.44],[1.92,113.61]],"id":52385904}],"con":true,"img":false}]}
{"op":"mcm","clk":"11449934701","pt":1717316114971,"mc":[{"id":"1.229554897","rc":[{"atl":[[790,0]],"id":52385886}],"con":true,"img":false}]}
{"op":"mcm","clk":"11449934867","pt":1717316116788,"mc":[{"id":"1.229554897","rc":[{"atb":[[2.66,0],[2.78,49.78]],"id":52385907},{"atb":[[3.6,0],[3.85,35.09]],"id":52385903}],"con":true,"img":false}]}
{"op":"mcm","clk":"11449934896","pt":1717316117045,"mc":[{"id":"1.229554897","rc":[{"atl":[[740,0],[750,3.51]],"id":52385886},{"atl":[[75,4.42]],"id":52385920},{"atl":[[100,4.33]],"id":52385889},{"atl":[[310,3.51]],"id":52385884},{"atl":[[300,0],[310,4.14]],"id":52385895},{"atl":[[12,0],[12.5,3.99]],"id":52385891},{"atl":[[46,0],[48,4.37]],"id":52385893},{"atb":[[1.64,0],[1.59,0],[1.74,0],[1.62,0],[1.69,0]],"id":52385904},{"atl":[[960,0],[970,0]],"id":52385932}],"con":true,"img":false}]}
{"op":"mcm","clk":"11449934905","pt":1717316117147,"mc":[{"id":"1.229554897","rc":[{"atl":[[70,0]],"id":52385920},{"atl":[[95,0]],"id":52385889},{"atl":[[300,0]],"id":52385884}],"con":true,"img":false}]}
{"op":"mcm","clk":"11449934967","pt":1717316117772,"mc":[{"id":"1.229554897","rc":[{"atb":[[1.73,35.83],[1.63,124.57],[1.58,180.41],[1.68,76.94]],"id":52385904}],"con":true,"img":false}]}
{"op":"mcm","clk":"11449940102","pt":1717316173039,"mc":[{"id":"1.229554897","rc":[{"atb":[[18.5,4.57],[20,0]],"id":52385918},{"atb":[[15,0]],"id":52385920},{"atb":[[100,4.17],[110,0]],"id":52385917},{"atb":[[2.86,25.67],[2.84,0]],"id":52385891},{"atb":[[10.5,3.91]],"id":52385893},{"atb":[[190,0]],"id":52385936}],"con":true,"img":false}]}
{"op":"mcm","clk":"11449940113","pt":1717316173144,"mc":[{"id":"1.229554897","rc":[{"atb":[[11,0]],"id":52385893}],"con":true,"img":false}]}
{"op":"mcm","clk":"11449941105","pt":1717316183056,"mc":[{"id":"1.229554897","rc":[{"atb":[[17.5,4.69],[19,0]],"id":52385918},{"atb":[[13,3.65]],"id":52385920}],"con":true,"img":false}]}
{"op":"mcm","clk":"11449945965","pt":1717316236761,"mc":[{"id":"1.229554897","rc":[{"atb":[[2.66,49.78]],"id":52385907}],"con":true,"img":false}]}
{"op":"mcm","clk":"11449945975","pt":1717316236818,"mc":[{"id":"1.229554897","rc":[{"atb":[[2.78,0]],"id":52385907}],"con":true,"img":false}]}
{"op":"mcm","clk":"11449952403","pt":1717316311128,"mc":[{"id":"1.229554897","rc":[{"atb":[[3.2,45.45],[2.66,0]],"id":52385907},{"atl":[[34,3.03],[21,0]],"id":52385907},{"atb":[[6.6,0],[3.9,12.4]],"id":52385909},{"atl":[[85,2],[360,0]],"id":52385909},{"atb":[[8.6,13.16],[7.4,0]],"id":52385918},{"atl":[[410,0],[500,2]],"id":52385918},{"atb":[[14,6.9],[30,0]],"id":52385886},{"atl":[[740,2]],"id":52385886},{"atl":[[410,0],[480,2]],"id":52385920},{"atl":[[1000,2]],"id":52385888},{"atl":[[570,0],[160,2]],"id":52385889},{"atl":[[250,2]],"id":52385882},{"atl":[[300,2]],"id":52385884},{"atb":[[19.5,5.41],[29,0]],"id":52385917},{"atl":[[750,2]],"id":52385917},{"atl":[[590,2]],"id":52385895},{"atl":[[36,0],[60,2]],"id":52385891},{"atb":[[5.8,0],[7,16.67]],"id":52385893},{"atl":[[320,2],[230,0]],"id":52385893},{"atb":[[21,5],[28,0]],"id":52385934},{"atl":[[1000,2]],"id":52385934},{"atb":[[3.85,0],[2.66,30.74]],"id":52385903},{"atl":[[20,3.98],[85,0]],"id":52385903},{"atb":[[1.21,0],[1.76,131.58]],"id":52385904},{"atl":[[1000,2]],"id":52385932}],"con":true,"img":false}]}
{"op":"mcm","clk":"11449952435","pt":1717316311442,"mc":[{"id":"1.229554897","rc":[{"atb":[[5.6,0],[6.6,3.55]],"id":52385907},{"atb":[[16.5,0],[17.5,0],[19,0],[23,0],[28,0]],"id":52385909},{"atl":[[65,0],[44,2.86]],"id":52385909},{"atb":[[100,0],[120,0],[60,3.58]],"id":52385886},{"atl":[[720,4.06],[750,0]],"id":52385886},{"atb":[[180,0],[200,0],[100,2.86]],"id":52385888},{"atl":[[75,0],[85,4.44]],"id":52385920},{"atl":[[44,4.14],[100,0]],"id":52385889},{"atb":[[65,0],[36,0],[46,0],[28,0]],"id":52385882},{"atl":[[260,0],[190,3.09]],"id":52385882},{"atl":[[140,4.16],[310,0]],"id":52385884},{"atb":[[80,3.22],[100,0]],"id":52385917},{"atl":[[310,0],[110,4.64]],"id":52385895},{"atl":[[16,4.39],[12.5,0],[13,0]],"id":52385891},{"atb":[[150,2.94],[160,0]],"id":52385923},{"atl":[[48,0],[50,0],[60,3]],"id":52385893},{"atl":[[470,4.17],[490,3.89]],"id":52385934},{"atb":[[5.6,0],[5.8,0]],"id":52385903},{"atb":[[1.73,0],[1.63,0],[1.58,0],[1.68,0],[2.12,14.01]],"id":52385904},{"atb":[[540,0],[170,0],[390,0],[440,0],[490,0]],"id":52385936},{"atb":[[220,0],[120,3.07]],"id":52385931},{"atb":[[150,0],[75,0],[100,0],[50,0]],"id":52385932},{"atl":[[640,4.03],[660,4]],"id":52385932}],"con":true,"img":false}]}
{"op":"mcm","clk":"11449952451","pt":1717316311642,"mc":[{"id":"1.229554897","rc":[{"atl":[[200,2],[250,0]],"id":52385882},{"atl":[[760,2],[1000,0]],"id":52385932}],"con":true,"img":false}]}
{"op":"mcm","clk":"11449952494","pt":1717316312158,"mc":[{"id":"1.229554897","rc":[{"atb":[[17,1.64],[12,7.14],[9.8,11.89],[14.5,3.88]],"id":52385909},{"atb":[[32,0.84],[18,6.15],[21,3.92],[26,2.09]],"id":52385882},{"atb":[[270,0.19],[320,0.08],[170,0.62],[220,0.36]],"id":52385936},{"atb":[[2.02,102.58],[2.32,19.82],[2.22,42.89],[2.12,84.09]],"id":52385904},{"atb":[[130,0.2],[65,1.22],[90,0.59],[46,2.32]],"id":52385932}],"con":true,"img":false}]}
{"op":"mcm","clk":"11449952582","pt":1717316313138,"mc":[{"id":"1.229554897","rc":[{"atb":[[11,3.14],[12,10.91]],"id":52385909},{"atl":[[80,0]],"id":52385920},{"atb":[[90,0]],"id":52385917},{"atb":[[200,0]],"id":52385931}],"con":true,"img":false}]}
{"op":"mcm","clk":"11449953296","pt":1717316321449,"mc":[{"id":"1.229554897","rc":[{"atb":[[6.2,3.43]],"id":52385907},{"atb":[[50,3.45]],"id":52385886},{"atl":[[740,5.06]],"id":52385886},{"atl":[[95,2.7]],"id":52385920},{"atb":[[90,2.9]],"id":52385888},{"atl":[[48,3.63]],"id":52385889},{"atl":[[210,3.65]],"id":52385882},{"atl":[[160,3.17]],"id":52385884},{"atb":[[70,3.79]],"id":52385917},{"atl":[[130,4.1]],"id":52385895},{"atl":[[17,3.89]],"id":52385891},{"atl":[[70,4.63]],"id":52385893},{"atb":[[2.08,14.53]],"id":52385904},{"atb":[[100,3.57]],"id":52385931}],"con":true,"img":false}]}
{"op":"mcm","clk":"11449953442","pt":1717316323053,"mc":[{"id":"1.229554897","rc":[{"atl":[[48,3.43]],"id":52385909}],"con":true,"img":false}]}
{"op":"mcm","clk":"11449953669","pt":1717316325551,"mc":[{"id":"1.229554897","rc":[{"atb":[[5.4,0]],"id":52385907},{"atl":[[75,0]],"id":52385909},{"atl":[[760,0]],"id":52385886},{"atl":[[110,0]],"id":52385889},{"atl":[[270,0]],"id":52385882},{"atl":[[320,0]],"id":52385884},{"atl":[[320,0]],"id":52385895},{"atb":[[1.6,0]],"id":52385904}],"con":true,"img":false}]}
{"op":"mcm","clk":"11449953682","pt":1717316325762,"mc":[{"id":"1.229554897","rc":[{"atl":[[710,2],[740,3.06]],"id":52385886},{"atl":[[300,0],[190,2]],"id":52385884},{"atl":[[760,2],[1000,0]],"id":52385934}],"con":true,"img":false}]}
{"op":"mcm","clk":"11449955314","pt":1717316346581,"mc":[{"id":"1.229554897","rc":[{"atb":[[2.12,70.07]],"id":52385904}],"con":true,"img":false}]}
{"op":"mcm","clk":"11449956841","pt":1717316367126,"mc":[{"id":"1.229554897","rc":[{"atl":[[46,3.87]],"id":52385889},{"atl":[[190,0]],"id":52385882},{"atb":[[2.86,17.24]],"id":52385891},{"atb":[[2.02,0],[2.32,0],[2.22,0],[2.12,0]],"id":52385904}],"con":true,"img":false}]}
{"op":"mcm","clk":"11449956850","pt":1717316367231,"mc":[{"id":"1.229554897","rc":[{"atb":[[2.86,0],[2.84,54.35]],"id":52385891}],"con":true,"img":false}]}
{"op":"mcm","clk":"11449956898","pt":1717316367845,"mc":[{"id":"1.229554897","rc":[{"atb":[[2.02,102.58],[2.32,19.82],[2.22,42.89],[2.12,70.07]],"id":52385904}],"con":true,"img":false}]}
{"op":"mcm","clk":"11449956926","pt":1717316368257,"mc":[{"id":"1.229554897","rc":[{"atb":[[6.8,3.85],[6.6,0]],"id":52385907},{"atb":[[20,4.27]],"id":52385918},{"atb":[[14,0],[15,3.85]],"id":52385920},{"atl":[[190,3.43]],"id":52385882},{"atb":[[2.84,62.87]],"id":52385891},{"atb":[[2.1,14.26]],"id":52385904}],"con":true,"img":false}]}
{"op":"mcm","clk":"11449956932","pt":1717316368361,"mc":[{"id":"1.229554897","rc":[{"atb":[[18.5,0]],"id":52385918},{"atl":[[46,0],[48,0]],"id":52385889}],"con":true,"img":false}]}
{"op":"mcm","clk":"11449957002","pt":1717316369136,"mc":[{"id":"1.229554897","rc":[{"atl":[[790,3.28]],"id":52385886}],"con":true,"img":false}]}
{"op":"mcm","clk":"11449957012","pt":1717316369241,"mc":[{"id":"1.229554897","rc":[{"atb":[[11,4.13]],"id":52385893}],"con":true,"img":false}]}
{"op":"mcm","clk":"11449957022","pt":1717316369345,"mc":[{"id":"1.229554897","rc":[{"atb":[[10.5,0]],"id":52385893}],"con":true,"img":false}]}
{"op":"mcm","clk":"11449957999","pt":1717316382498,"mc":[{"id":"1.229554897","rc":[{"atb":[[2.12,84.09]],"id":52385904}],"con":true,"img":false}]}
{"op":"mcm","clk":"11449958751","pt":1717316392781,"mc":[{"id":"1.229554897","rc":[{"atl":[[44,0]],"id":52385889},{"atl":[[140,0]],"id":52385884}],"con":true,"img":false}]}
{"op":"mcm","clk":"11449958762","pt":1717316392882,"mc":[{"id":"1.229554897","rc":[{"atl":[[160,0],[170,2]],"id":52385889}],"con":true,"img":false}]}
{"op":"mcm","clk":"11449959578","pt":1717316402809,"mc":[{"id":"1.229554897","rc":[{"atb":[[6.6,2.89]],"id":52385907},{"atb":[[14,3.44],[15,0]],"id":52385920},{"atl":[[44,3.2],[48,3.54]],"id":52385889},{"atl":[[140,4.01]],"id":52385884},{"atb":[[2.86,8.43],[2.84,54.35]],"id":52385891},{"atl":[[16,0],[16.5,3.41]],"id":52385891},{"atb":[[10.5,3.99],[11,0]],"id":52385893},{"atl":[[65,3.26],[60,0]],"id":52385893},{"atb":[[2.08,0]],"id":52385904}],"con":true,"img":false}]}
{"op":"mcm","clk":"11449959589","pt":1717316402917,"mc":[{"id":"1.229554897","rc":[{"atb":[[2.88,8.62],[2.84,0]],"id":52385891}],"con":true,"img":false}]}
{"op":"mcm","clk":"11449959608","pt":1717316403123,"mc":[{"id":"1.229554897","rc":[{"atb":[[11.5,4.19]],"id":52385909},{"atb":[[2.02,0],[2.32,0],[2.22,0],[2.12,0]],"id":52385904},{"atb":[[130,2.67]],"id":52385931}],"con":true,"img":false}]}
{"op":"mcm","clk":"11449959618","pt":1717316403229,"mc":[{"id":"1.229554897","rc":[{"atb":[[6.8,0]],"id":52385907}],"con":true,"img":false}]}
{"op":"mcm","clk":"11449959686","pt":1717316403905,"mc":[{"id":"1.229554897","rc":[{"atb":[[2,104.64],[2.3,20.12],[2.2,43.6],[2.1,85.61]],"id":52385904}],"con":true,"img":false}]}
{"op":"mcm","clk":"11449959701","pt":1717316404114,"mc":[{"id":"1.229554897","rc":[{"atb":[[12,7.14]],"id":52385909},{"atl":[[720,0],[740,0]],"id":52385886},{"atl":[[44,0],[46,3.68]],"id":52385889},{"atl":[[190,0]],"id":52385882},{"atl":[[140,0]],"id":52385884},{"atl":[[530,0]],"id":52385917},{"atl":[[23,4.13]],"id":52385903},{"atb":[[2.12,14.01]],"id":52385904},{"atb":[[100,0]],"id":52385931}],"con":true,"img":false}]}
{"op":"mcm","clk":"11449959713","pt":1717316404216,"mc":[{"id":"1.229554897","rc":[{"atl":[[780,2]],"id":52385886},{"atb":[[18.5,2.94],[20,0]],"id":52385918},{"atl":[[21,0]],"id":52385903}],"con":true,"img":false}]}
{"op":"mcm","clk":"11449959721","pt":1717316404314,"mc":[{"id":"1.229554897","rc":[{"atl":[[710,0]],"id":52385886},{"atl":[[22,4.76]],"id":52385903}],"con":true,"img":false}]}
{"op":"mcm","clk":"11449959729","pt":1717316404421,"mc":[{"id":"1.229554897","rc":[{"atl":[[20,0]],"id":52385903}],"con":true,"img":false}]}
{"op":"mcm","clk":"11449960422","pt":1717316412828,"mc":[{"id":"1.229554897","rc":[{"atl":[[140,3.52]],"id":52385884}],"con":true,"img":false}]}
{"op":"mcm","clk":"11449960450","pt":1717316413088,"mc":[{"id":"1.229554897","rc":[{"atl":[[720,3.24]],"id":52385886},{"atl":[[190,2.66]],"id":52385882},{"atl":[[530,3.98]],"id":52385917}],"con":true,"img":false}]}
{"op":"mcm","clk":"11449960526","pt":1717316413811,"mc":[{"id":"1.229554897","rc":[{"atl":[[44,3.76]],"id":52385889}],"con":true,"img":false}]}
{"op":"mcm","clk":"11449960530","pt":1717316413912,"mc":[{"id":"1.229554897","rc":[{"atb":[[6.8,2.82],[6.6,0]],"id":52385907},{"atb":[[18.5,0],[20,2.98]],"id":52385918},{"atb":[[14,0],[15,4.12]],"id":52385920},{"atl":[[46,0]],"id":52385889},{"atb":[[2.86,0],[2.84,8.52]],"id":52385891},{"atb":[[10.5,0],[11,3.66]],"id":52385893},{"atl":[[21,4.05],[23,0]],"id":52385903},{"atb":[[2.12,0]],"id":52385904}],"con":true,"img":false}]}
{"op":"mcm","clk":"11449960545","pt":1717316414130,"mc":[{"id":"1.229554897","rc":[{"atb":[[2.88,0],[2.86,17.24]],"id":52385891},{"atb":[[2.06,14.8]],"id":52385904}],"con":true,"img":false}]}
{"op":"mcm","clk":"11449960727","pt":1717316416449,"mc":[{"id":"1.229554897","rc":[{"atb":[[6.8,0],[6.6,3.74]],"id":52385907},{"atb":[[18.5,3.28],[20,0]],"id":52385918},{"atl":[[720,0],[770,3.25]],"id":52385886},{"atb":[[14,3.02],[15,0]],"id":52385920},{"atl":[[44,0],[46,4.01]],"id":52385889},{"atl":[[190,0]],"id":52385882},{"atl":[[140,0]],"id":52385884},{"atl":[[530,0],[540,3.11]],"id":52385917},{"atb":[[2.86,25.67],[2.84,0]],"id":52385891},{"atb":[[10.5,3.06],[11,0]],"id":52385893},{"atl":[[21,0],[22,7.81]],"id":52385903},{"atb":[[2.12,14.01],[2.1,71.34]],"id":52385904}],"con":true,"img":false}]}
{"op":"mcm","clk":"11449960802","pt":1717316417329,"mc":[{"id":"1.229554897","rc":[{"atl":[[720,3.1],[770,0]],"id":52385886},{"atb":[[7.4,0],[8.4,27.63]],"id":52385920},{"atl":[[1000,0]],"id":52385888},{"atl":[[44,3.71],[46,0]],"id":52385889},{"atl":[[190,3.01]],"id":52385882},{"atl":[[140,3.96],[190,0],[200,2]],"id":52385884},{"atl":[[540,0],[530,3.29]],"id":52385917},{"atl":[[21,3.58],[22,4.76]],"id":52385903}],"con":true,"img":false}]}
{"op":"mcm","clk":"11449960824","pt":1717316417636,"mc":[{"id":"1.229554897","rc":[{"atb":[[11.5,0],[12,11.76]],"id":52385909},{"atb":[[65,3.44],[60,0]],"id":52385886},{"atb":[[100,0],[110,3.15]],"id":52385888},{"atb":[[80,0],[85,4.54]],"id":52385917},{"atl":[[16.5,0],[16,4.53]],"id":52385891}],"con":true,"img":false}]}
{"op":"mcm","clk":"11449960847","pt":1717316417944,"mc":[{"id":"1.229554897","rc":[{"atl":[[710,2],[780,0]],"id":52385886}],"con":true,"img":false}]}
{"op":"mcm","clk":"11449960859","pt":1717316418002,"mc":[{"id":"1.229554897","rc":[{"atl":[[20,3.98],[22,0]],"id":52385903}],"con":true,"img":false}]}
{"op":"mcm","clk":"11449961481","pt":1717316425217,"mc":[{"id":"1.229554897","rc":[{"atb":[[2.84,8.52]],"id":52385891},{"atb":[[10.5,0]],"id":52385893}],"con":true,"img":false}]}
{"op":"mcm","clk":"11449961489","pt":1717316425319,"mc":[{"id":"1.229554897","rc":[{"atb":[[6.8,3.76],[6.6,0]],"id":52385907},{"atb":[[18.5,0],[20,3.06]],"id":52385918},{"atb":[[14,0],[15,3.14]],"id":52385920},{"atb":[[2.86,17.24]],"id":52385891},{"atb":[[11,4.14]],"id":52385893},{"atb":[[2.12,0],[2.1,85.61]],"id":52385904}],"con":true,"img":false}]}
{"op":"mcm","clk":"11449961625","pt":1717316426931,"mc":[{"id":"1.229554897","rc":[{"atb":[[6.8,0],[6.6,3.64]],"id":52385907},{"atb":[[18.5,4.4],[20,0]],"id":52385918},{"atl":[[720,0],[770,4.51]],"id":52385886},{"atb":[[14,3.11],[15,0]],"id":52385920},{"atl":[[44,0],[46,3.95]],"id":52385889},{"atl":[[190,0]],"id":52385882},{"atl":[[140,0]],"id":52385884},{"atl":[[530,0],[540,3.25]],"id":52385917},{"atb":[[2.86,25.67],[2.84,0]],"id":52385891},{"atb":[[10.5,4.67],[11,0]],"id":52385893},{"atl":[[21,0],[22,4.63]],"id":52385903},{"atb":[[2.12,14.01],[2.1,71.34]],"id":52385904}],"con":true,"img":false}]}
{"op":"mcm","clk":"11449961634","pt":1717316427032,"mc":[{"id":"1.229554897","rc":[{"atl":[[760,2]],"id":52385886},{"atl":[[21,5]],"id":52385903}],"con":true,"img":false}]}
{"op":"mcm","clk":"11449961638","pt":1717316427141,"mc":[{"id":"1.229554897","rc":[{"atl":[[710,0]],"id":52385886},{"atl":[[20,0]],"id":52385903}],"con":true,"img":false}]}
{"op":"mcm","clk":"11449962061","pt":1717316432460,"mc":[{"id":"1.229554897","rc":[{"atb":[[18,5.88],[14,0]],"id":52385886},{"atb":[[8.6,0],[9.8,11.36]],"id":52385918},{"atl":[[200,0],[230,2]],"id":52385882},{"atl":[[200,0],[210,2]],"id":52385884},{"atb":[[19.5,0],[26,4]],"id":52385917},{"atb":[[1.7,142.7],[1.76,0]],"id":52385904}],"con":true,"img":false}]}
{"op":"mcm","clk":"11449962080","pt":1717316432769,"mc":[{"id":"1.229554897","rc":[{"atl":[[90,0]],"id":52385918},{"atb":[[65,0],[75,2.81]],"id":52385886},{"atl":[[720,4.69],[770,0]],"id":52385886},{"atl":[[85,0],[90,4.64]],"id":52385920},{"atb":[[110,0],[120,3.63]],"id":52385888},{"atl":[[44,2.77],[46,0]],"id":52385889},{"atl":[[190,3.07]],"id":52385882},{"atl":[[140,3.16]],"id":52385884},{"atb":[[85,0],[100,3.27]],"id":52385917},{"atl":[[540,0],[530,3.44]],"id":52385917},{"atl":[[110,0],[120,4.57]],"id":52385895},{"atl":[[16,0],[16.5,4.16]],"id":52385891},{"atb":[[150,0],[160,4.51]],"id":52385923},{"atl":[[65,0]],"id":52385893},{"atl":[[21,9.67],[22,0]],"id":52385903},{"atb":[[130,0],[140,2.73]],"id":52385931}],"con":true,"img":false}]}
{"op":"mcm","clk":"11449962423","pt":1717316436971,"mc":[{"id":"1.229554897","rc":[{"atl":[[120,4.21]],"id":52385918},{"atl":[[80,4.47]],"id":52385893}],"con":true,"img":false}]}
{"op":"mcm","clk":"11449962434","pt":1717316437076,"mc":[{"id":"1.229554897","rc":[{"atb":[[6.8,3.79],[6.6,0]],"id":52385907},{"atb":[[18.5,0],[20,4.46]],"id":52385918},{"atb":[[14,0],[15,3.86]],"id":52385920},{"atb":[[2.86,17.24],[2.84,8.52]],"id":52385891},{"atb":[[10.5,0],[11,2.99]],"id":52385893},{"atb":[[2.12,0],[2.1,85.61]],"id":52385904}],"con":true,"img":false}]}
{"op":"mcm","clk":"11449962535","pt":1717316438365,"mc":[{"id":"1.229554897","rc":[{"atb":[[6.8,0],[6.6,3.46]],"id":52385907},{"atb":[[18.5,2.79]],"id":52385918},{"atl":[[720,0],[770,4.3]],"id":52385886},{"atb":[[14,3.37],[15,0]],"id":52385920},{"atl":[[44,0],[46,3.45]],"id":52385889},{"atl":[[190,0]],"id":52385882},{"atl":[[140,0]],"id":52385884},{"atl":[[530,0],[540,4.67]],"id":52385917},{"atb":[[2.86,25.67],[2.84,0]],"id":52385891},{"atb":[[10.5,2.92],[11,0]],"id":52385893},{"atl":[[21,5],[22,4.15]],"id":52385903},{"atb":[[2.12,14.01],[2.1,71.34]],"id":52385904}],"con":true,"img":false}]}
{"op":"mcm","clk":"11449962540","pt":1717316438465,"mc":[{"id":"1.229554897","rc":[{"atb":[[20,0]],"id":52385918}],"con":true,"img":false}]}
{"op":"mcm","clk":"11449962900","pt":1717316442750,"mc":[{"id":"1.229554897","rc":[{"atb":[[100,3.14]],"id":52385888},{"atl":[[140,2.74]],"id":52385884}],"con":true,"img":false}]}
{"op":"mcm","clk":"11449962908","pt":1717316442854,"mc":[{"id":"1.229554897","rc":[{"atl":[[190,4.02]],"id":52385882}],"con":true,"img":false}]}
{"op":"mcm","clk":"11449963022","pt":1717316444251,"mc":[{"id":"1.229554897","rc":[{"atl":[[720,4.19],[770,0]],"id":52385886},{"atl":[[44,3.1],[46,0]],"id":52385889},{"atl":[[540,0],[530,4.24]],"id":52385917},{"atl":[[21,8.13]],"id":52385903}],"con":true,"img":false}]}
{"op":"mcm","clk":"11449963026","pt":1717316444354,"mc":[{"id":"1.229554897","rc":[{"atl":[[730,2],[760,0]],"id":52385886},{"atb":[[90,0]],"id":52385888},{"atl":[[22,0]],"id":52385903}],"con":true,"img":false}]}
{"op":"mcm","clk":"11449963134","pt":1717316445954,"mc":[{"id":"1.229554897","rc":[{"atb":[[6.8,2.63],[6.6,0]],"id":52385907},{"atb":[[18.5,0],[20,2.79]],"id":52385918},{"atb":[[14,0],[15,2.68]],"id":52385920},{"atb":[[2.86,17.24],[2.84,8.52]],"id":52385891},{"atb":[[10.5,0],[11,4.3]],"id":52385893},{"atb":[[2.12,0],[2.1,85.61]],"id":52385904}],"con":true,"img":false}]}
{"op":"mcm","clk":"11449963161","pt":1717316446371,"mc":[{"id":"1.229554897","rc":[{"atl":[[720,0],[770,3.87]],"id":52385886},{"atl":[[44,0],[46,2.97]],"id":52385889},{"atl":[[190,0]],"id":52385882},{"atl":[[140,0]],"id":52385884},{"atl":[[530,0],[540,3.43]],"id":52385917},{"atl":[[21,5],[22,3.18]],"id":52385903}],"con":true,"img":false}]}
{"op":"mcm","clk":"11449963165","pt":1717316446474,"mc":[{"id":"1.229554897","rc":[{"atl":[[730,0],[760,2]],"id":52385886}],"con":true,"img":false}]}
{"op":"mcm","clk":"11449963206","pt":1717316446987,"mc":[{"id":"1.229554897","rc":[{"atb":[[2.86,25.67],[2.84,0]],"id":52385891},{"atb":[[2.12,14.01],[2.1,71.34]],"id":52385904}],"con":true,"img":false}]}
{"op":"mcm","clk":"11449963291","pt":1717316448075,"mc":[{"id":"1.229554897","rc":[{"atl":[[720,4.63],[770,0]],"id":52385886},{"atl":[[44,2.81]],"id":52385889},{"atl":[[190,4.01]],"id":52385882},{"atl":[[140,4.58]],"id":52385884},{"atl":[[530,3.43]],"id":52385917},{"atb":[[2.86,17.24],[2.84,8.52]],"id":52385891},{"atl":[[21,8.93],[22,0]],"id":52385903},{"atb":[[2.1,85.61]],"id":52385904}],"con":true,"img":false}]}
{"op":"mcm","clk":"11449963297","pt":1717316448180,"mc":[{"id":"1.229554897","rc":[{"atl":[[46,0]],"id":52385889},{"atl":[[540,0]],"id":52385917},{"atb":[[2.12,0]],"id":52385904}],"con":true,"img":false}]}
{"op":"mcm","clk":"11449963342","pt":1717316449005,"mc":[{"id":"1.229554897","rc":[{"atb":[[6.8,0],[6.6,2.95]],"id":52385907},{"atl":[[720,0],[770,4.09]],"id":52385886},{"atb":[[18.5,3.68],[20,0]],"id":52385918},{"atb":[[14,3.69],[15,0]],"id":52385920},{"atl":[[44,0],[46,2.94]],"id":52385889},{"atl":[[190,0]],"id":52385882},{"atl":[[140,0]],"id":52385884},{"atl":[[530,0],[540,4.4]],"id":52385917},{"atb":[[2.86,25.67],[2.84,0]],"id":52385891},{"atb":[[10.5,3.38],[11,0]],"id":52385893},{"atl":[[21,5],[22,3.3]],"id":52385903},{"atb":[[2.12,14.01],[2.1,71.34]],"id":52385904}],"con":true,"img":false}]}
{"op":"mcm","clk":"11449963477","pt":1717316450874,"mc":[{"id":"1.229554897","rc":[{"atb":[[6.8,3.32],[6.6,0]],"id":52385907},{"atl":[[720,3.48],[770,0]],"id":52385886},{"atb":[[18.5,0],[20,3.19]],"id":52385918},{"atb":[[14,0],[15,4.25]],"id":52385920},{"atl":[[44,3.62],[46,0]],"id":52385889},{"atl":[[190,2.88]],"id":52385882},{"atl":[[140,3.25]],"id":52385884},{"atl":[[540,0],[530,3.45]],"id":52385917},{"atb":[[2.86,17.24],[2.84,8.52]],"id":52385891},{"atb":[[10.5,0],[11,3.81]],"id":52385893},{"atl":[[21,8.65]],"id":52385903},{"atb":[[2.12,0],[2.1,85.61]],"id":52385904}],"con":true,"img":false}]}
{"op":"mcm","clk":"11449963487","pt":1717316450975,"mc":[{"id":"1.229554897","rc":[{"atl":[[22,0]],"id":52385903}],"con":true,"img":false}]}
{"op":"mcm","clk":"11449963606","pt":1717316452572,"mc":[{"id":"1.229554897","rc":[{"atb":[[32,0],[18,0],[21,0],[26,0]],"id":52385882},{"atb":[[320,0],[170,0],[220,0]],"id":52385936},{"atb":[[130,0],[65,0],[90,0]],"id":52385932}],"con":true,"img":false}]}
{"op":"mcm","clk":"11449963614","pt":1717316452674,"mc":[{"id":"1.229554897","rc":[{"atb":[[270,0]],"id":52385936},{"atb":[[46,0]],"id":52385932}],"con":true,"img":false}]}
{"op":"mcm","clk":"11449963621","pt":1717316452777,"mc":[{"id":"1.229554897","rc":[{"atl":[[750,0],[810,2]],"id":52385917},{"atb":[[21,0],[26,4]],"id":52385934}],"con":true,"img":false}]}
{"op":"mcm","clk":"11449963639","pt":1717316453086,"mc":[{"id":"1.229554897","rc":[{"atl":[[720,0],[770,3.04]],"id":52385886},{"atl":[[90,0]],"id":52385920},{"atl":[[44,0],[46,3.37]],"id":52385889},{"atl":[[190,0]],"id":52385882},{"atl":[[140,0]],"id":52385884},{"atl":[[530,0],[540,4.06]],"id":52385917},{"atl":[[21,5],[22,3.09]],"id":52385903},{"atb":[[150,3.44],[170,3.91]],"id":52385936}],"con":true,"img":false}]}
{"op":"mcm","clk":"11449963649","pt":1717316453293,"mc":[{"id":"1.229554897","rc":[{"atb":[[38,0.71],[19.5,5.66],[24,3.41],[29,1.87]],"id":52385882},{"atb":[[290,0.27],[390,0.07],[240,0.44]],"id":52385936},{"atb":[[150,0.18],[75,1.06],[100,0.53]],"id":52385932}],"con":true,"img":false}]}
{"op":"mcm","clk":"11449963652","pt":1717316453395,"mc":[{"id":"1.229554897","rc":[{"atb":[[340,0.15]],"id":52385936},{"atb":[[50,2.13]],"id":52385932}],"con":true,"img":false}]}
{"op":"mcm","clk":"11449964189","pt":1717316460895,"mc":[{"id":"1.229554897","rc":[{"atb":[[19,2.98]],"id":52385918},{"atb":[[14,2.69]],"id":52385920},{"atl":[[110,3.34]],"id":52385920},{"atl":[[230,6.16]],"id":52385882},{"atl":[[180,3.6]],"id":52385884}],"con":true,"img":false}]}
{"op":"mcm","clk":"11449964343","pt":1717316463104,"mc":[{"id":"1.229554897","rc":[{"atb":[[65,3.23]],"id":52385886}],"con":true,"img":false}]}
{"op":"mcm","clk":"11449964351","pt":1717316463160,"mc":[{"id":"1.229554897","rc":[{"atb":[[90,4.44]],"id":52385917}],"con":true,"img":false}]}
{"op":"mcm","clk":"11449964714","pt":1717316467981,"mc":[{"id":"1.229554897","rc":[{"atl":[[560,2],[500,0]],"id":52385918},{"atb":[[8.4,14.12],[9.4,11.9]],"id":52385920},{"atl":[[210,0],[220,2]],"id":52385884},{"atl":[[760,0],[830,2]],"id":52385932}],"con":true,"img":false}]}
{"op":"mcm","clk":"11449964746","pt":1717316468292,"mc":[{"id":"1.229554897","rc":[{"atb":[[17.5,0]],"id":52385918},{"atb":[[75,0],[80,4.66],[50,0]],"id":52385886},{"atb":[[13,0]],"id":52385920},{"atb":[[70,0]],"id":52385917},{"atb":[[290,0],[340,0],[390,0],[240,0]],"id":52385936}],"con":true,"img":false}]}
{"op":"mcm","clk":"11449964802","pt":1717316469014,"mc":[{"id":"1.229554897","rc":[{"atb":[[300,0.26],[350,0.15],[400,0.07],[250,0.42]],"id":52385936}],"con":true,"img":false}]}
{"op":"mcm","clk":"11449966463","pt":1717316492135,"mc":[{"id":"1.229554897","rc":[{"atb":[[5.2,0],[4.2,0]],"id":52385907},{"atb":[[9.6,0],[14,0]],"id":52385909},{"atb":[[10.5,0],[8.2,0]],"id":52385918},{"atb":[[70,0],[38,0]],"id":52385886},{"atb":[[6.4,0],[8.4,0]],"id":52385920},{"atb":[[550,0],[650,0]],"id":52385888},{"atb":[[9,0],[12.5,0]],"id":52385889},{"atb":[[10,0],[15,0]],"id":52385882},{"atb":[[12,0],[8.8,0]],"id":52385884},{"atb":[[65,0],[36,0]],"id":52385917},{"atb":[[19,0],[14,0]],"id":52385895},{"atb":[[2.5,0],[2.3,0]],"id":52385891},{"atb":[[530,0],[630,0]],"id":52385923},{"atb":[[8.6,0],[6.6,0]],"id":52385893},{"atb":[[19,0],[14,0]],"id":52385934},{"atb":[[7.8,0],[5.9,0]],"id":52385903},{"atb":[[550,0],[650,0]],"id":52385936},{"atb":[[1.82,0],[1.92,0]],"id":52385904},{"atb":[[550,0],[650,0]],"id":52385931},{"atb":[[17.5,0],[25,0]],"id":52385932}],"con":true,"img":false}]}
{"op":"mcm","clk":"11449967207","pt":1717316502504,"mc":[{"id":"1.229554897","rc":[{"atb":[[4.8,3.47],[4.6,3.66]],"id":52385903}],"con":true,"img":false}]}
{"op":"mcm","clk":"11449967805","pt":1717316511433,"mc":[{"id":"1.229554897","rc":[{"atb":[[2.82,6.86],[3.2,0]],"id":52385907},{"atl":[[34,0],[21,5]],"id":52385907},{"atb":[[6.8,12.4],[3.9,0]],"id":52385909},{"atl":[[310,2],[85,0]],"id":52385909},{"atb":[[18,0],[29,3.57]],"id":52385886},{"atl":[[760,0]],"id":52385886},{"atb":[[6.2,6.38],[9.8,0]],"id":52385918},{"atl":[[560,0],[230,2]],"id":52385918},{"atb":[[6.8,8.52],[9.4,0]],"id":52385920},{"atl":[[290,2],[480,0]],"id":52385920},{"atl":[[170,0],[490,2]],"id":52385889},{"atl":[[230,4.16],[970,2]],"id":52385882},{"atl":[[220,0]],"id":52385884},{"atb":[[32,3.23],[26,0]],"id":52385917},{"atl":[[810,0]],"id":52385917},{"atl":[[590,0],[960,2]],"id":52385895},{"atl":[[29,3.57],[60,0]],"id":52385891},{"atb":[[5.2,7.64],[7,0]],"id":52385893},{"atl":[[320,0],[160,2]],"id":52385893},{"atb":[[26,0]],"id":52385934},{"atl":[[760,0]],"id":52385934},{"atb":[[4,30.74]],"id":52385903},{"atl":[[110,2]],"id":52385903},{"atb":[[1.28,129.21],[1.7,0]],"id":52385904},{"atl":[[830,0]],"id":52385932}],"con":true,"img":false}]}
{"op":"mcm","clk":"11449967809","pt":1717316511537,"mc":[{"id":"1.229554897","rc":[{"atb":[[2.82,0],[3,6.86]],"id":52385907},{"atl":[[18.5,5.71],[21,0]],"id":52385907},{"atb":[[6.8,0],[7.8,12.4]],"id":52385909},{"atb":[[7.2,6.38],[6.2,0]],"id":52385918},{"atb":[[34,3.03],[29,0]],"id":52385886},{"atl":[[440,2],[490,0]],"id":52385889},{"atl":[[870,2],[970,0]],"id":52385882},{"atl":[[860,2],[960,0]],"id":52385895},{"atl":[[26,4],[29,0]],"id":52385891},{"atb":[[5.2,0],[5.9,7.64]],"id":52385893},{"atb":[[34,3.03]],"id":52385934},{"atb":[[4,0],[4.5,28.57],[2.66,0]],"id":52385903},{"atl":[[21,0]],"id":52385903}],"con":true,"img":false}]}
{"op":"mcm","clk":"11449967821","pt":1717316511747,"mc":[{"id":"1.229554897","rc":[{"atb":[[6.8,0],[5.7,4.67]],"id":52385907},{"atb":[[17,0],[17.5,3.18],[12,0],[9.8,0],[14.5,0]],"id":52385909},{"atl":[[44,0],[48,0],[60,2.75]],"id":52385909},{"atl":[[90,4.6],[100,0]],"id":52385918},{"atb":[[80,0],[120,3.93]],"id":52385886},{"atl":[[65,3.52],[95,0]],"id":52385920},{"atb":[[200,4.2],[120,0]],"id":52385888},{"atl":[[85,3.19],[46,0],[48,0]],"id":52385889},{"atb":[[38,0],[19.5,0],[24,0],[29,0]],"id":52385882},{"atl":[[290,4.49],[160,0],[180,0]],"id":52385884},{"atb":[[100,0],[110,2.95]],"id":52385917},{"atl":[[130,0],[210,4.67],[120,0]],"id":52385895},{"atl":[[16.5,0],[11,3.33]],"id":52385891},{"atl":[[70,0],[36,4.37]],"id":52385893},{"atl":[[780,2.83],[470,0],[490,0]],"id":52385934},{"atb":[[4.8,0],[5.8,3.28]],"id":52385903},{"atl":[[22,0]],"id":52385903},{"atb":[[2,0],[2.3,0],[2.06,0],[2.2,0],[2.1,0]],"id":52385904},{"atb":[[300,0],[350,0],[170,0],[190,3.34],[400,0],[250,0]],"id":52385936},{"atb":[[140,0],[220,3.49]],"id":52385931}],"con":true,"img":false}]}
{"op":"mcm","clk":"11449967837","pt":1717316511954,"mc":[{"id":"1.229554897","rc":[{"atb":[[1.69,22.74]],"id":52385904}],"con":true,"img":false}]}
{"op":"mcm","clk":"11449967884","pt":1717316512522,"mc":[{"id":"1.229554897","rc":[{"atb":[[34,2.38],[44,1.22],[27,4.02],[60,0.44]],"id":52385882},{"atb":[[540,0.05],[390,0.27],[440,0.18],[490,0.1]],"id":52385936}],"con":true,"img":false}]}
{"op":"mcm","clk":"11449967890","pt":1717316512628,"mc":[{"id":"1.229554897","rc":[{"atb":[[16,6.97],[18.5,4.48],[22,2.49],[27,1]],"id":52385909},{"atb":[[1.73,107.5],[1.83,31.52],[1.78,67.08],[1.68,153.88]],"id":52385904}],"con":true,"img":false}]}
{"op":"mcm","clk":"11449968432","pt":1717316521513,"mc":[{"id":"1.229554897","rc":[{"atb":[[5.2,24.88],[4.2,76.22]],"id":52385907},{"atb":[[9.6,28.36],[14,8.04]],"id":52385909},{"atb":[[70,1.51],[38,6.59]],"id":52385886},{"atb":[[10.5,11],[8.2,33.87]],"id":52385918},{"atb":[[550,0.44],[650,0.16]],"id":52385888},{"atb":[[6.4,45.16],[8.4,14.12]],"id":52385920},{"atb":[[9,30.48],[12.5,9.08]],"id":52385889},{"atb":[[10,27.1],[15,7.46]],"id":52385882},{"atb":[[12,9.5],[8.8,31.27]],"id":52385884},{"atb":[[65,1.63],[36,6.96]],"id":52385917},{"atb":[[19,5.8],[14,18.76]],"id":52385895},{"atb":[[2.5,69.68],[2.3,187.62]],"id":52385891},{"atb":[[530,0.46],[630,0.16]],"id":52385923},{"atb":[[8.6,13.75],[6.6,43.55]],"id":52385893},{"atb":[[19,5.8],[14,18.76]],"id":52385934},{"atb":[[7.8,15.37],[5.9,49.77]],"id":52385903},{"atb":[[1.82,297.44],[1.92,113.61]],"id":52385904},{"atb":[[550,0.44],[650,0.16]],"id":52385936},{"atb":[[550,0.44],[650,0.16]],"id":52385931},{"atb":[[17.5,14.77],[25,4.35]],"id":52385932}],"con":true,"img":false}]}
{"op":"mcm","clk":"11449968441","pt":1717316521726,"mc":[{"id":"1.229554897","rc":[{"atb":[[6.2,0],[5.5,3.62]],"id":52385907},{"atb":[[100,3.68]],"id":52385886},{"atl":[[100,4.26]],"id":52385918},{"atb":[[180,4.22]],"id":52385888},{"atl":[[75,3.3]],"id":52385920},{"atl":[[95,3.32]],"id":52385889},{"atl":[[310,4.55]],"id":52385884},{"atl":[[230,3.77]],"id":52385895},{"atl":[[12,3.92]],"id":52385891},{"atl":[[40,3.25]],"id":52385893},{"atb":[[5.6,2.82]],"id":52385903},{"atl":[[26,4.08]],"id":52385903},{"atb":[[170,3.65]],"id":52385936},{"atb":[[200,3.87]],"id":52385931}],"con":true,"img":false}]}
{"op":"mcm","clk":"11449968444","pt":1717316521828,"mc":[{"id":"1.229554897","rc":[{"atb":[[16.5,4.14]],"id":52385909},{"atl":[[70,2.91]],"id":52385909},{"atl":[[800,3.71]],"id":52385934}],"con":true,"img":false}]}
{"op":"mcm","clk":"11449968451","pt":1717316521934,"mc":[{"id":"1.229554897","rc":[{"atb":[[1.67,23.42]],"id":52385904}],"con":true,"img":false}]}
{"op":"mcm","clk":"11449969113","pt":1717316531724,"mc":[{"id":"1.229554897","rc":[{"atb":[[11,0]],"id":52385909},{"atb":[[65,0]],"id":52385886},{"atb":[[100,0]],"id":52385888},{"atl":[[110,0]],"id":52385920},{"atl":[[80,0]],"id":52385893},{"atb":[[120,0]],"id":52385931}],"con":true,"img":false}]}
{"op":"mcm","clk":"11449969123","pt":1717316531829,"mc":[{"id":"1.229554897","rc":[{"atl":[[120,0]],"id":52385918},{"atl":[[17,0]],"id":52385891}],"con":true,"img":false}]}
{"op":"mcm","clk":"11449969542","pt":1717316538337,"mc":[{"id":"1.229554897","rc":[{"atb":[[20,0],[21,3.79]],"id":52385918},{"atl":[[90,0],[95,3.93]],"id":52385918},{"atb":[[130,4.48]],"id":52385886},{"atl":[[800,3.87]],"id":52385886},{"atb":[[200,0],[210,3.19]],"id":52385888},{"atb":[[14.5,11.57],[15,0]],"id":52385920},{"atl":[[65,0],[70,3.44]],"id":52385920},{"atb":[[110,0],[120,4.44]],"id":52385917},{"atl":[[540,0],[570,2.95]],"id":52385917},{"atb":[[2.84,0],[2.76,8.92]],"id":52385891},{"atb":[[160,0],[170,4.26]],"id":52385923},{"atb":[[11,0],[12,4.09]],"id":52385893},{"atb":[[55,5.76],[60,0]],"id":52385934},{"atl":[[640,0],[740,3.62]],"id":52385932}],"con":true,"img":false}]}
{"op":"mcm","clk":"11449969548","pt":1717316538444,"mc":[{"id":"1.229554897","rc":[{"atb":[[120,0]],"id":52385886},{"atl":[[770,0]],"id":52385886}],"con":true,"img":false}]}
{"op":"mcm","clk":"11449969556","pt":1717316538547,"mc":[{"id":"1.229554897","rc":[{"atb":[[2.86,0],[2.84,34.48]],"id":52385891}],"con":true,"img":false}]}
{"op":"mcm","clk":"11449969644","pt":1717316540043,"mc":[{"id":"1.229554897","rc":[{"atb":[[130,0],[120,4.34]],"id":52385886},{"atl":[[790,0]],"id":52385886},{"atb":[[20,4.14],[21,0]],"id":52385918},{"atb":[[14.5,7.75],[15,3.81]],"id":52385920},{"atb":[[200,2.96],[210,0]],"id":52385888},{"atb":[[110,3.75],[120,0]],"id":52385917},{"atl":[[560,0]],"id":52385917},{"atb":[[2.82,0],[2.84,43]],"id":52385891},{"atb":[[160,4.11],[170,0]],"id":52385923},{"atb":[[11,4.27],[12,0]],"id":52385893},{"atb":[[55,1.45],[60,3.36]],"id":52385934},{"atl":[[660,0]],"id":52385932}],"con":true,"img":false}]}
{"op":"mcm","clk":"11449969857","pt":1717316543033,"mc":[{"id":"1.229554897","rc":[{"atb":[[130,3.26],[120,0]],"id":52385886},{"atl":[[770,3.17]],"id":52385886},{"atb":[[21,3.67]],"id":52385918},{"atl":[[90,3.38]],"id":52385918},{"atb":[[14.5,12.26],[15,0]],"id":52385920},{"atl":[[65,3.77],[70,0]],"id":52385920},{"atb":[[210,2.69]],"id":52385888},{"atb":[[110,0],[120,2.66]],"id":52385917},{"atl":[[540,3.4]],"id":52385917},{"atb":[[2.84,34.48]],"id":52385891},{"atb":[[160,0],[170,3.97]],"id":52385923},{"atb":[[11,0],[12,2.64]],"id":52385893},{"atb":[[55,4.98],[60,0]],"id":52385934},{"atl":[[640,4.62]],"id":52385932}],"con":true,"img":false}]}
{"op":"mcm","clk":"11449969867","pt":1717316543147,"mc":[{"id":"1.229554897","rc":[{"atb":[[20,0]],"id":52385918},{"atl":[[95,0]],"id":52385918},{"atb":[[200,0]],"id":52385888},{"atb":[[2.78,56.18]],"id":52385891}],"con":true,"img":false}]}
{"op":"mcm","clk":"11449969875","pt":1717316543243,"mc":[{"id":"1.229554897","rc":[{"atb":[[2.84,0]],"id":52385891}],"con":true,"img":false}]}
{"op":"mcm","clk":"11449970335","pt":1717316550068,"mc":[{"id":"1.229554897","rc":[{"atb":[[2.84,8.52]],"id":52385891}],"con":true,"img":false}]}
{"op":"mcm","clk":"11449970341","pt":1717316550177,"mc":[{"id":"1.229554897","rc":[{"atb":[[2.86,8.92]],"id":52385891}],"con":true,"img":false}]}
{"op":"mcm","clk":"11449970346","pt":1717316550275,"mc":[{"id":"1.229554897","rc":[{"atb":[[2.78,0]],"id":52385891}],"con":true,"img":false}]}
{"op":"mcm","clk":"11449970534","pt":1717316553077,"mc":[{"id":"1.229554897","rc":[{"atb":[[20,2.65],[21,0]],"id":52385918},{"atb":[[130,0],[120,3.3]],"id":52385886},{"atb":[[200,4.29],[210,0]],"id":52385888},{"atb":[[15,4.44]],"id":52385920},{"atb":[[110,2.73],[120,0]],"id":52385917},{"atb":[[160,4.35],[170,0]],"id":52385923},{"atb":[[11,2.84],[12,0]],"id":52385893},{"atb":[[55,1.45],[60,4.38]],"id":52385934},{"atl":[[660,3.58]],"id":52385932}],"con":true,"img":false}]}
{"op":"mcm","clk":"11449970538","pt":1717316553182,"mc":[{"id":"1.229554897","rc":[{"atb":[[14.5,7.75]],"id":52385920}],"con":true,"img":false}]}
{"op":"mcm","clk":"11449970670","pt":1717316555062,"mc":[{"id":"1.229554897","rc":[{"atb":[[20,0],[21,2.95]],"id":52385918},{"atb":[[130,4.33],[120,0]],"id":52385886},{"atb":[[14.5,10.78],[15,0]],"id":52385920},{"atb":[[200,0],[210,3.3]],"id":52385888},{"atb":[[110,0],[120,3.59]],"id":52385917},{"atb":[[160,0],[170,4.63]],"id":52385923},{"atb":[[2.84,0]],"id":52385891},{"atb":[[11,0],[12,4.62]],"id":52385893},{"atb":[[55,4.17],[60,0]],"id":52385934},{"atl":[[740,0]],"id":52385932}],"con":true,"img":false}]}
{"op":"mcm","clk":"11449970676","pt":1717316555169,"mc":[{"id":"1.229554897","rc":[{"atl":[[770,0]],"id":52385886},{"atl":[[90,0],[95,3.41]],"id":52385918},{"atl":[[65,0],[70,4.44]],"id":52385920},{"atl":[[540,0]],"id":52385917},{"atb":[[2.78,56.18]],"id":52385891},{"atl":[[640,0],[660,0]],"id":52385932}],"con":true,"img":false}]}
{"op":"mcm","clk":"11449970682","pt":1717316555270,"mc":[{"id":"1.229554897","rc":[{"atb":[[2.86,0]],"id":52385891}],"con":true,"img":false}]}
{"op":"mcm","clk":"11449970808","pt":1717316557400,"mc":[{"id":"1.229554897","rc":[{"atl":[[90,3.86],[95,0]],"id":52385918},{"atl":[[770,4.34]],"id":52385886},{"atl":[[65,4.09],[70,0]],"id":52385920},{"atl":[[540,3.28]],"id":52385917},{"atl":[[640,2.96],[660,4.13]],"id":52385932}],"con":true,"img":false}]}
{"op":"mcm","clk":"11449970883","pt":1717316558497,"mc":[{"id":"1.229554897","rc":[{"atb":[[20,3.68],[21,0]],"id":52385918},{"atl":[[90,0],[95,3.6]],"id":52385918},{"atb":[[130,0],[120,4.34]],"id":52385886},{"atl":[[770,0]],"id":52385886},{"atb":[[14.5,7.75],[15,2.74]],"id":52385920},{"atl":[[65,0],[70,2.68]],"id":52385920},{"atb":[[200,3.95],[210,0]],"id":52385888},{"atb":[[110,3.56],[120,0]],"id":52385917},{"atl":[[540,0]],"id":52385917},{"atb":[[2.84,8.52]],"id":52385891},{"atb":[[160,3.57],[170,0]],"id":52385923},{"atb":[[11,3.36],[12,0]],"id":52385893},{"atb":[[55,1.45],[60,3.79]],"id":52385934},{"atl":[[640,0],[740,3.02]],"id":52385932}],"con":true,"img":false}]}
{"op":"mcm","clk":"11449970993","pt":1717316560468,"mc":[{"id":"1.229554897","rc":[{"atb":[[20,0],[21,3.4]],"id":52385918},{"atl":[[90,2.78],[95,0]],"id":52385918},{"atb":[[130,3.44],[120,0]],"id":52385886},{"atl":[[770,3.88]],"id":52385886},{"atb":[[14.5,10.78],[15,0]],"id":52385920},{"atl":[[65,2.65],[70,0]],"id":52385920},{"atb":[[200,0],[210,3.19]],"id":52385888},{"atb":[[110,0],[120,4.4]],"id":52385917},{"atl":[[540,4.55]],"id":52385917},{"atb":[[160,0],[170,4.21]],"id":52385923},{"atb":[[2.84,0]],"id":52385891},{"atb":[[11,0],[12,4.65]],"id":52385893},{"atb":[[55,6.04],[60,0]],"id":52385934},{"atl":[[660,0],[640,4.55]],"id":52385932}],"con":true,"img":false}]}
{"op":"mcm","clk":"11449971152","pt":1717316562900,"mc":[{"id":"1.229554897","rc":[{"atb":[[120,2.69]],"id":52385886},{"atb":[[20,3.34],[21,0]],"id":52385918},{"atl":[[90,0],[95,4.58]],"id":52385918},{"atb":[[200,4.19],[210,0]],"id":52385888},{"atb":[[14.5,7.75],[15,3.22]],"id":52385920},{"atl":[[65,0],[70,3.02]],"id":52385920},{"atb":[[110,3.57]],"id":52385917},{"atb":[[160,3.87]],"id":52385923},{"atb":[[2.84,8.52]],"id":52385891},{"atb":[[11,3.07]],"id":52385893},{"atb":[[55,1.45],[60,4.65]],"id":52385934},{"atl":[[640,0]],"id":52385932}],"con":true,"img":false}]}
{"op":"mcm","clk":"11449971162","pt":1717316563004,"mc":[{"id":"1.229554897","rc":[{"atb":[[130,0]],"id":52385886},{"atl":[[770,0]],"id":52385886},{"atb":[[120,0]],"id":52385917},{"atl":[[540,0]],"id":52385917},{"atb":[[170,0]],"id":52385923},{"atb":[[12,0]],"id":52385893}],"con":true,"img":false}]}
{"op":"mcm","clk":"11449971195","pt":1717316563369,"mc":[{"id":"1.229554897","rc":[{"atb":[[3,0],[3.25,29.57]],"id":52385907},{"atl":[[18.5,0],[25,4.17]],"id":52385907},{"atb":[[7.2,0],[8.4,13.51]],"id":52385918},{"atl":[[350,2],[230,0]],"id":52385918},{"atb":[[6.8,0],[9.4,11.9]],"id":52385920},{"atl":[[290,0],[440,2]],"id":52385920},{"atl":[[440,0],[510,2]],"id":52385889},{"atl":[[870,0]],"id":52385882},{"atl":[[860,0]],"id":52385895},{"atb":[[6.8,17.24],[5.9,0]],"id":52385893}],"con":true,"img":false}]}
{"op":"mcm","clk":"11449971201","pt":1717316563474,"mc":[{"id":"1.229554897","rc":[{"atl":[[370,2]],"id":52385909}],"con":true,"img":false}]}
{"op":"mcm","clk":"11449971203","pt":1717316563575,"mc":[{"id":"1.229554897","rc":[{"atb":[[16,0],[17.5,0],[18.5,0],[18,2.64],[22,0],[27,0]],"id":52385909},{"atl":[[310,0]],"id":52385909},{"atb":[[220,4.23]],"id":52385888},{"atb":[[180,3.11]],"id":52385923},{"atb":[[2.74,9.01],[2.76,0]],"id":52385891},{"atb":[[70,3.8],[80,0],[42,0],[110,0],[55,0]],"id":52385934},{"atb":[[220,0],[230,4.21]],"id":52385931}],"con":true,"img":false}]}
{"op":"mcm","clk":"11449971209","pt":1717316563679,"mc":[{"id":"1.229554897","rc":[{"atb":[[5.7,0],[6.6,4.1]],"id":52385907},{"atl":[[60,0]],"id":52385909},{"atb":[[130,4.39],[120,0]],"id":52385886},{"atl":[[800,0],[880,3.18]],"id":52385886},{"atb":[[200,0]],"id":52385888},{"atb":[[14.5,11.83],[15,0]],"id":52385920},{"atl":[[70,0],[85,2.98]],"id":52385920},{"atl":[[85,0],[110,3.34]],"id":52385889},{"atl":[[280,3.38],[210,0],[230,0]],"id":52385882},{"atl":[[290,0],[310,0],[400,2.64]],"id":52385884},{"atb":[[110,0],[120,2.96]],"id":52385917},{"atl":[[570,0],[580,4.46]],"id":52385917},{"atl":[[260,3.18],[210,0],[230,0]],"id":52385895},{"atb":[[2.84,0]],"id":52385891},{"atb":[[160,0]],"id":52385923},{"atb":[[11,0],[12,4.1]],"id":52385893},{"atl":[[36,0],[40,0],[44,4.46]],"id":52385893},{"atb":[[60,0]],"id":52385934},{"atl":[[780,0],[800,0]],"id":52385934},{"atl":[[24,0],[27,4.05]],"id":52385903},{"atb":[[1.73,0],[1.83,0],[1.67,0],[1.78,0],[1.68,0],[1.69,0]],"id":52385904},{"atb":[[150,0],[75,0],[100,0],[50,0]],"id":52385932},{"atl":[[740,0],[800,2.68]],"id":52385932}],"con":true,"img":false}]}
{"op":"mcm","clk":"11449971216","pt":1717316563783,"mc":[{"id":"1.229554897","rc":[{"atb":[[6.4,4.52]],"id":52385907},{"atl":[[80,2.86]],"id":52385920},{"atb":[[2.78,0],[2.76,56.82]],"id":52385891},{"atl":[[28,4.55]],"id":52385903}],"con":true,"img":false}]}
{"op":"mcm","clk":"11449971222","pt":1717316563887,"mc":[{"id":"1.229554897","rc":[{"atl":[[75,3.96]],"id":52385909},{"atl":[[850,2.68]],"id":52385886},{"atl":[[95,0]],"id":52385889},{"atl":[[270,4.64]],"id":52385895},{"atl":[[850,3.01]],"id":52385932}],"con":true,"img":false}]}
{"op":"mcm","clk":"11449971246","pt":1717316564303,"mc":[{"id":"1.229554897","rc":[{"atb":[[32,0.84],[18,8.8],[21,3.92],[26,2.09]],"id":52385909},{"atb":[[85,0.62],[44,2.43],[120,0.22],[60,1.33]],"id":52385934}],"con":true,"img":false}]}
{"op":"mcm","clk":"11449971259","pt":1717316564408,"mc":[{"id":"1.229554897","rc":[{"atb":[[1.6,87.2],[1.55,142.69],[1.5,209.27],[1.65,40.24]],"id":52385904},{"atb":[[130,0.41],[65,1.64],[180,0.15],[90,0.88]],"id":52385932}],"con":true,"img":false}]}
{"op":"mcm","clk":"11449971279","pt":1717316564669,"mc":[{"id":"1.229554897","rc":[{"atb":[[6.6,0]],"id":52385907},{"atl":[[70,0]],"id":52385909},{"atb":[[120,2.94]],"id":52385886},{"atl":[[75,0],[85,0]],"id":52385920},{"atb":[[210,4.56],[220,0]],"id":52385888},{"atb":[[110,4.66],[120,0]],"id":52385917},{"atl":[[260,0]],"id":52385895},{"atb":[[2.8,8.72]],"id":52385891},{"atb":[[11.5,2.97],[12,0]],"id":52385893},{"atb":[[70,0],[75,2.85]],"id":52385934},{"atl":[[26,0],[27,0]],"id":52385903},{"atl":[[800,0]],"id":52385932}],"con":true,"img":false}]}
{"op":"mcm","clk":"11449971286","pt":1717316564770,"mc":[{"id":"1.229554897","rc":[{"atb":[[130,0]],"id":52385886}],"con":true,"img":false}]}
{"op":"mcm","clk":"11449971292","pt":1717316564872,"mc":[{"id":"1.229554897","rc":[{"atl":[[90,3.68]],"id":52385918},{"atl":[[550,2.63]],"id":52385917}],"con":true,"img":false}]}
{"op":"mcm","clk":"11449971301","pt":1717316564975,"mc":[{"id":"1.229554897","rc":[{"atl":[[95,0]],"id":52385918}],"con":true,"img":false}]}
{"op":"mcm","clk":"11449971569","pt":1717316569784,"mc":[{"id":"1.229554897","rc":[{"atb":[[17.5,3.78],[18,6.15]],"id":52385909},{"atb":[[20,0],[21,2.85]],"id":52385918},{"atl":[[90,0],[95,3.55]],"id":52385918},{"atb":[[130,3.76],[120,0]],"id":52385886},{"atb":[[110,0],[120,4.23]],"id":52385917},{"atl":[[550,0]],"id":52385917},{"atb":[[2.8,0],[2.76,65.74]],"id":52385891},{"atb":[[170,2.83],[180,0]],"id":52385923},{"atb":[[11.5,0],[12,3.85]],"id":52385893},{"atb":[[75,0],[55,4.12]],"id":52385934},{"atb":[[220,2.75],[230,0]],"id":52385931}],"con":true,"img":false}]}
{"op":"mcm","clk":"11449971837","pt":1717316573708,"mc":[{"id":"1.229554897","rc":[{"atl":[[130,3.12]],"id":52385889},{"atl":[[300,3.42]],"id":52385882},{"atl":[[420,3.9]],"id":52385884}],"con":true,"img":false}]}
{"op":"mcm","clk":"11449971855","pt":1717316573911,"mc":[{"id":"1.229554897","rc":[{"atb":[[6,3.15]],"id":52385907},{"atl":[[90,4.4]],"id":52385920},{"atl":[[290,4.08]],"id":52385895},{"atl":[[30,3.85]],"id":52385903},{"atl":[[870,4.01]],"id":52385932}],"con":true,"img":false}]}
{"op":"mcm","clk":"11449972271","pt":1717316579796,"mc":[{"id":"1.229554897","rc":[{"atl":[[85,3.59]],"id":52385909},{"atb":[[100,4.62]],"id":52385917},{"atl":[[600,2.71]],"id":52385917},{"atb":[[11,4.19]],"id":52385893},{"atl":[[48,4.58]],"id":52385893}],"con":true,"img":false}]}
{"op":"mcm","clk":"11449972296","pt":1717316580206,"mc":[{"id":"1.229554897","rc":[{"atb":[[5.5,0]],"id":52385907}],"con":true,"img":false}]}
{"op":"mcm","clk":"11449972646","pt":1717316585200,"mc":[{"id":"1.229554897","rc":[{"atb":[[20,4.07],[21,0]],"id":52385918},{"atb":[[130,0],[120,4.56]],"id":52385886},{"atb":[[110,2.95],[120,0]],"id":52385917},{"atb":[[2.8,8.72],[2.76,56.82]],"id":52385891},{"atb":[[11.5,2.99],[12,0]],"id":52385893},{"atb":[[55,0],[60,5.84]],"id":52385934}],"con":true,"img":false}]}
{"op":"mcm","clk":"11449972654","pt":1717316585305,"mc":[{"id":"1.229554897","rc":[{"atb":[[2.82,9.02],[2.76,0]],"id":52385891}],"con":true,"img":false}]}
{"op":"mcm","clk":"11449972720","pt":1717316586236,"mc":[{"id":"1.229554897","rc":[{"atb":[[17.5,0],[18,9.46]],"id":52385909},{"atb":[[20,0],[22,4]],"id":52385918},{"atl":[[90,4.1],[95,0]],"id":52385918},{"atb":[[130,3.85],[120,0]],"id":52385886},{"atb":[[14.5,7.75],[15.5,2.66]],"id":52385920},{"atb":[[210,0],[220,4.24]],"id":52385888},{"atb":[[90,0],[110,0],[120,2.65]],"id":52385917},{"atl":[[530,3.8],[580,0]],"id":52385917},{"atb":[[2.8,0]],"id":52385891},{"atb":[[170,0],[180,4.52]],"id":52385923},{"atb":[[11.5,0],[9.8,0],[12.5,4.54]],"id":52385893},{"atb":[[70,2.92],[60,1.33]],"id":52385934},{"atb":[[220,0],[230,3.25]],"id":52385931}],"con":true,"img":false}]}
{"op":"mcm","clk":"11449972786","pt":1717316587216,"mc":[{"id":"1.229554897","rc":[{"atl":[[95,3.4]],"id":52385918},{"atb":[[16,3.86],[17,0],[19.5,0],[24,0],[14.5,0],[15.5,0]],"id":52385920},{"atb":[[210,3.8],[220,0]],"id":52385888},{"atl":[[530,0]],"id":52385917},{"atb":[[2.78,8.81]],"id":52385891},{"atb":[[12,3.33],[12.5,0]],"id":52385893},{"atb":[[75,3.21],[85,0],[44,0],[120,0],[60,0]],"id":52385934}],"con":true,"img":false}]}
{"op":"mcm","clk":"11449972793","pt":1717316587317,"mc":[{"id":"1.229554897","rc":[{"atl":[[90,0]],"id":52385918},{"atb":[[70,0]],"id":52385934}],"con":true,"img":false}]}
{"op":"mcm","clk":"11449972816","pt":1717316587626,"mc":[{"id":"1.229554897","rc":[{"atb":[[17.5,2.71],[18,6.15]],"id":52385909},{"atb":[[20,3.28],[22,0]],"id":52385918},{"atb":[[130,0],[120,2.75]],"id":52385886},{"atb":[[14.5,4.58]],"id":52385920},{"atb":[[110,4.27],[120,0]],"id":52385917},{"atb":[[2.8,8.72]],"id":52385891},{"atb":[[170,4.14],[180,0]],"id":52385923},{"atb":[[11.5,3.46]],"id":52385893},{"atb":[[60,3.8]],"id":52385934},{"atb":[[220,3.09],[230,0]],"id":52385931}],"con":true,"img":false}]}
{"op":"mcm","clk":"11449972843","pt":1717316587938,"mc":[{"id":"1.229554897","rc":[{"atb":[[16.5,5.06],[19,2.91],[23,1.19],[14,10.74]],"id":52385920},{"atb":[[80,0.66],[42,2.55],[110,0.24],[55,1.45]],"id":52385934}],"con":true,"img":false}]}
{"op":"mcm","clk":"11449972881","pt":1717316588410,"mc":[{"id":"1.229554897","rc":[{"atl":[[20,5.26],[25,0]],"id":52385907},{"atl":[[320,2],[370,0]],"id":52385909},{"atl":[[350,0],[250,2]],"id":52385918},{"atb":[[8,14.29],[9.4,0]],"id":52385920},{"atl":[[310,2],[440,0]],"id":52385920},{"atl":[[450,2],[510,0]],"id":52385889},{"atl":[[910,2]],"id":52385882}],"con":true,"img":false}]}
{"op":"mcm","clk":"11449972911","pt":1717316588718,"mc":[{"id":"1.229554897","rc":[{"atb":[[6.4,0]],"id":52385907},{"atl":[[75,0]],"id":52385909},{"atl":[[90,3.21],[95,0]],"id":52385918},{"atl":[[720,3.5],[850,0]],"id":52385886},{"atb":[[16,0]],"id":52385920},{"atl":[[65,4.11],[80,0]],"id":52385920},{"atl":[[90,3.92],[110,0]],"id":52385889},{"atl":[[280,0],[220,4.66]],"id":52385882},{"atl":[[300,2.91],[400,0]],"id":52385884},{"atl":[[530,3.87]],"id":52385917},{"atl":[[270,0],[240,4.49]],"id":52385895},{"atb":[[2.74,0]],"id":52385891},{"atb":[[12,0]],"id":52385893},{"atl":[[44,0]],"id":52385893},{"atb":[[75,0]],"id":52385934},{"atl":[[24,3.35],[28,0]],"id":52385903},{"atl":[[700,2.91],[850,0]],"id":52385932}],"con":true,"img":false}]}
{"op":"mcm","clk":"11449972921","pt":1717316588827,"mc":[{"id":"1.229554897","rc":[{"atl":[[65,3.15]],"id":52385909},{"atl":[[38,3.5]],"id":52385893}],"con":true,"img":false}]}
{"op":"mcm","clk":"11449973397","pt":1717316595248,"mc":[{"id":"1.229554897","rc":[{"atb":[[5.8,3.5]],"id":52385907}],"con":true,"img":false}]}
{"op":"mcm","clk":"11449973487","pt":1717316596446,"mc":[{"id":"1.229554897","rc":[{"atl":[[90,0],[95,2.96]],"id":52385918},{"atl":[[65,0],[70,3.74]],"id":52385920},{"atl":[[530,0],[570,3.59]],"id":52385917}],"con":true,"img":false}]}
{"op":"mcm","clk":"11449973500","pt":1717316596547,"mc":[{"id":"1.229554897","rc":[{"atl":[[720,0],[770,4.59]],"id":52385886}],"con":true,"img":false}]}
{"op":"mcm","clk":"11449973532","pt":1717316597070,"mc":[{"id":"1.229554897","rc":[{"atb":[[120,0]],"id":52385886},{"atb":[[22,3.46]],"id":52385918},{"atb":[[15.5,3.97]],"id":52385920},{"atl":[[75,4.58]],"id":52385920},{"atb":[[210,0],[220,4.23]],"id":52385888},{"atb":[[120,2.63]],"id":52385917},{"atl":[[610,3.66]],"id":52385917},{"atb":[[2.8,0],[2.74,9.01]],"id":52385891},{"atb":[[170,0],[180,4.33]],"id":52385923},{"atb":[[12.5,3.59]],"id":52385893},{"atb":[[70,4.68],[60,0]],"id":52385934},{"atb":[[230,2.68]],"id":52385931},{"atl":[[700,0],[780,3.26]],"id":52385932}],"con":true,"img":false}]}
{"op":"mcm","clk":"11449973540","pt":1717316597127,"mc":[{"id":"1.229554897","rc":[{"atb":[[17.5,0],[18,9.38]],"id":52385909},{"atb":[[130,2.61]],"id":52385886},{"atl":[[850,3.68]],"id":52385886},{"atb":[[20,0]],"id":52385918},{"atb":[[14.5,0]],"id":52385920},{"atb":[[110,0]],"id":52385917},{"atb":[[2.8,18.04]],"id":52385891},{"atb":[[11.5,0]],"id":52385893},{"atb":[[220,0]],"id":52385931}],"con":true,"img":false}]}
{"op":"mcm","clk":"11449973549","pt":1717316597227,"mc":[{"id":"1.229554897","rc":[{"atb":[[2.82,0]],"id":52385891}],"con":true,"img":false}]}
{"op":"mcm","clk":"11449973634","pt":1717316598624,"mc":[{"id":"1.229554897","rc":[{"atl":[[770,0],[850,0],[880,0],[870,3.19]],"id":52385886},{"atl":[[95,0]],"id":52385918},{"atb":[[16,4.63],[15.5,0]],"id":52385920},{"atl":[[75,0],[90,0]],"id":52385920},{"atb":[[210,4.14],[220,0]],"id":52385888},{"atl":[[570,0],[600,0],[610,0],[630,4.39]],"id":52385917},{"atb":[[2.84,8.52],[2.78,0]],"id":52385891},{"atb":[[12,4.67],[12.5,0]],"id":52385893},{"atb":[[70,0],[75,3.98]],"id":52385934},{"atl":[[780,0],[790,3.97]],"id":52385932}],"con":true,"img":false}]}
{"op":"mcm","clk":"11449973648","pt":1717316598724,"mc":[{"id":"1.229554897","rc":[{"atl":[[100,3.11]],"id":52385889},{"atl":[[240,3.35]],"id":52385882},{"atl":[[320,4.7]],"id":52385884},{"atl":[[260,4.16]],"id":52385895},{"atb":[[2.8,0],[2.86,9.02]],"id":52385891},{"atl":[[26,4.39]],"id":52385903}],"con":true,"img":false}]}
{"op":"mcm","clk":"11449973670","pt":1717316599034,"mc":[{"id":"1.229554897","rc":[{"atb":[[17.5,4.23],[18,6.15]],"id":52385909},{"atb":[[130,0],[120,3.52]],"id":52385886},{"atb":[[20,3.02],[22,0]],"id":52385918},{"atb":[[14.5,3.6]],"id":52385920},{"atb":[[110,4.42],[120,0]],"id":52385917},{"atb":[[2.8,8.72]],"id":52385891},{"atb":[[170,3.99],[180,0]],"id":52385923},{"atb":[[11.5,2.75]],"id":52385893},{"atb":[[60,2.89]],"id":52385934},{"atb":[[220,4.57],[230,0]],"id":52385931}],"con":true,"img":false}]}
{"op":"mcm","clk":"11449974353","pt":1717316608453,"mc":[{"id":"1.229554897","rc":[{"atb":[[130,4.55],[120,0]],"id":52385886},{"atl":[[850,4.09]],"id":52385886},{"atb":[[20,0],[22,3.58]],"id":52385918},{"atb":[[16,0]],"id":52385920},{"atl":[[70,0]],"id":52385920},{"atb":[[210,0]],"id":52385888},{"atl":[[130,0]],"id":52385889},{"atl":[[300,0]],"id":52385882},{"atl":[[420,0]],"id":52385884},{"atb":[[110,0],[120,4.26]],"id":52385917},{"atl":[[610,4.4]],"id":52385917},{"atl":[[290,0]],"id":52385895},{"atb":[[170,0],[180,4.27]],"id":52385923},{"atb":[[2.8,0],[2.84,0]],"id":52385891},{"atb":[[70,3.66],[75,0]],"id":52385934},{"atl":[[30,0]],"id":52385903},{"atb":[[220,0],[230,4.33]],"id":52385931},{"atl":[[790,0],[780,4.27]],"id":52385932}],"con":true,"img":false}]}
{"op":"mcm","clk":"11449974357","pt":1717316608554,"mc":[{"id":"1.229554897","rc":[{"atb":[[17.5,0],[18,10.86]],"id":52385909},{"atb":[[15.5,3.89]],"id":52385920},{"atl":[[75,3.54]],"id":52385920},{"atb":[[220,3.05]],"id":52385888},{"atb":[[2.86,0],[2.76,56.82]],"id":52385891},{"atb":[[11,0],[12,0],[12.5,3.36]],"id":52385893}],"con":true,"img":false}]}
{"op":"mcm","clk":"11449974396","pt":1717316609022,"mc":[{"id":"1.229554897","rc":[{"atb":[[2.7,9.23]],"id":52385891}],"con":true,"img":false}]}
{"op":"mcm","clk":"11449974446","pt":1717316610053,"mc":[{"id":"1.229554897","rc":[{"atl":[[850,0]],"id":52385886},{"atb":[[210,3.1],[220,0]],"id":52385888},{"atb":[[16,3.59],[14,8.05],[15.5,0]],"id":52385920},{"atl":[[70,3.31]],"id":52385920},{"atl":[[610,0]],"id":52385917},{"atb":[[2.74,0],[2.84,8.52]],"id":52385891},{"atb":[[12,4.2],[12.5,0]],"id":52385893},{"atb":[[70,0],[75,3.68],[50,0]],"id":52385934},{"atl":[[780,0],[790,2.71]],"id":52385932}],"con":true,"img":false}]}
{"op":"mcm","clk":"11449974469","pt":1717316610467,"mc":[{"id":"1.229554897","rc":[{"atb":[[17.5,4.12],[18,6.15]],"id":52385909},{"atb":[[130,0],[120,3.78]],"id":52385886},{"atb":[[20,2.78],[22,0]],"id":52385918},{"atb":[[110,3.29],[120,0]],"id":52385917},{"atb":[[2.8,8.72]],"id":52385891},{"atb":[[170,3.91],[180,0]],"id":52385923},{"atb":[[220,4.29],[230,0]],"id":52385931}],"con":true,"img":false}]}
{"op":"mcm","clk":"11449974473","pt":1717316610534,"mc":[{"id":"1.229554897","rc":[{"atb":[[2.86,9.23],[2.76,0]],"id":52385891}],"con":true,"img":false}]}
{"op":"mcm","clk":"11449974602","pt":1717316612646,"mc":[{"id":"1.229554897","rc":[{"atl":[[850,4.39]],"id":52385886},{"atb":[[16,0]],"id":52385920},{"atl":[[70,0]],"id":52385920},{"atl":[[610,2.62]],"id":52385917},{"atb":[[2.84,0]],"id":52385891},{"atb":[[75,0]],"id":52385934},{"atl":[[790,0],[780,4.05]],"id":52385932}],"con":true,"img":false}]}
{"op":"mcm","clk":"11449974609","pt":1717316612749,"mc":[{"id":"1.229554897","rc":[{"atb":[[12,0]],"id":52385893}],"con":true,"img":false}]}
{"op":"mcm","clk":"11449974802","pt":1717316615638,"mc":[{"id":"1.229554897","rc":[{"atb":[[2.82,18.46],[2.86,0]],"id":52385891}],"con":true,"img":false}]}
{"op":"mcm","clk":"11449974969","pt":1717316618064,"mc":[{"id":"1.229554897","rc":[{"atl":[[780,4.55],[850,0]],"id":52385886},{"atb":[[20,0]],"id":52385918},{"atl":[[90,3.7]],"id":52385918},{"atb":[[14.5,0]],"id":52385920},{"atl":[[70,4.7]],"id":52385920},{"atl":[[570,2.73],[610,0]],"id":52385917},{"atb":[[2.8,0],[2.88,8.34]],"id":52385891},{"atb":[[160,2.88],[170,0]],"id":52385923},{"atb":[[11,3.9],[11.5,0]],"id":52385893},{"atl":[[710,3.92],[780,0]],"id":52385932}],"con":true,"img":false}]}
{"op":"mcm","clk":"11449974994","pt":1717316618479,"mc":[{"id":"1.229554897","rc":[{"atb":[[7.2,16.13]],"id":52385918},{"atl":[[210,2]],"id":52385918}],"con":true,"img":false}]}
{"op":"mcm","clk":"11449975002","pt":1717316618538,"mc":[{"id":"1.229554897","rc":[{"atl":[[18.5,5.71],[20,0]],"id":52385907},{"atb":[[8.4,0]],"id":52385918},{"atl":[[250,0]],"id":52385918},{"atl":[[260,2],[310,0]],"id":52385920},{"atl":[[860,2]],"id":52385895}],"con":true,"img":false}]}
{"op":"mcm","clk":"11449975017","pt":1717316618743,"mc":[{"id":"1.229554897","rc":[{"atl":[[65,0]],"id":52385909},{"atb":[[12.5,3.46],[13.5,4.38]],"id":52385920},{"atl":[[290,3.4]],"id":52385884},{"atl":[[210,3.3]],"id":52385895}],"con":true,"img":false}]}
{"op":"mcm","clk":"11449975024","pt":1717316618846,"mc":[{"id":"1.229554897","rc":[{"atb":[[6,0],[5.7,3.39]],"id":52385907},{"atl":[[60,4.63]],"id":52385909},{"atl":[[90,0],[95,3.35]],"id":52385918},{"atl":[[780,0],[800,2.85]],"id":52385886},{"atl":[[85,3.33],[90,0]],"id":52385889},{"atl":[[210,3.8],[220,0]],"id":52385882},{"atl":[[300,0]],"id":52385884},{"atl":[[570,0],[580,3.54]],"id":52385917},{"atl":[[240,0]],"id":52385895},{"atl":[[36,4.16],[38,0]],"id":52385893},{"atl":[[780,3.09],[800,4.27]],"id":52385934}],"con":true,"img":false}]}
{"op":"mcm","clk":"11449975087","pt":1717316619887,"mc":[{"id":"1.229554897","rc":[{"atb":[[5.8,0]],"id":52385907},{"atb":[[130,3.46]],"id":52385886},{"atb":[[13,3.08]],"id":52385920},{"atb":[[220,3.86]],"id":52385888},{"atb":[[120,3.74]],"id":52385917},{"atb":[[2.88,0],[2.76,8.92]],"id":52385891},{"atb":[[55,4.77],[60,0]],"id":52385934}],"con":true,"img":false}]}
{"op":"mcm","clk":"11449975092","pt":1717316619941,"mc":[{"id":"1.229554897","rc":[{"atb":[[120,0]],"id":52385886},{"atb":[[13.5,0]],"id":52385920},{"atb":[[210,0]],"id":52385888},{"atb":[[110,0]],"id":52385917},{"atb":[[11.5,4.39]],"id":52385893},{"atb":[[220,0],[230,4.11]],"id":52385931}],"con":true,"img":false}]}
{"op":"mcm","clk":"11449975118","pt":1717316620256,"mc":[{"id":"1.229554897","rc":[{"atb":[[5.2,0],[4.2,0]],"id":52385907},{"atb":[[9.6,0],[14,0]],"id":52385909},{"atb":[[70,0],[38,0]],"id":52385886},{"atb":[[10.5,0],[8.2,0]],"id":52385918},{"atb":[[6.4,0],[8.4,0]],"id":52385920},{"atb":[[550,0],[650,0]],"id":52385888},{"atb":[[9,0],[12.5,0]],"id":52385889},{"atb":[[10,0],[15,0]],"id":52385882},{"atb":[[12,0],[8.8,0]],"id":52385884},{"atb":[[65,0],[36,0]],"id":52385917},{"atb":[[19,0],[14,0]],"id":52385895},{"atb":[[2.5,0],[2.3,0]],"id":52385891},{"atb":[[530,0],[630,0]],"id":52385923},{"atb":[[8.6,0],[6.6,0]],"id":52385893},{"atb":[[19,0],[14,0]],"id":52385934},{"atb":[[7.8,0],[5.9,0]],"id":52385903},{"atb":[[1.82,0],[1.92,0]],"id":52385904},{"atb":[[550,0],[650,0]],"id":52385936},{"atb":[[550,0],[650,0]],"id":52385931},{"atb":[[17.5,0],[25,0]],"id":52385932}],"con":true,"img":false}]}
{"op":"mcm","clk":"11449975154","pt":1717316620776,"mc":[{"id":"1.229554897","rc":[{"atb":[[2.82,0],[2.78,36.92]],"id":52385891}],"con":true,"img":false}]}
{"op":"mcm","clk":"11449975226","pt":1717316621669,"mc":[{"id":"1.229554897","rc":[{"atb":[[130,0],[120,4.38]],"id":52385886},{"atb":[[13,0],[13.5,3.09]],"id":52385920},{"atb":[[210,4.64],[220,0]],"id":52385888},{"atb":[[110,3.77],[120,0]],"id":52385917},{"atb":[[2.88,8.34],[2.76,0]],"id":52385891},{"atb":[[11.5,0]],"id":52385893},{"atb":[[60,4.62]],"id":52385934},{"atb":[[1.67,23.42],[1.69,22.74]],"id":52385904},{"atb":[[150,0]],"id":52385936},{"atb":[[220,3.26],[230,0]],"id":52385931}],"con":true,"img":false}]}
{"op":"mcm","clk":"11449975234","pt":1717316621778,"mc":[{"id":"1.229554897","rc":[{"atb":[[4.6,0]],"id":52385903}],"con":true,"img":false}]}
{"op":"mcm","clk":"11449975423","pt":1717316624151,"mc":[{"id":"1.229554897","rc":[{"atl":[[65,4.32],[70,0]],"id":52385920},{"atl":[[700,3.01],[710,0]],"id":52385932}],"con":true,"img":false}]}
{"op":"mcm","clk":"11449975663","pt":1717316627282,"mc":[{"id":"1.229554897","rc":[{"atb":[[2.9,9.23],[2.78,0]],"id":52385891}],"con":true,"img":false}]}
{"op":"mcm","clk":"11449975790","pt":1717316628794,"mc":[{"id":"1.229554897","rc":[{"atl":[[800,0],[880,3]],"id":52385886},{"atl":[[95,0]],"id":52385918},{"atl":[[65,0],[70,3.05]],"id":52385920},{"atl":[[210,0],[230,3.52]],"id":52385882},{"atl":[[580,0],[620,3.72]],"id":52385917},{"atb":[[2.82,8.62]],"id":52385891},{"atl":[[700,0],[790,3.11]],"id":52385932}],"con":true,"img":false}]}
{"op":"mcm","clk":"11449975796","pt":1717316628843,"mc":[{"id":"1.229554897","rc":[{"atb":[[5.5,4.46]],"id":52385907},{"atl":[[70,3.98]],"id":52385909},{"atl":[[230,4.36]],"id":52385895},{"atb":[[2.88,0]],"id":52385891}],"con":true,"img":false}]}
{"op":"mcm","clk":"11449975803","pt":1717316628946,"mc":[{"id":"1.229554897","rc":[{"atb":[[2.84,18.46]],"id":52385891}],"con":true,"img":false}]}
{"op":"mcm","clk":"11449975809","pt":1717316629049,"mc":[{"id":"1.229554897","rc":[{"atb":[[2.9,0]],"id":52385891}],"con":true,"img":false}]}
{"op":"mcm","clk":"11449975861","pt":1717316629976,"mc":[{"id":"1.229554897","rc":[{"atb":[[10,4.41]],"id":52385893},{"atl":[[40,3.35]],"id":52385893}],"con":true,"img":false}]}
{"op":"mcm","clk":"11449976002","pt":1717316632059,"mc":[{"id":"1.229554897","rc":[{"atb":[[17.5,0],[18.5,2.77]],"id":52385909},{"atl":[[85,0]],"id":52385909},{"atl":[[860,2.9],[870,0]],"id":52385886},{"atb":[[20,2.89]],"id":52385918},{"atb":[[14.5,3.1]],"id":52385920},{"atb":[[210,0],[220,4.41]],"id":52385888},{"atl":[[220,4.56]],"id":52385882},{"atl":[[260,0]],"id":52385895},{"atb":[[2.82,0],[2.78,8.81]],"id":52385891},{"atb":[[160,0],[180,3.88]],"id":52385923},{"atb":[[11,0],[11.5,4.36]],"id":52385893},{"atb":[[75,4],[60,0]],"id":52385934},{"atb":[[190,0],[200,3.34]],"id":52385936},{"atb":[[220,0],[230,2.91]],"id":52385931},{"atl":[[790,0],[800,3.24]],"id":52385932}],"con":true,"img":false}]}
{"op":"mcm","clk":"11449976009","pt":1717316632162,"mc":[{"id":"1.229554897","rc":[{"atb":[[13.5,0]],"id":52385920},{"atl":[[230,0]],"id":52385882},{"atl":[[48,0]],"id":52385893}],"con":true,"img":false}]}
{"op":"mcm","clk":"11449976055","pt":1717316632987,"mc":[{"id":"1.229554897","rc":[{"atb":[[540,0],[390,0],[440,0],[490,0]],"id":52385936}],"con":true,"img":false}]}
{"op":"mcm","clk":"11449976085","pt":1717316633353,"mc":[{"id":"1.229554897","rc":[{"atl":[[13,3.27],[13.5,0]],"id":52385907},{"atl":[[860,0],[900,3.37]],"id":52385886},{"atl":[[650,4.25]],"id":52385917},{"atl":[[800,0]],"id":52385932}],"con":true,"img":false}]}
{"op":"mcm","clk":"11449976089","pt":1717316633454,"mc":[{"id":"1.229554897","rc":[{"atl":[[620,0]],"id":52385917},{"atl":[[810,4.66]],"id":52385932}],"con":true,"img":false}]}
{"op":"mcm","clk":"11449976106","pt":1717316633662,"mc":[{"id":"1.229554897","rc":[{"atb":[[520,0.2],[570,0.14],[620,0.08],[670,0.04]],"id":52385936}],"con":true,"img":false}]}
{"op":"mcm","clk":"11449976138","pt":1717316634080,"mc":[{"id":"1.229554897","rc":[{"atb":[[130,3.77],[120,0]],"id":52385886},{"atl":[[880,0]],"id":52385886},{"atb":[[110,0],[120,3.47]],"id":52385917},{"atl":[[630,0]],"id":52385917},{"atb":[[2.8,36.92],[2.74,9.01],[2.84,0],[2.78,0]],"id":52385891},{"atb":[[11.5,0],[12,4.16]],"id":52385893},{"atb":[[70,4.23],[75,0]],"id":52385934}],"con":true,"img":false}]}
{"op":"mcm","clk":"11449976502","pt":1717316639236,"mc":[{"id":"1.229554897","rc":[{"atb":[[2.8,0],[2.76,56.82]],"id":52385891}],"con":true,"img":false}]}
{"op":"mcm","clk":"11449976700","pt":1717316642074,"mc":[{"id":"1.229554897","rc":[{"atb":[[17.5,4.35]],"id":52385909},{"atl":[[100,0],[110,2.67]],"id":52385918},{"atb":[[13.5,3.1]],"id":52385920},{"atl":[[70,0],[85,2.73]],"id":52385920},{"atb":[[200,2.79]],"id":52385888},{"atl":[[220,0],[230,4.63]],"id":52385882},{"atb":[[160,4.21]],"id":52385923}],"con":true,"img":false}]}
{"op":"mcm","clk":"11449976765","pt":1717316643022,"mc":[{"id":"1.229554897","rc":[{"atl":[[13,0],[13.5,3.55]],"id":52385907},{"atb":[[16.5,0]],"id":52385909},{"atb":[[130,0],[120,4.54]],"id":52385886},{"atl":[[900,0],[970,2.86]],"id":52385886},{"atb":[[12.5,0]],"id":52385920},{"atb":[[180,0]],"id":52385888},{"atb":[[110,2.71],[120,0]],"id":52385917},{"atl":[[650,0],[710,3.63]],"id":52385917},{"atb":[[140,0]],"id":52385923},{"atb":[[2.74,0],[2.78,8.81]],"id":52385891},{"atb":[[11.5,4.36],[12,0]],"id":52385893},{"atb":[[70,0],[75,4.2]],"id":52385934},{"atl":[[810,0],[920,2.98]],"id":52385932}],"con":true,"img":false}]}
{"op":"mcm","clk":"11449976894","pt":1717316644588,"mc":[{"id":"1.229554897","rc":[{"atl":[[870,0]],"id":52385932}],"con":true,"img":false}]}
{"op":"mcm","clk":"11449977037","pt":1717316646319,"mc":[{"id":"1.229554897","rc":[{"atb":[[110,0]],"id":52385917},{"atb":[[2.74,9.01],[2.78,0]],"id":52385891},{"atb":[[12,3.15]],"id":52385893},{"atb":[[75,0]],"id":52385934}],"con":true,"img":false}]}
{"op":"mcm","clk":"11449977042","pt":1717316646421,"mc":[{"id":"1.229554897","rc":[{"atb":[[130,2.99],[120,0]],"id":52385886},{"atb":[[120,2.69]],"id":52385917},{"atb":[[11.5,0]],"id":52385893},{"atb":[[70,3.12]],"id":52385934}],"con":true,"img":false}]}
{"op":"mcm","clk":"11449977067","pt":1717316646579,"mc":[{"id":"1.229554897","rc":[{"atb":[[18.5,0]],"id":52385909},{"atl":[[950,3.02]],"id":52385886},{"atl":[[910,4.67]],"id":52385932}],"con":true,"img":false}]}
{"op":"mcm","clk":"11449977153","pt":1717316647613,"mc":[{"id":"1.229554897","rc":[{"atl":[[18.5,0],[25,4.17]],"id":52385907},{"atb":[[7.2,0],[8.4,13.51]],"id":52385918},{"atl":[[350,2],[210,0]],"id":52385918},{"atb":[[8,0],[9.4,11.9]],"id":52385920},{"atl":[[260,0],[440,2]],"id":52385920},{"atl":[[450,0],[510,2]],"id":52385889},{"atl":[[910,0]],"id":52385882},{"atl":[[860,0]],"id":52385895},{"atb":[[4.5,0],[4.9,25.64]],"id":52385903}],"con":true,"img":false}]}
{"op":"mcm","clk":"11449977175","pt":1717316647926,"mc":[{"id":"1.229554897","rc":[{"atb":[[5.7,0],[6.6,3.29]],"id":52385907},{"atl":[[60,0]],"id":52385909},{"atl":[[75,0]],"id":52385920},{"atl":[[85,0],[110,2.92]],"id":52385889},{"atl":[[280,3.37],[230,0]],"id":52385882},{"atl":[[290,0],[320,0],[400,4.47]],"id":52385884},{"atl":[[260,4.43],[210,0],[230,0]],"id":52385895},{"atl":[[36,0],[40,0],[44,3.13]],"id":52385893},{"atl":[[780,0],[800,0]],"id":52385934},{"atl":[[24,0],[27,2.94]],"id":52385903},{"atb":[[1.6,0],[1.55,0],[1.67,0],[1.5,0],[1.65,0],[1.53,29.61],[1.69,0]],"id":52385904}],"con":true,"img":false}]}
{"op":"mcm","clk":"11449977186","pt":1717316647979,"mc":[{"id":"1.229554897","rc":[{"atb":[[1.54,29.06]],"id":52385904}],"con":true,"img":false}]}
{"op":"mcm","clk":"11449977195","pt":1717316648084,"mc":[{"id":"1.229554897","rc":[{"atb":[[6.4,3.36]],"id":52385907},{"atl":[[75,3.67]],"id":52385909},{"atl":[[80,3.83]],"id":52385920},{"atl":[[100,0]],"id":52385889},{"atl":[[270,3.32]],"id":52385895},{"atl":[[28,4.35]],"id":52385903}],"con":true,"img":false}]}
{"op":"mcm","clk":"11449977237","pt":1717316648700,"mc":[{"id":"1.229554897","rc":[{"atb":[[1.6,87.2],[1.55,142.69],[1.5,209.27],[1.65,40.24]],"id":52385904}],"con":true,"img":false}]}
{"op":"mcm","clk":"11449977257","pt":1717316648908,"mc":[{"id":"1.229554897","rc":[{"atb":[[6.6,0]],"id":52385907},{"atl":[[70,0]],"id":52385909},{"atl":[[240,0]],"id":52385882},{"atl":[[260,0]],"id":52385895},{"atl":[[26,0],[27,0]],"id":52385903}],"con":true,"img":false}]}
{"op":"mcm","clk":"11449977287","pt":1717316649320,"mc":[{"id":"1.229554897","rc":[{"atl":[[910,2]],"id":52385882}],"con":true,"img":false}]}
{"op":"mcm","clk":"11449977306","pt":1717316649631,"mc":[{"id":"1.229554897","rc":[{"atb":[[6.4,0],[6,3.3]],"id":52385907},{"atl":[[65,3.29]],"id":52385909},{"atl":[[75,3.47],[80,0]],"id":52385920},{"atl":[[90,3.29]],"id":52385889},{"atl":[[230,4.14]],"id":52385882},{"atl":[[300,2.98]],"id":52385884},{"atl":[[240,4.27]],"id":52385895},{"atl":[[38,3.88]],"id":52385893},{"atl":[[24,4.17]],"id":52385903},{"atb":[[1.63,24.91],[1.54,0]],"id":52385904}],"con":true,"img":false}]}
{"op":"mcm","clk":"11449977502","pt":1717316652121,"mc":[{"id":"1.229554897","rc":[{"atl":[[110,0],[120,3.15]],"id":52385918}],"con":true,"img":false}]}
{"op":"mcm","clk":"11449977555","pt":1717316652695,"mc":[{"id":"1.229554897","rc":[{"atb":[[8,6.2],[9.4,0]],"id":52385920},{"atb":[[4.5,6.56],[4.9,0]],"id":52385903}],"con":true,"img":false}]}
{"op":"mcm","clk":"11449977682","pt":1717316654296,"mc":[{"id":"1.229554897","rc":[{"atb":[[8.8,12.4],[7.8,0]],"id":52385909},{"atl":[[320,0],[410,2]],"id":52385909},{"atl":[[910,0]],"id":52385882},{"atb":[[1.28,0],[1.22,174.4]],"id":52385904}],"con":true,"img":false}]}
{"op":"mcm","clk":"11449977704","pt":1717316654712,"mc":[{"id":"1.229554897","rc":[{"atb":[[6,0],[6.6,3.82]],"id":52385907},{"atl":[[13.5,0],[14,2.79]],"id":52385907},{"atl":[[65,0],[75,0],[80,4.43]],"id":52385909},{"atl":[[950,0],[970,0]],"id":52385886},{"atl":[[75,0],[85,0],[95,4.59]],"id":52385920},{"atl":[[90,0],[110,0],[120,2.75]],"id":52385889},{"atl":[[280,0],[340,3.82],[230,0]],"id":52385882},{"atl":[[300,0],[400,0],[490,2.78]],"id":52385884},{"atl":[[710,0],[830,4.16]],"id":52385917},{"atl":[[270,0],[300,4.16],[240,0]],"id":52385895},{"atl":[[10.5,3.98],[11,0]],"id":52385891},{"atl":[[38,0],[44,0],[48,3.63]],"id":52385893},{"atl":[[32,4.29],[24,0],[28,0]],"id":52385903},{"atb":[[1.63,0],[1.6,0],[1.55,0],[1.5,0],[1.65,0],[1.53,0]],"id":52385904},{"atl":[[910,0],[920,0]],"id":52385932}],"con":true,"img":false}]}
{"op":"mcm","clk":"11449977793","pt":1717316655829,"mc":[{"id":"1.229554897","rc":[{"atb":[[1.43,243.34],[1.58,45.1],[1.53,98.71],[1.48,163.49]],"id":52385904}],"con":true,"img":false}]}
{"op":"mcm","clk":"11449977945","pt":1717316657624,"mc":[{"id":"1.229554897","rc":[{"atb":[[5.1,25.49],[4.1,78.68]],"id":52385907},{"atb":[[13.5,8.36],[9.4,29.03]],"id":52385909},{"atb":[[11,10.45],[8.4,46.47]],"id":52385918},{"atb":[[6.4,45.16],[8.4,14.12]],"id":52385920},{"atb":[[80,1.32],[42,5.94]],"id":52385917},{"atb":[[550,0.44],[650,0.16]],"id":52385923},{"atb":[[19,5.8],[14,18.76]],"id":52385934},{"atb":[[550,0.44],[650,0.16]],"id":52385936},{"atb":[[550,0.44],[650,0.16]],"id":52385931},{"atb":[[18,14.34],[26,4.18]],"id":52385932}],"con":true,"img":false}]}
{"op":"mcm","clk":"11449977952","pt":1717316657721,"mc":[{"id":"1.229554897","rc":[{"atb":[[85,1.24],[44,5.67]],"id":52385886},{"atb":[[550,0.44],[650,0.16]],"id":52385888},{"atb":[[9.2,29.74],[13,8.71]],"id":52385889},{"atb":[[10.5,25.67],[15.5,7.2]],"id":52385882},{"atb":[[9,30.48],[12.5,9.08]],"id":52385884},{"atb":[[20,5.5],[15,17.42]],"id":52385895},{"atb":[[2.54,67.87],[2.34,182.01]],"id":52385891},{"atb":[[7.2,39.33],[9.2,12.74]],"id":52385893},{"atb":[[5.8,54.09],[7.6,15.83]],"id":52385903},{"atb":[[1.88,118.78],[1.78,312.69]],"id":52385904}],"con":true,"img":false}]}
{"op":"mcm","clk":"11449978047","pt":1717316658827,"mc":[{"id":"1.229554897","rc":[{"atb":[[8,0]],"id":52385920},{"atb":[[5.4,22.73]],"id":52385903}],"con":true,"img":false}]}
{"op":"mcm","clk":"11449978057","pt":1717316658923,"mc":[{"id":"1.229554897","rc":[{"atb":[[10.5,10.53]],"id":52385920},{"atb":[[4.5,0]],"id":52385903}],"con":true,"img":false}]}
{"op":"mcm","clk":"11449978124","pt":1717316659605,"mc":[{"id":"1.229554897","rc":[{"atb":[[17.5,0],[17,4.55],[19,3.33]],"id":52385909}],"con":true,"img":false}]}
{"op":"mcm","clk":"11449978296","pt":1717316662126,"mc":[{"id":"1.229554897","rc":[{"atl":[[140,3.32]],"id":52385918}],"con":true,"img":false}]}
{"op":"mcm","clk":"11449978493","pt":1717316664621,"mc":[{"id":"1.229554897","rc":[{"atb":[[6.2,3.01]],"id":52385907},{"atl":[[13.5,3.36],[14,0]],"id":52385907},{"atl":[[110,4.04]],"id":52385920},{"atl":[[140,3.84]],"id":52385889},{"atl":[[360,3.52]],"id":52385882},{"atl":[[510,2.91]],"id":52385884},{"atl":[[810,2.72]],"id":52385917},{"atl":[[320,3.56]],"id":52385895},{"atb":[[11,3.46]],"id":52385893},{"atl":[[55,3.69]],"id":52385893},{"atl":[[36,3.28]],"id":52385903}],"con":true,"img":false}]}
{"op":"mcm","clk":"11449978885","pt":1717316669538,"mc":[{"id":"1.229554897","rc":[{"atb":[[18,9.59]],"id":52385909},{"atl":[[90,4.35]],"id":52385909}],"con":true,"img":false}]}
{"op":"mcm","clk":"11449979263","pt":1717316674711,"mc":[{"id":"1.229554897","rc":[{"atb":[[5.5,0]],"id":52385907},{"atb":[[10,0]],"id":52385893}],"con":true,"img":false}]}
{"op":"mcm","clk":"11449979354","pt":1717316676317,"mc":[{"id":"1.229554897","rc":[{"atb":[[6.4,4.41],[6.6,0]],"id":52385907},{"atl":[[13.5,0],[14,3.65]],"id":52385907},{"atb":[[17,0]],"id":52385909},{"atl":[[110,4.56],[120,0]],"id":52385918},{"atb":[[140,3.9]],"id":52385886},{"atb":[[220,0],[230,4.07]],"id":52385888},{"atb":[[34,0],[44,0],[27,0],[60,0]],"id":52385882},{"atb":[[130,3.35],[120,0]],"id":52385917},{"atl":[[810,0],[820,4.36]],"id":52385917},{"atb":[[2.72,9.12],[2.74,0]],"id":52385891},{"atb":[[11.5,4.08]],"id":52385893},{"atb":[[230,0],[240,3.5]],"id":52385931}],"con":true,"img":false}]}
{"op":"mcm","clk":"11449979361","pt":1717316676420,"mc":[{"id":"1.229554897","rc":[{"atb":[[130,0]],"id":52385886},{"atb":[[2.74,57.47]],"id":52385891},{"atb":[[12,0]],"id":52385893}],"con":true,"img":false}]}
{"op":"mcm","clk":"11449979368","pt":1717316676525,"mc":[{"id":"1.229554897","rc":[{"atb":[[2.76,0]],"id":52385891}],"con":true,"img":false}]}
{"op":"mcm","clk":"11449979401","pt":1717316677150,"mc":[{"id":"1.229554897","rc":[{"atb":[[75,0.36],[40,2.01],[50,1.07],[30,3.61]],"id":52385882}],"con":true,"img":false}]}
{"op":"mcm","clk":"11449979457","pt":1717316677925,"mc":[{"id":"1.229554897","rc":[{"atb":[[6.6,3.02]],"id":52385907},{"atb":[[20,0],[22,3.82]],"id":52385918},{"atb":[[230,0],[240,4.07]],"id":52385888},{"atb":[[14.5,0],[15.5,4.69]],"id":52385920},{"atb":[[180,0],[190,3.45]],"id":52385923},{"atb":[[11.5,0],[12,2.78]],"id":52385893},{"atb":[[70,0],[85,4.37]],"id":52385934},{"atb":[[240,0],[250,2.84]],"id":52385931},{"atb":[[130,0],[65,0],[180,0],[90,0]],"id":52385932}],"con":true,"img":false}]}
{"op":"mcm","clk":"11449979469","pt":1717316678039,"mc":[{"id":"1.229554897","rc":[{"atb":[[6.4,0]],"id":52385907},{"atb":[[32,0],[18,3.43],[21,0],[26,0]],"id":52385909},{"atb":[[2.72,0]],"id":52385891}],"con":true,"img":false}]}
{"op":"mcm","clk":"11449979503","pt":1717316678452,"mc":[{"id":"1.229554897","rc":[{"atl":[[22,4.76],[25,0]],"id":52385907},{"atl":[[350,2],[410,0]],"id":52385909},{"atl":[[280,2],[350,0]],"id":52385918},{"atb":[[10.5,0],[8.4,27.63]],"id":52385920},{"atl":[[350,2],[440,0]],"id":52385920}],"con":true,"img":false}]}
{"op":"mcm","clk":"11449979512","pt":1717316678542,"mc":[{"id":"1.229554897","rc":[{"atb":[[6.8,3.45]],"id":52385907},{"atb":[[140,0]],"id":52385886},{"atb":[[220,4.17]],"id":52385888},{"atb":[[130,0],[120,3.74]],"id":52385917},{"atb":[[90,3.74]],"id":52385934}],"con":true,"img":false}]}
{"op":"mcm","clk":"11449979519","pt":1717316678643,"mc":[{"id":"1.229554897","rc":[{"atb":[[130,3.71]],"id":52385886},{"atb":[[160,0.33],[80,1.32],[210,0.13],[110,0.72]],"id":52385932}],"con":true,"img":false}]}
{"op":"mcm","clk":"11449979526","pt":1717316678747,"mc":[{"id":"1.229554897","rc":[{"atb":[[6.6,0]],"id":52385907},{"atb":[[34,0.8],[18.5,5.98],[22,3.74],[27,2.01]],"id":52385909},{"atl":[[70,3.39],[80,0]],"id":52385909},{"atl":[[80,3.48]],"id":52385920},{"atl":[[100,4.04],[120,0]],"id":52385889},{"atl":[[270,3.03],[340,0]],"id":52385882},{"atl":[[390,3.16],[490,0]],"id":52385884},{"atl":[[260,3.77],[300,0]],"id":52385895},{"atb":[[2.72,9.12]],"id":52385891},{"atl":[[10.5,0],[11,2.92]],"id":52385891},{"atl":[[40,4.34]],"id":52385893},{"atl":[[32,0],[28,4.21]],"id":52385903},{"atb":[[240,3.9],[250,0]],"id":52385931},{"atl":[[890,3.51],[910,3.03]],"id":52385932}],"con":true,"img":false}]}
{"op":"mcm","clk":"11449979530","pt":1717316678850,"mc":[{"id":"1.229554897","rc":[{"atl":[[95,0]],"id":52385920},{"atb":[[240,0]],"id":52385888},{"atl":[[48,0]],"id":52385893},{"atb":[[85,0]],"id":52385934}],"con":true,"img":false}]}
{"op":"mcm","clk":"11449979536","pt":1717316678955,"mc":[{"id":"1.229554897","rc":[{"atb":[[230,3.79]],"id":52385888}],"con":true,"img":false}]}
{"op":"mcm","clk":"11449979543","pt":1717316679057,"mc":[{"id":"1.229554897","rc":[{"atb":[[18.5,10.17],[19,0]],"id":52385909}],"con":true,"img":false}]}
{"op":"mcm","clk":"11449980148","pt":1717316687766,"mc":[{"id":"1.229554897","rc":[{"atb":[[6.8,0]],"id":52385907},{"atb":[[18.5,5.98],[19,3.82]],"id":52385909},{"atb":[[130,0],[140,2.84]],"id":52385886},{"atl":[[110,0],[120,2.8]],"id":52385918},{"atb":[[200,0],[230,0]],"id":52385888},{"atb":[[130,2.96],[120,0]],"id":52385917},{"atb":[[2.72,0],[2.76,8.92]],"id":52385891},{"atb":[[180,3.22],[190,0]],"id":52385923},{"atb":[[85,2.9],[90,0]],"id":52385934},{"atl":[[890,0],[870,2.93]],"id":52385932}],"con":true,"img":false}]}
{"op":"mcm","clk":"11449980157","pt":1717316687864,"mc":[{"id":"1.229554897","rc":[{"atb":[[2.78,9.23]],"id":52385891}],"con":true,"img":false}]}
{"op":"mcm","clk":"11449980170","pt":1717316687969,"mc":[{"id":"1.229554897","rc":[{"atb":[[2.74,0]],"id":52385891}],"con":true,"img":false}]}
{"op":"mcm","clk":"11449980219","pt":1717316688600,"mc":[{"id":"1.229554897","rc":[{"atb":[[5.9,4.07]],"id":52385907}],"con":true,"img":false}]}
{"op":"mcm","clk":"11449980231","pt":1717316688758,"mc":[{"id":"1.229554897","rc":[{"atl":[[120,4.48]],"id":52385889},{"atl":[[410,3.94]],"id":52385884},{"atl":[[280,4.24]],"id":52385895},{"atl":[[44,4.38]],"id":52385893},{"atl":[[30,2.75]],"id":52385903},{"atb":[[220,4.16]],"id":52385931}],"con":true,"img":false}]}
{"op":"mcm","clk":"11449980238","pt":1717316688856,"mc":[{"id":"1.229554897","rc":[{"atb":[[14.5,2.64]],"id":52385920},{"atl":[[90,4.38]],"id":52385920},{"atl":[[290,3.5]],"id":52385882}],"con":true,"img":false}]}
{"op":"mcm","clk":"11449980249","pt":1717316688959,"mc":[{"id":"1.229554897","rc":[{"atb":[[200,3.28]],"id":52385888}],"con":true,"img":false}]}
{"op":"mcm","clk":"11449980816","pt":1717316697729,"mc":[{"id":"1.229554897","rc":[{"atl":[[80,4.19]],"id":52385909},{"atb":[[130,3.87],[140,0]],"id":52385886},{"atb":[[20,2.8]],"id":52385918},{"atb":[[130,0],[120,2.83]],"id":52385917},{"atb":[[75,3.5]],"id":52385934},{"atl":[[890,3.47]],"id":52385932}],"con":true,"img":false}]}
{"op":"mcm","clk":"11449980884","pt":1717316698767,"mc":[{"id":"1.229554897","rc":[{"atl":[[140,0]],"id":52385889},{"atl":[[320,0]],"id":52385895},{"atb":[[200,0]],"id":52385931}],"con":true,"img":false}]}
{"op":"mcm","clk":"11449980892","pt":1717316698868,"mc":[{"id":"1.229554897","rc":[{"atb":[[13.5,0]],"id":52385920},{"atl":[[110,0]],"id":52385920},{"atl":[[360,0]],"id":52385882},{"atl":[[510,0]],"id":52385884},{"atl":[[36,0]],"id":52385903}],"con":true,"img":false}]}
{"op":"mcm","clk":"11449980897","pt":1717316698970,"mc":[{"id":"1.229554897","rc":[{"atl":[[55,0]],"id":52385893}],"con":true,"img":false}]}
{"op":"mcm","clk":"11449981019","pt":1717316700878,"mc":[{"id":"1.229554897","rc":[{"atb":[[16.5,0],[19,0],[23,0],[14,0]],"id":52385920},{"atb":[[80,0],[42,0],[110,0],[55,3.31]],"id":52385934}],"con":true,"img":false}]}
{"op":"mcm","clk":"11449981065","pt":1717316701556,"mc":[{"id":"1.229554897","rc":[{"atb":[[17.5,4.76],[20,2.75],[25,1.09],[15,7.48]],"id":52385920},{"atb":[[140,0.19],[70,1.14],[95,0.55],[48,2.23]],"id":52385934}],"con":true,"img":false}]}
{"op":"mcm","clk":"11449981226","pt":1717316703570,"mc":[{"id":"1.229554897","rc":[{"atl":[[90,0]],"id":52385909},{"atb":[[19,0]],"id":52385918},{"atb":[[55,0]],"id":52385934},{"atl":[[910,0]],"id":52385932}],"con":true,"img":false}]}
{"op":"mcm","clk":"11449981413","pt":1717316705953,"mc":[{"id":"1.229554897","rc":[{"atb":[[18.5,10.47],[19,0]],"id":52385909}],"con":true,"img":false}]}
{"op":"mcm","clk":"11449981606","pt":1717316708857,"mc":[{"id":"1.229554897","rc":[{"atb":[[5.1,0],[4.1,0]],"id":52385907},{"atb":[[13.5,0],[9.4,0]],"id":52385909},{"atb":[[11,0],[8.4,13.51]],"id":52385918},{"atb":[[85,0],[44,0]],"id":52385886},{"atb":[[6.4,0],[8.4,13.51]],"id":52385920},{"atb":[[550,0],[650,0]],"id":52385888},{"atb":[[9.2,0],[13,0]],"id":52385889},{"atb":[[10.5,0],[15.5,0]],"id":52385882},{"atb":[[9,0],[12.5,0]],"id":52385884},{"atb":[[80,0],[42,0]],"id":52385917},{"atb":[[20,0],[15,0]],"id":52385895},{"atb":[[2.54,0],[2.34,0]],"id":52385891},{"atb":[[550,0],[650,0]],"id":52385923},{"atb":[[7.2,0],[9.2,0]],"id":52385893},{"atb":[[19,0],[14,0]],"id":52385934},{"atb":[[5.8,3.28],[7.6,0]],"id":52385903},{"atb":[[1.88,0],[1.78,0]],"id":52385904},{"atb":[[550,0],[650,0]],"id":52385936},{"atb":[[550,0],[650,0]],"id":52385931},{"atb":[[18,0],[26,0]],"id":52385932}],"con":true,"img":false}]}
{"op":"mcm","clk":"11449981609","pt":1717316708961,"mc":[{"id":"1.229554897","rc":[{"atb":[[4.9,6.56],[5.4,0]],"id":52385903}],"con":true,"img":false}]}
{"op":"mcm","clk":"11449981624","pt":1717316709166,"mc":[{"id":"1.229554897","rc":[{"atb":[[18.5,5.98],[19.5,3.32]],"id":52385909}],"con":true,"img":false}]}
{"op":"mcm","clk":"11449981863","pt":1717316712486,"mc":[{"id":"1.229554897","rc":[{"atb":[[200,0],[210,4.29]],"id":52385936},{"atb":[[1.56,28.02],[1.58,72.16]],"id":52385904}],"con":true,"img":false}]}
{"op":"mcm","clk":"11449981965","pt":1717316713566,"mc":[{"id":"1.229554897","rc":[{"atb":[[22,0],[24,3.83]],"id":52385918},{"atb":[[130,0],[140,2.76]],"id":52385886},{"atb":[[17.5,0],[18,3.59],[20,0],[25,0],[15,0],[15.5,0]],"id":52385920},{"atb":[[130,4.19],[120,0]],"id":52385917},{"atb":[[2.74,9.01],[2.76,0]],"id":52385891},{"atb":[[180,0],[190,2.8]],"id":52385923},{"atb":[[12,0],[12.5,3.75]],"id":52385893},{"atb":[[80,2.91],[85,0]],"id":52385934},{"atb":[[210,0],[220,3.66]],"id":52385936},{"atb":[[230,2.83],[240,0]],"id":52385931}],"con":true,"img":false}]}
{"op":"mcm","clk":"11449981972","pt":1717316713668,"mc":[{"id":"1.229554897","rc":[{"atb":[[2.76,18.46]],"id":52385891}],"con":true,"img":false}]}
{"op":"mcm","clk":"11449981980","pt":1717316713769,"mc":[{"id":"1.229554897","rc":[{"atb":[[2.78,0]],"id":52385891}],"con":true,"img":false}]}
{"op":"mcm","clk":"11449982010","pt":1717316714285,"mc":[{"id":"1.229554897","rc":[{"atb":[[16.5,6.75],[19,4.36],[23,2.38],[28,0.97]],"id":52385920}],"con":true,"img":false}]}
{"op":"mcm","clk":"11449982538","pt":1717316721696,"mc":[{"id":"1.229554897","rc":[{"atb":[[170,0.61],[85,2.9]],"id":52385886},{"atb":[[550,0.44],[650,0.16]],"id":52385888},{"atb":[[13.5,8.36],[9.4,29.03]],"id":52385889},{"atb":[[16,6.96],[11,24.39]],"id":52385882},{"atb":[[9.2,29.74],[13,8.71]],"id":52385884},{"atb":[[16.5,15.73],[23,4.75]],"id":52385895},{"atb":[[2.28,190.55],[2.48,70.62]],"id":52385891},{"atb":[[9.6,12.15],[7.6,36.95]],"id":52385893},{"atb":[[7.8,15.37],[5.9,49.77]],"id":52385903},{"atb":[[1.82,127.47],[1.72,338.75]],"id":52385904}],"con":true,"img":false}]}
{"op":"mcm","clk":"11449982546","pt":1717316721801,"mc":[{"id":"1.229554897","rc":[{"atb":[[4.4,71.73],[5.4,23.75]],"id":52385907},{"atb":[[10,27.1],[15,7.46]],"id":52385909},{"atb":[[9,30.48],[12.5,9.08]],"id":52385918},{"atb":[[7.2,39.33],[9.2,12.74]],"id":52385920},{"atb":[[160,0.65],[80,3.08]],"id":52385917},{"atb":[[550,0.44],[650,0.16]],"id":52385923},{"atb":[[16,16.26],[22,4.97]],"id":52385934},{"atb":[[550,0.44],[650,0.16]],"id":52385936},{"atb":[[550,0.44],[650,0.16]],"id":52385931},{"atb":[[32,3.37],[21,12.19]],"id":52385932}],"con":true,"img":false}]}
{"op":"mcm","clk":"11449982566","pt":1717316722062,"mc":[{"id":"1.229554897","rc":[{"atb":[[19,4.48]],"id":52385909}],"con":true,"img":false}]}
{"op":"mcm","clk":"11449982574","pt":1717316722162,"mc":[{"id":"1.229554897","rc":[{"atb":[[19.5,0]],"id":52385909}],"con":true,"img":false}]}
{"op":"mcm","clk":"11449982656","pt":1717316723496,"mc":[{"id":"1.229554897","rc":[{"atb":[[120,3.84]],"id":52385886}],"con":true,"img":false}]}
{"op":"mcm","clk":"11449982665","pt":1717316723596,"mc":[{"id":"1.229554897","rc":[{"atb":[[22,3.64]],"id":52385918},{"atb":[[17,3.21]],"id":52385920}],"con":true,"img":false}]}
{"op":"mcm","clk":"11449982706","pt":1717316724274,"mc":[{"id":"1.229554897","rc":[{"atb":[[130,4.7],[140,0]],"id":52385886},{"atb":[[18,0]],"id":52385920},{"atb":[[130,0],[120,2.88]],"id":52385917},{"atb":[[180,2.64],[190,0]],"id":52385923},{"atb":[[2.74,0],[2.76,27.38]],"id":52385891},{"atb":[[12,3.24],[12.5,0]],"id":52385893},{"atb":[[80,0],[85,4.42]],"id":52385934},{"atb":[[220,0]],"id":52385936},{"atb":[[230,0],[240,3.26]],"id":52385931}],"con":true,"img":false}]}
{"op":"mcm","clk":"11449982713","pt":1717316724375,"mc":[{"id":"1.229554897","rc":[{"atb":[[24,0]],"id":52385918}],"con":true,"img":false}]}
{"op":"mcm","clk":"11449982722","pt":1717316724579,"mc":[{"id":"1.229554897","rc":[{"atb":[[20,0]],"id":52385918},{"atb":[[100,0]],"id":52385886},{"atb":[[14.5,0]],"id":52385920}],"con":true,"img":false}]}
{"op":"mcm","clk":"11449983339","pt":1717316733511,"mc":[{"id":"1.229554897","rc":[{"atb":[[24,3.55]],"id":52385918}],"con":true,"img":false}]}
{"op":"mcm","clk":"11449983350","pt":1717316733609,"mc":[{"id":"1.229554897","rc":[{"atb":[[18,3.25]],"id":52385920}],"con":true,"img":false}]}
{"op":"mcm","clk":"11449983399","pt":1717316734281,"mc":[{"id":"1.229554897","rc":[{"atb":[[130,0],[140,4.25]],"id":52385886},{"atb":[[130,3.22],[120,0]],"id":52385917},{"atb":[[2.74,9.01],[2.76,18.46]],"id":52385891},{"atb":[[180,0],[190,3.23]],"id":52385923},{"atb":[[12,0],[12.5,3.31]],"id":52385893},{"atb":[[80,3.04],[85,0]],"id":52385934},{"atb":[[230,3.07],[240,0]],"id":52385931}],"con":true,"img":false}]}
{"op":"mcm","clk":"11449983478","pt":1717316735687,"mc":[{"id":"1.229554897","rc":[{"atb":[[130,3.35],[140,0]],"id":52385886},{"atb":[[17,0],[18,0]],"id":52385920},{"atb":[[130,0],[120,4.07]],"id":52385917},{"atb":[[2.74,0],[2.76,27.38]],"id":52385891},{"atb":[[180,3.75],[190,0]],"id":52385923},{"atb":[[12,4.16],[12.5,0]],"id":52385893},{"atb":[[80,0],[85,4.48]],"id":52385934},{"atb":[[230,0],[240,3.62]],"id":52385931}],"con":true,"img":false}]}
{"op":"mcm","clk":"11449983487","pt":1717316735787,"mc":[{"id":"1.229554897","rc":[{"atb":[[24,0]],"id":52385918}],"con":true,"img":false}]}
{"op":"mcm","clk":"11449983891","pt":1717316742031,"mc":[{"id":"1.229554897","rc":[{"atb":[[520,0],[570,0],[620,0],[670,0]],"id":52385936}],"con":true,"img":false}]}
{"op":"mcm","clk":"11449983917","pt":1717316742487,"mc":[{"id":"1.229554897","rc":[{"atb":[[24,3.75]],"id":52385918},{"atb":[[130,0],[140,3.16]],"id":52385886},{"atb":[[17,4.56],[18,3.76]],"id":52385920},{"atb":[[130,3.73],[120,0]],"id":52385917},{"atb":[[190,4.12]],"id":52385923},{"atb":[[2.74,9.01],[2.76,18.46]],"id":52385891},{"atb":[[12.5,3.36]],"id":52385893},{"atb":[[80,2.89],[85,0]],"id":52385934},{"atb":[[230,3.91],[240,0]],"id":52385931}],"con":true,"img":false}]}
{"op":"mcm","clk":"11449983922","pt":1717316742588,"mc":[{"id":"1.229554897","rc":[{"atb":[[180,0]],"id":52385923},{"atb":[[12,0]],"id":52385893}],"con":true,"img":false}]}
{"op":"mcm","clk":"11449983933","pt":1717316742693,"mc":[{"id":"1.229554897","rc":[{"atb":[[690,0.15],[740,0.1],[790,0.07],[840,0.03]],"id":52385936}],"con":true,"img":false}]}
{"op":"mcm","clk":"11449984056","pt":1717316744300,"mc":[{"id":"1.229554897","rc":[{"atb":[[130,2.78],[140,0]],"id":52385886},{"atb":[[24,0]],"id":52385918},{"atb":[[17,0],[18,0]],"id":52385920},{"atb":[[130,0],[120,4.42]],"id":52385917},{"atb":[[180,4.35],[190,0]],"id":52385923},{"atb":[[2.74,0],[2.76,27.38]],"id":52385891},{"atb":[[12,2.71],[12.5,0]],"id":52385893},{"atb":[[80,0],[85,3.53]],"id":52385934},{"atb":[[230,0],[240,2.95]],"id":52385931}],"con":true,"img":false}]}
{"op":"mcm","clk":"11449984240","pt":1717316746827,"mc":[{"id":"1.229554897","rc":[{"atb":[[2.74,9.01],[2.76,18.46]],"id":52385891}],"con":true,"img":false}]}
{"op":"mcm","clk":"11449984386","pt":1717316748835,"mc":[{"id":"1.229554897","rc":[{"atb":[[24,3.21]],"id":52385918},{"atb":[[150,3.58]],"id":52385886},{"atb":[[16.5,10.7],[17.5,4.67]],"id":52385920},{"atb":[[230,4.61]],"id":52385888},{"atb":[[140,3.36]],"id":52385917},{"atb":[[2.68,9.34]],"id":52385891},{"atb":[[200,3.55]],"id":52385923},{"atb":[[12,0],[13,4.33]],"id":52385893}],"con":true,"img":false}]}
{"op":"mcm","clk":"11449984396","pt":1717316748936,"mc":[{"id":"1.229554897","rc":[{"atb":[[220,0]],"id":52385888},{"atb":[[120,0]],"id":52385917},{"atb":[[2.74,0]],"id":52385891},{"atb":[[180,0]],"id":52385923}],"con":true,"img":false}]}
{"op":"mcm","clk":"11449984403","pt":1717316749038,"mc":[{"id":"1.229554897","rc":[{"atb":[[130,0]],"id":52385886},{"atb":[[2.72,36.92],[2.76,0]],"id":52385891}],"con":true,"img":false}]}
{"op":"mcm","clk":"11449984614","pt":1717316752242,"mc":[{"id":"1.229554897","rc":[{"atb":[[140,3.88],[150,0]],"id":52385886},{"atb":[[220,3.34],[230,0]],"id":52385888},{"atb":[[17.5,0],[18,3.92]],"id":52385920},{"atb":[[130,4.58],[140,0]],"id":52385917},{"atb":[[2.74,9.01],[2.7,0]],"id":52385891},{"atb":[[190,3.4]],"id":52385923},{"atb":[[12.5,4.46],[13,0]],"id":52385893},{"atb":[[80,4.15],[85,0]],"id":52385934},{"atb":[[230,3.46],[240,0]],"id":52385931}],"con":true,"img":false}]}
{"op":"mcm","clk":"11449984620","pt":1717316752293,"mc":[{"id":"1.229554897","rc":[{"atb":[[200,0]],"id":52385923}],"con":true,"img":false}]}
{"op":"mcm","clk":"11449984628","pt":1717316752406,"mc":[{"id":"1.229554897","rc":[{"atb":[[2.72,0],[2.76,9.34]],"id":52385891}],"con":true,"img":false}]}
{"op":"mcm","clk":"11449984669","pt":1717316753022,"mc":[{"id":"1.229554897","rc":[{"atb":[[150,2.63]],"id":52385886},{"atb":[[220,0],[230,4.63]],"id":52385888},{"atb":[[17.5,3.7],[18,0]],"id":52385920},{"atb":[[140,3.24]],"id":52385917},{"atb":[[160,0]],"id":52385923},{"atb":[[12.5,0],[13,4.31]],"id":52385893},{"atb":[[80,0],[85,3.27]],"id":52385934},{"atb":[[230,0],[240,2.98]],"id":52385931}],"con":true,"img":false}]}
{"op":"mcm","clk":"11449984677","pt":1717316753131,"mc":[{"id":"1.229554897","rc":[{"atb":[[140,0]],"id":52385886},{"atb":[[130,0]],"id":52385917},{"atb":[[2.74,0]],"id":52385891}],"con":true,"img":false}]}
{"op":"mcm","clk":"11449984709","pt":1717316753541,"mc":[{"id":"1.229554897","rc":[{"atb":[[23,4.55],[5.7,0]],"id":52385882},{"atb":[[5.7,0],[13.5,8]],"id":52385884},{"atb":[[11.5,8.01],[2.78,0]],"id":52385895},{"atb":[[4.9,0],[5.4,18.65]],"id":52385903},{"atl":[[7.2,2.81],[29,3.57]],"id":52385904},{"atb":[[11.5,8.01],[2.78,0]],"id":52385932}],"con":true,"img":false}]}
{"op":"mcm","clk":"11449984720","pt":1717316753597,"mc":[{"id":"1.229554897","rc":[{"atb":[[190,0],[200,3.26]],"id":52385923}],"con":true,"img":false}]}
{"op":"mcm","clk":"11449984733","pt":1717316753798,"mc":[{"id":"1.229554897","rc":[{"atb":[[19,2.93],[5.8,0]],"id":52385889},{"atb":[[38,4],[5.8,0]],"id":52385882},{"atb":[[5.8,0],[28,4.6]],"id":52385884},{"atb":[[36,4.03],[2.96,0]],"id":52385895},{"atb":[[5.8,0],[9.8,4.52]],"id":52385903},{"atl":[[7.2,0],[3.15,7.29]],"id":52385904},{"atb":[[2.96,0],[120,3.07]],"id":52385932}],"con":true,"img":false}]}
{"op":"mcm","clk":"11449984742","pt":1717316753904,"mc":[{"id":"1.229554897","rc":[{"atb":[[23,4.55],[13.5,0]],"id":52385884}],"con":true,"img":false}]}
{"op":"mcm","clk":"11449984935","pt":1717316756848,"mc":[{"id":"1.229554897","rc":[{"atb":[[230,0]],"id":52385888},{"atb":[[17,2.97]],"id":52385889},{"atb":[[34,4.65]],"id":52385882},{"atb":[[26,3.37],[28,0]],"id":52385884},{"atb":[[130,3.67]],"id":52385917},{"atb":[[32,3.56]],"id":52385895},{"atb":[[190,3.38]],"id":52385923},{"atb":[[2.74,9.01]],"id":52385891},{"atb":[[12.5,2.88]],"id":52385893},{"atb":[[80,2.96]],"id":52385934},{"atb":[[230,3.38],[240,0]],"id":52385931},{"atb":[[110,3.62],[120,0]],"id":52385932}],"con":true,"img":false}]}
{"op":"mcm","clk":"11449984945","pt":1717316756950,"mc":[{"id":"1.229554897","rc":[{"atb":[[140,3.95],[150,0]],"id":52385886},{"atb":[[220,3.25]],"id":52385888},{"atb":[[17.5,0],[18,4.6]],"id":52385920},{"atb":[[19,0]],"id":52385889},{"atb":[[38,0]],"id":52385882},{"atb":[[140,0]],"id":52385917},{"atb":[[36,0]],"id":52385895},{"atb":[[200,0]],"id":52385923},{"atb":[[13,0]],"id":52385893},{"atb":[[85,0]],"id":52385934}],"con":true,"img":false}]}
{"op":"mcm","clk":"11449985437","pt":1717316763555,"mc":[{"id":"1.229554897","rc":[{"atb":[[150,3.01]],"id":52385886},{"atb":[[17.5,4.39]],"id":52385920},{"atb":[[230,3.11]],"id":52385888},{"atb":[[38,3.34]],"id":52385882},{"atb":[[26,0]],"id":52385884},{"atb":[[140,4.67]],"id":52385917},{"atb":[[12.5,0],[13,4.54]],"id":52385893},{"atb":[[80,0],[85,4.7]],"id":52385934}],"con":true,"img":false}]}
{"op":"mcm","clk":"11449985447","pt":1717316763660,"mc":[{"id":"1.229554897","rc":[{"atb":[[140,0]],"id":52385886},{"atb":[[18,0]],"id":52385920},{"atb":[[220,0]],"id":52385888},{"atb":[[17,0]],"id":52385889},{"atb":[[34,0]],"id":52385882},{"atb":[[13.5,8],[28,4.65]],"id":52385884},{"atb":[[130,0]],"id":52385917},{"atb":[[32,0],[36,3.69]],"id":52385895},{"atb":[[200,3.85]],"id":52385923},{"atb":[[2.74,0]],"id":52385891},{"atb":[[230,0],[240,4.15]],"id":52385931},{"atb":[[110,0.72],[120,3.88]],"id":52385932}],"con":true,"img":false}]}
{"op":"mcm","clk":"11449985458","pt":1717316763765,"mc":[{"id":"1.229554897","rc":[{"atb":[[23,0]],"id":52385884},{"atb":[[2.76,0],[2.7,58.82]],"id":52385891}],"con":true,"img":false}]}
{"op":"mcm","clk":"11449985469","pt":1717316763812,"mc":[{"id":"1.229554897","rc":[{"atb":[[9.4,2.71]],"id":52385903},{"atl":[[3.25,6.97]],"id":52385904}],"con":true,"img":false}]}
{"op":"mcm","clk":"11449985503","pt":1717316764121,"mc":[{"id":"1.229554897","rc":[{"atb":[[23,4.55],[13.5,0]],"id":52385884}],"con":true,"img":false}]}
{"op":"mcm","clk":"11449985510","pt":1717316764226,"mc":[{"id":"1.229554897","rc":[{"atb":[[19,3.02]],"id":52385889}],"con":true,"img":false}]}
{"op":"mcm","clk":"11449985704","pt":1717316766621,"mc":[{"id":"1.229554897","rc":[{"atb":[[2.64,9.56]],"id":52385891}],"con":true,"img":false}]}
{"op":"mcm","clk":"11449986248","pt":1717316773465,"mc":[{"id":"1.229554897","rc":[{"atb":[[18.5,10.55],[19,0]],"id":52385909},{"atb":[[5.6,0]],"id":52385903},{"atl":[[7.6,0]],"id":52385904}],"con":true,"img":false}]}
{"op":"mcm","clk":"11449986264","pt":1717316773620,"mc":[{"id":"1.229554897","rc":[{"atb":[[18,2.98]],"id":52385889},{"atb":[[34,3.11]],"id":52385882},{"atb":[[26,3.71]],"id":52385884},{"atb":[[120,4.24]],"id":52385917},{"atb":[[32,3.73]],"id":52385895},{"atb":[[12,4.01]],"id":52385893},{"atb":[[100,2.96]],"id":52385932}],"con":true,"img":false}]}
{"op":"mcm","clk":"11449986342","pt":1717316774545,"mc":[{"id":"1.229554897","rc":[{"atb":[[5.6,0]],"id":52385882},{"atb":[[5.6,0]],"id":52385884},{"atb":[[2.92,0]],"id":52385895},{"atb":[[11,0]],"id":52385893},{"atb":[[10,2.81],[9.8,0]],"id":52385903},{"atb":[[2.92,0]],"id":52385932}],"con":true,"img":false}]}
{"op":"mcm","clk":"11449986347","pt":1717316774649,"mc":[{"id":"1.229554897","rc":[{"atb":[[5.6,0]],"id":52385889},{"atb":[[100,0]],"id":52385917}],"con":true,"img":false}]}
{"op":"mcm","clk":"11449986376","pt":1717316774957,"mc":[{"id":"1.229554897","rc":[{"atb":[[19.5,4.36]],"id":52385909}],"con":true,"img":false}]}
{"op":"mcm","clk":"11449986383","pt":1717316775059,"mc":[{"id":"1.229554897","rc":[{"atb":[[18.5,5.98]],"id":52385909}],"con":true,"img":false}]}
{"op":"mcm","clk":"11449986408","pt":1717316775425,"mc":[{"id":"1.229554897","rc":[{"atb":[[10,0],[9.8,3.71]],"id":52385903}],"con":true,"img":false}]}
{"op":"mcm","clk":"11449986501","pt":1717316776867,"mc":[{"id":"1.229554897","rc":[{"atb":[[140,3.45],[150,0]],"id":52385886},{"atb":[[24,0],[25,2.94]],"id":52385918},{"atb":[[220,4.09],[230,0]],"id":52385888},{"atb":[[17.5,0],[18,3.25]],"id":52385920},{"atb":[[19,0]],"id":52385889},{"atb":[[38,0]],"id":52385882},{"atb":[[28,0]],"id":52385884},{"atb":[[130,3.56],[140,0]],"id":52385917},{"atb":[[34,4.69],[36,0]],"id":52385895},{"atb":[[2.68,0],[2.7,68.05]],"id":52385891},{"atb":[[80,3.61],[85,0]],"id":52385934},{"atb":[[9.6,4.39],[9.8,0]],"id":52385903},{"atb":[[110,3.45],[120,0]],"id":52385932}],"con":true,"img":false}]}
{"op":"mcm","clk":"11449986995","pt":1717316783566,"mc":[{"id":"1.229554897","rc":[{"atb":[[17,4.18]],"id":52385889},{"atb":[[30,7.09]],"id":52385882},{"atb":[[24,3.8]],"id":52385884}],"con":true,"img":false}]}
{"op":"mcm","clk":"11449988108","pt":1717316798500,"mc":[{"id":"1.229554897","rc":[{"atb":[[7.6,8.74],[8.8,0]],"id":52385909},{"atb":[[7.2,16.13],[8.4,0]],"id":52385918},{"atb":[[10.5,10.53],[5.7,0]],"id":52385889}],"con":true,"img":false}]}
{"op":"mcm","clk":"11449991230","pt":1717316840137,"mc":[{"id":"1.229554897","rc":[{"atb":[[690,0],[740,0],[790,0],[840,0]],"id":52385936}],"con":true,"img":false}]}
{"op":"mcm","clk":"11449991274","pt":1717316840848,"mc":[{"id":"1.229554897","rc":[{"atb":[[730,0.14],[780,0.1],[830,0.06],[880,0.03]],"id":52385936}],"con":true,"img":false}]}
{"op":"mcm","clk":"11449993580","pt":1717316869952,"mc":[{"id":"1.229554897","rc":[{"atb":[[4.4,0],[5.4,0]],"id":52385907},{"atb":[[10,0],[15,0]],"id":52385909},{"atb":[[9,0],[12.5,0]],"id":52385918},{"atb":[[170,0],[85,0]],"id":52385886},{"atb":[[7.2,0],[9.2,0]],"id":52385920},{"atb":[[550,0],[650,0]],"id":52385888},{"atb":[[13.5,0],[9.4,0]],"id":52385889},{"atb":[[16,0],[11,0]],"id":52385882},{"atb":[[9.2,0],[13,0]],"id":52385884},{"atb":[[160,0],[80,0]],"id":52385917},{"atb":[[16.5,0],[23,0]],"id":52385895},{"atb":[[2.28,0],[2.48,0]],"id":52385891},{"atb":[[550,0],[650,0]],"id":52385923},{"atb":[[9.6,0],[7.6,0]],"id":52385893},{"atb":[[16,0],[22,0]],"id":52385934},{"atb":[[7.8,0],[5.9,0]],"id":52385903},{"atb":[[550,0],[650,0]],"id":52385936},{"atb":[[1.82,0],[1.72,0]],"id":52385904},{"atb":[[550,0],[650,0]],"id":52385931},{"atb":[[32,0],[21,0]],"id":52385932}],"con":true,"img":false}]}
{"op":"mcm","clk":"11449993627","pt":1717316870467,"mc":[{"id":"1.229554897","rc":[{"atb":[[220,3.74]],"id":52385936}],"con":true,"img":false}]}
{"op":"mcm","clk":"11449994491","pt":1717316880458,"mc":[{"id":"1.229554897","rc":[{"atb":[[200,3.99]],"id":52385936}],"con":true,"img":false}]}
{"op":"mcm","clk":"11449994599","pt":1717316881767,"mc":[{"id":"1.229554897","rc":[{"atb":[[34,0],[18.5,0],[22,0],[27,0]],"id":52385909},{"atb":[[75,0],[40,0],[50,0],[30,3.48]],"id":52385882}],"con":true,"img":false}]}
{"op":"mcm","clk":"11449994684","pt":1717316882763,"mc":[{"id":"1.229554897","rc":[{"atb":[[32,0.84],[18,9.59],[21,3.92],[26,2.09]],"id":52385909},{"atb":[[65,0.41],[36,2.24],[46,1.16],[28,3.88]],"id":52385882}],"con":true,"img":false}]}
{"op":"mcm","clk":"11449994873","pt":1717316884787,"mc":[{"id":"1.229554897","rc":[{"atb":[[170,0]],"id":52385936}],"con":true,"img":false}]}
{"op":"mcm","clk":"11449995977","pt":1717316896880,"mc":[{"id":"1.229554897","rc":[{"atb":[[24,3.47],[25,0]],"id":52385918},{"atb":[[18,0]],"id":52385889},{"atb":[[34,1.59]],"id":52385895},{"atb":[[200,0]],"id":52385923},{"atb":[[2.74,9.01],[2.7,58.82]],"id":52385891},{"atb":[[12.5,4.23],[13,0]],"id":52385893},{"atb":[[9.6,0],[9.8,4.67]],"id":52385903},{"atb":[[230,3.03],[240,0]],"id":52385931}],"con":true,"img":false}]}
{"op":"mcm","clk":"11449995985","pt":1717316896986,"mc":[{"id":"1.229554897","rc":[{"atb":[[2.7,0],[2.76,9.57]],"id":52385891}],"con":true,"img":false}]}
{"op":"mcm","clk":"11449996019","pt":1717316897397,"mc":[{"id":"1.229554897","rc":[{"atb":[[730,0],[780,0],[830,0],[880,0]],"id":52385936}],"con":true,"img":false}]}
{"op":"mcm","clk":"11449996083","pt":1717316898065,"mc":[{"id":"1.229554897","rc":[{"atb":[[690,0.15],[740,0.1],[790,0.07],[840,0.03]],"id":52385936}],"con":true,"img":false}]}
{"op":"mcm","clk":"11449996372","pt":1717316901583,"mc":[{"id":"1.229554897","rc":[{"atb":[[16,4.31]],"id":52385889},{"atb":[[29,3.23]],"id":52385895},{"atb":[[170,3.76]],"id":52385923}],"con":true,"img":false}]}
{"op":"mcm","clk":"11449996407","pt":1717316901996,"mc":[{"id":"1.229554897","rc":[{"atb":[[4.4,71.73],[5.4,23.75]],"id":52385907},{"atb":[[10,27.1],[15,7.46]],"id":52385909},{"atb":[[9,30.48],[12.5,9.08]],"id":52385918},{"atb":[[170,0.61],[85,2.9]],"id":52385886},{"atb":[[7.2,39.33],[9.2,12.74]],"id":52385920},{"atb":[[550,0.44],[650,0.16]],"id":52385888},{"atb":[[13.5,8.36],[9.4,29.03]],"id":52385889},{"atb":[[16,6.96],[11,24.39]],"id":52385882},{"atb":[[9.2,29.74],[13,8.71]],"id":52385884},{"atb":[[160,0.65],[80,3.08]],"id":52385917},{"atb":[[16.5,15.73],[23,4.75]],"id":52385895},{"atb":[[550,0.44],[650,0.16]],"id":52385923},{"atb":[[2.28,190.55],[2.48,70.62]],"id":52385891},{"atb":[[9.6,12.15],[7.6,36.95]],"id":52385893},{"atb":[[16,16.26],[22,4.97]],"id":52385934},{"atb":[[7.8,15.37],[5.9,49.77]],"id":52385903},{"atb":[[550,0.44],[650,0.16]],"id":52385936},{"atb":[[1.82,127.47],[1.72,338.75]],"id":52385904},{"atb":[[550,0.44],[650,0.16]],"id":52385931},{"atb":[[32,3.37],[21,12.19]],"id":52385932}],"con":true,"img":false}]}
{"op":"mcm","clk":"11449996820","pt":1717316906881,"mc":[{"id":"1.229554897","rc":[{"atb":[[2.7,9.23]],"id":52385891}],"con":true,"img":false}]}
{"op":"mcm","clk":"11449997235","pt":1717316912323,"mc":[{"id":"1.229554897","rc":[{"atb":[[2.64,0]],"id":52385891}],"con":true,"img":false}]}
{"op":"mcm","clk":"11449998234","pt":1717316924824,"mc":[{"id":"1.229554897","rc":[{"atb":[[24,0],[25,4.62]],"id":52385918},{"atb":[[17,0],[18,2.72]],"id":52385889},{"atb":[[32,0],[34,4.33]],"id":52385895},{"atb":[[2.74,0]],"id":52385891},{"atb":[[190,0],[200,2.73]],"id":52385923},{"atb":[[12.5,0],[13,4.04]],"id":52385893},{"atb":[[9.6,4.22],[9.8,0]],"id":52385903},{"atb":[[230,0],[240,3.93]],"id":52385931}],"con":true,"img":false}]}
{"op":"mcm","clk":"11449998242","pt":1717316924928,"mc":[{"id":"1.229554897","rc":[{"atb":[[2.72,58.14],[2.76,0]],"id":52385891}],"con":true,"img":false}]}
{"op":"mcm","clk":"11449998338","pt":1717316926222,"mc":[{"id":"1.229554897","rc":[{"atb":[[24,4.61],[25,0]],"id":52385918},{"atb":[[17,3.88],[18,0]],"id":52385889},{"atb":[[32,3.66],[34,1.59]],"id":52385895},{"atb":[[2.74,9.01]],"id":52385891},{"atb":[[190,2.93],[200,0]],"id":52385923},{"atb":[[12.5,4.54],[13,0]],"id":52385893},{"atb":[[9.6,0],[9.8,4.03]],"id":52385903},{"atb":[[230,4.25],[240,0]],"id":52385931}],"con":true,"img":false}]}
{"op":"mcm","clk":"11449998400","pt":1717316927148,"mc":[{"id":"1.229554897","rc":[{"atb":[[24,0],[25,3.84]],"id":52385918},{"atb":[[17,0],[18,4.36]],"id":52385889},{"atb":[[32,0],[34,5.28]],"id":52385895},{"atb":[[190,0],[200,2.9]],"id":52385923},{"atb":[[2.74,0]],"id":52385891},{"atb":[[12.5,0],[13,2.71]],"id":52385893},{"atb":[[9.6,3.11],[9.8,0]],"id":52385903},{"atb":[[230,0],[240,3.09]],"id":52385931}],"con":true,"img":false}]}
{"op":"mcm","clk":"11449999123","pt":1717316936253,"mc":[{"id":"1.229554897","rc":[{"atb":[[2.66,9.45]],"id":52385891}],"con":true,"img":false}]}
{"op":"mcm","clk":"11449999224","pt":1717316937165,"mc":[{"id":"1.229554897","rc":[{"atb":[[17,2.66]],"id":52385889}],"con":true,"img":false}]}
{"op":"mcm","clk":"11450000132","pt":1717316947197,"mc":[{"id":"1.229554897","rc":[{"atb":[[16,0]],"id":52385889}],"con":true,"img":false}]}
{"op":"mcm","clk":"11450002945","pt":1717316979997,"mc":[{"id":"1.229554897","rc":[{"atb":[[690,0],[740,0],[790,0],[840,0]],"id":52385936}],"con":true,"img":false}]}
{"op":"mcm","clk":"11450003004","pt":1717316980726,"mc":[{"id":"1.229554897","rc":[{"atb":[[730,0.14],[780,0.1],[830,0.06],[880,0.03]],"id":52385936}],"con":true,"img":false}]}
{"op":"mcm","clk":"11450003944","pt":1717316992037,"mc":[{"id":"1.229554897","rc":[{"atb":[[4.4,0],[5.4,0]],"id":52385907},{"atb":[[10,0],[15,0]],"id":52385909},{"atb":[[9,0],[12.5,0]],"id":52385918},{"atb":[[170,0],[85,0]],"id":52385886},{"atb":[[7.2,0],[9.2,0]],"id":52385920},{"atb":[[550,0],[650,0]],"id":52385888},{"atb":[[13.5,0],[9.4,0]],"id":52385889},{"atb":[[16,0],[11,0]],"id":52385882},{"atb":[[9.2,0],[13,0]],"id":52385884},{"atb":[[160,0],[80,0]],"id":52385917},{"atb":[[16.5,0],[23,0]],"id":52385895},{"atb":[[2.28,0],[2.48,0]],"id":52385891},{"atb":[[550,0],[650,0]],"id":52385923},{"atb":[[9.6,0],[7.6,0]],"id":52385893},{"atb":[[16,0],[22,0]],"id":52385934},{"atb":[[7.8,0],[5.9,0]],"id":52385903},{"atb":[[550,0],[650,0]],"id":52385936},{"atb":[[1.82,0],[1.72,0]],"id":52385904},{"atb":[[550,0],[650,0]],"id":52385931},{"atb":[[32,0],[21,0]],"id":52385932}],"con":true,"img":false}]}
{"op":"mcm","clk":"11450006471","pt":1717317018552,"mc":[{"id":"1.229554897","rc":[{"atb":[[3.25,0],[3.5,29.57]],"id":52385907},{"atl":[[18,5.88],[22,0]],"id":52385907},{"atb":[[4.3,8.3],[7.6,0]],"id":52385909},{"atl":[[75,2],[350,0]],"id":52385909},{"atb":[[5.6,7.68],[7.2,0]],"id":52385918},{"atl":[[140,5.32],[280,0]],"id":52385918},{"atl":[[1000,2]],"id":52385886},{"atb":[[44,2.33],[30,0]],"id":52385888},{"atb":[[8.4,0],[4.7,7.62]],"id":52385920},{"atl":[[350,0],[110,2]],"id":52385920},{"atb":[[10.5,0],[7,8.72]],"id":52385889},{"atl":[[150,2],[510,0]],"id":52385889},{"atb":[[9,6.24],[23,0]],"id":52385882},{"atl":[[420,2]],"id":52385882},{"atb":[[23,0],[8.4,7.6]],"id":52385884},{"atl":[[380,2]],"id":52385884},{"atb":[[32,0],[11.5,7.14]],"id":52385917},{"atl":[[810,2]],"id":52385917},{"atb":[[8.2,8.22],[11.5,0]],"id":52385895},{"atl":[[320,2]],"id":52385895},{"atb":[[18.5,5.71],[30,0]],"id":52385923},{"atl":[[1000,2]],"id":52385923},{"atb":[[5,8.02],[6.8,0]],"id":52385893},{"atl":[[100,2]],"id":52385893},{"atb":[[34,0],[10,4.46]],"id":52385934},{"atl":[[860,2]],"id":52385934},{"atb":[[3.75,6.24],[5.4,0]],"id":52385903},{"atl":[[40,2.56],[110,0]],"id":52385903},{"atb":[[1.6,72.17],[1.22,0]],"id":52385904},{"atb":[[42,2.44],[30,0]],"id":52385931},{"atl":[[870,4.93]],"id":52385932}],"con":true,"img":false}]}
{"op":"mcm","clk":"11450006479","pt":1717317018653,"mc":[{"id":"1.229554897","rc":[{"atl":[[160,0]],"id":52385893}],"con":true,"img":false}]}
{"op":"mcm","clk":"11450006487","pt":1717317018756,"mc":[{"id":"1.229554897","rc":[{"atb":[[10,8.22],[8.2,0]],"id":52385895},{"atl":[[270,2],[320,0]],"id":52385895}],"con":true,"img":false}]}
{"op":"mcm","clk":"11450006495","pt":1717317018859,"mc":[{"id":"1.229554897","rc":[{"atb":[[6.2,0],[6,3.89]],"id":52385907},{"atb":[[32,0],[18,0],[19.5,0],[21,0],[11.5,4.37],[26,0]],"id":52385909},{"atl":[[70,0],[48,3.99]],"id":52385909},{"atb":[[17.5,3.95],[25,0]],"id":52385918},{"atb":[[140,0],[95,3.33]],"id":52385886},{"atb":[[16.5,3.95],[18,0],[19,0],[23,0],[28,0],[14,2.95]],"id":52385920},{"atb":[[180,3.74],[220,0]],"id":52385888},{"atl":[[100,0],[55,3.28]],"id":52385889},{"atl":[[270,0],[260,4.5]],"id":52385882},{"atl":[[180,2.74],[390,0]],"id":52385884},{"atb":[[130,0],[46,3.63],[120,0]],"id":52385917},{"atb":[[34,1.59],[30,3.92]],"id":52385895},{"atl":[[260,0],[110,3.41]],"id":52385895},{"atb":[[65,4.65],[170,0],[200,0]],"id":52385923},{"atl":[[11,0],[9.8,3.03]],"id":52385891},{"atl":[[32,4.59],[40,0]],"id":52385893},{"atb":[[140,0],[70,0],[75,0],[80,0],[95,0],[48,0]],"id":52385934},{"atl":[[610,4.44],[630,4.47]],"id":52385934},{"atb":[[9.6,0],[8.6,2.74]],"id":52385903},{"atl":[[23,3.64],[28,0]],"id":52385903},{"atb":[[1.58,45.1],[1.84,18.68]],"id":52385904},{"atl":[[3.15,0],[3.75,5.7]],"id":52385904},{"atb":[[730,0],[780,0],[830,0],[200,0],[880,0],[220,0]],"id":52385936},{"atb":[[160,4.69],[240,0]],"id":52385931},{"atb":[[160,0],[80,0],[100,0],[50,2.78],[210,0],[110,0]],"id":52385932}],"con":true,"img":false}]}
{"op":"mcm","clk":"11450006574","pt":1717317019583,"mc":[{"id":"1.229554897","rc":[{"atb":[[16.5,1.69],[9.6,12.17],[11.5,11.85],[14,4.02]],"id":52385909},{"atb":[[18,3.08],[21,1.31],[13,8.72],[15.5,5.41]],"id":52385920},{"atb":[[70,0.38],[38,2.12],[48,1.11],[29,3.74]],"id":52385934},{"atb":[[160,0.16],[80,0.99],[110,0.48],[55,1.94]],"id":52385936},{"atb":[[65,0.82],[36,2.99],[90,0.29],[46,1.74]],"id":52385932}],"con":true,"img":false}]}
{"op":"mcm","clk":"11450006707","pt":1717317020878,"mc":[{"id":"1.229554897","rc":[{"atb":[[22,0]],"id":52385918},{"atb":[[16.5,0]],"id":52385920},{"atb":[[36,3.73],[40,3.67]],"id":52385934},{"atb":[[90,3.93],[100,3.68]],"id":52385936},{"atl":[[3.25,0]],"id":52385904}],"con":true,"img":false}]}
{"op":"mcm","clk":"11450006716","pt":1717317020976,"mc":[{"id":"1.229554897","rc":[{"atb":[[120,0]],"id":52385886},{"atb":[[200,0]],"id":52385888},{"atb":[[9.4,0]],"id":52385903},{"atb":[[220,0]],"id":52385931}],"con":true,"img":false}]}
{"op":"mcm","clk":"11450007021","pt":1717317023981,"mc":[{"id":"1.229554897","rc":[{"atb":[[100,3.89]],"id":52385886}],"con":true,"img":false}]}
{"op":"mcm","clk":"11450007234","pt":1717317026097,"mc":[{"id":"1.229554897","rc":[{"atb":[[9,0],[11,6.24]],"id":52385882},{"atl":[[360,2],[420,0]],"id":52385882},{"atb":[[10.5,7.6],[8.4,0]],"id":52385884},{"atl":[[320,2],[380,0]],"id":52385884}],"con":true,"img":false}]}
{"op":"mcm","clk":"11450007244","pt":1717317026202,"mc":[{"id":"1.229554897","rc":[{"atb":[[4.3,0],[5,15.89]],"id":52385909},{"atl":[[65,2],[75,0]],"id":52385909},{"atb":[[5.6,0],[6.8,7.92]],"id":52385918},{"atl":[[140,3.32],[120,4.8]],"id":52385918},{"atb":[[5.7,7.62],[4.7,0]],"id":52385920},{"atl":[[90,6.38],[110,0]],"id":52385920},{"atb":[[8.8,8.72],[7,0]],"id":52385889},{"atb":[[11.5,0],[14.5,7.26]],"id":52385917},{"atb":[[18.5,0],[23,4.55]],"id":52385923},{"atb":[[5,0],[6,8.02]],"id":52385893},{"atb":[[10,0],[12.5,5.8]],"id":52385934},{"atl":[[600,2],[860,0]],"id":52385934},{"atb":[[4.3,6.24],[3.75,0]],"id":52385903},{"atl":[[34,3.03],[40,0]],"id":52385903},{"atb":[[1.6,0],[1.85,45.11]],"id":52385904},{"atl":[[850,2],[870,2.93]],"id":52385932}],"con":true,"img":false}]}
{"op":"mcm","clk":"11450007254","pt":1717317026256,"mc":[{"id":"1.229554897","rc":[{"atl":[[130,2],[120,2.8]],"id":52385918}],"con":true,"img":false}]}
{"op":"mcm","clk":"11450007500","pt":1717317028895,"mc":[{"id":"1.229554897","rc":[{"atb":[[10.5,4.36]],"id":52385909},{"atl":[[55,3.9]],"id":52385909},{"atb":[[16.5,2.83]],"id":52385918},{"atb":[[13,12.47]],"id":52385920},{"atb":[[160,3.59]],"id":52385888},{"atl":[[65,4.01]],"id":52385889},{"atl":[[200,3.52]],"id":52385884},{"atb":[[42,3.45]],"id":52385917},{"atl":[[130,4.21]],"id":52385895},{"atb":[[55,3.12]],"id":52385923},{"atl":[[10.5,4.53]],"id":52385891},{"atl":[[36,4.44]],"id":52385893},{"atb":[[8.2,4.53]],"id":52385903},{"atl":[[25,2.81]],"id":52385903},{"atb":[[1.82,19.14]],"id":52385904},{"atl":[[3.85,5.5]],"id":52385904},{"atb":[[140,4.24]],"id":52385931},{"atb":[[46,4.47]],"id":52385932}],"con":true,"img":false}]}
{"op":"mcm","clk":"11450007767","pt":1717317031597,"mc":[{"id":"1.229554897","rc":[{"atb":[[170,0.61],[85,2.9]],"id":52385886},{"atb":[[550,0.44],[650,0.16]],"id":52385888},{"atb":[[13.5,8.36],[9.4,29.03]],"id":52385889},{"atb":[[16,6.96],[11,30.63]],"id":52385882},{"atb":[[9.2,29.74],[13,8.71]],"id":52385884},{"atb":[[16.5,15.73],[23,4.75]],"id":52385895},{"atb":[[2.28,190.55],[2.48,70.62]],"id":52385891},{"atb":[[9.6,12.15],[7.6,36.95]],"id":52385893},{"atb":[[7.8,15.37],[5.9,49.77]],"id":52385903},{"atb":[[1.82,146.62],[1.72,338.75]],"id":52385904}],"con":true,"img":false}]}
{"op":"mcm","clk":"11450007777","pt":1717317031700,"mc":[{"id":"1.229554897","rc":[{"atb":[[4.4,71.73],[5.4,23.75]],"id":52385907},{"atb":[[10,27.1],[15,7.46]],"id":52385909},{"atl":[[80,0]],"id":52385909},{"atb":[[9,30.48],[12.5,9.08]],"id":52385918},{"atb":[[7.2,39.33],[9.2,12.74]],"id":52385920},{"atl":[[120,0]],"id":52385889},{"atl":[[410,0]],"id":52385884},{"atb":[[160,0.65],[80,3.08]],"id":52385917},{"atl":[[280,0]],"id":52385895},{"atl":[[12,0]],"id":52385891},{"atb":[[550,0.44],[650,0.16]],"id":52385923},{"atl":[[44,0]],"id":52385893},{"atb":[[16,16.26],[22,4.97]],"id":52385934},{"atl":[[30,0]],"id":52385903},{"atb":[[1.56,0]],"id":52385904},{"atb":[[550,0.44],[650,0.16]],"id":52385936},{"atb":[[550,0.44],[650,0.16]],"id":52385931},{"atb":[[32,3.37],[21,12.19]],"id":52385932}],"con":true,"img":false}]}
{"op":"mcm","clk":"11450011797","pt":1717317072828,"mc":[{"id":"1.229554897","rc":[{"atb":[[40,2]],"id":52385936}],"con":true,"img":false}]}
{"op":"mcm","clk":"11450011809","pt":1717317072934,"mc":[{"id":"1.229554897","rc":[{"atb":[[30,0]],"id":52385936}],"con":true,"img":false}]}
{"op":"mcm","clk":"11450011849","pt":1717317073205,"mc":[{"id":"1.229554897","rc":[{"atb":[[110,5.5]],"id":52385936}],"con":true,"img":false}]}
{"op":"mcm","clk":"11450012279","pt":1717317077033,"mc":[{"id":"1.229554897","rc":[{"atb":[[18,0],[19,4.05]],"id":52385889},{"atb":[[34,0],[36,6.24]],"id":52385882},{"atb":[[26,0],[28,3.26]],"id":52385884},{"atb":[[2.68,9.34],[2.7,0]],"id":52385891},{"atb":[[1.84,0]],"id":52385904}],"con":true,"img":false}]}
{"op":"mcm","clk":"11450012304","pt":1717317077236,"mc":[{"id":"1.229554897","rc":[{"atb":[[2.72,0],[2.7,58.82]],"id":52385891},{"atb":[[1.83,120.48],[1.85,0]],"id":52385904}],"con":true,"img":false}]}
{"op":"mcm","clk":"11450012344","pt":1717317077549,"mc":[{"id":"1.229554897","rc":[{"atb":[[6,8.9]],"id":52385907},{"atl":[[10,5.01]],"id":52385907},{"atl":[[24,5.01]],"id":52385909},{"atb":[[18,5.01]],"id":52385918},{"atl":[[70,5.01]],"id":52385918},{"atb":[[100,8.91]],"id":52385886},{"atb":[[14.5,5.01]],"id":52385920},{"atl":[[50,5.01]],"id":52385920},{"atb":[[160,8.61]],"id":52385888},{"atb":[[22,5.01]],"id":52385889},{"atl":[[38,5.01]],"id":52385889},{"atb":[[34,5.01]],"id":52385882},{"atl":[[100,5.01]],"id":52385882},{"atb":[[34,5.01]],"id":52385884},{"atl":[[80,5.01]],"id":52385884},{"atb":[[50,5.01]],"id":52385917},{"atb":[[29,8.25]],"id":52385895},{"atl":[[70,5.01]],"id":52385895},{"atb":[[4.3,5.01]],"id":52385891},{"atl":[[9.6,5.01]],"id":52385891},{"atb":[[70,5.01]],"id":52385923},{"atb":[[15,5.01]],"id":52385893},{"atl":[[28,5.01]],"id":52385893},{"atb":[[38,7.14]],"id":52385934},{"atl":[[210,5.01]],"id":52385934},{"atb":[[8.6,7.76]],"id":52385903},{"atl":[[14,5.01]],"id":52385903},{"atb":[[2.72,5.01]],"id":52385904},{"atl":[[3.7,5.01]],"id":52385904},{"atb":[[160,9.71]],"id":52385931},{"atb":[[46,9.49]],"id":52385932}],"con":true,"img":false}]}
{"op":"mcm","clk":"11450012353","pt":1717317077601,"mc":[{"id":"1.229554897","rc":[{"atl":[[600,0],[390,2]],"id":52385934}],"con":true,"img":false}]}
{"op":"mcm","clk":"11450012370","pt":1717317077709,"mc":[{"id":"1.229554897","rc":[{"atl":[[18,0],[15,7.14]],"id":52385907},{"atl":[[130,0],[95,2]],"id":52385918},{"atl":[[900,2],[1000,0]],"id":52385886},{"atl":[[75,2],[90,4.38]],"id":52385920},{"atl":[[150,0],[100,2]],"id":52385889},{"atl":[[290,5.5],[360,0]],"id":52385882},{"atl":[[260,2],[320,0]],"id":52385884},{"atl":[[740,2],[810,0]],"id":52385917},{"atl":[[270,0],[220,2]],"id":52385895},{"atl":[[770,2],[850,0]],"id":52385932}],"con":true,"img":false}]}
{"op":"mcm","clk":"11450013024","pt":1717317084220,"mc":[{"id":"1.229554897","rc":[{"atb":[[3.45,10.04],[2.7,0]],"id":52385891},{"atb":[[1.83,0],[2.16,86.21]],"id":52385904}],"con":true,"img":false}]}
{"op":"mcm","clk":"11450013042","pt":1717317084518,"mc":[{"id":"1.229554897","rc":[{"atb":[[6,22.61]],"id":52385907},{"atl":[[10,18.71]],"id":52385907},{"atl":[[24,12]],"id":52385909},{"atb":[[18,14.46]],"id":52385918},{"atl":[[70,7.34]],"id":52385918},{"atl":[[890,0.18]],"id":52385886},{"atl":[[50,8.29]],"id":52385920},{"atl":[[1000,0.16]],"id":52385888},{"atl":[[100,6.63]],"id":52385882},{"atb":[[34,9.88]],"id":52385884},{"atl":[[80,7.05]],"id":52385884},{"atl":[[730,0.21]],"id":52385917},{"atb":[[4.3,20.13]],"id":52385891},{"atl":[[9.6,20.13]],"id":52385891},{"atl":[[990,0.16]],"id":52385923},{"atb":[[15,16.48]],"id":52385893},{"atl":[[28,10.96]],"id":52385893},{"atl":[[210,5.78]],"id":52385934},{"atb":[[8.6,22.15]],"id":52385903},{"atl":[[14,17.36]],"id":52385903},{"atb":[[2.72,21.91]],"id":52385904},{"atl":[[3.7,21.91]],"id":52385904},{"atl":[[760,0.2]],"id":52385932}],"con":true,"img":false}]}
{"op":"mcm","clk":"11450013053","pt":1717317084618,"mc":[{"id":"1.229554897","rc":[{"atl":[[310,2]],"id":52385934}],"con":true,"img":false}]}
{"op":"mcm","clk":"11450013068","pt":1717317084724,"mc":[{"id":"1.229554897","rc":[{"atl":[[390,0]],"id":52385934}],"con":true,"img":false}]}
{"op":"mcm","clk":"11450013341","pt":1717317087753,"mc":[{"id":"1.229554897","rc":[{"atb":[[18,2.71]],"id":52385889},{"atb":[[26,2.83]],"id":52385884},{"atb":[[1.8,19.61]],"id":52385904}],"con":true,"img":false}]}
{"op":"mcm","clk":"11450013590","pt":1717317090443,"mc":[{"id":"1.229554897","rc":[{"atb":[[17,0]],"id":52385889},{"atb":[[24,0]],"id":52385884}],"con":true,"img":false}]}
{"op":"mcm","clk":"11450013612","pt":1717317090646,"mc":[{"id":"1.229554897","rc":[{"atl":[[75,5.01]],"id":52385918}],"con":true,"img":false}]}
{"op":"mcm","clk":"11450013619","pt":1717317090749,"mc":[{"id":"1.229554897","rc":[{"atl":[[70,0]],"id":52385918}],"con":true,"img":false}]}
{"op":"mcm","clk":"11450013688","pt":1717317091420,"mc":[{"id":"1.229554897","rc":[{"atl":[[90,1.8]],"id":52385918}],"con":true,"img":false}]}
{"op":"mcm","clk":"11450014250","pt":1717317097653,"mc":[{"id":"1.229554897","rc":[{"atb":[[18.5,3.15],[19,0]],"id":52385889},{"atb":[[28,0],[29,4.18]],"id":52385884},{"atb":[[2.72,9.12],[2.68,0]],"id":52385891},{"atb":[[12.5,3.67]],"id":52385893},{"atb":[[1.82,127.47],[1.9,17.43]],"id":52385904}],"con":true,"img":false}]}
{"op":"mcm","clk":"11450014265","pt":1717317097756,"mc":[{"id":"1.229554897","rc":[{"atb":[[13,0]],"id":52385893}],"con":true,"img":false}]}
{"op":"mcm","clk":"11450014389","pt":1717317099052,"mc":[{"id":"1.229554897","rc":[{"atb":[[3.5,0],[3.75,36.36]],"id":52385907},{"atl":[[17,6.25],[15,0]],"id":52385907},{"atl":[[65,0],[34,3.03]],"id":52385909},{"atb":[[8.6,13.16],[6.8,0]],"id":52385918},{"atl":[[95,0],[120,4.8]],"id":52385918},{"atb":[[7.2,55.46],[5.7,0]],"id":52385920},{"atl":[[75,0],[95,2]],"id":52385920},{"atb":[[10.5,10.53],[8.8,0]],"id":52385889},{"atb":[[16.5,6.45],[11,24.39]],"id":52385882},{"atl":[[290,3.5],[350,2]],"id":52385882},{"atb":[[10.5,0],[14.5,7.41]],"id":52385884},{"atl":[[260,0],[330,2]],"id":52385884},{"atb":[[14.5,0],[29,3.57]],"id":52385917},{"atl":[[740,0],[810,2]],"id":52385917},{"atl":[[170,2],[220,0]],"id":52385895},{"atb":[[7.2,16.13],[6,0]],"id":52385893},{"atl":[[310,0],[210,7.78]],"id":52385934},{"atb":[[40,0]],"id":52385936},{"atl":[[670,2],[770,0]],"id":52385932}],"con":true,"img":false}]}
{"op":"mcm","clk":"11450014394","pt":1717317099149,"mc":[{"id":"1.229554897","rc":[{"atb":[[32,3.23]],"id":52385936}],"con":true,"img":false}]}
{"op":"mcm","clk":"11450014403","pt":1717317099255,"mc":[{"id":"1.229554897","rc":[{"atb":[[8.6,0]],"id":52385918},{"atb":[[7.2,39.33]],"id":52385920},{"atb":[[29,0]],"id":52385917},{"atb":[[18,5.88],[23,0]],"id":52385923},{"atb":[[4.3,0],[4.9,25.64]],"id":52385903}],"con":true,"img":false}]}
{"op":"mcm","clk":"11450014413","pt":1717317099363,"mc":[{"id":"1.229554897","rc":[{"atb":[[6.4,4.68],[6,18.71]],"id":52385907},{"atb":[[16.5,0],[9.6,0],[10.5,0],[11.5,0],[14,0]],"id":52385909},{"atb":[[17.5,0],[7.2,16.13],[22,3.8]],"id":52385918},{"atb":[[100,5.01],[120,2.98]],"id":52385886},{"atb":[[18,2.77],[21,0],[13,3.75],[14,0],[5.9,10.43],[15.5,0]],"id":52385920},{"atb":[[25,7.78]],"id":52385889},{"atl":[[38,0.42],[46,5.01]],"id":52385889},{"atb":[[65,0],[36,0],[38,3.51],[46,0],[28,0]],"id":52385882},{"atl":[[100,5.01]],"id":52385882},{"atl":[[80,2.03],[100,5.01]],"id":52385884},{"atb":[[75,3.34],[20,5.26],[46,0]],"id":52385917},{"atb":[[34,0],[44,0],[22,0],[26,4.37],[27,0],[30,0]],"id":52385895},{"atl":[[65,2.51]],"id":52385895},{"atb":[[65,0],[70,9]],"id":52385923},{"atl":[[10,3.16],[9.8,0]],"id":52385891},{"atl":[[32,0],[34,9.36],[28,5.94]],"id":52385893},{"atb":[[70,0],[38,0],[40,0],[48,0],[29,0],[30,4.49]],"id":52385934},{"atb":[[8.6,19.4],[9.4,4.67]],"id":52385903},{"atl":[[14,12.35],[15,5.01]],"id":52385903},{"atb":[[32,0],[160,0],[80,0],[90,0],[100,0],[110,0],[55,0]],"id":52385936},{"atl":[[3.5,6.27],[3.75,0]],"id":52385904},{"atb":[[150,3.13],[160,5.01]],"id":52385931},{"atb":[[65,0],[34,4.35],[36,0],[90,0],[46,2.72],[50,0]],"id":52385932}],"con":true,"img":false}]}
{"op":"mcm","clk":"11450014422","pt":1717317099461,"mc":[{"id":"1.229554897","rc":[{"atb":[[25,2]],"id":52385936}],"con":true,"img":false}]}
{"op":"mcm","clk":"11450014428","pt":1717317099564,"mc":[{"id":"1.229554897","rc":[{"atb":[[5.6,5.01],[5.5,2.64],[6,0]],"id":52385907},{"atb":[[180,0]],"id":52385888},{"atl":[[100,0],[120,5.01]],"id":52385882},{"atb":[[55,4.43]],"id":52385917},{"atb":[[28,4.16]],"id":52385895},{"atb":[[70,3.98],[50,3.37]],"id":52385923},{"atl":[[9.6,15.11],[10.5,9.54],[11,3.1]],"id":52385891},{"atb":[[32,3.98]],"id":52385934},{"atb":[[10,4.11]],"id":52385903},{"atl":[[3.8,5.6]],"id":52385904},{"atb":[[140,9.26],[160,0]],"id":52385931},{"atb":[[36,2.86]],"id":52385932}],"con":true,"img":false}]}
{"op":"mcm","clk":"11450014440","pt":1717317099668,"mc":[{"id":"1.229554897","rc":[{"atb":[[110,4.59]],"id":52385886},{"atb":[[170,2.97]],"id":52385888},{"atb":[[18.5,0],[19,3.39]],"id":52385889},{"atb":[[28,4.08],[29,0]],"id":52385884},{"atb":[[2.72,0],[2.68,9.34]],"id":52385891},{"atb":[[12.5,0],[13,4.13]],"id":52385893},{"atb":[[1.82,146.62],[1.9,0]],"id":52385904}],"con":true,"img":false}]}
{"op":"mcm","clk":"11450014445","pt":1717317099770,"mc":[{"id":"1.229554897","rc":[{"atb":[[9.6,5.01]],"id":52385909},{"atl":[[75,7.18]],"id":52385918},{"atb":[[40,4.11]],"id":52385882},{"atb":[[29,12.02]],"id":52385895},{"atb":[[55,8.14]],"id":52385923},{"atb":[[36,8.32],[30,9.51]],"id":52385934},{"atb":[[9.6,14.58],[9.8,3.55]],"id":52385903},{"atl":[[3.45,47.2]],"id":52385904},{"atb":[[75,5.01]],"id":52385936},{"atb":[[34,9.37]],"id":52385932},{"atl":[[660,0.24]],"id":52385932}],"con":true,"img":false}]}
{"op":"mcm","clk":"11450014473","pt":1717317100083,"mc":[{"id":"1.229554897","rc":[{"atb":[[11,5.23],[13.5,2.09],[8.4,14.14],[9.4,9.34]],"id":52385909},{"atl":[[50,5.01]],"id":52385889},{"atb":[[36,1.5],[23,9.51],[46,0.58],[28,7.08]],"id":52385895},{"atb":[[32,6.51],[42,1.28],[26,4.19],[55,0.49]],"id":52385934},{"atl":[[16.5,5.01]],"id":52385903},{"atb":[[80,0.66],[42,2.55],[110,0.24],[55,1.45]],"id":52385936},{"atb":[[36,3.31]],"id":52385932}],"con":true,"img":false}]}
{"op":"mcm","clk":"11450014481","pt":1717317100138,"mc":[{"id":"1.229554897","rc":[{"atb":[[6.4,0]],"id":52385907},{"atb":[[17.5,3.52]],"id":52385918},{"atb":[[120,0]],"id":52385886},{"atb":[[18,3.08],[21,1.31],[13,12.47],[15.5,5.41],[9.4,9.42]],"id":52385920},{"atl":[[46,0]],"id":52385889},{"atb":[[75,0.36],[40,6.13],[50,1.07],[30,7.09]],"id":52385882},{"atb":[[75,0]],"id":52385917},{"atb":[[29,8.79]],"id":52385895},{"atl":[[10,0]],"id":52385891},{"atl":[[32,3.47],[34,5.01]],"id":52385893},{"atb":[[36,4.58]],"id":52385934},{"atb":[[9.4,0]],"id":52385903},{"atl":[[15,0]],"id":52385903},{"atb":[[65,0.41],[36,5.56],[46,1.16],[28,3.88]],"id":52385932}],"con":true,"img":false}]}
{"op":"mcm","clk":"11450014492","pt":1717317100289,"mc":[{"id":"1.229554897","rc":[{"atb":[[22,0]],"id":52385918},{"atb":[[14,4.65]],"id":52385920},{"atl":[[120,6.36]],"id":52385882},{"atb":[[70,0]],"id":52385923},{"atl":[[3.5,0]],"id":52385904},{"atb":[[150,0]],"id":52385931}],"con":true,"img":false}]}
{"op":"mcm","clk":"11450014510","pt":1717317100443,"mc":[{"id":"1.229554897","rc":[{"atl":[[90,0]],"id":52385918},{"atb":[[8.6,5.01]],"id":52385903},{"atl":[[3.7,5.01]],"id":52385904},{"atl":[[760,0]],"id":52385932}],"con":true,"img":false}]}
{"op":"mcm","clk":"11450014517","pt":1717317100548,"mc":[{"id":"1.229554897","rc":[{"atb":[[5.9,0]],"id":52385907},{"atb":[[55,5.01]],"id":52385923},{"atl":[[10.5,5.01]],"id":52385891},{"atb":[[10,0]],"id":52385903},{"atl":[[3.85,0]],"id":52385904},{"atb":[[70,3.88],[60,3.51]],"id":52385936}],"con":true,"img":false}]}
{"op":"mcm","clk":"11450014536","pt":1717317100859,"mc":[{"id":"1.229554897","rc":[{"atb":[[5.6,16.65]],"id":52385907}],"con":true,"img":false}]}
{"op":"mcm","clk":"11450014551","pt":1717317101076,"mc":[{"id":"1.229554897","rc":[{"atl":[[120,5.01]],"id":52385882}],"con":true,"img":false}]}
{"op":"mcm","clk":"11450014625","pt":1717317101972,"mc":[{"id":"1.229554897","rc":[{"atb":[[18.5,3.85],[19,0]],"id":52385889},{"atb":[[28,0],[29,3.45]],"id":52385884},{"atb":[[2.72,9.12],[2.68,0]],"id":52385891},{"atb":[[12.5,4.39],[13,0]],"id":52385893},{"atb":[[1.82,127.47],[1.9,17.43]],"id":52385904}],"con":true,"img":false}]}
{"op":"mcm","clk":"11450014810","pt":1717317103974,"mc":[{"id":"1.229554897","rc":[{"atl":[[1000,2]],"id":52385936}],"con":true,"img":false}]}
{"op":"mcm","clk":"11450014829","pt":1717317104179,"mc":[{"id":"1.229554897","rc":[{"atb":[[3.4,41.67],[3.75,0]],"id":52385907},{"atl":[[210,5.78],[230,2]],"id":52385934},{"atl":[[670,0],[690,2]],"id":52385932}],"con":true,"img":false}]}
{"op":"mcm","clk":"11450014839","pt":1717317104285,"mc":[{"id":"1.229554897","rc":[{"atb":[[18.5,0],[19,4.65]],"id":52385889},{"atl":[[260,0],[250,4.58]],"id":52385882},{"atb":[[28,4.37],[29,0]],"id":52385884},{"atb":[[2.72,0],[2.68,9.34]],"id":52385891},{"atb":[[12.5,0],[13,3.14]],"id":52385893},{"atl":[[32,0],[34,8.36]],"id":52385893},{"atl":[[600,3.12],[610,0]],"id":52385934},{"atb":[[1.82,146.62],[1.9,0]],"id":52385904},{"atl":[[850,4.64],[870,0]],"id":52385932}],"con":true,"img":false}]}
{"op":"mcm","clk":"11450014979","pt":1717317105740,"mc":[{"id":"1.229554897","rc":[{"atl":[[17,0],[13,8.33]],"id":52385907},{"atl":[[95,2],[120,2.8]],"id":52385918},{"atl":[[70,2],[95,0]],"id":52385920}],"con":true,"img":false}]}
{"op":"mcm","clk":"11450015304","pt":1717317109661,"mc":[{"id":"1.229554897","rc":[{"atb":[[120,2.87]],"id":52385931}],"con":true,"img":false}]}
{"op":"mcm","clk":"11450015323","pt":1717317109874,"mc":[{"id":"1.229554897","rc":[{"atb":[[46,4.45]],"id":52385923}],"con":true,"img":false}]}
{"op":"mcm","clk":"11450015338","pt":1717317109971,"mc":[{"id":"1.229554897","rc":[{"atb":[[5.3,3.07]],"id":52385907},{"atb":[[48,2.71]],"id":52385917},{"atl":[[810,6.05],[820,0]],"id":52385917}],"con":true,"img":false}]}
{"op":"mcm","clk":"11450015345","pt":1717317110072,"mc":[{"id":"1.229554897","rc":[{"atb":[[9.4,4.45]],"id":52385903}],"con":true,"img":false}]}
{"op":"mcm","clk":"11450015745","pt":1717317114563,"mc":[{"id":"1.229554897","rc":[{"atb":[[34,8.19]],"id":52385882},{"atl":[[260,4.63],[250,0]],"id":52385882},{"atl":[[12,3.81]],"id":52385891},{"atl":[[3.9,5.4]],"id":52385904},{"atl":[[850,0],[860,2.96]],"id":52385932}],"con":true,"img":false}]}
{"op":"mcm","clk":"11450015753","pt":1717317114665,"mc":[{"id":"1.229554897","rc":[{"atb":[[9.8,17.82]],"id":52385903}],"con":true,"img":false}]}
{"op":"mcm","clk":"11450015810","pt":1717317115386,"mc":[{"id":"1.229554897","rc":[{"atb":[[9.6,0]],"id":52385903}],"con":true,"img":false}]}
{"op":"mcm","clk":"11450016293","pt":1717317120174,"mc":[{"id":"1.229554897","rc":[{"atb":[[42,0]],"id":52385917}],"con":true,"img":false}]}
{"op":"mcm","clk":"11450016316","pt":1717317120381,"mc":[{"id":"1.229554897","rc":[{"atb":[[8.2,0]],"id":52385903}],"con":true,"img":false}]}
{"op":"mcm","clk":"11450016574","pt":1717317122832,"mc":[{"id":"1.229554897","rc":[{"atb":[[4.4,0],[5.4,0]],"id":52385907},{"atb":[[10,0],[15,0]],"id":52385909},{"atb":[[9,0],[12.5,0]],"id":52385918},{"atb":[[170,0],[85,0]],"id":52385886},{"atb":[[7.2,0],[9.2,0]],"id":52385920},{"atb":[[550,0],[650,0]],"id":52385888},{"atb":[[13.5,0],[9.4,0]],"id":52385889},{"atb":[[16,0],[11,0]],"id":52385882},{"atb":[[9.2,0],[13,0]],"id":52385884},{"atb":[[160,0],[80,0]],"id":52385917},{"atb":[[16.5,0],[23,4.76]],"id":52385895},{"atb":[[2.28,0],[2.48,0]],"id":52385891},{"atb":[[550,0],[650,0]],"id":52385923},{"atb":[[9.6,0],[7.6,0]],"id":52385893},{"atb":[[16,0],[22,0]],"id":52385934},{"atb":[[7.8,0],[5.9,0]],"id":52385903},{"atb":[[1.82,19.14],[1.72,0]],"id":52385904},{"atb":[[550,0],[650,0]],"id":52385936},{"atb":[[550,0],[650,0]],"id":52385931},{"atb":[[32,0],[21,0]],"id":52385932}],"con":true,"img":false}]}
{"op":"mcm","clk":"11450016611","pt":1717317123200,"mc":[{"id":"1.229554897","rc":[{"atb":[[30,3.61]],"id":52385882}],"con":true,"img":false}]}
{"op":"mcm","clk":"11450016621","pt":1717317123296,"mc":[{"id":"1.229554897","rc":[{"atb":[[110,6.06]],"id":52385886},{"atb":[[180,0.89]],"id":52385888},{"atb":[[55,7.4]],"id":52385917},{"atb":[[55,7.98]],"id":52385923},{"atb":[[140,10.41]],"id":52385931}],"con":true,"img":false}]}
{"op":"mcm","clk":"11450017122","pt":1717317128029,"mc":[{"id":"1.229554897","rc":[{"atb":[[9.6,8.09],[10,3.64]],"id":52385909}],"con":true,"img":false}]}
{"op":"mcm","clk":"11450017182","pt":1717317128658,"mc":[{"id":"1.229554897","rc":[{"atb":[[100,0],[120,5.01]],"id":52385886},{"atb":[[18,9.44],[18.5,5.01]],"id":52385918},{"atb":[[22,0],[27,5.01]],"id":52385889},{"atb":[[34,3.17],[48,5.01]],"id":52385882},{"atb":[[34,4.86],[48,5.01]],"id":52385884},{"atb":[[65,5.01],[50,0]],"id":52385917},{"atl":[[70,0],[60,5.01]],"id":52385895},{"atb":[[15,11.46],[15.5,5.01]],"id":52385893},{"atb":[[8.6,0],[9.8,22.84]],"id":52385903}],"con":true,"img":false}]}
{"op":"mcm","clk":"11450017229","pt":1717317129122,"mc":[{"id":"1.229554897","rc":[{"atb":[[19,8.92]],"id":52385918},{"atb":[[27,11.19]],"id":52385889},{"atb":[[50,3.27]],"id":52385884},{"atb":[[16,10.7]],"id":52385893}],"con":true,"img":false}]}
{"op":"mcm","clk":"11450017258","pt":1717317129429,"mc":[{"id":"1.229554897","rc":[{"atl":[[34,3.34],[29,5.01]],"id":52385893}],"con":true,"img":false}]}
{"op":"mcm","clk":"11450017320","pt":1717317129946,"mc":[{"id":"1.229554897","rc":[{"atb":[[18,0]],"id":52385918},{"atb":[[25,1.09]],"id":52385889},{"atb":[[34,0]],"id":52385884},{"atb":[[15,0]],"id":52385893}],"con":true,"img":false}]}
{"op":"mcm","clk":"11450018088","pt":1717317137735,"mc":[{"id":"1.229554897","rc":[{"atb":[[65,7.52]],"id":52385917}],"con":true,"img":false}]}
{"op":"mcm","clk":"11450018094","pt":1717317137837,"mc":[{"id":"1.229554897","rc":[{"atb":[[120,6.36]],"id":52385886}],"con":true,"img":false}]}
{"op":"mcm","clk":"11450018166","pt":1717317138513,"mc":[{"id":"1.229554897","rc":[{"atb":[[110,4.59]],"id":52385886},{"atb":[[55,4.43]],"id":52385917}],"con":true,"img":false}]}
{"op":"mcm","clk":"11450018258","pt":1717317139445,"mc":[{"id":"1.229554897","rc":[{"atl":[[10,0],[10.5,5.01]],"id":52385907}],"con":true,"img":false}]}
{"op":"mcm","clk":"11450018348","pt":1717317140227,"mc":[{"id":"1.229554897","rc":[{"atl":[[12.5,12.19]],"id":52385907}],"con":true,"img":false}]}
{"op":"mcm","clk":"11450018694","pt":1717317143633,"mc":[{"id":"1.229554897","rc":[{"atl":[[13,0],[13.5,8]],"id":52385907},{"atl":[[70,0],[75,2]],"id":52385920}],"con":true,"img":false}]}
{"op":"mcm","clk":"11450018721","pt":1717317143942,"mc":[{"id":"1.229554897","rc":[{"atb":[[18,3.01]],"id":52385918}],"con":true,"img":false}]}
{"op":"mcm","clk":"11450018732","pt":1717317144045,"mc":[{"id":"1.229554897","rc":[{"atb":[[17.5,0]],"id":52385918}],"con":true,"img":false}]}
{"op":"mcm","clk":"11450019065","pt":1717317147832,"mc":[{"id":"1.229554897","rc":[{"atl":[[10,5.01],[10.5,0]],"id":52385907},{"atb":[[27,6.17],[28,5.01]],"id":52385889}],"con":true,"img":false}]}
{"op":"mcm","clk":"11450019104","pt":1717317148243,"mc":[{"id":"1.229554897","rc":[{"atb":[[28,10.96]],"id":52385889}],"con":true,"img":false}]}
{"op":"mcm","clk":"11450019181","pt":1717317149016,"mc":[{"id":"1.229554897","rc":[{"atb":[[27,0]],"id":52385889}],"con":true,"img":false}]}
{"op":"mcm","clk":"11450019194","pt":1717317149143,"mc":[{"id":"1.229554897","rc":[{"atb":[[48,0],[50,6.08]],"id":52385882},{"atb":[[4.3,15.11],[4.4,5.01]],"id":52385891},{"atb":[[32,2.53]],"id":52385934}],"con":true,"img":false}]}
{"op":"mcm","clk":"11450019231","pt":1717317149531,"mc":[{"id":"1.229554897","rc":[{"atb":[[4.4,27.69]],"id":52385891}],"con":true,"img":false}]}
{"op":"mcm","clk":"11450019265","pt":1717317149940,"mc":[{"id":"1.229554897","rc":[{"atl":[[13,8.33],[13.5,0]],"id":52385907},{"atl":[[70,2],[75,0]],"id":52385920}],"con":true,"img":false}]}
{"op":"mcm","clk":"11450019319","pt":1717317150354,"mc":[{"id":"1.229554897","rc":[{"atb":[[4.3,0]],"id":52385891}],"con":true,"img":false}]}
{"op":"mcm","clk":"11450019650","pt":1717317153865,"mc":[{"id":"1.229554897","rc":[{"atb":[[18.5,3.98],[19,0]],"id":52385889},{"atb":[[28,0],[29,3.52]],"id":52385884},{"atb":[[2.72,9.12]],"id":52385891},{"atb":[[12.5,3.52],[13,0]],"id":52385893},{"atb":[[1.82,0],[1.9,17.43]],"id":52385904}],"con":true,"img":false}]}
{"op":"mcm","clk":"11450019660","pt":1717317153923,"mc":[{"id":"1.229554897","rc":[{"atb":[[2.68,0]],"id":52385891}],"con":true,"img":false}]}
{"op":"mcm","clk":"11450019680","pt":1717317154127,"mc":[{"id":"1.229554897","rc":[{"atl":[[300,5.01]],"id":52385932}],"con":true,"img":false}]}
{"op":"mcm","clk":"11450019694","pt":1717317154230,"mc":[{"id":"1.229554897","rc":[{"atl":[[38,0]],"id":52385889},{"atl":[[290,2]],"id":52385932}],"con":true,"img":false}]}
{"op":"mcm","clk":"11450019702","pt":1717317154332,"mc":[{"id":"1.229554897","rc":[{"atl":[[690,0]],"id":52385932}],"con":true,"img":false}]}
{"op":"mcm","clk":"11450019713","pt":1717317154438,"mc":[{"id":"1.229554897","rc":[{"atl":[[10,22.85]],"id":52385907},{"atl":[[140,2],[100,0]],"id":52385889}],"con":true,"img":false}]}
{"op":"mcm","clk":"11450019730","pt":1717317154641,"mc":[{"id":"1.229554897","rc":[{"atl":[[300,5.55]],"id":52385932}],"con":true,"img":false}]}
{"op":"mcm","clk":"11450019772","pt":1717317155055,"mc":[{"id":"1.229554897","rc":[{"atl":[[50,8.29]],"id":52385889}],"con":true,"img":false}]}
{"op":"mcm","clk":"11450019797","pt":1717317155262,"mc":[{"id":"1.229554897","rc":[{"atl":[[12.5,0]],"id":52385907}],"con":true,"img":false}]}
{"op":"mcm","clk":"11450019820","pt":1717317155468,"mc":[{"id":"1.229554897","rc":[{"atl":[[660,0]],"id":52385932}],"con":true,"img":false}]}
{"op":"mcm","clk":"11450019857","pt":1717317155833,"mc":[{"id":"1.229554897","rc":[{"atb":[[18.5,0],[19,3.28]],"id":52385889},{"atb":[[28,4.22],[29,0]],"id":52385884},{"atb":[[2.72,0],[2.68,9.34]],"id":52385891},{"atb":[[12.5,0],[13,3.31]],"id":52385893},{"atb":[[1.82,19.14],[1.9,0]],"id":52385904}],"con":true,"img":false}]}
{"op":"mcm","clk":"11450020045","pt":1717317157642,"mc":[{"id":"1.229554897","rc":[{"atb":[[4.4,71.73],[5.4,23.75]],"id":52385907},{"atb":[[10,30.74],[15,7.46]],"id":52385909},{"atb":[[9,30.48],[12.5,9.08]],"id":52385918},{"atb":[[170,0.61],[85,2.9]],"id":52385886},{"atb":[[7.2,39.33],[9.2,12.74]],"id":52385920},{"atb":[[550,0.44],[650,0.16]],"id":52385888},{"atb":[[13.5,8.36],[9.4,29.03]],"id":52385889},{"atb":[[16,6.96],[11,24.39]],"id":52385882},{"atb":[[9.2,29.74],[13,8.71]],"id":52385884},{"atb":[[160,0.65],[80,3.08]],"id":52385917},{"atb":[[16.5,15.73],[23,9.51]],"id":52385895},{"atb":[[2.28,190.55],[2.48,70.62]],"id":52385891},{"atb":[[550,0.44],[650,0.16]],"id":52385923},{"atb":[[9.6,12.15],[7.6,36.95]],"id":52385893},{"atb":[[16,16.26],[22,4.97]],"id":52385934},{"atb":[[7.8,15.37],[5.9,49.77]],"id":52385903},{"atb":[[1.82,146.62],[1.72,338.75]],"id":52385904},{"atb":[[550,0.44],[650,0.16]],"id":52385936},{"atb":[[550,0.44],[650,0.16]],"id":52385931},{"atb":[[32,3.37],[21,12.19]],"id":52385932}],"con":true,"img":false}]}
{"op":"mcm","clk":"11450020067","pt":1717317157849,"mc":[{"id":"1.229554897","rc":[{"atl":[[12.5,8.7],[13,0]],"id":52385907},{"atl":[[90,2],[95,0]],"id":52385918},{"atl":[[770,2],[810,4.05]],"id":52385917},{"atl":[[220,2],[230,0]],"id":52385934}],"con":true,"img":false}]}
{"op":"mcm","clk":"11450020103","pt":1717317158158,"mc":[{"id":"1.229554897","rc":[{"atb":[[2.72,9.12]],"id":52385891},{"atb":[[12.5,3.99]],"id":52385893},{"atb":[[1.82,127.47]],"id":52385904}],"con":true,"img":false}]}
