{"op":"mcm","clk":"11448351864","pt":1717289088271,"mc":[{"id":"1.229554899","marketDefinition":{"bspMarket":false,"turnInPlayEnabled":false,"persistenceEnabled":false,"marketBaseRate":7.0,"eventId":"33318908","eventTypeId":"4339","numberOfWinners":1,"bettingType":"ODDS","marketType":"MATCH_BET","marketTime":"2024-06-02T08:41:00.000Z","suspendTime":"2024-06-02T08:41:00.000Z","bspReconciled":false,"complete":true,"inPlay":false,"crossMatching":true,"runnersVoidable":false,"numberOfActiveRunners":2,"betDelay":0,"status":"OPEN","runners":[{"status":"ACTIVE","sortPriority":1,"id":65732558,"name":"2. All The Sass"},{"status":"ACTIVE","sortPriority":2,"id":63161712,"name":"4. Dirty Dash"}],"regulators":["MR_INT"],"venue":"Murray Bridge","countryCode":"AU","discountAllowed":true,"timezone":"Australia/Adelaide","openDate":"2024-06-02T08:21:00.000Z","version":5962433800,"name":"All The Sass v Dirty Dash","eventName":"Murray Bridge (AUS) 2nd Jun"},"rc":[],"con":true,"img":false}]}
{"op":"mcm","clk":"11448366403","pt":1717289278043,"mc":[{"id":"1.229554899","rc":[{"atb":[[1.58,13.52],[1.48,16.34]],"id":63161712},{"atb":[[2,7.84],[2.2,6.53]],"id":65732558}],"con":true,"img":false}]}
{"op":"mcm","clk":"11448470639","pt":1717290837881,"mc":[{"id":"1.229554899","rc":[{"atb":[[1.58,0],[1.48,0]],"id":63161712},{"atb":[[2,0],[2.2,0]],"id":65732558}],"con":true,"img":false}]}
{"op":"mcm","clk":"11448471003","pt":1717290844005,"mc":[{"id":"1.229554899","rc":[{"atb":[[1.58,13.52],[1.48,16.34]],"id":63161712},{"atb":[[2,7.84],[2.2,6.53]],"id":65732558}],"con":true,"img":false}]}
{"op":"mcm","clk":"11448472535","pt":1717290873858,"mc":[{"id":"1.229554899","rc":[{"atb":[[1.58,0],[1.48,0]],"id":63161712},{"atb":[[2,0],[2.2,0]],"id":65732558}],"con":true,"img":false}]}
{"op":"mcm","clk":"11448472839","pt":1717290879454,"mc":[{"id":"1.229554899","rc":[{"atb":[[1.58,13.52],[1.48,16.34]],"id":63161712},{"atb":[[2,7.84],[2.2,6.53]],"id":65732558}],"con":true,"img":false}]}
{"op":"mcm","clk":"11448473355","pt":1717290888050,"mc":[{"id":"1.229554899","rc":[{"atb":[[1.58,0],[1.48,0]],"id":63161712},{"atb":[[2,0],[2.2,0]],"id":65732558}],"con":true,"img":false}]}
{"op":"mcm","clk":"11448473596","pt":1717290892695,"mc":[{"id":"1.229554899","rc":[{"atb":[[1.58,13.52],[1.48,16.34]],"id":63161712},{"atb":[[2,7.84],[2.2,6.53]],"id":65732558}],"con":true,"img":false}]}
{"op":"mcm","clk":"11448476918","pt":1717290945627,"mc":[{"id":"1.229554899","rc":[{"atb":[[1.58,0],[1.48,0]],"id":63161712},{"atb":[[2,0],[2.2,0]],"id":65732558}],"con":true,"img":false}]}
{"op":"mcm","clk":"11448477487","pt":1717290954750,"mc":[{"id":"1.229554899","rc":[{"atb":[[1.58,13.52],[1.48,16.34]],"id":63161712},{"atb":[[2,7.84],[2.2,6.53]],"id":65732558}],"con":true,"img":false}]}
{"op":"mcm","clk":"11448951114","pt":1717300633743,"mc":[{"id":"1.229554899","rc":[{"atb":[[1.03,5.73]],"id":63161712},{"atl":[[1000,0.85]],"id":63161712},{"atb":[[1.02,8.59]],"id":65732558},{"atl":[[1000,0.85]],"id":65732558}],"con":true,"img":false}]}
{"op":"mcm","clk":"11448953481","pt":1717300705899,"mc":[{"id":"1.229554899","rc":[{"atb":[[1.58,0],[1.48,0]],"id":63161712},{"atb":[[2,0],[2.2,0]],"id":65732558}],"con":true,"img":false}]}
{"op":"mcm","clk":"11448954486","pt":1717300734211,"mc":[{"id":"1.229554899","rc":[{"atb":[[1.56,14.01],[1.46,17.06]],"id":63161712},{"atb":[[2.24,6.33],[2.04,7.54]],"id":65732558}],"con":true,"img":false}]}
{"op":"mcm","clk":"11448957702","pt":1717300805016,"mc":[{"id":"1.229554899","rc":[{"atb":[[1.56,0],[1.46,0]],"id":63161712},{"atb":[[2.24,0],[2.04,0]],"id":65732558}],"con":true,"img":false}]}
{"op":"mcm","clk":"11448958449","pt":1717300819077,"mc":[{"id":"1.229554899","rc":[{"atb":[[1.45,17.43],[1.55,14.26]],"id":63161712},{"atb":[[2.28,6.13],[2.08,7.26]],"id":65732558}],"con":true,"img":false}]}
{"op":"mcm","clk":"11448963905","pt":1717300914322,"mc":[{"id":"1.229554899","rc":[{"atb":[[1.45,0],[1.55,0]],"id":63161712},{"atb":[[2.28,0],[2.08,0]],"id":65732558}],"con":true,"img":false}]}
{"op":"mcm","clk":"11448965590","pt":1717300946049,"mc":[{"id":"1.229554899","rc":[{"atb":[[1.44,17.83],[1.54,14.53]],"id":63161712},{"atb":[[2.3,6.03],[2.1,7.13]],"id":65732558}],"con":true,"img":false}]}
{"op":"mcm","clk":"11449308160","pt":1717306957906,"mc":[{"id":"1.229554899","rc":[{"atb":[[1.44,0],[1.54,0]],"id":63161712},{"atb":[[2.3,0],[2.1,0]],"id":65732558}],"con":true,"img":false}]}
{"op":"mcm","clk":"11449308938","pt":1717306969019,"mc":[{"id":"1.229554899","rc":[{"atb":[[1.44,17.83],[1.54,14.53]],"id":63161712},{"atb":[[2.3,6.03],[2.1,7.13]],"id":65732558}],"con":true,"img":false}]}
{"op":"mcm","clk":"11449319014","pt":1717307115947,"mc":[{"id":"1.229554899","rc":[{"atb":[[1.44,0],[1.54,0]],"id":63161712},{"atb":[[2.3,0],[2.1,0]],"id":65732558}],"con":true,"img":false}]}
{"op":"mcm","clk":"11449319872","pt":1717307127037,"mc":[{"id":"1.229554899","rc":[{"atb":[[1.45,17.43],[1.55,14.26]],"id":63161712},{"atb":[[2.28,6.13],[2.08,7.26]],"id":65732558}],"con":true,"img":false}]}
{"op":"mcm","clk":"11449321804","pt":1717307154576,"mc":[{"id":"1.229554899","rc":[{"atb":[[1.45,0],[1.55,0]],"id":63161712},{"atb":[[2.28,0],[2.08,0]],"id":65732558}],"con":true,"img":false}]}
{"op":"mcm","clk":"11449322426","pt":1717307163106,"mc":[{"id":"1.229554899","rc":[{"atb":[[1.45,17.43],[1.55,14.26]],"id":63161712},{"atb":[[2.28,6.13],[2.08,7.26]],"id":65732558}],"con":true,"img":false}]}
{"op":"mcm","clk":"11449459031","pt":1717309460000,"mc":[{"id":"1.229554899","rc":[{"atb":[[1.45,0],[1.55,0]],"id":63161712},{"atb":[[2.28,0],[2.08,0]],"id":65732558}],"con":true,"img":false}]}
{"op":"mcm","clk":"11449460685","pt":1717309485524,"mc":[{"id":"1.229554899","rc":[{"atb":[[1.45,17.43],[1.55,14.26]],"id":63161712},{"atb":[[2.28,6.13],[2.08,7.26]],"id":65732558}],"con":true,"img":false}]}
{"op":"mcm","clk":"11449586273","pt":1717311435187,"mc":[{"id":"1.229554899","rc":[{"atl":[[1000,0.17]],"id":63161712},{"atl":[[1000,0.17]],"id":65732558}],"con":true,"img":false}]}
{"op":"mcm","clk":"11449733443","pt":1717314060376,"mc":[{"id":"1.229554899","rc":[{"atb":[[1.05,31.71]],"id":63161712},{"atl":[[2.22,2]],"id":63161712},{"atl":[[75,2]],"id":65732558}],"con":true,"img":false}]}
{"op":"mcm","clk":"11449733462","pt":1717314060530,"mc":[{"id":"1.229554899","rc":[{"atl":[[2.06,14.15],[2.18,25.42],[2.1,18.18],[2.14,21.93]],"id":63161712},{"atl":[[8.2,4.17],[7.4,3.12],[7,2.5],[7.8,3.68]],"id":65732558}],"con":true,"img":false}]}
{"op":"mcm","clk":"11449733471","pt":1717314060638,"mc":[{"id":"1.229554899","rc":[{"atl":[[75,0],[12.5,2]],"id":65732558}],"con":true,"img":false}]}
{"op":"mcm","clk":"11449736805","pt":1717314097490,"mc":[{"id":"1.229554899","rc":[{"atl":[[2.14,54.26]],"id":63161712}],"con":true,"img":false}]}
{"op":"mcm","clk":"11449736813","pt":1717314097595,"mc":[{"id":"1.229554899","rc":[{"atl":[[2.22,0]],"id":63161712}],"con":true,"img":false}]}
{"op":"mcm","clk":"11449737413","pt":1717314104427,"mc":[{"id":"1.229554899","rc":[{"atl":[[7.2,2.42],[7,0]],"id":65732558}],"con":true,"img":false}]}
{"op":"mcm","clk":"11449738482","pt":1717314116134,"mc":[{"id":"1.229554899","rc":[{"atl":[[2.06,0],[2.04,14.42]],"id":63161712}],"con":true,"img":false}]}
{"op":"mcm","clk":"11449739666","pt":1717314128524,"mc":[{"id":"1.229554899","rc":[{"atl":[[7.2,0],[7,2.5]],"id":65732558}],"con":true,"img":false}]}
{"op":"mcm","clk":"11449740208","pt":1717314134264,"mc":[{"id":"1.229554899","rc":[{"atl":[[2.1,47.02],[2.14,21.93]],"id":63161712}],"con":true,"img":false}]}
{"op":"mcm","clk":"11449740216","pt":1717314134364,"mc":[{"id":"1.229554899","rc":[{"atl":[[2.14,83.37]],"id":63161712}],"con":true,"img":false}]}
{"op":"mcm","clk":"11449740225","pt":1717314134420,"mc":[{"id":"1.229554899","rc":[{"atl":[[2.1,18.18]],"id":63161712}],"con":true,"img":false}]}
{"op":"mcm","clk":"11449740650","pt":1717314139276,"mc":[{"id":"1.229554899","rc":[{"atl":[[2.06,14.15],[2.04,0]],"id":63161712}],"con":true,"img":false}]}
{"op":"mcm","clk":"11449740660","pt":1717314139384,"mc":[{"id":"1.229554899","rc":[{"atl":[[2.1,47.02],[2.14,21.93]],"id":63161712}],"con":true,"img":false}]}
{"op":"mcm","clk":"11449741124","pt":1717314144551,"mc":[{"id":"1.229554899","rc":[{"atl":[[2.1,18.18],[2.14,83.1]],"id":63161712}],"con":true,"img":false}]}
{"op":"mcm","clk":"11449741840","pt":1717314153703,"mc":[{"id":"1.229554899","rc":[{"atl":[[2.06,0],[2.04,14.42]],"id":63161712}],"con":true,"img":false}]}
{"op":"mcm","clk":"11449742187","pt":1717314158068,"mc":[{"id":"1.229554899","rc":[{"atl":[[2.06,14.15]],"id":63161712}],"con":true,"img":false}]}
{"op":"mcm","clk":"11449742196","pt":1717314158173,"mc":[{"id":"1.229554899","rc":[{"atl":[[2.04,0]],"id":63161712}],"con":true,"img":false}]}
{"op":"mcm","clk":"11449742787","pt":1717314165378,"mc":[{"id":"1.229554899","rc":[{"atl":[[2.06,0],[2.04,14.42]],"id":63161712}],"con":true,"img":false}]}
{"op":"mcm","clk":"11449744202","pt":1717314180831,"mc":[{"id":"1.229554899","rc":[{"atl":[[2.1,47.02]],"id":63161712}],"con":true,"img":false}]}
{"op":"mcm","clk":"11449744213","pt":1717314180887,"mc":[{"id":"1.229554899","rc":[{"atl":[[2.14,21.93]],"id":63161712}],"con":true,"img":false}]}
{"op":"mcm","clk":"11449744224","pt":1717314180993,"mc":[{"id":"1.229554899","rc":[{"atl":[[2.1,18.18],[2.14,83.37]],"id":63161712}],"con":true,"img":false}]}
{"op":"mcm","clk":"11449750535","pt":1717314248801,"mc":[{"id":"1.229554899","rc":[{"atl":[[2.06,14.15],[2.04,0]],"id":63161712}],"con":true,"img":false}]}
{"op":"mcm","clk":"11449750546","pt":1717314248907,"mc":[{"id":"1.229554899","rc":[{"atl":[[2.1,47.02],[2.14,21.93]],"id":63161712}],"con":true,"img":false}]}
{"op":"mcm","clk":"11449751088","pt":1717314253999,"mc":[{"id":"1.229554899","rc":[{"atl":[[2.14,83.1]],"id":63161712}],"con":true,"img":false}]}
{"op":"mcm","clk":"11449751099","pt":1717314254105,"mc":[{"id":"1.229554899","rc":[{"atl":[[2.1,18.18]],"id":63161712}],"con":true,"img":false}]}
{"op":"mcm","clk":"11449778015","pt":1717314556083,"mc":[{"id":"1.229554899","rc":[{"atl":[[2.06,0],[2.04,14.42]],"id":63161712}],"con":true,"img":false}]}
{"op":"mcm","clk":"11449778025","pt":1717314556187,"mc":[{"id":"1.229554899","rc":[{"atl":[[2.1,46.48],[2.14,21.93]],"id":63161712}],"con":true,"img":false}]}
{"op":"mcm","clk":"11449778482","pt":1717314561319,"mc":[{"id":"1.229554899","rc":[{"atl":[[2.14,82.83]],"id":63161712}],"con":true,"img":false}]}
{"op":"mcm","clk":"11449778490","pt":1717314561419,"mc":[{"id":"1.229554899","rc":[{"atl":[[2.1,18.18]],"id":63161712}],"con":true,"img":false}]}
{"op":"mcm","clk":"11449779760","pt":1717314575624,"mc":[{"id":"1.229554899","rc":[{"atl":[[2.06,14.15]],"id":63161712}],"con":true,"img":false}]}
{"op":"mcm","clk":"11449779766","pt":1717314575727,"mc":[{"id":"1.229554899","rc":[{"atl":[[2.04,0]],"id":63161712}],"con":true,"img":false}]}
{"op":"mcm","clk":"11449808519","pt":1717314915275,"mc":[{"id":"1.229554899","rc":[{"atl":[[2.06,0],[2.04,14.42]],"id":63161712}],"con":true,"img":false}]}
{"op":"mcm","clk":"11449808530","pt":1717314915378,"mc":[{"id":"1.229554899","rc":[{"atl":[[2.1,46.48]],"id":63161712}],"con":true,"img":false}]}
{"op":"mcm","clk":"11449808541","pt":1717314915480,"mc":[{"id":"1.229554899","rc":[{"atl":[[2.14,21.93]],"id":63161712}],"con":true,"img":false}]}
{"op":"mcm","clk":"11449808554","pt":1717314915583,"mc":[{"id":"1.229554899","rc":[{"atl":[[2.1,18.18],[2.14,82.83]],"id":63161712}],"con":true,"img":false}]}
{"op":"mcm","clk":"11449810846","pt":1717314941029,"mc":[{"id":"1.229554899","rc":[{"atl":[[2.06,14.15],[2.04,0]],"id":63161712}],"con":true,"img":false}]}
{"op":"mcm","clk":"11449811104","pt":1717314944117,"mc":[{"id":"1.229554899","rc":[{"atl":[[2.1,46.48]],"id":63161712}],"con":true,"img":false}]}
{"op":"mcm","clk":"11449811115","pt":1717314944220,"mc":[{"id":"1.229554899","rc":[{"atl":[[2.14,21.93]],"id":63161712}],"con":true,"img":false}]}
{"op":"mcm","clk":"11449811532","pt":1717314949217,"mc":[{"id":"1.229554899","rc":[{"atl":[[2.14,82.56]],"id":63161712}],"con":true,"img":false}]}
{"op":"mcm","clk":"11449811545","pt":1717314949320,"mc":[{"id":"1.229554899","rc":[{"atl":[[2.1,18.18]],"id":63161712}],"con":true,"img":false}]}
{"op":"mcm","clk":"11449866498","pt":1717315447076,"mc":[{"id":"1.229554899","rc":[{"atl":[[7.2,2.42],[7,0]],"id":65732558}],"con":true,"img":false}]}
{"op":"mcm","clk":"11449866506","pt":1717315447130,"mc":[{"id":"1.229554899","rc":[{"atl":[[2.12,32.33],[2.14,21.93]],"id":63161712}],"con":true,"img":false}]}
{"op":"mcm","clk":"11449866641","pt":1717315448473,"mc":[{"id":"1.229554899","rc":[{"atl":[[7,2.5]],"id":65732558}],"con":true,"img":false}]}
{"op":"mcm","clk":"11449866654","pt":1717315448526,"mc":[{"id":"1.229554899","rc":[{"atl":[[7.2,0]],"id":65732558}],"con":true,"img":false}]}
{"op":"mcm","clk":"11449868969","pt":1717315470582,"mc":[{"id":"1.229554899","rc":[{"atl":[[2.04,14.42]],"id":63161712}],"con":true,"img":false}]}
{"op":"mcm","clk":"11449868979","pt":1717315470684,"mc":[{"id":"1.229554899","rc":[{"atl":[[2.02,14.42],[2.06,0],[2.12,0]],"id":63161712}],"con":true,"img":false}]}
{"op":"mcm","clk":"11449868994","pt":1717315470791,"mc":[{"id":"1.229554899","rc":[{"atl":[[2.02,0],[2.06,28.84]],"id":63161712}],"con":true,"img":false}]}
{"op":"mcm","clk":"11449878930","pt":1717315568693,"mc":[{"id":"1.229554899","rc":[{"atl":[[2.06,42.99],[2.04,0]],"id":63161712}],"con":true,"img":false}]}
{"op":"mcm","clk":"11449878940","pt":1717315568792,"mc":[{"id":"1.229554899","rc":[{"atl":[[2.06,14.15],[2.14,83.1]],"id":63161712}],"con":true,"img":false}]}
{"op":"mcm","clk":"11449893637","pt":1717315712464,"mc":[{"id":"1.229554899","rc":[{"atl":[[2.06,0],[2.04,14.42]],"id":63161712}],"con":true,"img":false}]}
{"op":"mcm","clk":"11449893648","pt":1717315712569,"mc":[{"id":"1.229554899","rc":[{"atl":[[2.1,46.48],[2.14,21.93]],"id":63161712}],"con":true,"img":false}]}
{"op":"mcm","clk":"11449894199","pt":1717315717726,"mc":[{"id":"1.229554899","rc":[{"atl":[[2.1,18.18],[2.14,82.83]],"id":63161712}],"con":true,"img":false}]}
{"op":"mcm","clk":"11449896911","pt":1717315743088,"mc":[{"id":"1.229554899","rc":[{"atl":[[2.06,14.15],[2.04,0]],"id":63161712}],"con":true,"img":false}]}
{"op":"mcm","clk":"11449896925","pt":1717315743190,"mc":[{"id":"1.229554899","rc":[{"atl":[[2.04,18.18],[2.14,21.93]],"id":63161712}],"con":true,"img":false}]}
{"op":"mcm","clk":"11449896937","pt":1717315743247,"mc":[{"id":"1.229554899","rc":[{"atl":[[2.04,0],[2.1,46.48]],"id":63161712}],"con":true,"img":false}]}
{"op":"mcm","clk":"11449896952","pt":1717315743350,"mc":[{"id":"1.229554899","rc":[{"atl":[[2.14,82.56]],"id":63161712}],"con":true,"img":false}]}
{"op":"mcm","clk":"11449896963","pt":1717315743454,"mc":[{"id":"1.229554899","rc":[{"atl":[[2.1,18.18]],"id":63161712}],"con":true,"img":false}]}
{"op":"mcm","clk":"11449934867","pt":1717316116788,"mc":[{"id":"1.229554899","rc":[{"atl":[[2.12,32.33],[2.14,21.93]],"id":63161712},{"atl":[[7.2,2.42],[7,0]],"id":65732558}],"con":true,"img":false}]}
{"op":"mcm","clk":"11449952403","pt":1717316311128,"mc":[{"id":"1.229554899","rc":[{"atb":[[1.15,13.4]],"id":65732558},{"atl":[[7.2,0],[5.8,3.12],[12.5,0],[8.8,6.8]],"id":65732558}],"con":true,"img":false}]}
{"op":"mcm","clk":"11449952422","pt":1717316311347,"mc":[{"id":"1.229554899","rc":[{"atl":[[2.06,0],[2.1,13.64]],"id":63161712}],"con":true,"img":false}]}
{"op":"mcm","clk":"11449953270","pt":1717316321146,"mc":[{"id":"1.229554899","rc":[{"atl":[[6,4]],"id":65732558}],"con":true,"img":false}]}
{"op":"mcm","clk":"11449953286","pt":1717316321346,"mc":[{"id":"1.229554899","rc":[{"atl":[[2.14,17.54]],"id":63161712}],"con":true,"img":false}]}
{"op":"mcm","clk":"11449953296","pt":1717316321449,"mc":[{"id":"1.229554899","rc":[{"atl":[[2.12,0],[2.14,63.51]],"id":63161712}],"con":true,"img":false}]}
{"op":"mcm","clk":"11449953305","pt":1717316321551,"mc":[{"id":"1.229554899","rc":[{"atl":[[2.18,102.57],[2.14,17.54]],"id":63161712}],"con":true,"img":false}]}
{"op":"mcm","clk":"11449953643","pt":1717316325287,"mc":[{"id":"1.229554899","rc":[{"atl":[[8.2,0],[7.4,0],[7.8,0]],"id":65732558}],"con":true,"img":false}]}
{"op":"mcm","clk":"11449954125","pt":1717316331180,"mc":[{"id":"1.229554899","rc":[{"atl":[[6.4,4.63]],"id":65732558}],"con":true,"img":false}]}
{"op":"mcm","clk":"11449954142","pt":1717316331378,"mc":[{"id":"1.229554899","rc":[{"atl":[[2.18,98.34]],"id":63161712}],"con":true,"img":false}]}
{"op":"mcm","clk":"11449954903","pt":1717316341183,"mc":[{"id":"1.229554899","rc":[{"atl":[[6.8,5.17]],"id":65732558}],"con":true,"img":false}]}
{"op":"mcm","clk":"11449954920","pt":1717316341378,"mc":[{"id":"1.229554899","rc":[{"atl":[[2.22,24.59]],"id":63161712}],"con":true,"img":false}]}
{"op":"mcm","clk":"11449957297","pt":1717316372848,"mc":[{"id":"1.229554899","rc":[{"atl":[[5.9,3.06]],"id":65732558}],"con":true,"img":false}]}
{"op":"mcm","clk":"11449957305","pt":1717316372950,"mc":[{"id":"1.229554899","rc":[{"atl":[[5.8,0]],"id":65732558}],"con":true,"img":false}]}
{"op":"mcm","clk":"11449957323","pt":1717316373153,"mc":[{"id":"1.229554899","rc":[{"atl":[[6.4,0],[6,0],[6.8,0]],"id":65732558}],"con":true,"img":false}]}
{"op":"mcm","clk":"11449957331","pt":1717316373255,"mc":[{"id":"1.229554899","rc":[{"atl":[[40,2.56]],"id":65732558}],"con":true,"img":false}]}
{"op":"mcm","clk":"11449957340","pt":1717316373360,"mc":[{"id":"1.229554899","rc":[{"atl":[[8.8,0]],"id":65732558}],"con":true,"img":false}]}
{"op":"mcm","clk":"11449958030","pt":1717316382863,"mc":[{"id":"1.229554899","rc":[{"atl":[[6.2,3.85]],"id":65732558}],"con":true,"img":false}]}
{"op":"mcm","clk":"11449958762","pt":1717316392882,"mc":[{"id":"1.229554899","rc":[{"atl":[[6.6,4.46]],"id":65732558}],"con":true,"img":false}]}
{"op":"mcm","clk":"11449958771","pt":1717316392989,"mc":[{"id":"1.229554899","rc":[{"atl":[[9,6.91],[40,0]],"id":65732558}],"con":true,"img":false}]}
{"op":"mcm","clk":"11449959589","pt":1717316402917,"mc":[{"id":"1.229554899","rc":[{"atl":[[7,5]],"id":65732558}],"con":true,"img":false}]}
{"op":"mcm","clk":"11449960802","pt":1717316417329,"mc":[{"id":"1.229554899","rc":[{"atl":[[5.8,3.12],[5.9,0]],"id":65732558}],"con":true,"img":false}]}
{"op":"mcm","clk":"11449962061","pt":1717316432460,"mc":[{"id":"1.229554899","rc":[{"atb":[[1.15,0]],"id":65732558},{"atl":[[6.4,2.78],[5.8,0]],"id":65732558}],"con":true,"img":false}]}
{"op":"mcm","clk":"11449962067","pt":1717316432563,"mc":[{"id":"1.229554899","rc":[{"atl":[[2.18,21.18],[2.16,31.18]],"id":63161712}],"con":true,"img":false}]}
{"op":"mcm","clk":"11449962080","pt":1717316432769,"mc":[{"id":"1.229554899","rc":[{"atl":[[6.2,0]],"id":65732558}],"con":true,"img":false}]}
{"op":"mcm","clk":"11449962877","pt":1717316442447,"mc":[{"id":"1.229554899","rc":[{"atl":[[6.8,3.45]],"id":65732558}],"con":true,"img":false}]}
{"op":"mcm","clk":"11449964172","pt":1717316460684,"mc":[{"id":"1.229554899","rc":[{"atb":[[1.2,2]],"id":63161712},{"atl":[[2.16,33.18]],"id":63161712},{"atb":[[2.3,3.06]],"id":65732558},{"atl":[[5.8,3.06]],"id":65732558}],"con":true,"img":false}]}
{"op":"mcm","clk":"11449964714","pt":1717316467981,"mc":[{"id":"1.229554899","rc":[{"atl":[[5.8,0],[5.7,2]],"id":65732558}],"con":true,"img":false}]}
{"op":"mcm","clk":"11449964723","pt":1717316468086,"mc":[{"id":"1.229554899","rc":[{"atl":[[2.08,13.89]],"id":63161712},{"atb":[[1.03,12.26]],"id":65732558}],"con":true,"img":false}]}
{"op":"mcm","clk":"11449964735","pt":1717316468188,"mc":[{"id":"1.229554899","rc":[{"atl":[[2.06,20.83],[2.1,0],[2.16,0]],"id":63161712}],"con":true,"img":false}]}
{"op":"mcm","clk":"11449964746","pt":1717316468292,"mc":[{"id":"1.229554899","rc":[{"atl":[[2.06,0],[2.1,36.72]],"id":63161712}],"con":true,"img":false}]}
{"op":"mcm","clk":"11449967777","pt":1717316511023,"mc":[{"id":"1.229554899","rc":[{"atl":[[2.1,50.36]],"id":63161712}],"con":true,"img":false}]}
{"op":"mcm","clk":"11449967787","pt":1717316511138,"mc":[{"id":"1.229554899","rc":[{"atl":[[2.1,15.64],[2.14,19.54],[2.08,0]],"id":63161712}],"con":true,"img":false}]}
{"op":"mcm","clk":"11449967793","pt":1717316511229,"mc":[{"id":"1.229554899","rc":[{"atl":[[2.1,13.64],[2.14,83.79]],"id":63161712}],"con":true,"img":false}]}
{"op":"mcm","clk":"11449967798","pt":1717316511330,"mc":[{"id":"1.229554899","rc":[{"atl":[[2.18,56.36],[2.14,19.54]],"id":63161712}],"con":true,"img":false}]}
{"op":"mcm","clk":"11449967805","pt":1717316511433,"mc":[{"id":"1.229554899","rc":[{"atb":[[1.03,0]],"id":65732558},{"atl":[[6.4,0],[8.2,6.9],[5.7,0],[5.9,3.06],[5.4,2]],"id":65732558}],"con":true,"img":false}]}
{"op":"mcm","clk":"11449967809","pt":1717316511537,"mc":[{"id":"1.229554899","rc":[{"atb":[[1.1,28.54],[1.05,0]],"id":63161712},{"atl":[[2.18,21.18],[2.08,19.54]],"id":63161712},{"atb":[[1.26,12.26]],"id":65732558},{"atl":[[9,0]],"id":65732558}],"con":true,"img":false}]}
{"op":"mcm","clk":"11449967815","pt":1717316511639,"mc":[{"id":"1.229554899","rc":[{"atl":[[2.1,0],[2.08,33.43]],"id":63161712}],"con":true,"img":false}]}
{"op":"mcm","clk":"11449967821","pt":1717316511747,"mc":[{"id":"1.229554899","rc":[{"atb":[[1.45,12.26],[1.26,0]],"id":65732558}],"con":true,"img":false}]}
{"op":"mcm","clk":"11449968106","pt":1717316516246,"mc":[{"id":"1.229554899","rc":[{"atl":[[2.16,2]],"id":63161712}],"con":true,"img":false}]}
{"op":"mcm","clk":"11449968111","pt":1717316516349,"mc":[{"id":"1.229554899","rc":[{"atl":[[2.14,17.54]],"id":63161712}],"con":true,"img":false}]}
{"op":"mcm","clk":"11449968355","pt":1717316520427,"mc":[{"id":"1.229554899","rc":[{"atl":[[2.06,14.15],[2.14,19.54],[2.08,19.54]],"id":63161712}],"con":true,"img":false}]}
{"op":"mcm","clk":"11449968364","pt":1717316520533,"mc":[{"id":"1.229554899","rc":[{"atl":[[2.16,0]],"id":63161712}],"con":true,"img":false}]}
{"op":"mcm","clk":"11449969025","pt":1717316530430,"mc":[{"id":"1.229554899","rc":[{"atl":[[2.1,18.18]],"id":63161712}],"con":true,"img":false}]}
{"op":"mcm","clk":"11449969032","pt":1717316530537,"mc":[{"id":"1.229554899","rc":[{"atl":[[2.1,20.18],[2.14,17.54]],"id":63161712}],"con":true,"img":false}]}
{"op":"mcm","clk":"11449969527","pt":1717316538128,"mc":[{"id":"1.229554899","rc":[{"atl":[[2.22,0]],"id":63161712}],"con":true,"img":false}]}
{"op":"mcm","clk":"11449971195","pt":1717316563369,"mc":[{"id":"1.229554899","rc":[{"atb":[[1.2,0]],"id":63161712},{"atl":[[2.02,19.54]],"id":63161712},{"atb":[[1.45,0],[1.04,13.4]],"id":65732558},{"atl":[[9.6,7.91],[6.2,2],[8.2,0],[6.6,2.68],[5.9,0]],"id":65732558}],"con":true,"img":false}]}
{"op":"mcm","clk":"11449971201","pt":1717316563474,"mc":[{"id":"1.229554899","rc":[{"atb":[[1.19,2]],"id":63161712},{"atl":[[2.08,0]],"id":63161712},{"atb":[[1.19,13.4],[1.04,0]],"id":65732558},{"atl":[[5.4,0]],"id":65732558}],"con":true,"img":false}]}
{"op":"mcm","clk":"11449971499","pt":1717316568486,"mc":[{"id":"1.229554899","rc":[{"atl":[[6,2]],"id":65732558}],"con":true,"img":false}]}
{"op":"mcm","clk":"11449971506","pt":1717316568588,"mc":[{"id":"1.229554899","rc":[{"atl":[[6.2,0]],"id":65732558}],"con":true,"img":false}]}
{"op":"mcm","clk":"11449971813","pt":1717316573395,"mc":[{"id":"1.229554899","rc":[{"atl":[[7,8.33]],"id":65732558}],"con":true,"img":false}]}
{"op":"mcm","clk":"11449971822","pt":1717316573496,"mc":[{"id":"1.229554899","rc":[{"atl":[[7,3.33]],"id":65732558}],"con":true,"img":false}]}
{"op":"mcm","clk":"11449971983","pt":1717316575513,"mc":[{"id":"1.229554899","rc":[{"atl":[[1.99,19.54],[2.02,0]],"id":63161712}],"con":true,"img":false}]}
{"op":"mcm","clk":"11449971992","pt":1717316575614,"mc":[{"id":"1.229554899","rc":[{"atl":[[2.06,16.15],[2.1,18.18]],"id":63161712}],"con":true,"img":false}]}
{"op":"mcm","clk":"11449971999","pt":1717316575719,"mc":[{"id":"1.229554899","rc":[{"atl":[[2.1,20.18]],"id":63161712}],"con":true,"img":false}]}
{"op":"mcm","clk":"11449972009","pt":1717316575821,"mc":[{"id":"1.229554899","rc":[{"atl":[[2.06,14.15]],"id":63161712}],"con":true,"img":false}]}
{"op":"mcm","clk":"11449972510","pt":1717316583432,"mc":[{"id":"1.229554899","rc":[{"atl":[[7.4,3.91]],"id":65732558}],"con":true,"img":false}]}
{"op":"mcm","clk":"11449972881","pt":1717316588410,"mc":[{"id":"1.229554899","rc":[{"atb":[[1.44,12.26]],"id":65732558},{"atl":[[8.6,6.66]],"id":65732558}],"con":true,"img":false}]}
{"op":"mcm","clk":"11449972888","pt":1717316588512,"mc":[{"id":"1.229554899","rc":[{"atl":[[2,39.08],[1.99,0]],"id":63161712},{"atb":[[1.44,0],[1.37,12.26],[1.19,0]],"id":65732558},{"atl":[[9.6,0],[5.6,2],[6.2,2.88],[6,0],[6.6,0]],"id":65732558}],"con":true,"img":false}]}
{"op":"mcm","clk":"11449972900","pt":1717316588614,"mc":[{"id":"1.229554899","rc":[{"atl":[[2.06,16.15],[2.1,18.18]],"id":63161712}],"con":true,"img":false}]}
{"op":"mcm","clk":"11449973283","pt":1717316593640,"mc":[{"id":"1.229554899","rc":[{"atl":[[2,0],[2.02,78.16]],"id":63161712}],"con":true,"img":false}]}
{"op":"mcm","clk":"11449973288","pt":1717316593743,"mc":[{"id":"1.229554899","rc":[{"atl":[[2.06,14.15],[2.1,20.18]],"id":63161712}],"con":true,"img":false}]}
{"op":"mcm","clk":"11449975008","pt":1717316618639,"mc":[{"id":"1.229554899","rc":[{"atl":[[2.02,0],[2.06,108.49]],"id":63161712},{"atb":[[1.37,0],[1.52,12.26]],"id":65732558},{"atl":[[5.6,0],[6.2,0],[5.9,3.06],[5.4,2]],"id":65732558}],"con":true,"img":false}]}
{"op":"mcm","clk":"11449975017","pt":1717316618743,"mc":[{"id":"1.229554899","rc":[{"atl":[[2.1,18.18],[2.14,19.54]],"id":63161712},{"atl":[[8.6,0],[8.2,6.66]],"id":65732558}],"con":true,"img":false}]}
{"op":"mcm","clk":"11449975118","pt":1717316620256,"mc":[{"id":"1.229554899","rc":[{"atb":[[1.45,0],[1.55,0]],"id":63161712},{"atl":[[2,15],[2.06,94.34]],"id":63161712},{"atb":[[2.28,0],[2.08,0]],"id":65732558}],"con":true,"img":false}]}
{"op":"mcm","clk":"11449975126","pt":1717316620364,"mc":[{"id":"1.229554899","rc":[{"atb":[[1.15,166.67],[1.19,78.95],[1.22,2],[1.1,0],[1.13,230.77],[1.17,117.65],[1.04,30.54]],"id":63161712},{"atb":[[1.8,18.75],[2.3,0],[1.74,40.54],[1.78,25.64],[1.95,2],[1.76,32.89]],"id":65732558}],"con":true,"img":false}]}
{"op":"mcm","clk":"11449975136","pt":1717316620461,"mc":[{"id":"1.229554899","rc":[{"atb":[[1.1,17.13],[1.04,0]],"id":63161712}],"con":true,"img":false}]}
{"op":"mcm","clk":"11449975203","pt":1717316621355,"mc":[{"id":"1.229554899","rc":[{"atb":[[1.21,71.43],[1.19,0]],"id":63161712},{"atb":[[1.8,0],[1.83,18.07]],"id":65732558}],"con":true,"img":false}]}
{"op":"mcm","clk":"11449975218","pt":1717316621564,"mc":[{"id":"1.229554899","rc":[{"atb":[[1.96,2]],"id":65732558}],"con":true,"img":false}]}
{"op":"mcm","clk":"11449975226","pt":1717316621669,"mc":[{"id":"1.229554899","rc":[{"atb":[[1.95,0]],"id":65732558}],"con":true,"img":false}]}
{"op":"mcm","clk":"11449975234","pt":1717316621778,"mc":[{"id":"1.229554899","rc":[{"atl":[[1.98,15.31]],"id":63161712},{"atb":[[1.98,2]],"id":65732558}],"con":true,"img":false}]}
{"op":"mcm","clk":"11449975240","pt":1717316621880,"mc":[{"id":"1.229554899","rc":[{"atl":[[2,0]],"id":63161712},{"atb":[[1.96,0]],"id":65732558}],"con":true,"img":false}]}
{"op":"mcm","clk":"11449975392","pt":1717316623787,"mc":[{"id":"1.229554899","rc":[{"atb":[[1.45,43.71],[1.52,0]],"id":65732558}],"con":true,"img":false}]}
{"op":"mcm","clk":"11449975400","pt":1717316623891,"mc":[{"id":"1.229554899","rc":[{"atl":[[2,15],[1.98,0],[2.04,2],[2.14,17.54]],"id":63161712},{"atb":[[1.96,2]],"id":65732558},{"atl":[[8.2,0],[9.4,6.78]],"id":65732558}],"con":true,"img":false}]}
{"op":"mcm","clk":"11449975408","pt":1717316623943,"mc":[{"id":"1.229554899","rc":[{"atl":[[2.06,96.34]],"id":63161712},{"atb":[[1.98,0]],"id":65732558}],"con":true,"img":false}]}
{"op":"mcm","clk":"11449975414","pt":1717316624046,"mc":[{"id":"1.229554899","rc":[{"atl":[[2.04,0]],"id":63161712}],"con":true,"img":false}]}
{"op":"mcm","clk":"11449975423","pt":1717316624151,"mc":[{"id":"1.229554899","rc":[{"atl":[[2.1,109.09]],"id":63161712}],"con":true,"img":false}]}
{"op":"mcm","clk":"11449975428","pt":1717316624252,"mc":[{"id":"1.229554899","rc":[{"atl":[[2.06,2]],"id":63161712}],"con":true,"img":false}]}
{"op":"mcm","clk":"11449975537","pt":1717316625560,"mc":[{"id":"1.229554899","rc":[{"atl":[[2.06,0],[1.98,15.31],[2.04,2]],"id":63161712},{"atb":[[1.99,2]],"id":65732558}],"con":true,"img":false}]}
{"op":"mcm","clk":"11449975543","pt":1717316625665,"mc":[{"id":"1.229554899","rc":[{"atl":[[2,0]],"id":63161712},{"atb":[[1.96,0]],"id":65732558}],"con":true,"img":false}]}
{"op":"mcm","clk":"11449975763","pt":1717316628478,"mc":[{"id":"1.229554899","rc":[{"atb":[[1.83,0],[1.8,18.75]],"id":65732558}],"con":true,"img":false}]}
{"op":"mcm","clk":"11449975983","pt":1717316631751,"mc":[{"id":"1.229554899","rc":[{"atb":[[1.81,18.52]],"id":65732558}],"con":true,"img":false}]}
{"op":"mcm","clk":"11449975988","pt":1717316631852,"mc":[{"id":"1.229554899","rc":[{"atb":[[1.8,0]],"id":65732558}],"con":true,"img":false}]}
{"op":"mcm","clk":"11449976109","pt":1717316633765,"mc":[{"id":"1.229554899","rc":[{"atb":[[1.2,75],[1.21,0]],"id":63161712}],"con":true,"img":false}]}
{"op":"mcm","clk":"11449976677","pt":1717316641762,"mc":[{"id":"1.229554899","rc":[{"atl":[[6.2,3.85]],"id":65732558}],"con":true,"img":false}]}
{"op":"mcm","clk":"11449976737","pt":1717316642595,"mc":[{"id":"1.229554899","rc":[{"atb":[[1.2,0],[1.21,71.43]],"id":63161712},{"atl":[[7.4,0],[6.8,0]],"id":65732558}],"con":true,"img":false}]}
{"op":"mcm","clk":"11449976754","pt":1717316642911,"mc":[{"id":"1.229554899","rc":[{"atb":[[1.2,75],[1.21,0]],"id":63161712}],"con":true,"img":false}]}
{"op":"mcm","clk":"11449976865","pt":1717316644275,"mc":[{"id":"1.229554899","rc":[{"atb":[[1.21,71.43]],"id":63161712}],"con":true,"img":false}]}
{"op":"mcm","clk":"11449976873","pt":1717316644379,"mc":[{"id":"1.229554899","rc":[{"atb":[[1.2,0]],"id":63161712}],"con":true,"img":false}]}
{"op":"mcm","clk":"11449977005","pt":1717316646006,"mc":[{"id":"1.229554899","rc":[{"atb":[[1.2,75]],"id":63161712}],"con":true,"img":false}]}
{"op":"mcm","clk":"11449977013","pt":1717316646108,"mc":[{"id":"1.229554899","rc":[{"atb":[[1.21,0]],"id":63161712}],"con":true,"img":false}]}
{"op":"mcm","clk":"11449977026","pt":1717316646214,"mc":[{"id":"1.229554899","rc":[{"atl":[[2.06,14.15],[2.1,111.09]],"id":63161712},{"atb":[[1.88,2]],"id":65732558}],"con":true,"img":false}]}
{"op":"mcm","clk":"11449977037","pt":1717316646319,"mc":[{"id":"1.229554899","rc":[{"atl":[[1.98,0],[2.04,30.62],[2.1,20.18]],"id":63161712},{"atb":[[1.99,0]],"id":65732558}],"con":true,"img":false}]}
{"op":"mcm","clk":"11449977042","pt":1717316646421,"mc":[{"id":"1.229554899","rc":[{"atb":[[1.89,2]],"id":65732558}],"con":true,"img":false}]}
{"op":"mcm","clk":"11449977052","pt":1717316646524,"mc":[{"id":"1.229554899","rc":[{"atb":[[1.88,0]],"id":65732558}],"con":true,"img":false}]}
{"op":"mcm","clk":"11449977153","pt":1717316647613,"mc":[{"id":"1.229554899","rc":[{"atb":[[1.2,0],[1.18,83.33],[1.19,2],[1.22,0]],"id":63161712},{"atb":[[1.45,0],[1.04,58.53]],"id":65732558},{"atl":[[6.2,5.85],[6.6,2.68],[5.9,0],[5.4,0]],"id":65732558}],"con":true,"img":false}]}
{"op":"mcm","clk":"11449977161","pt":1717316647716,"mc":[{"id":"1.229554899","rc":[{"atl":[[6.2,2],[12.5,8.7]],"id":65732558}],"con":true,"img":false}]}
{"op":"mcm","clk":"11449977167","pt":1717316647821,"mc":[{"id":"1.229554899","rc":[{"atl":[[9.4,0]],"id":65732558}],"con":true,"img":false}]}
{"op":"mcm","clk":"11449977287","pt":1717316649320,"mc":[{"id":"1.229554899","rc":[{"atb":[[1.18,0],[1.2,75]],"id":63161712},{"atl":[[6.2,4.88]],"id":65732558}],"con":true,"img":false}]}
{"op":"mcm","clk":"11449977449","pt":1717316651397,"mc":[{"id":"1.229554899","rc":[{"atl":[[2.04,0],[2.1,64.95]],"id":63161712}],"con":true,"img":false}]}
{"op":"mcm","clk":"11449977455","pt":1717316651502,"mc":[{"id":"1.229554899","rc":[{"atl":[[2.1,18.18],[2.14,98.64]],"id":63161712},{"atb":[[1.89,0],[1.88,2]],"id":65732558}],"con":true,"img":false}]}
{"op":"mcm","clk":"11449977555","pt":1717316652695,"mc":[{"id":"1.229554899","rc":[{"atb":[[1.21,2],[1.19,0]],"id":63161712},{"atl":[[5.6,2],[6.2,2.88]],"id":65732558}],"con":true,"img":false}]}
{"op":"mcm","clk":"11449977682","pt":1717316654296,"mc":[{"id":"1.229554899","rc":[{"atb":[[1.18,2],[1.21,0],[1.17,205.89]],"id":63161712},{"atl":[[5.6,0],[6.2,4.88],[6.8,2.59]],"id":65732558}],"con":true,"img":false}]}
{"op":"mcm","clk":"11449977685","pt":1717316654399,"mc":[{"id":"1.229554899","rc":[{"atb":[[1.2,0],[1.17,88.24]],"id":63161712},{"atl":[[6.2,2]],"id":65732558}],"con":true,"img":false}]}
{"op":"mcm","clk":"11449977937","pt":1717316657515,"mc":[{"id":"1.229554899","rc":[{"atb":[[1.4,19.61],[1.5,15.69]],"id":63161712},{"atb":[[2.38,5.68],[2.18,6.64]],"id":65732558}],"con":true,"img":false}]}
{"op":"mcm","clk":"11449977952","pt":1717316657721,"mc":[{"id":"1.229554899","rc":[{"atl":[[2.12,2]],"id":63161712},{"atb":[[2.4,2],[1.88,0]],"id":65732558}],"con":true,"img":false}]}
{"op":"mcm","clk":"11449977962","pt":1717316657829,"mc":[{"id":"1.229554899","rc":[{"atl":[[2.14,96.64]],"id":63161712},{"atl":[[6.6,0]],"id":65732558}],"con":true,"img":false}]}
{"op":"mcm","clk":"11449978057","pt":1717316658923,"mc":[{"id":"1.229554899","rc":[{"atl":[[12.5,0],[9.8,5.18]],"id":65732558}],"con":true,"img":false}]}
{"op":"mcm","clk":"11449978339","pt":1717316662706,"mc":[{"id":"1.229554899","rc":[{"atl":[[1.98,14.15]],"id":63161712}],"con":true,"img":false}]}
{"op":"mcm","clk":"11449978352","pt":1717316662804,"mc":[{"id":"1.229554899","rc":[{"atl":[[2.14,17.54]],"id":63161712}],"con":true,"img":false}]}
{"op":"mcm","clk":"11449978416","pt":1717316663523,"mc":[{"id":"1.229554899","rc":[{"atb":[[1.1,37.04],[1.04,0]],"id":65732558}],"con":true,"img":false}]}
{"op":"mcm","clk":"11449978471","pt":1717316664313,"mc":[{"id":"1.229554899","rc":[{"atl":[[7.2,3.23]],"id":65732558}],"con":true,"img":false}]}
{"op":"mcm","clk":"11449979238","pt":1717316674344,"mc":[{"id":"1.229554899","rc":[{"atl":[[7.6,3.79]],"id":65732558}],"con":true,"img":false}]}
{"op":"mcm","clk":"11449979512","pt":1717316678542,"mc":[{"id":"1.229554899","rc":[{"atl":[[1.99,28.3],[1.98,0]],"id":63161712},{"atb":[[1.36,37.04],[1.1,0]],"id":65732558},{"atl":[[9,6.46],[6.4,2.78],[5.8,2],[6.2,0],[6.8,0],[9.8,0]],"id":65732558}],"con":true,"img":false}]}
{"op":"mcm","clk":"11449979519","pt":1717316678643,"mc":[{"id":"1.229554899","rc":[{"atl":[[1.99,0],[2.02,28.3],[2.06,16.15],[2.12,0]],"id":63161712},{"atb":[[1.28,37.04],[1.36,0]],"id":65732558}],"con":true,"img":false}]}
{"op":"mcm","clk":"11449979526","pt":1717316678747,"mc":[{"id":"1.229554899","rc":[{"atl":[[2.06,14.15],[2.1,20.18]],"id":63161712}],"con":true,"img":false}]}
{"op":"mcm","clk":"11449981606","pt":1717316708857,"mc":[{"id":"1.229554899","rc":[{"atb":[[1.4,0],[1.5,0]],"id":63161712},{"atb":[[2.38,0],[2.18,0]],"id":65732558}],"con":true,"img":false}]}
{"op":"mcm","clk":"11449981609","pt":1717316708961,"mc":[{"id":"1.229554899","rc":[{"atb":[[1.18,0],[1.2,2]],"id":63161712},{"atl":[[2.06,0],[2.04,14.42]],"id":63161712},{"atb":[[2.4,0],[1.91,2]],"id":65732558}],"con":true,"img":false}]}
{"op":"mcm","clk":"11449981616","pt":1717316709059,"mc":[{"id":"1.229554899","rc":[{"atb":[[1.19,78.95]],"id":63161712},{"atl":[[2.02,0],[2.06,2],[2.1,62.63]],"id":63161712},{"atb":[[1.83,18.07],[1.81,0]],"id":65732558},{"atl":[[9,0],[10.5,6.56]],"id":65732558}],"con":true,"img":false}]}
{"op":"mcm","clk":"11449981624","pt":1717316709166,"mc":[{"id":"1.229554899","rc":[{"atl":[[2.06,44.72],[2.1,18.18]],"id":63161712}],"con":true,"img":false}]}
{"op":"mcm","clk":"11449981631","pt":1717316709266,"mc":[{"id":"1.229554899","rc":[{"atl":[[2.06,0],[2.1,41.37]],"id":63161712}],"con":true,"img":false}]}
{"op":"mcm","clk":"11449981713","pt":1717316710574,"mc":[{"id":"1.229554899","rc":[{"atl":[[2.02,14.71],[2.04,0]],"id":63161712},{"atb":[[1.92,2],[1.91,0]],"id":65732558}],"con":true,"img":false}]}
{"op":"mcm","clk":"11449981912","pt":1717316712993,"mc":[{"id":"1.229554899","rc":[{"atl":[[2.02,0],[2.04,14.42]],"id":63161712},{"atb":[[1.92,0],[1.91,2]],"id":65732558}],"con":true,"img":false}]}
{"op":"mcm","clk":"11449981943","pt":1717316713262,"mc":[{"id":"1.229554899","rc":[{"atb":[[1.84,17.86]],"id":65732558}],"con":true,"img":false}]}
{"op":"mcm","clk":"11449981952","pt":1717316713361,"mc":[{"id":"1.229554899","rc":[{"atb":[[1.83,0]],"id":65732558}],"con":true,"img":false}]}
{"op":"mcm","clk":"11449982017","pt":1717316714387,"mc":[{"id":"1.229554899","rc":[{"atb":[[1.92,2],[1.91,0]],"id":65732558}],"con":true,"img":false}]}
{"op":"mcm","clk":"11449982528","pt":1717316721588,"mc":[{"id":"1.229554899","rc":[{"atb":[[1.4,19.61],[1.5,15.69]],"id":63161712},{"atb":[[2.38,5.68],[2.18,6.64]],"id":65732558}],"con":true,"img":false}]}
{"op":"mcm","clk":"11449982546","pt":1717316721801,"mc":[{"id":"1.229554899","rc":[{"atl":[[2.1,18.18],[2.14,75.33],[2.08,13.89]],"id":63161712},{"atb":[[2.4,2],[1.92,0]],"id":65732558},{"atl":[[9,6.46],[10.5,0]],"id":65732558}],"con":true,"img":false}]}
{"op":"mcm","clk":"11449982552","pt":1717316721896,"mc":[{"id":"1.229554899","rc":[{"atl":[[2.04,0]],"id":63161712}],"con":true,"img":false}]}
{"op":"mcm","clk":"11449982690","pt":1717316723962,"mc":[{"id":"1.229554899","rc":[{"atb":[[1.84,0]],"id":65732558}],"con":true,"img":false}]}
{"op":"mcm","clk":"11449982856","pt":1717316726901,"mc":[{"id":"1.229554899","rc":[{"atl":[[2.1,20.18]],"id":63161712}],"con":true,"img":false}]}
{"op":"mcm","clk":"11449982864","pt":1717316727003,"mc":[{"id":"1.229554899","rc":[{"atl":[[2.14,73.33]],"id":63161712}],"con":true,"img":false}]}
{"op":"mcm","clk":"11449982871","pt":1717316727117,"mc":[{"id":"1.229554899","rc":[{"atl":[[2.1,18.18],[2.14,75.33]],"id":63161712}],"con":true,"img":false}]}
{"op":"mcm","clk":"11449983237","pt":1717316732314,"mc":[{"id":"1.229554899","rc":[{"atl":[[2.02,18.18]],"id":63161712}],"con":true,"img":false}]}
{"op":"mcm","clk":"11449983244","pt":1717316732419,"mc":[{"id":"1.229554899","rc":[{"atl":[[2,7.85],[2.14,17.54]],"id":63161712}],"con":true,"img":false}]}
{"op":"mcm","clk":"11449983607","pt":1717316737497,"mc":[{"id":"1.229554899","rc":[{"atl":[[2.08,15.89]],"id":63161712}],"con":true,"img":false}]}
{"op":"mcm","clk":"11449983616","pt":1717316737595,"mc":[{"id":"1.229554899","rc":[{"atl":[[2,0]],"id":63161712}],"con":true,"img":false}]}
{"op":"mcm","clk":"11449983620","pt":1717316737704,"mc":[{"id":"1.229554899","rc":[{"atl":[[2.1,20.18],[2.08,13.89]],"id":63161712}],"con":true,"img":false}]}
{"op":"mcm","clk":"11449988108","pt":1717316798500,"mc":[{"id":"1.229554899","rc":[{"atl":[[2.02,0],[2.1,52.25]],"id":63161712},{"atb":[[1.14,51.28]],"id":65732558}],"con":true,"img":false}]}
{"op":"mcm","clk":"11449988114","pt":1717316798599,"mc":[{"id":"1.229554899","rc":[{"atl":[[2.1,50.25],[2.14,19.54]],"id":63161712},{"atb":[[1.28,0]],"id":65732558}],"con":true,"img":false}]}
{"op":"mcm","clk":"11449990025","pt":1717316825813,"mc":[{"id":"1.229554899","rc":[{"atb":[[1.2,0]],"id":63161712},{"atl":[[2.14,17.54]],"id":63161712},{"atb":[[2.4,0]],"id":65732558},{"atl":[[5.8,0]],"id":65732558}],"con":true,"img":false}]}
{"op":"mcm","clk":"11449990394","pt":1717316830129,"mc":[{"id":"1.229554899","rc":[{"atb":[[1.14,0],[1.07,58.53]],"id":65732558}],"con":true,"img":false}]}
{"op":"mcm","clk":"11450003837","pt":1717316990739,"mc":[{"id":"1.229554899","rc":[{"atl":[[2.06,14.15]],"id":63161712}],"con":true,"img":false}]}
{"op":"mcm","clk":"11450003845","pt":1717316990850,"mc":[{"id":"1.229554899","rc":[{"atl":[[2.08,0]],"id":63161712}],"con":true,"img":false}]}
{"op":"mcm","clk":"11450006471","pt":1717317018552,"mc":[{"id":"1.229554899","rc":[{"atb":[[1.15,333.34],[1.32,10],[1.1,0]],"id":63161712},{"atl":[[2.1,18.18],[2.14,91.94]],"id":63161712},{"atb":[[2.4,10],[2.24,25.64],[1.07,0]],"id":65732558},{"atl":[[7.2,9.34],[9,0],[6.4,0],[3.95,10],[4.4,4.41]],"id":65732558}],"con":true,"img":false}]}
{"op":"mcm","clk":"11450006512","pt":1717317019066,"mc":[{"id":"1.229554899","rc":[{"atl":[[2.06,0],[2.04,14.42]],"id":63161712}],"con":true,"img":false}]}
{"op":"mcm","clk":"11450006534","pt":1717317019275,"mc":[{"id":"1.229554899","rc":[{"atl":[[2.06,14.15],[2.04,0]],"id":63161712}],"con":true,"img":false}]}
{"op":"mcm","clk":"11450007015","pt":1717317023875,"mc":[{"id":"1.229554899","rc":[{"atl":[[2.12,10],[2.14,81.94]],"id":63161712}],"con":true,"img":false}]}
{"op":"mcm","clk":"11450007244","pt":1717317026202,"mc":[{"id":"1.229554899","rc":[{"atl":[[1.99,14.15],[2.14,17.54]],"id":63161712},{"atb":[[2.4,20],[2.24,0]],"id":65732558}],"con":true,"img":false}]}
{"op":"mcm","clk":"11450007471","pt":1717317028595,"mc":[{"id":"1.229554899","rc":[{"atl":[[4.6,5.56]],"id":65732558}],"con":true,"img":false}]}
{"op":"mcm","clk":"11450007483","pt":1717317028714,"mc":[{"id":"1.229554899","rc":[{"atl":[[4.8,14.41],[7.2,3.23]],"id":65732558}],"con":true,"img":false}]}
{"op":"mcm","clk":"11450007676","pt":1717317030761,"mc":[{"id":"1.229554899","rc":[{"atl":[[7.6,0],[7,0]],"id":65732558}],"con":true,"img":false}]}
{"op":"mcm","clk":"11450008432","pt":1717317038577,"mc":[{"id":"1.229554899","rc":[{"atl":[[4.8,20.99]],"id":65732558}],"con":true,"img":false}]}
{"op":"mcm","clk":"11450009406","pt":1717317048580,"mc":[{"id":"1.229554899","rc":[{"atl":[[5,7.5]],"id":65732558}],"con":true,"img":false}]}
{"op":"mcm","clk":"11450010010","pt":1717317054293,"mc":[{"id":"1.229554899","rc":[{"atl":[[7.2,0]],"id":65732558}],"con":true,"img":false}]}
{"op":"mcm","clk":"11450014389","pt":1717317099052,"mc":[{"id":"1.229554899","rc":[{"atb":[[1.32,0]],"id":63161712},{"atl":[[1.99,0],[1.97,14.15]],"id":63161712},{"atl":[[4.8,6.58],[3.95,0],[5.2,15],[4.4,0],[4.2,2],[4.7,4.05]],"id":65732558}],"con":true,"img":false}]}
{"op":"mcm","clk":"11450014394","pt":1717317099149,"mc":[{"id":"1.229554899","rc":[{"atb":[[1.3,2]],"id":63161712},{"atl":[[2.06,16.15],[2.12,0]],"id":63161712}],"con":true,"img":false}]}
{"op":"mcm","clk":"11450014403","pt":1717317099255,"mc":[{"id":"1.229554899","rc":[{"atl":[[2.06,2],[2.04,14.42]],"id":63161712},{"atl":[[4.6,0]],"id":65732558}],"con":true,"img":false}]}
{"op":"mcm","clk":"11450014422","pt":1717317099461,"mc":[{"id":"1.229554899","rc":[{"atl":[[4.6,4.17]],"id":65732558}],"con":true,"img":false}]}
{"op":"mcm","clk":"11450014440","pt":1717317099668,"mc":[{"id":"1.229554899","rc":[{"atl":[[2.02,14.71],[2.04,0]],"id":63161712}],"con":true,"img":false}]}
{"op":"mcm","clk":"11450014829","pt":1717317104179,"mc":[{"id":"1.229554899","rc":[{"atl":[[1.98,28.3],[1.97,0]],"id":63161712}],"con":true,"img":false}]}
{"op":"mcm","clk":"11450015338","pt":1717317109971,"mc":[{"id":"1.229554899","rc":[{"atl":[[2.06,20.87]],"id":63161712}],"con":true,"img":false}]}
{"op":"mcm","clk":"11450015532","pt":1717317112188,"mc":[{"id":"1.229554899","rc":[{"atl":[[2,15],[2.02,0],[2.06,2],[2.18,0],[2.1,0],[2.14,0]],"id":63161712}],"con":true,"img":false}]}
{"op":"mcm","clk":"11450015541","pt":1717317112293,"mc":[{"id":"1.229554899","rc":[{"atl":[[1.99,7.5],[2.06,0]],"id":63161712}],"con":true,"img":false}]}
{"op":"mcm","clk":"11450015548","pt":1717317112348,"mc":[{"id":"1.229554899","rc":[{"atl":[[2,17],[1.99,0]],"id":63161712}],"con":true,"img":false}]}
{"op":"mcm","clk":"11450016512","pt":1717317122260,"mc":[{"id":"1.229554899","rc":[{"atl":[[2.04,19.23]],"id":63161712}],"con":true,"img":false}]}
{"op":"mcm","clk":"11450016527","pt":1717317122414,"mc":[{"id":"1.229554899","rc":[{"atl":[[2,15],[2.04,21.23]],"id":63161712}],"con":true,"img":false}]}
{"op":"mcm","clk":"11450016580","pt":1717317122931,"mc":[{"id":"1.229554899","rc":[{"atl":[[1.98,43.61]],"id":63161712}],"con":true,"img":false}]}
{"op":"mcm","clk":"11450017597","pt":1717317132838,"mc":[{"id":"1.229554899","rc":[{"atl":[[2,20]],"id":63161712}],"con":true,"img":false}]}
{"op":"mcm","clk":"11450018599","pt":1717317142654,"mc":[{"id":"1.229554899","rc":[{"atl":[[2.04,26.04]],"id":63161712}],"con":true,"img":false}]}
{"op":"mcm","clk":"11450018694","pt":1717317143633,"mc":[{"id":"1.229554899","rc":[{"atl":[[1.97,26.04]],"id":63161712}],"con":true,"img":false}]}
{"op":"mcm","clk":"11450018706","pt":1717317143736,"mc":[{"id":"1.229554899","rc":[{"atl":[[1.98,15.31],[1.96,7.85]],"id":63161712}],"con":true,"img":false}]}
{"op":"mcm","clk":"11450018713","pt":1717317143837,"mc":[{"id":"1.229554899","rc":[{"atl":[[2.04,24.04]],"id":63161712}],"con":true,"img":false}]}
{"op":"mcm","clk":"11450018985","pt":1717317146956,"mc":[{"id":"1.229554899","rc":[{"atl":[[2,15],[1.98,0]],"id":63161712}],"con":true,"img":false}]}
{"op":"mcm","clk":"11450019165","pt":1717317148860,"mc":[{"id":"1.229554899","rc":[{"atl":[[2,17]],"id":63161712},{"atl":[[4.6,0]],"id":65732558}],"con":true,"img":false}]}
{"op":"mcm","clk":"11450019172","pt":1717317148912,"mc":[{"id":"1.229554899","rc":[{"atl":[[1.96,0]],"id":63161712}],"con":true,"img":false}]}
{"op":"mcm","clk":"11450019181","pt":1717317149016,"mc":[{"id":"1.229554899","rc":[{"atl":[[2,15],[2.04,26.04]],"id":63161712}],"con":true,"img":false}]}
{"op":"mcm","clk":"11450019912","pt":1717317156449,"mc":[{"id":"1.229554899","rc":[{"atl":[[2.04,21.23]],"id":63161712}],"con":true,"img":false}]}
{"op":"mcm","clk":"11450020091","pt":1717317158053,"mc":[{"id":"1.229554899","rc":[{"atl":[[1.99,15.15]],"id":63161712}],"con":true,"img":false}]}
{"op":"mcm","clk":"11450020103","pt":1717317158158,"mc":[{"id":"1.229554899","rc":[{"atl":[[1.98,7.58],[2.04,19.23]],"id":63161712}],"con":true,"img":false}]}
{"op":"mcm","clk":"11450020123","pt":1717317158362,"mc":[{"id":"1.229554899","rc":[{"atl":[[4.9,5.13]],"id":65732558}],"con":true,"img":false}]}
{"op":"mcm","clk":"11450020236","pt":1717317159447,"mc":[{"id":"1.229554899","rc":[{"atl":[[1.99,0]],"id":63161712}],"con":true,"img":false}]}
{"op":"mcm","clk":"11450020626","pt":1717317163378,"mc":[{"id":"1.229554899","rc":[{"atl":[[1.99,2],[1.98,0]],"id":63161712}],"con":true,"img":false}]}
{"op":"mcm","clk":"11450021041","pt":1717317167466,"mc":[{"id":"1.229554899","rc":[{"atl":[[2.08,23.15]],"id":63161712}],"con":true,"img":false}]}
{"op":"mcm","clk":"11450021054","pt":1717317167567,"mc":[{"id":"1.229554899","rc":[{"atl":[[2,17]],"id":63161712}],"con":true,"img":false}]}
{"op":"mcm","clk":"11450021066","pt":1717317167666,"mc":[{"id":"1.229554899","rc":[{"atl":[[1.99,0]],"id":63161712}],"con":true,"img":false}]}
{"op":"mcm","clk":"11450021923","pt":1717317176674,"mc":[{"id":"1.229554899","rc":[{"atl":[[2.12,26.79]],"id":63161712}],"con":true,"img":false}]}
{"op":"mcm","clk":"11450021932","pt":1717317176782,"mc":[{"id":"1.229554899","rc":[{"atl":[[2.04,21.23]],"id":63161712}],"con":true,"img":false}]}
{"op":"mcm","clk":"11450021942","pt":1717317176879,"mc":[{"id":"1.229554899","rc":[{"atl":[[2,15]],"id":63161712}],"con":true,"img":false}]}
{"op":"mcm","clk":"11450024424","pt":1717317201709,"mc":[{"id":"1.229554899","rc":[{"atl":[[2,0],[1.99,15.15]],"id":63161712}],"con":true,"img":false}]}
{"op":"mcm","clk":"11450024436","pt":1717317201816,"mc":[{"id":"1.229554899","rc":[{"atl":[[2,2],[2.04,19.23]],"id":63161712}],"con":true,"img":false}]}
{"op":"mcm","clk":"11450024447","pt":1717317201913,"mc":[{"id":"1.229554899","rc":[{"atl":[[2,17],[1.99,0]],"id":63161712}],"con":true,"img":false}]}
{"op":"mcm","clk":"11450024958","pt":1717317206629,"mc":[{"id":"1.229554899","rc":[{"atl":[[2,2],[1.99,15.15]],"id":63161712}],"con":true,"img":false}]}
{"op":"mcm","clk":"11450024977","pt":1717317206789,"mc":[{"id":"1.229554899","rc":[{"atl":[[2,17],[1.99,0]],"id":63161712}],"con":true,"img":false}]}
{"op":"mcm","clk":"11450024988","pt":1717317206894,"mc":[{"id":"1.229554899","rc":[{"atl":[[2.04,21.23]],"id":63161712}],"con":true,"img":false}]}
{"op":"mcm","clk":"11450024999","pt":1717317207001,"mc":[{"id":"1.229554899","rc":[{"atl":[[2,15]],"id":63161712}],"con":true,"img":false}]}
{"op":"mcm","clk":"11450025808","pt":1717317215297,"mc":[{"id":"1.229554899","rc":[{"atl":[[2,0],[1.99,15.15]],"id":63161712}],"con":true,"img":false}]}
{"op":"mcm","clk":"11450025820","pt":1717317215400,"mc":[{"id":"1.229554899","rc":[{"atl":[[2,2],[2.04,19.23]],"id":63161712}],"con":true,"img":false}]}
{"op":"mcm","clk":"11450025829","pt":1717317215503,"mc":[{"id":"1.229554899","rc":[{"atl":[[2.04,21.23]],"id":63161712}],"con":true,"img":false}]}
{"op":"mcm","clk":"11450025837","pt":1717317215605,"mc":[{"id":"1.229554899","rc":[{"atl":[[2,0]],"id":63161712}],"con":true,"img":false}]}
{"op":"mcm","clk":"11450025846","pt":1717317215708,"mc":[{"id":"1.229554899","rc":[{"atl":[[2,2]],"id":63161712}],"con":true,"img":false}]}
{"op":"mcm","clk":"11450025855","pt":1717317215811,"mc":[{"id":"1.229554899","rc":[{"atl":[[2.04,19.23]],"id":63161712}],"con":true,"img":false}]}
{"op":"mcm","clk":"11450026150","pt":1717317218302,"mc":[{"id":"1.229554899","rc":[{"atl":[[2,17],[1.99,0]],"id":63161712}],"con":true,"img":false}]}
{"op":"mcm","clk":"11450026159","pt":1717317218407,"mc":[{"id":"1.229554899","rc":[{"atl":[[2,15],[2.04,21.23]],"id":63161712}],"con":true,"img":false}]}
{"op":"mcm","clk":"11450026372","pt":1717317220327,"mc":[{"id":"1.229554899","rc":[{"atl":[[1.98,52.08],[1.97,0]],"id":63161712},{"atl":[[4.6,4.17],[4.1,2],[4.2,0],[4.7,0]],"id":65732558}],"con":true,"img":false}]}
{"op":"mcm","clk":"11450026379","pt":1717317220433,"mc":[{"id":"1.229554899","rc":[{"atl":[[5.1,10.26],[5.2,0]],"id":65732558}],"con":true,"img":false}]}
{"op":"mcm","clk":"11450026466","pt":1717317221212,"mc":[{"id":"1.229554899","rc":[{"atl":[[4.6,0],[4.7,4.05]],"id":65732558}],"con":true,"img":false}]}
{"op":"mcm","clk":"11450026532","pt":1717317221937,"mc":[{"id":"1.229554899","rc":[{"atl":[[2.02,14.71]],"id":63161712}],"con":true,"img":false}]}
{"op":"mcm","clk":"11450026545","pt":1717317222038,"mc":[{"id":"1.229554899","rc":[{"atl":[[2,0]],"id":63161712}],"con":true,"img":false}]}
{"op":"mcm","clk":"11450026568","pt":1717317222247,"mc":[{"id":"1.229554899","rc":[{"atl":[[2.04,2],[2.12,0],[2.08,0]],"id":63161712}],"con":true,"img":false}]}
{"op":"mcm","clk":"11450026902","pt":1717317225405,"mc":[{"id":"1.229554899","rc":[{"atl":[[4.1,0],[4.2,2]],"id":65732558}],"con":true,"img":false}]}
{"op":"mcm","clk":"11450026945","pt":1717317225823,"mc":[{"id":"1.229554899","rc":[{"atl":[[1.98,0],[1.96,14.71]],"id":63161712}],"con":true,"img":false}]}
{"op":"mcm","clk":"11450027053","pt":1717317226905,"mc":[{"id":"1.229554899","rc":[{"atl":[[2.02,0],[2.04,16.42]],"id":63161712}],"con":true,"img":false}]}
{"op":"mcm","clk":"11450027897","pt":1717317235132,"mc":[{"id":"1.229554899","rc":[{"atl":[[2.08,18.52]],"id":63161712}],"con":true,"img":false}]}
{"op":"mcm","clk":"11450028688","pt":1717317243255,"mc":[{"id":"1.229554899","rc":[{"atl":[[2.12,22.32]],"id":63161712}],"con":true,"img":false}]}
{"op":"mcm","clk":"11450029434","pt":1717317251168,"mc":[{"id":"1.229554899","rc":[{"atl":[[2.16,25.86]],"id":63161712}],"con":true,"img":false}]}
{"op":"mcm","clk":"11450033986","pt":1717317295313,"mc":[{"id":"1.229554899","rc":[{"atl":[[1.96,0],[1.95,16.42]],"id":63161712}],"con":true,"img":false}]}
{"op":"mcm","clk":"11450035152","pt":1717317305719,"mc":[{"id":"1.229554899","rc":[{"atb":[[1.4,0],[1.5,0]],"id":63161712},{"atb":[[2.38,0],[2.18,0]],"id":65732558}],"con":true,"img":false}]}
{"op":"mcm","clk":"11450035164","pt":1717317305823,"mc":[{"id":"1.229554899","rc":[{"atb":[[2.4,0],[1.83,40],[1.91,2]],"id":65732558}],"con":true,"img":false}]}
{"op":"mcm","clk":"11450035175","pt":1717317305929,"mc":[{"id":"1.229554899","rc":[{"atb":[[1.19,0],[1.24,62.5]],"id":63161712},{"atl":[[1.94,5.13]],"id":63161712},{"atb":[[1.79,3.76],[1.93,16.13]],"id":65732558}],"con":true,"img":false}]}
{"op":"mcm","clk":"11450035188","pt":1717317306028,"mc":[{"id":"1.229554899","rc":[{"atb":[[1.18,230.77],[1.15,166.67]],"id":63161712},{"atl":[[1.95,0]],"id":63161712},{"atl":[[5.1,0],[6,11.71]],"id":65732558}],"con":true,"img":false}]}
{"op":"mcm","clk":"11450035203","pt":1717317306131,"mc":[{"id":"1.229554899","rc":[{"atl":[[2.04,14.42],[1.93,2],[2.08,51.36]],"id":63161712}],"con":true,"img":false}]}
{"op":"mcm","clk":"11450035215","pt":1717317306242,"mc":[{"id":"1.229554899","rc":[{"atl":[[1.93,18.42],[2.08,18.51]],"id":63161712}],"con":true,"img":false}]}
{"op":"mcm","clk":"11450035942","pt":1717317312829,"mc":[{"id":"1.229554899","rc":[{"atb":[[1.22,90.91]],"id":63161712},{"atb":[[1.91,23.98]],"id":65732558}],"con":true,"img":false}]}
{"op":"mcm","clk":"11450035957","pt":1717317312938,"mc":[{"id":"1.229554899","rc":[{"atb":[[1.83,0],[1.92,32.26]],"id":65732558}],"con":true,"img":false}]}
{"op":"mcm","clk":"11450035969","pt":1717317313038,"mc":[{"id":"1.229554899","rc":[{"atb":[[1.83,40.11],[1.92,0]],"id":65732558}],"con":true,"img":false}]}
{"op":"mcm","clk":"11450035979","pt":1717317313166,"mc":[{"id":"1.229554899","rc":[{"atb":[[1.83,0],[1.91,56.24]],"id":65732558}],"con":true,"img":false}]}
{"op":"mcm","clk":"11450035990","pt":1717317313218,"mc":[{"id":"1.229554899","rc":[{"atb":[[1.83,72.37],[1.91,23.98]],"id":65732558}],"con":true,"img":false}]}
{"op":"mcm","clk":"11450036054","pt":1717317313835,"mc":[{"id":"1.229554899","rc":[{"atb":[[1.13,0]],"id":63161712},{"atb":[[1.74,0]],"id":65732558}],"con":true,"img":false}]}
{"op":"mcm","clk":"11450036335","pt":1717317316425,"mc":[{"id":"1.229554899","rc":[{"atb":[[1.25,60],[1.24,0]],"id":63161712},{"atb":[[1.9,16.67],[1.93,0]],"id":65732558}],"con":true,"img":false}]}
{"op":"mcm","clk":"11450036444","pt":1717317317303,"mc":[{"id":"1.229554899","rc":[{"atb":[[1.91,2]],"id":65732558}],"con":true,"img":false}]}
{"op":"mcm","clk":"11450036471","pt":1717317317518,"mc":[{"id":"1.229554899","rc":[{"atb":[[1.49,16.01],[1.39,20.12]],"id":63161712},{"atb":[[2.42,5.52],[2.22,6.43]],"id":65732558}],"con":true,"img":false}]}
{"op":"mcm","clk":"11450036494","pt":1717317317729,"mc":[{"id":"1.229554899","rc":[{"atb":[[1.3,8.23]],"id":63161712},{"atb":[[1.91,0],[2.44,2]],"id":65732558},{"atl":[[6,0],[5.2,10.26],[4.2,5.29]],"id":65732558}],"con":true,"img":false}]}
{"op":"mcm","clk":"11450036516","pt":1717317317931,"mc":[{"id":"1.229554899","rc":[{"atl":[[1.92,5.16]],"id":63161712},{"atb":[[2.24,3.74]],"id":65732558}],"con":true,"img":false}]}
{"op":"mcm","clk":"11450036526","pt":1717317318033,"mc":[{"id":"1.229554899","rc":[{"atl":[[1.91,10.86]],"id":63161712}],"con":true,"img":false}]}
{"op":"mcm","clk":"11450036538","pt":1717317318137,"mc":[{"id":"1.229554899","rc":[{"atl":[[1.93,0]],"id":63161712}],"con":true,"img":false}]}
{"op":"mcm","clk":"11450036566","pt":1717317318349,"mc":[{"id":"1.229554899","rc":[{"atb":[[1.83,0],[2.44,5.75]],"id":65732558}],"con":true,"img":false}]}
{"op":"mcm","clk":"11450036825","pt":1717317320732,"mc":[{"id":"1.229554899","rc":[{"atb":[[1.25,0]],"id":63161712},{"atb":[[1.9,0]],"id":65732558}],"con":true,"img":false}]}
{"op":"mcm","clk":"11450038459","pt":1717317335544,"mc":[{"id":"1.229554899","rc":[{"atl":[[4.8,3.95],[4.3,2],[4.2,3.29],[4.7,0]],"id":65732558}],"con":true,"img":false}]}
{"op":"mcm","clk":"11450038492","pt":1717317335865,"mc":[{"id":"1.229554899","rc":[{"atl":[[1.9,5.23]],"id":63161712}],"con":true,"img":false}]}
{"op":"mcm","clk":"11450038503","pt":1717317335948,"mc":[{"id":"1.229554899","rc":[{"atl":[[1.89,10.98],[1.91,0]],"id":63161712}],"con":true,"img":false}]}
{"op":"mcm","clk":"11450038907","pt":1717317339525,"mc":[{"id":"1.229554899","rc":[{"atl":[[1.97,15.46],[2.04,0]],"id":63161712}],"con":true,"img":false}]}
{"op":"mcm","clk":"11450039153","pt":1717317341957,"mc":[{"id":"1.229554899","rc":[{"atl":[[5,5]],"id":65732558}],"con":true,"img":false}]}
{"op":"mcm","clk":"11450039190","pt":1717317342268,"mc":[{"id":"1.229554899","rc":[{"atb":[[1.3,6.23]],"id":63161712},{"atl":[[4.8,0],[5.6,8.95],[4.3,0],[4.5,2],[5,3.75],[5.2,0]],"id":65732558}],"con":true,"img":false}]}
{"op":"mcm","clk":"11450039202","pt":1717317342370,"mc":[{"id":"1.229554899","rc":[{"atb":[[1.27,5.74]],"id":63161712}],"con":true,"img":false}]}
{"op":"mcm","clk":"11450039214","pt":1717317342422,"mc":[{"id":"1.229554899","rc":[{"atl":[[4.9,0]],"id":65732558}],"con":true,"img":false}]}
{"op":"mcm","clk":"11450039242","pt":1717317342631,"mc":[{"id":"1.229554899","rc":[{"atl":[[1.97,0],[1.95,15.79]],"id":63161712}],"con":true,"img":false}]}
{"op":"mcm","clk":"11450039255","pt":1717317342737,"mc":[{"id":"1.229554899","rc":[{"atl":[[1.96,15.62]],"id":63161712}],"con":true,"img":false}]}
{"op":"mcm","clk":"11450039287","pt":1717317343048,"mc":[{"id":"1.229554899","rc":[{"atl":[[2.12,0],[1.96,0],[2.16,0],[2.08,0]],"id":63161712}],"con":true,"img":false}]}
{"op":"mcm","clk":"11450039304","pt":1717317343146,"mc":[{"id":"1.229554899","rc":[{"atl":[[1.95,0]],"id":63161712}],"con":true,"img":false}]}
{"op":"mcm","clk":"11450039339","pt":1717317343456,"mc":[{"id":"1.229554899","rc":[{"atl":[[2,25],[1.98,20.41],[2.04,28.85],[1.96,15.62]],"id":63161712}],"con":true,"img":false}]}
{"op":"mcm","clk":"11450039498","pt":1717317344854,"mc":[{"id":"1.229554899","rc":[{"atl":[[1.97,15.46],[1.96,0]],"id":63161712}],"con":true,"img":false}]}
{"op":"mcm","clk":"11450039583","pt":1717317345569,"mc":[{"id":"1.229554899","rc":[{"atb":[[1.5,6.28]],"id":63161712},{"atl":[[1.88,5.4]],"id":63161712}],"con":true,"img":false}]}
{"op":"mcm","clk":"11450039592","pt":1717317345623,"mc":[{"id":"1.229554899","rc":[{"atl":[[1.89,0],[1.87,11.24]],"id":63161712}],"con":true,"img":false}]}
{"op":"mcm","clk":"11450039839","pt":1717317347851,"mc":[{"id":"1.229554899","rc":[{"atb":[[1.18,0],[1.27,0]],"id":63161712},{"atb":[[2.24,15.01],[2.44,2]],"id":65732558},{"atl":[[5.6,0],[4.5,0],[5,0],[4.9,2]],"id":65732558}],"con":true,"img":false}]}
{"op":"mcm","clk":"11450039848","pt":1717317347954,"mc":[{"id":"1.229554899","rc":[{"atb":[[1.25,5.84],[1.14,40.24]],"id":63161712},{"atl":[[6.2,5.29]],"id":65732558}],"con":true,"img":false}]}
{"op":"mcm","clk":"11450040160","pt":1717317351063,"mc":[{"id":"1.229554899","rc":[{"atl":[[1.96,15.62]],"id":63161712}],"con":true,"img":false}]}
{"op":"mcm","clk":"11450040173","pt":1717317351173,"mc":[{"id":"1.229554899","rc":[{"atl":[[1.97,0]],"id":63161712}],"con":true,"img":false}]}
{"op":"mcm","clk":"11450040765","pt":1717317357267,"mc":[{"id":"1.229554899","rc":[{"atb":[[1.5,0]],"id":63161712},{"trd":[[1.5,12.56]],"ltp":1.5,"tv":12.56,"id":63161712},{"atl":[[1.5,11.78]],"id":63161712}],"con":true,"img":false}]}
{"op":"mcm","clk":"11450040777","pt":1717317357368,"mc":[{"id":"1.229554899","rc":[{"atl":[[1.94,0],[1.87,0],[1.53,23.58],[1.5,20.8],[1.86,5.48]],"id":63161712},{"atb":[[2.26,3.56]],"id":65732558}],"con":true,"img":false}]}
{"op":"mcm","clk":"11450040808","pt":1717317357669,"mc":[{"id":"1.229554899","rc":[{"atb":[[2.24,3.74],[2.44,5.57]],"id":65732558}],"con":true,"img":false}]}
{"op":"mcm","clk":"11450040961","pt":1717317359072,"mc":[{"id":"1.229554899","rc":[{"atl":[[1.96,0]],"id":63161712}],"con":true,"img":false}]}
{"op":"mcm","clk":"11450041120","pt":1717317360475,"mc":[{"id":"1.229554899","rc":[{"atl":[[2,0],[1.98,0]],"id":63161712}],"con":true,"img":false}]}
{"op":"mcm","clk":"11450041549","pt":1717317364260,"mc":[{"id":"1.229554899","rc":[{"atl":[[1.53,0],[1.52,41.62]],"id":63161712}],"con":true,"img":false}]}
{"op":"mcm","clk":"11450041603","pt":1717317364778,"mc":[{"id":"1.229554899","rc":[{"atb":[[2.46,3.41]],"id":65732558}],"con":true,"img":false}]}
{"op":"mcm","clk":"11450041613","pt":1717317364879,"mc":[{"id":"1.229554899","rc":[{"atb":[[2.44,2],[2.48,2]],"id":65732558}],"con":true,"img":false}]}
{"op":"mcm","clk":"11450041623","pt":1717317364985,"mc":[{"id":"1.229554899","rc":[{"atb":[[2.44,0],[2.48,7.52]],"id":65732558}],"con":true,"img":false}]}
{"op":"mcm","clk":"11450041828","pt":1717317366854,"mc":[{"id":"1.229554899","rc":[{"atb":[[1.22,0]],"id":63161712}],"con":true,"img":false}]}
{"op":"mcm","clk":"11450042462","pt":1717317373059,"mc":[{"id":"1.229554899","rc":[{"atl":[[2.04,0]],"id":63161712}],"con":true,"img":false}]}
{"op":"mcm","clk":"11450042550","pt":1717317373880,"mc":[{"id":"1.229554899","rc":[{"atb":[[1.79,0],[2.5,3.37]],"id":65732558}],"con":true,"img":false}]}
{"op":"mcm","clk":"11450042563","pt":1717317373983,"mc":[{"id":"1.229554899","rc":[{"atb":[[2.52,5.41],[2.48,0]],"id":65732558}],"con":true,"img":false}]}
{"op":"mcm","clk":"11450043301","pt":1717317381160,"mc":[{"id":"1.229554899","rc":[{"atb":[[1.25,0]],"id":63161712},{"atl":[[1.51,41.62]],"id":63161712},{"atl":[[4.9,0]],"id":65732558}],"con":true,"img":false}]}
{"op":"mcm","clk":"11450043309","pt":1717317381262,"mc":[{"id":"1.229554899","rc":[{"atb":[[1.24,9.02]],"id":63161712},{"atl":[[1.52,0]],"id":63161712},{"atl":[[5.1,2]],"id":65732558}],"con":true,"img":false}]}
{"op":"mcm","clk":"11450043569","pt":1717317383757,"mc":[{"id":"1.229554899","rc":[{"atl":[[1.5,9.02]],"id":63161712}],"con":true,"img":false}]}
{"op":"mcm","clk":"11450043583","pt":1717317383905,"mc":[{"id":"1.229554899","rc":[{"atb":[[1.49,4.22]],"id":63161712},{"trd":[[1.49,23.57]],"ltp":1.49,"tv":23.57,"id":63161712},{"atl":[[1.85,5.86],[1.5,0]],"id":63161712}],"con":true,"img":false}]}
{"op":"mcm","clk":"11450043592","pt":1717317383960,"mc":[{"id":"1.229554899","rc":[{"atb":[[1.49,0]],"id":63161712},{"trd":[[1.49,32.03]],"ltp":1.49,"tv":32.03,"id":63161712},{"atl":[[1.92,0],[1.84,6.18]],"id":63161712},{"atb":[[2.24,0],[2.54,3.24]],"id":65732558}],"con":true,"img":false}]}
{"op":"mcm","clk":"11450043604","pt":1717317384060,"mc":[{"id":"1.229554899","rc":[{"atb":[[2.56,2],[2.54,6.61],[2.52,0]],"id":65732558}],"con":true,"img":false}]}
{"op":"mcm","clk":"11450043716","pt":1717317385095,"mc":[{"id":"1.229554899","rc":[{"atl":[[1.83,83.24],[1.51,0]],"id":63161712}],"con":true,"img":false}]}
{"op":"mcm","clk":"11450043766","pt":1717317385563,"mc":[{"id":"1.229554899","rc":[{"atl":[[1.82,0.8]],"id":63161712}],"con":true,"img":false}]}
{"op":"mcm","clk":"11450043812","pt":1717317386078,"mc":[{"id":"1.229554899","rc":[{"atb":[[2.54,3.24]],"id":65732558}],"con":true,"img":false}]}
{"op":"mcm","clk":"11450043823","pt":1717317386187,"mc":[{"id":"1.229554899","rc":[{"atb":[[2.24,25.64]],"id":65732558}],"con":true,"img":false}]}
{"op":"mcm","clk":"11450044140","pt":1717317388995,"mc":[{"id":"1.229554899","rc":[{"atl":[[1.83,86.74],[1.85,0]],"id":63161712}],"con":true,"img":false}]}
{"op":"mcm","clk":"11450044984","pt":1717317397398,"mc":[{"id":"1.229554899","rc":[{"atb":[[1.24,0]],"id":63161712},{"atb":[[2.24,0],[1.98,25.64]],"id":65732558},{"atl":[[5.1,0],[5.8,2],[6.2,0],[7.6,6.58]],"id":65732558}],"con":true,"img":false}]}
{"op":"mcm","clk":"11450044993","pt":1717317397504,"mc":[{"id":"1.229554899","rc":[{"atb":[[1.2,3.5]],"id":63161712}],"con":true,"img":false}]}
{"op":"mcm","clk":"11450045012","pt":1717317397709,"mc":[{"id":"1.229554899","rc":[{"atl":[[1.82,7.39],[1.9,0]],"id":63161712},{"atb":[[2.56,5.1],[2.26,0]],"id":65732558}],"con":true,"img":false}]}
{"op":"mcm","clk":"11450045030","pt":1717317397869,"mc":[{"id":"1.229554899","rc":[{"atl":[[1.83,0],[1.81,13.61]],"id":63161712}],"con":true,"img":false}]}
{"op":"mcm","clk":"11450045060","pt":1717317398179,"mc":[{"id":"1.229554899","rc":[{"atl":[[1.82,6.59]],"id":63161712}],"con":true,"img":false}]}
{"op":"mcm","clk":"11450045069","pt":1717317398282,"mc":[{"id":"1.229554899","rc":[{"atl":[[1.8,0.8]],"id":63161712}],"con":true,"img":false}]}
{"op":"mcm","clk":"11450045430","pt":1717317401772,"mc":[{"id":"1.229554899","rc":[{"atb":[[1.14,0]],"id":63161712}],"con":true,"img":false}]}
{"op":"mcm","clk":"11450045440","pt":1717317401882,"mc":[{"id":"1.229554899","rc":[{"atb":[[1.11,60.36]],"id":63161712}],"con":true,"img":false}]}
{"op":"mcm","clk":"11450045449","pt":1717317401976,"mc":[{"id":"1.229554899","rc":[{"atb":[[1.4,7.79]],"id":63161712}],"con":true,"img":false}]}
{"op":"mcm","clk":"11450045508","pt":1717317402596,"mc":[{"id":"1.229554899","rc":[{"atb":[[1.41,1.96]],"id":63161712}],"con":true,"img":false}]}
{"op":"mcm","clk":"11450045562","pt":1717317403115,"mc":[{"id":"1.229554899","rc":[{"atl":[[1.8,7.87]],"id":63161712}],"con":true,"img":false}]}
{"op":"mcm","clk":"11450045575","pt":1717317403218,"mc":[{"id":"1.229554899","rc":[{"atb":[[1.41,9.73]],"id":63161712},{"atl":[[1.88,0]],"id":63161712}],"con":true,"img":false}]}
{"op":"mcm","clk":"11450045586","pt":1717317403324,"mc":[{"id":"1.229554899","rc":[{"atl":[[1.79,15.08],[1.81,0]],"id":63161712}],"con":true,"img":false}]}
{"op":"mcm","clk":"11450045630","pt":1717317403587,"mc":[{"id":"1.229554899","rc":[{"atl":[[1.8,7.07]],"id":63161712}],"con":true,"img":false}]}
{"op":"mcm","clk":"11450045639","pt":1717317403693,"mc":[{"id":"1.229554899","rc":[{"atl":[[1.78,0.8]],"id":63161712}],"con":true,"img":false}]}
{"op":"mcm","clk":"11450046003","pt":1717317407012,"mc":[{"id":"1.229554899","rc":[{"atb":[[1.98,0],[2.1,25.64]],"id":65732558}],"con":true,"img":false}]}
{"op":"mcm","clk":"11450048625","pt":1717317431247,"mc":[{"id":"1.229554899","rc":[{"atb":[[2.2,25.64],[2.1,0]],"id":65732558}],"con":true,"img":false}]}
{"op":"mcm","clk":"11450048833","pt":1717317433051,"mc":[{"id":"1.229554899","rc":[{"atl":[[5.8,0],[5.5,3.18]],"id":65732558}],"con":true,"img":false}]}
{"op":"mcm","clk":"11450048860","pt":1717317433258,"mc":[{"id":"1.229554899","rc":[{"atb":[[1.15,0],[1.17,0]],"id":63161712},{"atb":[[1.78,0],[1.76,0]],"id":65732558}],"con":true,"img":false}]}
{"op":"mcm","clk":"11450049180","pt":1717317436062,"mc":[{"id":"1.229554899","rc":[{"atb":[[2.2,0],[2.26,8.6]],"id":65732558}],"con":true,"img":false}]}
{"op":"mcm","clk":"11450049520","pt":1717317439162,"mc":[{"id":"1.229554899","rc":[{"atb":[[1.41,1.96],[1.4,0]],"id":63161712}],"con":true,"img":false}]}
{"op":"mcm","clk":"11450049619","pt":1717317439938,"mc":[{"id":"1.229554899","rc":[{"atb":[[1.41,0]],"id":63161712}],"con":true,"img":false}]}
{"op":"mcm","clk":"11450049717","pt":1717317440979,"mc":[{"id":"1.229554899","rc":[{"atb":[[1.4,8.06]],"id":63161712}],"con":true,"img":false}]}
{"op":"mcm","clk":"11450049736","pt":1717317441139,"mc":[{"id":"1.229554899","rc":[{"atb":[[1.41,1.96]],"id":63161712}],"con":true,"img":false}]}
{"op":"mcm","clk":"11450050569","pt":1717317449050,"mc":[{"id":"1.229554899","rc":[{"atl":[[5.5,0]],"id":65732558}],"con":true,"img":false}]}
{"op":"mcm","clk":"11450050577","pt":1717317449156,"mc":[{"id":"1.229554899","rc":[{"atl":[[5.8,3.18]],"id":65732558}],"con":true,"img":false}]}
{"op":"mcm","clk":"11450050588","pt":1717317449258,"mc":[{"id":"1.229554899","rc":[{"atl":[[1.78,8.27],[1.86,0]],"id":63161712}],"con":true,"img":false}]}
{"op":"mcm","clk":"11450050600","pt":1717317449362,"mc":[{"id":"1.229554899","rc":[{"atl":[[1.79,0],[1.77,15.84]],"id":63161712}],"con":true,"img":false}]}
{"op":"mcm","clk":"11450050624","pt":1717317449565,"mc":[{"id":"1.229554899","rc":[{"atl":[[1.78,7.47]],"id":63161712}],"con":true,"img":false}]}
{"op":"mcm","clk":"11450050635","pt":1717317449669,"mc":[{"id":"1.229554899","rc":[{"atl":[[1.76,0.8]],"id":63161712}],"con":true,"img":false}]}
{"op":"mcm","clk":"11450050666","pt":1717317449979,"mc":[{"id":"1.229554899","rc":[{"atb":[[2.58,3.37],[2.26,0]],"id":65732558}],"con":true,"img":false}]}
{"op":"mcm","clk":"11450050723","pt":1717317450393,"mc":[{"id":"1.229554899","rc":[{"atl":[[1.84,0],[1.76,8.27]],"id":63161712},{"atb":[[2.46,0],[2.6,2.86]],"id":65732558}],"con":true,"img":false}]}
{"op":"mcm","clk":"11450050742","pt":1717317450552,"mc":[{"id":"1.229554899","rc":[{"atl":[[1.77,0],[1.75,16.03]],"id":63161712},{"atb":[[2.56,3.1],[2.6,4.86]],"id":65732558}],"con":true,"img":false}]}
{"op":"mcm","clk":"11450050820","pt":1717317451277,"mc":[{"id":"1.229554899","rc":[{"atl":[[1.76,7.47]],"id":63161712}],"con":true,"img":false}]}
{"op":"mcm","clk":"11450050829","pt":1717317451383,"mc":[{"id":"1.229554899","rc":[{"atl":[[1.74,0.8]],"id":63161712}],"con":true,"img":false}]}
{"op":"mcm","clk":"11450050875","pt":1717317451851,"mc":[{"id":"1.229554899","rc":[{"atl":[[1.74,8.28]],"id":63161712}],"con":true,"img":false}]}
{"op":"mcm","clk":"11450050883","pt":1717317451956,"mc":[{"id":"1.229554899","rc":[{"atl":[[1.73,8.29],[1.82,0],[1.75,7.76]],"id":63161712}],"con":true,"img":false}]}
{"op":"mcm","clk":"11450050932","pt":1717317452472,"mc":[{"id":"1.229554899","rc":[{"atl":[[1.74,7.48]],"id":63161712}],"con":true,"img":false}]}
{"op":"mcm","clk":"11450050943","pt":1717317452575,"mc":[{"id":"1.229554899","rc":[{"atl":[[1.72,0.8]],"id":63161712}],"con":true,"img":false}]}
{"op":"mcm","clk":"11450051249","pt":1717317455679,"mc":[{"id":"1.229554899","rc":[{"atl":[[1.73,13.02],[1.75,0]],"id":63161712}],"con":true,"img":false}]}
{"op":"mcm","clk":"11450051341","pt":1717317456767,"mc":[{"id":"1.229554899","rc":[{"atl":[[1.72,8.29]],"id":63161712}],"con":true,"img":false}]}
{"op":"mcm","clk":"11450051349","pt":1717317456870,"mc":[{"id":"1.229554899","rc":[{"atl":[[1.8,0]],"id":63161712}],"con":true,"img":false}]}
{"op":"mcm","clk":"11450051361","pt":1717317457073,"mc":[{"id":"1.229554899","rc":[{"atl":[[1.71,8.29]],"id":63161712}],"con":true,"img":false}]}
{"op":"mcm","clk":"11450051372","pt":1717317457178,"mc":[{"id":"1.229554899","rc":[{"atl":[[1.73,4.73]],"id":63161712}],"con":true,"img":false}]}
{"op":"mcm","clk":"11450051392","pt":1717317457338,"mc":[{"id":"1.229554899","rc":[{"atb":[[1.41,0]],"id":63161712},{"atl":[[1.72,7.49]],"id":63161712}],"con":true,"img":false}]}
{"op":"mcm","clk":"11450051402","pt":1717317457439,"mc":[{"id":"1.229554899","rc":[{"atl":[[1.7,0.8]],"id":63161712}],"con":true,"img":false}]}
{"op":"mcm","clk":"11450051667","pt":1717317460704,"mc":[{"id":"1.229554899","rc":[{"atb":[[1.39,0]],"id":63161712},{"atb":[[2.42,0],[2.22,0]],"id":65732558}],"con":true,"img":false}]}
{"op":"mcm","clk":"11450051676","pt":1717317460761,"mc":[{"id":"1.229554899","rc":[{"atl":[[1.73,0],[1.71,15.15]],"id":63161712}],"con":true,"img":false}]}
{"op":"mcm","clk":"11450052417","pt":1717317469266,"mc":[{"id":"1.229554899","rc":[{"atl":[[5.8,0]],"id":65732558}],"con":true,"img":false}]}
{"op":"mcm","clk":"11450052422","pt":1717317469367,"mc":[{"id":"1.229554899","rc":[{"atl":[[6,2]],"id":65732558}],"con":true,"img":false}]}
{"op":"mcm","clk":"11450052909","pt":1717317474961,"mc":[{"id":"1.229554899","rc":[{"atl":[[5.6,2],[6,0]],"id":65732558}],"con":true,"img":false}]}
{"op":"mcm","clk":"11450053353","pt":1717317479872,"mc":[{"id":"1.229554899","rc":[{"atb":[[1.01,392.38],[1.1,39.23]],"id":63161712},{"atb":[[2.46,10.86],[2.26,12.58]],"id":65732558}],"con":true,"img":false}]}
{"op":"mcm","clk":"11450053414","pt":1717317480496,"mc":[{"id":"1.229554899","rc":[{"atl":[[1.62,14.35]],"id":63161712}],"con":true,"img":false}]}
{"op":"mcm","clk":"11450053419","pt":1717317480597,"mc":[{"id":"1.229554899","rc":[{"atl":[[1.71,0],[1.61,17.88]],"id":63161712}],"con":true,"img":false}]}
{"op":"mcm","clk":"11450053426","pt":1717317480700,"mc":[{"id":"1.229554899","rc":[{"atl":[[1.7,0]],"id":63161712}],"con":true,"img":false}]}
{"op":"mcm","clk":"11450053472","pt":1717317481280,"mc":[{"id":"1.229554899","rc":[{"atl":[[1.6,0.8]],"id":63161712}],"con":true,"img":false}]}
{"op":"mcm","clk":"11450053488","pt":1717317481481,"mc":[{"id":"1.229554899","rc":[{"atl":[[1.6,7.46],[1.78,0]],"id":63161712}],"con":true,"img":false}]}
{"op":"mcm","clk":"11450053496","pt":1717317481585,"mc":[{"id":"1.229554899","rc":[{"atl":[[1.59,6.85]],"id":63161712}],"con":true,"img":false}]}
{"op":"mcm","clk":"11450053503","pt":1717317481694,"mc":[{"id":"1.229554899","rc":[{"atl":[[1.61,14.36]],"id":63161712}],"con":true,"img":false}]}
{"op":"mcm","clk":"11450053524","pt":1717317481902,"mc":[{"id":"1.229554899","rc":[{"atl":[[1.6,6.66]],"id":63161712}],"con":true,"img":false}]}
{"op":"mcm","clk":"11450053537","pt":1717317482005,"mc":[{"id":"1.229554899","rc":[{"atl":[[1.58,6.69],[1.76,0]],"id":63161712}],"con":true,"img":false}]}
{"op":"mcm","clk":"11450053546","pt":1717317482108,"mc":[{"id":"1.229554899","rc":[{"atl":[[1.59,0],[1.57,6.45]],"id":63161712}],"con":true,"img":false}]}
{"op":"mcm","clk":"11450053632","pt":1717317482984,"mc":[{"id":"1.229554899","rc":[{"atl":[[1.57,13.14],[1.74,0]],"id":63161712}],"con":true,"img":false}]}
{"op":"mcm","clk":"11450053741","pt":1717317484069,"mc":[{"id":"1.229554899","rc":[{"atl":[[1.56,15.09]],"id":63161712}],"con":true,"img":false}]}
{"op":"mcm","clk":"11450053765","pt":1717317484277,"mc":[{"id":"1.229554899","rc":[{"atl":[[1.57,6.69],[1.55,6.7]],"id":63161712}],"con":true,"img":false}]}
{"op":"mcm","clk":"11450053802","pt":1717317484687,"mc":[{"id":"1.229554899","rc":[{"atb":[[1.2,0]],"id":63161712},{"atl":[[6.4,2]],"id":65732558}],"con":true,"img":false}]}
{"op":"mcm","clk":"11450053809","pt":1717317484792,"mc":[{"id":"1.229554899","rc":[{"atb":[[1.18,6.47]],"id":63161712},{"atl":[[5.6,0]],"id":65732558}],"con":true,"img":false}]}
{"op":"mcm","clk":"11450053887","pt":1717317485672,"mc":[{"id":"1.229554899","rc":[{"atl":[[1.55,13.4],[1.61,0]],"id":63161712}],"con":true,"img":false}]}
{"op":"mcm","clk":"11450054075","pt":1717317487792,"mc":[{"id":"1.229554899","rc":[{"atl":[[1.54,15.36]],"id":63161712}],"con":true,"img":false}]}
{"op":"mcm","clk":"11450054083","pt":1717317487897,"mc":[{"id":"1.229554899","rc":[{"atl":[[1.53,22.24]],"id":63161712}],"con":true,"img":false}]}
{"op":"mcm","clk":"11450054087","pt":1717317487996,"mc":[{"id":"1.229554899","rc":[{"atl":[[1.55,0]],"id":63161712}],"con":true,"img":false}]}
{"op":"mcm","clk":"11450054114","pt":1717317488305,"mc":[{"id":"1.229554899","rc":[{"atl":[[1.62,0]],"id":63161712}],"con":true,"img":false}]}
{"op":"mcm","clk":"11450054389","pt":1717317491466,"mc":[{"id":"1.229554899","rc":[{"atl":[[1.52,12.56]],"id":63161712}],"con":true,"img":false}]}
{"op":"mcm","clk":"11450054396","pt":1717317491598,"mc":[{"id":"1.229554899","rc":[{"atl":[[1.56,21.86],[1.72,0]],"id":63161712}],"con":true,"img":false}]}
{"op":"mcm","clk":"11450054402","pt":1717317491671,"mc":[{"id":"1.229554899","rc":[{"atl":[[1.51,7.15],[1.53,15.09]],"id":63161712}],"con":true,"img":false}]}
{"op":"mcm","clk":"11450054519","pt":1717317493012,"mc":[{"id":"1.229554899","rc":[{"atl":[[1.51,19.71]],"id":63161712}],"con":true,"img":false}]}
{"op":"mcm","clk":"11450054527","pt":1717317493068,"mc":[{"id":"1.229554899","rc":[{"atl":[[1.6,0],[1.55,6.84],[1.53,0]],"id":63161712}],"con":true,"img":false}]}
{"op":"mcm","clk":"11450054640","pt":1717317494312,"mc":[{"id":"1.229554899","rc":[{"atl":[[1.55,0]],"id":63161712}],"con":true,"img":false}]}
{"op":"mcm","clk":"11450054740","pt":1717317495186,"mc":[{"id":"1.229554899","rc":[{"atl":[[1.5,12.79]],"id":63161712}],"con":true,"img":false}]}
{"op":"mcm","clk":"11450054747","pt":1717317495292,"mc":[{"id":"1.229554899","rc":[{"atl":[[1.49,12.8]],"id":63161712}],"con":true,"img":false}]}
{"op":"mcm","clk":"11450054755","pt":1717317495393,"mc":[{"id":"1.229554899","rc":[{"atl":[[1.51,7.15]],"id":63161712}],"con":true,"img":false}]}
{"op":"mcm","clk":"11450054762","pt":1717317495496,"mc":[{"id":"1.229554899","rc":[{"atl":[[1.56,6.77]],"id":63161712}],"con":true,"img":false}]}
{"op":"mcm","clk":"11450054861","pt":1717317496784,"mc":[{"id":"1.229554899","rc":[{"atl":[[1.49,15.92],[1.51,0]],"id":63161712}],"con":true,"img":false}]}
{"op":"mcm","clk":"11450055077","pt":1717317499104,"mc":[{"id":"1.229554899","rc":[{"atl":[[1.48,13.11]],"id":63161712}],"con":true,"img":false}]}
{"op":"mcm","clk":"11450055086","pt":1717317499209,"mc":[{"id":"1.229554899","rc":[{"atl":[[1.49,12.8],[1.47,7.15]],"id":63161712}],"con":true,"img":false}]}
{"op":"mcm","clk":"11450055103","pt":1717317499365,"mc":[{"id":"1.229554899","rc":[{"atl":[[1.54,0]],"id":63161712}],"con":true,"img":false}]}
{"op":"mcm","clk":"11450055196","pt":1717317500397,"mc":[{"id":"1.229554899","rc":[{"atl":[[1.47,19.95]],"id":63161712}],"con":true,"img":false}]}
{"op":"mcm","clk":"11450055206","pt":1717317500499,"mc":[{"id":"1.229554899","rc":[{"atl":[[1.49,0]],"id":63161712}],"con":true,"img":false}]}
{"op":"mcm","clk":"11450055282","pt":1717317501282,"mc":[{"id":"1.229554899","rc":[{"trd":[[1.47,14.59]],"ltp":1.47,"tv":14.59,"id":63161712},{"atl":[[1.47,12.65]],"id":63161712}],"con":true,"img":false}]}
{"op":"mcm","clk":"11450055299","pt":1717317501482,"mc":[{"id":"1.229554899","rc":[{"atb":[[1.4,9.98]],"id":63161712}],"con":true,"img":false}]}
{"op":"mcm","clk":"11450055381","pt":1717317502518,"mc":[{"id":"1.229554899","rc":[{"atl":[[1.46,13.39]],"id":63161712}],"con":true,"img":false}]}
{"op":"mcm","clk":"11450055410","pt":1717317502779,"mc":[{"id":"1.229554899","rc":[{"atl":[[1.46,0]],"id":63161712}],"con":true,"img":false}]}
{"op":"mcm","clk":"11450055656","pt":1717317505380,"mc":[{"id":"1.229554899","rc":[{"trd":[[1.48,13.11],[1.47,27.24]],"ltp":1.48,"tv":40.34,"id":63161712},{"atl":[[1.48,0],[1.47,0]],"id":63161712},{"trd":[[3.05,6.36],[3.1,6]],"ltp":3.05,"tv":12.36,"id":65732558},{"atl":[[3.05,13.79]],"id":65732558}],"con":true,"img":false}]}
{"op":"mcm","clk":"11450055677","pt":1717317505582,"mc":[{"id":"1.229554899","rc":[{"atl":[[1.5,0],[1.52,0]],"id":63161712}],"con":true,"img":false}]}
{"op":"mcm","clk":"11450055923","pt":1717317508379,"mc":[{"id":"1.229554899","rc":[{"atl":[[3.05,18.78]],"id":65732558}],"con":true,"img":false}]}
{"op":"mcm","clk":"11450056312","pt":1717317513381,"mc":[{"id":"1.229554899","rc":[{"atl":[[3.05,13.79]],"id":65732558}],"con":true,"img":false}]}
{"op":"mcm","clk":"11450056378","pt":1717317514202,"mc":[{"id":"1.229554899","rc":[{"atl":[[3.05,0]],"id":65732558}],"con":true,"img":false}]}
{"op":"mcm","clk":"11450056384","pt":1717317514309,"mc":[{"id":"1.229554899","rc":[{"atl":[[1.55,6.7]],"id":63161712},{"atb":[[2.6,5.71]],"id":65732558},{"atl":[[3.45,9.02]],"id":65732558}],"con":true,"img":false}]}
{"op":"mcm","clk":"11450056396","pt":1717317514518,"mc":[{"id":"1.229554899","rc":[{"atb":[[2.58,0],[2.62,3.37]],"id":65732558}],"con":true,"img":false}]}
{"op":"mcm","clk":"11450056403","pt":1717317514620,"mc":[{"id":"1.229554899","rc":[{"atb":[[2.6,3.71],[2.64,3.33]],"id":65732558}],"con":true,"img":false}]}
{"op":"mcm","clk":"11450056410","pt":1717317514745,"mc":[{"id":"1.229554899","rc":[{"atl":[[1.54,7.15]],"id":63161712},{"atb":[[2.5,0],[2.64,2.95],[2.66,3.37],[2.62,2]],"id":65732558}],"con":true,"img":false}]}
{"op":"mcm","clk":"11450056421","pt":1717317514826,"mc":[{"id":"1.229554899","rc":[{"atl":[[1.55,0],[1.53,6.78]],"id":63161712}],"con":true,"img":false}]}
{"op":"mcm","clk":"11450056504","pt":1717317515707,"mc":[{"id":"1.229554899","rc":[{"atb":[[1.4,0]],"id":63161712},{"trd":[[1.4,16.12]],"ltp":1.4,"tv":16.12,"id":63161712},{"atl":[[7.6,0]],"id":65732558}],"con":true,"img":false}]}
{"op":"mcm","clk":"11450056514","pt":1717317515806,"mc":[{"id":"1.229554899","rc":[{"atb":[[1.4,5.24]],"id":63161712},{"atl":[[1.58,0],[1.52,7.15]],"id":63161712},{"atb":[[2.54,0],[2.68,2.95]],"id":65732558},{"atl":[[8.4,9.87]],"id":65732558}],"con":true,"img":false}]}
{"op":"mcm","clk":"11450056526","pt":1717317515918,"mc":[{"id":"1.229554899","rc":[{"atb":[[1.4,0]],"id":63161712},{"atl":[[1.53,13.29]],"id":63161712},{"atl":[[3.45,0]],"id":65732558}],"con":true,"img":false}]}
{"op":"mcm","clk":"11450056538","pt":1717317516014,"mc":[{"id":"1.229554899","rc":[{"atb":[[1.3,12.49]],"id":63161712},{"atl":[[1.51,3.12],[1.53,6.78]],"id":63161712}],"con":true,"img":false}]}
{"op":"mcm","clk":"11450056546","pt":1717317516119,"mc":[{"id":"1.229554899","rc":[{"atl":[[1.51,3.92]],"id":63161712}],"con":true,"img":false}]}
{"op":"mcm","clk":"11450056568","pt":1717317516425,"mc":[{"id":"1.229554899","rc":[{"atl":[[1.57,0],[1.51,11.19]],"id":63161712}],"con":true,"img":false}]}
{"op":"mcm","clk":"11450056601","pt":1717317516786,"mc":[{"id":"1.229554899","rc":[{"atb":[[1.31,7.51]],"id":63161712}],"con":true,"img":false}]}
{"op":"mcm","clk":"11450056633","pt":1717317517202,"mc":[{"id":"1.229554899","rc":[{"atl":[[4.3,7.97]],"id":65732558}],"con":true,"img":false}]}
{"op":"mcm","clk":"11450056695","pt":1717317518128,"mc":[{"id":"1.229554899","rc":[{"atl":[[1.56,0],[1.5,7.35]],"id":63161712}],"con":true,"img":false}]}
{"op":"mcm","clk":"11450056702","pt":1717317518234,"mc":[{"id":"1.229554899","rc":[{"atl":[[1.49,7.26],[1.51,8.07]],"id":63161712}],"con":true,"img":false}]}
{"op":"mcm","clk":"11450056738","pt":1717317518599,"mc":[{"id":"1.229554899","rc":[{"atb":[[1.3,6.23],[1.31,13.72]],"id":63161712},{"atl":[[1.51,7.27]],"id":63161712}],"con":true,"img":false}]}
{"op":"mcm","clk":"11450056760","pt":1717317518906,"mc":[{"id":"1.229554899","rc":[{"atl":[[4.1,6.36]],"id":65732558}],"con":true,"img":false}]}
{"op":"mcm","clk":"11450056779","pt":1717317519111,"mc":[{"id":"1.229554899","rc":[{"atl":[[4,0.84]],"id":65732558}],"con":true,"img":false}]}
{"op":"mcm","clk":"11450056815","pt":1717317519524,"mc":[{"id":"1.229554899","rc":[{"atl":[[4.1,7.22]],"id":65732558}],"con":true,"img":false}]}
{"op":"mcm","clk":"11450056841","pt":1717317519784,"mc":[{"id":"1.229554899","rc":[{"atb":[[2.62,0],[2.68,5.91]],"id":65732558}],"con":true,"img":false}]}
{"op":"mcm","clk":"11450056851","pt":1717317519887,"mc":[{"id":"1.229554899","rc":[{"atl":[[1.49,14.54]],"id":63161712},{"atb":[[2.66,5.37],[2.68,2.95]],"id":65732558}],"con":true,"img":false}]}
{"op":"mcm","clk":"11450056860","pt":1717317519988,"mc":[{"id":"1.229554899","rc":[{"atl":[[1.53,0]],"id":63161712}],"con":true,"img":false}]}
{"op":"mcm","clk":"11450057427","pt":1717317526522,"mc":[{"id":"1.229554899","rc":[{"atb":[[1.01,0],[1.1,0]],"id":63161712},{"atb":[[2.46,0],[2.26,0]],"id":65732558}],"con":true,"img":false}]}
{"op":"mcm","clk":"11450057442","pt":1717317526728,"mc":[{"id":"1.229554899","rc":[{"atb":[[1.32,7.58]],"id":63161712}],"con":true,"img":false}]}
{"op":"mcm","clk":"11450057451","pt":1717317526843,"mc":[{"id":"1.229554899","rc":[{"atl":[[4.1,7.15]],"id":65732558}],"con":true,"img":false}]}
{"op":"mcm","clk":"11450057457","pt":1717317526933,"mc":[{"id":"1.229554899","rc":[{"atb":[[1.32,8.43]],"id":63161712}],"con":true,"img":false}]}
{"op":"mcm","clk":"11450057823","pt":1717317530933,"mc":[{"id":"1.229554899","rc":[{"atb":[[1.32,14.59],[1.31,7.51]],"id":63161712}],"con":true,"img":false}]}
{"op":"mcm","clk":"11450057850","pt":1717317531196,"mc":[{"id":"1.229554899","rc":[{"atb":[[1.32,14.25]],"id":63161712}],"con":true,"img":false}]}
{"op":"mcm","clk":"11450057866","pt":1717317531401,"mc":[{"id":"1.229554899","rc":[{"atb":[[1.33,7.52]],"id":63161712}],"con":true,"img":false}]}
{"op":"mcm","clk":"11450057919","pt":1717317532052,"mc":[{"id":"1.229554899","rc":[{"atl":[[1.54,0],[1.48,7.76]],"id":63161712}],"con":true,"img":false}]}
{"op":"mcm","clk":"11450057931","pt":1717317532123,"mc":[{"id":"1.229554899","rc":[{"atl":[[1.49,0],[1.47,15.29]],"id":63161712}],"con":true,"img":false}]}
{"op":"mcm","clk":"11450057937","pt":1717317532225,"mc":[{"id":"1.229554899","rc":[{"atb":[[1.31,103.72]],"id":63161712},{"atb":[[2.98,15.06]],"id":65732558}],"con":true,"img":false}]}
{"op":"mcm","clk":"11450057946","pt":1717317532330,"mc":[{"id":"1.229554899","rc":[{"atb":[[2.88,30.14],[3,3.12],[2.66,0]],"id":65732558}],"con":true,"img":false}]}
{"op":"mcm","clk":"11450057967","pt":1717317532536,"mc":[{"id":"1.229554899","rc":[{"atb":[[3,5.17]],"id":65732558}],"con":true,"img":false}]}
{"op":"mcm","clk":"11450058204","pt":1717317535135,"mc":[{"id":"1.229554899","rc":[{"atb":[[1.33,13.64],[1.32,8.09]],"id":63161712}],"con":true,"img":false}]}
{"op":"mcm","clk":"11450058234","pt":1717317535430,"mc":[{"id":"1.229554899","rc":[{"atb":[[2.6,3.43]],"id":65732558}],"con":true,"img":false}]}
{"op":"mcm","clk":"11450058262","pt":1717317535741,"mc":[{"id":"1.229554899","rc":[{"atb":[[3.05,14.54]],"id":65732558}],"con":true,"img":false}]}
{"op":"mcm","clk":"11450058272","pt":1717317535841,"mc":[{"id":"1.229554899","rc":[{"atb":[[3.1,5.22],[3,2.05]],"id":65732558}],"con":true,"img":false}]}
{"op":"mcm","clk":"11450058299","pt":1717317536123,"mc":[{"id":"1.229554899","rc":[{"atb":[[3,0]],"id":65732558}],"con":true,"img":false}]}
{"op":"mcm","clk":"11450058307","pt":1717317536228,"mc":[{"id":"1.229554899","rc":[{"atb":[[3.15,2.05]],"id":65732558}],"con":true,"img":false}]}
{"op":"mcm","clk":"11450058471","pt":1717317538141,"mc":[{"id":"1.229554899","rc":[{"atb":[[2.78,29.1]],"id":65732558}],"con":true,"img":false}]}
{"op":"mcm","clk":"11450058480","pt":1717317538243,"mc":[{"id":"1.229554899","rc":[{"atb":[[2.88,0]],"id":65732558}],"con":true,"img":false}]}
{"op":"mcm","clk":"11450058571","pt":1717317539231,"mc":[{"id":"1.229554899","rc":[{"atb":[[1.3,0],[1.34,7.91]],"id":63161712}],"con":true,"img":false}]}
{"op":"mcm","clk":"11450058587","pt":1717317539435,"mc":[{"id":"1.229554899","rc":[{"atl":[[4.1,6.36],[3.9,14.12]],"id":65732558}],"con":true,"img":false}]}
{"op":"mcm","clk":"11450058592","pt":1717317539537,"mc":[{"id":"1.229554899","rc":[{"atl":[[8.2,0.78]],"id":65732558}],"con":true,"img":false}]}
{"op":"mcm","clk":"11450058607","pt":1717317539745,"mc":[{"id":"1.229554899","rc":[{"atb":[[1.33,104.02]],"id":63161712},{"atb":[[3.15,15.92]],"id":65732558},{"atl":[[4.3,0]],"id":65732558}],"con":true,"img":false}]}
{"op":"mcm","clk":"11450058647","pt":1717317540236,"mc":[{"id":"1.229554899","rc":[{"atl":[[4,0]],"id":65732558}],"con":true,"img":false}]}
{"op":"mcm","clk":"11450058655","pt":1717317540317,"mc":[{"id":"1.229554899","rc":[{"atb":[[3.15,13.87]],"id":65732558},{"atl":[[3.85,0.84]],"id":65732558}],"con":true,"img":false}]}
{"op":"mcm","clk":"11450058663","pt":1717317540422,"mc":[{"id":"1.229554899","rc":[{"atl":[[1.47,7.77]],"id":63161712}],"con":true,"img":false}]}
{"op":"mcm","clk":"11450058684","pt":1717317540736,"mc":[{"id":"1.229554899","rc":[{"atb":[[3.15,0]],"id":65732558}],"con":true,"img":false}]}
{"op":"mcm","clk":"11450058700","pt":1717317540942,"mc":[{"id":"1.229554899","rc":[{"atb":[[3.15,2.05]],"id":65732558}],"con":true,"img":false}]}
{"op":"mcm","clk":"11450058708","pt":1717317541046,"mc":[{"id":"1.229554899","rc":[{"atb":[[1.33,97.9],[1.34,13.98]],"id":63161712}],"con":true,"img":false}]}
{"op":"mcm","clk":"11450058774","pt":1717317541832,"mc":[{"id":"1.229554899","rc":[{"atb":[[1.31,96.2],[1.35,7.86]],"id":63161712}],"con":true,"img":false}]}
{"op":"mcm","clk":"11450058827","pt":1717317542452,"mc":[{"id":"1.229554899","rc":[{"atl":[[4.1,0]],"id":65732558}],"con":true,"img":false}]}
{"op":"mcm","clk":"11450058858","pt":1717317542708,"mc":[{"id":"1.229554899","rc":[{"atb":[[1.33,7.52]],"id":63161712}],"con":true,"img":false}]}
{"op":"mcm","clk":"11450058928","pt":1717317543433,"mc":[{"id":"1.229554899","rc":[{"atb":[[2.84,19.77],[2.78,0]],"id":65732558}],"con":true,"img":false}]}
{"op":"mcm","clk":"11450059185","pt":1717317546033,"mc":[{"id":"1.229554899","rc":[{"atb":[[1.34,7.91],[1.35,13.89]],"id":63161712}],"con":true,"img":false}]}
{"op":"mcm","clk":"11450059214","pt":1717317546343,"mc":[{"id":"1.229554899","rc":[{"atb":[[3.15,0]],"id":65732558}],"con":true,"img":false}]}
{"op":"mcm","clk":"11450059401","pt":1717317548419,"mc":[{"id":"1.229554899","rc":[{"atl":[[3.95,9.39]],"id":65732558}],"con":true,"img":false}]}
{"op":"mcm","clk":"11450059424","pt":1717317548725,"mc":[{"id":"1.229554899","rc":[{"atb":[[1.34,95.63]],"id":63161712}],"con":true,"img":false}]}
{"op":"mcm","clk":"11450059503","pt":1717317549556,"mc":[{"id":"1.229554899","rc":[{"atb":[[2.56,0],[3.05,17.39]],"id":65732558}],"con":true,"img":false}]}
{"op":"mcm","clk":"11450059526","pt":1717317549727,"mc":[{"id":"1.229554899","rc":[{"atl":[[3.85,0]],"id":65732558}],"con":true,"img":false}]}
{"op":"mcm","clk":"11450059608","pt":1717317550651,"mc":[{"id":"1.229554899","rc":[{"atb":[[1.36,7.72]],"id":63161712}],"con":true,"img":false}]}
{"op":"mcm","clk":"11450059617","pt":1717317550754,"mc":[{"id":"1.229554899","rc":[{"atb":[[1.32,0.51]],"id":63161712}],"con":true,"img":false}]}
{"op":"mcm","clk":"11450059626","pt":1717317550859,"mc":[{"id":"1.229554899","rc":[{"atl":[[3.75,10.93]],"id":65732558}],"con":true,"img":false}]}
{"op":"mcm","clk":"11450059645","pt":1717317551019,"mc":[{"id":"1.229554899","rc":[{"atl":[[3.75,0]],"id":65732558}],"con":true,"img":false}]}
{"op":"mcm","clk":"11450059659","pt":1717317551224,"mc":[{"id":"1.229554899","rc":[{"atb":[[1.36,13.7],[1.35,7.86]],"id":63161712}],"con":true,"img":false}]}
{"op":"mcm","clk":"11450059789","pt":1717317552821,"mc":[{"id":"1.229554899","rc":[{"atb":[[2.84,0],[2.96,30.14]],"id":65732558}],"con":true,"img":false}]}
{"op":"mcm","clk":"11450059862","pt":1717317553646,"mc":[{"id":"1.229554899","rc":[{"atl":[[3.75,10.93]],"id":65732558}],"con":true,"img":false}]}
{"op":"mcm","clk":"11450059994","pt":1717317554941,"mc":[{"id":"1.229554899","rc":[{"atl":[[3.95,0]],"id":65732558}],"con":true,"img":false}]}
{"op":"mcm","clk":"11450060071","pt":1717317555823,"mc":[{"id":"1.229554899","rc":[{"atb":[[1.37,7.72],[1.33,0]],"id":63161712}],"con":true,"img":false}]}
{"op":"mcm","clk":"11450060095","pt":1717317556128,"mc":[{"id":"1.229554899","rc":[{"atb":[[1.36,7.72],[1.37,13.66]],"id":63161712}],"con":true,"img":false}]}
{"op":"mcm","clk":"11450060127","pt":1717317556436,"mc":[{"id":"1.229554899","rc":[{"atl":[[3.8,9.64],[3.9,0]],"id":65732558}],"con":true,"img":false}]}
{"op":"mcm","clk":"11450060173","pt":1717317556955,"mc":[{"id":"1.229554899","rc":[{"atl":[[1.47,15.47],[1.52,0]],"id":63161712},{"atb":[[3.1,8.03],[2.6,0.57]],"id":65732558}],"con":true,"img":false}]}
{"op":"mcm","clk":"11450060189","pt":1717317557163,"mc":[{"id":"1.229554899","rc":[{"atb":[[1.34,87.72],[1.38,7.81]],"id":63161712},{"atl":[[1.47,7.77]],"id":63161712}],"con":true,"img":false}]}
{"op":"mcm","clk":"11450060199","pt":1717317557266,"mc":[{"id":"1.229554899","rc":[{"atb":[[1.36,90.56]],"id":63161712},{"atb":[[3.15,13.87]],"id":65732558}],"con":true,"img":false}]}
{"op":"mcm","clk":"11450060216","pt":1717317557432,"mc":[{"id":"1.229554899","rc":[{"atb":[[3.2,10.29],[3.1,2.81]],"id":65732558}],"con":true,"img":false}]}
{"op":"mcm","clk":"11450060265","pt":1717317557939,"mc":[{"id":"1.229554899","rc":[{"atl":[[3.6,11.23]],"id":65732558}],"con":true,"img":false}]}
{"op":"mcm","clk":"11450060290","pt":1717317558253,"mc":[{"id":"1.229554899","rc":[{"atl":[[1.47,15.48]],"id":63161712}],"con":true,"img":false}]}
{"op":"mcm","clk":"11450060308","pt":1717317558464,"mc":[{"id":"1.229554899","rc":[{"atl":[[3.8,0]],"id":65732558}],"con":true,"img":false}]}
{"op":"mcm","clk":"11450060315","pt":1717317558565,"mc":[{"id":"1.229554899","rc":[{"atl":[[1.47,7.77]],"id":63161712}],"con":true,"img":false}]}
{"op":"mcm","clk":"11450060518","pt":1717317560735,"mc":[{"id":"1.229554899","rc":[{"atb":[[3.1,0]],"id":65732558}],"con":true,"img":false}]}
{"op":"mcm","clk":"11450060525","pt":1717317560838,"mc":[{"id":"1.229554899","rc":[{"atl":[[3.75,0],[3.65,8.68]],"id":65732558}],"con":true,"img":false}]}
{"op":"mcm","clk":"11450060548","pt":1717317561047,"mc":[{"id":"1.229554899","rc":[{"atb":[[1.01,392.38],[1.05,78.47]],"id":63161712},{"atb":[[2.4,11.32],[2.6,10.47]],"id":65732558}],"con":true,"img":false}]}
{"op":"mcm","clk":"11450060558","pt":1717317561154,"mc":[{"id":"1.229554899","rc":[{"atb":[[1.37,7.72],[1.38,13.71]],"id":63161712}],"con":true,"img":false}]}
{"op":"mcm","clk":"11450060610","pt":1717317561674,"mc":[{"id":"1.229554899","rc":[{"atb":[[3.1,2.84]],"id":65732558}],"con":true,"img":false}]}
{"op":"mcm","clk":"11450060634","pt":1717317561933,"mc":[{"id":"1.229554899","rc":[{"atb":[[1.39,7.7],[1.35,0]],"id":63161712},{"atb":[[3.1,0]],"id":65732558}],"con":true,"img":false}]}
{"op":"mcm","clk":"11450060664","pt":1717317562243,"mc":[{"id":"1.229554899","rc":[{"atb":[[1.31,0]],"id":63161712},{"atb":[[3.1,14.2],[3.15,0]],"id":65732558}],"con":true,"img":false}]}
{"op":"mcm","clk":"11450060675","pt":1717317562348,"mc":[{"id":"1.229554899","rc":[{"atb":[[3.2,0],[3.15,9.96]],"id":65732558}],"con":true,"img":false}]}
{"op":"mcm","clk":"11450060686","pt":1717317562448,"mc":[{"id":"1.229554899","rc":[{"atl":[[1.47,15.53]],"id":63161712},{"atb":[[3.15,12.76]],"id":65732558}],"con":true,"img":false}]}
{"op":"mcm","clk":"11450060721","pt":1717317562864,"mc":[{"id":"1.229554899","rc":[{"atb":[[3.15,9.96]],"id":65732558}],"con":true,"img":false}]}
{"op":"mcm","clk":"11450060768","pt":1717317563231,"mc":[{"id":"1.229554899","rc":[{"atb":[[1.38,92.2]],"id":63161712}],"con":true,"img":false}]}
{"op":"mcm","clk":"11450060811","pt":1717317563640,"mc":[{"id":"1.229554899","rc":[{"atl":[[1.48,0],[1.47,7.77]],"id":63161712}],"con":true,"img":false}]}
{"op":"mcm","clk":"11450060823","pt":1717317563742,"mc":[{"id":"1.229554899","rc":[{"atl":[[1.49,15.54],[1.47,0]],"id":63161712}],"con":true,"img":false}]}
{"op":"mcm","clk":"11450060874","pt":1717317564256,"mc":[{"id":"1.229554899","rc":[{"atb":[[3.1,0]],"id":65732558}],"con":true,"img":false}]}
{"op":"mcm","clk":"11450061058","pt":1717317566368,"mc":[{"id":"1.229554899","rc":[{"atb":[[1.39,13.55],[1.38,86.3]],"id":63161712}],"con":true,"img":false}]}
{"op":"mcm","clk":"11450061159","pt":1717317567450,"mc":[{"id":"1.229554899","rc":[{"atb":[[3.1,9.96]],"id":65732558}],"con":true,"img":false}]}
{"op":"mcm","clk":"11450061167","pt":1717317567552,"mc":[{"id":"1.229554899","rc":[{"atb":[[3.15,0]],"id":65732558}],"con":true,"img":false}]}
{"op":"mcm","clk":"11450061461","pt":1717317570761,"mc":[{"id":"1.229554899","rc":[{"atb":[[1.18,0]],"id":63161712},{"atl":[[6.4,0],[10.5,10.53],[7.6,9.96],[8.4,0]],"id":65732558}],"con":true,"img":false}]}
{"op":"mcm","clk":"11450061472","pt":1717317570859,"mc":[{"id":"1.229554899","rc":[{"atb":[[1.15,7.53]],"id":63161712}],"con":true,"img":false}]}
{"op":"mcm","clk":"11450061527","pt":1717317571378,"mc":[{"id":"1.229554899","rc":[{"atl":[[1.48,7.6]],"id":63161712}],"con":true,"img":false}]}
{"op":"mcm","clk":"11450061539","pt":1717317571483,"mc":[{"id":"1.229554899","rc":[{"atb":[[1.4,7.74],[1.36,82.84]],"id":63161712},{"atl":[[1.47,7.6]],"id":63161712}],"con":true,"img":false}]}
{"op":"mcm","clk":"11450061543","pt":1717317571588,"mc":[{"id":"1.229554899","rc":[{"atl":[[1.49,0]],"id":63161712}],"con":true,"img":false}]}
{"op":"mcm","clk":"11450061549","pt":1717317571690,"mc":[{"id":"1.229554899","rc":[{"atl":[[3.5,14.22]],"id":65732558}],"con":true,"img":false}]}
{"op":"mcm","clk":"11450061570","pt":1717317571901,"mc":[{"id":"1.229554899","rc":[{"atl":[[3.65,0]],"id":65732558}],"con":true,"img":false}]}
{"op":"mcm","clk":"11450061617","pt":1717317572393,"mc":[{"id":"1.229554899","rc":[{"atb":[[1.4,12.98],[1.39,7.7]],"id":63161712}],"con":true,"img":false}]}
{"op":"mcm","clk":"11450061807","pt":1717317574260,"mc":[{"id":"1.229554899","rc":[{"atb":[[2.84,32.47],[2.96,0]],"id":65732558}],"con":true,"img":false}]}
{"op":"mcm","clk":"11450061999","pt":1717317576380,"mc":[{"id":"1.229554899","rc":[{"atl":[[1.48,0]],"id":63161712}],"con":true,"img":false}]}
{"op":"mcm","clk":"11450062006","pt":1717317576483,"mc":[{"id":"1.229554899","rc":[{"atl":[[1.49,15.2],[1.47,0]],"id":63161712}],"con":true,"img":false}]}
{"op":"mcm","clk":"11450062028","pt":1717317576690,"mc":[{"id":"1.229554899","rc":[{"atb":[[1.37,0],[1.41,7.66]],"id":63161712}],"con":true,"img":false}]}
{"op":"mcm","clk":"11450062042","pt":1717317576898,"mc":[{"id":"1.229554899","rc":[{"atb":[[3.05,14.54]],"id":65732558}],"con":true,"img":false}]}
{"op":"mcm","clk":"11450062146","pt":1717317578189,"mc":[{"id":"1.229554899","rc":[{"atb":[[1.41,12.86],[1.4,7.74]],"id":63161712}],"con":true,"img":false}]}
{"op":"mcm","clk":"11450062699","pt":1717317584563,"mc":[{"id":"1.229554899","rc":[{"atl":[[1.5,0]],"id":63161712}],"con":true,"img":false}]}
{"op":"mcm","clk":"11450062710","pt":1717317584667,"mc":[{"id":"1.229554899","rc":[{"atl":[[1.5,30.4],[1.49,0]],"id":63161712}],"con":true,"img":false}]}
{"op":"mcm","clk":"11450062719","pt":1717317584768,"mc":[{"id":"1.229554899","rc":[{"atb":[[1.42,7.42]],"id":63161712}],"con":true,"img":false}]}
{"op":"mcm","clk":"11450062726","pt":1717317584872,"mc":[{"id":"1.229554899","rc":[{"atb":[[1.38,78.49]],"id":63161712}],"con":true,"img":false}]}
{"op":"mcm","clk":"11450062785","pt":1717317585491,"mc":[{"id":"1.229554899","rc":[{"atb":[[3,2.9]],"id":65732558}],"con":true,"img":false}]}
{"op":"mcm","clk":"11450062898","pt":1717317586690,"mc":[{"id":"1.229554899","rc":[{"atb":[[1.41,7.66],[1.42,12.58]],"id":63161712}],"con":true,"img":false}]}
{"op":"mcm","clk":"11450062934","pt":1717317587105,"mc":[{"id":"1.229554899","rc":[{"atb":[[1.43,7.42],[1.39,0]],"id":63161712},{"atb":[[3,0]],"id":65732558}],"con":true,"img":false}]}
{"op":"mcm","clk":"11450062943","pt":1717317587208,"mc":[{"id":"1.229554899","rc":[{"atb":[[2.98,17.98]],"id":65732558}],"con":true,"img":false}]}
{"op":"mcm","clk":"11450063019","pt":1717317587988,"mc":[{"id":"1.229554899","rc":[{"atb":[[3,2.89]],"id":65732558}],"con":true,"img":false}]}
{"op":"mcm","clk":"11450063185","pt":1717317589805,"mc":[{"id":"1.229554899","rc":[{"atl":[[1000,3.24]],"id":65732558}],"con":true,"img":false}]}
{"op":"mcm","clk":"11450063204","pt":1717317589966,"mc":[{"id":"1.229554899","rc":[{"atl":[[1000,3.87]],"id":63161712}],"con":true,"img":false}]}
{"op":"mcm","clk":"11450063278","pt":1717317590799,"mc":[{"id":"1.229554899","rc":[{"atl":[[1000,0.63]],"id":65732558}],"con":true,"img":false}]}
{"op":"mcm","clk":"11450063303","pt":1717317591111,"mc":[{"id":"1.229554899","rc":[{"atl":[[1000,1.25]],"id":63161712}],"con":true,"img":false}]}
{"op":"mcm","clk":"11450063369","pt":1717317591788,"mc":[{"id":"1.229554899","rc":[{"atb":[[1.43,12.55],[1.42,7.42]],"id":63161712},{"atl":[[1000,0.17]],"id":65732558}],"con":true,"img":false}]}
{"op":"mcm","clk":"11450063378","pt":1717317591893,"mc":[{"id":"1.229554899","rc":[{"atl":[[3.6,11.69]],"id":65732558}],"con":true,"img":false}]}
{"op":"mcm","clk":"11450063396","pt":1717317592102,"mc":[{"id":"1.229554899","rc":[{"atl":[[1000,0.17]],"id":63161712}],"con":true,"img":false}]}
{"op":"mcm","clk":"11450063404","pt":1717317592205,"mc":[{"id":"1.229554899","rc":[{"atl":[[1.52,1.07]],"id":63161712}],"con":true,"img":false}]}
{"op":"mcm","clk":"11450063665","pt":1717317595202,"mc":[{"id":"1.229554899","rc":[{"atl":[[1.47,24.72]],"id":63161712}],"con":true,"img":false}]}
{"op":"mcm","clk":"11450063675","pt":1717317595305,"mc":[{"id":"1.229554899","rc":[{"atl":[[1.46,24.72],[1.49,7.46]],"id":63161712},{"atb":[[2.64,0],[3.05,17.42]],"id":65732558}],"con":true,"img":false}]}
{"op":"mcm","clk":"11450063681","pt":1717317595408,"mc":[{"id":"1.229554899","rc":[{"atl":[[1.5,0],[1.47,0]],"id":63161712}],"con":true,"img":false}]}
{"op":"mcm","clk":"11450063689","pt":1717317595511,"mc":[{"id":"1.229554899","rc":[{"atl":[[1.48,49.44]],"id":63161712}],"con":true,"img":false}]}
{"op":"mcm","clk":"11450063701","pt":1717317595616,"mc":[{"id":"1.229554899","rc":[{"atl":[[1.46,0]],"id":63161712}],"con":true,"img":false}]}
{"op":"mcm","clk":"11450063779","pt":1717317596499,"mc":[{"id":"1.229554899","rc":[{"atb":[[3.05,14.54]],"id":65732558}],"con":true,"img":false}]}
{"op":"mcm","clk":"11450063825","pt":1717317597016,"mc":[{"id":"1.229554899","rc":[{"atl":[[1.49,0]],"id":63161712}],"con":true,"img":false}]}
{"op":"mcm","clk":"11450063851","pt":1717317597291,"mc":[{"id":"1.229554899","rc":[{"atb":[[1.44,7.5],[1.4,0]],"id":63161712}],"con":true,"img":false}]}
{"op":"mcm","clk":"11450063867","pt":1717317597489,"mc":[{"id":"1.229554899","rc":[{"atb":[[1.01,0],[1.05,0]],"id":63161712},{"atb":[[2.4,0],[2.6,0.57]],"id":65732558},{"atl":[[3.5,0]],"id":65732558}],"con":true,"img":false}]}
{"op":"mcm","clk":"11450063879","pt":1717317597594,"mc":[{"id":"1.229554899","rc":[{"atl":[[1.5,98.88],[1.48,0]],"id":63161712}],"con":true,"img":false}]}
{"op":"mcm","clk":"11450063886","pt":1717317597698,"mc":[{"id":"1.229554899","rc":[{"atb":[[1.32,93.71]],"id":63161712},{"atl":[[1.47,24.72]],"id":63161712}],"con":true,"img":false}]}
{"op":"mcm","clk":"11450063896","pt":1717317597802,"mc":[{"id":"1.229554899","rc":[{"atb":[[1.36,0],[1.34,0],[1.38,0]],"id":63161712},{"atb":[[3.05,0]],"id":65732558}],"con":true,"img":false}]}
{"op":"mcm","clk":"11450063898","pt":1717317597904,"mc":[{"id":"1.229554899","rc":[{"atb":[[1.44,0]],"id":63161712},{"atb":[[3.1,0],[3,5.99]],"id":65732558}],"con":true,"img":false}]}
{"op":"mcm","clk":"11450063913","pt":1717317598116,"mc":[{"id":"1.229554899","rc":[{"atl":[[1.47,0]],"id":63161712}],"con":true,"img":false}]}
{"op":"mcm","clk":"11450063921","pt":1717317598218,"mc":[{"id":"1.229554899","rc":[{"atb":[[1.32,0.51]],"id":63161712},{"atl":[[1.49,7.45]],"id":63161712},{"atb":[[2.98,2.91]],"id":65732558}],"con":true,"img":false}]}
{"op":"mcm","clk":"11450064074","pt":1717317599998,"mc":[{"id":"1.229554899","rc":[{"atl":[[1.49,0]],"id":63161712}],"con":true,"img":false}]}
{"op":"mcm","clk":"11450064092","pt":1717317600204,"mc":[{"id":"1.229554899","rc":[{"atl":[[1.48,24.23]],"id":63161712},{"atb":[[3.05,3.97]],"id":65732558}],"con":true,"img":false}]}
{"op":"mcm","clk":"11450064100","pt":1717317600310,"mc":[{"id":"1.229554899","rc":[{"atb":[[3.1,3.1],[3,2.89]],"id":65732558}],"con":true,"img":false}]}
{"op":"mcm","clk":"11450064107","pt":1717317600412,"mc":[{"id":"1.229554899","rc":[{"atl":[[1.48,0]],"id":63161712},{"atb":[[3.05,0]],"id":65732558}],"con":true,"img":false}]}
{"op":"mcm","clk":"11450064117","pt":1717317600517,"mc":[{"id":"1.229554899","rc":[{"atb":[[3.1,0],[3,5.79]],"id":65732558},{"atl":[[3.6,0.45]],"id":65732558}],"con":true,"img":false}]}
{"op":"mcm","clk":"11450064126","pt":1717317600623,"mc":[{"id":"1.229554899","rc":[{"atb":[[2.6,0]],"id":65732558}],"con":true,"img":false}]}
{"op":"mcm","clk":"11450064133","pt":1717317600681,"mc":[{"id":"1.229554899","rc":[{"atb":[[2.86,0.57]],"id":65732558}],"con":true,"img":false}]}
{"op":"mcm","clk":"11450064199","pt":1717317601409,"mc":[{"id":"1.229554899","rc":[{"atl":[[1.52,0]],"id":63161712}],"con":true,"img":false}]}
{"op":"mcm","clk":"11450064207","pt":1717317601511,"mc":[{"id":"1.229554899","rc":[{"atl":[[1.53,1.07]],"id":63161712}],"con":true,"img":false}]}
{"op":"mcm","clk":"11450064268","pt":1717317602205,"mc":[{"id":"1.229554899","rc":[{"atl":[[1.49,7.46]],"id":63161712}],"con":true,"img":false}]}
{"op":"mcm","clk":"11450064278","pt":1717317602300,"mc":[{"id":"1.229554899","rc":[{"atl":[[1.48,7.46]],"id":63161712}],"con":true,"img":false}]}
{"op":"mcm","clk":"11450064288","pt":1717317602395,"mc":[{"id":"1.229554899","rc":[{"atl":[[1.5,0]],"id":63161712}],"con":true,"img":false}]}
{"op":"mcm","clk":"11450064324","pt":1717317602707,"mc":[{"id":"1.229554899","rc":[{"atl":[[1.49,31.16]],"id":63161712},{"atb":[[3.05,2.86]],"id":65732558},{"atl":[[3.4,10.84]],"id":65732558}],"con":true,"img":false}]}
{"op":"mcm","clk":"11450064347","pt":1717317602914,"mc":[{"id":"1.229554899","rc":[{"atl":[[1.49,23.7]],"id":63161712}],"con":true,"img":false}]}
{"op":"mcm","clk":"11450064359","pt":1717317603021,"mc":[{"id":"1.229554899","rc":[{"atb":[[1.44,7.3]],"id":63161712},{"atl":[[1.51,0]],"id":63161712},{"atb":[[3,2.9],[2.98,0],[3.05,0]],"id":65732558},{"atl":[[3.6,0]],"id":65732558}],"con":true,"img":false}]}
{"op":"mcm","clk":"11450064370","pt":1717317603125,"mc":[{"id":"1.229554899","rc":[{"atb":[[2.86,3.51]],"id":65732558},{"atl":[[3.5,0.45]],"id":65732558}],"con":true,"img":false}]}
{"op":"mcm","clk":"11450064382","pt":1717317603228,"mc":[{"id":"1.229554899","rc":[{"atb":[[1.44,0]],"id":63161712},{"atl":[[1.53,8.51]],"id":63161712},{"atb":[[3,5.78]],"id":65732558}],"con":true,"img":false}]}
{"op":"mcm","clk":"11450064434","pt":1717317603750,"mc":[{"id":"1.229554899","rc":[{"atb":[[1.44,7.52]],"id":63161712}],"con":true,"img":false}]}
{"op":"mcm","clk":"11450064610","pt":1717317605711,"mc":[{"id":"1.229554899","rc":[{"atb":[[2.9,11.56],[2.84,0]],"id":65732558}],"con":true,"img":false}]}
{"op":"mcm","clk":"11450064618","pt":1717317605814,"mc":[{"id":"1.229554899","rc":[{"atl":[[3.5,0]],"id":65732558}],"con":true,"img":false}]}
{"op":"mcm","clk":"11450064625","pt":1717317605917,"mc":[{"id":"1.229554899","rc":[{"atl":[[3.55,0.45]],"id":65732558}],"con":true,"img":false}]}
{"op":"mcm","clk":"11450064641","pt":1717317606122,"mc":[{"id":"1.229554899","rc":[{"atl":[[1.53,7.43]],"id":63161712}],"con":true,"img":false}]}
{"op":"mcm","clk":"11450064646","pt":1717317606225,"mc":[{"id":"1.229554899","rc":[{"atl":[[1.54,1.07]],"id":63161712}],"con":true,"img":false}]}
{"op":"mcm","clk":"11450064700","pt":1717317606796,"mc":[{"id":"1.229554899","rc":[{"atb":[[1.44,12.61],[1.43,7.42]],"id":63161712}],"con":true,"img":false}]}
{"op":"mcm","clk":"11450064880","pt":1717317608912,"mc":[{"id":"1.229554899","rc":[{"atl":[[1.5,8.4]],"id":63161712}],"con":true,"img":false}]}
{"op":"mcm","clk":"11450064942","pt":1717317609544,"mc":[{"id":"1.229554899","rc":[{"atb":[[1.45,7.08]],"id":63161712},{"atb":[[3,2.9]],"id":65732558}],"con":true,"img":false}]}
{"op":"mcm","clk":"11450064952","pt":1717317609651,"mc":[{"id":"1.229554899","rc":[{"atb":[[1.41,0]],"id":63161712},{"atl":[[1.53,0]],"id":63161712}],"con":true,"img":false}]}
{"op":"mcm","clk":"11450064959","pt":1717317609698,"mc":[{"id":"1.229554899","rc":[{"atb":[[2.88,16.46],[2.9,0],[3,0]],"id":65732558}],"con":true,"img":false}]}
{"op":"mcm","clk":"11450064977","pt":1717317609906,"mc":[{"id":"1.229554899","rc":[{"atl":[[1.49,0]],"id":63161712}],"con":true,"img":false}]}
{"op":"mcm","clk":"11450064988","pt":1717317610004,"mc":[{"id":"1.229554899","rc":[{"atl":[[1.49,14.92],[1.48,0]],"id":63161712}],"con":true,"img":false}]}
{"op":"mcm","clk":"11450065014","pt":1717317610312,"mc":[{"id":"1.229554899","rc":[{"atl":[[1.53,21.06]],"id":63161712}],"con":true,"img":false}]}
{"op":"mcm","clk":"11450065035","pt":1717317610517,"mc":[{"id":"1.229554899","rc":[{"atl":[[1.54,8.07]],"id":63161712}],"con":true,"img":false}]}
{"op":"mcm","clk":"11450065049","pt":1717317610726,"mc":[{"id":"1.229554899","rc":[{"atl":[[1.54,6.99]],"id":63161712},{"atb":[[2.86,0.57]],"id":65732558}],"con":true,"img":false}]}
{"op":"mcm","clk":"11450065054","pt":1717317610829,"mc":[{"id":"1.229554899","rc":[{"atl":[[1.55,1.07],[1.54,0]],"id":63161712},{"atb":[[2.88,2],[2.7,19.03]],"id":65732558}],"con":true,"img":false}]}
{"op":"mcm","clk":"11450065062","pt":1717317610932,"mc":[{"id":"1.229554899","rc":[{"atb":[[2.88,0]],"id":65732558}],"con":true,"img":false}]}
{"op":"mcm","clk":"11450065089","pt":1717317611240,"mc":[{"id":"1.229554899","rc":[{"atl":[[3.55,0]],"id":65732558}],"con":true,"img":false}]}
{"op":"mcm","clk":"11450065095","pt":1717317611300,"mc":[{"id":"1.229554899","rc":[{"atl":[[3.5,0.45]],"id":65732558}],"con":true,"img":false}]}
{"op":"mcm","clk":"11450065106","pt":1717317611403,"mc":[{"id":"1.229554899","rc":[{"atb":[[2.86,0]],"id":65732558}],"con":true,"img":false}]}
{"op":"mcm","clk":"11450065131","pt":1717317611708,"mc":[{"id":"1.229554899","rc":[{"trd":[[1.49,47.77]],"ltp":1.49,"tv":47.77,"id":63161712},{"atl":[[1.49,7.05]],"id":63161712}],"con":true,"img":false}]}
{"op":"mcm","clk":"11450065140","pt":1717317611813,"mc":[{"id":"1.229554899","rc":[{"atb":[[1.45,14.16]],"id":63161712},{"atb":[[2.72,3.03],[1.03,1.71]],"id":65732558}],"con":true,"img":false}]}
{"op":"mcm","clk":"11450065148","pt":1717317611918,"mc":[{"id":"1.229554899","rc":[{"atb":[[1.44,7.52]],"id":63161712},{"atl":[[1.5,0],[1.53,0]],"id":63161712},{"atb":[[1.03,0.71]],"id":65732558},{"atl":[[9.2,6.58],[10.5,0]],"id":65732558}],"con":true,"img":false}]}
{"op":"mcm","clk":"11450065161","pt":1717317612080,"mc":[{"id":"1.229554899","rc":[{"atb":[[1.01,392.38],[1.03,136.52]],"id":63161712},{"atb":[[2.68,12.39],[2.48,10.71]],"id":65732558}],"con":true,"img":false}]}
{"op":"mcm","clk":"11450065165","pt":1717317612131,"mc":[{"id":"1.229554899","rc":[{"atb":[[1.03,0]],"id":65732558}],"con":true,"img":false}]}
{"op":"mcm","clk":"11450065174","pt":1717317612233,"mc":[{"id":"1.229554899","rc":[{"atb":[[1.45,12.57]],"id":63161712},{"trd":[[1.45,1.59]],"ltp":1.45,"tv":1.59,"id":63161712},{"atb":[[2.72,20.38]],"id":65732558},{"trd":[[3.25,0.71]],"ltp":3.25,"tv":0.71,"id":65732558}],"con":true,"img":false}]}
{"op":"mcm","clk":"11450065206","pt":1717317612599,"mc":[{"id":"1.229554899","rc":[{"atb":[[2.72,21.23]],"id":65732558},{"atl":[[3.3,8.18]],"id":65732558}],"con":true,"img":false}]}
{"op":"mcm","clk":"11450065266","pt":1717317613222,"mc":[{"id":"1.229554899","rc":[{"atb":[[1.42,78.43]],"id":63161712}],"con":true,"img":false}]}
{"op":"mcm","clk":"11450065324","pt":1717317613834,"mc":[{"id":"1.229554899","rc":[{"atb":[[2.72,20.95]],"id":65732558}],"con":true,"img":false}]}
{"op":"mcm","clk":"11450065333","pt":1717317613940,"mc":[{"id":"1.229554899","rc":[{"atl":[[3.2,9.83]],"id":65732558}],"con":true,"img":false}]}
{"op":"mcm","clk":"11450065525","pt":1717317615962,"mc":[{"id":"1.229554899","rc":[{"atb":[[2.74,29.37],[2.7,0]],"id":65732558}],"con":true,"img":false}]}
{"op":"mcm","clk":"11450065553","pt":1717317616125,"mc":[{"id":"1.229554899","rc":[{"atb":[[2.76,3.07]],"id":65732558}],"con":true,"img":false}]}
{"op":"mcm","clk":"11450065567","pt":1717317616231,"mc":[{"id":"1.229554899","rc":[{"atb":[[2.72,20.38],[2.74,0],[2.78,29.96],[2.76,20.02]],"id":65732558},{"atl":[[3.4,0],[3.25,7.13]],"id":65732558}],"con":true,"img":false}]}
{"op":"mcm","clk":"11450065578","pt":1717317616324,"mc":[{"id":"1.229554899","rc":[{"atb":[[2.76,20.59]],"id":65732558}],"con":true,"img":false}]}
{"op":"mcm","clk":"11450065592","pt":1717317616428,"mc":[{"id":"1.229554899","rc":[{"atl":[[3.2,0]],"id":65732558}],"con":true,"img":false}]}
{"op":"mcm","clk":"11450065638","pt":1717317616846,"mc":[{"id":"1.229554899","rc":[{"atl":[[1.55,15.17],[1.49,0]],"id":63161712},{"atb":[[2.8,3.06]],"id":65732558}],"con":true,"img":false}]}
{"op":"mcm","clk":"11450065646","pt":1717317616946,"mc":[{"id":"1.229554899","rc":[{"atl":[[1.86,8.13]],"id":63161712}],"con":true,"img":false}]}
{"op":"mcm","clk":"11450065653","pt":1717317617052,"mc":[{"id":"1.229554899","rc":[{"atl":[[1.55,1.07]],"id":63161712},{"atb":[[2.82,25.69],[2.78,0]],"id":65732558}],"con":true,"img":false}]}
{"op":"mcm","clk":"11450065676","pt":1717317617259,"mc":[{"id":"1.229554899","rc":[{"atb":[[2.84,16.2]],"id":65732558}],"con":true,"img":false}]}
{"op":"mcm","clk":"11450065686","pt":1717317617315,"mc":[{"id":"1.229554899","rc":[{"atb":[[2.86,16.21]],"id":65732558}],"con":true,"img":false}]}
{"op":"mcm","clk":"11450065697","pt":1717317617467,"mc":[{"id":"1.229554899","rc":[{"atb":[[2.82,5.1]],"id":65732558}],"con":true,"img":false}]}
{"op":"mcm","clk":"11450065706","pt":1717317617526,"mc":[{"id":"1.229554899","rc":[{"atl":[[2.02,8.72],[2.06,11.19],[1.85,6.79],[2.1,13.48],[2.14,15.6]],"id":63161712}],"con":true,"img":false}]}
{"op":"mcm","clk":"11450065717","pt":1717317617625,"mc":[{"id":"1.229554899","rc":[{"atl":[[1.55,7.87],[1.86,0]],"id":63161712}],"con":true,"img":false}]}
{"op":"mcm","clk":"11450065729","pt":1717317617728,"mc":[{"id":"1.229554899","rc":[{"atl":[[1.55,1.07],[1.84,8.13]],"id":63161712},{"atb":[[2.72,3.03]],"id":65732558}],"con":true,"img":false}]}
{"op":"mcm","clk":"11450065739","pt":1717317617834,"mc":[{"id":"1.229554899","rc":[{"atl":[[1.55,8.95],[1.84,0]],"id":63161712}],"con":true,"img":false}]}
{"op":"mcm","clk":"11450065746","pt":1717317617938,"mc":[{"id":"1.229554899","rc":[{"atb":[[2.82,17.95]],"id":65732558}],"con":true,"img":false}]}
{"op":"mcm","clk":"11450065774","pt":1717317618208,"mc":[{"id":"1.229554899","rc":[{"atb":[[2.88,15.86]],"id":65732558}],"con":true,"img":false}]}
{"op":"mcm","clk":"11450065782","pt":1717317618308,"mc":[{"id":"1.229554899","rc":[{"atb":[[2.86,0],[2.9,16.21]],"id":65732558},{"atl":[[3.5,0]],"id":65732558}],"con":true,"img":false}]}
{"op":"mcm","clk":"11450065789","pt":1717317618419,"mc":[{"id":"1.229554899","rc":[{"atl":[[3.05,0.45]],"id":65732558}],"con":true,"img":false}]}
{"op":"mcm","clk":"11450065813","pt":1717317618730,"mc":[{"id":"1.229554899","rc":[{"atb":[[2.76,3.64]],"id":65732558}],"con":true,"img":false}]}
{"op":"mcm","clk":"11450065829","pt":1717317618935,"mc":[{"id":"1.229554899","rc":[{"atl":[[1.52,23.83]],"id":63161712}],"con":true,"img":false}]}
{"op":"mcm","clk":"11450065837","pt":1717317619036,"mc":[{"id":"1.229554899","rc":[{"atl":[[1.55,15.8]],"id":63161712}],"con":true,"img":false}]}
{"op":"mcm","clk":"11450065844","pt":1717317619139,"mc":[{"id":"1.229554899","rc":[{"atl":[[1.55,7.92],[1.51,8.96]],"id":63161712}],"con":true,"img":false}]}
{"op":"mcm","clk":"11450065853","pt":1717317619245,"mc":[{"id":"1.229554899","rc":[{"atb":[[2.92,15.53]],"id":65732558}],"con":true,"img":false}]}
{"op":"mcm","clk":"11450066113","pt":1717317622152,"mc":[{"id":"1.229554899","rc":[{"atb":[[2.82,12.85],[2.94,7.66]],"id":65732558}],"con":true,"img":false}]}
{"op":"mcm","clk":"11450066149","pt":1717317622522,"mc":[{"id":"1.229554899","rc":[{"atb":[[2.86,3.01],[2.68,9.43]],"id":65732558}],"con":true,"img":false}]}
{"op":"mcm","clk":"11450066659","pt":1717317628741,"mc":[{"id":"1.229554899","rc":[{"atl":[[1000,2.8]],"id":65732558}],"con":true,"img":false}]}
{"op":"mcm","clk":"11450066767","pt":1717317629731,"mc":[{"id":"1.229554899","rc":[{"atl":[[1000,0.18]],"id":65732558}],"con":true,"img":false}]}
{"op":"mcm","clk":"11450066857","pt":1717317630858,"mc":[{"id":"1.229554899","rc":[{"atl":[[1000,0.17]],"id":65732558}],"con":true,"img":false}]}
{"op":"mcm","clk":"11450066865","pt":1717317630964,"mc":[{"id":"1.229554899","rc":[{"atl":[[3.9,0.01]],"id":65732558}],"con":true,"img":false}]}
{"op":"mcm","clk":"11450066874","pt":1717317631068,"mc":[{"id":"1.229554899","rc":[{"atl":[[1000,1.07]],"id":63161712}],"con":true,"img":false}]}
{"op":"mcm","clk":"11450066903","pt":1717317631341,"mc":[{"id":"1.229554899","rc":[{"atl":[[1000,0.32]],"id":63161712}],"con":true,"img":false}]}
{"op":"mcm","clk":"11450066941","pt":1717317631744,"mc":[{"id":"1.229554899","rc":[{"atl":[[1000,0.17]],"id":63161712}],"con":true,"img":false}]}
{"op":"mcm","clk":"11450066952","pt":1717317631849,"mc":[{"id":"1.229554899","rc":[{"trd":[[1.48,13.26]],"ltp":1.48,"tv":13.26,"id":63161712},{"trd":[[3.05,6.43]],"ltp":3.05,"tv":6.43,"id":65732558},{"atl":[[3.05,0.38]],"id":65732558}],"con":true,"img":false}]}
{"op":"mcm","clk":"11450066971","pt":1717317632055,"mc":[{"id":"1.229554899","rc":[{"atb":[[2.72,0],[2.92,18.5]],"id":65732558}],"con":true,"img":false}]}
{"op":"mcm","clk":"11450067124","pt":1717317633665,"mc":[{"id":"1.229554899","rc":[{"atb":[[2.92,15.53],[2.86,0]],"id":65732558}],"con":true,"img":false}]}
{"op":"mcm","clk":"11450067136","pt":1717317633768,"mc":[{"id":"1.229554899","rc":[{"atb":[[2.9,0],[2.94,23.87]],"id":65732558}],"con":true,"img":false}]}
{"op":"mcm","clk":"11450067143","pt":1717317633872,"mc":[{"id":"1.229554899","rc":[{"atb":[[2.86,3.01]],"id":65732558}],"con":true,"img":false}]}
{"op":"mcm","clk":"11450067153","pt":1717317633976,"mc":[{"id":"1.229554899","rc":[{"atl":[[3.25,0]],"id":65732558}],"con":true,"img":false}]}
{"op":"mcm","clk":"11450067178","pt":1717317634246,"mc":[{"id":"1.229554899","rc":[{"atb":[[1.42,7.42]],"id":63161712},{"atb":[[2.92,0],[2.88,0],[2.84,0]],"id":65732558}],"con":true,"img":false}]}
{"op":"mcm","clk":"11450067196","pt":1717317634470,"mc":[{"id":"1.229554899","rc":[{"atl":[[1.5,24.15]],"id":63161712},{"atb":[[2.88,2],[2.94,16.21]],"id":65732558}],"con":true,"img":false}]}
{"op":"mcm","clk":"11450067202","pt":1717317634548,"mc":[{"id":"1.229554899","rc":[{"atl":[[1.49,23.83]],"id":63161712}],"con":true,"img":false}]}
{"op":"mcm","clk":"11450067213","pt":1717317634653,"mc":[{"id":"1.229554899","rc":[{"atl":[[1.5,0],[1.51,0]],"id":63161712},{"atb":[[2.88,4.99]],"id":65732558}],"con":true,"img":false}]}
{"op":"mcm","clk":"11450067218","pt":1717317634756,"mc":[{"id":"1.229554899","rc":[{"atl":[[1.51,47.66]],"id":63161712},{"atl":[[3.3,0]],"id":65732558}],"con":true,"img":false}]}
{"op":"mcm","clk":"11450067228","pt":1717317634858,"mc":[{"id":"1.229554899","rc":[{"atl":[[1.49,0]],"id":63161712}],"con":true,"img":false}]}
{"op":"mcm","clk":"11450067319","pt":1717317635845,"mc":[{"id":"1.229554899","rc":[{"atb":[[2.88,37.41],[2.94,0]],"id":65732558}],"con":true,"img":false}]}
{"op":"mcm","clk":"11450067331","pt":1717317636048,"mc":[{"id":"1.229554899","rc":[{"atl":[[1.5,7.35]],"id":63161712},{"atb":[[2.9,2.9]],"id":65732558}],"con":true,"img":false}]}
{"op":"mcm","clk":"11450067340","pt":1717317636152,"mc":[{"id":"1.229554899","rc":[{"atb":[[1.45,7.08]],"id":63161712},{"atb":[[2.76,0.57]],"id":65732558}],"con":true,"img":false}]}
{"op":"mcm","clk":"11450067378","pt":1717317636669,"mc":[{"id":"1.229554899","rc":[{"atb":[[2.94,12.32]],"id":65732558},{"atl":[[3.9,0]],"id":65732558}],"con":true,"img":false}]}
{"op":"mcm","clk":"11450067383","pt":1717317636773,"mc":[{"id":"1.229554899","rc":[{"atb":[[1.44,0]],"id":63161712},{"atb":[[2.88,35.41],[2.96,2.96]],"id":65732558},{"atl":[[4,0.01]],"id":65732558}],"con":true,"img":false}]}
{"op":"mcm","clk":"11450067400","pt":1717317636981,"mc":[{"id":"1.229554899","rc":[{"atb":[[2.8,0],[2.98,2.87]],"id":65732558}],"con":true,"img":false}]}
{"op":"mcm","clk":"11450067413","pt":1717317637038,"mc":[{"id":"1.229554899","rc":[{"atb":[[2.82,0]],"id":65732558},{"trd":[[3.05,7.19]],"ltp":3.05,"tv":7.19,"id":65732558},{"atl":[[3.05,0]],"id":65732558}],"con":true,"img":false}]}
{"op":"mcm","clk":"11450067433","pt":1717317637246,"mc":[{"id":"1.229554899","rc":[{"atb":[[1.45,0],[1.43,0]],"id":63161712}],"con":true,"img":false}]}
{"op":"mcm","clk":"11450067444","pt":1717317637352,"mc":[{"id":"1.229554899","rc":[{"atb":[[1.43,7.18]],"id":63161712},{"atb":[[2.94,0]],"id":65732558}],"con":true,"img":false}]}
{"op":"mcm","clk":"11450067453","pt":1717317637449,"mc":[{"id":"1.229554899","rc":[{"atb":[[1.43,0],[1.42,14.65]],"id":63161712}],"con":true,"img":false}]}
{"op":"mcm","clk":"11450067485","pt":1717317637869,"mc":[{"id":"1.229554899","rc":[{"atb":[[2.76,0]],"id":65732558}],"con":true,"img":false}]}
{"op":"mcm","clk":"11450067497","pt":1717317637973,"mc":[{"id":"1.229554899","rc":[{"atb":[[2.9,3.47]],"id":65732558}],"con":true,"img":false}]}
{"op":"mcm","clk":"11450067590","pt":1717317638860,"mc":[{"id":"1.229554899","rc":[{"atb":[[2.88,2.99],[2.98,5.83]],"id":65732558}],"con":true,"img":false}]}
{"op":"mcm","clk":"11450067601","pt":1717317638965,"mc":[{"id":"1.229554899","rc":[{"atb":[[2.92,2],[2.96,0]],"id":65732558}],"con":true,"img":false}]}
{"op":"mcm","clk":"11450067617","pt":1717317639172,"mc":[{"id":"1.229554899","rc":[{"atl":[[1.49,24.32]],"id":63161712}],"con":true,"img":false}]}
{"op":"mcm","clk":"11450067693","pt":1717317639853,"mc":[{"id":"1.229554899","rc":[{"atl":[[1.48,24.33]],"id":63161712}],"con":true,"img":false}]}
{"op":"mcm","clk":"11450067705","pt":1717317639954,"mc":[{"id":"1.229554899","rc":[{"atl":[[1.55,6.84],[1.51,0]],"id":63161712}],"con":true,"img":false}]}
{"op":"mcm","clk":"11450067718","pt":1717317640056,"mc":[{"id":"1.229554899","rc":[{"atl":[[1.52,24.91]],"id":63161712}],"con":true,"img":false}]}
{"op":"mcm","clk":"11450067736","pt":1717317640265,"mc":[{"id":"1.229554899","rc":[{"atl":[[4,0]],"id":65732558}],"con":true,"img":false}]}
{"op":"mcm","clk":"11450067746","pt":1717317640367,"mc":[{"id":"1.229554899","rc":[{"atl":[[3.5,0.01]],"id":65732558}],"con":true,"img":false}]}
{"op":"mcm","clk":"11450067759","pt":1717317640473,"mc":[{"id":"1.229554899","rc":[{"atb":[[1.42,12.25]],"id":63161712},{"trd":[[1.42,2.39]],"ltp":1.42,"tv":2.39,"id":63161712},{"trd":[[3.4,1]],"ltp":3.4,"tv":1.0,"id":65732558}],"con":true,"img":false}]}
{"op":"mcm","clk":"11450067764","pt":1717317640575,"mc":[{"id":"1.229554899","rc":[{"atb":[[1.42,0.17]],"id":63161712},{"trd":[[1.42,26.57]],"ltp":1.42,"tv":26.57,"id":63161712},{"atb":[[2.86,0],[3,2.86]],"id":65732558}],"con":true,"img":false}]}
{"op":"mcm","clk":"11450067781","pt":1717317640780,"mc":[{"id":"1.229554899","rc":[{"atb":[[1.42,0]],"id":63161712},{"atb":[[2.98,17.99]],"id":65732558}],"con":true,"img":false}]}
{"op":"mcm","clk":"11450067791","pt":1717317640883,"mc":[{"id":"1.229554899","rc":[{"atb":[[1.12,166.67],[1.14,107.14],[1.32,0],[1.1,250],[1.08,250],[1.04,24.91]],"id":63161712}],"con":true,"img":false}]}
{"op":"mcm","clk":"11450067796","pt":1717317640987,"mc":[{"id":"1.229554899","rc":[{"atb":[[1.12,167.18],[1.11,0],[1.1,500]],"id":63161712},{"atl":[[1.52,1.07]],"id":63161712},{"atb":[[3,4.91]],"id":65732558}],"con":true,"img":false}]}
{"op":"mcm","clk":"11450067804","pt":1717317641044,"mc":[{"id":"1.229554899","rc":[{"atl":[[9.2,0],[11.5,6.58]],"id":65732558}],"con":true,"img":false}]}
{"op":"mcm","clk":"11450067821","pt":1717317641252,"mc":[{"id":"1.229554899","rc":[{"atl":[[1.47,0.79]],"id":63161712}],"con":true,"img":false}]}
{"op":"mcm","clk":"11450067837","pt":1717317641454,"mc":[{"id":"1.229554899","rc":[{"atb":[[1.12,166.67]],"id":63161712},{"atb":[[2.9,2.9]],"id":65732558},{"atl":[[4.1,14.62]],"id":65732558}],"con":true,"img":false}]}
{"op":"mcm","clk":"11450067846","pt":1717317641560,"mc":[{"id":"1.229554899","rc":[{"atb":[[1.15,8.04],[1.16,1.96]],"id":63161712},{"atb":[[3,5.48]],"id":65732558}],"con":true,"img":false}]}
{"op":"mcm","clk":"11450067851","pt":1717317641661,"mc":[{"id":"1.229554899","rc":[{"atl":[[8.2,0]],"id":65732558}],"con":true,"img":false}]}
{"op":"mcm","clk":"11450067860","pt":1717317641766,"mc":[{"id":"1.229554899","rc":[{"atl":[[4,1.63]],"id":65732558}],"con":true,"img":false}]}
{"op":"mcm","clk":"11450067870","pt":1717317641869,"mc":[{"id":"1.229554899","rc":[{"atb":[[1.04,0]],"id":63161712}],"con":true,"img":false}]}
{"op":"mcm","clk":"11450067889","pt":1717317642078,"mc":[{"id":"1.229554899","rc":[{"atb":[[2.98,15.03],[2.84,9.44]],"id":65732558}],"con":true,"img":false}]}
{"op":"mcm","clk":"11450067916","pt":1717317642385,"mc":[{"id":"1.229554899","rc":[{"atb":[[1.16,3.96],[1.15,100.51],[1.14,0]],"id":63161712},{"atl":[[9.6,6.58],[11.5,0]],"id":65732558}],"con":true,"img":false}]}
{"op":"mcm","clk":"11450067927","pt":1717317642490,"mc":[{"id":"1.229554899","rc":[{"atb":[[1.41,27.63]],"id":63161712}],"con":true,"img":false}]}
{"op":"mcm","clk":"11450067945","pt":1717317642651,"mc":[{"id":"1.229554899","rc":[{"atb":[[2.98,2.87]],"id":65732558}],"con":true,"img":false}]}
{"op":"mcm","clk":"11450067954","pt":1717317642759,"mc":[{"id":"1.229554899","rc":[{"atb":[[1.16,2]],"id":63161712},{"atb":[[3,3.43]],"id":65732558}],"con":true,"img":false}]}
{"op":"mcm","clk":"11450067973","pt":1717317642961,"mc":[{"id":"1.229554899","rc":[{"atl":[[1.47,0],[1.52,0]],"id":63161712}],"con":true,"img":false}]}
{"op":"mcm","clk":"11450067981","pt":1717317643065,"mc":[{"id":"1.229554899","rc":[{"atb":[[1.41,26.55]],"id":63161712},{"trd":[[1.41,2.15]],"ltp":1.41,"tv":2.15,"id":63161712}],"con":true,"img":false}]}
{"op":"mcm","clk":"11450067998","pt":1717317643275,"mc":[{"id":"1.229554899","rc":[{"atb":[[1.32,93.2]],"id":63161712},{"atb":[[3,2.86],[3.05,14.54]],"id":65732558}],"con":true,"img":false}]}
{"op":"mcm","clk":"11450068047","pt":1717317643687,"mc":[{"id":"1.229554899","rc":[{"atl":[[1.47,25.07]],"id":63161712}],"con":true,"img":false}]}
{"op":"mcm","clk":"11450068057","pt":1717317643791,"mc":[{"id":"1.229554899","rc":[{"atl":[[1.46,24.33]],"id":63161712}],"con":true,"img":false}]}
{"op":"mcm","clk":"11450068070","pt":1717317643900,"mc":[{"id":"1.229554899","rc":[{"atl":[[1.48,0]],"id":63161712},{"atb":[[3.05,17.41]],"id":65732558}],"con":true,"img":false}]}
{"op":"mcm","clk":"11450068078","pt":1717317643959,"mc":[{"id":"1.229554899","rc":[{"atb":[[2.88,0]],"id":65732558}],"con":true,"img":false}]}
{"op":"mcm","clk":"11450068088","pt":1717317644055,"mc":[{"id":"1.229554899","rc":[{"atl":[[1.49,0]],"id":63161712},{"atb":[[2.92,0],[3.1,2.87]],"id":65732558}],"con":true,"img":false}]}
{"op":"mcm","clk":"11450068114","pt":1717317644262,"mc":[{"id":"1.229554899","rc":[{"atb":[[1.01,0],[1.03,5.73]],"id":63161712},{"atb":[[3.15,13.87],[2.68,0],[2.48,0]],"id":65732558}],"con":true,"img":false}]}
{"op":"mcm","clk":"11450068141","pt":1717317644598,"mc":[{"id":"1.229554899","rc":[{"atb":[[3.2,2.05]],"id":65732558}],"con":true,"img":false}]}
{"op":"mcm","clk":"11450068149","pt":1717317644675,"mc":[{"id":"1.229554899","rc":[{"atl":[[4,0.84]],"id":65732558}],"con":true,"img":false}]}
{"op":"mcm","clk":"11450068160","pt":1717317644782,"mc":[{"id":"1.229554899","rc":[{"atl":[[4.1,15.4]],"id":65732558}],"con":true,"img":false}]}
{"op":"mcm","clk":"11450068220","pt":1717317645304,"mc":[{"id":"1.229554899","rc":[{"atl":[[4.1,14.62]],"id":65732558}],"con":true,"img":false}]}
{"op":"mcm","clk":"11450068227","pt":1717317645358,"mc":[{"id":"1.229554899","rc":[{"atl":[[7.4,0.78]],"id":65732558}],"con":true,"img":false}]}
{"op":"mcm","clk":"11450068272","pt":1717317645771,"mc":[{"id":"1.229554899","rc":[{"atb":[[1.32,0]],"id":63161712},{"atb":[[3.15,0]],"id":65732558}],"con":true,"img":false}]}
{"op":"mcm","clk":"11450068284","pt":1717317645875,"mc":[{"id":"1.229554899","rc":[{"atl":[[1.45,25.41]],"id":63161712}],"con":true,"img":false}]}
{"op":"mcm","clk":"11450068289","pt":1717317645978,"mc":[{"id":"1.229554899","rc":[{"atl":[[1.46,0],[1.44,25.07]],"id":63161712}],"con":true,"img":false}]}
{"op":"mcm","clk":"11450068320","pt":1717317646293,"mc":[{"id":"1.229554899","rc":[{"atb":[[3.1,17.07]],"id":65732558}],"con":true,"img":false}]}
{"op":"mcm","clk":"11450068333","pt":1717317646402,"mc":[{"id":"1.229554899","rc":[{"atl":[[1.47,0]],"id":63161712},{"atb":[[3.2,0]],"id":65732558}],"con":true,"img":false}]}
{"op":"mcm","clk":"11450068346","pt":1717317646558,"mc":[{"id":"1.229554899","rc":[{"atb":[[3.1,19.12]],"id":65732558}],"con":true,"img":false}]}
{"op":"mcm","clk":"11450068395","pt":1717317647079,"mc":[{"id":"1.229554899","rc":[{"atl":[[7.4,0]],"id":65732558}],"con":true,"img":false}]}
{"op":"mcm","clk":"11450068403","pt":1717317647184,"mc":[{"id":"1.229554899","rc":[{"atb":[[2.84,0],[3.15,17.42]],"id":65732558},{"atl":[[4.1,15.4]],"id":65732558}],"con":true,"img":false}]}
{"op":"mcm","clk":"11450068446","pt":1717317647599,"mc":[{"id":"1.229554899","rc":[{"atb":[[3.1,17.07]],"id":65732558}],"con":true,"img":false}]}
{"op":"mcm","clk":"11450068455","pt":1717317647655,"mc":[{"id":"1.229554899","rc":[{"atb":[[3.2,2.05]],"id":65732558}],"con":true,"img":false}]}
{"op":"mcm","clk":"11450068506","pt":1717317648274,"mc":[{"id":"1.229554899","rc":[{"atb":[[1.32,93.2]],"id":63161712},{"atb":[[3.25,13.25]],"id":65732558},{"atl":[[4.1,14.62]],"id":65732558}],"con":true,"img":false}]}
{"op":"mcm","clk":"11450068517","pt":1717317648378,"mc":[{"id":"1.229554899","rc":[{"atb":[[3.3,13.26]],"id":65732558},{"atl":[[7.4,0.78]],"id":65732558}],"con":true,"img":false}]}
{"op":"mcm","clk":"11450068524","pt":1717317648479,"mc":[{"id":"1.229554899","rc":[{"atb":[[3.15,0]],"id":65732558}],"con":true,"img":false}]}
{"op":"mcm","clk":"11450068531","pt":1717317648585,"mc":[{"id":"1.229554899","rc":[{"atb":[[1.41,18.88]],"id":63161712},{"trd":[[1.41,17.5]],"ltp":1.41,"tv":17.5,"id":63161712}],"con":true,"img":false}]}
{"op":"mcm","clk":"11450068541","pt":1717317648689,"mc":[{"id":"1.229554899","rc":[{"atl":[[1.44,41.46]],"id":63161712}],"con":true,"img":false}]}
{"op":"mcm","clk":"11450068545","pt":1717317648792,"mc":[{"id":"1.229554899","rc":[{"atb":[[1.32,0]],"id":63161712},{"atb":[[3.2,0],[3.25,0]],"id":65732558}],"con":true,"img":false}]}
{"op":"mcm","clk":"11450068553","pt":1717317648895,"mc":[{"id":"1.229554899","rc":[{"atb":[[3.15,26.52],[3.3,0]],"id":65732558}],"con":true,"img":false}]}
{"op":"mcm","clk":"11450068600","pt":1717317649467,"mc":[{"id":"1.229554899","rc":[{"atl":[[7.4,0]],"id":65732558}],"con":true,"img":false}]}
{"op":"mcm","clk":"11450068610","pt":1717317649571,"mc":[{"id":"1.229554899","rc":[{"atl":[[4.1,15.4]],"id":65732558}],"con":true,"img":false}]}
{"op":"mcm","clk":"11450068688","pt":1717317650402,"mc":[{"id":"1.229554899","rc":[{"trd":[[1.44,35.42]],"ltp":1.44,"tv":35.42,"id":63161712},{"atl":[[1.44,6.04]],"id":63161712},{"trd":[[3.25,16.4]],"ltp":3.25,"tv":16.4,"id":65732558}],"con":true,"img":false}]}
{"op":"mcm","clk":"11450068699","pt":1717317650459,"mc":[{"id":"1.229554899","rc":[{"atb":[[1.41,26.23]],"id":63161712}],"con":true,"img":false}]}
{"op":"mcm","clk":"11450068707","pt":1717317650564,"mc":[{"id":"1.229554899","rc":[{"atl":[[1.46,21.3],[1.44,0],[1.45,0],[1.53,6.76]],"id":63161712}],"con":true,"img":false}]}
{"op":"mcm","clk":"11450068726","pt":1717317650767,"mc":[{"id":"1.229554899","rc":[{"atb":[[1.32,93.2]],"id":63161712},{"atb":[[3.2,13.55]],"id":65732558}],"con":true,"img":false}]}
{"op":"mcm","clk":"11450068747","pt":1717317650972,"mc":[{"id":"1.229554899","rc":[{"atb":[[3.1,14.2],[3.15,0],[3.25,24.28]],"id":65732558}],"con":true,"img":false}]}
{"op":"mcm","clk":"11450068771","pt":1717317651282,"mc":[{"id":"1.229554899","rc":[{"atb":[[3.2,0]],"id":65732558},{"atl":[[4.1,14.62]],"id":65732558}],"con":true,"img":false}]}
{"op":"mcm","clk":"11450068777","pt":1717317651384,"mc":[{"id":"1.229554899","rc":[{"atl":[[7.4,0.78]],"id":65732558}],"con":true,"img":false}]}
{"op":"mcm","clk":"11450068789","pt":1717317651487,"mc":[{"id":"1.229554899","rc":[{"atb":[[3.25,7.2]],"id":65732558}],"con":true,"img":false}]}
{"op":"mcm","clk":"11450068797","pt":1717317651590,"mc":[{"id":"1.229554899","rc":[{"atb":[[2.84,10.11]],"id":65732558}],"con":true,"img":false}]}
{"op":"mcm","clk":"11450068814","pt":1717317651797,"mc":[{"id":"1.229554899","rc":[{"atb":[[1.32,0]],"id":63161712}],"con":true,"img":false}]}
{"op":"mcm","clk":"11450069063","pt":1717317654495,"mc":[{"id":"1.229554899","rc":[{"atl":[[2.02,0],[2.06,0]],"id":63161712}],"con":true,"img":false}]}
{"op":"mcm","clk":"11450069071","pt":1717317654597,"mc":[{"id":"1.229554899","rc":[{"atb":[[3.1,26.51]],"id":65732558}],"con":true,"img":false}]}
{"op":"mcm","clk":"11450069085","pt":1717317654806,"mc":[{"id":"1.229554899","rc":[{"atb":[[3.1,14.2]],"id":65732558}],"con":true,"img":false}]}
{"op":"mcm","clk":"11450069120","pt":1717317655270,"mc":[{"id":"1.229554899","rc":[{"atb":[[2.9,0],[3.15,2.76]],"id":65732558}],"con":true,"img":false}]}
{"op":"mcm","clk":"11450069132","pt":1717317655501,"mc":[{"id":"1.229554899","rc":[{"atl":[[1.45,8]],"id":63161712}],"con":true,"img":false}]}
{"op":"mcm","clk":"11450069139","pt":1717317655606,"mc":[{"id":"1.229554899","rc":[{"atl":[[1.45,15.35]],"id":63161712}],"con":true,"img":false}]}
{"op":"mcm","clk":"11450069181","pt":1717317656070,"mc":[{"id":"1.229554899","rc":[{"atb":[[3.25,0],[3.15,4.76]],"id":65732558}],"con":true,"img":false}]}
{"op":"mcm","clk":"11450069225","pt":1717317656687,"mc":[{"id":"1.229554899","rc":[{"atb":[[3.15,18.97]],"id":65732558},{"atl":[[9.6,0],[8.6,4.14],[6.4,8.49],[7.4,0],[7.6,0]],"id":65732558}],"con":true,"img":false}]}
{"op":"mcm","clk":"11450069237","pt":1717317656791,"mc":[{"id":"1.229554899","rc":[{"atb":[[3.1,0],[2.84,0]],"id":65732558},{"atl":[[4.1,15.4]],"id":65732558}],"con":true,"img":false}]}
{"op":"mcm","clk":"11450069245","pt":1717317656895,"mc":[{"id":"1.229554899","rc":[{"atl":[[1.46,26.15]],"id":63161712}],"con":true,"img":false}]}
{"op":"mcm","clk":"11450069360","pt":1717317657875,"mc":[{"id":"1.229554899","rc":[{"atb":[[3.2,2.75],[3.05,29.92]],"id":65732558}],"con":true,"img":false}]}
{"op":"mcm","clk":"11450069371","pt":1717317657979,"mc":[{"id":"1.229554899","rc":[{"atb":[[2.98,0]],"id":65732558}],"con":true,"img":false}]}
{"op":"mcm","clk":"11450069400","pt":1717317658289,"mc":[{"id":"1.229554899","rc":[{"atb":[[1.32,93.2]],"id":63161712},{"atb":[[3.2,16.31]],"id":65732558}],"con":true,"img":false}]}
{"op":"mcm","clk":"11450069407","pt":1717317658397,"mc":[{"id":"1.229554899","rc":[{"atl":[[1.44,8.24],[1.85,0]],"id":63161712},{"atb":[[3.15,2.76],[3.25,28.07]],"id":65732558}],"con":true,"img":false}]}
{"op":"mcm","clk":"11450069416","pt":1717317658498,"mc":[{"id":"1.229554899","rc":[{"atl":[[4.1,14.62]],"id":65732558}],"con":true,"img":false}]}
{"op":"mcm","clk":"11450069423","pt":1717317658603,"mc":[{"id":"1.229554899","rc":[{"atl":[[6.2,0.78]],"id":65732558}],"con":true,"img":false}]}
{"op":"mcm","clk":"11450069436","pt":1717317658809,"mc":[{"id":"1.229554899","rc":[{"atb":[[1.32,0]],"id":63161712},{"atb":[[3.2,2.75],[3,0],[3.3,2.7]],"id":65732558}],"con":true,"img":false}]}
{"op":"mcm","clk":"11450069451","pt":1717317659019,"mc":[{"id":"1.229554899","rc":[{"atl":[[1.44,29.32]],"id":63161712}],"con":true,"img":false}]}
{"op":"mcm","clk":"11450069469","pt":1717317659175,"mc":[{"id":"1.229554899","rc":[{"atb":[[1.41,7.35]],"id":63161712},{"atb":[[2.34,27.15]],"id":65732558}],"con":true,"img":false}]}
{"op":"mcm","clk":"11450069476","pt":1717317659275,"mc":[{"id":"1.229554899","rc":[{"atb":[[1.39,18.88]],"id":63161712},{"atl":[[1.46,0]],"id":63161712},{"atb":[[3.15,16.64]],"id":65732558}],"con":true,"img":false}]}
{"op":"mcm","clk":"11450069484","pt":1717317659379,"mc":[{"id":"1.229554899","rc":[{"atb":[[1.41,6.5]],"id":63161712},{"trd":[[1.41,19.21]],"ltp":1.41,"tv":19.21,"id":63161712}],"con":true,"img":false}]}
{"op":"mcm","clk":"11450069501","pt":1717317659583,"mc":[{"id":"1.229554899","rc":[{"atb":[[1.41,0]],"id":63161712}],"con":true,"img":false}]}
{"op":"mcm","clk":"11450069509","pt":1717317659688,"mc":[{"id":"1.229554899","rc":[{"atb":[[1.39,26.88]],"id":63161712}],"con":true,"img":false}]}
{"op":"mcm","clk":"11450069574","pt":1717317660368,"mc":[{"id":"1.229554899","rc":[{"atl":[[1.44,34.79]],"id":63161712}],"con":true,"img":false}]}
{"op":"mcm","clk":"11450069589","pt":1717317660571,"mc":[{"id":"1.229554899","rc":[{"atb":[[3.3,0]],"id":65732558}],"con":true,"img":false}]}
{"op":"mcm","clk":"11450069594","pt":1717317660675,"mc":[{"id":"1.229554899","rc":[{"atl":[[1.45,8],[1.43,15.35]],"id":63161712},{"atb":[[3.2,50.2]],"id":65732558}],"con":true,"img":false}]}
{"op":"mcm","clk":"11450069603","pt":1717317660779,"mc":[{"id":"1.229554899","rc":[{"atb":[[3.25,0],[3.15,2.76]],"id":65732558}],"con":true,"img":false}]}
{"op":"mcm","clk":"11450069636","pt":1717317661196,"mc":[{"id":"1.229554899","rc":[{"atb":[[3.2,4.75],[2.84,54.35]],"id":65732558}],"con":true,"img":false}]}
{"op":"mcm","clk":"11450069640","pt":1717317661300,"mc":[{"id":"1.229554899","rc":[{"atb":[[3.15,16.64]],"id":65732558}],"con":true,"img":false}]}
{"op":"mcm","clk":"11450069939","pt":1717317664319,"mc":[{"id":"1.229554899","rc":[{"atl":[[1.44,26.55]],"id":63161712}],"con":true,"img":false}]}
{"op":"mcm","clk":"11450069955","pt":1717317664471,"mc":[{"id":"1.229554899","rc":[{"atl":[[1.44,21.08]],"id":63161712}],"con":true,"img":false}]}
{"op":"mcm","clk":"11450069977","pt":1717317664678,"mc":[{"id":"1.229554899","rc":[{"atl":[[1.44,26.55]],"id":63161712}],"con":true,"img":false}]}
{"op":"mcm","clk":"11450070098","pt":1717317665876,"mc":[{"id":"1.229554899","rc":[{"atl":[[1.44,21.08]],"id":63161712}],"con":true,"img":false}]}
{"op":"mcm","clk":"11450070115","pt":1717317666082,"mc":[{"id":"1.229554899","rc":[{"atb":[[3.05,17.41]],"id":65732558}],"con":true,"img":false}]}
{"op":"mcm","clk":"11450070143","pt":1717317666393,"mc":[{"id":"1.229554899","rc":[{"atl":[[4,0]],"id":65732558}],"con":true,"img":false}]}
{"op":"mcm","clk":"11450070226","pt":1717317667175,"mc":[{"id":"1.229554899","rc":[{"atb":[[2.9,33.28],[2.84,0]],"id":65732558}],"con":true,"img":false}]}
{"op":"mcm","clk":"11450070378","pt":1717317668676,"mc":[{"id":"1.229554899","rc":[{"atl":[[1.45,0]],"id":63161712}],"con":true,"img":false}]}
{"op":"mcm","clk":"11450070698","pt":1717317672304,"mc":[{"id":"1.229554899","rc":[{"atb":[[3.2,2.75],[3.15,25.6]],"id":65732558}],"con":true,"img":false}]}
{"op":"mcm","clk":"11450070788","pt":1717317673194,"mc":[{"id":"1.229554899","rc":[{"atb":[[1.39,62.73]],"id":63161712}],"con":true,"img":false}]}
{"op":"mcm","clk":"11450070842","pt":1717317673807,"mc":[{"id":"1.229554899","rc":[{"atb":[[1.33,90.37]],"id":63161712},{"atb":[[3.3,12.96]],"id":65732558}],"con":true,"img":false}]}
{"op":"mcm","clk":"11450071049","pt":1717317675828,"mc":[{"id":"1.229554899","rc":[{"atb":[[3.2,0]],"id":65732558}],"con":true,"img":false}]}
{"op":"mcm","clk":"11450071068","pt":1717317675988,"mc":[{"id":"1.229554899","rc":[{"atb":[[1.01,784.76]],"id":63161712},{"atb":[[2.54,10.29],[2.74,9.11]],"id":65732558}],"con":true,"img":false}]}
{"op":"mcm","clk":"11450071312","pt":1717317678532,"mc":[{"id":"1.229554899","rc":[{"atb":[[3.15,22.83]],"id":65732558}],"con":true,"img":false}]}
{"op":"mcm","clk":"11450071340","pt":1717317678899,"mc":[{"id":"1.229554899","rc":[{"atb":[[3.1,2.81]],"id":65732558}],"con":true,"img":false}]}
{"op":"mcm","clk":"11450071378","pt":1717317679308,"mc":[{"id":"1.229554899","rc":[{"atb":[[1.39,26.88]],"id":63161712}],"con":true,"img":false}]}
{"op":"mcm","clk":"11450071419","pt":1717317679825,"mc":[{"id":"1.229554899","rc":[{"atb":[[1.33,0]],"id":63161712},{"atb":[[3.3,0]],"id":65732558}],"con":true,"img":false}]}
{"op":"mcm","clk":"11450071445","pt":1717317680133,"mc":[{"id":"1.229554899","rc":[{"atl":[[6.2,0]],"id":65732558}],"con":true,"img":false}]}
{"op":"mcm","clk":"11450071454","pt":1717317680237,"mc":[{"id":"1.229554899","rc":[{"atl":[[4.1,15.4]],"id":65732558}],"con":true,"img":false}]}
{"op":"mcm","clk":"11450071561","pt":1717317681523,"mc":[{"id":"1.229554899","rc":[{"atb":[[2.8,40.25]],"id":65732558}],"con":true,"img":false}]}
{"op":"mcm","clk":"11450071569","pt":1717317681624,"mc":[{"id":"1.229554899","rc":[{"atb":[[2.9,0]],"id":65732558}],"con":true,"img":false}]}
{"op":"mcm","clk":"11450071621","pt":1717317682199,"mc":[{"id":"1.229554899","rc":[{"atb":[[1.39,62.77]],"id":63161712}],"con":true,"img":false}]}
{"op":"mcm","clk":"11450071643","pt":1717317682410,"mc":[{"id":"1.229554899","rc":[{"atb":[[1.39,26.88]],"id":63161712}],"con":true,"img":false}]}
{"op":"mcm","clk":"11450071912","pt":1717317684940,"mc":[{"id":"1.229554899","rc":[{"atb":[[1.39,62.73]],"id":63161712},{"atb":[[3.1,0]],"id":65732558}],"con":true,"img":false}]}
{"op":"mcm","clk":"11450071930","pt":1717317685148,"mc":[{"id":"1.229554899","rc":[{"atb":[[1.39,26.88]],"id":63161712}],"con":true,"img":false}]}
{"op":"mcm","clk":"11450072037","pt":1717317686411,"mc":[{"id":"1.229554899","rc":[{"atb":[[1.39,62.73]],"id":63161712}],"con":true,"img":false}]}
{"op":"mcm","clk":"11450072056","pt":1717317686620,"mc":[{"id":"1.229554899","rc":[{"atb":[[1.39,26.88]],"id":63161712}],"con":true,"img":false}]}
{"op":"mcm","clk":"11450072156","pt":1717317687804,"mc":[{"id":"1.229554899","rc":[{"atb":[[1.39,62.73]],"id":63161712}],"con":true,"img":false}]}
{"op":"mcm","clk":"11450072177","pt":1717317688005,"mc":[{"id":"1.229554899","rc":[{"atb":[[1.39,26.88]],"id":63161712}],"con":true,"img":false}]}
{"op":"mcm","clk":"11450072278","pt":1717317689155,"mc":[{"id":"1.229554899","rc":[{"atb":[[3.05,14.54]],"id":65732558}],"con":true,"img":false}]}
{"op":"mcm","clk":"11450072307","pt":1717317689352,"mc":[{"id":"1.229554899","rc":[{"atb":[[1.39,27.77]],"id":63161712},{"trd":[[1.39,69.93],[1.4,16.15]],"ltp":1.39,"tv":86.08,"id":63161712},{"trd":[[3.5,0.01]],"ltp":3.5,"tv":0.01,"id":65732558},{"atl":[[3.5,0]],"id":65732558}],"con":true,"img":false}]}
{"op":"mcm","clk":"11450072317","pt":1717317689455,"mc":[{"id":"1.229554899","rc":[{"atb":[[1.39,28.83]],"id":63161712}],"con":true,"img":false}]}
{"op":"mcm","clk":"11450072332","pt":1717317689509,"mc":[{"id":"1.229554899","rc":[{"atb":[[3.1,2.81]],"id":65732558}],"con":true,"img":false}]}
{"op":"mcm","clk":"11450072342","pt":1717317689612,"mc":[{"id":"1.229554899","rc":[{"atb":[[2.34,0]],"id":65732558}],"con":true,"img":false}]}
{"op":"mcm","clk":"11450072349","pt":1717317689715,"mc":[{"id":"1.229554899","rc":[{"atb":[[1.32,93.2]],"id":63161712},{"atb":[[2.3,27.15],[3.3,12.96]],"id":65732558}],"con":true,"img":false}]}
{"op":"mcm","clk":"11450072403","pt":1717317690340,"mc":[{"id":"1.229554899","rc":[{"atl":[[4.1,14.62]],"id":65732558}],"con":true,"img":false}]}
{"op":"mcm","clk":"11450072413","pt":1717317690435,"mc":[{"id":"1.229554899","rc":[{"atl":[[6.2,0.78]],"id":65732558}],"con":true,"img":false}]}
{"op":"mcm","clk":"11450072421","pt":1717317690540,"mc":[{"id":"1.229554899","rc":[{"atb":[[3.35,12.97]],"id":65732558}],"con":true,"img":false}]}
{"op":"mcm","clk":"11450072432","pt":1717317690643,"mc":[{"id":"1.229554899","rc":[{"atb":[[2.8,0]],"id":65732558}],"con":true,"img":false}]}
{"op":"mcm","clk":"11450072440","pt":1717317690746,"mc":[{"id":"1.229554899","rc":[{"atb":[[1.39,1.06]],"id":63161712},{"atl":[[1.42,27.93]],"id":63161712},{"atb":[[3.2,13.55],[3.3,0]],"id":65732558}],"con":true,"img":false}]}
{"op":"mcm","clk":"11450072447","pt":1717317690850,"mc":[{"id":"1.229554899","rc":[{"atb":[[1.32,0]],"id":63161712}],"con":true,"img":false}]}
{"op":"mcm","clk":"11450072453","pt":1717317690951,"mc":[{"id":"1.229554899","rc":[{"atb":[[1.16,95.75],[1.15,0.51]],"id":63161712},{"atl":[[1.41,21.08],[1.43,0]],"id":63161712}],"con":true,"img":false}]}
{"op":"mcm","clk":"11450072462","pt":1717317691059,"mc":[{"id":"1.229554899","rc":[{"atb":[[3.2,16.33]],"id":65732558}],"con":true,"img":false}]}
{"op":"mcm","clk":"11450072480","pt":1717317691216,"mc":[{"id":"1.229554899","rc":[{"atl":[[1.53,0]],"id":63161712},{"atb":[[3.2,2.77],[3.15,8.96],[3.05,0]],"id":65732558}],"con":true,"img":false}]}
{"op":"mcm","clk":"11450072490","pt":1717317691322,"mc":[{"id":"1.229554899","rc":[{"atb":[[1.15,0]],"id":63161712}],"con":true,"img":false}]}
{"op":"mcm","clk":"11450072505","pt":1717317691425,"mc":[{"id":"1.229554899","rc":[{"atb":[[1.16,2],[1.17,88.75]],"id":63161712}],"con":true,"img":false}]}
{"op":"mcm","clk":"11450072535","pt":1717317691733,"mc":[{"id":"1.229554899","rc":[{"atb":[[1.39,0]],"id":63161712}],"con":true,"img":false}]}
{"op":"mcm","clk":"11450072548","pt":1717317691835,"mc":[{"id":"1.229554899","rc":[{"atb":[[1.12,416.67],[1.18,2],[1.1,250],[1.04,21.08]],"id":63161712},{"atb":[[3.4,12.42]],"id":65732558}],"con":true,"img":false}]}
{"op":"mcm","clk":"11450072560","pt":1717317691944,"mc":[{"id":"1.229554899","rc":[{"atb":[[1.16,0]],"id":63161712}],"con":true,"img":false}]}
{"op":"mcm","clk":"11450072589","pt":1717317692250,"mc":[{"id":"1.229554899","rc":[{"atl":[[1.44,0]],"id":63161712},{"atb":[[3.2,5.81],[3.15,0]],"id":65732558}],"con":true,"img":false}]}
{"op":"mcm","clk":"11450072615","pt":1717317692512,"mc":[{"id":"1.229554899","rc":[{"atb":[[1.15,133.33]],"id":63161712}],"con":true,"img":false}]}
{"op":"mcm","clk":"11450072638","pt":1717317692725,"mc":[{"id":"1.229554899","rc":[{"atb":[[1.08,0]],"id":63161712}],"con":true,"img":false}]}
{"op":"mcm","clk":"11450072668","pt":1717317693030,"mc":[{"id":"1.229554899","rc":[{"atb":[[1.33,34.62]],"id":63161712}],"con":true,"img":false}]}
{"op":"mcm","clk":"11450072698","pt":1717317693339,"mc":[{"id":"1.229554899","rc":[{"atl":[[1.53,20.66]],"id":63161712}],"con":true,"img":false}]}
{"op":"mcm","clk":"11450072847","pt":1717317694838,"mc":[{"id":"1.229554899","rc":[{"atb":[[1.33,35.73]],"id":63161712}],"con":true,"img":false}]}
{"op":"mcm","clk":"11450072854","pt":1717317694940,"mc":[{"id":"1.229554899","rc":[{"atb":[[1.04,0]],"id":63161712}],"con":true,"img":false}]}
{"op":"mcm","clk":"11450072862","pt":1717317695044,"mc":[{"id":"1.229554899","rc":[{"atb":[[3.25,2.73]],"id":65732558}],"con":true,"img":false}]}
{"op":"mcm","clk":"11450072872","pt":1717317695150,"mc":[{"id":"1.229554899","rc":[{"atl":[[1.42,0]],"id":63161712}],"con":true,"img":false}]}
{"op":"mcm","clk":"11450072879","pt":1717317695254,"mc":[{"id":"1.229554899","rc":[{"atb":[[3.25,0]],"id":65732558}],"con":true,"img":false}]}
{"op":"mcm","clk":"11450072890","pt":1717317695359,"mc":[{"id":"1.229554899","rc":[{"atl":[[1.41,0],[1.49,42.16]],"id":63161712}],"con":true,"img":false}]}
{"op":"mcm","clk":"11450072919","pt":1717317695624,"mc":[{"id":"1.229554899","rc":[{"atb":[[3.45,12.42],[3.35,0]],"id":65732558}],"con":true,"img":false}]}
{"op":"mcm","clk":"11450072929","pt":1717317695728,"mc":[{"id":"1.229554899","rc":[{"atl":[[1.48,8.02]],"id":63161712}],"con":true,"img":false}]}
{"op":"mcm","clk":"11450072942","pt":1717317695840,"mc":[{"id":"1.229554899","marketDefinition":{"bspMarket":false,"turnInPlayEnabled":false,"persistenceEnabled":false,"marketBaseRate":7.0,"eventId":"33318908","eventTypeId":"4339","numberOfWinners":1,"bettingType":"ODDS","marketType":"MATCH_BET","marketTime":"2024-06-02T08:41:00.000Z","suspendTime":"2024-06-02T08:41:00.000Z","bspReconciled":false,"complete":true,"inPlay":false,"crossMatching":true,"runnersVoidable":false,"numberOfActiveRunners":2,"betDelay":0,"status":"SUSPENDED","runners":[{"status":"ACTIVE","sortPriority":1,"id":65732558,"name":"2. All The Sass"},{"status":"ACTIVE","sortPriority":2,"id":63161712,"name":"4. Dirty Dash"}],"regulators":["MR_INT"],"venue":"Murray Bridge","countryCode":"AU","discountAllowed":true,"timezone":"Australia/Adelaide","openDate":"2024-06-02T08:21:00.000Z","version":5962996660,"name":"All The Sass v Dirty Dash","eventName":"Murray Bridge (AUS) 2nd Jun"},"rc":[],"con":true,"img":false}]}
{"op":"mcm","clk":"11450072942","pt":1717317695840,"mc":[{"id":"1.229554899","rc":[{"atb":[[1.18,0],[1.12,0],[1.01,0],[1.15,0],[1.03,0],[1.33,0],[1.1,0],[1.17,0]],"id":63161712},{"atl":[[1.55,0],[1.5,0],[1.49,0],[1.48,0],[1.53,0],[2.1,0],[2.14,0],[1000,0]],"id":63161712},{"atb":[[3.45,0],[3.2,0],[2.54,0],[2.74,0],[2.3,0],[3.1,0],[1.02,0],[3.4,0]],"id":65732558},{"atl":[[8.6,0],[6.4,0],[6.2,0],[4.1,0],[4.2,0],[1000,0]],"id":65732558}],"con":true,"img":false}]}
{"op":"mcm","clk":"11450077294","pt":1717317743646,"mc":[{"id":"1.229554899","rc":[{"trd":[[1.4,0],[1.41,0],[1.44,0],[1.45,0],[1.5,0],[1.42,0],[1.49,0],[1.39,0],[1.48,0],[1.47,0]],"ltp":1.4,"tv":0.0,"id":63161712},{"trd":[[3.1,0],[3.4,0],[3.25,0],[3.5,0],[3.05,0]],"ltp":3.1,"tv":0.0,"id":65732558}],"con":true,"img":false}]}
{"op":"mcm","clk":"11450077392","pt":1717317744568,"mc":[{"id":"1.229554899","marketDefinition":{"bspMarket":false,"turnInPlayEnabled":false,"persistenceEnabled":false,"marketBaseRate":7.0,"eventId":"33318908","eventTypeId":"4339","numberOfWinners":1,"bettingType":"ODDS","marketType":"MATCH_BET","marketTime":"2024-06-02T08:41:00.000Z","suspendTime":"2024-06-02T08:41:00.000Z","bspReconciled":false,"complete":true,"inPlay":false,"crossMatching":false,"runnersVoidable":false,"numberOfActiveRunners":0,"betDelay":0,"status":"CLOSED","settledTime":"2024-06-02T08:42:22.000Z","runners":[{"status":"LOSER","sortPriority":1,"id":65732558,"name":"2. All The Sass"},{"status":"WINNER","sortPriority":2,"id":63161712,"name":"4. Dirty Dash"}],"regulators":["MR_INT"],"venue":"Murray Bridge","countryCode":"AU","discountAllowed":true,"timezone":"Australia/Adelaide","openDate":"2024-06-02T08:21:00.000Z","version":5962997200,"name":"All The Sass v Dirty Dash","eventName":"Murray Bridge (AUS) 2nd Jun"},"rc":[],"con":true,"img":false}]}
