{"op":"mcm","clk":"11448351867","pt":1717289088271,"mc":[{"id":"1.229554909","marketDefinition":{"bspMarket":false,"turnInPlayEnabled":false,"persistenceEnabled":false,"marketBaseRate":7.0,"eventId":"33318908","eventTypeId":"4339","numberOfWinners":1,"bettingType":"ODDS","marketType":"MATCH_BET","marketTime":"2024-06-02T09:20:00.000Z","suspendTime":"2024-06-02T09:20:00.000Z","bspReconciled":false,"complete":true,"inPlay":false,"crossMatching":true,"runnersVoidable":false,"numberOfActiveRunners":2,"betDelay":0,"status":"OPEN","runners":[{"status":"ACTIVE","sortPriority":1,"id":61631980,"name":"1. Opella"},{"status":"ACTIVE","sortPriority":2,"id":61631978,"name":"4. Elwomple"}],"regulators":["MR_INT"],"venue":"Murray Bridge","countryCode":"AU","discountAllowed":true,"timezone":"Australia/Adelaide","openDate":"2024-06-02T08:21:00.000Z","version":5962433799,"name":"Opella v Elwomple","eventName":"Murray Bridge (AUS) 2nd Jun"},"rc":[],"con":true,"img":false}]}
{"op":"mcm","clk":"11448366403","pt":1717289278043,"mc":[{"id":"1.229554909","rc":[{"atb":[[1.98,8],[1.88,8.92]],"id":61631980},{"atb":[[1.72,10.89],[1.62,12.65]],"id":61631978}],"con":true,"img":false}]}
{"op":"mcm","clk":"11448957702","pt":1717300805016,"mc":[{"id":"1.229554909","rc":[{"atb":[[1.98,0],[1.88,0]],"id":61631980},{"atb":[[1.72,0],[1.62,0]],"id":61631978}],"con":true,"img":false}]}
{"op":"mcm","clk":"11448958449","pt":1717300819077,"mc":[{"id":"1.229554909","rc":[{"atb":[[1.98,8],[1.88,8.92]],"id":61631980},{"atb":[[1.73,10.75],[1.63,12.45]],"id":61631978}],"con":true,"img":false}]}
{"op":"mcm","clk":"11448963909","pt":1717300914420,"mc":[{"id":"1.229554909","rc":[{"atb":[[1.98,0],[1.88,0]],"id":61631980},{"atb":[[1.73,0],[1.63,0]],"id":61631978}],"con":true,"img":false}]}
{"op":"mcm","clk":"11448965590","pt":1717300946049,"mc":[{"id":"1.229554909","rc":[{"atb":[[1.98,8],[1.88,8.92]],"id":61631980},{"atb":[[1.73,10.75],[1.63,12.45]],"id":61631978}],"con":true,"img":false}]}
{"op":"mcm","clk":"11449358152","pt":1717307829157,"mc":[{"id":"1.229554909","rc":[{"atb":[[1.01,17.76]],"id":61631980},{"atl":[[1000,0.85]],"id":61631980},{"atb":[[1.02,8.87]],"id":61631978},{"atl":[[1000,0.85]],"id":61631978}],"con":true,"img":false}]}
{"op":"mcm","clk":"11449448635","pt":1717309303200,"mc":[{"id":"1.229554909","rc":[{"atb":[[1.98,0],[1.88,0]],"id":61631980},{"atb":[[1.73,0],[1.63,0]],"id":61631978}],"con":true,"img":false}]}
{"op":"mcm","clk":"11449449633","pt":1717309317217,"mc":[{"id":"1.229554909","rc":[{"atb":[[1.82,9.56],[1.92,8.52]],"id":61631980},{"atb":[[1.82,9.56],[1.72,10.89]],"id":61631978}],"con":true,"img":false}]}
{"op":"mcm","clk":"11449451530","pt":1717309344563,"mc":[{"id":"1.229554909","rc":[{"atb":[[1.82,0],[1.92,0]],"id":61631980},{"atb":[[1.82,0],[1.72,0]],"id":61631978}],"con":true,"img":false}]}
{"op":"mcm","clk":"11449452516","pt":1717309358186,"mc":[{"id":"1.229554909","rc":[{"atb":[[1.82,9.56],[1.92,8.52]],"id":61631980},{"atb":[[1.82,9.56],[1.72,10.89]],"id":61631978}],"con":true,"img":false}]}
{"op":"mcm","clk":"11449454225","pt":1717309384110,"mc":[{"id":"1.229554909","rc":[{"atb":[[1.82,0],[1.92,0]],"id":61631980},{"atb":[[1.82,0],[1.72,0]],"id":61631978}],"con":true,"img":false}]}
{"op":"mcm","clk":"11449454762","pt":1717309392781,"mc":[{"id":"1.229554909","rc":[{"atb":[[1.82,9.56],[1.92,8.52]],"id":61631980},{"atb":[[1.82,9.56],[1.72,10.89]],"id":61631978}],"con":true,"img":false}]}
{"op":"mcm","clk":"11449456328","pt":1717309418833,"mc":[{"id":"1.229554909","rc":[{"atb":[[1.82,0],[1.92,0]],"id":61631980},{"atb":[[1.82,0],[1.72,0]],"id":61631978}],"con":true,"img":false}]}
{"op":"mcm","clk":"11449457105","pt":1717309431138,"mc":[{"id":"1.229554909","rc":[{"atb":[[1.88,8.92],[1.78,10.06]],"id":61631980},{"atb":[[1.88,8.92],[1.78,10.06]],"id":61631978}],"con":true,"img":false}]}
{"op":"mcm","clk":"11449459046","pt":1717309460211,"mc":[{"id":"1.229554909","rc":[{"atb":[[1.88,0],[1.78,0]],"id":61631980},{"atb":[[1.88,0],[1.78,0]],"id":61631978}],"con":true,"img":false}]}
{"op":"mcm","clk":"11449460685","pt":1717309485524,"mc":[{"id":"1.229554909","rc":[{"atb":[[1.98,8],[1.88,8.92]],"id":61631980},{"atb":[[1.72,10.89],[1.62,12.65]],"id":61631978}],"con":true,"img":false}]}
{"op":"mcm","clk":"11449462429","pt":1717309511641,"mc":[{"id":"1.229554909","rc":[{"atb":[[1.98,0],[1.88,0]],"id":61631980},{"atb":[[1.72,0],[1.62,0]],"id":61631978}],"con":true,"img":false}]}
{"op":"mcm","clk":"11449463307","pt":1717309524897,"mc":[{"id":"1.229554909","rc":[{"atb":[[1.84,9.34],[1.94,8.34]],"id":61631980},{"atb":[[1.78,10.06],[1.68,11.54]],"id":61631978}],"con":true,"img":false}]}
{"op":"mcm","clk":"11449471763","pt":1717309643654,"mc":[{"id":"1.229554909","rc":[{"atb":[[1.84,0],[1.94,0]],"id":61631980},{"atb":[[1.78,0],[1.68,0]],"id":61631978}],"con":true,"img":false}]}
{"op":"mcm","clk":"11449472689","pt":1717309655786,"mc":[{"id":"1.229554909","rc":[{"atb":[[1.84,9.34],[1.94,8.34]],"id":61631980},{"atb":[[1.78,10.06],[1.68,11.54]],"id":61631978}],"con":true,"img":false}]}
{"op":"mcm","clk":"11449474643","pt":1717309682719,"mc":[{"id":"1.229554909","rc":[{"atb":[[1.84,0],[1.94,0]],"id":61631980},{"atb":[[1.78,0],[1.68,0]],"id":61631978}],"con":true,"img":false}]}
{"op":"mcm","clk":"11449475793","pt":1717309697516,"mc":[{"id":"1.229554909","rc":[{"atb":[[1.84,9.34],[1.94,8.34]],"id":61631980},{"atb":[[1.78,10.06],[1.68,11.54]],"id":61631978}],"con":true,"img":false}]}
{"op":"mcm","clk":"11449495570","pt":1717309879434,"mc":[{"id":"1.229554909","rc":[{"atb":[[1.84,0],[1.94,0]],"id":61631980},{"atb":[[1.78,0],[1.68,0]],"id":61631978}],"con":true,"img":false}]}
{"op":"mcm","clk":"11449496101","pt":1717309887943,"mc":[{"id":"1.229554909","rc":[{"atb":[[1.83,9.45],[1.93,8.43]],"id":61631980},{"atb":[[1.8,9.8],[1.7,11.21]],"id":61631978}],"con":true,"img":false}]}
{"op":"mcm","clk":"11449528865","pt":1717310431836,"mc":[{"id":"1.229554909","rc":[{"atb":[[1.83,0],[1.93,0]],"id":61631980},{"atb":[[1.8,0],[1.7,0]],"id":61631978}],"con":true,"img":false}]}
{"op":"mcm","clk":"11449530484","pt":1717310457770,"mc":[{"id":"1.229554909","rc":[{"atb":[[1.83,9.45],[1.93,8.43]],"id":61631980},{"atb":[[1.8,9.8],[1.7,11.21]],"id":61631978}],"con":true,"img":false}]}
{"op":"mcm","clk":"11449586261","pt":1717311434983,"mc":[{"id":"1.229554909","rc":[{"atl":[[1000,0.17]],"id":61631980},{"atl":[[1000,0.17]],"id":61631978}],"con":true,"img":false}]}
{"op":"mcm","clk":"11449589750","pt":1717311498509,"mc":[{"id":"1.229554909","rc":[{"atb":[[1.83,0],[1.93,0]],"id":61631980},{"atb":[[1.8,0],[1.7,0]],"id":61631978}],"con":true,"img":false}]}
{"op":"mcm","clk":"11449590382","pt":1717311508887,"mc":[{"id":"1.229554909","rc":[{"atb":[[1.83,9.45],[1.93,8.43]],"id":61631980},{"atb":[[1.8,9.8],[1.7,11.21]],"id":61631978}],"con":true,"img":false}]}
{"op":"mcm","clk":"11449640562","pt":1717312587580,"mc":[{"id":"1.229554909","rc":[{"atb":[[1.83,0],[1.93,0]],"id":61631980},{"atb":[[1.8,0],[1.7,0]],"id":61631978}],"con":true,"img":false}]}
{"op":"mcm","clk":"11449640837","pt":1717312594357,"mc":[{"id":"1.229554909","rc":[{"atb":[[1.83,9.45],[1.93,8.43]],"id":61631980},{"atb":[[1.8,9.8],[1.7,11.21]],"id":61631978}],"con":true,"img":false}]}
{"op":"mcm","clk":"11449680084","pt":1717313441226,"mc":[{"id":"1.229554909","rc":[{"atb":[[1.83,0],[1.93,0]],"id":61631980},{"atb":[[1.8,0],[1.7,0]],"id":61631978}],"con":true,"img":false}]}
{"op":"mcm","clk":"11449680658","pt":1717313449128,"mc":[{"id":"1.229554909","rc":[{"atb":[[1.83,9.45],[1.93,8.43]],"id":61631980},{"atb":[[1.8,9.8],[1.7,11.21]],"id":61631978}],"con":true,"img":false}]}
{"op":"mcm","clk":"11449753595","pt":1717314283452,"mc":[{"id":"1.229554909","rc":[{"atb":[[1.83,0],[1.93,0]],"id":61631980},{"atb":[[1.8,0],[1.7,0]],"id":61631978}],"con":true,"img":false}]}
{"op":"mcm","clk":"11449754572","pt":1717314295496,"mc":[{"id":"1.229554909","rc":[{"atb":[[1.83,9.45],[1.93,8.43]],"id":61631980},{"atb":[[1.8,9.8],[1.7,11.21]],"id":61631978}],"con":true,"img":false}]}
{"op":"mcm","clk":"11449835072","pt":1717315128957,"mc":[{"id":"1.229554909","rc":[{"atb":[[1.02,181.5]],"id":61631980},{"atl":[[980,0.85]],"id":61631980},{"atb":[[1.01,104.81]],"id":61631978},{"atl":[[970,1.44]],"id":61631978}],"con":true,"img":false}]}
{"op":"mcm","clk":"11449837917","pt":1717315160931,"mc":[{"id":"1.229554909","rc":[{"atb":[[1.83,0],[1.93,0]],"id":61631980},{"atb":[[1.8,0],[1.7,0]],"id":61631978}],"con":true,"img":false}]}
{"op":"mcm","clk":"11449841704","pt":1717315200095,"mc":[{"id":"1.229554909","rc":[{"atb":[[1.83,9.45],[1.93,8.43]],"id":61631980},{"atb":[[1.8,9.8],[1.7,11.21]],"id":61631978}],"con":true,"img":false}]}
{"op":"mcm","clk":"11449893637","pt":1717315712464,"mc":[{"id":"1.229554909","rc":[{"atb":[[1.83,0],[1.93,0]],"id":61631980},{"atb":[[1.8,0],[1.7,0]],"id":61631978}],"con":true,"img":false}]}
{"op":"mcm","clk":"11449898095","pt":1717315753812,"mc":[{"id":"1.229554909","rc":[{"atb":[[1.84,9.34],[1.94,8.34]],"id":61631980},{"atb":[[1.78,10.06],[1.68,11.54]],"id":61631978}],"con":true,"img":false}]}
{"op":"mcm","clk":"11449924790","pt":1717316009617,"mc":[{"id":"1.229554909","rc":[{"atb":[[1.84,0],[1.94,0]],"id":61631980},{"atb":[[1.78,0],[1.68,0]],"id":61631978}],"con":true,"img":false}]}
{"op":"mcm","clk":"11449928201","pt":1717316044386,"mc":[{"id":"1.229554909","rc":[{"atb":[[1.84,9.34],[1.94,8.34]],"id":61631980},{"atb":[[1.78,10.06],[1.68,11.54]],"id":61631978}],"con":true,"img":false}]}
{"op":"mcm","clk":"11449959396","pt":1717316400521,"mc":[{"id":"1.229554909","rc":[{"atl":[[23,2]],"id":61631980},{"atl":[[18,2]],"id":61631978}],"con":true,"img":false}]}
{"op":"mcm","clk":"11449959549","pt":1717316402495,"mc":[{"id":"1.229554909","rc":[{"atl":[[3.2,6.82],[3.4,10.42],[3.3,8.7],[3.5,12]],"id":61631980},{"atl":[[2.3,11.54],[2.42,21.13],[2.38,18.12],[2.34,14.93]],"id":61631978}],"con":true,"img":false}]}
{"op":"mcm","clk":"11449959560","pt":1717316402600,"mc":[{"id":"1.229554909","rc":[{"atl":[[23,0],[6.6,17.86]],"id":61631980},{"atl":[[5.6,21.74],[18,0]],"id":61631978}],"con":true,"img":false}]}
{"op":"mcm","clk":"11449960320","pt":1717316411633,"mc":[{"id":"1.229554909","rc":[{"atl":[[2.36,11.03],[2.3,0]],"id":61631978}],"con":true,"img":false}]}
{"op":"mcm","clk":"11449960326","pt":1717316411733,"mc":[{"id":"1.229554909","rc":[{"atl":[[2.3,11.54],[2.34,0]],"id":61631978}],"con":true,"img":false}]}
{"op":"mcm","clk":"11449960816","pt":1717316417533,"mc":[{"id":"1.229554909","rc":[{"atl":[[2.3,0]],"id":61631978}],"con":true,"img":false}]}
{"op":"mcm","clk":"11449961168","pt":1717316421731,"mc":[{"id":"1.229554909","rc":[{"atl":[[2.4,14.29]],"id":61631978}],"con":true,"img":false}]}
{"op":"mcm","clk":"11449961618","pt":1717316426826,"mc":[{"id":"1.229554909","rc":[{"atl":[[2.36,0],[2.3,11.54]],"id":61631978}],"con":true,"img":false}]}
{"op":"mcm","clk":"11449962072","pt":1717316432666,"mc":[{"id":"1.229554909","rc":[{"atl":[[2.36,11.03],[2.3,0]],"id":61631978}],"con":true,"img":false}]}
{"op":"mcm","clk":"11449964333","pt":1717316463002,"mc":[{"id":"1.229554909","rc":[{"atl":[[2.36,0],[2.3,11.54]],"id":61631978}],"con":true,"img":false}]}
{"op":"mcm","clk":"11449964548","pt":1717316465805,"mc":[{"id":"1.229554909","rc":[{"atl":[[2.36,11.03],[2.3,0]],"id":61631978}],"con":true,"img":false}]}
{"op":"mcm","clk":"11449967821","pt":1717316511747,"mc":[{"id":"1.229554909","rc":[{"atl":[[2.82,8.24],[3.2,0]],"id":61631980}],"con":true,"img":false}]}
{"op":"mcm","clk":"11449968441","pt":1717316521726,"mc":[{"id":"1.229554909","rc":[{"atl":[[2.86,10.75]],"id":61631980}],"con":true,"img":false}]}
{"op":"mcm","clk":"11449969113","pt":1717316531724,"mc":[{"id":"1.229554909","rc":[{"atl":[[2.9,13.16],[3.4,0],[3.3,0],[3.5,0]],"id":61631980}],"con":true,"img":false}]}
{"op":"mcm","clk":"11449969768","pt":1717316541743,"mc":[{"id":"1.229554909","rc":[{"atl":[[2.94,15.46]],"id":61631980}],"con":true,"img":false}]}
{"op":"mcm","clk":"11449970486","pt":1717316552457,"mc":[{"id":"1.229554909","rc":[{"atb":[[1.84,0],[1.94,0]],"id":61631980},{"atb":[[1.78,0],[1.68,0]],"id":61631978}],"con":true,"img":false}]}
{"op":"mcm","clk":"11449971052","pt":1717316561400,"mc":[{"id":"1.229554909","rc":[{"atb":[[1.49,51.02],[1.51,39.22],[1.53,28.3],[1.47,63.83]],"id":61631980},{"atb":[[1.4,62.5],[1.44,34.09],[1.42,47.62],[1.38,78.95]],"id":61631978}],"con":true,"img":false}]}
{"op":"mcm","clk":"11449971658","pt":1717316571125,"mc":[{"id":"1.229554909","rc":[{"atb":[[1.84,9.34],[1.94,8.34]],"id":61631980},{"atb":[[1.78,10.06],[1.68,11.54]],"id":61631978}],"con":true,"img":false}]}
{"op":"mcm","clk":"11449989458","pt":1717316817414,"mc":[{"id":"1.229554909","rc":[{"atb":[[1.44,0],[1.42,0]],"id":61631978}],"con":true,"img":false}]}
{"op":"mcm","clk":"11449990138","pt":1717316827321,"mc":[{"id":"1.229554909","rc":[{"atl":[[2.36,0],[2.3,11.54]],"id":61631978}],"con":true,"img":false}]}
{"op":"mcm","clk":"11449999418","pt":1717316939030,"mc":[{"id":"1.229554909","rc":[{"atb":[[1.84,0],[1.94,0]],"id":61631980},{"atb":[[1.78,0],[1.68,0]],"id":61631978}],"con":true,"img":false}]}
{"op":"mcm","clk":"11450000048","pt":1717316946370,"mc":[{"id":"1.229554909","rc":[{"atb":[[1.42,35.71]],"id":61631978}],"con":true,"img":false}]}
{"op":"mcm","clk":"11450000408","pt":1717316949998,"mc":[{"id":"1.229554909","rc":[{"atb":[[1.84,9.34],[1.94,8.34]],"id":61631980},{"atb":[[1.78,10.06],[1.68,11.54]],"id":61631978}],"con":true,"img":false}]}
{"op":"mcm","clk":"11450013144","pt":1717317085441,"mc":[{"id":"1.229554909","rc":[{"atb":[[1.4,0],[1.42,0]],"id":61631978}],"con":true,"img":false}]}
{"op":"mcm","clk":"11450015745","pt":1717317114563,"mc":[{"id":"1.229554909","rc":[{"atl":[[2.82,0],[2.88,7.98],[2.86,18.81]],"id":61631980},{"atl":[[2.36,11.03],[2.3,0]],"id":61631978}],"con":true,"img":false}]}
{"op":"mcm","clk":"11450015753","pt":1717317114665,"mc":[{"id":"1.229554909","rc":[{"atl":[[2.86,8.06]],"id":61631980}],"con":true,"img":false}]}
{"op":"mcm","clk":"11450016756","pt":1717317124501,"mc":[{"id":"1.229554909","rc":[{"atl":[[2.36,0],[2.3,11.54]],"id":61631978}],"con":true,"img":false}]}
{"op":"mcm","clk":"11450017182","pt":1717317128658,"mc":[{"id":"1.229554909","rc":[{"atl":[[2.82,8.24],[2.86,0]],"id":61631980},{"atl":[[2.36,11.03],[2.3,0]],"id":61631978}],"con":true,"img":false}]}
{"op":"mcm","clk":"11450019426","pt":1717317151442,"mc":[{"id":"1.229554909","rc":[{"atl":[[2.36,0],[2.3,11.54]],"id":61631978}],"con":true,"img":false}]}
{"op":"mcm","clk":"11450020427","pt":1717317161466,"mc":[{"id":"1.229554909","rc":[{"atl":[[2.36,11.03]],"id":61631978}],"con":true,"img":false}]}
{"op":"mcm","clk":"11450020436","pt":1717317161568,"mc":[{"id":"1.229554909","rc":[{"atl":[[2.3,0]],"id":61631978}],"con":true,"img":false}]}
{"op":"mcm","clk":"11450022465","pt":1717317181903,"mc":[{"id":"1.229554909","rc":[{"atl":[[2.36,0],[2.3,11.54]],"id":61631978}],"con":true,"img":false}]}
{"op":"mcm","clk":"11450023457","pt":1717317191920,"mc":[{"id":"1.229554909","rc":[{"atl":[[2.36,11.03],[2.3,0]],"id":61631978}],"con":true,"img":false}]}
{"op":"mcm","clk":"11450025543","pt":1717317212396,"mc":[{"id":"1.229554909","rc":[{"atl":[[2.36,0],[2.3,11.54]],"id":61631978}],"con":true,"img":false}]}
{"op":"mcm","clk":"11450026588","pt":1717317222402,"mc":[{"id":"1.229554909","rc":[{"atl":[[2.36,11.03],[2.3,0]],"id":61631978}],"con":true,"img":false}]}
{"op":"mcm","clk":"11450028619","pt":1717317242637,"mc":[{"id":"1.229554909","rc":[{"atl":[[2.36,0],[2.3,11.54]],"id":61631978}],"con":true,"img":false}]}
{"op":"mcm","clk":"11450029578","pt":1717317252670,"mc":[{"id":"1.229554909","rc":[{"atl":[[2.36,11.03],[2.3,0]],"id":61631978}],"con":true,"img":false}]}
{"op":"mcm","clk":"11450031665","pt":1717317273077,"mc":[{"id":"1.229554909","rc":[{"atl":[[2.36,0],[2.3,11.54]],"id":61631978}],"con":true,"img":false}]}
{"op":"mcm","clk":"11450032772","pt":1717317283114,"mc":[{"id":"1.229554909","rc":[{"atl":[[2.36,11.03],[2.3,0]],"id":61631978}],"con":true,"img":false}]}
{"op":"mcm","clk":"11450034950","pt":1717317303934,"mc":[{"id":"1.229554909","rc":[{"atl":[[2.36,0],[2.3,11.54]],"id":61631978}],"con":true,"img":false}]}
{"op":"mcm","clk":"11450036068","pt":1717317313942,"mc":[{"id":"1.229554909","rc":[{"atl":[[2.36,11.03],[2.3,0]],"id":61631978}],"con":true,"img":false}]}
{"op":"mcm","clk":"11450037187","pt":1717317323944,"mc":[{"id":"1.229554909","rc":[{"atl":[[2.36,0],[2.3,11.54]],"id":61631978}],"con":true,"img":false}]}
{"op":"mcm","clk":"11450039989","pt":1717317349450,"mc":[{"id":"1.229554909","rc":[{"atl":[[2.36,11.03],[2.3,0]],"id":61631978}],"con":true,"img":false}]}
{"op":"mcm","clk":"11450040241","pt":1717317351952,"mc":[{"id":"1.229554909","rc":[{"atb":[[1.84,0],[1.94,0]],"id":61631980},{"atb":[[1.78,0],[1.68,0]],"id":61631978}],"con":true,"img":false}]}
{"op":"mcm","clk":"11450040473","pt":1717317354245,"mc":[{"id":"1.229554909","rc":[{"atb":[[1.61,24.59]],"id":61631980}],"con":true,"img":false}]}
{"op":"mcm","clk":"11450040482","pt":1717317354347,"mc":[{"id":"1.229554909","rc":[{"atb":[[1.53,0]],"id":61631980},{"atb":[[1.4,37.5]],"id":61631978}],"con":true,"img":false}]}
{"op":"mcm","clk":"11450041561","pt":1717317364373,"mc":[{"id":"1.229554909","rc":[{"atb":[[1.59,33.9]],"id":61631980},{"atb":[[1.38,52.63]],"id":61631978},{"atl":[[2.36,0],[2.3,11.54]],"id":61631978}],"con":true,"img":false}]}
{"op":"mcm","clk":"11450042154","pt":1717317369851,"mc":[{"id":"1.229554909","rc":[{"atb":[[1.47,0]],"id":61631980},{"atb":[[1.42,35.71]],"id":61631978}],"con":true,"img":false}]}
{"op":"mcm","clk":"11450042607","pt":1717317374353,"mc":[{"id":"1.229554909","rc":[{"atb":[[1.57,43.86]],"id":61631980}],"con":true,"img":false}]}
{"op":"mcm","clk":"11450043007","pt":1717317378261,"mc":[{"id":"1.229554909","rc":[{"atb":[[1.49,0]],"id":61631980},{"atl":[[2.36,11.03],[2.3,0]],"id":61631978}],"con":true,"img":false}]}
{"op":"mcm","clk":"11450043635","pt":1717317384371,"mc":[{"id":"1.229554909","rc":[{"atb":[[1.55,54.55]],"id":61631980}],"con":true,"img":false}]}
{"op":"mcm","clk":"11450043682","pt":1717317384784,"mc":[{"id":"1.229554909","rc":[{"atb":[[1.51,0]],"id":61631980},{"atb":[[1.42,0]],"id":61631978}],"con":true,"img":false}]}
{"op":"mcm","clk":"11450044064","pt":1717317388273,"mc":[{"id":"1.229554909","rc":[{"atb":[[1.36,69.44]],"id":61631978},{"atl":[[2.36,0],[2.3,11.54]],"id":61631978}],"con":true,"img":false}]}
{"op":"mcm","clk":"11450044127","pt":1717317388890,"mc":[{"id":"1.229554909","rc":[{"atb":[[1.84,9.34],[1.94,8.34]],"id":61631980},{"atb":[[1.78,10.06],[1.68,11.54]],"id":61631978}],"con":true,"img":false}]}
{"op":"mcm","clk":"11450046375","pt":1717317410374,"mc":[{"id":"1.229554909","rc":[{"atl":[[2.36,11.03],[2.3,0]],"id":61631978}],"con":true,"img":false}]}
{"op":"mcm","clk":"11450047419","pt":1717317420369,"mc":[{"id":"1.229554909","rc":[{"atl":[[2.36,0],[2.3,11.54]],"id":61631978}],"con":true,"img":false}]}
{"op":"mcm","clk":"11450049691","pt":1717317440668,"mc":[{"id":"1.229554909","rc":[{"atl":[[2.36,11.03],[2.3,0]],"id":61631978}],"con":true,"img":false}]}
{"op":"mcm","clk":"11450050751","pt":1717317450654,"mc":[{"id":"1.229554909","rc":[{"atl":[[2.36,0],[2.3,11.54]],"id":61631978}],"con":true,"img":false}]}
{"op":"mcm","clk":"11450052550","pt":1717317471069,"mc":[{"id":"1.229554909","rc":[{"atl":[[2.36,11.03]],"id":61631978}],"con":true,"img":false}]}
{"op":"mcm","clk":"11450052560","pt":1717317471174,"mc":[{"id":"1.229554909","rc":[{"atl":[[2.3,0]],"id":61631978}],"con":true,"img":false}]}
{"op":"mcm","clk":"11450052882","pt":1717317474650,"mc":[{"id":"1.229554909","rc":[{"atb":[[1.59,0],[1.57,0],[1.55,0],[1.61,0]],"id":61631980}],"con":true,"img":false}]}
{"op":"mcm","clk":"11450052916","pt":1717317475063,"mc":[{"id":"1.229554909","rc":[{"atl":[[2.36,0],[2.3,11.54]],"id":61631978}],"con":true,"img":false}]}
{"op":"mcm","clk":"11450054441","pt":1717317492087,"mc":[{"id":"1.229554909","rc":[{"atl":[[2.36,11.03],[2.3,0]],"id":61631978}],"con":true,"img":false}]}
{"op":"mcm","clk":"11450054740","pt":1717317495186,"mc":[{"id":"1.229554909","rc":[{"atl":[[2.36,0],[2.3,11.54]],"id":61631978}],"con":true,"img":false}]}
{"op":"mcm","clk":"11450055613","pt":1717317505009,"mc":[{"id":"1.229554909","rc":[{"atl":[[2.36,11.03],[2.3,0]],"id":61631978}],"con":true,"img":false}]}
{"op":"mcm","clk":"11450055776","pt":1717317506674,"mc":[{"id":"1.229554909","rc":[{"atl":[[2.36,0],[2.3,11.54]],"id":61631978}],"con":true,"img":false}]}
{"op":"mcm","clk":"11450056592","pt":1717317516682,"mc":[{"id":"1.229554909","rc":[{"atl":[[2.36,11.03],[2.3,0]],"id":61631978}],"con":true,"img":false}]}
{"op":"mcm","clk":"11450062388","pt":1717317580974,"mc":[{"id":"1.229554909","rc":[{"atl":[[2.36,0],[2.3,11.54]],"id":61631978}],"con":true,"img":false}]}
{"op":"mcm","clk":"11450062559","pt":1717317583007,"mc":[{"id":"1.229554909","rc":[{"atl":[[2.36,11.03],[2.3,0]],"id":61631978}],"con":true,"img":false}]}
{"op":"mcm","clk":"11450062584","pt":1717317583266,"mc":[{"id":"1.229554909","rc":[{"atl":[[2.36,0],[2.3,11.54]],"id":61631978}],"con":true,"img":false}]}
{"op":"mcm","clk":"11450062652","pt":1717317584092,"mc":[{"id":"1.229554909","rc":[{"atl":[[2.36,11.03],[2.3,0]],"id":61631978}],"con":true,"img":false}]}
{"op":"mcm","clk":"11450063098","pt":1717317588772,"mc":[{"id":"1.229554909","rc":[{"atl":[[2.36,0],[2.3,11.54]],"id":61631978}],"con":true,"img":false}]}
{"op":"mcm","clk":"11450063976","pt":1717317598794,"mc":[{"id":"1.229554909","rc":[{"atl":[[2.36,11.03],[2.3,0]],"id":61631978}],"con":true,"img":false}]}
{"op":"mcm","clk":"11450076063","pt":1717317730372,"mc":[{"id":"1.229554909","rc":[{"atb":[[1.84,0],[1.94,0]],"id":61631980},{"atb":[[1.78,0],[1.68,0]],"id":61631978}],"con":true,"img":false}]}
{"op":"mcm","clk":"11450077002","pt":1717317740385,"mc":[{"id":"1.229554909","rc":[{"atb":[[1.44,34.09]],"id":61631978}],"con":true,"img":false}]}
{"op":"mcm","clk":"11450077030","pt":1717317740659,"mc":[{"id":"1.229554909","rc":[{"atb":[[1.49,51.02],[1.51,39.22],[1.53,28.3],[1.47,63.83]],"id":61631980}],"con":true,"img":false}]}
{"op":"mcm","clk":"11450077886","pt":1717317750349,"mc":[{"id":"1.229554909","rc":[{"atb":[[1.42,47.62]],"id":61631978}],"con":true,"img":false}]}
{"op":"mcm","clk":"11450078043","pt":1717317752051,"mc":[{"id":"1.229554909","rc":[{"atb":[[1.36,0]],"id":61631978}],"con":true,"img":false}]}
{"op":"mcm","clk":"11450078622","pt":1717317758321,"mc":[{"id":"1.229554909","rc":[{"atb":[[1.44,0],[1.42,35.71]],"id":61631978}],"con":true,"img":false}]}
{"op":"mcm","clk":"11450078991","pt":1717317762426,"mc":[{"id":"1.229554909","rc":[{"atb":[[1.44,34.09]],"id":61631978},{"atl":[[2.36,0],[2.3,11.54]],"id":61631978}],"con":true,"img":false}]}
{"op":"mcm","clk":"11450079083","pt":1717317763464,"mc":[{"id":"1.229554909","rc":[{"atb":[[1.44,0]],"id":61631978},{"atl":[[2.36,11.03],[2.3,0]],"id":61631978}],"con":true,"img":false}]}
{"op":"mcm","clk":"11450079204","pt":1717317764759,"mc":[{"id":"1.229554909","rc":[{"atb":[[1.84,9.34],[1.94,8.34]],"id":61631980},{"atb":[[1.78,10.06],[1.68,11.54]],"id":61631978}],"con":true,"img":false}]}
{"op":"mcm","clk":"11450079242","pt":1717317765082,"mc":[{"id":"1.229554909","rc":[{"atl":[[2.36,0],[2.3,11.54]],"id":61631978}],"con":true,"img":false}]}
{"op":"mcm","clk":"11450079653","pt":1717317769361,"mc":[{"id":"1.229554909","rc":[{"atl":[[2.36,11.03]],"id":61631978}],"con":true,"img":false}]}
{"op":"mcm","clk":"11450079663","pt":1717317769461,"mc":[{"id":"1.229554909","rc":[{"atb":[[1.4,0],[1.42,0]],"id":61631978},{"atl":[[2.3,0]],"id":61631978}],"con":true,"img":false}]}
{"op":"mcm","clk":"11450080552","pt":1717317779344,"mc":[{"id":"1.229554909","rc":[{"atl":[[2.3,11.54]],"id":61631978}],"con":true,"img":false}]}
{"op":"mcm","clk":"11450080557","pt":1717317779447,"mc":[{"id":"1.229554909","rc":[{"atl":[[2.36,0]],"id":61631978}],"con":true,"img":false}]}
{"op":"mcm","clk":"11450081385","pt":1717317789381,"mc":[{"id":"1.229554909","rc":[{"atl":[[2.3,0],[2.34,11.19]],"id":61631978}],"con":true,"img":false}]}
{"op":"mcm","clk":"11450083214","pt":1717317811134,"mc":[{"id":"1.229554909","rc":[{"atl":[[2.3,11.54],[2.34,0]],"id":61631978}],"con":true,"img":false}]}
{"op":"mcm","clk":"11450092597","pt":1717317919317,"mc":[{"id":"1.229554909","rc":[{"atl":[[2.3,0],[2.34,11.19]],"id":61631978}],"con":true,"img":false}]}
{"op":"mcm","clk":"11450093959","pt":1717317934231,"mc":[{"id":"1.229554909","rc":[{"atl":[[2.3,11.54]],"id":61631978}],"con":true,"img":false}]}
{"op":"mcm","clk":"11450093972","pt":1717317934339,"mc":[{"id":"1.229554909","rc":[{"atl":[[2.34,0]],"id":61631978}],"con":true,"img":false}]}
{"op":"mcm","clk":"11450097946","pt":1717317981685,"mc":[{"id":"1.229554909","rc":[{"atl":[[2.3,0],[2.34,11.19]],"id":61631978}],"con":true,"img":false}]}
{"op":"mcm","clk":"11450099232","pt":1717317997628,"mc":[{"id":"1.229554909","rc":[{"atl":[[2.3,11.54],[2.34,0]],"id":61631978}],"con":true,"img":false}]}
{"op":"mcm","clk":"11450103055","pt":1717318040695,"mc":[{"id":"1.229554909","rc":[{"atl":[[2.36,11.03]],"id":61631978}],"con":true,"img":false}]}
{"op":"mcm","clk":"11450103062","pt":1717318040798,"mc":[{"id":"1.229554909","rc":[{"atl":[[2.3,0]],"id":61631978}],"con":true,"img":false}]}
{"op":"mcm","clk":"11450111188","pt":1717318130993,"mc":[{"id":"1.229554909","rc":[{"atb":[[1.84,0],[1.94,0]],"id":61631980},{"atb":[[1.78,0],[1.68,0]],"id":61631978}],"con":true,"img":false}]}
{"op":"mcm","clk":"11450111204","pt":1717318131201,"mc":[{"id":"1.229554909","rc":[{"atb":[[1.53,0],[1.61,24.59]],"id":61631980},{"atb":[[1.4,37.5]],"id":61631978}],"con":true,"img":false}]}
{"op":"mcm","clk":"11450111766","pt":1717318137693,"mc":[{"id":"1.229554909","rc":[{"atb":[[1.42,35.71]],"id":61631978}],"con":true,"img":false}]}
{"op":"mcm","clk":"11450112045","pt":1717318141116,"mc":[{"id":"1.229554909","rc":[{"atb":[[1.59,33.9]],"id":61631980}],"con":true,"img":false}]}
{"op":"mcm","clk":"11450112389","pt":1717318144171,"mc":[{"id":"1.229554909","rc":[{"atb":[[1.47,0]],"id":61631980}],"con":true,"img":false}]}
{"op":"mcm","clk":"11450112497","pt":1717318145309,"mc":[{"id":"1.229554909","rc":[{"atb":[[1.42,0]],"id":61631978}],"con":true,"img":false}]}
{"op":"mcm","clk":"11450112734","pt":1717318147718,"mc":[{"id":"1.229554909","rc":[{"atb":[[1.36,69.44]],"id":61631978},{"atl":[[2.36,0],[2.3,11.54]],"id":61631978}],"con":true,"img":false}]}
{"op":"mcm","clk":"11450113073","pt":1717318151093,"mc":[{"id":"1.229554909","rc":[{"atb":[[1.57,43.86]],"id":61631980}],"con":true,"img":false}]}
{"op":"mcm","clk":"11450113662","pt":1717318157734,"mc":[{"id":"1.229554909","rc":[{"atb":[[1.34,88.24]],"id":61631978}],"con":true,"img":false}]}
{"op":"mcm","clk":"11450113960","pt":1717318160947,"mc":[{"id":"1.229554909","rc":[{"atb":[[1.49,0]],"id":61631980}],"con":true,"img":false}]}
{"op":"mcm","clk":"11450113969","pt":1717318161047,"mc":[{"id":"1.229554909","rc":[{"atb":[[1.4,0],[1.42,35.71]],"id":61631978}],"con":true,"img":false}]}
{"op":"mcm","clk":"11450113981","pt":1717318161151,"mc":[{"id":"1.229554909","rc":[{"atb":[[1.55,54.55]],"id":61631980}],"con":true,"img":false}]}
{"op":"mcm","clk":"11450114498","pt":1717318166751,"mc":[{"id":"1.229554909","rc":[{"atb":[[1.51,0]],"id":61631980},{"atl":[[2.36,11.03],[2.3,0]],"id":61631978}],"con":true,"img":false}]}
{"op":"mcm","clk":"11450115280","pt":1717318175624,"mc":[{"id":"1.229554909","rc":[{"atb":[[1.4,37.5],[1.42,0]],"id":61631978}],"con":true,"img":false}]}
{"op":"mcm","clk":"11450115435","pt":1717318177651,"mc":[{"id":"1.229554909","rc":[{"atb":[[1.84,9.34],[1.94,8.34]],"id":61631980},{"atb":[[1.78,10.06],[1.68,11.54]],"id":61631978}],"con":true,"img":false}]}
{"op":"mcm","clk":"11450115546","pt":1717318179150,"mc":[{"id":"1.229554909","rc":[{"atl":[[2.36,0],[2.3,11.54]],"id":61631978}],"con":true,"img":false}]}
{"op":"mcm","clk":"11450115672","pt":1717318180660,"mc":[{"id":"1.229554909","rc":[{"atb":[[1.59,0],[1.57,0],[1.55,0],[1.61,0]],"id":61631980}],"con":true,"img":false}]}
{"op":"mcm","clk":"11450116493","pt":1717318189133,"mc":[{"id":"1.229554909","rc":[{"atl":[[2.36,11.03],[2.3,0]],"id":61631978}],"con":true,"img":false}]}
{"op":"mcm","clk":"11450116622","pt":1717318190734,"mc":[{"id":"1.229554909","rc":[{"atl":[[2.36,0],[2.3,11.54]],"id":61631978}],"con":true,"img":false}]}
{"op":"mcm","clk":"11450116636","pt":1717318190940,"mc":[{"id":"1.229554909","rc":[{"atl":[[2.36,11.03]],"id":61631978}],"con":true,"img":false}]}
{"op":"mcm","clk":"11450116645","pt":1717318191045,"mc":[{"id":"1.229554909","rc":[{"atl":[[2.3,0]],"id":61631978}],"con":true,"img":false}]}
{"op":"mcm","clk":"11450116939","pt":1717318194254,"mc":[{"id":"1.229554909","rc":[{"atl":[[2.36,0],[2.3,11.54]],"id":61631978}],"con":true,"img":false}]}
{"op":"mcm","clk":"11450117562","pt":1717318201277,"mc":[{"id":"1.229554909","rc":[{"atl":[[2.36,11.03]],"id":61631978}],"con":true,"img":false}]}
{"op":"mcm","clk":"11450117567","pt":1717318201376,"mc":[{"id":"1.229554909","rc":[{"atl":[[2.3,0]],"id":61631978}],"con":true,"img":false}]}
{"op":"mcm","clk":"11450117752","pt":1717318203478,"mc":[{"id":"1.229554909","rc":[{"atl":[[2.36,0],[2.3,11.54]],"id":61631978}],"con":true,"img":false}]}
{"op":"mcm","clk":"11450117989","pt":1717318206081,"mc":[{"id":"1.229554909","rc":[{"atl":[[2.36,11.03],[2.3,0]],"id":61631978}],"con":true,"img":false}]}
{"op":"mcm","clk":"11450138818","pt":1717318447883,"mc":[{"id":"1.229554909","rc":[{"atl":[[2.82,0]],"id":61631980}],"con":true,"img":false}]}
{"op":"mcm","clk":"11450138825","pt":1717318447985,"mc":[{"id":"1.229554909","rc":[{"atl":[[2.86,8.06]],"id":61631980}],"con":true,"img":false}]}
{"op":"mcm","clk":"11450139265","pt":1717318453310,"mc":[{"id":"1.229554909","rc":[{"atl":[[2.82,8.24],[2.86,0]],"id":61631980}],"con":true,"img":false}]}
{"op":"mcm","clk":"11450142086","pt":1717318485120,"mc":[{"id":"1.229554909","rc":[{"atb":[[1.84,0],[1.94,0]],"id":61631980},{"atb":[[1.78,0],[1.68,0]],"id":61631978}],"con":true,"img":false}]}
{"op":"mcm","clk":"11450142797","pt":1717318493228,"mc":[{"id":"1.229554909","rc":[{"atb":[[1.59,33.9],[1.57,43.86],[1.55,54.55],[1.61,24.59]],"id":61631980}],"con":true,"img":false}]}
{"op":"mcm","clk":"11450144001","pt":1717318506857,"mc":[{"id":"1.229554909","rc":[{"atb":[[1.84,9.34],[1.94,8.34]],"id":61631980},{"atb":[[1.78,10.06],[1.68,11.54]],"id":61631978}],"con":true,"img":false}]}
{"op":"mcm","clk":"11450148408","pt":1717318557805,"mc":[{"id":"1.229554909","rc":[{"atb":[[1.59,0],[1.57,0],[1.55,0],[1.61,0]],"id":61631980}],"con":true,"img":false}]}
{"op":"mcm","clk":"11450148919","pt":1717318563627,"mc":[{"id":"1.229554909","rc":[{"atl":[[2.36,0],[2.3,11.54]],"id":61631978}],"con":true,"img":false}]}
{"op":"mcm","clk":"11450171527","pt":1717318800880,"mc":[{"id":"1.229554909","rc":[{"atl":[[2.36,11.03],[2.3,0]],"id":61631978}],"con":true,"img":false}]}
{"op":"mcm","clk":"11450176920","pt":1717318857156,"mc":[{"id":"1.229554909","rc":[{"atb":[[1.84,0],[1.94,0]],"id":61631980},{"atb":[[1.78,0],[1.68,0]],"id":61631978}],"con":true,"img":false}]}
{"op":"mcm","clk":"11450178969","pt":1717318877467,"mc":[{"id":"1.229554909","rc":[{"atb":[[1.84,9.34],[1.94,8.34]],"id":61631980},{"atb":[[1.78,10.06],[1.68,11.54]],"id":61631978}],"con":true,"img":false}]}
{"op":"mcm","clk":"11450180654","pt":1717318895473,"mc":[{"id":"1.229554909","rc":[{"atl":[[2.36,0],[2.3,11.54]],"id":61631978}],"con":true,"img":false}]}
{"op":"mcm","clk":"11450181078","pt":1717318899630,"mc":[{"id":"1.229554909","rc":[{"atl":[[2.36,11.03],[2.3,0]],"id":61631978}],"con":true,"img":false}]}
{"op":"mcm","clk":"11450197782","pt":1717319076694,"mc":[{"id":"1.229554909","rc":[{"atl":[[2.36,0],[2.3,11.54]],"id":61631978}],"con":true,"img":false}]}
{"op":"mcm","clk":"11450197886","pt":1717319077890,"mc":[{"id":"1.229554909","rc":[{"atl":[[2.36,11.03]],"id":61631978}],"con":true,"img":false}]}
{"op":"mcm","clk":"11450197891","pt":1717319077987,"mc":[{"id":"1.229554909","rc":[{"atl":[[2.3,0]],"id":61631978}],"con":true,"img":false}]}
{"op":"mcm","clk":"11450198063","pt":1717319079701,"mc":[{"id":"1.229554909","rc":[{"atl":[[2.36,0],[2.3,11.54]],"id":61631978}],"con":true,"img":false}]}
{"op":"mcm","clk":"11450198139","pt":1717319080585,"mc":[{"id":"1.229554909","rc":[{"atl":[[2.36,11.03],[2.3,0]],"id":61631978}],"con":true,"img":false}]}
{"op":"mcm","clk":"11450198194","pt":1717319081310,"mc":[{"id":"1.229554909","rc":[{"atl":[[2.36,0],[2.3,11.54]],"id":61631978}],"con":true,"img":false}]}
{"op":"mcm","clk":"11450198250","pt":1717319081781,"mc":[{"id":"1.229554909","rc":[{"atl":[[2.36,11.03],[2.3,0]],"id":61631978}],"con":true,"img":false}]}
{"op":"mcm","clk":"11450198301","pt":1717319082300,"mc":[{"id":"1.229554909","rc":[{"atl":[[2.36,0],[2.3,11.54]],"id":61631978}],"con":true,"img":false}]}
{"op":"mcm","clk":"11450199273","pt":1717319092304,"mc":[{"id":"1.229554909","rc":[{"atl":[[2.36,11.03],[2.3,0]],"id":61631978}],"con":true,"img":false}]}
{"op":"mcm","clk":"11450208333","pt":1717319182607,"mc":[{"id":"1.229554909","rc":[{"atb":[[1.84,0],[1.94,0]],"id":61631980},{"atb":[[1.78,0],[1.68,0]],"id":61631978}],"con":true,"img":false}]}
{"op":"mcm","clk":"11450210488","pt":1717319203422,"mc":[{"id":"1.229554909","rc":[{"atb":[[1.84,9.34],[1.94,8.34]],"id":61631980},{"atb":[[1.78,10.06],[1.68,11.54]],"id":61631978}],"con":true,"img":false}]}
{"op":"mcm","clk":"11450210504","pt":1717319203529,"mc":[{"id":"1.229554909","rc":[{"atb":[[1.59,33.9],[1.57,43.86],[1.55,54.55],[1.61,24.59]],"id":61631980}],"con":true,"img":false}]}
{"op":"mcm","clk":"11450216164","pt":1717319258670,"mc":[{"id":"1.229554909","rc":[{"atb":[[1.59,0],[1.57,0],[1.55,0],[1.61,0]],"id":61631980}],"con":true,"img":false}]}
{"op":"mcm","clk":"11450216200","pt":1717319258975,"mc":[{"id":"1.229554909","rc":[{"atl":[[2.36,0],[2.3,11.54]],"id":61631978}],"con":true,"img":false}]}
{"op":"mcm","clk":"11450216250","pt":1717319259593,"mc":[{"id":"1.229554909","rc":[{"atl":[[2.36,11.03],[2.3,0]],"id":61631978}],"con":true,"img":false}]}
{"op":"mcm","clk":"11450216409","pt":1717319261003,"mc":[{"id":"1.229554909","rc":[{"atl":[[2.36,0],[2.3,11.54]],"id":61631978}],"con":true,"img":false}]}
{"op":"mcm","clk":"11450216456","pt":1717319261470,"mc":[{"id":"1.229554909","rc":[{"atl":[[2.36,11.03],[2.3,0]],"id":61631978}],"con":true,"img":false}]}
{"op":"mcm","clk":"11450216576","pt":1717319262581,"mc":[{"id":"1.229554909","rc":[{"atl":[[2.36,0],[2.3,11.54]],"id":61631978}],"con":true,"img":false}]}
{"op":"mcm","clk":"11450217593","pt":1717319272590,"mc":[{"id":"1.229554909","rc":[{"atl":[[2.36,11.03],[2.3,0]],"id":61631978}],"con":true,"img":false}]}
{"op":"mcm","clk":"11450228413","pt":1717319388717,"mc":[{"id":"1.229554909","rc":[{"atb":[[1.84,0],[1.94,0]],"id":61631980},{"atb":[[1.78,0],[1.68,0]],"id":61631978}],"con":true,"img":false}]}
{"op":"mcm","clk":"11450229058","pt":1717319395993,"mc":[{"id":"1.229554909","rc":[{"atb":[[1.59,33.9],[1.57,43.86],[1.55,54.55],[1.61,24.59]],"id":61631980}],"con":true,"img":false}]}
{"op":"mcm","clk":"11450230358","pt":1717319410122,"mc":[{"id":"1.229554909","rc":[{"atb":[[1.84,9.34],[1.94,8.34]],"id":61631980},{"atb":[[1.78,10.06],[1.68,11.54]],"id":61631978}],"con":true,"img":false}]}
{"op":"mcm","clk":"11450232863","pt":1717319436442,"mc":[{"id":"1.229554909","rc":[{"atb":[[1.59,0],[1.57,0],[1.55,0],[1.61,0]],"id":61631980}],"con":true,"img":false}]}
{"op":"mcm","clk":"11450232884","pt":1717319436650,"mc":[{"id":"1.229554909","rc":[{"atl":[[2.36,0],[2.3,11.54]],"id":61631978}],"con":true,"img":false}]}
{"op":"mcm","clk":"11450233079","pt":1717319438776,"mc":[{"id":"1.229554909","rc":[{"atl":[[2.36,11.03],[2.3,0]],"id":61631978}],"con":true,"img":false}]}
{"op":"mcm","clk":"11450233168","pt":1717319439767,"mc":[{"id":"1.229554909","rc":[{"atl":[[2.36,0],[2.3,11.54]],"id":61631978}],"con":true,"img":false}]}
{"op":"mcm","clk":"11450233259","pt":1717319440650,"mc":[{"id":"1.229554909","rc":[{"atl":[[2.36,11.03],[2.3,0]],"id":61631978}],"con":true,"img":false}]}
{"op":"mcm","clk":"11450233329","pt":1717319441374,"mc":[{"id":"1.229554909","rc":[{"atl":[[2.36,0],[2.3,11.54]],"id":61631978}],"con":true,"img":false}]}
{"op":"mcm","clk":"11450233345","pt":1717319441579,"mc":[{"id":"1.229554909","rc":[{"atl":[[2.36,11.03],[2.3,0]],"id":61631978}],"con":true,"img":false}]}
{"op":"mcm","clk":"11450233368","pt":1717319441789,"mc":[{"id":"1.229554909","rc":[{"atl":[[2.36,0],[2.3,11.54]],"id":61631978}],"con":true,"img":false}]}
{"op":"mcm","clk":"11450233555","pt":1717319443465,"mc":[{"id":"1.229554909","rc":[{"atl":[[2.36,11.03],[2.3,0]],"id":61631978}],"con":true,"img":false}]}
{"op":"mcm","clk":"11450234767","pt":1717319456085,"mc":[{"id":"1.229554909","rc":[{"atl":[[2.36,0],[2.34,11.19]],"id":61631978}],"con":true,"img":false}]}
{"op":"mcm","clk":"11450236588","pt":1717319476075,"mc":[{"id":"1.229554909","rc":[{"atl":[[2.3,11.54],[2.34,0]],"id":61631978}],"con":true,"img":false}]}
{"op":"mcm","clk":"11450242751","pt":1717319543125,"mc":[{"id":"1.229554909","rc":[{"atl":[[2.3,0],[2.38,10.87]],"id":61631978}],"con":true,"img":false}]}
{"op":"mcm","clk":"11450242874","pt":1717319544531,"mc":[{"id":"1.229554909","rc":[{"atl":[[2.3,11.54]],"id":61631978}],"con":true,"img":false}]}
{"op":"mcm","clk":"11450242931","pt":1717319545049,"mc":[{"id":"1.229554909","rc":[{"atl":[[2.36,11.03],[2.3,0]],"id":61631978}],"con":true,"img":false}]}
{"op":"mcm","clk":"11450244084","pt":1717319557151,"mc":[{"id":"1.229554909","rc":[{"atl":[[2.36,0]],"id":61631978}],"con":true,"img":false}]}
{"op":"mcm","clk":"11450244175","pt":1717319558283,"mc":[{"id":"1.229554909","rc":[{"atl":[[2.36,11.03]],"id":61631978}],"con":true,"img":false}]}
{"op":"mcm","clk":"11450244211","pt":1717319558649,"mc":[{"id":"1.229554909","rc":[{"atl":[[2.36,0]],"id":61631978}],"con":true,"img":false}]}
{"op":"mcm","clk":"11450244262","pt":1717319559164,"mc":[{"id":"1.229554909","rc":[{"atl":[[2.36,11.03]],"id":61631978}],"con":true,"img":false}]}
{"op":"mcm","clk":"11450244399","pt":1717319560562,"mc":[{"id":"1.229554909","rc":[{"atl":[[2.36,0]],"id":61631978}],"con":true,"img":false}]}
{"op":"mcm","clk":"11450244426","pt":1717319560873,"mc":[{"id":"1.229554909","rc":[{"atl":[[2.36,11.03]],"id":61631978}],"con":true,"img":false}]}
{"op":"mcm","clk":"11450244928","pt":1717319566413,"mc":[{"id":"1.229554909","rc":[{"atb":[[1.45,99.64],[1.95,4.18]],"id":61631980},{"atl":[[2.82,0],[4.5,4.29],[2.88,0],[2.9,0],[3.95,4.18],[4.9,21.4],[2.94,0]],"id":61631980},{"atb":[[1.4,0],[1.36,0],[1.19,90.13],[1.32,2],[1.34,0],[1.38,0]],"id":61631978},{"atl":[[2.36,0],[2.4,36.19],[5.6,0],[2.18,2]],"id":61631978}],"con":true,"img":false}]}
{"op":"mcm","clk":"11450244937","pt":1717319566470,"mc":[{"id":"1.229554909","rc":[{"atl":[[6.6,0]],"id":61631980}],"con":true,"img":false}]}
{"op":"mcm","clk":"11450244947","pt":1717319566580,"mc":[{"id":"1.229554909","rc":[{"atb":[[1.45,0],[1.26,99.64]],"id":61631980},{"atl":[[2.36,11.03],[2.12,2],[2.18,0]],"id":61631978}],"con":true,"img":false}]}
{"op":"mcm","clk":"11450244959","pt":1717319566682,"mc":[{"id":"1.229554909","rc":[{"atl":[[2.36,32.16],[2.4,14.29]],"id":61631978}],"con":true,"img":false}]}
{"op":"mcm","clk":"11450245026","pt":1717319567402,"mc":[{"id":"1.229554909","rc":[{"atb":[[2.02,2]],"id":61631980},{"atl":[[2.02,2]],"id":61631978}],"con":true,"img":false}]}
{"op":"mcm","clk":"11450245037","pt":1717319567513,"mc":[{"id":"1.229554909","rc":[{"atb":[[1.95,0]],"id":61631980},{"atl":[[2.36,21.13],[2.12,0]],"id":61631978}],"con":true,"img":false}]}
{"op":"mcm","clk":"11450245169","pt":1717319568898,"mc":[{"id":"1.229554909","rc":[{"atb":[[2,2]],"id":61631980}],"con":true,"img":false}]}
{"op":"mcm","clk":"11450245179","pt":1717319569001,"mc":[{"id":"1.229554909","rc":[{"atb":[[2.02,0]],"id":61631980}],"con":true,"img":false}]}
{"op":"mcm","clk":"11450245260","pt":1717319569985,"mc":[{"id":"1.229554909","rc":[{"atb":[[2,0],[2.02,2]],"id":61631980}],"con":true,"img":false}]}
{"op":"mcm","clk":"11450245282","pt":1717319570190,"mc":[{"id":"1.229554909","rc":[{"atb":[[2,2]],"id":61631980}],"con":true,"img":false}]}
{"op":"mcm","clk":"11450245291","pt":1717319570296,"mc":[{"id":"1.229554909","rc":[{"atb":[[2.02,0]],"id":61631980}],"con":true,"img":false}]}
{"op":"mcm","clk":"11450245448","pt":1717319571896,"mc":[{"id":"1.229554909","rc":[{"atb":[[1.98,2]],"id":61631980},{"atl":[[2.02,0],[2.06,2]],"id":61631978}],"con":true,"img":false}]}
{"op":"mcm","clk":"11450245455","pt":1717319572000,"mc":[{"id":"1.229554909","rc":[{"atb":[[2,0],[1.99,2],[1.98,0]],"id":61631980},{"atl":[[2.06,0],[2.04,2]],"id":61631978}],"con":true,"img":false}]}
{"op":"mcm","clk":"11450245480","pt":1717319572310,"mc":[{"id":"1.229554909","rc":[{"atb":[[1.99,0],[2.02,2]],"id":61631980},{"atl":[[2,2],[2.04,0]],"id":61631978}],"con":true,"img":false}]}
{"op":"mcm","clk":"11450245487","pt":1717319572413,"mc":[{"id":"1.229554909","rc":[{"atb":[[2,2]],"id":61631980},{"atl":[[2.36,0],[2.02,2],[2.06,14.29]],"id":61631978}],"con":true,"img":false}]}
{"op":"mcm","clk":"11450245497","pt":1717319572473,"mc":[{"id":"1.229554909","rc":[{"atb":[[2.02,0]],"id":61631980},{"atl":[[2,0],[2.06,0],[2.38,34]],"id":61631978}],"con":true,"img":false}]}
{"op":"mcm","clk":"11450245507","pt":1717319572570,"mc":[{"id":"1.229554909","rc":[{"atl":[[2.06,14.29]],"id":61631978}],"con":true,"img":false}]}
{"op":"mcm","clk":"11450245516","pt":1717319572675,"mc":[{"id":"1.229554909","rc":[{"atl":[[2.4,50.29],[2.06,0],[2.38,10.87]],"id":61631978}],"con":true,"img":false}]}
{"op":"mcm","clk":"11450245690","pt":1717319574589,"mc":[{"id":"1.229554909","rc":[{"atl":[[4.7,5.41]],"id":61631980}],"con":true,"img":false}]}
{"op":"mcm","clk":"11450245710","pt":1717319574790,"mc":[{"id":"1.229554909","rc":[{"atl":[[2.42,14.08]],"id":61631978}],"con":true,"img":false}]}
{"op":"mcm","clk":"11450246318","pt":1717319581518,"mc":[{"id":"1.229554909","rc":[{"atb":[[1.99,2]],"id":61631980}],"con":true,"img":false}]}
{"op":"mcm","clk":"11450246326","pt":1717319581619,"mc":[{"id":"1.229554909","rc":[{"atb":[[2,0]],"id":61631980},{"atl":[[2.02,0],[2.04,2]],"id":61631978}],"con":true,"img":false}]}
{"op":"mcm","clk":"11450246355","pt":1717319581930,"mc":[{"id":"1.229554909","rc":[{"atb":[[2,2],[1.99,0]],"id":61631980},{"atl":[[2.02,2],[2.04,0]],"id":61631978}],"con":true,"img":false}]}
{"op":"mcm","clk":"11450246413","pt":1717319582512,"mc":[{"id":"1.229554909","rc":[{"atb":[[1.84,0],[1.94,0]],"id":61631980},{"atb":[[1.78,0],[1.68,0]],"id":61631978}],"con":true,"img":false}]}
{"op":"mcm","clk":"11450246436","pt":1717319582743,"mc":[{"id":"1.229554909","rc":[{"atb":[[1.59,33.9],[1.03,101.64],[1.57,43.86],[1.55,54.55],[1.26,0],[1.61,24.59]],"id":61631980},{"atl":[[4.9,27.81]],"id":61631980},{"atb":[[1.03,92.13],[1.19,0]],"id":61631978}],"con":true,"img":false}]}
{"op":"mcm","clk":"11450246467","pt":1717319582903,"mc":[{"id":"1.229554909","rc":[{"atb":[[1.27,92.59],[1.25,120],[1.29,68.97],[1.31,48.39]],"id":61631978},{"atl":[[2.46,17.12]],"id":61631978}],"con":true,"img":false}]}
{"op":"mcm","clk":"11450246619","pt":1717319584515,"mc":[{"id":"1.229554909","rc":[{"atl":[[5.6,9.7],[4.9,6.41]],"id":61631980}],"con":true,"img":false}]}
{"op":"mcm","clk":"11450246935","pt":1717319588032,"mc":[{"id":"1.229554909","rc":[{"atb":[[1.03,0],[1.26,101.64]],"id":61631980},{"atb":[[1.03,0],[1.19,137.94]],"id":61631978}],"con":true,"img":false}]}
{"op":"mcm","clk":"11450247158","pt":1717319590728,"mc":[{"id":"1.229554909","rc":[{"atl":[[5.1,7.32]],"id":61631980}],"con":true,"img":false}]}
{"op":"mcm","clk":"11450247307","pt":1717319592326,"mc":[{"id":"1.229554909","rc":[{"atb":[[2,0],[2.02,2]],"id":61631980},{"atl":[[2,2],[2.02,0]],"id":61631978}],"con":true,"img":false}]}
{"op":"mcm","clk":"11450247315","pt":1717319592431,"mc":[{"id":"1.229554909","rc":[{"atl":[[2.4,14.29],[2.06,14.08]],"id":61631978}],"con":true,"img":false}]}
{"op":"mcm","clk":"11450247322","pt":1717319592535,"mc":[{"id":"1.229554909","rc":[{"atl":[[2.06,0],[2.38,26.95]],"id":61631978}],"con":true,"img":false}]}
{"op":"mcm","clk":"11450247472","pt":1717319594133,"mc":[{"id":"1.229554909","rc":[{"atb":[[2.04,2]],"id":61631980},{"atl":[[2,0],[1.99,2]],"id":61631978}],"con":true,"img":false}]}
{"op":"mcm","clk":"11450247477","pt":1717319594238,"mc":[{"id":"1.229554909","rc":[{"atb":[[2.02,0]],"id":61631980}],"con":true,"img":false}]}
{"op":"mcm","clk":"11450247605","pt":1717319595636,"mc":[{"id":"1.229554909","rc":[{"atb":[[1.84,9.34],[1.94,8.34]],"id":61631980},{"atb":[[1.78,10.06],[1.68,11.54]],"id":61631978}],"con":true,"img":false}]}
{"op":"mcm","clk":"11450247656","pt":1717319596111,"mc":[{"id":"1.229554909","rc":[{"atl":[[4.9,14.99]],"id":61631980}],"con":true,"img":false}]}
{"op":"mcm","clk":"11450247666","pt":1717319596210,"mc":[{"id":"1.229554909","rc":[{"atl":[[5.6,0]],"id":61631980}],"con":true,"img":false}]}
{"op":"mcm","clk":"11450247893","pt":1717319598827,"mc":[{"id":"1.229554909","rc":[{"atl":[[2.36,11.03],[2.38,16.08]],"id":61631978}],"con":true,"img":false}]}
{"op":"mcm","clk":"11450247912","pt":1717319599131,"mc":[{"id":"1.229554909","rc":[{"atl":[[2.36,0],[2.3,11.54]],"id":61631978}],"con":true,"img":false}]}
{"op":"mcm","clk":"11450247921","pt":1717319599235,"mc":[{"id":"1.229554909","rc":[{"atb":[[2.02,2],[2.04,0]],"id":61631980},{"atl":[[2,2],[1.99,0]],"id":61631978}],"con":true,"img":false}]}
{"op":"mcm","clk":"11450247928","pt":1717319599337,"mc":[{"id":"1.229554909","rc":[{"atl":[[2,13.54],[2.38,0]],"id":61631978}],"con":true,"img":false}]}
{"op":"mcm","clk":"11450247937","pt":1717319599442,"mc":[{"id":"1.229554909","rc":[{"atl":[[2,2],[2.38,25.08]],"id":61631978}],"con":true,"img":false}]}
{"op":"mcm","clk":"11450248306","pt":1717319604137,"mc":[{"id":"1.229554909","rc":[{"atl":[[2.24,12.1]],"id":61631978}],"con":true,"img":false}]}
{"op":"mcm","clk":"11450248312","pt":1717319604241,"mc":[{"id":"1.229554909","rc":[{"atl":[[2.3,0]],"id":61631978}],"con":true,"img":false}]}
{"op":"mcm","clk":"11450248322","pt":1717319604348,"mc":[{"id":"1.229554909","rc":[{"atl":[[1.99,2]],"id":61631978}],"con":true,"img":false}]}
{"op":"mcm","clk":"11450248331","pt":1717319604449,"mc":[{"id":"1.229554909","rc":[{"atb":[[2.02,0],[2.04,2]],"id":61631980},{"atl":[[2,0]],"id":61631978}],"con":true,"img":false}]}
{"op":"mcm","clk":"11450248345","pt":1717319604609,"mc":[{"id":"1.229554909","rc":[{"atb":[[2.02,2],[2.04,0]],"id":61631980},{"atl":[[2,2],[1.99,0]],"id":61631978}],"con":true,"img":false}]}
{"op":"mcm","clk":"11450248351","pt":1717319604717,"mc":[{"id":"1.229554909","rc":[{"atl":[[2,14.1],[2.38,0]],"id":61631978}],"con":true,"img":false}]}
{"op":"mcm","clk":"11450248801","pt":1717319609735,"mc":[{"id":"1.229554909","rc":[{"atb":[[2,2],[2.02,0]],"id":61631980},{"atl":[[2,12.1],[2.04,2]],"id":61631978}],"con":true,"img":false}]}
{"op":"mcm","clk":"11450248810","pt":1717319609841,"mc":[{"id":"1.229554909","rc":[{"atl":[[2,0],[2.38,26.2]],"id":61631978}],"con":true,"img":false}]}
{"op":"mcm","clk":"11450248816","pt":1717319609936,"mc":[{"id":"1.229554909","rc":[{"atl":[[2.24,26.2],[2.38,0]],"id":61631978}],"con":true,"img":false}]}
{"op":"mcm","clk":"11450248827","pt":1717319610041,"mc":[{"id":"1.229554909","rc":[{"atl":[[2.24,12.1],[2.38,14.29]],"id":61631978}],"con":true,"img":false}]}
{"op":"mcm","clk":"11450248988","pt":1717319611850,"mc":[{"id":"1.229554909","rc":[{"atl":[[2.28,15.63]],"id":61631978}],"con":true,"img":false}]}
{"op":"mcm","clk":"11450248999","pt":1717319611909,"mc":[{"id":"1.229554909","rc":[{"atl":[[2.38,0],[2.28,29.92]],"id":61631978}],"con":true,"img":false}]}
{"op":"mcm","clk":"11450249292","pt":1717319615428,"mc":[{"id":"1.229554909","rc":[{"atb":[[2,0],[2.02,2]],"id":61631980},{"atl":[[2.24,0],[2.4,0],[2,2],[2.04,0],[2.28,14.29],[2.26,11.9]],"id":61631978}],"con":true,"img":false}]}
{"op":"mcm","clk":"11450249300","pt":1717319615532,"mc":[{"id":"1.229554909","rc":[{"atl":[[2.24,14.29],[2.28,0]],"id":61631978}],"con":true,"img":false}]}
{"op":"mcm","clk":"11450249415","pt":1717319616952,"mc":[{"id":"1.229554909","rc":[{"atb":[[1.15,99.64],[1.26,0]],"id":61631980},{"atl":[[4.5,0],[3.95,0],[4.2,2],[4.7,4.05]],"id":61631980},{"atb":[[1.32,0],[1.29,0],[1.31,0]],"id":61631978}],"con":true,"img":false}]}
{"op":"mcm","clk":"11450249421","pt":1717319617035,"mc":[{"id":"1.229554909","rc":[{"atl":[[4.9,6.41],[5.2,10.82]],"id":61631980},{"atb":[[1.3,2]],"id":61631978}],"con":true,"img":false}]}
{"op":"mcm","clk":"11450249482","pt":1717319617644,"mc":[{"id":"1.229554909","rc":[{"atl":[[1.98,2]],"id":61631978}],"con":true,"img":false}]}
{"op":"mcm","clk":"11450249494","pt":1717319617750,"mc":[{"id":"1.229554909","rc":[{"atl":[[2,0],[1.99,2]],"id":61631978}],"con":true,"img":false}]}
{"op":"mcm","clk":"11450249504","pt":1717319617856,"mc":[{"id":"1.229554909","rc":[{"atl":[[1.98,0]],"id":61631978}],"con":true,"img":false}]}
{"op":"mcm","clk":"11450249605","pt":1717319619148,"mc":[{"id":"1.229554909","rc":[{"atl":[[1.99,0],[2.02,2]],"id":61631978}],"con":true,"img":false}]}
{"op":"mcm","clk":"11450249712","pt":1717319620247,"mc":[{"id":"1.229554909","rc":[{"atl":[[2.3,11.54],[2.26,0]],"id":61631978}],"con":true,"img":false}]}
{"op":"mcm","clk":"11450249797","pt":1717319621236,"mc":[{"id":"1.229554909","rc":[{"atl":[[2.26,11.9]],"id":61631978}],"con":true,"img":false}]}
{"op":"mcm","clk":"11450249927","pt":1717319622283,"mc":[{"id":"1.229554909","rc":[{"atl":[[2.26,0]],"id":61631978}],"con":true,"img":false}]}
{"op":"mcm","clk":"11450249960","pt":1717319622679,"mc":[{"id":"1.229554909","rc":[{"atb":[[2.02,0],[2.04,2]],"id":61631980},{"atl":[[2,2],[2.02,0],[2.26,11.9]],"id":61631978}],"con":true,"img":false}]}
{"op":"mcm","clk":"11450250119","pt":1717319624364,"mc":[{"id":"1.229554909","rc":[{"atb":[[1.84,0],[1.94,0]],"id":61631980},{"atl":[[4.9,5.13]],"id":61631980},{"atb":[[1.78,0],[1.68,0]],"id":61631978},{"atl":[[2.26,0]],"id":61631978}],"con":true,"img":false}]}
{"op":"mcm","clk":"11450250137","pt":1717319624571,"mc":[{"id":"1.229554909","rc":[{"atl":[[6,10.26],[5.2,0]],"id":61631980},{"atb":[[1.29,51.72]],"id":61631978}],"con":true,"img":false}]}
{"op":"mcm","clk":"11450250317","pt":1717319626352,"mc":[{"id":"1.229554909","rc":[{"atb":[[1.62,24.19],[1.61,0]],"id":61631980}],"con":true,"img":false}]}
{"op":"mcm","clk":"11450250350","pt":1717319626661,"mc":[{"id":"1.229554909","rc":[{"atb":[[1.62,0],[1.61,24.59]],"id":61631980}],"con":true,"img":false}]}
{"op":"mcm","clk":"11450250364","pt":1717319626863,"mc":[{"id":"1.229554909","rc":[{"atl":[[2.26,11.9]],"id":61631978}],"con":true,"img":false}]}
{"op":"mcm","clk":"11450250557","pt":1717319628951,"mc":[{"id":"1.229554909","rc":[{"atb":[[1.62,24.19]],"id":61631980}],"con":true,"img":false}]}
{"op":"mcm","clk":"11450250560","pt":1717319629087,"mc":[{"id":"1.229554909","rc":[{"atb":[[1.61,0]],"id":61631980}],"con":true,"img":false}]}
{"op":"mcm","clk":"11450250581","pt":1717319629265,"mc":[{"id":"1.229554909","rc":[{"atl":[[2.26,0]],"id":61631978}],"con":true,"img":false}]}
{"op":"mcm","clk":"11450250687","pt":1717319630551,"mc":[{"id":"1.229554909","rc":[{"atl":[[2.26,11.9]],"id":61631978}],"con":true,"img":false}]}
{"op":"mcm","clk":"11450250916","pt":1717319633356,"mc":[{"id":"1.229554909","rc":[{"atl":[[2.28,11.72],[2.26,0]],"id":61631978}],"con":true,"img":false}]}
{"op":"mcm","clk":"11450251157","pt":1717319636157,"mc":[{"id":"1.229554909","rc":[{"atl":[[5.1,6.1]],"id":61631980}],"con":true,"img":false}]}
{"op":"mcm","clk":"11450251488","pt":1717319640503,"mc":[{"id":"1.229554909","rc":[{"atb":[[1.27,74.07]],"id":61631978},{"atl":[[2.32,15.15]],"id":61631978}],"con":true,"img":false}]}
{"op":"mcm","clk":"11450251500","pt":1717319640560,"mc":[{"id":"1.229554909","rc":[{"atb":[[1.63,4.38]],"id":61631980},{"atl":[[4.2,5.92]],"id":61631980},{"atb":[[1.3,6.96]],"id":61631978},{"atl":[[2.22,4.39]],"id":61631978}],"con":true,"img":false}]}
{"op":"mcm","clk":"11450251515","pt":1717319640770,"mc":[{"id":"1.229554909","rc":[{"atl":[[2.24,0],[2.2,11.72]],"id":61631978}],"con":true,"img":false}]}
{"op":"mcm","clk":"11450251698","pt":1717319642993,"mc":[{"id":"1.229554909","rc":[{"atb":[[1.83,9.45],[1.93,8.43]],"id":61631980},{"atb":[[1.8,9.8],[1.7,11.21]],"id":61631978}],"con":true,"img":false}]}
{"op":"mcm","clk":"11450251711","pt":1717319643105,"mc":[{"id":"1.229554909","rc":[{"atl":[[2.3,0],[2.42,0],[2.46,0]],"id":61631978}],"con":true,"img":false}]}
{"op":"mcm","clk":"11450251723","pt":1717319643164,"mc":[{"id":"1.229554909","rc":[{"atl":[[5.3,6.98]],"id":61631980}],"con":true,"img":false}]}
{"op":"mcm","clk":"11450251760","pt":1717319643479,"mc":[{"id":"1.229554909","rc":[{"atb":[[1.62,0]],"id":61631980},{"atl":[[6,0],[5.2,11.06]],"id":61631980}],"con":true,"img":false}]}
{"op":"mcm","clk":"11450251804","pt":1717319643991,"mc":[{"id":"1.229554909","rc":[{"atl":[[2.32,11.36],[2.28,0],[2.26,11.9]],"id":61631978}],"con":true,"img":false}]}
{"op":"mcm","clk":"11450251844","pt":1717319644402,"mc":[{"id":"1.229554909","rc":[{"atl":[[2.26,0]],"id":61631978}],"con":true,"img":false}]}
{"op":"mcm","clk":"11450252240","pt":1717319649101,"mc":[{"id":"1.229554909","rc":[{"atb":[[2.02,2]],"id":61631980},{"atl":[[1.92,22],[2.02,54.68],[1.89,15],[1.96,33],[1.87,10]],"id":61631978}],"con":true,"img":false}]}
{"op":"mcm","clk":"11450252255","pt":1717319649208,"mc":[{"id":"1.229554909","rc":[{"atb":[[2.04,0],[1.94,4.37]],"id":61631980},{"atl":[[2,0],[1.92,49.48],[2.02,50],[2.2,0]],"id":61631978}],"con":true,"img":false}]}
{"op":"mcm","clk":"11450252319","pt":1717319649783,"mc":[{"id":"1.229554909","rc":[{"atb":[[2.02,0],[2.04,2]],"id":61631980}],"con":true,"img":false}]}
{"op":"mcm","clk":"11450252360","pt":1717319650298,"mc":[{"id":"1.229554909","rc":[{"atb":[[2.06,2],[2.04,0]],"id":61631980}],"con":true,"img":false}]}
{"op":"mcm","clk":"11450252423","pt":1717319651073,"mc":[{"id":"1.229554909","rc":[{"atb":[[2.02,2],[2.06,0],[1.15,0]],"id":61631980},{"atl":[[4.5,2],[5,3.75],[5.2,0],[5.7,12.03],[4.2,3.92],[4.7,0]],"id":61631980},{"atb":[[1.27,0],[1.3,4.96],[1.29,0]],"id":61631978}],"con":true,"img":false}]}
{"op":"mcm","clk":"11450252431","pt":1717319651181,"mc":[{"id":"1.229554909","rc":[{"atb":[[1.27,2.48]],"id":61631978}],"con":true,"img":false}]}
{"op":"mcm","clk":"11450252448","pt":1717319651387,"mc":[{"id":"1.229554909","rc":[{"atl":[[4.9,0]],"id":61631980}],"con":true,"img":false}]}
{"op":"mcm","clk":"11450252543","pt":1717319652488,"mc":[{"id":"1.229554909","rc":[{"atb":[[1.71,4.97]],"id":61631978}],"con":true,"img":false}]}
{"op":"mcm","clk":"11450252665","pt":1717319653981,"mc":[{"id":"1.229554909","rc":[{"atl":[[1.92,47],[1.91,2.49]],"id":61631978}],"con":true,"img":false}]}
{"op":"mcm","clk":"11450252893","pt":1717319656512,"mc":[{"id":"1.229554909","rc":[{"atb":[[1.99,2],[2.02,0]],"id":61631980},{"atl":[[4.8,2],[4.5,0],[5.1,0],[5,0],[5.3,0]],"id":61631980},{"atb":[[1.27,0],[1.25,0],[1.19,0]],"id":61631978}],"con":true,"img":false}]}
{"op":"mcm","clk":"11450252900","pt":1717319656614,"mc":[{"id":"1.229554909","rc":[{"atb":[[1.25,2.49],[1.15,56.84]],"id":61631978}],"con":true,"img":false}]}
{"op":"mcm","clk":"11450254301","pt":1717319672116,"mc":[{"id":"1.229554909","rc":[{"atl":[[1.89,17.49],[1.91,0]],"id":61631978}],"con":true,"img":false}]}
{"op":"mcm","clk":"11450254786","pt":1717319677235,"mc":[{"id":"1.229554909","rc":[{"atl":[[1.88,2.49]],"id":61631978}],"con":true,"img":false}]}
{"op":"mcm","clk":"11450254798","pt":1717319677341,"mc":[{"id":"1.229554909","rc":[{"atl":[[1.92,22],[1.89,15],[1.9,47]],"id":61631978}],"con":true,"img":false}]}
{"op":"mcm","clk":"11450254882","pt":1717319678431,"mc":[{"id":"1.229554909","rc":[{"atl":[[2.32,0]],"id":61631978}],"con":true,"img":false}]}
{"op":"mcm","clk":"11450254896","pt":1717319678539,"mc":[{"id":"1.229554909","rc":[{"atb":[[1.83,0],[1.93,0]],"id":61631980},{"atb":[[1.8,0],[1.7,0]],"id":61631978}],"con":true,"img":false}]}
{"op":"mcm","clk":"11450254985","pt":1717319679602,"mc":[{"id":"1.229554909","rc":[{"atb":[[1.99,6.26]],"id":61631980}],"con":true,"img":false}]}
{"op":"mcm","clk":"11450255195","pt":1717319682348,"mc":[{"id":"1.229554909","rc":[{"atl":[[1.84,2],[1.88,0]],"id":61631978}],"con":true,"img":false}]}
{"op":"mcm","clk":"11450255203","pt":1717319682406,"mc":[{"id":"1.229554909","rc":[{"atl":[[1.83,2],[1.84,0]],"id":61631978}],"con":true,"img":false}]}
{"op":"mcm","clk":"11450255679","pt":1717319687538,"mc":[{"id":"1.229554909","rc":[{"atl":[[1.83,0],[1.85,2]],"id":61631978}],"con":true,"img":false}]}
{"op":"mcm","clk":"11450255698","pt":1717319687851,"mc":[{"id":"1.229554909","rc":[{"atb":[[1.99,4.26],[2.16,4.1],[1.52,99.64]],"id":61631980},{"atl":[[4.8,0],[4,8.33],[4.1,3.93],[3.4,4.1],[3.8,5.36],[5.7,0],[3.9,6.9],[4.2,13.3]],"id":61631980},{"atb":[[1.4,2],[1.25,0],[1.15,0],[1.24,56.84]],"id":61631978},{"atl":[[1.98,37],[1.9,0]],"id":61631978}],"con":true,"img":false}]}
{"op":"mcm","clk":"11450255715","pt":1717319688153,"mc":[{"id":"1.229554909","rc":[{"atb":[[2.16,0],[2.14,2],[1.71,33.9],[1.52,0]],"id":61631980},{"atl":[[1.85,0],[1.88,2]],"id":61631978}],"con":true,"img":false}]}
{"op":"mcm","clk":"11450255976","pt":1717319690759,"mc":[{"id":"1.229554909","rc":[{"atb":[[1.98,8],[1.88,8.92]],"id":61631980},{"atb":[[1.72,10.89],[1.62,12.65]],"id":61631978}],"con":true,"img":false}]}
{"op":"mcm","clk":"11450255983","pt":1717319690857,"mc":[{"id":"1.229554909","rc":[{"atb":[[2.14,0],[2.08,2]],"id":61631980},{"atl":[[1.89,17.49]],"id":61631978}],"con":true,"img":false}]}
{"op":"mcm","clk":"11450255993","pt":1717319690912,"mc":[{"id":"1.229554909","rc":[{"atl":[[1.88,0]],"id":61631978}],"con":true,"img":false}]}
{"op":"mcm","clk":"11450256397","pt":1717319695968,"mc":[{"id":"1.229554909","rc":[{"atl":[[1.92,24.49],[1.89,15]],"id":61631978}],"con":true,"img":false}]}
{"op":"mcm","clk":"11450256797","pt":1717319700471,"mc":[{"id":"1.229554909","rc":[{"atb":[[2,2],[2.08,0]],"id":61631980}],"con":true,"img":false}]}
{"op":"mcm","clk":"11450256984","pt":1717319702197,"mc":[{"id":"1.229554909","rc":[{"atl":[[3.35,2],[3.4,0],[3.8,0],[3.75,5.45]],"id":61631980},{"atb":[[1.29,56.84],[1.24,0]],"id":61631978}],"con":true,"img":false}]}
{"op":"mcm","clk":"11450257008","pt":1717319702353,"mc":[{"id":"1.229554909","rc":[{"atl":[[4,19.05],[4.1,0]],"id":61631980}],"con":true,"img":false}]}
{"op":"mcm","clk":"11450257072","pt":1717319702979,"mc":[{"id":"1.229554909","rc":[{"atb":[[1.73,4.97]],"id":61631978}],"con":true,"img":false}]}
{"op":"mcm","clk":"11450257085","pt":1717319703077,"mc":[{"id":"1.229554909","rc":[{"atb":[[2,6.23]],"id":61631980},{"atl":[[3.35,5.92]],"id":61631980}],"con":true,"img":false}]}
{"op":"mcm","clk":"11450257491","pt":1717319707378,"mc":[{"id":"1.229554909","rc":[{"atl":[[3.35,3.92],[3.3,4.08]],"id":61631980}],"con":true,"img":false}]}
{"op":"mcm","clk":"11450257651","pt":1717319709286,"mc":[{"id":"1.229554909","rc":[{"atb":[[1.71,0],[1.76,33.9]],"id":61631980}],"con":true,"img":false}]}
{"op":"mcm","clk":"11450258265","pt":1717319715664,"mc":[{"id":"1.229554909","rc":[{"atb":[[1.98,0],[1.88,0]],"id":61631980},{"atb":[[1.72,0],[1.62,0]],"id":61631978}],"con":true,"img":false}]}
{"op":"mcm","clk":"11450259464","pt":1717319727297,"mc":[{"id":"1.229554909","rc":[{"atb":[[1.98,8],[1.88,8.92]],"id":61631980},{"atb":[[1.72,10.89],[1.62,12.65]],"id":61631978}],"con":true,"img":false}]}
{"op":"mcm","clk":"11450259496","pt":1717319727606,"mc":[{"id":"1.229554909","rc":[{"atl":[[3.35,8],[3.3,0]],"id":61631980}],"con":true,"img":false}]}
{"op":"mcm","clk":"11450259762","pt":1717319730963,"mc":[{"id":"1.229554909","rc":[{"atb":[[1.76,0],[1.81,33.9]],"id":61631980},{"atl":[[1.98,0],[1.96,70]],"id":61631978}],"con":true,"img":false}]}
{"op":"mcm","clk":"11450259837","pt":1717319731792,"mc":[{"id":"1.229554909","rc":[{"atl":[[2.24,16.13],[2.32,22.73],[2.28,19.53],[2.2,12.5]],"id":61631978}],"con":true,"img":false}]}
{"op":"mcm","clk":"11450259929","pt":1717319732724,"mc":[{"id":"1.229554909","rc":[{"atl":[[3.3,4.08]],"id":61631980}],"con":true,"img":false}]}
{"op":"mcm","clk":"11450259936","pt":1717319732774,"mc":[{"id":"1.229554909","rc":[{"atl":[[3.35,3.92]],"id":61631980}],"con":true,"img":false}]}
{"op":"mcm","clk":"11450260553","pt":1717319739506,"mc":[{"id":"1.229554909","rc":[{"atl":[[3.35,8],[3.3,0]],"id":61631980},{"atl":[[2.24,0],[2.2,0]],"id":61631978}],"con":true,"img":false}]}
{"op":"mcm","clk":"11450260629","pt":1717319740390,"mc":[{"id":"1.229554909","rc":[{"atl":[[2.2,12.5]],"id":61631978}],"con":true,"img":false}]}
{"op":"mcm","clk":"11450260891","pt":1717319743181,"mc":[{"id":"1.229554909","rc":[{"atb":[[1.97,12.48]],"id":61631980},{"atl":[[3.35,3.92],[3,7.5],[3.3,6.9],[2.94,4.08],[3.75,0]],"id":61631980},{"atb":[[1.4,15.88],[1.58,2.48],[1.29,0]],"id":61631978},{"atl":[[1.96,33],[2.1,48.98]],"id":61631978}],"con":true,"img":false}]}
{"op":"mcm","clk":"11450260904","pt":1717319743284,"mc":[{"id":"1.229554909","rc":[{"atb":[[1.81,0]],"id":61631980},{"atl":[[4,8.33]],"id":61631980}],"con":true,"img":false}]}
{"op":"mcm","clk":"11450261227","pt":1717319747020,"mc":[{"id":"1.229554909","rc":[{"atl":[[2.2,0]],"id":61631978}],"con":true,"img":false}]}
{"op":"mcm","clk":"11450261358","pt":1717319748518,"mc":[{"id":"1.229554909","rc":[{"atl":[[3.1,9.52]],"id":61631980}],"con":true,"img":false}]}
{"op":"mcm","clk":"11450261367","pt":1717319748623,"mc":[{"id":"1.229554909","rc":[{"atl":[[3.3,0],[3.05,11.58]],"id":61631980}],"con":true,"img":false}]}
{"op":"mcm","clk":"11450261378","pt":1717319748725,"mc":[{"id":"1.229554909","rc":[{"atl":[[3.1,21.1],[3.05,0]],"id":61631980}],"con":true,"img":false}]}
{"op":"mcm","clk":"11450261391","pt":1717319748878,"mc":[{"id":"1.229554909","rc":[{"atl":[[4.2,3.92]],"id":61631980}],"con":true,"img":false}]}
{"op":"mcm","clk":"11450261544","pt":1717319750996,"mc":[{"id":"1.229554909","rc":[{"atb":[[1.98,18.51],[1.97,0]],"id":61631980}],"con":true,"img":false}]}
{"op":"mcm","clk":"11450261584","pt":1717319751614,"mc":[{"id":"1.229554909","rc":[{"atl":[[2.92,3.83]],"id":61631980}],"con":true,"img":false}]}
{"op":"mcm","clk":"11450261591","pt":1717319751717,"mc":[{"id":"1.229554909","rc":[{"atl":[[2.9,4.04],[3.1,9.52],[2.94,0],[3.05,8.16]],"id":61631980}],"con":true,"img":false}]}
{"op":"mcm","clk":"11450261679","pt":1717319752706,"mc":[{"id":"1.229554909","rc":[{"atb":[[1.98,10.51],[1.88,0]],"id":61631980},{"atb":[[1.72,0],[1.62,0]],"id":61631978}],"con":true,"img":false}]}
{"op":"mcm","clk":"11450261771","pt":1717319753588,"mc":[{"id":"1.229554909","rc":[{"atb":[[1.98,0],[1.97,12.48]],"id":61631980},{"atl":[[3,0],[2.98,7.58]],"id":61631980}],"con":true,"img":false}]}
{"op":"mcm","clk":"11450262061","pt":1717319756806,"mc":[{"id":"1.229554909","rc":[{"atl":[[2.9,0],[2.86,2]],"id":61631980}],"con":true,"img":false}]}
{"op":"mcm","clk":"11450262447","pt":1717319761917,"mc":[{"id":"1.229554909","rc":[{"atl":[[2.88,2]],"id":61631980}],"con":true,"img":false}]}
{"op":"mcm","clk":"11450262457","pt":1717319762023,"mc":[{"id":"1.229554909","rc":[{"atl":[[2.86,0]],"id":61631980}],"con":true,"img":false}]}
{"op":"mcm","clk":"11450262700","pt":1717319764407,"mc":[{"id":"1.229554909","rc":[{"atb":[[1.98,10.51]],"id":61631980}],"con":true,"img":false}]}
{"op":"mcm","clk":"11450262710","pt":1717319764509,"mc":[{"id":"1.229554909","rc":[{"atb":[[1.97,0]],"id":61631980}],"con":true,"img":false}]}
{"op":"mcm","clk":"11450262731","pt":1717319764723,"mc":[{"id":"1.229554909","rc":[{"atb":[[1.94,12.72],[2.08,7.26]],"id":61631980},{"atb":[[1.55,14.26],[1.65,12.07]],"id":61631978}],"con":true,"img":false}]}
{"op":"mcm","clk":"11450262745","pt":1717319764821,"mc":[{"id":"1.229554909","rc":[{"atb":[[2,4.23],[2.1,4.04]],"id":61631980},{"atl":[[2.88,5.82]],"id":61631980}],"con":true,"img":false}]}
{"op":"mcm","clk":"11450263106","pt":1717319769814,"mc":[{"id":"1.229554909","rc":[{"atb":[[1.59,0],[1.57,0],[1.55,0]],"id":61631980}],"con":true,"img":false}]}
{"op":"mcm","clk":"11450263120","pt":1717319770018,"mc":[{"id":"1.229554909","rc":[{"atb":[[1.63,0],[2.08,11.33]],"id":61631980}],"con":true,"img":false}]}
{"op":"mcm","clk":"11450263244","pt":1717319771824,"mc":[{"id":"1.229554909","rc":[{"atl":[[2.32,0],[2.28,0]],"id":61631978}],"con":true,"img":false}]}
{"op":"mcm","clk":"11450263901","pt":1717319778959,"mc":[{"id":"1.229554909","rc":[{"atb":[[1.73,0]],"id":61631978}],"con":true,"img":false}]}
{"op":"mcm","clk":"11450263963","pt":1717319779735,"mc":[{"id":"1.229554909","rc":[{"atb":[[1.99,14.77],[1.98,0]],"id":61631980},{"atl":[[3,7.5]],"id":61631980}],"con":true,"img":false}]}
{"op":"mcm","clk":"11450263976","pt":1717319779850,"mc":[{"id":"1.229554909","rc":[{"atl":[[2.98,0]],"id":61631980}],"con":true,"img":false}]}
{"op":"mcm","clk":"11450264351","pt":1717319784385,"mc":[{"id":"1.229554909","rc":[{"atl":[[3.2,11.36]],"id":61631980}],"con":true,"img":false}]}
{"op":"mcm","clk":"11450264376","pt":1717319784650,"mc":[{"id":"1.229554909","rc":[{"atl":[[4,0]],"id":61631980}],"con":true,"img":false}]}
{"op":"mcm","clk":"11450264742","pt":1717319788996,"mc":[{"id":"1.229554909","rc":[{"atl":[[3.3,13.04]],"id":61631980}],"con":true,"img":false}]}
{"op":"mcm","clk":"11450264771","pt":1717319789254,"mc":[{"id":"1.229554909","rc":[{"atb":[[2.12,3.88],[1.94,8.34]],"id":61631980},{"atl":[[1.86,5]],"id":61631978}],"con":true,"img":false}]}
{"op":"mcm","clk":"11450264779","pt":1717319789352,"mc":[{"id":"1.229554909","rc":[{"atl":[[3.9,0]],"id":61631980},{"atl":[[1.85,2.49]],"id":61631978}],"con":true,"img":false}]}
{"op":"mcm","clk":"11450264787","pt":1717319789456,"mc":[{"id":"1.229554909","rc":[{"atb":[[2.1,0],[2.14,3.83]],"id":61631980},{"atl":[[1.92,22]],"id":61631978}],"con":true,"img":false}]}
{"op":"mcm","clk":"11450264838","pt":1717319790080,"mc":[{"id":"1.229554909","rc":[{"atb":[[1.99,10.51],[2.16,3.77]],"id":61631980},{"atl":[[2.72,3.83]],"id":61631980},{"atb":[[1.71,0]],"id":61631978},{"atl":[[1.84,5.15]],"id":61631978}],"con":true,"img":false}]}
{"op":"mcm","clk":"11450264845","pt":1717319790184,"mc":[{"id":"1.229554909","rc":[{"atb":[[2.18,3.83],[2.14,0]],"id":61631980},{"atl":[[2.72,0],[2.88,3.82],[2.86,3.8]],"id":61631980},{"atl":[[1.83,5.08],[1.85,0]],"id":61631978}],"con":true,"img":false}]}
{"op":"mcm","clk":"11450264883","pt":1717319790553,"mc":[{"id":"1.229554909","rc":[{"atb":[[1.94,0],[2.08,4.06]],"id":61631980},{"atb":[[1.55,0],[1.65,0]],"id":61631978}],"con":true,"img":false}]}
{"op":"mcm","clk":"11450264891","pt":1717319790657,"mc":[{"id":"1.229554909","rc":[{"atb":[[1.58,0],[1.31,18.36],[1.47,2.48]],"id":61631978}],"con":true,"img":false}]}
{"op":"mcm","clk":"11450264901","pt":1717319790760,"mc":[{"id":"1.229554909","rc":[{"atb":[[1.4,0],[1.27,74.07],[1.25,100],[1.23,130.43],[1.29,51.72]],"id":61631978}],"con":true,"img":false}]}
{"op":"mcm","clk":"11450264939","pt":1717319791283,"mc":[{"id":"1.229554909","rc":[{"atb":[[1.27,55.56],[1.29,0]],"id":61631978}],"con":true,"img":false}]}
{"op":"mcm","clk":"11450265033","pt":1717319792275,"mc":[{"id":"1.229554909","rc":[{"atl":[[2.84,3.61]],"id":61631980},{"atb":[[1.48,5.47]],"id":61631978}],"con":true,"img":false}]}
{"op":"mcm","clk":"11450265040","pt":1717319792378,"mc":[{"id":"1.229554909","rc":[{"atb":[[2,0],[2.2,3.77]],"id":61631980},{"atl":[[4.2,0]],"id":61631980},{"atl":[[1.82,5.16]],"id":61631978}],"con":true,"img":false}]}
{"op":"mcm","clk":"11450265047","pt":1717319792482,"mc":[{"id":"1.229554909","rc":[{"atl":[[1.82,0]],"id":61631978}],"con":true,"img":false}]}
{"op":"mcm","clk":"11450265121","pt":1717319793160,"mc":[{"id":"1.229554909","rc":[{"atl":[[1.83,10.2]],"id":61631978}],"con":true,"img":false}]}
{"op":"mcm","clk":"11450265181","pt":1717319793780,"mc":[{"id":"1.229554909","rc":[{"atl":[[2.22,0],[1.82,5.13]],"id":61631978}],"con":true,"img":false}]}
{"op":"mcm","clk":"11450265295","pt":1717319794972,"mc":[{"id":"1.229554909","rc":[{"atl":[[3,0],[2.98,8.16],[3.05,0],[2.92,11.64]],"id":61631980},{"atl":[[1.87,0]],"id":61631978}],"con":true,"img":false}]}
{"op":"mcm","clk":"11450265320","pt":1717319795276,"mc":[{"id":"1.229554909","rc":[{"atl":[[2.72,3.7],[2.86,0]],"id":61631980}],"con":true,"img":false}]}
{"op":"mcm","clk":"11450265328","pt":1717319795382,"mc":[{"id":"1.229554909","rc":[{"atb":[[2.22,3.7],[2.18,0]],"id":61631980},{"atl":[[1.82,10.27],[1.83,5.12]],"id":61631978}],"con":true,"img":false}]}
{"op":"mcm","clk":"11450265364","pt":1717319795794,"mc":[{"id":"1.229554909","rc":[{"atb":[[1.42,18.36],[1.31,0],[1.47,0],[1.52,5.14]],"id":61631978}],"con":true,"img":false}]}
{"op":"mcm","clk":"11450265415","pt":1717319796260,"mc":[{"id":"1.229554909","rc":[{"atl":[[2.92,3.83],[2.96,7.65]],"id":61631980}],"con":true,"img":false}]}
{"op":"mcm","clk":"11450265451","pt":1717319796675,"mc":[{"id":"1.229554909","rc":[{"atl":[[3.35,0],[2.7,3.69]],"id":61631980},{"atb":[[1.53,5.32]],"id":61631978}],"con":true,"img":false}]}
{"op":"mcm","clk":"11450265460","pt":1717319796776,"mc":[{"id":"1.229554909","rc":[{"atl":[[1.82,5.14]],"id":61631978}],"con":true,"img":false}]}
{"op":"mcm","clk":"11450265561","pt":1717319797970,"mc":[{"id":"1.229554909","rc":[{"atb":[[1.8,99.64],[1.99,0],[2.22,0],[2.08,7.72]],"id":61631980},{"atl":[[2.88,11.8],[2.96,0]],"id":61631980},{"atl":[[1.89,0],[1.96,0],[1.93,5.14],[2.1,0],[1.82,0],[1.92,0],[2.28,30]],"id":61631978}],"con":true,"img":false}]}
{"op":"mcm","clk":"11450265584","pt":1717319798282,"mc":[{"id":"1.229554909","rc":[{"atl":[[2.88,3.82],[2.86,8.06]],"id":61631980}],"con":true,"img":false}]}
{"op":"mcm","clk":"11450265633","pt":1717319798958,"mc":[{"id":"1.229554909","rc":[{"atl":[[2.82,8.24],[2.86,0]],"id":61631980}],"con":true,"img":false}]}
{"op":"mcm","clk":"11450265686","pt":1717319799680,"mc":[{"id":"1.229554909","rc":[{"atl":[[2.82,0],[2.84,11.76]],"id":61631980}],"con":true,"img":false}]}
{"op":"mcm","clk":"11450265736","pt":1717319800298,"mc":[{"id":"1.229554909","rc":[{"atl":[[2.82,8.24]],"id":61631980}],"con":true,"img":false}]}
{"op":"mcm","clk":"11450265744","pt":1717319800396,"mc":[{"id":"1.229554909","rc":[{"atl":[[2.84,3.61],[2.68,3.74]],"id":61631980}],"con":true,"img":false}]}
{"op":"mcm","clk":"11450265750","pt":1717319800501,"mc":[{"id":"1.229554909","rc":[{"atl":[[2.72,0]],"id":61631980}],"con":true,"img":false}]}
{"op":"mcm","clk":"11450265789","pt":1717319800867,"mc":[{"id":"1.229554909","rc":[{"atb":[[1.54,5.14],[1.52,0]],"id":61631978}],"con":true,"img":false}]}
{"op":"mcm","clk":"11450265839","pt":1717319801389,"mc":[{"id":"1.229554909","rc":[{"atl":[[2.82,0],[2.88,11.8]],"id":61631980}],"con":true,"img":false}]}
{"op":"mcm","clk":"11450265872","pt":1717319801703,"mc":[{"id":"1.229554909","rc":[{"atl":[[2.88,3.82]],"id":61631980}],"con":true,"img":false}]}
{"op":"mcm","clk":"11450266072","pt":1717319803785,"mc":[{"id":"1.229554909","rc":[{"atb":[[1.95,8.26],[2.1,7.13]],"id":61631980},{"atb":[[1.63,12.45],[1.53,20.12]],"id":61631978}],"con":true,"img":false}]}
{"op":"mcm","clk":"11450266277","pt":1717319805963,"mc":[{"id":"1.229554909","rc":[{"atb":[[1.59,5.14]],"id":61631978}],"con":true,"img":false}]}
{"op":"mcm","clk":"11450266285","pt":1717319806067,"mc":[{"id":"1.229554909","rc":[{"atb":[[1.54,0]],"id":61631978}],"con":true,"img":false}]}
{"op":"mcm","clk":"11450266936","pt":1717319813399,"mc":[{"id":"1.229554909","rc":[{"atl":[[2.86,8.06]],"id":61631980}],"con":true,"img":false}]}
{"op":"mcm","clk":"11450267005","pt":1717319814276,"mc":[{"id":"1.229554909","rc":[{"atl":[[2.66,3.7]],"id":61631980},{"atb":[[1.64,5.29]],"id":61631978}],"con":true,"img":false}]}
{"op":"mcm","clk":"11450267012","pt":1717319814381,"mc":[{"id":"1.229554909","rc":[{"atl":[[2.64,3.74],[2.92,0],[2.68,0]],"id":61631980}],"con":true,"img":false}]}
{"op":"mcm","clk":"11450267107","pt":1717319815574,"mc":[{"id":"1.229554909","rc":[{"atl":[[2.92,9.52]],"id":61631980}],"con":true,"img":false}]}
{"op":"mcm","clk":"11450267114","pt":1717319815678,"mc":[{"id":"1.229554909","rc":[{"atl":[[2.84,11.76],[2.98,0],[2.86,0]],"id":61631980}],"con":true,"img":false}]}
{"op":"mcm","clk":"11450267146","pt":1717319816086,"mc":[{"id":"1.229554909","rc":[{"atl":[[2.88,0],[2.62,3.7]],"id":61631980}],"con":true,"img":false}]}
{"op":"mcm","clk":"11450267154","pt":1717319816189,"mc":[{"id":"1.229554909","rc":[{"atl":[[2.6,3.74]],"id":61631980}],"con":true,"img":false}]}
{"op":"mcm","clk":"11450267162","pt":1717319816291,"mc":[{"id":"1.229554909","rc":[{"atl":[[2.64,0]],"id":61631980}],"con":true,"img":false}]}
{"op":"mcm","clk":"11450267210","pt":1717319816811,"mc":[{"id":"1.229554909","rc":[{"atl":[[2.84,8.15],[2.58,3.71]],"id":61631980}],"con":true,"img":false}]}
{"op":"mcm","clk":"11450267389","pt":1717319819087,"mc":[{"id":"1.229554909","rc":[{"atl":[[1.83,0]],"id":61631978}],"con":true,"img":false}]}
{"op":"mcm","clk":"11450267407","pt":1717319819297,"mc":[{"id":"1.229554909","rc":[{"atb":[[2.2,0]],"id":61631980}],"con":true,"img":false}]}
{"op":"mcm","clk":"11450267527","pt":1717319820799,"mc":[{"id":"1.229554909","rc":[{"atb":[[2.1,10.88],[2.08,4.06]],"id":61631980},{"atl":[[1.91,5.08],[1.93,0]],"id":61631978}],"con":true,"img":false}]}
{"op":"mcm","clk":"11450267566","pt":1717319821315,"mc":[{"id":"1.229554909","rc":[{"atl":[[2.6,0],[2.84,0],[2.56,3.75]],"id":61631980}],"con":true,"img":false}]}
{"op":"mcm","clk":"11450267725","pt":1717319823097,"mc":[{"id":"1.229554909","rc":[{"atl":[[1.84,0]],"id":61631978}],"con":true,"img":false}]}
{"op":"mcm","clk":"11450267970","pt":1717319825785,"mc":[{"id":"1.229554909","rc":[{"atb":[[2.1,7.13]],"id":61631980},{"atl":[[1.91,0]],"id":61631978}],"con":true,"img":false}]}
{"op":"mcm","clk":"11450267979","pt":1717319825889,"mc":[{"id":"1.229554909","rc":[{"atb":[[2.06,3.75]],"id":61631980},{"atl":[[1.95,2.5]],"id":61631978}],"con":true,"img":false}]}
{"op":"mcm","clk":"11450268090","pt":1717319827234,"mc":[{"id":"1.229554909","rc":[{"atb":[[1.95,0],[2.1,0]],"id":61631980},{"atb":[[1.63,0],[1.53,5.32]],"id":61631978}],"con":true,"img":false}]}
{"op":"mcm","clk":"11450268929","pt":1717319836423,"mc":[{"id":"1.229554909","rc":[{"atb":[[2.06,0],[2.04,3.75]],"id":61631980},{"atl":[[2.02,0]],"id":61631978}],"con":true,"img":false}]}
{"op":"mcm","clk":"11450268946","pt":1717319836631,"mc":[{"id":"1.229554909","rc":[{"atl":[[2.28,0]],"id":61631978}],"con":true,"img":false}]}
{"op":"mcm","clk":"11450268970","pt":1717319836943,"mc":[{"id":"1.229554909","rc":[{"atb":[[2.16,0]],"id":61631980},{"atl":[[2.54,3.88],[2.7,0]],"id":61631980},{"atl":[[1.86,0]],"id":61631978}],"con":true,"img":false}]}
{"op":"mcm","clk":"11450268980","pt":1717319837045,"mc":[{"id":"1.229554909","rc":[{"atl":[[2.04,2],[1.95,0]],"id":61631978}],"con":true,"img":false}]}
{"op":"mcm","clk":"11450269008","pt":1717319837415,"mc":[{"id":"1.229554909","rc":[{"atl":[[2.3,19.23],[2.22,12.3],[2.26,15.87],[2.34,22.39]],"id":61631978}],"con":true,"img":false}]}
{"op":"mcm","clk":"11450269019","pt":1717319837520,"mc":[{"id":"1.229554909","rc":[{"atl":[[2.32,28.17]],"id":61631978}],"con":true,"img":false}]}
{"op":"mcm","clk":"11450269038","pt":1717319837723,"mc":[{"id":"1.229554909","rc":[{"atl":[[2.32,0]],"id":61631978}],"con":true,"img":false}]}
{"op":"mcm","clk":"11450269060","pt":1717319838033,"mc":[{"id":"1.229554909","rc":[{"atl":[[2.04,6.9]],"id":61631978}],"con":true,"img":false}]}
{"op":"mcm","clk":"11450269130","pt":1717319839022,"mc":[{"id":"1.229554909","rc":[{"atb":[[1.95,8.26],[2.1,7.13]],"id":61631980},{"atb":[[1.63,12.45],[1.53,20.12]],"id":61631978}],"con":true,"img":false}]}
{"op":"mcm","clk":"11450269305","pt":1717319841351,"mc":[{"id":"1.229554909","rc":[{"atl":[[2.22,0],[2.26,0]],"id":61631978}],"con":true,"img":false}]}
{"op":"mcm","clk":"11450269316","pt":1717319841455,"mc":[{"id":"1.229554909","rc":[{"atb":[[2.06,3.88],[2.04,0]],"id":61631980}],"con":true,"img":false}]}
{"op":"mcm","clk":"11450269607","pt":1717319844755,"mc":[{"id":"1.229554909","rc":[{"atl":[[2.3,0],[2.34,0]],"id":61631978}],"con":true,"img":false}]}
{"op":"mcm","clk":"11450269691","pt":1717319846044,"mc":[{"id":"1.229554909","rc":[{"atl":[[2.02,2.46],[2.04,4.9]],"id":61631978}],"con":true,"img":false}]}
{"op":"mcm","clk":"11450269726","pt":1717319846563,"mc":[{"id":"1.229554909","rc":[{"atb":[[2.04,3.88]],"id":61631980}],"con":true,"img":false}]}
{"op":"mcm","clk":"11450269733","pt":1717319846620,"mc":[{"id":"1.229554909","rc":[{"atb":[[2.06,0]],"id":61631980}],"con":true,"img":false}]}
{"op":"mcm","clk":"11450269755","pt":1717319846930,"mc":[{"id":"1.229554909","rc":[{"atb":[[2,3.88],[1.73,99.64],[1.8,0],[2.04,0]],"id":61631980},{"atb":[[1.58,3.18]],"id":61631978}],"con":true,"img":false}]}
{"op":"mcm","clk":"11450269763","pt":1717319847029,"mc":[{"id":"1.229554909","rc":[{"atb":[[1.59,0]],"id":61631978}],"con":true,"img":false}]}
{"op":"mcm","clk":"11450270081","pt":1717319851441,"mc":[{"id":"1.229554909","rc":[{"atb":[[2,0],[1.73,0],[1.67,99.64],[1.95,12.14]],"id":61631980},{"atl":[[2.92,0],[2.84,9.52]],"id":61631980},{"atl":[[2.02,0],[2.06,3.18]],"id":61631978}],"con":true,"img":false}]}
{"op":"mcm","clk":"11450270089","pt":1717319851542,"mc":[{"id":"1.229554909","rc":[{"atl":[[980,2]],"id":61631978}],"con":true,"img":false}]}
{"op":"mcm","clk":"11450270098","pt":1717319851647,"mc":[{"id":"1.229554909","rc":[{"atl":[[980,0]],"id":61631978}],"con":true,"img":false}]}
{"op":"mcm","clk":"11450270119","pt":1717319851952,"mc":[{"id":"1.229554909","rc":[{"atb":[[1.96,31.06]],"id":61631980}],"con":true,"img":false}]}
{"op":"mcm","clk":"11450270380","pt":1717319854850,"mc":[{"id":"1.229554909","rc":[{"atl":[[2.06,0],[2.08,3.18]],"id":61631978}],"con":true,"img":false}]}
{"op":"mcm","clk":"11450270692","pt":1717319858780,"mc":[{"id":"1.229554909","rc":[{"atl":[[2.56,0],[2.62,7.58]],"id":61631980},{"atb":[[1.58,0],[1.55,3.18]],"id":61631978}],"con":true,"img":false}]}
{"op":"mcm","clk":"11450270775","pt":1717319859966,"mc":[{"id":"1.229554909","rc":[{"atl":[[2.06,3.18]],"id":61631978}],"con":true,"img":false}]}
{"op":"mcm","clk":"11450270782","pt":1717319860072,"mc":[{"id":"1.229554909","rc":[{"atl":[[2.08,0]],"id":61631978}],"con":true,"img":false}]}
{"op":"mcm","clk":"11450270944","pt":1717319862096,"mc":[{"id":"1.229554909","rc":[{"atb":[[1.95,3.88],[2.1,0]],"id":61631980},{"atb":[[1.63,0],[1.53,5.32]],"id":61631978}],"con":true,"img":false}]}
{"op":"mcm","clk":"11450270963","pt":1717319862260,"mc":[{"id":"1.229554909","rc":[{"atb":[[1.96,0]],"id":61631980}],"con":true,"img":false}]}
{"op":"mcm","clk":"11450271751","pt":1717319871994,"mc":[{"id":"1.229554909","rc":[{"atb":[[1.95,12.14],[2.1,7.13]],"id":61631980},{"atb":[[1.63,12.45],[1.53,20.12]],"id":61631978}],"con":true,"img":false}]}
{"op":"mcm","clk":"11450271774","pt":1717319872293,"mc":[{"id":"1.229554909","rc":[{"atb":[[1.96,31.06]],"id":61631980}],"con":true,"img":false}]}
{"op":"mcm","clk":"11450272197","pt":1717319877466,"mc":[{"id":"1.229554909","rc":[{"atb":[[1.95,8.26]],"id":61631980},{"atl":[[2.06,0],[2.08,3.18]],"id":61631978}],"con":true,"img":false}]}
{"op":"mcm","clk":"11450272205","pt":1717319877568,"mc":[{"id":"1.229554909","rc":[{"atb":[[1.92,3.88]],"id":61631980}],"con":true,"img":false}]}
{"op":"mcm","clk":"11450272215","pt":1717319877776,"mc":[{"id":"1.229554909","rc":[{"atb":[[1.93,32.06]],"id":61631980}],"con":true,"img":false}]}
{"op":"mcm","clk":"11450272223","pt":1717319877878,"mc":[{"id":"1.229554909","rc":[{"atb":[[1.96,0]],"id":61631980}],"con":true,"img":false}]}
{"op":"mcm","clk":"11450272623","pt":1717319882895,"mc":[{"id":"1.229554909","rc":[{"atb":[[1.42,0],[1.47,18.36]],"id":61631978}],"con":true,"img":false}]}
{"op":"mcm","clk":"11450273162","pt":1717319889792,"mc":[{"id":"1.229554909","rc":[{"atl":[[2.84,0],[2.78,9.52]],"id":61631980}],"con":true,"img":false}]}
{"op":"mcm","clk":"11450273242","pt":1717319890928,"mc":[{"id":"1.229554909","rc":[{"atb":[[1.92,0],[2.06,3.88],[1.67,0],[1.78,99.64]],"id":61631980},{"atl":[[2.9,11.36],[2.78,0]],"id":61631980},{"atb":[[1.55,0],[1.57,3.18]],"id":61631978},{"atl":[[2.02,3.18],[2.08,0]],"id":61631978}],"con":true,"img":false}]}
{"op":"mcm","clk":"11450273250","pt":1717319890989,"mc":[{"id":"1.229554909","rc":[{"atl":[[2.3,19.23],[2.22,12.3],[2.26,15.87],[2.34,22.39]],"id":61631978}],"con":true,"img":false}]}
{"op":"mcm","clk":"11450273275","pt":1717319891301,"mc":[{"id":"1.229554909","rc":[{"atb":[[1.96,31.06]],"id":61631980}],"con":true,"img":false}]}
{"op":"mcm","clk":"11450273282","pt":1717319891402,"mc":[{"id":"1.229554909","rc":[{"atl":[[2.3,0],[2.22,0],[2.26,0],[2.34,0]],"id":61631978}],"con":true,"img":false}]}
{"op":"mcm","clk":"11450273411","pt":1717319892808,"mc":[{"id":"1.229554909","rc":[{"atb":[[2.06,0],[2.08,7.94]],"id":61631980}],"con":true,"img":false}]}
{"op":"mcm","clk":"11450273637","pt":1717319895660,"mc":[{"id":"1.229554909","rc":[{"atb":[[1.95,0],[2.1,0]],"id":61631980},{"atb":[[1.63,0],[1.53,5.32]],"id":61631978}],"con":true,"img":false}]}
{"op":"mcm","clk":"11450273647","pt":1717319895861,"mc":[{"id":"1.229554909","rc":[{"atb":[[1.96,0],[1.93,0]],"id":61631980}],"con":true,"img":false}]}
{"op":"mcm","clk":"11450273707","pt":1717319896547,"mc":[{"id":"1.229554909","rc":[{"atl":[[2.3,8.09]],"id":61631978}],"con":true,"img":false}]}
{"op":"mcm","clk":"11450273825","pt":1717319898062,"mc":[{"id":"1.229554909","rc":[{"atb":[[2.1,3.8],[2.08,4.06]],"id":61631980}],"con":true,"img":false}]}
{"op":"mcm","clk":"11450273836","pt":1717319898265,"mc":[{"id":"1.229554909","rc":[{"atl":[[2,5.03]],"id":61631978}],"con":true,"img":false}]}
{"op":"mcm","clk":"11450273844","pt":1717319898369,"mc":[{"id":"1.229554909","rc":[{"atl":[[1.99,4.97]],"id":61631978}],"con":true,"img":false}]}
{"op":"mcm","clk":"11450273853","pt":1717319898485,"mc":[{"id":"1.229554909","rc":[{"atl":[[2.02,0]],"id":61631978}],"con":true,"img":false}]}
{"op":"mcm","clk":"11450274303","pt":1717319904370,"mc":[{"id":"1.229554909","rc":[{"atb":[[2,7.84],[1.9,8.72]],"id":61631980},{"atb":[[1.6,13.07],[1.7,11.21]],"id":61631978}],"con":true,"img":false}]}
{"op":"mcm","clk":"11450274342","pt":1717319904841,"mc":[{"id":"1.229554909","rc":[{"atb":[[2.02,29.23]],"id":61631980}],"con":true,"img":false}]}
{"op":"mcm","clk":"11450274555","pt":1717319907885,"mc":[{"id":"1.229554909","rc":[{"atb":[[1.83,99.64],[2.12,7.68],[1.78,0],[2.1,0]],"id":61631980}],"con":true,"img":false}]}
{"op":"mcm","clk":"11450274578","pt":1717319908243,"mc":[{"id":"1.229554909","rc":[{"atl":[[2.24,9.94],[2.3,0]],"id":61631978}],"con":true,"img":false}]}
{"op":"mcm","clk":"11450274661","pt":1717319909287,"mc":[{"id":"1.229554909","rc":[{"atb":[[2.14,3.85]],"id":61631980},{"atl":[[1.98,5.05]],"id":61631978}],"con":true,"img":false}]}
{"op":"mcm","clk":"11450274669","pt":1717319909388,"mc":[{"id":"1.229554909","rc":[{"atl":[[1.99,0],[1.97,5.18]],"id":61631978}],"con":true,"img":false}]}
{"op":"mcm","clk":"11450274940","pt":1717319912946,"mc":[{"id":"1.229554909","rc":[{"atb":[[2.12,3.88],[2.14,7.72]],"id":61631980}],"con":true,"img":false}]}
{"op":"mcm","clk":"11450274959","pt":1717319913258,"mc":[{"id":"1.229554909","rc":[{"atb":[[1.88,99.64]],"id":61631980}],"con":true,"img":false}]}
{"op":"mcm","clk":"11450274966","pt":1717319913360,"mc":[{"id":"1.229554909","rc":[{"atb":[[1.83,0]],"id":61631980}],"con":true,"img":false}]}
{"op":"mcm","clk":"11450275463","pt":1717319920386,"mc":[{"id":"1.229554909","rc":[{"atb":[[1.92,99.64],[1.88,0]],"id":61631980},{"atl":[[2.24,0],[2.16,10.08]],"id":61631978}],"con":true,"img":false}]}
{"op":"mcm","clk":"11450275552","pt":1717319921369,"mc":[{"id":"1.229554909","rc":[{"atl":[[2.6,3.87]],"id":61631980}],"con":true,"img":false}]}
{"op":"mcm","clk":"11450275557","pt":1717319921469,"mc":[{"id":"1.229554909","rc":[{"atl":[[2.62,3.7]],"id":61631980}],"con":true,"img":false}]}
{"op":"mcm","clk":"11450276227","pt":1717319929399,"mc":[{"id":"1.229554909","rc":[{"atb":[[2,0],[1.9,0]],"id":61631980},{"atb":[[1.6,0],[1.7,0]],"id":61631978}],"con":true,"img":false}]}
{"op":"mcm","clk":"11450276243","pt":1717319929600,"mc":[{"id":"1.229554909","rc":[{"atb":[[1.57,0],[1.58,5.04]],"id":61631978}],"con":true,"img":false}]}
{"op":"mcm","clk":"11450276285","pt":1717319930015,"mc":[{"id":"1.229554909","rc":[{"atb":[[2.16,3.86]],"id":61631980},{"atl":[[1.96,5.04]],"id":61631978}],"con":true,"img":false}]}
{"op":"mcm","clk":"11450276293","pt":1717319930121,"mc":[{"id":"1.229554909","rc":[{"atb":[[2.16,7.72],[2.14,3.85]],"id":61631980},{"atl":[[1.95,5.05]],"id":61631978}],"con":true,"img":false}]}
{"op":"mcm","clk":"11450276300","pt":1717319930174,"mc":[{"id":"1.229554909","rc":[{"atl":[[1.97,0]],"id":61631978}],"con":true,"img":false}]}
{"op":"mcm","clk":"11450276314","pt":1717319930379,"mc":[{"id":"1.229554909","rc":[{"atb":[[2.02,0]],"id":61631980}],"con":true,"img":false}]}
{"op":"mcm","clk":"11450276418","pt":1717319932011,"mc":[{"id":"1.229554909","rc":[{"atb":[[1.27,0],[1.25,0]],"id":61631978}],"con":true,"img":false}]}
{"op":"mcm","clk":"11450276723","pt":1717319936292,"mc":[{"id":"1.229554909","rc":[{"atb":[[1.59,5.05],[1.58,0]],"id":61631978}],"con":true,"img":false}]}
{"op":"mcm","clk":"11450276762","pt":1717319936803,"mc":[{"id":"1.229554909","rc":[{"atb":[[2.06,28.13]],"id":61631980}],"con":true,"img":false}]}
{"op":"mcm","clk":"11450276780","pt":1717319937116,"mc":[{"id":"1.229554909","rc":[{"atl":[[1.94,4.98]],"id":61631978}],"con":true,"img":false}]}
{"op":"mcm","clk":"11450276788","pt":1717319937222,"mc":[{"id":"1.229554909","rc":[{"atl":[[2.04,0],[1.95,0],[1.93,5.02]],"id":61631978}],"con":true,"img":false}]}
{"op":"mcm","clk":"11450276980","pt":1717319939546,"mc":[{"id":"1.229554909","rc":[{"atb":[[1.94,8.34],[2.08,11.33]],"id":61631980},{"atb":[[1.64,17.56],[1.54,14.53]],"id":61631978}],"con":true,"img":false}]}
{"op":"mcm","clk":"11450276997","pt":1717319939703,"mc":[{"id":"1.229554909","rc":[{"atl":[[2,0],[1.92,4.99]],"id":61631978}],"con":true,"img":false}]}
{"op":"mcm","clk":"11450277004","pt":1717319939806,"mc":[{"id":"1.229554909","rc":[{"atb":[[2.1,27.11]],"id":61631980},{"atb":[[1.61,48.89]],"id":61631978}],"con":true,"img":false}]}
{"op":"mcm","clk":"11450277229","pt":1717319942295,"mc":[{"id":"1.229554909","rc":[{"atl":[[1.91,4.99],[1.93,0]],"id":61631978}],"con":true,"img":false}]}
{"op":"mcm","clk":"11450277851","pt":1717319949424,"mc":[{"id":"1.229554909","rc":[{"atb":[[1.98,99.64]],"id":61631980}],"con":true,"img":false}]}
{"op":"mcm","clk":"11450277858","pt":1717319949533,"mc":[{"id":"1.229554909","rc":[{"atb":[[1.92,0]],"id":61631980}],"con":true,"img":false}]}
{"op":"mcm","clk":"11450277897","pt":1717319949940,"mc":[{"id":"1.229554909","rc":[{"atb":[[1.3,0],[1.65,5.05]],"id":61631978}],"con":true,"img":false}]}
{"op":"mcm","clk":"11450278107","pt":1717319952417,"mc":[{"id":"1.229554909","rc":[{"atb":[[2.16,3.86]],"id":61631980}],"con":true,"img":false}]}
{"op":"mcm","clk":"11450278165","pt":1717319953137,"mc":[{"id":"1.229554909","rc":[{"atl":[[1.98,0],[1.9,4.95]],"id":61631978}],"con":true,"img":false}]}
{"op":"mcm","clk":"11450278169","pt":1717319953242,"mc":[{"id":"1.229554909","rc":[{"atl":[[1.89,5.02],[1.91,0]],"id":61631978}],"con":true,"img":false}]}
{"op":"mcm","clk":"11450278236","pt":1717319954022,"mc":[{"id":"1.229554909","rc":[{"atb":[[1.98,0],[1.91,99.64]],"id":61631980}],"con":true,"img":false}]}
{"op":"mcm","clk":"11450278297","pt":1717319954845,"mc":[{"id":"1.229554909","rc":[{"atb":[[2.16,7.76]],"id":61631980},{"atl":[[1.88,4.99],[1.96,0]],"id":61631978}],"con":true,"img":false}]}
{"op":"mcm","clk":"11450278580","pt":1717319958355,"mc":[{"id":"1.229554909","rc":[{"atl":[[1.89,0],[1.87,5.02]],"id":61631978}],"con":true,"img":false}]}
{"op":"mcm","clk":"11450278607","pt":1717319958616,"mc":[{"id":"1.229554909","rc":[{"atl":[[1.86,4.99],[1.94,0]],"id":61631978}],"con":true,"img":false}]}
{"op":"mcm","clk":"11450278618","pt":1717319958825,"mc":[{"id":"1.229554909","rc":[{"atb":[[2.14,30.01]],"id":61631980},{"atl":[[1.85,5.03],[1.87,0]],"id":61631978}],"con":true,"img":false}]}
{"op":"mcm","clk":"11450278642","pt":1717319959136,"mc":[{"id":"1.229554909","rc":[{"atb":[[1.91,0],[1.94,107.98]],"id":61631980},{"atl":[[1.85,10.04]],"id":61631978}],"con":true,"img":false}]}
{"op":"mcm","clk":"11450278649","pt":1717319959241,"mc":[{"id":"1.229554909","rc":[{"atb":[[2.18,3.87],[2.08,7.26]],"id":61631980},{"atl":[[1.92,0]],"id":61631978}],"con":true,"img":false}]}
{"op":"mcm","clk":"11450278657","pt":1717319959347,"mc":[{"id":"1.229554909","rc":[{"atb":[[2.2,3.88],[2.16,3.9]],"id":61631980},{"atl":[[1.84,5.05],[1.9,0]],"id":61631978}],"con":true,"img":false}]}
{"op":"mcm","clk":"11450278661","pt":1717319959450,"mc":[{"id":"1.229554909","rc":[{"atl":[[1.83,5.05],[1.85,5.01]],"id":61631978}],"con":true,"img":false}]}
{"op":"mcm","clk":"11450278690","pt":1717319959819,"mc":[{"id":"1.229554909","rc":[{"atb":[[2.06,0]],"id":61631980},{"atl":[[1.84,0]],"id":61631978}],"con":true,"img":false}]}
{"op":"mcm","clk":"11450278696","pt":1717319959923,"mc":[{"id":"1.229554909","rc":[{"atl":[[1.84,5.04]],"id":61631978}],"con":true,"img":false}]}
{"op":"mcm","clk":"11450278700","pt":1717319960025,"mc":[{"id":"1.229554909","rc":[{"atl":[[1.83,0]],"id":61631978}],"con":true,"img":false}]}
{"op":"mcm","clk":"11450278875","pt":1717319962246,"mc":[{"id":"1.229554909","rc":[{"atl":[[2.6,0],[2.58,7.51]],"id":61631980}],"con":true,"img":false}]}
{"op":"mcm","clk":"11450279014","pt":1717319964057,"mc":[{"id":"1.229554909","rc":[{"atb":[[1.98,102.04],[1.94,8.34]],"id":61631980}],"con":true,"img":false}]}
{"op":"mcm","clk":"11450279062","pt":1717319964889,"mc":[{"id":"1.229554909","rc":[{"atb":[[1.94,0],[2.08,0]],"id":61631980},{"atb":[[1.64,5.29],[1.54,0]],"id":61631978}],"con":true,"img":false}]}
{"op":"mcm","clk":"11450279087","pt":1717319965358,"mc":[{"id":"1.229554909","rc":[{"atb":[[1.61,0]],"id":61631978}],"con":true,"img":false}]}
{"op":"mcm","clk":"11450279135","pt":1717319965960,"mc":[{"id":"1.229554909","rc":[{"atl":[[1.84,10.09]],"id":61631978}],"con":true,"img":false}]}
{"op":"mcm","clk":"11450279234","pt":1717319966847,"mc":[{"id":"1.229554909","rc":[{"atb":[[2.18,29.15]],"id":61631980}],"con":true,"img":false}]}
{"op":"mcm","clk":"11450279300","pt":1717319967627,"mc":[{"id":"1.229554909","rc":[{"atb":[[2.2,0]],"id":61631980},{"trd":[[2.2,7.76]],"ltp":2.2,"tv":7.76,"id":61631980},{"atl":[[2.2,30.12]],"id":61631980}],"con":true,"img":false}]}
{"op":"mcm","clk":"11450279307","pt":1717319967729,"mc":[{"id":"1.229554909","rc":[{"trd":[[2.2,68]],"ltp":2.2,"tv":68.0,"id":61631980},{"atl":[[2.52,3.39],[2.2,0]],"id":61631980}],"con":true,"img":false}]}
{"op":"mcm","clk":"11450279312","pt":1717319967834,"mc":[{"id":"1.229554909","rc":[{"atb":[[2.18,20.39],[2.14,3.85]],"id":61631980},{"atl":[[2.52,0]],"id":61631980},{"atb":[[1.78,38.23]],"id":61631978},{"atl":[[1.84,5.04]],"id":61631978}],"con":true,"img":false}]}
{"op":"mcm","clk":"11450279319","pt":1717319967935,"mc":[{"id":"1.229554909","rc":[{"atb":[[2.18,21.24]],"id":61631980},{"atb":[[1.78,27.38]],"id":61631978},{"trd":[[1.78,21.69]],"ltp":1.78,"tv":21.69,"id":61631978}],"con":true,"img":false}]}
{"op":"mcm","clk":"11450279326","pt":1717319968036,"mc":[{"id":"1.229554909","rc":[{"atb":[[1.78,20.59]],"id":61631978},{"trd":[[1.78,35.27]],"ltp":1.78,"tv":35.27,"id":61631978},{"atl":[[1.84,10.09]],"id":61631978}],"con":true,"img":false}]}
{"op":"mcm","clk":"11450279345","pt":1717319968345,"mc":[{"id":"1.229554909","rc":[{"atl":[[2.54,4.73]],"id":61631980},{"atb":[[1.78,0]],"id":61631978}],"con":true,"img":false}]}
{"op":"mcm","clk":"11450279359","pt":1717319968452,"mc":[{"id":"1.229554909","rc":[{"atl":[[1.84,5.04]],"id":61631978}],"con":true,"img":false}]}
{"op":"mcm","clk":"11450279377","pt":1717319968655,"mc":[{"id":"1.229554909","rc":[{"atb":[[2.3,1.23]],"id":61631980}],"con":true,"img":false}]}
{"op":"mcm","clk":"11450279394","pt":1717319968861,"mc":[{"id":"1.229554909","rc":[{"atb":[[2.2,24.85]],"id":61631980}],"con":true,"img":false}]}
{"op":"mcm","clk":"11450279404","pt":1717319968966,"mc":[{"id":"1.229554909","rc":[{"atb":[[2.1,0]],"id":61631980}],"con":true,"img":false}]}
{"op":"mcm","clk":"11450279421","pt":1717319969173,"mc":[{"id":"1.229554909","rc":[{"atb":[[2.18,21.12]],"id":61631980}],"con":true,"img":false}]}
{"op":"mcm","clk":"11450279436","pt":1717319969331,"mc":[{"id":"1.229554909","rc":[{"atb":[[1.02,184.92]],"id":61631980},{"atb":[[1.02,12.68]],"id":61631978}],"con":true,"img":false}]}
{"op":"mcm","clk":"11450279447","pt":1717319969536,"mc":[{"id":"1.229554909","rc":[{"atl":[[2.54,4.61]],"id":61631980}],"con":true,"img":false}]}
{"op":"mcm","clk":"11450279461","pt":1717319969750,"mc":[{"id":"1.229554909","rc":[{"atb":[[2.18,20.39]],"id":61631980},{"atl":[[2.52,15.66]],"id":61631980},{"atb":[[1.66,21.57]],"id":61631978},{"atl":[[1.77,21.69]],"id":61631978}],"con":true,"img":false}]}
{"op":"mcm","clk":"11450279471","pt":1717319969852,"mc":[{"id":"1.229554909","rc":[{"atb":[[2.22,0.73]],"id":61631980},{"atl":[[1.83,5.18],[1.84,5.06]],"id":61631978}],"con":true,"img":false}]}
{"op":"mcm","clk":"11450279481","pt":1717319969954,"mc":[{"id":"1.229554909","rc":[{"atl":[[2.52,0]],"id":61631980},{"atb":[[1.66,0]],"id":61631978},{"atl":[[1.77,0]],"id":61631978}],"con":true,"img":false}]}
{"op":"mcm","clk":"11450279517","pt":1717319970364,"mc":[{"id":"1.229554909","rc":[{"atb":[[1.02,182.3]],"id":61631980},{"atb":[[1.02,10.06]],"id":61631978}],"con":true,"img":false}]}
{"op":"mcm","clk":"11450279526","pt":1717319970466,"mc":[{"id":"1.229554909","rc":[{"atl":[[1000,1.06]],"id":61631978}],"con":true,"img":false}]}
{"op":"mcm","clk":"11450279555","pt":1717319970830,"mc":[{"id":"1.229554909","rc":[{"atl":[[1000,0.32]],"id":61631978}],"con":true,"img":false}]}
{"op":"mcm","clk":"11450279581","pt":1717319971153,"mc":[{"id":"1.229554909","rc":[{"atl":[[1000,0.17]],"id":61631978}],"con":true,"img":false}]}
{"op":"mcm","clk":"11450279592","pt":1717319971249,"mc":[{"id":"1.229554909","rc":[{"atb":[[1.65,4.9]],"id":61631978},{"trd":[[1.65,0.3]],"ltp":1.65,"tv":0.3,"id":61631978}],"con":true,"img":false}]}
{"op":"mcm","clk":"11450279603","pt":1717319971354,"mc":[{"id":"1.229554909","rc":[{"atb":[[1.02,181.5]],"id":61631980},{"atb":[[1.02,8.87]],"id":61631978}],"con":true,"img":false}]}
{"op":"mcm","clk":"11450279609","pt":1717319971449,"mc":[{"id":"1.229554909","rc":[{"atb":[[2.1,0.8]],"id":61631980},{"atl":[[2.52,3.39]],"id":61631980},{"atb":[[1.74,1.18]],"id":61631978}],"con":true,"img":false}]}
{"op":"mcm","clk":"11450279630","pt":1717319971862,"mc":[{"id":"1.229554909","rc":[{"atl":[[2.5,15.66]],"id":61631980},{"atb":[[1.61,48.89]],"id":61631978}],"con":true,"img":false}]}
{"op":"mcm","clk":"11450279641","pt":1717319972070,"mc":[{"id":"1.229554909","rc":[{"atl":[[2.5,0]],"id":61631980}],"con":true,"img":false}]}
{"op":"mcm","clk":"11450279647","pt":1717319972170,"mc":[{"id":"1.229554909","rc":[{"atb":[[1.65,5.75]],"id":61631978}],"con":true,"img":false}]}
{"op":"mcm","clk":"11450279655","pt":1717319972272,"mc":[{"id":"1.229554909","rc":[{"atl":[[2.5,3.83]],"id":61631980},{"atb":[[1.74,6.27]],"id":61631978}],"con":true,"img":false}]}
{"op":"mcm","clk":"11450279662","pt":1717319972351,"mc":[{"id":"1.229554909","rc":[{"atl":[[2.66,0]],"id":61631980},{"atb":[[1.48,0]],"id":61631978}],"con":true,"img":false}]}
{"op":"mcm","clk":"11450279687","pt":1717319972639,"mc":[{"id":"1.229554909","rc":[{"atb":[[2.1,0]],"id":61631980}],"con":true,"img":false}]}
{"op":"mcm","clk":"11450279693","pt":1717319972745,"mc":[{"id":"1.229554909","rc":[{"atb":[[2.32,0.8]],"id":61631980}],"con":true,"img":false}]}
{"op":"mcm","clk":"11450279701","pt":1717319972847,"mc":[{"id":"1.229554909","rc":[{"atb":[[1.64,51.9]],"id":61631978}],"con":true,"img":false}]}
{"op":"mcm","clk":"11450279711","pt":1717319972947,"mc":[{"id":"1.229554909","rc":[{"atb":[[2.22,2.73]],"id":61631980}],"con":true,"img":false}]}
{"op":"mcm","clk":"11450279718","pt":1717319973055,"mc":[{"id":"1.229554909","rc":[{"atb":[[2.18,3.87]],"id":61631980}],"con":true,"img":false}]}
{"op":"mcm","clk":"11450279738","pt":1717319973358,"mc":[{"id":"1.229554909","rc":[{"atb":[[2.2,0]],"id":61631980}],"con":true,"img":false}]}
{"op":"mcm","clk":"11450279767","pt":1717319973870,"mc":[{"id":"1.229554909","rc":[{"atb":[[2.18,29.15]],"id":61631980}],"con":true,"img":false}]}
{"op":"mcm","clk":"11450279772","pt":1717319973972,"mc":[{"id":"1.229554909","rc":[{"atb":[[2.22,2]],"id":61631980}],"con":true,"img":false}]}
{"op":"mcm","clk":"11450279779","pt":1717319974026,"mc":[{"id":"1.229554909","rc":[{"atb":[[2.18,29.88]],"id":61631980}],"con":true,"img":false}]}
{"op":"mcm","clk":"11450279793","pt":1717319974236,"mc":[{"id":"1.229554909","rc":[{"atl":[[2.52,0]],"id":61631980}],"con":true,"img":false}]}
{"op":"mcm","clk":"11450279840","pt":1717319974955,"mc":[{"id":"1.229554909","rc":[{"atl":[[2.48,3.44]],"id":61631980},{"atb":[[1.64,5.29]],"id":61631978},{"atl":[[1.83,0],[1.84,10.46]],"id":61631978}],"con":true,"img":false}]}
{"op":"mcm","clk":"11450279876","pt":1717319975365,"mc":[{"id":"1.229554909","rc":[{"atb":[[2.32,0]],"id":61631980},{"trd":[[2.32,1.6]],"ltp":2.32,"tv":1.6,"id":61631980},{"atl":[[2.46,3.84],[2.62,0]],"id":61631980},{"atl":[[1.84,5.4]],"id":61631978}],"con":true,"img":false}]}
{"op":"mcm","clk":"11450279912","pt":1717319975836,"mc":[{"id":"1.229554909","rc":[{"atb":[[2.18,4.6],[2.16,29.61]],"id":61631980},{"atb":[[1.64,51.9]],"id":61631978}],"con":true,"img":false}]}
{"op":"mcm","clk":"11450280028","pt":1717319977177,"mc":[{"id":"1.229554909","rc":[{"atb":[[1.94,8.34],[2.08,7.26]],"id":61631980},{"atb":[[1.64,64.16],[1.54,14.53]],"id":61631978}],"con":true,"img":false}]}
{"op":"mcm","clk":"11450280137","pt":1717319978471,"mc":[{"id":"1.229554909","rc":[{"atl":[[2.44,3.5]],"id":61631980}],"con":true,"img":false}]}
{"op":"mcm","clk":"11450280145","pt":1717319978573,"mc":[{"id":"1.229554909","rc":[{"atl":[[2.48,0]],"id":61631980}],"con":true,"img":false}]}
{"op":"mcm","clk":"11450280363","pt":1717319981776,"mc":[{"id":"1.229554909","rc":[{"atb":[[1.92,99.64],[1.98,0]],"id":61631980}],"con":true,"img":false}]}
{"op":"mcm","clk":"11450280371","pt":1717319981876,"mc":[{"id":"1.229554909","rc":[{"atl":[[2.54,7.14],[2.58,3.71]],"id":61631980}],"con":true,"img":false}]}
{"op":"mcm","clk":"11450280414","pt":1717319982343,"mc":[{"id":"1.229554909","rc":[{"atb":[[2.18,3.87]],"id":61631980}],"con":true,"img":false}]}
{"op":"mcm","clk":"11450280422","pt":1717319982446,"mc":[{"id":"1.229554909","rc":[{"atb":[[1.01,18.5]],"id":61631980}],"con":true,"img":false}]}
{"op":"mcm","clk":"11450280461","pt":1717319982858,"mc":[{"id":"1.229554909","rc":[{"atl":[[1.84,10.45]],"id":61631978}],"con":true,"img":false}]}
{"op":"mcm","clk":"11450280573","pt":1717319984151,"mc":[{"id":"1.229554909","rc":[{"atb":[[1.74,2.34]],"id":61631978},{"trd":[[1.74,7.85]],"ltp":1.74,"tv":7.85,"id":61631978}],"con":true,"img":false}]}
{"op":"mcm","clk":"11450280581","pt":1717319984252,"mc":[{"id":"1.229554909","rc":[{"atl":[[1.83,5.09],[1.88,0]],"id":61631978}],"con":true,"img":false}]}
{"op":"mcm","clk":"11450280586","pt":1717319984358,"mc":[{"id":"1.229554909","rc":[{"atb":[[2.22,0],[2.26,2.53],[1.92,0],[1.97,99.64]],"id":61631980},{"atl":[[1.82,5.07],[1.84,5.05]],"id":61631978}],"con":true,"img":false}]}
{"op":"mcm","clk":"11450280617","pt":1717319984768,"mc":[{"id":"1.229554909","rc":[{"atb":[[1.01,17.76]],"id":61631980}],"con":true,"img":false}]}
{"op":"mcm","clk":"11450280626","pt":1717319984874,"mc":[{"id":"1.229554909","rc":[{"atb":[[2.18,4.6]],"id":61631980}],"con":true,"img":false}]}
{"op":"mcm","clk":"11450280665","pt":1717319985388,"mc":[{"id":"1.229554909","rc":[{"atb":[[1.65,5.63]],"id":61631978}],"con":true,"img":false}]}
{"op":"mcm","clk":"11450280718","pt":1717319986158,"mc":[{"id":"1.229554909","rc":[{"atb":[[1.97,0],[1.91,99.64]],"id":61631980}],"con":true,"img":false}]}
{"op":"mcm","clk":"11450280815","pt":1717319987250,"mc":[{"id":"1.229554909","rc":[{"atl":[[2.42,3.8],[2.58,0]],"id":61631980}],"con":true,"img":false}]}
{"op":"mcm","clk":"11450280876","pt":1717319988073,"mc":[{"id":"1.229554909","rc":[{"atb":[[1.71,7.45]],"id":61631978}],"con":true,"img":false}]}
{"op":"mcm","clk":"11450280917","pt":1717319988548,"mc":[{"id":"1.229554909","rc":[{"atl":[[2.42,7.33],[2.44,0]],"id":61631980}],"con":true,"img":false}]}
{"op":"mcm","clk":"11450280965","pt":1717319989270,"mc":[{"id":"1.229554909","rc":[{"atl":[[1.82,10.2],[1.86,0]],"id":61631978}],"con":true,"img":false}]}
{"op":"mcm","clk":"11450281013","pt":1717319989882,"mc":[{"id":"1.229554909","rc":[{"atb":[[2.2,24.85]],"id":61631980}],"con":true,"img":false}]}
{"op":"mcm","clk":"11450281078","pt":1717319990766,"mc":[{"id":"1.229554909","rc":[{"atb":[[2.22,3.79],[2.12,0]],"id":61631980}],"con":true,"img":false}]}
{"op":"mcm","clk":"11450281088","pt":1717319990874,"mc":[{"id":"1.229554909","rc":[{"atb":[[2.3,0.23]],"id":61631980},{"trd":[[2.3,2]],"ltp":2.3,"tv":2.0,"id":61631980}],"con":true,"img":false}]}
{"op":"mcm","clk":"11450281094","pt":1717319990982,"mc":[{"id":"1.229554909","rc":[{"atb":[[2.26,0],[2.24,3.8]],"id":61631980}],"con":true,"img":false}]}
{"op":"mcm","clk":"11450281111","pt":1717319991277,"mc":[{"id":"1.229554909","rc":[{"atb":[[1.96,99.64],[1.91,0]],"id":61631980}],"con":true,"img":false}]}
{"op":"mcm","clk":"11450281195","pt":1717319992262,"mc":[{"id":"1.229554909","rc":[{"atl":[[1.8,6.17]],"id":61631978}],"con":true,"img":false}]}
{"op":"mcm","clk":"11450281209","pt":1717319992466,"mc":[{"id":"1.229554909","rc":[{"atl":[[1.82,5.13],[1.81,5.38]],"id":61631978}],"con":true,"img":false}]}
{"op":"mcm","clk":"11450281391","pt":1717319994173,"mc":[{"id":"1.229554909","rc":[{"atb":[[2.22,0],[2.18,0.73]],"id":61631980},{"atl":[[1.82,0],[1.83,0],[1.84,0],[1.85,0]],"id":61631978}],"con":true,"img":false}]}
{"op":"mcm","clk":"11450281403","pt":1717319994278,"mc":[{"id":"1.229554909","rc":[{"atb":[[2.24,0],[2.22,3.82]],"id":61631980}],"con":true,"img":false}]}
{"op":"mcm","clk":"11450281407","pt":1717319994381,"mc":[{"id":"1.229554909","rc":[{"atb":[[1.89,99.64],[2.22,0],[1.96,0],[2.1,27.11],[2.2,0],[2.16,3.9]],"id":61631980},{"atl":[[1.81,0],[2.14,4.98]],"id":61631978}],"con":true,"img":false}]}
{"op":"mcm","clk":"11450281418","pt":1717319994487,"mc":[{"id":"1.229554909","rc":[{"atb":[[2.3,0],[2.18,4.55]],"id":61631980},{"trd":[[2.3,2.46]],"ltp":2.3,"tv":2.46,"id":61631980},{"atl":[[1.86,4]],"id":61631978}],"con":true,"img":false}]}
{"op":"mcm","clk":"11450281425","pt":1717319994586,"mc":[{"id":"1.229554909","rc":[{"atb":[[2.16,0]],"id":61631980},{"atl":[[2.4,3.91],[2.54,3.26]],"id":61631980},{"atl":[[1.8,0]],"id":61631978}],"con":true,"img":false}]}
{"op":"mcm","clk":"11450281449","pt":1717319994797,"mc":[{"id":"1.229554909","rc":[{"atl":[[2.3,15.38],[2.38,21.74],[2.26,11.9],[2.34,18.66]],"id":61631978}],"con":true,"img":false}]}
{"op":"mcm","clk":"11450281460","pt":1717319994909,"mc":[{"id":"1.229554909","rc":[{"atb":[[2.1,0]],"id":61631980},{"atb":[[1.64,17.56],[1.61,0]],"id":61631978}],"con":true,"img":false}]}
{"op":"mcm","clk":"11450281496","pt":1717319995376,"mc":[{"id":"1.229554909","rc":[{"atb":[[1.9,33.14]],"id":61631980},{"atb":[[1.65,51.52],[1.75,7.45]],"id":61631978},{"atl":[[1.85,3.35]],"id":61631978}],"con":true,"img":false}]}
{"op":"mcm","clk":"11450281546","pt":1717319995988,"mc":[{"id":"1.229554909","rc":[{"atl":[[2.3,0],[2.38,0],[2.26,0],[2.34,0]],"id":61631978}],"con":true,"img":false}]}
{"op":"mcm","clk":"11450281560","pt":1717319996089,"mc":[{"id":"1.229554909","rc":[{"atb":[[1.53,0],[1.76,4.94]],"id":61631978}],"con":true,"img":false}]}
{"op":"mcm","clk":"11450281587","pt":1717319996399,"mc":[{"id":"1.229554909","rc":[{"atb":[[1.95,31.39]],"id":61631980},{"atb":[[1.69,43.22]],"id":61631978}],"con":true,"img":false}]}
{"op":"mcm","clk":"11450281661","pt":1717319997281,"mc":[{"id":"1.229554909","rc":[{"atb":[[2.14,0]],"id":61631980}],"con":true,"img":false}]}
{"op":"mcm","clk":"11450281675","pt":1717319997487,"mc":[{"id":"1.229554909","rc":[{"atb":[[1.77,7.36]],"id":61631978},{"atl":[[1.86,8.03]],"id":61631978}],"con":true,"img":false}]}
{"op":"mcm","clk":"11450281695","pt":1717319997693,"mc":[{"id":"1.229554909","rc":[{"atb":[[1.64,12.26],[1.78,4.88]],"id":61631978}],"con":true,"img":false}]}
{"op":"mcm","clk":"11450281710","pt":1717319997898,"mc":[{"id":"1.229554909","rc":[{"atb":[[1.65,5.63]],"id":61631978},{"atl":[[1.85,0]],"id":61631978}],"con":true,"img":false}]}
{"op":"mcm","clk":"11450281722","pt":1717319998001,"mc":[{"id":"1.229554909","rc":[{"atb":[[2.18,3.82]],"id":61631980}],"con":true,"img":false}]}
{"op":"mcm","clk":"11450281728","pt":1717319998115,"mc":[{"id":"1.229554909","rc":[{"atb":[[1.01,18.5]],"id":61631980}],"con":true,"img":false}]}
{"op":"mcm","clk":"11450281756","pt":1717319998370,"mc":[{"id":"1.229554909","rc":[{"atb":[[1.95,0]],"id":61631980}],"con":true,"img":false}]}
{"op":"mcm","clk":"11450281770","pt":1717319998587,"mc":[{"id":"1.229554909","rc":[{"atb":[[2.1,3.99]],"id":61631980},{"atl":[[1.86,4]],"id":61631978}],"con":true,"img":false}]}
{"op":"mcm","clk":"11450281777","pt":1717319998677,"mc":[{"id":"1.229554909","rc":[{"atl":[[2.3,15.38],[2.38,21.74],[2.26,11.9],[2.34,18.66]],"id":61631978}],"con":true,"img":false}]}
{"op":"mcm","clk":"11450281795","pt":1717319998894,"mc":[{"id":"1.229554909","rc":[{"atb":[[1.71,49.46]],"id":61631978}],"con":true,"img":false}]}
{"op":"mcm","clk":"11450281829","pt":1717319999398,"mc":[{"id":"1.229554909","rc":[{"atb":[[2.18,0]],"id":61631980},{"atl":[[2.42,3.8],[2.38,3.59]],"id":61631980}],"con":true,"img":false}]}
{"op":"mcm","clk":"11450281834","pt":1717319999510,"mc":[{"id":"1.229554909","rc":[{"atb":[[2.12,3.86]],"id":61631980}],"con":true,"img":false}]}
{"op":"mcm","clk":"11450281841","pt":1717319999613,"mc":[{"id":"1.229554909","rc":[{"atb":[[2.12,16.02]],"id":61631980},{"atb":[[1.77,14.96]],"id":61631978},{"atl":[[2.12,4.92],[1.86,0]],"id":61631978}],"con":true,"img":false}]}
{"op":"mcm","clk":"11450281848","pt":1717319999706,"mc":[{"id":"1.229554909","rc":[{"atl":[[2.22,15.38],[2.16,0]],"id":61631978}],"con":true,"img":false}]}
{"op":"mcm","clk":"11450281870","pt":1717319999889,"mc":[{"id":"1.229554909","rc":[{"atb":[[2.1,31.1]],"id":61631980},{"atb":[[1.69,0]],"id":61631978}],"con":true,"img":false}]}
{"op":"mcm","clk":"11450281885","pt":1717320000033,"mc":[{"id":"1.229554909","rc":[{"atl":[[2.1,4.88]],"id":61631978}],"con":true,"img":false}]}
{"op":"mcm","clk":"11450281902","pt":1717320000228,"mc":[{"id":"1.229554909","rc":[{"atb":[[2.1,27.11]],"id":61631980},{"atl":[[2.54,2.53],[2.5,0],[2.36,4.04]],"id":61631980},{"atl":[[2.12,0],[2.1,5.73],[2.08,4.92]],"id":61631978}],"con":true,"img":false}]}
{"op":"mcm","clk":"11450281910","pt":1717320000298,"mc":[{"id":"1.229554909","rc":[{"atl":[[2.38,4.32]],"id":61631980},{"atl":[[2.08,5.7]],"id":61631978}],"con":true,"img":false}]}
{"op":"mcm","clk":"11450281920","pt":1717320000402,"mc":[{"id":"1.229554909","rc":[{"atb":[[2.1,0],[2.08,11.32]],"id":61631980},{"atl":[[2.06,4.78]],"id":61631978}],"con":true,"img":false}]}
{"op":"mcm","clk":"11450281927","pt":1717320000518,"mc":[{"id":"1.229554909","rc":[{"atl":[[2.04,4.92]],"id":61631978}],"con":true,"img":false}]}
{"op":"mcm","clk":"11450281936","pt":1717320000611,"mc":[{"id":"1.229554909","rc":[{"atb":[[2.1,4.04],[2.08,20.16]],"id":61631980},{"atl":[[2.08,0.78]],"id":61631978}],"con":true,"img":false}]}
{"op":"mcm","clk":"11450281942","pt":1717320000703,"mc":[{"id":"1.229554909","rc":[{"atl":[[2.02,4.79]],"id":61631978}],"con":true,"img":false}]}
{"op":"mcm","clk":"11450281951","pt":1717320000817,"mc":[{"id":"1.229554909","rc":[{"atl":[[2.38,3.59]],"id":61631980},{"atl":[[2.3,0],[2.26,0],[2.34,0]],"id":61631978}],"con":true,"img":false}]}
{"op":"mcm","clk":"11450281957","pt":1717320000907,"mc":[{"id":"1.229554909","rc":[{"atb":[[1.9,0],[2.1,31.15]],"id":61631980},{"atl":[[2.36,4.77]],"id":61631980},{"atb":[[1.74,42.65]],"id":61631978},{"atl":[[2.08,0.43]],"id":61631978}],"con":true,"img":false}]}
{"op":"mcm","clk":"11450281978","pt":1717320001180,"mc":[{"id":"1.229554909","rc":[{"atb":[[2.14,3.94]],"id":61631980}],"con":true,"img":false}]}
{"op":"mcm","clk":"11450281986","pt":1717320001284,"mc":[{"id":"1.229554909","rc":[{"atl":[[2.38,0]],"id":61631978}],"con":true,"img":false}]}
{"op":"mcm","clk":"11450281994","pt":1717320001380,"mc":[{"id":"1.229554909","rc":[{"atl":[[2.1,5.57]],"id":61631978}],"con":true,"img":false}]}
{"op":"mcm","clk":"11450282002","pt":1717320001492,"mc":[{"id":"1.229554909","rc":[{"atl":[[2.08,0]],"id":61631978}],"con":true,"img":false}]}
{"op":"mcm","clk":"11450282008","pt":1717320001595,"mc":[{"id":"1.229554909","rc":[{"atb":[[2.16,12.37]],"id":61631980},{"atl":[[2,0.43]],"id":61631978}],"con":true,"img":false}]}
{"op":"mcm","clk":"11450282035","pt":1717320001904,"mc":[{"id":"1.229554909","rc":[{"atb":[[2.14,30.1]],"id":61631980}],"con":true,"img":false}]}
{"op":"mcm","clk":"11450282043","pt":1717320002007,"mc":[{"id":"1.229554909","rc":[{"atb":[[2.16,0]],"id":61631980},{"atl":[[2.36,4.04]],"id":61631980},{"atl":[[2.1,4.88]],"id":61631978}],"con":true,"img":false}]}
{"op":"mcm","clk":"11450282048","pt":1717320002106,"mc":[{"id":"1.229554909","rc":[{"atl":[[3.05,0.73]],"id":61631980},{"atl":[[2.02,5.48]],"id":61631978}],"con":true,"img":false}]}
{"op":"mcm","clk":"11450282069","pt":1717320002420,"mc":[{"id":"1.229554909","rc":[{"atb":[[2.14,3.94]],"id":61631980},{"atl":[[2.34,3.65],[2.38,0]],"id":61631980},{"atb":[[1.78,0]],"id":61631978},{"atl":[[2,5.49],[2.14,0]],"id":61631978}],"con":true,"img":false}]}
{"op":"mcm","clk":"11450282075","pt":1717320002525,"mc":[{"id":"1.229554909","rc":[{"atb":[[2.16,3.85]],"id":61631980},{"atb":[[1.77,0]],"id":61631978}],"con":true,"img":false}]}
{"op":"mcm","clk":"11450282084","pt":1717320002586,"mc":[{"id":"1.229554909","rc":[{"atb":[[1.75,0]],"id":61631978}],"con":true,"img":false}]}
{"op":"mcm","clk":"11450282108","pt":1717320002900,"mc":[{"id":"1.229554909","rc":[{"atl":[[2.32,3.84],[2.46,0]],"id":61631980},{"atb":[[1.71,7.45],[1.69,43.22],[1.74,2.34],[1.75,15.15]],"id":61631978}],"con":true,"img":false}]}
{"op":"mcm","clk":"11450282176","pt":1717320003616,"mc":[{"id":"1.229554909","rc":[{"atb":[[1.75,0]],"id":61631978}],"con":true,"img":false}]}
{"op":"mcm","clk":"11450282185","pt":1717320003682,"mc":[{"id":"1.229554909","rc":[{"atl":[[2.32,7.52],[2.34,0]],"id":61631980}],"con":true,"img":false}]}
{"op":"mcm","clk":"11450282195","pt":1717320003779,"mc":[{"id":"1.229554909","rc":[{"atl":[[2.3,3.84]],"id":61631980}],"con":true,"img":false}]}
{"op":"mcm","clk":"11450282202","pt":1717320003889,"mc":[{"id":"1.229554909","rc":[{"atb":[[2.16,14.19]],"id":61631980},{"atl":[[2.36,15.77],[2.42,0]],"id":61631980},{"atb":[[1.71,49.46]],"id":61631978}],"con":true,"img":false}]}
{"op":"mcm","clk":"11450282216","pt":1717320004088,"mc":[{"id":"1.229554909","rc":[{"atb":[[2.16,3.85]],"id":61631980}],"con":true,"img":false}]}
{"op":"mcm","clk":"11450282243","pt":1717320004402,"mc":[{"id":"1.229554909","rc":[{"atb":[[1.89,0],[1.96,99.64]],"id":61631980},{"atl":[[2.32,3.84]],"id":61631980},{"atb":[[1.69,0]],"id":61631978},{"atl":[[2.22,0],[2.14,9.84]],"id":61631978}],"con":true,"img":false}]}
{"op":"mcm","clk":"11450282250","pt":1717320004505,"mc":[{"id":"1.229554909","rc":[{"atb":[[1.9,99.64],[1.96,0]],"id":61631980}],"con":true,"img":false}]}
{"op":"mcm","clk":"11450282259","pt":1717320004604,"mc":[{"id":"1.229554909","rc":[{"atb":[[2.12,12.16],[2.18,3.9]],"id":61631980}],"con":true,"img":false}]}
{"op":"mcm","clk":"11450282277","pt":1717320004919,"mc":[{"id":"1.229554909","rc":[{"atb":[[1.94,0],[2.08,12.89]],"id":61631980},{"atb":[[1.64,0],[1.54,0]],"id":61631978}],"con":true,"img":false}]}
{"op":"mcm","clk":"11450282321","pt":1717320005393,"mc":[{"id":"1.229554909","rc":[{"atb":[[2.18,14.1]],"id":61631980},{"atl":[[2.32,14.77]],"id":61631980}],"con":true,"img":false}]}
{"op":"mcm","clk":"11450282333","pt":1717320005604,"mc":[{"id":"1.229554909","rc":[{"atl":[[1.99,5.22],[2.04,0]],"id":61631978}],"con":true,"img":false}]}
{"op":"mcm","clk":"11450282354","pt":1717320005909,"mc":[{"id":"1.229554909","rc":[{"atb":[[2.14,30.1]],"id":61631980},{"atb":[[1.74,42.65]],"id":61631978}],"con":true,"img":false}]}
{"op":"mcm","clk":"11450282383","pt":1717320006220,"mc":[{"id":"1.229554909","rc":[{"trd":[[2.3,6.3]],"ltp":2.3,"tv":6.3,"id":61631980},{"atl":[[2.3,0]],"id":61631980},{"atb":[[1.76,0]],"id":61631978},{"trd":[[1.76,14.92]],"ltp":1.76,"tv":14.92,"id":61631978},{"atl":[[1.76,26.02]],"id":61631978}],"con":true,"img":false}]}
{"op":"mcm","clk":"11450282394","pt":1717320006327,"mc":[{"id":"1.229554909","rc":[{"atb":[[2.18,17.95],[2.2,3.83],[2.1,27.11],[2.08,8.84]],"id":61631980},{"trd":[[1.76,19.14]],"ltp":1.76,"tv":19.14,"id":61631978},{"atl":[[2,5.05],[1.82,15.83],[1.98,5.07],[2.1,0],[1.76,23.91]],"id":61631978}],"con":true,"img":false}]}
{"op":"mcm","clk":"11450282405","pt":1717320006429,"mc":[{"id":"1.229554909","rc":[{"atl":[[2.32,3.84]],"id":61631980},{"atb":[[1.74,2.34]],"id":61631978},{"trd":[[1.76,66.97]],"ltp":1.76,"tv":66.97,"id":61631978},{"atl":[[1.99,0],[1.98,5.51],[1.76,0]],"id":61631978}],"con":true,"img":false}]}
{"op":"mcm","clk":"11450282418","pt":1717320006495,"mc":[{"id":"1.229554909","rc":[{"atb":[[2.22,8.98],[2.18,14.05]],"id":61631980},{"atl":[[2.36,4.04]],"id":61631980}],"con":true,"img":false}]}
{"op":"mcm","clk":"11450282430","pt":1717320006597,"mc":[{"id":"1.229554909","rc":[{"atl":[[1.82,0],[1.97,3.93]],"id":61631978}],"con":true,"img":false}]}
{"op":"mcm","clk":"11450282438","pt":1717320006701,"mc":[{"id":"1.229554909","rc":[{"atb":[[2.16,13.98]],"id":61631980}],"con":true,"img":false}]}
{"op":"mcm","clk":"11450282456","pt":1717320006912,"mc":[{"id":"1.229554909","rc":[{"atb":[[2.2,0]],"id":61631980},{"atb":[[1.71,7.45]],"id":61631978},{"atl":[[1.98,5.07]],"id":61631978}],"con":true,"img":false}]}
{"op":"mcm","clk":"11450282464","pt":1717320007010,"mc":[{"id":"1.229554909","rc":[{"atl":[[1.96,0.43]],"id":61631978}],"con":true,"img":false}]}
{"op":"mcm","clk":"11450282537","pt":1717320007897,"mc":[{"id":"1.229554909","rc":[{"atl":[[2.06,0],[1.96,5.47]],"id":61631978}],"con":true,"img":false}]}
{"op":"mcm","clk":"11450282544","pt":1717320008003,"mc":[{"id":"1.229554909","rc":[{"atb":[[1.74,16.43]],"id":61631978},{"atl":[[1.82,13.07],[1.97,0],[1.95,5.28]],"id":61631978}],"con":true,"img":false}]}
{"op":"mcm","clk":"11450282554","pt":1717320008104,"mc":[{"id":"1.229554909","rc":[{"atl":[[1.96,5.03]],"id":61631978}],"con":true,"img":false}]}
{"op":"mcm","clk":"11450282561","pt":1717320008211,"mc":[{"id":"1.229554909","rc":[{"atb":[[1.74,2.34]],"id":61631978},{"atl":[[1.82,0],[1000,0.61]],"id":61631978}],"con":true,"img":false}]}
{"op":"mcm","clk":"11450282644","pt":1717320009300,"mc":[{"id":"1.229554909","rc":[{"atl":[[1.82,16.59]],"id":61631978}],"con":true,"img":false}]}
{"op":"mcm","clk":"11450282697","pt":1717320010016,"mc":[{"id":"1.229554909","rc":[{"atb":[[2.18,3.84]],"id":61631980}],"con":true,"img":false}]}
{"op":"mcm","clk":"11450282743","pt":1717320010713,"mc":[{"id":"1.229554909","rc":[{"atb":[[1.73,12.65]],"id":61631978},{"atl":[[1.84,22.07]],"id":61631978}],"con":true,"img":false}]}
{"op":"mcm","clk":"11450282752","pt":1717320010814,"mc":[{"id":"1.229554909","rc":[{"atb":[[2.16,3.85]],"id":61631980}],"con":true,"img":false}]}
{"op":"mcm","clk":"11450282761","pt":1717320010914,"mc":[{"id":"1.229554909","rc":[{"atb":[[2.2,24.85]],"id":61631980},{"atb":[[1.73,0],[1.66,45.18]],"id":61631978}],"con":true,"img":false}]}
{"op":"mcm","clk":"11450282790","pt":1717320011326,"mc":[{"id":"1.229554909","rc":[{"trd":[[2.32,5.44]],"ltp":2.32,"tv":5.44,"id":61631980},{"atl":[[2.32,0]],"id":61631980},{"trd":[[1.75,5.09]],"ltp":1.75,"tv":5.09,"id":61631978},{"atl":[[1.75,13.21]],"id":61631978}],"con":true,"img":false}]}
{"op":"mcm","clk":"11450282796","pt":1717320011432,"mc":[{"id":"1.229554909","rc":[{"atb":[[2.2,0]],"id":61631980},{"atb":[[1.74,0],[1.66,0]],"id":61631978},{"trd":[[1.74,12.55]],"ltp":1.74,"tv":12.55,"id":61631978},{"atl":[[2.02,0.69],[1.94,5.04]],"id":61631978}],"con":true,"img":false}]}
{"op":"mcm","clk":"11450282808","pt":1717320011492,"mc":[{"id":"1.229554909","rc":[{"atb":[[1.59,0],[1.61,10.34]],"id":61631978}],"con":true,"img":false}]}
{"op":"mcm","clk":"11450282817","pt":1717320011597,"mc":[{"id":"1.229554909","rc":[{"atb":[[2.22,0],[2.2,3.86]],"id":61631980},{"trd":[[2.36,8.08]],"ltp":2.36,"tv":8.08,"id":61631980},{"atl":[[2.36,0]],"id":61631980}],"con":true,"img":false}]}
{"op":"mcm","clk":"11450282825","pt":1717320011698,"mc":[{"id":"1.229554909","rc":[{"atb":[[2.2,7.68]],"id":61631980},{"atb":[[1.71,12.87]],"id":61631978},{"atl":[[2,0],[1.83,5.09]],"id":61631978}],"con":true,"img":false}]}
{"op":"mcm","clk":"11450282843","pt":1717320011907,"mc":[{"id":"1.229554909","rc":[{"atb":[[2.22,24.44]],"id":61631980},{"atl":[[1.83,0]],"id":61631978}],"con":true,"img":false}]}
{"op":"mcm","clk":"11450282853","pt":1717320012012,"mc":[{"id":"1.229554909","rc":[{"atb":[[2.22,28.28],[2.2,3.86]],"id":61631980}],"con":true,"img":false}]}
{"op":"mcm","clk":"11450282862","pt":1717320012114,"mc":[{"id":"1.229554909","rc":[{"atb":[[2.2,0]],"id":61631980}],"con":true,"img":false}]}
{"op":"mcm","clk":"11450282869","pt":1717320012216,"mc":[{"id":"1.229554909","rc":[{"atb":[[1.71,0]],"id":61631978}],"con":true,"img":false}]}
{"op":"mcm","clk":"11450282919","pt":1717320012730,"mc":[{"id":"1.229554909","rc":[{"atl":[[2.54,0],[2.38,3.59],[2.48,3.86]],"id":61631980},{"atb":[[1.64,9.43],[1.61,0]],"id":61631978}],"con":true,"img":false}]}
{"op":"mcm","clk":"11450282938","pt":1717320012896,"mc":[{"id":"1.229554909","rc":[{"atb":[[1.68,15.73]],"id":61631978}],"con":true,"img":false}]}
{"op":"mcm","clk":"11450282951","pt":1717320013001,"mc":[{"id":"1.229554909","rc":[{"atb":[[1.65,4.9]],"id":61631978}],"con":true,"img":false}]}
{"op":"mcm","clk":"11450282960","pt":1717320013098,"mc":[{"id":"1.229554909","rc":[{"atb":[[1.01,105.54]],"id":61631978},{"atl":[[1.86,14.48]],"id":61631978}],"con":true,"img":false}]}
{"op":"mcm","clk":"11450282971","pt":1717320013197,"mc":[{"id":"1.229554909","rc":[{"atl":[[1.95,0]],"id":61631978}],"con":true,"img":false}]}
{"op":"mcm","clk":"11450283096","pt":1717320014913,"mc":[{"id":"1.229554909","rc":[{"atl":[[2.5,3.86],[2.48,0]],"id":61631980},{"atl":[[1.75,0]],"id":61631978}],"con":true,"img":false}]}
{"op":"mcm","clk":"11450283107","pt":1717320015013,"mc":[{"id":"1.229554909","rc":[{"trd":[[2.38,3.59]],"ltp":2.38,"tv":3.59,"id":61631980},{"atl":[[2.38,0]],"id":61631980},{"trd":[[1.72,4.96]],"ltp":1.72,"tv":4.96,"id":61631978},{"atl":[[1.72,8.25]],"id":61631978}],"con":true,"img":false}]}
{"op":"mcm","clk":"11450283115","pt":1717320015114,"mc":[{"id":"1.229554909","rc":[{"atb":[[1.68,0]],"id":61631978}],"con":true,"img":false}]}
{"op":"mcm","clk":"11450283138","pt":1717320015425,"mc":[{"id":"1.229554909","rc":[{"atb":[[2.22,3.84],[2.28,6.13],[2.2,24.85],[2.08,16.11]],"id":61631980},{"atb":[[1.44,17.83],[1.54,14.53]],"id":61631978}],"con":true,"img":false}]}
{"op":"mcm","clk":"11450283180","pt":1717320016008,"mc":[{"id":"1.229554909","rc":[{"atb":[[1.67,15.84]],"id":61631978}],"con":true,"img":false}]}
{"op":"mcm","clk":"11450283216","pt":1717320016438,"mc":[{"id":"1.229554909","rc":[{"atb":[[1.55,54.23]],"id":61631978}],"con":true,"img":false}]}
{"op":"mcm","clk":"11450283244","pt":1717320016828,"mc":[{"id":"1.229554909","rc":[{"atb":[[2.18,0]],"id":61631980}],"con":true,"img":false}]}
{"op":"mcm","clk":"11450283272","pt":1717320017133,"mc":[{"id":"1.229554909","rc":[{"atb":[[2.22,0],[2.18,2]],"id":61631980}],"con":true,"img":false}]}
{"op":"mcm","clk":"11450283291","pt":1717320017340,"mc":[{"id":"1.229554909","rc":[{"atl":[[1.82,0]],"id":61631978}],"con":true,"img":false}]}
{"op":"mcm","clk":"11450283310","pt":1717320017508,"mc":[{"id":"1.229554909","rc":[{"atb":[[2.18,5.88]],"id":61631980},{"atl":[[1.85,5.02]],"id":61631978}],"con":true,"img":false}]}
{"op":"mcm","clk":"11450283339","pt":1717320017915,"mc":[{"id":"1.229554909","rc":[{"atb":[[1.55,0]],"id":61631978}],"con":true,"img":false}]}
{"op":"mcm","clk":"11450283345","pt":1717320018019,"mc":[{"id":"1.229554909","rc":[{"atb":[[2.18,2]],"id":61631980}],"con":true,"img":false}]}
{"op":"mcm","clk":"11450283368","pt":1717320018330,"mc":[{"id":"1.229554909","rc":[{"atb":[[2.18,5.88]],"id":61631980}],"con":true,"img":false}]}
{"op":"mcm","clk":"11450283485","pt":1717320020039,"mc":[{"id":"1.229554909","rc":[{"atb":[[2.18,3.88],[2.16,7.75]],"id":61631980},{"atl":[[2.5,0],[2.46,3.9]],"id":61631980},{"atb":[[1.64,0],[1.65,11.54]],"id":61631978}],"con":true,"img":false}]}
{"op":"mcm","clk":"11450283510","pt":1717320020346,"mc":[{"id":"1.229554909","rc":[{"atb":[[1.67,0]],"id":61631978},{"atl":[[1.72,0]],"id":61631978}],"con":true,"img":false}]}
{"op":"mcm","clk":"11450283518","pt":1717320020404,"mc":[{"id":"1.229554909","rc":[{"trd":[[2.4,3.91]],"ltp":2.4,"tv":3.91,"id":61631980},{"atl":[[2.4,0]],"id":61631980},{"trd":[[1.71,5.49]],"ltp":1.71,"tv":5.49,"id":61631978},{"atl":[[1.88,4.96],[1.86,0],[1.71,2.75]],"id":61631978}],"con":true,"img":false}]}
{"op":"mcm","clk":"11450283527","pt":1717320020520,"mc":[{"id":"1.229554909","rc":[{"atl":[[2.46,0],[2.64,2.3],[3.05,15.99]],"id":61631980}],"con":true,"img":false}]}
{"op":"mcm","clk":"11450283534","pt":1717320020614,"mc":[{"id":"1.229554909","rc":[{"atl":[[2.9,0],[2.86,8.06]],"id":61631980}],"con":true,"img":false}]}
{"op":"mcm","clk":"11450283553","pt":1717320020918,"mc":[{"id":"1.229554909","rc":[{"atb":[[2.14,3.94],[2.1,0]],"id":61631980}],"con":true,"img":false}]}
{"op":"mcm","clk":"11450283567","pt":1717320021125,"mc":[{"id":"1.229554909","rc":[{"atb":[[1.66,21.18]],"id":61631978}],"con":true,"img":false}]}
{"op":"mcm","clk":"11450283579","pt":1717320021333,"mc":[{"id":"1.229554909","rc":[{"atb":[[1.66,0]],"id":61631978}],"con":true,"img":false}]}
{"op":"mcm","clk":"11450283598","pt":1717320021639,"mc":[{"id":"1.229554909","rc":[{"atl":[[2.9,10.53]],"id":61631980}],"con":true,"img":false}]}
{"op":"mcm","clk":"11450283613","pt":1717320021805,"mc":[{"id":"1.229554909","rc":[{"atl":[[3.05,15.26]],"id":61631980}],"con":true,"img":false}]}
{"op":"mcm","clk":"11450283620","pt":1717320021906,"mc":[{"id":"1.229554909","rc":[{"atl":[[2.84,0.73]],"id":61631980}],"con":true,"img":false}]}
{"op":"mcm","clk":"11450283659","pt":1717320022424,"mc":[{"id":"1.229554909","rc":[{"atb":[[1.53,56.27]],"id":61631978}],"con":true,"img":false}]}
{"op":"mcm","clk":"11450283670","pt":1717320022628,"mc":[{"id":"1.229554909","rc":[{"atl":[[3.2,0],[3.1,0],[3.3,0],[2.94,12.89]],"id":61631980}],"con":true,"img":false}]}
{"op":"mcm","clk":"11450283712","pt":1717320023310,"mc":[{"id":"1.229554909","rc":[{"atl":[[1.71,0]],"id":61631978}],"con":true,"img":false}]}
{"op":"mcm","clk":"11450283722","pt":1717320023412,"mc":[{"id":"1.229554909","rc":[{"atl":[[1.69,2.75]],"id":61631978}],"con":true,"img":false}]}
{"op":"mcm","clk":"11450283733","pt":1717320023617,"mc":[{"id":"1.229554909","rc":[{"atl":[[2.98,15.15]],"id":61631980}],"con":true,"img":false}]}
{"op":"mcm","clk":"11450283784","pt":1717320024333,"mc":[{"id":"1.229554909","rc":[{"atl":[[2.86,0],[2.9,7.89]],"id":61631980}],"con":true,"img":false}]}
{"op":"mcm","clk":"11450283824","pt":1717320024803,"mc":[{"id":"1.229554909","rc":[{"atl":[[2.84,0]],"id":61631980}],"con":true,"img":false}]}
{"op":"mcm","clk":"11450283832","pt":1717320024904,"mc":[{"id":"1.229554909","rc":[{"atl":[[2.88,0.73]],"id":61631980},{"atb":[[1.53,0],[1.52,57.35]],"id":61631978}],"con":true,"img":false}]}
{"op":"mcm","clk":"11450283871","pt":1717320025331,"mc":[{"id":"1.229554909","rc":[{"trd":[[2.44,1.9]],"ltp":2.44,"tv":1.9,"id":61631980},{"atl":[[2.4,10.13],[2.94,23.2]],"id":61631980},{"trd":[[1.69,2.75]],"ltp":1.69,"tv":2.75,"id":61631978},{"atl":[[1.69,0]],"id":61631978}],"con":true,"img":false}]}
{"op":"mcm","clk":"11450283880","pt":1717320025429,"mc":[{"id":"1.229554909","rc":[{"atl":[[2.94,10.31]],"id":61631980}],"con":true,"img":false}]}
{"op":"mcm","clk":"11450283889","pt":1717320025530,"mc":[{"id":"1.229554909","rc":[{"trd":[[2.4,10.37]],"ltp":2.4,"tv":10.37,"id":61631980},{"atl":[[2.4,6.9]],"id":61631980},{"atl":[[1.88,0],[1.87,9.77]],"id":61631978}],"con":true,"img":false}]}
{"op":"mcm","clk":"11450283899","pt":1717320025726,"mc":[{"id":"1.229554909","rc":[{"atl":[[2.88,13.17],[2.46,5],[2.64,0],[3.05,0]],"id":61631980}],"con":true,"img":false}]}
{"op":"mcm","clk":"11450283912","pt":1717320025933,"mc":[{"id":"1.229554909","rc":[{"atb":[[1.54,69.76],[1.52,0]],"id":61631978}],"con":true,"img":false}]}
{"op":"mcm","clk":"11450283999","pt":1717320027223,"mc":[{"id":"1.229554909","rc":[{"atb":[[1.71,15.41]],"id":61631978}],"con":true,"img":false}]}
{"op":"mcm","clk":"11450284013","pt":1717320027430,"mc":[{"id":"1.229554909","rc":[{"atb":[[1.54,14.53],[1.66,45.18]],"id":61631978}],"con":true,"img":false}]}
{"op":"mcm","clk":"11450284111","pt":1717320028654,"mc":[{"id":"1.229554909","rc":[{"atb":[[1.72,22.44]],"id":61631978}],"con":true,"img":false}]}
{"op":"mcm","clk":"11450284132","pt":1717320028932,"mc":[{"id":"1.229554909","rc":[{"atb":[[1.72,63.86]],"id":61631978}],"con":true,"img":false}]}
{"op":"mcm","clk":"11450284168","pt":1717320029446,"mc":[{"id":"1.229554909","rc":[{"atb":[[1.71,0]],"id":61631978}],"con":true,"img":false}]}
{"op":"mcm","clk":"11450284176","pt":1717320029549,"mc":[{"id":"1.229554909","rc":[{"atl":[[2.9,0]],"id":61631980}],"con":true,"img":false}]}
{"op":"mcm","clk":"11450284189","pt":1717320029613,"mc":[{"id":"1.229554909","rc":[{"atb":[[2.18,8.88],[2.16,3.85]],"id":61631980},{"atl":[[1.83,5.1],[1.98,0]],"id":61631978}],"con":true,"img":false}]}
{"op":"mcm","clk":"11450284219","pt":1717320029924,"mc":[{"id":"1.229554909","rc":[{"atb":[[1.72,22.44]],"id":61631978}],"con":true,"img":false}]}
{"op":"mcm","clk":"11450284255","pt":1717320030342,"mc":[{"id":"1.229554909","rc":[{"atl":[[2.5,5.01],[2.46,0]],"id":61631980}],"con":true,"img":false}]}
{"op":"mcm","clk":"11450284281","pt":1717320030646,"mc":[{"id":"1.229554909","rc":[{"atl":[[1.86,13.59],[1.87,0]],"id":61631978}],"con":true,"img":false}]}
{"op":"mcm","clk":"11450284311","pt":1717320030950,"mc":[{"id":"1.229554909","rc":[{"atb":[[1.9,0],[1.95,99.64]],"id":61631980},{"atl":[[2.5,0],[2.52,5.01]],"id":61631980},{"atb":[[1.65,4.9]],"id":61631978}],"con":true,"img":false}]}
{"op":"mcm","clk":"11450284317","pt":1717320031017,"mc":[{"id":"1.229554909","rc":[{"atb":[[1.63,13.59]],"id":61631978}],"con":true,"img":false}]}
{"op":"mcm","clk":"11450284489","pt":1717320033131,"mc":[{"id":"1.229554909","rc":[{"atl":[[1.74,3]],"id":61631978}],"con":true,"img":false}]}
{"op":"mcm","clk":"11450284592","pt":1717320034929,"mc":[{"id":"1.229554909","marketDefinition":{"bspMarket":false,"turnInPlayEnabled":false,"persistenceEnabled":false,"marketBaseRate":7.0,"eventId":"33318908","eventTypeId":"4339","numberOfWinners":1,"bettingType":"ODDS","marketType":"MATCH_BET","marketTime":"2024-06-02T09:20:00.000Z","suspendTime":"2024-06-02T09:20:00.000Z","bspReconciled":false,"complete":true,"inPlay":false,"crossMatching":true,"runnersVoidable":false,"numberOfActiveRunners":2,"betDelay":0,"status":"SUSPENDED","runners":[{"status":"ACTIVE","sortPriority":1,"id":61631980,"name":"1. Opella"},{"status":"ACTIVE","sortPriority":2,"id":61631978,"name":"4. Elwomple"}],"regulators":["MR_INT"],"venue":"Murray Bridge","countryCode":"AU","discountAllowed":true,"timezone":"Australia/Adelaide","openDate":"2024-06-02T08:21:00.000Z","version":5963035922,"name":"Opella v Elwomple","eventName":"Murray Bridge (AUS) 2nd Jun"},"rc":[],"con":true,"img":false}]}
{"op":"mcm","clk":"11450284600","pt":1717320034953,"mc":[{"id":"1.229554909","rc":[{"atb":[[1.01,0],[1.02,0],[2.28,0],[2.12,0],[2.18,0],[2.2,0],[1.95,0],[2.16,0],[2.14,0],[2.08,0]],"id":61631980},{"atl":[[2.4,0],[2.88,0],[2.52,0],[2.98,0],[2.94,0],[980,0],[1000,0]],"id":61631980},{"atb":[[1.72,0],[1.63,0],[1.44,0],[1.01,0],[1.54,0],[1.02,0],[1.23,0],[1.66,0],[1.65,0],[1.47,0]],"id":61631978},{"atl":[[1.83,0],[2.02,0],[1.84,0],[1.74,0],[1.85,0],[1.86,0],[1.96,0],[1.94,0],[2.14,0],[970,0],[1000,0]],"id":61631978}],"con":true,"img":false}]}
{"op":"mcm","clk":"11450296109","pt":1717320206460,"mc":[{"id":"1.229554909","rc":[{"trd":[[2.36,0],[2.4,0],[2.3,0],[2.32,0],[2.38,0],[2.44,0],[2.2,0]],"ltp":2.36,"tv":0.0,"id":61631980},{"trd":[[1.72,0],[1.74,0],[1.78,0],[1.65,0],[1.75,0],[1.71,0],[1.69,0],[1.76,0]],"ltp":1.72,"tv":0.0,"id":61631978}],"con":true,"img":false}]}
{"op":"mcm","clk":"11450296160","pt":1717320207211,"mc":[{"id":"1.229554909","marketDefinition":{"bspMarket":false,"turnInPlayEnabled":false,"persistenceEnabled":false,"marketBaseRate":7.0,"eventId":"33318908","eventTypeId":"4339","numberOfWinners":1,"bettingType":"ODDS","marketType":"MATCH_BET","marketTime":"2024-06-02T09:20:00.000Z","suspendTime":"2024-06-02T09:20:00.000Z","bspReconciled":false,"complete":true,"inPlay":false,"crossMatching":false,"runnersVoidable":false,"numberOfActiveRunners":0,"betDelay":0,"status":"CLOSED","settledTime":"2024-06-02T09:23:25.000Z","runners":[{"status":"WINNER","sortPriority":1,"id":61631980,"name":"1. Opella"},{"status":"LOSER","sortPriority":2,"id":61631978,"name":"4. Elwomple"}],"regulators":["MR_INT"],"venue":"Murray Bridge","countryCode":"AU","discountAllowed":true,"timezone":"Australia/Adelaide","openDate":"2024-06-02T08:21:00.000Z","version":5963039083,"name":"Opella v Elwomple","eventName":"Murray Bridge (AUS) 2nd Jun"},"rc":[],"con":true,"img":false}]}
