{"op":"mcm","clk":"11449075390","pt":1717303241532,"mc":[{"id":"1.229554907","marketDefinition":{"bspMarket":false,"turnInPlayEnabled":false,"persistenceEnabled":false,"marketBaseRate":7.0,"eventId":"33318908","eventTypeId":"4339","numberOfWinners":1,"bettingType":"ODDS","marketType":"EXACTA","marketTime":"2024-06-02T09:20:00.000Z","suspendTime":"2024-06-02T09:20:00.000Z","bspReconciled":false,"complete":true,"inPlay":false,"crossMatching":false,"runnersVoidable":false,"numberOfActiveRunners":20,"betDelay":0,"status":"OPEN","runners":[{"status":"ACTIVE","sortPriority":1,"id":52385882,"name":"1 - 2"},{"status":"ACTIVE","sortPriority":2,"id":52385884,"name":"1 - 4"},{"status":"ACTIVE","sortPriority":3,"id":52385886,"name":"1 - 6"},{"status":"ACTIVE","sortPriority":4,"id":52385888,"name":"1 - 8"},{"status":"ACTIVE","sortPriority":5,"id":52385889,"name":"2 - 1"},{"status":"ACTIVE","sortPriority":6,"id":52385891,"name":"2 - 4"},{"status":"ACTIVE","sortPriority":7,"id":52385893,"name":"2 - 6"},{"status":"ACTIVE","sortPriority":8,"id":52385895,"name":"2 - 8"},{"status":"ACTIVE","sortPriority":9,"id":52385903,"name":"4 - 1"},{"status":"ACTIVE","sortPriority":10,"id":52385904,"name":"4 - 2"},{"status":"ACTIVE","sortPriority":11,"id":52385907,"name":"4 - 6"},{"status":"ACTIVE","sortPriority":12,"id":52385909,"name":"4 - 8"},{"status":"ACTIVE","sortPriority":13,"id":52385917,"name":"6 - 1"},{"status":"ACTIVE","sortPriority":14,"id":52385918,"name":"6 - 2"},{"status":"ACTIVE","sortPriority":15,"id":52385920,"name":"6 - 4"},{"status":"ACTIVE","sortPriority":16,"id":52385923,"name":"6 - 8"},{"status":"ACTIVE","sortPriority":17,"id":52385931,"name":"8 - 1"},{"status":"ACTIVE","sortPriority":18,"id":52385932,"name":"8 - 2"},{"status":"ACTIVE","sortPriority":19,"id":52385934,"name":"8 - 4"},{"status":"ACTIVE","sortPriority":20,"id":52385936,"name":"8 - 6"}],"regulators":["MR_INT"],"venue":"Murray Bridge","countryCode":"AU","discountAllowed":true,"timezone":"Australia/Adelaide","openDate":"2024-06-02T08:21:00.000Z","version":5962801945,"name":"Exacta","eventName":"Murray Bridge (AUS) 2nd Jun"},"rc":[],"con":true,"img":false}]}
{"op":"mcm","clk":"11449095056","pt":1717303714149,"mc":[{"id":"1.229554907","rc":[{"atb":[[150,0.35],[75,1.41],[200,0.13],[100,0.8]],"id":52385907},{"atb":[[34,2.38],[44,1.22],[27,4.02],[60,0.44]],"id":52385891},{"atb":[[5.6,11.37],[5.1,19.14],[4.6,29.07],[6.2,5.03]],"id":52385909},{"atb":[[840,0.13],[890,0.09],[940,0.06],[990,0.03]],"id":52385918},{"atb":[[2.56,50.3],[2.46,71.67],[2.66,31.52],[2.76,14.86]],"id":52385934},{"atb":[[280,0.38],[330,0.24],[380,0.14],[430,0.06]],"id":52385920},{"atb":[[8,3.74],[5.5,23.25],[6,15.7],[7,8.72]],"id":52385888},{"atb":[[40,0.67],[20,5.51],[25,3.27],[30,1.81]],"id":52385904},{"atb":[[70,0.38],[38,2.12],[48,1.11],[29,3.74]],"id":52385889},{"atb":[[3.6,10.06],[3.1,37.37],[3.35,22.26],[2.94,53.93]],"id":52385931},{"atb":[[520,0.05],[370,0.28],[420,0.19],[470,0.11]],"id":52385917}],"con":true,"img":false}]}
{"op":"mcm","clk":"11449095072","pt":1717303714618,"mc":[{"id":"1.229554907","rc":[{"atb":[[260,0.1],[160,0.49],[210,0.25],[110,0.96]],"id":52385886},{"atb":[[32,2.53],[42,1.28],[26,4.19],[55,0.49]],"id":52385882},{"atb":[[17.5,3.17],[20,1.38],[12.5,9.1],[15,5.6]],"id":52385884},{"atb":[[16.5,5.06],[19,2.91],[23,1.19],[14,8.05]],"id":52385895},{"atb":[[130,0.41],[65,1.64],[180,0.15],[90,0.88]],"id":52385923},{"atb":[[590,0.18],[640,0.12],[690,0.08],[740,0.04]],"id":52385893},{"atb":[[16,3.49],[18.5,1.5],[11,10.46],[13.5,6.28]],"id":52385903},{"atb":[[40,0.67],[20,5.51],[25,3.27],[30,1.81]],"id":52385936},{"atb":[[8,3.74],[5.5,23.25],[6,15.7],[7,8.72]],"id":52385932}],"con":true,"img":false}]}
{"op":"mcm","clk":"11449099382","pt":1717303849562,"mc":[{"id":"1.229554907","rc":[{"atb":[[140,0.75],[70,3.53]],"id":52385886},{"atb":[[4,34.84],[3.5,97.56]],"id":52385888},{"atb":[[17,6.53],[12,22.17]],"id":52385889},{"atb":[[16,6.96],[11,24.39]],"id":52385882},{"atb":[[6.4,45.16],[8.4,14.12]],"id":52385884},{"atb":[[6.4,45.16],[8.4,14.12]],"id":52385895},{"atb":[[10.5,25.67],[15.5,7.2]],"id":52385891},{"atb":[[550,0.44],[650,0.16]],"id":52385893},{"atb":[[6.2,46.9],[8.2,14.51]],"id":52385903},{"atb":[[9.8,27.71],[14.5,7.74]],"id":52385904}],"con":true,"img":false}]}
{"op":"mcm","clk":"11449099388","pt":1717303849619,"mc":[{"id":"1.229554907","rc":[{"atb":[[75,2.83],[40,6.25]],"id":52385907},{"atb":[[3.6,40.2],[3.1,116.14]],"id":52385909},{"atb":[[550,0.44],[650,0.16]],"id":52385918},{"atb":[[140,0.75],[70,3.53]],"id":52385920},{"atb":[[220,0.47],[120,2.05]],"id":52385917},{"atb":[[16,16.26],[22,4.97]],"id":52385923},{"atb":[[2.46,238.73],[2.66,94.49]],"id":52385934},{"atb":[[10,27.1],[15,7.46]],"id":52385936},{"atb":[[2.64,148.72],[2.84,56.81]],"id":52385931},{"atb":[[4,81.3],[5,26.13]],"id":52385932}],"con":true,"img":false}]}
{"op":"mcm","clk":"11449112530","pt":1717304231714,"mc":[{"id":"1.229554907","rc":[{"atb":[[150,0],[75,1.41],[200,0],[100,0]],"id":52385907},{"atb":[[5.6,0],[5.1,0],[4.6,0],[6.2,0]],"id":52385909},{"atb":[[280,0],[330,0],[380,0],[430,0]],"id":52385920},{"atb":[[17.5,0],[20,0],[12.5,0],[15,0]],"id":52385884},{"atb":[[590,0],[640,0],[690,0],[740,0]],"id":52385893},{"atb":[[16,0],[18.5,0],[11,0],[13.5,0]],"id":52385903},{"atb":[[40,0],[20,0],[25,0],[30,0]],"id":52385936},{"atb":[[8,0],[5.5,0],[6,0],[7,0]],"id":52385932}],"con":true,"img":false}]}
{"op":"mcm","clk":"11449112584","pt":1717304232739,"mc":[{"id":"1.229554907","rc":[{"atb":[[160,0.33],[80,1.32],[210,0.13],[110,0.72]],"id":52385907},{"atb":[[4.8,27.54],[5.8,10.9],[5.3,18.25],[6.6,4.67]],"id":52385909},{"atb":[[300,0.35],[350,0.23],[400,0.13],[450,0.06]],"id":52385920},{"atb":[[18,3.08],[21,1.31],[13,8.72],[15.5,5.41]],"id":52385884},{"atb":[[520,0.2],[570,0.14],[620,0.08],[670,0.04]],"id":52385893},{"atb":[[17,3.27],[19.5,1.41],[12,9.51],[14.5,5.81]],"id":52385903},{"atb":[[38,0.71],[19.5,5.66],[24,3.41],[29,1.87]],"id":52385936},{"atb":[[6.4,9.69],[7.4,4.09],[5.2,24.91],[5.7,16.69]],"id":52385932}],"con":true,"img":false}]}
{"op":"mcm","clk":"11449127679","pt":1717304401620,"mc":[{"id":"1.229554907","rc":[{"atb":[[160,0],[80,0],[210,0],[110,0]],"id":52385907},{"atb":[[260,0],[160,0],[210,0],[110,0]],"id":52385886},{"atb":[[300,0],[350,0],[400,0],[450,0]],"id":52385920},{"atb":[[8,0],[5.5,0],[6,0],[7,0]],"id":52385888},{"atb":[[520,0],[370,0],[420,0],[470,0]],"id":52385917},{"atb":[[16.5,0],[19,0],[23,0],[14,0]],"id":52385895},{"atb":[[38,0],[19.5,0],[24,0],[29,0]],"id":52385936},{"atb":[[6.4,0],[7.4,0],[5.2,0],[5.7,0]],"id":52385932}],"con":true,"img":false}]}
{"op":"mcm","clk":"11449127689","pt":1717304401728,"mc":[{"id":"1.229554907","rc":[{"atb":[[520,0],[570,0],[620,0],[670,0]],"id":52385893},{"atb":[[3.6,0],[3.1,0],[3.35,0],[2.94,0]],"id":52385931}],"con":true,"img":false}]}
{"op":"mcm","clk":"11449127734","pt":1717304402320,"mc":[{"id":"1.229554907","rc":[{"atb":[[140,0.38],[70,1.52],[190,0.14],[95,0.84]],"id":52385907},{"atb":[[150,0.53],[200,0.26],[100,1.06],[250,0.1]],"id":52385886},{"atb":[[5.6,22.75],[7.2,8.44],[6.2,15.09],[8.2,3.63]],"id":52385888},{"atb":[[280,0.38],[330,0.24],[380,0.14],[430,0.06]],"id":52385920},{"atb":[[360,0.29],[410,0.19],[460,0.12],[510,0.05]],"id":52385917},{"atb":[[17,4.9],[19.5,2.83],[24,1.14],[14.5,7.75]],"id":52385895},{"atb":[[40,0.67],[20,5.51],[25,3.27],[30,1.81]],"id":52385936},{"atb":[[8,3.74],[5.5,23.25],[6,15.7],[7,8.72]],"id":52385932}],"con":true,"img":false}]}
{"op":"mcm","clk":"11449127745","pt":1717304402473,"mc":[{"id":"1.229554907","rc":[{"atb":[[550,0.63],[600,0.13],[650,0.24],[700,0.04]],"id":52385893},{"atb":[[3.45,21.36],[3.2,35.67],[3.7,9.69],[2.98,52.85]],"id":52385931}],"con":true,"img":false}]}
{"op":"mcm","clk":"11449154965","pt":1717304856222,"mc":[{"id":"1.229554907","rc":[{"atb":[[8,0],[5.5,0],[6,0],[7,0]],"id":52385932}],"con":true,"img":false}]}
{"op":"mcm","clk":"11449154973","pt":1717304856327,"mc":[{"id":"1.229554907","rc":[{"atb":[[550,0.44],[600,0],[650,0.16],[700,0]],"id":52385893},{"atb":[[40,0],[20,0],[25,0],[30,0]],"id":52385904}],"con":true,"img":false}]}
{"op":"mcm","clk":"11449155025","pt":1717304857103,"mc":[{"id":"1.229554907","rc":[{"atb":[[560,0.14],[610,0.08],[660,0.04],[510,0.2]],"id":52385893},{"atb":[[38,0.71],[19.5,5.66],[24,3.41],[29,1.87]],"id":52385904},{"atb":[[5.8,16.35],[5.3,24.33],[7.6,3.97],[6.6,9.34]],"id":52385932}],"con":true,"img":false}]}
{"op":"mcm","clk":"11449158959","pt":1717304911371,"mc":[{"id":"1.229554907","rc":[{"atb":[[3.45,0],[3.2,0],[3.7,0],[2.98,0]],"id":52385931}],"con":true,"img":false}]}
{"op":"mcm","clk":"11449159008","pt":1717304912093,"mc":[{"id":"1.229554907","rc":[{"atb":[[3.6,10.06],[3.1,37.37],[3.35,22.26],[2.94,53.93]],"id":52385931}],"con":true,"img":false}]}
{"op":"mcm","clk":"11449162736","pt":1717304962318,"mc":[{"id":"1.229554907","rc":[{"atb":[[40,0],[20,0],[25,0],[30,0]],"id":52385936},{"atb":[[3.6,0],[3.1,0],[3.35,0],[2.94,0]],"id":52385931}],"con":true,"img":false}]}
{"op":"mcm","clk":"11449162805","pt":1717304963139,"mc":[{"id":"1.229554907","rc":[{"atb":[[38,0.71],[19.5,5.66],[24,3.41],[29,1.87]],"id":52385936},{"atb":[[2.92,54.5],[3.55,10.26],[3.3,22.75],[3.05,38.28]],"id":52385931}],"con":true,"img":false}]}
{"op":"mcm","clk":"11449222776","pt":1717305798839,"mc":[{"id":"1.229554907","rc":[{"atb":[[150,0],[200,0],[100,0],[250,0]],"id":52385886},{"atb":[[560,0],[610,0],[660,0],[510,0]],"id":52385893},{"atb":[[5.8,0],[5.3,0],[7.6,0],[6.6,0]],"id":52385932}],"con":true,"img":false}]}
{"op":"mcm","clk":"11449222828","pt":1717305799510,"mc":[{"id":"1.229554907","rc":[{"atb":[[140,1.32],[190,0.28],[95,1.11],[240,0.11]],"id":52385886},{"atb":[[540,0.15],[590,0.09],[640,0.04],[490,0.21]],"id":52385893},{"atb":[[6.4,9.69],[7.4,4.09],[5.2,24.91],[5.7,16.69]],"id":52385932}],"con":true,"img":false}]}
{"op":"mcm","clk":"11449234427","pt":1717305967768,"mc":[{"id":"1.229554907","rc":[{"atb":[[140,0],[190,0]],"id":52385907},{"atb":[[410,0]],"id":52385917}],"con":true,"img":false}]}
{"op":"mcm","clk":"11449234433","pt":1717305967866,"mc":[{"id":"1.229554907","rc":[{"atb":[[70,0],[95,0]],"id":52385907},{"atb":[[280,0],[330,0],[380,0],[430,0]],"id":52385920},{"atb":[[360,0],[460,0],[510,0]],"id":52385917}],"con":true,"img":false}]}
{"op":"mcm","clk":"11449234485","pt":1717305968489,"mc":[{"id":"1.229554907","rc":[{"atb":[[160,0.33],[210,0.13]],"id":52385907},{"atb":[[420,0.19]],"id":52385917}],"con":true,"img":false}]}
{"op":"mcm","clk":"11449234493","pt":1717305968546,"mc":[{"id":"1.229554907","rc":[{"atb":[[80,1.32],[110,0.72]],"id":52385907},{"atb":[[300,0.35],[350,0.23],[400,0.13],[450,0.06]],"id":52385920},{"atb":[[520,0.05],[370,0.28]],"id":52385917}],"con":true,"img":false}]}
{"op":"mcm","clk":"11449234502","pt":1717305968650,"mc":[{"id":"1.229554907","rc":[{"atb":[[470,0.11]],"id":52385917}],"con":true,"img":false}]}
{"op":"mcm","clk":"11449264739","pt":1717306377254,"mc":[{"id":"1.229554907","rc":[{"atb":[[38,0],[19.5,0],[24,0],[29,0]],"id":52385904}],"con":true,"img":false}]}
{"op":"mcm","clk":"11449264792","pt":1717306377975,"mc":[{"id":"1.229554907","rc":[{"atb":[[40,0.67],[20,5.51],[25,3.27],[30,1.81]],"id":52385904}],"con":true,"img":false}]}
{"op":"mcm","clk":"11449327105","pt":1717307225296,"mc":[{"id":"1.229554907","rc":[{"atb":[[140,0.75],[190,0],[95,0],[240,0]],"id":52385886},{"atb":[[540,0],[590,0],[640,0],[490,0]],"id":52385893}],"con":true,"img":false}]}
{"op":"mcm","clk":"11449327151","pt":1717307226014,"mc":[{"id":"1.229554907","rc":[{"atb":[[260,0.1],[160,0.49],[210,0.25],[110,0.96]],"id":52385886},{"atb":[[520,0.2],[570,0.14],[620,0.08],[670,0.04]],"id":52385893}],"con":true,"img":false}]}
{"op":"mcm","clk":"11449339116","pt":1717307401514,"mc":[{"id":"1.229554907","rc":[{"atb":[[160,0],[80,0],[210,0],[110,0]],"id":52385907},{"atb":[[260,0],[160,0],[210,0],[110,0]],"id":52385886},{"atb":[[300,0],[350,0],[400,0],[450,0]],"id":52385920},{"atb":[[520,0],[570,0],[620,0],[670,0]],"id":52385893},{"atb":[[40,0],[20,0],[25,0],[30,0]],"id":52385904},{"atb":[[6.4,0],[7.4,0],[5.2,0],[5.7,0]],"id":52385932}],"con":true,"img":false}]}
{"op":"mcm","clk":"11449339163","pt":1717307402236,"mc":[{"id":"1.229554907","rc":[{"atb":[[140,0.38],[70,1.52],[190,0.14],[95,0.84]],"id":52385907},{"atb":[[150,0.53],[200,0.26],[100,1.06],[250,0.1]],"id":52385886},{"atb":[[280,0.38],[330,0.24],[380,0.14],[430,0.06]],"id":52385920},{"atb":[[560,0.14],[610,0.08],[660,0.04],[510,0.2]],"id":52385893},{"atb":[[38,0.71],[19.5,5.66],[24,3.41],[29,1.87]],"id":52385904},{"atb":[[5.8,16.35],[5.3,24.33],[7.6,3.97],[6.6,9.34]],"id":52385932}],"con":true,"img":false}]}
{"op":"mcm","clk":"11449342311","pt":1717307456955,"mc":[{"id":"1.229554907","rc":[{"atb":[[4.8,0],[5.8,0],[5.3,0],[6.6,0]],"id":52385909},{"atb":[[70,0],[38,0],[48,0],[29,0]],"id":52385889},{"atb":[[17,0],[19.5,0],[24,0],[14.5,0]],"id":52385895},{"atb":[[34,0],[44,0],[27,0],[60,0]],"id":52385891},{"atb":[[2.56,0],[2.46,167.06],[2.66,62.96],[2.76,0]],"id":52385934},{"atb":[[17,0],[19.5,0],[12,0],[14.5,0]],"id":52385903},{"atb":[[38,0],[19.5,0],[24,0],[29,0]],"id":52385904}],"con":true,"img":false}]}
{"op":"mcm","clk":"11449342358","pt":1717307457623,"mc":[{"id":"1.229554907","rc":[{"atb":[[3.6,50.27],[3.1,153.52],[3.35,22.26],[2.94,53.93]],"id":52385909},{"atb":[[4.8,27.54],[5.8,10.9],[5.3,18.25],[6.6,4.67]],"id":52385904}],"con":true,"img":false}]}
{"op":"mcm","clk":"11449342364","pt":1717307457726,"mc":[{"id":"1.229554907","rc":[{"atb":[[65,0.41],[36,2.24],[46,1.16],[28,3.88]],"id":52385889},{"atb":[[16,5.23],[18.5,2.99],[22,1.25],[13.5,8.37]],"id":52385895},{"atb":[[18,1.54],[10.5,36.69],[13,6.54],[15.5,10.82]],"id":52385891},{"atb":[[2.86,42.19],[3.15,12.17],[2.96,26.69],[2.76,59.45]],"id":52385934},{"atb":[[9.6,9.12],[8.6,13.77],[11.5,4.98],[14,2.01]],"id":52385903}],"con":true,"img":false}]}
{"op":"mcm","clk":"11449346819","pt":1717307560169,"mc":[{"id":"1.229554907","rc":[{"atb":[[140,0],[70,0],[190,0],[95,0]],"id":52385907},{"atb":[[150,0],[200,0],[100,0],[250,0]],"id":52385886},{"atb":[[280,0],[330,0],[380,0],[430,0]],"id":52385920},{"atb":[[560,0],[610,0],[660,0],[510,0]],"id":52385893}],"con":true,"img":false}]}
{"op":"mcm","clk":"11449346830","pt":1717307560890,"mc":[{"id":"1.229554907","rc":[{"atb":[[160,0.33],[80,1.32],[210,0.13],[110,0.72]],"id":52385907},{"atb":[[260,0.1],[160,0.49],[210,0.25],[110,0.96]],"id":52385886},{"atb":[[300,0.35],[350,0.23],[400,0.13],[450,0.06]],"id":52385920},{"atb":[[520,0.2],[570,0.14],[620,0.08],[670,0.04]],"id":52385893}],"con":true,"img":false}]}
{"op":"mcm","clk":"11449349201","pt":1717307617356,"mc":[{"id":"1.229554907","rc":[{"atb":[[65,0],[36,0],[46,0],[28,0]],"id":52385889},{"atb":[[18,0],[10.5,25.67],[13,0],[15.5,7.2]],"id":52385891}],"con":true,"img":false}]}
{"op":"mcm","clk":"11449349228","pt":1717307618074,"mc":[{"id":"1.229554907","rc":[{"atb":[[65,0.41],[36,2.24],[46,1.16],[28,3.88]],"id":52385889},{"atb":[[18,1.54],[10.5,36.69],[13,6.54],[15.5,10.82]],"id":52385891}],"con":true,"img":false}]}
{"op":"mcm","clk":"11449365489","pt":1717308004047,"mc":[{"id":"1.229554907","rc":[{"atb":[[160,0],[80,0],[210,0],[110,0]],"id":52385907},{"atb":[[5.8,0],[5.3,0],[7.6,0],[6.6,0]],"id":52385932}],"con":true,"img":false}]}
{"op":"mcm","clk":"11449365501","pt":1717308004157,"mc":[{"id":"1.229554907","rc":[{"atb":[[300,0],[350,0],[400,0],[450,0]],"id":52385920}],"con":true,"img":false}]}
{"op":"mcm","clk":"11449365546","pt":1717308004728,"mc":[{"id":"1.229554907","rc":[{"atb":[[75,2.83],[150,0.35],[200,0.13],[100,0.8]],"id":52385907},{"atb":[[8,3.74],[5.5,23.25],[6,15.7],[7,8.72]],"id":52385932}],"con":true,"img":false}]}
{"op":"mcm","clk":"11449365556","pt":1717308004832,"mc":[{"id":"1.229554907","rc":[{"atb":[[280,0.38],[330,0.24],[380,0.14],[430,0.06]],"id":52385920}],"con":true,"img":false}]}
{"op":"mcm","clk":"11449378865","pt":1717308286273,"mc":[{"id":"1.229554907","rc":[{"atb":[[150,0],[75,1.41],[200,0],[100,0]],"id":52385907}],"con":true,"img":false}]}
{"op":"mcm","clk":"11449378876","pt":1717308286482,"mc":[{"id":"1.229554907","rc":[{"atb":[[520,0],[570,0],[620,0],[670,0]],"id":52385893}],"con":true,"img":false}]}
{"op":"mcm","clk":"11449378883","pt":1717308286581,"mc":[{"id":"1.229554907","rc":[{"atb":[[260,0],[160,0],[210,0],[110,0]],"id":52385886}],"con":true,"img":false}]}
{"op":"mcm","clk":"11449378913","pt":1717308286999,"mc":[{"id":"1.229554907","rc":[{"atb":[[140,0.38],[70,1.52],[190,0.14],[95,0.84]],"id":52385907}],"con":true,"img":false}]}
{"op":"mcm","clk":"11449378921","pt":1717308287200,"mc":[{"id":"1.229554907","rc":[{"atb":[[560,0.14],[610,0.08],[660,0.04],[510,0.2]],"id":52385893}],"con":true,"img":false}]}
{"op":"mcm","clk":"11449378926","pt":1717308287305,"mc":[{"id":"1.229554907","rc":[{"atb":[[150,0.53],[200,0.26],[100,1.06],[250,0.1]],"id":52385886}],"con":true,"img":false}]}
{"op":"mcm","clk":"11449391980","pt":1717308486704,"mc":[{"id":"1.229554907","rc":[{"atb":[[520,0],[370,0],[420,0],[470,0]],"id":52385917},{"atb":[[560,0],[610,0],[660,0],[510,0]],"id":52385893}],"con":true,"img":false}]}
{"op":"mcm","clk":"11449391987","pt":1717308486808,"mc":[{"id":"1.229554907","rc":[{"atb":[[150,0],[200,0],[100,0],[250,0]],"id":52385886}],"con":true,"img":false}]}
{"op":"mcm","clk":"11449392030","pt":1717308487383,"mc":[{"id":"1.229554907","rc":[{"atb":[[360,0.29],[410,0.19],[460,0.12],[510,0.05]],"id":52385917},{"atb":[[540,0.15],[590,0.09],[640,0.04],[490,0.21]],"id":52385893}],"con":true,"img":false}]}
{"op":"mcm","clk":"11449392039","pt":1717308487487,"mc":[{"id":"1.229554907","rc":[{"atb":[[140,1.32],[190,0.28],[95,1.11],[240,0.11]],"id":52385886}],"con":true,"img":false}]}
{"op":"mcm","clk":"11449447774","pt":1717309289068,"mc":[{"id":"1.229554907","rc":[{"atb":[[280,0],[330,0],[380,0],[430,0]],"id":52385920},{"atb":[[130,0],[65,0],[180,0],[90,0]],"id":52385923}],"con":true,"img":false}]}
{"op":"mcm","clk":"11449447818","pt":1717309289783,"mc":[{"id":"1.229554907","rc":[{"atb":[[330,0.32],[380,0.21],[430,0.12],[480,0.05]],"id":52385920},{"atb":[[150,0.35],[75,1.41],[200,0.13],[100,0.8]],"id":52385923}],"con":true,"img":false}]}
{"op":"mcm","clk":"11449448635","pt":1717309303200,"mc":[{"id":"1.229554907","rc":[{"atb":[[75,0],[40,0]],"id":52385907},{"atb":[[3.6,10.06],[3.1,37.37]],"id":52385909},{"atb":[[140,0.57],[70,0]],"id":52385886},{"atb":[[550,0],[650,0]],"id":52385918},{"atb":[[140,0],[70,0]],"id":52385920},{"atb":[[4,0],[3.5,0]],"id":52385888},{"atb":[[17,0],[12,0]],"id":52385889},{"atb":[[16,0],[11,0]],"id":52385882},{"atb":[[6.4,0],[8.4,0]],"id":52385884},{"atb":[[220,0],[120,0]],"id":52385917},{"atb":[[6.4,0],[8.4,0]],"id":52385895},{"atb":[[16,0],[22,0]],"id":52385923},{"atb":[[10.5,11.01],[15.5,3.61]],"id":52385891},{"atb":[[550,0],[650,0]],"id":52385893},{"atb":[[2.46,0],[2.66,0]],"id":52385934},{"atb":[[6.2,0],[8.2,0]],"id":52385903},{"atb":[[9.8,0],[14.5,0]],"id":52385904},{"atb":[[10,0],[15,0]],"id":52385936},{"atb":[[2.64,0],[2.84,0]],"id":52385931},{"atb":[[4,0],[5,0]],"id":52385932}],"con":true,"img":false}]}
{"op":"mcm","clk":"11449450083","pt":1717309323534,"mc":[{"id":"1.229554907","rc":[{"atb":[[330,0],[380,0],[430,0],[480,0]],"id":52385920}],"con":true,"img":false}]}
{"op":"mcm","clk":"11449450136","pt":1717309324206,"mc":[{"id":"1.229554907","rc":[{"atb":[[340,0.31],[390,0.2],[440,0.12],[490,0.05]],"id":52385920}],"con":true,"img":false}]}
{"op":"mcm","clk":"11449450415","pt":1717309328143,"mc":[{"id":"1.229554907","rc":[{"atb":[[90,1.17],[46,5.42]],"id":52385907},{"atb":[[3.25,108.4],[3.75,38]],"id":52385909},{"atb":[[120,0.87],[60,4.13]],"id":52385886},{"atb":[[550,0.44],[650,0.16]],"id":52385918},{"atb":[[170,0.61],[85,2.9]],"id":52385920},{"atb":[[3.4,101.62],[3.9,36.04]],"id":52385888},{"atb":[[16.5,6.74],[11.5,23.22]],"id":52385889},{"atb":[[10.5,25.67],[15.5,7.2]],"id":52385882},{"atb":[[8.6,13.75],[6.6,43.55]],"id":52385884},{"atb":[[200,0.52],[100,2.46]],"id":52385917},{"atb":[[6.2,46.9],[8.2,14.51]],"id":52385895},{"atb":[[21,5.22],[15.5,16.82]],"id":52385923},{"atb":[[16,6.96],[11,24.39]],"id":52385891},{"atb":[[550,0.44],[650,0.16]],"id":52385893},{"atb":[[2.72,60.77],[2.52,160.46]],"id":52385934},{"atb":[[8.6,27.52],[6.6,43.55]],"id":52385903},{"atb":[[9.8,27.71],[14.5,7.74]],"id":52385936},{"atb":[[10,27.1],[15,7.46]],"id":52385904},{"atb":[[2.58,154.36],[2.78,58.72]],"id":52385931},{"atb":[[3.95,82.67],[4.9,26.8]],"id":52385932}],"con":true,"img":false}]}
{"op":"mcm","clk":"11449450876","pt":1717309334347,"mc":[{"id":"1.229554907","rc":[{"atb":[[340,0],[390,0],[440,0],[490,0]],"id":52385920}],"con":true,"img":false}]}
{"op":"mcm","clk":"11449450930","pt":1717309335021,"mc":[{"id":"1.229554907","rc":[{"atb":[[330,0.32],[380,0.21],[430,0.12],[480,0.05]],"id":52385920}],"con":true,"img":false}]}
{"op":"mcm","clk":"11449451530","pt":1717309344563,"mc":[{"id":"1.229554907","rc":[{"atb":[[90,0],[46,0]],"id":52385907},{"atb":[[3.25,0],[3.75,0]],"id":52385909},{"atb":[[120,0],[60,0]],"id":52385886},{"atb":[[550,0],[650,0]],"id":52385918},{"atb":[[170,0],[85,0]],"id":52385920},{"atb":[[3.4,0],[3.9,0]],"id":52385888},{"atb":[[16.5,0],[11.5,0]],"id":52385889},{"atb":[[10.5,0],[15.5,0]],"id":52385882},{"atb":[[8.6,0],[6.6,0]],"id":52385884},{"atb":[[200,0],[100,0]],"id":52385917},{"atb":[[6.2,0],[8.2,0]],"id":52385895},{"atb":[[21,0],[15.5,0]],"id":52385923},{"atb":[[16,0],[11,0]],"id":52385891},{"atb":[[550,0],[650,0]],"id":52385893},{"atb":[[2.72,0],[2.52,0]],"id":52385934},{"atb":[[8.6,13.77],[6.6,0]],"id":52385903},{"atb":[[10,0],[15,0]],"id":52385904},{"atb":[[9.8,0],[14.5,0]],"id":52385936},{"atb":[[2.58,0],[2.78,0]],"id":52385931},{"atb":[[3.95,0],[4.9,0]],"id":52385932}],"con":true,"img":false}]}
{"op":"mcm","clk":"11449452516","pt":1717309358186,"mc":[{"id":"1.229554907","rc":[{"atb":[[330,0.74],[430,0.24]],"id":52385886},{"atb":[[3.45,99.55],[3.95,35.43]],"id":52385888},{"atb":[[17,6.53],[12,22.17]],"id":52385889},{"atb":[[16,6.96],[11,24.39]],"id":52385882},{"atb":[[9,13.06],[7,40.65]],"id":52385884},{"atb":[[6.2,46.9],[8.2,14.51]],"id":52385895},{"atb":[[16.5,6.74],[11.5,23.22]],"id":52385891},{"atb":[[550,0.44],[650,0.16]],"id":52385893},{"atb":[[9,13.06],[7,40.65]],"id":52385903},{"atb":[[10.5,25.67],[15.5,7.2]],"id":52385904}],"con":true,"img":false}]}
{"op":"mcm","clk":"11449452526","pt":1717309358242,"mc":[{"id":"1.229554907","rc":[{"atb":[[270,0.9],[370,0.28]],"id":52385907},{"atb":[[3.25,108.4],[3.75,38]],"id":52385909},{"atb":[[550,0.44],[650,0.16]],"id":52385918},{"atb":[[410,0.59],[510,0.2]],"id":52385920},{"atb":[[570,0.18],[470,0.51]],"id":52385917},{"atb":[[32,3.37],[21,12.19]],"id":52385923},{"atb":[[2.46,167.06],[2.66,62.96]],"id":52385934},{"atb":[[18,6.14],[13,20.32]],"id":52385936},{"atb":[[2.54,158.38],[2.74,60.07]],"id":52385931},{"atb":[[4.8,27.5],[3.9,84.1]],"id":52385932}],"con":true,"img":false}]}
{"op":"mcm","clk":"11449454187","pt":1717309383479,"mc":[{"id":"1.229554907","rc":[{"atb":[[330,0],[380,0],[430,0],[480,0]],"id":52385920},{"atb":[[150,0],[75,0],[200,0],[100,0]],"id":52385923}],"con":true,"img":false}]}
{"op":"mcm","clk":"11449454225","pt":1717309384110,"mc":[{"id":"1.229554907","rc":[{"atb":[[270,0],[370,0]],"id":52385907},{"atb":[[3.25,0],[3.75,0]],"id":52385909},{"atb":[[550,0],[650,0]],"id":52385918},{"atb":[[330,0],[430,0]],"id":52385886},{"atb":[[410,0],[510,0]],"id":52385920},{"atb":[[3.45,0],[3.95,0]],"id":52385888},{"atb":[[17,0],[12,0]],"id":52385889},{"atb":[[16,0],[11,0]],"id":52385882},{"atb":[[9,0],[7,0]],"id":52385884},{"atb":[[570,0],[470,0]],"id":52385917},{"atb":[[6.2,0],[8.2,0]],"id":52385895},{"atb":[[32,0],[21,0]],"id":52385923},{"atb":[[16.5,0],[11.5,0]],"id":52385891},{"atb":[[550,0],[650,0]],"id":52385893},{"atb":[[2.46,0],[2.66,0]],"id":52385934},{"atb":[[9,0],[7,0]],"id":52385903},{"atb":[[18,0],[13,0]],"id":52385936},{"atb":[[10.5,0],[15.5,0]],"id":52385904},{"atb":[[2.54,0],[2.74,0]],"id":52385931},{"atb":[[4.8,0],[3.9,0]],"id":52385932}],"con":true,"img":false}]}
{"op":"mcm","clk":"11449454230","pt":1717309384200,"mc":[{"id":"1.229554907","rc":[{"atb":[[280,0.38],[330,0.24],[380,0.14],[430,0.06]],"id":52385920},{"atb":[[130,0.41],[65,1.64],[180,0.15],[90,0.88]],"id":52385923}],"con":true,"img":false}]}
{"op":"mcm","clk":"11449455409","pt":1717309403522,"mc":[{"id":"1.229554907","rc":[{"atb":[[200,0.52],[100,2.46]],"id":52385907},{"atb":[[3.25,108.4],[3.75,38]],"id":52385909},{"atb":[[550,0.44],[650,0.16]],"id":52385918},{"atb":[[150,1.63],[250,0.41]],"id":52385886},{"atb":[[310,0.34],[210,1.16]],"id":52385920},{"atb":[[3.4,101.62],[3.9,36.04]],"id":52385888},{"atb":[[18,6.14],[13,20.32]],"id":52385889},{"atb":[[17,6.53],[12,22.17]],"id":52385882},{"atb":[[9,13.06],[7,40.65]],"id":52385884},{"atb":[[260,0.94],[360,0.59]],"id":52385917},{"atb":[[8.6,13.75],[6.6,43.55]],"id":52385895},{"atb":[[17.5,14.77],[25,4.35]],"id":52385923},{"atb":[[17.5,6.33],[12.5,21.2]],"id":52385891},{"atb":[[550,0.44],[650,0.16]],"id":52385893},{"atb":[[2.46,167.06],[2.66,62.96]],"id":52385934},{"atb":[[6.8,42.05],[8.8,13.4]],"id":52385903},{"atb":[[10.5,25.67],[15.5,7.2]],"id":52385936},{"atb":[[16,6.96],[11,24.39]],"id":52385904},{"atb":[[2.54,158.38],[2.74,60.07]],"id":52385931},{"atb":[[3.95,82.67],[4.9,26.8]],"id":52385932}],"con":true,"img":false}]}
{"op":"mcm","clk":"11449456328","pt":1717309418833,"mc":[{"id":"1.229554907","rc":[{"atb":[[200,0],[100,0]],"id":52385907},{"atb":[[3.25,0],[3.75,0]],"id":52385909},{"atb":[[150,0],[250,0]],"id":52385886},{"atb":[[550,0],[650,0]],"id":52385918},{"atb":[[3.4,0],[3.9,0]],"id":52385888},{"atb":[[310,0],[210,0]],"id":52385920},{"atb":[[18,0],[13,0]],"id":52385889},{"atb":[[17,0],[12,0]],"id":52385882},{"atb":[[9,0],[7,0]],"id":52385884},{"atb":[[260,0],[360,0.29]],"id":52385917},{"atb":[[8.6,0],[6.6,0]],"id":52385895},{"atb":[[17.5,0],[12.5,0]],"id":52385891},{"atb":[[17.5,0],[25,0]],"id":52385923},{"atb":[[550,0],[650,0]],"id":52385893},{"atb":[[2.46,0],[2.66,0]],"id":52385934},{"atb":[[6.8,0],[8.8,0]],"id":52385903},{"atb":[[10.5,0],[15.5,0]],"id":52385936},{"atb":[[16,0],[11,0]],"id":52385904},{"atb":[[2.54,0],[2.74,0]],"id":52385931},{"atb":[[3.95,0],[4.9,0]],"id":52385932}],"con":true,"img":false}]}
{"op":"mcm","clk":"11449456547","pt":1717309422149,"mc":[{"id":"1.229554907","rc":[{"atb":[[3.6,0],[3.1,0],[3.35,0],[2.94,0]],"id":52385909},{"atb":[[65,0],[36,0],[46,0],[28,0]],"id":52385889},{"atb":[[16,0],[18.5,0],[22,0],[13.5,0]],"id":52385895},{"atb":[[18,0],[10.5,0],[13,0],[15.5,0]],"id":52385891},{"atb":[[4.8,0],[5.8,0],[5.3,0],[6.6,0]],"id":52385904}],"con":true,"img":false}]}
{"op":"mcm","clk":"11449456561","pt":1717309422353,"mc":[{"id":"1.229554907","rc":[{"atb":[[9.6,0],[8.6,0],[11.5,0],[14,0]],"id":52385903}],"con":true,"img":false}]}
{"op":"mcm","clk":"11449456597","pt":1717309422922,"mc":[{"id":"1.229554907","rc":[{"atb":[[2.9,55.07],[3,39.24],[3.25,23.25],[3.5,10.46]],"id":52385909},{"atb":[[70,0.38],[38,2.12],[48,1.11],[29,3.74]],"id":52385889},{"atb":[[16.5,5.06],[19,2.91],[23,1.19],[14,8.05]],"id":52385895},{"atb":[[17,3.27],[19.5,1.41],[12,9.51],[14.5,5.81]],"id":52385891},{"atb":[[5,26.16],[5.5,17.44],[6,10.46],[7,4.36]],"id":52385904}],"con":true,"img":false}]}
{"op":"mcm","clk":"11449456608","pt":1717309423073,"mc":[{"id":"1.229554907","rc":[{"atb":[[12,4.76],[9.8,8.92],[8.8,13.41],[14.5,1.94]],"id":52385903}],"con":true,"img":false}]}
{"op":"mcm","clk":"11449457820","pt":1717309441782,"mc":[{"id":"1.229554907","rc":[{"atb":[[160,0.65],[80,3.08]],"id":52385907},{"atb":[[3.85,36.67],[3.35,103.78]],"id":52385909},{"atb":[[550,0.44],[650,0.16]],"id":52385918},{"atb":[[160,0.65],[80,3.08]],"id":52385886},{"atb":[[3.85,36.67],[3.35,103.78]],"id":52385888},{"atb":[[260,0.4],[160,1.53]],"id":52385920},{"atb":[[18,6.14],[13,20.32]],"id":52385889},{"atb":[[17,6.53],[12,22.17]],"id":52385882},{"atb":[[7.2,39.33],[9.2,12.74]],"id":52385884},{"atb":[[260,0.4],[160,1.53]],"id":52385917},{"atb":[[9,13.06],[7,40.65]],"id":52385895},{"atb":[[18,6.14],[13,20.32]],"id":52385891},{"atb":[[16,16.26],[22,4.97]],"id":52385923},{"atb":[[550,0.44],[650,0.16]],"id":52385893},{"atb":[[2.68,62.22],[2.48,164.8]],"id":52385934},{"atb":[[7.2,39.33],[9.2,12.74]],"id":52385903},{"atb":[[17,6.53],[12,22.17]],"id":52385904},{"atb":[[9.8,27.71],[14.5,7.74]],"id":52385936},{"atb":[[2.68,62.22],[2.48,164.8]],"id":52385931},{"atb":[[4,81.3],[5,26.13]],"id":52385932}],"con":true,"img":false}]}
{"op":"mcm","clk":"11449457936","pt":1717309443484,"mc":[{"id":"1.229554907","rc":[{"atb":[[130,0],[65,0],[180,0],[90,0]],"id":52385923}],"con":true,"img":false}]}
{"op":"mcm","clk":"11449457987","pt":1717309444159,"mc":[{"id":"1.229554907","rc":[{"atb":[[150,0.35],[75,1.41],[200,0.13],[100,0.8]],"id":52385923}],"con":true,"img":false}]}
{"op":"mcm","clk":"11449459046","pt":1717309460211,"mc":[{"id":"1.229554907","rc":[{"atb":[[160,0],[80,0]],"id":52385907},{"atb":[[3.85,0],[3.35,0]],"id":52385909},{"atb":[[550,0],[650,0]],"id":52385918},{"atb":[[160,0],[80,0]],"id":52385886},{"atb":[[3.85,0],[3.35,0]],"id":52385888},{"atb":[[260,0],[160,0]],"id":52385920},{"atb":[[18,0],[13,0]],"id":52385889},{"atb":[[17,0],[12,0]],"id":52385882},{"atb":[[7.2,0],[9.2,0]],"id":52385884},{"atb":[[260,0],[160,0]],"id":52385917},{"atb":[[9,0],[7,0]],"id":52385895},{"atb":[[16,0],[22,0]],"id":52385923},{"atb":[[18,0],[13,0]],"id":52385891},{"atb":[[550,0],[650,0]],"id":52385893},{"atb":[[2.68,0],[2.48,0]],"id":52385934},{"atb":[[7.2,0],[9.2,0]],"id":52385903},{"atb":[[17,0],[12,0]],"id":52385904},{"atb":[[9.8,0],[14.5,0]],"id":52385936},{"atb":[[2.68,0],[2.48,0]],"id":52385931},{"atb":[[4,0],[5,0]],"id":52385932}],"con":true,"img":false}]}
{"op":"mcm","clk":"11449459286","pt":1717309463590,"mc":[{"id":"1.229554907","rc":[{"atb":[[150,0],[75,0],[200,0],[100,0]],"id":52385923}],"con":true,"img":false}]}
{"op":"mcm","clk":"11449459340","pt":1717309464311,"mc":[{"id":"1.229554907","rc":[{"atb":[[140,0.38],[70,1.52],[190,0.14],[95,0.84]],"id":52385923}],"con":true,"img":false}]}
{"op":"mcm","clk":"11449461417","pt":1717309496448,"mc":[{"id":"1.229554907","rc":[{"atb":[[180,0.58],[90,2.74]],"id":52385907},{"atb":[[3.15,113.44],[3.65,39.44]],"id":52385909},{"atb":[[550,0.44],[650,0.16]],"id":52385918},{"atb":[[280,0.75],[180,1.36]],"id":52385920},{"atb":[[300,0.81],[400,0.26]],"id":52385917},{"atb":[[17,15.24],[24,4.54]],"id":52385923},{"atb":[[2.54,67.87],[2.34,182.01]],"id":52385934},{"atb":[[10,27.1],[15,7.46]],"id":52385936},{"atb":[[2.56,156.35],[2.76,59.39]],"id":52385931},{"atb":[[3.95,82.67],[4.9,26.8]],"id":52385932}],"con":true,"img":false}]}
{"op":"mcm","clk":"11449461424","pt":1717309496544,"mc":[{"id":"1.229554907","rc":[{"atb":[[300,0.35],[200,1.22]],"id":52385886},{"atb":[[3.6,93.81],[4.2,32.66]],"id":52385888},{"atb":[[18.5,5.97],[13.5,19.51]],"id":52385889},{"atb":[[18,6.14],[13,20.32]],"id":52385882},{"atb":[[7.2,39.33],[9.2,12.74]],"id":52385884},{"atb":[[9,13.06],[7,40.65]],"id":52385895},{"atb":[[17.5,6.33],[12.5,21.2]],"id":52385891},{"atb":[[550,0.44],[650,0.16]],"id":52385893},{"atb":[[7.2,39.33],[9.2,12.74]],"id":52385903},{"atb":[[16.5,6.74],[11.5,23.22]],"id":52385904}],"con":true,"img":false}]}
{"op":"mcm","clk":"11449462429","pt":1717309511641,"mc":[{"id":"1.229554907","rc":[{"atb":[[180,0],[90,0]],"id":52385907},{"atb":[[3.15,0],[3.65,0]],"id":52385909},{"atb":[[300,0],[200,0]],"id":52385886},{"atb":[[550,0],[650,0]],"id":52385918},{"atb":[[3.6,0],[4.2,0]],"id":52385888},{"atb":[[280,0.38],[180,0]],"id":52385920},{"atb":[[18.5,0],[13.5,0]],"id":52385889},{"atb":[[18,0],[13,0]],"id":52385882},{"atb":[[7.2,0],[9.2,0]],"id":52385884},{"atb":[[300,0],[400,0]],"id":52385917},{"atb":[[9,0],[7,0]],"id":52385895},{"atb":[[17.5,0],[12.5,0]],"id":52385891},{"atb":[[17,0],[24,0]],"id":52385923},{"atb":[[550,0],[650,0]],"id":52385893},{"atb":[[2.54,0],[2.34,0]],"id":52385934},{"atb":[[7.2,0],[9.2,0]],"id":52385903},{"atb":[[16.5,0],[11.5,0]],"id":52385904},{"atb":[[10,0],[15,0]],"id":52385936},{"atb":[[2.56,0],[2.76,0]],"id":52385931},{"atb":[[3.95,0],[4.9,0]],"id":52385932}],"con":true,"img":false}]}
{"op":"mcm","clk":"11449464092","pt":1717309535684,"mc":[{"id":"1.229554907","rc":[{"atb":[[210,0.5],[110,2.23]],"id":52385907},{"atb":[[3.25,131.65],[3.75,38]],"id":52385909},{"atb":[[550,0.44],[650,0.16]],"id":52385918},{"atb":[[280,0.37],[180,1.36]],"id":52385886},{"atb":[[4.1,33.71],[3.55,95.64]],"id":52385888},{"atb":[[310,0.34],[210,1.16]],"id":52385920},{"atb":[[18.5,5.97],[13.5,19.51]],"id":52385889},{"atb":[[18,6.14],[13,20.32]],"id":52385882},{"atb":[[7.4,38.1],[9.4,12.44]],"id":52385884},{"atb":[[290,0.84],[390,0.26]],"id":52385917},{"atb":[[6.8,42.05],[8.8,13.4]],"id":52385895},{"atb":[[18,6.14],[13,20.32]],"id":52385891},{"atb":[[17,15.24],[24,4.54]],"id":52385923},{"atb":[[550,0.44],[650,0.16]],"id":52385893},{"atb":[[2.38,176.74],[2.58,66.16]],"id":52385934},{"atb":[[7.4,38.1],[9.4,12.44]],"id":52385903},{"atb":[[9.8,27.71],[14.5,7.74]],"id":52385936},{"atb":[[17,6.53],[12,22.17]],"id":52385904},{"atb":[[2.72,60.77],[2.52,160.46]],"id":52385931},{"atb":[[4.8,27.5],[3.9,84.1]],"id":52385932}],"con":true,"img":false}]}
{"op":"mcm","clk":"11449468189","pt":1717309595203,"mc":[{"id":"1.229554907","rc":[{"atb":[[840,0],[890,0],[940,0],[990,0]],"id":52385918},{"atb":[[140,0],[190,0],[95,0],[240,0]],"id":52385886},{"atb":[[280,0],[330,0],[380,0],[430,0]],"id":52385920},{"atb":[[360,0],[410,0],[460,0],[510,0]],"id":52385917},{"atb":[[140,0],[70,0],[190,0],[95,0]],"id":52385923},{"atb":[[38,0],[19.5,0],[24,0],[29,0]],"id":52385936}],"con":true,"img":false}]}
{"op":"mcm","clk":"11449468234","pt":1717309595923,"mc":[{"id":"1.229554907","rc":[{"atb":[[170,0.31],[85,1.25],[220,0.12],[120,0.66]],"id":52385886},{"atb":[[820,0.13],[870,0.09],[920,0.06],[970,0.03]],"id":52385918},{"atb":[[260,0.4],[310,0.6],[360,0.15],[410,0.06]],"id":52385920},{"atb":[[300,0.35],[350,0.23],[400,0.13],[450,0.06]],"id":52385917},{"atb":[[160,0.16],[80,0.99],[110,0.48],[55,1.94]],"id":52385923},{"atb":[[34,0.8],[18.5,5.98],[22,3.74],[27,2.01]],"id":52385936}],"con":true,"img":false}]}
{"op":"mcm","clk":"11449470466","pt":1717309626463,"mc":[{"id":"1.229554907","rc":[{"atb":[[820,0],[870,0],[920,0],[970,0]],"id":52385918},{"atb":[[18,0],[21,0],[13,0],[15.5,0]],"id":52385884},{"atb":[[160,0],[80,0],[110,0],[55,0]],"id":52385923}],"con":true,"img":false}]}
{"op":"mcm","clk":"11449470525","pt":1717309627142,"mc":[{"id":"1.229554907","rc":[{"atb":[[16,5.23],[18.5,2.99],[22,1.25],[13.5,8.37]],"id":52385884}],"con":true,"img":false}]}
{"op":"mcm","clk":"11449470532","pt":1717309627246,"mc":[{"id":"1.229554907","rc":[{"atb":[[840,0.13],[890,0.09],[940,0.06],[990,0.03]],"id":52385918},{"atb":[[150,0.18],[75,1.06],[100,0.53],[50,2.13]],"id":52385923}],"con":true,"img":false}]}
{"op":"mcm","clk":"11449471763","pt":1717309643654,"mc":[{"id":"1.229554907","rc":[{"atb":[[210,0],[110,0]],"id":52385907},{"atb":[[3.25,23.25],[3.75,0]],"id":52385909},{"atb":[[550,0],[650,0]],"id":52385918},{"atb":[[280,0],[180,0]],"id":52385886},{"atb":[[310,0.26],[210,0]],"id":52385920},{"atb":[[4.1,0],[3.55,0]],"id":52385888},{"atb":[[18.5,0],[13.5,0]],"id":52385889},{"atb":[[18,0],[13,0]],"id":52385882},{"atb":[[7.4,0],[9.4,0]],"id":52385884},{"atb":[[290,0],[390,0]],"id":52385917},{"atb":[[6.8,0],[8.8,0]],"id":52385895},{"atb":[[17,0],[24,0]],"id":52385923},{"atb":[[18,0],[13,0]],"id":52385891},{"atb":[[550,0],[650,0]],"id":52385893},{"atb":[[2.38,0],[2.58,0]],"id":52385934},{"atb":[[7.4,0],[9.4,0]],"id":52385903},{"atb":[[9.8,0],[14.5,0]],"id":52385936},{"atb":[[17,0],[12,0]],"id":52385904},{"atb":[[2.72,0],[2.52,0]],"id":52385931},{"atb":[[4.8,0],[3.9,0]],"id":52385932}],"con":true,"img":false}]}
{"op":"mcm","clk":"11449471816","pt":1717309644376,"mc":[{"id":"1.229554907","rc":[{"atb":[[540,0],[590,0],[640,0],[490,0]],"id":52385893}],"con":true,"img":false}]}
{"op":"mcm","clk":"11449471879","pt":1717309645062,"mc":[{"id":"1.229554907","rc":[{"atb":[[560,0.14],[610,0.08],[660,0.04],[510,0.2]],"id":52385893}],"con":true,"img":false}]}
{"op":"mcm","clk":"11449473519","pt":1717309667229,"mc":[{"id":"1.229554907","rc":[{"atb":[[270,0.38],[170,1.44]],"id":52385907},{"atb":[[3.25,131.65],[3.75,38]],"id":52385909},{"atb":[[550,0.44],[650,0.16]],"id":52385918},{"atb":[[350,0.29],[250,0.97]],"id":52385886},{"atb":[[4,34.84],[3.5,97.56]],"id":52385888},{"atb":[[290,0.84],[390,0.26]],"id":52385920},{"atb":[[19,5.8],[14,18.76]],"id":52385889},{"atb":[[18,6.14],[13,20.32]],"id":52385882},{"atb":[[7.4,38.1],[9.4,12.44]],"id":52385884},{"atb":[[370,0.65],[470,0.22]],"id":52385917},{"atb":[[7.2,39.33],[9.2,12.74]],"id":52385895},{"atb":[[18.5,5.97],[13.5,19.51]],"id":52385891},{"atb":[[17.5,14.77],[25,4.35]],"id":52385923},{"atb":[[550,0.44],[650,0.16]],"id":52385893},{"atb":[[2.56,67],[2.36,179.33]],"id":52385934},{"atb":[[7.4,38.1],[9.4,12.44]],"id":52385903},{"atb":[[17.5,6.33],[12.5,21.2]],"id":52385904},{"atb":[[10.5,25.67],[15.5,7.2]],"id":52385936},{"atb":[[2.72,60.77],[2.52,160.46]],"id":52385931},{"atb":[[4,81.3],[5,26.13]],"id":52385932}],"con":true,"img":false}]}
{"op":"mcm","clk":"11449474634","pt":1717309682617,"mc":[{"id":"1.229554907","rc":[{"atb":[[270,0],[170,0]],"id":52385907},{"atb":[[3.25,23.25],[3.75,0]],"id":52385909},{"atb":[[550,0],[650,0]],"id":52385918},{"atb":[[350,0],[250,0]],"id":52385886},{"atb":[[290,0],[390,0]],"id":52385920},{"atb":[[4,0],[3.5,0]],"id":52385888},{"atb":[[19,0],[14,0]],"id":52385889},{"atb":[[18,0],[13,0]],"id":52385882},{"atb":[[7.4,0],[9.4,0]],"id":52385884},{"atb":[[370,0],[470,0]],"id":52385917},{"atb":[[7.2,0],[9.2,0]],"id":52385895},{"atb":[[17.5,0],[25,0]],"id":52385923},{"atb":[[18.5,0],[13.5,0]],"id":52385891},{"atb":[[550,0],[650,0]],"id":52385893},{"atb":[[2.56,0],[2.36,0]],"id":52385934},{"atb":[[7.4,0],[9.4,0]],"id":52385903},{"atb":[[17.5,0],[12.5,0]],"id":52385904},{"atb":[[10.5,0],[15.5,0]],"id":52385936},{"atb":[[2.72,0],[2.52,0]],"id":52385931},{"atb":[[4,0],[5,0]],"id":52385932}],"con":true,"img":false}]}
{"op":"mcm","clk":"11449476663","pt":1717309708366,"mc":[{"id":"1.229554907","rc":[{"atb":[[260,0.94],[360,0.29]],"id":52385907},{"atb":[[3.25,131.65],[3.75,38]],"id":52385909},{"atb":[[360,0.68],[460,0.23]],"id":52385886},{"atb":[[550,0.44],[650,0.16]],"id":52385918},{"atb":[[4,34.84],[3.5,97.56]],"id":52385888},{"atb":[[400,0.61],[500,0.2]],"id":52385920},{"atb":[[19,5.8],[14,18.76]],"id":52385889},{"atb":[[18,6.14],[13,20.32]],"id":52385882},{"atb":[[7.4,38.1],[9.4,12.44]],"id":52385884},{"atb":[[590,0.17],[490,0.49]],"id":52385917},{"atb":[[7.2,39.33],[9.2,12.74]],"id":52385895},{"atb":[[18.5,5.97],[13.5,19.51]],"id":52385891},{"atb":[[19.5,13.18],[29,3.73]],"id":52385923},{"atb":[[550,0.44],[650,0.16]],"id":52385893},{"atb":[[2.56,67],[2.36,179.33]],"id":52385934},{"atb":[[7.4,38.1],[9.4,12.44]],"id":52385903},{"atb":[[17.5,6.33],[12.5,21.2]],"id":52385904},{"atb":[[16.5,6.74],[11.5,23.22]],"id":52385936},{"atb":[[2.72,60.77],[2.52,160.46]],"id":52385931},{"atb":[[4,81.3],[5,26.13]],"id":52385932}],"con":true,"img":false}]}
{"op":"mcm","clk":"11449490082","pt":1717309799634,"mc":[{"id":"1.229554907","rc":[{"atb":[[140,0],[70,0],[190,0],[95,0]],"id":52385907},{"atb":[[5.6,0],[7.2,0],[6.2,0],[8.2,0]],"id":52385888},{"atb":[[260,0],[310,0],[360,0],[410,0]],"id":52385920},{"atb":[[32,0],[42,0],[26,0],[55,0]],"id":52385882},{"atb":[[16,0],[18.5,0],[22,0],[13.5,0]],"id":52385884},{"atb":[[34,0],[18.5,0],[22,0],[27,0]],"id":52385936}],"con":true,"img":false}]}
{"op":"mcm","clk":"11449490143","pt":1717309800371,"mc":[{"id":"1.229554907","rc":[{"atb":[[130,0.41],[65,1.64],[180,0.15],[90,0.88]],"id":52385907},{"atb":[[300,0.26],[350,0.15],[400,0.68],[250,0.42]],"id":52385920},{"atb":[[8.6,3.44],[5.8,21.8],[7.6,7.93],[6.6,14.02]],"id":52385888},{"atb":[[65,0.41],[36,2.24],[46,1.16],[28,3.88]],"id":52385882},{"atb":[[16.5,5.06],[19,2.91],[23,1.19],[14,8.05]],"id":52385884},{"atb":[[17.5,6.34],[20,4.13],[25,2.18],[30,0.9]],"id":52385936}],"con":true,"img":false}]}
{"op":"mcm","clk":"11449493501","pt":1717309847574,"mc":[{"id":"1.229554907","rc":[{"atb":[[2.9,0],[3,0],[3.25,108.4],[3.5,0]],"id":52385909},{"atb":[[12,0],[9.8,0],[8.8,0],[14.5,0]],"id":52385903}],"con":true,"img":false}]}
{"op":"mcm","clk":"11449493539","pt":1717309848294,"mc":[{"id":"1.229554907","rc":[{"atb":[[2.9,55.07],[3,39.24],[3.25,131.65],[3.5,10.46]],"id":52385909},{"atb":[[9.6,9.12],[8.6,13.77],[11.5,4.98],[14,2.01]],"id":52385903}],"con":true,"img":false}]}
{"op":"mcm","clk":"11449495570","pt":1717309879434,"mc":[{"id":"1.229554907","rc":[{"atb":[[260,0],[360,0]],"id":52385907},{"atb":[[3.25,23.25],[3.75,0]],"id":52385909},{"atb":[[550,0],[650,0]],"id":52385918},{"atb":[[360,0],[460,0]],"id":52385886},{"atb":[[4,0],[3.5,0]],"id":52385888},{"atb":[[400,0.07],[500,0]],"id":52385920},{"atb":[[19,0],[14,0]],"id":52385889},{"atb":[[18,0],[13,0]],"id":52385882},{"atb":[[7.4,0],[9.4,0]],"id":52385884},{"atb":[[590,0],[490,0]],"id":52385917},{"atb":[[7.2,0],[9.2,0]],"id":52385895},{"atb":[[18.5,0],[13.5,0]],"id":52385891},{"atb":[[19.5,0],[29,0]],"id":52385923},{"atb":[[550,0],[650,0]],"id":52385893},{"atb":[[2.56,0],[2.36,0]],"id":52385934},{"atb":[[7.4,0],[9.4,0]],"id":52385903},{"atb":[[16.5,0],[11.5,0]],"id":52385936},{"atb":[[17.5,0],[12.5,0]],"id":52385904},{"atb":[[2.72,0],[2.52,0]],"id":52385931},{"atb":[[4,0],[5,0]],"id":52385932}],"con":true,"img":false}]}
{"op":"mcm","clk":"11449496112","pt":1717309888001,"mc":[{"id":"1.229554907","rc":[{"atb":[[270,0.9],[370,0.28]],"id":52385907},{"atb":[[3.8,37.33],[3.3,106.04]],"id":52385909},{"atb":[[350,0.7],[450,0.23]],"id":52385886},{"atb":[[550,0.44],[650,0.16]],"id":52385918},{"atb":[[4,34.84],[3.5,97.56]],"id":52385888},{"atb":[[410,0.59],[510,0.2]],"id":52385920},{"atb":[[19,5.8],[14,18.76]],"id":52385889},{"atb":[[18,6.14],[13,20.32]],"id":52385882},{"atb":[[7.4,38.1],[9.4,12.44]],"id":52385884},{"atb":[[590,0.17],[490,0.49]],"id":52385917},{"atb":[[9,13.06],[7,40.65]],"id":52385895},{"atb":[[19,13.55],[28,3.87]],"id":52385923},{"atb":[[18.5,5.97],[13.5,19.51]],"id":52385891},{"atb":[[550,0.44],[650,0.16]],"id":52385893},{"atb":[[2.56,67],[2.36,179.33]],"id":52385934},{"atb":[[7.4,38.1],[9.4,12.44]],"id":52385903},{"atb":[[16.5,6.74],[11.5,23.22]],"id":52385936},{"atb":[[17.5,6.33],[12.5,21.2]],"id":52385904},{"atb":[[2.5,162.6],[2.7,61.48]],"id":52385931},{"atb":[[3.95,82.67],[4.9,26.8]],"id":52385932}],"con":true,"img":false}]}
{"op":"mcm","clk":"11449496195","pt":1717309889086,"mc":[{"id":"1.229554907","rc":[{"atb":[[150,0],[75,0],[100,0],[50,0]],"id":52385923},{"atb":[[8,0],[5.5,0],[6,0],[7,0]],"id":52385932}],"con":true,"img":false}]}
{"op":"mcm","clk":"11449496230","pt":1717309889803,"mc":[{"id":"1.229554907","rc":[{"atb":[[140,0.38],[70,1.52],[190,0.14],[95,0.84]],"id":52385923},{"atb":[[5.6,22.75],[7.2,8.44],[6.2,15.09],[8.2,3.63]],"id":52385932}],"con":true,"img":false}]}
{"op":"mcm","clk":"11449505670","pt":1717310047347,"mc":[{"id":"1.229554907","rc":[{"atb":[[2.9,0],[3,0],[3.25,0],[3.5,0]],"id":52385909}],"con":true,"img":false}]}
{"op":"mcm","clk":"11449505716","pt":1717310048067,"mc":[{"id":"1.229554907","rc":[{"atb":[[2.9,55.07],[3,39.24],[3.25,23.25],[3.5,10.46]],"id":52385909}],"con":true,"img":false}]}
{"op":"mcm","clk":"11449528865","pt":1717310431836,"mc":[{"id":"1.229554907","rc":[{"atb":[[270,0],[370,0]],"id":52385907},{"atb":[[3.8,0],[3.3,0]],"id":52385909},{"atb":[[550,0],[650,0]],"id":52385918},{"atb":[[350,0],[450,0]],"id":52385886},{"atb":[[410,0],[510,0]],"id":52385920},{"atb":[[4,0],[3.5,0]],"id":52385888},{"atb":[[19,0],[14,0]],"id":52385889},{"atb":[[18,0],[13,0]],"id":52385882},{"atb":[[7.4,0],[9.4,0]],"id":52385884},{"atb":[[590,0],[490,0]],"id":52385917},{"atb":[[9,0],[7,0]],"id":52385895},{"atb":[[19,0],[28,0]],"id":52385923},{"atb":[[18.5,0],[13.5,0]],"id":52385891},{"atb":[[550,0],[650,0]],"id":52385893},{"atb":[[2.56,0],[2.36,0]],"id":52385934},{"atb":[[7.4,0],[9.4,0]],"id":52385903},{"atb":[[16.5,0],[11.5,0]],"id":52385936},{"atb":[[17.5,0],[12.5,0]],"id":52385904},{"atb":[[2.5,0],[2.7,0]],"id":52385931},{"atb":[[3.95,0],[4.9,0]],"id":52385932}],"con":true,"img":false}]}
{"op":"mcm","clk":"11449530494","pt":1717310457874,"mc":[{"id":"1.229554907","rc":[{"atb":[[270,0.9],[370,0.28]],"id":52385907},{"atb":[[3.8,37.33],[3.3,106.04]],"id":52385909},{"atb":[[350,0.7],[450,0.23]],"id":52385886},{"atb":[[550,0.44],[650,0.16]],"id":52385918},{"atb":[[410,0.59],[510,0.2]],"id":52385920},{"atb":[[4,34.84],[3.5,97.56]],"id":52385888},{"atb":[[19,5.8],[14,18.76]],"id":52385889},{"atb":[[18,6.14],[13,20.32]],"id":52385882},{"atb":[[7.4,38.1],[9.4,12.44]],"id":52385884},{"atb":[[590,0.17],[490,0.49]],"id":52385917},{"atb":[[9,13.06],[7,40.65]],"id":52385895},{"atb":[[18.5,5.97],[13.5,19.51]],"id":52385891},{"atb":[[19,13.55],[28,3.87]],"id":52385923},{"atb":[[550,0.44],[650,0.16]],"id":52385893},{"atb":[[2.56,67],[2.36,179.33]],"id":52385934},{"atb":[[7.4,38.1],[9.4,12.44]],"id":52385903},{"atb":[[17.5,6.33],[12.5,21.2]],"id":52385904},{"atb":[[16.5,6.74],[11.5,23.22]],"id":52385936},{"atb":[[2.5,162.6],[2.7,61.48]],"id":52385931},{"atb":[[3.95,82.67],[4.9,26.8]],"id":52385932}],"con":true,"img":false}]}
{"op":"mcm","clk":"11449530617","pt":1717310459681,"mc":[{"id":"1.229554907","rc":[{"atb":[[9.6,0],[8.6,0],[11.5,0],[14,0]],"id":52385903}],"con":true,"img":false}]}
{"op":"mcm","clk":"11449530674","pt":1717310460356,"mc":[{"id":"1.229554907","rc":[{"atb":[[12,4.76],[9.8,8.92],[8.8,13.41],[14.5,1.94]],"id":52385903}],"con":true,"img":false}]}
{"op":"mcm","clk":"11449532107","pt":1717310486406,"mc":[{"id":"1.229554907","rc":[{"atb":[[38,0]],"id":52385889},{"atb":[[16.5,0],[14,0]],"id":52385895},{"atb":[[17,0],[19.5,0],[12,0]],"id":52385891},{"atb":[[5.5,0],[6,0]],"id":52385904}],"con":true,"img":false}]}
{"op":"mcm","clk":"11449532113","pt":1717310486507,"mc":[{"id":"1.229554907","rc":[{"atb":[[70,0],[48,0],[29,0]],"id":52385889},{"atb":[[19,0],[23,0]],"id":52385895},{"atb":[[14.5,0]],"id":52385891},{"atb":[[5,0],[7,0]],"id":52385904}],"con":true,"img":false}]}
{"op":"mcm","clk":"11449532148","pt":1717310487085,"mc":[{"id":"1.229554907","rc":[{"atb":[[40,2.01]],"id":52385889},{"atb":[[17.5,4.76],[15,7.48]],"id":52385895},{"atb":[[18,3.08],[21,1.31],[13,8.72]],"id":52385891},{"atb":[[5.6,17.06],[6.2,10.06]],"id":52385904}],"con":true,"img":false}]}
{"op":"mcm","clk":"11449532158","pt":1717310487192,"mc":[{"id":"1.229554907","rc":[{"atb":[[75,0.36],[50,1.07],[30,3.61]],"id":52385889},{"atb":[[20,2.75],[25,1.09]],"id":52385895},{"atb":[[15.5,5.41]],"id":52385891},{"atb":[[7.2,4.22],[5.1,25.52]],"id":52385904}],"con":true,"img":false}]}
{"op":"mcm","clk":"11449543822","pt":1717310686351,"mc":[{"id":"1.229554907","rc":[{"atb":[[560,0],[610,0],[660,0],[510,0]],"id":52385893}],"con":true,"img":false}]}
{"op":"mcm","clk":"11449543865","pt":1717310687072,"mc":[{"id":"1.229554907","rc":[{"atb":[[660,0.16],[710,0.11],[760,0.07],[810,0.03]],"id":52385893}],"con":true,"img":false}]}
{"op":"mcm","clk":"11449572150","pt":1717311196001,"mc":[{"id":"1.229554907","rc":[{"atb":[[810,0]],"id":52385893}],"con":true,"img":false}]}
{"op":"mcm","clk":"11449572189","pt":1717311196719,"mc":[{"id":"1.229554907","rc":[{"atb":[[860,0.03]],"id":52385893}],"con":true,"img":false}]}
{"op":"mcm","clk":"11449572229","pt":1717311197592,"mc":[{"id":"1.229554907","rc":[{"atb":[[860,0]],"id":52385893}],"con":true,"img":false}]}
{"op":"mcm","clk":"11449572253","pt":1717311198310,"mc":[{"id":"1.229554907","rc":[{"atb":[[850,0.03]],"id":52385893}],"con":true,"img":false}]}
{"op":"mcm","clk":"11449589743","pt":1717311498410,"mc":[{"id":"1.229554907","rc":[{"atb":[[270,0],[370,0]],"id":52385907},{"atb":[[3.8,0],[3.3,0]],"id":52385909},{"atb":[[350,0],[450,0]],"id":52385886},{"atb":[[550,0],[650,0]],"id":52385918},{"atb":[[410,0],[510,0]],"id":52385920},{"atb":[[4,0],[3.5,0]],"id":52385888},{"atb":[[19,0],[14,0]],"id":52385889},{"atb":[[18,0],[13,0]],"id":52385882},{"atb":[[7.4,0],[9.4,0]],"id":52385884},{"atb":[[590,0],[490,0]],"id":52385917},{"atb":[[9,0],[7,0]],"id":52385895},{"atb":[[18.5,0],[13.5,0]],"id":52385891},{"atb":[[19,0],[28,0]],"id":52385923},{"atb":[[550,0],[650,0]],"id":52385893},{"atb":[[2.56,0],[2.36,0]],"id":52385934},{"atb":[[7.4,0],[9.4,0]],"id":52385903},{"atb":[[17.5,0],[12.5,0]],"id":52385904},{"atb":[[16.5,0],[11.5,0]],"id":52385936},{"atb":[[2.5,0],[2.7,0]],"id":52385931},{"atb":[[3.95,0],[4.9,0]],"id":52385932}],"con":true,"img":false}]}
{"op":"mcm","clk":"11449590382","pt":1717311508887,"mc":[{"id":"1.229554907","rc":[{"atb":[[270,0.9],[370,0.28]],"id":52385907},{"atb":[[3.8,37.33],[3.3,106.04]],"id":52385909},{"atb":[[350,0.7],[450,0.23]],"id":52385886},{"atb":[[550,0.44],[650,0.16]],"id":52385918},{"atb":[[4,34.84],[3.5,97.56]],"id":52385888},{"atb":[[410,0.59],[510,0.2]],"id":52385920},{"atb":[[19,5.8],[14,18.76]],"id":52385889},{"atb":[[18,6.14],[13,20.32]],"id":52385882},{"atb":[[7.4,38.1],[9.4,12.44]],"id":52385884},{"atb":[[590,0.17],[490,0.49]],"id":52385917},{"atb":[[9,13.06],[7,40.65]],"id":52385895},{"atb":[[18.5,5.97],[13.5,19.51]],"id":52385891},{"atb":[[19,13.55],[28,3.87]],"id":52385923},{"atb":[[550,0.44],[650,0.16]],"id":52385893},{"atb":[[2.56,67],[2.36,179.33]],"id":52385934},{"atb":[[7.4,38.1],[9.4,12.44]],"id":52385903},{"atb":[[17.5,6.33],[12.5,21.2]],"id":52385904},{"atb":[[16.5,6.74],[11.5,23.22]],"id":52385936},{"atb":[[2.5,162.6],[2.7,61.48]],"id":52385931},{"atb":[[3.95,82.67],[4.9,26.8]],"id":52385932}],"con":true,"img":false}]}
{"op":"mcm","clk":"11449592315","pt":1717311548520,"mc":[{"id":"1.229554907","rc":[{"atb":[[2.9,0],[3,0],[3.25,0],[3.5,0]],"id":52385909},{"atb":[[17.5,0],[20,0],[25,0],[15,0]],"id":52385895},{"atb":[[12,0],[9.8,0],[8.8,0],[14.5,0]],"id":52385903}],"con":true,"img":false}]}
{"op":"mcm","clk":"11449592347","pt":1717311549233,"mc":[{"id":"1.229554907","rc":[{"atb":[[12,4.76],[9.8,8.92],[8.8,13.41],[14.5,1.94]],"id":52385903}],"con":true,"img":false}]}
{"op":"mcm","clk":"11449593408","pt":1717311568530,"mc":[{"id":"1.229554907","rc":[{"atb":[[17.5,4.76],[20,2.75],[25,1.09],[15,7.48]],"id":52385895}],"con":true,"img":false}]}
{"op":"mcm","clk":"11449593444","pt":1717311568954,"mc":[{"id":"1.229554907","rc":[{"atb":[[2.9,55.07],[3,39.24],[3.25,23.25],[3.5,10.46]],"id":52385909}],"con":true,"img":false}]}
{"op":"mcm","clk":"11449593461","pt":1717311569348,"mc":[{"id":"1.229554907","rc":[{"atb":[[2.9,110.14],[3,78.48],[3.25,46.51],[3.5,20.93]],"id":52385909}],"con":true,"img":false}]}
{"op":"mcm","clk":"11449593517","pt":1717311570189,"mc":[{"id":"1.229554907","rc":[{"atb":[[2.9,55.07],[3,39.24],[3.25,23.25],[3.5,10.46]],"id":52385909}],"con":true,"img":false}]}
{"op":"mcm","clk":"11449596635","pt":1717311627925,"mc":[{"id":"1.229554907","rc":[{"atb":[[660,0],[710,0],[760,0]],"id":52385893}],"con":true,"img":false}]}
{"op":"mcm","clk":"11449596683","pt":1717311628640,"mc":[{"id":"1.229554907","rc":[{"atb":[[700,0.15],[750,0.1],[800,0.07]],"id":52385893}],"con":true,"img":false}]}
{"op":"mcm","clk":"11449599905","pt":1717311688816,"mc":[{"id":"1.229554907","rc":[{"atb":[[16.5,0],[19,0],[23,0],[14,0]],"id":52385884}],"con":true,"img":false}]}
{"op":"mcm","clk":"11449599941","pt":1717311689482,"mc":[{"id":"1.229554907","rc":[{"atb":[[17,4.9],[19.5,2.83],[24,1.14],[14.5,7.75]],"id":52385884}],"con":true,"img":false}]}
{"op":"mcm","clk":"11449619716","pt":1717312057790,"mc":[{"id":"1.229554907","rc":[{"atb":[[700,0],[750,0],[800,0],[850,0]],"id":52385893}],"con":true,"img":false}]}
{"op":"mcm","clk":"11449619749","pt":1717312058462,"mc":[{"id":"1.229554907","rc":[{"atb":[[660,0.16],[710,0.11],[760,0.07],[810,0.03]],"id":52385893}],"con":true,"img":false}]}
{"op":"mcm","clk":"11449640553","pt":1717312587478,"mc":[{"id":"1.229554907","rc":[{"atb":[[270,0],[370,0]],"id":52385907},{"atb":[[3.8,0],[3.3,0]],"id":52385909},{"atb":[[550,0],[650,0]],"id":52385918},{"atb":[[350,0],[450,0]],"id":52385886},{"atb":[[410,0],[510,0]],"id":52385920},{"atb":[[4,0],[3.5,0]],"id":52385888},{"atb":[[19,0],[14,0]],"id":52385889},{"atb":[[18,0],[13,0]],"id":52385882},{"atb":[[7.4,0],[9.4,0]],"id":52385884},{"atb":[[590,0],[490,0]],"id":52385917},{"atb":[[9,0],[7,0]],"id":52385895},{"atb":[[18.5,0],[13.5,0]],"id":52385891},{"atb":[[19,0],[28,0]],"id":52385923},{"atb":[[550,0],[650,0]],"id":52385893},{"atb":[[2.56,0],[2.36,0]],"id":52385934},{"atb":[[7.4,0],[9.4,0]],"id":52385903},{"atb":[[17.5,0],[12.5,0]],"id":52385904},{"atb":[[16.5,0],[11.5,0]],"id":52385936},{"atb":[[2.5,0],[2.7,0]],"id":52385931},{"atb":[[3.95,0],[4.9,0]],"id":52385932}],"con":true,"img":false}]}
{"op":"mcm","clk":"11449640837","pt":1717312594357,"mc":[{"id":"1.229554907","rc":[{"atb":[[270,0.9],[370,0.28]],"id":52385907},{"atb":[[3.8,37.33],[3.3,106.04]],"id":52385909},{"atb":[[350,0.7],[450,0.23]],"id":52385886},{"atb":[[550,0.44],[650,0.16]],"id":52385918},{"atb":[[4,34.84],[3.5,97.56]],"id":52385888},{"atb":[[410,0.59],[510,0.2]],"id":52385920},{"atb":[[19,5.8],[14,18.76]],"id":52385889},{"atb":[[18,6.14],[13,20.32]],"id":52385882},{"atb":[[7.4,38.1],[9.4,12.44]],"id":52385884},{"atb":[[590,0.17],[490,0.49]],"id":52385917},{"atb":[[9,13.06],[7,40.65]],"id":52385895},{"atb":[[18.5,5.97],[13.5,19.51]],"id":52385891},{"atb":[[19,13.55],[28,3.87]],"id":52385923},{"atb":[[550,0.44],[650,0.16]],"id":52385893},{"atb":[[2.56,67],[2.36,179.33]],"id":52385934},{"atb":[[7.4,38.1],[9.4,12.44]],"id":52385903},{"atb":[[17.5,6.33],[12.5,21.2]],"id":52385904},{"atb":[[16.5,6.74],[11.5,23.22]],"id":52385936},{"atb":[[2.5,162.6],[2.7,61.48]],"id":52385931},{"atb":[[3.95,82.67],[4.9,26.8]],"id":52385932}],"con":true,"img":false}]}
{"op":"mcm","clk":"11449648344","pt":1717312778820,"mc":[{"id":"1.229554907","rc":[{"atb":[[75,0],[40,0],[50,0],[30,0]],"id":52385889},{"atb":[[12,0],[9.8,0],[8.8,0],[14.5,0]],"id":52385903},{"atb":[[5.6,0],[7.2,0],[5.1,0],[6.2,0]],"id":52385904}],"con":true,"img":false}]}
{"op":"mcm","clk":"11449648349","pt":1717312778922,"mc":[{"id":"1.229554907","rc":[{"atb":[[17.5,0],[20,0],[25,0],[15,0]],"id":52385895},{"atb":[[18,0],[21,0],[13,0],[15.5,0]],"id":52385891}],"con":true,"img":false}]}
{"op":"mcm","clk":"11449648371","pt":1717312779536,"mc":[{"id":"1.229554907","rc":[{"atb":[[70,0.38],[38,2.12],[48,1.11],[29,3.74]],"id":52385889},{"atb":[[9.6,9.12],[8.6,13.77],[11.5,4.98],[14,2.01]],"id":52385903},{"atb":[[5,26.16],[5.5,17.44],[6,10.46],[7,4.36]],"id":52385904}],"con":true,"img":false}]}
{"op":"mcm","clk":"11449648377","pt":1717312779642,"mc":[{"id":"1.229554907","rc":[{"atb":[[17,4.9],[19.5,2.83],[24,1.14],[14.5,7.75]],"id":52385895},{"atb":[[17,3.27],[19.5,1.41],[12,9.51],[14.5,5.81]],"id":52385891}],"con":true,"img":false}]}
{"op":"mcm","clk":"11449649059","pt":1717312796724,"mc":[{"id":"1.229554907","rc":[{"atb":[[2.9,0],[3,0],[3.25,0],[3.5,0]],"id":52385909},{"atb":[[70,0],[38,0],[48,0],[29,0]],"id":52385889},{"atb":[[17,0],[19.5,0],[24,0],[14.5,0]],"id":52385895},{"atb":[[17,0],[19.5,0],[12,0],[14.5,0]],"id":52385891},{"atb":[[5,0],[5.5,0],[6,0],[7,0]],"id":52385904}],"con":true,"img":false}]}
{"op":"mcm","clk":"11449649063","pt":1717312796826,"mc":[{"id":"1.229554907","rc":[{"atb":[[9.6,0],[8.6,0],[11.5,0],[14,0]],"id":52385903}],"con":true,"img":false}]}
{"op":"mcm","clk":"11449649087","pt":1717312797444,"mc":[{"id":"1.229554907","rc":[{"atb":[[2.9,55.07],[3,39.24],[3.25,23.25],[3.5,10.46]],"id":52385909},{"atb":[[75,0.36],[40,2.01],[50,1.07],[30,3.61]],"id":52385889},{"atb":[[17.5,4.76],[20,2.75],[25,1.09],[15,7.48]],"id":52385895},{"atb":[[18,3.08],[21,1.31],[13,8.72],[15.5,5.41]],"id":52385891},{"atb":[[5.6,17.06],[7.2,4.22],[5.1,25.52],[6.2,10.06]],"id":52385904}],"con":true,"img":false}]}
{"op":"mcm","clk":"11449649092","pt":1717312797545,"mc":[{"id":"1.229554907","rc":[{"atb":[[12,4.76],[9.8,8.92],[8.8,13.41],[14.5,1.94]],"id":52385903}],"con":true,"img":false}]}
{"op":"mcm","clk":"11449649571","pt":1717312808771,"mc":[{"id":"1.229554907","rc":[{"atb":[[75,0],[40,0],[50,0],[30,0]],"id":52385889},{"atb":[[17.5,0],[20,0],[25,0],[15,0]],"id":52385895},{"atb":[[12,0],[9.8,0],[8.8,0],[14.5,0]],"id":52385903},{"atb":[[5.6,0],[7.2,0],[5.1,0],[6.2,0]],"id":52385904}],"con":true,"img":false}]}
{"op":"mcm","clk":"11449649577","pt":1717312808874,"mc":[{"id":"1.229554907","rc":[{"atb":[[18,0],[21,0],[13,0],[15.5,0]],"id":52385891}],"con":true,"img":false}]}
{"op":"mcm","clk":"11449649606","pt":1717312809440,"mc":[{"id":"1.229554907","rc":[{"atb":[[70,0.38],[38,2.12],[48,1.11],[29,3.74]],"id":52385889},{"atb":[[17,4.9],[19.5,2.83],[24,1.14],[14.5,7.75]],"id":52385895},{"atb":[[9.6,9.12],[8.6,13.77],[11.5,4.98],[14,2.01]],"id":52385903},{"atb":[[5,26.16],[5.5,17.44],[6,10.46],[7,4.36]],"id":52385904}],"con":true,"img":false}]}
{"op":"mcm","clk":"11449649610","pt":1717312809543,"mc":[{"id":"1.229554907","rc":[{"atb":[[17,3.27],[19.5,1.41],[12,9.51],[14.5,5.81]],"id":52385891}],"con":true,"img":false}]}
{"op":"mcm","clk":"11449652383","pt":1717312868036,"mc":[{"id":"1.229554907","rc":[{"atb":[[660,0],[710,0],[760,0],[810,0]],"id":52385893}],"con":true,"img":false}]}
{"op":"mcm","clk":"11449652413","pt":1717312868751,"mc":[{"id":"1.229554907","rc":[{"atb":[[700,0.15],[750,0.1],[800,0.07],[850,0.03]],"id":52385893}],"con":true,"img":false}]}
{"op":"mcm","clk":"11449658175","pt":1717313009689,"mc":[{"id":"1.229554907","rc":[{"atb":[[700,0],[750,0],[800,0],[850,0]],"id":52385893}],"con":true,"img":false}]}
{"op":"mcm","clk":"11449658203","pt":1717313010361,"mc":[{"id":"1.229554907","rc":[{"atb":[[660,0.16],[710,0.11],[760,0.07],[810,0.03]],"id":52385893}],"con":true,"img":false}]}
{"op":"mcm","clk":"11449680084","pt":1717313441226,"mc":[{"id":"1.229554907","rc":[{"atb":[[270,0],[370,0]],"id":52385907},{"atb":[[3.8,0],[3.3,0]],"id":52385909},{"atb":[[550,0],[650,0]],"id":52385918},{"atb":[[350,0],[450,0]],"id":52385886},{"atb":[[410,0],[510,0]],"id":52385920},{"atb":[[4,0],[3.5,0]],"id":52385888},{"atb":[[19,0],[14,0]],"id":52385889},{"atb":[[18,0],[13,0]],"id":52385882},{"atb":[[7.4,0],[9.4,0]],"id":52385884},{"atb":[[590,0],[490,0]],"id":52385917},{"atb":[[9,0],[7,0]],"id":52385895},{"atb":[[18.5,0],[13.5,0]],"id":52385891},{"atb":[[19,0],[28,0]],"id":52385923},{"atb":[[550,0],[650,0]],"id":52385893},{"atb":[[2.56,0],[2.36,0]],"id":52385934},{"atb":[[7.4,0],[9.4,0]],"id":52385903},{"atb":[[17.5,0],[12.5,0]],"id":52385904},{"atb":[[16.5,0],[11.5,0]],"id":52385936},{"atb":[[2.5,0],[2.7,0]],"id":52385931},{"atb":[[3.95,0],[4.9,0]],"id":52385932}],"con":true,"img":false}]}
{"op":"mcm","clk":"11449680671","pt":1717313449233,"mc":[{"id":"1.229554907","rc":[{"atb":[[270,0.9],[370,0.28]],"id":52385907},{"atb":[[3.8,37.33],[3.3,106.04]],"id":52385909},{"atb":[[350,0.7],[450,0.23]],"id":52385886},{"atb":[[550,0.44],[650,0.16]],"id":52385918},{"atb":[[410,0.59],[510,0.2]],"id":52385920},{"atb":[[4,34.84],[3.5,97.56]],"id":52385888},{"atb":[[19,5.8],[14,18.76]],"id":52385889},{"atb":[[18,6.14],[13,20.32]],"id":52385882},{"atb":[[7.4,38.1],[9.4,12.44]],"id":52385884},{"atb":[[590,0.17],[490,0.49]],"id":52385917},{"atb":[[9,13.06],[7,40.65]],"id":52385895},{"atb":[[18.5,5.97],[13.5,19.51]],"id":52385891},{"atb":[[19,13.55],[28,3.87]],"id":52385923},{"atb":[[550,0.44],[650,0.16]],"id":52385893},{"atb":[[2.56,67],[2.36,179.33]],"id":52385934},{"atb":[[7.4,38.1],[9.4,12.44]],"id":52385903},{"atb":[[17.5,6.33],[12.5,21.2]],"id":52385904},{"atb":[[16.5,6.74],[11.5,23.22]],"id":52385936},{"atb":[[2.5,162.6],[2.7,61.48]],"id":52385931},{"atb":[[3.95,82.67],[4.9,26.8]],"id":52385932}],"con":true,"img":false}]}
{"op":"mcm","clk":"11449708582","pt":1717313791007,"mc":[{"id":"1.229554907","rc":[{"atb":[[660,0],[710,0],[760,0],[810,0]],"id":52385893}],"con":true,"img":false}]}
{"op":"mcm","clk":"11449708641","pt":1717313791733,"mc":[{"id":"1.229554907","rc":[{"atb":[[700,0.15],[750,0.1],[800,0.07],[850,0.03]],"id":52385893}],"con":true,"img":false}]}
{"op":"mcm","clk":"11449718238","pt":1717313900704,"mc":[{"id":"1.229554907","rc":[{"atb":[[2.86,0],[3.15,0],[2.96,0],[2.76,0]],"id":52385934},{"atb":[[2.92,0],[3.55,0],[3.3,0],[3.05,0]],"id":52385931},{"atb":[[5.6,0],[7.2,0],[6.2,0],[8.2,0]],"id":52385932}],"con":true,"img":false}]}
{"op":"mcm","clk":"11449718309","pt":1717313901434,"mc":[{"id":"1.229554907","rc":[{"atb":[[2.8,43.6],[2.9,27.54],[3,13.08],[2.7,61.55]],"id":52385934},{"atb":[[3.45,10.68],[3.2,23.78],[2.88,55.66],[2.98,39.64]],"id":52385931},{"atb":[[8,3.74],[5.5,23.25],[6,15.7],[7,8.72]],"id":52385932}],"con":true,"img":false}]}
{"op":"mcm","clk":"11449723853","pt":1717313961672,"mc":[{"id":"1.229554907","rc":[{"atb":[[65,0],[36,0],[46,0],[28,0]],"id":52385882},{"atb":[[700,0],[750,0],[800,0],[850,0]],"id":52385893},{"atb":[[2.8,0],[2.9,0],[3,0],[2.7,0]],"id":52385934},{"atb":[[8,0],[5.5,0],[6,0],[7,0]],"id":52385932}],"con":true,"img":false}]}
{"op":"mcm","clk":"11449723921","pt":1717313962350,"mc":[{"id":"1.229554907","rc":[{"atb":[[34,2.38],[44,1.22],[27,4.02],[60,0.44]],"id":52385882},{"atb":[[660,0.16],[710,0.11],[760,0.07],[810,0.03]],"id":52385893},{"atb":[[2.88,27.83],[2.98,13.21],[2.78,44.09],[2.68,62.28]],"id":52385934},{"atb":[[6.8,9.02],[7.8,3.85],[5.9,16.01],[5.4,23.78]],"id":52385932}],"con":true,"img":false}]}
{"op":"mcm","clk":"11449750449","pt":1717314247810,"mc":[{"id":"1.229554907","rc":[{"atb":[[2.9,0],[3,0],[3.25,0],[3.5,0]],"id":52385909},{"atb":[[17,0],[19.5,0],[12,0],[14.5,0]],"id":52385891},{"atb":[[9.6,0],[8.6,0],[11.5,0],[14,0]],"id":52385903}],"con":true,"img":false}]}
{"op":"mcm","clk":"11449750509","pt":1717314248539,"mc":[{"id":"1.229554907","rc":[{"atb":[[2.9,55.07],[3,39.24],[3.25,23.25],[3.5,10.46]],"id":52385909},{"atb":[[18,3.08],[21,1.31],[13,8.72],[15.5,5.41]],"id":52385891},{"atb":[[12,4.76],[9.8,8.92],[8.8,13.41],[14.5,1.94]],"id":52385903}],"con":true,"img":false}]}
{"op":"mcm","clk":"11449751117","pt":1717314254310,"mc":[{"id":"1.229554907","rc":[{"atb":[[13,0]],"id":52385891}],"con":true,"img":false}]}
{"op":"mcm","clk":"11449751125","pt":1717314254414,"mc":[{"id":"1.229554907","rc":[{"atb":[[18,0],[21,0],[15.5,0]],"id":52385891},{"atb":[[12,0],[9.8,0],[8.8,0],[14.5,0]],"id":52385903}],"con":true,"img":false}]}
{"op":"mcm","clk":"11449751182","pt":1717314255048,"mc":[{"id":"1.229554907","rc":[{"atb":[[12,9.51]],"id":52385891}],"con":true,"img":false}]}
{"op":"mcm","clk":"11449751190","pt":1717314255095,"mc":[{"id":"1.229554907","rc":[{"atb":[[17,3.27],[19.5,1.41],[14.5,5.81]],"id":52385891},{"atb":[[9.6,9.12],[8.6,13.77],[11.5,4.98],[14,2.01]],"id":52385903}],"con":true,"img":false}]}
{"op":"mcm","clk":"11449753588","pt":1717314283343,"mc":[{"id":"1.229554907","rc":[{"atb":[[270,0],[370,0]],"id":52385907},{"atb":[[3.8,0],[3.3,0]],"id":52385909},{"atb":[[350,0],[450,0]],"id":52385886},{"atb":[[550,0],[650,0]],"id":52385918},{"atb":[[4,0],[3.5,0]],"id":52385888},{"atb":[[410,0],[510,0]],"id":52385920},{"atb":[[19,0],[14,0]],"id":52385889},{"atb":[[18,0],[13,0]],"id":52385882},{"atb":[[7.4,0],[9.4,0]],"id":52385884},{"atb":[[590,0],[490,0]],"id":52385917},{"atb":[[9,0],[7,0]],"id":52385895},{"atb":[[18.5,0],[13.5,0]],"id":52385891},{"atb":[[19,0],[28,0]],"id":52385923},{"atb":[[550,0],[650,0]],"id":52385893},{"atb":[[2.56,0],[2.36,0]],"id":52385934},{"atb":[[7.4,0],[9.4,0]],"id":52385903},{"atb":[[16.5,0],[11.5,0]],"id":52385936},{"atb":[[17.5,0],[12.5,0]],"id":52385904},{"atb":[[2.5,0],[2.7,0]],"id":52385931},{"atb":[[3.95,0],[4.9,0]],"id":52385932}],"con":true,"img":false}]}
{"op":"mcm","clk":"11449754582","pt":1717314295554,"mc":[{"id":"1.229554907","rc":[{"atb":[[270,0.9],[370,0.28]],"id":52385907},{"atb":[[3.8,37.33],[3.3,106.04]],"id":52385909},{"atb":[[550,0.44],[650,0.16]],"id":52385918},{"atb":[[350,0.7],[450,0.23]],"id":52385886},{"atb":[[4,34.84],[3.5,97.56]],"id":52385888},{"atb":[[410,0.59],[510,0.2]],"id":52385920},{"atb":[[19,5.8],[14,18.76]],"id":52385889},{"atb":[[18,6.14],[13,20.32]],"id":52385882},{"atb":[[7.4,38.1],[9.4,12.44]],"id":52385884},{"atb":[[590,0.17],[490,0.49]],"id":52385917},{"atb":[[9,13.06],[7,40.65]],"id":52385895},{"atb":[[18.5,5.97],[13.5,19.51]],"id":52385891},{"atb":[[19,13.55],[28,3.87]],"id":52385923},{"atb":[[550,0.44],[650,0.16]],"id":52385893},{"atb":[[2.56,67],[2.36,179.33]],"id":52385934},{"atb":[[7.4,38.1],[9.4,12.44]],"id":52385903},{"atb":[[17.5,6.33],[12.5,21.2]],"id":52385904},{"atb":[[16.5,6.74],[11.5,23.22]],"id":52385936},{"atb":[[2.5,162.6],[2.7,61.48]],"id":52385931},{"atb":[[3.95,82.67],[4.9,26.8]],"id":52385932}],"con":true,"img":false}]}
{"op":"mcm","clk":"11449774367","pt":1717314516947,"mc":[{"id":"1.229554907","rc":[{"atb":[[3.45,0],[3.2,0],[2.88,0],[2.98,0]],"id":52385931}],"con":true,"img":false}]}
{"op":"mcm","clk":"11449774435","pt":1717314517675,"mc":[{"id":"1.229554907","rc":[{"atb":[[2.9,55.07],[3,39.24],[3.25,23.25],[3.5,10.46]],"id":52385931}],"con":true,"img":false}]}
{"op":"mcm","clk":"11449781332","pt":1717314595426,"mc":[{"id":"1.229554907","rc":[{"atb":[[660,0],[710,0],[760,0],[810,0]],"id":52385893},{"atb":[[2.88,0],[2.98,0],[2.78,0],[2.68,0]],"id":52385934}],"con":true,"img":false}]}
{"op":"mcm","clk":"11449781338","pt":1717314595530,"mc":[{"id":"1.229554907","rc":[{"atb":[[6.8,0],[7.8,0],[5.9,0],[5.4,0]],"id":52385932}],"con":true,"img":false}]}
{"op":"mcm","clk":"11449781389","pt":1717314596150,"mc":[{"id":"1.229554907","rc":[{"atb":[[710,0.15],[760,0.1],[810,0.06],[860,0.03]],"id":52385893},{"atb":[[2.74,60.13],[3.1,12.46],[2.84,42.65],[2.94,26.97]],"id":52385934}],"con":true,"img":false}]}
{"op":"mcm","clk":"11449781398","pt":1717314596253,"mc":[{"id":"1.229554907","rc":[{"atb":[[8,3.74],[5.5,23.25],[6,15.7],[7,8.72]],"id":52385932}],"con":true,"img":false}]}
{"op":"mcm","clk":"11449781750","pt":1717314600844,"mc":[{"id":"1.229554907","rc":[{"atb":[[710,0],[760,0],[810,0],[860,0]],"id":52385893}],"con":true,"img":false}]}
{"op":"mcm","clk":"11449781800","pt":1717314601569,"mc":[{"id":"1.229554907","rc":[{"atb":[[660,0.16],[710,0.11],[760,0.07],[810,0.03]],"id":52385893}],"con":true,"img":false}]}
{"op":"mcm","clk":"11449827992","pt":1717315127973,"mc":[{"id":"1.229554907","rc":[{"atb":[[1.04,86.91]],"id":52385907},{"atb":[[1.03,68.17]],"id":52385909},{"atb":[[1.03,155.94]],"id":52385886},{"atb":[[1.03,155.94]],"id":52385918},{"atb":[[1.03,188.32]],"id":52385920},{"atb":[[1.03,68.17]],"id":52385888},{"atb":[[1.03,97.99]],"id":52385889},{"atb":[[1.02,106.51]],"id":52385882},{"atb":[[1.03,166.16]],"id":52385884},{"atb":[[1.04,68.17]],"id":52385917},{"atb":[[1.03,80.95]],"id":52385895},{"atb":[[1.02,102.25]],"id":52385923},{"atb":[[1.03,73.28]],"id":52385891},{"atb":[[1.04,118.44]],"id":52385893},{"atb":[[1.03,137.19]],"id":52385934},{"atb":[[1.03,122.7]],"id":52385903},{"atb":[[1.04,103.11]],"id":52385904},{"atb":[[1.02,137.19]],"id":52385936},{"atb":[[1.02,99.7]],"id":52385931},{"atb":[[1.04,71.58]],"id":52385932}],"con":true,"img":false}]}
{"op":"mcm","clk":"11449837917","pt":1717315160931,"mc":[{"id":"1.229554907","rc":[{"atb":[[270,0],[370,0]],"id":52385907},{"atb":[[3.8,0],[3.3,0]],"id":52385909},{"atb":[[350,0],[450,0]],"id":52385886},{"atb":[[550,0],[650,0]],"id":52385918},{"atb":[[410,0],[510,0]],"id":52385920},{"atb":[[4,0],[3.5,0]],"id":52385888},{"atb":[[19,0],[14,0]],"id":52385889},{"atb":[[18,0],[13,0]],"id":52385882},{"atb":[[7.4,0],[9.4,0]],"id":52385884},{"atb":[[590,0],[490,0]],"id":52385917},{"atb":[[9,0],[7,0]],"id":52385895},{"atb":[[19,0],[28,0]],"id":52385923},{"atb":[[18.5,0],[13.5,0]],"id":52385891},{"atb":[[550,0],[650,0]],"id":52385893},{"atb":[[2.56,0],[2.36,0]],"id":52385934},{"atb":[[7.4,0],[9.4,0]],"id":52385903},{"atb":[[16.5,0],[11.5,0]],"id":52385936},{"atb":[[17.5,0],[12.5,0]],"id":52385904},{"atb":[[2.5,0],[2.7,0]],"id":52385931},{"atb":[[3.95,0],[4.9,0]],"id":52385932}],"con":true,"img":false}]}
{"op":"mcm","clk":"11449843010","pt":1717315211575,"mc":[{"id":"1.229554907","rc":[{"atb":[[270,0.9],[370,0.28]],"id":52385907},{"atb":[[3.8,37.33],[3.3,106.04]],"id":52385909},{"atb":[[350,0.7],[450,0.23]],"id":52385886},{"atb":[[550,0.44],[650,0.16]],"id":52385918},{"atb":[[4,34.84],[3.5,97.56]],"id":52385888},{"atb":[[410,0.59],[510,0.2]],"id":52385920},{"atb":[[19,5.8],[14,18.76]],"id":52385889},{"atb":[[18,6.14],[13,20.32]],"id":52385882},{"atb":[[7.4,38.1],[9.4,12.44]],"id":52385884},{"atb":[[590,0.17],[490,0.49]],"id":52385917},{"atb":[[9,13.06],[7,40.65]],"id":52385895},{"atb":[[18.5,5.97],[13.5,19.51]],"id":52385891},{"atb":[[19,13.55],[28,3.87]],"id":52385923},{"atb":[[550,0.44],[650,0.16]],"id":52385893},{"atb":[[2.56,67],[2.36,179.33]],"id":52385934},{"atb":[[7.4,38.1],[9.4,12.44]],"id":52385903},{"atb":[[16.5,6.74],[11.5,23.22]],"id":52385936},{"atb":[[17.5,6.33],[12.5,21.2]],"id":52385904},{"atb":[[2.5,162.6],[2.7,61.48]],"id":52385931},{"atb":[[3.95,82.67],[4.9,26.8]],"id":52385932}],"con":true,"img":false}]}
{"op":"mcm","clk":"11449888951","pt":1717315666838,"mc":[{"id":"1.229554907","rc":[{"atb":[[140,0],[70,0],[190,0],[95,0]],"id":52385923},{"atb":[[660,0],[710,0],[760,0],[810,0]],"id":52385893},{"atb":[[2.9,0],[3,0],[3.25,0],[3.5,0]],"id":52385931}],"con":true,"img":false}]}
{"op":"mcm","clk":"11449889041","pt":1717315667717,"mc":[{"id":"1.229554907","rc":[{"atb":[[170,0.16],[85,0.94],[120,0.44],[60,1.77]],"id":52385923},{"atb":[[580,0.18],[630,0.13],[680,0.08],[730,0.04]],"id":52385893},{"atb":[[3.6,10.06],[3.1,37.37],[3.35,22.26],[2.94,53.93]],"id":52385931}],"con":true,"img":false}]}
{"op":"mcm","clk":"11449893648","pt":1717315712569,"mc":[{"id":"1.229554907","rc":[{"atb":[[270,0],[370,0]],"id":52385907},{"atb":[[3.8,0],[3.3,0]],"id":52385909},{"atb":[[550,0],[650,0]],"id":52385918},{"atb":[[350,0],[450,0]],"id":52385886},{"atb":[[4,0],[3.5,0]],"id":52385888},{"atb":[[410,0],[510,0]],"id":52385920},{"atb":[[19,0],[14,0]],"id":52385889},{"atb":[[18,0],[13,0]],"id":52385882},{"atb":[[7.4,0],[9.4,0]],"id":52385884},{"atb":[[590,0],[490,0]],"id":52385917},{"atb":[[9,0],[7,0]],"id":52385895},{"atb":[[19,0],[28,0]],"id":52385923},{"atb":[[18.5,0],[13.5,0]],"id":52385891},{"atb":[[550,0],[650,0]],"id":52385893},{"atb":[[2.56,0],[2.36,0]],"id":52385934},{"atb":[[7.4,0],[9.4,0]],"id":52385903},{"atb":[[17.5,0],[12.5,0]],"id":52385904},{"atb":[[16.5,0],[11.5,0]],"id":52385936},{"atb":[[2.5,0],[2.7,0]],"id":52385931},{"atb":[[3.95,0],[4.9,0]],"id":52385932}],"con":true,"img":false}]}
{"op":"mcm","clk":"11449897727","pt":1717315750469,"mc":[{"id":"1.229554907","rc":[{"atb":[[2.9,0],[3,0],[3.25,0],[3.5,0]],"id":52385909},{"atb":[[12,0]],"id":52385891}],"con":true,"img":false}]}
{"op":"mcm","clk":"11449897799","pt":1717315751203,"mc":[{"id":"1.229554907","rc":[{"atb":[[2.9,55.07],[3,39.24],[3.25,23.25],[3.5,10.46]],"id":52385909},{"atb":[[13,8.72]],"id":52385891}],"con":true,"img":false}]}
{"op":"mcm","clk":"11449898343","pt":1717315756106,"mc":[{"id":"1.229554907","rc":[{"atb":[[13,0]],"id":52385891}],"con":true,"img":false}]}
{"op":"mcm","clk":"11449898420","pt":1717315756784,"mc":[{"id":"1.229554907","rc":[{"atb":[[12,9.51]],"id":52385891}],"con":true,"img":false}]}
{"op":"mcm","clk":"11449899234","pt":1717315764715,"mc":[{"id":"1.229554907","rc":[{"atb":[[160,0.65],[80,3.08]],"id":52385907},{"atb":[[3.2,110.86],[3.7,38.71]],"id":52385909},{"atb":[[130,1.88],[230,0.45]],"id":52385886},{"atb":[[550,0.44],[650,0.16]],"id":52385918},{"atb":[[4,34.84],[3.5,97.56]],"id":52385888},{"atb":[[270,0.38],[170,1.44]],"id":52385920},{"atb":[[18.5,5.97],[13.5,19.51]],"id":52385889},{"atb":[[18,6.14],[13,20.32]],"id":52385882},{"atb":[[7.2,39.33],[9.2,12.74]],"id":52385884},{"atb":[[330,0.31],[230,1.06]],"id":52385917},{"atb":[[9,13.06],[7,40.65]],"id":52385895},{"atb":[[18,6.14],[13,20.32]],"id":52385891},{"atb":[[16.5,15.73],[23,4.75]],"id":52385923},{"atb":[[550,0.44],[650,0.16]],"id":52385893},{"atb":[[2.4,174.21],[2.6,65.33]],"id":52385934},{"atb":[[9,13.06],[7,40.65]],"id":52385903},{"atb":[[16.5,6.74],[11.5,23.22]],"id":52385904},{"atb":[[10,27.1],[15,7.46]],"id":52385936},{"atb":[[2.54,158.38],[2.74,60.07]],"id":52385931},{"atb":[[4,81.3],[5,26.13]],"id":52385932}],"con":true,"img":false}]}
{"op":"mcm","clk":"11449909635","pt":1717315865654,"mc":[{"id":"1.229554907","rc":[{"atb":[[8.6,0],[5.8,0],[7.6,0],[6.6,0]],"id":52385888},{"atb":[[170,0],[85,0],[120,0],[60,0]],"id":52385923},{"atb":[[580,0],[630,0],[680,0],[730,0]],"id":52385893}],"con":true,"img":false}]}
{"op":"mcm","clk":"11449909724","pt":1717315866335,"mc":[{"id":"1.229554907","rc":[{"atb":[[6.8,13.53],[8.8,3.35],[7.8,7.7],[5.9,21.36]],"id":52385888},{"atb":[[150,0.18],[75,1.06],[100,0.53],[50,2.13]],"id":52385923},{"atb":[[520,0.2],[570,0.14],[620,0.08],[670,0.04]],"id":52385893}],"con":true,"img":false}]}
{"op":"mcm","clk":"11449924790","pt":1717316009617,"mc":[{"id":"1.229554907","rc":[{"atb":[[160,0],[80,0]],"id":52385907},{"atb":[[3.2,0],[3.7,0]],"id":52385909},{"atb":[[550,0],[650,0]],"id":52385918},{"atb":[[130,0],[230,0]],"id":52385886},{"atb":[[4,0],[3.5,0]],"id":52385888},{"atb":[[270,0],[170,0]],"id":52385920},{"atb":[[18.5,0],[13.5,0]],"id":52385889},{"atb":[[18,0],[13,0]],"id":52385882},{"atb":[[7.2,0],[9.2,0]],"id":52385884},{"atb":[[330,0],[230,0]],"id":52385917},{"atb":[[9,0],[7,0]],"id":52385895},{"atb":[[16.5,0],[23,0]],"id":52385923},{"atb":[[18,0],[13,0]],"id":52385891},{"atb":[[550,0],[650,0]],"id":52385893},{"atb":[[2.4,0],[2.6,0]],"id":52385934},{"atb":[[9,0],[7,0]],"id":52385903},{"atb":[[10,0],[15,0]],"id":52385936},{"atb":[[16.5,0],[11.5,0]],"id":52385904},{"atb":[[2.54,0],[2.74,0]],"id":52385931},{"atb":[[4,0],[5,0]],"id":52385932}],"con":true,"img":false}]}
{"op":"mcm","clk":"11449928213","pt":1717316044489,"mc":[{"id":"1.229554907","rc":[{"atb":[[130,1.88],[230,0.45]],"id":52385886},{"atb":[[4,34.84],[3.5,97.56]],"id":52385888},{"atb":[[18.5,5.97],[13.5,19.51]],"id":52385889},{"atb":[[18,6.14],[13,20.32]],"id":52385882},{"atb":[[7.2,39.33],[9.2,12.74]],"id":52385884},{"atb":[[9,13.06],[7,40.65]],"id":52385895},{"atb":[[18,6.14],[13,20.32]],"id":52385891},{"atb":[[550,0.44],[650,0.16]],"id":52385893},{"atb":[[9,13.06],[7,40.65]],"id":52385903},{"atb":[[16.5,6.74],[11.5,23.22]],"id":52385904}],"con":true,"img":false}]}
{"op":"mcm","clk":"11449928225","pt":1717316044601,"mc":[{"id":"1.229554907","rc":[{"atb":[[160,0.65],[80,3.08]],"id":52385907},{"atb":[[3.2,110.86],[3.7,38.71]],"id":52385909},{"atb":[[550,0.44],[650,0.16]],"id":52385918},{"atb":[[270,0.38],[170,1.44]],"id":52385920},{"atb":[[330,0.31],[230,1.06]],"id":52385917},{"atb":[[16.5,15.73],[23,4.75]],"id":52385923},{"atb":[[2.4,174.21],[2.6,65.33]],"id":52385934},{"atb":[[10,27.1],[15,7.46]],"id":52385936},{"atb":[[2.54,158.38],[2.74,60.07]],"id":52385931},{"atb":[[4,81.3],[5,26.13]],"id":52385932}],"con":true,"img":false}]}
{"op":"mcm","clk":"11449934911","pt":1717316117249,"mc":[{"id":"1.229554907","rc":[{"atb":[[2.9,0],[3,0],[3.25,0],[3.5,0]],"id":52385909}],"con":true,"img":false}]}
{"op":"mcm","clk":"11449934982","pt":1717316117974,"mc":[{"id":"1.229554907","rc":[{"atb":[[2.92,54.5],[3.55,10.26],[3.3,22.75],[3.05,38.28]],"id":52385909}],"con":true,"img":false}]}
{"op":"mcm","clk":"11449941457","pt":1717316186881,"mc":[{"id":"1.229554907","rc":[{"atb":[[12,0]],"id":52385891}],"con":true,"img":false}]}
{"op":"mcm","clk":"11449941519","pt":1717316187556,"mc":[{"id":"1.229554907","rc":[{"atb":[[12.5,9.1]],"id":52385891}],"con":true,"img":false}]}
{"op":"mcm","clk":"11449952451","pt":1717316311642,"mc":[{"id":"1.229554907","rc":[{"atb":[[2.92,0],[3.55,0],[3.3,0],[3.05,0]],"id":52385909},{"atb":[[70,0],[38,0],[48,0],[29,0]],"id":52385889},{"atb":[[34,0],[44,0],[27,0],[60,0]],"id":52385882},{"atb":[[17,0],[19.5,0],[24,0],[14.5,0]],"id":52385895},{"atb":[[12.5,0]],"id":52385891},{"atb":[[8,0],[5.5,0],[6,0],[7,0]],"id":52385932}],"con":true,"img":false}]}
{"op":"mcm","clk":"11449952508","pt":1717316312313,"mc":[{"id":"1.229554907","rc":[{"atb":[[40,0.67],[20,5.51],[25,3.27],[30,1.81]],"id":52385882},{"atb":[[7.2,16.88],[9.2,6.38],[10.5,2.75],[8.2,10.9]],"id":52385895},{"atb":[[12,9.51]],"id":52385891},{"atb":[[3.45,21.36],[3.2,35.67],[3.7,9.69],[2.98,52.85]],"id":52385932}],"con":true,"img":false}]}
{"op":"mcm","clk":"11449952515","pt":1717316312419,"mc":[{"id":"1.229554907","rc":[{"atb":[[6.8,4.51],[4.9,26.83],[5.9,10.68],[5.4,17.84]],"id":52385909},{"atb":[[16.5,6.75],[19,4.36],[23,2.38],[28,0.97]],"id":52385889}],"con":true,"img":false}]}
{"op":"mcm","clk":"11449959210","pt":1717316398480,"mc":[{"id":"1.229554907","rc":[{"atb":[[16.5,0],[19,0],[23,0],[28,0]],"id":52385889},{"atb":[[40,0],[20,0],[25,0],[30,0]],"id":52385882}],"con":true,"img":false}]}
{"op":"mcm","clk":"11449959268","pt":1717316399208,"mc":[{"id":"1.229554907","rc":[{"atb":[[16,6.97],[18.5,10.46],[22,2.49],[27,1]],"id":52385889},{"atb":[[38,0.71],[19.5,5.66],[24,3.41],[29,1.87]],"id":52385882}],"con":true,"img":false}]}
{"op":"mcm","clk":"11449959396","pt":1717316400521,"mc":[{"id":"1.229554907","rc":[{"atb":[[85,2]],"id":52385907},{"atb":[[3.35,42.55]],"id":52385909},{"atl":[[310,2]],"id":52385909},{"atb":[[500,2]],"id":52385918},{"atb":[[100,2]],"id":52385886},{"atb":[[190,2]],"id":52385920},{"atb":[[4.3,30.3]],"id":52385888},{"atl":[[350,2]],"id":52385888},{"atb":[[27,3.5]],"id":52385889},{"atb":[[29,5.29]],"id":52385882},{"atb":[[11,10]],"id":52385884},{"atb":[[230,3.06]],"id":52385917},{"atb":[[1.35,80.95]],"id":52385895},{"atb":[[19.5,4.69]],"id":52385891},{"atb":[[70,2]],"id":52385923},{"atb":[[330,2]],"id":52385893},{"atb":[[1.52,137.2]],"id":52385934},{"atl":[[55,2]],"id":52385934},{"atb":[[10.5,10.53]],"id":52385903},{"atb":[[14.5,7.41]],"id":52385936},{"atb":[[17,6.25]],"id":52385904},{"atb":[[1.78,99.7]],"id":52385931},{"atl":[[70,2]],"id":52385931},{"atb":[[1.35,71.58]],"id":52385932},{"atl":[[270,2]],"id":52385932}],"con":true,"img":false}]}
{"op":"mcm","clk":"11449959549","pt":1717316402495,"mc":[{"id":"1.229554907","rc":[{"atb":[[4.3,0],[3.85,35.09]],"id":52385888},{"atb":[[1.78,0],[1.69,107.88]],"id":52385931}],"con":true,"img":false}]}
{"op":"mcm","clk":"11449959578","pt":1717316402809,"mc":[{"id":"1.229554907","rc":[{"atb":[[170,0],[85,0],[220,0],[120,0]],"id":52385886},{"atb":[[300,0],[350,0],[400,0],[450,0]],"id":52385917},{"atb":[[150,0],[75,0],[100,0],[50,0]],"id":52385923}],"con":true,"img":false}]}
{"op":"mcm","clk":"11449959589","pt":1717316402917,"mc":[{"id":"1.229554907","rc":[{"atb":[[70,0],[24,4.35]],"id":52385923},{"atb":[[2.74,0],[3.1,0],[2.84,0],[2.94,0]],"id":52385934}],"con":true,"img":false}]}
{"op":"mcm","clk":"11449959618","pt":1717316403229,"mc":[{"id":"1.229554907","rc":[{"atb":[[520,0],[570,0],[620,0],[670,0]],"id":52385893}],"con":true,"img":false}]}
{"op":"mcm","clk":"11449959648","pt":1717316403496,"mc":[{"id":"1.229554907","rc":[{"atb":[[160,0.33],[80,1.32],[210,0.13],[110,0.72]],"id":52385886},{"atb":[[290,0.36],[340,0.23],[390,0.14],[440,0.06]],"id":52385917},{"atb":[[160,0.16],[80,0.99],[110,0.48],[55,1.94]],"id":52385923}],"con":true,"img":false}]}
{"op":"mcm","clk":"11449959659","pt":1717316403593,"mc":[{"id":"1.229554907","rc":[{"atb":[[75,2],[24,0]],"id":52385923},{"atb":[[2.86,42.19],[3.15,12.17],[2.96,26.69],[2.76,59.45]],"id":52385934}],"con":true,"img":false}]}
{"op":"mcm","clk":"11449959686","pt":1717316403905,"mc":[{"id":"1.229554907","rc":[{"atb":[[560,0.19],[610,0.13],[660,0.08],[710,0.04]],"id":52385893}],"con":true,"img":false}]}
{"op":"mcm","clk":"11449959966","pt":1717316407417,"mc":[{"id":"1.229554907","rc":[{"atb":[[26,4]],"id":52385882},{"atb":[[1.58,137.2],[1.52,0]],"id":52385934}],"con":true,"img":false}]}
{"op":"mcm","clk":"11449959975","pt":1717316407522,"mc":[{"id":"1.229554907","rc":[{"atb":[[29,1.87]],"id":52385882}],"con":true,"img":false}]}
{"op":"mcm","clk":"11449960004","pt":1717316407789,"mc":[{"id":"1.229554907","rc":[{"atb":[[560,0],[610,0],[660,0],[710,0]],"id":52385893},{"atb":[[2.86,0],[3.15,0],[2.96,0],[2.76,0]],"id":52385934}],"con":true,"img":false}]}
{"op":"mcm","clk":"11449960091","pt":1717316408820,"mc":[{"id":"1.229554907","rc":[{"atb":[[550,0.63],[600,0.13],[650,0.24],[700,0.04]],"id":52385893},{"atb":[[3.2,11.89],[2.88,41.74],[2.98,26.43],[2.78,58.78]],"id":52385934}],"con":true,"img":false}]}
{"op":"mcm","clk":"11449960340","pt":1717316411895,"mc":[{"id":"1.229554907","rc":[{"atb":[[550,0.44],[600,0],[650,0.16],[700,0]],"id":52385893}],"con":true,"img":false}]}
{"op":"mcm","clk":"11449960407","pt":1717316412625,"mc":[{"id":"1.229554907","rc":[{"atb":[[550,0.63],[600,0.13],[650,0.24],[700,0.04]],"id":52385893}],"con":true,"img":false}]}
{"op":"mcm","clk":"11449961496","pt":1717316425424,"mc":[{"id":"1.229554907","rc":[{"atb":[[550,0.44],[600,0],[650,0.16],[700,0]],"id":52385893}],"con":true,"img":false}]}
{"op":"mcm","clk":"11449961558","pt":1717316426154,"mc":[{"id":"1.229554907","rc":[{"atb":[[560,0.19],[610,0.13],[660,0.08],[710,0.04]],"id":52385893}],"con":true,"img":false}]}
{"op":"mcm","clk":"11449962024","pt":1717316431947,"mc":[{"id":"1.229554907","rc":[{"atb":[[560,0],[610,0],[660,0],[710,0]],"id":52385893}],"con":true,"img":false}]}
{"op":"mcm","clk":"11449962072","pt":1717316432666,"mc":[{"id":"1.229554907","rc":[{"atb":[[550,0.63],[600,0.13],[650,0.24],[700,0.04]],"id":52385893}],"con":true,"img":false}]}
{"op":"mcm","clk":"11449965993","pt":1717316485213,"mc":[{"id":"1.229554907","rc":[{"atb":[[85,0],[100,2]],"id":52385907},{"atb":[[580,2],[500,0]],"id":52385918}],"con":true,"img":false}]}
{"op":"mcm","clk":"11449966022","pt":1717316485625,"mc":[{"id":"1.229554907","rc":[{"atb":[[160,0],[80,0],[110,0],[55,0]],"id":52385923}],"con":true,"img":false}]}
{"op":"mcm","clk":"11449966029","pt":1717316485731,"mc":[{"id":"1.229554907","rc":[{"atb":[[24,4.35]],"id":52385923}],"con":true,"img":false}]}
{"op":"mcm","clk":"11449966036","pt":1717316485787,"mc":[{"id":"1.229554907","rc":[{"atb":[[75,0]],"id":52385923}],"con":true,"img":false}]}
{"op":"mcm","clk":"11449966062","pt":1717316486300,"mc":[{"id":"1.229554907","rc":[{"atb":[[170,0.16],[85,0.94],[120,0.44],[60,1.77]],"id":52385923}],"con":true,"img":false}]}
{"op":"mcm","clk":"11449967837","pt":1717316511954,"mc":[{"id":"1.229554907","rc":[{"atb":[[17,0],[19.5,0],[24,0],[14.5,0]],"id":52385884},{"atb":[[3.2,0],[2.88,0],[2.98,0],[2.78,0]],"id":52385934},{"atb":[[3.6,0],[3.1,0],[3.35,0],[2.94,0]],"id":52385931}],"con":true,"img":false}]}
{"op":"mcm","clk":"11449967848","pt":1717316512007,"mc":[{"id":"1.229554907","rc":[{"atb":[[11,0],[9.4,11.9]],"id":52385884}],"con":true,"img":false}]}
{"op":"mcm","clk":"11449967890","pt":1717316512628,"mc":[{"id":"1.229554907","rc":[{"atb":[[16,5.23],[18.5,2.99],[22,1.25],[13.5,8.37]],"id":52385884},{"atb":[[2.82,14.37],[2.72,30.42],[2.52,68.84],[2.62,48.44]],"id":52385934},{"atb":[[2.86,56.26],[3.4,10.9],[3.15,24.33],[2.96,40.04]],"id":52385931}],"con":true,"img":false}]}
{"op":"mcm","clk":"11449968458","pt":1717316522039,"mc":[{"id":"1.229554907","rc":[{"atb":[[80,2],[24,0]],"id":52385923}],"con":true,"img":false}]}
{"op":"mcm","clk":"11449970478","pt":1717316552402,"mc":[{"id":"1.229554907","rc":[{"atb":[[160,0],[80,0]],"id":52385907},{"atb":[[3.2,0],[3.7,0]],"id":52385909},{"atb":[[550,0],[650,0]],"id":52385918},{"atb":[[130,0],[230,0]],"id":52385886},{"atb":[[4,0],[3.5,0]],"id":52385888},{"atb":[[270,0],[170,0]],"id":52385920},{"atb":[[18.5,4.48],[13.5,0]],"id":52385889},{"atb":[[18,0],[13,0]],"id":52385882},{"atb":[[7.2,0],[9.2,0]],"id":52385884},{"atb":[[330,0],[230,2]],"id":52385917},{"atb":[[9,0],[7,0]],"id":52385895},{"atb":[[16.5,0],[23,0]],"id":52385923},{"atb":[[18,0],[13,0]],"id":52385891},{"atb":[[550,0.19],[650,0.08]],"id":52385893},{"atb":[[2.4,0],[2.6,0]],"id":52385934},{"atb":[[9,0],[7,0]],"id":52385903},{"atb":[[16.5,0],[11.5,0]],"id":52385904},{"atb":[[10,0],[15,0]],"id":52385936},{"atb":[[2.54,0],[2.74,0]],"id":52385931},{"atb":[[4,0],[5,0]],"id":52385932}],"con":true,"img":false}]}
{"op":"mcm","clk":"11449970486","pt":1717316552457,"mc":[{"id":"1.229554907","rc":[{"atb":[[17,0],[7.2,12.5]],"id":52385904}],"con":true,"img":false}]}
{"op":"mcm","clk":"11449971667","pt":1717316571229,"mc":[{"id":"1.229554907","rc":[{"atb":[[160,0.65],[80,3.08]],"id":52385907},{"atb":[[3.2,110.86],[3.7,38.71]],"id":52385909},{"atb":[[550,0.44],[650,0.16]],"id":52385918},{"atb":[[130,1.88],[230,0.45]],"id":52385886},{"atb":[[4,34.84],[3.5,97.56]],"id":52385888},{"atb":[[270,0.38],[170,1.44]],"id":52385920},{"atb":[[18.5,10.46],[13.5,19.51]],"id":52385889},{"atb":[[18,6.14],[13,20.32]],"id":52385882},{"atb":[[7.2,39.33],[9.2,12.74]],"id":52385884},{"atb":[[330,0.31],[230,3.06]],"id":52385917},{"atb":[[9,13.06],[7,40.65]],"id":52385895},{"atb":[[18,6.14],[13,20.32]],"id":52385891},{"atb":[[16.5,15.73],[23,4.75]],"id":52385923},{"atb":[[550,0.63],[650,0.24]],"id":52385893},{"atb":[[2.4,174.21],[2.6,65.33]],"id":52385934},{"atb":[[9,13.06],[7,40.65]],"id":52385903},{"atb":[[16.5,6.74],[11.5,23.22]],"id":52385904},{"atb":[[10,27.1],[15,7.46]],"id":52385936},{"atb":[[2.54,158.38],[2.74,60.07]],"id":52385931},{"atb":[[4,81.3],[5,26.13]],"id":52385932}],"con":true,"img":false}]}
{"op":"mcm","clk":"11449971674","pt":1717316571282,"mc":[{"id":"1.229554907","rc":[{"atb":[[17,6.25]],"id":52385904}],"con":true,"img":false}]}
{"op":"mcm","clk":"11449971679","pt":1717316571382,"mc":[{"id":"1.229554907","rc":[{"atb":[[7.2,0]],"id":52385904}],"con":true,"img":false}]}
{"op":"mcm","clk":"11449980084","pt":1717316686828,"mc":[{"id":"1.229554907","rc":[{"atb":[[7.2,0],[9.2,0],[10.5,0],[8.2,0]],"id":52385895},{"atb":[[12,0]],"id":52385891},{"atb":[[3.45,0],[3.2,0],[3.7,0],[2.98,0]],"id":52385932}],"con":true,"img":false}]}
{"op":"mcm","clk":"11449980092","pt":1717316686929,"mc":[{"id":"1.229554907","rc":[{"atb":[[4.9,0],[5.9,0],[5.4,0]],"id":52385909}],"con":true,"img":false}]}
{"op":"mcm","clk":"11449980098","pt":1717316687031,"mc":[{"id":"1.229554907","rc":[{"atb":[[6.8,0]],"id":52385909}],"con":true,"img":false}]}
{"op":"mcm","clk":"11449980104","pt":1717316687132,"mc":[{"id":"1.229554907","rc":[{"atb":[[3.35,0],[3.5,40]],"id":52385909}],"con":true,"img":false}]}
{"op":"mcm","clk":"11449980133","pt":1717316687547,"mc":[{"id":"1.229554907","rc":[{"atb":[[16,6.97],[18.5,4.48],[22,2.49],[27,1]],"id":52385895},{"atb":[[30,3.61]],"id":52385891},{"atb":[[5.6,22.75],[7.2,8.44],[6.2,15.09],[8.2,3.63]],"id":52385932}],"con":true,"img":false}]}
{"op":"mcm","clk":"11449980142","pt":1717316687707,"mc":[{"id":"1.229554907","rc":[{"atb":[[5.6,17.06],[5.1,25.52],[6.2,10.06]],"id":52385909},{"atb":[[32,3.23],[19.5,1.41]],"id":52385891}],"con":true,"img":false}]}
{"op":"mcm","clk":"11449980148","pt":1717316687766,"mc":[{"id":"1.229554907","rc":[{"atb":[[7.2,4.22]],"id":52385909}],"con":true,"img":false}]}
{"op":"mcm","clk":"11449989453","pt":1717316817312,"mc":[{"id":"1.229554907","rc":[{"atb":[[520,2]],"id":52385918}],"con":true,"img":false}]}
{"op":"mcm","clk":"11449989458","pt":1717316817414,"mc":[{"id":"1.229554907","rc":[{"atb":[[580,0]],"id":52385918}],"con":true,"img":false}]}
{"op":"mcm","clk":"11449989470","pt":1717316817618,"mc":[{"id":"1.229554907","rc":[{"atb":[[170,0],[85,0],[120,0],[60,0]],"id":52385923}],"con":true,"img":false}]}
{"op":"mcm","clk":"11449989478","pt":1717316817679,"mc":[{"id":"1.229554907","rc":[{"atb":[[80,0],[24,4.35]],"id":52385923}],"con":true,"img":false}]}
{"op":"mcm","clk":"11449989531","pt":1717316818296,"mc":[{"id":"1.229554907","rc":[{"atb":[[160,0.16],[80,0.99],[110,0.48],[55,1.94]],"id":52385923}],"con":true,"img":false}]}
{"op":"mcm","clk":"11449989542","pt":1717316818411,"mc":[{"id":"1.229554907","rc":[{"atb":[[75,2],[24,0]],"id":52385923}],"con":true,"img":false}]}
{"op":"mcm","clk":"11449999409","pt":1717316938929,"mc":[{"id":"1.229554907","rc":[{"atb":[[160,0],[80,0]],"id":52385907},{"atb":[[3.2,0],[3.7,0]],"id":52385909},{"atb":[[550,0],[650,0]],"id":52385918},{"atb":[[130,0],[230,0]],"id":52385886},{"atb":[[4,0],[3.5,0]],"id":52385888},{"atb":[[270,0],[170,0]],"id":52385920},{"atb":[[18.5,4.48],[13.5,0]],"id":52385889},{"atb":[[18,0],[13,0]],"id":52385882},{"atb":[[7.2,0],[9.2,0]],"id":52385884},{"atb":[[330,0],[230,2]],"id":52385917},{"atb":[[9,0],[7,0]],"id":52385895},{"atb":[[16.5,0],[23,0]],"id":52385923},{"atb":[[18,0],[13,0]],"id":52385891},{"atb":[[550,0.19],[650,0.08]],"id":52385893},{"atb":[[2.4,0],[2.6,0]],"id":52385934},{"atb":[[9,0],[7,0]],"id":52385903},{"atb":[[16.5,0],[11.5,0]],"id":52385904},{"atb":[[10,0],[15,0]],"id":52385936},{"atb":[[2.54,0],[2.74,0]],"id":52385931},{"atb":[[4,0],[5,0]],"id":52385932}],"con":true,"img":false}]}
{"op":"mcm","clk":"11449999418","pt":1717316939030,"mc":[{"id":"1.229554907","rc":[{"atb":[[7.2,12.5]],"id":52385904}],"con":true,"img":false}]}
{"op":"mcm","clk":"11449999428","pt":1717316939135,"mc":[{"id":"1.229554907","rc":[{"atb":[[17,0]],"id":52385904}],"con":true,"img":false}]}
{"op":"mcm","clk":"11450000416","pt":1717316950116,"mc":[{"id":"1.229554907","rc":[{"atb":[[160,0.65],[80,3.08]],"id":52385907},{"atb":[[3.2,110.86],[3.7,38.71]],"id":52385909},{"atb":[[550,0.44],[650,0.16]],"id":52385918},{"atb":[[130,1.88],[230,0.45]],"id":52385886},{"atb":[[270,0.38],[170,1.44]],"id":52385920},{"atb":[[4,34.84],[3.5,97.56]],"id":52385888},{"atb":[[18.5,10.46],[13.5,19.51]],"id":52385889},{"atb":[[18,6.14],[13,20.32]],"id":52385882},{"atb":[[7.2,39.33],[9.2,12.74]],"id":52385884},{"atb":[[330,0.31],[230,3.06]],"id":52385917},{"atb":[[9,13.06],[7,40.65]],"id":52385895},{"atb":[[18,6.14],[13,20.32]],"id":52385891},{"atb":[[16.5,15.73],[23,4.75]],"id":52385923},{"atb":[[550,0.63],[650,0.24]],"id":52385893},{"atb":[[2.4,174.21],[2.6,65.33]],"id":52385934},{"atb":[[9,13.06],[7,40.65]],"id":52385903},{"atb":[[16.5,6.74],[11.5,23.22]],"id":52385904},{"atb":[[10,27.1],[15,7.46]],"id":52385936},{"atb":[[2.54,158.38],[2.74,60.07]],"id":52385931},{"atb":[[4,81.3],[5,26.13]],"id":52385932}],"con":true,"img":false}]}
{"op":"mcm","clk":"11450000436","pt":1717316950306,"mc":[{"id":"1.229554907","rc":[{"atb":[[7.2,0],[17,6.25]],"id":52385904}],"con":true,"img":false}]}
{"op":"mcm","clk":"11450013144","pt":1717317085441,"mc":[{"id":"1.229554907","rc":[{"atb":[[4.3,30.3],[3.85,0]],"id":52385888},{"atb":[[26,0],[29,5.29]],"id":52385882},{"atb":[[11,10],[9.4,0]],"id":52385884},{"atb":[[1.58,0],[1.52,137.2]],"id":52385934},{"atb":[[1.78,103.79],[1.69,0]],"id":52385931}],"con":true,"img":false}]}
{"op":"mcm","clk":"11450013170","pt":1717317085747,"mc":[{"id":"1.229554907","rc":[{"atb":[[16,0],[18.5,0],[22,0],[13.5,0]],"id":52385884},{"atb":[[30,0]],"id":52385891},{"atb":[[550,0.44],[600,0],[650,0.16],[700,0]],"id":52385893},{"atb":[[2.86,0],[3.4,0],[3.15,0],[2.96,0]],"id":52385931},{"atb":[[5.6,0],[7.2,0],[6.2,0],[8.2,0]],"id":52385932}],"con":true,"img":false}]}
{"op":"mcm","clk":"11450013184","pt":1717317085904,"mc":[{"id":"1.229554907","rc":[{"atb":[[19.5,6.82]],"id":52385891}],"con":true,"img":false}]}
{"op":"mcm","clk":"11450013196","pt":1717317086007,"mc":[{"id":"1.229554907","rc":[{"atb":[[32,0]],"id":52385891}],"con":true,"img":false}]}
{"op":"mcm","clk":"11450013232","pt":1717317086418,"mc":[{"id":"1.229554907","rc":[{"atb":[[16.5,5.06],[19,2.91],[23,1.19],[14,8.05]],"id":52385884},{"atb":[[29,3.74]],"id":52385891},{"atb":[[520,0.2],[570,0.14],[620,0.08],[670,0.04]],"id":52385893},{"atb":[[3.6,10.06],[3.1,37.37],[3.35,22.26],[2.94,53.93]],"id":52385931},{"atb":[[8,3.74],[5.5,23.25],[6,15.7],[7,8.72]],"id":52385932}],"con":true,"img":false}]}
{"op":"mcm","clk":"11450013236","pt":1717317086520,"mc":[{"id":"1.229554907","rc":[{"atb":[[30,3.45]],"id":52385891}],"con":true,"img":false}]}
{"op":"mcm","clk":"11450013243","pt":1717317086625,"mc":[{"id":"1.229554907","rc":[{"atb":[[19.5,1.41]],"id":52385891}],"con":true,"img":false}]}
{"op":"mcm","clk":"11450013810","pt":1717317092755,"mc":[{"id":"1.229554907","rc":[{"atb":[[4.3,0],[3.85,35.09]],"id":52385888},{"atb":[[1.69,107.88]],"id":52385931}],"con":true,"img":false}]}
{"op":"mcm","clk":"11450013816","pt":1717317092858,"mc":[{"id":"1.229554907","rc":[{"atb":[[1.78,0]],"id":52385931}],"con":true,"img":false}]}
{"op":"mcm","clk":"11450013848","pt":1717317093123,"mc":[{"id":"1.229554907","rc":[{"atb":[[3.6,0],[3.1,0],[3.35,0],[2.94,0]],"id":52385931}],"con":true,"img":false}]}
{"op":"mcm","clk":"11450013928","pt":1717317093951,"mc":[{"id":"1.229554907","rc":[{"atb":[[2.86,56.26],[3.4,10.9],[3.15,24.33],[2.96,40.04]],"id":52385931}],"con":true,"img":false}]}
{"op":"mcm","clk":"11450014009","pt":1717317094927,"mc":[{"id":"1.229554907","rc":[{"atb":[[160,0],[80,0],[110,0],[55,0]],"id":52385923}],"con":true,"img":false}]}
{"op":"mcm","clk":"11450014018","pt":1717317095028,"mc":[{"id":"1.229554907","rc":[{"atb":[[75,0],[24,4.35]],"id":52385923}],"con":true,"img":false}]}
{"op":"mcm","clk":"11450014021","pt":1717317095129,"mc":[{"id":"1.229554907","rc":[{"atb":[[16.5,0],[19,0],[23,0],[14,0]],"id":52385884}],"con":true,"img":false}]}
{"op":"mcm","clk":"11450014032","pt":1717317095230,"mc":[{"id":"1.229554907","rc":[{"atb":[[9.4,11.9]],"id":52385884}],"con":true,"img":false}]}
{"op":"mcm","clk":"11450014042","pt":1717317095334,"mc":[{"id":"1.229554907","rc":[{"atb":[[11,0]],"id":52385884}],"con":true,"img":false}]}
{"op":"mcm","clk":"11450014073","pt":1717317095649,"mc":[{"id":"1.229554907","rc":[{"atb":[[160,0.16],[80,0.99],[110,0.48],[55,1.94]],"id":52385923}],"con":true,"img":false}]}
{"op":"mcm","clk":"11450014091","pt":1717317095951,"mc":[{"id":"1.229554907","rc":[{"atb":[[18,3.08],[21,1.31],[13,8.72],[15.5,5.41]],"id":52385884}],"con":true,"img":false}]}
{"op":"mcm","clk":"11450014575","pt":1717317101343,"mc":[{"id":"1.229554907","rc":[{"atb":[[110,0]],"id":52385923}],"con":true,"img":false}]}
{"op":"mcm","clk":"11450014584","pt":1717317101448,"mc":[{"id":"1.229554907","rc":[{"atb":[[160,0],[80,0],[55,0]],"id":52385923}],"con":true,"img":false}]}
{"op":"mcm","clk":"11450014633","pt":1717317102066,"mc":[{"id":"1.229554907","rc":[{"atb":[[100,0.53]],"id":52385923}],"con":true,"img":false}]}
{"op":"mcm","clk":"11450014641","pt":1717317102169,"mc":[{"id":"1.229554907","rc":[{"atb":[[150,0.18],[75,1.06],[50,2.13]],"id":52385923}],"con":true,"img":false}]}
{"op":"mcm","clk":"11450015725","pt":1717317114358,"mc":[{"id":"1.229554907","rc":[{"atb":[[580,2]],"id":52385918}],"con":true,"img":false}]}
{"op":"mcm","clk":"11450015735","pt":1717317114461,"mc":[{"id":"1.229554907","rc":[{"atb":[[520,0]],"id":52385918}],"con":true,"img":false}]}
{"op":"mcm","clk":"11450015759","pt":1717317114773,"mc":[{"id":"1.229554907","rc":[{"atb":[[16,0],[18.5,0],[22,0],[27,0]],"id":52385895}],"con":true,"img":false}]}
{"op":"mcm","clk":"11450015772","pt":1717317114874,"mc":[{"id":"1.229554907","rc":[{"atb":[[2.82,0],[2.72,0],[2.52,0],[2.62,0]],"id":52385934}],"con":true,"img":false}]}
{"op":"mcm","clk":"11450015821","pt":1717317115489,"mc":[{"id":"1.229554907","rc":[{"atb":[[16.5,6.75],[19,4.36],[23,2.38],[28,0.97]],"id":52385895}],"con":true,"img":false}]}
{"op":"mcm","clk":"11450015830","pt":1717317115592,"mc":[{"id":"1.229554907","rc":[{"atb":[[2.72,15.21],[2.42,73.69],[2.52,51.63],[2.62,32.3]],"id":52385934}],"con":true,"img":false}]}
{"op":"mcm","clk":"11450015841","pt":1717317115696,"mc":[{"id":"1.229554907","rc":[{"atb":[[4.3,30.3],[3.85,0]],"id":52385888},{"atb":[[11,10],[9.4,0]],"id":52385884},{"atb":[[1.78,103.79]],"id":52385931}],"con":true,"img":false}]}
{"op":"mcm","clk":"11450015855","pt":1717317115755,"mc":[{"id":"1.229554907","rc":[{"atb":[[1.69,0]],"id":52385931}],"con":true,"img":false}]}
{"op":"mcm","clk":"11450016238","pt":1717317119455,"mc":[{"id":"1.229554907","rc":[{"atb":[[500,2]],"id":52385918}],"con":true,"img":false}]}
{"op":"mcm","clk":"11450016246","pt":1717317119557,"mc":[{"id":"1.229554907","rc":[{"atb":[[580,0]],"id":52385918}],"con":true,"img":false}]}
{"op":"mcm","clk":"11450016830","pt":1717317125222,"mc":[{"id":"1.229554907","rc":[{"atb":[[70,2],[24,0]],"id":52385923}],"con":true,"img":false}]}
{"op":"mcm","clk":"11450016969","pt":1717317126521,"mc":[{"id":"1.229554907","rc":[{"atb":[[70,0],[80,2]],"id":52385923}],"con":true,"img":false}]}
{"op":"mcm","clk":"11450019970","pt":1717317156962,"mc":[{"id":"1.229554907","rc":[{"atb":[[580,2]],"id":52385918}],"con":true,"img":false}]}
{"op":"mcm","clk":"11450019979","pt":1717317157067,"mc":[{"id":"1.229554907","rc":[{"atb":[[500,0]],"id":52385918}],"con":true,"img":false}]}
{"op":"mcm","clk":"11450021462","pt":1717317171862,"mc":[{"id":"1.229554907","rc":[{"atb":[[500,2]],"id":52385918}],"con":true,"img":false}]}
{"op":"mcm","clk":"11450021468","pt":1717317171961,"mc":[{"id":"1.229554907","rc":[{"atb":[[580,0]],"id":52385918}],"con":true,"img":false}]}
{"op":"mcm","clk":"11450022998","pt":1717317187400,"mc":[{"id":"1.229554907","rc":[{"atb":[[580,2],[500,0]],"id":52385918}],"con":true,"img":false}]}
{"op":"mcm","clk":"11450024494","pt":1717317202428,"mc":[{"id":"1.229554907","rc":[{"atb":[[580,0],[500,2]],"id":52385918}],"con":true,"img":false}]}
{"op":"mcm","clk":"11450026138","pt":1717317218196,"mc":[{"id":"1.229554907","rc":[{"atb":[[580,2],[500,0]],"id":52385918}],"con":true,"img":false}]}
{"op":"mcm","clk":"11450027632","pt":1717317232637,"mc":[{"id":"1.229554907","rc":[{"atb":[[580,0],[500,2]],"id":52385918}],"con":true,"img":false}]}
{"op":"mcm","clk":"11450029158","pt":1717317248269,"mc":[{"id":"1.229554907","rc":[{"atb":[[580,2]],"id":52385918}],"con":true,"img":false}]}
{"op":"mcm","clk":"11450029169","pt":1717317248370,"mc":[{"id":"1.229554907","rc":[{"atb":[[500,0]],"id":52385918}],"con":true,"img":false}]}
{"op":"mcm","clk":"11450030673","pt":1717317263088,"mc":[{"id":"1.229554907","rc":[{"atb":[[500,2]],"id":52385918}],"con":true,"img":false}]}
{"op":"mcm","clk":"11450030681","pt":1717317263141,"mc":[{"id":"1.229554907","rc":[{"atb":[[580,0]],"id":52385918}],"con":true,"img":false}]}
{"op":"mcm","clk":"11450033630","pt":1717317291492,"mc":[{"id":"1.229554907","rc":[{"atb":[[580,2]],"id":52385918}],"con":true,"img":false}]}
{"op":"mcm","clk":"11450033637","pt":1717317291595,"mc":[{"id":"1.229554907","rc":[{"atb":[[500,0]],"id":52385918}],"con":true,"img":false}]}
{"op":"mcm","clk":"11450033856","pt":1717317293920,"mc":[{"id":"1.229554907","rc":[{"atb":[[580,0],[500,2]],"id":52385918}],"con":true,"img":false}]}
{"op":"mcm","clk":"11450036975","pt":1717317322144,"mc":[{"id":"1.229554907","rc":[{"atb":[[580,2],[500,0]],"id":52385918}],"con":true,"img":false}]}
{"op":"mcm","clk":"11450037187","pt":1717317323944,"mc":[{"id":"1.229554907","rc":[{"atb":[[580,0],[500,2]],"id":52385918}],"con":true,"img":false}]}
{"op":"mcm","clk":"11450038898","pt":1717317339423,"mc":[{"id":"1.229554907","rc":[{"atb":[[580,2],[500,0]],"id":52385918}],"con":true,"img":false}]}
{"op":"mcm","clk":"11450040241","pt":1717317351952,"mc":[{"id":"1.229554907","rc":[{"atb":[[160,0],[80,0]],"id":52385907},{"atb":[[3.2,0],[3.7,0]],"id":52385909},{"atb":[[550,0],[650,0]],"id":52385918},{"atb":[[130,0],[230,0]],"id":52385886},{"atb":[[4,0],[3.5,0]],"id":52385888},{"atb":[[270,0],[170,0]],"id":52385920},{"atb":[[18.5,4.48],[13.5,0]],"id":52385889},{"atb":[[18,0],[13,0]],"id":52385882},{"atb":[[7.2,0],[9.2,0]],"id":52385884},{"atb":[[330,0],[230,2]],"id":52385917},{"atb":[[9,0],[7,0]],"id":52385895},{"atb":[[16.5,0],[23,0]],"id":52385923},{"atb":[[18,0],[13,0]],"id":52385891},{"atb":[[550,0],[650,0]],"id":52385893},{"atb":[[2.4,0],[2.6,0]],"id":52385934},{"atb":[[9,0],[7,0]],"id":52385903},{"atb":[[16.5,0],[11.5,0]],"id":52385904},{"atb":[[10,0],[15,0]],"id":52385936},{"atb":[[2.54,0],[2.74,0]],"id":52385931},{"atb":[[4,0],[5,0]],"id":52385932}],"con":true,"img":false}]}
{"op":"mcm","clk":"11450040257","pt":1717317352164,"mc":[{"id":"1.229554907","rc":[{"atb":[[17,0],[7.2,12.5]],"id":52385904}],"con":true,"img":false}]}
{"op":"mcm","clk":"11450040473","pt":1717317354245,"mc":[{"id":"1.229554907","rc":[{"atb":[[500,2]],"id":52385918}],"con":true,"img":false}]}
{"op":"mcm","clk":"11450040482","pt":1717317354347,"mc":[{"id":"1.229554907","rc":[{"atb":[[580,0]],"id":52385918}],"con":true,"img":false}]}
{"op":"mcm","clk":"11450042154","pt":1717317369851,"mc":[{"id":"1.229554907","rc":[{"atb":[[580,2],[500,0]],"id":52385918}],"con":true,"img":false}]}
{"op":"mcm","clk":"11450043545","pt":1717317383593,"mc":[{"id":"1.229554907","rc":[{"atb":[[29,0]],"id":52385891},{"atb":[[520,0],[570,0],[620,0],[670,0]],"id":52385893},{"atb":[[8,0],[5.5,0],[6,0],[7,0]],"id":52385932}],"con":true,"img":false}]}
{"op":"mcm","clk":"11450043557","pt":1717317383697,"mc":[{"id":"1.229554907","rc":[{"atb":[[19.5,6.82],[30,0]],"id":52385891},{"atb":[[330,0],[44,2.33]],"id":52385893},{"atb":[[1.05,143.16],[1.35,0]],"id":52385932}],"con":true,"img":false}]}
{"op":"mcm","clk":"11450043625","pt":1717317384269,"mc":[{"id":"1.229554907","rc":[{"atb":[[30,3.61]],"id":52385891},{"atb":[[610,0.17],[660,0.12],[710,0.07],[760,0.04]],"id":52385893},{"atb":[[5.6,22.75],[7.2,8.44],[6.2,15.09],[8.2,3.63]],"id":52385932}],"con":true,"img":false}]}
{"op":"mcm","clk":"11450043635","pt":1717317384371,"mc":[{"id":"1.229554907","rc":[{"atb":[[32,3.23],[19.5,1.41]],"id":52385891},{"atb":[[44,0],[370,2]],"id":52385893},{"atb":[[1.35,107.37]],"id":52385932}],"con":true,"img":false}]}
{"op":"mcm","clk":"11450043650","pt":1717317384477,"mc":[{"id":"1.229554907","rc":[{"atb":[[1.05,0]],"id":52385932}],"con":true,"img":false}]}
{"op":"mcm","clk":"11450043672","pt":1717317384682,"mc":[{"id":"1.229554907","rc":[{"atb":[[500,2]],"id":52385918}],"con":true,"img":false}]}
{"op":"mcm","clk":"11450043682","pt":1717317384784,"mc":[{"id":"1.229554907","rc":[{"atb":[[580,0]],"id":52385918}],"con":true,"img":false}]}
{"op":"mcm","clk":"11450044140","pt":1717317388995,"mc":[{"id":"1.229554907","rc":[{"atb":[[160,0.65],[80,3.08]],"id":52385907},{"atb":[[3.2,110.86],[3.7,38.71]],"id":52385909},{"atb":[[550,0.44],[650,0.16]],"id":52385918},{"atb":[[130,1.88],[230,0.45]],"id":52385886},{"atb":[[4,34.84],[3.5,97.56]],"id":52385888},{"atb":[[270,0.38],[170,1.44]],"id":52385920},{"atb":[[18.5,10.46],[13.5,19.51]],"id":52385889},{"atb":[[18,6.14],[13,20.32]],"id":52385882},{"atb":[[7.2,39.33],[9.2,12.74]],"id":52385884},{"atb":[[330,0.31],[230,3.06]],"id":52385917},{"atb":[[9,13.06],[7,40.65]],"id":52385895},{"atb":[[18,6.14],[13,20.32]],"id":52385891},{"atb":[[16.5,15.73],[23,4.75]],"id":52385923},{"atb":[[550,0.44],[650,0.16]],"id":52385893},{"atb":[[2.4,174.21],[2.6,65.33]],"id":52385934},{"atb":[[9,13.06],[7,40.65]],"id":52385903},{"atb":[[16.5,6.74],[11.5,23.22]],"id":52385904},{"atb":[[10,27.1],[15,7.46]],"id":52385936},{"atb":[[2.54,158.38],[2.74,60.07]],"id":52385931},{"atb":[[4,81.3],[5,26.13]],"id":52385932}],"con":true,"img":false}]}
{"op":"mcm","clk":"11450044159","pt":1717317389203,"mc":[{"id":"1.229554907","rc":[{"atb":[[7.2,0],[17,6.25]],"id":52385904}],"con":true,"img":false}]}
{"op":"mcm","clk":"11450044244","pt":1717317389984,"mc":[{"id":"1.229554907","rc":[{"atb":[[710,0]],"id":52385893},{"atb":[[5.6,0],[7.2,0],[6.2,0],[8.2,0]],"id":52385932}],"con":true,"img":false}]}
{"op":"mcm","clk":"11450044258","pt":1717317390087,"mc":[{"id":"1.229554907","rc":[{"atb":[[610,0],[660,0],[760,0]],"id":52385893}],"con":true,"img":false}]}
{"op":"mcm","clk":"11450044282","pt":1717317390293,"mc":[{"id":"1.229554907","rc":[{"atb":[[2.86,0],[3.4,0],[3.15,0],[2.96,0]],"id":52385931}],"con":true,"img":false}]}
{"op":"mcm","clk":"11450044318","pt":1717317390663,"mc":[{"id":"1.229554907","rc":[{"atb":[[620,0.08]],"id":52385893},{"atb":[[8,3.74],[5.5,23.25],[6,15.7],[7,8.72]],"id":52385932}],"con":true,"img":false}]}
{"op":"mcm","clk":"11450044340","pt":1717317390869,"mc":[{"id":"1.229554907","rc":[{"atb":[[520,0.2],[570,0.14],[670,0.04]],"id":52385893}],"con":true,"img":false}]}
{"op":"mcm","clk":"11450044354","pt":1717317390973,"mc":[{"id":"1.229554907","rc":[{"atb":[[3.6,10.06],[3.35,22.26],[2.94,53.93]],"id":52385931}],"con":true,"img":false}]}
{"op":"mcm","clk":"11450044361","pt":1717317391075,"mc":[{"id":"1.229554907","rc":[{"atb":[[3.1,37.37]],"id":52385931}],"con":true,"img":false}]}
{"op":"mcm","clk":"11450044469","pt":1717317392066,"mc":[{"id":"1.229554907","rc":[{"atb":[[18,0],[21,0],[13,0],[15.5,0]],"id":52385884}],"con":true,"img":false}]}
{"op":"mcm","clk":"11450044475","pt":1717317392174,"mc":[{"id":"1.229554907","rc":[{"atb":[[11,0],[9.4,11.9]],"id":52385884}],"con":true,"img":false}]}
{"op":"mcm","clk":"11450044539","pt":1717317392798,"mc":[{"id":"1.229554907","rc":[{"atb":[[16.5,5.06],[19,2.91],[23,1.19],[14,8.05]],"id":52385884}],"con":true,"img":false}]}
{"op":"mcm","clk":"11450045292","pt":1717317400372,"mc":[{"id":"1.229554907","rc":[{"atb":[[580,2],[500,0]],"id":52385918}],"con":true,"img":false}]}
{"op":"mcm","clk":"11450045326","pt":1717317400681,"mc":[{"id":"1.229554907","rc":[{"atb":[[3.6,0],[3.1,0],[3.35,0],[2.94,0]],"id":52385931}],"con":true,"img":false}]}
{"op":"mcm","clk":"11450045395","pt":1717317401406,"mc":[{"id":"1.229554907","rc":[{"atb":[[2.92,54.5],[3.55,10.26],[3.3,22.75],[3.05,38.28]],"id":52385931}],"con":true,"img":false}]}
{"op":"mcm","clk":"11450046318","pt":1717317409803,"mc":[{"id":"1.229554907","rc":[{"atb":[[2.72,0],[2.42,0],[2.52,0],[2.62,0]],"id":52385934}],"con":true,"img":false}]}
{"op":"mcm","clk":"11450046389","pt":1717317410527,"mc":[{"id":"1.229554907","rc":[{"atb":[[2.52,68.84],[2.62,48.44]],"id":52385934}],"con":true,"img":false}]}
{"op":"mcm","clk":"11450046399","pt":1717317410583,"mc":[{"id":"1.229554907","rc":[{"atb":[[2.82,14.37],[2.72,30.42]],"id":52385934}],"con":true,"img":false}]}
{"op":"mcm","clk":"11450046878","pt":1717317415245,"mc":[{"id":"1.229554907","rc":[{"atb":[[580,0],[500,2]],"id":52385918}],"con":true,"img":false}]}
{"op":"mcm","clk":"11450046914","pt":1717317415554,"mc":[{"id":"1.229554907","rc":[{"atb":[[3.3,0]],"id":52385931}],"con":true,"img":false}]}
{"op":"mcm","clk":"11450046986","pt":1717317416228,"mc":[{"id":"1.229554907","rc":[{"atb":[[3.35,22.26]],"id":52385931}],"con":true,"img":false}]}
{"op":"mcm","clk":"11450047309","pt":1717317419326,"mc":[{"id":"1.229554907","rc":[{"atb":[[11,10]],"id":52385884}],"con":true,"img":false}]}
{"op":"mcm","clk":"11450047320","pt":1717317419430,"mc":[{"id":"1.229554907","rc":[{"atb":[[9.4,0]],"id":52385884}],"con":true,"img":false}]}
{"op":"mcm","clk":"11450048558","pt":1717317430671,"mc":[{"id":"1.229554907","rc":[{"atb":[[580,2],[500,0]],"id":52385918}],"con":true,"img":false}]}
{"op":"mcm","clk":"11450048594","pt":1717317430934,"mc":[{"id":"1.229554907","rc":[{"atb":[[3.35,0]],"id":52385931}],"con":true,"img":false}]}
{"op":"mcm","clk":"11450048730","pt":1717317432172,"mc":[{"id":"1.229554907","rc":[{"atb":[[3.3,22.75]],"id":52385931}],"con":true,"img":false}]}
{"op":"mcm","clk":"11450050222","pt":1717317445544,"mc":[{"id":"1.229554907","rc":[{"atb":[[580,0],[500,2]],"id":52385918}],"con":true,"img":false}]}
{"op":"mcm","clk":"11450052657","pt":1717317472271,"mc":[{"id":"1.229554907","rc":[{"atb":[[580,2],[500,0]],"id":52385918}],"con":true,"img":false}]}
{"op":"mcm","clk":"11450052882","pt":1717317474650,"mc":[{"id":"1.229554907","rc":[{"atb":[[520,2],[580,0]],"id":52385918},{"atb":[[4.3,0],[3.85,35.09]],"id":52385888},{"atb":[[1.78,0],[1.69,109]],"id":52385931}],"con":true,"img":false}]}
{"op":"mcm","clk":"11450052916","pt":1717317475063,"mc":[{"id":"1.229554907","rc":[{"atb":[[520,0],[580,2]],"id":52385918},{"atb":[[3.85,0],[4.2,31.25]],"id":52385888},{"atb":[[16.5,0],[19,0],[23,0],[14,0]],"id":52385884},{"atb":[[2.92,0],[3.55,0],[3.3,0],[1.75,104.35],[3.05,0],[1.69,0]],"id":52385931}],"con":true,"img":false}]}
{"op":"mcm","clk":"11450052926","pt":1717317475169,"mc":[{"id":"1.229554907","rc":[{"atb":[[520,2],[580,0]],"id":52385918},{"atb":[[11,0],[9.4,11.9]],"id":52385884},{"atb":[[1.75,0],[1.69,144.93]],"id":52385931}],"con":true,"img":false}]}
{"op":"mcm","clk":"11450052988","pt":1717317475789,"mc":[{"id":"1.229554907","rc":[{"atb":[[18,3.08],[21,1.31],[13,8.72],[15.5,5.41]],"id":52385884},{"atb":[[2.86,56.26],[3.4,10.9],[3.15,24.33],[2.96,40.04]],"id":52385931}],"con":true,"img":false}]}
{"op":"mcm","clk":"11450052998","pt":1717317475893,"mc":[{"id":"1.229554907","rc":[{"atb":[[11,10],[9.4,0]],"id":52385884},{"atb":[[1.78,122.32],[1.69,0]],"id":52385931}],"con":true,"img":false}]}
{"op":"mcm","clk":"11450053063","pt":1717317476473,"mc":[{"id":"1.229554907","rc":[{"atb":[[18,0]],"id":52385884}],"con":true,"img":false}]}
{"op":"mcm","clk":"11450053117","pt":1717317477183,"mc":[{"id":"1.229554907","rc":[{"atb":[[19,2.91]],"id":52385884}],"con":true,"img":false}]}
{"op":"mcm","clk":"11450054389","pt":1717317491466,"mc":[{"id":"1.229554907","rc":[{"atb":[[520,0],[580,2]],"id":52385918}],"con":true,"img":false}]}
{"op":"mcm","clk":"11450055613","pt":1717317505009,"mc":[{"id":"1.229554907","rc":[{"atb":[[580,0],[500,2]],"id":52385918}],"con":true,"img":false}]}
{"op":"mcm","clk":"11450056676","pt":1717317517715,"mc":[{"id":"1.229554907","rc":[{"atb":[[580,2]],"id":52385918}],"con":true,"img":false}]}
{"op":"mcm","clk":"11450056679","pt":1717317517819,"mc":[{"id":"1.229554907","rc":[{"atb":[[500,0]],"id":52385918}],"con":true,"img":false}]}
{"op":"mcm","clk":"11450062252","pt":1717317579477,"mc":[{"id":"1.229554907","rc":[{"atb":[[520,2],[580,0]],"id":52385918},{"atb":[[1.78,0],[1.69,112.52]],"id":52385931}],"con":true,"img":false}]}
{"op":"mcm","clk":"11450062277","pt":1717317579787,"mc":[{"id":"1.229554907","rc":[{"atb":[[19,0]],"id":52385884}],"con":true,"img":false}]}
{"op":"mcm","clk":"11450062340","pt":1717317580462,"mc":[{"id":"1.229554907","rc":[{"atb":[[18,3.08]],"id":52385884}],"con":true,"img":false}]}
{"op":"mcm","clk":"11450062388","pt":1717317580974,"mc":[{"id":"1.229554907","rc":[{"atb":[[520,0],[580,2]],"id":52385918},{"atb":[[1.75,106.11],[1.69,0]],"id":52385931}],"con":true,"img":false}]}
{"op":"mcm","clk":"11450062559","pt":1717317583007,"mc":[{"id":"1.229554907","rc":[{"atb":[[520,2],[580,0]],"id":52385918},{"atb":[[1.75,0],[1.69,112.52]],"id":52385931}],"con":true,"img":false}]}
{"op":"mcm","clk":"11450062584","pt":1717317583266,"mc":[{"id":"1.229554907","rc":[{"atb":[[520,0],[580,2]],"id":52385918},{"atb":[[1.75,106.11],[1.69,0]],"id":52385931}],"con":true,"img":false}]}
{"op":"mcm","clk":"11450062652","pt":1717317584092,"mc":[{"id":"1.229554907","rc":[{"atb":[[520,2],[580,0]],"id":52385918},{"atb":[[1.69,112.52]],"id":52385931}],"con":true,"img":false}]}
{"op":"mcm","clk":"11450062659","pt":1717317584195,"mc":[{"id":"1.229554907","rc":[{"atb":[[1.75,0]],"id":52385931}],"con":true,"img":false}]}
{"op":"mcm","clk":"11450063098","pt":1717317588772,"mc":[{"id":"1.229554907","rc":[{"atb":[[520,0],[580,2]],"id":52385918},{"atb":[[1.75,106.11],[1.69,0]],"id":52385931}],"con":true,"img":false}]}
{"op":"mcm","clk":"11450066369","pt":1717317625022,"mc":[{"id":"1.229554907","rc":[{"atb":[[26,4],[29,1.87]],"id":52385882},{"atb":[[1.57,137.2],[1.52,0]],"id":52385934},{"atb":[[1.68,112.52],[1.75,0]],"id":52385931}],"con":true,"img":false}]}
{"op":"mcm","clk":"11450069286","pt":1717317657306,"mc":[{"id":"1.229554907","rc":[{"atb":[[620,0]],"id":52385893},{"atb":[[8,0],[5.5,0],[6,0],[7,0]],"id":52385932}],"con":true,"img":false}]}
{"op":"mcm","clk":"11450069313","pt":1717317657465,"mc":[{"id":"1.229554907","rc":[{"atb":[[520,0],[570,0],[670,0]],"id":52385893}],"con":true,"img":false}]}
{"op":"mcm","clk":"11450069371","pt":1717317657979,"mc":[{"id":"1.229554907","rc":[{"atb":[[710,0.07]],"id":52385893},{"atb":[[5.6,22.75],[7.2,8.44],[8.2,3.63]],"id":52385932}],"con":true,"img":false}]}
{"op":"mcm","clk":"11450069380","pt":1717317658084,"mc":[{"id":"1.229554907","rc":[{"atb":[[6.2,15.09]],"id":52385932}],"con":true,"img":false}]}
{"op":"mcm","clk":"11450069391","pt":1717317658187,"mc":[{"id":"1.229554907","rc":[{"atb":[[610,0.17],[660,0.12],[760,0.04]],"id":52385893}],"con":true,"img":false}]}
{"op":"mcm","clk":"11450076055","pt":1717317730270,"mc":[{"id":"1.229554907","rc":[{"atb":[[160,0],[80,0]],"id":52385907},{"atb":[[3.2,0],[3.7,0]],"id":52385909},{"atb":[[550,0],[650,0]],"id":52385918},{"atb":[[130,0],[230,0]],"id":52385886},{"atb":[[4,0],[3.5,0]],"id":52385888},{"atb":[[270,0],[170,0]],"id":52385920},{"atb":[[18.5,4.48],[13.5,0]],"id":52385889},{"atb":[[18,0],[13,0]],"id":52385882},{"atb":[[7.2,0],[9.2,0]],"id":52385884},{"atb":[[330,0],[230,2]],"id":52385917},{"atb":[[9,0],[7,0]],"id":52385895},{"atb":[[18,0],[13,0]],"id":52385891},{"atb":[[16.5,0],[23,0]],"id":52385923},{"atb":[[550,0],[650,0]],"id":52385893},{"atb":[[2.4,0],[2.6,0]],"id":52385934},{"atb":[[9,0],[7,0]],"id":52385903},{"atb":[[16.5,0],[11.5,0]],"id":52385904},{"atb":[[10,0],[15,0]],"id":52385936},{"atb":[[2.54,0],[2.74,0]],"id":52385931},{"atb":[[4,0],[5,0]],"id":52385932}],"con":true,"img":false}]}
{"op":"mcm","clk":"11450076071","pt":1717317730477,"mc":[{"id":"1.229554907","rc":[{"atb":[[17,0],[7.2,12.5]],"id":52385904}],"con":true,"img":false}]}
{"op":"mcm","clk":"11450078622","pt":1717317758321,"mc":[{"id":"1.229554907","rc":[{"atb":[[520,2],[580,0]],"id":52385918}],"con":true,"img":false}]}
{"op":"mcm","clk":"11450078649","pt":1717317758644,"mc":[{"id":"1.229554907","rc":[{"atb":[[610,0],[660,0],[710,0],[760,0]],"id":52385893}],"con":true,"img":false}]}
{"op":"mcm","clk":"11450078668","pt":1717317758848,"mc":[{"id":"1.229554907","rc":[{"atb":[[40,2.56],[370,0]],"id":52385893}],"con":true,"img":false}]}
{"op":"mcm","clk":"11450078721","pt":1717317759368,"mc":[{"id":"1.229554907","rc":[{"atb":[[560,0.19],[610,0.13],[660,0.08],[710,0.04]],"id":52385893}],"con":true,"img":false}]}
{"op":"mcm","clk":"11450078730","pt":1717317759471,"mc":[{"id":"1.229554907","rc":[{"atb":[[40,0],[350,2]],"id":52385893}],"con":true,"img":false}]}
{"op":"mcm","clk":"11450078991","pt":1717317762426,"mc":[{"id":"1.229554907","rc":[{"atb":[[520,0],[580,2]],"id":52385918}],"con":true,"img":false}]}
{"op":"mcm","clk":"11450079083","pt":1717317763464,"mc":[{"id":"1.229554907","rc":[{"atb":[[520,2],[580,0]],"id":52385918}],"con":true,"img":false}]}
{"op":"mcm","clk":"11450079213","pt":1717317764868,"mc":[{"id":"1.229554907","rc":[{"atb":[[160,0.65],[80,3.08]],"id":52385907},{"atb":[[3.2,110.86],[3.7,38.71]],"id":52385909},{"atb":[[550,0.44],[650,0.16]],"id":52385918},{"atb":[[130,1.88],[230,0.45]],"id":52385886},{"atb":[[4,34.84],[3.5,97.56]],"id":52385888},{"atb":[[270,0.38],[170,1.44]],"id":52385920},{"atb":[[18.5,10.46],[13.5,19.51]],"id":52385889},{"atb":[[18,6.14],[13,20.32]],"id":52385882},{"atb":[[7.2,39.33],[9.2,12.74]],"id":52385884},{"atb":[[330,0.31],[230,3.06]],"id":52385917},{"atb":[[9,13.06],[7,40.65]],"id":52385895},{"atb":[[18,6.14],[13,20.32]],"id":52385891},{"atb":[[16.5,15.73],[23,4.75]],"id":52385923},{"atb":[[550,0.44],[650,0.16]],"id":52385893},{"atb":[[2.4,174.21],[2.6,65.33]],"id":52385934},{"atb":[[9,13.06],[7,40.65]],"id":52385903},{"atb":[[16.5,6.74],[11.5,23.22]],"id":52385904},{"atb":[[10,27.1],[15,7.46]],"id":52385936},{"atb":[[2.54,158.38],[2.74,60.07]],"id":52385931},{"atb":[[4,81.3],[5,26.13]],"id":52385932}],"con":true,"img":false}]}
{"op":"mcm","clk":"11450079225","pt":1717317764969,"mc":[{"id":"1.229554907","rc":[{"atb":[[17,6.25]],"id":52385904}],"con":true,"img":false}]}
{"op":"mcm","clk":"11450079242","pt":1717317765082,"mc":[{"id":"1.229554907","rc":[{"atb":[[520,0],[580,2]],"id":52385918},{"atb":[[7.2,0]],"id":52385904}],"con":true,"img":false}]}
{"op":"mcm","clk":"11450079653","pt":1717317769361,"mc":[{"id":"1.229554907","rc":[{"atb":[[26,0],[29,5.29]],"id":52385882},{"atb":[[1.68,0],[1.78,106.11]],"id":52385931}],"con":true,"img":false}]}
{"op":"mcm","clk":"11450079690","pt":1717317769721,"mc":[{"id":"1.229554907","rc":[{"atb":[[560,0],[610,0],[660,0],[710,0]],"id":52385893}],"con":true,"img":false}]}
{"op":"mcm","clk":"11450079700","pt":1717317769878,"mc":[{"id":"1.229554907","rc":[{"atb":[[5.6,0],[7.2,0],[6.2,0],[8.2,0]],"id":52385932}],"con":true,"img":false}]}
{"op":"mcm","clk":"11450079731","pt":1717317770240,"mc":[{"id":"1.229554907","rc":[{"atb":[[580,0],[500,2]],"id":52385918}],"con":true,"img":false}]}
{"op":"mcm","clk":"11450079744","pt":1717317770445,"mc":[{"id":"1.229554907","rc":[{"atb":[[520,0.2],[570,0.14],[620,0.08],[670,0.04]],"id":52385893}],"con":true,"img":false}]}
{"op":"mcm","clk":"11450079756","pt":1717317770549,"mc":[{"id":"1.229554907","rc":[{"atb":[[8,3.74],[5.5,23.25],[6,15.7],[7,8.72]],"id":52385932}],"con":true,"img":false}]}
{"op":"mcm","clk":"11450084636","pt":1717317828156,"mc":[{"id":"1.229554907","rc":[{"atb":[[18,0]],"id":52385884}],"con":true,"img":false}]}
{"op":"mcm","clk":"11450084682","pt":1717317828828,"mc":[{"id":"1.229554907","rc":[{"atb":[[19,2.91]],"id":52385884}],"con":true,"img":false}]}
{"op":"mcm","clk":"11450108236","pt":1717318096759,"mc":[{"id":"1.229554907","rc":[{"atb":[[30,0]],"id":52385891}],"con":true,"img":false}]}
{"op":"mcm","clk":"11450108246","pt":1717318096854,"mc":[{"id":"1.229554907","rc":[{"atb":[[32,0],[19.5,6.82]],"id":52385891}],"con":true,"img":false}]}
{"op":"mcm","clk":"11450108294","pt":1717318097468,"mc":[{"id":"1.229554907","rc":[{"atb":[[29,3.74]],"id":52385891}],"con":true,"img":false}]}
{"op":"mcm","clk":"11450110009","pt":1717318117070,"mc":[{"id":"1.229554907","rc":[{"atb":[[19.5,1.41],[30,3.45]],"id":52385891}],"con":true,"img":false}]}
{"op":"mcm","clk":"11450111188","pt":1717318130993,"mc":[{"id":"1.229554907","rc":[{"atb":[[160,0],[80,0]],"id":52385907},{"atb":[[3.2,0],[3.7,0]],"id":52385909},{"atb":[[550,0],[650,0]],"id":52385918},{"atb":[[130,0],[230,0]],"id":52385886},{"atb":[[4,0],[3.5,0]],"id":52385888},{"atb":[[270,0],[170,0]],"id":52385920},{"atb":[[18.5,4.48],[13.5,0]],"id":52385889},{"atb":[[18,0],[13,0]],"id":52385882},{"atb":[[7.2,0],[9.2,0]],"id":52385884},{"atb":[[330,0],[230,2]],"id":52385917},{"atb":[[9,0],[7,0]],"id":52385895},{"atb":[[18,0],[13,0]],"id":52385891},{"atb":[[16.5,0],[23,0]],"id":52385923},{"atb":[[550,0],[650,0]],"id":52385893},{"atb":[[2.4,0],[2.6,0]],"id":52385934},{"atb":[[9,0],[7,0]],"id":52385903},{"atb":[[16.5,0],[11.5,0]],"id":52385904},{"atb":[[10,0],[15,0]],"id":52385936},{"atb":[[2.54,0],[2.74,0]],"id":52385931},{"atb":[[4,0],[5,0]],"id":52385932}],"con":true,"img":false}]}
{"op":"mcm","clk":"11450111193","pt":1717318131093,"mc":[{"id":"1.229554907","rc":[{"atb":[[17,0],[7.2,12.5]],"id":52385904}],"con":true,"img":false}]}
{"op":"mcm","clk":"11450111766","pt":1717318137693,"mc":[{"id":"1.229554907","rc":[{"atb":[[580,2],[500,0]],"id":52385918}],"con":true,"img":false}]}
{"op":"mcm","clk":"11450111803","pt":1717318138007,"mc":[{"id":"1.229554907","rc":[{"atb":[[520,0],[570,0],[620,0],[670,0]],"id":52385893},{"atb":[[8,0],[5.5,0],[6,0],[7,0]],"id":52385932}],"con":true,"img":false}]}
{"op":"mcm","clk":"11450111813","pt":1717318138116,"mc":[{"id":"1.229554907","rc":[{"atb":[[350,0],[44,2.33]],"id":52385893},{"atb":[[1.05,214.74],[1.35,0]],"id":52385932}],"con":true,"img":false}]}
{"op":"mcm","clk":"11450111861","pt":1717318138678,"mc":[{"id":"1.229554907","rc":[{"atb":[[610,0.17],[660,0.12],[710,0.07],[760,0.04]],"id":52385893}],"con":true,"img":false}]}
{"op":"mcm","clk":"11450111871","pt":1717318138783,"mc":[{"id":"1.229554907","rc":[{"atb":[[5.6,22.75],[7.2,8.44],[6.2,15.09],[8.2,3.63]],"id":52385932}],"con":true,"img":false}]}
{"op":"mcm","clk":"11450111880","pt":1717318138931,"mc":[{"id":"1.229554907","rc":[{"atb":[[44,0],[370,2]],"id":52385893}],"con":true,"img":false}]}
{"op":"mcm","clk":"11450111888","pt":1717318138987,"mc":[{"id":"1.229554907","rc":[{"atb":[[1.05,0],[1.35,143.16]],"id":52385932}],"con":true,"img":false}]}
{"op":"mcm","clk":"11450112489","pt":1717318145209,"mc":[{"id":"1.229554907","rc":[{"atb":[[500,2]],"id":52385918}],"con":true,"img":false}]}
{"op":"mcm","clk":"11450112497","pt":1717318145309,"mc":[{"id":"1.229554907","rc":[{"atb":[[580,0]],"id":52385918}],"con":true,"img":false}]}
{"op":"mcm","clk":"11450112520","pt":1717318145620,"mc":[{"id":"1.229554907","rc":[{"atb":[[610,0],[660,0],[710,0],[760,0]],"id":52385893},{"atb":[[5.6,0],[7.2,0],[6.2,0],[8.2,0]],"id":52385932}],"con":true,"img":false}]}
{"op":"mcm","clk":"11450112530","pt":1717318145721,"mc":[{"id":"1.229554907","rc":[{"atb":[[36,2.86],[370,0]],"id":52385893},{"atb":[[1.05,286.32],[1.35,0]],"id":52385932}],"con":true,"img":false}]}
{"op":"mcm","clk":"11450112584","pt":1717318146299,"mc":[{"id":"1.229554907","rc":[{"atb":[[520,0.2],[570,0.14],[620,0.08],[670,0.04]],"id":52385893},{"atb":[[8,3.74],[5.5,23.25],[6,15.7],[7,8.72]],"id":52385932}],"con":true,"img":false}]}
{"op":"mcm","clk":"11450114338","pt":1717318164937,"mc":[{"id":"1.229554907","rc":[{"atb":[[580,2],[500,0]],"id":52385918}],"con":true,"img":false}]}
{"op":"mcm","clk":"11450114387","pt":1717318165451,"mc":[{"id":"1.229554907","rc":[{"atb":[[36,0],[370,2]],"id":52385893},{"atb":[[1.05,0],[1.35,178.95]],"id":52385932}],"con":true,"img":false}]}
{"op":"mcm","clk":"11450115280","pt":1717318175624,"mc":[{"id":"1.229554907","rc":[{"atb":[[580,0],[500,2]],"id":52385918}],"con":true,"img":false}]}
{"op":"mcm","clk":"11450115672","pt":1717318180660,"mc":[{"id":"1.229554907","rc":[{"atb":[[1.78,0],[1.69,99.7]],"id":52385931}],"con":true,"img":false}]}
{"op":"mcm","clk":"11450116028","pt":1717318184562,"mc":[{"id":"1.229554907","rc":[{"atb":[[1.78,99.7],[1.69,0]],"id":52385931}],"con":true,"img":false}]}
{"op":"mcm","clk":"11450116455","pt":1717318188663,"mc":[{"id":"1.229554907","rc":[{"atb":[[160,0.65],[80,3.08]],"id":52385907},{"atb":[[3.2,110.86],[3.7,38.71]],"id":52385909},{"atb":[[550,0.44],[650,0.16]],"id":52385918},{"atb":[[130,1.88],[230,0.45]],"id":52385886},{"atb":[[4,34.84],[3.5,97.56]],"id":52385888},{"atb":[[270,0.38],[170,1.44]],"id":52385920},{"atb":[[18.5,10.46],[13.5,19.51]],"id":52385889},{"atb":[[18,6.14],[13,20.32]],"id":52385882},{"atb":[[7.2,39.33],[9.2,12.74]],"id":52385884},{"atb":[[330,0.31],[230,3.06]],"id":52385917},{"atb":[[9,13.06],[7,40.65]],"id":52385895},{"atb":[[18,6.14],[13,20.32]],"id":52385891},{"atb":[[16.5,15.73],[23,4.75]],"id":52385923},{"atb":[[550,0.44],[650,0.16]],"id":52385893},{"atb":[[2.4,174.21],[2.6,65.33]],"id":52385934},{"atb":[[9,13.06],[7,40.65]],"id":52385903},{"atb":[[16.5,6.74],[11.5,23.22]],"id":52385904},{"atb":[[10,27.1],[15,7.46]],"id":52385936},{"atb":[[2.54,158.38],[2.74,60.07]],"id":52385931},{"atb":[[4,81.3],[5,26.13]],"id":52385932}],"con":true,"img":false}]}
{"op":"mcm","clk":"11450116466","pt":1717318188769,"mc":[{"id":"1.229554907","rc":[{"atb":[[7.2,0],[17,6.25]],"id":52385904}],"con":true,"img":false}]}
{"op":"mcm","clk":"11450116487","pt":1717318189030,"mc":[{"id":"1.229554907","rc":[{"atb":[[580,2],[500,0]],"id":52385918}],"con":true,"img":false}]}
{"op":"mcm","clk":"11450116927","pt":1717318194143,"mc":[{"id":"1.229554907","rc":[{"atb":[[580,0],[500,2]],"id":52385918}],"con":true,"img":false}]}
{"op":"mcm","clk":"11450117585","pt":1717318201586,"mc":[{"id":"1.229554907","rc":[{"atb":[[40,3.2],[44,2.82]],"id":52385889},{"atl":[[230,3.15],[250,3.19]],"id":52385889},{"atb":[[18,3.87],[19,4.35]],"id":52385936},{"atl":[[46,3.17],[50,2.71]],"id":52385936}],"con":true,"img":false}]}
{"op":"mcm","clk":"11450117592","pt":1717318201695,"mc":[{"id":"1.229554907","rc":[{"atb":[[90,3.76],[100,5.12]],"id":52385907},{"atl":[[370,3.07],[390,3.39]],"id":52385907},{"atb":[[5.5,2.77],[5.7,4.49]],"id":52385909},{"atl":[[14.5,4.49],[15.5,3.6]],"id":52385909},{"atb":[[100,6.38],[120,3.74]],"id":52385886},{"atl":[[470,3.98],[490,3.31]],"id":52385886},{"atb":[[7,3.24],[6.6,2.99]],"id":52385888},{"atl":[[19.5,4.7],[21,4.05]],"id":52385888},{"atb":[[40,5.76]],"id":52385889},{"atb":[[32,3.82],[29,8.46]],"id":52385882},{"atl":[[130,3.99],[150,4.39]],"id":52385882},{"atb":[[14,2.85],[15,3.86]],"id":52385884},{"atl":[[48,3.94],[55,2.89]],"id":52385884},{"atl":[[130,3.14],[110,3.6]],"id":52385895},{"atb":[[90,3.54],[100,4.05]],"id":52385923},{"atl":[[760,2.67],[780,4.45]],"id":52385923},{"atb":[[32,4.65],[36,3.6]],"id":52385891},{"atl":[[210,3.02],[230,4.23]],"id":52385891},{"atb":[[2.58,9.93],[2.62,58.13]],"id":52385934},{"atl":[[4.8,4.12],[4.6,4.16]],"id":52385934},{"atb":[[13,4.19],[14,6.14]],"id":52385903},{"atl":[[42,2.67],[46,3.58]],"id":52385903},{"atb":[[25,2.66],[27,4.49]],"id":52385904},{"atl":[[100,2.62],[120,2.88]],"id":52385904},{"atb":[[3.2,7.13],[3.1,7.47]],"id":52385931},{"atl":[[5.1,4.13],[5.3,2.87]],"id":52385931},{"atl":[[12,3.06],[13,3.91]],"id":52385932}],"con":true,"img":false}]}
{"op":"mcm","clk":"11450117600","pt":1717318201794,"mc":[{"id":"1.229554907","rc":[{"atb":[[27,1]],"id":52385889}],"con":true,"img":false}]}
{"op":"mcm","clk":"11450117608","pt":1717318201892,"mc":[{"id":"1.229554907","rc":[{"atl":[[32,3.23],[310,0]],"id":52385909},{"atl":[[40,2.56],[350,0]],"id":52385888},{"atb":[[34,3.03],[30,0]],"id":52385891},{"atl":[[10.5,8.3],[55,0]],"id":52385934},{"atl":[[70,0],[12,7.02]],"id":52385931},{"atl":[[270,0],[27,3.85]],"id":52385932}],"con":true,"img":false}]}
{"op":"mcm","clk":"11450117787","pt":1717318203785,"mc":[{"id":"1.229554907","rc":[{"atl":[[200,4.66],[210,0]],"id":52385891},{"atl":[[690,4.34],[760,0]],"id":52385923},{"atl":[[95,3.99],[100,0]],"id":52385904},{"atl":[[5.1,0]],"id":52385931}],"con":true,"img":false}]}
{"op":"mcm","clk":"11450118168","pt":1717318208006,"mc":[{"id":"1.229554907","rc":[{"atb":[[17,0],[23,4.55]],"id":52385904}],"con":true,"img":false}]}
{"op":"mcm","clk":"11450118470","pt":1717318211694,"mc":[{"id":"1.229554907","rc":[{"atl":[[5.1,2.77]],"id":52385931}],"con":true,"img":false}]}
{"op":"mcm","clk":"11450118641","pt":1717318213757,"mc":[{"id":"1.229554907","rc":[{"atl":[[200,0],[210,4.43]],"id":52385891},{"atl":[[690,0],[760,3.57]],"id":52385923},{"atl":[[95,0],[100,4.51]],"id":52385904}],"con":true,"img":false}]}
{"op":"mcm","clk":"11450138842","pt":1717318448197,"mc":[{"id":"1.229554907","rc":[{"atl":[[19.5,0]],"id":52385888},{"atl":[[110,0],[120,3.73]],"id":52385895},{"atb":[[2.82,0],[2.72,0],[2.54,10.19],[2.52,0],[2.62,0]],"id":52385934}],"con":true,"img":false}]}
{"op":"mcm","clk":"11450138908","pt":1717318448869,"mc":[{"id":"1.229554907","rc":[{"atb":[[2.72,15.21],[2.42,73.69],[2.52,51.63],[2.62,32.3]],"id":52385934}],"con":true,"img":false}]}
{"op":"mcm","clk":"11450139297","pt":1717318453573,"mc":[{"id":"1.229554907","rc":[{"atl":[[19.5,2.66]],"id":52385888},{"atl":[[110,4.1],[120,0]],"id":52385895},{"atb":[[2.58,0],[2.62,41.99]],"id":52385934}],"con":true,"img":false}]}
{"op":"mcm","clk":"11450140218","pt":1717318463605,"mc":[{"id":"1.229554907","rc":[{"atb":[[2.58,9.93]],"id":52385934}],"con":true,"img":false}]}
{"op":"mcm","clk":"11450141102","pt":1717318473707,"mc":[{"id":"1.229554907","rc":[{"atb":[[2.54,0]],"id":52385934}],"con":true,"img":false}]}
{"op":"mcm","clk":"11450142080","pt":1717318485016,"mc":[{"id":"1.229554907","rc":[{"atb":[[160,0],[80,0]],"id":52385907},{"atb":[[3.2,0],[3.7,0]],"id":52385909},{"atb":[[130,0],[230,0]],"id":52385886},{"atb":[[550,0],[650,0]],"id":52385918},{"atb":[[4,0],[3.5,0]],"id":52385888},{"atb":[[270,0],[170,0]],"id":52385920},{"atb":[[18.5,4.48],[13.5,0]],"id":52385889},{"atb":[[18,0],[13,0]],"id":52385882},{"atb":[[7.2,0],[9.2,0]],"id":52385884},{"atb":[[330,0],[230,2]],"id":52385917},{"atb":[[9,0],[7,0]],"id":52385895},{"atb":[[18,0],[13,0]],"id":52385891},{"atb":[[16.5,0],[23,0]],"id":52385923},{"atb":[[550,0],[650,0]],"id":52385893},{"atb":[[2.4,0],[2.6,0]],"id":52385934},{"atb":[[9,0],[7,0]],"id":52385903},{"atb":[[16.5,0],[11.5,0]],"id":52385904},{"atb":[[10,0],[15,0]],"id":52385936},{"atb":[[2.54,0],[2.74,0]],"id":52385931},{"atb":[[4,0],[5,0]],"id":52385932}],"con":true,"img":false}]}
{"op":"mcm","clk":"11450142835","pt":1717318493532,"mc":[{"id":"1.229554907","rc":[{"atb":[[150,4.3],[170,2.92]],"id":52385920},{"atb":[[160,2.87],[180,4.1]],"id":52385917},{"atb":[[1.45,34.88],[1.43,36.5]],"id":52385895},{"atb":[[180,3.23],[200,3.41]],"id":52385893}],"con":true,"img":false}]}
{"op":"mcm","clk":"11450142846","pt":1717318493632,"mc":[{"id":"1.229554907","rc":[{"atb":[[210,3.71],[230,4.16]],"id":52385918},{"atb":[[1.45,34.88],[1.43,36.5]],"id":52385932}],"con":true,"img":false}]}
{"op":"mcm","clk":"11450144976","pt":1717318517683,"mc":[{"id":"1.229554907","rc":[{"atb":[[160,0.65],[80,3.08]],"id":52385907},{"atb":[[3.2,110.86],[3.7,38.71]],"id":52385909},{"atb":[[550,0.44],[650,0.16]],"id":52385918},{"atb":[[130,1.88],[230,0.45]],"id":52385886},{"atb":[[270,0.38],[170,4.37]],"id":52385920},{"atb":[[4,34.84],[3.5,97.56]],"id":52385888},{"atb":[[18.5,10.46],[13.5,19.51]],"id":52385889},{"atb":[[18,6.14],[13,20.32]],"id":52385882},{"atb":[[7.2,39.33],[9.2,12.74]],"id":52385884},{"atb":[[330,0.31],[230,3.06]],"id":52385917},{"atb":[[9,13.06],[7,40.65]],"id":52385895},{"atb":[[18,6.14],[13,20.32]],"id":52385891},{"atb":[[16.5,15.73],[23,4.75]],"id":52385923},{"atb":[[550,0.44],[650,0.16]],"id":52385893},{"atb":[[2.4,174.21],[2.6,65.33]],"id":52385934},{"atb":[[9,13.06],[7,40.65]],"id":52385903},{"atb":[[16.5,6.74],[11.5,23.22]],"id":52385904},{"atb":[[10,27.1],[15,7.46]],"id":52385936},{"atb":[[2.54,158.38],[2.74,60.07]],"id":52385931},{"atb":[[4,81.3],[5,26.13]],"id":52385932}],"con":true,"img":false}]}
{"op":"mcm","clk":"11450148408","pt":1717318557805,"mc":[{"id":"1.229554907","rc":[{"atb":[[38,2.7],[40,3.2]],"id":52385889},{"atb":[[1.78,0],[1.69,99.7]],"id":52385931}],"con":true,"img":false}]}
{"op":"mcm","clk":"11450148432","pt":1717318558117,"mc":[{"id":"1.229554907","rc":[{"atb":[[100,2],[110,3.94]],"id":52385907},{"atb":[[6.4,3.01],[7,0]],"id":52385888},{"atb":[[42,2.64],[44,0]],"id":52385889},{"atb":[[32,0],[30,2.62]],"id":52385882},{"atb":[[19,0],[13.5,3.15],[15,0]],"id":52385884},{"atb":[[180,0]],"id":52385917},{"atb":[[36,0],[38,2.92],[29,0]],"id":52385891},{"atb":[[520,0],[570,0],[620,0],[670,0]],"id":52385893},{"atb":[[14,2.01]],"id":52385903},{"atb":[[27,0],[28,4.3]],"id":52385904},{"atb":[[19,0],[19.5,3.48]],"id":52385936},{"atb":[[3.2,0],[3.05,7.65]],"id":52385931},{"atb":[[8,0],[5.5,0],[6,0],[7,0]],"id":52385932}],"con":true,"img":false}]}
{"op":"mcm","clk":"11450148482","pt":1717318558836,"mc":[{"id":"1.229554907","rc":[{"atb":[[18,3.08]],"id":52385884},{"atb":[[30,3.61]],"id":52385891},{"atb":[[560,0.19],[610,0.13],[660,0.08],[710,0.04]],"id":52385893},{"atb":[[5.6,22.75],[7.2,8.44],[6.2,15.09],[8.2,3.63]],"id":52385932}],"con":true,"img":false}]}
{"op":"mcm","clk":"11450148943","pt":1717318563937,"mc":[{"id":"1.229554907","rc":[{"atl":[[760,0],[770,2.61]],"id":52385923},{"atb":[[12,3.47]],"id":52385903}],"con":true,"img":false}]}
{"op":"mcm","clk":"11450149337","pt":1717318568118,"mc":[{"id":"1.229554907","rc":[{"atb":[[6,3.96],[6.6,0]],"id":52385888},{"atb":[[12.5,4.34],[14,0]],"id":52385884},{"atl":[[200,3.87],[210,0]],"id":52385891},{"atl":[[95,4.08],[100,0]],"id":52385904},{"atl":[[46,0],[48,4.25]],"id":52385936},{"atb":[[3.1,0],[2.98,7.92]],"id":52385931},{"atl":[[5.1,0],[5.2,3.42]],"id":52385931}],"con":true,"img":false}]}
{"op":"mcm","clk":"11450153391","pt":1717318609724,"mc":[{"id":"1.229554907","rc":[{"atb":[[2.72,0],[2.42,0],[2.52,0],[2.62,9.68]],"id":52385934}],"con":true,"img":false}]}
{"op":"mcm","clk":"11450153447","pt":1717318610474,"mc":[{"id":"1.229554907","rc":[{"atb":[[2.82,14.37],[2.72,30.42],[2.52,68.84],[2.62,58.13]],"id":52385934}],"con":true,"img":false}]}
{"op":"mcm","clk":"11450161059","pt":1717318685643,"mc":[{"id":"1.229554907","rc":[{"atb":[[16.5,0],[19,0],[23,0],[28,0]],"id":52385895}],"con":true,"img":false}]}
{"op":"mcm","clk":"11450161137","pt":1717318686315,"mc":[{"id":"1.229554907","rc":[{"atb":[[16,6.97],[18.5,4.48],[22,2.49],[27,1]],"id":52385895}],"con":true,"img":false}]}
{"op":"mcm","clk":"11450170656","pt":1717318790842,"mc":[{"id":"1.229554907","rc":[{"atb":[[40,5.76]],"id":52385889},{"atb":[[1.78,99.7],[1.69,0]],"id":52385931}],"con":true,"img":false}]}
{"op":"mcm","clk":"11450170662","pt":1717318790943,"mc":[{"id":"1.229554907","rc":[{"atb":[[38,0]],"id":52385889}],"con":true,"img":false}]}
{"op":"mcm","clk":"11450170675","pt":1717318791149,"mc":[{"id":"1.229554907","rc":[{"atb":[[100,5.86],[110,0]],"id":52385907},{"atb":[[6.4,0],[7,2.65]],"id":52385888},{"atb":[[42,0],[44,3.46]],"id":52385889},{"atb":[[32,4.52],[30,0]],"id":52385882},{"atb":[[18,0],[13.5,0],[15,4.37]],"id":52385884},{"atb":[[36,3.35],[38,0]],"id":52385891},{"atb":[[560,0],[610,0],[660,0],[710,0]],"id":52385893},{"atb":[[13,0],[14,5.29]],"id":52385903},{"atb":[[19.5,0],[19,3.9]],"id":52385936},{"atb":[[27,3.2],[28,0]],"id":52385904},{"atb":[[3.2,7.13],[3.05,0]],"id":52385931},{"atb":[[5.6,0],[7.2,0],[6.2,0],[8.2,0]],"id":52385932}],"con":true,"img":false}]}
{"op":"mcm","clk":"11450170731","pt":1717318791866,"mc":[{"id":"1.229554907","rc":[{"atb":[[19,2.91]],"id":52385884},{"atb":[[520,0.2],[570,0.14],[620,0.08],[670,0.04]],"id":52385893},{"atb":[[8,3.74],[5.5,23.25],[6,15.7],[7,8.72]],"id":52385932}],"con":true,"img":false}]}
{"op":"mcm","clk":"11450171568","pt":1717318801189,"mc":[{"id":"1.229554907","rc":[{"atb":[[6.6,4.43]],"id":52385888},{"atb":[[14,3.62]],"id":52385884},{"atl":[[200,0],[210,4.56]],"id":52385891},{"atl":[[760,4.56],[770,0]],"id":52385923},{"atb":[[13,3.57]],"id":52385903},{"atl":[[95,0],[100,3.87]],"id":52385904},{"atl":[[46,3.53],[48,0]],"id":52385936},{"atb":[[3.1,7.47]],"id":52385931},{"atl":[[5.1,4.4],[5.2,0]],"id":52385931}],"con":true,"img":false}]}
{"op":"mcm","clk":"11450171986","pt":1717318804700,"mc":[{"id":"1.229554907","rc":[{"atb":[[6,0]],"id":52385888},{"atb":[[12.5,0]],"id":52385884},{"atb":[[12,0]],"id":52385903},{"atb":[[2.98,0]],"id":52385931}],"con":true,"img":false}]}
{"op":"mcm","clk":"11450176906","pt":1717318857054,"mc":[{"id":"1.229554907","rc":[{"atb":[[160,0],[80,0]],"id":52385907},{"atb":[[3.2,0],[3.7,0]],"id":52385909},{"atb":[[550,0],[650,0]],"id":52385918},{"atb":[[130,0],[230,0]],"id":52385886},{"atb":[[4,0],[3.5,0]],"id":52385888},{"atb":[[270,0],[170,2.92]],"id":52385920},{"atb":[[18.5,4.48],[13.5,0]],"id":52385889},{"atb":[[18,0],[13,0]],"id":52385882},{"atb":[[7.2,0],[9.2,0]],"id":52385884},{"atb":[[330,0],[230,2]],"id":52385917},{"atb":[[9,0],[7,0]],"id":52385895},{"atb":[[16.5,0],[23,0]],"id":52385923},{"atb":[[18,0],[13,0]],"id":52385891},{"atb":[[550,0],[650,0]],"id":52385893},{"atb":[[2.4,0],[2.6,0]],"id":52385934},{"atb":[[9,0],[7,0]],"id":52385903},{"atb":[[16.5,0],[11.5,0]],"id":52385904},{"atb":[[10,0],[15,0]],"id":52385936},{"atb":[[2.54,0],[2.74,0]],"id":52385931},{"atb":[[4,0],[5,0]],"id":52385932}],"con":true,"img":false}]}
{"op":"mcm","clk":"11450179017","pt":1717318877972,"mc":[{"id":"1.229554907","rc":[{"atb":[[180,3.18]],"id":52385917}],"con":true,"img":false}]}
{"op":"mcm","clk":"11450179937","pt":1717318888187,"mc":[{"id":"1.229554907","rc":[{"atb":[[160,0.65],[80,3.08]],"id":52385907},{"atb":[[3.2,110.86],[3.7,38.71]],"id":52385909},{"atb":[[550,0.44],[650,0.16]],"id":52385918},{"atb":[[130,1.88],[230,0.45]],"id":52385886},{"atb":[[270,0.38],[170,4.37]],"id":52385920},{"atb":[[4,34.84],[3.5,97.56]],"id":52385888},{"atb":[[18.5,10.46],[13.5,19.51]],"id":52385889},{"atb":[[18,6.14],[13,20.32]],"id":52385882},{"atb":[[7.2,39.33],[9.2,12.74]],"id":52385884},{"atb":[[330,0.31],[230,3.06]],"id":52385917},{"atb":[[9,13.06],[7,40.65]],"id":52385895},{"atb":[[18,6.14],[13,20.32]],"id":52385891},{"atb":[[16.5,15.73],[23,4.75]],"id":52385923},{"atb":[[550,0.44],[650,0.16]],"id":52385893},{"atb":[[2.4,174.21],[2.6,65.33]],"id":52385934},{"atb":[[9,13.06],[7,40.65]],"id":52385903},{"atb":[[16.5,6.74],[11.5,23.22]],"id":52385904},{"atb":[[10,27.1],[15,7.46]],"id":52385936},{"atb":[[2.54,158.38],[2.74,60.07]],"id":52385931},{"atb":[[4,81.3],[5,26.13]],"id":52385932}],"con":true,"img":false}]}
{"op":"mcm","clk":"11450180538","pt":1717318894334,"mc":[{"id":"1.229554907","rc":[{"atb":[[38,2.7],[40,3.2]],"id":52385889},{"atb":[[1.78,0],[1.69,99.7]],"id":52385931}],"con":true,"img":false}]}
{"op":"mcm","clk":"11450180571","pt":1717318894646,"mc":[{"id":"1.229554907","rc":[{"atb":[[100,2],[110,4.27]],"id":52385907},{"atb":[[6.4,2.96],[7,0]],"id":52385888},{"atb":[[42,3.99],[44,0]],"id":52385889},{"atb":[[32,0],[30,4.58]],"id":52385882},{"atb":[[19,0],[13.5,2.89],[15,0]],"id":52385884},{"atb":[[180,0]],"id":52385917},{"atb":[[36,0],[38,3.75]],"id":52385891},{"atb":[[14,2.01]],"id":52385903},{"atb":[[19,0],[19.5,2.78]],"id":52385936},{"atb":[[27,0],[28,3.45]],"id":52385904},{"atb":[[3.2,0],[3.05,7.65]],"id":52385931}],"con":true,"img":false}]}
{"op":"mcm","clk":"11450180642","pt":1717318895370,"mc":[{"id":"1.229554907","rc":[{"atb":[[18,3.08]],"id":52385884}],"con":true,"img":false}]}
{"op":"mcm","clk":"11450180701","pt":1717318895842,"mc":[{"id":"1.229554907","rc":[{"atb":[[6.6,0]],"id":52385888},{"atb":[[14,0]],"id":52385884},{"atl":[[200,3.63],[210,0]],"id":52385891},{"atl":[[760,0],[770,4.07]],"id":52385923},{"atl":[[46,0],[48,4.56]],"id":52385936},{"atl":[[95,2.65],[100,0]],"id":52385904},{"atb":[[3.1,0]],"id":52385931},{"atl":[[5.1,0],[5.2,4.7]],"id":52385931}],"con":true,"img":false}]}
{"op":"mcm","clk":"11450180897","pt":1717318897864,"mc":[{"id":"1.229554907","rc":[{"atb":[[38,0],[40,5.76]],"id":52385889},{"atb":[[1.78,99.7],[1.69,0]],"id":52385931}],"con":true,"img":false}]}
{"op":"mcm","clk":"11450180932","pt":1717318898199,"mc":[{"id":"1.229554907","rc":[{"atb":[[100,5.57],[110,0]],"id":52385907},{"atb":[[7,3.96]],"id":52385888},{"atb":[[42,0],[44,3.45]],"id":52385889},{"atb":[[32,3.9],[30,0]],"id":52385882},{"atb":[[15,3.1]],"id":52385884},{"atb":[[36,3.51],[38,0]],"id":52385891},{"atb":[[14,5.35]],"id":52385903},{"atb":[[27,4.64],[28,0]],"id":52385904},{"atb":[[19.5,0],[19,3.26]],"id":52385936},{"atb":[[3.2,7.13]],"id":52385931}],"con":true,"img":false}]}
{"op":"mcm","clk":"11450181112","pt":1717318899946,"mc":[{"id":"1.229554907","rc":[{"atl":[[200,0],[210,4.17]],"id":52385891},{"atl":[[760,3.66]],"id":52385923},{"atl":[[46,4.35],[48,0]],"id":52385936},{"atl":[[95,0],[100,2.72]],"id":52385904}],"con":true,"img":false}]}
{"op":"mcm","clk":"11450181121","pt":1717318900048,"mc":[{"id":"1.229554907","rc":[{"atl":[[770,0]],"id":52385923},{"atl":[[5.1,3.18],[5.2,0]],"id":52385931}],"con":true,"img":false}]}
{"op":"mcm","clk":"11450187807","pt":1717318969226,"mc":[{"id":"1.229554907","rc":[{"atb":[[30,0]],"id":52385891}],"con":true,"img":false}]}
{"op":"mcm","clk":"11450187885","pt":1717318970054,"mc":[{"id":"1.229554907","rc":[{"atb":[[29,3.74]],"id":52385891}],"con":true,"img":false}]}
{"op":"mcm","clk":"11450191828","pt":1717319011591,"mc":[{"id":"1.229554907","rc":[{"atb":[[18,0]],"id":52385884}],"con":true,"img":false}]}
{"op":"mcm","clk":"11450191896","pt":1717319012315,"mc":[{"id":"1.229554907","rc":[{"atb":[[19,2.91]],"id":52385884}],"con":true,"img":false}]}
{"op":"mcm","clk":"11450197759","pt":1717319076383,"mc":[{"id":"1.229554907","rc":[{"atb":[[38,2.7],[40,3.2]],"id":52385889},{"atb":[[1.78,0],[1.69,99.7]],"id":52385931}],"con":true,"img":false}]}
{"op":"mcm","clk":"11450197782","pt":1717319076694,"mc":[{"id":"1.229554907","rc":[{"atb":[[100,2],[110,3.74]],"id":52385907},{"atb":[[7,0]],"id":52385888},{"atb":[[42,3.51],[44,0]],"id":52385889},{"atb":[[32,0],[30,3.24]],"id":52385882},{"atb":[[15,0]],"id":52385884},{"atb":[[36,0],[38,2.86]],"id":52385891},{"atb":[[520,0],[570,0],[620,0],[670,0]],"id":52385893},{"atb":[[14,2.01]],"id":52385903},{"atb":[[19,0],[19.5,2.84]],"id":52385936},{"atb":[[27,0],[28,3.47]],"id":52385904},{"atb":[[3.2,0]],"id":52385931},{"atb":[[8,0],[5.5,0],[6,0],[7,0]],"id":52385932}],"con":true,"img":false}]}
{"op":"mcm","clk":"11450197813","pt":1717319077012,"mc":[{"id":"1.229554907","rc":[{"atl":[[200,4.03],[210,0]],"id":52385891},{"atl":[[760,0],[770,4.05]],"id":52385923},{"atl":[[46,0],[48,3.59]],"id":52385936},{"atl":[[95,2.73],[100,0]],"id":52385904},{"atl":[[5.1,0],[5.2,3.86]],"id":52385931}],"con":true,"img":false}]}
{"op":"mcm","clk":"11450197847","pt":1717319077373,"mc":[{"id":"1.229554907","rc":[{"atb":[[520,0.2],[570,0.14],[620,0.08],[670,0.04]],"id":52385893},{"atb":[[8,3.74],[5.5,23.25],[6,15.7],[7,8.72]],"id":52385932}],"con":true,"img":false}]}
{"op":"mcm","clk":"11450197912","pt":1717319078204,"mc":[{"id":"1.229554907","rc":[{"atl":[[760,4.58]],"id":52385923},{"atl":[[200,0]],"id":52385891},{"atl":[[95,0],[100,3.55]],"id":52385904},{"atl":[[46,3.23],[48,0]],"id":52385936},{"atl":[[5.1,3.6],[5.2,0]],"id":52385931}],"con":true,"img":false}]}
{"op":"mcm","clk":"11450197921","pt":1717319078301,"mc":[{"id":"1.229554907","rc":[{"atl":[[770,0]],"id":52385923},{"atl":[[210,2.79]],"id":52385891}],"con":true,"img":false}]}
{"op":"mcm","clk":"11450197969","pt":1717319078815,"mc":[{"id":"1.229554907","rc":[{"atb":[[29,0]],"id":52385891}],"con":true,"img":false}]}
{"op":"mcm","clk":"11450198042","pt":1717319079492,"mc":[{"id":"1.229554907","rc":[{"atb":[[30,3.61]],"id":52385891}],"con":true,"img":false}]}
{"op":"mcm","clk":"11450198088","pt":1717319080011,"mc":[{"id":"1.229554907","rc":[{"atb":[[100,5.15],[110,0]],"id":52385907},{"atb":[[7,3.53]],"id":52385888},{"atb":[[42,0],[44,4.15]],"id":52385889},{"atb":[[15,3.25]],"id":52385884},{"atl":[[760,0],[770,4.6]],"id":52385923},{"atb":[[14,6.03]],"id":52385903},{"atb":[[27,4.42]],"id":52385904},{"atl":[[95,3.83]],"id":52385904},{"atb":[[3.2,7.13]],"id":52385931},{"atl":[[5.1,0],[5.2,3.35]],"id":52385931}],"con":true,"img":false}]}
{"op":"mcm","clk":"11450198097","pt":1717319080113,"mc":[{"id":"1.229554907","rc":[{"atb":[[28,0]],"id":52385904},{"atl":[[100,0]],"id":52385904}],"con":true,"img":false}]}
{"op":"mcm","clk":"11450198110","pt":1717319080313,"mc":[{"id":"1.229554907","rc":[{"atb":[[30,0]],"id":52385891}],"con":true,"img":false}]}
{"op":"mcm","clk":"11450198162","pt":1717319080895,"mc":[{"id":"1.229554907","rc":[{"atb":[[100,2],[110,4.47]],"id":52385907},{"atb":[[7,0]],"id":52385888},{"atb":[[42,3.57],[44,0]],"id":52385889},{"atb":[[15,0]],"id":52385884},{"atl":[[760,3.71],[770,0]],"id":52385923},{"atb":[[14,2.01]],"id":52385903},{"atb":[[3.2,0]],"id":52385931},{"atl":[[5.1,4.36],[5.2,0]],"id":52385931}],"con":true,"img":false}]}
{"op":"mcm","clk":"11450198169","pt":1717319080995,"mc":[{"id":"1.229554907","rc":[{"atb":[[30,3.61]],"id":52385891}],"con":true,"img":false}]}
{"op":"mcm","clk":"11450198219","pt":1717319081522,"mc":[{"id":"1.229554907","rc":[{"atb":[[19,0]],"id":52385884}],"con":true,"img":false}]}
{"op":"mcm","clk":"11450198276","pt":1717319082096,"mc":[{"id":"1.229554907","rc":[{"atb":[[27,0],[28,4.34]],"id":52385904},{"atl":[[95,0],[100,4.47]],"id":52385904}],"con":true,"img":false}]}
{"op":"mcm","clk":"11450198336","pt":1717319082715,"mc":[{"id":"1.229554907","rc":[{"atb":[[110,0]],"id":52385907},{"atb":[[7,4.12]],"id":52385888},{"atb":[[44,4.44]],"id":52385889},{"atb":[[14,6.47]],"id":52385903}],"con":true,"img":false}]}
{"op":"mcm","clk":"11450198348","pt":1717319082816,"mc":[{"id":"1.229554907","rc":[{"atb":[[42,0]],"id":52385889}],"con":true,"img":false}]}
{"op":"mcm","clk":"11450198600","pt":1717319085423,"mc":[{"id":"1.229554907","rc":[{"atb":[[19,2.91]],"id":52385884}],"con":true,"img":false}]}
{"op":"mcm","clk":"11450198736","pt":1717319086839,"mc":[{"id":"1.229554907","rc":[{"atb":[[38,0],[40,5.76]],"id":52385889},{"atb":[[1.78,99.7],[1.69,0]],"id":52385931}],"con":true,"img":false}]}
{"op":"mcm","clk":"11450199253","pt":1717319092101,"mc":[{"id":"1.229554907","rc":[{"atb":[[27,3.2],[28,0]],"id":52385904}],"con":true,"img":false}]}
{"op":"mcm","clk":"11450199306","pt":1717319092616,"mc":[{"id":"1.229554907","rc":[{"atb":[[100,5.42]],"id":52385907},{"atb":[[32,4.26],[30,0]],"id":52385882},{"atb":[[15,4.49]],"id":52385884},{"atb":[[36,3.92],[38,0]],"id":52385891},{"atb":[[19.5,0],[19,3.06]],"id":52385936},{"atb":[[3.2,7.13]],"id":52385931}],"con":true,"img":false}]}
{"op":"mcm","clk":"11450208333","pt":1717319182607,"mc":[{"id":"1.229554907","rc":[{"atb":[[160,0],[80,0]],"id":52385907},{"atb":[[3.2,0],[3.7,0]],"id":52385909},{"atb":[[550,0],[650,0]],"id":52385918},{"atb":[[130,0],[230,0]],"id":52385886},{"atb":[[4,0],[3.5,0]],"id":52385888},{"atb":[[270,0],[170,2.92]],"id":52385920},{"atb":[[18.5,4.48],[13.5,0]],"id":52385889},{"atb":[[18,0],[13,0]],"id":52385882},{"atb":[[7.2,0],[9.2,0]],"id":52385884},{"atb":[[330,0],[230,2]],"id":52385917},{"atb":[[9,0],[7,0]],"id":52385895},{"atb":[[18,0],[13,0]],"id":52385891},{"atb":[[16.5,0],[23,0]],"id":52385923},{"atb":[[550,0],[650,0]],"id":52385893},{"atb":[[2.4,0],[2.6,0]],"id":52385934},{"atb":[[9,0],[7,0]],"id":52385903},{"atb":[[10,0],[15,0]],"id":52385936},{"atb":[[16.5,0],[11.5,0]],"id":52385904},{"atb":[[2.54,0],[2.74,0]],"id":52385931},{"atb":[[4,0],[5,0]],"id":52385932}],"con":true,"img":false}]}
{"op":"mcm","clk":"11450210546","pt":1717319203788,"mc":[{"id":"1.229554907","rc":[{"atb":[[180,4.07]],"id":52385917}],"con":true,"img":false}]}
{"op":"mcm","clk":"11450211546","pt":1717319214150,"mc":[{"id":"1.229554907","rc":[{"atb":[[160,0.65],[80,3.08]],"id":52385907},{"atb":[[3.2,110.86],[3.7,38.71]],"id":52385909},{"atb":[[130,1.88],[230,0.45]],"id":52385886},{"atb":[[550,0.44],[650,0.16]],"id":52385918},{"atb":[[4,34.84],[3.5,97.56]],"id":52385888},{"atb":[[270,0.38],[170,4.37]],"id":52385920},{"atb":[[18.5,10.46],[13.5,19.51]],"id":52385889},{"atb":[[18,6.14],[13,20.32]],"id":52385882},{"atb":[[7.2,39.33],[9.2,12.74]],"id":52385884},{"atb":[[330,0.31],[230,3.06]],"id":52385917},{"atb":[[9,13.06],[7,40.65]],"id":52385895},{"atb":[[16.5,15.73],[23,4.75]],"id":52385923},{"atb":[[18,6.14],[13,20.32]],"id":52385891},{"atb":[[550,0.44],[650,0.16]],"id":52385893},{"atb":[[2.4,174.21],[2.6,65.33]],"id":52385934},{"atb":[[9,13.06],[7,40.65]],"id":52385903},{"atb":[[10,27.1],[15,7.46]],"id":52385936},{"atb":[[16.5,6.74],[11.5,23.22]],"id":52385904},{"atb":[[2.54,158.38],[2.74,60.07]],"id":52385931},{"atb":[[4,81.3],[5,26.13]],"id":52385932}],"con":true,"img":false}]}
{"op":"mcm","clk":"11450212047","pt":1717319219429,"mc":[{"id":"1.229554907","rc":[{"atb":[[30,0]],"id":52385891}],"con":true,"img":false}]}
{"op":"mcm","clk":"11450212108","pt":1717319220104,"mc":[{"id":"1.229554907","rc":[{"atb":[[29,3.74]],"id":52385891}],"con":true,"img":false}]}
{"op":"mcm","clk":"11450216164","pt":1717319258670,"mc":[{"id":"1.229554907","rc":[{"atb":[[38,2.7],[40,3.2]],"id":52385889},{"atb":[[1.78,0],[1.69,99.7]],"id":52385931}],"con":true,"img":false}]}
{"op":"mcm","clk":"11450216200","pt":1717319258975,"mc":[{"id":"1.229554907","rc":[{"atb":[[100,2],[110,3.5]],"id":52385907},{"atb":[[7,0]],"id":52385888},{"atb":[[38,0],[40,5.76],[42,4.26],[44,0]],"id":52385889},{"atb":[[15,0]],"id":52385884},{"atb":[[180,0]],"id":52385917},{"atb":[[38,3.78],[29,0]],"id":52385891},{"atb":[[14,2.01]],"id":52385903},{"atb":[[1.78,99.7],[1.69,0]],"id":52385931}],"con":true,"img":false}]}
{"op":"mcm","clk":"11450216209","pt":1717319259081,"mc":[{"id":"1.229554907","rc":[{"atb":[[32,0],[30,3.52]],"id":52385882},{"atb":[[36,0]],"id":52385891},{"atb":[[520,0],[570,0],[620,0],[670,0]],"id":52385893},{"atb":[[27,0],[28,3.89]],"id":52385904},{"atb":[[3.2,0]],"id":52385931},{"atb":[[8,0],[5.5,0],[6,0],[7,0]],"id":52385932}],"con":true,"img":false}]}
{"op":"mcm","clk":"11450216228","pt":1717319259286,"mc":[{"id":"1.229554907","rc":[{"atl":[[200,3.1],[210,0]],"id":52385891},{"atl":[[760,0],[770,4.19]],"id":52385923},{"atl":[[95,4.56],[100,0]],"id":52385904},{"atl":[[46,0],[48,2.75]],"id":52385936},{"atl":[[5.1,0],[5.2,2.92]],"id":52385931}],"con":true,"img":false}]}
{"op":"mcm","clk":"11450216260","pt":1717319259696,"mc":[{"id":"1.229554907","rc":[{"atb":[[29,3.74]],"id":52385891}],"con":true,"img":false}]}
{"op":"mcm","clk":"11450216268","pt":1717319259755,"mc":[{"id":"1.229554907","rc":[{"atb":[[520,0.2],[570,0.14],[620,0.08],[670,0.04]],"id":52385893},{"atb":[[8,3.74],[5.5,23.25],[6,15.7],[7,8.72]],"id":52385932}],"con":true,"img":false}]}
{"op":"mcm","clk":"11450216349","pt":1717319260485,"mc":[{"id":"1.229554907","rc":[{"atb":[[29,0]],"id":52385891}],"con":true,"img":false}]}
{"op":"mcm","clk":"11450216373","pt":1717319260701,"mc":[{"id":"1.229554907","rc":[{"atb":[[19,0]],"id":52385884}],"con":true,"img":false}]}
{"op":"mcm","clk":"11450216435","pt":1717319261264,"mc":[{"id":"1.229554907","rc":[{"atb":[[100,6.47]],"id":52385907},{"atb":[[7,4.08]],"id":52385888},{"atb":[[42,0],[44,3.62]],"id":52385889},{"atb":[[32,4.2],[30,0]],"id":52385882},{"atb":[[15,3.65]],"id":52385884},{"atb":[[36,4.69],[38,0],[30,3.61]],"id":52385891},{"atb":[[14,5.53]],"id":52385903},{"atb":[[27,3.69]],"id":52385904},{"atb":[[3.2,7.13]],"id":52385931}],"con":true,"img":false}]}
{"op":"mcm","clk":"11450216443","pt":1717319261369,"mc":[{"id":"1.229554907","rc":[{"atb":[[110,0]],"id":52385907},{"atb":[[19,2.91]],"id":52385884},{"atb":[[28,0]],"id":52385904}],"con":true,"img":false}]}
{"op":"mcm","clk":"11450217531","pt":1717319271809,"mc":[{"id":"1.229554907","rc":[{"atl":[[200,0],[210,4.52]],"id":52385891},{"atl":[[760,3.59],[770,0]],"id":52385923},{"atl":[[95,0],[100,3.55]],"id":52385904},{"atl":[[46,3.55],[48,0]],"id":52385936},{"atl":[[5.1,4.05],[5.2,0]],"id":52385931}],"con":true,"img":false}]}
{"op":"mcm","clk":"11450227115","pt":1717319373440,"mc":[{"id":"1.229554907","rc":[{"atb":[[30,0]],"id":52385891}],"con":true,"img":false}]}
{"op":"mcm","clk":"11450227183","pt":1717319374167,"mc":[{"id":"1.229554907","rc":[{"atb":[[29,3.74]],"id":52385891}],"con":true,"img":false}]}
{"op":"mcm","clk":"11450228413","pt":1717319388717,"mc":[{"id":"1.229554907","rc":[{"atb":[[160,0],[80,0]],"id":52385907},{"atb":[[3.2,0],[3.7,0]],"id":52385909},{"atb":[[130,0],[230,0]],"id":52385886},{"atb":[[550,0],[650,0]],"id":52385918},{"atb":[[4,0],[3.5,0]],"id":52385888},{"atb":[[270,0],[170,2.92]],"id":52385920},{"atb":[[18.5,4.48],[13.5,0]],"id":52385889},{"atb":[[18,0],[13,0]],"id":52385882},{"atb":[[7.2,0],[9.2,0]],"id":52385884},{"atb":[[330,0],[230,2]],"id":52385917},{"atb":[[9,0],[7,0]],"id":52385895},{"atb":[[18,0],[13,0]],"id":52385891},{"atb":[[16.5,0],[23,0]],"id":52385923},{"atb":[[550,0],[650,0]],"id":52385893},{"atb":[[2.4,0],[2.6,0]],"id":52385934},{"atb":[[9,0],[7,0]],"id":52385903},{"atb":[[10,0],[15,0]],"id":52385936},{"atb":[[16.5,0],[11.5,0]],"id":52385904},{"atb":[[2.54,0],[2.74,0]],"id":52385931},{"atb":[[4,0],[5,0]],"id":52385932}],"con":true,"img":false}]}
{"op":"mcm","clk":"11450230358","pt":1717319410122,"mc":[{"id":"1.229554907","rc":[{"atb":[[160,0.65],[80,3.08]],"id":52385907},{"atb":[[3.2,110.86],[3.7,38.71]],"id":52385909},{"atb":[[130,1.88],[230,0.45]],"id":52385886},{"atb":[[550,0.44],[650,0.16]],"id":52385918},{"atb":[[4,34.84],[3.5,97.56]],"id":52385888},{"atb":[[270,0.38],[170,4.37]],"id":52385920},{"atb":[[18.5,10.46],[13.5,19.51]],"id":52385889},{"atb":[[18,6.14],[13,20.32]],"id":52385882},{"atb":[[7.2,39.33],[9.2,12.74]],"id":52385884},{"atb":[[330,0.31],[230,3.06]],"id":52385917},{"atb":[[9,13.06],[7,40.65]],"id":52385895},{"atb":[[18,6.14],[13,20.32]],"id":52385891},{"atb":[[16.5,15.73],[23,4.75]],"id":52385923},{"atb":[[550,0.44],[650,0.16]],"id":52385893},{"atb":[[2.4,174.21],[2.6,65.33]],"id":52385934},{"atb":[[9,13.06],[7,40.65]],"id":52385903},{"atb":[[16.5,6.74],[11.5,23.22]],"id":52385904},{"atb":[[10,27.1],[15,7.46]],"id":52385936},{"atb":[[2.54,158.38],[2.74,60.07]],"id":52385931},{"atb":[[4,81.3],[5,26.13]],"id":52385932}],"con":true,"img":false}]}
{"op":"mcm","clk":"11450230387","pt":1717319410426,"mc":[{"id":"1.229554907","rc":[{"atb":[[180,2.84]],"id":52385917}],"con":true,"img":false}]}
{"op":"mcm","clk":"11450232863","pt":1717319436442,"mc":[{"id":"1.229554907","rc":[{"atb":[[38,2.7],[40,3.2]],"id":52385889},{"atb":[[1.78,0],[1.69,99.7]],"id":52385931}],"con":true,"img":false}]}
{"op":"mcm","clk":"11450232893","pt":1717319436754,"mc":[{"id":"1.229554907","rc":[{"atb":[[100,2],[110,3.65]],"id":52385907},{"atb":[[7,0]],"id":52385888},{"atb":[[42,3.44],[44,0]],"id":52385889},{"atb":[[32,0],[30,4.58]],"id":52385882},{"atb":[[15,0]],"id":52385884},{"atb":[[180,0]],"id":52385917},{"atb":[[36,0],[38,4.19],[29,0]],"id":52385891},{"atb":[[520,0],[570,0],[620,0],[670,0]],"id":52385893},{"atb":[[14,2.01]],"id":52385903},{"atb":[[27,0],[28,4.55]],"id":52385904},{"atb":[[3.2,0]],"id":52385931}],"con":true,"img":false}]}
{"op":"mcm","clk":"11450232903","pt":1717319436863,"mc":[{"id":"1.229554907","rc":[{"atb":[[8,0],[5.5,0],[6,0],[7,0]],"id":52385932}],"con":true,"img":false}]}
{"op":"mcm","clk":"11450232911","pt":1717319436961,"mc":[{"id":"1.229554907","rc":[{"atl":[[200,4.29],[210,0]],"id":52385891},{"atl":[[760,0],[770,2.83]],"id":52385923},{"atl":[[95,2.79],[100,0]],"id":52385904},{"atb":[[19,0],[19.5,4.25]],"id":52385936},{"atl":[[46,0],[48,3.3]],"id":52385936},{"atl":[[5.1,0],[5.2,4.35]],"id":52385931}],"con":true,"img":false}]}
{"op":"mcm","clk":"11450232939","pt":1717319437276,"mc":[{"id":"1.229554907","rc":[{"atb":[[38,0],[40,5.76]],"id":52385889},{"atb":[[1.78,99.7],[1.69,0]],"id":52385931}],"con":true,"img":false}]}
{"op":"mcm","clk":"11450232955","pt":1717319437475,"mc":[{"id":"1.229554907","rc":[{"atb":[[30,3.61]],"id":52385891},{"atb":[[560,0.19],[610,0.13],[660,0.08],[710,0.04]],"id":52385893}],"con":true,"img":false}]}
{"op":"mcm","clk":"11450232966","pt":1717319437580,"mc":[{"id":"1.229554907","rc":[{"atb":[[100,5.54],[110,0]],"id":52385907},{"atb":[[7,2.81]],"id":52385888},{"atb":[[42,0],[44,4.15]],"id":52385889},{"atb":[[32,3.66],[30,0]],"id":52385882},{"atb":[[15,3.23]],"id":52385884},{"atb":[[36,2.8],[38,0]],"id":52385891},{"atb":[[14,6.03]],"id":52385903},{"atb":[[27,3.2],[28,0]],"id":52385904},{"atb":[[3.2,7.13]],"id":52385931}],"con":true,"img":false}]}
{"op":"mcm","clk":"11450232977","pt":1717319437649,"mc":[{"id":"1.229554907","rc":[{"atb":[[8,3.74],[5.5,23.25],[6,15.7],[7,8.72]],"id":52385932}],"con":true,"img":false}]}
{"op":"mcm","clk":"11450233036","pt":1717319438366,"mc":[{"id":"1.229554907","rc":[{"atb":[[30,0]],"id":52385891},{"atb":[[560,0],[610,0],[660,0],[710,0]],"id":52385893}],"con":true,"img":false}]}
{"op":"mcm","clk":"11450233079","pt":1717319438776,"mc":[{"id":"1.229554907","rc":[{"atb":[[38,2.7],[40,3.2]],"id":52385889},{"atb":[[1.78,0],[1.69,99.7]],"id":52385931}],"con":true,"img":false}]}
{"op":"mcm","clk":"11450233104","pt":1717319439087,"mc":[{"id":"1.229554907","rc":[{"atb":[[100,2],[110,4.07]],"id":52385907},{"atb":[[7,0]],"id":52385888},{"atb":[[42,3.15],[44,0]],"id":52385889},{"atb":[[32,0],[30,3.19]],"id":52385882},{"atb":[[15,0]],"id":52385884},{"atb":[[36,0],[38,3.72]],"id":52385891},{"atl":[[200,0],[210,3.96]],"id":52385891},{"atl":[[760,4.19],[770,0]],"id":52385923},{"atb":[[560,0.19],[610,0.13],[660,0.08],[710,0.04]],"id":52385893},{"atb":[[14,2.01]],"id":52385903},{"atb":[[27,0],[28,3.63]],"id":52385904},{"atl":[[95,0],[100,2.76]],"id":52385904},{"atl":[[46,4.08],[48,0]],"id":52385936},{"atb":[[3.2,0]],"id":52385931},{"atl":[[5.1,3.82],[5.2,0]],"id":52385931},{"atb":[[8,0],[5.5,0],[6,0],[7,0]],"id":52385932}],"con":true,"img":false}]}
{"op":"mcm","clk":"11450233112","pt":1717319439153,"mc":[{"id":"1.229554907","rc":[{"atb":[[30,3.61]],"id":52385891}],"con":true,"img":false}]}
{"op":"mcm","clk":"11450233177","pt":1717319439865,"mc":[{"id":"1.229554907","rc":[{"atb":[[5.6,22.75],[7.2,8.44],[6.2,15.09],[8.2,3.63]],"id":52385932}],"con":true,"img":false}]}
{"op":"mcm","clk":"11450233197","pt":1717319440074,"mc":[{"id":"1.229554907","rc":[{"atb":[[100,6.23],[110,0]],"id":52385907},{"atb":[[7,2.86]],"id":52385888},{"atb":[[42,0],[44,3.14]],"id":52385889},{"atb":[[32,3.99],[30,0]],"id":52385882},{"atb":[[15,2.74]],"id":52385884},{"atb":[[36,3.58],[38,0]],"id":52385891},{"atl":[[200,3.18],[210,0]],"id":52385891},{"atl":[[760,0],[770,4.44]],"id":52385923},{"atb":[[14,5.57]],"id":52385903},{"atb":[[27,3.28],[28,0]],"id":52385904},{"atl":[[95,4.14],[100,0]],"id":52385904},{"atb":[[19.5,0],[19,3.37]],"id":52385936},{"atl":[[46,0],[48,3.71]],"id":52385936},{"atb":[[3.2,7.13]],"id":52385931},{"atl":[[5.1,0],[5.2,3.76]],"id":52385931}],"con":true,"img":false}]}
{"op":"mcm","clk":"11450233318","pt":1717319441272,"mc":[{"id":"1.229554907","rc":[{"atb":[[42,4.69],[44,0]],"id":52385889}],"con":true,"img":false}]}
{"op":"mcm","clk":"11450233380","pt":1717319441847,"mc":[{"id":"1.229554907","rc":[{"atb":[[15,0]],"id":52385884},{"atb":[[14,2.01]],"id":52385903}],"con":true,"img":false}]}
{"op":"mcm","clk":"11450233584","pt":1717319443796,"mc":[{"id":"1.229554907","rc":[{"atb":[[42,0],[44,2.69]],"id":52385889},{"atb":[[15,2.92]],"id":52385884},{"atl":[[200,0],[210,2.94]],"id":52385891},{"atl":[[760,2.88],[770,0]],"id":52385923},{"atb":[[14,5.45]],"id":52385903},{"atl":[[46,3.52],[48,0]],"id":52385936},{"atl":[[95,0],[100,4.58]],"id":52385904},{"atl":[[5.1,2.75],[5.2,0]],"id":52385931}],"con":true,"img":false}]}
{"op":"mcm","clk":"11450233670","pt":1717319444751,"mc":[{"id":"1.229554907","rc":[{"atb":[[660,0],[710,0]],"id":52385893}],"con":true,"img":false}]}
{"op":"mcm","clk":"11450233682","pt":1717319444860,"mc":[{"id":"1.229554907","rc":[{"atb":[[560,0],[610,0]],"id":52385893}],"con":true,"img":false}]}
{"op":"mcm","clk":"11450233695","pt":1717319444961,"mc":[{"id":"1.229554907","rc":[{"atb":[[30,0]],"id":52385891}],"con":true,"img":false}]}
{"op":"mcm","clk":"11450233746","pt":1717319445481,"mc":[{"id":"1.229554907","rc":[{"atb":[[40,5.76]],"id":52385889},{"atb":[[620,0.08],[670,0.04]],"id":52385893},{"atb":[[1.69,0]],"id":52385931}],"con":true,"img":false}]}
{"op":"mcm","clk":"11450233758","pt":1717319445580,"mc":[{"id":"1.229554907","rc":[{"atb":[[38,0]],"id":52385889},{"atb":[[520,0.2],[570,0.14]],"id":52385893},{"atb":[[1.78,99.7]],"id":52385931},{"atb":[[5.6,0],[7.2,0],[6.2,0],[8.2,0]],"id":52385932}],"con":true,"img":false}]}
{"op":"mcm","clk":"11450233778","pt":1717319445790,"mc":[{"id":"1.229554907","rc":[{"atb":[[29,3.74]],"id":52385891}],"con":true,"img":false}]}
{"op":"mcm","clk":"11450233826","pt":1717319446267,"mc":[{"id":"1.229554907","rc":[{"atb":[[8,3.74],[5.5,23.25],[6,15.7],[7,8.72]],"id":52385932}],"con":true,"img":false}]}
{"op":"mcm","clk":"11450234666","pt":1717319455092,"mc":[{"id":"1.229554907","rc":[{"atb":[[580,2],[500,0]],"id":52385918},{"atb":[[38,2.7],[40,3.2]],"id":52385889},{"atb":[[26,4],[29,5.04]],"id":52385882},{"atb":[[23,0],[24,4.35]],"id":52385904},{"atb":[[1.78,0],[1.68,99.7]],"id":52385931}],"con":true,"img":false}]}
{"op":"mcm","clk":"11450234699","pt":1717319455358,"mc":[{"id":"1.229554907","rc":[{"atb":[[27,0]],"id":52385904}],"con":true,"img":false}]}
{"op":"mcm","clk":"11450234862","pt":1717319457083,"mc":[{"id":"1.229554907","rc":[{"atb":[[120,3.84]],"id":52385907},{"atb":[[5.8,3.12],[5.7,0]],"id":52385909},{"atb":[[42,4.09],[44,0]],"id":52385889},{"atb":[[32,0],[30,3.45]],"id":52385882},{"atb":[[14,3.67],[15,0]],"id":52385884},{"atb":[[36,0],[38,2.71]],"id":52385891},{"atb":[[13.5,4.29],[14,2.01]],"id":52385903},{"atb":[[28,3.77]],"id":52385904},{"atb":[[19,0],[21,3.03]],"id":52385936},{"atb":[[3.2,0]],"id":52385931}],"con":true,"img":false}]}
{"op":"mcm","clk":"11450234923","pt":1717319457701,"mc":[{"id":"1.229554907","rc":[{"atb":[[7,0]],"id":52385888}],"con":true,"img":false}]}
{"op":"mcm","clk":"11450234933","pt":1717319457806,"mc":[{"id":"1.229554907","rc":[{"atb":[[100,2]],"id":52385907}],"con":true,"img":false}]}
{"op":"mcm","clk":"11450235656","pt":1717319465485,"mc":[{"id":"1.229554907","rc":[{"atb":[[100,5.82]],"id":52385907},{"atl":[[370,0],[380,2.88]],"id":52385907},{"atb":[[6,4.44]],"id":52385888},{"atb":[[19.5,3.27]],"id":52385936},{"atb":[[2.98,7.92]],"id":52385931}],"con":true,"img":false}]}
{"op":"mcm","clk":"11450236527","pt":1717319475467,"mc":[{"id":"1.229554907","rc":[{"atb":[[90,0.88]],"id":52385907},{"atl":[[380,0],[370,3]],"id":52385907},{"atb":[[18,0]],"id":52385936},{"atl":[[46,0],[48,4.2]],"id":52385936},{"atl":[[5.1,0],[5.2,4.31]],"id":52385931}],"con":true,"img":false}]}
{"op":"mcm","clk":"11450236608","pt":1717319476288,"mc":[{"id":"1.229554907","rc":[{"atb":[[580,0],[500,2]],"id":52385918},{"atb":[[38,0],[40,5.76]],"id":52385889},{"atb":[[26,0],[29,8.61]],"id":52385882},{"atb":[[23,4.55],[24,0]],"id":52385904},{"atb":[[1.68,0],[1.78,99.7]],"id":52385931}],"con":true,"img":false}]}
{"op":"mcm","clk":"11450236625","pt":1717319476491,"mc":[{"id":"1.229554907","rc":[{"atb":[[3.2,7.13]],"id":52385931}],"con":true,"img":false}]}
{"op":"mcm","clk":"11450236637","pt":1717319476602,"mc":[{"id":"1.229554907","rc":[{"atb":[[120,0]],"id":52385907},{"atb":[[5.8,0],[5.7,4.55]],"id":52385909},{"atb":[[6.4,0],[7,4.4]],"id":52385888},{"atb":[[42,0],[44,2.9]],"id":52385889},{"atb":[[32,3.64],[30,0]],"id":52385882},{"atb":[[14,0],[15,3.1]],"id":52385884},{"atb":[[36,3.43],[38,0]],"id":52385891},{"atl":[[200,3.79],[210,0]],"id":52385891},{"atl":[[760,0],[770,3.91]],"id":52385923},{"atb":[[13.5,0],[14,5.79]],"id":52385903},{"atb":[[27,3.33],[28,0]],"id":52385904},{"atl":[[95,3.88],[100,0]],"id":52385904},{"atb":[[19,3.06],[21,0]],"id":52385936},{"atb":[[3.05,0]],"id":52385931}],"con":true,"img":false}]}
{"op":"mcm","clk":"11450236660","pt":1717319476902,"mc":[{"id":"1.229554907","rc":[{"atl":[[690,3.93]],"id":52385923},{"atl":[[46,3.52],[48,0]],"id":52385936}],"con":true,"img":false}]}
{"op":"mcm","clk":"11450236668","pt":1717319477009,"mc":[{"id":"1.229554907","rc":[{"atl":[[5.2,0]],"id":52385931}],"con":true,"img":false}]}
{"op":"mcm","clk":"11450236713","pt":1717319477522,"mc":[{"id":"1.229554907","rc":[{"atl":[[770,0]],"id":52385923},{"atb":[[19.5,0]],"id":52385936}],"con":true,"img":false}]}
{"op":"mcm","clk":"11450237372","pt":1717319485229,"mc":[{"id":"1.229554907","rc":[{"atb":[[90,4.5]],"id":52385907}],"con":true,"img":false}]}
{"op":"mcm","clk":"11450237486","pt":1717319486524,"mc":[{"id":"1.229554907","rc":[{"atb":[[6.6,4.52]],"id":52385888},{"atb":[[3.1,7.47]],"id":52385931},{"atl":[[5.5,3.81]],"id":52385931}],"con":true,"img":false}]}
{"op":"mcm","clk":"11450237498","pt":1717319486730,"mc":[{"id":"1.229554907","rc":[{"atl":[[710,4.19]],"id":52385923},{"atb":[[18,4.64]],"id":52385936}],"con":true,"img":false}]}
{"op":"mcm","clk":"11450238194","pt":1717319494035,"mc":[{"id":"1.229554907","rc":[{"atb":[[38,2.7]],"id":52385889},{"atb":[[1.78,0]],"id":52385931}],"con":true,"img":false}]}
{"op":"mcm","clk":"11450238204","pt":1717319494140,"mc":[{"id":"1.229554907","rc":[{"atb":[[40,3.2]],"id":52385889},{"atb":[[1.69,99.7]],"id":52385931}],"con":true,"img":false}]}
{"op":"mcm","clk":"11450238707","pt":1717319500241,"mc":[{"id":"1.229554907","rc":[{"atb":[[38,0],[40,5.76]],"id":52385889}],"con":true,"img":false}]}
{"op":"mcm","clk":"11450238714","pt":1717319500344,"mc":[{"id":"1.229554907","rc":[{"atb":[[1.78,99.7],[1.69,0]],"id":52385931}],"con":true,"img":false}]}
{"op":"mcm","clk":"11450239989","pt":1717319514256,"mc":[{"id":"1.229554907","rc":[{"atb":[[6,0]],"id":52385888},{"atl":[[780,0]],"id":52385923},{"atb":[[2.98,0]],"id":52385931}],"con":true,"img":false}]}
{"op":"mcm","clk":"11450242243","pt":1717319537826,"mc":[{"id":"1.229554907","rc":[{"atl":[[690,0],[760,4.68]],"id":52385923},{"atl":[[95,0],[100,3.48]],"id":52385904},{"atl":[[5.3,0]],"id":52385931}],"con":true,"img":false}]}
{"op":"mcm","clk":"11450242254","pt":1717319537928,"mc":[{"id":"1.229554907","rc":[{"atl":[[200,0],[210,4]],"id":52385891},{"atl":[[5.1,2.81]],"id":52385931}],"con":true,"img":false}]}
{"op":"mcm","clk":"11450243085","pt":1717319546560,"mc":[{"id":"1.229554907","rc":[{"atl":[[710,0],[780,3.17]],"id":52385923},{"atl":[[5.3,3.5]],"id":52385931}],"con":true,"img":false}]}
{"op":"mcm","clk":"11450243898","pt":1717319555183,"mc":[{"id":"1.229554907","rc":[{"atl":[[5.5,0]],"id":52385931}],"con":true,"img":false}]}
{"op":"mcm","clk":"11450244920","pt":1717319566262,"mc":[{"id":"1.229554907","rc":[{"atb":[[560,2],[500,0]],"id":52385918},{"atb":[[22,4.76],[23,0]],"id":52385904}],"con":true,"img":false}]}
{"op":"mcm","clk":"11450244928","pt":1717319566413,"mc":[{"id":"1.229554907","rc":[{"atb":[[16,6.67],[100,3.82]],"id":52385907},{"atl":[[430,2]],"id":52385907},{"atb":[[3.15,46.51],[3.5,0]],"id":52385909},{"atl":[[32,0],[14,3.61]],"id":52385909},{"atb":[[560,0]],"id":52385918},{"atb":[[46,2.22],[100,4.38]],"id":52385886},{"atb":[[7.4,11.06],[4.2,0]],"id":52385888},{"atl":[[40,0],[120,2]],"id":52385888},{"atb":[[190,0],[48,2.13]],"id":52385920},{"atb":[[40,3.2],[10,11.11]],"id":52385889},{"atl":[[220,2]],"id":52385889},{"atb":[[29,5.04],[8.4,13.51]],"id":52385882},{"atl":[[150,6.39]],"id":52385882},{"atb":[[11,0],[5.4,22.73]],"id":52385884},{"atl":[[65,2]],"id":52385884},{"atb":[[50,2.04],[230,1.06]],"id":52385917},{"atl":[[100,2]],"id":52385895},{"atb":[[50,4.17]],"id":52385923},{"atb":[[34,0],[7,16.67]],"id":52385891},{"atl":[[200,2]],"id":52385891},{"atb":[[46,2.22]],"id":52385893},{"atb":[[1.57,0],[2.84,30.42]],"id":52385934},{"atb":[[4,33.33],[10.5,0]],"id":52385903},{"atl":[[42,5.11]],"id":52385903},{"atb":[[22,0]],"id":52385904},{"atl":[[95,2]],"id":52385904},{"atb":[[21,4.13],[14.5,0]],"id":52385936},{"atl":[[500,2]],"id":52385936},{"atb":[[3.45,10.9],[1.78,0]],"id":52385931},{"atl":[[12,0],[55,2]],"id":52385931}],"con":true,"img":false}]}
{"op":"mcm","clk":"11450244937","pt":1717319566470,"mc":[{"id":"1.229554907","rc":[{"atb":[[80,0]],"id":52385923},{"atb":[[370,0]],"id":52385893}],"con":true,"img":false}]}
{"op":"mcm","clk":"11450244947","pt":1717319566580,"mc":[{"id":"1.229554907","rc":[{"atb":[[100,0],[110,4.59]],"id":52385907},{"atb":[[130,5.19],[120,0]],"id":52385886},{"atb":[[50,2.04]],"id":52385918},{"atb":[[6.8,17.14],[7,0]],"id":52385888},{"atb":[[620,0],[670,0]],"id":52385893},{"atb":[[13.5,3.52],[14,2.01]],"id":52385903},{"atl":[[42,2.67],[44,2.33]],"id":52385903},{"atb":[[19,0],[20,8.08]],"id":52385936},{"atb":[[4.2,31.25]],"id":52385904},{"atb":[[8,0],[5.5,0],[6,0],[7,0]],"id":52385932}],"con":true,"img":false}]}
{"op":"mcm","clk":"11450244959","pt":1717319566682,"mc":[{"id":"1.229554907","rc":[{"atb":[[130,0],[65,0],[180,0],[90,0]],"id":52385907},{"atl":[[360,0.44],[190,5]],"id":52385907},{"atb":[[5.6,0],[7.2,0],[5.1,0],[6.2,0],[5.5,0],[5.7,0]],"id":52385909},{"atl":[[10.5,5],[14,15.37],[14.5,0],[15,4.21]],"id":52385909},{"atb":[[150,5]],"id":52385886},{"atl":[[530,3.9],[470,1.08]],"id":52385886},{"atb":[[9,11.14],[12,5]],"id":52385888},{"atl":[[36,9.39],[19.5,0],[21,0]],"id":52385888},{"atb":[[44,0],[27,9.72]],"id":52385889},{"atl":[[220,2.73],[110,5],[230,0]],"id":52385889},{"atb":[[32,0],[38,0],[19.5,0],[24,0],[29,3.17]],"id":52385882},{"atl":[[65,5],[120,1.34]],"id":52385882},{"atb":[[19,0],[21,0],[13,0],[13.5,0],[15,0],[15.5,0]],"id":52385884},{"atl":[[46,3.56],[48,0],[50,3.08],[30,5]],"id":52385884},{"atb":[[16,0],[18.5,0],[22,0],[27,0]],"id":52385895},{"atl":[[40,5],[85,4.14],[100,3.61],[110,0]],"id":52385895},{"atb":[[160,6.01]],"id":52385923},{"atl":[[760,0],[780,0.02]],"id":52385923},{"atb":[[32,0],[36,0],[29,0]],"id":52385891},{"atl":[[95,5],[210,0],[220,0.73]],"id":52385891},{"atb":[[520,0],[570,0],[180,0],[200,0]],"id":52385893},{"atl":[[1000,0.16]],"id":52385893},{"atb":[[2.82,0],[2.72,0],[2.52,0],[2.84,64.48],[2.62,9.68],[3.9,5]],"id":52385934},{"atl":[[7,5]],"id":52385934},{"atb":[[9.6,0],[8.6,0],[11.5,0],[13,0],[14,0]],"id":52385903},{"atl":[[40,4.1],[42,0],[28,5]],"id":52385903},{"atb":[[25,0],[27,0]],"id":52385904},{"atl":[[55,5],[110,1.47]],"id":52385904},{"atb":[[27,5]],"id":52385936},{"atl":[[130,8.53],[46,0],[50,0]],"id":52385936},{"atb":[[3.45,26.89],[4.3,5]],"id":52385931},{"atl":[[5.1,0],[18,3.5],[18.5,5],[5.3,0]],"id":52385931},{"atb":[[7,5]],"id":52385932},{"atl":[[11,5],[12,14.73]],"id":52385932}],"con":true,"img":false}]}
{"op":"mcm","clk":"11450244969","pt":1717319566781,"mc":[{"id":"1.229554907","rc":[{"atb":[[21,2.76]],"id":52385882},{"atl":[[80,4.5]],"id":52385895},{"atl":[[220,4.02]],"id":52385891},{"atb":[[2.8,8.72],[2.62,0]],"id":52385934},{"atl":[[4.8,0],[4.6,0],[7,9.19]],"id":52385934}],"con":true,"img":false}]}
{"op":"mcm","clk":"11450244979","pt":1717319566886,"mc":[{"id":"1.229554907","rc":[{"atl":[[12.5,8.7],[14,11.76]],"id":52385909},{"atl":[[200,0],[110,2]],"id":52385891},{"atb":[[3,50],[2.84,34.06]],"id":52385934},{"atl":[[95,0],[50,2.04]],"id":52385904}],"con":true,"img":false}]}
{"op":"mcm","clk":"11450244998","pt":1717319567092,"mc":[{"id":"1.229554907","rc":[{"atb":[[5,30.74]],"id":52385932}],"con":true,"img":false}]}
{"op":"mcm","clk":"11450245006","pt":1717319567196,"mc":[{"id":"1.229554907","rc":[{"atb":[[3.7,41.33]],"id":52385909},{"atl":[[36,13.96]],"id":52385888},{"atb":[[9.2,14.66]],"id":52385884},{"atb":[[9.2,5.43]],"id":52385895},{"atb":[[19.5,2.27]],"id":52385891},{"atb":[[160,5]],"id":52385893},{"atl":[[7,16.72]],"id":52385934},{"atl":[[130,9.77]],"id":52385936},{"atl":[[18,12.92]],"id":52385931}],"con":true,"img":false}]}
{"op":"mcm","clk":"11450245016","pt":1717319567298,"mc":[{"id":"1.229554907","rc":[{"atb":[[420,0.13],[470,0.06]],"id":52385893},{"atb":[[6.8,9.02],[7.8,3.85],[5.9,16.01],[5.4,23.78]],"id":52385932}],"con":true,"img":false}]}
{"op":"mcm","clk":"11450245026","pt":1717319567402,"mc":[{"id":"1.229554907","rc":[{"atb":[[50,5]],"id":52385907},{"atb":[[4.7,5]],"id":52385909},{"atb":[[28,5.93]],"id":52385889},{"atb":[[21,7.77]],"id":52385882},{"atb":[[18,11.15]],"id":52385891},{"atb":[[2.82,43.12],[2.92,27.25],[2.72,60.84],[3.05,12.76]],"id":52385934},{"atb":[[7.4,5]],"id":52385904}],"con":true,"img":false}]}
{"op":"mcm","clk":"11450245054","pt":1717319567717,"mc":[{"id":"1.229554907","rc":[{"atb":[[16.5,5.06],[19,2.91],[23,1.19],[14,8.05]],"id":52385895}],"con":true,"img":false}]}
{"op":"mcm","clk":"11450245066","pt":1717319567767,"mc":[{"id":"1.229554907","rc":[{"atb":[[110,0]],"id":52385907},{"atb":[[4.8,4.29],[4.6,4.14]],"id":52385909},{"atl":[[530,0],[490,0]],"id":52385886},{"atb":[[40,0]],"id":52385889},{"atb":[[11,2.66],[12,4.24]],"id":52385884},{"atb":[[16,4.05],[17,7.73]],"id":52385891},{"atb":[[3.8,5],[3.9,0]],"id":52385934},{"atb":[[13.5,0]],"id":52385903},{"atb":[[26,5],[27,0]],"id":52385936}],"con":true,"img":false}]}
{"op":"mcm","clk":"11450245085","pt":1717319568023,"mc":[{"id":"1.229554907","rc":[{"atb":[[32,3.37],[80,3.42],[42,1.92],[55,0.97]],"id":52385907},{"atb":[[5.6,5.69],[5.1,12.76],[4.6,25.95],[4.1,33.76]],"id":52385909},{"atb":[[32,0.84],[18,12.3],[21,11.7],[22,6.77],[26,2.09]],"id":52385882},{"atb":[[17,1.64],[11,7.67],[12,11.38],[9.8,11.89],[14.5,3.88]],"id":52385884},{"atl":[[36,5],[30,0]],"id":52385884},{"atb":[[14.5,5]],"id":52385895},{"atb":[[15.5,7.21]],"id":52385891},{"atb":[[320,0.33],[370,0.21]],"id":52385893},{"atb":[[7.2,10.3],[6.8,13.53],[8.8,3.35],[7.8,7.7],[5.9,21.36]],"id":52385903},{"atl":[[28,0],[29,5]],"id":52385903}],"con":true,"img":false}]}
{"op":"mcm","clk":"11450245095","pt":1717319568073,"mc":[{"id":"1.229554907","rc":[{"atl":[[65,0],[70,5]],"id":52385882}],"con":true,"img":false}]}
{"op":"mcm","clk":"11450245147","pt":1717319568694,"mc":[{"id":"1.229554907","rc":[{"atl":[[530,3.59],[550,3.82]],"id":52385886},{"atb":[[29,0]],"id":52385882},{"atb":[[3.75,5]],"id":52385934},{"atb":[[7.2,13.29],[6.8,17.71]],"id":52385903}],"con":true,"img":false}]}
{"op":"mcm","clk":"11450245157","pt":1717319568795,"mc":[{"id":"1.229554907","rc":[{"atb":[[42,5.83],[46,3.82]],"id":52385907},{"atl":[[80,0]],"id":52385895},{"atb":[[3.8,0]],"id":52385934}],"con":true,"img":false}]}
{"op":"mcm","clk":"11450245212","pt":1717319569367,"mc":[{"id":"1.229554907","rc":[{"atb":[[3.75,0]],"id":52385934}],"con":true,"img":false}]}
{"op":"mcm","clk":"11450245270","pt":1717319570087,"mc":[{"id":"1.229554907","rc":[{"atb":[[3.8,5]],"id":52385934}],"con":true,"img":false}]}
{"op":"mcm","clk":"11450245291","pt":1717319570296,"mc":[{"id":"1.229554907","rc":[{"atl":[[29,0],[30,5]],"id":52385903}],"con":true,"img":false}]}
{"op":"mcm","clk":"11450245327","pt":1717319570707,"mc":[{"id":"1.229554907","rc":[{"atl":[[350,2],[430,0]],"id":52385907},{"atl":[[180,2],[220,0.73]],"id":52385889},{"atl":[[150,4.39],[120,3.34]],"id":52385882},{"atl":[[65,0],[55,4.89]],"id":52385884},{"atl":[[80,2],[100,1.61]],"id":52385895},{"atl":[[400,2],[500,0]],"id":52385936},{"atl":[[42,2.44],[55,0]],"id":52385931},{"atl":[[21,5],[27,0]],"id":52385932}],"con":true,"img":false}]}
{"op":"mcm","clk":"11450245335","pt":1717319570813,"mc":[{"id":"1.229554907","rc":[{"atb":[[3.8,0],[3.75,5]],"id":52385934}],"con":true,"img":false}]}
{"op":"mcm","clk":"11450245455","pt":1717319572000,"mc":[{"id":"1.229554907","rc":[{"atl":[[44,0],[29,3.57]],"id":52385903},{"atl":[[50,0],[55,7]],"id":52385904}],"con":true,"img":false}]}
{"op":"mcm","clk":"11450245487","pt":1717319572413,"mc":[{"id":"1.229554907","rc":[{"atl":[[11,10],[12.5,0]],"id":52385909},{"atl":[[90,2],[110,0]],"id":52385891}],"con":true,"img":false}]}
{"op":"mcm","clk":"11450245722","pt":1717319574905,"mc":[{"id":"1.229554907","rc":[{"atl":[[40,3.34]],"id":52385888},{"atb":[[25,3.2]],"id":52385889},{"atl":[[270,3.62]],"id":52385889},{"atb":[[19.5,4.44]],"id":52385882},{"atl":[[7.4,2.61]],"id":52385934},{"atb":[[19,2.83]],"id":52385936},{"atl":[[150,2.71]],"id":52385936},{"atl":[[19,3.63]],"id":52385931}],"con":true,"img":false}]}
{"op":"mcm","clk":"11450245745","pt":1717319575100,"mc":[{"id":"1.229554907","rc":[{"atl":[[95,3.84]],"id":52385895}],"con":true,"img":false}]}
{"op":"mcm","clk":"11450245927","pt":1717319576906,"mc":[{"id":"1.229554907","rc":[{"atl":[[50,3.28]],"id":52385903}],"con":true,"img":false}]}
{"op":"mcm","clk":"11450246111","pt":1717319579078,"mc":[{"id":"1.229554907","rc":[{"atb":[[3.75,36.65]],"id":52385934},{"atb":[[4.4,23.89]],"id":52385931}],"con":true,"img":false}]}
{"op":"mcm","clk":"11450246126","pt":1717319579284,"mc":[{"id":"1.229554907","rc":[{"atl":[[190,5.85]],"id":52385907},{"atl":[[10.5,21.86]],"id":52385909},{"atb":[[12.5,12.57]],"id":52385888},{"atl":[[90,3.79]],"id":52385891},{"atl":[[55,9.97]],"id":52385904}],"con":true,"img":false}]}
{"op":"mcm","clk":"11450246146","pt":1717319579591,"mc":[{"id":"1.229554907","rc":[{"atl":[[110,6.47]],"id":52385889},{"atl":[[70,7.32]],"id":52385882},{"atl":[[36,9.58]],"id":52385884},{"atl":[[38,4.33]],"id":52385895},{"atl":[[1000,0.16]],"id":52385923},{"atl":[[29,9.29]],"id":52385903},{"atl":[[11,20.05]],"id":52385932}],"con":true,"img":false}]}
{"op":"mcm","clk":"11450246166","pt":1717319579806,"mc":[{"id":"1.229554907","rc":[{"atb":[[2.84,0]],"id":52385934},{"atb":[[3.45,10.9]],"id":52385931}],"con":true,"img":false}]}
{"op":"mcm","clk":"11450246187","pt":1717319580010,"mc":[{"id":"1.229554907","rc":[{"atl":[[360,0]],"id":52385907},{"atl":[[14,0]],"id":52385909},{"atb":[[9,0]],"id":52385888},{"atl":[[220,3.29]],"id":52385891},{"atl":[[110,0]],"id":52385904}],"con":true,"img":false}]}
{"op":"mcm","clk":"11450246214","pt":1717319580320,"mc":[{"id":"1.229554907","rc":[{"atl":[[220,0]],"id":52385889},{"atl":[[120,2]],"id":52385882},{"atl":[[46,0]],"id":52385884},{"atl":[[100,0]],"id":52385895},{"atl":[[780,0],[1000,0]],"id":52385923},{"atl":[[40,0]],"id":52385903},{"atl":[[12,3.06]],"id":52385932}],"con":true,"img":false}]}
{"op":"mcm","clk":"11450246286","pt":1717319581104,"mc":[{"id":"1.229554907","rc":[{"atl":[[1000,0.16]],"id":52385923}],"con":true,"img":false}]}
{"op":"mcm","clk":"11450246355","pt":1717319581930,"mc":[{"id":"1.229554907","rc":[{"atl":[[130,0]],"id":52385895},{"atb":[[18,0]],"id":52385936}],"con":true,"img":false}]}
{"op":"mcm","clk":"11450246413","pt":1717319582512,"mc":[{"id":"1.229554907","rc":[{"atb":[[160,0],[80,0.33]],"id":52385907},{"atb":[[3.2,0],[3.7,2.61]],"id":52385909},{"atb":[[130,3.3],[230,0]],"id":52385886},{"atb":[[550,0],[650,0]],"id":52385918},{"atb":[[4,0],[3.5,0]],"id":52385888},{"atb":[[270,0],[170,2.92]],"id":52385920},{"atb":[[18.5,4.48],[13.5,0]],"id":52385889},{"atb":[[18,6.15],[13,0]],"id":52385882},{"atb":[[7.2,0],[9.2,1.92]],"id":52385884},{"atb":[[330,0],[230,0]],"id":52385917},{"atb":[[9,0],[7,0]],"id":52385895},{"atb":[[16.5,0],[23,0]],"id":52385923},{"atb":[[18,5],[13,0]],"id":52385891},{"atb":[[550,0],[650,0]],"id":52385893},{"atb":[[2.4,0],[2.6,0]],"id":52385934},{"atb":[[9,0],[7,0]],"id":52385903},{"atb":[[10,0],[15,0]],"id":52385936},{"atb":[[16.5,0],[11.5,0]],"id":52385904},{"atb":[[2.54,0],[2.74,0]],"id":52385931},{"atb":[[4,0],[5,4.6]],"id":52385932}],"con":true,"img":false}]}
{"op":"mcm","clk":"11450246480","pt":1717319583006,"mc":[{"id":"1.229554907","rc":[{"atb":[[210,0.89]],"id":52385886},{"atb":[[2.76,8.92]],"id":52385934},{"atb":[[7.4,19.08]],"id":52385904}],"con":true,"img":false}]}
{"op":"mcm","clk":"11450246882","pt":1717319587410,"mc":[{"id":"1.229554907","rc":[{"atl":[[350,0],[430,2]],"id":52385907},{"atl":[[11,0],[12.5,8.7]],"id":52385909},{"atl":[[180,0],[220,2]],"id":52385889},{"atl":[[90,1.79],[110,2]],"id":52385891},{"atl":[[400,0],[500,2]],"id":52385936}],"con":true,"img":false}]}
{"op":"mcm","clk":"11450246904","pt":1717319587723,"mc":[{"id":"1.229554907","rc":[{"atb":[[130,0],[120,3.57]],"id":52385886},{"atb":[[6.8,13.53],[7,3.71]],"id":52385888},{"atb":[[180,3.44]],"id":52385917},{"atb":[[160,8.75],[180,4.15]],"id":52385893},{"atb":[[2.82,0],[2.92,0],[2.72,0],[2.58,0],[3.05,0]],"id":52385934},{"atb":[[20,4.13]],"id":52385936},{"atb":[[7.4,22.75],[7.8,2.9]],"id":52385904},{"atb":[[6.8,0],[7.8,0],[5.9,0],[5.4,0]],"id":52385932}],"con":true,"img":false}]}
{"op":"mcm","clk":"11450246945","pt":1717319588131,"mc":[{"id":"1.229554907","rc":[{"atb":[[7,15.5]],"id":52385932}],"con":true,"img":false}]}
{"op":"mcm","clk":"11450246968","pt":1717319588397,"mc":[{"id":"1.229554907","rc":[{"atb":[[2.74,60.13],[3.1,12.46],[2.84,42.65],[2.94,26.97]],"id":52385934}],"con":true,"img":false}]}
{"op":"mcm","clk":"11450246980","pt":1717319588501,"mc":[{"id":"1.229554907","rc":[{"atb":[[8,3.74],[5.5,23.25],[6,15.7],[7,24.23]],"id":52385932}],"con":true,"img":false}]}
{"op":"mcm","clk":"11450247009","pt":1717319588819,"mc":[{"id":"1.229554907","rc":[{"atb":[[5,0]],"id":52385932}],"con":true,"img":false}]}
{"op":"mcm","clk":"11450247492","pt":1717319594441,"mc":[{"id":"1.229554907","rc":[{"atl":[[70,2.32],[75,5]],"id":52385882}],"con":true,"img":false}]}
{"op":"mcm","clk":"11450247501","pt":1717319594503,"mc":[{"id":"1.229554907","rc":[{"atl":[[70,0]],"id":52385882}],"con":true,"img":false}]}
{"op":"mcm","clk":"11450247509","pt":1717319594605,"mc":[{"id":"1.229554907","rc":[{"atl":[[150,6.39]],"id":52385882}],"con":true,"img":false}]}
{"op":"mcm","clk":"11450247516","pt":1717319594707,"mc":[{"id":"1.229554907","rc":[{"atl":[[120,0]],"id":52385882}],"con":true,"img":false}]}
{"op":"mcm","clk":"11450247552","pt":1717319595113,"mc":[{"id":"1.229554907","rc":[{"atb":[[7.8,14.68]],"id":52385904}],"con":true,"img":false}]}
{"op":"mcm","clk":"11450247559","pt":1717319595218,"mc":[{"id":"1.229554907","rc":[{"atl":[[75,7.17]],"id":52385882}],"con":true,"img":false}]}
{"op":"mcm","clk":"11450247605","pt":1717319595636,"mc":[{"id":"1.229554907","rc":[{"atb":[[80,3.42],[160,0.65]],"id":52385907},{"atb":[[3.2,110.86],[3.7,41.33]],"id":52385909},{"atb":[[130,1.88],[230,0.45]],"id":52385886},{"atb":[[550,0.44],[650,0.16]],"id":52385918},{"atb":[[4,34.84],[3.5,97.56]],"id":52385888},{"atb":[[270,0.38],[170,4.37]],"id":52385920},{"atb":[[18.5,10.46],[13.5,19.51]],"id":52385889},{"atb":[[18,12.3],[13,20.32]],"id":52385882},{"atb":[[7.2,39.33],[9.2,14.66]],"id":52385884},{"atb":[[330,0.31],[230,1.06]],"id":52385917},{"atb":[[9,13.06],[7,40.65]],"id":52385895},{"atb":[[18,11.15],[13,20.32]],"id":52385891},{"atb":[[16.5,15.73],[23,4.75]],"id":52385923},{"atb":[[550,0.44],[650,0.16]],"id":52385893},{"atb":[[2.4,174.21],[2.6,65.33]],"id":52385934},{"atb":[[9,13.06],[7,40.65]],"id":52385903},{"atb":[[16.5,6.74],[11.5,23.22]],"id":52385904},{"atb":[[18,3.97],[10,27.1],[15,7.46]],"id":52385936},{"atb":[[2.54,158.38],[2.74,60.07]],"id":52385931},{"atb":[[4,81.3],[5,26.13]],"id":52385932}],"con":true,"img":false}]}
{"op":"mcm","clk":"11450247637","pt":1717319595949,"mc":[{"id":"1.229554907","rc":[{"atb":[[7.4,8.67]],"id":52385904}],"con":true,"img":false}]}
{"op":"mcm","clk":"11450247666","pt":1717319596210,"mc":[{"id":"1.229554907","rc":[{"atl":[[350,2]],"id":52385907},{"atl":[[11,10],[12.5,0]],"id":52385909},{"atl":[[180,2]],"id":52385889},{"atl":[[120,2]],"id":52385882},{"atl":[[90,3.79]],"id":52385891},{"atl":[[400,2],[500,0]],"id":52385936}],"con":true,"img":false}]}
{"op":"mcm","clk":"11450247676","pt":1717319596312,"mc":[{"id":"1.229554907","rc":[{"atl":[[430,0]],"id":52385907},{"atl":[[220,0]],"id":52385889},{"atl":[[150,4.39]],"id":52385882},{"atl":[[110,0]],"id":52385891}],"con":true,"img":false}]}
{"op":"mcm","clk":"11450247697","pt":1717319596519,"mc":[{"id":"1.229554907","rc":[{"atl":[[370,0],[400,2.65]],"id":52385907},{"atb":[[7,0]],"id":52385888},{"atb":[[95,2.99],[100,0.53]],"id":52385923},{"atb":[[2.8,0]],"id":52385934},{"atb":[[19,0]],"id":52385936},{"atb":[[8,0],[5.5,0],[6,0],[7,15.5]],"id":52385932}],"con":true,"img":false}]}
{"op":"mcm","clk":"11450247762","pt":1717319597221,"mc":[{"id":"1.229554907","rc":[{"atb":[[5.6,22.75],[7.2,8.44],[6.2,15.09],[8.2,3.63]],"id":52385932}],"con":true,"img":false}]}
{"op":"mcm","clk":"11450247912","pt":1717319599131,"mc":[{"id":"1.229554907","rc":[{"atl":[[44,2.9],[46,0]],"id":52385903}],"con":true,"img":false}]}
{"op":"mcm","clk":"11450248016","pt":1717319600425,"mc":[{"id":"1.229554907","rc":[{"atl":[[14.5,3.56],[15,0]],"id":52385909},{"atl":[[65,3.57],[50,0]],"id":52385884},{"atl":[[220,0],[250,2.85]],"id":52385891}],"con":true,"img":false}]}
{"op":"mcm","clk":"11450248020","pt":1717319600525,"mc":[{"id":"1.229554907","rc":[{"atb":[[7,4.41]],"id":52385888},{"atl":[[260,3.5],[250,0]],"id":52385889},{"atl":[[130,0],[140,2.86]],"id":52385882},{"atb":[[95,0],[100,3.69]],"id":52385923},{"atb":[[2.8,8.72]],"id":52385934},{"atl":[[44,0],[46,3]],"id":52385903},{"atb":[[19,3.14]],"id":52385936},{"atl":[[100,0],[110,3.19]],"id":52385904}],"con":true,"img":false}]}
{"op":"mcm","clk":"11450248195","pt":1717319602947,"mc":[{"id":"1.229554907","rc":[{"atb":[[5.6,0],[7.2,0]],"id":52385932}],"con":true,"img":false}]}
{"op":"mcm","clk":"11450248203","pt":1717319603007,"mc":[{"id":"1.229554907","rc":[{"atb":[[6.2,0],[8.2,0]],"id":52385932}],"con":true,"img":false}]}
{"op":"mcm","clk":"11450248254","pt":1717319603624,"mc":[{"id":"1.229554907","rc":[{"atb":[[5.5,23.25],[4.1,10.5],[7,24.23]],"id":52385932}],"con":true,"img":false}]}
{"op":"mcm","clk":"11450248263","pt":1717319603725,"mc":[{"id":"1.229554907","rc":[{"atb":[[8,3.74],[6,15.7]],"id":52385932}],"con":true,"img":false}]}
{"op":"mcm","clk":"11450248322","pt":1717319604348,"mc":[{"id":"1.229554907","rc":[{"atb":[[4.1,0]],"id":52385932}],"con":true,"img":false}]}
{"op":"mcm","clk":"11450248331","pt":1717319604449,"mc":[{"id":"1.229554907","rc":[{"atl":[[14.5,0]],"id":52385909},{"atl":[[55,2]],"id":52385884},{"atl":[[220,4.19],[230,0]],"id":52385891}],"con":true,"img":false}]}
{"op":"mcm","clk":"11450248341","pt":1717319604507,"mc":[{"id":"1.229554907","rc":[{"atl":[[13.5,3.76]],"id":52385909},{"atl":[[260,0]],"id":52385889},{"atl":[[50,4.6]],"id":52385884},{"atl":[[44,2.8],[46,0]],"id":52385903},{"atl":[[100,3.81],[110,0]],"id":52385904}],"con":true,"img":false}]}
{"op":"mcm","clk":"11450248582","pt":1717319607361,"mc":[{"id":"1.229554907","rc":[{"atl":[[29,3.57]],"id":52385903}],"con":true,"img":false}]}
{"op":"mcm","clk":"11450248647","pt":1717319608042,"mc":[{"id":"1.229554907","rc":[{"atl":[[30,10.53]],"id":52385903}],"con":true,"img":false}]}
{"op":"mcm","clk":"11450248663","pt":1717319608236,"mc":[{"id":"1.229554907","rc":[{"atl":[[290,3.53]],"id":52385889}],"con":true,"img":false}]}
{"op":"mcm","clk":"11450249012","pt":1717319612118,"mc":[{"id":"1.229554907","rc":[{"atl":[[14.5,4.16]],"id":52385909}],"con":true,"img":false}]}
{"op":"mcm","clk":"11450249315","pt":1717319615736,"mc":[{"id":"1.229554907","rc":[{"atl":[[13.5,0],[14,4.41],[14.5,0],[15.5,0]],"id":52385909},{"atl":[[270,0],[260,4.36]],"id":52385889},{"atl":[[100,0],[110,4.35]],"id":52385904}],"con":true,"img":false}]}
{"op":"mcm","clk":"11450249415","pt":1717319616952,"mc":[{"id":"1.229554907","rc":[{"atb":[[16,0],[12,9.09]],"id":52385907},{"atl":[[300,2],[350,0]],"id":52385907},{"atl":[[11,0],[11.5,9.52]],"id":52385909},{"atb":[[5.7,21.28],[7,0]],"id":52385891},{"atb":[[3.7,37.04],[4.2,0]],"id":52385904}],"con":true,"img":false}]}
{"op":"mcm","clk":"11450249441","pt":1717319617233,"mc":[{"id":"1.229554907","rc":[{"atb":[[42,1.92],[46,0],[50,0]],"id":52385907},{"atb":[[5.6,0],[4.8,0],[5.1,0],[4.6,4.14],[4.1,0],[4.9,3.64]],"id":52385909},{"atl":[[470,0],[510,4.22]],"id":52385886},{"atl":[[1000,0.16]],"id":52385920},{"atb":[[27,6.01],[28,9.21]],"id":52385889},{"atb":[[32,0],[18,6.14],[21,7.77],[22,11.21],[26,0]],"id":52385882},{"atb":[[17,0],[12,0],[9.8,0],[12.5,3.63],[14.5,0]],"id":52385884},{"atb":[[16.5,0],[19,0],[23,0],[14,0]],"id":52385895},{"atb":[[16,0],[17,3.27],[18,6.14],[19.5,1.41],[15.5,0]],"id":52385891},{"atb":[[320,0],[180,0],[370,0],[420,0],[470,0]],"id":52385893},{"atl":[[7.2,2.84],[7,12.53]],"id":52385934},{"atb":[[7.2,10.3],[7.4,3.08],[6.8,4.18],[8.8,0],[7.8,0],[5.9,0]],"id":52385903},{"atb":[[7.4,0],[7.8,0]],"id":52385904},{"atl":[[130,6.24],[140,3.72]],"id":52385936},{"atl":[[18,9.42]],"id":52385931}],"con":true,"img":false}]}
{"op":"mcm","clk":"11450249454","pt":1717319617342,"mc":[{"id":"1.229554907","rc":[{"atb":[[32,0],[80,3.08],[42,0],[55,0]],"id":52385907},{"atl":[[530,0]],"id":52385886},{"atb":[[21,5]],"id":52385882}],"con":true,"img":false}]}
{"op":"mcm","clk":"11450249494","pt":1717319617750,"mc":[{"id":"1.229554907","rc":[{"atb":[[42,5]],"id":52385907},{"atb":[[4.9,15.75]],"id":52385909},{"atb":[[12.5,12.08]],"id":52385884},{"atb":[[14.5,8]],"id":52385895},{"atb":[[15,5]],"id":52385891},{"atb":[[6.2,5]],"id":52385904}],"con":true,"img":false}]}
{"op":"mcm","clk":"11450249511","pt":1717319617953,"mc":[{"id":"1.229554907","rc":[{"atb":[[5.2,12.46],[5.7,5.57],[4.2,32.7],[4.7,26.22]],"id":52385909},{"atl":[[500,0.31]],"id":52385886},{"atb":[[34,0.8],[18.5,5.98],[22,14.95],[27,2.01]],"id":52385882},{"atb":[[18,1.54],[10.5,11.01],[13,6.54],[15.5,3.61]],"id":52385884},{"atb":[[17.5,4.76],[20,2.75],[25,1.09],[15,7.48]],"id":52385895},{"atb":[[13,29.05],[13.5,12]],"id":52385891},{"atb":[[290,0.27],[340,0.15],[390,0.07],[240,0.44]],"id":52385893},{"atb":[[7.2,22.96],[9.2,3.19],[6.2,20.12],[8.2,7.27]],"id":52385903}],"con":true,"img":false}]}
{"op":"mcm","clk":"11450249517","pt":1717319618058,"mc":[{"id":"1.229554907","rc":[{"atb":[[70,0.38],[38,2.12],[48,1.11],[29,3.74]],"id":52385907},{"atl":[[300,0],[370,2]],"id":52385907},{"atl":[[11.5,0],[13,8.33]],"id":52385909},{"atl":[[550,0]],"id":52385886},{"atl":[[180,0],[230,2]],"id":52385889},{"atb":[[19.5,0]],"id":52385882},{"atl":[[150,6.39],[120,0]],"id":52385882},{"atl":[[10.5,0],[13.5,8]],"id":52385934},{"atl":[[520,2],[400,0]],"id":52385936},{"atl":[[21,0],[27,3.85]],"id":52385932}],"con":true,"img":false}]}
{"op":"mcm","clk":"11450249542","pt":1717319618325,"mc":[{"id":"1.229554907","rc":[{"atb":[[12,0],[13.5,5]],"id":52385888},{"atb":[[27,1],[28,14.22]],"id":52385889},{"atl":[[38,9.33],[40,0]],"id":52385895},{"atl":[[29,8.57],[30,5.52]],"id":52385903},{"atb":[[4.3,0],[4.4,28.9]],"id":52385931},{"atb":[[7.4,5]],"id":52385932}],"con":true,"img":false}]}
{"op":"mcm","clk":"11450249548","pt":1717319618451,"mc":[{"id":"1.229554907","rc":[{"atl":[[180,5]],"id":52385907},{"atb":[[3.7,38.71]],"id":52385909},{"atb":[[9.2,12.74]],"id":52385884},{"atb":[[9.2,0]],"id":52385895},{"atl":[[90,8.8],[95,0]],"id":52385891},{"atb":[[7,19.22]],"id":52385932}],"con":true,"img":false}]}
{"op":"mcm","clk":"11450249554","pt":1717319618532,"mc":[{"id":"1.229554907","rc":[{"atl":[[190,0.84]],"id":52385907}],"con":true,"img":false}]}
{"op":"mcm","clk":"11450249580","pt":1717319618838,"mc":[{"id":"1.229554907","rc":[{"atb":[[13.5,17.56]],"id":52385888}],"con":true,"img":false}]}
{"op":"mcm","clk":"11450249589","pt":1717319618947,"mc":[{"id":"1.229554907","rc":[{"atl":[[180,5.9]],"id":52385907}],"con":true,"img":false}]}
{"op":"mcm","clk":"11450249599","pt":1717319619052,"mc":[{"id":"1.229554907","rc":[{"atb":[[4.8,5],[4.7,21.21]],"id":52385909}],"con":true,"img":false}]}
{"op":"mcm","clk":"11450249634","pt":1717319619458,"mc":[{"id":"1.229554907","rc":[{"atl":[[190,5.85]],"id":52385907},{"atl":[[70,5],[75,2.16]],"id":52385882},{"atl":[[29,3.57],[30,10.53]],"id":52385903}],"con":true,"img":false}]}
{"op":"mcm","clk":"11450249642","pt":1717319619561,"mc":[{"id":"1.229554907","rc":[{"atl":[[180,0.89]],"id":52385907},{"atb":[[11,2.66]],"id":52385884},{"atb":[[15,12.48]],"id":52385895},{"atb":[[13,32.26],[14,4.02]],"id":52385891}],"con":true,"img":false}]}
{"op":"mcm","clk":"11450249651","pt":1717319619668,"mc":[{"id":"1.229554907","rc":[{"atl":[[180,0],[190,5]],"id":52385907},{"atb":[[12.5,0]],"id":52385888},{"atb":[[14.5,3]],"id":52385895}],"con":true,"img":false}]}
{"op":"mcm","clk":"11450249673","pt":1717319619841,"mc":[{"id":"1.229554907","rc":[{"atl":[[70,7.32]],"id":52385882}],"con":true,"img":false}]}
{"op":"mcm","clk":"11450249692","pt":1717319620042,"mc":[{"id":"1.229554907","rc":[{"atl":[[300,2],[370,0]],"id":52385907},{"atl":[[11.5,9.52],[13,0]],"id":52385909},{"atl":[[190,2],[230,0]],"id":52385889},{"atl":[[130,2],[150,4.39]],"id":52385882},{"atl":[[520,0],[420,2]],"id":52385936}],"con":true,"img":false}]}
{"op":"mcm","clk":"11450249702","pt":1717319620146,"mc":[{"id":"1.229554907","rc":[{"atb":[[7.2,17.96],[7.4,8.08]],"id":52385903}],"con":true,"img":false}]}
{"op":"mcm","clk":"11450249723","pt":1717319620353,"mc":[{"id":"1.229554907","rc":[{"atl":[[360,0.44]],"id":52385907}],"con":true,"img":false}]}
{"op":"mcm","clk":"11450249738","pt":1717319620554,"mc":[{"id":"1.229554907","rc":[{"atb":[[130,5.82],[120,0]],"id":52385886},{"atb":[[7,0]],"id":52385888},{"atl":[[75,0]],"id":52385882},{"atb":[[19.5,4.01]],"id":52385936},{"atb":[[3.2,0],[3.15,31.63]],"id":52385931}],"con":true,"img":false}]}
{"op":"mcm","clk":"11450249744","pt":1717319620653,"mc":[{"id":"1.229554907","rc":[{"atb":[[2.8,0]],"id":52385934},{"atb":[[19,0]],"id":52385936}],"con":true,"img":false}]}
{"op":"mcm","clk":"11450249749","pt":1717319620760,"mc":[{"id":"1.229554907","rc":[{"atl":[[14,0],[14.5,3.4]],"id":52385909},{"atl":[[500,3.1]],"id":52385886},{"atl":[[50,0],[55,4.65]],"id":52385884},{"atl":[[230,3.6]],"id":52385891},{"atl":[[44,0],[46,3.15]],"id":52385903}],"con":true,"img":false}]}
{"op":"mcm","clk":"11450249759","pt":1717319620864,"mc":[{"id":"1.229554907","rc":[{"atl":[[220,0]],"id":52385891}],"con":true,"img":false}]}
{"op":"mcm","clk":"11450249827","pt":1717319621553,"mc":[{"id":"1.229554907","rc":[{"atl":[[14,3.45]],"id":52385909},{"atl":[[500,0.31]],"id":52385886},{"atb":[[6.8,17.74]],"id":52385888},{"atl":[[50,4.32],[55,2]],"id":52385884},{"atl":[[230,0],[250,0]],"id":52385891},{"atl":[[44,3.92],[46,0]],"id":52385903}],"con":true,"img":false}]}
{"op":"mcm","clk":"11450249947","pt":1717319622481,"mc":[{"id":"1.229554907","rc":[{"atl":[[14,0]],"id":52385909},{"atb":[[130,1.88],[120,4.05]],"id":52385886},{"atl":[[500,3.37]],"id":52385886},{"atb":[[6.8,13.53],[7,4.22]],"id":52385888},{"atl":[[50,0],[55,5.68]],"id":52385884},{"atl":[[230,2.93],[250,4.29]],"id":52385891},{"atb":[[2.8,8.72]],"id":52385934},{"atl":[[44,0],[46,3.02]],"id":52385903},{"atb":[[19.5,0]],"id":52385936},{"atb":[[3.2,7.13],[3.15,24.33]],"id":52385931}],"con":true,"img":false}]}
{"op":"mcm","clk":"11450250007","pt":1717319623167,"mc":[{"id":"1.229554907","rc":[{"atl":[[70,0],[75,5]],"id":52385882},{"atl":[[220,4],[240,3.1]],"id":52385891},{"atl":[[29,9.29]],"id":52385903}],"con":true,"img":false}]}
{"op":"mcm","clk":"11450250083","pt":1717319623954,"mc":[{"id":"1.229554907","rc":[{"atl":[[120,1.34]],"id":52385882},{"atl":[[30,5]],"id":52385903}],"con":true,"img":false}]}
{"op":"mcm","clk":"11450250108","pt":1717319624260,"mc":[{"id":"1.229554907","rc":[{"atb":[[160,0],[80,0]],"id":52385907},{"atb":[[3.2,0],[3.7,0]],"id":52385909},{"atb":[[130,0],[230,0]],"id":52385886},{"atb":[[550,0],[650,0]],"id":52385918},{"atb":[[4,0],[3.5,0]],"id":52385888},{"atb":[[270,0],[170,2.92]],"id":52385920},{"atb":[[18.5,4.48],[13.5,0]],"id":52385889},{"atb":[[18,0],[13,0]],"id":52385882},{"atb":[[7.2,0],[9.2,0]],"id":52385884},{"atb":[[330,0],[230,0]],"id":52385917},{"atb":[[9,0],[7,0]],"id":52385895},{"atb":[[18,0],[13,11.93]],"id":52385891},{"atb":[[16.5,0],[23,0]],"id":52385923},{"atb":[[550,0],[650,0]],"id":52385893},{"atb":[[2.4,0],[2.6,0]],"id":52385934},{"atb":[[9,0],[7,0]],"id":52385903},{"atb":[[10,0],[15,0]],"id":52385936},{"atb":[[16.5,0],[11.5,0]],"id":52385904},{"atb":[[2.54,0],[2.74,0]],"id":52385931},{"atb":[[4,0],[5,0]],"id":52385932}],"con":true,"img":false}]}
{"op":"mcm","clk":"11450250148","pt":1717319624630,"mc":[{"id":"1.229554907","rc":[{"atb":[[20,4.11]],"id":52385882},{"atb":[[7,18.43]],"id":52385904}],"con":true,"img":false}]}
{"op":"mcm","clk":"11450250264","pt":1717319625875,"mc":[{"id":"1.229554907","rc":[{"atl":[[300,0],[370,2]],"id":52385907},{"atl":[[11.5,0],[13,8.33]],"id":52385909},{"atl":[[190,0],[230,2]],"id":52385889},{"atl":[[520,2],[420,0]],"id":52385936}],"con":true,"img":false}]}
{"op":"mcm","clk":"11450250350","pt":1717319626661,"mc":[{"id":"1.229554907","rc":[{"atb":[[34,4.39],[38,6.1]],"id":52385907},{"atb":[[130,2.71],[120,0]],"id":52385886},{"atb":[[6.8,17.28],[7,0]],"id":52385888},{"atb":[[180,0],[190,3.74]],"id":52385917},{"atl":[[220,0],[240,0]],"id":52385891},{"atb":[[170,3.17]],"id":52385893},{"atb":[[2.8,0],[2.76,0]],"id":52385934},{"atb":[[20,6.97]],"id":52385936},{"atb":[[6.4,3.22],[6,14.66]],"id":52385904},{"atb":[[3.2,0],[3.15,31.63]],"id":52385931}],"con":true,"img":false}]}
{"op":"mcm","clk":"11450250380","pt":1717319626970,"mc":[{"id":"1.229554907","rc":[{"atb":[[19,4.41]],"id":52385936}],"con":true,"img":false}]}
{"op":"mcm","clk":"11450250546","pt":1717319628848,"mc":[{"id":"1.229554907","rc":[{"atl":[[14,3.49]],"id":52385909}],"con":true,"img":false}]}
{"op":"mcm","clk":"11450250581","pt":1717319629265,"mc":[{"id":"1.229554907","rc":[{"atl":[[500,0.31]],"id":52385886},{"atl":[[50,4.43],[55,2]],"id":52385884},{"atl":[[220,3.26],[230,0]],"id":52385891},{"atl":[[44,4.48],[46,0]],"id":52385903},{"atb":[[18,0]],"id":52385936}],"con":true,"img":false}]}
{"op":"mcm","clk":"11450250664","pt":1717319630246,"mc":[{"id":"1.229554907","rc":[{"atl":[[180,0.89]],"id":52385907}],"con":true,"img":false}]}
{"op":"mcm","clk":"11450250710","pt":1717319630863,"mc":[{"id":"1.229554907","rc":[{"atl":[[370,5.02],[390,0]],"id":52385907},{"atl":[[500,3.76]],"id":52385886},{"atl":[[260,0],[240,3.81]],"id":52385889},{"atl":[[80,4.88],[85,0]],"id":52385895},{"atl":[[210,2.86],[220,0]],"id":52385891},{"atl":[[11.5,3.92],[12,0]],"id":52385932}],"con":true,"img":false}]}
{"op":"mcm","clk":"11450250722","pt":1717319630964,"mc":[{"id":"1.229554907","rc":[{"atl":[[360,0]],"id":52385907}],"con":true,"img":false}]}
{"op":"mcm","clk":"11450250750","pt":1717319631271,"mc":[{"id":"1.229554907","rc":[{"atl":[[75,7.17]],"id":52385882}],"con":true,"img":false}]}
{"op":"mcm","clk":"11450250811","pt":1717319631950,"mc":[{"id":"1.229554907","rc":[{"atl":[[120,0]],"id":52385882}],"con":true,"img":false}]}
{"op":"mcm","clk":"11450250949","pt":1717319633665,"mc":[{"id":"1.229554907","rc":[{"atl":[[14,0]],"id":52385909},{"atl":[[520,2.89],[500,0.31]],"id":52385886},{"atl":[[240,0],[250,3.06]],"id":52385889},{"atl":[[50,0],[55,5.91]],"id":52385884},{"atl":[[210,0],[220,4.03]],"id":52385891},{"atl":[[44,0],[46,3.67]],"id":52385903},{"atb":[[3.2,7.13],[3.15,24.33]],"id":52385931}],"con":true,"img":false}]}
{"op":"mcm","clk":"11450250966","pt":1717319633869,"mc":[{"id":"1.229554907","rc":[{"atl":[[29,3.57]],"id":52385903}],"con":true,"img":false}]}
{"op":"mcm","clk":"11450250976","pt":1717319633975,"mc":[{"id":"1.229554907","rc":[{"atl":[[180,0]],"id":52385907}],"con":true,"img":false}]}
{"op":"mcm","clk":"11450251026","pt":1717319634593,"mc":[{"id":"1.229554907","rc":[{"atl":[[30,10.53]],"id":52385903}],"con":true,"img":false}]}
{"op":"mcm","clk":"11450251037","pt":1717319634654,"mc":[{"id":"1.229554907","rc":[{"atl":[[190,5.85]],"id":52385907}],"con":true,"img":false}]}
{"op":"mcm","clk":"11450251157","pt":1717319636157,"mc":[{"id":"1.229554907","rc":[{"atl":[[15.5,4.02]],"id":52385909}],"con":true,"img":false}]}
{"op":"mcm","clk":"11450251515","pt":1717319640770,"mc":[{"id":"1.229554907","rc":[{"atl":[[540,3.86],[510,0]],"id":52385886},{"atl":[[270,3.78]],"id":52385889},{"atl":[[20,2.97]],"id":52385931}],"con":true,"img":false}]}
{"op":"mcm","clk":"11450251711","pt":1717319643105,"mc":[{"id":"1.229554907","rc":[{"atb":[[170,0.61],[85,2.9]],"id":52385907},{"atb":[[3.25,108.4],[3.75,38]],"id":52385909},{"atb":[[220,0.47],[120,2.05]],"id":52385886},{"atb":[[550,0.44],[650,0.16]],"id":52385918},{"atb":[[3.45,99.55],[3.95,35.43]],"id":52385888},{"atb":[[270,0.38],[170,4.37]],"id":52385920},{"atb":[[19,5.8],[14,18.76]],"id":52385889},{"atb":[[18,6.14],[13,20.32]],"id":52385882},{"atb":[[7.2,39.33],[9.2,12.74]],"id":52385884},{"atb":[[320,0.32],[220,1.11]],"id":52385917},{"atb":[[7.2,39.33],[9.2,12.74]],"id":52385895},{"atb":[[18.5,5.97],[13.5,31.51]],"id":52385891},{"atb":[[16.5,15.73],[23,4.75]],"id":52385923},{"atb":[[550,0.44],[650,0.16]],"id":52385893},{"atb":[[2.4,174.21],[2.6,65.33]],"id":52385934},{"atb":[[7.2,57.29],[9.2,15.94]],"id":52385903},{"atb":[[9.8,27.71],[14.5,7.74]],"id":52385936},{"atb":[[17.5,6.33],[12.5,21.2]],"id":52385904},{"atb":[[2.72,60.77],[2.52,160.46]],"id":52385931},{"atb":[[5.1,25.49],[4.1,78.68]],"id":52385932}],"con":true,"img":false}]}
{"op":"mcm","clk":"11450251760","pt":1717319643479,"mc":[{"id":"1.229554907","rc":[{"atl":[[300,2],[370,3.02]],"id":52385907},{"atl":[[11.5,9.52],[13,0]],"id":52385909},{"atl":[[190,2],[230,0]],"id":52385889},{"atl":[[520,0],[420,2]],"id":52385936}],"con":true,"img":false}]}
{"op":"mcm","clk":"11450251788","pt":1717319643783,"mc":[{"id":"1.229554907","rc":[{"atb":[[130,0],[120,5.56]],"id":52385886},{"atl":[[290,0]],"id":52385889},{"atb":[[190,0]],"id":52385917},{"atb":[[95,3.04],[100,0.53]],"id":52385923},{"atb":[[2.8,8.72],[2.84,51.18]],"id":52385934},{"atb":[[19,0],[20,4.13]],"id":52385936},{"atb":[[8,0],[5.5,0],[6,0],[7,10.5]],"id":52385932}],"con":true,"img":false}]}
{"op":"mcm","clk":"11450251835","pt":1717319644300,"mc":[{"id":"1.229554907","rc":[{"atl":[[14,4.46],[14.5,0]],"id":52385909},{"atl":[[520,0],[500,4.52]],"id":52385886},{"atb":[[170,1.44],[180,4.2]],"id":52385920},{"atl":[[270,0],[240,3.45],[250,0]],"id":52385889},{"atl":[[50,2.96],[55,2]],"id":52385884},{"atl":[[210,2.83],[220,0]],"id":52385891},{"atb":[[2.76,8.92]],"id":52385934},{"atl":[[44,4.01],[46,0]],"id":52385903},{"atb":[[3.2,0],[3.15,31.63]],"id":52385931},{"atb":[[7.4,18.42]],"id":52385932}],"con":true,"img":false}]}
{"op":"mcm","clk":"11450251854","pt":1717319644507,"mc":[{"id":"1.229554907","rc":[{"atb":[[5.6,22.75],[7.2,8.44],[6.2,15.09],[8.2,3.63]],"id":52385932}],"con":true,"img":false}]}
{"op":"mcm","clk":"11450251896","pt":1717319644973,"mc":[{"id":"1.229554907","rc":[{"atb":[[7,0]],"id":52385932}],"con":true,"img":false}]}
{"op":"mcm","clk":"11450252277","pt":1717319649371,"mc":[{"id":"1.229554907","rc":[{"atl":[[14,0]],"id":52385909},{"atb":[[120,2.05]],"id":52385886},{"atl":[[130,6.32],[140,0]],"id":52385882},{"atb":[[95,0],[100,3.8]],"id":52385923},{"atb":[[2.84,42.65]],"id":52385934}],"con":true,"img":false}]}
{"op":"mcm","clk":"11450252295","pt":1717319649476,"mc":[{"id":"1.229554907","rc":[{"atl":[[14.5,3.37]],"id":52385909},{"atb":[[130,2.72]],"id":52385886},{"atb":[[19,3.88],[20,8.11]],"id":52385936},{"atl":[[100,3.32],[110,0]],"id":52385904},{"atl":[[11.5,0],[12,4.58]],"id":52385932}],"con":true,"img":false}]}
{"op":"mcm","clk":"11450252381","pt":1717319650604,"mc":[{"id":"1.229554907","rc":[{"atl":[[36,0],[38,5]],"id":52385884},{"atb":[[3.7,5],[3.75,0]],"id":52385934},{"atb":[[25,7.19],[26,0]],"id":52385936},{"atb":[[7.2,13.45],[7.4,5]],"id":52385932}],"con":true,"img":false}]}
{"op":"mcm","clk":"11450252389","pt":1717319650709,"mc":[{"id":"1.229554907","rc":[{"atb":[[7.4,0]],"id":52385932}],"con":true,"img":false}]}
{"op":"mcm","clk":"11450252403","pt":1717319650868,"mc":[{"id":"1.229554907","rc":[{"atl":[[32,5],[30,0]],"id":52385903}],"con":true,"img":false}]}
{"op":"mcm","clk":"11450252413","pt":1717319650971,"mc":[{"id":"1.229554907","rc":[{"atl":[[30,3.45]],"id":52385903}],"con":true,"img":false}]}
