{"op":"mcm","clk":"11448127638","pt":1717286034977,"mc":[{"id":"1.229554906","marketDefinition":{"bspMarket":true,"turnInPlayEnabled":false,"persistenceEnabled":false,"marketBaseRate":7.0,"eventId":"33318908","eventTypeId":"4339","numberOfWinners":2,"bettingType":"ODDS","marketType":"PLACE","marketTime":"2024-06-02T09:20:00.000Z","suspendTime":"2024-06-02T09:20:00.000Z","bspReconciled":false,"complete":true,"inPlay":false,"crossMatching":true,"runnersVoidable":false,"numberOfActiveRunners":5,"betDelay":0,"status":"OPEN","runners":[{"status":"ACTIVE","sortPriority":1,"id":61631980,"name":"1. Opella"},{"status":"ACTIVE","sortPriority":2,"id":57451148,"name":"2. Taras Girl"},{"status":"ACTIVE","sortPriority":3,"id":61631978,"name":"4. Elwomple"},{"status":"ACTIVE","sortPriority":4,"id":42269942,"name":"6. Hey Sisco"},{"status":"ACTIVE","sortPriority":5,"id":60780007,"name":"8. Got Rhythm"}],"regulators":["MR_INT"],"venue":"Murray Bridge","countryCode":"AU","discountAllowed":true,"timezone":"Australia/Adelaide","openDate":"2024-06-02T08:21:00.000Z","version":5962317622,"name":"To Be Placed","eventName":"Murray Bridge (AUS) 2nd Jun"},"rc":[],"con":true,"img":false}]}
{"op":"mcm","clk":"11448258036","pt":1717287872067,"mc":[{"id":"1.229554906","rc":[{"atb":[[8.6,3.05],[6.6,6.22]],"id":42269942},{"spn":"Infinity","spf":"NaN","id":42269942},{"atb":[[2.4,24.88],[2.6,14.51]],"id":57451148},{"atl":[[16.5,0.03]],"id":57451148},{"spn":9.55,"spf":"NaN","id":57451148},{"atb":[[1.01,5807.26]],"id":60780007},{"atl":[[2.58,0.32]],"id":60780007},{"spn":1.79,"spf":"NaN","id":60780007},{"atb":[[1.75,30.97],[1.65,53.6]],"id":61631980},{"atl":[[7,0.08]],"id":61631980},{"spn":4.37,"spf":"NaN","id":61631980},{"atb":[[1.51,68.32],[1.61,38.08]],"id":61631978},{"atl":[[5.7,0.1]],"id":61631978},{"spn":3.65,"spf":"NaN","id":61631978}],"con":true,"img":false}]}
{"op":"mcm","clk":"11448259645","pt":1717287895294,"mc":[{"id":"1.229554906","rc":[{"atb":[[8.6,0],[6.6,0]],"id":42269942},{"atb":[[2.4,0],[2.6,0]],"id":57451148},{"atl":[[16.5,0]],"id":57451148},{"atb":[[1.01,0]],"id":60780007},{"atl":[[2.58,0]],"id":60780007},{"atb":[[1.75,0],[1.65,0]],"id":61631980},{"atl":[[7,0]],"id":61631980},{"atb":[[1.51,0],[1.61,0]],"id":61631978},{"atl":[[5.7,0]],"id":61631978}],"con":true,"img":false}]}
{"op":"mcm","clk":"11448260594","pt":1717287908430,"mc":[{"id":"1.229554906","rc":[{"atb":[[6.8,6],[8.8,2.97]],"id":42269942},{"atb":[[2.64,14.16],[2.44,24.19]],"id":57451148},{"atl":[[17.5,0.03]],"id":57451148},{"atb":[[1.01,5807.26]],"id":60780007},{"atl":[[2.52,0.34]],"id":60780007},{"atb":[[1.64,54.44],[1.74,31.39]],"id":61631980},{"atl":[[6.8,0.08]],"id":61631980},{"atb":[[1.63,36.87],[1.53,65.74]],"id":61631978},{"atl":[[5.9,0.1]],"id":61631978}],"con":true,"img":false}]}
{"op":"mcm","clk":"11448264312","pt":1717287962366,"mc":[{"id":"1.229554906","rc":[{"atb":[[6.8,0],[8.8,0]],"id":42269942},{"spn":"NaN","spf":"NaN","id":42269942},{"atb":[[2.64,0],[2.44,0]],"id":57451148},{"atl":[[17.5,0]],"id":57451148},{"spn":"NaN","spf":"NaN","id":57451148},{"atb":[[1.01,0]],"id":60780007},{"atl":[[2.52,0]],"id":60780007},{"spn":"NaN","spf":"NaN","id":60780007},{"atb":[[1.64,0],[1.74,0]],"id":61631980},{"atl":[[6.8,0]],"id":61631980},{"spn":"NaN","spf":"NaN","id":61631980},{"atb":[[1.63,0],[1.53,0]],"id":61631978},{"atl":[[5.9,0]],"id":61631978},{"spn":"NaN","spf":"NaN","id":61631978}],"con":true,"img":false}]}
{"op":"mcm","clk":"11448265018","pt":1717287972318,"mc":[{"id":"1.229554906","rc":[{"atb":[[8.6,3.05],[6.6,6.22]],"id":42269942},{"atb":[[2.64,14.16],[2.44,24.19]],"id":57451148},{"atl":[[17.5,0.03]],"id":57451148},{"atb":[[1.01,5807.26]],"id":60780007},{"atl":[[2.48,0.35]],"id":60780007},{"atb":[[1.81,28.67],[1.71,49.07]],"id":61631980},{"atl":[[7.4,0.08]],"id":61631980},{"atb":[[1.58,40.04],[1.48,72.59]],"id":61631978},{"atl":[[5.4,0.12]],"id":61631978}],"con":true,"img":false}]}
{"op":"mcm","clk":"11448266377","pt":1717287995151,"mc":[{"id":"1.229554906","rc":[{"atb":[[1.58,0],[1.48,0]],"id":61631978},{"atl":[[5.4,0]],"id":61631978}],"con":true,"img":false}]}
{"op":"mcm","clk":"11448266886","pt":1717288003942,"mc":[{"id":"1.229554906","rc":[{"atb":[[1.6,38.71],[1.5,69.68]],"id":61631978},{"atl":[[5.6,0.11]],"id":61631978}],"con":true,"img":false}]}
{"op":"mcm","clk":"11448272364","pt":1717288089682,"mc":[{"id":"1.229554906","rc":[{"spn":"Infinity","spf":"NaN","id":42269942},{"spn":10.07,"spf":"NaN","id":57451148},{"spn":1.74,"spf":"NaN","id":60780007},{"spn":4.6,"spf":"NaN","id":61631980},{"atb":[[1.6,0],[1.5,0]],"id":61631978},{"atl":[[5.6,0]],"id":61631978}],"con":true,"img":false}]}
{"op":"mcm","clk":"11448273012","pt":1717288099886,"mc":[{"id":"1.229554906","rc":[{"atb":[[1.51,68.32],[1.61,38.08]],"id":61631978},{"atl":[[5.7,0.1]],"id":61631978}],"con":true,"img":false}]}
{"op":"mcm","clk":"11448277241","pt":1717288128429,"mc":[{"id":"1.229554906","marketDefinition":{"bspMarket":true,"turnInPlayEnabled":false,"persistenceEnabled":false,"marketBaseRate":7.0,"eventId":"33318908","eventTypeId":"4339","numberOfWinners":2,"bettingType":"ODDS","marketType":"PLACE","marketTime":"2024-06-02T09:20:00.000Z","suspendTime":"2024-06-02T09:20:00.000Z","bspReconciled":false,"complete":true,"inPlay":false,"crossMatching":true,"runnersVoidable":false,"numberOfActiveRunners":5,"betDelay":0,"status":"OPEN","runners":[{"status":"ACTIVE","sortPriority":1,"id":61631980,"name":"1. Opella"},{"status":"ACTIVE","sortPriority":2,"id":57451148,"name":"2. Taras Girl"},{"status":"ACTIVE","sortPriority":3,"id":61631978,"name":"4. Elwomple"},{"status":"ACTIVE","sortPriority":4,"id":42269942,"name":"6. Hey Sisco"},{"status":"ACTIVE","sortPriority":5,"id":60780007,"name":"8. Got Rhythm"}],"regulators":["MR_INT"],"venue":"Murray Bridge","countryCode":"AU","discountAllowed":true,"timezone":"Australia/Adelaide","openDate":"2024-06-02T08:21:00.000Z","version":5962317622,"name":"To Be Placed","eventName":"Murray Bridge (AUS) 2nd Jun"},"rc":[{"atb":[[8.6,3.05],[6.6,6.22]],"id":42269942},{"spn":"Infinity","spf":"NaN","id":42269942},{"atb":[[2.64,14.16],[2.44,24.19]],"id":57451148},{"atl":[[17.5,0.03]],"id":57451148},{"spn":10.07,"spf":"NaN","id":57451148},{"atb":[[1.01,5807.26]],"id":60780007},{"atl":[[2.48,0.35]],"id":60780007},{"spn":1.74,"spf":"NaN","id":60780007},{"atb":[[1.81,28.67],[1.71,49.07]],"id":61631980},{"atl":[[7.4,0.08]],"id":61631980},{"spn":4.6,"spf":"NaN","id":61631980},{"atb":[[1.51,68.32],[1.61,38.08]],"id":61631978},{"atl":[[5.7,0.1]],"id":61631978},{"spn":"NaN","spf":"NaN","id":61631978}],"con":true,"img":true}]}
{"op":"mcm","clk":"11448292464","pt":1717288273959,"mc":[{"id":"1.229554906","rc":[{"atb":[[8.6,0],[6.6,0]],"id":42269942},{"spn":"NaN","spf":"NaN","id":42269942},{"atb":[[2.64,0],[2.44,0]],"id":57451148},{"atl":[[17.5,0]],"id":57451148},{"spn":"NaN","spf":"NaN","id":57451148},{"atb":[[1.01,0]],"id":60780007},{"atl":[[2.48,0]],"id":60780007},{"spn":"NaN","spf":"NaN","id":60780007},{"atb":[[1.81,0],[1.71,0]],"id":61631980},{"atl":[[7.4,0]],"id":61631980},{"spn":"NaN","spf":"NaN","id":61631980},{"atb":[[1.51,0],[1.61,0]],"id":61631978},{"atl":[[5.7,0]],"id":61631978}],"con":true,"img":false}]}
{"op":"mcm","clk":"11448293804","pt":1717288291623,"mc":[{"id":"1.229554906","rc":[{"atb":[[6.4,6.45],[8.4,3.13]],"id":42269942},{"atb":[[2.72,13.5],[2.52,22.92]],"id":57451148},{"atb":[[1.01,5807.26]],"id":60780007},{"atl":[[2.48,0.35]],"id":60780007},{"atb":[[1.72,32.26],[1.62,56.19]],"id":61631980},{"atl":[[6.8,0.08]],"id":61631980},{"atb":[[1.51,68.32],[1.61,38.08]],"id":61631978},{"atl":[[5.7,0.1]],"id":61631978}],"con":true,"img":false}]}
{"op":"mcm","clk":"11448298269","pt":1717288351379,"mc":[{"id":"1.229554906","rc":[{"spn":"Infinity","spf":"NaN","id":42269942},{"atb":[[2.72,0],[2.52,0]],"id":57451148},{"spn":1.74,"spf":"NaN","id":60780007},{"atb":[[1.72,0],[1.62,0]],"id":61631980},{"atl":[[6.8,0]],"id":61631980},{"atb":[[1.51,0],[1.61,0]],"id":61631978},{"atl":[[5.7,0]],"id":61631978}],"con":true,"img":false}]}
{"op":"mcm","clk":"11448300795","pt":1717288383947,"mc":[{"id":"1.229554906","rc":[{"atb":[[2.58,22.05],[2.78,13.04]],"id":57451148},{"atb":[[1.81,28.67],[1.71,49.07]],"id":61631980},{"atl":[[7.4,0.08]],"id":61631980},{"atb":[[1.41,84.98],[1.51,45.54]],"id":61631978},{"atl":[[4.6,0.14]],"id":61631978}],"con":true,"img":false}]}
{"op":"mcm","clk":"11448629971","pt":1717293528419,"mc":[{"id":"1.229554906","marketDefinition":{"bspMarket":true,"turnInPlayEnabled":false,"persistenceEnabled":false,"marketBaseRate":7.0,"eventId":"33318908","eventTypeId":"4339","numberOfWinners":2,"bettingType":"ODDS","marketType":"PLACE","marketTime":"2024-06-02T09:20:00.000Z","suspendTime":"2024-06-02T09:20:00.000Z","bspReconciled":false,"complete":true,"inPlay":false,"crossMatching":true,"runnersVoidable":false,"numberOfActiveRunners":5,"betDelay":0,"status":"OPEN","runners":[{"status":"ACTIVE","sortPriority":1,"id":61631980,"name":"1. Opella"},{"status":"ACTIVE","sortPriority":2,"id":57451148,"name":"2. Taras Girl"},{"status":"ACTIVE","sortPriority":3,"id":61631978,"name":"4. Elwomple"},{"status":"ACTIVE","sortPriority":4,"id":42269942,"name":"6. Hey Sisco"},{"status":"ACTIVE","sortPriority":5,"id":60780007,"name":"8. Got Rhythm"}],"regulators":["MR_INT"],"venue":"Murray Bridge","countryCode":"AU","discountAllowed":true,"timezone":"Australia/Adelaide","openDate":"2024-06-02T08:21:00.000Z","version":5962317622,"name":"To Be Placed","eventName":"Murray Bridge (AUS) 2nd Jun"},"rc":[{"atb":[[6.4,6.45],[8.4,3.13]],"id":42269942},{"spn":"Infinity","spf":"NaN","id":42269942},{"atb":[[2.58,22.05],[2.78,13.04]],"id":57451148},{"spn":"Infinity","spf":"NaN","id":57451148},{"atb":[[1.01,5807.26]],"id":60780007},{"atl":[[2.48,0.35]],"id":60780007},{"spn":1.74,"spf":"NaN","id":60780007},{"atb":[[1.81,28.67],[1.71,49.07]],"id":61631980},{"atl":[[7.4,0.08]],"id":61631980},{"spn":4.6,"spf":"NaN","id":61631980},{"atb":[[1.41,84.98],[1.51,45.54]],"id":61631978},{"atl":[[4.6,0.14]],"id":61631978},{"spn":3.05,"spf":"NaN","id":61631978}],"con":true,"img":true}]}
{"op":"mcm","clk":"11448957710","pt":1717300805068,"mc":[{"id":"1.229554906","rc":[{"atb":[[6.4,0],[8.4,0]],"id":42269942},{"spn":"NaN","spf":"NaN","id":42269942},{"atb":[[2.58,0],[2.78,0]],"id":57451148},{"atb":[[1.01,0]],"id":60780007},{"atl":[[2.48,0]],"id":60780007},{"spn":"NaN","spf":"NaN","id":60780007},{"atb":[[1.81,0],[1.71,0]],"id":61631980},{"atl":[[7.4,0]],"id":61631980},{"atb":[[1.41,0],[1.51,0]],"id":61631978},{"atl":[[4.6,0]],"id":61631978}],"con":true,"img":false}]}
{"op":"mcm","clk":"11448958449","pt":1717300819077,"mc":[{"id":"1.229554906","rc":[{"atb":[[7.4,5.44],[9.4,2.76]],"id":42269942},{"atb":[[2.8,12.9],[2.6,21.77]],"id":57451148},{"atb":[[1.01,5807.26]],"id":60780007},{"atl":[[2.38,0.37]],"id":60780007},{"atb":[[1.67,52],[1.77,30.16]],"id":61631980},{"atl":[[7,0.08]],"id":61631980},{"atb":[[1.63,36.87],[1.53,65.74]],"id":61631978},{"atl":[[5.9,0.1]],"id":61631978}],"con":true,"img":false}]}
{"op":"mcm","clk":"11448963909","pt":1717300914420,"mc":[{"id":"1.229554906","rc":[{"spn":"Infinity","spf":"NaN","id":42269942},{"atb":[[2.8,0],[2.6,0]],"id":57451148},{"spn":1.69,"spf":"NaN","id":60780007},{"atb":[[1.67,0],[1.77,0]],"id":61631980},{"atl":[[7,0]],"id":61631980},{"atb":[[1.63,0],[1.53,0]],"id":61631978},{"atl":[[5.9,0]],"id":61631978}],"con":true,"img":false}]}
{"op":"mcm","clk":"11448965586","pt":1717300945947,"mc":[{"id":"1.229554906","rc":[{"atb":[[3.1,11.05],[2.84,18.93]],"id":57451148},{"atb":[[1.75,30.97],[1.65,53.6]],"id":61631980},{"atl":[[7,0.08]],"id":61631980},{"atb":[[1.6,38.71],[1.5,69.68]],"id":61631978},{"atl":[[5.6,0.11]],"id":61631978}],"con":true,"img":false}]}
{"op":"mcm","clk":"11449119158","pt":1717304328432,"mc":[{"id":"1.229554906","marketDefinition":{"bspMarket":true,"turnInPlayEnabled":false,"persistenceEnabled":false,"marketBaseRate":7.0,"eventId":"33318908","eventTypeId":"4339","numberOfWinners":2,"bettingType":"ODDS","marketType":"PLACE","marketTime":"2024-06-02T09:20:00.000Z","suspendTime":"2024-06-02T09:20:00.000Z","bspReconciled":false,"complete":true,"inPlay":false,"crossMatching":true,"runnersVoidable":false,"numberOfActiveRunners":5,"betDelay":0,"status":"OPEN","runners":[{"status":"ACTIVE","sortPriority":1,"id":61631980,"name":"1. Opella"},{"status":"ACTIVE","sortPriority":2,"id":57451148,"name":"2. Taras Girl"},{"status":"ACTIVE","sortPriority":3,"id":61631978,"name":"4. Elwomple"},{"status":"ACTIVE","sortPriority":4,"id":42269942,"name":"6. Hey Sisco"},{"status":"ACTIVE","sortPriority":5,"id":60780007,"name":"8. Got Rhythm"}],"regulators":["MR_INT"],"venue":"Murray Bridge","countryCode":"AU","discountAllowed":true,"timezone":"Australia/Adelaide","openDate":"2024-06-02T08:21:00.000Z","version":5962317622,"name":"To Be Placed","eventName":"Murray Bridge (AUS) 2nd Jun"},"rc":[{"atb":[[7.4,5.44],[9.4,2.76]],"id":42269942},{"spn":"Infinity","spf":"NaN","id":42269942},{"atb":[[3.1,11.05],[2.84,18.93]],"id":57451148},{"spn":"Infinity","spf":"NaN","id":57451148},{"atb":[[1.01,5807.26]],"id":60780007},{"atl":[[2.38,0.37]],"id":60780007},{"spn":1.69,"spf":"NaN","id":60780007},{"atb":[[1.75,30.97],[1.65,53.6]],"id":61631980},{"atl":[[7,0.08]],"id":61631980},{"spn":4.37,"spf":"NaN","id":61631980},{"atb":[[1.6,38.71],[1.5,69.68]],"id":61631978},{"atl":[[5.6,0.11]],"id":61631978},{"spn":3.6,"spf":"NaN","id":61631978}],"con":true,"img":true}]}
{"op":"mcm","clk":"11449358390","pt":1717307834349,"mc":[{"id":"1.229554906","rc":[{"atb":[[1.02,8.87]],"id":42269942},{"atl":[[990,0.85]],"id":42269942},{"spn":499.7,"spf":"NaN","id":42269942},{"atb":[[1.02,8.87]],"id":57451148},{"atl":[[990,0.85]],"id":57451148},{"spn":496.55,"spf":"NaN","id":57451148},{"atb":[[1.02,8.87]],"id":60780007},{"atl":[[990,0.85]],"id":60780007},{"spn":1.7,"spf":"NaN","id":60780007},{"atb":[[1.01,17.76]],"id":61631980},{"atl":[[990,0.85]],"id":61631980},{"spn":4.37,"spf":"NaN","id":61631980},{"atb":[[1.01,17.76]],"id":61631978},{"atl":[[990,0.85]],"id":61631978},{"spn":3.6,"spf":"NaN","id":61631978}],"con":true,"img":false}]}
{"op":"mcm","clk":"11449448623","pt":1717309303098,"mc":[{"id":"1.229554906","rc":[{"atb":[[7.4,0],[9.4,0]],"id":42269942},{"spn":495.51,"spf":"NaN","id":42269942},{"atb":[[3.1,0],[2.84,0]],"id":57451148},{"spn":495.51,"spf":"NaN","id":57451148},{"atb":[[1.01,0]],"id":60780007},{"atl":[[2.38,0]],"id":60780007},{"spn":495.51,"spf":"NaN","id":60780007},{"atb":[[1.75,0],[1.65,0]],"id":61631980},{"atl":[[7,0]],"id":61631980},{"spn":495.5,"spf":"NaN","id":61631980},{"atb":[[1.6,0],[1.5,0]],"id":61631978},{"atl":[[5.6,0]],"id":61631978},{"spn":495.5,"spf":"NaN","id":61631978}],"con":true,"img":false}]}
{"op":"mcm","clk":"11449449633","pt":1717309317217,"mc":[{"id":"1.229554906","rc":[{"atb":[[6.4,6.45],[8.4,3.13]],"id":42269942},{"atb":[[2.9,12.22],[2.7,20.49]],"id":57451148},{"atb":[[1.01,5807.26]],"id":60780007},{"atl":[[2.36,0.38]],"id":60780007},{"atb":[[1.72,32.26],[1.62,56.19]],"id":61631980},{"atl":[[6.8,0.08]],"id":61631980},{"atb":[[1.56,62.22],[1.66,35.19]],"id":61631978},{"atl":[[6.2,0.09]],"id":61631978}],"con":true,"img":false}]}
{"op":"mcm","clk":"11449451521","pt":1717309344449,"mc":[{"id":"1.229554906","rc":[{"atb":[[6.4,0],[8.4,0]],"id":42269942},{"atb":[[2.9,0],[2.7,0]],"id":57451148},{"atb":[[1.01,0]],"id":60780007},{"atl":[[2.36,0]],"id":60780007},{"atb":[[1.72,0],[1.62,0]],"id":61631980},{"atl":[[6.8,0]],"id":61631980},{"atb":[[1.56,0],[1.66,0]],"id":61631978},{"atl":[[6.2,0]],"id":61631978}],"con":true,"img":false}]}
{"op":"mcm","clk":"11449452507","pt":1717309358077,"mc":[{"id":"1.229554906","rc":[{"atb":[[10.5,2.44],[8.2,4.83]],"id":42269942},{"atb":[[2.88,12.35],[2.68,20.73]],"id":57451148},{"atb":[[1.01,5807.26]],"id":60780007},{"atl":[[2.32,0.39]],"id":60780007},{"atb":[[1.64,54.44],[1.74,31.39]],"id":61631980},{"atl":[[6.8,0.08]],"id":61631980},{"atb":[[1.56,62.22],[1.66,35.19]],"id":61631978},{"atl":[[6.2,0.09]],"id":61631978}],"con":true,"img":false}]}
{"op":"mcm","clk":"11449454214","pt":1717309383995,"mc":[{"id":"1.229554906","rc":[{"atb":[[10.5,0],[8.2,0]],"id":42269942},{"atb":[[2.88,0],[2.68,0]],"id":57451148},{"spn":1.67,"spf":"NaN","id":60780007},{"atb":[[1.64,0],[1.74,0]],"id":61631980},{"atl":[[6.8,0]],"id":61631980},{"atb":[[1.56,0],[1.66,0]],"id":61631978},{"atl":[[6.2,0]],"id":61631978}],"con":true,"img":false}]}
{"op":"mcm","clk":"11449454762","pt":1717309392781,"mc":[{"id":"1.229554906","rc":[{"atb":[[7.4,5.44],[9.4,2.76]],"id":42269942},{"atb":[[2.82,19.14],[3.05,11.33]],"id":57451148},{"atb":[[1.64,54.44],[1.74,31.39]],"id":61631980},{"atl":[[6.8,0.08]],"id":61631980},{"atb":[[1.51,68.32],[1.61,38.08]],"id":61631978},{"atl":[[5.7,0.1]],"id":61631978}],"con":true,"img":false}]}
{"op":"mcm","clk":"11449456317","pt":1717309418730,"mc":[{"id":"1.229554906","rc":[{"atb":[[7.4,0],[9.4,0]],"id":42269942},{"atb":[[2.82,0],[3.05,0]],"id":57451148},{"atb":[[1.64,0],[1.74,0]],"id":61631980},{"atl":[[6.8,0]],"id":61631980},{"atb":[[1.51,0],[1.61,0]],"id":61631978},{"atl":[[5.7,0]],"id":61631978}],"con":true,"img":false}]}
{"op":"mcm","clk":"11449457105","pt":1717309431138,"mc":[{"id":"1.229554906","rc":[{"atb":[[8.6,3.05],[6.6,6.22]],"id":42269942},{"atb":[[2.82,19.14],[3.05,11.33]],"id":57451148},{"atb":[[1.59,59.05],[1.69,33.66]],"id":61631980},{"atl":[[6.6,0.09]],"id":61631980},{"atb":[[1.58,60.07],[1.68,34.15]],"id":61631978},{"atl":[[6.4,0.09]],"id":61631978}],"con":true,"img":false}]}
{"op":"mcm","clk":"11449459037","pt":1717309460099,"mc":[{"id":"1.229554906","rc":[{"atb":[[8.6,0],[6.6,0]],"id":42269942},{"atb":[[2.82,0],[3.05,0]],"id":57451148},{"atb":[[1.59,0],[1.69,0]],"id":61631980},{"atl":[[6.6,0]],"id":61631980},{"atb":[[1.58,0],[1.68,0]],"id":61631978},{"atl":[[6.4,0]],"id":61631978}],"con":true,"img":false}]}
{"op":"mcm","clk":"11449460680","pt":1717309485424,"mc":[{"id":"1.229554906","rc":[{"atb":[[7.4,5.44],[9.4,2.76]],"id":42269942},{"atb":[[3.1,11.05],[2.84,18.93]],"id":57451148},{"atb":[[1.66,52.79],[1.76,30.56]],"id":61631980},{"atl":[[7,0.08]],"id":61631980},{"atb":[[1.62,37.46],[1.52,67]],"id":61631978},{"atl":[[5.8,0.1]],"id":61631978}],"con":true,"img":false}]}
{"op":"mcm","clk":"11449462421","pt":1717309511563,"mc":[{"id":"1.229554906","rc":[{"atb":[[7.4,0],[9.4,0]],"id":42269942},{"atb":[[1.66,0],[1.76,0]],"id":61631980},{"atl":[[7,0]],"id":61631980},{"atb":[[1.62,0],[1.52,0]],"id":61631978},{"atl":[[5.8,0]],"id":61631978}],"con":true,"img":false}]}
{"op":"mcm","clk":"11449463292","pt":1717309524777,"mc":[{"id":"1.229554906","rc":[{"atb":[[9,2.9],[7,5.8]],"id":42269942},{"spn":499.5,"spf":"NaN","id":42269942},{"spn":496.55,"spf":"NaN","id":57451148},{"atb":[[1.67,52],[1.77,30.16]],"id":61631980},{"atl":[[7,0.08]],"id":61631980},{"spn":4.38,"spf":"NaN","id":61631980},{"atb":[[1.64,36.29],[1.54,64.52]],"id":61631978},{"atl":[[6,0.1]],"id":61631978},{"spn":3.82,"spf":"NaN","id":61631978}],"con":true,"img":false}]}
{"op":"mcm","clk":"11449471755","pt":1717309643556,"mc":[{"id":"1.229554906","rc":[{"atb":[[9,0],[7,0]],"id":42269942},{"spn":495.51,"spf":"NaN","id":42269942},{"atb":[[3.1,0],[2.84,0]],"id":57451148},{"spn":495.51,"spf":"NaN","id":57451148},{"atb":[[1.01,0]],"id":60780007},{"atl":[[2.32,0]],"id":60780007},{"spn":495.51,"spf":"NaN","id":60780007},{"atb":[[1.67,0],[1.77,0]],"id":61631980},{"atl":[[7,0]],"id":61631980},{"spn":495.5,"spf":"NaN","id":61631980},{"atb":[[1.64,0],[1.54,0]],"id":61631978},{"atl":[[6,0]],"id":61631978},{"spn":495.5,"spf":"NaN","id":61631978}],"con":true,"img":false}]}
{"op":"mcm","clk":"11449472678","pt":1717309655680,"mc":[{"id":"1.229554906","rc":[{"atb":[[7.2,5.61],[9.2,2.83]],"id":42269942},{"atb":[[3.1,11.05],[2.84,18.93]],"id":57451148},{"atb":[[1.01,5807.26]],"id":60780007},{"atl":[[2.3,0.4]],"id":60780007},{"atb":[[1.72,32.26],[1.62,56.19]],"id":61631980},{"atl":[[6.8,0.08]],"id":61631980},{"atb":[[1.64,36.29],[1.54,64.52]],"id":61631978},{"atl":[[6,0.1]],"id":61631978}],"con":true,"img":false}]}
{"op":"mcm","clk":"11449474634","pt":1717309682617,"mc":[{"id":"1.229554906","rc":[{"atb":[[7.2,0],[9.2,0]],"id":42269942},{"atb":[[3.1,0],[2.84,0]],"id":57451148},{"atb":[[1.72,0],[1.62,0]],"id":61631980},{"atl":[[6.8,0]],"id":61631980},{"atb":[[1.64,0],[1.54,0]],"id":61631978},{"atl":[[6,0]],"id":61631978}],"con":true,"img":false}]}
{"op":"mcm","clk":"11449475793","pt":1717309697516,"mc":[{"id":"1.229554906","rc":[{"atb":[[9.6,2.69],[7.6,5.27]],"id":42269942},{"atb":[[2.9,18.33],[3.25,10.32]],"id":57451148},{"atb":[[1.73,31.81],[1.63,55.3]],"id":61631980},{"atl":[[6.8,0.08]],"id":61631980},{"atb":[[1.62,37.46],[1.52,67]],"id":61631978},{"atl":[[5.8,0.1]],"id":61631978}],"con":true,"img":false}]}
{"op":"mcm","clk":"11449480357","pt":1717309728420,"mc":[{"id":"1.229554906","marketDefinition":{"bspMarket":true,"turnInPlayEnabled":false,"persistenceEnabled":false,"marketBaseRate":7.0,"eventId":"33318908","eventTypeId":"4339","numberOfWinners":2,"bettingType":"ODDS","marketType":"PLACE","marketTime":"2024-06-02T09:20:00.000Z","suspendTime":"2024-06-02T09:20:00.000Z","bspReconciled":false,"complete":true,"inPlay":false,"crossMatching":true,"runnersVoidable":false,"numberOfActiveRunners":5,"betDelay":0,"status":"OPEN","runners":[{"status":"ACTIVE","sortPriority":1,"id":61631980,"name":"1. Opella"},{"status":"ACTIVE","sortPriority":2,"id":57451148,"name":"2. Taras Girl"},{"status":"ACTIVE","sortPriority":3,"id":61631978,"name":"4. Elwomple"},{"status":"ACTIVE","sortPriority":4,"id":42269942,"name":"6. Hey Sisco"},{"status":"ACTIVE","sortPriority":5,"id":60780007,"name":"8. Got Rhythm"}],"regulators":["MR_INT"],"venue":"Murray Bridge","countryCode":"AU","discountAllowed":true,"timezone":"Australia/Adelaide","openDate":"2024-06-02T08:21:00.000Z","version":5962317622,"name":"To Be Placed","eventName":"Murray Bridge (AUS) 2nd Jun"},"rc":[{"atb":[[9.6,2.69],[1.02,8.87],[7.6,5.27]],"id":42269942},{"atl":[[990,0.85]],"id":42269942},{"spn":499.8,"spf":"NaN","id":42269942},{"atb":[[2.9,18.33],[1.02,8.87],[3.25,10.32]],"id":57451148},{"atl":[[990,0.85]],"id":57451148},{"spn":496.62,"spf":"NaN","id":57451148},{"atb":[[1.01,5807.26],[1.02,8.87]],"id":60780007},{"atl":[[2.3,0.4],[990,0.85]],"id":60780007},{"spn":1.66,"spf":"NaN","id":60780007},{"atb":[[1.73,31.81],[1.63,55.3],[1.01,17.76]],"id":61631980},{"atl":[[6.8,0.08],[990,0.85]],"id":61631980},{"spn":4.26,"spf":"NaN","id":61631980},{"atb":[[1.01,17.76],[1.62,37.46],[1.52,67]],"id":61631978},{"atl":[[5.8,0.1],[990,0.85]],"id":61631978},{"spn":3.71,"spf":"NaN","id":61631978}],"con":true,"img":true}]}
{"op":"mcm","clk":"11449495560","pt":1717309879327,"mc":[{"id":"1.229554906","rc":[{"atb":[[9.6,0],[7.6,0]],"id":42269942},{"atb":[[2.9,0],[3.25,0]],"id":57451148},{"spn":1.66,"spf":"NaN","id":60780007},{"atb":[[1.73,0],[1.63,0]],"id":61631980},{"atl":[[6.8,0]],"id":61631980},{"atb":[[1.62,0],[1.52,0]],"id":61631978},{"atl":[[5.8,0]],"id":61631978}],"con":true,"img":false}]}
{"op":"mcm","clk":"11449496101","pt":1717309887943,"mc":[{"id":"1.229554906","rc":[{"atb":[[7.4,5.44],[9.4,2.76]],"id":42269942},{"atb":[[3.1,11.05],[2.84,18.93]],"id":57451148},{"atb":[[1.64,54.44],[1.74,31.39]],"id":61631980},{"atl":[[6.8,0.08]],"id":61631980},{"atb":[[1.55,63.35],[1.65,35.73]],"id":61631978},{"atl":[[6.2,0.09]],"id":61631978}],"con":true,"img":false}]}
{"op":"mcm","clk":"11449528856","pt":1717310431735,"mc":[{"id":"1.229554906","rc":[{"atb":[[7.4,0],[9.4,0]],"id":42269942},{"atb":[[3.1,0],[2.84,0]],"id":57451148},{"atb":[[1.01,0]],"id":60780007},{"atl":[[2.3,0]],"id":60780007},{"spn":495.51,"spf":"NaN","id":60780007},{"atb":[[1.64,0],[1.74,0]],"id":61631980},{"atl":[[6.8,0]],"id":61631980},{"atb":[[1.55,0],[1.65,0]],"id":61631978},{"atl":[[6.2,0]],"id":61631978}],"con":true,"img":false}]}
{"op":"mcm","clk":"11449530484","pt":1717310457770,"mc":[{"id":"1.229554906","rc":[{"atb":[[9.8,2.64],[7.8,5.12]],"id":42269942},{"atb":[[3.2,10.55],[2.88,18.53]],"id":57451148},{"atb":[[1.01,5807.26]],"id":60780007},{"atl":[[2.28,0.4]],"id":60780007},{"atb":[[1.73,31.81],[1.63,55.3]],"id":61631980},{"atl":[[6.8,0.08]],"id":61631980},{"atb":[[1.64,36.29],[1.54,64.52]],"id":61631978},{"atl":[[6,0.1]],"id":61631978}],"con":true,"img":false}]}
{"op":"mcm","clk":"11449586670","pt":1717311442594,"mc":[{"id":"1.229554906","rc":[{"atl":[[990,0.17]],"id":42269942},{"spn":499.9,"spf":"NaN","id":42269942},{"atl":[[990,0.17]],"id":57451148},{"spn":496.6,"spf":"NaN","id":57451148},{"atl":[[990,0.17]],"id":60780007},{"spn":1.65,"spf":"NaN","id":60780007},{"atl":[[990,0.17]],"id":61631980},{"spn":4.26,"spf":"NaN","id":61631980},{"atl":[[990,0.17]],"id":61631978},{"spn":3.82,"spf":"NaN","id":61631978}],"con":true,"img":false}]}
{"op":"mcm","clk":"11449589743","pt":1717311498410,"mc":[{"id":"1.229554906","rc":[{"atb":[[9.8,0],[7.8,0]],"id":42269942},{"atb":[[3.2,0],[2.88,0]],"id":57451148},{"atb":[[1.01,0]],"id":60780007},{"atl":[[2.28,0]],"id":60780007},{"atb":[[1.73,0],[1.63,0]],"id":61631980},{"atl":[[6.8,0]],"id":61631980},{"atb":[[1.64,0],[1.54,0]],"id":61631978},{"atl":[[6,0]],"id":61631978}],"con":true,"img":false}]}
{"op":"mcm","clk":"11449590376","pt":1717311508785,"mc":[{"id":"1.229554906","rc":[{"atb":[[7.4,5.44],[9.4,2.76]],"id":42269942},{"spn":499.7,"spf":"NaN","id":42269942},{"atb":[[3.2,10.55],[2.88,18.53]],"id":57451148},{"atb":[[1.01,5807.26]],"id":60780007},{"atl":[[2.28,0.4]],"id":60780007},{"atb":[[1.73,31.81],[1.63,55.3]],"id":61631980},{"atl":[[6.8,0.08]],"id":61631980},{"atb":[[1.64,36.29],[1.54,64.52]],"id":61631978},{"atl":[[6,0.1]],"id":61631978}],"con":true,"img":false}]}
{"op":"mcm","clk":"11449640544","pt":1717312587377,"mc":[{"id":"1.229554906","rc":[{"atb":[[7.4,0],[9.4,0]],"id":42269942},{"spn":495.51,"spf":"NaN","id":42269942},{"atb":[[3.2,0],[2.88,0]],"id":57451148},{"spn":495.51,"spf":"NaN","id":57451148},{"atb":[[1.01,0]],"id":60780007},{"atl":[[2.28,0]],"id":60780007},{"spn":495.51,"spf":"NaN","id":60780007},{"atb":[[1.73,0],[1.63,0]],"id":61631980},{"atl":[[6.8,0]],"id":61631980},{"spn":495.5,"spf":"NaN","id":61631980},{"atb":[[1.64,0],[1.54,0]],"id":61631978},{"atl":[[6,0]],"id":61631978},{"spn":495.5,"spf":"NaN","id":61631978}],"con":true,"img":false}]}
{"op":"mcm","clk":"11449640837","pt":1717312594357,"mc":[{"id":"1.229554906","rc":[{"atb":[[7.4,5.44],[9.4,2.76]],"id":42269942},{"atb":[[2.86,18.73],[3.15,10.8]],"id":57451148},{"atb":[[1.01,5807.26]],"id":60780007},{"atl":[[2.28,0.4]],"id":60780007},{"atb":[[1.71,32.71],[1.61,57.12]],"id":61631980},{"atl":[[6.6,0.09]],"id":61631980},{"atb":[[1.56,62.22],[1.66,35.19]],"id":61631978},{"atl":[[6.2,0.09]],"id":61631978}],"con":true,"img":false}]}
{"op":"mcm","clk":"11449680075","pt":1717313441072,"mc":[{"id":"1.229554906","rc":[{"atb":[[7.4,0],[9.4,0]],"id":42269942},{"atb":[[2.86,0],[3.15,0]],"id":57451148},{"atb":[[1.01,0]],"id":60780007},{"atl":[[2.28,0]],"id":60780007},{"atb":[[1.71,0],[1.61,0]],"id":61631980},{"atl":[[6.6,0]],"id":61631980},{"atb":[[1.56,0],[1.66,0]],"id":61631978},{"atl":[[6.2,0]],"id":61631978}],"con":true,"img":false}]}
{"op":"mcm","clk":"11449680658","pt":1717313449128,"mc":[{"id":"1.229554906","rc":[{"atb":[[10.5,2.44],[8.2,4.83]],"id":42269942},{"atb":[[3.2,10.55],[2.88,18.53]],"id":57451148},{"atb":[[1.01,5807.26]],"id":60780007},{"atl":[[2.28,0.4]],"id":60780007},{"atb":[[1.73,31.81],[1.63,55.3]],"id":61631980},{"atl":[[6.8,0.08]],"id":61631980},{"atb":[[1.64,36.29],[1.54,64.52]],"id":61631978},{"atl":[[6,0.1]],"id":61631978}],"con":true,"img":false}]}
{"op":"mcm","clk":"11449753578","pt":1717314283242,"mc":[{"id":"1.229554906","rc":[{"atb":[[10.5,0],[8.2,0]],"id":42269942},{"atb":[[3.2,0],[2.88,0]],"id":57451148},{"atb":[[1.01,0]],"id":60780007},{"atl":[[2.28,0]],"id":60780007},{"atb":[[1.73,0],[1.63,0]],"id":61631980},{"atl":[[6.8,0]],"id":61631980},{"atb":[[1.64,0],[1.54,0]],"id":61631978},{"atl":[[6,0]],"id":61631978}],"con":true,"img":false}]}
{"op":"mcm","clk":"11449754572","pt":1717314295496,"mc":[{"id":"1.229554906","rc":[{"atb":[[10.5,2.44],[8.2,4.83]],"id":42269942},{"atb":[[2.86,18.73],[3.15,10.8]],"id":57451148},{"atb":[[1.01,5807.26]],"id":60780007},{"atl":[[2.28,0.4]],"id":60780007},{"atb":[[1.73,31.81],[1.63,55.3]],"id":61631980},{"atl":[[6.8,0.08]],"id":61631980},{"atb":[[1.64,36.29],[1.54,64.52]],"id":61631978},{"atl":[[6,0.1]],"id":61631978}],"con":true,"img":false}]}
{"op":"mcm","clk":"11449807422","pt":1717314903056,"mc":[{"id":"1.229554906","rc":[{"atb":[[10.5,8.72],[12.5,3.64]],"id":42269942},{"atl":[[270,0.15],[290,2.61]],"id":42269942},{"spn":141.25,"spf":"NaN","id":42269942},{"atb":[[2.88,22.26],[2.42,44.99]],"id":57451148},{"atl":[[28,2.61],[30,2.61]],"id":57451148},{"spn":15.57,"spf":"NaN","id":57451148},{"atb":[[1.07,101.16],[1.05,1187.61]],"id":60780007},{"atl":[[2.64,25.52],[2.94,30.61]],"id":60780007},{"spn":1.67,"spf":"NaN","id":60780007},{"atb":[[1.64,45.77],[1.38,142.15]],"id":61631980},{"atl":[[9.6,6.28],[8.6,5.5]],"id":61631980},{"spn":4.26,"spf":"NaN","id":61631980},{"atb":[[1.28,213.97],[1.37,45.24]],"id":61631978},{"atl":[[7.2,9.41],[6.6,7.47]],"id":61631978},{"spn":3.82,"spf":"NaN","id":61631978}],"con":true,"img":false}]}
{"op":"mcm","clk":"11449837907","pt":1717315160824,"mc":[{"id":"1.229554906","rc":[{"atb":[[10.5,6.27],[8.2,0]],"id":42269942},{"atb":[[2.86,0],[3.15,0]],"id":57451148},{"atb":[[1.01,0]],"id":60780007},{"atl":[[2.28,0]],"id":60780007},{"atb":[[1.73,0],[1.63,0]],"id":61631980},{"atl":[[6.8,0]],"id":61631980},{"atb":[[1.64,0],[1.54,0]],"id":61631978},{"atl":[[6,0]],"id":61631978}],"con":true,"img":false}]}
{"op":"mcm","clk":"11449840127","pt":1717315183553,"mc":[{"id":"1.229554906","rc":[{"atb":[[2.88,0]],"id":57451148},{"atb":[[1.64,0]],"id":61631980}],"con":true,"img":false}]}
{"op":"mcm","clk":"11449840137","pt":1717315183660,"mc":[{"id":"1.229554906","rc":[{"atb":[[2.72,22.26]],"id":57451148},{"atb":[[1.47,45.77]],"id":61631980}],"con":true,"img":false}]}
{"op":"mcm","clk":"11449841686","pt":1717315199991,"mc":[{"id":"1.229554906","rc":[{"atb":[[10.5,8.72],[8.2,4.83]],"id":42269942},{"atb":[[2.82,19.14],[3.05,11.33]],"id":57451148},{"spn":15.52,"spf":"NaN","id":57451148},{"atb":[[1.01,5807.26]],"id":60780007},{"atl":[[2.28,0.4]],"id":60780007},{"atb":[[1.64,54.44],[1.74,31.39]],"id":61631980},{"atl":[[6.8,0.08]],"id":61631980},{"spn":4.27,"spf":"NaN","id":61631980},{"atb":[[1.55,63.35],[1.65,35.73]],"id":61631978},{"atl":[[6.2,0.09]],"id":61631978},{"spn":3.92,"spf":"NaN","id":61631978}],"con":true,"img":false}]}
{"op":"mcm","clk":"11449848101","pt":1717315263651,"mc":[{"id":"1.229554906","rc":[{"atb":[[2.72,0]],"id":57451148},{"atb":[[1.47,0]],"id":61631980}],"con":true,"img":false}]}
{"op":"mcm","clk":"11449848116","pt":1717315263762,"mc":[{"id":"1.229554906","rc":[{"atb":[[2.84,22.26]],"id":57451148},{"atb":[[1.65,45.77]],"id":61631980}],"con":true,"img":false}]}
{"op":"mcm","clk":"11449888277","pt":1717315659736,"mc":[{"id":"1.229554906","rc":[{"atb":[[12.5,0]],"id":42269942},{"spn":140.25,"spf":"NaN","id":42269942}],"con":true,"img":false}]}
{"op":"mcm","clk":"11449888290","pt":1717315659790,"mc":[{"id":"1.229554906","rc":[{"atb":[[12,3.64]],"id":42269942}],"con":true,"img":false}]}
{"op":"mcm","clk":"11449891326","pt":1717315690143,"mc":[{"id":"1.229554906","rc":[{"atb":[[10.5,2.44],[12,0],[8.4,8.37]],"id":42269942}],"con":true,"img":false}]}
{"op":"mcm","clk":"11449891334","pt":1717315690247,"mc":[{"id":"1.229554906","rc":[{"atb":[[10,3.64]],"id":42269942}],"con":true,"img":false}]}
{"op":"mcm","clk":"11449893625","pt":1717315712406,"mc":[{"id":"1.229554906","rc":[{"atb":[[10.5,0],[8.2,0]],"id":42269942},{"atb":[[2.82,0],[3.05,0]],"id":57451148},{"atb":[[1.01,0]],"id":60780007},{"atl":[[2.28,0]],"id":60780007},{"atb":[[1.64,0],[1.74,0]],"id":61631980},{"atl":[[6.8,0]],"id":61631980},{"atb":[[1.55,0],[1.65,0]],"id":61631978},{"atl":[[6.2,0]],"id":61631978}],"con":true,"img":false}]}
{"op":"mcm","clk":"11449893849","pt":1717315714597,"mc":[{"id":"1.229554906","rc":[{"atl":[[270,0]],"id":42269942},{"atb":[[2.84,0]],"id":57451148},{"atb":[[1.65,0]],"id":61631980}],"con":true,"img":false}]}
{"op":"mcm","clk":"11449893863","pt":1717315714700,"mc":[{"id":"1.229554906","rc":[{"atl":[[240,0.15]],"id":42269942},{"atb":[[2.72,22.26]],"id":57451148},{"atb":[[1.47,45.77]],"id":61631980}],"con":true,"img":false}]}
{"op":"mcm","clk":"11449896887","pt":1717315742884,"mc":[{"id":"1.229554906","rc":[{"atb":[[6.4,6.45],[8.4,11.5]],"id":42269942},{"spn":125.0,"spf":"NaN","id":42269942},{"atb":[[3.2,10.55],[2.88,18.53]],"id":57451148},{"spn":15.6,"spf":"NaN","id":57451148},{"atb":[[1.01,5807.26]],"id":60780007},{"atl":[[2.32,0.39]],"id":60780007},{"spn":1.69,"spf":"NaN","id":60780007},{"atb":[[1.75,30.97],[1.65,53.6]],"id":61631980},{"atl":[[7,0.08]],"id":61631980},{"spn":4.37,"spf":"NaN","id":61631980},{"atb":[[1.51,68.32],[1.61,38.08]],"id":61631978},{"atl":[[5.7,0.1]],"id":61631978},{"spn":3.65,"spf":"NaN","id":61631978}],"con":true,"img":false}]}
{"op":"mcm","clk":"11449903465","pt":1717315805749,"mc":[{"id":"1.229554906","rc":[{"atb":[[2.72,0]],"id":57451148},{"atb":[[1.47,0]],"id":61631980},{"atb":[[1.37,0]],"id":61631978}],"con":true,"img":false}]}
{"op":"mcm","clk":"11449903475","pt":1717315805855,"mc":[{"id":"1.229554906","rc":[{"atb":[[2.9,22.26]],"id":57451148},{"atb":[[1.66,45.77]],"id":61631980},{"atb":[[1.52,45.24]],"id":61631978}],"con":true,"img":false}]}
{"op":"mcm","clk":"11449924783","pt":1717316009514,"mc":[{"id":"1.229554906","rc":[{"atb":[[6.4,0],[8.4,8.37]],"id":42269942},{"atb":[[3.2,0],[2.88,0]],"id":57451148},{"spn":15.45,"spf":"NaN","id":57451148},{"atb":[[1.01,0]],"id":60780007},{"atl":[[2.32,0]],"id":60780007},{"spn":1.85,"spf":"NaN","id":60780007},{"atb":[[1.75,0],[1.65,0]],"id":61631980},{"atl":[[7,0]],"id":61631980},{"spn":5.13,"spf":"NaN","id":61631980},{"atb":[[1.51,0],[1.61,0]],"id":61631978},{"atl":[[5.7,0]],"id":61631978},{"spn":4.06,"spf":"NaN","id":61631978}],"con":true,"img":false}]}
{"op":"mcm","clk":"11449926397","pt":1717316026638,"mc":[{"id":"1.229554906","rc":[{"atb":[[2.9,0]],"id":57451148},{"atb":[[1.66,0]],"id":61631980},{"atb":[[1.52,0]],"id":61631978}],"con":true,"img":false}]}
{"op":"mcm","clk":"11449926407","pt":1717316026743,"mc":[{"id":"1.229554906","rc":[{"atb":[[2.7,22.26]],"id":57451148},{"atb":[[1.47,45.77]],"id":61631980},{"atb":[[1.34,45.24]],"id":61631978}],"con":true,"img":false}]}
{"op":"mcm","clk":"11449926999","pt":1717316032550,"mc":[{"id":"1.229554906","rc":[{"atb":[[6.8,6],[8.8,2.97]],"id":42269942},{"atb":[[2.82,19.14],[3.05,11.33]],"id":57451148},{"atb":[[1.01,5807.26]],"id":60780007},{"atl":[[2.3,0.4]],"id":60780007},{"atb":[[1.75,30.97],[1.65,53.6]],"id":61631980},{"atl":[[7,0.08]],"id":61631980},{"atb":[[1.63,36.87],[1.53,65.74]],"id":61631978},{"atl":[[5.9,0.1]],"id":61631978}],"con":true,"img":false}]}
{"op":"mcm","clk":"11449930461","pt":1717316068300,"mc":[{"id":"1.229554906","rc":[{"atb":[[2.7,0]],"id":57451148},{"atb":[[1.47,0]],"id":61631980},{"atb":[[1.34,0]],"id":61631978}],"con":true,"img":false}]}
{"op":"mcm","clk":"11449930466","pt":1717316068403,"mc":[{"id":"1.229554906","rc":[{"atb":[[2.84,22.26]],"id":57451148},{"atb":[[1.66,45.77]],"id":61631980},{"atb":[[1.38,45.24]],"id":61631978}],"con":true,"img":false}]}
{"op":"mcm","clk":"11449959396","pt":1717316400521,"mc":[{"id":"1.229554906","rc":[{"atb":[[5.5,9.65]],"id":42269942},{"atb":[[1.55,41.4]],"id":57451148},{"atl":[[28,5.23]],"id":57451148},{"spn":15.52,"spf":"NaN","id":57451148},{"atl":[[3.7,37.04]],"id":60780007},{"spn":1.68,"spf":"NaN","id":60780007},{"atl":[[8.4,5.51]],"id":61631980},{"spn":4.37,"spf":"NaN","id":61631980},{"atl":[[6.4,7.48]],"id":61631978},{"spn":3.76,"spf":"NaN","id":61631978}],"con":true,"img":false}]}
{"op":"mcm","clk":"11449959966","pt":1717316407417,"mc":[{"id":"1.229554906","rc":[{"atb":[[9,7.28],[5.5,0]],"id":42269942}],"con":true,"img":false}]}
{"op":"mcm","clk":"11449960320","pt":1717316411633,"mc":[{"id":"1.229554906","rc":[{"atb":[[9,0]],"id":42269942}],"con":true,"img":false}]}
{"op":"mcm","clk":"11449960326","pt":1717316411733,"mc":[{"id":"1.229554906","rc":[{"atb":[[5.5,12.02]],"id":42269942}],"con":true,"img":false}]}
{"op":"mcm","clk":"11449962624","pt":1717316439552,"mc":[{"id":"1.229554906","rc":[{"atb":[[10,0]],"id":42269942}],"con":true,"img":false}]}
{"op":"mcm","clk":"11449963034","pt":1717316444457,"mc":[{"id":"1.229554906","rc":[{"atb":[[5.5,0],[8.8,8.98]],"id":42269942}],"con":true,"img":false}]}
{"op":"mcm","clk":"11449964030","pt":1717316458766,"mc":[{"id":"1.229554906","rc":[{"atb":[[5.5,16.74],[8.8,2.97]],"id":42269942}],"con":true,"img":false}]}
{"op":"mcm","clk":"11449964533","pt":1717316465593,"mc":[{"id":"1.229554906","rc":[{"atb":[[9.2,5.1]],"id":42269942},{"spn":124.6,"spf":"NaN","id":42269942},{"atl":[[30,0]],"id":57451148}],"con":true,"img":false}]}
{"op":"mcm","clk":"11449964539","pt":1717316465702,"mc":[{"id":"1.229554906","rc":[{"atl":[[27,2.61]],"id":57451148}],"con":true,"img":false}]}
{"op":"mcm","clk":"11449965697","pt":1717316481143,"mc":[{"id":"1.229554906","rc":[{"atb":[[9,10.22]],"id":42269942}],"con":true,"img":false}]}
{"op":"mcm","clk":"11449965704","pt":1717316481224,"mc":[{"id":"1.229554906","rc":[{"atb":[[5.5,0]],"id":42269942}],"con":true,"img":false}]}
{"op":"mcm","clk":"11449965993","pt":1717316485213,"mc":[{"id":"1.229554906","rc":[{"atb":[[9,0]],"id":42269942}],"con":true,"img":false}]}
{"op":"mcm","clk":"11449966000","pt":1717316485316,"mc":[{"id":"1.229554906","rc":[{"atb":[[6,12.02]],"id":42269942}],"con":true,"img":false}]}
{"op":"mcm","clk":"11449968111","pt":1717316516349,"mc":[{"id":"1.229554906","rc":[{"atb":[[1.01,2.35]],"id":57451148},{"atb":[[1.69,5.69]],"id":61631980}],"con":true,"img":false}]}
{"op":"mcm","clk":"11449968142","pt":1717316516716,"mc":[{"id":"1.229554906","rc":[{"atb":[[1.01,2.04]],"id":57451148}],"con":true,"img":false}]}
{"op":"mcm","clk":"11449968156","pt":1717316517015,"mc":[{"id":"1.229554906","rc":[{"atb":[[1.01,0]],"id":57451148}],"con":true,"img":false}]}
{"op":"mcm","clk":"11449968161","pt":1717316517117,"mc":[{"id":"1.229554906","rc":[{"atb":[[2.92,2.04]],"id":57451148}],"con":true,"img":false}]}
{"op":"mcm","clk":"11449970478","pt":1717316552402,"mc":[{"id":"1.229554906","rc":[{"atb":[[6.8,0],[8.8,0]],"id":42269942},{"atb":[[2.82,0],[3.05,0]],"id":57451148},{"spn":14.96,"spf":"NaN","id":57451148},{"atb":[[1.01,0]],"id":60780007},{"atl":[[2.3,0]],"id":60780007},{"spn":1.85,"spf":"NaN","id":60780007},{"atb":[[1.75,0],[1.65,0]],"id":61631980},{"atl":[[7,0]],"id":61631980},{"spn":5.04,"spf":"NaN","id":61631980},{"atb":[[1.63,0],[1.53,0]],"id":61631978},{"atl":[[5.9,0]],"id":61631978},{"spn":3.89,"spf":"NaN","id":61631978}],"con":true,"img":false}]}
{"op":"mcm","clk":"11449971044","pt":1717316561292,"mc":[{"id":"1.229554906","rc":[{"atb":[[1.4,9.81]],"id":61631978}],"con":true,"img":false}]}
{"op":"mcm","clk":"11449971357","pt":1717316566159,"mc":[{"id":"1.229554906","rc":[{"atb":[[2.84,0]],"id":57451148},{"atb":[[1.66,0]],"id":61631980}],"con":true,"img":false}]}
{"op":"mcm","clk":"11449971362","pt":1717316566264,"mc":[{"id":"1.229554906","rc":[{"atb":[[2.7,22.26]],"id":57451148},{"atb":[[1.47,45.77]],"id":61631980}],"con":true,"img":false}]}
{"op":"mcm","clk":"11449971651","pt":1717316571019,"mc":[{"id":"1.229554906","rc":[{"atb":[[6.8,6],[8.8,2.97]],"id":42269942},{"atb":[[3.2,10.55],[2.88,18.53]],"id":57451148},{"atb":[[1.01,5807.26]],"id":60780007},{"atl":[[2.32,0.39]],"id":60780007},{"atb":[[1.73,31.81],[1.63,55.3]],"id":61631980},{"atl":[[6.8,0.08]],"id":61631980},{"atb":[[1.51,68.32],[1.61,38.08]],"id":61631978},{"atl":[[5.7,0.1]],"id":61631978}],"con":true,"img":false}]}
{"op":"mcm","clk":"11449975092","pt":1717316619941,"mc":[{"id":"1.229554906","rc":[{"spn":15.1,"spf":"NaN","id":57451148},{"spn":1.69,"spf":"NaN","id":60780007},{"spn":4.26,"spf":"NaN","id":61631980},{"atb":[[1.53,8.03]],"id":61631978},{"spn":3.65,"spf":"NaN","id":61631978}],"con":true,"img":false}]}
{"op":"mcm","clk":"11449975126","pt":1717316620364,"mc":[{"id":"1.229554906","rc":[{"atb":[[2.48,2.88]],"id":57451148},{"atb":[[1.66,6.45]],"id":61631980}],"con":true,"img":false}]}
{"op":"mcm","clk":"11449975721","pt":1717316627959,"mc":[{"id":"1.229554906","rc":[{"atb":[[2.7,0]],"id":57451148},{"atb":[[1.47,0]],"id":61631980},{"atb":[[1.38,0]],"id":61631978}],"con":true,"img":false}]}
{"op":"mcm","clk":"11449975732","pt":1717316628064,"mc":[{"id":"1.229554906","rc":[{"atb":[[2.9,22.26]],"id":57451148},{"atb":[[1.64,45.77]],"id":61631980},{"atb":[[1.52,45.24]],"id":61631978}],"con":true,"img":false}]}
{"op":"mcm","clk":"11449976364","pt":1717316637184,"mc":[{"id":"1.229554906","rc":[{"atb":[[2.92,0]],"id":57451148}],"con":true,"img":false}]}
{"op":"mcm","clk":"11449977514","pt":1717316652226,"mc":[{"id":"1.229554906","rc":[{"atb":[[1.01,2.35]],"id":57451148}],"con":true,"img":false}]}
{"op":"mcm","clk":"11449977529","pt":1717316652384,"mc":[{"id":"1.229554906","rc":[{"atb":[[1.01,1.98]],"id":57451148}],"con":true,"img":false}]}
{"op":"mcm","clk":"11449977555","pt":1717316652695,"mc":[{"id":"1.229554906","rc":[{"atb":[[1.01,0]],"id":57451148}],"con":true,"img":false}]}
{"op":"mcm","clk":"11449977564","pt":1717316652797,"mc":[{"id":"1.229554906","rc":[{"atb":[[2.98,1.98]],"id":57451148}],"con":true,"img":false}]}
{"op":"mcm","clk":"11449982323","pt":1717316718785,"mc":[{"id":"1.229554906","rc":[{"atb":[[9,10.22],[6,0]],"id":42269942}],"con":true,"img":false}]}
{"op":"mcm","clk":"11449985858","pt":1717316768662,"mc":[{"id":"1.229554906","rc":[{"atb":[[8.4,0]],"id":42269942}],"con":true,"img":false}]}
{"op":"mcm","clk":"11449985865","pt":1717316768748,"mc":[{"id":"1.229554906","rc":[{"atb":[[9.2,13.47]],"id":42269942}],"con":true,"img":false}]}
{"op":"mcm","clk":"11449987398","pt":1717316788850,"mc":[{"id":"1.229554906","rc":[{"atb":[[9,0],[6,16.23]],"id":42269942}],"con":true,"img":false}]}
{"op":"mcm","clk":"11449987553","pt":1717316790955,"mc":[{"id":"1.229554906","rc":[{"atb":[[9.2,5.1]],"id":42269942}],"con":true,"img":false}]}
{"op":"mcm","clk":"11449987559","pt":1717316791057,"mc":[{"id":"1.229554906","rc":[{"atb":[[7.8,8.37]],"id":42269942}],"con":true,"img":false}]}
{"op":"mcm","clk":"11449999397","pt":1717316938878,"mc":[{"id":"1.229554906","rc":[{"atb":[[6.8,0],[8.8,0]],"id":42269942},{"atb":[[3.2,0],[2.88,0]],"id":57451148},{"spn":14.99,"spf":"NaN","id":57451148},{"atb":[[1.01,0]],"id":60780007},{"atl":[[2.32,0]],"id":60780007},{"spn":1.85,"spf":"NaN","id":60780007},{"atb":[[1.73,0],[1.63,0]],"id":61631980},{"atl":[[6.8,0]],"id":61631980},{"spn":5.04,"spf":"NaN","id":61631980},{"atb":[[1.51,0],[1.61,0]],"id":61631978},{"atl":[[5.7,0]],"id":61631978},{"spn":3.96,"spf":"NaN","id":61631978}],"con":true,"img":false}]}
{"op":"mcm","clk":"11449999832","pt":1717316944046,"mc":[{"id":"1.229554906","rc":[{"atb":[[2.9,0]],"id":57451148},{"atb":[[1.64,0]],"id":61631980},{"atb":[[1.52,0]],"id":61631978}],"con":true,"img":false}]}
{"op":"mcm","clk":"11449999849","pt":1717316944155,"mc":[{"id":"1.229554906","rc":[{"atb":[[2.7,22.26]],"id":57451148},{"atb":[[1.46,45.77]],"id":61631980},{"atb":[[1.34,45.24]],"id":61631978}],"con":true,"img":false}]}
{"op":"mcm","clk":"11450000398","pt":1717316949889,"mc":[{"id":"1.229554906","rc":[{"atb":[[7.2,5.61],[9.2,7.93]],"id":42269942},{"atb":[[2.86,18.73],[3.15,10.8]],"id":57451148},{"atb":[[1.01,5807.26]],"id":60780007},{"atl":[[2.3,0.4]],"id":60780007},{"atb":[[1.72,32.26],[1.62,56.19]],"id":61631980},{"atl":[[6.8,0.08]],"id":61631980},{"atb":[[1.63,36.87],[1.53,73.77]],"id":61631978},{"atl":[[5.9,0.1]],"id":61631978}],"con":true,"img":false}]}
{"op":"mcm","clk":"11450001223","pt":1717316959392,"mc":[{"id":"1.229554906","rc":[{"atb":[[1.66,0]],"id":61631980},{"atb":[[1.53,65.74]],"id":61631978}],"con":true,"img":false}]}
{"op":"mcm","clk":"11450003816","pt":1717316990531,"mc":[{"id":"1.229554906","rc":[{"atb":[[1.64,6.65]],"id":61631980}],"con":true,"img":false}]}
{"op":"mcm","clk":"11450003826","pt":1717316990635,"mc":[{"id":"1.229554906","rc":[{"atb":[[1.55,7.74]],"id":61631978}],"con":true,"img":false}]}
{"op":"mcm","clk":"11450004767","pt":1717317001258,"mc":[{"id":"1.229554906","rc":[{"atb":[[2.7,0]],"id":57451148},{"spn":15.07,"spf":"NaN","id":57451148},{"spn":1.68,"spf":"NaN","id":60780007},{"atb":[[1.46,0]],"id":61631980},{"spn":4.26,"spf":"NaN","id":61631980},{"atb":[[1.34,0]],"id":61631978},{"spn":3.76,"spf":"NaN","id":61631978}],"con":true,"img":false}]}
{"op":"mcm","clk":"11450004780","pt":1717317001365,"mc":[{"id":"1.229554906","rc":[{"atb":[[2.88,22.26]],"id":57451148},{"atb":[[1.63,45.77]],"id":61631980},{"atb":[[1.37,45.24]],"id":61631978}],"con":true,"img":false}]}
{"op":"mcm","clk":"11450006239","pt":1717317016159,"mc":[{"id":"1.229554906","rc":[{"atb":[[2.98,0]],"id":57451148}],"con":true,"img":false}]}
{"op":"mcm","clk":"11450007744","pt":1717317031383,"mc":[{"id":"1.229554906","rc":[{"atb":[[1.01,2.35]],"id":57451148}],"con":true,"img":false}]}
{"op":"mcm","clk":"11450007767","pt":1717317031597,"mc":[{"id":"1.229554906","rc":[{"atb":[[1.01,2]],"id":57451148}],"con":true,"img":false}]}
{"op":"mcm","clk":"11450007787","pt":1717317031803,"mc":[{"id":"1.229554906","rc":[{"atb":[[1.01,0]],"id":57451148}],"con":true,"img":false}]}
{"op":"mcm","clk":"11450007800","pt":1717317031864,"mc":[{"id":"1.229554906","rc":[{"atb":[[2.96,2]],"id":57451148}],"con":true,"img":false}]}
{"op":"mcm","clk":"11450040232","pt":1717317351851,"mc":[{"id":"1.229554906","rc":[{"atb":[[7.2,0],[9.2,5.1]],"id":42269942},{"atb":[[2.86,0],[3.15,0]],"id":57451148},{"spn":14.98,"spf":"NaN","id":57451148},{"atb":[[1.01,0]],"id":60780007},{"atl":[[2.3,0]],"id":60780007},{"spn":1.85,"spf":"NaN","id":60780007},{"atb":[[1.72,0],[1.62,0]],"id":61631980},{"atl":[[6.8,0]],"id":61631980},{"spn":5.04,"spf":"NaN","id":61631980},{"atb":[[1.63,0],[1.53,0]],"id":61631978},{"atl":[[5.9,0]],"id":61631978},{"spn":3.97,"spf":"NaN","id":61631978}],"con":true,"img":false}]}
{"op":"mcm","clk":"11450041989","pt":1717317368353,"mc":[{"id":"1.229554906","rc":[{"atb":[[2.88,0]],"id":57451148},{"atb":[[1.63,0]],"id":61631980}],"con":true,"img":false}]}
{"op":"mcm","clk":"11450041999","pt":1717317368459,"mc":[{"id":"1.229554906","rc":[{"atb":[[2.7,22.26]],"id":57451148},{"atb":[[1.46,45.77]],"id":61631980}],"con":true,"img":false}]}
{"op":"mcm","clk":"11450042982","pt":1717317378075,"mc":[{"id":"1.229554906","rc":[{"atb":[[9,2.9],[7,5.8]],"id":42269942},{"atb":[[2.86,18.73],[3.15,10.8]],"id":57451148},{"atb":[[1.01,5807.26]],"id":60780007},{"atl":[[2.28,0.4]],"id":60780007},{"atb":[[1.73,31.81],[1.63,55.3]],"id":61631980},{"atl":[[6.8,0.08]],"id":61631980},{"atb":[[1.64,36.29],[1.54,64.52]],"id":61631978},{"atl":[[6,0.1]],"id":61631978}],"con":true,"img":false}]}
{"op":"mcm","clk":"11450043197","pt":1717317380174,"mc":[{"id":"1.229554906","rc":[{"atb":[[1.64,0]],"id":61631980},{"atb":[[1.55,0]],"id":61631978}],"con":true,"img":false}]}
{"op":"mcm","clk":"11450047193","pt":1717317418341,"mc":[{"id":"1.229554906","rc":[{"spn":15.07,"spf":"NaN","id":57451148},{"spn":1.67,"spf":"NaN","id":60780007},{"atb":[[1.66,6.45]],"id":61631980},{"spn":4.26,"spf":"NaN","id":61631980},{"spn":3.82,"spf":"NaN","id":61631978}],"con":true,"img":false}]}
{"op":"mcm","clk":"11450047263","pt":1717317418913,"mc":[{"id":"1.229554906","rc":[{"atb":[[1.56,7.6]],"id":61631978}],"con":true,"img":false}]}
{"op":"mcm","clk":"11450047554","pt":1717317421531,"mc":[{"id":"1.229554906","rc":[{"atb":[[2.7,0]],"id":57451148},{"atb":[[1.46,0]],"id":61631980}],"con":true,"img":false}]}
{"op":"mcm","clk":"11450047569","pt":1717317421629,"mc":[{"id":"1.229554906","rc":[{"atb":[[2.88,22.26]],"id":57451148},{"atb":[[1.64,45.77]],"id":61631980}],"con":true,"img":false}]}
{"op":"mcm","clk":"11450047674","pt":1717317422667,"mc":[{"id":"1.229554906","rc":[{"atb":[[1.69,0]],"id":61631980},{"atb":[[1.4,0]],"id":61631978}],"con":true,"img":false}]}
{"op":"mcm","clk":"11450049343","pt":1717317437459,"mc":[{"id":"1.229554906","rc":[{"atb":[[2.96,0]],"id":57451148}],"con":true,"img":false}]}
{"op":"mcm","clk":"11450066369","pt":1717317625022,"mc":[{"id":"1.229554906","rc":[{"atb":[[9,13.12],[6,0]],"id":42269942}],"con":true,"img":false}]}
{"op":"mcm","clk":"11450071612","pt":1717317682096,"mc":[{"id":"1.229554906","rc":[{"atb":[[7.8,0]],"id":42269942}],"con":true,"img":false}]}
{"op":"mcm","clk":"11450071621","pt":1717317682199,"mc":[{"id":"1.229554906","rc":[{"atb":[[9.2,13.47]],"id":42269942}],"con":true,"img":false}]}
{"op":"mcm","clk":"11450071966","pt":1717317685522,"mc":[{"id":"1.229554906","rc":[{"atb":[[6,20]],"id":42269942}],"con":true,"img":false}]}
{"op":"mcm","clk":"11450071974","pt":1717317685612,"mc":[{"id":"1.229554906","rc":[{"atb":[[9,2.9]],"id":42269942}],"con":true,"img":false}]}
{"op":"mcm","clk":"11450073032","pt":1717317696709,"mc":[{"id":"1.229554906","rc":[{"atb":[[9.2,5.1]],"id":42269942}],"con":true,"img":false}]}
{"op":"mcm","clk":"11450073043","pt":1717317696822,"mc":[{"id":"1.229554906","rc":[{"atb":[[7.8,8.37]],"id":42269942}],"con":true,"img":false}]}
{"op":"mcm","clk":"11450076055","pt":1717317730270,"mc":[{"id":"1.229554906","rc":[{"atb":[[9,0],[7,0]],"id":42269942},{"atb":[[2.86,0],[3.15,0]],"id":57451148},{"atb":[[1.01,0]],"id":60780007},{"atl":[[2.28,0]],"id":60780007},{"atb":[[1.73,0],[1.63,0]],"id":61631980},{"atl":[[6.8,0]],"id":61631980},{"atb":[[1.64,0],[1.54,0]],"id":61631978},{"atl":[[6,0]],"id":61631978}],"con":true,"img":false}]}
{"op":"mcm","clk":"11450078016","pt":1717317751745,"mc":[{"id":"1.229554906","rc":[{"atb":[[2.88,0]],"id":57451148},{"spn":14.74,"spf":"NaN","id":57451148},{"spn":1.85,"spf":"NaN","id":60780007},{"atb":[[1.64,0]],"id":61631980},{"spn":5.03,"spf":"NaN","id":61631980},{"spn":3.98,"spf":"NaN","id":61631978}],"con":true,"img":false}]}
{"op":"mcm","clk":"11450078025","pt":1717317751844,"mc":[{"id":"1.229554906","rc":[{"atb":[[2.7,22.26]],"id":57451148},{"atb":[[1.46,45.77]],"id":61631980}],"con":true,"img":false}]}
{"op":"mcm","clk":"11450078216","pt":1717317753972,"mc":[{"id":"1.229554906","rc":[{"atb":[[9,2.9],[7,5.8]],"id":42269942},{"atb":[[3.1,11.05],[2.84,18.93]],"id":57451148},{"atb":[[1.01,5807.26]],"id":60780007},{"atl":[[2.32,0.39]],"id":60780007},{"atb":[[1.72,32.26],[1.62,56.19]],"id":61631980},{"atl":[[6.8,0.08]],"id":61631980},{"atb":[[1.64,36.29],[1.54,64.52]],"id":61631978},{"atl":[[6,0.1]],"id":61631978}],"con":true,"img":false}]}
{"op":"mcm","clk":"11450079783","pt":1717317770856,"mc":[{"id":"1.229554906","rc":[{"atb":[[1.66,0]],"id":61631980}],"con":true,"img":false}]}
{"op":"mcm","clk":"11450082713","pt":1717317805336,"mc":[{"id":"1.229554906","rc":[{"atb":[[2.7,0]],"id":57451148},{"atb":[[1.46,0]],"id":61631980}],"con":true,"img":false}]}
{"op":"mcm","clk":"11450082723","pt":1717317805395,"mc":[{"id":"1.229554906","rc":[{"atb":[[2.86,22.26]],"id":57451148},{"atb":[[1.63,45.77]],"id":61631980}],"con":true,"img":false}]}
{"op":"mcm","clk":"11450083223","pt":1717317811241,"mc":[{"id":"1.229554906","rc":[{"atb":[[1.64,6.65]],"id":61631980}],"con":true,"img":false}]}
{"op":"mcm","clk":"11450091238","pt":1717317904420,"mc":[{"id":"1.229554906","rc":[{"atb":[[1.01,2.35]],"id":57451148},{"spn":15.05,"spf":"NaN","id":57451148},{"spn":1.69,"spf":"NaN","id":60780007},{"spn":4.26,"spf":"NaN","id":61631980},{"spn":3.82,"spf":"NaN","id":61631978}],"con":true,"img":false}]}
{"op":"mcm","clk":"11450091544","pt":1717317907622,"mc":[{"id":"1.229554906","rc":[{"atb":[[1.01,2.02]],"id":57451148}],"con":true,"img":false}]}
{"op":"mcm","clk":"11450091652","pt":1717317909022,"mc":[{"id":"1.229554906","rc":[{"atb":[[1.01,0]],"id":57451148}],"con":true,"img":false}]}
{"op":"mcm","clk":"11450091662","pt":1717317909122,"mc":[{"id":"1.229554906","rc":[{"atb":[[2.94,2.02]],"id":57451148}],"con":true,"img":false}]}
{"op":"mcm","clk":"11450092578","pt":1717317919110,"mc":[{"id":"1.229554906","rc":[{"atb":[[9.2,0],[7.8,0]],"id":42269942},{"atl":[[290,0],[240,0]],"id":42269942},{"atb":[[2.86,0],[2.42,0]],"id":57451148},{"atl":[[27,0],[28,2.62]],"id":57451148},{"atb":[[1.07,0],[1.05,0]],"id":60780007},{"atl":[[2.64,0],[2.94,0]],"id":60780007},{"atb":[[1.63,0],[1.38,0]],"id":61631980},{"atl":[[9.6,0],[8.6,0]],"id":61631980},{"atb":[[1.28,0],[1.37,0]],"id":61631978},{"atl":[[7.2,0],[6.6,0]],"id":61631978}],"con":true,"img":false}]}
{"op":"mcm","clk":"11450092587","pt":1717317919215,"mc":[{"id":"1.229554906","rc":[{"atl":[[100,2],[28,0]],"id":57451148},{"atl":[[3.7,0],[8.8,12.82]],"id":60780007},{"atl":[[24,4.35]],"id":61631980},{"atl":[[6.4,0],[19.5,5.41]],"id":61631978}],"con":true,"img":false}]}
{"op":"mcm","clk":"11450092597","pt":1717317919317,"mc":[{"id":"1.229554906","rc":[{"atl":[[8.4,0]],"id":61631980}],"con":true,"img":false}]}
{"op":"mcm","clk":"11450093481","pt":1717317929331,"mc":[{"id":"1.229554906","rc":[{"atb":[[2.48,0]],"id":57451148}],"con":true,"img":false}]}
{"op":"mcm","clk":"11450093948","pt":1717317934129,"mc":[{"id":"1.229554906","rc":[{"atb":[[1.75,5.23]],"id":61631980},{"atb":[[1.67,5.85]],"id":61631978}],"con":true,"img":false}]}
{"op":"mcm","clk":"11450097925","pt":1717317981480,"mc":[{"id":"1.229554906","rc":[{"atb":[[9.2,5.1],[7.8,9.94]],"id":42269942},{"atl":[[230,0.18],[250,2.61]],"id":42269942},{"spn":119.6,"spf":"NaN","id":42269942},{"atb":[[2.4,45.51],[2.86,22.5]],"id":57451148},{"atl":[[28,2.61],[30,2.61]],"id":57451148},{"spn":15.55,"spf":"NaN","id":57451148},{"atb":[[1.07,101.16],[1.05,1187.61]],"id":60780007},{"atl":[[2.66,25.21],[2.94,30.61]],"id":60780007},{"atb":[[1.63,46.5],[1.38,142.15]],"id":61631980},{"atl":[[9.8,6.13],[8.8,5.36]],"id":61631980},{"spn":4.27,"spf":"NaN","id":61631980},{"atb":[[1.28,213.97],[1.37,45.24]],"id":61631978},{"atl":[[7.4,9.41],[6.8,7.21]],"id":61631978},{"spn":3.83,"spf":"NaN","id":61631978}],"con":true,"img":false}]}
{"op":"mcm","clk":"11450097933","pt":1717317981582,"mc":[{"id":"1.229554906","rc":[{"atl":[[100,0],[28,5.23]],"id":57451148},{"atl":[[3.7,37.04],[8.8,0]],"id":60780007},{"atl":[[8.6,5.37],[24,0]],"id":61631980},{"atl":[[19.5,0],[6.6,7.21]],"id":61631978}],"con":true,"img":false}]}
{"op":"mcm","clk":"11450097946","pt":1717317981685,"mc":[{"id":"1.229554906","rc":[{"atl":[[28,2.61],[30,6.06]],"id":57451148}],"con":true,"img":false}]}
{"op":"mcm","clk":"11450097953","pt":1717317981790,"mc":[{"id":"1.229554906","rc":[{"atl":[[28,5.23]],"id":57451148}],"con":true,"img":false}]}
{"op":"mcm","clk":"11450097960","pt":1717317981901,"mc":[{"id":"1.229554906","rc":[{"atl":[[30,2.61]],"id":57451148}],"con":true,"img":false}]}
{"op":"mcm","clk":"11450098986","pt":1717317994733,"mc":[{"id":"1.229554906","rc":[{"atb":[[2.94,0]],"id":57451148}],"con":true,"img":false}]}
{"op":"mcm","clk":"11450099201","pt":1717317997315,"mc":[{"id":"1.229554906","rc":[{"atb":[[1.01,2.35]],"id":57451148},{"atb":[[1.75,0]],"id":61631980},{"atb":[[1.67,0]],"id":61631978}],"con":true,"img":false}]}
{"op":"mcm","clk":"11450099222","pt":1717317997522,"mc":[{"id":"1.229554906","rc":[{"atb":[[1.01,2.02]],"id":57451148}],"con":true,"img":false}]}
{"op":"mcm","clk":"11450099243","pt":1717317997730,"mc":[{"id":"1.229554906","rc":[{"atb":[[1.01,0]],"id":57451148}],"con":true,"img":false}]}
{"op":"mcm","clk":"11450099249","pt":1717317997828,"mc":[{"id":"1.229554906","rc":[{"atb":[[2.94,2.02]],"id":57451148}],"con":true,"img":false}]}
{"op":"mcm","clk":"11450099737","pt":1717318003319,"mc":[{"id":"1.229554906","rc":[{"atb":[[2.46,2.91]],"id":57451148}],"con":true,"img":false}]}
{"op":"mcm","clk":"11450102076","pt":1717318030450,"mc":[{"id":"1.229554906","rc":[{"atl":[[28,2.62]],"id":57451148}],"con":true,"img":false}]}
{"op":"mcm","clk":"11450102085","pt":1717318030553,"mc":[{"id":"1.229554906","rc":[{"atl":[[27,2.61],[28,0],[30,6.06]],"id":57451148}],"con":true,"img":false}]}
{"op":"mcm","clk":"11450102104","pt":1717318030760,"mc":[{"id":"1.229554906","rc":[{"atl":[[27,5.23],[30,2.61]],"id":57451148}],"con":true,"img":false}]}
{"op":"mcm","clk":"11450102113","pt":1717318030865,"mc":[{"id":"1.229554906","rc":[{"atl":[[27,2.61],[29,3.57]],"id":57451148}],"con":true,"img":false}]}
{"op":"mcm","clk":"11450103314","pt":1717318043502,"mc":[{"id":"1.229554906","rc":[{"atl":[[30,0]],"id":57451148},{"spn":15.05,"spf":"NaN","id":57451148},{"atl":[[9.8,0]],"id":61631980},{"spn":4.26,"spf":"NaN","id":61631980},{"atl":[[7.4,0]],"id":61631978},{"spn":3.82,"spf":"NaN","id":61631978}],"con":true,"img":false}]}
{"op":"mcm","clk":"11450103324","pt":1717318043597,"mc":[{"id":"1.229554906","rc":[{"atl":[[28,2.61]],"id":57451148},{"atl":[[8.4,6.13]],"id":61631980},{"atl":[[6.4,9.41]],"id":61631978}],"con":true,"img":false}]}
{"op":"mcm","clk":"11450103334","pt":1717318043705,"mc":[{"id":"1.229554906","rc":[{"atl":[[8.6,0],[8.2,5.37]],"id":61631980},{"atl":[[6.2,7.21],[6.6,0]],"id":61631978}],"con":true,"img":false}]}
{"op":"mcm","clk":"11450104043","pt":1717318051682,"mc":[{"id":"1.229554906","rc":[{"atl":[[27,5.23],[29,0]],"id":57451148}],"con":true,"img":false}]}
{"op":"mcm","clk":"11450105278","pt":1717318064324,"mc":[{"id":"1.229554906","rc":[{"atl":[[28,0]],"id":57451148},{"atl":[[8.4,0]],"id":61631980},{"atl":[[6.4,0]],"id":61631978}],"con":true,"img":false}]}
{"op":"mcm","clk":"11450105285","pt":1717318064429,"mc":[{"id":"1.229554906","rc":[{"atl":[[32,2.61]],"id":57451148},{"atl":[[10,6.13]],"id":61631980},{"atl":[[7.6,9.41]],"id":61631978}],"con":true,"img":false}]}
{"op":"mcm","clk":"11450105296","pt":1717318064531,"mc":[{"id":"1.229554906","rc":[{"atl":[[6.2,0],[6.6,7.31]],"id":61631978}],"con":true,"img":false}]}
{"op":"mcm","clk":"11450111024","pt":1717318129177,"mc":[{"id":"1.229554906","rc":[{"atl":[[7.6,0]],"id":61631978}],"con":true,"img":false}]}
{"op":"mcm","clk":"11450111039","pt":1717318129285,"mc":[{"id":"1.229554906","rc":[{"atl":[[6.4,9.41]],"id":61631978}],"con":true,"img":false}]}
{"op":"mcm","clk":"11450111055","pt":1717318129490,"mc":[{"id":"1.229554906","rc":[{"atl":[[6.2,7.31],[6.6,0]],"id":61631978}],"con":true,"img":false}]}
{"op":"mcm","clk":"11450111170","pt":1717318130781,"mc":[{"id":"1.229554906","rc":[{"atb":[[9,0],[7,0]],"id":42269942},{"atb":[[3.1,0],[2.84,0]],"id":57451148},{"atb":[[1.01,0]],"id":60780007},{"atl":[[2.32,0]],"id":60780007},{"atb":[[1.72,0],[1.62,0]],"id":61631980},{"atl":[[6.8,0]],"id":61631980},{"atb":[[1.64,0],[1.54,0]],"id":61631978},{"atl":[[6,0]],"id":61631978}],"con":true,"img":false}]}
{"op":"mcm","clk":"11450111180","pt":1717318130887,"mc":[{"id":"1.229554906","rc":[{"atl":[[8.6,10.74]],"id":61631980}],"con":true,"img":false}]}
{"op":"mcm","clk":"11450111188","pt":1717318130993,"mc":[{"id":"1.229554906","rc":[{"atl":[[8.2,0]],"id":61631980}],"con":true,"img":false}]}
{"op":"mcm","clk":"11450111288","pt":1717318132497,"mc":[{"id":"1.229554906","rc":[{"atb":[[1.66,5.95]],"id":61631980},{"atb":[[1.38,10.33]],"id":61631978}],"con":true,"img":false}]}
{"op":"mcm","clk":"11450112349","pt":1717318143815,"mc":[{"id":"1.229554906","rc":[{"atb":[[2.86,0]],"id":57451148},{"atb":[[1.63,0]],"id":61631980},{"atl":[[6.4,0]],"id":61631978}],"con":true,"img":false}]}
{"op":"mcm","clk":"11450112360","pt":1717318143916,"mc":[{"id":"1.229554906","rc":[{"atb":[[2.7,22.5]],"id":57451148},{"atb":[[1.47,46.5]],"id":61631980},{"atl":[[7.4,9.41],[6.6,14.62]],"id":61631978}],"con":true,"img":false}]}
{"op":"mcm","clk":"11450112371","pt":1717318144017,"mc":[{"id":"1.229554906","rc":[{"atl":[[6.2,0]],"id":61631978}],"con":true,"img":false}]}
{"op":"mcm","clk":"11450113940","pt":1717318160734,"mc":[{"id":"1.229554906","rc":[{"atb":[[1.64,0]],"id":61631980},{"atb":[[1.56,0]],"id":61631978}],"con":true,"img":false}]}
{"op":"mcm","clk":"11450114488","pt":1717318166651,"mc":[{"id":"1.229554906","rc":[{"atb":[[7.2,5.61],[9.2,7.93]],"id":42269942},{"atb":[[2.86,18.73],[3.15,10.8]],"id":57451148},{"atb":[[1.01,5807.26]],"id":60780007},{"atl":[[2.3,0.4]],"id":60780007},{"atb":[[1.66,58.74],[1.76,30.56]],"id":61631980},{"atl":[[7,0.08]],"id":61631980},{"atb":[[1.59,39.36],[1.49,71.11]],"id":61631978},{"atl":[[5.5,0.11]],"id":61631978}],"con":true,"img":false}]}
{"op":"mcm","clk":"11450115472","pt":1717318178167,"mc":[{"id":"1.229554906","rc":[{"atb":[[1.66,52.79]],"id":61631980},{"atb":[[1.38,0]],"id":61631978}],"con":true,"img":false}]}
{"op":"mcm","clk":"11450115531","pt":1717318178941,"mc":[{"id":"1.229554906","rc":[{"atb":[[1.69,5.69]],"id":61631980},{"atb":[[1.61,6.43]],"id":61631978}],"con":true,"img":false}]}
{"op":"mcm","clk":"11450115842","pt":1717318182583,"mc":[{"id":"1.229554906","rc":[{"atl":[[8.8,0]],"id":61631980}],"con":true,"img":false}]}
{"op":"mcm","clk":"11450115853","pt":1717318182636,"mc":[{"id":"1.229554906","rc":[{"atl":[[8.4,5.36]],"id":61631980}],"con":true,"img":false}]}
{"op":"mcm","clk":"11450115862","pt":1717318182745,"mc":[{"id":"1.229554906","rc":[{"atl":[[8.6,0],[9.8,10.83]],"id":61631980}],"con":true,"img":false}]}
{"op":"mcm","clk":"11450117042","pt":1717318195285,"mc":[{"id":"1.229554906","rc":[{"spn":15.07,"spf":"NaN","id":57451148},{"spn":1.68,"spf":"NaN","id":60780007},{"atl":[[10,0]],"id":61631980},{"spn":4.38,"spf":"NaN","id":61631980},{"atl":[[6.8,0]],"id":61631978},{"spn":3.55,"spf":"NaN","id":61631978}],"con":true,"img":false}]}
{"op":"mcm","clk":"11450117053","pt":1717318195388,"mc":[{"id":"1.229554906","rc":[{"atl":[[9.4,6.13]],"id":61631980},{"atl":[[6.4,7.21]],"id":61631978}],"con":true,"img":false}]}
{"op":"mcm","clk":"11450117064","pt":1717318195438,"mc":[{"id":"1.229554906","rc":[{"atl":[[6.2,9.42],[6.6,0]],"id":61631978}],"con":true,"img":false}]}
{"op":"mcm","clk":"11450117540","pt":1717318201068,"mc":[{"id":"1.229554906","rc":[{"atb":[[1.69,11.86]],"id":61631980},{"atb":[[1.51,8.35]],"id":61631978}],"con":true,"img":false}]}
{"op":"mcm","clk":"11450117626","pt":1717318202107,"mc":[{"id":"1.229554906","rc":[{"atl":[[8.2,6.14],[9.8,0]],"id":61631980}],"con":true,"img":false}]}
{"op":"mcm","clk":"11450117968","pt":1717318205771,"mc":[{"id":"1.229554906","rc":[{"atb":[[2.7,0]],"id":57451148},{"atl":[[32,0]],"id":57451148},{"atb":[[1.47,0]],"id":61631980},{"atb":[[1.37,0]],"id":61631978}],"con":true,"img":false}]}
{"op":"mcm","clk":"11450117976","pt":1717318205872,"mc":[{"id":"1.229554906","rc":[{"atb":[[2.88,22.5]],"id":57451148},{"atl":[[26,2.61]],"id":57451148},{"atb":[[1.67,46.5]],"id":61631980},{"atb":[[1.5,45.24]],"id":61631978}],"con":true,"img":false}]}
{"op":"mcm","clk":"11450118132","pt":1717318207588,"mc":[{"id":"1.229554906","rc":[{"atb":[[2.94,0]],"id":57451148},{"atb":[[1.69,6.17]],"id":61631980}],"con":true,"img":false}]}
{"op":"mcm","clk":"11450118151","pt":1717318207792,"mc":[{"id":"1.229554906","rc":[{"atb":[[1.01,2.35]],"id":57451148},{"atb":[[1.7,5.61]],"id":61631980}],"con":true,"img":false}]}
{"op":"mcm","clk":"11450118228","pt":1717318208673,"mc":[{"id":"1.229554906","rc":[{"atb":[[1.01,2]],"id":57451148}],"con":true,"img":false}]}
{"op":"mcm","clk":"11450118242","pt":1717318208879,"mc":[{"id":"1.229554906","rc":[{"atb":[[1.01,0]],"id":57451148}],"con":true,"img":false}]}
{"op":"mcm","clk":"11450118250","pt":1717318208987,"mc":[{"id":"1.229554906","rc":[{"atb":[[2.96,2]],"id":57451148}],"con":true,"img":false}]}
{"op":"mcm","clk":"11450119744","pt":1717318225795,"mc":[{"id":"1.229554906","rc":[{"atl":[[6.4,0]],"id":61631978}],"con":true,"img":false}]}
{"op":"mcm","clk":"11450119754","pt":1717318225925,"mc":[{"id":"1.229554906","rc":[{"atl":[[7.2,9.54],[6.2,0],[6,7.21]],"id":61631978}],"con":true,"img":false}]}
{"op":"mcm","clk":"11450119773","pt":1717318226124,"mc":[{"id":"1.229554906","rc":[{"atl":[[5.9,9.42]],"id":61631978}],"con":true,"img":false}]}
{"op":"mcm","clk":"11450119779","pt":1717318226197,"mc":[{"id":"1.229554906","rc":[{"atl":[[7.2,0]],"id":61631978}],"con":true,"img":false}]}
{"op":"mcm","clk":"11450122319","pt":1717318255807,"mc":[{"id":"1.229554906","rc":[{"spn":14.57,"spf":"NaN","id":57451148},{"atl":[[6,0]],"id":61631978}],"con":true,"img":false}]}
{"op":"mcm","clk":"11450122330","pt":1717318255908,"mc":[{"id":"1.229554906","rc":[{"atl":[[7.2,9.54],[5.8,7.21]],"id":61631978}],"con":true,"img":false}]}
{"op":"mcm","clk":"11450122336","pt":1717318256010,"mc":[{"id":"1.229554906","rc":[{"atl":[[5.9,0]],"id":61631978}],"con":true,"img":false}]}
{"op":"mcm","clk":"11450122344","pt":1717318256115,"mc":[{"id":"1.229554906","rc":[{"atl":[[7.2,0],[5.9,9.42]],"id":61631978}],"con":true,"img":false}]}
{"op":"mcm","clk":"11450129233","pt":1717318335783,"mc":[{"id":"1.229554906","rc":[{"atl":[[26,0]],"id":57451148},{"spn":15.07,"spf":"NaN","id":57451148}],"con":true,"img":false}]}
{"op":"mcm","clk":"11450129243","pt":1717318335836,"mc":[{"id":"1.229554906","rc":[{"atl":[[30,2.61]],"id":57451148}],"con":true,"img":false}]}
{"op":"mcm","clk":"11450142065","pt":1717318484862,"mc":[{"id":"1.229554906","rc":[{"atb":[[7.2,0],[9.2,5.1]],"id":42269942},{"atb":[[2.86,0],[3.15,0]],"id":57451148},{"spn":14.98,"spf":"NaN","id":57451148},{"atb":[[1.01,0]],"id":60780007},{"atl":[[2.3,0]],"id":60780007},{"spn":1.86,"spf":"NaN","id":60780007},{"atb":[[1.66,0],[1.76,0]],"id":61631980},{"atl":[[7,0]],"id":61631980},{"spn":4.95,"spf":"NaN","id":61631980},{"atb":[[1.59,0],[1.49,0]],"id":61631978},{"atl":[[5.5,0]],"id":61631978},{"spn":3.7,"spf":"NaN","id":61631978}],"con":true,"img":false}]}
{"op":"mcm","clk":"11450142147","pt":1717318485850,"mc":[{"id":"1.229554906","rc":[{"atb":[[2.88,0]],"id":57451148},{"atb":[[1.67,0]],"id":61631980},{"atb":[[1.5,0]],"id":61631978}],"con":true,"img":false}]}
{"op":"mcm","clk":"11450142160","pt":1717318485950,"mc":[{"id":"1.229554906","rc":[{"atb":[[2.7,22.5]],"id":57451148},{"atb":[[1.46,46.5]],"id":61631980},{"atb":[[1.34,45.24]],"id":61631978}],"con":true,"img":false}]}
{"op":"mcm","clk":"11450143053","pt":1717318495854,"mc":[{"id":"1.229554906","rc":[{"atb":[[1.69,0]],"id":61631980},{"atb":[[1.51,0]],"id":61631978}],"con":true,"img":false}]}
{"op":"mcm","clk":"11450143993","pt":1717318506755,"mc":[{"id":"1.229554906","rc":[{"atb":[[6.8,6],[8.8,2.97]],"id":42269942},{"atb":[[3.1,11.05],[2.84,18.93]],"id":57451148},{"atb":[[1.01,5807.26]],"id":60780007},{"atl":[[2.32,0.39]],"id":60780007},{"atb":[[1.75,30.97],[1.65,53.6]],"id":61631980},{"atl":[[7,0.08]],"id":61631980},{"atb":[[1.51,68.32],[1.61,44.51]],"id":61631978},{"atl":[[5.7,0.1]],"id":61631978}],"con":true,"img":false}]}
{"op":"mcm","clk":"11450144192","pt":1717318509085,"mc":[{"id":"1.229554906","rc":[{"atb":[[1.61,38.08]],"id":61631978}],"con":true,"img":false}]}
{"op":"mcm","clk":"11450144208","pt":1717318509243,"mc":[{"id":"1.229554906","rc":[{"atb":[[1.63,6.23]],"id":61631978}],"con":true,"img":false}]}
{"op":"mcm","clk":"11450146795","pt":1717318539690,"mc":[{"id":"1.229554906","rc":[{"atb":[[1.68,6.26]],"id":61631980}],"con":true,"img":false}]}
{"op":"mcm","clk":"11450146827","pt":1717318540108,"mc":[{"id":"1.229554906","rc":[{"atb":[[1.53,8.03]],"id":61631978}],"con":true,"img":false}]}
{"op":"mcm","clk":"11450147373","pt":1717318545787,"mc":[{"id":"1.229554906","rc":[{"atb":[[2.7,0]],"id":57451148},{"spn":15.05,"spf":"NaN","id":57451148},{"spn":1.69,"spf":"NaN","id":60780007},{"spn":4.37,"spf":"NaN","id":61631980},{"atb":[[1.34,0]],"id":61631978},{"spn":3.66,"spf":"NaN","id":61631978}],"con":true,"img":false}]}
{"op":"mcm","clk":"11450147381","pt":1717318545889,"mc":[{"id":"1.229554906","rc":[{"atb":[[2.86,22.5]],"id":57451148},{"atb":[[1.52,45.24]],"id":61631978}],"con":true,"img":false}]}
{"op":"mcm","clk":"11450148130","pt":1717318554605,"mc":[{"id":"1.229554906","rc":[{"atb":[[2.96,0]],"id":57451148},{"atb":[[1.7,0]],"id":61631980}],"con":true,"img":false}]}
{"op":"mcm","clk":"11450148234","pt":1717318555835,"mc":[{"id":"1.229554906","rc":[{"atb":[[1.46,0]],"id":61631980}],"con":true,"img":false}]}
{"op":"mcm","clk":"11450148241","pt":1717318555938,"mc":[{"id":"1.229554906","rc":[{"atb":[[1.66,46.5]],"id":61631980}],"con":true,"img":false}]}
{"op":"mcm","clk":"11450172481","pt":1717318809875,"mc":[{"id":"1.229554906","rc":[{"atb":[[1.01,2.35]],"id":57451148},{"atb":[[1.69,5.69]],"id":61631980}],"con":true,"img":false}]}
{"op":"mcm","clk":"11450172596","pt":1717318811011,"mc":[{"id":"1.229554906","rc":[{"atb":[[1.01,2.02]],"id":57451148}],"con":true,"img":false}]}
{"op":"mcm","clk":"11450172709","pt":1717318812060,"mc":[{"id":"1.229554906","rc":[{"atb":[[1.01,0]],"id":57451148}],"con":true,"img":false}]}
{"op":"mcm","clk":"11450172716","pt":1717318812209,"mc":[{"id":"1.229554906","rc":[{"atb":[[2.94,2.02]],"id":57451148}],"con":true,"img":false}]}
{"op":"mcm","clk":"11450176892","pt":1717318856950,"mc":[{"id":"1.229554906","rc":[{"atb":[[6.8,0],[8.8,0]],"id":42269942},{"atb":[[3.1,0],[2.84,0]],"id":57451148},{"atb":[[1.01,0]],"id":60780007},{"atl":[[2.32,0]],"id":60780007},{"atb":[[1.75,0],[1.65,0]],"id":61631980},{"atl":[[7,0]],"id":61631980},{"atb":[[1.51,0],[1.61,0]],"id":61631978},{"atl":[[5.7,0]],"id":61631978}],"con":true,"img":false}]}
{"op":"mcm","clk":"11450177791","pt":1717318865843,"mc":[{"id":"1.229554906","rc":[{"atb":[[2.86,0]],"id":57451148},{"atb":[[1.66,0]],"id":61631980},{"atb":[[1.52,0]],"id":61631978}],"con":true,"img":false}]}
{"op":"mcm","clk":"11450177807","pt":1717318865947,"mc":[{"id":"1.229554906","rc":[{"atb":[[2.7,22.5]],"id":57451148},{"atb":[[1.46,46.5]],"id":61631980},{"atb":[[1.34,45.24]],"id":61631978}],"con":true,"img":false}]}
{"op":"mcm","clk":"11450177907","pt":1717318866938,"mc":[{"id":"1.229554906","rc":[{"atb":[[1.44,9.36]],"id":61631980},{"atb":[[1.32,12.76]],"id":61631978}],"con":true,"img":false}]}
{"op":"mcm","clk":"11450178320","pt":1717318871141,"mc":[{"id":"1.229554906","rc":[{"spn":14.97,"spf":"NaN","id":57451148},{"spn":1.86,"spf":"NaN","id":60780007},{"atb":[[1.44,7.42]],"id":61631980},{"spn":4.94,"spf":"NaN","id":61631980},{"spn":3.71,"spf":"NaN","id":61631978}],"con":true,"img":false}]}
{"op":"mcm","clk":"11450178934","pt":1717318877144,"mc":[{"id":"1.229554906","rc":[{"atb":[[1.68,0]],"id":61631980},{"atb":[[1.53,0]],"id":61631978}],"con":true,"img":false}]}
{"op":"mcm","clk":"11450178969","pt":1717318877467,"mc":[{"id":"1.229554906","rc":[{"atb":[[6.2,6.7],[8.2,3.22]],"id":42269942},{"atb":[[2.86,18.73],[3.15,10.8]],"id":57451148},{"atb":[[1.01,5807.26]],"id":60780007},{"atl":[[2.3,0.4]],"id":60780007},{"atb":[[1.64,54.44],[1.74,31.39]],"id":61631980},{"atl":[[6.8,0.08]],"id":61631980},{"atb":[[1.64,36.29],[1.54,64.52]],"id":61631978},{"atl":[[6,0.1]],"id":61631978}],"con":true,"img":false}]}
{"op":"mcm","clk":"11450179577","pt":1717318884576,"mc":[{"id":"1.229554906","rc":[{"atb":[[1.63,0]],"id":61631978}],"con":true,"img":false}]}
{"op":"mcm","clk":"11450179707","pt":1717318885778,"mc":[{"id":"1.229554906","rc":[{"atl":[[5.8,0]],"id":61631978}],"con":true,"img":false}]}
{"op":"mcm","clk":"11450179715","pt":1717318885874,"mc":[{"id":"1.229554906","rc":[{"atl":[[7,7.21]],"id":61631978}],"con":true,"img":false}]}
{"op":"mcm","clk":"11450179724","pt":1717318885978,"mc":[{"id":"1.229554906","rc":[{"atl":[[7.2,9.52],[5.9,0]],"id":61631978}],"con":true,"img":false}]}
{"op":"mcm","clk":"11450180943","pt":1717318898225,"mc":[{"id":"1.229554906","rc":[{"atl":[[7.2,0],[6.8,9.42]],"id":61631978}],"con":true,"img":false}]}
{"op":"mcm","clk":"11450181654","pt":1717318905746,"mc":[{"id":"1.229554906","rc":[{"atb":[[1.34,0]],"id":61631978}],"con":true,"img":false}]}
{"op":"mcm","clk":"11450181663","pt":1717318905846,"mc":[{"id":"1.229554906","rc":[{"atb":[[1.37,45.24]],"id":61631978}],"con":true,"img":false}]}
{"op":"mcm","clk":"11450181833","pt":1717318907661,"mc":[{"id":"1.229554906","rc":[{"atb":[[1.56,7.6]],"id":61631978}],"con":true,"img":false}]}
{"op":"mcm","clk":"11450181864","pt":1717318907966,"mc":[{"id":"1.229554906","rc":[{"atb":[[1.67,6.35]],"id":61631980}],"con":true,"img":false}]}
{"op":"mcm","clk":"11450182571","pt":1717318915774,"mc":[{"id":"1.229554906","rc":[{"atb":[[2.7,0]],"id":57451148},{"atb":[[1.46,0]],"id":61631980},{"atl":[[7,0]],"id":61631978}],"con":true,"img":false}]}
{"op":"mcm","clk":"11450182578","pt":1717318915876,"mc":[{"id":"1.229554906","rc":[{"atb":[[2.88,22.5]],"id":57451148},{"atb":[[1.65,46.5]],"id":61631980},{"atl":[[7.2,9.52],[6.6,7.21]],"id":61631978}],"con":true,"img":false}]}
{"op":"mcm","clk":"11450182589","pt":1717318915982,"mc":[{"id":"1.229554906","rc":[{"atl":[[6.4,9.42],[6.8,0]],"id":61631978}],"con":true,"img":false}]}
{"op":"mcm","clk":"11450182599","pt":1717318916084,"mc":[{"id":"1.229554906","rc":[{"atl":[[7.2,0]],"id":61631978}],"con":true,"img":false}]}
{"op":"mcm","clk":"11450183320","pt":1717318923571,"mc":[{"id":"1.229554906","rc":[{"atb":[[1.44,9.36]],"id":61631980}],"con":true,"img":false}]}
{"op":"mcm","clk":"11450183331","pt":1717318923671,"mc":[{"id":"1.229554906","rc":[{"atb":[[2.62,6.42]],"id":57451148},{"atb":[[1.05,1257.39]],"id":60780007},{"atl":[[2.78,5.98]],"id":60780007}],"con":true,"img":false}]}
{"op":"mcm","clk":"11450183844","pt":1717318929705,"mc":[{"id":"1.229554906","rc":[{"atb":[[2.94,0]],"id":57451148}],"con":true,"img":false}]}
{"op":"mcm","clk":"11450183867","pt":1717318929908,"mc":[{"id":"1.229554906","rc":[{"atb":[[1.01,2.35]],"id":57451148}],"con":true,"img":false}]}
{"op":"mcm","clk":"11450183978","pt":1717318931095,"mc":[{"id":"1.229554906","rc":[{"atb":[[1.01,2]],"id":57451148}],"con":true,"img":false}]}
{"op":"mcm","clk":"11450184009","pt":1717318931407,"mc":[{"id":"1.229554906","rc":[{"atb":[[1.01,0]],"id":57451148},{"spn":15.07,"spf":"NaN","id":57451148},{"spn":1.68,"spf":"NaN","id":60780007},{"spn":4.27,"spf":"NaN","id":61631980},{"spn":3.82,"spf":"NaN","id":61631978}],"con":true,"img":false}]}
{"op":"mcm","clk":"11450184020","pt":1717318931507,"mc":[{"id":"1.229554906","rc":[{"atb":[[2.96,2]],"id":57451148}],"con":true,"img":false}]}
{"op":"mcm","clk":"11450184118","pt":1717318932698,"mc":[{"id":"1.229554906","rc":[{"atb":[[1.69,0]],"id":61631980}],"con":true,"img":false}]}
{"op":"mcm","clk":"11450184823","pt":1717318939523,"mc":[{"id":"1.229554906","rc":[{"atb":[[1.32,0]],"id":61631978}],"con":true,"img":false}]}
{"op":"mcm","clk":"11450185381","pt":1717318944688,"mc":[{"id":"1.229554906","rc":[{"atb":[[1.68,5.77]],"id":61631980}],"con":true,"img":false}]}
{"op":"mcm","clk":"11450185482","pt":1717318945827,"mc":[{"id":"1.229554906","rc":[{"atl":[[6.6,0]],"id":61631978}],"con":true,"img":false}]}
{"op":"mcm","clk":"11450185497","pt":1717318945936,"mc":[{"id":"1.229554906","rc":[{"atl":[[7.2,9.52],[6.4,0],[6.2,7.21]],"id":61631978}],"con":true,"img":false}]}
{"op":"mcm","clk":"11450186567","pt":1717318955906,"mc":[{"id":"1.229554906","rc":[{"atb":[[2.62,0]],"id":57451148}],"con":true,"img":false}]}
{"op":"mcm","clk":"11450186729","pt":1717318957607,"mc":[{"id":"1.229554906","rc":[{"atl":[[6,7.31]],"id":61631978}],"con":true,"img":false}]}
{"op":"mcm","clk":"11450186737","pt":1717318957709,"mc":[{"id":"1.229554906","rc":[{"atl":[[7.2,0]],"id":61631978}],"con":true,"img":false}]}
{"op":"mcm","clk":"11450188686","pt":1717318978539,"mc":[{"id":"1.229554906","rc":[{"atb":[[2.86,25.15]],"id":57451148}],"con":true,"img":false}]}
{"op":"mcm","clk":"11450189052","pt":1717318982171,"mc":[{"id":"1.229554906","rc":[{"atb":[[1.44,0]],"id":61631980}],"con":true,"img":false}]}
{"op":"mcm","clk":"11450195941","pt":1717319055886,"mc":[{"id":"1.229554906","rc":[{"atb":[[2.86,18.73]],"id":57451148}],"con":true,"img":false}]}
{"op":"mcm","clk":"11450196035","pt":1717319056881,"mc":[{"id":"1.229554906","rc":[{"atb":[[1.37,58]],"id":61631978}],"con":true,"img":false}]}
{"op":"mcm","clk":"11450196052","pt":1717319057082,"mc":[{"id":"1.229554906","rc":[{"atb":[[2.88,28.92]],"id":57451148}],"con":true,"img":false}]}
{"op":"mcm","clk":"11450197231","pt":1717319071006,"mc":[{"id":"1.229554906","rc":[{"atb":[[2.46,0]],"id":57451148}],"con":true,"img":false}]}
{"op":"mcm","clk":"11450200916","pt":1717319108518,"mc":[{"id":"1.229554906","rc":[{"atb":[[2.96,4.17]],"id":57451148}],"con":true,"img":false}]}
{"op":"mcm","clk":"11450208321","pt":1717319182499,"mc":[{"id":"1.229554906","rc":[{"atb":[[6.2,0],[8.2,0]],"id":42269942},{"atb":[[2.86,0],[3.15,0]],"id":57451148},{"spn":14.98,"spf":"NaN","id":57451148},{"atb":[[1.01,0]],"id":60780007},{"atl":[[2.3,0]],"id":60780007},{"spn":1.86,"spf":"NaN","id":60780007},{"atb":[[1.64,0],[1.74,0]],"id":61631980},{"atl":[[6.8,0]],"id":61631980},{"spn":4.94,"spf":"NaN","id":61631980},{"atb":[[1.64,0],[1.54,0]],"id":61631978},{"atl":[[6,7.21]],"id":61631978},{"spn":3.78,"spf":"NaN","id":61631978}],"con":true,"img":false}]}
{"op":"mcm","clk":"11450208634","pt":1717319185206,"mc":[{"id":"1.229554906","rc":[{"atb":[[1.38,10.33]],"id":61631978}],"con":true,"img":false}]}
{"op":"mcm","clk":"11450208707","pt":1717319185838,"mc":[{"id":"1.229554906","rc":[{"atb":[[2.88,6.42]],"id":57451148},{"atb":[[1.65,0]],"id":61631980}],"con":true,"img":false}]}
{"op":"mcm","clk":"11450208717","pt":1717319185894,"mc":[{"id":"1.229554906","rc":[{"atb":[[2.88,0]],"id":57451148},{"atb":[[1.37,45.24]],"id":61631978}],"con":true,"img":false}]}
{"op":"mcm","clk":"11450208731","pt":1717319186004,"mc":[{"id":"1.229554906","rc":[{"atb":[[2.7,22.5]],"id":57451148},{"atb":[[1.46,46.5]],"id":61631980}],"con":true,"img":false}]}
{"op":"mcm","clk":"11450208813","pt":1717319186998,"mc":[{"id":"1.229554906","rc":[{"atb":[[2.64,6.42]],"id":57451148},{"atb":[[1.32,12.76]],"id":61631978}],"con":true,"img":false}]}
{"op":"mcm","clk":"11450209017","pt":1717319189012,"mc":[{"id":"1.229554906","rc":[{"atb":[[1.38,0]],"id":61631978}],"con":true,"img":false}]}
{"op":"mcm","clk":"11450210137","pt":1717319200256,"mc":[{"id":"1.229554906","rc":[{"atb":[[1.38,10.33]],"id":61631978}],"con":true,"img":false}]}
{"op":"mcm","clk":"11450210471","pt":1717319203311,"mc":[{"id":"1.229554906","rc":[{"atb":[[8.6,3.05],[6.6,6.22]],"id":42269942},{"atb":[[3.2,10.55],[2.88,18.53]],"id":57451148},{"atb":[[1.01,5807.26]],"id":60780007},{"atl":[[2.3,0.4]],"id":60780007},{"atb":[[1.71,32.71],[1.61,57.12]],"id":61631980},{"atl":[[6.6,0.09]],"id":61631980},{"atb":[[1.55,63.35],[1.65,35.73]],"id":61631978},{"atl":[[6.2,7.31]],"id":61631978}],"con":true,"img":false}]}
{"op":"mcm","clk":"11450211925","pt":1717319217928,"mc":[{"id":"1.229554906","rc":[{"atb":[[2.96,2]],"id":57451148},{"atb":[[1.67,0]],"id":61631980},{"atb":[[1.56,0]],"id":61631978}],"con":true,"img":false}]}
{"op":"mcm","clk":"11450212599","pt":1717319224528,"mc":[{"id":"1.229554906","rc":[{"atb":[[1.44,9.36]],"id":61631980}],"con":true,"img":false}]}
{"op":"mcm","clk":"11450212695","pt":1717319225512,"mc":[{"id":"1.229554906","rc":[{"atb":[[2.64,0]],"id":57451148},{"atb":[[1.44,0]],"id":61631980},{"atb":[[1.32,0]],"id":61631978}],"con":true,"img":false}]}
{"op":"mcm","clk":"11450213734","pt":1717319235859,"mc":[{"id":"1.229554906","rc":[{"atb":[[2.7,0]],"id":57451148},{"atb":[[1.46,0]],"id":61631980}],"con":true,"img":false}]}
{"op":"mcm","clk":"11450213742","pt":1717319235962,"mc":[{"id":"1.229554906","rc":[{"atb":[[2.9,22.5]],"id":57451148},{"atb":[[1.62,46.5]],"id":61631980}],"con":true,"img":false}]}
{"op":"mcm","clk":"11450213861","pt":1717319237048,"mc":[{"id":"1.229554906","rc":[{"atb":[[2.64,6.42]],"id":57451148}],"con":true,"img":false}]}
{"op":"mcm","clk":"11450214735","pt":1717319245472,"mc":[{"id":"1.229554906","rc":[{"atb":[[2.96,0]],"id":57451148},{"spn":15.1,"spf":"NaN","id":57451148},{"spn":1.68,"spf":"NaN","id":60780007},{"spn":4.15,"spf":"NaN","id":61631980},{"spn":3.82,"spf":"NaN","id":61631978}],"con":true,"img":false}]}
{"op":"mcm","clk":"11450214753","pt":1717319245681,"mc":[{"id":"1.229554906","rc":[{"atb":[[1.01,2.35]],"id":57451148}],"con":true,"img":false}]}
{"op":"mcm","clk":"11450214774","pt":1717319245940,"mc":[{"id":"1.229554906","rc":[{"atb":[[1.01,1.97]],"id":57451148}],"con":true,"img":false}]}
{"op":"mcm","clk":"11450214797","pt":1717319246148,"mc":[{"id":"1.229554906","rc":[{"atb":[[1.01,0]],"id":57451148}],"con":true,"img":false}]}
{"op":"mcm","clk":"11450214807","pt":1717319246254,"mc":[{"id":"1.229554906","rc":[{"atb":[[2.98,1.97]],"id":57451148}],"con":true,"img":false}]}
{"op":"mcm","clk":"11450214885","pt":1717319246875,"mc":[{"id":"1.229554906","rc":[{"atb":[[1.38,23.09]],"id":61631978}],"con":true,"img":false}]}
{"op":"mcm","clk":"11450215851","pt":1717319255574,"mc":[{"id":"1.229554906","rc":[{"atb":[[1.57,7.47]],"id":61631978}],"con":true,"img":false}]}
{"op":"mcm","clk":"11450215872","pt":1717319255771,"mc":[{"id":"1.229554906","rc":[{"atb":[[2.46,2.91]],"id":57451148}],"con":true,"img":false}]}
{"op":"mcm","clk":"11450215915","pt":1717319256186,"mc":[{"id":"1.229554906","rc":[{"atb":[[1.63,6.76]],"id":61631980}],"con":true,"img":false}]}
{"op":"mcm","clk":"11450216349","pt":1717319260485,"mc":[{"id":"1.229554906","rc":[{"atb":[[1.68,0]],"id":61631980}],"con":true,"img":false}]}
{"op":"mcm","clk":"11450217888","pt":1717319275793,"mc":[{"id":"1.229554906","rc":[{"atb":[[1.37,0]],"id":61631978}],"con":true,"img":false}]}
{"op":"mcm","clk":"11450217900","pt":1717319275897,"mc":[{"id":"1.229554906","rc":[{"atb":[[1.39,45.24]],"id":61631978}],"con":true,"img":false}]}
{"op":"mcm","clk":"11450217911","pt":1717319276002,"mc":[{"id":"1.229554906","rc":[{"atb":[[1.38,21.67]],"id":61631978}],"con":true,"img":false}]}
{"op":"mcm","clk":"11450218765","pt":1717319284514,"mc":[{"id":"1.229554906","rc":[{"atb":[[1.65,48.4]],"id":61631978},{"atl":[[5.9,12.67]],"id":61631978}],"con":true,"img":false}]}
{"op":"mcm","clk":"11450218778","pt":1717319284618,"mc":[{"id":"1.229554906","rc":[{"atb":[[3.2,16.45],[3.1,5],[3.3,2.5],[2.96,10]],"id":57451148},{"atl":[[9.6,2.5],[11,5],[13,10],[26,3.2]],"id":57451148},{"atb":[[1.07,126.73],[1.08,2.5],[1.04,5]],"id":60780007},{"atl":[[1.89,5],[1.85,2.5],[2.64,25.57],[1.93,10]],"id":60780007},{"atb":[[2.02,2.5],[1.97,5],[1.93,10]],"id":61631980},{"atl":[[4,2.5],[4.8,10],[4.4,5]],"id":61631980},{"atb":[[1.58,2.5],[1.54,5],[1.5,10],[1.38,11.75]],"id":61631978},{"atl":[[3.95,10],[3.55,2.5],[3.75,5]],"id":61631978}],"con":true,"img":false}]}
{"op":"mcm","clk":"11450218787","pt":1717319284722,"mc":[{"id":"1.229554906","rc":[{"atb":[[2.64,0]],"id":57451148},{"atl":[[27,2.61],[15,2.62]],"id":57451148},{"atl":[[2.78,0]],"id":60780007},{"atb":[[1.71,42.39]],"id":61631980},{"atl":[[8,9.68],[8.2,0],[6.8,6.14]],"id":61631980},{"atb":[[1.38,10.33]],"id":61631978},{"atl":[[6,0],[5.9,19.98]],"id":61631978}],"con":true,"img":false}]}
{"op":"mcm","clk":"11450219378","pt":1717319290645,"mc":[{"id":"1.229554906","rc":[{"atb":[[2.46,0]],"id":57451148},{"atb":[[1.57,0]],"id":61631978}],"con":true,"img":false}]}
{"op":"mcm","clk":"11450219401","pt":1717319290814,"mc":[{"id":"1.229554906","rc":[{"atb":[[2.98,0]],"id":57451148}],"con":true,"img":false}]}
{"op":"mcm","clk":"11450219920","pt":1717319295827,"mc":[{"id":"1.229554906","rc":[{"atb":[[2.9,0]],"id":57451148}],"con":true,"img":false}]}
{"op":"mcm","clk":"11450219928","pt":1717319295931,"mc":[{"id":"1.229554906","rc":[{"atb":[[2.98,22.5]],"id":57451148}],"con":true,"img":false}]}
{"op":"mcm","clk":"11450220471","pt":1717319301986,"mc":[{"id":"1.229554906","rc":[{"atl":[[3.5,11.25]],"id":61631978}],"con":true,"img":false}]}
{"op":"mcm","clk":"11450220483","pt":1717319302089,"mc":[{"id":"1.229554906","rc":[{"atb":[[3.3,10]],"id":57451148},{"atl":[[9.4,7.5]],"id":57451148},{"atb":[[1.08,13.75]],"id":60780007},{"atl":[[1.7,11.25]],"id":60780007},{"atl":[[5.9,7.31]],"id":61631978}],"con":true,"img":false}]}
{"op":"mcm","clk":"11450220495","pt":1717319302199,"mc":[{"id":"1.229554906","rc":[{"atb":[[2.02,10]],"id":61631980},{"atl":[[3.7,7.5]],"id":61631980}],"con":true,"img":false}]}
{"op":"mcm","clk":"11450220505","pt":1717319302253,"mc":[{"id":"1.229554906","rc":[{"atb":[[3.2,10.55]],"id":57451148},{"atl":[[26,0]],"id":57451148},{"atb":[[1.07,101.16]],"id":60780007},{"atl":[[2.64,0]],"id":60780007}],"con":true,"img":false}]}
{"op":"mcm","clk":"11450220517","pt":1717319302403,"mc":[{"id":"1.229554906","rc":[{"atb":[[1.71,32.71]],"id":61631980},{"atl":[[8,0]],"id":61631980}],"con":true,"img":false}]}
{"op":"mcm","clk":"11450220873","pt":1717319305887,"mc":[{"id":"1.229554906","rc":[{"atl":[[27,0]],"id":57451148},{"spn":6.35,"spf":"NaN","id":57451148},{"spn":1.39,"spf":"NaN","id":60780007},{"spn":2.86,"spf":"NaN","id":61631980},{"atl":[[6.2,0.09]],"id":61631978},{"spn":2.57,"spf":"NaN","id":61631978}],"con":true,"img":false}]}
{"op":"mcm","clk":"11450220884","pt":1717319305986,"mc":[{"id":"1.229554906","rc":[{"atl":[[23,2.61]],"id":57451148},{"atl":[[5.8,7.21]],"id":61631978}],"con":true,"img":false}]}
{"op":"mcm","clk":"11450221873","pt":1717319315793,"mc":[{"id":"1.229554906","rc":[{"atl":[[8.4,0]],"id":61631980}],"con":true,"img":false}]}
{"op":"mcm","clk":"11450221884","pt":1717319315899,"mc":[{"id":"1.229554906","rc":[{"atl":[[6.6,5.46]],"id":61631980}],"con":true,"img":false}]}
{"op":"mcm","clk":"11450226556","pt":1717319367678,"mc":[{"id":"1.229554906","rc":[{"atl":[[4.3,5],[3.95,2.5],[4.7,10]],"id":61631980}],"con":true,"img":false}]}
{"op":"mcm","clk":"11450226568","pt":1717319367782,"mc":[{"id":"1.229554906","rc":[{"atl":[[4,0],[4.8,0],[4.4,0]],"id":61631980}],"con":true,"img":false}]}
{"op":"mcm","clk":"11450227050","pt":1717319372673,"mc":[{"id":"1.229554906","rc":[{"atb":[[3.1,0],[3.35,11.88],[2.98,32.5],[3.15,5],[3.3,7.5],[2.96,0]],"id":57451148}],"con":true,"img":false}]}
{"op":"mcm","clk":"11450227065","pt":1717319372871,"mc":[{"id":"1.229554906","rc":[{"atb":[[3.3,0]],"id":57451148}],"con":true,"img":false}]}
{"op":"mcm","clk":"11450227096","pt":1717319373288,"mc":[{"id":"1.229554906","rc":[{"atb":[[3.35,0],[3.15,0],[2.98,22.5]],"id":57451148},{"atl":[[9.6,0],[11,0],[13,0],[9.4,0]],"id":57451148},{"atb":[[1.08,0],[1.04,0]],"id":60780007},{"atl":[[1.89,0],[1.85,0],[1.7,0],[1.93,0]],"id":60780007},{"atb":[[2.02,0],[1.97,0],[1.93,0]],"id":61631980},{"atl":[[4.3,0],[3.95,0],[3.7,0],[4.7,0]],"id":61631980},{"atb":[[1.58,0],[1.54,0],[1.5,0],[1.65,35.73]],"id":61631978},{"atl":[[3.95,0],[3.55,0],[3.5,0],[3.75,0]],"id":61631978}],"con":true,"img":false}]}
{"op":"mcm","clk":"11450227106","pt":1717319373343,"mc":[{"id":"1.229554906","rc":[{"atl":[[23,7.16],[15,0]],"id":57451148}],"con":true,"img":false}]}
{"op":"mcm","clk":"11450227143","pt":1717319373751,"mc":[{"id":"1.229554906","rc":[{"atb":[[2.9,6.42]],"id":57451148}],"con":true,"img":false}]}
{"op":"mcm","clk":"11450227214","pt":1717319374476,"mc":[{"id":"1.229554906","rc":[{"atb":[[1.63,16.12]],"id":61631980}],"con":true,"img":false}]}
{"op":"mcm","clk":"11450227268","pt":1717319375149,"mc":[{"id":"1.229554906","rc":[{"atl":[[2.78,5.98]],"id":60780007}],"con":true,"img":false}]}
{"op":"mcm","clk":"11450227317","pt":1717319375769,"mc":[{"id":"1.229554906","rc":[{"atb":[[2.98,0]],"id":57451148},{"atl":[[6.6,0.09]],"id":61631980},{"atl":[[5.8,0]],"id":61631978}],"con":true,"img":false}]}
{"op":"mcm","clk":"11450227326","pt":1717319375880,"mc":[{"id":"1.229554906","rc":[{"atb":[[2.9,22.5]],"id":57451148},{"atl":[[8.6,5.36],[9.2,6.23],[6.8,0]],"id":61631980},{"atl":[[7.2,7.41],[6.6,7.21]],"id":61631978}],"con":true,"img":false}]}
{"op":"mcm","clk":"11450227331","pt":1717319375974,"mc":[{"id":"1.229554906","rc":[{"atl":[[5.9,0]],"id":61631978}],"con":true,"img":false}]}
{"op":"mcm","clk":"11450227646","pt":1717319379969,"mc":[{"id":"1.229554906","rc":[{"atb":[[1.57,7.47]],"id":61631978}],"con":true,"img":false}]}
{"op":"mcm","clk":"11450227692","pt":1717319380594,"mc":[{"id":"1.229554906","rc":[{"atb":[[1.01,2.35],[2.46,2.91]],"id":57451148}],"con":true,"img":false}]}
{"op":"mcm","clk":"11450227710","pt":1717319380806,"mc":[{"id":"1.229554906","rc":[{"atb":[[1.01,1.98]],"id":57451148}],"con":true,"img":false}]}
{"op":"mcm","clk":"11450227731","pt":1717319381057,"mc":[{"id":"1.229554906","rc":[{"atb":[[1.01,0]],"id":57451148}],"con":true,"img":false}]}
{"op":"mcm","clk":"11450227738","pt":1717319381162,"mc":[{"id":"1.229554906","rc":[{"atb":[[2.98,1.98]],"id":57451148}],"con":true,"img":false}]}
{"op":"mcm","clk":"11450227934","pt":1717319383297,"mc":[{"id":"1.229554906","rc":[{"atl":[[9.2,0],[8.4,6.14]],"id":61631980},{"atl":[[7.2,0],[6.4,7.41]],"id":61631978}],"con":true,"img":false}]}
{"op":"mcm","clk":"11450228405","pt":1717319388612,"mc":[{"id":"1.229554906","rc":[{"atb":[[8.6,0],[6.6,0]],"id":42269942},{"atb":[[3.2,0],[2.88,0]],"id":57451148},{"atb":[[1.01,0]],"id":60780007},{"atl":[[2.3,0]],"id":60780007},{"atb":[[1.71,0],[1.61,0]],"id":61631980},{"atl":[[6.6,0]],"id":61631980},{"atb":[[1.55,0],[1.65,0]],"id":61631978},{"atl":[[6.2,0]],"id":61631978}],"con":true,"img":false}]}
{"op":"mcm","clk":"11450228422","pt":1717319388773,"mc":[{"id":"1.229554906","rc":[{"atl":[[2.78,0]],"id":60780007}],"con":true,"img":false}]}
{"op":"mcm","clk":"11450228432","pt":1717319388877,"mc":[{"id":"1.229554906","rc":[{"atb":[[1.05,1272.15]],"id":60780007}],"con":true,"img":false}]}
{"op":"mcm","clk":"11450229040","pt":1717319395788,"mc":[{"id":"1.229554906","rc":[{"atb":[[2.9,0]],"id":57451148},{"atb":[[1.64,6.13],[1.62,0]],"id":61631980}],"con":true,"img":false}]}
{"op":"mcm","clk":"11450229050","pt":1717319395888,"mc":[{"id":"1.229554906","rc":[{"atb":[[2.72,22.5]],"id":57451148},{"atb":[[1.63,6.76],[1.47,46.5]],"id":61631980},{"atb":[[1.38,0]],"id":61631978}],"con":true,"img":false}]}
{"op":"mcm","clk":"11450229123","pt":1717319396614,"mc":[{"id":"1.229554906","rc":[{"atb":[[1.41,9.57]],"id":61631978}],"con":true,"img":false}]}
{"op":"mcm","clk":"11450229947","pt":1717319405508,"mc":[{"id":"1.229554906","rc":[{"atb":[[1.32,12.76]],"id":61631978}],"con":true,"img":false}]}
{"op":"mcm","clk":"11450229996","pt":1717319406124,"mc":[{"id":"1.229554906","rc":[{"atb":[[2.66,6.42]],"id":57451148}],"con":true,"img":false}]}
{"op":"mcm","clk":"11450230049","pt":1717319406695,"mc":[{"id":"1.229554906","rc":[{"atb":[[1.44,9.36]],"id":61631980}],"con":true,"img":false}]}
{"op":"mcm","clk":"11450230112","pt":1717319407420,"mc":[{"id":"1.229554906","rc":[{"atl":[[2.78,5.98]],"id":60780007}],"con":true,"img":false}]}
{"op":"mcm","clk":"11450230349","pt":1717319410014,"mc":[{"id":"1.229554906","rc":[{"atb":[[9,2.9],[7,5.8]],"id":42269942},{"atb":[[2.86,18.73],[3.15,10.8]],"id":57451148},{"atb":[[1.01,5807.26]],"id":60780007},{"atl":[[2.3,0.4]],"id":60780007},{"atb":[[1.64,60.57],[1.74,31.39]],"id":61631980},{"atl":[[6.8,0.08]],"id":61631980},{"atb":[[1.63,36.87],[1.53,65.74]],"id":61631978},{"atl":[[5.9,0.1]],"id":61631978}],"con":true,"img":false}]}
{"op":"mcm","clk":"11450230358","pt":1717319410122,"mc":[{"id":"1.229554906","rc":[{"atl":[[5.1,18.29],[5.3,29.07],[4.9,12.82],[4.7,5.41]],"id":61631980}],"con":true,"img":false}]}
{"op":"mcm","clk":"11450230365","pt":1717319410226,"mc":[{"id":"1.229554906","rc":[{"atb":[[8.6,2.63],[8.2,6.94],[7.4,19.53],[7.8,20.97]],"id":42269942},{"atl":[[270,1],[290,1],[230,1.18],[250,3.61]],"id":42269942},{"atl":[[8.6,9.87],[9,15.62],[8.2,6.94],[7.8,2.94]],"id":57451148},{"atb":[[1.44,0]],"id":61631980},{"atl":[[6.8,17.32],[8.4,0]],"id":61631980},{"atb":[[1.32,0]],"id":61631978},{"atl":[[5.1,18.29],[5.3,29.07],[4.9,12.82],[4.7,5.41]],"id":61631978}],"con":true,"img":false}]}
{"op":"mcm","clk":"11450230377","pt":1717319410328,"mc":[{"id":"1.229554906","rc":[{"atl":[[23,2.61],[15,7.14]],"id":57451148},{"atl":[[6.4,0],[5.9,20.51]],"id":61631978}],"con":true,"img":false}]}
{"op":"mcm","clk":"11450230705","pt":1717319413824,"mc":[{"id":"1.229554906","rc":[{"atb":[[1.17,100]],"id":42269942},{"atb":[[1.17,100]],"id":57451148}],"con":true,"img":false}]}
{"op":"mcm","clk":"11450231769","pt":1717319425332,"mc":[{"id":"1.229554906","rc":[{"atb":[[1.64,54.44]],"id":61631980}],"con":true,"img":false}]}
{"op":"mcm","clk":"11450231804","pt":1717319425666,"mc":[{"id":"1.229554906","rc":[{"atb":[[1.67,5.85]],"id":61631980}],"con":true,"img":false}]}
{"op":"mcm","clk":"11450231812","pt":1717319425751,"mc":[{"id":"1.229554906","rc":[{"atb":[[2.28,32.69],[1.95,67.48]],"id":57451148},{"atl":[[3.5,22.4]],"id":60780007}],"con":true,"img":false}]}
{"op":"mcm","clk":"11450231821","pt":1717319425848,"mc":[{"id":"1.229554906","rc":[{"atb":[[9.2,0],[7.8,11.03]],"id":42269942},{"atb":[[2.4,0],[2.72,0]],"id":57451148},{"atl":[[2.66,0],[2.78,0],[2.94,0]],"id":60780007}],"con":true,"img":false}]}
{"op":"mcm","clk":"11450231835","pt":1717319425957,"mc":[{"id":"1.229554906","rc":[{"atb":[[6.2,9.94],[8.4,5.1]],"id":42269942},{"atb":[[2.66,0]],"id":57451148},{"atl":[[2.92,25.21]],"id":60780007}],"con":true,"img":false}]}
{"op":"mcm","clk":"11450231982","pt":1717319427562,"mc":[{"id":"1.229554906","rc":[{"atb":[[2.46,0]],"id":57451148},{"atb":[[1.63,0]],"id":61631980},{"atb":[[1.57,0]],"id":61631978}],"con":true,"img":false}]}
{"op":"mcm","clk":"11450232806","pt":1717319435767,"mc":[{"id":"1.229554906","rc":[{"spn":119.5,"spf":"NaN","id":42269942},{"spn":5.47,"spf":"NaN","id":57451148},{"spn":1.68,"spf":"NaN","id":60780007},{"spn":3.22,"spf":"NaN","id":61631980},{"atb":[[1.39,0]],"id":61631978},{"spn":3.16,"spf":"NaN","id":61631978}],"con":true,"img":false}]}
{"op":"mcm","clk":"11450232814","pt":1717319435866,"mc":[{"id":"1.229554906","rc":[{"atb":[[1.42,45.24]],"id":61631978}],"con":true,"img":false}]}
{"op":"mcm","clk":"11450232863","pt":1717319436442,"mc":[{"id":"1.229554906","rc":[{"atb":[[1.01,6057.26],[1.03,250],[1.05,1522.15]],"id":60780007},{"atl":[[1.56,89.29],[1.6,208.33],[1.58,129.31],[1.54,37.04]],"id":60780007}],"con":true,"img":false}]}
{"op":"mcm","clk":"11450232884","pt":1717319436650,"mc":[{"id":"1.229554906","rc":[{"atl":[[320,1],[230,0.18]],"id":42269942}],"con":true,"img":false}]}
{"op":"mcm","clk":"11450232903","pt":1717319436863,"mc":[{"id":"1.229554906","rc":[{"atb":[[2.12,9.23]],"id":57451148},{"atb":[[1.41,22.33]],"id":61631978}],"con":true,"img":false}]}
{"op":"mcm","clk":"11450232939","pt":1717319437276,"mc":[{"id":"1.229554906","rc":[{"atb":[[1.05,1272.15],[1.04,250]],"id":60780007}],"con":true,"img":false}]}
{"op":"mcm","clk":"11450233079","pt":1717319438776,"mc":[{"id":"1.229554906","rc":[{"atb":[[1.05,1522.15]],"id":60780007}],"con":true,"img":false}]}
{"op":"mcm","clk":"11450233168","pt":1717319439767,"mc":[{"id":"1.229554906","rc":[{"atb":[[1.05,1272.15]],"id":60780007}],"con":true,"img":false}]}
{"op":"mcm","clk":"11450233237","pt":1717319440447,"mc":[{"id":"1.229554906","rc":[{"atl":[[230,1.18]],"id":42269942},{"atl":[[3,10]],"id":61631980},{"atl":[[2.46,13.7],[4.7,0]],"id":61631978}],"con":true,"img":false}]}
{"op":"mcm","clk":"11450233245","pt":1717319440548,"mc":[{"id":"1.229554906","rc":[{"atb":[[8.6,0],[8.2,0],[7.4,0],[7.8,0]],"id":42269942},{"atl":[[250,2.61]],"id":42269942},{"atb":[[2.12,0]],"id":57451148},{"atl":[[4.7,0]],"id":61631980}],"con":true,"img":false}]}
{"op":"mcm","clk":"11450233292","pt":1717319440963,"mc":[{"id":"1.229554906","rc":[{"atb":[[1.05,1522.15]],"id":60780007}],"con":true,"img":false}]}
{"op":"mcm","clk":"11450233329","pt":1717319441374,"mc":[{"id":"1.229554906","rc":[{"atb":[[1.05,1272.15]],"id":60780007}],"con":true,"img":false}]}
{"op":"mcm","clk":"11450233345","pt":1717319441579,"mc":[{"id":"1.229554906","rc":[{"atb":[[1.05,1522.15]],"id":60780007}],"con":true,"img":false}]}
{"op":"mcm","clk":"11450233368","pt":1717319441789,"mc":[{"id":"1.229554906","rc":[{"atb":[[1.05,1272.15]],"id":60780007}],"con":true,"img":false}]}
{"op":"mcm","clk":"11450233778","pt":1717319445790,"mc":[{"id":"1.229554906","rc":[{"atb":[[8.4,0]],"id":42269942},{"atl":[[120,0.35]],"id":42269942},{"atl":[[23,0]],"id":57451148},{"atb":[[1.47,0]],"id":61631980},{"atl":[[5.2,9.96]],"id":61631980},{"atl":[[6.6,0]],"id":61631978}],"con":true,"img":false}]}
{"op":"mcm","clk":"11450233785","pt":1717319445895,"mc":[{"id":"1.229554906","rc":[{"atb":[[7.2,5.1]],"id":42269942},{"atl":[[230,1]],"id":42269942},{"atl":[[16,2.61]],"id":57451148},{"atb":[[1.65,46.5]],"id":61631980},{"atl":[[8.6,0]],"id":61631980},{"atl":[[5.2,7.21]],"id":61631978}],"con":true,"img":false}]}
{"op":"mcm","clk":"11450234242","pt":1717319450895,"mc":[{"id":"1.229554906","rc":[{"atl":[[250,3.61]],"id":42269942},{"atl":[[3.1,23.81]],"id":61631980},{"atl":[[2.5,33.33]],"id":61631978}],"con":true,"img":false}]}
{"op":"mcm","clk":"11450234346","pt":1717319451888,"mc":[{"id":"1.229554906","rc":[{"atb":[[1.02,258.87]],"id":60780007}],"con":true,"img":false}]}
{"op":"mcm","clk":"11450234666","pt":1717319455092,"mc":[{"id":"1.229554906","rc":[{"atb":[[9,8.01],[6,0]],"id":42269942},{"atl":[[320,0]],"id":42269942},{"atl":[[5.1,0],[5.3,0],[4.9,0]],"id":61631980}],"con":true,"img":false}]}
{"op":"mcm","clk":"11450234677","pt":1717319455195,"mc":[{"id":"1.229554906","rc":[{"atb":[[9,2.9],[7.4,5.81]],"id":42269942}],"con":true,"img":false}]}
{"op":"mcm","clk":"11450234686","pt":1717319455299,"mc":[{"id":"1.229554906","rc":[{"atb":[[9,8.71],[7.4,0]],"id":42269942}],"con":true,"img":false}]}
{"op":"mcm","clk":"11450234699","pt":1717319455358,"mc":[{"id":"1.229554906","rc":[{"atb":[[7.4,5.81]],"id":42269942}],"con":true,"img":false}]}
{"op":"mcm","clk":"11450234711","pt":1717319455461,"mc":[{"id":"1.229554906","rc":[{"atb":[[9,2.9]],"id":42269942}],"con":true,"img":false}]}
{"op":"mcm","clk":"11450234719","pt":1717319455565,"mc":[{"id":"1.229554906","rc":[{"atb":[[9,8.71],[7.4,0]],"id":42269942}],"con":true,"img":false}]}
{"op":"mcm","clk":"11450234741","pt":1717319455778,"mc":[{"id":"1.229554906","rc":[{"atb":[[7.2,0],[2.9,31.91],[6.2,0],[3.55,16.41]],"id":42269942},{"atl":[[250,1]],"id":42269942},{"atl":[[5.2,0],[8.4,5.65]],"id":61631980},{"atl":[[7.4,0]],"id":61631978}],"con":true,"img":false}]}
{"op":"mcm","clk":"11450234753","pt":1717319455881,"mc":[{"id":"1.229554906","rc":[{"atl":[[38,2.61]],"id":42269942},{"atl":[[8.4,9.41]],"id":61631978}],"con":true,"img":false}]}
{"op":"mcm","clk":"11450234759","pt":1717319455985,"mc":[{"id":"1.229554906","rc":[{"atb":[[1.67,0]],"id":61631980}],"con":true,"img":false}]}
{"op":"mcm","clk":"11450234776","pt":1717319456189,"mc":[{"id":"1.229554906","rc":[{"atb":[[1.68,5.77]],"id":61631980}],"con":true,"img":false}]}
{"op":"mcm","clk":"11450234862","pt":1717319457083,"mc":[{"id":"1.229554906","rc":[{"atb":[[3.2,4.68]],"id":42269942}],"con":true,"img":false}]}
{"op":"mcm","clk":"11450234873","pt":1717319457096,"mc":[{"id":"1.229554906","rc":[{"atb":[[1.44,9.36]],"id":61631980}],"con":true,"img":false}]}
{"op":"mcm","clk":"11450235150","pt":1717319459987,"mc":[{"id":"1.229554906","rc":[{"trd":[[38,5.23]],"ltp":38.0,"tv":5.23,"id":42269942},{"atl":[[38,0]],"id":42269942}],"con":true,"img":false}]}
{"op":"mcm","clk":"11450235231","pt":1717319460975,"mc":[{"id":"1.229554906","rc":[{"atl":[[320,1],[230,0]],"id":42269942},{"atl":[[3.2,34.09]],"id":61631980},{"atl":[[5.1,0],[2.5,0],[5.3,0],[2.52,13.16],[2.46,0],[4.9,0]],"id":61631978}],"con":true,"img":false}]}
{"op":"mcm","clk":"11450235340","pt":1717319462168,"mc":[{"id":"1.229554906","rc":[{"atb":[[1.44,0]],"id":61631980}],"con":true,"img":false}]}
{"op":"mcm","clk":"11450235682","pt":1717319465795,"mc":[{"id":"1.229554906","rc":[{"atl":[[180,2.06]],"id":42269942},{"atb":[[1.95,0]],"id":57451148},{"atl":[[14.5,4.7]],"id":57451148},{"atb":[[1.38,0]],"id":61631980},{"atb":[[1.35,171.07]],"id":61631978},{"atl":[[5.2,0]],"id":61631978}],"con":true,"img":false}]}
{"op":"mcm","clk":"11450235688","pt":1717319465892,"mc":[{"id":"1.229554906","rc":[{"atb":[[1.8,67.48],[2.28,0]],"id":57451148},{"atl":[[30,0]],"id":57451148},{"atb":[[1.07,0]],"id":60780007},{"atb":[[1.33,142.15],[1.65,0]],"id":61631980},{"atb":[[1.28,0],[1.42,0]],"id":61631978},{"atl":[[8.2,13.89],[6.6,7.21]],"id":61631978}],"con":true,"img":false}]}
{"op":"mcm","clk":"11450235696","pt":1717319466000,"mc":[{"id":"1.229554906","rc":[{"atb":[[1.41,24.45]],"id":61631978},{"atl":[[5.9,0.1]],"id":61631978}],"con":true,"img":false}]}
{"op":"mcm","clk":"11450235707","pt":1717319466204,"mc":[{"id":"1.229554906","rc":[{"atb":[[1.41,22.33]],"id":61631978}],"con":true,"img":false}]}
{"op":"mcm","clk":"11450236092","pt":1717319470702,"mc":[{"id":"1.229554906","rc":[{"atb":[[2.98,0]],"id":57451148}],"con":true,"img":false}]}
{"op":"mcm","clk":"11450236126","pt":1717319471013,"mc":[{"id":"1.229554906","rc":[{"atl":[[270,0],[290,0],[320,0],[250,0]],"id":42269942},{"atl":[[3.3,54.35]],"id":61631980},{"atl":[[2.56,32.05]],"id":61631978}],"con":true,"img":false}]}
{"op":"mcm","clk":"11450236137","pt":1717319471117,"mc":[{"id":"1.229554906","rc":[{"atb":[[1.41,12.76]],"id":61631978}],"con":true,"img":false}]}
{"op":"mcm","clk":"11450236159","pt":1717319471277,"mc":[{"id":"1.229554906","rc":[{"atb":[[1.66,5.95]],"id":61631978}],"con":true,"img":false}]}
{"op":"mcm","clk":"11450236229","pt":1717319471999,"mc":[{"id":"1.229554906","rc":[{"atl":[[60,5]],"id":60780007},{"atl":[[60,5]],"id":61631980},{"atl":[[60,5]],"id":61631978}],"con":true,"img":false}]}
{"op":"mcm","clk":"11450236273","pt":1717319472413,"mc":[{"id":"1.229554906","rc":[{"atl":[[8.2,0],[5.9,20.51]],"id":61631978}],"con":true,"img":false}]}
{"op":"mcm","clk":"11450236488","pt":1717319474883,"mc":[{"id":"1.229554906","rc":[{"atb":[[9,2.9],[6,16.41]],"id":42269942},{"atb":[[1.05,1522.15],[1.04,0]],"id":60780007}],"con":true,"img":false}]}
{"op":"mcm","clk":"11450236496","pt":1717319474991,"mc":[{"id":"1.229554906","rc":[{"atb":[[1.05,1437.61]],"id":60780007}],"con":true,"img":false}]}
{"op":"mcm","clk":"11450236567","pt":1717319475816,"mc":[{"id":"1.229554906","rc":[{"atl":[[120,0]],"id":42269942},{"atl":[[8.8,5.36]],"id":57451148}],"con":true,"img":false}]}
{"op":"mcm","clk":"11450236574","pt":1717319475916,"mc":[{"id":"1.229554906","rc":[{"atb":[[3.2,0]],"id":42269942},{"atl":[[44,0.35]],"id":42269942},{"atl":[[16,0]],"id":57451148}],"con":true,"img":false}]}
{"op":"mcm","clk":"11450236820","pt":1717319478709,"mc":[{"id":"1.229554906","rc":[{"atb":[[1.41,0]],"id":61631978}],"con":true,"img":false}]}
{"op":"mcm","clk":"11450236982","pt":1717319480829,"mc":[{"id":"1.229554906","rc":[{"atl":[[2.6,46.88]],"id":61631978}],"con":true,"img":false}]}
{"op":"mcm","clk":"11450237360","pt":1717319485126,"mc":[{"id":"1.229554906","rc":[{"atb":[[3.7,4.68]],"id":42269942}],"con":true,"img":false}]}
{"op":"mcm","clk":"11450237414","pt":1717319485700,"mc":[{"id":"1.229554906","rc":[{"atb":[[9.2,3.41]],"id":42269942},{"atl":[[240,0.06]],"id":42269942},{"atl":[[14,3.21]],"id":57451148},{"atl":[[1.96,41.85]],"id":60780007},{"atl":[[4.9,10.73]],"id":61631980},{"atb":[[1.26,230.19]],"id":61631978}],"con":true,"img":false}]}
{"op":"mcm","clk":"11450237423","pt":1717319485806,"mc":[{"id":"1.229554906","rc":[{"atb":[[3.55,0]],"id":42269942},{"atl":[[44,0],[180,0]],"id":42269942},{"atl":[[8.8,0]],"id":57451148},{"atl":[[2.92,0]],"id":60780007},{"atl":[[8.4,0]],"id":61631980},{"atb":[[1.35,0]],"id":61631978}],"con":true,"img":false}]}
{"op":"mcm","clk":"11450237431","pt":1717319485910,"mc":[{"id":"1.229554906","rc":[{"atl":[[280,2.06]],"id":42269942}],"con":true,"img":false}]}
{"op":"mcm","clk":"11450237445","pt":1717319486011,"mc":[{"id":"1.229554906","rc":[{"atb":[[3.7,0]],"id":42269942}],"con":true,"img":false}]}
{"op":"mcm","clk":"11450237518","pt":1717319486936,"mc":[{"id":"1.229554906","rc":[{"atb":[[1.47,9.36]],"id":61631980}],"con":true,"img":false}]}
{"op":"mcm","clk":"11450237872","pt":1717319490513,"mc":[{"id":"1.229554906","rc":[{"atl":[[2.64,76.22]],"id":61631978}],"con":true,"img":false}]}
{"op":"mcm","clk":"11450237970","pt":1717319491807,"mc":[{"id":"1.229554906","rc":[{"atb":[[1.55,7.74]],"id":61631978}],"con":true,"img":false}]}
{"op":"mcm","clk":"11450237986","pt":1717319492016,"mc":[{"id":"1.229554906","rc":[{"atb":[[1.67,6.35]],"id":61631980}],"con":true,"img":false}]}
{"op":"mcm","clk":"11450238007","pt":1717319492231,"mc":[{"id":"1.229554906","rc":[{"atb":[[1.47,0]],"id":61631980}],"con":true,"img":false}]}
{"op":"mcm","clk":"11450238338","pt":1717319495807,"mc":[{"id":"1.229554906","rc":[{"spn":124.6,"spf":"NaN","id":42269942},{"atl":[[14.5,0]],"id":57451148},{"spn":1.29,"spf":"NaN","id":60780007},{"spn":2.37,"spf":"NaN","id":61631980},{"spn":2.09,"spf":"NaN","id":61631978}],"con":true,"img":false}]}
{"op":"mcm","clk":"11450238347","pt":1717319495920,"mc":[{"id":"1.229554906","rc":[{"atl":[[17,4.7]],"id":57451148}],"con":true,"img":false}]}
{"op":"mcm","clk":"11450238503","pt":1717319497923,"mc":[{"id":"1.229554906","rc":[{"atl":[[320,1],[340,1],[360,1],[380,1]],"id":42269942}],"con":true,"img":false}]}
{"op":"mcm","clk":"11450238814","pt":1717319501337,"mc":[{"id":"1.229554906","rc":[{"atb":[[1.05,1522.15]],"id":60780007}],"con":true,"img":false}]}
{"op":"mcm","clk":"11450239191","pt":1717319505727,"mc":[{"id":"1.229554906","rc":[{"atb":[[7.8,8.89]],"id":42269942},{"atl":[[280,2.61]],"id":42269942},{"atb":[[2.88,10.15]],"id":57451148},{"atl":[[2.26,47.12]],"id":60780007},{"atl":[[6,9.64]],"id":61631980},{"atl":[[4.1,13.5],[4.9,15.17]],"id":61631978}],"con":true,"img":false}]}
{"op":"mcm","clk":"11450239203","pt":1717319505831,"mc":[{"id":"1.229554906","rc":[{"atb":[[2.9,0]],"id":42269942},{"atl":[[3.5,0]],"id":60780007},{"atl":[[9.4,0]],"id":61631980},{"atl":[[6.6,0],[8.4,0]],"id":61631978}],"con":true,"img":false}]}
{"op":"mcm","clk":"11450239338","pt":1717319507320,"mc":[{"id":"1.229554906","rc":[{"atl":[[320,0],[230,1]],"id":42269942}],"con":true,"img":false}]}
{"op":"mcm","clk":"11450239902","pt":1717319513366,"mc":[{"id":"1.229554906","rc":[{"atl":[[2.52,0],[2.46,13.7]],"id":61631978}],"con":true,"img":false}]}
{"op":"mcm","clk":"11450240209","pt":1717319516584,"mc":[{"id":"1.229554906","rc":[{"atl":[[250,1]],"id":42269942}],"con":true,"img":false}]}
{"op":"mcm","clk":"11450240755","pt":1717319522451,"mc":[{"id":"1.229554906","rc":[{"atl":[[2.5,33.33]],"id":61631978}],"con":true,"img":false}]}
{"op":"mcm","clk":"11450240882","pt":1717319523585,"mc":[{"id":"1.229554906","rc":[{"atb":[[1.05,1272.15],[1.04,250]],"id":60780007}],"con":true,"img":false}]}
{"op":"mcm","clk":"11450241101","pt":1717319525600,"mc":[{"id":"1.229554906","rc":[{"atl":[[270,1],[340,0],[360,0],[380,0]],"id":42269942}],"con":true,"img":false}]}
{"op":"mcm","clk":"11450241123","pt":1717319525820,"mc":[{"id":"1.229554906","rc":[{"atl":[[210,0.09],[240,0]],"id":42269942},{"atb":[[1.8,0]],"id":57451148}],"con":true,"img":false}]}
{"op":"mcm","clk":"11450241133","pt":1717319525965,"mc":[{"id":"1.229554906","rc":[{"atb":[[2.08,67.48]],"id":57451148}],"con":true,"img":false}]}
{"op":"mcm","clk":"11450241333","pt":1717319528137,"mc":[{"id":"1.229554906","rc":[{"atb":[[1.05,1522.15],[1.04,0]],"id":60780007}],"con":true,"img":false}]}
{"op":"mcm","clk":"11450241627","pt":1717319531214,"mc":[{"id":"1.229554906","rc":[{"atb":[[1.68,0]],"id":61631980}],"con":true,"img":false}]}
{"op":"mcm","clk":"11450241647","pt":1717319531419,"mc":[{"id":"1.229554906","rc":[{"atl":[[2.56,0],[2.54,48.7],[2.6,0],[2.64,0]],"id":61631978}],"con":true,"img":false}]}
{"op":"mcm","clk":"11450241677","pt":1717319531730,"mc":[{"id":"1.229554906","rc":[{"atb":[[1.05,1272.15],[1.04,250]],"id":60780007}],"con":true,"img":false}]}
{"op":"mcm","clk":"11450241851","pt":1717319533542,"mc":[{"id":"1.229554906","rc":[{"atb":[[1.05,1522.15],[1.04,0]],"id":60780007}],"con":true,"img":false}]}
{"op":"mcm","clk":"11450241949","pt":1717319534525,"mc":[{"id":"1.229554906","rc":[{"atl":[[290,1]],"id":42269942}],"con":true,"img":false}]}
{"op":"mcm","clk":"11450241964","pt":1717319534731,"mc":[{"id":"1.229554906","rc":[{"atb":[[2.12,3.8]],"id":57451148}],"con":true,"img":false}]}
{"op":"mcm","clk":"11450242161","pt":1717319536939,"mc":[{"id":"1.229554906","rc":[{"atb":[[2.78,6.26]],"id":57451148}],"con":true,"img":false}]}
{"op":"mcm","clk":"11450242211","pt":1717319537459,"mc":[{"id":"1.229554906","rc":[{"atb":[[1.05,1272.15],[1.04,250]],"id":60780007}],"con":true,"img":false}]}
{"op":"mcm","clk":"11450242308","pt":1717319538449,"mc":[{"id":"1.229554906","rc":[{"atb":[[1.56,9.36]],"id":61631980}],"con":true,"img":false}]}
{"op":"mcm","clk":"11450242364","pt":1717319539018,"mc":[{"id":"1.229554906","rc":[{"atb":[[1.05,1522.15],[1.04,0]],"id":60780007}],"con":true,"img":false}]}
{"op":"mcm","clk":"11450242472","pt":1717319540216,"mc":[{"id":"1.229554906","rc":[{"atl":[[2.58,79.11]],"id":61631978}],"con":true,"img":false}]}
{"op":"mcm","clk":"11450242678","pt":1717319542448,"mc":[{"id":"1.229554906","rc":[{"atb":[[1.05,1272.15],[1.04,250]],"id":60780007}],"con":true,"img":false}]}
{"op":"mcm","clk":"11450242728","pt":1717319542969,"mc":[{"id":"1.229554906","rc":[{"atl":[[220,1],[230,0]],"id":42269942},{"atl":[[2.46,0],[2.48,13.51]],"id":61631978}],"con":true,"img":false}]}
{"op":"mcm","clk":"11450242857","pt":1717319544375,"mc":[{"id":"1.229554906","rc":[{"atl":[[220,0],[230,1]],"id":42269942},{"atb":[[1.05,1522.15],[1.04,0]],"id":60780007},{"atl":[[2.46,13.7],[2.48,0]],"id":61631978}],"con":true,"img":false}]}
{"op":"mcm","clk":"11450242897","pt":1717319544738,"mc":[{"id":"1.229554906","rc":[{"atb":[[1.05,1272.15],[1.04,250]],"id":60780007}],"con":true,"img":false}]}
{"op":"mcm","clk":"11450242910","pt":1717319544842,"mc":[{"id":"1.229554906","rc":[{"atl":[[220,1],[230,0]],"id":42269942},{"atl":[[2.46,0],[2.48,13.51]],"id":61631978}],"con":true,"img":false}]}
{"op":"mcm","clk":"11450242922","pt":1717319544944,"mc":[{"id":"1.229554906","rc":[{"atl":[[220,0],[230,1]],"id":42269942},{"atl":[[2.46,13.7],[2.48,0]],"id":61631978}],"con":true,"img":false}]}
{"op":"mcm","clk":"11450243951","pt":1717319555750,"mc":[{"id":"1.229554906","rc":[{"atl":[[280,0],[220,2.61]],"id":42269942}],"con":true,"img":false}]}
{"op":"mcm","clk":"11450244056","pt":1717319556844,"mc":[{"id":"1.229554906","rc":[{"atl":[[220,3.61],[230,0]],"id":42269942},{"spn":109.6,"spf":"NaN","id":42269942},{"atl":[[2.48,13.51]],"id":61631978},{"spn":2.06,"spf":"NaN","id":61631978}],"con":true,"img":false}]}
{"op":"mcm","clk":"11450244062","pt":1717319556948,"mc":[{"id":"1.229554906","rc":[{"atl":[[2.46,0]],"id":61631978}],"con":true,"img":false}]}
{"op":"mcm","clk":"11450244160","pt":1717319558078,"mc":[{"id":"1.229554906","rc":[{"atl":[[220,2.61],[230,1]],"id":42269942},{"atl":[[2.46,13.7],[2.48,0]],"id":61631978}],"con":true,"img":false}]}
{"op":"mcm","clk":"11450244193","pt":1717319558443,"mc":[{"id":"1.229554906","rc":[{"atl":[[220,3.61],[230,0]],"id":42269942},{"atl":[[2.46,0],[2.48,13.51]],"id":61631978}],"con":true,"img":false}]}
{"op":"mcm","clk":"11450244244","pt":1717319558960,"mc":[{"id":"1.229554906","rc":[{"atl":[[220,2.61],[230,1]],"id":42269942},{"atl":[[2.46,13.7],[2.48,0]],"id":61631978}],"con":true,"img":false}]}
{"op":"mcm","clk":"11450244371","pt":1717319560252,"mc":[{"id":"1.229554906","rc":[{"atl":[[220,3.61]],"id":42269942},{"atl":[[2.48,13.51]],"id":61631978}],"con":true,"img":false}]}
{"op":"mcm","clk":"11450244381","pt":1717319560354,"mc":[{"id":"1.229554906","rc":[{"atl":[[230,0]],"id":42269942},{"atl":[[2.46,0]],"id":61631978}],"con":true,"img":false}]}
{"op":"mcm","clk":"11450244408","pt":1717319560666,"mc":[{"id":"1.229554906","rc":[{"atl":[[220,2.61],[230,1]],"id":42269942},{"atl":[[2.46,13.7],[2.48,0]],"id":61631978}],"con":true,"img":false}]}
{"op":"mcm","clk":"11450244471","pt":1717319561495,"mc":[{"id":"1.229554906","rc":[{"atl":[[220,3.61],[230,0]],"id":42269942},{"atl":[[2.46,0],[2.48,13.51]],"id":61631978}],"con":true,"img":false}]}
{"op":"mcm","clk":"11450244928","pt":1717319566413,"mc":[{"id":"1.229554906","rc":[{"atb":[[7.2,16.13],[8.2,2.5],[7.4,5],[6,0],[9.4,4.73]],"id":42269942},{"atl":[[80,5],[200,0.4],[220,4.61],[230,1],[60,2.5]],"id":42269942},{"atb":[[1.55,0],[2.22,41.4]],"id":57451148},{"atl":[[8.6,19.75],[9,25.62],[8.2,11.94],[7.4,2.5],[7.6,12.12],[7.8,0],[7,3.33],[15,0]],"id":57451148},{"atb":[[1.02,268.87],[1.06,5],[1.1,2.5],[1.05,1556.63]],"id":60780007},{"atl":[[2.02,98.04],[1.54,2.74],[3.7,0],[1.93,21.51]],"id":60780007},{"atb":[[1.98,5],[1.74,72.79],[2.04,2.5],[1.94,10],[1.75,31.39]],"id":61631980},{"atl":[[4,6.67],[3.2,0],[4.6,27.78],[3.1,0],[3,1],[6.8,0.08]],"id":61631980},{"atb":[[1.25,73.74]],"id":61631978},{"atl":[[2.5,82.03],[2.46,13.7],[5.9,0.1],[2.48,15.94]],"id":61631978}],"con":true,"img":false}]}
{"op":"mcm","clk":"11450244937","pt":1717319566470,"mc":[{"id":"1.229554906","rc":[{"atb":[[1.05,1472.09]],"id":60780007},{"atb":[[1.56,0]],"id":61631980}],"con":true,"img":false}]}
{"op":"mcm","clk":"11450244947","pt":1717319566580,"mc":[{"id":"1.229554906","rc":[{"atl":[[200,2.4],[220,2.61]],"id":42269942},{"atl":[[8.6,9.87],[7.6,19.06]],"id":57451148},{"atl":[[1.56,0],[1.54,0]],"id":60780007},{"atb":[[1.83,31.39],[1.75,0]],"id":61631980},{"atl":[[3,0],[3.3,0]],"id":61631980}],"con":true,"img":false}]}
{"op":"mcm","clk":"11450244959","pt":1717319566682,"mc":[{"id":"1.229554906","rc":[{"atl":[[1.56,15.52]],"id":60780007},{"atl":[[4.5,13.34],[4.6,0],[3.3,8.75]],"id":61631980}],"con":true,"img":false}]}
{"op":"mcm","clk":"11450244969","pt":1717319566781,"mc":[{"id":"1.229554906","rc":[{"atl":[[5.1,2.5],[5.5,5],[3.3,0],[5.9,10]],"id":61631980}],"con":true,"img":false}]}
{"op":"mcm","clk":"11450244979","pt":1717319566886,"mc":[{"id":"1.229554906","rc":[{"atl":[[1.56,0]],"id":60780007},{"atl":[[4.5,22.09]],"id":61631980}],"con":true,"img":false}]}
{"op":"mcm","clk":"11450244989","pt":1717319566988,"mc":[{"id":"1.229554906","rc":[{"atl":[[1.58,156.21]],"id":60780007}],"con":true,"img":false}]}
{"op":"mcm","clk":"11450245016","pt":1717319567298,"mc":[{"id":"1.229554906","rc":[{"atl":[[220,3.61],[230,0]],"id":42269942},{"atl":[[1.58,26.9]],"id":60780007},{"atl":[[2.46,0],[2.48,29.45]],"id":61631978}],"con":true,"img":false}]}
{"op":"mcm","clk":"11450245026","pt":1717319567402,"mc":[{"id":"1.229554906","rc":[{"atl":[[210,1.09]],"id":42269942},{"atl":[[1.58,0]],"id":60780007},{"atl":[[2.5,33.33],[2.46,48.7]],"id":61631978}],"con":true,"img":false}]}
{"op":"mcm","clk":"11450245037","pt":1717319567513,"mc":[{"id":"1.229554906","rc":[{"atl":[[220,2.61]],"id":42269942},{"atl":[[1.6,0]],"id":60780007}],"con":true,"img":false}]}
{"op":"mcm","clk":"11450245047","pt":1717319567559,"mc":[{"id":"1.229554906","rc":[{"atb":[[1.05,1505.23]],"id":60780007},{"atl":[[1.6,19.88],[1.97,83.7]],"id":60780007},{"atl":[[2.5,100],[2.46,0]],"id":61631978}],"con":true,"img":false}]}
{"op":"mcm","clk":"11450245054","pt":1717319567717,"mc":[{"id":"1.229554906","rc":[{"atl":[[1.6,0],[2.02,0]],"id":60780007},{"atl":[[2.54,113.64],[2.5,33.33]],"id":61631978}],"con":true,"img":false}]}
{"op":"mcm","clk":"11450245066","pt":1717319567767,"mc":[{"id":"1.229554906","rc":[{"atl":[[1.93,52.55]],"id":60780007}],"con":true,"img":false}]}
{"op":"mcm","clk":"11450245132","pt":1717319568487,"mc":[{"id":"1.229554906","rc":[{"atl":[[2.02,9.84]],"id":60780007}],"con":true,"img":false}]}
{"op":"mcm","clk":"11450245430","pt":1717319571691,"mc":[{"id":"1.229554906","rc":[{"atb":[[2.12,0]],"id":57451148},{"atb":[[1.67,0]],"id":61631980},{"atb":[[1.55,0]],"id":61631978}],"con":true,"img":false}]}
{"op":"mcm","clk":"11450245441","pt":1717319571797,"mc":[{"id":"1.229554906","rc":[{"atl":[[4.8,26.32]],"id":61631980},{"atb":[[1.28,5],[1.32,2.5]],"id":61631978}],"con":true,"img":false}]}
{"op":"mcm","clk":"11450245448","pt":1717319571896,"mc":[{"id":"1.229554906","rc":[{"atl":[[4.5,8.75]],"id":61631980}],"con":true,"img":false}]}
{"op":"mcm","clk":"11450245611","pt":1717319573807,"mc":[{"id":"1.229554906","rc":[{"atb":[[1.44,12.76]],"id":61631978}],"con":true,"img":false}]}
{"op":"mcm","clk":"11450245690","pt":1717319574589,"mc":[{"id":"1.229554906","rc":[{"atl":[[7.4,10.31]],"id":57451148},{"atl":[[1.95,52.63]],"id":60780007},{"atl":[[4.2,15.62]],"id":61631980}],"con":true,"img":false}]}
{"op":"mcm","clk":"11450245702","pt":1717319574687,"mc":[{"id":"1.229554906","rc":[{"atl":[[7.2,11.94]],"id":57451148},{"atl":[[2.02,0]],"id":60780007}],"con":true,"img":false}]}
{"op":"mcm","clk":"11450245710","pt":1717319574790,"mc":[{"id":"1.229554906","rc":[{"atl":[[7.2,0],[7.4,22.25],[7.6,12.12]],"id":57451148}],"con":true,"img":false}]}
{"op":"mcm","clk":"11450245732","pt":1717319575007,"mc":[{"id":"1.229554906","rc":[{"atl":[[7.4,10.31],[7.6,27.27]],"id":57451148}],"con":true,"img":false}]}
{"op":"mcm","clk":"11450245793","pt":1717319575617,"mc":[{"id":"1.229554906","rc":[{"atb":[[1.66,0]],"id":61631978}],"con":true,"img":false}]}
{"op":"mcm","clk":"11450245807","pt":1717319575736,"mc":[{"id":"1.229554906","rc":[{"atl":[[230,1]],"id":42269942}],"con":true,"img":false}]}
{"op":"mcm","clk":"11450245818","pt":1717319575778,"mc":[{"id":"1.229554906","rc":[{"atl":[[220,0]],"id":42269942},{"atb":[[1.84,97.65],[2.08,0]],"id":57451148},{"atl":[[17,0],[24,17.54]],"id":57451148},{"atl":[[3.15,90.27],[2.26,0]],"id":60780007},{"atl":[[9.4,46.28],[6,0]],"id":61631980},{"atb":[[1.26,0]],"id":61631978},{"atl":[[4.9,0],[6.6,53.19]],"id":61631978}],"con":true,"img":false}]}
{"op":"mcm","clk":"11450245829","pt":1717319575883,"mc":[{"id":"1.229554906","rc":[{"atl":[[240,2.61]],"id":42269942},{"atb":[[2.78,0]],"id":57451148},{"atb":[[1.2,230.19],[1.44,0]],"id":61631978}],"con":true,"img":false}]}
{"op":"mcm","clk":"11450245837","pt":1717319576008,"mc":[{"id":"1.229554906","rc":[{"atb":[[2.3,10],[2.38,5],[2.46,2.5]],"id":57451148}],"con":true,"img":false}]}
{"op":"mcm","clk":"11450245935","pt":1717319577008,"mc":[{"id":"1.229554906","rc":[{"atb":[[2.72,6.26]],"id":57451148}],"con":true,"img":false}]}
{"op":"mcm","clk":"11450245962","pt":1717319577219,"mc":[{"id":"1.229554906","rc":[{"atl":[[4.8,0],[4.5,31.04]],"id":61631980}],"con":true,"img":false}]}
{"op":"mcm","clk":"11450246042","pt":1717319578199,"mc":[{"id":"1.229554906","rc":[{"atl":[[55,1.48]],"id":42269942},{"atl":[[6.8,13.79]],"id":57451148},{"atb":[[1.1,73.3]],"id":60780007},{"atb":[[2.04,15]],"id":61631980},{"atl":[[4,19.17]],"id":61631980}],"con":true,"img":false}]}
{"op":"mcm","clk":"11450246051","pt":1717319578301,"mc":[{"id":"1.229554906","rc":[{"atl":[[130,2]],"id":42269942},{"atl":[[7,20]],"id":57451148}],"con":true,"img":false}]}
{"op":"mcm","clk":"11450246060","pt":1717319578404,"mc":[{"id":"1.229554906","rc":[{"atl":[[200,0]],"id":42269942},{"atl":[[7.6,0]],"id":57451148},{"atb":[[1.05,1220.75]],"id":60780007},{"atb":[[1.74,31.39]],"id":61631980},{"atl":[[4.5,22.29]],"id":61631980}],"con":true,"img":false}]}
{"op":"mcm","clk":"11450246326","pt":1717319581619,"mc":[{"id":"1.229554906","rc":[{"atl":[[290,0]],"id":42269942},{"atl":[[9,10]],"id":57451148}],"con":true,"img":false}]}
{"op":"mcm","clk":"11450246399","pt":1717319582305,"mc":[{"id":"1.229554906","rc":[{"atb":[[9,0],[7,0]],"id":42269942},{"atb":[[2.86,0],[3.15,0]],"id":57451148},{"atb":[[1.01,250]],"id":60780007},{"atl":[[2.3,0]],"id":60780007},{"atb":[[1.64,0],[1.74,0]],"id":61631980},{"atl":[[6.8,0]],"id":61631980},{"atb":[[1.63,0],[1.53,0]],"id":61631978},{"atl":[[5.9,0]],"id":61631978}],"con":true,"img":false}]}
{"op":"mcm","clk":"11450246413","pt":1717319582512,"mc":[{"id":"1.229554906","rc":[{"atb":[[2.72,0]],"id":57451148},{"atb":[[1.32,49.58]],"id":61631978}],"con":true,"img":false}]}
{"op":"mcm","clk":"11450246436","pt":1717319582743,"mc":[{"id":"1.229554906","rc":[{"atb":[[2.72,11.63],[2.64,45.73],[2.6,78.12],[2.68,29.76]],"id":57451148},{"atl":[[7.8,11.03]],"id":57451148},{"atl":[[1.97,161.02]],"id":60780007},{"atb":[[1.56,35.71],[1.54,92.59],[1.5,250],[1.52,144.23]],"id":61631980},{"atl":[[4.4,22.06]],"id":61631980}],"con":true,"img":false}]}
{"op":"mcm","clk":"11450246524","pt":1717319583418,"mc":[{"id":"1.229554906","rc":[{"atl":[[7.4,25.93]],"id":57451148}],"con":true,"img":false}]}
{"op":"mcm","clk":"11450246534","pt":1717319583521,"mc":[{"id":"1.229554906","rc":[{"atl":[[7,3.33]],"id":57451148}],"con":true,"img":false}]}
{"op":"mcm","clk":"11450246602","pt":1717319584301,"mc":[{"id":"1.229554906","rc":[{"atb":[[2.88,0]],"id":57451148},{"atb":[[1.05,296.47]],"id":60780007}],"con":true,"img":false}]}
{"op":"mcm","clk":"11450246611","pt":1717319584404,"mc":[{"id":"1.229554906","rc":[{"atb":[[2.72,41.42]],"id":57451148}],"con":true,"img":false}]}
{"op":"mcm","clk":"11450246753","pt":1717319585814,"mc":[{"id":"1.229554906","rc":[{"atl":[[4.9,0],[7,6.97]],"id":61631980}],"con":true,"img":false}]}
{"op":"mcm","clk":"11450246877","pt":1717319587310,"mc":[{"id":"1.229554906","rc":[{"atl":[[2.02,98.04],[1.97,77.32]],"id":60780007},{"atl":[[4.5,0],[4.6,27.78]],"id":61631980}],"con":true,"img":false}]}
{"op":"mcm","clk":"11450247040","pt":1717319589220,"mc":[{"id":"1.229554906","rc":[{"atb":[[1.05,347.87]],"id":60780007}],"con":true,"img":false}]}
{"op":"mcm","clk":"11450247057","pt":1717319589430,"mc":[{"id":"1.229554906","rc":[{"atl":[[8.6,0]],"id":57451148}],"con":true,"img":false}]}
{"op":"mcm","clk":"11450247063","pt":1717319589532,"mc":[{"id":"1.229554906","rc":[{"atb":[[1.36,138.89],[1.32,299.58],[1.34,220.59],[1.38,52.63]],"id":61631978}],"con":true,"img":false}]}
{"op":"mcm","clk":"11450247158","pt":1717319590728,"mc":[{"id":"1.229554906","rc":[{"atl":[[1.99,126.26]],"id":60780007},{"atl":[[4.6,62.5]],"id":61631980}],"con":true,"img":false}]}
{"op":"mcm","clk":"11450247464","pt":1717319594030,"mc":[{"id":"1.229554906","rc":[{"atb":[[1.38,148.37]],"id":61631978}],"con":true,"img":false}]}
{"op":"mcm","clk":"11450247477","pt":1717319594238,"mc":[{"id":"1.229554906","rc":[{"atb":[[1.32,252.5]],"id":61631978}],"con":true,"img":false}]}
{"op":"mcm","clk":"11450247591","pt":1717319595533,"mc":[{"id":"1.229554906","rc":[{"atb":[[6.4,6.45],[8.4,3.13]],"id":42269942},{"atb":[[3.2,10.55],[2.88,18.53]],"id":57451148},{"atb":[[1.01,6057.26]],"id":60780007},{"atl":[[2.3,0.4]],"id":60780007},{"atb":[[1.73,31.81],[1.63,55.3]],"id":61631980},{"atl":[[6.8,0.08]],"id":61631980},{"atb":[[1.64,36.29],[1.54,64.52]],"id":61631978},{"atl":[[6,0.1]],"id":61631978}],"con":true,"img":false}]}
{"op":"mcm","clk":"11450247627","pt":1717319595842,"mc":[{"id":"1.229554906","rc":[{"atb":[[9.2,0]],"id":42269942},{"atl":[[210,1]],"id":42269942},{"atl":[[14,0]],"id":57451148}],"con":true,"img":false}]}
{"op":"mcm","clk":"11450247637","pt":1717319595949,"mc":[{"id":"1.229554906","rc":[{"atb":[[9.6,3.41],[9.4,0]],"id":42269942},{"atl":[[12.5,3.21]],"id":57451148}],"con":true,"img":false}]}
{"op":"mcm","clk":"11450247646","pt":1717319596003,"mc":[{"id":"1.229554906","rc":[{"atb":[[9,4.23]],"id":42269942}],"con":true,"img":false}]}
{"op":"mcm","clk":"11450247865","pt":1717319598412,"mc":[{"id":"1.229554906","rc":[{"atl":[[2.02,0],[1.97,180.41]],"id":60780007},{"atl":[[4.5,28.57],[4.6,34.72]],"id":61631980}],"con":true,"img":false}]}
{"op":"mcm","clk":"11450247893","pt":1717319598827,"mc":[{"id":"1.229554906","rc":[{"atl":[[7.2,3.23],[7,0]],"id":57451148},{"atb":[[1.56,0],[1.54,0],[1.52,0]],"id":61631980},{"atl":[[2.54,77.93],[2.48,15.94]],"id":61631978}],"con":true,"img":false}]}
{"op":"mcm","clk":"11450247899","pt":1717319598928,"mc":[{"id":"1.229554906","rc":[{"atl":[[6.8,0]],"id":57451148}],"con":true,"img":false}]}
{"op":"mcm","clk":"11450247906","pt":1717319599026,"mc":[{"id":"1.229554906","rc":[{"atl":[[7.4,10.31],[7.8,25.74],[7,13.33]],"id":57451148}],"con":true,"img":false}]}
{"op":"mcm","clk":"11450248306","pt":1717319604137,"mc":[{"id":"1.229554906","rc":[{"atl":[[6.4,3.7]],"id":57451148}],"con":true,"img":false}]}
{"op":"mcm","clk":"11450248312","pt":1717319604241,"mc":[{"id":"1.229554906","rc":[{"atl":[[7.2,0],[7.4,25.93],[7.8,11.03]],"id":57451148},{"atl":[[2.5,0]],"id":61631978}],"con":true,"img":false}]}
{"op":"mcm","clk":"11450248322","pt":1717319604348,"mc":[{"id":"1.229554906","rc":[{"atl":[[3.35,2.5],[2.58,142.4],[3.55,5],[3.75,10]],"id":61631978}],"con":true,"img":false}]}
{"op":"mcm","clk":"11450248331","pt":1717319604449,"mc":[{"id":"1.229554906","rc":[{"atl":[[2.54,12.99],[2.48,0]],"id":61631978}],"con":true,"img":false}]}
{"op":"mcm","clk":"11450248341","pt":1717319604507,"mc":[{"id":"1.229554906","rc":[{"atl":[[2.52,52.63],[2.58,79.11],[2.98,50.51]],"id":61631978}],"con":true,"img":false}]}
{"op":"mcm","clk":"11450248437","pt":1717319605846,"mc":[{"id":"1.229554906","rc":[{"atb":[[9.6,0],[7.8,14.02]],"id":42269942}],"con":true,"img":false}]}
{"op":"mcm","clk":"11450248445","pt":1717319605948,"mc":[{"id":"1.229554906","rc":[{"atb":[[9.2,3.41]],"id":42269942}],"con":true,"img":false}]}
{"op":"mcm","clk":"11450248457","pt":1717319606012,"mc":[{"id":"1.229554906","rc":[{"atb":[[9,0],[9.4,4.91]],"id":42269942}],"con":true,"img":false}]}
{"op":"mcm","clk":"11450248506","pt":1717319606531,"mc":[{"id":"1.229554906","rc":[{"atl":[[2.58,31.65]],"id":61631978}],"con":true,"img":false}]}
{"op":"mcm","clk":"11450248516","pt":1717319606632,"mc":[{"id":"1.229554906","rc":[{"atb":[[1.05,263.33]],"id":60780007}],"con":true,"img":false}]}
{"op":"mcm","clk":"11450248793","pt":1717319609630,"mc":[{"id":"1.229554906","rc":[{"atb":[[1.38,117.35]],"id":61631980},{"atb":[[1.26,157.64]],"id":61631978},{"atl":[[2.58,94.94],[2.98,0]],"id":61631978}],"con":true,"img":false}]}
{"op":"mcm","clk":"11450248801","pt":1717319609735,"mc":[{"id":"1.229554906","rc":[{"atl":[[240,0]],"id":42269942},{"atb":[[1.33,0]],"id":61631980},{"atb":[[1.2,0]],"id":61631978}],"con":true,"img":false}]}
{"op":"mcm","clk":"11450248810","pt":1717319609841,"mc":[{"id":"1.229554906","rc":[{"atl":[[120,2.61]],"id":42269942}],"con":true,"img":false}]}
{"op":"mcm","clk":"11450248849","pt":1717319610249,"mc":[{"id":"1.229554906","rc":[{"atl":[[6.2,15.38]],"id":57451148}],"con":true,"img":false}]}
{"op":"mcm","clk":"11450248861","pt":1717319610351,"mc":[{"id":"1.229554906","rc":[{"atl":[[7.4,10.31]],"id":57451148}],"con":true,"img":false}]}
{"op":"mcm","clk":"11450248956","pt":1717319611441,"mc":[{"id":"1.229554906","rc":[{"atl":[[7,0]],"id":61631980}],"con":true,"img":false}]}
{"op":"mcm","clk":"11450248965","pt":1717319611548,"mc":[{"id":"1.229554906","rc":[{"atl":[[6.4,6.97]],"id":61631980}],"con":true,"img":false}]}
{"op":"mcm","clk":"11450248988","pt":1717319611850,"mc":[{"id":"1.229554906","rc":[{"atl":[[6.8,8.62]],"id":57451148}],"con":true,"img":false}]}
{"op":"mcm","clk":"11450249189","pt":1717319614130,"mc":[{"id":"1.229554906","rc":[{"atl":[[2.62,46.3]],"id":61631978}],"con":true,"img":false}]}
{"op":"mcm","clk":"11450249292","pt":1717319615428,"mc":[{"id":"1.229554906","rc":[{"atl":[[8.2,5],[7.4,2.5],[7.8,0]],"id":57451148}],"con":true,"img":false}]}
{"op":"mcm","clk":"11450249315","pt":1717319615736,"mc":[{"id":"1.229554906","rc":[{"atl":[[12.5,0]],"id":57451148}],"con":true,"img":false}]}
{"op":"mcm","clk":"11450249326","pt":1717319615842,"mc":[{"id":"1.229554906","rc":[{"atl":[[14.5,3.21]],"id":57451148}],"con":true,"img":false}]}
{"op":"mcm","clk":"11450249415","pt":1717319616952,"mc":[{"id":"1.229554906","rc":[{"atb":[[7.2,0],[8.2,9.32]],"id":42269942},{"atl":[[130,0],[110,2]],"id":42269942},{"spn":32.2,"spf":"NaN","id":42269942},{"atb":[[2.72,0],[2.64,0],[2.6,0],[2.68,0]],"id":57451148},{"spn":4.7,"spf":"NaN","id":57451148},{"atl":[[2,20],[1.97,77.32],[1.93,31.04],[2.08,92.59]],"id":60780007},{"spn":1.51,"spf":"NaN","id":60780007},{"atb":[[1.83,0],[1.77,55.31]],"id":61631980},{"atl":[[4,12.5],[4.2,6.25]],"id":61631980},{"spn":3.02,"spf":"NaN","id":61631980},{"atb":[[1.36,0],[1.38,95.74]],"id":61631978},{"spn":2.08,"spf":"NaN","id":61631978}],"con":true,"img":false}]}
{"op":"mcm","clk":"11450249432","pt":1717319617132,"mc":[{"id":"1.229554906","rc":[{"atl":[[1.93,0]],"id":60780007},{"atl":[[4,0]],"id":61631980}],"con":true,"img":false}]}
{"op":"mcm","clk":"11450249441","pt":1717319617233,"mc":[{"id":"1.229554906","rc":[{"atl":[[1.95,123.49]],"id":60780007},{"atl":[[4.5,0],[4.2,23.13],[4.7,27.03]],"id":61631980}],"con":true,"img":false}]}
{"op":"mcm","clk":"11450249494","pt":1717319617750,"mc":[{"id":"1.229554906","rc":[{"atl":[[1.95,70.86]],"id":60780007}],"con":true,"img":false}]}
{"op":"mcm","clk":"11450249526","pt":1717319618161,"mc":[{"id":"1.229554906","rc":[{"atl":[[70,5],[80,0],[50,2.5],[60,0]],"id":42269942},{"atl":[[9,0],[8.2,0],[7.4,0],[7,15.83]],"id":57451148},{"atb":[[1.98,0],[2.12,5],[2.18,27.8],[1.94,0],[2.2,2.5]],"id":61631980}],"con":true,"img":false}]}
{"op":"mcm","clk":"11450249533","pt":1717319618265,"mc":[{"id":"1.229554906","rc":[{"atl":[[50,4.13]],"id":42269942},{"atb":[[2.04,2.5]],"id":61631980}],"con":true,"img":false}]}
{"op":"mcm","clk":"11450249542","pt":1717319618325,"mc":[{"id":"1.229554906","rc":[{"atl":[[55,0]],"id":42269942}],"con":true,"img":false}]}
{"op":"mcm","clk":"11450249580","pt":1717319618838,"mc":[{"id":"1.229554906","rc":[{"atl":[[120,0]],"id":42269942}],"con":true,"img":false}]}
{"op":"mcm","clk":"11450249589","pt":1717319618947,"mc":[{"id":"1.229554906","rc":[{"atl":[[200,2.61]],"id":42269942}],"con":true,"img":false}]}
{"op":"mcm","clk":"11450249614","pt":1717319619262,"mc":[{"id":"1.229554906","rc":[{"atl":[[7.2,12.1]],"id":57451148}],"con":true,"img":false}]}
{"op":"mcm","clk":"11450249692","pt":1717319620042,"mc":[{"id":"1.229554906","rc":[{"atl":[[1.95,141.72],[2.08,0]],"id":60780007},{"atl":[[2.46,54.79]],"id":61631978}],"con":true,"img":false}]}
{"op":"mcm","clk":"11450249702","pt":1717319620146,"mc":[{"id":"1.229554906","rc":[{"atl":[[2.54,77.93],[2.58,31.65],[2.52,0]],"id":61631978}],"con":true,"img":false}]}
{"op":"mcm","clk":"11450249730","pt":1717319620458,"mc":[{"id":"1.229554906","rc":[{"atl":[[2.48,13.51]],"id":61631978}],"con":true,"img":false}]}
{"op":"mcm","clk":"11450249797","pt":1717319621236,"mc":[{"id":"1.229554906","rc":[{"atl":[[2.48,0]],"id":61631978}],"con":true,"img":false}]}
{"op":"mcm","clk":"11450249915","pt":1717319622157,"mc":[{"id":"1.229554906","rc":[{"atl":[[2.48,13.51]],"id":61631978}],"con":true,"img":false}]}
{"op":"mcm","clk":"11450249960","pt":1717319622679,"mc":[{"id":"1.229554906","rc":[{"atl":[[2.48,0]],"id":61631978}],"con":true,"img":false}]}
{"op":"mcm","clk":"11450250102","pt":1717319624163,"mc":[{"id":"1.229554906","rc":[{"atb":[[6.4,0],[8.4,0]],"id":42269942},{"atb":[[3.2,0],[2.88,0]],"id":57451148},{"atb":[[1.01,250]],"id":60780007},{"atl":[[2.3,0]],"id":60780007},{"atb":[[1.73,0],[1.63,0]],"id":61631980},{"atl":[[6.8,0]],"id":61631980},{"atb":[[1.64,0],[1.54,0]],"id":61631978},{"atl":[[6,0]],"id":61631978}],"con":true,"img":false}]}
{"op":"mcm","clk":"11450250108","pt":1717319624260,"mc":[{"id":"1.229554906","rc":[{"atb":[[2.46,12.72]],"id":57451148},{"atb":[[1.38,0]],"id":61631978}],"con":true,"img":false}]}
{"op":"mcm","clk":"11450250119","pt":1717319624364,"mc":[{"id":"1.229554906","rc":[{"atl":[[1.97,0],[2.04,48.08]],"id":60780007},{"atb":[[1.56,35.71]],"id":61631980},{"atl":[[4.4,14.71]],"id":61631980},{"atb":[[1.36,93.04]],"id":61631978}],"con":true,"img":false}]}
{"op":"mcm","clk":"11450250181","pt":1717319625051,"mc":[{"id":"1.229554906","rc":[{"atl":[[2.58,94.94]],"id":61631978}],"con":true,"img":false}]}
{"op":"mcm","clk":"11450250197","pt":1717319625238,"mc":[{"id":"1.229554906","rc":[{"atl":[[2.54,12.99]],"id":61631978}],"con":true,"img":false}]}
{"op":"mcm","clk":"11450250254","pt":1717319625773,"mc":[{"id":"1.229554906","rc":[{"atl":[[100,0.35]],"id":42269942},{"atb":[[2.24,28.05]],"id":57451148}],"con":true,"img":false}]}
{"op":"mcm","clk":"11450250350","pt":1717319626661,"mc":[{"id":"1.229554906","rc":[{"atb":[[2.56,32.05],[2.52,49.34],[2.6,12.5],[2.48,84.46]],"id":57451148},{"atl":[[7.6,18.94]],"id":57451148},{"atl":[[1.95,70.86],[2.14,87.72]],"id":60780007},{"atb":[[1.56,0]],"id":61631980},{"atb":[[1.36,148.6]],"id":61631978},{"atl":[[2.46,0],[2.48,13.51]],"id":61631978}],"con":true,"img":false}]}
{"op":"mcm","clk":"11450250360","pt":1717319626763,"mc":[{"id":"1.229554906","rc":[{"atl":[[2.46,13.51],[2.58,31.65]],"id":61631978}],"con":true,"img":false}]}
{"op":"mcm","clk":"11450250364","pt":1717319626863,"mc":[{"id":"1.229554906","rc":[{"atl":[[2.52,52.63]],"id":61631978}],"con":true,"img":false}]}
{"op":"mcm","clk":"11450250429","pt":1717319627443,"mc":[{"id":"1.229554906","rc":[{"atb":[[1.06,53.8]],"id":60780007}],"con":true,"img":false}]}
{"op":"mcm","clk":"11450250546","pt":1717319628848,"mc":[{"id":"1.229554906","rc":[{"atb":[[2.2,30.88]],"id":61631980}],"con":true,"img":false}]}
{"op":"mcm","clk":"11450250557","pt":1717319628951,"mc":[{"id":"1.229554906","rc":[{"atb":[[1.56,35.71]],"id":61631980},{"atl":[[2.48,0]],"id":61631978}],"con":true,"img":false}]}
{"op":"mcm","clk":"11450250560","pt":1717319629087,"mc":[{"id":"1.229554906","rc":[{"atb":[[2.18,0]],"id":61631980}],"con":true,"img":false}]}
{"op":"mcm","clk":"11450250687","pt":1717319630551,"mc":[{"id":"1.229554906","rc":[{"atl":[[7.2,3.23],[6.4,0]],"id":57451148},{"atl":[[2.48,13.51]],"id":61631978}],"con":true,"img":false}]}
{"op":"mcm","clk":"11450250703","pt":1717319630760,"mc":[{"id":"1.229554906","rc":[{"atl":[[2.44,55.56]],"id":61631978}],"con":true,"img":false}]}
{"op":"mcm","clk":"11450250722","pt":1717319630964,"mc":[{"id":"1.229554906","rc":[{"atl":[[2.52,0]],"id":61631978}],"con":true,"img":false}]}
{"op":"mcm","clk":"11450250784","pt":1717319631682,"mc":[{"id":"1.229554906","rc":[{"atl":[[2.08,69.44]],"id":60780007},{"atl":[[2.48,81.07],[2.46,0]],"id":61631978}],"con":true,"img":false}]}
{"op":"mcm","clk":"11450250793","pt":1717319631743,"mc":[{"id":"1.229554906","rc":[{"atl":[[1.99,0]],"id":60780007}],"con":true,"img":false}]}
{"op":"mcm","clk":"11450250800","pt":1717319631842,"mc":[{"id":"1.229554906","rc":[{"atl":[[2.44,0]],"id":61631978}],"con":true,"img":false}]}
{"op":"mcm","clk":"11450250811","pt":1717319631950,"mc":[{"id":"1.229554906","rc":[{"atl":[[2.46,54.79]],"id":61631978}],"con":true,"img":false}]}
{"op":"mcm","clk":"11450250939","pt":1717319633562,"mc":[{"id":"1.229554906","rc":[{"atl":[[6.8,0]],"id":57451148}],"con":true,"img":false}]}
{"op":"mcm","clk":"11450250949","pt":1717319633665,"mc":[{"id":"1.229554906","rc":[{"atl":[[6.2,0]],"id":57451148}],"con":true,"img":false}]}
{"op":"mcm","clk":"11450250956","pt":1717319633773,"mc":[{"id":"1.229554906","rc":[{"atl":[[7.2,19.36],[7,2.5],[6.6,14.29]],"id":57451148}],"con":true,"img":false}]}
{"op":"mcm","clk":"11450250966","pt":1717319633869,"mc":[{"id":"1.229554906","rc":[{"atl":[[6.6,0]],"id":57451148}],"con":true,"img":false}]}
{"op":"mcm","clk":"11450250976","pt":1717319633975,"mc":[{"id":"1.229554906","rc":[{"atl":[[7,15.83]],"id":57451148}],"con":true,"img":false}]}
{"op":"mcm","clk":"11450251037","pt":1717319634654,"mc":[{"id":"1.229554906","rc":[{"atb":[[7.8,9.41]],"id":42269942}],"con":true,"img":false}]}
{"op":"mcm","clk":"11450251053","pt":1717319634861,"mc":[{"id":"1.229554906","rc":[{"atb":[[2.6,41.22]],"id":57451148}],"con":true,"img":false}]}
{"op":"mcm","clk":"11450251062","pt":1717319634962,"mc":[{"id":"1.229554906","rc":[{"atb":[[2.46,2.49]],"id":57451148}],"con":true,"img":false}]}
{"op":"mcm","clk":"11450251157","pt":1717319636157,"mc":[{"id":"1.229554906","rc":[{"atb":[[1.54,92.59]],"id":61631980},{"atl":[[4.6,20.83]],"id":61631980}],"con":true,"img":false}]}
{"op":"mcm","clk":"11450251178","pt":1717319636476,"mc":[{"id":"1.229554906","rc":[{"atl":[[2.54,77.93],[2.48,13.51]],"id":61631978}],"con":true,"img":false}]}
{"op":"mcm","clk":"11450251279","pt":1717319637658,"mc":[{"id":"1.229554906","rc":[{"atl":[[7.6,7.58]],"id":57451148},{"atb":[[1.34,147.06]],"id":61631978}],"con":true,"img":false}]}
{"op":"mcm","clk":"11450251349","pt":1717319638582,"mc":[{"id":"1.229554906","rc":[{"atl":[[7.2,3.23],[7.6,22.73]],"id":57451148}],"con":true,"img":false}]}
{"op":"mcm","clk":"11450251365","pt":1717319638788,"mc":[{"id":"1.229554906","rc":[{"atb":[[1.05,1187.61]],"id":60780007},{"atl":[[2.12,111.61]],"id":60780007},{"atb":[[1.26,230.19]],"id":61631978}],"con":true,"img":false}]}
{"op":"mcm","clk":"11450251685","pt":1717319642890,"mc":[{"id":"1.229554906","rc":[{"atb":[[6.8,6],[8.8,2.97]],"id":42269942},{"atb":[[3.3,10.09],[2.92,18.14]],"id":57451148},{"atb":[[1.01,6057.26]],"id":60780007},{"atl":[[2.3,0.4]],"id":60780007},{"atb":[[1.72,32.26],[1.62,56.19]],"id":61631980},{"atl":[[6.8,0.08]],"id":61631980},{"atb":[[1.62,37.46],[1.52,67]],"id":61631978},{"atl":[[5.8,0.1]],"id":61631978}],"con":true,"img":false}]}
{"op":"mcm","clk":"11450251723","pt":1717319643164,"mc":[{"id":"1.229554906","rc":[{"atl":[[4.8,32.89]],"id":61631980}],"con":true,"img":false}]}
{"op":"mcm","clk":"11450251760","pt":1717319643479,"mc":[{"id":"1.229554906","rc":[{"atl":[[1.95,112.71],[2.14,0]],"id":60780007}],"con":true,"img":false}]}
{"op":"mcm","clk":"11450251804","pt":1717319643991,"mc":[{"id":"1.229554906","rc":[{"atl":[[2.48,0]],"id":61631978}],"con":true,"img":false}]}
{"op":"mcm","clk":"11450251827","pt":1717319644201,"mc":[{"id":"1.229554906","rc":[{"atl":[[2.54,12.99],[2.46,0],[2.58,94.94]],"id":61631978}],"con":true,"img":false}]}
{"op":"mcm","clk":"11450251835","pt":1717319644300,"mc":[{"id":"1.229554906","rc":[{"atl":[[2.5,53.33],[2.58,31.65],[2.62,108.03]],"id":61631978}],"con":true,"img":false}]}
{"op":"mcm","clk":"11450251844","pt":1717319644402,"mc":[{"id":"1.229554906","rc":[{"atl":[[2.5,0],[2.58,77.95],[2.62,46.3]],"id":61631978}],"con":true,"img":false}]}
{"op":"mcm","clk":"11450251854","pt":1717319644507,"mc":[{"id":"1.229554906","rc":[{"atl":[[2.52,52.63],[2.58,31.65],[2.62,108.03]],"id":61631978}],"con":true,"img":false}]}
{"op":"mcm","clk":"11450251864","pt":1717319644567,"mc":[{"id":"1.229554906","rc":[{"atl":[[2.58,77.95],[2.62,46.3]],"id":61631978}],"con":true,"img":false}]}
{"op":"mcm","clk":"11450251883","pt":1717319644769,"mc":[{"id":"1.229554906","rc":[{"atl":[[8,10.71]],"id":57451148},{"atl":[[2.54,0],[2.56,12.82]],"id":61631978}],"con":true,"img":false}]}
{"op":"mcm","clk":"11450251962","pt":1717319645796,"mc":[{"id":"1.229554906","rc":[{"atb":[[1.84,70.1]],"id":57451148},{"atl":[[6.4,0],[4.7,39]],"id":61631980}],"con":true,"img":false}]}
{"op":"mcm","clk":"11450251970","pt":1717319645898,"mc":[{"id":"1.229554906","rc":[{"atb":[[9.2,0]],"id":42269942},{"atl":[[1.96,0]],"id":60780007}],"con":true,"img":false}]}
{"op":"mcm","clk":"11450251979","pt":1717319646001,"mc":[{"id":"1.229554906","rc":[{"atb":[[8.4,3.41],[9.4,0]],"id":42269942},{"atl":[[1.94,41.85]],"id":60780007}],"con":true,"img":false}]}
{"op":"mcm","clk":"11450251988","pt":1717319646059,"mc":[{"id":"1.229554906","rc":[{"atb":[[9,4.79]],"id":42269942},{"atl":[[1.94,126.96]],"id":60780007}],"con":true,"img":false}]}
{"op":"mcm","clk":"11450251999","pt":1717319646163,"mc":[{"id":"1.229554906","rc":[{"atl":[[1.95,41.85]],"id":60780007}],"con":true,"img":false}]}
{"op":"mcm","clk":"11450252190","pt":1717319648588,"mc":[{"id":"1.229554906","rc":[{"atl":[[1.95,0],[1.93,41.85]],"id":60780007}],"con":true,"img":false}]}
{"op":"mcm","clk":"11450252255","pt":1717319649208,"mc":[{"id":"1.229554906","rc":[{"atl":[[210,0],[230,0],[250,0]],"id":42269942}],"con":true,"img":false}]}
{"op":"mcm","clk":"11450252423","pt":1717319651073,"mc":[{"id":"1.229554906","rc":[{"atb":[[8,8.2],[8.2,2.5]],"id":42269942},{"atb":[[2.22,0],[2.04,70.11],[2.6,28.72],[2.56,0]],"id":57451148},{"atl":[[2,0],[1.95,21.05]],"id":60780007},{"atb":[[1.77,0],[1.61,92.59]],"id":61631980},{"atl":[[4.8,59.21],[4.5,5.71],[4.2,16.88],[4.7,11.97]],"id":61631980},{"atb":[[1.36,93.04]],"id":61631978}],"con":true,"img":false}]}
{"op":"mcm","clk":"11450252431","pt":1717319651181,"mc":[{"id":"1.229554906","rc":[{"atl":[[4.2,0]],"id":61631980}],"con":true,"img":false}]}
{"op":"mcm","clk":"11450252436","pt":1717319651282,"mc":[{"id":"1.229554906","rc":[{"atl":[[4.4,30.03]],"id":61631980}],"con":true,"img":false}]}
{"op":"mcm","clk":"11450252462","pt":1717319651592,"mc":[{"id":"1.229554906","rc":[{"atl":[[240,1],[250,1]],"id":42269942},{"atl":[[7,19.16]],"id":57451148},{"atl":[[4.4,15.32]],"id":61631980}],"con":true,"img":false}]}
{"op":"mcm","clk":"11450252472","pt":1717319651693,"mc":[{"id":"1.229554906","rc":[{"atl":[[230,1]],"id":42269942},{"atl":[[2.56,0],[2.58,58.96]],"id":61631978}],"con":true,"img":false}]}
{"op":"mcm","clk":"11450252482","pt":1717319651799,"mc":[{"id":"1.229554906","rc":[{"atl":[[240,0],[250,0]],"id":42269942},{"atl":[[7.6,18.18],[7,15.83]],"id":57451148},{"atl":[[2.58,12.66],[2.62,108.03]],"id":61631978}],"con":true,"img":false}]}
{"op":"mcm","clk":"11450252502","pt":1717319652001,"mc":[{"id":"1.229554906","rc":[{"atl":[[7.2,0],[7,19.16]],"id":57451148}],"con":true,"img":false}]}
{"op":"mcm","clk":"11450252509","pt":1717319652105,"mc":[{"id":"1.229554906","rc":[{"atl":[[230,0]],"id":42269942},{"atl":[[8,25],[7,15.83]],"id":57451148},{"atl":[[2.56,12.82]],"id":61631978}],"con":true,"img":false}]}
{"op":"mcm","clk":"11450252515","pt":1717319652210,"mc":[{"id":"1.229554906","rc":[{"atl":[[7.6,3.03]],"id":57451148}],"con":true,"img":false}]}
{"op":"mcm","clk":"11450252528","pt":1717319652314,"mc":[{"id":"1.229554906","rc":[{"atl":[[2.54,64.94],[2.62,46.3]],"id":61631978}],"con":true,"img":false}]}
{"op":"mcm","clk":"11450252538","pt":1717319652370,"mc":[{"id":"1.229554906","rc":[{"atl":[[7.2,3.23]],"id":57451148},{"atl":[[1.96,20.83],[1.95,0]],"id":60780007},{"atl":[[2.58,75.95]],"id":61631978}],"con":true,"img":false}]}
{"op":"mcm","clk":"11450252543","pt":1717319652488,"mc":[{"id":"1.229554906","rc":[{"atl":[[2.54,0]],"id":61631978}],"con":true,"img":false}]}
{"op":"mcm","clk":"11450252550","pt":1717319652589,"mc":[{"id":"1.229554906","rc":[{"atl":[[1.96,0],[1.95,21.05]],"id":60780007}],"con":true,"img":false}]}
{"op":"mcm","clk":"11450252665","pt":1717319653981,"mc":[{"id":"1.229554906","rc":[{"atb":[[8.4,5.91]],"id":42269942}],"con":true,"img":false}]}
{"op":"mcm","clk":"11450252675","pt":1717319654084,"mc":[{"id":"1.229554906","rc":[{"atb":[[8.2,0],[7.4,0]],"id":42269942}],"con":true,"img":false}]}
{"op":"mcm","clk":"11450252686","pt":1717319654190,"mc":[{"id":"1.229554906","rc":[{"atl":[[250,1]],"id":42269942}],"con":true,"img":false}]}
{"op":"mcm","clk":"11450252715","pt":1717319654500,"mc":[{"id":"1.229554906","rc":[{"atl":[[2.46,54.79]],"id":61631978}],"con":true,"img":false}]}
{"op":"mcm","clk":"11450252730","pt":1717319654701,"mc":[{"id":"1.229554906","rc":[{"atl":[[2.52,0]],"id":61631978}],"con":true,"img":false}]}
{"op":"mcm","clk":"11450252876","pt":1717319656312,"mc":[{"id":"1.229554906","rc":[{"atl":[[1.93,127.87]],"id":60780007}],"con":true,"img":false}]}
{"op":"mcm","clk":"11450252885","pt":1717319656413,"mc":[{"id":"1.229554906","rc":[{"atl":[[1.94,41.85]],"id":60780007}],"con":true,"img":false}]}
{"op":"mcm","clk":"11450252893","pt":1717319656512,"mc":[{"id":"1.229554906","rc":[{"atb":[[2.8,2.5],[2.72,5],[2.3,0],[2.5,46.87],[2.04,0],[2.64,10],[3.3,28.47],[2.38,0],[2.46,0]],"id":57451148},{"atl":[[1.9,22.22],[1.95,0]],"id":60780007},{"atb":[[1.7,56.2],[1.61,0]],"id":61631980},{"atl":[[4.8,32.89],[4.3,6.06],[4.6,41.86]],"id":61631980},{"atb":[[1.28,0],[1.36,0],[1.25,0],[1.32,0],[1.34,0],[1.17,166.78]],"id":61631978},{"atl":[[2.46,0]],"id":61631978}],"con":true,"img":false}]}
{"op":"mcm","clk":"11450252900","pt":1717319656614,"mc":[{"id":"1.229554906","rc":[{"atb":[[2.6,0]],"id":57451148},{"atb":[[1.2,5],[1.24,2.5]],"id":61631978},{"atl":[[2.58,12.66],[2.62,108.03],[2.48,54.05]],"id":61631978}],"con":true,"img":false}]}
{"op":"mcm","clk":"11450252911","pt":1717319656772,"mc":[{"id":"1.229554906","rc":[{"atl":[[2.62,46.3],[2.46,12.82]],"id":61631978}],"con":true,"img":false}]}
{"op":"mcm","clk":"11450252918","pt":1717319656826,"mc":[{"id":"1.229554906","rc":[{"atb":[[6.8,16.46],[7.8,0]],"id":42269942}],"con":true,"img":false}]}
{"op":"mcm","clk":"11450252930","pt":1717319656930,"mc":[{"id":"1.229554906","rc":[{"atl":[[2.56,76.91],[2.46,0]],"id":61631978}],"con":true,"img":false}]}
{"op":"mcm","clk":"11450252964","pt":1717319657303,"mc":[{"id":"1.229554906","rc":[{"atl":[[8,10.71],[7.6,18.18]],"id":57451148}],"con":true,"img":false}]}
{"op":"mcm","clk":"11450253049","pt":1717319658287,"mc":[{"id":"1.229554906","rc":[{"atl":[[16.5,4.18],[24,0]],"id":57451148}],"con":true,"img":false}]}
{"op":"mcm","clk":"11450253067","pt":1717319658493,"mc":[{"id":"1.229554906","rc":[{"atb":[[1.37,12.76]],"id":61631978}],"con":true,"img":false}]}
{"op":"mcm","clk":"11450253091","pt":1717319658803,"mc":[{"id":"1.229554906","rc":[{"atl":[[6.4,2],[5.8,2],[5.3,2],[6.8,33],[5.9,22],[5.4,2],[5.6,2],[5.1,19.51],[5,7],[6.2,2],[5.5,15],[5.2,10]],"id":57451148}],"con":true,"img":false}]}
{"op":"mcm","clk":"11450253097","pt":1717319658906,"mc":[{"id":"1.229554906","rc":[{"atl":[[7.6,3.03],[7,31.66]],"id":57451148},{"atl":[[2.6,31.25]],"id":61631978}],"con":true,"img":false}]}
{"op":"mcm","clk":"11450253106","pt":1717319659009,"mc":[{"id":"1.229554906","rc":[{"atl":[[7,18.33]],"id":57451148}],"con":true,"img":false}]}
{"op":"mcm","clk":"11450253155","pt":1717319659477,"mc":[{"id":"1.229554906","rc":[{"atl":[[1.96,9.84]],"id":60780007}],"con":true,"img":false}]}
{"op":"mcm","clk":"11450253164","pt":1717319659575,"mc":[{"id":"1.229554906","rc":[{"atl":[[14.5,0]],"id":57451148}],"con":true,"img":false}]}
{"op":"mcm","clk":"11450253171","pt":1717319659682,"mc":[{"id":"1.229554906","rc":[{"atb":[[2.6,6.26]],"id":57451148},{"atl":[[13,3.21]],"id":57451148},{"atl":[[1.96,0]],"id":60780007}],"con":true,"img":false}]}
{"op":"mcm","clk":"11450253281","pt":1717319660919,"mc":[{"id":"1.229554906","rc":[{"atl":[[210,1]],"id":42269942}],"con":true,"img":false}]}
{"op":"mcm","clk":"11450253335","pt":1717319661392,"mc":[{"id":"1.229554906","rc":[{"atl":[[4.3,14.89]],"id":61631980}],"con":true,"img":false}]}
{"op":"mcm","clk":"11450253347","pt":1717319661541,"mc":[{"id":"1.229554906","rc":[{"atl":[[1.89,22.47],[1.9,0]],"id":60780007},{"atl":[[4.4,0]],"id":61631980},{"atb":[[1.37,0]],"id":61631978},{"atl":[[2.58,75.95],[2.48,67.56],[2.56,0]],"id":61631978}],"con":true,"img":false}]}
{"op":"mcm","clk":"11450253363","pt":1717319661708,"mc":[{"id":"1.229554906","rc":[{"atl":[[2.6,93.75],[2.58,12.66]],"id":61631978}],"con":true,"img":false}]}
{"op":"mcm","clk":"11450253455","pt":1717319662728,"mc":[{"id":"1.229554906","rc":[{"atl":[[200,3.61]],"id":42269942},{"atl":[[2.48,54.05]],"id":61631978}],"con":true,"img":false}]}
{"op":"mcm","clk":"11450253475","pt":1717319662894,"mc":[{"id":"1.229554906","rc":[{"atb":[[8,0],[7.4,15.62]],"id":42269942},{"atl":[[36,1],[38,2.16],[200,0]],"id":42269942},{"atb":[[2.6,0],[2.24,0]],"id":57451148},{"atl":[[7.2,0],[7.6,0]],"id":57451148},{"atl":[[2.72,34.52],[3.15,0]],"id":60780007},{"atl":[[8,7.71],[9.4,0]],"id":61631980},{"atl":[[5.1,14.64],[6.6,0]],"id":61631978}],"con":true,"img":false}]}
{"op":"mcm","clk":"11450253480","pt":1717319662995,"mc":[{"id":"1.229554906","rc":[{"atl":[[100,2.96]],"id":42269942},{"atb":[[2.62,28.05]],"id":57451148}],"con":true,"img":false}]}
{"op":"mcm","clk":"11450253493","pt":1717319663101,"mc":[{"id":"1.229554906","rc":[{"atb":[[7.4,0]],"id":42269942},{"atl":[[75,2],[50,2.5],[110,0]],"id":42269942}],"con":true,"img":false}]}
{"op":"mcm","clk":"11450253513","pt":1717319663306,"mc":[{"id":"1.229554906","rc":[{"atb":[[3.5,40]],"id":42269942}],"con":true,"img":false}]}
{"op":"mcm","clk":"11450253559","pt":1717319663726,"mc":[{"id":"1.229554906","rc":[{"atl":[[36,0],[210,0]],"id":42269942},{"atl":[[2.56,12.82]],"id":61631978}],"con":true,"img":false}]}
{"op":"mcm","clk":"11450253566","pt":1717319663817,"mc":[{"id":"1.229554906","rc":[{"atl":[[2.54,64.94],[2.6,31.25]],"id":61631978}],"con":true,"img":false}]}
{"op":"mcm","clk":"11450253571","pt":1717319663918,"mc":[{"id":"1.229554906","rc":[{"atb":[[8.4,2.5]],"id":42269942}],"con":true,"img":false}]}
{"op":"mcm","clk":"11450253581","pt":1717319664022,"mc":[{"id":"1.229554906","rc":[{"atb":[[9.2,3.41]],"id":42269942},{"atl":[[38,0]],"id":42269942}],"con":true,"img":false}]}
{"op":"mcm","clk":"11450253592","pt":1717319664127,"mc":[{"id":"1.229554906","rc":[{"atb":[[9.4,4.79]],"id":42269942},{"atl":[[48,1.7]],"id":42269942},{"atl":[[2.56,0]],"id":61631978}],"con":true,"img":false}]}
{"op":"mcm","clk":"11450253603","pt":1717319664180,"mc":[{"id":"1.229554906","rc":[{"atb":[[9,0]],"id":42269942}],"con":true,"img":false}]}
{"op":"mcm","clk":"11450253640","pt":1717319664600,"mc":[{"id":"1.229554906","rc":[{"atl":[[2.46,54.79]],"id":61631978}],"con":true,"img":false}]}
{"op":"mcm","clk":"11450253653","pt":1717319664701,"mc":[{"id":"1.229554906","rc":[{"atl":[[2.48,0]],"id":61631978}],"con":true,"img":false}]}
{"op":"mcm","clk":"11450253791","pt":1717319666314,"mc":[{"id":"1.229554906","rc":[{"atl":[[1.89,112.36]],"id":60780007}],"con":true,"img":false}]}
{"op":"mcm","clk":"11450253795","pt":1717319666417,"mc":[{"id":"1.229554906","rc":[{"atl":[[36,1]],"id":42269942},{"atl":[[1.93,41.85]],"id":60780007}],"con":true,"img":false}]}
{"op":"mcm","clk":"11450253866","pt":1717319667194,"mc":[{"id":"1.229554906","rc":[{"atl":[[70,0],[44,2.5],[50,0],[55,5]],"id":42269942},{"atl":[[7,15.83]],"id":57451148},{"atb":[[2.04,0],[2.28,17.95]],"id":61631980}],"con":true,"img":false}]}
{"op":"mcm","clk":"11450253875","pt":1717319667295,"mc":[{"id":"1.229554906","rc":[{"atb":[[2.2,2.5]],"id":61631980}],"con":true,"img":false}]}
{"op":"mcm","clk":"11450253945","pt":1717319668120,"mc":[{"id":"1.229554906","rc":[{"atl":[[1.91,54.95]],"id":60780007}],"con":true,"img":false}]}
{"op":"mcm","clk":"11450253954","pt":1717319668223,"mc":[{"id":"1.229554906","rc":[{"atl":[[1.9,111.11]],"id":60780007}],"con":true,"img":false}]}
{"op":"mcm","clk":"11450253962","pt":1717319668325,"mc":[{"id":"1.229554906","rc":[{"atl":[[1.93,0]],"id":60780007}],"con":true,"img":false}]}
{"op":"mcm","clk":"11450254007","pt":1717319668696,"mc":[{"id":"1.229554906","rc":[{"atl":[[5,27]],"id":57451148}],"con":true,"img":false}]}
{"op":"mcm","clk":"11450254015","pt":1717319668793,"mc":[{"id":"1.229554906","rc":[{"atl":[[5.1,0]],"id":57451148}],"con":true,"img":false}]}
{"op":"mcm","clk":"11450254068","pt":1717319669416,"mc":[{"id":"1.229554906","rc":[{"trd":[[36,1.99]],"ltp":36.0,"tv":1.99,"id":42269942},{"atl":[[36,0]],"id":42269942}],"con":true,"img":false}]}
{"op":"mcm","clk":"11450254076","pt":1717319669517,"mc":[{"id":"1.229554906","rc":[{"atb":[[9.6,1]],"id":42269942}],"con":true,"img":false}]}
{"op":"mcm","clk":"11450254149","pt":1717319670297,"mc":[{"id":"1.229554906","rc":[{"atl":[[2.62,30.86]],"id":61631978}],"con":true,"img":false}]}
{"op":"mcm","clk":"11450254160","pt":1717319670401,"mc":[{"id":"1.229554906","rc":[{"atl":[[2.54,0],[2.58,75.95],[2.46,0]],"id":61631978}],"con":true,"img":false}]}
{"op":"mcm","clk":"11450254168","pt":1717319670507,"mc":[{"id":"1.229554906","rc":[{"atl":[[2.48,54.05]],"id":61631978}],"con":true,"img":false}]}
{"op":"mcm","clk":"11450254206","pt":1717319671023,"mc":[{"id":"1.229554906","rc":[{"atl":[[100,0.35]],"id":42269942},{"atb":[[2.62,0]],"id":57451148}],"con":true,"img":false}]}
{"op":"mcm","clk":"11450254215","pt":1717319671129,"mc":[{"id":"1.229554906","rc":[{"atl":[[110,2.61]],"id":42269942},{"atb":[[2.5,74.92]],"id":57451148}],"con":true,"img":false}]}
{"op":"mcm","clk":"11450254225","pt":1717319671228,"mc":[{"id":"1.229554906","rc":[{"atl":[[36,1]],"id":42269942},{"atl":[[2.04,0],[2.12,0],[2.08,0]],"id":60780007}],"con":true,"img":false}]}
{"op":"mcm","clk":"11450254352","pt":1717319672732,"mc":[{"id":"1.229554906","rc":[{"atl":[[1.9,0],[1.91,164.84]],"id":60780007}],"con":true,"img":false}]}
{"op":"mcm","clk":"11450254496","pt":1717319674027,"mc":[{"id":"1.229554906","rc":[{"atb":[[9.8,3.15]],"id":42269942}],"con":true,"img":false}]}
{"op":"mcm","clk":"11450254506","pt":1717319674132,"mc":[{"id":"1.229554906","rc":[{"atb":[[9.4,0]],"id":42269942}],"con":true,"img":false}]}
{"op":"mcm","clk":"11450254572","pt":1717319674701,"mc":[{"id":"1.229554906","rc":[{"atl":[[1.93,80.65]],"id":60780007}],"con":true,"img":false}]}
{"op":"mcm","clk":"11450254583","pt":1717319674803,"mc":[{"id":"1.229554906","rc":[{"atl":[[2.6,93.75],[2.58,12.66]],"id":61631978}],"con":true,"img":false}]}
{"op":"mcm","clk":"11450254655","pt":1717319675628,"mc":[{"id":"1.229554906","rc":[{"atb":[[1.37,12.76]],"id":61631978}],"con":true,"img":false}]}
{"op":"mcm","clk":"11450254748","pt":1717319676723,"mc":[{"id":"1.229554906","rc":[{"atl":[[1.94,0]],"id":60780007}],"con":true,"img":false}]}
{"op":"mcm","clk":"11450254755","pt":1717319676825,"mc":[{"id":"1.229554906","rc":[{"atl":[[1.92,41.85]],"id":60780007},{"atl":[[2.66,45.18]],"id":61631978}],"con":true,"img":false}]}
{"op":"mcm","clk":"11450254826","pt":1717319677704,"mc":[{"id":"1.229554906","rc":[{"atl":[[40,1.16]],"id":42269942},{"spn":22.9,"spf":"NaN","id":42269942},{"spn":4.15,"spf":"NaN","id":57451148},{"spn":1.49,"spf":"NaN","id":60780007},{"spn":3.29,"spf":"NaN","id":61631980},{"spn":2.05,"spf":"NaN","id":61631978}],"con":true,"img":false}]}
{"op":"mcm","clk":"11450254866","pt":1717319678270,"mc":[{"id":"1.229554906","rc":[{"atl":[[2.58,0],[2.56,12.82]],"id":61631978}],"con":true,"img":false}]}
{"op":"mcm","clk":"11450254882","pt":1717319678431,"mc":[{"id":"1.229554906","rc":[{"atb":[[6.8,10.46],[8.8,0]],"id":42269942},{"atb":[[2.92,0],[3.3,18.38]],"id":57451148},{"atb":[[1.72,0],[1.62,0]],"id":61631980},{"atl":[[6.8,0]],"id":61631980},{"atb":[[1.62,0],[1.52,0]],"id":61631978},{"atl":[[5.8,0]],"id":61631978}],"con":true,"img":false}]}
{"op":"mcm","clk":"11450254902","pt":1717319678642,"mc":[{"id":"1.229554906","rc":[{"atb":[[3.3,0]],"id":57451148}],"con":true,"img":false}]}
{"op":"mcm","clk":"11450254909","pt":1717319678749,"mc":[{"id":"1.229554906","rc":[{"atb":[[3.2,11.25]],"id":57451148},{"atl":[[1.92,150.55],[1.91,54.95]],"id":60780007},{"atl":[[4.6,20.83],[5,25]],"id":61631980},{"atl":[[2.48,0]],"id":61631978}],"con":true,"img":false}]}
{"op":"mcm","clk":"11450254918","pt":1717319678842,"mc":[{"id":"1.229554906","rc":[{"atb":[[3.2,0]],"id":57451148},{"atl":[[2.52,19.18]],"id":61631978}],"con":true,"img":false}]}
{"op":"mcm","clk":"11450254927","pt":1717319678946,"mc":[{"id":"1.229554906","rc":[{"trd":[[36,3.99]],"ltp":36.0,"tv":3.99,"id":42269942},{"atl":[[36,0]],"id":42269942},{"atb":[[2.86,5.62]],"id":57451148},{"atl":[[2.52,0]],"id":61631978}],"con":true,"img":false}]}
{"op":"mcm","clk":"11450254937","pt":1717319679003,"mc":[{"id":"1.229554906","rc":[{"atl":[[75,0],[38,2.16],[95,2]],"id":42269942},{"atl":[[2.58,19.18]],"id":61631978}],"con":true,"img":false}]}
{"op":"mcm","clk":"11450254947","pt":1717319679135,"mc":[{"id":"1.229554906","rc":[{"atl":[[48,0]],"id":42269942}],"con":true,"img":false}]}
{"op":"mcm","clk":"11450254964","pt":1717319679345,"mc":[{"id":"1.229554906","rc":[{"atb":[[10,2]],"id":42269942}],"con":true,"img":false}]}
{"op":"mcm","clk":"11450254972","pt":1717319679448,"mc":[{"id":"1.229554906","rc":[{"atb":[[9.6,0]],"id":42269942}],"con":true,"img":false}]}
{"op":"mcm","clk":"11450254993","pt":1717319679715,"mc":[{"id":"1.229554906","rc":[{"atl":[[36,1]],"id":42269942},{"atb":[[2.78,11.24]],"id":57451148},{"atb":[[1.6,33.33]],"id":61631980},{"atb":[[1.27,185.19],[1.25,250],[1.23,250],[1.29,68.97]],"id":61631978}],"con":true,"img":false}]}
{"op":"mcm","clk":"11450255029","pt":1717319680227,"mc":[{"id":"1.229554906","rc":[{"atl":[[2.54,51.95]],"id":61631978}],"con":true,"img":false}]}
{"op":"mcm","clk":"11450255038","pt":1717319680332,"mc":[{"id":"1.229554906","rc":[{"atl":[[2.6,31.25],[2.58,0],[2.52,19.18]],"id":61631978}],"con":true,"img":false}]}
{"op":"mcm","clk":"11450255097","pt":1717319681054,"mc":[{"id":"1.229554906","rc":[{"atl":[[80,0.53],[100,0]],"id":42269942}],"con":true,"img":false}]}
{"op":"mcm","clk":"11450255101","pt":1717319681111,"mc":[{"id":"1.229554906","rc":[{"atl":[[1.95,131.58]],"id":60780007}],"con":true,"img":false}]}
{"op":"mcm","clk":"11450255245","pt":1717319683025,"mc":[{"id":"1.229554906","rc":[{"atl":[[1.96,104.17]],"id":60780007}],"con":true,"img":false}]}
{"op":"mcm","clk":"11450255253","pt":1717319683128,"mc":[{"id":"1.229554906","rc":[{"atl":[[1.92,41.85]],"id":60780007}],"con":true,"img":false}]}
{"op":"mcm","clk":"11450255266","pt":1717319683230,"mc":[{"id":"1.229554906","rc":[{"atb":[[9.2,0],[9.8,6.35]],"id":42269942},{"atb":[[2.5,46.87],[2.06,0.59]],"id":57451148}],"con":true,"img":false}]}
{"op":"mcm","clk":"11450255314","pt":1717319683660,"mc":[{"id":"1.229554906","rc":[{"atb":[[10.5,3.12]],"id":42269942}],"con":true,"img":false}]}
{"op":"mcm","clk":"11450255325","pt":1717319683749,"mc":[{"id":"1.229554906","rc":[{"atb":[[9.8,3.2]],"id":42269942}],"con":true,"img":false}]}
{"op":"mcm","clk":"11450255337","pt":1717319683849,"mc":[{"id":"1.229554906","rc":[{"atl":[[2.6,0],[2.62,0],[2.56,0]],"id":61631978}],"con":true,"img":false}]}
{"op":"mcm","clk":"11450255378","pt":1717319684216,"mc":[{"id":"1.229554906","rc":[{"atb":[[1.6,0]],"id":61631980},{"atl":[[2.64,12.2]],"id":61631978}],"con":true,"img":false}]}
{"op":"mcm","clk":"11450255406","pt":1717319684526,"mc":[{"id":"1.229554906","rc":[{"atb":[[1.6,33.33]],"id":61631980}],"con":true,"img":false}]}
{"op":"mcm","clk":"11450255414","pt":1717319684629,"mc":[{"id":"1.229554906","rc":[{"atl":[[2.52,0],[2.64,73.18]],"id":61631978}],"con":true,"img":false}]}
{"op":"mcm","clk":"11450255422","pt":1717319684733,"mc":[{"id":"1.229554906","rc":[{"atl":[[2.54,0],[2.64,12.2],[2.66,105.42]],"id":61631978}],"con":true,"img":false}]}
{"op":"mcm","clk":"11450255431","pt":1717319684835,"mc":[{"id":"1.229554906","rc":[{"atl":[[3.2,4.63]],"id":61631980},{"atl":[[2.58,50.63]],"id":61631978}],"con":true,"img":false}]}
{"op":"mcm","clk":"11450255441","pt":1717319684941,"mc":[{"id":"1.229554906","rc":[{"atb":[[1.6,0]],"id":61631980},{"atl":[[3.2,5.63]],"id":61631980},{"atl":[[2.58,0]],"id":61631978}],"con":true,"img":false}]}
{"op":"mcm","clk":"11450255448","pt":1717319685043,"mc":[{"id":"1.229554906","rc":[{"atl":[[4.3,6.06]],"id":61631980},{"atl":[[2.6,50]],"id":61631978}],"con":true,"img":false}]}
{"op":"mcm","clk":"11450255468","pt":1717319685258,"mc":[{"id":"1.229554906","rc":[{"atb":[[1.6,33.33]],"id":61631980}],"con":true,"img":false}]}
{"op":"mcm","clk":"11450255510","pt":1717319685626,"mc":[{"id":"1.229554906","rc":[{"atb":[[1.6,0]],"id":61631980}],"con":true,"img":false}]}
{"op":"mcm","clk":"11450255534","pt":1717319685838,"mc":[{"id":"1.229554906","rc":[{"atb":[[1.37,0]],"id":61631978}],"con":true,"img":false}]}
{"op":"mcm","clk":"11450255543","pt":1717319685936,"mc":[{"id":"1.229554906","rc":[{"atb":[[1.29,158.2]],"id":61631978}],"con":true,"img":false}]}
{"op":"mcm","clk":"11450255550","pt":1717319686037,"mc":[{"id":"1.229554906","rc":[{"atl":[[44,3.92]],"id":42269942},{"atb":[[2.74,28.74]],"id":57451148}],"con":true,"img":false}]}
{"op":"mcm","clk":"11450255560","pt":1717319686140,"mc":[{"id":"1.229554906","rc":[{"atb":[[1.6,33.33]],"id":61631980}],"con":true,"img":false}]}
{"op":"mcm","clk":"11450255702","pt":1717319687952,"mc":[{"id":"1.229554906","rc":[{"atb":[[2.12,54.44],[3.5,0]],"id":42269942},{"atl":[[270,0],[36,0],[38,1],[40,0],[44,2.5],[250,0]],"id":42269942},{"atb":[[2.5,0],[2.58,49.34]],"id":57451148},{"atl":[[1.89,89.89],[2.06,94.34],[1.96,20.83]],"id":60780007},{"atb":[[2.02,35.71],[1.7,0]],"id":61631980},{"atl":[[4.3,0],[3.55,7.84],[5.9,0],[4.5,17.68],[5.1,0],[4.6,23.33],[5,0],[5.5,0]],"id":61631980},{"atb":[[1.22,415.39],[1.29,89.23],[1.17,0],[1.38,52.63]],"id":61631978}],"con":true,"img":false}]}
{"op":"mcm","clk":"11450255708","pt":1717319688050,"mc":[{"id":"1.229554906","rc":[{"atl":[[40,2.05]],"id":42269942},{"atl":[[1.89,0]],"id":60780007},{"atl":[[4.5,5.71],[3.65,17.68]],"id":61631980}],"con":true,"img":false}]}
{"op":"mcm","clk":"11450255715","pt":1717319688153,"mc":[{"id":"1.229554906","rc":[{"atl":[[1.91,87.91]],"id":60780007}],"con":true,"img":false}]}
{"op":"mcm","clk":"11450255740","pt":1717319688416,"mc":[{"id":"1.229554906","rc":[{"trd":[[38,7.23]],"ltp":38.0,"tv":7.23,"id":42269942},{"atl":[[38,0]],"id":42269942}],"con":true,"img":false}]}
{"op":"mcm","clk":"11450255769","pt":1717319688727,"mc":[{"id":"1.229554906","rc":[{"atl":[[11,4.61],[13,0]],"id":57451148},{"atb":[[1.6,0]],"id":61631980}],"con":true,"img":false}]}
{"op":"mcm","clk":"11450255787","pt":1717319688936,"mc":[{"id":"1.229554906","rc":[{"atb":[[11,2.81]],"id":42269942},{"atl":[[2.6,0]],"id":61631978}],"con":true,"img":false}]}
{"op":"mcm","clk":"11450255800","pt":1717319689042,"mc":[{"id":"1.229554906","rc":[{"atb":[[10,0]],"id":42269942},{"atl":[[2.64,60.98]],"id":61631978}],"con":true,"img":false}]}
{"op":"mcm","clk":"11450255808","pt":1717319689140,"mc":[{"id":"1.229554906","rc":[{"atl":[[2.66,45.18],[2.62,60.98]],"id":61631978}],"con":true,"img":false}]}
{"op":"mcm","clk":"11450255875","pt":1717319689718,"mc":[{"id":"1.229554906","rc":[{"atl":[[2.6,50]],"id":61631978}],"con":true,"img":false}]}
{"op":"mcm","clk":"11450255888","pt":1717319689821,"mc":[{"id":"1.229554906","rc":[{"trd":[[3.1,5.84]],"ltp":3.1,"tv":5.84,"id":61631980},{"atl":[[2.64,12.2]],"id":61631978}],"con":true,"img":false}]}
{"op":"mcm","clk":"11450255897","pt":1717319689929,"mc":[{"id":"1.229554906","rc":[{"atl":[[1.96,30.67]],"id":60780007},{"atb":[[2.3,2.92],[1.37,6.61]],"id":61631980}],"con":true,"img":false}]}
{"op":"mcm","clk":"11450255908","pt":1717319690031,"mc":[{"id":"1.229554906","rc":[{"atb":[[10,6.83]],"id":42269942},{"atb":[[2.3,0],[1.37,0]],"id":61631980}],"con":true,"img":false}]}
{"op":"mcm","clk":"11450255915","pt":1717319690129,"mc":[{"id":"1.229554906","rc":[{"atb":[[2.3,10.1]],"id":61631980}],"con":true,"img":false}]}
{"op":"mcm","clk":"11450255928","pt":1717319690234,"mc":[{"id":"1.229554906","rc":[{"atb":[[1.6,33.33],[2.28,2.5]],"id":61631980}],"con":true,"img":false}]}
{"op":"mcm","clk":"11450255936","pt":1717319690340,"mc":[{"id":"1.229554906","rc":[{"atl":[[3.35,4.14]],"id":61631980}],"con":true,"img":false}]}
{"op":"mcm","clk":"11450255966","pt":1717319690656,"mc":[{"id":"1.229554906","rc":[{"atb":[[6.4,4.3],[5.2,8.29]],"id":42269942},{"atb":[[3.2,10.55],[2.88,18.53]],"id":57451148},{"atb":[[1.73,47.72],[1.83,27.98]],"id":61631980},{"atl":[[7.4,0.08]],"id":61631980},{"atb":[[1.62,37.46],[1.52,67]],"id":61631978},{"atl":[[5.8,0.1]],"id":61631978}],"con":true,"img":false}]}
{"op":"mcm","clk":"11450255976","pt":1717319690759,"mc":[{"id":"1.229554906","rc":[{"atb":[[3.2,25.97]],"id":57451148}],"con":true,"img":false}]}
{"op":"mcm","clk":"11450255983","pt":1717319690857,"mc":[{"id":"1.229554906","rc":[{"atl":[[38,1],[42,1],[46,1.19],[50,1.82]],"id":42269942}],"con":true,"img":false}]}
{"op":"mcm","clk":"11450255993","pt":1717319690912,"mc":[{"id":"1.229554906","rc":[{"atb":[[2.86,0]],"id":57451148}],"con":true,"img":false}]}
{"op":"mcm","clk":"11450256019","pt":1717319691226,"mc":[{"id":"1.229554906","rc":[{"atl":[[1.96,20.83],[1.93,0]],"id":60780007}],"con":true,"img":false}]}
{"op":"mcm","clk":"11450256074","pt":1717319691848,"mc":[{"id":"1.229554906","rc":[{"atb":[[1.61,2.22]],"id":61631980}],"con":true,"img":false}]}
{"op":"mcm","clk":"11450256112","pt":1717319692360,"mc":[{"id":"1.229554906","rc":[{"atl":[[1.95,0]],"id":60780007}],"con":true,"img":false}]}
{"op":"mcm","clk":"11450256150","pt":1717319692823,"mc":[{"id":"1.229554906","rc":[{"atb":[[1.28,12.76]],"id":61631978}],"con":true,"img":false}]}
{"op":"mcm","clk":"11450256164","pt":1717319693030,"mc":[{"id":"1.229554906","rc":[{"atb":[[11.5,3.64]],"id":42269942}],"con":true,"img":false}]}
{"op":"mcm","clk":"11450256173","pt":1717319693136,"mc":[{"id":"1.229554906","rc":[{"atb":[[10.5,0]],"id":42269942}],"con":true,"img":false}]}
{"op":"mcm","clk":"11450256190","pt":1717319693345,"mc":[{"id":"1.229554906","rc":[{"atl":[[80,2.53],[95,0]],"id":42269942},{"atl":[[2.06,0],[1.91,129.76]],"id":60780007},{"atb":[[1.6,0],[1.56,0]],"id":61631980},{"atl":[[3.55,17.61],[3.65,0]],"id":61631980}],"con":true,"img":false}]}
{"op":"mcm","clk":"11450256195","pt":1717319693445,"mc":[{"id":"1.229554906","rc":[{"atl":[[2.64,73.18],[2.62,0]],"id":61631978}],"con":true,"img":false}]}
{"op":"mcm","clk":"11450256244","pt":1717319694162,"mc":[{"id":"1.229554906","rc":[{"atl":[[1.98,51.02]],"id":60780007},{"atb":[[1.28,0]],"id":61631978},{"atl":[[2.68,29.76]],"id":61631978}],"con":true,"img":false}]}
{"op":"mcm","clk":"11450256253","pt":1717319694265,"mc":[{"id":"1.229554906","rc":[{"atl":[[2.64,12.2],[2.56,51.28],[2.66,105.42]],"id":61631978}],"con":true,"img":false}]}
{"op":"mcm","clk":"11450256263","pt":1717319694372,"mc":[{"id":"1.229554906","rc":[{"atl":[[2.6,0]],"id":61631978}],"con":true,"img":false}]}
{"op":"mcm","clk":"11450256374","pt":1717319695783,"mc":[{"id":"1.229554906","rc":[{"atb":[[6,18.34]],"id":42269942},{"atb":[[1.7,125.96]],"id":57451148},{"atl":[[16.5,14.56]],"id":57451148},{"atl":[[3.2,92.29]],"id":60780007},{"atl":[[10,45.9]],"id":61631980},{"atl":[[6.6,52.02]],"id":61631978}],"con":true,"img":false}]}
{"op":"mcm","clk":"11450256386","pt":1717319695864,"mc":[{"id":"1.229554906","rc":[{"atb":[[6.8,0]],"id":42269942},{"atb":[[1.84,0]],"id":57451148},{"atb":[[1.05,334.21]],"id":60780007},{"atl":[[2.72,0]],"id":60780007},{"atl":[[8,0]],"id":61631980},{"atb":[[1.26,157.64]],"id":61631978},{"atl":[[5.1,0]],"id":61631978}],"con":true,"img":false}]}
{"op":"mcm","clk":"11450256435","pt":1717319696332,"mc":[{"id":"1.229554906","rc":[{"trd":[[3.1,11.68]],"ltp":3.1,"tv":11.68,"id":61631980}],"con":true,"img":false}]}
{"op":"mcm","clk":"11450256446","pt":1717319696433,"mc":[{"id":"1.229554906","rc":[{"atl":[[3.15,2.92],[3.65,18.87]],"id":61631980}],"con":true,"img":false}]}
{"op":"mcm","clk":"11450256457","pt":1717319696536,"mc":[{"id":"1.229554906","rc":[{"atl":[[3.55,7.84],[3.3,17.61],[3.15,8.22]],"id":61631980}],"con":true,"img":false}]}
{"op":"mcm","clk":"11450256468","pt":1717319696655,"mc":[{"id":"1.229554906","rc":[{"atl":[[3.2,4.63],[3.15,5.3]],"id":61631980}],"con":true,"img":false}]}
{"op":"mcm","clk":"11450256486","pt":1717319696850,"mc":[{"id":"1.229554906","rc":[{"atl":[[3.3,19.97]],"id":61631980}],"con":true,"img":false}]}
{"op":"mcm","clk":"11450256604","pt":1717319698238,"mc":[{"id":"1.229554906","rc":[{"atb":[[12,2.43]],"id":42269942},{"trd":[[38,8.92]],"ltp":38.0,"tv":8.92,"id":42269942},{"atl":[[38,0.15]],"id":42269942}],"con":true,"img":false}]}
{"op":"mcm","clk":"11450256624","pt":1717319698444,"mc":[{"id":"1.229554906","rc":[{"atb":[[11,0]],"id":42269942}],"con":true,"img":false}]}
{"op":"mcm","clk":"11450256692","pt":1717319699270,"mc":[{"id":"1.229554906","rc":[{"atl":[[4.8,0],[4.6,2.5]],"id":61631980}],"con":true,"img":false}]}
{"op":"mcm","clk":"11450256777","pt":1717319700262,"mc":[{"id":"1.229554906","rc":[{"atb":[[1.01,5807.26],[1.03,0],[1.02,8.87],[1.06,0],[1.1,0],[1.04,0]],"id":60780007},{"atl":[[1.98,0],[1.91,41.85],[1.96,0]],"id":60780007},{"atb":[[2.3,0],[2.28,0],[2.12,0],[2.2,0]],"id":61631980},{"atl":[[4.6,0],[3.15,0]],"id":61631980},{"atb":[[1.2,0],[1.27,0],[1.25,0],[1.23,0],[1.29,0],[1.24,0],[1.38,0]],"id":61631978},{"atl":[[2.56,0],[3.35,0],[2.64,0],[2.66,60.24],[3.55,0],[2.68,0],[3.75,0]],"id":61631978}],"con":true,"img":false}]}
{"op":"mcm","clk":"11450256782","pt":1717319700360,"mc":[{"id":"1.229554906","rc":[{"atb":[[11.5,0],[8.4,0]],"id":42269942},{"atl":[[40,0],[44,0],[55,0]],"id":42269942},{"atb":[[3.2,10.55]],"id":57451148},{"atl":[[5,7]],"id":57451148}],"con":true,"img":false}]}
{"op":"mcm","clk":"11450256797","pt":1717319700471,"mc":[{"id":"1.229554906","rc":[{"atb":[[12,0]],"id":42269942},{"atb":[[2.8,0],[2.72,0],[2.64,0]],"id":57451148}],"con":true,"img":false}]}
{"op":"mcm","clk":"11450256841","pt":1717319700936,"mc":[{"id":"1.229554906","rc":[{"atl":[[130,3.54],[110,0]],"id":42269942},{"atb":[[1.61,0]],"id":61631980},{"atl":[[6.2,8.04],[4.7,0]],"id":61631980}],"con":true,"img":false}]}
{"op":"mcm","clk":"11450256853","pt":1717319701044,"mc":[{"id":"1.229554906","rc":[{"atb":[[10.5,2.2]],"id":42269942},{"atb":[[2.02,0],[1.84,71.42]],"id":61631980},{"atl":[[3.35,28.74],[3.3,2.36]],"id":61631980}],"con":true,"img":false}]}
{"op":"mcm","clk":"11450256877","pt":1717319701250,"mc":[{"id":"1.229554906","rc":[{"atb":[[1.5,264.45]],"id":61631980}],"con":true,"img":false}]}
{"op":"mcm","clk":"11450256904","pt":1717319701463,"mc":[{"id":"1.229554906","rc":[{"atb":[[1.01,33106.53],[1.19,1742.45]],"id":42269942},{"atb":[[1.01,33106.53],[1.09,3678.5]],"id":57451148},{"atb":[[1.01,72020.34],[1.06,48.8]],"id":60780007},{"atb":[[1.01,33124.3],[1.5,250],[1.05,6621.3]],"id":61631980},{"atb":[[1.01,33124.3],[1.03,11035.51]],"id":61631978}],"con":true,"img":false}]}
{"op":"mcm","clk":"11450256915","pt":1717319701567,"mc":[{"id":"1.229554906","rc":[{"atl":[[2.66,0],[2.96,51.02]],"id":61631978}],"con":true,"img":false}]}
{"op":"mcm","clk":"11450256959","pt":1717319701993,"mc":[{"id":"1.229554906","rc":[{"atl":[[38,0],[42,0],[46,0],[50,0]],"id":42269942},{"atb":[[2.48,0],[2.74,0],[2.52,0],[2.78,0]],"id":57451148},{"atl":[[8,0]],"id":57451148},{"atb":[[1.54,0],[1.5,0]],"id":61631980},{"atl":[[4.5,0],[3.2,0],[3.35,24.6],[3.55,0],[3.3,0],[3.65,0]],"id":61631980}],"con":true,"img":false}]}
{"op":"mcm","clk":"11450256984","pt":1717319702197,"mc":[{"id":"1.229554906","rc":[{"atb":[[2.12,0],[4.2,31.25]],"id":42269942},{"atl":[[80,0.53],[120,2]],"id":42269942},{"atl":[[1.91,0],[2.1,83.7]],"id":60780007}],"con":true,"img":false}]}
{"op":"mcm","clk":"11450256996","pt":1717319702257,"mc":[{"id":"1.229554906","rc":[{"atl":[[4.5,3.1]],"id":61631978}],"con":true,"img":false}]}
{"op":"mcm","clk":"11450257008","pt":1717319702353,"mc":[{"id":"1.229554906","rc":[{"atl":[[4.5,0]],"id":61631978}],"con":true,"img":false}]}
{"op":"mcm","clk":"11450257188","pt":1717319703966,"mc":[{"id":"1.229554906","rc":[{"atb":[[1.93,6.26]],"id":57451148}],"con":true,"img":false}]}
{"op":"mcm","clk":"11450257208","pt":1717319704168,"mc":[{"id":"1.229554906","rc":[{"atb":[[12,2.61]],"id":42269942}],"con":true,"img":false}]}
{"op":"mcm","clk":"11450257220","pt":1717319704269,"mc":[{"id":"1.229554906","rc":[{"atb":[[9.8,0]],"id":42269942}],"con":true,"img":false}]}
{"op":"mcm","clk":"11450257300","pt":1717319705154,"mc":[{"id":"1.229554906","rc":[{"atl":[[3.35,0],[6,20]],"id":61631980}],"con":true,"img":false}]}
{"op":"mcm","clk":"11450257342","pt":1717319705668,"mc":[{"id":"1.229554906","rc":[{"atl":[[3.2,45.45],[2.96,0]],"id":61631978}],"con":true,"img":false}]}
{"op":"mcm","clk":"11450257362","pt":1717319705876,"mc":[{"id":"1.229554906","rc":[{"atl":[[80,0]],"id":42269942}],"con":true,"img":false}]}
{"op":"mcm","clk":"11450257371","pt":1717319705925,"mc":[{"id":"1.229554906","rc":[{"atl":[[100,0.53]],"id":42269942}],"con":true,"img":false}]}
{"op":"mcm","clk":"11450257401","pt":1717319706343,"mc":[{"id":"1.229554906","rc":[{"atl":[[6.2,0]],"id":61631980}],"con":true,"img":false}]}
{"op":"mcm","clk":"11450257410","pt":1717319706447,"mc":[{"id":"1.229554906","rc":[{"atl":[[7.4,8.13]],"id":61631980}],"con":true,"img":false}]}
{"op":"mcm","clk":"11450257473","pt":1717319707174,"mc":[{"id":"1.229554906","rc":[{"atb":[[10,0],[12.5,3.92]],"id":42269942}],"con":true,"img":false}]}
{"op":"mcm","clk":"11450257480","pt":1717319707274,"mc":[{"id":"1.229554906","rc":[{"atb":[[4.2,0],[3.75,36.36]],"id":42269942},{"atb":[[1.93,0]],"id":57451148},{"atb":[[1.27,370.37],[1.22,0]],"id":61631978},{"atl":[[3.2,0],[3.15,13.5]],"id":61631978}],"con":true,"img":false}]}
{"op":"mcm","clk":"11450257491","pt":1717319707378,"mc":[{"id":"1.229554906","rc":[{"atl":[[1.91,41.85],[2.1,0]],"id":60780007},{"atl":[[3.15,0],[3.55,39.22]],"id":61631978}],"con":true,"img":false}]}
{"op":"mcm","clk":"11450257499","pt":1717319707480,"mc":[{"id":"1.229554906","rc":[{"atb":[[13,2.41]],"id":42269942},{"atl":[[2.46,9.84]],"id":60780007}],"con":true,"img":false}]}
{"op":"mcm","clk":"11450257506","pt":1717319707583,"mc":[{"id":"1.229554906","rc":[{"atb":[[10.5,0]],"id":42269942}],"con":true,"img":false}]}
{"op":"mcm","clk":"11450257528","pt":1717319707842,"mc":[{"id":"1.229554906","rc":[{"atb":[[3.2,28.88]],"id":57451148},{"atl":[[5,13.32]],"id":57451148},{"atl":[[1.92,62.78]],"id":60780007},{"atb":[[1.84,92.34]],"id":61631980},{"atl":[[6,33.6]],"id":61631980},{"atb":[[1.62,58.39]],"id":61631978},{"atl":[[3.15,20.92]],"id":61631978}],"con":true,"img":false}]}
{"op":"mcm","clk":"11450257548","pt":1717319708049,"mc":[{"id":"1.229554906","rc":[{"atl":[[3.1,20.93],[3.55,0]],"id":61631978}],"con":true,"img":false}]}
{"op":"mcm","clk":"11450257651","pt":1717319709286,"mc":[{"id":"1.229554906","rc":[{"atb":[[1.28,12.76]],"id":61631978}],"con":true,"img":false}]}
{"op":"mcm","clk":"11450257927","pt":1717319712397,"mc":[{"id":"1.229554906","rc":[{"atb":[[4,33.33],[3.75,0]],"id":42269942}],"con":true,"img":false}]}
{"op":"mcm","clk":"11450257957","pt":1717319712655,"mc":[{"id":"1.229554906","rc":[{"atl":[[1.92,41.85]],"id":60780007},{"atl":[[3.15,0]],"id":61631978}],"con":true,"img":false}]}
{"op":"mcm","clk":"11450257977","pt":1717319712863,"mc":[{"id":"1.229554906","rc":[{"atl":[[1.91,62.77]],"id":60780007},{"atl":[[3.1,20.92],[3.5,40]],"id":61631978}],"con":true,"img":false}]}
{"op":"mcm","clk":"11450258244","pt":1717319715512,"mc":[{"id":"1.229554906","rc":[{"atb":[[6.4,0],[5.2,0]],"id":42269942},{"atb":[[3.2,18.32],[2.88,0]],"id":57451148},{"atb":[[1.01,66213.07]],"id":60780007},{"atl":[[2.3,0]],"id":60780007},{"atb":[[1.73,0],[1.83,0]],"id":61631980},{"atl":[[7.4,8.04]],"id":61631980},{"atb":[[1.62,20.92],[1.52,0]],"id":61631978},{"atl":[[5.8,0]],"id":61631978}],"con":true,"img":false}]}
{"op":"mcm","clk":"11450258276","pt":1717319715770,"mc":[{"id":"1.229554906","rc":[{"atb":[[2.06,3.29]],"id":57451148},{"atl":[[1.92,0]],"id":60780007},{"atb":[[1.56,6.35]],"id":61631980}],"con":true,"img":false}]}
{"op":"mcm","clk":"11450258288","pt":1717319715878,"mc":[{"id":"1.229554906","rc":[{"atl":[[2.4,41.85]],"id":60780007}],"con":true,"img":false}]}
{"op":"mcm","clk":"11450258338","pt":1717319716287,"mc":[{"id":"1.229554906","rc":[{"atl":[[2.46,0]],"id":60780007}],"con":true,"img":false}]}
{"op":"mcm","clk":"11450258413","pt":1717319717174,"mc":[{"id":"1.229554906","rc":[{"atb":[[1.65,14.45]],"id":61631980}],"con":true,"img":false}]}
{"op":"mcm","clk":"11450258453","pt":1717319717493,"mc":[{"id":"1.229554906","rc":[{"atb":[[4,0],[3.15,46.51]],"id":42269942}],"con":true,"img":false}]}
{"op":"mcm","clk":"11450258508","pt":1717319718013,"mc":[{"id":"1.229554906","rc":[{"atb":[[1.23,500]],"id":42269942},{"atb":[[1.23,500]],"id":57451148},{"atb":[[1.23,500]],"id":61631980},{"atl":[[3.5,0],[3.05,20.93]],"id":61631978}],"con":true,"img":false}]}
{"op":"mcm","clk":"11450258528","pt":1717319718170,"mc":[{"id":"1.229554906","rc":[{"atl":[[5,3.31]],"id":61631978}],"con":true,"img":false}]}
{"op":"mcm","clk":"11450258571","pt":1717319718588,"mc":[{"id":"1.229554906","rc":[{"atb":[[12,0]],"id":42269942}],"con":true,"img":false}]}
{"op":"mcm","clk":"11450258579","pt":1717319718694,"mc":[{"id":"1.229554906","rc":[{"atb":[[10.5,2.61]],"id":42269942}],"con":true,"img":false}]}
{"op":"mcm","clk":"11450258700","pt":1717319719781,"mc":[{"id":"1.229554906","rc":[{"atb":[[1.93,6.47]],"id":57451148}],"con":true,"img":false}]}
{"op":"mcm","clk":"11450258805","pt":1717319720661,"mc":[{"id":"1.229554906","rc":[{"atb":[[1.65,0]],"id":61631980}],"con":true,"img":false}]}
{"op":"mcm","clk":"11450258941","pt":1717319722105,"mc":[{"id":"1.229554906","rc":[{"atl":[[2.46,9.84]],"id":60780007}],"con":true,"img":false}]}
{"op":"mcm","clk":"11450258948","pt":1717319722158,"mc":[{"id":"1.229554906","rc":[{"atl":[[130,0],[160,2.61]],"id":42269942},{"atl":[[3.1,0]],"id":61631978}],"con":true,"img":false}]}
{"op":"mcm","clk":"11450258955","pt":1717319722262,"mc":[{"id":"1.229554906","rc":[{"atl":[[3.5,40]],"id":61631978}],"con":true,"img":false}]}
{"op":"mcm","clk":"11450258962","pt":1717319722367,"mc":[{"id":"1.229554906","rc":[{"atl":[[150,2],[120,0]],"id":42269942},{"atl":[[3.05,20.92]],"id":61631978}],"con":true,"img":false}]}
{"op":"mcm","clk":"11450258973","pt":1717319722469,"mc":[{"id":"1.229554906","rc":[{"atb":[[12.5,0]],"id":42269942}],"con":true,"img":false}]}
{"op":"mcm","clk":"11450258982","pt":1717319722570,"mc":[{"id":"1.229554906","rc":[{"atb":[[11,10.49],[13,0]],"id":42269942}],"con":true,"img":false}]}
{"op":"mcm","clk":"11450258994","pt":1717319722680,"mc":[{"id":"1.229554906","rc":[{"atb":[[11.5,2.62]],"id":42269942}],"con":true,"img":false}]}
{"op":"mcm","clk":"11450259019","pt":1717319722889,"mc":[{"id":"1.229554906","rc":[{"atb":[[1.93,0]],"id":57451148},{"atl":[[8.2,12],[7,0]],"id":57451148},{"atl":[[2.46,0]],"id":60780007},{"atl":[[5,0]],"id":61631978}],"con":true,"img":false}]}
{"op":"mcm","clk":"11450259276","pt":1717319725270,"mc":[{"id":"1.229554906","rc":[{"atb":[[1.05,1187.61]],"id":60780007}],"con":true,"img":false}]}
{"op":"mcm","clk":"11450259313","pt":1717319725681,"mc":[{"id":"1.229554906","rc":[{"atl":[[100,0]],"id":42269942}],"con":true,"img":false}]}
{"op":"mcm","clk":"11450259324","pt":1717319725791,"mc":[{"id":"1.229554906","rc":[{"atl":[[150,0],[160,4.61],[110,0.53]],"id":42269942}],"con":true,"img":false}]}
{"op":"mcm","clk":"11450259454","pt":1717319727182,"mc":[{"id":"1.229554906","rc":[{"atb":[[5.3,8.1],[6.6,4.14]],"id":42269942},{"atb":[[2.9,18.33],[3.25,10.32]],"id":57451148},{"atb":[[1.01,72020.34]],"id":60780007},{"atl":[[2.32,0.39]],"id":60780007},{"atb":[[1.66,52.79],[1.76,30.56]],"id":61631980},{"atl":[[7,0.08]],"id":61631980},{"atb":[[1.62,58.39],[1.52,67]],"id":61631978},{"atl":[[5.8,0.1]],"id":61631978}],"con":true,"img":false}]}
{"op":"mcm","clk":"11450259487","pt":1717319727501,"mc":[{"id":"1.229554906","rc":[{"atl":[[3,20.93],[3.5,0]],"id":61631978}],"con":true,"img":false}]}
{"op":"mcm","clk":"11450259496","pt":1717319727606,"mc":[{"id":"1.229554906","rc":[{"atb":[[1.01,82020.34]],"id":60780007}],"con":true,"img":false}]}
{"op":"mcm","clk":"11450259736","pt":1717319730708,"mc":[{"id":"1.229554906","rc":[{"atl":[[7.4,0]],"id":61631980},{"atl":[[3.45,19.57],[4.1,0]],"id":61631978}],"con":true,"img":false}]}
{"op":"mcm","clk":"11450259746","pt":1717319730807,"mc":[{"id":"1.229554906","rc":[{"atl":[[5.9,8.04]],"id":61631980}],"con":true,"img":false}]}
{"op":"mcm","clk":"11450259753","pt":1717319730909,"mc":[{"id":"1.229554906","rc":[{"atl":[[5.8,8.05],[6,13.6]],"id":61631980}],"con":true,"img":false}]}
{"op":"mcm","clk":"11450259795","pt":1717319731375,"mc":[{"id":"1.229554906","rc":[{"atb":[[1.65,14.45]],"id":61631980}],"con":true,"img":false}]}
{"op":"mcm","clk":"11450259805","pt":1717319731476,"mc":[{"id":"1.229554906","rc":[{"atb":[[3.2,0]],"id":57451148},{"atl":[[6,0]],"id":61631980},{"atl":[[3.05,0]],"id":61631978}],"con":true,"img":false}]}
{"op":"mcm","clk":"11450259817","pt":1717319731583,"mc":[{"id":"1.229554906","rc":[{"atl":[[3,0],[3.4,41.67]],"id":61631978}],"con":true,"img":false}]}
{"op":"mcm","clk":"11450259826","pt":1717319731686,"mc":[{"id":"1.229554906","rc":[{"atb":[[3.25,27.43]],"id":57451148},{"atl":[[5.9,21.92]],"id":61631980},{"atl":[[3,20.92]],"id":61631978}],"con":true,"img":false}]}
{"op":"mcm","clk":"11450259884","pt":1717319732304,"mc":[{"id":"1.229554906","rc":[{"atl":[[5,3.1]],"id":61631978}],"con":true,"img":false}]}
{"op":"mcm","clk":"11450260079","pt":1717319734174,"mc":[{"id":"1.229554906","rc":[{"atl":[[140,0.34],[110,0]],"id":42269942}],"con":true,"img":false}]}
{"op":"mcm","clk":"11450260134","pt":1717319734795,"mc":[{"id":"1.229554906","rc":[{"atb":[[2.08,9.57]],"id":57451148}],"con":true,"img":false}]}
{"op":"mcm","clk":"11450260223","pt":1717319735776,"mc":[{"id":"1.229554906","rc":[{"atb":[[1.04,449.71]],"id":60780007},{"atb":[[1.22,200.75]],"id":61631978}],"con":true,"img":false}]}
{"op":"mcm","clk":"11450260235","pt":1717319735932,"mc":[{"id":"1.229554906","rc":[{"atb":[[10.5,0]],"id":42269942},{"atb":[[1.06,0],[1.05,0]],"id":60780007},{"atl":[[5.9,13.87]],"id":61631980},{"atb":[[1.26,0]],"id":61631978}],"con":true,"img":false}]}
{"op":"mcm","clk":"11450260240","pt":1717319735981,"mc":[{"id":"1.229554906","rc":[{"atb":[[11.5,5.23]],"id":42269942},{"atl":[[2.46,9.84]],"id":60780007},{"atl":[[7.4,8.04]],"id":61631980}],"con":true,"img":false}]}
{"op":"mcm","clk":"11450260259","pt":1717319736192,"mc":[{"id":"1.229554906","rc":[{"atl":[[5.9,0]],"id":61631980}],"con":true,"img":false}]}
{"op":"mcm","clk":"11450260267","pt":1717319736296,"mc":[{"id":"1.229554906","rc":[{"atl":[[140,0.7]],"id":42269942},{"atl":[[7.2,8.14],[5.8,14.16]],"id":61631980}],"con":true,"img":false}]}
{"op":"mcm","clk":"11450260308","pt":1717319736712,"mc":[{"id":"1.229554906","rc":[{"atl":[[3.4,0],[2.98,20.93]],"id":61631978}],"con":true,"img":false}]}
{"op":"mcm","clk":"11450260350","pt":1717319737128,"mc":[{"id":"1.229554906","rc":[{"atb":[[1.05,84.54]],"id":60780007}],"con":true,"img":false}]}
{"op":"mcm","clk":"11450260397","pt":1717319737697,"mc":[{"id":"1.229554906","rc":[{"atl":[[2.46,0]],"id":60780007}],"con":true,"img":false}]}
{"op":"mcm","clk":"11450260405","pt":1717319737802,"mc":[{"id":"1.229554906","rc":[{"spn":75.75,"spf":"NaN","id":42269942},{"atb":[[2.08,0]],"id":57451148},{"spn":4.12,"spf":"NaN","id":57451148},{"spn":1.48,"spf":"NaN","id":60780007},{"spn":3.82,"spf":"NaN","id":61631980},{"spn":2.3,"spf":"NaN","id":61631978}],"con":true,"img":false}]}
{"op":"mcm","clk":"11450260436","pt":1717319738164,"mc":[{"id":"1.229554906","rc":[{"atb":[[11,0],[12,3.38]],"id":42269942}],"con":true,"img":false}]}
{"op":"mcm","clk":"11450260443","pt":1717319738279,"mc":[{"id":"1.229554906","rc":[{"atb":[[12.5,3.76]],"id":42269942}],"con":true,"img":false}]}
{"op":"mcm","clk":"11450260463","pt":1717319738547,"mc":[{"id":"1.229554906","rc":[{"atb":[[11.5,2.61]],"id":42269942}],"con":true,"img":false}]}
{"op":"mcm","clk":"11450260542","pt":1717319739404,"mc":[{"id":"1.229554906","rc":[{"atb":[[5.4,22.73],[3.15,0]],"id":42269942}],"con":true,"img":false}]}
{"op":"mcm","clk":"11450260673","pt":1717319740909,"mc":[{"id":"1.229554906","rc":[{"atl":[[3,0]],"id":61631978}],"con":true,"img":false}]}
{"op":"mcm","clk":"11450260695","pt":1717319741115,"mc":[{"id":"1.229554906","rc":[{"atl":[[3.4,41.67],[2.98,20.92]],"id":61631978}],"con":true,"img":false}]}
{"op":"mcm","clk":"11450260721","pt":1717319741376,"mc":[{"id":"1.229554906","rc":[{"atl":[[5.7,8.14]],"id":61631980}],"con":true,"img":false}]}
{"op":"mcm","clk":"11450260730","pt":1717319741474,"mc":[{"id":"1.229554906","rc":[{"atl":[[7.2,0]],"id":61631980}],"con":true,"img":false}]}
{"op":"mcm","clk":"11450260752","pt":1717319741786,"mc":[{"id":"1.229554906","rc":[{"atl":[[2.96,20.93]],"id":61631978}],"con":true,"img":false}]}
{"op":"mcm","clk":"11450260771","pt":1717319741992,"mc":[{"id":"1.229554906","rc":[{"atl":[[3.4,0]],"id":61631978}],"con":true,"img":false}]}
{"op":"mcm","clk":"11450260779","pt":1717319742098,"mc":[{"id":"1.229554906","rc":[{"atl":[[5,0]],"id":61631978}],"con":true,"img":false}]}
{"op":"mcm","clk":"11450260891","pt":1717319743181,"mc":[{"id":"1.229554906","rc":[{"atb":[[2.44,69.44],[2.58,0]],"id":57451148},{"atb":[[1.01,72020.34],[1.03,3333.33]],"id":60780007},{"atb":[[1.27,0],[1.35,200.75]],"id":61631978}],"con":true,"img":false}]}
{"op":"mcm","clk":"11450260913","pt":1717319743392,"mc":[{"id":"1.229554906","rc":[{"atb":[[1.28,0]],"id":61631978}],"con":true,"img":false}]}
{"op":"mcm","clk":"11450260921","pt":1717319743492,"mc":[{"id":"1.229554906","rc":[{"atb":[[1.28,12.76]],"id":61631978}],"con":true,"img":false}]}
{"op":"mcm","clk":"11450261077","pt":1717319745206,"mc":[{"id":"1.229554906","rc":[{"atl":[[4.7,12.14]],"id":61631978}],"con":true,"img":false}]}
{"op":"mcm","clk":"11450261089","pt":1717319745316,"mc":[{"id":"1.229554906","rc":[{"atb":[[2.06,0]],"id":57451148},{"atl":[[3.45,0]],"id":61631978}],"con":true,"img":false}]}
{"op":"mcm","clk":"11450261130","pt":1717319745783,"mc":[{"id":"1.229554906","rc":[{"atl":[[5.8,0]],"id":61631980},{"atl":[[2.98,0],[4.7,0]],"id":61631978}],"con":true,"img":false}]}
{"op":"mcm","clk":"11450261137","pt":1717319745881,"mc":[{"id":"1.229554906","rc":[{"atl":[[5.2,12.14]],"id":61631978}],"con":true,"img":false}]}
{"op":"mcm","clk":"11450261145","pt":1717319745985,"mc":[{"id":"1.229554906","rc":[{"atl":[[7.2,8.23],[5.7,14.47]],"id":61631980},{"atl":[[2.96,20.92],[4.7,27.03]],"id":61631978}],"con":true,"img":false}]}
{"op":"mcm","clk":"11450261179","pt":1717319746502,"mc":[{"id":"1.229554906","rc":[{"atl":[[5.6,8.23],[7.2,0]],"id":61631980}],"con":true,"img":false}]}
{"op":"mcm","clk":"11450261199","pt":1717319746712,"mc":[{"id":"1.229554906","rc":[{"atl":[[5,3.1]],"id":61631978}],"con":true,"img":false}]}
{"op":"mcm","clk":"11450261209","pt":1717319746813,"mc":[{"id":"1.229554906","rc":[{"atb":[[1.28,0]],"id":61631978},{"atl":[[2.94,20.93]],"id":61631978}],"con":true,"img":false}]}
{"op":"mcm","clk":"11450261215","pt":1717319746915,"mc":[{"id":"1.229554906","rc":[{"atl":[[4.7,0]],"id":61631978}],"con":true,"img":false}]}
{"op":"mcm","clk":"11450261367","pt":1717319748623,"mc":[{"id":"1.229554906","rc":[{"atb":[[4.8,26.32],[5.4,0]],"id":42269942}],"con":true,"img":false}]}
{"op":"mcm","clk":"11450261405","pt":1717319749087,"mc":[{"id":"1.229554906","rc":[{"atb":[[1.92,9.57]],"id":57451148}],"con":true,"img":false}]}
{"op":"mcm","clk":"11450261414","pt":1717319749192,"mc":[{"id":"1.229554906","rc":[{"atl":[[2.46,9.84]],"id":60780007}],"con":true,"img":false}]}
{"op":"mcm","clk":"11450261489","pt":1717319750220,"mc":[{"id":"1.229554906","rc":[{"atl":[[6.6,0]],"id":61631978}],"con":true,"img":false}]}
{"op":"mcm","clk":"11450261495","pt":1717319750323,"mc":[{"id":"1.229554906","rc":[{"atl":[[7.6,52.02]],"id":61631978}],"con":true,"img":false}]}
{"op":"mcm","clk":"11450261521","pt":1717319750685,"mc":[{"id":"1.229554906","rc":[{"atl":[[5.7,0]],"id":61631980},{"atl":[[2.96,0]],"id":61631978}],"con":true,"img":false}]}
{"op":"mcm","clk":"11450261529","pt":1717319750788,"mc":[{"id":"1.229554906","rc":[{"atl":[[7.2,8.32]],"id":61631980},{"atl":[[2.94,0],[4.7,27.03]],"id":61631978}],"con":true,"img":false}]}
{"op":"mcm","clk":"11450261535","pt":1717319750891,"mc":[{"id":"1.229554906","rc":[{"atb":[[1.92,0]],"id":57451148},{"atl":[[5.6,14.78]],"id":61631980},{"atl":[[5,0],[2.94,20.92]],"id":61631978}],"con":true,"img":false}]}
{"op":"mcm","clk":"11450261544","pt":1717319750996,"mc":[{"id":"1.229554906","rc":[{"atl":[[5.5,8.32]],"id":61631980}],"con":true,"img":false}]}
{"op":"mcm","clk":"11450261550","pt":1717319751099,"mc":[{"id":"1.229554906","rc":[{"atl":[[7.2,0]],"id":61631980}],"con":true,"img":false}]}
{"op":"mcm","clk":"11450261584","pt":1717319751614,"mc":[{"id":"1.229554906","rc":[{"atb":[[1.56,0]],"id":61631980}],"con":true,"img":false}]}
{"op":"mcm","clk":"11450261606","pt":1717319751925,"mc":[{"id":"1.229554906","rc":[{"atl":[[2.92,20.93],[4.7,0]],"id":61631978}],"con":true,"img":false}]}
{"op":"mcm","clk":"11450261663","pt":1717319752601,"mc":[{"id":"1.229554906","rc":[{"atb":[[5.3,0],[6.6,0]],"id":42269942},{"atb":[[2.9,0],[3.25,17.1]],"id":57451148},{"atb":[[1.66,0],[1.76,0]],"id":61631980},{"atl":[[7,0]],"id":61631980},{"atb":[[1.62,20.92],[1.52,0]],"id":61631978},{"atl":[[5.8,0]],"id":61631978}],"con":true,"img":false}]}
{"op":"mcm","clk":"11450261690","pt":1717319752809,"mc":[{"id":"1.229554906","rc":[{"atb":[[1.65,16.1]],"id":61631980}],"con":true,"img":false}]}
{"op":"mcm","clk":"11450261704","pt":1717319752912,"mc":[{"id":"1.229554906","rc":[{"atb":[[1.65,14.45]],"id":61631980}],"con":true,"img":false}]}
{"op":"mcm","clk":"11450261980","pt":1717319755828,"mc":[{"id":"1.229554906","rc":[{"atb":[[1.04,899.43]],"id":60780007},{"atl":[[5.6,0]],"id":61631980},{"atl":[[2.94,0]],"id":61631978}],"con":true,"img":false}]}
{"op":"mcm","clk":"11450261990","pt":1717319755928,"mc":[{"id":"1.229554906","rc":[{"atb":[[1.03,0],[1.05,0]],"id":60780007},{"atl":[[7.2,16.13],[5.5,15.11]],"id":61631980},{"atl":[[2.92,20.92],[4.7,27.03]],"id":61631978}],"con":true,"img":false}]}
{"op":"mcm","clk":"11450262044","pt":1717319756494,"mc":[{"id":"1.229554906","rc":[{"atb":[[1.36,10.9]],"id":61631978}],"con":true,"img":false}]}
{"op":"mcm","clk":"11450262077","pt":1717319757012,"mc":[{"id":"1.229554906","rc":[{"atb":[[1.05,52.81]],"id":60780007}],"con":true,"img":false}]}
{"op":"mcm","clk":"11450262101","pt":1717319757426,"mc":[{"id":"1.229554906","rc":[{"atb":[[1.32,12.76]],"id":61631978}],"con":true,"img":false}]}
{"op":"mcm","clk":"11450262165","pt":1717319758201,"mc":[{"id":"1.229554906","rc":[{"atb":[[1.57,13.14]],"id":61631980}],"con":true,"img":false}]}
{"op":"mcm","clk":"11450262237","pt":1717319759335,"mc":[{"id":"1.229554906","rc":[{"atl":[[5,3.1]],"id":61631978}],"con":true,"img":false}]}
{"op":"mcm","clk":"11450262248","pt":1717319759491,"mc":[{"id":"1.229554906","rc":[{"atb":[[4.8,0],[3.5,40]],"id":42269942}],"con":true,"img":false}]}
{"op":"mcm","clk":"11450262365","pt":1717319761042,"mc":[{"id":"1.229554906","rc":[{"atl":[[7.2,0],[5.4,15.11]],"id":61631980},{"atl":[[2.9,20.93],[4.7,0]],"id":61631978}],"con":true,"img":false}]}
{"op":"mcm","clk":"11450262525","pt":1717319762698,"mc":[{"id":"1.229554906","rc":[{"atb":[[1.92,9.57]],"id":57451148}],"con":true,"img":false}]}
{"op":"mcm","clk":"11450262663","pt":1717319764042,"mc":[{"id":"1.229554906","rc":[{"atb":[[1.65,0]],"id":61631980}],"con":true,"img":false}]}
{"op":"mcm","clk":"11450262721","pt":1717319764617,"mc":[{"id":"1.229554906","rc":[{"atl":[[2.46,0]],"id":60780007}],"con":true,"img":false}]}
{"op":"mcm","clk":"11450262731","pt":1717319764723,"mc":[{"id":"1.229554906","rc":[{"atb":[[5.1,8.49],[6.2,4.46]],"id":42269942},{"atb":[[3.2,10.55],[2.88,18.53]],"id":57451148},{"atl":[[2.46,9.84]],"id":60780007},{"atb":[[1.88,26.39],[1.78,44.66]],"id":61631980},{"atl":[[7.8,0.07]],"id":61631980},{"atb":[[1.44,79.18],[1.54,43.01]],"id":61631978},{"atl":[[4.9,0.13]],"id":61631978}],"con":true,"img":false}]}
{"op":"mcm","clk":"11450262745","pt":1717319764821,"mc":[{"id":"1.229554906","rc":[{"atb":[[1.89,44.67],[1.84,20.92]],"id":61631980}],"con":true,"img":false}]}
{"op":"mcm","clk":"11450262755","pt":1717319764924,"mc":[{"id":"1.229554906","rc":[{"atb":[[1.92,0]],"id":57451148},{"atb":[[1.32,0]],"id":61631978}],"con":true,"img":false}]}
{"op":"mcm","clk":"11450262818","pt":1717319765799,"mc":[{"id":"1.229554906","rc":[{"atb":[[11.5,0],[13,2.41]],"id":42269942},{"atl":[[160,2]],"id":42269942},{"atl":[[16.5,0],[19.5,15.1]],"id":57451148},{"atl":[[10,0]],"id":61631980}],"con":true,"img":false}]}
{"op":"mcm","clk":"11450262822","pt":1717319765901,"mc":[{"id":"1.229554906","rc":[{"atb":[[13.5,2.21]],"id":42269942},{"atl":[[160,0],[230,2.61],[500,2]],"id":42269942},{"atl":[[11.5,45.9]],"id":61631980}],"con":true,"img":false}]}
{"op":"mcm","clk":"11450262831","pt":1717319766006,"mc":[{"id":"1.229554906","rc":[{"atb":[[12.5,0]],"id":42269942}],"con":true,"img":false}]}
{"op":"mcm","clk":"11450262851","pt":1717319766311,"mc":[{"id":"1.229554906","rc":[{"atl":[[5.5,0]],"id":61631980},{"atl":[[2.92,0]],"id":61631978}],"con":true,"img":false}]}
{"op":"mcm","clk":"11450262857","pt":1717319766413,"mc":[{"id":"1.229554906","rc":[{"atl":[[7.2,16.13]],"id":61631980},{"atl":[[2.9,0],[4.7,27.03]],"id":61631978}],"con":true,"img":false}]}
{"op":"mcm","clk":"11450262867","pt":1717319766516,"mc":[{"id":"1.229554906","rc":[{"atl":[[5.4,15.45]],"id":61631980},{"atl":[[5,0],[2.9,20.92]],"id":61631978}],"con":true,"img":false}]}
{"op":"mcm","clk":"11450262874","pt":1717319766619,"mc":[{"id":"1.229554906","rc":[{"atl":[[5.2,15.66]],"id":61631978}],"con":true,"img":false}]}
{"op":"mcm","clk":"11450262880","pt":1717319766721,"mc":[{"id":"1.229554906","rc":[{"atl":[[7.2,12]],"id":57451148},{"atl":[[1.89,41.85],[1.91,20.92]],"id":60780007}],"con":true,"img":false}]}
{"op":"mcm","clk":"11450262890","pt":1717319766826,"mc":[{"id":"1.229554906","rc":[{"atl":[[8.2,0]],"id":57451148}],"con":true,"img":false}]}
{"op":"mcm","clk":"11450263058","pt":1717319769146,"mc":[{"id":"1.229554906","rc":[{"atl":[[5.2,12.14]],"id":61631978}],"con":true,"img":false}]}
{"op":"mcm","clk":"11450263066","pt":1717319769255,"mc":[{"id":"1.229554906","rc":[{"atb":[[1.05,78.47]],"id":60780007}],"con":true,"img":false}]}
{"op":"mcm","clk":"11450263097","pt":1717319769669,"mc":[{"id":"1.229554906","rc":[{"atb":[[12,0],[3.5,0],[4.1,32.26]],"id":42269942},{"atl":[[2.46,0]],"id":60780007}],"con":true,"img":false}]}
{"op":"mcm","clk":"11450263153","pt":1717319770533,"mc":[{"id":"1.229554906","rc":[{"atb":[[1.34,12.76]],"id":61631978}],"con":true,"img":false}]}
{"op":"mcm","clk":"11450263188","pt":1717319771049,"mc":[{"id":"1.229554906","rc":[{"atl":[[230,4.61]],"id":42269942}],"con":true,"img":false}]}
{"op":"mcm","clk":"11450263194","pt":1717319771151,"mc":[{"id":"1.229554906","rc":[{"atl":[[230,2.61],[490,2],[500,0]],"id":42269942}],"con":true,"img":false}]}
{"op":"mcm","clk":"11450263207","pt":1717319771357,"mc":[{"id":"1.229554906","rc":[{"atl":[[1.91,0]],"id":60780007},{"atb":[[1.84,0]],"id":61631980}],"con":true,"img":false}]}
{"op":"mcm","clk":"11450263226","pt":1717319771516,"mc":[{"id":"1.229554906","rc":[{"atl":[[1.89,62.77]],"id":60780007},{"atb":[[1.89,65.59]],"id":61631980},{"atl":[[7.2,0],[5.3,15.46]],"id":61631980},{"atl":[[2.88,20.93],[4.7,0]],"id":61631978}],"con":true,"img":false}]}
{"op":"mcm","clk":"11450263297","pt":1717319772443,"mc":[{"id":"1.229554906","rc":[{"atl":[[5,3.1]],"id":61631978}],"con":true,"img":false}]}
{"op":"mcm","clk":"11450263331","pt":1717319772857,"mc":[{"id":"1.229554906","rc":[{"atl":[[140,0.36]],"id":42269942}],"con":true,"img":false}]}
{"op":"mcm","clk":"11450263346","pt":1717319772959,"mc":[{"id":"1.229554906","rc":[{"atl":[[150,0.34]],"id":42269942}],"con":true,"img":false}]}
{"op":"mcm","clk":"11450263352","pt":1717319773015,"mc":[{"id":"1.229554906","rc":[{"atl":[[230,4.61]],"id":42269942}],"con":true,"img":false}]}
{"op":"mcm","clk":"11450263365","pt":1717319773119,"mc":[{"id":"1.229554906","rc":[{"atl":[[490,0]],"id":42269942}],"con":true,"img":false}]}
{"op":"mcm","clk":"11450263586","pt":1717319775540,"mc":[{"id":"1.229554906","rc":[{"atb":[[1.92,9.57]],"id":57451148}],"con":true,"img":false}]}
{"op":"mcm","clk":"11450263609","pt":1717319775757,"mc":[{"id":"1.229554906","rc":[{"atb":[[8,3.92],[13,0]],"id":42269942}],"con":true,"img":false}]}
{"op":"mcm","clk":"11450263618","pt":1717319775857,"mc":[{"id":"1.229554906","rc":[{"atb":[[1.92,0]],"id":57451148}],"con":true,"img":false}]}
{"op":"mcm","clk":"11450263630","pt":1717319775964,"mc":[{"id":"1.229554906","rc":[{"atb":[[13.5,0]],"id":42269942}],"con":true,"img":false}]}
{"op":"mcm","clk":"11450263640","pt":1717319776063,"mc":[{"id":"1.229554906","rc":[{"atb":[[8.2,3.85]],"id":42269942},{"atb":[[1.34,0]],"id":61631978}],"con":true,"img":false}]}
{"op":"mcm","clk":"11450263655","pt":1717319776270,"mc":[{"id":"1.229554906","rc":[{"atl":[[5.4,0]],"id":61631980},{"atl":[[2.9,0]],"id":61631978}],"con":true,"img":false}]}
{"op":"mcm","clk":"11450263664","pt":1717319776325,"mc":[{"id":"1.229554906","rc":[{"atl":[[7.2,16.13],[5.3,15.81]],"id":61631980},{"atl":[[2.88,20.92],[4.2,31.25]],"id":61631978}],"con":true,"img":false}]}
{"op":"mcm","clk":"11450263684","pt":1717319776530,"mc":[{"id":"1.229554906","rc":[{"atl":[[2.46,9.84]],"id":60780007},{"atl":[[5,0]],"id":61631978}],"con":true,"img":false}]}
{"op":"mcm","clk":"11450264116","pt":1717319781443,"mc":[{"id":"1.229554906","rc":[{"atl":[[2.86,20.93]],"id":61631978}],"con":true,"img":false}]}
{"op":"mcm","clk":"11450264124","pt":1717319781548,"mc":[{"id":"1.229554906","rc":[{"atl":[[4.2,0]],"id":61631978}],"con":true,"img":false}]}
{"op":"mcm","clk":"11450264228","pt":1717319782837,"mc":[{"id":"1.229554906","rc":[{"atb":[[1.05,84.54]],"id":60780007}],"con":true,"img":false}]}
{"op":"mcm","clk":"11450264242","pt":1717319783041,"mc":[{"id":"1.229554906","rc":[{"atb":[[1.37,7.24]],"id":61631978}],"con":true,"img":false}]}
{"op":"mcm","clk":"11450264267","pt":1717319783352,"mc":[{"id":"1.229554906","rc":[{"atb":[[1.62,20.17]],"id":61631978},{"trd":[[1.62,1.5]],"ltp":1.62,"tv":1.5,"id":61631978}],"con":true,"img":false}]}
{"op":"mcm","clk":"11450264303","pt":1717319783766,"mc":[{"id":"1.229554906","rc":[{"atl":[[5,3.1]],"id":61631978}],"con":true,"img":false}]}
{"op":"mcm","clk":"11450264376","pt":1717319784650,"mc":[{"id":"1.229554906","rc":[{"atb":[[2.5,2.83]],"id":57451148}],"con":true,"img":false}]}
{"op":"mcm","clk":"11450264430","pt":1717319785263,"mc":[{"id":"1.229554906","rc":[{"atb":[[1.46,9.26]],"id":61631978}],"con":true,"img":false}]}
{"op":"mcm","clk":"11450264439","pt":1717319785376,"mc":[{"id":"1.229554906","rc":[{"atl":[[2.88,0]],"id":61631978}],"con":true,"img":false}]}
{"op":"mcm","clk":"11450264452","pt":1717319785469,"mc":[{"id":"1.229554906","rc":[{"atl":[[4.5,28.57]],"id":61631978}],"con":true,"img":false}]}
{"op":"mcm","clk":"11450264461","pt":1717319785573,"mc":[{"id":"1.229554906","rc":[{"atl":[[2.86,20.92],[5,0]],"id":61631978}],"con":true,"img":false}]}
{"op":"mcm","clk":"11450264469","pt":1717319785677,"mc":[{"id":"1.229554906","rc":[{"atl":[[2.84,20.93]],"id":61631978}],"con":true,"img":false}]}
{"op":"mcm","clk":"11450264476","pt":1717319785778,"mc":[{"id":"1.229554906","rc":[{"atb":[[1.79,8.11],[1.57,0]],"id":61631980},{"atl":[[4.5,0]],"id":61631978}],"con":true,"img":false}]}
{"op":"mcm","clk":"11450264485","pt":1717319785882,"mc":[{"id":"1.229554906","rc":[{"atl":[[5.2,15.82]],"id":61631980}],"con":true,"img":false}]}
{"op":"mcm","clk":"11450264491","pt":1717319785985,"mc":[{"id":"1.229554906","rc":[{"atl":[[7.2,0]],"id":61631980}],"con":true,"img":false}]}
{"op":"mcm","clk":"11450264545","pt":1717319786663,"mc":[{"id":"1.229554906","rc":[{"atb":[[1.36,0]],"id":61631978}],"con":true,"img":false}]}
{"op":"mcm","clk":"11450264560","pt":1717319786868,"mc":[{"id":"1.229554906","rc":[{"atb":[[1.56,7.01]],"id":61631978}],"con":true,"img":false}]}
{"op":"mcm","clk":"11450264638","pt":1717319787851,"mc":[{"id":"1.229554906","rc":[{"atb":[[2.2,5.94]],"id":57451148}],"con":true,"img":false}]}
{"op":"mcm","clk":"11450264688","pt":1717319788470,"mc":[{"id":"1.229554906","rc":[{"atb":[[1.05,0]],"id":60780007}],"con":true,"img":false}]}
{"op":"mcm","clk":"11450264833","pt":1717319789975,"mc":[{"id":"1.229554906","rc":[{"atl":[[2.46,0]],"id":60780007}],"con":true,"img":false}]}
{"op":"mcm","clk":"11450264838","pt":1717319790080,"mc":[{"id":"1.229554906","rc":[{"atl":[[2.46,9.84]],"id":60780007}],"con":true,"img":false}]}
{"op":"mcm","clk":"11450264845","pt":1717319790184,"mc":[{"id":"1.229554906","rc":[{"atl":[[5.3,0]],"id":61631980},{"atl":[[2.86,0]],"id":61631978}],"con":true,"img":false}]}
{"op":"mcm","clk":"11450264855","pt":1717319790284,"mc":[{"id":"1.229554906","rc":[{"atl":[[7.2,16.13],[5.2,0]],"id":61631980},{"atl":[[4.5,28.57],[2.84,0]],"id":61631978}],"con":true,"img":false}]}
{"op":"mcm","clk":"11450264866","pt":1717319790393,"mc":[{"id":"1.229554906","rc":[{"atb":[[5.1,0],[6.2,0]],"id":42269942},{"atb":[[3.2,0],[2.88,0]],"id":57451148},{"atb":[[1.01,66213.07]],"id":60780007},{"atl":[[2.32,0]],"id":60780007},{"atb":[[1.88,0],[1.78,0]],"id":61631980},{"atl":[[5.2,16.19],[7.8,0]],"id":61631980},{"atb":[[1.44,0],[1.54,0]],"id":61631978},{"atl":[[4.9,0],[2.84,20.92]],"id":61631978}],"con":true,"img":false}]}
{"op":"mcm","clk":"11450264883","pt":1717319790553,"mc":[{"id":"1.229554906","rc":[{"atb":[[2.2,0]],"id":57451148}],"con":true,"img":false}]}
{"op":"mcm","clk":"11450264901","pt":1717319790760,"mc":[{"id":"1.229554906","rc":[{"atl":[[2.82,20.93],[4.5,0]],"id":61631978}],"con":true,"img":false}]}
{"op":"mcm","clk":"11450264919","pt":1717319790971,"mc":[{"id":"1.229554906","rc":[{"atl":[[5.1,16.13]],"id":61631980}],"con":true,"img":false}]}
{"op":"mcm","clk":"11450264927","pt":1717319791076,"mc":[{"id":"1.229554906","rc":[{"atl":[[7.2,0]],"id":61631980}],"con":true,"img":false}]}
{"op":"mcm","clk":"11450264969","pt":1717319791594,"mc":[{"id":"1.229554906","rc":[{"atb":[[1.67,14.45]],"id":61631980}],"con":true,"img":false}]}
{"op":"mcm","clk":"11450265217","pt":1717319794191,"mc":[{"id":"1.229554906","rc":[{"atl":[[150,0]],"id":42269942},{"atl":[[2.4,0]],"id":60780007}],"con":true,"img":false}]}
{"op":"mcm","clk":"11450265228","pt":1717319794249,"mc":[{"id":"1.229554906","rc":[{"atl":[[180,0.34]],"id":42269942},{"atl":[[1.88,41.85]],"id":60780007}],"con":true,"img":false}]}
{"op":"mcm","clk":"11450265235","pt":1717319794354,"mc":[{"id":"1.229554906","rc":[{"atl":[[1.89,20.92],[1.87,41.85]],"id":60780007}],"con":true,"img":false}]}
{"op":"mcm","clk":"11450265246","pt":1717319794503,"mc":[{"id":"1.229554906","rc":[{"atl":[[1.88,0]],"id":60780007}],"con":true,"img":false}]}
