{"op":"mcm","clk":"11448127637","pt":1717286034976,"mc":[{"id":"1.229554890","marketDefinition":{"bspMarket":true,"turnInPlayEnabled":false,"persistenceEnabled":false,"marketBaseRate":7.0,"eventId":"33318908","eventTypeId":"4339","numberOfWinners":1,"bettingType":"ODDS","marketType":"WIN","marketTime":"2024-06-02T08:21:00.000Z","suspendTime":"2024-06-02T08:21:00.000Z","bspReconciled":false,"complete":true,"inPlay":false,"crossMatching":true,"runnersVoidable":false,"numberOfActiveRunners":5,"betDelay":0,"status":"OPEN","runners":[{"status":"ACTIVE","sortPriority":1,"id":70003363,"name":"1. Plodding Along"},{"status":"ACTIVE","sortPriority":2,"id":70003364,"name":"2. Parrakie"},{"status":"ACTIVE","sortPriority":3,"id":70003365,"name":"4. Bookaloo"},{"status":"ACTIVE","sortPriority":4,"id":70003366,"name":"6. Manner Of Strife"},{"status":"ACTIVE","sortPriority":5,"id":70003367,"name":"8. Apilla"}],"regulators":["MR_INT"],"venue":"Murray Bridge","countryCode":"AU","discountAllowed":true,"timezone":"Australia/Adelaide","openDate":"2024-06-02T08:21:00.000Z","version":5962317624,"name":"R1 395m Mdn","eventName":"Murray Bridge (AUS) 2nd Jun"},"rc":[],"con":true,"img":false}]}
{"op":"mcm","clk":"11448260594","pt":1717287908430,"mc":[{"id":"1.229554890","rc":[{"atb":[[16.5,6.74],[11.5,19.91],[14,16.08]],"id":70003366},{"atl":[[350,0.59],[250,0.55]],"id":70003366},{"spn":133.25,"spf":"NaN","id":70003366},{"atb":[[2.8,116.14],[2.9,55.01],[2.7,122.97]],"id":70003367},{"atl":[[10,15.48],[15,14.93]],"id":70003367},{"spn":6.45,"spf":"NaN","id":70003367},{"atb":[[1.73,286.38],[1.83,125.93],[1.78,268.02]],"id":70003364},{"atl":[[4.5,39.81],[5.5,46.45]],"id":70003364},{"spn":3.16,"spf":"NaN","id":70003364},{"atb":[[2.86,112.39],[2.96,53.33],[2.76,118.78]],"id":70003365},{"atl":[[10.5,14.66],[15.5,14.41]],"id":70003365},{"spn":6.73,"spf":"NaN","id":70003365},{"atb":[[17,6.53],[12,19],[14.5,15.48]],"id":70003363},{"atl":[[350,0.59],[250,0.55]],"id":70003363},{"spn":133.5,"spf":"NaN","id":70003363}],"con":true,"img":false}]}
{"op":"mcm","clk":"11448264294","pt":1717287962153,"mc":[{"id":"1.229554890","rc":[{"atb":[[16.5,0],[11.5,0],[14,0]],"id":70003366},{"atl":[[350,0],[250,0]],"id":70003366},{"atb":[[2.8,0],[2.9,0],[2.7,0]],"id":70003367},{"atl":[[10,0],[15,0]],"id":70003367},{"atb":[[1.73,0],[1.83,0],[1.78,0]],"id":70003364},{"atl":[[4.5,0],[5.5,0]],"id":70003364},{"atb":[[2.86,0],[2.96,0],[2.76,0]],"id":70003365},{"atl":[[10.5,0],[15.5,0]],"id":70003365},{"atb":[[17,0],[12,0],[14.5,0]],"id":70003363},{"atl":[[350,0],[250,0]],"id":70003363}],"con":true,"img":false}]}
{"op":"mcm","clk":"11448265018","pt":1717287972318,"mc":[{"id":"1.229554890","rc":[{"atb":[[18,6.14],[13,17.42],[15.5,14.41]],"id":70003366},{"atl":[[260,0.53],[360,0.58]],"id":70003366},{"spn":139.0,"spf":"NaN","id":70003366},{"atb":[[2.36,153.71],[2.46,71.59],[2.26,165.92]],"id":70003367},{"atl":[[8,19.91],[10,23.22]],"id":70003367},{"spn":5.23,"spf":"NaN","id":70003367},{"atb":[[1.73,286.38],[1.83,125.93],[1.78,268.02]],"id":70003364},{"atl":[[4.5,39.81],[5.5,46.45]],"id":70003364},{"atb":[[2.86,112.39],[2.96,53.33],[2.76,118.78]],"id":70003365},{"atl":[[10.5,14.66],[15.5,14.41]],"id":70003365},{"atb":[[17,6.53],[12,19],[14.5,15.48]],"id":70003363},{"atl":[[350,0.59],[250,0.55]],"id":70003363}],"con":true,"img":false}]}
{"op":"mcm","clk":"11448270133","pt":1717288057118,"mc":[{"id":"1.229554890","rc":[{"atb":[[18,0],[13,0],[15.5,0]],"id":70003366},{"atl":[[260,0],[360,0]],"id":70003366},{"spn":"NaN","spf":"NaN","id":70003366},{"atb":[[2.36,0],[2.46,0],[2.26,0]],"id":70003367},{"atl":[[8,0],[10,0]],"id":70003367},{"spn":"NaN","spf":"NaN","id":70003367},{"atb":[[1.73,0],[1.83,0],[1.78,0]],"id":70003364},{"atl":[[4.5,0],[5.5,0]],"id":70003364},{"spn":"NaN","spf":"NaN","id":70003364},{"atb":[[2.86,0],[2.96,0],[2.76,0]],"id":70003365},{"atl":[[10.5,0],[15.5,0]],"id":70003365},{"spn":"NaN","spf":"NaN","id":70003365},{"atb":[[17,0],[12,0],[14.5,0]],"id":70003363},{"atl":[[350,0],[250,0]],"id":70003363},{"spn":"NaN","spf":"NaN","id":70003363}],"con":true,"img":false}]}
{"op":"mcm","clk":"11448270978","pt":1717288067734,"mc":[{"id":"1.229554890","rc":[{"atb":[[18,6.14],[13,17.42],[15.5,14.41]],"id":70003366},{"atl":[[260,0.53],[360,0.58]],"id":70003366},{"atb":[[2.36,153.71],[2.46,71.59],[2.26,165.92]],"id":70003367},{"atl":[[8,19.91],[10,23.22]],"id":70003367},{"atb":[[1.79,264.63],[1.89,117.44],[1.84,248.88]],"id":70003364},{"atl":[[5.1,33.99],[6.2,40.2]],"id":70003364},{"atb":[[2.88,111.2],[2.98,52.79],[2.78,117.44]],"id":70003365},{"atl":[[10.5,14.66],[15.5,14.41]],"id":70003365},{"atb":[[17,6.53],[12,19],[14.5,15.48]],"id":70003363},{"atl":[[350,0.59],[250,0.55]],"id":70003363}],"con":true,"img":false}]}
{"op":"mcm","clk":"11448272355","pt":1717288089584,"mc":[{"id":"1.229554890","rc":[{"atb":[[18,0],[13,0],[15.5,0]],"id":70003366},{"atl":[[260,0],[360,0]],"id":70003366},{"atb":[[2.36,0],[2.46,0],[2.26,0]],"id":70003367},{"atl":[[8,0],[10,0]],"id":70003367},{"atb":[[1.79,0],[1.89,0],[1.84,0]],"id":70003364},{"atl":[[5.1,0],[6.2,0]],"id":70003364},{"atb":[[2.88,0],[2.98,0],[2.78,0]],"id":70003365},{"atl":[[10.5,0],[15.5,0]],"id":70003365},{"atb":[[17,0],[12,0],[14.5,0]],"id":70003363},{"atl":[[350,0],[250,0]],"id":70003363}],"con":true,"img":false}]}
{"op":"mcm","clk":"11448273012","pt":1717288099886,"mc":[{"id":"1.229554890","rc":[{"atb":[[17,13.06],[19.5,5.65],[14.5,15.48]],"id":70003366},{"atl":[[300,0.46],[400,0.52]],"id":70003366},{"atb":[[2.36,153.71],[2.46,71.59],[2.26,165.92]],"id":70003367},{"atl":[[8,19.91],[10,23.22]],"id":70003367},{"atb":[[1.73,286.38],[1.83,125.93],[1.78,268.02]],"id":70003364},{"atl":[[4.5,39.81],[5.5,46.45]],"id":70003364},{"atb":[[2.88,111.2],[2.98,52.79],[2.78,117.44]],"id":70003365},{"atl":[[10.5,14.66],[15.5,14.41]],"id":70003365},{"atb":[[17,13.06],[19.5,5.65],[14.5,15.48]],"id":70003363},{"atl":[[300,0.46],[400,0.52]],"id":70003363}],"con":true,"img":false}]}
{"op":"mcm","clk":"11448277223","pt":1717288128428,"mc":[{"id":"1.229554890","marketDefinition":{"bspMarket":true,"turnInPlayEnabled":false,"persistenceEnabled":false,"marketBaseRate":7.0,"eventId":"33318908","eventTypeId":"4339","numberOfWinners":1,"bettingType":"ODDS","marketType":"WIN","marketTime":"2024-06-02T08:21:00.000Z","suspendTime":"2024-06-02T08:21:00.000Z","bspReconciled":false,"complete":true,"inPlay":false,"crossMatching":true,"runnersVoidable":false,"numberOfActiveRunners":5,"betDelay":0,"status":"OPEN","runners":[{"status":"ACTIVE","sortPriority":1,"id":70003363,"name":"1. Plodding Along"},{"status":"ACTIVE","sortPriority":2,"id":70003364,"name":"2. Parrakie"},{"status":"ACTIVE","sortPriority":3,"id":70003365,"name":"4. Bookaloo"},{"status":"ACTIVE","sortPriority":4,"id":70003366,"name":"6. Manner Of Strife"},{"status":"ACTIVE","sortPriority":5,"id":70003367,"name":"8. Apilla"}],"regulators":["MR_INT"],"venue":"Murray Bridge","countryCode":"AU","discountAllowed":true,"timezone":"Australia/Adelaide","openDate":"2024-06-02T08:21:00.000Z","version":5962317624,"name":"R1 395m Mdn","eventName":"Murray Bridge (AUS) 2nd Jun"},"rc":[{"atb":[[17,13.06],[19.5,5.65],[14.5,15.48]],"id":70003366},{"atl":[[300,0.46],[400,0.52]],"id":70003366},{"spn":159.75,"spf":"NaN","id":70003366},{"atb":[[2.36,153.71],[2.46,71.59],[2.26,165.92]],"id":70003367},{"atl":[[8,19.91],[10,23.22]],"id":70003367},{"spn":5.23,"spf":"NaN","id":70003367},{"atb":[[1.73,286.38],[1.83,125.93],[1.78,268.02]],"id":70003364},{"atl":[[4.5,39.81],[5.5,46.45]],"id":70003364},{"spn":3.16,"spf":"NaN","id":70003364},{"atb":[[2.88,111.2],[2.98,52.79],[2.78,117.44]],"id":70003365},{"atl":[[10.5,14.66],[15.5,14.41]],"id":70003365},{"spn":6.74,"spf":"NaN","id":70003365},{"atb":[[17,13.06],[19.5,5.65],[14.5,15.48]],"id":70003363},{"atl":[[300,0.46],[400,0.52]],"id":70003363},{"spn":159.75,"spf":"NaN","id":70003363}],"con":true,"img":true}]}
{"op":"mcm","clk":"11448284287","pt":1717288159833,"mc":[{"id":"1.229554890","rc":[{"spn":159.75,"spf":"NaN","id":70003366},{"spn":5.23,"spf":"NaN","id":70003367},{"spn":3.16,"spf":"NaN","id":70003364},{"atb":[[2.88,0],[2.98,0],[2.78,0]],"id":70003365},{"atl":[[10.5,0],[15.5,0]],"id":70003365},{"spn":6.74,"spf":"NaN","id":70003365},{"atb":[[17,0],[19.5,0],[14.5,0]],"id":70003363},{"atl":[[300,0],[400,0]],"id":70003363},{"spn":159.75,"spf":"NaN","id":70003363}],"con":true,"img":false}]}
{"op":"mcm","clk":"11448285284","pt":1717288174030,"mc":[{"id":"1.229554890","rc":[{"atb":[[2.88,111.2],[2.98,52.79],[2.78,117.44]],"id":70003365},{"atl":[[10.5,14.66],[15.5,14.41]],"id":70003365},{"atb":[[18,6.14],[13,17.42],[15.5,14.41]],"id":70003363},{"atl":[[260,0.53],[360,0.58]],"id":70003363}],"con":true,"img":false}]}
{"op":"mcm","clk":"11448289491","pt":1717288232485,"mc":[{"id":"1.229554890","rc":[{"atb":[[2.36,0],[2.46,0],[2.26,0]],"id":70003367},{"atl":[[8,0],[10,0]],"id":70003367},{"spn":"NaN","spf":"NaN","id":70003367},{"atb":[[18,0],[13,0],[15.5,0]],"id":70003363},{"atl":[[260,0],[360,0]],"id":70003363},{"spn":"NaN","spf":"NaN","id":70003363}],"con":true,"img":false}]}
{"op":"mcm","clk":"11448290414","pt":1717288245743,"mc":[{"id":"1.229554890","rc":[{"atb":[[2.28,81.66],[2.18,177.16],[2.08,193.57]],"id":70003367},{"atl":[[7.4,21.77],[9.4,24.88]],"id":70003367},{"atb":[[18,6.14],[13,17.42],[15.5,14.41]],"id":70003363},{"atl":[[260,0.53],[360,0.58]],"id":70003363}],"con":true,"img":false}]}
{"op":"mcm","clk":"11448292443","pt":1717288273689,"mc":[{"id":"1.229554890","rc":[{"atb":[[17,0],[19.5,0],[14.5,0]],"id":70003366},{"atl":[[300,0],[400,0]],"id":70003366},{"atb":[[2.28,0],[2.18,0],[2.08,0]],"id":70003367},{"atl":[[7.4,0],[9.4,0]],"id":70003367},{"atb":[[2.88,0],[2.98,0],[2.78,0]],"id":70003365},{"atl":[[10.5,0],[15.5,0]],"id":70003365},{"atb":[[18,0],[13,0],[15.5,0]],"id":70003363},{"atl":[[260,0],[360,0]],"id":70003363}],"con":true,"img":false}]}
{"op":"mcm","clk":"11448293804","pt":1717288291623,"mc":[{"id":"1.229554890","rc":[{"atb":[[17.5,12.67],[20,5.5],[15,14.93]],"id":70003366},{"atl":[[310,0.44],[410,0.51]],"id":70003366},{"atb":[[2.28,81.66],[2.18,177.16],[2.08,193.57]],"id":70003367},{"atl":[[7.4,21.77],[9.4,24.88]],"id":70003367},{"atb":[[3.1,49.77],[2.84,113.61],[2.94,107.76]],"id":70003365},{"atl":[[16,13.93],[11,13.93]],"id":70003365},{"atb":[[17,13.06],[19.5,5.65],[14.5,15.48]],"id":70003363},{"atl":[[300,0.46],[400,0.52]],"id":70003363}],"con":true,"img":false}]}
{"op":"mcm","clk":"11448298252","pt":1717288351176,"mc":[{"id":"1.229554890","rc":[{"spn":165.0,"spf":"NaN","id":70003366},{"atb":[[2.28,0],[2.18,0],[2.08,0]],"id":70003367},{"atl":[[7.4,0],[9.4,0]],"id":70003367},{"atb":[[3.1,0],[2.84,0],[2.94,0]],"id":70003365},{"atl":[[16,0],[11,0]],"id":70003365},{"spn":"NaN","spf":"NaN","id":70003365},{"atb":[[17,0],[19.5,0],[14.5,0]],"id":70003363},{"atl":[[300,0],[400,0]],"id":70003363}],"con":true,"img":false}]}
{"op":"mcm","clk":"11448300795","pt":1717288383947,"mc":[{"id":"1.229554890","rc":[{"atb":[[2.28,81.66],[2.18,177.16],[2.08,193.57]],"id":70003367},{"atl":[[7.4,21.77],[9.4,24.88]],"id":70003367},{"atb":[[2.86,112.39],[3.15,48.61],[2.96,106.66]],"id":70003365},{"atl":[[16,13.93],[11,13.93]],"id":70003365},{"atb":[[17.5,12.67],[20,5.5],[15,14.93]],"id":70003363},{"atl":[[310,0.44],[410,0.51]],"id":70003363}],"con":true,"img":false}]}
{"op":"mcm","clk":"11448449904","pt":1717290485765,"mc":[{"id":"1.229554890","rc":[{"atb":[[17.5,0],[20,0],[15,0]],"id":70003366},{"atl":[[310,0],[410,0]],"id":70003366},{"spn":"NaN","spf":"NaN","id":70003366},{"atb":[[2.28,0],[2.18,0],[2.08,0]],"id":70003367},{"atl":[[7.4,0],[9.4,0]],"id":70003367},{"atb":[[1.73,0],[1.83,0],[1.78,0]],"id":70003364},{"atl":[[4.5,0],[5.5,0]],"id":70003364},{"spn":"NaN","spf":"NaN","id":70003364},{"atb":[[2.86,0],[3.15,0],[2.96,0]],"id":70003365},{"atl":[[16,0],[11,0]],"id":70003365},{"atb":[[17.5,0],[20,0],[15,0]],"id":70003363},{"atl":[[310,0],[410,0]],"id":70003363}],"con":true,"img":false}]}
{"op":"mcm","clk":"11448450355","pt":1717290493608,"mc":[{"id":"1.229554890","rc":[{"atb":[[17.5,12.67],[20,5.5],[15,14.93]],"id":70003366},{"atl":[[310,0.44],[410,0.51]],"id":70003366},{"atb":[[2.06,197.22],[1.98,213.33],[2.16,90.11]],"id":70003367},{"atl":[[9,26.13],[7,23.22]],"id":70003367},{"atb":[[1.79,264.63],[1.89,117.44],[1.84,248.88]],"id":70003364},{"atl":[[5.1,33.99],[6.2,40.2]],"id":70003364},{"atb":[[2.9,110.03],[3,104.53],[3.25,46.45]],"id":70003365},{"atl":[[17,13.06],[12,12.67]],"id":70003365},{"atb":[[17.5,12.67],[20,5.5],[15,14.93]],"id":70003363},{"atl":[[310,0.44],[410,0.51]],"id":70003363}],"con":true,"img":false}]}
{"op":"mcm","clk":"11448451088","pt":1717290505987,"mc":[{"id":"1.229554890","rc":[{"atb":[[2.06,0],[1.98,0],[2.16,0]],"id":70003367},{"atl":[[9,0],[7,0]],"id":70003367},{"atb":[[1.79,0],[1.89,0],[1.84,0]],"id":70003364},{"atl":[[5.1,0],[6.2,0]],"id":70003364},{"atb":[[2.9,0],[3,0],[3.25,0]],"id":70003365},{"atl":[[17,0],[12,0]],"id":70003365}],"con":true,"img":false}]}
{"op":"mcm","clk":"11448451644","pt":1717290515494,"mc":[{"id":"1.229554890","rc":[{"atb":[[2.06,197.22],[1.98,213.33],[2.16,90.11]],"id":70003367},{"atl":[[9,26.13],[7,23.22]],"id":70003367},{"atb":[[1.83,251.88],[1.88,237.56],[1.93,112.39]],"id":70003364},{"atl":[[5.6,30.29],[7.2,33.71]],"id":70003364},{"atb":[[3.4,43.55],[3.15,97.23],[2.96,106.66]],"id":70003365},{"atl":[[19,11.61],[14,10.71]],"id":70003365}],"con":true,"img":false}]}
{"op":"mcm","clk":"11448452959","pt":1717290537143,"mc":[{"id":"1.229554890","rc":[{"atb":[[2.06,0],[1.98,0],[2.16,0]],"id":70003367},{"atl":[[9,0],[7,0]],"id":70003367},{"atb":[[1.83,0],[1.88,0],[1.93,0]],"id":70003364},{"atl":[[5.6,0],[7.2,0]],"id":70003364},{"atb":[[3.4,0],[3.15,0],[2.96,0]],"id":70003365},{"atl":[[19,0],[14,0]],"id":70003365}],"con":true,"img":false}]}
{"op":"mcm","clk":"11448453486","pt":1717290545869,"mc":[{"id":"1.229554890","rc":[{"spn":165.0,"spf":"NaN","id":70003366},{"atb":[[2.06,197.22],[1.98,213.33],[2.16,90.11]],"id":70003367},{"atl":[[9,26.13],[7,23.22]],"id":70003367},{"spn":4.58,"spf":"NaN","id":70003367},{"atb":[[1.83,251.88],[1.88,237.56],[1.93,112.39]],"id":70003364},{"atl":[[5.6,30.29],[7.2,33.71]],"id":70003364},{"spn":3.76,"spf":"NaN","id":70003364},{"atb":[[3.4,43.55],[3.15,97.23],[2.96,106.66]],"id":70003365},{"atl":[[19,11.61],[14,10.71]],"id":70003365},{"spn":8.7,"spf":"NaN","id":70003365},{"spn":165.0,"spf":"NaN","id":70003363}],"con":true,"img":false}]}
{"op":"mcm","clk":"11448455672","pt":1717290576906,"mc":[{"id":"1.229554890","rc":[{"atb":[[2.06,0],[1.98,0],[2.16,0]],"id":70003367},{"atl":[[9,0],[7,0]],"id":70003367},{"atb":[[1.83,0],[1.88,0],[1.93,0]],"id":70003364},{"atl":[[5.6,0],[7.2,0]],"id":70003364},{"atb":[[3.4,0],[3.15,0],[2.96,0]],"id":70003365},{"atl":[[19,0],[14,0]],"id":70003365}],"con":true,"img":false}]}
{"op":"mcm","clk":"11448456054","pt":1717290583503,"mc":[{"id":"1.229554890","rc":[{"atb":[[2.06,197.22],[1.98,213.33],[2.16,90.11]],"id":70003367},{"atl":[[9,26.13],[7,23.22]],"id":70003367},{"atb":[[1.91,229.73],[1.96,108.88],[1.86,243.09]],"id":70003364},{"atl":[[7.8,30.74],[5.9,28.44]],"id":70003364},{"atb":[[3.45,42.66],[3.2,95.02],[2.98,105.58]],"id":70003365},{"atl":[[19.5,11.3],[14.5,10.32]],"id":70003365}],"con":true,"img":false}]}
{"op":"mcm","clk":"11448459584","pt":1717290647283,"mc":[{"id":"1.229554890","rc":[{"atb":[[2.06,0],[1.98,0],[2.16,0]],"id":70003367},{"atl":[[9,0],[7,0]],"id":70003367},{"spn":"NaN","spf":"NaN","id":70003367},{"atb":[[1.91,0],[1.96,0],[1.86,0]],"id":70003364},{"atl":[[7.8,0],[5.9,0]],"id":70003364},{"spn":"NaN","spf":"NaN","id":70003364},{"atb":[[3.45,0],[3.2,0],[2.98,0]],"id":70003365},{"atl":[[19.5,0],[14.5,0]],"id":70003365},{"spn":"NaN","spf":"NaN","id":70003365}],"con":true,"img":false}]}
{"op":"mcm","clk":"11448459963","pt":1717290655598,"mc":[{"id":"1.229554890","rc":[{"atb":[[2.06,197.22],[1.98,213.33],[2.16,90.11]],"id":70003367},{"atl":[[9,26.13],[7,23.22]],"id":70003367},{"atb":[[1.91,229.73],[1.96,108.88],[1.86,243.09]],"id":70003364},{"atl":[[7.8,30.74],[5.9,28.44]],"id":70003364},{"atb":[[3.45,42.66],[3.2,95.02],[2.98,105.58]],"id":70003365},{"atl":[[19.5,11.3],[14.5,10.32]],"id":70003365}],"con":true,"img":false}]}
{"op":"mcm","clk":"11448461408","pt":1717290680414,"mc":[{"id":"1.229554890","rc":[{"atb":[[2.06,0],[1.98,0],[2.16,0]],"id":70003367},{"atl":[[9,0],[7,0]],"id":70003367},{"atb":[[3.45,0],[3.2,0],[2.98,0]],"id":70003365},{"atl":[[19.5,0],[14.5,0]],"id":70003365}],"con":true,"img":false}]}
{"op":"mcm","clk":"11448462200","pt":1717290691801,"mc":[{"id":"1.229554890","rc":[{"atb":[[2.06,197.22],[1.98,213.33],[2.16,90.11]],"id":70003367},{"atl":[[9,26.13],[7,23.22]],"id":70003367},{"atb":[[3.6,40.2],[3.1,99.55],[3.35,88.96]],"id":70003365},{"atl":[[18.5,11.94],[13.5,11.14]],"id":70003365}],"con":true,"img":false}]}
{"op":"mcm","clk":"11448463733","pt":1717290717628,"mc":[{"id":"1.229554890","rc":[{"atb":[[2.06,0],[1.98,0],[2.16,0]],"id":70003367},{"atl":[[9,0],[7,0]],"id":70003367},{"atb":[[1.91,0],[1.96,0],[1.86,0]],"id":70003364},{"atl":[[7.8,0],[5.9,0]],"id":70003364},{"atb":[[3.6,0],[3.1,0],[3.35,0]],"id":70003365},{"atl":[[18.5,0],[13.5,0]],"id":70003365},{"atb":[[17.5,0],[20,0],[15,0]],"id":70003363},{"atl":[[310,0],[410,0]],"id":70003363},{"spn":"NaN","spf":"NaN","id":70003363}],"con":true,"img":false}]}
{"op":"mcm","clk":"11448464660","pt":1717290732657,"mc":[{"id":"1.229554890","rc":[{"atb":[[2.06,197.22],[1.98,213.33],[2.16,90.11]],"id":70003367},{"atl":[[9,26.13],[7,23.22]],"id":70003367},{"atb":[[1.91,229.73],[1.96,108.88],[1.86,243.09]],"id":70003364},{"atl":[[7.8,30.74],[5.9,28.44]],"id":70003364},{"atb":[[3.6,40.2],[3.1,99.55],[3.35,88.96]],"id":70003365},{"atl":[[18.5,11.94],[13.5,11.14]],"id":70003365},{"atb":[[17,13.06],[19.5,5.65],[14.5,15.48]],"id":70003363},{"atl":[[300,0.46],[400,0.52]],"id":70003363}],"con":true,"img":false}]}
{"op":"mcm","clk":"11448474826","pt":1717290912477,"mc":[{"id":"1.229554890","rc":[{"atb":[[2.06,0],[1.98,0],[2.16,0]],"id":70003367},{"atl":[[9,0],[7,0]],"id":70003367},{"atb":[[1.91,0],[1.96,0],[1.86,0]],"id":70003364},{"atl":[[7.8,0],[5.9,0]],"id":70003364},{"atb":[[3.6,0],[3.1,0],[3.35,0]],"id":70003365},{"atl":[[18.5,0],[13.5,0]],"id":70003365},{"spn":159.75,"spf":"NaN","id":70003363}],"con":true,"img":false}]}
{"op":"mcm","clk":"11448475142","pt":1717290917393,"mc":[{"id":"1.229554890","rc":[{"atb":[[2.02,102.47],[1.91,229.73],[1.96,217.77]],"id":70003367},{"atl":[[6.4,25.8],[8.4,28.25]],"id":70003367},{"atb":[[1.91,229.73],[1.96,108.88],[1.86,243.09]],"id":70003364},{"atl":[[7.8,30.74],[5.9,28.44]],"id":70003364},{"atb":[[3.6,40.2],[3.1,99.55],[3.35,88.96]],"id":70003365},{"atl":[[18.5,11.94],[13.5,11.14]],"id":70003365}],"con":true,"img":false}]}
{"op":"mcm","clk":"11448476910","pt":1717290945522,"mc":[{"id":"1.229554890","rc":[{"atb":[[2.02,0],[1.91,0],[1.96,0]],"id":70003367},{"atl":[[6.4,0],[8.4,0]],"id":70003367},{"atb":[[1.91,0],[1.96,0],[1.86,0]],"id":70003364},{"atl":[[7.8,0],[5.9,0]],"id":70003364},{"atb":[[3.6,0],[3.1,0],[3.35,0]],"id":70003365},{"atl":[[18.5,0],[13.5,0]],"id":70003365}],"con":true,"img":false}]}
{"op":"mcm","clk":"11448477472","pt":1717290954640,"mc":[{"id":"1.229554890","rc":[{"atb":[[2.02,102.47],[1.91,229.73],[1.96,217.77]],"id":70003367},{"atl":[[6.4,25.8],[8.4,28.25]],"id":70003367},{"atb":[[1.98,106.66],[1.88,237.56],[1.93,224.79]],"id":70003364},{"atl":[[6.2,26.8],[8.2,29.03]],"id":70003364},{"atb":[[3.6,40.2],[3.1,99.55],[3.35,88.96]],"id":70003365},{"atl":[[18.5,11.94],[13.5,11.14]],"id":70003365}],"con":true,"img":false}]}
{"op":"mcm","clk":"11448482360","pt":1717291031786,"mc":[{"id":"1.229554890","rc":[{"atb":[[2.02,0],[1.91,0],[1.96,0]],"id":70003367},{"atl":[[6.4,0],[8.4,0]],"id":70003367},{"atb":[[1.98,0],[1.88,0],[1.93,0]],"id":70003364},{"atl":[[6.2,0],[8.2,0]],"id":70003364},{"atb":[[3.6,0],[3.1,0],[3.35,0]],"id":70003365},{"atl":[[18.5,0],[13.5,0]],"id":70003365}],"con":true,"img":false}]}
{"op":"mcm","clk":"11448483015","pt":1717291041104,"mc":[{"id":"1.229554890","rc":[{"atb":[[2.02,102.47],[1.91,229.73],[1.96,217.77]],"id":70003367},{"atl":[[6.4,25.8],[8.4,28.25]],"id":70003367},{"atb":[[2.02,102.47],[1.91,229.73],[1.96,217.77]],"id":70003364},{"atl":[[6.4,25.8],[8.4,28.25]],"id":70003364},{"atb":[[3.6,40.2],[3.1,99.55],[3.35,88.96]],"id":70003365},{"atl":[[18.5,11.94],[13.5,11.14]],"id":70003365}],"con":true,"img":false}]}
{"op":"mcm","clk":"11448487738","pt":1717291112533,"mc":[{"id":"1.229554890","rc":[{"atb":[[17.5,0],[20,0],[15,0]],"id":70003366},{"atl":[[310,0],[410,0]],"id":70003366},{"spn":"NaN","spf":"NaN","id":70003366},{"spn":4.21,"spf":"NaN","id":70003367},{"spn":4.21,"spf":"NaN","id":70003364},{"spn":8.55,"spf":"NaN","id":70003365},{"atb":[[17,0],[19.5,0],[14.5,0]],"id":70003363},{"atl":[[300,0],[400,0]],"id":70003363},{"spn":"NaN","spf":"NaN","id":70003363}],"con":true,"img":false}]}
{"op":"mcm","clk":"11448487972","pt":1717291116013,"mc":[{"id":"1.229554890","rc":[{"atb":[[16,13.93],[18.5,11.94],[22,4.97]],"id":70003366},{"atl":[[320,0.43],[420,0.49]],"id":70003366},{"atb":[[16,13.93],[18.5,11.94],[22,4.97]],"id":70003363},{"atl":[[320,0.43],[420,0.49]],"id":70003363}],"con":true,"img":false}]}
{"op":"mcm","clk":"11448491817","pt":1717291173850,"mc":[{"id":"1.229554890","rc":[{"atb":[[16,0],[18.5,0],[22,0]],"id":70003366},{"atl":[[320,0],[420,0]],"id":70003366},{"atb":[[2.02,0],[1.91,0],[1.96,0]],"id":70003367},{"atl":[[6.4,0],[8.4,0]],"id":70003367},{"spn":"NaN","spf":"NaN","id":70003367},{"atb":[[2.02,0],[1.91,0],[1.96,0]],"id":70003364},{"atl":[[6.4,0],[8.4,0]],"id":70003364},{"spn":"NaN","spf":"NaN","id":70003364},{"atb":[[3.6,0],[3.1,0],[3.35,0]],"id":70003365},{"atl":[[18.5,0],[13.5,0]],"id":70003365},{"spn":"NaN","spf":"NaN","id":70003365},{"atb":[[16,0],[18.5,0],[22,0]],"id":70003363},{"atl":[[320,0],[420,0]],"id":70003363}],"con":true,"img":false}]}
{"op":"mcm","clk":"11448492653","pt":1717291186676,"mc":[{"id":"1.229554890","rc":[{"atb":[[16,13.93],[18.5,11.94],[22,4.97]],"id":70003366},{"atl":[[320,0.43],[420,0.49]],"id":70003366},{"atb":[[2.02,102.47],[1.91,229.73],[1.96,217.77]],"id":70003367},{"atl":[[6.4,25.8],[8.4,28.25]],"id":70003367},{"atb":[[2.02,102.47],[1.91,229.73],[1.96,217.77]],"id":70003364},{"atl":[[6.4,25.8],[8.4,28.25]],"id":70003364},{"atb":[[2.88,111.2],[2.98,52.79],[2.78,117.44]],"id":70003365},{"atl":[[10.5,14.66],[15.5,14.41]],"id":70003365},{"atb":[[16,13.93],[18.5,11.94],[22,4.97]],"id":70003363},{"atl":[[320,0.43],[420,0.49]],"id":70003363}],"con":true,"img":false}]}
{"op":"mcm","clk":"11448494258","pt":1717291212082,"mc":[{"id":"1.229554890","rc":[{"atb":[[16,0],[18.5,0],[22,0]],"id":70003366},{"atl":[[320,0],[420,0]],"id":70003366},{"atb":[[2.02,0],[1.91,0],[1.96,0]],"id":70003367},{"atl":[[6.4,0],[8.4,0]],"id":70003367},{"atb":[[2.02,0],[1.91,0],[1.96,0]],"id":70003364},{"atl":[[6.4,0],[8.4,0]],"id":70003364},{"atb":[[2.88,0],[2.98,0],[2.78,0]],"id":70003365},{"atl":[[10.5,0],[15.5,0]],"id":70003365},{"atb":[[16,0],[18.5,0],[22,0]],"id":70003363},{"atl":[[320,0],[420,0]],"id":70003363}],"con":true,"img":false}]}
{"op":"mcm","clk":"11448494993","pt":1717291222496,"mc":[{"id":"1.229554890","rc":[{"atb":[[17.5,12.67],[20,11],[25,4.35]],"id":70003366},{"atl":[[350,0.39],[450,0.46]],"id":70003366},{"atb":[[2.02,102.47],[1.91,229.73],[1.96,217.77]],"id":70003367},{"atl":[[6.4,25.8],[8.4,28.25]],"id":70003367},{"atb":[[1.99,211.17],[1.94,222.4],[2.08,96.78]],"id":70003364},{"atl":[[8.6,27.5],[6.6,24.88]],"id":70003364},{"atb":[[2.88,111.2],[2.98,52.79],[2.78,117.44]],"id":70003365},{"atl":[[10.5,14.66],[15.5,14.41]],"id":70003365},{"atb":[[17.5,12.67],[20,11],[25,4.35]],"id":70003363},{"atl":[[350,0.39],[450,0.46]],"id":70003363}],"con":true,"img":false}]}
{"op":"mcm","clk":"11448496462","pt":1717291244029,"mc":[{"id":"1.229554890","rc":[{"spn":187.5,"spf":"NaN","id":70003366},{"atb":[[2.02,0],[1.91,0],[1.96,0]],"id":70003367},{"atl":[[6.4,0],[8.4,0]],"id":70003367},{"atb":[[1.99,0],[1.94,0],[2.08,0]],"id":70003364},{"atl":[[8.6,0],[6.6,0]],"id":70003364},{"atb":[[2.88,0],[2.98,0],[2.78,0]],"id":70003365},{"atl":[[10.5,0],[15.5,0]],"id":70003365},{"spn":187.5,"spf":"NaN","id":70003363}],"con":true,"img":false}]}
{"op":"mcm","clk":"11448497015","pt":1717291252057,"mc":[{"id":"1.229554890","rc":[{"atb":[[1.99,211.17],[1.94,222.4],[2.08,96.78]],"id":70003367},{"atl":[[8.6,27.5],[6.6,24.88]],"id":70003367},{"atb":[[1.99,211.17],[1.94,222.4],[2.08,96.78]],"id":70003364},{"atl":[[8.6,27.5],[6.6,24.88]],"id":70003364},{"atb":[[2.8,116.14],[2.9,55.01],[2.7,122.97]],"id":70003365},{"atl":[[10,15.48],[15,14.93]],"id":70003365}],"con":true,"img":false}]}
{"op":"mcm","clk":"11448497991","pt":1717291267478,"mc":[{"id":"1.229554890","rc":[{"atb":[[17.5,0],[20,0],[25,0]],"id":70003366},{"atl":[[350,0],[450,0]],"id":70003366},{"atb":[[1.99,0],[1.94,0],[2.08,0]],"id":70003367},{"atl":[[8.6,0],[6.6,0]],"id":70003367},{"atb":[[1.99,0],[1.94,0],[2.08,0]],"id":70003364},{"atl":[[8.6,0],[6.6,0]],"id":70003364},{"atb":[[2.8,0],[2.9,0],[2.7,0]],"id":70003365},{"atl":[[10,0],[15,0]],"id":70003365},{"atb":[[17.5,0],[20,0],[25,0]],"id":70003363},{"atl":[[350,0],[450,0]],"id":70003363}],"con":true,"img":false}]}
{"op":"mcm","clk":"11448498617","pt":1717291276972,"mc":[{"id":"1.229554890","rc":[{"atb":[[17.5,12.67],[20,11],[25,4.35]],"id":70003366},{"atl":[[350,0.39],[450,0.46]],"id":70003366},{"atb":[[1.99,211.17],[1.94,222.4],[2.08,96.78]],"id":70003367},{"atl":[[8.6,27.5],[6.6,24.88]],"id":70003367},{"atb":[[2.02,204.95],[2.12,93.32],[1.96,217.77]],"id":70003364},{"atl":[[6.8,24.02],[8.8,26.8]],"id":70003364},{"atb":[[2.86,56.19],[2.66,125.93],[2.76,118.78]],"id":70003365},{"atl":[[9.8,15.83],[14.5,15.48]],"id":70003365},{"atb":[[17.5,12.67],[20,11],[25,4.35]],"id":70003363},{"atl":[[350,0.39],[450,0.46]],"id":70003363}],"con":true,"img":false}]}
{"op":"mcm","clk":"11448500201","pt":1717291300007,"mc":[{"id":"1.229554890","rc":[{"atb":[[1.99,0],[1.94,0],[2.08,0]],"id":70003367},{"atl":[[8.6,0],[6.6,0]],"id":70003367},{"atb":[[2.02,0],[2.12,0],[1.96,0]],"id":70003364},{"atl":[[6.8,0],[8.8,0]],"id":70003364},{"atb":[[2.86,0],[2.66,0],[2.76,0]],"id":70003365},{"atl":[[9.8,0],[14.5,0]],"id":70003365}],"con":true,"img":false}]}
{"op":"mcm","clk":"11448500711","pt":1717291307822,"mc":[{"id":"1.229554890","rc":[{"atb":[[1.99,211.17],[1.94,222.4],[2.08,96.78]],"id":70003367},{"atl":[[8.6,27.5],[6.6,24.88]],"id":70003367},{"spn":4.34,"spf":"NaN","id":70003367},{"atb":[[2.06,197.22],[1.98,213.33],[2.16,90.11]],"id":70003364},{"atl":[[9,26.13],[7,23.22]],"id":70003364},{"spn":4.58,"spf":"NaN","id":70003364},{"atb":[[2.86,56.19],[2.66,125.93],[2.76,118.78]],"id":70003365},{"atl":[[9.8,15.83],[14.5,15.48]],"id":70003365},{"spn":6.33,"spf":"NaN","id":70003365}],"con":true,"img":false}]}
{"op":"mcm","clk":"11448505177","pt":1717291373191,"mc":[{"id":"1.229554890","rc":[{"atb":[[1.99,0],[1.94,0],[2.08,0]],"id":70003367},{"atl":[[8.6,0],[6.6,0]],"id":70003367},{"spn":"NaN","spf":"NaN","id":70003367},{"atb":[[2.06,0],[1.98,0],[2.16,0]],"id":70003364},{"atl":[[9,0],[7,0]],"id":70003364},{"spn":"NaN","spf":"NaN","id":70003364},{"atb":[[2.86,0],[2.66,0],[2.76,0]],"id":70003365},{"atl":[[9.8,0],[14.5,0]],"id":70003365},{"spn":"NaN","spf":"NaN","id":70003365}],"con":true,"img":false}]}
{"op":"mcm","clk":"11448506046","pt":1717291384677,"mc":[{"id":"1.229554890","rc":[{"atb":[[1.99,211.17],[1.94,222.4],[2.08,96.78]],"id":70003367},{"atl":[[8.6,27.5],[6.6,24.88]],"id":70003367},{"atb":[[2.02,204.95],[2.22,85.68],[2.12,186.66]],"id":70003364},{"atl":[[7.2,22.48],[9.2,25.49]],"id":70003364},{"atb":[[2.86,56.19],[2.66,125.93],[2.76,118.78]],"id":70003365},{"atl":[[9.8,15.83],[14.5,15.48]],"id":70003365}],"con":true,"img":false}]}
{"op":"mcm","clk":"11448507525","pt":1717291405810,"mc":[{"id":"1.229554890","rc":[{"atb":[[1.99,0],[1.94,0],[2.08,0]],"id":70003367},{"atl":[[8.6,0],[6.6,0]],"id":70003367},{"atb":[[2.86,0],[2.66,0],[2.76,0]],"id":70003365},{"atl":[[9.8,0],[14.5,0]],"id":70003365}],"con":true,"img":false}]}
{"op":"mcm","clk":"11448507967","pt":1717291412383,"mc":[{"id":"1.229554890","rc":[{"atb":[[2.02,204.95],[2.12,93.32],[1.96,217.77]],"id":70003367},{"atl":[[6.8,24.02],[8.8,26.8]],"id":70003367},{"atb":[[2.86,56.19],[2.66,125.93],[2.76,118.78]],"id":70003365},{"atl":[[9.8,15.83],[14.5,15.48]],"id":70003365}],"con":true,"img":false}]}
{"op":"mcm","clk":"11448516305","pt":1717291543772,"mc":[{"id":"1.229554890","rc":[{"atb":[[17.5,0],[20,0],[25,0]],"id":70003366},{"atl":[[350,0],[450,0]],"id":70003366},{"spn":"NaN","spf":"NaN","id":70003366},{"atb":[[2.02,0],[2.12,0],[1.96,0]],"id":70003367},{"atl":[[6.8,0],[8.8,0]],"id":70003367},{"atb":[[2.02,0],[2.22,0],[2.12,0]],"id":70003364},{"atl":[[7.2,0],[9.2,0]],"id":70003364},{"atb":[[2.86,0],[2.66,0],[2.76,0]],"id":70003365},{"atl":[[9.8,0],[14.5,0]],"id":70003365}],"con":true,"img":false}]}
{"op":"mcm","clk":"11448516748","pt":1717291550972,"mc":[{"id":"1.229554890","rc":[{"atb":[[17.5,12.67],[20,11],[25,4.35]],"id":70003366},{"atl":[[350,0.39],[450,0.46]],"id":70003366},{"atb":[[2.02,204.95],[2.12,93.32],[1.96,217.77]],"id":70003367},{"atl":[[6.8,24.02],[8.8,26.8]],"id":70003367},{"atb":[[2.02,204.95],[2.22,85.68],[2.12,186.66]],"id":70003364},{"atl":[[7.2,22.48],[9.2,25.49]],"id":70003364},{"atb":[[2.56,134.01],[2.46,143.19],[2.66,62.96]],"id":70003365},{"atl":[[8.6,18.33],[11.5,19.91]],"id":70003365}],"con":true,"img":false}]}
{"op":"mcm","clk":"11448517440","pt":1717291562288,"mc":[{"id":"1.229554890","rc":[{"atb":[[17.5,0],[20,0],[25,0]],"id":70003366},{"atl":[[350,0],[450,0]],"id":70003366},{"atb":[[2.02,0],[2.12,0],[1.96,0]],"id":70003367},{"atl":[[6.8,0],[8.8,0]],"id":70003367},{"atb":[[2.02,0],[2.22,0],[2.12,0]],"id":70003364},{"atl":[[7.2,0],[9.2,0]],"id":70003364},{"atb":[[2.56,0],[2.46,0],[2.66,0]],"id":70003365},{"atl":[[8.6,0],[11.5,0]],"id":70003365}],"con":true,"img":false}]}
{"op":"mcm","clk":"11448517838","pt":1717291568298,"mc":[{"id":"1.229554890","rc":[{"atb":[[19.5,11.3],[24,9.08],[29,3.73]],"id":70003366},{"atl":[[400,0.35],[500,0.41]],"id":70003366},{"atb":[[2.02,204.95],[2.12,93.32],[1.96,217.77]],"id":70003367},{"atl":[[6.8,24.02],[8.8,26.8]],"id":70003367},{"atb":[[2.32,79.18],[2.22,171.36],[2.12,186.66]],"id":70003364},{"atl":[[7.4,21.77],[9.4,24.88]],"id":70003364},{"atb":[[2.56,134.01],[2.46,143.19],[2.66,62.96]],"id":70003365},{"atl":[[8.6,18.33],[11.5,19.91]],"id":70003365}],"con":true,"img":false}]}
{"op":"mcm","clk":"11448520458","pt":1717291614238,"mc":[{"id":"1.229554890","rc":[{"spn":214.5,"spf":"NaN","id":70003366},{"atb":[[2.02,0],[2.12,0],[1.96,0]],"id":70003367},{"atl":[[6.8,0],[8.8,0]],"id":70003367},{"atb":[[2.32,0],[2.22,0],[2.12,0]],"id":70003364},{"atl":[[7.4,0],[9.4,0]],"id":70003364},{"atb":[[2.56,0],[2.46,0],[2.66,0]],"id":70003365},{"atl":[[8.6,0],[11.5,0]],"id":70003365}],"con":true,"img":false}]}
{"op":"mcm","clk":"11448520760","pt":1717291619576,"mc":[{"id":"1.229554890","rc":[{"atb":[[2.02,204.95],[2.12,93.32],[1.96,217.77]],"id":70003367},{"atl":[[6.8,24.02],[8.8,26.8]],"id":70003367},{"atb":[[2.36,76.85],[2.26,165.92],[2.16,180.22]],"id":70003364},{"atl":[[9.6,24.31],[7.6,21.11]],"id":70003364},{"atb":[[2.42,147.22],[2.52,137.53],[2.62,64.52]],"id":70003365},{"atl":[[11,20.9],[8.4,18.83]],"id":70003365}],"con":true,"img":false}]}
{"op":"mcm","clk":"11448521421","pt":1717291630105,"mc":[{"id":"1.229554890","rc":[{"atb":[[2.02,0],[2.12,0],[1.96,0]],"id":70003367},{"atl":[[6.8,0],[8.8,0]],"id":70003367},{"atb":[[2.42,0],[2.52,0],[2.62,0]],"id":70003365},{"atl":[[11,0],[8.4,0]],"id":70003365}],"con":true,"img":false}]}
{"op":"mcm","clk":"11448521774","pt":1717291635884,"mc":[{"id":"1.229554890","rc":[{"atb":[[2.02,204.95],[2.12,93.32],[1.96,217.77]],"id":70003367},{"atl":[[6.8,24.02],[8.8,26.8]],"id":70003367},{"atb":[[2.42,147.22],[2.52,137.53],[2.62,64.52]],"id":70003365},{"atl":[[11,20.9],[8.4,18.83]],"id":70003365}],"con":true,"img":false}]}
{"op":"mcm","clk":"11448524030","pt":1717291678626,"mc":[{"id":"1.229554890","rc":[{"atb":[[19.5,0],[24,0],[29,0]],"id":70003366},{"atl":[[400,0],[500,0]],"id":70003366},{"spn":"NaN","spf":"NaN","id":70003366},{"spn":4.46,"spf":"NaN","id":70003367},{"spn":4.98,"spf":"NaN","id":70003364},{"spn":5.51,"spf":"NaN","id":70003365}],"con":true,"img":false}]}
{"op":"mcm","clk":"11448524291","pt":1717291682657,"mc":[{"id":"1.229554890","rc":[{"atb":[[19.5,11.3],[24,9.08],[29,3.73]],"id":70003366},{"atl":[[400,0.35],[500,0.41]],"id":70003366}],"con":true,"img":false}]}
{"op":"mcm","clk":"11448527332","pt":1717291733107,"mc":[{"id":"1.229554890","rc":[{"atb":[[2.02,0],[2.12,0],[1.96,0]],"id":70003367},{"atl":[[6.8,0],[8.8,0]],"id":70003367},{"atb":[[2.42,0],[2.52,0],[2.62,0]],"id":70003365},{"atl":[[11,0],[8.4,0]],"id":70003365}],"con":true,"img":false}]}
{"op":"mcm","clk":"11448527765","pt":1717291740723,"mc":[{"id":"1.229554890","rc":[{"spn":214.5,"spf":"NaN","id":70003366},{"atb":[[2.02,204.95],[2.12,93.32],[1.96,217.77]],"id":70003367},{"atl":[[6.8,24.02],[8.8,26.8]],"id":70003367},{"atb":[[2.42,147.22],[2.52,137.53],[2.62,64.52]],"id":70003365},{"atl":[[11,20.9],[8.4,18.83]],"id":70003365}],"con":true,"img":false}]}
{"op":"mcm","clk":"11448528399","pt":1717291751018,"mc":[{"id":"1.229554890","rc":[{"atb":[[19.5,0],[24,0],[29,0]],"id":70003366},{"atl":[[400,0],[500,0]],"id":70003366},{"atb":[[2.02,0],[2.12,0],[1.96,0]],"id":70003367},{"atl":[[6.8,0],[8.8,0]],"id":70003367},{"atb":[[2.36,0],[2.26,0],[2.16,0]],"id":70003364},{"atl":[[9.6,0],[7.6,0]],"id":70003364},{"atb":[[2.42,0],[2.52,0],[2.62,0]],"id":70003365},{"atl":[[11,0],[8.4,0]],"id":70003365}],"con":true,"img":false}]}
{"op":"mcm","clk":"11448528848","pt":1717291758052,"mc":[{"id":"1.229554890","rc":[{"atb":[[19.5,11.3],[24,9.08],[29,3.73]],"id":70003366},{"atl":[[400,0.35],[500,0.41]],"id":70003366},{"atb":[[2.02,204.95],[2.12,93.32],[1.96,217.77]],"id":70003367},{"atl":[[6.8,24.02],[8.8,26.8]],"id":70003367},{"atb":[[2.36,76.85],[2.26,165.92],[2.16,180.22]],"id":70003364},{"atl":[[9.6,24.31],[7.6,21.11]],"id":70003364},{"atb":[[2.42,147.22],[2.52,137.53],[2.62,64.52]],"id":70003365},{"atl":[[11,20.9],[8.4,18.83]],"id":70003365}],"con":true,"img":false}]}
{"op":"mcm","clk":"11448629951","pt":1717293528418,"mc":[{"id":"1.229554890","marketDefinition":{"bspMarket":true,"turnInPlayEnabled":false,"persistenceEnabled":false,"marketBaseRate":7.0,"eventId":"33318908","eventTypeId":"4339","numberOfWinners":1,"bettingType":"ODDS","marketType":"WIN","marketTime":"2024-06-02T08:21:00.000Z","suspendTime":"2024-06-02T08:21:00.000Z","bspReconciled":false,"complete":true,"inPlay":false,"crossMatching":true,"runnersVoidable":false,"numberOfActiveRunners":5,"betDelay":0,"status":"OPEN","runners":[{"status":"ACTIVE","sortPriority":1,"id":70003363,"name":"1. Plodding Along"},{"status":"ACTIVE","sortPriority":2,"id":70003364,"name":"2. Parrakie"},{"status":"ACTIVE","sortPriority":3,"id":70003365,"name":"4. Bookaloo"},{"status":"ACTIVE","sortPriority":4,"id":70003366,"name":"6. Manner Of Strife"},{"status":"ACTIVE","sortPriority":5,"id":70003367,"name":"8. Apilla"}],"regulators":["MR_INT"],"venue":"Murray Bridge","countryCode":"AU","discountAllowed":true,"timezone":"Australia/Adelaide","openDate":"2024-06-02T08:21:00.000Z","version":5962317624,"name":"R1 395m Mdn","eventName":"Murray Bridge (AUS) 2nd Jun"},"rc":[{"atb":[[19.5,11.3],[24,9.08],[29,3.73]],"id":70003366},{"atl":[[400,0.35],[500,0.41]],"id":70003366},{"spn":214.5,"spf":"NaN","id":70003366},{"atb":[[2.02,204.95],[2.12,93.32],[1.96,217.77]],"id":70003367},{"atl":[[6.8,24.02],[8.8,26.8]],"id":70003367},{"spn":4.46,"spf":"NaN","id":70003367},{"atb":[[2.36,76.85],[2.26,165.92],[2.16,180.22]],"id":70003364},{"atl":[[9.6,24.31],[7.6,21.11]],"id":70003364},{"spn":4.98,"spf":"NaN","id":70003364},{"atb":[[2.42,147.22],[2.52,137.53],[2.62,64.52]],"id":70003365},{"atl":[[11,20.9],[8.4,18.83]],"id":70003365},{"spn":5.51,"spf":"NaN","id":70003365},{"atb":[[17.5,12.67],[20,11],[25,4.35]],"id":70003363},{"atl":[[350,0.39],[450,0.46]],"id":70003363},{"spn":187.5,"spf":"NaN","id":70003363}],"con":true,"img":true}]}
{"op":"mcm","clk":"11448772464","pt":1717296122426,"mc":[{"id":"1.229554890","rc":[{"atb":[[2.36,0],[2.26,0],[2.16,0]],"id":70003364},{"atl":[[9.6,0],[7.6,0]],"id":70003364},{"spn":"NaN","spf":"NaN","id":70003364},{"atb":[[17.5,0],[20,0],[25,0]],"id":70003363},{"atl":[[350,0],[450,0]],"id":70003363},{"spn":"NaN","spf":"NaN","id":70003363}],"con":true,"img":false}]}
{"op":"mcm","clk":"11448773249","pt":1717296140447,"mc":[{"id":"1.229554890","rc":[{"atb":[[2.36,76.85],[2.26,165.92],[2.16,180.22]],"id":70003364},{"atl":[[9.6,24.31],[7.6,21.11]],"id":70003364},{"atb":[[17.5,12.67],[20,11],[25,4.35]],"id":70003363},{"atl":[[350,0.39],[450,0.46]],"id":70003363}],"con":true,"img":false}]}
{"op":"mcm","clk":"11448777241","pt":1717296235499,"mc":[{"id":"1.229554890","rc":[{"atb":[[19.5,0],[24,0],[29,0]],"id":70003366},{"atl":[[400,0],[500,0]],"id":70003366},{"spn":"NaN","spf":"NaN","id":70003366},{"atb":[[2.02,0],[2.12,0],[1.96,0]],"id":70003367},{"atl":[[6.8,0],[8.8,0]],"id":70003367},{"spn":"NaN","spf":"NaN","id":70003367},{"atb":[[2.36,0],[2.26,0],[2.16,0]],"id":70003364},{"atl":[[9.6,0],[7.6,0]],"id":70003364},{"atb":[[2.42,0],[2.52,0],[2.62,0]],"id":70003365},{"atl":[[11,0],[8.4,0]],"id":70003365},{"spn":"NaN","spf":"NaN","id":70003365},{"spn":187.5,"spf":"NaN","id":70003363}],"con":true,"img":false}]}
{"op":"mcm","clk":"11448777880","pt":1717296252867,"mc":[{"id":"1.229554890","rc":[{"atb":[[19.5,11.3],[24,9.08],[29,3.73]],"id":70003366},{"atl":[[400,0.35],[500,0.41]],"id":70003366},{"atb":[[2.02,204.95],[2.12,93.32],[1.96,217.77]],"id":70003367},{"atl":[[6.8,24.02],[8.8,26.8]],"id":70003367},{"atb":[[2.36,76.85],[2.26,165.92],[2.16,180.22]],"id":70003364},{"atl":[[9.6,24.31],[7.6,21.11]],"id":70003364},{"atb":[[2.42,147.22],[2.52,137.53],[2.62,64.52]],"id":70003365},{"atl":[[11,20.9],[8.4,18.83]],"id":70003365}],"con":true,"img":false}]}
{"op":"mcm","clk":"11448885224","pt":1717298928435,"mc":[{"id":"1.229554890","marketDefinition":{"bspMarket":true,"turnInPlayEnabled":false,"persistenceEnabled":false,"marketBaseRate":7.0,"eventId":"33318908","eventTypeId":"4339","numberOfWinners":1,"bettingType":"ODDS","marketType":"WIN","marketTime":"2024-06-02T08:21:00.000Z","suspendTime":"2024-06-02T08:21:00.000Z","bspReconciled":false,"complete":true,"inPlay":false,"crossMatching":true,"runnersVoidable":false,"numberOfActiveRunners":5,"betDelay":0,"status":"OPEN","runners":[{"status":"ACTIVE","sortPriority":1,"id":70003363,"name":"1. Plodding Along"},{"status":"ACTIVE","sortPriority":2,"id":70003364,"name":"2. Parrakie"},{"status":"ACTIVE","sortPriority":3,"id":70003365,"name":"4. Bookaloo"},{"status":"ACTIVE","sortPriority":4,"id":70003366,"name":"6. Manner Of Strife"},{"status":"ACTIVE","sortPriority":5,"id":70003367,"name":"8. Apilla"}],"regulators":["MR_INT"],"venue":"Murray Bridge","countryCode":"AU","discountAllowed":true,"timezone":"Australia/Adelaide","openDate":"2024-06-02T08:21:00.000Z","version":5962317624,"name":"R1 395m Mdn","eventName":"Murray Bridge (AUS) 2nd Jun"},"rc":[{"atb":[[19.5,11.3],[24,9.08],[29,3.73]],"id":70003366},{"atl":[[400,0.35],[500,0.41]],"id":70003366},{"spn":214.5,"spf":"NaN","id":70003366},{"atb":[[2.02,204.95],[2.12,93.32],[1.96,217.77]],"id":70003367},{"atl":[[6.8,24.02],[8.8,26.8]],"id":70003367},{"spn":4.46,"spf":"NaN","id":70003367},{"atb":[[2.36,76.85],[2.26,165.92],[2.16,180.22]],"id":70003364},{"atl":[[9.6,24.31],[7.6,21.11]],"id":70003364},{"spn":4.98,"spf":"NaN","id":70003364},{"atb":[[2.42,147.22],[2.52,137.53],[2.62,64.52]],"id":70003365},{"atl":[[11,20.9],[8.4,18.83]],"id":70003365},{"spn":5.51,"spf":"NaN","id":70003365},{"atb":[[17.5,12.67],[20,11],[25,4.35]],"id":70003363},{"atl":[[350,0.39],[450,0.46]],"id":70003363},{"spn":187.5,"spf":"NaN","id":70003363}],"con":true,"img":true}]}
{"op":"mcm","clk":"11448990874","pt":1717301393980,"mc":[{"id":"1.229554890","rc":[{"atb":[[19.5,0],[24,0],[29,0]],"id":70003366},{"atl":[[400,0],[500,0]],"id":70003366},{"atb":[[2.02,0],[2.12,0],[1.96,0]],"id":70003367},{"atl":[[6.8,0],[8.8,0]],"id":70003367},{"atb":[[2.36,0],[2.26,0],[2.16,0]],"id":70003364},{"atl":[[9.6,0],[7.6,0]],"id":70003364},{"atb":[[2.42,0],[2.52,0],[2.62,0]],"id":70003365},{"atl":[[11,0],[8.4,0]],"id":70003365},{"atb":[[17.5,0],[20,0],[25,0]],"id":70003363},{"atl":[[350,0],[450,0]],"id":70003363},{"spn":"NaN","spf":"NaN","id":70003363}],"con":true,"img":false}]}
{"op":"mcm","clk":"11448991763","pt":1717301409733,"mc":[{"id":"1.229554890","rc":[{"atb":[[19.5,11.3],[24,9.08],[29,3.73]],"id":70003366},{"atl":[[400,0.35],[500,0.41]],"id":70003366},{"atb":[[2.02,204.95],[2.12,93.32],[1.96,217.77]],"id":70003367},{"atl":[[6.8,24.02],[8.8,26.8]],"id":70003367},{"atb":[[1.99,211.17],[1.94,222.4],[2.08,96.78]],"id":70003364},{"atl":[[8.6,27.5],[6.6,24.88]],"id":70003364},{"atb":[[2.32,158.38],[2.42,147.22],[2.52,68.77]],"id":70003365},{"atl":[[10.5,22],[8.2,19.35]],"id":70003365},{"atb":[[10.5,22],[13,17.42],[15.5,7.2]],"id":70003363},{"atl":[[340,0.61],[240,0.58]],"id":70003363}],"con":true,"img":false}]}
{"op":"mcm","clk":"11448993604","pt":1717301444870,"mc":[{"id":"1.229554890","rc":[{"atb":[[19.5,0],[24,0],[29,0]],"id":70003366},{"atl":[[400,0],[500,0]],"id":70003366},{"atb":[[2.02,0],[2.12,0],[1.96,0]],"id":70003367},{"atl":[[6.8,0],[8.8,0]],"id":70003367},{"atb":[[1.99,0],[1.94,0],[2.08,0]],"id":70003364},{"atl":[[8.6,0],[6.6,0]],"id":70003364},{"atb":[[2.32,0],[2.42,0],[2.52,0]],"id":70003365},{"atl":[[10.5,0],[8.2,0]],"id":70003365},{"atb":[[10.5,0],[13,0],[15.5,0]],"id":70003363},{"atl":[[340,0],[240,0]],"id":70003363}],"con":true,"img":false}]}
{"op":"mcm","clk":"11448994259","pt":1717301457173,"mc":[{"id":"1.229554890","rc":[{"atb":[[19.5,11.3],[24,9.08],[29,3.73]],"id":70003366},{"atl":[[400,0.35],[500,0.41]],"id":70003366},{"spn":214.5,"spf":"NaN","id":70003366},{"atb":[[2.02,204.95],[2.12,93.32],[1.96,217.77]],"id":70003367},{"atl":[[6.8,24.02],[8.8,26.8]],"id":70003367},{"spn":4.46,"spf":"NaN","id":70003367},{"atb":[[1.99,211.17],[1.94,222.4],[2.08,96.78]],"id":70003364},{"atl":[[8.6,27.5],[6.6,24.88]],"id":70003364},{"spn":4.34,"spf":"NaN","id":70003364},{"atb":[[2.32,158.38],[2.42,147.22],[2.52,68.77]],"id":70003365},{"atl":[[10.5,22],[8.2,19.35]],"id":70003365},{"spn":5.36,"spf":"NaN","id":70003365},{"atb":[[10.5,22],[13,17.42],[15.5,7.2]],"id":70003363},{"atl":[[340,0.61],[240,0.58]],"id":70003363},{"spn":127.75,"spf":"NaN","id":70003363}],"con":true,"img":false}]}
{"op":"mcm","clk":"11448995833","pt":1717301484409,"mc":[{"id":"1.229554890","rc":[{"atb":[[19.5,0],[24,0],[29,0]],"id":70003366},{"atl":[[400,0],[500,0]],"id":70003366},{"atb":[[1.99,0],[1.94,0],[2.08,0]],"id":70003364},{"atl":[[8.6,0],[6.6,0]],"id":70003364},{"atb":[[10.5,0],[13,0],[15.5,0]],"id":70003363},{"atl":[[340,0],[240,0]],"id":70003363}],"con":true,"img":false}]}
{"op":"mcm","clk":"11448996689","pt":1717301499641,"mc":[{"id":"1.229554890","rc":[{"atb":[[32,3.37],[21,10.45],[26,8.36]],"id":70003366},{"atl":[[520,0.4],[420,0.33]],"id":70003366},{"atb":[[1.99,211.17],[1.94,222.4],[2.08,96.78]],"id":70003364},{"atl":[[8.6,27.5],[6.6,24.88]],"id":70003364},{"atb":[[10.5,22],[13,17.42],[15.5,7.2]],"id":70003363},{"atl":[[340,0.61],[240,0.58]],"id":70003363}],"con":true,"img":false}]}
{"op":"mcm","clk":"11448998387","pt":1717301534009,"mc":[{"id":"1.229554890","rc":[{"atb":[[32,0],[21,0],[26,0]],"id":70003366},{"atl":[[520,0],[420,0]],"id":70003366},{"spn":"NaN","spf":"NaN","id":70003366},{"atb":[[1.99,0],[1.94,0],[2.08,0]],"id":70003364},{"atl":[[8.6,0],[6.6,0]],"id":70003364},{"spn":"NaN","spf":"NaN","id":70003364},{"atb":[[10.5,0],[13,0],[15.5,0]],"id":70003363},{"atl":[[340,0],[240,0]],"id":70003363},{"spn":"NaN","spf":"NaN","id":70003363}],"con":true,"img":false}]}
{"op":"mcm","clk":"11448999556","pt":1717301555299,"mc":[{"id":"1.229554890","rc":[{"atb":[[18,12.29],[21,10.45],[26,4.18]],"id":70003366},{"atl":[[360,0.38],[460,0.45]],"id":70003366},{"atb":[[1.99,211.17],[1.94,222.4],[2.08,96.78]],"id":70003364},{"atl":[[8.6,27.5],[6.6,24.88]],"id":70003364},{"atb":[[10.5,22],[13,17.42],[15.5,7.2]],"id":70003363},{"atl":[[340,0.61],[240,0.58]],"id":70003363}],"con":true,"img":false}]}
{"op":"mcm","clk":"11449002373","pt":1717301606771,"mc":[{"id":"1.229554890","rc":[{"atb":[[18,0],[21,0],[26,0]],"id":70003366},{"atl":[[360,0],[460,0]],"id":70003366},{"atb":[[2.02,0],[2.12,0],[1.96,0]],"id":70003367},{"atl":[[6.8,0],[8.8,0]],"id":70003367},{"spn":"NaN","spf":"NaN","id":70003367},{"atb":[[1.99,0],[1.94,0],[2.08,0]],"id":70003364},{"atl":[[8.6,0],[6.6,0]],"id":70003364},{"atb":[[2.32,0],[2.42,0],[2.52,0]],"id":70003365},{"atl":[[10.5,0],[8.2,0]],"id":70003365},{"spn":"NaN","spf":"NaN","id":70003365},{"atb":[[10.5,0],[13,0],[15.5,0]],"id":70003363},{"atl":[[340,0],[240,0]],"id":70003363}],"con":true,"img":false}]}
{"op":"mcm","clk":"11449003390","pt":1717301626865,"mc":[{"id":"1.229554890","rc":[{"atb":[[18,12.29],[21,10.45],[26,4.18]],"id":70003366},{"atl":[[360,0.38],[460,0.45]],"id":70003366},{"atb":[[2.02,204.95],[2.12,93.32],[1.96,217.77]],"id":70003367},{"atl":[[6.8,24.02],[8.8,26.8]],"id":70003367},{"atb":[[1.99,211.17],[1.94,222.4],[2.08,96.78]],"id":70003364},{"atl":[[8.6,27.5],[6.6,24.88]],"id":70003364},{"atb":[[2.36,153.71],[2.46,71.59],[2.26,165.92]],"id":70003365},{"atl":[[8,19.91],[10,23.22]],"id":70003365},{"atb":[[10.5,22],[13,17.42],[15.5,7.2]],"id":70003363},{"atl":[[340,0.61],[240,0.58]],"id":70003363}],"con":true,"img":false}]}
{"op":"mcm","clk":"11449012695","pt":1717301809743,"mc":[{"id":"1.229554890","rc":[{"atb":[[18,0],[21,0],[26,0]],"id":70003366},{"atl":[[360,0],[460,0]],"id":70003366},{"atb":[[2.02,0],[2.12,0],[1.96,0]],"id":70003367},{"atl":[[6.8,0],[8.8,0]],"id":70003367},{"spn":4.34,"spf":"NaN","id":70003364},{"atb":[[2.36,0],[2.46,0],[2.26,0]],"id":70003365},{"atl":[[8,0],[10,0]],"id":70003365},{"spn":127.75,"spf":"NaN","id":70003363}],"con":true,"img":false}]}
{"op":"mcm","clk":"11449014020","pt":1717301838486,"mc":[{"id":"1.229554890","rc":[{"atb":[[18,12.29],[21,10.45],[26,4.18]],"id":70003366},{"atl":[[360,0.38],[460,0.45]],"id":70003366},{"atb":[[2.02,204.95],[2.12,93.32],[1.96,217.77]],"id":70003367},{"atl":[[6.8,24.02],[8.8,26.8]],"id":70003367},{"atb":[[2.36,153.71],[2.46,71.59],[2.26,165.92]],"id":70003365},{"atl":[[8,19.91],[10,23.22]],"id":70003365}],"con":true,"img":false}]}
{"op":"mcm","clk":"11449015138","pt":1717301864300,"mc":[{"id":"1.229554890","rc":[{"atb":[[2.02,0],[2.12,0],[1.96,0]],"id":70003367},{"atl":[[6.8,0],[8.8,0]],"id":70003367},{"atb":[[1.99,0],[1.94,0],[2.08,0]],"id":70003364},{"atl":[[8.6,0],[6.6,0]],"id":70003364},{"atb":[[2.36,0],[2.46,0],[2.26,0]],"id":70003365},{"atl":[[8,0],[10,0]],"id":70003365},{"atb":[[10.5,0],[13,0],[15.5,0]],"id":70003363},{"atl":[[340,0],[240,0]],"id":70003363}],"con":true,"img":false}]}
{"op":"mcm","clk":"11449015693","pt":1717301876517,"mc":[{"id":"1.229554890","rc":[{"spn":193.0,"spf":"NaN","id":70003366},{"atb":[[2.02,204.95],[2.12,93.32],[1.96,217.77]],"id":70003367},{"atl":[[6.8,24.02],[8.8,26.8]],"id":70003367},{"spn":4.46,"spf":"NaN","id":70003367},{"atb":[[2.02,102.47],[1.91,229.73],[1.96,217.77]],"id":70003364},{"atl":[[6.4,25.8],[8.4,28.25]],"id":70003364},{"spn":4.21,"spf":"NaN","id":70003364},{"atb":[[2.32,158.38],[2.42,73.61],[2.22,171.36]],"id":70003365},{"atl":[[9.8,23.75],[7.8,20.49]],"id":70003365},{"spn":5.11,"spf":"NaN","id":70003365},{"atb":[[10.5,22],[13,17.42],[15.5,7.2]],"id":70003363},{"atl":[[340,0.61],[240,0.58]],"id":70003363}],"con":true,"img":false}]}
{"op":"mcm","clk":"11449020027","pt":1717301965559,"mc":[{"id":"1.229554890","rc":[{"atb":[[18,0],[21,0],[26,0]],"id":70003366},{"atl":[[360,0],[460,0]],"id":70003366},{"spn":"NaN","spf":"NaN","id":70003366},{"atb":[[2.02,0],[2.12,0],[1.96,0]],"id":70003367},{"atl":[[6.8,0],[8.8,0]],"id":70003367},{"spn":"NaN","spf":"NaN","id":70003367},{"atb":[[2.02,0],[1.91,0],[1.96,0]],"id":70003364},{"atl":[[6.4,0],[8.4,0]],"id":70003364},{"spn":"NaN","spf":"NaN","id":70003364},{"atb":[[2.32,0],[2.42,0],[2.22,0]],"id":70003365},{"atl":[[9.8,0],[7.8,0]],"id":70003365},{"spn":"NaN","spf":"NaN","id":70003365}],"con":true,"img":false}]}
{"op":"mcm","clk":"11449020854","pt":1717301985172,"mc":[{"id":"1.229554890","rc":[{"atb":[[38,2.82],[24,9.08],[29,7.46]],"id":70003366},{"atl":[[550,0.38],[450,0.3]],"id":70003366},{"atb":[[2.02,204.95],[2.12,93.32],[1.96,217.77]],"id":70003367},{"atl":[[6.8,24.02],[8.8,26.8]],"id":70003367},{"atb":[[2.02,102.47],[1.91,229.73],[1.96,217.77]],"id":70003364},{"atl":[[6.4,25.8],[8.4,28.25]],"id":70003364},{"atb":[[2.32,158.38],[2.42,73.61],[2.22,171.36]],"id":70003365},{"atl":[[9.8,23.75],[7.8,20.49]],"id":70003365}],"con":true,"img":false}]}
{"op":"mcm","clk":"11449022542","pt":1717302023274,"mc":[{"id":"1.229554890","rc":[{"atb":[[2.02,0],[2.12,0],[1.96,0]],"id":70003367},{"atl":[[6.8,0],[8.8,0]],"id":70003367},{"atb":[[2.02,0],[1.91,0],[1.96,0]],"id":70003364},{"atl":[[6.4,0],[8.4,0]],"id":70003364},{"atb":[[2.32,0],[2.42,0],[2.22,0]],"id":70003365},{"atl":[[9.8,0],[7.8,0]],"id":70003365}],"con":true,"img":false}]}
{"op":"mcm","clk":"11449023117","pt":1717302036350,"mc":[{"id":"1.229554890","rc":[{"spn":244.0,"spf":"NaN","id":70003366},{"atb":[[2.02,204.95],[2.22,85.68],[2.12,186.66]],"id":70003367},{"atl":[[7.2,22.48],[9.2,25.49]],"id":70003367},{"spn":4.71,"spf":"NaN","id":70003367},{"atb":[[2.02,102.47],[1.91,229.73],[1.96,217.77]],"id":70003364},{"atl":[[6.4,25.8],[8.4,28.25]],"id":70003364},{"spn":4.21,"spf":"NaN","id":70003364},{"atb":[[2.32,158.38],[2.42,73.61],[2.22,171.36]],"id":70003365},{"atl":[[9.8,23.75],[7.8,20.49]],"id":70003365},{"spn":5.11,"spf":"NaN","id":70003365}],"con":true,"img":false}]}
{"op":"mcm","clk":"11449024254","pt":1717302063805,"mc":[{"id":"1.229554890","rc":[{"atb":[[38,0],[24,0],[29,0]],"id":70003366},{"atl":[[550,0],[450,0]],"id":70003366},{"atb":[[2.02,0],[2.22,0],[2.12,0]],"id":70003367},{"atl":[[7.2,0],[9.2,0]],"id":70003367},{"atb":[[2.02,0],[1.91,0],[1.96,0]],"id":70003364},{"atl":[[6.4,0],[8.4,0]],"id":70003364},{"atb":[[2.32,0],[2.42,0],[2.22,0]],"id":70003365},{"atl":[[9.8,0],[7.8,0]],"id":70003365},{"atb":[[10.5,0],[13,0],[15.5,0]],"id":70003363},{"atl":[[340,0],[240,0]],"id":70003363}],"con":true,"img":false}]}
{"op":"mcm","clk":"11449024937","pt":1717302080015,"mc":[{"id":"1.229554890","rc":[{"atb":[[38,2.82],[24,9.08],[29,7.46]],"id":70003366},{"atl":[[550,0.38],[450,0.3]],"id":70003366},{"atb":[[2.02,204.95],[2.22,85.68],[2.12,186.66]],"id":70003367},{"atl":[[7.2,22.48],[9.2,25.49]],"id":70003367},{"atb":[[2.02,102.47],[1.91,229.73],[1.96,217.77]],"id":70003364},{"atl":[[6.4,25.8],[8.4,28.25]],"id":70003364},{"atb":[[2.36,153.71],[2.46,71.59],[2.26,165.92]],"id":70003365},{"atl":[[8,19.91],[10,23.22]],"id":70003365},{"atb":[[10.5,22],[13,17.42],[15.5,7.2]],"id":70003363},{"atl":[[340,0.61],[240,0.58]],"id":70003363}],"con":true,"img":false}]}
{"op":"mcm","clk":"11449025877","pt":1717302103368,"mc":[{"id":"1.229554890","rc":[{"atb":[[38,0],[24,0],[29,0]],"id":70003366},{"atl":[[550,0],[450,0]],"id":70003366},{"spn":"NaN","spf":"NaN","id":70003366},{"atb":[[2.02,0],[2.22,0],[2.12,0]],"id":70003367},{"atl":[[7.2,0],[9.2,0]],"id":70003367},{"spn":"NaN","spf":"NaN","id":70003367},{"atb":[[2.02,0],[1.91,0],[1.96,0]],"id":70003364},{"atl":[[6.4,0],[8.4,0]],"id":70003364},{"spn":"NaN","spf":"NaN","id":70003364},{"atb":[[2.36,0],[2.46,0],[2.26,0]],"id":70003365},{"atl":[[8,0],[10,0]],"id":70003365},{"spn":"NaN","spf":"NaN","id":70003365},{"atb":[[10.5,0],[13,0],[15.5,0]],"id":70003363},{"atl":[[340,0],[240,0]],"id":70003363},{"spn":"NaN","spf":"NaN","id":70003363}],"con":true,"img":false}]}
{"op":"mcm","clk":"11449026271","pt":1717302113439,"mc":[{"id":"1.229554890","rc":[{"atb":[[32,3.37],[21,10.45],[26,8.36]],"id":70003366},{"atl":[[520,0.4],[420,0.33]],"id":70003366},{"atb":[[2.28,81.66],[2.18,177.16],[2.08,193.57]],"id":70003367},{"atl":[[7.4,21.77],[9.4,24.88]],"id":70003367},{"atb":[[2.02,102.47],[1.91,229.73],[1.96,217.77]],"id":70003364},{"atl":[[6.4,25.8],[8.4,28.25]],"id":70003364},{"atb":[[2.36,153.71],[2.46,71.59],[2.26,165.92]],"id":70003365},{"atl":[[8,19.91],[10,23.22]],"id":70003365},{"atb":[[10.5,22],[13,17.42],[15.5,7.2]],"id":70003363},{"atl":[[340,0.61],[240,0.58]],"id":70003363}],"con":true,"img":false}]}
{"op":"mcm","clk":"11449119139","pt":1717304328431,"mc":[{"id":"1.229554890","marketDefinition":{"bspMarket":true,"turnInPlayEnabled":false,"persistenceEnabled":false,"marketBaseRate":7.0,"eventId":"33318908","eventTypeId":"4339","numberOfWinners":1,"bettingType":"ODDS","marketType":"WIN","marketTime":"2024-06-02T08:21:00.000Z","suspendTime":"2024-06-02T08:21:00.000Z","bspReconciled":false,"complete":true,"inPlay":false,"crossMatching":true,"runnersVoidable":false,"numberOfActiveRunners":5,"betDelay":0,"status":"OPEN","runners":[{"status":"ACTIVE","sortPriority":1,"id":70003363,"name":"1. Plodding Along"},{"status":"ACTIVE","sortPriority":2,"id":70003364,"name":"2. Parrakie"},{"status":"ACTIVE","sortPriority":3,"id":70003365,"name":"4. Bookaloo"},{"status":"ACTIVE","sortPriority":4,"id":70003366,"name":"6. Manner Of Strife"},{"status":"ACTIVE","sortPriority":5,"id":70003367,"name":"8. Apilla"}],"regulators":["MR_INT"],"venue":"Murray Bridge","countryCode":"AU","discountAllowed":true,"timezone":"Australia/Adelaide","openDate":"2024-06-02T08:21:00.000Z","version":5962317624,"name":"R1 395m Mdn","eventName":"Murray Bridge (AUS) 2nd Jun"},"rc":[{"atb":[[32,3.37],[21,10.45],[26,8.36]],"id":70003366},{"atl":[[520,0.4],[420,0.33]],"id":70003366},{"spn":226.0,"spf":"NaN","id":70003366},{"atb":[[2.28,81.66],[2.18,177.16],[2.08,193.57]],"id":70003367},{"atl":[[7.4,21.77],[9.4,24.88]],"id":70003367},{"spn":4.84,"spf":"NaN","id":70003367},{"atb":[[2.02,102.47],[1.91,229.73],[1.96,217.77]],"id":70003364},{"atl":[[6.4,25.8],[8.4,28.25]],"id":70003364},{"spn":4.21,"spf":"NaN","id":70003364},{"atb":[[2.36,153.71],[2.46,71.59],[2.26,165.92]],"id":70003365},{"atl":[[8,19.91],[10,23.22]],"id":70003365},{"spn":5.23,"spf":"NaN","id":70003365},{"atb":[[10.5,22],[13,17.42],[15.5,7.2]],"id":70003363},{"atl":[[340,0.61],[240,0.58]],"id":70003363},{"spn":127.75,"spf":"NaN","id":70003363}],"con":true,"img":true}]}
{"op":"mcm","clk":"11449222793","pt":1717305798995,"mc":[{"id":"1.229554890","rc":[{"atb":[[32,0],[21,0],[26,0]],"id":70003366},{"atl":[[520,0],[420,0]],"id":70003366},{"atb":[[2.28,0],[2.18,0],[2.08,0]],"id":70003367},{"atl":[[7.4,0],[9.4,0]],"id":70003367},{"atb":[[2.02,0],[1.91,0],[1.96,0]],"id":70003364},{"atl":[[6.4,0],[8.4,0]],"id":70003364},{"atb":[[2.36,0],[2.46,0],[2.26,0]],"id":70003365},{"atl":[[8,0],[10,0]],"id":70003365},{"atb":[[10.5,0],[13,0],[15.5,0]],"id":70003363},{"atl":[[340,0],[240,0]],"id":70003363}],"con":true,"img":false}]}
{"op":"mcm","clk":"11449223860","pt":1717305813531,"mc":[{"id":"1.229554890","rc":[{"atb":[[32,3.37],[21,10.45],[26,8.36]],"id":70003366},{"atl":[[520,0.4],[420,0.33]],"id":70003366},{"atb":[[2.28,81.66],[2.18,177.16],[2.08,193.57]],"id":70003367},{"atl":[[7.4,21.77],[9.4,24.88]],"id":70003367},{"atb":[[1.83,251.88],[1.88,237.56],[1.93,112.39]],"id":70003364},{"atl":[[5.6,30.29],[7.2,33.71]],"id":70003364},{"atb":[[2.32,158.38],[2.42,73.61],[2.22,171.36]],"id":70003365},{"atl":[[9.8,23.75],[7.8,20.49]],"id":70003365},{"atb":[[17,6.53],[12,19],[14.5,15.48]],"id":70003363},{"atl":[[350,0.59],[250,0.55]],"id":70003363}],"con":true,"img":false}]}
{"op":"mcm","clk":"11449228501","pt":1717305881325,"mc":[{"id":"1.229554890","rc":[{"spn":226.0,"spf":"NaN","id":70003366},{"atb":[[2.28,0],[2.18,0],[2.08,0]],"id":70003367},{"atl":[[7.4,0],[9.4,0]],"id":70003367},{"atb":[[1.83,0],[1.88,0],[1.93,0]],"id":70003364},{"atl":[[5.6,0],[7.2,0]],"id":70003364},{"atb":[[2.32,0],[2.42,0],[2.22,0]],"id":70003365},{"atl":[[9.8,0],[7.8,0]],"id":70003365},{"spn":133.5,"spf":"NaN","id":70003363}],"con":true,"img":false}]}
{"op":"mcm","clk":"11449230789","pt":1717305912539,"mc":[{"id":"1.229554890","rc":[{"atb":[[2.28,81.66],[2.18,177.16],[2.08,193.57]],"id":70003367},{"atl":[[7.4,21.77],[9.4,24.88]],"id":70003367},{"atb":[[1.83,251.88],[1.88,237.56],[1.93,112.39]],"id":70003364},{"atl":[[5.6,30.29],[7.2,33.71]],"id":70003364},{"atb":[[2.32,158.38],[2.42,73.61],[2.22,171.36]],"id":70003365},{"atl":[[9.8,23.75],[7.8,20.49]],"id":70003365}],"con":true,"img":false}]}
{"op":"mcm","clk":"11449233576","pt":1717305955844,"mc":[{"id":"1.229554890","rc":[{"atb":[[32,0],[21,0],[26,0]],"id":70003366},{"atl":[[520,0],[420,0]],"id":70003366},{"spn":"NaN","spf":"NaN","id":70003366},{"atb":[[2.28,0],[2.18,0],[2.08,0]],"id":70003367},{"atl":[[7.4,0],[9.4,0]],"id":70003367},{"atb":[[1.83,0],[1.88,0],[1.93,0]],"id":70003364},{"atl":[[5.6,0],[7.2,0]],"id":70003364},{"atb":[[2.32,0],[2.42,0],[2.22,0]],"id":70003365},{"atl":[[9.8,0],[7.8,0]],"id":70003365},{"atb":[[17,0],[12,0],[14.5,0]],"id":70003363},{"atl":[[350,0],[250,0]],"id":70003363},{"spn":"NaN","spf":"NaN","id":70003363}],"con":true,"img":false}]}
{"op":"mcm","clk":"11449234827","pt":1717305972932,"mc":[{"id":"1.229554890","rc":[{"atb":[[38,2.82],[24,9.08],[29,7.46]],"id":70003366},{"atl":[[550,0.38],[450,0.3]],"id":70003366},{"atb":[[2.32,79.18],[2.22,171.36],[2.12,186.66]],"id":70003367},{"atl":[[7.4,21.77],[9.4,24.88]],"id":70003367},{"atb":[[1.73,143.19],[1.63,331.84],[1.68,307.44]],"id":70003364},{"atl":[[4,46.45],[5,52.26]],"id":70003364},{"atb":[[2.36,153.71],[2.46,71.59],[2.26,165.92]],"id":70003365},{"atl":[[8,19.91],[10,23.22]],"id":70003365},{"atb":[[12,19],[9.8,23.75],[14.5,7.74]],"id":70003363},{"atl":[[330,0.63],[230,0.6]],"id":70003363}],"con":true,"img":false}]}
{"op":"mcm","clk":"11449237628","pt":1717306014307,"mc":[{"id":"1.229554890","rc":[{"atb":[[38,0],[24,0],[29,0]],"id":70003366},{"atl":[[550,0],[450,0]],"id":70003366},{"atb":[[2.32,0],[2.22,0],[2.12,0]],"id":70003367},{"atl":[[7.4,0],[9.4,0]],"id":70003367},{"atb":[[1.73,0],[1.63,0],[1.68,0]],"id":70003364},{"atl":[[4,0],[5,0]],"id":70003364},{"atb":[[2.36,0],[2.46,0],[2.26,0]],"id":70003365},{"atl":[[8,0],[10,0]],"id":70003365},{"atb":[[12,0],[9.8,0],[14.5,0]],"id":70003363},{"atl":[[330,0],[230,0]],"id":70003363}],"con":true,"img":false}]}
{"op":"mcm","clk":"11449238752","pt":1717306032017,"mc":[{"id":"1.229554890","rc":[{"atb":[[38,2.82],[24,9.08],[29,7.46]],"id":70003366},{"atl":[[550,0.38],[450,0.3]],"id":70003366},{"spn":244.0,"spf":"NaN","id":70003366},{"atb":[[2.32,79.18],[2.22,171.36],[2.12,186.66]],"id":70003367},{"atl":[[7.4,21.77],[9.4,24.88]],"id":70003367},{"spn":4.86,"spf":"NaN","id":70003367},{"atb":[[1.73,143.19],[1.63,331.84],[1.68,307.44]],"id":70003364},{"atl":[[4,46.45],[5,52.26]],"id":70003364},{"spn":2.86,"spf":"NaN","id":70003364},{"atb":[[2.36,153.71],[2.46,71.59],[2.26,165.92]],"id":70003365},{"atl":[[8,19.91],[10,23.22]],"id":70003365},{"spn":5.23,"spf":"NaN","id":70003365},{"atb":[[12,19],[9.8,23.75],[14.5,7.74]],"id":70003363},{"atl":[[330,0.63],[230,0.6]],"id":70003363},{"spn":122.25,"spf":"NaN","id":70003363}],"con":true,"img":false}]}
{"op":"mcm","clk":"11449241221","pt":1717306068555,"mc":[{"id":"1.229554890","rc":[{"atb":[[38,0],[24,0],[29,0]],"id":70003366},{"atl":[[550,0],[450,0]],"id":70003366}],"con":true,"img":false}]}
{"op":"mcm","clk":"11449241953","pt":1717306078693,"mc":[{"id":"1.229554890","rc":[{"atb":[[38,2.82],[24,9.08],[29,7.46]],"id":70003366},{"atl":[[550,0.38],[450,0.3]],"id":70003366}],"con":true,"img":false}]}
{"op":"mcm","clk":"11449258053","pt":1717306290281,"mc":[{"id":"1.229554890","rc":[{"atb":[[38,0],[24,0],[29,0]],"id":70003366},{"atl":[[550,0],[450,0]],"id":70003366},{"spn":"NaN","spf":"NaN","id":70003366},{"atb":[[2.32,0],[2.22,0],[2.12,0]],"id":70003367},{"atl":[[7.4,0],[9.4,0]],"id":70003367},{"spn":"NaN","spf":"NaN","id":70003367},{"atb":[[1.73,0],[1.63,0],[1.68,0]],"id":70003364},{"atl":[[4,0],[5,0]],"id":70003364},{"spn":"NaN","spf":"NaN","id":70003364},{"atb":[[2.36,0],[2.46,0],[2.26,0]],"id":70003365},{"atl":[[8,0],[10,0]],"id":70003365},{"spn":"NaN","spf":"NaN","id":70003365},{"atb":[[12,0],[9.8,0],[14.5,0]],"id":70003363},{"atl":[[330,0],[230,0]],"id":70003363},{"spn":"NaN","spf":"NaN","id":70003363}],"con":true,"img":false}]}
{"op":"mcm","clk":"11449259122","pt":1717306303983,"mc":[{"id":"1.229554890","rc":[{"atb":[[38,2.82],[24,9.08],[29,7.46]],"id":70003366},{"atl":[[550,0.38],[450,0.3]],"id":70003366},{"atb":[[2.38,151.49],[2.58,66.16],[2.48,141.25]],"id":70003367},{"atl":[[11,20.9],[8.4,18.83]],"id":70003367},{"atb":[[1.73,143.19],[1.63,331.84],[1.68,307.44]],"id":70003364},{"atl":[[4,46.45],[5,52.26]],"id":70003364},{"atb":[[2.42,147.22],[2.52,137.53],[2.62,64.52]],"id":70003365},{"atl":[[11,20.9],[8.4,18.83]],"id":70003365},{"atb":[[12,19],[9.8,23.75],[14.5,7.74]],"id":70003363},{"atl":[[330,0.63],[230,0.6]],"id":70003363}],"con":true,"img":false}]}
{"op":"mcm","clk":"11449262352","pt":1717306345421,"mc":[{"id":"1.229554890","rc":[{"atb":[[38,0],[24,0],[29,0]],"id":70003366},{"atl":[[550,0],[450,0]],"id":70003366},{"atb":[[2.38,0],[2.58,0],[2.48,0]],"id":70003367},{"atl":[[11,0],[8.4,0]],"id":70003367},{"atb":[[1.73,0],[1.63,0],[1.68,0]],"id":70003364},{"atl":[[4,0],[5,0]],"id":70003364},{"atb":[[2.42,0],[2.52,0],[2.62,0]],"id":70003365},{"atl":[[11,0],[8.4,0]],"id":70003365},{"atb":[[12,0],[9.8,0],[14.5,0]],"id":70003363},{"atl":[[330,0],[230,0]],"id":70003363}],"con":true,"img":false}]}
{"op":"mcm","clk":"11449263734","pt":1717306363673,"mc":[{"id":"1.229554890","rc":[{"atb":[[38,2.82],[24,9.08],[29,7.46]],"id":70003366},{"atl":[[550,0.38],[450,0.3]],"id":70003366},{"spn":244.0,"spf":"NaN","id":70003366},{"atb":[[2.58,132.31],[2.78,58.72],[2.68,124.44]],"id":70003367},{"atl":[[13.5,16.72],[9.4,16.58]],"id":70003367},{"spn":6.09,"spf":"NaN","id":70003367},{"atb":[[1.73,143.19],[1.63,331.84],[1.68,307.44]],"id":70003364},{"atl":[[4,46.45],[5,52.26]],"id":70003364},{"spn":2.86,"spf":"NaN","id":70003364},{"atb":[[2.72,60.77],[2.52,137.53],[2.62,129.05]],"id":70003365},{"atl":[[9,17.42],[12.5,18.18]],"id":70003365},{"spn":5.86,"spf":"NaN","id":70003365},{"atb":[[12,19],[9.8,23.75],[14.5,7.74]],"id":70003363},{"atl":[[330,0.63],[230,0.6]],"id":70003363},{"spn":122.25,"spf":"NaN","id":70003363}],"con":true,"img":false}]}
{"op":"mcm","clk":"11449301937","pt":1717306870185,"mc":[{"id":"1.229554890","rc":[{"atb":[[38,0],[24,0],[29,0]],"id":70003366},{"atl":[[550,0],[450,0]],"id":70003366},{"spn":"NaN","spf":"NaN","id":70003366},{"atb":[[2.58,0],[2.78,0],[2.68,0]],"id":70003367},{"atl":[[13.5,0],[9.4,0]],"id":70003367},{"spn":"NaN","spf":"NaN","id":70003367},{"atb":[[1.73,0],[1.63,0],[1.68,0]],"id":70003364},{"atl":[[4,0],[5,0]],"id":70003364},{"spn":"NaN","spf":"NaN","id":70003364},{"atb":[[2.72,0],[2.52,0],[2.62,0]],"id":70003365},{"atl":[[9,0],[12.5,0]],"id":70003365},{"spn":"NaN","spf":"NaN","id":70003365},{"atb":[[12,0],[9.8,0],[14.5,0]],"id":70003363},{"atl":[[330,0],[230,0]],"id":70003363},{"spn":"NaN","spf":"NaN","id":70003363}],"con":true,"img":false}]}
{"op":"mcm","clk":"11449304928","pt":1717306910017,"mc":[{"id":"1.229554890","rc":[{"atb":[[38,2.82],[24,9.08],[29,7.46]],"id":70003366},{"atl":[[550,0.38],[450,0.3]],"id":70003366},{"atb":[[2.58,132.31],[2.78,58.72],[2.68,124.44]],"id":70003367},{"atl":[[13.5,16.72],[9.4,16.58]],"id":70003367},{"atb":[[1.73,143.19],[1.63,331.84],[1.68,307.44]],"id":70003364},{"atl":[[4,46.45],[5,52.26]],"id":70003364},{"atb":[[2.72,60.77],[2.52,137.53],[2.62,129.05]],"id":70003365},{"atl":[[9,17.42],[12.5,18.18]],"id":70003365},{"atb":[[12,19],[9.8,23.75],[14.5,7.74]],"id":70003363},{"atl":[[330,0.63],[230,0.6]],"id":70003363}],"con":true,"img":false}]}
{"op":"mcm","clk":"11449308116","pt":1717306957281,"mc":[{"id":"1.229554890","rc":[{"spn":244.0,"spf":"NaN","id":70003366},{"spn":6.09,"spf":"NaN","id":70003367},{"atl":[[3.75,3.55]],"id":70003364},{"spn":2.74,"spf":"NaN","id":70003364},{"atl":[[1000,2.35]],"id":70003365},{"spn":5.86,"spf":"NaN","id":70003365},{"spn":122.25,"spf":"NaN","id":70003363}],"con":true,"img":false}]}
{"op":"mcm","clk":"11449308131","pt":1717306957490,"mc":[{"id":"1.229554890","rc":[{"atl":[[1000,2.35]],"id":70003367}],"con":true,"img":false}]}
{"op":"mcm","clk":"11449308139","pt":1717306957598,"mc":[{"id":"1.229554890","rc":[{"atl":[[1000,1.62]],"id":70003365}],"con":true,"img":false}]}
{"op":"mcm","clk":"11449308154","pt":1717306957803,"mc":[{"id":"1.229554890","rc":[{"atl":[[1000,1.55]],"id":70003367}],"con":true,"img":false}]}
{"op":"mcm","clk":"11449308160","pt":1717306957906,"mc":[{"id":"1.229554890","rc":[{"atl":[[1000,0]],"id":70003365}],"con":true,"img":false}]}
{"op":"mcm","clk":"11449308169","pt":1717306958006,"mc":[{"id":"1.229554890","rc":[{"atl":[[8.2,1.62]],"id":70003365}],"con":true,"img":false}]}
{"op":"mcm","clk":"11449308189","pt":1717306958264,"mc":[{"id":"1.229554890","rc":[{"atl":[[1000,0]],"id":70003367}],"con":true,"img":false}]}
{"op":"mcm","clk":"11449308194","pt":1717306958368,"mc":[{"id":"1.229554890","rc":[{"atl":[[8.6,1.55]],"id":70003367}],"con":true,"img":false}]}
{"op":"mcm","clk":"11449315225","pt":1717307061113,"mc":[{"id":"1.229554890","rc":[{"spn":5.69,"spf":"NaN","id":70003367},{"atl":[[3.75,8.69]],"id":70003364},{"spn":5.46,"spf":"NaN","id":70003365}],"con":true,"img":false}]}
{"op":"mcm","clk":"11449315235","pt":1717307061215,"mc":[{"id":"1.229554890","rc":[{"atl":[[8.2,3.97]],"id":70003365}],"con":true,"img":false}]}
{"op":"mcm","clk":"11449315243","pt":1717307061326,"mc":[{"id":"1.229554890","rc":[{"atl":[[8.6,3.8]],"id":70003367}],"con":true,"img":false}]}
{"op":"mcm","clk":"11449321249","pt":1717307146573,"mc":[{"id":"1.229554890","rc":[{"atl":[[3.75,5.13]],"id":70003364}],"con":true,"img":false}]}
{"op":"mcm","clk":"11449322251","pt":1717307160881,"mc":[{"id":"1.229554890","rc":[{"atl":[[8.2,2.35]],"id":70003365}],"con":true,"img":false}]}
{"op":"mcm","clk":"11449323492","pt":1717307176506,"mc":[{"id":"1.229554890","rc":[{"atl":[[8.6,2.24]],"id":70003367}],"con":true,"img":false}]}
{"op":"mcm","clk":"11449323815","pt":1717307180117,"mc":[{"id":"1.229554890","rc":[{"atl":[[1000,2.35]],"id":70003367},{"atl":[[3.75,8.69]],"id":70003364},{"atl":[[1000,2.35]],"id":70003365}],"con":true,"img":false}]}
{"op":"mcm","clk":"11449323834","pt":1717307180426,"mc":[{"id":"1.229554890","rc":[{"atl":[[1000,1.55]],"id":70003367},{"atl":[[1000,1.62]],"id":70003365}],"con":true,"img":false}]}
{"op":"mcm","clk":"11449323849","pt":1717307180579,"mc":[{"id":"1.229554890","rc":[{"atl":[[1000,0]],"id":70003367}],"con":true,"img":false}]}
{"op":"mcm","clk":"11449323855","pt":1717307180683,"mc":[{"id":"1.229554890","rc":[{"atl":[[8.6,3.8]],"id":70003367}],"con":true,"img":false}]}
{"op":"mcm","clk":"11449323880","pt":1717307180993,"mc":[{"id":"1.229554890","rc":[{"atl":[[1000,0]],"id":70003365}],"con":true,"img":false}]}
{"op":"mcm","clk":"11449323889","pt":1717307181095,"mc":[{"id":"1.229554890","rc":[{"atl":[[8.2,3.97]],"id":70003365}],"con":true,"img":false}]}
{"op":"mcm","clk":"11449328659","pt":1717307247592,"mc":[{"id":"1.229554890","rc":[{"atl":[[3.75,3.55]],"id":70003364}],"con":true,"img":false}]}
{"op":"mcm","clk":"11449331005","pt":1717307282493,"mc":[{"id":"1.229554890","rc":[{"atl":[[8.2,1.62]],"id":70003365}],"con":true,"img":false}]}
{"op":"mcm","clk":"11449332883","pt":1717307309312,"mc":[{"id":"1.229554890","rc":[{"atl":[[8.6,1.55]],"id":70003367}],"con":true,"img":false}]}
{"op":"mcm","clk":"11449334055","pt":1717307327740,"mc":[{"id":"1.229554890","rc":[{"atb":[[38,0],[24,0],[29,0]],"id":70003366},{"atl":[[550,0],[450,0]],"id":70003366},{"atb":[[2.58,0],[2.78,0],[2.68,0]],"id":70003367},{"atl":[[13.5,0],[9.4,0]],"id":70003367},{"atb":[[2.72,0],[2.52,0],[2.62,0]],"id":70003365},{"atl":[[9,0],[12.5,0]],"id":70003365},{"atb":[[12,0],[9.8,0],[14.5,0]],"id":70003363},{"atl":[[330,0],[230,0]],"id":70003363}],"con":true,"img":false}]}
{"op":"mcm","clk":"11449335094","pt":1717307344108,"mc":[{"id":"1.229554890","rc":[{"atb":[[38,2.82],[24,9.08],[29,7.46]],"id":70003366},{"atl":[[550,0.38],[450,0.3]],"id":70003366},{"atb":[[2.58,132.31],[2.78,58.72],[2.68,124.44]],"id":70003367},{"atl":[[13.5,16.72],[9.4,16.58]],"id":70003367},{"atb":[[2.72,60.77],[2.52,137.53],[2.62,129.05]],"id":70003365},{"atl":[[9,17.42],[12.5,18.18]],"id":70003365},{"atb":[[12,19],[9.8,23.75],[14.5,7.74]],"id":70003363},{"atl":[[330,0.63],[230,0.6]],"id":70003363}],"con":true,"img":false}]}
{"op":"mcm","clk":"11449335706","pt":1717307353061,"mc":[{"id":"1.229554890","rc":[{"atl":[[3.75,8.69]],"id":70003364}],"con":true,"img":false}]}
{"op":"mcm","clk":"11449335717","pt":1717307353268,"mc":[{"id":"1.229554890","rc":[{"atl":[[8.6,3.8]],"id":70003367},{"atl":[[8.2,3.97]],"id":70003365}],"con":true,"img":false}]}
{"op":"mcm","clk":"11449336693","pt":1717307367001,"mc":[{"id":"1.229554890","rc":[{"atl":[[3.75,5.13]],"id":70003364}],"con":true,"img":false}]}
{"op":"mcm","clk":"11449337767","pt":1717307382225,"mc":[{"id":"1.229554890","rc":[{"atl":[[8.2,2.35]],"id":70003365}],"con":true,"img":false}]}
{"op":"mcm","clk":"11449339104","pt":1717307401352,"mc":[{"id":"1.229554890","rc":[{"atl":[[8.6,2.24]],"id":70003367}],"con":true,"img":false}]}
{"op":"mcm","clk":"11449340067","pt":1717307416395,"mc":[{"id":"1.229554890","rc":[{"atl":[[3.75,8.69]],"id":70003364},{"atl":[[1000,2.35]],"id":70003365}],"con":true,"img":false}]}
{"op":"mcm","clk":"11449340079","pt":1717307416604,"mc":[{"id":"1.229554890","rc":[{"atl":[[1000,2.35]],"id":70003367},{"atl":[[1000,1.62]],"id":70003365}],"con":true,"img":false}]}
{"op":"mcm","clk":"11449340098","pt":1717307416923,"mc":[{"id":"1.229554890","rc":[{"atl":[[1000,0]],"id":70003365}],"con":true,"img":false}]}
{"op":"mcm","clk":"11449340104","pt":1717307417018,"mc":[{"id":"1.229554890","rc":[{"atl":[[8.2,3.97]],"id":70003365}],"con":true,"img":false}]}
{"op":"mcm","clk":"11449340118","pt":1717307417221,"mc":[{"id":"1.229554890","rc":[{"atl":[[1000,1.55]],"id":70003367}],"con":true,"img":false}]}
{"op":"mcm","clk":"11449340132","pt":1717307417433,"mc":[{"id":"1.229554890","rc":[{"atl":[[1000,0]],"id":70003367}],"con":true,"img":false}]}
{"op":"mcm","clk":"11449340140","pt":1717307417534,"mc":[{"id":"1.229554890","rc":[{"atl":[[8.6,3.8]],"id":70003367}],"con":true,"img":false}]}
{"op":"mcm","clk":"11449341381","pt":1717307438748,"mc":[{"id":"1.229554890","rc":[{"atb":[[38,0],[24,0],[29,0]],"id":70003366},{"atl":[[550,0],[450,0]],"id":70003366},{"atb":[[2.58,0],[2.78,0],[2.68,0]],"id":70003367},{"atl":[[13.5,0],[9.4,0]],"id":70003367},{"atb":[[2.72,0],[2.52,0],[2.62,0]],"id":70003365},{"atl":[[9,0],[12.5,0]],"id":70003365},{"atb":[[12,0],[9.8,0],[14.5,0]],"id":70003363},{"atl":[[330,0],[230,0]],"id":70003363}],"con":true,"img":false}]}
{"op":"mcm","clk":"11449342048","pt":1717307452010,"mc":[{"id":"1.229554890","rc":[{"atb":[[38,2.82],[24,9.08],[29,7.46]],"id":70003366},{"atl":[[550,0.38],[450,0.3]],"id":70003366},{"atb":[[2.58,132.31],[2.78,58.72],[2.68,124.44]],"id":70003367},{"atl":[[13.5,16.72],[9.4,16.58]],"id":70003367},{"atb":[[2.58,132.31],[2.78,58.72],[2.68,124.44]],"id":70003365},{"atl":[[13.5,16.72],[9.4,16.58]],"id":70003365},{"spn":5.49,"spf":"NaN","id":70003365},{"atb":[[12,19],[9.8,23.75],[14.5,7.74]],"id":70003363},{"atl":[[330,0.63],[230,0.6]],"id":70003363}],"con":true,"img":false}]}
{"op":"mcm","clk":"11449346563","pt":1717307552448,"mc":[{"id":"1.229554890","rc":[{"atl":[[3.75,3.55]],"id":70003364}],"con":true,"img":false}]}
{"op":"mcm","clk":"11449347762","pt":1717307586094,"mc":[{"id":"1.229554890","rc":[{"atl":[[8.2,1.62]],"id":70003365}],"con":true,"img":false}]}
{"op":"mcm","clk":"11449348650","pt":1717307605766,"mc":[{"id":"1.229554890","rc":[{"atl":[[3.75,0]],"id":70003364}],"con":true,"img":false}]}
{"op":"mcm","clk":"11449349314","pt":1717307620653,"mc":[{"id":"1.229554890","rc":[{"spn":2.86,"spf":"NaN","id":70003364},{"atl":[[8.2,0]],"id":70003365},{"spn":6.09,"spf":"NaN","id":70003365}],"con":true,"img":false}]}
{"op":"mcm","clk":"11449349366","pt":1717307621878,"mc":[{"id":"1.229554890","rc":[{"atl":[[8.6,1.55]],"id":70003367}],"con":true,"img":false}]}
{"op":"mcm","clk":"11449349884","pt":1717307635876,"mc":[{"id":"1.229554890","rc":[{"atl":[[8.6,0]],"id":70003367}],"con":true,"img":false}]}
{"op":"mcm","clk":"11449350462","pt":1717307650794,"mc":[{"id":"1.229554890","rc":[{"atl":[[1000,2.35]],"id":70003365}],"con":true,"img":false}]}
{"op":"mcm","clk":"11449350466","pt":1717307650900,"mc":[{"id":"1.229554890","rc":[{"atl":[[3.75,3.55]],"id":70003364}],"con":true,"img":false}]}
{"op":"mcm","clk":"11449350470","pt":1717307650999,"mc":[{"id":"1.229554890","rc":[{"atl":[[1000,2.35]],"id":70003367}],"con":true,"img":false}]}
{"op":"mcm","clk":"11449350475","pt":1717307651204,"mc":[{"id":"1.229554890","rc":[{"atl":[[1000,1.55]],"id":70003367},{"atl":[[1000,1.55]],"id":70003365}],"con":true,"img":false}]}
{"op":"mcm","clk":"11449350488","pt":1717307651415,"mc":[{"id":"1.229554890","rc":[{"atl":[[1000,0]],"id":70003367}],"con":true,"img":false}]}
{"op":"mcm","clk":"11449350494","pt":1717307651465,"mc":[{"id":"1.229554890","rc":[{"atl":[[8.6,1.55]],"id":70003367}],"con":true,"img":false}]}
{"op":"mcm","clk":"11449350507","pt":1717307651770,"mc":[{"id":"1.229554890","rc":[{"atl":[[1000,0]],"id":70003365}],"con":true,"img":false}]}
{"op":"mcm","clk":"11449350513","pt":1717307651874,"mc":[{"id":"1.229554890","rc":[{"atl":[[8.6,1.55]],"id":70003365}],"con":true,"img":false}]}
{"op":"mcm","clk":"11449350856","pt":1717307658972,"mc":[{"id":"1.229554890","rc":[{"atl":[[3.75,8.69]],"id":70003364}],"con":true,"img":false}]}
{"op":"mcm","clk":"11449350861","pt":1717307659071,"mc":[{"id":"1.229554890","rc":[{"atl":[[8.6,3.8]],"id":70003365}],"con":true,"img":false}]}
{"op":"mcm","clk":"11449350869","pt":1717307659225,"mc":[{"id":"1.229554890","rc":[{"atl":[[8.6,3.8]],"id":70003367}],"con":true,"img":false}]}
{"op":"mcm","clk":"11449358332","pt":1717307833160,"mc":[{"id":"1.229554890","rc":[{"atl":[[3.75,5.13]],"id":70003364},{"spn":2.74,"spf":"NaN","id":70003364},{"spn":5.69,"spf":"NaN","id":70003365}],"con":true,"img":false}]}
{"op":"mcm","clk":"11449359187","pt":1717307853583,"mc":[{"id":"1.229554890","rc":[{"atl":[[8.6,2.24]],"id":70003365}],"con":true,"img":false}]}
{"op":"mcm","clk":"11449359406","pt":1717307859954,"mc":[{"id":"1.229554890","rc":[{"atl":[[8.6,2.24]],"id":70003367}],"con":true,"img":false}]}
{"op":"mcm","clk":"11449359546","pt":1717307863293,"mc":[{"id":"1.229554890","rc":[{"atl":[[3.75,0]],"id":70003364}],"con":true,"img":false}]}
{"op":"mcm","clk":"11449360438","pt":1717307884014,"mc":[{"id":"1.229554890","rc":[{"atl":[[1000,2.35]],"id":70003367},{"atl":[[3.75,3.55]],"id":70003364},{"atl":[[1000,2.35]],"id":70003365}],"con":true,"img":false}]}
{"op":"mcm","clk":"11449360451","pt":1717307884220,"mc":[{"id":"1.229554890","rc":[{"atl":[[1000,1.55]],"id":70003367},{"atl":[[1000,1.55]],"id":70003365}],"con":true,"img":false}]}
{"op":"mcm","clk":"11449360464","pt":1717307884426,"mc":[{"id":"1.229554890","rc":[{"atl":[[1000,0]],"id":70003367}],"con":true,"img":false}]}
{"op":"mcm","clk":"11449360470","pt":1717307884530,"mc":[{"id":"1.229554890","rc":[{"atl":[[8.6,3.8]],"id":70003367}],"con":true,"img":false}]}
{"op":"mcm","clk":"11449360480","pt":1717307884837,"mc":[{"id":"1.229554890","rc":[{"atl":[[1000,0]],"id":70003365}],"con":true,"img":false}]}
{"op":"mcm","clk":"11449360484","pt":1717307884895,"mc":[{"id":"1.229554890","rc":[{"atl":[[8.6,3.8]],"id":70003365}],"con":true,"img":false}]}
{"op":"mcm","clk":"11449360943","pt":1717307895008,"mc":[{"id":"1.229554890","rc":[{"atl":[[8.6,1.55]],"id":70003365}],"con":true,"img":false}]}
{"op":"mcm","clk":"11449362221","pt":1717307928593,"mc":[{"id":"1.229554890","rc":[{"atl":[[8.6,1.55]],"id":70003367}],"con":true,"img":false}]}
{"op":"mcm","clk":"11449363520","pt":1717307961594,"mc":[{"id":"1.229554890","rc":[{"atl":[[3.75,8.69]],"id":70003364}],"con":true,"img":false}]}
{"op":"mcm","clk":"11449363526","pt":1717307961698,"mc":[{"id":"1.229554890","rc":[{"atl":[[8.6,3.8]],"id":70003365}],"con":true,"img":false}]}
{"op":"mcm","clk":"11449363528","pt":1717307961798,"mc":[{"id":"1.229554890","rc":[{"atl":[[8.6,3.8]],"id":70003367}],"con":true,"img":false}]}
{"op":"mcm","clk":"11449363583","pt":1717307963108,"mc":[{"id":"1.229554890","rc":[{"atb":[[38,0],[24,0],[29,0]],"id":70003366},{"atl":[[550,0],[450,0]],"id":70003366},{"atb":[[2.58,0],[2.78,0],[2.68,0]],"id":70003367},{"atl":[[13.5,0],[9.4,0]],"id":70003367},{"atb":[[1.73,0],[1.63,0],[1.68,0]],"id":70003364},{"atl":[[4,0],[5,0]],"id":70003364},{"atb":[[2.58,0],[2.78,0],[2.68,0]],"id":70003365},{"atl":[[13.5,0],[9.4,0]],"id":70003365},{"atb":[[12,0],[9.8,0],[14.5,0]],"id":70003363},{"atl":[[330,0],[230,0]],"id":70003363}],"con":true,"img":false}]}
{"op":"mcm","clk":"11449364610","pt":1717307987909,"mc":[{"id":"1.229554890","rc":[{"atb":[[38,2.82],[24,9.08],[29,7.46]],"id":70003366},{"atl":[[550,0.38],[450,0.3]],"id":70003366},{"atb":[[2.58,132.31],[2.78,58.72],[2.68,124.44]],"id":70003367},{"atl":[[13.5,16.72],[9.4,16.58]],"id":70003367},{"atb":[[1.73,143.19],[1.63,331.84],[1.68,307.44]],"id":70003364},{"atl":[[4,46.45],[5,52.26]],"id":70003364},{"atb":[[2.58,132.31],[2.78,58.72],[2.68,124.44]],"id":70003365},{"atl":[[13.5,16.72],[9.4,16.58]],"id":70003365},{"atb":[[12,19],[9.8,23.75],[14.5,7.74]],"id":70003363},{"atl":[[330,0.63],[230,0.6]],"id":70003363}],"con":true,"img":false}]}
{"op":"mcm","clk":"11449368666","pt":1717308065007,"mc":[{"id":"1.229554890","rc":[{"atl":[[3.75,5.13]],"id":70003364}],"con":true,"img":false}]}
{"op":"mcm","clk":"11449369160","pt":1717308075811,"mc":[{"id":"1.229554890","rc":[{"atl":[[8.6,2.24]],"id":70003365}],"con":true,"img":false}]}
{"op":"mcm","clk":"11449369880","pt":1717308090821,"mc":[{"id":"1.229554890","rc":[{"atl":[[8.6,2.24]],"id":70003367}],"con":true,"img":false}]}
{"op":"mcm","clk":"11449370263","pt":1717308098519,"mc":[{"id":"1.229554890","rc":[{"atl":[[1000,2.35]],"id":70003367},{"atl":[[3.75,8.69]],"id":70003364},{"atl":[[1000,2.35]],"id":70003365}],"con":true,"img":false}]}
{"op":"mcm","clk":"11449370273","pt":1717308098833,"mc":[{"id":"1.229554890","rc":[{"atl":[[1000,1.55]],"id":70003367},{"atl":[[1000,1.55]],"id":70003365}],"con":true,"img":false}]}
{"op":"mcm","clk":"11449370284","pt":1717308099141,"mc":[{"id":"1.229554890","rc":[{"atl":[[1000,0]],"id":70003367}],"con":true,"img":false}]}
{"op":"mcm","clk":"11449370292","pt":1717308099243,"mc":[{"id":"1.229554890","rc":[{"atl":[[8.6,3.8]],"id":70003367}],"con":true,"img":false}]}
{"op":"mcm","clk":"11449370304","pt":1717308099550,"mc":[{"id":"1.229554890","rc":[{"atl":[[1000,0]],"id":70003365}],"con":true,"img":false}]}
{"op":"mcm","clk":"11449370309","pt":1717308099651,"mc":[{"id":"1.229554890","rc":[{"atl":[[8.6,3.8]],"id":70003365}],"con":true,"img":false}]}
{"op":"mcm","clk":"11449372602","pt":1717308153740,"mc":[{"id":"1.229554890","rc":[{"atl":[[3.75,3.55]],"id":70003364}],"con":true,"img":false}]}
{"op":"mcm","clk":"11449373993","pt":1717308188256,"mc":[{"id":"1.229554890","rc":[{"atl":[[8.6,1.55]],"id":70003365}],"con":true,"img":false}]}
{"op":"mcm","clk":"11449375728","pt":1717308224294,"mc":[{"id":"1.229554890","rc":[{"atl":[[8.6,1.55]],"id":70003367}],"con":true,"img":false}]}
{"op":"mcm","clk":"11449378234","pt":1717308274984,"mc":[{"id":"1.229554890","rc":[{"atl":[[3.75,8.69]],"id":70003364}],"con":true,"img":false}]}
{"op":"mcm","clk":"11449378239","pt":1717308275190,"mc":[{"id":"1.229554890","rc":[{"atl":[[8.6,3.8]],"id":70003367},{"atl":[[8.6,3.8]],"id":70003365}],"con":true,"img":false}]}
{"op":"mcm","clk":"11449379129","pt":1717308290613,"mc":[{"id":"1.229554890","rc":[{"atl":[[3.75,5.13]],"id":70003364}],"con":true,"img":false}]}
{"op":"mcm","clk":"11449380032","pt":1717308305643,"mc":[{"id":"1.229554890","rc":[{"atl":[[8.6,2.24]],"id":70003365}],"con":true,"img":false}]}
{"op":"mcm","clk":"11449381012","pt":1717308321221,"mc":[{"id":"1.229554890","rc":[{"atl":[[8.6,2.24]],"id":70003367}],"con":true,"img":false}]}
{"op":"mcm","clk":"11449382045","pt":1717308335652,"mc":[{"id":"1.229554890","rc":[{"atl":[[1000,2.35]],"id":70003367},{"atl":[[3.75,8.69]],"id":70003364},{"atl":[[1000,2.35]],"id":70003365}],"con":true,"img":false}]}
{"op":"mcm","clk":"11449382057","pt":1717308335849,"mc":[{"id":"1.229554890","rc":[{"atl":[[1000,1.55]],"id":70003365}],"con":true,"img":false}]}
{"op":"mcm","clk":"11449382065","pt":1717308335950,"mc":[{"id":"1.229554890","rc":[{"atl":[[1000,1.55]],"id":70003367}],"con":true,"img":false}]}
{"op":"mcm","clk":"11449382072","pt":1717308336055,"mc":[{"id":"1.229554890","rc":[{"atl":[[1000,0]],"id":70003365}],"con":true,"img":false}]}
{"op":"mcm","clk":"11449382078","pt":1717308336155,"mc":[{"id":"1.229554890","rc":[{"atl":[[8.6,3.8]],"id":70003365}],"con":true,"img":false}]}
{"op":"mcm","clk":"11449382092","pt":1717308336365,"mc":[{"id":"1.229554890","rc":[{"atl":[[1000,0]],"id":70003367}],"con":true,"img":false}]}
{"op":"mcm","clk":"11449382098","pt":1717308336464,"mc":[{"id":"1.229554890","rc":[{"atl":[[8.6,3.8]],"id":70003367}],"con":true,"img":false}]}
{"op":"mcm","clk":"11449391907","pt":1717308485812,"mc":[{"id":"1.229554890","rc":[{"atl":[[3.75,3.55]],"id":70003364}],"con":true,"img":false}]}
{"op":"mcm","clk":"11449394378","pt":1717308521519,"mc":[{"id":"1.229554890","rc":[{"atl":[[8.6,1.55]],"id":70003365}],"con":true,"img":false}]}
{"op":"mcm","clk":"11449394667","pt":1717308526114,"mc":[{"id":"1.229554890","rc":[{"atl":[[3.75,0]],"id":70003364}],"con":true,"img":false}]}
{"op":"mcm","clk":"11449395212","pt":1717308534919,"mc":[{"id":"1.229554890","rc":[{"atl":[[8.6,0]],"id":70003365}],"con":true,"img":false}]}
{"op":"mcm","clk":"11449396593","pt":1717308553974,"mc":[{"id":"1.229554890","rc":[{"atl":[[8.6,1.55]],"id":70003367},{"spn":2.86,"spf":"NaN","id":70003364},{"spn":6.09,"spf":"NaN","id":70003365}],"con":true,"img":false}]}
{"op":"mcm","clk":"11449396603","pt":1717308554179,"mc":[{"id":"1.229554890","rc":[{"atl":[[8.6,0]],"id":70003367}],"con":true,"img":false}]}
{"op":"mcm","clk":"11449397584","pt":1717308569031,"mc":[{"id":"1.229554890","rc":[{"atl":[[3.75,3.55]],"id":70003364}],"con":true,"img":false}]}
{"op":"mcm","clk":"11449397600","pt":1717308569264,"mc":[{"id":"1.229554890","rc":[{"atl":[[1000,2.35]],"id":70003367},{"atl":[[1000,2.35]],"id":70003365}],"con":true,"img":false}]}
{"op":"mcm","clk":"11449397634","pt":1717308569753,"mc":[{"id":"1.229554890","rc":[{"atl":[[1000,1.55]],"id":70003367},{"atl":[[1000,1.55]],"id":70003365}],"con":true,"img":false}]}
{"op":"mcm","clk":"11449397655","pt":1717308570063,"mc":[{"id":"1.229554890","rc":[{"atl":[[1000,0]],"id":70003365}],"con":true,"img":false}]}
{"op":"mcm","clk":"11449397662","pt":1717308570169,"mc":[{"id":"1.229554890","rc":[{"atl":[[8.6,1.55]],"id":70003365}],"con":true,"img":false}]}
{"op":"mcm","clk":"11449397685","pt":1717308570475,"mc":[{"id":"1.229554890","rc":[{"atl":[[1000,0]],"id":70003367}],"con":true,"img":false}]}
{"op":"mcm","clk":"11449397695","pt":1717308570579,"mc":[{"id":"1.229554890","rc":[{"atl":[[8.6,1.55]],"id":70003367}],"con":true,"img":false}]}
{"op":"mcm","clk":"11449410543","pt":1717308754464,"mc":[{"id":"1.229554890","rc":[{"atl":[[3.75,0]],"id":70003364},{"spn":5.69,"spf":"NaN","id":70003365}],"con":true,"img":false}]}
{"op":"mcm","clk":"11449411398","pt":1717308766801,"mc":[{"id":"1.229554890","rc":[{"atl":[[8.6,0]],"id":70003365}],"con":true,"img":false}]}
{"op":"mcm","clk":"11449412745","pt":1717308786537,"mc":[{"id":"1.229554890","rc":[{"atl":[[8.6,0]],"id":70003367}],"con":true,"img":false}]}
{"op":"mcm","clk":"11449413632","pt":1717308797746,"mc":[{"id":"1.229554890","rc":[{"atl":[[1000,2.35]],"id":70003367},{"atl":[[3.75,3.55]],"id":70003364},{"atl":[[1000,2.35]],"id":70003365}],"con":true,"img":false}]}
{"op":"mcm","clk":"11449413656","pt":1717308798055,"mc":[{"id":"1.229554890","rc":[{"atl":[[1000,1.55]],"id":70003367},{"atl":[[1000,1.55]],"id":70003365}],"con":true,"img":false}]}
{"op":"mcm","clk":"11449413676","pt":1717308798365,"mc":[{"id":"1.229554890","rc":[{"atl":[[1000,0]],"id":70003367}],"con":true,"img":false}]}
{"op":"mcm","clk":"11449413686","pt":1717308798416,"mc":[{"id":"1.229554890","rc":[{"atl":[[8.6,1.55]],"id":70003367}],"con":true,"img":false}]}
{"op":"mcm","clk":"11449413705","pt":1717308798725,"mc":[{"id":"1.229554890","rc":[{"atl":[[1000,0]],"id":70003365}],"con":true,"img":false}]}
{"op":"mcm","clk":"11449413714","pt":1717308798831,"mc":[{"id":"1.229554890","rc":[{"atl":[[8.6,1.55]],"id":70003365}],"con":true,"img":false}]}
{"op":"mcm","clk":"11449421677","pt":1717308905939,"mc":[{"id":"1.229554890","rc":[{"atl":[[3.75,8.69]],"id":70003364},{"spn":2.74,"spf":"NaN","id":70003364}],"con":true,"img":false}]}
{"op":"mcm","clk":"11449421697","pt":1717308906203,"mc":[{"id":"1.229554890","rc":[{"atl":[[8.6,3.8]],"id":70003367}],"con":true,"img":false}]}
{"op":"mcm","clk":"11449421703","pt":1717308906300,"mc":[{"id":"1.229554890","rc":[{"atl":[[8.6,3.8]],"id":70003365}],"con":true,"img":false}]}
{"op":"mcm","clk":"11449427348","pt":1717308980633,"mc":[{"id":"1.229554890","rc":[{"atl":[[3.75,5.13]],"id":70003364}],"con":true,"img":false}]}
{"op":"mcm","clk":"11449427787","pt":1717308986654,"mc":[{"id":"1.229554890","rc":[{"atl":[[8.6,2.24]],"id":70003365}],"con":true,"img":false}]}
{"op":"mcm","clk":"11449428898","pt":1717309001674,"mc":[{"id":"1.229554890","rc":[{"atl":[[8.6,2.24]],"id":70003367}],"con":true,"img":false}]}
{"op":"mcm","clk":"11449430178","pt":1717309019295,"mc":[{"id":"1.229554890","rc":[{"atl":[[3.75,8.69]],"id":70003364},{"atl":[[1000,2.35]],"id":70003365}],"con":true,"img":false}]}
{"op":"mcm","clk":"11449430198","pt":1717309019502,"mc":[{"id":"1.229554890","rc":[{"atl":[[1000,2.35]],"id":70003367},{"atl":[[1000,1.55]],"id":70003365}],"con":true,"img":false}]}
{"op":"mcm","clk":"11449430220","pt":1717309019810,"mc":[{"id":"1.229554890","rc":[{"atl":[[1000,1.55]],"id":70003367},{"atl":[[1000,0]],"id":70003365}],"con":true,"img":false}]}
{"op":"mcm","clk":"11449430230","pt":1717309019872,"mc":[{"id":"1.229554890","rc":[{"atl":[[8.6,3.8]],"id":70003365}],"con":true,"img":false}]}
{"op":"mcm","clk":"11449430250","pt":1717309020180,"mc":[{"id":"1.229554890","rc":[{"atl":[[1000,0]],"id":70003367}],"con":true,"img":false}]}
{"op":"mcm","clk":"11449430258","pt":1717309020289,"mc":[{"id":"1.229554890","rc":[{"atl":[[8.6,3.8]],"id":70003367}],"con":true,"img":false}]}
{"op":"mcm","clk":"11449433528","pt":1717309070158,"mc":[{"id":"1.229554890","rc":[{"atb":[[38,0],[24,0],[29,0]],"id":70003366},{"atl":[[550,0],[450,0]],"id":70003366},{"spn":"NaN","spf":"NaN","id":70003366},{"atb":[[2.58,0],[2.78,0],[2.68,0]],"id":70003367},{"atl":[[13.5,0],[9.4,0]],"id":70003367},{"spn":1.0,"spf":"NaN","id":70003367},{"atb":[[1.73,0],[1.63,0],[1.68,0]],"id":70003364},{"atl":[[4,0],[5,0]],"id":70003364},{"spn":1.0,"spf":"NaN","id":70003364},{"atb":[[2.58,0],[2.78,0],[2.68,0]],"id":70003365},{"atl":[[13.5,0],[9.4,0]],"id":70003365},{"spn":1.0,"spf":"NaN","id":70003365},{"atb":[[12,0],[9.8,0],[14.5,0]],"id":70003363},{"atl":[[330,0],[230,0]],"id":70003363},{"spn":"NaN","spf":"NaN","id":70003363}],"con":true,"img":false}]}
{"op":"mcm","clk":"11449435527","pt":1717309098802,"mc":[{"id":"1.229554890","rc":[{"atb":[[38,2.82],[24,9.08],[29,7.46]],"id":70003366},{"atl":[[550,0.38],[450,0.3]],"id":70003366},{"atb":[[2.58,132.31],[2.78,58.72],[2.68,124.44]],"id":70003367},{"atl":[[13.5,16.72],[9.4,16.58]],"id":70003367},{"atb":[[1.73,143.19],[1.63,331.84],[1.68,307.44]],"id":70003364},{"atl":[[4,46.45],[5,52.26]],"id":70003364},{"atb":[[2.58,132.31],[2.78,58.72],[2.68,124.44]],"id":70003365},{"atl":[[13.5,16.72],[9.4,16.58]],"id":70003365},{"atb":[[12,19],[9.8,23.75],[14.5,7.74]],"id":70003363},{"atl":[[330,0.63],[230,0.6]],"id":70003363}],"con":true,"img":false}]}
{"op":"mcm","clk":"11449436160","pt":1717309108895,"mc":[{"id":"1.229554890","rc":[{"atl":[[3.75,3.55]],"id":70003364}],"con":true,"img":false}]}
{"op":"mcm","clk":"11449438399","pt":1717309143510,"mc":[{"id":"1.229554890","rc":[{"spn":244.0,"spf":"NaN","id":70003366},{"spn":5.69,"spf":"NaN","id":70003367},{"spn":2.74,"spf":"NaN","id":70003364},{"atl":[[8.6,1.55]],"id":70003365},{"spn":5.69,"spf":"NaN","id":70003365},{"spn":122.25,"spf":"NaN","id":70003363}],"con":true,"img":false}]}
{"op":"mcm","clk":"11449440417","pt":1717309175377,"mc":[{"id":"1.229554890","rc":[{"atl":[[8.6,1.55]],"id":70003367}],"con":true,"img":false}]}
{"op":"mcm","clk":"11449442515","pt":1717309208408,"mc":[{"id":"1.229554890","rc":[{"atl":[[3.75,0]],"id":70003364},{"spn":2.86,"spf":"NaN","id":70003364}],"con":true,"img":false}]}
{"op":"mcm","clk":"11449442676","pt":1717309210893,"mc":[{"id":"1.229554890","rc":[{"atl":[[3.75,5.13]],"id":70003364}],"con":true,"img":false}]}
{"op":"mcm","clk":"11449442681","pt":1717309210996,"mc":[{"id":"1.229554890","rc":[{"atl":[[8.6,3.8]],"id":70003365}],"con":true,"img":false}]}
{"op":"mcm","clk":"11449442693","pt":1717309211201,"mc":[{"id":"1.229554890","rc":[{"atl":[[8.6,3.8]],"id":70003367}],"con":true,"img":false}]}
{"op":"mcm","clk":"11449443561","pt":1717309224020,"mc":[{"id":"1.229554890","rc":[{"atl":[[8.6,2.24]],"id":70003365}],"con":true,"img":false}]}
{"op":"mcm","clk":"11449444501","pt":1717309239027,"mc":[{"id":"1.229554890","rc":[{"atl":[[8.6,2.24]],"id":70003367}],"con":true,"img":false}]}
{"op":"mcm","clk":"11449444685","pt":1717309242070,"mc":[{"id":"1.229554890","rc":[{"atl":[[1000,2.35]],"id":70003367},{"atl":[[3.75,8.69]],"id":70003364},{"atl":[[1000,2.35]],"id":70003365}],"con":true,"img":false}]}
{"op":"mcm","clk":"11449444701","pt":1717309242235,"mc":[{"id":"1.229554890","rc":[{"atl":[[1000,1.55]],"id":70003367},{"atl":[[1000,1.55]],"id":70003365}],"con":true,"img":false}]}
{"op":"mcm","clk":"11449444715","pt":1717309242440,"mc":[{"id":"1.229554890","rc":[{"atl":[[1000,0]],"id":70003365}],"con":true,"img":false}]}
{"op":"mcm","clk":"11449444723","pt":1717309242544,"mc":[{"id":"1.229554890","rc":[{"atl":[[8.6,3.8]],"id":70003365}],"con":true,"img":false}]}
{"op":"mcm","clk":"11449444745","pt":1717309242849,"mc":[{"id":"1.229554890","rc":[{"atl":[[1000,0]],"id":70003367}],"con":true,"img":false}]}
{"op":"mcm","clk":"11449444754","pt":1717309242952,"mc":[{"id":"1.229554890","rc":[{"atl":[[8.6,3.8]],"id":70003367}],"con":true,"img":false}]}
{"op":"mcm","clk":"11449456103","pt":1717309415006,"mc":[{"id":"1.229554890","rc":[{"atl":[[3.75,3.55]],"id":70003364},{"spn":2.74,"spf":"NaN","id":70003364}],"con":true,"img":false}]}
{"op":"mcm","clk":"11449456868","pt":1717309427058,"mc":[{"id":"1.229554890","rc":[{"atl":[[3.75,0]],"id":70003364}],"con":true,"img":false}]}
{"op":"mcm","clk":"11449457826","pt":1717309441895,"mc":[{"id":"1.229554890","rc":[{"atl":[[8.6,2.24]],"id":70003365}],"con":true,"img":false}]}
{"op":"mcm","clk":"11449458275","pt":1717309448193,"mc":[{"id":"1.229554890","rc":[{"atl":[[8.6,0]],"id":70003365}],"con":true,"img":false}]}
{"op":"mcm","clk":"11449458841","pt":1717309457095,"mc":[{"id":"1.229554890","rc":[{"atl":[[8.6,2.24]],"id":70003367}],"con":true,"img":false}]}
{"op":"mcm","clk":"11449459821","pt":1717309471917,"mc":[{"id":"1.229554890","rc":[{"atl":[[1000,2.35]],"id":70003367},{"atl":[[3.75,3.55]],"id":70003364}],"con":true,"img":false}]}
{"op":"mcm","clk":"11449459824","pt":1717309472016,"mc":[{"id":"1.229554890","rc":[{"atl":[[1000,2.35]],"id":70003365}],"con":true,"img":false}]}
{"op":"mcm","clk":"11449459835","pt":1717309472221,"mc":[{"id":"1.229554890","rc":[{"atl":[[1000,1.55]],"id":70003367}],"con":true,"img":false}]}
{"op":"mcm","clk":"11449459842","pt":1717309472278,"mc":[{"id":"1.229554890","rc":[{"atl":[[1000,1.55]],"id":70003365}],"con":true,"img":false}]}
{"op":"mcm","clk":"11449459852","pt":1717309472485,"mc":[{"id":"1.229554890","rc":[{"atl":[[1000,0]],"id":70003367}],"con":true,"img":false}]}
{"op":"mcm","clk":"11449459858","pt":1717309472589,"mc":[{"id":"1.229554890","rc":[{"atl":[[8.6,3.8]],"id":70003367}],"con":true,"img":false}]}
{"op":"mcm","clk":"11449459876","pt":1717309472898,"mc":[{"id":"1.229554890","rc":[{"atl":[[1000,0]],"id":70003365}],"con":true,"img":false}]}
{"op":"mcm","clk":"11449459884","pt":1717309472999,"mc":[{"id":"1.229554890","rc":[{"atl":[[8.6,1.55]],"id":70003365}],"con":true,"img":false}]}
{"op":"mcm","clk":"11449460449","pt":1717309482201,"mc":[{"id":"1.229554890","rc":[{"atl":[[8.6,1.55]],"id":70003367}],"con":true,"img":false}]}
{"op":"mcm","clk":"11449462494","pt":1717309512676,"mc":[{"id":"1.229554890","rc":[{"atl":[[3.75,8.69]],"id":70003364}],"con":true,"img":false}]}
{"op":"mcm","clk":"11449462501","pt":1717309512778,"mc":[{"id":"1.229554890","rc":[{"atl":[[8.6,3.8]],"id":70003365}],"con":true,"img":false}]}
{"op":"mcm","clk":"11449462515","pt":1717309512941,"mc":[{"id":"1.229554890","rc":[{"atl":[[8.6,3.8]],"id":70003367}],"con":true,"img":false}]}
{"op":"mcm","clk":"11449472468","pt":1717309652879,"mc":[{"id":"1.229554890","rc":[{"atl":[[3.75,5.13]],"id":70003364}],"con":true,"img":false}]}
{"op":"mcm","clk":"11449473547","pt":1717309667492,"mc":[{"id":"1.229554890","rc":[{"atl":[[8.6,2.24]],"id":70003365}],"con":true,"img":false}]}
{"op":"mcm","clk":"11449474663","pt":1717309682887,"mc":[{"id":"1.229554890","rc":[{"atl":[[8.6,2.24]],"id":70003367}],"con":true,"img":false}]}
{"op":"mcm","clk":"11449475793","pt":1717309697516,"mc":[{"id":"1.229554890","rc":[{"atl":[[1000,2.35]],"id":70003367},{"atl":[[3.75,8.69]],"id":70003364},{"atl":[[1000,2.35]],"id":70003365}],"con":true,"img":false}]}
{"op":"mcm","clk":"11449475818","pt":1717309697731,"mc":[{"id":"1.229554890","rc":[{"atl":[[1000,1.55]],"id":70003367},{"atl":[[1000,1.55]],"id":70003365}],"con":true,"img":false}]}
{"op":"mcm","clk":"11449475844","pt":1717309698038,"mc":[{"id":"1.229554890","rc":[{"atl":[[1000,0]],"id":70003365}],"con":true,"img":false}]}
{"op":"mcm","clk":"11449475852","pt":1717309698134,"mc":[{"id":"1.229554890","rc":[{"atl":[[8.6,3.8]],"id":70003365}],"con":true,"img":false}]}
{"op":"mcm","clk":"11449475868","pt":1717309698339,"mc":[{"id":"1.229554890","rc":[{"atl":[[1000,0]],"id":70003367}],"con":true,"img":false}]}
{"op":"mcm","clk":"11449475878","pt":1717309698403,"mc":[{"id":"1.229554890","rc":[{"atl":[[8.6,3.8]],"id":70003367}],"con":true,"img":false}]}
{"op":"mcm","clk":"11449476358","pt":1717309704741,"mc":[{"id":"1.229554890","rc":[{"atl":[[3.75,3.55]],"id":70003364}],"con":true,"img":false}]}
{"op":"mcm","clk":"11449486978","pt":1717309753807,"mc":[{"id":"1.229554890","rc":[{"atl":[[8.6,1.55]],"id":70003365}],"con":true,"img":false}]}
{"op":"mcm","clk":"11449488305","pt":1717309772610,"mc":[{"id":"1.229554890","rc":[{"atl":[[8.6,1.55]],"id":70003367}],"con":true,"img":false}]}
{"op":"mcm","clk":"11449490641","pt":1717309805939,"mc":[{"id":"1.229554890","rc":[{"atl":[[3.75,8.69]],"id":70003364}],"con":true,"img":false}]}
{"op":"mcm","clk":"11449490658","pt":1717309806142,"mc":[{"id":"1.229554890","rc":[{"atl":[[8.6,3.8]],"id":70003365}],"con":true,"img":false}]}
{"op":"mcm","clk":"11449490670","pt":1717309806242,"mc":[{"id":"1.229554890","rc":[{"atl":[[8.6,3.8]],"id":70003367}],"con":true,"img":false}]}
{"op":"mcm","clk":"11449495647","pt":1717309880527,"mc":[{"id":"1.229554890","rc":[{"atl":[[3.75,5.13]],"id":70003364}],"con":true,"img":false}]}
{"op":"mcm","clk":"11449496607","pt":1717309895703,"mc":[{"id":"1.229554890","rc":[{"atl":[[8.6,2.24]],"id":70003365}],"con":true,"img":false}]}
{"op":"mcm","clk":"11449497493","pt":1717309911233,"mc":[{"id":"1.229554890","rc":[{"atl":[[8.6,2.24]],"id":70003367}],"con":true,"img":false}]}
{"op":"mcm","clk":"11449497920","pt":1717309918625,"mc":[{"id":"1.229554890","rc":[{"atb":[[38,0],[24,0],[29,0]],"id":70003366},{"atl":[[550,0],[450,0]],"id":70003366},{"atb":[[2.58,0],[2.78,0],[2.68,0]],"id":70003367},{"atl":[[13.5,0],[9.4,0]],"id":70003367},{"atb":[[1.73,0],[1.63,0],[1.68,0]],"id":70003364},{"atl":[[4,0],[5,0]],"id":70003364},{"atb":[[2.58,0],[2.78,0],[2.68,0]],"id":70003365},{"atl":[[13.5,0],[9.4,0]],"id":70003365},{"atb":[[12,0],[9.8,0],[14.5,0]],"id":70003363},{"atl":[[330,0],[230,0]],"id":70003363}],"con":true,"img":false}]}
{"op":"mcm","clk":"11449499421","pt":1717309943849,"mc":[{"id":"1.229554890","rc":[{"atb":[[38,2.82],[24,9.08],[29,7.46]],"id":70003366},{"atl":[[550,0.38],[450,0.3]],"id":70003366},{"atb":[[2.58,132.31],[2.78,58.72],[2.68,124.44]],"id":70003367},{"atl":[[13.5,16.72],[9.4,16.58]],"id":70003367},{"atb":[[1.73,143.19],[1.63,331.84],[1.68,307.44]],"id":70003364},{"atl":[[4,46.45],[5,52.26]],"id":70003364},{"atb":[[2.58,132.31],[2.78,58.72],[2.68,124.44]],"id":70003365},{"atl":[[13.5,16.72],[9.4,16.58]],"id":70003365},{"atb":[[12,19],[9.8,23.75],[14.5,7.74]],"id":70003363},{"atl":[[330,0.63],[230,0.6]],"id":70003363}],"con":true,"img":false}]}
{"op":"mcm","clk":"11449499931","pt":1717309953274,"mc":[{"id":"1.229554890","rc":[{"atl":[[1000,2.35]],"id":70003367},{"atl":[[3.75,8.69]],"id":70003364},{"atl":[[1000,2.35]],"id":70003365}],"con":true,"img":false}]}
{"op":"mcm","clk":"11449499949","pt":1717309953538,"mc":[{"id":"1.229554890","rc":[{"atl":[[1000,1.55]],"id":70003367},{"atl":[[1000,1.55]],"id":70003365}],"con":true,"img":false}]}
{"op":"mcm","clk":"11449499959","pt":1717309953744,"mc":[{"id":"1.229554890","rc":[{"atl":[[1000,0]],"id":70003367}],"con":true,"img":false}]}
{"op":"mcm","clk":"11449499965","pt":1717309953845,"mc":[{"id":"1.229554890","rc":[{"atl":[[8.6,3.8]],"id":70003367}],"con":true,"img":false}]}
{"op":"mcm","clk":"11449499979","pt":1717309954054,"mc":[{"id":"1.229554890","rc":[{"atl":[[1000,0]],"id":70003365}],"con":true,"img":false}]}
{"op":"mcm","clk":"11449499989","pt":1717309954156,"mc":[{"id":"1.229554890","rc":[{"atl":[[8.6,3.8]],"id":70003365}],"con":true,"img":false}]}
{"op":"mcm","clk":"11449503016","pt":1717310005315,"mc":[{"id":"1.229554890","rc":[{"atl":[[3.75,3.55]],"id":70003364}],"con":true,"img":false}]}
{"op":"mcm","clk":"11449505115","pt":1717310038842,"mc":[{"id":"1.229554890","rc":[{"atl":[[8.6,1.55]],"id":70003365}],"con":true,"img":false}]}
{"op":"mcm","clk":"11449506993","pt":1717310069779,"mc":[{"id":"1.229554890","rc":[{"atl":[[8.6,1.55]],"id":70003367}],"con":true,"img":false}]}
{"op":"mcm","clk":"11449509257","pt":1717310108182,"mc":[{"id":"1.229554890","rc":[{"atl":[[3.75,8.69]],"id":70003364}],"con":true,"img":false}]}
{"op":"mcm","clk":"11449509267","pt":1717310108286,"mc":[{"id":"1.229554890","rc":[{"atl":[[8.6,3.8]],"id":70003365}],"con":true,"img":false}]}
{"op":"mcm","clk":"11449509272","pt":1717310108385,"mc":[{"id":"1.229554890","rc":[{"atl":[[8.6,3.8]],"id":70003367}],"con":true,"img":false}]}
{"op":"mcm","clk":"11449511579","pt":1717310145260,"mc":[{"id":"1.229554890","rc":[{"atl":[[3.75,5.13]],"id":70003364}],"con":true,"img":false}]}
{"op":"mcm","clk":"11449512423","pt":1717310160571,"mc":[{"id":"1.229554890","rc":[{"atl":[[8.6,2.24]],"id":70003365}],"con":true,"img":false}]}
{"op":"mcm","clk":"11449513268","pt":1717310175282,"mc":[{"id":"1.229554890","rc":[{"atl":[[8.6,2.24]],"id":70003367}],"con":true,"img":false}]}
{"op":"mcm","clk":"11449514116","pt":1717310190182,"mc":[{"id":"1.229554890","rc":[{"atl":[[3.75,8.69]],"id":70003364}],"con":true,"img":false}]}
{"op":"mcm","clk":"11449514122","pt":1717310190286,"mc":[{"id":"1.229554890","rc":[{"atl":[[1000,2.35]],"id":70003367},{"atl":[[1000,2.35]],"id":70003365}],"con":true,"img":false}]}
{"op":"mcm","clk":"11449514138","pt":1717310190494,"mc":[{"id":"1.229554890","rc":[{"atl":[[1000,1.55]],"id":70003367},{"atl":[[1000,1.55]],"id":70003365}],"con":true,"img":false}]}
{"op":"mcm","clk":"11449514151","pt":1717310190696,"mc":[{"id":"1.229554890","rc":[{"atl":[[1000,0]],"id":70003367}],"con":true,"img":false}]}
{"op":"mcm","clk":"11449514157","pt":1717310190799,"mc":[{"id":"1.229554890","rc":[{"atl":[[8.6,3.8]],"id":70003367}],"con":true,"img":false}]}
{"op":"mcm","clk":"11449514171","pt":1717310191007,"mc":[{"id":"1.229554890","rc":[{"atl":[[1000,0]],"id":70003365}],"con":true,"img":false}]}
{"op":"mcm","clk":"11449514177","pt":1717310191108,"mc":[{"id":"1.229554890","rc":[{"atl":[[8.6,3.8]],"id":70003365}],"con":true,"img":false}]}
{"op":"mcm","clk":"11449522538","pt":1717310328971,"mc":[{"id":"1.229554890","rc":[{"atl":[[3.75,3.55]],"id":70003364}],"con":true,"img":false}]}
{"op":"mcm","clk":"11449524668","pt":1717310362446,"mc":[{"id":"1.229554890","rc":[{"atl":[[8.6,1.55]],"id":70003365}],"con":true,"img":false}]}
{"op":"mcm","clk":"11449525295","pt":1717310372360,"mc":[{"id":"1.229554890","rc":[{"atl":[[3.75,0]],"id":70003364}],"con":true,"img":false}]}
{"op":"mcm","clk":"11449526206","pt":1717310387583,"mc":[{"id":"1.229554890","rc":[{"atl":[[8.6,0]],"id":70003365}],"con":true,"img":false}]}
{"op":"mcm","clk":"11449526495","pt":1717310392068,"mc":[{"id":"1.229554890","rc":[{"atl":[[8.6,1.55]],"id":70003367},{"spn":2.86,"spf":"NaN","id":70003364},{"spn":6.09,"spf":"NaN","id":70003365}],"con":true,"img":false}]}
{"op":"mcm","clk":"11449527109","pt":1717310402486,"mc":[{"id":"1.229554890","rc":[{"atl":[[8.6,0]],"id":70003367}],"con":true,"img":false}]}
{"op":"mcm","clk":"11449528033","pt":1717310417373,"mc":[{"id":"1.229554890","rc":[{"atl":[[1000,2.35]],"id":70003367},{"atl":[[3.75,3.55]],"id":70003364},{"atl":[[1000,2.35]],"id":70003365}],"con":true,"img":false}]}
{"op":"mcm","clk":"11449528047","pt":1717310417579,"mc":[{"id":"1.229554890","rc":[{"atl":[[1000,1.55]],"id":70003367},{"atl":[[1000,1.55]],"id":70003365}],"con":true,"img":false}]}
{"op":"mcm","clk":"11449528058","pt":1717310417784,"mc":[{"id":"1.229554890","rc":[{"atl":[[1000,0]],"id":70003367}],"con":true,"img":false}]}
{"op":"mcm","clk":"11449528062","pt":1717310417885,"mc":[{"id":"1.229554890","rc":[{"atl":[[8.6,1.55]],"id":70003367}],"con":true,"img":false}]}
{"op":"mcm","clk":"11449528085","pt":1717310418198,"mc":[{"id":"1.229554890","rc":[{"atl":[[1000,0]],"id":70003365}],"con":true,"img":false}]}
{"op":"mcm","clk":"11449528093","pt":1717310418299,"mc":[{"id":"1.229554890","rc":[{"atl":[[8.6,1.55]],"id":70003365}],"con":true,"img":false}]}
{"op":"mcm","clk":"11449528458","pt":1717310425017,"mc":[{"id":"1.229554890","rc":[{"atl":[[3.75,8.69]],"id":70003364}],"con":true,"img":false}]}
{"op":"mcm","clk":"11449528462","pt":1717310425118,"mc":[{"id":"1.229554890","rc":[{"atl":[[8.6,3.8]],"id":70003365}],"con":true,"img":false}]}
{"op":"mcm","clk":"11449528477","pt":1717310425326,"mc":[{"id":"1.229554890","rc":[{"atl":[[8.6,3.8]],"id":70003367}],"con":true,"img":false}]}
{"op":"mcm","clk":"11449532192","pt":1717310487911,"mc":[{"id":"1.229554890","rc":[{"atb":[[38,0],[24,0],[29,0]],"id":70003366},{"atl":[[550,0],[450,0]],"id":70003366},{"spn":"NaN","spf":"NaN","id":70003366},{"spn":2.74,"spf":"NaN","id":70003364},{"spn":5.69,"spf":"NaN","id":70003365},{"atb":[[12,0],[9.8,0],[14.5,0]],"id":70003363},{"atl":[[330,0],[230,0]],"id":70003363},{"spn":"NaN","spf":"NaN","id":70003363}],"con":true,"img":false}]}
{"op":"mcm","clk":"11449533234","pt":1717310504889,"mc":[{"id":"1.229554890","rc":[{"atb":[[32,3.37],[21,10.45],[26,8.36]],"id":70003366},{"atl":[[520,0.4],[420,0.33]],"id":70003366},{"atb":[[12,19],[9.8,23.75],[14.5,7.74]],"id":70003363},{"atl":[[330,0.63],[230,0.6]],"id":70003363}],"con":true,"img":false}]}
{"op":"mcm","clk":"11449539324","pt":1717310605442,"mc":[{"id":"1.229554890","rc":[{"spn":226.0,"spf":"NaN","id":70003366},{"atl":[[3.75,3.55]],"id":70003364},{"spn":122.25,"spf":"NaN","id":70003363}],"con":true,"img":false}]}
{"op":"mcm","clk":"11449539402","pt":1717310606875,"mc":[{"id":"1.229554890","rc":[{"atl":[[3.75,0]],"id":70003364}],"con":true,"img":false}]}
{"op":"mcm","clk":"11449539672","pt":1717310611679,"mc":[{"id":"1.229554890","rc":[{"atl":[[8.6,2.24]],"id":70003365}],"con":true,"img":false}]}
{"op":"mcm","clk":"11449540465","pt":1717310626712,"mc":[{"id":"1.229554890","rc":[{"atl":[[8.6,2.24]],"id":70003367}],"con":true,"img":false}]}
{"op":"mcm","clk":"11449541307","pt":1717310642719,"mc":[{"id":"1.229554890","rc":[{"atl":[[8.6,0]],"id":70003365}],"con":true,"img":false}]}
{"op":"mcm","clk":"11449541346","pt":1717310643190,"mc":[{"id":"1.229554890","rc":[{"atl":[[3.75,3.55]],"id":70003364},{"atl":[[1000,2.35]],"id":70003365}],"con":true,"img":false}]}
{"op":"mcm","clk":"11449541357","pt":1717310643392,"mc":[{"id":"1.229554890","rc":[{"atl":[[1000,2.35]],"id":70003367}],"con":true,"img":false}]}
{"op":"mcm","clk":"11449541363","pt":1717310643493,"mc":[{"id":"1.229554890","rc":[{"atl":[[1000,1.55]],"id":70003365}],"con":true,"img":false}]}
{"op":"mcm","clk":"11449541375","pt":1717310643712,"mc":[{"id":"1.229554890","rc":[{"atl":[[1000,1.55]],"id":70003367},{"atl":[[1000,0]],"id":70003365}],"con":true,"img":false}]}
{"op":"mcm","clk":"11449541382","pt":1717310643804,"mc":[{"id":"1.229554890","rc":[{"atl":[[8.6,1.55]],"id":70003365}],"con":true,"img":false}]}
{"op":"mcm","clk":"11449541399","pt":1717310644111,"mc":[{"id":"1.229554890","rc":[{"atl":[[1000,0]],"id":70003367}],"con":true,"img":false}]}
{"op":"mcm","clk":"11449541406","pt":1717310644214,"mc":[{"id":"1.229554890","rc":[{"atl":[[8.6,3.8]],"id":70003367}],"con":true,"img":false}]}
{"op":"mcm","clk":"11449542900","pt":1717310670011,"mc":[{"id":"1.229554890","rc":[{"atl":[[8.6,1.55]],"id":70003367}],"con":true,"img":false}]}
{"op":"mcm","clk":"11449545108","pt":1717310708609,"mc":[{"id":"1.229554890","rc":[{"atl":[[3.75,8.69]],"id":70003364}],"con":true,"img":false}]}
{"op":"mcm","clk":"11449545122","pt":1717310708764,"mc":[{"id":"1.229554890","rc":[{"atl":[[8.6,3.8]],"id":70003365}],"con":true,"img":false}]}
{"op":"mcm","clk":"11449545128","pt":1717310708865,"mc":[{"id":"1.229554890","rc":[{"atl":[[8.6,3.8]],"id":70003367}],"con":true,"img":false}]}
{"op":"mcm","clk":"11449550471","pt":1717310796824,"mc":[{"id":"1.229554890","rc":[{"atb":[[32,0],[21,0],[26,0]],"id":70003366},{"atl":[[520,0],[420,0]],"id":70003366},{"spn":"NaN","spf":"NaN","id":70003366},{"atb":[[2.58,0],[2.78,0],[2.68,0]],"id":70003367},{"atl":[[13.5,0],[9.4,0]],"id":70003367},{"spn":1.0,"spf":"NaN","id":70003367},{"atb":[[1.73,0],[1.63,0],[1.68,0]],"id":70003364},{"atl":[[4,0],[5,0]],"id":70003364},{"spn":1.0,"spf":"NaN","id":70003364},{"atb":[[2.58,0],[2.78,0],[2.68,0]],"id":70003365},{"atl":[[13.5,0],[9.4,0]],"id":70003365},{"spn":1.0,"spf":"NaN","id":70003365},{"atb":[[12,0],[9.8,0],[14.5,0]],"id":70003363},{"atl":[[330,0],[230,0]],"id":70003363},{"spn":"NaN","spf":"NaN","id":70003363}],"con":true,"img":false}]}
{"op":"mcm","clk":"11449552007","pt":1717310824031,"mc":[{"id":"1.229554890","rc":[{"atl":[[3.75,5.13]],"id":70003364}],"con":true,"img":false}]}
{"op":"mcm","clk":"11449552512","pt":1717310833578,"mc":[{"id":"1.229554890","rc":[{"atb":[[32,3.37],[21,10.45],[26,8.36]],"id":70003366},{"atl":[[520,0.4],[420,0.33]],"id":70003366},{"atb":[[2.58,132.31],[2.78,58.72],[2.68,124.44]],"id":70003367},{"atl":[[13.5,16.72],[9.4,16.58]],"id":70003367},{"atb":[[1.73,143.19],[1.63,331.84],[1.68,307.44]],"id":70003364},{"atl":[[4,46.45],[5,52.26]],"id":70003364},{"atb":[[2.58,132.31],[2.78,58.72],[2.68,124.44]],"id":70003365},{"atl":[[13.5,16.72],[9.4,16.58]],"id":70003365},{"atb":[[12,19],[9.8,23.75],[14.5,7.74]],"id":70003363},{"atl":[[330,0.63],[230,0.6]],"id":70003363}],"con":true,"img":false}]}
{"op":"mcm","clk":"11449552838","pt":1717310838994,"mc":[{"id":"1.229554890","rc":[{"atl":[[8.6,2.24]],"id":70003365}],"con":true,"img":false}]}
{"op":"mcm","clk":"11449553620","pt":1717310854012,"mc":[{"id":"1.229554890","rc":[{"atl":[[8.6,2.24]],"id":70003367}],"con":true,"img":false}]}
{"op":"mcm","clk":"11449554985","pt":1717310877024,"mc":[{"id":"1.229554890","rc":[{"spn":226.0,"spf":"NaN","id":70003366},{"atl":[[1000,2.35]],"id":70003367},{"spn":5.69,"spf":"NaN","id":70003367},{"atl":[[3.75,8.69]],"id":70003364},{"spn":2.74,"spf":"NaN","id":70003364},{"atl":[[1000,2.35]],"id":70003365},{"spn":5.69,"spf":"NaN","id":70003365},{"spn":122.25,"spf":"NaN","id":70003363}],"con":true,"img":false}]}
{"op":"mcm","clk":"11449555004","pt":1717310877333,"mc":[{"id":"1.229554890","rc":[{"atl":[[1000,1.55]],"id":70003367},{"atl":[[1000,1.55]],"id":70003365}],"con":true,"img":false}]}
{"op":"mcm","clk":"11449555021","pt":1717310877536,"mc":[{"id":"1.229554890","rc":[{"atl":[[1000,0]],"id":70003365}],"con":true,"img":false}]}
{"op":"mcm","clk":"11449555031","pt":1717310877643,"mc":[{"id":"1.229554890","rc":[{"atl":[[8.6,3.8]],"id":70003365}],"con":true,"img":false}]}
{"op":"mcm","clk":"11449555049","pt":1717310877897,"mc":[{"id":"1.229554890","rc":[{"atl":[[1000,0]],"id":70003367}],"con":true,"img":false}]}
{"op":"mcm","clk":"11449555055","pt":1717310878005,"mc":[{"id":"1.229554890","rc":[{"atl":[[8.6,3.8]],"id":70003367}],"con":true,"img":false}]}
{"op":"mcm","clk":"11449556042","pt":1717310895819,"mc":[{"id":"1.229554890","rc":[{"atl":[[3.75,3.55]],"id":70003364}],"con":true,"img":false}]}
{"op":"mcm","clk":"11449557904","pt":1717310928973,"mc":[{"id":"1.229554890","rc":[{"atl":[[8.6,1.55]],"id":70003365}],"con":true,"img":false}]}
{"op":"mcm","clk":"11449560225","pt":1717310970947,"mc":[{"id":"1.229554890","rc":[{"atl":[[8.6,1.55]],"id":70003367}],"con":true,"img":false}]}
{"op":"mcm","clk":"11449561890","pt":1717311004669,"mc":[{"id":"1.229554890","rc":[{"atl":[[3.75,8.69]],"id":70003364}],"con":true,"img":false}]}
{"op":"mcm","clk":"11449561898","pt":1717311004773,"mc":[{"id":"1.229554890","rc":[{"atl":[[8.6,3.8]],"id":70003365}],"con":true,"img":false}]}
{"op":"mcm","clk":"11449561911","pt":1717311004978,"mc":[{"id":"1.229554890","rc":[{"atl":[[8.6,3.8]],"id":70003367}],"con":true,"img":false}]}
{"op":"mcm","clk":"11449565216","pt":1717311067147,"mc":[{"id":"1.229554890","rc":[{"atl":[[3.75,5.13]],"id":70003364}],"con":true,"img":false}]}
{"op":"mcm","clk":"11449565973","pt":1717311082075,"mc":[{"id":"1.229554890","rc":[{"atl":[[8.6,2.24]],"id":70003365}],"con":true,"img":false}]}
{"op":"mcm","clk":"11449566801","pt":1717311097101,"mc":[{"id":"1.229554890","rc":[{"atl":[[8.6,2.24]],"id":70003367}],"con":true,"img":false}]}
{"op":"mcm","clk":"11449567587","pt":1717311112431,"mc":[{"id":"1.229554890","rc":[{"atl":[[3.75,8.69]],"id":70003364},{"atl":[[1000,2.35]],"id":70003365}],"con":true,"img":false}]}
{"op":"mcm","clk":"11449567598","pt":1717311112588,"mc":[{"id":"1.229554890","rc":[{"atl":[[1000,2.35]],"id":70003367},{"atl":[[1000,1.55]],"id":70003365}],"con":true,"img":false}]}
{"op":"mcm","clk":"11449567614","pt":1717311112898,"mc":[{"id":"1.229554890","rc":[{"atl":[[1000,0]],"id":70003365}],"con":true,"img":false}]}
{"op":"mcm","clk":"11449567622","pt":1717311112999,"mc":[{"id":"1.229554890","rc":[{"atl":[[1000,1.55]],"id":70003367},{"atl":[[8.6,3.8]],"id":70003365}],"con":true,"img":false}]}
{"op":"mcm","clk":"11449567640","pt":1717311113307,"mc":[{"id":"1.229554890","rc":[{"atl":[[1000,0]],"id":70003367}],"con":true,"img":false}]}
{"op":"mcm","clk":"11449567645","pt":1717311113408,"mc":[{"id":"1.229554890","rc":[{"atl":[[8.6,3.8]],"id":70003367}],"con":true,"img":false}]}
{"op":"mcm","clk":"11449573511","pt":1717311221244,"mc":[{"id":"1.229554890","rc":[{"atb":[[32,5.99],[28,4.09]],"id":70003366},{"atl":[[510,2.72]],"id":70003366},{"atb":[[2.6,77.95],[2.7,33]],"id":70003367},{"atl":[[9.2,15.17],[7.8,8.25]],"id":70003367},{"spn":5.29,"spf":"NaN","id":70003367},{"atb":[[1.64,195.14],[1.74,62.21]],"id":70003364},{"atl":[[3.95,42.37],[3.7,20.78]],"id":70003364},{"spn":2.72,"spf":"NaN","id":70003364},{"atb":[[2.6,74.71],[2.7,33]],"id":70003365},{"atl":[[9.2,14.58],[7.8,8.25]],"id":70003365},{"spn":5.29,"spf":"NaN","id":70003365},{"atb":[[13.5,9.41],[15.5,3.87]],"id":70003363},{"atl":[[150,2.61],[120,2.61]],"id":70003363},{"spn":67.75,"spf":"NaN","id":70003363}],"con":true,"img":false}]}
{"op":"mcm","clk":"11449573558","pt":1717311222221,"mc":[{"id":"1.229554890","rc":[{"atl":[[3.75,3.55]],"id":70003364}],"con":true,"img":false}]}
{"op":"mcm","clk":"11449574889","pt":1717311245483,"mc":[{"id":"1.229554890","rc":[{"atl":[[8.6,1.55]],"id":70003365}],"con":true,"img":false}]}
{"op":"mcm","clk":"11449577436","pt":1717311286462,"mc":[{"id":"1.229554890","rc":[{"atl":[[8.6,1.55]],"id":70003367}],"con":true,"img":false}]}
{"op":"mcm","clk":"11449577697","pt":1717311290519,"mc":[{"id":"1.229554890","rc":[{"atl":[[510,2.61]],"id":70003366},{"atb":[[2.7,0]],"id":70003367},{"atb":[[2.7,0]],"id":70003365}],"con":true,"img":false}]}
{"op":"mcm","clk":"11449577706","pt":1717311290572,"mc":[{"id":"1.229554890","rc":[{"atl":[[410,0.1]],"id":70003366},{"atb":[[2.8,33]],"id":70003367},{"atb":[[2.8,33]],"id":70003365}],"con":true,"img":false}]}
{"op":"mcm","clk":"11449577857","pt":1717311293290,"mc":[{"id":"1.229554890","rc":[{"atl":[[3.75,0]],"id":70003364}],"con":true,"img":false}]}
{"op":"mcm","clk":"11449578791","pt":1717311308025,"mc":[{"id":"1.229554890","rc":[{"atl":[[8.6,0]],"id":70003365}],"con":true,"img":false}]}
{"op":"mcm","clk":"11449579603","pt":1717311321710,"mc":[{"id":"1.229554890","rc":[{"atl":[[3.45,5.59]],"id":70003364}],"con":true,"img":false}]}
{"op":"mcm","clk":"11449579618","pt":1717311321918,"mc":[{"id":"1.229554890","rc":[{"atl":[[7.2,2.67]],"id":70003365}],"con":true,"img":false}]}
{"op":"mcm","clk":"11449579625","pt":1717311322019,"mc":[{"id":"1.229554890","rc":[{"atl":[[7.2,2.67]],"id":70003367}],"con":true,"img":false}]}
{"op":"mcm","clk":"11449579713","pt":1717311323155,"mc":[{"id":"1.229554890","rc":[{"atl":[[8.6,0]],"id":70003367}],"con":true,"img":false}]}
{"op":"mcm","clk":"11449580751","pt":1717311338329,"mc":[{"id":"1.229554890","rc":[{"atl":[[1000,2.35]],"id":70003367},{"atl":[[3.45,9.46]],"id":70003364},{"atl":[[1000,2.35]],"id":70003365}],"con":true,"img":false}]}
{"op":"mcm","clk":"11449580760","pt":1717311338632,"mc":[{"id":"1.229554890","rc":[{"atl":[[1000,1.85]],"id":70003367},{"atl":[[1000,1.85]],"id":70003365}],"con":true,"img":false}]}
{"op":"mcm","clk":"11449580767","pt":1717311338838,"mc":[{"id":"1.229554890","rc":[{"atl":[[1000,0]],"id":70003367}],"con":true,"img":false}]}
{"op":"mcm","clk":"11449580773","pt":1717311338943,"mc":[{"id":"1.229554890","rc":[{"atl":[[7.2,4.52]],"id":70003367}],"con":true,"img":false}]}
{"op":"mcm","clk":"11449580788","pt":1717311339145,"mc":[{"id":"1.229554890","rc":[{"atl":[[1000,0]],"id":70003365}],"con":true,"img":false}]}
{"op":"mcm","clk":"11449580796","pt":1717311339259,"mc":[{"id":"1.229554890","rc":[{"atl":[[7.2,4.52]],"id":70003365}],"con":true,"img":false}]}
{"op":"mcm","clk":"11449586472","pt":1717311439076,"mc":[{"id":"1.229554890","rc":[{"atb":[[1.03,5.96]],"id":70003366},{"atl":[[990,0.85]],"id":70003366},{"spn":221.0,"spf":"NaN","id":70003366},{"atb":[[1.01,17.89]],"id":70003367},{"atl":[[1000,0.85]],"id":70003367},{"spn":5.0,"spf":"NaN","id":70003367},{"atb":[[1.02,8.94]],"id":70003364},{"atl":[[1000,0.85]],"id":70003364},{"spn":2.59,"spf":"NaN","id":70003364},{"atb":[[1.01,17.89]],"id":70003365},{"atl":[[1000,0.85]],"id":70003365},{"spn":5.0,"spf":"NaN","id":70003365},{"atb":[[1.01,17.89]],"id":70003363},{"atl":[[1000,0.85]],"id":70003363}],"con":true,"img":false}]}
{"op":"mcm","clk":"11449590889","pt":1717311519507,"mc":[{"id":"1.229554890","rc":[{"atl":[[3.45,5.59]],"id":70003364}],"con":true,"img":false}]}
{"op":"mcm","clk":"11449590920","pt":1717311520074,"mc":[{"id":"1.229554890","rc":[{"atb":[[1.01,71.58]],"id":70003366},{"atl":[[970,1.89]],"id":70003366},{"atb":[[1.03,89.47]],"id":70003367},{"atl":[[990,0.85]],"id":70003367},{"atb":[[1.03,121.85]],"id":70003364},{"atl":[[990,1.27]],"id":70003364},{"atb":[[1.03,148.27]],"id":70003365},{"atl":[[970,1.82]],"id":70003365},{"atb":[[1.02,113.33]],"id":70003363},{"atl":[[990,1.72]],"id":70003363}],"con":true,"img":false}]}
{"op":"mcm","clk":"11449591228","pt":1717311526113,"mc":[{"id":"1.229554890","rc":[{"atl":[[3.45,0]],"id":70003364}],"con":true,"img":false}]}
{"op":"mcm","clk":"11449591612","pt":1717311534081,"mc":[{"id":"1.229554890","rc":[{"atl":[[7.2,2.67]],"id":70003365}],"con":true,"img":false}]}
{"op":"mcm","clk":"11449592267","pt":1717311547697,"mc":[{"id":"1.229554890","rc":[{"atl":[[7.2,0]],"id":70003365}],"con":true,"img":false}]}
{"op":"mcm","clk":"11449592337","pt":1717311549028,"mc":[{"id":"1.229554890","rc":[{"atl":[[7.2,2.67]],"id":70003367}],"con":true,"img":false}]}
{"op":"mcm","clk":"11449593161","pt":1717311564052,"mc":[{"id":"1.229554890","rc":[{"atl":[[1000,3.2]],"id":70003367},{"atl":[[3.45,3.87]],"id":70003364},{"atl":[[1000,3.2]],"id":70003365}],"con":true,"img":false}]}
{"op":"mcm","clk":"11449593172","pt":1717311564362,"mc":[{"id":"1.229554890","rc":[{"atl":[[1000,2.7]],"id":70003367},{"atl":[[1000,2.7]],"id":70003365}],"con":true,"img":false}]}
{"op":"mcm","clk":"11449593182","pt":1717311564567,"mc":[{"id":"1.229554890","rc":[{"atl":[[1000,0.85]],"id":70003367}],"con":true,"img":false}]}
{"op":"mcm","clk":"11449593188","pt":1717311564658,"mc":[{"id":"1.229554890","rc":[{"atl":[[7.2,4.52]],"id":70003367}],"con":true,"img":false}]}
{"op":"mcm","clk":"11449593199","pt":1717311564863,"mc":[{"id":"1.229554890","rc":[{"atl":[[1000,0.85]],"id":70003365}],"con":true,"img":false}]}
{"op":"mcm","clk":"11449593207","pt":1717311564977,"mc":[{"id":"1.229554890","rc":[{"atl":[[7.2,1.85]],"id":70003365}],"con":true,"img":false}]}
{"op":"mcm","clk":"11449594201","pt":1717311584278,"mc":[{"id":"1.229554890","rc":[{"atl":[[7.2,1.85]],"id":70003367}],"con":true,"img":false}]}
{"op":"mcm","clk":"11449596148","pt":1717311620293,"mc":[{"id":"1.229554890","rc":[{"atl":[[3.45,9.46]],"id":70003364}],"con":true,"img":false}]}
{"op":"mcm","clk":"11449596167","pt":1717311620500,"mc":[{"id":"1.229554890","rc":[{"atl":[[7.2,4.52]],"id":70003367},{"atl":[[7.2,4.52]],"id":70003365}],"con":true,"img":false}]}
{"op":"mcm","clk":"11449601377","pt":1717311718333,"mc":[{"id":"1.229554890","rc":[{"atb":[[32,2.61],[21,0],[26,0]],"id":70003366},{"atl":[[520,0],[420,0]],"id":70003366},{"atb":[[2.58,0],[2.78,0],[2.68,0]],"id":70003367},{"atl":[[13.5,0],[9.4,0]],"id":70003367},{"atb":[[1.73,0],[1.63,0],[1.68,0]],"id":70003364},{"atl":[[4,0],[5,0]],"id":70003364},{"atb":[[2.58,0],[2.78,0],[2.68,0]],"id":70003365},{"atl":[[13.5,0],[9.4,0]],"id":70003365},{"atb":[[12,0],[9.8,0],[14.5,0]],"id":70003363},{"atl":[[330,0],[230,0]],"id":70003363}],"con":true,"img":false}]}
{"op":"mcm","clk":"11449602231","pt":1717311733648,"mc":[{"id":"1.229554890","rc":[{"atl":[[4.6,34.52],[3.95,0]],"id":70003364}],"con":true,"img":false}]}
{"op":"mcm","clk":"11449602248","pt":1717311734056,"mc":[{"id":"1.229554890","rc":[{"atl":[[410,0],[510,0]],"id":70003366},{"atb":[[2.8,0],[2.6,0]],"id":70003367},{"atb":[[1.64,0],[1.74,0]],"id":70003364},{"atb":[[2.8,0],[2.6,0]],"id":70003365}],"con":true,"img":false}]}
{"op":"mcm","clk":"11449602254","pt":1717311734160,"mc":[{"id":"1.229554890","rc":[{"atl":[[690,2.61],[510,0.1]],"id":70003366},{"atb":[[2.42,77.95],[2.66,33]],"id":70003367},{"atb":[[1.57,195.14],[1.67,62.21]],"id":70003364},{"atb":[[2.42,74.71],[2.68,33]],"id":70003365}],"con":true,"img":false}]}
{"op":"mcm","clk":"11449603030","pt":1717311749683,"mc":[{"id":"1.229554890","rc":[{"atl":[[3.45,5.59]],"id":70003364}],"con":true,"img":false}]}
{"op":"mcm","clk":"11449603138","pt":1717311751696,"mc":[{"id":"1.229554890","rc":[{"atb":[[32,5.99],[21,10.45],[26,8.36]],"id":70003366},{"atl":[[520,0.4],[420,0.33]],"id":70003366},{"atb":[[2.58,132.31],[2.78,58.72],[2.68,124.44]],"id":70003367},{"atl":[[13.5,16.72],[9.4,16.58]],"id":70003367},{"atb":[[1.73,143.19],[1.63,331.84],[1.68,307.44]],"id":70003364},{"atl":[[4,46.45],[5,52.26]],"id":70003364},{"atb":[[2.58,132.31],[2.78,58.72],[2.68,157.45]],"id":70003365},{"atl":[[13.5,16.72],[9.4,16.58]],"id":70003365},{"atb":[[12,19],[9.8,23.75],[14.5,7.74]],"id":70003363},{"atl":[[330,0.63],[230,0.6]],"id":70003363}],"con":true,"img":false}]}
{"op":"mcm","clk":"11449603858","pt":1717311764563,"mc":[{"id":"1.229554890","rc":[{"atl":[[7.2,2.67]],"id":70003365}],"con":true,"img":false}]}
{"op":"mcm","clk":"11449604598","pt":1717311779818,"mc":[{"id":"1.229554890","rc":[{"spn":226.0,"spf":"NaN","id":70003366},{"atl":[[7.2,2.67]],"id":70003367},{"spn":4.99,"spf":"NaN","id":70003367},{"spn":2.59,"spf":"NaN","id":70003364},{"spn":4.99,"spf":"NaN","id":70003365}],"con":true,"img":false}]}
{"op":"mcm","clk":"11449605319","pt":1717311794830,"mc":[{"id":"1.229554890","rc":[{"atl":[[1000,3.2]],"id":70003367},{"atl":[[3.45,9.46]],"id":70003364},{"atl":[[1000,3.2]],"id":70003365}],"con":true,"img":false}]}
{"op":"mcm","clk":"11449605329","pt":1717311795034,"mc":[{"id":"1.229554890","rc":[{"atl":[[1000,2.7]],"id":70003367},{"atl":[[1000,2.7]],"id":70003365}],"con":true,"img":false}]}
{"op":"mcm","clk":"11449605337","pt":1717311795238,"mc":[{"id":"1.229554890","rc":[{"atl":[[1000,0.85]],"id":70003365}],"con":true,"img":false}]}
{"op":"mcm","clk":"11449605344","pt":1717311795342,"mc":[{"id":"1.229554890","rc":[{"atl":[[7.2,4.52]],"id":70003365}],"con":true,"img":false}]}
{"op":"mcm","clk":"11449605356","pt":1717311795550,"mc":[{"id":"1.229554890","rc":[{"atl":[[1000,0.85]],"id":70003367}],"con":true,"img":false}]}
{"op":"mcm","clk":"11449605363","pt":1717311795603,"mc":[{"id":"1.229554890","rc":[{"atl":[[7.2,4.52]],"id":70003367}],"con":true,"img":false}]}
{"op":"mcm","clk":"11449605971","pt":1717311806332,"mc":[{"id":"1.229554890","rc":[{"atl":[[690,0],[510,0]],"id":70003366},{"atb":[[2.42,0],[2.66,0]],"id":70003367},{"atb":[[1.57,0],[1.67,0]],"id":70003364},{"atb":[[2.42,0],[2.68,124.44]],"id":70003365}],"con":true,"img":false}]}
{"op":"mcm","clk":"11449605979","pt":1717311806431,"mc":[{"id":"1.229554890","rc":[{"atl":[[410,0.1],[510,2.61]],"id":70003366},{"atb":[[2.8,33],[2.6,77.95]],"id":70003367},{"atb":[[1.64,195.14],[1.74,62.21]],"id":70003364},{"atl":[[4.6,0],[3.95,42.37]],"id":70003364},{"atb":[[2.8,33],[2.6,74.71]],"id":70003365}],"con":true,"img":false}]}
{"op":"mcm","clk":"11449606656","pt":1717311817386,"mc":[{"id":"1.229554890","rc":[{"atl":[[3.45,3.87]],"id":70003364}],"con":true,"img":false}]}
{"op":"mcm","clk":"11449608684","pt":1717311852304,"mc":[{"id":"1.229554890","rc":[{"spn":221.0,"spf":"NaN","id":70003366},{"spn":5.0,"spf":"NaN","id":70003367},{"spn":2.59,"spf":"NaN","id":70003364},{"atl":[[7.2,1.85]],"id":70003365},{"spn":5.0,"spf":"NaN","id":70003365}],"con":true,"img":false}]}
{"op":"mcm","clk":"11449610643","pt":1717311887967,"mc":[{"id":"1.229554890","rc":[{"atl":[[7.2,1.85]],"id":70003367}],"con":true,"img":false}]}
{"op":"mcm","clk":"11449612529","pt":1717311920519,"mc":[{"id":"1.229554890","rc":[{"atl":[[3.45,9.46]],"id":70003364}],"con":true,"img":false}]}
{"op":"mcm","clk":"11449612538","pt":1717311920726,"mc":[{"id":"1.229554890","rc":[{"atl":[[7.2,4.52]],"id":70003365}],"con":true,"img":false}]}
{"op":"mcm","clk":"11449612546","pt":1717311920830,"mc":[{"id":"1.229554890","rc":[{"atl":[[7.2,4.52]],"id":70003367}],"con":true,"img":false}]}
{"op":"mcm","clk":"11449615508","pt":1717311975185,"mc":[{"id":"1.229554890","rc":[{"atl":[[3.45,5.59]],"id":70003364}],"con":true,"img":false}]}
{"op":"mcm","clk":"11449616252","pt":1717311990588,"mc":[{"id":"1.229554890","rc":[{"atl":[[7.2,2.67]],"id":70003365}],"con":true,"img":false}]}
{"op":"mcm","clk":"11449616731","pt":1717312000714,"mc":[{"id":"1.229554890","rc":[{"atl":[[7.2,2.67]],"id":70003367}],"con":true,"img":false}]}
{"op":"mcm","clk":"11449617476","pt":1717312015720,"mc":[{"id":"1.229554890","rc":[{"atl":[[1000,3.2]],"id":70003367},{"atl":[[3.45,9.46]],"id":70003364},{"atl":[[1000,3.2]],"id":70003365}],"con":true,"img":false}]}
{"op":"mcm","clk":"11449617492","pt":1717312016032,"mc":[{"id":"1.229554890","rc":[{"atl":[[1000,2.7]],"id":70003367},{"atl":[[1000,2.7]],"id":70003365}],"con":true,"img":false}]}
{"op":"mcm","clk":"11449617502","pt":1717312016293,"mc":[{"id":"1.229554890","rc":[{"atl":[[1000,0.85]],"id":70003367}],"con":true,"img":false}]}
{"op":"mcm","clk":"11449617506","pt":1717312016396,"mc":[{"id":"1.229554890","rc":[{"atl":[[7.2,4.52]],"id":70003367}],"con":true,"img":false}]}
{"op":"mcm","clk":"11449617519","pt":1717312016702,"mc":[{"id":"1.229554890","rc":[{"atl":[[1000,0.85]],"id":70003365}],"con":true,"img":false}]}
{"op":"mcm","clk":"11449617524","pt":1717312016806,"mc":[{"id":"1.229554890","rc":[{"atl":[[7.2,4.52]],"id":70003365}],"con":true,"img":false}]}
{"op":"mcm","clk":"11449622849","pt":1717312128176,"mc":[{"id":"1.229554890","rc":[{"atl":[[3.45,3.87]],"id":70003364}],"con":true,"img":false}]}
{"op":"mcm","clk":"11449624516","pt":1717312174505,"mc":[{"id":"1.229554890","rc":[{"atl":[[7.2,1.85]],"id":70003365}],"con":true,"img":false}]}
{"op":"mcm","clk":"11449625486","pt":1717312196652,"mc":[{"id":"1.229554890","rc":[{"atl":[[3.45,0]],"id":70003364},{"spn":2.72,"spf":"NaN","id":70003364}],"con":true,"img":false}]}
{"op":"mcm","clk":"11449625933","pt":1717312206032,"mc":[{"id":"1.229554890","rc":[{"atl":[[7.2,1.85]],"id":70003367}],"con":true,"img":false}]}
{"op":"mcm","clk":"11449626111","pt":1717312211274,"mc":[{"id":"1.229554890","rc":[{"atl":[[7.2,0]],"id":70003365}],"con":true,"img":false}]}
{"op":"mcm","clk":"11449626718","pt":1717312226568,"mc":[{"id":"1.229554890","rc":[{"atl":[[7.2,0]],"id":70003367}],"con":true,"img":false}]}
{"op":"mcm","clk":"11449627617","pt":1717312246819,"mc":[{"id":"1.229554890","rc":[{"atl":[[3.45,3.87]],"id":70003364},{"atl":[[1000,3.2]],"id":70003365}],"con":true,"img":false}]}
{"op":"mcm","clk":"11449627624","pt":1717312247026,"mc":[{"id":"1.229554890","rc":[{"atl":[[1000,3.2]],"id":70003367}],"con":true,"img":false}]}
{"op":"mcm","clk":"11449627628","pt":1717312247127,"mc":[{"id":"1.229554890","rc":[{"atl":[[1000,2.7]],"id":70003365}],"con":true,"img":false}]}
{"op":"mcm","clk":"11449627636","pt":1717312247329,"mc":[{"id":"1.229554890","rc":[{"atl":[[1000,2.7]],"id":70003367}],"con":true,"img":false}]}
{"op":"mcm","clk":"11449627638","pt":1717312247432,"mc":[{"id":"1.229554890","rc":[{"atl":[[1000,0.85]],"id":70003365}],"con":true,"img":false}]}
{"op":"mcm","clk":"11449627641","pt":1717312247535,"mc":[{"id":"1.229554890","rc":[{"atl":[[7.2,1.85]],"id":70003365}],"con":true,"img":false}]}
{"op":"mcm","clk":"11449627651","pt":1717312247842,"mc":[{"id":"1.229554890","rc":[{"atl":[[1000,0.85]],"id":70003367}],"con":true,"img":false}]}
{"op":"mcm","clk":"11449627654","pt":1717312247943,"mc":[{"id":"1.229554890","rc":[{"atl":[[7.2,1.85]],"id":70003367}],"con":true,"img":false}]}
{"op":"mcm","clk":"11449632691","pt":1717312379204,"mc":[{"id":"1.229554890","rc":[{"atb":[[1.55,100]],"id":70003364},{"spn":2.59,"spf":"NaN","id":70003364}],"con":true,"img":false}]}
{"op":"mcm","clk":"11449634996","pt":1717312440500,"mc":[{"id":"1.229554890","rc":[{"atl":[[3.45,0]],"id":70003364},{"spn":2.72,"spf":"NaN","id":70003364}],"con":true,"img":false}]}
{"op":"mcm","clk":"11449635493","pt":1717312455321,"mc":[{"id":"1.229554890","rc":[{"atl":[[7.2,0]],"id":70003365}],"con":true,"img":false}]}
{"op":"mcm","clk":"11449636103","pt":1717312470208,"mc":[{"id":"1.229554890","rc":[{"atl":[[7.2,0]],"id":70003367}],"con":true,"img":false}]}
{"op":"mcm","clk":"11449636625","pt":1717312485236,"mc":[{"id":"1.229554890","rc":[{"atl":[[3.45,3.87]],"id":70003364}],"con":true,"img":false}]}
{"op":"mcm","clk":"11449636632","pt":1717312485446,"mc":[{"id":"1.229554890","rc":[{"atl":[[1000,3.2]],"id":70003365}],"con":true,"img":false}]}
{"op":"mcm","clk":"11449636643","pt":1717312485652,"mc":[{"id":"1.229554890","rc":[{"atl":[[1000,3.2]],"id":70003367}],"con":true,"img":false}]}
{"op":"mcm","clk":"11449636656","pt":1717312485954,"mc":[{"id":"1.229554890","rc":[{"atl":[[1000,2.7]],"id":70003365}],"con":true,"img":false}]}
{"op":"mcm","clk":"11449636662","pt":1717312486160,"mc":[{"id":"1.229554890","rc":[{"atl":[[1000,2.7]],"id":70003367},{"atl":[[1000,0.85]],"id":70003365}],"con":true,"img":false}]}
{"op":"mcm","clk":"11449636664","pt":1717312486262,"mc":[{"id":"1.229554890","rc":[{"atl":[[7.2,1.85]],"id":70003365}],"con":true,"img":false}]}
{"op":"mcm","clk":"11449636674","pt":1717312486521,"mc":[{"id":"1.229554890","rc":[{"atl":[[1000,0.85]],"id":70003367}],"con":true,"img":false}]}
{"op":"mcm","clk":"11449636677","pt":1717312486623,"mc":[{"id":"1.229554890","rc":[{"atl":[[7.2,1.85]],"id":70003367}],"con":true,"img":false}]}
{"op":"mcm","clk":"11449637855","pt":1717312516060,"mc":[{"id":"1.229554890","rc":[{"atl":[[3.45,9.46]],"id":70003364},{"spn":2.59,"spf":"NaN","id":70003364}],"con":true,"img":false}]}
{"op":"mcm","clk":"11449637861","pt":1717312516261,"mc":[{"id":"1.229554890","rc":[{"atl":[[7.2,4.52]],"id":70003365}],"con":true,"img":false}]}
{"op":"mcm","clk":"11449637867","pt":1717312516569,"mc":[{"id":"1.229554890","rc":[{"atl":[[7.2,4.52]],"id":70003367}],"con":true,"img":false}]}
{"op":"mcm","clk":"11449639286","pt":1717312554827,"mc":[{"id":"1.229554890","rc":[{"atb":[[32,2.61],[21,0],[26,0]],"id":70003366},{"atl":[[520,0],[420,0]],"id":70003366},{"atb":[[2.58,0],[2.78,0],[2.68,0]],"id":70003367},{"atl":[[13.5,0],[9.4,0]],"id":70003367},{"atb":[[1.73,0],[1.63,0],[1.68,0]],"id":70003364},{"atl":[[4,0],[5,0]],"id":70003364},{"atb":[[2.58,0],[2.78,0],[2.68,0]],"id":70003365},{"atl":[[13.5,0],[9.4,0]],"id":70003365},{"atb":[[12,0],[9.8,0],[14.5,0]],"id":70003363},{"atl":[[330,0],[230,0]],"id":70003363}],"con":true,"img":false}]}
{"op":"mcm","clk":"11449639387","pt":1717312557602,"mc":[{"id":"1.229554890","rc":[{"atl":[[410,0],[510,0]],"id":70003366},{"atb":[[2.8,0],[2.6,0]],"id":70003367},{"atb":[[1.64,0],[1.74,0]],"id":70003364},{"atl":[[4.6,34.52],[3.95,0]],"id":70003364},{"atb":[[2.8,0],[2.6,0]],"id":70003365}],"con":true,"img":false}]}
{"op":"mcm","clk":"11449639392","pt":1717312557708,"mc":[{"id":"1.229554890","rc":[{"atl":[[690,2.61],[510,0.1]],"id":70003366},{"atb":[[2.42,77.95],[2.66,33]],"id":70003367},{"atb":[[1.57,195.14],[1.67,62.21]],"id":70003364},{"atb":[[2.42,74.71],[2.68,33]],"id":70003365}],"con":true,"img":false}]}
{"op":"mcm","clk":"11449639756","pt":1717312566697,"mc":[{"id":"1.229554890","rc":[{"atb":[[32,5.99],[21,10.45],[26,8.36]],"id":70003366},{"atl":[[520,0.4],[420,0.33]],"id":70003366},{"atb":[[2.58,132.31],[2.78,58.72],[2.68,124.44]],"id":70003367},{"atl":[[13.5,16.72],[9.4,16.58]],"id":70003367},{"atb":[[1.73,143.19],[1.63,331.84],[1.68,307.44]],"id":70003364},{"atl":[[4,46.45],[5,52.26]],"id":70003364},{"atb":[[2.58,132.31],[2.78,58.72],[2.68,157.45]],"id":70003365},{"atl":[[13.5,16.72],[9.4,16.58]],"id":70003365},{"atb":[[12,19],[9.8,23.75],[14.5,7.74]],"id":70003363},{"atl":[[330,0.63],[230,0.6]],"id":70003363}],"con":true,"img":false}]}
{"op":"mcm","clk":"11449642314","pt":1717312629421,"mc":[{"id":"1.229554890","rc":[{"atl":[[690,0],[510,0]],"id":70003366},{"spn":226.0,"spf":"NaN","id":70003366},{"atb":[[2.42,0],[2.66,0]],"id":70003367},{"spn":4.99,"spf":"NaN","id":70003367},{"atb":[[1.57,0],[1.67,0]],"id":70003364},{"atl":[[4.6,0],[3.95,42.37]],"id":70003364},{"spn":2.59,"spf":"NaN","id":70003364},{"atb":[[2.42,0],[2.68,124.44]],"id":70003365},{"spn":4.99,"spf":"NaN","id":70003365}],"con":true,"img":false}]}
{"op":"mcm","clk":"11449642317","pt":1717312629525,"mc":[{"id":"1.229554890","rc":[{"atl":[[410,0.1],[510,2.61]],"id":70003366},{"atb":[[2.8,33],[2.6,77.95]],"id":70003367},{"atb":[[1.64,195.14],[1.74,62.21]],"id":70003364},{"atb":[[2.8,33],[2.6,74.71]],"id":70003365}],"con":true,"img":false}]}
{"op":"mcm","clk":"11449643847","pt":1717312667445,"mc":[{"id":"1.229554890","rc":[{"atl":[[3.45,5.59]],"id":70003364}],"con":true,"img":false}]}
{"op":"mcm","clk":"11449644144","pt":1717312674248,"mc":[{"id":"1.229554890","rc":[{"atl":[[7.2,2.67]],"id":70003365}],"con":true,"img":false}]}
{"op":"mcm","clk":"11449644782","pt":1717312688969,"mc":[{"id":"1.229554890","rc":[{"atl":[[7.2,2.67]],"id":70003367}],"con":true,"img":false}]}
{"op":"mcm","clk":"11449645570","pt":1717312707948,"mc":[{"id":"1.229554890","rc":[{"spn":221.0,"spf":"NaN","id":70003366},{"spn":5.0,"spf":"NaN","id":70003367},{"atl":[[3.45,9.46]],"id":70003364},{"spn":2.59,"spf":"NaN","id":70003364},{"atl":[[1000,3.2]],"id":70003365},{"spn":5.0,"spf":"NaN","id":70003365}],"con":true,"img":false}]}
{"op":"mcm","clk":"11449645583","pt":1717312708102,"mc":[{"id":"1.229554890","rc":[{"atl":[[1000,3.2]],"id":70003367},{"atl":[[1000,2.7]],"id":70003365}],"con":true,"img":false}]}
{"op":"mcm","clk":"11449645592","pt":1717312708304,"mc":[{"id":"1.229554890","rc":[{"atl":[[1000,0.85]],"id":70003365}],"con":true,"img":false}]}
{"op":"mcm","clk":"11449645597","pt":1717312708408,"mc":[{"id":"1.229554890","rc":[{"atl":[[7.2,4.52]],"id":70003365}],"con":true,"img":false}]}
{"op":"mcm","clk":"11449645605","pt":1717312708614,"mc":[{"id":"1.229554890","rc":[{"atl":[[1000,2.7]],"id":70003367}],"con":true,"img":false}]}
{"op":"mcm","clk":"11449645614","pt":1717312708919,"mc":[{"id":"1.229554890","rc":[{"atl":[[1000,0.85]],"id":70003367}],"con":true,"img":false}]}
{"op":"mcm","clk":"11449645620","pt":1717312709022,"mc":[{"id":"1.229554890","rc":[{"atl":[[7.2,4.52]],"id":70003367}],"con":true,"img":false}]}
{"op":"mcm","clk":"11449646538","pt":1717312733369,"mc":[{"id":"1.229554890","rc":[{"atl":[[3.45,3.87]],"id":70003364}],"con":true,"img":false}]}
{"op":"mcm","clk":"11449647915","pt":1717312768716,"mc":[{"id":"1.229554890","rc":[{"atl":[[7.2,1.85]],"id":70003365}],"con":true,"img":false}]}
{"op":"mcm","clk":"11449649933","pt":1717312815750,"mc":[{"id":"1.229554890","rc":[{"atl":[[7.2,1.85]],"id":70003367}],"con":true,"img":false}]}
{"op":"mcm","clk":"11449651663","pt":1717312851507,"mc":[{"id":"1.229554890","rc":[{"atl":[[3.45,9.46]],"id":70003364}],"con":true,"img":false}]}
{"op":"mcm","clk":"11449651671","pt":1717312851712,"mc":[{"id":"1.229554890","rc":[{"atl":[[7.2,4.52]],"id":70003365}],"con":true,"img":false}]}
{"op":"mcm","clk":"11449651677","pt":1717312851816,"mc":[{"id":"1.229554890","rc":[{"atl":[[7.2,4.52]],"id":70003367}],"con":true,"img":false}]}
{"op":"mcm","clk":"11449652040","pt":1717312860343,"mc":[{"id":"1.229554890","rc":[{"atb":[[8,14.29]],"id":70003366},{"atb":[[1.26,155.9]],"id":70003367},{"atl":[[12,9.09]],"id":70003367},{"atl":[[6.6,17.86]],"id":70003364},{"atb":[[1.6,149.42]],"id":70003365},{"atl":[[13.5,24.72]],"id":70003365},{"atb":[[9.4,11.9]],"id":70003363}],"con":true,"img":false}]}
{"op":"mcm","clk":"11449653093","pt":1717312883469,"mc":[{"id":"1.229554890","rc":[{"atl":[[510,0]],"id":70003366}],"con":true,"img":false}]}
{"op":"mcm","clk":"11449653099","pt":1717312883572,"mc":[{"id":"1.229554890","rc":[{"atl":[[720,2.61]],"id":70003366}],"con":true,"img":false}]}
{"op":"mcm","clk":"11449653284","pt":1717312888651,"mc":[{"id":"1.229554890","rc":[{"atl":[[3.45,5.59]],"id":70003364}],"con":true,"img":false}]}
{"op":"mcm","clk":"11449653918","pt":1717312903395,"mc":[{"id":"1.229554890","rc":[{"atl":[[7.2,2.67]],"id":70003365}],"con":true,"img":false}]}
{"op":"mcm","clk":"11449654288","pt":1717312912674,"mc":[{"id":"1.229554890","rc":[{"atl":[[410,0]],"id":70003366},{"spn":226.0,"spf":"NaN","id":70003366}],"con":true,"img":false}]}
{"op":"mcm","clk":"11449654294","pt":1717312912783,"mc":[{"id":"1.229554890","rc":[{"atl":[[500,0.1]],"id":70003366}],"con":true,"img":false}]}
{"op":"mcm","clk":"11449654519","pt":1717312918485,"mc":[{"id":"1.229554890","rc":[{"atl":[[7.2,2.67]],"id":70003367}],"con":true,"img":false}]}
{"op":"mcm","clk":"11449655111","pt":1717312933382,"mc":[{"id":"1.229554890","rc":[{"atl":[[1000,3.2]],"id":70003367},{"atl":[[3.45,9.46]],"id":70003364},{"atl":[[1000,3.2]],"id":70003365}],"con":true,"img":false}]}
{"op":"mcm","clk":"11449655116","pt":1717312933586,"mc":[{"id":"1.229554890","rc":[{"atl":[[1000,2.7]],"id":70003367},{"atl":[[1000,2.7]],"id":70003365}],"con":true,"img":false}]}
{"op":"mcm","clk":"11449655128","pt":1717312933844,"mc":[{"id":"1.229554890","rc":[{"atl":[[1000,0.85]],"id":70003365}],"con":true,"img":false}]}
{"op":"mcm","clk":"11449655131","pt":1717312933945,"mc":[{"id":"1.229554890","rc":[{"atl":[[7.2,4.52]],"id":70003365}],"con":true,"img":false}]}
{"op":"mcm","clk":"11449655141","pt":1717312934150,"mc":[{"id":"1.229554890","rc":[{"atl":[[1000,0.85]],"id":70003367}],"con":true,"img":false}]}
{"op":"mcm","clk":"11449655148","pt":1717312934252,"mc":[{"id":"1.229554890","rc":[{"atl":[[7.2,4.52]],"id":70003367}],"con":true,"img":false}]}
{"op":"mcm","clk":"11449655610","pt":1717312947098,"mc":[{"id":"1.229554890","rc":[{"atb":[[1.73,48.45],[1.74,0]],"id":70003364},{"trd":[[1.73,189.48],[1.74,124.42]],"ltp":1.73,"tv":313.9,"id":70003364}],"con":true,"img":false}]}
{"op":"mcm","clk":"11449655957","pt":1717312955773,"mc":[{"id":"1.229554890","rc":[{"atb":[[32,2.61],[21,0],[26,0]],"id":70003366},{"atl":[[520,0],[420,0]],"id":70003366},{"atb":[[2.58,0],[2.78,0],[2.68,0]],"id":70003367},{"atl":[[13.5,0],[9.4,0]],"id":70003367},{"atb":[[1.73,0],[1.63,0],[1.68,0]],"id":70003364},{"atl":[[4,0],[5,0]],"id":70003364},{"atb":[[2.58,0],[2.78,0],[2.68,0]],"id":70003365},{"atl":[[13.5,8],[9.4,0]],"id":70003365},{"atb":[[12,0],[9.8,0],[14.5,0]],"id":70003363},{"atl":[[330,0],[230,0]],"id":70003363}],"con":true,"img":false}]}
{"op":"mcm","clk":"11449655980","pt":1717312956496,"mc":[{"id":"1.229554890","rc":[{"atl":[[720,0],[500,0]],"id":70003366},{"atl":[[11.5,12.03],[7.8,0]],"id":70003367},{"atb":[[1.41,247.98]],"id":70003364},{"atl":[[11.5,9.96],[7.8,0]],"id":70003365},{"atl":[[140,0.4],[150,0]],"id":70003363}],"con":true,"img":false}]}
{"op":"mcm","clk":"11449655986","pt":1717312956600,"mc":[{"id":"1.229554890","rc":[{"atl":[[620,0.1],[850,2.61]],"id":70003366},{"atl":[[9,8.25],[9.2,0]],"id":70003367},{"atb":[[1.64,0]],"id":70003364},{"atl":[[9,8.25],[9.2,0]],"id":70003365},{"atl":[[180,2.61],[120,0]],"id":70003363}],"con":true,"img":false}]}
{"op":"mcm","clk":"11449656120","pt":1717312960109,"mc":[{"id":"1.229554890","rc":[{"atl":[[3.7,0],[3.3,9.51]],"id":70003364}],"con":true,"img":false}]}
{"op":"mcm","clk":"11449656341","pt":1717312964996,"mc":[{"id":"1.229554890","rc":[{"atb":[[32,0]],"id":70003366},{"atb":[[15.5,0]],"id":70003363}],"con":true,"img":false}]}
{"op":"mcm","clk":"11449656346","pt":1717312965111,"mc":[{"id":"1.229554890","rc":[{"atb":[[40,2.61]],"id":70003366},{"atb":[[18.5,3.87]],"id":70003363}],"con":true,"img":false}]}
{"op":"mcm","clk":"11449656387","pt":1717312965929,"mc":[{"id":"1.229554890","rc":[{"atb":[[32,3.98],[21,12.34],[26,9.87]],"id":70003366},{"atl":[[520,0.29],[420,0.24]],"id":70003366},{"atb":[[2.58,156.3],[2.78,69.36],[2.68,146.99]],"id":70003367},{"atl":[[13.5,12.17],[9.4,12.08]],"id":70003367},{"atb":[[1.73,124.24],[1.63,287.93],[1.68,266.75]],"id":70003364},{"atl":[[4,55.68],[5,62.63]],"id":70003364},{"atb":[[2.58,156.3],[2.78,69.36],[2.68,146.99]],"id":70003365},{"atl":[[13.5,20.17],[9.4,12.08]],"id":70003365},{"atb":[[12,22.44],[9.8,28.06],[14.5,9.14]],"id":70003363},{"atl":[[330,0.46],[230,0.44]],"id":70003363}],"con":true,"img":false}]}
{"op":"mcm","clk":"11449656425","pt":1717312966509,"mc":[{"id":"1.229554890","rc":[{"atb":[[1.56,69.38]],"id":70003364}],"con":true,"img":false}]}
{"op":"mcm","clk":"11449656933","pt":1717312977310,"mc":[{"id":"1.229554890","rc":[{"atb":[[40,0]],"id":70003366},{"trd":[[40,5.23]],"ltp":40.0,"tv":5.23,"id":70003366},{"spn":2.51,"spf":"NaN","id":70003364},{"spn":79.25,"spf":"NaN","id":70003363}],"con":true,"img":false}]}
{"op":"mcm","clk":"11449656938","pt":1717312977515,"mc":[{"id":"1.229554890","rc":[{"atb":[[27,2.61],[28,0]],"id":70003366}],"con":true,"img":false}]}
{"op":"mcm","clk":"11449657322","pt":1717312989265,"mc":[{"id":"1.229554890","rc":[{"atb":[[29,2.34]],"id":70003366}],"con":true,"img":false}]}
{"op":"mcm","clk":"11449657409","pt":1717312991535,"mc":[{"id":"1.229554890","rc":[{"atl":[[620,0],[410,0.07]],"id":70003366}],"con":true,"img":false}]}
{"op":"mcm","clk":"11449657513","pt":1717312993772,"mc":[{"id":"1.229554890","rc":[{"atb":[[13.5,0]],"id":70003363}],"con":true,"img":false}]}
{"op":"mcm","clk":"11449657518","pt":1717312993874,"mc":[{"id":"1.229554890","rc":[{"atb":[[15.5,9.41]],"id":70003363}],"con":true,"img":false}]}
{"op":"mcm","clk":"11449657588","pt":1717312995065,"mc":[{"id":"1.229554890","rc":[{"atb":[[1.74,15.32]],"id":70003364}],"con":true,"img":false}]}
{"op":"mcm","clk":"11449657602","pt":1717312995272,"mc":[{"id":"1.229554890","rc":[{"atb":[[2.82,6.22]],"id":70003365}],"con":true,"img":false}]}
{"op":"mcm","clk":"11449657607","pt":1717312995373,"mc":[{"id":"1.229554890","rc":[{"atb":[[2.82,6.22]],"id":70003367}],"con":true,"img":false}]}
{"op":"mcm","clk":"11449657670","pt":1717312997261,"mc":[{"id":"1.229554890","rc":[{"atb":[[1.56,0]],"id":70003364}],"con":true,"img":false}]}
{"op":"mcm","clk":"11449657677","pt":1717312997356,"mc":[{"id":"1.229554890","rc":[{"atb":[[1.64,69.38]],"id":70003364}],"con":true,"img":false}]}
{"op":"mcm","clk":"11449658544","pt":1717313020101,"mc":[{"id":"1.229554890","rc":[{"atl":[[9.2,15.17]],"id":70003367},{"atl":[[9.2,14.58]],"id":70003365}],"con":true,"img":false}]}
{"op":"mcm","clk":"11449658555","pt":1717313020305,"mc":[{"id":"1.229554890","rc":[{"atl":[[11.5,0]],"id":70003367},{"atl":[[11.5,0]],"id":70003365}],"con":true,"img":false}]}
{"op":"mcm","clk":"11449658586","pt":1717313021286,"mc":[{"id":"1.229554890","rc":[{"atb":[[2.6,0]],"id":70003367},{"atb":[[2.6,0]],"id":70003365}],"con":true,"img":false}]}
{"op":"mcm","clk":"11449658591","pt":1717313021391,"mc":[{"id":"1.229554890","rc":[{"atb":[[2.8,110.96]],"id":70003367},{"atb":[[2.8,107.72]],"id":70003365}],"con":true,"img":false}]}
{"op":"mcm","clk":"11449659025","pt":1717313030795,"mc":[{"id":"1.229554890","rc":[{"atl":[[850,0]],"id":70003366}],"con":true,"img":false}]}
{"op":"mcm","clk":"11449659032","pt":1717313030902,"mc":[{"id":"1.229554890","rc":[{"atl":[[510,2.61]],"id":70003366}],"con":true,"img":false}]}
{"op":"mcm","clk":"11449659080","pt":1717313032081,"mc":[{"id":"1.229554890","rc":[{"atl":[[3.45,3.87]],"id":70003364}],"con":true,"img":false}]}
{"op":"mcm","clk":"11449659089","pt":1717313032292,"mc":[{"id":"1.229554890","rc":[{"atb":[[2.82,0]],"id":70003367},{"atb":[[2.82,0]],"id":70003365}],"con":true,"img":false}]}
{"op":"mcm","clk":"11449660229","pt":1717313059621,"mc":[{"id":"1.229554890","rc":[{"spn":221.0,"spf":"NaN","id":70003366},{"spn":2.52,"spf":"NaN","id":70003364},{"atb":[[1.65,153.85]],"id":70003365}],"con":true,"img":false}]}
{"op":"mcm","clk":"11449660236","pt":1717313059722,"mc":[{"id":"1.229554890","rc":[{"atb":[[1.6,0]],"id":70003365}],"con":true,"img":false}]}
{"op":"mcm","clk":"11449660357","pt":1717313062439,"mc":[{"id":"1.229554890","rc":[{"atb":[[2.8,112.17]],"id":70003367},{"atb":[[1.75,1.23]],"id":70003364},{"atb":[[2.8,108.99]],"id":70003365}],"con":true,"img":false}]}
{"op":"mcm","clk":"11449660616","pt":1717313070354,"mc":[{"id":"1.229554890","rc":[{"atl":[[7.2,1.85]],"id":70003365}],"con":true,"img":false}]}
{"op":"mcm","clk":"11449660622","pt":1717313070456,"mc":[{"id":"1.229554890","rc":[{"atb":[[2.84,6.16]],"id":70003365}],"con":true,"img":false}]}
{"op":"mcm","clk":"11449660626","pt":1717313070557,"mc":[{"id":"1.229554890","rc":[{"atb":[[2.84,6.16]],"id":70003367}],"con":true,"img":false}]}
{"op":"mcm","clk":"11449660636","pt":1717313070765,"mc":[{"id":"1.229554890","rc":[{"atb":[[2.8,110.96]],"id":70003367},{"atb":[[2.8,107.72]],"id":70003365}],"con":true,"img":false}]}
{"op":"mcm","clk":"11449660640","pt":1717313070863,"mc":[{"id":"1.229554890","rc":[{"atb":[[2.84,7.37]],"id":70003367},{"atb":[[2.84,7.43]],"id":70003365}],"con":true,"img":false}]}
{"op":"mcm","clk":"11449661463","pt":1717313091961,"mc":[{"id":"1.229554890","rc":[{"atl":[[7.2,1.85]],"id":70003367}],"con":true,"img":false}]}
{"op":"mcm","clk":"11449661496","pt":1717313092685,"mc":[{"id":"1.229554890","rc":[{"atl":[[3.3,0]],"id":70003364}],"con":true,"img":false}]}
{"op":"mcm","clk":"11449661504","pt":1717313092791,"mc":[{"id":"1.229554890","rc":[{"atl":[[3.25,9.51]],"id":70003364}],"con":true,"img":false}]}
{"op":"mcm","clk":"11449661633","pt":1717313095904,"mc":[{"id":"1.229554890","rc":[{"atl":[[9,0]],"id":70003367}],"con":true,"img":false}]}
{"op":"mcm","clk":"11449661636","pt":1717313095984,"mc":[{"id":"1.229554890","rc":[{"atl":[[8.8,8.25]],"id":70003367}],"con":true,"img":false}]}
{"op":"mcm","clk":"11449661679","pt":1717313097066,"mc":[{"id":"1.229554890","rc":[{"atb":[[2.8,74.71]],"id":70003365}],"con":true,"img":false}]}
{"op":"mcm","clk":"11449661681","pt":1717313097166,"mc":[{"id":"1.229554890","rc":[{"atb":[[2.9,33]],"id":70003365}],"con":true,"img":false}]}
{"op":"mcm","clk":"11449661712","pt":1717313097851,"mc":[{"id":"1.229554890","rc":[{"atb":[[2.84,6.16]],"id":70003365}],"con":true,"img":false}]}
{"op":"mcm","clk":"11449661723","pt":1717313098000,"mc":[{"id":"1.229554890","rc":[{"atb":[[2.9,34.27]],"id":70003365}],"con":true,"img":false}]}
{"op":"mcm","clk":"11449662224","pt":1717313105799,"mc":[{"id":"1.229554890","rc":[{"atb":[[29,0]],"id":70003366}],"con":true,"img":false}]}
{"op":"mcm","clk":"11449662233","pt":1717313105905,"mc":[{"id":"1.229554890","rc":[{"atb":[[34,2.34]],"id":70003366}],"con":true,"img":false}]}
{"op":"mcm","clk":"11449663517","pt":1717313129339,"mc":[{"id":"1.229554890","rc":[{"spn":222.0,"spf":"NaN","id":70003366},{"spn":5.02,"spf":"NaN","id":70003367},{"atb":[[1.73,0],[1.74,0],[1.75,0]],"id":70003364},{"trd":[[1.73,437.97],[1.74,155.06],[1.75,2.47]],"ltp":1.73,"tv":595.5,"id":70003364},{"atl":[[1.73,16.15]],"id":70003364},{"spn":1.7,"spf":"NaN","id":70003364},{"spn":5.05,"spf":"NaN","id":70003365}],"con":true,"img":false}]}
{"op":"mcm","clk":"11449663720","pt":1717313134332,"mc":[{"id":"1.229554890","rc":[{"atl":[[3.45,0]],"id":70003364}],"con":true,"img":false}]}
{"op":"mcm","clk":"11449663935","pt":1717313139218,"mc":[{"id":"1.229554890","rc":[{"atl":[[1.73,0]],"id":70003364}],"con":true,"img":false}]}
{"op":"mcm","clk":"11449663961","pt":1717313139841,"mc":[{"id":"1.229554890","rc":[{"atb":[[34,0]],"id":70003366},{"atl":[[3.2,1.01]],"id":70003364}],"con":true,"img":false}]}
{"op":"mcm","clk":"11449663966","pt":1717313139946,"mc":[{"id":"1.229554890","rc":[{"atb":[[28,2.34]],"id":70003366}],"con":true,"img":false}]}
{"op":"mcm","clk":"11449664088","pt":1717313143153,"mc":[{"id":"1.229554890","rc":[{"atb":[[32,0],[21,0],[26,0]],"id":70003366},{"atl":[[520,0],[420,0]],"id":70003366},{"atb":[[2.58,0],[2.78,0],[2.68,0]],"id":70003367},{"atl":[[13.5,0],[9.4,0]],"id":70003367},{"atb":[[1.63,0],[1.68,0]],"id":70003364},{"atl":[[4,0],[5,0]],"id":70003364},{"atb":[[2.58,0],[2.78,0],[2.68,0]],"id":70003365},{"atl":[[13.5,8],[9.4,0]],"id":70003365},{"atb":[[12,0],[9.8,0],[14.5,0]],"id":70003363},{"atl":[[330,0],[230,0]],"id":70003363}],"con":true,"img":false}]}
{"op":"mcm","clk":"11449664118","pt":1717313143669,"mc":[{"id":"1.229554890","rc":[{"atb":[[27,0]],"id":70003366},{"atl":[[410,0],[440,0.07],[510,0]],"id":70003366},{"atb":[[2.8,33]],"id":70003367},{"atl":[[9.2,0],[11.5,12.03]],"id":70003367},{"atb":[[2.8,0]],"id":70003365},{"atl":[[9.2,0],[12,9.96]],"id":70003365}],"con":true,"img":false}]}
{"op":"mcm","clk":"11449664121","pt":1717313143727,"mc":[{"id":"1.229554890","rc":[{"atb":[[24,2.61]],"id":70003366},{"atl":[[590,2.61]],"id":70003366},{"atb":[[2.54,77.95]],"id":70003367},{"atb":[[2.62,74.71]],"id":70003365}],"con":true,"img":false}]}
{"op":"mcm","clk":"11449664332","pt":1717313149153,"mc":[{"id":"1.229554890","rc":[{"atl":[[7.2,0]],"id":70003365}],"con":true,"img":false}]}
{"op":"mcm","clk":"11449664516","pt":1717313153380,"mc":[{"id":"1.229554890","rc":[{"atb":[[1.64,0]],"id":70003364}],"con":true,"img":false}]}
{"op":"mcm","clk":"11449664519","pt":1717313153435,"mc":[{"id":"1.229554890","rc":[{"atb":[[1.56,69.38]],"id":70003364}],"con":true,"img":false}]}
{"op":"mcm","clk":"11449664932","pt":1717313163162,"mc":[{"id":"1.229554890","rc":[{"atl":[[1.83,14.57]],"id":70003364}],"con":true,"img":false}]}
{"op":"mcm","clk":"11449664941","pt":1717313163474,"mc":[{"id":"1.229554890","rc":[{"atb":[[2.84,1.21]],"id":70003367},{"atb":[[2.84,0]],"id":70003365}],"con":true,"img":false}]}
{"op":"mcm","clk":"11449664960","pt":1717313163890,"mc":[{"id":"1.229554890","rc":[{"atb":[[2.84,0]],"id":70003367}],"con":true,"img":false}]}
{"op":"mcm","clk":"11449664964","pt":1717313163984,"mc":[{"id":"1.229554890","rc":[{"atb":[[2.8,34.21]],"id":70003367}],"con":true,"img":false}]}
{"op":"mcm","clk":"11449664971","pt":1717313164190,"mc":[{"id":"1.229554890","rc":[{"atl":[[7.2,0]],"id":70003367}],"con":true,"img":false}]}
{"op":"mcm","clk":"11449665020","pt":1717313165587,"mc":[{"id":"1.229554890","rc":[{"atb":[[38,4],[24,15.51],[29,10.59]],"id":70003366},{"atl":[[550,0.14],[450,0.11]],"id":70003366},{"atb":[[2.86,79.74],[2.66,178.7],[2.76,168.55]],"id":70003367},{"atl":[[9.8,5.88],[14.5,5.75]],"id":70003367},{"atb":[[1.6,287.75],[1.65,113.83]],"id":70003364},{"atl":[[2.8,70.72],[2.6,53.04]],"id":70003364},{"atb":[[2.86,79.74],[2.66,178.7],[2.76,168.55]],"id":70003365},{"atl":[[9.8,5.88],[14.5,5.75]],"id":70003365},{"atb":[[12,26.96],[9.8,33.7],[14.5,10.98]],"id":70003363},{"atl":[[330,0.23],[230,0.22]],"id":70003363}],"con":true,"img":false}]}
{"op":"mcm","clk":"11449665058","pt":1717313166258,"mc":[{"id":"1.229554890","rc":[{"atb":[[2.8,33]],"id":70003367}],"con":true,"img":false}]}
{"op":"mcm","clk":"11449665061","pt":1717313166358,"mc":[{"id":"1.229554890","rc":[{"atb":[[2.86,80.95]],"id":70003367}],"con":true,"img":false}]}
{"op":"mcm","clk":"11449666007","pt":1717313188198,"mc":[{"id":"1.229554890","rc":[{"atb":[[2.88,2.86]],"id":70003367},{"atb":[[2.92,2.85]],"id":70003365},{"atb":[[16,2.84]],"id":70003363}],"con":true,"img":false}]}
{"op":"mcm","clk":"11449666277","pt":1717313193712,"mc":[{"id":"1.229554890","rc":[{"spn":239.0,"spf":"NaN","id":70003366},{"spn":5.84,"spf":"NaN","id":70003367},{"atl":[[2.02,15.53],[3.25,0]],"id":70003364},{"spn":1.74,"spf":"NaN","id":70003364},{"spn":5.96,"spf":"NaN","id":70003365}],"con":true,"img":false}]}
{"op":"mcm","clk":"11449666326","pt":1717313194901,"mc":[{"id":"1.229554890","rc":[{"atb":[[1.56,0]],"id":70003364}],"con":true,"img":false}]}
{"op":"mcm","clk":"11449666329","pt":1717313195033,"mc":[{"id":"1.229554890","rc":[{"atb":[[1.61,69.38]],"id":70003364}],"con":true,"img":false}]}
{"op":"mcm","clk":"11449666402","pt":1717313196907,"mc":[{"id":"1.229554890","rc":[{"atb":[[2.8,0]],"id":70003367}],"con":true,"img":false}]}
{"op":"mcm","clk":"11449666408","pt":1717313197009,"mc":[{"id":"1.229554890","rc":[{"atb":[[2.88,35.87]],"id":70003367}],"con":true,"img":false}]}
{"op":"mcm","clk":"11449666434","pt":1717313197525,"mc":[{"id":"1.229554890","rc":[{"atb":[[2.86,79.74]],"id":70003367}],"con":true,"img":false}]}
{"op":"mcm","clk":"11449666437","pt":1717313197624,"mc":[{"id":"1.229554890","rc":[{"atb":[[2.88,37.08]],"id":70003367}],"con":true,"img":false}]}
{"op":"mcm","clk":"11449666734","pt":1717313204332,"mc":[{"id":"1.229554890","rc":[{"atb":[[28,0]],"id":70003366}],"con":true,"img":false}]}
{"op":"mcm","clk":"11449666740","pt":1717313204433,"mc":[{"id":"1.229554890","rc":[{"atb":[[30,2.34]],"id":70003366}],"con":true,"img":false}]}
{"op":"mcm","clk":"11449666791","pt":1717313205306,"mc":[{"id":"1.229554890","rc":[{"atl":[[9,0]],"id":70003365}],"con":true,"img":false}]}
{"op":"mcm","clk":"11449666798","pt":1717313205413,"mc":[{"id":"1.229554890","rc":[{"atl":[[9.4,8.25]],"id":70003365}],"con":true,"img":false}]}
{"op":"mcm","clk":"11449667237","pt":1717313213645,"mc":[{"id":"1.229554890","rc":[{"atb":[[2.9,40.24]],"id":70003365}],"con":true,"img":false}]}
{"op":"mcm","clk":"11449667243","pt":1717313213798,"mc":[{"id":"1.229554890","rc":[{"atb":[[2.9,5.96]],"id":70003367}],"con":true,"img":false}]}
{"op":"mcm","clk":"11449667262","pt":1717313214313,"mc":[{"id":"1.229554890","rc":[{"atb":[[2.88,35.87]],"id":70003367}],"con":true,"img":false}]}
{"op":"mcm","clk":"11449667267","pt":1717313214412,"mc":[{"id":"1.229554890","rc":[{"atb":[[2.88,33],[2.9,7.17]],"id":70003367}],"con":true,"img":false}]}
{"op":"mcm","clk":"11449667277","pt":1717313214524,"mc":[{"id":"1.229554890","rc":[{"atb":[[2.92,2.86]],"id":70003367}],"con":true,"img":false}]}
{"op":"mcm","clk":"11449667326","pt":1717313215349,"mc":[{"id":"1.229554890","rc":[{"atb":[[38,0],[24,2.61],[29,0]],"id":70003366},{"atl":[[550,0],[450,0]],"id":70003366},{"atb":[[2.86,0],[2.66,0],[2.76,0]],"id":70003367},{"atl":[[9.8,0],[14.5,0]],"id":70003367},{"atb":[[1.6,0],[1.65,0]],"id":70003364},{"atl":[[2.8,0],[2.6,0]],"id":70003364},{"atb":[[2.86,0],[2.66,0],[2.76,0]],"id":70003365},{"atl":[[9.8,0],[14.5,0]],"id":70003365},{"atb":[[12,0],[9.8,0],[14.5,0]],"id":70003363},{"atl":[[330,0],[230,0]],"id":70003363}],"con":true,"img":false}]}
{"op":"mcm","clk":"11449667342","pt":1717313215614,"mc":[{"id":"1.229554890","rc":[{"atl":[[2.02,0]],"id":70003364},{"atb":[[2.92,0]],"id":70003365},{"atb":[[16,0]],"id":70003363}],"con":true,"img":false}]}
{"op":"mcm","clk":"11449667351","pt":1717313215726,"mc":[{"id":"1.229554890","rc":[{"atl":[[2.14,15.53]],"id":70003364}],"con":true,"img":false}]}
{"op":"mcm","clk":"11449667376","pt":1717313216135,"mc":[{"id":"1.229554890","rc":[{"atl":[[2.18,14.39]],"id":70003364}],"con":true,"img":false}]}
{"op":"mcm","clk":"11449667380","pt":1717313216237,"mc":[{"id":"1.229554890","rc":[{"atl":[[2.14,0]],"id":70003364}],"con":true,"img":false}]}
{"op":"mcm","clk":"11449667710","pt":1717313222916,"mc":[{"id":"1.229554890","rc":[{"atl":[[9.2,0.92]],"id":70003365}],"con":true,"img":false}]}
{"op":"mcm","clk":"11449667805","pt":1717313225330,"mc":[{"id":"1.229554890","rc":[{"atb":[[1.61,0]],"id":70003364}],"con":true,"img":false}]}
{"op":"mcm","clk":"11449667811","pt":1717313225432,"mc":[{"id":"1.229554890","rc":[{"atb":[[1.56,69.38]],"id":70003364}],"con":true,"img":false}]}
{"op":"mcm","clk":"11449668017","pt":1717313230061,"mc":[{"id":"1.229554890","rc":[{"atb":[[32,4.78],[21,14.83],[26,11.86]],"id":70003366},{"atl":[[520,0.15],[420,0.12]],"id":70003366},{"atb":[[2.86,79.74],[2.66,178.7],[2.76,168.55]],"id":70003367},{"atl":[[9.8,5.88],[14.5,5.75]],"id":70003367},{"atb":[[1.56,201.52],[1.51,338.53]],"id":70003364},{"atl":[[2.4,60.62],[2.6,79.56]],"id":70003364},{"atb":[[2.86,79.74],[2.66,178.7],[2.76,168.55]],"id":70003365},{"atl":[[9.8,5.88],[14.5,5.75]],"id":70003365},{"atb":[[12,26.96],[9.8,33.7],[14.5,10.98]],"id":70003363},{"atl":[[330,0.23],[230,0.22]],"id":70003363}],"con":true,"img":false}]}
{"op":"mcm","clk":"11449668032","pt":1717313230222,"mc":[{"id":"1.229554890","rc":[{"atb":[[2.92,2.85]],"id":70003365},{"atb":[[16,2.84]],"id":70003363}],"con":true,"img":false}]}
{"op":"mcm","clk":"11449668291","pt":1717313235432,"mc":[{"id":"1.229554890","rc":[{"atl":[[9.4,0]],"id":70003365}],"con":true,"img":false}]}
{"op":"mcm","clk":"11449668298","pt":1717313235569,"mc":[{"id":"1.229554890","rc":[{"atl":[[10,8.25]],"id":70003365}],"con":true,"img":false}]}
{"op":"mcm","clk":"11449668693","pt":1717313242137,"mc":[{"id":"1.229554890","rc":[{"atl":[[2.18,0]],"id":70003364}],"con":true,"img":false}]}
{"op":"mcm","clk":"11449668698","pt":1717313242236,"mc":[{"id":"1.229554890","rc":[{"atl":[[1.93,14.39]],"id":70003364}],"con":true,"img":false}]}
{"op":"mcm","clk":"11449669088","pt":1717313251350,"mc":[{"id":"1.229554890","rc":[{"atl":[[9.2,0]],"id":70003365}],"con":true,"img":false}]}
{"op":"mcm","clk":"11449669366","pt":1717313257591,"mc":[{"id":"1.229554890","rc":[{"atl":[[440,0]],"id":70003366},{"spn":226.0,"spf":"NaN","id":70003366},{"spn":5.86,"spf":"NaN","id":70003367},{"spn":1.69,"spf":"NaN","id":70003364},{"spn":6.36,"spf":"NaN","id":70003365}],"con":true,"img":false}]}
{"op":"mcm","clk":"11449669373","pt":1717313257645,"mc":[{"id":"1.229554890","rc":[{"atl":[[410,0.07]],"id":70003366}],"con":true,"img":false}]}
{"op":"mcm","clk":"11449669624","pt":1717313263076,"mc":[{"id":"1.229554890","rc":[{"atb":[[2.9,7.23]],"id":70003365}],"con":true,"img":false}]}
{"op":"mcm","clk":"11449669634","pt":1717313263179,"mc":[{"id":"1.229554890","rc":[{"atb":[[3,33]],"id":70003365}],"con":true,"img":false}]}
{"op":"mcm","clk":"11449669659","pt":1717313263485,"mc":[{"id":"1.229554890","rc":[{"atb":[[2.9,5.96]],"id":70003365}],"con":true,"img":false}]}
{"op":"mcm","clk":"11449669668","pt":1717313263585,"mc":[{"id":"1.229554890","rc":[{"atb":[[3,34.27]],"id":70003365}],"con":true,"img":false}]}
{"op":"mcm","clk":"11449669698","pt":1717313263894,"mc":[{"id":"1.229554890","rc":[{"atb":[[2.92,0]],"id":70003365}],"con":true,"img":false}]}
{"op":"mcm","clk":"11449669702","pt":1717313263995,"mc":[{"id":"1.229554890","rc":[{"atb":[[3.05,2.85]],"id":70003365}],"con":true,"img":false}]}
{"op":"mcm","clk":"11449670025","pt":1717313270894,"mc":[{"id":"1.229554890","rc":[{"atb":[[30,0]],"id":70003366}],"con":true,"img":false}]}
{"op":"mcm","clk":"11449670030","pt":1717313270998,"mc":[{"id":"1.229554890","rc":[{"atb":[[34,2.34]],"id":70003366}],"con":true,"img":false}]}
{"op":"mcm","clk":"11449670066","pt":1717313271972,"mc":[{"id":"1.229554890","rc":[{"atl":[[1.93,0]],"id":70003364}],"con":true,"img":false}]}
{"op":"mcm","clk":"11449670068","pt":1717313272077,"mc":[{"id":"1.229554890","rc":[{"atl":[[1.92,14.39]],"id":70003364}],"con":true,"img":false}]}
{"op":"mcm","clk":"11449670104","pt":1717313273012,"mc":[{"id":"1.229554890","rc":[{"atb":[[32,0],[21,0],[26,0]],"id":70003366},{"atl":[[520,0],[420,0]],"id":70003366},{"atb":[[2.86,0],[2.66,0],[2.76,0]],"id":70003367},{"atl":[[9.8,0],[14.5,0]],"id":70003367},{"atb":[[1.56,69.38],[1.51,0]],"id":70003364},{"atl":[[2.4,0],[2.6,0]],"id":70003364},{"atb":[[2.86,0],[2.66,0],[2.76,0]],"id":70003365},{"atl":[[9.8,0],[14.5,0]],"id":70003365},{"atb":[[12,0],[9.8,0],[14.5,0]],"id":70003363},{"atl":[[330,0],[230,0]],"id":70003363}],"con":true,"img":false}]}
{"op":"mcm","clk":"11449670124","pt":1717313273432,"mc":[{"id":"1.229554890","rc":[{"atb":[[16,0]],"id":70003363}],"con":true,"img":false}]}
{"op":"mcm","clk":"11449670170","pt":1717313274208,"mc":[{"id":"1.229554890","rc":[{"atl":[[590,0],[410,0],[510,0.06]],"id":70003366},{"atl":[[1.92,0]],"id":70003364}],"con":true,"img":false}]}
{"op":"mcm","clk":"11449670185","pt":1717313274314,"mc":[{"id":"1.229554890","rc":[{"atl":[[690,2.61]],"id":70003366},{"atl":[[2.08,14.39]],"id":70003364}],"con":true,"img":false}]}
{"op":"mcm","clk":"11449670238","pt":1717313275296,"mc":[{"id":"1.229554890","rc":[{"atl":[[2.08,0]],"id":70003364}],"con":true,"img":false}]}
{"op":"mcm","clk":"11449670244","pt":1717313275400,"mc":[{"id":"1.229554890","rc":[{"atl":[[2.1,14.39]],"id":70003364}],"con":true,"img":false}]}
{"op":"mcm","clk":"11449670476","pt":1717313280391,"mc":[{"id":"1.229554890","rc":[{"atl":[[140,0]],"id":70003363}],"con":true,"img":false}]}
{"op":"mcm","clk":"11449670481","pt":1717313280493,"mc":[{"id":"1.229554890","rc":[{"atl":[[150,0.4]],"id":70003363}],"con":true,"img":false}]}
{"op":"mcm","clk":"11449670915","pt":1717313288011,"mc":[{"id":"1.229554890","rc":[{"atb":[[2.9,1.21]],"id":70003367},{"atb":[[2.9,0]],"id":70003365}],"con":true,"img":false}]}
{"op":"mcm","clk":"11449670922","pt":1717313288113,"mc":[{"id":"1.229554890","rc":[{"atb":[[2.92,0]],"id":70003367},{"atb":[[3.05,0]],"id":70003365}],"con":true,"img":false}]}
{"op":"mcm","clk":"11449670946","pt":1717313288727,"mc":[{"id":"1.229554890","rc":[{"atb":[[2.9,0]],"id":70003367}],"con":true,"img":false}]}
{"op":"mcm","clk":"11449670951","pt":1717313288829,"mc":[{"id":"1.229554890","rc":[{"atb":[[2.88,34.21]],"id":70003367}],"con":true,"img":false}]}
{"op":"mcm","clk":"11449670981","pt":1717313289802,"mc":[{"id":"1.229554890","rc":[{"atl":[[9.8,0.78]],"id":70003365}],"con":true,"img":false}]}
{"op":"mcm","clk":"11449671001","pt":1717313290420,"mc":[{"id":"1.229554890","rc":[{"atl":[[9.8,0.57]],"id":70003365}],"con":true,"img":false}]}
{"op":"mcm","clk":"11449671034","pt":1717313291048,"mc":[{"id":"1.229554890","rc":[{"atb":[[38,4],[24,15.51],[29,10.59]],"id":70003366},{"atl":[[550,0.14],[450,0.11]],"id":70003366},{"atb":[[2.86,79.74],[2.66,178.7],[2.76,168.55]],"id":70003367},{"atl":[[9.8,5.88],[14.5,5.75]],"id":70003367},{"atb":[[1.56,201.52],[1.51,338.53]],"id":70003364},{"atl":[[2.4,60.62],[2.6,79.56]],"id":70003364},{"atb":[[2.86,79.74],[2.66,178.7],[2.76,168.55]],"id":70003365},{"atl":[[9.8,6.45],[14.5,5.75]],"id":70003365},{"atb":[[12,26.96],[9.8,33.7],[14.5,10.98]],"id":70003363},{"atl":[[330,0.23],[230,0.22]],"id":70003363}],"con":true,"img":false}]}
{"op":"mcm","clk":"11449671074","pt":1717313291614,"mc":[{"id":"1.229554890","rc":[{"atl":[[8.6,0.78]],"id":70003367}],"con":true,"img":false}]}
{"op":"mcm","clk":"11449671078","pt":1717313291715,"mc":[{"id":"1.229554890","rc":[{"atb":[[2.9,2.86]],"id":70003367}],"con":true,"img":false}]}
{"op":"mcm","clk":"11449671116","pt":1717313292232,"mc":[{"id":"1.229554890","rc":[{"atl":[[8.6,0.58]],"id":70003367}],"con":true,"img":false}]}
{"op":"mcm","clk":"11449672105","pt":1717313312952,"mc":[{"id":"1.229554890","rc":[{"atl":[[2.1,0]],"id":70003364}],"con":true,"img":false}]}
{"op":"mcm","clk":"11449672111","pt":1717313313048,"mc":[{"id":"1.229554890","rc":[{"atl":[[1.92,14.39]],"id":70003364}],"con":true,"img":false}]}
{"op":"mcm","clk":"11449672405","pt":1717313318845,"mc":[{"id":"1.229554890","rc":[{"atl":[[510,0]],"id":70003366},{"spn":244.0,"spf":"NaN","id":70003366},{"spn":5.75,"spf":"NaN","id":70003367},{"spn":6.4,"spf":"NaN","id":70003365},{"spn":84.25,"spf":"NaN","id":70003363}],"con":true,"img":false}]}
{"op":"mcm","clk":"11449672413","pt":1717313318946,"mc":[{"id":"1.229554890","rc":[{"atl":[[440,0.06]],"id":70003366}],"con":true,"img":false}]}
{"op":"mcm","clk":"11449672558","pt":1717313321563,"mc":[{"id":"1.229554890","rc":[{"atl":[[1.92,0]],"id":70003364}],"con":true,"img":false}]}
{"op":"mcm","clk":"11449672561","pt":1717313321665,"mc":[{"id":"1.229554890","rc":[{"atl":[[1.93,14.39]],"id":70003364}],"con":true,"img":false}]}
{"op":"mcm","clk":"11449672802","pt":1717313325529,"mc":[{"id":"1.229554890","rc":[{"atb":[[2.9,5.96]],"id":70003365}],"con":true,"img":false}]}
{"op":"mcm","clk":"11449672812","pt":1717313325632,"mc":[{"id":"1.229554890","rc":[{"atb":[[3.05,2.85]],"id":70003365}],"con":true,"img":false}]}
{"op":"mcm","clk":"11449672819","pt":1717313325734,"mc":[{"id":"1.229554890","rc":[{"atb":[[2.9,8.82]],"id":70003367}],"con":true,"img":false}]}
{"op":"mcm","clk":"11449672869","pt":1717313326551,"mc":[{"id":"1.229554890","rc":[{"atb":[[2.88,33]],"id":70003367}],"con":true,"img":false}]}
{"op":"mcm","clk":"11449672874","pt":1717313326656,"mc":[{"id":"1.229554890","rc":[{"atb":[[2.9,10.03]],"id":70003367}],"con":true,"img":false}]}
{"op":"mcm","clk":"11449673048","pt":1717313329388,"mc":[{"id":"1.229554890","rc":[{"atb":[[38,0],[24,2.61],[29,0]],"id":70003366},{"atl":[[550,0],[450,0]],"id":70003366},{"atb":[[2.86,0],[2.66,0],[2.76,0]],"id":70003367},{"atl":[[9.8,0],[14.5,0]],"id":70003367},{"atb":[[1.56,69.38],[1.51,0]],"id":70003364},{"atl":[[2.4,0],[2.6,0]],"id":70003364},{"atb":[[2.86,0],[2.66,0],[2.76,0]],"id":70003365},{"atl":[[9.8,0.57],[14.5,0]],"id":70003365},{"atb":[[12,0],[9.8,0],[14.5,0]],"id":70003363},{"atl":[[330,0],[230,0]],"id":70003363}],"con":true,"img":false}]}
{"op":"mcm","clk":"11449673083","pt":1717313329956,"mc":[{"id":"1.229554890","rc":[{"atl":[[440,0]],"id":70003366},{"atl":[[8.6,0]],"id":70003367},{"atl":[[1.93,0]],"id":70003364}],"con":true,"img":false}]}
{"op":"mcm","clk":"11449673090","pt":1717313330059,"mc":[{"id":"1.229554890","rc":[{"atl":[[520,0.06]],"id":70003366},{"atl":[[1000,1.43]],"id":70003367},{"atl":[[2.06,14.39]],"id":70003364}],"con":true,"img":false}]}
{"op":"mcm","clk":"11449673445","pt":1717313336693,"mc":[{"id":"1.229554890","rc":[{"atb":[[24,0]],"id":70003366}],"con":true,"img":false}]}
{"op":"mcm","clk":"11449673451","pt":1717313336745,"mc":[{"id":"1.229554890","rc":[{"atb":[[26,2.61]],"id":70003366}],"con":true,"img":false}]}
{"op":"mcm","clk":"11449673662","pt":1717313340763,"mc":[{"id":"1.229554890","rc":[{"atb":[[38,4],[24,12.89],[29,10.59]],"id":70003366},{"atl":[[550,0.14],[450,0.11]],"id":70003366},{"atb":[[2.86,79.74],[2.66,178.7],[2.76,168.55]],"id":70003367},{"atl":[[9.8,5.88],[14.5,5.75]],"id":70003367},{"atb":[[1.56,201.52],[1.51,338.53]],"id":70003364},{"atl":[[2.4,60.62],[2.6,79.56]],"id":70003364},{"atb":[[2.86,79.74],[2.66,178.7],[2.76,168.55]],"id":70003365},{"atl":[[9.8,6.45],[14.5,5.75]],"id":70003365},{"atb":[[12,26.96],[9.8,33.7],[14.5,10.98]],"id":70003363},{"atl":[[330,0.23],[230,0.22]],"id":70003363}],"con":true,"img":false}]}
{"op":"mcm","clk":"11449673707","pt":1717313341485,"mc":[{"id":"1.229554890","rc":[{"atl":[[1000,0.85]],"id":70003367}],"con":true,"img":false}]}
{"op":"mcm","clk":"11449673713","pt":1717313341589,"mc":[{"id":"1.229554890","rc":[{"atl":[[8.6,0.58]],"id":70003367}],"con":true,"img":false}]}
{"op":"mcm","clk":"11449675111","pt":1717313365178,"mc":[{"id":"1.229554890","rc":[{"atl":[[2.06,0]],"id":70003364}],"con":true,"img":false}]}
{"op":"mcm","clk":"11449675118","pt":1717313365282,"mc":[{"id":"1.229554890","rc":[{"atl":[[1.92,14.39]],"id":70003364}],"con":true,"img":false}]}
{"op":"mcm","clk":"11449675273","pt":1717313368289,"mc":[{"id":"1.229554890","rc":[{"atl":[[520,0]],"id":70003366}],"con":true,"img":false}]}
{"op":"mcm","clk":"11449675279","pt":1717313368389,"mc":[{"id":"1.229554890","rc":[{"atl":[[440,0.06]],"id":70003366}],"con":true,"img":false}]}
{"op":"mcm","clk":"11449676058","pt":1717313380617,"mc":[{"id":"1.229554890","rc":[{"atb":[[34,0]],"id":70003366},{"spn":239.0,"spf":"NaN","id":70003366},{"spn":6.42,"spf":"NaN","id":70003365}],"con":true,"img":false}]}
{"op":"mcm","clk":"11449676073","pt":1717313380821,"mc":[{"id":"1.229554890","rc":[{"atb":[[36,2.34]],"id":70003366}],"con":true,"img":false}]}
{"op":"mcm","clk":"11449676849","pt":1717313394038,"mc":[{"id":"1.229554890","rc":[{"atl":[[690,0]],"id":70003366}],"con":true,"img":false}]}
{"op":"mcm","clk":"11449676858","pt":1717313394142,"mc":[{"id":"1.229554890","rc":[{"atl":[[540,2.61]],"id":70003366}],"con":true,"img":false}]}
{"op":"mcm","clk":"11449676918","pt":1717313395016,"mc":[{"id":"1.229554890","rc":[{"atl":[[9.6,14.64],[11.5,0]],"id":70003367}],"con":true,"img":false}]}
{"op":"mcm","clk":"11449676965","pt":1717313396142,"mc":[{"id":"1.229554890","rc":[{"atb":[[2.88,0],[2.54,0]],"id":70003367},{"atl":[[10,0]],"id":70003365}],"con":true,"img":false}]}
{"op":"mcm","clk":"11449676970","pt":1717313396245,"mc":[{"id":"1.229554890","rc":[{"atb":[[2.9,43.04],[2.78,77.95]],"id":70003367},{"atl":[[9.6,8.25]],"id":70003365}],"con":true,"img":false}]}
{"op":"mcm","clk":"11449676999","pt":1717313396710,"mc":[{"id":"1.229554890","rc":[{"atl":[[9.8,5.88]],"id":70003365}],"con":true,"img":false}]}
{"op":"mcm","clk":"11449677006","pt":1717313396814,"mc":[{"id":"1.229554890","rc":[{"atl":[[9.4,0.57]],"id":70003365}],"con":true,"img":false}]}
{"op":"mcm","clk":"11449677028","pt":1717313397222,"mc":[{"id":"1.229554890","rc":[{"atb":[[2.62,0]],"id":70003365}],"con":true,"img":false}]}
{"op":"mcm","clk":"11449677034","pt":1717313397326,"mc":[{"id":"1.229554890","rc":[{"atb":[[2.88,74.71]],"id":70003365}],"con":true,"img":false}]}
{"op":"mcm","clk":"11449677171","pt":1717313399844,"mc":[{"id":"1.229554890","rc":[{"atb":[[26,0]],"id":70003366}],"con":true,"img":false}]}
{"op":"mcm","clk":"11449677180","pt":1717313399946,"mc":[{"id":"1.229554890","rc":[{"atb":[[30,2.61]],"id":70003366}],"con":true,"img":false}]}
{"op":"mcm","clk":"11449677382","pt":1717313402185,"mc":[{"id":"1.229554890","rc":[{"atl":[[9.2,0.92]],"id":70003365}],"con":true,"img":false}]}
{"op":"mcm","clk":"11449677466","pt":1717313402969,"mc":[{"id":"1.229554890","rc":[{"atb":[[2.9,0]],"id":70003365}],"con":true,"img":false}]}
{"op":"mcm","clk":"11449677488","pt":1717313403177,"mc":[{"id":"1.229554890","rc":[{"atb":[[3.05,0]],"id":70003365}],"con":true,"img":false}]}
{"op":"mcm","clk":"11449678199","pt":1717313412770,"mc":[{"id":"1.229554890","rc":[{"atb":[[36,0]],"id":70003366}],"con":true,"img":false}]}
{"op":"mcm","clk":"11449678209","pt":1717313412874,"mc":[{"id":"1.229554890","rc":[{"atb":[[38,6.35]],"id":70003366}],"con":true,"img":false}]}
{"op":"mcm","clk":"11449678984","pt":1717313423857,"mc":[{"id":"1.229554890","rc":[{"atb":[[38,4]],"id":70003366}],"con":true,"img":false}]}
{"op":"mcm","clk":"11449678989","pt":1717313423961,"mc":[{"id":"1.229554890","rc":[{"atb":[[30,4.96]],"id":70003366}],"con":true,"img":false}]}
{"op":"mcm","clk":"11449679035","pt":1717313424885,"mc":[{"id":"1.229554890","rc":[{"atb":[[2.92,5.9]],"id":70003365}],"con":true,"img":false}]}
{"op":"mcm","clk":"11449679048","pt":1717313425194,"mc":[{"id":"1.229554890","rc":[{"atl":[[1.92,0]],"id":70003364}],"con":true,"img":false}]}
{"op":"mcm","clk":"11449679053","pt":1717313425295,"mc":[{"id":"1.229554890","rc":[{"atl":[[1.91,14.39]],"id":70003364}],"con":true,"img":false}]}
{"op":"mcm","clk":"11449684913","pt":1717313501218,"mc":[{"id":"1.229554890","rc":[{"atl":[[1.91,0]],"id":70003364},{"spn":6.1,"spf":"NaN","id":70003365}],"con":true,"img":false}]}
{"op":"mcm","clk":"11449684924","pt":1717313501319,"mc":[{"id":"1.229554890","rc":[{"atl":[[1.9,14.39]],"id":70003364}],"con":true,"img":false}]}
{"op":"mcm","clk":"11449684953","pt":1717313501589,"mc":[{"id":"1.229554890","rc":[{"atb":[[16,2.84]],"id":70003363}],"con":true,"img":false}]}
{"op":"mcm","clk":"11449687597","pt":1717313534151,"mc":[{"id":"1.229554890","rc":[{"atb":[[30,2.61]],"id":70003366}],"con":true,"img":false}]}
{"op":"mcm","clk":"11449687612","pt":1717313534265,"mc":[{"id":"1.229554890","rc":[{"atb":[[32,2.34]],"id":70003366},{"atb":[[3.05,2.85]],"id":70003365}],"con":true,"img":false}]}
{"op":"mcm","clk":"11449688497","pt":1717313544547,"mc":[{"id":"1.229554890","rc":[{"atl":[[3.3,4.26]],"id":70003364}],"con":true,"img":false}]}
{"op":"mcm","clk":"11449688515","pt":1717313544756,"mc":[{"id":"1.229554890","rc":[{"atl":[[8.6,4.84]],"id":70003367}],"con":true,"img":false}]}
{"op":"mcm","clk":"11449688532","pt":1717313544962,"mc":[{"id":"1.229554890","rc":[{"atl":[[9.4,4.83]],"id":70003365}],"con":true,"img":false}]}
{"op":"mcm","clk":"11449688558","pt":1717313545267,"mc":[{"id":"1.229554890","rc":[{"atl":[[180,6.87]],"id":70003363}],"con":true,"img":false}]}
{"op":"mcm","clk":"11449688582","pt":1717313545575,"mc":[{"id":"1.229554890","rc":[{"atb":[[1.37,8.52]],"id":70003364}],"con":true,"img":false}]}
{"op":"mcm","clk":"11449688605","pt":1717313545880,"mc":[{"id":"1.229554890","rc":[{"atb":[[2.48,8.52]],"id":70003367}],"con":true,"img":false}]}
{"op":"mcm","clk":"11449688633","pt":1717313546145,"mc":[{"id":"1.229554890","rc":[{"atb":[[2.68,8.52]],"id":70003365}],"con":true,"img":false}]}
{"op":"mcm","clk":"11449688652","pt":1717313546352,"mc":[{"id":"1.229554890","rc":[{"atb":[[15.5,17.93]],"id":70003363}],"con":true,"img":false}]}
{"op":"mcm","clk":"11449688665","pt":1717313546557,"mc":[{"id":"1.229554890","rc":[{"atb":[[40,8.52]],"id":70003366},{"atl":[[9.6,0]],"id":70003367}],"con":true,"img":false}]}
{"op":"mcm","clk":"11449688675","pt":1717313546655,"mc":[{"id":"1.229554890","rc":[{"atl":[[540,0]],"id":70003366},{"atl":[[11.5,12.03]],"id":70003367},{"atl":[[9.6,0]],"id":70003365}],"con":true,"img":false}]}
{"op":"mcm","clk":"11449688684","pt":1717313546763,"mc":[{"id":"1.229554890","rc":[{"atl":[[700,2.61]],"id":70003366},{"atl":[[10,8.25]],"id":70003365}],"con":true,"img":false}]}
{"op":"mcm","clk":"11449688692","pt":1717313546864,"mc":[{"id":"1.229554890","rc":[{"atl":[[980,1.03]],"id":70003366},{"atb":[[15.5,19.23]],"id":70003363}],"con":true,"img":false}]}
{"op":"mcm","clk":"11449688709","pt":1717313547073,"mc":[{"id":"1.229554890","rc":[{"atl":[[9.4,0.57]],"id":70003365}],"con":true,"img":false}]}
{"op":"mcm","clk":"11449688720","pt":1717313547173,"mc":[{"id":"1.229554890","rc":[{"atl":[[9.6,4.26]],"id":70003365}],"con":true,"img":false}]}
{"op":"mcm","clk":"11449688761","pt":1717313547686,"mc":[{"id":"1.229554890","rc":[{"atl":[[1.9,0]],"id":70003364}],"con":true,"img":false}]}
{"op":"mcm","clk":"11449688771","pt":1717313547789,"mc":[{"id":"1.229554890","rc":[{"atl":[[1.94,14.39]],"id":70003364}],"con":true,"img":false}]}
{"op":"mcm","clk":"11449688862","pt":1717313548974,"mc":[{"id":"1.229554890","rc":[{"atl":[[1.83,0]],"id":70003364}],"con":true,"img":false}]}
{"op":"mcm","clk":"11449688887","pt":1717313549237,"mc":[{"id":"1.229554890","rc":[{"atl":[[1.91,13.95]],"id":70003364}],"con":true,"img":false}]}
{"op":"mcm","clk":"11449690689","pt":1717313570457,"mc":[{"id":"1.229554890","rc":[{"atb":[[32,0]],"id":70003366},{"spn":240.0,"spf":"NaN","id":70003366},{"spn":1.73,"spf":"NaN","id":70003364},{"spn":6.12,"spf":"NaN","id":70003365}],"con":true,"img":false}]}
{"op":"mcm","clk":"11449690698","pt":1717313570557,"mc":[{"id":"1.229554890","rc":[{"atb":[[42,2.34]],"id":70003366}],"con":true,"img":false}]}
{"op":"mcm","clk":"11449690792","pt":1717313571795,"mc":[{"id":"1.229554890","rc":[{"atb":[[40,0]],"id":70003366}],"con":true,"img":false}]}
{"op":"mcm","clk":"11449690803","pt":1717313571897,"mc":[{"id":"1.229554890","rc":[{"atb":[[42,10.87]],"id":70003366}],"con":true,"img":false}]}
{"op":"mcm","clk":"11449703751","pt":1717313733733,"mc":[{"id":"1.229554890","rc":[{"atb":[[38,0],[24,0],[29,0]],"id":70003366},{"atl":[[550,0],[450,0]],"id":70003366},{"spn":241.0,"spf":"NaN","id":70003366},{"atb":[[2.86,0],[2.66,0],[2.76,0]],"id":70003367},{"atl":[[9.8,0],[14.5,0]],"id":70003367},{"atb":[[1.56,69.38],[1.51,0]],"id":70003364},{"atl":[[2.4,0],[2.6,0]],"id":70003364},{"atb":[[2.86,0],[2.66,0],[2.76,0]],"id":70003365},{"atl":[[9.8,0],[14.5,0]],"id":70003365},{"atb":[[12,0],[9.8,0],[14.5,0]],"id":70003363},{"atl":[[330,0],[230,0]],"id":70003363}],"con":true,"img":false}]}
{"op":"mcm","clk":"11449703761","pt":1717313733840,"mc":[{"id":"1.229554890","rc":[{"atb":[[2.9,40.18]],"id":70003367},{"atb":[[16,0]],"id":70003363}],"con":true,"img":false}]}
{"op":"mcm","clk":"11449703809","pt":1717313734411,"mc":[{"id":"1.229554890","rc":[{"atl":[[9.6,0]],"id":70003365}],"con":true,"img":false}]}
{"op":"mcm","clk":"11449703818","pt":1717313734513,"mc":[{"id":"1.229554890","rc":[{"atl":[[9.8,4.26]],"id":70003365}],"con":true,"img":false}]}
{"op":"mcm","clk":"11449703833","pt":1717313734721,"mc":[{"id":"1.229554890","rc":[{"atl":[[9.2,0]],"id":70003365}],"con":true,"img":false}]}
{"op":"mcm","clk":"11449703851","pt":1717313734928,"mc":[{"id":"1.229554890","rc":[{"atb":[[30,0]],"id":70003366},{"atl":[[440,0]],"id":70003366},{"atb":[[2.78,0]],"id":70003367}],"con":true,"img":false}]}
{"op":"mcm","clk":"11449703858","pt":1717313735033,"mc":[{"id":"1.229554890","rc":[{"atb":[[26,2.61]],"id":70003366},{"atl":[[520,0.06]],"id":70003366},{"atb":[[2.56,77.95]],"id":70003367},{"atl":[[9.4,0]],"id":70003365}],"con":true,"img":false}]}
{"op":"mcm","clk":"11449703865","pt":1717313735136,"mc":[{"id":"1.229554890","rc":[{"atl":[[9.6,0.57]],"id":70003365}],"con":true,"img":false}]}
{"op":"mcm","clk":"11449703891","pt":1717313735396,"mc":[{"id":"1.229554890","rc":[{"atb":[[15.5,17.93]],"id":70003363}],"con":true,"img":false}]}
{"op":"mcm","clk":"11449705180","pt":1717313751217,"mc":[{"id":"1.229554890","rc":[{"atl":[[1.94,0]],"id":70003364}],"con":true,"img":false}]}
{"op":"mcm","clk":"11449705188","pt":1717313751320,"mc":[{"id":"1.229554890","rc":[{"atl":[[1.95,14.39]],"id":70003364}],"con":true,"img":false}]}
{"op":"mcm","clk":"11449705303","pt":1717313752774,"mc":[{"id":"1.229554890","rc":[{"atb":[[38,4],[24,12.89],[29,10.59]],"id":70003366},{"atl":[[550,0.14],[450,0.11]],"id":70003366},{"atb":[[2.86,79.74],[2.66,178.7],[2.76,168.55]],"id":70003367},{"atl":[[9.8,5.88],[14.5,5.75]],"id":70003367},{"atb":[[1.56,201.52],[1.51,338.53]],"id":70003364},{"atl":[[2.4,60.62],[2.6,79.56]],"id":70003364},{"atb":[[2.86,79.74],[2.66,178.7],[2.76,168.55]],"id":70003365},{"atl":[[9.8,10.14],[14.5,5.75]],"id":70003365},{"atb":[[12,26.96],[9.8,33.7],[14.5,10.98]],"id":70003363},{"atl":[[330,0.23],[230,0.22]],"id":70003363}],"con":true,"img":false}]}
{"op":"mcm","clk":"11449705321","pt":1717313752927,"mc":[{"id":"1.229554890","rc":[{"atb":[[2.92,2.86]],"id":70003367},{"atb":[[16,2.84]],"id":70003363}],"con":true,"img":false}]}
{"op":"mcm","clk":"11449705354","pt":1717313753338,"mc":[{"id":"1.229554890","rc":[{"atb":[[15.5,19.21]],"id":70003363}],"con":true,"img":false}]}
{"op":"mcm","clk":"11449705362","pt":1717313753443,"mc":[{"id":"1.229554890","rc":[{"atl":[[9.8,5.88]],"id":70003365}],"con":true,"img":false}]}
{"op":"mcm","clk":"11449705368","pt":1717313753544,"mc":[{"id":"1.229554890","rc":[{"atl":[[9.6,4.83]],"id":70003365}],"con":true,"img":false}]}
{"op":"mcm","clk":"11449707324","pt":1717313776395,"mc":[{"id":"1.229554890","rc":[{"atl":[[1.95,0]],"id":70003364}],"con":true,"img":false}]}
{"op":"mcm","clk":"11449707334","pt":1717313776498,"mc":[{"id":"1.229554890","rc":[{"atl":[[1.93,14.39]],"id":70003364}],"con":true,"img":false}]}
{"op":"mcm","clk":"11449707684","pt":1717313780685,"mc":[{"id":"1.229554890","rc":[{"atl":[[520,0]],"id":70003366}],"con":true,"img":false}]}
{"op":"mcm","clk":"11449707695","pt":1717313780790,"mc":[{"id":"1.229554890","rc":[{"atl":[[440,0.06]],"id":70003366}],"con":true,"img":false}]}
{"op":"mcm","clk":"11449710013","pt":1717313807303,"mc":[{"id":"1.229554890","rc":[{"spn":5.76,"spf":"NaN","id":70003367},{"atl":[[1.91,0]],"id":70003364},{"spn":1.74,"spf":"NaN","id":70003364},{"spn":6.32,"spf":"NaN","id":70003365}],"con":true,"img":false}]}
{"op":"mcm","clk":"11449710033","pt":1717313807503,"mc":[{"id":"1.229554890","rc":[{"atl":[[1.9,14.03]],"id":70003364}],"con":true,"img":false}]}
{"op":"mcm","clk":"11449710116","pt":1717313808637,"mc":[{"id":"1.229554890","rc":[{"atb":[[2.56,0]],"id":70003367}],"con":true,"img":false}]}
{"op":"mcm","clk":"11449710125","pt":1717313808738,"mc":[{"id":"1.229554890","rc":[{"atb":[[2.78,77.95]],"id":70003367}],"con":true,"img":false}]}
{"op":"mcm","clk":"11449710509","pt":1717313813218,"mc":[{"id":"1.229554890","rc":[{"atb":[[26,0]],"id":70003366}],"con":true,"img":false}]}
{"op":"mcm","clk":"11449710518","pt":1717313813322,"mc":[{"id":"1.229554890","rc":[{"atb":[[30,2.61]],"id":70003366}],"con":true,"img":false}]}
{"op":"mcm","clk":"11449725570","pt":1717313980651,"mc":[{"id":"1.229554890","rc":[{"atl":[[1000,1]],"id":70003366},{"atl":[[1000,1.85]],"id":70003367},{"atl":[[1000,1.85]],"id":70003364},{"spn":1.73,"spf":"NaN","id":70003364},{"atl":[[1000,1.85]],"id":70003365},{"atl":[[1000,1.85]],"id":70003363}],"con":true,"img":false}]}
{"op":"mcm","clk":"11449727775","pt":1717314004409,"mc":[{"id":"1.229554890","rc":[{"atl":[[9.4,0.9]],"id":70003365}],"con":true,"img":false}]}
{"op":"mcm","clk":"11449736689","pt":1717314096184,"mc":[{"id":"1.229554890","rc":[{"atb":[[38,0],[24,0],[29,0]],"id":70003366},{"atl":[[550,0],[450,0]],"id":70003366},{"atb":[[2.86,0],[2.66,0],[2.76,0]],"id":70003367},{"atl":[[9.8,0],[14.5,0]],"id":70003367},{"atb":[[1.56,69.38],[1.51,0]],"id":70003364},{"atl":[[2.4,0],[2.6,0]],"id":70003364},{"atb":[[2.86,0],[2.66,0],[2.76,0]],"id":70003365},{"atl":[[9.8,0],[14.5,0]],"id":70003365},{"spn":6.22,"spf":"NaN","id":70003365},{"atb":[[12,0],[9.8,0],[14.5,0]],"id":70003363},{"atl":[[330,0],[230,0]],"id":70003363}],"con":true,"img":false}]}
{"op":"mcm","clk":"11449736728","pt":1717314096607,"mc":[{"id":"1.229554890","rc":[{"atb":[[30,0]],"id":70003366},{"atl":[[440,0]],"id":70003366},{"atb":[[2.92,0],[2.78,0]],"id":70003367},{"atl":[[1.93,0]],"id":70003364},{"atl":[[9.4,0]],"id":70003365},{"atb":[[16,0]],"id":70003363}],"con":true,"img":false}]}
{"op":"mcm","clk":"11449736736","pt":1717314096708,"mc":[{"id":"1.229554890","rc":[{"atb":[[26,2.61]],"id":70003366},{"atl":[[520,0.06]],"id":70003366},{"atb":[[2.56,77.95]],"id":70003367},{"atl":[[1.94,14.39]],"id":70003364}],"con":true,"img":false}]}
{"op":"mcm","clk":"11449736756","pt":1717314096914,"mc":[{"id":"1.229554890","rc":[{"atl":[[9.6,0.57],[9.8,0.9]],"id":70003365}],"con":true,"img":false}]}
{"op":"mcm","clk":"11449736762","pt":1717314096969,"mc":[{"id":"1.229554890","rc":[{"atl":[[9.8,5.16]],"id":70003365}],"con":true,"img":false}]}
{"op":"mcm","clk":"11449736783","pt":1717314097175,"mc":[{"id":"1.229554890","rc":[{"atl":[[9.2,0.92]],"id":70003365}],"con":true,"img":false}]}
{"op":"mcm","clk":"11449736805","pt":1717314097490,"mc":[{"id":"1.229554890","rc":[{"atl":[[9.8,4.26]],"id":70003365}],"con":true,"img":false}]}
{"op":"mcm","clk":"11449736834","pt":1717314097808,"mc":[{"id":"1.229554890","rc":[{"atl":[[9.8,0]],"id":70003365}],"con":true,"img":false}]}
{"op":"mcm","clk":"11449736844","pt":1717314097908,"mc":[{"id":"1.229554890","rc":[{"atl":[[9.6,4.83]],"id":70003365}],"con":true,"img":false}]}
{"op":"mcm","clk":"11449736851","pt":1717314098016,"mc":[{"id":"1.229554890","rc":[{"atl":[[9.6,4.26]],"id":70003365}],"con":true,"img":false}]}
{"op":"mcm","clk":"11449736861","pt":1717314098117,"mc":[{"id":"1.229554890","rc":[{"atl":[[9.8,0.57]],"id":70003365},{"atb":[[15.5,17.93]],"id":70003363}],"con":true,"img":false}]}
{"op":"mcm","clk":"11449736912","pt":1717314098692,"mc":[{"id":"1.229554890","rc":[{"atl":[[9.6,0],[9.8,0]],"id":70003365}],"con":true,"img":false}]}
{"op":"mcm","clk":"11449736918","pt":1717314098793,"mc":[{"id":"1.229554890","rc":[{"atl":[[9.8,4.26],[9.4,0.57]],"id":70003365}],"con":true,"img":false}]}
{"op":"mcm","clk":"11449736961","pt":1717314099308,"mc":[{"id":"1.229554890","rc":[{"atl":[[9.4,0]],"id":70003365}],"con":true,"img":false}]}
{"op":"mcm","clk":"11449736972","pt":1717314099410,"mc":[{"id":"1.229554890","rc":[{"atl":[[9.6,0.57]],"id":70003365}],"con":true,"img":false}]}
{"op":"mcm","clk":"11449738237","pt":1717314113455,"mc":[{"id":"1.229554890","rc":[{"atb":[[38,4],[24,12.89],[29,10.59]],"id":70003366},{"atl":[[550,0.14],[450,0.11]],"id":70003366},{"atb":[[2.86,79.74],[2.66,178.7],[2.76,168.55]],"id":70003367},{"atl":[[9.8,5.88],[14.5,5.75]],"id":70003367},{"atb":[[1.56,201.52],[1.51,338.53]],"id":70003364},{"atl":[[2.4,60.62],[2.6,79.56]],"id":70003364},{"atb":[[2.86,79.74],[2.66,178.7],[2.76,168.55]],"id":70003365},{"atl":[[9.8,10.14],[14.5,5.75]],"id":70003365},{"atb":[[12,26.96],[9.8,33.7],[14.5,10.98]],"id":70003363},{"atl":[[330,0.23],[230,0.22]],"id":70003363}],"con":true,"img":false}]}
{"op":"mcm","clk":"11449738267","pt":1717314113711,"mc":[{"id":"1.229554890","rc":[{"atb":[[15.5,19.13]],"id":70003363}],"con":true,"img":false}]}
{"op":"mcm","clk":"11449738277","pt":1717314113814,"mc":[{"id":"1.229554890","rc":[{"atb":[[2.92,2.86]],"id":70003367},{"atb":[[16,2.84]],"id":70003363}],"con":true,"img":false}]}
{"op":"mcm","clk":"11449738285","pt":1717314113918,"mc":[{"id":"1.229554890","rc":[{"atl":[[9.8,5.88]],"id":70003365}],"con":true,"img":false}]}
{"op":"mcm","clk":"11449738292","pt":1717314114023,"mc":[{"id":"1.229554890","rc":[{"atl":[[9.6,4.83]],"id":70003365}],"con":true,"img":false}]}
{"op":"mcm","clk":"11449739258","pt":1717314124126,"mc":[{"id":"1.229554890","rc":[{"atl":[[9.4,0.92]],"id":70003365}],"con":true,"img":false}]}
{"op":"mcm","clk":"11449739292","pt":1717314124436,"mc":[{"id":"1.229554890","rc":[{"atl":[[9.6,4.26]],"id":70003365}],"con":true,"img":false}]}
{"op":"mcm","clk":"11449739303","pt":1717314124543,"mc":[{"id":"1.229554890","rc":[{"atl":[[9.6,0],[9.2,1.5]],"id":70003365}],"con":true,"img":false}]}
{"op":"mcm","clk":"11449739312","pt":1717314124645,"mc":[{"id":"1.229554890","rc":[{"atl":[[9.2,5.76]],"id":70003365}],"con":true,"img":false}]}
{"op":"mcm","clk":"11449739322","pt":1717314124752,"mc":[{"id":"1.229554890","rc":[{"atl":[[9.2,4.83]],"id":70003365}],"con":true,"img":false}]}
{"op":"mcm","clk":"11449739339","pt":1717314124959,"mc":[{"id":"1.229554890","rc":[{"atl":[[9,0.94]],"id":70003365}],"con":true,"img":false}]}
{"op":"mcm","clk":"11449739349","pt":1717314125058,"mc":[{"id":"1.229554890","rc":[{"atl":[[9.4,0]],"id":70003365}],"con":true,"img":false}]}
{"op":"mcm","clk":"11449739358","pt":1717314125115,"mc":[{"id":"1.229554890","rc":[{"atb":[[2.92,7.26]],"id":70003367}],"con":true,"img":false}]}
{"op":"mcm","clk":"11449739383","pt":1717314125369,"mc":[{"id":"1.229554890","rc":[{"atb":[[3.05,7.27]],"id":70003365}],"con":true,"img":false}]}
{"op":"mcm","clk":"11449739395","pt":1717314125427,"mc":[{"id":"1.229554890","rc":[{"atl":[[9.2,0.57]],"id":70003365}],"con":true,"img":false}]}
{"op":"mcm","clk":"11449739406","pt":1717314125530,"mc":[{"id":"1.229554890","rc":[{"atl":[[9.6,4.26]],"id":70003365}],"con":true,"img":false}]}
{"op":"mcm","clk":"11449739420","pt":1717314125630,"mc":[{"id":"1.229554890","rc":[{"atl":[[9.2,0]],"id":70003365}],"con":true,"img":false}]}
{"op":"mcm","clk":"11449739433","pt":1717314125733,"mc":[{"id":"1.229554890","rc":[{"atb":[[2.9,38.97]],"id":70003367},{"atb":[[3,33]],"id":70003365},{"atl":[[9.6,4.83]],"id":70003365}],"con":true,"img":false}]}
{"op":"mcm","clk":"11449739441","pt":1717314125836,"mc":[{"id":"1.229554890","rc":[{"atb":[[2.92,8.47]],"id":70003367},{"atb":[[3.05,8.54]],"id":70003365}],"con":true,"img":false}]}
{"op":"mcm","clk":"11449740536","pt":1717314137936,"mc":[{"id":"1.229554890","rc":[{"atl":[[1.94,0]],"id":70003364}],"con":true,"img":false}]}
{"op":"mcm","clk":"11449740548","pt":1717314138044,"mc":[{"id":"1.229554890","rc":[{"atl":[[1.93,14.39]],"id":70003364}],"con":true,"img":false}]}
{"op":"mcm","clk":"11449740843","pt":1717314141447,"mc":[{"id":"1.229554890","rc":[{"atl":[[520,0]],"id":70003366}],"con":true,"img":false}]}
{"op":"mcm","clk":"11449740851","pt":1717314141551,"mc":[{"id":"1.229554890","rc":[{"atl":[[440,0.06]],"id":70003366}],"con":true,"img":false}]}
{"op":"mcm","clk":"11449741809","pt":1717314153384,"mc":[{"id":"1.229554890","rc":[{"atl":[[9.4,0.94]],"id":70003365}],"con":true,"img":false}]}
{"op":"mcm","clk":"11449741821","pt":1717314153491,"mc":[{"id":"1.229554890","rc":[{"atl":[[9,0]],"id":70003365}],"con":true,"img":false}]}
{"op":"mcm","clk":"11449743138","pt":1717314169192,"mc":[{"id":"1.229554890","rc":[{"atb":[[2.56,0]],"id":70003367}],"con":true,"img":false}]}
{"op":"mcm","clk":"11449743153","pt":1717314169300,"mc":[{"id":"1.229554890","rc":[{"atb":[[2.78,77.95]],"id":70003367}],"con":true,"img":false}]}
{"op":"mcm","clk":"11449743642","pt":1717314174410,"mc":[{"id":"1.229554890","rc":[{"atb":[[26,0]],"id":70003366}],"con":true,"img":false}]}
{"op":"mcm","clk":"11449743653","pt":1717314174510,"mc":[{"id":"1.229554890","rc":[{"atb":[[30,2.61]],"id":70003366}],"con":true,"img":false}]}
{"op":"mcm","clk":"11449766630","pt":1717314431573,"mc":[{"id":"1.229554890","rc":[{"atb":[[38,0],[24,0],[29,0]],"id":70003366},{"atl":[[550,0],[450,0]],"id":70003366},{"atb":[[2.86,0],[2.66,0],[2.76,0]],"id":70003367},{"atl":[[9.8,0],[14.5,0]],"id":70003367},{"atb":[[1.56,69.38],[1.51,0]],"id":70003364},{"atl":[[2.4,0],[2.6,0]],"id":70003364},{"atb":[[2.86,0],[2.66,0],[2.76,0]],"id":70003365},{"atl":[[9.8,0],[14.5,0]],"id":70003365},{"atb":[[12,0],[9.8,0],[14.5,0]],"id":70003363},{"atl":[[330,0],[230,0]],"id":70003363}],"con":true,"img":false}]}
{"op":"mcm","clk":"11449766650","pt":1717314431784,"mc":[{"id":"1.229554890","rc":[{"atb":[[2.92,5.61]],"id":70003367},{"atb":[[16,0]],"id":70003363}],"con":true,"img":false}]}
{"op":"mcm","clk":"11449766663","pt":1717314431839,"mc":[{"id":"1.229554890","rc":[{"atl":[[9.4,0]],"id":70003365}],"con":true,"img":false}]}
{"op":"mcm","clk":"11449766697","pt":1717314432146,"mc":[{"id":"1.229554890","rc":[{"atb":[[30,0]],"id":70003366},{"atl":[[440,0]],"id":70003366},{"atb":[[2.78,0]],"id":70003367},{"atl":[[1.93,0]],"id":70003364}],"con":true,"img":false}]}
{"op":"mcm","clk":"11449766710","pt":1717314432254,"mc":[{"id":"1.229554890","rc":[{"atb":[[40,0.42],[42,11.29],[44,0.42],[26,2.61]],"id":70003366},{"atl":[[520,0.06]],"id":70003366},{"atb":[[2.56,77.95],[2.92,9.45],[2.9,42.81],[2.94,3.84]],"id":70003367},{"atl":[[8.6,5.44],[8.8,8.84],[8.4,0.62]],"id":70003367},{"atb":[[1.56,74.7],[1.55,105.31],[1.57,5.31]],"id":70003364},{"atl":[[1.89,1.74],[1.9,15.77],[1.91,1.74],[1.94,14.39]],"id":70003364},{"atb":[[3.1,3.83],[3,36.84],[3.05,12.37]],"id":70003365},{"atl":[[9.6,1.29],[9.8,0.72],[9.4,0.72]],"id":70003365},{"atb":[[18.5,4.59],[18,0.72],[19,0.72]],"id":70003363},{"atl":[[140,0.22],[160,0.19],[180,7.04]],"id":70003363}],"con":true,"img":false}]}
{"op":"mcm","clk":"11449766723","pt":1717314432359,"mc":[{"id":"1.229554890","rc":[{"atl":[[9.8,4.98]],"id":70003365}],"con":true,"img":false}]}
{"op":"mcm","clk":"11449766768","pt":1717314432877,"mc":[{"id":"1.229554890","rc":[{"atb":[[2.92,5.05]],"id":70003367}],"con":true,"img":false}]}
{"op":"mcm","clk":"11449766782","pt":1717314432979,"mc":[{"id":"1.229554890","rc":[{"atb":[[2.94,6.7]],"id":70003367}],"con":true,"img":false}]}
{"op":"mcm","clk":"11449766801","pt":1717314433139,"mc":[{"id":"1.229554890","rc":[{"atb":[[36,0.38],[38,0.38],[46,0.38]],"id":70003366},{"atb":[[2.92,3.84]],"id":70003367},{"atl":[[8.6,1.18],[9,0.58],[9.2,0.57],[8.2,0.63]],"id":70003367},{"atb":[[1.58,5.81]],"id":70003364},{"atb":[[3.15,4.19],[3.05,7.95]],"id":70003365},{"atl":[[10,9.04],[9.2,0.78],[10.5,0.78]],"id":70003365},{"atb":[[17.5,0.78],[17,0.78],[19.5,0.78]],"id":70003363},{"atl":[[200,0.15],[220,0.14]],"id":70003363}],"con":true,"img":false}]}
{"op":"mcm","clk":"11449766813","pt":1717314433241,"mc":[{"id":"1.229554890","rc":[{"atb":[[2.94,7.91]],"id":70003367},{"atl":[[8.4,4.88]],"id":70003367}],"con":true,"img":false}]}
{"op":"mcm","clk":"11449766830","pt":1717314433451,"mc":[{"id":"1.229554890","rc":[{"atl":[[9.4,0]],"id":70003365},{"atb":[[19,0]],"id":70003363}],"con":true,"img":false}]}
{"op":"mcm","clk":"11449766844","pt":1717314433554,"mc":[{"id":"1.229554890","rc":[{"atb":[[2.94,5.05]],"id":70003367},{"atl":[[9.8,0.72]],"id":70003365}],"con":true,"img":false}]}
{"op":"mcm","clk":"11449766857","pt":1717314433658,"mc":[{"id":"1.229554890","rc":[{"atl":[[9.4,4.26]],"id":70003365}],"con":true,"img":false}]}
{"op":"mcm","clk":"11449766869","pt":1717314433759,"mc":[{"id":"1.229554890","rc":[{"atb":[[2.94,3.84]],"id":70003367},{"atl":[[8.6,0.6]],"id":70003367},{"atb":[[3.05,6.68]],"id":70003365}],"con":true,"img":false}]}
{"op":"mcm","clk":"11449766879","pt":1717314433864,"mc":[{"id":"1.229554890","rc":[{"atb":[[2.9,44.02]],"id":70003367},{"atl":[[8.2,1.21]],"id":70003367},{"atb":[[3.15,5.46]],"id":70003365}],"con":true,"img":false}]}
{"op":"mcm","clk":"11449766899","pt":1717314434076,"mc":[{"id":"1.229554890","rc":[{"atb":[[32,0.41],[34,0.41],[48,0.41]],"id":70003366},{"atl":[[8,0.65]],"id":70003367},{"atl":[[9,0.84]],"id":70003365},{"atb":[[20,0.84]],"id":70003363}],"con":true,"img":false}]}
{"op":"mcm","clk":"11449766928","pt":1717314434385,"mc":[{"id":"1.229554890","rc":[{"atb":[[46,0]],"id":70003366},{"atl":[[8.2,0.58]],"id":70003367},{"atl":[[9.6,0.72]],"id":70003365}],"con":true,"img":false}]}
{"op":"mcm","clk":"11449766937","pt":1717314434438,"mc":[{"id":"1.229554890","rc":[{"atl":[[9,1.41]],"id":70003365}],"con":true,"img":false}]}
{"op":"mcm","clk":"11449766950","pt":1717314434544,"mc":[{"id":"1.229554890","rc":[{"atl":[[8.4,0.62]],"id":70003367}],"con":true,"img":false}]}
{"op":"mcm","clk":"11449766957","pt":1717314434643,"mc":[{"id":"1.229554890","rc":[{"atl":[[8,4.91]],"id":70003367}],"con":true,"img":false}]}
{"op":"mcm","clk":"11449766983","pt":1717314434957,"mc":[{"id":"1.229554890","rc":[{"atb":[[50,0.44]],"id":70003366},{"atl":[[8.2,0]],"id":70003367},{"atl":[[9,0.84]],"id":70003365}],"con":true,"img":false}]}
{"op":"mcm","clk":"11449766997","pt":1717314435058,"mc":[{"id":"1.229554890","rc":[{"atl":[[7.8,0.58]],"id":70003367},{"atl":[[9.2,1.36]],"id":70003365}],"con":true,"img":false}]}
{"op":"mcm","clk":"11449767016","pt":1717314435266,"mc":[{"id":"1.229554890","rc":[{"atl":[[9,0]],"id":70003365},{"atb":[[20,0]],"id":70003363}],"con":true,"img":false}]}
{"op":"mcm","clk":"11449767037","pt":1717314435467,"mc":[{"id":"1.229554890","rc":[{"atl":[[8,0.65]],"id":70003367}],"con":true,"img":false}]}
{"op":"mcm","clk":"11449767049","pt":1717314435573,"mc":[{"id":"1.229554890","rc":[{"atl":[[8.2,4.26]],"id":70003367}],"con":true,"img":false}]}
{"op":"mcm","clk":"11449767073","pt":1717314435832,"mc":[{"id":"1.229554890","rc":[{"atl":[[9.4,0]],"id":70003365}],"con":true,"img":false}]}
{"op":"mcm","clk":"11449767083","pt":1717314435987,"mc":[{"id":"1.229554890","rc":[{"atl":[[7.6,0.69]],"id":70003367},{"atl":[[9,4.26],[11,0.84]],"id":70003365},{"atb":[[16.5,0.84]],"id":70003363}],"con":true,"img":false}]}
{"op":"mcm","clk":"11449767100","pt":1717314436144,"mc":[{"id":"1.229554890","rc":[{"atl":[[7.8,0]],"id":70003367},{"atl":[[9.2,0.78]],"id":70003365}],"con":true,"img":false}]}
{"op":"mcm","clk":"11449767109","pt":1717314436246,"mc":[{"id":"1.229554890","rc":[{"atb":[[50,0]],"id":70003366},{"atl":[[8,1.23]],"id":70003367},{"atl":[[8.8,0.57]],"id":70003365}],"con":true,"img":false}]}
{"op":"mcm","clk":"11449767148","pt":1717314436758,"mc":[{"id":"1.229554890","rc":[{"atl":[[8.2,0]],"id":70003367}],"con":true,"img":false}]}
{"op":"mcm","clk":"11449767157","pt":1717314436863,"mc":[{"id":"1.229554890","rc":[{"atl":[[7.8,4.26]],"id":70003367}],"con":true,"img":false}]}
{"op":"mcm","clk":"11449767193","pt":1717314437271,"mc":[{"id":"1.229554890","rc":[{"atl":[[9,0]],"id":70003365}],"con":true,"img":false}]}
{"op":"mcm","clk":"11449767201","pt":1717314437376,"mc":[{"id":"1.229554890","rc":[{"atl":[[8,0.65]],"id":70003367},{"atl":[[9.4,4.26]],"id":70003365}],"con":true,"img":false}]}
{"op":"mcm","clk":"11449767213","pt":1717314437430,"mc":[{"id":"1.229554890","rc":[{"atb":[[46,0.44]],"id":70003366},{"atl":[[7.6,1.27]],"id":70003367}],"con":true,"img":false}]}
{"op":"mcm","clk":"11449767253","pt":1717314437940,"mc":[{"id":"1.229554890","rc":[{"atl":[[8.8,0]],"id":70003365}],"con":true,"img":false}]}
{"op":"mcm","clk":"11449767263","pt":1717314438041,"mc":[{"id":"1.229554890","rc":[{"atl":[[9.2,1.36]],"id":70003365}],"con":true,"img":false}]}
{"op":"mcm","clk":"11449767314","pt":1717314438655,"mc":[{"id":"1.229554890","rc":[{"atb":[[48,0]],"id":70003366}],"con":true,"img":false}]}
{"op":"mcm","clk":"11449767361","pt":1717314439270,"mc":[{"id":"1.229554890","rc":[{"atb":[[48,0.44]],"id":70003366}],"con":true,"img":false}]}
{"op":"mcm","clk":"11449767381","pt":1717314439478,"mc":[{"id":"1.229554890","rc":[{"atb":[[46,0]],"id":70003366}],"con":true,"img":false}]}
{"op":"mcm","clk":"11449767498","pt":1717314440974,"mc":[{"id":"1.229554890","rc":[{"atb":[[50,0.44]],"id":70003366}],"con":true,"img":false}]}
{"op":"mcm","clk":"11449767591","pt":1717314441951,"mc":[{"id":"1.229554890","rc":[{"atb":[[50,0]],"id":70003366}],"con":true,"img":false}]}
{"op":"mcm","clk":"11449767651","pt":1717314442566,"mc":[{"id":"1.229554890","rc":[{"atb":[[46,0.44]],"id":70003366}],"con":true,"img":false}]}
{"op":"mcm","clk":"11449767721","pt":1717314443440,"mc":[{"id":"1.229554890","rc":[{"atb":[[48,0]],"id":70003366}],"con":true,"img":false}]}
{"op":"mcm","clk":"11449767768","pt":1717314444063,"mc":[{"id":"1.229554890","rc":[{"atb":[[48,0.44]],"id":70003366}],"con":true,"img":false}]}
{"op":"mcm","clk":"11449767784","pt":1717314444274,"mc":[{"id":"1.229554890","rc":[{"atb":[[46,0]],"id":70003366}],"con":true,"img":false}]}
{"op":"mcm","clk":"11449767910","pt":1717314445664,"mc":[{"id":"1.229554890","rc":[{"atb":[[50,0.44]],"id":70003366}],"con":true,"img":false}]}
{"op":"mcm","clk":"11449767940","pt":1717314446074,"mc":[{"id":"1.229554890","rc":[{"atb":[[38,4.38],[24,12.89],[29,10.59]],"id":70003366},{"atl":[[550,0.14],[450,0.11]],"id":70003366},{"atb":[[2.86,79.74],[2.66,178.7],[2.76,168.55]],"id":70003367},{"atl":[[14.5,5.75],[9.8,5.88]],"id":70003367},{"atb":[[1.56,206.83],[1.51,338.53]],"id":70003364},{"atl":[[2.4,60.62],[2.6,79.56]],"id":70003364},{"atb":[[2.76,168.55],[2.86,79.74],[2.66,178.7]],"id":70003365},{"atl":[[9.8,6.6],[14.5,5.75]],"id":70003365},{"atb":[[12,26.96],[14.5,10.98],[9.8,33.7]],"id":70003363},{"atl":[[330,0.23],[230,0.22]],"id":70003363}],"con":true,"img":false}]}
{"op":"mcm","clk":"11449767977","pt":1717314446491,"mc":[{"id":"1.229554890","rc":[{"atb":[[55,0.57]],"id":70003366},{"atb":[[2.96,4.12]],"id":70003367},{"atb":[[1.59,6.26],[1.54,6.26],[1.53,6.26]],"id":70003364},{"atl":[[9,1.05]],"id":70003365}],"con":true,"img":false}]}
{"op":"mcm","clk":"11449767991","pt":1717314446700,"mc":[{"id":"1.229554890","rc":[{"atb":[[50,0]],"id":70003366}],"con":true,"img":false}]}
{"op":"mcm","clk":"11449767998","pt":1717314446751,"mc":[{"id":"1.229554890","rc":[{"atb":[[2.92,6.7]],"id":70003367},{"atb":[[16,2.84]],"id":70003363}],"con":true,"img":false}]}
{"op":"mcm","clk":"11449768017","pt":1717314447009,"mc":[{"id":"1.229554890","rc":[{"atb":[[2.9,42.81]],"id":70003367},{"atl":[[9.2,0.78]],"id":70003365}],"con":true,"img":false}]}
{"op":"mcm","clk":"11449768027","pt":1717314447062,"mc":[{"id":"1.229554890","rc":[{"atb":[[2.96,5.33]],"id":70003367},{"atl":[[9,1.62],[9.4,0]],"id":70003365}],"con":true,"img":false}]}
{"op":"mcm","clk":"11449768036","pt":1717314447162,"mc":[{"id":"1.229554890","rc":[{"atl":[[9,5.88]],"id":70003365}],"con":true,"img":false}]}
{"op":"mcm","clk":"11449768047","pt":1717314447263,"mc":[{"id":"1.229554890","rc":[{"atb":[[60,0.52]],"id":70003366},{"atb":[[1.6,6.26],[1.51,344.79],[1.52,6.26]],"id":70003364},{"atb":[[20,0.95]],"id":70003363}],"con":true,"img":false}]}
{"op":"mcm","clk":"11449768122","pt":1717314448085,"mc":[{"id":"1.229554890","rc":[{"atb":[[48,1]],"id":70003366}],"con":true,"img":false}]}
{"op":"mcm","clk":"11449768148","pt":1717314448392,"mc":[{"id":"1.229554890","rc":[{"atb":[[60,0]],"id":70003366},{"atb":[[20,0]],"id":70003363}],"con":true,"img":false}]}
{"op":"mcm","clk":"11449768188","pt":1717314448861,"mc":[{"id":"1.229554890","rc":[{"atb":[[19,0.95]],"id":70003363}],"con":true,"img":false}]}
{"op":"mcm","clk":"11449768277","pt":1717314449992,"mc":[{"id":"1.229554890","rc":[{"atb":[[19.5,0]],"id":70003363}],"con":true,"img":false}]}
{"op":"mcm","clk":"11449768303","pt":1717314450301,"mc":[{"id":"1.229554890","rc":[{"atl":[[1.9,1.74]],"id":70003364}],"con":true,"img":false}]}
{"op":"mcm","clk":"11449768322","pt":1717314450460,"mc":[{"id":"1.229554890","rc":[{"atb":[[19.5,0.96]],"id":70003363}],"con":true,"img":false}]}
{"op":"mcm","clk":"11449768334","pt":1717314450564,"mc":[{"id":"1.229554890","rc":[{"atl":[[1.91,15.7]],"id":70003364}],"con":true,"img":false}]}
{"op":"mcm","clk":"11449768343","pt":1717314450662,"mc":[{"id":"1.229554890","rc":[{"atb":[[19,0]],"id":70003363}],"con":true,"img":false}]}
{"op":"mcm","clk":"11449768397","pt":1717314451285,"mc":[{"id":"1.229554890","rc":[{"atb":[[20,0.96]],"id":70003363}],"con":true,"img":false}]}
{"op":"mcm","clk":"11449768467","pt":1717314452053,"mc":[{"id":"1.229554890","rc":[{"atb":[[20,0]],"id":70003363}],"con":true,"img":false}]}
{"op":"mcm","clk":"11449768517","pt":1717314452671,"mc":[{"id":"1.229554890","rc":[{"atb":[[16,3.8]],"id":70003363}],"con":true,"img":false}]}
{"op":"mcm","clk":"11449769930","pt":1717314469982,"mc":[{"id":"1.229554890","rc":[{"atl":[[1.94,0]],"id":70003364}],"con":true,"img":false}]}
{"op":"mcm","clk":"11449769938","pt":1717314470084,"mc":[{"id":"1.229554890","rc":[{"atl":[[1.93,14.39]],"id":70003364}],"con":true,"img":false}]}
{"op":"mcm","clk":"11449770306","pt":1717314474004,"mc":[{"id":"1.229554890","rc":[{"atl":[[520,0]],"id":70003366}],"con":true,"img":false}]}
{"op":"mcm","clk":"11449770317","pt":1717314474107,"mc":[{"id":"1.229554890","rc":[{"atl":[[440,0.06]],"id":70003366}],"con":true,"img":false}]}
{"op":"mcm","clk":"11449770602","pt":1717314477218,"mc":[{"id":"1.229554890","rc":[{"atl":[[10,0.78]],"id":70003365}],"con":true,"img":false}]}
{"op":"mcm","clk":"11449770613","pt":1717314477322,"mc":[{"id":"1.229554890","rc":[{"atl":[[9.6,8.97]],"id":70003365}],"con":true,"img":false}]}
{"op":"mcm","clk":"11449771368","pt":1717314485711,"mc":[{"id":"1.229554890","rc":[{"atl":[[1.91,1.74]],"id":70003364}],"con":true,"img":false}]}
{"op":"mcm","clk":"11449771394","pt":1717314485917,"mc":[{"id":"1.229554890","rc":[{"atl":[[1.9,15.77]],"id":70003364}],"con":true,"img":false}]}
