{"op":"mcm","clk":"11448127639","pt":1717286034978,"mc":[{"id":"1.229554905","marketDefinition":{"bspMarket":true,"turnInPlayEnabled":false,"persistenceEnabled":false,"marketBaseRate":7.0,"eventId":"33318908","eventTypeId":"4339","numberOfWinners":1,"bettingType":"ODDS","marketType":"WIN","marketTime":"2024-06-02T09:20:00.000Z","suspendTime":"2024-06-02T09:20:00.000Z","bspReconciled":false,"complete":true,"inPlay":false,"crossMatching":true,"runnersVoidable":false,"numberOfActiveRunners":5,"betDelay":0,"status":"OPEN","runners":[{"status":"ACTIVE","sortPriority":1,"id":61631980,"name":"1. Opella"},{"status":"ACTIVE","sortPriority":2,"id":57451148,"name":"2. Taras Girl"},{"status":"ACTIVE","sortPriority":3,"id":61631978,"name":"4. Elwomple"},{"status":"ACTIVE","sortPriority":4,"id":42269942,"name":"6. Hey Sisco"},{"status":"ACTIVE","sortPriority":5,"id":60780007,"name":"8. Got Rhythm"}],"regulators":["MR_INT"],"venue":"Murray Bridge","countryCode":"AU","discountAllowed":true,"timezone":"Australia/Adelaide","openDate":"2024-06-02T08:21:00.000Z","version":5962317642,"name":"R4 395m Gr5","eventName":"Murray Bridge (AUS) 2nd Jun"},"rc":[],"con":true,"img":false}]}
{"op":"mcm","clk":"11448233921","pt":1717287573385,"mc":[{"id":"1.229554905","rc":[{"atl":[[2.66,2.61]],"id":60780007},{"spn":1.0,"spf":"NaN","id":60780007}],"con":true,"img":false}]}
{"op":"mcm","clk":"11448258036","pt":1717287872067,"mc":[{"id":"1.229554905","rc":[{"atb":[[36,5.97],[46,2.32],[28,7.74]],"id":42269942},{"atl":[[590,0.35],[490,0.28]],"id":42269942},{"spn":268.0,"spf":"NaN","id":42269942},{"atb":[[5.8,43.55],[5.3,48.61],[6.6,18.66]],"id":57451148},{"atl":[[95,2.22],[48,2.96]],"id":57451148},{"spn":27.3,"spf":"NaN","id":57451148},{"atb":[[1.44,475.13],[1.54,193.57],[1.49,426.65]],"id":60780007},{"atl":[[3.6,80.4],[3.1,66.37]],"id":60780007},{"spn":2.1,"spf":"NaN","id":60780007},{"atb":[[3.25,92.91],[3.5,83.62],[3.75,38]],"id":61631980},{"atl":[[17.5,8.44],[25,8.71]],"id":61631980},{"spn":10.62,"spf":"NaN","id":61631980},{"atb":[[2.9,110.03],[3,104.53],[3.25,46.45]],"id":61631978},{"atl":[[17,13.06],[12,12.67]],"id":61631978},{"spn":7.62,"spf":"NaN","id":61631978}],"con":true,"img":false}]}
{"op":"mcm","clk":"11448259645","pt":1717287895294,"mc":[{"id":"1.229554905","rc":[{"atb":[[36,0],[46,0],[28,0]],"id":42269942},{"atl":[[590,0],[490,0]],"id":42269942},{"atb":[[5.8,0],[5.3,0],[6.6,0]],"id":57451148},{"atl":[[95,0],[48,0]],"id":57451148},{"atb":[[3.25,0],[3.5,0],[3.75,0]],"id":61631980},{"atl":[[17.5,0],[25,0]],"id":61631980},{"atb":[[1.44,0],[1.54,0],[1.49,0]],"id":60780007},{"atl":[[3.6,0],[3.1,0]],"id":60780007},{"atb":[[2.9,0],[3,0],[3.25,0]],"id":61631978},{"atl":[[17,0],[12,0]],"id":61631978}],"con":true,"img":false}]}
{"op":"mcm","clk":"11448260594","pt":1717287908430,"mc":[{"id":"1.229554905","rc":[{"atb":[[34,6.33],[44,2.43],[27,8.04]],"id":42269942},{"atl":[[580,0.36],[480,0.29]],"id":42269942},{"atb":[[5.8,43.55],[5.3,48.61],[6.6,18.66]],"id":57451148},{"atl":[[95,2.22],[48,2.96]],"id":57451148},{"atb":[[3.25,92.91],[3.5,83.62],[3.75,38]],"id":61631980},{"atl":[[17.5,8.44],[25,8.71]],"id":61631980},{"atb":[[1.43,243.09],[1.33,633.51],[1.38,550.16]],"id":60780007},{"atl":[[2.9,73.35],[3.25,92.91]],"id":60780007},{"atb":[[2.9,110.03],[3,104.53],[3.25,46.45]],"id":61631978},{"atl":[[17,13.06],[12,12.67]],"id":61631978}],"con":true,"img":false}]}
{"op":"mcm","clk":"11448264312","pt":1717287962366,"mc":[{"id":"1.229554905","rc":[{"atb":[[34,0],[44,0],[27,0]],"id":42269942},{"atl":[[580,0],[480,0]],"id":42269942},{"spn":"NaN","spf":"NaN","id":42269942},{"atb":[[5.8,0],[5.3,0],[6.6,0]],"id":57451148},{"atl":[[95,0],[48,0]],"id":57451148},{"spn":"NaN","spf":"NaN","id":57451148},{"atb":[[3.25,0],[3.5,0],[3.75,0]],"id":61631980},{"atl":[[17.5,0],[25,0]],"id":61631980},{"spn":"NaN","spf":"NaN","id":61631980},{"atb":[[1.43,0],[1.33,0],[1.38,0]],"id":60780007},{"atl":[[2.9,0],[3.25,0]],"id":60780007},{"spn":1.0,"spf":"NaN","id":60780007},{"atb":[[2.9,0],[3,0],[3.25,0]],"id":61631978},{"atl":[[17,0],[12,0]],"id":61631978},{"spn":"NaN","spf":"NaN","id":61631978}],"con":true,"img":false}]}
{"op":"mcm","clk":"11448265018","pt":1717287972318,"mc":[{"id":"1.229554905","rc":[{"atb":[[34,6.33],[44,2.43],[27,8.04]],"id":42269942},{"atl":[[580,0.36],[480,0.29]],"id":42269942},{"atb":[[5.8,43.55],[5.3,48.61],[6.6,18.66]],"id":57451148},{"atl":[[95,2.22],[48,2.96]],"id":57451148},{"atb":[[3.25,92.91],[3.5,83.62],[3.75,38]],"id":61631980},{"atl":[[17.5,8.44],[25,8.71]],"id":61631980},{"atb":[[1.43,243.09],[1.33,633.51],[1.38,550.16]],"id":60780007},{"atl":[[2.9,73.35],[3.25,92.91]],"id":60780007},{"atb":[[2.9,110.03],[3,104.53],[3.25,46.45]],"id":61631978},{"atl":[[17,13.06],[12,12.67]],"id":61631978}],"con":true,"img":false}]}
{"op":"mcm","clk":"11448266368","pt":1717287995050,"mc":[{"id":"1.229554905","rc":[{"atb":[[2.9,0],[3,0],[3.25,0]],"id":61631978},{"atl":[[17,0],[12,0]],"id":61631978}],"con":true,"img":false}]}
{"op":"mcm","clk":"11448266886","pt":1717288003942,"mc":[{"id":"1.229554905","rc":[{"atb":[[2.86,112.39],[3.15,48.61],[2.96,106.66]],"id":61631978},{"atl":[[16,13.93],[11,13.93]],"id":61631978}],"con":true,"img":false}]}
{"op":"mcm","clk":"11448272364","pt":1717288089682,"mc":[{"id":"1.229554905","rc":[{"spn":262.0,"spf":"NaN","id":42269942},{"spn":27.3,"spf":"NaN","id":57451148},{"spn":10.62,"spf":"NaN","id":61631980},{"spn":2.04,"spf":"NaN","id":60780007},{"atb":[[2.86,0],[3.15,0],[2.96,0]],"id":61631978},{"atl":[[16,0],[11,0]],"id":61631978}],"con":true,"img":false}]}
{"op":"mcm","clk":"11448273012","pt":1717288099886,"mc":[{"id":"1.229554905","rc":[{"atb":[[3.1,49.77],[2.84,113.61],[2.94,107.76]],"id":61631978},{"atl":[[16,13.93],[11,13.93]],"id":61631978}],"con":true,"img":false}]}
{"op":"mcm","clk":"11448277240","pt":1717288128429,"mc":[{"id":"1.229554905","marketDefinition":{"bspMarket":true,"turnInPlayEnabled":false,"persistenceEnabled":false,"marketBaseRate":7.0,"eventId":"33318908","eventTypeId":"4339","numberOfWinners":1,"bettingType":"ODDS","marketType":"WIN","marketTime":"2024-06-02T09:20:00.000Z","suspendTime":"2024-06-02T09:20:00.000Z","bspReconciled":false,"complete":true,"inPlay":false,"crossMatching":true,"runnersVoidable":false,"numberOfActiveRunners":5,"betDelay":0,"status":"OPEN","runners":[{"status":"ACTIVE","sortPriority":1,"id":61631980,"name":"1. Opella"},{"status":"ACTIVE","sortPriority":2,"id":57451148,"name":"2. Taras Girl"},{"status":"ACTIVE","sortPriority":3,"id":61631978,"name":"4. Elwomple"},{"status":"ACTIVE","sortPriority":4,"id":42269942,"name":"6. Hey Sisco"},{"status":"ACTIVE","sortPriority":5,"id":60780007,"name":"8. Got Rhythm"}],"regulators":["MR_INT"],"venue":"Murray Bridge","countryCode":"AU","discountAllowed":true,"timezone":"Australia/Adelaide","openDate":"2024-06-02T08:21:00.000Z","version":5962317642,"name":"R4 395m Gr5","eventName":"Murray Bridge (AUS) 2nd Jun"},"rc":[{"atb":[[34,6.33],[44,2.43],[27,8.04]],"id":42269942},{"atl":[[580,0.36],[480,0.29]],"id":42269942},{"spn":262.0,"spf":"NaN","id":42269942},{"atb":[[5.8,43.55],[5.3,48.61],[6.6,18.66]],"id":57451148},{"atl":[[95,2.22],[48,2.96]],"id":57451148},{"spn":27.3,"spf":"NaN","id":57451148},{"atb":[[3.25,92.91],[3.5,83.62],[3.75,38]],"id":61631980},{"atl":[[17.5,8.44],[25,8.71]],"id":61631980},{"spn":10.62,"spf":"NaN","id":61631980},{"atb":[[1.43,243.09],[1.33,633.51],[1.38,550.16]],"id":60780007},{"atl":[[2.9,73.35],[2.66,2.61],[3.25,92.91]],"id":60780007},{"spn":2.04,"spf":"NaN","id":60780007},{"atb":[[3.1,49.77],[2.84,113.61],[2.94,107.76]],"id":61631978},{"atl":[[16,13.93],[11,13.93]],"id":61631978},{"spn":"NaN","spf":"NaN","id":61631978}],"con":true,"img":true}]}
{"op":"mcm","clk":"11448292464","pt":1717288273959,"mc":[{"id":"1.229554905","rc":[{"atb":[[34,0],[44,0],[27,0]],"id":42269942},{"atl":[[580,0],[480,0]],"id":42269942},{"spn":"NaN","spf":"NaN","id":42269942},{"atb":[[5.8,0],[5.3,0],[6.6,0]],"id":57451148},{"atl":[[95,0],[48,0]],"id":57451148},{"spn":"NaN","spf":"NaN","id":57451148},{"atb":[[3.25,0],[3.5,0],[3.75,0]],"id":61631980},{"atl":[[17.5,0],[25,0]],"id":61631980},{"spn":"NaN","spf":"NaN","id":61631980},{"atb":[[1.43,0],[1.33,0],[1.38,0]],"id":60780007},{"atl":[[2.9,0],[3.25,0]],"id":60780007},{"spn":1.0,"spf":"NaN","id":60780007},{"atb":[[3.1,0],[2.84,0],[2.94,0]],"id":61631978},{"atl":[[16,0],[11,0]],"id":61631978}],"con":true,"img":false}]}
{"op":"mcm","clk":"11448293804","pt":1717288291623,"mc":[{"id":"1.229554905","rc":[{"atb":[[34,6.33],[44,2.43],[27,8.04]],"id":42269942},{"atl":[[580,0.36],[480,0.29]],"id":42269942},{"atb":[[5.8,43.55],[7.6,15.83],[6.6,37.33]],"id":57451148},{"atl":[[75,1.88],[150,1.4]],"id":57451148},{"atb":[[3.25,92.91],[3.5,83.62],[3.75,38]],"id":61631980},{"atl":[[17.5,8.44],[25,8.71]],"id":61631980},{"atb":[[1.43,243.09],[1.33,633.51],[1.38,550.16]],"id":60780007},{"atl":[[2.9,73.35],[3.25,92.91]],"id":60780007},{"atb":[[2.9,110.03],[3,104.53],[3.25,46.45]],"id":61631978},{"atl":[[17,13.06],[12,12.67]],"id":61631978}],"con":true,"img":false}]}
{"op":"mcm","clk":"11448298269","pt":1717288351379,"mc":[{"id":"1.229554905","rc":[{"spn":262.0,"spf":"NaN","id":42269942},{"atb":[[5.8,0],[7.6,0],[6.6,0]],"id":57451148},{"atl":[[75,0],[150,0]],"id":57451148},{"atb":[[3.25,0],[3.5,0],[3.75,0]],"id":61631980},{"atl":[[17.5,0],[25,0]],"id":61631980},{"spn":2.04,"spf":"NaN","id":60780007},{"atb":[[2.9,0],[3,0],[3.25,0]],"id":61631978},{"atl":[[17,0],[12,0]],"id":61631978}],"con":true,"img":false}]}
{"op":"mcm","clk":"11448300795","pt":1717288383947,"mc":[{"id":"1.229554905","rc":[{"atb":[[8.6,13.75],[7.6,31.67],[6.6,37.33]],"id":57451148},{"atl":[[100,1.4],[200,1.05]],"id":57451148},{"atb":[[3.4,87.1],[3.9,36.04],[3.65,78.88]],"id":61631980},{"atl":[[19,7.74],[28,7.74]],"id":61631980},{"atb":[[3.4,43.55],[3.15,97.23],[2.96,106.66]],"id":61631978},{"atl":[[19,11.61],[14,10.71]],"id":61631978}],"con":true,"img":false}]}
{"op":"mcm","clk":"11448629970","pt":1717293528419,"mc":[{"id":"1.229554905","marketDefinition":{"bspMarket":true,"turnInPlayEnabled":false,"persistenceEnabled":false,"marketBaseRate":7.0,"eventId":"33318908","eventTypeId":"4339","numberOfWinners":1,"bettingType":"ODDS","marketType":"WIN","marketTime":"2024-06-02T09:20:00.000Z","suspendTime":"2024-06-02T09:20:00.000Z","bspReconciled":false,"complete":true,"inPlay":false,"crossMatching":true,"runnersVoidable":false,"numberOfActiveRunners":5,"betDelay":0,"status":"OPEN","runners":[{"status":"ACTIVE","sortPriority":1,"id":61631980,"name":"1. Opella"},{"status":"ACTIVE","sortPriority":2,"id":57451148,"name":"2. Taras Girl"},{"status":"ACTIVE","sortPriority":3,"id":61631978,"name":"4. Elwomple"},{"status":"ACTIVE","sortPriority":4,"id":42269942,"name":"6. Hey Sisco"},{"status":"ACTIVE","sortPriority":5,"id":60780007,"name":"8. Got Rhythm"}],"regulators":["MR_INT"],"venue":"Murray Bridge","countryCode":"AU","discountAllowed":true,"timezone":"Australia/Adelaide","openDate":"2024-06-02T08:21:00.000Z","version":5962317642,"name":"R4 395m Gr5","eventName":"Murray Bridge (AUS) 2nd Jun"},"rc":[{"atb":[[34,6.33],[44,2.43],[27,8.04]],"id":42269942},{"atl":[[580,0.36],[480,0.29]],"id":42269942},{"spn":262.0,"spf":"NaN","id":42269942},{"atb":[[8.6,13.75],[7.6,31.67],[6.6,37.33]],"id":57451148},{"atl":[[100,1.4],[200,1.05]],"id":57451148},{"spn":54.3,"spf":"NaN","id":57451148},{"atb":[[3.4,87.1],[3.9,36.04],[3.65,78.88]],"id":61631980},{"atl":[[19,7.74],[28,7.74]],"id":61631980},{"spn":11.45,"spf":"NaN","id":61631980},{"atb":[[1.43,243.09],[1.33,633.51],[1.38,550.16]],"id":60780007},{"atl":[[2.9,73.35],[2.66,2.61],[3.25,92.91]],"id":60780007},{"spn":2.04,"spf":"NaN","id":60780007},{"atb":[[3.4,43.55],[3.15,97.23],[2.96,106.66]],"id":61631978},{"atl":[[19,11.61],[14,10.71]],"id":61631978},{"spn":8.7,"spf":"NaN","id":61631978}],"con":true,"img":true}]}
{"op":"mcm","clk":"11448957702","pt":1717300805016,"mc":[{"id":"1.229554905","rc":[{"atb":[[34,0],[44,0],[27,0]],"id":42269942},{"atl":[[580,0],[480,0]],"id":42269942},{"spn":"NaN","spf":"NaN","id":42269942},{"atb":[[8.6,0],[7.6,0],[6.6,0]],"id":57451148},{"atl":[[100,0],[200,0]],"id":57451148},{"atb":[[3.4,0],[3.9,0],[3.65,0]],"id":61631980},{"atl":[[19,0],[28,0]],"id":61631980},{"atb":[[1.43,0],[1.33,0],[1.38,0]],"id":60780007},{"atl":[[2.9,0],[3.25,0]],"id":60780007},{"spn":1.0,"spf":"NaN","id":60780007},{"atb":[[3.4,0],[3.15,0],[2.96,0]],"id":61631978},{"atl":[[19,0],[14,0]],"id":61631978}],"con":true,"img":false}]}
{"op":"mcm","clk":"11448958444","pt":1717300819024,"mc":[{"id":"1.229554905","rc":[{"atb":[[34,6.33],[44,2.43],[27,8.04]],"id":42269942},{"atl":[[580,0.36],[480,0.29]],"id":42269942},{"atb":[[8.6,13.75],[7.6,31.67],[6.6,37.33]],"id":57451148},{"atl":[[100,1.4],[200,1.05]],"id":57451148},{"atb":[[3.4,87.1],[3.9,36.04],[3.65,78.88]],"id":61631980},{"atl":[[19,7.74],[28,7.74]],"id":61631980},{"atb":[[1.18,1161.45],[1.23,454.48],[1.13,1608.16]],"id":60780007},{"atl":[[2.64,84.98],[2.84,113.61]],"id":60780007},{"atb":[[3.45,42.66],[3.2,95.02],[2.98,105.58]],"id":61631978},{"atl":[[19.5,11.3],[14.5,10.32]],"id":61631978}],"con":true,"img":false}]}
{"op":"mcm","clk":"11448963905","pt":1717300914322,"mc":[{"id":"1.229554905","rc":[{"spn":262.0,"spf":"NaN","id":42269942},{"atb":[[8.6,0],[7.6,0],[6.6,0]],"id":57451148},{"atl":[[100,0],[200,0]],"id":57451148},{"atb":[[3.4,0],[3.9,0],[3.65,0]],"id":61631980},{"atl":[[19,0],[28,0]],"id":61631980},{"spn":1.93,"spf":"NaN","id":60780007},{"atb":[[3.45,0],[3.2,0],[2.98,0]],"id":61631978},{"atl":[[19.5,0],[14.5,0]],"id":61631978}],"con":true,"img":false}]}
{"op":"mcm","clk":"11448965590","pt":1717300946049,"mc":[{"id":"1.229554905","rc":[{"atb":[[7.4,32.66],[8.4,28.25],[9.4,12.44]],"id":57451148},{"atl":[[140,1],[240,0.87]],"id":57451148},{"atb":[[3.4,87.1],[3.9,36.04],[3.65,78.88]],"id":61631980},{"atl":[[19,7.74],[28,7.74]],"id":61631980},{"atb":[[3.45,42.66],[3.2,95.02],[2.98,105.58]],"id":61631978},{"atl":[[19.5,11.3],[14.5,10.32]],"id":61631978}],"con":true,"img":false}]}
{"op":"mcm","clk":"11449119157","pt":1717304328432,"mc":[{"id":"1.229554905","marketDefinition":{"bspMarket":true,"turnInPlayEnabled":false,"persistenceEnabled":false,"marketBaseRate":7.0,"eventId":"33318908","eventTypeId":"4339","numberOfWinners":1,"bettingType":"ODDS","marketType":"WIN","marketTime":"2024-06-02T09:20:00.000Z","suspendTime":"2024-06-02T09:20:00.000Z","bspReconciled":false,"complete":true,"inPlay":false,"crossMatching":true,"runnersVoidable":false,"numberOfActiveRunners":5,"betDelay":0,"status":"OPEN","runners":[{"status":"ACTIVE","sortPriority":1,"id":61631980,"name":"1. Opella"},{"status":"ACTIVE","sortPriority":2,"id":57451148,"name":"2. Taras Girl"},{"status":"ACTIVE","sortPriority":3,"id":61631978,"name":"4. Elwomple"},{"status":"ACTIVE","sortPriority":4,"id":42269942,"name":"6. Hey Sisco"},{"status":"ACTIVE","sortPriority":5,"id":60780007,"name":"8. Got Rhythm"}],"regulators":["MR_INT"],"venue":"Murray Bridge","countryCode":"AU","discountAllowed":true,"timezone":"Australia/Adelaide","openDate":"2024-06-02T08:21:00.000Z","version":5962317642,"name":"R4 395m Gr5","eventName":"Murray Bridge (AUS) 2nd Jun"},"rc":[{"atb":[[34,6.33],[44,2.43],[27,8.04]],"id":42269942},{"atl":[[580,0.36],[480,0.29]],"id":42269942},{"spn":262.0,"spf":"NaN","id":42269942},{"atb":[[7.4,32.66],[8.4,28.25],[9.4,12.44]],"id":57451148},{"atl":[[140,1],[240,0.87]],"id":57451148},{"spn":74.7,"spf":"NaN","id":57451148},{"atb":[[3.4,87.1],[3.9,36.04],[3.65,78.88]],"id":61631980},{"atl":[[19,7.74],[28,7.74]],"id":61631980},{"spn":11.45,"spf":"NaN","id":61631980},{"atb":[[1.18,1161.45],[1.23,454.48],[1.13,1608.16]],"id":60780007},{"atl":[[2.64,84.98],[2.66,2.61],[2.84,113.61]],"id":60780007},{"spn":1.93,"spf":"NaN","id":60780007},{"atb":[[3.45,42.66],[3.2,95.02],[2.98,105.58]],"id":61631978},{"atl":[[19.5,11.3],[14.5,10.32]],"id":61631978},{"spn":8.97,"spf":"NaN","id":61631978}],"con":true,"img":true}]}
{"op":"mcm","clk":"11449172172","pt":1717305097328,"mc":[{"id":"1.229554905","rc":[{"spn":74.7,"spf":"NaN","id":57451148},{"spn":11.45,"spf":"NaN","id":61631980},{"atl":[[2,4.73]],"id":60780007},{"spn":1.61,"spf":"NaN","id":60780007},{"spn":8.97,"spf":"NaN","id":61631978}],"con":true,"img":false}]}
{"op":"mcm","clk":"11449358366","pt":1717307834038,"mc":[{"id":"1.229554905","rc":[{"atb":[[1.01,17.76]],"id":42269942},{"atl":[[990,0.85]],"id":42269942},{"atb":[[1.03,5.92]],"id":57451148},{"atl":[[990,0.85]],"id":57451148},{"atb":[[1.02,8.87]],"id":61631980},{"atl":[[990,0.85]],"id":61631980},{"atb":[[1.01,17.76]],"id":60780007},{"atl":[[990,0.85]],"id":60780007},{"atb":[[1.03,5.92]],"id":61631978},{"atl":[[1000,0.85]],"id":61631978}],"con":true,"img":false}]}
{"op":"mcm","clk":"11449448623","pt":1717309303098,"mc":[{"id":"1.229554905","rc":[{"atb":[[34,0],[44,0],[27,0]],"id":42269942},{"atl":[[580,0],[480,0]],"id":42269942},{"spn":495.5,"spf":"NaN","id":42269942},{"atb":[[7.4,0],[8.4,0],[9.4,0]],"id":57451148},{"atl":[[140,0],[240,0]],"id":57451148},{"spn":495.51,"spf":"NaN","id":57451148},{"atb":[[3.4,0],[3.9,0],[3.65,0]],"id":61631980},{"atl":[[19,0],[28,0]],"id":61631980},{"spn":495.51,"spf":"NaN","id":61631980},{"atb":[[1.18,0],[1.23,0],[1.13,0]],"id":60780007},{"atl":[[2.64,0],[2.84,0]],"id":60780007},{"spn":1.5,"spf":"NaN","id":60780007},{"atb":[[3.45,0],[3.2,0],[2.98,0]],"id":61631978},{"atl":[[19.5,0],[14.5,0]],"id":61631978},{"spn":500.51,"spf":"NaN","id":61631978}],"con":true,"img":false}]}
{"op":"mcm","clk":"11449449644","pt":1717309317318,"mc":[{"id":"1.229554905","rc":[{"atb":[[34,6.33],[44,2.43],[27,8.04]],"id":42269942},{"atl":[[580,0.36],[480,0.29]],"id":42269942},{"atb":[[7.4,32.66],[8.4,28.25],[9.4,12.44]],"id":57451148},{"atl":[[140,1],[240,0.87]],"id":57451148},{"atb":[[3.4,87.1],[3.9,36.04],[3.65,78.88]],"id":61631980},{"atl":[[19,7.74],[28,7.74]],"id":61631980},{"atb":[[1.18,1161.45],[1.23,454.48],[1.13,1608.16]],"id":60780007},{"atl":[[2.64,84.98],[2.84,113.61]],"id":60780007},{"atb":[[3.25,92.91],[3.5,83.62],[3.75,38]],"id":61631978},{"atl":[[17.5,8.44],[25,8.71]],"id":61631978}],"con":true,"img":false}]}
{"op":"mcm","clk":"11449451521","pt":1717309344449,"mc":[{"id":"1.229554905","rc":[{"atb":[[34,0],[44,0],[27,0]],"id":42269942},{"atl":[[580,0],[480,0]],"id":42269942},{"atb":[[7.4,0],[8.4,0],[9.4,0]],"id":57451148},{"atl":[[140,0],[240,0]],"id":57451148},{"atb":[[3.4,0],[3.9,0],[3.65,0]],"id":61631980},{"atl":[[19,0],[28,0]],"id":61631980},{"atb":[[1.18,0],[1.23,0],[1.13,0]],"id":60780007},{"atl":[[2.64,0],[2.84,0]],"id":60780007},{"atb":[[3.25,0],[3.5,0],[3.75,0]],"id":61631978},{"atl":[[17.5,0],[25,0]],"id":61631978}],"con":true,"img":false}]}
{"op":"mcm","clk":"11449452507","pt":1717309358077,"mc":[{"id":"1.229554905","rc":[{"atb":[[70,1.51],[38,5.65],[48,4.44]],"id":42269942},{"atl":[[630,0.21],[730,0.28]],"id":42269942},{"atb":[[7.4,32.66],[8.4,28.25],[9.4,12.44]],"id":57451148},{"atl":[[140,1],[240,0.87]],"id":57451148},{"atb":[[3.4,87.1],[3.9,36.04],[3.65,78.88]],"id":61631980},{"atl":[[19,7.74],[28,7.74]],"id":61631980},{"atb":[[1.16,653.31],[1.11,1900.55],[1.06,3484.35]],"id":60780007},{"atl":[[2.46,95.46],[2.66,128.55]],"id":60780007},{"atb":[[3.25,92.91],[3.5,83.62],[3.75,38]],"id":61631978},{"atl":[[17.5,8.44],[25,8.71]],"id":61631978}],"con":true,"img":false}]}
{"op":"mcm","clk":"11449454214","pt":1717309383995,"mc":[{"id":"1.229554905","rc":[{"atb":[[70,0],[38,0],[48,0]],"id":42269942},{"atl":[[630,0],[730,0]],"id":42269942},{"atb":[[7.4,0],[8.4,0],[9.4,0]],"id":57451148},{"atl":[[140,0],[240,0]],"id":57451148},{"atb":[[3.4,0],[3.9,0],[3.65,0]],"id":61631980},{"atl":[[19,0],[28,0]],"id":61631980},{"spn":1.58,"spf":"NaN","id":60780007},{"atb":[[3.25,0],[3.5,0],[3.75,0]],"id":61631978},{"atl":[[17.5,0],[25,0]],"id":61631978}],"con":true,"img":false}]}
{"op":"mcm","clk":"11449454762","pt":1717309392781,"mc":[{"id":"1.229554905","rc":[{"atb":[[40,5.36],[50,2.13],[30,7.2]],"id":42269942},{"atl":[[610,0.34],[510,0.27]],"id":42269942},{"atb":[[9.8,11.87],[8.8,26.8],[7.8,30.74]],"id":57451148},{"atl":[[260,0.8],[160,0.87]],"id":57451148},{"atb":[[3.4,87.1],[3.9,36.04],[3.65,78.88]],"id":61631980},{"atl":[[19,7.74],[28,7.74]],"id":61631980},{"atb":[[3.25,92.91],[3.5,83.62],[3.75,38]],"id":61631978},{"atl":[[17.5,8.44],[25,8.71]],"id":61631978}],"con":true,"img":false}]}
{"op":"mcm","clk":"11449456317","pt":1717309418730,"mc":[{"id":"1.229554905","rc":[{"atb":[[40,0],[50,0],[30,0]],"id":42269942},{"atl":[[610,0],[510,0]],"id":42269942},{"atb":[[9.8,0],[8.8,0],[7.8,0]],"id":57451148},{"atl":[[260,0],[160,0]],"id":57451148},{"atb":[[3.4,0],[3.9,0],[3.65,0]],"id":61631980},{"atl":[[19,0],[28,0]],"id":61631980},{"atb":[[3.25,0],[3.5,0],[3.75,0]],"id":61631978},{"atl":[[17.5,0],[25,0]],"id":61631978}],"con":true,"img":false}]}
{"op":"mcm","clk":"11449457093","pt":1717309430980,"mc":[{"id":"1.229554905","rc":[{"atb":[[36,5.97],[46,2.32],[28,7.74]],"id":42269942},{"atl":[[590,0.35],[490,0.28]],"id":42269942},{"atb":[[9.2,25.49],[10.5,11],[8.2,29.03]],"id":57451148},{"atl":[[280,0.74],[180,0.77]],"id":57451148},{"atb":[[3.4,87.1],[3.9,36.04],[3.65,78.88]],"id":61631980},{"atl":[[19,7.74],[28,7.74]],"id":61631980},{"atb":[[3.4,87.1],[3.9,36.04],[3.65,78.88]],"id":61631978},{"atl":[[19,7.74],[28,7.74]],"id":61631978}],"con":true,"img":false}]}
{"op":"mcm","clk":"11449459037","pt":1717309460099,"mc":[{"id":"1.229554905","rc":[{"atb":[[36,0],[46,0],[28,0]],"id":42269942},{"atl":[[590,0],[490,0]],"id":42269942},{"atb":[[9.2,0],[10.5,0],[8.2,0]],"id":57451148},{"atl":[[280,0],[180,0]],"id":57451148},{"atb":[[3.4,0],[3.9,0],[3.65,0]],"id":61631980},{"atl":[[19,0],[28,0]],"id":61631980},{"atb":[[3.4,0],[3.9,0],[3.65,0]],"id":61631978},{"atl":[[19,0],[28,0]],"id":61631978}],"con":true,"img":false}]}
{"op":"mcm","clk":"11449460685","pt":1717309485524,"mc":[{"id":"1.229554905","rc":[{"atb":[[40,5.36],[50,2.13],[30,7.2]],"id":42269942},{"atl":[[610,0.34],[510,0.27]],"id":42269942},{"atb":[[9.2,25.49],[10.5,11],[8.2,29.03]],"id":57451148},{"atl":[[280,0.74],[180,0.77]],"id":57451148},{"atb":[[4.3,31.67],[3.9,72.08],[3.65,78.88]],"id":61631980},{"atl":[[34,6.33],[22,6.63]],"id":61631980},{"atb":[[3.25,92.91],[3.5,83.62],[3.75,38]],"id":61631978},{"atl":[[17.5,8.44],[25,8.71]],"id":61631978}],"con":true,"img":false}]}
{"op":"mcm","clk":"11449462408","pt":1717309511436,"mc":[{"id":"1.229554905","rc":[{"atb":[[40,0],[50,0],[30,0]],"id":42269942},{"atl":[[610,0],[510,0]],"id":42269942},{"atb":[[4.3,0],[3.9,0],[3.65,0]],"id":61631980},{"atl":[[34,0],[22,0]],"id":61631980},{"atb":[[3.25,0],[3.5,0],[3.75,0]],"id":61631978},{"atl":[[17.5,0],[25,0]],"id":61631978}],"con":true,"img":false}]}
{"op":"mcm","clk":"11449463292","pt":1717309524777,"mc":[{"id":"1.229554905","rc":[{"atb":[[40,5.36],[50,2.13],[30,7.2]],"id":42269942},{"atl":[[610,0.34],[510,0.27]],"id":42269942},{"spn":280.0,"spf":"NaN","id":42269942},{"spn":95.25,"spf":"NaN","id":57451148},{"atb":[[4.3,31.67],[3.9,72.08],[3.65,78.88]],"id":61631980},{"atl":[[34,6.33],[22,6.63]],"id":61631980},{"spn":13.15,"spf":"NaN","id":61631980},{"atb":[[3.4,87.1],[3.9,36.04],[3.65,78.88]],"id":61631978},{"atl":[[19,7.74],[28,7.74]],"id":61631978},{"spn":11.45,"spf":"NaN","id":61631978}],"con":true,"img":false}]}
{"op":"mcm","clk":"11449471746","pt":1717309643503,"mc":[{"id":"1.229554905","rc":[{"atb":[[40,0],[50,0],[30,0]],"id":42269942},{"atl":[[610,0],[510,0]],"id":42269942},{"spn":495.5,"spf":"NaN","id":42269942},{"atb":[[9.2,0],[10.5,0],[8.2,0]],"id":57451148},{"atl":[[280,0],[180,0]],"id":57451148},{"spn":495.51,"spf":"NaN","id":57451148},{"atb":[[4.3,0],[3.9,0],[3.65,0]],"id":61631980},{"atl":[[34,0],[22,0]],"id":61631980},{"spn":495.51,"spf":"NaN","id":61631980},{"atb":[[1.16,0],[1.11,0],[1.06,0]],"id":60780007},{"atl":[[2.46,0],[2.66,2.61]],"id":60780007},{"spn":1.5,"spf":"NaN","id":60780007},{"atb":[[3.4,0],[3.9,0],[3.65,0]],"id":61631978},{"atl":[[19,0],[28,0]],"id":61631978},{"spn":500.51,"spf":"NaN","id":61631978}],"con":true,"img":false}]}
{"op":"mcm","clk":"11449472678","pt":1717309655680,"mc":[{"id":"1.229554905","rc":[{"atb":[[34,6.33],[44,4.86],[60,1.77]],"id":42269942},{"atl":[[550,0.25],[650,0.32]],"id":42269942},{"atb":[[9.6,24.31],[8.6,27.5],[11.5,9.95]],"id":57451148},{"atl":[[300,0.7],[200,0.7]],"id":57451148},{"atb":[[4.3,31.67],[3.9,72.08],[3.65,78.88]],"id":61631980},{"atl":[[34,6.33],[22,6.63]],"id":61631980},{"atb":[[1.16,653.31],[1.11,1900.55],[1.06,3484.35]],"id":60780007},{"atl":[[2.46,95.46],[2.66,128.55]],"id":60780007},{"atb":[[3.4,87.1],[3.9,36.04],[3.65,78.88]],"id":61631978},{"atl":[[19,7.74],[28,7.74]],"id":61631978}],"con":true,"img":false}]}
{"op":"mcm","clk":"11449474621","pt":1717309682516,"mc":[{"id":"1.229554905","rc":[{"atb":[[34,0],[44,0],[60,0]],"id":42269942},{"atl":[[550,0],[650,0]],"id":42269942},{"atb":[[9.6,0],[8.6,0],[11.5,0]],"id":57451148},{"atl":[[300,0],[200,0]],"id":57451148},{"atb":[[4.3,0],[3.9,0],[3.65,0]],"id":61631980},{"atl":[[34,0],[22,0]],"id":61631980},{"atb":[[3.4,0],[3.9,0],[3.65,0]],"id":61631978},{"atl":[[19,0],[28,0]],"id":61631978}],"con":true,"img":false}]}
{"op":"mcm","clk":"11449475793","pt":1717309697516,"mc":[{"id":"1.229554905","rc":[{"atb":[[70,1.51],[38,5.65],[48,4.44]],"id":42269942},{"atl":[[630,0.21],[730,0.28]],"id":42269942},{"atb":[[9.6,24.31],[8.6,27.5],[11.5,9.95]],"id":57451148},{"atl":[[300,0.7],[200,0.7]],"id":57451148},{"atb":[[4.3,31.67],[3.9,72.08],[3.65,78.88]],"id":61631980},{"atl":[[34,6.33],[22,6.63]],"id":61631980},{"atb":[[3.4,87.1],[3.9,36.04],[3.65,78.88]],"id":61631978},{"atl":[[19,7.74],[28,7.74]],"id":61631978}],"con":true,"img":false}]}
{"op":"mcm","clk":"11449480356","pt":1717309728420,"mc":[{"id":"1.229554905","marketDefinition":{"bspMarket":true,"turnInPlayEnabled":false,"persistenceEnabled":false,"marketBaseRate":7.0,"eventId":"33318908","eventTypeId":"4339","numberOfWinners":1,"bettingType":"ODDS","marketType":"WIN","marketTime":"2024-06-02T09:20:00.000Z","suspendTime":"2024-06-02T09:20:00.000Z","bspReconciled":false,"complete":true,"inPlay":false,"crossMatching":true,"runnersVoidable":false,"numberOfActiveRunners":5,"betDelay":0,"status":"OPEN","runners":[{"status":"ACTIVE","sortPriority":1,"id":61631980,"name":"1. Opella"},{"status":"ACTIVE","sortPriority":2,"id":57451148,"name":"2. Taras Girl"},{"status":"ACTIVE","sortPriority":3,"id":61631978,"name":"4. Elwomple"},{"status":"ACTIVE","sortPriority":4,"id":42269942,"name":"6. Hey Sisco"},{"status":"ACTIVE","sortPriority":5,"id":60780007,"name":"8. Got Rhythm"}],"regulators":["MR_INT"],"venue":"Murray Bridge","countryCode":"AU","discountAllowed":true,"timezone":"Australia/Adelaide","openDate":"2024-06-02T08:21:00.000Z","version":5962317642,"name":"R4 395m Gr5","eventName":"Murray Bridge (AUS) 2nd Jun"},"rc":[{"atb":[[70,1.51],[38,5.65],[1.01,17.76],[48,4.44]],"id":42269942},{"atl":[[630,0.21],[730,0.28],[990,0.85]],"id":42269942},{"spn":350.0,"spf":"NaN","id":42269942},{"atb":[[9.6,24.31],[8.6,27.5],[1.03,5.92],[11.5,9.95]],"id":57451148},{"atl":[[300,0.7],[200,0.7],[990,0.85]],"id":57451148},{"spn":105.75,"spf":"NaN","id":57451148},{"atb":[[4.3,31.67],[1.02,8.87],[3.9,72.08],[3.65,78.88]],"id":61631980},{"atl":[[34,6.33],[22,6.63],[990,0.85]],"id":61631980},{"spn":13.15,"spf":"NaN","id":61631980},{"atb":[[1.01,17.76],[1.16,653.31],[1.11,1900.55],[1.06,3484.35]],"id":60780007},{"atl":[[2,4.73],[2.46,95.46],[2.66,128.55],[990,0.85]],"id":60780007},{"spn":1.58,"spf":"NaN","id":60780007},{"atb":[[1.03,5.92],[3.4,87.1],[3.9,36.04],[3.65,78.88]],"id":61631978},{"atl":[[19,7.74],[28,7.74],[1000,0.85]],"id":61631978},{"spn":11.45,"spf":"NaN","id":61631978}],"con":true,"img":true}]}
{"op":"mcm","clk":"11449495560","pt":1717309879327,"mc":[{"id":"1.229554905","rc":[{"atb":[[70,0],[38,0],[48,0]],"id":42269942},{"atl":[[630,0],[730,0]],"id":42269942},{"atb":[[9.6,0],[8.6,0],[11.5,0]],"id":57451148},{"atl":[[300,0],[200,0]],"id":57451148},{"atb":[[4.3,0],[3.9,0],[3.65,0]],"id":61631980},{"atl":[[34,0],[22,0]],"id":61631980},{"spn":1.58,"spf":"NaN","id":60780007},{"atb":[[3.4,0],[3.9,0],[3.65,0]],"id":61631978},{"atl":[[19,0],[28,0]],"id":61631978}],"con":true,"img":false}]}
{"op":"mcm","clk":"11449496101","pt":1717309887943,"mc":[{"id":"1.229554905","rc":[{"atb":[[70,1.51],[38,5.65],[48,4.44]],"id":42269942},{"atl":[[630,0.21],[730,0.28]],"id":42269942},{"atb":[[9.6,24.31],[8.6,27.5],[11.5,9.95]],"id":57451148},{"atl":[[300,0.7],[200,0.7]],"id":57451148},{"atb":[[4.3,31.67],[3.9,72.08],[3.65,78.88]],"id":61631980},{"atl":[[34,6.33],[22,6.63]],"id":61631980},{"atb":[[3.45,85.33],[3.95,35.43],[3.7,77.43]],"id":61631978},{"atl":[[19.5,7.53],[29,7.46]],"id":61631978}],"con":true,"img":false}]}
{"op":"mcm","clk":"11449528856","pt":1717310431735,"mc":[{"id":"1.229554905","rc":[{"atb":[[70,0],[38,0],[48,0]],"id":42269942},{"atl":[[630,0],[730,0]],"id":42269942},{"atb":[[9.6,0],[8.6,0],[11.5,0]],"id":57451148},{"atl":[[300,0],[200,0]],"id":57451148},{"atb":[[4.3,0],[3.9,0],[3.65,0]],"id":61631980},{"atl":[[34,0],[22,0]],"id":61631980},{"atb":[[1.16,0],[1.11,0],[1.06,0]],"id":60780007},{"atl":[[2.46,0],[2.66,2.61]],"id":60780007},{"spn":1.5,"spf":"NaN","id":60780007},{"atb":[[3.45,0],[3.95,0],[3.7,0]],"id":61631978},{"atl":[[19.5,0],[29,0]],"id":61631978}],"con":true,"img":false}]}
{"op":"mcm","clk":"11449530484","pt":1717310457770,"mc":[{"id":"1.229554905","rc":[{"atb":[[70,1.51],[38,5.65],[48,4.44]],"id":42269942},{"atl":[[630,0.21],[730,0.28]],"id":42269942},{"atb":[[9.6,24.31],[8.6,27.5],[11.5,9.95]],"id":57451148},{"atl":[[300,0.7],[200,0.7]],"id":57451148},{"atb":[[4.3,31.67],[3.9,72.08],[3.65,78.88]],"id":61631980},{"atl":[[34,6.33],[22,6.63]],"id":61631980},{"atb":[[1.16,653.31],[1.11,1900.55],[1.06,3484.35]],"id":60780007},{"atl":[[2.46,95.46],[2.66,128.55]],"id":60780007},{"atb":[[3.45,85.33],[3.95,35.43],[3.7,77.43]],"id":61631978},{"atl":[[19.5,7.53],[29,7.46]],"id":61631978}],"con":true,"img":false}]}
{"op":"mcm","clk":"11449586617","pt":1717311441817,"mc":[{"id":"1.229554905","rc":[{"atl":[[990,0.17]],"id":42269942},{"spn":350.0,"spf":"NaN","id":42269942},{"atl":[[990,0.17]],"id":57451148},{"spn":105.75,"spf":"NaN","id":57451148},{"atl":[[990,0.17]],"id":61631980},{"spn":13.15,"spf":"NaN","id":61631980},{"atl":[[990,0.17]],"id":60780007},{"spn":1.58,"spf":"NaN","id":60780007},{"atl":[[1000,0.17]],"id":61631978},{"spn":11.72,"spf":"NaN","id":61631978}],"con":true,"img":false}]}
{"op":"mcm","clk":"11449589743","pt":1717311498410,"mc":[{"id":"1.229554905","rc":[{"atb":[[70,0],[38,0],[48,0]],"id":42269942},{"atl":[[630,0],[730,0]],"id":42269942},{"atb":[[9.6,0],[8.6,0],[11.5,0]],"id":57451148},{"atl":[[300,0],[200,0]],"id":57451148},{"atb":[[4.3,0],[3.9,0],[3.65,0]],"id":61631980},{"atl":[[34,0],[22,0]],"id":61631980},{"atb":[[1.16,0],[1.11,0],[1.06,0]],"id":60780007},{"atl":[[2.46,0],[2.66,2.61]],"id":60780007},{"atb":[[3.45,0],[3.95,0],[3.7,0]],"id":61631978},{"atl":[[19.5,0],[29,0]],"id":61631978}],"con":true,"img":false}]}
{"op":"mcm","clk":"11449590382","pt":1717311508887,"mc":[{"id":"1.229554905","rc":[{"atb":[[70,1.51],[38,5.65],[48,4.44]],"id":42269942},{"atl":[[630,0.21],[730,0.28]],"id":42269942},{"atb":[[9.6,24.31],[8.6,27.5],[11.5,9.95]],"id":57451148},{"atl":[[300,0.7],[200,0.7]],"id":57451148},{"atb":[[4.3,31.67],[3.9,72.08],[3.65,78.88]],"id":61631980},{"atl":[[34,6.33],[22,6.63]],"id":61631980},{"atb":[[1.16,653.31],[1.11,1900.55],[1.06,3484.35]],"id":60780007},{"atl":[[2.46,95.46],[2.66,128.55]],"id":60780007},{"atb":[[3.45,85.33],[3.95,35.43],[3.7,77.43]],"id":61631978},{"atl":[[19.5,7.53],[29,7.46]],"id":61631978}],"con":true,"img":false}]}
{"op":"mcm","clk":"11449640544","pt":1717312587377,"mc":[{"id":"1.229554905","rc":[{"atb":[[70,0],[38,0],[48,0]],"id":42269942},{"atl":[[630,0],[730,0]],"id":42269942},{"spn":495.5,"spf":"NaN","id":42269942},{"atb":[[9.6,0],[8.6,0],[11.5,0]],"id":57451148},{"atl":[[300,0],[200,0]],"id":57451148},{"spn":495.51,"spf":"NaN","id":57451148},{"atb":[[4.3,0],[3.9,0],[3.65,0]],"id":61631980},{"atl":[[34,0],[22,0]],"id":61631980},{"spn":495.51,"spf":"NaN","id":61631980},{"atb":[[1.16,0],[1.11,0],[1.06,0]],"id":60780007},{"atl":[[2.46,0],[2.66,2.61]],"id":60780007},{"spn":1.5,"spf":"NaN","id":60780007},{"atb":[[3.45,0],[3.95,0],[3.7,0]],"id":61631978},{"atl":[[19.5,0],[29,0]],"id":61631978},{"spn":500.51,"spf":"NaN","id":61631978}],"con":true,"img":false}]}
{"op":"mcm","clk":"11449640837","pt":1717312594357,"mc":[{"id":"1.229554905","rc":[{"atb":[[70,1.51],[38,5.65],[48,4.44]],"id":42269942},{"atl":[[630,0.21],[730,0.28]],"id":42269942},{"atb":[[9.6,24.31],[8.6,27.5],[11.5,9.95]],"id":57451148},{"atl":[[300,0.7],[200,0.7]],"id":57451148},{"atb":[[4.3,31.67],[3.9,72.08],[3.65,78.88]],"id":61631980},{"atl":[[34,6.33],[22,6.63]],"id":61631980},{"atb":[[1.16,653.31],[1.11,1900.55],[1.06,3484.35]],"id":60780007},{"atl":[[2.46,95.46],[2.66,128.55]],"id":60780007},{"atb":[[3.45,85.33],[3.95,35.43],[3.7,77.43]],"id":61631978},{"atl":[[19.5,7.53],[29,7.46]],"id":61631978}],"con":true,"img":false}]}
{"op":"mcm","clk":"11449655533","pt":1717312944277,"mc":[{"id":"1.229554905","rc":[{"spn":350.0,"spf":"NaN","id":42269942},{"atl":[[50,5.23]],"id":57451148},{"spn":30.75,"spf":"NaN","id":57451148},{"spn":13.15,"spf":"NaN","id":61631980},{"spn":1.58,"spf":"NaN","id":60780007},{"spn":11.72,"spf":"NaN","id":61631978}],"con":true,"img":false}]}
{"op":"mcm","clk":"11449655996","pt":1717312956912,"mc":[{"id":"1.229554905","rc":[{"atl":[[600,52.31]],"id":57451148}],"con":true,"img":false}]}
{"op":"mcm","clk":"11449656387","pt":1717312965929,"mc":[{"id":"1.229554905","rc":[{"atl":[[600,5.23]],"id":57451148}],"con":true,"img":false}]}
{"op":"mcm","clk":"11449657155","pt":1717312984235,"mc":[{"id":"1.229554905","rc":[{"atl":[[700,5.23]],"id":57451148}],"con":true,"img":false}]}
{"op":"mcm","clk":"11449657772","pt":1717312999876,"mc":[{"id":"1.229554905","rc":[{"atl":[[900,15.69]],"id":57451148}],"con":true,"img":false}]}
{"op":"mcm","clk":"11449680060","pt":1717313440916,"mc":[{"id":"1.229554905","rc":[{"atb":[[70,0],[38,0],[48,0]],"id":42269942},{"atl":[[630,0],[730,0]],"id":42269942},{"spn":495.5,"spf":"NaN","id":42269942},{"atb":[[9.6,0],[8.6,0],[11.5,0]],"id":57451148},{"atl":[[300,0],[200,0]],"id":57451148},{"spn":25.51,"spf":"NaN","id":57451148},{"atb":[[4.3,0],[3.9,0],[3.65,0]],"id":61631980},{"atl":[[34,0],[22,0]],"id":61631980},{"spn":495.51,"spf":"NaN","id":61631980},{"atb":[[1.16,0],[1.11,0],[1.06,0]],"id":60780007},{"atl":[[2.46,0],[2.66,2.61]],"id":60780007},{"spn":1.5,"spf":"NaN","id":60780007},{"atb":[[3.45,0],[3.95,0],[3.7,0]],"id":61631978},{"atl":[[19.5,0],[29,0]],"id":61631978},{"spn":500.51,"spf":"NaN","id":61631978}],"con":true,"img":false}]}
{"op":"mcm","clk":"11449680658","pt":1717313449128,"mc":[{"id":"1.229554905","rc":[{"atb":[[70,1.51],[38,5.65],[48,4.44]],"id":42269942},{"atl":[[630,0.21],[730,0.28]],"id":42269942},{"atb":[[9.6,24.31],[8.6,27.5],[11.5,9.95]],"id":57451148},{"atl":[[300,0.7],[200,0.7]],"id":57451148},{"atb":[[4.3,31.67],[3.9,72.08],[3.65,78.88]],"id":61631980},{"atl":[[34,6.33],[22,6.63]],"id":61631980},{"atb":[[1.16,653.31],[1.11,1900.55],[1.06,3484.35]],"id":60780007},{"atl":[[2.46,95.46],[2.66,128.55]],"id":60780007},{"atb":[[3.45,85.33],[3.95,35.43],[3.7,77.43]],"id":61631978},{"atl":[[19.5,7.53],[29,7.46]],"id":61631978}],"con":true,"img":false}]}
{"op":"mcm","clk":"11449753578","pt":1717314283242,"mc":[{"id":"1.229554905","rc":[{"atb":[[70,0],[38,0],[48,0]],"id":42269942},{"atl":[[630,0],[730,0]],"id":42269942},{"atb":[[9.6,0],[8.6,0],[11.5,0]],"id":57451148},{"atl":[[300,0],[200,0]],"id":57451148},{"atb":[[4.3,0],[3.9,0],[3.65,0]],"id":61631980},{"atl":[[34,0],[22,0]],"id":61631980},{"atb":[[1.16,0],[1.11,0],[1.06,0]],"id":60780007},{"atl":[[2.46,0],[2.66,2.61]],"id":60780007},{"atb":[[3.45,0],[3.95,0],[3.7,0]],"id":61631978},{"atl":[[19.5,0],[29,0]],"id":61631978}],"con":true,"img":false}]}
{"op":"mcm","clk":"11449754582","pt":1717314295554,"mc":[{"id":"1.229554905","rc":[{"atb":[[70,1.51],[38,5.65],[48,4.44]],"id":42269942},{"atl":[[630,0.21],[730,0.28]],"id":42269942},{"atb":[[9.6,24.31],[8.6,27.5],[11.5,9.95]],"id":57451148},{"atl":[[300,0.7],[200,0.7]],"id":57451148},{"atb":[[4.3,31.67],[3.9,72.08],[3.65,78.88]],"id":61631980},{"atl":[[34,6.33],[22,6.63]],"id":61631980},{"atb":[[1.16,653.31],[1.11,1900.55],[1.06,3484.35]],"id":60780007},{"atl":[[2.46,95.46],[2.66,128.55]],"id":60780007},{"atb":[[3.45,85.33],[3.95,35.43],[3.7,77.43]],"id":61631978},{"atl":[[19.5,7.53],[29,7.46]],"id":61631978}],"con":true,"img":false}]}
{"op":"mcm","clk":"11449801989","pt":1717314839394,"mc":[{"id":"1.229554905","rc":[{"atb":[[75,2.61],[60,2.61]],"id":42269942},{"spn":352.5,"spf":"NaN","id":42269942},{"atb":[[12,5.1],[9.8,12.19]],"id":57451148},{"atl":[[80,2.61],[110,2.61]],"id":57451148},{"spn":31.0,"spf":"NaN","id":57451148},{"atb":[[4.6,15.58],[3.95,40.8]],"id":61631980},{"atl":[[18,3.3],[21,5.75]],"id":61631980},{"spn":11.3,"spf":"NaN","id":61631980},{"atb":[[1.19,164.82],[1.17,689.36]],"id":60780007},{"atl":[[2.44,81.38],[2.2,46.75]],"id":60780007},{"spn":1.59,"spf":"NaN","id":60780007},{"atb":[[4,18.7],[3.75,41.18]],"id":61631978},{"atl":[[19,6.29],[15,4]],"id":61631978},{"spn":9.5,"spf":"NaN","id":61631978}],"con":true,"img":false}]}
{"op":"mcm","clk":"11449802988","pt":1717314851573,"mc":[{"id":"1.229554905","rc":[{"atl":[[1000,2.52]],"id":61631978}],"con":true,"img":false}]}
{"op":"mcm","clk":"11449803005","pt":1717314851779,"mc":[{"id":"1.229554905","rc":[{"atl":[[1000,1.15]],"id":61631978}],"con":true,"img":false}]}
{"op":"mcm","clk":"11449803023","pt":1717314851988,"mc":[{"id":"1.229554905","rc":[{"atl":[[1000,0.17]],"id":61631978}],"con":true,"img":false}]}
{"op":"mcm","clk":"11449803032","pt":1717314852088,"mc":[{"id":"1.229554905","rc":[{"atl":[[13.5,0.98]],"id":61631978}],"con":true,"img":false}]}
{"op":"mcm","clk":"11449803049","pt":1717314852297,"mc":[{"id":"1.229554905","rc":[{"atl":[[13.5,2.42]],"id":61631978}],"con":true,"img":false}]}
{"op":"mcm","clk":"11449803056","pt":1717314852401,"mc":[{"id":"1.229554905","rc":[{"atl":[[2.1,9.18]],"id":60780007}],"con":true,"img":false}]}
{"op":"mcm","clk":"11449807700","pt":1717314906154,"mc":[{"id":"1.229554905","rc":[{"atb":[[3.95,0]],"id":61631980},{"atb":[[1.19,95.36]],"id":60780007},{"atb":[[3.75,0]],"id":61631978},{"spn":8.75,"spf":"NaN","id":61631978}],"con":true,"img":false}]}
{"op":"mcm","clk":"11449807713","pt":1717314906257,"mc":[{"id":"1.229554905","rc":[{"atb":[[4.4,40.8]],"id":61631980},{"atb":[[4,59.89]],"id":61631978}],"con":true,"img":false}]}
{"op":"mcm","clk":"11449819106","pt":1717315032355,"mc":[{"id":"1.229554905","rc":[{"atl":[[13.5,1.43]],"id":61631978}],"con":true,"img":false}]}
{"op":"mcm","clk":"11449819231","pt":1717315033448,"mc":[{"id":"1.229554905","rc":[{"atl":[[13.5,0]],"id":61631978}],"con":true,"img":false}]}
{"op":"mcm","clk":"11449819741","pt":1717315038650,"mc":[{"id":"1.229554905","rc":[{"atl":[[1000,2.52]],"id":61631978}],"con":true,"img":false}]}
{"op":"mcm","clk":"11449819759","pt":1717315038857,"mc":[{"id":"1.229554905","rc":[{"atl":[[1000,1.15]],"id":61631978}],"con":true,"img":false}]}
{"op":"mcm","clk":"11449819785","pt":1717315039082,"mc":[{"id":"1.229554905","rc":[{"atl":[[1000,0.17]],"id":61631978}],"con":true,"img":false}]}
{"op":"mcm","clk":"11449819797","pt":1717315039171,"mc":[{"id":"1.229554905","rc":[{"atl":[[13.5,0.98]],"id":61631978}],"con":true,"img":false}]}
{"op":"mcm","clk":"11449821656","pt":1717315058181,"mc":[{"id":"1.229554905","rc":[{"atl":[[2.1,0]],"id":60780007}],"con":true,"img":false}]}
{"op":"mcm","clk":"11449825722","pt":1717315101944,"mc":[{"id":"1.229554905","rc":[{"atl":[[13.5,2.42]],"id":61631978}],"con":true,"img":false}]}
{"op":"mcm","clk":"11449825732","pt":1717315102048,"mc":[{"id":"1.229554905","rc":[{"atl":[[2.1,9.18]],"id":60780007}],"con":true,"img":false}]}
{"op":"mcm","clk":"11449827909","pt":1717315126946,"mc":[{"id":"1.229554905","rc":[{"atb":[[1.03,114.18]],"id":42269942},{"atl":[[960,0.85]],"id":42269942},{"atb":[[1.02,159.35]],"id":57451148},{"atl":[[970,1.3]],"id":57451148},{"atb":[[1.02,205.72]],"id":61631980},{"atl":[[960,0.85]],"id":61631980},{"atb":[[1.02,138.04]],"id":60780007},{"atl":[[980,1.97]],"id":60780007},{"atb":[[1.03,77.5]],"id":61631978},{"atl":[[960,0.85]],"id":61631978}],"con":true,"img":false}]}
{"op":"mcm","clk":"11449837907","pt":1717315160824,"mc":[{"id":"1.229554905","rc":[{"atb":[[70,0],[38,0],[48,0]],"id":42269942},{"atl":[[630,0],[730,0]],"id":42269942},{"atb":[[9.6,0],[8.6,0],[11.5,0]],"id":57451148},{"atl":[[300,0],[200,0]],"id":57451148},{"atb":[[4.3,0],[3.9,0],[3.65,0]],"id":61631980},{"atl":[[34,0],[22,0]],"id":61631980},{"atb":[[1.16,0],[1.11,0],[1.06,0]],"id":60780007},{"atl":[[2.46,0],[2.66,2.61]],"id":60780007},{"atb":[[3.45,0],[3.95,0],[3.7,0]],"id":61631978},{"atl":[[19.5,0],[29,0]],"id":61631978}],"con":true,"img":false}]}
{"op":"mcm","clk":"11449839250","pt":1717315174649,"mc":[{"id":"1.229554905","rc":[{"atb":[[6.2,9.62],[4.1,16.13],[2.12,44.64],[1.51,98.04],[3.05,24.39]],"id":42269942},{"spn":517.5,"spf":"NaN","id":42269942},{"atb":[[4.1,16.13],[2.12,44.64],[1.51,98.04],[3.05,24.39]],"id":57451148},{"atb":[[1.51,98.04]],"id":61631980},{"atl":[[16,10],[34,10]],"id":60780007},{"atb":[[1.51,98.04]],"id":61631978}],"con":true,"img":false}]}
{"op":"mcm","clk":"11449840412","pt":1717315186550,"mc":[{"id":"1.229554905","rc":[{"atb":[[4.4,0]],"id":61631980},{"atl":[[21,0]],"id":61631980},{"atl":[[2.44,0],[2.76,66.58]],"id":60780007},{"atb":[[4,18.7]],"id":61631978}],"con":true,"img":false}]}
{"op":"mcm","clk":"11449840421","pt":1717315186658,"mc":[{"id":"1.229554905","rc":[{"atb":[[3.9,40.8]],"id":61631980},{"atl":[[25,5.75]],"id":61631980},{"atb":[[3.4,41.18]],"id":61631978}],"con":true,"img":false}]}
{"op":"mcm","clk":"11449841719","pt":1717315200200,"mc":[{"id":"1.229554905","rc":[{"atb":[[70,1.51],[38,5.65],[48,4.44]],"id":42269942},{"atl":[[630,0.21],[730,0.28]],"id":42269942},{"atb":[[9.6,24.31],[8.6,27.5],[11.5,9.95]],"id":57451148},{"atl":[[300,0.7],[200,0.7]],"id":57451148},{"atb":[[4.3,31.67],[3.9,112.89],[3.65,78.88]],"id":61631980},{"atl":[[34,6.33],[22,6.63]],"id":61631980},{"atb":[[1.16,653.31],[1.11,1900.55],[1.06,3484.35]],"id":60780007},{"atl":[[2.46,95.46],[2.66,128.55]],"id":60780007},{"atb":[[3.45,85.33],[3.95,35.43],[3.7,77.43]],"id":61631978},{"atl":[[19.5,7.53],[29,7.46]],"id":61631978}],"con":true,"img":false}]}
{"op":"mcm","clk":"11449844883","pt":1717315229711,"mc":[{"id":"1.229554905","rc":[{"atl":[[13.5,1.43]],"id":61631978}],"con":true,"img":false}]}
{"op":"mcm","clk":"11449846334","pt":1717315246121,"mc":[{"id":"1.229554905","rc":[{"spn":352.5,"spf":"NaN","id":42269942},{"atl":[[1000,2.52]],"id":61631978}],"con":true,"img":false}]}
{"op":"mcm","clk":"11449846363","pt":1717315246431,"mc":[{"id":"1.229554905","rc":[{"atl":[[1000,1.15]],"id":61631978}],"con":true,"img":false}]}
{"op":"mcm","clk":"11449846385","pt":1717315246635,"mc":[{"id":"1.229554905","rc":[{"atl":[[1000,0.17]],"id":61631978}],"con":true,"img":false}]}
{"op":"mcm","clk":"11449846400","pt":1717315246753,"mc":[{"id":"1.229554905","rc":[{"atl":[[13.5,2.42]],"id":61631978}],"con":true,"img":false}]}
{"op":"mcm","clk":"11449848394","pt":1717315266658,"mc":[{"id":"1.229554905","rc":[{"atb":[[3.9,72.08]],"id":61631980},{"atl":[[25,0]],"id":61631980},{"atl":[[2.44,81.38],[2.76,0]],"id":60780007},{"atb":[[3.4,0]],"id":61631978}],"con":true,"img":false}]}
{"op":"mcm","clk":"11449848403","pt":1717315266759,"mc":[{"id":"1.229554905","rc":[{"atb":[[4.4,40.8]],"id":61631980},{"atl":[[21,5.75]],"id":61631980},{"atb":[[4,59.89]],"id":61631978}],"con":true,"img":false}]}
{"op":"mcm","clk":"11449852932","pt":1717315313938,"mc":[{"id":"1.229554905","rc":[{"atl":[[13.5,0.98]],"id":61631978}],"con":true,"img":false}]}
{"op":"mcm","clk":"11449854561","pt":1717315329854,"mc":[{"id":"1.229554905","rc":[{"atl":[[2.1,0]],"id":60780007}],"con":true,"img":false}]}
{"op":"mcm","clk":"11449858803","pt":1717315370688,"mc":[{"id":"1.229554905","rc":[{"atl":[[13.5,2.42]],"id":61631978}],"con":true,"img":false}]}
{"op":"mcm","clk":"11449858880","pt":1717315371416,"mc":[{"id":"1.229554905","rc":[{"atl":[[2.1,9.18]],"id":60780007}],"con":true,"img":false}]}
{"op":"mcm","clk":"11449865309","pt":1717315436297,"mc":[{"id":"1.229554905","rc":[{"atl":[[13.5,1.43]],"id":61631978}],"con":true,"img":false}]}
{"op":"mcm","clk":"11449866999","pt":1717315451773,"mc":[{"id":"1.229554905","rc":[{"atl":[[1000,2.52]],"id":61631978}],"con":true,"img":false}]}
{"op":"mcm","clk":"11449867025","pt":1717315451978,"mc":[{"id":"1.229554905","rc":[{"atl":[[1000,1.15]],"id":61631978}],"con":true,"img":false}]}
{"op":"mcm","clk":"11449867084","pt":1717315452495,"mc":[{"id":"1.229554905","rc":[{"atl":[[1000,0.17]],"id":61631978}],"con":true,"img":false}]}
{"op":"mcm","clk":"11449867095","pt":1717315452551,"mc":[{"id":"1.229554905","rc":[{"atl":[[13.5,2.42]],"id":61631978}],"con":true,"img":false}]}
{"op":"mcm","clk":"11449880120","pt":1717315580519,"mc":[{"id":"1.229554905","rc":[{"atl":[[13.5,0.98]],"id":61631978}],"con":true,"img":false}]}
{"op":"mcm","clk":"11449882383","pt":1717315602865,"mc":[{"id":"1.229554905","rc":[{"atl":[[2.1,0]],"id":60780007}],"con":true,"img":false}]}
{"op":"mcm","clk":"11449886702","pt":1717315644084,"mc":[{"id":"1.229554905","rc":[{"atl":[[13.5,0]],"id":61631978},{"spn":9.5,"spf":"NaN","id":61631978}],"con":true,"img":false}]}
{"op":"mcm","clk":"11449887574","pt":1717315652807,"mc":[{"id":"1.229554905","rc":[{"atl":[[13.5,1.43]],"id":61631978}],"con":true,"img":false}]}
{"op":"mcm","clk":"11449887593","pt":1717315653015,"mc":[{"id":"1.229554905","rc":[{"atl":[[2.1,9.18]],"id":60780007}],"con":true,"img":false}]}
{"op":"mcm","clk":"11449888120","pt":1717315658233,"mc":[{"id":"1.229554905","rc":[{"atl":[[1000,2.52]],"id":61631978}],"con":true,"img":false}]}
{"op":"mcm","clk":"11449888141","pt":1717315658397,"mc":[{"id":"1.229554905","rc":[{"atl":[[1000,1.15]],"id":61631978}],"con":true,"img":false}]}
{"op":"mcm","clk":"11449888170","pt":1717315658701,"mc":[{"id":"1.229554905","rc":[{"atl":[[1000,0.17]],"id":61631978}],"con":true,"img":false}]}
{"op":"mcm","clk":"11449888180","pt":1717315658804,"mc":[{"id":"1.229554905","rc":[{"atl":[[13.5,2.42]],"id":61631978}],"con":true,"img":false}]}
{"op":"mcm","clk":"11449888277","pt":1717315659736,"mc":[{"id":"1.229554905","rc":[{"atl":[[18,0]],"id":61631980},{"atb":[[4,18.7]],"id":61631978},{"atl":[[15,0]],"id":61631978}],"con":true,"img":false}]}
{"op":"mcm","clk":"11449888290","pt":1717315659790,"mc":[{"id":"1.229554905","rc":[{"atl":[[17.5,3.3]],"id":61631980},{"atb":[[3.75,41.18]],"id":61631978},{"atl":[[14.5,4]],"id":61631978}],"con":true,"img":false}]}
{"op":"mcm","clk":"11449888493","pt":1717315662024,"mc":[{"id":"1.229554905","rc":[{"atb":[[4.4,0]],"id":61631980}],"con":true,"img":false}]}
{"op":"mcm","clk":"11449888506","pt":1717315662130,"mc":[{"id":"1.229554905","rc":[{"atb":[[3.95,40.8]],"id":61631980}],"con":true,"img":false}]}
{"op":"mcm","clk":"11449891827","pt":1717315694954,"mc":[{"id":"1.229554905","rc":[{"atb":[[12,0]],"id":57451148}],"con":true,"img":false}]}
{"op":"mcm","clk":"11449891838","pt":1717315695060,"mc":[{"id":"1.229554905","rc":[{"atb":[[12.5,5.1]],"id":57451148}],"con":true,"img":false}]}
{"op":"mcm","clk":"11449893625","pt":1717315712406,"mc":[{"id":"1.229554905","rc":[{"atb":[[70,0],[38,0],[48,0]],"id":42269942},{"atl":[[630,0],[730,0]],"id":42269942},{"spn":517.5,"spf":"NaN","id":42269942},{"atb":[[9.6,0],[8.6,0],[11.5,0]],"id":57451148},{"atl":[[300,0],[200,0]],"id":57451148},{"spn":31.25,"spf":"NaN","id":57451148},{"atb":[[4.3,0],[3.9,0],[3.65,0]],"id":61631980},{"atl":[[34,0],[22,0]],"id":61631980},{"spn":11.05,"spf":"NaN","id":61631980},{"atb":[[1.16,0],[1.11,0],[1.06,0]],"id":60780007},{"atl":[[2.46,0],[2.66,2.61]],"id":60780007},{"atb":[[3.45,0],[3.95,0],[3.7,0]],"id":61631978},{"atl":[[19.5,0],[29,0]],"id":61631978},{"spn":8.75,"spf":"NaN","id":61631978}],"con":true,"img":false}]}
{"op":"mcm","clk":"11449894175","pt":1717315717569,"mc":[{"id":"1.229554905","rc":[{"atl":[[21,0]],"id":61631980},{"atl":[[2.44,0],[2.78,65.83]],"id":60780007},{"atb":[[3.75,0]],"id":61631978}],"con":true,"img":false}]}
{"op":"mcm","clk":"11449894190","pt":1717315717676,"mc":[{"id":"1.229554905","rc":[{"atl":[[24,5.75]],"id":61631980},{"atb":[[3.3,41.18]],"id":61631978}],"con":true,"img":false}]}
{"op":"mcm","clk":"11449896030","pt":1717315734435,"mc":[{"id":"1.229554905","rc":[{"atb":[[12.5,0],[9.8,0]],"id":57451148}],"con":true,"img":false}]}
{"op":"mcm","clk":"11449896042","pt":1717315734539,"mc":[{"id":"1.229554905","rc":[{"atb":[[10.5,5.1],[8.4,12.19]],"id":57451148}],"con":true,"img":false}]}
{"op":"mcm","clk":"11449896887","pt":1717315742884,"mc":[{"id":"1.229554905","rc":[{"atb":[[40,5.36],[50,2.13],[30,7.2]],"id":42269942},{"atl":[[610,0.34],[510,0.27]],"id":42269942},{"atb":[[9.6,24.31],[8.6,27.5],[11.5,9.95]],"id":57451148},{"atl":[[300,0.7],[200,0.7]],"id":57451148},{"atb":[[4.3,31.67],[3.9,72.08],[3.65,78.88]],"id":61631980},{"atl":[[34,6.33],[22,6.63]],"id":61631980},{"atb":[[1.18,1161.45],[1.23,454.48],[1.13,1608.16]],"id":60780007},{"atl":[[2.64,84.98],[2.84,113.61]],"id":60780007},{"atb":[[3.4,87.1],[3.9,36.04],[3.65,78.88]],"id":61631978},{"atl":[[19,14.03],[28,7.74]],"id":61631978}],"con":true,"img":false}]}
{"op":"mcm","clk":"11449898751","pt":1717315760005,"mc":[{"id":"1.229554905","rc":[{"atb":[[2.12,44.64]],"id":61631980}],"con":true,"img":false}]}
{"op":"mcm","clk":"11449899131","pt":1717315763679,"mc":[{"id":"1.229554905","rc":[{"atl":[[80,0]],"id":57451148},{"atb":[[4,0]],"id":61631978}],"con":true,"img":false}]}
{"op":"mcm","clk":"11449899142","pt":1717315763782,"mc":[{"id":"1.229554905","rc":[{"atl":[[75,2.61]],"id":57451148},{"atb":[[4.1,18.7]],"id":61631978}],"con":true,"img":false}]}
{"op":"mcm","clk":"11449904190","pt":1717315812771,"mc":[{"id":"1.229554905","rc":[{"spn":292.5,"spf":"NaN","id":42269942},{"atb":[[8.4,0]],"id":57451148},{"spn":30.75,"spf":"NaN","id":57451148},{"atb":[[3.95,0]],"id":61631980},{"atl":[[24,0]],"id":61631980},{"atb":[[1.19,0],[1.17,0]],"id":60780007},{"atl":[[2.78,0]],"id":60780007},{"spn":1.61,"spf":"NaN","id":60780007},{"atb":[[3.3,0]],"id":61631978},{"spn":8.8,"spf":"NaN","id":61631978}],"con":true,"img":false}]}
{"op":"mcm","clk":"11449904199","pt":1717315812876,"mc":[{"id":"1.229554905","rc":[{"atb":[[9.8,12.19]],"id":57451148},{"atb":[[4.4,40.8]],"id":61631980},{"atl":[[21,5.75]],"id":61631980},{"atb":[[1.19,689.36],[1.24,95.36]],"id":60780007},{"atl":[[2.62,65.83]],"id":60780007},{"atb":[[3.95,41.18]],"id":61631978}],"con":true,"img":false}]}
{"op":"mcm","clk":"11449906380","pt":1717315834620,"mc":[{"id":"1.229554905","rc":[{"atb":[[10.5,0]],"id":57451148}],"con":true,"img":false}]}
{"op":"mcm","clk":"11449906390","pt":1717315834720,"mc":[{"id":"1.229554905","rc":[{"atb":[[12,5.1]],"id":57451148}],"con":true,"img":false}]}
{"op":"mcm","clk":"11449907200","pt":1717315842993,"mc":[{"id":"1.229554905","rc":[{"atl":[[13.5,1.43]],"id":61631978}],"con":true,"img":false}]}
{"op":"mcm","clk":"11449908808","pt":1717315858153,"mc":[{"id":"1.229554905","rc":[{"atl":[[1000,2.52]],"id":61631978}],"con":true,"img":false}]}
{"op":"mcm","clk":"11449908829","pt":1717315858311,"mc":[{"id":"1.229554905","rc":[{"atl":[[1000,1.15]],"id":61631978}],"con":true,"img":false}]}
{"op":"mcm","clk":"11449908852","pt":1717315858512,"mc":[{"id":"1.229554905","rc":[{"atl":[[1000,0.17]],"id":61631978}],"con":true,"img":false}]}
{"op":"mcm","clk":"11449908865","pt":1717315858619,"mc":[{"id":"1.229554905","rc":[{"atl":[[13.5,2.42]],"id":61631978}],"con":true,"img":false}]}
{"op":"mcm","clk":"11449912974","pt":1717315896559,"mc":[{"id":"1.229554905","rc":[{"spn":31.0,"spf":"NaN","id":57451148},{"spn":1.62,"spf":"NaN","id":60780007},{"atl":[[13.5,0.98]],"id":61631978}],"con":true,"img":false}]}
{"op":"mcm","clk":"11449917602","pt":1717315940629,"mc":[{"id":"1.229554905","rc":[{"atl":[[2.1,0]],"id":60780007}],"con":true,"img":false}]}
{"op":"mcm","clk":"11449924783","pt":1717316009514,"mc":[{"id":"1.229554905","rc":[{"atb":[[40,0],[50,0],[30,0]],"id":42269942},{"atl":[[610,0],[510,0]],"id":42269942},{"spn":517.5,"spf":"NaN","id":42269942},{"atb":[[9.6,0],[8.6,0],[11.5,0]],"id":57451148},{"atl":[[300,0],[200,0]],"id":57451148},{"atb":[[4.3,0],[3.9,0],[3.65,0]],"id":61631980},{"atl":[[34,0],[22,0]],"id":61631980},{"atb":[[1.18,0],[1.23,0],[1.13,0]],"id":60780007},{"atl":[[2.64,0],[2.84,0]],"id":60780007},{"atb":[[3.4,0],[3.9,0],[3.65,0]],"id":61631978},{"atl":[[19,6.29],[28,0]],"id":61631978}],"con":true,"img":false}]}
{"op":"mcm","clk":"11449925653","pt":1717316019046,"mc":[{"id":"1.229554905","rc":[{"atb":[[4.4,0]],"id":61631980},{"atl":[[21,0]],"id":61631980},{"atb":[[1.19,0],[1.24,0]],"id":60780007},{"atb":[[3.95,0]],"id":61631978}],"con":true,"img":false}]}
{"op":"mcm","clk":"11449925661","pt":1717316019145,"mc":[{"id":"1.229554905","rc":[{"atb":[[3.85,40.8]],"id":61631980},{"atl":[[24,5.75]],"id":61631980},{"atb":[[1.15,689.36],[1.19,95.36]],"id":60780007},{"atb":[[3.45,41.18]],"id":61631978}],"con":true,"img":false}]}
{"op":"mcm","clk":"11449926999","pt":1717316032550,"mc":[{"id":"1.229554905","rc":[{"atb":[[40,5.36],[50,2.13],[30,7.2]],"id":42269942},{"atl":[[610,0.34],[510,0.27]],"id":42269942},{"atb":[[9.6,24.31],[8.6,27.5],[11.5,9.95]],"id":57451148},{"atl":[[300,0.7],[200,0.7]],"id":57451148},{"atb":[[4.3,31.67],[3.9,72.08],[3.65,78.88]],"id":61631980},{"atl":[[34,6.33],[22,6.63]],"id":61631980},{"atb":[[1.18,1161.45],[1.23,454.48],[1.13,1608.16]],"id":60780007},{"atl":[[2.64,84.98],[2.84,113.61]],"id":60780007},{"atb":[[3.4,87.1],[3.9,36.04],[3.65,78.88]],"id":61631978},{"atl":[[19,14.03],[28,7.74]],"id":61631978}],"con":true,"img":false}]}
{"op":"mcm","clk":"11449928213","pt":1717316044489,"mc":[{"id":"1.229554905","rc":[{"atl":[[13.5,0]],"id":61631978}],"con":true,"img":false}]}
{"op":"mcm","clk":"11449931608","pt":1717316081223,"mc":[{"id":"1.229554905","rc":[{"spn":292.5,"spf":"NaN","id":42269942},{"atb":[[1.19,0]],"id":60780007},{"spn":1.61,"spf":"NaN","id":60780007},{"spn":9.3,"spf":"NaN","id":61631978}],"con":true,"img":false}]}
{"op":"mcm","clk":"11449931616","pt":1717316081331,"mc":[{"id":"1.229554905","rc":[{"atb":[[1.24,95.36]],"id":60780007}],"con":true,"img":false}]}
{"op":"mcm","clk":"11449933484","pt":1717316101760,"mc":[{"id":"1.229554905","rc":[{"atb":[[3.85,0]],"id":61631980},{"atl":[[24,0]],"id":61631980},{"atb":[[1.15,0]],"id":60780007},{"atb":[[3.45,0]],"id":61631978}],"con":true,"img":false}]}
{"op":"mcm","clk":"11449933491","pt":1717316101863,"mc":[{"id":"1.229554905","rc":[{"atb":[[4.4,40.8]],"id":61631980},{"atl":[[21,5.75]],"id":61631980},{"atb":[[1.19,689.36]],"id":60780007},{"atb":[[3.95,41.18]],"id":61631978}],"con":true,"img":false}]}
{"op":"mcm","clk":"11449934419","pt":1717316111958,"mc":[{"id":"1.229554905","rc":[{"atl":[[13.5,1.43]],"id":61631978}],"con":true,"img":false}]}
{"op":"mcm","clk":"11449934441","pt":1717316112169,"mc":[{"id":"1.229554905","rc":[{"atl":[[2.1,9.18]],"id":60780007}],"con":true,"img":false}]}
{"op":"mcm","clk":"11449934701","pt":1717316114971,"mc":[{"id":"1.229554905","rc":[{"atl":[[1000,2.52]],"id":61631978}],"con":true,"img":false}]}
{"op":"mcm","clk":"11449934718","pt":1717316115175,"mc":[{"id":"1.229554905","rc":[{"atl":[[1000,1.15]],"id":61631978}],"con":true,"img":false}]}
{"op":"mcm","clk":"11449934738","pt":1717316115380,"mc":[{"id":"1.229554905","rc":[{"atl":[[1000,0.17]],"id":61631978}],"con":true,"img":false}]}
{"op":"mcm","clk":"11449934749","pt":1717316115487,"mc":[{"id":"1.229554905","rc":[{"atl":[[13.5,2.42]],"id":61631978}],"con":true,"img":false}]}
{"op":"mcm","clk":"11449950662","pt":1717316291609,"mc":[{"id":"1.229554905","rc":[{"trd":[[510,0.54]],"ltp":510.0,"tv":0.54,"id":42269942},{"atl":[[510,0]],"id":42269942},{"spn":342.5,"spf":"NaN","id":42269942},{"spn":1.62,"spf":"NaN","id":60780007},{"spn":8.8,"spf":"NaN","id":61631978}],"con":true,"img":false}]}
{"op":"mcm","clk":"11449952208","pt":1717316308945,"mc":[{"id":"1.229554905","rc":[{"atl":[[13.5,1.43]],"id":61631978}],"con":true,"img":false}]}
{"op":"mcm","clk":"11449952368","pt":1717316310761,"mc":[{"id":"1.229554905","rc":[{"atl":[[13.5,0]],"id":61631978}],"con":true,"img":false}]}
{"op":"mcm","clk":"11449953532","pt":1717316324055,"mc":[{"id":"1.229554905","rc":[{"atl":[[1000,2.52]],"id":61631978}],"con":true,"img":false}]}
{"op":"mcm","clk":"11449953564","pt":1717316324376,"mc":[{"id":"1.229554905","rc":[{"atl":[[1000,1.15]],"id":61631978}],"con":true,"img":false}]}
{"op":"mcm","clk":"11449953588","pt":1717316324680,"mc":[{"id":"1.229554905","rc":[{"atl":[[1000,0.17]],"id":61631978}],"con":true,"img":false}]}
{"op":"mcm","clk":"11449953600","pt":1717316324781,"mc":[{"id":"1.229554905","rc":[{"atl":[[13.5,0.98]],"id":61631978}],"con":true,"img":false}]}
{"op":"mcm","clk":"11449955616","pt":1717316350679,"mc":[{"id":"1.229554905","rc":[{"atl":[[2.1,0]],"id":60780007}],"con":true,"img":false}]}
{"op":"mcm","clk":"11449957136","pt":1717316370735,"mc":[{"id":"1.229554905","rc":[{"atl":[[2.1,9.18]],"id":60780007}],"con":true,"img":false}]}
{"op":"mcm","clk":"11449957144","pt":1717316370834,"mc":[{"id":"1.229554905","rc":[{"atl":[[13.5,2.42]],"id":61631978}],"con":true,"img":false}]}
{"op":"mcm","clk":"11449959396","pt":1717316400521,"mc":[{"id":"1.229554905","rc":[{"atb":[[40,7.92]],"id":42269942},{"atb":[[1.53,98.04]],"id":57451148},{"atb":[[2.74,57.47]],"id":61631980},{"atl":[[26,4]],"id":61631980},{"atl":[[4.3,30.3]],"id":60780007},{"atb":[[2.24,80.65]],"id":61631978},{"atl":[[21,5]],"id":61631978}],"con":true,"img":false}]}
{"op":"mcm","clk":"11449959549","pt":1717316402495,"mc":[{"id":"1.229554905","rc":[{"atb":[[2.74,0],[2.5,66.67]],"id":61631980}],"con":true,"img":false}]}
{"op":"mcm","clk":"11449965993","pt":1717316485213,"mc":[{"id":"1.229554905","rc":[{"atb":[[40,5.36],[44,2.33]],"id":42269942}],"con":true,"img":false}]}
{"op":"mcm","clk":"11449967665","pt":1717316509311,"mc":[{"id":"1.229554905","rc":[{"atl":[[13.5,1.43]],"id":61631978}],"con":true,"img":false}]}
{"op":"mcm","clk":"11449968631","pt":1717316524313,"mc":[{"id":"1.229554905","rc":[{"atl":[[1000,2.52]],"id":61631978}],"con":true,"img":false}]}
{"op":"mcm","clk":"11449968652","pt":1717316524623,"mc":[{"id":"1.229554905","rc":[{"atl":[[1000,1.15]],"id":61631978}],"con":true,"img":false}]}
{"op":"mcm","clk":"11449968667","pt":1717316524831,"mc":[{"id":"1.229554905","rc":[{"atl":[[1000,0.17]],"id":61631978}],"con":true,"img":false}]}
{"op":"mcm","clk":"11449968677","pt":1717316524934,"mc":[{"id":"1.229554905","rc":[{"atl":[[13.5,2.42]],"id":61631978}],"con":true,"img":false}]}
{"op":"mcm","clk":"11449970478","pt":1717316552402,"mc":[{"id":"1.229554905","rc":[{"atb":[[40,0],[50,0],[30,0]],"id":42269942},{"atl":[[610,0]],"id":42269942},{"spn":517.5,"spf":"NaN","id":42269942},{"atb":[[9.6,0],[8.6,0],[11.5,0]],"id":57451148},{"atl":[[300,0],[200,0]],"id":57451148},{"atb":[[4.3,0],[3.9,0],[3.65,0]],"id":61631980},{"atl":[[34,0],[22,0]],"id":61631980},{"atb":[[1.18,0],[1.23,0],[1.13,0]],"id":60780007},{"atl":[[2.64,0],[2.84,0]],"id":60780007},{"atb":[[3.4,0],[3.9,0],[3.65,0]],"id":61631978},{"atl":[[19,6.29],[28,0]],"id":61631978}],"con":true,"img":false}]}
{"op":"mcm","clk":"11449971651","pt":1717316571019,"mc":[{"id":"1.229554905","rc":[{"atb":[[40,6.78],[50,2.69],[30,9.11]],"id":42269942},{"atl":[[610,0.2],[510,0.16]],"id":42269942},{"atb":[[9.6,24.29],[8.6,27.49],[11.5,9.95]],"id":57451148},{"atl":[[300,0.7],[200,0.7]],"id":57451148},{"atb":[[4.3,31.65],[3.9,72.05],[3.65,78.84]],"id":61631980},{"atl":[[34,6.34],[22,6.64]],"id":61631980},{"atb":[[1.18,1160.84],[1.23,454.24],[1.13,1607.32]],"id":60780007},{"atl":[[2.64,85.05],[2.84,113.7]],"id":60780007},{"atb":[[3.4,87.06],[3.9,36.02],[3.65,78.84]],"id":61631978},{"atl":[[19,14.04],[28,7.74]],"id":61631978}],"con":true,"img":false}]}
{"op":"mcm","clk":"11449971691","pt":1717316571589,"mc":[{"id":"1.229554905","rc":[{"trd":[[510,0.74]],"ltp":510.0,"tv":0.74,"id":42269942},{"atl":[[510,0.06]],"id":42269942}],"con":true,"img":false}]}
{"op":"mcm","clk":"11449971837","pt":1717316573708,"mc":[{"id":"1.229554905","rc":[{"atl":[[13.5,0.98]],"id":61631978}],"con":true,"img":false}]}
{"op":"mcm","clk":"11449974632","pt":1717316613057,"mc":[{"id":"1.229554905","rc":[{"spn":292.5,"spf":"NaN","id":42269942},{"atl":[[2.1,0]],"id":60780007}],"con":true,"img":false}]}
{"op":"mcm","clk":"11449974699","pt":1717316613830,"mc":[{"id":"1.229554905","rc":[{"atl":[[1000,0.85]],"id":61631980}],"con":true,"img":false}]}
{"op":"mcm","clk":"11449974707","pt":1717316613934,"mc":[{"id":"1.229554905","rc":[{"atl":[[1000,0.85]],"id":57451148}],"con":true,"img":false}]}
{"op":"mcm","clk":"11449974713","pt":1717316614039,"mc":[{"id":"1.229554905","rc":[{"atl":[[1000,1.02]],"id":61631978}],"con":true,"img":false}]}
{"op":"mcm","clk":"11449974721","pt":1717316614140,"mc":[{"id":"1.229554905","rc":[{"atb":[[1.07,0.85]],"id":42269942}],"con":true,"img":false}]}
{"op":"mcm","clk":"11449974736","pt":1717316614448,"mc":[{"id":"1.229554905","rc":[{"atl":[[1000,0.5]],"id":61631980}],"con":true,"img":false}]}
{"op":"mcm","clk":"11449974745","pt":1717316614656,"mc":[{"id":"1.229554905","rc":[{"atl":[[1000,0.17]],"id":57451148}],"con":true,"img":false}]}
{"op":"mcm","clk":"11449974758","pt":1717316614862,"mc":[{"id":"1.229554905","rc":[{"atl":[[1000,0.82]],"id":61631978}],"con":true,"img":false}]}
{"op":"mcm","clk":"11449974777","pt":1717316615172,"mc":[{"id":"1.229554905","rc":[{"atb":[[1.07,0.1]],"id":42269942}],"con":true,"img":false}]}
{"op":"mcm","clk":"11449974782","pt":1717316615225,"mc":[{"id":"1.229554905","rc":[{"atl":[[1000,0]],"id":61631980}],"con":true,"img":false}]}
{"op":"mcm","clk":"11449974788","pt":1717316615328,"mc":[{"id":"1.229554905","rc":[{"atl":[[17,0.5]],"id":61631980}],"con":true,"img":false}]}
{"op":"mcm","clk":"11449974802","pt":1717316615638,"mc":[{"id":"1.229554905","rc":[{"atl":[[1000,0]],"id":57451148}],"con":true,"img":false}]}
{"op":"mcm","clk":"11449974811","pt":1717316615738,"mc":[{"id":"1.229554905","rc":[{"atl":[[48,0.17]],"id":57451148}],"con":true,"img":false}]}
{"op":"mcm","clk":"11449974841","pt":1717316616153,"mc":[{"id":"1.229554905","rc":[{"atl":[[1000,0.17]],"id":61631978}],"con":true,"img":false}]}
{"op":"mcm","clk":"11449974846","pt":1717316616255,"mc":[{"id":"1.229554905","rc":[{"atl":[[13,0.65]],"id":61631978}],"con":true,"img":false}]}
{"op":"mcm","clk":"11449974881","pt":1717316616775,"mc":[{"id":"1.229554905","rc":[{"atb":[[1.07,0]],"id":42269942}],"con":true,"img":false}]}
{"op":"mcm","clk":"11449974890","pt":1717316616877,"mc":[{"id":"1.229554905","rc":[{"atb":[[80,0.1]],"id":42269942}],"con":true,"img":false}]}
{"op":"mcm","clk":"11449975532","pt":1717316625454,"mc":[{"id":"1.229554905","rc":[{"atl":[[1000,1]],"id":42269942},{"atl":[[1000,1]],"id":57451148},{"atl":[[1000,1]],"id":61631980},{"atl":[[1000,1]],"id":60780007},{"atl":[[1000,1.17]],"id":61631978}],"con":true,"img":false}]}
{"op":"mcm","clk":"11449977478","pt":1717316651813,"mc":[{"id":"1.229554905","rc":[{"atl":[[13.5,2.42]],"id":61631978}],"con":true,"img":false}]}
{"op":"mcm","clk":"11449977484","pt":1717316651917,"mc":[{"id":"1.229554905","rc":[{"atl":[[2.1,9.18]],"id":60780007}],"con":true,"img":false}]}
{"op":"mcm","clk":"11449982384","pt":1717316719558,"mc":[{"id":"1.229554905","rc":[{"spn":295.0,"spf":"NaN","id":42269942},{"spn":30.0,"spf":"NaN","id":57451148},{"spn":10.8,"spf":"NaN","id":61631980},{"atl":[[13.5,1.43]],"id":61631978},{"spn":8.55,"spf":"NaN","id":61631978}],"con":true,"img":false}]}
{"op":"mcm","clk":"11449993580","pt":1717316869952,"mc":[{"id":"1.229554905","rc":[{"atl":[[13.5,0]],"id":61631978}],"con":true,"img":false}]}
{"op":"mcm","clk":"11449994832","pt":1717316884265,"mc":[{"id":"1.229554905","rc":[{"atl":[[13,0]],"id":61631978}],"con":true,"img":false}]}
{"op":"mcm","clk":"11449996433","pt":1717316902308,"mc":[{"id":"1.229554905","rc":[{"atl":[[2.1,0]],"id":60780007}],"con":true,"img":false}]}
{"op":"mcm","clk":"11449999397","pt":1717316938878,"mc":[{"id":"1.229554905","rc":[{"atb":[[40,0],[50,0],[30,0]],"id":42269942},{"atl":[[610,0],[510,0]],"id":42269942},{"spn":520.0,"spf":"NaN","id":42269942},{"atb":[[9.6,0],[8.6,0],[11.5,0]],"id":57451148},{"atl":[[300,0],[200,0]],"id":57451148},{"atb":[[4.3,0],[3.9,0],[3.65,0]],"id":61631980},{"atl":[[34,0],[22,0]],"id":61631980},{"atb":[[1.18,0],[1.23,0],[1.13,0]],"id":60780007},{"atl":[[2.64,0],[2.84,0]],"id":60780007},{"atb":[[3.4,0],[3.9,0],[3.65,0]],"id":61631978},{"atl":[[19,6.29],[28,0]],"id":61631978},{"spn":9.3,"spf":"NaN","id":61631978}],"con":true,"img":false}]}
{"op":"mcm","clk":"11450000026","pt":1717316946162,"mc":[{"id":"1.229554905","rc":[{"atb":[[4.4,0]],"id":61631980},{"atl":[[21,0]],"id":61631980},{"atb":[[1.19,0],[1.24,0]],"id":60780007},{"atb":[[3.95,0]],"id":61631978}],"con":true,"img":false}]}
{"op":"mcm","clk":"11450000038","pt":1717316946268,"mc":[{"id":"1.229554905","rc":[{"atb":[[3.85,40.8]],"id":61631980},{"atl":[[24,5.75]],"id":61631980},{"atb":[[1.15,689.36],[1.19,95.36]],"id":60780007},{"atb":[[3.45,41.18]],"id":61631978}],"con":true,"img":false}]}
{"op":"mcm","clk":"11450000060","pt":1717316946471,"mc":[{"id":"1.229554905","rc":[{"atl":[[17,0]],"id":61631980}],"con":true,"img":false}]}
{"op":"mcm","clk":"11450000369","pt":1717316949581,"mc":[{"id":"1.229554905","rc":[{"atl":[[13.5,1.43]],"id":61631978}],"con":true,"img":false}]}
{"op":"mcm","clk":"11450000388","pt":1717316949784,"mc":[{"id":"1.229554905","rc":[{"atl":[[2.1,9.18]],"id":60780007}],"con":true,"img":false}]}
{"op":"mcm","clk":"11450000408","pt":1717316949998,"mc":[{"id":"1.229554905","rc":[{"atb":[[40,7.29],[50,2.9],[30,9.81]],"id":42269942},{"atl":[[610,0.15],[510,0.12]],"id":42269942},{"atb":[[9.6,24.29],[8.6,27.48],[11.5,9.95]],"id":57451148},{"atl":[[300,0.7],[200,0.7]],"id":57451148},{"atb":[[4.3,31.65],[3.9,72.04],[3.65,78.83]],"id":61631980},{"atl":[[34,6.34],[22,6.64]],"id":61631980},{"atb":[[1.18,1160.62],[1.23,454.15],[1.13,1607.02]],"id":60780007},{"atl":[[2.64,85.07],[2.84,113.74]],"id":60780007},{"atb":[[3.4,87.04],[3.9,36.02],[3.65,78.83]],"id":61631978},{"atl":[[19,14.04],[28,7.75]],"id":61631978}],"con":true,"img":false}]}
{"op":"mcm","clk":"11450005235","pt":1717317005737,"mc":[{"id":"1.229554905","rc":[{"spn":295.0,"spf":"NaN","id":42269942},{"atl":[[1000,1.85]],"id":61631980},{"spn":11.05,"spf":"NaN","id":61631980},{"spn":1.61,"spf":"NaN","id":60780007},{"spn":8.8,"spf":"NaN","id":61631978}],"con":true,"img":false}]}
{"op":"mcm","clk":"11450005256","pt":1717317005942,"mc":[{"id":"1.229554905","rc":[{"atl":[[1000,2.02]],"id":61631978}],"con":true,"img":false}]}
{"op":"mcm","clk":"11450005431","pt":1717317007646,"mc":[{"id":"1.229554905","rc":[{"atl":[[1000,1.82]],"id":61631978}],"con":true,"img":false}]}
{"op":"mcm","clk":"11450005452","pt":1717317007857,"mc":[{"id":"1.229554905","rc":[{"atl":[[1000,4.18]],"id":61631978}],"con":true,"img":false}]}
{"op":"mcm","clk":"11450005473","pt":1717317008065,"mc":[{"id":"1.229554905","rc":[{"atl":[[1000,1.5]],"id":61631980},{"atl":[[1000,2.81]],"id":61631978}],"con":true,"img":false}]}
{"op":"mcm","clk":"11450005546","pt":1717317008736,"mc":[{"id":"1.229554905","rc":[{"atb":[[3.85,0]],"id":61631980},{"atl":[[24,0]],"id":61631980},{"atb":[[1.15,0],[1.19,0]],"id":60780007},{"atb":[[3.45,0]],"id":61631978}],"con":true,"img":false}]}
{"op":"mcm","clk":"11450005556","pt":1717317008844,"mc":[{"id":"1.229554905","rc":[{"atb":[[4.4,40.8]],"id":61631980},{"atl":[[21,5.75]],"id":61631980},{"atb":[[1.19,689.36],[1.24,95.36]],"id":60780007},{"atb":[[3.95,41.18]],"id":61631978},{"atl":[[1000,1.82]],"id":61631978}],"con":true,"img":false}]}
{"op":"mcm","clk":"11450005568","pt":1717317008942,"mc":[{"id":"1.229554905","rc":[{"atl":[[13.5,2.42]],"id":61631978}],"con":true,"img":false}]}
{"op":"mcm","clk":"11450005829","pt":1717317012066,"mc":[{"id":"1.229554905","rc":[{"atl":[[1000,1.17]],"id":61631978}],"con":true,"img":false}]}
{"op":"mcm","clk":"11450005843","pt":1717317012169,"mc":[{"id":"1.229554905","rc":[{"atl":[[13,0.65]],"id":61631978}],"con":true,"img":false}]}
{"op":"mcm","clk":"11450005933","pt":1717317012943,"mc":[{"id":"1.229554905","rc":[{"atl":[[1000,1]],"id":61631980}],"con":true,"img":false}]}
{"op":"mcm","clk":"11450005943","pt":1717317013047,"mc":[{"id":"1.229554905","rc":[{"atl":[[17,0.5]],"id":61631980}],"con":true,"img":false}]}
{"op":"mcm","clk":"11450013144","pt":1717317085441,"mc":[{"id":"1.229554905","rc":[{"atb":[[2.5,0],[2.74,57.47]],"id":61631980},{"spn":10.8,"spf":"NaN","id":61631980},{"spn":1.62,"spf":"NaN","id":60780007},{"spn":8.55,"spf":"NaN","id":61631978}],"con":true,"img":false}]}
{"op":"mcm","clk":"11450013810","pt":1717317092755,"mc":[{"id":"1.229554905","rc":[{"atb":[[2.74,0],[2.5,66.67]],"id":61631980}],"con":true,"img":false}]}
{"op":"mcm","clk":"11450015841","pt":1717317115696,"mc":[{"id":"1.229554905","rc":[{"atb":[[2.5,0],[2.74,57.47]],"id":61631980}],"con":true,"img":false}]}
{"op":"mcm","clk":"11450017782","pt":1717317134641,"mc":[{"id":"1.229554905","rc":[{"atl":[[13.5,0.98]],"id":61631978}],"con":true,"img":false}]}
{"op":"mcm","clk":"11450021569","pt":1717317172949,"mc":[{"id":"1.229554905","rc":[{"atl":[[2.1,0]],"id":60780007}],"con":true,"img":false}]}
{"op":"mcm","clk":"11450023329","pt":1717317190683,"mc":[{"id":"1.229554905","rc":[{"atl":[[13.5,0]],"id":61631978}],"con":true,"img":false}]}
{"op":"mcm","clk":"11450024846","pt":1717317205493,"mc":[{"id":"1.229554905","rc":[{"atl":[[1000,3.52]],"id":61631978}],"con":true,"img":false}]}
{"op":"mcm","clk":"11450024869","pt":1717317205702,"mc":[{"id":"1.229554905","rc":[{"atl":[[1000,2.15]],"id":61631978}],"con":true,"img":false}]}
{"op":"mcm","clk":"11450024889","pt":1717317205913,"mc":[{"id":"1.229554905","rc":[{"atl":[[1000,1.17]],"id":61631978}],"con":true,"img":false}]}
{"op":"mcm","clk":"11450024902","pt":1717317206009,"mc":[{"id":"1.229554905","rc":[{"atl":[[13.5,0.98]],"id":61631978}],"con":true,"img":false}]}
{"op":"mcm","clk":"11450025467","pt":1717317211621,"mc":[{"id":"1.229554905","rc":[{"atl":[[13.5,2.42]],"id":61631978}],"con":true,"img":false}]}
{"op":"mcm","clk":"11450025476","pt":1717317211725,"mc":[{"id":"1.229554905","rc":[{"atl":[[2.1,9.18]],"id":60780007}],"con":true,"img":false}]}
{"op":"mcm","clk":"11450040232","pt":1717317351851,"mc":[{"id":"1.229554905","rc":[{"atb":[[40,0],[50,0],[30,0]],"id":42269942},{"atl":[[610,0],[510,0]],"id":42269942},{"spn":520.0,"spf":"NaN","id":42269942},{"atb":[[9.6,0],[8.6,0],[11.5,0]],"id":57451148},{"atl":[[300,0],[200,0]],"id":57451148},{"atb":[[4.3,0],[3.9,0],[3.65,0]],"id":61631980},{"atl":[[34,0],[22,0]],"id":61631980},{"atb":[[1.18,0],[1.23,0],[1.13,0]],"id":60780007},{"atl":[[2.64,0],[2.84,0]],"id":60780007},{"atb":[[3.4,0],[3.9,0],[3.65,0]],"id":61631978},{"atl":[[19,6.29],[28,0]],"id":61631978}],"con":true,"img":false}]}
{"op":"mcm","clk":"11450042982","pt":1717317378075,"mc":[{"id":"1.229554905","rc":[{"atb":[[40,7.29],[50,2.9],[30,9.81]],"id":42269942},{"atl":[[610,0.15],[510,0.12]],"id":42269942},{"atb":[[9.6,24.29],[8.6,27.48],[11.5,9.95]],"id":57451148},{"atl":[[300,0.7],[200,0.7]],"id":57451148},{"atb":[[4.3,31.65],[3.9,72.04],[3.65,78.83]],"id":61631980},{"atl":[[34,6.34],[22,6.64]],"id":61631980},{"atb":[[1.18,1160.62],[1.23,454.15],[1.13,1607.02]],"id":60780007},{"atl":[[2.64,85.07],[2.84,113.74]],"id":60780007},{"atb":[[3.4,87.04],[3.9,36.02],[3.65,78.83]],"id":61631978},{"atl":[[19,14.04],[28,7.75]],"id":61631978}],"con":true,"img":false}]}
{"op":"mcm","clk":"11450043109","pt":1717317379387,"mc":[{"id":"1.229554905","rc":[{"atb":[[1.24,0]],"id":60780007}],"con":true,"img":false}]}
{"op":"mcm","clk":"11450043118","pt":1717317379492,"mc":[{"id":"1.229554905","rc":[{"atb":[[1.19,784.72]],"id":60780007}],"con":true,"img":false}]}
{"op":"mcm","clk":"11450043985","pt":1717317387493,"mc":[{"id":"1.229554905","rc":[{"atl":[[13.5,1.43]],"id":61631978}],"con":true,"img":false}]}
{"op":"mcm","clk":"11450044928","pt":1717317396884,"mc":[{"id":"1.229554905","rc":[{"atl":[[13.5,0]],"id":61631978}],"con":true,"img":false}]}
{"op":"mcm","clk":"11450045498","pt":1717317402500,"mc":[{"id":"1.229554905","rc":[{"atl":[[1000,3.52]],"id":61631978}],"con":true,"img":false}]}
{"op":"mcm","clk":"11450045521","pt":1717317402702,"mc":[{"id":"1.229554905","rc":[{"atl":[[1000,2.15]],"id":61631978}],"con":true,"img":false}]}
{"op":"mcm","clk":"11450045541","pt":1717317402910,"mc":[{"id":"1.229554905","rc":[{"atl":[[1000,1.17]],"id":61631978}],"con":true,"img":false}]}
{"op":"mcm","clk":"11450045553","pt":1717317403012,"mc":[{"id":"1.229554905","rc":[{"atl":[[13.5,0.98]],"id":61631978}],"con":true,"img":false}]}
{"op":"mcm","clk":"11450046809","pt":1717317414525,"mc":[{"id":"1.229554905","rc":[{"spn":295.0,"spf":"NaN","id":42269942},{"atb":[[1.19,689.36]],"id":60780007},{"spn":1.61,"spf":"NaN","id":60780007}],"con":true,"img":false}]}
{"op":"mcm","clk":"11450046818","pt":1717317414625,"mc":[{"id":"1.229554905","rc":[{"atb":[[1.24,95.36]],"id":60780007}],"con":true,"img":false}]}
{"op":"mcm","clk":"11450049853","pt":1717317442277,"mc":[{"id":"1.229554905","rc":[{"atl":[[2.1,0]],"id":60780007}],"con":true,"img":false}]}
{"op":"mcm","clk":"11450052882","pt":1717317474650,"mc":[{"id":"1.229554905","rc":[{"atb":[[2.74,0],[2.5,66.67]],"id":61631980},{"spn":1.62,"spf":"NaN","id":60780007}],"con":true,"img":false}]}
{"op":"mcm","clk":"11450052916","pt":1717317475063,"mc":[{"id":"1.229554905","rc":[{"atb":[[2.5,0],[2.74,57.47]],"id":61631980}],"con":true,"img":false}]}
{"op":"mcm","clk":"11450052926","pt":1717317475169,"mc":[{"id":"1.229554905","rc":[{"atb":[[2.74,0],[2.5,66.67]],"id":61631980}],"con":true,"img":false}]}
{"op":"mcm","clk":"11450052998","pt":1717317475893,"mc":[{"id":"1.229554905","rc":[{"atb":[[2.5,0],[2.74,57.47]],"id":61631980}],"con":true,"img":false}]}
{"op":"mcm","clk":"11450053897","pt":1717317485781,"mc":[{"id":"1.229554905","rc":[{"atl":[[2.1,9.18]],"id":60780007},{"atl":[[13.5,2.42]],"id":61631978}],"con":true,"img":false}]}
{"op":"mcm","clk":"11450062252","pt":1717317579477,"mc":[{"id":"1.229554905","rc":[{"atb":[[2.74,0],[2.5,66.67]],"id":61631980}],"con":true,"img":false}]}
{"op":"mcm","clk":"11450062388","pt":1717317580974,"mc":[{"id":"1.229554905","rc":[{"atb":[[2.5,0],[2.74,57.47]],"id":61631980}],"con":true,"img":false}]}
{"op":"mcm","clk":"11450062559","pt":1717317583007,"mc":[{"id":"1.229554905","rc":[{"atb":[[2.74,0],[2.5,66.67]],"id":61631980}],"con":true,"img":false}]}
{"op":"mcm","clk":"11450062584","pt":1717317583266,"mc":[{"id":"1.229554905","rc":[{"atb":[[2.5,0],[2.74,57.47]],"id":61631980}],"con":true,"img":false}]}
{"op":"mcm","clk":"11450062652","pt":1717317584092,"mc":[{"id":"1.229554905","rc":[{"atb":[[2.5,66.67]],"id":61631980}],"con":true,"img":false}]}
{"op":"mcm","clk":"11450062659","pt":1717317584195,"mc":[{"id":"1.229554905","rc":[{"atb":[[2.74,0]],"id":61631980}],"con":true,"img":false}]}
{"op":"mcm","clk":"11450063098","pt":1717317588772,"mc":[{"id":"1.229554905","rc":[{"atb":[[2.5,0],[2.74,57.47]],"id":61631980}],"con":true,"img":false}]}
{"op":"mcm","clk":"11450063359","pt":1717317591685,"mc":[{"id":"1.229554905","rc":[{"atl":[[13.5,1.43]],"id":61631978}],"con":true,"img":false}]}
{"op":"mcm","clk":"11450064695","pt":1717317606749,"mc":[{"id":"1.229554905","rc":[{"atl":[[1000,3.52]],"id":61631978}],"con":true,"img":false}]}
{"op":"mcm","clk":"11450064710","pt":1717317606905,"mc":[{"id":"1.229554905","rc":[{"atl":[[1000,2.15]],"id":61631978}],"con":true,"img":false}]}
{"op":"mcm","clk":"11450064726","pt":1717317607108,"mc":[{"id":"1.229554905","rc":[{"atl":[[1000,1.17]],"id":61631978}],"con":true,"img":false}]}
{"op":"mcm","clk":"11450064737","pt":1717317607210,"mc":[{"id":"1.229554905","rc":[{"atl":[[13.5,2.42]],"id":61631978}],"con":true,"img":false}]}
{"op":"mcm","clk":"11450066369","pt":1717317625022,"mc":[{"id":"1.229554905","rc":[{"atb":[[2.74,0],[2.5,66.67]],"id":61631980}],"con":true,"img":false}]}
{"op":"mcm","clk":"11450067889","pt":1717317642078,"mc":[{"id":"1.229554905","rc":[{"atl":[[2.42,5.96]],"id":60780007}],"con":true,"img":false}]}
{"op":"mcm","clk":"11450067905","pt":1717317642284,"mc":[{"id":"1.229554905","rc":[{"atl":[[17.5,5.96]],"id":61631978}],"con":true,"img":false}]}
{"op":"mcm","clk":"11450067936","pt":1717317642549,"mc":[{"id":"1.229554905","rc":[{"atl":[[23,5.96]],"id":61631980}],"con":true,"img":false}]}
{"op":"mcm","clk":"11450067962","pt":1717317642860,"mc":[{"id":"1.229554905","rc":[{"atl":[[110,8.58]],"id":57451148}],"con":true,"img":false}]}
{"op":"mcm","clk":"11450067989","pt":1717317643170,"mc":[{"id":"1.229554905","rc":[{"atb":[[1.07,10.22]],"id":60780007}],"con":true,"img":false}]}
{"op":"mcm","clk":"11450068010","pt":1717317643379,"mc":[{"id":"1.229554905","rc":[{"atb":[[3.7,10.22]],"id":61631978}],"con":true,"img":false}]}
{"op":"mcm","clk":"11450068040","pt":1717317643587,"mc":[{"id":"1.229554905","rc":[{"atb":[[4.4,51.03]],"id":61631980}],"con":true,"img":false}]}
{"op":"mcm","clk":"11450068057","pt":1717317643791,"mc":[{"id":"1.229554905","rc":[{"atb":[[12,15.32]],"id":57451148}],"con":true,"img":false}]}
{"op":"mcm","clk":"11450071788","pt":1717317683707,"mc":[{"id":"1.229554905","rc":[{"atl":[[13.5,0.98]],"id":61631978}],"con":true,"img":false}]}
{"op":"mcm","clk":"11450072570","pt":1717317692043,"mc":[{"id":"1.229554905","rc":[{"atl":[[19,7.75]],"id":61631978}],"con":true,"img":false}]}
{"op":"mcm","clk":"11450072579","pt":1717317692156,"mc":[{"id":"1.229554905","rc":[{"atl":[[17,6.29]],"id":61631978}],"con":true,"img":false}]}
{"op":"mcm","clk":"11450073898","pt":1717317706141,"mc":[{"id":"1.229554905","rc":[{"atl":[[2.1,0]],"id":60780007}],"con":true,"img":false}]}
{"op":"mcm","clk":"11450076046","pt":1717317730170,"mc":[{"id":"1.229554905","rc":[{"atb":[[40,0],[50,0],[30,0]],"id":42269942},{"atl":[[610,0],[510,0]],"id":42269942},{"atb":[[9.6,0],[8.6,0],[11.5,0]],"id":57451148},{"atl":[[300,0],[200,0]],"id":57451148},{"atb":[[4.3,0],[3.9,0],[3.65,0]],"id":61631980},{"atl":[[34,0],[22,0]],"id":61631980},{"atb":[[1.18,0],[1.23,0],[1.13,0]],"id":60780007},{"atl":[[2.64,0],[2.84,0]],"id":60780007},{"atb":[[3.4,0],[3.9,0],[3.65,0]],"id":61631978},{"atl":[[19,0],[28,0]],"id":61631978}],"con":true,"img":false}]}
{"op":"mcm","clk":"11450077020","pt":1717317740593,"mc":[{"id":"1.229554905","rc":[{"atl":[[21,0]],"id":61631980},{"atb":[[1.19,0],[1.24,0]],"id":60780007},{"atb":[[3.95,0]],"id":61631978},{"atl":[[17,0]],"id":61631978}],"con":true,"img":false}]}
{"op":"mcm","clk":"11450077030","pt":1717317740659,"mc":[{"id":"1.229554905","rc":[{"atl":[[24,5.75]],"id":61631980},{"atb":[[1.15,689.36],[1.19,95.36]],"id":60780007},{"atb":[[3.45,41.18]],"id":61631978},{"atl":[[20,6.29]],"id":61631978}],"con":true,"img":false}]}
{"op":"mcm","clk":"11450077054","pt":1717317741003,"mc":[{"id":"1.229554905","rc":[{"atl":[[17,0]],"id":61631980}],"con":true,"img":false}]}
{"op":"mcm","clk":"11450077304","pt":1717317743752,"mc":[{"id":"1.229554905","rc":[{"atl":[[13.5,2.42]],"id":61631978}],"con":true,"img":false}]}
{"op":"mcm","clk":"11450077372","pt":1717317744408,"mc":[{"id":"1.229554905","rc":[{"atl":[[2.1,9.18]],"id":60780007}],"con":true,"img":false}]}
{"op":"mcm","clk":"11450078216","pt":1717317753972,"mc":[{"id":"1.229554905","rc":[{"atb":[[40,7.29],[50,2.9],[30,9.81]],"id":42269942},{"atl":[[610,0.15],[510,0.12]],"id":42269942},{"atb":[[9.6,24.29],[8.6,27.48],[11.5,9.95]],"id":57451148},{"atl":[[300,0.7],[200,0.7]],"id":57451148},{"atb":[[4.3,31.65],[3.9,72.04],[3.65,78.83]],"id":61631980},{"atl":[[34,6.34],[22,6.64]],"id":61631980},{"atb":[[1.18,1160.62],[1.23,454.15],[1.13,1607.02]],"id":60780007},{"atl":[[2.64,85.07],[2.84,113.74]],"id":60780007},{"atb":[[3.4,87.04],[3.9,36.02],[3.65,78.83]],"id":61631978},{"atl":[[19,7.75],[28,7.75]],"id":61631978}],"con":true,"img":false}]}
{"op":"mcm","clk":"11450079653","pt":1717317769361,"mc":[{"id":"1.229554905","rc":[{"atb":[[2.5,0],[2.74,57.47]],"id":61631980},{"spn":11.05,"spf":"NaN","id":61631980},{"spn":1.61,"spf":"NaN","id":60780007}],"con":true,"img":false}]}
{"op":"mcm","clk":"11450081992","pt":1717317796748,"mc":[{"id":"1.229554905","rc":[{"atl":[[13.5,1.43]],"id":61631978}],"con":true,"img":false}]}
{"op":"mcm","clk":"11450082324","pt":1717317800880,"mc":[{"id":"1.229554905","rc":[{"atl":[[24,0]],"id":61631980},{"atb":[[1.15,0],[1.19,0]],"id":60780007},{"atb":[[3.45,0]],"id":61631978},{"atl":[[20,0]],"id":61631978}],"con":true,"img":false}]}
{"op":"mcm","clk":"11450082334","pt":1717317800986,"mc":[{"id":"1.229554905","rc":[{"atl":[[21,5.75]],"id":61631980},{"atb":[[1.19,689.36],[1.24,95.36]],"id":60780007},{"atb":[[3.95,41.18]],"id":61631978},{"atl":[[17,6.29]],"id":61631978}],"con":true,"img":false}]}
{"op":"mcm","clk":"11450092187","pt":1717317914920,"mc":[{"id":"1.229554905","rc":[{"spn":1.62,"spf":"NaN","id":60780007},{"atl":[[1000,3.52]],"id":61631978}],"con":true,"img":false}]}
{"op":"mcm","clk":"11450092431","pt":1717317917455,"mc":[{"id":"1.229554905","rc":[{"atl":[[1000,2.15]],"id":61631978}],"con":true,"img":false}]}
{"op":"mcm","clk":"11450092587","pt":1717317919215,"mc":[{"id":"1.229554905","rc":[{"atl":[[1000,1.17]],"id":61631978}],"con":true,"img":false}]}
{"op":"mcm","clk":"11450092597","pt":1717317919317,"mc":[{"id":"1.229554905","rc":[{"atl":[[13.5,2.42]],"id":61631978}],"con":true,"img":false}]}
{"op":"mcm","clk":"11450096140","pt":1717317960210,"mc":[{"id":"1.229554905","rc":[{"atl":[[13.5,0.98]],"id":61631978}],"con":true,"img":false}]}
{"op":"mcm","clk":"11450099222","pt":1717317997522,"mc":[{"id":"1.229554905","rc":[{"atl":[[2.1,0]],"id":60780007}],"con":true,"img":false}]}
{"op":"mcm","clk":"11450102798","pt":1717318038083,"mc":[{"id":"1.229554905","rc":[{"atl":[[13.5,2.42]],"id":61631978}],"con":true,"img":false}]}
{"op":"mcm","clk":"11450102808","pt":1717318038188,"mc":[{"id":"1.229554905","rc":[{"atl":[[2.1,9.18]],"id":60780007}],"con":true,"img":false}]}
{"op":"mcm","clk":"11450108554","pt":1717318100781,"mc":[{"id":"1.229554905","rc":[{"atl":[[13.5,1.43]],"id":61631978}],"con":true,"img":false}]}
{"op":"mcm","clk":"11450109884","pt":1717318115773,"mc":[{"id":"1.229554905","rc":[{"atl":[[1000,3.52]],"id":61631978}],"con":true,"img":false}]}
{"op":"mcm","clk":"11450109900","pt":1717318116004,"mc":[{"id":"1.229554905","rc":[{"atl":[[1000,2.15]],"id":61631978}],"con":true,"img":false}]}
{"op":"mcm","clk":"11450109922","pt":1717318116190,"mc":[{"id":"1.229554905","rc":[{"atl":[[1000,1.17]],"id":61631978}],"con":true,"img":false}]}
{"op":"mcm","clk":"11450109933","pt":1717318116287,"mc":[{"id":"1.229554905","rc":[{"atl":[[13.5,2.42]],"id":61631978}],"con":true,"img":false}]}
{"op":"mcm","clk":"11450111170","pt":1717318130781,"mc":[{"id":"1.229554905","rc":[{"atb":[[40,0],[50,0],[30,0]],"id":42269942},{"atl":[[610,0],[510,0]],"id":42269942},{"atb":[[9.6,0],[8.6,0],[11.5,0]],"id":57451148},{"atl":[[300,0],[200,0]],"id":57451148},{"atb":[[4.3,0],[3.9,0],[3.65,0]],"id":61631980},{"atl":[[34,0],[22,0]],"id":61631980},{"atb":[[1.18,0],[1.23,0],[1.13,0]],"id":60780007},{"atl":[[2.64,0],[2.84,0]],"id":60780007},{"atb":[[3.4,0],[3.9,0],[3.65,0]],"id":61631978},{"atl":[[19,0],[28,0]],"id":61631978}],"con":true,"img":false}]}
{"op":"mcm","clk":"11450111602","pt":1717318136187,"mc":[{"id":"1.229554905","rc":[{"atl":[[21,0]],"id":61631980},{"atb":[[1.19,0],[1.24,0]],"id":60780007},{"atb":[[3.95,0]],"id":61631978},{"atl":[[17,0]],"id":61631978}],"con":true,"img":false}]}
{"op":"mcm","clk":"11450111615","pt":1717318136290,"mc":[{"id":"1.229554905","rc":[{"atl":[[24,5.75]],"id":61631980},{"atb":[[1.15,689.36],[1.19,95.36]],"id":60780007},{"atb":[[3.45,41.18]],"id":61631978},{"atl":[[20,6.29]],"id":61631978}],"con":true,"img":false}]}
{"op":"mcm","clk":"11450111652","pt":1717318136704,"mc":[{"id":"1.229554905","rc":[{"atb":[[1.07,0]],"id":60780007}],"con":true,"img":false}]}
{"op":"mcm","clk":"11450111665","pt":1717318136810,"mc":[{"id":"1.229554905","rc":[{"atb":[[1.03,10.22]],"id":60780007}],"con":true,"img":false}]}
{"op":"mcm","clk":"11450111758","pt":1717318137594,"mc":[{"id":"1.229554905","rc":[{"atb":[[1.03,0]],"id":60780007}],"con":true,"img":false}]}
{"op":"mcm","clk":"11450111766","pt":1717318137693,"mc":[{"id":"1.229554905","rc":[{"atb":[[1.07,10.22]],"id":60780007}],"con":true,"img":false}]}
{"op":"mcm","clk":"11450113044","pt":1717318150830,"mc":[{"id":"1.229554905","rc":[{"atb":[[4.4,10.22]],"id":61631980}],"con":true,"img":false}]}
{"op":"mcm","clk":"11450113054","pt":1717318150935,"mc":[{"id":"1.229554905","rc":[{"atb":[[3.85,40.8]],"id":61631980}],"con":true,"img":false}]}
{"op":"mcm","clk":"11450114475","pt":1717318166534,"mc":[{"id":"1.229554905","rc":[{"atb":[[40,7.29],[50,2.9],[30,9.81]],"id":42269942},{"atl":[[610,0.15],[510,0.12]],"id":42269942},{"atb":[[9.6,24.29],[8.6,27.48],[11.5,9.95]],"id":57451148},{"atl":[[300,0.7],[200,0.7]],"id":57451148},{"atb":[[4.3,31.65],[3.9,72.04],[3.65,78.83]],"id":61631980},{"atl":[[34,6.34],[22,6.64]],"id":61631980},{"atb":[[1.18,1160.62],[1.23,454.15],[1.13,1607.02]],"id":60780007},{"atl":[[2.64,85.07],[2.84,113.74]],"id":60780007},{"spn":1.61,"spf":"NaN","id":60780007},{"atb":[[3.4,87.04],[3.9,36.02],[3.65,78.83]],"id":61631978},{"atl":[[19,7.75],[28,7.75]],"id":61631978}],"con":true,"img":false}]}
{"op":"mcm","clk":"11450115672","pt":1717318180660,"mc":[{"id":"1.229554905","rc":[{"atb":[[2.74,0],[2.5,66.67]],"id":61631980}],"con":true,"img":false}]}
{"op":"mcm","clk":"11450116028","pt":1717318184562,"mc":[{"id":"1.229554905","rc":[{"atb":[[2.5,0],[2.74,57.47]],"id":61631980}],"con":true,"img":false}]}
{"op":"mcm","clk":"11450116949","pt":1717318194359,"mc":[{"id":"1.229554905","rc":[{"atb":[[4.4,0]],"id":61631980}],"con":true,"img":false}]}
{"op":"mcm","clk":"11450116957","pt":1717318194457,"mc":[{"id":"1.229554905","rc":[{"atb":[[4.2,10.22]],"id":61631980}],"con":true,"img":false}]}
{"op":"mcm","clk":"11450116984","pt":1717318194766,"mc":[{"id":"1.229554905","rc":[{"atb":[[12,5.1]],"id":57451148}],"con":true,"img":false}]}
{"op":"mcm","clk":"11450116996","pt":1717318194869,"mc":[{"id":"1.229554905","rc":[{"atb":[[11.5,20.17]],"id":57451148}],"con":true,"img":false}]}
{"op":"mcm","clk":"11450117072","pt":1717318195544,"mc":[{"id":"1.229554905","rc":[{"atb":[[1.07,0]],"id":60780007}],"con":true,"img":false}]}
{"op":"mcm","clk":"11450117084","pt":1717318195647,"mc":[{"id":"1.229554905","rc":[{"atb":[[1.02,148.27]],"id":60780007}],"con":true,"img":false}]}
{"op":"mcm","clk":"11450117118","pt":1717318195963,"mc":[{"id":"1.229554905","rc":[{"atb":[[3.7,0]],"id":61631978}],"con":true,"img":false}]}
{"op":"mcm","clk":"11450117129","pt":1717318196062,"mc":[{"id":"1.229554905","rc":[{"atb":[[3.5,10.22]],"id":61631978}],"con":true,"img":false}]}
{"op":"mcm","clk":"11450117729","pt":1717318203158,"mc":[{"id":"1.229554905","rc":[{"atb":[[1.19,0]],"id":60780007}],"con":true,"img":false}]}
{"op":"mcm","clk":"11450117739","pt":1717318203265,"mc":[{"id":"1.229554905","rc":[{"atb":[[1.24,95.36]],"id":60780007}],"con":true,"img":false}]}
{"op":"mcm","clk":"11450117811","pt":1717318204099,"mc":[{"id":"1.229554905","rc":[{"atl":[[1000,1.85]],"id":61631980}],"con":true,"img":false}]}
{"op":"mcm","clk":"11450117888","pt":1717318204782,"mc":[{"id":"1.229554905","rc":[{"atl":[[1000,1.5]],"id":61631980}],"con":true,"img":false}]}
{"op":"mcm","clk":"11450117929","pt":1717318205197,"mc":[{"id":"1.229554905","rc":[{"atl":[[1000,1]],"id":61631980}],"con":true,"img":false}]}
{"op":"mcm","clk":"11450117935","pt":1717318205300,"mc":[{"id":"1.229554905","rc":[{"atl":[[17,0.5]],"id":61631980}],"con":true,"img":false}]}
{"op":"mcm","clk":"11450118584","pt":1717318213078,"mc":[{"id":"1.229554905","rc":[{"atb":[[3.85,0]],"id":61631980},{"atl":[[24,0]],"id":61631980},{"atb":[[1.15,0]],"id":60780007},{"atb":[[3.45,0]],"id":61631978},{"atl":[[20,0]],"id":61631978}],"con":true,"img":false}]}
{"op":"mcm","clk":"11450118592","pt":1717318213181,"mc":[{"id":"1.229554905","rc":[{"atb":[[4.4,40.8]],"id":61631980},{"atl":[[21,5.75]],"id":61631980},{"atb":[[1.19,689.36]],"id":60780007},{"atb":[[3.95,41.18]],"id":61631978},{"atl":[[17,6.29]],"id":61631978}],"con":true,"img":false}]}
{"op":"mcm","clk":"11450119134","pt":1717318219207,"mc":[{"id":"1.229554905","rc":[{"atl":[[17,0],[1000,1.85]],"id":61631980}],"con":true,"img":false}]}
{"op":"mcm","clk":"11450119405","pt":1717318222415,"mc":[{"id":"1.229554905","rc":[{"atl":[[1000,1.5]],"id":61631980}],"con":true,"img":false}]}
{"op":"mcm","clk":"11450119614","pt":1717318224378,"mc":[{"id":"1.229554905","rc":[{"atl":[[1000,1]],"id":61631980}],"con":true,"img":false}]}
{"op":"mcm","clk":"11450119628","pt":1717318224483,"mc":[{"id":"1.229554905","rc":[{"atl":[[20,0.5]],"id":61631980}],"con":true,"img":false}]}
{"op":"mcm","clk":"11450119654","pt":1717318224797,"mc":[{"id":"1.229554905","rc":[{"atl":[[20,0],[1000,1.85]],"id":61631980}],"con":true,"img":false}]}
{"op":"mcm","clk":"11450119677","pt":1717318225104,"mc":[{"id":"1.229554905","rc":[{"atl":[[1000,1.51]],"id":61631980}],"con":true,"img":false}]}
{"op":"mcm","clk":"11450119707","pt":1717318225364,"mc":[{"id":"1.229554905","rc":[{"atl":[[1000,1]],"id":61631980}],"con":true,"img":false}]}
{"op":"mcm","clk":"11450119724","pt":1717318225533,"mc":[{"id":"1.229554905","rc":[{"atl":[[16.5,0.51]],"id":61631980}],"con":true,"img":false}]}
{"op":"mcm","clk":"11450120421","pt":1717318233491,"mc":[{"id":"1.229554905","rc":[{"spn":10.55,"spf":"NaN","id":61631980},{"spn":1.62,"spf":"NaN","id":60780007},{"atl":[[13.5,0.98]],"id":61631978}],"con":true,"img":false}]}
{"op":"mcm","clk":"11450120884","pt":1717318238993,"mc":[{"id":"1.229554905","rc":[{"atl":[[16.5,0]],"id":61631980}],"con":true,"img":false}]}
{"op":"mcm","clk":"11450120911","pt":1717318239308,"mc":[{"id":"1.229554905","rc":[{"atl":[[1000,1.85]],"id":61631980}],"con":true,"img":false}]}
{"op":"mcm","clk":"11450120969","pt":1717318239928,"mc":[{"id":"1.229554905","rc":[{"atl":[[1000,1.51]],"id":61631980}],"con":true,"img":false}]}
{"op":"mcm","clk":"11450121048","pt":1717318240907,"mc":[{"id":"1.229554905","rc":[{"atl":[[1000,1]],"id":61631980}],"con":true,"img":false}]}
{"op":"mcm","clk":"11450121054","pt":1717318241010,"mc":[{"id":"1.229554905","rc":[{"atl":[[17,0.51]],"id":61631980}],"con":true,"img":false}]}
{"op":"mcm","clk":"11450121110","pt":1717318241683,"mc":[{"id":"1.229554905","rc":[{"atl":[[17,0],[1000,1.85]],"id":61631980}],"con":true,"img":false}]}
{"op":"mcm","clk":"11450121128","pt":1717318241993,"mc":[{"id":"1.229554905","rc":[{"atl":[[1000,1.52]],"id":61631980}],"con":true,"img":false}]}
{"op":"mcm","clk":"11450121156","pt":1717318242305,"mc":[{"id":"1.229554905","rc":[{"atl":[[1000,1]],"id":61631980}],"con":true,"img":false}]}
{"op":"mcm","clk":"11450121164","pt":1717318242412,"mc":[{"id":"1.229554905","rc":[{"atl":[[16,0.52]],"id":61631980}],"con":true,"img":false}]}
{"op":"mcm","clk":"11450123327","pt":1717318268051,"mc":[{"id":"1.229554905","rc":[{"atl":[[1000,1.85]],"id":61631980}],"con":true,"img":false}]}
{"op":"mcm","clk":"11450123334","pt":1717318268155,"mc":[{"id":"1.229554905","rc":[{"atl":[[16,0]],"id":61631980}],"con":true,"img":false}]}
{"op":"mcm","clk":"11450123381","pt":1717318268734,"mc":[{"id":"1.229554905","rc":[{"atl":[[1000,1.52]],"id":61631980}],"con":true,"img":false}]}
{"op":"mcm","clk":"11450123443","pt":1717318269444,"mc":[{"id":"1.229554905","rc":[{"atl":[[1000,1]],"id":61631980}],"con":true,"img":false}]}
{"op":"mcm","clk":"11450123454","pt":1717318269544,"mc":[{"id":"1.229554905","rc":[{"atl":[[17,0.52]],"id":61631980}],"con":true,"img":false}]}
{"op":"mcm","clk":"11450123501","pt":1717318270122,"mc":[{"id":"1.229554905","rc":[{"atl":[[17,0],[1000,1.85]],"id":61631980},{"atl":[[2.1,0]],"id":60780007}],"con":true,"img":false}]}
{"op":"mcm","clk":"11450123585","pt":1717318271160,"mc":[{"id":"1.229554905","rc":[{"atl":[[1000,1.55]],"id":61631980}],"con":true,"img":false}]}
{"op":"mcm","clk":"11450123677","pt":1717318271994,"mc":[{"id":"1.229554905","rc":[{"atl":[[1000,1]],"id":61631980}],"con":true,"img":false}]}
{"op":"mcm","clk":"11450123704","pt":1717318272149,"mc":[{"id":"1.229554905","rc":[{"atl":[[15.5,0.55]],"id":61631980}],"con":true,"img":false}]}
{"op":"mcm","clk":"11450126196","pt":1717318301320,"mc":[{"id":"1.229554905","rc":[{"atl":[[15.5,0]],"id":61631980},{"spn":11.05,"spf":"NaN","id":61631980}],"con":true,"img":false}]}
{"op":"mcm","clk":"11450126242","pt":1717318301833,"mc":[{"id":"1.229554905","rc":[{"atl":[[13.5,0]],"id":61631978}],"con":true,"img":false}]}
{"op":"mcm","clk":"11450126279","pt":1717318302243,"mc":[{"id":"1.229554905","rc":[{"atl":[[1000,1.85]],"id":61631980}],"con":true,"img":false}]}
{"op":"mcm","clk":"11450126421","pt":1717318303643,"mc":[{"id":"1.229554905","rc":[{"atl":[[1000,1.55]],"id":61631980}],"con":true,"img":false}]}
{"op":"mcm","clk":"11450126526","pt":1717318304934,"mc":[{"id":"1.229554905","rc":[{"atl":[[1000,1]],"id":61631980}],"con":true,"img":false}]}
{"op":"mcm","clk":"11450126537","pt":1717318305037,"mc":[{"id":"1.229554905","rc":[{"atl":[[17,0.55]],"id":61631980}],"con":true,"img":false}]}
{"op":"mcm","clk":"11450126652","pt":1717318306540,"mc":[{"id":"1.229554905","rc":[{"atl":[[13.5,1.43]],"id":61631978}],"con":true,"img":false}]}
{"op":"mcm","clk":"11450126660","pt":1717318306640,"mc":[{"id":"1.229554905","rc":[{"atl":[[2.1,9.18]],"id":60780007}],"con":true,"img":false}]}
{"op":"mcm","clk":"11450127302","pt":1717318314542,"mc":[{"id":"1.229554905","rc":[{"atb":[[1.02,138.04]],"id":60780007}],"con":true,"img":false}]}
{"op":"mcm","clk":"11450127314","pt":1717318314648,"mc":[{"id":"1.229554905","rc":[{"atb":[[1.05,10.22]],"id":60780007}],"con":true,"img":false}]}
{"op":"mcm","clk":"11450127334","pt":1717318314855,"mc":[{"id":"1.229554905","rc":[{"atb":[[3.5,0]],"id":61631978}],"con":true,"img":false}]}
{"op":"mcm","clk":"11450127340","pt":1717318314955,"mc":[{"id":"1.229554905","rc":[{"atb":[[3.6,10.22]],"id":61631978}],"con":true,"img":false}]}
{"op":"mcm","clk":"11450127369","pt":1717318315218,"mc":[{"id":"1.229554905","rc":[{"atb":[[4.2,0]],"id":61631980}],"con":true,"img":false}]}
{"op":"mcm","clk":"11450127379","pt":1717318315321,"mc":[{"id":"1.229554905","rc":[{"atb":[[4.3,41.87]],"id":61631980}],"con":true,"img":false}]}
{"op":"mcm","clk":"11450127415","pt":1717318315737,"mc":[{"id":"1.229554905","rc":[{"atb":[[11.5,9.95]],"id":57451148}],"con":true,"img":false}]}
{"op":"mcm","clk":"11450127425","pt":1717318315844,"mc":[{"id":"1.229554905","rc":[{"atb":[[12,15.32]],"id":57451148}],"con":true,"img":false}]}
{"op":"mcm","clk":"11450127509","pt":1717318316927,"mc":[{"id":"1.229554905","rc":[{"atl":[[1000,3.52]],"id":61631978}],"con":true,"img":false}]}
{"op":"mcm","clk":"11450127524","pt":1717318317138,"mc":[{"id":"1.229554905","rc":[{"atl":[[1000,2.15]],"id":61631978}],"con":true,"img":false}]}
{"op":"mcm","clk":"11450127542","pt":1717318317345,"mc":[{"id":"1.229554905","rc":[{"atl":[[1000,1.17]],"id":61631978}],"con":true,"img":false}]}
{"op":"mcm","clk":"11450127552","pt":1717318317448,"mc":[{"id":"1.229554905","rc":[{"atl":[[13.5,2.42]],"id":61631978}],"con":true,"img":false}]}
{"op":"mcm","clk":"11450132569","pt":1717318374801,"mc":[{"id":"1.229554905","rc":[{"spn":10.8,"spf":"NaN","id":61631980},{"atb":[[1.05,0]],"id":60780007}],"con":true,"img":false}]}
{"op":"mcm","clk":"11450132574","pt":1717318374907,"mc":[{"id":"1.229554905","rc":[{"atb":[[1.07,10.22]],"id":60780007}],"con":true,"img":false}]}
{"op":"mcm","clk":"11450132595","pt":1717318375223,"mc":[{"id":"1.229554905","rc":[{"atb":[[3.6,0]],"id":61631978}],"con":true,"img":false}]}
{"op":"mcm","clk":"11450132603","pt":1717318375319,"mc":[{"id":"1.229554905","rc":[{"atb":[[3.7,10.22]],"id":61631978}],"con":true,"img":false}]}
{"op":"mcm","clk":"11450132622","pt":1717318375582,"mc":[{"id":"1.229554905","rc":[{"atb":[[4.3,31.65]],"id":61631980}],"con":true,"img":false}]}
{"op":"mcm","clk":"11450132631","pt":1717318375686,"mc":[{"id":"1.229554905","rc":[{"atb":[[4.4,51.03]],"id":61631980}],"con":true,"img":false}]}
{"op":"mcm","clk":"11450142065","pt":1717318484862,"mc":[{"id":"1.229554905","rc":[{"atb":[[40,0],[50,0],[30,0]],"id":42269942},{"atl":[[610,0],[510,0]],"id":42269942},{"spn":520.0,"spf":"NaN","id":42269942},{"atb":[[9.6,0],[8.6,0],[11.5,0]],"id":57451148},{"atl":[[300,0],[200,0]],"id":57451148},{"atb":[[4.3,0],[3.9,0],[3.65,0]],"id":61631980},{"atl":[[34,0],[22,0]],"id":61631980},{"atb":[[1.18,0],[1.23,0],[1.13,0]],"id":60780007},{"atl":[[2.64,0],[2.84,0]],"id":60780007},{"atb":[[3.4,0],[3.9,0],[3.65,0]],"id":61631978},{"atl":[[19,0],[28,0]],"id":61631978}],"con":true,"img":false}]}
{"op":"mcm","clk":"11450142744","pt":1717318492754,"mc":[{"id":"1.229554905","rc":[{"atb":[[2.8,4.36]],"id":61631980}],"con":true,"img":false}]}
{"op":"mcm","clk":"11450142788","pt":1717318493121,"mc":[{"id":"1.229554905","rc":[{"atl":[[21,0]],"id":61631980},{"atb":[[1.19,0],[1.24,0]],"id":60780007},{"atb":[[3.95,0]],"id":61631978},{"atl":[[17,0]],"id":61631978}],"con":true,"img":false}]}
{"op":"mcm","clk":"11450142797","pt":1717318493228,"mc":[{"id":"1.229554905","rc":[{"atl":[[24,5.75]],"id":61631980},{"atb":[[1.15,689.36],[1.19,95.36]],"id":60780007},{"atb":[[3.45,41.18]],"id":61631978},{"atl":[[20,6.29]],"id":61631978}],"con":true,"img":false}]}
{"op":"mcm","clk":"11450143684","pt":1717318503164,"mc":[{"id":"1.229554905","rc":[{"atb":[[4.4,10.22]],"id":61631980}],"con":true,"img":false}]}
{"op":"mcm","clk":"11450143692","pt":1717318503268,"mc":[{"id":"1.229554905","rc":[{"atb":[[3.85,40.8]],"id":61631980}],"con":true,"img":false}]}
{"op":"mcm","clk":"11450143993","pt":1717318506755,"mc":[{"id":"1.229554905","rc":[{"atb":[[40,7.29],[50,2.9],[30,9.81]],"id":42269942},{"atl":[[610,0.15],[510,0.12]],"id":42269942},{"atb":[[9.6,24.29],[8.6,27.48],[11.5,9.95]],"id":57451148},{"atl":[[300,0.7],[200,0.7]],"id":57451148},{"atb":[[4.3,31.65],[3.9,72.04],[3.65,78.83]],"id":61631980},{"atl":[[34,6.34],[22,6.64]],"id":61631980},{"atb":[[1.18,1160.62],[1.23,454.15],[1.13,1607.02]],"id":60780007},{"atl":[[2.64,85.07],[2.84,113.74]],"id":60780007},{"atb":[[3.4,87.04],[3.9,36.02],[3.65,78.83]],"id":61631978},{"atl":[[19,7.75],[28,7.75]],"id":61631978}],"con":true,"img":false}]}
{"op":"mcm","clk":"11450144103","pt":1717318508053,"mc":[{"id":"1.229554905","rc":[{"atl":[[13.5,1.43]],"id":61631978}],"con":true,"img":false}]}
{"op":"mcm","clk":"11450145204","pt":1717318520582,"mc":[{"id":"1.229554905","rc":[{"atl":[[1000,3.52]],"id":61631978}],"con":true,"img":false}]}
{"op":"mcm","clk":"11450145221","pt":1717318520797,"mc":[{"id":"1.229554905","rc":[{"atl":[[1000,2.15]],"id":61631978}],"con":true,"img":false}]}
{"op":"mcm","clk":"11450145239","pt":1717318521001,"mc":[{"id":"1.229554905","rc":[{"atl":[[1000,1.17]],"id":61631978}],"con":true,"img":false}]}
{"op":"mcm","clk":"11450145251","pt":1717318521054,"mc":[{"id":"1.229554905","rc":[{"atl":[[13.5,2.42]],"id":61631978}],"con":true,"img":false}]}
{"op":"mcm","clk":"11450145419","pt":1717318522979,"mc":[{"id":"1.229554905","rc":[{"atb":[[5.5,2.61]],"id":61631980},{"atb":[[1.3,2.61]],"id":60780007},{"atb":[[4.8,2.61]],"id":61631978}],"con":true,"img":false}]}
{"op":"mcm","clk":"11450146076","pt":1717318531273,"mc":[{"id":"1.229554905","rc":[{"atl":[[13.5,0.98]],"id":61631978}],"con":true,"img":false}]}
{"op":"mcm","clk":"11450147122","pt":1717318543196,"mc":[{"id":"1.229554905","rc":[{"atb":[[1.15,0],[1.19,0]],"id":60780007}],"con":true,"img":false}]}
{"op":"mcm","clk":"11450147130","pt":1717318543302,"mc":[{"id":"1.229554905","rc":[{"atb":[[1.19,689.36],[1.24,95.36]],"id":60780007}],"con":true,"img":false}]}
{"op":"mcm","clk":"11450147789","pt":1717318550710,"mc":[{"id":"1.229554905","rc":[{"spn":295.0,"spf":"NaN","id":42269942},{"spn":11.25,"spf":"NaN","id":61631980},{"atl":[[2.1,0]],"id":60780007},{"spn":1.65,"spf":"NaN","id":60780007},{"spn":8.9,"spf":"NaN","id":61631978}],"con":true,"img":false}]}
{"op":"mcm","clk":"11450148001","pt":1717318553101,"mc":[{"id":"1.229554905","rc":[{"atb":[[3.85,0]],"id":61631980},{"atl":[[24,0]],"id":61631980},{"atb":[[3.45,0]],"id":61631978},{"atl":[[20,0]],"id":61631978}],"con":true,"img":false}]}
{"op":"mcm","clk":"11450148013","pt":1717318553204,"mc":[{"id":"1.229554905","rc":[{"atb":[[4.4,51.03]],"id":61631980},{"atl":[[21,5.75]],"id":61631980},{"atb":[[3.95,41.18]],"id":61631978},{"atl":[[17,6.29]],"id":61631978}],"con":true,"img":false}]}
{"op":"mcm","clk":"11450148043","pt":1717318553509,"mc":[{"id":"1.229554905","rc":[{"atl":[[17,0]],"id":61631980}],"con":true,"img":false}]}
{"op":"mcm","clk":"11450148408","pt":1717318557805,"mc":[{"id":"1.229554905","rc":[{"atb":[[2.74,0],[2.5,66.67]],"id":61631980}],"con":true,"img":false}]}
{"op":"mcm","clk":"11450150669","pt":1717318582219,"mc":[{"id":"1.229554905","rc":[{"atb":[[2.8,0]],"id":61631980}],"con":true,"img":false}]}
{"op":"mcm","clk":"11450152878","pt":1717318603831,"mc":[{"id":"1.229554905","rc":[{"atl":[[2.1,9.18]],"id":60780007}],"con":true,"img":false}]}
{"op":"mcm","clk":"11450155464","pt":1717318631668,"mc":[{"id":"1.229554905","rc":[{"atl":[[990,0]],"id":42269942},{"spn":11.5,"spf":"NaN","id":61631980}],"con":true,"img":false}]}
{"op":"mcm","clk":"11450162640","pt":1717318702662,"mc":[{"id":"1.229554905","rc":[{"atl":[[13.5,0]],"id":61631978}],"con":true,"img":false}]}
{"op":"mcm","clk":"11450164079","pt":1717318718278,"mc":[{"id":"1.229554905","rc":[{"atl":[[13,0]],"id":61631978}],"con":true,"img":false}]}
{"op":"mcm","clk":"11450166337","pt":1717318743009,"mc":[{"id":"1.229554905","rc":[{"atl":[[13.5,1.43]],"id":61631978}],"con":true,"img":false}]}
{"op":"mcm","clk":"11450170656","pt":1717318790842,"mc":[{"id":"1.229554905","rc":[{"atb":[[2.74,57.47]],"id":61631980},{"spn":9.15,"spf":"NaN","id":61631978}],"con":true,"img":false}]}
{"op":"mcm","clk":"11450170662","pt":1717318790943,"mc":[{"id":"1.229554905","rc":[{"atb":[[2.5,0]],"id":61631980}],"con":true,"img":false}]}
{"op":"mcm","clk":"11450170962","pt":1717318794760,"mc":[{"id":"1.229554905","rc":[{"atl":[[2.42,0]],"id":60780007}],"con":true,"img":false}]}
{"op":"mcm","clk":"11450170973","pt":1717318794864,"mc":[{"id":"1.229554905","rc":[{"atl":[[3.6,5.96]],"id":60780007}],"con":true,"img":false}]}
{"op":"mcm","clk":"11450171501","pt":1717318800674,"mc":[{"id":"1.229554905","rc":[{"atl":[[960,2.85]],"id":42269942}],"con":true,"img":false}]}
{"op":"mcm","clk":"11450171516","pt":1717318800776,"mc":[{"id":"1.229554905","rc":[{"atl":[[990,2]],"id":42269942}],"con":true,"img":false}]}
{"op":"mcm","clk":"11450171527","pt":1717318800880,"mc":[{"id":"1.229554905","rc":[{"atl":[[960,0.85]],"id":42269942}],"con":true,"img":false}]}
{"op":"mcm","clk":"11450171542","pt":1717318800976,"mc":[{"id":"1.229554905","rc":[{"atl":[[960,2.85]],"id":42269942}],"con":true,"img":false}]}
{"op":"mcm","clk":"11450171553","pt":1717318801083,"mc":[{"id":"1.229554905","rc":[{"atl":[[990,0]],"id":42269942},{"atb":[[4.9,1.73]],"id":61631978}],"con":true,"img":false}]}
{"op":"mcm","clk":"11450171593","pt":1717318801362,"mc":[{"id":"1.229554905","rc":[{"atl":[[1000,1.85]],"id":61631980}],"con":true,"img":false}]}
{"op":"mcm","clk":"11450171696","pt":1717318802298,"mc":[{"id":"1.229554905","rc":[{"atl":[[1000,1.5]],"id":61631980}],"con":true,"img":false}]}
{"op":"mcm","clk":"11450171909","pt":1717318804075,"mc":[{"id":"1.229554905","rc":[{"atl":[[1000,1]],"id":61631980}],"con":true,"img":false}]}
{"op":"mcm","clk":"11450171922","pt":1717318804182,"mc":[{"id":"1.229554905","rc":[{"atl":[[17,0.5]],"id":61631980}],"con":true,"img":false}]}
{"op":"mcm","clk":"11450172469","pt":1717318809770,"mc":[{"id":"1.229554905","rc":[{"atl":[[17.5,0]],"id":61631978}],"con":true,"img":false}]}
{"op":"mcm","clk":"11450172492","pt":1717318809976,"mc":[{"id":"1.229554905","rc":[{"atl":[[23,0]],"id":61631980}],"con":true,"img":false}]}
{"op":"mcm","clk":"11450172515","pt":1717318810186,"mc":[{"id":"1.229554905","rc":[{"atl":[[110,2.61]],"id":57451148}],"con":true,"img":false}]}
{"op":"mcm","clk":"11450172535","pt":1717318810383,"mc":[{"id":"1.229554905","rc":[{"atb":[[12,5.1]],"id":57451148}],"con":true,"img":false}]}
{"op":"mcm","clk":"11450172556","pt":1717318810595,"mc":[{"id":"1.229554905","rc":[{"atb":[[1.07,0]],"id":60780007}],"con":true,"img":false}]}
{"op":"mcm","clk":"11450172588","pt":1717318810954,"mc":[{"id":"1.229554905","rc":[{"atb":[[3.7,0]],"id":61631978}],"con":true,"img":false}]}
{"op":"mcm","clk":"11450172617","pt":1717318811170,"mc":[{"id":"1.229554905","rc":[{"atb":[[4.4,40.8]],"id":61631980}],"con":true,"img":false}]}
{"op":"mcm","clk":"11450172638","pt":1717318811383,"mc":[{"id":"1.229554905","rc":[{"atl":[[3.6,0]],"id":60780007}],"con":true,"img":false}]}
{"op":"mcm","clk":"11450172823","pt":1717318813200,"mc":[{"id":"1.229554905","rc":[{"atl":[[17,0]],"id":61631978}],"con":true,"img":false}]}
{"op":"mcm","clk":"11450172836","pt":1717318813304,"mc":[{"id":"1.229554905","rc":[{"atl":[[18.5,6.29]],"id":61631978}],"con":true,"img":false}]}
{"op":"mcm","clk":"11450174507","pt":1717318831186,"mc":[{"id":"1.229554905","rc":[{"atl":[[2.1,0]],"id":60780007}],"con":true,"img":false}]}
{"op":"mcm","clk":"11450176745","pt":1717318855645,"mc":[{"id":"1.229554905","rc":[{"spn":11.25,"spf":"NaN","id":61631980},{"atl":[[2.1,9.18]],"id":60780007},{"spn":9.2,"spf":"NaN","id":61631978}],"con":true,"img":false}]}
{"op":"mcm","clk":"11450176881","pt":1717318856851,"mc":[{"id":"1.229554905","rc":[{"atb":[[40,0],[50,0],[30,0]],"id":42269942},{"atl":[[610,0],[510,0]],"id":42269942},{"atb":[[9.6,0],[8.6,0],[11.5,0]],"id":57451148},{"atl":[[300,0],[200,0]],"id":57451148},{"atb":[[4.3,0],[3.9,0],[3.65,0]],"id":61631980},{"atl":[[34,0],[22,0]],"id":61631980},{"atb":[[1.18,0],[1.23,0],[1.13,0]],"id":60780007},{"atl":[[2.64,0],[2.84,0]],"id":60780007},{"atb":[[3.4,0],[3.9,0],[3.65,0]],"id":61631978},{"atl":[[19,0],[28,0]],"id":61631978}],"con":true,"img":false}]}
{"op":"mcm","clk":"11450176906","pt":1717318857054,"mc":[{"id":"1.229554905","rc":[{"atl":[[960,0.85],[1000,3]],"id":42269942}],"con":true,"img":false}]}
{"op":"mcm","clk":"11450177494","pt":1717318863129,"mc":[{"id":"1.229554905","rc":[{"atb":[[4.4,0]],"id":61631980},{"atl":[[21,0]],"id":61631980},{"atb":[[1.19,0],[1.24,0]],"id":60780007},{"atb":[[3.95,0]],"id":61631978}],"con":true,"img":false}]}
{"op":"mcm","clk":"11450177507","pt":1717318863236,"mc":[{"id":"1.229554905","rc":[{"atb":[[3.85,40.8]],"id":61631980},{"atl":[[24,5.75]],"id":61631980},{"atb":[[1.15,689.36],[1.19,95.36]],"id":60780007},{"atb":[[3.45,41.18]],"id":61631978}],"con":true,"img":false}]}
{"op":"mcm","clk":"11450177623","pt":1717318864325,"mc":[{"id":"1.229554905","rc":[{"atb":[[1.17,43.84]],"id":60780007}],"con":true,"img":false}]}
{"op":"mcm","clk":"11450177633","pt":1717318864431,"mc":[{"id":"1.229554905","rc":[{"atb":[[4.3,3.1]],"id":61631980},{"atl":[[2.28,8.36]],"id":60780007},{"atb":[[3.9,3.57]],"id":61631978}],"con":true,"img":false}]}
{"op":"mcm","clk":"11450177990","pt":1717318867932,"mc":[{"id":"1.229554905","rc":[{"atb":[[3.9,0]],"id":61631978}],"con":true,"img":false}]}
{"op":"mcm","clk":"11450178969","pt":1717318877467,"mc":[{"id":"1.229554905","rc":[{"atb":[[40,7.29],[50,2.9],[30,9.81]],"id":42269942},{"atl":[[610,0.15],[510,0.12]],"id":42269942},{"atb":[[9.6,24.29],[8.6,27.48],[11.5,9.95]],"id":57451148},{"atl":[[300,0.7],[200,0.7]],"id":57451148},{"atb":[[4.3,34.75],[3.9,72.04],[3.65,78.83]],"id":61631980},{"atl":[[34,6.34],[22,6.64]],"id":61631980},{"atb":[[1.18,1160.62],[1.23,454.15],[1.13,1607.02]],"id":60780007},{"atl":[[2.64,85.07],[2.84,113.74]],"id":60780007},{"atb":[[3.4,87.04],[3.9,36.02],[3.65,78.83]],"id":61631978},{"atl":[[19,7.75],[28,7.75]],"id":61631978}],"con":true,"img":false}]}
{"op":"mcm","clk":"11450178988","pt":1717318877669,"mc":[{"id":"1.229554905","rc":[{"atl":[[960,2.85],[1000,1]],"id":42269942}],"con":true,"img":false}]}
{"op":"mcm","clk":"11450179000","pt":1717318877771,"mc":[{"id":"1.229554905","rc":[{"atl":[[1000,1.85]],"id":61631980}],"con":true,"img":false}]}
{"op":"mcm","clk":"11450179007","pt":1717318877868,"mc":[{"id":"1.229554905","rc":[{"atl":[[17,0]],"id":61631980}],"con":true,"img":false}]}
{"op":"mcm","clk":"11450179060","pt":1717318878647,"mc":[{"id":"1.229554905","rc":[{"atl":[[1000,1.5]],"id":61631980}],"con":true,"img":false}]}
{"op":"mcm","clk":"11450179110","pt":1717318879267,"mc":[{"id":"1.229554905","rc":[{"atl":[[1000,1]],"id":61631980}],"con":true,"img":false}]}
{"op":"mcm","clk":"11450179124","pt":1717318879366,"mc":[{"id":"1.229554905","rc":[{"atl":[[21,0.5]],"id":61631980}],"con":true,"img":false}]}
{"op":"mcm","clk":"11450180538","pt":1717318894334,"mc":[{"id":"1.229554905","rc":[{"atb":[[2.74,0],[2.5,66.67]],"id":61631980}],"con":true,"img":false}]}
{"op":"mcm","clk":"11450180571","pt":1717318894646,"mc":[{"id":"1.229554905","rc":[{"atl":[[21,0],[1000,1.85]],"id":61631980}],"con":true,"img":false}]}
{"op":"mcm","clk":"11450180601","pt":1717318894960,"mc":[{"id":"1.229554905","rc":[{"atl":[[1000,1.51]],"id":61631980}],"con":true,"img":false}]}
{"op":"mcm","clk":"11450180631","pt":1717318895270,"mc":[{"id":"1.229554905","rc":[{"atl":[[1000,1]],"id":61631980}],"con":true,"img":false}]}
{"op":"mcm","clk":"11450180642","pt":1717318895370,"mc":[{"id":"1.229554905","rc":[{"atl":[[16.5,0.51]],"id":61631980}],"con":true,"img":false}]}
{"op":"mcm","clk":"11450180897","pt":1717318897864,"mc":[{"id":"1.229554905","rc":[{"atb":[[2.5,0],[2.74,57.47]],"id":61631980}],"con":true,"img":false}]}
{"op":"mcm","clk":"11450181067","pt":1717318899577,"mc":[{"id":"1.229554905","rc":[{"atl":[[16.5,0]],"id":61631980}],"con":true,"img":false}]}
{"op":"mcm","clk":"11450181121","pt":1717318900048,"mc":[{"id":"1.229554905","rc":[{"atl":[[1000,1.85]],"id":61631980}],"con":true,"img":false}]}
{"op":"mcm","clk":"11450181205","pt":1717318901038,"mc":[{"id":"1.229554905","rc":[{"atl":[[1000,1.51]],"id":61631980}],"con":true,"img":false}]}
{"op":"mcm","clk":"11450181394","pt":1717318903162,"mc":[{"id":"1.229554905","rc":[{"atl":[[1000,1]],"id":61631980}],"con":true,"img":false}]}
{"op":"mcm","clk":"11450181404","pt":1717318903266,"mc":[{"id":"1.229554905","rc":[{"atl":[[17,0.51]],"id":61631980},{"atb":[[1.15,0],[1.19,0]],"id":60780007}],"con":true,"img":false}]}
{"op":"mcm","clk":"11450181410","pt":1717318903370,"mc":[{"id":"1.229554905","rc":[{"atb":[[1.19,689.36],[1.24,95.36]],"id":60780007}],"con":true,"img":false}]}
{"op":"mcm","clk":"11450181545","pt":1717318904540,"mc":[{"id":"1.229554905","rc":[{"atl":[[1000,1.85]],"id":61631980}],"con":true,"img":false}]}
{"op":"mcm","clk":"11450181568","pt":1717318904849,"mc":[{"id":"1.229554905","rc":[{"atl":[[17,0]],"id":61631980}],"con":true,"img":false}]}
{"op":"mcm","clk":"11450181595","pt":1717318905159,"mc":[{"id":"1.229554905","rc":[{"atl":[[1000,1.52]],"id":61631980}],"con":true,"img":false}]}
{"op":"mcm","clk":"11450181633","pt":1717318905587,"mc":[{"id":"1.229554905","rc":[{"atl":[[1000,1]],"id":61631980}],"con":true,"img":false}]}
{"op":"mcm","clk":"11450181640","pt":1717318905693,"mc":[{"id":"1.229554905","rc":[{"atl":[[16,0.52]],"id":61631980}],"con":true,"img":false}]}
{"op":"mcm","clk":"11450181799","pt":1717318907244,"mc":[{"id":"1.229554905","rc":[{"atb":[[1.17,0]],"id":60780007}],"con":true,"img":false}]}
{"op":"mcm","clk":"11450182828","pt":1717318918685,"mc":[{"id":"1.229554905","rc":[{"spn":10.75,"spf":"NaN","id":61631980},{"atl":[[1.92,3]],"id":60780007},{"spn":1.61,"spf":"NaN","id":60780007}],"con":true,"img":false}]}
{"op":"mcm","clk":"11450183067","pt":1717318921086,"mc":[{"id":"1.229554905","rc":[{"atb":[[1.17,17.4]],"id":60780007}],"con":true,"img":false}]}
{"op":"mcm","clk":"11450183159","pt":1717318922168,"mc":[{"id":"1.229554905","rc":[{"atb":[[3.9,39.59]],"id":61631978}],"con":true,"img":false}]}
{"op":"mcm","clk":"11450183276","pt":1717318923199,"mc":[{"id":"1.229554905","rc":[{"atb":[[3.85,0]],"id":61631980},{"atl":[[24,0]],"id":61631980},{"atb":[[3.45,0]],"id":61631978}],"con":true,"img":false}]}
{"op":"mcm","clk":"11450183287","pt":1717318923304,"mc":[{"id":"1.229554905","rc":[{"atb":[[4.4,40.8]],"id":61631980},{"atl":[[21,5.75]],"id":61631980},{"atb":[[3.95,41.18]],"id":61631978}],"con":true,"img":false}]}
{"op":"mcm","clk":"11450183978","pt":1717318931095,"mc":[{"id":"1.229554905","rc":[{"atl":[[1000,1.85]],"id":61631980}],"con":true,"img":false}]}
{"op":"mcm","clk":"11450184020","pt":1717318931507,"mc":[{"id":"1.229554905","rc":[{"atl":[[16,0]],"id":61631980}],"con":true,"img":false}]}
{"op":"mcm","clk":"11450184112","pt":1717318932589,"mc":[{"id":"1.229554905","rc":[{"atb":[[5.6,1.52]],"id":61631980}],"con":true,"img":false}]}
{"op":"mcm","clk":"11450184118","pt":1717318932698,"mc":[{"id":"1.229554905","rc":[{"atl":[[1000,1.52]],"id":61631980}],"con":true,"img":false}]}
{"op":"mcm","clk":"11450184204","pt":1717318933468,"mc":[{"id":"1.229554905","rc":[{"atl":[[1000,1]],"id":61631980}],"con":true,"img":false}]}
{"op":"mcm","clk":"11450184217","pt":1717318933627,"mc":[{"id":"1.229554905","rc":[{"atl":[[17,0.52]],"id":61631980}],"con":true,"img":false}]}
{"op":"mcm","clk":"11450184597","pt":1717318937514,"mc":[{"id":"1.229554905","rc":[{"atl":[[13.5,0]],"id":61631978}],"con":true,"img":false}]}
{"op":"mcm","clk":"11450185793","pt":1717318948629,"mc":[{"id":"1.229554905","rc":[{"atl":[[1000,3.52]],"id":61631978}],"con":true,"img":false}]}
{"op":"mcm","clk":"11450185812","pt":1717318948836,"mc":[{"id":"1.229554905","rc":[{"atl":[[1000,2.15]],"id":61631978}],"con":true,"img":false}]}
{"op":"mcm","clk":"11450185844","pt":1717318949047,"mc":[{"id":"1.229554905","rc":[{"atl":[[1000,1.17]],"id":61631978}],"con":true,"img":false}]}
{"op":"mcm","clk":"11450185849","pt":1717318949147,"mc":[{"id":"1.229554905","rc":[{"atl":[[13.5,0.98]],"id":61631978}],"con":true,"img":false}]}
{"op":"mcm","clk":"11450186458","pt":1717318954828,"mc":[{"id":"1.229554905","rc":[{"atb":[[4.3,31.65]],"id":61631980}],"con":true,"img":false}]}
{"op":"mcm","clk":"11450186521","pt":1717318955443,"mc":[{"id":"1.229554905","rc":[{"atb":[[3.9,36.02]],"id":61631978}],"con":true,"img":false}]}
{"op":"mcm","clk":"11450186567","pt":1717318955906,"mc":[{"id":"1.229554905","rc":[{"atb":[[4.3,34.75]],"id":61631980}],"con":true,"img":false}]}
{"op":"mcm","clk":"11450187777","pt":1717318968927,"mc":[{"id":"1.229554905","rc":[{"atl":[[960,0.85]],"id":42269942}],"con":true,"img":false}]}
{"op":"mcm","clk":"11450188545","pt":1717318977132,"mc":[{"id":"1.229554905","rc":[{"atb":[[3.9,39.59]],"id":61631978}],"con":true,"img":false}]}
{"op":"mcm","clk":"11450191495","pt":1717319008172,"mc":[{"id":"1.229554905","rc":[{"atb":[[4.3,35.69]],"id":61631980},{"spn":11.3,"spf":"NaN","id":61631980}],"con":true,"img":false}]}
{"op":"mcm","clk":"11450196472","pt":1717319062267,"mc":[{"id":"1.229554905","rc":[{"atl":[[2.1,0]],"id":60780007}],"con":true,"img":false}]}
{"op":"mcm","clk":"11450196481","pt":1717319062377,"mc":[{"id":"1.229554905","rc":[{"atb":[[1.17,43.84]],"id":60780007}],"con":true,"img":false}]}
{"op":"mcm","clk":"11450197759","pt":1717319076383,"mc":[{"id":"1.229554905","rc":[{"atb":[[4.3,31.65],[2.74,0],[2.5,66.67]],"id":61631980}],"con":true,"img":false}]}
{"op":"mcm","clk":"11450198184","pt":1717319081211,"mc":[{"id":"1.229554905","rc":[{"atl":[[960,2.85]],"id":42269942}],"con":true,"img":false}]}
{"op":"mcm","clk":"11450198736","pt":1717319086839,"mc":[{"id":"1.229554905","rc":[{"atb":[[2.5,0],[2.74,57.47]],"id":61631980}],"con":true,"img":false}]}
{"op":"mcm","clk":"11450199451","pt":1717319093920,"mc":[{"id":"1.229554905","rc":[{"atl":[[1.92,0]],"id":60780007}],"con":true,"img":false}]}
{"op":"mcm","clk":"11450199468","pt":1717319094123,"mc":[{"id":"1.229554905","rc":[{"atl":[[1.91,3]],"id":60780007}],"con":true,"img":false}]}
{"op":"mcm","clk":"11450200145","pt":1717319101232,"mc":[{"id":"1.229554905","rc":[{"atl":[[2.1,9.18]],"id":60780007}],"con":true,"img":false}]}
{"op":"mcm","clk":"11450200164","pt":1717319101349,"mc":[{"id":"1.229554905","rc":[{"atl":[[2.28,0]],"id":60780007}],"con":true,"img":false}]}
{"op":"mcm","clk":"11450200178","pt":1717319101393,"mc":[{"id":"1.229554905","rc":[{"atb":[[3.9,42.53]],"id":61631978}],"con":true,"img":false}]}
{"op":"mcm","clk":"11450200187","pt":1717319101494,"mc":[{"id":"1.229554905","rc":[{"atb":[[3.9,38.96]],"id":61631978}],"con":true,"img":false}]}
{"op":"mcm","clk":"11450200301","pt":1717319102509,"mc":[{"id":"1.229554905","rc":[{"atl":[[2.28,8.36]],"id":60780007}],"con":true,"img":false}]}
{"op":"mcm","clk":"11450201022","pt":1717319109713,"mc":[{"id":"1.229554905","rc":[{"atb":[[1.2,1.7]],"id":57451148},{"atb":[[1.09,1.7]],"id":61631980}],"con":true,"img":false}]}
{"op":"mcm","clk":"11450201048","pt":1717319110023,"mc":[{"id":"1.229554905","rc":[{"atb":[[1.08,1.7]],"id":61631978}],"con":true,"img":false}]}
{"op":"mcm","clk":"11450201063","pt":1717319110238,"mc":[{"id":"1.229554905","rc":[{"atb":[[1.8,1.7]],"id":42269942},{"atb":[[1.03,1.7]],"id":60780007}],"con":true,"img":false}]}
{"op":"mcm","clk":"11450201095","pt":1717319110544,"mc":[{"id":"1.229554905","rc":[{"atb":[[1.09,0.07]],"id":61631980},{"atb":[[1.08,0.08]],"id":61631978}],"con":true,"img":false}]}
{"op":"mcm","clk":"11450201130","pt":1717319110858,"mc":[{"id":"1.229554905","rc":[{"atb":[[1.03,0.32]],"id":60780007}],"con":true,"img":false}]}
{"op":"mcm","clk":"11450201157","pt":1717319111056,"mc":[{"id":"1.229554905","rc":[{"atb":[[1.8,0]],"id":42269942}],"con":true,"img":false}]}
{"op":"mcm","clk":"11450201177","pt":1717319111271,"mc":[{"id":"1.229554905","rc":[{"atb":[[1.08,0]],"id":61631978}],"con":true,"img":false}]}
{"op":"mcm","clk":"11450201186","pt":1717319111331,"mc":[{"id":"1.229554905","rc":[{"atb":[[1.2,0.03]],"id":57451148},{"atb":[[5,0.08]],"id":61631978}],"con":true,"img":false}]}
{"op":"mcm","clk":"11450201232","pt":1717319111741,"mc":[{"id":"1.229554905","rc":[{"atb":[[1.09,0]],"id":61631980}],"con":true,"img":false}]}
{"op":"mcm","clk":"11450201241","pt":1717319111844,"mc":[{"id":"1.229554905","rc":[{"atb":[[5.7,0.07]],"id":61631980}],"con":true,"img":false}]}
{"op":"mcm","clk":"11450201270","pt":1717319112149,"mc":[{"id":"1.229554905","rc":[{"atb":[[1.05,1.7]],"id":61631980}],"con":true,"img":false}]}
{"op":"mcm","clk":"11450201280","pt":1717319112255,"mc":[{"id":"1.229554905","rc":[{"atb":[[1.1,1.7]],"id":57451148},{"atb":[[1.03,0]],"id":60780007}],"con":true,"img":false}]}
{"op":"mcm","clk":"11450201290","pt":1717319112357,"mc":[{"id":"1.229554905","rc":[{"atb":[[1.31,0.32]],"id":60780007}],"con":true,"img":false}]}
{"op":"mcm","clk":"11450201308","pt":1717319112516,"mc":[{"id":"1.229554905","rc":[{"atb":[[1.04,1.7]],"id":61631978}],"con":true,"img":false}]}
{"op":"mcm","clk":"11450201321","pt":1717319112615,"mc":[{"id":"1.229554905","rc":[{"atb":[[1.8,1.7]],"id":42269942}],"con":true,"img":false}]}
{"op":"mcm","clk":"11450201334","pt":1717319112725,"mc":[{"id":"1.229554905","rc":[{"atb":[[80,0.11]],"id":42269942}],"con":true,"img":false}]}
{"op":"mcm","clk":"11450201354","pt":1717319112927,"mc":[{"id":"1.229554905","rc":[{"atb":[[1.03,1.7]],"id":60780007}],"con":true,"img":false}]}
{"op":"mcm","clk":"11450201366","pt":1717319113037,"mc":[{"id":"1.229554905","rc":[{"atb":[[1.2,0]],"id":57451148},{"atl":[[1000,2.7]],"id":61631980}],"con":true,"img":false}]}
{"op":"mcm","clk":"11450201379","pt":1717319113137,"mc":[{"id":"1.229554905","rc":[{"atb":[[12.5,0.03]],"id":57451148}],"con":true,"img":false}]}
{"op":"mcm","clk":"11450201399","pt":1717319113342,"mc":[{"id":"1.229554905","rc":[{"atl":[[1000,2.87]],"id":61631978}],"con":true,"img":false}]}
{"op":"mcm","clk":"11450201418","pt":1717319113651,"mc":[{"id":"1.229554905","rc":[{"atb":[[1.05,0.15]],"id":61631980},{"atl":[[1000,2.7],[2.28,0]],"id":60780007}],"con":true,"img":false}]}
{"op":"mcm","clk":"11450201443","pt":1717319113921,"mc":[{"id":"1.229554905","rc":[{"atb":[[1.1,0.06]],"id":57451148},{"atl":[[1000,2.7]],"id":57451148}],"con":true,"img":false}]}
{"op":"mcm","clk":"11450201473","pt":1717319114230,"mc":[{"id":"1.229554905","rc":[{"atb":[[1.05,0]],"id":61631980},{"atb":[[1.04,0.17]],"id":61631978}],"con":true,"img":false}]}
{"op":"mcm","clk":"11450201484","pt":1717319114334,"mc":[{"id":"1.229554905","rc":[{"atb":[[5.7,0.23]],"id":61631980}],"con":true,"img":false}]}
{"op":"mcm","clk":"11450201527","pt":1717319114861,"mc":[{"id":"1.229554905","rc":[{"atl":[[1000,1.05]],"id":61631980}],"con":true,"img":false}]}
{"op":"mcm","clk":"11450201539","pt":1717319114958,"mc":[{"id":"1.229554905","rc":[{"atb":[[1.1,0]],"id":57451148}],"con":true,"img":false}]}
{"op":"mcm","clk":"11450201551","pt":1717319115016,"mc":[{"id":"1.229554905","rc":[{"atb":[[12.5,0.1]],"id":57451148}],"con":true,"img":false}]}
{"op":"mcm","clk":"11450201591","pt":1717319115326,"mc":[{"id":"1.229554905","rc":[{"atb":[[1.8,0]],"id":42269942}],"con":true,"img":false}]}
{"op":"mcm","clk":"11450201621","pt":1717319115738,"mc":[{"id":"1.229554905","rc":[{"atb":[[1.03,0.64]],"id":60780007}],"con":true,"img":false}]}
{"op":"mcm","clk":"11450201633","pt":1717319115843,"mc":[{"id":"1.229554905","rc":[{"atl":[[1000,1.23]],"id":61631978}],"con":true,"img":false}]}
{"op":"mcm","clk":"11450201647","pt":1717319116047,"mc":[{"id":"1.229554905","rc":[{"atl":[[1000,1.45]],"id":60780007}],"con":true,"img":false}]}
{"op":"mcm","clk":"11450201663","pt":1717319116162,"mc":[{"id":"1.229554905","rc":[{"atb":[[1.04,0]],"id":61631978}],"con":true,"img":false}]}
{"op":"mcm","clk":"11450201675","pt":1717319116258,"mc":[{"id":"1.229554905","rc":[{"atb":[[5,0.25]],"id":61631978}],"con":true,"img":false}]}
{"op":"mcm","clk":"11450201713","pt":1717319116525,"mc":[{"id":"1.229554905","rc":[{"atl":[[1000,1.01]],"id":57451148}],"con":true,"img":false}]}
{"op":"mcm","clk":"11450201818","pt":1717319117646,"mc":[{"id":"1.229554905","rc":[{"atl":[[1000,1]],"id":61631980}],"con":true,"img":false}]}
{"op":"mcm","clk":"11450201828","pt":1717319117757,"mc":[{"id":"1.229554905","rc":[{"atl":[[17,0.57]],"id":61631980}],"con":true,"img":false}]}
{"op":"mcm","clk":"11450201880","pt":1717319118267,"mc":[{"id":"1.229554905","rc":[{"atb":[[1.8,0]],"id":42269942}],"con":true,"img":false}]}
{"op":"mcm","clk":"11450201888","pt":1717319118333,"mc":[{"id":"1.229554905","rc":[{"atb":[[80,0.11]],"id":42269942}],"con":true,"img":false}]}
{"op":"mcm","clk":"11450201925","pt":1717319118733,"mc":[{"id":"1.229554905","rc":[{"atb":[[1.03,0]],"id":60780007}],"con":true,"img":false}]}
{"op":"mcm","clk":"11450201936","pt":1717319118834,"mc":[{"id":"1.229554905","rc":[{"atb":[[1.31,0.97]],"id":60780007}],"con":true,"img":false}]}
{"op":"mcm","clk":"11450201982","pt":1717319119256,"mc":[{"id":"1.229554905","rc":[{"atl":[[1000,1.17]],"id":61631978}],"con":true,"img":false}]}
{"op":"mcm","clk":"11450201998","pt":1717319119363,"mc":[{"id":"1.229554905","rc":[{"atl":[[13,0.06]],"id":61631978}],"con":true,"img":false}]}
{"op":"mcm","clk":"11450202032","pt":1717319119618,"mc":[{"id":"1.229554905","rc":[{"atl":[[1000,1]],"id":60780007}],"con":true,"img":false}]}
{"op":"mcm","clk":"11450202047","pt":1717319119724,"mc":[{"id":"1.229554905","rc":[{"atl":[[1.9,0.45]],"id":60780007}],"con":true,"img":false}]}
{"op":"mcm","clk":"11450202090","pt":1717319120133,"mc":[{"id":"1.229554905","rc":[{"atl":[[1000,1]],"id":57451148}],"con":true,"img":false}]}
{"op":"mcm","clk":"11450202104","pt":1717319120238,"mc":[{"id":"1.229554905","rc":[{"atl":[[48,0.19]],"id":57451148}],"con":true,"img":false}]}
{"op":"mcm","clk":"11450202288","pt":1717319121636,"mc":[{"id":"1.229554905","rc":[{"atl":[[1000,2.87]],"id":61631978}],"con":true,"img":false}]}
{"op":"mcm","clk":"11450202517","pt":1717319123756,"mc":[{"id":"1.229554905","rc":[{"atb":[[4.3,35.69]],"id":61631980}],"con":true,"img":false}]}
{"op":"mcm","clk":"11450202551","pt":1717319124157,"mc":[{"id":"1.229554905","rc":[{"atl":[[1000,1.23]],"id":61631978}],"con":true,"img":false}]}
{"op":"mcm","clk":"11450202806","pt":1717319127268,"mc":[{"id":"1.229554905","rc":[{"atl":[[1000,1.17]],"id":61631978}],"con":true,"img":false}]}
{"op":"mcm","clk":"11450202813","pt":1717319127367,"mc":[{"id":"1.229554905","rc":[{"atl":[[14,0.05]],"id":61631978}],"con":true,"img":false}]}
{"op":"mcm","clk":"11450202968","pt":1717319129343,"mc":[{"id":"1.229554905","rc":[{"atl":[[13.5,0]],"id":61631978}],"con":true,"img":false}]}
{"op":"mcm","clk":"11450203630","pt":1717319136263,"mc":[{"id":"1.229554905","rc":[{"atb":[[12.5,2.14]],"id":57451148}],"con":true,"img":false}]}
{"op":"mcm","clk":"11450203966","pt":1717319139627,"mc":[{"id":"1.229554905","rc":[{"spn":30.25,"spf":"NaN","id":57451148},{"atb":[[1.02,207.72]],"id":61631980},{"spn":11.35,"spf":"NaN","id":61631980},{"spn":1.6,"spf":"NaN","id":60780007},{"spn":9.0,"spf":"NaN","id":61631978}],"con":true,"img":false}]}
{"op":"mcm","clk":"11450204042","pt":1717319140354,"mc":[{"id":"1.229554905","rc":[{"atb":[[1.02,2]],"id":61631978}],"con":true,"img":false}]}
{"op":"mcm","clk":"11450204131","pt":1717319141035,"mc":[{"id":"1.229554905","rc":[{"atb":[[1.02,140.04]],"id":60780007}],"con":true,"img":false}]}
{"op":"mcm","clk":"11450204340","pt":1717319143061,"mc":[{"id":"1.229554905","rc":[{"atb":[[1.02,205.72]],"id":61631980}],"con":true,"img":false}]}
{"op":"mcm","clk":"11450204348","pt":1717319143109,"mc":[{"id":"1.229554905","rc":[{"atb":[[5.6,3.52]],"id":61631980}],"con":true,"img":false}]}
{"op":"mcm","clk":"11450204378","pt":1717319143419,"mc":[{"id":"1.229554905","rc":[{"atb":[[1.02,0]],"id":61631978}],"con":true,"img":false}]}
{"op":"mcm","clk":"11450204388","pt":1717319143528,"mc":[{"id":"1.229554905","rc":[{"atb":[[4.9,3.73]],"id":61631978}],"con":true,"img":false}]}
{"op":"mcm","clk":"11450204424","pt":1717319143832,"mc":[{"id":"1.229554905","rc":[{"atb":[[1.02,138.04]],"id":60780007}],"con":true,"img":false}]}
{"op":"mcm","clk":"11450204433","pt":1717319143939,"mc":[{"id":"1.229554905","rc":[{"atb":[[1.31,2.97]],"id":60780007}],"con":true,"img":false}]}
{"op":"mcm","clk":"11450204782","pt":1717319147516,"mc":[{"id":"1.229554905","rc":[{"atb":[[3.9,39.62]],"id":61631978}],"con":true,"img":false}]}
{"op":"mcm","clk":"11450204860","pt":1717319148339,"mc":[{"id":"1.229554905","rc":[{"atl":[[2.28,7.46]],"id":60780007}],"con":true,"img":false}]}
{"op":"mcm","clk":"11450205989","pt":1717319159664,"mc":[{"id":"1.229554905","rc":[{"atb":[[1.25,31.4]],"id":60780007}],"con":true,"img":false}]}
{"op":"mcm","clk":"11450208307","pt":1717319182392,"mc":[{"id":"1.229554905","rc":[{"atb":[[40,0],[50,0],[30,0]],"id":42269942},{"atl":[[610,0],[510,0]],"id":42269942},{"atb":[[11.5,0],[9.6,0],[8.6,0]],"id":57451148},{"atl":[[300,0],[200,0]],"id":57451148},{"atb":[[4.3,4.04],[3.9,0],[3.65,0]],"id":61631980},{"atl":[[34,0],[22,0]],"id":61631980},{"atb":[[1.18,0],[1.23,0],[1.13,0]],"id":60780007},{"atl":[[2.64,0],[2.84,0]],"id":60780007},{"atb":[[3.4,0],[3.9,3.6],[3.65,0]],"id":61631978},{"atl":[[19,0],[28,0]],"id":61631978}],"con":true,"img":false}]}
{"op":"mcm","clk":"11450208321","pt":1717319182499,"mc":[{"id":"1.229554905","rc":[{"atl":[[1000,3]],"id":42269942}],"con":true,"img":false}]}
{"op":"mcm","clk":"11450208333","pt":1717319182607,"mc":[{"id":"1.229554905","rc":[{"atl":[[960,0.85]],"id":42269942}],"con":true,"img":false}]}
{"op":"mcm","clk":"11450208399","pt":1717319183137,"mc":[{"id":"1.229554905","rc":[{"atb":[[4.4,0]],"id":61631980},{"atl":[[21,0]],"id":61631980},{"atb":[[1.19,0],[1.24,0]],"id":60780007},{"atb":[[3.95,0]],"id":61631978}],"con":true,"img":false}]}
{"op":"mcm","clk":"11450208408","pt":1717319183232,"mc":[{"id":"1.229554905","rc":[{"atb":[[3.85,40.8]],"id":61631980},{"atl":[[24,5.75]],"id":61631980},{"atb":[[1.18,689.36],[1.19,95.36]],"id":60780007},{"atb":[[3.45,41.18]],"id":61631978}],"con":true,"img":false}]}
{"op":"mcm","clk":"11450208434","pt":1717319183393,"mc":[{"id":"1.229554905","rc":[{"atl":[[17,0.05]],"id":61631980}],"con":true,"img":false}]}
{"op":"mcm","clk":"11450210111","pt":1717319200091,"mc":[{"id":"1.229554905","rc":[{"spn":520.0,"spf":"NaN","id":42269942},{"atb":[[4.3,3.1]],"id":61631980}],"con":true,"img":false}]}
{"op":"mcm","clk":"11450210471","pt":1717319203311,"mc":[{"id":"1.229554905","rc":[{"atb":[[40,7.29],[50,2.9],[30,9.81]],"id":42269942},{"atl":[[610,0.15],[510,0.12]],"id":42269942},{"atb":[[11.5,9.95],[9.6,24.29],[8.6,27.48]],"id":57451148},{"atl":[[300,0.7],[200,0.7]],"id":57451148},{"atb":[[4.3,34.75],[3.9,72.04],[3.65,78.83]],"id":61631980},{"atl":[[34,6.34],[22,6.64]],"id":61631980},{"atb":[[1.18,1849.98],[1.23,454.15],[1.13,1607.02]],"id":60780007},{"atl":[[2.64,85.07],[2.84,113.74]],"id":60780007},{"atb":[[3.4,87.04],[3.9,39.62],[3.65,78.83]],"id":61631978},{"atl":[[19,7.75],[28,7.75]],"id":61631978}],"con":true,"img":false}]}
{"op":"mcm","clk":"11450210488","pt":1717319203422,"mc":[{"id":"1.229554905","rc":[{"atl":[[960,2.85]],"id":42269942}],"con":true,"img":false}]}
{"op":"mcm","clk":"11450210504","pt":1717319203529,"mc":[{"id":"1.229554905","rc":[{"atl":[[1000,1]],"id":42269942}],"con":true,"img":false}]}
{"op":"mcm","clk":"11450212021","pt":1717319219119,"mc":[{"id":"1.229554905","rc":[{"atl":[[960,0.85]],"id":42269942}],"con":true,"img":false}]}
{"op":"mcm","clk":"11450212237","pt":1717319221307,"mc":[{"id":"1.229554905","rc":[{"atb":[[80,0.44]],"id":42269942}],"con":true,"img":false}]}
{"op":"mcm","clk":"11450213724","pt":1717319235757,"mc":[{"id":"1.229554905","rc":[{"atb":[[5.7,0.15]],"id":61631980}],"con":true,"img":false}]}
{"op":"mcm","clk":"11450213766","pt":1717319236119,"mc":[{"id":"1.229554905","rc":[{"atb":[[12.5,2.11]],"id":57451148}],"con":true,"img":false}]}
{"op":"mcm","clk":"11450213794","pt":1717319236433,"mc":[{"id":"1.229554905","rc":[{"atb":[[5,0.17]],"id":61631978}],"con":true,"img":false}]}
{"op":"mcm","clk":"11450213829","pt":1717319236737,"mc":[{"id":"1.229554905","rc":[{"atb":[[80,0.43]],"id":42269942}],"con":true,"img":false}]}
{"op":"mcm","clk":"11450213918","pt":1717319237664,"mc":[{"id":"1.229554905","rc":[{"atb":[[1.31,2.64]],"id":60780007}],"con":true,"img":false}]}
{"op":"mcm","clk":"11450213960","pt":1717319238135,"mc":[{"id":"1.229554905","rc":[{"atb":[[5.7,0]],"id":61631980},{"atl":[[17,0]],"id":61631980}],"con":true,"img":false}]}
{"op":"mcm","clk":"11450214081","pt":1717319239324,"mc":[{"id":"1.229554905","rc":[{"atb":[[12.5,2.04]],"id":57451148}],"con":true,"img":false}]}
{"op":"mcm","clk":"11450214102","pt":1717319239533,"mc":[{"id":"1.229554905","rc":[{"atl":[[48,0.17]],"id":57451148}],"con":true,"img":false}]}
{"op":"mcm","clk":"11450214135","pt":1717319239948,"mc":[{"id":"1.229554905","rc":[{"atb":[[5,0]],"id":61631978},{"atl":[[13,0]],"id":61631978}],"con":true,"img":false}]}
{"op":"mcm","clk":"11450214168","pt":1717319240259,"mc":[{"id":"1.229554905","rc":[{"atb":[[80,0.42]],"id":42269942}],"con":true,"img":false}]}
{"op":"mcm","clk":"11450214227","pt":1717319240827,"mc":[{"id":"1.229554905","rc":[{"atl":[[1.9,0]],"id":60780007}],"con":true,"img":false}]}
{"op":"mcm","clk":"11450214240","pt":1717319240932,"mc":[{"id":"1.229554905","rc":[{"atl":[[2.28,8.36]],"id":60780007}],"con":true,"img":false}]}
{"op":"mcm","clk":"11450214270","pt":1717319241240,"mc":[{"id":"1.229554905","rc":[{"atb":[[1.04,1.7]],"id":61631978}],"con":true,"img":false}]}
{"op":"mcm","clk":"11450214317","pt":1717319241659,"mc":[{"id":"1.229554905","rc":[{"atb":[[1.31,2]],"id":60780007}],"con":true,"img":false}]}
{"op":"mcm","clk":"11450214357","pt":1717319242075,"mc":[{"id":"1.229554905","rc":[{"atb":[[1.1,1.7]],"id":57451148},{"atl":[[2.28,0]],"id":60780007}],"con":true,"img":false}]}
{"op":"mcm","clk":"11450214377","pt":1717319242236,"mc":[{"id":"1.229554905","rc":[{"atl":[[1000,2.7]],"id":57451148},{"atl":[[1000,2.7]],"id":61631980}],"con":true,"img":false}]}
{"op":"mcm","clk":"11450214396","pt":1717319242499,"mc":[{"id":"1.229554905","rc":[{"atb":[[1.8,1.7]],"id":42269942}],"con":true,"img":false}]}
{"op":"mcm","clk":"11450214406","pt":1717319242545,"mc":[{"id":"1.229554905","rc":[{"atb":[[1.05,1.7]],"id":61631980}],"con":true,"img":false}]}
{"op":"mcm","clk":"11450214452","pt":1717319242960,"mc":[{"id":"1.229554905","rc":[{"atb":[[1.04,0.17]],"id":61631978}],"con":true,"img":false}]}
{"op":"mcm","clk":"11450214470","pt":1717319243167,"mc":[{"id":"1.229554905","rc":[{"atl":[[24,0]],"id":61631980},{"atb":[[1.19,0]],"id":60780007}],"con":true,"img":false}]}
{"op":"mcm","clk":"11450214482","pt":1717319243276,"mc":[{"id":"1.229554905","rc":[{"atl":[[21,5.75]],"id":61631980},{"atb":[[1.24,95.36]],"id":60780007}],"con":true,"img":false}]}
{"op":"mcm","clk":"11450214497","pt":1717319243372,"mc":[{"id":"1.229554905","rc":[{"atb":[[1.1,0.06]],"id":57451148}],"con":true,"img":false}]}
{"op":"mcm","clk":"11450214530","pt":1717319243583,"mc":[{"id":"1.229554905","rc":[{"atb":[[1.04,0]],"id":61631978}],"con":true,"img":false}]}
{"op":"mcm","clk":"11450214541","pt":1717319243656,"mc":[{"id":"1.229554905","rc":[{"atb":[[5,0.17]],"id":61631978}],"con":true,"img":false}]}
{"op":"mcm","clk":"11450214576","pt":1717319243972,"mc":[{"id":"1.229554905","rc":[{"atl":[[1000,2.7]],"id":60780007}],"con":true,"img":false}]}
{"op":"mcm","clk":"11450214586","pt":1717319244062,"mc":[{"id":"1.229554905","rc":[{"atb":[[1.03,1.7]],"id":60780007}],"con":true,"img":false}]}
{"op":"mcm","clk":"11450214605","pt":1717319244274,"mc":[{"id":"1.229554905","rc":[{"atl":[[1000,1.05]],"id":61631980}],"con":true,"img":false}]}
{"op":"mcm","clk":"11450214619","pt":1717319244374,"mc":[{"id":"1.229554905","rc":[{"atl":[[1000,1.01]],"id":57451148}],"con":true,"img":false}]}
{"op":"mcm","clk":"11450214644","pt":1717319244532,"mc":[{"id":"1.229554905","rc":[{"atl":[[1000,3.52]],"id":61631978}],"con":true,"img":false}]}
{"op":"mcm","clk":"11450214663","pt":1717319244793,"mc":[{"id":"1.229554905","rc":[{"atl":[[1000,2.15]],"id":61631978}],"con":true,"img":false}]}
{"op":"mcm","clk":"11450214694","pt":1717319245054,"mc":[{"id":"1.229554905","rc":[{"atb":[[1.1,0]],"id":57451148},{"atl":[[1000,1.17]],"id":61631978}],"con":true,"img":false}]}
{"op":"mcm","clk":"11450214703","pt":1717319245158,"mc":[{"id":"1.229554905","rc":[{"atb":[[13,0.06]],"id":57451148},{"atl":[[13.5,0.98]],"id":61631978}],"con":true,"img":false}]}
{"op":"mcm","clk":"11450214753","pt":1717319245681,"mc":[{"id":"1.229554905","rc":[{"atl":[[14,0]],"id":61631978}],"con":true,"img":false}]}
{"op":"mcm","clk":"11450214766","pt":1717319245838,"mc":[{"id":"1.229554905","rc":[{"atb":[[1.8,0]],"id":42269942}],"con":true,"img":false}]}
{"op":"mcm","clk":"11450214774","pt":1717319245940,"mc":[{"id":"1.229554905","rc":[{"atb":[[1.05,0.15]],"id":61631980}],"con":true,"img":false}]}
{"op":"mcm","clk":"11450214807","pt":1717319246254,"mc":[{"id":"1.229554905","rc":[{"atl":[[1000,1]],"id":61631980}],"con":true,"img":false}]}
{"op":"mcm","clk":"11450214823","pt":1717319246356,"mc":[{"id":"1.229554905","rc":[{"atl":[[17,0.05]],"id":61631980}],"con":true,"img":false}]}
{"op":"mcm","clk":"11450214935","pt":1717319247237,"mc":[{"id":"1.229554905","rc":[{"atl":[[1000,1.45]],"id":60780007}],"con":true,"img":false}]}
{"op":"mcm","clk":"11450214946","pt":1717319247341,"mc":[{"id":"1.229554905","rc":[{"atb":[[1.03,0.64]],"id":60780007}],"con":true,"img":false}]}
{"op":"mcm","clk":"11450214978","pt":1717319247651,"mc":[{"id":"1.229554905","rc":[{"atl":[[1000,1]],"id":57451148}],"con":true,"img":false}]}
{"op":"mcm","clk":"11450214990","pt":1717319247755,"mc":[{"id":"1.229554905","rc":[{"atl":[[48,0.19]],"id":57451148}],"con":true,"img":false}]}
{"op":"mcm","clk":"11450215066","pt":1717319248593,"mc":[{"id":"1.229554905","rc":[{"atb":[[1.8,0]],"id":42269942}],"con":true,"img":false}]}
{"op":"mcm","clk":"11450215077","pt":1717319248647,"mc":[{"id":"1.229554905","rc":[{"atb":[[80,0.43]],"id":42269942}],"con":true,"img":false}]}
{"op":"mcm","clk":"11450215127","pt":1717319249067,"mc":[{"id":"1.229554905","rc":[{"atb":[[1.05,0]],"id":61631980}],"con":true,"img":false}]}
{"op":"mcm","clk":"11450215140","pt":1717319249172,"mc":[{"id":"1.229554905","rc":[{"atb":[[5.7,0.15]],"id":61631980}],"con":true,"img":false}]}
{"op":"mcm","clk":"11450215198","pt":1717319249799,"mc":[{"id":"1.229554905","rc":[{"atl":[[1000,2.87]],"id":61631978}],"con":true,"img":false}]}
{"op":"mcm","clk":"11450215227","pt":1717319250063,"mc":[{"id":"1.229554905","rc":[{"atl":[[1000,1]],"id":60780007}],"con":true,"img":false}]}
{"op":"mcm","clk":"11450215238","pt":1717319250163,"mc":[{"id":"1.229554905","rc":[{"atl":[[1.9,0.45]],"id":60780007}],"con":true,"img":false}]}
{"op":"mcm","clk":"11450215308","pt":1717319250786,"mc":[{"id":"1.229554905","rc":[{"atb":[[1.03,0]],"id":60780007}],"con":true,"img":false}]}
{"op":"mcm","clk":"11450215318","pt":1717319250844,"mc":[{"id":"1.229554905","rc":[{"atb":[[1.32,0.64]],"id":60780007}],"con":true,"img":false}]}
{"op":"mcm","clk":"11450215491","pt":1717319252357,"mc":[{"id":"1.229554905","rc":[{"atl":[[1000,1.23]],"id":61631978}],"con":true,"img":false}]}
{"op":"mcm","clk":"11450215591","pt":1717319253183,"mc":[{"id":"1.229554905","rc":[{"atb":[[3.85,0]],"id":61631980},{"atb":[[3.45,0]],"id":61631978}],"con":true,"img":false}]}
{"op":"mcm","clk":"11450215606","pt":1717319253286,"mc":[{"id":"1.229554905","rc":[{"atb":[[4.4,40.8]],"id":61631980},{"atb":[[3.95,41.18]],"id":61631978}],"con":true,"img":false}]}
{"op":"mcm","clk":"11450215851","pt":1717319255574,"mc":[{"id":"1.229554905","rc":[{"atl":[[1000,1.17]],"id":61631978}],"con":true,"img":false}]}
{"op":"mcm","clk":"11450215866","pt":1717319255672,"mc":[{"id":"1.229554905","rc":[{"atl":[[14,0.05]],"id":61631978}],"con":true,"img":false}]}
{"op":"mcm","clk":"11450216164","pt":1717319258670,"mc":[{"id":"1.229554905","rc":[{"atb":[[2.5,66.67],[2.74,0]],"id":61631980}],"con":true,"img":false}]}
{"op":"mcm","clk":"11450216200","pt":1717319258975,"mc":[{"id":"1.229554905","rc":[{"atb":[[2.5,0],[2.74,57.47]],"id":61631980}],"con":true,"img":false}]}
{"op":"mcm","clk":"11450216338","pt":1717319260382,"mc":[{"id":"1.229554905","rc":[{"atl":[[960,2.85]],"id":42269942},{"spn":295.0,"spf":"NaN","id":42269942},{"spn":30.5,"spf":"NaN","id":57451148},{"spn":1.61,"spf":"NaN","id":60780007},{"spn":9.25,"spf":"NaN","id":61631978}],"con":true,"img":false}]}
{"op":"mcm","clk":"11450218613","pt":1717319283114,"mc":[{"id":"1.229554905","rc":[{"atl":[[2.1,0]],"id":60780007}],"con":true,"img":false}]}
{"op":"mcm","clk":"11450219185","pt":1717319288817,"mc":[{"id":"1.229554905","rc":[{"atl":[[2.28,5.78]],"id":60780007}],"con":true,"img":false}]}
{"op":"mcm","clk":"11450224222","pt":1717319342301,"mc":[{"id":"1.229554905","rc":[{"atl":[[1.9,3]],"id":60780007}],"con":true,"img":false}]}
{"op":"mcm","clk":"11450224244","pt":1717319342507,"mc":[{"id":"1.229554905","rc":[{"atl":[[2.28,7.03]],"id":60780007}],"con":true,"img":false}]}
{"op":"mcm","clk":"11450224255","pt":1717319342609,"mc":[{"id":"1.229554905","rc":[{"atb":[[80,0.33]],"id":42269942},{"atl":[[48,0.01]],"id":57451148},{"atb":[[5.6,2]],"id":61631980},{"atb":[[4.9,2]],"id":61631978}],"con":true,"img":false}]}
{"op":"mcm","clk":"11450226550","pt":1717319367573,"mc":[{"id":"1.229554905","rc":[{"atb":[[5.7,0]],"id":61631980}],"con":true,"img":false}]}
{"op":"mcm","clk":"11450226556","pt":1717319367678,"mc":[{"id":"1.229554905","rc":[{"atb":[[4.3,31.65]],"id":61631980}],"con":true,"img":false}]}
{"op":"mcm","clk":"11450226568","pt":1717319367782,"mc":[{"id":"1.229554905","rc":[{"atl":[[17,0]],"id":61631980}],"con":true,"img":false}]}
{"op":"mcm","clk":"11450226618","pt":1717319368354,"mc":[{"id":"1.229554905","rc":[{"atb":[[13,0]],"id":57451148}],"con":true,"img":false}]}
{"op":"mcm","clk":"11450226637","pt":1717319368558,"mc":[{"id":"1.229554905","rc":[{"atl":[[48,0]],"id":57451148}],"con":true,"img":false}]}
{"op":"mcm","clk":"11450226653","pt":1717319368767,"mc":[{"id":"1.229554905","rc":[{"atb":[[5,0]],"id":61631978}],"con":true,"img":false}]}
{"op":"mcm","clk":"11450226665","pt":1717319368877,"mc":[{"id":"1.229554905","rc":[{"atb":[[4.3,34.75]],"id":61631980},{"atl":[[1.9,2.55]],"id":60780007},{"atb":[[3.9,36.02]],"id":61631978}],"con":true,"img":false}]}
{"op":"mcm","clk":"11450226682","pt":1717319369075,"mc":[{"id":"1.229554905","rc":[{"atb":[[80,0.32]],"id":42269942}],"con":true,"img":false}]}
{"op":"mcm","clk":"11450226694","pt":1717319369182,"mc":[{"id":"1.229554905","rc":[{"atl":[[1000,2.7]],"id":61631980}],"con":true,"img":false}]}
{"op":"mcm","clk":"11450226720","pt":1717319369436,"mc":[{"id":"1.229554905","rc":[{"atb":[[1.1,1.7]],"id":57451148}],"con":true,"img":false}]}
{"op":"mcm","clk":"11450226735","pt":1717319369542,"mc":[{"id":"1.229554905","rc":[{"atb":[[1.05,1.7]],"id":61631980}],"con":true,"img":false}]}
{"op":"mcm","clk":"11450226758","pt":1717319369753,"mc":[{"id":"1.229554905","rc":[{"atl":[[1000,2.7]],"id":57451148},{"atb":[[1.32,0]],"id":60780007}],"con":true,"img":false}]}
{"op":"mcm","clk":"11450226788","pt":1717319370069,"mc":[{"id":"1.229554905","rc":[{"atb":[[1.04,1.7]],"id":61631978}],"con":true,"img":false}]}
{"op":"mcm","clk":"11450226822","pt":1717319370333,"mc":[{"id":"1.229554905","rc":[{"atl":[[1000,1.05]],"id":61631980}],"con":true,"img":false}]}
{"op":"mcm","clk":"11450226835","pt":1717319370536,"mc":[{"id":"1.229554905","rc":[{"atl":[[2.1,9.18]],"id":60780007}],"con":true,"img":false}]}
{"op":"mcm","clk":"11450226846","pt":1717319370639,"mc":[{"id":"1.229554905","rc":[{"atb":[[1.8,1.7]],"id":42269942}],"con":true,"img":false}]}
{"op":"mcm","clk":"11450226874","pt":1717319370955,"mc":[{"id":"1.229554905","rc":[{"atl":[[1000,2.7]],"id":60780007}],"con":true,"img":false}]}
{"op":"mcm","clk":"11450226893","pt":1717319371162,"mc":[{"id":"1.229554905","rc":[{"atb":[[1.1,0.06]],"id":57451148}],"con":true,"img":false}]}
{"op":"mcm","clk":"11450226900","pt":1717319371268,"mc":[{"id":"1.229554905","rc":[{"atl":[[1000,1.01]],"id":57451148}],"con":true,"img":false}]}
{"op":"mcm","clk":"11450226918","pt":1717319371480,"mc":[{"id":"1.229554905","rc":[{"atb":[[1.05,0.15]],"id":61631980}],"con":true,"img":false}]}
{"op":"mcm","clk":"11450226953","pt":1717319371580,"mc":[{"id":"1.229554905","rc":[{"atl":[[1000,1]],"id":61631980}],"con":true,"img":false}]}
{"op":"mcm","clk":"11450226964","pt":1717319371631,"mc":[{"id":"1.229554905","rc":[{"atl":[[17,0.05]],"id":61631980}],"con":true,"img":false}]}
{"op":"mcm","clk":"11450226980","pt":1717319371838,"mc":[{"id":"1.229554905","rc":[{"atb":[[1.03,1.7]],"id":60780007}],"con":true,"img":false}]}
{"op":"mcm","clk":"11450227028","pt":1717319372458,"mc":[{"id":"1.229554905","rc":[{"atb":[[1.1,0]],"id":57451148}],"con":true,"img":false}]}
{"op":"mcm","clk":"11450227038","pt":1717319372560,"mc":[{"id":"1.229554905","rc":[{"atb":[[13,0.06]],"id":57451148}],"con":true,"img":false}]}
{"op":"mcm","clk":"11450227050","pt":1717319372673,"mc":[{"id":"1.229554905","rc":[{"atb":[[1.04,0.17]],"id":61631978}],"con":true,"img":false}]}
{"op":"mcm","clk":"11450227084","pt":1717319373082,"mc":[{"id":"1.229554905","rc":[{"atl":[[14,0]],"id":61631978}],"con":true,"img":false}]}
{"op":"mcm","clk":"11450227096","pt":1717319373288,"mc":[{"id":"1.229554905","rc":[{"atl":[[960,0.85]],"id":42269942}],"con":true,"img":false}]}
{"op":"mcm","clk":"11450227124","pt":1717319373551,"mc":[{"id":"1.229554905","rc":[{"atb":[[1.8,0]],"id":42269942},{"atl":[[1000,1.45]],"id":60780007}],"con":true,"img":false}]}
{"op":"mcm","clk":"11450227156","pt":1717319373856,"mc":[{"id":"1.229554905","rc":[{"atl":[[1000,1]],"id":57451148}],"con":true,"img":false}]}
{"op":"mcm","clk":"11450227162","pt":1717319373958,"mc":[{"id":"1.229554905","rc":[{"atl":[[48,0.01]],"id":57451148}],"con":true,"img":false}]}
{"op":"mcm","clk":"11450227205","pt":1717319374371,"mc":[{"id":"1.229554905","rc":[{"atl":[[1.91,0]],"id":60780007}],"con":true,"img":false}]}
{"op":"mcm","clk":"11450227214","pt":1717319374476,"mc":[{"id":"1.229554905","rc":[{"atb":[[1.05,0]],"id":61631980}],"con":true,"img":false}]}
{"op":"mcm","clk":"11450227224","pt":1717319374581,"mc":[{"id":"1.229554905","rc":[{"atb":[[5.7,0.15]],"id":61631980}],"con":true,"img":false}]}
{"op":"mcm","clk":"11450227246","pt":1717319374886,"mc":[{"id":"1.229554905","rc":[{"atb":[[1.03,0.64]],"id":60780007}],"con":true,"img":false}]}
{"op":"mcm","clk":"11450227268","pt":1717319375149,"mc":[{"id":"1.229554905","rc":[{"atb":[[1.04,0]],"id":61631978}],"con":true,"img":false}]}
{"op":"mcm","clk":"11450227278","pt":1717319375295,"mc":[{"id":"1.229554905","rc":[{"atb":[[5,0.17]],"id":61631978}],"con":true,"img":false}]}
{"op":"mcm","clk":"11450227305","pt":1717319375561,"mc":[{"id":"1.229554905","rc":[{"atl":[[1000,2.87]],"id":61631978}],"con":true,"img":false}]}
{"op":"mcm","clk":"11450227317","pt":1717319375769,"mc":[{"id":"1.229554905","rc":[{"atl":[[1000,1]],"id":60780007}],"con":true,"img":false}]}
{"op":"mcm","clk":"11450227326","pt":1717319375880,"mc":[{"id":"1.229554905","rc":[{"atl":[[1.89,0.45]],"id":60780007}],"con":true,"img":false}]}
{"op":"mcm","clk":"11450227346","pt":1717319376184,"mc":[{"id":"1.229554905","rc":[{"atb":[[1.8,0]],"id":42269942}],"con":true,"img":false}]}
{"op":"mcm","clk":"11450227354","pt":1717319376292,"mc":[{"id":"1.229554905","rc":[{"atb":[[80,0.33]],"id":42269942}],"con":true,"img":false}]}
{"op":"mcm","clk":"11450227374","pt":1717319376551,"mc":[{"id":"1.229554905","rc":[{"atb":[[1.03,0]],"id":60780007}],"con":true,"img":false}]}
{"op":"mcm","clk":"11450227386","pt":1717319376651,"mc":[{"id":"1.229554905","rc":[{"atb":[[1.32,0.64]],"id":60780007}],"con":true,"img":false}]}
{"op":"mcm","clk":"11450227440","pt":1717319377372,"mc":[{"id":"1.229554905","rc":[{"atl":[[1000,1.23]],"id":61631978}],"con":true,"img":false}]}
{"op":"mcm","clk":"11450227465","pt":1717319377683,"mc":[{"id":"1.229554905","rc":[{"atl":[[1000,1.17]],"id":61631978}],"con":true,"img":false}]}
{"op":"mcm","clk":"11450227475","pt":1717319377790,"mc":[{"id":"1.229554905","rc":[{"atl":[[14,0.05]],"id":61631978}],"con":true,"img":false}]}
{"op":"mcm","clk":"11450227710","pt":1717319380806,"mc":[{"id":"1.229554905","rc":[{"atl":[[1.89,3.45]],"id":60780007}],"con":true,"img":false}]}
{"op":"mcm","clk":"11450227848","pt":1717319382361,"mc":[{"id":"1.229554905","rc":[{"atl":[[1.9,0]],"id":60780007}],"con":true,"img":false}]}
{"op":"mcm","clk":"11450227956","pt":1717319383461,"mc":[{"id":"1.229554905","rc":[{"atb":[[1.01,1]],"id":61631980}],"con":true,"img":false}]}
{"op":"mcm","clk":"11450228045","pt":1717319384395,"mc":[{"id":"1.229554905","rc":[{"atl":[[1.89,0.45]],"id":60780007}],"con":true,"img":false}]}
{"op":"mcm","clk":"11450228097","pt":1717319385076,"mc":[{"id":"1.229554905","rc":[{"atl":[[1.88,2.55]],"id":60780007}],"con":true,"img":false}]}
{"op":"mcm","clk":"11450228332","pt":1717319387883,"mc":[{"id":"1.229554905","rc":[{"atl":[[1.87,3]],"id":60780007}],"con":true,"img":false}]}
{"op":"mcm","clk":"11450228405","pt":1717319388612,"mc":[{"id":"1.229554905","rc":[{"atb":[[40,0],[50,0],[30,0]],"id":42269942},{"atl":[[610,0],[510,0]],"id":42269942},{"atb":[[11.5,0],[9.6,0],[8.6,0]],"id":57451148},{"atl":[[300,0],[200,0]],"id":57451148},{"atb":[[4.3,3.1],[3.9,0],[3.65,0]],"id":61631980},{"atl":[[34,0],[22,0]],"id":61631980},{"atb":[[1.18,689.36],[1.23,0],[1.13,0]],"id":60780007},{"atl":[[2.64,0],[2.84,0]],"id":60780007},{"atb":[[3.4,0],[3.9,0],[3.65,0]],"id":61631978},{"atl":[[19,0],[28,0]],"id":61631978}],"con":true,"img":false}]}
{"op":"mcm","clk":"11450228553","pt":1717319390386,"mc":[{"id":"1.229554905","rc":[{"atl":[[1.88,0]],"id":60780007}],"con":true,"img":false}]}
{"op":"mcm","clk":"11450228635","pt":1717319391478,"mc":[{"id":"1.229554905","rc":[{"atl":[[1.87,0]],"id":60780007}],"con":true,"img":false}]}
{"op":"mcm","clk":"11450228796","pt":1717319393097,"mc":[{"id":"1.229554905","rc":[{"atb":[[4.4,0]],"id":61631980},{"atl":[[21,0]],"id":61631980},{"atb":[[1.24,0]],"id":60780007},{"atl":[[1.9,2.55]],"id":60780007},{"atb":[[3.95,0]],"id":61631978}],"con":true,"img":false}]}
{"op":"mcm","clk":"11450228803","pt":1717319393200,"mc":[{"id":"1.229554905","rc":[{"atb":[[3.85,40.8]],"id":61631980},{"atl":[[24,5.75]],"id":61631980},{"atb":[[1.19,95.36]],"id":60780007},{"atb":[[3.45,41.18]],"id":61631978}],"con":true,"img":false}]}
{"op":"mcm","clk":"11450228974","pt":1717319395009,"mc":[{"id":"1.229554905","rc":[{"atl":[[1.89,3.45]],"id":60780007}],"con":true,"img":false}]}
{"op":"mcm","clk":"11450229186","pt":1717319397284,"mc":[{"id":"1.229554905","rc":[{"atl":[[1.9,0]],"id":60780007}],"con":true,"img":false}]}
{"op":"mcm","clk":"11450229308","pt":1717319398687,"mc":[{"id":"1.229554905","rc":[{"atl":[[1.89,0.45]],"id":60780007}],"con":true,"img":false}]}
{"op":"mcm","clk":"11450229405","pt":1717319399877,"mc":[{"id":"1.229554905","rc":[{"atl":[[1.88,2.55]],"id":60780007}],"con":true,"img":false}]}
{"op":"mcm","clk":"11450229454","pt":1717319400611,"mc":[{"id":"1.229554905","rc":[{"atb":[[1.25,0]],"id":60780007}],"con":true,"img":false}]}
{"op":"mcm","clk":"11450229486","pt":1717319401024,"mc":[{"id":"1.229554905","rc":[{"atb":[[1.08,1.7]],"id":61631978}],"con":true,"img":false}]}
{"op":"mcm","clk":"11450229503","pt":1717319401233,"mc":[{"id":"1.229554905","rc":[{"atb":[[1.09,1.7]],"id":61631980},{"atl":[[1000,2.7]],"id":60780007}],"con":true,"img":false}]}
{"op":"mcm","clk":"11450229519","pt":1717319401396,"mc":[{"id":"1.229554905","rc":[{"atb":[[1.2,1.7]],"id":57451148}],"con":true,"img":false}]}
{"op":"mcm","clk":"11450229531","pt":1717319401499,"mc":[{"id":"1.229554905","rc":[{"atl":[[1000,2.7]],"id":57451148}],"con":true,"img":false}]}
{"op":"mcm","clk":"11450229541","pt":1717319401601,"mc":[{"id":"1.229554905","rc":[{"atb":[[1.02,161.7]],"id":57451148},{"atb":[[3.9,3.57]],"id":61631978}],"con":true,"img":false}]}
{"op":"mcm","clk":"11450229577","pt":1717319402019,"mc":[{"id":"1.229554905","rc":[{"atb":[[1.03,1.7]],"id":60780007}],"con":true,"img":false}]}
{"op":"mcm","clk":"11450229605","pt":1717319402328,"mc":[{"id":"1.229554905","rc":[{"atb":[[1.8,1.7]],"id":42269942},{"spn":520.0,"spf":"NaN","id":42269942},{"atl":[[1.87,3]],"id":60780007},{"spn":1.59,"spf":"NaN","id":60780007}],"con":true,"img":false}]}
{"op":"mcm","clk":"11450229659","pt":1717319402803,"mc":[{"id":"1.229554905","rc":[{"atb":[[1.02,159.74]],"id":57451148}],"con":true,"img":false}]}
{"op":"mcm","clk":"11450229725","pt":1717319403428,"mc":[{"id":"1.229554905","rc":[{"atl":[[1000,1.23]],"id":60780007}],"con":true,"img":false}]}
{"op":"mcm","clk":"11450229737","pt":1717319403534,"mc":[{"id":"1.229554905","rc":[{"atb":[[80,0.72]],"id":42269942}],"con":true,"img":false}]}
{"op":"mcm","clk":"11450229803","pt":1717319404016,"mc":[{"id":"1.229554905","rc":[{"atl":[[1.88,0]],"id":60780007}],"con":true,"img":false}]}
{"op":"mcm","clk":"11450229861","pt":1717319404526,"mc":[{"id":"1.229554905","rc":[{"atb":[[1.09,0.07]],"id":61631980}],"con":true,"img":false}]}
{"op":"mcm","clk":"11450229905","pt":1717319405040,"mc":[{"id":"1.229554905","rc":[{"atb":[[1.02,159.35]],"id":57451148}],"con":true,"img":false}]}
{"op":"mcm","clk":"11450229914","pt":1717319405104,"mc":[{"id":"1.229554905","rc":[{"atb":[[12.5,2.43]],"id":57451148}],"con":true,"img":false}]}
{"op":"mcm","clk":"11450229925","pt":1717319405208,"mc":[{"id":"1.229554905","rc":[{"atl":[[1000,1]],"id":57451148},{"atb":[[1.03,0.32]],"id":60780007}],"con":true,"img":false}]}
{"op":"mcm","clk":"11450229971","pt":1717319405818,"mc":[{"id":"1.229554905","rc":[{"atl":[[1.87,0],[1000,1]],"id":60780007}],"con":true,"img":false}]}
{"op":"mcm","clk":"11450229978","pt":1717319405920,"mc":[{"id":"1.229554905","rc":[{"atl":[[1.87,0.23]],"id":60780007}],"con":true,"img":false}]}
{"op":"mcm","clk":"11450229996","pt":1717319406124,"mc":[{"id":"1.229554905","rc":[{"atb":[[1.8,0]],"id":42269942}],"con":true,"img":false}]}
{"op":"mcm","clk":"11450230017","pt":1717319406432,"mc":[{"id":"1.229554905","rc":[{"atb":[[1.08,0.08]],"id":61631978}],"con":true,"img":false}]}
{"op":"mcm","clk":"11450230026","pt":1717319406543,"mc":[{"id":"1.229554905","rc":[{"atb":[[1.2,0.03]],"id":57451148}],"con":true,"img":false}]}
{"op":"mcm","clk":"11450230118","pt":1717319407521,"mc":[{"id":"1.229554905","rc":[{"atb":[[1.02,2.35]],"id":61631978}],"con":true,"img":false}]}
{"op":"mcm","clk":"11450230182","pt":1717319408201,"mc":[{"id":"1.229554905","rc":[{"atb":[[1.09,0]],"id":61631980},{"atl":[[1.9,2.55]],"id":60780007}],"con":true,"img":false}]}
{"op":"mcm","clk":"11450230191","pt":1717319408314,"mc":[{"id":"1.229554905","rc":[{"atb":[[1.02,0.39]],"id":61631978}],"con":true,"img":false}]}
{"op":"mcm","clk":"11450230296","pt":1717319409440,"mc":[{"id":"1.229554905","rc":[{"atl":[[1.88,3]],"id":60780007}],"con":true,"img":false}]}
{"op":"mcm","clk":"11450230314","pt":1717319409646,"mc":[{"id":"1.229554905","rc":[{"atb":[[1.02,0]],"id":61631978}],"con":true,"img":false}]}
{"op":"mcm","clk":"11450230320","pt":1717319409707,"mc":[{"id":"1.229554905","rc":[{"atb":[[1.03,0]],"id":60780007},{"atb":[[4.2,0.39]],"id":61631978}],"con":true,"img":false}]}
{"op":"mcm","clk":"11450230331","pt":1717319409809,"mc":[{"id":"1.229554905","rc":[{"atb":[[1.32,0.97]],"id":60780007}],"con":true,"img":false}]}
{"op":"mcm","clk":"11450230349","pt":1717319410014,"mc":[{"id":"1.229554905","rc":[{"atb":[[40,7.29],[50,2.9],[30,9.81]],"id":42269942},{"atl":[[610,0.15],[510,0.12]],"id":42269942},{"atb":[[11.5,9.95],[9.6,24.29],[8.6,27.48]],"id":57451148},{"atl":[[300,0.7],[200,0.7]],"id":57451148},{"atb":[[4.3,34.75],[3.9,72.04],[3.65,78.83]],"id":61631980},{"atl":[[34,6.34],[22,6.64]],"id":61631980},{"atb":[[1.18,1849.98],[1.23,454.15],[1.13,1607.02]],"id":60780007},{"atl":[[2.64,85.07],[2.84,113.74]],"id":60780007},{"atb":[[3.4,87.04],[3.9,39.59],[3.65,78.83]],"id":61631978},{"atl":[[19,7.75],[28,7.75]],"id":61631978}],"con":true,"img":false}]}
{"op":"mcm","clk":"11450230358","pt":1717319410122,"mc":[{"id":"1.229554905","rc":[{"atl":[[1000,1]],"id":57451148}],"con":true,"img":false}]}
{"op":"mcm","clk":"11450230365","pt":1717319410226,"mc":[{"id":"1.229554905","rc":[{"atl":[[48,0.02]],"id":57451148}],"con":true,"img":false}]}
{"op":"mcm","clk":"11450230457","pt":1717319411118,"mc":[{"id":"1.229554905","rc":[{"atl":[[1.9,0]],"id":60780007}],"con":true,"img":false}]}
{"op":"mcm","clk":"11450230468","pt":1717319411219,"mc":[{"id":"1.229554905","rc":[{"atb":[[1.8,0]],"id":42269942}],"con":true,"img":false}]}
{"op":"mcm","clk":"11450230480","pt":1717319411329,"mc":[{"id":"1.229554905","rc":[{"atb":[[80,0.73]],"id":42269942}],"con":true,"img":false}]}
{"op":"mcm","clk":"11450230543","pt":1717319411950,"mc":[{"id":"1.229554905","rc":[{"atb":[[1.08,0]],"id":61631978}],"con":true,"img":false}]}
{"op":"mcm","clk":"11450230552","pt":1717319412055,"mc":[{"id":"1.229554905","rc":[{"atb":[[5,0.25]],"id":61631978}],"con":true,"img":false}]}
{"op":"mcm","clk":"11450230600","pt":1717319412543,"mc":[{"id":"1.229554905","rc":[{"atb":[[1.2,0]],"id":57451148}],"con":true,"img":false}]}
{"op":"mcm","clk":"11450230610","pt":1717319412628,"mc":[{"id":"1.229554905","rc":[{"atb":[[13,0.1]],"id":57451148},{"atl":[[1.87,2.78]],"id":60780007}],"con":true,"img":false}]}
{"op":"mcm","clk":"11450230705","pt":1717319413824,"mc":[{"id":"1.229554905","rc":[{"atb":[[1.17,100]],"id":42269942},{"atb":[[1.17,100]],"id":57451148},{"atb":[[1.17,100]],"id":61631980},{"atb":[[1.17,100]],"id":61631978}],"con":true,"img":false}]}
{"op":"mcm","clk":"11450230846","pt":1717319415644,"mc":[{"id":"1.229554905","rc":[{"atb":[[1.24,32.71]],"id":60780007}],"con":true,"img":false}]}
{"op":"mcm","clk":"11450231317","pt":1717319421257,"mc":[{"id":"1.229554905","rc":[{"atl":[[1000,2.87]],"id":61631978}],"con":true,"img":false}]}
{"op":"mcm","clk":"11450231352","pt":1717319421652,"mc":[{"id":"1.229554905","rc":[{"atb":[[1.09,1.7]],"id":61631980}],"con":true,"img":false}]}
{"op":"mcm","clk":"11450231896","pt":1717319426631,"mc":[{"id":"1.229554905","rc":[{"atl":[[1000,1.2]],"id":61631978}],"con":true,"img":false}]}
{"op":"mcm","clk":"11450231925","pt":1717319426943,"mc":[{"id":"1.229554905","rc":[{"atb":[[1.09,0.07]],"id":61631980}],"con":true,"img":false}]}
{"op":"mcm","clk":"11450232115","pt":1717319429158,"mc":[{"id":"1.229554905","rc":[{"atl":[[1000,1.17]],"id":61631978}],"con":true,"img":false}]}
{"op":"mcm","clk":"11450232122","pt":1717319429261,"mc":[{"id":"1.229554905","rc":[{"atl":[[13,0.03]],"id":61631978}],"con":true,"img":false}]}
{"op":"mcm","clk":"11450232262","pt":1717319430664,"mc":[{"id":"1.229554905","rc":[{"atl":[[13.5,0]],"id":61631978}],"con":true,"img":false}]}
{"op":"mcm","clk":"11450232316","pt":1717319431134,"mc":[{"id":"1.229554905","rc":[{"atb":[[1.09,0]],"id":61631980}],"con":true,"img":false}]}
{"op":"mcm","clk":"11450232327","pt":1717319431283,"mc":[{"id":"1.229554905","rc":[{"atb":[[5.7,0.23]],"id":61631980}],"con":true,"img":false}]}
{"op":"mcm","clk":"11450232863","pt":1717319436442,"mc":[{"id":"1.229554905","rc":[{"atb":[[2.5,66.67],[2.74,0]],"id":61631980},{"atl":[[11.5,1.9],[12.5,4.35],[13.5,6],[14.5,9.26]],"id":61631980}],"con":true,"img":false}]}
{"op":"mcm","clk":"11450232939","pt":1717319437276,"mc":[{"id":"1.229554905","rc":[{"atb":[[2.5,0],[2.74,57.47]],"id":61631980}],"con":true,"img":false}]}
{"op":"mcm","clk":"11450233079","pt":1717319438776,"mc":[{"id":"1.229554905","rc":[{"atb":[[2.5,66.67],[2.74,0]],"id":61631980}],"con":true,"img":false}]}
{"op":"mcm","clk":"11450233495","pt":1717319442988,"mc":[{"id":"1.229554905","rc":[{"atl":[[1000,2.7]],"id":61631980}],"con":true,"img":false}]}
{"op":"mcm","clk":"11450233512","pt":1717319443149,"mc":[{"id":"1.229554905","rc":[{"atb":[[75,0]],"id":42269942},{"atb":[[1.19,0]],"id":60780007}],"con":true,"img":false}]}
{"op":"mcm","clk":"11450233526","pt":1717319443254,"mc":[{"id":"1.229554905","rc":[{"atb":[[85,2.61]],"id":42269942},{"atb":[[1.24,128.07]],"id":60780007}],"con":true,"img":false}]}
{"op":"mcm","clk":"11450233614","pt":1717319444078,"mc":[{"id":"1.229554905","rc":[{"atb":[[80,0.4]],"id":42269942}],"con":true,"img":false}]}
{"op":"mcm","clk":"11450233629","pt":1717319444280,"mc":[{"id":"1.229554905","rc":[{"atb":[[90,0.28]],"id":42269942}],"con":true,"img":false}]}
{"op":"mcm","clk":"11450233746","pt":1717319445481,"mc":[{"id":"1.229554905","rc":[{"atb":[[2.5,0],[2.74,57.47]],"id":61631980}],"con":true,"img":false}]}
{"op":"mcm","clk":"11450233877","pt":1717319446888,"mc":[{"id":"1.229554905","rc":[{"atb":[[10.5,10.53],[44,0]],"id":42269942},{"atb":[[4.2,24.39]],"id":57451148},{"atb":[[1.21,238.1],[1.19,250],[1.23,541.11],[1.17,293.84]],"id":60780007},{"atl":[[7.8,14.71]],"id":60780007},{"atb":[[1.26,88.75]],"id":61631978}],"con":true,"img":false}]}
{"op":"mcm","clk":"11450233887","pt":1717319446992,"mc":[{"id":"1.229554905","rc":[{"atb":[[1.53,0]],"id":57451148},{"atl":[[11.5,0],[12.5,0],[13.5,0],[14.5,0]],"id":61631980},{"atl":[[4.3,0]],"id":60780007},{"atb":[[2.24,0]],"id":61631978},{"atl":[[9.2,2.44],[10,8.33],[11,12.5],[9.6,5.81]],"id":61631978}],"con":true,"img":false}]}
{"op":"mcm","clk":"11450233902","pt":1717319447160,"mc":[{"id":"1.229554905","rc":[{"atb":[[1.17,250]],"id":60780007},{"atb":[[3.9,36.02]],"id":61631978}],"con":true,"img":false}]}
{"op":"mcm","clk":"11450233916","pt":1717319447367,"mc":[{"id":"1.229554905","rc":[{"atl":[[1000,1.04]],"id":61631980}],"con":true,"img":false}]}
{"op":"mcm","clk":"11450233992","pt":1717319448255,"mc":[{"id":"1.229554905","rc":[{"atl":[[1000,1]],"id":61631980},{"atb":[[3.9,39.59]],"id":61631978}],"con":true,"img":false}]}
{"op":"mcm","clk":"11450234001","pt":1717319448359,"mc":[{"id":"1.229554905","rc":[{"atl":[[11,0.04]],"id":61631980}],"con":true,"img":false}]}
{"op":"mcm","clk":"11450234474","pt":1717319453182,"mc":[{"id":"1.229554905","rc":[{"atl":[[24,0]],"id":61631980}],"con":true,"img":false}]}
{"op":"mcm","clk":"11450234484","pt":1717319453297,"mc":[{"id":"1.229554905","rc":[{"atl":[[21,5.75]],"id":61631980}],"con":true,"img":false}]}
{"op":"mcm","clk":"11450234666","pt":1717319455092,"mc":[{"id":"1.229554905","rc":[{"atb":[[2.5,66.67],[2.74,0]],"id":61631980},{"atl":[[19.5,1.08],[21,8.25],[23,3.41],[25,5.21]],"id":61631980}],"con":true,"img":false}]}
{"op":"mcm","clk":"11450235438","pt":1717319463098,"mc":[{"id":"1.229554905","rc":[{"spn":300.0,"spf":"NaN","id":42269942},{"atb":[[3.85,0]],"id":61631980},{"spn":8.35,"spf":"NaN","id":61631980},{"atb":[[3.45,0]],"id":61631978},{"spn":7.1,"spf":"NaN","id":61631978}],"con":true,"img":false}]}
{"op":"mcm","clk":"11450235444","pt":1717319463200,"mc":[{"id":"1.229554905","rc":[{"atb":[[4.4,40.8]],"id":61631980},{"atb":[[3.95,41.18]],"id":61631978}],"con":true,"img":false}]}
{"op":"mcm","clk":"11450236229","pt":1717319471999,"mc":[{"id":"1.229554905","rc":[{"atl":[[60,5]],"id":60780007}],"con":true,"img":false}]}
{"op":"mcm","clk":"11450236608","pt":1717319476288,"mc":[{"id":"1.229554905","rc":[{"atb":[[2.5,0],[2.74,57.47]],"id":61631980}],"con":true,"img":false}]}
{"op":"mcm","clk":"11450236625","pt":1717319476491,"mc":[{"id":"1.229554905","rc":[{"atb":[[1.38,47.1]],"id":60780007}],"con":true,"img":false}]}
{"op":"mcm","clk":"11450236660","pt":1717319476902,"mc":[{"id":"1.229554905","rc":[{"atb":[[1.31,0]],"id":60780007}],"con":true,"img":false}]}
{"op":"mcm","clk":"11450236668","pt":1717319477009,"mc":[{"id":"1.229554905","rc":[{"atb":[[1.39,2]],"id":60780007}],"con":true,"img":false}]}
{"op":"mcm","clk":"11450236705","pt":1717319477413,"mc":[{"id":"1.229554905","rc":[{"atb":[[1.01,3.35]],"id":61631980}],"con":true,"img":false}]}
{"op":"mcm","clk":"11450236728","pt":1717319477682,"mc":[{"id":"1.229554905","rc":[{"atb":[[1.01,3.1]],"id":61631980}],"con":true,"img":false}]}
{"op":"mcm","clk":"11450236739","pt":1717319477788,"mc":[{"id":"1.229554905","rc":[{"atb":[[1.01,2.35]],"id":57451148}],"con":true,"img":false}]}
{"op":"mcm","clk":"11450236759","pt":1717319477995,"mc":[{"id":"1.229554905","rc":[{"atb":[[4.9,4.4]],"id":61631978}],"con":true,"img":false}]}
{"op":"mcm","clk":"11450236784","pt":1717319478297,"mc":[{"id":"1.229554905","rc":[{"atb":[[1.01,1]],"id":61631980}],"con":true,"img":false}]}
{"op":"mcm","clk":"11450236794","pt":1717319478402,"mc":[{"id":"1.229554905","rc":[{"atb":[[5.6,4.1]],"id":61631980}],"con":true,"img":false}]}
{"op":"mcm","clk":"11450236820","pt":1717319478709,"mc":[{"id":"1.229554905","rc":[{"atb":[[1.01,0.94]],"id":57451148}],"con":true,"img":false}]}
{"op":"mcm","clk":"11450236837","pt":1717319479018,"mc":[{"id":"1.229554905","rc":[{"atb":[[1.01,0]],"id":57451148}],"con":true,"img":false}]}
{"op":"mcm","clk":"11450236845","pt":1717319479115,"mc":[{"id":"1.229554905","rc":[{"atb":[[12.5,3.37]],"id":57451148},{"atb":[[1.4,6.39]],"id":60780007}],"con":true,"img":false}]}
{"op":"mcm","clk":"11450236857","pt":1717319479321,"mc":[{"id":"1.229554905","rc":[{"atb":[[1.38,0]],"id":60780007}],"con":true,"img":false}]}
{"op":"mcm","clk":"11450236871","pt":1717319479433,"mc":[{"id":"1.229554905","rc":[{"atb":[[1.39,0]],"id":60780007}],"con":true,"img":false}]}
{"op":"mcm","clk":"11450236876","pt":1717319479479,"mc":[{"id":"1.229554905","rc":[{"atb":[[1.41,2]],"id":60780007}],"con":true,"img":false}]}
{"op":"mcm","clk":"11450236902","pt":1717319479800,"mc":[{"id":"1.229554905","rc":[{"atb":[[1.4,0]],"id":60780007}],"con":true,"img":false}]}
{"op":"mcm","clk":"11450237099","pt":1717319482225,"mc":[{"id":"1.229554905","rc":[{"atb":[[1.41,0]],"id":60780007}],"con":true,"img":false}]}
{"op":"mcm","clk":"11450237109","pt":1717319482331,"mc":[{"id":"1.229554905","rc":[{"atb":[[1.31,2]],"id":60780007}],"con":true,"img":false}]}
{"op":"mcm","clk":"11450237445","pt":1717319486011,"mc":[{"id":"1.229554905","rc":[{"atb":[[4.3,31.65]],"id":61631980}],"con":true,"img":false}]}
{"op":"mcm","clk":"11450237534","pt":1717319487099,"mc":[{"id":"1.229554905","rc":[{"atb":[[4.3,34.75]],"id":61631980}],"con":true,"img":false}]}
{"op":"mcm","clk":"11450237945","pt":1717319491500,"mc":[{"id":"1.229554905","rc":[{"atb":[[1.2,0.78]],"id":61631980},{"atb":[[1.2,0.78]],"id":61631978}],"con":true,"img":false}]}
{"op":"mcm","clk":"11450237962","pt":1717319491707,"mc":[{"id":"1.229554905","rc":[{"atb":[[5.7,0.07]],"id":61631980},{"atl":[[17,0]],"id":61631980}],"con":true,"img":false}]}
{"op":"mcm","clk":"11450237986","pt":1717319492016,"mc":[{"id":"1.229554905","rc":[{"atb":[[13,0.03]],"id":57451148},{"atl":[[48,0]],"id":57451148},{"atb":[[1.2,0.2]],"id":61631980},{"atb":[[1.2,0.23]],"id":61631978}],"con":true,"img":false}]}
{"op":"mcm","clk":"11450238014","pt":1717319492333,"mc":[{"id":"1.229554905","rc":[{"atb":[[5,0.08]],"id":61631978}],"con":true,"img":false}]}
{"op":"mcm","clk":"11450238023","pt":1717319492431,"mc":[{"id":"1.229554905","rc":[{"atb":[[1.2,0]],"id":61631980},{"atb":[[1.2,0]],"id":61631978}],"con":true,"img":false}]}
{"op":"mcm","clk":"11450238036","pt":1717319492535,"mc":[{"id":"1.229554905","rc":[{"atl":[[1000,2.7]],"id":57451148},{"atb":[[5.7,0.28]],"id":61631980},{"atb":[[5,0.32]],"id":61631978}],"con":true,"img":false}]}
{"op":"mcm","clk":"11450238044","pt":1717319492633,"mc":[{"id":"1.229554905","rc":[{"atl":[[1.89,0]],"id":60780007}],"con":true,"img":false}]}
{"op":"mcm","clk":"11450238062","pt":1717319492838,"mc":[{"id":"1.229554905","rc":[{"atb":[[80,0.4]],"id":42269942}],"con":true,"img":false}]}
{"op":"mcm","clk":"11450238069","pt":1717319492944,"mc":[{"id":"1.229554905","rc":[{"atl":[[1000,2.7]],"id":61631980},{"atb":[[1.32,1.85]],"id":60780007}],"con":true,"img":false}]}
{"op":"mcm","clk":"11450238092","pt":1717319493107,"mc":[{"id":"1.229554905","rc":[{"atb":[[1.1,1.7]],"id":57451148},{"atl":[[21,2.5]],"id":61631980}],"con":true,"img":false}]}
{"op":"mcm","clk":"11450238104","pt":1717319493208,"mc":[{"id":"1.229554905","rc":[{"atl":[[20,5.75]],"id":61631980}],"con":true,"img":false}]}
{"op":"mcm","clk":"11450238115","pt":1717319493317,"mc":[{"id":"1.229554905","rc":[{"atb":[[1.05,1.7]],"id":61631980}],"con":true,"img":false}]}
{"op":"mcm","clk":"11450238142","pt":1717319493527,"mc":[{"id":"1.229554905","rc":[{"atb":[[1.04,1.7]],"id":61631978}],"con":true,"img":false}]}
{"op":"mcm","clk":"11450238152","pt":1717319493625,"mc":[{"id":"1.229554905","rc":[{"atl":[[1000,1.05]],"id":61631980}],"con":true,"img":false}]}
{"op":"mcm","clk":"11450238174","pt":1717319493834,"mc":[{"id":"1.229554905","rc":[{"atl":[[1000,2.7]],"id":60780007}],"con":true,"img":false}]}
{"op":"mcm","clk":"11450238184","pt":1717319493932,"mc":[{"id":"1.229554905","rc":[{"atb":[[1.4,1.7]],"id":42269942}],"con":true,"img":false}]}
{"op":"mcm","clk":"11450238194","pt":1717319494035,"mc":[{"id":"1.229554905","rc":[{"atb":[[1.1,0.06]],"id":57451148},{"atb":[[2.5,66.67],[2.74,0]],"id":61631980}],"con":true,"img":false}]}
{"op":"mcm","clk":"11450238222","pt":1717319494349,"mc":[{"id":"1.229554905","rc":[{"atl":[[1000,1.01]],"id":57451148}],"con":true,"img":false}]}
{"op":"mcm","clk":"11450238242","pt":1717319494510,"mc":[{"id":"1.229554905","rc":[{"atb":[[1.05,0.15]],"id":61631980}],"con":true,"img":false}]}
{"op":"mcm","clk":"11450238249","pt":1717319494618,"mc":[{"id":"1.229554905","rc":[{"atb":[[1.04,0.17]],"id":61631978}],"con":true,"img":false}]}
{"op":"mcm","clk":"11450238269","pt":1717319494832,"mc":[{"id":"1.229554905","rc":[{"atl":[[1000,1]],"id":61631980}],"con":true,"img":false}]}
{"op":"mcm","clk":"11450238277","pt":1717319494926,"mc":[{"id":"1.229554905","rc":[{"atl":[[17,0.05]],"id":61631980}],"con":true,"img":false}]}
{"op":"mcm","clk":"11450238299","pt":1717319495233,"mc":[{"id":"1.229554905","rc":[{"atl":[[1000,1.46]],"id":60780007}],"con":true,"img":false}]}
{"op":"mcm","clk":"11450238319","pt":1717319495545,"mc":[{"id":"1.229554905","rc":[{"atb":[[1.4,0.01]],"id":42269942},{"atb":[[1.32,1.2]],"id":60780007}],"con":true,"img":false}]}
{"op":"mcm","clk":"11450238338","pt":1717319495807,"mc":[{"id":"1.229554905","rc":[{"atb":[[1.1,0]],"id":57451148}],"con":true,"img":false}]}
{"op":"mcm","clk":"11450238347","pt":1717319495920,"mc":[{"id":"1.229554905","rc":[{"atb":[[13,0.1]],"id":57451148}],"con":true,"img":false}]}
{"op":"mcm","clk":"11450238370","pt":1717319496223,"mc":[{"id":"1.229554905","rc":[{"atl":[[1000,1]],"id":57451148}],"con":true,"img":false}]}
{"op":"mcm","clk":"11450238379","pt":1717319496332,"mc":[{"id":"1.229554905","rc":[{"atl":[[48,0.02]],"id":57451148}],"con":true,"img":false}]}
{"op":"mcm","clk":"11450238408","pt":1717319496636,"mc":[{"id":"1.229554905","rc":[{"atb":[[1.05,0]],"id":61631980}],"con":true,"img":false}]}
{"op":"mcm","clk":"11450238416","pt":1717319496739,"mc":[{"id":"1.229554905","rc":[{"atb":[[5.7,0.43]],"id":61631980}],"con":true,"img":false}]}
{"op":"mcm","clk":"11450238435","pt":1717319497043,"mc":[{"id":"1.229554905","rc":[{"atb":[[1.04,0]],"id":61631978}],"con":true,"img":false}]}
{"op":"mcm","clk":"11450238442","pt":1717319497145,"mc":[{"id":"1.229554905","rc":[{"atb":[[5,0.49]],"id":61631978}],"con":true,"img":false}]}
{"op":"mcm","clk":"11450238469","pt":1717319497406,"mc":[{"id":"1.229554905","rc":[{"atl":[[14,0]],"id":61631978}],"con":true,"img":false}]}
{"op":"mcm","clk":"11450238492","pt":1717319497716,"mc":[{"id":"1.229554905","rc":[{"atl":[[1000,1]],"id":60780007}],"con":true,"img":false}]}
{"op":"mcm","clk":"11450238498","pt":1717319497817,"mc":[{"id":"1.229554905","rc":[{"atl":[[1.86,0.46]],"id":60780007}],"con":true,"img":false}]}
{"op":"mcm","clk":"11450238521","pt":1717319498133,"mc":[{"id":"1.229554905","rc":[{"atb":[[1.4,0]],"id":42269942}],"con":true,"img":false}]}
{"op":"mcm","clk":"11450238529","pt":1717319498232,"mc":[{"id":"1.229554905","rc":[{"atb":[[65,0.01]],"id":42269942}],"con":true,"img":false}]}
{"op":"mcm","clk":"11450238556","pt":1717319498536,"mc":[{"id":"1.229554905","rc":[{"atb":[[1.03,1.7]],"id":60780007}],"con":true,"img":false}]}
{"op":"mcm","clk":"11450238564","pt":1717319498642,"mc":[{"id":"1.229554905","rc":[{"atl":[[1000,2.87]],"id":61631978}],"con":true,"img":false}]}
{"op":"mcm","clk":"11450238593","pt":1717319498949,"mc":[{"id":"1.229554905","rc":[{"atb":[[1.03,0.63]],"id":60780007},{"atl":[[1000,1.26]],"id":61631978}],"con":true,"img":false}]}
{"op":"mcm","clk":"11450238618","pt":1717319499209,"mc":[{"id":"1.229554905","rc":[{"atb":[[1.03,0]],"id":60780007}],"con":true,"img":false}]}
{"op":"mcm","clk":"11450238628","pt":1717319499313,"mc":[{"id":"1.229554905","rc":[{"atb":[[1.33,0.63]],"id":60780007}],"con":true,"img":false}]}
{"op":"mcm","clk":"11450238654","pt":1717319499629,"mc":[{"id":"1.229554905","rc":[{"atl":[[1000,1.17]],"id":61631978}],"con":true,"img":false}]}
{"op":"mcm","clk":"11450238663","pt":1717319499730,"mc":[{"id":"1.229554905","rc":[{"atl":[[9,0.09]],"id":61631978}],"con":true,"img":false}]}
{"op":"mcm","clk":"11450238707","pt":1717319500241,"mc":[{"id":"1.229554905","rc":[{"atb":[[2.74,57.47]],"id":61631980}],"con":true,"img":false}]}
{"op":"mcm","clk":"11450238714","pt":1717319500344,"mc":[{"id":"1.229554905","rc":[{"atb":[[2.5,0]],"id":61631980}],"con":true,"img":false}]}
{"op":"mcm","clk":"11450239191","pt":1717319505727,"mc":[{"id":"1.229554905","rc":[{"atb":[[1.24,95.36]],"id":60780007}],"con":true,"img":false}]}
{"op":"mcm","clk":"11450239459","pt":1717319508451,"mc":[{"id":"1.229554905","rc":[{"atb":[[1.32,0.32]],"id":60780007}],"con":true,"img":false}]}
{"op":"mcm","clk":"11450239890","pt":1717319513267,"mc":[{"id":"1.229554905","rc":[{"atl":[[1000,2]],"id":42269942},{"atl":[[1000,2]],"id":57451148}],"con":true,"img":false}]}
{"op":"mcm","clk":"11450239911","pt":1717319513474,"mc":[{"id":"1.229554905","rc":[{"atl":[[1000,1.01]],"id":42269942},{"atl":[[1000,1.01]],"id":57451148}],"con":true,"img":false}]}
{"op":"mcm","clk":"11450239928","pt":1717319513680,"mc":[{"id":"1.229554905","rc":[{"atl":[[1000,1]],"id":42269942},{"atl":[[1000,1]],"id":57451148}],"con":true,"img":false}]}
{"op":"mcm","clk":"11450239947","pt":1717319513840,"mc":[{"id":"1.229554905","rc":[{"atl":[[500,0.01]],"id":42269942},{"atl":[[46,0.01]],"id":57451148}],"con":true,"img":false}]}
{"op":"mcm","clk":"11450240557","pt":1717319520481,"mc":[{"id":"1.229554905","rc":[{"atl":[[44,3.59],[22,3.49]],"id":60780007},{"atl":[[44,3.59]],"id":61631978}],"con":true,"img":false}]}
{"op":"mcm","clk":"11450240587","pt":1717319520782,"mc":[{"id":"1.229554905","rc":[{"atb":[[1.2,0.78]],"id":60780007}],"con":true,"img":false}]}
{"op":"mcm","clk":"11450240625","pt":1717319521157,"mc":[{"id":"1.229554905","rc":[{"atb":[[1.2,0.57]],"id":60780007}],"con":true,"img":false}]}
{"op":"mcm","clk":"11450240664","pt":1717319521594,"mc":[{"id":"1.229554905","rc":[{"atb":[[1.2,0]],"id":60780007}],"con":true,"img":false}]}
{"op":"mcm","clk":"11450240673","pt":1717319521670,"mc":[{"id":"1.229554905","rc":[{"atb":[[1.33,1.21]],"id":60780007}],"con":true,"img":false}]}
{"op":"mcm","clk":"11450240724","pt":1717319522187,"mc":[{"id":"1.229554905","rc":[{"atb":[[12.5,2.98]],"id":57451148}],"con":true,"img":false}]}
{"op":"mcm","clk":"11450240780","pt":1717319522704,"mc":[{"id":"1.229554905","rc":[{"atb":[[1.02,161.7]],"id":57451148}],"con":true,"img":false}]}
{"op":"mcm","clk":"11450240836","pt":1717319523177,"mc":[{"id":"1.229554905","rc":[{"spn":295.0,"spf":"NaN","id":42269942},{"atb":[[1.02,159.74]],"id":57451148},{"spn":29.5,"spf":"NaN","id":57451148},{"spn":7.0,"spf":"NaN","id":61631978}],"con":true,"img":false}]}
{"op":"mcm","clk":"11450240882","pt":1717319523585,"mc":[{"id":"1.229554905","rc":[{"atb":[[1.02,159.35]],"id":57451148}],"con":true,"img":false}]}
{"op":"mcm","clk":"11450240896","pt":1717319523691,"mc":[{"id":"1.229554905","rc":[{"atb":[[12.5,3.37]],"id":57451148}],"con":true,"img":false}]}
{"op":"mcm","clk":"11450240929","pt":1717319523949,"mc":[{"id":"1.229554905","rc":[{"atb":[[13,0.06]],"id":57451148},{"atl":[[48,0.01]],"id":57451148}],"con":true,"img":false}]}
{"op":"mcm","clk":"11450240965","pt":1717319524311,"mc":[{"id":"1.229554905","rc":[{"atl":[[1.87,2.55]],"id":60780007},{"atb":[[5,0.4]],"id":61631978}],"con":true,"img":false}]}
{"op":"mcm","clk":"11450240991","pt":1717319524620,"mc":[{"id":"1.229554905","rc":[{"atb":[[80,0.39]],"id":42269942}],"con":true,"img":false}]}
{"op":"mcm","clk":"11450241002","pt":1717319524722,"mc":[{"id":"1.229554905","rc":[{"atl":[[1000,2.7]],"id":57451148}],"con":true,"img":false}]}
{"op":"mcm","clk":"11450241037","pt":1717319525032,"mc":[{"id":"1.229554905","rc":[{"atb":[[1.32,0]],"id":60780007}],"con":true,"img":false}]}
{"op":"mcm","clk":"11450241073","pt":1717319525300,"mc":[{"id":"1.229554905","rc":[{"atb":[[1.2,1.7]],"id":57451148},{"atb":[[1.08,1.7]],"id":61631978}],"con":true,"img":false}]}
{"op":"mcm","clk":"11450241101","pt":1717319525600,"mc":[{"id":"1.229554905","rc":[{"atl":[[1000,1]],"id":57451148}],"con":true,"img":false}]}
{"op":"mcm","clk":"11450241111","pt":1717319525702,"mc":[{"id":"1.229554905","rc":[{"atb":[[1.03,1.7]],"id":60780007}],"con":true,"img":false}]}
{"op":"mcm","clk":"11450241123","pt":1717319525820,"mc":[{"id":"1.229554905","rc":[{"atb":[[80,0]],"id":42269942}],"con":true,"img":false}]}
{"op":"mcm","clk":"11450241133","pt":1717319525965,"mc":[{"id":"1.229554905","rc":[{"atl":[[1000,2.7]],"id":60780007}],"con":true,"img":false}]}
{"op":"mcm","clk":"11450241146","pt":1717319526015,"mc":[{"id":"1.229554905","rc":[{"atb":[[1.08,0.08]],"id":61631978}],"con":true,"img":false}]}
{"op":"mcm","clk":"11450241163","pt":1717319526220,"mc":[{"id":"1.229554905","rc":[{"atb":[[1.2,0.03]],"id":57451148}],"con":true,"img":false}]}
{"op":"mcm","clk":"11450241170","pt":1717319526324,"mc":[{"id":"1.229554905","rc":[{"atl":[[1000,1]],"id":57451148}],"con":true,"img":false}]}
{"op":"mcm","clk":"11450241177","pt":1717319526427,"mc":[{"id":"1.229554905","rc":[{"atl":[[48,0.02]],"id":57451148}],"con":true,"img":false}]}
{"op":"mcm","clk":"11450241211","pt":1717319526842,"mc":[{"id":"1.229554905","rc":[{"atb":[[1.03,0.31]],"id":60780007},{"atl":[[1000,1.23]],"id":60780007}],"con":true,"img":false}]}
{"op":"mcm","clk":"11450241254","pt":1717319527310,"mc":[{"id":"1.229554905","rc":[{"atb":[[1.08,0]],"id":61631978}],"con":true,"img":false}]}
{"op":"mcm","clk":"11450241266","pt":1717319527413,"mc":[{"id":"1.229554905","rc":[{"atb":[[5,0.49]],"id":61631978}],"con":true,"img":false}]}
{"op":"mcm","clk":"11450241323","pt":1717319528032,"mc":[{"id":"1.229554905","rc":[{"atb":[[1.2,0]],"id":57451148}],"con":true,"img":false}]}
{"op":"mcm","clk":"11450241333","pt":1717319528137,"mc":[{"id":"1.229554905","rc":[{"atb":[[13,0.1]],"id":57451148}],"con":true,"img":false}]}
{"op":"mcm","clk":"11450241354","pt":1717319528359,"mc":[{"id":"1.229554905","rc":[{"atb":[[4.2,0]],"id":61631978}],"con":true,"img":false}]}
{"op":"mcm","clk":"11450241362","pt":1717319528401,"mc":[{"id":"1.229554905","rc":[{"atb":[[1.03,0]],"id":60780007}],"con":true,"img":false}]}
{"op":"mcm","clk":"11450241373","pt":1717319528515,"mc":[{"id":"1.229554905","rc":[{"atb":[[1.34,0.31]],"id":60780007}],"con":true,"img":false}]}
{"op":"mcm","clk":"11450241404","pt":1717319528826,"mc":[{"id":"1.229554905","rc":[{"atl":[[1000,1]],"id":60780007}],"con":true,"img":false}]}
{"op":"mcm","clk":"11450241420","pt":1717319528931,"mc":[{"id":"1.229554905","rc":[{"atl":[[1.86,0.69]],"id":60780007}],"con":true,"img":false}]}
{"op":"mcm","clk":"11450241448","pt":1717319529239,"mc":[{"id":"1.229554905","rc":[{"atb":[[1.8,1.7]],"id":42269942}],"con":true,"img":false}]}
{"op":"mcm","clk":"11450241483","pt":1717319529603,"mc":[{"id":"1.229554905","rc":[{"atb":[[1.8,0]],"id":42269942}],"con":true,"img":false}]}
{"op":"mcm","clk":"11450241516","pt":1717319530019,"mc":[{"id":"1.229554905","rc":[{"atb":[[1.8,0]],"id":42269942}],"con":true,"img":false}]}
{"op":"mcm","clk":"11450241525","pt":1717319530120,"mc":[{"id":"1.229554905","rc":[{"atb":[[65,0.02]],"id":42269942}],"con":true,"img":false}]}
{"op":"mcm","clk":"11450241565","pt":1717319530639,"mc":[{"id":"1.229554905","rc":[{"atb":[[1.02,2.35]],"id":61631978}],"con":true,"img":false}]}
{"op":"mcm","clk":"11450241638","pt":1717319531319,"mc":[{"id":"1.229554905","rc":[{"atb":[[1.02,0.39]],"id":61631978}],"con":true,"img":false}]}
{"op":"mcm","clk":"11450241677","pt":1717319531730,"mc":[{"id":"1.229554905","rc":[{"atb":[[1.02,0]],"id":61631978}],"con":true,"img":false}]}
{"op":"mcm","clk":"11450241688","pt":1717319531832,"mc":[{"id":"1.229554905","rc":[{"atb":[[4.2,0.39]],"id":61631978}],"con":true,"img":false}]}
{"op":"mcm","clk":"11450242190","pt":1717319537252,"mc":[{"id":"1.229554905","rc":[{"atb":[[1.33,0.63]],"id":60780007}],"con":true,"img":false}]}
{"op":"mcm","clk":"11450242479","pt":1717319540371,"mc":[{"id":"1.229554905","rc":[{"atb":[[5.6,2]],"id":61631980}],"con":true,"img":false}]}
{"op":"mcm","clk":"11450242502","pt":1717319540630,"mc":[{"id":"1.229554905","rc":[{"atb":[[12.5,2.43]],"id":57451148},{"atb":[[4.9,2]],"id":61631978}],"con":true,"img":false}]}
{"op":"mcm","clk":"11450242522","pt":1717319540840,"mc":[{"id":"1.229554905","rc":[{"atb":[[1.01,2.35]],"id":57451148}],"con":true,"img":false}]}
{"op":"mcm","clk":"11450242535","pt":1717319541000,"mc":[{"id":"1.229554905","rc":[{"atb":[[1.01,3.35]],"id":61631980}],"con":true,"img":false}]}
{"op":"mcm","clk":"11450242552","pt":1717319541154,"mc":[{"id":"1.229554905","rc":[{"atb":[[1.01,0.94]],"id":57451148}],"con":true,"img":false}]}
{"op":"mcm","clk":"11450242564","pt":1717319541258,"mc":[{"id":"1.229554905","rc":[{"atb":[[1.01,3.1]],"id":61631980}],"con":true,"img":false}]}
{"op":"mcm","clk":"11450242587","pt":1717319541464,"mc":[{"id":"1.229554905","rc":[{"atb":[[1.01,0]],"id":57451148}],"con":true,"img":false}]}
{"op":"mcm","clk":"11450242597","pt":1717319541566,"mc":[{"id":"1.229554905","rc":[{"atb":[[12.5,3.37]],"id":57451148},{"atb":[[4.9,4.4]],"id":61631978}],"con":true,"img":false}]}
{"op":"mcm","clk":"11450242641","pt":1717319541928,"mc":[{"id":"1.229554905","rc":[{"atb":[[1.01,1]],"id":61631980}],"con":true,"img":false}]}
{"op":"mcm","clk":"11450242652","pt":1717319542042,"mc":[{"id":"1.229554905","rc":[{"atb":[[5.6,4.1]],"id":61631980}],"con":true,"img":false}]}
{"op":"mcm","clk":"11450243390","pt":1717319549539,"mc":[{"id":"1.229554905","rc":[{"atb":[[1.2,0.78]],"id":60780007}],"con":true,"img":false}]}
{"op":"mcm","clk":"11450243437","pt":1717319549950,"mc":[{"id":"1.229554905","rc":[{"atb":[[1.2,0.28]],"id":60780007}],"con":true,"img":false}]}
{"op":"mcm","clk":"11450243481","pt":1717319550365,"mc":[{"id":"1.229554905","rc":[{"atb":[[1.2,0]],"id":60780007}],"con":true,"img":false}]}
{"op":"mcm","clk":"11450243492","pt":1717319550474,"mc":[{"id":"1.229554905","rc":[{"atb":[[1.34,0.59]],"id":60780007}],"con":true,"img":false}]}
{"op":"mcm","clk":"11450243621","pt":1717319551771,"mc":[{"id":"1.229554905","rc":[{"atb":[[5.7,0.35]],"id":61631980}],"con":true,"img":false}]}
{"op":"mcm","clk":"11450243642","pt":1717319552080,"mc":[{"id":"1.229554905","rc":[{"atl":[[13,0]],"id":61631978}],"con":true,"img":false}]}
{"op":"mcm","clk":"11450243884","pt":1717319554977,"mc":[{"id":"1.229554905","rc":[{"atb":[[1.09,1.7]],"id":61631980}],"con":true,"img":false}]}
{"op":"mcm","clk":"11450243917","pt":1717319555340,"mc":[{"id":"1.229554905","rc":[{"atl":[[1000,2.87]],"id":61631978}],"con":true,"img":false}]}
{"op":"mcm","clk":"11450243951","pt":1717319555750,"mc":[{"id":"1.229554905","rc":[{"atl":[[1.88,6.07]],"id":60780007}],"con":true,"img":false}]}
{"op":"mcm","clk":"11450244166","pt":1717319558179,"mc":[{"id":"1.229554905","rc":[{"atb":[[1.09,0.07]],"id":61631980}],"con":true,"img":false}]}
{"op":"mcm","clk":"11450244211","pt":1717319558649,"mc":[{"id":"1.229554905","rc":[{"atl":[[1000,1.22]],"id":61631978}],"con":true,"img":false}]}
{"op":"mcm","clk":"11450244244","pt":1717319558960,"mc":[{"id":"1.229554905","rc":[{"atb":[[1.09,0]],"id":61631980}],"con":true,"img":false}]}
{"op":"mcm","clk":"11450244254","pt":1717319559061,"mc":[{"id":"1.229554905","rc":[{"atb":[[5.7,0.43]],"id":61631980}],"con":true,"img":false}]}
{"op":"mcm","clk":"11450244351","pt":1717319560045,"mc":[{"id":"1.229554905","rc":[{"atl":[[1000,1.17]],"id":61631978}],"con":true,"img":false}]}
{"op":"mcm","clk":"11450244362","pt":1717319560151,"mc":[{"id":"1.229554905","rc":[{"atl":[[9,0.14]],"id":61631978}],"con":true,"img":false}]}
{"op":"mcm","clk":"11450244928","pt":1717319566413,"mc":[{"id":"1.229554905","rc":[{"atb":[[85,4.61]],"id":42269942},{"atl":[[610,2.15]],"id":42269942},{"atl":[[48,2.02],[55,2]],"id":57451148},{"atb":[[3.8,35.71],[2.74,0]],"id":61631980},{"atl":[[34,9.37],[26,0]],"id":61631980},{"atl":[[9,2.64],[9.2,0],[12.5,8.7],[21,0]],"id":61631978}],"con":true,"img":false}]}
{"op":"mcm","clk":"11450244947","pt":1717319566580,"mc":[{"id":"1.229554905","rc":[{"atb":[[70,2],[85,2.61]],"id":42269942},{"atl":[[610,0.15],[960,2.85]],"id":42269942},{"atl":[[48,4.15],[55,0]],"id":57451148},{"atb":[[3.8,0],[4.4,70.21]],"id":61631980}],"con":true,"img":false}]}
{"op":"mcm","clk":"11450244998","pt":1717319567092,"mc":[{"id":"1.229554905","rc":[{"atl":[[2.1,0]],"id":60780007}],"con":true,"img":false}]}
{"op":"mcm","clk":"11450245016","pt":1717319567298,"mc":[{"id":"1.229554905","rc":[{"atl":[[11,0]],"id":61631980}],"con":true,"img":false}]}
{"op":"mcm","clk":"11450245026","pt":1717319567402,"mc":[{"id":"1.229554905","rc":[{"atl":[[34,6.34],[29,3.57]],"id":61631980}],"con":true,"img":false}]}
{"op":"mcm","clk":"11450245054","pt":1717319567717,"mc":[{"id":"1.229554905","rc":[{"atl":[[1000,2.7]],"id":61631980}],"con":true,"img":false}]}
{"op":"mcm","clk":"11450245066","pt":1717319567767,"mc":[{"id":"1.229554905","rc":[{"atl":[[1.88,3]],"id":60780007}],"con":true,"img":false}]}
{"op":"mcm","clk":"11450245085","pt":1717319568023,"mc":[{"id":"1.229554905","rc":[{"atb":[[5.7,3.13]],"id":61631980},{"atl":[[1000,1.02]],"id":61631980},{"atl":[[1.86,3.69]],"id":60780007},{"atb":[[5,3.49]],"id":61631978},{"atl":[[9,5.49]],"id":61631978}],"con":true,"img":false}]}
{"op":"mcm","clk":"11450245109","pt":1717319568280,"mc":[{"id":"1.229554905","rc":[{"atb":[[5.8,4.4]],"id":61631980},{"atl":[[1000,1]],"id":61631980},{"atb":[[5.1,5.01]],"id":61631978}],"con":true,"img":false}]}
{"op":"mcm","clk":"11450245122","pt":1717319568392,"mc":[{"id":"1.229554905","rc":[{"atl":[[1000,2],[17,0.07]],"id":61631980}],"con":true,"img":false}]}
{"op":"mcm","clk":"11450245132","pt":1717319568487,"mc":[{"id":"1.229554905","rc":[{"atl":[[1000,1.01]],"id":61631980}],"con":true,"img":false}]}
{"op":"mcm","clk":"11450245147","pt":1717319568694,"mc":[{"id":"1.229554905","rc":[{"atl":[[1000,1]],"id":61631980}],"con":true,"img":false}]}
{"op":"mcm","clk":"11450245157","pt":1717319568795,"mc":[{"id":"1.229554905","rc":[{"atl":[[16.5,0.01]],"id":61631980}],"con":true,"img":false}]}
{"op":"mcm","clk":"11450245232","pt":1717319569674,"mc":[{"id":"1.229554905","rc":[{"atb":[[5.6,2.1]],"id":61631980}],"con":true,"img":false}]}
{"op":"mcm","clk":"11450245240","pt":1717319569778,"mc":[{"id":"1.229554905","rc":[{"atb":[[5.9,2]],"id":61631980}],"con":true,"img":false}]}
{"op":"mcm","clk":"11450245260","pt":1717319569985,"mc":[{"id":"1.229554905","rc":[{"atb":[[4.9,2.4]],"id":61631978}],"con":true,"img":false}]}
{"op":"mcm","clk":"11450245270","pt":1717319570087,"mc":[{"id":"1.229554905","rc":[{"atb":[[5.2,2]],"id":61631978}],"con":true,"img":false}]}
{"op":"mcm","clk":"11450245308","pt":1717319570503,"mc":[{"id":"1.229554905","rc":[{"atb":[[5.8,0]],"id":61631980},{"atb":[[5.1,0]],"id":61631978}],"con":true,"img":false}]}
{"op":"mcm","clk":"11450245327","pt":1717319570707,"mc":[{"id":"1.229554905","rc":[{"atl":[[950,2]],"id":42269942},{"atl":[[25,9.38],[29,0]],"id":61631980},{"atl":[[1.87,0]],"id":60780007}],"con":true,"img":false}]}
{"op":"mcm","clk":"11450245379","pt":1717319571176,"mc":[{"id":"1.229554905","rc":[{"atl":[[940,0.02]],"id":42269942}],"con":true,"img":false}]}
{"op":"mcm","clk":"11450245430","pt":1717319571691,"mc":[{"id":"1.229554905","rc":[{"atb":[[70,0],[85,4.61]],"id":42269942},{"atl":[[610,2.15],[960,0.85]],"id":42269942}],"con":true,"img":false}]}
{"op":"mcm","clk":"11450245441","pt":1717319571797,"mc":[{"id":"1.229554905","rc":[{"atb":[[70,2],[85,2.61]],"id":42269942},{"atl":[[610,0.15],[940,2.02]],"id":42269942},{"atb":[[4.3,31.65],[5.9,0]],"id":61631980}],"con":true,"img":false}]}
{"op":"mcm","clk":"11450245448","pt":1717319571896,"mc":[{"id":"1.229554905","rc":[{"atl":[[48,2.02],[50,7.27]],"id":57451148},{"atb":[[5.8,2]],"id":61631980}],"con":true,"img":false}]}
{"op":"mcm","clk":"11450245455","pt":1717319572000,"mc":[{"id":"1.229554905","rc":[{"atl":[[950,0]],"id":42269942}],"con":true,"img":false}]}
{"op":"mcm","clk":"11450245471","pt":1717319572206,"mc":[{"id":"1.229554905","rc":[{"atb":[[5.2,0]],"id":61631978}],"con":true,"img":false}]}
{"op":"mcm","clk":"11450245480","pt":1717319572310,"mc":[{"id":"1.229554905","rc":[{"atb":[[5.1,2]],"id":61631978}],"con":true,"img":false}]}
{"op":"mcm","clk":"11450245535","pt":1717319572879,"mc":[{"id":"1.229554905","rc":[{"atb":[[4.3,34.74]],"id":61631980}],"con":true,"img":false}]}
{"op":"mcm","clk":"11450245690","pt":1717319574589,"mc":[{"id":"1.229554905","rc":[{"atl":[[9,2.99],[9.4,2.38]],"id":61631978}],"con":true,"img":false}]}
{"op":"mcm","clk":"11450245927","pt":1717319576906,"mc":[{"id":"1.229554905","rc":[{"atb":[[70,0],[85,4.61]],"id":42269942},{"atl":[[610,2.15],[940,0.02]],"id":42269942}],"con":true,"img":false}]}
{"op":"mcm","clk":"11450245935","pt":1717319577008,"mc":[{"id":"1.229554905","rc":[{"atb":[[85,2.61]],"id":42269942}],"con":true,"img":false}]}
{"op":"mcm","clk":"11450245949","pt":1717319577112,"mc":[{"id":"1.229554905","rc":[{"atb":[[70,2]],"id":42269942}],"con":true,"img":false}]}
{"op":"mcm","clk":"11450245990","pt":1717319577579,"mc":[{"id":"1.229554905","rc":[{"atl":[[940,0]],"id":42269942}],"con":true,"img":false}]}
{"op":"mcm","clk":"11450246002","pt":1717319577685,"mc":[{"id":"1.229554905","rc":[{"atb":[[5.7,2.93]],"id":61631980},{"atb":[[5,3.25]],"id":61631978}],"con":true,"img":false}]}
{"op":"mcm","clk":"11450246166","pt":1717319579806,"mc":[{"id":"1.229554905","rc":[{"atb":[[5.7,0.23]],"id":61631980},{"atb":[[5,0.25]],"id":61631978},{"atl":[[9,0.14]],"id":61631978}],"con":true,"img":false}]}
{"op":"mcm","clk":"11450246205","pt":1717319580214,"mc":[{"id":"1.229554905","rc":[{"atb":[[10,6.2],[3,12.2],[4,6.2],[2.02,12.2],[6,6.2],[30,11.81]],"id":42269942},{"atb":[[3,12.2],[4,6.2],[2.02,12.2],[6,6.2]],"id":57451148},{"atb":[[3,12.2],[2.02,12.2]],"id":61631980},{"atb":[[2.02,12.2]],"id":61631978}],"con":true,"img":false}]}
{"op":"mcm","clk":"11450246310","pt":1717319581416,"mc":[{"id":"1.229554905","rc":[{"atb":[[5.8,0]],"id":61631980}],"con":true,"img":false}]}
{"op":"mcm","clk":"11450246318","pt":1717319581518,"mc":[{"id":"1.229554905","rc":[{"atb":[[5.7,2.23]],"id":61631980}],"con":true,"img":false}]}
{"op":"mcm","clk":"11450246338","pt":1717319581727,"mc":[{"id":"1.229554905","rc":[{"atb":[[5.1,0]],"id":61631978}],"con":true,"img":false}]}
{"op":"mcm","clk":"11450246348","pt":1717319581829,"mc":[{"id":"1.229554905","rc":[{"atb":[[5,2.25]],"id":61631978}],"con":true,"img":false}]}
{"op":"mcm","clk":"11450246399","pt":1717319582305,"mc":[{"id":"1.229554905","rc":[{"atb":[[40,0],[50,0],[70,0],[85,4.61],[30,2]],"id":42269942},{"atl":[[610,2],[510,0]],"id":42269942},{"atb":[[11.5,0],[9.6,0],[8.6,0]],"id":57451148},{"atl":[[200,0],[300,0]],"id":57451148},{"atb":[[4.3,3.09],[3.9,0],[3.65,0]],"id":61631980},{"atl":[[34,0],[22,0]],"id":61631980},{"atb":[[1.18,689.36],[1.23,86.96],[1.13,0]],"id":60780007},{"atl":[[2.64,0],[2.84,0]],"id":60780007},{"atb":[[3.4,0],[3.9,3.57],[3.65,0]],"id":61631978},{"atl":[[19,0],[28,0]],"id":61631978}],"con":true,"img":false}]}
{"op":"mcm","clk":"11450246413","pt":1717319582512,"mc":[{"id":"1.229554905","rc":[{"atl":[[610,0],[990,2]],"id":42269942}],"con":true,"img":false}]}
{"op":"mcm","clk":"11450246491","pt":1717319583115,"mc":[{"id":"1.229554905","rc":[{"atb":[[3.95,0]],"id":61631978}],"con":true,"img":false}]}
{"op":"mcm","clk":"11450246500","pt":1717319583210,"mc":[{"id":"1.229554905","rc":[{"spn":11.1,"spf":"NaN","id":61631980},{"spn":1.6,"spf":"NaN","id":60780007},{"atb":[[3.45,41.18]],"id":61631978}],"con":true,"img":false}]}
{"op":"mcm","clk":"11450246596","pt":1717319584203,"mc":[{"id":"1.229554905","rc":[{"atb":[[1.21,244.35]],"id":60780007}],"con":true,"img":false}]}
{"op":"mcm","clk":"11450247040","pt":1717319589220,"mc":[{"id":"1.229554905","rc":[{"atl":[[1.85,2.55]],"id":60780007}],"con":true,"img":false}]}
{"op":"mcm","clk":"11450247219","pt":1717319591409,"mc":[{"id":"1.229554905","rc":[{"atb":[[5.7,4.23]],"id":61631980},{"atb":[[5,4.28]],"id":61631978}],"con":true,"img":false}]}
{"op":"mcm","clk":"11450247272","pt":1717319591915,"mc":[{"id":"1.229554905","rc":[{"atl":[[1.86,0.69]],"id":60780007}],"con":true,"img":false}]}
{"op":"mcm","clk":"11450247284","pt":1717319592020,"mc":[{"id":"1.229554905","rc":[{"atl":[[1.85,5.59]],"id":60780007},{"atl":[[9.4,4.38]],"id":61631978}],"con":true,"img":false}]}
{"op":"mcm","clk":"11450247292","pt":1717319592125,"mc":[{"id":"1.229554905","rc":[{"atb":[[5.8,4.4]],"id":61631980}],"con":true,"img":false}]}
{"op":"mcm","clk":"11450247445","pt":1717319593824,"mc":[{"id":"1.229554905","rc":[{"atb":[[5.7,2.23]],"id":61631980}],"con":true,"img":false}]}
{"op":"mcm","clk":"11450247455","pt":1717319593928,"mc":[{"id":"1.229554905","rc":[{"atb":[[5.9,2]],"id":61631980}],"con":true,"img":false}]}
{"op":"mcm","clk":"11450247509","pt":1717319594605,"mc":[{"id":"1.229554905","rc":[{"atb":[[5.8,0]],"id":61631980}],"con":true,"img":false}]}
{"op":"mcm","clk":"11450247559","pt":1717319595218,"mc":[{"id":"1.229554905","rc":[{"atb":[[5.9,0]],"id":61631980}],"con":true,"img":false}]}
{"op":"mcm","clk":"11450247569","pt":1717319595319,"mc":[{"id":"1.229554905","rc":[{"atb":[[5.8,2]],"id":61631980}],"con":true,"img":false}]}
{"op":"mcm","clk":"11450247591","pt":1717319595533,"mc":[{"id":"1.229554905","rc":[{"atb":[[40,7.29],[50,2.9],[30,11.81]],"id":42269942},{"atl":[[610,0.15],[510,0.12]],"id":42269942},{"atb":[[11.5,9.95],[9.6,24.29],[8.6,27.48]],"id":57451148},{"atl":[[200,0.7],[300,0.7]],"id":57451148},{"atb":[[4.3,34.74],[3.9,72.04],[3.65,78.83]],"id":61631980},{"atl":[[34,6.34],[22,6.64]],"id":61631980},{"atb":[[1.18,1849.98],[1.23,541.11],[1.13,1607.02]],"id":60780007},{"atl":[[2.64,85.07],[2.84,113.74]],"id":60780007},{"atb":[[3.4,87.04],[3.9,39.59],[3.65,78.83]],"id":61631978},{"atl":[[19,7.75],[28,7.75]],"id":61631978}],"con":true,"img":false}]}
{"op":"mcm","clk":"11450247617","pt":1717319595742,"mc":[{"id":"1.229554905","rc":[{"atl":[[610,2.15],[990,0]],"id":42269942}],"con":true,"img":false}]}
{"op":"mcm","clk":"11450247637","pt":1717319595949,"mc":[{"id":"1.229554905","rc":[{"atl":[[610,0.15]],"id":42269942}],"con":true,"img":false}]}
{"op":"mcm","clk":"11450247646","pt":1717319596003,"mc":[{"id":"1.229554905","rc":[{"atl":[[610,2.15]],"id":42269942}],"con":true,"img":false}]}
{"op":"mcm","clk":"11450248105","pt":1717319601717,"mc":[{"id":"1.229554905","rc":[{"atl":[[9.2,2.77]],"id":61631978}],"con":true,"img":false}]}
{"op":"mcm","clk":"11450248127","pt":1717319602021,"mc":[{"id":"1.229554905","rc":[{"atb":[[5.6,0],[5.7,0.23]],"id":61631980}],"con":true,"img":false}]}
{"op":"mcm","clk":"11450248133","pt":1717319602129,"mc":[{"id":"1.229554905","rc":[{"atb":[[12.5,2.43]],"id":57451148}],"con":true,"img":false}]}
{"op":"mcm","clk":"11450248149","pt":1717319602334,"mc":[{"id":"1.229554905","rc":[{"atb":[[1.01,3.35]],"id":61631980}],"con":true,"img":false}]}
{"op":"mcm","clk":"11450248157","pt":1717319602433,"mc":[{"id":"1.229554905","rc":[{"atb":[[4.9,0]],"id":61631978}],"con":true,"img":false}]}
{"op":"mcm","clk":"11450248174","pt":1717319602639,"mc":[{"id":"1.229554905","rc":[{"atb":[[1.01,3.03]],"id":61631980}],"con":true,"img":false}]}
{"op":"mcm","clk":"11450248182","pt":1717319602741,"mc":[{"id":"1.229554905","rc":[{"atb":[[1.01,2.35]],"id":57451148}],"con":true,"img":false}]}
{"op":"mcm","clk":"11450248195","pt":1717319602947,"mc":[{"id":"1.229554905","rc":[{"atb":[[1.01,1]],"id":61631980}],"con":true,"img":false}]}
{"op":"mcm","clk":"11450248203","pt":1717319603007,"mc":[{"id":"1.229554905","rc":[{"atb":[[5.8,4.03]],"id":61631980}],"con":true,"img":false}]}
{"op":"mcm","clk":"11450248209","pt":1717319603112,"mc":[{"id":"1.229554905","rc":[{"atl":[[20,0]],"id":61631980}],"con":true,"img":false}]}
{"op":"mcm","clk":"11450248217","pt":1717319603217,"mc":[{"id":"1.229554905","rc":[{"atl":[[21,8.25]],"id":61631980}],"con":true,"img":false}]}
{"op":"mcm","clk":"11450248226","pt":1717319603321,"mc":[{"id":"1.229554905","rc":[{"atb":[[5,6.63]],"id":61631978}],"con":true,"img":false}]}
{"op":"mcm","clk":"11450248254","pt":1717319603624,"mc":[{"id":"1.229554905","rc":[{"atb":[[5.8,2]],"id":61631980}],"con":true,"img":false}]}
{"op":"mcm","clk":"11450248283","pt":1717319603933,"mc":[{"id":"1.229554905","rc":[{"atb":[[1.01,0.94]],"id":57451148}],"con":true,"img":false}]}
{"op":"mcm","clk":"11450248294","pt":1717319604035,"mc":[{"id":"1.229554905","rc":[{"atl":[[9.4,2],[8.6,2.63]],"id":61631978}],"con":true,"img":false}]}
{"op":"mcm","clk":"11450248312","pt":1717319604241,"mc":[{"id":"1.229554905","rc":[{"atb":[[1.01,0]],"id":57451148},{"atb":[[1.01,3.35]],"id":61631980},{"atl":[[9.4,0]],"id":61631978}],"con":true,"img":false}]}
{"op":"mcm","clk":"11450248322","pt":1717319604348,"mc":[{"id":"1.229554905","rc":[{"atb":[[12.5,3.37]],"id":57451148}],"con":true,"img":false}]}
{"op":"mcm","clk":"11450248331","pt":1717319604449,"mc":[{"id":"1.229554905","rc":[{"atb":[[5.1,3.2]],"id":61631978}],"con":true,"img":false}]}
{"op":"mcm","clk":"11450248341","pt":1717319604507,"mc":[{"id":"1.229554905","rc":[{"atl":[[9.2,0]],"id":61631978}],"con":true,"img":false}]}
{"op":"mcm","clk":"11450248345","pt":1717319604609,"mc":[{"id":"1.229554905","rc":[{"atb":[[1.01,3.03]],"id":61631980}],"con":true,"img":false}]}
{"op":"mcm","clk":"11450248364","pt":1717319604921,"mc":[{"id":"1.229554905","rc":[{"atb":[[1.01,1]],"id":61631980}],"con":true,"img":false}]}
{"op":"mcm","clk":"11450248369","pt":1717319605027,"mc":[{"id":"1.229554905","rc":[{"atb":[[5.8,4.03]],"id":61631980}],"con":true,"img":false}]}
{"op":"mcm","clk":"11450248393","pt":1717319605330,"mc":[{"id":"1.229554905","rc":[{"atb":[[5.8,2.03]],"id":61631980}],"con":true,"img":false}]}
{"op":"mcm","clk":"11450248400","pt":1717319605433,"mc":[{"id":"1.229554905","rc":[{"atb":[[5.6,2]],"id":61631980}],"con":true,"img":false}]}
{"op":"mcm","clk":"11450248417","pt":1717319605639,"mc":[{"id":"1.229554905","rc":[{"atb":[[5,4.63]],"id":61631978}],"con":true,"img":false}]}
{"op":"mcm","clk":"11450248428","pt":1717319605745,"mc":[{"id":"1.229554905","rc":[{"atb":[[5.8,0]],"id":61631980},{"atb":[[5.2,2]],"id":61631978}],"con":true,"img":false}]}
{"op":"mcm","clk":"11450248445","pt":1717319605948,"mc":[{"id":"1.229554905","rc":[{"atb":[[1.01,3.35]],"id":61631980}],"con":true,"img":false}]}
{"op":"mcm","clk":"11450248495","pt":1717319606430,"mc":[{"id":"1.229554905","rc":[{"atb":[[1.01,3.03]],"id":61631980}],"con":true,"img":false}]}
{"op":"mcm","clk":"11450248526","pt":1717319606733,"mc":[{"id":"1.229554905","rc":[{"atb":[[1.01,1]],"id":61631980}],"con":true,"img":false}]}
{"op":"mcm","clk":"11450248537","pt":1717319606835,"mc":[{"id":"1.229554905","rc":[{"atb":[[5.8,2.03]],"id":61631980}],"con":true,"img":false}]}
{"op":"mcm","clk":"11450248569","pt":1717319607251,"mc":[{"id":"1.229554905","rc":[{"atb":[[5.8,0],[5.6,0]],"id":61631980}],"con":true,"img":false}]}
{"op":"mcm","clk":"11450248582","pt":1717319607361,"mc":[{"id":"1.229554905","rc":[{"atb":[[5.9,2]],"id":61631980}],"con":true,"img":false}]}
{"op":"mcm","clk":"11450248595","pt":1717319607460,"mc":[{"id":"1.229554905","rc":[{"atb":[[4.3,31.65]],"id":61631980}],"con":true,"img":false}]}
{"op":"mcm","clk":"11450248614","pt":1717319607618,"mc":[{"id":"1.229554905","rc":[{"atb":[[1.01,3.35]],"id":61631980}],"con":true,"img":false}]}
{"op":"mcm","clk":"11450248639","pt":1717319607926,"mc":[{"id":"1.229554905","rc":[{"atb":[[1.01,3.14]],"id":61631980}],"con":true,"img":false}]}
{"op":"mcm","clk":"11450248663","pt":1717319608236,"mc":[{"id":"1.229554905","rc":[{"atb":[[1.01,1]],"id":61631980}],"con":true,"img":false}]}
{"op":"mcm","clk":"11450248671","pt":1717319608338,"mc":[{"id":"1.229554905","rc":[{"atb":[[5.5,4.75]],"id":61631980}],"con":true,"img":false}]}
{"op":"mcm","clk":"11450248692","pt":1717319608544,"mc":[{"id":"1.229554905","rc":[{"atb":[[4.3,34.44]],"id":61631980}],"con":true,"img":false}]}
{"op":"mcm","clk":"11450248719","pt":1717319608807,"mc":[{"id":"1.229554905","rc":[{"atl":[[1.85,3.04]],"id":60780007}],"con":true,"img":false}]}
{"op":"mcm","clk":"11450248747","pt":1717319609116,"mc":[{"id":"1.229554905","rc":[{"atb":[[5.9,0]],"id":61631980}],"con":true,"img":false}]}
{"op":"mcm","clk":"11450248752","pt":1717319609216,"mc":[{"id":"1.229554905","rc":[{"atb":[[5.6,2]],"id":61631980}],"con":true,"img":false}]}
{"op":"mcm","clk":"11450248973","pt":1717319611647,"mc":[{"id":"1.229554905","rc":[{"atl":[[9,6.39]],"id":61631978}],"con":true,"img":false}]}
{"op":"mcm","clk":"11450248983","pt":1717319611749,"mc":[{"id":"1.229554905","rc":[{"atl":[[1.84,2.55]],"id":60780007}],"con":true,"img":false}]}
{"op":"mcm","clk":"11450249202","pt":1717319614336,"mc":[{"id":"1.229554905","rc":[{"atb":[[5.7,0.07]],"id":61631980}],"con":true,"img":false}]}
{"op":"mcm","clk":"11450249227","pt":1717319614649,"mc":[{"id":"1.229554905","rc":[{"atb":[[13,0.03]],"id":57451148},{"atl":[[17,0.02]],"id":61631980}],"con":true,"img":false}]}
{"op":"mcm","clk":"11450249249","pt":1717319614954,"mc":[{"id":"1.229554905","rc":[{"atl":[[48,2]],"id":57451148},{"atb":[[5,4.46]],"id":61631978}],"con":true,"img":false}]}
{"op":"mcm","clk":"11450249262","pt":1717319615115,"mc":[{"id":"1.229554905","rc":[{"atb":[[5,2.44]],"id":61631978}],"con":true,"img":false}]}
{"op":"mcm","clk":"11450249271","pt":1717319615223,"mc":[{"id":"1.229554905","rc":[{"atb":[[5.9,1.8]],"id":61631980},{"atl":[[1000,2.7]],"id":61631980}],"con":true,"img":false}]}
