{"op":"mcm","clk":"11448127651","pt":1717286034987,"mc":[{"id":"1.229554926","marketDefinition":{"bspMarket":true,"turnInPlayEnabled":false,"persistenceEnabled":false,"marketBaseRate":7.0,"eventId":"33318908","eventTypeId":"4339","numberOfWinners":2,"bettingType":"ODDS","marketType":"PLACE","marketTime":"2024-06-02T10:45:00.000Z","suspendTime":"2024-06-02T10:45:00.000Z","bspReconciled":false,"complete":true,"inPlay":false,"crossMatching":true,"runnersVoidable":false,"numberOfActiveRunners":6,"betDelay":0,"status":"OPEN","runners":[{"status":"ACTIVE","sortPriority":1,"id":40917581,"name":"1. Sophia Palms"},{"status":"ACTIVE","sortPriority":2,"id":47148562,"name":"2. Under Siege"},{"status":"ACTIVE","sortPriority":3,"id":49546922,"name":"4. Uno Whiskey"},{"status":"ACTIVE","sortPriority":4,"id":70003372,"name":"5. Southern Sun"},{"status":"ACTIVE","sortPriority":5,"id":48638605,"name":"7. Lochinvar Aloisi"},{"status":"ACTIVE","sortPriority":6,"id":64343695,"name":"8. Punching Poncho"}],"regulators":["MR_INT"],"venue":"Murray Bridge","countryCode":"AU","discountAllowed":true,"timezone":"Australia/Adelaide","openDate":"2024-06-02T08:21:00.000Z","version":5962317644,"name":"To Be Placed","eventName":"Murray Bridge (AUS) 2nd Jun"},"rc":[],"con":true,"img":false}]}
{"op":"mcm","clk":"11448135507","pt":1717286146256,"mc":[{"id":"1.229554926","marketDefinition":{"bspMarket":true,"turnInPlayEnabled":false,"persistenceEnabled":false,"marketBaseRate":7.0,"eventId":"33318908","eventTypeId":"4339","numberOfWinners":2,"bettingType":"ODDS","marketType":"PLACE","marketTime":"2024-06-02T10:41:00.000Z","suspendTime":"2024-06-02T10:41:00.000Z","bspReconciled":false,"complete":true,"inPlay":false,"crossMatching":true,"runnersVoidable":false,"numberOfActiveRunners":6,"betDelay":0,"status":"OPEN","runners":[{"status":"ACTIVE","sortPriority":1,"id":40917581,"name":"1. Sophia Palms"},{"status":"ACTIVE","sortPriority":2,"id":47148562,"name":"2. Under Siege"},{"status":"ACTIVE","sortPriority":3,"id":49546922,"name":"4. Uno Whiskey"},{"status":"ACTIVE","sortPriority":4,"id":70003372,"name":"5. Southern Sun"},{"status":"ACTIVE","sortPriority":5,"id":48638605,"name":"7. Lochinvar Aloisi"},{"status":"ACTIVE","sortPriority":6,"id":64343695,"name":"8. Punching Poncho"}],"regulators":["MR_INT"],"venue":"Murray Bridge","countryCode":"AU","discountAllowed":true,"timezone":"Australia/Adelaide","openDate":"2024-06-02T08:21:00.000Z","version":5962327457,"name":"To Be Placed","eventName":"Murray Bridge (AUS) 2nd Jun"},"rc":[],"con":true,"img":false}]}
{"op":"mcm","clk":"11448266886","pt":1717288003942,"mc":[{"id":"1.229554926","rc":[{"atb":[[1.37,94.17],[1.47,49.42]],"id":47148562},{"atl":[[4.3,0.15]],"id":47148562},{"spn":2.88,"spf":"NaN","id":47148562},{"atb":[[4.3,7.03],[3.65,13.14]],"id":64343695},{"spn":"Infinity","spf":"NaN","id":64343695},{"atb":[[2.58,22.05],[2.78,13.04]],"id":48638605},{"spn":"Infinity","spf":"NaN","id":48638605},{"atb":[[1.67,52],[1.77,30.16]],"id":49546922},{"atl":[[7,0.08]],"id":49546922},{"spn":4.38,"spf":"NaN","id":49546922},{"atb":[[1.01,3484.35],[1.02,1161.45]],"id":70003372},{"atl":[[2.82,0.28]],"id":70003372},{"spn":1.92,"spf":"NaN","id":70003372},{"atb":[[6.2,6.7],[8.2,3.22]],"id":40917581},{"spn":"Infinity","spf":"NaN","id":40917581}],"con":true,"img":false}]}
{"op":"mcm","clk":"11448270153","pt":1717288057431,"mc":[{"id":"1.229554926","rc":[{"atb":[[1.37,0],[1.47,0]],"id":47148562},{"atl":[[4.3,0]],"id":47148562},{"atb":[[4.3,0],[3.65,0]],"id":64343695},{"atb":[[2.58,0],[2.78,0]],"id":48638605},{"atb":[[1.67,0],[1.77,0]],"id":49546922},{"atl":[[7,0]],"id":49546922},{"atb":[[1.01,0],[1.02,0]],"id":70003372},{"atl":[[2.82,0]],"id":70003372},{"atb":[[6.2,0],[8.2,0]],"id":40917581}],"con":true,"img":false}]}
{"op":"mcm","clk":"11448270978","pt":1717288067734,"mc":[{"id":"1.229554926","rc":[{"atb":[[1.41,56.65],[1.31,112.39]],"id":47148562},{"atl":[[4.1,0.16]],"id":47148562},{"spn":2.75,"spf":"NaN","id":47148562},{"atb":[[4.3,7.03],[3.65,13.14]],"id":64343695},{"atb":[[2.58,22.05],[2.78,13.04]],"id":48638605},{"atb":[[1.8,29.03],[1.7,49.77]],"id":49546922},{"atl":[[7.2,0.08]],"id":49546922},{"spn":4.5,"spf":"NaN","id":49546922},{"atb":[[1.01,3484.35],[1.03,774.3]],"id":70003372},{"atl":[[2.84,0.28]],"id":70003372},{"spn":1.93,"spf":"NaN","id":70003372},{"atb":[[7.8,3.41],[5.9,7.1]],"id":40917581}],"con":true,"img":false}]}
{"op":"mcm","clk":"11448277249","pt":1717288128429,"mc":[{"id":"1.229554926","marketDefinition":{"bspMarket":true,"turnInPlayEnabled":false,"persistenceEnabled":false,"marketBaseRate":7.0,"eventId":"33318908","eventTypeId":"4339","numberOfWinners":2,"bettingType":"ODDS","marketType":"PLACE","marketTime":"2024-06-02T10:41:00.000Z","suspendTime":"2024-06-02T10:41:00.000Z","bspReconciled":false,"complete":true,"inPlay":false,"crossMatching":true,"runnersVoidable":false,"numberOfActiveRunners":6,"betDelay":0,"status":"OPEN","runners":[{"status":"ACTIVE","sortPriority":1,"id":40917581,"name":"1. Sophia Palms"},{"status":"ACTIVE","sortPriority":2,"id":47148562,"name":"2. Under Siege"},{"status":"ACTIVE","sortPriority":3,"id":49546922,"name":"4. Uno Whiskey"},{"status":"ACTIVE","sortPriority":4,"id":70003372,"name":"5. Southern Sun"},{"status":"ACTIVE","sortPriority":5,"id":48638605,"name":"7. Lochinvar Aloisi"},{"status":"ACTIVE","sortPriority":6,"id":64343695,"name":"8. Punching Poncho"}],"regulators":["MR_INT"],"venue":"Murray Bridge","countryCode":"AU","discountAllowed":true,"timezone":"Australia/Adelaide","openDate":"2024-06-02T08:21:00.000Z","version":5962327457,"name":"To Be Placed","eventName":"Murray Bridge (AUS) 2nd Jun"},"rc":[{"atb":[[1.41,56.65],[1.31,112.39]],"id":47148562},{"atl":[[4.1,0.16]],"id":47148562},{"spn":2.75,"spf":"NaN","id":47148562},{"atb":[[4.3,7.03],[3.65,13.14]],"id":64343695},{"spn":"Infinity","spf":"NaN","id":64343695},{"atb":[[2.58,22.05],[2.78,13.04]],"id":48638605},{"spn":"Infinity","spf":"NaN","id":48638605},{"atb":[[1.8,29.03],[1.7,49.77]],"id":49546922},{"atl":[[7.2,0.08]],"id":49546922},{"spn":4.5,"spf":"NaN","id":49546922},{"atb":[[1.01,3484.35],[1.03,774.3]],"id":70003372},{"atl":[[2.84,0.28]],"id":70003372},{"spn":1.93,"spf":"NaN","id":70003372},{"atb":[[7.8,3.41],[5.9,7.1]],"id":40917581},{"spn":"Infinity","spf":"NaN","id":40917581}],"con":true,"img":true}]}
{"op":"mcm","clk":"11448289496","pt":1717288232637,"mc":[{"id":"1.229554926","rc":[{"atb":[[4.3,0],[3.65,0]],"id":64343695},{"spn":"NaN","spf":"NaN","id":64343695},{"atb":[[2.58,0],[2.78,0]],"id":48638605},{"spn":"NaN","spf":"NaN","id":48638605},{"atb":[[7.8,0],[5.9,0]],"id":40917581},{"spn":"NaN","spf":"NaN","id":40917581}],"con":true,"img":false}]}
{"op":"mcm","clk":"11448290414","pt":1717288245743,"mc":[{"id":"1.229554926","rc":[{"atb":[[3.7,12.9],[4.4,6.83]],"id":64343695},{"atb":[[2.58,22.05],[2.78,13.04]],"id":48638605},{"atb":[[4.5,9.95],[5.5,5.16]],"id":40917581}],"con":true,"img":false}]}
{"op":"mcm","clk":"11448292488","pt":1717288274268,"mc":[{"id":"1.229554926","rc":[{"atb":[[1.41,0],[1.31,0]],"id":47148562},{"atl":[[4.1,0]],"id":47148562},{"atb":[[3.7,0],[4.4,0]],"id":64343695},{"atb":[[2.58,0],[2.78,0]],"id":48638605},{"atb":[[1.8,0],[1.7,0]],"id":49546922},{"atl":[[7.2,0]],"id":49546922},{"atb":[[1.01,0],[1.03,0]],"id":70003372},{"atl":[[2.84,0]],"id":70003372},{"atb":[[4.5,0],[5.5,0]],"id":40917581}],"con":true,"img":false}]}
{"op":"mcm","clk":"11448293813","pt":1717288291678,"mc":[{"id":"1.229554926","rc":[{"atb":[[1.46,50.49],[1.36,96.78]],"id":47148562},{"atl":[[4.3,0.15]],"id":47148562},{"atb":[[3.55,9.1],[3.05,16.99]],"id":64343695},{"atb":[[2.64,21.24],[2.84,12.62]],"id":48638605},{"atb":[[1.77,45.24],[1.87,26.69]],"id":49546922},{"atl":[[7.8,0.07]],"id":49546922},{"atb":[[1.01,3484.35],[1.05,464.58]],"id":70003372},{"atl":[[2.86,0.28]],"id":70003372},{"atb":[[4.5,9.95],[5.5,5.16]],"id":40917581}],"con":true,"img":false}]}
{"op":"mcm","clk":"11448298286","pt":1717288351588,"mc":[{"id":"1.229554926","rc":[{"atb":[[1.46,0],[1.36,0]],"id":47148562},{"atl":[[4.3,0]],"id":47148562},{"spn":"NaN","spf":"NaN","id":47148562},{"atb":[[3.55,0],[3.05,0]],"id":64343695},{"atb":[[2.64,0],[2.84,0]],"id":48638605},{"atb":[[1.77,0],[1.87,0]],"id":49546922},{"atl":[[7.8,0]],"id":49546922},{"spn":"NaN","spf":"NaN","id":49546922},{"atb":[[1.01,0],[1.05,0]],"id":70003372},{"atl":[[2.86,0]],"id":70003372},{"spn":"NaN","spf":"NaN","id":70003372},{"atb":[[4.5,0],[5.5,0]],"id":40917581}],"con":true,"img":false}]}
{"op":"mcm","clk":"11448300795","pt":1717288383947,"mc":[{"id":"1.229554926","rc":[{"atb":[[1.42,82.96],[1.52,44.66]],"id":47148562},{"atl":[[4.7,0.14]],"id":47148562},{"atb":[[3.15,16.2],[3.65,8.76]],"id":64343695},{"atb":[[2.58,22.05],[2.78,13.04]],"id":48638605},{"atb":[[1.82,28.33],[1.72,48.39]],"id":49546922},{"atl":[[7.4,0.08]],"id":49546922},{"atb":[[1.01,3484.35],[1.03,774.3]],"id":70003372},{"atl":[[2.84,0.28]],"id":70003372},{"atb":[[5.3,8.1],[6.6,4.14]],"id":40917581}],"con":true,"img":false}]}
{"op":"mcm","clk":"11448305326","pt":1717288449310,"mc":[{"id":"1.229554926","rc":[{"atb":[[1.42,0],[1.52,0]],"id":47148562},{"atl":[[4.7,0]],"id":47148562},{"atb":[[3.15,0],[3.65,0]],"id":64343695},{"atb":[[2.58,0],[2.78,0]],"id":48638605},{"atb":[[1.82,0],[1.72,0]],"id":49546922},{"atl":[[7.4,0]],"id":49546922},{"atb":[[1.01,0],[1.03,0]],"id":70003372},{"atl":[[2.84,0]],"id":70003372},{"atb":[[5.3,0],[6.6,0]],"id":40917581}],"con":true,"img":false}]}
{"op":"mcm","clk":"11448307458","pt":1717288481177,"mc":[{"id":"1.229554926","rc":[{"atb":[[1.6,38.71],[1.5,69.68]],"id":47148562},{"atl":[[5.6,0.11]],"id":47148562},{"atb":[[3.85,8.15],[3.35,14.82]],"id":64343695},{"atb":[[2.8,12.9],[2.6,21.77]],"id":48638605},{"atb":[[1.58,60.07],[1.68,34.15]],"id":49546922},{"atl":[[6.4,0.09]],"id":49546922},{"atb":[[1.01,3484.35],[1.08,290.36]],"id":70003372},{"atl":[[2.88,0.27]],"id":70003372},{"atb":[[6.4,4.3],[5.2,8.29]],"id":40917581}],"con":true,"img":false}]}
{"op":"mcm","clk":"11448310805","pt":1717288529482,"mc":[{"id":"1.229554926","rc":[{"spn":3.6,"spf":"NaN","id":47148562},{"atb":[[3.85,0],[3.35,0]],"id":64343695},{"spn":"Infinity","spf":"NaN","id":48638605},{"atb":[[1.58,0],[1.68,0]],"id":49546922},{"atl":[[6.4,0]],"id":49546922},{"atb":[[1.01,0],[1.08,0]],"id":70003372},{"atl":[[2.88,0]],"id":70003372},{"atb":[[6.4,0],[5.2,0]],"id":40917581}],"con":true,"img":false}]}
{"op":"mcm","clk":"11448312152","pt":1717288548667,"mc":[{"id":"1.229554926","rc":[{"atb":[[4,7.74],[3.5,13.93]],"id":64343695},{"atb":[[1.62,37.46],[1.52,67]],"id":49546922},{"atl":[[5.8,0.1]],"id":49546922},{"atb":[[1.01,3484.35],[1.09,258.09]],"id":70003372},{"atl":[[2.9,0.27]],"id":70003372},{"atb":[[5.5,7.74],[7,3.87]],"id":40917581}],"con":true,"img":false}]}
{"op":"mcm","clk":"11448330087","pt":1717288800135,"mc":[{"id":"1.229554926","rc":[{"atb":[[1.6,0],[1.5,0]],"id":47148562},{"atl":[[5.6,0]],"id":47148562},{"spn":"NaN","spf":"NaN","id":47148562},{"atb":[[4,0],[3.5,0]],"id":64343695},{"atb":[[1.62,0],[1.52,0]],"id":49546922},{"atl":[[5.8,0]],"id":49546922},{"spn":1.99,"spf":"NaN","id":70003372},{"spn":"Infinity","spf":"NaN","id":40917581}],"con":true,"img":false}]}
{"op":"mcm","clk":"11448330740","pt":1717288810059,"mc":[{"id":"1.229554926","rc":[{"atb":[[1.62,37.46],[1.52,67]],"id":47148562},{"atl":[[5.8,0.1]],"id":47148562},{"atb":[[3.6,13.4],[4.2,7.26]],"id":64343695},{"atb":[[1.59,39.36],[1.49,71.11]],"id":49546922},{"atl":[[5.5,0.11]],"id":49546922}],"con":true,"img":false}]}
{"op":"mcm","clk":"11448332054","pt":1717288831250,"mc":[{"id":"1.229554926","rc":[{"atb":[[1.62,0],[1.52,0]],"id":47148562},{"atl":[[5.8,0]],"id":47148562},{"atb":[[3.6,0],[4.2,0]],"id":64343695},{"atb":[[2.8,0],[2.6,0]],"id":48638605},{"atb":[[1.59,0],[1.49,0]],"id":49546922},{"atl":[[5.5,0]],"id":49546922},{"atb":[[1.01,0],[1.09,0]],"id":70003372},{"atl":[[2.9,0]],"id":70003372}],"con":true,"img":false}]}
{"op":"mcm","clk":"11448332531","pt":1717288838850,"mc":[{"id":"1.229554926","rc":[{"atb":[[1.63,36.87],[1.53,65.74]],"id":47148562},{"atl":[[5.9,0.1]],"id":47148562},{"atb":[[3.6,13.4],[4.2,7.26]],"id":64343695},{"atb":[[2.88,12.35],[2.68,20.73]],"id":48638605},{"atb":[[1.45,77.43],[1.55,42.23]],"id":49546922},{"atl":[[5,0.13]],"id":49546922},{"atb":[[1.01,3484.35],[1.08,290.36]],"id":70003372},{"atl":[[2.88,0.27]],"id":70003372}],"con":true,"img":false}]}
{"op":"mcm","clk":"11448333310","pt":1717288850467,"mc":[{"id":"1.229554926","rc":[{"atb":[[1.63,0],[1.53,0]],"id":47148562},{"atl":[[5.9,0]],"id":47148562},{"atb":[[3.6,0],[4.2,0]],"id":64343695},{"atb":[[2.88,0],[2.68,0]],"id":48638605},{"atb":[[1.45,0],[1.55,0]],"id":49546922},{"atl":[[5,0]],"id":49546922},{"atb":[[5.5,0],[7,0]],"id":40917581}],"con":true,"img":false}]}
{"op":"mcm","clk":"11448333846","pt":1717288858189,"mc":[{"id":"1.229554926","rc":[{"atb":[[1.51,68.32],[1.61,38.08]],"id":47148562},{"atl":[[5.7,0.1]],"id":47148562},{"atb":[[3.6,13.4],[4.2,7.26]],"id":64343695},{"atb":[[2.74,20.02],[2.94,11.97]],"id":48638605},{"atb":[[1.49,47.4],[1.39,89.34]],"id":49546922},{"atl":[[4.4,0.15]],"id":49546922},{"atb":[[6.4,6.45],[8.4,3.13]],"id":40917581}],"con":true,"img":false}]}
{"op":"mcm","clk":"11448336313","pt":1717288889878,"mc":[{"id":"1.229554926","rc":[{"atb":[[1.51,0],[1.61,0]],"id":47148562},{"atl":[[5.7,0]],"id":47148562},{"atb":[[3.6,0],[4.2,0]],"id":64343695},{"atb":[[2.74,0],[2.94,0]],"id":48638605},{"spn":"NaN","spf":"NaN","id":48638605},{"atb":[[1.49,0],[1.39,0]],"id":49546922},{"atl":[[4.4,0]],"id":49546922},{"spn":1.98,"spf":"NaN","id":70003372},{"atb":[[6.4,0],[8.4,0]],"id":40917581},{"spn":"NaN","spf":"NaN","id":40917581}],"con":true,"img":false}]}
{"op":"mcm","clk":"11448336545","pt":1717288892675,"mc":[{"id":"1.229554926","rc":[{"atb":[[1.63,36.87],[1.53,65.74]],"id":47148562},{"atl":[[5.9,0.1]],"id":47148562},{"atb":[[4.3,7.03],[3.65,13.14]],"id":64343695},{"atb":[[2.9,12.22],[2.7,20.49]],"id":48638605},{"atb":[[1.45,51.62],[1.35,99.55]],"id":49546922},{"atl":[[4.2,0.16]],"id":49546922},{"atb":[[6.2,6.7],[8.2,3.22]],"id":40917581}],"con":true,"img":false}]}
{"op":"mcm","clk":"11448344112","pt":1717288986613,"mc":[{"id":"1.229554926","rc":[{"atb":[[1.63,0],[1.53,0]],"id":47148562},{"atl":[[5.9,0]],"id":47148562},{"spn":"Infinity","spf":"NaN","id":64343695},{"spn":"Infinity","spf":"NaN","id":48638605},{"spn":2.82,"spf":"NaN","id":49546922},{"atb":[[1.01,0],[1.08,0]],"id":70003372},{"atl":[[2.88,0]],"id":70003372},{"spn":"NaN","spf":"NaN","id":70003372},{"spn":"Infinity","spf":"NaN","id":40917581}],"con":true,"img":false}]}
{"op":"mcm","clk":"11448345399","pt":1717289003637,"mc":[{"id":"1.229554926","rc":[{"atb":[[1.57,61.12],[1.67,34.67]],"id":47148562},{"atl":[[6.4,0.09]],"id":47148562},{"atb":[[1.01,3484.35],[1.09,258.09]],"id":70003372},{"atl":[[2.9,0.27]],"id":70003372}],"con":true,"img":false}]}
{"op":"mcm","clk":"11448350573","pt":1717289071605,"mc":[{"id":"1.229554926","rc":[{"spn":4.03,"spf":"NaN","id":47148562},{"atb":[[4.3,0],[3.65,0]],"id":64343695},{"spn":"NaN","spf":"NaN","id":64343695},{"atb":[[2.9,0],[2.7,0]],"id":48638605},{"spn":"NaN","spf":"NaN","id":48638605},{"atb":[[1.01,0],[1.09,0]],"id":70003372},{"atl":[[2.9,0]],"id":70003372}],"con":true,"img":false}]}
{"op":"mcm","clk":"11448351093","pt":1717289078691,"mc":[{"id":"1.229554926","rc":[{"atb":[[4.3,7.03],[3.65,13.14]],"id":64343695},{"atb":[[2.92,12.1],[2.72,20.25]],"id":48638605},{"atb":[[1.01,3484.35],[1.06,387.15]],"id":70003372},{"atl":[[2.86,0.28]],"id":70003372}],"con":true,"img":false}]}
{"op":"mcm","clk":"11448355207","pt":1717289130591,"mc":[{"id":"1.229554926","rc":[{"atb":[[4.3,0],[3.65,0]],"id":64343695},{"atb":[[2.92,0],[2.72,0]],"id":48638605},{"atb":[[6.2,0],[8.2,0]],"id":40917581}],"con":true,"img":false}]}
{"op":"mcm","clk":"11448355883","pt":1717289139416,"mc":[{"id":"1.229554926","rc":[{"atb":[[3.7,12.9],[4.4,6.83]],"id":64343695},{"spn":"Infinity","spf":"NaN","id":64343695},{"atb":[[2.74,20.02],[2.94,11.97]],"id":48638605},{"spn":"Infinity","spf":"NaN","id":48638605},{"spn":1.96,"spf":"NaN","id":70003372},{"atb":[[7.8,3.41],[5.9,7.1]],"id":40917581}],"con":true,"img":false}]}
{"op":"mcm","clk":"11448357429","pt":1717289159719,"mc":[{"id":"1.229554926","rc":[{"atb":[[7.8,0],[5.9,0]],"id":40917581}],"con":true,"img":false}]}
{"op":"mcm","clk":"11448357912","pt":1717289165668,"mc":[{"id":"1.229554926","rc":[{"atb":[[7.2,5.61],[9.2,2.83]],"id":40917581}],"con":true,"img":false}]}
{"op":"mcm","clk":"11448516312","pt":1717291543831,"mc":[{"id":"1.229554926","rc":[{"atb":[[1.57,0],[1.67,0]],"id":47148562},{"atl":[[6.4,0]],"id":47148562},{"spn":"NaN","spf":"NaN","id":47148562},{"atb":[[3.7,0],[4.4,0]],"id":64343695},{"spn":"NaN","spf":"NaN","id":64343695},{"atb":[[2.74,0],[2.94,0]],"id":48638605},{"spn":"NaN","spf":"NaN","id":48638605},{"atb":[[1.45,0],[1.35,0]],"id":49546922},{"atl":[[4.2,0]],"id":49546922},{"spn":"NaN","spf":"NaN","id":49546922},{"atb":[[1.01,0],[1.06,0]],"id":70003372},{"atl":[[2.86,0]],"id":70003372},{"spn":"NaN","spf":"NaN","id":70003372},{"atb":[[7.2,0],[9.2,0]],"id":40917581},{"spn":"NaN","spf":"NaN","id":40917581}],"con":true,"img":false}]}
{"op":"mcm","clk":"11448516748","pt":1717291550972,"mc":[{"id":"1.229554926","rc":[{"atb":[[1.56,62.22],[1.66,35.19]],"id":47148562},{"atl":[[6.2,0.09]],"id":47148562},{"atb":[[3.6,13.4],[4.2,7.26]],"id":64343695},{"atb":[[2.82,19.14],[3.05,11.33]],"id":48638605},{"atb":[[1.37,94.17],[1.47,49.42]],"id":49546922},{"atl":[[4.3,0.15]],"id":49546922},{"atb":[[1.01,3484.35],[1.02,1161.45]],"id":70003372},{"atl":[[2.82,0.28]],"id":70003372},{"atb":[[8.6,3.05],[6.6,6.22]],"id":40917581}],"con":true,"img":false}]}
{"op":"mcm","clk":"11448517449","pt":1717291562388,"mc":[{"id":"1.229554926","rc":[{"atb":[[1.56,0],[1.66,0]],"id":47148562},{"atl":[[6.2,0]],"id":47148562},{"atb":[[3.6,0],[4.2,0]],"id":64343695},{"atb":[[1.37,0],[1.47,0]],"id":49546922},{"atl":[[4.3,0]],"id":49546922},{"atb":[[1.01,0],[1.02,0]],"id":70003372},{"atl":[[2.82,0]],"id":70003372},{"atb":[[8.6,0],[6.6,0]],"id":40917581}],"con":true,"img":false}]}
{"op":"mcm","clk":"11448517838","pt":1717291568298,"mc":[{"id":"1.229554926","rc":[{"atb":[[1.57,61.12],[1.67,34.67]],"id":47148562},{"atl":[[6.4,0.09]],"id":47148562},{"atb":[[4.3,7.03],[3.65,13.14]],"id":64343695},{"atb":[[1.46,50.49],[1.36,96.78]],"id":49546922},{"atl":[[4.3,0.15]],"id":49546922},{"atb":[[1.01,3484.35],[1.04,580.72]],"id":70003372},{"atl":[[2.84,0.28]],"id":70003372},{"atb":[[6.8,6],[8.8,2.97]],"id":40917581}],"con":true,"img":false}]}
{"op":"mcm","clk":"11448521432","pt":1717291630165,"mc":[{"id":"1.229554926","rc":[{"spn":4.03,"spf":"NaN","id":47148562},{"atb":[[4.3,0],[3.65,0]],"id":64343695},{"atb":[[2.82,0],[3.05,0]],"id":48638605},{"spn":2.88,"spf":"NaN","id":49546922},{"spn":1.94,"spf":"NaN","id":70003372},{"atb":[[6.8,0],[8.8,0]],"id":40917581}],"con":true,"img":false}]}
{"op":"mcm","clk":"11448521774","pt":1717291635884,"mc":[{"id":"1.229554926","rc":[{"atb":[[4.3,7.03],[3.65,13.14]],"id":64343695},{"atb":[[2.96,11.84],[2.76,19.79]],"id":48638605},{"atb":[[9,2.9],[7,5.8]],"id":40917581}],"con":true,"img":false}]}
{"op":"mcm","clk":"11448522288","pt":1717291645993,"mc":[{"id":"1.229554926","rc":[{"atb":[[1.57,0],[1.67,0]],"id":47148562},{"atl":[[6.4,0]],"id":47148562},{"atb":[[2.96,0],[2.76,0]],"id":48638605},{"atb":[[1.46,0],[1.36,0]],"id":49546922},{"atl":[[4.3,0]],"id":49546922}],"con":true,"img":false}]}
{"op":"mcm","clk":"11448522564","pt":1717291651915,"mc":[{"id":"1.229554926","rc":[{"atb":[[1.6,58.07],[1.7,33.18]],"id":47148562},{"atl":[[6.6,0.09]],"id":47148562},{"atb":[[2.8,19.35],[3,11.61]],"id":48638605},{"atb":[[1.32,108.88],[1.42,55.3]],"id":49546922},{"atl":[[4.1,0.16]],"id":49546922}],"con":true,"img":false}]}
{"op":"mcm","clk":"11448523124","pt":1717291661917,"mc":[{"id":"1.229554926","rc":[{"atb":[[1.6,0],[1.7,0]],"id":47148562},{"atl":[[6.6,0]],"id":47148562},{"atb":[[4.3,0],[3.65,0]],"id":64343695},{"atb":[[2.8,0],[3,0]],"id":48638605},{"atb":[[1.32,0],[1.42,0]],"id":49546922},{"atl":[[4.1,0]],"id":49546922},{"atb":[[1.01,0],[1.04,0]],"id":70003372},{"atl":[[2.84,0]],"id":70003372},{"atb":[[9,0],[7,0]],"id":40917581}],"con":true,"img":false}]}
{"op":"mcm","clk":"11448523428","pt":1717291667331,"mc":[{"id":"1.229554926","rc":[{"atb":[[1.59,59.05],[1.69,33.66]],"id":47148562},{"atl":[[6.6,0.09]],"id":47148562},{"atb":[[4.5,6.63],[3.75,12.67]],"id":64343695},{"atb":[[2.82,19.14],[3.05,11.33]],"id":48638605},{"atb":[[1.29,120.15],[1.39,59.56]],"id":49546922},{"atl":[[3.95,0.17]],"id":49546922},{"atb":[[1.01,3484.35],[1.02,1161.45]],"id":70003372},{"atl":[[2.82,0.28]],"id":70003372},{"atb":[[8.6,3.05],[6.6,6.22]],"id":40917581}],"con":true,"img":false}]}
{"op":"mcm","clk":"11448527341","pt":1717291733198,"mc":[{"id":"1.229554926","rc":[{"atb":[[1.59,0],[1.69,0]],"id":47148562},{"atl":[[6.6,0]],"id":47148562},{"spn":"NaN","spf":"NaN","id":47148562},{"atb":[[4.5,0],[3.75,0]],"id":64343695},{"spn":"Infinity","spf":"NaN","id":48638605},{"atb":[[1.29,0],[1.39,0]],"id":49546922},{"atl":[[3.95,0]],"id":49546922},{"spn":"NaN","spf":"NaN","id":49546922},{"atb":[[1.01,0],[1.02,0]],"id":70003372},{"atl":[[2.82,0]],"id":70003372},{"spn":"NaN","spf":"NaN","id":70003372},{"atb":[[8.6,0],[6.6,0]],"id":40917581}],"con":true,"img":false}]}
{"op":"mcm","clk":"11448527774","pt":1717291740829,"mc":[{"id":"1.229554926","rc":[{"atb":[[1.57,61.12],[1.67,34.67]],"id":47148562},{"atl":[[6.4,0.09]],"id":47148562},{"atb":[[4.3,7.03],[3.65,13.14]],"id":64343695},{"atb":[[1.43,54.02],[1.33,105.58]],"id":49546922},{"atl":[[4.1,0.16]],"id":49546922},{"atb":[[1.01,3484.35],[1.02,1161.45]],"id":70003372},{"atl":[[2.82,0.28]],"id":70003372},{"atb":[[9,2.9],[7,5.8]],"id":40917581}],"con":true,"img":false}]}
{"op":"mcm","clk":"11448528407","pt":1717291751125,"mc":[{"id":"1.229554926","rc":[{"atb":[[1.57,0],[1.67,0]],"id":47148562},{"atl":[[6.4,0]],"id":47148562},{"atb":[[4.3,0],[3.65,0]],"id":64343695},{"atb":[[2.82,0],[3.05,0]],"id":48638605},{"atb":[[1.43,0],[1.33,0]],"id":49546922},{"atl":[[4.1,0]],"id":49546922},{"atb":[[1.01,0],[1.02,0]],"id":70003372},{"atl":[[2.82,0]],"id":70003372},{"atb":[[9,0],[7,0]],"id":40917581}],"con":true,"img":false}]}
{"op":"mcm","clk":"11448528848","pt":1717291758052,"mc":[{"id":"1.229554926","rc":[{"atb":[[1.71,32.71],[1.61,57.12]],"id":47148562},{"atl":[[6.6,0.09]],"id":47148562},{"atb":[[4.6,6.45],[3.8,12.44]],"id":64343695},{"atb":[[2.98,11.72],[2.78,19.57]],"id":48638605},{"atb":[[1.32,108.88],[1.42,55.3]],"id":49546922},{"atl":[[4.1,0.16]],"id":49546922},{"atb":[[1.01,5807.26]],"id":70003372},{"atl":[[2.8,0.29]],"id":70003372},{"atb":[[9,2.9],[7,5.8]],"id":40917581}],"con":true,"img":false}]}
{"op":"mcm","clk":"11448629983","pt":1717293528420,"mc":[{"id":"1.229554926","marketDefinition":{"bspMarket":true,"turnInPlayEnabled":false,"persistenceEnabled":false,"marketBaseRate":7.0,"eventId":"33318908","eventTypeId":"4339","numberOfWinners":2,"bettingType":"ODDS","marketType":"PLACE","marketTime":"2024-06-02T10:41:00.000Z","suspendTime":"2024-06-02T10:41:00.000Z","bspReconciled":false,"complete":true,"inPlay":false,"crossMatching":true,"runnersVoidable":false,"numberOfActiveRunners":6,"betDelay":0,"status":"OPEN","runners":[{"status":"ACTIVE","sortPriority":1,"id":40917581,"name":"1. Sophia Palms"},{"status":"ACTIVE","sortPriority":2,"id":47148562,"name":"2. Under Siege"},{"status":"ACTIVE","sortPriority":3,"id":49546922,"name":"4. Uno Whiskey"},{"status":"ACTIVE","sortPriority":4,"id":70003372,"name":"5. Southern Sun"},{"status":"ACTIVE","sortPriority":5,"id":48638605,"name":"7. Lochinvar Aloisi"},{"status":"ACTIVE","sortPriority":6,"id":64343695,"name":"8. Punching Poncho"}],"regulators":["MR_INT"],"venue":"Murray Bridge","countryCode":"AU","discountAllowed":true,"timezone":"Australia/Adelaide","openDate":"2024-06-02T08:21:00.000Z","version":5962327457,"name":"To Be Placed","eventName":"Murray Bridge (AUS) 2nd Jun"},"rc":[{"atb":[[1.71,32.71],[1.61,57.12]],"id":47148562},{"atl":[[6.6,0.09]],"id":47148562},{"spn":4.15,"spf":"NaN","id":47148562},{"atb":[[4.6,6.45],[3.8,12.44]],"id":64343695},{"spn":"Infinity","spf":"NaN","id":64343695},{"atb":[[2.98,11.72],[2.78,19.57]],"id":48638605},{"spn":"Infinity","spf":"NaN","id":48638605},{"atb":[[1.32,108.88],[1.42,55.3]],"id":49546922},{"atl":[[4.1,0.16]],"id":49546922},{"spn":2.76,"spf":"NaN","id":49546922},{"atb":[[1.01,5807.26]],"id":70003372},{"atl":[[2.8,0.29]],"id":70003372},{"spn":1.9,"spf":"NaN","id":70003372},{"atb":[[9,2.9],[7,5.8]],"id":40917581},{"spn":"Infinity","spf":"NaN","id":40917581}],"con":true,"img":true}]}
{"op":"mcm","clk":"11449586833","pt":1717311445615,"mc":[{"id":"1.229554926","rc":[{"atb":[[1.01,17.35]],"id":47148562},{"atl":[[1000,0.85]],"id":47148562},{"spn":4.15,"spf":"NaN","id":47148562},{"atb":[[1.01,17.35]],"id":64343695},{"atl":[[1000,0.85]],"id":64343695},{"spn":502.3,"spf":"NaN","id":64343695},{"atb":[[1.01,17.35]],"id":48638605},{"atl":[[1000,0.85]],"id":48638605},{"spn":501.49,"spf":"NaN","id":48638605},{"atb":[[1.03,5.78]],"id":49546922},{"atl":[[990,0.85]],"id":49546922},{"spn":2.76,"spf":"NaN","id":49546922},{"atb":[[1.02,8.67]],"id":70003372},{"atl":[[990,0.85]],"id":70003372},{"spn":1.91,"spf":"NaN","id":70003372},{"atb":[[1.02,8.67]],"id":40917581},{"atl":[[990,0.85]],"id":40917581},{"spn":499.5,"spf":"NaN","id":40917581}],"con":true,"img":false}]}
{"op":"mcm","clk":"11449741833","pt":1717314153599,"mc":[{"id":"1.229554926","rc":[{"atb":[[1.71,0],[1.61,0]],"id":47148562},{"atl":[[6.6,0]],"id":47148562},{"spn":500.5,"spf":"NaN","id":47148562},{"atb":[[4.6,0],[3.8,0]],"id":64343695},{"spn":500.5,"spf":"NaN","id":64343695},{"atb":[[2.98,0],[2.78,0]],"id":48638605},{"spn":500.5,"spf":"NaN","id":48638605},{"atb":[[1.32,0],[1.42,0]],"id":49546922},{"atl":[[4.1,0]],"id":49546922},{"spn":495.51,"spf":"NaN","id":49546922},{"atb":[[1.01,0]],"id":70003372},{"atl":[[2.8,0]],"id":70003372},{"spn":495.51,"spf":"NaN","id":70003372},{"atb":[[9,0],[7,0]],"id":40917581},{"spn":495.51,"spf":"NaN","id":40917581}],"con":true,"img":false}]}
{"op":"mcm","clk":"11449742651","pt":1717314163984,"mc":[{"id":"1.229554926","rc":[{"atb":[[1.6,58.07],[1.7,33.18]],"id":47148562},{"atl":[[6.6,0.09]],"id":47148562},{"atb":[[4.5,6.63],[3.75,12.67]],"id":64343695},{"atb":[[2.98,11.72],[2.78,19.57]],"id":48638605},{"atb":[[1.32,108.88],[1.42,55.3]],"id":49546922},{"atl":[[4.1,0.16]],"id":49546922},{"atb":[[1.01,3484.35],[1.02,1170.12]],"id":70003372},{"atl":[[2.82,0.28]],"id":70003372},{"atb":[[6.4,6.45],[8.4,3.13]],"id":40917581}],"con":true,"img":false}]}
{"op":"mcm","clk":"11449756789","pt":1717314321017,"mc":[{"id":"1.229554926","rc":[{"spn":4.15,"spf":"NaN","id":47148562},{"atb":[[4.5,0],[3.75,0]],"id":64343695},{"atb":[[2.98,0],[2.78,0]],"id":48638605},{"spn":2.76,"spf":"NaN","id":49546922},{"spn":1.92,"spf":"NaN","id":70003372},{"spn":499.2,"spf":"NaN","id":40917581}],"con":true,"img":false}]}
{"op":"mcm","clk":"11449757847","pt":1717314333535,"mc":[{"id":"1.229554926","rc":[{"atb":[[4.6,6.45],[3.8,12.44]],"id":64343695},{"atb":[[3.1,11.05],[2.84,18.93]],"id":48638605}],"con":true,"img":false}]}
{"op":"mcm","clk":"11449759684","pt":1717314355289,"mc":[{"id":"1.229554926","rc":[{"atb":[[4.6,0],[3.8,0]],"id":64343695},{"atb":[[3.1,0],[2.84,0]],"id":48638605}],"con":true,"img":false}]}
{"op":"mcm","clk":"11449760259","pt":1717314361964,"mc":[{"id":"1.229554926","rc":[{"atb":[[3.85,12.22],[4.7,6.27]],"id":64343695},{"atb":[[2.82,19.14],[3.05,11.33]],"id":48638605}],"con":true,"img":false}]}
{"op":"mcm","clk":"11449830319","pt":1717315128436,"mc":[{"id":"1.229554926","marketDefinition":{"bspMarket":true,"turnInPlayEnabled":false,"persistenceEnabled":false,"marketBaseRate":7.0,"eventId":"33318908","eventTypeId":"4339","numberOfWinners":2,"bettingType":"ODDS","marketType":"PLACE","marketTime":"2024-06-02T10:41:00.000Z","suspendTime":"2024-06-02T10:41:00.000Z","bspReconciled":false,"complete":true,"inPlay":false,"crossMatching":true,"runnersVoidable":false,"numberOfActiveRunners":6,"betDelay":0,"status":"OPEN","runners":[{"status":"ACTIVE","sortPriority":1,"id":40917581,"name":"1. Sophia Palms"},{"status":"ACTIVE","sortPriority":2,"id":47148562,"name":"2. Under Siege"},{"status":"ACTIVE","sortPriority":3,"id":49546922,"name":"4. Uno Whiskey"},{"status":"ACTIVE","sortPriority":4,"id":70003372,"name":"5. Southern Sun"},{"status":"ACTIVE","sortPriority":5,"id":48638605,"name":"7. Lochinvar Aloisi"},{"status":"ACTIVE","sortPriority":6,"id":64343695,"name":"8. Punching Poncho"}],"regulators":["MR_INT"],"venue":"Murray Bridge","countryCode":"AU","discountAllowed":true,"timezone":"Australia/Adelaide","openDate":"2024-06-02T08:21:00.000Z","version":5962327457,"name":"To Be Placed","eventName":"Murray Bridge (AUS) 2nd Jun"},"rc":[{"atb":[[1.6,58.07],[1.01,17.35],[1.7,33.18]],"id":47148562},{"atl":[[6.6,0.09],[1000,0.85]],"id":47148562},{"spn":4.15,"spf":"NaN","id":47148562},{"atb":[[3.85,12.22],[1.01,17.35],[4.7,6.27]],"id":64343695},{"atl":[[1000,0.85]],"id":64343695},{"spn":502.35,"spf":"NaN","id":64343695},{"atb":[[2.82,19.14],[1.01,17.35],[3.05,11.33]],"id":48638605},{"atl":[[1000,0.85]],"id":48638605},{"spn":501.52,"spf":"NaN","id":48638605},{"atb":[[1.03,5.78],[1.32,108.88],[1.42,55.3]],"id":49546922},{"atl":[[4.1,0.16],[990,0.85]],"id":49546922},{"spn":2.76,"spf":"NaN","id":49546922},{"atb":[[1.01,3484.35],[1.02,1170.12]],"id":70003372},{"atl":[[2.82,0.28],[990,0.85]],"id":70003372},{"spn":1.92,"spf":"NaN","id":70003372},{"atb":[[6.4,6.45],[1.02,8.67],[8.4,3.13]],"id":40917581},{"atl":[[990,0.85]],"id":40917581},{"spn":499.2,"spf":"NaN","id":40917581}],"con":true,"img":true}]}
{"op":"mcm","clk":"11449851287","pt":1717315296619,"mc":[{"id":"1.229554926","rc":[{"atb":[[1.6,0],[1.7,0]],"id":47148562},{"atl":[[6.6,0]],"id":47148562},{"spn":500.5,"spf":"NaN","id":47148562},{"atb":[[3.85,0],[4.7,0]],"id":64343695},{"atb":[[2.82,0],[3.05,0]],"id":48638605},{"atb":[[1.32,0],[1.42,0]],"id":49546922},{"atl":[[4.1,0]],"id":49546922},{"spn":495.51,"spf":"NaN","id":49546922},{"atb":[[1.01,0],[1.02,8.67]],"id":70003372},{"atl":[[2.82,0]],"id":70003372},{"spn":495.51,"spf":"NaN","id":70003372},{"atb":[[6.4,0],[8.4,0]],"id":40917581},{"spn":495.51,"spf":"NaN","id":40917581}],"con":true,"img":false}]}
{"op":"mcm","clk":"11449853607","pt":1717315320659,"mc":[{"id":"1.229554926","rc":[{"atb":[[1.6,58.07],[1.7,33.18]],"id":47148562},{"atl":[[6.6,0.09]],"id":47148562},{"atb":[[4.6,6.45],[3.8,12.44]],"id":64343695},{"atb":[[2.8,19.35],[3,11.61]],"id":48638605},{"atb":[[1.41,56.65],[1.31,112.39]],"id":49546922},{"atl":[[4.1,0.16]],"id":49546922},{"atb":[[1.01,5807.26]],"id":70003372},{"atl":[[2.78,0.29]],"id":70003372},{"atb":[[9.6,2.69],[7.6,5.27]],"id":40917581}],"con":true,"img":false}]}
{"op":"mcm","clk":"11449893722","pt":1717315713296,"mc":[{"id":"1.229554926","rc":[{"atb":[[1.6,0],[1.7,0]],"id":47148562},{"atl":[[6.6,0]],"id":47148562},{"atb":[[4.6,0],[3.8,0]],"id":64343695},{"spn":501.5,"spf":"NaN","id":48638605},{"atb":[[1.41,0],[1.31,0]],"id":49546922},{"atl":[[4.1,0]],"id":49546922},{"spn":1.9,"spf":"NaN","id":70003372},{"atb":[[9.6,0],[7.6,0]],"id":40917581}],"con":true,"img":false}]}
{"op":"mcm","clk":"11449896899","pt":1717315742980,"mc":[{"id":"1.229554926","rc":[{"atb":[[1.58,60.07],[1.68,34.15]],"id":47148562},{"atl":[[6.4,0.09]],"id":47148562},{"atb":[[3.85,12.22],[4.7,6.27]],"id":64343695},{"atb":[[1.4,58.07],[1.3,116.14]],"id":49546922},{"atl":[[4,0.17]],"id":49546922},{"atb":[[9,2.9],[7,5.8]],"id":40917581}],"con":true,"img":false}]}
{"op":"mcm","clk":"11449959202","pt":1717316398378,"mc":[{"id":"1.229554926","rc":[{"atb":[[1.58,0],[1.68,0]],"id":47148562},{"atl":[[6.4,0]],"id":47148562},{"atb":[[3.85,0],[4.7,0]],"id":64343695},{"atb":[[2.8,0],[3,0]],"id":48638605},{"spn":500.5,"spf":"NaN","id":48638605},{"atb":[[1.4,0],[1.3,0]],"id":49546922},{"atl":[[4,0]],"id":49546922},{"atb":[[1.01,0]],"id":70003372},{"atl":[[2.78,0]],"id":70003372},{"spn":495.51,"spf":"NaN","id":70003372},{"atb":[[9,0],[7,0]],"id":40917581}],"con":true,"img":false}]}
{"op":"mcm","clk":"11449960619","pt":1717316415047,"mc":[{"id":"1.229554926","rc":[{"atb":[[1.58,60.07],[1.68,34.15]],"id":47148562},{"atl":[[6.4,0.09]],"id":47148562},{"atb":[[4.6,6.45],[3.8,12.44]],"id":64343695},{"atb":[[2.82,19.14],[3.05,11.33]],"id":48638605},{"atb":[[1.4,58.07],[1.3,116.14]],"id":49546922},{"atl":[[4,0.17]],"id":49546922},{"atb":[[1.01,3484.35],[1.02,1170.12]],"id":70003372},{"atl":[[2.82,0.28]],"id":70003372},{"atb":[[6.8,6],[8.8,2.97]],"id":40917581}],"con":true,"img":false}]}
{"op":"mcm","clk":"11450057427","pt":1717317526522,"mc":[{"id":"1.229554926","rc":[{"atb":[[1.58,0],[1.68,0]],"id":47148562},{"atl":[[6.4,0]],"id":47148562},{"atb":[[4.6,0],[3.8,0]],"id":64343695},{"atb":[[2.82,0],[3.05,0]],"id":48638605},{"atb":[[1.4,0],[1.3,0]],"id":49546922},{"atl":[[4,0]],"id":49546922},{"atb":[[1.01,0],[1.02,8.67]],"id":70003372},{"atl":[[2.82,0]],"id":70003372},{"atb":[[6.8,0],[8.8,0]],"id":40917581}],"con":true,"img":false}]}
{"op":"mcm","clk":"11450059564","pt":1717317550136,"mc":[{"id":"1.229554926","rc":[{"atb":[[1.55,63.35],[1.65,35.73]],"id":47148562},{"atl":[[6.2,0.09]],"id":47148562},{"atb":[[4.5,6.63],[3.75,12.67]],"id":64343695},{"atb":[[2.82,19.14],[3.05,11.33]],"id":48638605},{"atb":[[1.43,54.02],[1.33,105.58]],"id":49546922},{"atl":[[4.1,0.16]],"id":49546922},{"atb":[[1.01,3484.35],[1.03,774.3]],"id":70003372},{"atl":[[2.84,0.28]],"id":70003372},{"atb":[[8.6,3.05],[6.6,6.22]],"id":40917581}],"con":true,"img":false}]}
{"op":"mcm","clk":"11450133810","pt":1717318390008,"mc":[{"id":"1.229554926","rc":[{"atb":[[1.55,0],[1.65,0]],"id":47148562},{"atl":[[6.2,0]],"id":47148562},{"atb":[[4.5,0],[3.75,0]],"id":64343695},{"atb":[[2.82,0],[3.05,0]],"id":48638605},{"atb":[[1.43,0],[1.33,0]],"id":49546922},{"atl":[[4.1,0]],"id":49546922},{"atb":[[1.01,0],[1.03,0]],"id":70003372},{"atl":[[2.84,0]],"id":70003372},{"atb":[[8.6,0],[6.6,0]],"id":40917581}],"con":true,"img":false}]}
{"op":"mcm","clk":"11450134730","pt":1717318401243,"mc":[{"id":"1.229554926","rc":[{"atb":[[1.56,62.22],[1.66,35.19]],"id":47148562},{"atl":[[6.2,0.09]],"id":47148562},{"atb":[[4.6,6.45],[3.8,12.44]],"id":64343695},{"atb":[[2.82,19.14],[3.05,11.33]],"id":48638605},{"atb":[[1.44,52.79],[1.34,102.47]],"id":49546922},{"atl":[[4.2,0.16]],"id":49546922},{"atb":[[1.01,5807.26]],"id":70003372},{"atl":[[2.82,0.28]],"id":70003372},{"atb":[[6.8,6],[8.8,2.97]],"id":40917581}],"con":true,"img":false}]}
{"op":"mcm","clk":"11450155581","pt":1717318632869,"mc":[{"id":"1.229554926","rc":[{"atl":[[1000,0.17]],"id":47148562},{"spn":3.93,"spf":"NaN","id":47148562},{"atl":[[1000,0.17]],"id":64343695},{"spn":502.3,"spf":"NaN","id":64343695},{"atl":[[1000,0.17]],"id":48638605},{"spn":501.52,"spf":"NaN","id":48638605},{"atl":[[990,0.17]],"id":49546922},{"spn":2.82,"spf":"NaN","id":49546922},{"atl":[[990,0.17]],"id":70003372},{"spn":1.92,"spf":"NaN","id":70003372},{"atl":[[990,0.17]],"id":40917581},{"spn":499.4,"spf":"NaN","id":40917581}],"con":true,"img":false}]}
{"op":"mcm","clk":"11450214744","pt":1717319245580,"mc":[{"id":"1.229554926","rc":[{"atb":[[1.56,0],[1.66,0]],"id":47148562},{"atl":[[6.2,0]],"id":47148562},{"spn":500.5,"spf":"NaN","id":47148562},{"atb":[[4.6,0],[3.8,0]],"id":64343695},{"spn":500.5,"spf":"NaN","id":64343695},{"atb":[[2.82,0],[3.05,0]],"id":48638605},{"spn":500.5,"spf":"NaN","id":48638605},{"atb":[[1.44,0],[1.34,0]],"id":49546922},{"atl":[[4.2,0]],"id":49546922},{"spn":495.51,"spf":"NaN","id":49546922},{"atb":[[1.01,0]],"id":70003372},{"atl":[[2.82,0]],"id":70003372},{"spn":495.51,"spf":"NaN","id":70003372},{"atb":[[6.8,0],[8.8,0]],"id":40917581},{"spn":495.51,"spf":"NaN","id":40917581}],"con":true,"img":false}]}
{"op":"mcm","clk":"11450217182","pt":1717319268291,"mc":[{"id":"1.229554926","rc":[{"atb":[[1.59,59.05],[1.69,33.66]],"id":47148562},{"atl":[[6.6,0.09]],"id":47148562},{"atb":[[3.85,12.22],[4.7,6.27]],"id":64343695},{"atb":[[3.2,10.55],[2.88,18.53]],"id":48638605},{"atb":[[1.27,129.05],[1.37,62.78]],"id":49546922},{"atl":[[3.85,0.18]],"id":49546922},{"atb":[[1.01,5807.26]],"id":70003372},{"atl":[[2.8,0.29]],"id":70003372},{"atb":[[6.8,6],[8.8,2.97]],"id":40917581}],"con":true,"img":false}]}
{"op":"mcm","clk":"11450241502","pt":1717319529809,"mc":[{"id":"1.229554926","rc":[{"atb":[[1.41,40.83],[1.31,193.05]],"id":47148562},{"atl":[[9.2,7.32],[8.2,5.81]],"id":47148562},{"spn":4.14,"spf":"NaN","id":47148562},{"atb":[[4.1,13.5],[3.55,20.92]],"id":64343695},{"atl":[[65,5.23]],"id":64343695},{"spn":34.85,"spf":"NaN","id":64343695},{"atb":[[2.9,22.03],[2.28,45.26]],"id":48638605},{"atl":[[32,2.61],[34,2.61]],"id":48638605},{"spn":17.6,"spf":"NaN","id":48638605},{"atb":[[1.28,197.59],[1.38,44.05]],"id":49546922},{"atl":[[7,6.97],[7.8,8.13]],"id":49546922},{"spn":2.61,"spf":"NaN","id":49546922},{"atb":[[1.12,517.94],[1.14,114.64]],"id":70003372},{"atl":[[4.6,17.26],[4.1,13.5]],"id":70003372},{"spn":1.97,"spf":"NaN","id":70003372},{"atb":[[10.5,4.4],[8.8,10.32]],"id":40917581},{"atl":[[290,0.14],[330,2.61]],"id":40917581},{"spn":150.25,"spf":"NaN","id":40917581}],"con":true,"img":false}]}
{"op":"mcm","clk":"11450245611","pt":1717319573807,"mc":[{"id":"1.229554926","rc":[{"atb":[[10.5,0]],"id":40917581}],"con":true,"img":false}]}
{"op":"mcm","clk":"11450245623","pt":1717319573909,"mc":[{"id":"1.229554926","rc":[{"atb":[[13.5,4.4]],"id":40917581}],"con":true,"img":false}]}
{"op":"mcm","clk":"11450255005","pt":1717319679915,"mc":[{"id":"1.229554926","rc":[{"atb":[[3.55,0]],"id":64343695},{"spn":151.75,"spf":"NaN","id":40917581}],"con":true,"img":false}]}
{"op":"mcm","clk":"11450255012","pt":1717319680018,"mc":[{"id":"1.229554926","rc":[{"atb":[[3.9,20.92]],"id":64343695}],"con":true,"img":false}]}
{"op":"mcm","clk":"11450262485","pt":1717319762333,"mc":[{"id":"1.229554926","rc":[{"atb":[[11.5,5.45],[8.8,2.97]],"id":40917581}],"con":true,"img":false}]}
{"op":"mcm","clk":"11450286930","pt":1717320072780,"mc":[{"id":"1.229554926","rc":[{"atb":[[1.59,0],[1.69,0]],"id":47148562},{"atl":[[6.6,0]],"id":47148562},{"spn":4.8,"spf":"NaN","id":47148562},{"atb":[[3.85,0],[4.7,0]],"id":64343695},{"spn":34.55,"spf":"NaN","id":64343695},{"atb":[[3.2,0],[2.88,0]],"id":48638605},{"spn":17.45,"spf":"NaN","id":48638605},{"atb":[[1.27,0],[1.37,0]],"id":49546922},{"atl":[[3.85,0]],"id":49546922},{"spn":4.19,"spf":"NaN","id":49546922},{"atb":[[1.01,0]],"id":70003372},{"atl":[[2.8,0]],"id":70003372},{"spn":2.62,"spf":"NaN","id":70003372},{"atb":[[6.8,0],[8.8,0]],"id":40917581}],"con":true,"img":false}]}
{"op":"mcm","clk":"11450287440","pt":1717320079380,"mc":[{"id":"1.229554926","rc":[{"atb":[[3.9,0]],"id":64343695},{"atb":[[2.9,0]],"id":48638605},{"atb":[[1.38,0]],"id":49546922}],"con":true,"img":false}]}
{"op":"mcm","clk":"11450287446","pt":1717320079477,"mc":[{"id":"1.229554926","rc":[{"atb":[[3.55,20.92]],"id":64343695},{"atb":[[2.6,22.03]],"id":48638605},{"atb":[[1.3,44.05]],"id":49546922}],"con":true,"img":false}]}
{"op":"mcm","clk":"11450287939","pt":1717320087284,"mc":[{"id":"1.229554926","rc":[{"atb":[[1.58,60.07],[1.68,34.15]],"id":47148562},{"atl":[[6.4,0.09]],"id":47148562},{"atb":[[4.6,6.45],[3.8,12.44]],"id":64343695},{"atb":[[2.74,20.02],[2.94,11.97]],"id":48638605},{"atb":[[1.44,52.79],[1.34,102.47]],"id":49546922},{"atl":[[4.2,0.16]],"id":49546922},{"atb":[[1.01,5807.26]],"id":70003372},{"atl":[[2.82,0.28]],"id":70003372},{"atb":[[7.2,5.61],[9.2,2.83]],"id":40917581}],"con":true,"img":false}]}
{"op":"mcm","clk":"11450292978","pt":1717320160988,"mc":[{"id":"1.229554926","rc":[{"atb":[[1.41,0]],"id":47148562},{"spn":4.04,"spf":"NaN","id":47148562},{"atb":[[3.55,0]],"id":64343695},{"spn":34.8,"spf":"NaN","id":64343695},{"atb":[[2.6,0]],"id":48638605},{"spn":17.47,"spf":"NaN","id":48638605},{"atb":[[1.3,0]],"id":49546922},{"spn":2.82,"spf":"NaN","id":49546922},{"spn":1.98,"spf":"NaN","id":70003372}],"con":true,"img":false}]}
{"op":"mcm","clk":"11450292984","pt":1717320161092,"mc":[{"id":"1.229554926","rc":[{"atb":[[1.59,40.83]],"id":47148562},{"atb":[[3.85,20.92]],"id":64343695},{"atb":[[2.96,22.03]],"id":48638605},{"atb":[[1.45,44.05]],"id":49546922}],"con":true,"img":false}]}
{"op":"mcm","clk":"11450318679","pt":1717320528418,"mc":[{"id":"1.229554926","marketDefinition":{"bspMarket":true,"turnInPlayEnabled":false,"persistenceEnabled":false,"marketBaseRate":7.0,"eventId":"33318908","eventTypeId":"4339","numberOfWinners":2,"bettingType":"ODDS","marketType":"PLACE","marketTime":"2024-06-02T10:41:00.000Z","suspendTime":"2024-06-02T10:41:00.000Z","bspReconciled":false,"complete":true,"inPlay":false,"crossMatching":true,"runnersVoidable":false,"numberOfActiveRunners":6,"betDelay":0,"status":"OPEN","runners":[{"status":"ACTIVE","sortPriority":1,"id":40917581,"name":"1. Sophia Palms"},{"status":"ACTIVE","sortPriority":2,"id":47148562,"name":"2. Under Siege"},{"status":"ACTIVE","sortPriority":3,"id":49546922,"name":"4. Uno Whiskey"},{"status":"ACTIVE","sortPriority":4,"id":70003372,"name":"5. Southern Sun"},{"status":"ACTIVE","sortPriority":5,"id":48638605,"name":"7. Lochinvar Aloisi"},{"status":"ACTIVE","sortPriority":6,"id":64343695,"name":"8. Punching Poncho"}],"regulators":["MR_INT"],"venue":"Murray Bridge","countryCode":"AU","discountAllowed":true,"timezone":"Australia/Adelaide","openDate":"2024-06-02T08:21:00.000Z","version":5962327457,"name":"To Be Placed","eventName":"Murray Bridge (AUS) 2nd Jun"},"rc":[{"atb":[[1.59,40.83],[1.01,17.35],[1.58,60.07],[1.68,34.15],[1.31,193.05]],"id":47148562},{"atl":[[6.4,0.09],[9.2,7.32],[8.2,5.81],[1000,0.17]],"id":47148562},{"spn":4.04,"spf":"NaN","id":47148562},{"atb":[[3.85,20.92],[1.01,17.35],[4.6,6.45],[4.1,13.5],[3.8,12.44]],"id":64343695},{"atl":[[65,5.23],[1000,0.17]],"id":64343695},{"spn":34.8,"spf":"NaN","id":64343695},{"atb":[[1.01,17.35],[2.74,20.02],[2.28,45.26],[2.96,22.03],[2.94,11.97]],"id":48638605},{"atl":[[32,2.61],[34,2.61],[1000,0.17]],"id":48638605},{"spn":17.48,"spf":"NaN","id":48638605},{"atb":[[1.28,197.59],[1.44,52.79],[1.45,44.05],[1.03,5.78],[1.34,102.47]],"id":49546922},{"atl":[[7,6.97],[7.8,8.13],[4.2,0.16],[990,0.17]],"id":49546922},{"spn":2.82,"spf":"NaN","id":49546922},{"atb":[[1.12,517.94],[1.01,5807.26],[1.02,8.67],[1.14,114.64]],"id":70003372},{"atl":[[2.82,0.28],[4.6,17.26],[4.1,13.5],[990,0.17]],"id":70003372},{"spn":1.98,"spf":"NaN","id":70003372},{"atb":[[7.2,5.61],[9.2,2.83],[11.5,5.45],[1.02,8.67],[13.5,4.4]],"id":40917581},{"atl":[[290,0.14],[330,2.61],[990,0.17]],"id":40917581},{"spn":151.75,"spf":"NaN","id":40917581}],"con":true,"img":true}]}
{"op":"mcm","clk":"11450360419","pt":1717320990750,"mc":[{"id":"1.229554926","rc":[{"atb":[[1.58,0],[1.68,0]],"id":47148562},{"atl":[[6.4,0]],"id":47148562},{"spn":4.89,"spf":"NaN","id":47148562},{"atb":[[4.6,0],[3.8,0]],"id":64343695},{"spn":34.55,"spf":"NaN","id":64343695},{"atb":[[2.74,0],[2.94,0]],"id":48638605},{"spn":17.48,"spf":"NaN","id":48638605},{"atb":[[1.44,0],[1.34,0]],"id":49546922},{"atl":[[4.2,0]],"id":49546922},{"spn":4.22,"spf":"NaN","id":49546922},{"atb":[[1.01,0]],"id":70003372},{"atl":[[2.82,0]],"id":70003372},{"spn":2.62,"spf":"NaN","id":70003372},{"atb":[[7.2,0],[9.2,0]],"id":40917581}],"con":true,"img":false}]}
{"op":"mcm","clk":"11450361748","pt":1717321007297,"mc":[{"id":"1.229554926","rc":[{"atb":[[1.59,0]],"id":47148562},{"atb":[[2.96,0]],"id":48638605},{"atb":[[1.45,0]],"id":49546922}],"con":true,"img":false}]}
{"op":"mcm","clk":"11450361754","pt":1717321007402,"mc":[{"id":"1.229554926","rc":[{"atb":[[1.37,40.83]],"id":47148562},{"atb":[[2.6,22.03]],"id":48638605},{"atb":[[1.3,44.05]],"id":49546922}],"con":true,"img":false}]}
{"op":"mcm","clk":"11450362070","pt":1717321011617,"mc":[{"id":"1.229554926","rc":[{"atb":[[1.55,63.35],[1.65,35.73]],"id":47148562},{"atl":[[6.2,0.09]],"id":47148562},{"atb":[[4.6,6.45],[3.8,12.44]],"id":64343695},{"atb":[[3.1,11.05],[2.84,18.93]],"id":48638605},{"atb":[[1.45,51.62],[1.35,99.55]],"id":49546922},{"atl":[[4.2,0.16]],"id":49546922},{"atb":[[1.01,5807.26]],"id":70003372},{"atl":[[2.8,0.29]],"id":70003372},{"atb":[[6.8,6],[8.8,2.97]],"id":40917581}],"con":true,"img":false}]}
{"op":"mcm","clk":"11450366514","pt":1717321069058,"mc":[{"id":"1.229554926","rc":[{"atb":[[1.37,0]],"id":47148562},{"spn":3.92,"spf":"NaN","id":47148562},{"spn":34.8,"spf":"NaN","id":64343695},{"atb":[[2.6,0]],"id":48638605},{"spn":17.55,"spf":"NaN","id":48638605},{"atb":[[1.3,0]],"id":49546922},{"spn":2.82,"spf":"NaN","id":49546922},{"spn":1.97,"spf":"NaN","id":70003372}],"con":true,"img":false}]}
{"op":"mcm","clk":"11450366522","pt":1717321069165,"mc":[{"id":"1.229554926","rc":[{"atb":[[1.56,40.83]],"id":47148562},{"atb":[[2.86,22.03]],"id":48638605},{"atb":[[1.46,44.05]],"id":49546922}],"con":true,"img":false}]}
{"op":"mcm","clk":"11450371369","pt":1717321140984,"mc":[{"id":"1.229554926","rc":[{"atb":[[2.86,0]],"id":48638605},{"spn":2.83,"spf":"NaN","id":49546922}],"con":true,"img":false}]}
{"op":"mcm","clk":"11450371381","pt":1717321141042,"mc":[{"id":"1.229554926","rc":[{"atb":[[3.15,22.03]],"id":48638605}],"con":true,"img":false}]}
{"op":"mcm","clk":"11450378793","pt":1717321260336,"mc":[{"id":"1.229554926","rc":[{"spn":17.57,"spf":"NaN","id":48638605},{"atl":[[6.2,21.87]],"id":49546922}],"con":true,"img":false}]}
{"op":"mcm","clk":"11450378801","pt":1717321260440,"mc":[{"id":"1.229554926","rc":[{"atb":[[1.55,139.92]],"id":47148562},{"atl":[[8,5.81]],"id":47148562},{"atb":[[4,19.95]],"id":64343695},{"atl":[[60,2]],"id":64343695},{"atb":[[2.38,37.88]],"id":48638605},{"atl":[[32,5.23]],"id":48638605},{"atb":[[1.3,103.24]],"id":49546922},{"atl":[[6.8,6.97]],"id":49546922},{"atb":[[1.03,2907.96]],"id":70003372},{"atl":[[3.05,13.5]],"id":70003372},{"atb":[[13,8.33]],"id":40917581},{"atl":[[550,2]],"id":40917581}],"con":true,"img":false}]}
{"op":"mcm","clk":"11450379611","pt":1717321272033,"mc":[{"id":"1.229554926","rc":[{"atb":[[1.55,63.35],[1.51,105.21]],"id":47148562},{"atb":[[4,0],[3.75,27]],"id":64343695},{"atl":[[65,7.23],[60,0]],"id":64343695},{"atb":[[12,9.09],[13,0]],"id":40917581}],"con":true,"img":false}]}
{"op":"mcm","clk":"11450382299","pt":1717321314272,"mc":[{"id":"1.229554926","rc":[{"atb":[[1.55,0],[1.65,0]],"id":47148562},{"atl":[[6.2,0]],"id":47148562},{"atb":[[4.6,0],[3.8,0]],"id":64343695},{"atb":[[3.1,0],[2.84,0]],"id":48638605},{"atb":[[1.45,0],[1.35,0]],"id":49546922},{"atl":[[4.2,0]],"id":49546922},{"atb":[[1.01,0]],"id":70003372},{"atl":[[2.8,0]],"id":70003372},{"atb":[[6.8,0],[8.8,0]],"id":40917581}],"con":true,"img":false}]}
{"op":"mcm","clk":"11450382311","pt":1717321314481,"mc":[{"id":"1.229554926","rc":[{"atl":[[6.8,0],[6,6.97]],"id":49546922},{"atl":[[3.2,27],[3.05,0]],"id":70003372}],"con":true,"img":false}]}
{"op":"mcm","clk":"11450382388","pt":1717321315992,"mc":[{"id":"1.229554926","rc":[{"atb":[[1.56,0]],"id":47148562},{"atl":[[65,4.61]],"id":64343695},{"atb":[[2.28,0],[3.15,0]],"id":48638605},{"atl":[[34,0]],"id":48638605},{"atb":[[1.28,0],[1.46,0]],"id":49546922},{"atl":[[7,0]],"id":49546922},{"atb":[[11.5,0]],"id":40917581}],"con":true,"img":false}]}
{"op":"mcm","clk":"11450382395","pt":1717321316098,"mc":[{"id":"1.229554926","rc":[{"atb":[[1.32,210.42],[1.51,0],[1.52,40.83]],"id":47148562},{"atl":[[60,2.61]],"id":64343695},{"atb":[[2.4,45.26],[1.74,75.76],[2.38,0],[2.6,22.03]],"id":48638605},{"atl":[[30,2.61]],"id":48638605},{"atb":[[1.3,0],[1.31,241.65],[1.04,206.48]],"id":49546922},{"atl":[[6,13.94]],"id":49546922},{"atb":[[12.5,5.45]],"id":40917581}],"con":true,"img":false}]}
{"op":"mcm","clk":"11450382401","pt":1717321316199,"mc":[{"id":"1.229554926","rc":[{"atl":[[6.2,0]],"id":49546922}],"con":true,"img":false}]}
{"op":"mcm","clk":"11450382411","pt":1717321316306,"mc":[{"id":"1.229554926","rc":[{"atb":[[1.32,0],[1.51,193.05]],"id":47148562},{"atb":[[1.74,0],[2.28,67.3]],"id":48638605},{"atb":[[1.28,357.14],[1.04,0]],"id":49546922}],"con":true,"img":false}]}
{"op":"mcm","clk":"11450382436","pt":1717321316618,"mc":[{"id":"1.229554926","rc":[{"atl":[[6.2,7.18]],"id":49546922}],"con":true,"img":false}]}
{"op":"mcm","clk":"11450382844","pt":1717321322766,"mc":[{"id":"1.229554926","rc":[{"atb":[[1.54,7.26]],"id":47148562},{"spn":4.77,"spf":"NaN","id":47148562},{"spn":32.05,"spf":"NaN","id":64343695},{"atb":[[2.66,2.36]],"id":48638605},{"spn":16.33,"spf":"NaN","id":48638605},{"atb":[[1.32,12.26]],"id":49546922},{"spn":3.66,"spf":"NaN","id":49546922},{"spn":2.17,"spf":"NaN","id":70003372}],"con":true,"img":false}]}
{"op":"mcm","clk":"11450383329","pt":1717321330840,"mc":[{"id":"1.229554926","rc":[{"atb":[[1.54,0]],"id":47148562}],"con":true,"img":false}]}
{"op":"mcm","clk":"11450383466","pt":1717321332960,"mc":[{"id":"1.229554926","rc":[{"atb":[[1.59,59.05],[1.69,33.66]],"id":47148562},{"atl":[[6.6,0.09]],"id":47148562},{"atb":[[4.6,6.45],[3.8,12.44]],"id":64343695},{"atb":[[2.98,11.72],[2.78,19.57]],"id":48638605},{"atb":[[1.41,56.65],[1.31,354.04]],"id":49546922},{"atl":[[4.1,0.16]],"id":49546922},{"atb":[[1.01,3484.35],[1.02,1170.12]],"id":70003372},{"atl":[[2.82,0.28]],"id":70003372},{"atb":[[6.8,6],[8.8,2.97]],"id":40917581}],"con":true,"img":false}]}
{"op":"mcm","clk":"11450383609","pt":1717321334942,"mc":[{"id":"1.229554926","rc":[{"atb":[[1.31,156.45]],"id":49546922},{"atl":[[6,6.97]],"id":49546922}],"con":true,"img":false}]}
{"op":"mcm","clk":"11450383616","pt":1717321335045,"mc":[{"id":"1.229554926","rc":[{"atb":[[1.29,197.59]],"id":49546922},{"atl":[[6.8,6.97]],"id":49546922}],"con":true,"img":false}]}
{"op":"mcm","clk":"11450383799","pt":1717321338052,"mc":[{"id":"1.229554926","rc":[{"atb":[[1.72,5.44]],"id":47148562},{"atb":[[1.32,0]],"id":49546922}],"con":true,"img":false}]}
{"op":"mcm","clk":"11450383831","pt":1717321338570,"mc":[{"id":"1.229554926","rc":[{"atb":[[1.43,9.12]],"id":49546922}],"con":true,"img":false}]}
{"op":"mcm","clk":"11450384992","pt":1717321358583,"mc":[{"id":"1.229554926","rc":[{"atl":[[4.1,0],[3.15,19.46]],"id":70003372}],"con":true,"img":false}]}
{"op":"mcm","clk":"11450386086","pt":1717321377594,"mc":[{"id":"1.229554926","rc":[{"atb":[[2.6,0]],"id":48638605},{"atb":[[1.31,112.39]],"id":49546922}],"con":true,"img":false}]}
{"op":"mcm","clk":"11450386090","pt":1717321377695,"mc":[{"id":"1.229554926","rc":[{"atb":[[3,22.03]],"id":48638605},{"atb":[[1.42,44.05]],"id":49546922}],"con":true,"img":false}]}
{"op":"mcm","clk":"11450386531","pt":1717321384811,"mc":[{"id":"1.229554926","rc":[{"spn":4.16,"spf":"NaN","id":47148562},{"spn":32.3,"spf":"NaN","id":64343695},{"atb":[[2.66,0]],"id":48638605},{"spn":16.5,"spf":"NaN","id":48638605},{"atb":[[1.43,0]],"id":49546922},{"spn":2.76,"spf":"NaN","id":49546922},{"spn":1.98,"spf":"NaN","id":70003372}],"con":true,"img":false}]}
{"op":"mcm","clk":"11450386545","pt":1717321385018,"mc":[{"id":"1.229554926","rc":[{"atb":[[1.01,19.71]],"id":48638605},{"atb":[[1.44,8.91]],"id":49546922}],"con":true,"img":false}]}
{"op":"mcm","clk":"11450386564","pt":1717321385282,"mc":[{"id":"1.229554926","rc":[{"atb":[[1.01,19.22]],"id":48638605}],"con":true,"img":false}]}
{"op":"mcm","clk":"11450386577","pt":1717321385487,"mc":[{"id":"1.229554926","rc":[{"atb":[[1.01,17.35]],"id":48638605}],"con":true,"img":false}]}
{"op":"mcm","clk":"11450386586","pt":1717321385590,"mc":[{"id":"1.229554926","rc":[{"atb":[[3.1,1.86]],"id":48638605}],"con":true,"img":false}]}
{"op":"mcm","clk":"11450388356","pt":1717321412833,"mc":[{"id":"1.229554926","rc":[{"atb":[[1.32,13.31]],"id":49546922}],"con":true,"img":false}]}
{"op":"mcm","clk":"11450388361","pt":1717321412938,"mc":[{"id":"1.229554926","rc":[{"atb":[[1.61,6.98]],"id":47148562}],"con":true,"img":false}]}
{"op":"mcm","clk":"11450388383","pt":1717321413257,"mc":[{"id":"1.229554926","rc":[{"atb":[[2.46,2.91]],"id":48638605}],"con":true,"img":false}]}
{"op":"mcm","clk":"11450388766","pt":1717321419373,"mc":[{"id":"1.229554926","rc":[{"atl":[[7.8,8.89]],"id":47148562}],"con":true,"img":false}]}
{"op":"mcm","clk":"11450388771","pt":1717321419436,"mc":[{"id":"1.229554926","rc":[{"atl":[[9.2,0],[7.6,5.81]],"id":47148562}],"con":true,"img":false}]}
{"op":"mcm","clk":"11450388777","pt":1717321419530,"mc":[{"id":"1.229554926","rc":[{"atl":[[8,0]],"id":47148562}],"con":true,"img":false}]}
{"op":"mcm","clk":"11450389803","pt":1717321437350,"mc":[{"id":"1.229554926","rc":[{"atl":[[9,7.32]],"id":47148562}],"con":true,"img":false}]}
{"op":"mcm","clk":"11450389809","pt":1717321437453,"mc":[{"id":"1.229554926","rc":[{"atl":[[7.8,0]],"id":47148562}],"con":true,"img":false}]}
{"op":"mcm","clk":"11450391152","pt":1717321458865,"mc":[{"id":"1.229554926","rc":[{"atb":[[4.1,0]],"id":64343695},{"spn":16.55,"spf":"NaN","id":48638605},{"spn":2.77,"spf":"NaN","id":49546922}],"con":true,"img":false}]}
{"op":"mcm","clk":"11450391160","pt":1717321458973,"mc":[{"id":"1.229554926","rc":[{"atb":[[4.7,13.5]],"id":64343695}],"con":true,"img":false}]}
{"op":"mcm","clk":"11450406729","pt":1717321679340,"mc":[{"id":"1.229554926","rc":[{"atb":[[1.59,0],[1.69,0]],"id":47148562},{"atl":[[6.6,0]],"id":47148562},{"spn":4.66,"spf":"NaN","id":47148562},{"atb":[[4.6,0],[3.8,0]],"id":64343695},{"spn":32.35,"spf":"NaN","id":64343695},{"atb":[[2.98,0],[2.78,0]],"id":48638605},{"atb":[[1.41,0],[1.31,0]],"id":49546922},{"atl":[[4.1,0]],"id":49546922},{"spn":3.72,"spf":"NaN","id":49546922},{"atb":[[1.01,0],[1.02,8.67]],"id":70003372},{"atl":[[2.82,0]],"id":70003372},{"spn":2.14,"spf":"NaN","id":70003372},{"atb":[[6.8,0],[8.8,0]],"id":40917581}],"con":true,"img":false}]}
{"op":"mcm","clk":"11450406735","pt":1717321679445,"mc":[{"id":"1.229554926","rc":[{"atl":[[8,11.62]],"id":47148562},{"atl":[[3.2,0],[3.1,19.47]],"id":70003372}],"con":true,"img":false}]}
{"op":"mcm","clk":"11450406740","pt":1717321679548,"mc":[{"id":"1.229554926","rc":[{"atl":[[7.6,0]],"id":47148562}],"con":true,"img":false}]}
{"op":"mcm","clk":"11450407831","pt":1717321693628,"mc":[{"id":"1.229554926","rc":[{"atb":[[4.7,0]],"id":64343695},{"atb":[[3,0]],"id":48638605},{"atb":[[1.42,0]],"id":49546922},{"atl":[[4.1,13.5],[3.15,0]],"id":70003372}],"con":true,"img":false}]}
{"op":"mcm","clk":"11450407840","pt":1717321693730,"mc":[{"id":"1.229554926","rc":[{"atb":[[4.1,13.5]],"id":64343695},{"atb":[[2.6,22.03]],"id":48638605},{"atb":[[1.3,44.05]],"id":49546922},{"atl":[[3.2,38.94]],"id":70003372}],"con":true,"img":false}]}
{"op":"mcm","clk":"11450407844","pt":1717321693832,"mc":[{"id":"1.229554926","rc":[{"atl":[[3.1,0]],"id":70003372}],"con":true,"img":false}]}
{"op":"mcm","clk":"11450408137","pt":1717321698279,"mc":[{"id":"1.229554926","rc":[{"atb":[[1.56,62.22],[1.66,35.19]],"id":47148562},{"atl":[[6.2,0.09]],"id":47148562},{"atb":[[4.6,6.45],[3.8,12.44]],"id":64343695},{"atb":[[3.1,12.92],[2.84,18.93]],"id":48638605},{"atb":[[1.45,51.62],[1.35,99.55]],"id":49546922},{"atl":[[4.2,0.16]],"id":49546922},{"atb":[[1.01,5807.26]],"id":70003372},{"atl":[[2.78,0.29]],"id":70003372},{"atb":[[9,2.9],[7,5.8]],"id":40917581}],"con":true,"img":false}]}
{"op":"mcm","clk":"11450408382","pt":1717321701382,"mc":[{"id":"1.229554926","rc":[{"atb":[[1.44,0]],"id":49546922}],"con":true,"img":false}]}
{"op":"mcm","clk":"11450408398","pt":1717321701589,"mc":[{"id":"1.229554926","rc":[{"atb":[[1.47,8.34]],"id":49546922}],"con":true,"img":false}]}
{"op":"mcm","clk":"11450408844","pt":1717321707791,"mc":[{"id":"1.229554926","rc":[{"atb":[[1.61,0]],"id":47148562},{"atb":[[1.32,0]],"id":49546922}],"con":true,"img":false}]}
{"op":"mcm","clk":"11450410956","pt":1717321734204,"mc":[{"id":"1.229554926","rc":[{"atl":[[9,0],[8.2,0],[7.8,8.89]],"id":47148562},{"atl":[[32,2.62]],"id":48638605}],"con":true,"img":false}]}
{"op":"mcm","clk":"11450410966","pt":1717321734306,"mc":[{"id":"1.229554926","rc":[{"atl":[[7.6,8.89],[7.8,14.7]],"id":47148562},{"atl":[[29,2.61]],"id":48638605}],"con":true,"img":false}]}
{"op":"mcm","clk":"11450410976","pt":1717321734404,"mc":[{"id":"1.229554926","rc":[{"atl":[[8,0]],"id":47148562},{"atl":[[29,5.23]],"id":48638605}],"con":true,"img":false}]}
{"op":"mcm","clk":"11450410983","pt":1717321734509,"mc":[{"id":"1.229554926","rc":[{"atl":[[32,0]],"id":48638605}],"con":true,"img":false}]}
{"op":"mcm","clk":"11450412119","pt":1717321747126,"mc":[{"id":"1.229554926","rc":[{"spn":3.96,"spf":"NaN","id":47148562},{"spn":32.3,"spf":"NaN","id":64343695},{"spn":16.05,"spf":"NaN","id":48638605},{"atb":[[1.36,11.83]],"id":49546922},{"spn":2.83,"spf":"NaN","id":49546922},{"spn":1.96,"spf":"NaN","id":70003372}],"con":true,"img":false}]}
{"op":"mcm","clk":"11450412134","pt":1717321747228,"mc":[{"id":"1.229554926","rc":[{"atb":[[1.58,7.34]],"id":47148562}],"con":true,"img":false}]}
{"op":"mcm","clk":"11450412480","pt":1717321751226,"mc":[{"id":"1.229554926","rc":[{"atb":[[1.52,0]],"id":47148562},{"atb":[[2.6,0]],"id":48638605},{"atb":[[1.3,0]],"id":49546922},{"atl":[[4.1,0],[3.15,19.46]],"id":70003372}],"con":true,"img":false}]}
{"op":"mcm","clk":"11450412491","pt":1717321751337,"mc":[{"id":"1.229554926","rc":[{"atb":[[1.57,40.83]],"id":47148562},{"atb":[[3.15,22.03]],"id":48638605},{"atb":[[1.46,44.05]],"id":49546922}],"con":true,"img":false}]}
{"op":"mcm","clk":"11450413613","pt":1717321764336,"mc":[{"id":"1.229554926","rc":[{"atb":[[1.72,0]],"id":47148562},{"atb":[[3.1,11.05]],"id":48638605},{"atb":[[1.47,0]],"id":49546922}],"con":true,"img":false}]}
{"op":"mcm","clk":"11450413726","pt":1717321765742,"mc":[{"id":"1.229554926","rc":[{"atb":[[1.48,8.17]],"id":49546922}],"con":true,"img":false}]}
{"op":"mcm","clk":"11450415373","pt":1717321783972,"mc":[{"id":"1.229554926","rc":[{"atb":[[1.69,5.69]],"id":47148562},{"atb":[[1.01,19.71]],"id":48638605}],"con":true,"img":false}]}
{"op":"mcm","clk":"11450415399","pt":1717321784285,"mc":[{"id":"1.229554926","rc":[{"atb":[[1.01,19.1]],"id":48638605}],"con":true,"img":false}]}
{"op":"mcm","clk":"11450415424","pt":1717321784492,"mc":[{"id":"1.229554926","rc":[{"atb":[[1.01,17.35]],"id":48638605}],"con":true,"img":false}]}
{"op":"mcm","clk":"11450415431","pt":1717321784596,"mc":[{"id":"1.229554926","rc":[{"atb":[[3.25,1.74]],"id":48638605}],"con":true,"img":false}]}
{"op":"mcm","clk":"11450416032","pt":1717321791999,"mc":[{"id":"1.229554926","rc":[{"atl":[[7.8,5.81]],"id":47148562},{"atl":[[30,0]],"id":48638605}],"con":true,"img":false}]}
{"op":"mcm","clk":"11450416043","pt":1717321792058,"mc":[{"id":"1.229554926","rc":[{"atl":[[7.4,8.89]],"id":47148562},{"atl":[[28,2.61]],"id":48638605}],"con":true,"img":false}]}
{"op":"mcm","clk":"11450416051","pt":1717321792165,"mc":[{"id":"1.229554926","rc":[{"atl":[[7.2,8.89],[7.6,0]],"id":47148562}],"con":true,"img":false}]}
{"op":"mcm","clk":"11450417713","pt":1717321810216,"mc":[{"id":"1.229554926","rc":[{"atl":[[7.4,0]],"id":47148562},{"spn":3.94,"spf":"NaN","id":47148562},{"spn":15.62,"spf":"NaN","id":48638605},{"spn":2.84,"spf":"NaN","id":49546922}],"con":true,"img":false}]}
{"op":"mcm","clk":"11450417727","pt":1717321810315,"mc":[{"id":"1.229554926","rc":[{"atl":[[8.6,8.89]],"id":47148562}],"con":true,"img":false}]}
{"op":"mcm","clk":"11450419655","pt":1717321831189,"mc":[{"id":"1.229554926","rc":[{"atb":[[4.1,0]],"id":64343695}],"con":true,"img":false}]}
{"op":"mcm","clk":"11450419661","pt":1717321831243,"mc":[{"id":"1.229554926","rc":[{"atb":[[4.7,13.5]],"id":64343695}],"con":true,"img":false}]}
{"op":"mcm","clk":"11450438283","pt":1717322047773,"mc":[{"id":"1.229554926","rc":[{"atb":[[1.54,185.19],[1.51,0]],"id":47148562},{"atb":[[4,20.93],[3.75,0]],"id":64343695},{"spn":32.35,"spf":"NaN","id":64343695},{"atl":[[3.2,0],[2.98,19.47]],"id":70003372},{"atb":[[12,0],[13.5,9.86]],"id":40917581}],"con":true,"img":false}]}
{"op":"mcm","clk":"11450438392","pt":1717322048971,"mc":[{"id":"1.229554926","rc":[{"atb":[[2.38,42.33],[2.28,0]],"id":48638605},{"atb":[[13.5,4.4]],"id":40917581}],"con":true,"img":false}]}
{"op":"mcm","clk":"11450438400","pt":1717322049075,"mc":[{"id":"1.229554926","rc":[{"atb":[[13,8.33]],"id":40917581}],"con":true,"img":false}]}
{"op":"mcm","clk":"11450438973","pt":1717322055857,"mc":[{"id":"1.229554926","rc":[{"atl":[[3.15,0]],"id":70003372}],"con":true,"img":false}]}
{"op":"mcm","clk":"11450438985","pt":1717322055963,"mc":[{"id":"1.229554926","rc":[{"atl":[[3.9,19.46]],"id":70003372}],"con":true,"img":false}]}
{"op":"mcm","clk":"11450440021","pt":1717322066589,"mc":[{"id":"1.229554926","rc":[{"atb":[[1.56,0],[1.66,0]],"id":47148562},{"atl":[[6.2,0]],"id":47148562},{"atb":[[4.6,0],[3.8,0]],"id":64343695},{"atb":[[3.1,0],[2.84,0]],"id":48638605},{"atb":[[1.45,0],[1.35,0]],"id":49546922},{"atl":[[4.2,0]],"id":49546922},{"atb":[[1.01,0]],"id":70003372},{"atl":[[2.78,0]],"id":70003372},{"atb":[[9,0],[7,0]],"id":40917581}],"con":true,"img":false}]}
{"op":"mcm","clk":"11450440040","pt":1717322066795,"mc":[{"id":"1.229554926","rc":[{"atl":[[7.2,0],[7.6,15.15]],"id":47148562},{"atl":[[2.98,0],[3.05,38.94]],"id":70003372}],"con":true,"img":false}]}
{"op":"mcm","clk":"11450441483","pt":1717322080228,"mc":[{"id":"1.229554926","rc":[{"atb":[[1.57,0]],"id":47148562},{"atb":[[4.7,0]],"id":64343695},{"atb":[[3.15,0]],"id":48638605},{"atb":[[1.46,0]],"id":49546922}],"con":true,"img":false}]}
{"op":"mcm","clk":"11450441501","pt":1717322080400,"mc":[{"id":"1.229554926","rc":[{"atb":[[1.55,40.83]],"id":47148562},{"atb":[[4,0],[3.9,34.48],[4.2,13.5]],"id":64343695},{"atb":[[2.62,22.03]],"id":48638605},{"atb":[[1.31,44.05]],"id":49546922}],"con":true,"img":false}]}
{"op":"mcm","clk":"11450441510","pt":1717322080501,"mc":[{"id":"1.229554926","rc":[{"atb":[[4,27]],"id":64343695}],"con":true,"img":false}]}
{"op":"mcm","clk":"11450441518","pt":1717322080603,"mc":[{"id":"1.229554926","rc":[{"atb":[[3.9,0]],"id":64343695}],"con":true,"img":false}]}
{"op":"mcm","clk":"11450441765","pt":1717322083299,"mc":[{"id":"1.229554926","rc":[{"atb":[[1.55,104.18],[1.65,35.73]],"id":47148562},{"atl":[[6.2,0.09]],"id":47148562},{"atb":[[4.6,6.45],[3.8,12.44]],"id":64343695},{"atb":[[3.1,11.05],[2.84,18.93]],"id":48638605},{"atb":[[1.41,56.65],[1.31,156.45]],"id":49546922},{"atl":[[4.1,0.16]],"id":49546922},{"atb":[[1.01,3484.35],[1.02,1170.12]],"id":70003372},{"atl":[[2.82,0.28]],"id":70003372},{"atb":[[8.6,3.05],[6.6,6.22]],"id":40917581}],"con":true,"img":false}]}
{"op":"mcm","clk":"11450442039","pt":1717322086739,"mc":[{"id":"1.229554926","rc":[{"atb":[[1.58,0]],"id":47148562},{"atb":[[1.36,0]],"id":49546922}],"con":true,"img":false}]}
{"op":"mcm","clk":"11450443033","pt":1717322100310,"mc":[{"id":"1.229554926","rc":[{"atb":[[1.69,0]],"id":47148562}],"con":true,"img":false}]}
{"op":"mcm","clk":"11450443441","pt":1717322105212,"mc":[{"id":"1.229554926","rc":[{"atb":[[4.1,17.21]],"id":64343695}],"con":true,"img":false}]}
{"op":"mcm","clk":"11450443452","pt":1717322105314,"mc":[{"id":"1.229554926","rc":[{"atb":[[3.85,0]],"id":64343695},{"atb":[[12.5,0],[13.5,0]],"id":40917581}],"con":true,"img":false}]}
{"op":"mcm","clk":"11450443461","pt":1717322105422,"mc":[{"id":"1.229554926","rc":[{"atb":[[13,0],[13.5,5.45],[8.8,12.82],[14,4.4]],"id":40917581}],"con":true,"img":false}]}
{"op":"mcm","clk":"11450444882","pt":1717322121840,"mc":[{"id":"1.229554926","rc":[{"atb":[[1.68,5.77]],"id":47148562},{"spn":3.94,"spf":"NaN","id":47148562},{"spn":32.3,"spf":"NaN","id":64343695},{"spn":2.79,"spf":"NaN","id":49546922},{"spn":1.98,"spf":"NaN","id":70003372},{"spn":152.0,"spf":"NaN","id":40917581}],"con":true,"img":false}]}
{"op":"mcm","clk":"11450444935","pt":1717322122415,"mc":[{"id":"1.229554926","rc":[{"atl":[[8.6,0],[7.8,0]],"id":47148562},{"atl":[[3.9,0]],"id":70003372},{"atb":[[13.5,0]],"id":40917581}],"con":true,"img":false}]}
{"op":"mcm","clk":"11450444946","pt":1717322122519,"mc":[{"id":"1.229554926","rc":[{"atl":[[7.4,14.7]],"id":47148562},{"atl":[[3,19.46]],"id":70003372},{"atb":[[11.5,5.45]],"id":40917581}],"con":true,"img":false}]}
{"op":"mcm","clk":"11450444956","pt":1717322122622,"mc":[{"id":"1.229554926","rc":[{"atl":[[10.5,10.53],[7.6,0]],"id":47148562}],"con":true,"img":false}]}
{"op":"mcm","clk":"11450444967","pt":1717322122726,"mc":[{"id":"1.229554926","rc":[{"atl":[[3.05,0]],"id":70003372}],"con":true,"img":false}]}
{"op":"mcm","clk":"11450444981","pt":1717322122839,"mc":[{"id":"1.229554926","rc":[{"atl":[[2.98,19.47]],"id":70003372}],"con":true,"img":false}]}
{"op":"mcm","clk":"11450445150","pt":1717322124650,"mc":[{"id":"1.229554926","rc":[{"atb":[[1.57,7.47]],"id":47148562}],"con":true,"img":false}]}
{"op":"mcm","clk":"11450445165","pt":1717322124853,"mc":[{"id":"1.229554926","rc":[{"atb":[[1.32,13.31]],"id":49546922}],"con":true,"img":false}]}
{"op":"mcm","clk":"11450445936","pt":1717322134146,"mc":[{"id":"1.229554926","rc":[{"atb":[[13,8.33],[8.8,0]],"id":40917581}],"con":true,"img":false}]}
{"op":"mcm","clk":"11450446396","pt":1717322139492,"mc":[{"id":"1.229554926","rc":[{"atb":[[1.55,63.35]],"id":47148562},{"atl":[[7.4,5.81]],"id":47148562},{"atb":[[2.62,0]],"id":48638605},{"atb":[[1.31,112.39]],"id":49546922}],"con":true,"img":false}]}
{"op":"mcm","clk":"11450446402","pt":1717322139547,"mc":[{"id":"1.229554926","rc":[{"atb":[[1.56,40.83]],"id":47148562},{"atl":[[8.4,8.89]],"id":47148562},{"atb":[[3.15,22.03]],"id":48638605},{"atb":[[1.42,44.05]],"id":49546922}],"con":true,"img":false}]}
{"op":"mcm","clk":"11450447324","pt":1717322151173,"mc":[{"id":"1.229554926","rc":[{"atl":[[7.2,8.89],[10.5,0]],"id":47148562}],"con":true,"img":false}]}
{"op":"mcm","clk":"11450447930","pt":1717322158450,"mc":[{"id":"1.229554926","rc":[{"atl":[[3,0]],"id":70003372}],"con":true,"img":false}]}
{"op":"mcm","clk":"11450447937","pt":1717322158553,"mc":[{"id":"1.229554926","rc":[{"atl":[[3.85,19.46]],"id":70003372}],"con":true,"img":false}]}
{"op":"mcm","clk":"11450448110","pt":1717322160387,"mc":[{"id":"1.229554926","rc":[{"atb":[[3.25,0]],"id":48638605},{"atb":[[1.48,0]],"id":49546922}],"con":true,"img":false}]}
{"op":"mcm","clk":"11450448899","pt":1717322168883,"mc":[{"id":"1.229554926","rc":[{"atb":[[3.75,27]],"id":64343695},{"atl":[[2.98,0]],"id":70003372},{"atb":[[12,9.09]],"id":40917581}],"con":true,"img":false}]}
{"op":"mcm","clk":"11450448913","pt":1717322168989,"mc":[{"id":"1.229554926","rc":[{"atb":[[4,0]],"id":64343695},{"atl":[[3.2,19.76]],"id":70003372},{"atb":[[13,0]],"id":40917581}],"con":true,"img":false}]}
{"op":"mcm","clk":"11450449879","pt":1717322179479,"mc":[{"id":"1.229554926","rc":[{"atb":[[4.1,0]],"id":64343695},{"atl":[[29,2.62]],"id":48638605},{"atl":[[6.8,0]],"id":49546922},{"atb":[[11.5,0]],"id":40917581}],"con":true,"img":false}]}
{"op":"mcm","clk":"11450449887","pt":1717322179579,"mc":[{"id":"1.229554926","rc":[{"atb":[[3.85,17.21]],"id":64343695},{"atl":[[28,5.23]],"id":48638605},{"atl":[[6,13.94]],"id":49546922},{"atb":[[12.5,5.45]],"id":40917581}],"con":true,"img":false}]}
{"op":"mcm","clk":"11450449895","pt":1717322179680,"mc":[{"id":"1.229554926","rc":[{"atl":[[27,2.62],[29,0]],"id":48638605}],"con":true,"img":false}]}
{"op":"mcm","clk":"11450451886","pt":1717322202216,"mc":[{"id":"1.229554926","rc":[{"atl":[[28,2.61]],"id":48638605},{"spn":15.07,"spf":"NaN","id":48638605},{"spn":2.76,"spf":"NaN","id":49546922}],"con":true,"img":false}]}
{"op":"mcm","clk":"11450451894","pt":1717322202322,"mc":[{"id":"1.229554926","rc":[{"atl":[[32,2.61],[27,0],[28,6.31]],"id":48638605}],"con":true,"img":false}]}
{"op":"mcm","clk":"11450456461","pt":1717322249605,"mc":[{"id":"1.229554926","rc":[{"atb":[[1.03,161.05]],"id":47148562},{"atl":[[980,1.03]],"id":47148562},{"atb":[[1.01,119.61]],"id":64343695},{"atl":[[990,1.64]],"id":64343695},{"atb":[[1.03,149.12]],"id":48638605},{"atl":[[960,1.19]],"id":48638605},{"atb":[[1.02,160.2]],"id":49546922},{"atl":[[960,0.85]],"id":49546922},{"atb":[[1.02,1250.22]],"id":70003372},{"atl":[[970,1.75]],"id":70003372},{"atb":[[1.02,118.6]],"id":40917581},{"atl":[[970,0.85]],"id":40917581}],"con":true,"img":false}]}
{"op":"mcm","clk":"11450458417","pt":1717322270693,"mc":[{"id":"1.229554926","rc":[{"atl":[[32,0]],"id":48638605},{"spn":15.57,"spf":"NaN","id":48638605}],"con":true,"img":false}]}
{"op":"mcm","clk":"11450458425","pt":1717322270796,"mc":[{"id":"1.229554926","rc":[{"atl":[[27,2.61]],"id":48638605}],"con":true,"img":false}]}
{"op":"mcm","clk":"11450461290","pt":1717322304626,"mc":[{"id":"1.229554926","rc":[{"atl":[[27,0]],"id":48638605}],"con":true,"img":false}]}
{"op":"mcm","clk":"11450461297","pt":1717322304673,"mc":[{"id":"1.229554926","rc":[{"atl":[[32,2.61]],"id":48638605}],"con":true,"img":false}]}
{"op":"mcm","clk":"11450464948","pt":1717322346857,"mc":[{"id":"1.229554926","rc":[{"atl":[[6,6.97]],"id":49546922}],"con":true,"img":false}]}
{"op":"mcm","clk":"11450464955","pt":1717322346959,"mc":[{"id":"1.229554926","rc":[{"atl":[[6.8,6.97]],"id":49546922}],"con":true,"img":false}]}
{"op":"mcm","clk":"11450471407","pt":1717322418268,"mc":[{"id":"1.229554926","rc":[{"atb":[[1.01,19.71]],"id":48638605},{"atb":[[1.44,8.91]],"id":49546922},{"spn":2.77,"spf":"NaN","id":49546922}],"con":true,"img":false}]}
{"op":"mcm","clk":"11450471466","pt":1717322418765,"mc":[{"id":"1.229554926","rc":[{"atb":[[1.01,19.1]],"id":48638605}],"con":true,"img":false}]}
{"op":"mcm","clk":"11450471497","pt":1717322418927,"mc":[{"id":"1.229554926","rc":[{"atb":[[1.01,17.35]],"id":48638605}],"con":true,"img":false}]}
{"op":"mcm","clk":"11450471508","pt":1717322419056,"mc":[{"id":"1.229554926","rc":[{"atb":[[3.25,1.74]],"id":48638605}],"con":true,"img":false}]}
{"op":"mcm","clk":"11450474943","pt":1717322453582,"mc":[{"id":"1.229554926","rc":[{"atb":[[4.2,0]],"id":64343695}],"con":true,"img":false}]}
{"op":"mcm","clk":"11450474952","pt":1717322453684,"mc":[{"id":"1.229554926","rc":[{"atb":[[4.7,13.5]],"id":64343695}],"con":true,"img":false}]}
{"op":"mcm","clk":"11450476021","pt":1717322464922,"mc":[{"id":"1.229554926","rc":[{"atb":[[4.7,0]],"id":64343695}],"con":true,"img":false}]}
{"op":"mcm","clk":"11450476032","pt":1717322465025,"mc":[{"id":"1.229554926","rc":[{"atb":[[4.3,13.5]],"id":64343695}],"con":true,"img":false}]}
{"op":"mcm","clk":"11450476576","pt":1717322471226,"mc":[{"id":"1.229554926","rc":[{"atb":[[1.55,0],[1.65,0]],"id":47148562},{"atl":[[6.2,0]],"id":47148562},{"atb":[[4.6,0],[3.8,0]],"id":64343695},{"atb":[[3.1,0],[2.84,0]],"id":48638605},{"atb":[[1.41,0],[1.31,0]],"id":49546922},{"atl":[[4.1,0]],"id":49546922},{"atb":[[1.01,0],[1.02,88.77]],"id":70003372},{"atl":[[2.82,0]],"id":70003372},{"atb":[[8.6,0],[6.6,0]],"id":40917581}],"con":true,"img":false}]}
{"op":"mcm","clk":"11450477274","pt":1717322479849,"mc":[{"id":"1.229554926","rc":[{"spn":4.44,"spf":"NaN","id":47148562},{"spn":32.15,"spf":"NaN","id":64343695},{"atb":[[3.15,0]],"id":48638605},{"spn":15.62,"spf":"NaN","id":48638605},{"spn":3.72,"spf":"NaN","id":49546922},{"spn":2.17,"spf":"NaN","id":70003372}],"con":true,"img":false}]}
{"op":"mcm","clk":"11450477285","pt":1717322479953,"mc":[{"id":"1.229554926","rc":[{"atb":[[2.6,22.03]],"id":48638605}],"con":true,"img":false}]}
{"op":"mcm","clk":"11450477881","pt":1717322487245,"mc":[{"id":"1.229554926","rc":[{"atb":[[1.56,0]],"id":47148562},{"atb":[[1.42,0]],"id":49546922}],"con":true,"img":false}]}
{"op":"mcm","clk":"11450477890","pt":1717322487345,"mc":[{"id":"1.229554926","rc":[{"atb":[[1.55,40.83]],"id":47148562},{"atb":[[1.31,44.05]],"id":49546922}],"con":true,"img":false}]}
{"op":"mcm","clk":"11450478094","pt":1717322490148,"mc":[{"id":"1.229554926","rc":[{"atb":[[1.59,59.05],[1.69,33.66]],"id":47148562},{"atl":[[6.6,0.09]],"id":47148562},{"atb":[[3.7,12.9],[4.4,6.83]],"id":64343695},{"atb":[[2.82,19.14],[3.05,11.33]],"id":48638605},{"atb":[[1.44,61.71],[1.34,102.47]],"id":49546922},{"atl":[[4.2,0.16]],"id":49546922},{"atb":[[1.01,5807.26]],"id":70003372},{"atl":[[2.78,0.29]],"id":70003372},{"atb":[[6.8,6],[8.8,2.97]],"id":40917581}],"con":true,"img":false}]}
{"op":"mcm","clk":"11450478805","pt":1717322498962,"mc":[{"id":"1.229554926","rc":[{"atb":[[1.44,52.79]],"id":49546922}],"con":true,"img":false}]}
{"op":"mcm","clk":"11450478815","pt":1717322499068,"mc":[{"id":"1.229554926","rc":[{"atb":[[1.68,0]],"id":47148562}],"con":true,"img":false}]}
{"op":"mcm","clk":"11450478823","pt":1717322499128,"mc":[{"id":"1.229554926","rc":[{"atb":[[1.46,8.53]],"id":49546922}],"con":true,"img":false}]}
{"op":"mcm","clk":"11450478826","pt":1717322499238,"mc":[{"id":"1.229554926","rc":[{"atb":[[1.72,5.44]],"id":47148562}],"con":true,"img":false}]}
{"op":"mcm","clk":"11450479006","pt":1717322501755,"mc":[{"id":"1.229554926","rc":[{"atb":[[14,0]],"id":40917581}],"con":true,"img":false}]}
{"op":"mcm","clk":"11450479013","pt":1717322501853,"mc":[{"id":"1.229554926","rc":[{"atb":[[13,4.4]],"id":40917581}],"con":true,"img":false}]}
{"op":"mcm","clk":"11450479166","pt":1717322503573,"mc":[{"id":"1.229554926","rc":[{"atb":[[1.57,0]],"id":47148562},{"atb":[[1.32,0]],"id":49546922}],"con":true,"img":false}]}
{"op":"mcm","clk":"11450480260","pt":1717322516383,"mc":[{"id":"1.229554926","rc":[{"atb":[[3.85,0]],"id":64343695},{"atb":[[12.5,0]],"id":40917581}],"con":true,"img":false}]}
{"op":"mcm","clk":"11450480270","pt":1717322516488,"mc":[{"id":"1.229554926","rc":[{"atb":[[3.8,17.21]],"id":64343695},{"atb":[[10,5.45]],"id":40917581}],"con":true,"img":false}]}
{"op":"mcm","clk":"11450480796","pt":1717322523476,"mc":[{"id":"1.229554926","rc":[{"atb":[[2.6,0]],"id":48638605},{"atb":[[1.31,0]],"id":49546922}],"con":true,"img":false}]}
{"op":"mcm","clk":"11450480802","pt":1717322523577,"mc":[{"id":"1.229554926","rc":[{"atb":[[2.84,22.03]],"id":48638605},{"atb":[[1.45,44.05]],"id":49546922}],"con":true,"img":false}]}
{"op":"mcm","clk":"11450481122","pt":1717322527694,"mc":[{"id":"1.229554926","rc":[{"atb":[[1.59,0],[1.69,0]],"id":47148562},{"atl":[[6.6,0]],"id":47148562},{"atb":[[3.7,0],[4.4,0]],"id":64343695},{"atb":[[2.82,0],[3.05,0]],"id":48638605},{"atb":[[1.44,0],[1.34,0]],"id":49546922},{"atl":[[4.2,0]],"id":49546922},{"atb":[[1.01,0]],"id":70003372},{"atl":[[2.78,0]],"id":70003372},{"atb":[[6.8,0],[8.8,0]],"id":40917581}],"con":true,"img":false}]}
{"op":"mcm","clk":"11450481694","pt":1717322534816,"mc":[{"id":"1.229554926","rc":[{"atb":[[2.84,0]],"id":48638605}],"con":true,"img":false}]}
{"op":"mcm","clk":"11450481705","pt":1717322534894,"mc":[{"id":"1.229554926","rc":[{"atb":[[2.58,22.03]],"id":48638605}],"con":true,"img":false}]}
{"op":"mcm","clk":"11450482224","pt":1717322541207,"mc":[{"id":"1.229554926","rc":[{"spn":4.46,"spf":"NaN","id":47148562},{"atb":[[1.46,0]],"id":49546922},{"spn":3.72,"spf":"NaN","id":49546922},{"spn":151.5,"spf":"NaN","id":40917581}],"con":true,"img":false}]}
{"op":"mcm","clk":"11450482243","pt":1717322541413,"mc":[{"id":"1.229554926","rc":[{"atb":[[1.47,8.35]],"id":49546922}],"con":true,"img":false}]}
{"op":"mcm","clk":"11450482343","pt":1717322542613,"mc":[{"id":"1.229554926","rc":[{"atb":[[1.58,60.07],[1.68,34.15]],"id":47148562},{"atl":[[6.4,0.09]],"id":47148562},{"atb":[[3.7,12.9],[4.4,6.83]],"id":64343695},{"atb":[[2.98,11.72],[2.78,19.57]],"id":48638605},{"atb":[[1.43,54.02],[1.33,105.58]],"id":49546922},{"atl":[[4.1,0.16]],"id":49546922},{"atb":[[1.01,3484.35],[1.04,580.72]],"id":70003372},{"atl":[[2.84,0.28]],"id":70003372},{"atb":[[8.6,3.05],[6.6,6.22]],"id":40917581}],"con":true,"img":false}]}
{"op":"mcm","clk":"11450482389","pt":1717322543143,"mc":[{"id":"1.229554926","rc":[{"atb":[[1.45,0]],"id":49546922},{"atb":[[13,0]],"id":40917581}],"con":true,"img":false}]}
{"op":"mcm","clk":"11450482397","pt":1717322543242,"mc":[{"id":"1.229554926","rc":[{"atb":[[1.3,44.05]],"id":49546922},{"atb":[[10.5,10.53],[12.5,4.4]],"id":40917581}],"con":true,"img":false}]}
{"op":"mcm","clk":"11450482403","pt":1717322543345,"mc":[{"id":"1.229554926","rc":[{"atb":[[12,0]],"id":40917581}],"con":true,"img":false}]}
{"op":"mcm","clk":"11450482524","pt":1717322545063,"mc":[{"id":"1.229554926","rc":[{"atb":[[1.56,7.6]],"id":47148562}],"con":true,"img":false}]}
{"op":"mcm","clk":"11450482532","pt":1717322545169,"mc":[{"id":"1.229554926","rc":[{"atb":[[1.3,58.26]],"id":49546922}],"con":true,"img":false}]}
{"op":"mcm","clk":"11450483695","pt":1717322561670,"mc":[{"id":"1.229554926","rc":[{"atb":[[3.25,0]],"id":48638605}],"con":true,"img":false}]}
{"op":"mcm","clk":"11450484154","pt":1717322567600,"mc":[{"id":"1.229554926","rc":[{"atb":[[10.5,0],[12,8.82]],"id":40917581}],"con":true,"img":false}]}
{"op":"mcm","clk":"11450484782","pt":1717322576308,"mc":[{"id":"1.229554926","rc":[{"atb":[[2.58,0]],"id":48638605},{"atb":[[12.5,0]],"id":40917581}],"con":true,"img":false}]}
{"op":"mcm","clk":"11450484792","pt":1717322576409,"mc":[{"id":"1.229554926","rc":[{"atb":[[2.8,22.03]],"id":48638605},{"atb":[[10.5,10.53],[12,4.4]],"id":40917581}],"con":true,"img":false}]}
{"op":"mcm","clk":"11450485172","pt":1717322581322,"mc":[{"id":"1.229554926","rc":[{"atb":[[1.56,0]],"id":47148562},{"atb":[[1.3,44.05]],"id":49546922}],"con":true,"img":false}]}
{"op":"mcm","clk":"11450485221","pt":1717322581908,"mc":[{"id":"1.229554926","rc":[{"atb":[[1.3,0]],"id":49546922}],"con":true,"img":false}]}
{"op":"mcm","clk":"11450485233","pt":1717322582010,"mc":[{"id":"1.229554926","rc":[{"atb":[[1.44,44.05]],"id":49546922}],"con":true,"img":false}]}
{"op":"mcm","clk":"11450485381","pt":1717322583804,"mc":[{"id":"1.229554926","rc":[{"atb":[[1.01,19.71]],"id":48638605}],"con":true,"img":false}]}
{"op":"mcm","clk":"11450485399","pt":1717322584020,"mc":[{"id":"1.229554926","rc":[{"atb":[[1.01,19.44]],"id":48638605}],"con":true,"img":false}]}
{"op":"mcm","clk":"11450485448","pt":1717322584532,"mc":[{"id":"1.229554926","rc":[{"atb":[[1.58,0],[1.68,0]],"id":47148562},{"atl":[[6.4,0]],"id":47148562},{"atb":[[3.7,0],[4.4,0]],"id":64343695},{"atb":[[2.98,0],[2.78,0]],"id":48638605},{"atb":[[1.43,0],[1.33,0]],"id":49546922},{"atl":[[4.1,0]],"id":49546922},{"atb":[[8.6,0],[6.6,0]],"id":40917581}],"con":true,"img":false}]}
{"op":"mcm","clk":"11450485537","pt":1717322585686,"mc":[{"id":"1.229554926","rc":[{"atb":[[1.01,17.35]],"id":48638605}],"con":true,"img":false}]}
{"op":"mcm","clk":"11450485544","pt":1717322585788,"mc":[{"id":"1.229554926","rc":[{"atb":[[2.88,2.08]],"id":48638605}],"con":true,"img":false}]}
{"op":"mcm","clk":"11450486851","pt":1717322600339,"mc":[{"id":"1.229554926","rc":[{"atb":[[10.5,0],[12,9.86]],"id":40917581}],"con":true,"img":false}]}
{"op":"mcm","clk":"11450486860","pt":1717322600442,"mc":[{"id":"1.229554926","rc":[{"atb":[[10.5,10.53],[12,4.4]],"id":40917581}],"con":true,"img":false}]}
{"op":"mcm","clk":"11450486867","pt":1717322600543,"mc":[{"id":"1.229554926","rc":[{"atb":[[10.5,0],[12,13.49]],"id":40917581}],"con":true,"img":false}]}
{"op":"mcm","clk":"11450486952","pt":1717322601544,"mc":[{"id":"1.229554926","rc":[{"atb":[[1.56,62.22],[1.66,35.19]],"id":47148562},{"atl":[[6.2,0.09]],"id":47148562},{"spn":3.96,"spf":"NaN","id":47148562},{"atb":[[4.5,6.63],[3.75,39.67]],"id":64343695},{"spn":32.25,"spf":"NaN","id":64343695},{"atb":[[2.88,20.62],[3.2,10.55]],"id":48638605},{"spn":15.6,"spf":"NaN","id":48638605},{"atb":[[1.43,54.02],[1.33,105.58]],"id":49546922},{"atl":[[4.1,0.16]],"id":49546922},{"spn":2.78,"spf":"NaN","id":49546922},{"spn":1.99,"spf":"NaN","id":70003372},{"atb":[[8,3.31],[6,6.96]],"id":40917581},{"spn":151.0,"spf":"NaN","id":40917581}],"con":true,"img":false}]}
{"op":"mcm","clk":"11450487012","pt":1717322602226,"mc":[{"id":"1.229554926","rc":[{"atb":[[1.72,0]],"id":47148562}],"con":true,"img":false}]}
{"op":"mcm","clk":"11450487244","pt":1717322604626,"mc":[{"id":"1.229554926","rc":[{"atb":[[1.69,5.69]],"id":47148562}],"con":true,"img":false}]}
{"op":"mcm","clk":"11450487387","pt":1717322606345,"mc":[{"id":"1.229554926","rc":[{"atl":[[9,7.32],[8.4,0]],"id":47148562}],"con":true,"img":false}]}
{"op":"mcm","clk":"11450488545","pt":1717322618869,"mc":[{"id":"1.229554926","rc":[{"atb":[[1.58,7.34]],"id":47148562}],"con":true,"img":false}]}
{"op":"mcm","clk":"11450488558","pt":1717322618973,"mc":[{"id":"1.229554926","rc":[{"atb":[[1.55,0]],"id":47148562},{"atb":[[2.8,0]],"id":48638605}],"con":true,"img":false}]}
{"op":"mcm","clk":"11450488570","pt":1717322619052,"mc":[{"id":"1.229554926","rc":[{"atb":[[1.57,40.83]],"id":47148562},{"atb":[[2.9,22.03]],"id":48638605}],"con":true,"img":false}]}
{"op":"mcm","clk":"11450488614","pt":1717322619573,"mc":[{"id":"1.229554926","rc":[{"atb":[[1.34,12.53]],"id":49546922}],"con":true,"img":false}]}
{"op":"mcm","clk":"11450489011","pt":1717322623559,"mc":[{"id":"1.229554926","rc":[{"atb":[[1.47,0]],"id":49546922}],"con":true,"img":false}]}
{"op":"mcm","clk":"11450489220","pt":1717322625450,"mc":[{"id":"1.229554926","rc":[{"atb":[[2.88,18.53]],"id":48638605},{"atb":[[1.46,8.53]],"id":49546922}],"con":true,"img":false}]}
{"op":"mcm","clk":"11450489243","pt":1717322625658,"mc":[{"id":"1.229554926","rc":[{"atb":[[1.01,19.71]],"id":48638605}],"con":true,"img":false}]}
{"op":"mcm","clk":"11450489292","pt":1717322626072,"mc":[{"id":"1.229554926","rc":[{"atb":[[1.01,19.34]],"id":48638605}],"con":true,"img":false}]}
{"op":"mcm","clk":"11450489310","pt":1717322626382,"mc":[{"id":"1.229554926","rc":[{"atb":[[1.01,17.35]],"id":48638605}],"con":true,"img":false}]}
{"op":"mcm","clk":"11450489316","pt":1717322626432,"mc":[{"id":"1.229554926","rc":[{"atb":[[2.98,1.98]],"id":48638605}],"con":true,"img":false}]}
{"op":"mcm","clk":"11450490333","pt":1717322639379,"mc":[{"id":"1.229554926","rc":[{"atb":[[1.56,0],[1.66,0]],"id":47148562},{"atl":[[6.2,0]],"id":47148562},{"atb":[[3.2,0],[2.88,0]],"id":48638605},{"atb":[[1.43,0],[1.33,0]],"id":49546922},{"atl":[[4.1,0]],"id":49546922}],"con":true,"img":false}]}
{"op":"mcm","clk":"11450491510","pt":1717322651899,"mc":[{"id":"1.229554926","rc":[{"atb":[[1.59,59.05],[1.69,39.35]],"id":47148562},{"atl":[[6.6,0.09]],"id":47148562},{"atb":[[3.1,11.05],[2.84,18.93]],"id":48638605},{"atb":[[1.43,54.02],[1.33,105.58]],"id":49546922},{"atl":[[4.1,0.16]],"id":49546922}],"con":true,"img":false}]}
{"op":"mcm","clk":"11450491952","pt":1717322656982,"mc":[{"id":"1.229554926","rc":[{"atb":[[1.57,0]],"id":47148562}],"con":true,"img":false}]}
{"op":"mcm","clk":"11450491961","pt":1717322657085,"mc":[{"id":"1.229554926","rc":[{"atb":[[1.55,40.83]],"id":47148562}],"con":true,"img":false}]}
{"op":"mcm","clk":"11450492105","pt":1717322658910,"mc":[{"id":"1.229554926","rc":[{"atb":[[1.58,0]],"id":47148562}],"con":true,"img":false}]}
{"op":"mcm","clk":"11450492876","pt":1717322668338,"mc":[{"id":"1.229554926","rc":[{"atb":[[1.69,33.66]],"id":47148562},{"spn":4.14,"spf":"NaN","id":47148562},{"spn":15.55,"spf":"NaN","id":48638605},{"spn":2.78,"spf":"NaN","id":49546922}],"con":true,"img":false}]}
{"op":"mcm","clk":"11450492911","pt":1717322668610,"mc":[{"id":"1.229554926","rc":[{"atb":[[1.72,5.45]],"id":47148562}],"con":true,"img":false}]}
{"op":"mcm","clk":"11450493220","pt":1717322672044,"mc":[{"id":"1.229554926","rc":[{"atb":[[2.9,0]],"id":48638605}],"con":true,"img":false}]}
{"op":"mcm","clk":"11450493230","pt":1717322672108,"mc":[{"id":"1.229554926","rc":[{"atb":[[3.15,22.03]],"id":48638605}],"con":true,"img":false}]}
{"op":"mcm","clk":"11450494792","pt":1717322689662,"mc":[{"id":"1.229554926","rc":[{"atb":[[2.98,0]],"id":48638605}],"con":true,"img":false}]}
{"op":"mcm","clk":"11450494807","pt":1717322689867,"mc":[{"id":"1.229554926","rc":[{"atb":[[1.01,19.71]],"id":48638605}],"con":true,"img":false}]}
{"op":"mcm","clk":"11450494848","pt":1717322690447,"mc":[{"id":"1.229554926","rc":[{"atb":[[1.01,19.1]],"id":48638605}],"con":true,"img":false}]}
{"op":"mcm","clk":"11450494863","pt":1717322690684,"mc":[{"id":"1.229554926","rc":[{"atb":[[1.01,17.35]],"id":48638605}],"con":true,"img":false}]}
{"op":"mcm","clk":"11450494873","pt":1717322690745,"mc":[{"id":"1.229554926","rc":[{"atb":[[3.25,1.75]],"id":48638605}],"con":true,"img":false}]}
{"op":"mcm","clk":"11450494912","pt":1717322691257,"mc":[{"id":"1.229554926","rc":[{"atb":[[1.61,6.98]],"id":47148562}],"con":true,"img":false}]}
{"op":"mcm","clk":"11450505715","pt":1717322805472,"mc":[{"id":"1.229554926","rc":[{"atb":[[1.59,0],[1.69,0]],"id":47148562},{"atl":[[6.6,0]],"id":47148562},{"spn":4.46,"spf":"NaN","id":47148562},{"atb":[[4.5,0],[3.75,27]],"id":64343695},{"spn":32.15,"spf":"NaN","id":64343695},{"atb":[[3.1,0],[2.84,0]],"id":48638605},{"spn":15.62,"spf":"NaN","id":48638605},{"atb":[[1.43,0],[1.33,0]],"id":49546922},{"atl":[[4.1,0]],"id":49546922},{"spn":3.73,"spf":"NaN","id":49546922},{"atb":[[1.01,0],[1.04,0]],"id":70003372},{"atl":[[2.84,0]],"id":70003372},{"spn":2.17,"spf":"NaN","id":70003372},{"atb":[[8,0],[6,0]],"id":40917581}],"con":true,"img":false}]}
{"op":"mcm","clk":"11450506042","pt":1717322809570,"mc":[{"id":"1.229554926","rc":[{"atb":[[3.15,0]],"id":48638605},{"atb":[[1.44,0]],"id":49546922}],"con":true,"img":false}]}
{"op":"mcm","clk":"11450506054","pt":1717322809680,"mc":[{"id":"1.229554926","rc":[{"atb":[[2.56,22.03]],"id":48638605},{"atb":[[1.31,44.05]],"id":49546922}],"con":true,"img":false}]}
{"op":"mcm","clk":"11450506997","pt":1717322820682,"mc":[{"id":"1.229554926","rc":[{"atb":[[1.64,36.29],[1.54,249.71]],"id":47148562},{"atl":[[6,0.1]],"id":47148562},{"atb":[[4.3,20.53],[3.65,13.14]],"id":64343695},{"atb":[[3.1,11.05],[2.84,18.93]],"id":48638605},{"atb":[[1.32,108.88],[1.42,55.3]],"id":49546922},{"atl":[[4.1,0.16]],"id":49546922},{"atb":[[1.01,3484.35],[1.05,464.58]],"id":70003372},{"atl":[[2.86,0.28]],"id":70003372},{"atb":[[8.6,3.05],[6.6,6.22]],"id":40917581}],"con":true,"img":false}]}
{"op":"mcm","clk":"11450508480","pt":1717322835884,"mc":[{"id":"1.229554926","rc":[{"atb":[[1.72,0]],"id":47148562}],"con":true,"img":false}]}
{"op":"mcm","clk":"11450508908","pt":1717322840509,"mc":[{"id":"1.229554926","rc":[{"atb":[[1.61,0]],"id":47148562},{"atb":[[1.34,0]],"id":49546922}],"con":true,"img":false}]}
{"op":"mcm","clk":"11450510347","pt":1717322856481,"mc":[{"id":"1.229554926","rc":[{"atb":[[1.67,5.85]],"id":47148562}],"con":true,"img":false}]}
{"op":"mcm","clk":"11450510687","pt":1717322860056,"mc":[{"id":"1.229554926","rc":[{"atb":[[2.56,0]],"id":48638605},{"atb":[[1.31,0]],"id":49546922}],"con":true,"img":false}]}
{"op":"mcm","clk":"11450510696","pt":1717322860159,"mc":[{"id":"1.229554926","rc":[{"atb":[[2.86,22.03]],"id":48638605},{"atb":[[1.43,44.05]],"id":49546922}],"con":true,"img":false}]}
{"op":"mcm","clk":"11450512283","pt":1717322875271,"mc":[{"id":"1.229554926","rc":[{"atb":[[1.56,7.6]],"id":47148562},{"spn":3.83,"spf":"NaN","id":47148562},{"spn":2.78,"spf":"NaN","id":49546922},{"spn":2.0,"spf":"NaN","id":70003372}],"con":true,"img":false}]}
{"op":"mcm","clk":"11450512313","pt":1717322875474,"mc":[{"id":"1.229554926","rc":[{"atb":[[1.33,12.91]],"id":49546922}],"con":true,"img":false}]}
{"op":"mcm","clk":"11450512548","pt":1717322877664,"mc":[{"id":"1.229554926","rc":[{"atb":[[3.25,0]],"id":48638605},{"atb":[[1.46,0]],"id":49546922}],"con":true,"img":false}]}
{"op":"mcm","clk":"11450514897","pt":1717322899727,"mc":[{"id":"1.229554926","rc":[{"atb":[[1.45,8.72]],"id":49546922}],"con":true,"img":false}]}
{"op":"mcm","clk":"11450514917","pt":1717322899932,"mc":[{"id":"1.229554926","rc":[{"atb":[[1.01,19.71]],"id":48638605}],"con":true,"img":false}]}
{"op":"mcm","clk":"11450514968","pt":1717322900416,"mc":[{"id":"1.229554926","rc":[{"atb":[[1.01,19.38]],"id":48638605}],"con":true,"img":false}]}
{"op":"mcm","clk":"11450515000","pt":1717322900727,"mc":[{"id":"1.229554926","rc":[{"atb":[[1.01,17.35]],"id":48638605}],"con":true,"img":false}]}
{"op":"mcm","clk":"11450515013","pt":1717322900826,"mc":[{"id":"1.229554926","rc":[{"atb":[[2.94,2.02]],"id":48638605}],"con":true,"img":false}]}
{"op":"mcm","clk":"11450539327","pt":1717323141563,"mc":[{"id":"1.229554926","rc":[{"atb":[[1.64,0],[1.54,185.19]],"id":47148562},{"atl":[[6,0]],"id":47148562},{"spn":4.43,"spf":"NaN","id":47148562},{"atb":[[4.3,13.5],[3.65,0]],"id":64343695},{"atb":[[3.1,0],[2.84,0]],"id":48638605},{"spn":15.47,"spf":"NaN","id":48638605},{"atb":[[1.32,0],[1.42,0]],"id":49546922},{"atl":[[4.1,0]],"id":49546922},{"spn":3.72,"spf":"NaN","id":49546922},{"atb":[[1.01,0],[1.05,0]],"id":70003372},{"atl":[[2.86,0]],"id":70003372},{"spn":2.17,"spf":"NaN","id":70003372},{"atb":[[8.6,0],[6.6,0]],"id":40917581}],"con":true,"img":false}]}
{"op":"mcm","clk":"11450539471","pt":1717323142667,"mc":[{"id":"1.229554926","rc":[{"atb":[[2.86,0]],"id":48638605},{"atb":[[1.43,0]],"id":49546922}],"con":true,"img":false}]}
{"op":"mcm","clk":"11450539486","pt":1717323142771,"mc":[{"id":"1.229554926","rc":[{"atb":[[2.56,22.03]],"id":48638605},{"atb":[[1.31,44.05]],"id":49546922}],"con":true,"img":false}]}
{"op":"mcm","clk":"11450540612","pt":1717323152809,"mc":[{"id":"1.229554926","rc":[{"atb":[[1.56,69.83],[1.66,35.19]],"id":47148562},{"atl":[[6.2,0.09]],"id":47148562},{"atb":[[3.7,12.9],[4.4,6.83]],"id":64343695},{"atb":[[2.82,19.14],[3.05,11.33]],"id":48638605},{"atb":[[1.32,108.88],[1.42,55.3]],"id":49546922},{"atl":[[4.1,0.16]],"id":49546922},{"atb":[[1.01,3484.35],[1.04,580.72]],"id":70003372},{"atl":[[2.84,0.28]],"id":70003372},{"atb":[[8.6,3.05],[6.6,6.22]],"id":40917581}],"con":true,"img":false}]}
{"op":"mcm","clk":"11450541488","pt":1717323160294,"mc":[{"id":"1.229554926","rc":[{"atb":[[1.56,62.22]],"id":47148562}],"con":true,"img":false}]}
{"op":"mcm","clk":"11450542698","pt":1717323171602,"mc":[{"id":"1.229554926","rc":[{"atb":[[1.67,0]],"id":47148562}],"con":true,"img":false}]}
{"op":"mcm","clk":"11450542883","pt":1717323173324,"mc":[{"id":"1.229554926","rc":[{"atb":[[1.69,5.68]],"id":47148562}],"con":true,"img":false}]}
{"op":"mcm","clk":"11450543979","pt":1717323182761,"mc":[{"id":"1.229554926","rc":[{"atb":[[1.55,0]],"id":47148562}],"con":true,"img":false}]}
{"op":"mcm","clk":"11450543995","pt":1717323182879,"mc":[{"id":"1.229554926","rc":[{"atb":[[1.57,40.83]],"id":47148562}],"con":true,"img":false}]}
{"op":"mcm","clk":"11450545107","pt":1717323192666,"mc":[{"id":"1.229554926","rc":[{"atb":[[2.56,0]],"id":48638605},{"atb":[[1.31,0]],"id":49546922}],"con":true,"img":false}]}
{"op":"mcm","clk":"11450545117","pt":1717323192768,"mc":[{"id":"1.229554926","rc":[{"atb":[[2.84,22.03]],"id":48638605},{"atb":[[1.43,44.05]],"id":49546922}],"con":true,"img":false}]}
{"op":"mcm","clk":"11450545939","pt":1717323200377,"mc":[{"id":"1.229554926","rc":[{"atb":[[1.58,7.34]],"id":47148562}],"con":true,"img":false}]}
{"op":"mcm","clk":"11450547044","pt":1717323210680,"mc":[{"id":"1.229554926","rc":[{"spn":3.94,"spf":"NaN","id":47148562},{"spn":32.2,"spf":"NaN","id":64343695},{"atb":[[2.94,0]],"id":48638605},{"spn":15.52,"spf":"NaN","id":48638605},{"atb":[[1.45,0]],"id":49546922},{"spn":2.76,"spf":"NaN","id":49546922},{"spn":1.99,"spf":"NaN","id":70003372}],"con":true,"img":false}]}
{"op":"mcm","clk":"11450548338","pt":1717323222724,"mc":[{"id":"1.229554926","rc":[{"atb":[[2.84,0]],"id":48638605}],"con":true,"img":false}]}
{"op":"mcm","clk":"11450548352","pt":1717323222858,"mc":[{"id":"1.229554926","rc":[{"atb":[[3.1,22.03]],"id":48638605}],"con":true,"img":false}]}
{"op":"mcm","clk":"11450551194","pt":1717323248091,"mc":[{"id":"1.229554926","rc":[{"atb":[[1.59,40.87],[1.54,0]],"id":47148562},{"atb":[[4,20.33],[3.75,0]],"id":64343695}],"con":true,"img":false}]}
{"op":"mcm","clk":"11450551202","pt":1717323248133,"mc":[{"id":"1.229554926","rc":[{"atl":[[3.2,0],[2.98,19.47]],"id":70003372}],"con":true,"img":false}]}
{"op":"mcm","clk":"11450551691","pt":1717323252651,"mc":[{"id":"1.229554926","rc":[{"atb":[[3.8,0]],"id":64343695}],"con":true,"img":false}]}
{"op":"mcm","clk":"11450551695","pt":1717323252748,"mc":[{"id":"1.229554926","rc":[{"atb":[[3.75,17.21]],"id":64343695}],"con":true,"img":false}]}
{"op":"mcm","clk":"11450551750","pt":1717323253264,"mc":[{"id":"1.229554926","rc":[{"atb":[[1.59,0],[1.55,161.06]],"id":47148562}],"con":true,"img":false}]}
{"op":"mcm","clk":"11450557464","pt":1717323305791,"mc":[{"id":"1.229554926","rc":[{"spn":15.55,"spf":"NaN","id":48638605},{"atb":[[1.45,8.72]],"id":49546922},{"spn":2.77,"spf":"NaN","id":49546922}],"con":true,"img":false}]}
{"op":"mcm","clk":"11450557496","pt":1717323306065,"mc":[{"id":"1.229554926","rc":[{"atb":[[1.01,19.71]],"id":48638605}],"con":true,"img":false}]}
{"op":"mcm","clk":"11450557608","pt":1717323307146,"mc":[{"id":"1.229554926","rc":[{"atb":[[1.01,19.14]],"id":48638605}],"con":true,"img":false}]}
{"op":"mcm","clk":"11450557649","pt":1717323307461,"mc":[{"id":"1.229554926","rc":[{"atb":[[1.01,17.35]],"id":48638605}],"con":true,"img":false}]}
{"op":"mcm","clk":"11450557661","pt":1717323307522,"mc":[{"id":"1.229554926","rc":[{"atb":[[3.2,1.78]],"id":48638605}],"con":true,"img":false}]}
{"op":"mcm","clk":"11450561612","pt":1717323342675,"mc":[{"id":"1.229554926","rc":[{"atb":[[4.3,0]],"id":64343695}],"con":true,"img":false}]}
{"op":"mcm","clk":"11450561626","pt":1717323342792,"mc":[{"id":"1.229554926","rc":[{"atb":[[4.5,13.5]],"id":64343695}],"con":true,"img":false}]}
{"op":"mcm","clk":"11450562729","pt":1717323352710,"mc":[{"id":"1.229554926","rc":[{"atb":[[4.5,0]],"id":64343695}],"con":true,"img":false}]}
{"op":"mcm","clk":"11450562740","pt":1717323352813,"mc":[{"id":"1.229554926","rc":[{"atb":[[4.1,13.5]],"id":64343695}],"con":true,"img":false}]}
{"op":"mcm","clk":"11450564619","pt":1717323369258,"mc":[{"id":"1.229554926","rc":[{"atb":[[4,0],[3.75,44.21]],"id":64343695},{"spn":15.6,"spf":"NaN","id":48638605},{"atl":[[3.2,19.75],[2.98,0]],"id":70003372}],"con":true,"img":false}]}
{"op":"mcm","clk":"11450578795","pt":1717323487255,"mc":[{"id":"1.229554926","rc":[{"atb":[[1.56,0],[1.66,0]],"id":47148562},{"atl":[[6.2,0]],"id":47148562},{"spn":4.44,"spf":"NaN","id":47148562},{"atb":[[3.7,0],[4.4,0]],"id":64343695},{"spn":32.05,"spf":"NaN","id":64343695},{"atb":[[2.82,0],[3.05,0]],"id":48638605},{"atb":[[1.32,0],[1.42,0]],"id":49546922},{"atl":[[4.1,0]],"id":49546922},{"spn":3.72,"spf":"NaN","id":49546922},{"atb":[[1.01,0],[1.04,0]],"id":70003372},{"atl":[[2.84,0]],"id":70003372},{"spn":2.17,"spf":"NaN","id":70003372},{"atb":[[8.6,0],[6.6,0]],"id":40917581}],"con":true,"img":false}]}
{"op":"mcm","clk":"11450579392","pt":1717323492755,"mc":[{"id":"1.229554926","rc":[{"atb":[[1.57,0]],"id":47148562},{"atb":[[3.1,0]],"id":48638605},{"atb":[[1.43,0]],"id":49546922}],"con":true,"img":false}]}
{"op":"mcm","clk":"11450579401","pt":1717323492858,"mc":[{"id":"1.229554926","rc":[{"atb":[[1.56,40.83]],"id":47148562},{"atb":[[2.56,22.03]],"id":48638605},{"atb":[[1.31,44.05]],"id":49546922}],"con":true,"img":false}]}
{"op":"mcm","clk":"11450579729","pt":1717323495846,"mc":[{"id":"1.229554926","rc":[{"atb":[[1.58,0]],"id":47148562},{"atb":[[1.33,0]],"id":49546922}],"con":true,"img":false}]}
{"op":"mcm","clk":"11450579871","pt":1717323497097,"mc":[{"id":"1.229554926","rc":[{"atb":[[1.6,58.07],[1.7,33.18]],"id":47148562},{"atl":[[6.6,0.09]],"id":47148562},{"atb":[[3.7,12.9],[4.4,6.83]],"id":64343695},{"atb":[[3.1,11.05],[2.84,18.93]],"id":48638605},{"atb":[[1.36,64.52],[1.26,134.01]],"id":49546922},{"atl":[[3.75,0.18]],"id":49546922},{"atb":[[1.01,3484.35],[1.03,3682.26]],"id":70003372},{"atl":[[2.84,0.28]],"id":70003372},{"atb":[[7.2,5.61],[9.2,2.83]],"id":40917581}],"con":true,"img":false}]}
{"op":"mcm","clk":"11450580887","pt":1717323506827,"mc":[{"id":"1.229554926","rc":[{"atb":[[1.69,0]],"id":47148562}],"con":true,"img":false}]}
{"op":"mcm","clk":"11450580909","pt":1717323507037,"mc":[{"id":"1.229554926","rc":[{"atb":[[1.73,5.36]],"id":47148562}],"con":true,"img":false}]}
{"op":"mcm","clk":"11450583039","pt":1717323527465,"mc":[{"id":"1.229554926","rc":[{"atb":[[1.62,6.86]],"id":47148562},{"atb":[[1.37,11.51]],"id":49546922}],"con":true,"img":false}]}
{"op":"mcm","clk":"11450583575","pt":1717323532675,"mc":[{"id":"1.229554926","rc":[{"atb":[[2.56,0]],"id":48638605},{"atb":[[1.31,0]],"id":49546922}],"con":true,"img":false}]}
{"op":"mcm","clk":"11450583586","pt":1717323532779,"mc":[{"id":"1.229554926","rc":[{"atb":[[2.86,22.03]],"id":48638605},{"atb":[[1.37,55.56]],"id":49546922}],"con":true,"img":false}]}
{"op":"mcm","clk":"11450586434","pt":1717323562653,"mc":[{"id":"1.229554926","rc":[{"spn":4.16,"spf":"NaN","id":47148562},{"spn":32.2,"spf":"NaN","id":64343695},{"atb":[[2.86,0]],"id":48638605},{"spn":2.6,"spf":"NaN","id":49546922},{"spn":1.99,"spf":"NaN","id":70003372}],"con":true,"img":false}]}
{"op":"mcm","clk":"11450586446","pt":1717323562756,"mc":[{"id":"1.229554926","rc":[{"atb":[[3.15,22.03]],"id":48638605}],"con":true,"img":false}]}
{"op":"mcm","clk":"11450586896","pt":1717323566641,"mc":[{"id":"1.229554926","rc":[{"atb":[[3.2,0]],"id":48638605}],"con":true,"img":false}]}
{"op":"mcm","clk":"11450586967","pt":1717323567437,"mc":[{"id":"1.229554926","rc":[{"atb":[[1.01,19.71]],"id":48638605}],"con":true,"img":false}]}
{"op":"mcm","clk":"11450586986","pt":1717323567644,"mc":[{"id":"1.229554926","rc":[{"atb":[[1.01,19.1]],"id":48638605}],"con":true,"img":false}]}
{"op":"mcm","clk":"11450587033","pt":1717323568160,"mc":[{"id":"1.229554926","rc":[{"atb":[[1.01,17.35]],"id":48638605}],"con":true,"img":false}]}
{"op":"mcm","clk":"11450587043","pt":1717323568265,"mc":[{"id":"1.229554926","rc":[{"atb":[[3.25,1.74]],"id":48638605}],"con":true,"img":false}]}
{"op":"mcm","clk":"11450587097","pt":1717323568849,"mc":[{"id":"1.229554926","rc":[{"atb":[[1.45,0]],"id":49546922}],"con":true,"img":false}]}
{"op":"mcm","clk":"11450588622","pt":1717323584256,"mc":[{"id":"1.229554926","rc":[{"atb":[[1.38,10.33]],"id":49546922}],"con":true,"img":false}]}
{"op":"mcm","clk":"11450596265","pt":1717323662349,"mc":[{"id":"1.229554926","rc":[{"atb":[[1.73,7.5]],"id":47148562},{"spn":15.62,"spf":"NaN","id":48638605},{"atb":[[1.41,2.13]],"id":49546922},{"spn":2.58,"spf":"NaN","id":49546922}],"con":true,"img":false}]}
{"op":"mcm","clk":"11450603202","pt":1717323733845,"mc":[{"id":"1.229554926","rc":[{"atb":[[3.9,3.57]],"id":64343695},{"atb":[[2.5,6.92]],"id":48638605},{"atb":[[1.29,211.63]],"id":49546922},{"atb":[[1.13,30.08]],"id":70003372},{"atl":[[4.4,3.19]],"id":70003372}],"con":true,"img":false}]}
{"op":"mcm","clk":"11450603722","pt":1717323739267,"mc":[{"id":"1.229554926","rc":[{"atl":[[4.4,0]],"id":70003372}],"con":true,"img":false}]}
{"op":"mcm","clk":"11450608556","pt":1717323791157,"mc":[{"id":"1.229554926","rc":[{"atl":[[4.4,3.19]],"id":70003372}],"con":true,"img":false}]}
{"op":"mcm","clk":"11450614299","pt":1717323847685,"mc":[{"id":"1.229554926","rc":[{"atb":[[1.6,0],[1.7,0]],"id":47148562},{"atl":[[6.6,0]],"id":47148562},{"spn":4.46,"spf":"NaN","id":47148562},{"atb":[[3.7,0],[4.4,0]],"id":64343695},{"spn":32.05,"spf":"NaN","id":64343695},{"atb":[[3.1,0],[2.84,0]],"id":48638605},{"atb":[[1.36,0],[1.26,0]],"id":49546922},{"atl":[[3.75,0]],"id":49546922},{"spn":3.7,"spf":"NaN","id":49546922},{"atb":[[1.01,0],[1.03,2907.96]],"id":70003372},{"atl":[[2.84,0]],"id":70003372},{"spn":2.17,"spf":"NaN","id":70003372},{"atb":[[7.2,0],[9.2,0]],"id":40917581}],"con":true,"img":false}]}
{"op":"mcm","clk":"11450614538","pt":1717323849788,"mc":[{"id":"1.229554926","rc":[{"atb":[[1.73,5.36]],"id":47148562}],"con":true,"img":false}]}
{"op":"mcm","clk":"11450614549","pt":1717323849894,"mc":[{"id":"1.229554926","rc":[{"atb":[[1.51,12.03],[1.65,2.13]],"id":47148562}],"con":true,"img":false}]}
{"op":"mcm","clk":"11450614873","pt":1717323852674,"mc":[{"id":"1.229554926","rc":[{"atb":[[3.15,0]],"id":48638605},{"atb":[[1.37,11.51]],"id":49546922}],"con":true,"img":false}]}
{"op":"mcm","clk":"11450614886","pt":1717323852781,"mc":[{"id":"1.229554926","rc":[{"atb":[[1.51,0]],"id":47148562},{"atb":[[2.56,22.03]],"id":48638605},{"atb":[[1.31,44.05]],"id":49546922}],"con":true,"img":false}]}
{"op":"mcm","clk":"11450615016","pt":1717323853879,"mc":[{"id":"1.229554926","rc":[{"atb":[[2.62,2.13]],"id":48638605}],"con":true,"img":false}]}
{"op":"mcm","clk":"11450616034","pt":1717323862308,"mc":[{"id":"1.229554926","rc":[{"atb":[[1.62,0]],"id":47148562},{"atb":[[1.37,0]],"id":49546922}],"con":true,"img":false}]}
{"op":"mcm","clk":"11450616134","pt":1717323863090,"mc":[{"id":"1.229554926","rc":[{"atb":[[1.56,103.05],[1.66,35.19]],"id":47148562},{"atl":[[6.2,0.09]],"id":47148562},{"atb":[[3.6,13.4],[4.2,7.26]],"id":64343695},{"atb":[[3.1,11.05],[2.84,18.93]],"id":48638605},{"atb":[[1.45,51.62],[1.35,99.55]],"id":49546922},{"atl":[[4.2,0.16]],"id":49546922},{"atb":[[1.01,3484.35],[1.02,1250.22]],"id":70003372},{"atl":[[2.82,0.28]],"id":70003372},{"atb":[[6.8,6],[8.8,2.97]],"id":40917581}],"con":true,"img":false}]}
{"op":"mcm","clk":"11450616509","pt":1717323866120,"mc":[{"id":"1.229554926","rc":[{"atb":[[1.41,0],[1.48,2.13]],"id":49546922}],"con":true,"img":false}]}
{"op":"mcm","clk":"11450617453","pt":1717323874341,"mc":[{"id":"1.229554926","rc":[{"atb":[[1.38,0]],"id":49546922}],"con":true,"img":false}]}
{"op":"mcm","clk":"11450617477","pt":1717323874543,"mc":[{"id":"1.229554926","rc":[{"atb":[[1.47,8.35]],"id":49546922}],"con":true,"img":false}]}
{"op":"mcm","clk":"11450619971","pt":1717323900457,"mc":[{"id":"1.229554926","rc":[{"atb":[[1.29,197.59]],"id":49546922}],"con":true,"img":false}]}
{"op":"mcm","clk":"11450620063","pt":1717323901349,"mc":[{"id":"1.229554926","rc":[{"atb":[[1.55,173.09]],"id":47148562}],"con":true,"img":false}]}
{"op":"mcm","clk":"11450620130","pt":1717323901937,"mc":[{"id":"1.229554926","rc":[{"atb":[[1.58,7.34]],"id":47148562}],"con":true,"img":false}]}
{"op":"mcm","clk":"11450620138","pt":1717323902038,"mc":[{"id":"1.229554926","rc":[{"atb":[[1.36,11.83]],"id":49546922}],"con":true,"img":false}]}
{"op":"mcm","clk":"11450620179","pt":1717323902464,"mc":[{"id":"1.229554926","rc":[{"atb":[[1.29,211.63]],"id":49546922}],"con":true,"img":false}]}
{"op":"mcm","clk":"11450620196","pt":1717323902668,"mc":[{"id":"1.229554926","rc":[{"atb":[[2.56,0]],"id":48638605},{"atb":[[1.31,0]],"id":49546922}],"con":true,"img":false}]}
{"op":"mcm","clk":"11450620216","pt":1717323902872,"mc":[{"id":"1.229554926","rc":[{"atb":[[3.15,22.03]],"id":48638605},{"atb":[[1.46,44.05],[1.29,197.59]],"id":49546922}],"con":true,"img":false}]}
{"op":"mcm","clk":"11450621118","pt":1717323912159,"mc":[{"id":"1.229554926","rc":[{"spn":3.96,"spf":"NaN","id":47148562},{"spn":32.1,"spf":"NaN","id":64343695},{"atb":[[1.47,0]],"id":49546922},{"spn":2.84,"spf":"NaN","id":49546922},{"spn":1.98,"spf":"NaN","id":70003372}],"con":true,"img":false}]}
{"op":"mcm","clk":"11450621155","pt":1717323912684,"mc":[{"id":"1.229554926","rc":[{"atb":[[1.48,10.31]],"id":49546922}],"con":true,"img":false}]}
{"op":"mcm","clk":"11450621163","pt":1717323912788,"mc":[{"id":"1.229554926","rc":[{"atb":[[1.55,161.06]],"id":47148562}],"con":true,"img":false}]}
{"op":"mcm","clk":"11450622923","pt":1717323930414,"mc":[{"id":"1.229554926","rc":[{"atb":[[1.73,0]],"id":47148562},{"atb":[[3.25,0]],"id":48638605}],"con":true,"img":false}]}
{"op":"mcm","clk":"11450622954","pt":1717323930620,"mc":[{"id":"1.229554926","rc":[{"atb":[[1.55,0],[1.51,161.06]],"id":47148562}],"con":true,"img":false}]}
{"op":"mcm","clk":"11450623949","pt":1717323940935,"mc":[{"id":"1.229554926","rc":[{"atb":[[1.55,161.06],[1.51,0]],"id":47148562},{"atb":[[4,20.76],[3.9,0],[3.75,17.21]],"id":64343695},{"atl":[[3.2,0],[3.05,19.47]],"id":70003372}],"con":true,"img":false}]}
{"op":"mcm","clk":"11450623959","pt":1717323940996,"mc":[{"id":"1.229554926","rc":[{"atb":[[3.9,3.57]],"id":64343695},{"atl":[[4.4,0]],"id":70003372}],"con":true,"img":false}]}
{"op":"mcm","clk":"11450623970","pt":1717323941110,"mc":[{"id":"1.229554926","rc":[{"atl":[[4.4,3.19]],"id":70003372}],"con":true,"img":false}]}
{"op":"mcm","clk":"11450624117","pt":1717323942724,"mc":[{"id":"1.229554926","rc":[{"atb":[[3.15,0]],"id":48638605}],"con":true,"img":false}]}
{"op":"mcm","clk":"11450624127","pt":1717323942831,"mc":[{"id":"1.229554926","rc":[{"atb":[[2.86,22.03]],"id":48638605}],"con":true,"img":false}]}
{"op":"mcm","clk":"11450624515","pt":1717323946401,"mc":[{"id":"1.229554926","rc":[{"atb":[[4,0],[3.95,27]],"id":64343695},{"atb":[[1.03,0],[1.05,2000]],"id":70003372},{"atb":[[10,16.56],[12,4.4]],"id":40917581},{"atl":[[550,0],[480,2]],"id":40917581}],"con":true,"img":false}]}
{"op":"mcm","clk":"11450624534","pt":1717323946608,"mc":[{"id":"1.229554926","rc":[{"atb":[[1.13,0]],"id":70003372}],"con":true,"img":false}]}
{"op":"mcm","clk":"11450624543","pt":1717323946718,"mc":[{"id":"1.229554926","rc":[{"atb":[[1.13,30.08]],"id":70003372}],"con":true,"img":false}]}
{"op":"mcm","clk":"11450624630","pt":1717323947905,"mc":[{"id":"1.229554926","rc":[{"atb":[[1.69,5.69]],"id":47148562},{"atb":[[1.01,19.71]],"id":48638605}],"con":true,"img":false}]}
{"op":"mcm","clk":"11450624640","pt":1717323948005,"mc":[{"id":"1.229554926","rc":[{"atl":[[6.2,0]],"id":49546922}],"con":true,"img":false}]}
{"op":"mcm","clk":"11450624650","pt":1717323948112,"mc":[{"id":"1.229554926","rc":[{"atb":[[1.01,19.38]],"id":48638605}],"con":true,"img":false}]}
{"op":"mcm","clk":"11450624658","pt":1717323948211,"mc":[{"id":"1.229554926","rc":[{"atl":[[6.2,10.41]],"id":49546922}],"con":true,"img":false}]}
{"op":"mcm","clk":"11450624667","pt":1717323948317,"mc":[{"id":"1.229554926","rc":[{"atb":[[1.01,17.35]],"id":48638605}],"con":true,"img":false}]}
{"op":"mcm","clk":"11450624677","pt":1717323948419,"mc":[{"id":"1.229554926","rc":[{"atb":[[2.94,2.02]],"id":48638605}],"con":true,"img":false}]}
{"op":"mcm","clk":"11450624825","pt":1717323950300,"mc":[{"id":"1.229554926","rc":[{"atb":[[1.55,173.09]],"id":47148562}],"con":true,"img":false}]}
{"op":"mcm","clk":"11450624897","pt":1717323951188,"mc":[{"id":"1.229554926","rc":[{"atb":[[1.55,12.03],[1.61,103.06]],"id":47148562},{"atl":[[2.92,19.47],[3.05,0]],"id":70003372}],"con":true,"img":false}]}
{"op":"mcm","clk":"11450624904","pt":1717323951297,"mc":[{"id":"1.229554926","rc":[{"atb":[[1.37,14.04]],"id":49546922}],"con":true,"img":false}]}
{"op":"mcm","clk":"11450625014","pt":1717323952490,"mc":[{"id":"1.229554926","rc":[{"atb":[[1.55,10.8]],"id":47148562}],"con":true,"img":false}]}
{"op":"mcm","clk":"11450625252","pt":1717323955438,"mc":[{"id":"1.229554926","rc":[{"atb":[[1.65,0],[1.69,7.82]],"id":47148562}],"con":true,"img":false}]}
{"op":"mcm","clk":"11450625354","pt":1717323956639,"mc":[{"id":"1.229554926","rc":[{"atb":[[4,20.76]],"id":64343695}],"con":true,"img":false}]}
{"op":"mcm","clk":"11450625364","pt":1717323956743,"mc":[{"id":"1.229554926","rc":[{"atb":[[3.95,0]],"id":64343695}],"con":true,"img":false}]}
{"op":"mcm","clk":"11450625378","pt":1717323956843,"mc":[{"id":"1.229554926","rc":[{"atb":[[1.55,0]],"id":47148562}],"con":true,"img":false}]}
{"op":"mcm","clk":"11450625466","pt":1717323957829,"mc":[{"id":"1.229554926","rc":[{"atb":[[12,0]],"id":40917581}],"con":true,"img":false}]}
{"op":"mcm","clk":"11450625473","pt":1717323957931,"mc":[{"id":"1.229554926","rc":[{"atb":[[11,4.4]],"id":40917581}],"con":true,"img":false}]}
{"op":"mcm","clk":"11450625863","pt":1717323962410,"mc":[{"id":"1.229554926","rc":[{"atl":[[4.4,0]],"id":70003372}],"con":true,"img":false}]}
{"op":"mcm","clk":"11450626508","pt":1717323970331,"mc":[{"id":"1.229554926","rc":[{"atb":[[1.58,0]],"id":47148562}],"con":true,"img":false}]}
{"op":"mcm","clk":"11450626657","pt":1717323971638,"mc":[{"id":"1.229554926","rc":[{"atb":[[1.56,40.83],[1.66,0]],"id":47148562},{"atl":[[6.2,0]],"id":47148562},{"atb":[[3.1,0],[2.84,0]],"id":48638605},{"atb":[[1.45,0],[1.35,0]],"id":49546922},{"atl":[[4.2,0]],"id":49546922},{"atb":[[1.01,0],[1.02,88.77]],"id":70003372},{"atl":[[2.82,0]],"id":70003372},{"atb":[[6.8,0],[8.8,0]],"id":40917581}],"con":true,"img":false}]}
{"op":"mcm","clk":"11450626751","pt":1717323972645,"mc":[{"id":"1.229554926","rc":[{"spn":4.44,"spf":"NaN","id":47148562},{"atb":[[2.86,0]],"id":48638605},{"spn":15.47,"spf":"NaN","id":48638605},{"spn":3.74,"spf":"NaN","id":49546922},{"spn":2.03,"spf":"NaN","id":70003372},{"atl":[[290,0]],"id":40917581},{"spn":170.5,"spf":"NaN","id":40917581}],"con":true,"img":false}]}
{"op":"mcm","clk":"11450626762","pt":1717323972748,"mc":[{"id":"1.229554926","rc":[{"atb":[[2.64,22.03]],"id":48638605},{"atl":[[220,0.14]],"id":40917581}],"con":true,"img":false}]}
{"op":"mcm","clk":"11450626772","pt":1717323972850,"mc":[{"id":"1.229554926","rc":[{"atb":[[1.37,0]],"id":49546922}],"con":true,"img":false}]}
{"op":"mcm","clk":"11450627049","pt":1717323975637,"mc":[{"id":"1.229554926","rc":[{"atb":[[1.64,2.13],[1.69,5.69]],"id":47148562}],"con":true,"img":false}]}
{"op":"mcm","clk":"11450627470","pt":1717323979871,"mc":[{"id":"1.229554926","rc":[{"atb":[[1.56,0]],"id":47148562},{"atb":[[1.46,0]],"id":49546922},{"atl":[[6.8,0]],"id":49546922}],"con":true,"img":false}]}
{"op":"mcm","clk":"11450627479","pt":1717323979974,"mc":[{"id":"1.229554926","rc":[{"atb":[[1.41,40.83]],"id":47148562},{"atb":[[1.32,44.05]],"id":49546922},{"atl":[[6,13.94]],"id":49546922}],"con":true,"img":false}]}
{"op":"mcm","clk":"11450627552","pt":1717323980962,"mc":[{"id":"1.229554926","rc":[{"atb":[[1.6,58.07],[1.7,33.18]],"id":47148562},{"atl":[[6.6,0.09]],"id":47148562},{"atb":[[2.82,19.14],[3.05,11.33]],"id":48638605},{"atb":[[1.32,152.94],[1.42,55.3]],"id":49546922},{"atl":[[4.1,0.16]],"id":49546922},{"atb":[[1.01,5807.26]],"id":70003372},{"atl":[[2.82,0.28]],"id":70003372},{"atb":[[8,3.31],[6,6.96]],"id":40917581}],"con":true,"img":false}]}
{"op":"mcm","clk":"11450627853","pt":1717323984159,"mc":[{"id":"1.229554926","rc":[{"atb":[[1.69,0]],"id":47148562}],"con":true,"img":false}]}
{"op":"mcm","clk":"11450627869","pt":1717323984373,"mc":[{"id":"1.229554926","rc":[{"atb":[[1.73,5.37]],"id":47148562}],"con":true,"img":false}]}
{"op":"mcm","clk":"11450628178","pt":1717323988059,"mc":[{"id":"1.229554926","rc":[{"atl":[[4.4,3.19]],"id":70003372}],"con":true,"img":false}]}
{"op":"mcm","clk":"11450628437","pt":1717323991286,"mc":[{"id":"1.229554926","rc":[{"atb":[[10,11.11],[11,0],[7.8,8.42]],"id":40917581}],"con":true,"img":false}]}
{"op":"mcm","clk":"11450628444","pt":1717323991389,"mc":[{"id":"1.229554926","rc":[{"atb":[[10,0],[9.2,4.4],[8.2,13.89]],"id":40917581}],"con":true,"img":false}]}
{"op":"mcm","clk":"11450628456","pt":1717323991492,"mc":[{"id":"1.229554926","rc":[{"atb":[[8.2,0],[9.4,4.41]],"id":40917581}],"con":true,"img":false}]}
{"op":"mcm","clk":"11450628595","pt":1717323992793,"mc":[{"id":"1.229554926","rc":[{"atl":[[330,0]],"id":40917581}],"con":true,"img":false}]}
{"op":"mcm","clk":"11450628605","pt":1717323992897,"mc":[{"id":"1.229554926","rc":[{"atl":[[860,2],[220,2.76]],"id":40917581}],"con":true,"img":false}]}
{"op":"mcm","clk":"11450628616","pt":1717323992955,"mc":[{"id":"1.229554926","rc":[{"atl":[[480,0]],"id":40917581}],"con":true,"img":false}]}
{"op":"mcm","clk":"11450629050","pt":1717323997784,"mc":[{"id":"1.229554926","rc":[{"atb":[[1.3,14.04]],"id":49546922}],"con":true,"img":false}]}
{"op":"mcm","clk":"11450629216","pt":1717323999707,"mc":[{"id":"1.229554926","rc":[{"atb":[[1.6,0],[1.7,0]],"id":47148562},{"atl":[[6.6,0]],"id":47148562},{"atb":[[3.6,0],[4.2,0]],"id":64343695},{"atb":[[2.82,0],[3.05,0]],"id":48638605},{"atb":[[1.32,44.05],[1.42,0]],"id":49546922},{"atl":[[4.1,0]],"id":49546922},{"atb":[[1.01,0]],"id":70003372},{"atl":[[2.82,0]],"id":70003372},{"atb":[[8,0],[6,0]],"id":40917581}],"con":true,"img":false}]}
{"op":"mcm","clk":"11450629323","pt":1717324000766,"mc":[{"id":"1.229554926","rc":[{"atb":[[1.39,12.03]],"id":47148562}],"con":true,"img":false}]}
{"op":"mcm","clk":"11450629527","pt":1717324002692,"mc":[{"id":"1.229554926","rc":[{"atl":[[860,0],[460,2]],"id":40917581}],"con":true,"img":false}]}
{"op":"mcm","clk":"11450629735","pt":1717324004825,"mc":[{"id":"1.229554926","rc":[{"atb":[[1.6,58.07],[1.7,33.18]],"id":47148562},{"atl":[[6.6,0.09]],"id":47148562},{"atb":[[4.3,7.03],[3.65,13.14]],"id":64343695},{"atb":[[2.82,19.14],[3.05,11.33]],"id":48638605},{"atb":[[1.43,54.02],[1.33,105.58]],"id":49546922},{"atl":[[4.1,0.16]],"id":49546922},{"atb":[[1.01,3484.35],[1.02,1250.22]],"id":70003372},{"atl":[[2.82,0.28]],"id":70003372},{"atb":[[7.8,11.83],[5.9,7.1]],"id":40917581}],"con":true,"img":false}]}
{"op":"mcm","clk":"11450629742","pt":1717324004874,"mc":[{"id":"1.229554926","rc":[{"atb":[[1.39,0]],"id":47148562}],"con":true,"img":false}]}
{"op":"mcm","clk":"11450629927","pt":1717324007014,"mc":[{"id":"1.229554926","rc":[{"atb":[[1.36,0]],"id":49546922}],"con":true,"img":false}]}
{"op":"mcm","clk":"11450629948","pt":1717324007271,"mc":[{"id":"1.229554926","rc":[{"atb":[[1.63,6.76]],"id":47148562}],"con":true,"img":false}]}
{"op":"mcm","clk":"11450630062","pt":1717324008414,"mc":[{"id":"1.229554926","rc":[{"atl":[[4.4,0]],"id":70003372}],"con":true,"img":false}]}
{"op":"mcm","clk":"11450630199","pt":1717324009979,"mc":[{"id":"1.229554926","rc":[{"atl":[[6.2,0]],"id":49546922}],"con":true,"img":false}]}
{"op":"mcm","clk":"11450630227","pt":1717324010396,"mc":[{"id":"1.229554926","rc":[{"atl":[[6,16.97]],"id":49546922}],"con":true,"img":false}]}
{"op":"mcm","clk":"11450630429","pt":1717324012696,"mc":[{"id":"1.229554926","rc":[{"atl":[[32,0]],"id":48638605},{"atl":[[6,10]],"id":49546922}],"con":true,"img":false}]}
{"op":"mcm","clk":"11450630438","pt":1717324012801,"mc":[{"id":"1.229554926","rc":[{"atl":[[34,2.61]],"id":48638605},{"atl":[[7,6.97]],"id":49546922}],"con":true,"img":false}]}
{"op":"mcm","clk":"11450631272","pt":1717324022626,"mc":[{"id":"1.229554926","rc":[{"atl":[[7.4,0]],"id":47148562}],"con":true,"img":false}]}
{"op":"mcm","clk":"11450631284","pt":1717324022729,"mc":[{"id":"1.229554926","rc":[{"atl":[[8.4,5.81]],"id":47148562}],"con":true,"img":false}]}
{"op":"mcm","clk":"11450631315","pt":1717324023039,"mc":[{"id":"1.229554926","rc":[{"atl":[[7.2,0],[8.8,8.98]],"id":47148562}],"con":true,"img":false}]}
{"op":"mcm","clk":"11450631339","pt":1717324023260,"mc":[{"id":"1.229554926","rc":[{"atl":[[8.2,7.32]],"id":47148562}],"con":true,"img":false}]}
{"op":"mcm","clk":"11450631348","pt":1717324023312,"mc":[{"id":"1.229554926","rc":[{"atl":[[8.8,0]],"id":47148562}],"con":true,"img":false}]}
{"op":"mcm","clk":"11450632165","pt":1717324032710,"mc":[{"id":"1.229554926","rc":[{"spn":4.16,"spf":"NaN","id":47148562},{"spn":32.15,"spf":"NaN","id":64343695},{"spn":15.52,"spf":"NaN","id":48638605},{"spn":2.79,"spf":"NaN","id":49546922},{"atl":[[4.4,3.19]],"id":70003372},{"spn":1.98,"spf":"NaN","id":70003372},{"spn":114.7,"spf":"NaN","id":40917581}],"con":true,"img":false}]}
{"op":"mcm","clk":"11450632970","pt":1717324042768,"mc":[{"id":"1.229554926","rc":[{"atb":[[2.64,0]],"id":48638605},{"atb":[[1.32,0]],"id":49546922}],"con":true,"img":false}]}
{"op":"mcm","clk":"11450632977","pt":1717324042829,"mc":[{"id":"1.229554926","rc":[{"atb":[[3.1,22.03]],"id":48638605},{"atb":[[1.44,44.05],[1.3,0]],"id":49546922}],"con":true,"img":false}]}
{"op":"mcm","clk":"11450633089","pt":1717324043971,"mc":[{"id":"1.229554926","rc":[{"atb":[[1.42,9.79]],"id":49546922}],"con":true,"img":false}]}
{"op":"mcm","clk":"11450633178","pt":1717324044838,"mc":[{"id":"1.229554926","rc":[{"atb":[[1.56,12.03]],"id":47148562}],"con":true,"img":false}]}
{"op":"mcm","clk":"11450633247","pt":1717324045756,"mc":[{"id":"1.229554926","rc":[{"atb":[[1.34,12.53]],"id":49546922}],"con":true,"img":false}]}
{"op":"mcm","clk":"11450633796","pt":1717324051960,"mc":[{"id":"1.229554926","rc":[{"atl":[[4.4,0]],"id":70003372}],"con":true,"img":false}]}
{"op":"mcm","clk":"11450633885","pt":1717324052838,"mc":[{"id":"1.229554926","rc":[{"atb":[[2.5,0]],"id":48638605}],"con":true,"img":false}]}
{"op":"mcm","clk":"11450633979","pt":1717324053930,"mc":[{"id":"1.229554926","rc":[{"atb":[[2.82,26.19]],"id":48638605}],"con":true,"img":false}]}
{"op":"mcm","clk":"11450634173","pt":1717324056315,"mc":[{"id":"1.229554926","rc":[{"atb":[[2.94,0]],"id":48638605},{"atb":[[1.48,2.13]],"id":49546922}],"con":true,"img":false}]}
{"op":"mcm","clk":"11450634708","pt":1717324062707,"mc":[{"id":"1.229554926","rc":[{"atl":[[9,0]],"id":47148562},{"atb":[[9.2,0]],"id":40917581}],"con":true,"img":false}]}
{"op":"mcm","clk":"11450634723","pt":1717324062811,"mc":[{"id":"1.229554926","rc":[{"atl":[[8,7.32]],"id":47148562},{"atb":[[9.6,4.4],[8,11.84]],"id":40917581}],"con":true,"img":false}]}
{"op":"mcm","clk":"11450634733","pt":1717324062914,"mc":[{"id":"1.229554926","rc":[{"atl":[[8.2,0],[7.8,7.32]],"id":47148562},{"atb":[[9.4,0]],"id":40917581}],"con":true,"img":false}]}
{"op":"mcm","clk":"11450635078","pt":1717324066622,"mc":[{"id":"1.229554926","rc":[{"atb":[[1.56,0]],"id":47148562},{"atb":[[4,0],[3.8,20.54],[3.9,7.98]],"id":64343695},{"atl":[[2.92,0],[2.98,19.76]],"id":70003372}],"con":true,"img":false}]}
{"op":"mcm","clk":"11450635089","pt":1717324066729,"mc":[{"id":"1.229554926","rc":[{"atb":[[3.9,3.57]],"id":64343695}],"con":true,"img":false}]}
{"op":"mcm","clk":"11450635129","pt":1717324067144,"mc":[{"id":"1.229554926","rc":[{"atb":[[1.73,0]],"id":47148562}],"con":true,"img":false}]}
{"op":"mcm","clk":"11450635137","pt":1717324067249,"mc":[{"id":"1.229554926","rc":[{"atb":[[1.57,161.06]],"id":47148562}],"con":true,"img":false}]}
{"op":"mcm","clk":"11450635149","pt":1717324067353,"mc":[{"id":"1.229554926","rc":[{"atb":[[1.61,0]],"id":47148562}],"con":true,"img":false}]}
{"op":"mcm","clk":"11450635584","pt":1717324071934,"mc":[{"id":"1.229554926","rc":[{"atb":[[8,0],[9.2,11.84]],"id":40917581}],"con":true,"img":false}]}
{"op":"mcm","clk":"11450635648","pt":1717324072764,"mc":[{"id":"1.229554926","rc":[{"atl":[[8,0]],"id":47148562},{"atb":[[3.1,0]],"id":48638605}],"con":true,"img":false}]}
{"op":"mcm","clk":"11450635659","pt":1717324072862,"mc":[{"id":"1.229554926","rc":[{"atl":[[9.4,7.32]],"id":47148562},{"atb":[[2.82,19.14],[2.84,22.03]],"id":48638605}],"con":true,"img":false}]}
{"op":"mcm","clk":"11450635856","pt":1717324075040,"mc":[{"id":"1.229554926","rc":[{"atb":[[1.73,5.37]],"id":47148562}],"con":true,"img":false}]}
{"op":"mcm","clk":"11450635865","pt":1717324075150,"mc":[{"id":"1.229554926","rc":[{"atl":[[4.4,3.19]],"id":70003372}],"con":true,"img":false}]}
{"op":"mcm","clk":"11450635874","pt":1717324075243,"mc":[{"id":"1.229554926","rc":[{"atb":[[1.01,19.71]],"id":48638605},{"atb":[[1.46,8.53]],"id":49546922}],"con":true,"img":false}]}
{"op":"mcm","clk":"11450635918","pt":1717324075664,"mc":[{"id":"1.229554926","rc":[{"atb":[[1.01,19.39]],"id":48638605}],"con":true,"img":false}]}
{"op":"mcm","clk":"11450635941","pt":1717324075873,"mc":[{"id":"1.229554926","rc":[{"atb":[[1.01,17.35]],"id":48638605}],"con":true,"img":false}]}
{"op":"mcm","clk":"11450635950","pt":1717324075980,"mc":[{"id":"1.229554926","rc":[{"atb":[[2.92,2.04]],"id":48638605}],"con":true,"img":false}]}
{"op":"mcm","clk":"11450636189","pt":1717324078980,"mc":[{"id":"1.229554926","rc":[{"atb":[[1.63,0]],"id":47148562}],"con":true,"img":false}]}
{"op":"mcm","clk":"11450636777","pt":1717324085550,"mc":[{"id":"1.229554926","rc":[{"atb":[[1.56,12.03]],"id":47148562}],"con":true,"img":false}]}
{"op":"mcm","clk":"11450636974","pt":1717324087985,"mc":[{"id":"1.229554926","rc":[{"atb":[[1.6,0],[1.7,0]],"id":47148562},{"atl":[[6.6,0]],"id":47148562},{"atb":[[4.3,0],[3.65,0]],"id":64343695},{"atb":[[2.82,0],[3.05,0]],"id":48638605},{"atb":[[1.43,0],[1.33,0]],"id":49546922},{"atl":[[4.1,0]],"id":49546922},{"atb":[[1.01,0],[1.02,88.77]],"id":70003372},{"atl":[[2.82,0]],"id":70003372},{"atb":[[7.8,8.42],[5.9,0]],"id":40917581}],"con":true,"img":false}]}
{"op":"mcm","clk":"11450636987","pt":1717324088093,"mc":[{"id":"1.229554926","rc":[{"atb":[[1.56,9.04]],"id":47148562},{"atl":[[8.2,13.89],[7.8,0]],"id":47148562},{"atb":[[1.42,11.48]],"id":49546922}],"con":true,"img":false}]}
{"op":"mcm","clk":"11450637007","pt":1717324088252,"mc":[{"id":"1.229554926","rc":[{"atb":[[1.42,9.79]],"id":49546922}],"con":true,"img":false}]}
{"op":"mcm","clk":"11450637362","pt":1717324092670,"mc":[{"id":"1.229554926","rc":[{"atb":[[1.41,0]],"id":47148562},{"atb":[[2.84,0]],"id":48638605},{"atb":[[1.44,0]],"id":49546922}],"con":true,"img":false}]}
{"op":"mcm","clk":"11450637374","pt":1717324092776,"mc":[{"id":"1.229554926","rc":[{"atb":[[1.56,0],[1.58,40.83]],"id":47148562},{"spn":4.96,"spf":"NaN","id":47148562},{"spn":32.05,"spf":"NaN","id":64343695},{"atb":[[2.62,24.16]],"id":48638605},{"spn":15.46,"spf":"NaN","id":48638605},{"atb":[[1.42,0],[1.31,44.05]],"id":49546922},{"spn":3.74,"spf":"NaN","id":49546922},{"spn":2.06,"spf":"NaN","id":70003372},{"spn":114.8,"spf":"NaN","id":40917581}],"con":true,"img":false}]}
{"op":"mcm","clk":"11450637502","pt":1717324094082,"mc":[{"id":"1.229554926","rc":[{"atb":[[1.71,32.71],[1.61,57.12]],"id":47148562},{"atl":[[6.6,0.09]],"id":47148562},{"atb":[[3.7,12.9],[4.4,6.83]],"id":64343695},{"atb":[[2.82,19.14],[3.05,11.33]],"id":48638605},{"atb":[[1.43,54.02],[1.33,105.58]],"id":49546922},{"atl":[[4.1,0.16]],"id":49546922},{"atb":[[1.01,5807.26]],"id":70003372},{"atl":[[2.78,0.29]],"id":70003372},{"atb":[[6.2,6.7],[8.2,3.22]],"id":40917581}],"con":true,"img":false}]}
{"op":"mcm","clk":"11450637603","pt":1717324095279,"mc":[{"id":"1.229554926","rc":[{"atb":[[2.54,7.06]],"id":48638605},{"atl":[[4.4,0]],"id":70003372}],"con":true,"img":false}]}
{"op":"mcm","clk":"11450638257","pt":1717324102672,"mc":[{"id":"1.229554926","rc":[{"atb":[[3.75,0]],"id":64343695}],"con":true,"img":false}]}
{"op":"mcm","clk":"11450638263","pt":1717324102772,"mc":[{"id":"1.229554926","rc":[{"atb":[[3.85,17.21]],"id":64343695}],"con":true,"img":false}]}
{"op":"mcm","clk":"11450638946","pt":1717324110398,"mc":[{"id":"1.229554926","rc":[{"atb":[[1.73,0]],"id":47148562}],"con":true,"img":false}]}
{"op":"mcm","clk":"11450639172","pt":1717324112694,"mc":[{"id":"1.229554926","rc":[{"atb":[[1.63,6.76]],"id":47148562},{"atl":[[8.4,0]],"id":47148562},{"atl":[[200,0.2],[220,2.61]],"id":40917581}],"con":true,"img":false}]}
{"op":"mcm","clk":"11450639181","pt":1717324112802,"mc":[{"id":"1.229554926","rc":[{"atl":[[8,5.81]],"id":47148562}],"con":true,"img":false}]}
{"op":"mcm","clk":"11450639191","pt":1717324112907,"mc":[{"id":"1.229554926","rc":[{"atl":[[9.2,12.2],[8.2,0]],"id":47148562}],"con":true,"img":false}]}
{"op":"mcm","clk":"11450639204","pt":1717324113008,"mc":[{"id":"1.229554926","rc":[{"atl":[[7.8,7.32]],"id":47148562}],"con":true,"img":false}]}
{"op":"mcm","clk":"11450639212","pt":1717324113112,"mc":[{"id":"1.229554926","rc":[{"atl":[[9.2,0]],"id":47148562}],"con":true,"img":false}]}
{"op":"mcm","clk":"11450640922","pt":1717324132737,"mc":[{"id":"1.229554926","rc":[{"atb":[[2.62,2.13]],"id":48638605},{"atb":[[1.31,0]],"id":49546922}],"con":true,"img":false}]}
{"op":"mcm","clk":"11450640937","pt":1717324132846,"mc":[{"id":"1.229554926","rc":[{"atb":[[3.1,22.03]],"id":48638605},{"atb":[[1.44,44.05]],"id":49546922}],"con":true,"img":false}]}
{"op":"mcm","clk":"11450641050","pt":1717324133832,"mc":[{"id":"1.229554926","rc":[{"atb":[[1.56,12.03]],"id":47148562}],"con":true,"img":false}]}
{"op":"mcm","clk":"11450641639","pt":1717324141131,"mc":[{"id":"1.229554926","rc":[{"atb":[[1.43,64.02],[1.51,2.5],[1.48,13.75],[1.47,5]],"id":49546922},{"atl":[[3.95,10],[3.55,2.5],[5.9,11.62],[3.75,5]],"id":49546922},{"atb":[[8.2,5.72],[9.8,4.39]],"id":40917581},{"atl":[[190,0.42]],"id":40917581}],"con":true,"img":false}]}
{"op":"mcm","clk":"11450641646","pt":1717324141231,"mc":[{"id":"1.229554926","rc":[{"atl":[[3.95,16.97]],"id":49546922}],"con":true,"img":false}]}
{"op":"mcm","clk":"11450641657","pt":1717324141337,"mc":[{"id":"1.229554926","rc":[{"atb":[[1.94,2.5],[1.71,42.14],[1.56,0],[1.9,5],[1.86,10]],"id":47148562},{"atl":[[4,10],[3.6,2.5],[3.8,5],[7.6,9.43]],"id":47148562},{"atb":[[4.5,6.14],[5.8,2.5],[5,10],[3.9,0],[5.4,5]],"id":64343695},{"atl":[[23,2.5],[27,5],[55,1.48]],"id":64343695},{"atb":[[2.54,0],[3.1,28.74],[3.25,2.5],[2.94,10],[3.05,16.33]],"id":48638605},{"atl":[[9.2,5],[10,10],[27,3.08],[8.4,2.5]],"id":48638605},{"atl":[[6,3.03]],"id":49546922},{"atb":[[1.15,5],[1.11,10],[1.19,2.5],[1.14,152.02],[1.13,21.59]],"id":70003372},{"atl":[[2.42,10],[2.6,37.38],[2.26,2.5],[2.34,5]],"id":70003372}],"con":true,"img":false}]}
{"op":"mcm","clk":"11450641669","pt":1717324141445,"mc":[{"id":"1.229554926","rc":[{"atl":[[4.4,5.81],[7.8,0]],"id":47148562},{"atl":[[10.5,2.62]],"id":48638605},{"atb":[[1.13,30.08]],"id":70003372},{"atl":[[2.42,29.47]],"id":70003372}],"con":true,"img":false}]}
{"op":"mcm","clk":"11450641679","pt":1717324141551,"mc":[{"id":"1.229554926","rc":[{"atl":[[28,2.61]],"id":48638605},{"atl":[[2.98,0]],"id":70003372}],"con":true,"img":false}]}
{"op":"mcm","clk":"11450641930","pt":1717324144518,"mc":[{"id":"1.229554926","rc":[{"atb":[[1.13,27.71]],"id":70003372}],"con":true,"img":false}]}
{"op":"mcm","clk":"11450642156","pt":1717324146467,"mc":[{"id":"1.229554926","rc":[{"atb":[[2.92,0]],"id":48638605}],"con":true,"img":false}]}
{"op":"mcm","clk":"11450642610","pt":1717324151165,"mc":[{"id":"1.229554926","rc":[{"atl":[[4,17.5]],"id":47148562}],"con":true,"img":false}]}
{"op":"mcm","clk":"11450642620","pt":1717324151263,"mc":[{"id":"1.229554926","rc":[{"atl":[[4.4,0]],"id":47148562}],"con":true,"img":false}]}
{"op":"mcm","clk":"11450642764","pt":1717324152651,"mc":[{"id":"1.229554926","rc":[{"atl":[[12.5,5.23]],"id":47148562},{"atb":[[2.64,32.54]],"id":64343695},{"atb":[[1.92,62.98]],"id":48638605},{"atb":[[6.4,10.61]],"id":40917581}],"con":true,"img":false}]}
{"op":"mcm","clk":"11450642775","pt":1717324152762,"mc":[{"id":"1.229554926","rc":[{"atl":[[9.4,0]],"id":47148562},{"atb":[[3.85,0],[4.1,0]],"id":64343695},{"atb":[[2.4,0],[3.1,6.71]],"id":48638605},{"atb":[[7.8,0]],"id":40917581}],"con":true,"img":false}]}
{"op":"mcm","clk":"11450642783","pt":1717324152863,"mc":[{"id":"1.229554926","rc":[{"spn":2.77,"spf":"NaN","id":47148562},{"atb":[[3.85,13.5]],"id":64343695},{"spn":14.4,"spf":"NaN","id":64343695},{"atb":[[2.4,22.03]],"id":48638605},{"spn":5.82,"spf":"NaN","id":48638605},{"spn":2.53,"spf":"NaN","id":49546922},{"spn":1.72,"spf":"NaN","id":70003372},{"spn":99.9,"spf":"NaN","id":40917581}],"con":true,"img":false}]}
{"op":"mcm","clk":"11450642915","pt":1717324154265,"mc":[{"id":"1.229554926","rc":[{"atl":[[4.6,0]],"id":70003372}],"con":true,"img":false}]}
{"op":"mcm","clk":"11450642922","pt":1717324154367,"mc":[{"id":"1.229554926","rc":[{"atl":[[5,17.26]],"id":70003372}],"con":true,"img":false}]}
{"op":"mcm","clk":"11450643283","pt":1717324158645,"mc":[{"id":"1.229554926","rc":[{"atb":[[1.51,10]],"id":49546922},{"atl":[[3.3,7.5]],"id":49546922}],"con":true,"img":false}]}
{"op":"mcm","clk":"11450643293","pt":1717324158751,"mc":[{"id":"1.229554926","rc":[{"atb":[[1.48,2.13]],"id":49546922},{"atl":[[3.95,10],[5.9,0],[3.75,10]],"id":49546922}],"con":true,"img":false}]}
{"op":"mcm","clk":"11450643307","pt":1717324158854,"mc":[{"id":"1.229554926","rc":[{"atb":[[1.94,10]],"id":47148562},{"atl":[[3.55,7.5]],"id":47148562},{"atb":[[5.9,5.62]],"id":64343695},{"atl":[[22,3.81]],"id":64343695},{"atb":[[3.35,8.78]],"id":48638605},{"atl":[[8.2,8.78]],"id":48638605},{"atb":[[1.19,10]],"id":70003372},{"atl":[[2.24,7.5]],"id":70003372}],"con":true,"img":false}]}
{"op":"mcm","clk":"11450643323","pt":1717324158965,"mc":[{"id":"1.229554926","rc":[{"atb":[[1.71,32.71]],"id":47148562},{"atl":[[7.6,0]],"id":47148562},{"atb":[[4.5,0]],"id":64343695},{"atl":[[55,0]],"id":64343695},{"atb":[[3.1,0]],"id":48638605},{"atl":[[10.5,0],[27,0],[9.4,7.5]],"id":48638605},{"atb":[[1.14,114.64]],"id":70003372},{"atl":[[2.42,10],[2.6,0],[2.34,34.47]],"id":70003372}],"con":true,"img":false}]}
{"op":"mcm","clk":"11450643626","pt":1717324161775,"mc":[{"id":"1.229554926","rc":[{"atb":[[2.46,0]],"id":48638605},{"atb":[[1.34,0]],"id":49546922}],"con":true,"img":false}]}
{"op":"mcm","clk":"11450643687","pt":1717324162245,"mc":[{"id":"1.229554926","rc":[{"atb":[[1.31,14.04]],"id":49546922}],"con":true,"img":false}]}
{"op":"mcm","clk":"11450643743","pt":1717324162654,"mc":[{"id":"1.229554926","rc":[{"atb":[[1.58,0]],"id":47148562},{"atl":[[8,0]],"id":47148562}],"con":true,"img":false}]}
{"op":"mcm","clk":"11450643761","pt":1717324162782,"mc":[{"id":"1.229554926","rc":[{"atb":[[1.62,40.83]],"id":47148562},{"atl":[[7.4,5.81]],"id":47148562}],"con":true,"img":false}]}
{"op":"mcm","clk":"11450644725","pt":1717324172689,"mc":[{"id":"1.229554926","rc":[{"atl":[[60,0]],"id":64343695},{"atl":[[28,0]],"id":48638605},{"atb":[[1.14,0]],"id":70003372},{"atb":[[9.6,0]],"id":40917581}],"con":true,"img":false}]}
{"op":"mcm","clk":"11450644735","pt":1717324172797,"mc":[{"id":"1.229554926","rc":[{"atl":[[26,2.61]],"id":64343695},{"atl":[[19,2.61]],"id":48638605},{"atb":[[1.18,114.64],[1.13,0]],"id":70003372},{"atb":[[9.2,0],[10,4.4],[9.8,0],[8.4,13.51]],"id":40917581}],"con":true,"img":false}]}
{"op":"mcm","clk":"11450644749","pt":1717324172846,"mc":[{"id":"1.229554926","rc":[{"atb":[[9.4,5.26]],"id":40917581}],"con":true,"img":false}]}
{"op":"mcm","clk":"11450645519","pt":1717324180774,"mc":[{"id":"1.229554926","rc":[{"atb":[[9.2,10.61],[8.4,0]],"id":40917581}],"con":true,"img":false}]}
{"op":"mcm","clk":"11450645686","pt":1717324182299,"mc":[{"id":"1.229554926","rc":[{"atb":[[1.46,0]],"id":49546922}],"con":true,"img":false}]}
{"op":"mcm","clk":"11450645705","pt":1717324182502,"mc":[{"id":"1.229554926","rc":[{"atb":[[1.31,0]],"id":49546922}],"con":true,"img":false}]}
{"op":"mcm","clk":"11450645724","pt":1717324182659,"mc":[{"id":"1.229554926","rc":[{"atb":[[1.15,419.35]],"id":70003372}],"con":true,"img":false}]}
{"op":"mcm","clk":"11450645735","pt":1717324182764,"mc":[{"id":"1.229554926","rc":[{"atb":[[3.85,0]],"id":64343695},{"atl":[[65,2]],"id":64343695},{"atb":[[2.4,0]],"id":48638605},{"atl":[[34,0]],"id":48638605},{"atb":[[1.12,0]],"id":70003372},{"atb":[[10,0]],"id":40917581},{"atl":[[220,0]],"id":40917581}],"con":true,"img":false}]}
{"op":"mcm","clk":"11450645747","pt":1717324182867,"mc":[{"id":"1.229554926","rc":[{"atb":[[4.5,13.5]],"id":64343695},{"atl":[[46,2.61]],"id":64343695},{"atb":[[2.84,22.03]],"id":48638605},{"atl":[[25,2.61]],"id":48638605},{"atb":[[9.6,4.4]],"id":40917581},{"atl":[[180,2.61]],"id":40917581}],"con":true,"img":false}]}
{"op":"mcm","clk":"11450645760","pt":1717324182974,"mc":[{"id":"1.229554926","rc":[{"atl":[[170,0.47]],"id":40917581}],"con":true,"img":false}]}
{"op":"mcm","clk":"11450645782","pt":1717324183180,"mc":[{"id":"1.229554926","rc":[{"atl":[[190,0]],"id":40917581}],"con":true,"img":false}]}
{"op":"mcm","clk":"11450646434","pt":1717324189793,"mc":[{"id":"1.229554926","rc":[{"atb":[[9.8,5.27]],"id":40917581}],"con":true,"img":false}]}
{"op":"mcm","clk":"11450646454","pt":1717324190004,"mc":[{"id":"1.229554926","rc":[{"atb":[[9.4,0]],"id":40917581}],"con":true,"img":false}]}
{"op":"mcm","clk":"11450646725","pt":1717324192815,"mc":[{"id":"1.229554926","rc":[{"atl":[[180,0]],"id":40917581}],"con":true,"img":false}]}
{"op":"mcm","clk":"11450646738","pt":1717324192916,"mc":[{"id":"1.229554926","rc":[{"atl":[[200,2.82]],"id":40917581}],"con":true,"img":false}]}
{"op":"mcm","clk":"11450646750","pt":1717324193020,"mc":[{"id":"1.229554926","rc":[{"atl":[[170,0]],"id":40917581}],"con":true,"img":false}]}
{"op":"mcm","clk":"11450646759","pt":1717324193075,"mc":[{"id":"1.229554926","rc":[{"atl":[[190,0.42]],"id":40917581}],"con":true,"img":false}]}
{"op":"mcm","clk":"11450647643","pt":1717324201460,"mc":[{"id":"1.229554926","rc":[{"atb":[[1.71,0],[1.61,0]],"id":47148562},{"atl":[[6.6,0]],"id":47148562},{"atb":[[3.7,0],[4.4,0]],"id":64343695},{"atb":[[2.82,0],[3.05,5]],"id":48638605},{"atb":[[1.43,10],[1.33,0]],"id":49546922},{"atl":[[4.1,0]],"id":49546922},{"atb":[[1.01,0]],"id":70003372},{"atl":[[2.78,0]],"id":70003372},{"atb":[[6.2,0],[8.2,2.5]],"id":40917581}],"con":true,"img":false}]}
{"op":"mcm","clk":"11450647819","pt":1717324202629,"mc":[{"id":"1.229554926","rc":[{"atb":[[1.62,0]],"id":47148562},{"atl":[[9,7.32]],"id":47148562},{"atb":[[4.5,0],[2.64,0]],"id":64343695},{"atb":[[2.84,0]],"id":48638605},{"atb":[[1.44,0]],"id":49546922},{"atb":[[7.8,8.42]],"id":40917581}],"con":true,"img":false}]}
{"op":"mcm","clk":"11450647834","pt":1717324202731,"mc":[{"id":"1.229554926","rc":[{"atb":[[1.58,40.83]],"id":47148562},{"atl":[[12.5,0]],"id":47148562},{"atb":[[2.82,32.54],[3.85,13.5]],"id":64343695},{"atb":[[2.4,22.03]],"id":48638605},{"atb":[[1.35,44.05]],"id":49546922},{"atb":[[6.4,0]],"id":40917581}],"con":true,"img":false}]}
{"op":"mcm","clk":"11450648295","pt":1717324207024,"mc":[{"id":"1.229554926","rc":[{"atb":[[8.4,2.5]],"id":40917581}],"con":true,"img":false}]}
{"op":"mcm","clk":"11450648307","pt":1717324207134,"mc":[{"id":"1.229554926","rc":[{"atb":[[8.2,0]],"id":40917581}],"con":true,"img":false}]}
{"op":"mcm","clk":"11450648409","pt":1717324208231,"mc":[{"id":"1.229554926","rc":[{"atb":[[1.16,30.08]],"id":70003372}],"con":true,"img":false}]}
{"op":"mcm","clk":"11450648472","pt":1717324208746,"mc":[{"id":"1.229554926","rc":[{"atb":[[1.58,100.91],[1.68,34.15]],"id":47148562},{"atl":[[6.4,0.09]],"id":47148562},{"atb":[[4.3,7.03],[3.65,13.14]],"id":64343695},{"atb":[[3.1,11.05],[2.84,18.93]],"id":48638605},{"atb":[[1.45,51.62],[1.35,143.61]],"id":49546922},{"atl":[[4.2,0.16]],"id":49546922},{"atb":[[1.01,5807.26]],"id":70003372},{"atl":[[2.82,0.28]],"id":70003372},{"atb":[[8,3.31],[6,6.96]],"id":40917581}],"con":true,"img":false}]}
{"op":"mcm","clk":"11450649518","pt":1717324219184,"mc":[{"id":"1.229554926","rc":[{"atb":[[1.71,5.52]],"id":47148562},{"spn":2.74,"spf":"NaN","id":47148562},{"spn":13.95,"spf":"NaN","id":64343695},{"atb":[[2.44,2.72]],"id":48638605},{"spn":5.77,"spf":"NaN","id":48638605},{"atb":[[1.47,13.35]],"id":49546922},{"spn":2.4,"spf":"NaN","id":49546922},{"spn":1.71,"spf":"NaN","id":70003372}],"con":true,"img":false}]}
{"op":"mcm","clk":"11450649697","pt":1717324220661,"mc":[{"id":"1.229554926","rc":[{"atl":[[3.25,13.12]],"id":49546922}],"con":true,"img":false}]}
{"op":"mcm","clk":"11450649713","pt":1717324220759,"mc":[{"id":"1.229554926","rc":[{"atl":[[3.2,7.5]],"id":49546922}],"con":true,"img":false}]}
{"op":"mcm","clk":"11450649726","pt":1717324220866,"mc":[{"id":"1.229554926","rc":[{"atl":[[3.2,0],[3.55,23.12],[3.3,0],[3.75,5]],"id":49546922}],"con":true,"img":false}]}
{"op":"mcm","clk":"11450649931","pt":1717324222682,"mc":[{"id":"1.229554926","rc":[{"atb":[[9.6,0]],"id":40917581}],"con":true,"img":false}]}
{"op":"mcm","clk":"11450649943","pt":1717324222788,"mc":[{"id":"1.229554926","rc":[{"atb":[[9.2,0],[10,4.4],[9.8,0],[8.4,16.01]],"id":40917581}],"con":true,"img":false}]}
{"op":"mcm","clk":"11450649961","pt":1717324222897,"mc":[{"id":"1.229554926","rc":[{"atb":[[9.4,4]],"id":40917581}],"con":true,"img":false}]}
{"op":"mcm","clk":"11450650205","pt":1717324224988,"mc":[{"id":"1.229554926","rc":[{"atl":[[130,0.62]],"id":40917581}],"con":true,"img":false}]}
{"op":"mcm","clk":"11450650234","pt":1717324225197,"mc":[{"id":"1.229554926","rc":[{"atl":[[190,0]],"id":40917581}],"con":true,"img":false}]}
{"op":"mcm","clk":"11450650323","pt":1717324225985,"mc":[{"id":"1.229554926","rc":[{"atl":[[3.55,2.5],[3.75,41.24]],"id":49546922}],"con":true,"img":false}]}
{"op":"mcm","clk":"11450650559","pt":1717324228067,"mc":[{"id":"1.229554926","rc":[{"atb":[[1.63,0]],"id":47148562}],"con":true,"img":false}]}
{"op":"mcm","clk":"11450650576","pt":1717324228281,"mc":[{"id":"1.229554926","rc":[{"atb":[[2.44,5.68]],"id":48638605}],"con":true,"img":false}]}
{"op":"mcm","clk":"11450650611","pt":1717324228695,"mc":[{"id":"1.229554926","rc":[{"atb":[[1.36,11.83]],"id":49546922}],"con":true,"img":false}]}
{"op":"mcm","clk":"11450650754","pt":1717324230098,"mc":[{"id":"1.229554926","rc":[{"atb":[[2.9,2.24]],"id":64343695}],"con":true,"img":false}]}
{"op":"mcm","clk":"11450650776","pt":1717324230279,"mc":[{"id":"1.229554926","rc":[{"atb":[[9.2,8.42],[8.4,2.5]],"id":40917581}],"con":true,"img":false}]}
{"op":"mcm","clk":"11450651029","pt":1717324232670,"mc":[{"id":"1.229554926","rc":[{"atb":[[1.58,60.07]],"id":47148562},{"atb":[[3.85,0]],"id":64343695},{"atb":[[2.4,0]],"id":48638605},{"atb":[[10,0]],"id":40917581}],"con":true,"img":false}]}
{"op":"mcm","clk":"11450651042","pt":1717324232776,"mc":[{"id":"1.229554926","rc":[{"atb":[[1.59,40.83]],"id":47148562},{"atb":[[4.4,13.5]],"id":64343695},{"atb":[[2.86,22.03]],"id":48638605},{"atb":[[9.6,4.4],[9.2,0],[8.4,14.92]],"id":40917581}],"con":true,"img":false}]}
{"op":"mcm","clk":"11450651069","pt":1717324232983,"mc":[{"id":"1.229554926","rc":[{"atb":[[9.2,8.42],[8.4,2.5]],"id":40917581}],"con":true,"img":false}]}
{"op":"mcm","clk":"11450651613","pt":1717324238145,"mc":[{"id":"1.229554926","rc":[{"atb":[[2.44,2.95]],"id":48638605}],"con":true,"img":false}]}
{"op":"mcm","clk":"11450651684","pt":1717324238730,"mc":[{"id":"1.229554926","rc":[{"atb":[[9.8,5.12]],"id":40917581}],"con":true,"img":false}]}
{"op":"mcm","clk":"11450651697","pt":1717324238833,"mc":[{"id":"1.229554926","rc":[{"atb":[[9.4,0]],"id":40917581}],"con":true,"img":false}]}
{"op":"mcm","clk":"11450651716","pt":1717324239047,"mc":[{"id":"1.229554926","rc":[{"atb":[[1.01,19.71]],"id":48638605},{"atb":[[1.35,99.55]],"id":49546922}],"con":true,"img":false}]}
{"op":"mcm","clk":"11450651731","pt":1717324239152,"mc":[{"id":"1.229554926","rc":[{"atb":[[1.46,44.05]],"id":49546922}],"con":true,"img":false}]}
{"op":"mcm","clk":"11450651764","pt":1717324239569,"mc":[{"id":"1.229554926","rc":[{"atb":[[1.01,19.38]],"id":48638605}],"con":true,"img":false}]}
{"op":"mcm","clk":"11450651791","pt":1717324239781,"mc":[{"id":"1.229554926","rc":[{"atb":[[1.01,17.35]],"id":48638605}],"con":true,"img":false}]}
{"op":"mcm","clk":"11450651816","pt":1717324239837,"mc":[{"id":"1.229554926","rc":[{"atb":[[2.94,12.02]],"id":48638605}],"con":true,"img":false}]}
{"op":"mcm","clk":"11450651999","pt":1717324241346,"mc":[{"id":"1.229554926","rc":[{"atb":[[1.31,14.04]],"id":49546922}],"con":true,"img":false}]}
{"op":"mcm","clk":"11450652119","pt":1717324242640,"mc":[{"id":"1.229554926","rc":[{"atl":[[7,0]],"id":49546922},{"atb":[[1.15,5]],"id":70003372}],"con":true,"img":false}]}
{"op":"mcm","clk":"11450652132","pt":1717324242743,"mc":[{"id":"1.229554926","rc":[{"atl":[[6.4,6.97]],"id":49546922},{"atb":[[1.17,414.35]],"id":70003372}],"con":true,"img":false}]}
{"op":"mcm","clk":"11450652155","pt":1717324242949,"mc":[{"id":"1.229554926","rc":[{"atb":[[1.16,25.08]],"id":70003372}],"con":true,"img":false}]}
{"op":"mcm","clk":"11450652166","pt":1717324243053,"mc":[{"id":"1.229554926","rc":[{"atb":[[1.16,30.08]],"id":70003372}],"con":true,"img":false}]}
{"op":"mcm","clk":"11450652413","pt":1717324245446,"mc":[{"id":"1.229554926","rc":[{"atl":[[120,2.5]],"id":40917581}],"con":true,"img":false}]}
{"op":"mcm","clk":"11450652423","pt":1717324245548,"mc":[{"id":"1.229554926","rc":[{"atl":[[120,3.17]],"id":40917581}],"con":true,"img":false}]}
{"op":"mcm","clk":"11450652430","pt":1717324245652,"mc":[{"id":"1.229554926","rc":[{"atl":[[130,0]],"id":40917581}],"con":true,"img":false}]}
{"op":"mcm","clk":"11450653017","pt":1717324251639,"mc":[{"id":"1.229554926","rc":[{"atb":[[1.31,0]],"id":49546922}],"con":true,"img":false}]}
{"op":"mcm","clk":"11450653109","pt":1717324252687,"mc":[{"id":"1.229554926","rc":[{"atb":[[7.8,0]],"id":40917581}],"con":true,"img":false}]}
{"op":"mcm","clk":"11450653121","pt":1717324252781,"mc":[{"id":"1.229554926","rc":[{"atb":[[8.2,8.42]],"id":40917581}],"con":true,"img":false}]}
{"op":"mcm","clk":"11450653744","pt":1717324259380,"mc":[{"id":"1.229554926","rc":[{"atb":[[1.47,5]],"id":49546922}],"con":true,"img":false}]}
{"op":"mcm","clk":"11450653759","pt":1717324259589,"mc":[{"id":"1.229554926","rc":[{"atb":[[1.48,10.31]],"id":49546922}],"con":true,"img":false}]}
{"op":"mcm","clk":"11450654087","pt":1717324262672,"mc":[{"id":"1.229554926","rc":[{"atb":[[6.2,11.01],[8.2,0]],"id":40917581}],"con":true,"img":false}]}
{"op":"mcm","clk":"11450654213","pt":1717324263978,"mc":[{"id":"1.229554926","rc":[{"atl":[[3.1,23.81],[3,10],[3.3,54.35],[3.2,34.09]],"id":47148562},{"atl":[[18,1.18],[19,2.78],[20,3.95],[22,9.76]],"id":64343695},{"atb":[[2.82,68.68],[2.94,22.33],[2.86,62.35],[2.9,26.32]],"id":48638605},{"atl":[[8,10.71],[7.2,3.23],[7.6,7.58],[8.4,19.39]],"id":48638605},{"atb":[[1.46,152.75],[1.44,170.45],[1.48,51.98],[1.42,250]],"id":49546922},{"atl":[[2.54,12.99],[2.58,31.65],[2.62,46.3],[2.66,75.3]],"id":49546922}],"con":true,"img":false}]}
{"op":"mcm","clk":"11450654223","pt":1717324264086,"mc":[{"id":"1.229554926","rc":[{"atb":[[1.6,7.09]],"id":47148562},{"atl":[[3.05,9.38]],"id":47148562},{"atl":[[18.5,4.57]],"id":64343695},{"atl":[[7.4,10.34]],"id":48638605},{"atl":[[3.1,47.62],[3.75,5],[2.56,15.23]],"id":49546922}],"con":true,"img":false}]}
{"op":"mcm","clk":"11450654237","pt":1717324264187,"mc":[{"id":"1.229554926","rc":[{"atl":[[3.55,0]],"id":47148562},{"atl":[[22,5.95]],"id":64343695},{"atl":[[8.2,0]],"id":48638605},{"atl":[[3.25,0]],"id":49546922}],"con":true,"img":false}]}
{"op":"mcm","clk":"11450654437","pt":1717324265957,"mc":[{"id":"1.229554926","rc":[{"atb":[[1.94,7.5],[1.95,2.5],[1.87,10],[1.9,0],[1.91,5],[1.86,0]],"id":47148562}],"con":true,"img":false}]}
{"op":"mcm","clk":"11450654448","pt":1717324266117,"mc":[{"id":"1.229554926","rc":[{"atb":[[1.95,15.16],[1.57,0],[1.66,20]],"id":47148562},{"atl":[[3.35,8.51],[3,0],[2.36,4.51]],"id":47148562},{"atb":[[5.8,0],[5,0],[3.8,0],[3.15,32.54],[5.4,0]],"id":64343695},{"atl":[[13.5,1.6],[14.5,2.5],[65,0],[16.5,5],[18,0],[18.5,14.57],[23,0],[27,3.85]],"id":64343695},{"atb":[[3.35,11.28],[3.25,0],[3.5,12.27],[2.94,12.33],[3.05,0],[2.74,37.88],[2.38,0],[3.15,5]],"id":48638605},{"atl":[[8.2,13.89],[9.4,0]],"id":48638605},{"atb":[[1.28,0],[1.43,0],[1.78,2.5],[1.7,10],[1.51,7.5],[1.35,297.14],[1.74,5],[1.75,21.16],[1.47,0]],"id":49546922},{"atl":[[2.54,0],[3.1,0],[3.45,40.82],[2.68,11.9]],"id":49546922},{"atb":[[1.16,0],[1.15,255],[1.19,115.26],[1.13,250],[1.1,1000],[1.05,0],[1.17,664.35]],"id":70003372},{"atl":[[1.83,90.36],[1.85,147.06],[2.1,2.5],[2.34,0],[1.8,33.35],[1.79,25.32],[1.81,61.73],[2.42,0],[2.18,5],[2.2,7.5]],"id":70003372},{"atb":[[9.6,14.64],[9.2,0]],"id":40917581},{"atl":[[400,2],[460,0]],"id":40917581}],"con":true,"img":false}]}
{"op":"mcm","clk":"11450654461","pt":1717324266270,"mc":[{"id":"1.229554926","rc":[{"atb":[[1.94,0]],"id":47148562},{"atl":[[3.1,0],[3.3,0],[3.2,0]],"id":47148562},{"atb":[[4.5,5],[4.1,10],[4.9,2.5],[3.15,0],[3.55,32.54]],"id":64343695},{"atl":[[19,0],[20,0],[22,0]],"id":64343695},{"atb":[[3.35,2.5]],"id":48638605},{"atl":[[8,13.21],[9.2,0],[10,0],[8.4,16.89]],"id":48638605},{"atb":[[1.45,222.07],[1.51,0],[1.35,99.55]],"id":49546922},{"atl":[[3.1,47.62],[3.45,0]],"id":49546922},{"atl":[[2.24,0]],"id":70003372},{"atl":[[320,2],[400,0]],"id":40917581}],"con":true,"img":false}]}
{"op":"mcm","clk":"11450654476","pt":1717324266381,"mc":[{"id":"1.229554926","rc":[{"atl":[[1.74,1.98]],"id":70003372}],"con":true,"img":false}]}
{"op":"mcm","clk":"11450654483","pt":1717324266479,"mc":[{"id":"1.229554926","rc":[{"atb":[[5.9,0]],"id":64343695}],"con":true,"img":false}]}
{"op":"mcm","clk":"11450654493","pt":1717324266582,"mc":[{"id":"1.229554926","rc":[{"atb":[[4.7,3.75]],"id":64343695}],"con":true,"img":false}]}
{"op":"mcm","clk":"11450654574","pt":1717324267528,"mc":[{"id":"1.229554926","rc":[{"atl":[[2.58,0]],"id":49546922}],"con":true,"img":false}]}
{"op":"mcm","clk":"11450654586","pt":1717324267683,"mc":[{"id":"1.229554926","rc":[{"atl":[[2.56,0]],"id":49546922}],"con":true,"img":false}]}
{"op":"mcm","clk":"11450654615","pt":1717324267899,"mc":[{"id":"1.229554926","rc":[{"atl":[[2.62,73.59]],"id":49546922}],"con":true,"img":false}]}
{"op":"mcm","clk":"11450654684","pt":1717324268470,"mc":[{"id":"1.229554926","rc":[{"atb":[[1.78,4.63],[1.48,49.85]],"id":49546922}],"con":true,"img":false}]}
{"op":"mcm","clk":"11450654757","pt":1717324269101,"mc":[{"id":"1.229554926","rc":[{"atb":[[1.17,100]],"id":64343695},{"atb":[[1.17,100]],"id":48638605},{"atb":[[1.17,100]],"id":40917581}],"con":true,"img":false}]}
{"op":"mcm","clk":"11450655116","pt":1717324272698,"mc":[{"id":"1.229554926","rc":[{"atl":[[200,2.61],[110,0.38]],"id":40917581}],"con":true,"img":false}]}
{"op":"mcm","clk":"11450655124","pt":1717324272804,"mc":[{"id":"1.229554926","rc":[{"atl":[[7.4,0]],"id":47148562},{"atb":[[4.4,0]],"id":64343695},{"atl":[[26,0]],"id":64343695},{"atb":[[9.6,10.24]],"id":40917581},{"atl":[[110,1.11]],"id":40917581}],"con":true,"img":false}]}
{"op":"mcm","clk":"11450655140","pt":1717324272907,"mc":[{"id":"1.229554926","rc":[{"atl":[[8.4,5.81]],"id":47148562},{"atb":[[4.2,13.5]],"id":64343695},{"atl":[[36,2.61]],"id":64343695},{"atb":[[9.6,0],[10,4.4],[8.4,16.01]],"id":40917581},{"atl":[[120,2.5]],"id":40917581}],"con":true,"img":false}]}
{"op":"mcm","clk":"11450655151","pt":1717324272960,"mc":[{"id":"1.229554926","rc":[{"atl":[[4,7.5],[3.6,0],[3.35,0],[3.8,0],[3.4,8.33]],"id":47148562},{"atb":[[3.55,0],[4,13.15]],"id":64343695},{"atb":[[1.45,51.62],[1.55,152.76]],"id":49546922},{"atl":[[2.62,27.29],[2.7,11.76]],"id":49546922},{"atb":[[10.5,5.27]],"id":40917581}],"con":true,"img":false}]}
{"op":"mcm","clk":"11450655164","pt":1717324273065,"mc":[{"id":"1.229554926","rc":[{"atl":[[2.62,0]],"id":49546922},{"atb":[[9.8,0]],"id":40917581}],"con":true,"img":false}]}
{"op":"mcm","clk":"11450655176","pt":1717324273173,"mc":[{"id":"1.229554926","rc":[{"atb":[[1.77,20],[1.66,0]],"id":47148562},{"atb":[[2.98,26.32],[2.74,0]],"id":48638605},{"atl":[[8.2,0],[7.8,14.71]],"id":48638605},{"atl":[[2.66,24.8]],"id":49546922},{"atb":[[1.15,505],[1.1,0]],"id":70003372},{"atl":[[1.74,27.3],[2.2,0]],"id":70003372}],"con":true,"img":false}]}
{"op":"mcm","clk":"11450655222","pt":1717324273588,"mc":[{"id":"1.229554926","rc":[{"atl":[[2.68,0]],"id":49546922}],"con":true,"img":false}]}
{"op":"mcm","clk":"11450655263","pt":1717324273901,"mc":[{"id":"1.229554926","rc":[{"atl":[[2.66,0]],"id":49546922}],"con":true,"img":false}]}
{"op":"mcm","clk":"11450655275","pt":1717324274003,"mc":[{"id":"1.229554926","rc":[{"atl":[[3.55,41.72],[2.7,36.45]],"id":49546922}],"con":true,"img":false}]}
{"op":"mcm","clk":"11450655290","pt":1717324274057,"mc":[{"id":"1.229554926","rc":[{"atl":[[3.1,0]],"id":49546922}],"con":true,"img":false}]}
{"op":"mcm","clk":"11450655394","pt":1717324275096,"mc":[{"id":"1.229554926","rc":[{"trd":[[2.34,8.52]],"ltp":2.34,"tv":8.52,"id":47148562}],"con":true,"img":false}]}
{"op":"mcm","clk":"11450655402","pt":1717324275201,"mc":[{"id":"1.229554926","rc":[{"atl":[[8.2,1.22]],"id":47148562}],"con":true,"img":false}]}
{"op":"mcm","clk":"11450655413","pt":1717324275307,"mc":[{"id":"1.229554926","rc":[{"atl":[[8.2,0]],"id":47148562}],"con":true,"img":false}]}
{"op":"mcm","clk":"11450655443","pt":1717324275570,"mc":[{"id":"1.229554926","rc":[{"atl":[[2.4,2.29]],"id":47148562}],"con":true,"img":false}]}
{"op":"mcm","clk":"11450655502","pt":1717324276193,"mc":[{"id":"1.229554926","rc":[{"atb":[[1.48,41.67]],"id":49546922}],"con":true,"img":false}]}
{"op":"mcm","clk":"11450655519","pt":1717324276404,"mc":[{"id":"1.229554926","rc":[{"atb":[[1.57,6.88]],"id":49546922}],"con":true,"img":false}]}
{"op":"mcm","clk":"11450655592","pt":1717324276983,"mc":[{"id":"1.229554926","rc":[{"atl":[[14.5,6.2]],"id":64343695}],"con":true,"img":false}]}
{"op":"mcm","clk":"11450655792","pt":1717324279113,"mc":[{"id":"1.229554926","rc":[{"atl":[[13,6.56]],"id":64343695},{"atl":[[7,9.44]],"id":48638605}],"con":true,"img":false}]}
{"op":"mcm","clk":"11450655805","pt":1717324279217,"mc":[{"id":"1.229554926","rc":[{"spn":2.15,"spf":"NaN","id":47148562},{"atl":[[18.5,10]],"id":64343695},{"spn":8.95,"spf":"NaN","id":64343695},{"spn":5.25,"spf":"NaN","id":48638605},{"spn":2.24,"spf":"NaN","id":49546922},{"spn":1.46,"spf":"NaN","id":70003372},{"spn":60.25,"spf":"NaN","id":40917581}],"con":true,"img":false}]}
{"op":"mcm","clk":"11450655813","pt":1717324279323,"mc":[{"id":"1.229554926","rc":[{"atl":[[7.4,0]],"id":48638605}],"con":true,"img":false}]}
{"op":"mcm","clk":"11450655878","pt":1717324279897,"mc":[{"id":"1.229554926","rc":[{"atb":[[10.5,10.54],[8.4,2.5]],"id":40917581}],"con":true,"img":false}]}
{"op":"mcm","clk":"11450656009","pt":1717324281203,"mc":[{"id":"1.229554926","rc":[{"atb":[[1.78,24.25]],"id":49546922},{"atl":[[1.74,135.41]],"id":70003372}],"con":true,"img":false}]}
{"op":"mcm","clk":"11450656015","pt":1717324281318,"mc":[{"id":"1.229554926","rc":[{"atb":[[1.75,0]],"id":49546922},{"atl":[[1.8,0]],"id":70003372}],"con":true,"img":false}]}
{"op":"mcm","clk":"11450656050","pt":1717324281576,"mc":[{"id":"1.229554926","rc":[{"atb":[[4.9,9.06]],"id":64343695}],"con":true,"img":false}]}
{"op":"mcm","clk":"11450656059","pt":1717324281685,"mc":[{"id":"1.229554926","rc":[{"atb":[[4.7,0]],"id":64343695}],"con":true,"img":false}]}
{"op":"mcm","clk":"11450656155","pt":1717324282727,"mc":[{"id":"1.229554926","rc":[{"atl":[[9,0],[11,5.75],[8.4,0]],"id":47148562},{"atb":[[2.86,40.32]],"id":48638605},{"atb":[[1.17,250]],"id":70003372}],"con":true,"img":false}]}
{"op":"mcm","clk":"11450656166","pt":1717324282780,"mc":[{"id":"1.229554926","rc":[{"atl":[[9.8,5.81]],"id":47148562},{"atb":[[2.92,22.03]],"id":48638605},{"atb":[[1.14,414.35]],"id":70003372}],"con":true,"img":false}]}
{"op":"mcm","clk":"11450656181","pt":1717324282988,"mc":[{"id":"1.229554926","rc":[{"atb":[[1.64,27.29],[1.77,0]],"id":47148562},{"atb":[[4,0],[3.55,32.54]],"id":64343695},{"atb":[[2.98,0],[2.7,37.88]],"id":48638605},{"atb":[[1.45,222.07],[1.55,0]],"id":49546922},{"atb":[[1.12,500],[1.15,255]],"id":70003372}],"con":true,"img":false}]}
{"op":"mcm","clk":"11450656252","pt":1717324283714,"mc":[{"id":"1.229554926","rc":[{"atl":[[3.5,20]],"id":47148562},{"atl":[[2.74,28.74]],"id":49546922}],"con":true,"img":false}]}
{"op":"mcm","clk":"11450656329","pt":1717324284292,"mc":[{"id":"1.229554926","rc":[{"trd":[[2.34,17.04]],"ltp":2.34,"tv":17.04,"id":47148562}],"con":true,"img":false}]}
{"op":"mcm","clk":"11450656342","pt":1717324284394,"mc":[{"id":"1.229554926","rc":[{"atb":[[1.7,5.64],[1.96,4.26]],"id":47148562}],"con":true,"img":false}]}
{"op":"mcm","clk":"11450656352","pt":1717324284497,"mc":[{"id":"1.229554926","rc":[{"atb":[[1.7,0],[1.96,0]],"id":47148562}],"con":true,"img":false}]}
{"op":"mcm","clk":"11450656366","pt":1717324284603,"mc":[{"id":"1.229554926","rc":[{"atb":[[1.96,7.13]],"id":47148562}],"con":true,"img":false}]}
{"op":"mcm","clk":"11450656385","pt":1717324284808,"mc":[{"id":"1.229554926","rc":[{"atb":[[1.95,2.5]],"id":47148562},{"atl":[[2.38,3.68]],"id":47148562}],"con":true,"img":false}]}
{"op":"mcm","clk":"11450656654","pt":1717324287716,"mc":[{"id":"1.229554926","rc":[{"atl":[[15.5,5.17]],"id":64343695}],"con":true,"img":false}]}
{"op":"mcm","clk":"11450657169","pt":1717324292706,"mc":[{"id":"1.229554926","rc":[{"atb":[[1.59,0]],"id":47148562},{"atl":[[36,0]],"id":64343695},{"atb":[[1.46,108.7]],"id":49546922},{"atb":[[1.18,0]],"id":70003372},{"atb":[[10,0]],"id":40917581}],"con":true,"img":false}]}
{"op":"mcm","clk":"11450657180","pt":1717324292809,"mc":[{"id":"1.229554926","rc":[{"atb":[[1.69,40.83]],"id":47148562},{"atl":[[29,2.61]],"id":64343695},{"atb":[[1.49,44.05]],"id":49546922},{"atb":[[1.2,114.64]],"id":70003372},{"atb":[[10.5,5.27],[8.2,13.04],[9.4,4.4]],"id":40917581}],"con":true,"img":false}]}
{"op":"mcm","clk":"11450657208","pt":1717324293011,"mc":[{"id":"1.229554926","rc":[{"atb":[[1.2,285.22]],"id":70003372},{"atb":[[9.6,10.54],[10.5,0],[8.2,0]],"id":40917581}],"con":true,"img":false}]}
{"op":"mcm","clk":"11450657222","pt":1717324293118,"mc":[{"id":"1.229554926","rc":[{"atb":[[1.19,107.76]],"id":70003372},{"atb":[[9.8,3.84]],"id":40917581}],"con":true,"img":false}]}
{"op":"mcm","clk":"11450657232","pt":1717324293219,"mc":[{"id":"1.229554926","rc":[{"atb":[[9.6,0],[10,4.41]],"id":40917581}],"con":true,"img":false}]}
{"op":"mcm","clk":"11450657244","pt":1717324293324,"mc":[{"id":"1.229554926","rc":[{"atb":[[9.6,8.25],[10,0]],"id":40917581}],"con":true,"img":false}]}
{"op":"mcm","clk":"11450657268","pt":1717324293532,"mc":[{"id":"1.229554926","rc":[{"trd":[[2.34,21.58]],"ltp":2.34,"tv":21.58,"id":47148562}],"con":true,"img":false}]}
{"op":"mcm","clk":"11450657333","pt":1717324294009,"mc":[{"id":"1.229554926","rc":[{"atl":[[2.42,3.38]],"id":47148562}],"con":true,"img":false}]}
{"op":"mcm","clk":"11450657364","pt":1717324294319,"mc":[{"id":"1.229554926","rc":[{"atl":[[3.6,28.85]],"id":47148562},{"atl":[[2.78,42.13]],"id":49546922}],"con":true,"img":false}]}
{"op":"mcm","clk":"11450657377","pt":1717324294425,"mc":[{"id":"1.229554926","rc":[{"atl":[[3,50],[3.55,2.5]],"id":49546922}],"con":true,"img":false}]}
{"op":"mcm","clk":"11450657445","pt":1717324295107,"mc":[{"id":"1.229554926","rc":[{"atb":[[1.71,0]],"id":47148562}],"con":true,"img":false}]}
{"op":"mcm","clk":"11450657470","pt":1717324295316,"mc":[{"id":"1.229554926","rc":[{"atb":[[1.72,5.44]],"id":47148562}],"con":true,"img":false}]}
{"op":"mcm","clk":"11450657646","pt":1717324297028,"mc":[{"id":"1.229554926","rc":[{"atb":[[1.12,530.08]],"id":70003372}],"con":true,"img":false}]}
{"op":"mcm","clk":"11450657760","pt":1717324298226,"mc":[{"id":"1.229554926","rc":[{"atl":[[16.5,13.06]],"id":64343695}],"con":true,"img":false}]}
{"op":"mcm","clk":"11450657889","pt":1717324299433,"mc":[{"id":"1.229554926","rc":[{"atl":[[2.36,0]],"id":47148562}],"con":true,"img":false}]}
{"op":"mcm","clk":"11450657937","pt":1717324299844,"mc":[{"id":"1.229554926","rc":[{"atl":[[2.68,11.9]],"id":49546922}],"con":true,"img":false}]}
{"op":"mcm","clk":"11450657947","pt":1717324299946,"mc":[{"id":"1.229554926","rc":[{"atl":[[2.68,39.01]],"id":49546922}],"con":true,"img":false}]}
{"op":"mcm","clk":"11450657958","pt":1717324300052,"mc":[{"id":"1.229554926","rc":[{"atl":[[2.7,11.76]],"id":49546922}],"con":true,"img":false}]}
{"op":"mcm","clk":"11450657996","pt":1717324300424,"mc":[{"id":"1.229554926","rc":[{"atb":[[1.31,0],[1.38,157.47]],"id":47148562},{"atl":[[6.4,0]],"id":49546922},{"atl":[[3.85,0]],"id":70003372}],"con":true,"img":false}]}
{"op":"mcm","clk":"11450658007","pt":1717324300526,"mc":[{"id":"1.229554926","rc":[{"atl":[[5.3,6.97]],"id":49546922},{"atl":[[3.05,19.46]],"id":70003372}],"con":true,"img":false}]}
{"op":"mcm","clk":"11450658173","pt":1717324302031,"mc":[{"id":"1.229554926","rc":[{"atl":[[7.2,0],[6.8,9.44],[6.6,3.57]],"id":48638605},{"atb":[[1.28,2.39]],"id":70003372},{"atl":[[140,1],[160,1],[100,1],[120,3.5]],"id":40917581}],"con":true,"img":false}]}
{"op":"mcm","clk":"11450658184","pt":1717324302135,"mc":[{"id":"1.229554926","rc":[{"atl":[[7.6,22.73],[7,0],[7.8,0]],"id":48638605},{"atb":[[1.12,500]],"id":70003372},{"atl":[[100,1.81]],"id":40917581}],"con":true,"img":false}]}
{"op":"mcm","clk":"11450658196","pt":1717324302240,"mc":[{"id":"1.229554926","rc":[{"atl":[[6,0]],"id":49546922}],"con":true,"img":false}]}
{"op":"mcm","clk":"11450658207","pt":1717324302343,"mc":[{"id":"1.229554926","rc":[{"atl":[[110,0.38]],"id":40917581}],"con":true,"img":false}]}
{"op":"mcm","clk":"11450658236","pt":1717324302553,"mc":[{"id":"1.229554926","rc":[{"trd":[[2.34,26.12]],"ltp":2.34,"tv":26.12,"id":47148562}],"con":true,"img":false}]}
{"op":"mcm","clk":"11450658244","pt":1717324302655,"mc":[{"id":"1.229554926","rc":[{"atb":[[1.58,0],[1.68,0]],"id":47148562},{"atl":[[6.4,0]],"id":47148562},{"atb":[[4.3,0],[3.65,0]],"id":64343695},{"atb":[[3.1,0],[2.84,0]],"id":48638605},{"atb":[[1.45,170.45],[1.35,0]],"id":49546922},{"atl":[[4.2,0]],"id":49546922},{"atb":[[1.01,0]],"id":70003372},{"atl":[[2.82,0]],"id":70003372},{"atb":[[8,0],[6,0]],"id":40917581}],"con":true,"img":false}]}
{"op":"mcm","clk":"11450658256","pt":1717324302765,"mc":[{"id":"1.229554926","rc":[{"atb":[[1.64,2.13],[1.76,34.16],[1.97,2.27]],"id":47148562},{"atb":[[4,18.12],[3.55,0]],"id":64343695},{"atb":[[2.98,22.03],[2.7,0]],"id":48638605},{"atl":[[7.2,3.23],[6.6,0]],"id":48638605},{"atb":[[1.45,0],[1.55,44.06]],"id":49546922},{"atl":[[140,0],[160,0],[100,0.81],[120,2.5]],"id":40917581}],"con":true,"img":false}]}
{"op":"mcm","clk":"11450658264","pt":1717324302819,"mc":[{"id":"1.229554926","rc":[{"atb":[[1.97,0]],"id":47148562}],"con":true,"img":false}]}
{"op":"mcm","clk":"11450658273","pt":1717324302921,"mc":[{"id":"1.229554926","rc":[{"atb":[[1.97,4.41]],"id":47148562},{"atl":[[6.8,0]],"id":48638605}],"con":true,"img":false}]}
{"op":"mcm","clk":"11450658285","pt":1717324303026,"mc":[{"id":"1.229554926","rc":[{"atb":[[1.96,0]],"id":47148562},{"atl":[[2.36,4.71]],"id":47148562},{"atl":[[7,10.83]],"id":48638605}],"con":true,"img":false}]}
{"op":"mcm","clk":"11450658299","pt":1717324303135,"mc":[{"id":"1.229554926","rc":[{"atb":[[1.64,14.71],[1.76,0]],"id":47148562},{"atb":[[4,0],[3.55,32.54]],"id":64343695},{"atb":[[2.72,44.06],[2.98,0]],"id":48638605},{"atl":[[8,27.5],[7.6,7.58]],"id":48638605},{"atb":[[1.45,170.45],[1.55,0]],"id":49546922}],"con":true,"img":false}]}
{"op":"mcm","clk":"11450658323","pt":1717324303344,"mc":[{"id":"1.229554926","rc":[{"atb":[[1.64,2.13],[1.97,0],[1.76,14.71]],"id":47148562},{"atl":[[3.6,0],[3.5,0],[3.4,0]],"id":47148562},{"atb":[[4,32.54],[3.55,0]],"id":64343695},{"atb":[[2.82,0],[2.98,22.03],[3.5,0],[2.94,2.02],[2.9,0],[2.86,0]],"id":48638605},{"atl":[[8,13.21],[7.6,22.73]],"id":48638605},{"atb":[[1.45,0],[1.55,44.06]],"id":49546922},{"atl":[[2.84,10.87],[2.68,27.11]],"id":49546922}],"con":true,"img":false}]}
{"op":"mcm","clk":"11450658333","pt":1717324303445,"mc":[{"id":"1.229554926","rc":[{"atb":[[2.9,0]],"id":64343695},{"atb":[[2.72,0],[3.35,0],[2.44,0],[3.15,0]],"id":48638605},{"atb":[[1.36,0]],"id":49546922}],"con":true,"img":false}]}
{"op":"mcm","clk":"11450658345","pt":1717324303575,"mc":[{"id":"1.229554926","rc":[{"atb":[[1.93,4.64],[1.76,0],[1.65,15.45]],"id":47148562},{"atb":[[4,0],[4.3,14.06]],"id":64343695},{"atb":[[2.24,80.65],[2.98,0]],"id":48638605}],"con":true,"img":false}]}
{"op":"mcm","clk":"11450658364","pt":1717324303658,"mc":[{"id":"1.229554926","rc":[{"atb":[[2.3,5],[2.38,2.5]],"id":48638605}],"con":true,"img":false}]}
{"op":"mcm","clk":"11450658514","pt":1717324304824,"mc":[{"id":"1.229554926","rc":[{"atl":[[3.8,17.86],[4,49.17],[3.7,7.41],[3.9,25.86]],"id":47148562}],"con":true,"img":false}]}
{"op":"mcm","clk":"11450658629","pt":1717324305825,"mc":[{"id":"1.229554926","rc":[{"trd":[[2.32,6.08]],"ltp":2.32,"tv":6.08,"id":47148562}],"con":true,"img":false}]}
{"op":"mcm","clk":"11450658646","pt":1717324306020,"mc":[{"id":"1.229554926","rc":[{"atl":[[2.7,0]],"id":49546922},{"atl":[[120,0]],"id":40917581}],"con":true,"img":false}]}
{"op":"mcm","clk":"11450658689","pt":1717324306434,"mc":[{"id":"1.229554926","rc":[{"atl":[[12.5,1.37]],"id":64343695},{"atl":[[6.8,1.29]],"id":48638605},{"atl":[[2.66,1.38]],"id":49546922},{"atl":[[1.73,1.27]],"id":70003372}],"con":true,"img":false}]}
{"op":"mcm","clk":"11450658700","pt":1717324306540,"mc":[{"id":"1.229554926","rc":[{"atl":[[12.5,8.33]],"id":64343695},{"atl":[[6.8,4.52],[7.6,7.58]],"id":48638605},{"atl":[[1.73,101.08]],"id":70003372}],"con":true,"img":false}]}
{"op":"mcm","clk":"11450658708","pt":1717324306642,"mc":[{"id":"1.229554926","rc":[{"atl":[[1.74,27.3]],"id":70003372}],"con":true,"img":false}]}
{"op":"mcm","clk":"11450658716","pt":1717324306745,"mc":[{"id":"1.229554926","rc":[{"atl":[[13,0]],"id":64343695}],"con":true,"img":false}]}
{"op":"mcm","clk":"11450658809","pt":1717324307522,"mc":[{"id":"1.229554926","rc":[{"atb":[[1.28,75.21]],"id":70003372}],"con":true,"img":false}]}
{"op":"mcm","clk":"11450658821","pt":1717324307631,"mc":[{"id":"1.229554926","rc":[{"atb":[[1.2,114.64]],"id":70003372}],"con":true,"img":false}]}
{"op":"mcm","clk":"11450658900","pt":1717324308470,"mc":[{"id":"1.229554926","rc":[{"atl":[[2.36,0]],"id":47148562},{"atl":[[2.74,0]],"id":49546922}],"con":true,"img":false}]}
{"op":"mcm","clk":"11450659128","pt":1717324310344,"mc":[{"id":"1.229554926","rc":[{"trd":[[1.33,5.68]],"ltp":1.33,"tv":5.68,"id":70003372}],"con":true,"img":false}]}
{"op":"mcm","clk":"11450659142","pt":1717324310450,"mc":[{"id":"1.229554926","rc":[{"atb":[[1.29,2.84]],"id":70003372}],"con":true,"img":false}]}
{"op":"mcm","clk":"11450659155","pt":1717324310553,"mc":[{"id":"1.229554926","rc":[{"atl":[[2.78,0]],"id":49546922},{"atb":[[1.29,0]],"id":70003372},{"atl":[[1.74,25.32]],"id":70003372}],"con":true,"img":false}]}
{"op":"mcm","clk":"11450659167","pt":1717324310656,"mc":[{"id":"1.229554926","rc":[{"atb":[[2.94,3.6]],"id":48638605},{"atb":[[1.79,1.77]],"id":49546922},{"atb":[[1.29,1.65]],"id":70003372},{"atb":[[9.8,5.58]],"id":40917581}],"con":true,"img":false}]}
{"op":"mcm","clk":"11450659175","pt":1717324310760,"mc":[{"id":"1.229554926","rc":[{"atb":[[1.79,13.67]],"id":49546922},{"atl":[[1.74,27.3]],"id":70003372}],"con":true,"img":false}]}
{"op":"mcm","clk":"11450659192","pt":1717324310866,"mc":[{"id":"1.229554926","rc":[{"atb":[[1.78,4.63]],"id":49546922},{"atl":[[2.66,0]],"id":49546922}],"con":true,"img":false}]}
{"op":"mcm","clk":"11450659207","pt":1717324310929,"mc":[{"id":"1.229554926","rc":[{"atb":[[1.29,3.92]],"id":70003372}],"con":true,"img":false}]}
{"op":"mcm","clk":"11450659220","pt":1717324311031,"mc":[{"id":"1.229554926","rc":[{"atl":[[2.68,0]],"id":49546922}],"con":true,"img":false}]}
{"op":"mcm","clk":"11450659236","pt":1717324311181,"mc":[{"id":"1.229554926","rc":[{"atl":[[2.72,18.4]],"id":49546922}],"con":true,"img":false}]}
{"op":"mcm","clk":"11450659243","pt":1717324311238,"mc":[{"id":"1.229554926","rc":[{"atb":[[1.51,157.48],[1.65,0]],"id":47148562},{"atb":[[2.24,0],[2.1,90.91]],"id":48638605},{"atb":[[1.43,197.59],[1.55,0]],"id":49546922},{"atl":[[3,0],[3.55,41.72]],"id":49546922},{"atb":[[9.6,0],[8.2,13.89]],"id":40917581}],"con":true,"img":false}]}
{"op":"mcm","clk":"11450659257","pt":1717324311342,"mc":[{"id":"1.229554926","rc":[{"atl":[[2.72,0],[3.1,29.27],[3.55,2.5]],"id":49546922}],"con":true,"img":false}]}
{"op":"mcm","clk":"11450659271","pt":1717324311442,"mc":[{"id":"1.229554926","rc":[{"atl":[[2.86,11.9],[2.7,1.38]],"id":49546922}],"con":true,"img":false}]}
{"op":"mcm","clk":"11450659312","pt":1717324311861,"mc":[{"id":"1.229554926","rc":[{"atb":[[9.8,3.84]],"id":40917581}],"con":true,"img":false}]}
{"op":"mcm","clk":"11450659336","pt":1717324312023,"mc":[{"id":"1.229554926","rc":[{"atl":[[2.38,0]],"id":47148562},{"atl":[[2.7,0]],"id":49546922},{"atb":[[9.8,0]],"id":40917581}],"con":true,"img":false}]}
{"op":"mcm","clk":"11450659347","pt":1717324312127,"mc":[{"id":"1.229554926","rc":[{"atl":[[2.82,1.38]],"id":49546922},{"atb":[[9.6,3.84]],"id":40917581}],"con":true,"img":false}]}
{"op":"mcm","clk":"11450659397","pt":1717324312645,"mc":[{"id":"1.229554926","rc":[{"atb":[[2.3,37.19]],"id":48638605},{"atl":[[190,0.21]],"id":40917581}],"con":true,"img":false}]}
{"op":"mcm","clk":"11450659409","pt":1717324312750,"mc":[{"id":"1.229554926","rc":[{"atb":[[1.69,0]],"id":47148562},{"atb":[[2.92,0]],"id":48638605},{"atl":[[5.3,0]],"id":49546922},{"atl":[[200,0],[110,0]],"id":40917581}],"con":true,"img":false}]}
{"op":"mcm","clk":"11450659422","pt":1717324312855,"mc":[{"id":"1.229554926","rc":[{"atb":[[1.52,40.83]],"id":47148562},{"atl":[[5.8,6.97]],"id":49546922},{"atl":[[220,2.61]],"id":40917581}],"con":true,"img":false}]}
{"op":"mcm","clk":"11450659435","pt":1717324312957,"mc":[{"id":"1.229554926","rc":[{"atl":[[100,0]],"id":40917581}],"con":true,"img":false}]}
{"op":"mcm","clk":"11450659448","pt":1717324313061,"mc":[{"id":"1.229554926","rc":[{"atb":[[2.94,2.02]],"id":48638605},{"atl":[[150,0.54]],"id":40917581}],"con":true,"img":false}]}
{"op":"mcm","clk":"11450659471","pt":1717324313275,"mc":[{"id":"1.229554926","rc":[{"atb":[[1.6,65.17],[1.7,33.18]],"id":47148562},{"atl":[[6.6,0.09]],"id":47148562},{"atb":[[3.6,13.4],[4.2,20.76]],"id":64343695},{"atb":[[2.82,19.14],[3.05,11.33]],"id":48638605},{"atb":[[1.44,223.24],[1.34,102.47]],"id":49546922},{"atl":[[4.2,0.16]],"id":49546922},{"atb":[[1.01,5807.26]],"id":70003372},{"atl":[[2.82,0.28]],"id":70003372},{"atb":[[6.2,17.71],[8.2,17.11]],"id":40917581}],"con":true,"img":false}]}
{"op":"mcm","clk":"11450659483","pt":1717324313381,"mc":[{"id":"1.229554926","rc":[{"atl":[[2.4,0]],"id":47148562}],"con":true,"img":false}]}
{"op":"mcm","clk":"11450659507","pt":1717324313542,"mc":[{"id":"1.229554926","rc":[{"atb":[[1.2,117.14],[1.15,250],[1.11,0],[1.19,105.26]],"id":70003372}],"con":true,"img":false}]}
{"op":"mcm","clk":"11450659518","pt":1717324313648,"mc":[{"id":"1.229554926","rc":[{"atl":[[2.88,26.6]],"id":49546922}],"con":true,"img":false}]}
{"op":"mcm","clk":"11450659596","pt":1717324314230,"mc":[{"id":"1.229554926","rc":[{"atl":[[2.82,13.28]],"id":49546922}],"con":true,"img":false}]}
{"op":"mcm","clk":"11450659607","pt":1717324314332,"mc":[{"id":"1.229554926","rc":[{"atl":[[2.86,0]],"id":49546922}],"con":true,"img":false}]}
{"op":"mcm","clk":"11450659631","pt":1717324314641,"mc":[{"id":"1.229554926","rc":[{"trd":[[2.4,5.88]],"ltp":2.4,"tv":5.88,"id":47148562}],"con":true,"img":false}]}
{"op":"mcm","clk":"11450659670","pt":1717324315106,"mc":[{"id":"1.229554926","rc":[{"atb":[[2.94,0]],"id":48638605}],"con":true,"img":false}]}
{"op":"mcm","clk":"11450659679","pt":1717324315160,"mc":[{"id":"1.229554926","rc":[{"atl":[[2.48,2.96]],"id":47148562}],"con":true,"img":false}]}
{"op":"mcm","clk":"11450659808","pt":1717324316362,"mc":[{"id":"1.229554926","rc":[{"atl":[[6.6,11.52]],"id":48638605}],"con":true,"img":false}]}
{"op":"mcm","clk":"11450659819","pt":1717324316464,"mc":[{"id":"1.229554926","rc":[{"atl":[[13.5,0],[14,1.54]],"id":64343695},{"atl":[[7,0]],"id":48638605},{"atb":[[1.46,0],[1.44,52.79],[1.48,0]],"id":49546922},{"atl":[[1.8,25],[1.79,0]],"id":70003372},{"atl":[[130,0.62],[140,1],[160,1],[180,1],[120,1]],"id":40917581}],"con":true,"img":false}]}
{"op":"mcm","clk":"11450659831","pt":1717324316568,"mc":[{"id":"1.229554926","rc":[{"atl":[[150,0]],"id":40917581}],"con":true,"img":false}]}
{"op":"mcm","clk":"11450659868","pt":1717324317042,"mc":[{"id":"1.229554926","rc":[{"atl":[[6.8,3.23]],"id":48638605}],"con":true,"img":false}]}
{"op":"mcm","clk":"11450659880","pt":1717324317143,"mc":[{"id":"1.229554926","rc":[{"atl":[[13.5,1.6],[14,0]],"id":64343695},{"atl":[[7.2,0],[6.4,1.29],[7.6,3.03]],"id":48638605},{"atl":[[1.8,0],[1.79,25.32]],"id":70003372}],"con":true,"img":false}]}
{"op":"mcm","clk":"11450659894","pt":1717324317247,"mc":[{"id":"1.229554926","rc":[{"atb":[[1.95,8.52]],"id":47148562},{"atl":[[7.2,14.75],[6.8,0]],"id":48638605}],"con":true,"img":false}]}
{"op":"mcm","clk":"11450659909","pt":1717324317352,"mc":[{"id":"1.229554926","rc":[{"atb":[[1.93,0]],"id":47148562},{"atl":[[13.5,0],[14,1.54]],"id":64343695},{"atl":[[6.2,10.92]],"id":48638605},{"atl":[[1.8,25],[1.79,0]],"id":70003372}],"con":true,"img":false}]}
{"op":"mcm","clk":"11450659925","pt":1717324317558,"mc":[{"id":"1.229554926","rc":[{"atl":[[6.6,0]],"id":48638605}],"con":true,"img":false}]}
{"op":"mcm","clk":"11450659934","pt":1717324317660,"mc":[{"id":"1.229554926","rc":[{"atl":[[6.4,0]],"id":48638605}],"con":true,"img":false}]}
{"op":"mcm","clk":"11450659943","pt":1717324317764,"mc":[{"id":"1.229554926","rc":[{"atl":[[6.2,0],[6,1.29]],"id":48638605}],"con":true,"img":false}]}
{"op":"mcm","clk":"11450659951","pt":1717324317867,"mc":[{"id":"1.229554926","rc":[{"atl":[[7,13.33]],"id":48638605}],"con":true,"img":false}]}
{"op":"mcm","clk":"11450659986","pt":1717324318235,"mc":[{"id":"1.229554926","rc":[{"atl":[[6,0]],"id":48638605}],"con":true,"img":false}]}
{"op":"mcm","clk":"11450659994","pt":1717324318338,"mc":[{"id":"1.229554926","rc":[{"atl":[[2.42,0]],"id":47148562},{"atl":[[6.8,1.29]],"id":48638605}],"con":true,"img":false}]}
{"op":"mcm","clk":"11450660003","pt":1717324318440,"mc":[{"id":"1.229554926","rc":[{"atl":[[3.7,0],[3.75,7.27]],"id":47148562},{"atb":[[4,32.54],[4.3,0]],"id":64343695},{"atl":[[2.82,24.27]],"id":49546922},{"atb":[[1.28,2.39]],"id":70003372},{"atb":[[9.6,7.68],[8.2,3.22]],"id":40917581},{"atl":[[140,3.5],[110,1],[120,0]],"id":40917581}],"con":true,"img":false}]}
{"op":"mcm","clk":"11450660058","pt":1717324319072,"mc":[{"id":"1.229554926","rc":[{"atb":[[1.29,2.27]],"id":70003372},{"atb":[[9.8,1.74]],"id":40917581}],"con":true,"img":false}]}
{"op":"mcm","clk":"11450660068","pt":1717324319171,"mc":[{"id":"1.229554926","rc":[{"trd":[[1.33,11.36]],"ltp":1.33,"tv":11.36,"id":70003372}],"con":true,"img":false}]}
{"op":"mcm","clk":"11450660114","pt":1717324319646,"mc":[{"id":"1.229554926","rc":[{"atl":[[13.5,1.6],[14,0]],"id":64343695},{"atb":[[1.3,2.75]],"id":70003372},{"atl":[[1.8,0],[1.79,25.32]],"id":70003372}],"con":true,"img":false}]}
{"op":"mcm","clk":"11450660202","pt":1717324320481,"mc":[{"id":"1.229554926","rc":[{"atl":[[7.2,17.98]],"id":48638605},{"atl":[[140,2.5],[160,0],[180,0],[110,0]],"id":40917581}],"con":true,"img":false}]}
{"op":"mcm","clk":"11450660308","pt":1717324321649,"mc":[{"id":"1.229554926","rc":[{"atl":[[2.48,0]],"id":47148562}],"con":true,"img":false}]}
{"op":"mcm","clk":"11450660378","pt":1717324322372,"mc":[{"id":"1.229554926","rc":[{"trd":[[1.33,18.9]],"ltp":1.33,"tv":18.9,"id":70003372}],"con":true,"img":false}]}
{"op":"mcm","clk":"11450660406","pt":1717324322640,"mc":[{"id":"1.229554926","rc":[{"atl":[[9.8,0]],"id":47148562},{"atb":[[1.49,0]],"id":49546922},{"atl":[[5,0],[3.7,23.01]],"id":70003372},{"atb":[[6.2,6.7],[8.4,10.24],[9.4,0]],"id":40917581}],"con":true,"img":false}]}
{"op":"mcm","clk":"11450660420","pt":1717324322745,"mc":[{"id":"1.229554926","rc":[{"atl":[[7.2,5.81]],"id":47148562},{"atb":[[1.45,44.05]],"id":49546922},{"atb":[[9.8,6.15]],"id":40917581}],"con":true,"img":false}]}
{"op":"mcm","clk":"11450660429","pt":1717324322846,"mc":[{"id":"1.229554926","rc":[{"atl":[[3.05,0],[60,5]],"id":47148562},{"atl":[[60,5]],"id":49546922},{"atb":[[1.31,2.36]],"id":70003372},{"atl":[[60,5]],"id":70003372}],"con":true,"img":false}]}
{"op":"mcm","clk":"11450660439","pt":1717324322949,"mc":[{"id":"1.229554926","rc":[{"atl":[[4,41.67],[3.8,29.7],[4.4,29.41]],"id":47148562}],"con":true,"img":false}]}
{"op":"mcm","clk":"11450660470","pt":1717324323261,"mc":[{"id":"1.229554926","rc":[{"atb":[[9.8,4.4]],"id":40917581}],"con":true,"img":false}]}
{"op":"mcm","clk":"11450660479","pt":1717324323366,"mc":[{"id":"1.229554926","rc":[{"atl":[[3.7,1.39]],"id":47148562}],"con":true,"img":false}]}
{"op":"mcm","clk":"11450660531","pt":1717324323856,"mc":[{"id":"1.229554926","rc":[{"atb":[[2.12,11.84]],"id":47148562},{"atl":[[7.2,3.23],[6.8,14.62]],"id":48638605}],"con":true,"img":false}]}
{"op":"mcm","clk":"11450660545","pt":1717324324002,"mc":[{"id":"1.229554926","rc":[{"atb":[[1.95,2.5]],"id":47148562}],"con":true,"img":false}]}
{"op":"mcm","clk":"11450660566","pt":1717324324217,"mc":[{"id":"1.229554926","rc":[{"trd":[[3.65,5.38]],"ltp":3.65,"tv":5.38,"id":47148562}],"con":true,"img":false}]}
{"op":"mcm","clk":"11450660585","pt":1717324324379,"mc":[{"id":"1.229554926","rc":[{"atl":[[3.7,4.04],[3.65,3.92]],"id":47148562}],"con":true,"img":false}]}
{"op":"mcm","clk":"11450660598","pt":1717324324482,"mc":[{"id":"1.229554926","rc":[{"atl":[[3.7,1.39],[3.65,0]],"id":47148562}],"con":true,"img":false}]}
{"op":"mcm","clk":"11450660612","pt":1717324324539,"mc":[{"id":"1.229554926","rc":[{"atl":[[3.7,0]],"id":47148562}],"con":true,"img":false}]}
{"op":"mcm","clk":"11450660624","pt":1717324324643,"mc":[{"id":"1.229554926","rc":[{"atl":[[3.6,1.39],[2.56,3.1]],"id":47148562}],"con":true,"img":false}]}
{"op":"mcm","clk":"11450660671","pt":1717324325062,"mc":[{"id":"1.229554926","rc":[{"atb":[[9.6,3.84],[10,7.68]],"id":40917581}],"con":true,"img":false}]}
{"op":"mcm","clk":"11450660691","pt":1717324325268,"mc":[{"id":"1.229554926","rc":[{"atb":[[10.5,1.74]],"id":40917581}],"con":true,"img":false}]}
{"op":"mcm","clk":"11450660726","pt":1717324325581,"mc":[{"id":"1.229554926","rc":[{"trd":[[1.33,26.44]],"ltp":1.33,"tv":26.44,"id":70003372}],"con":true,"img":false}]}
{"op":"mcm","clk":"11450660741","pt":1717324325688,"mc":[{"id":"1.229554926","rc":[{"atb":[[1.95,0],[1.87,0],[2.14,2.5],[1.99,10],[2.06,5],[1.91,0]],"id":47148562}],"con":true,"img":false}]}
{"op":"mcm","clk":"11450660764","pt":1717324325798,"mc":[{"id":"1.229554926","rc":[{"atb":[[2.14,4.1]],"id":47148562},{"atb":[[5.2,10.9]],"id":64343695},{"atb":[[2.4,2.5],[2.3,32.19],[2.38,0]],"id":48638605},{"atb":[[1.73,10],[1.78,2.13],[1.7,0],[1.81,2.5],[1.74,0],[1.77,5]],"id":49546922}],"con":true,"img":false}]}
{"op":"mcm","clk":"11450660780","pt":1717324325895,"mc":[{"id":"1.229554926","rc":[{"atb":[[1.81,20.9]],"id":49546922}],"con":true,"img":false}]}
{"op":"mcm","clk":"11450660791","pt":1717324325997,"mc":[{"id":"1.229554926","rc":[{"atb":[[5.6,2.5],[4.8,10],[4.5,0],[4.1,0],[5.2,15.9],[4.9,0]],"id":64343695},{"atl":[[8,10.71]],"id":48638605},{"atb":[[1.79,1.77]],"id":49546922}],"con":true,"img":false}]}
{"op":"mcm","clk":"11450660813","pt":1717324326209,"mc":[{"id":"1.229554926","rc":[{"atb":[[1.18,30.08]],"id":70003372},{"atb":[[11,3.19]],"id":40917581}],"con":true,"img":false}]}
{"op":"mcm","clk":"11450660822","pt":1717324326314,"mc":[{"id":"1.229554926","rc":[{"atb":[[9.6,0]],"id":40917581}],"con":true,"img":false}]}
{"op":"mcm","clk":"11450660849","pt":1717324326521,"mc":[{"id":"1.229554926","rc":[{"atb":[[1.79,0]],"id":49546922}],"con":true,"img":false}]}
{"op":"mcm","clk":"11450660860","pt":1717324326572,"mc":[{"id":"1.229554926","rc":[{"atb":[[1.82,1.77]],"id":49546922}],"con":true,"img":false}]}
{"op":"mcm","clk":"11450661046","pt":1717324328501,"mc":[{"id":"1.229554926","rc":[{"atl":[[2.86,26.88]],"id":49546922}],"con":true,"img":false}]}
{"op":"mcm","clk":"11450661114","pt":1717324329135,"mc":[{"id":"1.229554926","rc":[{"atl":[[3.8,18.98],[3.75,0]],"id":47148562},{"atl":[[2.82,37.56],[2.8,11.11],[3.1,0]],"id":49546922},{"atl":[[260,2],[320,0]],"id":40917581}],"con":true,"img":false}]}
{"op":"mcm","clk":"11450661139","pt":1717324329290,"mc":[{"id":"1.229554926","rc":[{"atl":[[2.8,27.59]],"id":49546922}],"con":true,"img":false}]}
{"op":"mcm","clk":"11450661153","pt":1717324329395,"mc":[{"id":"1.229554926","rc":[{"atb":[[1.64,0],[2.18,2.13]],"id":47148562},{"atl":[[2.82,25.66]],"id":49546922}],"con":true,"img":false}]}
{"op":"mcm","clk":"11450661170","pt":1717324329599,"mc":[{"id":"1.229554926","rc":[{"atl":[[2.82,24.28]],"id":49546922}],"con":true,"img":false}]}
{"op":"mcm","clk":"11450661182","pt":1717324329707,"mc":[{"id":"1.229554926","rc":[{"atl":[[2.78,1.38]],"id":49546922}],"con":true,"img":false}]}
{"op":"mcm","clk":"11450661218","pt":1717324330018,"mc":[{"id":"1.229554926","rc":[{"atb":[[2.14,2.5]],"id":47148562}],"con":true,"img":false}]}
{"op":"mcm","clk":"11450661265","pt":1717324330385,"mc":[{"id":"1.229554926","rc":[{"atl":[[46,0]],"id":64343695},{"atb":[[1.92,0],[2.12,51.73]],"id":48638605},{"atl":[[6.6,14.29]],"id":48638605}],"con":true,"img":false}]}
{"op":"mcm","clk":"11450661275","pt":1717324330491,"mc":[{"id":"1.229554926","rc":[{"atl":[[36,2.61]],"id":64343695},{"atl":[[6.4,14.29],[6.8,1.29],[7,0]],"id":48638605}],"con":true,"img":false}]}
{"op":"mcm","clk":"11450661287","pt":1717324330597,"mc":[{"id":"1.229554926","rc":[{"atl":[[6.4,0],[6.8,18.53]],"id":48638605}],"con":true,"img":false}]}
{"op":"mcm","clk":"11450661303","pt":1717324330801,"mc":[{"id":"1.229554926","rc":[{"atl":[[6.8,17.24]],"id":48638605}],"con":true,"img":false}]}
{"op":"mcm","clk":"11450661318","pt":1717324330906,"mc":[{"id":"1.229554926","rc":[{"atl":[[7.2,19.36],[6.4,1.29],[6.8,0]],"id":48638605}],"con":true,"img":false}]}
{"op":"mcm","clk":"11450661336","pt":1717324331110,"mc":[{"id":"1.229554926","rc":[{"atl":[[7.2,3.23],[6.4,15.58]],"id":48638605}],"con":true,"img":false}]}
{"op":"mcm","clk":"11450661343","pt":1717324331219,"mc":[{"id":"1.229554926","rc":[{"atb":[[2.18,6.33]],"id":47148562},{"atl":[[6.4,1.29],[6.8,15.59]],"id":48638605}],"con":true,"img":false}]}
{"op":"mcm","clk":"11450661361","pt":1717324331423,"mc":[{"id":"1.229554926","rc":[{"atb":[[2.12,0]],"id":47148562},{"atl":[[6.2,15.38]],"id":48638605}],"con":true,"img":false}]}
{"op":"mcm","clk":"11450661384","pt":1717324331638,"mc":[{"id":"1.229554926","rc":[{"atl":[[6.6,0]],"id":48638605}],"con":true,"img":false}]}
{"op":"mcm","clk":"11450661558","pt":1717324332693,"mc":[{"id":"1.229554926","rc":[{"trd":[[2.54,7.74]],"ltp":2.54,"tv":7.74,"id":47148562}],"con":true,"img":false}]}
{"op":"mcm","clk":"11450661571","pt":1717324332801,"mc":[{"id":"1.229554926","rc":[{"atb":[[2.2,3.91],[2.16,4.55]],"id":47148562}],"con":true,"img":false}]}
{"op":"mcm","clk":"11450661653","pt":1717324333060,"mc":[{"id":"1.229554926","rc":[{"atb":[[2.2,0],[2.16,0]],"id":47148562}],"con":true,"img":false}]}
{"op":"mcm","clk":"11450661679","pt":1717324333212,"mc":[{"id":"1.229554926","rc":[{"atl":[[2.58,3.32]],"id":47148562}],"con":true,"img":false}]}
{"op":"mcm","clk":"11450661707","pt":1717324333531,"mc":[{"id":"1.229554926","rc":[{"atb":[[1.72,0]],"id":47148562},{"atb":[[1.57,0]],"id":49546922}],"con":true,"img":false}]}
{"op":"mcm","clk":"11450661801","pt":1717324334114,"mc":[{"id":"1.229554926","rc":[{"trd":[[1.33,35.34]],"ltp":1.33,"tv":35.34,"id":70003372}],"con":true,"img":false}]}
{"op":"mcm","clk":"11450661814","pt":1717324334220,"mc":[{"id":"1.229554926","rc":[{"atb":[[1.56,8.02]],"id":47148562}],"con":true,"img":false}]}
{"op":"mcm","clk":"11450661832","pt":1717324334331,"mc":[{"id":"1.229554926","rc":[{"atb":[[1.52,0]],"id":47148562},{"atl":[[9,7.32],[11,0]],"id":47148562},{"atl":[[36,0]],"id":64343695},{"atl":[[19,0]],"id":48638605},{"atl":[[130,0.94],[190,0]],"id":40917581}],"con":true,"img":false}]}
{"op":"mcm","clk":"11450661848","pt":1717324334433,"mc":[{"id":"1.229554926","rc":[{"atb":[[1.61,40.83]],"id":47148562},{"atl":[[40,2.61]],"id":64343695},{"atl":[[17,2.61]],"id":48638605}],"con":true,"img":false}]}
{"op":"mcm","clk":"11450662177","pt":1717324336523,"mc":[{"id":"1.229554926","rc":[{"atb":[[1.56,0]],"id":47148562},{"atb":[[1.18,0]],"id":70003372}],"con":true,"img":false}]}
{"op":"mcm","clk":"11450662289","pt":1717324337723,"mc":[{"id":"1.229554926","rc":[{"atl":[[6.4,19.81],[6.8,0]],"id":48638605}],"con":true,"img":false}]}
{"op":"mcm","clk":"11450662421","pt":1717324338842,"mc":[{"id":"1.229554926","rc":[{"atb":[[1.6,58.07]],"id":47148562}],"con":true,"img":false}]}
{"op":"mcm","clk":"11450662426","pt":1717324338898,"mc":[{"id":"1.229554926","rc":[{"atl":[[3.9,43.1]],"id":47148562}],"con":true,"img":false}]}
{"op":"mcm","clk":"11450662443","pt":1717324338999,"mc":[{"id":"1.229554926","rc":[{"atl":[[3.9,17.24]],"id":47148562}],"con":true,"img":false}]}
{"op":"mcm","clk":"11450662522","pt":1717324339627,"mc":[{"id":"1.229554926","rc":[{"spn":2.37,"spf":"NaN","id":47148562},{"atb":[[5.6,13.4]],"id":64343695},{"spn":9.05,"spf":"NaN","id":64343695},{"spn":4.62,"spf":"NaN","id":48638605},{"spn":2.3,"spf":"NaN","id":49546922},{"spn":1.52,"spf":"NaN","id":70003372},{"spn":70.5,"spf":"NaN","id":40917581}],"con":true,"img":false}]}
{"op":"mcm","clk":"11450662537","pt":1717324339683,"mc":[{"id":"1.229554926","rc":[{"atb":[[5.2,5]],"id":64343695},{"atb":[[1.82,19.04]],"id":49546922}],"con":true,"img":false}]}
{"op":"mcm","clk":"11450662549","pt":1717324339783,"mc":[{"id":"1.229554926","rc":[{"atb":[[1.81,2.5]],"id":49546922}],"con":true,"img":false}]}
{"op":"mcm","clk":"11450662593","pt":1717324340201,"mc":[{"id":"1.229554926","rc":[{"atb":[[5.7,1.57]],"id":64343695}],"con":true,"img":false}]}
{"op":"mcm","clk":"11450662605","pt":1717324340304,"mc":[{"id":"1.229554926","rc":[{"atl":[[12.5,6.96]],"id":64343695}],"con":true,"img":false}]}
{"op":"mcm","clk":"11450662616","pt":1717324340412,"mc":[{"id":"1.229554926","rc":[{"atl":[[12.5,0]],"id":64343695}],"con":true,"img":false}]}
{"op":"mcm","clk":"11450662631","pt":1717324340513,"mc":[{"id":"1.229554926","rc":[{"atl":[[13.5,8]],"id":64343695}],"con":true,"img":false}]}
{"op":"mcm","clk":"11450662680","pt":1717324340933,"mc":[{"id":"1.229554926","rc":[{"atl":[[13,1.37]],"id":64343695}],"con":true,"img":false}]}
{"op":"mcm","clk":"11450662707","pt":1717324341139,"mc":[{"id":"1.229554926","rc":[{"trd":[[2.54,14.2]],"ltp":2.54,"tv":14.2,"id":47148562}],"con":true,"img":false}]}
{"op":"mcm","clk":"11450662731","pt":1717324341348,"mc":[{"id":"1.229554926","rc":[{"atb":[[2.16,3.8]],"id":47148562}],"con":true,"img":false}]}
{"op":"mcm","clk":"11450662741","pt":1717324341400,"mc":[{"id":"1.229554926","rc":[{"atb":[[2.16,0]],"id":47148562}],"con":true,"img":false}]}
{"op":"mcm","clk":"11450662764","pt":1717324341607,"mc":[{"id":"1.229554926","rc":[{"atl":[[2.6,4.24]],"id":47148562}],"con":true,"img":false}]}
{"op":"mcm","clk":"11450662865","pt":1717324342503,"mc":[{"id":"1.229554926","rc":[{"trd":[[1.33,44.24]],"ltp":1.33,"tv":44.24,"id":70003372}],"con":true,"img":false}]}
{"op":"mcm","clk":"11450662877","pt":1717324342601,"mc":[{"id":"1.229554926","rc":[{"atl":[[1.72,4.45]],"id":70003372}],"con":true,"img":false}]}
{"op":"mcm","clk":"11450662889","pt":1717324342710,"mc":[{"id":"1.229554926","rc":[{"atl":[[1.72,9.85]],"id":70003372}],"con":true,"img":false}]}
{"op":"mcm","clk":"11450662906","pt":1717324342826,"mc":[{"id":"1.229554926","rc":[{"atb":[[1.2,117.99]],"id":70003372},{"atl":[[1.73,0],[1.72,5.4]],"id":70003372}],"con":true,"img":false}]}
{"op":"mcm","clk":"11450662911","pt":1717324342922,"mc":[{"id":"1.229554926","rc":[{"atl":[[1.71,1.27]],"id":70003372}],"con":true,"img":false}]}
{"op":"mcm","clk":"11450662929","pt":1717324343033,"mc":[{"id":"1.229554926","rc":[{"atl":[[2.78,17.54]],"id":49546922},{"atl":[[1.71,10.5],[1.72,0]],"id":70003372}],"con":true,"img":false}]}
{"op":"mcm","clk":"11450662936","pt":1717324343137,"mc":[{"id":"1.229554926","rc":[{"atl":[[1.74,1.98]],"id":70003372}],"con":true,"img":false}]}
{"op":"mcm","clk":"11450662955","pt":1717324343193,"mc":[{"id":"1.229554926","rc":[{"atl":[[2.8,11.11]],"id":49546922},{"atl":[[1.73,27.3],[1.71,5.1]],"id":70003372}],"con":true,"img":false}]}
{"op":"mcm","clk":"11450662967","pt":1717324343298,"mc":[{"id":"1.229554926","rc":[{"atl":[[1.73,0],[1.71,15.6]],"id":70003372}],"con":true,"img":false}]}
{"op":"mcm","clk":"11450662984","pt":1717324343427,"mc":[{"id":"1.229554926","rc":[{"atl":[[1.73,25.32],[1.71,5.1]],"id":70003372}],"con":true,"img":false}]}
{"op":"mcm","clk":"11450663003","pt":1717324343540,"mc":[{"id":"1.229554926","rc":[{"atl":[[1.73,0],[1.71,20.7]],"id":70003372}],"con":true,"img":false}]}
{"op":"mcm","clk":"11450663024","pt":1717324343589,"mc":[{"id":"1.229554926","rc":[{"atl":[[1.73,25.32],[1.71,5.1]],"id":70003372}],"con":true,"img":false}]}
{"op":"mcm","clk":"11450663036","pt":1717324343743,"mc":[{"id":"1.229554926","rc":[{"atl":[[1.73,0],[1.71,25.8]],"id":70003372}],"con":true,"img":false}]}
{"op":"mcm","clk":"11450663053","pt":1717324343804,"mc":[{"id":"1.229554926","rc":[{"atl":[[1.73,25.32],[1.71,5.1]],"id":70003372}],"con":true,"img":false}]}
{"op":"mcm","clk":"11450663062","pt":1717324343904,"mc":[{"id":"1.229554926","rc":[{"atl":[[1.73,0],[1.71,30.42]],"id":70003372}],"con":true,"img":false}]}
{"op":"mcm","clk":"11450663099","pt":1717324344111,"mc":[{"id":"1.229554926","rc":[{"atb":[[1.2,117.48]],"id":70003372}],"con":true,"img":false}]}
{"op":"mcm","clk":"11450663164","pt":1717324344635,"mc":[{"id":"1.229554926","rc":[{"atb":[[2.14,2.93],[2.2,0.43],[2.16,0.43]],"id":47148562},{"atl":[[2.54,0.33],[2.64,0.33],[2.62,0.33]],"id":47148562},{"atb":[[5.8,0.62],[5.5,0.62],[5.7,2.2]],"id":64343695},{"atl":[[12.5,1.06],[13,2.43],[14,1.06]],"id":64343695},{"atb":[[3.1,0.35],[3,0.35],[2.98,0.35]],"id":48638605},{"atl":[[6.8,1.3],[6,1.3],[6.6,1.3]],"id":48638605},{"atb":[[1.83,0.89],[1.8,0.89],[1.81,3.39]],"id":49546922},{"atl":[[2.76,3.68],[2.9,3.68]],"id":49546922},{"atb":[[1.3,3.05],[1.32,0.3],[1.31,2.66]],"id":70003372},{"atl":[[1.73,1.81],[1.7,1.81],[1.72,1.81]],"id":70003372},{"atb":[[9.6,0.53],[10.5,2.28],[11.5,0.53]],"id":40917581},{"atl":[[140,2.6],[160,0.09],[120,0.1]],"id":40917581}],"con":true,"img":false}]}
{"op":"mcm","clk":"11450663176","pt":1717324344690,"mc":[{"id":"1.229554926","rc":[{"atl":[[5.9,9.47],[6,16.68]],"id":48638605},{"atb":[[10,0],[11,6.38],[11.5,2.95]],"id":40917581},{"atl":[[120,0.77]],"id":40917581}],"con":true,"img":false}]}
{"op":"mcm","clk":"11450663189","pt":1717324344792,"mc":[{"id":"1.229554926","rc":[{"atl":[[3.8,11.84]],"id":47148562},{"atl":[[6.4,1.29],[5.8,15.38],[6.2,0],[6,1.3]],"id":48638605},{"atl":[[2.8,21.23],[2.82,0],[2.78,28.78]],"id":49546922}],"con":true,"img":false}]}
{"op":"mcm","clk":"11450663197","pt":1717324344893,"mc":[{"id":"1.229554926","rc":[{"atb":[[11,3.19]],"id":40917581},{"atl":[[130,0.32]],"id":40917581}],"con":true,"img":false}]}
{"op":"mcm","clk":"11450663210","pt":1717324345003,"mc":[{"id":"1.229554926","rc":[{"atl":[[5.8,0],[6,21.3]],"id":48638605}],"con":true,"img":false}]}
{"op":"mcm","clk":"11450663220","pt":1717324345103,"mc":[{"id":"1.229554926","rc":[{"atl":[[5.7,8.08]],"id":48638605}],"con":true,"img":false}]}
{"op":"mcm","clk":"11450663236","pt":1717324345207,"mc":[{"id":"1.229554926","rc":[{"atb":[[2.84,22.74]],"id":48638605},{"atl":[[5.9,0]],"id":48638605}],"con":true,"img":false}]}
{"op":"mcm","clk":"11450663251","pt":1717324345314,"mc":[{"id":"1.229554926","rc":[{"atb":[[2.3,0]],"id":48638605},{"atl":[[5.7,0]],"id":48638605},{"atl":[[1.71,29.15]],"id":70003372}],"con":true,"img":false}]}
{"op":"mcm","clk":"11450663263","pt":1717324345418,"mc":[{"id":"1.229554926","rc":[{"atl":[[5.9,1.25]],"id":48638605},{"atl":[[1.7,3.08]],"id":70003372}],"con":true,"img":false}]}
{"op":"mcm","clk":"11450663276","pt":1717324345529,"mc":[{"id":"1.229554926","rc":[{"atl":[[1.71,3.83],[1.69,3.08]],"id":70003372}],"con":true,"img":false}]}
{"op":"mcm","clk":"11450663290","pt":1717324345685,"mc":[{"id":"1.229554926","rc":[{"atb":[[1.85,2.13],[1.78,0]],"id":49546922}],"con":true,"img":false}]}
{"op":"mcm","clk":"11450663324","pt":1717324345942,"mc":[{"id":"1.229554926","rc":[{"atl":[[1.7,1.81]],"id":70003372}],"con":true,"img":false}]}
{"op":"mcm","clk":"11450663337","pt":1717324345998,"mc":[{"id":"1.229554926","rc":[{"atl":[[1.7,7.97],[1.69,0]],"id":70003372}],"con":true,"img":false}]}
{"op":"mcm","clk":"11450663361","pt":1717324346211,"mc":[{"id":"1.229554926","rc":[{"atb":[[1.82,17.27]],"id":49546922}],"con":true,"img":false}]}
{"op":"mcm","clk":"11450663448","pt":1717324346937,"mc":[{"id":"1.229554926","rc":[{"atb":[[2.22,0.47],[2.12,0.47],[2.1,0.47]],"id":47148562},{"atl":[[2.52,0.36],[2.66,0.36]],"id":47148562},{"atb":[[5.9,0.68],[5.4,0.68]],"id":64343695},{"atl":[[12,1.16]],"id":64343695},{"atb":[[2.94,0.38],[3.15,0.38],[2.96,0.38]],"id":48638605},{"atb":[[1.86,0.98]],"id":49546922},{"atb":[[1.28,2.72],[1.33,0.33],[1.29,2.6]],"id":70003372},{"atb":[[10,0.41],[12,0.41],[9.4,0.41]],"id":40917581},{"atl":[[180,0.08]],"id":40917581}],"con":true,"img":false}]}
{"op":"mcm","clk":"11450663456","pt":1717324347045,"mc":[{"id":"1.229554926","rc":[{"atb":[[1.51,0],[1.61,98.9]],"id":47148562},{"atb":[[4,0],[4.7,20.76]],"id":64343695},{"atl":[[13.5,6.4],[14,2.6]],"id":64343695},{"atb":[[2.1,0],[2.24,80.65]],"id":48638605},{"atb":[[1.43,0],[1.55,52.79]],"id":49546922},{"atl":[[1.79,0]],"id":70003372}],"con":true,"img":false}]}
{"op":"mcm","clk":"11450663484","pt":1717324347201,"mc":[{"id":"1.229554926","rc":[{"atb":[[5.8,0]],"id":64343695},{"atl":[[12.5,0]],"id":64343695},{"atb":[[1.32,0]],"id":70003372}],"con":true,"img":false}]}
{"op":"mcm","clk":"11450663545","pt":1717324347724,"mc":[{"id":"1.229554926","rc":[{"atl":[[13.5,8],[14,1.06]],"id":64343695},{"atl":[[7.2,0],[7.6,0]],"id":48638605},{"atl":[[1.79,25.32]],"id":70003372},{"atl":[[130,1.32],[150,1],[170,1],[110,1]],"id":40917581}],"con":true,"img":false}]}
{"op":"mcm","clk":"11450663605","pt":1717324348301,"mc":[{"id":"1.229554926","rc":[{"atl":[[7.2,3.23]],"id":48638605},{"atl":[[130,0.32],[150,0],[170,0],[110,0]],"id":40917581}],"con":true,"img":false}]}
{"op":"mcm","clk":"11450663614","pt":1717324348401,"mc":[{"id":"1.229554926","rc":[{"atl":[[130,1.71]],"id":40917581}],"con":true,"img":false}]}
{"op":"mcm","clk":"11450663649","pt":1717324348721,"mc":[{"id":"1.229554926","rc":[{"atb":[[2.12,0]],"id":48638605}],"con":true,"img":false}]}
{"op":"mcm","clk":"11450663657","pt":1717324348817,"mc":[{"id":"1.229554926","rc":[{"atb":[[1.98,51.73]],"id":48638605}],"con":true,"img":false}]}
{"op":"mcm","clk":"11450663683","pt":1717324349032,"mc":[{"id":"1.229554926","rc":[{"atl":[[2.5,0.38]],"id":47148562},{"atb":[[6,0.71]],"id":64343695},{"atb":[[3.2,0.42]],"id":48638605},{"atb":[[1.34,0.35],[1.27,0.35],[1.32,0.35]],"id":70003372},{"atb":[[12.5,0.46]],"id":40917581},{"atl":[[130,0.32]],"id":40917581}],"con":true,"img":false}]}
{"op":"mcm","clk":"11450663715","pt":1717324349342,"mc":[{"id":"1.229554926","rc":[{"atb":[[2.22,0]],"id":47148562},{"atl":[[2.52,0]],"id":47148562},{"atb":[[3.15,0]],"id":48638605},{"atb":[[12,0]],"id":40917581}],"con":true,"img":false}]}
{"op":"mcm","clk":"11450663867","pt":1717324350654,"mc":[{"id":"1.229554926","rc":[{"trd":[[2.48,6.62]],"ltp":2.48,"tv":6.62,"id":47148562}],"con":true,"img":false}]}
{"op":"mcm","clk":"11450663880","pt":1717324350706,"mc":[{"id":"1.229554926","rc":[{"atb":[[2.22,1],[2.16,4.23]],"id":47148562}],"con":true,"img":false}]}
{"op":"mcm","clk":"11450663893","pt":1717324350812,"mc":[{"id":"1.229554926","rc":[{"atb":[[2.22,0],[2.16,0.43]],"id":47148562}],"con":true,"img":false}]}
{"op":"mcm","clk":"11450663902","pt":1717324350913,"mc":[{"id":"1.229554926","rc":[{"atb":[[2.22,1.07]],"id":47148562}],"con":true,"img":false}]}
{"op":"mcm","clk":"11450663916","pt":1717324351019,"mc":[{"id":"1.229554926","rc":[{"atb":[[2.18,2.13]],"id":47148562},{"trd":[[1.36,5.06]],"ltp":1.36,"tv":5.06,"id":70003372}],"con":true,"img":false}]}
{"op":"mcm","clk":"11450663926","pt":1717324351120,"mc":[{"id":"1.229554926","rc":[{"atl":[[2.54,4.79]],"id":47148562}],"con":true,"img":false}]}
{"op":"mcm","clk":"11450663942","pt":1717324351228,"mc":[{"id":"1.229554926","rc":[{"atb":[[2.08,0.5]],"id":47148562},{"atl":[[2.48,0.38],[2.52,0.38]],"id":47148562},{"atb":[[3.25,0.42],[3.15,0.42]],"id":48638605},{"atb":[[1.35,0.39]],"id":70003372},{"atb":[[13,0.46]],"id":40917581}],"con":true,"img":false}]}
{"op":"mcm","clk":"11450664004","pt":1717324351695,"mc":[{"id":"1.229554926","rc":[{"atb":[[6,0]],"id":64343695},{"atb":[[1.34,0]],"id":70003372}],"con":true,"img":false}]}
{"op":"mcm","clk":"11450664039","pt":1717324352010,"mc":[{"id":"1.229554926","rc":[{"atl":[[13.5,6.4],[14,2.6]],"id":64343695},{"atl":[[1.79,0]],"id":70003372}],"con":true,"img":false}]}
{"op":"mcm","clk":"11450664054","pt":1717324352115,"mc":[{"id":"1.229554926","rc":[{"atl":[[7.2,0]],"id":48638605},{"atl":[[130,1.32],[150,1],[170,1],[110,1]],"id":40917581}],"con":true,"img":false}]}
{"op":"mcm","clk":"11450664062","pt":1717324352217,"mc":[{"id":"1.229554926","rc":[{"atl":[[220,0]],"id":40917581}],"con":true,"img":false}]}
{"op":"mcm","clk":"11450664074","pt":1717324352325,"mc":[{"id":"1.229554926","rc":[{"atl":[[190,2.61]],"id":40917581}],"con":true,"img":false}]}
{"op":"mcm","clk":"11450664098","pt":1717324352534,"mc":[{"id":"1.229554926","rc":[{"atl":[[7.2,3.23]],"id":48638605},{"atl":[[130,0.32],[150,0],[170,0],[110,0]],"id":40917581}],"con":true,"img":false}]}
{"op":"mcm","clk":"11450664163","pt":1717324353107,"mc":[{"id":"1.229554926","rc":[{"atb":[[5.7,5.68]],"id":64343695}],"con":true,"img":false}]}
{"op":"mcm","clk":"11450664172","pt":1717324353211,"mc":[{"id":"1.229554926","rc":[{"atb":[[5.6,2.5]],"id":64343695},{"atb":[[1.85,6.49]],"id":49546922}],"con":true,"img":false}]}
{"op":"mcm","clk":"11450664186","pt":1717324353313,"mc":[{"id":"1.229554926","rc":[{"atb":[[1.82,0]],"id":49546922}],"con":true,"img":false}]}
{"op":"mcm","clk":"11450664199","pt":1717324353419,"mc":[{"id":"1.229554926","rc":[{"atb":[[2.18,2.55]],"id":47148562},{"atl":[[2.46,0.54]],"id":47148562},{"atb":[[6,0.71],[5.7,4.1]],"id":64343695},{"atb":[[1.36,0.39]],"id":70003372},{"atl":[[130,1.32],[150,1],[170,1],[110,1]],"id":40917581}],"con":true,"img":false}]}
{"op":"mcm","clk":"11450664214","pt":1717324353522,"mc":[{"id":"1.229554926","rc":[{"atl":[[7.2,0]],"id":48638605}],"con":true,"img":false}]}
{"op":"mcm","clk":"11450664238","pt":1717324353732,"mc":[{"id":"1.229554926","rc":[{"trd":[[2.42,5.94]],"ltp":2.42,"tv":5.94,"id":47148562}],"con":true,"img":false}]}
{"op":"mcm","clk":"11450664250","pt":1717324353843,"mc":[{"id":"1.229554926","rc":[{"atl":[[2.48,0]],"id":47148562},{"atb":[[3.25,0]],"id":48638605},{"atb":[[13,0]],"id":40917581}],"con":true,"img":false}]}
{"op":"mcm","clk":"11450664273","pt":1717324354045,"mc":[{"id":"1.229554926","rc":[{"atl":[[12,3.86]],"id":64343695}],"con":true,"img":false}]}
{"op":"mcm","clk":"11450664280","pt":1717324354100,"mc":[{"id":"1.229554926","rc":[{"atl":[[13.5,0]],"id":64343695}],"con":true,"img":false}]}
{"op":"mcm","clk":"11450664286","pt":1717324354204,"mc":[{"id":"1.229554926","rc":[{"atl":[[2.54,0.33],[2.62,2.72]],"id":47148562}],"con":true,"img":false}]}
{"op":"mcm","clk":"11450664295","pt":1717324354364,"mc":[{"id":"1.229554926","rc":[{"atl":[[7.6,3.03]],"id":48638605},{"atl":[[130,2.71]],"id":40917581}],"con":true,"img":false}]}
{"op":"mcm","clk":"11450664305","pt":1717324354417,"mc":[{"id":"1.229554926","rc":[{"atb":[[2.66,2.1]],"id":48638605}],"con":true,"img":false}]}
{"op":"mcm","clk":"11450664376","pt":1717324355004,"mc":[{"id":"1.229554926","rc":[{"atl":[[2.8,11.11],[2.82,42.46],[2.78,17.54]],"id":49546922}],"con":true,"img":false}]}
{"op":"mcm","clk":"11450664436","pt":1717324355533,"mc":[{"id":"1.229554926","rc":[{"atl":[[4.4,0],[3.95,29.41]],"id":47148562},{"atl":[[2.8,0],[3.55,0],[3.75,0],[2.76,15.04],[3.95,0]],"id":49546922}],"con":true,"img":false}]}
{"op":"mcm","clk":"11450664457","pt":1717324355737,"mc":[{"id":"1.229554926","rc":[{"atl":[[2.48,0.47]],"id":47148562},{"atb":[[3.25,0.43]],"id":48638605},{"atb":[[13,0.46]],"id":40917581},{"atl":[[100,0.15]],"id":40917581}],"con":true,"img":false}]}
{"op":"mcm","clk":"11450664494","pt":1717324356184,"mc":[{"id":"1.229554926","rc":[{"atb":[[6,0]],"id":64343695},{"atb":[[3.2,0]],"id":48638605},{"atb":[[1.36,0]],"id":70003372}],"con":true,"img":false}]}
{"op":"mcm","clk":"11450664502","pt":1717324356237,"mc":[{"id":"1.229554926","rc":[{"atl":[[1.7,9.62]],"id":70003372}],"con":true,"img":false}]}
{"op":"mcm","clk":"11450664511","pt":1717324356345,"mc":[{"id":"1.229554926","rc":[{"atl":[[1.7,3.46],[1.71,15.94]],"id":70003372}],"con":true,"img":false}]}
{"op":"mcm","clk":"11450664529","pt":1717324356505,"mc":[{"id":"1.229554926","rc":[{"atl":[[2.76,31.19]],"id":49546922}],"con":true,"img":false}]}
{"op":"mcm","clk":"11450664539","pt":1717324356610,"mc":[{"id":"1.229554926","rc":[{"atl":[[2.78,1.38]],"id":49546922}],"con":true,"img":false}]}
{"op":"mcm","clk":"11450664560","pt":1717324356814,"mc":[{"id":"1.229554926","rc":[{"atl":[[1.7,4.73]],"id":70003372}],"con":true,"img":false}]}
{"op":"mcm","clk":"11450664577","pt":1717324356929,"mc":[{"id":"1.229554926","rc":[{"atl":[[1.71,0],[1.69,4.73]],"id":70003372}],"con":true,"img":false}]}
{"op":"mcm","clk":"11450664586","pt":1717324357023,"mc":[{"id":"1.229554926","rc":[{"atl":[[1.69,6.38]],"id":70003372}],"con":true,"img":false}]}
{"op":"mcm","clk":"11450664594","pt":1717324357127,"mc":[{"id":"1.229554926","rc":[{"atl":[[1.7,3.08]],"id":70003372}],"con":true,"img":false}]}
{"op":"mcm","clk":"11450664624","pt":1717324357445,"mc":[{"id":"1.229554926","rc":[{"atl":[[1.7,1.81]],"id":70003372}],"con":true,"img":false}]}
{"op":"mcm","clk":"11450664705","pt":1717324358127,"mc":[{"id":"1.229554926","rc":[{"atl":[[6.4,0]],"id":48638605},{"atl":[[2.78,0]],"id":49546922},{"atb":[[13,1.39]],"id":40917581},{"atl":[[100,0.96]],"id":40917581}],"con":true,"img":false}]}
{"op":"mcm","clk":"11450664718","pt":1717324358225,"mc":[{"id":"1.229554926","rc":[{"atb":[[6,0.42]],"id":64343695},{"atb":[[3.3,0.43]],"id":48638605},{"atl":[[5.9,2.54]],"id":48638605},{"atl":[[2.74,1.38]],"id":49546922},{"atb":[[1.36,0.39]],"id":70003372}],"con":true,"img":false}]}
{"op":"mcm","clk":"11450664729","pt":1717324358332,"mc":[{"id":"1.229554926","rc":[{"atb":[[11.5,0.53]],"id":40917581},{"atl":[[120,0.1]],"id":40917581}],"con":true,"img":false}]}
{"op":"mcm","clk":"11450664798","pt":1717324358959,"mc":[{"id":"1.229554926","rc":[{"atl":[[2.46,0]],"id":47148562},{"atb":[[13,0.93]],"id":40917581}],"con":true,"img":false}]}
{"op":"mcm","clk":"11450664907","pt":1717324359954,"mc":[{"id":"1.229554926","rc":[{"trd":[[100,1.93]],"ltp":100.0,"tv":1.93,"id":40917581},{"atl":[[100,0]],"id":40917581}],"con":true,"img":false}]}
{"op":"mcm","clk":"11450664969","pt":1717324360527,"mc":[{"id":"1.229554926","rc":[{"atl":[[2.46,0.48]],"id":47148562},{"atb":[[5.1,20.76],[4.7,0]],"id":64343695},{"atb":[[2.44,51.73],[2.24,0]],"id":48638605},{"atb":[[1.73,0],[1.85,2.13],[1.81,0.89],[1.77,0]],"id":49546922},{"atl":[[2.5,13.33],[2.76,19.83]],"id":49546922},{"atb":[[1.28,0.33],[1.3,0.3],[1.29,0.33],[1.31,0.3]],"id":70003372},{"atl":[[130,1.32]],"id":40917581}],"con":true,"img":false}]}
{"op":"mcm","clk":"11450664979","pt":1717324360630,"mc":[{"id":"1.229554926","rc":[{"atb":[[1.55,55.43]],"id":49546922}],"con":true,"img":false}]}
{"op":"mcm","clk":"11450664989","pt":1717324360733,"mc":[{"id":"1.229554926","rc":[{"atl":[[29,0]],"id":64343695}],"con":true,"img":false}]}
{"op":"mcm","clk":"11450664999","pt":1717324360839,"mc":[{"id":"1.229554926","rc":[{"atl":[[26,2.61]],"id":64343695},{"atb":[[1.21,1.65]],"id":70003372}],"con":true,"img":false}]}
{"op":"mcm","clk":"11450665011","pt":1717324360944,"mc":[{"id":"1.229554926","rc":[{"atb":[[6,0]],"id":64343695},{"atb":[[3.3,0]],"id":48638605},{"atl":[[2.76,16.15],[2.9,0]],"id":49546922},{"atb":[[1.36,0]],"id":70003372}],"con":true,"img":false}]}
{"op":"mcm","clk":"11450665029","pt":1717324361151,"mc":[{"id":"1.229554926","rc":[{"atb":[[2.66,0]],"id":48638605}],"con":true,"img":false}]}
{"op":"mcm","clk":"11450665038","pt":1717324361257,"mc":[{"id":"1.229554926","rc":[{"atl":[[2.82,0],[2.74,28.04]],"id":49546922}],"con":true,"img":false}]}
{"op":"mcm","clk":"11450665067","pt":1717324361567,"mc":[{"id":"1.229554926","rc":[{"atb":[[2.4,0]],"id":48638605}],"con":true,"img":false}]}
{"op":"mcm","clk":"11450665089","pt":1717324361729,"mc":[{"id":"1.229554926","rc":[{"atb":[[1.17,252.75]],"id":70003372}],"con":true,"img":false}]}
{"op":"mcm","clk":"11450665105","pt":1717324361835,"mc":[{"id":"1.229554926","rc":[{"trd":[[2.44,5.9]],"ltp":2.44,"tv":5.9,"id":47148562}],"con":true,"img":false}]}
{"op":"mcm","clk":"11450665136","pt":1717324362042,"mc":[{"id":"1.229554926","rc":[{"atl":[[1.7,14.57],[1.69,1.64]],"id":70003372}],"con":true,"img":false}]}
{"op":"mcm","clk":"11450665172","pt":1717324362349,"mc":[{"id":"1.229554926","rc":[{"atl":[[2.54,3.08]],"id":47148562}],"con":true,"img":false}]}
{"op":"mcm","clk":"11450665195","pt":1717324362556,"mc":[{"id":"1.229554926","rc":[{"atb":[[1.42,258.59]],"id":49546922}],"con":true,"img":false}]}
{"op":"mcm","clk":"11450665237","pt":1717324362929,"mc":[{"id":"1.229554926","rc":[{"atb":[[6,1.07]],"id":64343695},{"atb":[[3.3,0.43]],"id":48638605},{"atl":[[2.54,0.41],[2.48,0.41],[2.52,0.41]],"id":49546922},{"atl":[[100,0.15]],"id":40917581}],"con":true,"img":false}]}
{"op":"mcm","clk":"11450665251","pt":1717324363032,"mc":[{"id":"1.229554926","rc":[{"atl":[[2.74,1.38],[2.52,14.16]],"id":49546922}],"con":true,"img":false}]}
{"op":"mcm","clk":"11450665286","pt":1717324363341,"mc":[{"id":"1.229554926","rc":[{"atl":[[2.46,0]],"id":47148562}],"con":true,"img":false}]}
{"op":"mcm","clk":"11450665324","pt":1717324363654,"mc":[{"id":"1.229554926","rc":[{"atl":[[2.74,0]],"id":49546922}],"con":true,"img":false}]}
{"op":"mcm","clk":"11450665336","pt":1717324363759,"mc":[{"id":"1.229554926","rc":[{"atl":[[8,7.14]],"id":48638605},{"atl":[[2.48,1.8]],"id":49546922}],"con":true,"img":false}]}
{"op":"mcm","clk":"11450665351","pt":1717324363864,"mc":[{"id":"1.229554926","rc":[{"atl":[[2.5,26.66],[2.52,0.41]],"id":49546922}],"con":true,"img":false}]}
{"op":"mcm","clk":"11450665408","pt":1717324364338,"mc":[{"id":"1.229554926","rc":[{"atl":[[2.48,0.41]],"id":49546922}],"con":true,"img":false}]}
{"op":"mcm","clk":"11450665421","pt":1717324364444,"mc":[{"id":"1.229554926","rc":[{"atl":[[2.5,13.33],[2.52,27.49]],"id":49546922}],"con":true,"img":false}]}
{"op":"mcm","clk":"11450665433","pt":1717324364551,"mc":[{"id":"1.229554926","rc":[{"atb":[[1.42,250]],"id":49546922}],"con":true,"img":false}]}
{"op":"mcm","clk":"11450665444","pt":1717324364652,"mc":[{"id":"1.229554926","rc":[{"atl":[[25,0]],"id":48638605},{"atl":[[7.8,0]],"id":49546922}],"con":true,"img":false}]}
