{"op":"mcm","clk":"11448351868","pt":1717289088271,"mc":[{"id":"1.229554914","marketDefinition":{"bspMarket":false,"turnInPlayEnabled":false,"persistenceEnabled":false,"marketBaseRate":7.0,"eventId":"33318908","eventTypeId":"4339","numberOfWinners":1,"bettingType":"ODDS","marketType":"MATCH_BET","marketTime":"2024-06-02T09:38:00.000Z","suspendTime":"2024-06-02T09:38:00.000Z","bspReconciled":false,"complete":true,"inPlay":false,"crossMatching":true,"runnersVoidable":false,"numberOfActiveRunners":2,"betDelay":0,"status":"OPEN","runners":[{"status":"ACTIVE","sortPriority":1,"id":55943164,"name":"5. Lektra Ringo"},{"status":"ACTIVE","sortPriority":2,"id":70003369,"name":"6. Rickis Burner"}],"regulators":["MR_INT"],"venue":"Murray Bridge","countryCode":"AU","discountAllowed":true,"timezone":"Australia/Adelaide","openDate":"2024-06-02T08:21:00.000Z","version":5962433790,"name":"Lektra Ringo v Rickis Burner","eventName":"Murray Bridge (AUS) 2nd Jun"},"rc":[],"con":true,"img":false}]}
{"op":"mcm","clk":"11448366403","pt":1717289278043,"mc":[{"id":"1.229554914","rc":[{"atb":[[1.8,9.8],[1.9,8.72]],"id":70003369},{"atb":[[1.86,9.12],[1.76,10.32]],"id":55943164}],"con":true,"img":false}]}
{"op":"mcm","clk":"11449358110","pt":1717307828337,"mc":[{"id":"1.229554914","rc":[{"atb":[[1.03,5.92]],"id":70003369},{"atl":[[990,0.85]],"id":70003369},{"atb":[[1.01,17.76]],"id":55943164},{"atl":[[990,0.85]],"id":55943164}],"con":true,"img":false}]}
{"op":"mcm","clk":"11449524704","pt":1717310363066,"mc":[{"id":"1.229554914","rc":[{"atb":[[1.8,0],[1.9,0]],"id":70003369},{"atb":[[1.86,0],[1.76,0]],"id":55943164}],"con":true,"img":false}]}
{"op":"mcm","clk":"11449527122","pt":1717310402690,"mc":[{"id":"1.229554914","rc":[{"atb":[[1.8,9.8],[1.9,8.72]],"id":70003369},{"atb":[[1.86,9.12],[1.76,10.32]],"id":55943164}],"con":true,"img":false}]}
{"op":"mcm","clk":"11449584906","pt":1717311411574,"mc":[{"id":"1.229554914","rc":[{"atb":[[1.8,0],[1.9,0]],"id":70003369},{"atb":[[1.86,0],[1.76,0]],"id":55943164}],"con":true,"img":false}]}
{"op":"mcm","clk":"11449585312","pt":1717311419686,"mc":[{"id":"1.229554914","rc":[{"atb":[[1.8,9.8],[1.9,8.72]],"id":70003369},{"atb":[[1.86,9.12],[1.76,10.32]],"id":55943164}],"con":true,"img":false}]}
{"op":"mcm","clk":"11449586157","pt":1717311433495,"mc":[{"id":"1.229554914","rc":[{"atl":[[990,0.17]],"id":70003369},{"atl":[[990,0.17]],"id":55943164}],"con":true,"img":false}]}
{"op":"mcm","clk":"11449637279","pt":1717312502875,"mc":[{"id":"1.229554914","rc":[{"atb":[[1.8,0],[1.9,0]],"id":70003369},{"atb":[[1.86,0],[1.76,0]],"id":55943164}],"con":true,"img":false}]}
{"op":"mcm","clk":"11449637957","pt":1717312518476,"mc":[{"id":"1.229554914","rc":[{"atb":[[1.8,9.8],[1.9,8.72]],"id":70003369},{"atb":[[1.86,9.12],[1.76,10.32]],"id":55943164}],"con":true,"img":false}]}
{"op":"mcm","clk":"11449693432","pt":1717313604723,"mc":[{"id":"1.229554914","rc":[{"atb":[[1.8,0],[1.9,0]],"id":70003369},{"atb":[[1.86,0],[1.76,0]],"id":55943164}],"con":true,"img":false}]}
{"op":"mcm","clk":"11449696048","pt":1717313635048,"mc":[{"id":"1.229554914","rc":[{"atb":[[1.8,9.8],[1.9,8.72]],"id":70003369},{"atb":[[1.86,9.12],[1.76,10.32]],"id":55943164}],"con":true,"img":false}]}
{"op":"mcm","clk":"11449766676","pt":1717314431940,"mc":[{"id":"1.229554914","rc":[{"atb":[[1.8,0],[1.9,0]],"id":70003369},{"atb":[[1.86,0],[1.76,0]],"id":55943164}],"con":true,"img":false}]}
{"op":"mcm","clk":"11449767953","pt":1717314446185,"mc":[{"id":"1.229554914","rc":[{"atb":[[1.8,9.8],[1.9,8.72]],"id":70003369},{"atb":[[1.86,9.12],[1.76,10.32]],"id":55943164}],"con":true,"img":false}]}
{"op":"mcm","clk":"11449851245","pt":1717315296108,"mc":[{"id":"1.229554914","rc":[{"atb":[[1.8,0],[1.9,0]],"id":70003369},{"atb":[[1.86,0],[1.76,0]],"id":55943164}],"con":true,"img":false}]}
{"op":"mcm","clk":"11449854719","pt":1717315331356,"mc":[{"id":"1.229554914","rc":[{"atb":[[1.8,9.8],[1.9,8.72]],"id":70003369},{"atb":[[1.86,9.12],[1.76,10.32]],"id":55943164}],"con":true,"img":false}]}
{"op":"mcm","clk":"11449936832","pt":1717316137988,"mc":[{"id":"1.229554914","rc":[{"atb":[[1.8,0],[1.9,0]],"id":70003369},{"atb":[[1.86,0],[1.76,0]],"id":55943164}],"con":true,"img":false}]}
{"op":"mcm","clk":"11449938393","pt":1717316154732,"mc":[{"id":"1.229554914","rc":[{"atb":[[1.8,9.8],[1.9,8.72]],"id":70003369},{"atb":[[1.86,9.12],[1.76,10.32]],"id":55943164}],"con":true,"img":false}]}
{"op":"mcm","clk":"11449941962","pt":1717316192498,"mc":[{"id":"1.229554914","rc":[{"atb":[[1.8,0],[1.9,0]],"id":70003369},{"atb":[[1.86,0],[1.76,0]],"id":55943164}],"con":true,"img":false}]}
{"op":"mcm","clk":"11449942970","pt":1717316203588,"mc":[{"id":"1.229554914","rc":[{"atb":[[1.8,9.8],[1.9,8.72]],"id":70003369},{"atb":[[1.86,9.12],[1.76,10.32]],"id":55943164}],"con":true,"img":false}]}
{"op":"mcm","clk":"11450003961","pt":1717316992343,"mc":[{"id":"1.229554914","rc":[{"atb":[[1.8,0],[1.9,0]],"id":70003369},{"atb":[[1.86,0],[1.76,0]],"id":55943164}],"con":true,"img":false}]}
{"op":"mcm","clk":"11450007756","pt":1717317031487,"mc":[{"id":"1.229554914","rc":[{"atb":[[1.8,9.8],[1.9,8.72]],"id":70003369},{"atb":[[1.86,9.12],[1.76,10.32]],"id":55943164}],"con":true,"img":false}]}
{"op":"mcm","clk":"11450053404","pt":1717317480394,"mc":[{"id":"1.229554914","rc":[{"atl":[[21,2]],"id":70003369},{"atl":[[19.5,2]],"id":55943164}],"con":true,"img":false}]}
{"op":"mcm","clk":"11450053419","pt":1717317480597,"mc":[{"id":"1.229554914","rc":[{"atl":[[2.86,8.06],[2.9,10.53],[2.98,15.15],[2.94,12.89]],"id":70003369},{"atl":[[2.42,17.61],[2.38,14.49],[2.46,20.55],[2.34,11.19]],"id":55943164}],"con":true,"img":false}]}
{"op":"mcm","clk":"11450056661","pt":1717317517514,"mc":[{"id":"1.229554914","rc":[{"atl":[[21,0],[6.2,19.23]],"id":70003369},{"atl":[[19.5,0],[5.9,20.41]],"id":55943164}],"con":true,"img":false}]}
{"op":"mcm","clk":"11450063886","pt":1717317597698,"mc":[{"id":"1.229554914","rc":[{"atb":[[1.8,0],[1.9,0]],"id":70003369},{"atb":[[1.86,0],[1.76,0]],"id":55943164}],"con":true,"img":false}]}
{"op":"mcm","clk":"11450064199","pt":1717317601409,"mc":[{"id":"1.229554914","rc":[{"atb":[[1.45,55.56],[1.43,69.77],[1.49,30.61],[1.47,42.55]],"id":70003369},{"atb":[[1.4,62.5],[1.44,34.09],[1.42,47.62],[1.38,78.95]],"id":55943164}],"con":true,"img":false}]}
{"op":"mcm","clk":"11450065161","pt":1717317612080,"mc":[{"id":"1.229554914","rc":[{"atb":[[1.8,9.8],[1.9,8.72]],"id":70003369},{"atb":[[1.86,9.12],[1.76,10.32]],"id":55943164}],"con":true,"img":false}]}
{"op":"mcm","clk":"11450104907","pt":1717318060524,"mc":[{"id":"1.229554914","rc":[{"atb":[[1.8,0],[1.9,0]],"id":70003369},{"atb":[[1.86,0],[1.76,0]],"id":55943164}],"con":true,"img":false}]}
{"op":"mcm","clk":"11450106664","pt":1717318078855,"mc":[{"id":"1.229554914","rc":[{"atb":[[1.8,9.8],[1.9,8.72]],"id":70003369},{"atb":[[1.86,9.12],[1.76,10.32]],"id":55943164}],"con":true,"img":false}]}
{"op":"mcm","clk":"11450115058","pt":1717318173052,"mc":[{"id":"1.229554914","rc":[{"atb":[[1.49,0],[1.47,0]],"id":70003369}],"con":true,"img":false}]}
{"op":"mcm","clk":"11450137042","pt":1717318428088,"mc":[{"id":"1.229554914","rc":[{"atb":[[1.8,0],[1.9,0]],"id":70003369},{"atb":[[1.86,0],[1.76,0]],"id":55943164}],"con":true,"img":false}]}
{"op":"mcm","clk":"11450137804","pt":1717318436564,"mc":[{"id":"1.229554914","rc":[{"atb":[[1.49,30.61]],"id":70003369}],"con":true,"img":false}]}
{"op":"mcm","clk":"11450138370","pt":1717318442408,"mc":[{"id":"1.229554914","rc":[{"atb":[[1.8,9.8],[1.9,8.72]],"id":70003369},{"atb":[[1.86,9.12],[1.76,10.32]],"id":55943164}],"con":true,"img":false}]}
{"op":"mcm","clk":"11450138803","pt":1717318447675,"mc":[{"id":"1.229554914","rc":[{"atl":[[2.74,8.62]],"id":70003369}],"con":true,"img":false}]}
{"op":"mcm","clk":"11450138811","pt":1717318447781,"mc":[{"id":"1.229554914","rc":[{"atl":[[2.8,8.33],[2.86,0]],"id":70003369}],"con":true,"img":false}]}
{"op":"mcm","clk":"11450139341","pt":1717318453984,"mc":[{"id":"1.229554914","rc":[{"atl":[[2.86,8.06]],"id":70003369}],"con":true,"img":false}]}
{"op":"mcm","clk":"11450139349","pt":1717318454087,"mc":[{"id":"1.229554914","rc":[{"atl":[[2.8,0],[2.74,0]],"id":70003369}],"con":true,"img":false}]}
{"op":"mcm","clk":"11450148183","pt":1717318555213,"mc":[{"id":"1.229554914","rc":[{"atb":[[1.49,0]],"id":70003369}],"con":true,"img":false}]}
{"op":"mcm","clk":"11450159913","pt":1717318674140,"mc":[{"id":"1.229554914","rc":[{"atb":[[1.44,0]],"id":55943164}],"con":true,"img":false}]}
{"op":"mcm","clk":"11450171396","pt":1717318799673,"mc":[{"id":"1.229554914","rc":[{"atb":[[1.8,0],[1.9,0]],"id":70003369},{"atb":[[1.86,0],[1.76,0]],"id":55943164}],"con":true,"img":false}]}
{"op":"mcm","clk":"11450172449","pt":1717318809568,"mc":[{"id":"1.229554914","rc":[{"atb":[[1.48,31.25]],"id":70003369},{"atb":[[1.44,34.09]],"id":55943164}],"con":true,"img":false}]}
{"op":"mcm","clk":"11450173197","pt":1717318816589,"mc":[{"id":"1.229554914","rc":[{"atb":[[1.8,9.8],[1.9,8.72]],"id":70003369},{"atb":[[1.86,9.12],[1.76,10.32]],"id":55943164}],"con":true,"img":false}]}
{"op":"mcm","clk":"11450175669","pt":1717318844130,"mc":[{"id":"1.229554914","rc":[{"atb":[[1.44,0]],"id":55943164}],"con":true,"img":false}]}
{"op":"mcm","clk":"11450208375","pt":1717319182926,"mc":[{"id":"1.229554914","rc":[{"atb":[[1.8,0],[1.9,0]],"id":70003369},{"atb":[[1.86,0],[1.76,0]],"id":55943164}],"con":true,"img":false}]}
{"op":"mcm","clk":"11450208422","pt":1717319183287,"mc":[{"id":"1.229554914","rc":[{"atb":[[1.51,29.41]],"id":70003369},{"atb":[[1.44,34.09]],"id":55943164}],"con":true,"img":false}]}
{"op":"mcm","clk":"11450210488","pt":1717319203422,"mc":[{"id":"1.229554914","rc":[{"atb":[[1.8,9.8],[1.9,8.72]],"id":70003369},{"atb":[[1.86,9.12],[1.76,10.32]],"id":55943164}],"con":true,"img":false}]}
{"op":"mcm","clk":"11450216474","pt":1717319261577,"mc":[{"id":"1.229554914","rc":[{"atb":[[1.51,0]],"id":70003369},{"atb":[[1.44,0]],"id":55943164}],"con":true,"img":false}]}
{"op":"mcm","clk":"11450246447","pt":1717319582799,"mc":[{"id":"1.229554914","rc":[{"atb":[[1.8,0],[1.9,0]],"id":70003369},{"atb":[[1.86,0],[1.76,0]],"id":55943164}],"con":true,"img":false}]}
{"op":"mcm","clk":"11450246708","pt":1717319585297,"mc":[{"id":"1.229554914","rc":[{"atb":[[1.5,30]],"id":70003369},{"atb":[[1.43,34.88]],"id":55943164}],"con":true,"img":false}]}
{"op":"mcm","clk":"11450247605","pt":1717319595636,"mc":[{"id":"1.229554914","rc":[{"atb":[[1.8,9.8],[1.9,8.72]],"id":70003369},{"atb":[[1.86,9.12],[1.76,10.32]],"id":55943164}],"con":true,"img":false}]}
{"op":"mcm","clk":"11450271722","pt":1717319871673,"mc":[{"id":"1.229554914","rc":[{"atb":[[1.5,0],[1.48,0]],"id":70003369},{"atl":[[2.86,0],[2.74,8.62]],"id":70003369}],"con":true,"img":false}]}
{"op":"mcm","clk":"11450271732","pt":1717319871769,"mc":[{"id":"1.229554914","rc":[{"atl":[[2.8,8.33],[2.74,0]],"id":70003369}],"con":true,"img":false}]}
{"op":"mcm","clk":"11450272521","pt":1717319881807,"mc":[{"id":"1.229554914","rc":[{"atb":[[1.91,2]],"id":70003369},{"atl":[[2.46,2],[2.84,10.87]],"id":70003369}],"con":true,"img":false}]}
{"op":"mcm","clk":"11450272537","pt":1717319882008,"mc":[{"id":"1.229554914","rc":[{"atb":[[1.65,2]],"id":55943164},{"atl":[[2.32,2]],"id":55943164}],"con":true,"img":false}]}
{"op":"mcm","clk":"11450272643","pt":1717319883104,"mc":[{"id":"1.229554914","rc":[{"atl":[[2.9,0],[2.98,0],[2.94,0]],"id":70003369}],"con":true,"img":false}]}
{"op":"mcm","clk":"11450273074","pt":1717319888625,"mc":[{"id":"1.229554914","rc":[{"atl":[[2.8,0],[2.86,8.06],[2.52,2],[2.46,0]],"id":70003369},{"atb":[[1.65,0]],"id":55943164}],"con":true,"img":false}]}
{"op":"mcm","clk":"11450273082","pt":1717319888682,"mc":[{"id":"1.229554914","rc":[{"atb":[[1.63,2]],"id":55943164}],"con":true,"img":false}]}
{"op":"mcm","clk":"11450273226","pt":1717319890720,"mc":[{"id":"1.229554914","rc":[{"atl":[[2.84,0]],"id":70003369}],"con":true,"img":false}]}
{"op":"mcm","clk":"11450273869","pt":1717319898679,"mc":[{"id":"1.229554914","rc":[{"atl":[[2.9,10.53]],"id":70003369}],"con":true,"img":false}]}
{"op":"mcm","clk":"11450274607","pt":1717319908661,"mc":[{"id":"1.229554914","rc":[{"atl":[[2.94,12.89]],"id":70003369}],"con":true,"img":false}]}
{"op":"mcm","clk":"11450275350","pt":1717319918686,"mc":[{"id":"1.229554914","rc":[{"atl":[[2.98,15.15]],"id":70003369}],"con":true,"img":false}]}
{"op":"mcm","clk":"11450276257","pt":1717319929706,"mc":[{"id":"1.229554914","rc":[{"atb":[[1.8,0],[1.9,0]],"id":70003369},{"atb":[[1.86,0],[1.76,0]],"id":55943164}],"con":true,"img":false}]}
{"op":"mcm","clk":"11450276269","pt":1717319929807,"mc":[{"id":"1.229554914","rc":[{"atb":[[1.74,2],[1.91,0]],"id":70003369}],"con":true,"img":false}]}
{"op":"mcm","clk":"11450276293","pt":1717319930121,"mc":[{"id":"1.229554914","rc":[{"atb":[[1.44,34.09],[1.43,0]],"id":55943164}],"con":true,"img":false}]}
{"op":"mcm","clk":"11450276300","pt":1717319930174,"mc":[{"id":"1.229554914","rc":[{"atb":[[1.48,31.25]],"id":70003369}],"con":true,"img":false}]}
{"op":"mcm","clk":"11450276980","pt":1717319939546,"mc":[{"id":"1.229554914","rc":[{"atb":[[1.8,9.8],[1.9,8.72]],"id":70003369},{"atb":[[1.86,9.12],[1.76,10.32]],"id":55943164}],"con":true,"img":false}]}
{"op":"mcm","clk":"11450276997","pt":1717319939703,"mc":[{"id":"1.229554914","rc":[{"atb":[[1.74,0],[1.91,2]],"id":70003369}],"con":true,"img":false}]}
{"op":"mcm","clk":"11450277938","pt":1717319950403,"mc":[{"id":"1.229554914","rc":[{"atl":[[2.4,10.71]],"id":55943164}],"con":true,"img":false}]}
{"op":"mcm","clk":"11450277945","pt":1717319950505,"mc":[{"id":"1.229554914","rc":[{"atl":[[2.34,0]],"id":55943164}],"con":true,"img":false}]}
{"op":"mcm","clk":"11450277995","pt":1717319951231,"mc":[{"id":"1.229554914","rc":[{"atl":[[2.38,0]],"id":55943164}],"con":true,"img":false}]}
{"op":"mcm","clk":"11450278737","pt":1717319960449,"mc":[{"id":"1.229554914","rc":[{"atl":[[2.44,13.89]],"id":55943164}],"con":true,"img":false}]}
{"op":"mcm","clk":"11450279779","pt":1717319974026,"mc":[{"id":"1.229554914","rc":[{"atb":[[1.44,0]],"id":55943164}],"con":true,"img":false}]}
{"op":"mcm","clk":"11450286574","pt":1717320067461,"mc":[{"id":"1.229554914","rc":[{"atb":[[1.91,0]],"id":70003369},{"atl":[[2.52,0]],"id":70003369},{"atb":[[1.63,0]],"id":55943164},{"atl":[[2.32,0]],"id":55943164}],"con":true,"img":false}]}
{"op":"mcm","clk":"11450287984","pt":1717320088093,"mc":[{"id":"1.229554914","rc":[{"atb":[[1.91,2]],"id":70003369},{"atl":[[2.86,0],[2.74,8.62],[2.42,2]],"id":70003369},{"atb":[[1.67,2]],"id":55943164},{"atl":[[2.32,2]],"id":55943164}],"con":true,"img":false}]}
{"op":"mcm","clk":"11450287994","pt":1717320088195,"mc":[{"id":"1.229554914","rc":[{"atb":[[1.89,5.31],[1.91,0]],"id":70003369}],"con":true,"img":false}]}
{"op":"mcm","clk":"11450288623","pt":1717320098082,"mc":[{"id":"1.229554914","rc":[{"atl":[[2.78,11.24]],"id":70003369}],"con":true,"img":false}]}
{"op":"mcm","clk":"11450288662","pt":1717320098605,"mc":[{"id":"1.229554914","rc":[{"atl":[[2.98,0]],"id":70003369}],"con":true,"img":false}]}
{"op":"mcm","clk":"11450288673","pt":1717320098812,"mc":[{"id":"1.229554914","rc":[{"atb":[[1.89,0],[1.9,10.72]],"id":70003369},{"atl":[[2.74,0],[2.86,8.06],[2.42,0],[2.52,2]],"id":70003369},{"atb":[[1.67,0]],"id":55943164}],"con":true,"img":false}]}
{"op":"mcm","clk":"11450288681","pt":1717320098915,"mc":[{"id":"1.229554914","rc":[{"atb":[[1.63,2]],"id":55943164}],"con":true,"img":false}]}
{"op":"mcm","clk":"11450289033","pt":1717320104418,"mc":[{"id":"1.229554914","rc":[{"atl":[[2.78,0]],"id":70003369}],"con":true,"img":false}]}
{"op":"mcm","clk":"11450289307","pt":1717320108725,"mc":[{"id":"1.229554914","rc":[{"atl":[[2.98,15.15]],"id":70003369}],"con":true,"img":false}]}
{"op":"mcm","clk":"11450289443","pt":1717320110900,"mc":[{"id":"1.229554914","rc":[{"atl":[[2.8,8.33],[2.86,0],[2.52,0],[2.46,2]],"id":70003369}],"con":true,"img":false}]}
{"op":"mcm","clk":"11450289692","pt":1717320114535,"mc":[{"id":"1.229554914","rc":[{"atb":[[1.8,0],[1.9,2]],"id":70003369},{"atb":[[1.86,0],[1.76,0]],"id":55943164}],"con":true,"img":false}]}
{"op":"mcm","clk":"11450289704","pt":1717320114742,"mc":[{"id":"1.229554914","rc":[{"atb":[[1.74,2],[1.9,0]],"id":70003369},{"atb":[[1.63,0],[1.65,2]],"id":55943164}],"con":true,"img":false}]}
{"op":"mcm","clk":"11450289802","pt":1717320116146,"mc":[{"id":"1.229554914","rc":[{"atb":[[1.44,34.09]],"id":55943164}],"con":true,"img":false}]}
{"op":"mcm","clk":"11450289872","pt":1717320117045,"mc":[{"id":"1.229554914","rc":[{"atb":[[1.46,32.61]],"id":55943164}],"con":true,"img":false}]}
{"op":"mcm","clk":"11450289882","pt":1717320117149,"mc":[{"id":"1.229554914","rc":[{"atb":[[1.44,0]],"id":55943164}],"con":true,"img":false}]}
{"op":"mcm","clk":"11450289903","pt":1717320117414,"mc":[{"id":"1.229554914","rc":[{"atb":[[1.44,34.09]],"id":55943164}],"con":true,"img":false}]}
{"op":"mcm","clk":"11450289910","pt":1717320117532,"mc":[{"id":"1.229554914","rc":[{"atb":[[1.46,0]],"id":55943164}],"con":true,"img":false}]}
{"op":"mcm","clk":"11450290154","pt":1717320120942,"mc":[{"id":"1.229554914","rc":[{"atl":[[2.84,10.87]],"id":70003369}],"con":true,"img":false}]}
{"op":"mcm","clk":"11450290248","pt":1717320122142,"mc":[{"id":"1.229554914","rc":[{"atl":[[2.9,0],[2.98,0],[2.94,0]],"id":70003369},{"atb":[[1.46,32.61]],"id":55943164}],"con":true,"img":false}]}
{"op":"mcm","clk":"11450290254","pt":1717320122244,"mc":[{"id":"1.229554914","rc":[{"atb":[[1.44,0]],"id":55943164}],"con":true,"img":false}]}
{"op":"mcm","clk":"11450290265","pt":1717320122352,"mc":[{"id":"1.229554914","rc":[{"atl":[[2.74,8.62],[2.42,2],[2.46,0]],"id":70003369},{"atb":[[1.67,2],[1.38,0]],"id":55943164}],"con":true,"img":false}]}
{"op":"mcm","clk":"11450290273","pt":1717320122461,"mc":[{"id":"1.229554914","rc":[{"atb":[[1.65,0]],"id":55943164}],"con":true,"img":false}]}
{"op":"mcm","clk":"11450290726","pt":1717320128731,"mc":[{"id":"1.229554914","rc":[{"atl":[[2.86,8.06],[2.42,0],[2.52,2]],"id":70003369},{"atb":[[1.63,2],[1.67,0]],"id":55943164},{"atl":[[2.46,30.82]],"id":55943164}],"con":true,"img":false}]}
{"op":"mcm","clk":"11450290733","pt":1717320128830,"mc":[{"id":"1.229554914","rc":[{"atl":[[2.74,0]],"id":70003369},{"atl":[[2.4,0],[2.46,10.27]],"id":55943164}],"con":true,"img":false}]}
{"op":"mcm","clk":"11450290766","pt":1717320129241,"mc":[{"id":"1.229554914","rc":[{"atl":[[2.8,0]],"id":70003369},{"atl":[[2.42,0]],"id":55943164}],"con":true,"img":false}]}
{"op":"mcm","clk":"11450290795","pt":1717320129551,"mc":[{"id":"1.229554914","rc":[{"atl":[[2.44,0]],"id":55943164}],"con":true,"img":false}]}
{"op":"mcm","clk":"11450290799","pt":1717320129652,"mc":[{"id":"1.229554914","rc":[{"atl":[[2.84,0]],"id":70003369}],"con":true,"img":false}]}
{"op":"mcm","clk":"11450290812","pt":1717320129762,"mc":[{"id":"1.229554914","rc":[{"atb":[[1.8,9.8],[1.9,8.72]],"id":70003369},{"atb":[[1.86,9.12],[1.76,10.32]],"id":55943164}],"con":true,"img":false}]}
{"op":"mcm","clk":"11450290825","pt":1717320129869,"mc":[{"id":"1.229554914","rc":[{"atb":[[1.91,2]],"id":70003369}],"con":true,"img":false}]}
{"op":"mcm","clk":"11450290837","pt":1717320129973,"mc":[{"id":"1.229554914","rc":[{"atb":[[1.74,0]],"id":70003369}],"con":true,"img":false}]}
{"op":"mcm","clk":"11450291161","pt":1717320134670,"mc":[{"id":"1.229554914","rc":[{"atb":[[1.46,0]],"id":55943164}],"con":true,"img":false}]}
{"op":"mcm","clk":"11450291449","pt":1717320138772,"mc":[{"id":"1.229554914","rc":[{"atl":[[2.9,10.53]],"id":70003369},{"atl":[[2.5,13.33]],"id":55943164}],"con":true,"img":false}]}
{"op":"mcm","clk":"11450292129","pt":1717320148793,"mc":[{"id":"1.229554914","rc":[{"atl":[[2.94,12.89]],"id":70003369},{"atl":[[2.54,16.23]],"id":55943164}],"con":true,"img":false}]}
{"op":"mcm","clk":"11450292843","pt":1717320158811,"mc":[{"id":"1.229554914","rc":[{"atl":[[2.98,15.15]],"id":70003369},{"atl":[[2.58,18.99]],"id":55943164}],"con":true,"img":false}]}
{"op":"mcm","clk":"11450300373","pt":1717320271542,"mc":[{"id":"1.229554914","rc":[{"atb":[[1.91,0]],"id":70003369},{"atl":[[2.52,0]],"id":70003369},{"atb":[[1.63,0]],"id":55943164},{"atl":[[2.32,0]],"id":55943164}],"con":true,"img":false}]}
{"op":"mcm","clk":"11450302610","pt":1717320306195,"mc":[{"id":"1.229554914","rc":[{"atb":[[1.8,0],[1.9,0]],"id":70003369},{"atb":[[1.86,0],[1.76,0]],"id":55943164}],"con":true,"img":false}]}
{"op":"mcm","clk":"11450302799","pt":1717320309173,"mc":[{"id":"1.229554914","rc":[{"atb":[[1.44,34.09]],"id":55943164}],"con":true,"img":false}]}
{"op":"mcm","clk":"11450303468","pt":1717320319195,"mc":[{"id":"1.229554914","rc":[{"atb":[[1.38,78.95]],"id":55943164}],"con":true,"img":false}]}
{"op":"mcm","clk":"11450303925","pt":1717320326716,"mc":[{"id":"1.229554914","rc":[{"atb":[[1.8,9.8],[1.9,8.72]],"id":70003369},{"atb":[[1.86,9.12],[1.76,10.32]],"id":55943164}],"con":true,"img":false}]}
{"op":"mcm","clk":"11450307297","pt":1717320385476,"mc":[{"id":"1.229554914","rc":[{"atb":[[1.45,0],[1.48,0]],"id":70003369},{"atb":[[1.4,0],[1.44,0],[1.42,0]],"id":55943164},{"atl":[[2.46,0],[2.48,10.14]],"id":55943164}],"con":true,"img":false}]}
{"op":"mcm","clk":"11450307859","pt":1717320395498,"mc":[{"id":"1.229554914","rc":[{"atl":[[2.46,10.27]],"id":55943164}],"con":true,"img":false}]}
{"op":"mcm","clk":"11450307864","pt":1717320395603,"mc":[{"id":"1.229554914","rc":[{"atl":[[2.48,0]],"id":55943164}],"con":true,"img":false}]}
{"op":"mcm","clk":"11450307983","pt":1717320398084,"mc":[{"id":"1.229554914","rc":[{"atl":[[2.46,0],[2.48,10.14]],"id":55943164}],"con":true,"img":false}]}
{"op":"mcm","clk":"11450308698","pt":1717320409122,"mc":[{"id":"1.229554914","rc":[{"atb":[[1.91,2]],"id":70003369},{"atl":[[2.86,0],[2.46,2],[2.76,8.52]],"id":70003369},{"atb":[[1.67,2]],"id":55943164},{"atl":[[2.26,2]],"id":55943164}],"con":true,"img":false}]}
{"op":"mcm","clk":"11450308983","pt":1717320414263,"mc":[{"id":"1.229554914","rc":[{"atb":[[1.89,2],[1.91,0]],"id":70003369}],"con":true,"img":false}]}
{"op":"mcm","clk":"11450309099","pt":1717320415867,"mc":[{"id":"1.229554914","rc":[{"atl":[[2.46,10.27],[2.48,0]],"id":55943164}],"con":true,"img":false}]}
{"op":"mcm","clk":"11450309290","pt":1717320419180,"mc":[{"id":"1.229554914","rc":[{"atl":[[2.8,11.11]],"id":70003369}],"con":true,"img":false}]}
{"op":"mcm","clk":"11450309885","pt":1717320427501,"mc":[{"id":"1.229554914","rc":[{"atl":[[2.9,0],[2.98,0],[2.94,0]],"id":70003369}],"con":true,"img":false}]}
{"op":"mcm","clk":"11450310004","pt":1717320429221,"mc":[{"id":"1.229554914","rc":[{"atl":[[2.84,13.59]],"id":70003369}],"con":true,"img":false}]}
{"op":"mcm","clk":"11450310069","pt":1717320430207,"mc":[{"id":"1.229554914","rc":[{"atl":[[2.24,2],[2.26,0]],"id":55943164}],"con":true,"img":false}]}
{"op":"mcm","clk":"11450310137","pt":1717320431033,"mc":[{"id":"1.229554914","rc":[{"atl":[[2.46,0],[2.44,10.42]],"id":55943164}],"con":true,"img":false}]}
{"op":"mcm","clk":"11450310146","pt":1717320431106,"mc":[{"id":"1.229554914","rc":[{"atl":[[2.46,0],[2.44,2]],"id":70003369}],"con":true,"img":false}]}
{"op":"mcm","clk":"11450310287","pt":1717320433010,"mc":[{"id":"1.229554914","rc":[{"atl":[[2.26,2]],"id":55943164}],"con":true,"img":false}]}
{"op":"mcm","clk":"11450310294","pt":1717320433104,"mc":[{"id":"1.229554914","rc":[{"atl":[[2.24,0]],"id":55943164}],"con":true,"img":false}]}
{"op":"mcm","clk":"11450310352","pt":1717320433994,"mc":[{"id":"1.229554914","rc":[{"atl":[[2.28,2]],"id":55943164}],"con":true,"img":false}]}
{"op":"mcm","clk":"11450310361","pt":1717320434090,"mc":[{"id":"1.229554914","rc":[{"atl":[[2.26,0]],"id":55943164}],"con":true,"img":false}]}
{"op":"mcm","clk":"11450310395","pt":1717320434721,"mc":[{"id":"1.229554914","rc":[{"atl":[[2.28,0],[2.26,2]],"id":55943164}],"con":true,"img":false}]}
{"op":"mcm","clk":"11450310476","pt":1717320436211,"mc":[{"id":"1.229554914","rc":[{"atl":[[2.46,2]],"id":70003369}],"con":true,"img":false}]}
{"op":"mcm","clk":"11450310486","pt":1717320436314,"mc":[{"id":"1.229554914","rc":[{"atl":[[2.44,0]],"id":70003369}],"con":true,"img":false}]}
{"op":"mcm","clk":"11450310528","pt":1717320436895,"mc":[{"id":"1.229554914","rc":[{"atb":[[1.8,0],[1.9,0]],"id":70003369},{"atb":[[1.86,0],[1.76,0]],"id":55943164}],"con":true,"img":false}]}
{"op":"mcm","clk":"11450310531","pt":1717320437022,"mc":[{"id":"1.229554914","rc":[{"atb":[[1.46,32.61],[1.79,2],[1.89,0]],"id":70003369},{"atb":[[1.46,32.61],[1.67,0],[1.65,2]],"id":55943164}],"con":true,"img":false}]}
{"op":"mcm","clk":"11450310630","pt":1717320438780,"mc":[{"id":"1.229554914","rc":[{"atb":[[1.47,31.91]],"id":70003369}],"con":true,"img":false}]}
{"op":"mcm","clk":"11450310635","pt":1717320438884,"mc":[{"id":"1.229554914","rc":[{"atb":[[1.46,0],[1.44,34.09]],"id":55943164}],"con":true,"img":false}]}
{"op":"mcm","clk":"11450310672","pt":1717320439412,"mc":[{"id":"1.229554914","rc":[{"atl":[[2.42,10.56]],"id":55943164}],"con":true,"img":false}]}
{"op":"mcm","clk":"11450310683","pt":1717320439515,"mc":[{"id":"1.229554914","rc":[{"atl":[[2.44,0]],"id":55943164}],"con":true,"img":false}]}
{"op":"mcm","clk":"11450310703","pt":1717320439826,"mc":[{"id":"1.229554914","rc":[{"atl":[[2.24,2],[2.26,0]],"id":55943164}],"con":true,"img":false}]}
{"op":"mcm","clk":"11450310832","pt":1717320441395,"mc":[{"id":"1.229554914","rc":[{"atb":[[1.78,2]],"id":70003369}],"con":true,"img":false}]}
{"op":"mcm","clk":"11450310840","pt":1717320441498,"mc":[{"id":"1.229554914","rc":[{"atb":[[1.79,0]],"id":70003369}],"con":true,"img":false}]}
{"op":"mcm","clk":"11450311088","pt":1717320444916,"mc":[{"id":"1.229554914","rc":[{"atl":[[2.24,0],[2.26,2]],"id":55943164}],"con":true,"img":false}]}
{"op":"mcm","clk":"11450311234","pt":1717320447095,"mc":[{"id":"1.229554914","rc":[{"atl":[[2.42,0],[2.46,10.27]],"id":55943164}],"con":true,"img":false}]}
{"op":"mcm","clk":"11450311356","pt":1717320448911,"mc":[{"id":"1.229554914","rc":[{"atb":[[1.45,44.44]],"id":70003369},{"atl":[[2.88,15.96]],"id":70003369}],"con":true,"img":false}]}
{"op":"mcm","clk":"11450311734","pt":1717320455216,"mc":[{"id":"1.229554914","rc":[{"atb":[[1.88,8.92],[1.78,12.06]],"id":70003369},{"atb":[[1.88,8.92],[1.78,10.06]],"id":55943164}],"con":true,"img":false}]}
{"op":"mcm","clk":"11450311747","pt":1717320455422,"mc":[{"id":"1.229554914","rc":[{"atb":[[1.89,2],[1.78,10.06]],"id":70003369}],"con":true,"img":false}]}
{"op":"mcm","clk":"11450312510","pt":1717320467456,"mc":[{"id":"1.229554914","rc":[{"atl":[[2.46,0],[2.48,10.14]],"id":55943164}],"con":true,"img":false}]}
{"op":"mcm","clk":"11450313936","pt":1717320493496,"mc":[{"id":"1.229554914","rc":[{"atb":[[1.88,0],[1.78,0]],"id":70003369},{"atb":[[1.88,0],[1.78,0]],"id":55943164}],"con":true,"img":false}]}
{"op":"mcm","clk":"11450313942","pt":1717320493600,"mc":[{"id":"1.229554914","rc":[{"atb":[[1.78,2]],"id":70003369},{"atb":[[1.64,2],[1.65,0]],"id":55943164}],"con":true,"img":false}]}
{"op":"mcm","clk":"11450313948","pt":1717320493702,"mc":[{"id":"1.229554914","rc":[{"atb":[[1.89,0]],"id":70003369}],"con":true,"img":false}]}
{"op":"mcm","clk":"11450314052","pt":1717320495378,"mc":[{"id":"1.229554914","rc":[{"atb":[[1.47,31.91]],"id":55943164},{"atl":[[2.5,10],[2.48,0]],"id":55943164}],"con":true,"img":false}]}
{"op":"mcm","clk":"11450314221","pt":1717320497895,"mc":[{"id":"1.229554914","rc":[{"atb":[[1.47,0]],"id":55943164}],"con":true,"img":false}]}
{"op":"mcm","clk":"11450314234","pt":1717320498107,"mc":[{"id":"1.229554914","rc":[{"atb":[[1.47,31.91]],"id":55943164},{"atl":[[2.48,10.14]],"id":55943164}],"con":true,"img":false}]}
{"op":"mcm","clk":"11450314344","pt":1717320500188,"mc":[{"id":"1.229554914","rc":[{"atl":[[2.48,0]],"id":55943164}],"con":true,"img":false}]}
{"op":"mcm","clk":"11450314538","pt":1717320503174,"mc":[{"id":"1.229554914","rc":[{"atb":[[1.47,0]],"id":55943164}],"con":true,"img":false}]}
{"op":"mcm","clk":"11450314547","pt":1717320503381,"mc":[{"id":"1.229554914","rc":[{"atb":[[1.47,31.91]],"id":55943164},{"atl":[[2.48,10.14]],"id":55943164}],"con":true,"img":false}]}
{"op":"mcm","clk":"11450314599","pt":1717320504202,"mc":[{"id":"1.229554914","rc":[{"atl":[[2.48,0]],"id":55943164}],"con":true,"img":false}]}
{"op":"mcm","clk":"11450314876","pt":1717320508604,"mc":[{"id":"1.229554914","rc":[{"atb":[[1.47,0]],"id":55943164}],"con":true,"img":false}]}
{"op":"mcm","clk":"11450314885","pt":1717320508768,"mc":[{"id":"1.229554914","rc":[{"atb":[[1.47,31.91]],"id":55943164},{"atl":[[2.48,10.14]],"id":55943164}],"con":true,"img":false}]}
{"op":"mcm","clk":"11450314955","pt":1717320509901,"mc":[{"id":"1.229554914","rc":[{"atb":[[1.78,0]],"id":70003369},{"atl":[[2.46,0]],"id":70003369},{"atb":[[1.64,0]],"id":55943164},{"atl":[[2.26,0]],"id":55943164}],"con":true,"img":false}]}
{"op":"mcm","clk":"11450314962","pt":1717320510004,"mc":[{"id":"1.229554914","rc":[{"atl":[[2.48,0]],"id":55943164}],"con":true,"img":false}]}
{"op":"mcm","clk":"11450315165","pt":1717320512492,"mc":[{"id":"1.229554914","rc":[{"atb":[[1.88,8.92],[1.78,10.06]],"id":70003369},{"atb":[[1.88,8.92],[1.78,10.06]],"id":55943164}],"con":true,"img":false}]}
{"op":"mcm","clk":"11450315293","pt":1717320514192,"mc":[{"id":"1.229554914","rc":[{"atb":[[1.44,0],[1.47,0]],"id":55943164},{"atl":[[2.48,10.14]],"id":55943164}],"con":true,"img":false}]}
{"op":"mcm","clk":"11450315392","pt":1717320515495,"mc":[{"id":"1.229554914","rc":[{"atl":[[2.48,0]],"id":55943164}],"con":true,"img":false}]}
{"op":"mcm","clk":"11450315633","pt":1717320519310,"mc":[{"id":"1.229554914","rc":[{"atl":[[2.48,10.14]],"id":55943164}],"con":true,"img":false}]}
{"op":"mcm","clk":"11450315658","pt":1717320519626,"mc":[{"id":"1.229554914","rc":[{"atl":[[2.48,0]],"id":55943164}],"con":true,"img":false}]}
{"op":"mcm","clk":"11450315673","pt":1717320519892,"mc":[{"id":"1.229554914","rc":[{"atl":[[2.48,10.14]],"id":55943164}],"con":true,"img":false}]}
{"op":"mcm","clk":"11450315732","pt":1717320520878,"mc":[{"id":"1.229554914","rc":[{"atl":[[2.48,0]],"id":55943164}],"con":true,"img":false}]}
{"op":"mcm","clk":"11450315777","pt":1717320521609,"mc":[{"id":"1.229554914","rc":[{"atb":[[1.46,0],[1.47,0]],"id":70003369}],"con":true,"img":false}]}
{"op":"mcm","clk":"11450315829","pt":1717320522294,"mc":[{"id":"1.229554914","rc":[{"atl":[[2.48,10.14]],"id":55943164}],"con":true,"img":false}]}
{"op":"mcm","clk":"11450315851","pt":1717320522610,"mc":[{"id":"1.229554914","rc":[{"atl":[[2.48,0]],"id":55943164}],"con":true,"img":false}]}
{"op":"mcm","clk":"11450315884","pt":1717320523121,"mc":[{"id":"1.229554914","rc":[{"atl":[[2.48,10.14]],"id":55943164}],"con":true,"img":false}]}
{"op":"mcm","clk":"11450315896","pt":1717320523241,"mc":[{"id":"1.229554914","rc":[{"atb":[[1.89,2],[1.5,44.44]],"id":70003369},{"atl":[[2.8,8.33],[6.2,0],[2.46,2],[3.25,24.7],[2.76,0]],"id":70003369},{"atb":[[1.32,20.12],[1.66,2]],"id":55943164},{"atl":[[2.28,2],[2.58,45.22],[5.9,0]],"id":55943164}],"con":true,"img":false}]}
{"op":"mcm","clk":"11450315904","pt":1717320523292,"mc":[{"id":"1.229554914","rc":[{"atl":[[2.48,0]],"id":55943164}],"con":true,"img":false}]}
{"op":"mcm","clk":"11450323191","pt":1717320528645,"mc":[{"id":"1.229554914","rc":[{"atl":[[2.28,0],[2.44,2]],"id":55943164}],"con":true,"img":false}]}
{"op":"mcm","clk":"11450323198","pt":1717320528667,"mc":[{"id":"1.229554914","rc":[{"atl":[[2.64,26.23],[2.58,18.99]],"id":55943164}],"con":true,"img":false}]}
{"op":"mcm","clk":"11450323203","pt":1717320528679,"mc":[{"id":"1.229554914","rc":[{"atl":[[2.4,2],[2.44,0]],"id":55943164}],"con":true,"img":false}]}
{"op":"mcm","clk":"11450323223","pt":1717320528892,"mc":[{"id":"1.229554914","rc":[{"atl":[[2.4,0],[2.42,2]],"id":55943164}],"con":true,"img":false}]}
{"op":"mcm","clk":"11450323278","pt":1717320529927,"mc":[{"id":"1.229554914","rc":[{"atb":[[1.37,18.98],[1.32,0]],"id":55943164}],"con":true,"img":false}]}
{"op":"mcm","clk":"11450323324","pt":1717320530542,"mc":[{"id":"1.229554914","rc":[{"atl":[[2.42,0],[2.44,2]],"id":55943164}],"con":true,"img":false}]}
{"op":"mcm","clk":"11450323448","pt":1717320532460,"mc":[{"id":"1.229554914","rc":[{"atl":[[2.4,2]],"id":55943164}],"con":true,"img":false}]}
{"op":"mcm","clk":"11450323456","pt":1717320532514,"mc":[{"id":"1.229554914","rc":[{"atl":[[2.44,0]],"id":55943164}],"con":true,"img":false}]}
{"op":"mcm","clk":"11450323482","pt":1717320532812,"mc":[{"id":"1.229554914","rc":[{"atl":[[2.42,2]],"id":55943164}],"con":true,"img":false}]}
{"op":"mcm","clk":"11450323493","pt":1717320532926,"mc":[{"id":"1.229554914","rc":[{"atl":[[2.4,0]],"id":55943164}],"con":true,"img":false}]}
{"op":"mcm","clk":"11450323526","pt":1717320533435,"mc":[{"id":"1.229554914","rc":[{"atl":[[2.84,24.46]],"id":70003369},{"atl":[[2.54,12.99]],"id":55943164}],"con":true,"img":false}]}
{"op":"mcm","clk":"11450323539","pt":1717320533571,"mc":[{"id":"1.229554914","rc":[{"atl":[[2.84,10.87]],"id":70003369}],"con":true,"img":false}]}
{"op":"mcm","clk":"11450323977","pt":1717320539619,"mc":[{"id":"1.229554914","rc":[{"atl":[[2.42,0],[2.44,2]],"id":55943164}],"con":true,"img":false}]}
{"op":"mcm","clk":"11450324088","pt":1717320541167,"mc":[{"id":"1.229554914","rc":[{"atl":[[2.42,2],[2.44,0]],"id":55943164}],"con":true,"img":false}]}
{"op":"mcm","clk":"11450324108","pt":1717320541320,"mc":[{"id":"1.229554914","rc":[{"atl":[[2.42,0],[2.44,2]],"id":55943164}],"con":true,"img":false}]}
{"op":"mcm","clk":"11450324145","pt":1717320541840,"mc":[{"id":"1.229554914","rc":[{"atl":[[2.4,2]],"id":55943164}],"con":true,"img":false}]}
{"op":"mcm","clk":"11450324158","pt":1717320541945,"mc":[{"id":"1.229554914","rc":[{"atl":[[2.44,0]],"id":55943164}],"con":true,"img":false}]}
{"op":"mcm","clk":"11450324244","pt":1717320542933,"mc":[{"id":"1.229554914","rc":[{"atl":[[2.4,0],[2.42,2]],"id":55943164}],"con":true,"img":false}]}
{"op":"mcm","clk":"11450324294","pt":1717320543535,"mc":[{"id":"1.229554914","rc":[{"atl":[[2.58,15.82]],"id":55943164}],"con":true,"img":false}]}
{"op":"mcm","clk":"11450324301","pt":1717320543637,"mc":[{"id":"1.229554914","rc":[{"atl":[[2.88,13.3]],"id":70003369}],"con":true,"img":false}]}
{"op":"mcm","clk":"11450324325","pt":1717320543949,"mc":[{"id":"1.229554914","rc":[{"atl":[[2.42,0],[2.44,2]],"id":55943164}],"con":true,"img":false}]}
{"op":"mcm","clk":"11450324444","pt":1717320545755,"mc":[{"id":"1.229554914","rc":[{"atl":[[2.4,2],[2.44,0]],"id":55943164}],"con":true,"img":false}]}
{"op":"mcm","clk":"11450324481","pt":1717320546327,"mc":[{"id":"1.229554914","rc":[{"atl":[[2.42,2]],"id":55943164}],"con":true,"img":false}]}
{"op":"mcm","clk":"11450324489","pt":1717320546445,"mc":[{"id":"1.229554914","rc":[{"atl":[[2.4,0]],"id":55943164}],"con":true,"img":false}]}
{"op":"mcm","clk":"11450324922","pt":1717320551426,"mc":[{"id":"1.229554914","rc":[{"atl":[[2.44,2]],"id":55943164}],"con":true,"img":false}]}
{"op":"mcm","clk":"11450324931","pt":1717320551528,"mc":[{"id":"1.229554914","rc":[{"atl":[[2.42,0]],"id":55943164}],"con":true,"img":false}]}
{"op":"mcm","clk":"11450325109","pt":1717320553459,"mc":[{"id":"1.229554914","rc":[{"atl":[[2.48,10.14]],"id":55943164}],"con":true,"img":false}]}
{"op":"mcm","clk":"11450325115","pt":1717320553558,"mc":[{"id":"1.229554914","rc":[{"atl":[[2.92,15.62]],"id":70003369}],"con":true,"img":false}]}
{"op":"mcm","clk":"11450325323","pt":1717320556151,"mc":[{"id":"1.229554914","rc":[{"atl":[[2.78,8.43]],"id":70003369}],"con":true,"img":false}]}
{"op":"mcm","clk":"11450325332","pt":1717320556260,"mc":[{"id":"1.229554914","rc":[{"atl":[[2.8,0]],"id":70003369}],"con":true,"img":false}]}
{"op":"mcm","clk":"11450325392","pt":1717320556840,"mc":[{"id":"1.229554914","rc":[{"atl":[[2.42,2],[2.44,0]],"id":55943164}],"con":true,"img":false}]}
{"op":"mcm","clk":"11450325458","pt":1717320557563,"mc":[{"id":"1.229554914","rc":[{"atl":[[2.4,2],[2.42,0]],"id":55943164}],"con":true,"img":false}]}
{"op":"mcm","clk":"11450325850","pt":1717320562679,"mc":[{"id":"1.229554914","rc":[{"atl":[[2.44,2]],"id":55943164}],"con":true,"img":false}]}
{"op":"mcm","clk":"11450325857","pt":1717320562735,"mc":[{"id":"1.229554914","rc":[{"atl":[[2.4,0]],"id":55943164}],"con":true,"img":false}]}
{"op":"mcm","clk":"11450325950","pt":1717320563974,"mc":[{"id":"1.229554914","rc":[{"atl":[[2.46,2]],"id":55943164}],"con":true,"img":false}]}
{"op":"mcm","clk":"11450325960","pt":1717320564081,"mc":[{"id":"1.229554914","rc":[{"atl":[[2.44,0]],"id":55943164}],"con":true,"img":false}]}
{"op":"mcm","clk":"11450326196","pt":1717320567241,"mc":[{"id":"1.229554914","rc":[{"atl":[[2.44,2]],"id":55943164}],"con":true,"img":false}]}
{"op":"mcm","clk":"11450326204","pt":1717320567346,"mc":[{"id":"1.229554914","rc":[{"atl":[[2.46,0]],"id":55943164}],"con":true,"img":false}]}
{"op":"mcm","clk":"11450326221","pt":1717320567558,"mc":[{"id":"1.229554914","rc":[{"atl":[[2.46,2],[2.44,0]],"id":55943164}],"con":true,"img":false}]}
{"op":"mcm","clk":"11450326396","pt":1717320569682,"mc":[{"id":"1.229554914","rc":[{"atl":[[2.42,2],[2.46,0]],"id":55943164}],"con":true,"img":false}]}
{"op":"mcm","clk":"11450326681","pt":1717320573357,"mc":[{"id":"1.229554914","rc":[{"atl":[[2.42,0],[2.44,2]],"id":55943164}],"con":true,"img":false}]}
{"op":"mcm","clk":"11450327548","pt":1717320585593,"mc":[{"id":"1.229554914","rc":[{"atl":[[2.42,2]],"id":55943164}],"con":true,"img":false}]}
{"op":"mcm","clk":"11450327554","pt":1717320585699,"mc":[{"id":"1.229554914","rc":[{"atl":[[2.44,0]],"id":55943164}],"con":true,"img":false}]}
{"op":"mcm","clk":"11450327616","pt":1717320586688,"mc":[{"id":"1.229554914","rc":[{"atl":[[2.4,2],[2.42,0]],"id":55943164}],"con":true,"img":false}]}
{"op":"mcm","clk":"11450327908","pt":1717320590936,"mc":[{"id":"1.229554914","rc":[{"atb":[[1.5,0],[1.65,44.44]],"id":70003369},{"atl":[[2.84,24.17],[3.25,0],[2.78,0],[2.48,10.14]],"id":70003369},{"atb":[[1.79,2],[1.37,0],[1.43,18.98],[1.66,0]],"id":55943164},{"atl":[[2.82,23.13],[2.64,0]],"id":55943164}],"con":true,"img":false}]}
{"op":"mcm","clk":"11450327973","pt":1717320591919,"mc":[{"id":"1.229554914","rc":[{"atl":[[2.4,0],[2.42,2]],"id":55943164}],"con":true,"img":false}]}
{"op":"mcm","clk":"11450328047","pt":1717320592916,"mc":[{"id":"1.229554914","rc":[{"atl":[[2.42,2]],"id":70003369}],"con":true,"img":false}]}
{"op":"mcm","clk":"11450328056","pt":1717320593018,"mc":[{"id":"1.229554914","rc":[{"atl":[[2.46,0]],"id":70003369}],"con":true,"img":false}]}
{"op":"mcm","clk":"11450328326","pt":1717320597016,"mc":[{"id":"1.229554914","rc":[{"atb":[[1.43,0],[1.54,18.98]],"id":55943164},{"atl":[[2.82,0],[2.5,22.99]],"id":55943164}],"con":true,"img":false}]}
{"op":"mcm","clk":"11450328339","pt":1717320597221,"mc":[{"id":"1.229554914","rc":[{"atl":[[2.44,2]],"id":55943164}],"con":true,"img":false}]}
{"op":"mcm","clk":"11450328347","pt":1717320597317,"mc":[{"id":"1.229554914","rc":[{"atl":[[2.42,0]],"id":55943164}],"con":true,"img":false}]}
{"op":"mcm","clk":"11450328384","pt":1717320598010,"mc":[{"id":"1.229554914","rc":[{"atl":[[2.42,0],[2.44,2]],"id":70003369}],"con":true,"img":false}]}
{"op":"mcm","clk":"11450328394","pt":1717320598106,"mc":[{"id":"1.229554914","rc":[{"atl":[[2.66,15.62],[2.84,10.87]],"id":70003369}],"con":true,"img":false}]}
{"op":"mcm","clk":"11450328533","pt":1717320600021,"mc":[{"id":"1.229554914","rc":[{"atl":[[2.52,13.16]],"id":70003369}],"con":true,"img":false}]}
{"op":"mcm","clk":"11450328885","pt":1717320603868,"mc":[{"id":"1.229554914","rc":[{"atl":[[2.92,0]],"id":70003369}],"con":true,"img":false}]}
{"op":"mcm","clk":"11450328929","pt":1717320604496,"mc":[{"id":"1.229554914","rc":[{"atb":[[1.88,0],[1.78,0]],"id":70003369},{"atb":[[1.88,0],[1.78,0]],"id":55943164}],"con":true,"img":false}]}
{"op":"mcm","clk":"11450328949","pt":1717320604656,"mc":[{"id":"1.229554914","rc":[{"atb":[[1.46,32.61],[1.89,0],[1.45,90.88],[1.65,0],[1.66,2]],"id":70003369},{"atb":[[1.46,32.61],[1.79,0],[1.54,0],[1.65,2],[1.38,127.31]],"id":55943164}],"con":true,"img":false}]}
{"op":"mcm","clk":"11450328959","pt":1717320604759,"mc":[{"id":"1.229554914","rc":[{"atb":[[1.65,44.44]],"id":70003369},{"atb":[[1.54,18.98],[1.38,78.95]],"id":55943164}],"con":true,"img":false}]}
{"op":"mcm","clk":"11450328968","pt":1717320604863,"mc":[{"id":"1.229554914","rc":[{"atb":[[1.46,102.38],[1.45,44.44],[1.65,0]],"id":70003369},{"atb":[[1.54,0],[1.38,151.49]],"id":55943164}],"con":true,"img":false}]}
{"op":"mcm","clk":"11450328976","pt":1717320604967,"mc":[{"id":"1.229554914","rc":[{"atb":[[1.46,65.22],[1.38,78.94]],"id":55943164}],"con":true,"img":false}]}
{"op":"mcm","clk":"11450328982","pt":1717320605069,"mc":[{"id":"1.229554914","rc":[{"atb":[[1.38,146.17]],"id":55943164}],"con":true,"img":false}]}
{"op":"mcm","clk":"11450328990","pt":1717320605171,"mc":[{"id":"1.229554914","rc":[{"atb":[[1.46,32.61]],"id":55943164}],"con":true,"img":false}]}
{"op":"mcm","clk":"11450329032","pt":1717320605797,"mc":[{"id":"1.229554914","rc":[{"atl":[[2.92,24.03],[2.66,0]],"id":70003369},{"atl":[[2.74,25.98]],"id":55943164}],"con":true,"img":false}]}
{"op":"mcm","clk":"11450329037","pt":1717320605855,"mc":[{"id":"1.229554914","rc":[{"atl":[[2.5,10]],"id":55943164}],"con":true,"img":false}]}
{"op":"mcm","clk":"11450329044","pt":1717320605961,"mc":[{"id":"1.229554914","rc":[{"atb":[[1.65,2]],"id":70003369}],"con":true,"img":false}]}
{"op":"mcm","clk":"11450329089","pt":1717320606139,"mc":[{"id":"1.229554914","rc":[{"atb":[[1.46,32.61],[1.66,0],[1.65,46.44]],"id":70003369}],"con":true,"img":false}]}
{"op":"mcm","clk":"11450329421","pt":1717320611300,"mc":[{"id":"1.229554914","rc":[{"atb":[[1.45,123.49],[1.65,2]],"id":70003369}],"con":true,"img":false}]}
{"op":"mcm","clk":"11450329611","pt":1717320613584,"mc":[{"id":"1.229554914","rc":[{"atb":[[1.44,45.45]],"id":70003369},{"atl":[[2.56,16.03]],"id":70003369},{"atb":[[1.44,45.45]],"id":55943164}],"con":true,"img":false}]}
{"op":"mcm","clk":"11450329618","pt":1717320613687,"mc":[{"id":"1.229554914","rc":[{"atb":[[1.45,45.45],[1.38,78.95]],"id":55943164}],"con":true,"img":false}]}
{"op":"mcm","clk":"11450329660","pt":1717320614261,"mc":[{"id":"1.229554914","rc":[{"atb":[[1.65,0],[1.66,2]],"id":70003369},{"atl":[[2.88,0]],"id":70003369},{"atl":[[2.42,2],[2.44,0]],"id":55943164}],"con":true,"img":false}]}
{"op":"mcm","clk":"11450329716","pt":1717320614985,"mc":[{"id":"1.229554914","rc":[{"atl":[[2.5,10],[2.48,0]],"id":70003369},{"atl":[[2.48,0]],"id":55943164}],"con":true,"img":false}]}
{"op":"mcm","clk":"11450329870","pt":1717320616959,"mc":[{"id":"1.229554914","rc":[{"atl":[[2.5,0],[2.48,10.14]],"id":70003369},{"atl":[[2.48,10.14]],"id":55943164}],"con":true,"img":false}]}
{"op":"mcm","clk":"11450330398","pt":1717320623597,"mc":[{"id":"1.229554914","rc":[{"atb":[[1.88,8.92],[1.78,10.06]],"id":70003369},{"atb":[[1.88,8.92],[1.78,10.06]],"id":55943164}],"con":true,"img":false}]}
{"op":"mcm","clk":"11450330409","pt":1717320623700,"mc":[{"id":"1.229554914","rc":[{"atb":[[1.64,45.45],[1.45,44.44],[1.89,2],[1.66,0]],"id":70003369},{"atb":[[1.79,2],[1.45,0],[1.54,45.45],[1.65,0]],"id":55943164}],"con":true,"img":false}]}
{"op":"mcm","clk":"11450330437","pt":1717320624009,"mc":[{"id":"1.229554914","rc":[{"atl":[[2.92,0],[2.66,23.3]],"id":70003369},{"atl":[[2.5,22.99],[2.74,0]],"id":55943164}],"con":true,"img":false}]}
{"op":"mcm","clk":"11450330602","pt":1717320625675,"mc":[{"id":"1.229554914","rc":[{"atl":[[2.6,18.75]],"id":70003369}],"con":true,"img":false}]}
{"op":"mcm","clk":"11450330675","pt":1717320626603,"mc":[{"id":"1.229554914","rc":[{"atl":[[2.56,0],[2.52,0],[2.46,10.27],[2.6,0],[2.84,0],[2.48,0]],"id":70003369},{"atl":[[2.46,10.27],[2.48,0]],"id":55943164}],"con":true,"img":false}]}
{"op":"mcm","clk":"11450330857","pt":1717320628782,"mc":[{"id":"1.229554914","rc":[{"atl":[[2.52,9.87],[2.46,0]],"id":70003369},{"atl":[[2.52,9.87],[2.46,0]],"id":55943164}],"con":true,"img":false}]}
{"op":"mcm","clk":"11450330876","pt":1717320628990,"mc":[{"id":"1.229554914","rc":[{"atl":[[2.5,10],[2.52,34.86]],"id":55943164}],"con":true,"img":false}]}
{"op":"mcm","clk":"11450330922","pt":1717320629501,"mc":[{"id":"1.229554914","rc":[{"atl":[[2.5,10]],"id":70003369}],"con":true,"img":false}]}
{"op":"mcm","clk":"11450330965","pt":1717320629873,"mc":[{"id":"1.229554914","rc":[{"atl":[[2.46,10.27]],"id":70003369}],"con":true,"img":false}]}
{"op":"mcm","clk":"11450330971","pt":1717320629971,"mc":[{"id":"1.229554914","rc":[{"atl":[[2.5,0],[2.44,10.42]],"id":55943164}],"con":true,"img":false}]}
{"op":"mcm","clk":"11450331019","pt":1717320630596,"mc":[{"id":"1.229554914","rc":[{"atb":[[1.46,0],[1.45,0]],"id":70003369},{"atb":[[1.46,0]],"id":55943164}],"con":true,"img":false}]}
{"op":"mcm","clk":"11450331330","pt":1717320634287,"mc":[{"id":"1.229554914","rc":[{"atl":[[2.36,2],[2.44,0]],"id":70003369}],"con":true,"img":false}]}
{"op":"mcm","clk":"11450331649","pt":1717320638394,"mc":[{"id":"1.229554914","rc":[{"atl":[[2.5,23.33]],"id":70003369}],"con":true,"img":false}]}
{"op":"mcm","clk":"11450331657","pt":1717320638506,"mc":[{"id":"1.229554914","rc":[{"atl":[[2.5,13.33]],"id":70003369}],"con":true,"img":false}]}
{"op":"mcm","clk":"11450331825","pt":1717320640700,"mc":[{"id":"1.229554914","rc":[{"atl":[[2.46,0]],"id":70003369},{"atl":[[2.5,10],[2.44,0]],"id":55943164}],"con":true,"img":false}]}
{"op":"mcm","clk":"11450331834","pt":1717320640804,"mc":[{"id":"1.229554914","rc":[{"atl":[[2.52,9.87],[2.48,12.99]],"id":55943164}],"con":true,"img":false}]}
{"op":"mcm","clk":"11450331888","pt":1717320641531,"mc":[{"id":"1.229554914","rc":[{"atl":[[2.5,0]],"id":70003369},{"atl":[[2.5,0],[2.48,23.13]],"id":55943164}],"con":true,"img":false}]}
{"op":"mcm","clk":"11450331905","pt":1717320641686,"mc":[{"id":"1.229554914","rc":[{"atl":[[2.5,10],[2.48,12.99]],"id":55943164}],"con":true,"img":false}]}
{"op":"mcm","clk":"11450332115","pt":1717320644187,"mc":[{"id":"1.229554914","rc":[{"atl":[[2.5,0],[2.44,10.42]],"id":55943164}],"con":true,"img":false}]}
{"op":"mcm","clk":"11450332331","pt":1717320646829,"mc":[{"id":"1.229554914","rc":[{"atl":[[2.56,12.82]],"id":70003369}],"con":true,"img":false}]}
{"op":"mcm","clk":"11450332700","pt":1717320652508,"mc":[{"id":"1.229554914","rc":[{"atl":[[2.44,0],[2.48,23.13]],"id":55943164}],"con":true,"img":false}]}
{"op":"mcm","clk":"11450332707","pt":1717320652602,"mc":[{"id":"1.229554914","rc":[{"atl":[[2.52,35],[2.48,10.14]],"id":55943164}],"con":true,"img":false}]}
{"op":"mcm","clk":"11450332890","pt":1717320655013,"mc":[{"id":"1.229554914","rc":[{"atl":[[2.6,15.62]],"id":70003369}],"con":true,"img":false}]}
{"op":"mcm","clk":"11450333267","pt":1717320660260,"mc":[{"id":"1.229554914","rc":[{"atb":[[1.88,0],[1.78,0]],"id":70003369},{"atb":[[1.88,0],[1.78,0]],"id":55943164}],"con":true,"img":false}]}
{"op":"mcm","clk":"11450333284","pt":1717320660420,"mc":[{"id":"1.229554914","rc":[{"atb":[[1.64,0],[1.44,92.9],[1.89,0],[1.67,2]],"id":70003369},{"atb":[[1.79,0],[1.44,92.9],[1.54,0],[1.7,2]],"id":55943164}],"con":true,"img":false}]}
{"op":"mcm","clk":"11450333293","pt":1717320660525,"mc":[{"id":"1.229554914","rc":[{"atb":[[1.44,45.45],[1.67,71.77]],"id":70003369},{"atb":[[1.44,45.45],[1.55,78.95]],"id":55943164}],"con":true,"img":false}]}
{"op":"mcm","clk":"11450333300","pt":1717320660633,"mc":[{"id":"1.229554914","rc":[{"atb":[[1.43,186.99]],"id":70003369},{"atb":[[1.44,126.4],[1.45,33.33]],"id":55943164}],"con":true,"img":false}]}
{"op":"mcm","clk":"11450333309","pt":1717320660743,"mc":[{"id":"1.229554914","rc":[{"atb":[[1.67,2]],"id":70003369},{"atb":[[1.55,0]],"id":55943164}],"con":true,"img":false}]}
{"op":"mcm","clk":"11450333315","pt":1717320660844,"mc":[{"id":"1.229554914","rc":[{"atb":[[1.44,34.09]],"id":70003369},{"atb":[[1.48,31.25]],"id":55943164}],"con":true,"img":false}]}
{"op":"mcm","clk":"11450333336","pt":1717320661156,"mc":[{"id":"1.229554914","rc":[{"atl":[[2.5,10],[2.48,0]],"id":55943164}],"con":true,"img":false}]}
{"op":"mcm","clk":"11450333760","pt":1717320666416,"mc":[{"id":"1.229554914","rc":[{"atl":[[2.48,10.14]],"id":55943164}],"con":true,"img":false}]}
{"op":"mcm","clk":"11450333769","pt":1717320666517,"mc":[{"id":"1.229554914","rc":[{"atl":[[2.5,0]],"id":55943164}],"con":true,"img":false}]}
{"op":"mcm","clk":"11450333942","pt":1717320668818,"mc":[{"id":"1.229554914","rc":[{"atb":[[1.42,47.62]],"id":70003369},{"atl":[[2.64,18.29]],"id":70003369}],"con":true,"img":false}]}
{"op":"mcm","clk":"11450334351","pt":1717320673955,"mc":[{"id":"1.229554914","rc":[{"atb":[[1.88,8.92],[1.78,10.06]],"id":70003369},{"atb":[[1.88,8.92],[1.78,10.06]],"id":55943164}],"con":true,"img":false}]}
{"op":"mcm","clk":"11450334378","pt":1717320674124,"mc":[{"id":"1.229554914","rc":[{"atb":[[1.43,69.77],[1.89,2],[1.67,0],[1.65,47.62]],"id":70003369},{"atb":[[1.79,2],[1.44,45.45],[1.55,33.33],[1.7,0]],"id":55943164}],"con":true,"img":false}]}
{"op":"mcm","clk":"11450334787","pt":1717320678539,"mc":[{"id":"1.229554914","rc":[{"atl":[[2.4,2],[2.42,0]],"id":55943164}],"con":true,"img":false}]}
{"op":"mcm","clk":"11450334799","pt":1717320678638,"mc":[{"id":"1.229554914","rc":[{"atl":[[2.48,23.13]],"id":55943164}],"con":true,"img":false}]}
{"op":"mcm","clk":"11450334808","pt":1717320678744,"mc":[{"id":"1.229554914","rc":[{"atl":[[2.52,9.87]],"id":55943164}],"con":true,"img":false}]}
{"op":"mcm","clk":"11450334815","pt":1717320678850,"mc":[{"id":"1.229554914","rc":[{"atl":[[2.44,2]],"id":55943164}],"con":true,"img":false}]}
{"op":"mcm","clk":"11450334823","pt":1717320678950,"mc":[{"id":"1.229554914","rc":[{"atl":[[2.4,0],[2.6,9.38],[2.48,12.99]],"id":55943164}],"con":true,"img":false}]}
{"op":"mcm","clk":"11450334856","pt":1717320679563,"mc":[{"id":"1.229554914","rc":[{"atl":[[2.54,0],[2.42,2],[2.52,0],[2.6,0],[2.58,0]],"id":55943164}],"con":true,"img":false}]}
{"op":"mcm","clk":"11450334863","pt":1717320679668,"mc":[{"id":"1.229554914","rc":[{"atl":[[2.44,0]],"id":55943164}],"con":true,"img":false}]}
{"op":"mcm","clk":"11450334869","pt":1717320679775,"mc":[{"id":"1.229554914","rc":[{"atl":[[2.72,17.44],[2.6,9.38],[2.64,12.2],[2.68,14.88]],"id":55943164}],"con":true,"img":false}]}
{"op":"mcm","clk":"11450334906","pt":1717320680248,"mc":[{"id":"1.229554914","rc":[{"atl":[[2.42,0],[2.44,2]],"id":55943164}],"con":true,"img":false}]}
{"op":"mcm","clk":"11450334939","pt":1717320680656,"mc":[{"id":"1.229554914","rc":[{"atb":[[1.48,0]],"id":55943164},{"atl":[[2.58,9.49]],"id":55943164}],"con":true,"img":false}]}
{"op":"mcm","clk":"11450334945","pt":1717320680763,"mc":[{"id":"1.229554914","rc":[{"atl":[[2.6,0]],"id":55943164}],"con":true,"img":false}]}
{"op":"mcm","clk":"11450335188","pt":1717320683774,"mc":[{"id":"1.229554914","rc":[{"atl":[[2.58,24.48],[2.48,0]],"id":55943164}],"con":true,"img":false}]}
{"op":"mcm","clk":"11450335200","pt":1717320683943,"mc":[{"id":"1.229554914","rc":[{"atl":[[2.64,38.68],[2.58,9.49]],"id":55943164}],"con":true,"img":false}]}
{"op":"mcm","clk":"11450335255","pt":1717320684873,"mc":[{"id":"1.229554914","rc":[{"atl":[[2.36,0],[2.38,2]],"id":70003369}],"con":true,"img":false}]}
{"op":"mcm","clk":"11450335289","pt":1717320685341,"mc":[{"id":"1.229554914","rc":[{"atl":[[2.42,2]],"id":55943164}],"con":true,"img":false}]}
{"op":"mcm","clk":"11450335297","pt":1717320685449,"mc":[{"id":"1.229554914","rc":[{"atl":[[2.44,0]],"id":55943164}],"con":true,"img":false}]}
{"op":"mcm","clk":"11450335331","pt":1717320685860,"mc":[{"id":"1.229554914","rc":[{"atl":[[2.38,2]],"id":55943164}],"con":true,"img":false}]}
{"op":"mcm","clk":"11450335338","pt":1717320685959,"mc":[{"id":"1.229554914","rc":[{"atl":[[2.42,0]],"id":55943164}],"con":true,"img":false}]}
{"op":"mcm","clk":"11450335530","pt":1717320688461,"mc":[{"id":"1.229554914","rc":[{"atl":[[2.4,2],[2.38,0]],"id":55943164}],"con":true,"img":false}]}
{"op":"mcm","clk":"11450335920","pt":1717320693563,"mc":[{"id":"1.229554914","rc":[{"atl":[[2.4,0],[2.38,2]],"id":55943164}],"con":true,"img":false}]}
{"op":"mcm","clk":"11450335928","pt":1717320693664,"mc":[{"id":"1.229554914","rc":[{"atl":[[2.58,24.37]],"id":55943164}],"con":true,"img":false}]}
{"op":"mcm","clk":"11450335934","pt":1717320693771,"mc":[{"id":"1.229554914","rc":[{"atl":[[2.64,12.2]],"id":55943164}],"con":true,"img":false}]}
{"op":"mcm","clk":"11450335943","pt":1717320693874,"mc":[{"id":"1.229554914","rc":[{"atl":[[2.36,2],[2.38,0]],"id":70003369}],"con":true,"img":false}]}
{"op":"mcm","clk":"11450336015","pt":1717320694868,"mc":[{"id":"1.229554914","rc":[{"atl":[[2.4,2],[2.38,0]],"id":55943164}],"con":true,"img":false}]}
{"op":"mcm","clk":"11450336188","pt":1717320697494,"mc":[{"id":"1.229554914","rc":[{"atl":[[2.6,9.38],[2.58,14.88]],"id":55943164}],"con":true,"img":false}]}
{"op":"mcm","clk":"11450336567","pt":1717320702181,"mc":[{"id":"1.229554914","rc":[{"atb":[[1.88,0],[1.78,0]],"id":70003369},{"atb":[[1.88,0],[1.78,0]],"id":55943164}],"con":true,"img":false}]}
{"op":"mcm","clk":"11450336581","pt":1717320702386,"mc":[{"id":"1.229554914","rc":[{"atb":[[1.46,32.61],[1.44,83.71],[1.89,0],[1.68,2],[1.65,0]],"id":70003369},{"atb":[[1.46,32.61],[1.79,0],[1.45,78.78],[1.55,0],[1.7,2]],"id":55943164},{"atl":[[2.6,0],[2.48,10.14]],"id":55943164}],"con":true,"img":false}]}
{"op":"mcm","clk":"11450337211","pt":1717320709665,"mc":[{"id":"1.229554914","rc":[{"atb":[[1.42,59.52]],"id":55943164},{"atl":[[2.52,13.16]],"id":55943164}],"con":true,"img":false}]}
{"op":"mcm","clk":"11450337219","pt":1717320709771,"mc":[{"id":"1.229554914","rc":[{"atl":[[2.52,28.04],[2.58,0]],"id":55943164}],"con":true,"img":false}]}
{"op":"mcm","clk":"11450337233","pt":1717320709982,"mc":[{"id":"1.229554914","rc":[{"atb":[[1.38,0]],"id":55943164},{"atl":[[2.72,0],[2.52,14.88],[2.64,9.15],[2.48,0]],"id":55943164}],"con":true,"img":false}]}
{"op":"mcm","clk":"11450337815","pt":1717320717093,"mc":[{"id":"1.229554914","rc":[{"atl":[[2.68,26.78]],"id":55943164}],"con":true,"img":false}]}
{"op":"mcm","clk":"11450337823","pt":1717320717192,"mc":[{"id":"1.229554914","rc":[{"atl":[[2.64,26.03],[2.68,11.9]],"id":55943164}],"con":true,"img":false}]}
{"op":"mcm","clk":"11450337834","pt":1717320717295,"mc":[{"id":"1.229554914","rc":[{"atl":[[2.52,0]],"id":55943164}],"con":true,"img":false}]}
{"op":"mcm","clk":"11450337854","pt":1717320717498,"mc":[{"id":"1.229554914","rc":[{"atl":[[2.62,9.26]],"id":55943164}],"con":true,"img":false}]}
{"op":"mcm","clk":"11450338327","pt":1717320723012,"mc":[{"id":"1.229554914","rc":[{"atb":[[1.46,0],[1.45,33.33]],"id":70003369},{"atb":[[1.46,0],[1.5,30]],"id":55943164}],"con":true,"img":false}]}
{"op":"mcm","clk":"11450338338","pt":1717320723115,"mc":[{"id":"1.229554914","rc":[{"atl":[[2.36,6.09]],"id":70003369},{"atb":[[1.7,6.73]],"id":55943164},{"atl":[[2.4,6.23]],"id":55943164}],"con":true,"img":false}]}
{"op":"mcm","clk":"11450338349","pt":1717320723218,"mc":[{"id":"1.229554914","rc":[{"atb":[[1.68,6.56]],"id":70003369},{"atb":[[1.45,33.33],[1.55,45.45]],"id":55943164},{"atl":[[2.46,12.46],[2.64,9.15]],"id":55943164}],"con":true,"img":false}]}
{"op":"mcm","clk":"11450338357","pt":1717320723328,"mc":[{"id":"1.229554914","rc":[{"atb":[[1.44,34.09],[1.88,8.92],[1.78,10.06],[1.65,69.77]],"id":70003369},{"atb":[[1.88,8.92],[1.78,10.06]],"id":55943164}],"con":true,"img":false}]}
{"op":"mcm","clk":"11450338374","pt":1717320723503,"mc":[{"id":"1.229554914","rc":[{"atb":[[1.89,4.33],[1.68,4.56]],"id":70003369},{"atb":[[1.79,4.49],[1.7,4.73]],"id":55943164}],"con":true,"img":false}]}
{"op":"mcm","clk":"11450340137","pt":1717320744767,"mc":[{"id":"1.229554914","rc":[{"atb":[[1.89,0]],"id":70003369},{"atl":[[2.36,4.09]],"id":70003369},{"atb":[[1.79,0]],"id":55943164},{"atl":[[2.4,4.23]],"id":55943164}],"con":true,"img":false}]}
{"op":"mcm","clk":"11450341148","pt":1717320757332,"mc":[{"id":"1.229554914","rc":[{"atb":[[1.88,0],[1.78,0]],"id":70003369},{"atb":[[1.88,0],[1.78,0]],"id":55943164}],"con":true,"img":false}]}
{"op":"mcm","clk":"11450341507","pt":1717320761670,"mc":[{"id":"1.229554914","rc":[{"atb":[[1.64,74.34],[1.65,0],[1.69,2]],"id":70003369},{"atl":[[2.36,6.09],[2.56,0],[2.52,0]],"id":70003369},{"atb":[[1.71,2]],"id":55943164},{"atl":[[2.4,6.23]],"id":55943164}],"con":true,"img":false}]}
{"op":"mcm","clk":"11450341993","pt":1717320767945,"mc":[{"id":"1.229554914","rc":[{"atb":[[1.86,9.12],[1.76,10.32]],"id":70003369},{"atb":[[1.8,9.8],[1.9,8.72]],"id":55943164}],"con":true,"img":false}]}
{"op":"mcm","clk":"11450342013","pt":1717320768107,"mc":[{"id":"1.229554914","rc":[{"atb":[[1.87,2.04],[1.69,0]],"id":70003369},{"atb":[[1.77,2.12],[1.71,0]],"id":55943164}],"con":true,"img":false}]}
{"op":"mcm","clk":"11450342022","pt":1717320768212,"mc":[{"id":"1.229554914","rc":[{"atb":[[1.87,6.57]],"id":70003369},{"atb":[[1.81,4.7]],"id":55943164}],"con":true,"img":false}]}
{"op":"mcm","clk":"11450342397","pt":1717320772925,"mc":[{"id":"1.229554914","rc":[{"atl":[[2.54,9.74]],"id":70003369}],"con":true,"img":false}]}
{"op":"mcm","clk":"11450343159","pt":1717320782126,"mc":[{"id":"1.229554914","rc":[{"atl":[[2.36,4.09],[2.24,4.31]],"id":70003369}],"con":true,"img":false}]}
{"op":"mcm","clk":"11450343231","pt":1717320782958,"mc":[{"id":"1.229554914","rc":[{"atl":[[2.24,0],[2.34,4.31]],"id":70003369}],"con":true,"img":false}]}
{"op":"mcm","clk":"11450343399","pt":1717320785038,"mc":[{"id":"1.229554914","rc":[{"atl":[[2.54,0],[2.6,0],[2.64,0]],"id":70003369}],"con":true,"img":false}]}
{"op":"mcm","clk":"11450343432","pt":1717320785451,"mc":[{"id":"1.229554914","rc":[{"atl":[[2.54,9.74],[2.66,41.37],[2.58,12.66],[2.62,15.43]],"id":70003369}],"con":true,"img":false}]}
{"op":"mcm","clk":"11450344284","pt":1717320796448,"mc":[{"id":"1.229554914","rc":[{"atb":[[1.5,0]],"id":55943164}],"con":true,"img":false}]}
{"op":"mcm","clk":"11450344976","pt":1717320805155,"mc":[{"id":"1.229554914","rc":[{"atl":[[2.54,0]],"id":70003369}],"con":true,"img":false}]}
{"op":"mcm","clk":"11450345162","pt":1717320807578,"mc":[{"id":"1.229554914","rc":[{"atl":[[2.4,4.23],[2.38,4.46]],"id":55943164}],"con":true,"img":false}]}
{"op":"mcm","clk":"11450345189","pt":1717320807890,"mc":[{"id":"1.229554914","rc":[{"atl":[[2.32,4.16]],"id":70003369}],"con":true,"img":false}]}
{"op":"mcm","clk":"11450345196","pt":1717320807941,"mc":[{"id":"1.229554914","rc":[{"atl":[[2.36,4.29]],"id":55943164}],"con":true,"img":false}]}
{"op":"mcm","clk":"11450345201","pt":1717320808046,"mc":[{"id":"1.229554914","rc":[{"atl":[[2.3,4.35],[2.34,0]],"id":70003369}],"con":true,"img":false}]}
{"op":"mcm","clk":"11450345377","pt":1717320810178,"mc":[{"id":"1.229554914","rc":[{"atl":[[2.44,9.26]],"id":55943164}],"con":true,"img":false}]}
{"op":"mcm","clk":"11450345385","pt":1717320810274,"mc":[{"id":"1.229554914","rc":[{"atl":[[2.46,0]],"id":55943164}],"con":true,"img":false}]}
{"op":"mcm","clk":"11450345571","pt":1717320812671,"mc":[{"id":"1.229554914","rc":[{"atl":[[2.38,0],[2.34,4.5]],"id":55943164}],"con":true,"img":false}]}
{"op":"mcm","clk":"11450345921","pt":1717320816959,"mc":[{"id":"1.229554914","rc":[{"atl":[[2.32,4.5]],"id":55943164}],"con":true,"img":false}]}
{"op":"mcm","clk":"11450345930","pt":1717320817065,"mc":[{"id":"1.229554914","rc":[{"atl":[[2.34,0]],"id":55943164}],"con":true,"img":false}]}
{"op":"mcm","clk":"11450346715","pt":1717320826891,"mc":[{"id":"1.229554914","rc":[{"atl":[[2.58,0]],"id":70003369},{"atl":[[2.42,9.26],[2.44,0]],"id":55943164}],"con":true,"img":false}]}
{"op":"mcm","clk":"11450346723","pt":1717320826996,"mc":[{"id":"1.229554914","rc":[{"atl":[[2.3,0],[2.32,8.51],[2.62,0]],"id":70003369},{"atb":[[1.77,0]],"id":55943164}],"con":true,"img":false}]}
{"op":"mcm","clk":"11450346733","pt":1717320827097,"mc":[{"id":"1.229554914","rc":[{"atl":[[2.32,4.16],[2.34,4.31]],"id":70003369},{"atb":[[1.73,4.5]],"id":55943164}],"con":true,"img":false}]}
{"op":"mcm","clk":"11450346740","pt":1717320827204,"mc":[{"id":"1.229554914","rc":[{"atl":[[2.32,8.51],[2.34,0]],"id":70003369}],"con":true,"img":false}]}
{"op":"mcm","clk":"11450346751","pt":1717320827308,"mc":[{"id":"1.229554914","rc":[{"atl":[[2.32,4.16],[2.34,4.31]],"id":70003369}],"con":true,"img":false}]}
{"op":"mcm","clk":"11450346762","pt":1717320827413,"mc":[{"id":"1.229554914","rc":[{"atl":[[2.32,8.51],[2.34,0]],"id":70003369}],"con":true,"img":false}]}
{"op":"mcm","clk":"11450348172","pt":1717320843285,"mc":[{"id":"1.229554914","rc":[{"atl":[[2.4,13.49],[2.32,0],[2.3,4.5],[2.42,0]],"id":55943164}],"con":true,"img":false}]}
{"op":"mcm","clk":"11450348258","pt":1717320844225,"mc":[{"id":"1.229554914","rc":[{"atl":[[2.66,18.07],[2.78,17.02]],"id":70003369}],"con":true,"img":false}]}
{"op":"mcm","clk":"11450348879","pt":1717320851033,"mc":[{"id":"1.229554914","rc":[{"atl":[[2.46,10.27]],"id":55943164}],"con":true,"img":false}]}
{"op":"mcm","clk":"11450349047","pt":1717320853005,"mc":[{"id":"1.229554914","rc":[{"atb":[[1.44,0],[1.45,0]],"id":55943164},{"atl":[[2.46,0],[2.48,10.14]],"id":55943164}],"con":true,"img":false}]}
{"op":"mcm","clk":"11450349058","pt":1717320853106,"mc":[{"id":"1.229554914","rc":[{"atb":[[1.44,0],[1.45,0]],"id":70003369}],"con":true,"img":false}]}
{"op":"mcm","clk":"11450349083","pt":1717320853419,"mc":[{"id":"1.229554914","rc":[{"atl":[[2.62,0],[2.48,0]],"id":55943164}],"con":true,"img":false}]}
{"op":"mcm","clk":"11450349130","pt":1717320853891,"mc":[{"id":"1.229554914","rc":[{"atl":[[2.28,4.5]],"id":55943164}],"con":true,"img":false}]}
{"op":"mcm","clk":"11450349140","pt":1717320853995,"mc":[{"id":"1.229554914","rc":[{"atl":[[2.3,0]],"id":55943164}],"con":true,"img":false}]}
{"op":"mcm","clk":"11450349184","pt":1717320854511,"mc":[{"id":"1.229554914","rc":[{"atl":[[2.32,4.16],[2.34,4.35]],"id":70003369},{"atl":[[2.46,10.27]],"id":55943164}],"con":true,"img":false}]}
{"op":"mcm","clk":"11450349418","pt":1717320856907,"mc":[{"id":"1.229554914","rc":[{"atl":[[2.46,0],[2.48,10.14]],"id":55943164}],"con":true,"img":false}]}
{"op":"mcm","clk":"11450349630","pt":1717320859352,"mc":[{"id":"1.229554914","rc":[{"atl":[[2.3,4.5],[2.28,0]],"id":55943164}],"con":true,"img":false}]}
{"op":"mcm","clk":"11450349655","pt":1717320859613,"mc":[{"id":"1.229554914","rc":[{"atl":[[2.32,8.51],[2.34,0]],"id":70003369},{"atl":[[2.4,4.23],[2.42,10.14]],"id":55943164}],"con":true,"img":false}]}
{"op":"mcm","clk":"11450349749","pt":1717320860704,"mc":[{"id":"1.229554914","rc":[{"atl":[[2.4,14.37],[2.42,0]],"id":55943164}],"con":true,"img":false}]}
{"op":"mcm","clk":"11450349757","pt":1717320860807,"mc":[{"id":"1.229554914","rc":[{"atl":[[2.5,10],[2.48,0]],"id":55943164}],"con":true,"img":false}]}
{"op":"mcm","clk":"11450349769","pt":1717320861013,"mc":[{"id":"1.229554914","rc":[{"atl":[[2.5,0],[2.48,10.14]],"id":55943164}],"con":true,"img":false}]}
{"op":"mcm","clk":"11450350075","pt":1717320864910,"mc":[{"id":"1.229554914","rc":[{"atl":[[2.3,0],[2.28,4.5],[2.48,0]],"id":55943164}],"con":true,"img":false}]}
{"op":"mcm","clk":"11450350134","pt":1717320865524,"mc":[{"id":"1.229554914","rc":[{"atl":[[2.28,0],[2.26,4.5]],"id":55943164}],"con":true,"img":false}]}
{"op":"mcm","clk":"11450351204","pt":1717320877619,"mc":[{"id":"1.229554914","rc":[{"atb":[[1.43,0],[1.42,0]],"id":70003369},{"atb":[[1.42,0]],"id":55943164}],"con":true,"img":false}]}
{"op":"mcm","clk":"11450351209","pt":1717320877716,"mc":[{"id":"1.229554914","rc":[{"atl":[[2.64,0],[2.68,0]],"id":55943164}],"con":true,"img":false}]}
{"op":"mcm","clk":"11450351696","pt":1717320883350,"mc":[{"id":"1.229554914","rc":[{"atl":[[2.32,4.16],[2.34,4.35]],"id":70003369},{"atl":[[2.4,4.23],[2.38,8.79]],"id":55943164}],"con":true,"img":false}]}
{"op":"mcm","clk":"11450351979","pt":1717320886524,"mc":[{"id":"1.229554914","rc":[{"atb":[[1.64,0],[1.69,18.24]],"id":70003369}],"con":true,"img":false}]}
{"op":"mcm","clk":"11450353131","pt":1717320901066,"mc":[{"id":"1.229554914","rc":[{"atl":[[2.24,4.5],[2.26,0]],"id":55943164}],"con":true,"img":false}]}
{"op":"mcm","clk":"11450353421","pt":1717320904237,"mc":[{"id":"1.229554914","rc":[{"atl":[[2.24,0],[2.32,4.5]],"id":55943164}],"con":true,"img":false}]}
{"op":"mcm","clk":"11450353430","pt":1717320904343,"mc":[{"id":"1.229554914","rc":[{"atl":[[2.24,4.6]],"id":55943164}],"con":true,"img":false}]}
{"op":"mcm","clk":"11450353439","pt":1717320904445,"mc":[{"id":"1.229554914","rc":[{"atl":[[2.32,0]],"id":55943164}],"con":true,"img":false}]}
{"op":"mcm","clk":"11450353500","pt":1717320905165,"mc":[{"id":"1.229554914","rc":[{"atb":[[1.74,18.24],[1.69,0]],"id":70003369},{"atl":[[2.9,8.7],[2.46,4.35],[2.66,0],[2.78,0],[2.34,0]],"id":70003369},{"atb":[[1.73,0],[1.45,17.77],[1.55,0],[1.65,4.5]],"id":55943164},{"atl":[[2.38,0],[2.34,9.2]],"id":55943164}],"con":true,"img":false}]}
{"op":"mcm","clk":"11450354594","pt":1717320918187,"mc":[{"id":"1.229554914","rc":[{"atl":[[2.24,0],[2.22,4.5]],"id":55943164}],"con":true,"img":false}]}
{"op":"mcm","clk":"11450354611","pt":1717320918347,"mc":[{"id":"1.229554914","rc":[{"atl":[[2.2,4.36]],"id":55943164}],"con":true,"img":false}]}
{"op":"mcm","clk":"11450354619","pt":1717320918453,"mc":[{"id":"1.229554914","rc":[{"atl":[[2.3,8.87]],"id":55943164}],"con":true,"img":false}]}
{"op":"mcm","clk":"11450354625","pt":1717320918553,"mc":[{"id":"1.229554914","rc":[{"atl":[[2.34,0]],"id":55943164}],"con":true,"img":false}]}
{"op":"mcm","clk":"11450354995","pt":1717320923253,"mc":[{"id":"1.229554914","rc":[{"atl":[[2.22,0],[2.18,4.54]],"id":55943164}],"con":true,"img":false}]}
{"op":"mcm","clk":"11450355615","pt":1717320930698,"mc":[{"id":"1.229554914","rc":[{"atl":[[2.3,0],[2.28,8.91]],"id":55943164}],"con":true,"img":false}]}
{"op":"mcm","clk":"11450356160","pt":1717320937182,"mc":[{"id":"1.229554914","rc":[{"atl":[[2.46,0],[2.44,4.35]],"id":70003369},{"atl":[[2.3,9.08],[2.28,0]],"id":55943164}],"con":true,"img":false}]}
{"op":"mcm","clk":"11450356559","pt":1717320942307,"mc":[{"id":"1.229554914","rc":[{"atl":[[2.42,4.35]],"id":70003369}],"con":true,"img":false}]}
{"op":"mcm","clk":"11450356566","pt":1717320942413,"mc":[{"id":"1.229554914","rc":[{"atl":[[2.44,0]],"id":70003369}],"con":true,"img":false}]}
{"op":"mcm","clk":"11450356891","pt":1717320946315,"mc":[{"id":"1.229554914","rc":[{"atb":[[1.86,0],[1.76,0]],"id":70003369},{"atb":[[1.8,0],[1.9,0]],"id":55943164}],"con":true,"img":false}]}
{"op":"mcm","clk":"11450357147","pt":1717320949602,"mc":[{"id":"1.229554914","rc":[{"atl":[[2.18,0],[2.16,2.18]],"id":55943164}],"con":true,"img":false}]}
{"op":"mcm","clk":"11450357177","pt":1717320950017,"mc":[{"id":"1.229554914","rc":[{"atl":[[2.14,4.5]],"id":55943164}],"con":true,"img":false}]}
{"op":"mcm","clk":"11450357184","pt":1717320950112,"mc":[{"id":"1.229554914","rc":[{"atl":[[2.12,4.44],[2.16,0]],"id":55943164}],"con":true,"img":false}]}
{"op":"mcm","clk":"11450357318","pt":1717320951827,"mc":[{"id":"1.229554914","rc":[{"atl":[[2.42,0],[2.44,4.12]],"id":70003369}],"con":true,"img":false}]}
{"op":"mcm","clk":"11450357746","pt":1717320957215,"mc":[{"id":"1.229554914","rc":[{"atb":[[1.8,13.14]],"id":70003369},{"atl":[[2.5,4.12]],"id":70003369}],"con":true,"img":false}]}
{"op":"mcm","clk":"11450357752","pt":1717320957320,"mc":[{"id":"1.229554914","rc":[{"atb":[[1.74,0]],"id":70003369},{"atl":[[2.44,0]],"id":70003369},{"atl":[[2.24,8.88],[2.3,0]],"id":55943164}],"con":true,"img":false}]}
{"op":"mcm","clk":"11450357814","pt":1717320958107,"mc":[{"id":"1.229554914","rc":[{"atb":[[1.86,9.12],[1.76,10.32]],"id":70003369},{"atb":[[1.8,9.8],[1.9,8.72]],"id":55943164}],"con":true,"img":false}]}
{"op":"mcm","clk":"11450357962","pt":1717320960031,"mc":[{"id":"1.229554914","rc":[{"atb":[[1.91,4.12]],"id":70003369},{"atb":[[1.81,0]],"id":55943164},{"atl":[[2.06,4.6]],"id":55943164}],"con":true,"img":false}]}
{"op":"mcm","clk":"11450357970","pt":1717320960135,"mc":[{"id":"1.229554914","rc":[{"atb":[[1.87,4.53]],"id":70003369},{"atl":[[2.12,0]],"id":55943164}],"con":true,"img":false}]}
{"op":"mcm","clk":"11450358168","pt":1717320962330,"mc":[{"id":"1.229554914","rc":[{"atl":[[2.5,0]],"id":70003369},{"atb":[[1.65,0]],"id":55943164}],"con":true,"img":false}]}
{"op":"mcm","clk":"11450358184","pt":1717320962435,"mc":[{"id":"1.229554914","rc":[{"atl":[[2.54,4.12]],"id":70003369},{"atb":[[1.62,4.62]],"id":55943164}],"con":true,"img":false}]}
{"op":"mcm","clk":"11450358194","pt":1717320962542,"mc":[{"id":"1.229554914","rc":[{"atb":[[1.8,0],[1.74,18.24]],"id":70003369},{"atl":[[2.24,0],[2.32,9.1]],"id":55943164}],"con":true,"img":false}]}
{"op":"mcm","clk":"11450358393","pt":1717320965102,"mc":[{"id":"1.229554914","rc":[{"atb":[[1.91,0],[1.9,4.12]],"id":70003369},{"atl":[[2.06,0],[2.08,4.62]],"id":55943164}],"con":true,"img":false}]}
{"op":"mcm","clk":"11450358596","pt":1717320967529,"mc":[{"id":"1.229554914","rc":[{"atl":[[2.4,4.12]],"id":70003369},{"atb":[[1.69,4.62]],"id":55943164}],"con":true,"img":false}]}
{"op":"mcm","clk":"11450358601","pt":1717320967634,"mc":[{"id":"1.229554914","rc":[{"atl":[[2.54,0]],"id":70003369},{"atb":[[1.62,0]],"id":55943164}],"con":true,"img":false}]}
{"op":"mcm","clk":"11450359468","pt":1717320978658,"mc":[{"id":"1.229554914","rc":[{"atb":[[1.79,10.33],[1.74,0],[1.9,0],[1.91,4.12]],"id":70003369},{"atl":[[2.4,0],[2.46,4.12]],"id":70003369},{"atb":[[1.69,0]],"id":55943164},{"atl":[[2.32,0],[2.06,4.62],[2.26,9],[2.08,0]],"id":55943164}],"con":true,"img":false}]}
{"op":"mcm","clk":"11450359473","pt":1717320978755,"mc":[{"id":"1.229554914","rc":[{"atb":[[1.66,4.62]],"id":55943164}],"con":true,"img":false}]}
{"op":"mcm","clk":"11450359500","pt":1717320979122,"mc":[{"id":"1.229554914","rc":[{"atb":[[1.92,4.03]],"id":70003369},{"atl":[[2.4,0],[2.04,4.79]],"id":55943164}],"con":true,"img":false}]}
{"op":"mcm","clk":"11450359863","pt":1717320983752,"mc":[{"id":"1.229554914","rc":[{"atb":[[1.91,0],[1.95,4.06]],"id":70003369},{"atl":[[2.06,0],[2.04,9.56]],"id":55943164}],"con":true,"img":false}]}
{"op":"mcm","clk":"11450359912","pt":1717320984315,"mc":[{"id":"1.229554914","rc":[{"atb":[[1.87,38.81]],"id":70003369}],"con":true,"img":false}]}
{"op":"mcm","clk":"11450360367","pt":1717320990171,"mc":[{"id":"1.229554914","rc":[{"atb":[[1.82,13.18],[1.79,0],[1.86,0],[1.76,0]],"id":70003369},{"atb":[[1.8,0],[1.9,0]],"id":55943164}],"con":true,"img":false}]}
{"op":"mcm","clk":"11450360382","pt":1717320990330,"mc":[{"id":"1.229554914","rc":[{"atb":[[1.87,4.53]],"id":70003369}],"con":true,"img":false}]}
{"op":"mcm","clk":"11450362078","pt":1717321011721,"mc":[{"id":"1.229554914","rc":[{"atb":[[1.83,9.45],[1.93,8.43]],"id":70003369},{"atb":[[1.8,9.8],[1.7,15.95]],"id":55943164}],"con":true,"img":false}]}
{"op":"mcm","clk":"11450362093","pt":1717321011886,"mc":[{"id":"1.229554914","rc":[{"atb":[[1.71,5.08]],"id":55943164}],"con":true,"img":false}]}
{"op":"mcm","clk":"11450362131","pt":1717321012296,"mc":[{"id":"1.229554914","rc":[{"atb":[[1.88,33.89]],"id":70003369}],"con":true,"img":false}]}
{"op":"mcm","clk":"11450362651","pt":1717321018706,"mc":[{"id":"1.229554914","rc":[{"atl":[[2.32,0]],"id":70003369}],"con":true,"img":false}]}
{"op":"mcm","clk":"11450362776","pt":1717321020583,"mc":[{"id":"1.229554914","rc":[{"atb":[[1.94,2.02],[1.95,0]],"id":70003369}],"con":true,"img":false}]}
{"op":"mcm","clk":"11450362781","pt":1717321020740,"mc":[{"id":"1.229554914","rc":[{"atb":[[1.82,0],[1.84,9.45]],"id":70003369}],"con":true,"img":false}]}
{"op":"mcm","clk":"11450363078","pt":1717321024347,"mc":[{"id":"1.229554914","rc":[{"atb":[[1.84,0],[1.86,9.45]],"id":70003369},{"atl":[[3.2,8.24],[2.9,0],[2.74,2.02],[2.46,0]],"id":70003369},{"atb":[[1.45,0],[1.54,4.94],[1.66,0],[1.38,19.62]],"id":55943164},{"atl":[[2.04,14.06],[2.26,0]],"id":55943164}],"con":true,"img":false}]}
{"op":"mcm","clk":"11450363121","pt":1717321024819,"mc":[{"id":"1.229554914","rc":[{"atb":[[1.88,0]],"id":70003369}],"con":true,"img":false}]}
{"op":"mcm","clk":"11450363205","pt":1717321025904,"mc":[{"id":"1.229554914","rc":[{"atb":[[1.86,0],[1.93,12.96]],"id":70003369}],"con":true,"img":false}]}
{"op":"mcm","clk":"11450363236","pt":1717321026336,"mc":[{"id":"1.229554914","rc":[{"atb":[[1.93,45.03]],"id":70003369}],"con":true,"img":false}]}
{"op":"mcm","clk":"11450363377","pt":1717321028029,"mc":[{"id":"1.229554914","rc":[{"atb":[[1.92,51.09],[1.93,40.5]],"id":70003369}],"con":true,"img":false}]}
{"op":"mcm","clk":"11450363396","pt":1717321028341,"mc":[{"id":"1.229554914","rc":[{"atl":[[2.74,0]],"id":70003369},{"atb":[[1.54,0]],"id":55943164}],"con":true,"img":false}]}
{"op":"mcm","clk":"11450363406","pt":1717321028444,"mc":[{"id":"1.229554914","rc":[{"atl":[[2.82,2.02]],"id":70003369},{"atb":[[1.52,4.94]],"id":55943164}],"con":true,"img":false}]}
{"op":"mcm","clk":"11450363543","pt":1717321030213,"mc":[{"id":"1.229554914","rc":[{"atb":[[1.92,4.03],[1.86,45.04]],"id":70003369}],"con":true,"img":false}]}
{"op":"mcm","clk":"11450363589","pt":1717321030834,"mc":[{"id":"1.229554914","rc":[{"atb":[[1.93,8.43]],"id":70003369}],"con":true,"img":false}]}
{"op":"mcm","clk":"11450363973","pt":1717321035345,"mc":[{"id":"1.229554914","rc":[{"atb":[[1.86,0],[1.94,6.06]],"id":70003369}],"con":true,"img":false}]}
{"op":"mcm","clk":"11450364019","pt":1717321035815,"mc":[{"id":"1.229554914","rc":[{"atb":[[1.93,40.5]],"id":70003369}],"con":true,"img":false}]}
{"op":"mcm","clk":"11450365165","pt":1717321050627,"mc":[{"id":"1.229554914","rc":[{"atl":[[1000,0.89]],"id":55943164}],"con":true,"img":false}]}
{"op":"mcm","clk":"11450365190","pt":1717321051043,"mc":[{"id":"1.229554914","rc":[{"atl":[[1000,0.14]],"id":55943164}],"con":true,"img":false}]}
{"op":"mcm","clk":"11450365211","pt":1717321051355,"mc":[{"id":"1.229554914","rc":[{"atl":[[1000,0]],"id":55943164}],"con":true,"img":false}]}
{"op":"mcm","clk":"11450365215","pt":1717321051458,"mc":[{"id":"1.229554914","rc":[{"atb":[[1.8,9.65]],"id":55943164},{"trd":[[1.8,0.3]],"ltp":1.8,"tv":0.3,"id":55943164}],"con":true,"img":false}]}
{"op":"mcm","clk":"11450365266","pt":1717321052230,"mc":[{"id":"1.229554914","rc":[{"atb":[[1.95,3.81]],"id":70003369},{"atl":[[2.36,0],[2.02,5.12]],"id":55943164}],"con":true,"img":false}]}
{"op":"mcm","clk":"11450365276","pt":1717321052337,"mc":[{"id":"1.229554914","rc":[{"atb":[[1.96,6.06],[1.94,2.02]],"id":70003369},{"atl":[[2,5.12],[2.02,10.22],[2.04,4.79]],"id":55943164}],"con":true,"img":false}]}
{"op":"mcm","clk":"11450365284","pt":1717321052453,"mc":[{"id":"1.229554914","rc":[{"atl":[[2,0],[2.02,15.34]],"id":55943164}],"con":true,"img":false}]}
{"op":"mcm","clk":"11450365319","pt":1717321052849,"mc":[{"id":"1.229554914","rc":[{"atb":[[1.95,35.2],[1.93,8.43]],"id":70003369}],"con":true,"img":false}]}
{"op":"mcm","clk":"11450365380","pt":1717321053522,"mc":[{"id":"1.229554914","rc":[{"trd":[[2.26,4.3]],"ltp":2.26,"tv":4.3,"id":70003369},{"atb":[[1.8,4.25]],"id":55943164},{"trd":[[1.8,5.7]],"ltp":1.8,"tv":5.7,"id":55943164}],"con":true,"img":false}]}
{"op":"mcm","clk":"11450365389","pt":1717321053625,"mc":[{"id":"1.229554914","rc":[{"atb":[[1.99,17.4]],"id":70003369},{"atl":[[2,19]],"id":55943164}],"con":true,"img":false}]}
{"op":"mcm","clk":"11450365396","pt":1717321053726,"mc":[{"id":"1.229554914","rc":[{"atl":[[1.99,15.34],[2.02,10.22]],"id":55943164}],"con":true,"img":false}]}
{"op":"mcm","clk":"11450365483","pt":1717321054961,"mc":[{"id":"1.229554914","rc":[{"atb":[[1.02,3.47]],"id":70003369},{"atb":[[1.02,3.63]],"id":55943164}],"con":true,"img":false}]}
{"op":"mcm","clk":"11450365550","pt":1717321055943,"mc":[{"id":"1.229554914","rc":[{"atb":[[1.02,0.86]],"id":70003369}],"con":true,"img":false}]}
{"op":"mcm","clk":"11450365557","pt":1717321056047,"mc":[{"id":"1.229554914","rc":[{"atb":[[1.02,1.02]],"id":55943164}],"con":true,"img":false}]}
{"op":"mcm","clk":"11450365588","pt":1717321056463,"mc":[{"id":"1.229554914","rc":[{"atb":[[1.83,0],[1.93,0]],"id":70003369},{"atb":[[1.8,0],[1.7,4.73]],"id":55943164}],"con":true,"img":false}]}
{"op":"mcm","clk":"11450365623","pt":1717321056880,"mc":[{"id":"1.229554914","rc":[{"atb":[[2.02,17.12],[1.95,3.81]],"id":70003369},{"atl":[[2.42,17.32]],"id":70003369},{"atl":[[1.98,19.69]],"id":55943164}],"con":true,"img":false}]}
{"op":"mcm","clk":"11450365637","pt":1717321057088,"mc":[{"id":"1.229554914","rc":[{"atb":[[1.02,0]],"id":70003369},{"atl":[[1.99,0],[1.97,19]],"id":55943164}],"con":true,"img":false}]}
{"op":"mcm","clk":"11450365641","pt":1717321057140,"mc":[{"id":"1.229554914","rc":[{"atb":[[2.06,0.86]],"id":70003369},{"atb":[[1.02,0]],"id":55943164}],"con":true,"img":false}]}
{"op":"mcm","clk":"11450365652","pt":1717321057246,"mc":[{"id":"1.229554914","rc":[{"atb":[[1.9,1.02]],"id":55943164}],"con":true,"img":false}]}
{"op":"mcm","clk":"11450365659","pt":1717321057352,"mc":[{"id":"1.229554914","rc":[{"atb":[[1.9,0]],"id":55943164},{"trd":[[1.9,2.04]],"ltp":1.9,"tv":2.04,"id":55943164}],"con":true,"img":false}]}
{"op":"mcm","clk":"11450365678","pt":1717321057662,"mc":[{"id":"1.229554914","rc":[{"atl":[[2,0]],"id":55943164}],"con":true,"img":false}]}
{"op":"mcm","clk":"11450365832","pt":1717321059937,"mc":[{"id":"1.229554914","rc":[{"atl":[[1.96,19.71]],"id":55943164}],"con":true,"img":false}]}
{"op":"mcm","clk":"11450365846","pt":1717321060144,"mc":[{"id":"1.229554914","rc":[{"atl":[[1.96,0]],"id":55943164}],"con":true,"img":false}]}
{"op":"mcm","clk":"11450366098","pt":1717321063156,"mc":[{"id":"1.229554914","rc":[{"atl":[[1.96,19.71]],"id":55943164}],"con":true,"img":false}]}
{"op":"mcm","clk":"11450366104","pt":1717321063261,"mc":[{"id":"1.229554914","rc":[{"atl":[[1.97,0],[1.96,39.4]],"id":55943164}],"con":true,"img":false}]}
{"op":"mcm","clk":"11450366109","pt":1717321063365,"mc":[{"id":"1.229554914","rc":[{"atb":[[2.04,28.67]],"id":70003369},{"atl":[[1.98,0]],"id":55943164}],"con":true,"img":false}]}
{"op":"mcm","clk":"11450366254","pt":1717321065387,"mc":[{"id":"1.229554914","rc":[{"atb":[[1.84,12.64],[1.94,13.32]],"id":70003369},{"atb":[[1.78,7.21],[1.68,8.27]],"id":55943164}],"con":true,"img":false}]}
{"op":"mcm","clk":"11450366296","pt":1717321065857,"mc":[{"id":"1.229554914","rc":[{"atb":[[1.71,47.09]],"id":55943164}],"con":true,"img":false}]}
{"op":"mcm","clk":"11450366359","pt":1717321066677,"mc":[{"id":"1.229554914","rc":[{"atb":[[2.06,14.57]],"id":70003369}],"con":true,"img":false}]}
{"op":"mcm","clk":"11450366365","pt":1717321066730,"mc":[{"id":"1.229554914","rc":[{"atb":[[2.06,0.86]],"id":70003369}],"con":true,"img":false}]}
{"op":"mcm","clk":"11450366552","pt":1717321069779,"mc":[{"id":"1.229554914","rc":[{"atb":[[2.06,14.57]],"id":70003369}],"con":true,"img":false}]}
{"op":"mcm","clk":"11450366600","pt":1717321070662,"mc":[{"id":"1.229554914","rc":[{"atb":[[1.99,0]],"id":70003369}],"con":true,"img":false}]}
{"op":"mcm","clk":"11450366645","pt":1717321071489,"mc":[{"id":"1.229554914","rc":[{"atb":[[1.72,5.14]],"id":55943164}],"con":true,"img":false}]}
{"op":"mcm","clk":"11450366701","pt":1717321072265,"mc":[{"id":"1.229554914","rc":[{"atb":[[1.68,0]],"id":70003369},{"atl":[[2.2,0],[1.95,5.1]],"id":55943164}],"con":true,"img":false}]}
{"op":"mcm","clk":"11450366706","pt":1717321072370,"mc":[{"id":"1.229554914","rc":[{"atb":[[2.08,3.82]],"id":70003369}],"con":true,"img":false}]}
{"op":"mcm","clk":"11450366711","pt":1717321072469,"mc":[{"id":"1.229554914","rc":[{"atl":[[1.96,19.71],[1.95,15.32]],"id":55943164}],"con":true,"img":false}]}
{"op":"mcm","clk":"11450366747","pt":1717321072992,"mc":[{"id":"1.229554914","rc":[{"atb":[[2.1,13.45]],"id":70003369},{"atl":[[1.94,5.11],[2.14,0]],"id":55943164}],"con":true,"img":false}]}
{"op":"mcm","clk":"11450366764","pt":1717321073193,"mc":[{"id":"1.229554914","rc":[{"atb":[[2.12,3.81],[1.87,0],[2.02,0]],"id":70003369}],"con":true,"img":false}]}
{"op":"mcm","clk":"11450366811","pt":1717321073868,"mc":[{"id":"1.229554914","rc":[{"atl":[[2.42,0]],"id":70003369}],"con":true,"img":false}]}
{"op":"mcm","clk":"11450366842","pt":1717321074383,"mc":[{"id":"1.229554914","rc":[{"atb":[[2.08,31.44]],"id":70003369},{"atb":[[1.71,5.08]],"id":55943164}],"con":true,"img":false}]}
{"op":"mcm","clk":"11450366858","pt":1717321074692,"mc":[{"id":"1.229554914","rc":[{"atl":[[2,5.12],[2.02,5.12],[1.95,5.1],[1.93,15.32]],"id":55943164}],"con":true,"img":false}]}
{"op":"mcm","clk":"11450366872","pt":1717321074899,"mc":[{"id":"1.229554914","rc":[{"atb":[[2.08,3.82]],"id":70003369}],"con":true,"img":false}]}
{"op":"mcm","clk":"11450366895","pt":1717321075261,"mc":[{"id":"1.229554914","rc":[{"atl":[[1.92,5.15],[2.04,0]],"id":55943164}],"con":true,"img":false}]}
{"op":"mcm","clk":"11450367064","pt":1717321078059,"mc":[{"id":"1.229554914","rc":[{"atb":[[2.06,13.71]],"id":70003369}],"con":true,"img":false}]}
{"op":"mcm","clk":"11450367069","pt":1717321078160,"mc":[{"id":"1.229554914","rc":[{"atb":[[2.1,14.31]],"id":70003369}],"con":true,"img":false}]}
{"op":"mcm","clk":"11450367164","pt":1717321079773,"mc":[{"id":"1.229554914","rc":[{"atl":[[1.94,25.59],[1.93,0]],"id":55943164}],"con":true,"img":false}]}
{"op":"mcm","clk":"11450367421","pt":1717321083098,"mc":[{"id":"1.229554914","rc":[{"atb":[[1.84,0],[1.94,2.02]],"id":70003369},{"atb":[[1.78,0],[1.68,0]],"id":55943164}],"con":true,"img":false}]}
{"op":"mcm","clk":"11450367441","pt":1717321083405,"mc":[{"id":"1.229554914","rc":[{"atb":[[2.04,0]],"id":70003369}],"con":true,"img":false}]}
{"op":"mcm","clk":"11450367562","pt":1717321084999,"mc":[{"id":"1.229554914","rc":[{"atl":[[1.94,5.11],[1.93,19.71]],"id":55943164}],"con":true,"img":false}]}
{"op":"mcm","clk":"11450367568","pt":1717321085106,"mc":[{"id":"1.229554914","rc":[{"atl":[[1.94,29.98],[1.93,0]],"id":55943164}],"con":true,"img":false}]}
{"op":"mcm","clk":"11450367853","pt":1717321089489,"mc":[{"id":"1.229554914","rc":[{"atb":[[2.14,7.93]],"id":70003369}],"con":true,"img":false}]}
{"op":"mcm","clk":"11450367986","pt":1717321091479,"mc":[{"id":"1.229554914","rc":[{"atl":[[1.94,5.11],[1.93,19.71]],"id":55943164}],"con":true,"img":false}]}
{"op":"mcm","clk":"11450368002","pt":1717321091791,"mc":[{"id":"1.229554914","rc":[{"atb":[[1.92,0],[2.16,3.77]],"id":70003369}],"con":true,"img":false}]}
{"op":"mcm","clk":"11450368042","pt":1717321092312,"mc":[{"id":"1.229554914","rc":[{"atb":[[1.99,3.8],[1.94,0]],"id":70003369},{"atl":[[2,0],[1.96,24.81]],"id":55943164}],"con":true,"img":false}]}
{"op":"mcm","clk":"11450368056","pt":1717321092513,"mc":[{"id":"1.229554914","rc":[{"atl":[[1.97,5.1],[1.96,19.71]],"id":55943164}],"con":true,"img":false}]}
{"op":"mcm","clk":"11450368078","pt":1717321092777,"mc":[{"id":"1.229554914","rc":[{"atb":[[2.18,7.79]],"id":70003369}],"con":true,"img":false}]}
{"op":"mcm","clk":"11450368082","pt":1717321092881,"mc":[{"id":"1.229554914","rc":[{"atl":[[50,2.61]],"id":55943164}],"con":true,"img":false}]}
{"op":"mcm","clk":"11450368111","pt":1717321093296,"mc":[{"id":"1.229554914","rc":[{"atb":[[2.06,0]],"id":70003369}],"con":true,"img":false}]}
{"op":"mcm","clk":"11450368117","pt":1717321093397,"mc":[{"id":"1.229554914","rc":[{"atb":[[2.1,13.45]],"id":70003369}],"con":true,"img":false}]}
{"op":"mcm","clk":"11450368127","pt":1717321093497,"mc":[{"id":"1.229554914","rc":[{"atb":[[2.16,4.64]],"id":70003369}],"con":true,"img":false}]}
{"op":"mcm","clk":"11450368146","pt":1717321093723,"mc":[{"id":"1.229554914","rc":[{"atb":[[2.2,3.76]],"id":70003369},{"atl":[[2.36,0]],"id":70003369}],"con":true,"img":false}]}
{"op":"mcm","clk":"11450368153","pt":1717321093810,"mc":[{"id":"1.229554914","rc":[{"atb":[[1.95,0]],"id":70003369}],"con":true,"img":false}]}
{"op":"mcm","clk":"11450368162","pt":1717321093917,"mc":[{"id":"1.229554914","rc":[{"atl":[[2.82,0],[3.2,0],[2.88,2],[7.4,10.26]],"id":70003369}],"con":true,"img":false}]}
{"op":"mcm","clk":"11450368173","pt":1717321094017,"mc":[{"id":"1.229554914","rc":[{"atb":[[2.1,0]],"id":70003369},{"atl":[[7.4,0],[3.35,10.26]],"id":70003369}],"con":true,"img":false}]}
{"op":"mcm","clk":"11450368206","pt":1717321094383,"mc":[{"id":"1.229554914","rc":[{"atb":[[2.12,30.44]],"id":70003369},{"atl":[[3.45,10.2],[2.88,0],[3.35,18.77],[2.84,2],[3.25,6.67],[3.55,11.76]],"id":70003369}],"con":true,"img":false}]}
{"op":"mcm","clk":"11450368251","pt":1717321095003,"mc":[{"id":"1.229554914","rc":[{"atl":[[3.35,16.64],[2.84,0],[3.25,0]],"id":70003369},{"atb":[[1.52,0]],"id":55943164}],"con":true,"img":false}]}
{"op":"mcm","clk":"11450368261","pt":1717321095116,"mc":[{"id":"1.229554914","rc":[{"atl":[[2.92,2]],"id":70003369},{"atb":[[1.49,5.1]],"id":55943164}],"con":true,"img":false}]}
{"op":"mcm","clk":"11450368317","pt":1717321095778,"mc":[{"id":"1.229554914","rc":[{"atl":[[2.92,5.74]],"id":70003369}],"con":true,"img":false}]}
{"op":"mcm","clk":"11450368328","pt":1717321095989,"mc":[{"id":"1.229554914","rc":[{"atl":[[3.45,8.16]],"id":70003369}],"con":true,"img":false}]}
{"op":"mcm","clk":"11450368340","pt":1717321096187,"mc":[{"id":"1.229554914","rc":[{"atb":[[2.22,6.76]],"id":70003369}],"con":true,"img":false}]}
{"op":"mcm","clk":"11450368350","pt":1717321096391,"mc":[{"id":"1.229554914","rc":[{"atb":[[2.14,34.09]],"id":70003369}],"con":true,"img":false}]}
{"op":"mcm","clk":"11450368366","pt":1717321096605,"mc":[{"id":"1.229554914","rc":[{"atl":[[1.91,5.16],[1.93,0]],"id":55943164}],"con":true,"img":false}]}
{"op":"mcm","clk":"11450368433","pt":1717321097583,"mc":[{"id":"1.229554914","rc":[{"atl":[[2.02,0],[1.9,5.1]],"id":55943164}],"con":true,"img":false}]}
{"op":"mcm","clk":"11450368437","pt":1717321097685,"mc":[{"id":"1.229554914","rc":[{"atl":[[1.89,5.16],[1.91,0]],"id":55943164}],"con":true,"img":false}]}
{"op":"mcm","clk":"11450368487","pt":1717321098609,"mc":[{"id":"1.229554914","rc":[{"atl":[[50,2.87]],"id":55943164}],"con":true,"img":false}]}
{"op":"mcm","clk":"11450368503","pt":1717321098819,"mc":[{"id":"1.229554914","rc":[{"atb":[[1.84,12.64],[1.94,11.3]],"id":70003369},{"atb":[[1.78,7.21],[1.68,8.27]],"id":55943164}],"con":true,"img":false}]}
{"op":"mcm","clk":"11450368561","pt":1717321099497,"mc":[{"id":"1.229554914","rc":[{"atl":[[2.94,3.75]],"id":70003369}],"con":true,"img":false}]}
{"op":"mcm","clk":"11450368569","pt":1717321099599,"mc":[{"id":"1.229554914","rc":[{"atl":[[2.92,3.74]],"id":70003369}],"con":true,"img":false}]}
{"op":"mcm","clk":"11450368768","pt":1717321102489,"mc":[{"id":"1.229554914","rc":[{"atb":[[2.2,0]],"id":70003369}],"con":true,"img":false}]}
{"op":"mcm","clk":"11450368780","pt":1717321102695,"mc":[{"id":"1.229554914","rc":[{"atl":[[1.84,15.95]],"id":55943164}],"con":true,"img":false}]}
{"op":"mcm","clk":"11450368787","pt":1717321102806,"mc":[{"id":"1.229554914","rc":[{"atb":[[2.22,0]],"id":70003369},{"atl":[[1.89,0],[1.88,36.94],[1.95,0]],"id":55943164}],"con":true,"img":false}]}
{"op":"mcm","clk":"11450368800","pt":1717321102903,"mc":[{"id":"1.229554914","rc":[{"atb":[[2.18,11.65]],"id":70003369}],"con":true,"img":false}]}
{"op":"mcm","clk":"11450368840","pt":1717321103420,"mc":[{"id":"1.229554914","rc":[{"atb":[[2.12,3.81],[2.14,7.93]],"id":70003369}],"con":true,"img":false}]}
{"op":"mcm","clk":"11450368876","pt":1717321103892,"mc":[{"id":"1.229554914","rc":[{"atb":[[2.1,27.11]],"id":70003369}],"con":true,"img":false}]}
{"op":"mcm","clk":"11450368894","pt":1717321104303,"mc":[{"id":"1.229554914","rc":[{"atl":[[1.94,0],[1.87,5.05]],"id":55943164}],"con":true,"img":false}]}
{"op":"mcm","clk":"11450368905","pt":1717321104512,"mc":[{"id":"1.229554914","rc":[{"atl":[[3.35,10.26]],"id":70003369},{"atl":[[1.96,0],[1.86,16.88]],"id":55943164}],"con":true,"img":false}]}
{"op":"mcm","clk":"11450368909","pt":1717321104613,"mc":[{"id":"1.229554914","rc":[{"atl":[[2.98,4.19],[2.94,0]],"id":70003369},{"atb":[[1.38,0]],"id":55943164}],"con":true,"img":false}]}
{"op":"mcm","clk":"11450368915","pt":1717321104717,"mc":[{"id":"1.229554914","rc":[{"atb":[[1.33,17.77]],"id":55943164},{"atl":[[50,2.61]],"id":55943164}],"con":true,"img":false}]}
{"op":"mcm","clk":"11450368918","pt":1717321104819,"mc":[{"id":"1.229554914","rc":[{"atl":[[1.8,0.26]],"id":55943164}],"con":true,"img":false}]}
{"op":"mcm","clk":"11450369182","pt":1717321108584,"mc":[{"id":"1.229554914","rc":[{"atb":[[2,12.57],[1.96,0]],"id":70003369}],"con":true,"img":false}]}
{"op":"mcm","clk":"11450369259","pt":1717321109722,"mc":[{"id":"1.229554914","rc":[{"atl":[[2.92,7.93],[2.98,0]],"id":70003369}],"con":true,"img":false}]}
{"op":"mcm","clk":"11450369284","pt":1717321110037,"mc":[{"id":"1.229554914","rc":[{"atl":[[2.9,3.77]],"id":70003369}],"con":true,"img":false}]}
{"op":"mcm","clk":"11450369289","pt":1717321110138,"mc":[{"id":"1.229554914","rc":[{"atb":[[2.18,7.79]],"id":70003369}],"con":true,"img":false}]}
{"op":"mcm","clk":"11450369428","pt":1717321112313,"mc":[{"id":"1.229554914","rc":[{"atl":[[2.92,3.74]],"id":70003369}],"con":true,"img":false}]}
{"op":"mcm","clk":"11450369432","pt":1717321112415,"mc":[{"id":"1.229554914","rc":[{"atl":[[2.96,4.21]],"id":70003369}],"con":true,"img":false}]}
{"op":"mcm","clk":"11450369503","pt":1717321113355,"mc":[{"id":"1.229554914","rc":[{"atb":[[2.16,0.86]],"id":70003369},{"atl":[[1.87,0]],"id":55943164}],"con":true,"img":false}]}
{"op":"mcm","clk":"11450369519","pt":1717321113610,"mc":[{"id":"1.229554914","rc":[{"atb":[[2.14,11.87]],"id":70003369}],"con":true,"img":false}]}
{"op":"mcm","clk":"11450369625","pt":1717321115212,"mc":[{"id":"1.229554914","rc":[{"atl":[[2.92,7.5],[2.96,0]],"id":70003369}],"con":true,"img":false}]}
{"op":"mcm","clk":"11450369670","pt":1717321116043,"mc":[{"id":"1.229554914","rc":[{"atl":[[1.8,0]],"id":55943164}],"con":true,"img":false}]}
{"op":"mcm","clk":"11450369682","pt":1717321116147,"mc":[{"id":"1.229554914","rc":[{"atb":[[1.78,6.95]],"id":55943164},{"trd":[[1.78,0.52]],"ltp":1.78,"tv":0.52,"id":55943164}],"con":true,"img":false}]}
{"op":"mcm","clk":"11450369687","pt":1717321116245,"mc":[{"id":"1.229554914","rc":[{"atb":[[1.78,4.66]],"id":55943164},{"trd":[[1.78,5.1]],"ltp":1.78,"tv":5.1,"id":55943164}],"con":true,"img":false}]}
{"op":"mcm","clk":"11450369734","pt":1717321116918,"mc":[{"id":"1.229554914","rc":[{"atb":[[2.18,11.66]],"id":70003369},{"atl":[[1.85,5.03]],"id":55943164}],"con":true,"img":false}]}
{"op":"mcm","clk":"11450369754","pt":1717321117330,"mc":[{"id":"1.229554914","rc":[{"atb":[[1.53,56.27]],"id":55943164}],"con":true,"img":false}]}
{"op":"mcm","clk":"11450369934","pt":1717321120238,"mc":[{"id":"1.229554914","rc":[{"atb":[[2.18,7.79]],"id":70003369},{"atl":[[1.85,0]],"id":55943164}],"con":true,"img":false}]}
{"op":"mcm","clk":"11450369971","pt":1717321120808,"mc":[{"id":"1.229554914","rc":[{"atl":[[2.92,3.74],[2.94,3.76]],"id":70003369}],"con":true,"img":false}]}
{"op":"mcm","clk":"11450369992","pt":1717321121103,"mc":[{"id":"1.229554914","marketDefinition":{"bspMarket":false,"turnInPlayEnabled":false,"persistenceEnabled":false,"marketBaseRate":7.0,"eventId":"33318908","eventTypeId":"4339","numberOfWinners":1,"bettingType":"ODDS","marketType":"MATCH_BET","marketTime":"2024-06-02T09:38:00.000Z","suspendTime":"2024-06-02T09:38:00.000Z","bspReconciled":false,"complete":true,"inPlay":false,"crossMatching":true,"runnersVoidable":false,"numberOfActiveRunners":2,"betDelay":0,"status":"SUSPENDED","runners":[{"status":"ACTIVE","sortPriority":1,"id":55943164,"name":"5. Lektra Ringo"},{"status":"ACTIVE","sortPriority":2,"id":70003369,"name":"6. Rickis Burner"}],"regulators":["MR_INT"],"venue":"Murray Bridge","countryCode":"AU","discountAllowed":true,"timezone":"Australia/Adelaide","openDate":"2024-06-02T08:21:00.000Z","version":5963063266,"name":"Lektra Ringo v Rickis Burner","eventName":"Murray Bridge (AUS) 2nd Jun"},"rc":[],"con":true,"img":false}]}
{"op":"mcm","clk":"11450370000","pt":1717321121137,"mc":[{"id":"1.229554914","rc":[{"atb":[[2,0],[1.99,0],[1.03,0],[1.84,0],[2.12,0],[2.18,0],[1.94,0],[2.16,0],[2.14,0],[2.1,0],[2.08,0]],"id":70003369},{"atl":[[2.92,0],[3.45,0],[2.9,0],[3.35,0],[3.55,0],[2.94,0],[990,0]],"id":70003369},{"atb":[[1.72,0],[1.01,0],[1.78,0],[1.7,0],[1.68,0],[1.33,0],[1.49,0],[1.53,0],[1.71,0]],"id":55943164},{"atl":[[1.92,0],[1.84,0],[1.97,0],[1.88,0],[1.9,0],[1.86,0],[50,0],[990,0]],"id":55943164}],"con":true,"img":false}]}
{"op":"mcm","clk":"11450377385","pt":1717321236214,"mc":[{"id":"1.229554914","rc":[{"trd":[[2.26,0]],"ltp":2.26,"tv":0.0,"id":70003369},{"trd":[[1.8,0],[1.78,0],[1.9,0]],"ltp":1.8,"tv":0.0,"id":55943164}],"con":true,"img":false}]}
{"op":"mcm","clk":"11450377439","pt":1717321237335,"mc":[{"id":"1.229554914","marketDefinition":{"bspMarket":false,"turnInPlayEnabled":false,"persistenceEnabled":false,"marketBaseRate":7.0,"eventId":"33318908","eventTypeId":"4339","numberOfWinners":1,"bettingType":"ODDS","marketType":"MATCH_BET","marketTime":"2024-06-02T09:38:00.000Z","suspendTime":"2024-06-02T09:38:00.000Z","bspReconciled":false,"complete":true,"inPlay":false,"crossMatching":false,"runnersVoidable":false,"numberOfActiveRunners":0,"betDelay":0,"status":"CLOSED","settledTime":"2024-06-02T09:40:34.000Z","runners":[{"status":"WINNER","sortPriority":1,"id":55943164,"name":"5. Lektra Ringo"},{"status":"LOSER","sortPriority":2,"id":70003369,"name":"6. Rickis Burner"}],"regulators":["MR_INT"],"venue":"Murray Bridge","countryCode":"AU","discountAllowed":true,"timezone":"Australia/Adelaide","openDate":"2024-06-02T08:21:00.000Z","version":5963065112,"name":"Lektra Ringo v Rickis Burner","eventName":"Murray Bridge (AUS) 2nd Jun"},"rc":[],"con":true,"img":false}]}
