{"op":"mcm","clk":"11449075395","pt":1717303241533,"mc":[{"id":"1.229554917","marketDefinition":{"bspMarket":false,"turnInPlayEnabled":false,"persistenceEnabled":false,"marketBaseRate":7.0,"eventId":"33318908","eventTypeId":"4339","numberOfWinners":1,"bettingType":"ODDS","marketType":"EXACTA","marketTime":"2024-06-02T10:03:00.000Z","suspendTime":"2024-06-02T10:03:00.000Z","bspReconciled":false,"complete":true,"inPlay":false,"crossMatching":true,"runnersVoidable":false,"numberOfActiveRunners":56,"betDelay":0,"status":"OPEN","runners":[{"status":"ACTIVE","sortPriority":1,"id":52385882,"name":"1 - 2"},{"status":"ACTIVE","sortPriority":2,"id":52385883,"name":"1 - 3"},{"status":"ACTIVE","sortPriority":3,"id":52385884,"name":"1 - 4"},{"status":"ACTIVE","sortPriority":4,"id":52385885,"name":"1 - 5"},{"status":"ACTIVE","sortPriority":5,"id":52385886,"name":"1 - 6"},{"status":"ACTIVE","sortPriority":6,"id":52385887,"name":"1 - 7"},{"status":"ACTIVE","sortPriority":7,"id":52385888,"name":"1 - 8"},{"status":"ACTIVE","sortPriority":8,"id":52385889,"name":"2 - 1"},{"status":"ACTIVE","sortPriority":9,"id":52385890,"name":"2 - 3"},{"status":"ACTIVE","sortPriority":10,"id":52385891,"name":"2 - 4"},{"status":"ACTIVE","sortPriority":11,"id":52385892,"name":"2 - 5"},{"status":"ACTIVE","sortPriority":12,"id":52385893,"name":"2 - 6"},{"status":"ACTIVE","sortPriority":13,"id":52385894,"name":"2 - 7"},{"status":"ACTIVE","sortPriority":14,"id":52385895,"name":"2 - 8"},{"status":"ACTIVE","sortPriority":15,"id":52385896,"name":"3 - 1"},{"status":"ACTIVE","sortPriority":16,"id":52385897,"name":"3 - 2"},{"status":"ACTIVE","sortPriority":17,"id":52385898,"name":"3 - 4"},{"status":"ACTIVE","sortPriority":18,"id":52385899,"name":"3 - 5"},{"status":"ACTIVE","sortPriority":19,"id":52385900,"name":"3 - 6"},{"status":"ACTIVE","sortPriority":20,"id":52385901,"name":"3 - 7"},{"status":"ACTIVE","sortPriority":21,"id":52385902,"name":"3 - 8"},{"status":"ACTIVE","sortPriority":22,"id":52385903,"name":"4 - 1"},{"status":"ACTIVE","sortPriority":23,"id":52385904,"name":"4 - 2"},{"status":"ACTIVE","sortPriority":24,"id":52385905,"name":"4 - 3"},{"status":"ACTIVE","sortPriority":25,"id":52385906,"name":"4 - 5"},{"status":"ACTIVE","sortPriority":26,"id":52385907,"name":"4 - 6"},{"status":"ACTIVE","sortPriority":27,"id":52385908,"name":"4 - 7"},{"status":"ACTIVE","sortPriority":28,"id":52385909,"name":"4 - 8"},{"status":"ACTIVE","sortPriority":29,"id":52385910,"name":"5 - 1"},{"status":"ACTIVE","sortPriority":30,"id":52385911,"name":"5 - 2"},{"status":"ACTIVE","sortPriority":31,"id":52385912,"name":"5 - 3"},{"status":"ACTIVE","sortPriority":32,"id":52385913,"name":"5 - 4"},{"status":"ACTIVE","sortPriority":33,"id":52385914,"name":"5 - 6"},{"status":"ACTIVE","sortPriority":34,"id":52385915,"name":"5 - 7"},{"status":"ACTIVE","sortPriority":35,"id":52385916,"name":"5 - 8"},{"status":"ACTIVE","sortPriority":36,"id":52385917,"name":"6 - 1"},{"status":"ACTIVE","sortPriority":37,"id":52385918,"name":"6 - 2"},{"status":"ACTIVE","sortPriority":38,"id":52385919,"name":"6 - 3"},{"status":"ACTIVE","sortPriority":39,"id":52385920,"name":"6 - 4"},{"status":"ACTIVE","sortPriority":40,"id":52385921,"name":"6 - 5"},{"status":"ACTIVE","sortPriority":41,"id":52385922,"name":"6 - 7"},{"status":"ACTIVE","sortPriority":42,"id":52385923,"name":"6 - 8"},{"status":"ACTIVE","sortPriority":43,"id":52385924,"name":"7 - 1"},{"status":"ACTIVE","sortPriority":44,"id":52385925,"name":"7 - 2"},{"status":"ACTIVE","sortPriority":45,"id":52385926,"name":"7 - 3"},{"status":"ACTIVE","sortPriority":46,"id":52385927,"name":"7 - 4"},{"status":"ACTIVE","sortPriority":47,"id":52385928,"name":"7 - 5"},{"status":"ACTIVE","sortPriority":48,"id":52385929,"name":"7 - 6"},{"status":"ACTIVE","sortPriority":49,"id":52385930,"name":"7 - 8"},{"status":"ACTIVE","sortPriority":50,"id":52385931,"name":"8 - 1"},{"status":"ACTIVE","sortPriority":51,"id":52385932,"name":"8 - 2"},{"status":"ACTIVE","sortPriority":52,"id":52385933,"name":"8 - 3"},{"status":"ACTIVE","sortPriority":53,"id":52385934,"name":"8 - 4"},{"status":"ACTIVE","sortPriority":54,"id":52385935,"name":"8 - 5"},{"status":"ACTIVE","sortPriority":55,"id":52385936,"name":"8 - 6"},{"status":"ACTIVE","sortPriority":56,"id":52385937,"name":"8 - 7"}],"regulators":["MR_INT"],"venue":"Murray Bridge","countryCode":"AU","discountAllowed":true,"timezone":"Australia/Adelaide","openDate":"2024-06-02T08:21:00.000Z","version":5962801938,"name":"Exacta","eventName":"Murray Bridge (AUS) 2nd Jun"},"rc":[],"con":true,"img":false}]}
{"op":"mcm","clk":"11449099382","pt":1717303849562,"mc":[{"id":"1.229554917","rc":[{"atb":[[16,6.96],[11,24.39]],"id":52385906},{"atb":[[270,0.9],[370,0.28]],"id":52385908},{"atb":[[19,13.55],[28,3.87]],"id":52385887},{"atb":[[130,1.88],[230,0.45]],"id":52385889},{"atb":[[9.8,11.87],[7.8,35.86]],"id":52385883},{"atb":[[6.4,45.16],[8.4,14.12]],"id":52385885},{"atb":[[550,0.44],[650,0.16]],"id":52385894},{"atb":[[11,10.45],[8.4,32.96]],"id":52385896},{"atb":[[550,0.44],[650,0.16]],"id":52385890},{"atb":[[400,0.61],[500,0.2]],"id":52385892},{"atb":[[8,14.93],[6,48.78]],"id":52385902},{"atb":[[550,0.44],[650,0.16]],"id":52385904},{"atb":[[18.5,5.97],[13.5,19.51]],"id":52385898},{"atb":[[19,5.8],[14,18.76]],"id":52385900},{"atb":[[16.5,15.73],[23,4.75]],"id":52385907},{"atb":[[7.2,39.33],[9.2,12.74]],"id":52385909},{"atb":[[9.2,29.74],[13,8.71]],"id":52385886},{"atb":[[4.5,29.86],[3.75,88.69]],"id":52385888},{"atb":[[110,0.95],[55,4.51]],"id":52385882},{"atb":[[9,30.48],[12.5,9.08]],"id":52385884},{"atb":[[46,2.32],[28,9.03]],"id":52385895},{"atb":[[550,0.44],[650,0.16]],"id":52385897},{"atb":[[550,0.44],[650,0.16]],"id":52385891},{"atb":[[550,0.44],[650,0.16]],"id":52385893},{"atb":[[13.5,8.36],[9.4,29.03]],"id":52385903},{"atb":[[18.5,5.97],[13.5,19.51]],"id":52385905},{"atb":[[9.6,28.36],[14,8.04]],"id":52385899},{"atb":[[200,0.52],[100,2.46]],"id":52385901}],"con":true,"img":false}]}
{"op":"mcm","clk":"11449099395","pt":1717303849820,"mc":[{"id":"1.229554917","rc":[{"atb":[[9.6,28.36],[14,8.04]],"id":52385912},{"atb":[[16.5,15.73],[23,4.75]],"id":52385920},{"atb":[[4.8,64.18],[5.8,21.77]],"id":52385916},{"atb":[[400,0.61],[500,0.2]],"id":52385929},{"atb":[[550,0.44],[650,0.16]],"id":52385925},{"atb":[[18,6.14],[13,20.32]],"id":52385937},{"atb":[[4.9,62.54],[5.9,21.33]],"id":52385933},{"atb":[[10.5,25.67],[15.5,7.2]],"id":52385913},{"atb":[[17,6.53],[12,22.17]],"id":52385921},{"atb":[[9.6,28.36],[14,8.04]],"id":52385917},{"atb":[[150,1.63],[250,0.41]],"id":52385926},{"atb":[[360,0.68],[460,0.23]],"id":52385922},{"atb":[[7.4,16.33],[5.7,51.89]],"id":52385934},{"atb":[[21,5.22],[15.5,16.82]],"id":52385930},{"atb":[[6.8,42.05],[8.8,13.4]],"id":52385910},{"atb":[[550,0.44],[650,0.16]],"id":52385918},{"atb":[[16.5,6.74],[11.5,23.22]],"id":52385914},{"atb":[[320,0.76],[420,0.25]],"id":52385927},{"atb":[[9.6,12.15],[7.6,36.95]],"id":52385923},{"atb":[[3.95,82.67],[4.9,26.8]],"id":52385935},{"atb":[[3.25,108.4],[3.75,38]],"id":52385931},{"atb":[[290,0.84],[390,0.26]],"id":52385911},{"atb":[[19.5,5.65],[14.5,18.06]],"id":52385919},{"atb":[[34,7.39],[60,1.77]],"id":52385915},{"atb":[[85,1.24],[44,5.67]],"id":52385928},{"atb":[[38,2.82],[24,10.6]],"id":52385924},{"atb":[[7.8,15.37],[5.9,49.77]],"id":52385936},{"atb":[[18,14.34],[26,4.18]],"id":52385932}],"con":true,"img":false}]}
{"op":"mcm","clk":"11449136323","pt":1717304580505,"mc":[{"id":"1.229554917","rc":[{"atb":[[32,2.53],[42,1.28],[26,4.19],[55,0.49]],"id":52385912},{"atb":[[300,0.09],[150,0.7],[200,0.39],[250,0.21]],"id":52385908},{"atb":[[65,0.82],[36,2.99],[90,0.29],[46,1.74]],"id":52385887},{"atb":[[32,3.37],[80,0.33],[42,1.92],[55,0.97]],"id":52385920},{"atb":[[17,4.9],[19.5,2.83],[24,1.14],[14.5,7.75]],"id":52385883},{"atb":[[17,1.64],[12,7.14],[9.8,11.89],[14.5,3.88]],"id":52385916},{"atb":[[32,0.84],[18,6.15],[21,3.92],[26,2.09]],"id":52385896},{"atb":[[270,0.39],[320,0.25],[370,0.14],[420,0.06]],"id":52385929},{"atb":[[550,0.14],[600,0.09],[650,0.04],[500,0.42]],"id":52385892},{"atb":[[840,0.13],[890,0.09],[940,0.06],[990,0.03]],"id":52385925},{"atb":[[520,0.15],[570,0.09],[620,0.04],[470,0.23]],"id":52385904},{"atb":[[32,1.69],[42,0.64],[21,5.23],[26,3.14]],"id":52385937},{"atb":[[32,2.53],[42,1.28],[26,4.19],[55,0.49]],"id":52385900},{"atb":[[4.5,29.89],[5,19.62],[5.5,11.63],[6,5.23]],"id":52385933},{"atb":[[70,0.38],[38,2.12],[48,1.11],[29,3.74]],"id":52385913},{"atb":[[16,6.97],[18.5,4.48],[22,2.49],[27,1]],"id":52385909},{"atb":[[6.8,9.02],[7.8,3.85],[5.9,16.01],[5.4,23.78]],"id":52385888},{"atb":[[34,3.17],[85,0.31],[44,1.83],[60,0.88]],"id":52385921},{"atb":[[32,0.84],[18,6.15],[21,3.92],[26,2.09]],"id":52385884},{"atb":[[38,1.41],[48,0.55],[24,4.55],[29,2.8]],"id":52385917},{"atb":[[260,0.2],[310,0.08],[160,0.66],[210,0.38]],"id":52385926},{"atb":[[300,0.35],[350,0.23],[400,0.13],[450,0.06]],"id":52385897},{"atb":[[280,0.19],[330,0.08],[180,0.59],[230,0.35]],"id":52385922},{"atb":[[840,0.13],[890,0.09],[940,0.06],[990,0.03]],"id":52385893},{"atb":[[5.6,22.75],[7.2,8.44],[6.2,15.09],[8.2,3.63]],"id":52385934},{"atb":[[32,2.53],[42,1.28],[26,4.19],[55,0.49]],"id":52385905},{"atb":[[75,0.71],[40,2.68],[100,0.27],[50,1.6]],"id":52385930},{"atb":[[170,0.31],[85,1.25],[220,0.12],[120,0.66]],"id":52385901},{"atb":[[16,6.97],[18.5,4.48],[22,2.49],[27,1]],"id":52385910},{"atb":[[75,0.36],[40,2.01],[50,1.07],[30,3.61]],"id":52385906},{"atb":[[540,0.19],[590,0.13],[640,0.08],[690,0.04]],"id":52385918},{"atb":[[280,0.28],[330,0.16],[380,0.07],[230,0.91]],"id":52385889},{"atb":[[75,0.36],[40,2.01],[50,1.07],[30,3.61]],"id":52385914},{"atb":[[16,5.23],[18.5,2.99],[22,1.25],[13.5,8.37]],"id":52385885},{"atb":[[840,0.13],[890,0.09],[940,0.06],[990,0.03]],"id":52385894},{"atb":[[290,0.27],[340,0.15],[390,0.07],[240,0.44]],"id":52385927},{"atb":[[590,0.18],[640,0.12],[690,0.08],[740,0.04]],"id":52385890},{"atb":[[17.5,6.34],[20,4.13],[25,2.18],[30,0.9]],"id":52385923},{"atb":[[17,3.27],[19.5,1.41],[12,9.51],[14.5,5.81]],"id":52385902},{"atb":[[7.2,16.88],[9.2,6.38],[10.5,2.75],[8.2,10.9]],"id":52385935},{"atb":[[32,2.53],[42,1.28],[26,4.19],[55,0.49]],"id":52385898},{"atb":[[4.9,20.12],[4.4,30.77],[5.9,5.34],[5.4,11.89]],"id":52385931},{"atb":[[290,1.11],[340,0.15],[390,0.34],[240,0.44]],"id":52385911},{"atb":[[75,0.36],[40,2.01],[50,1.07],[30,3.61]],"id":52385907},{"atb":[[34,0.8],[18.5,5.98],[22,3.74],[27,2.01]],"id":52385886},{"atb":[[34,2.38],[44,1.22],[27,4.02],[60,0.44]],"id":52385919},{"atb":[[140,0.38],[70,1.52],[190,0.14],[95,0.84]],"id":52385882},{"atb":[[140,0.38],[70,1.52],[190,0.14],[95,0.84]],"id":52385915},{"atb":[[140,0.57],[190,0.28],[95,1.11],[240,0.11]],"id":52385895},{"atb":[[270,0.1],[170,0.47],[220,0.24],[120,0.88]],"id":52385928},{"atb":[[780,0.14],[830,0.09],[880,0.06],[930,0.03]],"id":52385891},{"atb":[[160,0.16],[80,0.99],[110,0.48],[55,1.94]],"id":52385924},{"atb":[[34,1.59],[44,0.61],[22,4.98],[27,3.02]],"id":52385903},{"atb":[[6.8,9.02],[7.8,19.22],[5.9,65.79],[5.4,23.78]],"id":52385936},{"atb":[[32,2.53],[42,1.28],[26,4.19],[55,0.49]],"id":52385899},{"atb":[[34,3.17],[85,0.31],[44,1.83],[60,0.88]],"id":52385932}],"con":true,"img":false}]}
{"op":"mcm","clk":"11449138152","pt":1717304614763,"mc":[{"id":"1.229554917","rc":[{"atb":[[270,0],[320,0],[370,0],[420,0]],"id":52385929},{"atb":[[32,0],[42,0],[21,0],[26,0]],"id":52385937}],"con":true,"img":false}]}
{"op":"mcm","clk":"11449138162","pt":1717304614871,"mc":[{"id":"1.229554917","rc":[{"atb":[[300,0],[150,0],[200,0],[250,0]],"id":52385908},{"atb":[[17,0],[12,0],[9.8,0],[14.5,0]],"id":52385916},{"atb":[[550,0],[600,0],[650,0],[500,0.2]],"id":52385892},{"atb":[[520,0],[570,0],[620,0],[470,0]],"id":52385904},{"atb":[[16,0],[18.5,0],[22,0],[27,0]],"id":52385909},{"atb":[[38,0],[48,0],[24,0],[29,0]],"id":52385917},{"atb":[[300,0],[350,0],[400,0],[450,0]],"id":52385897},{"atb":[[280,0],[330,0],[180,0],[230,0]],"id":52385922},{"atb":[[75,0],[40,0],[100,0],[50,0]],"id":52385930},{"atb":[[170,0],[85,0],[220,0],[120,0]],"id":52385901},{"atb":[[16,0],[18.5,0],[22,0],[27,0]],"id":52385910},{"atb":[[75,0],[40,0],[50,0],[30,0]],"id":52385906},{"atb":[[540,0],[590,0],[640,0],[690,0]],"id":52385918},{"atb":[[16,0],[18.5,0],[22,0],[13.5,0]],"id":52385885},{"atb":[[290,0],[340,0],[390,0],[240,0]],"id":52385927},{"atb":[[590,0],[640,0],[690,0],[740,0]],"id":52385890},{"atb":[[17.5,0],[20,0],[25,0],[30,0]],"id":52385923},{"atb":[[17,0],[19.5,0],[12,0],[14.5,0]],"id":52385902},{"atb":[[7.2,0],[9.2,0],[10.5,0],[8.2,0]],"id":52385935},{"atb":[[4.9,0],[4.4,0],[5.9,0],[5.4,0]],"id":52385931},{"atb":[[290,0.84],[340,0],[390,0.26],[240,0]],"id":52385911},{"atb":[[140,0],[70,0],[190,0],[95,0]],"id":52385915},{"atb":[[140,0],[190,0],[95,0],[240,0]],"id":52385895},{"atb":[[270,0],[170,0],[220,0],[120,0]],"id":52385928},{"atb":[[780,0],[830,0],[880,0],[930,0]],"id":52385891}],"con":true,"img":false}]}
{"op":"mcm","clk":"11449138208","pt":1717304615491,"mc":[{"id":"1.229554917","rc":[{"atb":[[280,0.38],[330,0.24],[380,0.14],[430,0.06]],"id":52385929},{"atb":[[40,0.67],[20,5.51],[25,3.27],[30,1.81]],"id":52385937}],"con":true,"img":false}]}
{"op":"mcm","clk":"11449138212","pt":1717304615587,"mc":[{"id":"1.229554917","rc":[{"atb":[[260,0.2],[310,0.08],[160,0.66],[210,0.38]],"id":52385908},{"atb":[[16.5,1.69],[9.6,12.17],[11.5,7.48],[14,4.02]],"id":52385916},{"atb":[[560,0.14],[610,0.08],[660,0.04],[510,0.2]],"id":52385892},{"atb":[[540,0.15],[590,0.09],[640,0.04],[490,0.21]],"id":52385904},{"atb":[[18,4.61],[21,2.62],[26,1.05],[15.5,7.21]],"id":52385909},{"atb":[[40,1.34],[50,0.53],[25,4.36],[30,2.71]],"id":52385917},{"atb":[[320,0.33],[370,0.21],[420,0.13],[470,0.06]],"id":52385897},{"atb":[[290,0.18],[340,0.08],[190,0.55],[240,0.33]],"id":52385922},{"atb":[[70,0.76],[38,2.83],[95,0.28],[48,1.67]],"id":52385930},{"atb":[[130,0.61],[180,0.29],[90,1.18],[230,0.12]],"id":52385901},{"atb":[[16.5,6.75],[19,4.36],[23,2.38],[28,0.97]],"id":52385910},{"atb":[[32,3.37],[80,0.33],[42,1.92],[55,0.97]],"id":52385906},{"atb":[[560,0.19],[610,0.13],[660,0.08],[710,0.04]],"id":52385918},{"atb":[[16.5,5.06],[19,2.91],[23,1.19],[14,8.05]],"id":52385885},{"atb":[[300,0.26],[350,0.15],[400,0.07],[250,0.42]],"id":52385927},{"atb":[[600,0.17],[650,0.28],[700,0.07],[750,0.04]],"id":52385890},{"atb":[[17,6.54],[19.5,4.24],[24,2.28],[29,0.94]],"id":52385923},{"atb":[[16.5,3.37],[19,1.45],[11.5,9.97],[14,6.04]],"id":52385902},{"atb":[[8,11.21],[9,6.54],[10,2.91],[7,17.44]],"id":52385935},{"atb":[[5.2,12.46],[5.7,5.57],[4.2,32.7],[4.7,21.21]],"id":52385931},{"atb":[[300,0.26],[350,0.15],[400,0.07],[250,0.42]],"id":52385911},{"atb":[[150,0.35],[75,1.41],[200,0.13],[100,0.8]],"id":52385915},{"atb":[[130,0.61],[180,0.29],[90,1.18],[230,0.12]],"id":52385895},{"atb":[[130,0.81],[280,0.09],[180,0.44],[230,0.23]],"id":52385928},{"atb":[[800,0.13],[850,0.09],[900,0.06],[950,0.03]],"id":52385891}],"con":true,"img":false}]}
{"op":"mcm","clk":"11449204394","pt":1717305552537,"mc":[{"id":"1.229554917","rc":[{"atb":[[5.6,0],[7.2,0],[6.2,0],[8.2,0]],"id":52385934},{"atb":[[75,0],[40,0],[50,0],[30,0]],"id":52385907}],"con":true,"img":false}]}
{"op":"mcm","clk":"11449204465","pt":1717305553218,"mc":[{"id":"1.229554917","rc":[{"atb":[[5.6,22.75],[7.2,8.44],[6.2,15.09],[8.2,3.63]],"id":52385934},{"atb":[[75,0.36],[40,2.01],[50,1.07],[30,3.61]],"id":52385907}],"con":true,"img":false}]}
{"op":"mcm","clk":"11449256634","pt":1717306272841,"mc":[{"id":"1.229554917","rc":[{"atb":[[260,0],[310,0],[160,0],[210,0]],"id":52385908},{"atb":[[16.5,0],[9.6,0],[11.5,0],[14,0]],"id":52385916},{"atb":[[280,0],[330,0],[380,0],[430,0]],"id":52385929},{"atb":[[560,0],[610,0],[660,0],[510,0]],"id":52385892},{"atb":[[540,0],[590,0],[640,0],[490,0]],"id":52385904},{"atb":[[40,0],[20,0],[25,0],[30,0]],"id":52385937},{"atb":[[18,0],[21,0],[26,0],[15.5,0]],"id":52385909},{"atb":[[320,0],[370,0],[420,0],[470,0]],"id":52385897},{"atb":[[290,0],[340,0],[190,0],[240,0]],"id":52385922},{"atb":[[70,0],[38,0],[95,0],[48,0]],"id":52385930},{"atb":[[130,0],[180,0],[90,0],[230,0]],"id":52385901},{"atb":[[16.5,0],[19,0],[23,0],[28,0]],"id":52385910},{"atb":[[32,0],[80,0],[42,0],[55,0]],"id":52385906},{"atb":[[560,0],[610,0],[660,0],[710,0]],"id":52385918},{"atb":[[16.5,0],[19,0],[23,0],[14,0]],"id":52385885},{"atb":[[300,0],[350,0],[400,0],[250,0]],"id":52385927},{"atb":[[600,0],[650,0.16],[700,0],[750,0]],"id":52385890},{"atb":[[17,0],[19.5,0],[24,0],[29,0]],"id":52385923},{"atb":[[16.5,0],[19,0],[11.5,0],[14,0]],"id":52385902},{"atb":[[8,0],[9,0],[10,0],[7,0]],"id":52385935},{"atb":[[5.2,0],[5.7,0],[4.2,0],[4.7,0]],"id":52385931},{"atb":[[300,0],[350,0],[400,0],[250,0]],"id":52385911},{"atb":[[150,0],[75,0],[200,0],[100,0]],"id":52385915},{"atb":[[130,0],[180,0],[90,0],[230,0]],"id":52385895},{"atb":[[130,0],[280,0],[180,0],[230,0]],"id":52385928},{"atb":[[800,0],[850,0],[900,0],[950,0]],"id":52385891}],"con":true,"img":false}]}
{"op":"mcm","clk":"11449256702","pt":1717306273517,"mc":[{"id":"1.229554917","rc":[{"atb":[[300,0.09],[150,0.7],[200,0.39],[250,0.21]],"id":52385908},{"atb":[[17,1.64],[12,7.14],[9.8,11.89],[14.5,3.88]],"id":52385916},{"atb":[[550,0.14],[600,0.09],[650,0.04],[500,0.42]],"id":52385892},{"atb":[[520,0.15],[570,0.09],[620,0.04],[470,0.23]],"id":52385904},{"atb":[[32,1.69],[42,0.64],[21,5.23],[26,3.14]],"id":52385937},{"atb":[[16,6.97],[18.5,4.48],[22,2.49],[27,1]],"id":52385909},{"atb":[[300,0.35],[350,0.23],[400,0.13],[450,0.06]],"id":52385897},{"atb":[[280,0.19],[330,0.08],[180,0.59],[230,0.35]],"id":52385922},{"atb":[[75,0.71],[40,2.68],[100,0.27],[50,1.6]],"id":52385930},{"atb":[[170,0.31],[85,1.25],[220,0.12],[120,0.66]],"id":52385901},{"atb":[[16,6.97],[18.5,4.48],[22,2.49],[27,1]],"id":52385910},{"atb":[[75,0.36],[40,2.01],[50,1.07],[30,3.61]],"id":52385906},{"atb":[[540,0.19],[590,0.13],[640,0.08],[690,0.04]],"id":52385918},{"atb":[[16,5.23],[18.5,2.99],[22,1.25],[13.5,8.37]],"id":52385885},{"atb":[[290,0.27],[340,0.15],[390,0.07],[240,0.44]],"id":52385927},{"atb":[[590,0.18],[640,0.12],[690,0.08],[740,0.04]],"id":52385890},{"atb":[[17.5,6.34],[20,4.13],[25,2.18],[30,0.9]],"id":52385923},{"atb":[[17,3.27],[19.5,1.41],[12,9.51],[14.5,5.81]],"id":52385902},{"atb":[[7.2,16.88],[9.2,6.38],[10.5,2.75],[8.2,10.9]],"id":52385935},{"atb":[[4.9,20.12],[4.4,30.77],[5.9,5.34],[5.4,11.89]],"id":52385931},{"atb":[[290,1.11],[340,0.15],[390,0.34],[240,0.44]],"id":52385911},{"atb":[[140,0.38],[70,1.52],[190,0.14],[95,0.84]],"id":52385915},{"atb":[[140,0.57],[190,0.28],[95,1.11],[240,0.11]],"id":52385895},{"atb":[[270,0.1],[170,0.47],[220,0.24],[120,0.88]],"id":52385928},{"atb":[[780,0.14],[830,0.09],[880,0.06],[930,0.03]],"id":52385891}],"con":true,"img":false}]}
{"op":"mcm","clk":"11449256707","pt":1717306273616,"mc":[{"id":"1.229554917","rc":[{"atb":[[270,0.39],[320,0.25],[370,0.14],[420,0.06]],"id":52385929}],"con":true,"img":false}]}
{"op":"mcm","clk":"11449264761","pt":1717306377564,"mc":[{"id":"1.229554917","rc":[{"atb":[[17,0],[19.5,0],[24,0],[14.5,0]],"id":52385883},{"atb":[[520,0],[570,0],[620,0],[470,0]],"id":52385904},{"atb":[[4.5,0],[5,0],[5.5,0],[6,0]],"id":52385933},{"atb":[[300,0],[350,0],[400,0],[450,0]],"id":52385897},{"atb":[[32,0],[42,0],[26,0],[55,0]],"id":52385905},{"atb":[[540,0],[590,0],[640,0],[690,0]],"id":52385918},{"atb":[[17.5,0],[20,0],[25,0],[30,0]],"id":52385923},{"atb":[[32,0],[42,0],[26,0],[55,0]],"id":52385898},{"atb":[[75,0],[40,0],[50,0],[30,0]],"id":52385907},{"atb":[[34,0],[44,0],[27,0],[60,0]],"id":52385919}],"con":true,"img":false}]}
{"op":"mcm","clk":"11449264767","pt":1717306377665,"mc":[{"id":"1.229554917","rc":[{"atb":[[32,0],[80,0],[42,0],[55,0]],"id":52385920},{"atb":[[32,0],[42,0],[26,0],[55,0]],"id":52385900},{"atb":[[34,0],[85,0],[44,0],[60,0]],"id":52385932}],"con":true,"img":false}]}
{"op":"mcm","clk":"11449264815","pt":1717306378284,"mc":[{"id":"1.229554917","rc":[{"atb":[[17.5,4.76],[20,2.75],[25,1.09],[15,7.48]],"id":52385883},{"atb":[[270,0.39],[320,0.25],[370,0.14],[420,0.06]],"id":52385904},{"atb":[[4.8,20.65],[4.3,31.71],[5.8,5.45],[5.3,12.17]],"id":52385933},{"atb":[[270,0.1],[170,0.47],[220,0.24],[120,0.88]],"id":52385897},{"atb":[[38,1.41],[48,0.55],[24,4.55],[29,2.8]],"id":52385905},{"atb":[[300,0.35],[350,0.23],[400,0.13],[450,0.06]],"id":52385918},{"atb":[[17,6.54],[19.5,4.24],[24,2.28],[29,0.94]],"id":52385923},{"atb":[[40,1.34],[50,0.53],[25,4.36],[30,2.71]],"id":52385898},{"atb":[[65,0.41],[36,2.24],[46,1.16],[28,3.88]],"id":52385907},{"atb":[[40,1.34],[50,0.53],[25,4.36],[30,2.71]],"id":52385919}],"con":true,"img":false}]}
{"op":"mcm","clk":"11449264823","pt":1717306378389,"mc":[{"id":"1.229554917","rc":[{"atb":[[75,0.36],[40,2.01],[50,1.07],[30,3.61]],"id":52385920},{"atb":[[38,1.41],[48,0.55],[24,4.55],[29,2.8]],"id":52385900},{"atb":[[32,2.53],[42,1.28],[26,8.37],[55,0.49]],"id":52385932}],"con":true,"img":false}]}
{"op":"mcm","clk":"11449267691","pt":1717306417091,"mc":[{"id":"1.229554917","rc":[{"atb":[[32,0],[42,0],[21,0],[26,0]],"id":52385937},{"atb":[[17,0],[19.5,0],[12,0],[14.5,0]],"id":52385902},{"atb":[[7.2,0],[9.2,0],[10.5,0],[8.2,0]],"id":52385935}],"con":true,"img":false}]}
{"op":"mcm","clk":"11449267699","pt":1717306417195,"mc":[{"id":"1.229554917","rc":[{"atb":[[17,0],[12,0],[9.8,0],[14.5,0]],"id":52385916},{"atb":[[270,0],[320,0],[370,0],[420,0]],"id":52385929},{"atb":[[16,0],[18.5,0],[22,0],[27,0]],"id":52385909},{"atb":[[75,0],[40,0],[100,0],[50,0]],"id":52385930},{"atb":[[34,0],[18.5,0],[22,0],[27,0]],"id":52385886}],"con":true,"img":false}]}
{"op":"mcm","clk":"11449267743","pt":1717306417819,"mc":[{"id":"1.229554917","rc":[{"atb":[[40,0.67],[20,5.51],[25,3.27],[30,1.81]],"id":52385937},{"atb":[[16.5,3.37],[19,1.45],[11.5,9.97],[14,6.04]],"id":52385902},{"atb":[[8,11.21],[9,6.54],[10,2.91],[7,17.44]],"id":52385935}],"con":true,"img":false}]}
{"op":"mcm","clk":"11449267749","pt":1717306417921,"mc":[{"id":"1.229554917","rc":[{"atb":[[16.5,1.69],[9.6,12.17],[11.5,7.48],[14,4.02]],"id":52385916},{"atb":[[280,0.38],[330,0.24],[380,0.14],[430,0.06]],"id":52385929},{"atb":[[18,4.61],[21,2.62],[26,1.05],[15.5,7.21]],"id":52385909},{"atb":[[70,0.76],[38,2.83],[95,0.28],[48,1.67]],"id":52385930},{"atb":[[36,0.75],[19,5.81],[23,3.57],[28,1.94]],"id":52385886}],"con":true,"img":false}]}
{"op":"mcm","clk":"11449271289","pt":1717306465313,"mc":[{"id":"1.229554917","rc":[{"atb":[[280,0],[330,0],[380,0],[430,0]],"id":52385929},{"atb":[[36,0],[19,0],[23,0],[28,0]],"id":52385886}],"con":true,"img":false}]}
{"op":"mcm","clk":"11449271337","pt":1717306465987,"mc":[{"id":"1.229554917","rc":[{"atb":[[270,0.39],[320,0.25],[370,0.14],[420,0.06]],"id":52385929},{"atb":[[34,0.8],[18.5,5.98],[22,3.74],[27,2.01]],"id":52385886}],"con":true,"img":false}]}
{"op":"mcm","clk":"11449289064","pt":1717306703015,"mc":[{"id":"1.229554917","rc":[{"atb":[[270,0],[320,0],[370,0],[420,0]],"id":52385904},{"atb":[[4.8,0],[4.3,0],[5.8,0],[5.3,0]],"id":52385933},{"atb":[[38,0],[48,0],[24,0],[29,0]],"id":52385905},{"atb":[[300,0],[350,0],[400,0],[450,0]],"id":52385918},{"atb":[[4.9,0],[4.4,0],[5.9,0],[5.4,0]],"id":52385931},{"atb":[[140,0],[70,0],[190,0],[95,0]],"id":52385882},{"atb":[[6.8,0],[7.8,15.37],[5.9,49.77],[5.4,0]],"id":52385936},{"atb":[[32,0],[42,0],[26,4.18],[55,0]],"id":52385932}],"con":true,"img":false}]}
{"op":"mcm","clk":"11449289130","pt":1717306703797,"mc":[{"id":"1.229554917","rc":[{"atb":[[270,0.39],[320,0.25],[370,0.14],[420,0.06]],"id":52385918},{"atb":[[160,0.16],[80,0.99],[110,1.44],[55,6.45]],"id":52385882}],"con":true,"img":false}]}
{"op":"mcm","clk":"11449289161","pt":1717306704263,"mc":[{"id":"1.229554917","rc":[{"atb":[[290,0.27],[340,0.15],[390,0.07],[240,0.44]],"id":52385904},{"atb":[[6.4,4.84],[5.2,18.68],[5.7,11.13],[4.7,28.28]],"id":52385933},{"atb":[[34,2.38],[44,1.22],[27,4.02],[60,0.44]],"id":52385905},{"atb":[[5.2,12.46],[5.7,5.57],[4.2,32.7],[4.7,21.21]],"id":52385931},{"atb":[[5.6,22.75],[7.2,8.44],[6.2,15.09],[8.2,3.63]],"id":52385936},{"atb":[[36,1.5],[46,0.58],[23,4.76],[28,2.91]],"id":52385932}],"con":true,"img":false}]}
{"op":"mcm","clk":"11449296632","pt":1717306798167,"mc":[{"id":"1.229554917","rc":[{"atb":[[290,0],[340,0],[390,0],[240,0]],"id":52385904},{"atb":[[34,0],[44,0],[27,0],[60,0]],"id":52385905},{"atb":[[270,0],[320,0],[370,0],[420,0]],"id":52385918}],"con":true,"img":false}]}
{"op":"mcm","clk":"11449296687","pt":1717306798889,"mc":[{"id":"1.229554917","rc":[{"atb":[[290,0.27],[340,0.15],[390,0.07],[240,0.44]],"id":52385904},{"atb":[[34,2.38],[44,1.22],[27,4.02],[60,0.44]],"id":52385905},{"atb":[[270,0.39],[320,0.25],[370,0.14],[420,0.06]],"id":52385918}],"con":true,"img":false}]}
{"op":"mcm","clk":"11449329587","pt":1717307261697,"mc":[{"id":"1.229554917","rc":[{"atb":[[5.6,0],[7.2,0],[6.2,0],[8.2,0]],"id":52385934}],"con":true,"img":false}]}
{"op":"mcm","clk":"11449329635","pt":1717307262368,"mc":[{"id":"1.229554917","rc":[{"atb":[[6.8,13.53],[8.8,3.35],[7.8,7.7],[5.9,21.36]],"id":52385934}],"con":true,"img":false}]}
{"op":"mcm","clk":"11449361525","pt":1717307909967,"mc":[{"id":"1.229554917","rc":[{"atb":[[300,0],[150,0],[200,0],[250,0]],"id":52385908},{"atb":[[550,0],[600,0],[650,0],[500,0.2]],"id":52385892},{"atb":[[280,0],[330,0],[180,0],[230,0]],"id":52385922},{"atb":[[170,0],[85,0],[220,0],[120,0]],"id":52385901},{"atb":[[16,0],[18.5,0],[22,0],[27,0]],"id":52385910},{"atb":[[75,0],[40,0],[50,0],[30,0]],"id":52385906},{"atb":[[16,0],[18.5,0],[22,0],[13.5,0]],"id":52385885},{"atb":[[290,0],[340,0],[390,0],[240,0]],"id":52385927},{"atb":[[590,0],[640,0],[690,0],[740,0]],"id":52385890},{"atb":[[290,0.84],[340,0],[390,0.26],[240,0]],"id":52385911},{"atb":[[140,0],[70,0],[190,0],[95,0]],"id":52385915},{"atb":[[270,0],[170,0],[220,0],[120,0]],"id":52385928},{"atb":[[780,0],[880,0]],"id":52385891}],"con":true,"img":false}]}
{"op":"mcm","clk":"11449361527","pt":1717307910023,"mc":[{"id":"1.229554917","rc":[{"atb":[[830,0],[930,0]],"id":52385891}],"con":true,"img":false}]}
{"op":"mcm","clk":"11449361556","pt":1717307910638,"mc":[{"id":"1.229554917","rc":[{"atb":[[260,0.2],[310,0.08],[160,0.66],[210,0.38]],"id":52385908},{"atb":[[560,0.14],[610,0.08],[660,0.04],[510,0.2]],"id":52385892},{"atb":[[290,0.18],[340,0.08],[190,0.55],[240,0.33]],"id":52385922},{"atb":[[130,0.61],[180,0.29],[90,1.18],[230,0.12]],"id":52385901},{"atb":[[16.5,6.75],[19,4.36],[23,2.38],[28,0.97]],"id":52385910},{"atb":[[32,3.37],[80,0.33],[42,1.92],[55,0.97]],"id":52385906},{"atb":[[16.5,5.06],[19,2.91],[23,1.19],[14,8.05]],"id":52385885},{"atb":[[300,0.26],[350,0.15],[400,0.07],[250,0.42]],"id":52385927},{"atb":[[600,0.17],[650,0.28],[700,0.07],[750,0.04]],"id":52385890},{"atb":[[300,0.26],[350,0.15],[400,0.07],[250,0.42]],"id":52385911},{"atb":[[150,0.35],[75,1.41],[200,0.13],[100,0.8]],"id":52385915},{"atb":[[130,0.81],[280,0.09],[180,0.44],[230,0.23]],"id":52385928},{"atb":[[800,0.13],[900,0.06]],"id":52385891}],"con":true,"img":false}]}
{"op":"mcm","clk":"11449361563","pt":1717307910740,"mc":[{"id":"1.229554917","rc":[{"atb":[[850,0.09],[950,0.03]],"id":52385891}],"con":true,"img":false}]}
{"op":"mcm","clk":"11449365501","pt":1717308004157,"mc":[{"id":"1.229554917","rc":[{"atb":[[170,0]],"id":52385897},{"atb":[[28,0]],"id":52385907},{"atb":[[40,0]],"id":52385919}],"con":true,"img":false}]}
{"op":"mcm","clk":"11449365512","pt":1717308004257,"mc":[{"id":"1.229554917","rc":[{"atb":[[75,0],[40,0],[50,0],[30,0]],"id":52385920},{"atb":[[38,0],[48,0],[24,0],[29,0]],"id":52385900},{"atb":[[270,0],[220,0],[120,0]],"id":52385897},{"atb":[[40,0],[50,0],[25,0],[30,0]],"id":52385898},{"atb":[[65,0],[36,0],[46,0]],"id":52385907},{"atb":[[50,0],[25,0],[30,0]],"id":52385919}],"con":true,"img":false}]}
{"op":"mcm","clk":"11449365556","pt":1717308004832,"mc":[{"id":"1.229554917","rc":[{"atb":[[180,0.44]],"id":52385897},{"atb":[[30,3.61]],"id":52385907},{"atb":[[46,1.16]],"id":52385919}],"con":true,"img":false}]}
{"op":"mcm","clk":"11449365562","pt":1717308004938,"mc":[{"id":"1.229554917","rc":[{"atb":[[34,3.17],[85,0.31],[44,1.83],[60,0.88]],"id":52385920},{"atb":[[34,2.38],[44,1.22],[27,4.02],[60,0.44]],"id":52385900},{"atb":[[130,0.81],[280,0.09],[230,0.23]],"id":52385897},{"atb":[[65,0.41],[36,2.24],[46,1.16],[28,3.88]],"id":52385898},{"atb":[[75,0.36],[40,2.01],[50,1.07]],"id":52385907},{"atb":[[65,0.41],[36,2.24],[28,3.88]],"id":52385919}],"con":true,"img":false}]}
{"op":"mcm","clk":"11449369543","pt":1717308083118,"mc":[{"id":"1.229554917","rc":[{"atb":[[270,0]],"id":52385929}],"con":true,"img":false}]}
{"op":"mcm","clk":"11449369546","pt":1717308083218,"mc":[{"id":"1.229554917","rc":[{"atb":[[320,0],[370,0],[420,0]],"id":52385929}],"con":true,"img":false}]}
{"op":"mcm","clk":"11449369573","pt":1717308083831,"mc":[{"id":"1.229554917","rc":[{"atb":[[280,0.38]],"id":52385929}],"con":true,"img":false}]}
{"op":"mcm","clk":"11449369578","pt":1717308083936,"mc":[{"id":"1.229554917","rc":[{"atb":[[330,0.24],[380,0.14],[430,0.06]],"id":52385929}],"con":true,"img":false}]}
{"op":"mcm","clk":"11449372909","pt":1717308161549,"mc":[{"id":"1.229554917","rc":[{"atb":[[260,0],[310,0],[160,0],[210,0]],"id":52385908},{"atb":[[16.5,0],[9.6,0],[11.5,0],[14,0]],"id":52385916},{"atb":[[280,0],[330,0],[380,0],[430,0]],"id":52385929},{"atb":[[560,0],[610,0],[660,0],[510,0]],"id":52385892},{"atb":[[40,0],[20,0],[25,0],[30,0]],"id":52385937},{"atb":[[18,0],[21,0],[26,0],[15.5,0]],"id":52385909},{"atb":[[290,0],[340,0],[190,0],[240,0]],"id":52385922},{"atb":[[70,0],[38,0],[95,0],[48,0]],"id":52385930},{"atb":[[130,0],[180,0],[90,0],[230,0]],"id":52385901},{"atb":[[16.5,0],[19,0],[23,0],[28,0]],"id":52385910},{"atb":[[32,0],[80,0],[42,0],[55,0]],"id":52385906},{"atb":[[16.5,0],[19,0],[23,0],[14,0]],"id":52385885},{"atb":[[300,0],[350,0],[400,0],[250,0]],"id":52385927},{"atb":[[600,0],[650,0.16],[700,0],[750,0]],"id":52385890},{"atb":[[17,0],[19.5,0],[24,0],[29,0]],"id":52385923},{"atb":[[16.5,0],[19,0],[11.5,0],[14,0]],"id":52385902},{"atb":[[8,0],[9,0],[10,0],[7,0]],"id":52385935},{"atb":[[300,0],[350,0],[400,0],[250,0]],"id":52385911},{"atb":[[150,0],[75,0],[200,0],[100,0]],"id":52385915},{"atb":[[130,0],[280,0],[180,0],[230,0]],"id":52385928}],"con":true,"img":false}]}
{"op":"mcm","clk":"11449372944","pt":1717308162626,"mc":[{"id":"1.229554917","rc":[{"atb":[[300,0.09],[150,0.7],[200,0.39],[250,0.21]],"id":52385908},{"atb":[[17,1.64],[12,7.14],[9.8,11.89],[14.5,3.88]],"id":52385916},{"atb":[[270,0.39],[320,0.25],[370,0.14],[420,0.06]],"id":52385929},{"atb":[[550,0.14],[600,0.09],[650,0.04],[500,0.42]],"id":52385892},{"atb":[[32,1.69],[42,0.64],[21,5.23],[26,3.14]],"id":52385937},{"atb":[[280,0.19],[330,0.08],[180,0.59],[230,0.35]],"id":52385922},{"atb":[[75,0.71],[40,2.68],[100,0.27],[50,1.6]],"id":52385930},{"atb":[[170,0.31],[85,1.25],[220,0.12],[120,0.66]],"id":52385901},{"atb":[[16,6.97],[18.5,4.48],[22,2.49],[27,1]],"id":52385910},{"atb":[[16,5.23],[18.5,2.99],[22,1.25],[13.5,8.37]],"id":52385885},{"atb":[[290,0.27],[340,0.15],[390,0.07],[240,0.44]],"id":52385927},{"atb":[[590,0.18],[640,0.12],[690,0.08],[740,0.04]],"id":52385890},{"atb":[[17.5,6.34],[20,4.13],[25,2.18],[30,0.9]],"id":52385923},{"atb":[[17,3.27],[19.5,1.41],[12,9.51],[14.5,5.81]],"id":52385902},{"atb":[[290,1.11],[340,0.15],[390,0.34],[240,0.44]],"id":52385911},{"atb":[[140,0.38],[70,1.52],[190,0.14],[95,0.84]],"id":52385915},{"atb":[[270,0.1],[170,0.47],[220,0.24],[120,0.88]],"id":52385928}],"con":true,"img":false}]}
{"op":"mcm","clk":"11449372949","pt":1717308162727,"mc":[{"id":"1.229554917","rc":[{"atb":[[16,6.97],[18.5,4.48],[22,2.49],[27,1]],"id":52385909},{"atb":[[75,0.36],[40,2.01],[50,1.07],[30,3.61]],"id":52385906},{"atb":[[7.2,16.88],[9.2,6.38],[10.5,2.75],[8.2,10.9]],"id":52385935}],"con":true,"img":false}]}
{"op":"mcm","clk":"11449375484","pt":1717308219493,"mc":[{"id":"1.229554917","rc":[{"atb":[[17,0],[12,0],[9.8,0],[14.5,0]],"id":52385916},{"atb":[[32,0],[42,0],[21,0],[26,0]],"id":52385937},{"atb":[[16,0],[18.5,0],[22,0],[27,0]],"id":52385909},{"atb":[[75,0],[40,0],[100,0],[50,0]],"id":52385930},{"atb":[[17.5,0],[20,0],[25,0],[30,0]],"id":52385923},{"atb":[[7.2,0],[9.2,0],[10.5,0],[8.2,0]],"id":52385935}],"con":true,"img":false}]}
{"op":"mcm","clk":"11449375530","pt":1717308220215,"mc":[{"id":"1.229554917","rc":[{"atb":[[16.5,1.69],[9.6,12.17],[11.5,7.48],[14,4.02]],"id":52385916},{"atb":[[40,0.67],[20,5.51],[25,3.27],[30,1.81]],"id":52385937},{"atb":[[18,4.61],[21,2.62],[26,1.05],[15.5,7.21]],"id":52385909},{"atb":[[70,0.76],[38,2.83],[95,0.28],[48,1.67]],"id":52385930},{"atb":[[17,6.54],[19.5,4.24],[24,2.28],[29,0.94]],"id":52385923},{"atb":[[8,11.21],[9,6.54],[10,2.91],[7,17.44]],"id":52385935}],"con":true,"img":false}]}
{"op":"mcm","clk":"11449377137","pt":1717308255047,"mc":[{"id":"1.229554917","rc":[{"atb":[[290,0],[340,0],[390,0],[240,0]],"id":52385904},{"atb":[[130,0],[280,0],[180,0],[230,0]],"id":52385897},{"atb":[[34,0],[44,0],[27,0],[60,0]],"id":52385905},{"atb":[[270,0],[320,0],[370,0],[420,0]],"id":52385918},{"atb":[[65,0],[36,0],[46,0],[28,0]],"id":52385898}],"con":true,"img":false}]}
{"op":"mcm","clk":"11449377185","pt":1717308255771,"mc":[{"id":"1.229554917","rc":[{"atb":[[130,0.81],[280,0.09],[180,0.44],[230,0.23]],"id":52385897},{"atb":[[34,2.38],[44,1.22],[27,4.02],[60,0.44]],"id":52385905},{"atb":[[270,0.39],[320,0.25],[370,0.14],[420,0.06]],"id":52385918}],"con":true,"img":false}]}
{"op":"mcm","clk":"11449377191","pt":1717308255875,"mc":[{"id":"1.229554917","rc":[{"atb":[[290,0.27],[340,0.15],[390,0.07],[240,0.44]],"id":52385904},{"atb":[[65,0.41],[36,2.24],[46,1.16],[28,3.88]],"id":52385898}],"con":true,"img":false}]}
{"op":"mcm","clk":"11449377575","pt":1717308263285,"mc":[{"id":"1.229554917","rc":[{"atb":[[270,0],[370,0]],"id":52385908},{"atb":[[19,0],[28,0]],"id":52385887},{"atb":[[9.8,0],[7.8,0]],"id":52385883},{"atb":[[11,0],[8.4,0]],"id":52385896},{"atb":[[400,0],[500,0.21]],"id":52385892},{"atb":[[550,0],[650,0]],"id":52385904},{"atb":[[19,0],[14,0]],"id":52385900},{"atb":[[7.2,0],[9.2,0]],"id":52385909},{"atb":[[4.5,0],[3.75,0]],"id":52385888},{"atb":[[9,0],[12.5,0]],"id":52385884},{"atb":[[550,0],[650,0]],"id":52385897},{"atb":[[550,0],[650,0]],"id":52385893},{"atb":[[18.5,0],[13.5,0]],"id":52385905},{"atb":[[200,0],[100,0]],"id":52385901},{"atb":[[6.8,0],[8.8,0]],"id":52385910},{"atb":[[16,0],[11,0]],"id":52385906},{"atb":[[130,0],[230,0.46]],"id":52385889},{"atb":[[6.4,0],[8.4,0]],"id":52385885},{"atb":[[550,0],[650,0]],"id":52385894},{"atb":[[550,0],[650,0]],"id":52385890},{"atb":[[8,0],[6,0]],"id":52385902},{"atb":[[18.5,0],[13.5,0]],"id":52385898},{"atb":[[290,0.27],[390,0.07]],"id":52385911},{"atb":[[16.5,0],[23,0]],"id":52385907},{"atb":[[9.2,0],[13,0]],"id":52385886},{"atb":[[110,0.48],[55,1.94]],"id":52385882},{"atb":[[46,0],[28,0]],"id":52385895},{"atb":[[550,0],[650,0]],"id":52385891},{"atb":[[13.5,0],[9.4,0]],"id":52385903},{"atb":[[9.6,0],[14,0]],"id":52385899}],"con":true,"img":false}]}
{"op":"mcm","clk":"11449377580","pt":1717308263348,"mc":[{"id":"1.229554917","rc":[{"atb":[[9.6,0],[14,0]],"id":52385912},{"atb":[[16.5,0],[23,0]],"id":52385920},{"atb":[[4.8,0],[5.8,0]],"id":52385916},{"atb":[[400,0],[500,0]],"id":52385929},{"atb":[[550,0],[650,0]],"id":52385925},{"atb":[[18,0],[13,0]],"id":52385937},{"atb":[[4.9,0],[5.9,0]],"id":52385933},{"atb":[[10.5,0],[15.5,0]],"id":52385913},{"atb":[[17,0],[12,0]],"id":52385921},{"atb":[[9.6,0],[14,0]],"id":52385917},{"atb":[[150,0],[250,0]],"id":52385926},{"atb":[[360,0],[460,0]],"id":52385922},{"atb":[[7.4,0],[5.7,0]],"id":52385934},{"atb":[[21,0],[15.5,0]],"id":52385930},{"atb":[[550,0],[650,0]],"id":52385918},{"atb":[[16.5,0],[11.5,0]],"id":52385914},{"atb":[[320,0],[420,0]],"id":52385927},{"atb":[[9.6,0],[7.6,0]],"id":52385923},{"atb":[[3.95,0],[4.9,0]],"id":52385935},{"atb":[[3.25,0],[3.75,0]],"id":52385931},{"atb":[[19.5,0],[14.5,0]],"id":52385919},{"atb":[[34,0],[60,0]],"id":52385915},{"atb":[[85,0],[44,0]],"id":52385928},{"atb":[[38,0],[24,0]],"id":52385924},{"atb":[[7.8,0],[5.9,0]],"id":52385936},{"atb":[[18,0],[26,0]],"id":52385932}],"con":true,"img":false}]}
{"op":"mcm","clk":"11449380791","pt":1717308317713,"mc":[{"id":"1.229554917","rc":[{"atb":[[9.6,28.36],[14,8.04]],"id":52385912},{"atb":[[290,0.84],[390,0.26]],"id":52385908},{"atb":[[19.5,13.18],[29,3.73]],"id":52385887},{"atb":[[16.5,15.73],[23,4.75]],"id":52385920},{"atb":[[8,34.84],[10,11.61]],"id":52385883},{"atb":[[5.7,22.24],[4.7,65.92]],"id":52385916},{"atb":[[11,10.45],[8.4,32.96]],"id":52385896},{"atb":[[530,0.19],[430,0.57]],"id":52385929},{"atb":[[530,0.19],[430,0.57]],"id":52385892},{"atb":[[550,0.44],[650,0.16]],"id":52385925},{"atb":[[550,0.44],[650,0.16]],"id":52385904},{"atb":[[17.5,6.33],[12.5,21.2]],"id":52385937},{"atb":[[19.5,5.65],[14.5,18.06]],"id":52385900},{"atb":[[4.8,64.18],[5.8,21.77]],"id":52385933},{"atb":[[10.5,25.67],[15.5,7.2]],"id":52385913},{"atb":[[7.2,39.33],[9.2,12.74]],"id":52385909},{"atb":[[4.5,29.86],[3.75,88.69]],"id":52385888},{"atb":[[17.5,6.33],[12.5,21.2]],"id":52385921},{"atb":[[9,30.48],[12.5,9.08]],"id":52385884},{"atb":[[9.6,28.36],[14,8.04]],"id":52385917},{"atb":[[260,0.61],[160,2.19]],"id":52385926},{"atb":[[550,0.44],[650,0.16]],"id":52385897},{"atb":[[380,0.64],[480,0.21]],"id":52385922},{"atb":[[550,0.44],[650,0.16]],"id":52385893},{"atb":[[7.4,16.33],[5.7,51.89]],"id":52385934},{"atb":[[19,5.8],[14,18.76]],"id":52385905},{"atb":[[21,5.22],[15.5,16.82]],"id":52385930},{"atb":[[210,0.5],[110,2.23]],"id":52385901},{"atb":[[9,13.06],[7,40.65]],"id":52385910},{"atb":[[16.5,6.74],[11.5,23.22]],"id":52385906},{"atb":[[550,0.44],[650,0.16]],"id":52385918},{"atb":[[140,1.75],[240,0.43]],"id":52385889},{"atb":[[16.5,6.74],[11.5,23.22]],"id":52385914},{"atb":[[6.4,45.16],[8.4,14.12]],"id":52385885},{"atb":[[550,0.44],[650,0.16]],"id":52385894},{"atb":[[340,0.87],[440,0.24]],"id":52385927},{"atb":[[550,0.44],[650,0.16]],"id":52385890},{"atb":[[9.6,12.15],[7.6,36.95]],"id":52385923},{"atb":[[7.8,15.37],[5.9,49.77]],"id":52385902},{"atb":[[4.8,27.5],[3.9,84.1]],"id":52385935},{"atb":[[18.5,5.97],[13.5,19.51]],"id":52385898},{"atb":[[3.2,110.86],[3.7,38.71]],"id":52385931},{"atb":[[310,0.78],[410,0.25]],"id":52385911},{"atb":[[16.5,15.73],[23,4.75]],"id":52385907},{"atb":[[13.5,8.36],[9.4,29.03]],"id":52385886},{"atb":[[19.5,5.65],[14.5,18.06]],"id":52385919},{"atb":[[120,0.87],[60,4.13]],"id":52385882},{"atb":[[65,1.63],[36,6.96]],"id":52385915},{"atb":[[46,2.32],[28,9.03]],"id":52385895},{"atb":[[90,1.17],[46,5.42]],"id":52385928},{"atb":[[550,0.44],[650,0.16]],"id":52385891},{"atb":[[38,2.82],[24,10.6]],"id":52385924},{"atb":[[13.5,8.36],[9.4,29.03]],"id":52385903},{"atb":[[7.8,15.37],[5.9,49.77]],"id":52385936},{"atb":[[9.8,27.71],[14.5,7.74]],"id":52385899},{"atb":[[17.5,14.77],[25,4.35]],"id":52385932}],"con":true,"img":false}]}
{"op":"mcm","clk":"11449383827","pt":1717308364977,"mc":[{"id":"1.229554917","rc":[{"atb":[[290,0],[390,0]],"id":52385908},{"atb":[[19.5,0],[29,0]],"id":52385887},{"atb":[[8,0],[10,0]],"id":52385883},{"atb":[[11,0],[8.4,0]],"id":52385896},{"atb":[[530,0],[430,0]],"id":52385892},{"atb":[[550,0],[650,0]],"id":52385904},{"atb":[[19.5,0],[14.5,0]],"id":52385900},{"atb":[[7.2,0],[9.2,0]],"id":52385909},{"atb":[[4.5,0],[3.75,0]],"id":52385888},{"atb":[[9,0],[12.5,0]],"id":52385884},{"atb":[[550,0],[650,0]],"id":52385897},{"atb":[[550,0],[650,0]],"id":52385893},{"atb":[[19,0],[14,0]],"id":52385905},{"atb":[[210,0],[110,0]],"id":52385901},{"atb":[[9,0],[7,0]],"id":52385910},{"atb":[[16.5,0],[11.5,0]],"id":52385906},{"atb":[[140,0],[240,0]],"id":52385889},{"atb":[[6.4,0],[8.4,0]],"id":52385885},{"atb":[[550,0],[650,0]],"id":52385894},{"atb":[[550,0],[650,0]],"id":52385890},{"atb":[[7.8,0],[5.9,0]],"id":52385902},{"atb":[[18.5,0],[13.5,0]],"id":52385898},{"atb":[[310,0],[410,0]],"id":52385911},{"atb":[[16.5,0],[23,0]],"id":52385907},{"atb":[[13.5,0],[9.4,0]],"id":52385886},{"atb":[[120,0],[60,0]],"id":52385882},{"atb":[[46,0],[28,0]],"id":52385895},{"atb":[[550,0],[650,0]],"id":52385891},{"atb":[[13.5,0],[9.4,0]],"id":52385903},{"atb":[[9.8,0],[14.5,0]],"id":52385899}],"con":true,"img":false}]}
{"op":"mcm","clk":"11449383832","pt":1717308365078,"mc":[{"id":"1.229554917","rc":[{"atb":[[9.6,0],[14,0]],"id":52385912},{"atb":[[16.5,0],[23,0]],"id":52385920},{"atb":[[5.7,0],[4.7,0]],"id":52385916},{"atb":[[530,0],[430,0]],"id":52385929},{"atb":[[550,0],[650,0]],"id":52385925},{"atb":[[17.5,0],[12.5,0]],"id":52385937},{"atb":[[4.8,0],[5.8,0]],"id":52385933},{"atb":[[10.5,0],[15.5,0]],"id":52385913},{"atb":[[17.5,0],[12.5,0]],"id":52385921},{"atb":[[9.6,0],[14,0]],"id":52385917},{"atb":[[260,0.2],[160,0.66]],"id":52385926},{"atb":[[380,0],[480,0]],"id":52385922},{"atb":[[7.4,0],[5.7,0]],"id":52385934},{"atb":[[21,0],[15.5,0]],"id":52385930},{"atb":[[550,0],[650,0]],"id":52385918},{"atb":[[16.5,0],[11.5,0]],"id":52385914},{"atb":[[340,0.15],[440,0]],"id":52385927},{"atb":[[9.6,0],[7.6,0]],"id":52385923},{"atb":[[4.8,0],[3.9,0]],"id":52385935},{"atb":[[3.2,0],[3.7,0]],"id":52385931},{"atb":[[19.5,0],[14.5,0]],"id":52385919},{"atb":[[65,0],[36,0]],"id":52385915},{"atb":[[90,0],[46,0]],"id":52385928},{"atb":[[38,0],[24,0]],"id":52385924},{"atb":[[7.8,0],[5.9,0]],"id":52385936},{"atb":[[17.5,0],[25,0]],"id":52385932}],"con":true,"img":false}]}
{"op":"mcm","clk":"11449386610","pt":1717308408621,"mc":[{"id":"1.229554917","rc":[{"atb":[[350,0.7],[450,0.23]],"id":52385908},{"atb":[[19.5,13.18],[29,3.73]],"id":52385887},{"atb":[[11,10.45],[8.4,32.96]],"id":52385883},{"atb":[[9,30.48],[12.5,9.08]],"id":52385896},{"atb":[[390,0.62],[490,0.21]],"id":52385892},{"atb":[[550,0.44],[650,0.16]],"id":52385904},{"atb":[[21,5.22],[15.5,16.82]],"id":52385900},{"atb":[[7.4,38.1],[9.4,12.44]],"id":52385909},{"atb":[[3.7,90.33],[4.4,30.74]],"id":52385888},{"atb":[[13.5,8.36],[9.4,29.03]],"id":52385884},{"atb":[[550,0.44],[650,0.16]],"id":52385897},{"atb":[[550,0.44],[650,0.16]],"id":52385893},{"atb":[[20,5.5],[15,17.42]],"id":52385905},{"atb":[[140,1.75],[240,0.43]],"id":52385901},{"atb":[[17,6.53],[12,22.17]],"id":52385906},{"atb":[[140,1.75],[240,0.43]],"id":52385889},{"atb":[[8.6,13.75],[6.6,43.55]],"id":52385885},{"atb":[[550,0.44],[650,0.16]],"id":52385894},{"atb":[[550,0.44],[650,0.16]],"id":52385890},{"atb":[[8,14.93],[6,48.78]],"id":52385902},{"atb":[[19.5,5.65],[14.5,18.06]],"id":52385898},{"atb":[[18,14.34],[26,4.18]],"id":52385907},{"atb":[[9.6,28.36],[14,8.04]],"id":52385886},{"atb":[[130,0.81],[65,3.8]],"id":52385882},{"atb":[[40,2.67],[25,10.16]],"id":52385895},{"atb":[[550,0.44],[650,0.16]],"id":52385891},{"atb":[[9.6,28.36],[14,8.04]],"id":52385903},{"atb":[[9.8,27.71],[14.5,7.74]],"id":52385899}],"con":true,"img":false}]}
{"op":"mcm","clk":"11449386619","pt":1717308408677,"mc":[{"id":"1.229554917","rc":[{"atb":[[9.6,28.36],[14,8.04]],"id":52385912},{"atb":[[18,14.34],[26,4.18]],"id":52385920},{"atb":[[4.5,69.68],[5.5,23.22]],"id":52385916},{"atb":[[580,0.18],[480,0.5]],"id":52385929},{"atb":[[550,0.44],[650,0.16]],"id":52385925},{"atb":[[16.5,6.74],[11.5,23.22]],"id":52385937},{"atb":[[4.8,64.18],[5.8,21.77]],"id":52385933},{"atb":[[16.5,6.74],[11.5,23.22]],"id":52385913},{"atb":[[18,6.14],[13,20.32]],"id":52385921},{"atb":[[10,27.1],[15,7.46]],"id":52385917},{"atb":[[290,0.36],[190,1.29]],"id":52385926},{"atb":[[530,0.19],[430,0.57]],"id":52385922},{"atb":[[7.4,16.33],[5.7,51.89]],"id":52385934},{"atb":[[20,5.5],[15,17.42]],"id":52385930},{"atb":[[9,13.06],[7,40.65]],"id":52385910},{"atb":[[550,0.44],[650,0.16]],"id":52385918},{"atb":[[17,6.53],[12,22.17]],"id":52385914},{"atb":[[390,0.7],[490,0.21]],"id":52385927},{"atb":[[9.8,11.87],[7.8,35.86]],"id":52385923},{"atb":[[4.6,29.03],[3.8,87.1]],"id":52385935},{"atb":[[3.6,40.2],[3.1,116.14]],"id":52385931},{"atb":[[280,0.87],[380,0.27]],"id":52385911},{"atb":[[21,5.22],[15.5,16.82]],"id":52385919},{"atb":[[32,7.86],[55,1.93]],"id":52385915},{"atb":[[85,1.24],[44,5.67]],"id":52385928},{"atb":[[38,2.82],[24,10.6]],"id":52385924},{"atb":[[7.8,15.37],[5.9,49.77]],"id":52385936},{"atb":[[17,15.24],[24,4.54]],"id":52385932}],"con":true,"img":false}]}
{"op":"mcm","clk":"11449461747","pt":1717309501739,"mc":[{"id":"1.229554917","rc":[{"atb":[[290,0],[340,0],[390,0],[240,0]],"id":52385904},{"atb":[[130,0],[280,0],[180,0],[230,0]],"id":52385897},{"atb":[[34,0],[44,0],[27,0],[60,0]],"id":52385905},{"atb":[[270,0],[320,0],[370,0],[420,0]],"id":52385918},{"atb":[[65,0],[36,0],[46,0],[28,0]],"id":52385898}],"con":true,"img":false}]}
{"op":"mcm","clk":"11449461796","pt":1717309502418,"mc":[{"id":"1.229554917","rc":[{"atb":[[290,0.27],[340,0.15],[390,0.07],[240,0.44]],"id":52385904},{"atb":[[130,0.81],[280,0.09],[180,0.44],[230,0.23]],"id":52385897},{"atb":[[34,2.38],[44,1.22],[27,4.02],[60,0.44]],"id":52385905},{"atb":[[270,0.39],[320,0.25],[370,0.14],[420,0.06]],"id":52385918},{"atb":[[65,0.41],[36,2.24],[46,1.16],[28,3.88]],"id":52385898}],"con":true,"img":false}]}
{"op":"mcm","clk":"11449469363","pt":1717309610334,"mc":[{"id":"1.229554917","rc":[{"atb":[[75,0],[40,0],[50,0],[30,0]],"id":52385906}],"con":true,"img":false}]}
{"op":"mcm","clk":"11449469420","pt":1717309611008,"mc":[{"id":"1.229554917","rc":[{"atb":[[32,3.37],[80,0.33],[42,1.92],[55,0.97]],"id":52385906}],"con":true,"img":false}]}
{"op":"mcm","clk":"11449539689","pt":1717310612043,"mc":[{"id":"1.229554917","rc":[{"atb":[[65,0],[36,0],[90,0],[46,0]],"id":52385887},{"atb":[[32,0],[18,0],[21,0],[26,0]],"id":52385896},{"atb":[[40,0],[20,0],[25,0],[30,0]],"id":52385937},{"atb":[[6.8,0],[7.8,0],[5.9,0],[5.4,0]],"id":52385888},{"atb":[[32,0],[18,0],[21,0],[26,0]],"id":52385884},{"atb":[[260,0],[310,0],[160,0],[210,0]],"id":52385926},{"atb":[[170,0],[85,0],[220,0],[120,0]],"id":52385901},{"atb":[[32,0],[80,0],[42,0],[55,0]],"id":52385906},{"atb":[[280,0],[330,0],[380,0],[230,0]],"id":52385889},{"atb":[[590,0],[640,0],[690,0],[740,0]],"id":52385890},{"atb":[[8,0],[9,0],[10,0],[7,0]],"id":52385935},{"atb":[[160,0],[80,0],[110,0],[55,0]],"id":52385924},{"atb":[[34,0],[44,0],[22,0],[27,0]],"id":52385903}],"con":true,"img":false}]}
{"op":"mcm","clk":"11449539734","pt":1717310612767,"mc":[{"id":"1.229554917","rc":[{"atb":[[70,0.76],[38,2.83],[95,0.28],[48,1.67]],"id":52385887},{"atb":[[32,0.84],[18,6.15],[21,3.92],[26,2.09]],"id":52385896},{"atb":[[32,1.69],[42,0.64],[21,5.23],[26,3.14]],"id":52385937},{"atb":[[8,3.74],[5.5,23.25],[6,15.7],[7,8.72]],"id":52385888},{"atb":[[34,0.8],[18.5,5.98],[22,3.74],[27,2.01]],"id":52385884},{"atb":[[140,0.75],[290,0.45],[190,1.71],[240,0.22]],"id":52385926},{"atb":[[160,0.33],[80,1.32],[210,0.13],[110,0.72]],"id":52385901},{"atb":[[32,3.37],[80,0.33],[42,1.92],[55,0.97]],"id":52385906},{"atb":[[290,0.27],[340,0.15],[390,0.07],[240,0.88]],"id":52385889},{"atb":[[550,0.63],[600,0.13],[650,0.24],[700,0.04]],"id":52385890},{"atb":[[8,11.21],[9,6.54],[10,2.91],[7,17.44]],"id":52385935},{"atb":[[170,0.16],[85,0.94],[120,0.44],[60,1.77]],"id":52385924},{"atb":[[36,1.5],[46,0.58],[23,4.76],[28,2.91]],"id":52385903}],"con":true,"img":false}]}
{"op":"mcm","clk":"11449539881","pt":1717310615659,"mc":[{"id":"1.229554917","rc":[{"atb":[[32,0],[18,0],[21,0],[26,0]],"id":52385896},{"atb":[[32,0],[42,0],[21,0],[26,0]],"id":52385937},{"atb":[[140,0],[290,0.36],[190,1.29],[240,0]],"id":52385926},{"atb":[[32,0],[80,0],[42,0],[55,0]],"id":52385906},{"atb":[[8,0],[9,0],[10,0],[7,0]],"id":52385935},{"atb":[[170,0],[85,0],[120,0],[60,0]],"id":52385924}],"con":true,"img":false}]}
{"op":"mcm","clk":"11449539918","pt":1717310616375,"mc":[{"id":"1.229554917","rc":[{"atb":[[32,0.84],[18,6.15],[21,3.92],[26,2.09]],"id":52385896},{"atb":[[32,1.69],[42,0.64],[21,5.23],[26,3.14]],"id":52385937},{"atb":[[140,0.75],[290,0.45],[190,1.71],[240,0.22]],"id":52385926},{"atb":[[32,3.37],[80,0.33],[42,1.92],[55,0.97]],"id":52385906},{"atb":[[170,0.16],[85,0.94],[120,0.44],[60,1.77]],"id":52385924}],"con":true,"img":false}]}
{"op":"mcm","clk":"11449539926","pt":1717310616476,"mc":[{"id":"1.229554917","rc":[{"atb":[[8,11.21],[9,6.54],[10,2.91],[7,17.44]],"id":52385935}],"con":true,"img":false}]}
{"op":"mcm","clk":"11449541154","pt":1717310639823,"mc":[{"id":"1.229554917","rc":[{"atb":[[70,0],[38,0],[95,0],[48,0]],"id":52385887},{"atb":[[32,0],[42,0],[21,0],[26,0]],"id":52385937},{"atb":[[34,0],[18.5,0],[22,0],[27,0]],"id":52385884},{"atb":[[140,0],[290,0.36],[190,1.29],[240,0]],"id":52385926},{"atb":[[170,0],[85,0],[120,0],[60,0]],"id":52385924}],"con":true,"img":false}]}
{"op":"mcm","clk":"11449541197","pt":1717310640498,"mc":[{"id":"1.229554917","rc":[{"atb":[[65,0.82],[36,2.99],[90,0.29],[46,1.74]],"id":52385887},{"atb":[[40,0.67],[20,5.51],[25,3.27],[30,1.81]],"id":52385937},{"atb":[[32,0.84],[18,6.15],[21,3.92],[26,2.09]],"id":52385884},{"atb":[[260,0.2],[310,0.08],[160,0.66],[210,0.38]],"id":52385926},{"atb":[[160,0.16],[80,0.99],[110,0.48],[55,1.94]],"id":52385924}],"con":true,"img":false}]}
{"op":"mcm","clk":"11449544827","pt":1717310703363,"mc":[{"id":"1.229554917","rc":[{"atb":[[260,0],[310,0],[160,0],[210,0]],"id":52385926}],"con":true,"img":false}]}
{"op":"mcm","clk":"11449544835","pt":1717310703467,"mc":[{"id":"1.229554917","rc":[{"atb":[[34,0],[85,0],[44,0],[60,0]],"id":52385920},{"atb":[[17.5,0],[20,0],[25,0],[15,0]],"id":52385883},{"atb":[[290,0],[340,0],[390,0],[240,0]],"id":52385904},{"atb":[[6.4,0],[5.2,0],[5.7,0],[4.7,0]],"id":52385933},{"atb":[[130,0],[280,0],[180,0],[230,0]],"id":52385897},{"atb":[[34,0],[44,0],[27,0],[60,0]],"id":52385905},{"atb":[[17,0],[19.5,0],[12,0],[14.5,0]],"id":52385902},{"atb":[[65,0],[36,0],[46,0],[28,0]],"id":52385898},{"atb":[[34,0],[18.5,0],[22,0],[27,0]],"id":52385886},{"atb":[[5.6,0],[7.2,0],[6.2,0],[8.2,0]],"id":52385936}],"con":true,"img":false}]}
{"op":"mcm","clk":"11449544841","pt":1717310703570,"mc":[{"id":"1.229554917","rc":[{"atb":[[75,0],[40,0],[50,0],[30,0]],"id":52385907}],"con":true,"img":false}]}
{"op":"mcm","clk":"11449544864","pt":1717310704086,"mc":[{"id":"1.229554917","rc":[{"atb":[[140,0.75],[290,0.45],[190,1.71],[240,0.22]],"id":52385926}],"con":true,"img":false}]}
{"op":"mcm","clk":"11449544870","pt":1717310704191,"mc":[{"id":"1.229554917","rc":[{"atb":[[65,0.82],[36,2.99],[90,0.29],[46,1.74]],"id":52385920},{"atb":[[17.5,4.76],[20,2.75],[25,1.09],[15,7.48]],"id":52385883},{"atb":[[280,0.28],[330,0.16],[380,0.07],[230,0.46]],"id":52385904},{"atb":[[5.6,11.37],[5.1,19.14],[4.6,29.07],[6.2,5.03]],"id":52385933},{"atb":[[260,0.1],[160,0.49],[210,0.25],[110,0.96]],"id":52385897},{"atb":[[32,2.53],[42,1.28],[26,4.19],[55,0.49]],"id":52385905},{"atb":[[18,1.54],[10.5,11.01],[13,6.54],[15.5,3.61]],"id":52385902},{"atb":[[36,0.75],[19,5.81],[23,3.57],[28,1.94]],"id":52385886},{"atb":[[6.4,14.53],[7.4,8.18],[5.7,22.26],[8.4,3.54]],"id":52385936}],"con":true,"img":false}]}
{"op":"mcm","clk":"11449544879","pt":1717310704293,"mc":[{"id":"1.229554917","rc":[{"atb":[[34,2.38],[44,1.22],[27,4.02],[60,0.44]],"id":52385898},{"atb":[[32,3.37],[80,0.33],[42,1.92],[55,0.97]],"id":52385907}],"con":true,"img":false}]}
{"op":"mcm","clk":"11449546552","pt":1717310732937,"mc":[{"id":"1.229554917","rc":[{"atb":[[350,0],[450,0]],"id":52385908},{"atb":[[19.5,0],[29,0]],"id":52385887},{"atb":[[11,0],[8.4,0]],"id":52385883},{"atb":[[9,0],[12.5,0]],"id":52385896},{"atb":[[390,0],[490,0]],"id":52385892},{"atb":[[550,0],[650,0]],"id":52385904},{"atb":[[21,0],[15.5,0]],"id":52385900},{"atb":[[7.4,0],[9.4,0]],"id":52385909},{"atb":[[3.7,0],[4.4,0]],"id":52385888},{"atb":[[13.5,0],[9.4,0]],"id":52385884},{"atb":[[550,0],[650,0]],"id":52385897},{"atb":[[550,0],[650,0]],"id":52385893},{"atb":[[20,0],[15,0]],"id":52385905},{"atb":[[140,0],[240,0]],"id":52385901},{"atb":[[9,0],[7,0]],"id":52385910},{"atb":[[17,0],[12,0]],"id":52385906},{"atb":[[140,0],[240,0.44]],"id":52385889},{"atb":[[8.6,0],[6.6,0]],"id":52385885},{"atb":[[550,0],[650,0]],"id":52385894},{"atb":[[550,0.19],[650,0.08]],"id":52385890},{"atb":[[8,0],[6,0]],"id":52385902},{"atb":[[19.5,0],[14.5,0]],"id":52385898},{"atb":[[280,0],[380,0]],"id":52385911},{"atb":[[18,0],[26,0]],"id":52385907},{"atb":[[9.6,0],[14,0]],"id":52385886},{"atb":[[130,0],[65,0]],"id":52385882},{"atb":[[40,0],[25,0]],"id":52385895},{"atb":[[550,0],[650,0]],"id":52385891},{"atb":[[9.6,0],[14,0]],"id":52385903},{"atb":[[9.8,0],[14.5,0]],"id":52385899}],"con":true,"img":false}]}
{"op":"mcm","clk":"11449546559","pt":1717310733042,"mc":[{"id":"1.229554917","rc":[{"atb":[[9.6,0],[14,0]],"id":52385912},{"atb":[[18,0],[26,0]],"id":52385920},{"atb":[[4.5,0],[5.5,0]],"id":52385916},{"atb":[[580,0],[480,0]],"id":52385929},{"atb":[[550,0],[650,0]],"id":52385925},{"atb":[[16.5,0],[11.5,0]],"id":52385937},{"atb":[[4.8,0],[5.8,0]],"id":52385933},{"atb":[[16.5,0],[11.5,0]],"id":52385913},{"atb":[[18,0],[13,0]],"id":52385921},{"atb":[[10,0],[15,0]],"id":52385917},{"atb":[[290,0.09],[190,0.41]],"id":52385926},{"atb":[[530,0],[430,0]],"id":52385922},{"atb":[[7.4,0],[5.7,0]],"id":52385934},{"atb":[[20,0],[15,0]],"id":52385930},{"atb":[[550,0],[650,0]],"id":52385918},{"atb":[[17,0],[12,0]],"id":52385914},{"atb":[[390,0.07],[490,0]],"id":52385927},{"atb":[[9.8,0],[7.8,0]],"id":52385923},{"atb":[[4.6,0],[3.8,0]],"id":52385935},{"atb":[[3.6,0],[3.1,0]],"id":52385931},{"atb":[[21,0],[15.5,0]],"id":52385919},{"atb":[[32,0],[55,0]],"id":52385915},{"atb":[[85,0],[44,0]],"id":52385928},{"atb":[[38,0],[24,0]],"id":52385924},{"atb":[[7.8,0],[5.9,0]],"id":52385936},{"atb":[[17,0],[24,0]],"id":52385932}],"con":true,"img":false}]}
{"op":"mcm","clk":"11449548306","pt":1717310761953,"mc":[{"id":"1.229554917","rc":[{"atb":[[9.6,28.36],[14,8.04]],"id":52385912},{"atb":[[18.5,13.93],[27,4.01]],"id":52385920},{"atb":[[5.6,22.72],[4.6,67.75]],"id":52385916},{"atb":[[580,0.18],[480,0.5]],"id":52385929},{"atb":[[550,0.44],[650,0.16]],"id":52385925},{"atb":[[17,6.53],[12,22.17]],"id":52385937},{"atb":[[5.6,34.1],[4.6,96.82]],"id":52385933},{"atb":[[16.5,6.74],[11.5,23.22]],"id":52385913},{"atb":[[18,6.14],[13,20.32]],"id":52385921},{"atb":[[10,27.1],[15,7.46]],"id":52385917},{"atb":[[150,1.63],[250,0.41]],"id":52385926},{"atb":[[540,0.19],[440,0.55]],"id":52385922},{"atb":[[7.4,16.33],[5.7,51.89]],"id":52385934},{"atb":[[20,5.5],[15,17.42]],"id":52385930},{"atb":[[7.2,39.33],[9.2,12.74]],"id":52385910},{"atb":[[550,0.44],[650,0.16]],"id":52385918},{"atb":[[17,6.53],[12,22.17]],"id":52385914},{"atb":[[400,0.61],[500,0.2]],"id":52385927},{"atb":[[9.8,11.87],[7.8,35.86]],"id":52385923},{"atb":[[3.85,85.58],[4.7,28.25]],"id":52385935},{"atb":[[3.15,113.44],[3.65,39.44]],"id":52385931},{"atb":[[290,1.11],[390,0.34]],"id":52385911},{"atb":[[20,5.5],[15,17.42]],"id":52385919},{"atb":[[34,7.39],[60,1.77]],"id":52385915},{"atb":[[85,1.24],[44,5.67]],"id":52385928},{"atb":[[40,2.67],[25,10.16]],"id":52385924},{"atb":[[7.8,15.37],[5.9,49.77]],"id":52385936},{"atb":[[17,15.24],[24,4.54]],"id":52385932}],"con":true,"img":false}]}
{"op":"mcm","clk":"11449548317","pt":1717310762165,"mc":[{"id":"1.229554917","rc":[{"atb":[[350,0.7],[450,0.23]],"id":52385908},{"atb":[[20,12.83],[30,3.6]],"id":52385887},{"atb":[[10.5,11],[8.2,33.87]],"id":52385883},{"atb":[[8.6,32.09],[11.5,9.95]],"id":52385896},{"atb":[[400,0.61],[500,0.42]],"id":52385892},{"atb":[[550,0.44],[650,0.16]],"id":52385904},{"atb":[[20,5.5],[15,17.42]],"id":52385900},{"atb":[[7.4,38.1],[9.4,12.44]],"id":52385909},{"atb":[[4.6,29.03],[3.8,87.1]],"id":52385888},{"atb":[[13.5,8.36],[9.4,29.03]],"id":52385884},{"atb":[[550,0.44],[650,0.16]],"id":52385897},{"atb":[[550,0.44],[650,0.16]],"id":52385893},{"atb":[[19.5,5.65],[14.5,18.06]],"id":52385905},{"atb":[[200,0.52],[100,2.46]],"id":52385901},{"atb":[[17,6.53],[12,22.17]],"id":52385906},{"atb":[[260,0.4],[160,1.53]],"id":52385889},{"atb":[[6.8,42.05],[8.8,13.4]],"id":52385885},{"atb":[[550,0.44],[650,0.16]],"id":52385894},{"atb":[[550,0.63],[650,0.24]],"id":52385890},{"atb":[[5.8,50.81],[7.6,15.83]],"id":52385902},{"atb":[[19,5.8],[14,18.76]],"id":52385898},{"atb":[[18,14.34],[26,4.18]],"id":52385907},{"atb":[[9.6,28.36],[14,8.04]],"id":52385886},{"atb":[[140,0.75],[70,3.53]],"id":52385882},{"atb":[[42,2.54],[26,9.75]],"id":52385895},{"atb":[[550,0.44],[650,0.16]],"id":52385891},{"atb":[[9.8,27.71],[14.5,7.74]],"id":52385903},{"atb":[[9.6,28.36],[14,8.04]],"id":52385899}],"con":true,"img":false}]}
{"op":"mcm","clk":"11449550495","pt":1717310797136,"mc":[{"id":"1.229554917","rc":[{"atb":[[350,0],[450,0]],"id":52385908},{"atb":[[20,0],[30,0]],"id":52385887},{"atb":[[10.5,0],[8.2,0]],"id":52385883},{"atb":[[8.6,0],[11.5,0]],"id":52385896},{"atb":[[400,0],[500,0.21]],"id":52385892},{"atb":[[550,0],[650,0]],"id":52385904},{"atb":[[20,0],[15,0]],"id":52385900},{"atb":[[7.4,0],[9.4,0]],"id":52385909},{"atb":[[4.6,0],[3.8,0]],"id":52385888},{"atb":[[13.5,0],[9.4,0]],"id":52385884},{"atb":[[550,0],[650,0]],"id":52385897},{"atb":[[550,0],[650,0]],"id":52385893},{"atb":[[19.5,0],[14.5,0]],"id":52385905},{"atb":[[200,0],[100,0]],"id":52385901},{"atb":[[7.2,0],[9.2,0]],"id":52385910},{"atb":[[17,0],[12,0]],"id":52385906},{"atb":[[260,0],[160,0]],"id":52385889},{"atb":[[6.8,0],[8.8,0]],"id":52385885},{"atb":[[550,0],[650,0]],"id":52385894},{"atb":[[550,0.19],[650,0.08]],"id":52385890},{"atb":[[5.8,0],[7.6,0]],"id":52385902},{"atb":[[19,0],[14,0]],"id":52385898},{"atb":[[290,0.27],[390,0.07]],"id":52385911},{"atb":[[18,0],[26,0]],"id":52385907},{"atb":[[9.6,0],[14,0]],"id":52385886},{"atb":[[140,0],[70,0]],"id":52385882},{"atb":[[42,0],[26,0]],"id":52385895},{"atb":[[550,0],[650,0]],"id":52385891},{"atb":[[9.8,0],[14.5,0]],"id":52385903},{"atb":[[9.6,0],[14,0]],"id":52385899}],"con":true,"img":false}]}
{"op":"mcm","clk":"11449550504","pt":1717310797190,"mc":[{"id":"1.229554917","rc":[{"atb":[[9.6,0],[14,0]],"id":52385912},{"atb":[[18.5,0],[27,0]],"id":52385920},{"atb":[[5.6,0],[4.6,0]],"id":52385916},{"atb":[[580,0],[480,0]],"id":52385929},{"atb":[[550,0],[650,0]],"id":52385925},{"atb":[[17,0],[12,0]],"id":52385937},{"atb":[[5.6,11.37],[4.6,29.07]],"id":52385933},{"atb":[[16.5,0],[11.5,0]],"id":52385913},{"atb":[[18,0],[13,0]],"id":52385921},{"atb":[[10,0],[15,0]],"id":52385917},{"atb":[[150,0],[250,0]],"id":52385926},{"atb":[[540,0],[440,0]],"id":52385922},{"atb":[[7.4,0],[5.7,0]],"id":52385934},{"atb":[[20,0],[15,0]],"id":52385930},{"atb":[[550,0],[650,0]],"id":52385918},{"atb":[[17,0],[12,0]],"id":52385914},{"atb":[[400,0],[500,0]],"id":52385927},{"atb":[[9.8,0],[7.8,0]],"id":52385923},{"atb":[[3.85,0],[4.7,0]],"id":52385935},{"atb":[[3.15,0],[3.65,0]],"id":52385931},{"atb":[[20,0],[15,0]],"id":52385919},{"atb":[[34,0],[60,0]],"id":52385915},{"atb":[[85,0],[44,0]],"id":52385928},{"atb":[[40,0],[25,0]],"id":52385924},{"atb":[[7.8,0],[5.9,0]],"id":52385936},{"atb":[[17,0],[24,0]],"id":52385932}],"con":true,"img":false}]}
{"op":"mcm","clk":"11449553110","pt":1717310844499,"mc":[{"id":"1.229554917","rc":[{"atb":[[9.6,28.36],[14,8.04]],"id":52385912},{"atb":[[18.5,13.93],[27,4.01]],"id":52385920},{"atb":[[5.6,22.72],[4.6,67.75]],"id":52385916},{"atb":[[590,0.17],[490,0.49]],"id":52385929},{"atb":[[550,0.44],[650,0.16]],"id":52385925},{"atb":[[17,6.53],[12,22.17]],"id":52385937},{"atb":[[5.6,34.1],[4.6,96.82]],"id":52385933},{"atb":[[16.5,6.74],[11.5,23.22]],"id":52385913},{"atb":[[18,6.14],[13,20.32]],"id":52385921},{"atb":[[10,27.1],[15,7.46]],"id":52385917},{"atb":[[150,1.63],[250,0.41]],"id":52385926},{"atb":[[540,0.19],[440,0.55]],"id":52385922},{"atb":[[7.4,16.33],[5.7,51.89]],"id":52385934},{"atb":[[20,5.5],[15,17.42]],"id":52385930},{"atb":[[7.2,39.33],[9.2,12.74]],"id":52385910},{"atb":[[550,0.44],[650,0.16]],"id":52385918},{"atb":[[17,6.53],[12,22.17]],"id":52385914},{"atb":[[400,0.61],[500,0.2]],"id":52385927},{"atb":[[9.8,11.87],[7.8,35.86]],"id":52385923},{"atb":[[3.85,85.58],[4.7,28.25]],"id":52385935},{"atb":[[3.15,113.44],[3.65,39.44]],"id":52385931},{"atb":[[300,0.35],[200,1.22]],"id":52385911},{"atb":[[20,5.5],[15,17.42]],"id":52385919},{"atb":[[34,7.39],[60,1.77]],"id":52385915},{"atb":[[85,1.24],[44,5.67]],"id":52385928},{"atb":[[40,2.67],[25,10.16]],"id":52385924},{"atb":[[7.8,15.37],[5.9,49.77]],"id":52385936},{"atb":[[16,16.26],[22,4.97]],"id":52385932}],"con":true,"img":false}]}
{"op":"mcm","clk":"11449553123","pt":1717310844656,"mc":[{"id":"1.229554917","rc":[{"atb":[[360,0.68],[460,0.23]],"id":52385908},{"atb":[[20,12.83],[30,3.6]],"id":52385887},{"atb":[[10.5,11],[8.2,33.87]],"id":52385883},{"atb":[[8.6,32.09],[11.5,9.95]],"id":52385896},{"atb":[[300,0.81],[400,0.26]],"id":52385892},{"atb":[[550,0.44],[650,0.16]],"id":52385904},{"atb":[[20,5.5],[15,17.42]],"id":52385900},{"atb":[[7.4,38.1],[9.4,12.44]],"id":52385909},{"atb":[[4.6,29.03],[3.8,87.1]],"id":52385888},{"atb":[[13.5,8.36],[9.4,29.03]],"id":52385884},{"atb":[[520,0.47],[620,0.16]],"id":52385897},{"atb":[[550,0.44],[650,0.16]],"id":52385893},{"atb":[[19.5,5.65],[14.5,18.06]],"id":52385905},{"atb":[[200,0.52],[100,2.46]],"id":52385901},{"atb":[[17,6.53],[12,22.17]],"id":52385906},{"atb":[[190,0.55],[95,2.59]],"id":52385889},{"atb":[[6.8,42.05],[8.8,13.4]],"id":52385885},{"atb":[[550,0.44],[650,0.16]],"id":52385894},{"atb":[[550,0.63],[650,0.24]],"id":52385890},{"atb":[[5.8,50.81],[7.6,15.83]],"id":52385902},{"atb":[[19,5.8],[14,18.76]],"id":52385898},{"atb":[[18,14.34],[26,4.18]],"id":52385907},{"atb":[[9.6,28.36],[14,8.04]],"id":52385886},{"atb":[[95,1.11],[48,5.18]],"id":52385882},{"atb":[[34,3.16],[22,11.61]],"id":52385895},{"atb":[[550,0.44],[650,0.16]],"id":52385891},{"atb":[[9.8,27.71],[14.5,7.74]],"id":52385903},{"atb":[[9.6,28.36],[14,8.04]],"id":52385899}],"con":true,"img":false}]}
{"op":"mcm","clk":"11449555713","pt":1717310889835,"mc":[{"id":"1.229554917","rc":[{"atb":[[800,0],[850,0],[900,0],[950,0]],"id":52385891}],"con":true,"img":false}]}
{"op":"mcm","clk":"11449555720","pt":1717310889941,"mc":[{"id":"1.229554917","rc":[{"atb":[[17.5,0],[20,0],[25,0],[15,0]],"id":52385883}],"con":true,"img":false}]}
{"op":"mcm","clk":"11449555749","pt":1717310890551,"mc":[{"id":"1.229554917","rc":[{"atb":[[810,0.13],[860,0.09],[910,0.06],[960,0.03]],"id":52385891}],"con":true,"img":false}]}
{"op":"mcm","clk":"11449555766","pt":1717310890914,"mc":[{"id":"1.229554917","rc":[{"atb":[[17,4.9],[19.5,2.83],[24,1.14],[14.5,7.75]],"id":52385883}],"con":true,"img":false}]}
{"op":"mcm","clk":"11449571725","pt":1717311187483,"mc":[{"id":"1.229554917","rc":[{"atb":[[32,0],[42,0],[26,0],[55,0]],"id":52385912},{"atb":[[550,0],[600,0],[650,0],[500,0]],"id":52385892},{"atb":[[34,0],[85,0],[44,0],[60,0]],"id":52385921},{"atb":[[40,0],[50,0],[25,0],[30,0]],"id":52385917},{"atb":[[32,0],[80,0],[42,0],[55,0]],"id":52385906},{"atb":[[75,0],[40,0],[50,0],[30,0]],"id":52385914},{"atb":[[550,0.44],[600,0],[650,0.16],[700,0]],"id":52385890},{"atb":[[17,0],[19.5,0],[24,0],[29,0]],"id":52385923},{"atb":[[8,0],[9,0],[10,0],[7,0]],"id":52385935},{"atb":[[290,0],[340,0],[390,0],[240,0]],"id":52385911}],"con":true,"img":false}]}
{"op":"mcm","clk":"11449571764","pt":1717311188205,"mc":[{"id":"1.229554917","rc":[{"atb":[[40,1.34],[50,0.53],[25,4.36],[30,2.71]],"id":52385912},{"atb":[[530,0.1],[580,0.05],[430,0.25],[480,0.16]],"id":52385892},{"atb":[[70,0.76],[38,2.83],[95,0.28],[48,1.67]],"id":52385921},{"atb":[[75,0.36],[40,2.01],[50,1.07],[30,3.61]],"id":52385906},{"atb":[[32,3.37],[80,0.33],[42,1.92],[55,0.97]],"id":52385914},{"atb":[[560,0.09],[610,0.04],[460,0.23],[510,0.15]],"id":52385890},{"atb":[[32,0.84],[18,6.15],[21,3.92],[26,2.09]],"id":52385923},{"atb":[[6.8,18.04],[9.8,2.97],[8.8,6.71],[7.8,11.54]],"id":52385935},{"atb":[[260,0.3],[310,0.17],[360,0.07],[210,0.5]],"id":52385911}],"con":true,"img":false}]}
{"op":"mcm","clk":"11449571788","pt":1717311188509,"mc":[{"id":"1.229554917","rc":[{"atb":[[32,2.53],[42,1.28],[26,4.19],[55,0.49]],"id":52385917}],"con":true,"img":false}]}
{"op":"mcm","clk":"11449607984","pt":1717311840180,"mc":[{"id":"1.229554917","rc":[{"atb":[[65,0],[36,0],[90,0],[46,0]],"id":52385887},{"atb":[[32,0],[18,0],[21,0],[26,0]],"id":52385884},{"atb":[[160,0],[80,0],[110,0],[55,0]],"id":52385924}],"con":true,"img":false}]}
{"op":"mcm","clk":"11449608025","pt":1717311840908,"mc":[{"id":"1.229554917","rc":[{"atb":[[70,0.76],[38,2.83],[95,0.28],[48,1.67]],"id":52385887},{"atb":[[34,0.8],[18.5,5.98],[22,3.74],[27,2.01]],"id":52385884},{"atb":[[170,0.16],[85,0.94],[120,0.44],[60,1.77]],"id":52385924}],"con":true,"img":false}]}
{"op":"mcm","clk":"11449609366","pt":1717311864602,"mc":[{"id":"1.229554917","rc":[{"atb":[[360,0],[460,0]],"id":52385908},{"atb":[[20,0],[30,0]],"id":52385887},{"atb":[[10.5,0],[8.2,0]],"id":52385883},{"atb":[[8.6,0],[11.5,0]],"id":52385896},{"atb":[[300,0],[400,0]],"id":52385892},{"atb":[[550,0],[650,0]],"id":52385904},{"atb":[[20,0],[15,0]],"id":52385900},{"atb":[[7.4,0],[9.4,0]],"id":52385909},{"atb":[[4.6,0],[3.8,0]],"id":52385888},{"atb":[[13.5,0],[9.4,0]],"id":52385884},{"atb":[[520,0],[620,0]],"id":52385897},{"atb":[[550,0],[650,0]],"id":52385893},{"atb":[[19.5,0],[14.5,0]],"id":52385905},{"atb":[[200,0],[100,0]],"id":52385901},{"atb":[[7.2,0],[9.2,0]],"id":52385910},{"atb":[[17,0],[12,0]],"id":52385906},{"atb":[[190,0],[95,0]],"id":52385889},{"atb":[[6.8,0],[8.8,0]],"id":52385885},{"atb":[[550,0],[650,0]],"id":52385894},{"atb":[[550,0],[650,0]],"id":52385890},{"atb":[[5.8,0],[7.6,0]],"id":52385902},{"atb":[[19,0],[14,0]],"id":52385898},{"atb":[[300,0],[200,0]],"id":52385911},{"atb":[[18,0],[26,0]],"id":52385907},{"atb":[[9.6,0],[14,0]],"id":52385886},{"atb":[[95,0],[48,0]],"id":52385882},{"atb":[[34,0],[22,0]],"id":52385895},{"atb":[[550,0],[650,0]],"id":52385891},{"atb":[[9.8,0],[14.5,0]],"id":52385903},{"atb":[[9.6,0],[14,0]],"id":52385899}],"con":true,"img":false}]}
{"op":"mcm","clk":"11449609371","pt":1717311864736,"mc":[{"id":"1.229554917","rc":[{"atb":[[9.6,0],[14,0]],"id":52385912},{"atb":[[18.5,0],[27,0]],"id":52385920},{"atb":[[5.6,0],[4.6,0]],"id":52385916},{"atb":[[590,0],[490,0]],"id":52385929},{"atb":[[550,0],[650,0]],"id":52385925},{"atb":[[17,0],[12,0]],"id":52385937},{"atb":[[5.6,11.37],[4.6,29.07]],"id":52385933},{"atb":[[16.5,0],[11.5,0]],"id":52385913},{"atb":[[18,0],[13,0]],"id":52385921},{"atb":[[10,0],[15,0]],"id":52385917},{"atb":[[150,0],[250,0]],"id":52385926},{"atb":[[540,0],[440,0]],"id":52385922},{"atb":[[7.4,0],[5.7,0]],"id":52385934},{"atb":[[20,0],[15,0]],"id":52385930},{"atb":[[550,0],[650,0]],"id":52385918},{"atb":[[17,0],[12,0]],"id":52385914},{"atb":[[400,0],[500,0]],"id":52385927},{"atb":[[9.8,0],[7.8,0]],"id":52385923},{"atb":[[3.85,0],[4.7,0]],"id":52385935},{"atb":[[3.15,0],[3.65,0]],"id":52385931},{"atb":[[20,0],[15,0]],"id":52385919},{"atb":[[34,0],[60,0]],"id":52385915},{"atb":[[85,0],[44,0]],"id":52385928},{"atb":[[40,0],[25,0]],"id":52385924},{"atb":[[7.8,0],[5.9,0]],"id":52385936},{"atb":[[16,0],[22,0]],"id":52385932}],"con":true,"img":false}]}
{"op":"mcm","clk":"11449610115","pt":1717311877557,"mc":[{"id":"1.229554917","rc":[{"atb":[[360,0.68],[460,0.23]],"id":52385908},{"atb":[[20,12.83],[30,3.6]],"id":52385887},{"atb":[[10.5,11],[8.2,33.87]],"id":52385883},{"atb":[[8.6,32.09],[11.5,9.95]],"id":52385896},{"atb":[[300,0.81],[400,0.26]],"id":52385892},{"atb":[[550,0.44],[650,0.16]],"id":52385904},{"atb":[[20,5.5],[15,17.42]],"id":52385900},{"atb":[[7.4,38.1],[9.4,12.44]],"id":52385909},{"atb":[[4.6,29.03],[3.8,87.1]],"id":52385888},{"atb":[[13.5,8.36],[9.4,29.03]],"id":52385884},{"atb":[[520,0.47],[620,0.16]],"id":52385897},{"atb":[[550,0.44],[650,0.16]],"id":52385893},{"atb":[[19.5,5.65],[14.5,18.06]],"id":52385905},{"atb":[[200,0.52],[100,2.46]],"id":52385901},{"atb":[[17,6.53],[12,22.17]],"id":52385906},{"atb":[[190,0.55],[95,2.59]],"id":52385889},{"atb":[[6.8,42.05],[8.8,13.4]],"id":52385885},{"atb":[[550,0.44],[650,0.16]],"id":52385894},{"atb":[[550,0.44],[650,0.16]],"id":52385890},{"atb":[[5.8,50.81],[7.6,15.83]],"id":52385902},{"atb":[[19,5.8],[14,18.76]],"id":52385898},{"atb":[[18,14.34],[26,4.18]],"id":52385907},{"atb":[[9.6,28.36],[14,8.04]],"id":52385886},{"atb":[[95,1.11],[48,5.18]],"id":52385882},{"atb":[[34,3.16],[22,11.61]],"id":52385895},{"atb":[[550,0.44],[650,0.16]],"id":52385891},{"atb":[[9.8,27.71],[14.5,7.74]],"id":52385903},{"atb":[[9.6,28.36],[14,8.04]],"id":52385899}],"con":true,"img":false}]}
{"op":"mcm","clk":"11449610132","pt":1717311877862,"mc":[{"id":"1.229554917","rc":[{"atb":[[9.6,28.36],[14,8.04]],"id":52385912},{"atb":[[18.5,13.93],[27,4.01]],"id":52385920},{"atb":[[5.6,22.72],[4.6,67.75]],"id":52385916},{"atb":[[590,0.17],[490,0.49]],"id":52385929},{"atb":[[550,0.44],[650,0.16]],"id":52385925},{"atb":[[17,6.53],[12,22.17]],"id":52385937},{"atb":[[5.6,34.1],[4.6,96.82]],"id":52385933},{"atb":[[16.5,6.74],[11.5,23.22]],"id":52385913},{"atb":[[18,6.14],[13,20.32]],"id":52385921},{"atb":[[10,27.1],[15,7.46]],"id":52385917},{"atb":[[150,1.63],[250,0.41]],"id":52385926},{"atb":[[540,0.19],[440,0.55]],"id":52385922},{"atb":[[7.4,16.33],[5.7,51.89]],"id":52385934},{"atb":[[20,5.5],[15,17.42]],"id":52385930},{"atb":[[7.2,39.33],[9.2,12.74]],"id":52385910},{"atb":[[550,0.44],[650,0.16]],"id":52385918},{"atb":[[17,6.53],[12,22.17]],"id":52385914},{"atb":[[400,0.61],[500,0.2]],"id":52385927},{"atb":[[9.8,11.87],[7.8,35.86]],"id":52385923},{"atb":[[3.85,85.58],[4.7,28.25]],"id":52385935},{"atb":[[3.15,113.44],[3.65,39.44]],"id":52385931},{"atb":[[300,0.35],[200,1.22]],"id":52385911},{"atb":[[20,5.5],[15,17.42]],"id":52385919},{"atb":[[34,7.39],[60,1.77]],"id":52385915},{"atb":[[85,1.24],[44,5.67]],"id":52385928},{"atb":[[40,2.67],[25,10.16]],"id":52385924},{"atb":[[7.8,15.37],[5.9,49.77]],"id":52385936},{"atb":[[16,16.26],[22,4.97]],"id":52385932}],"con":true,"img":false}]}
{"op":"mcm","clk":"11449611584","pt":1717311905002,"mc":[{"id":"1.229554917","rc":[{"atb":[[32,0],[80,0],[42,0],[55,0]],"id":52385907}],"con":true,"img":false}]}
{"op":"mcm","clk":"11449611633","pt":1717311905686,"mc":[{"id":"1.229554917","rc":[{"atb":[[32,3.37],[80,0.33],[42,1.92],[55,0.97]],"id":52385907}],"con":true,"img":false}]}
{"op":"mcm","clk":"11449614858","pt":1717311962349,"mc":[{"id":"1.229554917","rc":[{"atb":[[360,0],[460,0]],"id":52385908},{"atb":[[20,0],[30,0]],"id":52385887},{"atb":[[10.5,0],[8.2,0]],"id":52385883},{"atb":[[8.6,0],[11.5,0]],"id":52385896},{"atb":[[300,0],[400,0]],"id":52385892},{"atb":[[550,0],[650,0]],"id":52385904},{"atb":[[20,0],[15,0]],"id":52385900},{"atb":[[7.4,0],[9.4,0]],"id":52385909},{"atb":[[4.6,0],[3.8,0]],"id":52385888},{"atb":[[13.5,0],[9.4,0]],"id":52385884},{"atb":[[520,0],[620,0]],"id":52385897},{"atb":[[550,0],[650,0]],"id":52385893},{"atb":[[19.5,0],[14.5,0]],"id":52385905},{"atb":[[200,0],[100,0]],"id":52385901},{"atb":[[7.2,0],[9.2,0]],"id":52385910},{"atb":[[17,0],[12,0]],"id":52385906},{"atb":[[190,0],[95,0]],"id":52385889},{"atb":[[6.8,0],[8.8,0]],"id":52385885},{"atb":[[550,0],[650,0]],"id":52385894},{"atb":[[550,0],[650,0]],"id":52385890},{"atb":[[5.8,0],[7.6,0]],"id":52385902},{"atb":[[19,0],[14,0]],"id":52385898},{"atb":[[300,0],[200,0]],"id":52385911},{"atb":[[18,0],[26,0]],"id":52385907},{"atb":[[9.6,0],[14,0]],"id":52385886},{"atb":[[95,0],[48,0]],"id":52385882},{"atb":[[34,0],[22,0]],"id":52385895},{"atb":[[550,0],[650,0]],"id":52385891},{"atb":[[9.8,0],[14.5,0]],"id":52385903},{"atb":[[9.6,0],[14,0]],"id":52385899}],"con":true,"img":false}]}
{"op":"mcm","clk":"11449614862","pt":1717311962450,"mc":[{"id":"1.229554917","rc":[{"atb":[[9.6,0],[14,0]],"id":52385912},{"atb":[[18.5,0],[27,0]],"id":52385920},{"atb":[[5.6,0],[4.6,0]],"id":52385916},{"atb":[[590,0],[490,0]],"id":52385929},{"atb":[[550,0],[650,0]],"id":52385925},{"atb":[[17,0],[12,0]],"id":52385937},{"atb":[[5.6,11.37],[4.6,29.07]],"id":52385933},{"atb":[[16.5,0],[11.5,0]],"id":52385913},{"atb":[[18,0],[13,0]],"id":52385921},{"atb":[[10,0],[15,0]],"id":52385917},{"atb":[[150,0],[250,0]],"id":52385926},{"atb":[[540,0],[440,0]],"id":52385922},{"atb":[[7.4,0],[5.7,0]],"id":52385934},{"atb":[[20,0],[15,0]],"id":52385930},{"atb":[[550,0],[650,0]],"id":52385918},{"atb":[[17,0],[12,0]],"id":52385914},{"atb":[[400,0],[500,0]],"id":52385927},{"atb":[[9.8,0],[7.8,0]],"id":52385923},{"atb":[[3.85,0],[4.7,0]],"id":52385935},{"atb":[[3.15,0],[3.65,0]],"id":52385931},{"atb":[[20,0],[15,0]],"id":52385919},{"atb":[[34,0],[60,0]],"id":52385915},{"atb":[[85,0],[44,0]],"id":52385928},{"atb":[[40,0],[25,0]],"id":52385924},{"atb":[[7.8,0],[5.9,0]],"id":52385936},{"atb":[[16,0],[22,0]],"id":52385932}],"con":true,"img":false}]}
{"op":"mcm","clk":"11449616056","pt":1717311986580,"mc":[{"id":"1.229554917","rc":[{"atb":[[9.6,28.36],[14,8.04]],"id":52385912},{"atb":[[18.5,13.93],[27,4.01]],"id":52385920},{"atb":[[5.6,22.72],[4.6,67.75]],"id":52385916},{"atb":[[590,0.17],[490,0.49]],"id":52385929},{"atb":[[550,0.44],[650,0.16]],"id":52385925},{"atb":[[17,6.53],[12,22.17]],"id":52385937},{"atb":[[5.6,34.1],[4.6,96.82]],"id":52385933},{"atb":[[16.5,6.74],[11.5,23.22]],"id":52385913},{"atb":[[18,6.14],[13,20.32]],"id":52385921},{"atb":[[10,27.1],[15,7.46]],"id":52385917},{"atb":[[150,1.63],[250,0.41]],"id":52385926},{"atb":[[540,0.19],[440,0.55]],"id":52385922},{"atb":[[7.4,16.33],[5.7,51.89]],"id":52385934},{"atb":[[20,5.5],[15,17.42]],"id":52385930},{"atb":[[7.2,39.33],[9.2,12.74]],"id":52385910},{"atb":[[550,0.44],[650,0.16]],"id":52385918},{"atb":[[17,6.53],[12,22.17]],"id":52385914},{"atb":[[400,0.61],[500,0.2]],"id":52385927},{"atb":[[9.8,11.87],[7.8,35.86]],"id":52385923},{"atb":[[3.85,85.58],[4.7,28.25]],"id":52385935},{"atb":[[3.15,113.44],[3.65,39.44]],"id":52385931},{"atb":[[300,0.35],[200,1.22]],"id":52385911},{"atb":[[20,5.5],[15,17.42]],"id":52385919},{"atb":[[34,7.39],[60,1.77]],"id":52385915},{"atb":[[85,1.24],[44,5.67]],"id":52385928},{"atb":[[40,2.67],[25,10.16]],"id":52385924},{"atb":[[7.8,15.37],[5.9,49.77]],"id":52385936},{"atb":[[16,16.26],[22,4.97]],"id":52385932}],"con":true,"img":false}]}
{"op":"mcm","clk":"11449616064","pt":1717311986688,"mc":[{"id":"1.229554917","rc":[{"atb":[[360,0.68],[460,0.23]],"id":52385908},{"atb":[[20,12.83],[30,3.6]],"id":52385887},{"atb":[[10.5,11],[8.2,33.87]],"id":52385883},{"atb":[[8.6,32.09],[11.5,9.95]],"id":52385896},{"atb":[[300,0.81],[400,0.26]],"id":52385892},{"atb":[[550,0.44],[650,0.16]],"id":52385904},{"atb":[[20,5.5],[15,17.42]],"id":52385900},{"atb":[[7.4,38.1],[9.4,12.44]],"id":52385909},{"atb":[[4.6,29.03],[3.8,87.1]],"id":52385888},{"atb":[[13.5,8.36],[9.4,29.03]],"id":52385884},{"atb":[[520,0.47],[620,0.16]],"id":52385897},{"atb":[[550,0.44],[650,0.16]],"id":52385893},{"atb":[[19.5,5.65],[14.5,18.06]],"id":52385905},{"atb":[[200,0.52],[100,2.46]],"id":52385901},{"atb":[[17,6.53],[12,22.17]],"id":52385906},{"atb":[[190,0.55],[95,2.59]],"id":52385889},{"atb":[[6.8,42.05],[8.8,13.4]],"id":52385885},{"atb":[[550,0.44],[650,0.16]],"id":52385894},{"atb":[[550,0.44],[650,0.16]],"id":52385890},{"atb":[[5.8,50.81],[7.6,15.83]],"id":52385902},{"atb":[[19,5.8],[14,18.76]],"id":52385898},{"atb":[[18,14.34],[26,4.18]],"id":52385907},{"atb":[[9.6,28.36],[14,8.04]],"id":52385886},{"atb":[[95,1.11],[48,5.18]],"id":52385882},{"atb":[[34,3.16],[22,11.61]],"id":52385895},{"atb":[[550,0.44],[650,0.16]],"id":52385891},{"atb":[[9.8,27.71],[14.5,7.74]],"id":52385903},{"atb":[[9.6,28.36],[14,8.04]],"id":52385899}],"con":true,"img":false}]}
{"op":"mcm","clk":"11449620095","pt":1717312065598,"mc":[{"id":"1.229554917","rc":[{"atb":[[17,0],[19.5,0]],"id":52385883}],"con":true,"img":false}]}
{"op":"mcm","clk":"11449620102","pt":1717312065696,"mc":[{"id":"1.229554917","rc":[{"atb":[[24,0],[14.5,0]],"id":52385883}],"con":true,"img":false}]}
{"op":"mcm","clk":"11449620137","pt":1717312066269,"mc":[{"id":"1.229554917","rc":[{"atb":[[17.5,4.76],[20,2.75]],"id":52385883}],"con":true,"img":false}]}
{"op":"mcm","clk":"11449620142","pt":1717312066371,"mc":[{"id":"1.229554917","rc":[{"atb":[[25,1.09],[15,7.48]],"id":52385883}],"con":true,"img":false}]}
{"op":"mcm","clk":"11449620519","pt":1717312074382,"mc":[{"id":"1.229554917","rc":[{"atb":[[65,0],[36,0],[90,0],[46,0]],"id":52385920},{"atb":[[280,0],[330,0],[380,0],[230,0]],"id":52385904},{"atb":[[260,0],[160,0],[210,0],[110,0]],"id":52385897},{"atb":[[6.8,0],[8.8,0],[7.8,0],[5.9,0]],"id":52385934},{"atb":[[32,0],[42,0],[26,0],[55,0]],"id":52385905},{"atb":[[65,0],[36,0],[46,0],[28,0]],"id":52385919}],"con":true,"img":false}]}
{"op":"mcm","clk":"11449620551","pt":1717312075108,"mc":[{"id":"1.229554917","rc":[{"atb":[[70,0.76],[38,2.83],[95,0.28],[48,1.67]],"id":52385920},{"atb":[[290,0.27],[340,0.15],[390,0.07],[240,0.44]],"id":52385904},{"atb":[[270,0.1],[170,0.47],[220,0.24],[120,0.88]],"id":52385897},{"atb":[[8.6,3.44],[5.8,21.8],[7.6,7.93],[6.6,14.02]],"id":52385934},{"atb":[[34,2.38],[44,1.22],[27,4.02],[60,0.44]],"id":52385905},{"atb":[[70,0.38],[38,2.12],[48,1.11],[29,3.74]],"id":52385919}],"con":true,"img":false}]}
{"op":"mcm","clk":"11449648545","pt":1717312783254,"mc":[{"id":"1.229554917","rc":[{"atb":[[40,0],[50,0],[25,0],[30,0]],"id":52385912},{"atb":[[70,0],[38,0],[95,0],[48,0]],"id":52385887},{"atb":[[17.5,0],[20,0],[25,0],[15,0]],"id":52385883},{"atb":[[70,0],[38,0],[48,0],[29,0]],"id":52385913},{"atb":[[70,0],[38,0],[95,0],[48,0]],"id":52385921},{"atb":[[75,0],[40,0],[50,0],[30,0]],"id":52385906},{"atb":[[32,0],[80,0],[42,0],[55,0]],"id":52385914},{"atb":[[170,0],[85,0],[120,0],[60,0]],"id":52385924}],"con":true,"img":false}]}
{"op":"mcm","clk":"11449648548","pt":1717312783308,"mc":[{"id":"1.229554917","rc":[{"atb":[[16.5,0],[9.6,0],[11.5,0],[14,0]],"id":52385916}],"con":true,"img":false}]}
{"op":"mcm","clk":"11449648572","pt":1717312783926,"mc":[{"id":"1.229554917","rc":[{"atb":[[32,2.53],[42,1.28],[26,4.19],[55,0.49]],"id":52385912},{"atb":[[65,0.82],[36,2.99],[90,0.29],[46,1.74]],"id":52385887},{"atb":[[17,4.9],[19.5,2.83],[24,1.14],[14.5,7.75]],"id":52385883},{"atb":[[75,0.36],[40,2.01],[50,1.07],[30,3.61]],"id":52385913},{"atb":[[75,0.71],[40,2.68],[100,0.27],[50,1.6]],"id":52385921},{"atb":[[32,3.37],[80,0.33],[42,1.92],[55,0.97]],"id":52385906},{"atb":[[34,3.17],[85,0.31],[44,1.83],[60,0.88]],"id":52385914},{"atb":[[160,0.16],[80,0.99],[110,0.48],[55,1.94]],"id":52385924}],"con":true,"img":false}]}
{"op":"mcm","clk":"11449648576","pt":1717312784028,"mc":[{"id":"1.229554917","rc":[{"atb":[[18,1.54],[10.5,11.01],[13,6.54],[15.5,3.61]],"id":52385916}],"con":true,"img":false}]}
{"op":"mcm","clk":"11449648599","pt":1717312784745,"mc":[{"id":"1.229554917","rc":[{"atb":[[18,0],[10.5,0],[13,0],[15.5,0]],"id":52385916}],"con":true,"img":false}]}
{"op":"mcm","clk":"11449648619","pt":1717312785418,"mc":[{"id":"1.229554917","rc":[{"atb":[[16.5,1.69],[9.6,12.17],[11.5,7.48],[14,4.02]],"id":52385916}],"con":true,"img":false}]}
{"op":"mcm","clk":"11449648784","pt":1717312789657,"mc":[{"id":"1.229554917","rc":[{"atb":[[32,0],[42,0],[26,0],[55,0]],"id":52385912},{"atb":[[75,0],[40,0],[50,0],[30,0]],"id":52385913},{"atb":[[75,0],[40,0],[100,0],[50,0]],"id":52385921},{"atb":[[32,0],[80,0],[42,0],[55,0]],"id":52385906},{"atb":[[34,0],[85,0],[44,0],[60,0]],"id":52385914}],"con":true,"img":false}]}
{"op":"mcm","clk":"11449648810","pt":1717312790326,"mc":[{"id":"1.229554917","rc":[{"atb":[[40,1.34],[50,0.53],[25,4.36],[30,2.71]],"id":52385912},{"atb":[[38,2.12],[48,1.11]],"id":52385913},{"atb":[[70,0.76],[38,2.83],[95,0.28],[48,1.67]],"id":52385921},{"atb":[[75,0.36],[40,2.01],[50,1.07]],"id":52385906},{"atb":[[80,0.33],[42,1.92],[55,0.97]],"id":52385914}],"con":true,"img":false}]}
{"op":"mcm","clk":"11449648816","pt":1717312790425,"mc":[{"id":"1.229554917","rc":[{"atb":[[70,0.38],[29,3.74]],"id":52385913},{"atb":[[30,3.61]],"id":52385906},{"atb":[[32,3.37]],"id":52385914}],"con":true,"img":false}]}
{"op":"mcm","clk":"11449655971","pt":1717312956187,"mc":[{"id":"1.229554917","rc":[{"atb":[[360,0],[460,0]],"id":52385908},{"atb":[[20,0],[30,0]],"id":52385887},{"atb":[[10.5,0],[8.2,0]],"id":52385883},{"atb":[[8.6,0],[11.5,0]],"id":52385896},{"atb":[[300,0],[400,0]],"id":52385892},{"atb":[[550,0],[650,0]],"id":52385904},{"atb":[[20,0],[15,0]],"id":52385900},{"atb":[[7.4,0],[9.4,0]],"id":52385909},{"atb":[[4.6,0],[3.8,0]],"id":52385888},{"atb":[[13.5,0],[9.4,0]],"id":52385884},{"atb":[[520,0],[620,0]],"id":52385897},{"atb":[[550,0],[650,0]],"id":52385893},{"atb":[[19.5,0],[14.5,0]],"id":52385905},{"atb":[[200,0],[100,0]],"id":52385901},{"atb":[[7.2,0],[9.2,0]],"id":52385910},{"atb":[[17,0],[12,0]],"id":52385906},{"atb":[[190,0],[95,0]],"id":52385889},{"atb":[[6.8,0],[8.8,0]],"id":52385885},{"atb":[[550,0],[650,0]],"id":52385894},{"atb":[[550,0],[650,0]],"id":52385890},{"atb":[[5.8,0],[7.6,0]],"id":52385902},{"atb":[[19,0],[14,0]],"id":52385898},{"atb":[[300,0],[200,0]],"id":52385911},{"atb":[[18,0],[26,0]],"id":52385907},{"atb":[[9.6,0],[14,0]],"id":52385886},{"atb":[[95,0],[48,0]],"id":52385882},{"atb":[[34,0],[22,0]],"id":52385895},{"atb":[[550,0],[650,0]],"id":52385891},{"atb":[[9.8,0],[14.5,0]],"id":52385903},{"atb":[[9.6,0],[14,0]],"id":52385899}],"con":true,"img":false}]}
{"op":"mcm","clk":"11449655974","pt":1717312956289,"mc":[{"id":"1.229554917","rc":[{"atb":[[9.6,0],[14,0]],"id":52385912},{"atb":[[18.5,0],[27,0]],"id":52385920},{"atb":[[5.6,0],[4.6,0]],"id":52385916},{"atb":[[590,0],[490,0]],"id":52385929},{"atb":[[550,0],[650,0]],"id":52385925},{"atb":[[17,0],[12,0]],"id":52385937},{"atb":[[5.6,11.37],[4.6,29.07]],"id":52385933},{"atb":[[16.5,0],[11.5,0]],"id":52385913},{"atb":[[18,0],[13,0]],"id":52385921},{"atb":[[10,0],[15,0]],"id":52385917},{"atb":[[150,0],[250,0]],"id":52385926},{"atb":[[540,0],[440,0]],"id":52385922},{"atb":[[7.4,0],[5.7,0]],"id":52385934},{"atb":[[20,0],[15,0]],"id":52385930},{"atb":[[550,0],[650,0]],"id":52385918},{"atb":[[17,0],[12,0]],"id":52385914},{"atb":[[400,0],[500,0]],"id":52385927},{"atb":[[9.8,0],[7.8,0]],"id":52385923},{"atb":[[3.85,0],[4.7,0]],"id":52385935},{"atb":[[3.15,0],[3.65,0]],"id":52385931},{"atb":[[20,0],[15,0]],"id":52385919},{"atb":[[34,0],[60,0]],"id":52385915},{"atb":[[85,0],[44,0]],"id":52385928},{"atb":[[40,0],[25,0]],"id":52385924},{"atb":[[7.8,0],[5.9,0]],"id":52385936},{"atb":[[16,0],[22,0]],"id":52385932}],"con":true,"img":false}]}
{"op":"mcm","clk":"11449656399","pt":1717312966144,"mc":[{"id":"1.229554917","rc":[{"atb":[[9.6,28.36],[14,8.04]],"id":52385912},{"atb":[[360,0.68],[460,0.23]],"id":52385908},{"atb":[[20,12.83],[30,3.6]],"id":52385887},{"atb":[[18.5,13.93],[27,4.01]],"id":52385920},{"atb":[[10.5,11],[8.2,33.87]],"id":52385883},{"atb":[[5.6,22.72],[4.6,67.75]],"id":52385916},{"atb":[[8.6,32.09],[11.5,9.95]],"id":52385896},{"atb":[[590,0.17],[490,0.49]],"id":52385929},{"atb":[[300,0.81],[400,0.26]],"id":52385892},{"atb":[[550,0.44],[650,0.16]],"id":52385925},{"atb":[[550,0.44],[650,0.16]],"id":52385904},{"atb":[[17,6.53],[12,22.17]],"id":52385937},{"atb":[[20,5.5],[15,17.42]],"id":52385900},{"atb":[[5.6,34.1],[4.6,96.82]],"id":52385933},{"atb":[[16.5,6.74],[11.5,23.22]],"id":52385913},{"atb":[[7.4,38.1],[9.4,12.44]],"id":52385909},{"atb":[[4.6,29.03],[3.8,87.1]],"id":52385888},{"atb":[[18,6.14],[13,20.32]],"id":52385921},{"atb":[[13.5,8.36],[9.4,29.03]],"id":52385884},{"atb":[[10,27.1],[15,7.46]],"id":52385917},{"atb":[[150,1.63],[250,0.41]],"id":52385926},{"atb":[[520,0.47],[620,0.16]],"id":52385897},{"atb":[[540,0.19],[440,0.55]],"id":52385922},{"atb":[[550,0.44],[650,0.16]],"id":52385893},{"atb":[[7.4,16.33],[5.7,51.89]],"id":52385934},{"atb":[[19.5,5.65],[14.5,18.06]],"id":52385905},{"atb":[[20,5.5],[15,17.42]],"id":52385930},{"atb":[[200,0.52],[100,2.46]],"id":52385901},{"atb":[[7.2,39.33],[9.2,12.74]],"id":52385910},{"atb":[[17,6.53],[12,22.17]],"id":52385906},{"atb":[[550,0.44],[650,0.16]],"id":52385918},{"atb":[[190,0.55],[95,2.59]],"id":52385889},{"atb":[[17,6.53],[12,22.17]],"id":52385914},{"atb":[[6.8,42.05],[8.8,13.4]],"id":52385885},{"atb":[[550,0.44],[650,0.16]],"id":52385894},{"atb":[[400,0.61],[500,0.2]],"id":52385927},{"atb":[[550,0.44],[650,0.16]],"id":52385890},{"atb":[[9.8,11.87],[7.8,35.86]],"id":52385923},{"atb":[[5.8,50.81],[7.6,15.83]],"id":52385902},{"atb":[[3.85,85.58],[4.7,28.25]],"id":52385935},{"atb":[[19,5.8],[14,18.76]],"id":52385898},{"atb":[[3.15,113.44],[3.65,39.44]],"id":52385931},{"atb":[[300,0.35],[200,1.22]],"id":52385911},{"atb":[[18,14.34],[26,4.18]],"id":52385907},{"atb":[[9.6,28.36],[14,8.04]],"id":52385886},{"atb":[[20,5.5],[15,17.42]],"id":52385919},{"atb":[[95,1.11],[48,5.18]],"id":52385882},{"atb":[[34,7.39],[60,1.77]],"id":52385915},{"atb":[[34,3.16],[22,11.61]],"id":52385895},{"atb":[[85,1.24],[44,5.67]],"id":52385928},{"atb":[[550,0.44],[650,0.16]],"id":52385891},{"atb":[[40,2.67],[25,10.16]],"id":52385924},{"atb":[[9.8,27.71],[14.5,7.74]],"id":52385903},{"atb":[[7.8,15.37],[5.9,49.77]],"id":52385936},{"atb":[[9.6,28.36],[14,8.04]],"id":52385899},{"atb":[[16,16.26],[22,4.97]],"id":52385932}],"con":true,"img":false}]}
{"op":"mcm","clk":"11449674299","pt":1717313350869,"mc":[{"id":"1.229554917","rc":[{"atb":[[70,0],[38,0],[95,0],[48,0]],"id":52385920},{"atb":[[8.6,0],[5.8,0],[7.6,0],[6.6,0]],"id":52385934},{"atb":[[34,0],[44,0],[27,0],[60,0]],"id":52385905},{"atb":[[70,0],[38,0],[48,0],[29,0]],"id":52385919}],"con":true,"img":false}]}
{"op":"mcm","clk":"11449674337","pt":1717313351592,"mc":[{"id":"1.229554917","rc":[{"atb":[[70,0.76],[38,2.83],[95,0.28],[48,1.67]],"id":52385920},{"atb":[[8.6,3.44],[5.8,21.8],[7.6,7.93],[6.6,14.02]],"id":52385934},{"atb":[[34,2.38],[44,1.22],[27,4.02],[60,0.44]],"id":52385905},{"atb":[[70,0.38],[38,2.12],[48,1.11],[29,3.74]],"id":52385919}],"con":true,"img":false}]}
{"op":"mcm","clk":"11449706678","pt":1717313769274,"mc":[{"id":"1.229554917","rc":[{"atb":[[65,0],[36,0],[90,0],[46,0]],"id":52385887},{"atb":[[17,0],[19.5,0],[24,0],[14.5,0]],"id":52385883},{"atb":[[160,0],[80,0],[110,0],[55,0]],"id":52385924}],"con":true,"img":false}]}
{"op":"mcm","clk":"11449706733","pt":1717313769945,"mc":[{"id":"1.229554917","rc":[{"atb":[[70,0.76],[38,2.83],[95,0.28],[48,1.67]],"id":52385887},{"atb":[[17.5,4.76],[20,2.75],[25,1.09],[15,7.48]],"id":52385883},{"atb":[[170,0.16],[85,0.94],[120,0.44],[60,1.77]],"id":52385924}],"con":true,"img":false}]}
{"op":"mcm","clk":"11449736728","pt":1717314096607,"mc":[{"id":"1.229554917","rc":[{"atb":[[360,0],[460,0]],"id":52385908},{"atb":[[20,0],[30,0]],"id":52385887},{"atb":[[10.5,0],[8.2,0]],"id":52385883},{"atb":[[8.6,0],[11.5,0]],"id":52385896},{"atb":[[300,0],[400,0]],"id":52385892},{"atb":[[550,0],[650,0]],"id":52385904},{"atb":[[20,0],[15,0]],"id":52385900},{"atb":[[7.4,0],[9.4,0]],"id":52385909},{"atb":[[4.6,0],[3.8,0]],"id":52385888},{"atb":[[13.5,0],[9.4,0]],"id":52385884},{"atb":[[520,0],[620,0]],"id":52385897},{"atb":[[550,0],[650,0]],"id":52385893},{"atb":[[19.5,0],[14.5,0]],"id":52385905},{"atb":[[200,0],[100,0]],"id":52385901},{"atb":[[7.2,0],[9.2,0]],"id":52385910},{"atb":[[17,0],[12,0]],"id":52385906},{"atb":[[190,0],[95,0]],"id":52385889},{"atb":[[6.8,0],[8.8,0]],"id":52385885},{"atb":[[550,0],[650,0]],"id":52385894},{"atb":[[550,0],[650,0]],"id":52385890},{"atb":[[5.8,0],[7.6,0]],"id":52385902},{"atb":[[19,0],[14,0]],"id":52385898},{"atb":[[300,0],[200,0]],"id":52385911},{"atb":[[18,0],[26,0]],"id":52385907},{"atb":[[9.6,0],[14,0]],"id":52385886},{"atb":[[95,0],[48,0]],"id":52385882},{"atb":[[34,0],[22,0]],"id":52385895},{"atb":[[550,0],[650,0]],"id":52385891},{"atb":[[9.8,0],[14.5,0]],"id":52385903},{"atb":[[9.6,0],[14,0]],"id":52385899}],"con":true,"img":false}]}
{"op":"mcm","clk":"11449736736","pt":1717314096708,"mc":[{"id":"1.229554917","rc":[{"atb":[[9.6,0],[14,0]],"id":52385912},{"atb":[[18.5,0],[27,0]],"id":52385920},{"atb":[[5.6,0],[4.6,0]],"id":52385916},{"atb":[[590,0],[490,0]],"id":52385929},{"atb":[[550,0],[650,0]],"id":52385925},{"atb":[[17,0],[12,0]],"id":52385937},{"atb":[[5.6,11.37],[4.6,29.07]],"id":52385933},{"atb":[[16.5,0],[11.5,0]],"id":52385913},{"atb":[[18,0],[13,0]],"id":52385921},{"atb":[[10,0],[15,0]],"id":52385917},{"atb":[[150,0],[250,0]],"id":52385926},{"atb":[[540,0],[440,0]],"id":52385922},{"atb":[[7.4,0],[5.7,0]],"id":52385934},{"atb":[[20,0],[15,0]],"id":52385930},{"atb":[[550,0],[650,0]],"id":52385918},{"atb":[[17,0],[12,0]],"id":52385914},{"atb":[[400,0],[500,0]],"id":52385927},{"atb":[[9.8,0],[7.8,0]],"id":52385923},{"atb":[[3.85,0],[4.7,0]],"id":52385935},{"atb":[[3.15,0],[3.65,0]],"id":52385931},{"atb":[[20,0],[15,0]],"id":52385919},{"atb":[[34,0],[60,0]],"id":52385915},{"atb":[[85,0],[44,0]],"id":52385928},{"atb":[[40,0],[25,0]],"id":52385924},{"atb":[[7.8,0],[5.9,0]],"id":52385936},{"atb":[[16,0],[22,0]],"id":52385932}],"con":true,"img":false}]}
{"op":"mcm","clk":"11449740295","pt":1717314135255,"mc":[{"id":"1.229554917","rc":[{"atb":[[9.6,28.36],[14,8.04]],"id":52385912},{"atb":[[360,0.68],[460,0.23]],"id":52385908},{"atb":[[20,12.83],[30,3.6]],"id":52385887},{"atb":[[18.5,13.93],[27,4.01]],"id":52385920},{"atb":[[10.5,11],[8.2,33.87]],"id":52385883},{"atb":[[5.6,22.72],[4.6,67.75]],"id":52385916},{"atb":[[8.6,32.09],[11.5,9.95]],"id":52385896},{"atb":[[590,0.17],[490,0.49]],"id":52385929},{"atb":[[300,0.81],[400,0.26]],"id":52385892},{"atb":[[550,0.44],[650,0.16]],"id":52385925},{"atb":[[550,0.44],[650,0.16]],"id":52385904},{"atb":[[17,6.53],[12,22.17]],"id":52385937},{"atb":[[20,5.5],[15,17.42]],"id":52385900},{"atb":[[5.6,34.1],[4.6,96.82]],"id":52385933},{"atb":[[16.5,6.74],[11.5,23.22]],"id":52385913},{"atb":[[7.4,38.1],[9.4,12.44]],"id":52385909},{"atb":[[4.6,29.03],[3.8,87.1]],"id":52385888},{"atb":[[18,6.14],[13,20.32]],"id":52385921},{"atb":[[13.5,8.36],[9.4,29.03]],"id":52385884},{"atb":[[10,27.1],[15,7.46]],"id":52385917},{"atb":[[150,1.63],[250,0.41]],"id":52385926},{"atb":[[520,0.47],[620,0.16]],"id":52385897},{"atb":[[540,0.19],[440,0.55]],"id":52385922},{"atb":[[550,0.44],[650,0.16]],"id":52385893},{"atb":[[7.4,16.33],[5.7,51.89]],"id":52385934},{"atb":[[19.5,5.65],[14.5,18.06]],"id":52385905},{"atb":[[20,5.5],[15,17.42]],"id":52385930},{"atb":[[200,0.52],[100,2.46]],"id":52385901},{"atb":[[7.2,39.33],[9.2,12.74]],"id":52385910},{"atb":[[17,6.53],[12,22.17]],"id":52385906},{"atb":[[550,0.44],[650,0.16]],"id":52385918},{"atb":[[190,0.55],[95,2.59]],"id":52385889},{"atb":[[17,6.53],[12,22.17]],"id":52385914},{"atb":[[6.8,42.05],[8.8,13.4]],"id":52385885},{"atb":[[550,0.44],[650,0.16]],"id":52385894},{"atb":[[400,0.61],[500,0.2]],"id":52385927},{"atb":[[550,0.44],[650,0.16]],"id":52385890},{"atb":[[9.8,11.87],[7.8,35.86]],"id":52385923},{"atb":[[5.8,50.81],[7.6,15.83]],"id":52385902},{"atb":[[3.85,85.58],[4.7,28.25]],"id":52385935},{"atb":[[19,5.8],[14,18.76]],"id":52385898},{"atb":[[3.15,113.44],[3.65,39.44]],"id":52385931},{"atb":[[300,0.35],[200,1.22]],"id":52385911},{"atb":[[18,14.34],[26,4.18]],"id":52385907},{"atb":[[9.6,28.36],[14,8.04]],"id":52385886},{"atb":[[20,5.5],[15,17.42]],"id":52385919},{"atb":[[95,1.11],[48,5.18]],"id":52385882},{"atb":[[34,7.39],[60,1.77]],"id":52385915},{"atb":[[34,3.16],[22,11.61]],"id":52385895},{"atb":[[85,1.24],[44,5.67]],"id":52385928},{"atb":[[550,0.44],[650,0.16]],"id":52385891},{"atb":[[40,2.67],[25,10.16]],"id":52385924},{"atb":[[9.8,27.71],[14.5,7.74]],"id":52385903},{"atb":[[7.8,15.37],[5.9,49.77]],"id":52385936},{"atb":[[9.6,28.36],[14,8.04]],"id":52385899},{"atb":[[16,16.26],[22,4.97]],"id":52385932}],"con":true,"img":false}]}
{"op":"mcm","clk":"11449745200","pt":1717314192255,"mc":[{"id":"1.229554917","rc":[{"atb":[[9.6,0],[14,0]],"id":52385912},{"atb":[[360,0],[460,0]],"id":52385908},{"atb":[[20,0],[30,0]],"id":52385887},{"atb":[[18.5,0],[27,0]],"id":52385920},{"atb":[[10.5,0],[8.2,0]],"id":52385883},{"atb":[[5.6,0],[4.6,0]],"id":52385916},{"atb":[[8.6,0],[11.5,0]],"id":52385896},{"atb":[[590,0],[490,0]],"id":52385929},{"atb":[[300,0],[400,0]],"id":52385892},{"atb":[[550,0],[650,0]],"id":52385925},{"atb":[[550,0],[650,0]],"id":52385904},{"atb":[[17,0],[12,0]],"id":52385937},{"atb":[[20,0],[15,0]],"id":52385900},{"atb":[[5.6,11.37],[4.6,29.07]],"id":52385933},{"atb":[[16.5,0],[11.5,0]],"id":52385913},{"atb":[[7.4,0],[9.4,0]],"id":52385909},{"atb":[[4.6,0],[3.8,0]],"id":52385888},{"atb":[[18,0],[13,0]],"id":52385921},{"atb":[[13.5,0],[9.4,0]],"id":52385884},{"atb":[[10,0],[15,0]],"id":52385917},{"atb":[[150,0],[250,0]],"id":52385926},{"atb":[[520,0],[620,0]],"id":52385897},{"atb":[[540,0],[440,0]],"id":52385922},{"atb":[[550,0],[650,0]],"id":52385893},{"atb":[[7.4,0],[5.7,0]],"id":52385934},{"atb":[[19.5,0],[14.5,0]],"id":52385905},{"atb":[[20,0],[15,0]],"id":52385930},{"atb":[[200,0],[100,0]],"id":52385901},{"atb":[[7.2,0],[9.2,0]],"id":52385910},{"atb":[[17,0],[12,0]],"id":52385906},{"atb":[[550,0],[650,0]],"id":52385918},{"atb":[[190,0],[95,0]],"id":52385889},{"atb":[[17,0],[12,0]],"id":52385914},{"atb":[[6.8,0],[8.8,0]],"id":52385885},{"atb":[[550,0],[650,0]],"id":52385894},{"atb":[[400,0],[500,0]],"id":52385927},{"atb":[[550,0],[650,0]],"id":52385890},{"atb":[[9.8,0],[7.8,0]],"id":52385923},{"atb":[[5.8,0],[7.6,0]],"id":52385902},{"atb":[[3.85,0],[4.7,0]],"id":52385935},{"atb":[[19,0],[14,0]],"id":52385898},{"atb":[[3.15,0],[3.65,0]],"id":52385931},{"atb":[[300,0],[200,0]],"id":52385911},{"atb":[[18,0],[26,0]],"id":52385907},{"atb":[[9.6,0],[14,0]],"id":52385886},{"atb":[[20,0],[15,0]],"id":52385919},{"atb":[[95,0],[48,0]],"id":52385882},{"atb":[[34,0],[60,0]],"id":52385915},{"atb":[[34,0],[22,0]],"id":52385895},{"atb":[[85,0],[44,0]],"id":52385928},{"atb":[[550,0],[650,0]],"id":52385891},{"atb":[[40,0],[25,0]],"id":52385924},{"atb":[[9.8,0],[14.5,0]],"id":52385903},{"atb":[[7.8,0],[5.9,0]],"id":52385936},{"atb":[[9.6,0],[14,0]],"id":52385899},{"atb":[[16,0],[22,0]],"id":52385932}],"con":true,"img":false}]}
{"op":"mcm","clk":"11449747522","pt":1717314217661,"mc":[{"id":"1.229554917","rc":[{"atb":[[9.6,28.36],[14,8.04]],"id":52385912},{"atb":[[360,0.68],[460,0.23]],"id":52385908},{"atb":[[20,12.83],[30,3.6]],"id":52385887},{"atb":[[18.5,13.93],[27,4.01]],"id":52385920},{"atb":[[10.5,11],[8.2,33.87]],"id":52385883},{"atb":[[5.6,22.72],[4.6,67.75]],"id":52385916},{"atb":[[8.6,32.09],[11.5,9.95]],"id":52385896},{"atb":[[590,0.17],[490,0.49]],"id":52385929},{"atb":[[300,0.81],[400,0.26]],"id":52385892},{"atb":[[550,0.44],[650,0.16]],"id":52385925},{"atb":[[550,0.44],[650,0.16]],"id":52385904},{"atb":[[17,6.53],[12,22.17]],"id":52385937},{"atb":[[20,5.5],[15,17.42]],"id":52385900},{"atb":[[5.6,34.1],[4.6,96.82]],"id":52385933},{"atb":[[16.5,6.74],[11.5,23.22]],"id":52385913},{"atb":[[7.4,38.1],[9.4,12.44]],"id":52385909},{"atb":[[4.6,29.03],[3.8,87.1]],"id":52385888},{"atb":[[18,6.14],[13,20.32]],"id":52385921},{"atb":[[13.5,8.36],[9.4,29.03]],"id":52385884},{"atb":[[10,27.1],[15,7.46]],"id":52385917},{"atb":[[150,1.63],[250,0.41]],"id":52385926},{"atb":[[520,0.47],[620,0.16]],"id":52385897},{"atb":[[540,0.19],[440,0.55]],"id":52385922},{"atb":[[550,0.44],[650,0.16]],"id":52385893},{"atb":[[7.4,16.33],[5.7,51.89]],"id":52385934},{"atb":[[19.5,5.65],[14.5,18.06]],"id":52385905},{"atb":[[20,5.5],[15,17.42]],"id":52385930},{"atb":[[200,0.52],[100,2.46]],"id":52385901},{"atb":[[7.2,39.33],[9.2,12.74]],"id":52385910},{"atb":[[17,6.53],[12,22.17]],"id":52385906},{"atb":[[550,0.44],[650,0.16]],"id":52385918},{"atb":[[190,0.55],[95,2.59]],"id":52385889},{"atb":[[17,6.53],[12,22.17]],"id":52385914},{"atb":[[6.8,42.05],[8.8,13.4]],"id":52385885},{"atb":[[550,0.44],[650,0.16]],"id":52385894},{"atb":[[400,0.61],[500,0.2]],"id":52385927},{"atb":[[550,0.44],[650,0.16]],"id":52385890},{"atb":[[9.8,11.87],[7.8,35.86]],"id":52385923},{"atb":[[5.8,50.81],[7.6,15.83]],"id":52385902},{"atb":[[3.85,85.58],[4.7,28.25]],"id":52385935},{"atb":[[19,5.8],[14,18.76]],"id":52385898},{"atb":[[3.15,113.44],[3.65,39.44]],"id":52385931},{"atb":[[300,0.35],[200,1.22]],"id":52385911},{"atb":[[18,14.34],[26,4.18]],"id":52385907},{"atb":[[9.6,28.36],[14,8.04]],"id":52385886},{"atb":[[20,5.5],[15,17.42]],"id":52385919},{"atb":[[95,1.11],[48,5.18]],"id":52385882},{"atb":[[34,7.39],[60,1.77]],"id":52385915},{"atb":[[34,3.16],[22,11.61]],"id":52385895},{"atb":[[85,1.24],[44,5.67]],"id":52385928},{"atb":[[550,0.44],[650,0.16]],"id":52385891},{"atb":[[40,2.67],[25,10.16]],"id":52385924},{"atb":[[9.8,27.71],[14.5,7.74]],"id":52385903},{"atb":[[7.8,15.37],[5.9,49.77]],"id":52385936},{"atb":[[9.6,28.36],[14,8.04]],"id":52385899},{"atb":[[16,16.26],[22,4.97]],"id":52385932}],"con":true,"img":false}]}
{"op":"mcm","clk":"11449752911","pt":1717314274567,"mc":[{"id":"1.229554917","rc":[{"atb":[[40,0],[50,0],[25,0],[30,0]],"id":52385912},{"atb":[[70,0],[38,0],[95,0],[48,0]],"id":52385887},{"atb":[[17.5,0],[20,0],[25,0],[15,0]],"id":52385883},{"atb":[[16.5,0],[9.6,0],[11.5,0],[14,0]],"id":52385916},{"atb":[[70,0],[38,0],[48,0],[29,0]],"id":52385913},{"atb":[[70,0],[38,0],[95,0],[48,0]],"id":52385921},{"atb":[[75,0],[40,0],[50,0],[30,0]],"id":52385906},{"atb":[[32,0],[80,0],[42,0],[55,0]],"id":52385914},{"atb":[[170,0],[85,0],[120,0],[60,0]],"id":52385924}],"con":true,"img":false}]}
{"op":"mcm","clk":"11449752974","pt":1717314275244,"mc":[{"id":"1.229554917","rc":[{"atb":[[70,0.38],[38,2.12],[48,1.11],[29,3.74]],"id":52385913},{"atb":[[70,0.76],[38,2.83],[95,0.28],[48,1.67]],"id":52385921},{"atb":[[75,0.36],[40,2.01],[50,1.07],[30,3.61]],"id":52385906}],"con":true,"img":false}]}
{"op":"mcm","clk":"11449752980","pt":1717314275350,"mc":[{"id":"1.229554917","rc":[{"atb":[[40,1.34],[50,0.53],[25,4.36],[30,2.71]],"id":52385912},{"atb":[[70,0.76],[38,2.83],[95,0.28],[48,1.67]],"id":52385887},{"atb":[[17.5,4.76],[20,2.75],[25,1.09],[15,7.48]],"id":52385883},{"atb":[[16.5,1.69],[9.6,12.17],[11.5,7.48],[14,4.02]],"id":52385916},{"atb":[[32,3.37],[80,0.33],[42,1.92],[55,0.97]],"id":52385914},{"atb":[[170,0.16],[85,0.94],[120,0.44],[60,1.77]],"id":52385924}],"con":true,"img":false}]}
{"op":"mcm","clk":"11449777611","pt":1717314552024,"mc":[{"id":"1.229554917","rc":[{"atb":[[70,0],[38,0],[95,0],[48,0]],"id":52385920},{"atb":[[8.6,0],[5.8,0],[7.6,0],[6.6,0]],"id":52385934},{"atb":[[34,0],[44,0],[27,0],[60,0]],"id":52385905},{"atb":[[70,0],[38,0],[48,0],[29,0]],"id":52385919}],"con":true,"img":false}]}
{"op":"mcm","clk":"11449777677","pt":1717314552804,"mc":[{"id":"1.229554917","rc":[{"atb":[[8.6,3.44],[5.8,21.8],[7.6,7.93],[6.6,14.02]],"id":52385934},{"atb":[[34,2.38],[44,1.22],[27,4.02],[60,0.44]],"id":52385905},{"atb":[[70,0.38],[38,2.12],[48,1.11],[29,3.74]],"id":52385919}],"con":true,"img":false}]}
{"op":"mcm","clk":"11449777687","pt":1717314552911,"mc":[{"id":"1.229554917","rc":[{"atb":[[70,0.76],[38,2.83],[95,0.28],[48,1.67]],"id":52385920}],"con":true,"img":false}]}
{"op":"mcm","clk":"11449778884","pt":1717314565908,"mc":[{"id":"1.229554917","rc":[{"atb":[[70,0],[38,0],[95,0],[48,0]],"id":52385887},{"atb":[[17.5,0],[20,0],[25,0],[15,0]],"id":52385883},{"atb":[[70,0],[38,0],[48,0],[29,0]],"id":52385913},{"atb":[[70,0],[38,0],[95,0],[48,0]],"id":52385921},{"atb":[[75,0],[40,0],[50,0],[30,0]],"id":52385906},{"atb":[[170,0],[85,0],[120,0],[60,0]],"id":52385924}],"con":true,"img":false}]}
{"op":"mcm","clk":"11449778937","pt":1717314566628,"mc":[{"id":"1.229554917","rc":[{"atb":[[65,0.82],[36,2.99],[90,0.29],[46,1.74]],"id":52385887},{"atb":[[17,4.9],[19.5,2.83],[24,1.14],[14.5,7.75]],"id":52385883},{"atb":[[75,0.36],[40,2.01],[50,1.07],[30,3.61]],"id":52385913},{"atb":[[75,0.71],[40,2.68],[100,0.27],[50,1.6]],"id":52385921},{"atb":[[32,3.37],[80,0.33],[42,1.92],[55,0.97]],"id":52385906},{"atb":[[160,0.16],[80,0.99],[110,0.48],[55,1.94]],"id":52385924}],"con":true,"img":false}]}
{"op":"mcm","clk":"11449780034","pt":1717314578931,"mc":[{"id":"1.229554917","rc":[{"atb":[[75,0],[40,0],[50,0],[30,0]],"id":52385913},{"atb":[[75,0],[40,0],[100,0],[50,0]],"id":52385921},{"atb":[[32,0],[80,0],[42,0],[55,0]],"id":52385906}],"con":true,"img":false}]}
{"op":"mcm","clk":"11449780097","pt":1717314579604,"mc":[{"id":"1.229554917","rc":[{"atb":[[70,0.38],[38,2.12],[48,1.11],[29,3.74]],"id":52385913},{"atb":[[70,0.76],[38,2.83],[95,0.28],[48,1.67]],"id":52385921},{"atb":[[75,0.36],[40,2.01],[50,1.07],[30,3.61]],"id":52385906}],"con":true,"img":false}]}
{"op":"mcm","clk":"11449781278","pt":1717314594754,"mc":[{"id":"1.229554917","rc":[{"atb":[[40,0],[20,0],[25,0],[30,0]],"id":52385937},{"atb":[[140,0],[290,0],[190,0],[240,0]],"id":52385926},{"atb":[[18,0],[10.5,0],[13,0],[15.5,0]],"id":52385902},{"atb":[[36,0],[46,0],[23,0],[28,0]],"id":52385903},{"atb":[[32,0],[42,0],[26,0],[55,0]],"id":52385899}],"con":true,"img":false}]}
{"op":"mcm","clk":"11449781288","pt":1717314594856,"mc":[{"id":"1.229554917","rc":[{"atb":[[34,0],[18.5,0],[22,0],[27,0]],"id":52385884}],"con":true,"img":false}]}
{"op":"mcm","clk":"11449781332","pt":1717314595426,"mc":[{"id":"1.229554917","rc":[{"atb":[[38,0.71],[19.5,5.66],[24,3.41],[29,1.87]],"id":52385937},{"atb":[[150,2.34],[300,0.09],[200,0.39],[250,0.63]],"id":52385926},{"atb":[[16.5,3.37],[19,1.45],[11.5,9.97],[14,6.04]],"id":52385902},{"atb":[[40,1.34],[50,0.53],[25,4.36],[30,2.71]],"id":52385903},{"atb":[[34,2.38],[44,1.22],[27,4.02],[60,0.44]],"id":52385899}],"con":true,"img":false}]}
{"op":"mcm","clk":"11449781338","pt":1717314595530,"mc":[{"id":"1.229554917","rc":[{"atb":[[36,0.75],[19,5.81],[23,3.57],[28,1.94]],"id":52385884}],"con":true,"img":false}]}
{"op":"mcm","clk":"11449782539","pt":1717314610915,"mc":[{"id":"1.229554917","rc":[{"atb":[[36,0],[19,0],[23,0],[28,0]],"id":52385884},{"atb":[[300,0],[150,1.63],[200,0],[250,0.41]],"id":52385926},{"atb":[[16.5,0],[19,0],[11.5,0],[14,0]],"id":52385902},{"atb":[[34,0],[44,0],[27,0],[60,0]],"id":52385899}],"con":true,"img":false}]}
{"op":"mcm","clk":"11449782589","pt":1717314611619,"mc":[{"id":"1.229554917","rc":[{"atb":[[34,0.8],[18.5,5.98],[22,3.74],[27,2.01]],"id":52385884},{"atb":[[140,0.75],[290,0.09],[190,0.41],[240,0.22]],"id":52385926},{"atb":[[18,1.54],[10.5,11.01],[13,6.54],[15.5,3.61]],"id":52385902},{"atb":[[32,2.53],[42,1.28],[26,4.19],[55,0.49]],"id":52385899}],"con":true,"img":false}]}
{"op":"mcm","clk":"11449823477","pt":1717315076909,"mc":[{"id":"1.229554917","rc":[{"atb":[[290,0],[340,0],[390,0],[240,0]],"id":52385904},{"atb":[[34,0],[44,0],[27,0],[60,0]],"id":52385900},{"atb":[[5.6,22.72],[5.1,0],[4.6,67.75],[6.2,0]],"id":52385933},{"atb":[[270,0],[170,0],[220,0],[120,0]],"id":52385897},{"atb":[[8.6,0],[5.8,0],[7.6,0],[6.6,0]],"id":52385934},{"atb":[[34,0],[44,0],[27,0],[60,0]],"id":52385905},{"atb":[[34,0],[44,0],[27,0],[60,0]],"id":52385898},{"atb":[[32,0],[80,0],[42,0],[55,0]],"id":52385907},{"atb":[[36,0],[19,0],[23,0],[28,0]],"id":52385886},{"atb":[[70,0],[38,0],[48,0],[29,0]],"id":52385919},{"atb":[[6.4,0],[7.4,0],[5.7,0],[8.4,0]],"id":52385936},{"atb":[[36,0],[46,0],[23,0],[28,0]],"id":52385932}],"con":true,"img":false}]}
{"op":"mcm","clk":"11449823546","pt":1717315077637,"mc":[{"id":"1.229554917","rc":[{"atb":[[520,0.05],[370,0.28],[420,0.19],[470,0.11]],"id":52385904},{"atb":[[70,0.38],[38,2.12],[48,1.11],[29,3.74]],"id":52385900},{"atb":[[4.9,20.12],[4.4,30.77],[5.9,5.34],[5.4,11.89]],"id":52385933},{"atb":[[300,0.17],[350,0.07],[200,0.53],[250,0.31]],"id":52385897},{"atb":[[5.6,22.75],[7.2,8.44],[6.2,15.09],[8.2,3.63]],"id":52385934},{"atb":[[70,0.38],[38,2.12],[48,1.11],[29,3.74]],"id":52385905},{"atb":[[75,0.36],[40,2.01],[50,1.07],[30,3.61]],"id":52385898},{"atb":[[65,0.82],[36,2.99],[90,0.29],[46,1.74]],"id":52385907},{"atb":[[38,0.71],[19.5,5.66],[24,3.41],[29,1.87]],"id":52385886},{"atb":[[75,0.36],[40,2.01],[50,1.07],[30,3.61]],"id":52385919},{"atb":[[6.4,9.69],[7.4,4.09],[5.2,24.91],[5.7,16.69]],"id":52385936},{"atb":[[38,1.41],[48,0.55],[24,4.55],[29,2.8]],"id":52385932}],"con":true,"img":false}]}
{"op":"mcm","clk":"11449826582","pt":1717315111642,"mc":[{"id":"1.229554917","rc":[{"atb":[[40,0],[50,0],[25,0],[30,0]],"id":52385912},{"atb":[[16.5,0],[9.6,0],[11.5,0],[14,0]],"id":52385916},{"atb":[[32,0],[80,0],[42,0],[55,0]],"id":52385914}],"con":true,"img":false}]}
{"op":"mcm","clk":"11449826645","pt":1717315112362,"mc":[{"id":"1.229554917","rc":[{"atb":[[34,2.38],[60,0.44]],"id":52385912},{"atb":[[17.5,1.59],[10,11.63],[12.5,6.82]],"id":52385916},{"atb":[[34,3.17],[85,0.31],[44,1.83],[60,0.88]],"id":52385914}],"con":true,"img":false}]}
{"op":"mcm","clk":"11449826654","pt":1717315112466,"mc":[{"id":"1.229554917","rc":[{"atb":[[44,1.22],[27,4.02]],"id":52385912},{"atb":[[15,3.74]],"id":52385916}],"con":true,"img":false}]}
{"op":"mcm","clk":"11449837942","pt":1717315161234,"mc":[{"id":"1.229554917","rc":[{"atb":[[360,0],[460,0]],"id":52385908},{"atb":[[20,0],[30,0]],"id":52385887},{"atb":[[10.5,0],[8.2,0]],"id":52385883},{"atb":[[8.6,0],[11.5,0]],"id":52385896},{"atb":[[300,0],[400,0]],"id":52385892},{"atb":[[550,0],[650,0]],"id":52385904},{"atb":[[20,0],[15,0]],"id":52385900},{"atb":[[7.4,0],[9.4,0]],"id":52385909},{"atb":[[4.6,0],[3.8,0]],"id":52385888},{"atb":[[13.5,0],[9.4,0]],"id":52385884},{"atb":[[520,0],[620,0]],"id":52385897},{"atb":[[550,0],[650,0]],"id":52385893},{"atb":[[19.5,0],[14.5,0]],"id":52385905},{"atb":[[200,0],[100,0]],"id":52385901},{"atb":[[7.2,0],[9.2,0]],"id":52385910},{"atb":[[17,0],[12,0]],"id":52385906},{"atb":[[190,0],[95,0]],"id":52385889},{"atb":[[6.8,0],[8.8,0]],"id":52385885},{"atb":[[550,0],[650,0]],"id":52385894},{"atb":[[550,0],[650,0]],"id":52385890},{"atb":[[5.8,0],[7.6,0]],"id":52385902},{"atb":[[19,0],[14,0]],"id":52385898},{"atb":[[300,0],[200,0]],"id":52385911},{"atb":[[18,0],[26,0]],"id":52385907},{"atb":[[9.6,0],[14,0]],"id":52385886},{"atb":[[95,0],[48,0]],"id":52385882},{"atb":[[34,0],[22,0]],"id":52385895},{"atb":[[550,0],[650,0]],"id":52385891},{"atb":[[9.8,0],[14.5,0]],"id":52385903},{"atb":[[9.6,0],[14,0]],"id":52385899}],"con":true,"img":false}]}
{"op":"mcm","clk":"11449837949","pt":1717315161337,"mc":[{"id":"1.229554917","rc":[{"atb":[[9.6,0],[14,0]],"id":52385912},{"atb":[[18.5,0],[27,0]],"id":52385920},{"atb":[[5.6,0],[4.6,0]],"id":52385916},{"atb":[[590,0],[490,0]],"id":52385929},{"atb":[[550,0],[650,0]],"id":52385925},{"atb":[[17,0],[12,0]],"id":52385937},{"atb":[[5.6,0],[4.6,0]],"id":52385933},{"atb":[[16.5,0],[11.5,0]],"id":52385913},{"atb":[[18,0],[13,0]],"id":52385921},{"atb":[[10,0],[15,0]],"id":52385917},{"atb":[[150,0],[250,0]],"id":52385926},{"atb":[[540,0],[440,0]],"id":52385922},{"atb":[[7.4,0],[5.7,0]],"id":52385934},{"atb":[[20,0],[15,0]],"id":52385930},{"atb":[[550,0],[650,0]],"id":52385918},{"atb":[[17,0],[12,0]],"id":52385914},{"atb":[[400,0],[500,0]],"id":52385927},{"atb":[[9.8,0],[7.8,0]],"id":52385923},{"atb":[[3.85,0],[4.7,0]],"id":52385935},{"atb":[[3.15,0],[3.65,0]],"id":52385931},{"atb":[[20,0],[15,0]],"id":52385919},{"atb":[[34,0],[60,0]],"id":52385915},{"atb":[[85,0],[44,0]],"id":52385928},{"atb":[[40,0],[25,0]],"id":52385924},{"atb":[[7.8,0],[5.9,0]],"id":52385936},{"atb":[[16,0],[22,0]],"id":52385932}],"con":true,"img":false}]}
{"op":"mcm","clk":"11449840541","pt":1717315188051,"mc":[{"id":"1.229554917","rc":[{"atb":[[34,0],[44,0],[27,0],[60,0]],"id":52385912},{"atb":[[160,0],[80,0],[110,0],[55,0]],"id":52385882}],"con":true,"img":false}]}
{"op":"mcm","clk":"11449840612","pt":1717315188770,"mc":[{"id":"1.229554917","rc":[{"atb":[[32,2.53],[42,1.28],[26,4.19],[55,0.49]],"id":52385912},{"atb":[[170,0.16],[85,0.94],[120,0.44],[60,1.77]],"id":52385882}],"con":true,"img":false}]}
{"op":"mcm","clk":"11449843033","pt":1717315211792,"mc":[{"id":"1.229554917","rc":[{"atb":[[360,0.68],[460,0.23]],"id":52385908},{"atb":[[20,12.83],[30,3.6]],"id":52385887},{"atb":[[10.5,11],[8.2,33.87]],"id":52385883},{"atb":[[8.6,32.09],[11.5,9.95]],"id":52385896},{"atb":[[300,0.81],[400,0.26]],"id":52385892},{"atb":[[550,0.44],[650,0.16]],"id":52385904},{"atb":[[20,5.5],[15,17.42]],"id":52385900},{"atb":[[7.4,38.1],[9.4,12.44]],"id":52385909},{"atb":[[4.6,29.03],[3.8,87.1]],"id":52385888},{"atb":[[13.5,8.36],[9.4,29.03]],"id":52385884},{"atb":[[520,0.47],[620,0.16]],"id":52385897},{"atb":[[550,0.44],[650,0.16]],"id":52385893},{"atb":[[19.5,5.65],[14.5,18.06]],"id":52385905},{"atb":[[200,0.52],[100,2.46]],"id":52385901},{"atb":[[17,6.53],[12,22.17]],"id":52385906},{"atb":[[190,0.55],[95,2.59]],"id":52385889},{"atb":[[6.8,42.05],[8.8,13.4]],"id":52385885},{"atb":[[550,0.44],[650,0.16]],"id":52385894},{"atb":[[550,0.44],[650,0.16]],"id":52385890},{"atb":[[5.8,50.81],[7.6,15.83]],"id":52385902},{"atb":[[19,5.8],[14,18.76]],"id":52385898},{"atb":[[18,14.34],[26,4.18]],"id":52385907},{"atb":[[9.6,28.36],[14,8.04]],"id":52385886},{"atb":[[95,1.11],[48,5.18]],"id":52385882},{"atb":[[34,3.16],[22,11.61]],"id":52385895},{"atb":[[550,0.44],[650,0.16]],"id":52385891},{"atb":[[9.8,27.71],[14.5,7.74]],"id":52385903},{"atb":[[9.6,28.36],[14,8.04]],"id":52385899}],"con":true,"img":false}]}
{"op":"mcm","clk":"11449843052","pt":1717315211998,"mc":[{"id":"1.229554917","rc":[{"atb":[[9.6,28.36],[14,8.04]],"id":52385912},{"atb":[[18.5,13.93],[27,4.01]],"id":52385920},{"atb":[[5.6,22.72],[4.6,67.75]],"id":52385916},{"atb":[[590,0.17],[490,0.49]],"id":52385929},{"atb":[[550,0.44],[650,0.16]],"id":52385925},{"atb":[[17,6.53],[12,22.17]],"id":52385937},{"atb":[[5.6,22.72],[4.6,67.75]],"id":52385933},{"atb":[[16.5,6.74],[11.5,23.22]],"id":52385913},{"atb":[[18,6.14],[13,20.32]],"id":52385921},{"atb":[[10,27.1],[15,7.46]],"id":52385917},{"atb":[[150,1.63],[250,0.41]],"id":52385926},{"atb":[[540,0.19],[440,0.55]],"id":52385922},{"atb":[[7.4,16.33],[5.7,51.89]],"id":52385934},{"atb":[[20,5.5],[15,17.42]],"id":52385930},{"atb":[[7.2,39.33],[9.2,12.74]],"id":52385910},{"atb":[[550,0.44],[650,0.16]],"id":52385918},{"atb":[[17,6.53],[12,22.17]],"id":52385914},{"atb":[[400,0.61],[500,0.2]],"id":52385927},{"atb":[[9.8,11.87],[7.8,35.86]],"id":52385923},{"atb":[[3.85,85.58],[4.7,28.25]],"id":52385935},{"atb":[[3.15,113.44],[3.65,39.44]],"id":52385931},{"atb":[[300,0.35],[200,1.22]],"id":52385911},{"atb":[[20,5.5],[15,17.42]],"id":52385919},{"atb":[[34,7.39],[60,1.77]],"id":52385915},{"atb":[[85,1.24],[44,5.67]],"id":52385928},{"atb":[[40,2.67],[25,10.16]],"id":52385924},{"atb":[[7.8,15.37],[5.9,49.77]],"id":52385936},{"atb":[[16,16.26],[22,4.97]],"id":52385932}],"con":true,"img":false}]}
{"op":"mcm","clk":"11449851273","pt":1717315296407,"mc":[{"id":"1.229554917","rc":[{"atb":[[9.6,0],[14,0]],"id":52385912},{"atb":[[360,0],[460,0]],"id":52385908},{"atb":[[20,0],[30,0]],"id":52385887},{"atb":[[18.5,0],[27,0]],"id":52385920},{"atb":[[10.5,0],[8.2,0]],"id":52385883},{"atb":[[5.6,0],[4.6,0]],"id":52385916},{"atb":[[8.6,0],[11.5,0]],"id":52385896},{"atb":[[590,0],[490,0]],"id":52385929},{"atb":[[300,0],[400,0]],"id":52385892},{"atb":[[550,0],[650,0]],"id":52385925},{"atb":[[550,0],[650,0]],"id":52385904},{"atb":[[17,0],[12,0]],"id":52385937},{"atb":[[20,0],[15,0]],"id":52385900},{"atb":[[5.6,0],[4.6,0]],"id":52385933},{"atb":[[16.5,0],[11.5,0]],"id":52385913},{"atb":[[7.4,0],[9.4,0]],"id":52385909},{"atb":[[4.6,0],[3.8,0]],"id":52385888},{"atb":[[18,0],[13,0]],"id":52385921},{"atb":[[13.5,0],[9.4,0]],"id":52385884},{"atb":[[10,0],[15,0]],"id":52385917},{"atb":[[150,0],[250,0]],"id":52385926},{"atb":[[520,0],[620,0]],"id":52385897},{"atb":[[540,0],[440,0]],"id":52385922},{"atb":[[550,0],[650,0]],"id":52385893},{"atb":[[7.4,0],[5.7,0]],"id":52385934},{"atb":[[19.5,0],[14.5,0]],"id":52385905},{"atb":[[20,0],[15,0]],"id":52385930},{"atb":[[200,0],[100,0]],"id":52385901},{"atb":[[7.2,0],[9.2,0]],"id":52385910},{"atb":[[17,0],[12,0]],"id":52385906},{"atb":[[550,0],[650,0]],"id":52385918},{"atb":[[190,0],[95,0]],"id":52385889},{"atb":[[17,0],[12,0]],"id":52385914},{"atb":[[6.8,0],[8.8,0]],"id":52385885},{"atb":[[550,0],[650,0]],"id":52385894},{"atb":[[400,0],[500,0]],"id":52385927},{"atb":[[550,0],[650,0]],"id":52385890},{"atb":[[9.8,0],[7.8,0]],"id":52385923},{"atb":[[5.8,0],[7.6,0]],"id":52385902},{"atb":[[3.85,0],[4.7,0]],"id":52385935},{"atb":[[19,0],[14,0]],"id":52385898},{"atb":[[3.15,0],[3.65,0]],"id":52385931},{"atb":[[300,0],[200,0]],"id":52385911},{"atb":[[18,0],[26,0]],"id":52385907},{"atb":[[9.6,0],[14,0]],"id":52385886},{"atb":[[20,0],[15,0]],"id":52385919},{"atb":[[95,0],[48,0]],"id":52385882},{"atb":[[34,0],[60,0]],"id":52385915},{"atb":[[34,0],[22,0]],"id":52385895},{"atb":[[85,0],[44,0]],"id":52385928},{"atb":[[550,0],[650,0]],"id":52385891},{"atb":[[40,0],[25,0]],"id":52385924},{"atb":[[9.8,0],[14.5,0]],"id":52385903},{"atb":[[7.8,0],[5.9,0]],"id":52385936},{"atb":[[9.6,0],[14,0]],"id":52385899},{"atb":[[16,0],[22,0]],"id":52385932}],"con":true,"img":false}]}
{"op":"mcm","clk":"11449855885","pt":1717315342157,"mc":[{"id":"1.229554917","rc":[{"atb":[[9.6,28.36],[14,8.04]],"id":52385912},{"atb":[[360,0.68],[460,0.23]],"id":52385908},{"atb":[[20,12.83],[30,3.6]],"id":52385887},{"atb":[[18.5,13.93],[27,4.01]],"id":52385920},{"atb":[[10.5,11],[8.2,33.87]],"id":52385883},{"atb":[[5.6,22.72],[4.6,67.75]],"id":52385916},{"atb":[[8.6,32.09],[11.5,9.95]],"id":52385896},{"atb":[[590,0.17],[490,0.49]],"id":52385929},{"atb":[[300,0.81],[400,0.26]],"id":52385892},{"atb":[[550,0.44],[650,0.16]],"id":52385925},{"atb":[[550,0.44],[650,0.16]],"id":52385904},{"atb":[[17,6.53],[12,22.17]],"id":52385937},{"atb":[[20,5.5],[15,17.42]],"id":52385900},{"atb":[[5.6,22.72],[4.6,67.75]],"id":52385933},{"atb":[[16.5,6.74],[11.5,23.22]],"id":52385913},{"atb":[[7.4,38.1],[9.4,12.44]],"id":52385909},{"atb":[[4.6,29.03],[3.8,87.1]],"id":52385888},{"atb":[[18,6.14],[13,20.32]],"id":52385921},{"atb":[[13.5,8.36],[9.4,29.03]],"id":52385884},{"atb":[[10,27.1],[15,7.46]],"id":52385917},{"atb":[[150,1.63],[250,0.41]],"id":52385926},{"atb":[[520,0.47],[620,0.16]],"id":52385897},{"atb":[[540,0.19],[440,0.55]],"id":52385922},{"atb":[[550,0.44],[650,0.16]],"id":52385893},{"atb":[[7.4,16.33],[5.7,51.89]],"id":52385934},{"atb":[[19.5,5.65],[14.5,18.06]],"id":52385905},{"atb":[[20,5.5],[15,17.42]],"id":52385930},{"atb":[[200,0.52],[100,2.46]],"id":52385901},{"atb":[[7.2,39.33],[9.2,12.74]],"id":52385910},{"atb":[[17,6.53],[12,22.17]],"id":52385906},{"atb":[[550,0.44],[650,0.16]],"id":52385918},{"atb":[[190,0.55],[95,2.59]],"id":52385889},{"atb":[[17,6.53],[12,22.17]],"id":52385914},{"atb":[[6.8,42.05],[8.8,13.4]],"id":52385885},{"atb":[[550,0.44],[650,0.16]],"id":52385894},{"atb":[[400,0.61],[500,0.2]],"id":52385927},{"atb":[[550,0.44],[650,0.16]],"id":52385890},{"atb":[[9.8,11.87],[7.8,35.86]],"id":52385923},{"atb":[[5.8,50.81],[7.6,15.83]],"id":52385902},{"atb":[[3.85,85.58],[4.7,28.25]],"id":52385935},{"atb":[[19,5.8],[14,18.76]],"id":52385898},{"atb":[[3.15,113.44],[3.65,39.44]],"id":52385931},{"atb":[[300,0.35],[200,1.22]],"id":52385911},{"atb":[[18,14.34],[26,4.18]],"id":52385907},{"atb":[[9.6,28.36],[14,8.04]],"id":52385886},{"atb":[[20,5.5],[15,17.42]],"id":52385919},{"atb":[[95,1.11],[48,5.18]],"id":52385882},{"atb":[[34,7.39],[60,1.77]],"id":52385915},{"atb":[[34,3.16],[22,11.61]],"id":52385895},{"atb":[[85,1.24],[44,5.67]],"id":52385928},{"atb":[[550,0.44],[650,0.16]],"id":52385891},{"atb":[[40,2.67],[25,10.16]],"id":52385924},{"atb":[[9.8,27.71],[14.5,7.74]],"id":52385903},{"atb":[[7.8,15.37],[5.9,49.77]],"id":52385936},{"atb":[[9.6,28.36],[14,8.04]],"id":52385899},{"atb":[[16,16.26],[22,4.97]],"id":52385932}],"con":true,"img":false}]}
{"op":"mcm","clk":"11449857645","pt":1717315358868,"mc":[{"id":"1.229554917","rc":[{"atb":[[520,0],[370,0],[420,0],[470,0]],"id":52385904},{"atb":[[6.4,0],[7.4,0],[5.2,0],[5.7,0]],"id":52385936}],"con":true,"img":false}]}
{"op":"mcm","clk":"11449857713","pt":1717315359588,"mc":[{"id":"1.229554917","rc":[{"atb":[[360,0.29],[410,0.19],[460,0.12],[510,0.05]],"id":52385904},{"atb":[[5.8,16.35],[5.3,24.33],[7.6,3.97],[6.6,9.34]],"id":52385936}],"con":true,"img":false}]}
{"op":"mcm","clk":"11449857898","pt":1717315361451,"mc":[{"id":"1.229554917","rc":[{"atb":[[70,0],[38,0],[95,0],[48,0]],"id":52385920}],"con":true,"img":false}]}
{"op":"mcm","clk":"11449857961","pt":1717315362171,"mc":[{"id":"1.229554917","rc":[{"atb":[[75,0.71],[40,2.68],[100,0.27],[50,1.6]],"id":52385920}],"con":true,"img":false}]}
{"op":"mcm","clk":"11449859795","pt":1717315381120,"mc":[{"id":"1.229554917","rc":[{"atb":[[32,0],[42,0],[26,0],[55,0]],"id":52385912},{"atb":[[65,0],[36,0],[90,0],[46,0]],"id":52385887},{"atb":[[17,0],[19.5,0],[24,0],[14.5,0]],"id":52385883},{"atb":[[17.5,0],[10,0],[12.5,0],[15,0]],"id":52385916},{"atb":[[34,0],[85,0],[44,0],[60,0]],"id":52385914},{"atb":[[160,0],[80,0],[110,0],[55,0]],"id":52385924}],"con":true,"img":false}]}
{"op":"mcm","clk":"11449859856","pt":1717315381784,"mc":[{"id":"1.229554917","rc":[{"atb":[[40,1.34],[50,0.53],[25,4.36],[30,2.71]],"id":52385912},{"atb":[[70,0.76],[38,2.83],[95,0.28],[48,1.67]],"id":52385887},{"atb":[[17.5,4.76],[20,2.75],[25,1.09],[15,7.48]],"id":52385883},{"atb":[[16.5,1.69],[9.6,12.17],[11.5,7.48],[14,4.02]],"id":52385916},{"atb":[[32,3.37],[80,0.33],[42,1.92],[55,0.97]],"id":52385914},{"atb":[[170,0.16],[85,0.94],[120,0.44],[60,1.77]],"id":52385924}],"con":true,"img":false}]}
{"op":"mcm","clk":"11449860420","pt":1717315387838,"mc":[{"id":"1.229554917","rc":[{"atb":[[70,0],[38,0],[95,0],[48,0]],"id":52385887},{"atb":[[17.5,0],[20,0],[25,0],[15,0]],"id":52385883},{"atb":[[70,0],[38,0],[48,0],[29,0]],"id":52385913},{"atb":[[70,0],[38,0],[95,0],[48,0]],"id":52385921},{"atb":[[75,0],[40,0],[50,0],[30,0]],"id":52385906},{"atb":[[170,0],[85,0],[120,0],[60,0]],"id":52385924}],"con":true,"img":false}]}
{"op":"mcm","clk":"11449860488","pt":1717315388512,"mc":[{"id":"1.229554917","rc":[{"atb":[[65,0.82],[36,2.99],[90,0.29],[46,1.74]],"id":52385887},{"atb":[[17,4.9],[19.5,2.83],[24,1.14],[14.5,7.75]],"id":52385883},{"atb":[[75,0.36],[40,2.01],[50,1.07],[30,3.61]],"id":52385913},{"atb":[[75,0.71],[40,2.68],[100,0.27],[50,1.6]],"id":52385921},{"atb":[[32,3.37],[80,0.33],[42,1.92],[55,0.97]],"id":52385906},{"atb":[[160,0.16],[80,0.99],[110,0.48],[55,1.94]],"id":52385924}],"con":true,"img":false}]}
{"op":"mcm","clk":"11449861464","pt":1717315398550,"mc":[{"id":"1.229554917","rc":[{"atb":[[75,0],[40,0],[50,0],[30,0]],"id":52385913},{"atb":[[75,0],[40,0],[100,0],[50,0]],"id":52385921},{"atb":[[32,0],[80,0],[42,0],[55,0]],"id":52385906}],"con":true,"img":false}]}
{"op":"mcm","clk":"11449861534","pt":1717315399230,"mc":[{"id":"1.229554917","rc":[{"atb":[[70,0.38],[38,2.12],[48,1.11],[29,3.74]],"id":52385913},{"atb":[[70,0.76],[38,2.83],[95,0.28],[48,1.67]],"id":52385921},{"atb":[[75,0.36],[40,2.01],[50,1.07],[30,3.61]],"id":52385906}],"con":true,"img":false}]}
{"op":"mcm","clk":"11449861571","pt":1717315399635,"mc":[{"id":"1.229554917","rc":[{"atb":[[24,0]],"id":52385937}],"con":true,"img":false}]}
{"op":"mcm","clk":"11449861583","pt":1717315399741,"mc":[{"id":"1.229554917","rc":[{"atb":[[38,0],[19.5,0],[29,0]],"id":52385937}],"con":true,"img":false}]}
{"op":"mcm","clk":"11449861636","pt":1717315400311,"mc":[{"id":"1.229554917","rc":[{"atb":[[25,3.27]],"id":52385937}],"con":true,"img":false}]}
{"op":"mcm","clk":"11449861647","pt":1717315400415,"mc":[{"id":"1.229554917","rc":[{"atb":[[40,0.67],[20,5.51],[30,1.81]],"id":52385937}],"con":true,"img":false}]}
{"op":"mcm","clk":"11449893671","pt":1717315712774,"mc":[{"id":"1.229554917","rc":[{"atb":[[9.6,0],[14,0]],"id":52385912},{"atb":[[360,0],[460,0]],"id":52385908},{"atb":[[20,0],[30,0]],"id":52385887},{"atb":[[18.5,0],[27,0]],"id":52385920},{"atb":[[10.5,0],[8.2,0]],"id":52385883},{"atb":[[5.6,0],[4.6,0]],"id":52385916},{"atb":[[8.6,0],[11.5,0]],"id":52385896},{"atb":[[590,0],[490,0]],"id":52385929},{"atb":[[300,0],[400,0]],"id":52385892},{"atb":[[550,0],[650,0]],"id":52385925},{"atb":[[550,0],[650,0]],"id":52385904},{"atb":[[17,0],[12,0]],"id":52385937},{"atb":[[20,0],[15,0]],"id":52385900},{"atb":[[5.6,0],[4.6,0]],"id":52385933},{"atb":[[16.5,0],[11.5,0]],"id":52385913},{"atb":[[7.4,0],[9.4,0]],"id":52385909},{"atb":[[4.6,0],[3.8,0]],"id":52385888},{"atb":[[18,0],[13,0]],"id":52385921},{"atb":[[13.5,0],[9.4,0]],"id":52385884},{"atb":[[10,0],[15,0]],"id":52385917},{"atb":[[150,0],[250,0]],"id":52385926},{"atb":[[520,0],[620,0]],"id":52385897},{"atb":[[540,0],[440,0]],"id":52385922},{"atb":[[550,0],[650,0]],"id":52385893},{"atb":[[7.4,0],[5.7,0]],"id":52385934},{"atb":[[19.5,0],[14.5,0]],"id":52385905},{"atb":[[20,0],[15,0]],"id":52385930},{"atb":[[200,0],[100,0]],"id":52385901},{"atb":[[7.2,0],[9.2,0]],"id":52385910},{"atb":[[17,0],[12,0]],"id":52385906},{"atb":[[550,0],[650,0]],"id":52385918},{"atb":[[190,0],[95,0]],"id":52385889},{"atb":[[17,0],[12,0]],"id":52385914},{"atb":[[6.8,0],[8.8,0]],"id":52385885},{"atb":[[550,0],[650,0]],"id":52385894},{"atb":[[400,0],[500,0]],"id":52385927},{"atb":[[550,0],[650,0]],"id":52385890},{"atb":[[9.8,0],[7.8,0]],"id":52385923},{"atb":[[5.8,0],[7.6,0]],"id":52385902},{"atb":[[3.85,0],[4.7,0]],"id":52385935},{"atb":[[19,0],[14,0]],"id":52385898},{"atb":[[3.15,0],[3.65,0]],"id":52385931},{"atb":[[300,0],[200,0]],"id":52385911},{"atb":[[18,0],[26,0]],"id":52385907},{"atb":[[9.6,0],[14,0]],"id":52385886},{"atb":[[20,0],[15,0]],"id":52385919},{"atb":[[95,0],[48,0]],"id":52385882},{"atb":[[34,0],[60,0]],"id":52385915},{"atb":[[34,0],[22,0]],"id":52385895},{"atb":[[85,0],[44,0]],"id":52385928},{"atb":[[550,0],[650,0]],"id":52385891},{"atb":[[40,0],[25,0]],"id":52385924},{"atb":[[9.8,0],[14.5,0]],"id":52385903},{"atb":[[7.8,0],[5.9,0]],"id":52385936},{"atb":[[9.6,0],[14,0]],"id":52385899},{"atb":[[16,0],[22,0]],"id":52385932}],"con":true,"img":false}]}
{"op":"mcm","clk":"11449898023","pt":1717315753189,"mc":[{"id":"1.229554917","rc":[{"atb":[[360,0],[410,0],[460,0],[510,0]],"id":52385904},{"atb":[[38,0],[19.5,0],[24,0],[29,0]],"id":52385886},{"atb":[[5.8,0],[5.3,0],[7.6,0],[6.6,0]],"id":52385936}],"con":true,"img":false}]}
{"op":"mcm","clk":"11449898130","pt":1717315754080,"mc":[{"id":"1.229554917","rc":[{"atb":[[520,0.05],[370,0.28],[420,0.19],[470,0.11]],"id":52385904},{"atb":[[40,0.67],[20,5.51],[25,3.27],[30,1.81]],"id":52385886},{"atb":[[6.4,9.69],[7.4,4.09],[5.2,24.91],[5.7,16.69]],"id":52385936}],"con":true,"img":false}]}
{"op":"mcm","clk":"11449898732","pt":1717315759802,"mc":[{"id":"1.229554917","rc":[{"atb":[[520,0],[370,0],[420,0],[470,0]],"id":52385904},{"atb":[[40,0],[20,0],[25,0],[30,0]],"id":52385886}],"con":true,"img":false}]}
{"op":"mcm","clk":"11449898795","pt":1717315760513,"mc":[{"id":"1.229554917","rc":[{"atb":[[360,0.29],[410,0.19],[460,0.12],[510,0.05]],"id":52385904},{"atb":[[38,0.71],[19.5,5.66],[24,3.41],[29,1.87]],"id":52385886}],"con":true,"img":false}]}
{"op":"mcm","clk":"11449899234","pt":1717315764715,"mc":[{"id":"1.229554917","rc":[{"atb":[[9.6,28.36],[14,8.04]],"id":52385912},{"atb":[[350,0.29],[250,1.19]],"id":52385908},{"atb":[[18,14.34],[26,4.18]],"id":52385887},{"atb":[[18.5,13.93],[27,4.01]],"id":52385920},{"atb":[[10.5,11],[8.2,33.87]],"id":52385883},{"atb":[[5.6,22.72],[4.6,67.75]],"id":52385916},{"atb":[[8.6,32.09],[11.5,9.95]],"id":52385896},{"atb":[[360,0.68],[460,0.23]],"id":52385929},{"atb":[[310,0.78],[410,0.25]],"id":52385892},{"atb":[[550,0.44],[650,0.16]],"id":52385925},{"atb":[[550,0.44],[650,0.16]],"id":52385904},{"atb":[[10.5,25.67],[15.5,7.2]],"id":52385937},{"atb":[[20,5.5],[15,17.42]],"id":52385900},{"atb":[[5.6,22.72],[4.6,67.75]],"id":52385933},{"atb":[[16.5,6.74],[11.5,23.22]],"id":52385913},{"atb":[[7.4,38.1],[9.4,12.44]],"id":52385909},{"atb":[[4.6,29.03],[3.8,87.1]],"id":52385888},{"atb":[[18,6.14],[13,20.32]],"id":52385921},{"atb":[[13.5,8.36],[9.4,29.03]],"id":52385884},{"atb":[[10,27.1],[15,7.46]],"id":52385917},{"atb":[[160,0.65],[80,3.08]],"id":52385926},{"atb":[[530,0.46],[630,0.16]],"id":52385897},{"atb":[[320,0.76],[420,0.25]],"id":52385922},{"atb":[[550,0.44],[650,0.16]],"id":52385893},{"atb":[[7.4,16.33],[5.7,51.89]],"id":52385934},{"atb":[[19.5,5.65],[14.5,18.06]],"id":52385905},{"atb":[[19,5.8],[14,18.76]],"id":52385930},{"atb":[[120,0.87],[60,4.13]],"id":52385901},{"atb":[[7.2,39.33],[9.2,12.74]],"id":52385910},{"atb":[[17,6.53],[12,22.17]],"id":52385906},{"atb":[[550,0.44],[650,0.16]],"id":52385918},{"atb":[[190,0.55],[95,2.59]],"id":52385889},{"atb":[[17.5,6.33],[12.5,21.2]],"id":52385914},{"atb":[[6.8,42.05],[8.8,13.4]],"id":52385885},{"atb":[[550,0.44],[650,0.16]],"id":52385894},{"atb":[[280,0.87],[380,0.27]],"id":52385927},{"atb":[[550,0.44],[650,0.16]],"id":52385890},{"atb":[[9.8,11.87],[7.8,35.86]],"id":52385923},{"atb":[[5.8,50.81],[7.6,15.83]],"id":52385902},{"atb":[[3.85,85.58],[4.7,28.25]],"id":52385935},{"atb":[[19.5,5.65],[14.5,18.06]],"id":52385898},{"atb":[[3.2,110.86],[3.7,38.71]],"id":52385931},{"atb":[[310,0.51],[210,1.67]],"id":52385911},{"atb":[[18.5,13.93],[27,4.01]],"id":52385907},{"atb":[[9.6,28.36],[14,8.04]],"id":52385886},{"atb":[[20,5.5],[15,17.42]],"id":52385919},{"atb":[[95,1.11],[48,5.18]],"id":52385882},{"atb":[[44,2.43],[27,9.38]],"id":52385915},{"atb":[[34,3.16],[22,11.61]],"id":52385895},{"atb":[[32,7.86],[55,1.93]],"id":52385928},{"atb":[[550,0.44],[650,0.16]],"id":52385891},{"atb":[[32,3.37],[21,12.19]],"id":52385924},{"atb":[[9.8,27.71],[14.5,7.74]],"id":52385903},{"atb":[[7.8,15.37],[5.9,49.77]],"id":52385936},{"atb":[[9.6,28.36],[14,8.04]],"id":52385899},{"atb":[[16,16.26],[22,4.97]],"id":52385932}],"con":true,"img":false}]}
{"op":"mcm","clk":"11449916865","pt":1717315933591,"mc":[{"id":"1.229554917","rc":[{"atb":[[170,0],[85,0],[120,0],[60,0]],"id":52385882}],"con":true,"img":false}]}
{"op":"mcm","clk":"11449916940","pt":1717315934311,"mc":[{"id":"1.229554917","rc":[{"atb":[[130,0.41],[65,1.64],[180,0.15],[90,0.88]],"id":52385882}],"con":true,"img":false}]}
{"op":"mcm","clk":"11449922514","pt":1717315986321,"mc":[{"id":"1.229554917","rc":[{"atb":[[300,0],[150,0],[200,0],[250,0.97]],"id":52385908},{"atb":[[40,0],[20,0],[25,0],[30,0]],"id":52385937},{"atb":[[140,0],[290,0],[190,0],[240,0]],"id":52385926},{"atb":[[70,0],[38,0],[95,0],[48,0]],"id":52385930},{"atb":[[160,0],[80,0],[210,0],[110,0]],"id":52385901},{"atb":[[290,0],[340,0],[390,0],[240,0]],"id":52385927},{"atb":[[140,0],[70,0],[190,0],[95,0]],"id":52385915},{"atb":[[270,0],[170,0],[220,0],[120,0]],"id":52385928},{"atb":[[160,0],[80,0],[110,0],[55,0]],"id":52385924}],"con":true,"img":false}]}
{"op":"mcm","clk":"11449922583","pt":1717315987020,"mc":[{"id":"1.229554917","rc":[{"atb":[[140,0.75],[290,0.09],[190,0.41],[240,0.22]],"id":52385908},{"atb":[[38,0.71],[19.5,5.66],[24,3.41],[29,1.87]],"id":52385937},{"atb":[[270,0.1],[170,0.47],[220,0.24],[120,0.88]],"id":52385926},{"atb":[[65,0.82],[36,2.99],[90,0.29],[46,1.74]],"id":52385930},{"atb":[[150,0.35],[75,1.41],[200,0.13],[100,0.8]],"id":52385901},{"atb":[[260,0.3],[310,0.17],[360,0.07],[210,0.5]],"id":52385927},{"atb":[[130,0.41],[65,1.64],[180,0.15],[90,0.88]],"id":52385915},{"atb":[[150,0.53],[200,0.26],[100,1.06],[250,0.1]],"id":52385928},{"atb":[[150,0.18],[75,1.06],[100,0.53],[50,2.13]],"id":52385924}],"con":true,"img":false}]}
{"op":"mcm","clk":"11449924816","pt":1717316009928,"mc":[{"id":"1.229554917","rc":[{"atb":[[350,0],[250,0]],"id":52385908},{"atb":[[18,0],[26,0]],"id":52385887},{"atb":[[10.5,0],[8.2,0]],"id":52385883},{"atb":[[8.6,0],[11.5,0]],"id":52385896},{"atb":[[310,0],[410,0]],"id":52385892},{"atb":[[550,0],[650,0]],"id":52385904},{"atb":[[20,0],[15,0]],"id":52385900},{"atb":[[7.4,0],[9.4,0]],"id":52385909},{"atb":[[4.6,0],[3.8,0]],"id":52385888},{"atb":[[13.5,0],[9.4,0]],"id":52385884},{"atb":[[530,0],[630,0]],"id":52385897},{"atb":[[550,0],[650,0]],"id":52385893},{"atb":[[19.5,0],[14.5,0]],"id":52385905},{"atb":[[120,0],[60,0]],"id":52385901},{"atb":[[7.2,0],[9.2,0]],"id":52385910},{"atb":[[17,0],[12,0]],"id":52385906},{"atb":[[190,0],[95,0]],"id":52385889},{"atb":[[6.8,0],[8.8,0]],"id":52385885},{"atb":[[550,0],[650,0]],"id":52385894},{"atb":[[550,0],[650,0]],"id":52385890},{"atb":[[5.8,0],[7.6,0]],"id":52385902},{"atb":[[19.5,0],[14.5,0]],"id":52385898},{"atb":[[310,0.17],[210,0.5]],"id":52385911},{"atb":[[18.5,0],[27,0]],"id":52385907},{"atb":[[9.6,0],[14,0]],"id":52385886},{"atb":[[95,0],[48,0]],"id":52385882},{"atb":[[34,0],[22,0]],"id":52385895},{"atb":[[550,0],[650,0]],"id":52385891},{"atb":[[9.8,0],[14.5,0]],"id":52385903},{"atb":[[9.6,0],[14,0]],"id":52385899}],"con":true,"img":false}]}
{"op":"mcm","clk":"11449924825","pt":1717316010032,"mc":[{"id":"1.229554917","rc":[{"atb":[[9.6,0],[14,0]],"id":52385912},{"atb":[[18.5,0],[27,0]],"id":52385920},{"atb":[[5.6,0],[4.6,0]],"id":52385916},{"atb":[[360,0],[460,0]],"id":52385929},{"atb":[[550,0],[650,0]],"id":52385925},{"atb":[[10.5,0],[15.5,0]],"id":52385937},{"atb":[[5.6,0],[4.6,0]],"id":52385933},{"atb":[[16.5,0],[11.5,0]],"id":52385913},{"atb":[[18,0],[13,0]],"id":52385921},{"atb":[[10,0],[15,0]],"id":52385917},{"atb":[[160,0],[80,0]],"id":52385926},{"atb":[[320,0],[420,0]],"id":52385922},{"atb":[[7.4,0],[5.7,0]],"id":52385934},{"atb":[[19,0],[14,0]],"id":52385930},{"atb":[[550,0],[650,0]],"id":52385918},{"atb":[[17.5,0],[12.5,0]],"id":52385914},{"atb":[[280,0],[380,0]],"id":52385927},{"atb":[[9.8,0],[7.8,0]],"id":52385923},{"atb":[[3.85,0],[4.7,0]],"id":52385935},{"atb":[[3.2,0],[3.7,0]],"id":52385931},{"atb":[[20,0],[15,0]],"id":52385919},{"atb":[[44,0],[27,0]],"id":52385915},{"atb":[[32,0],[55,0]],"id":52385928},{"atb":[[32,0],[21,0]],"id":52385924},{"atb":[[7.8,0],[5.9,0]],"id":52385936},{"atb":[[16,0],[22,0]],"id":52385932}],"con":true,"img":false}]}
{"op":"mcm","clk":"11449928225","pt":1717316044601,"mc":[{"id":"1.229554917","rc":[{"atb":[[9.6,28.36],[14,8.04]],"id":52385912},{"atb":[[350,0.29],[250,0.97]],"id":52385908},{"atb":[[18,14.34],[26,4.18]],"id":52385887},{"atb":[[18.5,13.93],[27,4.01]],"id":52385920},{"atb":[[10.5,11],[8.2,33.87]],"id":52385883},{"atb":[[5.6,22.72],[4.6,67.75]],"id":52385916},{"atb":[[8.6,32.09],[11.5,9.95]],"id":52385896},{"atb":[[360,0.68],[460,0.23]],"id":52385929},{"atb":[[310,0.78],[410,0.25]],"id":52385892},{"atb":[[550,0.44],[650,0.16]],"id":52385925},{"atb":[[550,0.44],[650,0.16]],"id":52385904},{"atb":[[10.5,25.67],[15.5,7.2]],"id":52385937},{"atb":[[20,5.5],[15,17.42]],"id":52385900},{"atb":[[5.6,22.72],[4.6,67.75]],"id":52385933},{"atb":[[16.5,6.74],[11.5,23.22]],"id":52385913},{"atb":[[7.4,38.1],[9.4,12.44]],"id":52385909},{"atb":[[4.6,29.03],[3.8,87.1]],"id":52385888},{"atb":[[18,6.14],[13,20.32]],"id":52385921},{"atb":[[13.5,8.36],[9.4,29.03]],"id":52385884},{"atb":[[10,27.1],[15,7.46]],"id":52385917},{"atb":[[160,0.65],[80,3.08]],"id":52385926},{"atb":[[530,0.46],[630,0.16]],"id":52385897},{"atb":[[320,0.76],[420,0.25]],"id":52385922},{"atb":[[550,0.44],[650,0.16]],"id":52385893},{"atb":[[7.4,16.33],[5.7,51.89]],"id":52385934},{"atb":[[19.5,5.65],[14.5,18.06]],"id":52385905},{"atb":[[19,5.8],[14,18.76]],"id":52385930},{"atb":[[120,0.87],[60,4.13]],"id":52385901},{"atb":[[7.2,39.33],[9.2,12.74]],"id":52385910},{"atb":[[17,6.53],[12,22.17]],"id":52385906},{"atb":[[550,0.44],[650,0.16]],"id":52385918},{"atb":[[190,0.55],[95,2.59]],"id":52385889},{"atb":[[17.5,6.33],[12.5,21.2]],"id":52385914},{"atb":[[6.8,42.05],[8.8,13.4]],"id":52385885},{"atb":[[550,0.44],[650,0.16]],"id":52385894},{"atb":[[280,0.87],[380,0.27]],"id":52385927},{"atb":[[550,0.44],[650,0.16]],"id":52385890},{"atb":[[9.8,11.87],[7.8,35.86]],"id":52385923},{"atb":[[5.8,50.81],[7.6,15.83]],"id":52385902},{"atb":[[3.85,85.58],[4.7,28.25]],"id":52385935},{"atb":[[19.5,5.65],[14.5,18.06]],"id":52385898},{"atb":[[3.2,110.86],[3.7,38.71]],"id":52385931},{"atb":[[310,0.51],[210,1.67]],"id":52385911},{"atb":[[18.5,13.93],[27,4.01]],"id":52385907},{"atb":[[9.6,28.36],[14,8.04]],"id":52385886},{"atb":[[20,5.5],[15,17.42]],"id":52385919},{"atb":[[95,1.11],[48,5.18]],"id":52385882},{"atb":[[44,2.43],[27,9.38]],"id":52385915},{"atb":[[34,3.16],[22,11.61]],"id":52385895},{"atb":[[32,7.86],[55,1.93]],"id":52385928},{"atb":[[550,0.44],[650,0.16]],"id":52385891},{"atb":[[32,3.37],[21,12.19]],"id":52385924},{"atb":[[9.8,27.71],[14.5,7.74]],"id":52385903},{"atb":[[7.8,15.37],[5.9,49.77]],"id":52385936},{"atb":[[9.6,28.36],[14,8.04]],"id":52385899},{"atb":[[16,16.26],[22,4.97]],"id":52385932}],"con":true,"img":false}]}
{"op":"mcm","clk":"11449935445","pt":1717316123107,"mc":[{"id":"1.229554917","rc":[{"atb":[[75,0],[40,0],[50,0],[30,0]],"id":52385906}],"con":true,"img":false}]}
{"op":"mcm","clk":"11449935517","pt":1717316123770,"mc":[{"id":"1.229554917","rc":[{"atb":[[32,3.37],[80,0.33],[42,1.92],[55,0.97]],"id":52385906}],"con":true,"img":false}]}
{"op":"mcm","clk":"11449955010","pt":1717316342779,"mc":[{"id":"1.229554917","rc":[{"atb":[[38,0],[19.5,0],[24,0],[29,0]],"id":52385937},{"atb":[[32,0],[80,0],[42,0],[55,0]],"id":52385906},{"atb":[[32,0],[18,0],[21,0],[26,0]],"id":52385923},{"atb":[[18,0],[10.5,0],[13,0],[15.5,0]],"id":52385902}],"con":true,"img":false}]}
{"op":"mcm","clk":"11449955019","pt":1717316342876,"mc":[{"id":"1.229554917","rc":[{"atb":[[260,0],[310,0.34],[360,0],[210,1.16]],"id":52385911}],"con":true,"img":false}]}
{"op":"mcm","clk":"11449956797","pt":1717316366555,"mc":[{"id":"1.229554917","rc":[{"atb":[[32,0],[42,0],[26,0],[55,0]],"id":52385899}],"con":true,"img":false}]}
{"op":"mcm","clk":"11449956826","pt":1717316366970,"mc":[{"id":"1.229554917","rc":[{"atb":[[32,3.37],[80,0.33],[42,1.92],[55,0.97]],"id":52385906},{"atb":[[32,0.84],[18,6.15],[21,3.92],[26,2.09]],"id":52385923},{"atb":[[18,1.54],[10.5,11.01],[13,6.54],[15.5,3.61]],"id":52385902},{"atb":[[260,0.3],[310,0.51],[360,0.07],[210,1.67]],"id":52385911}],"con":true,"img":false}]}
{"op":"mcm","clk":"11449956835","pt":1717316367028,"mc":[{"id":"1.229554917","rc":[{"atb":[[36,0.75],[38,0.71],[19.5,5.66],[19,5.81],[23,3.57],[24,3.41],[28,1.94],[29,1.87]],"id":52385937}],"con":true,"img":false}]}
{"op":"mcm","clk":"11449956926","pt":1717316368257,"mc":[{"id":"1.229554917","rc":[{"atb":[[32,2.53],[42,1.28],[26,4.19],[55,0.49]],"id":52385899}],"con":true,"img":false}]}
{"op":"mcm","clk":"11449957999","pt":1717316382498,"mc":[{"id":"1.229554917","rc":[{"atb":[[36,0],[19,0],[23,0],[28,0]],"id":52385937}],"con":true,"img":false}]}
{"op":"mcm","clk":"11449959675","pt":1717316403803,"mc":[{"id":"1.229554917","rc":[{"atb":[[65,0],[36,0],[90,0],[46,0]],"id":52385887},{"atb":[[16.5,0],[9.6,0],[11.5,0],[14,0]],"id":52385916},{"atb":[[270,0],[320,0],[370,0],[420,0]],"id":52385929},{"atb":[[38,0],[19.5,0],[24,0],[29,0]],"id":52385937},{"atb":[[70,0],[38,0],[48,0],[29,0]],"id":52385913},{"atb":[[280,0],[330,0],[180,0],[230,0]],"id":52385922},{"atb":[[150,0],[75,0],[200,0],[100,0]],"id":52385901},{"atb":[[32,0],[80,0],[42,0],[55,0]],"id":52385906},{"atb":[[32,0],[18,0],[21,0],[26,0]],"id":52385923},{"atb":[[130,0],[65,0],[180,0],[90,0]],"id":52385882},{"atb":[[32,0],[42,0],[26,0],[55,0]],"id":52385899}],"con":true,"img":false}]}
{"op":"mcm","clk":"11449959713","pt":1717316404216,"mc":[{"id":"1.229554917","rc":[{"atb":[[40,0],[50,0],[25,0],[30,0]],"id":52385912}],"con":true,"img":false}]}
{"op":"mcm","clk":"11449959741","pt":1717316404525,"mc":[{"id":"1.229554917","rc":[{"atb":[[32,3.37],[80,0.33],[42,1.92],[55,0.97]],"id":52385887},{"atb":[[18,1.54],[10.5,11.01],[13,6.54],[15.5,3.61]],"id":52385916},{"atb":[[300,0.26],[350,0.15],[400,0.07],[250,0.42]],"id":52385929},{"atb":[[36,0.75],[19,5.81],[23,3.57],[28,1.94]],"id":52385937},{"atb":[[75,0.36],[40,2.01],[50,1.07],[30,3.61]],"id":52385913},{"atb":[[270,0.19],[320,0.85],[170,0.62],[220,0.36]],"id":52385922},{"atb":[[140,0.38],[70,1.52],[190,0.14],[95,0.84]],"id":52385901},{"atb":[[34,3.17],[85,0.31],[44,1.83],[60,0.88]],"id":52385906},{"atb":[[34,0.8],[18.5,5.98],[22,3.74],[27,2.01]],"id":52385923},{"atb":[[160,0.16],[80,0.99],[110,0.48],[55,1.94]],"id":52385882},{"atb":[[34,2.38],[44,1.22],[27,4.02],[60,0.44]],"id":52385899}],"con":true,"img":false}]}
{"op":"mcm","clk":"11449959760","pt":1717316404682,"mc":[{"id":"1.229554917","rc":[{"atb":[[260,0],[310,0.34],[360,0],[210,1.16]],"id":52385911}],"con":true,"img":false}]}
{"op":"mcm","clk":"11449959774","pt":1717316404889,"mc":[{"id":"1.229554917","rc":[{"atb":[[40,1.34],[50,0.53],[25,4.36],[30,2.71]],"id":52385912}],"con":true,"img":false}]}
{"op":"mcm","clk":"11449959797","pt":1717316405195,"mc":[{"id":"1.229554917","rc":[{"atb":[[34,0],[44,0],[27,0],[60,0]],"id":52385899}],"con":true,"img":false}]}
{"op":"mcm","clk":"11449959805","pt":1717316405300,"mc":[{"id":"1.229554917","rc":[{"atb":[[18,0],[10.5,0],[13,0],[15.5,0]],"id":52385916},{"atb":[[75,0],[40,0],[50,0],[30,0]],"id":52385913},{"atb":[[34,0],[85,0],[44,0],[60,0]],"id":52385906},{"atb":[[34,0],[18.5,0],[22,0],[27,0]],"id":52385923}],"con":true,"img":false}]}
{"op":"mcm","clk":"11449959813","pt":1717316405400,"mc":[{"id":"1.229554917","rc":[{"atb":[[260,0.3],[310,0.51],[360,0.07],[210,1.67]],"id":52385911}],"con":true,"img":false}]}
{"op":"mcm","clk":"11449959854","pt":1717316405923,"mc":[{"id":"1.229554917","rc":[{"atb":[[32,2.53],[42,1.28],[26,4.19],[55,0.49]],"id":52385899}],"con":true,"img":false}]}
{"op":"mcm","clk":"11449959865","pt":1717316406126,"mc":[{"id":"1.229554917","rc":[{"atb":[[16.5,1.69],[9.6,12.17],[11.5,7.48],[14,4.02]],"id":52385916},{"atb":[[70,0.38],[38,2.12],[48,1.11],[29,3.74]],"id":52385913},{"atb":[[32,3.37],[80,0.33],[42,1.92],[55,0.97]],"id":52385906},{"atb":[[32,0.84],[18,6.15],[21,3.92],[26,2.09]],"id":52385923}],"con":true,"img":false}]}
{"op":"mcm","clk":"11449962204","pt":1717316434174,"mc":[{"id":"1.229554917","rc":[{"atb":[[40,0],[50,0],[25,0],[30,0]],"id":52385912},{"atb":[[16.5,0],[9.6,0],[11.5,0],[14,0]],"id":52385916},{"atb":[[70,0],[38,0],[48,0],[29,0]],"id":52385913},{"atb":[[32,0],[80,0],[42,0],[55,0]],"id":52385906},{"atb":[[32,0],[18,0],[21,0],[26,0]],"id":52385923},{"atb":[[260,0],[310,0.34],[360,0],[210,1.16]],"id":52385911},{"atb":[[32,0],[42,0],[26,0],[55,0]],"id":52385899}],"con":true,"img":false}]}
{"op":"mcm","clk":"11449962270","pt":1717316434854,"mc":[{"id":"1.229554917","rc":[{"atb":[[32,2.53],[42,1.28],[26,4.19],[55,0.49]],"id":52385912},{"atb":[[18,1.54],[10.5,11.01],[13,6.54],[15.5,3.61]],"id":52385916},{"atb":[[75,0.36],[40,2.01],[50,1.07],[30,3.61]],"id":52385913},{"atb":[[34,3.17],[85,0.31],[44,1.83],[60,0.88]],"id":52385906},{"atb":[[34,0.8],[18.5,5.98],[22,3.74],[27,2.01]],"id":52385923},{"atb":[[300,0.17],[350,0.07],[200,0.53],[250,0.31]],"id":52385911},{"atb":[[34,2.38],[44,1.22],[27,4.02],[60,0.44]],"id":52385899}],"con":true,"img":false}]}
{"op":"mcm","clk":"11449962698","pt":1717316440581,"mc":[{"id":"1.229554917","rc":[{"atb":[[32,0],[42,0],[26,0],[55,0]],"id":52385912},{"atb":[[18,0],[10.5,0],[13,0],[15.5,0]],"id":52385916},{"atb":[[75,0],[40,0],[50,0],[30,0]],"id":52385913},{"atb":[[34,0],[85,0],[44,0],[60,0]],"id":52385906},{"atb":[[34,0],[18.5,0],[22,0],[27,0]],"id":52385923},{"atb":[[34,0],[44,0],[27,0],[60,0]],"id":52385899}],"con":true,"img":false}]}
{"op":"mcm","clk":"11449962758","pt":1717316441256,"mc":[{"id":"1.229554917","rc":[{"atb":[[40,1.34],[50,0.53],[25,4.36],[30,2.71]],"id":52385912},{"atb":[[16.5,1.69],[9.6,12.17],[11.5,7.48],[14,4.02]],"id":52385916},{"atb":[[70,0.38],[38,2.12],[48,1.11],[29,3.74]],"id":52385913},{"atb":[[32,3.37],[80,0.33],[42,1.92],[55,0.97]],"id":52385906},{"atb":[[32,0.84],[18,6.15],[21,3.92],[26,2.09]],"id":52385923},{"atb":[[32,2.53],[42,1.28],[26,4.19],[55,0.49]],"id":52385899}],"con":true,"img":false}]}
{"op":"mcm","clk":"11449962863","pt":1717316442339,"mc":[{"id":"1.229554917","rc":[{"atb":[[6.4,0],[7.4,0],[5.2,0],[5.7,0]],"id":52385936}],"con":true,"img":false}]}
{"op":"mcm","clk":"11449962936","pt":1717316443165,"mc":[{"id":"1.229554917","rc":[{"atb":[[5.8,16.35],[5.3,24.33],[7.6,3.97],[6.6,9.34]],"id":52385936}],"con":true,"img":false}]}
{"op":"mcm","clk":"11449979412","pt":1717316677354,"mc":[{"id":"1.229554917","rc":[{"atb":[[150,0],[200,0],[100,0],[250,0]],"id":52385928}],"con":true,"img":false}]}
{"op":"mcm","clk":"11449979451","pt":1717316677821,"mc":[{"id":"1.229554917","rc":[{"atb":[[260,0],[310,0],[360,0],[210,0]],"id":52385927}],"con":true,"img":false}]}
{"op":"mcm","clk":"11449979469","pt":1717316678039,"mc":[{"id":"1.229554917","rc":[{"atb":[[260,0.1],[160,0.49],[210,0.25],[110,0.96]],"id":52385928}],"con":true,"img":false}]}
{"op":"mcm","clk":"11449979512","pt":1717316678542,"mc":[{"id":"1.229554917","rc":[{"atb":[[270,0.29],[320,0.16],[370,0.07],[220,0.48]],"id":52385927}],"con":true,"img":false}]}
{"op":"mcm","clk":"11449979526","pt":1717316678747,"mc":[{"id":"1.229554917","rc":[{"atb":[[260,0],[160,0],[210,0],[110,0]],"id":52385928}],"con":true,"img":false}]}
{"op":"mcm","clk":"11449979555","pt":1717316679228,"mc":[{"id":"1.229554917","rc":[{"atb":[[270,0],[320,0],[370,0],[220,0]],"id":52385927}],"con":true,"img":false}]}
{"op":"mcm","clk":"11449979571","pt":1717316679426,"mc":[{"id":"1.229554917","rc":[{"atb":[[150,0.53],[200,0.26],[100,1.06],[250,0.1]],"id":52385928}],"con":true,"img":false}]}
{"op":"mcm","clk":"11449979608","pt":1717316679943,"mc":[{"id":"1.229554917","rc":[{"atb":[[260,0.3],[310,0.17],[360,0.07],[210,0.5]],"id":52385927}],"con":true,"img":false}]}
{"op":"mcm","clk":"11449981573","pt":1717316708489,"mc":[{"id":"1.229554917","rc":[{"atb":[[150,0],[200,0],[100,0],[250,0]],"id":52385928}],"con":true,"img":false}]}
{"op":"mcm","clk":"11449981624","pt":1717316709166,"mc":[{"id":"1.229554917","rc":[{"atb":[[260,0.1],[160,0.49],[210,0.25],[110,0.96]],"id":52385928}],"con":true,"img":false}]}
{"op":"mcm","clk":"11449981730","pt":1717316710783,"mc":[{"id":"1.229554917","rc":[{"atb":[[260,0],[160,0],[210,0],[110,0]],"id":52385928}],"con":true,"img":false}]}
{"op":"mcm","clk":"11449981788","pt":1717316711461,"mc":[{"id":"1.229554917","rc":[{"atb":[[150,0.53],[200,0.26],[100,1.06],[250,0.1]],"id":52385928}],"con":true,"img":false}]}
{"op":"mcm","clk":"11449982814","pt":1717316726184,"mc":[{"id":"1.229554917","rc":[{"atb":[[140,0],[290,0],[190,0],[240,0]],"id":52385908},{"atb":[[8,0],[5.5,0],[6,0],[7,0]],"id":52385888},{"atb":[[34,0],[18.5,0],[22,0],[27,0]],"id":52385884},{"atb":[[270,0],[170,0],[220,0],[120,0]],"id":52385926},{"atb":[[260,0],[310,0],[360,0],[210,0]],"id":52385927},{"atb":[[130,0],[65,0],[180,0],[90,0]],"id":52385915},{"atb":[[150,0],[200,0],[100,0],[250,0]],"id":52385928}],"con":true,"img":false}]}
{"op":"mcm","clk":"11449982856","pt":1717316726901,"mc":[{"id":"1.229554917","rc":[{"atb":[[270,0.1],[170,0.47],[220,0.24],[120,0.88]],"id":52385908},{"atb":[[5.6,22.75],[7.2,8.44],[6.2,15.09],[8.2,3.63]],"id":52385888},{"atb":[[32,0.84],[18,6.15],[21,3.92],[26,2.09]],"id":52385884},{"atb":[[260,0.1],[160,1.15],[210,0.25],[110,0.96]],"id":52385926},{"atb":[[300,0.17],[350,0.07],[200,0.53],[250,0.31]],"id":52385927},{"atb":[[140,0.38],[70,1.52],[190,0.14],[95,0.84]],"id":52385915},{"atb":[[260,0.1],[160,0.49],[210,0.25],[110,0.96]],"id":52385928}],"con":true,"img":false}]}
{"op":"mcm","clk":"11449983713","pt":1717316739409,"mc":[{"id":"1.229554917","rc":[{"atb":[[140,0],[70,0],[190,0],[95,0]],"id":52385915},{"atb":[[260,0],[160,0],[210,0],[110,0]],"id":52385928}],"con":true,"img":false}]}
{"op":"mcm","clk":"11449983718","pt":1717316739511,"mc":[{"id":"1.229554917","rc":[{"atb":[[32,0],[18,0],[21,0],[26,0]],"id":52385884},{"atb":[[260,0],[160,0.65],[210,0],[110,0]],"id":52385926}],"con":true,"img":false}]}
{"op":"mcm","clk":"11449983762","pt":1717316740106,"mc":[{"id":"1.229554917","rc":[{"atb":[[130,0.41],[65,1.64],[180,0.15],[90,0.88]],"id":52385915},{"atb":[[150,0.53],[200,0.26],[100,1.06],[250,0.1]],"id":52385928}],"con":true,"img":false}]}
{"op":"mcm","clk":"11449983768","pt":1717316740211,"mc":[{"id":"1.229554917","rc":[{"atb":[[34,0.8],[18.5,5.98],[22,3.74],[27,2.01]],"id":52385884},{"atb":[[270,0.1],[170,0.47],[220,0.24],[120,0.88]],"id":52385926}],"con":true,"img":false}]}
{"op":"mcm","clk":"11449984935","pt":1717316756848,"mc":[{"id":"1.229554917","rc":[{"atb":[[34,0],[18.5,0],[22,0],[27,0]],"id":52385884},{"atb":[[270,0],[170,0],[220,0],[120,0]],"id":52385926},{"atb":[[130,0],[65,0],[180,0],[90,0]],"id":52385915},{"atb":[[150,0],[200,0],[100,0],[250,0]],"id":52385928}],"con":true,"img":false}]}
{"op":"mcm","clk":"11449984993","pt":1717316757537,"mc":[{"id":"1.229554917","rc":[{"atb":[[32,0.84],[18,6.15],[21,3.92],[26,2.09]],"id":52385884},{"atb":[[260,0.1],[160,1.15],[210,0.25],[110,0.96]],"id":52385926},{"atb":[[260,0.1],[160,0.49],[210,0.25],[110,0.96]],"id":52385928}],"con":true,"img":false}]}
{"op":"mcm","clk":"11449984997","pt":1717316757623,"mc":[{"id":"1.229554917","rc":[{"atb":[[140,0.38],[70,1.52],[190,0.14],[95,0.84]],"id":52385915}],"con":true,"img":false}]}
{"op":"mcm","clk":"11449985965","pt":1717316769879,"mc":[{"id":"1.229554917","rc":[{"atb":[[32,0],[18,0],[21,0],[26,0]],"id":52385884},{"atb":[[140,0],[70,0],[190,0],[95,0]],"id":52385915},{"atb":[[260,0],[160,0],[210,0],[110,0]],"id":52385928}],"con":true,"img":false}]}
{"op":"mcm","clk":"11449986019","pt":1717316770556,"mc":[{"id":"1.229554917","rc":[{"atb":[[34,0.8],[18.5,5.98],[22,3.74],[27,2.01]],"id":52385884},{"atb":[[130,0.41],[65,1.64],[180,0.15],[90,0.88]],"id":52385915},{"atb":[[150,0.53],[200,0.26],[100,1.06],[250,0.1]],"id":52385928}],"con":true,"img":false}]}
{"op":"mcm","clk":"11449986724","pt":1717316780028,"mc":[{"id":"1.229554917","rc":[{"atb":[[840,0],[890,0],[940,0],[990,0]],"id":52385893},{"atb":[[290,0],[340,0],[390,0],[240,0]],"id":52385889},{"atb":[[140,0],[190,0],[95,0],[240,0]],"id":52385895},{"atb":[[810,0],[860,0],[910,0],[960,0]],"id":52385891}],"con":true,"img":false}]}
{"op":"mcm","clk":"11449986775","pt":1717316780755,"mc":[{"id":"1.229554917","rc":[{"atb":[[820,0.13],[870,0.09],[920,0.06],[970,0.03]],"id":52385893},{"atb":[[290,0.18],[340,0.08],[190,1.11],[240,0.33]],"id":52385889},{"atb":[[150,0.35],[75,1.41],[200,0.13],[100,0.8]],"id":52385895},{"atb":[[680,0.15],[730,0.11],[780,0.07],[830,0.03]],"id":52385891}],"con":true,"img":false}]}
{"op":"mcm","clk":"11449987269","pt":1717316786887,"mc":[{"id":"1.229554917","rc":[{"atb":[[820,0],[870,0],[920,0],[970,0]],"id":52385893},{"atb":[[560,0],[610,0],[460,0],[510,0]],"id":52385890},{"atb":[[150,0],[75,0],[200,0],[100,0]],"id":52385895},{"atb":[[680,0],[730,0],[780,0],[830,0]],"id":52385891}],"con":true,"img":false}]}
{"op":"mcm","clk":"11449987308","pt":1717316787559,"mc":[{"id":"1.229554917","rc":[{"atb":[[790,0.13],[840,0.09],[890,0.06],[940,0.03]],"id":52385893},{"atb":[[550,0.54],[600,0.04],[450,0.24],[500,0.16]],"id":52385890},{"atb":[[160,0.33],[80,1.32],[210,0.13],[110,0.72]],"id":52385895}],"con":true,"img":false}]}
{"op":"mcm","clk":"11449987336","pt":1717316787966,"mc":[{"id":"1.229554917","rc":[{"atb":[[660,0.16],[710,0.11],[760,0.07],[810,0.03]],"id":52385891}],"con":true,"img":false}]}
{"op":"mcm","clk":"11449988223","pt":1717316800274,"mc":[{"id":"1.229554917","rc":[{"atb":[[790,0],[840,0],[890,0],[940,0]],"id":52385893}],"con":true,"img":false}]}
{"op":"mcm","clk":"11449988279","pt":1717316800998,"mc":[{"id":"1.229554917","rc":[{"atb":[[820,0.13],[870,0.09],[920,0.06],[970,0.03]],"id":52385893}],"con":true,"img":false}]}
{"op":"mcm","clk":"11449989458","pt":1717316817414,"mc":[{"id":"1.229554917","rc":[{"atb":[[820,0],[870,0],[920,0],[970,0]],"id":52385893}],"con":true,"img":false}]}
{"op":"mcm","clk":"11449989531","pt":1717316818296,"mc":[{"id":"1.229554917","rc":[{"atb":[[790,0.13],[840,0.09],[890,0.06],[940,0.03]],"id":52385893}],"con":true,"img":false}]}
{"op":"mcm","clk":"11449990447","pt":1717316830712,"mc":[{"id":"1.229554917","rc":[{"atb":[[790,0],[840,0],[890,0],[940,0]],"id":52385893}],"con":true,"img":false}]}
{"op":"mcm","clk":"11449990504","pt":1717316831427,"mc":[{"id":"1.229554917","rc":[{"atb":[[820,0.13],[870,0.09],[920,0.06],[970,0.03]],"id":52385893}],"con":true,"img":false}]}
{"op":"mcm","clk":"11449991813","pt":1717316847818,"mc":[{"id":"1.229554917","rc":[{"atb":[[820,0],[870,0],[920,0],[970,0]],"id":52385893}],"con":true,"img":false}]}
{"op":"mcm","clk":"11449991865","pt":1717316848534,"mc":[{"id":"1.229554917","rc":[{"atb":[[790,0.13],[840,0.09],[890,0.06],[940,0.03]],"id":52385893}],"con":true,"img":false}]}
{"op":"mcm","clk":"11449993618","pt":1717316870367,"mc":[{"id":"1.229554917","rc":[{"atb":[[350,0],[250,0]],"id":52385908},{"atb":[[18,0],[26,0]],"id":52385887},{"atb":[[10.5,0],[8.2,0]],"id":52385883},{"atb":[[8.6,0],[11.5,0]],"id":52385896},{"atb":[[310,0],[410,0]],"id":52385892},{"atb":[[550,0],[650,0]],"id":52385904},{"atb":[[20,0],[15,0]],"id":52385900},{"atb":[[7.4,0],[9.4,0]],"id":52385909},{"atb":[[4.6,0],[3.8,0]],"id":52385888},{"atb":[[13.5,0],[9.4,0]],"id":52385884},{"atb":[[530,0],[630,0]],"id":52385897},{"atb":[[550,0],[650,0]],"id":52385893},{"atb":[[19.5,0],[14.5,0]],"id":52385905},{"atb":[[120,0],[60,0]],"id":52385901},{"atb":[[7.2,0],[9.2,0]],"id":52385910},{"atb":[[17,0],[12,0]],"id":52385906},{"atb":[[190,0.55],[95,0]],"id":52385889},{"atb":[[6.8,0],[8.8,0]],"id":52385885},{"atb":[[550,0],[650,0]],"id":52385894},{"atb":[[550,0.09],[650,0]],"id":52385890},{"atb":[[5.8,0],[7.6,0]],"id":52385902},{"atb":[[19.5,0],[14.5,0]],"id":52385898},{"atb":[[310,0],[210,0]],"id":52385911},{"atb":[[18.5,0],[27,0]],"id":52385907},{"atb":[[9.6,0],[14,0]],"id":52385886},{"atb":[[95,0],[48,0]],"id":52385882},{"atb":[[34,0],[22,0]],"id":52385895},{"atb":[[550,0],[650,0]],"id":52385891},{"atb":[[9.8,0],[14.5,0]],"id":52385903},{"atb":[[9.6,0],[14,0]],"id":52385899}],"con":true,"img":false}]}
{"op":"mcm","clk":"11449993627","pt":1717316870467,"mc":[{"id":"1.229554917","rc":[{"atb":[[9.6,0],[14,0]],"id":52385912},{"atb":[[18.5,0],[27,0]],"id":52385920},{"atb":[[5.6,0],[4.6,0]],"id":52385916},{"atb":[[360,0],[460,0]],"id":52385929},{"atb":[[550,0],[650,0]],"id":52385925},{"atb":[[10.5,0],[15.5,0]],"id":52385937},{"atb":[[5.6,0],[4.6,0]],"id":52385933},{"atb":[[16.5,0],[11.5,0]],"id":52385913},{"atb":[[18,0],[13,0]],"id":52385921},{"atb":[[10,0],[15,0]],"id":52385917},{"atb":[[160,0.49],[80,0]],"id":52385926},{"atb":[[320,0.08],[420,0]],"id":52385922},{"atb":[[7.4,0],[5.7,0]],"id":52385934},{"atb":[[19,0],[14,0]],"id":52385930},{"atb":[[550,0],[650,0]],"id":52385918},{"atb":[[17.5,0],[12.5,0]],"id":52385914},{"atb":[[280,0],[380,0]],"id":52385927},{"atb":[[9.8,0],[7.8,0]],"id":52385923},{"atb":[[3.85,0],[4.7,0]],"id":52385935},{"atb":[[3.2,0],[3.7,0]],"id":52385931},{"atb":[[20,0],[15,0]],"id":52385919},{"atb":[[44,0],[27,0]],"id":52385915},{"atb":[[32,0],[55,0]],"id":52385928},{"atb":[[32,0],[21,0]],"id":52385924},{"atb":[[7.8,0],[5.9,0]],"id":52385936},{"atb":[[16,0],[22,0]],"id":52385932}],"con":true,"img":false}]}
{"op":"mcm","clk":"11449993658","pt":1717316870780,"mc":[{"id":"1.229554917","rc":[{"atb":[[34,0],[18.5,0],[22,0],[27,0]],"id":52385884}],"con":true,"img":false}]}
{"op":"mcm","clk":"11449993665","pt":1717316870838,"mc":[{"id":"1.229554917","rc":[{"atb":[[32,0],[18,0],[21,0],[26,0]],"id":52385896},{"atb":[[40,0],[50,0],[25,0],[30,0]],"id":52385903}],"con":true,"img":false}]}
{"op":"mcm","clk":"11449993722","pt":1717316871462,"mc":[{"id":"1.229554917","rc":[{"atb":[[32,0.84],[18,6.15],[21,3.92],[26,2.09]],"id":52385884}],"con":true,"img":false}]}
{"op":"mcm","clk":"11449993733","pt":1717316871565,"mc":[{"id":"1.229554917","rc":[{"atb":[[17.5,6.34],[20,4.13],[25,2.18],[30,0.9]],"id":52385896},{"atb":[[34,1.59],[44,0.61],[22,4.98],[27,3.02]],"id":52385903}],"con":true,"img":false}]}
{"op":"mcm","clk":"11449996407","pt":1717316901996,"mc":[{"id":"1.229554917","rc":[{"atb":[[350,0.29],[250,0.97]],"id":52385908},{"atb":[[18,14.34],[26,4.18]],"id":52385887},{"atb":[[10.5,11],[8.2,33.87]],"id":52385883},{"atb":[[8.6,32.09],[11.5,9.95]],"id":52385896},{"atb":[[310,0.78],[410,0.25]],"id":52385892},{"atb":[[550,0.44],[650,0.16]],"id":52385904},{"atb":[[20,5.5],[15,17.42]],"id":52385900},{"atb":[[7.4,38.1],[9.4,12.44]],"id":52385909},{"atb":[[4.6,29.03],[3.8,87.1]],"id":52385888},{"atb":[[13.5,8.36],[9.4,29.03]],"id":52385884},{"atb":[[530,0.46],[630,0.16]],"id":52385897},{"atb":[[550,0.44],[650,0.16]],"id":52385893},{"atb":[[19.5,5.65],[14.5,18.06]],"id":52385905},{"atb":[[120,0.87],[60,4.13]],"id":52385901},{"atb":[[17,6.53],[12,22.17]],"id":52385906},{"atb":[[190,1.11],[95,2.59]],"id":52385889},{"atb":[[6.8,42.05],[8.8,13.4]],"id":52385885},{"atb":[[550,0.44],[650,0.16]],"id":52385894},{"atb":[[550,0.54],[650,0.16]],"id":52385890},{"atb":[[5.8,50.81],[7.6,15.83]],"id":52385902},{"atb":[[19.5,5.65],[14.5,18.06]],"id":52385898},{"atb":[[18.5,13.93],[27,4.01]],"id":52385907},{"atb":[[9.6,28.36],[14,8.04]],"id":52385886},{"atb":[[95,1.11],[48,5.18]],"id":52385882},{"atb":[[34,3.16],[22,11.61]],"id":52385895},{"atb":[[550,0.44],[650,0.16]],"id":52385891},{"atb":[[9.8,27.71],[14.5,7.74]],"id":52385903},{"atb":[[9.6,28.36],[14,8.04]],"id":52385899}],"con":true,"img":false}]}
{"op":"mcm","clk":"11449996416","pt":1717316902105,"mc":[{"id":"1.229554917","rc":[{"atb":[[9.6,28.36],[14,8.04]],"id":52385912},{"atb":[[18.5,13.93],[27,4.01]],"id":52385920},{"atb":[[5.6,22.72],[4.6,67.75]],"id":52385916},{"atb":[[360,0.68],[460,0.23]],"id":52385929},{"atb":[[550,0.44],[650,0.16]],"id":52385925},{"atb":[[10.5,25.67],[15.5,7.2]],"id":52385937},{"atb":[[5.6,22.72],[4.6,67.75]],"id":52385933},{"atb":[[16.5,6.74],[11.5,23.22]],"id":52385913},{"atb":[[18,6.14],[13,20.32]],"id":52385921},{"atb":[[10,27.1],[15,7.46]],"id":52385917},{"atb":[[160,1.15],[80,3.08]],"id":52385926},{"atb":[[320,0.85],[420,0.25]],"id":52385922},{"atb":[[7.4,16.33],[5.7,51.89]],"id":52385934},{"atb":[[19,5.8],[14,18.76]],"id":52385930},{"atb":[[7.2,39.33],[9.2,12.74]],"id":52385910},{"atb":[[550,0.44],[650,0.16]],"id":52385918},{"atb":[[17.5,6.33],[12.5,21.2]],"id":52385914},{"atb":[[280,0.87],[380,0.27]],"id":52385927},{"atb":[[9.8,11.87],[7.8,35.86]],"id":52385923},{"atb":[[3.85,85.58],[4.7,28.25]],"id":52385935},{"atb":[[3.2,110.86],[3.7,38.71]],"id":52385931},{"atb":[[310,0.34],[210,1.16]],"id":52385911},{"atb":[[20,5.5],[15,17.42]],"id":52385919},{"atb":[[44,2.43],[27,9.38]],"id":52385915},{"atb":[[32,7.86],[55,1.93]],"id":52385928},{"atb":[[32,3.37],[21,12.19]],"id":52385924},{"atb":[[7.8,15.37],[5.9,49.77]],"id":52385936},{"atb":[[16,16.26],[22,4.97]],"id":52385932}],"con":true,"img":false}]}
{"op":"mcm","clk":"11450003996","pt":1717316992763,"mc":[{"id":"1.229554917","rc":[{"atb":[[9.6,0],[14,0]],"id":52385912},{"atb":[[350,0],[250,0]],"id":52385908},{"atb":[[18,0],[26,0]],"id":52385887},{"atb":[[18.5,0],[27,0]],"id":52385920},{"atb":[[10.5,0],[8.2,0]],"id":52385883},{"atb":[[5.6,0],[4.6,0]],"id":52385916},{"atb":[[8.6,0],[11.5,0]],"id":52385896},{"atb":[[360,0],[460,0]],"id":52385929},{"atb":[[310,0],[410,0]],"id":52385892},{"atb":[[550,0],[650,0]],"id":52385925},{"atb":[[550,0],[650,0]],"id":52385904},{"atb":[[10.5,0],[15.5,0]],"id":52385937},{"atb":[[20,0],[15,0]],"id":52385900},{"atb":[[5.6,0],[4.6,0]],"id":52385933},{"atb":[[16.5,0],[11.5,0]],"id":52385913},{"atb":[[7.4,0],[9.4,0]],"id":52385909},{"atb":[[4.6,0],[3.8,0]],"id":52385888},{"atb":[[18,0],[13,0]],"id":52385921},{"atb":[[13.5,0],[9.4,0]],"id":52385884},{"atb":[[10,0],[15,0]],"id":52385917},{"atb":[[160,0.49],[80,0]],"id":52385926},{"atb":[[530,0],[630,0]],"id":52385897},{"atb":[[320,0.08],[420,0]],"id":52385922},{"atb":[[550,0],[650,0]],"id":52385893},{"atb":[[7.4,0],[5.7,0]],"id":52385934},{"atb":[[19.5,0],[14.5,0]],"id":52385905},{"atb":[[19,0],[14,0]],"id":52385930},{"atb":[[120,0],[60,0]],"id":52385901},{"atb":[[7.2,0],[9.2,0]],"id":52385910},{"atb":[[17,0],[12,0]],"id":52385906},{"atb":[[550,0],[650,0]],"id":52385918},{"atb":[[190,0.55],[95,0]],"id":52385889},{"atb":[[17.5,0],[12.5,0]],"id":52385914},{"atb":[[6.8,0],[8.8,0]],"id":52385885},{"atb":[[550,0],[650,0]],"id":52385894},{"atb":[[280,0],[380,0]],"id":52385927},{"atb":[[550,0.09],[650,0]],"id":52385890},{"atb":[[9.8,0],[7.8,0]],"id":52385923},{"atb":[[5.8,0],[7.6,0]],"id":52385902},{"atb":[[3.85,0],[4.7,0]],"id":52385935},{"atb":[[19.5,0],[14.5,0]],"id":52385898},{"atb":[[3.2,0],[3.7,0]],"id":52385931},{"atb":[[310,0],[210,0]],"id":52385911},{"atb":[[18.5,0],[27,0]],"id":52385907},{"atb":[[9.6,0],[14,0]],"id":52385886},{"atb":[[20,0],[15,0]],"id":52385919},{"atb":[[95,0],[48,0]],"id":52385882},{"atb":[[44,0],[27,0]],"id":52385915},{"atb":[[34,0],[22,0]],"id":52385895},{"atb":[[32,0],[55,0]],"id":52385928},{"atb":[[550,0],[650,0]],"id":52385891},{"atb":[[32,0],[21,0]],"id":52385924},{"atb":[[9.8,0],[14.5,0]],"id":52385903},{"atb":[[7.8,0],[5.9,0]],"id":52385936},{"atb":[[9.6,0],[14,0]],"id":52385899},{"atb":[[16,0],[22,0]],"id":52385932}],"con":true,"img":false}]}
{"op":"mcm","clk":"11450008768","pt":1717317042506,"mc":[{"id":"1.229554917","rc":[{"atb":[[9.6,28.36],[14,8.04]],"id":52385912},{"atb":[[350,0.29],[250,0.97]],"id":52385908},{"atb":[[18,14.34],[26,4.18]],"id":52385887},{"atb":[[18.5,13.93],[27,4.01]],"id":52385920},{"atb":[[10.5,11],[8.2,33.87]],"id":52385883},{"atb":[[5.6,22.72],[4.6,67.75]],"id":52385916},{"atb":[[8.6,32.09],[11.5,9.95]],"id":52385896},{"atb":[[360,0.68],[460,0.23]],"id":52385929},{"atb":[[310,0.78],[410,0.25]],"id":52385892},{"atb":[[550,0.44],[650,0.16]],"id":52385925},{"atb":[[550,0.44],[650,0.16]],"id":52385904},{"atb":[[10.5,25.67],[15.5,7.2]],"id":52385937},{"atb":[[20,5.5],[15,17.42]],"id":52385900},{"atb":[[5.6,22.72],[4.6,67.75]],"id":52385933},{"atb":[[16.5,6.74],[11.5,23.22]],"id":52385913},{"atb":[[7.4,38.1],[9.4,12.44]],"id":52385909},{"atb":[[4.6,29.03],[3.8,87.1]],"id":52385888},{"atb":[[18,6.14],[13,20.32]],"id":52385921},{"atb":[[13.5,8.36],[9.4,29.03]],"id":52385884},{"atb":[[10,27.1],[15,7.46]],"id":52385917},{"atb":[[160,1.15],[80,3.08]],"id":52385926},{"atb":[[530,0.46],[630,0.16]],"id":52385897},{"atb":[[320,0.85],[420,0.25]],"id":52385922},{"atb":[[550,0.44],[650,0.16]],"id":52385893},{"atb":[[7.4,16.33],[5.7,51.89]],"id":52385934},{"atb":[[19.5,5.65],[14.5,18.06]],"id":52385905},{"atb":[[19,5.8],[14,18.76]],"id":52385930},{"atb":[[120,0.87],[60,4.13]],"id":52385901},{"atb":[[7.2,39.33],[9.2,12.74]],"id":52385910},{"atb":[[17,6.53],[12,22.17]],"id":52385906},{"atb":[[550,0.44],[650,0.16]],"id":52385918},{"atb":[[190,1.11],[95,2.59]],"id":52385889},{"atb":[[17.5,6.33],[12.5,21.2]],"id":52385914},{"atb":[[6.8,42.05],[8.8,13.4]],"id":52385885},{"atb":[[550,0.44],[650,0.16]],"id":52385894},{"atb":[[280,0.87],[380,0.27]],"id":52385927},{"atb":[[550,0.54],[650,0.16]],"id":52385890},{"atb":[[9.8,11.87],[7.8,35.86]],"id":52385923},{"atb":[[5.8,50.81],[7.6,15.83]],"id":52385902},{"atb":[[3.85,85.58],[4.7,28.25]],"id":52385935},{"atb":[[19.5,5.65],[14.5,18.06]],"id":52385898},{"atb":[[3.2,110.86],[3.7,38.71]],"id":52385931},{"atb":[[310,0.34],[210,1.16]],"id":52385911},{"atb":[[18.5,13.93],[27,4.01]],"id":52385907},{"atb":[[9.6,28.36],[14,8.04]],"id":52385886},{"atb":[[20,5.5],[15,17.42]],"id":52385919},{"atb":[[95,1.11],[48,5.18]],"id":52385882},{"atb":[[44,2.43],[27,9.38]],"id":52385915},{"atb":[[34,3.16],[22,11.61]],"id":52385895},{"atb":[[32,7.86],[55,1.93]],"id":52385928},{"atb":[[550,0.44],[650,0.16]],"id":52385891},{"atb":[[32,3.37],[21,12.19]],"id":52385924},{"atb":[[9.8,27.71],[14.5,7.74]],"id":52385903},{"atb":[[7.8,15.37],[5.9,49.77]],"id":52385936},{"atb":[[9.6,28.36],[14,8.04]],"id":52385899},{"atb":[[16,16.26],[22,4.97]],"id":52385932}],"con":true,"img":false}]}
{"op":"mcm","clk":"11450010079","pt":1717317055117,"mc":[{"id":"1.229554917","rc":[{"atb":[[300,0],[350,0],[200,0],[250,0]],"id":52385911}],"con":true,"img":false}]}
{"op":"mcm","clk":"11450010139","pt":1717317055794,"mc":[{"id":"1.229554917","rc":[{"atb":[[270,0.29],[320,0.16],[370,0.07],[220,0.48]],"id":52385911}],"con":true,"img":false}]}
{"op":"mcm","clk":"11450010604","pt":1717317060828,"mc":[{"id":"1.229554917","rc":[{"atb":[[40,0],[50,0],[25,0],[30,0]],"id":52385912},{"atb":[[16.5,0],[9.6,0],[11.5,0],[14,0]],"id":52385916},{"atb":[[70,0],[48,0],[29,0]],"id":52385913},{"atb":[[32,0],[18,0],[21,0],[26,0]],"id":52385923}],"con":true,"img":false}]}
{"op":"mcm","clk":"11450010609","pt":1717317060931,"mc":[{"id":"1.229554917","rc":[{"atb":[[38,0]],"id":52385913}],"con":true,"img":false}]}
{"op":"mcm","clk":"11450010679","pt":1717317061510,"mc":[{"id":"1.229554917","rc":[{"atb":[[32,2.53],[42,1.28],[26,4.19],[55,0.49]],"id":52385912},{"atb":[[18,1.54],[10.5,11.01],[13,6.54],[15.5,3.61]],"id":52385916},{"atb":[[50,1.07],[30,3.61]],"id":52385913},{"atb":[[34,0.8],[18.5,5.98],[22,3.74],[27,2.01]],"id":52385923}],"con":true,"img":false}]}
{"op":"mcm","clk":"11450010691","pt":1717317061617,"mc":[{"id":"1.229554917","rc":[{"atb":[[40,2.01]],"id":52385913}],"con":true,"img":false}]}
{"op":"mcm","clk":"11450010712","pt":1717317061819,"mc":[{"id":"1.229554917","rc":[{"atb":[[75,0.36]],"id":52385913}],"con":true,"img":false}]}
{"op":"mcm","clk":"11450023621","pt":1717317193432,"mc":[{"id":"1.229554917","rc":[{"atb":[[32,0],[42,0],[26,0],[55,0]],"id":52385912},{"atb":[[18,0],[10.5,0],[13,0],[15.5,0]],"id":52385916},{"atb":[[17.5,0],[20,0],[25,0],[30,0]],"id":52385896},{"atb":[[75,0],[40,0],[50,0],[30,0]],"id":52385913},{"atb":[[32,0],[18,0],[21,0],[26,0]],"id":52385884},{"atb":[[34,0],[18.5,0],[22,0],[27,0]],"id":52385923},{"atb":[[270,0],[320,0],[370,0],[220,0]],"id":52385911},{"atb":[[34,0],[44,0],[22,0],[27,0]],"id":52385903}],"con":true,"img":false}]}
{"op":"mcm","clk":"11450023693","pt":1717317194111,"mc":[{"id":"1.229554917","rc":[{"atb":[[40,1.34],[50,0.53],[25,4.36],[30,2.71]],"id":52385912},{"atb":[[16.5,1.69],[9.6,12.17],[11.5,7.48],[14,4.02]],"id":52385916},{"atb":[[32,0.84],[18,6.15],[21,3.92],[26,2.09]],"id":52385896},{"atb":[[70,0.38],[38,2.12],[48,1.11],[29,3.74]],"id":52385913},{"atb":[[34,0.8],[18.5,5.98],[22,3.74],[27,2.01]],"id":52385884},{"atb":[[32,0.84],[18,6.15],[21,3.92],[26,2.09]],"id":52385923},{"atb":[[260,0.3],[310,0.51],[360,0.07],[210,1.67]],"id":52385911},{"atb":[[36,1.5],[46,0.58],[23,4.76],[28,2.91]],"id":52385903}],"con":true,"img":false}]}
{"op":"mcm","clk":"11450023762","pt":1717317194786,"mc":[{"id":"1.229554917","rc":[{"atb":[[5.8,0],[5.3,0],[7.6,0],[6.6,0]],"id":52385936}],"con":true,"img":false}]}
{"op":"mcm","clk":"11450023833","pt":1717317195501,"mc":[{"id":"1.229554917","rc":[{"atb":[[6.4,9.69],[7.4,4.09],[5.2,24.91],[5.7,16.69]],"id":52385936}],"con":true,"img":false}]}
{"op":"mcm","clk":"11450024205","pt":1717317199221,"mc":[{"id":"1.229554917","rc":[{"atb":[[40,0],[50,0],[25,0],[30,0]],"id":52385912},{"atb":[[16.5,0],[9.6,0],[11.5,0],[14,0]],"id":52385916},{"atb":[[48,0],[29,0]],"id":52385913},{"atb":[[34,0],[18.5,0],[22,0],[27,0]],"id":52385884},{"atb":[[32,0],[18,0],[21,0],[26,0]],"id":52385923}],"con":true,"img":false}]}
{"op":"mcm","clk":"11450024268","pt":1717317199894,"mc":[{"id":"1.229554917","rc":[{"atb":[[32,2.53],[42,1.28],[26,4.19],[55,0.49]],"id":52385912},{"atb":[[18,1.54],[10.5,11.01],[13,6.54],[15.5,3.61]],"id":52385916},{"atb":[[50,1.07],[30,3.61]],"id":52385913},{"atb":[[32,0.84],[18,6.15],[21,3.92],[26,2.09]],"id":52385884},{"atb":[[34,0.8],[18.5,5.98],[22,3.74],[27,2.01]],"id":52385923}],"con":true,"img":false}]}
{"op":"mcm","clk":"11450024331","pt":1717317200718,"mc":[{"id":"1.229554917","rc":[{"atb":[[32,0],[42,0],[26,0],[55,0]],"id":52385912},{"atb":[[18,0],[10.5,0],[13,0],[15.5,0]],"id":52385916},{"atb":[[50,0],[30,0]],"id":52385913},{"atb":[[32,0],[18,0],[21,0],[26,0]],"id":52385884},{"atb":[[34,0],[18.5,0],[22,0],[27,0]],"id":52385923}],"con":true,"img":false}]}
{"op":"mcm","clk":"11450024389","pt":1717317201394,"mc":[{"id":"1.229554917","rc":[{"atb":[[40,1.34],[50,0.53],[25,4.36],[30,2.71]],"id":52385912},{"atb":[[16.5,1.69],[9.6,12.17],[11.5,7.48],[14,4.02]],"id":52385916},{"atb":[[48,1.11],[29,3.74]],"id":52385913},{"atb":[[34,0.8],[18.5,5.98],[22,3.74],[27,2.01]],"id":52385884},{"atb":[[32,0.84],[18,6.15],[21,3.92],[26,2.09]],"id":52385923}],"con":true,"img":false}]}
{"op":"mcm","clk":"11450024667","pt":1717317203930,"mc":[{"id":"1.229554917","rc":[{"atb":[[40,0],[50,0],[25,0],[30,0]],"id":52385912},{"atb":[[16.5,0],[9.6,0],[11.5,0],[14,0]],"id":52385916},{"atb":[[48,0],[29,0]],"id":52385913},{"atb":[[32,0],[18,0],[21,0],[26,0]],"id":52385923}],"con":true,"img":false}]}
{"op":"mcm","clk":"11450024677","pt":1717317204034,"mc":[{"id":"1.229554917","rc":[{"atb":[[34,0],[18.5,0],[22,0],[27,0]],"id":52385884}],"con":true,"img":false}]}
{"op":"mcm","clk":"11450024744","pt":1717317204609,"mc":[{"id":"1.229554917","rc":[{"atb":[[18,1.54],[10.5,11.01],[13,6.54],[15.5,3.61]],"id":52385916},{"atb":[[50,1.07],[30,3.61]],"id":52385913}],"con":true,"img":false}]}
{"op":"mcm","clk":"11450024761","pt":1717317204711,"mc":[{"id":"1.229554917","rc":[{"atb":[[32,2.53],[42,1.28],[26,4.19],[55,0.49]],"id":52385912},{"atb":[[32,0.84],[18,6.15],[21,3.92],[26,2.09]],"id":52385884},{"atb":[[34,0.8],[18.5,5.98],[22,3.74],[27,2.01]],"id":52385923}],"con":true,"img":false}]}
{"op":"mcm","clk":"11450025325","pt":1717317210321,"mc":[{"id":"1.229554917","rc":[{"atb":[[18,0],[10.5,0],[13,0],[15.5,0]],"id":52385916},{"atb":[[50,0],[30,0]],"id":52385913}],"con":true,"img":false}]}
{"op":"mcm","clk":"11450025337","pt":1717317210419,"mc":[{"id":"1.229554917","rc":[{"atb":[[32,0],[42,0],[26,0],[55,0]],"id":52385912},{"atb":[[34,0],[18.5,0],[22,0],[27,0]],"id":52385923}],"con":true,"img":false}]}
{"op":"mcm","clk":"11450025406","pt":1717317211041,"mc":[{"id":"1.229554917","rc":[{"atb":[[16.5,1.69],[9.6,12.17],[11.5,7.48],[14,4.02]],"id":52385916},{"atb":[[48,1.11],[29,3.74]],"id":52385913}],"con":true,"img":false}]}
{"op":"mcm","clk":"11450025418","pt":1717317211101,"mc":[{"id":"1.229554917","rc":[{"atb":[[40,1.34],[50,0.53],[25,4.36],[30,2.71]],"id":52385912},{"atb":[[32,0.84],[18,6.15],[21,3.92],[26,2.09]],"id":52385923}],"con":true,"img":false}]}
{"op":"mcm","clk":"11450026222","pt":1717317218929,"mc":[{"id":"1.229554917","rc":[{"atb":[[6.4,0],[7.4,0],[5.2,0],[5.7,0]],"id":52385936}],"con":true,"img":false}]}
{"op":"mcm","clk":"11450026315","pt":1717317219809,"mc":[{"id":"1.229554917","rc":[{"atb":[[5.8,16.35],[5.3,24.33],[7.6,3.97],[6.6,9.34]],"id":52385936}],"con":true,"img":false}]}
{"op":"mcm","clk":"11450039569","pt":1717317345466,"mc":[{"id":"1.229554917","rc":[{"atb":[[260,0],[160,0.65],[210,0],[110,0]],"id":52385926}],"con":true,"img":false}]}
{"op":"mcm","clk":"11450039656","pt":1717317346247,"mc":[{"id":"1.229554917","rc":[{"atb":[[170,0.47],[220,0.24]],"id":52385926}],"con":true,"img":false}]}
{"op":"mcm","clk":"11450039665","pt":1717317346348,"mc":[{"id":"1.229554917","rc":[{"atb":[[270,0.1],[120,0.88]],"id":52385926}],"con":true,"img":false}]}
{"op":"mcm","clk":"11450042437","pt":1717317372854,"mc":[{"id":"1.229554917","rc":[{"atb":[[660,0],[710,0],[760,0],[810,0]],"id":52385891}],"con":true,"img":false}]}
{"op":"mcm","clk":"11450042519","pt":1717317373572,"mc":[{"id":"1.229554917","rc":[{"atb":[[680,0.15],[730,0.11],[780,0.07],[830,0.03]],"id":52385891}],"con":true,"img":false}]}
{"op":"mcm","clk":"11450048196","pt":1717317427374,"mc":[{"id":"1.229554917","rc":[{"atb":[[790,0],[840,0],[890,0],[940,0]],"id":52385893}],"con":true,"img":false}]}
{"op":"mcm","clk":"11450048270","pt":1717317428028,"mc":[{"id":"1.229554917","rc":[{"atb":[[820,0.13],[870,0.09],[920,0.06],[970,0.03]],"id":52385893}],"con":true,"img":false}]}
{"op":"mcm","clk":"11450072872","pt":1717317695150,"mc":[{"id":"1.229554917","rc":[{"atb":[[270,0],[170,0],[220,0],[120,0]],"id":52385926}],"con":true,"img":false}]}
{"op":"mcm","clk":"11450072942","pt":1717317695840,"mc":[{"id":"1.229554917","rc":[{"atb":[[260,0.1],[160,1.15],[210,0.25],[110,0.96]],"id":52385926}],"con":true,"img":false}]}
{"op":"mcm","clk":"11450076080","pt":1717317730585,"mc":[{"id":"1.229554917","rc":[{"atb":[[350,0],[250,0]],"id":52385908},{"atb":[[18,0],[26,0]],"id":52385887},{"atb":[[10.5,0],[8.2,0]],"id":52385883},{"atb":[[8.6,0],[11.5,0]],"id":52385896},{"atb":[[310,0],[410,0]],"id":52385892},{"atb":[[550,0],[650,0]],"id":52385904},{"atb":[[20,0],[15,0]],"id":52385900},{"atb":[[7.4,0],[9.4,0]],"id":52385909},{"atb":[[4.6,0],[3.8,0]],"id":52385888},{"atb":[[13.5,0],[9.4,0]],"id":52385884},{"atb":[[530,0],[630,0]],"id":52385897},{"atb":[[550,0],[650,0]],"id":52385893},{"atb":[[19.5,0],[14.5,0]],"id":52385905},{"atb":[[120,0],[60,0]],"id":52385901},{"atb":[[7.2,0],[9.2,0]],"id":52385910},{"atb":[[17,0],[12,0]],"id":52385906},{"atb":[[190,0.55],[95,0]],"id":52385889},{"atb":[[6.8,0],[8.8,0]],"id":52385885},{"atb":[[550,0],[650,0]],"id":52385894},{"atb":[[550,0.09],[650,0]],"id":52385890},{"atb":[[5.8,0],[7.6,0]],"id":52385902},{"atb":[[19.5,0],[14.5,0]],"id":52385898},{"atb":[[310,0.17],[210,0.5]],"id":52385911},{"atb":[[18.5,0],[27,0]],"id":52385907},{"atb":[[9.6,0],[14,0]],"id":52385886},{"atb":[[95,0],[48,0]],"id":52385882},{"atb":[[34,0],[22,0]],"id":52385895},{"atb":[[550,0],[650,0]],"id":52385891},{"atb":[[9.8,0],[14.5,0]],"id":52385903},{"atb":[[9.6,0],[14,0]],"id":52385899}],"con":true,"img":false}]}
{"op":"mcm","clk":"11450076089","pt":1717317730689,"mc":[{"id":"1.229554917","rc":[{"atb":[[9.6,0],[14,0]],"id":52385912},{"atb":[[18.5,0],[27,0]],"id":52385920},{"atb":[[5.6,0],[4.6,0]],"id":52385916},{"atb":[[360,0],[460,0]],"id":52385929},{"atb":[[550,0],[650,0]],"id":52385925},{"atb":[[10.5,0],[15.5,0]],"id":52385937},{"atb":[[5.6,0],[4.6,0]],"id":52385933},{"atb":[[16.5,0],[11.5,0]],"id":52385913},{"atb":[[18,0],[13,0]],"id":52385921},{"atb":[[10,0],[15,0]],"id":52385917},{"atb":[[160,0.49],[80,0]],"id":52385926},{"atb":[[320,0.08],[420,0]],"id":52385922},{"atb":[[7.4,0],[5.7,0]],"id":52385934},{"atb":[[19,0],[14,0]],"id":52385930},{"atb":[[550,0],[650,0]],"id":52385918},{"atb":[[17.5,0],[12.5,0]],"id":52385914},{"atb":[[280,0],[380,0]],"id":52385927},{"atb":[[9.8,0],[7.8,0]],"id":52385923},{"atb":[[3.85,0],[4.7,0]],"id":52385935},{"atb":[[3.2,0],[3.7,0]],"id":52385931},{"atb":[[20,0],[15,0]],"id":52385919},{"atb":[[44,0],[27,0]],"id":52385915},{"atb":[[32,0],[55,0]],"id":52385928},{"atb":[[32,0],[21,0]],"id":52385924},{"atb":[[7.8,0],[5.9,0]],"id":52385936},{"atb":[[16,0],[22,0]],"id":52385932}],"con":true,"img":false}]}
{"op":"mcm","clk":"11450077691","pt":1717317748018,"mc":[{"id":"1.229554917","rc":[{"atb":[[32,0],[18,0],[21,0],[26,0]],"id":52385884}],"con":true,"img":false}]}
{"op":"mcm","clk":"11450077750","pt":1717317748743,"mc":[{"id":"1.229554917","rc":[{"atb":[[34,0.8],[18.5,5.98],[22,3.74],[27,2.01]],"id":52385884}],"con":true,"img":false}]}
{"op":"mcm","clk":"11450079213","pt":1717317764868,"mc":[{"id":"1.229554917","rc":[{"atb":[[350,0.29],[250,0.97]],"id":52385908},{"atb":[[18,14.34],[26,4.18]],"id":52385887},{"atb":[[10.5,11],[8.2,33.87]],"id":52385883},{"atb":[[8.6,32.09],[11.5,9.95]],"id":52385896},{"atb":[[310,0.78],[410,0.25]],"id":52385892},{"atb":[[550,0.44],[650,0.16]],"id":52385904},{"atb":[[20,5.5],[15,17.42]],"id":52385900},{"atb":[[7.4,38.1],[9.4,12.44]],"id":52385909},{"atb":[[4.6,29.03],[3.8,87.1]],"id":52385888},{"atb":[[13.5,8.36],[9.4,29.03]],"id":52385884},{"atb":[[530,0.46],[630,0.16]],"id":52385897},{"atb":[[550,0.44],[650,0.16]],"id":52385893},{"atb":[[19.5,5.65],[14.5,18.06]],"id":52385905},{"atb":[[120,0.87],[60,4.13]],"id":52385901},{"atb":[[17,6.53],[12,22.17]],"id":52385906},{"atb":[[190,1.11],[95,2.59]],"id":52385889},{"atb":[[6.8,42.05],[8.8,13.4]],"id":52385885},{"atb":[[550,0.44],[650,0.16]],"id":52385894},{"atb":[[550,0.54],[650,0.16]],"id":52385890},{"atb":[[5.8,50.81],[7.6,15.83]],"id":52385902},{"atb":[[19.5,5.65],[14.5,18.06]],"id":52385898},{"atb":[[18.5,13.93],[27,4.01]],"id":52385907},{"atb":[[9.6,28.36],[14,8.04]],"id":52385886},{"atb":[[95,1.11],[48,5.18]],"id":52385882},{"atb":[[34,3.16],[22,11.61]],"id":52385895},{"atb":[[550,0.44],[650,0.16]],"id":52385891},{"atb":[[9.8,27.71],[14.5,7.74]],"id":52385903},{"atb":[[9.6,28.36],[14,8.04]],"id":52385899}],"con":true,"img":false}]}
{"op":"mcm","clk":"11450079248","pt":1717317765181,"mc":[{"id":"1.229554917","rc":[{"atb":[[9.6,28.36],[14,8.04]],"id":52385912},{"atb":[[18.5,13.93],[27,4.01]],"id":52385920},{"atb":[[5.6,22.72],[4.6,67.75]],"id":52385916},{"atb":[[360,0.68],[460,0.23]],"id":52385929},{"atb":[[550,0.44],[650,0.16]],"id":52385925},{"atb":[[10.5,25.67],[15.5,7.2]],"id":52385937},{"atb":[[5.6,22.72],[4.6,67.75]],"id":52385933},{"atb":[[16.5,6.74],[11.5,23.22]],"id":52385913},{"atb":[[18,6.14],[13,20.32]],"id":52385921},{"atb":[[10,27.1],[15,7.46]],"id":52385917},{"atb":[[160,1.15],[80,3.08]],"id":52385926},{"atb":[[320,0.85],[420,0.25]],"id":52385922},{"atb":[[7.4,16.33],[5.7,51.89]],"id":52385934},{"atb":[[19,5.8],[14,18.76]],"id":52385930},{"atb":[[7.2,39.33],[9.2,12.74]],"id":52385910},{"atb":[[550,0.44],[650,0.16]],"id":52385918},{"atb":[[17.5,6.33],[12.5,21.2]],"id":52385914},{"atb":[[280,0.87],[380,0.27]],"id":52385927},{"atb":[[9.8,11.87],[7.8,35.86]],"id":52385923},{"atb":[[3.85,85.58],[4.7,28.25]],"id":52385935},{"atb":[[3.2,110.86],[3.7,38.71]],"id":52385931},{"atb":[[310,0.51],[210,1.67]],"id":52385911},{"atb":[[20,5.5],[15,17.42]],"id":52385919},{"atb":[[44,2.43],[27,9.38]],"id":52385915},{"atb":[[32,7.86],[55,1.93]],"id":52385928},{"atb":[[32,3.37],[21,12.19]],"id":52385924},{"atb":[[7.8,15.37],[5.9,49.77]],"id":52385936},{"atb":[[16,16.26],[22,4.97]],"id":52385932}],"con":true,"img":false}]}
{"op":"mcm","clk":"11450081602","pt":1717317792069,"mc":[{"id":"1.229554917","rc":[{"atb":[[40,0],[50,0],[25,0],[30,0]],"id":52385912},{"atb":[[16.5,0],[9.6,0],[11.5,0],[14,0]],"id":52385916},{"atb":[[18,0],[10.5,0],[13,0],[15.5,0]],"id":52385902}],"con":true,"img":false}]}
{"op":"mcm","clk":"11450081616","pt":1717317792174,"mc":[{"id":"1.229554917","rc":[{"atb":[[48,0],[29,0]],"id":52385913},{"atb":[[32,0],[18,0],[21,0],[26,0]],"id":52385923},{"atb":[[260,0],[310,0.34],[360,0],[210,1.16]],"id":52385911},{"atb":[[36,0],[46,0],[23,0],[28,0]],"id":52385903}],"con":true,"img":false}]}
{"op":"mcm","clk":"11450081699","pt":1717317792952,"mc":[{"id":"1.229554917","rc":[{"atb":[[32,2.53],[42,1.28],[26,4.19],[55,0.49]],"id":52385912},{"atb":[[18,1.54],[10.5,11.01],[13,6.54],[15.5,3.61]],"id":52385916},{"atb":[[50,1.07],[30,3.61]],"id":52385913},{"atb":[[34,0.8],[18.5,5.98],[22,3.74],[27,2.01]],"id":52385923},{"atb":[[17,3.27],[19.5,1.41],[12,9.51],[14.5,5.81]],"id":52385902},{"atb":[[300,0.17],[350,0.07],[200,0.53],[250,0.31]],"id":52385911},{"atb":[[40,1.34],[50,0.53],[25,4.36],[30,2.71]],"id":52385903}],"con":true,"img":false}]}
{"op":"mcm","clk":"11450082570","pt":1717317803891,"mc":[{"id":"1.229554917","rc":[{"atb":[[32,0],[42,0],[26,0],[55,0]],"id":52385912},{"atb":[[18,0],[10.5,0],[13,0],[15.5,0]],"id":52385916},{"atb":[[50,0],[30,0]],"id":52385913},{"atb":[[34,0],[18.5,0],[22,0],[27,0]],"id":52385923}],"con":true,"img":false}]}
{"op":"mcm","clk":"11450082681","pt":1717317804975,"mc":[{"id":"1.229554917","rc":[{"atb":[[40,1.34],[50,0.53],[25,4.36],[30,2.71]],"id":52385912},{"atb":[[16.5,1.69],[9.6,12.17],[11.5,7.48],[14,4.02]],"id":52385916},{"atb":[[48,1.11],[29,3.74]],"id":52385913},{"atb":[[32,0.84],[18,6.15],[21,3.92],[26,2.09]],"id":52385923}],"con":true,"img":false}]}
{"op":"mcm","clk":"11450088129","pt":1717317869881,"mc":[{"id":"1.229554917","rc":[{"atb":[[350,0],[250,0]],"id":52385908},{"atb":[[18,0],[26,0]],"id":52385887},{"atb":[[10.5,0],[8.2,0]],"id":52385883},{"atb":[[8.6,0],[11.5,0]],"id":52385896},{"atb":[[310,0],[410,0]],"id":52385892},{"atb":[[550,0],[650,0]],"id":52385904},{"atb":[[20,0],[15,0]],"id":52385900},{"atb":[[7.4,0],[9.4,0]],"id":52385909},{"atb":[[4.6,0],[3.8,0]],"id":52385888},{"atb":[[13.5,0],[9.4,0]],"id":52385884},{"atb":[[530,0],[630,0]],"id":52385897},{"atb":[[550,0],[650,0]],"id":52385893},{"atb":[[19.5,0],[14.5,0]],"id":52385905},{"atb":[[120,0],[60,0]],"id":52385901},{"atb":[[7.2,0],[9.2,0]],"id":52385910},{"atb":[[17,0],[12,0]],"id":52385906},{"atb":[[190,0.55],[95,0]],"id":52385889},{"atb":[[6.8,0],[8.8,0]],"id":52385885},{"atb":[[550,0],[650,0]],"id":52385894},{"atb":[[550,0.09],[650,0]],"id":52385890},{"atb":[[5.8,0],[7.6,0]],"id":52385902},{"atb":[[19.5,0],[14.5,0]],"id":52385898},{"atb":[[310,0],[210,0]],"id":52385911},{"atb":[[18.5,0],[27,0]],"id":52385907},{"atb":[[9.6,0],[14,0]],"id":52385886},{"atb":[[95,0],[48,0]],"id":52385882},{"atb":[[34,0],[22,0]],"id":52385895},{"atb":[[550,0],[650,0]],"id":52385891},{"atb":[[9.8,0],[14.5,0]],"id":52385903},{"atb":[[9.6,0],[14,0]],"id":52385899}],"con":true,"img":false}]}
{"op":"mcm","clk":"11450088140","pt":1717317869983,"mc":[{"id":"1.229554917","rc":[{"atb":[[9.6,0],[14,0]],"id":52385912},{"atb":[[18.5,0],[27,0]],"id":52385920},{"atb":[[5.6,0],[4.6,0]],"id":52385916},{"atb":[[360,0],[460,0]],"id":52385929},{"atb":[[550,0],[650,0]],"id":52385925},{"atb":[[10.5,0],[15.5,0]],"id":52385937},{"atb":[[5.6,0],[4.6,0]],"id":52385933},{"atb":[[16.5,0],[11.5,0]],"id":52385913},{"atb":[[18,0],[13,0]],"id":52385921},{"atb":[[10,0],[15,0]],"id":52385917},{"atb":[[160,0.49],[80,0]],"id":52385926},{"atb":[[320,0.08],[420,0]],"id":52385922},{"atb":[[7.4,0],[5.7,0]],"id":52385934},{"atb":[[19,0],[14,0]],"id":52385930},{"atb":[[550,0],[650,0]],"id":52385918},{"atb":[[17.5,0],[12.5,0]],"id":52385914},{"atb":[[280,0],[380,0]],"id":52385927},{"atb":[[9.8,0],[7.8,0]],"id":52385923},{"atb":[[3.85,0],[4.7,0]],"id":52385935},{"atb":[[3.2,0],[3.7,0]],"id":52385931},{"atb":[[20,0],[15,0]],"id":52385919},{"atb":[[44,0],[27,0]],"id":52385915},{"atb":[[32,0],[55,0]],"id":52385928},{"atb":[[32,0],[21,0]],"id":52385924},{"atb":[[7.8,0],[5.9,0]],"id":52385936},{"atb":[[16,0],[22,0]],"id":52385932}],"con":true,"img":false}]}
{"op":"mcm","clk":"11450090777","pt":1717317899499,"mc":[{"id":"1.229554917","rc":[{"atb":[[350,0.29],[250,0.97]],"id":52385908},{"atb":[[18,14.34],[26,4.18]],"id":52385887},{"atb":[[10.5,11],[8.2,33.87]],"id":52385883},{"atb":[[8.6,32.09],[11.5,9.95]],"id":52385896},{"atb":[[310,0.78],[410,0.25]],"id":52385892},{"atb":[[550,0.44],[650,0.16]],"id":52385904},{"atb":[[20,5.5],[15,17.42]],"id":52385900},{"atb":[[7.4,38.1],[9.4,12.44]],"id":52385909},{"atb":[[4.6,29.03],[3.8,87.1]],"id":52385888},{"atb":[[13.5,8.36],[9.4,29.03]],"id":52385884},{"atb":[[530,0.46],[630,0.16]],"id":52385897},{"atb":[[550,0.44],[650,0.16]],"id":52385893},{"atb":[[19.5,5.65],[14.5,18.06]],"id":52385905},{"atb":[[120,0.87],[60,4.13]],"id":52385901},{"atb":[[17,6.53],[12,22.17]],"id":52385906},{"atb":[[190,1.11],[95,2.59]],"id":52385889},{"atb":[[6.8,42.05],[8.8,13.4]],"id":52385885},{"atb":[[550,0.44],[650,0.16]],"id":52385894},{"atb":[[550,0.54],[650,0.16]],"id":52385890},{"atb":[[5.8,50.81],[7.6,15.83]],"id":52385902},{"atb":[[19.5,5.65],[14.5,18.06]],"id":52385898},{"atb":[[18.5,13.93],[27,4.01]],"id":52385907},{"atb":[[9.6,28.36],[14,8.04]],"id":52385886},{"atb":[[95,1.11],[48,5.18]],"id":52385882},{"atb":[[34,3.16],[22,11.61]],"id":52385895},{"atb":[[550,0.44],[650,0.16]],"id":52385891},{"atb":[[9.8,27.71],[14.5,7.74]],"id":52385903},{"atb":[[9.6,28.36],[14,8.04]],"id":52385899}],"con":true,"img":false}]}
{"op":"mcm","clk":"11450090785","pt":1717317899609,"mc":[{"id":"1.229554917","rc":[{"atb":[[9.6,28.36],[14,8.04]],"id":52385912},{"atb":[[18.5,13.93],[27,4.01]],"id":52385920},{"atb":[[5.6,22.72],[4.6,67.75]],"id":52385916},{"atb":[[360,0.68],[460,0.23]],"id":52385929},{"atb":[[550,0.44],[650,0.16]],"id":52385925},{"atb":[[10.5,25.67],[15.5,7.2]],"id":52385937},{"atb":[[5.6,22.72],[4.6,67.75]],"id":52385933},{"atb":[[16.5,6.74],[11.5,23.22]],"id":52385913},{"atb":[[18,6.14],[13,20.32]],"id":52385921},{"atb":[[10,27.1],[15,7.46]],"id":52385917},{"atb":[[160,1.15],[80,3.08]],"id":52385926},{"atb":[[320,0.85],[420,0.25]],"id":52385922},{"atb":[[7.4,16.33],[5.7,51.89]],"id":52385934},{"atb":[[19,5.8],[14,18.76]],"id":52385930},{"atb":[[7.2,39.33],[9.2,12.74]],"id":52385910},{"atb":[[550,0.44],[650,0.16]],"id":52385918},{"atb":[[17.5,6.33],[12.5,21.2]],"id":52385914},{"atb":[[280,0.87],[380,0.27]],"id":52385927},{"atb":[[9.8,11.87],[7.8,35.86]],"id":52385923},{"atb":[[3.85,85.58],[4.7,28.25]],"id":52385935},{"atb":[[3.2,110.86],[3.7,38.71]],"id":52385931},{"atb":[[310,0.34],[210,1.16]],"id":52385911},{"atb":[[20,5.5],[15,17.42]],"id":52385919},{"atb":[[44,2.43],[27,9.38]],"id":52385915},{"atb":[[32,7.86],[55,1.93]],"id":52385928},{"atb":[[32,3.37],[21,12.19]],"id":52385924},{"atb":[[7.8,15.37],[5.9,49.77]],"id":52385936},{"atb":[[16,16.26],[22,4.97]],"id":52385932}],"con":true,"img":false}]}
{"op":"mcm","clk":"11450092230","pt":1717317915336,"mc":[{"id":"1.229554917","rc":[{"atb":[[680,0],[730,0],[780,0],[830,0]],"id":52385891}],"con":true,"img":false}]}
{"op":"mcm","clk":"11450092296","pt":1717317916016,"mc":[{"id":"1.229554917","rc":[{"atb":[[700,0.15],[750,0.1],[800,0.07],[850,0.03]],"id":52385891}],"con":true,"img":false}]}
{"op":"mcm","clk":"11450105859","pt":1717318070635,"mc":[{"id":"1.229554917","rc":[{"atb":[[75,0],[40,0],[100,0],[50,0]],"id":52385920},{"atb":[[70,0],[38,0],[48,0],[29,0]],"id":52385900},{"atb":[[4.9,0],[4.4,0],[5.9,0],[5.4,0]],"id":52385933},{"atb":[[300,0],[350,0],[200,0],[250,0]],"id":52385897},{"atb":[[5.6,0],[7.2,0],[6.2,0],[8.2,0]],"id":52385934},{"atb":[[70,0],[38,0],[48,0],[29,0]],"id":52385905},{"atb":[[75,0],[40,0],[50,0],[30,0]],"id":52385898},{"atb":[[65,0],[36,0],[90,0],[46,0]],"id":52385907},{"atb":[[75,0],[40,0],[50,0],[30,0]],"id":52385919},{"atb":[[5.8,0],[5.3,0],[7.6,0],[6.6,0]],"id":52385936},{"atb":[[38,0],[48,0],[24,0],[29,0]],"id":52385932}],"con":true,"img":false}]}
{"op":"mcm","clk":"11450105924","pt":1717318071313,"mc":[{"id":"1.229554917","rc":[{"atb":[[80,0.66],[42,2.55],[110,0.24],[55,1.45]],"id":52385920},{"atb":[[65,0.41],[36,2.24],[46,1.16],[28,3.88]],"id":52385900},{"atb":[[260,0.2],[310,0.08],[160,0.66],[210,0.38]],"id":52385897},{"atb":[[8.6,3.44],[5.8,21.8],[7.6,7.93],[6.6,14.02]],"id":52385934},{"atb":[[65,0.41],[36,2.24],[46,1.16],[28,3.88]],"id":52385898},{"atb":[[70,0.38],[38,2.12],[48,1.11],[29,3.74]],"id":52385919},{"atb":[[6.8,9.02],[7.8,19.22],[5.9,65.79],[5.4,23.78]],"id":52385936}],"con":true,"img":false}]}
{"op":"mcm","clk":"11450105934","pt":1717318071424,"mc":[{"id":"1.229554917","rc":[{"atb":[[4,34.88],[4.5,22.42],[5,13.08],[5.5,5.81]],"id":52385933},{"atb":[[65,0.41],[36,2.24],[46,1.16],[28,3.88]],"id":52385905},{"atb":[[70,0.76],[38,2.83],[95,0.28],[48,1.67]],"id":52385907},{"atb":[[40,1.34],[50,0.53],[25,4.36],[30,2.71]],"id":52385932}],"con":true,"img":false}]}
{"op":"mcm","clk":"11450106527","pt":1717318077510,"mc":[{"id":"1.229554917","rc":[{"atb":[[17,0],[19.5,0],[12,0],[14.5,0]],"id":52385902}],"con":true,"img":false}]}
{"op":"mcm","clk":"11450106595","pt":1717318078239,"mc":[{"id":"1.229554917","rc":[{"atb":[[18,1.54],[10.5,11.01],[13,6.54],[15.5,3.61]],"id":52385902}],"con":true,"img":false}]}
{"op":"mcm","clk":"11450116558","pt":1717318189959,"mc":[{"id":"1.229554917","rc":[{"atb":[[260,0],[160,0.65],[210,0],[110,0]],"id":52385926}],"con":true,"img":false}]}
{"op":"mcm","clk":"11450116622","pt":1717318190734,"mc":[{"id":"1.229554917","rc":[{"atb":[[270,0.1],[170,0.47],[220,0.24],[120,0.88]],"id":52385926}],"con":true,"img":false}]}
{"op":"mcm","clk":"11450125092","pt":1717318288166,"mc":[{"id":"1.229554917","rc":[{"atb":[[50,0]],"id":52385912},{"atb":[[16.5,0],[14,0]],"id":52385916},{"atb":[[29,0]],"id":52385913},{"atb":[[32,0],[18,0],[21,0],[26,0]],"id":52385923}],"con":true,"img":false}]}
{"op":"mcm","clk":"11450125104","pt":1717318288273,"mc":[{"id":"1.229554917","rc":[{"atb":[[40,0],[25,0],[30,0]],"id":52385912},{"atb":[[9.6,0],[11.5,0]],"id":52385916},{"atb":[[48,0]],"id":52385913}],"con":true,"img":false}]}
{"op":"mcm","clk":"11450125165","pt":1717318288842,"mc":[{"id":"1.229554917","rc":[{"atb":[[55,0.49]],"id":52385912},{"atb":[[18,1.54],[15.5,3.61]],"id":52385916},{"atb":[[30,3.61]],"id":52385913},{"atb":[[34,0.8],[18.5,5.98],[22,3.74],[27,2.01]],"id":52385923}],"con":true,"img":false}]}
{"op":"mcm","clk":"11450125173","pt":1717318288947,"mc":[{"id":"1.229554917","rc":[{"atb":[[32,2.53],[42,1.28],[26,4.19]],"id":52385912},{"atb":[[10.5,11.01],[13,6.54]],"id":52385916},{"atb":[[50,1.07]],"id":52385913}],"con":true,"img":false}]}
{"op":"mcm","clk":"11450125251","pt":1717318289980,"mc":[{"id":"1.229554917","rc":[{"atb":[[32,0],[42,0],[26,0]],"id":52385912},{"atb":[[10.5,0],[13,0]],"id":52385916},{"atb":[[50,0]],"id":52385913}],"con":true,"img":false}]}
{"op":"mcm","clk":"11450125310","pt":1717318290655,"mc":[{"id":"1.229554917","rc":[{"atb":[[40,1.34],[25,4.36],[30,2.71]],"id":52385912},{"atb":[[9.6,12.17],[11.5,7.48]],"id":52385916},{"atb":[[48,1.11]],"id":52385913}],"con":true,"img":false}]}
{"op":"mcm","clk":"11450125624","pt":1717318294579,"mc":[{"id":"1.229554917","rc":[{"atb":[[55,0]],"id":52385912},{"atb":[[18,0],[15.5,0]],"id":52385916},{"atb":[[30,0]],"id":52385913},{"atb":[[34,0],[18.5,0],[22,0],[27,0]],"id":52385923}],"con":true,"img":false}]}
{"op":"mcm","clk":"11450125716","pt":1717318295665,"mc":[{"id":"1.229554917","rc":[{"atb":[[50,0.53]],"id":52385912},{"atb":[[16.5,1.69],[14,4.02]],"id":52385916},{"atb":[[29,3.74]],"id":52385913},{"atb":[[32,0.84],[18,6.15],[21,3.92],[26,2.09]],"id":52385923}],"con":true,"img":false}]}
{"op":"mcm","clk":"11450126962","pt":1717318309950,"mc":[{"id":"1.229554917","rc":[{"atb":[[40,0],[25,0],[30,0]],"id":52385912},{"atb":[[9.6,0],[11.5,0]],"id":52385916},{"atb":[[48,0]],"id":52385913}],"con":true,"img":false}]}
{"op":"mcm","clk":"11450127012","pt":1717318310632,"mc":[{"id":"1.229554917","rc":[{"atb":[[32,2.53],[42,1.28],[26,4.19]],"id":52385912},{"atb":[[10.5,11.01],[13,6.54]],"id":52385916},{"atb":[[50,1.07]],"id":52385913}],"con":true,"img":false}]}
{"op":"mcm","clk":"11450127800","pt":1717318320353,"mc":[{"id":"1.229554917","rc":[{"atb":[[32,0],[42,0],[26,0]],"id":52385912},{"atb":[[10.5,0],[13,0]],"id":52385916},{"atb":[[50,0]],"id":52385913}],"con":true,"img":false}]}
{"op":"mcm","clk":"11450127864","pt":1717318321031,"mc":[{"id":"1.229554917","rc":[{"atb":[[40,1.34],[25,4.36],[30,2.71]],"id":52385912},{"atb":[[9.6,12.17],[11.5,7.48]],"id":52385916},{"atb":[[48,1.11]],"id":52385913}],"con":true,"img":false}]}
{"op":"mcm","clk":"11450129653","pt":1717318340254,"mc":[{"id":"1.229554917","rc":[{"atb":[[40,0],[25,0],[30,0]],"id":52385912},{"atb":[[9.6,0],[11.5,0]],"id":52385916},{"atb":[[48,0]],"id":52385913}],"con":true,"img":false}]}
{"op":"mcm","clk":"11450129707","pt":1717318340981,"mc":[{"id":"1.229554917","rc":[{"atb":[[32,2.53],[42,1.28],[26,4.19]],"id":52385912},{"atb":[[10.5,11.01],[13,6.54]],"id":52385916},{"atb":[[50,1.07]],"id":52385913}],"con":true,"img":false}]}
{"op":"mcm","clk":"11450130478","pt":1717318350691,"mc":[{"id":"1.229554917","rc":[{"atb":[[32,0],[42,0],[26,0]],"id":52385912},{"atb":[[10.5,0],[13,0]],"id":52385916},{"atb":[[50,0]],"id":52385913}],"con":true,"img":false}]}
{"op":"mcm","clk":"11450130528","pt":1717318351405,"mc":[{"id":"1.229554917","rc":[{"atb":[[40,1.34],[25,4.36],[30,2.71]],"id":52385912},{"atb":[[9.6,12.17],[11.5,7.48]],"id":52385916},{"atb":[[48,1.11]],"id":52385913}],"con":true,"img":false}]}
{"op":"mcm","clk":"11450148013","pt":1717318553204,"mc":[{"id":"1.229554917","rc":[{"atb":[[18,0],[10.5,0],[13,0],[15.5,0]],"id":52385902}],"con":true,"img":false}]}
{"op":"mcm","clk":"11450148073","pt":1717318553923,"mc":[{"id":"1.229554917","rc":[{"atb":[[17,3.27],[19.5,1.41],[12,9.51],[14.5,5.81]],"id":52385902}],"con":true,"img":false}]}
{"op":"mcm","clk":"11450148919","pt":1717318563627,"mc":[{"id":"1.229554917","rc":[{"atb":[[17,0],[19.5,0],[12,0],[14.5,0]],"id":52385902}],"con":true,"img":false}]}
{"op":"mcm","clk":"11450148984","pt":1717318564303,"mc":[{"id":"1.229554917","rc":[{"atb":[[18,1.54],[10.5,11.01],[13,6.54],[15.5,3.61]],"id":52385902}],"con":true,"img":false}]}
{"op":"mcm","clk":"11450150249","pt":1717318577744,"mc":[{"id":"1.229554917","rc":[{"atb":[[9.6,0],[14,0]],"id":52385912},{"atb":[[350,0],[250,0]],"id":52385908},{"atb":[[18,0],[26,0]],"id":52385887},{"atb":[[18.5,0],[27,0]],"id":52385920},{"atb":[[10.5,0],[8.2,0]],"id":52385883},{"atb":[[5.6,0],[4.6,0]],"id":52385916},{"atb":[[8.6,0],[11.5,0]],"id":52385896},{"atb":[[360,0],[460,0]],"id":52385929},{"atb":[[310,0],[410,0]],"id":52385892},{"atb":[[550,0],[650,0]],"id":52385925},{"atb":[[550,0],[650,0]],"id":52385904},{"atb":[[10.5,0],[15.5,0]],"id":52385937},{"atb":[[20,0],[15,0]],"id":52385900},{"atb":[[5.6,0],[4.6,0]],"id":52385933},{"atb":[[16.5,0],[11.5,0]],"id":52385913},{"atb":[[7.4,0],[9.4,0]],"id":52385909},{"atb":[[4.6,0],[3.8,0]],"id":52385888},{"atb":[[18,0],[13,0]],"id":52385921},{"atb":[[13.5,0],[9.4,0]],"id":52385884},{"atb":[[10,0],[15,0]],"id":52385917},{"atb":[[160,0],[80,0]],"id":52385926},{"atb":[[530,0],[630,0]],"id":52385897},{"atb":[[320,0.08],[420,0]],"id":52385922},{"atb":[[550,0],[650,0]],"id":52385893},{"atb":[[7.4,0],[5.7,0]],"id":52385934},{"atb":[[19.5,0],[14.5,0]],"id":52385905},{"atb":[[19,0],[14,0]],"id":52385930},{"atb":[[120,0],[60,0]],"id":52385901},{"atb":[[7.2,0],[9.2,0]],"id":52385910},{"atb":[[17,0],[12,0]],"id":52385906},{"atb":[[550,0],[650,0]],"id":52385918},{"atb":[[190,0.55],[95,0]],"id":52385889},{"atb":[[17.5,0],[12.5,0]],"id":52385914},{"atb":[[6.8,0],[8.8,0]],"id":52385885},{"atb":[[550,0],[650,0]],"id":52385894},{"atb":[[280,0],[380,0]],"id":52385927},{"atb":[[550,0.09],[650,0]],"id":52385890},{"atb":[[9.8,0],[7.8,0]],"id":52385923},{"atb":[[5.8,0],[7.6,0]],"id":52385902},{"atb":[[3.85,0],[4.7,0]],"id":52385935},{"atb":[[19.5,0],[14.5,0]],"id":52385898},{"atb":[[3.2,0],[3.7,0]],"id":52385931},{"atb":[[310,0],[210,0]],"id":52385911},{"atb":[[18.5,0],[27,0]],"id":52385907},{"atb":[[9.6,0],[14,0]],"id":52385886},{"atb":[[20,0],[15,0]],"id":52385919},{"atb":[[95,0],[48,0]],"id":52385882},{"atb":[[44,0],[27,0]],"id":52385915},{"atb":[[34,0],[22,0]],"id":52385895},{"atb":[[32,0],[55,0]],"id":52385928},{"atb":[[550,0],[650,0]],"id":52385891},{"atb":[[32,0],[21,0]],"id":52385924},{"atb":[[9.8,0],[14.5,0]],"id":52385903},{"atb":[[7.8,3.85],[5.9,16.01]],"id":52385936},{"atb":[[9.6,0],[14,0]],"id":52385899},{"atb":[[16,0],[22,0]],"id":52385932}],"con":true,"img":false}]}
{"op":"mcm","clk":"11450152878","pt":1717318603831,"mc":[{"id":"1.229554917","rc":[{"atb":[[9.6,28.36],[14,8.04]],"id":52385912},{"atb":[[350,0.29],[250,0.97]],"id":52385908},{"atb":[[18,14.34],[26,4.18]],"id":52385887},{"atb":[[18.5,13.93],[27,4.01]],"id":52385920},{"atb":[[10.5,11],[8.2,33.87]],"id":52385883},{"atb":[[5.6,22.72],[4.6,67.75]],"id":52385916},{"atb":[[8.6,32.09],[11.5,9.95]],"id":52385896},{"atb":[[360,0.68],[460,0.23]],"id":52385929},{"atb":[[310,0.78],[410,0.25]],"id":52385892},{"atb":[[550,0.44],[650,0.16]],"id":52385925},{"atb":[[550,0.44],[650,0.16]],"id":52385904},{"atb":[[10.5,25.67],[15.5,7.2]],"id":52385937},{"atb":[[20,5.5],[15,17.42]],"id":52385900},{"atb":[[5.6,22.72],[4.6,67.75]],"id":52385933},{"atb":[[16.5,6.74],[11.5,23.22]],"id":52385913},{"atb":[[7.4,38.1],[9.4,12.44]],"id":52385909},{"atb":[[4.6,29.03],[3.8,87.1]],"id":52385888},{"atb":[[18,6.14],[13,20.32]],"id":52385921},{"atb":[[13.5,8.36],[9.4,29.03]],"id":52385884},{"atb":[[10,27.1],[15,7.46]],"id":52385917},{"atb":[[160,0.65],[80,3.08]],"id":52385926},{"atb":[[530,0.46],[630,0.16]],"id":52385897},{"atb":[[320,0.85],[420,0.25]],"id":52385922},{"atb":[[550,0.44],[650,0.16]],"id":52385893},{"atb":[[7.4,16.33],[5.7,51.89]],"id":52385934},{"atb":[[19.5,5.65],[14.5,18.06]],"id":52385905},{"atb":[[19,5.8],[14,18.76]],"id":52385930},{"atb":[[120,0.87],[60,4.13]],"id":52385901},{"atb":[[7.2,39.33],[9.2,12.74]],"id":52385910},{"atb":[[17,6.53],[12,22.17]],"id":52385906},{"atb":[[550,0.44],[650,0.16]],"id":52385918},{"atb":[[190,1.11],[95,2.59]],"id":52385889},{"atb":[[17.5,6.33],[12.5,21.2]],"id":52385914},{"atb":[[6.8,42.05],[8.8,13.4]],"id":52385885},{"atb":[[550,0.44],[650,0.16]],"id":52385894},{"atb":[[280,0.87],[380,0.27]],"id":52385927},{"atb":[[550,0.54],[650,0.16]],"id":52385890},{"atb":[[9.8,11.87],[7.8,35.86]],"id":52385923},{"atb":[[5.8,50.81],[7.6,15.83]],"id":52385902},{"atb":[[3.85,85.58],[4.7,28.25]],"id":52385935},{"atb":[[19.5,5.65],[14.5,18.06]],"id":52385898},{"atb":[[3.2,110.86],[3.7,38.71]],"id":52385931},{"atb":[[310,0.34],[210,1.16]],"id":52385911},{"atb":[[18.5,13.93],[27,4.01]],"id":52385907},{"atb":[[9.6,28.36],[14,8.04]],"id":52385886},{"atb":[[20,5.5],[15,17.42]],"id":52385919},{"atb":[[95,1.11],[48,5.18]],"id":52385882},{"atb":[[44,2.43],[27,9.38]],"id":52385915},{"atb":[[34,3.16],[22,11.61]],"id":52385895},{"atb":[[32,7.86],[55,1.93]],"id":52385928},{"atb":[[550,0.44],[650,0.16]],"id":52385891},{"atb":[[32,3.37],[21,12.19]],"id":52385924},{"atb":[[9.8,27.71],[14.5,7.74]],"id":52385903},{"atb":[[7.8,19.22],[5.9,65.79]],"id":52385936},{"atb":[[9.6,28.36],[14,8.04]],"id":52385899},{"atb":[[16,16.26],[22,4.97]],"id":52385932}],"con":true,"img":false}]}
{"op":"mcm","clk":"11450163912","pt":1717318716371,"mc":[{"id":"1.229554917","rc":[{"atb":[[1.02,161.9]],"id":52385912},{"atb":[[1.03,109.07]],"id":52385908},{"atb":[[1.04,78.39]],"id":52385887},{"atb":[[1.03,141.45]],"id":52385920},{"atb":[[1.03,201.95]],"id":52385883},{"atb":[[1.02,163.61]],"id":52385916},{"atb":[[1.03,109.92]],"id":52385896},{"atb":[[1.03,99.7]],"id":52385929},{"atb":[[1.03,117.59]],"id":52385892},{"atb":[[1.03,155.09]],"id":52385925},{"atb":[[1.02,132.08]],"id":52385904},{"atb":[[1.03,166.16]],"id":52385900},{"atb":[[1.02,102.25]],"id":52385913},{"atb":[[1.02,150.83]],"id":52385909},{"atb":[[1.02,138.9]],"id":52385888},{"atb":[[1.03,134.63]],"id":52385921},{"atb":[[1.04,126.11]],"id":52385884},{"atb":[[1.04,100.55]],"id":52385917},{"atb":[[1.03,155.09]],"id":52385926},{"atb":[[1.03,116.74]],"id":52385897},{"atb":[[1.04,77.54]],"id":52385922},{"atb":[[1.03,101.4]],"id":52385893},{"atb":[[1.02,166.16]],"id":52385905},{"atb":[[1.02,91.18]],"id":52385930},{"atb":[[1.02,136.34]],"id":52385901},{"atb":[[1.03,97.99]],"id":52385910},{"atb":[[1.03,89.47]],"id":52385906},{"atb":[[1.02,84.36]],"id":52385918},{"atb":[[1.04,168.72]],"id":52385889},{"atb":[[1.04,132.93]],"id":52385914},{"atb":[[1.02,115.04]],"id":52385885},{"atb":[[1.02,105.66]],"id":52385894},{"atb":[[1.02,150.83]],"id":52385927},{"atb":[[1.04,80.1]],"id":52385890},{"atb":[[1.03,122.7]],"id":52385923},{"atb":[[1.02,148.27]],"id":52385902},{"atb":[[1.02,186.62]],"id":52385898},{"atb":[[1.04,76.69]],"id":52385931},{"atb":[[1.02,94.58]],"id":52385911},{"atb":[[1.03,137.19]],"id":52385907},{"atb":[[1.02,150.83]],"id":52385886},{"atb":[[1.04,92.03]],"id":52385919},{"atb":[[1.04,168.72]],"id":52385882},{"atb":[[1.02,119.3]],"id":52385915},{"atb":[[1.04,172.98]],"id":52385895},{"atb":[[1.04,187.47]],"id":52385928},{"atb":[[1.02,130.37]],"id":52385891},{"atb":[[1.02,55.38]],"id":52385924},{"atb":[[1.04,157.64]],"id":52385903},{"atb":[[1.02,88.62]],"id":52385899}],"con":true,"img":false}]}
{"op":"mcm","clk":"11450164666","pt":1717318724291,"mc":[{"id":"1.229554917","rc":[{"atb":[[350,0],[250,0]],"id":52385908},{"atb":[[18,0],[26,0]],"id":52385887},{"atb":[[10.5,0],[8.2,0]],"id":52385883},{"atb":[[8.6,0],[11.5,0]],"id":52385896},{"atb":[[310,0],[410,0]],"id":52385892},{"atb":[[550,0],[650,0]],"id":52385904},{"atb":[[20,0],[15,0]],"id":52385900},{"atb":[[7.4,0],[9.4,0]],"id":52385909},{"atb":[[4.6,0],[3.8,0]],"id":52385888},{"atb":[[13.5,0],[9.4,0]],"id":52385884},{"atb":[[530,0],[630,0]],"id":52385897},{"atb":[[550,0],[650,0]],"id":52385893},{"atb":[[19.5,0],[14.5,0]],"id":52385905},{"atb":[[120,0],[60,0]],"id":52385901},{"atb":[[7.2,0],[9.2,0]],"id":52385910},{"atb":[[17,0],[12,0]],"id":52385906},{"atb":[[190,0.55],[95,0]],"id":52385889},{"atb":[[6.8,0],[8.8,0]],"id":52385885},{"atb":[[550,0],[650,0]],"id":52385894},{"atb":[[550,0.09],[650,0]],"id":52385890},{"atb":[[5.8,0],[7.6,0]],"id":52385902},{"atb":[[19.5,0],[14.5,0]],"id":52385898},{"atb":[[310,0],[210,0]],"id":52385911},{"atb":[[18.5,0],[27,0]],"id":52385907},{"atb":[[9.6,0],[14,0]],"id":52385886},{"atb":[[95,0],[48,0]],"id":52385882},{"atb":[[34,0],[22,0]],"id":52385895},{"atb":[[550,0],[650,0]],"id":52385891},{"atb":[[9.8,0],[14.5,0]],"id":52385903},{"atb":[[9.6,0],[14,0]],"id":52385899}],"con":true,"img":false}]}
{"op":"mcm","clk":"11450164677","pt":1717318724396,"mc":[{"id":"1.229554917","rc":[{"atb":[[9.6,0],[14,0]],"id":52385912},{"atb":[[18.5,0],[27,0]],"id":52385920},{"atb":[[5.6,0],[4.6,0]],"id":52385916},{"atb":[[360,0],[460,0]],"id":52385929},{"atb":[[550,0],[650,0]],"id":52385925},{"atb":[[10.5,0],[15.5,0]],"id":52385937},{"atb":[[5.6,0],[4.6,0]],"id":52385933},{"atb":[[16.5,0],[11.5,0]],"id":52385913},{"atb":[[18,0],[13,0]],"id":52385921},{"atb":[[10,0],[15,0]],"id":52385917},{"atb":[[160,0],[80,0]],"id":52385926},{"atb":[[320,0.08],[420,0]],"id":52385922},{"atb":[[7.4,0],[5.7,0]],"id":52385934},{"atb":[[19,0],[14,0]],"id":52385930},{"atb":[[550,0],[650,0]],"id":52385918},{"atb":[[17.5,0],[12.5,0]],"id":52385914},{"atb":[[280,0],[380,0]],"id":52385927},{"atb":[[9.8,0],[7.8,0]],"id":52385923},{"atb":[[3.85,0],[4.7,0]],"id":52385935},{"atb":[[3.2,0],[3.7,0]],"id":52385931},{"atb":[[20,0],[15,0]],"id":52385919},{"atb":[[44,0],[27,0]],"id":52385915},{"atb":[[32,0],[55,0]],"id":52385928},{"atb":[[32,0],[21,0]],"id":52385924},{"atb":[[7.8,3.85],[5.9,16.01]],"id":52385936},{"atb":[[16,0],[22,0]],"id":52385932}],"con":true,"img":false}]}
{"op":"mcm","clk":"11450165725","pt":1717318735921,"mc":[{"id":"1.229554917","rc":[{"atb":[[50,0]],"id":52385912},{"atb":[[16.5,0],[14,0]],"id":52385916},{"atb":[[29,0]],"id":52385913},{"atb":[[32,0],[18,0],[21,0],[26,0]],"id":52385923}],"con":true,"img":false}]}
{"op":"mcm","clk":"11450165778","pt":1717318736597,"mc":[{"id":"1.229554917","rc":[{"atb":[[55,0.49]],"id":52385912},{"atb":[[18,1.54],[15.5,3.61]],"id":52385916},{"atb":[[30,3.61]],"id":52385913},{"atb":[[34,0.8],[18.5,5.98],[22,3.74],[27,2.01]],"id":52385923}],"con":true,"img":false}]}
{"op":"mcm","clk":"11450166691","pt":1717318746431,"mc":[{"id":"1.229554917","rc":[{"atb":[[55,0]],"id":52385912},{"atb":[[18,0],[15.5,0]],"id":52385916},{"atb":[[30,0]],"id":52385913},{"atb":[[34,0],[18.5,0],[22,0],[27,0]],"id":52385923}],"con":true,"img":false}]}
{"op":"mcm","clk":"11450166779","pt":1717318747109,"mc":[{"id":"1.229554917","rc":[{"atb":[[50,0.53]],"id":52385912},{"atb":[[16.5,1.69],[14,4.02]],"id":52385916},{"atb":[[29,3.74]],"id":52385913},{"atb":[[32,0.84],[18,6.15],[21,3.92],[26,2.09]],"id":52385923}],"con":true,"img":false}]}
{"op":"mcm","clk":"11450167448","pt":1717318753533,"mc":[{"id":"1.229554917","rc":[{"atb":[[350,0.29],[250,0.97]],"id":52385908},{"atb":[[18,14.34],[26,4.18]],"id":52385887},{"atb":[[10.5,11],[8.2,33.87]],"id":52385883},{"atb":[[8.6,32.09],[11.5,9.95]],"id":52385896},{"atb":[[310,0.78],[410,0.25]],"id":52385892},{"atb":[[550,0.44],[650,0.16]],"id":52385904},{"atb":[[20,5.5],[15,17.42]],"id":52385900},{"atb":[[7.4,38.1],[9.4,12.44]],"id":52385909},{"atb":[[4.6,29.03],[3.8,87.1]],"id":52385888},{"atb":[[13.5,8.36],[9.4,29.03]],"id":52385884},{"atb":[[530,0.46],[630,0.16]],"id":52385897},{"atb":[[550,0.44],[650,0.16]],"id":52385893},{"atb":[[19.5,5.65],[14.5,18.06]],"id":52385905},{"atb":[[120,0.87],[60,4.13]],"id":52385901},{"atb":[[17,6.53],[12,22.17]],"id":52385906},{"atb":[[190,1.11],[95,2.59]],"id":52385889},{"atb":[[6.8,42.05],[8.8,13.4]],"id":52385885},{"atb":[[550,0.44],[650,0.16]],"id":52385894},{"atb":[[550,0.54],[650,0.16]],"id":52385890},{"atb":[[5.8,50.81],[7.6,15.83]],"id":52385902},{"atb":[[19.5,5.65],[14.5,18.06]],"id":52385898},{"atb":[[18.5,13.93],[27,4.01]],"id":52385907},{"atb":[[9.6,28.36],[14,8.04]],"id":52385886},{"atb":[[95,1.11],[48,5.18]],"id":52385882},{"atb":[[34,3.16],[22,11.61]],"id":52385895},{"atb":[[550,0.44],[650,0.16]],"id":52385891},{"atb":[[9.8,27.71],[14.5,7.74]],"id":52385903},{"atb":[[9.6,28.36],[14,8.04]],"id":52385899}],"con":true,"img":false}]}
