{"op":"mcm","clk":"11449075382","pt":1717303241522,"mc":[{"id":"1.229554918","marketDefinition":{"bspMarket":false,"turnInPlayEnabled":false,"persistenceEnabled":false,"marketBaseRate":7.0,"eventId":"33318908","eventTypeId":"4339","numberOfWinners":1,"bettingType":"ODDS","marketType":"QUINELLA","marketTime":"2024-06-02T10:03:00.000Z","suspendTime":"2024-06-02T10:03:00.000Z","bspReconciled":false,"complete":true,"inPlay":false,"crossMatching":true,"runnersVoidable":false,"numberOfActiveRunners":28,"betDelay":0,"status":"OPEN","runners":[{"status":"ACTIVE","sortPriority":1,"id":52671542,"name":"1 - 2 / 2 - 1"},{"status":"ACTIVE","sortPriority":2,"id":52671543,"name":"1 - 3 / 3 - 1"},{"status":"ACTIVE","sortPriority":3,"id":52671544,"name":"1 - 4 / 4 - 1"},{"status":"ACTIVE","sortPriority":4,"id":52237612,"name":"1 - 5 / 5 - 1"},{"status":"ACTIVE","sortPriority":5,"id":52671545,"name":"1 - 6 / 6 - 1"},{"status":"ACTIVE","sortPriority":6,"id":52671560,"name":"1 - 7 / 7 - 1"},{"status":"ACTIVE","sortPriority":7,"id":52671546,"name":"1 - 8 / 8 - 1"},{"status":"ACTIVE","sortPriority":8,"id":52671547,"name":"2 - 3 / 3 - 2"},{"status":"ACTIVE","sortPriority":9,"id":52671548,"name":"2 - 4 / 4 - 2"},{"status":"ACTIVE","sortPriority":10,"id":52237617,"name":"2 - 5 / 5 - 2"},{"status":"ACTIVE","sortPriority":11,"id":52671549,"name":"2 - 6 / 6 - 2"},{"status":"ACTIVE","sortPriority":12,"id":52671561,"name":"2 - 7 / 7 - 2"},{"status":"ACTIVE","sortPriority":13,"id":52671550,"name":"2 - 8 / 8 - 2"},{"status":"ACTIVE","sortPriority":14,"id":52671551,"name":"3 - 4 / 4 - 3"},{"status":"ACTIVE","sortPriority":15,"id":52237621,"name":"3 - 5 / 5 - 3"},{"status":"ACTIVE","sortPriority":16,"id":52671552,"name":"3 - 6 / 6 - 3"},{"status":"ACTIVE","sortPriority":17,"id":52671562,"name":"3 - 7 / 7 - 3"},{"status":"ACTIVE","sortPriority":18,"id":52671553,"name":"3 - 8 / 8 - 3"},{"status":"ACTIVE","sortPriority":19,"id":52237624,"name":"4 - 5 / 5 - 4"},{"status":"ACTIVE","sortPriority":20,"id":52671554,"name":"4 - 6 / 6 - 4"},{"status":"ACTIVE","sortPriority":21,"id":52671563,"name":"4 - 7 / 7 - 4"},{"status":"ACTIVE","sortPriority":22,"id":52671555,"name":"4 - 8 / 8 - 4"},{"status":"ACTIVE","sortPriority":23,"id":52237634,"name":"5 - 6 / 6 - 5"},{"status":"ACTIVE","sortPriority":24,"id":52237627,"name":"5 - 7 / 7 - 5"},{"status":"ACTIVE","sortPriority":25,"id":52237628,"name":"5 - 8 / 8 - 5"},{"status":"ACTIVE","sortPriority":26,"id":52671564,"name":"6 - 7 / 7 - 6"},{"status":"ACTIVE","sortPriority":27,"id":52671556,"name":"6 - 8 / 8 - 6"},{"status":"ACTIVE","sortPriority":28,"id":52671565,"name":"7 - 8 / 8 - 7"}],"regulators":["MR_INT"],"venue":"Murray Bridge","countryCode":"AU","discountAllowed":true,"timezone":"Australia/Adelaide","openDate":"2024-06-02T08:21:00.000Z","version":5962801932,"name":"Quinella","eventName":"Murray Bridge (AUS) 2nd Jun"},"rc":[],"con":true,"img":false}]}
{"op":"mcm","clk":"11449099382","pt":1717303849562,"mc":[{"id":"1.229554918","rc":[{"atb":[[550,0.44],[650,0.16]],"id":52671561},{"atb":[[19,5.8],[14,18.76]],"id":52671560},{"atb":[[4.3,73.9],[5.3,24.31]],"id":52237612},{"atb":[[13.5,8.36],[9.4,29.03]],"id":52671551},{"atb":[[19,5.8],[14,18.76]],"id":52671550},{"atb":[[130,1.88],[230,0.45]],"id":52671547},{"atb":[[2.8,58.07],[2.6,152.44]],"id":52671546},{"atb":[[75,1.41],[40,6.25]],"id":52237617},{"atb":[[390,0.62],[490,0.21]],"id":52671549},{"atb":[[310,0.78],[410,0.25]],"id":52671548},{"atb":[[5.5,54.2],[7,17.42]],"id":52671543},{"atb":[[32,3.37],[21,12.19]],"id":52671542},{"atb":[[6.8,42.05],[8.8,13.4]],"id":52671545},{"atb":[[6.2,46.9],[8.2,14.51]],"id":52671544}],"con":true,"img":false}]}
{"op":"mcm","clk":"11449099388","pt":1717303849619,"mc":[{"id":"1.229554918","rc":[{"atb":[[3.45,42.66],[2.98,123.18]],"id":52237628},{"atb":[[65,1.63],[36,6.96]],"id":52671563},{"atb":[[9.6,28.36],[14,8.04]],"id":52671565},{"atb":[[5.1,25.49],[4.1,78.68]],"id":52671555},{"atb":[[10.5,11],[8.2,33.87]],"id":52237624},{"atb":[[9.8,27.71],[14.5,7.74]],"id":52671552},{"atb":[[17.5,14.77],[25,4.35]],"id":52237627},{"atb":[[38,2.82],[24,10.6]],"id":52671562},{"atb":[[85,1.24],[44,5.67]],"id":52671564},{"atb":[[7.2,39.33],[9.2,12.74]],"id":52237621},{"atb":[[16.5,6.74],[11.5,23.22]],"id":52671554},{"atb":[[4.4,71.73],[5.4,23.75]],"id":52671556},{"atb":[[4.5,29.86],[3.75,88.69]],"id":52671553},{"atb":[[8.6,32.09],[11.5,9.95]],"id":52237634}],"con":true,"img":false}]}
{"op":"mcm","clk":"11449136316","pt":1717304580407,"mc":[{"id":"1.229554918","rc":[{"atb":[[17.5,6.34],[20,4.13],[25,2.18],[30,0.9]],"id":52671552},{"atb":[[130,2.7],[280,0.09],[180,0.44],[230,0.69]],"id":52671547}],"con":true,"img":false}]}
{"op":"mcm","clk":"11449136323","pt":1717304580505,"mc":[{"id":"1.229554918","rc":[{"atb":[[6.4,4.84],[5.2,18.68],[5.7,11.13],[4.7,28.28]],"id":52237628},{"atb":[[170,0.16],[85,0.94],[120,0.44],[60,1.77]],"id":52671563},{"atb":[[17,6.54],[19.5,4.24],[24,2.28],[29,0.94]],"id":52671565},{"atb":[[840,0.13],[890,0.09],[940,0.06],[990,0.03]],"id":52671561},{"atb":[[6.4,4.84],[5.2,18.68],[5.7,11.13],[4.7,28.28]],"id":52671555},{"atb":[[36,0.75],[19,5.81],[23,3.57],[28,1.94]],"id":52237624},{"atb":[[8,14.95],[9,9.81],[10,5.81],[12.5,2.28]],"id":52237612},{"atb":[[65,0.41],[36,2.24],[46,1.16],[28,3.88]],"id":52671550},{"atb":[[3.1,24.91],[3.35,11.13],[2.84,56.87],[2.94,40.45]],"id":52671546},{"atb":[[280,0.28],[330,0.16],[380,0.07],[230,0.46]],"id":52671548},{"atb":[[130,0.2],[65,1.22],[90,0.59],[46,2.32]],"id":52671542},{"atb":[[16,3.49],[18.5,1.5],[11,10.46],[13.5,6.28]],"id":52671544},{"atb":[[80,0.66],[42,2.55],[110,0.24],[55,1.45]],"id":52237627},{"atb":[[130,0.2],[65,1.22],[90,0.59],[46,2.32]],"id":52671562},{"atb":[[140,0.38],[70,1.52],[190,0.14],[95,0.84]],"id":52671564},{"atb":[[16,6.97],[18.5,4.48],[22,2.49],[27,1]],"id":52237621},{"atb":[[34,2.38],[44,1.22],[27,4.02],[60,0.44]],"id":52671560},{"atb":[[38,0.71],[19.5,5.66],[24,3.41],[29,1.87]],"id":52671554},{"atb":[[4.5,29.89],[5,19.62],[5.5,11.63],[6,5.23]],"id":52671556},{"atb":[[17,6.54],[19.5,4.24],[24,2.28],[29,0.94]],"id":52671551},{"atb":[[3.6,40.24],[3.85,27.54],[4.2,16.35],[4.7,7.07]],"id":52671553},{"atb":[[150,0.53],[200,0.26],[100,1.06],[250,0.1]],"id":52237617},{"atb":[[260,0.4],[310,0.26],[360,0.15],[410,0.06]],"id":52671549},{"atb":[[9.6,9.12],[8.6,13.77],[11.5,4.98],[14,2.01]],"id":52671543},{"atb":[[40,0.67],[20,5.51],[25,3.27],[30,1.81]],"id":52237634},{"atb":[[17.5,3.17],[20,1.38],[12.5,9.1],[15,5.6]],"id":52671545}],"con":true,"img":false}]}
{"op":"mcm","clk":"11449138162","pt":1717304614871,"mc":[{"id":"1.229554918","rc":[{"atb":[[6.4,0],[5.2,0],[5.7,0],[4.7,0]],"id":52237628},{"atb":[[170,0],[85,0],[120,0],[60,0]],"id":52671563},{"atb":[[17,0],[19.5,0],[24,0],[29,0]],"id":52671565},{"atb":[[280,0],[330,0],[380,0],[230,0]],"id":52671548},{"atb":[[80,0],[42,0],[110,0],[55,0]],"id":52237627},{"atb":[[130,1.88],[280,0],[180,0],[230,0.45]],"id":52671547},{"atb":[[260,0],[310,0],[360,0],[410,0]],"id":52671549},{"atb":[[17.5,0],[20,0],[12.5,0],[15,0]],"id":52671545}],"con":true,"img":false}]}
{"op":"mcm","clk":"11449138212","pt":1717304615587,"mc":[{"id":"1.229554918","rc":[{"atb":[[5.6,11.37],[5.1,19.14],[4.6,29.07],[6.2,5.03]],"id":52237628},{"atb":[[65,3.27],[130,0.41],[180,0.15],[90,0.88]],"id":52671563},{"atb":[[16.5,6.75],[19,4.36],[23,2.38],[28,0.97]],"id":52671565},{"atb":[[290,0.27],[340,0.15],[390,0.07],[240,0.44]],"id":52671548},{"atb":[[85,0.62],[44,2.43],[120,0.22],[60,1.33]],"id":52237627},{"atb":[[140,0.75],[290,0.09],[190,0.41],[240,0.22]],"id":52671547},{"atb":[[270,0.39],[320,0.25],[370,0.14],[420,0.06]],"id":52671549},{"atb":[[18,3.08],[21,1.31],[13,8.72],[15.5,5.41]],"id":52671545}],"con":true,"img":false}]}
{"op":"mcm","clk":"11449204394","pt":1717305552537,"mc":[{"id":"1.229554918","rc":[{"atb":[[17.5,0],[20,0],[25,0],[30,0]],"id":52671552},{"atb":[[17,0],[19.5,0],[24,0],[29,0]],"id":52671551}],"con":true,"img":false}]}
{"op":"mcm","clk":"11449204465","pt":1717305553218,"mc":[{"id":"1.229554918","rc":[{"atb":[[17.5,6.34],[20,4.13],[25,2.18],[30,0.9]],"id":52671552},{"atb":[[17,6.54],[19.5,4.24],[24,2.28],[29,0.94]],"id":52671551}],"con":true,"img":false}]}
{"op":"mcm","clk":"11449256634","pt":1717306272841,"mc":[{"id":"1.229554918","rc":[{"atb":[[5.6,0],[5.1,0],[4.6,0],[6.2,0]],"id":52237628},{"atb":[[130,0],[65,1.63],[180,0],[90,0]],"id":52671563},{"atb":[[16.5,0],[19,0],[23,0],[28,0]],"id":52671565},{"atb":[[290,0],[340,0],[390,0],[240,0]],"id":52671548},{"atb":[[85,0],[44,0],[120,0],[60,0]],"id":52237627},{"atb":[[140,0],[290,0],[190,0],[240,0]],"id":52671547},{"atb":[[270,0],[320,0],[370,0],[420,0]],"id":52671549},{"atb":[[18,0],[21,0],[13,0],[15.5,0]],"id":52671545}],"con":true,"img":false}]}
{"op":"mcm","clk":"11449256702","pt":1717306273517,"mc":[{"id":"1.229554918","rc":[{"atb":[[6.4,4.84],[5.2,18.68],[5.7,11.13],[4.7,28.28]],"id":52237628},{"atb":[[170,0.16],[85,0.94],[120,0.44],[60,1.77]],"id":52671563},{"atb":[[17,6.54],[19.5,4.24],[24,2.28],[29,0.94]],"id":52671565},{"atb":[[280,0.28],[330,0.16],[380,0.07],[230,0.46]],"id":52671548},{"atb":[[80,0.66],[42,2.55],[110,0.24],[55,1.45]],"id":52237627},{"atb":[[130,2.7],[280,0.09],[180,0.44],[230,0.69]],"id":52671547},{"atb":[[260,0.4],[310,0.26],[360,0.15],[410,0.06]],"id":52671549},{"atb":[[17.5,3.17],[20,1.38],[12.5,9.1],[15,5.6]],"id":52671545}],"con":true,"img":false}]}
{"op":"mcm","clk":"11449264761","pt":1717306377564,"mc":[{"id":"1.229554918","rc":[{"atb":[[65,0],[36,0],[46,0],[28,0]],"id":52671550},{"atb":[[17.5,0],[20,0],[25,0],[30,0]],"id":52671552},{"atb":[[3.6,0],[3.85,0],[4.2,0],[4.7,0]],"id":52671553},{"atb":[[260,0],[310,0],[360,0],[410,0]],"id":52671549}],"con":true,"img":false}]}
{"op":"mcm","clk":"11449264767","pt":1717306377665,"mc":[{"id":"1.229554918","rc":[{"atb":[[6.4,0],[5.2,0],[5.7,0],[4.7,0]],"id":52671555},{"atb":[[280,0],[330,0],[380,0],[230,0]],"id":52671548},{"atb":[[38,0],[19.5,0],[24,0],[29,0]],"id":52671554},{"atb":[[17,0],[19.5,0],[24,0],[29,0]],"id":52671551},{"atb":[[130,1.88],[280,0],[180,0],[230,0.45]],"id":52671547}],"con":true,"img":false}]}
{"op":"mcm","clk":"11449264815","pt":1717306378284,"mc":[{"id":"1.229554918","rc":[{"atb":[[40,1.34],[50,0.53],[25,4.36],[30,2.71]],"id":52671550},{"atb":[[17.5,4.76],[20,2.75],[25,1.09],[15,7.48]],"id":52671552},{"atb":[[4,17.44],[4.5,37.34],[3.5,41.85],[3.75,117.23]],"id":52671553},{"atb":[[300,0.17],[350,0.07],[200,0.53],[250,0.31]],"id":52671549}],"con":true,"img":false}]}
{"op":"mcm","clk":"11449264823","pt":1717306378389,"mc":[{"id":"1.229554918","rc":[{"atb":[[4.8,27.54],[5.8,10.9],[5.3,18.25],[6.6,4.67]],"id":52671555},{"atb":[[280,0.19],[330,0.08],[180,0.59],[230,0.35]],"id":52671548},{"atb":[[36,0.75],[19,5.81],[23,3.57],[28,1.94]],"id":52671554},{"atb":[[17.5,4.76],[20,2.75],[25,1.09],[15,7.48]],"id":52671551},{"atb":[[160,0.33],[80,1.32],[210,0.13],[110,0.72]],"id":52671547}],"con":true,"img":false}]}
{"op":"mcm","clk":"11449267691","pt":1717306417091,"mc":[{"id":"1.229554918","rc":[{"atb":[[6.4,0],[5.2,0],[5.7,0],[4.7,0]],"id":52237628}],"con":true,"img":false}]}
{"op":"mcm","clk":"11449267699","pt":1717306417195,"mc":[{"id":"1.229554918","rc":[{"atb":[[17,0],[19.5,0],[24,0],[29,0]],"id":52671565}],"con":true,"img":false}]}
{"op":"mcm","clk":"11449267743","pt":1717306417819,"mc":[{"id":"1.229554918","rc":[{"atb":[[5.6,11.37],[5.1,19.14],[4.6,29.07],[6.2,5.03]],"id":52237628}],"con":true,"img":false}]}
{"op":"mcm","clk":"11449267749","pt":1717306417921,"mc":[{"id":"1.229554918","rc":[{"atb":[[16.5,6.75],[19,4.36],[23,2.38],[28,0.97]],"id":52671565}],"con":true,"img":false}]}
{"op":"mcm","clk":"11449289064","pt":1717306703015,"mc":[{"id":"1.229554918","rc":[{"atb":[[40,0],[50,0],[25,0],[30,0]],"id":52671550},{"atb":[[280,0],[330,0],[180,0],[230,0]],"id":52671548},{"atb":[[4.5,0],[5,0],[5.5,0],[6,0]],"id":52671556},{"atb":[[160,0],[80,0],[210,0],[110,0]],"id":52671547},{"atb":[[300,0],[350,0],[200,0],[250,0]],"id":52671549}],"con":true,"img":false}]}
{"op":"mcm","clk":"11449289130","pt":1717306703797,"mc":[{"id":"1.229554918","rc":[{"atb":[[32,1.69],[42,0.64],[21,5.23],[26,3.14]],"id":52671550}],"con":true,"img":false}]}
{"op":"mcm","clk":"11449289161","pt":1717306704263,"mc":[{"id":"1.229554918","rc":[{"atb":[[140,0.75],[290,0.09],[190,0.41],[240,0.22]],"id":52671548},{"atb":[[6.4,4.84],[5.2,18.68],[5.7,11.13],[4.7,28.28]],"id":52671556},{"atb":[[150,0.35],[75,1.41],[200,0.13],[100,0.8]],"id":52671547},{"atb":[[260,0.2],[310,0.08],[160,0.66],[210,0.38]],"id":52671549}],"con":true,"img":false}]}
{"op":"mcm","clk":"11449296632","pt":1717306798167,"mc":[{"id":"1.229554918","rc":[{"atb":[[260,0],[310,0],[160,0],[210,0]],"id":52671549}],"con":true,"img":false}]}
{"op":"mcm","clk":"11449296687","pt":1717306798889,"mc":[{"id":"1.229554918","rc":[{"atb":[[260,0.2],[310,0.08],[160,0.66],[210,0.38]],"id":52671549}],"con":true,"img":false}]}
{"op":"mcm","clk":"11449361525","pt":1717307909967,"mc":[{"id":"1.229554918","rc":[{"atb":[[170,0],[85,0],[120,0],[60,0]],"id":52671563},{"atb":[[80,0],[42,0],[110,0],[55,0]],"id":52237627},{"atb":[[17.5,0],[12.5,0],[15,0]],"id":52671545}],"con":true,"img":false}]}
{"op":"mcm","clk":"11449361527","pt":1717307910023,"mc":[{"id":"1.229554918","rc":[{"atb":[[20,0]],"id":52671545}],"con":true,"img":false}]}
{"op":"mcm","clk":"11449361556","pt":1717307910638,"mc":[{"id":"1.229554918","rc":[{"atb":[[65,3.27],[130,0.41],[180,0.15],[90,0.88]],"id":52671563},{"atb":[[85,0.62],[44,2.43],[120,0.22],[60,1.33]],"id":52237627},{"atb":[[18,3.08],[13,8.72],[15.5,5.41]],"id":52671545}],"con":true,"img":false}]}
{"op":"mcm","clk":"11449361563","pt":1717307910740,"mc":[{"id":"1.229554918","rc":[{"atb":[[21,1.31]],"id":52671545}],"con":true,"img":false}]}
{"op":"mcm","clk":"11449365501","pt":1717308004157,"mc":[{"id":"1.229554918","rc":[{"atb":[[4,0],[4.5,29.86],[3.5,0]],"id":52671553}],"con":true,"img":false}]}
{"op":"mcm","clk":"11449365512","pt":1717308004257,"mc":[{"id":"1.229554918","rc":[{"atb":[[4.8,0],[5.8,0],[5.3,0],[6.6,0]],"id":52671555},{"atb":[[36,0],[19,0],[23,0],[28,0]],"id":52671554},{"atb":[[17.5,0],[20,0],[25,0],[15,0]],"id":52671551},{"atb":[[3.75,88.69]],"id":52671553}],"con":true,"img":false}]}
{"op":"mcm","clk":"11449365556","pt":1717308004832,"mc":[{"id":"1.229554918","rc":[{"atb":[[5.1,6.38],[4.6,14.53],[3.8,37.37]],"id":52671553}],"con":true,"img":false}]}
{"op":"mcm","clk":"11449365562","pt":1717308004938,"mc":[{"id":"1.229554918","rc":[{"atb":[[6.8,4.51],[4.9,26.83],[5.9,10.68],[5.4,17.84]],"id":52671555},{"atb":[[40,0.67],[20,5.51],[25,3.27],[30,1.81]],"id":52671554},{"atb":[[17.5,6.34],[20,4.13],[25,2.18],[30,0.9]],"id":52671551},{"atb":[[4.1,25.32]],"id":52671553}],"con":true,"img":false}]}
{"op":"mcm","clk":"11449372909","pt":1717308161549,"mc":[{"id":"1.229554918","rc":[{"atb":[[130,0],[65,1.63],[180,0],[90,0]],"id":52671563},{"atb":[[16.5,0],[19,0],[23,0],[28,0]],"id":52671565},{"atb":[[85,0],[44,0],[120,0],[60,0]],"id":52237627},{"atb":[[18,0],[21,0],[13,0],[15.5,0]],"id":52671545}],"con":true,"img":false}]}
{"op":"mcm","clk":"11449372944","pt":1717308162626,"mc":[{"id":"1.229554918","rc":[{"atb":[[170,0.16],[85,0.94],[120,0.44],[60,1.77]],"id":52671563},{"atb":[[17,6.54],[19.5,4.24],[24,2.28],[29,0.94]],"id":52671565},{"atb":[[80,0.66],[42,2.55],[110,0.24],[55,1.45]],"id":52237627},{"atb":[[17.5,3.17],[20,1.38],[12.5,9.1],[15,5.6]],"id":52671545}],"con":true,"img":false}]}
{"op":"mcm","clk":"11449375484","pt":1717308219493,"mc":[{"id":"1.229554918","rc":[{"atb":[[17,0],[19.5,0],[24,0],[29,0]],"id":52671565}],"con":true,"img":false}]}
{"op":"mcm","clk":"11449375530","pt":1717308220215,"mc":[{"id":"1.229554918","rc":[{"atb":[[16.5,6.75],[19,4.36],[23,2.38],[28,0.97]],"id":52671565}],"con":true,"img":false}]}
{"op":"mcm","clk":"11449377146","pt":1717308255148,"mc":[{"id":"1.229554918","rc":[{"atb":[[260,0],[310,0],[160,0],[210,0]],"id":52671549}],"con":true,"img":false}]}
{"op":"mcm","clk":"11449377191","pt":1717308255875,"mc":[{"id":"1.229554918","rc":[{"atb":[[260,0.2],[310,0.08],[160,0.66],[210,0.38]],"id":52671549}],"con":true,"img":false}]}
{"op":"mcm","clk":"11449377588","pt":1717308263446,"mc":[{"id":"1.229554918","rc":[{"atb":[[3.45,0],[2.98,0]],"id":52237628},{"atb":[[65,0],[36,0]],"id":52671563},{"atb":[[9.6,0],[14,0]],"id":52671565},{"atb":[[550,0],[650,0]],"id":52671561},{"atb":[[5.1,0],[4.1,0]],"id":52671555},{"atb":[[10.5,0],[8.2,0]],"id":52237624},{"atb":[[4.3,0],[5.3,0]],"id":52237612},{"atb":[[19,0],[14,0]],"id":52671550},{"atb":[[9.8,0],[14.5,0]],"id":52671552},{"atb":[[2.8,0],[2.6,0]],"id":52671546},{"atb":[[310,0],[410,0]],"id":52671548},{"atb":[[32,0],[21,0]],"id":52671542},{"atb":[[6.2,0],[8.2,0]],"id":52671544},{"atb":[[17.5,0],[25,0]],"id":52237627},{"atb":[[38,0],[24,0]],"id":52671562},{"atb":[[85,0],[44,0]],"id":52671564},{"atb":[[7.2,0],[9.2,0]],"id":52237621},{"atb":[[19,0],[14,0]],"id":52671560},{"atb":[[16.5,0],[11.5,0]],"id":52671554},{"atb":[[4.4,0],[5.4,0]],"id":52671556},{"atb":[[13.5,0],[9.4,0]],"id":52671551},{"atb":[[4.5,0],[3.75,0]],"id":52671553},{"atb":[[130,0],[230,0]],"id":52671547},{"atb":[[75,0],[40,0]],"id":52237617},{"atb":[[390,0],[490,0]],"id":52671549},{"atb":[[5.5,0],[7,0]],"id":52671543},{"atb":[[8.6,0],[11.5,0]],"id":52237634},{"atb":[[6.8,0],[8.8,0]],"id":52671545}],"con":true,"img":false}]}
{"op":"mcm","clk":"11449380791","pt":1717308317713,"mc":[{"id":"1.229554918","rc":[{"atb":[[3.45,42.66],[2.98,123.18]],"id":52237628},{"atb":[[65,1.63],[36,6.96]],"id":52671563},{"atb":[[9.6,28.36],[14,8.04]],"id":52671565},{"atb":[[550,0.44],[650,0.16]],"id":52671561},{"atb":[[5.1,25.49],[4.1,78.68]],"id":52671555},{"atb":[[10.5,11],[8.2,33.87]],"id":52237624},{"atb":[[4.4,71.73],[5.4,23.75]],"id":52237612},{"atb":[[19,5.8],[14,18.76]],"id":52671550},{"atb":[[9.8,27.71],[14.5,7.74]],"id":52671552},{"atb":[[2.58,154.36],[2.78,58.72]],"id":52671546},{"atb":[[330,0.74],[430,0.24]],"id":52671548},{"atb":[[34,3.16],[22,11.61]],"id":52671542},{"atb":[[6.4,45.16],[8.4,14.12]],"id":52671544},{"atb":[[17.5,14.77],[25,4.35]],"id":52237627},{"atb":[[40,2.67],[25,10.16]],"id":52671562},{"atb":[[90,1.17],[46,5.42]],"id":52671564},{"atb":[[7.2,39.33],[9.2,12.74]],"id":52237621},{"atb":[[19,5.8],[14,18.76]],"id":52671560},{"atb":[[16.5,6.74],[11.5,23.22]],"id":52671554},{"atb":[[4.4,71.73],[5.4,23.75]],"id":52671556},{"atb":[[9.6,28.36],[14,8.04]],"id":52671551},{"atb":[[3.7,90.33],[4.4,30.74]],"id":52671553},{"atb":[[150,1.99],[250,0.41]],"id":52671547},{"atb":[[80,1.32],[42,5.94]],"id":52237617},{"atb":[[520,0.19],[420,0.58]],"id":52671549},{"atb":[[5.6,53.02],[7.2,16.86]],"id":52671543},{"atb":[[12,9.5],[8.8,31.27]],"id":52237634},{"atb":[[9,13.06],[7,40.65]],"id":52671545}],"con":true,"img":false}]}
{"op":"mcm","clk":"11449383836","pt":1717308365181,"mc":[{"id":"1.229554918","rc":[{"atb":[[3.45,0],[2.98,0]],"id":52237628},{"atb":[[65,0],[36,0]],"id":52671563},{"atb":[[9.6,0],[14,0]],"id":52671565},{"atb":[[550,0],[650,0]],"id":52671561},{"atb":[[5.1,0],[4.1,0]],"id":52671555},{"atb":[[10.5,0],[8.2,0]],"id":52237624},{"atb":[[4.4,0],[5.4,0]],"id":52237612},{"atb":[[19,0],[14,0]],"id":52671550},{"atb":[[9.8,0],[14.5,0]],"id":52671552},{"atb":[[2.58,0],[2.78,0]],"id":52671546},{"atb":[[330,0],[430,0]],"id":52671548},{"atb":[[34,0],[22,0]],"id":52671542},{"atb":[[6.4,0],[8.4,0]],"id":52671544},{"atb":[[17.5,0],[25,0]],"id":52237627},{"atb":[[40,0],[25,0]],"id":52671562},{"atb":[[90,0],[46,0]],"id":52671564},{"atb":[[7.2,0],[9.2,0]],"id":52237621},{"atb":[[19,0],[14,0]],"id":52671560},{"atb":[[16.5,0],[11.5,0]],"id":52671554},{"atb":[[4.4,0],[5.4,0]],"id":52671556},{"atb":[[9.6,0],[14,0]],"id":52671551},{"atb":[[3.7,0],[4.4,0]],"id":52671553},{"atb":[[150,0.35],[250,0]],"id":52671547},{"atb":[[80,0],[42,0]],"id":52237617},{"atb":[[520,0],[420,0]],"id":52671549},{"atb":[[5.6,0],[7.2,0]],"id":52671543},{"atb":[[12,0],[8.8,0]],"id":52237634},{"atb":[[9,0],[7,0]],"id":52671545}],"con":true,"img":false}]}
{"op":"mcm","clk":"11449386610","pt":1717308408621,"mc":[{"id":"1.229554918","rc":[{"atb":[[2.92,127.03],[3.3,45.44]],"id":52237628},{"atb":[[80,1.32],[42,5.94]],"id":52671563},{"atb":[[13.5,8.36],[9.4,29.03]],"id":52671565},{"atb":[[550,0.44],[650,0.16]],"id":52671561},{"atb":[[5.1,25.49],[4.1,78.68]],"id":52671555},{"atb":[[8.6,32.09],[11.5,9.95]],"id":52237624},{"atb":[[4.4,71.73],[5.4,23.75]],"id":52237612},{"atb":[[18.5,5.97],[13.5,19.51]],"id":52671550},{"atb":[[10.5,25.67],[15.5,7.2]],"id":52671552},{"atb":[[2.54,158.38],[2.74,60.07]],"id":52671546},{"atb":[[380,0.64],[480,0.21]],"id":52671548},{"atb":[[34,3.16],[22,11.61]],"id":52671542},{"atb":[[9,13.06],[7,40.65]],"id":52671544},{"atb":[[17.5,14.77],[25,4.35]],"id":52237627},{"atb":[[42,2.54],[26,9.75]],"id":52671562},{"atb":[[100,1.05],[50,4.97]],"id":52671564},{"atb":[[7.4,38.1],[9.4,12.44]],"id":52237621},{"atb":[[19,5.8],[14,18.76]],"id":52671560},{"atb":[[18,6.14],[13,20.32]],"id":52671554},{"atb":[[4.4,71.73],[5.4,23.75]],"id":52671556},{"atb":[[10,27.1],[15,7.46]],"id":52671551},{"atb":[[3.7,90.33],[4.4,30.74]],"id":52671553},{"atb":[[280,0.37],[180,1.36]],"id":52671547},{"atb":[[70,1.51],[38,6.59]],"id":52237617},{"atb":[[570,0.18],[470,0.51]],"id":52671549},{"atb":[[5.8,50.81],[7.6,15.83]],"id":52671543},{"atb":[[9,30.48],[12.5,9.08]],"id":52237634},{"atb":[[7.4,38.1],[9.4,12.44]],"id":52671545}],"con":true,"img":false}]}
{"op":"mcm","clk":"11449461747","pt":1717309501739,"mc":[{"id":"1.229554918","rc":[{"atb":[[260,0],[310,0],[160,0],[210,0]],"id":52671549}],"con":true,"img":false}]}
{"op":"mcm","clk":"11449461796","pt":1717309502418,"mc":[{"id":"1.229554918","rc":[{"atb":[[260,0.2],[310,0.08],[160,0.66],[210,0.38]],"id":52671549}],"con":true,"img":false}]}
{"op":"mcm","clk":"11449539689","pt":1717310612043,"mc":[{"id":"1.229554918","rc":[{"atb":[[16.5,0],[19,0],[23,0],[28,0]],"id":52671565},{"atb":[[8,0],[9,0],[10,0],[12.5,0]],"id":52237612},{"atb":[[3.1,0],[3.35,0],[2.84,0],[2.94,0]],"id":52671546},{"atb":[[16,0],[18.5,0],[11,0],[13.5,0]],"id":52671544},{"atb":[[16,0],[18.5,0],[22,0],[27,0]],"id":52237621},{"atb":[[9.6,0],[8.6,0],[11.5,0],[14,0]],"id":52671543}],"con":true,"img":false}]}
{"op":"mcm","clk":"11449539734","pt":1717310612767,"mc":[{"id":"1.229554918","rc":[{"atb":[[17,6.54],[19.5,4.24],[24,2.28],[29,0.94]],"id":52671565},{"atb":[[9.2,9.57],[10.5,5.51],[8.2,14.53],[13,2.18]],"id":52237612},{"atb":[[2.86,56.26],[3.4,10.9],[3.15,24.33],[2.96,40.04]],"id":52671546},{"atb":[[16.5,3.37],[19,1.45],[11.5,9.97],[14,6.04]],"id":52671544},{"atb":[[18,4.61],[21,2.62],[26,1.05],[15.5,7.21]],"id":52237621},{"atb":[[11,5.23],[13.5,2.09],[8.4,14.14],[9.4,9.34]],"id":52671543}],"con":true,"img":false}]}
{"op":"mcm","clk":"11449539881","pt":1717310615659,"mc":[{"id":"1.229554918","rc":[{"atb":[[17,0],[19.5,0],[24,0],[29,0]],"id":52671565},{"atb":[[9.2,0],[10.5,0],[8.2,0],[13,0]],"id":52237612},{"atb":[[18,0],[21,0],[26,0],[15.5,0]],"id":52237621},{"atb":[[11,0],[13.5,0],[8.4,0],[9.4,0]],"id":52671543}],"con":true,"img":false}]}
{"op":"mcm","clk":"11449539918","pt":1717310616375,"mc":[{"id":"1.229554918","rc":[{"atb":[[17,6.54],[19.5,4.24],[24,2.28],[29,0.94]],"id":52671565},{"atb":[[9.2,9.57],[10.5,5.51],[8.2,14.53],[13,2.18]],"id":52237612},{"atb":[[18,4.61],[21,2.62],[26,1.05],[15.5,7.21]],"id":52237621},{"atb":[[11,5.23],[13.5,2.09],[8.4,14.14],[9.4,9.34]],"id":52671543}],"con":true,"img":false}]}
{"op":"mcm","clk":"11449541154","pt":1717310639823,"mc":[{"id":"1.229554918","rc":[{"atb":[[17,0],[19.5,0],[24,0],[29,0]],"id":52671565},{"atb":[[9.2,0],[10.5,0],[8.2,0],[13,0]],"id":52237612},{"atb":[[16.5,0],[19,0],[11.5,0],[14,0]],"id":52671544},{"atb":[[18,0],[21,0],[26,0],[15.5,0]],"id":52237621},{"atb":[[11,0],[13.5,0],[8.4,0],[9.4,0]],"id":52671543}],"con":true,"img":false}]}
{"op":"mcm","clk":"11449541197","pt":1717310640498,"mc":[{"id":"1.229554918","rc":[{"atb":[[8,14.95],[9,9.81],[10,5.81],[12.5,2.28]],"id":52237612},{"atb":[[16,3.49],[18.5,1.5],[11,10.46],[13.5,6.28]],"id":52671544},{"atb":[[16,6.97],[18.5,4.48],[22,2.49],[27,1]],"id":52237621},{"atb":[[9.6,9.12],[8.6,13.77],[11.5,4.98],[14,2.01]],"id":52671543}],"con":true,"img":false}]}
{"op":"mcm","clk":"11449541203","pt":1717310640596,"mc":[{"id":"1.229554918","rc":[{"atb":[[16.5,6.75],[19,4.36],[23,2.38],[28,0.97]],"id":52671565}],"con":true,"img":false}]}
{"op":"mcm","clk":"11449544827","pt":1717310703363,"mc":[{"id":"1.229554918","rc":[{"atb":[[16.5,0],[19,0],[23,0],[28,0]],"id":52671565},{"atb":[[16,0],[18.5,0],[22,0],[27,0]],"id":52237621},{"atb":[[9.6,0],[8.6,0],[11.5,0],[14,0]],"id":52671543}],"con":true,"img":false}]}
{"op":"mcm","clk":"11449544835","pt":1717310703467,"mc":[{"id":"1.229554918","rc":[{"atb":[[40,0],[20,0],[25,0],[30,0]],"id":52671554},{"atb":[[6.4,0],[5.2,0],[5.7,0],[4.7,0]],"id":52671556},{"atb":[[17.5,0],[20,0],[25,0],[30,0]],"id":52671551},{"atb":[[5.1,0],[4.6,0],[4.1,0],[3.8,0]],"id":52671553},{"atb":[[150,0],[75,0],[200,0],[100,0]],"id":52671547}],"con":true,"img":false}]}
{"op":"mcm","clk":"11449544864","pt":1717310704086,"mc":[{"id":"1.229554918","rc":[{"atb":[[17,6.54],[19.5,4.24],[24,2.28],[29,0.94]],"id":52671565},{"atb":[[18,4.61],[21,2.62],[26,1.05],[15.5,7.21]],"id":52237621},{"atb":[[11,5.23],[13.5,2.09],[8.4,14.14],[9.4,9.34]],"id":52671543}],"con":true,"img":false}]}
{"op":"mcm","clk":"11449544870","pt":1717310704191,"mc":[{"id":"1.229554918","rc":[{"atb":[[32,1.69],[42,0.64],[21,5.23],[26,3.14]],"id":52671554},{"atb":[[4.8,27.54],[5.8,10.9],[5.3,18.25],[6.6,4.67]],"id":52671556},{"atb":[[17.5,6.34],[20,4.13],[25,2.18],[30,0.9]],"id":52671551},{"atb":[[140,0.38],[70,1.52],[190,0.14],[95,0.84]],"id":52671547}],"con":true,"img":false}]}
{"op":"mcm","clk":"11449544879","pt":1717310704293,"mc":[{"id":"1.229554918","rc":[{"atb":[[3.95,26.6],[3.7,129.09],[4.9,6.71],[4.4,46.13]],"id":52671553}],"con":true,"img":false}]}
{"op":"mcm","clk":"11449546570","pt":1717310733145,"mc":[{"id":"1.229554918","rc":[{"atb":[[2.92,0],[3.3,0]],"id":52237628},{"atb":[[80,0],[42,0]],"id":52671563},{"atb":[[13.5,0],[9.4,0]],"id":52671565},{"atb":[[550,0],[650,0]],"id":52671561},{"atb":[[5.1,0],[4.1,0]],"id":52671555},{"atb":[[8.6,0],[11.5,0]],"id":52237624},{"atb":[[4.4,0],[5.4,0]],"id":52237612},{"atb":[[18.5,0],[13.5,0]],"id":52671550},{"atb":[[10.5,0],[15.5,0]],"id":52671552},{"atb":[[2.54,0],[2.74,0]],"id":52671546},{"atb":[[380,0],[480,0]],"id":52671548},{"atb":[[34,0],[22,0]],"id":52671542},{"atb":[[9,0],[7,0]],"id":52671544},{"atb":[[17.5,0],[25,0]],"id":52237627},{"atb":[[42,0],[26,0]],"id":52671562},{"atb":[[100,0],[50,0]],"id":52671564},{"atb":[[7.4,0],[9.4,0]],"id":52237621},{"atb":[[19,0],[14,0]],"id":52671560},{"atb":[[18,0],[13,0]],"id":52671554},{"atb":[[4.4,0],[5.4,0]],"id":52671556},{"atb":[[10,0],[15,0]],"id":52671551},{"atb":[[3.7,38.75],[4.4,15.39]],"id":52671553},{"atb":[[280,0],[180,0]],"id":52671547},{"atb":[[70,0],[38,0]],"id":52237617},{"atb":[[570,0],[470,0]],"id":52671549},{"atb":[[5.8,0],[7.6,0]],"id":52671543},{"atb":[[9,0],[12.5,0]],"id":52237634},{"atb":[[7.4,0],[9.4,0]],"id":52671545}],"con":true,"img":false}]}
{"op":"mcm","clk":"11449548313","pt":1717310762059,"mc":[{"id":"1.229554918","rc":[{"atb":[[2.92,127.03],[3.3,45.44]],"id":52237628},{"atb":[[85,2.18],[44,5.67]],"id":52671563},{"atb":[[13.5,8.36],[9.4,29.03]],"id":52671565},{"atb":[[550,0.44],[650,0.16]],"id":52671561},{"atb":[[5.2,24.88],[4.2,76.22]],"id":52671555},{"atb":[[8.6,32.09],[11.5,9.95]],"id":52237624},{"atb":[[4.5,69.68],[5.5,23.22]],"id":52237612},{"atb":[[18.5,5.97],[13.5,19.51]],"id":52671550},{"atb":[[10,27.1],[15,14.94]],"id":52671552},{"atb":[[2.58,154.36],[2.78,58.72]],"id":52671546},{"atb":[[390,0.62],[490,0.21]],"id":52671548},{"atb":[[34,3.16],[22,11.61]],"id":52671542},{"atb":[[7.2,39.33],[9.2,12.74]],"id":52671544},{"atb":[[17.5,14.77],[25,4.35]],"id":52237627},{"atb":[[38,2.82],[24,10.6]],"id":52671562},{"atb":[[110,0.95],[55,4.51]],"id":52671564},{"atb":[[7.2,39.33],[9.2,12.74]],"id":52237621},{"atb":[[19.5,5.65],[14.5,18.06]],"id":52671560},{"atb":[[18,6.14],[13,20.32]],"id":52671554},{"atb":[[4.4,71.73],[5.4,23.75]],"id":52671556},{"atb":[[9.8,27.71],[14.5,7.74]],"id":52671551},{"atb":[[4.1,33.71],[3.55,95.64]],"id":52671553},{"atb":[[130,1.88],[230,0.45]],"id":52671547},{"atb":[[75,1.41],[40,6.25]],"id":52237617},{"atb":[[580,0.18],[480,0.5]],"id":52671549},{"atb":[[7.4,16.33],[5.7,51.89]],"id":52671543},{"atb":[[9,30.48],[12.5,9.08]],"id":52237634},{"atb":[[7.4,38.1],[9.4,12.44]],"id":52671545}],"con":true,"img":false}]}
{"op":"mcm","clk":"11449550521","pt":1717310797396,"mc":[{"id":"1.229554918","rc":[{"atb":[[2.92,0],[3.3,0]],"id":52237628},{"atb":[[85,0.94],[44,0]],"id":52671563},{"atb":[[13.5,0],[9.4,0]],"id":52671565},{"atb":[[550,0],[650,0]],"id":52671561},{"atb":[[5.2,0],[4.2,0]],"id":52671555},{"atb":[[8.6,0],[11.5,0]],"id":52237624},{"atb":[[4.5,0],[5.5,0]],"id":52237612},{"atb":[[18.5,0],[13.5,0]],"id":52671550},{"atb":[[10,0],[15,7.48]],"id":52671552},{"atb":[[2.58,0],[2.78,0]],"id":52671546},{"atb":[[390,0],[490,0]],"id":52671548},{"atb":[[34,0],[22,0]],"id":52671542},{"atb":[[7.2,0],[9.2,0]],"id":52671544},{"atb":[[17.5,0],[25,0]],"id":52237627},{"atb":[[38,0],[24,0]],"id":52671562},{"atb":[[110,0],[55,0]],"id":52671564},{"atb":[[7.2,0],[9.2,0]],"id":52237621},{"atb":[[19.5,0],[14.5,0]],"id":52671560},{"atb":[[18,0],[13,0]],"id":52671554},{"atb":[[4.4,0],[5.4,0]],"id":52671556},{"atb":[[9.8,0],[14.5,0]],"id":52671551},{"atb":[[4.1,0],[3.55,0]],"id":52671553},{"atb":[[130,0],[230,0]],"id":52671547},{"atb":[[75,0],[40,0]],"id":52237617},{"atb":[[580,0],[480,0]],"id":52671549},{"atb":[[7.4,0],[5.7,0]],"id":52671543},{"atb":[[9,0],[12.5,0]],"id":52237634},{"atb":[[7.4,0],[9.4,0]],"id":52671545}],"con":true,"img":false}]}
{"op":"mcm","clk":"11449553110","pt":1717310844499,"mc":[{"id":"1.229554918","rc":[{"atb":[[3.35,44.48],[2.94,125.72]],"id":52237628},{"atb":[[85,2.18],[44,5.67]],"id":52671563},{"atb":[[13.5,8.36],[9.4,29.03]],"id":52671565},{"atb":[[5.2,24.88],[4.2,76.22]],"id":52671555},{"atb":[[8.6,32.09],[11.5,9.95]],"id":52237624},{"atb":[[10,27.1],[15,14.94]],"id":52671552},{"atb":[[17.5,14.77],[25,4.35]],"id":52237627},{"atb":[[38,2.82],[24,10.6]],"id":52671562},{"atb":[[110,0.95],[55,4.51]],"id":52671564},{"atb":[[7.2,39.33],[9.2,12.74]],"id":52237621},{"atb":[[18,6.14],[13,20.32]],"id":52671554},{"atb":[[4.4,71.73],[5.4,23.75]],"id":52671556},{"atb":[[4.1,33.71],[3.55,95.64]],"id":52671553},{"atb":[[9,30.48],[12.5,9.08]],"id":52237634}],"con":true,"img":false}]}
{"op":"mcm","clk":"11449553115","pt":1717310844600,"mc":[{"id":"1.229554918","rc":[{"atb":[[550,0.44],[650,0.16]],"id":52671561},{"atb":[[4.5,69.68],[5.5,23.22]],"id":52237612},{"atb":[[18,6.14],[13,20.32]],"id":52671550},{"atb":[[2.58,154.36],[2.78,58.72]],"id":52671546},{"atb":[[290,0.93],[390,0.26]],"id":52671548},{"atb":[[19.5,13.18],[29,3.73]],"id":52671542},{"atb":[[7.2,39.33],[9.2,12.74]],"id":52671544},{"atb":[[19.5,5.65],[14.5,18.06]],"id":52671560},{"atb":[[9.8,27.71],[14.5,7.74]],"id":52671551},{"atb":[[160,0.65],[80,3.08]],"id":52671547},{"atb":[[50,2.13],[30,8.41]],"id":52237617},{"atb":[[370,0.65],[470,0.22]],"id":52671549},{"atb":[[7.4,16.33],[5.7,51.89]],"id":52671543},{"atb":[[9.6,12.15],[7.6,36.95]],"id":52671545}],"con":true,"img":false}]}
{"op":"mcm","clk":"11449555720","pt":1717310889941,"mc":[{"id":"1.229554918","rc":[{"atb":[[140,0],[70,0],[190,0],[95,0]],"id":52671564},{"atb":[[150,0],[200,0],[100,0],[250,0]],"id":52237617}],"con":true,"img":false}]}
{"op":"mcm","clk":"11449555752","pt":1717310890652,"mc":[{"id":"1.229554918","rc":[{"atb":[[260,0.1],[160,0.49],[210,0.25],[110,0.96]],"id":52237617}],"con":true,"img":false}]}
{"op":"mcm","clk":"11449555755","pt":1717310890755,"mc":[{"id":"1.229554918","rc":[{"atb":[[150,0.35],[75,1.41],[200,0.13],[100,0.8]],"id":52671564}],"con":true,"img":false}]}
{"op":"mcm","clk":"11449557565","pt":1717310923097,"mc":[{"id":"1.229554918","rc":[{"atb":[[150,0],[75,0],[200,0],[100,0]],"id":52671564},{"atb":[[260,0],[160,0],[210,0],[110,0]],"id":52237617}],"con":true,"img":false}]}
{"op":"mcm","clk":"11449557602","pt":1717310923768,"mc":[{"id":"1.229554918","rc":[{"atb":[[140,0.38],[70,1.52],[190,0.14],[95,0.84]],"id":52671564}],"con":true,"img":false}]}
{"op":"mcm","clk":"11449557608","pt":1717310923869,"mc":[{"id":"1.229554918","rc":[{"atb":[[150,0.53],[200,0.26],[100,1.06],[250,0.1]],"id":52237617}],"con":true,"img":false}]}
{"op":"mcm","clk":"11449571725","pt":1717311187483,"mc":[{"id":"1.229554918","rc":[{"atb":[[17,0],[19.5,0],[24,0],[29,0]],"id":52671565},{"atb":[[130,0],[65,0],[90,0],[46,0]],"id":52671542},{"atb":[[130,0],[65,0],[90,0],[46,0]],"id":52671562},{"atb":[[150,0],[200,0],[100,0],[250,0]],"id":52237617},{"atb":[[40,0],[20,0],[25,0],[30,0]],"id":52237634}],"con":true,"img":false}]}
{"op":"mcm","clk":"11449571764","pt":1717311188205,"mc":[{"id":"1.229554918","rc":[{"atb":[[16.5,6.75],[19,4.36],[23,2.38],[28,0.97]],"id":52671565},{"atb":[[85,0.62],[44,2.43],[120,0.22],[60,1.33]],"id":52671542},{"atb":[[85,0.62],[44,2.43],[120,0.22],[60,1.33]],"id":52671562},{"atb":[[170,0.31],[85,1.25],[220,0.12],[120,0.66]],"id":52237617},{"atb":[[34,1.59],[44,0.61],[22,4.98],[27,3.02]],"id":52237634}],"con":true,"img":false}]}
{"op":"mcm","clk":"11449607984","pt":1717311840180,"mc":[{"id":"1.229554918","rc":[{"atb":[[16,0],[18.5,0],[11,0],[13.5,0]],"id":52671544}],"con":true,"img":false}]}
{"op":"mcm","clk":"11449608033","pt":1717311841012,"mc":[{"id":"1.229554918","rc":[{"atb":[[16.5,3.37],[19,1.45],[11.5,9.97],[14,6.04]],"id":52671544}],"con":true,"img":false}]}
{"op":"mcm","clk":"11449609377","pt":1717311864809,"mc":[{"id":"1.229554918","rc":[{"atb":[[3.35,0],[2.94,0]],"id":52237628},{"atb":[[85,0.94],[44,0]],"id":52671563},{"atb":[[13.5,0],[9.4,0]],"id":52671565},{"atb":[[550,0],[650,0]],"id":52671561},{"atb":[[5.2,0],[4.2,0]],"id":52671555},{"atb":[[8.6,0],[11.5,0]],"id":52237624},{"atb":[[4.5,0],[5.5,0]],"id":52237612},{"atb":[[18,0],[13,0]],"id":52671550},{"atb":[[10,0],[15,7.48]],"id":52671552},{"atb":[[2.58,0],[2.78,0]],"id":52671546},{"atb":[[290,0.09],[390,0]],"id":52671548},{"atb":[[19.5,0],[29,0]],"id":52671542},{"atb":[[7.2,0],[9.2,0]],"id":52671544},{"atb":[[17.5,0],[25,0]],"id":52237627},{"atb":[[38,0],[24,0]],"id":52671562},{"atb":[[110,0],[55,0]],"id":52671564},{"atb":[[7.2,0],[9.2,0]],"id":52237621},{"atb":[[19.5,0],[14.5,0]],"id":52671560},{"atb":[[18,0],[13,0]],"id":52671554},{"atb":[[4.4,0],[5.4,0]],"id":52671556},{"atb":[[9.8,0],[14.5,0]],"id":52671551},{"atb":[[4.1,0],[3.55,0]],"id":52671553},{"atb":[[160,0],[80,0]],"id":52671547},{"atb":[[50,0],[30,0]],"id":52237617},{"atb":[[370,0],[470,0]],"id":52671549},{"atb":[[7.4,0],[5.7,0]],"id":52671543},{"atb":[[9,0],[12.5,0]],"id":52237634},{"atb":[[9.6,0],[7.6,0]],"id":52671545}],"con":true,"img":false}]}
{"op":"mcm","clk":"11449610115","pt":1717311877557,"mc":[{"id":"1.229554918","rc":[{"atb":[[3.35,44.48],[2.94,125.72]],"id":52237628},{"atb":[[85,2.18],[44,5.67]],"id":52671563},{"atb":[[13.5,8.36],[9.4,29.03]],"id":52671565},{"atb":[[550,0.44],[650,0.16]],"id":52671561},{"atb":[[5.2,24.88],[4.2,76.22]],"id":52671555},{"atb":[[8.6,32.09],[11.5,9.95]],"id":52237624},{"atb":[[4.5,69.68],[5.5,23.22]],"id":52237612},{"atb":[[18,6.14],[13,20.32]],"id":52671550},{"atb":[[10,27.1],[15,14.94]],"id":52671552},{"atb":[[2.58,154.36],[2.78,58.72]],"id":52671546},{"atb":[[290,0.93],[390,0.26]],"id":52671548},{"atb":[[19.5,13.18],[29,3.73]],"id":52671542},{"atb":[[7.2,39.33],[9.2,12.74]],"id":52671544},{"atb":[[17.5,14.77],[25,4.35]],"id":52237627},{"atb":[[38,2.82],[24,10.6]],"id":52671562},{"atb":[[110,0.95],[55,4.51]],"id":52671564},{"atb":[[7.2,39.33],[9.2,12.74]],"id":52237621},{"atb":[[19.5,5.65],[14.5,18.06]],"id":52671560},{"atb":[[18,6.14],[13,20.32]],"id":52671554},{"atb":[[4.4,71.73],[5.4,23.75]],"id":52671556},{"atb":[[9.8,27.71],[14.5,7.74]],"id":52671551},{"atb":[[4.1,33.71],[3.55,95.64]],"id":52671553},{"atb":[[160,0.65],[80,3.08]],"id":52671547},{"atb":[[50,2.13],[30,8.41]],"id":52237617},{"atb":[[370,0.65],[470,0.22]],"id":52671549},{"atb":[[7.4,16.33],[5.7,51.89]],"id":52671543},{"atb":[[9,30.48],[12.5,9.08]],"id":52237634},{"atb":[[9.6,12.15],[7.6,36.95]],"id":52671545}],"con":true,"img":false}]}
{"op":"mcm","clk":"11449611584","pt":1717311905002,"mc":[{"id":"1.229554918","rc":[{"atb":[[17.5,0],[20,0],[25,0],[30,0]],"id":52671551}],"con":true,"img":false}]}
{"op":"mcm","clk":"11449611633","pt":1717311905686,"mc":[{"id":"1.229554918","rc":[{"atb":[[17.5,6.34],[20,4.13],[25,2.18],[30,0.9]],"id":52671551}],"con":true,"img":false}]}
{"op":"mcm","clk":"11449614866","pt":1717311962555,"mc":[{"id":"1.229554918","rc":[{"atb":[[3.35,0],[2.94,0]],"id":52237628},{"atb":[[85,0.94],[44,0]],"id":52671563},{"atb":[[13.5,0],[9.4,0]],"id":52671565},{"atb":[[550,0],[650,0]],"id":52671561},{"atb":[[5.2,0],[4.2,0]],"id":52671555},{"atb":[[8.6,0],[11.5,0]],"id":52237624},{"atb":[[4.5,0],[5.5,0]],"id":52237612},{"atb":[[18,0],[13,0]],"id":52671550},{"atb":[[10,0],[15,7.48]],"id":52671552},{"atb":[[2.58,0],[2.78,0]],"id":52671546},{"atb":[[290,0.09],[390,0]],"id":52671548},{"atb":[[19.5,0],[29,0]],"id":52671542},{"atb":[[7.2,0],[9.2,0]],"id":52671544},{"atb":[[17.5,0],[25,0]],"id":52237627},{"atb":[[38,0],[24,0]],"id":52671562},{"atb":[[110,0],[55,0]],"id":52671564},{"atb":[[7.2,0],[9.2,0]],"id":52237621},{"atb":[[19.5,0],[14.5,0]],"id":52671560},{"atb":[[18,0],[13,0]],"id":52671554},{"atb":[[4.4,0],[5.4,0]],"id":52671556},{"atb":[[9.8,0],[14.5,0]],"id":52671551},{"atb":[[4.1,0],[3.55,0]],"id":52671553},{"atb":[[160,0],[80,0]],"id":52671547},{"atb":[[50,0],[30,0]],"id":52237617},{"atb":[[370,0],[470,0]],"id":52671549},{"atb":[[7.4,0],[5.7,0]],"id":52671543},{"atb":[[9,0],[12.5,0]],"id":52237634},{"atb":[[9.6,0],[7.6,0]],"id":52671545}],"con":true,"img":false}]}
{"op":"mcm","clk":"11449616056","pt":1717311986580,"mc":[{"id":"1.229554918","rc":[{"atb":[[550,0.44],[650,0.16]],"id":52671561},{"atb":[[4.5,69.68],[5.5,23.22]],"id":52237612},{"atb":[[18,6.14],[13,20.32]],"id":52671550},{"atb":[[2.58,154.36],[2.78,58.72]],"id":52671546},{"atb":[[290,0.93],[390,0.26]],"id":52671548},{"atb":[[19.5,13.18],[29,3.73]],"id":52671542},{"atb":[[7.2,39.33],[9.2,12.74]],"id":52671544},{"atb":[[19.5,5.65],[14.5,18.06]],"id":52671560},{"atb":[[9.8,27.71],[14.5,7.74]],"id":52671551},{"atb":[[160,0.65],[80,3.08]],"id":52671547},{"atb":[[50,2.13],[30,8.41]],"id":52237617},{"atb":[[370,0.65],[470,0.22]],"id":52671549},{"atb":[[7.4,16.33],[5.7,51.89]],"id":52671543},{"atb":[[9.6,12.15],[7.6,36.95]],"id":52671545}],"con":true,"img":false}]}
{"op":"mcm","clk":"11449616064","pt":1717311986688,"mc":[{"id":"1.229554918","rc":[{"atb":[[3.35,44.48],[2.94,125.72]],"id":52237628},{"atb":[[85,2.18],[44,5.67]],"id":52671563},{"atb":[[13.5,8.36],[9.4,29.03]],"id":52671565},{"atb":[[5.2,24.88],[4.2,76.22]],"id":52671555},{"atb":[[8.6,32.09],[11.5,9.95]],"id":52237624},{"atb":[[10,27.1],[15,14.94]],"id":52671552},{"atb":[[17.5,14.77],[25,4.35]],"id":52237627},{"atb":[[38,2.82],[24,10.6]],"id":52671562},{"atb":[[110,0.95],[55,4.51]],"id":52671564},{"atb":[[7.2,39.33],[9.2,12.74]],"id":52237621},{"atb":[[18,6.14],[13,20.32]],"id":52671554},{"atb":[[4.4,71.73],[5.4,23.75]],"id":52671556},{"atb":[[4.1,33.71],[3.55,95.64]],"id":52671553},{"atb":[[9,30.48],[12.5,9.08]],"id":52237634}],"con":true,"img":false}]}
{"op":"mcm","clk":"11449620519","pt":1717312074382,"mc":[{"id":"1.229554918","rc":[{"atb":[[140,0],[70,0],[190,0],[95,0]],"id":52671547}],"con":true,"img":false}]}
{"op":"mcm","clk":"11449620525","pt":1717312074485,"mc":[{"id":"1.229554918","rc":[{"atb":[[32,0],[42,0],[21,0],[26,0]],"id":52671554}],"con":true,"img":false}]}
{"op":"mcm","clk":"11449620551","pt":1717312075108,"mc":[{"id":"1.229554918","rc":[{"atb":[[150,0.35],[75,1.41],[200,0.13],[100,0.8]],"id":52671547}],"con":true,"img":false}]}
{"op":"mcm","clk":"11449620556","pt":1717312075210,"mc":[{"id":"1.229554918","rc":[{"atb":[[34,1.59],[44,0.61],[22,4.98],[27,3.02]],"id":52671554}],"con":true,"img":false}]}
{"op":"mcm","clk":"11449621483","pt":1717312095111,"mc":[{"id":"1.229554918","rc":[{"atb":[[140,0],[70,0],[190,0],[95,0]],"id":52671564}],"con":true,"img":false}]}
{"op":"mcm","clk":"11449621511","pt":1717312095827,"mc":[{"id":"1.229554918","rc":[{"atb":[[210,0.13]],"id":52671564}],"con":true,"img":false}]}
{"op":"mcm","clk":"11449621514","pt":1717312095932,"mc":[{"id":"1.229554918","rc":[{"atb":[[160,0.33],[80,1.32],[110,1.68]],"id":52671564}],"con":true,"img":false}]}
{"op":"mcm","clk":"11449648545","pt":1717312783254,"mc":[{"id":"1.229554918","rc":[{"atb":[[36,0],[19,0],[23,0],[28,0]],"id":52237624},{"atb":[[8,0],[9,0],[10,0],[12.5,0]],"id":52237612},{"atb":[[160,0],[80,0],[210,0],[110,0.95]],"id":52671564}],"con":true,"img":false}]}
{"op":"mcm","clk":"11449648548","pt":1717312783308,"mc":[{"id":"1.229554918","rc":[{"atb":[[18,0],[21,0],[26,0],[15.5,0]],"id":52237621},{"atb":[[34,0],[44,0],[22,0],[27,0]],"id":52237634}],"con":true,"img":false}]}
{"op":"mcm","clk":"11449648572","pt":1717312783926,"mc":[{"id":"1.229554918","rc":[{"atb":[[38,0.71],[19.5,5.66],[24,3.41],[29,1.87]],"id":52237624},{"atb":[[11,5.23],[13.5,2.09],[8.4,14.14],[9.4,9.34]],"id":52237612},{"atb":[[150,0.35],[75,1.41],[200,0.13],[100,0.8]],"id":52671564}],"con":true,"img":false}]}
{"op":"mcm","clk":"11449648576","pt":1717312784028,"mc":[{"id":"1.229554918","rc":[{"atb":[[16,6.97],[18.5,4.48],[22,2.49],[27,1]],"id":52237621},{"atb":[[36,1.5],[46,0.58],[23,4.76],[28,2.91]],"id":52237634}],"con":true,"img":false}]}
{"op":"mcm","clk":"11449648599","pt":1717312784745,"mc":[{"id":"1.229554918","rc":[{"atb":[[16,0],[18.5,0],[22,0],[27,0]],"id":52237621},{"atb":[[36,0],[46,0],[23,0],[28,0]],"id":52237634}],"con":true,"img":false}]}
{"op":"mcm","clk":"11449648619","pt":1717312785418,"mc":[{"id":"1.229554918","rc":[{"atb":[[18,4.61],[21,2.62],[26,1.05],[15.5,7.21]],"id":52237621},{"atb":[[34,1.59],[44,0.61],[22,4.98],[27,3.02]],"id":52237634}],"con":true,"img":false}]}
{"op":"mcm","clk":"11449648784","pt":1717312789657,"mc":[{"id":"1.229554918","rc":[{"atb":[[38,0],[19.5,0],[24,0],[29,0]],"id":52237624},{"atb":[[11,0],[13.5,0],[8.4,0],[9.4,0]],"id":52237612}],"con":true,"img":false}]}
{"op":"mcm","clk":"11449648810","pt":1717312790326,"mc":[{"id":"1.229554918","rc":[{"atb":[[36,0.75],[19,5.81],[23,3.57],[28,1.94]],"id":52237624},{"atb":[[8,14.95],[9,9.81],[10,5.81],[12.5,2.28]],"id":52237612}],"con":true,"img":false}]}
{"op":"mcm","clk":"11449655976","pt":1717312956393,"mc":[{"id":"1.229554918","rc":[{"atb":[[3.35,0],[2.94,0]],"id":52237628},{"atb":[[85,0.94],[44,0]],"id":52671563},{"atb":[[13.5,0],[9.4,0]],"id":52671565},{"atb":[[550,0],[650,0]],"id":52671561},{"atb":[[5.2,0],[4.2,0]],"id":52671555},{"atb":[[8.6,0],[11.5,0]],"id":52237624},{"atb":[[4.5,0],[5.5,0]],"id":52237612},{"atb":[[18,0],[13,0]],"id":52671550},{"atb":[[10,0],[15,7.48]],"id":52671552},{"atb":[[2.58,0],[2.78,0]],"id":52671546},{"atb":[[290,0.09],[390,0]],"id":52671548},{"atb":[[19.5,0],[29,0]],"id":52671542},{"atb":[[7.2,0],[9.2,0]],"id":52671544},{"atb":[[17.5,0],[25,0]],"id":52237627},{"atb":[[38,0],[24,0]],"id":52671562},{"atb":[[110,0],[55,0]],"id":52671564},{"atb":[[7.2,0],[9.2,0]],"id":52237621},{"atb":[[19.5,0],[14.5,0]],"id":52671560},{"atb":[[18,0],[13,0]],"id":52671554},{"atb":[[4.4,0],[5.4,0]],"id":52671556},{"atb":[[9.8,0],[14.5,0]],"id":52671551},{"atb":[[4.1,0],[3.55,0]],"id":52671553},{"atb":[[160,0],[80,0]],"id":52671547},{"atb":[[50,0],[30,0]],"id":52237617},{"atb":[[370,0],[470,0]],"id":52671549},{"atb":[[7.4,0],[5.7,0]],"id":52671543},{"atb":[[9,0],[12.5,0]],"id":52237634},{"atb":[[9.6,0],[7.6,0]],"id":52671545}],"con":true,"img":false}]}
{"op":"mcm","clk":"11449656393","pt":1717312966043,"mc":[{"id":"1.229554918","rc":[{"atb":[[3.35,44.48],[2.94,125.72]],"id":52237628},{"atb":[[85,2.18],[44,5.67]],"id":52671563},{"atb":[[13.5,8.36],[9.4,29.03]],"id":52671565},{"atb":[[550,0.44],[650,0.16]],"id":52671561},{"atb":[[5.2,24.88],[4.2,76.22]],"id":52671555},{"atb":[[8.6,32.09],[11.5,9.95]],"id":52237624},{"atb":[[4.5,69.68],[5.5,23.22]],"id":52237612},{"atb":[[18,6.14],[13,20.32]],"id":52671550},{"atb":[[10,27.1],[15,14.94]],"id":52671552},{"atb":[[2.58,154.36],[2.78,58.72]],"id":52671546},{"atb":[[290,0.93],[390,0.26]],"id":52671548},{"atb":[[19.5,13.18],[29,3.73]],"id":52671542},{"atb":[[7.2,39.33],[9.2,12.74]],"id":52671544},{"atb":[[17.5,14.77],[25,4.35]],"id":52237627},{"atb":[[38,2.82],[24,10.6]],"id":52671562},{"atb":[[110,0.95],[55,4.51]],"id":52671564},{"atb":[[7.2,39.33],[9.2,12.74]],"id":52237621},{"atb":[[19.5,5.65],[14.5,18.06]],"id":52671560},{"atb":[[18,6.14],[13,20.32]],"id":52671554},{"atb":[[4.4,71.73],[5.4,23.75]],"id":52671556},{"atb":[[9.8,27.71],[14.5,7.74]],"id":52671551},{"atb":[[4.1,33.71],[3.55,95.64]],"id":52671553},{"atb":[[160,0.65],[80,3.08]],"id":52671547},{"atb":[[50,2.13],[30,8.41]],"id":52237617},{"atb":[[370,0.65],[470,0.22]],"id":52671549},{"atb":[[7.4,16.33],[5.7,51.89]],"id":52671543},{"atb":[[9,30.48],[12.5,9.08]],"id":52237634},{"atb":[[9.6,12.15],[7.6,36.95]],"id":52671545}],"con":true,"img":false}]}
{"op":"mcm","clk":"11449674299","pt":1717313350869,"mc":[{"id":"1.229554918","rc":[{"atb":[[34,0],[44,0],[22,0],[27,0]],"id":52671554}],"con":true,"img":false}]}
{"op":"mcm","clk":"11449674337","pt":1717313351592,"mc":[{"id":"1.229554918","rc":[{"atb":[[34,1.59],[44,0.61],[22,4.98],[27,3.02]],"id":52671554}],"con":true,"img":false}]}
{"op":"mcm","clk":"11449706678","pt":1717313769274,"mc":[{"id":"1.229554918","rc":[{"atb":[[150,0],[75,0],[200,0],[100,0]],"id":52671564}],"con":true,"img":false}]}
{"op":"mcm","clk":"11449706733","pt":1717313769945,"mc":[{"id":"1.229554918","rc":[{"atb":[[160,0.33],[80,1.32],[210,0.13],[110,1.68]],"id":52671564}],"con":true,"img":false}]}
{"op":"mcm","clk":"11449736747","pt":1717314096812,"mc":[{"id":"1.229554918","rc":[{"atb":[[3.35,0],[2.94,0]],"id":52237628},{"atb":[[85,0.94],[44,0]],"id":52671563},{"atb":[[13.5,0],[9.4,0]],"id":52671565},{"atb":[[550,0],[650,0]],"id":52671561},{"atb":[[5.2,0],[4.2,0]],"id":52671555},{"atb":[[8.6,0],[11.5,0]],"id":52237624},{"atb":[[4.5,0],[5.5,0]],"id":52237612},{"atb":[[18,0],[13,0]],"id":52671550},{"atb":[[10,0],[15,7.48]],"id":52671552},{"atb":[[2.58,0],[2.78,0]],"id":52671546},{"atb":[[290,0.09],[390,0]],"id":52671548},{"atb":[[19.5,0],[29,0]],"id":52671542},{"atb":[[7.2,0],[9.2,0]],"id":52671544},{"atb":[[17.5,0],[25,0]],"id":52237627},{"atb":[[38,0],[24,0]],"id":52671562},{"atb":[[110,0.72],[55,0]],"id":52671564},{"atb":[[7.2,0],[9.2,0]],"id":52237621},{"atb":[[19.5,0],[14.5,0]],"id":52671560},{"atb":[[18,0],[13,0]],"id":52671554},{"atb":[[4.4,0],[5.4,0]],"id":52671556},{"atb":[[9.8,0],[14.5,0]],"id":52671551},{"atb":[[4.1,0],[3.55,0]],"id":52671553},{"atb":[[160,0],[80,0]],"id":52671547},{"atb":[[50,0],[30,0]],"id":52237617},{"atb":[[370,0],[470,0]],"id":52671549},{"atb":[[7.4,0],[5.7,0]],"id":52671543},{"atb":[[9,0],[12.5,0]],"id":52237634},{"atb":[[9.6,0],[7.6,0]],"id":52671545}],"con":true,"img":false}]}
{"op":"mcm","clk":"11449740284","pt":1717314135147,"mc":[{"id":"1.229554918","rc":[{"atb":[[3.35,44.48],[2.94,125.72]],"id":52237628},{"atb":[[85,2.18],[44,5.67]],"id":52671563},{"atb":[[13.5,8.36],[9.4,29.03]],"id":52671565},{"atb":[[550,0.44],[650,0.16]],"id":52671561},{"atb":[[5.2,24.88],[4.2,76.22]],"id":52671555},{"atb":[[8.6,32.09],[11.5,9.95]],"id":52237624},{"atb":[[4.5,69.68],[5.5,23.22]],"id":52237612},{"atb":[[18,6.14],[13,20.32]],"id":52671550},{"atb":[[10,27.1],[15,14.94]],"id":52671552},{"atb":[[2.58,154.36],[2.78,58.72]],"id":52671546},{"atb":[[290,0.93],[390,0.26]],"id":52671548},{"atb":[[19.5,13.18],[29,3.73]],"id":52671542},{"atb":[[7.2,39.33],[9.2,12.74]],"id":52671544},{"atb":[[17.5,14.77],[25,4.35]],"id":52237627},{"atb":[[38,2.82],[24,10.6]],"id":52671562},{"atb":[[110,1.68],[55,4.51]],"id":52671564},{"atb":[[7.2,39.33],[9.2,12.74]],"id":52237621},{"atb":[[19.5,5.65],[14.5,18.06]],"id":52671560},{"atb":[[18,6.14],[13,20.32]],"id":52671554},{"atb":[[4.4,71.73],[5.4,23.75]],"id":52671556},{"atb":[[9.8,27.71],[14.5,7.74]],"id":52671551},{"atb":[[4.1,33.71],[3.55,95.64]],"id":52671553},{"atb":[[160,0.65],[80,3.08]],"id":52671547},{"atb":[[50,2.13],[30,8.41]],"id":52237617},{"atb":[[370,0.65],[470,0.22]],"id":52671549},{"atb":[[7.4,16.33],[5.7,51.89]],"id":52671543},{"atb":[[9,30.48],[12.5,9.08]],"id":52237634},{"atb":[[9.6,12.15],[7.6,36.95]],"id":52671545}],"con":true,"img":false}]}
{"op":"mcm","clk":"11449745221","pt":1717314192419,"mc":[{"id":"1.229554918","rc":[{"atb":[[3.35,0],[2.94,0]],"id":52237628},{"atb":[[85,0.94],[44,0]],"id":52671563},{"atb":[[13.5,0],[9.4,0]],"id":52671565},{"atb":[[550,0],[650,0]],"id":52671561},{"atb":[[5.2,0],[4.2,0]],"id":52671555},{"atb":[[8.6,0],[11.5,0]],"id":52237624},{"atb":[[4.5,0],[5.5,0]],"id":52237612},{"atb":[[18,0],[13,0]],"id":52671550},{"atb":[[10,0],[15,7.48]],"id":52671552},{"atb":[[2.58,0],[2.78,0]],"id":52671546},{"atb":[[290,0.09],[390,0]],"id":52671548},{"atb":[[19.5,0],[29,0]],"id":52671542},{"atb":[[7.2,0],[9.2,0]],"id":52671544},{"atb":[[17.5,0],[25,0]],"id":52237627},{"atb":[[38,0],[24,0]],"id":52671562},{"atb":[[110,0.72],[55,0]],"id":52671564},{"atb":[[7.2,0],[9.2,0]],"id":52237621},{"atb":[[19.5,0],[14.5,0]],"id":52671560},{"atb":[[18,0],[13,0]],"id":52671554},{"atb":[[4.4,0],[5.4,0]],"id":52671556},{"atb":[[9.8,0],[14.5,0]],"id":52671551},{"atb":[[4.1,0],[3.55,0]],"id":52671553},{"atb":[[160,0],[80,0]],"id":52671547},{"atb":[[50,0],[30,0]],"id":52237617},{"atb":[[370,0],[470,0]],"id":52671549},{"atb":[[7.4,0],[5.7,0]],"id":52671543},{"atb":[[9,0],[12.5,0]],"id":52237634},{"atb":[[9.6,0],[7.6,0]],"id":52671545}],"con":true,"img":false}]}
{"op":"mcm","clk":"11449747511","pt":1717314217555,"mc":[{"id":"1.229554918","rc":[{"atb":[[550,0.44],[650,0.16]],"id":52671561},{"atb":[[4.5,69.68],[5.5,23.22]],"id":52237612},{"atb":[[18,6.14],[13,20.32]],"id":52671550},{"atb":[[2.58,154.36],[2.78,58.72]],"id":52671546},{"atb":[[290,0.93],[390,0.26]],"id":52671548},{"atb":[[19.5,13.18],[29,3.73]],"id":52671542},{"atb":[[7.2,39.33],[9.2,12.74]],"id":52671544},{"atb":[[19.5,5.65],[14.5,18.06]],"id":52671560},{"atb":[[9.8,27.71],[14.5,7.74]],"id":52671551},{"atb":[[160,0.65],[80,3.08]],"id":52671547},{"atb":[[50,2.13],[30,8.41]],"id":52237617},{"atb":[[370,0.65],[470,0.22]],"id":52671549},{"atb":[[7.4,16.33],[5.7,51.89]],"id":52671543},{"atb":[[9.6,12.15],[7.6,36.95]],"id":52671545}],"con":true,"img":false}]}
{"op":"mcm","clk":"11449747522","pt":1717314217661,"mc":[{"id":"1.229554918","rc":[{"atb":[[3.35,44.48],[2.94,125.72]],"id":52237628},{"atb":[[85,2.18],[44,5.67]],"id":52671563},{"atb":[[13.5,8.36],[9.4,29.03]],"id":52671565},{"atb":[[5.2,24.88],[4.2,76.22]],"id":52671555},{"atb":[[8.6,32.09],[11.5,9.95]],"id":52237624},{"atb":[[10,27.1],[15,14.94]],"id":52671552},{"atb":[[17.5,14.77],[25,4.35]],"id":52237627},{"atb":[[38,2.82],[24,10.6]],"id":52671562},{"atb":[[110,1.68],[55,4.51]],"id":52671564},{"atb":[[7.2,39.33],[9.2,12.74]],"id":52237621},{"atb":[[18,6.14],[13,20.32]],"id":52671554},{"atb":[[4.4,71.73],[5.4,23.75]],"id":52671556},{"atb":[[4.1,33.71],[3.55,95.64]],"id":52671553},{"atb":[[9,30.48],[12.5,9.08]],"id":52237634}],"con":true,"img":false}]}
{"op":"mcm","clk":"11449752911","pt":1717314274567,"mc":[{"id":"1.229554918","rc":[{"atb":[[36,0],[19,0],[23,0],[28,0]],"id":52237624},{"atb":[[8,0],[9,0],[10,0],[12.5,0]],"id":52237612},{"atb":[[160,0],[80,0],[210,0],[110,0.95]],"id":52671564},{"atb":[[18,0],[21,0],[26,0],[15.5,0]],"id":52237621},{"atb":[[34,0],[44,0],[22,0],[27,0]],"id":52237634}],"con":true,"img":false}]}
{"op":"mcm","clk":"11449752974","pt":1717314275244,"mc":[{"id":"1.229554918","rc":[{"atb":[[8,14.95],[9,9.81],[10,5.81],[12.5,2.28]],"id":52237612},{"atb":[[160,0.33],[80,1.32],[210,0.13],[110,1.68]],"id":52671564},{"atb":[[34,1.59],[44,0.61],[22,4.98],[27,3.02]],"id":52237634}],"con":true,"img":false}]}
{"op":"mcm","clk":"11449752980","pt":1717314275350,"mc":[{"id":"1.229554918","rc":[{"atb":[[36,0.75],[19,5.81],[23,3.57],[28,1.94]],"id":52237624},{"atb":[[18,4.61],[21,2.62],[26,1.05],[15.5,7.21]],"id":52237621}],"con":true,"img":false}]}
{"op":"mcm","clk":"11449777611","pt":1717314552024,"mc":[{"id":"1.229554918","rc":[{"atb":[[34,0],[44,0],[22,0],[27,0]],"id":52671554}],"con":true,"img":false}]}
{"op":"mcm","clk":"11449777677","pt":1717314552804,"mc":[{"id":"1.229554918","rc":[{"atb":[[34,1.59],[44,0.61],[22,4.98],[27,3.02]],"id":52671554}],"con":true,"img":false}]}
{"op":"mcm","clk":"11449778884","pt":1717314565908,"mc":[{"id":"1.229554918","rc":[{"atb":[[8,0],[9,0],[10,0],[12.5,0]],"id":52237612},{"atb":[[160,0],[80,0],[210,0],[110,0.95]],"id":52671564},{"atb":[[34,0],[44,0],[22,0],[27,0]],"id":52237634}],"con":true,"img":false}]}
{"op":"mcm","clk":"11449778937","pt":1717314566628,"mc":[{"id":"1.229554918","rc":[{"atb":[[11,5.23],[13.5,2.09],[8.4,14.14],[9.4,9.34]],"id":52237612},{"atb":[[150,0.35],[75,1.41],[200,0.13],[100,0.8]],"id":52671564},{"atb":[[36,1.5],[46,0.58],[23,4.76],[28,2.91]],"id":52237634}],"con":true,"img":false}]}
{"op":"mcm","clk":"11449780034","pt":1717314578931,"mc":[{"id":"1.229554918","rc":[{"atb":[[11,0],[13.5,0],[8.4,0],[9.4,0]],"id":52237612},{"atb":[[36,0],[46,0],[23,0],[28,0]],"id":52237634}],"con":true,"img":false}]}
{"op":"mcm","clk":"11449780097","pt":1717314579604,"mc":[{"id":"1.229554918","rc":[{"atb":[[8,14.95],[9,9.81],[10,5.81],[12.5,2.28]],"id":52237612},{"atb":[[34,1.59],[44,0.61],[22,4.98],[27,3.02]],"id":52237634}],"con":true,"img":false}]}
{"op":"mcm","clk":"11449781278","pt":1717314594754,"mc":[{"id":"1.229554918","rc":[{"atb":[[16.5,0],[19,0],[23,0],[28,0]],"id":52671565},{"atb":[[85,0],[44,0],[120,0],[60,0]],"id":52671562},{"atb":[[11,0],[13.5,0],[8.4,0],[9.4,0]],"id":52671543}],"con":true,"img":false}]}
{"op":"mcm","clk":"11449781288","pt":1717314594856,"mc":[{"id":"1.229554918","rc":[{"atb":[[85,0],[44,0],[120,0],[60,0]],"id":52671542},{"atb":[[16.5,0],[19,0],[11.5,0],[14,0]],"id":52671544}],"con":true,"img":false}]}
{"op":"mcm","clk":"11449781332","pt":1717314595426,"mc":[{"id":"1.229554918","rc":[{"atb":[[16,6.97],[18.5,4.48],[22,2.49],[27,1]],"id":52671565},{"atb":[[130,0.2],[65,1.22],[90,0.59],[46,2.32]],"id":52671562},{"atb":[[9.6,9.12],[8.6,13.77],[11.5,4.98],[14,2.01]],"id":52671543}],"con":true,"img":false}]}
{"op":"mcm","clk":"11449781338","pt":1717314595530,"mc":[{"id":"1.229554918","rc":[{"atb":[[80,0.66],[42,2.55],[110,0.24],[55,1.45]],"id":52671542},{"atb":[[17.5,3.17],[20,1.38],[12.5,9.1],[15,5.6]],"id":52671544}],"con":true,"img":false}]}
{"op":"mcm","clk":"11449782539","pt":1717314610915,"mc":[{"id":"1.229554918","rc":[{"atb":[[17.5,0],[20,0],[12.5,0],[15,0]],"id":52671544},{"atb":[[130,0],[65,0],[90,0],[46,0]],"id":52671562},{"atb":[[9.6,0],[8.6,0],[11.5,0],[14,0]],"id":52671543}],"con":true,"img":false}]}
{"op":"mcm","clk":"11449782589","pt":1717314611619,"mc":[{"id":"1.229554918","rc":[{"atb":[[16.5,3.37],[19,1.45],[11.5,9.97],[14,6.04]],"id":52671544},{"atb":[[85,0.62],[44,2.43],[120,0.22],[60,1.33]],"id":52671562},{"atb":[[11,5.23],[13.5,2.09],[8.4,14.14],[9.4,9.34]],"id":52671543}],"con":true,"img":false}]}
{"op":"mcm","clk":"11449823477","pt":1717315076909,"mc":[{"id":"1.229554918","rc":[{"atb":[[6.8,0],[4.9,0],[5.9,0],[5.4,0]],"id":52671555},{"atb":[[2.86,0],[3.4,0],[3.15,0],[2.96,0]],"id":52671546},{"atb":[[34,0],[44,0],[22,0],[27,0]],"id":52671554},{"atb":[[4.8,0],[5.8,0],[5.3,0],[6.6,0]],"id":52671556},{"atb":[[17.5,0],[20,0],[25,0],[30,0]],"id":52671551},{"atb":[[3.95,0],[3.7,0],[4.9,0],[4.4,0]],"id":52671553},{"atb":[[150,0],[75,0],[200,0],[100,0]],"id":52671547}],"con":true,"img":false}]}
{"op":"mcm","clk":"11449823546","pt":1717315077637,"mc":[{"id":"1.229554918","rc":[{"atb":[[4.8,27.54],[5.8,10.9],[5.3,18.25],[6.6,4.67]],"id":52671555},{"atb":[[2.82,57.49],[2.92,40.88],[3.3,11.37],[3.05,25.52]],"id":52671546},{"atb":[[38,1.41],[48,0.55],[24,4.55],[29,2.8]],"id":52671554},{"atb":[[4.5,29.89],[5,19.62],[5.5,11.63],[6,5.23]],"id":52671556},{"atb":[[36,0.75],[19,5.81],[23,3.57],[28,1.94]],"id":52671551},{"atb":[[4.8,6.89],[4.3,15.85],[3.9,27.06],[3.65,39.48]],"id":52671553},{"atb":[[140,0.57],[190,0.28],[95,1.11],[240,0.11]],"id":52671547}],"con":true,"img":false}]}
{"op":"mcm","clk":"11449826573","pt":1717315111538,"mc":[{"id":"1.229554918","rc":[{"atb":[[26,0]],"id":52237621}],"con":true,"img":false}]}
{"op":"mcm","clk":"11449826582","pt":1717315111642,"mc":[{"id":"1.229554918","rc":[{"atb":[[36,0],[19,0],[23,0],[28,0]],"id":52237624},{"atb":[[18,0],[21,0],[15.5,0]],"id":52237621}],"con":true,"img":false}]}
{"op":"mcm","clk":"11449826636","pt":1717315112260,"mc":[{"id":"1.229554918","rc":[{"atb":[[28,0.97]],"id":52237621}],"con":true,"img":false}]}
{"op":"mcm","clk":"11449826645","pt":1717315112362,"mc":[{"id":"1.229554918","rc":[{"atb":[[21,5.23],[26,3.14]],"id":52237624},{"atb":[[19,4.36],[23,2.38]],"id":52237621}],"con":true,"img":false}]}
{"op":"mcm","clk":"11449826654","pt":1717315112466,"mc":[{"id":"1.229554918","rc":[{"atb":[[42,0.64]],"id":52237624},{"atb":[[16.5,6.75]],"id":52237621}],"con":true,"img":false}]}
{"op":"mcm","clk":"11449826707","pt":1717315112944,"mc":[{"id":"1.229554918","rc":[{"atb":[[32,1.69]],"id":52237624}],"con":true,"img":false}]}
{"op":"mcm","clk":"11449837969","pt":1717315161548,"mc":[{"id":"1.229554918","rc":[{"atb":[[3.35,0],[2.94,0]],"id":52237628},{"atb":[[85,0.94],[44,0]],"id":52671563},{"atb":[[13.5,0],[9.4,0]],"id":52671565},{"atb":[[550,0],[650,0]],"id":52671561},{"atb":[[5.2,0],[4.2,0]],"id":52671555},{"atb":[[8.6,0],[11.5,0]],"id":52237624},{"atb":[[4.5,0],[5.5,0]],"id":52237612},{"atb":[[18,0],[13,0]],"id":52671550},{"atb":[[10,0],[15,7.48]],"id":52671552},{"atb":[[2.58,0],[2.78,0]],"id":52671546},{"atb":[[290,0.09],[390,0]],"id":52671548},{"atb":[[19.5,0],[29,0]],"id":52671542},{"atb":[[7.2,0],[9.2,0]],"id":52671544},{"atb":[[17.5,0],[25,0]],"id":52237627},{"atb":[[38,0],[24,0]],"id":52671562},{"atb":[[110,0],[55,0]],"id":52671564},{"atb":[[7.2,0],[9.2,0]],"id":52237621},{"atb":[[19.5,0],[14.5,0]],"id":52671560},{"atb":[[18,0],[13,0]],"id":52671554},{"atb":[[4.4,0],[5.4,0]],"id":52671556},{"atb":[[9.8,0],[14.5,0]],"id":52671551},{"atb":[[4.1,0],[3.55,0]],"id":52671553},{"atb":[[160,0],[80,0]],"id":52671547},{"atb":[[50,0],[30,0]],"id":52237617},{"atb":[[370,0],[470,0]],"id":52671549},{"atb":[[7.4,0],[5.7,0]],"id":52671543},{"atb":[[9,0],[12.5,0]],"id":52237634},{"atb":[[9.6,0],[7.6,0]],"id":52671545}],"con":true,"img":false}]}
{"op":"mcm","clk":"11449840541","pt":1717315188051,"mc":[{"id":"1.229554918","rc":[{"atb":[[32,0],[42,0],[21,0],[26,0]],"id":52237624},{"atb":[[2.82,0],[2.92,0],[3.3,0],[3.05,0]],"id":52671546}],"con":true,"img":false}]}
{"op":"mcm","clk":"11449840553","pt":1717315188157,"mc":[{"id":"1.229554918","rc":[{"atb":[[16.5,0],[19,0],[23,0],[28,0]],"id":52237621},{"atb":[[140,0],[190,0],[95,0],[240,0]],"id":52671547}],"con":true,"img":false}]}
{"op":"mcm","clk":"11449840612","pt":1717315188770,"mc":[{"id":"1.229554918","rc":[{"atb":[[38,0.71],[19.5,5.66],[24,3.41],[29,1.87]],"id":52237624},{"atb":[[3.1,24.91],[3.35,11.13],[2.84,56.87],[2.94,40.45]],"id":52671546}],"con":true,"img":false}]}
{"op":"mcm","clk":"11449840622","pt":1717315188873,"mc":[{"id":"1.229554918","rc":[{"atb":[[16,6.97],[18.5,4.48],[22,2.49],[27,1]],"id":52237621}],"con":true,"img":false}]}
{"op":"mcm","clk":"11449840633","pt":1717315188976,"mc":[{"id":"1.229554918","rc":[{"atb":[[130,0.61],[180,0.29],[90,1.18],[230,0.12]],"id":52671547}],"con":true,"img":false}]}
{"op":"mcm","clk":"11449843010","pt":1717315211575,"mc":[{"id":"1.229554918","rc":[{"atb":[[3.35,44.48],[2.94,125.72]],"id":52237628},{"atb":[[85,2.18],[44,5.67]],"id":52671563},{"atb":[[13.5,8.36],[9.4,29.03]],"id":52671565},{"atb":[[550,0.44],[650,0.16]],"id":52671561},{"atb":[[5.2,24.88],[4.2,76.22]],"id":52671555},{"atb":[[8.6,32.09],[11.5,9.95]],"id":52237624},{"atb":[[4.5,69.68],[5.5,23.22]],"id":52237612},{"atb":[[18,6.14],[13,20.32]],"id":52671550},{"atb":[[10,27.1],[15,14.94]],"id":52671552},{"atb":[[2.58,154.36],[2.78,58.72]],"id":52671546},{"atb":[[290,0.93],[390,0.26]],"id":52671548},{"atb":[[19.5,13.18],[29,3.73]],"id":52671542},{"atb":[[7.2,39.33],[9.2,12.74]],"id":52671544},{"atb":[[17.5,14.77],[25,4.35]],"id":52237627},{"atb":[[38,2.82],[24,10.6]],"id":52671562},{"atb":[[110,0.95],[55,4.51]],"id":52671564},{"atb":[[7.2,39.33],[9.2,12.74]],"id":52237621},{"atb":[[19.5,5.65],[14.5,18.06]],"id":52671560},{"atb":[[18,6.14],[13,20.32]],"id":52671554},{"atb":[[4.4,71.73],[5.4,23.75]],"id":52671556},{"atb":[[9.8,27.71],[14.5,7.74]],"id":52671551},{"atb":[[4.1,33.71],[3.55,95.64]],"id":52671553},{"atb":[[160,0.65],[80,3.08]],"id":52671547},{"atb":[[50,2.13],[30,8.41]],"id":52237617},{"atb":[[370,0.65],[470,0.22]],"id":52671549},{"atb":[[7.4,16.33],[5.7,51.89]],"id":52671543},{"atb":[[9,30.48],[12.5,9.08]],"id":52237634},{"atb":[[9.6,12.15],[7.6,36.95]],"id":52671545}],"con":true,"img":false}]}
{"op":"mcm","clk":"11449851287","pt":1717315296619,"mc":[{"id":"1.229554918","rc":[{"atb":[[3.35,0],[2.94,0]],"id":52237628},{"atb":[[85,0.94],[44,0]],"id":52671563},{"atb":[[13.5,0],[9.4,0]],"id":52671565},{"atb":[[550,0],[650,0]],"id":52671561},{"atb":[[5.2,0],[4.2,0]],"id":52671555},{"atb":[[8.6,0],[11.5,0]],"id":52237624},{"atb":[[4.5,0],[5.5,0]],"id":52237612},{"atb":[[18,0],[13,0]],"id":52671550},{"atb":[[10,0],[15,7.48]],"id":52671552},{"atb":[[2.58,0],[2.78,0]],"id":52671546},{"atb":[[290,0.09],[390,0]],"id":52671548},{"atb":[[19.5,0],[29,0]],"id":52671542},{"atb":[[7.2,0],[9.2,0]],"id":52671544},{"atb":[[17.5,0],[25,0]],"id":52237627},{"atb":[[38,0],[24,0]],"id":52671562},{"atb":[[110,0],[55,0]],"id":52671564},{"atb":[[7.2,0],[9.2,0]],"id":52237621},{"atb":[[19.5,0],[14.5,0]],"id":52671560},{"atb":[[18,0],[13,0]],"id":52671554},{"atb":[[4.4,0],[5.4,0]],"id":52671556},{"atb":[[9.8,0],[14.5,0]],"id":52671551},{"atb":[[4.1,0],[3.55,0]],"id":52671553},{"atb":[[160,0],[80,0]],"id":52671547},{"atb":[[50,0],[30,0]],"id":52237617},{"atb":[[370,0],[470,0]],"id":52671549},{"atb":[[7.4,0],[5.7,0]],"id":52671543},{"atb":[[9,0],[12.5,0]],"id":52237634},{"atb":[[9.6,0],[7.6,0]],"id":52671545}],"con":true,"img":false}]}
{"op":"mcm","clk":"11449855873","pt":1717315342051,"mc":[{"id":"1.229554918","rc":[{"atb":[[3.35,44.48],[2.94,125.72]],"id":52237628},{"atb":[[85,2.18],[44,5.67]],"id":52671563},{"atb":[[13.5,8.36],[9.4,29.03]],"id":52671565},{"atb":[[550,0.44],[650,0.16]],"id":52671561},{"atb":[[5.2,24.88],[4.2,76.22]],"id":52671555},{"atb":[[8.6,32.09],[11.5,9.95]],"id":52237624},{"atb":[[4.5,69.68],[5.5,23.22]],"id":52237612},{"atb":[[18,6.14],[13,20.32]],"id":52671550},{"atb":[[10,27.1],[15,14.94]],"id":52671552},{"atb":[[2.58,154.36],[2.78,58.72]],"id":52671546},{"atb":[[290,0.93],[390,0.26]],"id":52671548},{"atb":[[19.5,13.18],[29,3.73]],"id":52671542},{"atb":[[7.2,39.33],[9.2,12.74]],"id":52671544},{"atb":[[17.5,14.77],[25,4.35]],"id":52237627},{"atb":[[38,2.82],[24,10.6]],"id":52671562},{"atb":[[110,0.95],[55,4.51]],"id":52671564},{"atb":[[7.2,39.33],[9.2,12.74]],"id":52237621},{"atb":[[19.5,5.65],[14.5,18.06]],"id":52671560},{"atb":[[18,6.14],[13,20.32]],"id":52671554},{"atb":[[4.4,71.73],[5.4,23.75]],"id":52671556},{"atb":[[9.8,27.71],[14.5,7.74]],"id":52671551},{"atb":[[4.1,33.71],[3.55,95.64]],"id":52671553},{"atb":[[160,0.65],[80,3.08]],"id":52671547},{"atb":[[50,2.13],[30,8.41]],"id":52237617},{"atb":[[370,0.65],[470,0.22]],"id":52671549},{"atb":[[7.4,16.33],[5.7,51.89]],"id":52671543},{"atb":[[9,30.48],[12.5,9.08]],"id":52237634},{"atb":[[9.6,12.15],[7.6,36.95]],"id":52671545}],"con":true,"img":false}]}
{"op":"mcm","clk":"11449859795","pt":1717315381120,"mc":[{"id":"1.229554918","rc":[{"atb":[[38,0],[19.5,0],[24,0],[29,0]],"id":52237624},{"atb":[[150,0],[75,0],[200,0],[100,0]],"id":52671564},{"atb":[[16,0],[18.5,0],[22,0],[27,0]],"id":52237621},{"atb":[[130,0],[180,0],[90,0],[230,0]],"id":52671547}],"con":true,"img":false}]}
{"op":"mcm","clk":"11449859856","pt":1717315381784,"mc":[{"id":"1.229554918","rc":[{"atb":[[36,0.75],[19,5.81],[23,3.57],[28,1.94]],"id":52237624},{"atb":[[18,4.61],[21,2.62],[26,1.05],[15.5,7.21]],"id":52237621}],"con":true,"img":false}]}
{"op":"mcm","clk":"11449859865","pt":1717315381887,"mc":[{"id":"1.229554918","rc":[{"atb":[[160,0.33],[80,1.32],[210,0.13],[110,1.68]],"id":52671564},{"atb":[[140,0.57],[190,0.28],[95,1.11],[240,0.11]],"id":52671547}],"con":true,"img":false}]}
{"op":"mcm","clk":"11449860420","pt":1717315387838,"mc":[{"id":"1.229554918","rc":[{"atb":[[8,0],[9,0],[10,0],[12.5,0]],"id":52237612},{"atb":[[160,0],[80,0],[210,0],[110,0.95]],"id":52671564},{"atb":[[140,0],[190,0],[95,0],[240,0]],"id":52671547},{"atb":[[34,0],[44,0],[22,0],[27,0]],"id":52237634}],"con":true,"img":false}]}
{"op":"mcm","clk":"11449860488","pt":1717315388512,"mc":[{"id":"1.229554918","rc":[{"atb":[[11,5.23],[13.5,2.09],[8.4,14.14],[9.4,9.34]],"id":52237612},{"atb":[[150,0.35],[75,1.41],[200,0.13],[100,0.8]],"id":52671564},{"atb":[[130,0.61],[180,0.29],[90,1.18],[230,0.12]],"id":52671547},{"atb":[[36,1.5],[46,0.58],[23,4.76],[28,2.91]],"id":52237634}],"con":true,"img":false}]}
{"op":"mcm","clk":"11449861464","pt":1717315398550,"mc":[{"id":"1.229554918","rc":[{"atb":[[11,0],[13.5,0],[8.4,0],[9.4,0]],"id":52237612},{"atb":[[150,0],[75,0],[200,0],[100,0]],"id":52671564},{"atb":[[130,0],[180,0],[90,0],[230,0]],"id":52671547},{"atb":[[36,0],[46,0],[23,0],[28,0]],"id":52237634}],"con":true,"img":false}]}
{"op":"mcm","clk":"11449861534","pt":1717315399230,"mc":[{"id":"1.229554918","rc":[{"atb":[[8,14.95],[9,9.81],[10,5.81],[12.5,2.28]],"id":52237612},{"atb":[[160,0.33],[80,1.32],[210,0.13],[110,1.68]],"id":52671564},{"atb":[[140,0.57],[190,0.28],[95,1.11],[240,0.11]],"id":52671547},{"atb":[[34,1.59],[44,0.61],[22,4.98],[27,3.02]],"id":52237634}],"con":true,"img":false}]}
{"op":"mcm","clk":"11449861583","pt":1717315399741,"mc":[{"id":"1.229554918","rc":[{"atb":[[16,0],[18.5,0],[22,0],[27,0]],"id":52671565},{"atb":[[80,0],[42,0],[110,0],[55,0]],"id":52671542}],"con":true,"img":false}]}
{"op":"mcm","clk":"11449861647","pt":1717315400415,"mc":[{"id":"1.229554918","rc":[{"atb":[[16.5,6.75],[19,4.36],[23,2.38],[28,0.97]],"id":52671565},{"atb":[[44,2.43],[120,0.22],[60,1.33]],"id":52671542}],"con":true,"img":false}]}
{"op":"mcm","clk":"11449861656","pt":1717315400520,"mc":[{"id":"1.229554918","rc":[{"atb":[[85,0.62]],"id":52671542}],"con":true,"img":false}]}
{"op":"mcm","clk":"11449893681","pt":1717315712900,"mc":[{"id":"1.229554918","rc":[{"atb":[[3.35,0],[2.94,0]],"id":52237628},{"atb":[[85,0.94],[44,0]],"id":52671563},{"atb":[[13.5,0],[9.4,0]],"id":52671565},{"atb":[[550,0],[650,0]],"id":52671561},{"atb":[[5.2,0],[4.2,0]],"id":52671555},{"atb":[[8.6,0],[11.5,0]],"id":52237624},{"atb":[[4.5,0],[5.5,0]],"id":52237612},{"atb":[[18,0],[13,0]],"id":52671550},{"atb":[[10,0],[15,7.48]],"id":52671552},{"atb":[[2.58,0],[2.78,0]],"id":52671546},{"atb":[[290,0.09],[390,0]],"id":52671548},{"atb":[[19.5,0],[29,0]],"id":52671542},{"atb":[[7.2,0],[9.2,0]],"id":52671544},{"atb":[[17.5,0],[25,0]],"id":52237627},{"atb":[[38,0],[24,0]],"id":52671562},{"atb":[[110,0.72],[55,0]],"id":52671564},{"atb":[[7.2,0],[9.2,0]],"id":52237621},{"atb":[[19.5,0],[14.5,0]],"id":52671560},{"atb":[[18,0],[13,0]],"id":52671554},{"atb":[[4.4,0],[5.4,0]],"id":52671556},{"atb":[[9.8,0],[14.5,0]],"id":52671551},{"atb":[[4.1,0],[3.55,0]],"id":52671553},{"atb":[[160,0],[80,0]],"id":52671547},{"atb":[[50,0],[30,0]],"id":52237617},{"atb":[[370,0],[470,0]],"id":52671549},{"atb":[[7.4,0],[5.7,0]],"id":52671543},{"atb":[[9,0],[12.5,0]],"id":52237634},{"atb":[[9.6,0],[7.6,0]],"id":52671545}],"con":true,"img":false}]}
{"op":"mcm","clk":"11449899234","pt":1717315764715,"mc":[{"id":"1.229554918","rc":[{"atb":[[3.35,44.48],[2.94,125.72]],"id":52237628},{"atb":[[32,7.86],[55,1.93]],"id":52671563},{"atb":[[9,30.48],[12.5,9.08]],"id":52671565},{"atb":[[550,0.44],[650,0.16]],"id":52671561},{"atb":[[5.2,24.88],[4.2,76.22]],"id":52671555},{"atb":[[8.6,32.09],[11.5,9.95]],"id":52237624},{"atb":[[4.5,69.68],[5.5,23.22]],"id":52237612},{"atb":[[18,6.14],[13,20.32]],"id":52671550},{"atb":[[10,27.1],[15,14.94]],"id":52671552},{"atb":[[2.58,154.36],[2.78,58.72]],"id":52671546},{"atb":[[300,0.81],[400,0.26]],"id":52671548},{"atb":[[19.5,13.18],[29,3.73]],"id":52671542},{"atb":[[7.2,39.33],[9.2,12.74]],"id":52671544},{"atb":[[16,16.26],[22,4.97]],"id":52237627},{"atb":[[20,12.83],[30,3.6]],"id":52671562},{"atb":[[75,1.41],[40,6.25]],"id":52671564},{"atb":[[7.2,39.33],[9.2,12.74]],"id":52237621},{"atb":[[18.5,5.97],[13.5,19.51]],"id":52671560},{"atb":[[18,6.14],[13,20.32]],"id":52671554},{"atb":[[4.5,99.58],[5.5,34.85]],"id":52671556},{"atb":[[9.8,27.71],[14.5,7.74]],"id":52671551},{"atb":[[4.1,33.71],[3.55,95.64]],"id":52671553},{"atb":[[170,0.61],[85,2.9]],"id":52671547},{"atb":[[50,2.13],[30,8.41]],"id":52237617},{"atb":[[370,0.65],[470,0.22]],"id":52671549},{"atb":[[7.4,16.33],[5.7,51.89]],"id":52671543},{"atb":[[9,30.48],[12.5,9.08]],"id":52237634},{"atb":[[9.6,12.15],[7.6,36.95]],"id":52671545}],"con":true,"img":false}]}
{"op":"mcm","clk":"11449922514","pt":1717315986321,"mc":[{"id":"1.229554918","rc":[{"atb":[[170,0],[85,0],[120,0],[60,0]],"id":52671563},{"atb":[[16.5,0],[19,0],[23,0],[28,0]],"id":52671565},{"atb":[[3.1,0],[3.35,0],[2.84,0],[2.94,0]],"id":52671546},{"atb":[[160,0],[80,0],[210,0],[110,0]],"id":52671564},{"atb":[[34,0],[44,0],[27,0],[60,0]],"id":52671560}],"con":true,"img":false}]}
{"op":"mcm","clk":"11449922583","pt":1717315987020,"mc":[{"id":"1.229554918","rc":[{"atb":[[160,0.16],[80,0.99],[55,3.87],[110,0.48]],"id":52671563},{"atb":[[18,4.61],[21,2.62],[26,1.05],[15.5,7.21]],"id":52671565},{"atb":[[2.86,56.26],[3.4,10.9],[3.15,24.33],[2.96,40.04]],"id":52671546},{"atb":[[140,0.38],[70,1.52],[190,0.14],[95,0.84]],"id":52671564},{"atb":[[32,2.53],[42,1.28],[26,4.19],[55,0.49]],"id":52671560}],"con":true,"img":false}]}
{"op":"mcm","clk":"11449924833","pt":1717316010137,"mc":[{"id":"1.229554918","rc":[{"atb":[[3.35,0],[2.94,0]],"id":52237628},{"atb":[[32,0],[55,1.94]],"id":52671563},{"atb":[[9,0],[12.5,0]],"id":52671565},{"atb":[[550,0],[650,0]],"id":52671561},{"atb":[[5.2,0],[4.2,0]],"id":52671555},{"atb":[[8.6,0],[11.5,0]],"id":52237624},{"atb":[[4.5,0],[5.5,0]],"id":52237612},{"atb":[[18,0],[13,0]],"id":52671550},{"atb":[[10,0],[15,7.48]],"id":52671552},{"atb":[[2.58,0],[2.78,0]],"id":52671546},{"atb":[[300,0],[400,0]],"id":52671548},{"atb":[[19.5,0],[29,0]],"id":52671542},{"atb":[[7.2,0],[9.2,0]],"id":52671544},{"atb":[[16,0],[22,0]],"id":52237627},{"atb":[[20,0],[30,0]],"id":52671562},{"atb":[[75,0],[40,0]],"id":52671564},{"atb":[[7.2,0],[9.2,0]],"id":52237621},{"atb":[[18.5,0],[13.5,0]],"id":52671560},{"atb":[[18,0],[13,0]],"id":52671554},{"atb":[[4.5,29.89],[5.5,11.63]],"id":52671556},{"atb":[[9.8,0],[14.5,0]],"id":52671551},{"atb":[[4.1,0],[3.55,0]],"id":52671553},{"atb":[[170,0],[85,0]],"id":52671547},{"atb":[[50,0],[30,0]],"id":52237617},{"atb":[[370,0],[470,0]],"id":52671549},{"atb":[[7.4,0],[5.7,0]],"id":52671543},{"atb":[[9,0],[12.5,0]],"id":52237634},{"atb":[[9.6,0],[7.6,0]],"id":52671545}],"con":true,"img":false}]}
{"op":"mcm","clk":"11449928225","pt":1717316044601,"mc":[{"id":"1.229554918","rc":[{"atb":[[3.35,44.48],[2.94,125.72]],"id":52237628},{"atb":[[32,7.86],[55,3.87]],"id":52671563},{"atb":[[9,30.48],[12.5,9.08]],"id":52671565},{"atb":[[550,0.44],[650,0.16]],"id":52671561},{"atb":[[5.2,24.88],[4.2,76.22]],"id":52671555},{"atb":[[8.6,32.09],[11.5,9.95]],"id":52237624},{"atb":[[4.5,69.68],[5.5,23.22]],"id":52237612},{"atb":[[18,6.14],[13,20.32]],"id":52671550},{"atb":[[10,27.1],[15,14.94]],"id":52671552},{"atb":[[2.58,154.36],[2.78,58.72]],"id":52671546},{"atb":[[300,0.81],[400,0.26]],"id":52671548},{"atb":[[19.5,13.18],[29,3.73]],"id":52671542},{"atb":[[7.2,39.33],[9.2,12.74]],"id":52671544},{"atb":[[16,16.26],[22,4.97]],"id":52237627},{"atb":[[20,12.83],[30,3.6]],"id":52671562},{"atb":[[75,1.41],[40,6.25]],"id":52671564},{"atb":[[7.2,39.33],[9.2,12.74]],"id":52237621},{"atb":[[18.5,5.97],[13.5,19.51]],"id":52671560},{"atb":[[18,6.14],[13,20.32]],"id":52671554},{"atb":[[4.5,99.58],[5.5,34.85]],"id":52671556},{"atb":[[9.8,27.71],[14.5,7.74]],"id":52671551},{"atb":[[4.1,33.71],[3.55,95.64]],"id":52671553},{"atb":[[170,0.61],[85,2.9]],"id":52671547},{"atb":[[50,2.13],[30,8.41]],"id":52237617},{"atb":[[370,0.65],[470,0.22]],"id":52671549},{"atb":[[7.4,16.33],[5.7,51.89]],"id":52671543},{"atb":[[9,30.48],[12.5,9.08]],"id":52237634},{"atb":[[9.6,12.15],[7.6,36.95]],"id":52671545}],"con":true,"img":false}]}
{"op":"mcm","clk":"11449935445","pt":1717316123107,"mc":[{"id":"1.229554918","rc":[{"atb":[[8,0],[9,0],[10,0],[12.5,0]],"id":52237612}],"con":true,"img":false}]}
{"op":"mcm","clk":"11449935517","pt":1717316123770,"mc":[{"id":"1.229554918","rc":[{"atb":[[9.2,9.57],[10.5,5.51],[8.2,14.53],[13,2.18]],"id":52237612}],"con":true,"img":false}]}
{"op":"mcm","clk":"11449955010","pt":1717316342779,"mc":[{"id":"1.229554918","rc":[{"atb":[[840,0],[890,0],[940,0],[990,0]],"id":52671561},{"atb":[[11,0],[13.5,0],[8.4,0],[9.4,0]],"id":52671543}],"con":true,"img":false}]}
{"op":"mcm","clk":"11449955019","pt":1717316342876,"mc":[{"id":"1.229554918","rc":[{"atb":[[140,0],[70,0],[190,0],[95,0]],"id":52671564}],"con":true,"img":false}]}
{"op":"mcm","clk":"11449955076","pt":1717316343499,"mc":[{"id":"1.229554918","rc":[{"atb":[[760,0.14],[810,0.1],[860,0.06],[910,0.03]],"id":52671561}],"con":true,"img":false}]}
{"op":"mcm","clk":"11449958651","pt":1717316391687,"mc":[{"id":"1.229554918","rc":[{"atb":[[11,5.23],[13.5,2.09],[8.4,14.14],[9.4,9.34]],"id":52671543}],"con":true,"img":false}]}
{"op":"mcm","clk":"11449958660","pt":1717316391791,"mc":[{"id":"1.229554918","rc":[{"atb":[[760,0],[810,0],[860,0],[910,0]],"id":52671561},{"atb":[[140,0.38],[70,1.52],[190,0.14],[95,0.84]],"id":52671564}],"con":true,"img":false}]}
{"op":"mcm","clk":"11449958721","pt":1717316392473,"mc":[{"id":"1.229554918","rc":[{"atb":[[840,0.13],[890,0.09],[940,0.06],[990,0.03]],"id":52671561}],"con":true,"img":false}]}
{"op":"mcm","clk":"11449959675","pt":1717316403803,"mc":[{"id":"1.229554918","rc":[{"atb":[[840,0],[890,0],[940,0],[990,0]],"id":52671561},{"atb":[[36,0],[19,0],[23,0],[28,0]],"id":52237624},{"atb":[[16.5,0],[19,0],[11.5,0],[14,0]],"id":52671544},{"atb":[[18,0],[21,0],[26,0],[15.5,0]],"id":52237621},{"atb":[[11,0],[13.5,0],[8.4,0],[9.4,0]],"id":52671543}],"con":true,"img":false}]}
{"op":"mcm","clk":"11449959741","pt":1717316404525,"mc":[{"id":"1.229554918","rc":[{"atb":[[760,0.14],[810,0.1],[860,0.06],[910,0.03]],"id":52671561},{"atb":[[40,0.67],[20,5.51],[25,3.27],[30,1.81]],"id":52237624},{"atb":[[17.5,3.17],[20,1.38],[12.5,9.1],[15,5.6]],"id":52671544},{"atb":[[140,0],[70,0],[190,0],[95,0]],"id":52671564},{"atb":[[9.6,9.12],[8.6,13.77],[11.5,4.98],[14,2.01]],"id":52671543}],"con":true,"img":false}]}
{"op":"mcm","clk":"11449959797","pt":1717316405195,"mc":[{"id":"1.229554918","rc":[{"atb":[[140,0.38],[70,1.52],[190,0.14],[95,0.84]],"id":52671564},{"atb":[[16.5,6.75],[19,4.36],[23,2.38],[28,0.97]],"id":52237621}],"con":true,"img":false}]}
{"op":"mcm","clk":"11449959805","pt":1717316405300,"mc":[{"id":"1.229554918","rc":[{"atb":[[40,0],[20,0],[25,0],[30,0]],"id":52237624}],"con":true,"img":false}]}
{"op":"mcm","clk":"11449959854","pt":1717316405923,"mc":[{"id":"1.229554918","rc":[{"atb":[[16.5,0],[19,0],[23,0],[28,0]],"id":52237621}],"con":true,"img":false}]}
{"op":"mcm","clk":"11449959865","pt":1717316406126,"mc":[{"id":"1.229554918","rc":[{"atb":[[36,0.75],[19,5.81],[23,3.57],[28,1.94]],"id":52237624}],"con":true,"img":false}]}
{"op":"mcm","clk":"11449959911","pt":1717316406690,"mc":[{"id":"1.229554918","rc":[{"atb":[[18,4.61],[21,2.62],[26,1.05],[15.5,7.21]],"id":52237621}],"con":true,"img":false}]}
{"op":"mcm","clk":"11449962204","pt":1717316434174,"mc":[{"id":"1.229554918","rc":[{"atb":[[36,0],[19,0],[23,0],[28,0]],"id":52237624},{"atb":[[140,0],[70,0],[190,0],[95,0]],"id":52671564},{"atb":[[18,0],[21,0],[26,0],[15.5,0]],"id":52237621}],"con":true,"img":false}]}
{"op":"mcm","clk":"11449962270","pt":1717316434854,"mc":[{"id":"1.229554918","rc":[{"atb":[[40,0.67],[20,5.51],[25,3.27],[30,1.81]],"id":52237624},{"atb":[[130,0.41],[65,1.64],[180,0.15],[90,0.88]],"id":52671564}],"con":true,"img":false}]}
{"op":"mcm","clk":"11449962276","pt":1717316434955,"mc":[{"id":"1.229554918","rc":[{"atb":[[16.5,6.75],[19,4.36],[23,2.38],[28,0.97]],"id":52237621}],"con":true,"img":false}]}
{"op":"mcm","clk":"11449962334","pt":1717316435627,"mc":[{"id":"1.229554918","rc":[{"atb":[[16.5,0],[19,0],[23,0],[28,0]],"id":52237621}],"con":true,"img":false}]}
{"op":"mcm","clk":"11449962376","pt":1717316436349,"mc":[{"id":"1.229554918","rc":[{"atb":[[18,4.61],[21,2.62],[26,1.05],[15.5,7.21]],"id":52237621}],"con":true,"img":false}]}
{"op":"mcm","clk":"11449962698","pt":1717316440581,"mc":[{"id":"1.229554918","rc":[{"atb":[[40,0],[20,0],[25,0],[30,0]],"id":52237624}],"con":true,"img":false}]}
{"op":"mcm","clk":"11449962758","pt":1717316441256,"mc":[{"id":"1.229554918","rc":[{"atb":[[36,0.75],[19,5.81],[23,3.57],[28,1.94]],"id":52237624}],"con":true,"img":false}]}
{"op":"mcm","clk":"11449979412","pt":1717316677354,"mc":[{"id":"1.229554918","rc":[{"atb":[[160,0],[80,0],[110,0],[55,1.93]],"id":52671563}],"con":true,"img":false}]}
{"op":"mcm","clk":"11449979469","pt":1717316678039,"mc":[{"id":"1.229554918","rc":[{"atb":[[170,0.16],[85,0.94],[120,0.44],[60,1.77]],"id":52671563}],"con":true,"img":false}]}
{"op":"mcm","clk":"11449979526","pt":1717316678747,"mc":[{"id":"1.229554918","rc":[{"atb":[[170,0],[85,0],[120,0],[60,0]],"id":52671563}],"con":true,"img":false}]}
{"op":"mcm","clk":"11449979579","pt":1717316679529,"mc":[{"id":"1.229554918","rc":[{"atb":[[160,0.16],[80,0.99],[55,3.87],[110,0.48]],"id":52671563}],"con":true,"img":false}]}
{"op":"mcm","clk":"11449981573","pt":1717316708489,"mc":[{"id":"1.229554918","rc":[{"atb":[[160,0],[80,0],[110,0],[55,1.93]],"id":52671563}],"con":true,"img":false}]}
{"op":"mcm","clk":"11449981624","pt":1717316709166,"mc":[{"id":"1.229554918","rc":[{"atb":[[170,0.16],[85,0.94],[120,0.44],[60,1.77]],"id":52671563}],"con":true,"img":false}]}
{"op":"mcm","clk":"11449981730","pt":1717316710783,"mc":[{"id":"1.229554918","rc":[{"atb":[[170,0],[85,0],[120,0],[60,0]],"id":52671563}],"con":true,"img":false}]}
{"op":"mcm","clk":"11449981788","pt":1717316711461,"mc":[{"id":"1.229554918","rc":[{"atb":[[160,0.16],[80,0.99],[55,3.87],[110,0.48]],"id":52671563}],"con":true,"img":false}]}
{"op":"mcm","clk":"11449982814","pt":1717316726184,"mc":[{"id":"1.229554918","rc":[{"atb":[[9.2,0],[10.5,0],[8.2,0],[13,0]],"id":52237612},{"atb":[[2.86,0],[3.4,0],[3.15,0],[2.96,0]],"id":52671546},{"atb":[[85,0],[44,0],[120,0],[60,0]],"id":52671562},{"atb":[[140,0],[190,0],[95,0],[240,0]],"id":52671547},{"atb":[[34,0],[44,0],[22,0],[27,0]],"id":52237634}],"con":true,"img":false}]}
{"op":"mcm","clk":"11449982856","pt":1717316726901,"mc":[{"id":"1.229554918","rc":[{"atb":[[11,5.23],[13.5,2.09],[8.4,14.14],[9.4,9.34]],"id":52237612},{"atb":[[3.45,10.68],[3.2,23.78],[2.88,55.66],[2.98,39.64]],"id":52671546},{"atb":[[80,0.66],[42,2.55],[110,0.24],[55,1.45]],"id":52671562},{"atb":[[130,0.61],[180,0.29],[90,1.18],[230,0.12]],"id":52671547},{"atb":[[36,1.5],[46,0.58],[23,4.76],[28,2.91]],"id":52237634}],"con":true,"img":false}]}
{"op":"mcm","clk":"11449983706","pt":1717316739308,"mc":[{"id":"1.229554918","rc":[{"atb":[[3.45,0],[3.2,0],[2.88,0],[2.98,0]],"id":52671546}],"con":true,"img":false}]}
{"op":"mcm","clk":"11449983713","pt":1717316739409,"mc":[{"id":"1.229554918","rc":[{"atb":[[11,0],[13.5,0],[8.4,0],[9.4,0]],"id":52237612},{"atb":[[80,0],[42,0],[110,0],[55,0]],"id":52671562},{"atb":[[36,0],[46,0],[23,0],[28,0]],"id":52237634}],"con":true,"img":false}]}
{"op":"mcm","clk":"11449983718","pt":1717316739511,"mc":[{"id":"1.229554918","rc":[{"atb":[[130,0],[180,0],[90,0],[230,0]],"id":52671547}],"con":true,"img":false}]}
{"op":"mcm","clk":"11449983762","pt":1717316740106,"mc":[{"id":"1.229554918","rc":[{"atb":[[9.2,9.57],[10.5,5.51],[8.2,14.53],[13,2.18]],"id":52237612},{"atb":[[2.86,56.26],[3.4,10.9],[3.15,24.33],[2.96,40.04]],"id":52671546},{"atb":[[85,0.62],[44,2.43],[120,0.22],[60,1.33]],"id":52671562},{"atb":[[34,1.59],[44,0.61],[22,4.98],[27,3.02]],"id":52237634}],"con":true,"img":false}]}
{"op":"mcm","clk":"11449983768","pt":1717316740211,"mc":[{"id":"1.229554918","rc":[{"atb":[[140,0.57],[190,0.28],[95,1.11],[240,0.11]],"id":52671547}],"con":true,"img":false}]}
{"op":"mcm","clk":"11449984935","pt":1717316756848,"mc":[{"id":"1.229554918","rc":[{"atb":[[9.2,0],[10.5,0],[8.2,0],[13,0]],"id":52237612},{"atb":[[2.86,0],[3.4,0],[3.15,0],[2.96,0]],"id":52671546},{"atb":[[85,0],[44,0],[120,0],[60,0]],"id":52671562},{"atb":[[140,0],[190,0],[95,0],[240,0]],"id":52671547},{"atb":[[34,0],[44,0],[22,0],[27,0]],"id":52237634}],"con":true,"img":false}]}
{"op":"mcm","clk":"11449984993","pt":1717316757537,"mc":[{"id":"1.229554918","rc":[{"atb":[[11,5.23],[13.5,2.09],[8.4,14.14],[9.4,9.34]],"id":52237612},{"atb":[[3.45,10.68],[3.2,23.78],[2.88,55.66],[2.98,39.64]],"id":52671546},{"atb":[[80,0.66],[42,2.55],[110,0.24],[55,1.45]],"id":52671562},{"atb":[[130,0.61],[180,0.29],[90,1.18],[230,0.12]],"id":52671547},{"atb":[[36,1.5],[46,0.58],[23,4.76],[28,2.91]],"id":52237634}],"con":true,"img":false}]}
{"op":"mcm","clk":"11449985965","pt":1717316769879,"mc":[{"id":"1.229554918","rc":[{"atb":[[11,0],[13.5,0],[8.4,0],[9.4,0]],"id":52237612},{"atb":[[3.45,0],[3.2,0],[2.88,0],[2.98,0]],"id":52671546},{"atb":[[36,0],[46,0],[23,0],[28,0]],"id":52237634}],"con":true,"img":false}]}
{"op":"mcm","clk":"11449986019","pt":1717316770556,"mc":[{"id":"1.229554918","rc":[{"atb":[[9.2,9.57],[10.5,5.51],[8.2,14.53],[13,2.18]],"id":52237612},{"atb":[[2.86,56.26],[3.4,10.9],[3.15,24.33],[2.96,40.04]],"id":52671546},{"atb":[[34,1.59],[44,0.61],[22,4.98],[27,3.02]],"id":52237634}],"con":true,"img":false}]}
{"op":"mcm","clk":"11449987269","pt":1717316786887,"mc":[{"id":"1.229554918","rc":[{"atb":[[85,0],[44,0],[120,0],[60,0]],"id":52671542}],"con":true,"img":false}]}
{"op":"mcm","clk":"11449987308","pt":1717316787559,"mc":[{"id":"1.229554918","rc":[{"atb":[[80,0.66],[42,2.55],[110,0.24],[55,1.45]],"id":52671542}],"con":true,"img":false}]}
{"op":"mcm","clk":"11449988223","pt":1717316800274,"mc":[{"id":"1.229554918","rc":[{"atb":[[80,0],[42,0],[110,0],[55,0]],"id":52671542}],"con":true,"img":false}]}
{"op":"mcm","clk":"11449988284","pt":1717316801105,"mc":[{"id":"1.229554918","rc":[{"atb":[[85,0.62],[44,2.43],[120,0.22],[60,1.33]],"id":52671542}],"con":true,"img":false}]}
{"op":"mcm","clk":"11449989458","pt":1717316817414,"mc":[{"id":"1.229554918","rc":[{"atb":[[85,0],[44,0],[120,0],[60,0]],"id":52671542}],"con":true,"img":false}]}
{"op":"mcm","clk":"11449989531","pt":1717316818296,"mc":[{"id":"1.229554918","rc":[{"atb":[[80,0.66],[42,2.55],[110,0.24],[55,1.45]],"id":52671542}],"con":true,"img":false}]}
{"op":"mcm","clk":"11449990447","pt":1717316830712,"mc":[{"id":"1.229554918","rc":[{"atb":[[80,0],[42,0],[110,0],[55,0]],"id":52671542}],"con":true,"img":false}]}
{"op":"mcm","clk":"11449990504","pt":1717316831427,"mc":[{"id":"1.229554918","rc":[{"atb":[[85,0.62],[44,2.43],[120,0.22],[60,1.33]],"id":52671542}],"con":true,"img":false}]}
{"op":"mcm","clk":"11449991813","pt":1717316847818,"mc":[{"id":"1.229554918","rc":[{"atb":[[85,0],[44,0],[120,0],[60,0]],"id":52671542}],"con":true,"img":false}]}
{"op":"mcm","clk":"11449991865","pt":1717316848534,"mc":[{"id":"1.229554918","rc":[{"atb":[[80,0.66],[42,2.55],[110,0.24],[55,1.45]],"id":52671542}],"con":true,"img":false}]}
{"op":"mcm","clk":"11449993640","pt":1717316870574,"mc":[{"id":"1.229554918","rc":[{"atb":[[3.35,0],[2.94,0]],"id":52237628},{"atb":[[32,0],[55,1.94]],"id":52671563},{"atb":[[9,0],[12.5,0]],"id":52671565},{"atb":[[550,0],[650,0]],"id":52671561},{"atb":[[5.2,0],[4.2,0]],"id":52671555},{"atb":[[8.6,0],[11.5,0]],"id":52237624},{"atb":[[4.5,0],[5.5,0]],"id":52237612},{"atb":[[18,0],[13,0]],"id":52671550},{"atb":[[10,0],[15,7.48]],"id":52671552},{"atb":[[2.58,0],[2.78,0]],"id":52671546},{"atb":[[300,0],[400,0]],"id":52671548},{"atb":[[19.5,0],[29,0]],"id":52671542},{"atb":[[7.2,0],[9.2,0]],"id":52671544},{"atb":[[16,0],[22,0]],"id":52237627},{"atb":[[20,0],[30,0]],"id":52671562},{"atb":[[75,0],[40,0]],"id":52671564},{"atb":[[7.2,0],[9.2,0]],"id":52237621},{"atb":[[18.5,0],[13.5,0]],"id":52671560},{"atb":[[18,0],[13,0]],"id":52671554},{"atb":[[4.5,29.89],[5.5,11.63]],"id":52671556},{"atb":[[9.8,0],[14.5,0]],"id":52671551},{"atb":[[4.1,0],[3.55,0]],"id":52671553},{"atb":[[170,0],[85,0]],"id":52671547},{"atb":[[50,0],[30,0]],"id":52237617},{"atb":[[370,0],[470,0]],"id":52671549},{"atb":[[7.4,0],[5.7,0]],"id":52671543},{"atb":[[9,0],[12.5,0]],"id":52237634},{"atb":[[9.6,0],[7.6,0]],"id":52671545}],"con":true,"img":false}]}
{"op":"mcm","clk":"11449993685","pt":1717316871050,"mc":[{"id":"1.229554918","rc":[{"atb":[[17.5,0],[20,0],[12.5,0],[15,0]],"id":52671544},{"atb":[[9.6,0],[8.6,0],[11.5,0],[14,0]],"id":52671543}],"con":true,"img":false}]}
{"op":"mcm","clk":"11449993754","pt":1717316871773,"mc":[{"id":"1.229554918","rc":[{"atb":[[16,3.49],[18.5,1.5],[11,10.46],[13.5,6.28]],"id":52671544},{"atb":[[11,5.23],[13.5,2.09],[8.4,14.14],[9.4,9.34]],"id":52671543}],"con":true,"img":false}]}
{"op":"mcm","clk":"11449996399","pt":1717316901889,"mc":[{"id":"1.229554918","rc":[{"atb":[[550,0.44],[650,0.16]],"id":52671561},{"atb":[[4.5,69.68],[5.5,23.22]],"id":52237612},{"atb":[[18,6.14],[13,20.32]],"id":52671550},{"atb":[[2.58,154.36],[2.78,58.72]],"id":52671546},{"atb":[[300,0.81],[400,0.26]],"id":52671548},{"atb":[[19.5,13.18],[29,3.73]],"id":52671542},{"atb":[[7.2,39.33],[9.2,12.74]],"id":52671544},{"atb":[[18.5,5.97],[13.5,19.51]],"id":52671560},{"atb":[[9.8,27.71],[14.5,7.74]],"id":52671551},{"atb":[[170,0.61],[85,2.9]],"id":52671547},{"atb":[[50,2.13],[30,8.41]],"id":52237617},{"atb":[[370,0.65],[470,0.22]],"id":52671549},{"atb":[[7.4,16.33],[5.7,51.89]],"id":52671543},{"atb":[[9.6,12.15],[7.6,36.95]],"id":52671545}],"con":true,"img":false}]}
{"op":"mcm","clk":"11449996407","pt":1717316901996,"mc":[{"id":"1.229554918","rc":[{"atb":[[3.35,44.48],[2.94,125.72]],"id":52237628},{"atb":[[32,7.86],[55,3.87]],"id":52671563},{"atb":[[9,30.48],[12.5,9.08]],"id":52671565},{"atb":[[5.2,24.88],[4.2,76.22]],"id":52671555},{"atb":[[8.6,32.09],[11.5,9.95]],"id":52237624},{"atb":[[10,27.1],[15,14.94]],"id":52671552},{"atb":[[16,16.26],[22,4.97]],"id":52237627},{"atb":[[20,12.83],[30,3.6]],"id":52671562},{"atb":[[75,1.41],[40,6.25]],"id":52671564},{"atb":[[7.2,39.33],[9.2,12.74]],"id":52237621},{"atb":[[18,6.14],[13,20.32]],"id":52671554},{"atb":[[4.5,99.58],[5.5,34.85]],"id":52671556},{"atb":[[4.1,33.71],[3.55,95.64]],"id":52671553},{"atb":[[9,30.48],[12.5,9.08]],"id":52237634}],"con":true,"img":false}]}
{"op":"mcm","clk":"11450004007","pt":1717316992820,"mc":[{"id":"1.229554918","rc":[{"atb":[[3.35,0],[2.94,0]],"id":52237628},{"atb":[[32,0],[55,1.94]],"id":52671563},{"atb":[[9,0],[12.5,0]],"id":52671565},{"atb":[[550,0],[650,0]],"id":52671561},{"atb":[[5.2,0],[4.2,0]],"id":52671555},{"atb":[[8.6,0],[11.5,0]],"id":52237624},{"atb":[[4.5,0],[5.5,0]],"id":52237612},{"atb":[[18,0],[13,0]],"id":52671550},{"atb":[[10,0],[15,7.48]],"id":52671552},{"atb":[[2.58,0],[2.78,0]],"id":52671546},{"atb":[[300,0],[400,0]],"id":52671548},{"atb":[[19.5,0],[29,0]],"id":52671542},{"atb":[[7.2,0],[9.2,0]],"id":52671544},{"atb":[[16,0],[22,0]],"id":52237627},{"atb":[[20,0],[30,0]],"id":52671562},{"atb":[[75,0],[40,0]],"id":52671564},{"atb":[[7.2,0],[9.2,0]],"id":52237621},{"atb":[[18.5,0],[13.5,0]],"id":52671560},{"atb":[[18,0],[13,0]],"id":52671554},{"atb":[[4.5,29.89],[5.5,11.63]],"id":52671556},{"atb":[[9.8,0],[14.5,0]],"id":52671551},{"atb":[[4.1,0],[3.55,0]],"id":52671553},{"atb":[[170,0],[85,0]],"id":52671547},{"atb":[[50,0],[30,0]],"id":52237617},{"atb":[[370,0],[470,0]],"id":52671549},{"atb":[[7.4,0],[5.7,0]],"id":52671543},{"atb":[[9,0],[12.5,0]],"id":52237634},{"atb":[[9.6,0],[7.6,0]],"id":52671545}],"con":true,"img":false}]}
{"op":"mcm","clk":"11450008758","pt":1717317042409,"mc":[{"id":"1.229554918","rc":[{"atb":[[3.35,44.48],[2.94,125.72]],"id":52237628},{"atb":[[32,7.86],[55,3.87]],"id":52671563},{"atb":[[9,30.48],[12.5,9.08]],"id":52671565},{"atb":[[550,0.44],[650,0.16]],"id":52671561},{"atb":[[5.2,24.88],[4.2,76.22]],"id":52671555},{"atb":[[8.6,32.09],[11.5,9.95]],"id":52237624},{"atb":[[4.5,69.68],[5.5,23.22]],"id":52237612},{"atb":[[18,6.14],[13,20.32]],"id":52671550},{"atb":[[10,27.1],[15,14.94]],"id":52671552},{"atb":[[2.58,154.36],[2.78,58.72]],"id":52671546},{"atb":[[300,0.81],[400,0.26]],"id":52671548},{"atb":[[19.5,13.18],[29,3.73]],"id":52671542},{"atb":[[7.2,39.33],[9.2,12.74]],"id":52671544},{"atb":[[16,16.26],[22,4.97]],"id":52237627},{"atb":[[20,12.83],[30,3.6]],"id":52671562},{"atb":[[75,1.41],[40,6.25]],"id":52671564},{"atb":[[7.2,39.33],[9.2,12.74]],"id":52237621},{"atb":[[18.5,5.97],[13.5,19.51]],"id":52671560},{"atb":[[18,6.14],[13,20.32]],"id":52671554},{"atb":[[4.5,99.58],[5.5,34.85]],"id":52671556},{"atb":[[9.8,27.71],[14.5,7.74]],"id":52671551},{"atb":[[4.1,33.71],[3.55,95.64]],"id":52671553},{"atb":[[170,0.61],[85,2.9]],"id":52671547},{"atb":[[50,2.13],[30,8.41]],"id":52237617},{"atb":[[370,0.65],[470,0.22]],"id":52671549},{"atb":[[7.4,16.33],[5.7,51.89]],"id":52671543},{"atb":[[9,30.48],[12.5,9.08]],"id":52237634},{"atb":[[9.6,12.15],[7.6,36.95]],"id":52671545}],"con":true,"img":false}]}
{"op":"mcm","clk":"11450010184","pt":1717317056411,"mc":[{"id":"1.229554918","rc":[{"atb":[[18,0],[21,0],[26,0],[15.5,0]],"id":52237621}],"con":true,"img":false}]}
{"op":"mcm","clk":"11450010245","pt":1717317057085,"mc":[{"id":"1.229554918","rc":[{"atb":[[16,6.97],[18.5,4.48],[22,2.49],[27,1]],"id":52237621}],"con":true,"img":false}]}
{"op":"mcm","clk":"11450010604","pt":1717317060828,"mc":[{"id":"1.229554918","rc":[{"atb":[[36,0],[19,0],[23,0],[28,0]],"id":52237624}],"con":true,"img":false}]}
{"op":"mcm","clk":"11450010679","pt":1717317061510,"mc":[{"id":"1.229554918","rc":[{"atb":[[38,0.71],[19.5,5.66],[24,3.41],[29,1.87]],"id":52237624}],"con":true,"img":false}]}
{"op":"mcm","clk":"11450023621","pt":1717317193432,"mc":[{"id":"1.229554918","rc":[{"atb":[[38,0],[19.5,0],[24,0],[29,0]],"id":52237624},{"atb":[[16,0],[18.5,0],[11,0],[13.5,0]],"id":52671544},{"atb":[[130,0],[65,0],[180,0],[90,0]],"id":52671564},{"atb":[[16,0],[18.5,0],[22,0],[27,0]],"id":52237621}],"con":true,"img":false}]}
{"op":"mcm","clk":"11450023693","pt":1717317194111,"mc":[{"id":"1.229554918","rc":[{"atb":[[36,0.75],[19,5.81],[23,3.57],[28,1.94]],"id":52237624},{"atb":[[16.5,3.37],[19,1.45],[11.5,9.97],[14,6.04]],"id":52671544},{"atb":[[140,0.38],[70,1.52],[190,0.14],[95,0.84]],"id":52671564},{"atb":[[18,4.61],[21,2.62],[26,1.05],[15.5,7.21]],"id":52237621}],"con":true,"img":false}]}
{"op":"mcm","clk":"11450024205","pt":1717317199221,"mc":[{"id":"1.229554918","rc":[{"atb":[[36,0],[19,0],[23,0],[28,0]],"id":52237624},{"atb":[[140,0],[70,0],[190,0],[95,0]],"id":52671564},{"atb":[[18,0],[21,0],[26,0],[15.5,0]],"id":52237621}],"con":true,"img":false}]}
{"op":"mcm","clk":"11450024268","pt":1717317199894,"mc":[{"id":"1.229554918","rc":[{"atb":[[38,0.71],[19.5,5.66],[24,3.41],[29,1.87]],"id":52237624},{"atb":[[130,0.41],[65,1.64],[180,0.15],[90,0.88]],"id":52671564},{"atb":[[16,6.97],[18.5,4.48],[22,2.49],[27,1]],"id":52237621}],"con":true,"img":false}]}
{"op":"mcm","clk":"11450024331","pt":1717317200718,"mc":[{"id":"1.229554918","rc":[{"atb":[[38,0],[19.5,0],[24,0],[29,0]],"id":52237624},{"atb":[[130,0],[65,0],[180,0],[90,0]],"id":52671564},{"atb":[[16,0],[18.5,0],[22,0],[27,0]],"id":52237621}],"con":true,"img":false}]}
{"op":"mcm","clk":"11450024389","pt":1717317201394,"mc":[{"id":"1.229554918","rc":[{"atb":[[36,0.75],[19,5.81],[23,3.57],[28,1.94]],"id":52237624},{"atb":[[140,0.38],[70,1.52],[190,0.14],[95,0.84]],"id":52671564},{"atb":[[18,4.61],[21,2.62],[26,1.05],[15.5,7.21]],"id":52237621}],"con":true,"img":false}]}
{"op":"mcm","clk":"11450024667","pt":1717317203930,"mc":[{"id":"1.229554918","rc":[{"atb":[[36,0],[19,0],[23,0],[28,0]],"id":52237624},{"atb":[[140,0],[70,0],[190,0],[95,0]],"id":52671564},{"atb":[[18,0],[21,0],[26,0],[15.5,0]],"id":52237621}],"con":true,"img":false}]}
{"op":"mcm","clk":"11450024744","pt":1717317204609,"mc":[{"id":"1.229554918","rc":[{"atb":[[38,0.71],[19.5,5.66],[24,3.41],[29,1.87]],"id":52237624},{"atb":[[130,0.41],[65,1.64],[180,0.15],[90,0.88]],"id":52671564},{"atb":[[16,6.97],[18.5,4.48],[22,2.49],[27,1]],"id":52237621}],"con":true,"img":false}]}
{"op":"mcm","clk":"11450025325","pt":1717317210321,"mc":[{"id":"1.229554918","rc":[{"atb":[[38,0],[19.5,0],[24,0],[29,0]],"id":52237624},{"atb":[[16,0],[18.5,0],[27,0]],"id":52237621}],"con":true,"img":false}]}
{"op":"mcm","clk":"11450025337","pt":1717317210419,"mc":[{"id":"1.229554918","rc":[{"atb":[[22,0]],"id":52237621}],"con":true,"img":false}]}
{"op":"mcm","clk":"11450025406","pt":1717317211041,"mc":[{"id":"1.229554918","rc":[{"atb":[[36,0.75],[19,5.81],[23,3.57],[28,1.94]],"id":52237624},{"atb":[[18,4.61],[26,1.05],[15.5,7.21]],"id":52237621}],"con":true,"img":false}]}
{"op":"mcm","clk":"11450025418","pt":1717317211101,"mc":[{"id":"1.229554918","rc":[{"atb":[[21,2.62]],"id":52237621}],"con":true,"img":false}]}
{"op":"mcm","clk":"11450039569","pt":1717317345466,"mc":[{"id":"1.229554918","rc":[{"atb":[[80,0],[42,0],[55,0]],"id":52671562},{"atb":[[130,0],[180,0],[90,0],[230,0]],"id":52671547}],"con":true,"img":false}]}
{"op":"mcm","clk":"11450039583","pt":1717317345569,"mc":[{"id":"1.229554918","rc":[{"atb":[[110,0]],"id":52671562}],"con":true,"img":false}]}
{"op":"mcm","clk":"11450039656","pt":1717317346247,"mc":[{"id":"1.229554918","rc":[{"atb":[[95,1.11]],"id":52671547}],"con":true,"img":false}]}
{"op":"mcm","clk":"11450039665","pt":1717317346348,"mc":[{"id":"1.229554918","rc":[{"atb":[[85,0.62],[44,2.43],[60,1.33]],"id":52671562},{"atb":[[140,0.57],[190,0.28],[240,0.11]],"id":52671547}],"con":true,"img":false}]}
{"op":"mcm","clk":"11450039687","pt":1717317346559,"mc":[{"id":"1.229554918","rc":[{"atb":[[120,0.22]],"id":52671562}],"con":true,"img":false}]}
{"op":"mcm","clk":"11450048196","pt":1717317427374,"mc":[{"id":"1.229554918","rc":[{"atb":[[80,0],[42,0],[110,0],[55,0]],"id":52671542}],"con":true,"img":false}]}
{"op":"mcm","clk":"11450048270","pt":1717317428028,"mc":[{"id":"1.229554918","rc":[{"atb":[[85,0.62],[44,2.43],[120,0.22],[60,1.33]],"id":52671542}],"con":true,"img":false}]}
{"op":"mcm","clk":"11450072862","pt":1717317695044,"mc":[{"id":"1.229554918","rc":[{"atb":[[140,0],[190,0],[95,0],[240,0]],"id":52671547}],"con":true,"img":false}]}
{"op":"mcm","clk":"11450072872","pt":1717317695150,"mc":[{"id":"1.229554918","rc":[{"atb":[[85,0],[44,0],[120,0],[60,0]],"id":52671562}],"con":true,"img":false}]}
{"op":"mcm","clk":"11450072929","pt":1717317695728,"mc":[{"id":"1.229554918","rc":[{"atb":[[130,0.61],[180,0.29],[90,1.18],[230,0.12]],"id":52671547}],"con":true,"img":false}]}
{"op":"mcm","clk":"11450072942","pt":1717317695840,"mc":[{"id":"1.229554918","rc":[{"atb":[[80,0.66],[42,2.55],[110,0.24],[55,1.45]],"id":52671562}],"con":true,"img":false}]}
{"op":"mcm","clk":"11450076107","pt":1717317730855,"mc":[{"id":"1.229554918","rc":[{"atb":[[3.35,0],[2.94,0]],"id":52237628},{"atb":[[32,0],[55,1.94]],"id":52671563},{"atb":[[9,0],[12.5,0]],"id":52671565},{"atb":[[550,0],[650,0]],"id":52671561},{"atb":[[5.2,0],[4.2,0]],"id":52671555},{"atb":[[8.6,0],[11.5,0]],"id":52237624},{"atb":[[4.5,0],[5.5,0]],"id":52237612},{"atb":[[18,0],[13,0]],"id":52671550},{"atb":[[10,0],[15,7.48]],"id":52671552},{"atb":[[2.58,0],[2.78,0]],"id":52671546},{"atb":[[300,0],[400,0]],"id":52671548},{"atb":[[19.5,0],[29,0]],"id":52671542},{"atb":[[7.2,0],[9.2,0]],"id":52671544},{"atb":[[16,0],[22,0]],"id":52237627},{"atb":[[20,0],[30,0]],"id":52671562},{"atb":[[75,0],[40,0]],"id":52671564},{"atb":[[7.2,0],[9.2,0]],"id":52237621},{"atb":[[18.5,0],[13.5,0]],"id":52671560},{"atb":[[18,0],[13,0]],"id":52671554},{"atb":[[4.5,29.89],[5.5,11.63]],"id":52671556},{"atb":[[9.8,0],[14.5,0]],"id":52671551},{"atb":[[4.1,0],[3.55,0]],"id":52671553},{"atb":[[170,0],[85,0]],"id":52671547},{"atb":[[50,0],[30,0]],"id":52237617},{"atb":[[370,0],[470,0]],"id":52671549},{"atb":[[7.4,0],[5.7,0]],"id":52671543},{"atb":[[9,0],[12.5,0]],"id":52237634},{"atb":[[9.6,0],[7.6,0]],"id":52671545}],"con":true,"img":false}]}
{"op":"mcm","clk":"11450077676","pt":1717317747813,"mc":[{"id":"1.229554918","rc":[{"atb":[[130,0],[65,0],[180,0],[90,0]],"id":52671564}],"con":true,"img":false}]}
{"op":"mcm","clk":"11450077735","pt":1717317748532,"mc":[{"id":"1.229554918","rc":[{"atb":[[140,0.38],[70,1.52],[190,0.14],[95,0.84]],"id":52671564}],"con":true,"img":false}]}
{"op":"mcm","clk":"11450079213","pt":1717317764868,"mc":[{"id":"1.229554918","rc":[{"atb":[[3.35,44.48],[2.94,125.72]],"id":52237628},{"atb":[[32,7.86],[55,3.87]],"id":52671563},{"atb":[[9,30.48],[12.5,9.08]],"id":52671565},{"atb":[[550,0.44],[650,0.16]],"id":52671561},{"atb":[[5.2,24.88],[4.2,76.22]],"id":52671555},{"atb":[[8.6,32.09],[11.5,9.95]],"id":52237624},{"atb":[[4.5,69.68],[5.5,23.22]],"id":52237612},{"atb":[[18,6.14],[13,20.32]],"id":52671550},{"atb":[[10,27.1],[15,14.94]],"id":52671552},{"atb":[[2.58,154.36],[2.78,58.72]],"id":52671546},{"atb":[[300,0.81],[400,0.26]],"id":52671548},{"atb":[[19.5,13.18],[29,3.73]],"id":52671542},{"atb":[[7.2,39.33],[9.2,12.74]],"id":52671544},{"atb":[[16,16.26],[22,4.97]],"id":52237627},{"atb":[[20,12.83],[30,3.6]],"id":52671562},{"atb":[[75,1.41],[40,6.25]],"id":52671564},{"atb":[[7.2,39.33],[9.2,12.74]],"id":52237621},{"atb":[[18.5,5.97],[13.5,19.51]],"id":52671560},{"atb":[[18,6.14],[13,20.32]],"id":52671554},{"atb":[[4.5,99.58],[5.5,34.85]],"id":52671556},{"atb":[[9.8,27.71],[14.5,7.74]],"id":52671551},{"atb":[[4.1,33.71],[3.55,95.64]],"id":52671553},{"atb":[[170,0.61],[85,2.9]],"id":52671547},{"atb":[[50,2.13],[30,8.41]],"id":52237617},{"atb":[[370,0.65],[470,0.22]],"id":52671549},{"atb":[[7.4,16.33],[5.7,51.89]],"id":52671543},{"atb":[[9,30.48],[12.5,9.08]],"id":52237634},{"atb":[[9.6,12.15],[7.6,36.95]],"id":52671545}],"con":true,"img":false}]}
{"op":"mcm","clk":"11450081602","pt":1717317792069,"mc":[{"id":"1.229554918","rc":[{"atb":[[160,0],[80,0],[110,0],[55,1.93]],"id":52671563},{"atb":[[16.5,0],[19,0],[11.5,0],[14,0]],"id":52671544},{"atb":[[11,0],[13.5,0],[8.4,0],[9.4,0]],"id":52671543}],"con":true,"img":false}]}
{"op":"mcm","clk":"11450081616","pt":1717317792174,"mc":[{"id":"1.229554918","rc":[{"atb":[[36,0],[19,0],[23,0],[28,0]],"id":52237624},{"atb":[[140,0],[70,0],[190,0],[95,0]],"id":52671564},{"atb":[[18,0],[21,0],[26,0],[15.5,0]],"id":52237621}],"con":true,"img":false}]}
{"op":"mcm","clk":"11450081699","pt":1717317792952,"mc":[{"id":"1.229554918","rc":[{"atb":[[170,0.16],[85,0.94],[120,0.44],[60,1.77]],"id":52671563},{"atb":[[40,0.67],[20,5.51],[25,3.27],[30,1.81]],"id":52237624},{"atb":[[17.5,3.17],[20,1.38],[12.5,9.1],[15,5.6]],"id":52671544},{"atb":[[130,0.41],[65,1.64],[180,0.15],[90,0.88]],"id":52671564},{"atb":[[16.5,6.75],[19,4.36],[23,2.38],[28,0.97]],"id":52237621},{"atb":[[9.6,9.12],[8.6,13.77],[11.5,4.98],[14,2.01]],"id":52671543}],"con":true,"img":false}]}
{"op":"mcm","clk":"11450082570","pt":1717317803891,"mc":[{"id":"1.229554918","rc":[{"atb":[[170,0],[85,0],[120,0],[60,0]],"id":52671563},{"atb":[[40,0],[20,0],[25,0],[30,0]],"id":52237624},{"atb":[[16.5,0],[19,0],[23,0],[28,0]],"id":52237621}],"con":true,"img":false}]}
{"op":"mcm","clk":"11450082681","pt":1717317804975,"mc":[{"id":"1.229554918","rc":[{"atb":[[160,0.16],[80,0.99],[55,3.87],[110,0.48]],"id":52671563},{"atb":[[36,0.75],[19,5.81],[23,3.57],[28,1.94]],"id":52237624},{"atb":[[18,4.61],[21,2.62],[26,1.05],[15.5,7.21]],"id":52237621}],"con":true,"img":false}]}
{"op":"mcm","clk":"11450088161","pt":1717317870193,"mc":[{"id":"1.229554918","rc":[{"atb":[[3.35,0],[2.94,0]],"id":52237628},{"atb":[[32,0],[55,1.94]],"id":52671563},{"atb":[[9,0],[12.5,0]],"id":52671565},{"atb":[[550,0],[650,0]],"id":52671561},{"atb":[[5.2,0],[4.2,0]],"id":52671555},{"atb":[[8.6,0],[11.5,0]],"id":52237624},{"atb":[[4.5,0],[5.5,0]],"id":52237612},{"atb":[[18,0],[13,0]],"id":52671550},{"atb":[[10,0],[15,7.48]],"id":52671552},{"atb":[[2.58,0],[2.78,0]],"id":52671546},{"atb":[[300,0],[400,0]],"id":52671548},{"atb":[[19.5,0],[29,0]],"id":52671542},{"atb":[[7.2,0],[9.2,0]],"id":52671544},{"atb":[[16,0],[22,0]],"id":52237627},{"atb":[[20,0],[30,0]],"id":52671562},{"atb":[[75,0],[40,0]],"id":52671564},{"atb":[[7.2,0],[9.2,0]],"id":52237621},{"atb":[[18.5,0],[13.5,0]],"id":52671560},{"atb":[[18,0],[13,0]],"id":52671554},{"atb":[[4.5,29.89],[5.5,11.63]],"id":52671556},{"atb":[[9.8,0],[14.5,0]],"id":52671551},{"atb":[[4.1,0],[3.55,0]],"id":52671553},{"atb":[[170,0],[85,0]],"id":52671547},{"atb":[[50,0],[30,0]],"id":52237617},{"atb":[[370,0],[470,0]],"id":52671549},{"atb":[[7.4,0],[5.7,0]],"id":52671543},{"atb":[[9,0],[12.5,0]],"id":52237634},{"atb":[[9.6,0],[7.6,0]],"id":52671545}],"con":true,"img":false}]}
{"op":"mcm","clk":"11450090777","pt":1717317899499,"mc":[{"id":"1.229554918","rc":[{"atb":[[3.35,44.48],[2.94,125.72]],"id":52237628},{"atb":[[32,7.86],[55,3.87]],"id":52671563},{"atb":[[9,30.48],[12.5,9.08]],"id":52671565},{"atb":[[550,0.44],[650,0.16]],"id":52671561},{"atb":[[5.2,24.88],[4.2,76.22]],"id":52671555},{"atb":[[8.6,32.09],[11.5,9.95]],"id":52237624},{"atb":[[4.5,69.68],[5.5,23.22]],"id":52237612},{"atb":[[18,6.14],[13,20.32]],"id":52671550},{"atb":[[10,27.1],[15,14.94]],"id":52671552},{"atb":[[2.58,154.36],[2.78,58.72]],"id":52671546},{"atb":[[300,0.81],[400,0.26]],"id":52671548},{"atb":[[19.5,13.18],[29,3.73]],"id":52671542},{"atb":[[7.2,39.33],[9.2,12.74]],"id":52671544},{"atb":[[16,16.26],[22,4.97]],"id":52237627},{"atb":[[20,12.83],[30,3.6]],"id":52671562},{"atb":[[75,1.41],[40,6.25]],"id":52671564},{"atb":[[7.2,39.33],[9.2,12.74]],"id":52237621},{"atb":[[18.5,5.97],[13.5,19.51]],"id":52671560},{"atb":[[18,6.14],[13,20.32]],"id":52671554},{"atb":[[4.5,99.58],[5.5,34.85]],"id":52671556},{"atb":[[9.8,27.71],[14.5,7.74]],"id":52671551},{"atb":[[4.1,33.71],[3.55,95.64]],"id":52671553},{"atb":[[170,0.61],[85,2.9]],"id":52671547},{"atb":[[50,2.13],[30,8.41]],"id":52237617},{"atb":[[370,0.65],[470,0.22]],"id":52671549},{"atb":[[7.4,16.33],[5.7,51.89]],"id":52671543},{"atb":[[9,30.48],[12.5,9.08]],"id":52237634},{"atb":[[9.6,12.15],[7.6,36.95]],"id":52671545}],"con":true,"img":false}]}
{"op":"mcm","clk":"11450105859","pt":1717318070635,"mc":[{"id":"1.229554918","rc":[{"atb":[[4.8,0],[5.8,0],[5.3,0],[6.6,0]],"id":52671555},{"atb":[[38,0],[48,0],[24,0],[29,0]],"id":52671554},{"atb":[[4.5,69.68],[5,0],[5.5,23.22],[6,0]],"id":52671556},{"atb":[[36,0],[19,0],[23,0],[28,0]],"id":52671551},{"atb":[[4.8,0],[4.3,0],[3.9,0],[3.65,0]],"id":52671553}],"con":true,"img":false}]}
{"op":"mcm","clk":"11450105924","pt":1717318071313,"mc":[{"id":"1.229554918","rc":[{"atb":[[6.8,4.51],[4.9,26.83],[5.9,10.68],[5.4,17.84]],"id":52671555},{"atb":[[40,1.34],[50,0.53],[25,4.36],[30,2.71]],"id":52671554},{"atb":[[5.6,11.37],[5.1,19.14],[4.6,29.07],[6.2,5.03]],"id":52671556},{"atb":[[32,0.84],[18,6.15],[21,3.92],[26,2.09]],"id":52671551},{"atb":[[3.45,42.71],[3.95,17.74],[3.7,29.07],[4.4,7.7]],"id":52671553}],"con":true,"img":false}]}
{"op":"mcm","clk":"11450116550","pt":1717318189859,"mc":[{"id":"1.229554918","rc":[{"atb":[[130,0],[180,0],[90,0],[230,0]],"id":52671547}],"con":true,"img":false}]}
{"op":"mcm","clk":"11450116558","pt":1717318189959,"mc":[{"id":"1.229554918","rc":[{"atb":[[80,0],[42,0],[110,0],[55,0]],"id":52671562}],"con":true,"img":false}]}
{"op":"mcm","clk":"11450116610","pt":1717318190576,"mc":[{"id":"1.229554918","rc":[{"atb":[[140,0.57],[190,0.28],[95,1.11],[240,0.11]],"id":52671547}],"con":true,"img":false}]}
{"op":"mcm","clk":"11450116616","pt":1717318190628,"mc":[{"id":"1.229554918","rc":[{"atb":[[85,0.62],[44,2.43],[120,0.22],[60,1.33]],"id":52671562}],"con":true,"img":false}]}
{"op":"mcm","clk":"11450125092","pt":1717318288166,"mc":[{"id":"1.229554918","rc":[{"atb":[[80,0],[55,1.93]],"id":52671563},{"atb":[[36,0],[28,0]],"id":52237624},{"atb":[[15.5,0]],"id":52237621}],"con":true,"img":false}]}
{"op":"mcm","clk":"11450125104","pt":1717318288273,"mc":[{"id":"1.229554918","rc":[{"atb":[[160,0],[110,0]],"id":52671563},{"atb":[[19,0],[23,0]],"id":52237624},{"atb":[[18,0],[21,0],[26,0]],"id":52237621}],"con":true,"img":false}]}
{"op":"mcm","clk":"11450125165","pt":1717318288842,"mc":[{"id":"1.229554918","rc":[{"atb":[[85,0.94],[60,1.77]],"id":52671563},{"atb":[[40,0.67],[30,1.81]],"id":52237624},{"atb":[[16.5,6.75]],"id":52237621}],"con":true,"img":false}]}
{"op":"mcm","clk":"11450125173","pt":1717318288947,"mc":[{"id":"1.229554918","rc":[{"atb":[[170,0.16],[120,0.44]],"id":52671563},{"atb":[[20,5.51],[25,3.27]],"id":52237624},{"atb":[[19,4.36],[23,2.38],[28,0.97]],"id":52237621}],"con":true,"img":false}]}
{"op":"mcm","clk":"11450125240","pt":1717318289878,"mc":[{"id":"1.229554918","rc":[{"atb":[[20,0],[25,0]],"id":52237624}],"con":true,"img":false}]}
{"op":"mcm","clk":"11450125251","pt":1717318289980,"mc":[{"id":"1.229554918","rc":[{"atb":[[170,0],[120,0]],"id":52671563},{"atb":[[19,0],[23,0],[28,0]],"id":52237621}],"con":true,"img":false}]}
{"op":"mcm","clk":"11450125298","pt":1717318290555,"mc":[{"id":"1.229554918","rc":[{"atb":[[19,5.81],[23,3.57]],"id":52237624}],"con":true,"img":false}]}
{"op":"mcm","clk":"11450125310","pt":1717318290655,"mc":[{"id":"1.229554918","rc":[{"atb":[[160,0.16],[110,0.48]],"id":52671563},{"atb":[[18,4.61],[21,2.62],[26,1.05]],"id":52237621}],"con":true,"img":false}]}
{"op":"mcm","clk":"11450125624","pt":1717318294579,"mc":[{"id":"1.229554918","rc":[{"atb":[[85,0],[60,0]],"id":52671563},{"atb":[[40,0],[30,0]],"id":52237624},{"atb":[[16.5,0]],"id":52237621}],"con":true,"img":false}]}
{"op":"mcm","clk":"11450125716","pt":1717318295665,"mc":[{"id":"1.229554918","rc":[{"atb":[[80,0.99],[55,3.87]],"id":52671563},{"atb":[[36,0.75],[28,1.94]],"id":52237624},{"atb":[[15.5,7.21]],"id":52237621}],"con":true,"img":false}]}
{"op":"mcm","clk":"11450126962","pt":1717318309950,"mc":[{"id":"1.229554918","rc":[{"atb":[[160,0],[110,0]],"id":52671563},{"atb":[[19,0],[23,0]],"id":52237624},{"atb":[[18,0],[21,0],[26,0]],"id":52237621}],"con":true,"img":false}]}
{"op":"mcm","clk":"11450127012","pt":1717318310632,"mc":[{"id":"1.229554918","rc":[{"atb":[[170,0.16],[120,0.44]],"id":52671563},{"atb":[[20,5.51],[25,3.27]],"id":52237624},{"atb":[[19,4.36],[23,2.38],[28,0.97]],"id":52237621}],"con":true,"img":false}]}
{"op":"mcm","clk":"11450127791","pt":1717318320249,"mc":[{"id":"1.229554918","rc":[{"atb":[[170,0],[120,0]],"id":52671563}],"con":true,"img":false}]}
{"op":"mcm","clk":"11450127800","pt":1717318320353,"mc":[{"id":"1.229554918","rc":[{"atb":[[19,0],[23,0],[28,0]],"id":52237621}],"con":true,"img":false}]}
{"op":"mcm","clk":"11450127864","pt":1717318321031,"mc":[{"id":"1.229554918","rc":[{"atb":[[160,0.16],[110,0.48]],"id":52671563},{"atb":[[18,4.61],[21,2.62],[26,1.05]],"id":52237621}],"con":true,"img":false}]}
{"op":"mcm","clk":"11450127908","pt":1717318321451,"mc":[{"id":"1.229554918","rc":[{"atb":[[20,0],[25,0]],"id":52237624}],"con":true,"img":false}]}
{"op":"mcm","clk":"11450127970","pt":1717318322187,"mc":[{"id":"1.229554918","rc":[{"atb":[[19,5.81],[23,3.57]],"id":52237624}],"con":true,"img":false}]}
{"op":"mcm","clk":"11450129653","pt":1717318340254,"mc":[{"id":"1.229554918","rc":[{"atb":[[160,0],[110,0]],"id":52671563},{"atb":[[18,0],[21,0],[26,0]],"id":52237621}],"con":true,"img":false}]}
{"op":"mcm","clk":"11450129707","pt":1717318340981,"mc":[{"id":"1.229554918","rc":[{"atb":[[170,0.16],[120,0.44]],"id":52671563},{"atb":[[19,4.36],[23,2.38],[28,0.97]],"id":52237621}],"con":true,"img":false}]}
{"op":"mcm","clk":"11450130478","pt":1717318350691,"mc":[{"id":"1.229554918","rc":[{"atb":[[170,0],[120,0]],"id":52671563},{"atb":[[19,0],[23,0],[28,0]],"id":52237621}],"con":true,"img":false}]}
{"op":"mcm","clk":"11450130528","pt":1717318351405,"mc":[{"id":"1.229554918","rc":[{"atb":[[160,0.16],[110,0.48]],"id":52671563}],"con":true,"img":false}]}
{"op":"mcm","clk":"11450130543","pt":1717318351486,"mc":[{"id":"1.229554918","rc":[{"atb":[[18,4.61],[21,2.62],[26,1.05]],"id":52237621}],"con":true,"img":false}]}
{"op":"mcm","clk":"11450139036","pt":1717318450466,"mc":[{"id":"1.229554918","rc":[{"atb":[[32,0],[18,0],[21,0],[26,0]],"id":52671551}],"con":true,"img":false}]}
{"op":"mcm","clk":"11450139091","pt":1717318451187,"mc":[{"id":"1.229554918","rc":[{"atb":[[34,0.8],[18.5,5.98],[22,3.74],[27,2.01]],"id":52671551}],"con":true,"img":false}]}
{"op":"mcm","clk":"11450139657","pt":1717318456985,"mc":[{"id":"1.229554918","rc":[{"atb":[[34,0],[18.5,0],[22,0],[27,0]],"id":52671551}],"con":true,"img":false}]}
{"op":"mcm","clk":"11450139717","pt":1717318457705,"mc":[{"id":"1.229554918","rc":[{"atb":[[32,0.84],[18,6.15],[21,3.92],[26,2.09]],"id":52671551}],"con":true,"img":false}]}
{"op":"mcm","clk":"11450150266","pt":1717318577907,"mc":[{"id":"1.229554918","rc":[{"atb":[[3.35,0],[2.94,0]],"id":52237628},{"atb":[[32,0],[55,1.94]],"id":52671563},{"atb":[[9,0],[12.5,0]],"id":52671565},{"atb":[[550,0],[650,0]],"id":52671561},{"atb":[[5.2,0],[4.2,0]],"id":52671555},{"atb":[[8.6,0],[11.5,0]],"id":52237624},{"atb":[[4.5,0],[5.5,0]],"id":52237612},{"atb":[[18,0],[13,0]],"id":52671550},{"atb":[[10,0],[15,7.48]],"id":52671552},{"atb":[[2.58,0],[2.78,0]],"id":52671546},{"atb":[[300,0],[400,0]],"id":52671548},{"atb":[[19.5,0],[29,0]],"id":52671542},{"atb":[[7.2,0],[9.2,0]],"id":52671544},{"atb":[[16,0],[22,0]],"id":52237627},{"atb":[[20,0],[30,0]],"id":52671562},{"atb":[[75,0],[40,0]],"id":52671564},{"atb":[[7.2,0],[9.2,0]],"id":52237621},{"atb":[[18.5,0],[13.5,0]],"id":52671560},{"atb":[[18,0],[13,0]],"id":52671554},{"atb":[[4.5,0],[5.5,0]],"id":52671556},{"atb":[[9.8,0],[14.5,0]],"id":52671551},{"atb":[[4.1,0],[3.55,0]],"id":52671553},{"atb":[[170,0],[85,0]],"id":52671547},{"atb":[[50,0],[30,0]],"id":52237617},{"atb":[[370,0],[470,0]],"id":52671549},{"atb":[[7.4,0],[5.7,0]],"id":52671543},{"atb":[[9,0],[12.5,0]],"id":52237634},{"atb":[[9.6,0],[7.6,0]],"id":52671545}],"con":true,"img":false}]}
{"op":"mcm","clk":"11450152878","pt":1717318603831,"mc":[{"id":"1.229554918","rc":[{"atb":[[3.35,44.48],[2.94,125.72]],"id":52237628},{"atb":[[32,7.86],[55,3.87]],"id":52671563},{"atb":[[9,30.48],[12.5,9.08]],"id":52671565},{"atb":[[5.2,24.88],[4.2,76.22]],"id":52671555},{"atb":[[8.6,32.09],[11.5,9.95]],"id":52237624},{"atb":[[10,27.1],[15,14.94]],"id":52671552},{"atb":[[16,16.26],[22,4.97]],"id":52237627},{"atb":[[20,12.83],[30,3.6]],"id":52671562},{"atb":[[75,1.41],[40,6.25]],"id":52671564},{"atb":[[7.2,39.33],[9.2,12.74]],"id":52237621},{"atb":[[18,6.14],[13,20.32]],"id":52671554},{"atb":[[4.5,69.68],[5.5,23.22]],"id":52671556},{"atb":[[4.1,33.71],[3.55,95.64]],"id":52671553},{"atb":[[9,30.48],[12.5,9.08]],"id":52237634}],"con":true,"img":false}]}
{"op":"mcm","clk":"11450152889","pt":1717318603933,"mc":[{"id":"1.229554918","rc":[{"atb":[[550,0.44],[650,0.16]],"id":52671561},{"atb":[[4.5,69.68],[5.5,23.22]],"id":52237612},{"atb":[[18,6.14],[13,20.32]],"id":52671550},{"atb":[[2.58,154.36],[2.78,58.72]],"id":52671546},{"atb":[[300,0.81],[400,0.26]],"id":52671548},{"atb":[[19.5,13.18],[29,3.73]],"id":52671542},{"atb":[[7.2,39.33],[9.2,12.74]],"id":52671544},{"atb":[[18.5,5.97],[13.5,19.51]],"id":52671560},{"atb":[[9.8,27.71],[14.5,7.74]],"id":52671551},{"atb":[[170,0.61],[85,2.9]],"id":52671547},{"atb":[[50,2.13],[30,8.41]],"id":52237617},{"atb":[[370,0.65],[470,0.22]],"id":52671549},{"atb":[[7.4,16.33],[5.7,51.89]],"id":52671543},{"atb":[[9.6,12.15],[7.6,36.95]],"id":52671545}],"con":true,"img":false}]}
{"op":"mcm","clk":"11450164687","pt":1717318724496,"mc":[{"id":"1.229554918","rc":[{"atb":[[3.35,0],[2.94,0]],"id":52237628},{"atb":[[32,0],[55,1.94]],"id":52671563},{"atb":[[9,0],[12.5,0]],"id":52671565},{"atb":[[550,0],[650,0]],"id":52671561},{"atb":[[5.2,0],[4.2,0]],"id":52671555},{"atb":[[8.6,0],[11.5,0]],"id":52237624},{"atb":[[4.5,0],[5.5,0]],"id":52237612},{"atb":[[18,0],[13,0]],"id":52671550},{"atb":[[10,0],[15,7.48]],"id":52671552},{"atb":[[2.58,0],[2.78,0]],"id":52671546},{"atb":[[300,0],[400,0]],"id":52671548},{"atb":[[19.5,0],[29,0]],"id":52671542},{"atb":[[7.2,0],[9.2,0]],"id":52671544},{"atb":[[16,0],[22,0]],"id":52237627},{"atb":[[20,0],[30,0]],"id":52671562},{"atb":[[75,0],[40,0]],"id":52671564},{"atb":[[7.2,0],[9.2,0]],"id":52237621},{"atb":[[18.5,0],[13.5,0]],"id":52671560},{"atb":[[18,0],[13,0]],"id":52671554},{"atb":[[4.5,0],[5.5,0]],"id":52671556},{"atb":[[9.8,0],[14.5,0]],"id":52671551},{"atb":[[4.1,0],[3.55,0]],"id":52671553},{"atb":[[170,0],[85,0]],"id":52671547},{"atb":[[50,0],[30,0]],"id":52237617},{"atb":[[370,0],[470,0]],"id":52671549},{"atb":[[7.4,0],[5.7,0]],"id":52671543},{"atb":[[9,0],[12.5,0]],"id":52237634},{"atb":[[9.6,0],[7.6,0]],"id":52671545}],"con":true,"img":false}]}
{"op":"mcm","clk":"11450165725","pt":1717318735921,"mc":[{"id":"1.229554918","rc":[{"atb":[[80,0],[55,0]],"id":52671563},{"atb":[[36,0],[28,0]],"id":52237624},{"atb":[[15.5,0]],"id":52237621}],"con":true,"img":false}]}
{"op":"mcm","clk":"11450165778","pt":1717318736597,"mc":[{"id":"1.229554918","rc":[{"atb":[[85,0.94],[60,1.77]],"id":52671563},{"atb":[[40,0.67],[30,1.81]],"id":52237624},{"atb":[[16.5,6.75]],"id":52237621}],"con":true,"img":false}]}
{"op":"mcm","clk":"11450166691","pt":1717318746431,"mc":[{"id":"1.229554918","rc":[{"atb":[[85,0],[60,0]],"id":52671563},{"atb":[[40,0],[30,0]],"id":52237624},{"atb":[[16.5,0]],"id":52237621}],"con":true,"img":false}]}
{"op":"mcm","clk":"11450166779","pt":1717318747109,"mc":[{"id":"1.229554918","rc":[{"atb":[[80,0.99],[55,1.94]],"id":52671563},{"atb":[[36,0.75],[28,1.94]],"id":52237624},{"atb":[[15.5,7.21]],"id":52237621}],"con":true,"img":false}]}
{"op":"mcm","clk":"11450167448","pt":1717318753533,"mc":[{"id":"1.229554918","rc":[{"atb":[[3.35,44.48],[2.94,125.72]],"id":52237628},{"atb":[[32,7.86],[55,3.87]],"id":52671563},{"atb":[[9,30.48],[12.5,9.08]],"id":52671565},{"atb":[[550,0.44],[650,0.16]],"id":52671561},{"atb":[[5.2,24.88],[4.2,76.22]],"id":52671555},{"atb":[[8.6,32.09],[11.5,9.95]],"id":52237624},{"atb":[[4.5,69.68],[5.5,23.22]],"id":52237612},{"atb":[[18,6.14],[13,20.32]],"id":52671550},{"atb":[[10,27.1],[15,14.94]],"id":52671552},{"atb":[[2.58,154.36],[2.78,58.72]],"id":52671546},{"atb":[[300,0.81],[400,0.26]],"id":52671548},{"atb":[[19.5,13.18],[29,3.73]],"id":52671542},{"atb":[[7.2,39.33],[9.2,12.74]],"id":52671544},{"atb":[[16,16.26],[22,4.97]],"id":52237627},{"atb":[[20,12.83],[30,3.6]],"id":52671562},{"atb":[[75,1.41],[40,6.25]],"id":52671564},{"atb":[[7.2,39.33],[9.2,12.74]],"id":52237621},{"atb":[[18.5,5.97],[13.5,19.51]],"id":52671560},{"atb":[[18,6.14],[13,20.32]],"id":52671554},{"atb":[[4.5,69.68],[5.5,23.22]],"id":52671556},{"atb":[[9.8,27.71],[14.5,7.74]],"id":52671551},{"atb":[[4.1,33.71],[3.55,95.64]],"id":52671553},{"atb":[[170,0.61],[85,2.9]],"id":52671547},{"atb":[[50,2.13],[30,8.41]],"id":52237617},{"atb":[[370,0.65],[470,0.22]],"id":52671549},{"atb":[[7.4,16.33],[5.7,51.89]],"id":52671543},{"atb":[[9,30.48],[12.5,9.08]],"id":52237634},{"atb":[[9.6,12.15],[7.6,36.95]],"id":52671545}],"con":true,"img":false}]}
{"op":"mcm","clk":"11450168612","pt":1717318766528,"mc":[{"id":"1.229554918","rc":[{"atb":[[19,0],[23,0]],"id":52237624}],"con":true,"img":false}]}
{"op":"mcm","clk":"11450168672","pt":1717318767246,"mc":[{"id":"1.229554918","rc":[{"atb":[[20,5.51],[25,3.27]],"id":52237624}],"con":true,"img":false}]}
{"op":"mcm","clk":"11450169595","pt":1717318776854,"mc":[{"id":"1.229554918","rc":[{"atb":[[20,0],[25,0]],"id":52237624}],"con":true,"img":false}]}
{"op":"mcm","clk":"11450169658","pt":1717318777639,"mc":[{"id":"1.229554918","rc":[{"atb":[[19,5.81],[23,3.57]],"id":52237624}],"con":true,"img":false}]}
{"op":"mcm","clk":"11450171215","pt":1717318797550,"mc":[{"id":"1.229554918","rc":[{"atb":[[160,0],[110,0]],"id":52671563},{"atb":[[19,0],[23,0]],"id":52237624},{"atb":[[18,0],[21,0],[26,0]],"id":52237621}],"con":true,"img":false}]}
{"op":"mcm","clk":"11450171286","pt":1717318798271,"mc":[{"id":"1.229554918","rc":[{"atb":[[170,0.16],[120,0.44]],"id":52671563},{"atb":[[20,5.51],[25,3.27]],"id":52237624},{"atb":[[19,4.36],[23,2.38],[28,0.97]],"id":52237621}],"con":true,"img":false}]}
{"op":"mcm","clk":"11450172282","pt":1717318807546,"mc":[{"id":"1.229554918","rc":[{"atb":[[170,0],[120,0]],"id":52671563},{"atb":[[20,0],[25,0]],"id":52237624},{"atb":[[19,0],[23,0],[28,0]],"id":52237621}],"con":true,"img":false}]}
{"op":"mcm","clk":"11450172336","pt":1717318808270,"mc":[{"id":"1.229554918","rc":[{"atb":[[160,0.16],[110,0.48]],"id":52671563},{"atb":[[19,5.81],[23,3.57]],"id":52237624},{"atb":[[18,4.61],[21,2.62],[26,1.05]],"id":52237621}],"con":true,"img":false}]}
{"op":"mcm","clk":"11450185812","pt":1717318948836,"mc":[{"id":"1.229554918","rc":[{"atb":[[85,0],[44,0],[120,0],[60,0]],"id":52671562}],"con":true,"img":false}]}
{"op":"mcm","clk":"11450185825","pt":1717318948945,"mc":[{"id":"1.229554918","rc":[{"atb":[[140,0],[190,0],[95,0],[240,0]],"id":52671547}],"con":true,"img":false}]}
{"op":"mcm","clk":"11450185887","pt":1717318949516,"mc":[{"id":"1.229554918","rc":[{"atb":[[80,0.66],[42,2.55],[110,0.24],[55,1.45]],"id":52671562}],"con":true,"img":false}]}
{"op":"mcm","clk":"11450185905","pt":1717318949715,"mc":[{"id":"1.229554918","rc":[{"atb":[[130,0.61],[180,0.29],[90,1.18],[230,0.12]],"id":52671547}],"con":true,"img":false}]}
{"op":"mcm","clk":"11450188856","pt":1717318980254,"mc":[{"id":"1.229554918","rc":[{"atb":[[3.3,43.48]],"id":52237628},{"atl":[[230,2]],"id":52237628},{"atb":[[8.8,2]],"id":52671563},{"atb":[[12.5,17.78]],"id":52671565},{"atb":[[470,2]],"id":52671561},{"atb":[[4.6,27.78]],"id":52671555},{"atl":[[330,2]],"id":52671555},{"atb":[[8.8,12.82]],"id":52237624},{"atb":[[6.4,18.52]],"id":52237612},{"atl":[[420,2]],"id":52237612},{"atb":[[5.1,8.38]],"id":52671550},{"atb":[[22,4.76]],"id":52671552},{"atb":[[1.71,96.3]],"id":52671546},{"atl":[[75,2]],"id":52671546},{"atb":[[8.8,2]],"id":52671548},{"atb":[[50,2.04]],"id":52671542},{"atb":[[8.8,12.82]],"id":52671544},{"atl":[[480,2]],"id":52671544},{"atb":[[50,2.04]],"id":52237627},{"atb":[[50,2.04]],"id":52671562},{"atb":[[85,2]],"id":52671564},{"atb":[[13,8.33]],"id":52237621},{"atb":[[26,8.19]],"id":52671560},{"atb":[[8.8,7.07]],"id":52671554},{"atb":[[5.4,22.73]],"id":52671556},{"atl":[[350,2]],"id":52671556},{"atb":[[8.8,10.09]],"id":52671551},{"atb":[[3.3,43.48]],"id":52671553},{"atl":[[250,2]],"id":52671553},{"atb":[[110,2]],"id":52671547},{"atb":[[110,2]],"id":52237617},{"atb":[[190,2]],"id":52671549},{"atb":[[5.1,22.91]],"id":52671543},{"atl":[[420,2]],"id":52671543},{"atb":[[10.5,10.53]],"id":52671545}],"con":true,"img":false}]}
{"op":"mcm","clk":"11450188864","pt":1717318980352,"mc":[{"id":"1.229554918","rc":[{"atb":[[22,9.74]],"id":52237634}],"con":true,"img":false}]}
{"op":"mcm","clk":"11450193607","pt":1717319029659,"mc":[{"id":"1.229554918","rc":[{"atb":[[3.35,0],[2.94,0]],"id":52237628},{"atb":[[32,0],[55,1.94]],"id":52671563},{"atb":[[9,0],[12.5,8.7]],"id":52671565},{"atb":[[550,0],[650,0]],"id":52671561},{"atb":[[5.2,0],[4.2,0]],"id":52671555},{"atl":[[330,0],[320,2]],"id":52671555},{"atb":[[8.6,0],[11.5,0]],"id":52237624},{"atb":[[4.5,0],[5.5,0]],"id":52237612},{"atb":[[18,0],[13,0]],"id":52671550},{"atb":[[10,0],[15,7.48]],"id":52671552},{"atb":[[2.58,0],[2.78,0]],"id":52671546},{"atb":[[300,0],[400,0]],"id":52671548},{"atb":[[19.5,0],[29,0]],"id":52671542},{"atb":[[7.2,0],[9.2,0]],"id":52671544},{"atl":[[470,2],[480,0]],"id":52671544},{"atb":[[16,0],[22,0]],"id":52237627},{"atb":[[20,0],[30,0]],"id":52671562},{"atb":[[75,0],[40,0]],"id":52671564},{"atb":[[7.2,0],[9.2,0]],"id":52237621},{"atb":[[18.5,0],[13.5,0]],"id":52671560},{"atb":[[18,0],[13,0]],"id":52671554},{"atb":[[4.5,0],[5.5,0]],"id":52671556},{"atb":[[9.8,0],[14.5,0]],"id":52671551},{"atb":[[4.1,0],[3.55,0]],"id":52671553},{"atb":[[170,0],[85,0]],"id":52671547},{"atb":[[50,0],[30,0]],"id":52237617},{"atb":[[370,0],[470,0]],"id":52671549},{"atb":[[7.4,0],[5.7,0]],"id":52671543},{"atb":[[9,0],[12.5,0]],"id":52237634},{"atb":[[9.6,0],[7.6,0]],"id":52671545}],"con":true,"img":false}]}
{"op":"mcm","clk":"11450196168","pt":1717319058488,"mc":[{"id":"1.229554918","rc":[{"atb":[[3.35,44.48],[2.94,125.72]],"id":52237628},{"atb":[[85,1.24],[44,5.67]],"id":52671563},{"atb":[[13.5,8.36],[9.4,29.03]],"id":52671565},{"atb":[[550,0.44],[650,0.16]],"id":52671561},{"atb":[[5.2,24.88],[4.2,76.22]],"id":52671555},{"atb":[[8.6,32.09],[11.5,9.95]],"id":52237624},{"atb":[[4.5,69.68],[5.5,23.22]],"id":52237612},{"atb":[[18,6.14],[13,20.32]],"id":52671550},{"atb":[[10,27.1],[15,14.94]],"id":52671552},{"atb":[[2.58,154.36],[2.78,58.72]],"id":52671546},{"atb":[[290,0.93],[390,0.26]],"id":52671548},{"atb":[[19.5,13.18],[29,3.73]],"id":52671542},{"atb":[[7.2,39.33],[9.2,12.74]],"id":52671544},{"atb":[[17.5,14.77],[25,4.35]],"id":52237627},{"atb":[[38,2.82],[24,10.6]],"id":52671562},{"atb":[[110,0.95],[55,4.51]],"id":52671564},{"atb":[[7.2,39.33],[9.2,12.74]],"id":52237621},{"atb":[[19.5,5.65],[14.5,18.06]],"id":52671560},{"atb":[[18,6.14],[13,20.32]],"id":52671554},{"atb":[[4.4,71.73],[5.4,46.48]],"id":52671556},{"atb":[[9.8,27.71],[14.5,7.74]],"id":52671551},{"atb":[[4.1,33.71],[3.55,95.64]],"id":52671553},{"atb":[[160,0.65],[80,3.08]],"id":52671547},{"atb":[[50,2.13],[30,8.41]],"id":52237617},{"atb":[[370,0.65],[470,0.22]],"id":52671549},{"atb":[[7.4,16.33],[5.7,51.89]],"id":52671543},{"atb":[[9,30.48],[12.5,9.08]],"id":52237634},{"atb":[[9.6,12.15],[7.6,36.95]],"id":52671545}],"con":true,"img":false}]}
{"op":"mcm","clk":"11450198630","pt":1717319085701,"mc":[{"id":"1.229554918","rc":[{"atb":[[3.35,0],[2.94,0]],"id":52237628},{"atb":[[85,0],[44,0]],"id":52671563},{"atb":[[13.5,0],[9.4,0]],"id":52671565},{"atb":[[550,0],[650,0]],"id":52671561},{"atb":[[5.2,0],[4.2,0]],"id":52671555},{"atb":[[8.6,0],[11.5,0]],"id":52237624},{"atb":[[4.5,0],[5.5,0]],"id":52237612},{"atb":[[18,0],[13,0]],"id":52671550},{"atb":[[10,0],[15,7.48]],"id":52671552},{"atb":[[2.58,0],[2.78,0]],"id":52671546},{"atb":[[290,0.09],[390,0]],"id":52671548},{"atb":[[19.5,0],[29,0]],"id":52671542},{"atb":[[7.2,0],[9.2,0]],"id":52671544},{"atb":[[17.5,0],[25,0]],"id":52237627},{"atb":[[38,0],[24,0]],"id":52671562},{"atb":[[110,0],[55,0]],"id":52671564},{"atb":[[7.2,0],[9.2,0]],"id":52237621},{"atb":[[19.5,0],[14.5,0]],"id":52671560},{"atb":[[18,0],[13,0]],"id":52671554},{"atb":[[4.4,0],[5.4,22.73]],"id":52671556},{"atb":[[9.8,0],[14.5,0]],"id":52671551},{"atb":[[4.1,0],[3.55,0]],"id":52671553},{"atb":[[160,0],[80,0]],"id":52671547},{"atb":[[50,0],[30,0]],"id":52237617},{"atb":[[370,0],[470,0]],"id":52671549},{"atb":[[7.4,0],[5.7,0]],"id":52671543},{"atb":[[9,0],[12.5,0]],"id":52237634},{"atb":[[9.6,0],[7.6,0]],"id":52671545}],"con":true,"img":false}]}
{"op":"mcm","clk":"11450200052","pt":1717319100348,"mc":[{"id":"1.229554918","rc":[{"atb":[[550,0.44],[650,0.16]],"id":52671561},{"atb":[[4.4,71.73],[5.4,23.75]],"id":52237612},{"atb":[[19,5.8],[14,18.76]],"id":52671550},{"atb":[[2.56,156.35],[2.76,59.39]],"id":52671546},{"atb":[[590,0.17],[490,0.49]],"id":52671548},{"atb":[[42,2.54],[26,9.75]],"id":52671542},{"atb":[[7.2,39.33],[9.2,12.74]],"id":52671544},{"atb":[[19.5,5.65],[14.5,18.06]],"id":52671560},{"atb":[[9.8,27.71],[14.5,7.74]],"id":52671551},{"atb":[[300,0.35],[200,1.22]],"id":52671547},{"atb":[[95,1.11],[48,5.18]],"id":52237617},{"atb":[[550,0.44],[650,0.16]],"id":52671549},{"atb":[[7.4,16.33],[5.7,51.89]],"id":52671543},{"atb":[[7.4,38.1],[9.4,12.44]],"id":52671545}],"con":true,"img":false}]}
{"op":"mcm","clk":"11450200072","pt":1717319100559,"mc":[{"id":"1.229554918","rc":[{"atb":[[2.92,127.03],[3.3,88.92]],"id":52237628},{"atb":[[85,1.24],[44,5.67]],"id":52671563},{"atb":[[13.5,8.36],[9.4,29.03]],"id":52671565},{"atb":[[5.2,24.88],[4.2,76.22]],"id":52671555},{"atb":[[8.6,32.09],[11.5,9.95]],"id":52237624},{"atb":[[10,27.1],[15,14.94]],"id":52671552},{"atb":[[17.5,14.77],[25,4.35]],"id":52237627},{"atb":[[38,2.82],[24,10.6]],"id":52671562},{"atb":[[110,0.95],[55,4.51]],"id":52671564},{"atb":[[7.2,39.33],[9.2,12.74]],"id":52237621},{"atb":[[18,6.14],[13,20.32]],"id":52671554},{"atb":[[4.4,71.73],[5.4,46.48]],"id":52671556},{"atb":[[4.1,33.71],[3.55,95.64]],"id":52671553},{"atb":[[9,30.48],[12.5,9.08]],"id":52237634}],"con":true,"img":false}]}
{"op":"mcm","clk":"11450218882","pt":1717319285816,"mc":[{"id":"1.229554918","rc":[{"atb":[[3,50],[3.3,45.44]],"id":52237628},{"atb":[[16,6.67],[12.5,0]],"id":52671565},{"atb":[[790,2],[470,0]],"id":52671561},{"atb":[[65,2],[50,0]],"id":52671542},{"atb":[[50,0],[60,2]],"id":52237627},{"atb":[[50,0],[60,2]],"id":52671562},{"atb":[[85,0],[110,2.95]],"id":52671564},{"atb":[[34,3.03],[26,4.19]],"id":52671560},{"atb":[[190,0],[240,2]],"id":52671549}],"con":true,"img":false}]}
{"op":"mcm","clk":"11450218923","pt":1717319286229,"mc":[{"id":"1.229554918","rc":[{"atb":[[160,0],[110,0]],"id":52671563},{"atb":[[18,0],[21,0],[26,0],[15.5,0]],"id":52671565},{"atb":[[9.2,0],[10.5,0],[8.2,0],[13,0]],"id":52237612},{"atb":[[85,0],[44,0],[120,0],[60,0]],"id":52671542},{"atb":[[18,0],[21,0],[26,0],[15.5,0]],"id":52237621},{"atb":[[32,0],[42,0],[26,0],[55,0]],"id":52671560},{"atb":[[34,0],[44,0],[22,4.76],[27,0]],"id":52237634}],"con":true,"img":false}]}
{"op":"mcm","clk":"11450218937","pt":1717319286438,"mc":[{"id":"1.229554918","rc":[{"atb":[[16,0],[14,7.69]],"id":52671565},{"atb":[[6.4,0],[5.5,22.22]],"id":52237612},{"atb":[[65,0],[42,4.98]],"id":52671542},{"atb":[[13,0],[9.4,11.9]],"id":52237621},{"atb":[[34,0],[20,5.26]],"id":52671560},{"atb":[[22,0],[13,8.33]],"id":52237634}],"con":true,"img":false}]}
{"op":"mcm","clk":"11450218994","pt":1717319286905,"mc":[{"id":"1.229554918","rc":[{"atb":[[150,0.35],[200,0.13]],"id":52671563},{"atb":[[34,0.8],[18.5,5.98],[22,3.74],[27,2.01]],"id":52671565},{"atb":[[8,14.95],[9,9.81],[10,5.81],[12.5,2.28]],"id":52237612},{"atb":[[140,0.19],[70,1.14],[95,0.55],[48,2.23]],"id":52671542},{"atb":[[17.5,4.76],[20,2.75],[25,1.09],[15,7.48]],"id":52237621},{"atb":[[70,0.38],[38,2.12],[48,1.11],[29,3.74]],"id":52671560},{"atb":[[32,1.69],[42,0.64],[21,5.23],[26,3.14]],"id":52237634}],"con":true,"img":false}]}
{"op":"mcm","clk":"11450219008","pt":1717319287008,"mc":[{"id":"1.229554918","rc":[{"atb":[[5.5,0],[6,20]],"id":52237612},{"atb":[[65,2],[42,2.54]],"id":52671542},{"atb":[[12,9.09],[9.4,0]],"id":52237621},{"atb":[[34,3.03],[20,0]],"id":52671560},{"atb":[[20,5.26],[13,0]],"id":52237634}],"con":true,"img":false}]}
{"op":"mcm","clk":"11450222098","pt":1717319318295,"mc":[{"id":"1.229554918","rc":[{"atb":[[80,0],[42,0],[110,0],[55,0]],"id":52671562}],"con":true,"img":false}]}
{"op":"mcm","clk":"11450222138","pt":1717319318497,"mc":[{"id":"1.229554918","rc":[{"atb":[[38,5.52],[60,0]],"id":52671562},{"atb":[[180,0],[230,0]],"id":52671547}],"con":true,"img":false}]}
{"op":"mcm","clk":"11450222152","pt":1717319318608,"mc":[{"id":"1.229554918","rc":[{"atb":[[38,2.82],[25,4.17]],"id":52671562},{"atb":[[130,0],[90,0]],"id":52671547}],"con":true,"img":false}]}
{"op":"mcm","clk":"11450222196","pt":1717319319016,"mc":[{"id":"1.229554918","rc":[{"atb":[[140,0.19],[70,1.14],[95,0.55],[48,2.23]],"id":52671562}],"con":true,"img":false}]}
{"op":"mcm","clk":"11450222220","pt":1717319319216,"mc":[{"id":"1.229554918","rc":[{"atb":[[190,0.28],[240,0.11]],"id":52671547}],"con":true,"img":false}]}
{"op":"mcm","clk":"11450222234","pt":1717319319324,"mc":[{"id":"1.229554918","rc":[{"atb":[[140,0.57],[95,1.11]],"id":52671547}],"con":true,"img":false}]}
{"op":"mcm","clk":"11450225175","pt":1717319352329,"mc":[{"id":"1.229554918","rc":[{"atb":[[65,2],[25,0]],"id":52671562}],"con":true,"img":false}]}
{"op":"mcm","clk":"11450232139","pt":1717319429467,"mc":[{"id":"1.229554918","rc":[{"atb":[[710,2]],"id":52671561}],"con":true,"img":false}]}
{"op":"mcm","clk":"11450232150","pt":1717319429571,"mc":[{"id":"1.229554918","rc":[{"atb":[[790,0]],"id":52671561}],"con":true,"img":false}]}
{"op":"mcm","clk":"11450232165","pt":1717319429735,"mc":[{"id":"1.229554918","rc":[{"atb":[[140,0],[70,0],[95,0],[48,0]],"id":52671562}],"con":true,"img":false}]}
{"op":"mcm","clk":"11450232177","pt":1717319429835,"mc":[{"id":"1.229554918","rc":[{"atb":[[65,0],[38,5.52]],"id":52671562}],"con":true,"img":false}]}
{"op":"mcm","clk":"11450232187","pt":1717319429940,"mc":[{"id":"1.229554918","rc":[{"atb":[[38,2.82],[25,4.17]],"id":52671562}],"con":true,"img":false}]}
{"op":"mcm","clk":"11450232242","pt":1717319430459,"mc":[{"id":"1.229554918","rc":[{"atb":[[150,0.18],[75,1.06],[100,0.53],[50,2.13]],"id":52671562}],"con":true,"img":false}]}
{"op":"mcm","clk":"11450232770","pt":1717319435359,"mc":[{"id":"1.229554918","rc":[{"atb":[[3,0],[3.3,88.92]],"id":52237628},{"atb":[[21,5],[22,0]],"id":52671552}],"con":true,"img":false}]}
{"op":"mcm","clk":"11450232801","pt":1717319435664,"mc":[{"id":"1.229554918","rc":[{"atb":[[19,0],[23,0]],"id":52237624}],"con":true,"img":false}]}
{"op":"mcm","clk":"11450232834","pt":1717319436132,"mc":[{"id":"1.229554918","rc":[{"atb":[[150,0],[75,0],[100,0],[50,0]],"id":52671562}],"con":true,"img":false}]}
{"op":"mcm","clk":"11450232853","pt":1717319436341,"mc":[{"id":"1.229554918","rc":[{"atb":[[19.5,5.66],[24,3.41]],"id":52237624}],"con":true,"img":false}]}
{"op":"mcm","clk":"11450232903","pt":1717319436863,"mc":[{"id":"1.229554918","rc":[{"atb":[[140,0.19],[70,1.14],[95,0.55],[48,2.23]],"id":52671562}],"con":true,"img":false}]}
{"op":"mcm","clk":"11450233818","pt":1717319446163,"mc":[{"id":"1.229554918","rc":[{"atb":[[2.92,0],[3.3,43.48]],"id":52237628},{"atb":[[85,0],[44,0]],"id":52671563},{"atb":[[13.5,0],[9.4,0]],"id":52671565},{"atb":[[550,0],[650,0]],"id":52671561},{"atb":[[5.2,0],[4.2,0]],"id":52671555},{"atb":[[8.6,0],[11.5,0]],"id":52237624},{"atb":[[4.4,0],[5.4,0]],"id":52237612},{"atb":[[19,0],[14,0]],"id":52671550},{"atb":[[10,0],[15,7.48]],"id":52671552},{"atb":[[2.56,0],[2.76,0]],"id":52671546},{"atb":[[590,0],[490,0]],"id":52671548},{"atb":[[42,0],[26,0]],"id":52671542},{"atb":[[7.2,0],[9.2,0]],"id":52671544},{"atb":[[17.5,0],[25,0]],"id":52237627},{"atb":[[38,0],[24,0]],"id":52671562},{"atb":[[110,2],[55,0]],"id":52671564},{"atb":[[7.2,0],[9.2,0]],"id":52237621},{"atb":[[19.5,0],[14.5,0]],"id":52671560},{"atb":[[18,0],[13,0]],"id":52671554},{"atb":[[4.4,0],[5.4,22.73]],"id":52671556},{"atb":[[9.8,0],[14.5,0]],"id":52671551},{"atb":[[4.1,0],[3.55,0]],"id":52671553},{"atb":[[300,0],[200,0]],"id":52671547},{"atb":[[95,0],[48,0]],"id":52237617},{"atb":[[550,0],[650,0]],"id":52671549},{"atb":[[7.4,0],[5.7,0]],"id":52671543},{"atb":[[9,0],[12.5,0]],"id":52237634},{"atb":[[7.4,0],[9.4,0]],"id":52671545}],"con":true,"img":false}]}
{"op":"mcm","clk":"11450233834","pt":1717319446371,"mc":[{"id":"1.229554918","rc":[{"atb":[[210,2.38],[240,0]],"id":52671549}],"con":true,"img":false}]}
{"op":"mcm","clk":"11450235383","pt":1717319462584,"mc":[{"id":"1.229554918","rc":[{"atb":[[65,2],[25,0]],"id":52671562}],"con":true,"img":false}]}
{"op":"mcm","clk":"11450238764","pt":1717319500866,"mc":[{"id":"1.229554918","rc":[{"atb":[[2.92,127.03],[3.3,88.92]],"id":52237628},{"atb":[[85,1.24],[44,5.67]],"id":52671563},{"atb":[[13.5,8.36],[9.4,29.03]],"id":52671565},{"atb":[[550,0.44],[650,0.16]],"id":52671561},{"atb":[[5.2,24.88],[4.2,76.22]],"id":52671555},{"atb":[[8.6,32.09],[11.5,9.95]],"id":52237624},{"atb":[[4.4,71.73],[5.4,23.75]],"id":52237612},{"atb":[[19,5.8],[14,18.76]],"id":52671550},{"atb":[[10,27.1],[15,14.94]],"id":52671552},{"atb":[[2.56,156.35],[2.76,59.39]],"id":52671546},{"atb":[[590,0.17],[490,0.49]],"id":52671548},{"atb":[[42,2.54],[26,9.75]],"id":52671542},{"atb":[[7.2,39.33],[9.2,12.74]],"id":52671544},{"atb":[[17.5,14.77],[25,4.35]],"id":52237627},{"atb":[[38,2.82],[24,10.6]],"id":52671562},{"atb":[[110,2.95],[55,4.51]],"id":52671564},{"atb":[[7.2,39.33],[9.2,12.74]],"id":52237621},{"atb":[[19.5,5.65],[14.5,18.06]],"id":52671560},{"atb":[[18,6.14],[13,20.32]],"id":52671554},{"atb":[[4.4,71.73],[5.4,46.48]],"id":52671556},{"atb":[[9.8,27.71],[14.5,7.74]],"id":52671551},{"atb":[[4.1,33.71],[3.55,95.64]],"id":52671553},{"atb":[[300,0.35],[200,1.22]],"id":52671547},{"atb":[[95,1.11],[48,5.18]],"id":52237617},{"atb":[[550,0.44],[650,0.16]],"id":52671549},{"atb":[[7.4,16.33],[5.7,51.89]],"id":52671543},{"atb":[[9,30.48],[12.5,9.08]],"id":52237634},{"atb":[[7.4,38.1],[9.4,12.44]],"id":52671545}],"con":true,"img":false}]}
{"op":"mcm","clk":"11450240724","pt":1717319522187,"mc":[{"id":"1.229554918","rc":[{"atb":[[140,0],[70,0],[95,0],[48,0]],"id":52671542}],"con":true,"img":false}]}
{"op":"mcm","clk":"11450240746","pt":1717319522394,"mc":[{"id":"1.229554918","rc":[{"atb":[[65,0],[42,4.98]],"id":52671542}],"con":true,"img":false}]}
{"op":"mcm","clk":"11450240805","pt":1717319522866,"mc":[{"id":"1.229554918","rc":[{"atb":[[130,0.2],[65,1.22],[90,0.59],[46,2.32]],"id":52671542}],"con":true,"img":false}]}
{"op":"mcm","clk":"11450243807","pt":1717319554047,"mc":[{"id":"1.229554918","rc":[{"atb":[[42,2.54],[60,2]],"id":52671542}],"con":true,"img":false}]}
{"op":"mcm","clk":"11450244062","pt":1717319556948,"mc":[{"id":"1.229554918","rc":[{"atb":[[6.8,0],[4.9,0],[5.9,0],[5.4,0]],"id":52671555},{"atb":[[40,0],[50,0],[25,0],[30,0]],"id":52671554},{"atb":[[5.6,0],[5.1,0],[4.6,0],[6.2,0]],"id":52671556},{"atb":[[32,0],[18,0],[21,0],[26,0]],"id":52671551},{"atb":[[3.45,0],[3.95,0],[3.7,0],[4.4,0]],"id":52671553},{"atb":[[140,0],[190,0],[95,0],[240,0]],"id":52671547},{"atb":[[9.6,0],[8.6,0],[11.5,0],[14,0]],"id":52671543}],"con":true,"img":false}]}
{"op":"mcm","clk":"11450244122","pt":1717319557666,"mc":[{"id":"1.229554918","rc":[{"atb":[[32,2.53],[42,1.28],[26,4.19],[55,0.49]],"id":52671554},{"atb":[[3.45,32.03],[3.2,47.56],[3.95,8.87],[3.7,19.38]],"id":52671553},{"atb":[[11,5.23],[13.5,2.09],[8.4,14.14],[9.4,9.34]],"id":52671543}],"con":true,"img":false}]}
{"op":"mcm","clk":"11450244132","pt":1717319557770,"mc":[{"id":"1.229554918","rc":[{"atb":[[5.8,16.35],[5.3,24.33],[7.6,3.97],[6.6,9.34]],"id":52671555},{"atb":[[5,26.16],[5.5,17.44],[6,10.46],[7,4.36]],"id":52671556},{"atb":[[17.5,6.34],[20,4.13],[25,2.18],[30,0.9]],"id":52671551},{"atb":[[150,0.35],[75,1.41],[200,1.36],[100,0.8]],"id":52671547}],"con":true,"img":false}]}
{"op":"mcm","clk":"11450249866","pt":1717319621957,"mc":[{"id":"1.229554918","rc":[{"atb":[[8,0],[9,0],[10,0],[12.5,0]],"id":52237612},{"atb":[[17.5,0],[20,0],[25,0],[15,0]],"id":52237621},{"atb":[[32,0],[42,0],[21,0],[26,0]],"id":52237634}],"con":true,"img":false}]}
{"op":"mcm","clk":"11450249871","pt":1717319622058,"mc":[{"id":"1.229554918","rc":[{"atb":[[5.5,22.22],[6,0]],"id":52237612},{"atb":[[12,0],[9.4,11.9]],"id":52237621},{"atb":[[20,0],[13,8.33]],"id":52237634}],"con":true,"img":false}]}
{"op":"mcm","clk":"11450249960","pt":1717319622679,"mc":[{"id":"1.229554918","rc":[{"atb":[[11,5.23],[13.5,2.09],[8.4,14.14],[9.4,9.34]],"id":52237612},{"atb":[[16,6.97],[18.5,4.48],[22,2.49],[27,1]],"id":52237621},{"atb":[[34,1.59],[44,0.61],[22,4.98],[27,3.02]],"id":52237634}],"con":true,"img":false}]}
{"op":"mcm","clk":"11450252566","pt":1717319652820,"mc":[{"id":"1.229554918","rc":[{"atb":[[6.4,18.52],[5.5,0]],"id":52237612},{"atb":[[13,8.33],[9.4,0]],"id":52237621},{"atb":[[21,5],[13,0]],"id":52237634}],"con":true,"img":false}]}
{"op":"mcm","clk":"11450255378","pt":1717319684216,"mc":[{"id":"1.229554918","rc":[{"atb":[[520,2],[710,0]],"id":52671561},{"atb":[[34,0]],"id":52671560}],"con":true,"img":false}]}
{"op":"mcm","clk":"11450255389","pt":1717319684329,"mc":[{"id":"1.229554918","rc":[{"atb":[[28,3.7]],"id":52671560}],"con":true,"img":false}]}
{"op":"mcm","clk":"11450255406","pt":1717319684526,"mc":[{"id":"1.229554918","rc":[{"atb":[[150,0],[200,0]],"id":52671563},{"atb":[[34,0],[18.5,0],[22,0],[27,0]],"id":52671565},{"atb":[[140,0],[70,0],[95,0],[48,0]],"id":52671562},{"atb":[[70,0],[38,0],[48,0],[29,0]],"id":52671560}],"con":true,"img":false}]}
{"op":"mcm","clk":"11450255414","pt":1717319684629,"mc":[{"id":"1.229554918","rc":[{"atb":[[520,0],[670,2]],"id":52671561}],"con":true,"img":false}]}
{"op":"mcm","clk":"11450255422","pt":1717319684733,"mc":[{"id":"1.229554918","rc":[{"atb":[[65,0],[38,5.52]],"id":52671562}],"con":true,"img":false}]}
{"op":"mcm","clk":"11450255441","pt":1717319684941,"mc":[{"id":"1.229554918","rc":[{"atb":[[520,2],[670,0]],"id":52671561}],"con":true,"img":false}]}
{"op":"mcm","clk":"11450255468","pt":1717319685258,"mc":[{"id":"1.229554918","rc":[{"atb":[[170,0.16],[120,0.44]],"id":52671563},{"atb":[[17,6.54],[19.5,4.24],[24,2.28],[29,0.94]],"id":52671565},{"atb":[[85,0.62],[44,2.43],[120,0.22],[60,1.33]],"id":52671562},{"atb":[[34,2.38],[44,1.22],[27,4.02],[60,0.44]],"id":52671560}],"con":true,"img":false}]}
{"op":"mcm","clk":"11450255482","pt":1717319685357,"mc":[{"id":"1.229554918","rc":[{"atb":[[38,2.82],[55,2]],"id":52671562}],"con":true,"img":false}]}
{"op":"mcm","clk":"11450255844","pt":1717319689453,"mc":[{"id":"1.229554918","rc":[{"atb":[[520,0],[670,2]],"id":52671561},{"atb":[[65,2],[55,0]],"id":52671562}],"con":true,"img":false}]}
{"op":"mcm","clk":"11450255875","pt":1717319689718,"mc":[{"id":"1.229554918","rc":[{"atb":[[17,0],[19.5,0],[24,0],[29,0]],"id":52671565},{"atb":[[34,0],[44,0],[27,0],[60,0]],"id":52671560}],"con":true,"img":false}]}
{"op":"mcm","clk":"11450255888","pt":1717319689821,"mc":[{"id":"1.229554918","rc":[{"atb":[[170,0],[120,0]],"id":52671563}],"con":true,"img":false}]}
{"op":"mcm","clk":"11450255897","pt":1717319689929,"mc":[{"id":"1.229554918","rc":[{"atb":[[20,5.26],[28,0]],"id":52671560}],"con":true,"img":false}]}
{"op":"mcm","clk":"11450255946","pt":1717319690437,"mc":[{"id":"1.229554918","rc":[{"atb":[[34,0.8],[18.5,5.98],[22,3.74],[27,2.01]],"id":52671565},{"atb":[[70,0.38],[38,2.12],[48,1.11],[29,3.74]],"id":52671560}],"con":true,"img":false}]}
{"op":"mcm","clk":"11450255956","pt":1717319690546,"mc":[{"id":"1.229554918","rc":[{"atb":[[150,0.35],[200,0.13]],"id":52671563}],"con":true,"img":false}]}
{"op":"mcm","clk":"11450258127","pt":1717319714473,"mc":[{"id":"1.229554918","rc":[{"atb":[[32,3.23],[20,0]],"id":52671560}],"con":true,"img":false}]}
{"op":"mcm","clk":"11450258536","pt":1717319718271,"mc":[{"id":"1.229554918","rc":[{"atb":[[3,50],[3.3,45.44]],"id":52237628},{"atb":[[21,0],[22,4.76]],"id":52671552}],"con":true,"img":false}]}
{"op":"mcm","clk":"11450258571","pt":1717319718588,"mc":[{"id":"1.229554918","rc":[{"atb":[[19.5,0],[24,0]],"id":52237624},{"atb":[[11,0],[13.5,0],[8.4,0],[9.4,0]],"id":52237612},{"atb":[[16,0],[18.5,0],[22,0],[27,0]],"id":52237621},{"atb":[[34,0],[44,0],[22,0],[27,0]],"id":52237634}],"con":true,"img":false}]}
{"op":"mcm","clk":"11450258579","pt":1717319718694,"mc":[{"id":"1.229554918","rc":[{"atb":[[6.4,0]],"id":52237612},{"atb":[[13,0],[9.4,11.9]],"id":52237621},{"atb":[[21,0],[13,8.33]],"id":52237634}],"con":true,"img":false}]}
{"op":"mcm","clk":"11450258591","pt":1717319718795,"mc":[{"id":"1.229554918","rc":[{"atb":[[5.5,22.22]],"id":52237612}],"con":true,"img":false}]}
{"op":"mcm","clk":"11450258635","pt":1717319719153,"mc":[{"id":"1.229554918","rc":[{"atl":[[470,0]],"id":52671544}],"con":true,"img":false}]}
{"op":"mcm","clk":"11450258648","pt":1717319719267,"mc":[{"id":"1.229554918","rc":[{"atb":[[19,5.81],[23,3.57]],"id":52237624},{"atb":[[8,14.95],[9,9.81],[10,5.81],[12.5,2.28]],"id":52237612}],"con":true,"img":false}]}
{"op":"mcm","clk":"11450258658","pt":1717319719364,"mc":[{"id":"1.229554918","rc":[{"atb":[[17.5,4.76],[20,2.75],[25,1.09],[15,7.48]],"id":52237621},{"atb":[[32,1.69],[42,0.64],[21,5.23],[26,3.14]],"id":52237634}],"con":true,"img":false}]}
{"op":"mcm","clk":"11450258670","pt":1717319719477,"mc":[{"id":"1.229554918","rc":[{"atb":[[12,9.09],[9.4,0]],"id":52237621},{"atb":[[3.45,0],[3.2,0],[3.95,0],[3.7,0]],"id":52671553},{"atb":[[20,5.26],[13,0]],"id":52237634}],"con":true,"img":false}]}
{"op":"mcm","clk":"11450258690","pt":1717319719678,"mc":[{"id":"1.229554918","rc":[{"atb":[[5,0],[5.5,0],[6,0],[7,0]],"id":52671556},{"atb":[[75,0],[100,0]],"id":52671547}],"con":true,"img":false}]}
{"op":"mcm","clk":"11450258700","pt":1717319719781,"mc":[{"id":"1.229554918","rc":[{"atb":[[5.3,23.26],[5.4,23.75]],"id":52671556}],"con":true,"img":false}]}
{"op":"mcm","clk":"11450258742","pt":1717319720193,"mc":[{"id":"1.229554918","rc":[{"atb":[[3.4,32.7],[3.15,48.67],[3.9,9.02],[3.65,19.74]],"id":52671553}],"con":true,"img":false}]}
{"op":"mcm","clk":"11450258765","pt":1717319720350,"mc":[{"id":"1.229554918","rc":[{"atb":[[6.8,4.51],[4.9,26.83],[5.9,10.68],[5.4,41.59]],"id":52671556},{"atb":[[80,1.32],[110,2.72]],"id":52671547}],"con":true,"img":false}]}
{"op":"mcm","clk":"11450260472","pt":1717319738579,"mc":[{"id":"1.229554918","rc":[{"atl":[[470,2]],"id":52671544}],"con":true,"img":false}]}
{"op":"mcm","clk":"11450260508","pt":1717319739028,"mc":[{"id":"1.229554918","rc":[{"atb":[[6.8,0],[4.9,0],[5.9,0],[5.4,23.75]],"id":52671556},{"atb":[[3.4,0],[3.15,0],[3.9,0],[3.65,0]],"id":52671553},{"atb":[[80,0],[110,2]],"id":52671547}],"con":true,"img":false}]}
{"op":"mcm","clk":"11450260570","pt":1717319739718,"mc":[{"id":"1.229554918","rc":[{"atb":[[5,26.16],[5.5,17.44],[6,10.46],[7,4.36]],"id":52671556},{"atb":[[3.45,32.03],[3.2,47.56],[3.95,8.87],[3.7,19.38]],"id":52671553},{"atb":[[75,1.41],[100,0.8]],"id":52671547}],"con":true,"img":false}]}
{"op":"mcm","clk":"11450260600","pt":1717319740077,"mc":[{"id":"1.229554918","rc":[{"atb":[[21,5],[22,0]],"id":52671552}],"con":true,"img":false}]}
{"op":"mcm","clk":"11450260629","pt":1717319740390,"mc":[{"id":"1.229554918","rc":[{"atb":[[42,0]],"id":52237634}],"con":true,"img":false}]}
{"op":"mcm","clk":"11450260695","pt":1717319741115,"mc":[{"id":"1.229554918","rc":[{"atb":[[44,0.61]],"id":52237634}],"con":true,"img":false}]}
{"op":"mcm","clk":"11450261316","pt":1717319748001,"mc":[{"id":"1.229554918","rc":[{"atb":[[3.3,88.92]],"id":52237628}],"con":true,"img":false}]}
{"op":"mcm","clk":"11450261325","pt":1717319748116,"mc":[{"id":"1.229554918","rc":[{"atb":[[3,0]],"id":52237628}],"con":true,"img":false}]}
{"op":"mcm","clk":"11450261358","pt":1717319748518,"mc":[{"id":"1.229554918","rc":[{"atb":[[6.4,18.52],[5.5,0]],"id":52237612}],"con":true,"img":false}]}
{"op":"mcm","clk":"11450261460","pt":1717319749808,"mc":[{"id":"1.229554918","rc":[{"atb":[[3,50]],"id":52237628}],"con":true,"img":false}]}
{"op":"mcm","clk":"11450261467","pt":1717319749910,"mc":[{"id":"1.229554918","rc":[{"atb":[[3.3,45.44]],"id":52237628}],"con":true,"img":false}]}
{"op":"mcm","clk":"11450261489","pt":1717319750220,"mc":[{"id":"1.229554918","rc":[{"atb":[[44,0]],"id":52237634}],"con":true,"img":false}]}
{"op":"mcm","clk":"11450261535","pt":1717319750891,"mc":[{"id":"1.229554918","rc":[{"atb":[[42,0.64]],"id":52237634}],"con":true,"img":false}]}
{"op":"mcm","clk":"11450263097","pt":1717319769669,"mc":[{"id":"1.229554918","rc":[{"atb":[[21,0],[22,4.76]],"id":52671552}],"con":true,"img":false}]}
{"op":"mcm","clk":"11450263147","pt":1717319770432,"mc":[{"id":"1.229554918","rc":[{"atb":[[21,5]],"id":52671552}],"con":true,"img":false}]}
{"op":"mcm","clk":"11450263153","pt":1717319770533,"mc":[{"id":"1.229554918","rc":[{"atb":[[22,0]],"id":52671552}],"con":true,"img":false}]}
{"op":"mcm","clk":"11450263174","pt":1717319770842,"mc":[{"id":"1.229554918","rc":[{"atb":[[42,0]],"id":52237634}],"con":true,"img":false}]}
{"op":"mcm","clk":"11450263252","pt":1717319771927,"mc":[{"id":"1.229554918","rc":[{"atb":[[44,0.61]],"id":52237634}],"con":true,"img":false}]}
{"op":"mcm","clk":"11450263920","pt":1717319779270,"mc":[{"id":"1.229554918","rc":[{"atb":[[3,0],[3.3,88.92]],"id":52237628}],"con":true,"img":false}]}
{"op":"mcm","clk":"11450264017","pt":1717319780151,"mc":[{"id":"1.229554918","rc":[{"atb":[[3,50],[3.3,45.44]],"id":52237628}],"con":true,"img":false}]}
{"op":"mcm","clk":"11450264055","pt":1717319780667,"mc":[{"id":"1.229554918","rc":[{"atb":[[44,0]],"id":52237634}],"con":true,"img":false}]}
{"op":"mcm","clk":"11450264106","pt":1717319781339,"mc":[{"id":"1.229554918","rc":[{"atb":[[42,0.64]],"id":52237634}],"con":true,"img":false}]}
{"op":"mcm","clk":"11450264927","pt":1717319791076,"mc":[{"id":"1.229554918","rc":[{"atb":[[2.92,0],[3.3,0]],"id":52237628},{"atb":[[85,0],[44,0]],"id":52671563},{"atb":[[13.5,0],[9.4,0]],"id":52671565},{"atb":[[550,0],[650,0]],"id":52671561},{"atb":[[5.2,0],[4.2,0]],"id":52671555},{"atb":[[8.6,0],[11.5,0]],"id":52237624},{"atb":[[4.4,0],[5.4,0]],"id":52237612},{"atb":[[19,0],[14,0]],"id":52671550},{"atb":[[10,0],[15,7.48]],"id":52671552},{"atb":[[2.56,0],[2.76,0]],"id":52671546},{"atb":[[590,0],[490,0]],"id":52671548},{"atb":[[42,0],[26,0]],"id":52671542},{"atb":[[7.2,0],[9.2,0]],"id":52671544},{"atb":[[17.5,0],[25,0]],"id":52237627},{"atb":[[38,0],[24,0]],"id":52671562},{"atb":[[110,2],[55,0]],"id":52671564},{"atb":[[7.2,0],[9.2,0]],"id":52237621},{"atb":[[19.5,0],[14.5,0]],"id":52671560},{"atb":[[18,0],[13,0]],"id":52671554},{"atb":[[4.4,0],[5.4,0]],"id":52671556},{"atb":[[9.8,0],[14.5,0]],"id":52671551},{"atb":[[4.1,0],[3.55,0]],"id":52671553},{"atb":[[300,0],[200,0.13]],"id":52671547},{"atb":[[95,0],[48,0]],"id":52237617},{"atb":[[550,0],[650,0]],"id":52671549},{"atb":[[7.4,0],[5.7,0]],"id":52671543},{"atb":[[9,0],[12.5,0]],"id":52237634},{"atb":[[7.4,0],[9.4,0]],"id":52671545}],"con":true,"img":false}]}
{"op":"mcm","clk":"11450265686","pt":1717319799680,"mc":[{"id":"1.229554918","rc":[{"atb":[[21,0],[22,4.76]],"id":52671552}],"con":true,"img":false}]}
{"op":"mcm","clk":"11450265801","pt":1717319800979,"mc":[{"id":"1.229554918","rc":[{"atb":[[3,0],[3.3,43.48]],"id":52237628},{"atb":[[21,5],[22,0]],"id":52671552}],"con":true,"img":false}]}
{"op":"mcm","clk":"11450266072","pt":1717319803785,"mc":[{"id":"1.229554918","rc":[{"atb":[[2.92,127.03],[3.3,88.92]],"id":52237628},{"atb":[[85,1.24],[44,5.67]],"id":52671563},{"atb":[[13.5,8.36],[9.4,29.03]],"id":52671565},{"atb":[[550,0.44],[650,0.16]],"id":52671561},{"atb":[[5.2,24.88],[4.2,76.22]],"id":52671555},{"atb":[[8.6,32.09],[11.5,9.95]],"id":52237624},{"atb":[[4.4,71.73],[5.4,23.75]],"id":52237612},{"atb":[[19,5.8],[14,18.76]],"id":52671550},{"atb":[[10,27.1],[15,14.94]],"id":52671552},{"atb":[[2.56,156.35],[2.76,59.39]],"id":52671546},{"atb":[[590,0.17],[490,0.49]],"id":52671548},{"atb":[[42,2.54],[26,9.75]],"id":52671542},{"atb":[[7.2,39.33],[9.2,12.74]],"id":52671544},{"atb":[[17.5,14.77],[25,4.35]],"id":52237627},{"atb":[[38,2.82],[24,10.6]],"id":52671562},{"atb":[[110,2.95],[55,4.51]],"id":52671564},{"atb":[[7.2,39.33],[9.2,12.74]],"id":52237621},{"atb":[[19.5,5.65],[14.5,18.06]],"id":52671560},{"atb":[[18,6.14],[13,20.32]],"id":52671554},{"atb":[[4.4,71.73],[5.4,23.75]],"id":52671556},{"atb":[[9.8,27.71],[14.5,7.74]],"id":52671551},{"atb":[[4.1,33.71],[3.55,95.64]],"id":52671553},{"atb":[[300,0.35],[200,1.36]],"id":52671547},{"atb":[[95,1.11],[48,5.18]],"id":52237617},{"atb":[[550,0.44],[650,0.16]],"id":52671549},{"atb":[[7.4,16.33],[5.7,51.89]],"id":52671543},{"atb":[[9,30.48],[12.5,9.08]],"id":52237634},{"atb":[[7.4,38.1],[9.4,12.44]],"id":52671545}],"con":true,"img":false}]}
{"op":"mcm","clk":"11450266706","pt":1717319810604,"mc":[{"id":"1.229554918","rc":[{"atb":[[3,50],[3.3,45.44]],"id":52237628}],"con":true,"img":false}]}
{"op":"mcm","clk":"11450268356","pt":1717319829911,"mc":[{"id":"1.229554918","rc":[{"atb":[[21,0],[22,4.76]],"id":52671552}],"con":true,"img":false}]}
{"op":"mcm","clk":"11450268466","pt":1717319831209,"mc":[{"id":"1.229554918","rc":[{"atb":[[3.3,88.92]],"id":52237628}],"con":true,"img":false}]}
{"op":"mcm","clk":"11450268471","pt":1717319831312,"mc":[{"id":"1.229554918","rc":[{"atb":[[3,0]],"id":52237628},{"atb":[[21,5],[22,0]],"id":52671552}],"con":true,"img":false}]}
{"op":"mcm","clk":"11450269285","pt":1717319841055,"mc":[{"id":"1.229554918","rc":[{"atb":[[3,50],[3.3,45.44]],"id":52237628}],"con":true,"img":false}]}
{"op":"mcm","clk":"11450270775","pt":1717319859966,"mc":[{"id":"1.229554918","rc":[{"atb":[[21,0],[22,4.76]],"id":52671552}],"con":true,"img":false}]}
{"op":"mcm","clk":"11450270914","pt":1717319861676,"mc":[{"id":"1.229554918","rc":[{"atb":[[21,5],[22,0]],"id":52671552}],"con":true,"img":false}]}
{"op":"mcm","clk":"11450271577","pt":1717319869559,"mc":[{"id":"1.229554918","rc":[{"atb":[[3,0],[3.3,88.92]],"id":52237628}],"con":true,"img":false}]}
{"op":"mcm","clk":"11450271701","pt":1717319871365,"mc":[{"id":"1.229554918","rc":[{"atb":[[3,50]],"id":52237628},{"atb":[[22,4.76]],"id":52671552}],"con":true,"img":false}]}
{"op":"mcm","clk":"11450271710","pt":1717319871478,"mc":[{"id":"1.229554918","rc":[{"atb":[[3.3,45.44]],"id":52237628},{"atb":[[21,0]],"id":52671552}],"con":true,"img":false}]}
{"op":"mcm","clk":"11450273348","pt":1717319892127,"mc":[{"id":"1.229554918","rc":[{"atb":[[3,0],[3.3,88.92]],"id":52237628},{"atb":[[21,5],[22,0]],"id":52671552}],"con":true,"img":false}]}
{"op":"mcm","clk":"11450274020","pt":1717319900654,"mc":[{"id":"1.229554918","rc":[{"atb":[[3,50],[3.3,45.44]],"id":52237628},{"atb":[[21,0],[22,4.76]],"id":52671552}],"con":true,"img":false}]}
{"op":"mcm","clk":"11450275650","pt":1717319922504,"mc":[{"id":"1.229554918","rc":[{"atb":[[3.3,88.92]],"id":52237628},{"atb":[[21,5],[22,0]],"id":52671552}],"con":true,"img":false}]}
{"op":"mcm","clk":"11450275658","pt":1717319922561,"mc":[{"id":"1.229554918","rc":[{"atb":[[3,0]],"id":52237628}],"con":true,"img":false}]}
{"op":"mcm","clk":"11450276431","pt":1717319932217,"mc":[{"id":"1.229554918","rc":[{"atb":[[3,50],[3.3,45.44]],"id":52237628}],"con":true,"img":false}]}
{"op":"mcm","clk":"11450277920","pt":1717319950247,"mc":[{"id":"1.229554918","rc":[{"atb":[[21,0],[22,4.76]],"id":52671552}],"con":true,"img":false}]}
{"op":"mcm","clk":"11450278145","pt":1717319952933,"mc":[{"id":"1.229554918","rc":[{"atb":[[3.3,88.92]],"id":52237628}],"con":true,"img":false}]}
{"op":"mcm","clk":"11450278158","pt":1717319953039,"mc":[{"id":"1.229554918","rc":[{"atb":[[3,0]],"id":52237628}],"con":true,"img":false}]}
{"op":"mcm","clk":"11450278340","pt":1717319955354,"mc":[{"id":"1.229554918","rc":[{"atb":[[21,5]],"id":52671552}],"con":true,"img":false}]}
{"op":"mcm","clk":"11450278345","pt":1717319955408,"mc":[{"id":"1.229554918","rc":[{"atb":[[22,0]],"id":52671552}],"con":true,"img":false}]}
{"op":"mcm","clk":"11450278900","pt":1717319962611,"mc":[{"id":"1.229554918","rc":[{"atb":[[3,50],[3.3,45.44]],"id":52237628}],"con":true,"img":false}]}
{"op":"mcm","clk":"11450280441","pt":1717319982658,"mc":[{"id":"1.229554918","rc":[{"atb":[[22,4.76]],"id":52671552}],"con":true,"img":false}]}
{"op":"mcm","clk":"11450280449","pt":1717319982758,"mc":[{"id":"1.229554918","rc":[{"atb":[[21,0]],"id":52671552}],"con":true,"img":false}]}
{"op":"mcm","clk":"11450280515","pt":1717319983377,"mc":[{"id":"1.229554918","rc":[{"atb":[[3.3,88.92]],"id":52237628},{"atb":[[21,5],[22,0]],"id":52671552}],"con":true,"img":false}]}
{"op":"mcm","clk":"11450280526","pt":1717319983481,"mc":[{"id":"1.229554918","rc":[{"atb":[[3,0]],"id":52237628}],"con":true,"img":false}]}
{"op":"mcm","clk":"11450281318","pt":1717319993499,"mc":[{"id":"1.229554918","rc":[{"atb":[[3,50],[3.3,45.44]],"id":52237628},{"atb":[[21,0],[22,4.76]],"id":52671552}],"con":true,"img":false}]}
{"op":"mcm","clk":"11450283016","pt":1717320013817,"mc":[{"id":"1.229554918","rc":[{"atb":[[3,0],[3.3,88.92]],"id":52237628},{"atb":[[21,5],[22,0]],"id":52671552}],"con":true,"img":false}]}
{"op":"mcm","clk":"11450283040","pt":1717320014123,"mc":[{"id":"1.229554918","rc":[{"atb":[[19,0],[23,0]],"id":52237624},{"atb":[[8,0],[9,0],[10,0],[12.5,0]],"id":52237612},{"atb":[[17.5,0],[20,0],[25,0],[15,0]],"id":52237621}],"con":true,"img":false}]}
{"op":"mcm","clk":"11450283042","pt":1717320014225,"mc":[{"id":"1.229554918","rc":[{"atb":[[5.5,22.22]],"id":52237612},{"atb":[[12,0],[9.4,11.9]],"id":52237621}],"con":true,"img":false}]}
{"op":"mcm","clk":"11450283052","pt":1717320014330,"mc":[{"id":"1.229554918","rc":[{"atb":[[6.4,0]],"id":52237612}],"con":true,"img":false}]}
{"op":"mcm","clk":"11450283088","pt":1717320014803,"mc":[{"id":"1.229554918","rc":[{"atb":[[19.5,5.66],[24,3.41]],"id":52237624},{"atb":[[11,5.23],[13.5,2.09],[8.4,14.14],[9.4,9.34]],"id":52237612},{"atb":[[16,6.97],[18.5,4.48],[22,2.49],[27,1]],"id":52237621}],"con":true,"img":false}]}
{"op":"mcm","clk":"11450283107","pt":1717320015013,"mc":[{"id":"1.229554918","rc":[{"atb":[[6.4,18.52],[5.5,0]],"id":52237612},{"atb":[[13,8.33],[9.4,0]],"id":52237621}],"con":true,"img":false}]}
{"op":"mcm","clk":"11450283722","pt":1717320023412,"mc":[{"id":"1.229554918","rc":[{"atb":[[3,50],[3.3,45.44]],"id":52237628}],"con":true,"img":false}]}
{"op":"mcm","clk":"11450283738","pt":1717320023721,"mc":[{"id":"1.229554918","rc":[{"atb":[[19.5,0],[24,0]],"id":52237624},{"atb":[[11,0],[13.5,0],[8.4,0],[9.4,0]],"id":52237612},{"atb":[[16,0],[18.5,0],[22,0],[27,0]],"id":52237621}],"con":true,"img":false}]}
{"op":"mcm","clk":"11450283745","pt":1717320023821,"mc":[{"id":"1.229554918","rc":[{"atb":[[13,0]],"id":52237621}],"con":true,"img":false}]}
{"op":"mcm","clk":"11450283755","pt":1717320023924,"mc":[{"id":"1.229554918","rc":[{"atb":[[6.4,0],[5.5,22.22]],"id":52237612},{"atb":[[9.4,11.9]],"id":52237621}],"con":true,"img":false}]}
{"op":"mcm","clk":"11450283795","pt":1717320024437,"mc":[{"id":"1.229554918","rc":[{"atb":[[19,5.81],[23,3.57]],"id":52237624},{"atb":[[8,14.95],[9,9.81],[10,5.81],[12.5,2.28]],"id":52237612},{"atb":[[17.5,4.76],[20,2.75],[25,1.09],[15,7.48]],"id":52237621}],"con":true,"img":false}]}
{"op":"mcm","clk":"11450284928","pt":1717320040633,"mc":[{"id":"1.229554918","rc":[{"atb":[[22,4.76]],"id":52671552}],"con":true,"img":false}]}
{"op":"mcm","clk":"11450284935","pt":1717320040733,"mc":[{"id":"1.229554918","rc":[{"atb":[[21,0]],"id":52671552}],"con":true,"img":false}]}
{"op":"mcm","clk":"11450284999","pt":1717320041720,"mc":[{"id":"1.229554918","rc":[{"atb":[[6,20]],"id":52237612},{"atb":[[12,9.09]],"id":52237621}],"con":true,"img":false}]}
{"op":"mcm","clk":"11450285018","pt":1717320041931,"mc":[{"id":"1.229554918","rc":[{"atb":[[5.5,0]],"id":52237612},{"atb":[[9.4,0]],"id":52237621}],"con":true,"img":false}]}
{"op":"mcm","clk":"11450285184","pt":1717320044248,"mc":[{"id":"1.229554918","rc":[{"atb":[[21,5],[22,0]],"id":52671552}],"con":true,"img":false}]}
{"op":"mcm","clk":"11450285551","pt":1717320050151,"mc":[{"id":"1.229554918","rc":[{"atb":[[3.3,88.92]],"id":52237628}],"con":true,"img":false}]}
{"op":"mcm","clk":"11450285557","pt":1717320050252,"mc":[{"id":"1.229554918","rc":[{"atb":[[3,0]],"id":52237628}],"con":true,"img":false}]}
{"op":"mcm","clk":"11450285820","pt":1717320055252,"mc":[{"id":"1.229554918","rc":[{"atb":[[3,50],[3.3,45.44]],"id":52237628}],"con":true,"img":false}]}
{"op":"mcm","clk":"11450286161","pt":1717320060667,"mc":[{"id":"1.229554918","rc":[{"atb":[[520,2]],"id":52671561}],"con":true,"img":false}]}
{"op":"mcm","clk":"11450286171","pt":1717320060869,"mc":[{"id":"1.229554918","rc":[{"atb":[[670,0]],"id":52671561}],"con":true,"img":false}]}
{"op":"mcm","clk":"11450286181","pt":1717320061072,"mc":[{"id":"1.229554918","rc":[{"atb":[[150,0],[200,0]],"id":52671563},{"atb":[[70,0],[38,0],[48,0],[29,0]],"id":52671560}],"con":true,"img":false}]}
{"op":"mcm","clk":"11450286188","pt":1717320061175,"mc":[{"id":"1.229554918","rc":[{"atb":[[34,0],[18.5,0],[22,0],[27,0]],"id":52671565},{"atb":[[32,0],[20,5.26]],"id":52671560}],"con":true,"img":false}]}
{"op":"mcm","clk":"11450286217","pt":1717320061781,"mc":[{"id":"1.229554918","rc":[{"atb":[[170,0.16],[120,0.44]],"id":52671563},{"atb":[[34,2.38],[44,1.22],[27,4.02],[60,0.44]],"id":52671560}],"con":true,"img":false}]}
{"op":"mcm","clk":"11450286225","pt":1717320061879,"mc":[{"id":"1.229554918","rc":[{"atb":[[17,6.54],[19.5,4.24],[24,2.28],[29,0.94]],"id":52671565},{"atb":[[20,0],[28,3.7]],"id":52671560}],"con":true,"img":false}]}
{"op":"mcm","clk":"11450286238","pt":1717320062085,"mc":[{"id":"1.229554918","rc":[{"atb":[[520,0],[670,2]],"id":52671561}],"con":true,"img":false}]}
{"op":"mcm","clk":"11450286455","pt":1717320065553,"mc":[{"id":"1.229554918","rc":[{"atb":[[670,0]],"id":52671561}],"con":true,"img":false}]}
{"op":"mcm","clk":"11450286461","pt":1717320065655,"mc":[{"id":"1.229554918","rc":[{"atb":[[520,2]],"id":52671561}],"con":true,"img":false}]}
{"op":"mcm","clk":"11450286752","pt":1717320069980,"mc":[{"id":"1.229554918","rc":[{"atb":[[42,0]],"id":52237634}],"con":true,"img":false}]}
{"op":"mcm","clk":"11450286788","pt":1717320070698,"mc":[{"id":"1.229554918","rc":[{"atb":[[44,0.61]],"id":52237634}],"con":true,"img":false}]}
{"op":"mcm","clk":"11450287042","pt":1717320074287,"mc":[{"id":"1.229554918","rc":[{"atb":[[22,4.76]],"id":52671552}],"con":true,"img":false}]}
{"op":"mcm","clk":"11450287047","pt":1717320074383,"mc":[{"id":"1.229554918","rc":[{"atb":[[21,0]],"id":52671552}],"con":true,"img":false}]}
{"op":"mcm","clk":"11450287212","pt":1717320076578,"mc":[{"id":"1.229554918","rc":[{"atb":[[3,0],[3.3,88.92]],"id":52237628}],"con":true,"img":false}]}
{"op":"mcm","clk":"11450287440","pt":1717320079380,"mc":[{"id":"1.229554918","rc":[{"atb":[[21,5]],"id":52671552}],"con":true,"img":false}]}
{"op":"mcm","clk":"11450287446","pt":1717320079477,"mc":[{"id":"1.229554918","rc":[{"atb":[[22,0]],"id":52671552}],"con":true,"img":false}]}
{"op":"mcm","clk":"11450287503","pt":1717320080463,"mc":[{"id":"1.229554918","rc":[{"atb":[[44,0]],"id":52237634}],"con":true,"img":false}]}
{"op":"mcm","clk":"11450287534","pt":1717320081188,"mc":[{"id":"1.229554918","rc":[{"atb":[[42,0.64]],"id":52237634}],"con":true,"img":false}]}
{"op":"mcm","clk":"11450287569","pt":1717320081701,"mc":[{"id":"1.229554918","rc":[{"atb":[[3,50],[3.3,45.44]],"id":52237628}],"con":true,"img":false}]}
{"op":"mcm","clk":"11450287994","pt":1717320088195,"mc":[{"id":"1.229554918","rc":[{"atb":[[34,5.41],[28,0]],"id":52671560}],"con":true,"img":false}]}
{"op":"mcm","clk":"11450288263","pt":1717320091987,"mc":[{"id":"1.229554918","rc":[{"atb":[[520,0],[670,2]],"id":52671561}],"con":true,"img":false}]}
{"op":"mcm","clk":"11450288775","pt":1717320100414,"mc":[{"id":"1.229554918","rc":[{"atb":[[22,4.76]],"id":52671552}],"con":true,"img":false}]}
{"op":"mcm","clk":"11450288780","pt":1717320100518,"mc":[{"id":"1.229554918","rc":[{"atb":[[21,0]],"id":52671552}],"con":true,"img":false}]}
{"op":"mcm","clk":"11450293008","pt":1717320161400,"mc":[{"id":"1.229554918","rc":[{"atb":[[3,0],[3.3,88.92]],"id":52237628},{"atb":[[520,2],[670,0]],"id":52671561},{"atb":[[21,5],[22,0]],"id":52671552},{"atb":[[34,2.38],[28,3.7]],"id":52671560}],"con":true,"img":false}]}
{"op":"mcm","clk":"11450293421","pt":1717320166522,"mc":[{"id":"1.229554918","rc":[{"atb":[[3,50],[3.3,45.44]],"id":52237628}],"con":true,"img":false}]}
{"op":"mcm","clk":"11450293550","pt":1717320168300,"mc":[{"id":"1.229554918","rc":[{"atb":[[2.92,0],[3.3,0]],"id":52237628},{"atb":[[85,0],[44,0]],"id":52671563},{"atb":[[13.5,0],[9.4,0]],"id":52671565},{"atb":[[550,0],[650,0]],"id":52671561},{"atb":[[5.2,0],[4.2,0]],"id":52671555},{"atb":[[8.6,0],[11.5,0]],"id":52237624},{"atb":[[4.4,0],[5.4,0]],"id":52237612},{"atb":[[19,0],[14,0]],"id":52671550},{"atb":[[10,0],[15,7.48]],"id":52671552},{"atb":[[2.56,0],[2.76,0]],"id":52671546},{"atb":[[590,0],[490,0]],"id":52671548},{"atb":[[42,0],[26,0]],"id":52671542},{"atb":[[7.2,0],[9.2,0]],"id":52671544},{"atb":[[17.5,0],[25,0]],"id":52237627},{"atb":[[38,0],[24,0]],"id":52671562},{"atb":[[110,2],[55,0]],"id":52671564},{"atb":[[7.2,0],[9.2,0]],"id":52237621},{"atb":[[19.5,0],[14.5,0]],"id":52671560},{"atb":[[18,0],[13,0]],"id":52671554},{"atb":[[4.4,0],[5.4,0]],"id":52671556},{"atb":[[9.8,0],[14.5,0]],"id":52671551},{"atb":[[4.1,0],[3.55,0]],"id":52671553},{"atb":[[300,0],[200,0.13]],"id":52671547},{"atb":[[95,0],[48,0]],"id":52237617},{"atb":[[550,0],[650,0]],"id":52671549},{"atb":[[7.4,0],[5.7,0]],"id":52671543},{"atb":[[9,0],[12.5,0]],"id":52237634},{"atb":[[7.4,0],[9.4,0]],"id":52671545}],"con":true,"img":false}]}
{"op":"mcm","clk":"11450293952","pt":1717320174606,"mc":[{"id":"1.229554918","rc":[{"atb":[[130,0],[65,0],[90,0],[46,0]],"id":52671542}],"con":true,"img":false}]}
{"op":"mcm","clk":"11450293990","pt":1717320175336,"mc":[{"id":"1.229554918","rc":[{"atb":[[140,0.19],[70,1.14],[95,0.55],[48,2.23]],"id":52671542}],"con":true,"img":false}]}
{"op":"mcm","clk":"11450294746","pt":1717320186755,"mc":[{"id":"1.229554918","rc":[{"atb":[[520,0],[790,2]],"id":52671561},{"atb":[[22,4.76]],"id":52671552},{"atb":[[34,5.41]],"id":52671560}],"con":true,"img":false}]}
{"op":"mcm","clk":"11450294754","pt":1717320186859,"mc":[{"id":"1.229554918","rc":[{"atb":[[21,0]],"id":52671552},{"atb":[[28,0]],"id":52671560}],"con":true,"img":false}]}
{"op":"mcm","clk":"11450295486","pt":1717320196967,"mc":[{"id":"1.229554918","rc":[{"atb":[[2.92,127.03],[3.3,45.44]],"id":52237628},{"atb":[[85,1.24],[44,5.67]],"id":52671563},{"atb":[[13.5,8.36],[9.4,29.03]],"id":52671565},{"atb":[[5.2,24.88],[4.2,76.22]],"id":52671555},{"atb":[[8.6,32.09],[11.5,9.95]],"id":52237624},{"atb":[[10,27.1],[15,14.94]],"id":52671552},{"atb":[[17.5,14.77],[25,4.35]],"id":52237627},{"atb":[[38,2.82],[24,10.6]],"id":52671562},{"atb":[[110,2.95],[55,4.51]],"id":52671564},{"atb":[[7.2,39.33],[9.2,12.74]],"id":52237621},{"atb":[[18,6.14],[13,20.32]],"id":52671554},{"atb":[[4.4,71.73],[5.4,23.75]],"id":52671556},{"atb":[[4.1,33.71],[3.55,95.64]],"id":52671553},{"atb":[[9,30.48],[12.5,9.08]],"id":52237634}],"con":true,"img":false}]}
{"op":"mcm","clk":"11450295499","pt":1717320197077,"mc":[{"id":"1.229554918","rc":[{"atb":[[550,0.44],[650,0.16]],"id":52671561},{"atb":[[4.4,71.73],[5.4,23.75]],"id":52237612},{"atb":[[19,5.8],[14,18.76]],"id":52671550},{"atb":[[2.56,156.35],[2.76,59.39]],"id":52671546},{"atb":[[590,0.17],[490,0.49]],"id":52671548},{"atb":[[42,2.54],[26,9.75]],"id":52671542},{"atb":[[7.2,39.33],[9.2,12.74]],"id":52671544},{"atb":[[19.5,5.65],[14.5,18.06]],"id":52671560},{"atb":[[9.8,27.71],[14.5,7.74]],"id":52671551},{"atb":[[300,0.35],[200,1.36]],"id":52671547},{"atb":[[95,1.11],[48,5.18]],"id":52237617},{"atb":[[550,0.44],[650,0.16]],"id":52671549},{"atb":[[7.4,16.33],[5.7,51.89]],"id":52671543},{"atb":[[7.4,38.1],[9.4,12.44]],"id":52671545}],"con":true,"img":false}]}
{"op":"mcm","clk":"11450303483","pt":1717320319402,"mc":[{"id":"1.229554918","rc":[{"atb":[[170,0],[120,0]],"id":52671563},{"atb":[[17,0],[19.5,0],[24,0],[29,0]],"id":52671565},{"atb":[[34,3.03],[44,0],[27,0],[60,0]],"id":52671560}],"con":true,"img":false}]}
{"op":"mcm","clk":"11450303489","pt":1717320319507,"mc":[{"id":"1.229554918","rc":[{"atb":[[34,0],[20,5.26]],"id":52671560}],"con":true,"img":false}]}
{"op":"mcm","clk":"11450303524","pt":1717320320083,"mc":[{"id":"1.229554918","rc":[{"atb":[[150,0.35],[200,0.13]],"id":52671563},{"atb":[[34,0.8],[18.5,5.98],[22,3.74],[27,2.01]],"id":52671565},{"atb":[[70,0.38],[38,2.12],[48,1.11],[29,3.74]],"id":52671560}],"con":true,"img":false}]}
{"op":"mcm","clk":"11450304756","pt":1717320340848,"mc":[{"id":"1.229554918","rc":[{"atb":[[3,0],[3.3,88.92]],"id":52237628},{"atb":[[520,2],[790,0]],"id":52671561},{"atb":[[21,5],[22,0]],"id":52671552}],"con":true,"img":false}]}
{"op":"mcm","clk":"11450304773","pt":1717320341159,"mc":[{"id":"1.229554918","rc":[{"atb":[[150,0],[200,0]],"id":52671563},{"atb":[[34,0],[18.5,0],[22,0],[27,0]],"id":52671565},{"atb":[[19,0],[23,0]],"id":52237624},{"atb":[[8,0],[9,0],[10,0],[12.5,0]],"id":52237612},{"atb":[[17.5,0],[20,0],[25,0],[15,0]],"id":52237621},{"atb":[[70,0],[38,0],[48,0],[29,0]],"id":52671560},{"atb":[[42,0]],"id":52237634}],"con":true,"img":false}]}
{"op":"mcm","clk":"11450304780","pt":1717320341215,"mc":[{"id":"1.229554918","rc":[{"atb":[[12,0]],"id":52237621}],"con":true,"img":false}]}
{"op":"mcm","clk":"11450304789","pt":1717320341322,"mc":[{"id":"1.229554918","rc":[{"atb":[[5.5,22.22],[6,0]],"id":52237612},{"atb":[[9.4,11.9]],"id":52237621}],"con":true,"img":false}]}
{"op":"mcm","clk":"11450304821","pt":1717320341837,"mc":[{"id":"1.229554918","rc":[{"atb":[[170,0.16],[120,0.44]],"id":52671563},{"atb":[[19.5,5.66],[24,3.41]],"id":52237624},{"atb":[[11,5.23],[13.5,2.09],[8.4,14.14],[9.4,9.34]],"id":52237612},{"atb":[[34,2.38],[44,1.22],[27,4.02],[60,0.44]],"id":52671560},{"atb":[[44,0.61]],"id":52237634}],"con":true,"img":false}]}
{"op":"mcm","clk":"11450304828","pt":1717320341941,"mc":[{"id":"1.229554918","rc":[{"atb":[[17,6.54],[19.5,4.24],[24,2.28],[29,0.94]],"id":52671565},{"atb":[[16,6.97],[18.5,4.48],[22,2.49],[27,1]],"id":52237621}],"con":true,"img":false}]}
{"op":"mcm","clk":"11450304918","pt":1717320343233,"mc":[{"id":"1.229554918","rc":[{"atb":[[20,0],[28,3.7]],"id":52671560}],"con":true,"img":false}]}
{"op":"mcm","clk":"11450305165","pt":1717320347456,"mc":[{"id":"1.229554918","rc":[{"atb":[[3,50],[3.3,45.44]],"id":52237628},{"atb":[[520,0],[790,2]],"id":52671561},{"atb":[[21,0],[22,4.76]],"id":52671552},{"atb":[[34,5.41],[28,0]],"id":52671560}],"con":true,"img":false}]}
{"op":"mcm","clk":"11450305177","pt":1717320347767,"mc":[{"id":"1.229554918","rc":[{"atb":[[170,0],[120,0]],"id":52671563},{"atb":[[17,0],[19.5,0],[24,0],[29,0]],"id":52671565},{"atb":[[19.5,0],[24,0]],"id":52237624},{"atb":[[11,0],[13.5,0],[8.4,0],[9.4,0]],"id":52237612},{"atb":[[16,0],[18.5,0],[22,0],[27,0]],"id":52237621},{"atb":[[34,3.03],[44,0],[27,0],[60,0]],"id":52671560},{"atb":[[44,0]],"id":52237634}],"con":true,"img":false}]}
{"op":"mcm","clk":"11450305209","pt":1717320348442,"mc":[{"id":"1.229554918","rc":[{"atb":[[150,0.35],[200,0.13]],"id":52671563},{"atb":[[34,0.8],[18.5,5.98],[22,3.74],[27,2.01]],"id":52671565},{"atb":[[19,5.81],[23,3.57]],"id":52237624},{"atb":[[8,14.95],[9,9.81],[10,5.81],[12.5,2.28]],"id":52237612},{"atb":[[17.5,4.76],[20,2.75],[25,1.09],[15,7.48]],"id":52237621},{"atb":[[70,0.38],[38,2.12],[48,1.11],[29,3.74]],"id":52671560},{"atb":[[42,0.64]],"id":52237634}],"con":true,"img":false}]}
{"op":"mcm","clk":"11450306089","pt":1717320364880,"mc":[{"id":"1.229554918","rc":[{"atb":[[5.5,0],[6,20]],"id":52237612},{"atb":[[12,9.09],[9.4,0]],"id":52237621}],"con":true,"img":false}]}
{"op":"mcm","clk":"11450307898","pt":1717320396422,"mc":[{"id":"1.229554918","rc":[{"atb":[[710,2],[790,0]],"id":52671561}],"con":true,"img":false}]}
{"op":"mcm","clk":"11450307997","pt":1717320398295,"mc":[{"id":"1.229554918","rc":[{"atb":[[1.65,112.52],[1.71,0]],"id":52671546}],"con":true,"img":false}]}
{"op":"mcm","clk":"11450308010","pt":1717320398497,"mc":[{"id":"1.229554918","rc":[{"atb":[[710,0],[770,2]],"id":52671561},{"atb":[[22,0],[23,4.55]],"id":52671552},{"atb":[[1.51,112.52],[1.65,0]],"id":52671546},{"atb":[[2.98,50.51],[3.3,0]],"id":52671553},{"atb":[[20,0],[23,4.55]],"id":52237634}],"con":true,"img":false}]}
{"op":"mcm","clk":"11450308027","pt":1717320398836,"mc":[{"id":"1.229554918","rc":[{"atb":[[5.6,0],[5.1,0],[4.6,0],[6.2,0]],"id":52237628},{"atb":[[150,0],[200,0]],"id":52671563},{"atb":[[34,0],[18.5,0],[22,0],[27,0]],"id":52671565},{"atb":[[19,0],[23,0]],"id":52237624},{"atb":[[8,0],[9,0],[10,0],[12.5,0]],"id":52237612},{"atb":[[17.5,0],[20,0],[25,0],[15,0]],"id":52237621},{"atb":[[70,0],[38,0],[48,0],[29,0]],"id":52671560},{"atb":[[11,0],[13.5,0],[8.4,0],[9.4,0]],"id":52671543},{"atb":[[42,0]],"id":52237634}],"con":true,"img":false}]}
{"op":"mcm","clk":"11450308041","pt":1717320398996,"mc":[{"id":"1.229554918","rc":[{"atb":[[5.5,22.22],[6,0]],"id":52237612},{"atb":[[12,0],[9.4,11.9]],"id":52237621},{"atb":[[34,0],[20,5.26]],"id":52671560}],"con":true,"img":false}]}
{"op":"mcm","clk":"11450308074","pt":1717320399512,"mc":[{"id":"1.229554918","rc":[{"atb":[[48,0.55]],"id":52237634}],"con":true,"img":false}]}
{"op":"mcm","clk":"11450308101","pt":1717320399919,"mc":[{"id":"1.229554918","rc":[{"atb":[[4.5,29.89],[5,19.62],[5.5,11.63],[6,5.23]],"id":52237628},{"atb":[[170,0.31],[220,0.12]],"id":52671563},{"atb":[[32,0.84],[18,6.15],[21,3.92],[26,2.09]],"id":52671565},{"atb":[[20,5.51],[25,3.27]],"id":52237624},{"atb":[[9.6,9.12],[8.6,13.77],[11.5,4.98],[14,2.01]],"id":52237612},{"atb":[[16.5,6.75],[19,4.36],[23,2.38],[28,0.97]],"id":52237621},{"atb":[[75,0.36],[40,2.01],[50,1.07],[30,3.61]],"id":52671560},{"atb":[[9.6,9.12],[8.6,13.77],[11.5,4.98],[14,2.01]],"id":52671543}],"con":true,"img":false}]}
{"op":"mcm","clk":"11450308105","pt":1717320400022,"mc":[{"id":"1.229554918","rc":[{"atb":[[6.8,17.24]],"id":52237612},{"atb":[[13.5,8]],"id":52237621},{"atb":[[36,2.86]],"id":52671560}],"con":true,"img":false}]}
{"op":"mcm","clk":"11450308111","pt":1717320400084,"mc":[{"id":"1.229554918","rc":[{"atb":[[5.5,0]],"id":52237612},{"atb":[[9.4,0]],"id":52237621},{"atb":[[20,0]],"id":52671560}],"con":true,"img":false}]}
{"op":"mcm","clk":"11450308291","pt":1717320402736,"mc":[{"id":"1.229554918","rc":[{"atb":[[3,0],[2.78,56.18]],"id":52237628}],"con":true,"img":false}]}
{"op":"mcm","clk":"11450308325","pt":1717320403111,"mc":[{"id":"1.229554918","rc":[{"atb":[[4.5,0],[5,0],[5.5,0],[6,0]],"id":52237628},{"atb":[[20,0],[25,0]],"id":52237624},{"atb":[[9.6,0],[8.6,0],[11.5,0],[14,0]],"id":52237612},{"atb":[[16.5,0],[19,0],[23,0],[28,0]],"id":52237621},{"atb":[[48,0]],"id":52237634}],"con":true,"img":false}]}
{"op":"mcm","clk":"11450308341","pt":1717320403323,"mc":[{"id":"1.229554918","rc":[{"atb":[[5.5,22.22],[6.8,0]],"id":52237612},{"atb":[[13.5,0],[9.4,11.9]],"id":52237621}],"con":true,"img":false}]}
{"op":"mcm","clk":"11450308361","pt":1717320403623,"mc":[{"id":"1.229554918","rc":[{"atb":[[32,0],[18,0],[21,0],[26,0]],"id":52671565},{"atb":[[75,0],[40,0],[50,0],[30,0]],"id":52671560}],"con":true,"img":false}]}
{"op":"mcm","clk":"11450308370","pt":1717320403726,"mc":[{"id":"1.229554918","rc":[{"atb":[[170,0],[220,0]],"id":52671563},{"atb":[[36,0],[20,5.26]],"id":52671560},{"atb":[[9.6,0],[8.6,0],[11.5,0],[14,0]],"id":52671543}],"con":true,"img":false}]}
{"op":"mcm","clk":"11450308377","pt":1717320403830,"mc":[{"id":"1.229554918","rc":[{"atb":[[5.6,5.69],[5.1,12.76],[4.6,21.8],[4.1,33.76]],"id":52237628},{"atb":[[19.5,5.66],[24,3.41]],"id":52237624},{"atb":[[9.2,9.57],[10.5,5.51],[8.2,14.53],[13,2.18]],"id":52237612},{"atb":[[16,6.97],[18.5,4.48],[22,2.49],[27,1]],"id":52237621},{"atb":[[46,0.58]],"id":52237634}],"con":true,"img":false}]}
{"op":"mcm","clk":"11450308412","pt":1717320404316,"mc":[{"id":"1.229554918","rc":[{"atb":[[32,0.84],[18,6.15],[21,3.92],[26,2.09]],"id":52671565},{"atb":[[75,0.36],[40,2.01],[50,1.07],[30,3.61]],"id":52671560}],"con":true,"img":false}]}
{"op":"mcm","clk":"11450308423","pt":1717320404420,"mc":[{"id":"1.229554918","rc":[{"atb":[[170,0.31],[220,0.12]],"id":52671563},{"atb":[[36,2.86]],"id":52671560},{"atb":[[9.6,9.12],[8.6,13.77],[11.5,4.98],[14,2.01]],"id":52671543}],"con":true,"img":false}]}
{"op":"mcm","clk":"11450308428","pt":1717320404516,"mc":[{"id":"1.229554918","rc":[{"atb":[[9.2,0],[10.5,0],[8.2,0],[13,0]],"id":52237612},{"atb":[[20,0]],"id":52671560},{"atb":[[46,0]],"id":52237634}],"con":true,"img":false}]}
{"op":"mcm","clk":"11450308475","pt":1717320405232,"mc":[{"id":"1.229554918","rc":[{"atb":[[9.6,9.12],[8.6,13.77],[11.5,4.98],[14,2.01]],"id":52237612},{"atb":[[48,0.55]],"id":52237634}],"con":true,"img":false}]}
{"op":"mcm","clk":"11450308724","pt":1717320409533,"mc":[{"id":"1.229554918","rc":[{"atb":[[710,2],[770,0]],"id":52671561},{"atb":[[22,4.76],[23,0]],"id":52671552}],"con":true,"img":false}]}
{"op":"mcm","clk":"11450308746","pt":1717320409801,"mc":[{"id":"1.229554918","rc":[{"atb":[[19.5,0],[24,0]],"id":52237624},{"atb":[[16,0],[18.5,0],[22,0],[27,0]],"id":52237621}],"con":true,"img":false}]}
{"op":"mcm","clk":"11450308755","pt":1717320410004,"mc":[{"id":"1.229554918","rc":[{"atb":[[30,0]],"id":52671560}],"con":true,"img":false}]}
{"op":"mcm","clk":"11450308762","pt":1717320410110,"mc":[{"id":"1.229554918","rc":[{"atb":[[75,0],[40,0],[50,0]],"id":52671560}],"con":true,"img":false}]}
{"op":"mcm","clk":"11450308768","pt":1717320410213,"mc":[{"id":"1.229554918","rc":[{"atb":[[20,5.26]],"id":52671560}],"con":true,"img":false}]}
{"op":"mcm","clk":"11450308771","pt":1717320410318,"mc":[{"id":"1.229554918","rc":[{"atb":[[170,0],[220,0]],"id":52671563},{"atb":[[36,0]],"id":52671560},{"atb":[[9.6,0],[8.6,0],[11.5,0],[14,0]],"id":52671543}],"con":true,"img":false}]}
{"op":"mcm","clk":"11450308784","pt":1717320410569,"mc":[{"id":"1.229554918","rc":[{"atb":[[19,5.81],[23,3.57]],"id":52237624},{"atb":[[17.5,4.76],[20,2.75],[25,1.09],[15,7.48]],"id":52237621}],"con":true,"img":false}]}
{"op":"mcm","clk":"11450308796","pt":1717320410775,"mc":[{"id":"1.229554918","rc":[{"atb":[[29,3.74]],"id":52671560}],"con":true,"img":false}]}
{"op":"mcm","clk":"11450308800","pt":1717320410888,"mc":[{"id":"1.229554918","rc":[{"atb":[[70,0.38],[38,2.12],[48,1.11]],"id":52671560}],"con":true,"img":false}]}
{"op":"mcm","clk":"11450308808","pt":1717320410992,"mc":[{"id":"1.229554918","rc":[{"atb":[[9.6,0],[8.6,0],[11.5,0],[14,0]],"id":52237612},{"atb":[[48,0]],"id":52237634}],"con":true,"img":false}]}
{"op":"mcm","clk":"11450308813","pt":1717320411094,"mc":[{"id":"1.229554918","rc":[{"atb":[[150,0.35],[200,0.13]],"id":52671563},{"atb":[[11,5.23],[13.5,2.09],[8.4,14.14],[9.4,9.34]],"id":52671543}],"con":true,"img":false}]}
{"op":"mcm","clk":"11450308845","pt":1717320411666,"mc":[{"id":"1.229554918","rc":[{"atb":[[8,14.95],[9,9.81],[10,5.81],[12.5,2.28]],"id":52237612},{"atb":[[42,0.64]],"id":52237634}],"con":true,"img":false}]}
{"op":"mcm","clk":"11450309451","pt":1717320421476,"mc":[{"id":"1.229554918","rc":[{"atb":[[1.51,0],[1.66,112.52]],"id":52671546},{"atb":[[3.2,93.01],[2.98,0]],"id":52671553}],"con":true,"img":false}]}
{"op":"mcm","clk":"11450309735","pt":1717320425584,"mc":[{"id":"1.229554918","rc":[{"atb":[[3,50]],"id":52237628}],"con":true,"img":false}]}
{"op":"mcm","clk":"11450309742","pt":1717320425687,"mc":[{"id":"1.229554918","rc":[{"atb":[[2.78,0]],"id":52237628}],"con":true,"img":false}]}
{"op":"mcm","clk":"11450309778","pt":1717320426202,"mc":[{"id":"1.229554918","rc":[{"atb":[[6.2,19.23],[5.5,0]],"id":52237612},{"atb":[[12.5,8.7]],"id":52237621}],"con":true,"img":false}]}
{"op":"mcm","clk":"11450309789","pt":1717320426301,"mc":[{"id":"1.229554918","rc":[{"atb":[[9.4,0]],"id":52237621}],"con":true,"img":false}]}
{"op":"mcm","clk":"11450309964","pt":1717320428597,"mc":[{"id":"1.229554918","rc":[{"atb":[[770,2]],"id":52671561},{"atb":[[23,4.55]],"id":52671552},{"atb":[[1.51,112.52],[1.66,0]],"id":52671546}],"con":true,"img":false}]}
{"op":"mcm","clk":"11450309975","pt":1717320428702,"mc":[{"id":"1.229554918","rc":[{"atb":[[710,0]],"id":52671561},{"atb":[[22,0]],"id":52671552}],"con":true,"img":false}]}
{"op":"mcm","clk":"11450310294","pt":1717320433104,"mc":[{"id":"1.229554918","rc":[{"atb":[[36,2.86],[20,0]],"id":52671560}],"con":true,"img":false}]}
{"op":"mcm","clk":"11450310364","pt":1717320434206,"mc":[{"id":"1.229554918","rc":[{"atl":[[410,2]],"id":52237612},{"atb":[[23,0],[24,4.35]],"id":52671552},{"atl":[[70,2],[75,0]],"id":52671546}],"con":true,"img":false}]}
{"op":"mcm","clk":"11450310369","pt":1717320434292,"mc":[{"id":"1.229554918","rc":[{"atl":[[420,0]],"id":52237612}],"con":true,"img":false}]}
{"op":"mcm","clk":"11450310672","pt":1717320439412,"mc":[{"id":"1.229554918","rc":[{"atb":[[3,0],[2.62,61.73]],"id":52237628},{"atb":[[770,0],[810,2.1]],"id":52671561},{"atb":[[4.6,0],[3.7,37.04]],"id":52671555},{"atb":[[7.2,16.13],[6.2,0]],"id":52237612},{"atb":[[1.51,0],[1.31,112.52]],"id":52671546},{"atb":[[75,2],[60,0]],"id":52671542},{"atb":[[12.5,0],[15.5,6.9]],"id":52237621},{"atb":[[5.3,0],[4.4,101.14]],"id":52671556},{"atb":[[2.8,55.56],[3.2,47.56]],"id":52671553},{"atb":[[170,2],[110,0]],"id":52671547},{"atb":[[270,2],[210,0.38]],"id":52671549}],"con":true,"img":false}]}
{"op":"mcm","clk":"11450310695","pt":1717320439722,"mc":[{"id":"1.229554918","rc":[{"atb":[[5.6,0],[5.1,0],[4.6,0],[4.1,0]],"id":52237628},{"atb":[[32,0],[18,0],[21,0],[26,0]],"id":52671565},{"atb":[[140,0],[70,0],[95,0],[48,0]],"id":52671542},{"atb":[[17.5,0],[20,0],[12.5,0],[15,0]],"id":52671544}],"con":true,"img":false}]}
{"op":"mcm","clk":"11450310711","pt":1717320439930,"mc":[{"id":"1.229554918","rc":[{"atb":[[1.5,112.52],[1.31,0]],"id":52671546}],"con":true,"img":false}]}
{"op":"mcm","clk":"11450310749","pt":1717320440408,"mc":[{"id":"1.229554918","rc":[{"atb":[[4.5,29.89],[5,19.62],[5.5,11.63],[6,5.23]],"id":52237628},{"atb":[[32,0.84],[18,6.15],[21,3.92],[26,2.09]],"id":52671565},{"atb":[[140,0.19],[70,1.14],[95,0.55],[48,2.23]],"id":52671542},{"atb":[[17,3.27],[19.5,1.41],[12,9.51],[14.5,5.81]],"id":52671544}],"con":true,"img":false}]}
{"op":"mcm","clk":"11450311065","pt":1717320444609,"mc":[{"id":"1.229554918","rc":[{"atb":[[750,2],[810,0.1]],"id":52671561}],"con":true,"img":false}]}
{"op":"mcm","clk":"11450311365","pt":1717320449117,"mc":[{"id":"1.229554918","rc":[{"atl":[[470,0]],"id":52671544}],"con":true,"img":false}]}
{"op":"mcm","clk":"11450311381","pt":1717320449429,"mc":[{"id":"1.229554918","rc":[{"atb":[[5.8,0],[5.3,0],[7.6,0],[6.6,0]],"id":52671555},{"atb":[[32,0],[42,0],[26,0],[55,0]],"id":52671554},{"atb":[[3.45,0],[3.2,0],[3.95,0],[3.7,0]],"id":52671553}],"con":true,"img":false}]}
{"op":"mcm","clk":"11450311385","pt":1717320449532,"mc":[{"id":"1.229554918","rc":[{"atb":[[5,0],[5.5,0],[6,0],[7,0]],"id":52671556},{"atb":[[17.5,0],[20,0],[25,0],[30,0]],"id":52671551}],"con":true,"img":false}]}
{"op":"mcm","clk":"11450311422","pt":1717320450105,"mc":[{"id":"1.229554918","rc":[{"atb":[[6.4,9.69],[7.4,4.09],[5.2,49.8],[5.7,16.69]],"id":52671555},{"atb":[[65,0.41],[36,2.24],[46,1.16],[28,3.88]],"id":52671554},{"atb":[[3.8,9.34],[3.55,116.17],[3.3,34.12],[3.05,51.04]],"id":52671553}],"con":true,"img":false}]}
{"op":"mcm","clk":"11450311428","pt":1717320450209,"mc":[{"id":"1.229554918","rc":[{"atb":[[6.8,4.51],[4.9,26.83],[5.9,10.68],[5.4,41.59]],"id":52671556},{"atb":[[32,0.84],[18,6.15],[21,3.92],[26,2.09]],"id":52671551}],"con":true,"img":false}]}
{"op":"mcm","clk":"11450311987","pt":1717320459060,"mc":[{"id":"1.229554918","rc":[{"atb":[[6.4,0],[7.4,0],[5.2,24.88],[5.7,0]],"id":52671555},{"atb":[[65,0],[36,0],[46,0],[28,0]],"id":52671554},{"atb":[[3.8,0],[3.55,95.64],[3.3,0],[3.05,0]],"id":52671553}],"con":true,"img":false}]}
{"op":"mcm","clk":"11450312024","pt":1717320459735,"mc":[{"id":"1.229554918","rc":[{"atb":[[5.8,16.35],[5.3,24.33],[7.6,3.97],[6.6,9.34]],"id":52671555},{"atb":[[34,2.38],[44,1.22],[27,4.02],[60,0.44]],"id":52671554},{"atb":[[3.4,32.7],[3.15,48.67],[3.9,9.02],[3.65,19.74]],"id":52671553}],"con":true,"img":false}]}
{"op":"mcm","clk":"11450312140","pt":1717320461910,"mc":[{"id":"1.229554918","rc":[{"atb":[[4.1,32.26]],"id":52671555},{"atb":[[2.8,0],[3.15,95.18]],"id":52671553}],"con":true,"img":false}]}
{"op":"mcm","clk":"11450312143","pt":1717320462011,"mc":[{"id":"1.229554918","rc":[{"atb":[[2.94,51.55]],"id":52237628},{"atb":[[3.7,0]],"id":52671555}],"con":true,"img":false}]}
{"op":"mcm","clk":"11450312149","pt":1717320462114,"mc":[{"id":"1.229554918","rc":[{"atb":[[2.62,0]],"id":52237628}],"con":true,"img":false}]}
{"op":"mcm","clk":"11450312275","pt":1717320464242,"mc":[{"id":"1.229554918","rc":[{"atb":[[2.62,59.8],[2.94,0]],"id":52237628},{"atb":[[4.1,0],[3.7,37.04]],"id":52671555},{"atb":[[1.5,0],[1.31,112.52]],"id":52671546},{"atb":[[36,0],[40,2.56]],"id":52671560},{"atb":[[2.8,55.56],[3.15,48.67]],"id":52671553}],"con":true,"img":false}]}
{"op":"mcm","clk":"11450312290","pt":1717320464554,"mc":[{"id":"1.229554918","rc":[{"atb":[[4.5,0],[5,0],[5.5,0],[6,0]],"id":52237628},{"atb":[[32,0],[18,0],[21,0],[26,0]],"id":52671565}],"con":true,"img":false}]}
{"op":"mcm","clk":"11450312336","pt":1717320465260,"mc":[{"id":"1.229554918","rc":[{"atb":[[4.8,13.77],[4.3,23.78],[5.3,6.08],[3.9,36.08]],"id":52237628},{"atb":[[17,6.54],[19.5,4.24],[24,2.28],[29,0.94]],"id":52671565}],"con":true,"img":false}]}
{"op":"mcm","clk":"11450312496","pt":1717320467034,"mc":[{"id":"1.229554918","rc":[{"atb":[[750,0],[810,2.1]],"id":52671561}],"con":true,"img":false}]}
{"op":"mcm","clk":"11450312650","pt":1717320470259,"mc":[{"id":"1.229554918","rc":[{"atb":[[2.62,0],[2.94,51.55]],"id":52237628},{"atb":[[750,2],[810,0.1]],"id":52671561},{"atb":[[4.1,32.26],[3.7,0]],"id":52671555},{"atb":[[1.5,112.52],[1.31,0]],"id":52671546},{"atb":[[2.8,0],[3.15,95.18]],"id":52671553}],"con":true,"img":false}]}
{"op":"mcm","clk":"11450312714","pt":1717320471247,"mc":[{"id":"1.229554918","rc":[{"atb":[[750,0],[780,2]],"id":52671561}],"con":true,"img":false}]}
{"op":"mcm","clk":"11450312813","pt":1717320472954,"mc":[{"id":"1.229554918","rc":[{"atb":[[2.62,61.73],[2.94,0]],"id":52237628},{"atb":[[4.1,0],[3.7,37.04]],"id":52671555},{"atb":[[1.5,0],[1.31,112.52]],"id":52671546},{"atb":[[2.8,55.56],[3.15,48.67]],"id":52671553}],"con":true,"img":false}]}
{"op":"mcm","clk":"11450313222","pt":1717320480647,"mc":[{"id":"1.229554918","rc":[{"atl":[[220,2],[230,0]],"id":52237628},{"atl":[[240,2],[250,0]],"id":52671553}],"con":true,"img":false}]}
{"op":"mcm","clk":"11450313237","pt":1717320480958,"mc":[{"id":"1.229554918","rc":[{"atb":[[5.8,0],[5.3,0],[7.6,0],[6.6,0]],"id":52671555},{"atb":[[2.86,0],[3.4,0],[3.15,0],[2.96,0]],"id":52671546},{"atb":[[6.8,0],[4.9,0],[5.9,0],[5.4,23.75]],"id":52671556},{"atb":[[3.4,0],[3.15,0],[3.9,0],[3.65,0]],"id":52671553}],"con":true,"img":false}]}
{"op":"mcm","clk":"11450313291","pt":1717320481851,"mc":[{"id":"1.229554918","rc":[{"atb":[[6.4,9.69],[7.4,4.09],[5.2,49.8],[5.7,16.69]],"id":52671555},{"atb":[[2.54,33.98],[2.64,15.95],[2.44,54.5],[2.34,78.08]],"id":52671546},{"atb":[[4.8,27.54],[5.8,10.9],[5.3,18.25],[6.6,4.67]],"id":52671556},{"atb":[[3.45,21.36],[3.2,35.67],[3.7,9.69],[2.98,52.85]],"id":52671553}],"con":true,"img":false}]}
{"op":"mcm","clk":"11450313504","pt":1717320485438,"mc":[{"id":"1.229554918","rc":[{"atl":[[230,2],[240,0]],"id":52671553}],"con":true,"img":false}]}
{"op":"mcm","clk":"11450313936","pt":1717320493496,"mc":[{"id":"1.229554918","rc":[{"atb":[[780,0],[810,2.1]],"id":52671561}],"con":true,"img":false}]}
{"op":"mcm","clk":"11450313973","pt":1717320493979,"mc":[{"id":"1.229554918","rc":[{"atb":[[2.92,0],[3.3,0]],"id":52237628},{"atb":[[85,0],[44,0]],"id":52671563},{"atb":[[13.5,0],[9.4,0]],"id":52671565},{"atb":[[550,0],[650,0]],"id":52671561},{"atb":[[5.2,24.91],[4.2,0]],"id":52671555},{"atb":[[8.6,0],[11.5,0]],"id":52237624},{"atb":[[4.4,0],[5.4,0]],"id":52237612},{"atb":[[19,0],[14,0]],"id":52671550},{"atb":[[10,0],[15,7.48]],"id":52671552},{"atb":[[2.56,0],[2.76,0]],"id":52671546},{"atb":[[590,0],[490,0]],"id":52671548},{"atb":[[42,0],[26,0]],"id":52671542},{"atb":[[7.2,0],[9.2,0]],"id":52671544},{"atb":[[17.5,0],[25,0]],"id":52237627},{"atb":[[38,0],[24,0]],"id":52671562},{"atb":[[110,2],[55,0]],"id":52671564},{"atb":[[7.2,0],[9.2,0]],"id":52237621},{"atb":[[19.5,0],[14.5,0]],"id":52671560},{"atb":[[18,0],[13,0]],"id":52671554},{"atb":[[4.4,29.41],[5.4,0]],"id":52671556},{"atb":[[9.8,0],[14.5,0]],"id":52671551},{"atb":[[4.1,0],[3.55,0]],"id":52671553},{"atb":[[300,0],[200,0.13]],"id":52671547},{"atb":[[95,0],[48,0]],"id":52237617},{"atb":[[550,0],[650,0]],"id":52671549},{"atb":[[7.4,0],[5.7,0]],"id":52671543},{"atb":[[9,0],[12.5,0]],"id":52237634},{"atb":[[7.4,0],[9.4,0]],"id":52671545}],"con":true,"img":false}]}
{"op":"mcm","clk":"11450313979","pt":1717320494080,"mc":[{"id":"1.229554918","rc":[{"atb":[[150,2.35],[170,0]],"id":52671547},{"atb":[[270,0],[260,2.2]],"id":52671549}],"con":true,"img":false}]}
{"op":"mcm","clk":"11450314293","pt":1717320499199,"mc":[{"id":"1.229554918","rc":[{"atb":[[100,2.8]],"id":52671547},{"atb":[[210,2.38]],"id":52671549}],"con":true,"img":false}]}
{"op":"mcm","clk":"11450314298","pt":1717320499298,"mc":[{"id":"1.229554918","rc":[{"atb":[[150,0.35]],"id":52671547},{"atb":[[260,0.2]],"id":52671549}],"con":true,"img":false}]}
{"op":"mcm","clk":"11450315896","pt":1717320523241,"mc":[{"id":"1.229554918","rc":[{"atb":[[2.9,128.37],[3.25,46.45]],"id":52237628},{"atb":[[80,2.32],[42,5.94]],"id":52671563},{"atb":[[9.2,29.74],[13,8.71]],"id":52671565},{"atb":[[550,0.44],[650,0.16]],"id":52671561},{"atb":[[5.1,25.49],[4.1,78.68]],"id":52671555},{"atb":[[8.6,32.09],[11.5,9.95]],"id":52237624},{"atb":[[4.5,69.68],[5.5,23.22]],"id":52237612},{"atb":[[19,5.8],[14,18.76]],"id":52671550},{"atb":[[10.5,25.67],[15.5,7.2]],"id":52671552},{"atb":[[2.56,156.35],[2.76,59.39]],"id":52671546},{"atb":[[580,0.18],[480,0.5]],"id":52671548},{"atb":[[42,2.54],[26,9.75]],"id":52671542},{"atb":[[7.2,39.33],[9.2,12.74]],"id":52671544},{"atb":[[17.5,14.77],[25,4.35]],"id":52237627},{"atb":[[38,2.82],[24,10.6]],"id":52671562},{"atb":[[150,0.7],[75,3.29]],"id":52671564},{"atb":[[7.2,39.33],[9.2,12.74]],"id":52237621},{"atb":[[19.5,5.65],[14.5,18.06]],"id":52671560},{"atb":[[18.5,5.97],[13.5,19.51]],"id":52671554},{"atb":[[5.6,22.72],[4.6,67.75]],"id":52671556},{"atb":[[9.8,27.71],[14.5,7.74]],"id":52671551},{"atb":[[3.45,120.91],[3.95,35.43]],"id":52671553},{"atb":[[290,0.36],[190,1.29]],"id":52671547},{"atb":[[95,1.11],[48,5.18]],"id":52237617},{"atb":[[550,0.44],[650,0.16]],"id":52671549},{"atb":[[7.4,16.33],[5.7,51.89]],"id":52671543},{"atb":[[9.2,29.74],[13,8.71]],"id":52237634},{"atb":[[8,34.84],[10,11.61]],"id":52671545}],"con":true,"img":false}]}
{"op":"mcm","clk":"11450315917","pt":1717320523399,"mc":[{"id":"1.229554918","rc":[{"atb":[[130,2.41],[110,0]],"id":52671564},{"atb":[[170,2],[100,0.8]],"id":52671547},{"atb":[[270,2],[210,0.38]],"id":52671549}],"con":true,"img":false}]}
{"op":"mcm","clk":"11450323980","pt":1717320539715,"mc":[{"id":"1.229554918","rc":[{"atl":[[210,2],[220,0]],"id":52237628},{"atl":[[310,2]],"id":52671555},{"atl":[[70,0],[60,2]],"id":52671546},{"atl":[[350,0],[340,2]],"id":52671556}],"con":true,"img":false}]}
{"op":"mcm","clk":"11450323991","pt":1717320539826,"mc":[{"id":"1.229554918","rc":[{"atl":[[320,0]],"id":52671555}],"con":true,"img":false}]}
{"op":"mcm","clk":"11450324176","pt":1717320542159,"mc":[{"id":"1.229554918","rc":[{"atl":[[220,2],[230,0]],"id":52671553}],"con":true,"img":false}]}
{"op":"mcm","clk":"11450324796","pt":1717320549758,"mc":[{"id":"1.229554918","rc":[{"atb":[[6.4,0],[7.4,0],[5.2,0],[5.7,0]],"id":52671555}],"con":true,"img":false}]}
{"op":"mcm","clk":"11450324804","pt":1717320549861,"mc":[{"id":"1.229554918","rc":[{"atb":[[2.9,0],[3.25,0]],"id":52237628},{"atb":[[80,0.99],[42,0]],"id":52671563},{"atb":[[9.2,0],[13,0]],"id":52671565},{"atb":[[550,0],[650,0]],"id":52671561},{"atb":[[5.1,0],[4.1,0]],"id":52671555},{"atb":[[8.6,0],[11.5,0]],"id":52237624},{"atb":[[4.5,0],[5.5,0]],"id":52237612},{"atb":[[19,0],[14,0]],"id":52671550},{"atb":[[10.5,0],[15.5,0]],"id":52671552},{"atb":[[2.56,0],[2.76,0]],"id":52671546},{"atb":[[580,0],[480,0]],"id":52671548},{"atb":[[42,0],[26,0]],"id":52671542},{"atb":[[7.2,0],[9.2,0]],"id":52671544},{"atb":[[17.5,0],[25,0]],"id":52237627},{"atb":[[38,0],[24,0]],"id":52671562},{"atb":[[150,0],[75,0]],"id":52671564},{"atb":[[7.2,0],[9.2,0]],"id":52237621},{"atb":[[19.5,0],[14.5,0]],"id":52671560},{"atb":[[18.5,0],[13.5,0]],"id":52671554},{"atb":[[5.6,0],[4.6,0]],"id":52671556},{"atb":[[9.8,0],[14.5,0]],"id":52671551},{"atb":[[3.45,21.36],[3.95,0]],"id":52671553},{"atb":[[290,0],[190,0]],"id":52671547},{"atb":[[95,0],[48,0]],"id":52237617},{"atb":[[550,0],[650,0]],"id":52671549},{"atb":[[7.4,0],[5.7,0]],"id":52671543},{"atb":[[9.2,0],[13,0]],"id":52237634},{"atb":[[8,0],[10,0]],"id":52671545}],"con":true,"img":false}]}
{"op":"mcm","clk":"11450324812","pt":1717320549962,"mc":[{"id":"1.229554918","rc":[{"atb":[[130,0.41],[90,2.88]],"id":52671564},{"atb":[[150,2.35],[170,0]],"id":52671547},{"atb":[[270,0],[260,2.2]],"id":52671549}],"con":true,"img":false}]}
{"op":"mcm","clk":"11450324819","pt":1717320550071,"mc":[{"id":"1.229554918","rc":[{"atb":[[100,2.8]],"id":52671547},{"atb":[[260,0.2],[210,2.38]],"id":52671549}],"con":true,"img":false}]}
{"op":"mcm","clk":"11450324828","pt":1717320550125,"mc":[{"id":"1.229554918","rc":[{"atb":[[150,0.35]],"id":52671547}],"con":true,"img":false}]}
{"op":"mcm","clk":"11450324854","pt":1717320550438,"mc":[{"id":"1.229554918","rc":[{"atb":[[5.6,17.06],[7.2,4.22],[5.1,25.52],[6.2,10.06]],"id":52671555}],"con":true,"img":false}]}
{"op":"mcm","clk":"11450326242","pt":1717320567768,"mc":[{"id":"1.229554918","rc":[{"atb":[[3.1,49.77],[2.84,132.55]],"id":52237628},{"atb":[[55,6.45],[110,0.95]],"id":52671563},{"atb":[[9.2,29.74],[13,8.71]],"id":52671565},{"atb":[[550,0.44],[650,0.16]],"id":52671561},{"atb":[[3.95,82.67],[4.9,26.8]],"id":52671555},{"atb":[[9.2,29.74],[13,8.71]],"id":52237624},{"atb":[[4.9,62.54],[5.9,21.33]],"id":52237612},{"atb":[[18.5,5.97],[13.5,19.51]],"id":52671550},{"atb":[[16.5,6.74],[11.5,23.22]],"id":52671552},{"atb":[[2.72,60.77],[2.52,160.46]],"id":52671546},{"atb":[[550,0.44],[650,0.16]],"id":52671548},{"atb":[[50,2.13],[30,8.41]],"id":52671542},{"atb":[[9.6,12.15],[7.6,36.95]],"id":52671544},{"atb":[[18.5,13.93],[27,4.01]],"id":52237627},{"atb":[[44,4.87],[27,9.38]],"id":52671562},{"atb":[[210,0.5],[110,2.23]],"id":52671564},{"atb":[[9.6,12.15],[7.6,36.95]],"id":52237621},{"atb":[[21,5.22],[15.5,16.82]],"id":52671560},{"atb":[[19,5.8],[14,18.76]],"id":52671554},{"atb":[[4.4,101.14],[5.4,23.75]],"id":52671556},{"atb":[[10,27.1],[15,7.46]],"id":52671551},{"atb":[[3.85,36.67],[3.35,103.78]],"id":52671553},{"atb":[[270,0.9],[370,0.28]],"id":52671547},{"atb":[[140,0.75],[70,3.53]],"id":52237617},{"atb":[[550,0.44],[650,0.16]],"id":52671549},{"atb":[[8,14.93],[6,48.78]],"id":52671543},{"atb":[[9.6,28.36],[14,8.04]],"id":52237634},{"atb":[[11,10.45],[8.4,32.96]],"id":52671545}],"con":true,"img":false}]}
{"op":"mcm","clk":"11450326264","pt":1717320567975,"mc":[{"id":"1.229554918","rc":[{"atb":[[130,2.41],[90,0.88]],"id":52671564},{"atb":[[170,2],[100,0.8]],"id":52671547},{"atb":[[140,2.75],[110,0]],"id":52237617},{"atb":[[270,2],[210,0.38]],"id":52671549}],"con":true,"img":false}]}
{"op":"mcm","clk":"11450326358","pt":1717320569171,"mc":[{"id":"1.229554918","rc":[{"atl":[[210,2],[220,0]],"id":52671553}],"con":true,"img":false}]}
{"op":"mcm","clk":"11450326389","pt":1717320569584,"mc":[{"id":"1.229554918","rc":[{"atl":[[190,2],[210,0]],"id":52237628}],"con":true,"img":false}]}
{"op":"mcm","clk":"11450326501","pt":1717320571082,"mc":[{"id":"1.229554918","rc":[{"atb":[[3.45,0],[3.2,0],[3.7,0],[2.98,0]],"id":52671553}],"con":true,"img":false}]}
{"op":"mcm","clk":"11450326553","pt":1717320571752,"mc":[{"id":"1.229554918","rc":[{"atb":[[3.45,10.68],[3.2,23.78],[2.88,55.66],[2.98,39.64]],"id":52671553}],"con":true,"img":false}]}
{"op":"mcm","clk":"11450328501","pt":1717320599615,"mc":[{"id":"1.229554918","rc":[{"atl":[[180,2],[190,0]],"id":52237628}],"con":true,"img":false}]}
{"op":"mcm","clk":"11450328976","pt":1717320604967,"mc":[{"id":"1.229554918","rc":[{"atb":[[3.1,0],[2.84,0]],"id":52237628},{"atb":[[110,0],[55,1.94]],"id":52671563},{"atb":[[9.2,0],[13,0]],"id":52671565},{"atb":[[550,0],[650,0]],"id":52671561},{"atb":[[3.95,0],[4.9,0]],"id":52671555},{"atb":[[9.2,0],[13,0]],"id":52237624},{"atb":[[4.9,0],[5.9,0]],"id":52237612},{"atb":[[18.5,0],[13.5,0]],"id":52671550},{"atb":[[16.5,0],[11.5,0]],"id":52671552},{"atb":[[2.72,0],[2.52,0]],"id":52671546},{"atb":[[550,0],[650,0]],"id":52671548},{"atb":[[50,0],[30,0]],"id":52671542},{"atb":[[9.6,0],[7.6,0]],"id":52671544},{"atb":[[18.5,0],[27,0]],"id":52237627},{"atb":[[44,2.43],[27,0]],"id":52671562},{"atb":[[210,0],[110,0]],"id":52671564},{"atb":[[9.6,0],[7.6,0]],"id":52237621},{"atb":[[21,0],[15.5,0]],"id":52671560},{"atb":[[19,0],[14,0]],"id":52671554},{"atb":[[4.4,29.41],[5.4,0]],"id":52671556},{"atb":[[10,0],[15,0]],"id":52671551},{"atb":[[3.85,0],[3.35,0]],"id":52671553},{"atb":[[270,0],[370,0]],"id":52671547},{"atb":[[140,2],[70,0]],"id":52237617},{"atb":[[550,0],[650,0]],"id":52671549},{"atb":[[8,0],[6,0]],"id":52671543},{"atb":[[9.6,0],[14,0]],"id":52237634},{"atb":[[11,0],[8.4,0]],"id":52671545}],"con":true,"img":false}]}
{"op":"mcm","clk":"11450328982","pt":1717320605069,"mc":[{"id":"1.229554918","rc":[{"atb":[[130,0.41],[90,2.88]],"id":52671564},{"atb":[[150,2.35],[170,0]],"id":52671547},{"atb":[[270,0],[260,2.2]],"id":52671549}],"con":true,"img":false}]}
{"op":"mcm","clk":"11450329355","pt":1717320610163,"mc":[{"id":"1.229554918","rc":[{"atb":[[150,0.35],[100,2.8]],"id":52671547},{"atb":[[260,0.2],[210,2.38]],"id":52671549}],"con":true,"img":false}]}
{"op":"mcm","clk":"11450330409","pt":1717320623700,"mc":[{"id":"1.229554918","rc":[{"atb":[[550,0.44],[650,0.16]],"id":52671561},{"atb":[[6.8,18.02],[5.4,55.43]],"id":52237612},{"atb":[[17,6.53],[12,22.17]],"id":52671550},{"atb":[[2.56,67],[2.36,179.33]],"id":52671546},{"atb":[[550,0.44],[650,0.16]],"id":52671548},{"atb":[[50,2.13],[30,8.41]],"id":52671542},{"atb":[[9.2,29.74],[13,8.71]],"id":52671544},{"atb":[[19.5,13.18],[29,7.47]],"id":52671560},{"atb":[[18,12.3],[13,20.32]],"id":52671551},{"atb":[[350,0.29],[250,0.97]],"id":52671547},{"atb":[[150,0.7],[75,3.29]],"id":52237617},{"atb":[[550,0.44],[650,0.16]],"id":52671549},{"atb":[[6.4,45.16],[8.4,28.27]],"id":52671543},{"atb":[[13.5,8.36],[9.4,29.03]],"id":52671545}],"con":true,"img":false}]}
{"op":"mcm","clk":"11450330628","pt":1717320625982,"mc":[{"id":"1.229554918","rc":[{"atb":[[170,2],[100,0.8]],"id":52671547},{"atb":[[270,2],[210,0.38]],"id":52671549}],"con":true,"img":false}]}
{"op":"mcm","clk":"11450331245","pt":1717320633290,"mc":[{"id":"1.229554918","rc":[{"atb":[[19,0],[23,0]],"id":52237624},{"atb":[[17.5,0],[20,0],[25,0],[15,0]],"id":52237621}],"con":true,"img":false}]}
{"op":"mcm","clk":"11450331262","pt":1717320633498,"mc":[{"id":"1.229554918","rc":[{"atb":[[29,3.73]],"id":52671560}],"con":true,"img":false}]}
{"op":"mcm","clk":"11450331271","pt":1717320633604,"mc":[{"id":"1.229554918","rc":[{"atb":[[70,0],[38,0],[48,0]],"id":52671560}],"con":true,"img":false}]}
{"op":"mcm","clk":"11450331279","pt":1717320633703,"mc":[{"id":"1.229554918","rc":[{"atb":[[150,0],[200,0]],"id":52671563},{"atb":[[40,0],[30,3.45]],"id":52671560},{"atb":[[11,0],[13.5,0],[8.4,14.12],[9.4,0]],"id":52671543}],"con":true,"img":false}]}
{"op":"mcm","clk":"11450331305","pt":1717320634018,"mc":[{"id":"1.229554918","rc":[{"atb":[[22,4.98],[27,3.02]],"id":52237624},{"atb":[[32,0.84],[18,6.15],[21,3.92],[26,2.09]],"id":52237621}],"con":true,"img":false}]}
{"op":"mcm","clk":"11450331321","pt":1717320634180,"mc":[{"id":"1.229554918","rc":[{"atb":[[8,0],[9,0],[10,0],[12.5,0]],"id":52237612},{"atb":[[34,3.17]],"id":52671560},{"atb":[[42,0]],"id":52237634}],"con":true,"img":false}]}
{"op":"mcm","clk":"11450331330","pt":1717320634287,"mc":[{"id":"1.229554918","rc":[{"atb":[[85,0.31],[44,1.83],[60,0.88]],"id":52671560}],"con":true,"img":false}]}
{"op":"mcm","clk":"11450331344","pt":1717320634448,"mc":[{"id":"1.229554918","rc":[{"atb":[[2.74,140.17],[2.94,53.88]],"id":52237628},{"atb":[[550,0.18],[190,0.28],[450,0.54],[240,0.11]],"id":52671563},{"atb":[[9.6,28.36],[14,15.73]],"id":52671565},{"atb":[[5.2,24.88],[4.2,76.22]],"id":52671555},{"atb":[[10,27.1],[15,7.46]],"id":52237624},{"atb":[[7.2,0],[7,16.67]],"id":52237612},{"atb":[[18.5,5.97],[13.5,19.51]],"id":52671552},{"atb":[[48,2.22],[29,8.71]],"id":52237627},{"atb":[[65,5.8],[130,0.81]],"id":52671562},{"atb":[[550,0.44],[650,0.16]],"id":52671564},{"atb":[[9.8,11.87],[7.8,35.86]],"id":52237621},{"atb":[[36,2.86],[30,0]],"id":52671560},{"atb":[[18.5,13.93],[27,8.04]],"id":52671554},{"atb":[[5.6,22.72],[4.6,67.75]],"id":52671556},{"atb":[[3.55,40.99],[3.05,118.97]],"id":52671553},{"atb":[[16,1.74],[11,7.85],[13.5,4.19],[9.4,12.46]],"id":52671543},{"atb":[[16,6.96],[11,24.39],[23,0],[25,4.17]],"id":52237634}],"con":true,"img":false}]}
{"op":"mcm","clk":"11450331358","pt":1717320634601,"mc":[{"id":"1.229554918","rc":[{"atb":[[65,3.8],[85,2.62]],"id":52671562},{"atb":[[140,2],[90,0.88]],"id":52671564}],"con":true,"img":false}]}
{"op":"mcm","clk":"11450331382","pt":1717320634919,"mc":[{"id":"1.229554918","rc":[{"atb":[[12,4.76],[9.8,8.92],[8.8,13.41],[14.5,1.94]],"id":52237612},{"atb":[[55,0.49]],"id":52237634}],"con":true,"img":false}]}
{"op":"mcm","clk":"11450333258","pt":1717320660105,"mc":[{"id":"1.229554918","rc":[{"atb":[[140,0],[70,0],[95,0],[48,0]],"id":52671542},{"atb":[[17,0],[19.5,0],[12,0],[14.5,0]],"id":52671544}],"con":true,"img":false}]}
{"op":"mcm","clk":"11450333267","pt":1717320660260,"mc":[{"id":"1.229554918","rc":[{"atb":[[75,0],[50,4.17]],"id":52671542}],"con":true,"img":false}]}
{"op":"mcm","clk":"11450333276","pt":1717320660323,"mc":[{"id":"1.229554918","rc":[{"atb":[[32,3.23],[50,2.13]],"id":52671542}],"con":true,"img":false}]}
{"op":"mcm","clk":"11450333309","pt":1717320660743,"mc":[{"id":"1.229554918","rc":[{"atb":[[2.74,0],[2.94,0]],"id":52237628},{"atb":[[550,0],[450,0]],"id":52671563},{"atb":[[9.6,0],[14,7.69]],"id":52671565},{"atb":[[550,0],[650,0]],"id":52671561},{"atb":[[5.2,0],[4.2,0]],"id":52671555},{"atb":[[10,0],[15,0]],"id":52237624},{"atb":[[6.8,0],[5.4,0]],"id":52237612},{"atb":[[17,0],[12,0]],"id":52671550},{"atb":[[18.5,0],[13.5,0]],"id":52671552},{"atb":[[2.56,0],[2.36,0]],"id":52671546},{"atb":[[550,0],[650,0]],"id":52671548},{"atb":[[50,0],[30,0]],"id":52671542},{"atb":[[9.2,0],[13,0]],"id":52671544},{"atb":[[48,0],[29,0]],"id":52237627},{"atb":[[130,0],[65,0]],"id":52671562},{"atb":[[550,0],[650,0]],"id":52671564},{"atb":[[9.8,0],[7.8,0]],"id":52237621},{"atb":[[19.5,0],[29,0]],"id":52671560},{"atb":[[18.5,0],[27,4.02]],"id":52671554},{"atb":[[5.6,0],[4.6,0]],"id":52671556},{"atb":[[18,6.15],[13,0]],"id":52671551},{"atb":[[3.55,0],[3.05,0]],"id":52671553},{"atb":[[350,0],[250,0]],"id":52671547},{"atb":[[150,0],[75,0]],"id":52237617},{"atb":[[550,0],[650,0]],"id":52671549},{"atb":[[6.4,0],[8.4,0]],"id":52671543},{"atb":[[16,0],[11,0]],"id":52237634},{"atb":[[13.5,0],[9.4,0]],"id":52671545}],"con":true,"img":false}]}
{"op":"mcm","clk":"11450333315","pt":1717320660844,"mc":[{"id":"1.229554918","rc":[{"atb":[[160,0.16],[80,0.99],[110,0.48],[55,1.94]],"id":52671542},{"atb":[[18,3.08],[21,1.31],[13,8.72],[15.5,5.41]],"id":52671544},{"atb":[[65,2]],"id":52671562},{"atb":[[130,2.41],[140,0]],"id":52671564},{"atb":[[150,2.35],[170,0]],"id":52671547},{"atb":[[260,2.2]],"id":52671549}],"con":true,"img":false}]}
{"op":"mcm","clk":"11450333324","pt":1717320660945,"mc":[{"id":"1.229554918","rc":[{"atb":[[75,2]],"id":52671542},{"atb":[[85,0.62]],"id":52671562},{"atb":[[130,0.41],[90,2.88]],"id":52671564},{"atb":[[100,2.8]],"id":52671547},{"atb":[[270,0]],"id":52671549}],"con":true,"img":false}]}
{"op":"mcm","clk":"11450333329","pt":1717320661053,"mc":[{"id":"1.229554918","rc":[{"atb":[[32,0]],"id":52671542},{"atb":[[150,0.35]],"id":52671547},{"atb":[[210,2.38]],"id":52671549}],"con":true,"img":false}]}
{"op":"mcm","clk":"11450333336","pt":1717320661156,"mc":[{"id":"1.229554918","rc":[{"atb":[[260,0.2]],"id":52671549}],"con":true,"img":false}]}
{"op":"mcm","clk":"11450333950","pt":1717320668921,"mc":[{"id":"1.229554918","rc":[{"atb":[[32,0],[18,0],[21,0],[26,0]],"id":52671551}],"con":true,"img":false}]}
{"op":"mcm","clk":"11450334017","pt":1717320669646,"mc":[{"id":"1.229554918","rc":[{"atb":[[36,0.75],[19,5.81],[23,3.57],[28,1.94]],"id":52671551}],"con":true,"img":false}]}
