{"op":"mcm","clk":"11449075389","pt":1717303241532,"mc":[{"id":"1.229554903","marketDefinition":{"bspMarket":false,"turnInPlayEnabled":false,"persistenceEnabled":false,"marketBaseRate":7.0,"eventId":"33318908","eventTypeId":"4339","numberOfWinners":1,"bettingType":"ODDS","marketType":"QUINELLA","marketTime":"2024-06-02T08:59:00.000Z","suspendTime":"2024-06-02T08:59:00.000Z","bspReconciled":false,"complete":true,"inPlay":false,"crossMatching":true,"runnersVoidable":false,"numberOfActiveRunners":15,"betDelay":0,"status":"OPEN","runners":[{"status":"ACTIVE","sortPriority":1,"id":52671542,"name":"1 - 2 / 2 - 1"},{"status":"ACTIVE","sortPriority":2,"id":52671544,"name":"1 - 4 / 4 - 1"},{"status":"ACTIVE","sortPriority":3,"id":52237612,"name":"1 - 5 / 5 - 1"},{"status":"ACTIVE","sortPriority":4,"id":52671560,"name":"1 - 7 / 7 - 1"},{"status":"ACTIVE","sortPriority":5,"id":52671546,"name":"1 - 8 / 8 - 1"},{"status":"ACTIVE","sortPriority":6,"id":52671548,"name":"2 - 4 / 4 - 2"},{"status":"ACTIVE","sortPriority":7,"id":52237617,"name":"2 - 5 / 5 - 2"},{"status":"ACTIVE","sortPriority":8,"id":52671561,"name":"2 - 7 / 7 - 2"},{"status":"ACTIVE","sortPriority":9,"id":52671550,"name":"2 - 8 / 8 - 2"},{"status":"ACTIVE","sortPriority":10,"id":52237624,"name":"4 - 5 / 5 - 4"},{"status":"ACTIVE","sortPriority":11,"id":52671563,"name":"4 - 7 / 7 - 4"},{"status":"ACTIVE","sortPriority":12,"id":52671555,"name":"4 - 8 / 8 - 4"},{"status":"ACTIVE","sortPriority":13,"id":52237627,"name":"5 - 7 / 7 - 5"},{"status":"ACTIVE","sortPriority":14,"id":52237628,"name":"5 - 8 / 8 - 5"},{"status":"ACTIVE","sortPriority":15,"id":52671565,"name":"7 - 8 / 8 - 7"}],"regulators":["MR_INT"],"venue":"Murray Bridge","countryCode":"AU","discountAllowed":true,"timezone":"Australia/Adelaide","openDate":"2024-06-02T08:21:00.000Z","version":5962801937,"name":"Quinella","eventName":"Murray Bridge (AUS) 2nd Jun"},"rc":[],"con":true,"img":false}]}
{"op":"mcm","clk":"11449095056","pt":1717303714149,"mc":[{"id":"1.229554903","rc":[{"atb":[[4.6,7.27],[4.1,16.88],[3.8,28.03],[3.55,41.03]],"id":52237628},{"atb":[[17,6.54],[19.5,4.24],[24,2.28],[29,0.94]],"id":52237627},{"atb":[[34,2.38],[44,1.22],[27,4.02],[60,0.44]],"id":52671563},{"atb":[[34,2.38],[44,1.22],[27,4.02],[60,0.44]],"id":52671565},{"atb":[[530,0.05],[380,0.28],[430,0.18],[480,0.11]],"id":52671561},{"atb":[[36,1.5],[46,0.58],[23,4.76],[28,2.91]],"id":52671560},{"atb":[[6.8,13.53],[8.8,3.35],[7.8,7.7],[5.9,21.36]],"id":52671555},{"atb":[[2.36,38.47],[2.46,17.92],[2.26,62.28],[2.16,90.2]],"id":52237612},{"atb":[[32,3.37],[80,0.33],[42,1.92],[55,0.97]],"id":52671550},{"atb":[[5,26.16],[5.5,17.44],[6,10.46],[7,4.36]],"id":52671546},{"atb":[[38,0.71],[19.5,5.66],[24,3.41],[29,1.87]],"id":52237617},{"atb":[[75,0.36],[40,2.01],[50,1.07],[30,3.61]],"id":52671548},{"atb":[[34,2.38],[44,1.22],[27,4.02],[60,0.44]],"id":52671542},{"atb":[[6.8,4.51],[4.9,26.83],[5.9,10.68],[5.4,17.84]],"id":52671544}],"con":true,"img":false}]}
{"op":"mcm","clk":"11449095072","pt":1717303714618,"mc":[{"id":"1.229554903","rc":[{"atb":[[2.06,74.03],[1.98,106.77],[2.26,20.76],[2.16,45.1]],"id":52237624}],"con":true,"img":false}]}
{"op":"mcm","clk":"11449096085","pt":1717303745645,"mc":[{"id":"1.229554903","rc":[{"atb":[[32,0],[80,0],[42,0],[55,0]],"id":52671550},{"atb":[[5,0],[5.5,0],[6,0],[7,0]],"id":52671546}],"con":true,"img":false}]}
{"op":"mcm","clk":"11449096118","pt":1717303746464,"mc":[{"id":"1.229554903","rc":[{"atb":[[75,0.36],[40,2.01],[50,1.07],[30,3.61]],"id":52671550},{"atb":[[5.6,17.06],[7.2,4.22],[5.1,25.52],[6.2,10.06]],"id":52671546}],"con":true,"img":false}]}
{"op":"mcm","clk":"11449099376","pt":1717303849458,"mc":[{"id":"1.229554903","rc":[{"atb":[[17.5,6.33],[12.5,21.2]],"id":52671560},{"atb":[[2.56,156.35],[2.76,59.39]],"id":52237612},{"atb":[[4.1,33.71],[3.55,95.64]],"id":52671546},{"atb":[[9.8,27.71],[14.5,7.74]],"id":52237617},{"atb":[[19.5,5.65],[14.5,18.06]],"id":52671548},{"atb":[[18,6.14],[13,20.32]],"id":52671542},{"atb":[[3.4,101.62],[3.9,36.04]],"id":52671544}],"con":true,"img":false}]}
{"op":"mcm","clk":"11449099382","pt":1717303849562,"mc":[{"id":"1.229554903","rc":[{"atb":[[2.82,134.01],[3.05,50.98]],"id":52237628},{"atb":[[9.6,28.36],[14,8.04]],"id":52237627},{"atb":[[19,5.8],[14,18.76]],"id":52671563},{"atb":[[19.5,5.65],[14.5,18.06]],"id":52671565},{"atb":[[550,0.44],[650,0.16]],"id":52671561},{"atb":[[2.96,53.33],[2.76,138.58]],"id":52237624},{"atb":[[4.8,27.5],[3.9,84.1]],"id":52671555},{"atb":[[20,5.5],[15,17.42]],"id":52671550}],"con":true,"img":false}]}
{"op":"mcm","clk":"11449099414","pt":1717303850537,"mc":[{"id":"1.229554903","rc":[{"atb":[[2.06,0],[1.98,0],[2.26,0],[2.16,0]],"id":52237624}],"con":true,"img":false}]}
{"op":"mcm","clk":"11449099433","pt":1717303851207,"mc":[{"id":"1.229554903","rc":[{"atb":[[2.06,74.03],[1.98,106.77],[2.26,20.76],[2.16,45.1]],"id":52237624}],"con":true,"img":false}]}
{"op":"mcm","clk":"11449116455","pt":1717304319309,"mc":[{"id":"1.229554903","rc":[{"atb":[[75,0],[40,0],[50,0],[30,0]],"id":52671550},{"atb":[[5.6,0],[7.2,0],[5.1,0],[6.2,0]],"id":52671546}],"con":true,"img":false}]}
{"op":"mcm","clk":"11449116489","pt":1717304320027,"mc":[{"id":"1.229554903","rc":[{"atb":[[32,3.37],[80,0.33],[42,1.92],[55,0.97]],"id":52671550},{"atb":[[5,26.16],[5.5,17.44],[6,10.46],[7,4.36]],"id":52671546}],"con":true,"img":false}]}
{"op":"mcm","clk":"11449182626","pt":1717305248480,"mc":[{"id":"1.229554903","rc":[{"atb":[[4.6,0],[4.1,0],[3.8,0],[3.55,0]],"id":52237628},{"atb":[[2.36,0],[2.46,0],[2.26,0],[2.16,0]],"id":52237612}],"con":true,"img":false}]}
{"op":"mcm","clk":"11449182688","pt":1717305249358,"mc":[{"id":"1.229554903","rc":[{"atb":[[3.45,42.71],[3.95,17.74],[3.7,29.07],[4.4,7.7]],"id":52237628},{"atb":[[2.92,54.5],[3.55,10.26],[3.3,22.75],[3.05,38.28]],"id":52237612}],"con":true,"img":false}]}
{"op":"mcm","clk":"11449189800","pt":1717305345818,"mc":[{"id":"1.229554903","rc":[{"atb":[[2.06,0],[1.98,0],[2.26,0],[2.16,0]],"id":52237624}],"con":true,"img":false}]}
{"op":"mcm","clk":"11449189847","pt":1717305346541,"mc":[{"id":"1.229554903","rc":[{"atb":[[2.74,60.13],[3.1,12.46],[2.84,42.65],[2.94,26.97]],"id":52237624}],"con":true,"img":false}]}
{"op":"mcm","clk":"11449276413","pt":1717306536602,"mc":[{"id":"1.229554903","rc":[{"atb":[[34,0],[44,0],[27,0],[60,0]],"id":52671565}],"con":true,"img":false}]}
{"op":"mcm","clk":"11449276419","pt":1717306536720,"mc":[{"id":"1.229554903","rc":[{"atb":[[38,0],[19.5,0],[24,0],[29,0]],"id":52237617},{"atb":[[75,0],[40,0],[50,0],[30,0]],"id":52671548}],"con":true,"img":false}]}
{"op":"mcm","clk":"11449276431","pt":1717306536808,"mc":[{"id":"1.229554903","rc":[{"atb":[[17,0],[19.5,0],[24,0],[29,0]],"id":52237627},{"atb":[[530,0],[380,0],[430,0],[480,0]],"id":52671561},{"atb":[[36,0],[46,0],[23,0],[28,0]],"id":52671560},{"atb":[[32,0],[80,0],[42,0],[55,0]],"id":52671550},{"atb":[[5,0],[5.5,0],[6,0],[7,0]],"id":52671546},{"atb":[[34,0],[44,0],[27,0],[60,0]],"id":52671542}],"con":true,"img":false}]}
{"op":"mcm","clk":"11449276468","pt":1717306537270,"mc":[{"id":"1.229554903","rc":[{"atb":[[65,0.41],[36,2.24],[46,1.16],[28,3.88]],"id":52671565}],"con":true,"img":false}]}
{"op":"mcm","clk":"11449276478","pt":1717306537374,"mc":[{"id":"1.229554903","rc":[{"atb":[[40,0.67],[20,5.51],[25,3.27],[30,1.81]],"id":52237617},{"atb":[[32,3.37],[80,0.33],[42,1.92],[55,0.97]],"id":52671548}],"con":true,"img":false}]}
{"op":"mcm","clk":"11449276487","pt":1717306537475,"mc":[{"id":"1.229554903","rc":[{"atb":[[32,0.84],[18,6.15],[21,3.92],[26,2.09]],"id":52237627},{"atb":[[530,0.15],[580,0.09],[630,0.04],[480,0.22]],"id":52671561},{"atb":[[40,1.34],[50,0.53],[25,4.36],[30,2.71]],"id":52671560}],"con":true,"img":false}]}
{"op":"mcm","clk":"11449276495","pt":1717306537578,"mc":[{"id":"1.229554903","rc":[{"atb":[[34,3.17],[85,0.31],[44,1.83],[60,0.88]],"id":52671550},{"atb":[[5.6,17.06],[7.2,4.22],[5.1,25.52],[6.2,10.06]],"id":52671546},{"atb":[[65,0.41],[36,2.24],[46,1.16],[28,3.88]],"id":52671542}],"con":true,"img":false}]}
{"op":"mcm","clk":"11449281662","pt":1717306604147,"mc":[{"id":"1.229554903","rc":[{"atb":[[3.3,0]],"id":52237612}],"con":true,"img":false}]}
{"op":"mcm","clk":"11449281673","pt":1717306604250,"mc":[{"id":"1.229554903","rc":[{"atb":[[2.92,0],[3.55,0],[3.05,0]],"id":52237612}],"con":true,"img":false}]}
{"op":"mcm","clk":"11449281727","pt":1717306604869,"mc":[{"id":"1.229554903","rc":[{"atb":[[3.35,22.26]],"id":52237612}],"con":true,"img":false}]}
{"op":"mcm","clk":"11449281737","pt":1717306604972,"mc":[{"id":"1.229554903","rc":[{"atb":[[3.6,10.06],[3.1,37.37],[2.94,53.93]],"id":52237612}],"con":true,"img":false}]}
{"op":"mcm","clk":"11449342311","pt":1717307456955,"mc":[{"id":"1.229554903","rc":[{"atb":[[3.45,0],[3.95,0],[3.7,0],[4.4,0]],"id":52237628},{"atb":[[32,0],[18,0],[21,0],[26,0]],"id":52237627},{"atb":[[65,0],[36,0],[46,0],[28,0]],"id":52671565},{"atb":[[530,0],[580,0],[630,0],[480,0]],"id":52671561},{"atb":[[2.74,0],[3.1,0],[2.84,0],[2.94,0]],"id":52237624},{"atb":[[6.8,0],[8.8,0],[7.8,0],[5.9,0]],"id":52671555},{"atb":[[34,0],[85,0],[44,0],[60,0]],"id":52671550}],"con":true,"img":false}]}
{"op":"mcm","clk":"11449342358","pt":1717307457623,"mc":[{"id":"1.229554903","rc":[{"atb":[[34,2.38],[44,1.22],[27,4.02],[60,0.44]],"id":52671550}],"con":true,"img":false}]}
{"op":"mcm","clk":"11449342364","pt":1717307457726,"mc":[{"id":"1.229554903","rc":[{"atb":[[2.24,84.38],[2.54,16.99],[2.44,36.33],[2.34,58.56]],"id":52237628},{"atb":[[17,6.54],[19.5,4.24],[24,2.28],[29,0.94]],"id":52237627},{"atb":[[17.5,6.34],[20,4.13],[25,2.18],[30,0.9]],"id":52671565},{"atb":[[530,0.05],[380,0.28],[430,0.18],[480,0.11]],"id":52671561},{"atb":[[3.45,42.71],[3.95,17.74],[3.7,29.07],[4.4,7.7]],"id":52237624},{"atb":[[6.8,9.02],[7.8,3.85],[5.9,16.01],[5.4,23.78]],"id":52671555}],"con":true,"img":false}]}
{"op":"mcm","clk":"11449367045","pt":1717308032562,"mc":[{"id":"1.229554903","rc":[{"atb":[[2.82,0],[3.05,0]],"id":52237628},{"atb":[[9.6,0],[14,0]],"id":52237627},{"atb":[[19,0],[14,0]],"id":52671563},{"atb":[[19.5,0],[14.5,0]],"id":52671565},{"atb":[[550,0],[650,0]],"id":52671561},{"atb":[[17.5,0],[12.5,0]],"id":52671560},{"atb":[[4.8,0],[3.9,0]],"id":52671555},{"atb":[[2.96,0],[2.76,0]],"id":52237624},{"atb":[[2.56,0],[2.76,0]],"id":52237612},{"atb":[[20,0],[15,0]],"id":52671550},{"atb":[[4.1,0],[3.55,0]],"id":52671546},{"atb":[[9.8,0],[14.5,0]],"id":52237617},{"atb":[[19.5,0],[14.5,0]],"id":52671548},{"atb":[[18,0],[13,0]],"id":52671542},{"atb":[[3.4,0],[3.9,0]],"id":52671544}],"con":true,"img":false}]}
{"op":"mcm","clk":"11449367317","pt":1717308038674,"mc":[{"id":"1.229554903","rc":[{"atb":[[2.82,134.01],[3.05,50.98]],"id":52237628},{"atb":[[9.6,28.36],[14,8.04]],"id":52237627},{"atb":[[19,5.8],[14,18.76]],"id":52671563},{"atb":[[19.5,5.65],[14.5,18.06]],"id":52671565},{"atb":[[550,0.44],[650,0.16]],"id":52671561},{"atb":[[17.5,6.33],[12.5,21.2]],"id":52671560},{"atb":[[2.96,53.33],[2.76,138.58]],"id":52237624},{"atb":[[4.8,27.5],[3.9,84.1]],"id":52671555},{"atb":[[2.56,156.35],[2.76,59.39]],"id":52237612},{"atb":[[20,5.5],[15,17.42]],"id":52671550},{"atb":[[9.8,27.71],[14.5,7.74]],"id":52237617},{"atb":[[4.1,33.71],[3.55,95.64]],"id":52671546},{"atb":[[19.5,5.65],[14.5,18.06]],"id":52671548},{"atb":[[18,6.14],[13,20.32]],"id":52671542},{"atb":[[3.4,101.62],[3.9,36.04]],"id":52671544}],"con":true,"img":false}]}
{"op":"mcm","clk":"11449437351","pt":1717309126726,"mc":[{"id":"1.229554903","rc":[{"atb":[[2.82,0],[3.05,0]],"id":52237628},{"atb":[[9.6,0],[14,0]],"id":52237627},{"atb":[[19,0],[14,0]],"id":52671563},{"atb":[[19.5,0],[14.5,0]],"id":52671565},{"atb":[[550,0],[650,0]],"id":52671561},{"atb":[[17.5,0],[12.5,0]],"id":52671560},{"atb":[[4.8,0],[3.9,0]],"id":52671555},{"atb":[[2.96,0],[2.76,0]],"id":52237624},{"atb":[[2.56,0],[2.76,0]],"id":52237612},{"atb":[[20,0],[15,0]],"id":52671550},{"atb":[[4.1,0],[3.55,0]],"id":52671546},{"atb":[[9.8,0],[14.5,0]],"id":52237617},{"atb":[[19.5,0],[14.5,0]],"id":52671548},{"atb":[[18,0],[13,0]],"id":52671542},{"atb":[[3.4,0],[3.9,0]],"id":52671544}],"con":true,"img":false}]}
{"op":"mcm","clk":"11449438870","pt":1717309151566,"mc":[{"id":"1.229554903","rc":[{"atb":[[2.82,134.01],[3.05,50.98]],"id":52237628},{"atb":[[9.6,28.36],[14,8.04]],"id":52237627},{"atb":[[19,5.8],[14,18.76]],"id":52671563},{"atb":[[19.5,5.65],[14.5,18.06]],"id":52671565},{"atb":[[550,0.44],[650,0.16]],"id":52671561},{"atb":[[4.8,27.5],[3.9,84.1]],"id":52671555},{"atb":[[2.96,53.33],[2.76,138.58]],"id":52237624},{"atb":[[20,5.5],[15,17.42]],"id":52671550}],"con":true,"img":false}]}
{"op":"mcm","clk":"11449438877","pt":1717309151673,"mc":[{"id":"1.229554903","rc":[{"atb":[[17.5,6.33],[12.5,21.2]],"id":52671560},{"atb":[[2.56,156.35],[2.76,59.39]],"id":52237612},{"atb":[[9.8,27.71],[14.5,7.74]],"id":52237617},{"atb":[[4.1,33.71],[3.55,95.64]],"id":52671546},{"atb":[[19.5,5.65],[14.5,18.06]],"id":52671548},{"atb":[[18,6.14],[13,20.32]],"id":52671542},{"atb":[[3.4,101.62],[3.9,36.04]],"id":52671544}],"con":true,"img":false}]}
{"op":"mcm","clk":"11449439219","pt":1717309156544,"mc":[{"id":"1.229554903","rc":[{"atb":[[17.5,0],[20,0],[25,0],[30,0]],"id":52671565},{"atb":[[530,0],[380,0],[430,0],[480,0]],"id":52671561},{"atb":[[40,0],[50,0],[25,0],[30,0]],"id":52671560},{"atb":[[3.6,0],[3.1,0],[3.35,0],[2.94,0]],"id":52237612},{"atb":[[34,0],[44,0],[27,0],[60,0]],"id":52671550},{"atb":[[5.6,0],[7.2,0],[5.1,0],[6.2,0]],"id":52671546},{"atb":[[65,0],[36,0],[46,0],[28,0]],"id":52671542},{"atb":[[6.8,0],[4.9,0],[5.9,0],[5.4,0]],"id":52671544}],"con":true,"img":false}]}
{"op":"mcm","clk":"11449439228","pt":1717309156647,"mc":[{"id":"1.229554903","rc":[{"atb":[[6.8,0],[7.8,0],[5.9,0],[5.4,0]],"id":52671555}],"con":true,"img":false}]}
{"op":"mcm","clk":"11449439265","pt":1717309157266,"mc":[{"id":"1.229554903","rc":[{"atb":[[17.5,6.34],[20,4.13],[25,2.18],[30,0.9]],"id":52671565},{"atb":[[140,0.75],[290,0.09],[190,0.41],[240,0.22]],"id":52671561},{"atb":[[20,11.01],[40,0.67],[25,3.27],[30,1.81]],"id":52671550}],"con":true,"img":false}]}
{"op":"mcm","clk":"11449439272","pt":1717309157371,"mc":[{"id":"1.229554903","rc":[{"atb":[[3.95,26.6],[3.7,38.75],[4.9,6.71],[4.4,15.39]],"id":52671555}],"con":true,"img":false}]}
{"op":"mcm","clk":"11449439383","pt":1717309159282,"mc":[{"id":"1.229554903","rc":[{"atb":[[140,0],[290,0],[190,0],[240,0]],"id":52671561},{"atb":[[40,0],[20,5.5],[25,0],[30,0]],"id":52671550}],"con":true,"img":false}]}
{"op":"mcm","clk":"11449439402","pt":1717309159437,"mc":[{"id":"1.229554903","rc":[{"atb":[[17.5,0],[20,0],[25,0],[30,0]],"id":52671565}],"con":true,"img":false}]}
{"op":"mcm","clk":"11449439438","pt":1717309159955,"mc":[{"id":"1.229554903","rc":[{"atb":[[140,0.75],[290,0.09],[190,0.41],[240,0.22]],"id":52671561},{"atb":[[20,11.01],[40,0.67],[25,3.27],[30,1.81]],"id":52671550}],"con":true,"img":false}]}
{"op":"mcm","clk":"11449439451","pt":1717309160160,"mc":[{"id":"1.229554903","rc":[{"atb":[[17.5,6.34],[20,4.13],[25,2.18],[30,0.9]],"id":52671565}],"con":true,"img":false}]}
{"op":"mcm","clk":"11449440769","pt":1717309180863,"mc":[{"id":"1.229554903","rc":[{"atb":[[2.24,0],[2.54,0],[2.44,0],[2.34,0]],"id":52237628},{"atb":[[17,0],[19.5,0],[24,0],[29,0]],"id":52237627},{"atb":[[17.5,0],[20,0],[25,0],[30,0]],"id":52671565},{"atb":[[40,0],[20,0],[25,0],[30,0]],"id":52237617}],"con":true,"img":false}]}
{"op":"mcm","clk":"11449440811","pt":1717309181587,"mc":[{"id":"1.229554903","rc":[{"atb":[[1.79,99.34],[1.89,29.39],[1.84,62.28],[1.74,141.4]],"id":52237628},{"atb":[[16,1.74],[11,7.85],[13.5,4.19],[9.4,12.46]],"id":52237627},{"atb":[[17.5,3.17],[20,1.38],[12.5,9.1],[15,5.6]],"id":52671565},{"atb":[[16,3.49],[18.5,1.5],[11,10.46],[13.5,6.28]],"id":52237617}],"con":true,"img":false}]}
{"op":"mcm","clk":"11449442393","pt":1717309206794,"mc":[{"id":"1.229554903","rc":[{"atb":[[2.82,0],[3.05,0]],"id":52237628},{"atb":[[9.6,0],[14,0]],"id":52237627},{"atb":[[19,0],[14,0]],"id":52671563},{"atb":[[19.5,0],[14.5,0]],"id":52671565},{"atb":[[550,0],[650,0]],"id":52671561},{"atb":[[17.5,0],[12.5,0]],"id":52671560},{"atb":[[4.8,0],[3.9,0]],"id":52671555},{"atb":[[2.96,0],[2.76,0]],"id":52237624},{"atb":[[2.56,0],[2.76,0]],"id":52237612},{"atb":[[20,5.51],[15,0]],"id":52671550},{"atb":[[9.8,0],[14.5,0]],"id":52237617},{"atb":[[4.1,0],[3.55,0]],"id":52671546},{"atb":[[19.5,0],[14.5,0]],"id":52671548},{"atb":[[18,0],[13,0]],"id":52671542},{"atb":[[3.4,0],[3.9,0]],"id":52671544}],"con":true,"img":false}]}
{"op":"mcm","clk":"11449443363","pt":1717309221125,"mc":[{"id":"1.229554903","rc":[{"atb":[[2.9,55.01],[2.7,143.47]],"id":52237628},{"atb":[[11,18.3],[8.4,32.96]],"id":52237627},{"atb":[[16.5,6.74],[11.5,23.22]],"id":52671563},{"atb":[[17,6.53],[12,22.17]],"id":52671565},{"atb":[[540,0.44],[640,0.16]],"id":52671561},{"atb":[[17,6.53],[12,22.17]],"id":52671560},{"atb":[[2.88,55.6],[2.68,145.18]],"id":52237624},{"atb":[[4.6,29.03],[3.8,87.1]],"id":52671555},{"atb":[[2.9,55.01],[2.7,143.47]],"id":52237612},{"atb":[[18.5,5.97],[13.5,19.51]],"id":52671550},{"atb":[[3.85,85.58],[4.7,28.25]],"id":52671546},{"atb":[[9.2,29.74],[13,8.71]],"id":52237617},{"atb":[[18.5,5.97],[13.5,19.51]],"id":52671548},{"atb":[[18.5,5.97],[13.5,19.51]],"id":52671542},{"atb":[[4.6,29.03],[3.8,87.1]],"id":52671544}],"con":true,"img":false}]}
{"op":"mcm","clk":"11449447232","pt":1717309280770,"mc":[{"id":"1.229554903","marketDefinition":{"bspMarket":false,"turnInPlayEnabled":false,"persistenceEnabled":false,"marketBaseRate":7.0,"eventId":"33318908","eventTypeId":"4339","numberOfWinners":1,"bettingType":"ODDS","marketType":"QUINELLA","marketTime":"2024-06-02T08:59:00.000Z","suspendTime":"2024-06-02T08:59:00.000Z","bspReconciled":false,"complete":true,"inPlay":false,"crossMatching":true,"runnersVoidable":false,"numberOfActiveRunners":15,"betDelay":0,"status":"SUSPENDED","runners":[{"status":"ACTIVE","sortPriority":1,"id":52671542,"name":"1 - 2 / 2 - 1"},{"status":"ACTIVE","sortPriority":2,"id":52671544,"name":"1 - 4 / 4 - 1"},{"status":"ACTIVE","sortPriority":3,"id":52237612,"name":"1 - 5 / 5 - 1"},{"status":"ACTIVE","sortPriority":4,"id":52671560,"name":"1 - 7 / 7 - 1"},{"status":"ACTIVE","sortPriority":5,"id":52671546,"name":"1 - 8 / 8 - 1"},{"status":"ACTIVE","sortPriority":6,"id":52671548,"name":"2 - 4 / 4 - 2"},{"status":"ACTIVE","sortPriority":7,"id":52237617,"name":"2 - 5 / 5 - 2"},{"status":"ACTIVE","sortPriority":8,"id":52671561,"name":"2 - 7 / 7 - 2"},{"status":"ACTIVE","sortPriority":9,"id":52671550,"name":"2 - 8 / 8 - 2"},{"status":"ACTIVE","sortPriority":10,"id":52237624,"name":"4 - 5 / 5 - 4"},{"status":"ACTIVE","sortPriority":11,"id":52671563,"name":"4 - 7 / 7 - 4"},{"status":"ACTIVE","sortPriority":12,"id":52671555,"name":"4 - 8 / 8 - 4"},{"status":"ACTIVE","sortPriority":13,"id":52237627,"name":"5 - 7 / 7 - 5"},{"status":"ACTIVE","sortPriority":14,"id":52237628,"name":"5 - 8 / 8 - 5"},{"status":"ACTIVE","sortPriority":15,"id":52671565,"name":"7 - 8 / 8 - 7"}],"regulators":["MR_INT"],"venue":"Murray Bridge","countryCode":"AU","discountAllowed":true,"timezone":"Australia/Adelaide","openDate":"2024-06-02T08:21:00.000Z","version":5962889460,"name":"Quinella","eventName":"Murray Bridge (AUS) 2nd Jun"},"rc":[],"con":true,"img":false}]}
{"op":"mcm","clk":"11449449004","pt":1717309308129,"mc":[{"id":"1.229554903","marketDefinition":{"bspMarket":false,"turnInPlayEnabled":false,"persistenceEnabled":false,"marketBaseRate":7.0,"eventId":"33318908","eventTypeId":"4339","numberOfWinners":1,"bettingType":"ODDS","marketType":"QUINELLA","marketTime":"2024-06-02T08:59:00.000Z","suspendTime":"2024-06-02T08:59:00.000Z","bspReconciled":false,"complete":true,"inPlay":false,"crossMatching":false,"runnersVoidable":false,"numberOfActiveRunners":15,"betDelay":0,"status":"SUSPENDED","runners":[{"status":"ACTIVE","sortPriority":1,"id":52671542,"name":"1 - 2 / 2 - 1"},{"status":"ACTIVE","sortPriority":2,"id":52671544,"name":"1 - 4 / 4 - 1"},{"status":"ACTIVE","sortPriority":3,"id":52237612,"name":"1 - 5 / 5 - 1"},{"status":"ACTIVE","sortPriority":4,"id":52671560,"name":"1 - 7 / 7 - 1"},{"status":"ACTIVE","sortPriority":5,"id":52671546,"name":"1 - 8 / 8 - 1"},{"status":"ACTIVE","sortPriority":6,"id":52671548,"name":"2 - 4 / 4 - 2"},{"status":"ACTIVE","sortPriority":7,"id":52237617,"name":"2 - 5 / 5 - 2"},{"status":"ACTIVE","sortPriority":8,"id":52671561,"name":"2 - 7 / 7 - 2"},{"status":"ACTIVE","sortPriority":9,"id":52671550,"name":"2 - 8 / 8 - 2"},{"status":"ACTIVE","sortPriority":10,"id":52237624,"name":"4 - 5 / 5 - 4"},{"status":"ACTIVE","sortPriority":11,"id":52671563,"name":"4 - 7 / 7 - 4"},{"status":"ACTIVE","sortPriority":12,"id":52671555,"name":"4 - 8 / 8 - 4"},{"status":"ACTIVE","sortPriority":13,"id":52237627,"name":"5 - 7 / 7 - 5"},{"status":"ACTIVE","sortPriority":14,"id":52237628,"name":"5 - 8 / 8 - 5"},{"status":"ACTIVE","sortPriority":15,"id":52671565,"name":"7 - 8 / 8 - 7"}],"regulators":["MR_INT"],"venue":"Murray Bridge","countryCode":"AU","discountAllowed":true,"timezone":"Australia/Adelaide","openDate":"2024-06-02T08:21:00.000Z","version":5962890000,"name":"Quinella","eventName":"Murray Bridge (AUS) 2nd Jun"},"rc":[],"con":true,"img":false}]}
{"op":"mcm","clk":"11449449004","pt":1717309308129,"mc":[{"id":"1.229554903","rc":[{"atb":[[1.79,0],[2.9,0],[1.89,0],[1.84,0],[1.74,0],[2.7,0]],"id":52237628},{"atb":[[16,0],[11,0],[13.5,0],[8.4,0],[9.4,0]],"id":52237627},{"atb":[[16.5,0],[34,0],[44,0],[11.5,0],[27,0],[60,0]],"id":52671563},{"atb":[[17.5,0],[17,0],[20,0],[12,0],[12.5,0],[15,0]],"id":52671565},{"atb":[[540,0],[140,0],[290,0],[640,0],[190,0],[240,0]],"id":52671561},{"atb":[[17,0],[12,0]],"id":52671560},{"atb":[[4.6,0],[3.95,0],[3.7,0],[3.8,0],[4.9,0],[4.4,0]],"id":52671555},{"atb":[[3.45,0],[2.88,0],[3.95,0],[3.7,0],[4.4,0],[2.68,0]],"id":52237624},{"atb":[[2.9,0],[2.7,0]],"id":52237612},{"atb":[[18.5,0],[40,0],[20,0],[25,0],[13.5,0],[30,0]],"id":52671550},{"atb":[[16,0],[18.5,0],[9.2,0],[11,0],[13,0],[13.5,0]],"id":52237617},{"atb":[[3.85,0],[4.7,0]],"id":52671546},{"atb":[[32,0],[18.5,0],[80,0],[42,0],[55,0],[13.5,0]],"id":52671548},{"atb":[[18.5,0],[13.5,0]],"id":52671542},{"atb":[[4.6,0],[3.8,0]],"id":52671544}],"con":true,"img":false}]}
{"op":"mcm","clk":"11449449051","pt":1717309308821,"mc":[{"id":"1.229554903","marketDefinition":{"bspMarket":false,"turnInPlayEnabled":false,"persistenceEnabled":false,"marketBaseRate":7.0,"eventId":"33318908","eventTypeId":"4339","numberOfWinners":1,"bettingType":"ODDS","marketType":"QUINELLA","marketTime":"2024-06-02T08:59:00.000Z","suspendTime":"2024-06-02T08:59:00.000Z","bspReconciled":false,"complete":true,"inPlay":false,"crossMatching":false,"runnersVoidable":false,"numberOfActiveRunners":0,"betDelay":0,"status":"CLOSED","settledTime":"2024-06-02T06:21:47.000Z","runners":[{"status":"REMOVED","sortPriority":1,"removalDate":"2024-06-02T06:21:47.000Z","id":52671542,"name":"1 - 2 / 2 - 1"},{"status":"REMOVED","sortPriority":2,"removalDate":"2024-06-02T06:21:47.000Z","id":52671544,"name":"1 - 4 / 4 - 1"},{"status":"REMOVED","sortPriority":3,"removalDate":"2024-06-02T06:21:47.000Z","id":52237612,"name":"1 - 5 / 5 - 1"},{"status":"REMOVED","sortPriority":4,"removalDate":"2024-06-02T06:21:47.000Z","id":52671560,"name":"1 - 7 / 7 - 1"},{"status":"REMOVED","sortPriority":5,"removalDate":"2024-06-02T06:21:47.000Z","id":52671546,"name":"1 - 8 / 8 - 1"},{"status":"REMOVED","sortPriority":6,"removalDate":"2024-06-02T06:21:47.000Z","id":52671548,"name":"2 - 4 / 4 - 2"},{"status":"REMOVED","sortPriority":7,"removalDate":"2024-06-02T06:21:47.000Z","id":52237617,"name":"2 - 5 / 5 - 2"},{"status":"REMOVED","sortPriority":8,"removalDate":"2024-06-02T06:21:47.000Z","id":52671561,"name":"2 - 7 / 7 - 2"},{"status":"REMOVED","sortPriority":9,"removalDate":"2024-06-02T06:21:47.000Z","id":52671550,"name":"2 - 8 / 8 - 2"},{"status":"REMOVED","sortPriority":10,"removalDate":"2024-06-02T06:21:47.000Z","id":52237624,"name":"4 - 5 / 5 - 4"},{"status":"REMOVED","sortPriority":11,"removalDate":"2024-06-02T06:21:47.000Z","id":52671563,"name":"4 - 7 / 7 - 4"},{"status":"REMOVED","sortPriority":12,"removalDate":"2024-06-02T06:21:47.000Z","id":52671555,"name":"4 - 8 / 8 - 4"},{"status":"REMOVED","sortPriority":13,"removalDate":"2024-06-02T06:21:47.000Z","id":52237627,"name":"5 - 7 / 7 - 5"},{"status":"REMOVED","sortPriority":14,"removalDate":"2024-06-02T06:21:47.000Z","id":52237628,"name":"5 - 8 / 8 - 5"},{"status":"REMOVED","sortPriority":15,"removalDate":"2024-06-02T06:21:47.000Z","id":52671565,"name":"7 - 8 / 8 - 7"}],"regulators":["MR_INT"],"venue":"Murray Bridge","countryCode":"AU","discountAllowed":true,"timezone":"Australia/Adelaide","openDate":"2024-06-02T08:21:00.000Z","version":5962890004,"name":"Quinella","eventName":"Murray Bridge (AUS) 2nd Jun"},"rc":[],"con":true,"img":false}]}
