{"op":"mcm","clk":"11448127644","pt":1717286034979,"mc":[{"id":"1.229554915","marketDefinition":{"bspMarket":true,"turnInPlayEnabled":false,"persistenceEnabled":false,"marketBaseRate":7.0,"eventId":"33318908","eventTypeId":"4339","numberOfWinners":1,"bettingType":"ODDS","marketType":"WIN","marketTime":"2024-06-02T10:03:00.000Z","suspendTime":"2024-06-02T10:03:00.000Z","bspReconciled":false,"complete":true,"inPlay":false,"crossMatching":true,"runnersVoidable":false,"numberOfActiveRunners":8,"betDelay":0,"status":"OPEN","runners":[{"status":"ACTIVE","sortPriority":1,"id":65293046,"name":"1. Beast Cut Loose"},{"status":"ACTIVE","sortPriority":2,"id":42099039,"name":"2. Thatll Do Neo"},{"status":"ACTIVE","sortPriority":3,"id":70003370,"name":"3. Ki Ki"},{"status":"ACTIVE","sortPriority":4,"id":56606596,"name":"4. Senna Wick"},{"status":"ACTIVE","sortPriority":5,"id":46292327,"name":"5. Immense"},{"status":"ACTIVE","sortPriority":6,"id":65788088,"name":"6. Bundy Baz"},{"status":"ACTIVE","sortPriority":7,"id":51562794,"name":"7. Chasing Boyd"},{"status":"ACTIVE","sortPriority":8,"id":64927898,"name":"8. Tilley Swamp"}],"regulators":["MR_INT"],"venue":"Murray Bridge","countryCode":"AU","discountAllowed":true,"timezone":"Australia/Adelaide","openDate":"2024-06-02T08:21:00.000Z","version":5962317635,"name":"R6 455m Gr4/5","eventName":"Murray Bridge (AUS) 2nd Jun"},"rc":[],"con":true,"img":false}]}
{"op":"mcm","clk":"11448260604","pt":1717287908538,"mc":[{"id":"1.229554915","rc":[{"atb":[[5.8,43.55],[7.6,15.83],[6.6,37.33]],"id":46292327},{"atl":[[75,1.88],[150,1.4]],"id":46292327},{"spn":41.3,"spf":"NaN","id":46292327},{"atb":[[5.8,43.55],[7.6,15.83],[6.6,37.33]],"id":65788088},{"atl":[[75,1.88],[150,1.4]],"id":65788088},{"spn":41.3,"spf":"NaN","id":65788088},{"atb":[[2.58,132.31],[2.78,58.72],[2.68,124.44]],"id":65293046},{"atl":[[13.5,16.72],[9.4,16.58]],"id":65293046},{"spn":6.09,"spf":"NaN","id":65293046},{"atb":[[4.8,55.01],[4.3,63.35],[5.3,24.31]],"id":70003370},{"atl":[[44,4.86],[27,5.36]],"id":70003370},{"spn":16.15,"spf":"NaN","id":70003370},{"atb":[[1.98,106.66],[1.88,237.56],[1.93,224.79]],"id":64927898},{"atl":[[6.2,26.8],[8.2,29.03]],"id":64927898},{"spn":4.09,"spf":"NaN","id":64927898}],"con":true,"img":false}]}
{"op":"mcm","clk":"11448262192","pt":1717287930135,"mc":[{"id":"1.229554915","rc":[{"atb":[[5.8,0],[7.6,0],[6.6,0]],"id":46292327},{"atl":[[75,0],[150,0]],"id":46292327},{"atb":[[5.8,0],[7.6,0],[6.6,0]],"id":65788088},{"atl":[[75,0],[150,0]],"id":65788088},{"atb":[[2.58,0],[2.78,0],[2.68,0]],"id":65293046},{"atl":[[13.5,0],[9.4,0]],"id":65293046},{"atb":[[4.8,0],[4.3,0],[5.3,0]],"id":70003370},{"atl":[[44,0],[27,0]],"id":70003370},{"atb":[[1.98,0],[1.88,0],[1.93,0]],"id":64927898},{"atl":[[6.2,0],[8.2,0]],"id":64927898}],"con":true,"img":false}]}
{"op":"mcm","clk":"11448262804","pt":1717287939632,"mc":[{"id":"1.229554915","rc":[{"atb":[[17,13.06],[19.5,11.3],[24,4.54]],"id":51562794},{"atl":[[340,0.41],[440,0.47]],"id":51562794},{"atb":[[5.8,43.55],[7.6,15.83],[6.6,37.33]],"id":46292327},{"atl":[[75,1.88],[150,1.4]],"id":46292327},{"atb":[[5.8,43.55],[5.3,48.61],[6.6,18.66]],"id":56606596},{"atl":[[95,2.22],[48,2.96]],"id":56606596},{"atb":[[5.8,43.55],[7.6,15.83],[6.6,37.33]],"id":65788088},{"atl":[[75,1.88],[150,1.4]],"id":65788088},{"atb":[[38,2.82],[24,9.08],[29,7.46]],"id":42099039},{"atl":[[550,0.38],[450,0.3]],"id":42099039},{"atb":[[2.58,132.31],[2.78,58.72],[2.68,124.44]],"id":65293046},{"atl":[[13.5,16.72],[9.4,16.58]],"id":65293046},{"atb":[[4.8,55.01],[4.3,63.35],[5.3,24.31]],"id":70003370},{"atl":[[44,4.86],[27,5.36]],"id":70003370},{"atb":[[1.83,251.88],[1.88,237.56],[1.93,112.39]],"id":64927898},{"atl":[[5.6,30.29],[7.2,33.71]],"id":64927898}],"con":true,"img":false}]}
{"op":"mcm","clk":"11448266386","pt":1717287995255,"mc":[{"id":"1.229554915","rc":[{"atb":[[17,0],[19.5,0],[24,0]],"id":51562794},{"atl":[[340,0],[440,0]],"id":51562794},{"spn":"NaN","spf":"NaN","id":51562794},{"atb":[[5.8,0],[7.6,0],[6.6,0]],"id":46292327},{"atl":[[75,0],[150,0]],"id":46292327},{"spn":"NaN","spf":"NaN","id":46292327},{"atb":[[5.8,0],[5.3,0],[6.6,0]],"id":56606596},{"atl":[[95,0],[48,0]],"id":56606596},{"spn":"NaN","spf":"NaN","id":56606596},{"atb":[[5.8,0],[7.6,0],[6.6,0]],"id":65788088},{"atl":[[75,0],[150,0]],"id":65788088},{"spn":"NaN","spf":"NaN","id":65788088},{"atb":[[38,0],[24,0],[29,0]],"id":42099039},{"atl":[[550,0],[450,0]],"id":42099039},{"spn":"NaN","spf":"NaN","id":42099039},{"atb":[[2.58,0],[2.78,0],[2.68,0]],"id":65293046},{"atl":[[13.5,0],[9.4,0]],"id":65293046},{"spn":"NaN","spf":"NaN","id":65293046},{"atb":[[4.8,0],[4.3,0],[5.3,0]],"id":70003370},{"atl":[[44,0],[27,0]],"id":70003370},{"spn":"NaN","spf":"NaN","id":70003370},{"atb":[[1.83,0],[1.88,0],[1.93,0]],"id":64927898},{"atl":[[5.6,0],[7.2,0]],"id":64927898},{"spn":"NaN","spf":"NaN","id":64927898}],"con":true,"img":false}]}
{"op":"mcm","clk":"11448266886","pt":1717288003942,"mc":[{"id":"1.229554915","rc":[{"atb":[[17.5,12.67],[20,11],[25,4.35]],"id":51562794},{"atl":[[350,0.39],[450,0.46]],"id":51562794},{"atb":[[5.8,43.55],[7.6,15.83],[6.6,37.33]],"id":46292327},{"atl":[[75,1.88],[150,1.4]],"id":46292327},{"atb":[[5.8,43.55],[5.3,48.61],[6.6,18.66]],"id":56606596},{"atl":[[95,2.22],[48,2.96]],"id":56606596},{"atb":[[5.8,43.55],[7.6,15.83],[6.6,37.33]],"id":65788088},{"atl":[[75,1.88],[150,1.4]],"id":65788088},{"atb":[[19.5,11.3],[24,9.08],[29,3.73]],"id":42099039},{"atl":[[400,0.35],[500,0.41]],"id":42099039},{"atb":[[2.58,132.31],[2.78,58.72],[2.68,124.44]],"id":65293046},{"atl":[[13.5,16.72],[9.4,16.58]],"id":65293046},{"atb":[[4.8,55.01],[4.3,63.35],[5.3,24.31]],"id":70003370},{"atl":[[44,4.86],[27,5.36]],"id":70003370},{"atb":[[1.83,251.88],[1.88,237.56],[1.93,112.39]],"id":64927898},{"atl":[[5.6,30.29],[7.2,33.71]],"id":64927898}],"con":true,"img":false}]}
{"op":"mcm","clk":"11448270142","pt":1717288057229,"mc":[{"id":"1.229554915","rc":[{"atb":[[17.5,0],[20,0],[25,0]],"id":51562794},{"atl":[[350,0],[450,0]],"id":51562794},{"atb":[[5.8,0],[7.6,0],[6.6,0]],"id":46292327},{"atl":[[75,0],[150,0]],"id":46292327},{"atb":[[5.8,0],[5.3,0],[6.6,0]],"id":56606596},{"atl":[[95,0],[48,0]],"id":56606596},{"atb":[[5.8,0],[7.6,0],[6.6,0]],"id":65788088},{"atl":[[75,0],[150,0]],"id":65788088},{"atb":[[19.5,0],[24,0],[29,0]],"id":42099039},{"atl":[[400,0],[500,0]],"id":42099039},{"atb":[[4.8,0],[4.3,0],[5.3,0]],"id":70003370},{"atl":[[44,0],[27,0]],"id":70003370},{"atb":[[2.58,0],[2.78,0],[2.68,0]],"id":65293046},{"atl":[[13.5,0],[9.4,0]],"id":65293046},{"atb":[[1.83,0],[1.88,0],[1.93,0]],"id":64927898},{"atl":[[5.6,0],[7.2,0]],"id":64927898}],"con":true,"img":false}]}
{"op":"mcm","clk":"11448270978","pt":1717288067734,"mc":[{"id":"1.229554915","rc":[{"atb":[[17.5,12.67],[20,11],[25,4.35]],"id":51562794},{"atl":[[350,0.39],[450,0.46]],"id":51562794},{"atb":[[5.8,43.55],[7.6,15.83],[6.6,37.33]],"id":46292327},{"atl":[[75,1.88],[150,1.4]],"id":46292327},{"atb":[[5.6,45.44],[7.2,16.86],[6.2,40.2]],"id":56606596},{"atl":[[65,2.17],[130,1.62]],"id":56606596},{"atb":[[7.2,33.71],[6.2,40.2],[8.2,14.51]],"id":65788088},{"atl":[[90,1.56],[180,1.16]],"id":65788088},{"atb":[[19.5,11.3],[24,9.08],[29,3.73]],"id":42099039},{"atl":[[400,0.35],[500,0.41]],"id":42099039},{"atb":[[2.8,116.14],[2.9,55.01],[2.7,122.97]],"id":65293046},{"atl":[[10,15.48],[15,14.93]],"id":65293046},{"atb":[[5.6,22.72],[5.1,50.98],[4.6,58.07]],"id":70003370},{"atl":[[46,4.64],[28,5.16]],"id":70003370},{"atb":[[1.79,132.31],[1.74,282.51],[1.69,302.98]],"id":64927898},{"atl":[[4.3,42.23],[5.3,48.61]],"id":64927898}],"con":true,"img":false}]}
{"op":"mcm","clk":"11448277244","pt":1717288128429,"mc":[{"id":"1.229554915","marketDefinition":{"bspMarket":true,"turnInPlayEnabled":false,"persistenceEnabled":false,"marketBaseRate":7.0,"eventId":"33318908","eventTypeId":"4339","numberOfWinners":1,"bettingType":"ODDS","marketType":"WIN","marketTime":"2024-06-02T10:03:00.000Z","suspendTime":"2024-06-02T10:03:00.000Z","bspReconciled":false,"complete":true,"inPlay":false,"crossMatching":true,"runnersVoidable":false,"numberOfActiveRunners":8,"betDelay":0,"status":"OPEN","runners":[{"status":"ACTIVE","sortPriority":1,"id":65293046,"name":"1. Beast Cut Loose"},{"status":"ACTIVE","sortPriority":2,"id":42099039,"name":"2. Thatll Do Neo"},{"status":"ACTIVE","sortPriority":3,"id":70003370,"name":"3. Ki Ki"},{"status":"ACTIVE","sortPriority":4,"id":56606596,"name":"4. Senna Wick"},{"status":"ACTIVE","sortPriority":5,"id":46292327,"name":"5. Immense"},{"status":"ACTIVE","sortPriority":6,"id":65788088,"name":"6. Bundy Baz"},{"status":"ACTIVE","sortPriority":7,"id":51562794,"name":"7. Chasing Boyd"},{"status":"ACTIVE","sortPriority":8,"id":64927898,"name":"8. Tilley Swamp"}],"regulators":["MR_INT"],"venue":"Murray Bridge","countryCode":"AU","discountAllowed":true,"timezone":"Australia/Adelaide","openDate":"2024-06-02T08:21:00.000Z","version":5962317635,"name":"R6 455m Gr4/5","eventName":"Murray Bridge (AUS) 2nd Jun"},"rc":[{"atb":[[17.5,12.67],[20,11],[25,4.35]],"id":51562794},{"atl":[[350,0.39],[450,0.46]],"id":51562794},{"spn":187.5,"spf":"NaN","id":51562794},{"atb":[[5.8,43.55],[7.6,15.83],[6.6,37.33]],"id":46292327},{"atl":[[75,1.88],[150,1.4]],"id":46292327},{"spn":41.3,"spf":"NaN","id":46292327},{"atb":[[5.6,45.44],[7.2,16.86],[6.2,40.2]],"id":56606596},{"atl":[[65,2.17],[130,1.62]],"id":56606596},{"spn":36.1,"spf":"NaN","id":56606596},{"atb":[[7.2,33.71],[6.2,40.2],[8.2,14.51]],"id":65788088},{"atl":[[90,1.56],[180,1.16]],"id":65788088},{"spn":49.1,"spf":"NaN","id":65788088},{"atb":[[19.5,11.3],[24,9.08],[29,3.73]],"id":42099039},{"atl":[[400,0.35],[500,0.41]],"id":42099039},{"spn":214.5,"spf":"NaN","id":42099039},{"atb":[[2.8,116.14],[2.9,55.01],[2.7,122.97]],"id":65293046},{"atl":[[10,15.48],[15,14.93]],"id":65293046},{"spn":6.45,"spf":"NaN","id":65293046},{"atb":[[5.6,22.72],[5.1,50.98],[4.6,58.07]],"id":70003370},{"atl":[[46,4.64],[28,5.16]],"id":70003370},{"spn":16.8,"spf":"NaN","id":70003370},{"atb":[[1.79,132.31],[1.74,282.51],[1.69,302.98]],"id":64927898},{"atl":[[4.3,42.23],[5.3,48.61]],"id":64927898},{"spn":3.04,"spf":"NaN","id":64927898}],"con":true,"img":true}]}
{"op":"mcm","clk":"11448292472","pt":1717288274058,"mc":[{"id":"1.229554915","rc":[{"atb":[[17.5,0],[20,0],[25,0]],"id":51562794},{"atl":[[350,0],[450,0]],"id":51562794},{"atb":[[5.8,0],[7.6,0],[6.6,0]],"id":46292327},{"atl":[[75,0],[150,0]],"id":46292327},{"atb":[[5.6,0],[7.2,0],[6.2,0]],"id":56606596},{"atl":[[65,0],[130,0]],"id":56606596},{"atb":[[7.2,0],[6.2,0],[8.2,0]],"id":65788088},{"atl":[[90,0],[180,0]],"id":65788088},{"atb":[[19.5,0],[24,0],[29,0]],"id":42099039},{"atl":[[400,0],[500,0]],"id":42099039},{"atb":[[2.8,0],[2.9,0],[2.7,0]],"id":65293046},{"atl":[[10,0],[15,0]],"id":65293046},{"atb":[[5.6,0],[5.1,0],[4.6,0]],"id":70003370},{"atl":[[46,0],[28,0]],"id":70003370},{"atb":[[1.79,0],[1.74,0],[1.69,0]],"id":64927898},{"atl":[[4.3,0],[5.3,0]],"id":64927898}],"con":true,"img":false}]}
{"op":"mcm","clk":"11448293804","pt":1717288291623,"mc":[{"id":"1.229554915","rc":[{"atb":[[18,12.29],[21,10.45],[26,4.18]],"id":51562794},{"atl":[[360,0.38],[460,0.45]],"id":51562794},{"atb":[[8.6,13.75],[7.6,31.67],[6.6,37.33]],"id":46292327},{"atl":[[100,1.4],[200,1.05]],"id":46292327},{"atb":[[5.6,45.44],[7.2,16.86],[6.2,40.2]],"id":56606596},{"atl":[[65,2.17],[130,1.62]],"id":56606596},{"atb":[[8.6,13.75],[7.6,31.67],[6.6,37.33]],"id":65788088},{"atl":[[100,1.4],[200,1.05]],"id":65788088},{"atb":[[32,6.74],[42,2.54],[26,8.36]],"id":42099039},{"atl":[[570,0.36],[470,0.29]],"id":42099039},{"atb":[[2.86,112.39],[2.96,53.33],[2.76,118.78]],"id":65293046},{"atl":[[10.5,14.66],[15.5,14.41]],"id":65293046},{"atb":[[5.6,22.72],[5.1,50.98],[4.6,58.07]],"id":70003370},{"atl":[[46,4.64],[28,5.16]],"id":70003370},{"atb":[[1.79,132.31],[1.74,282.51],[1.69,302.98]],"id":64927898},{"atl":[[4.3,42.23],[5.3,48.61]],"id":64927898}],"con":true,"img":false}]}
{"op":"mcm","clk":"11448298280","pt":1717288351487,"mc":[{"id":"1.229554915","rc":[{"atb":[[18,0],[21,0],[26,0]],"id":51562794},{"atl":[[360,0],[460,0]],"id":51562794},{"spn":54.3,"spf":"NaN","id":46292327},{"spn":36.1,"spf":"NaN","id":56606596},{"spn":54.3,"spf":"NaN","id":65788088},{"spn":256.0,"spf":"NaN","id":42099039},{"atb":[[2.86,0],[2.96,0],[2.76,0]],"id":65293046},{"atl":[[10.5,0],[15.5,0]],"id":65293046},{"spn":16.8,"spf":"NaN","id":70003370},{"spn":3.04,"spf":"NaN","id":64927898}],"con":true,"img":false}]}
{"op":"mcm","clk":"11448300795","pt":1717288383947,"mc":[{"id":"1.229554915","rc":[{"atb":[[18,12.29],[21,10.45],[26,4.18]],"id":51562794},{"atl":[[360,0.38],[460,0.45]],"id":51562794},{"atb":[[2.88,111.2],[2.98,52.79],[2.78,117.44]],"id":65293046},{"atl":[[10.5,14.66],[15.5,14.41]],"id":65293046}],"con":true,"img":false}]}
{"op":"mcm","clk":"11448317707","pt":1717288629759,"mc":[{"id":"1.229554915","rc":[{"atb":[[18,0],[21,0],[26,0]],"id":51562794},{"atl":[[360,0],[460,0]],"id":51562794},{"atb":[[8.6,0],[7.6,0],[6.6,0]],"id":46292327},{"atl":[[100,0],[200,0]],"id":46292327},{"spn":"NaN","spf":"NaN","id":46292327},{"atb":[[5.6,0],[7.2,0],[6.2,0]],"id":56606596},{"atl":[[65,0],[130,0]],"id":56606596},{"spn":"NaN","spf":"NaN","id":56606596},{"atb":[[8.6,0],[7.6,0],[6.6,0]],"id":65788088},{"atl":[[100,0],[200,0]],"id":65788088},{"spn":"NaN","spf":"NaN","id":65788088},{"atb":[[32,0],[42,0],[26,0]],"id":42099039},{"atl":[[570,0],[470,0]],"id":42099039},{"spn":"NaN","spf":"NaN","id":42099039},{"atb":[[2.88,0],[2.98,0],[2.78,0]],"id":65293046},{"atl":[[10.5,0],[15.5,0]],"id":65293046},{"atb":[[5.6,0],[5.1,0],[4.6,0]],"id":70003370},{"atl":[[46,0],[28,0]],"id":70003370},{"spn":"NaN","spf":"NaN","id":70003370},{"atb":[[1.79,0],[1.74,0],[1.69,0]],"id":64927898},{"atl":[[4.3,0],[5.3,0]],"id":64927898},{"spn":"NaN","spf":"NaN","id":64927898}],"con":true,"img":false}]}
{"op":"mcm","clk":"11448319059","pt":1717288649295,"mc":[{"id":"1.229554915","rc":[{"atb":[[19.5,11.3],[24,9.08],[29,3.73]],"id":51562794},{"atl":[[400,0.35],[500,0.41]],"id":51562794},{"atb":[[4.8,55.01],[4.3,63.35],[5.3,24.31]],"id":46292327},{"atl":[[44,4.86],[27,5.36]],"id":46292327},{"atb":[[5.8,43.55],[7.6,15.83],[6.6,37.33]],"id":56606596},{"atl":[[75,1.88],[150,1.4]],"id":56606596},{"atb":[[8.6,13.75],[7.6,31.67],[6.6,37.33]],"id":65788088},{"atl":[[100,1.4],[200,1.05]],"id":65788088},{"atb":[[32,6.74],[42,2.54],[26,8.36]],"id":42099039},{"atl":[[570,0.36],[470,0.29]],"id":42099039},{"atb":[[4.8,55.01],[5.8,21.77],[5.3,48.61]],"id":70003370},{"atl":[[48,4.44],[29,4.97]],"id":70003370},{"atb":[[2.88,111.2],[2.98,52.79],[2.78,117.44]],"id":65293046},{"atl":[[10.5,14.66],[15.5,14.41]],"id":65293046},{"atb":[[1.73,143.19],[1.63,331.84],[1.68,307.44]],"id":64927898},{"atl":[[4,46.45],[5,52.26]],"id":64927898}],"con":true,"img":false}]}
{"op":"mcm","clk":"11448321969","pt":1717288687675,"mc":[{"id":"1.229554915","rc":[{"atb":[[19.5,0],[24,0],[29,0]],"id":51562794},{"atl":[[400,0],[500,0]],"id":51562794},{"atb":[[4.8,0],[4.3,0],[5.3,0]],"id":46292327},{"atl":[[44,0],[27,0]],"id":46292327},{"atb":[[5.8,0],[7.6,0],[6.6,0]],"id":56606596},{"atl":[[75,0],[150,0]],"id":56606596},{"atb":[[8.6,0],[7.6,0],[6.6,0]],"id":65788088},{"atl":[[100,0],[200,0]],"id":65788088},{"atb":[[32,0],[42,0],[26,0]],"id":42099039},{"atl":[[570,0],[470,0]],"id":42099039},{"atb":[[4.8,0],[5.8,0],[5.3,0]],"id":70003370},{"atl":[[48,0],[29,0]],"id":70003370},{"atb":[[2.88,0],[2.98,0],[2.78,0]],"id":65293046},{"atl":[[10.5,0],[15.5,0]],"id":65293046},{"atb":[[1.73,0],[1.63,0],[1.68,0]],"id":64927898},{"atl":[[4,0],[5,0]],"id":64927898}],"con":true,"img":false}]}
{"op":"mcm","clk":"11448323056","pt":1717288701352,"mc":[{"id":"1.229554915","rc":[{"atb":[[19.5,11.3],[24,9.08],[29,3.73]],"id":51562794},{"atl":[[400,0.35],[500,0.41]],"id":51562794},{"spn":214.5,"spf":"NaN","id":51562794},{"atb":[[3.6,80.4],[3.85,73.35],[4.2,32.66]],"id":46292327},{"atl":[[32,6.74],[21,6.96]],"id":46292327},{"spn":12.6,"spf":"NaN","id":46292327},{"atb":[[5.8,43.55],[7.6,15.83],[6.6,37.33]],"id":56606596},{"atl":[[75,1.88],[150,1.4]],"id":56606596},{"spn":41.3,"spf":"NaN","id":56606596},{"atb":[[8.6,13.75],[7.6,31.67],[6.6,37.33]],"id":65788088},{"atl":[[100,1.4],[200,1.05]],"id":65788088},{"spn":54.3,"spf":"NaN","id":65788088},{"atb":[[34,6.33],[44,2.43],[27,8.04]],"id":42099039},{"atl":[[580,0.36],[480,0.29]],"id":42099039},{"spn":262.0,"spf":"NaN","id":42099039},{"atb":[[4.8,55.01],[5.8,21.77],[5.3,48.61]],"id":70003370},{"atl":[[48,4.44],[29,4.97]],"id":70003370},{"spn":17.4,"spf":"NaN","id":70003370},{"atb":[[2.88,111.2],[2.98,52.79],[2.78,117.44]],"id":65293046},{"atl":[[10.5,14.66],[15.5,14.41]],"id":65293046},{"spn":6.74,"spf":"NaN","id":65293046},{"atb":[[1.73,143.19],[1.63,331.84],[1.68,307.44]],"id":64927898},{"atl":[[4,46.45],[5,52.26]],"id":64927898},{"spn":2.86,"spf":"NaN","id":64927898}],"con":true,"img":false}]}
{"op":"mcm","clk":"11448325043","pt":1717288727655,"mc":[{"id":"1.229554915","rc":[{"atb":[[3.6,0],[3.85,0],[4.2,0]],"id":46292327},{"atl":[[32,0],[21,0]],"id":46292327},{"atb":[[34,0],[44,0],[27,0]],"id":42099039},{"atl":[[580,0],[480,0]],"id":42099039},{"atb":[[2.88,0],[2.98,0],[2.78,0]],"id":65293046},{"atl":[[10.5,0],[15.5,0]],"id":65293046}],"con":true,"img":false}]}
{"op":"mcm","clk":"11448326201","pt":1717288744502,"mc":[{"id":"1.229554915","rc":[{"atb":[[3.6,80.4],[3.85,73.35],[4.2,32.66]],"id":46292327},{"atl":[[32,6.74],[21,6.96]],"id":46292327},{"atb":[[36,5.97],[46,2.32],[28,7.74]],"id":42099039},{"atl":[[590,0.35],[490,0.28]],"id":42099039},{"atb":[[2.88,111.2],[2.98,52.79],[2.78,117.44]],"id":65293046},{"atl":[[10.5,14.66],[15.5,14.41]],"id":65293046}],"con":true,"img":false}]}
{"op":"mcm","clk":"11448327939","pt":1717288767617,"mc":[{"id":"1.229554915","rc":[{"atb":[[19.5,0],[24,0],[29,0]],"id":51562794},{"atl":[[400,0],[500,0]],"id":51562794},{"spn":"NaN","spf":"NaN","id":51562794},{"atb":[[3.6,0],[3.85,0],[4.2,0]],"id":46292327},{"atl":[[32,0],[21,0]],"id":46292327},{"spn":"NaN","spf":"NaN","id":46292327},{"atb":[[8.6,0],[7.6,0],[6.6,0]],"id":65788088},{"atl":[[100,0],[200,0]],"id":65788088},{"spn":"NaN","spf":"NaN","id":65788088},{"spn":268.0,"spf":"NaN","id":42099039}],"con":true,"img":false}]}
{"op":"mcm","clk":"11448328753","pt":1717288778134,"mc":[{"id":"1.229554915","rc":[{"atb":[[18,12.29],[21,10.45],[26,4.18]],"id":51562794},{"atl":[[360,0.38],[460,0.45]],"id":51562794},{"atb":[[3.6,80.4],[3.85,73.35],[4.2,32.66]],"id":46292327},{"atl":[[32,6.74],[21,6.96]],"id":46292327},{"atb":[[8.6,13.75],[7.6,31.67],[6.6,37.33]],"id":65788088},{"atl":[[100,1.4],[200,1.05]],"id":65788088}],"con":true,"img":false}]}
{"op":"mcm","clk":"11448494247","pt":1717291211930,"mc":[{"id":"1.229554915","rc":[{"atb":[[18,0],[21,0],[26,0]],"id":51562794},{"atl":[[360,0],[460,0]],"id":51562794},{"atb":[[3.6,0],[3.85,0],[4.2,0]],"id":46292327},{"atl":[[32,0],[21,0]],"id":46292327},{"atb":[[5.8,0],[7.6,0],[6.6,0]],"id":56606596},{"atl":[[75,0],[150,0]],"id":56606596},{"spn":"NaN","spf":"NaN","id":56606596},{"atb":[[8.6,0],[7.6,0],[6.6,0]],"id":65788088},{"atl":[[100,0],[200,0]],"id":65788088},{"atb":[[36,0],[46,0],[28,0]],"id":42099039},{"atl":[[590,0],[490,0]],"id":42099039},{"spn":"NaN","spf":"NaN","id":42099039},{"atb":[[4.8,0],[5.8,0],[5.3,0]],"id":70003370},{"atl":[[48,0],[29,0]],"id":70003370},{"spn":"NaN","spf":"NaN","id":70003370},{"atb":[[1.73,0],[1.63,0],[1.68,0]],"id":64927898},{"atl":[[4,0],[5,0]],"id":64927898},{"spn":"NaN","spf":"NaN","id":64927898}],"con":true,"img":false}]}
{"op":"mcm","clk":"11448494993","pt":1717291222496,"mc":[{"id":"1.229554915","rc":[{"atb":[[19.5,11.3],[24,9.08],[29,3.73]],"id":51562794},{"atl":[[400,0.35],[500,0.41]],"id":51562794},{"atb":[[3.6,80.4],[3.85,73.35],[4.2,32.66]],"id":46292327},{"atl":[[32,6.74],[21,6.96]],"id":46292327},{"atb":[[5.8,43.55],[7.6,15.83],[6.6,37.33]],"id":56606596},{"atl":[[75,1.88],[150,1.4]],"id":56606596},{"atb":[[8.6,13.75],[7.6,31.67],[6.6,37.33]],"id":65788088},{"atl":[[100,1.4],[200,1.05]],"id":65788088},{"atb":[[40,5.36],[50,2.13],[30,7.2]],"id":42099039},{"atl":[[610,0.34],[510,0.27]],"id":42099039},{"atb":[[4.8,55.01],[5.8,21.77],[5.3,48.61]],"id":70003370},{"atl":[[48,4.44],[29,4.97]],"id":70003370},{"atb":[[1.79,132.31],[1.74,282.51],[1.69,302.98]],"id":64927898},{"atl":[[4.3,42.23],[5.3,48.61]],"id":64927898}],"con":true,"img":false}]}
{"op":"mcm","clk":"11448629976","pt":1717293528419,"mc":[{"id":"1.229554915","marketDefinition":{"bspMarket":true,"turnInPlayEnabled":false,"persistenceEnabled":false,"marketBaseRate":7.0,"eventId":"33318908","eventTypeId":"4339","numberOfWinners":1,"bettingType":"ODDS","marketType":"WIN","marketTime":"2024-06-02T10:03:00.000Z","suspendTime":"2024-06-02T10:03:00.000Z","bspReconciled":false,"complete":true,"inPlay":false,"crossMatching":true,"runnersVoidable":false,"numberOfActiveRunners":8,"betDelay":0,"status":"OPEN","runners":[{"status":"ACTIVE","sortPriority":1,"id":65293046,"name":"1. Beast Cut Loose"},{"status":"ACTIVE","sortPriority":2,"id":42099039,"name":"2. Thatll Do Neo"},{"status":"ACTIVE","sortPriority":3,"id":70003370,"name":"3. Ki Ki"},{"status":"ACTIVE","sortPriority":4,"id":56606596,"name":"4. Senna Wick"},{"status":"ACTIVE","sortPriority":5,"id":46292327,"name":"5. Immense"},{"status":"ACTIVE","sortPriority":6,"id":65788088,"name":"6. Bundy Baz"},{"status":"ACTIVE","sortPriority":7,"id":51562794,"name":"7. Chasing Boyd"},{"status":"ACTIVE","sortPriority":8,"id":64927898,"name":"8. Tilley Swamp"}],"regulators":["MR_INT"],"venue":"Murray Bridge","countryCode":"AU","discountAllowed":true,"timezone":"Australia/Adelaide","openDate":"2024-06-02T08:21:00.000Z","version":5962317635,"name":"R6 455m Gr4/5","eventName":"Murray Bridge (AUS) 2nd Jun"},"rc":[{"atb":[[19.5,11.3],[24,9.08],[29,3.73]],"id":51562794},{"atl":[[400,0.35],[500,0.41]],"id":51562794},{"spn":214.5,"spf":"NaN","id":51562794},{"atb":[[3.6,80.4],[3.85,73.35],[4.2,32.66]],"id":46292327},{"atl":[[32,6.74],[21,6.96]],"id":46292327},{"spn":12.6,"spf":"NaN","id":46292327},{"atb":[[5.8,43.55],[7.6,15.83],[6.6,37.33]],"id":56606596},{"atl":[[75,1.88],[150,1.4]],"id":56606596},{"spn":41.3,"spf":"NaN","id":56606596},{"atb":[[8.6,13.75],[7.6,31.67],[6.6,37.33]],"id":65788088},{"atl":[[100,1.4],[200,1.05]],"id":65788088},{"spn":54.3,"spf":"NaN","id":65788088},{"atb":[[40,5.36],[50,2.13],[30,7.2]],"id":42099039},{"atl":[[610,0.34],[510,0.27]],"id":42099039},{"spn":280.0,"spf":"NaN","id":42099039},{"atb":[[4.8,55.01],[5.8,21.77],[5.3,48.61]],"id":70003370},{"atl":[[48,4.44],[29,4.97]],"id":70003370},{"spn":17.4,"spf":"NaN","id":70003370},{"atb":[[2.88,111.2],[2.98,52.79],[2.78,117.44]],"id":65293046},{"atl":[[10.5,14.66],[15.5,14.41]],"id":65293046},{"spn":6.74,"spf":"NaN","id":65293046},{"atb":[[1.79,132.31],[1.74,282.51],[1.69,302.98]],"id":64927898},{"atl":[[4.3,42.23],[5.3,48.61]],"id":64927898},{"spn":3.04,"spf":"NaN","id":64927898}],"con":true,"img":true}]}
{"op":"mcm","clk":"11449377567","pt":1717308263185,"mc":[{"id":"1.229554915","rc":[{"atb":[[19.5,0],[24,0],[29,0]],"id":51562794},{"atl":[[400,0],[500,0]],"id":51562794},{"spn":12.6,"spf":"NaN","id":46292327},{"atb":[[5.8,0],[7.6,0],[6.6,0]],"id":56606596},{"atl":[[75,0],[150,0]],"id":56606596},{"spn":54.3,"spf":"NaN","id":65788088},{"spn":280.0,"spf":"NaN","id":42099039},{"atb":[[4.8,0],[5.8,0],[5.3,0]],"id":70003370},{"atl":[[48,0],[29,0]],"id":70003370},{"atb":[[2.88,0],[2.98,0],[2.78,0]],"id":65293046},{"atl":[[10.5,0],[15.5,0]],"id":65293046},{"spn":"NaN","spf":"NaN","id":65293046},{"atb":[[1.79,0],[1.74,0],[1.69,0]],"id":64927898},{"atl":[[4.3,0],[5.3,0]],"id":64927898}],"con":true,"img":false}]}
{"op":"mcm","clk":"11449380116","pt":1717308306835,"mc":[{"id":"1.229554915","rc":[{"atb":[[19.5,11.3],[24,9.08],[29,3.73]],"id":51562794},{"atl":[[400,0.35],[500,0.41]],"id":51562794},{"atb":[[5.8,43.55],[7.6,15.83],[6.6,37.33]],"id":56606596},{"atl":[[75,1.88],[150,1.4]],"id":56606596},{"atb":[[4.8,55.01],[5.8,21.77],[5.3,48.61]],"id":70003370},{"atl":[[48,4.44],[29,4.97]],"id":70003370},{"atb":[[2.88,111.2],[2.98,52.79],[2.78,117.44]],"id":65293046},{"atl":[[10.5,14.66],[15.5,14.41]],"id":65293046},{"atb":[[1.73,143.19],[1.63,331.84],[1.68,307.44]],"id":64927898},{"atl":[[4,46.45],[5,52.26]],"id":64927898}],"con":true,"img":false}]}
{"op":"mcm","clk":"11449383812","pt":1717308364817,"mc":[{"id":"1.229554915","rc":[{"atb":[[19.5,0],[24,0],[29,0]],"id":51562794},{"atl":[[400,0],[500,0]],"id":51562794},{"atb":[[3.6,0],[3.85,0],[4.2,0]],"id":46292327},{"atl":[[32,0],[21,0]],"id":46292327},{"spn":"NaN","spf":"NaN","id":46292327},{"atb":[[5.8,0],[7.6,0],[6.6,0]],"id":56606596},{"atl":[[75,0],[150,0]],"id":56606596},{"atb":[[8.6,0],[7.6,0],[6.6,0]],"id":65788088},{"atl":[[100,0],[200,0]],"id":65788088},{"spn":"NaN","spf":"NaN","id":65788088},{"atb":[[2.88,0],[2.98,0],[2.78,0]],"id":65293046},{"atl":[[10.5,0],[15.5,0]],"id":65293046},{"atb":[[4.8,0],[5.8,0],[5.3,0]],"id":70003370},{"atl":[[48,0],[29,0]],"id":70003370},{"atb":[[1.73,0],[1.63,0],[1.68,0]],"id":64927898},{"atl":[[4,0],[5,0]],"id":64927898}],"con":true,"img":false}]}
{"op":"mcm","clk":"11449385225","pt":1717308387157,"mc":[{"id":"1.229554915","rc":[{"atb":[[19.5,11.3],[24,9.08],[29,3.73]],"id":51562794},{"atl":[[400,0.35],[500,0.41]],"id":51562794},{"atb":[[3.6,80.4],[3.85,73.35],[4.2,32.66]],"id":46292327},{"atl":[[32,6.74],[21,6.96]],"id":46292327},{"atb":[[8.6,13.75],[7.6,31.67],[6.6,37.33]],"id":56606596},{"atl":[[100,1.4],[200,1.05]],"id":56606596},{"atb":[[8,29.86],[9,13.06],[7,34.84]],"id":65788088},{"atl":[[210,0.99],[110,1.27]],"id":65788088},{"atb":[[3.1,49.77],[2.84,113.61],[2.94,107.76]],"id":65293046},{"atl":[[16,13.93],[11,13.93]],"id":65293046},{"atb":[[5.6,45.44],[5.1,50.98],[6.2,20.1]],"id":70003370},{"atl":[[70,3.02],[38,3.76]],"id":70003370},{"atb":[[1.63,331.84],[1.58,360.45],[1.68,153.71]],"id":64927898},{"atl":[[3.7,51.62],[4.4,61.48]],"id":64927898}],"con":true,"img":false}]}
{"op":"mcm","clk":"11449480365","pt":1717309728420,"mc":[{"id":"1.229554915","marketDefinition":{"bspMarket":true,"turnInPlayEnabled":false,"persistenceEnabled":false,"marketBaseRate":7.0,"eventId":"33318908","eventTypeId":"4339","numberOfWinners":1,"bettingType":"ODDS","marketType":"WIN","marketTime":"2024-06-02T10:03:00.000Z","suspendTime":"2024-06-02T10:03:00.000Z","bspReconciled":false,"complete":true,"inPlay":false,"crossMatching":true,"runnersVoidable":false,"numberOfActiveRunners":8,"betDelay":0,"status":"OPEN","runners":[{"status":"ACTIVE","sortPriority":1,"id":65293046,"name":"1. Beast Cut Loose"},{"status":"ACTIVE","sortPriority":2,"id":42099039,"name":"2. Thatll Do Neo"},{"status":"ACTIVE","sortPriority":3,"id":70003370,"name":"3. Ki Ki"},{"status":"ACTIVE","sortPriority":4,"id":56606596,"name":"4. Senna Wick"},{"status":"ACTIVE","sortPriority":5,"id":46292327,"name":"5. Immense"},{"status":"ACTIVE","sortPriority":6,"id":65788088,"name":"6. Bundy Baz"},{"status":"ACTIVE","sortPriority":7,"id":51562794,"name":"7. Chasing Boyd"},{"status":"ACTIVE","sortPriority":8,"id":64927898,"name":"8. Tilley Swamp"}],"regulators":["MR_INT"],"venue":"Murray Bridge","countryCode":"AU","discountAllowed":true,"timezone":"Australia/Adelaide","openDate":"2024-06-02T08:21:00.000Z","version":5962317635,"name":"R6 455m Gr4/5","eventName":"Murray Bridge (AUS) 2nd Jun"},"rc":[{"atb":[[19.5,11.3],[24,9.08],[29,3.73]],"id":51562794},{"atl":[[400,0.35],[500,0.41]],"id":51562794},{"spn":214.5,"spf":"NaN","id":51562794},{"atb":[[3.6,80.4],[3.85,73.35],[4.2,32.66]],"id":46292327},{"atl":[[32,6.74],[21,6.96]],"id":46292327},{"spn":12.6,"spf":"NaN","id":46292327},{"atb":[[8.6,13.75],[7.6,31.67],[6.6,37.33]],"id":56606596},{"atl":[[100,1.4],[200,1.05]],"id":56606596},{"spn":54.3,"spf":"NaN","id":56606596},{"atb":[[8,29.86],[9,13.06],[7,34.84]],"id":65788088},{"atl":[[210,0.99],[110,1.27]],"id":65788088},{"spn":59.5,"spf":"NaN","id":65788088},{"atb":[[40,5.36],[50,2.13],[30,7.2]],"id":42099039},{"atl":[[610,0.34],[510,0.27]],"id":42099039},{"spn":280.0,"spf":"NaN","id":42099039},{"atb":[[5.6,45.44],[5.1,50.98],[6.2,20.1]],"id":70003370},{"atl":[[70,3.02],[38,3.76]],"id":70003370},{"spn":22.1,"spf":"NaN","id":70003370},{"atb":[[3.1,49.77],[2.84,113.61],[2.94,107.76]],"id":65293046},{"atl":[[16,13.93],[11,13.93]],"id":65293046},{"spn":7.05,"spf":"NaN","id":65293046},{"atb":[[1.63,331.84],[1.58,360.45],[1.68,153.71]],"id":64927898},{"atl":[[3.7,51.62],[4.4,61.48]],"id":64927898},{"spn":2.69,"spf":"NaN","id":64927898}],"con":true,"img":true}]}
{"op":"mcm","clk":"11449546546","pt":1717310732834,"mc":[{"id":"1.229554915","rc":[{"atb":[[19.5,0],[24,0],[29,0]],"id":51562794},{"atl":[[400,0],[500,0]],"id":51562794},{"atb":[[3.6,0],[3.85,0],[4.2,0]],"id":46292327},{"atl":[[32,0],[21,0]],"id":46292327},{"spn":54.3,"spf":"NaN","id":56606596},{"atb":[[8,0],[9,0],[7,0]],"id":65788088},{"atl":[[210,0],[110,0]],"id":65788088},{"atb":[[5.6,0],[5.1,0],[6.2,0]],"id":70003370},{"atl":[[70,0],[38,0]],"id":70003370},{"atb":[[3.1,0],[2.84,0],[2.94,0]],"id":65293046},{"atl":[[16,0],[11,0]],"id":65293046},{"atb":[[1.63,0],[1.58,0],[1.68,0]],"id":64927898},{"atl":[[3.7,0],[4.4,0]],"id":64927898}],"con":true,"img":false}]}
{"op":"mcm","clk":"11449547665","pt":1717310751164,"mc":[{"id":"1.229554915","rc":[{"atb":[[19.5,11.3],[24,9.08],[29,3.73]],"id":51562794},{"atl":[[400,0.35],[500,0.41]],"id":51562794},{"atb":[[3.6,80.4],[3.85,73.35],[4.2,32.66]],"id":46292327},{"atl":[[32,6.74],[21,6.96]],"id":46292327},{"atb":[[8,29.86],[9,13.06],[7,34.84]],"id":65788088},{"atl":[[210,0.99],[110,1.27]],"id":65788088},{"atb":[[2.86,112.39],[3.15,48.61],[2.96,106.66]],"id":65293046},{"atl":[[16,13.93],[11,13.93]],"id":65293046},{"atb":[[4.8,55.01],[5.8,21.77],[5.3,48.61]],"id":70003370},{"atl":[[48,4.44],[29,4.97]],"id":70003370},{"atb":[[1.63,331.84],[1.58,360.45],[1.68,153.71]],"id":64927898},{"atl":[[3.7,51.62],[4.4,61.48]],"id":64927898}],"con":true,"img":false}]}
{"op":"mcm","clk":"11449550487","pt":1717310796983,"mc":[{"id":"1.229554915","rc":[{"atb":[[19.5,0],[24,0],[29,0]],"id":51562794},{"atl":[[400,0],[500,0]],"id":51562794},{"atb":[[3.6,0],[3.85,0],[4.2,0]],"id":46292327},{"atl":[[32,0],[21,0]],"id":46292327},{"atb":[[8,0],[9,0],[7,0]],"id":65788088},{"atl":[[210,0],[110,0]],"id":65788088},{"atb":[[40,0],[50,0],[30,0]],"id":42099039},{"atl":[[610,0],[510,0]],"id":42099039},{"spn":"NaN","spf":"NaN","id":42099039},{"atb":[[4.8,0],[5.8,0],[5.3,0]],"id":70003370},{"atl":[[48,0],[29,0]],"id":70003370},{"spn":7.07,"spf":"NaN","id":65293046},{"atb":[[1.63,0],[1.58,0],[1.68,0]],"id":64927898},{"atl":[[3.7,0],[4.4,0]],"id":64927898}],"con":true,"img":false}]}
{"op":"mcm","clk":"11449552512","pt":1717310833578,"mc":[{"id":"1.229554915","rc":[{"atb":[[19.5,11.3],[24,9.08],[29,3.73]],"id":51562794},{"atl":[[400,0.35],[500,0.41]],"id":51562794},{"atb":[[3.6,80.4],[3.85,73.35],[4.2,32.66]],"id":46292327},{"atl":[[32,6.74],[21,6.96]],"id":46292327},{"atb":[[8,29.86],[9,13.06],[7,34.84]],"id":65788088},{"atl":[[210,0.99],[110,1.27]],"id":65788088},{"atb":[[36,5.97],[46,2.32],[28,7.74]],"id":42099039},{"atl":[[590,0.35],[490,0.28]],"id":42099039},{"atb":[[4.8,55.01],[5.8,21.77],[5.3,48.61]],"id":70003370},{"atl":[[48,4.44],[29,4.97]],"id":70003370},{"atb":[[1.63,331.84],[1.58,360.45],[1.68,153.71]],"id":64927898},{"atl":[[3.7,51.62],[4.4,61.48]],"id":64927898}],"con":true,"img":false}]}
{"op":"mcm","clk":"11449609355","pt":1717311864401,"mc":[{"id":"1.229554915","rc":[{"atb":[[19.5,0],[24,0],[29,0]],"id":51562794},{"atl":[[400,0],[500,0]],"id":51562794},{"atb":[[3.6,0],[3.85,0],[4.2,0]],"id":46292327},{"atl":[[32,0],[21,0]],"id":46292327},{"atb":[[8.6,0],[7.6,0],[6.6,0]],"id":56606596},{"atl":[[100,0],[200,0]],"id":56606596},{"spn":"NaN","spf":"NaN","id":56606596},{"atb":[[8,0],[9,0],[7,0]],"id":65788088},{"atl":[[210,0],[110,0]],"id":65788088},{"atb":[[36,0],[46,0],[28,0]],"id":42099039},{"atl":[[590,0],[490,0]],"id":42099039},{"atb":[[4.8,0],[5.8,0],[5.3,0]],"id":70003370},{"atl":[[48,0],[29,0]],"id":70003370},{"atb":[[2.86,0],[3.15,0],[2.96,0]],"id":65293046},{"atl":[[16,0],[11,0]],"id":65293046},{"spn":"NaN","spf":"NaN","id":65293046},{"atb":[[1.63,0],[1.58,0],[1.68,0]],"id":64927898},{"atl":[[3.7,0],[4.4,0]],"id":64927898}],"con":true,"img":false}]}
{"op":"mcm","clk":"11449610121","pt":1717311877659,"mc":[{"id":"1.229554915","rc":[{"atb":[[19.5,11.3],[24,9.08],[29,3.73]],"id":51562794},{"atl":[[400,0.35],[500,0.41]],"id":51562794},{"atb":[[3.6,80.4],[3.85,73.35],[4.2,32.66]],"id":46292327},{"atl":[[32,6.74],[21,6.96]],"id":46292327},{"atb":[[8.6,13.75],[7.6,31.67],[6.6,37.33]],"id":56606596},{"atl":[[100,1.4],[200,1.05]],"id":56606596},{"atb":[[8,29.86],[9,13.06],[7,34.84]],"id":65788088},{"atl":[[210,0.99],[110,1.27]],"id":65788088},{"atb":[[36,5.97],[46,2.32],[28,7.74]],"id":42099039},{"atl":[[590,0.35],[490,0.28]],"id":42099039},{"atb":[[2.86,112.39],[3.15,48.61],[2.96,106.66]],"id":65293046},{"atl":[[16,13.93],[11,13.93]],"id":65293046},{"atb":[[4.8,55.01],[5.8,21.77],[5.3,48.61]],"id":70003370},{"atl":[[48,4.44],[29,4.97]],"id":70003370},{"atb":[[1.63,331.84],[1.58,360.45],[1.68,153.71]],"id":64927898},{"atl":[[3.7,51.62],[4.4,61.48]],"id":64927898}],"con":true,"img":false}]}
{"op":"mcm","clk":"11449614850","pt":1717311962244,"mc":[{"id":"1.229554915","rc":[{"spn":214.5,"spf":"NaN","id":51562794},{"spn":12.6,"spf":"NaN","id":46292327},{"spn":54.3,"spf":"NaN","id":56606596},{"spn":59.5,"spf":"NaN","id":65788088},{"spn":268.0,"spf":"NaN","id":42099039},{"spn":17.4,"spf":"NaN","id":70003370},{"atb":[[2.86,0],[3.15,0],[2.96,0]],"id":65293046},{"atl":[[16,0],[11,0]],"id":65293046},{"spn":2.69,"spf":"NaN","id":64927898}],"con":true,"img":false}]}
{"op":"mcm","clk":"11449615556","pt":1717311975906,"mc":[{"id":"1.229554915","rc":[{"atb":[[2.86,112.39],[3.15,48.61],[2.96,106.66]],"id":65293046},{"atl":[[16,13.93],[11,13.93]],"id":65293046}],"con":true,"img":false}]}
{"op":"mcm","clk":"11449636811","pt":1717312490724,"mc":[{"id":"1.229554915","rc":[{"spn":7.07,"spf":"NaN","id":65293046},{"atb":[[1.52,100]],"id":64927898}],"con":true,"img":false}]}
{"op":"mcm","clk":"11449655964","pt":1717312955983,"mc":[{"id":"1.229554915","rc":[{"atb":[[19.5,0],[24,0],[29,0]],"id":51562794},{"atl":[[400,0],[500,0]],"id":51562794},{"spn":"NaN","spf":"NaN","id":51562794},{"atb":[[3.6,0],[3.85,0],[4.2,0]],"id":46292327},{"atl":[[32,0],[21,0]],"id":46292327},{"spn":"NaN","spf":"NaN","id":46292327},{"atb":[[8.6,0],[7.6,0],[6.6,0]],"id":56606596},{"atl":[[100,0],[200,0]],"id":56606596},{"spn":"NaN","spf":"NaN","id":56606596},{"atb":[[8,0],[9,0],[7,0]],"id":65788088},{"atl":[[210,0],[110,0]],"id":65788088},{"spn":"NaN","spf":"NaN","id":65788088},{"atb":[[36,0],[46,0],[28,0]],"id":42099039},{"atl":[[590,0],[490,0]],"id":42099039},{"spn":"NaN","spf":"NaN","id":42099039},{"atb":[[2.86,0],[3.15,0],[2.96,0]],"id":65293046},{"atl":[[16,0],[11,0]],"id":65293046},{"spn":"NaN","spf":"NaN","id":65293046},{"atb":[[4.8,0],[5.8,0],[5.3,0]],"id":70003370},{"atl":[[48,0],[29,0]],"id":70003370},{"spn":"NaN","spf":"NaN","id":70003370},{"atb":[[1.63,0],[1.58,0],[1.68,0]],"id":64927898},{"atl":[[3.7,0],[4.4,0]],"id":64927898},{"spn":"Infinity","spf":"NaN","id":64927898}],"con":true,"img":false}]}
{"op":"mcm","clk":"11449656393","pt":1717312966043,"mc":[{"id":"1.229554915","rc":[{"atb":[[19.5,11.3],[24,9.08],[29,3.73]],"id":51562794},{"atl":[[400,0.35],[500,0.41]],"id":51562794},{"atb":[[3.6,80.4],[3.85,73.35],[4.2,32.66]],"id":46292327},{"atl":[[32,6.74],[21,6.96]],"id":46292327},{"atb":[[8.6,13.75],[7.6,31.67],[6.6,37.33]],"id":56606596},{"atl":[[100,1.4],[200,1.05]],"id":56606596},{"atb":[[8,29.86],[9,13.06],[7,34.84]],"id":65788088},{"atl":[[210,0.99],[110,1.27]],"id":65788088},{"atb":[[36,5.97],[46,2.32],[28,7.74]],"id":42099039},{"atl":[[590,0.35],[490,0.28]],"id":42099039},{"atb":[[4.8,55.01],[5.8,21.77],[5.3,48.61]],"id":70003370},{"atl":[[48,4.44],[29,4.97]],"id":70003370},{"atb":[[2.86,112.39],[3.15,48.61],[2.96,106.66]],"id":65293046},{"atl":[[16,13.93],[11,13.93]],"id":65293046},{"atb":[[1.63,331.84],[1.58,360.45],[1.68,153.71]],"id":64927898},{"atl":[[3.7,51.62],[4.4,61.48]],"id":64927898}],"con":true,"img":false}]}
{"op":"mcm","clk":"11449736728","pt":1717314096607,"mc":[{"id":"1.229554915","rc":[{"atb":[[19.5,0],[24,0],[29,0]],"id":51562794},{"atl":[[400,0],[500,0]],"id":51562794},{"atb":[[3.6,0],[3.85,0],[4.2,0]],"id":46292327},{"atl":[[32,0],[21,0]],"id":46292327},{"atb":[[8.6,0],[7.6,0],[6.6,0]],"id":56606596},{"atl":[[100,0],[200,0]],"id":56606596},{"atb":[[8,0],[9,0],[7,0]],"id":65788088},{"atl":[[210,0],[110,0]],"id":65788088},{"atb":[[36,0],[46,0],[28,0]],"id":42099039},{"atl":[[590,0],[490,0]],"id":42099039},{"atb":[[4.8,0],[5.8,0],[5.3,0]],"id":70003370},{"atl":[[48,0],[29,0]],"id":70003370},{"atb":[[2.86,0],[3.15,0],[2.96,0]],"id":65293046},{"atl":[[16,0],[11,0]],"id":65293046},{"atb":[[1.63,0],[1.58,0],[1.68,0]],"id":64927898},{"atl":[[3.7,0],[4.4,0]],"id":64927898}],"con":true,"img":false}]}
{"op":"mcm","clk":"11449738237","pt":1717314113455,"mc":[{"id":"1.229554915","rc":[{"atb":[[19.5,11.3],[24,9.08],[29,3.73]],"id":51562794},{"atl":[[400,0.35],[500,0.41]],"id":51562794},{"atb":[[3.6,80.4],[3.85,73.35],[4.2,32.66]],"id":46292327},{"atl":[[32,6.74],[21,6.96]],"id":46292327},{"atb":[[8.6,13.75],[7.6,31.67],[6.6,37.33]],"id":56606596},{"atl":[[100,1.4],[200,1.05]],"id":56606596},{"atb":[[8,29.86],[9,13.06],[7,34.84]],"id":65788088},{"atl":[[210,0.99],[110,1.27]],"id":65788088},{"atb":[[36,5.97],[46,2.32],[28,7.74]],"id":42099039},{"atl":[[590,0.35],[490,0.28]],"id":42099039},{"atb":[[4.8,55.01],[5.8,21.77],[5.3,48.61]],"id":70003370},{"atl":[[48,4.44],[29,4.97]],"id":70003370},{"atb":[[2.86,112.39],[3.15,48.61],[2.96,106.66]],"id":65293046},{"atl":[[16,13.93],[11,13.93]],"id":65293046},{"atb":[[1.63,331.84],[1.58,360.45],[1.68,153.71]],"id":64927898},{"atl":[[3.7,51.62],[4.4,61.48]],"id":64927898}],"con":true,"img":false}]}
{"op":"mcm","clk":"11449745174","pt":1717314192004,"mc":[{"id":"1.229554915","rc":[{"atb":[[19.5,0],[24,0],[29,0]],"id":51562794},{"atl":[[400,0],[500,0]],"id":51562794},{"atb":[[3.6,0],[3.85,0],[4.2,0]],"id":46292327},{"atl":[[32,0],[21,0]],"id":46292327},{"atb":[[8.6,0],[7.6,0],[6.6,0]],"id":56606596},{"atl":[[100,0],[200,0]],"id":56606596},{"atb":[[8,0],[9,0],[7,0]],"id":65788088},{"atl":[[210,0],[110,0]],"id":65788088},{"atb":[[36,0],[46,0],[28,0]],"id":42099039},{"atl":[[590,0],[490,0]],"id":42099039},{"atb":[[2.86,0],[3.15,0],[2.96,0]],"id":65293046},{"atl":[[16,0],[11,0]],"id":65293046},{"atb":[[4.8,0],[5.8,0],[5.3,0]],"id":70003370},{"atl":[[48,0],[29,0]],"id":70003370},{"atb":[[1.63,0],[1.58,0],[1.68,0]],"id":64927898},{"atl":[[3.7,0],[4.4,0]],"id":64927898}],"con":true,"img":false}]}
{"op":"mcm","clk":"11449746551","pt":1717314206858,"mc":[{"id":"1.229554915","rc":[{"atb":[[19.5,11.3],[24,9.08],[29,3.73]],"id":51562794},{"atl":[[400,0.35],[500,0.41]],"id":51562794},{"atb":[[3.6,80.4],[3.85,73.35],[4.2,32.66]],"id":46292327},{"atl":[[32,6.74],[21,6.96]],"id":46292327},{"atb":[[8.6,13.75],[7.6,31.67],[6.6,37.33]],"id":56606596},{"atl":[[100,1.4],[200,1.05]],"id":56606596},{"atb":[[8,29.86],[9,13.06],[7,34.84]],"id":65788088},{"atl":[[210,0.99],[110,1.27]],"id":65788088},{"atb":[[36,5.97],[46,2.32],[28,7.74]],"id":42099039},{"atl":[[590,0.35],[490,0.28]],"id":42099039},{"atb":[[4.8,55.01],[5.8,21.77],[5.3,48.61]],"id":70003370},{"atl":[[48,4.44],[29,4.97]],"id":70003370},{"atb":[[2.86,112.39],[3.15,48.61],[2.96,106.66]],"id":65293046},{"atl":[[16,13.93],[11,13.93]],"id":65293046},{"atb":[[1.63,331.84],[1.58,360.45],[1.68,153.71]],"id":64927898},{"atl":[[3.7,51.62],[4.4,61.48]],"id":64927898}],"con":true,"img":false}]}
{"op":"mcm","clk":"11449820024","pt":1717315041456,"mc":[{"id":"1.229554915","rc":[{"atb":[[1.03,6.04]],"id":51562794},{"atl":[[1000,0.85]],"id":51562794},{"spn":214.5,"spf":"NaN","id":51562794},{"atb":[[1.03,6.04]],"id":46292327},{"atl":[[1000,0.85]],"id":46292327},{"spn":12.6,"spf":"NaN","id":46292327},{"atb":[[1.01,18.11]],"id":56606596},{"atl":[[990,0.85]],"id":56606596},{"spn":54.3,"spf":"NaN","id":56606596},{"atb":[[1.01,18.11]],"id":65788088},{"atl":[[990,0.85]],"id":65788088},{"spn":59.5,"spf":"NaN","id":65788088},{"atb":[[1.01,18.11]],"id":42099039},{"atl":[[990,0.85]],"id":42099039},{"spn":268.0,"spf":"NaN","id":42099039},{"atb":[[1.01,18.11]],"id":70003370},{"atl":[[1000,0.85]],"id":70003370},{"spn":17.4,"spf":"NaN","id":70003370},{"atb":[[1.01,18.11]],"id":65293046},{"atl":[[990,0.85]],"id":65293046},{"spn":7.07,"spf":"NaN","id":65293046},{"atb":[[1.01,18.11]],"id":64927898},{"atl":[[990,0.85]],"id":64927898},{"spn":2.69,"spf":"NaN","id":64927898}],"con":true,"img":false}]}
{"op":"mcm","clk":"11449837942","pt":1717315161234,"mc":[{"id":"1.229554915","rc":[{"atb":[[19.5,0],[24,0],[29,0]],"id":51562794},{"atl":[[400,0],[500,0]],"id":51562794},{"atb":[[3.6,0],[3.85,0],[4.2,0]],"id":46292327},{"atl":[[32,0],[21,0]],"id":46292327},{"atb":[[8.6,0],[7.6,0],[6.6,0]],"id":56606596},{"atl":[[100,0],[200,0]],"id":56606596},{"atb":[[8,0],[9,0],[7,0]],"id":65788088},{"atl":[[210,0],[110,0]],"id":65788088},{"atb":[[36,0],[46,0],[28,0]],"id":42099039},{"atl":[[590,0],[490,0]],"id":42099039},{"atb":[[2.86,0],[3.15,0],[2.96,0]],"id":65293046},{"atl":[[16,0],[11,0]],"id":65293046},{"atb":[[4.8,0],[5.8,0],[5.3,0]],"id":70003370},{"atl":[[48,0],[29,0]],"id":70003370},{"atb":[[1.63,0],[1.58,0],[1.68,0]],"id":64927898},{"atl":[[3.7,0],[4.4,0]],"id":64927898}],"con":true,"img":false}]}
{"op":"mcm","clk":"11449839516","pt":1717315177241,"mc":[{"id":"1.229554915","rc":[{"atb":[[6.2,9.62],[4.1,16.13]],"id":51562794},{"atb":[[3.05,24.39]],"id":56606596},{"atb":[[6.2,9.62],[4.1,16.13],[3.05,24.39]],"id":42099039}],"con":true,"img":false}]}
{"op":"mcm","clk":"11449839525","pt":1717315177348,"mc":[{"id":"1.229554915","rc":[{"atb":[[2.12,44.64],[1.51,98.04],[3.05,24.39]],"id":51562794},{"atb":[[1.51,98.04]],"id":46292327},{"atb":[[2.12,44.64],[1.51,98.04]],"id":56606596},{"atb":[[2.12,44.64],[1.51,98.04],[3.05,24.39]],"id":65788088},{"atb":[[2.12,44.64],[1.51,98.04]],"id":42099039},{"atb":[[1.51,98.04]],"id":65293046},{"atb":[[2.12,44.64],[1.51,98.04]],"id":70003370}],"con":true,"img":false}]}
{"op":"mcm","clk":"11449841686","pt":1717315199991,"mc":[{"id":"1.229554915","rc":[{"atb":[[19.5,11.3],[24,9.08],[29,3.73]],"id":51562794},{"atl":[[400,0.35],[500,0.41]],"id":51562794},{"atb":[[3.6,80.4],[3.85,73.35],[4.2,32.66]],"id":46292327},{"atl":[[32,6.74],[21,6.96]],"id":46292327},{"atb":[[8.6,13.75],[7.6,31.67],[6.6,37.33]],"id":56606596},{"atl":[[100,1.4],[200,1.05]],"id":56606596},{"atb":[[8,29.86],[9,13.06],[7,34.84]],"id":65788088},{"atl":[[210,0.99],[110,1.27]],"id":65788088},{"atb":[[36,5.97],[46,2.32],[28,7.74]],"id":42099039},{"atl":[[590,0.35],[490,0.28]],"id":42099039},{"atb":[[4.8,55.01],[5.8,21.77],[5.3,48.61]],"id":70003370},{"atl":[[48,4.44],[29,4.97]],"id":70003370},{"atb":[[2.86,112.39],[3.15,48.61],[2.96,106.66]],"id":65293046},{"atl":[[16,13.93],[11,13.93]],"id":65293046},{"atb":[[1.63,331.84],[1.58,360.45],[1.68,153.71]],"id":64927898},{"atl":[[3.7,51.62],[4.4,61.48]],"id":64927898}],"con":true,"img":false}]}
{"op":"mcm","clk":"11449842752","pt":1717315209190,"mc":[{"id":"1.229554915","rc":[{"atl":[[34,10]],"id":65293046},{"atl":[[34,10]],"id":64927898}],"con":true,"img":false}]}
{"op":"mcm","clk":"11449851251","pt":1717315296202,"mc":[{"id":"1.229554915","rc":[{"atb":[[19.5,0],[24,0],[29,0]],"id":51562794},{"atl":[[400,0],[500,0]],"id":51562794},{"spn":503.1,"spf":"NaN","id":51562794},{"atb":[[3.6,0],[3.85,0],[4.2,0]],"id":46292327},{"atl":[[32,0],[21,0]],"id":46292327},{"spn":500.75,"spf":"NaN","id":46292327},{"atb":[[8.6,0],[7.6,0],[6.6,0]],"id":56606596},{"atl":[[100,0],[200,0]],"id":56606596},{"spn":496.52,"spf":"NaN","id":56606596},{"atb":[[8,0],[9,0],[7,0]],"id":65788088},{"atl":[[210,0],[110,0]],"id":65788088},{"spn":496.52,"spf":"NaN","id":65788088},{"atb":[[36,0],[46,0],[28,0]],"id":42099039},{"atl":[[590,0],[490,0]],"id":42099039},{"spn":498.1,"spf":"NaN","id":42099039},{"atb":[[2.86,0],[3.15,0],[2.96,0]],"id":65293046},{"atl":[[16,0],[11,0]],"id":65293046},{"spn":17.75,"spf":"NaN","id":65293046},{"atb":[[4.8,0],[5.8,0],[5.3,0]],"id":70003370},{"atl":[[48,0],[29,0]],"id":70003370},{"spn":501.06,"spf":"NaN","id":70003370},{"atb":[[1.63,0],[1.58,0],[1.68,0]],"id":64927898},{"atl":[[3.7,0],[4.4,0]],"id":64927898},{"spn":17.76,"spf":"NaN","id":64927898}],"con":true,"img":false}]}
{"op":"mcm","clk":"11449853607","pt":1717315320659,"mc":[{"id":"1.229554915","rc":[{"atb":[[19.5,11.3],[24,9.08],[29,3.73]],"id":51562794},{"atl":[[400,0.35],[500,0.41]],"id":51562794},{"atb":[[3.6,80.4],[3.85,73.35],[4.2,32.66]],"id":46292327},{"atl":[[32,6.74],[21,6.96]],"id":46292327},{"atb":[[8.6,13.75],[7.6,31.67],[6.6,37.33]],"id":56606596},{"atl":[[100,1.4],[200,1.05]],"id":56606596},{"atb":[[8,29.86],[9,13.06],[7,34.84]],"id":65788088},{"atl":[[210,0.99],[110,1.27]],"id":65788088},{"atb":[[36,5.97],[46,2.32],[28,7.74]],"id":42099039},{"atl":[[590,0.35],[490,0.28]],"id":42099039},{"atb":[[2.86,112.39],[3.15,48.61],[2.96,106.66]],"id":65293046},{"atl":[[16,13.93],[11,13.93]],"id":65293046},{"atb":[[4.8,55.01],[5.8,21.77],[5.3,48.61]],"id":70003370},{"atl":[[48,4.44],[29,4.97]],"id":70003370},{"atb":[[1.63,331.84],[1.58,360.45],[1.68,153.71]],"id":64927898},{"atl":[[3.7,51.62],[4.4,61.48]],"id":64927898}],"con":true,"img":false}]}
{"op":"mcm","clk":"11449893648","pt":1717315712569,"mc":[{"id":"1.229554915","rc":[{"atb":[[19.5,0],[24,0],[29,0]],"id":51562794},{"atl":[[400,0],[500,0]],"id":51562794},{"atb":[[3.6,0],[3.85,0],[4.2,0]],"id":46292327},{"atl":[[32,0],[21,0]],"id":46292327},{"spn":54.3,"spf":"NaN","id":56606596},{"atb":[[8,0],[9,0],[7,0]],"id":65788088},{"atl":[[210,0],[110,0]],"id":65788088},{"atb":[[36,0],[46,0],[28,0]],"id":42099039},{"atl":[[590,0],[490,0]],"id":42099039},{"spn":7.07,"spf":"NaN","id":65293046},{"spn":17.4,"spf":"NaN","id":70003370},{"spn":2.69,"spf":"NaN","id":64927898}],"con":true,"img":false}]}
{"op":"mcm","clk":"11449896887","pt":1717315742884,"mc":[{"id":"1.229554915","rc":[{"atb":[[18,12.29],[21,10.45],[26,4.18]],"id":51562794},{"atl":[[360,0.38],[460,0.45]],"id":51562794},{"atb":[[3.6,80.4],[3.85,73.35],[4.2,32.66]],"id":46292327},{"atl":[[32,6.74],[21,6.96]],"id":46292327},{"atb":[[8,29.86],[9,13.06],[7,34.84]],"id":65788088},{"atl":[[210,0.99],[110,1.27]],"id":65788088},{"atb":[[36,5.97],[46,2.32],[28,7.74]],"id":42099039},{"atl":[[590,0.35],[490,0.28]],"id":42099039}],"con":true,"img":false}]}
{"op":"mcm","clk":"11449924797","pt":1717316009720,"mc":[{"id":"1.229554915","rc":[{"atb":[[18,0],[21,0],[26,0]],"id":51562794},{"atl":[[360,0],[460,0]],"id":51562794},{"atb":[[3.6,0],[3.85,0],[4.2,0]],"id":46292327},{"atl":[[32,0],[21,0]],"id":46292327},{"atb":[[8.6,0],[7.6,0],[6.6,0]],"id":56606596},{"atl":[[100,0],[200,0]],"id":56606596},{"spn":496.52,"spf":"NaN","id":56606596},{"atb":[[8,0],[9,0],[7,0]],"id":65788088},{"atl":[[210,0],[110,0]],"id":65788088},{"atb":[[36,0],[46,0],[28,0]],"id":42099039},{"atl":[[590,0],[490,0]],"id":42099039},{"atb":[[2.86,0],[3.15,0],[2.96,0]],"id":65293046},{"atl":[[16,0],[11,0]],"id":65293046},{"spn":17.75,"spf":"NaN","id":65293046},{"atb":[[4.8,0],[5.8,0],[5.3,0]],"id":70003370},{"atl":[[48,0],[29,0]],"id":70003370},{"spn":501.06,"spf":"NaN","id":70003370},{"atb":[[1.63,0],[1.58,0],[1.68,0]],"id":64927898},{"atl":[[3.7,0],[4.4,0]],"id":64927898},{"spn":17.76,"spf":"NaN","id":64927898}],"con":true,"img":false}]}
{"op":"mcm","clk":"11449926999","pt":1717316032550,"mc":[{"id":"1.229554915","rc":[{"atb":[[18,12.29],[21,10.45],[26,4.18]],"id":51562794},{"atl":[[360,0.38],[460,0.45]],"id":51562794},{"atb":[[3.6,80.4],[3.85,73.35],[4.2,32.66]],"id":46292327},{"atl":[[32,6.74],[21,6.96]],"id":46292327},{"atb":[[8.6,13.75],[7.6,31.67],[6.6,37.33]],"id":56606596},{"atl":[[100,1.4],[200,1.05]],"id":56606596},{"atb":[[8,29.86],[9,13.06],[7,34.84]],"id":65788088},{"atl":[[210,0.99],[110,1.27]],"id":65788088},{"atb":[[36,5.97],[46,2.32],[28,7.74]],"id":42099039},{"atl":[[590,0.35],[490,0.28]],"id":42099039},{"atb":[[2.86,112.39],[3.15,48.61],[2.96,106.66]],"id":65293046},{"atl":[[16,13.93],[11,13.93]],"id":65293046},{"atb":[[4.8,55.01],[5.8,21.77],[5.3,48.61]],"id":70003370},{"atl":[[48,4.44],[29,4.97]],"id":70003370},{"atb":[[1.63,331.84],[1.58,360.45],[1.68,153.71]],"id":64927898},{"atl":[[3.7,51.62],[4.4,61.48]],"id":64927898}],"con":true,"img":false}]}
{"op":"mcm","clk":"11449990640","pt":1717316832932,"mc":[{"id":"1.229554915","rc":[{"atl":[[1000,1.85]],"id":51562794},{"spn":193.0,"spf":"NaN","id":51562794},{"atl":[[1000,1.85]],"id":46292327},{"spn":12.6,"spf":"NaN","id":46292327},{"atl":[[1000,1]],"id":56606596},{"spn":54.3,"spf":"NaN","id":56606596},{"atl":[[1000,1]],"id":65788088},{"spn":59.5,"spf":"NaN","id":65788088},{"atl":[[1000,1]],"id":42099039},{"spn":268.0,"spf":"NaN","id":42099039},{"atl":[[1000,1]],"id":65293046},{"spn":7.07,"spf":"NaN","id":65293046},{"atl":[[1000,1.85]],"id":70003370},{"spn":17.4,"spf":"NaN","id":70003370},{"atl":[[1000,1]],"id":64927898},{"spn":2.69,"spf":"NaN","id":64927898}],"con":true,"img":false}]}
{"op":"mcm","clk":"11449993608","pt":1717316870264,"mc":[{"id":"1.229554915","rc":[{"atb":[[18,0],[21,0],[26,0]],"id":51562794},{"atl":[[360,0],[460,0]],"id":51562794},{"atb":[[3.6,0],[3.85,0],[4.2,0]],"id":46292327},{"atl":[[32,0],[21,0]],"id":46292327},{"atb":[[8.6,0],[7.6,0],[6.6,0]],"id":56606596},{"atl":[[100,0],[200,0]],"id":56606596},{"atb":[[8,0],[9,0],[7,0]],"id":65788088},{"atl":[[210,0],[110,0]],"id":65788088},{"atb":[[36,0],[46,0],[28,0]],"id":42099039},{"atl":[[590,0],[490,0]],"id":42099039},{"atb":[[2.86,0],[3.15,0],[2.96,0]],"id":65293046},{"atl":[[16,0],[11,0]],"id":65293046},{"atb":[[4.8,0],[5.8,0],[5.3,0]],"id":70003370},{"atl":[[48,0],[29,0]],"id":70003370},{"atb":[[1.63,0],[1.58,0],[1.68,0]],"id":64927898},{"atl":[[3.7,0],[4.4,0]],"id":64927898}],"con":true,"img":false}]}
{"op":"mcm","clk":"11449995452","pt":1717316891206,"mc":[{"id":"1.229554915","rc":[{"atb":[[18,12.29],[21,10.45],[26,4.18]],"id":51562794},{"atl":[[360,0.38],[460,0.45]],"id":51562794},{"atb":[[3.6,80.4],[3.85,73.35],[4.2,32.66]],"id":46292327},{"atl":[[32,6.74],[21,6.96]],"id":46292327},{"atb":[[8.6,13.75],[7.6,31.67],[6.6,37.33]],"id":56606596},{"atl":[[100,1.4],[200,1.05]],"id":56606596},{"atb":[[8,29.86],[9,13.06],[7,34.84]],"id":65788088},{"atl":[[210,0.99],[110,1.27]],"id":65788088},{"atb":[[36,5.97],[46,2.32],[28,7.74]],"id":42099039},{"atl":[[590,0.35],[490,0.28]],"id":42099039},{"atb":[[4.8,55.01],[5.8,21.77],[5.3,48.61]],"id":70003370},{"atl":[[48,4.44],[29,4.97]],"id":70003370},{"atb":[[2.86,112.39],[3.15,48.61],[2.96,106.66]],"id":65293046},{"atl":[[16,13.93],[11,13.93]],"id":65293046},{"atb":[[1.63,331.84],[1.58,360.45],[1.68,153.71]],"id":64927898},{"atl":[[3.7,51.62],[4.4,61.48]],"id":64927898}],"con":true,"img":false}]}
{"op":"mcm","clk":"11450003970","pt":1717316992450,"mc":[{"id":"1.229554915","rc":[{"atb":[[18,0],[21,0],[26,0]],"id":51562794},{"atl":[[360,0],[460,0]],"id":51562794},{"spn":503.1,"spf":"NaN","id":51562794},{"atb":[[3.6,0],[3.85,0],[4.2,0]],"id":46292327},{"atl":[[32,0],[21,0]],"id":46292327},{"spn":500.75,"spf":"NaN","id":46292327},{"atb":[[8.6,0],[7.6,0],[6.6,0]],"id":56606596},{"atl":[[100,0],[200,0]],"id":56606596},{"spn":496.52,"spf":"NaN","id":56606596},{"atb":[[8,0],[9,0],[7,0]],"id":65788088},{"atl":[[210,0],[110,0]],"id":65788088},{"spn":496.52,"spf":"NaN","id":65788088},{"atb":[[36,0],[46,0],[28,0]],"id":42099039},{"atl":[[590,0],[490,0]],"id":42099039},{"spn":498.1,"spf":"NaN","id":42099039},{"atb":[[2.86,0],[3.15,0],[2.96,0]],"id":65293046},{"atl":[[16,0],[11,0]],"id":65293046},{"spn":17.75,"spf":"NaN","id":65293046},{"atb":[[4.8,0],[5.8,0],[5.3,0]],"id":70003370},{"atl":[[48,0],[29,0]],"id":70003370},{"spn":501.06,"spf":"NaN","id":70003370},{"atb":[[1.63,0],[1.58,0],[1.68,0]],"id":64927898},{"atl":[[3.7,0],[4.4,0]],"id":64927898},{"spn":17.76,"spf":"NaN","id":64927898}],"con":true,"img":false}]}
{"op":"mcm","clk":"11450006471","pt":1717317018552,"mc":[{"id":"1.229554915","rc":[{"atb":[[18,12.29],[21,10.45],[26,4.18]],"id":51562794},{"atl":[[360,0.38],[460,0.45]],"id":51562794},{"atb":[[3.6,80.4],[3.85,73.35],[4.2,32.66]],"id":46292327},{"atl":[[32,6.74],[21,6.96]],"id":46292327},{"atb":[[8.6,13.75],[7.6,31.67],[6.6,37.33]],"id":56606596},{"atl":[[100,1.4],[200,1.05]],"id":56606596},{"atb":[[8,29.86],[9,13.06],[7,34.84]],"id":65788088},{"atl":[[210,0.99],[110,1.27]],"id":65788088},{"atb":[[36,5.97],[46,2.32],[28,7.74]],"id":42099039},{"atl":[[590,0.35],[490,0.28]],"id":42099039},{"atb":[[4.8,55.01],[5.8,21.77],[5.3,48.61]],"id":70003370},{"atl":[[48,4.44],[29,4.97]],"id":70003370},{"atb":[[2.86,112.39],[3.15,48.61],[2.96,106.66]],"id":65293046},{"atl":[[16,13.93],[11,13.93]],"id":65293046},{"atb":[[1.63,331.84],[1.58,360.45],[1.68,153.71]],"id":64927898},{"atl":[[3.7,51.62],[4.4,61.48]],"id":64927898}],"con":true,"img":false}]}
{"op":"mcm","clk":"11450029245","pt":1717317249153,"mc":[{"id":"1.229554915","rc":[{"atb":[[22,5.75],[27,2.61]],"id":51562794},{"atl":[[410,0.13],[450,2.61]],"id":51562794},{"spn":193.5,"spf":"NaN","id":51562794},{"atb":[[4.9,30.86],[5.9,11.45]],"id":46292327},{"atl":[[27,2.61],[30,4.18]],"id":46292327},{"spn":13.45,"spf":"NaN","id":46292327},{"atb":[[7.8,17.31],[8.4,7.58]],"id":56606596},{"atl":[[44,2.61],[60,2.61]],"id":56606596},{"spn":26.3,"spf":"NaN","id":56606596},{"atb":[[9,20.08],[8.2,14.2]],"id":65788088},{"atl":[[65,2.61],[48,2.61]],"id":65788088},{"spn":28.5,"spf":"NaN","id":65788088},{"atb":[[40,2.83],[50,2.61]],"id":42099039},{"spn":270.0,"spf":"NaN","id":42099039},{"atb":[[2.98,56.81],[3.3,24.39]],"id":65293046},{"atl":[[11.5,5.34],[15.5,7.75]],"id":65293046},{"spn":7.15,"spf":"NaN","id":65293046},{"atb":[[6.4,10.39],[5.4,24.37]],"id":70003370},{"atl":[[42,2.61],[30,2.61]],"id":70003370},{"spn":17.7,"spf":"NaN","id":70003370},{"atb":[[1.73,76.86],[1.69,175.26]],"id":64927898},{"atl":[[4.3,36.62],[4.2,17.53]],"id":64927898},{"spn":2.71,"spf":"NaN","id":64927898}],"con":true,"img":false}]}
{"op":"mcm","clk":"11450037355","pt":1717317325542,"mc":[{"id":"1.229554915","rc":[{"atl":[[410,0]],"id":51562794},{"atb":[[8.4,0]],"id":56606596},{"atb":[[9,13.06]],"id":65788088},{"atb":[[5.4,0]],"id":70003370},{"atl":[[30,0]],"id":70003370},{"atb":[[2.98,0]],"id":65293046},{"atl":[[11.5,0]],"id":65293046}],"con":true,"img":false}]}
{"op":"mcm","clk":"11450037366","pt":1717317325646,"mc":[{"id":"1.229554915","rc":[{"atl":[[350,0.13]],"id":51562794},{"atb":[[8.8,7.58]],"id":56606596},{"atb":[[9.2,7.01]],"id":65788088},{"atb":[[3.2,56.81]],"id":65293046},{"atl":[[10.5,5.34]],"id":65293046},{"atb":[[5.9,24.37]],"id":70003370},{"atl":[[28,2.61]],"id":70003370}],"con":true,"img":false}]}
{"op":"mcm","clk":"11450076071","pt":1717317730477,"mc":[{"id":"1.229554915","rc":[{"atb":[[18,0],[21,0],[26,0]],"id":51562794},{"atl":[[360,0],[460,0]],"id":51562794},{"spn":188.5,"spf":"NaN","id":51562794},{"atb":[[3.6,0],[3.85,0],[4.2,0]],"id":46292327},{"atl":[[32,0],[21,0]],"id":46292327},{"spn":16.45,"spf":"NaN","id":46292327},{"atb":[[8.6,0],[7.6,0],[6.6,0]],"id":56606596},{"atl":[[100,0],[200,0]],"id":56606596},{"spn":26.4,"spf":"NaN","id":56606596},{"atb":[[8,0],[9,0],[7,0]],"id":65788088},{"atl":[[210,0],[110,0]],"id":65788088},{"spn":28.6,"spf":"NaN","id":65788088},{"atb":[[36,0],[46,0],[28,0]],"id":42099039},{"atl":[[590,0],[490,0]],"id":42099039},{"spn":520.0,"spf":"NaN","id":42099039},{"atb":[[4.8,0],[5.8,0],[5.3,0]],"id":70003370},{"atl":[[48,0],[29,0]],"id":70003370},{"spn":17.2,"spf":"NaN","id":70003370},{"atb":[[2.86,0],[3.15,0],[2.96,0]],"id":65293046},{"atl":[[16,0],[11,0]],"id":65293046},{"spn":6.9,"spf":"NaN","id":65293046},{"atb":[[1.63,0],[1.58,0],[1.68,0]],"id":64927898},{"atl":[[3.7,0],[4.4,0]],"id":64927898},{"spn":2.96,"spf":"NaN","id":64927898}],"con":true,"img":false}]}
{"op":"mcm","clk":"11450078216","pt":1717317753972,"mc":[{"id":"1.229554915","rc":[{"atb":[[18,12.29],[21,10.45],[26,4.18]],"id":51562794},{"atl":[[360,0.38],[460,0.45]],"id":51562794},{"atb":[[3.6,80.4],[3.85,73.35],[4.2,32.66]],"id":46292327},{"atl":[[32,6.74],[21,6.96]],"id":46292327},{"atb":[[8.6,13.75],[7.6,31.67],[6.6,37.33]],"id":56606596},{"atl":[[100,1.4],[200,1.05]],"id":56606596},{"atb":[[8,29.86],[9,13.06],[7,34.84]],"id":65788088},{"atl":[[210,0.99],[110,1.27]],"id":65788088},{"atb":[[36,5.97],[46,2.32],[28,7.74]],"id":42099039},{"atl":[[590,0.35],[490,0.28]],"id":42099039},{"atb":[[2.86,112.39],[3.15,48.61],[2.96,106.66]],"id":65293046},{"atl":[[16,13.93],[11,13.93]],"id":65293046},{"atb":[[4.8,55.01],[5.8,21.77],[5.3,48.61]],"id":70003370},{"atl":[[48,4.44],[29,4.97]],"id":70003370},{"atb":[[1.63,331.84],[1.58,360.45],[1.68,153.71]],"id":64927898},{"atl":[[3.7,51.62],[4.4,61.48]],"id":64927898}],"con":true,"img":false}]}
{"op":"mcm","clk":"11450085772","pt":1717317842946,"mc":[{"id":"1.229554915","rc":[{"spn":13.45,"spf":"NaN","id":46292327},{"atl":[[65,0],[48,0]],"id":65788088},{"spn":59.6,"spf":"NaN","id":65788088},{"atb":[[50,0]],"id":42099039},{"spn":268.0,"spf":"NaN","id":42099039},{"spn":2.71,"spf":"NaN","id":64927898}],"con":true,"img":false}]}
{"op":"mcm","clk":"11450085782","pt":1717317843045,"mc":[{"id":"1.229554915","rc":[{"atl":[[75,2.61],[55,2.61]],"id":65788088},{"atb":[[55,2.61]],"id":42099039}],"con":true,"img":false}]}
{"op":"mcm","clk":"11450088120","pt":1717317869776,"mc":[{"id":"1.229554915","rc":[{"atb":[[18,0],[21,0],[26,0]],"id":51562794},{"atl":[[360,0],[460,0]],"id":51562794},{"atb":[[3.6,0],[3.85,0],[4.2,0]],"id":46292327},{"atl":[[32,0],[21,0]],"id":46292327},{"atb":[[8.6,0],[7.6,0],[6.6,0]],"id":56606596},{"atl":[[100,0],[200,0]],"id":56606596},{"atb":[[8,0],[9,0],[7,0]],"id":65788088},{"atl":[[210,0],[110,0]],"id":65788088},{"atb":[[36,0],[46,0],[28,0]],"id":42099039},{"atl":[[590,0],[490,0]],"id":42099039},{"atb":[[2.86,0],[3.15,0],[2.96,0]],"id":65293046},{"atl":[[16,0],[11,0]],"id":65293046},{"atb":[[4.8,0],[5.8,0],[5.3,0]],"id":70003370},{"atl":[[48,0],[29,0]],"id":70003370},{"atb":[[1.63,0],[1.58,0],[1.68,0]],"id":64927898},{"atl":[[3.7,0],[4.4,0]],"id":64927898}],"con":true,"img":false}]}
{"op":"mcm","clk":"11450088746","pt":1717317876598,"mc":[{"id":"1.229554915","rc":[{"atl":[[350,0],[450,0]],"id":51562794},{"atl":[[38,3.13]],"id":46292327},{"atb":[[8.8,0],[7.8,0]],"id":56606596},{"atb":[[9.2,0]],"id":65788088},{"atb":[[40,0]],"id":42099039},{"atb":[[3.2,0]],"id":65293046},{"atl":[[10.5,0]],"id":65293046},{"atb":[[5.9,0]],"id":70003370},{"atl":[[28,0]],"id":70003370},{"atb":[[1.69,0]],"id":64927898},{"atl":[[5.6,26.15]],"id":64927898}],"con":true,"img":false}]}
{"op":"mcm","clk":"11450088760","pt":1717317876652,"mc":[{"id":"1.229554915","rc":[{"atl":[[580,2.61],[410,0.13]],"id":51562794},{"atb":[[8.2,7.58],[6.8,17.31]],"id":56606596},{"atb":[[9.6,7.01]],"id":65788088},{"atb":[[46,2.83]],"id":42099039},{"atb":[[5.2,24.37]],"id":70003370},{"atl":[[30,2.61]],"id":70003370},{"atb":[[2.82,56.81]],"id":65293046},{"atl":[[11.5,5.34]],"id":65293046},{"atb":[[1.6,175.26]],"id":64927898}],"con":true,"img":false}]}
{"op":"mcm","clk":"11450089853","pt":1717317888807,"mc":[{"id":"1.229554915","rc":[{"atb":[[18,12.29],[21,10.45],[26,4.18]],"id":51562794},{"atl":[[360,0.38],[460,0.45]],"id":51562794},{"atb":[[3.6,80.4],[3.85,73.35],[4.2,32.66]],"id":46292327},{"atl":[[32,6.74],[21,6.96]],"id":46292327},{"atb":[[8.6,13.75],[7.6,31.67],[6.6,37.33]],"id":56606596},{"atl":[[100,1.4],[200,1.05]],"id":56606596},{"atb":[[8,29.86],[9,13.06],[7,34.84]],"id":65788088},{"atl":[[210,0.99],[110,1.27]],"id":65788088},{"atb":[[36,5.97],[46,5.15],[28,7.74]],"id":42099039},{"atl":[[590,0.35],[490,0.28]],"id":42099039},{"atb":[[2.86,112.39],[3.15,48.61],[2.96,106.66]],"id":65293046},{"atl":[[16,13.93],[11,13.93]],"id":65293046},{"atb":[[4.8,55.01],[5.8,21.77],[5.3,48.61]],"id":70003370},{"atl":[[48,4.44],[29,4.97]],"id":70003370},{"atb":[[1.63,331.84],[1.58,360.45],[1.68,153.71]],"id":64927898},{"atl":[[3.7,51.62],[4.4,61.48]],"id":64927898}],"con":true,"img":false}]}
{"op":"mcm","clk":"11450090914","pt":1717317900904,"mc":[{"id":"1.229554915","rc":[{"atl":[[38,0],[30,0]],"id":46292327},{"atl":[[5.6,0],[4.3,0]],"id":64927898}],"con":true,"img":false}]}
{"op":"mcm","clk":"11450093972","pt":1717317934339,"mc":[{"id":"1.229554915","rc":[{"spn":193.5,"spf":"NaN","id":51562794},{"spn":26.3,"spf":"NaN","id":56606596},{"spn":32.3,"spf":"NaN","id":65788088},{"spn":272.5,"spf":"NaN","id":42099039},{"spn":7.15,"spf":"NaN","id":65293046},{"spn":17.7,"spf":"NaN","id":70003370},{"atl":[[16,10]],"id":64927898}],"con":true,"img":false}]}
{"op":"mcm","clk":"11450095269","pt":1717317948882,"mc":[{"id":"1.229554915","rc":[{"atl":[[580,0],[410,0]],"id":51562794},{"atl":[[27,0],[30,4.18]],"id":46292327},{"atb":[[8.2,0],[6.8,0]],"id":56606596},{"atb":[[8.2,0]],"id":65788088},{"atb":[[2.82,0]],"id":65293046},{"atl":[[11.5,0]],"id":65293046},{"atb":[[5.2,0]],"id":70003370},{"atl":[[30,0]],"id":70003370},{"atb":[[1.6,0]],"id":64927898},{"atl":[[4.3,36.62],[4.2,0]],"id":64927898}],"con":true,"img":false}]}
{"op":"mcm","clk":"11450095278","pt":1717317948984,"mc":[{"id":"1.229554915","rc":[{"atl":[[400,0.13],[450,2.61]],"id":51562794},{"atl":[[26,2.61]],"id":46292327},{"atb":[[8.8,7.58],[7.8,17.31]],"id":56606596},{"atb":[[9.2,14.2]],"id":65788088},{"atb":[[3.2,56.81]],"id":65293046},{"atl":[[10.5,5.34]],"id":65293046},{"atb":[[5.9,24.37]],"id":70003370},{"atl":[[28,2.61]],"id":70003370},{"atb":[[1.69,175.26]],"id":64927898},{"atl":[[4.1,17.53]],"id":64927898}],"con":true,"img":false}]}
{"op":"mcm","clk":"11450101103","pt":1717318019831,"mc":[{"id":"1.229554915","rc":[{"atl":[[400,0]],"id":51562794},{"spn":26.4,"spf":"NaN","id":56606596},{"spn":6.9,"spf":"NaN","id":65293046},{"spn":17.2,"spf":"NaN","id":70003370}],"con":true,"img":false}]}
{"op":"mcm","clk":"11450101114","pt":1717318019939,"mc":[{"id":"1.229554915","rc":[{"atl":[[350,0.13]],"id":51562794}],"con":true,"img":false}]}
{"op":"mcm","clk":"11450117118","pt":1717318195963,"mc":[{"id":"1.229554915","rc":[{"spn":188.5,"spf":"NaN","id":51562794},{"atb":[[2.12,44.64]],"id":46292327}],"con":true,"img":false}]}
{"op":"mcm","clk":"11450150228","pt":1717318577431,"mc":[{"id":"1.229554915","rc":[{"atb":[[18,0],[21,0],[26,0]],"id":51562794},{"atl":[[360,0],[460,0]],"id":51562794},{"atb":[[3.6,0],[3.85,0],[4.2,0]],"id":46292327},{"atl":[[32,0],[21,0]],"id":46292327},{"spn":15.95,"spf":"NaN","id":46292327},{"atb":[[8.6,0],[7.6,0],[6.6,0]],"id":56606596},{"atl":[[100,0],[200,0]],"id":56606596},{"atb":[[8,0],[9,0],[7,0]],"id":65788088},{"atl":[[210,0],[110,0]],"id":65788088},{"atb":[[36,0],[46,2.83],[28,0]],"id":42099039},{"atl":[[590,0],[490,0]],"id":42099039},{"spn":522.5,"spf":"NaN","id":42099039},{"atb":[[2.86,0],[3.15,0],[2.96,0]],"id":65293046},{"atl":[[16,0],[11,0]],"id":65293046},{"atb":[[4.8,0],[5.8,0],[5.3,0]],"id":70003370},{"atl":[[48,0],[29,0]],"id":70003370},{"atb":[[1.63,0],[1.58,0],[1.68,0]],"id":64927898},{"atl":[[3.7,0],[4.4,0]],"id":64927898},{"spn":2.91,"spf":"NaN","id":64927898}],"con":true,"img":false}]}
{"op":"mcm","clk":"11450151025","pt":1717318585897,"mc":[{"id":"1.229554915","rc":[{"atl":[[350,0],[450,0]],"id":51562794},{"atl":[[38,3.13],[30,0]],"id":46292327},{"atb":[[8.8,0],[7.8,0]],"id":56606596},{"atb":[[9.2,0]],"id":65788088},{"atb":[[3.2,0]],"id":65293046},{"atl":[[10.5,0]],"id":65293046},{"atb":[[5.9,0]],"id":70003370},{"atl":[[28,0]],"id":70003370},{"atb":[[1.69,0]],"id":64927898},{"atl":[[5.6,26.15],[4.3,0]],"id":64927898}],"con":true,"img":false}]}
{"op":"mcm","clk":"11450151035","pt":1717318585998,"mc":[{"id":"1.229554915","rc":[{"atl":[[580,2.61],[410,0.13]],"id":51562794},{"atb":[[8.2,7.58],[6.8,17.31]],"id":56606596},{"atb":[[7.8,14.2]],"id":65788088},{"atb":[[2.82,56.81]],"id":65293046},{"atl":[[11.5,5.34]],"id":65293046},{"atb":[[5.2,24.37]],"id":70003370},{"atl":[[30,2.61]],"id":70003370},{"atb":[[1.6,175.26]],"id":64927898}],"con":true,"img":false}]}
{"op":"mcm","clk":"11450151751","pt":1717318593147,"mc":[{"id":"1.229554915","rc":[{"atb":[[18,12.29],[21,10.45],[26,4.18]],"id":51562794},{"atl":[[360,0.38],[460,0.45]],"id":51562794},{"atb":[[3.6,80.4],[3.85,73.35],[4.2,32.66]],"id":46292327},{"atl":[[32,6.74],[21,6.96]],"id":46292327},{"atb":[[8.6,13.75],[7.6,31.67],[6.6,37.33]],"id":56606596},{"atl":[[100,1.4],[200,1.05]],"id":56606596},{"atb":[[8,29.86],[9,13.06],[7,34.84]],"id":65788088},{"atl":[[210,0.99],[110,1.27]],"id":65788088},{"atb":[[36,5.97],[46,5.15],[28,7.74]],"id":42099039},{"atl":[[590,0.35],[490,0.28]],"id":42099039},{"atb":[[4.8,55.01],[5.8,21.77],[5.3,48.61]],"id":70003370},{"atl":[[48,4.44],[29,4.97]],"id":70003370},{"atb":[[2.86,112.39],[3.15,48.61],[2.96,106.66]],"id":65293046},{"atl":[[16,13.93],[11,13.93]],"id":65293046},{"atb":[[1.63,331.84],[1.58,360.45],[1.68,153.71]],"id":64927898},{"atl":[[3.7,51.62],[4.4,61.48]],"id":64927898}],"con":true,"img":false}]}
{"op":"mcm","clk":"11450155596","pt":1717318633020,"mc":[{"id":"1.229554915","rc":[{"atl":[[1000,1.17]],"id":51562794},{"atl":[[1000,1.17]],"id":46292327},{"atl":[[990,0.17]],"id":56606596},{"atl":[[990,0.17]],"id":65788088},{"atl":[[990,0.17]],"id":42099039},{"atl":[[990,0.17]],"id":65293046},{"atl":[[1000,1.17]],"id":70003370},{"atl":[[990,0.17]],"id":64927898}],"con":true,"img":false}]}
{"op":"mcm","clk":"11450157906","pt":1717318653923,"mc":[{"id":"1.229554915","rc":[{"atl":[[580,0],[410,0]],"id":51562794},{"spn":193.5,"spf":"NaN","id":51562794},{"atl":[[38,0],[30,4.18]],"id":46292327},{"spn":13.45,"spf":"NaN","id":46292327},{"atb":[[8.2,0],[6.8,0]],"id":56606596},{"spn":26.3,"spf":"NaN","id":56606596},{"atb":[[7.8,0]],"id":65788088},{"spn":272.5,"spf":"NaN","id":42099039},{"atb":[[5.2,0]],"id":70003370},{"atl":[[30,0]],"id":70003370},{"spn":17.7,"spf":"NaN","id":70003370},{"atb":[[2.82,0]],"id":65293046},{"atl":[[11.5,0]],"id":65293046},{"spn":7.15,"spf":"NaN","id":65293046},{"atb":[[1.6,0]],"id":64927898},{"atl":[[5.6,0],[4.3,36.62]],"id":64927898},{"spn":2.71,"spf":"NaN","id":64927898}],"con":true,"img":false}]}
{"op":"mcm","clk":"11450157918","pt":1717318654023,"mc":[{"id":"1.229554915","rc":[{"atl":[[400,0.13],[450,2.61]],"id":51562794},{"atb":[[8.8,7.58],[7.8,17.31]],"id":56606596},{"atb":[[8.2,14.2]],"id":65788088},{"atb":[[3.2,56.81]],"id":65293046},{"atl":[[10.5,5.34]],"id":65293046},{"atb":[[5.9,24.37]],"id":70003370},{"atl":[[28,2.61]],"id":70003370},{"atb":[[1.69,175.26]],"id":64927898}],"con":true,"img":false}]}
{"op":"mcm","clk":"11450163835","pt":1717318715386,"mc":[{"id":"1.229554915","rc":[{"atb":[[1.03,111.7]],"id":51562794},{"atl":[[980,1.92]],"id":51562794},{"atb":[[1.04,79.25]],"id":46292327},{"atl":[[960,0.85]],"id":46292327},{"atb":[[1.02,123.56]],"id":56606596},{"atl":[[980,0.85]],"id":56606596},{"spn":26.4,"spf":"NaN","id":56606596},{"atb":[[1.02,122.7]],"id":65788088},{"atl":[[990,2.13]],"id":65788088},{"atb":[[1.02,101.4]],"id":42099039},{"atl":[[980,1.47]],"id":42099039},{"atb":[[1.04,111.63]],"id":70003370},{"atl":[[990,1.96]],"id":70003370},{"spn":17.2,"spf":"NaN","id":70003370},{"atb":[[1.04,105.66]],"id":65293046},{"atl":[[970,0.85]],"id":65293046},{"spn":6.9,"spf":"NaN","id":65293046},{"atb":[[1.03,164.46]],"id":64927898},{"atl":[[970,1.17]],"id":64927898}],"con":true,"img":false}]}
{"op":"mcm","clk":"11450164650","pt":1717318724082,"mc":[{"id":"1.229554915","rc":[{"atb":[[18,0],[21,0],[26,0]],"id":51562794},{"atl":[[360,0],[460,0]],"id":51562794},{"atb":[[3.6,0],[3.85,0],[4.2,0]],"id":46292327},{"atl":[[32,0],[21,0]],"id":46292327},{"atb":[[8.6,0],[7.6,0],[6.6,0]],"id":56606596},{"atl":[[100,0],[200,0]],"id":56606596},{"atb":[[8,0],[9,0],[7,0]],"id":65788088},{"atl":[[210,0],[110,0]],"id":65788088},{"atb":[[36,0],[46,2.83],[28,0]],"id":42099039},{"atl":[[590,0],[490,0]],"id":42099039},{"atb":[[2.86,0],[3.15,0],[2.96,0]],"id":65293046},{"atl":[[16,0],[11,0]],"id":65293046},{"atb":[[4.8,0],[5.8,0],[5.3,0]],"id":70003370},{"atl":[[48,0],[29,0]],"id":70003370},{"atb":[[1.63,0],[1.58,0],[1.68,0]],"id":64927898},{"atl":[[3.7,0],[4.4,0]],"id":64927898}],"con":true,"img":false}]}
{"op":"mcm","clk":"11450164915","pt":1717318726884,"mc":[{"id":"1.229554915","rc":[{"atl":[[450,0]],"id":51562794},{"atl":[[38,3.13],[30,0]],"id":46292327},{"atb":[[8.8,0],[7.8,0]],"id":56606596},{"atb":[[5.9,0]],"id":70003370},{"atl":[[28,0]],"id":70003370},{"atb":[[3.2,0]],"id":65293046},{"atl":[[10.5,0]],"id":65293046},{"atb":[[1.69,0]],"id":64927898},{"atl":[[5.6,26.15],[4.3,0]],"id":64927898}],"con":true,"img":false}]}
{"op":"mcm","clk":"11450164924","pt":1717318726990,"mc":[{"id":"1.229554915","rc":[{"atl":[[580,2.61]],"id":51562794},{"atb":[[8.2,7.58],[6.8,17.31]],"id":56606596},{"atb":[[2.82,56.81]],"id":65293046},{"atl":[[11.5,5.34]],"id":65293046},{"atb":[[5.2,24.37]],"id":70003370},{"atl":[[30,2.61]],"id":70003370},{"atb":[[1.6,175.26]],"id":64927898}],"con":true,"img":false}]}
{"op":"mcm","clk":"11450166303","pt":1717318742709,"mc":[{"id":"1.229554915","rc":[{"atb":[[18,12.29],[21,10.45],[26,4.18]],"id":51562794},{"atl":[[360,0.38],[460,0.45]],"id":51562794},{"atb":[[3.6,80.4],[3.85,73.35],[4.2,32.66]],"id":46292327},{"atl":[[32,6.74],[21,6.96]],"id":46292327},{"atb":[[8.6,13.75],[7.6,31.67],[6.6,37.33]],"id":56606596},{"atl":[[100,1.4],[200,1.05]],"id":56606596},{"atb":[[8,29.86],[9,13.06],[7,34.84]],"id":65788088},{"atl":[[210,0.99],[110,1.27]],"id":65788088},{"atb":[[36,5.97],[46,5.15],[28,7.74]],"id":42099039},{"atl":[[590,0.35],[490,0.28]],"id":42099039},{"atb":[[4.8,55.01],[5.8,21.77],[5.3,48.61]],"id":70003370},{"atl":[[48,4.44],[29,4.97]],"id":70003370},{"atb":[[2.86,112.39],[3.15,48.61],[2.96,106.66]],"id":65293046},{"atl":[[16,13.93],[11,13.93]],"id":65293046},{"atb":[[1.63,331.84],[1.58,360.45],[1.68,153.71]],"id":64927898},{"atl":[[3.7,51.62],[4.4,61.48]],"id":64927898}],"con":true,"img":false}]}
{"op":"mcm","clk":"11450171626","pt":1717318801669,"mc":[{"id":"1.229554915","rc":[{"atl":[[580,0],[400,0]],"id":51562794},{"atl":[[30,4.18]],"id":46292327},{"atb":[[8.2,0],[6.8,0]],"id":56606596},{"spn":26.3,"spf":"NaN","id":56606596},{"atb":[[8.2,0]],"id":65788088},{"atb":[[2.82,0]],"id":65293046},{"atl":[[11.5,0]],"id":65293046},{"spn":7.15,"spf":"NaN","id":65293046},{"atb":[[5.2,0]],"id":70003370},{"atl":[[30,0]],"id":70003370},{"spn":17.7,"spf":"NaN","id":70003370},{"atb":[[1.6,0]],"id":64927898},{"atl":[[4.3,36.62]],"id":64927898}],"con":true,"img":false}]}
{"op":"mcm","clk":"11450171637","pt":1717318801770,"mc":[{"id":"1.229554915","rc":[{"atl":[[390,0.13],[450,2.61]],"id":51562794},{"atl":[[38,0]],"id":46292327},{"atb":[[8.8,7.58],[7.8,17.31]],"id":56606596},{"atb":[[9.2,14.2]],"id":65788088},{"atb":[[3.2,56.81]],"id":65293046},{"atl":[[10.5,5.34]],"id":65293046},{"atb":[[5.9,24.37]],"id":70003370},{"atl":[[28,2.61]],"id":70003370},{"atb":[[1.69,175.26]],"id":64927898},{"atl":[[5.6,0]],"id":64927898}],"con":true,"img":false}]}
{"op":"mcm","clk":"11450176810","pt":1717318856221,"mc":[{"id":"1.229554915","rc":[{"atl":[[390,0]],"id":51562794}],"con":true,"img":false}]}
{"op":"mcm","clk":"11450176820","pt":1717318856327,"mc":[{"id":"1.229554915","rc":[{"atl":[[350,0.13]],"id":51562794}],"con":true,"img":false}]}
{"op":"mcm","clk":"11450188874","pt":1717318980457,"mc":[{"id":"1.229554915","rc":[{"atb":[[15.5,6.9]],"id":51562794},{"spn":188.5,"spf":"NaN","id":51562794},{"atb":[[3.5,40]],"id":46292327},{"atl":[[34,3.03]],"id":46292327},{"atb":[[1.98,98.04]],"id":56606596},{"atl":[[60,4.61]],"id":56606596},{"spn":26.4,"spf":"NaN","id":56606596},{"atb":[[6,20]],"id":65788088},{"atl":[[65,2]],"id":65788088},{"atb":[[28,11.44]],"id":42099039},{"atb":[[1.75,113.62]],"id":65293046},{"atl":[[17.5,6.06]],"id":65293046},{"spn":6.9,"spf":"NaN","id":65293046},{"atb":[[2.34,74.63]],"id":70003370},{"atl":[[36,2.86]],"id":70003370},{"spn":17.2,"spf":"NaN","id":70003370},{"atl":[[8.6,13.16]],"id":64927898}],"con":true,"img":false}]}
{"op":"mcm","clk":"11450188893","pt":1717318980666,"mc":[{"id":"1.229554915","rc":[{"atl":[[350,0]],"id":51562794}],"con":true,"img":false}]}
{"op":"mcm","clk":"11450188903","pt":1717318980767,"mc":[{"id":"1.229554915","rc":[{"atl":[[410,0.13]],"id":51562794}],"con":true,"img":false}]}
{"op":"mcm","clk":"11450190444","pt":1717318996583,"mc":[{"id":"1.229554915","rc":[{"atb":[[6,0],[5.4,22.73]],"id":65788088},{"atb":[[32,3.23],[28,7.74]],"id":42099039},{"atl":[[17.5,0],[21,5]],"id":65293046},{"atl":[[8.6,0],[10.5,10.53]],"id":64927898}],"con":true,"img":false}]}
{"op":"mcm","clk":"11450192619","pt":1717319019706,"mc":[{"id":"1.229554915","rc":[{"atl":[[34,3.24]],"id":70003370}],"con":true,"img":false}]}
{"op":"mcm","clk":"11450192628","pt":1717319019799,"mc":[{"id":"1.229554915","rc":[{"atl":[[410,0]],"id":51562794},{"atl":[[75,0]],"id":65788088},{"atl":[[42,0]],"id":70003370}],"con":true,"img":false}]}
{"op":"mcm","clk":"11450192640","pt":1717319019903,"mc":[{"id":"1.229554915","rc":[{"atl":[[400,0.13]],"id":51562794},{"atl":[[60,2.61]],"id":65788088}],"con":true,"img":false}]}
{"op":"mcm","clk":"11450193585","pt":1717319029335,"mc":[{"id":"1.229554915","rc":[{"atb":[[18,0],[21,0],[26,0]],"id":51562794},{"atl":[[360,0],[460,0]],"id":51562794},{"atb":[[3.6,0],[3.85,0],[4.2,0]],"id":46292327},{"atl":[[32,0],[21,0]],"id":46292327},{"atb":[[8.6,0],[7.6,0],[6.6,0]],"id":56606596},{"atl":[[100,0],[200,0]],"id":56606596},{"atb":[[8,0],[9,0],[7,0]],"id":65788088},{"atl":[[210,0],[110,0]],"id":65788088}],"con":true,"img":false}]}
{"op":"mcm","clk":"11450193607","pt":1717319029659,"mc":[{"id":"1.229554915","rc":[{"atl":[[55,2],[60,2.61]],"id":56606596},{"atl":[[65,0],[70,2]],"id":65788088}],"con":true,"img":false}]}
{"op":"mcm","clk":"11450194675","pt":1717319041272,"mc":[{"id":"1.229554915","rc":[{"atl":[[450,0]],"id":51562794},{"spn":213.5,"spf":"NaN","id":51562794},{"atl":[[30,0]],"id":46292327},{"spn":15.95,"spf":"NaN","id":46292327},{"atb":[[8.8,0],[7.8,0]],"id":56606596},{"spn":23.52,"spf":"NaN","id":56606596},{"atb":[[9.2,0]],"id":65788088},{"atl":[[60,0]],"id":65788088}],"con":true,"img":false}]}
{"op":"mcm","clk":"11450194686","pt":1717319041376,"mc":[{"id":"1.229554915","rc":[{"atl":[[600,2.61]],"id":51562794},{"atl":[[32,4.18]],"id":46292327},{"atb":[[8.2,7.58],[6.8,17.31]],"id":56606596},{"atb":[[7.8,14.2]],"id":65788088},{"atl":[[65,2.61]],"id":65788088}],"con":true,"img":false}]}
{"op":"mcm","clk":"11450194707","pt":1717319041534,"mc":[{"id":"1.229554915","rc":[{"atl":[[400,0]],"id":51562794}],"con":true,"img":false}]}
{"op":"mcm","clk":"11450194714","pt":1717319041634,"mc":[{"id":"1.229554915","rc":[{"atl":[[490,0.13]],"id":51562794}],"con":true,"img":false}]}
{"op":"mcm","clk":"11450194976","pt":1717319044446,"mc":[{"id":"1.229554915","rc":[{"atl":[[600,0]],"id":51562794},{"atl":[[34,0],[42,2.61],[28,0]],"id":70003370},{"atl":[[10.5,0]],"id":65293046}],"con":true,"img":false}]}
{"op":"mcm","clk":"11450194985","pt":1717319044543,"mc":[{"id":"1.229554915","rc":[{"atl":[[700,2.61]],"id":51562794},{"atl":[[29,7.59]],"id":70003370},{"atl":[[11.5,5.34]],"id":65293046}],"con":true,"img":false}]}
{"op":"mcm","clk":"11450195233","pt":1717319047650,"mc":[{"id":"1.229554915","rc":[{"atb":[[19.5,11.3],[24,9.08],[29,3.73]],"id":51562794},{"atl":[[400,0.35],[500,0.41]],"id":51562794},{"atb":[[3.6,80.4],[3.85,73.35],[4.2,32.66]],"id":46292327},{"atl":[[32,10.92],[21,6.96]],"id":46292327},{"atb":[[8.6,13.75],[7.6,31.67],[6.6,37.33]],"id":56606596},{"atl":[[100,1.4],[200,1.05]],"id":56606596},{"atb":[[8,29.86],[9,13.06],[7,34.84]],"id":65788088},{"atl":[[210,0.99],[110,1.27]],"id":65788088}],"con":true,"img":false}]}
{"op":"mcm","clk":"11450197243","pt":1717319071091,"mc":[{"id":"1.229554915","rc":[{"atb":[[27,0]],"id":51562794}],"con":true,"img":false}]}
{"op":"mcm","clk":"11450197253","pt":1717319071202,"mc":[{"id":"1.229554915","rc":[{"atb":[[30,2.61]],"id":51562794}],"con":true,"img":false}]}
{"op":"mcm","clk":"11450198219","pt":1717319081522,"mc":[{"id":"1.229554915","rc":[{"atl":[[490,0]],"id":51562794},{"atb":[[8.2,0]],"id":56606596}],"con":true,"img":false}]}
{"op":"mcm","clk":"11450198227","pt":1717319081616,"mc":[{"id":"1.229554915","rc":[{"atl":[[390,0.13]],"id":51562794},{"atb":[[8.8,7.58]],"id":56606596}],"con":true,"img":false}]}
{"op":"mcm","clk":"11450198600","pt":1717319085423,"mc":[{"id":"1.229554915","rc":[{"atb":[[19.5,0],[24,0],[29,0]],"id":51562794},{"atl":[[400,0],[500,0]],"id":51562794},{"atb":[[3.6,0],[3.85,0],[4.2,0]],"id":46292327},{"atl":[[32,4.18],[21,0]],"id":46292327},{"atb":[[8.6,0],[7.6,0],[6.6,0]],"id":56606596},{"atl":[[100,0],[200,0]],"id":56606596},{"atb":[[8,0],[9,0],[7,0]],"id":65788088},{"atl":[[210,0],[110,0]],"id":65788088},{"atb":[[36,0],[46,2.83],[28,0]],"id":42099039},{"atl":[[590,0],[490,0]],"id":42099039},{"atb":[[4.8,0],[5.8,0],[5.3,0]],"id":70003370},{"atl":[[48,0],[29,2.61]],"id":70003370},{"atb":[[2.86,0],[3.15,0],[2.96,0]],"id":65293046},{"atl":[[16,0],[11,0]],"id":65293046},{"atb":[[1.63,0],[1.58,0],[1.68,0]],"id":64927898},{"atl":[[3.7,0],[4.4,0]],"id":64927898}],"con":true,"img":false}]}
{"op":"mcm","clk":"11450200039","pt":1717319100235,"mc":[{"id":"1.229554915","rc":[{"atb":[[19.5,11.3],[24,9.08],[29,3.73]],"id":51562794},{"atl":[[400,0.35],[500,0.41]],"id":51562794},{"atb":[[3.6,80.4],[3.85,73.35],[4.2,32.66]],"id":46292327},{"atl":[[32,10.92],[21,6.96]],"id":46292327},{"atb":[[8.6,13.75],[7.6,31.67],[6.6,37.33]],"id":56606596},{"atl":[[100,1.4],[200,1.05]],"id":56606596},{"atb":[[8,29.86],[9,13.06],[7,34.84]],"id":65788088},{"atl":[[210,0.99],[110,1.27]],"id":65788088},{"atb":[[34,6.33],[44,4.86],[60,1.77]],"id":42099039},{"atl":[[550,0.25],[650,0.32]],"id":42099039},{"atb":[[2.86,112.39],[3.15,48.61],[2.96,106.66]],"id":65293046},{"atl":[[16,13.93],[11,13.93]],"id":65293046},{"atb":[[4.8,55.01],[5.8,21.77],[5.3,48.61]],"id":70003370},{"atl":[[48,4.44],[29,7.59]],"id":70003370},{"atb":[[1.63,331.84],[1.58,360.45],[1.68,153.71]],"id":64927898},{"atl":[[3.7,51.62],[4.4,61.48]],"id":64927898}],"con":true,"img":false}]}
{"op":"mcm","clk":"11450200790","pt":1717319107124,"mc":[{"id":"1.229554915","rc":[{"atb":[[22,0]],"id":51562794},{"atl":[[700,0]],"id":51562794},{"spn":210.0,"spf":"NaN","id":51562794},{"atl":[[32,6.74]],"id":46292327},{"spn":13.45,"spf":"NaN","id":46292327},{"atb":[[6.8,0]],"id":56606596},{"atl":[[60,0]],"id":56606596},{"spn":26.4,"spf":"NaN","id":56606596},{"atb":[[7.8,0]],"id":65788088},{"spn":305.0,"spf":"NaN","id":42099039},{"atl":[[34,3.24],[42,0],[29,4.97]],"id":70003370},{"spn":17.7,"spf":"NaN","id":70003370},{"atl":[[11.5,0]],"id":65293046},{"spn":7.15,"spf":"NaN","id":65293046}],"con":true,"img":false}]}
{"op":"mcm","clk":"11450200797","pt":1717319107229,"mc":[{"id":"1.229554915","rc":[{"atb":[[25,5.75]],"id":51562794},{"atl":[[490,2.61]],"id":51562794},{"atl":[[30,4.18]],"id":46292327},{"atb":[[7.8,17.31]],"id":56606596},{"atl":[[50,2.61]],"id":56606596},{"atb":[[9.2,14.2]],"id":65788088},{"atl":[[28,2.61]],"id":70003370},{"atl":[[10.5,5.34]],"id":65293046}],"con":true,"img":false}]}
{"op":"mcm","clk":"11450204887","pt":1717319148647,"mc":[{"id":"1.229554915","rc":[{"atb":[[55,0]],"id":42099039}],"con":true,"img":false}]}
{"op":"mcm","clk":"11450204898","pt":1717319148751,"mc":[{"id":"1.229554915","rc":[{"atb":[[60,4.38]],"id":42099039}],"con":true,"img":false}]}
{"op":"mcm","clk":"11450218882","pt":1717319285816,"mc":[{"id":"1.229554915","rc":[{"atb":[[15.5,0],[20,5.26]],"id":51562794},{"spn":6.9,"spf":"NaN","id":65293046},{"spn":17.2,"spf":"NaN","id":70003370}],"con":true,"img":false}]}
{"op":"mcm","clk":"11450230468","pt":1717319411219,"mc":[{"id":"1.229554915","rc":[{"atl":[[1000,2.02]],"id":46292327},{"atl":[[1000,2.02]],"id":70003370}],"con":true,"img":false}]}
{"op":"mcm","clk":"11450230503","pt":1717319411529,"mc":[{"id":"1.229554915","rc":[{"atl":[[10,0.85]],"id":65293046}],"con":true,"img":false}]}
{"op":"mcm","clk":"11450230552","pt":1717319412055,"mc":[{"id":"1.229554915","rc":[{"atl":[[1000,1.85]],"id":56606596}],"con":true,"img":false}]}
{"op":"mcm","clk":"11450230869","pt":1717319415903,"mc":[{"id":"1.229554915","rc":[{"atl":[[1000,1.85]],"id":65788088}],"con":true,"img":false}]}
{"op":"mcm","clk":"11450230891","pt":1717319416217,"mc":[{"id":"1.229554915","rc":[{"atl":[[1000,1.59]],"id":46292327}],"con":true,"img":false}]}
{"op":"mcm","clk":"11450230972","pt":1717319417456,"mc":[{"id":"1.229554915","rc":[{"atl":[[1000,1.48]],"id":70003370}],"con":true,"img":false}]}
{"op":"mcm","clk":"11450231002","pt":1717319417723,"mc":[{"id":"1.229554915","rc":[{"atl":[[1000,1.2]],"id":56606596}],"con":true,"img":false}]}
{"op":"mcm","clk":"11450231352","pt":1717319421652,"mc":[{"id":"1.229554915","rc":[{"atl":[[1000,1.17]],"id":65788088}],"con":true,"img":false}]}
{"op":"mcm","clk":"11450231401","pt":1717319422123,"mc":[{"id":"1.229554915","rc":[{"atl":[[1000,1.17]],"id":46292327}],"con":true,"img":false}]}
{"op":"mcm","clk":"11450231408","pt":1717319422222,"mc":[{"id":"1.229554915","rc":[{"atl":[[20,0.42]],"id":46292327}],"con":true,"img":false}]}
{"op":"mcm","clk":"11450231781","pt":1717319425437,"mc":[{"id":"1.229554915","rc":[{"atl":[[1000,1.17]],"id":70003370}],"con":true,"img":false}]}
{"op":"mcm","clk":"11450231792","pt":1717319425541,"mc":[{"id":"1.229554915","rc":[{"atl":[[27,0.31]],"id":70003370}],"con":true,"img":false}]}
{"op":"mcm","clk":"11450231821","pt":1717319425848,"mc":[{"id":"1.229554915","rc":[{"atl":[[1000,1]],"id":56606596}],"con":true,"img":false}]}
{"op":"mcm","clk":"11450231835","pt":1717319425957,"mc":[{"id":"1.229554915","rc":[{"atl":[[42,0.2]],"id":56606596}],"con":true,"img":false}]}
{"op":"mcm","clk":"11450231991","pt":1717319427662,"mc":[{"id":"1.229554915","rc":[{"atl":[[1000,1]],"id":65788088}],"con":true,"img":false}]}
{"op":"mcm","clk":"11450232002","pt":1717319427765,"mc":[{"id":"1.229554915","rc":[{"atl":[[50,0.17]],"id":65788088}],"con":true,"img":false}]}
{"op":"mcm","clk":"11450233778","pt":1717319445790,"mc":[{"id":"1.229554915","rc":[{"atb":[[19.5,0],[24,0],[29,0]],"id":51562794},{"atl":[[400,0],[500,0]],"id":51562794},{"atb":[[3.6,0],[3.85,0],[4.2,0]],"id":46292327},{"atl":[[32,0],[21,0]],"id":46292327},{"atb":[[8.6,0],[7.6,0],[6.6,0]],"id":56606596},{"atl":[[100,0],[200,0]],"id":56606596},{"atb":[[8,0],[9,0],[7,0]],"id":65788088},{"atl":[[210,0],[110,0]],"id":65788088},{"atb":[[34,0],[44,0],[60,2.61]],"id":42099039},{"atl":[[550,0],[650,0]],"id":42099039},{"atb":[[4.8,0],[5.8,0],[5.3,0]],"id":70003370},{"atl":[[48,0],[29,0]],"id":70003370},{"atb":[[2.86,0],[3.15,0],[2.96,0]],"id":65293046},{"atl":[[16,0],[11,0]],"id":65293046},{"atb":[[1.63,0],[1.58,0],[1.68,0]],"id":64927898},{"atl":[[3.7,0],[4.4,0]],"id":64927898}],"con":true,"img":false}]}
{"op":"mcm","clk":"11450233807","pt":1717319446063,"mc":[{"id":"1.229554915","rc":[{"atl":[[10,0],[15,0.85]],"id":65293046}],"con":true,"img":false}]}
{"op":"mcm","clk":"11450233834","pt":1717319446371,"mc":[{"id":"1.229554915","rc":[{"atl":[[27,0],[1000,2.02]],"id":70003370}],"con":true,"img":false}]}
{"op":"mcm","clk":"11450233859","pt":1717319446679,"mc":[{"id":"1.229554915","rc":[{"atl":[[9.8,0.86],[15,0]],"id":65293046}],"con":true,"img":false}]}
{"op":"mcm","clk":"11450233887","pt":1717319446992,"mc":[{"id":"1.229554915","rc":[{"atl":[[1000,1.48]],"id":70003370}],"con":true,"img":false}]}
{"op":"mcm","clk":"11450233933","pt":1717319447574,"mc":[{"id":"1.229554915","rc":[{"atl":[[1000,1.17]],"id":70003370}],"con":true,"img":false}]}
{"op":"mcm","clk":"11450233941","pt":1717319447679,"mc":[{"id":"1.229554915","rc":[{"atl":[[32,0.31]],"id":70003370}],"con":true,"img":false}]}
{"op":"mcm","clk":"11450234040","pt":1717319448772,"mc":[{"id":"1.229554915","rc":[{"atl":[[390,0],[490,0]],"id":51562794},{"atl":[[30,0]],"id":46292327},{"atb":[[8.8,0],[7.8,0]],"id":56606596},{"atl":[[50,0]],"id":56606596},{"atb":[[9.2,0]],"id":65788088},{"atl":[[65,0]],"id":65788088},{"atb":[[5.9,0]],"id":70003370},{"atl":[[34,0],[42,2.61],[28,0]],"id":70003370},{"atb":[[3.2,0]],"id":65293046},{"atl":[[10.5,0]],"id":65293046},{"atb":[[1.6,228.1],[1.69,0]],"id":64927898},{"atl":[[5.6,26.15],[4.3,0]],"id":64927898}],"con":true,"img":false}]}
{"op":"mcm","clk":"11450234049","pt":1717319448880,"mc":[{"id":"1.229554915","rc":[{"atl":[[700,2.61],[490,0.13]],"id":51562794},{"atl":[[36,4.18]],"id":46292327},{"atb":[[8.2,7.58],[6.8,17.31]],"id":56606596},{"atl":[[60,2.61]],"id":56606596},{"atb":[[7.8,14.2]],"id":65788088},{"atl":[[75,2.61]],"id":65788088},{"atb":[[2.82,56.81]],"id":65293046},{"atl":[[11.5,5.34]],"id":65293046},{"atb":[[5.2,24.37]],"id":70003370},{"atl":[[36,0],[40,2.56],[29,2.61]],"id":70003370}],"con":true,"img":false}]}
{"op":"mcm","clk":"11450234065","pt":1717319449081,"mc":[{"id":"1.229554915","rc":[{"atl":[[42,0]],"id":56606596}],"con":true,"img":false}]}
{"op":"mcm","clk":"11450234084","pt":1717319449254,"mc":[{"id":"1.229554915","rc":[{"atl":[[1000,1.85]],"id":65788088}],"con":true,"img":false}]}
{"op":"mcm","clk":"11450234095","pt":1717319449395,"mc":[{"id":"1.229554915","rc":[{"atl":[[1000,1.85]],"id":56606596}],"con":true,"img":false}]}
{"op":"mcm","clk":"11450234105","pt":1717319449488,"mc":[{"id":"1.229554915","rc":[{"atl":[[50,0]],"id":65788088}],"con":true,"img":false}]}
{"op":"mcm","clk":"11450234161","pt":1717319450084,"mc":[{"id":"1.229554915","rc":[{"atl":[[1000,1.2]],"id":56606596}],"con":true,"img":false}]}
{"op":"mcm","clk":"11450234173","pt":1717319450182,"mc":[{"id":"1.229554915","rc":[{"atl":[[1000,1.17]],"id":65788088}],"con":true,"img":false}]}
{"op":"mcm","clk":"11450234217","pt":1717319450686,"mc":[{"id":"1.229554915","rc":[{"atl":[[1000,1]],"id":56606596}],"con":true,"img":false}]}
{"op":"mcm","clk":"11450234229","pt":1717319450794,"mc":[{"id":"1.229554915","rc":[{"atl":[[50,0.2]],"id":56606596}],"con":true,"img":false}]}
{"op":"mcm","clk":"11450234265","pt":1717319451063,"mc":[{"id":"1.229554915","rc":[{"atl":[[1000,1]],"id":65788088}],"con":true,"img":false}]}
{"op":"mcm","clk":"11450234275","pt":1717319451167,"mc":[{"id":"1.229554915","rc":[{"atl":[[65,0.17]],"id":65788088}],"con":true,"img":false}]}
{"op":"mcm","clk":"11450234346","pt":1717319451888,"mc":[{"id":"1.229554915","rc":[{"atl":[[1000,1.85]],"id":56606596}],"con":true,"img":false}]}
{"op":"mcm","clk":"11450234361","pt":1717319451993,"mc":[{"id":"1.229554915","rc":[{"atl":[[50,0]],"id":56606596}],"con":true,"img":false}]}
{"op":"mcm","clk":"11450234439","pt":1717319452773,"mc":[{"id":"1.229554915","rc":[{"atl":[[1000,1.21]],"id":56606596}],"con":true,"img":false}]}
{"op":"mcm","clk":"11450234464","pt":1717319453095,"mc":[{"id":"1.229554915","rc":[{"atl":[[65,0],[1000,1.85]],"id":65788088}],"con":true,"img":false}]}
{"op":"mcm","clk":"11450234535","pt":1717319453797,"mc":[{"id":"1.229554915","rc":[{"atl":[[1000,1]],"id":56606596}],"con":true,"img":false}]}
{"op":"mcm","clk":"11450234549","pt":1717319453859,"mc":[{"id":"1.229554915","rc":[{"atl":[[40,0.21]],"id":56606596}],"con":true,"img":false}]}
{"op":"mcm","clk":"11450234577","pt":1717319454168,"mc":[{"id":"1.229554915","rc":[{"atl":[[1000,1.17]],"id":65788088}],"con":true,"img":false}]}
{"op":"mcm","clk":"11450234659","pt":1717319454988,"mc":[{"id":"1.229554915","rc":[{"atl":[[1000,1]],"id":65788088}],"con":true,"img":false}]}
{"op":"mcm","clk":"11450234666","pt":1717319455092,"mc":[{"id":"1.229554915","rc":[{"atl":[[48,0.17]],"id":65788088}],"con":true,"img":false}]}
{"op":"mcm","clk":"11450235879","pt":1717319468416,"mc":[{"id":"1.229554915","rc":[{"atl":[[9.8,0]],"id":65293046}],"con":true,"img":false}]}
{"op":"mcm","clk":"11450235886","pt":1717319468473,"mc":[{"id":"1.229554915","rc":[{"atl":[[11,0.86]],"id":65293046}],"con":true,"img":false}]}
{"op":"mcm","clk":"11450235896","pt":1717319468680,"mc":[{"id":"1.229554915","rc":[{"atl":[[40,0]],"id":56606596}],"con":true,"img":false}]}
{"op":"mcm","clk":"11450235911","pt":1717319468885,"mc":[{"id":"1.229554915","rc":[{"atl":[[1000,2.02]],"id":46292327}],"con":true,"img":false}]}
{"op":"mcm","clk":"11450235922","pt":1717319468990,"mc":[{"id":"1.229554915","rc":[{"atl":[[1000,1.85]],"id":56606596}],"con":true,"img":false}]}
{"op":"mcm","clk":"11450235950","pt":1717319469305,"mc":[{"id":"1.229554915","rc":[{"atl":[[1000,1.59]],"id":46292327},{"atl":[[48,0]],"id":65788088}],"con":true,"img":false}]}
{"op":"mcm","clk":"11450235979","pt":1717319469611,"mc":[{"id":"1.229554915","rc":[{"atl":[[1000,1.85]],"id":65788088}],"con":true,"img":false}]}
{"op":"mcm","clk":"11450235999","pt":1717319469813,"mc":[{"id":"1.229554915","rc":[{"atl":[[20,0]],"id":46292327}],"con":true,"img":false}]}
{"op":"mcm","clk":"11450236009","pt":1717319469915,"mc":[{"id":"1.229554915","rc":[{"atl":[[1000,1.21]],"id":56606596}],"con":true,"img":false}]}
{"op":"mcm","clk":"11450236065","pt":1717319470399,"mc":[{"id":"1.229554915","rc":[{"atl":[[1000,1.17]],"id":46292327}],"con":true,"img":false}]}
{"op":"mcm","clk":"11450236075","pt":1717319470502,"mc":[{"id":"1.229554915","rc":[{"atl":[[25,0.42]],"id":46292327}],"con":true,"img":false}]}
{"op":"mcm","clk":"11450236101","pt":1717319470807,"mc":[{"id":"1.229554915","rc":[{"atl":[[1000,1.17]],"id":65788088}],"con":true,"img":false}]}
{"op":"mcm","clk":"11450236137","pt":1717319471117,"mc":[{"id":"1.229554915","rc":[{"atl":[[1000,1]],"id":56606596}],"con":true,"img":false}]}
{"op":"mcm","clk":"11450236146","pt":1717319471216,"mc":[{"id":"1.229554915","rc":[{"atl":[[42,0.21]],"id":56606596}],"con":true,"img":false}]}
{"op":"mcm","clk":"11450236238","pt":1717319472099,"mc":[{"id":"1.229554915","rc":[{"spn":260.0,"spf":"NaN","id":51562794},{"spn":15.45,"spf":"NaN","id":46292327},{"spn":25.1,"spf":"NaN","id":56606596},{"atl":[[1000,1]],"id":65788088},{"spn":520.0,"spf":"NaN","id":42099039},{"spn":7.15,"spf":"NaN","id":65293046},{"spn":17.7,"spf":"NaN","id":70003370},{"spn":2.91,"spf":"NaN","id":64927898}],"con":true,"img":false}]}
{"op":"mcm","clk":"11450236252","pt":1717319472208,"mc":[{"id":"1.229554915","rc":[{"atl":[[50,0.17]],"id":65788088}],"con":true,"img":false}]}
{"op":"mcm","clk":"11450236313","pt":1717319472821,"mc":[{"id":"1.229554915","rc":[{"atl":[[42,0],[1000,1.85]],"id":56606596}],"con":true,"img":false}]}
{"op":"mcm","clk":"11450236371","pt":1717319473494,"mc":[{"id":"1.229554915","rc":[{"atl":[[1000,1.22]],"id":56606596}],"con":true,"img":false}]}
{"op":"mcm","clk":"11450236438","pt":1717319474318,"mc":[{"id":"1.229554915","rc":[{"atl":[[1000,1]],"id":56606596}],"con":true,"img":false}]}
{"op":"mcm","clk":"11450236446","pt":1717319474369,"mc":[{"id":"1.229554915","rc":[{"atl":[[38,0.22]],"id":56606596}],"con":true,"img":false}]}
{"op":"mcm","clk":"11450237020","pt":1717319481299,"mc":[{"id":"1.229554915","rc":[{"atl":[[36,2.86],[40,0]],"id":70003370}],"con":true,"img":false}]}
{"op":"mcm","clk":"11450238556","pt":1717319498536,"mc":[{"id":"1.229554915","rc":[{"atl":[[38,0]],"id":56606596}],"con":true,"img":false}]}
{"op":"mcm","clk":"11450238564","pt":1717319498642,"mc":[{"id":"1.229554915","rc":[{"atl":[[1000,1.85]],"id":56606596}],"con":true,"img":false}]}
{"op":"mcm","clk":"11450238593","pt":1717319498949,"mc":[{"id":"1.229554915","rc":[{"atl":[[1000,1.22]],"id":56606596}],"con":true,"img":false}]}
{"op":"mcm","clk":"11450238618","pt":1717319499209,"mc":[{"id":"1.229554915","rc":[{"atl":[[1000,1]],"id":56606596}],"con":true,"img":false}]}
{"op":"mcm","clk":"11450238628","pt":1717319499313,"mc":[{"id":"1.229554915","rc":[{"atl":[[42,0.22]],"id":56606596}],"con":true,"img":false}]}
{"op":"mcm","clk":"11450238777","pt":1717319500926,"mc":[{"id":"1.229554915","rc":[{"atb":[[19.5,11.3],[24,9.08],[29,3.73]],"id":51562794},{"atl":[[400,0.35],[500,0.41]],"id":51562794},{"atb":[[3.6,80.4],[3.85,73.35],[4.2,32.66]],"id":46292327},{"atl":[[32,6.74],[21,6.96]],"id":46292327},{"atb":[[8.6,13.75],[7.6,31.67],[6.6,37.33]],"id":56606596},{"atl":[[100,1.4],[200,1.05]],"id":56606596},{"atb":[[8,29.86],[9,13.06],[7,34.84]],"id":65788088},{"atl":[[210,0.99],[110,1.27]],"id":65788088},{"atb":[[34,6.33],[44,4.86],[60,4.38]],"id":42099039},{"atl":[[550,0.25],[650,0.32]],"id":42099039},{"atb":[[4.8,55.01],[5.8,21.77],[5.3,48.61]],"id":70003370},{"atl":[[48,4.44],[29,7.59]],"id":70003370},{"atb":[[2.86,112.39],[3.15,48.61],[2.96,106.66]],"id":65293046},{"atl":[[16,13.93],[11,14.8]],"id":65293046},{"atb":[[1.63,331.84],[1.58,360.45],[1.68,153.71]],"id":64927898},{"atl":[[3.7,51.62],[4.4,61.48]],"id":64927898}],"con":true,"img":false}]}
{"op":"mcm","clk":"11450241362","pt":1717319528401,"mc":[{"id":"1.229554915","rc":[{"atl":[[1000,2.02]],"id":70003370}],"con":true,"img":false}]}
{"op":"mcm","clk":"11450241381","pt":1717319528621,"mc":[{"id":"1.229554915","rc":[{"atl":[[32,0],[1000,1.47]],"id":70003370}],"con":true,"img":false}]}
{"op":"mcm","clk":"11450241420","pt":1717319528931,"mc":[{"id":"1.229554915","rc":[{"atl":[[1000,1.17]],"id":70003370}],"con":true,"img":false}]}
{"op":"mcm","clk":"11450241431","pt":1717319529033,"mc":[{"id":"1.229554915","rc":[{"atl":[[28,0.3]],"id":70003370}],"con":true,"img":false}]}
{"op":"mcm","clk":"11450242822","pt":1717319543956,"mc":[{"id":"1.229554915","rc":[{"atl":[[700,0],[490,0]],"id":51562794},{"spn":215.0,"spf":"NaN","id":51562794},{"atl":[[36,0]],"id":46292327},{"spn":13.45,"spf":"NaN","id":46292327},{"atb":[[8.2,0]],"id":56606596},{"atl":[[60,0]],"id":56606596},{"spn":25.3,"spf":"NaN","id":56606596},{"atl":[[75,0]],"id":65788088},{"spn":29.8,"spf":"NaN","id":65788088},{"spn":305.0,"spf":"NaN","id":42099039},{"atl":[[34,3.24],[42,0]],"id":70003370},{"spn":17.2,"spf":"NaN","id":70003370},{"atl":[[11.5,0]],"id":65293046},{"atb":[[1.6,0],[1.69,175.26]],"id":64927898},{"spn":2.71,"spf":"NaN","id":64927898}],"con":true,"img":false}]}
{"op":"mcm","clk":"11450242831","pt":1717319544059,"mc":[{"id":"1.229554915","rc":[{"atl":[[390,0.13],[490,2.61]],"id":51562794},{"atl":[[30,4.18]],"id":46292327},{"atb":[[8.8,7.58]],"id":56606596},{"atl":[[50,2.61]],"id":56606596},{"atl":[[65,2.61]],"id":65788088},{"atl":[[10.5,5.34]],"id":65293046}],"con":true,"img":false}]}
{"op":"mcm","clk":"11450242857","pt":1717319544375,"mc":[{"id":"1.229554915","rc":[{"atl":[[42,0],[1000,1.85]],"id":56606596}],"con":true,"img":false}]}
{"op":"mcm","clk":"11450242886","pt":1717319544635,"mc":[{"id":"1.229554915","rc":[{"atl":[[50,0],[1000,1.85]],"id":65788088}],"con":true,"img":false}]}
{"op":"mcm","clk":"11450242922","pt":1717319544944,"mc":[{"id":"1.229554915","rc":[{"atl":[[1000,1.22]],"id":56606596},{"atl":[[1000,1.17]],"id":65788088}],"con":true,"img":false}]}
{"op":"mcm","clk":"11450242951","pt":1717319545263,"mc":[{"id":"1.229554915","rc":[{"atl":[[1000,1]],"id":65788088}],"con":true,"img":false}]}
{"op":"mcm","clk":"11450242961","pt":1717319545367,"mc":[{"id":"1.229554915","rc":[{"atl":[[60,0.17]],"id":65788088}],"con":true,"img":false}]}
{"op":"mcm","clk":"11450242988","pt":1717319545630,"mc":[{"id":"1.229554915","rc":[{"atl":[[1000,1]],"id":56606596}],"con":true,"img":false}]}
{"op":"mcm","clk":"11450242997","pt":1717319545731,"mc":[{"id":"1.229554915","rc":[{"atl":[[48,0.22]],"id":56606596}],"con":true,"img":false}]}
{"op":"mcm","clk":"11450244444","pt":1717319561080,"mc":[{"id":"1.229554915","rc":[{"atb":[[6.8,0]],"id":56606596},{"atb":[[7.8,0]],"id":65788088},{"atb":[[2.82,0]],"id":65293046},{"atb":[[5.2,0]],"id":70003370},{"atl":[[5.6,0],[4.3,36.62]],"id":64927898}],"con":true,"img":false}]}
{"op":"mcm","clk":"11450244451","pt":1717319561183,"mc":[{"id":"1.229554915","rc":[{"atb":[[7.8,17.31]],"id":56606596},{"atb":[[8.2,14.2]],"id":65788088},{"atb":[[5.9,24.37]],"id":70003370},{"atb":[[3.2,56.81]],"id":65293046}],"con":true,"img":false}]}
{"op":"mcm","clk":"11450250956","pt":1717319633773,"mc":[{"id":"1.229554915","rc":[{"spn":210.0,"spf":"NaN","id":51562794},{"spn":26.4,"spf":"NaN","id":56606596},{"atb":[[8.2,0]],"id":65788088},{"spn":32.3,"spf":"NaN","id":65788088},{"spn":6.9,"spf":"NaN","id":65293046}],"con":true,"img":false}]}
{"op":"mcm","clk":"11450250966","pt":1717319633869,"mc":[{"id":"1.229554915","rc":[{"atb":[[9.2,14.2]],"id":65788088}],"con":true,"img":false}]}
{"op":"mcm","clk":"11450255378","pt":1717319684216,"mc":[{"id":"1.229554915","rc":[{"atb":[[17.5,6.06],[20,0]],"id":51562794}],"con":true,"img":false}]}
{"op":"mcm","clk":"11450255414","pt":1717319684629,"mc":[{"id":"1.229554915","rc":[{"atb":[[17.5,0],[20,5.26]],"id":51562794}],"con":true,"img":false}]}
{"op":"mcm","clk":"11450255441","pt":1717319684941,"mc":[{"id":"1.229554915","rc":[{"atb":[[17.5,6.06],[20,0]],"id":51562794}],"con":true,"img":false}]}
{"op":"mcm","clk":"11450255844","pt":1717319689453,"mc":[{"id":"1.229554915","rc":[{"atb":[[17.5,0],[20,5.26]],"id":51562794}],"con":true,"img":false}]}
{"op":"mcm","clk":"11450264891","pt":1717319790657,"mc":[{"id":"1.229554915","rc":[{"atb":[[19.5,0],[24,0],[29,0]],"id":51562794},{"atl":[[400,0],[500,0]],"id":51562794},{"atb":[[3.6,0],[3.85,0],[4.2,0]],"id":46292327},{"atl":[[32,0],[21,0]],"id":46292327},{"spn":15.45,"spf":"NaN","id":46292327},{"atb":[[8.6,0],[7.6,0],[6.6,0]],"id":56606596},{"atl":[[100,0],[200,0]],"id":56606596},{"atb":[[8,0],[9,0],[7,0]],"id":65788088},{"atl":[[210,0],[110,0]],"id":65788088},{"atb":[[34,0],[44,0],[60,2.61]],"id":42099039},{"atl":[[550,0],[650,0]],"id":42099039},{"spn":520.0,"spf":"NaN","id":42099039},{"atb":[[2.86,0],[3.15,0],[2.96,0]],"id":65293046},{"atl":[[16,0],[11,0.86]],"id":65293046},{"atb":[[4.8,0],[5.8,0],[5.3,0]],"id":70003370},{"atl":[[48,0],[29,2.61]],"id":70003370},{"atb":[[1.63,0],[1.58,0],[1.68,0]],"id":64927898},{"atl":[[3.7,0],[4.4,0]],"id":64927898},{"spn":2.91,"spf":"NaN","id":64927898}],"con":true,"img":false}]}
{"op":"mcm","clk":"11450264927","pt":1717319791076,"mc":[{"id":"1.229554915","rc":[{"atl":[[390,0],[490,0]],"id":51562794},{"atl":[[30,0]],"id":46292327},{"atb":[[8.8,0],[7.8,0]],"id":56606596},{"atl":[[50,0]],"id":56606596},{"atb":[[9.2,0]],"id":65788088},{"atb":[[5.9,0]],"id":70003370},{"atl":[[34,0],[42,2.61]],"id":70003370},{"atb":[[3.2,0]],"id":65293046},{"atl":[[10.5,0]],"id":65293046},{"atb":[[1.6,228.1],[1.69,0]],"id":64927898},{"atl":[[5.6,26.15],[4.3,0]],"id":64927898}],"con":true,"img":false}]}
{"op":"mcm","clk":"11450264934","pt":1717319791181,"mc":[{"id":"1.229554915","rc":[{"atl":[[700,2.61],[490,0.13]],"id":51562794},{"atl":[[36,4.18]],"id":46292327},{"atb":[[8.2,7.58],[6.8,17.31]],"id":56606596},{"atl":[[60,2.61]],"id":56606596},{"atb":[[7.8,14.2]],"id":65788088},{"atb":[[5.2,24.37]],"id":70003370},{"atb":[[2.82,56.81]],"id":65293046},{"atl":[[11.5,5.34]],"id":65293046}],"con":true,"img":false}]}
{"op":"mcm","clk":"11450264939","pt":1717319791283,"mc":[{"id":"1.229554915","rc":[{"atb":[[3.05,26.55]],"id":56606596}],"con":true,"img":false}]}
{"op":"mcm","clk":"11450265765","pt":1717319800664,"mc":[{"id":"1.229554915","rc":[{"atb":[[3.05,24.39]],"id":56606596}],"con":true,"img":false}]}
{"op":"mcm","clk":"11450266062","pt":1717319803684,"mc":[{"id":"1.229554915","rc":[{"atb":[[19.5,11.3],[24,9.08],[29,3.73]],"id":51562794},{"atl":[[400,0.35],[500,0.41]],"id":51562794},{"atb":[[3.6,80.4],[3.85,73.35],[4.2,32.66]],"id":46292327},{"atl":[[32,6.74],[21,6.96]],"id":46292327},{"atb":[[8.6,13.75],[7.6,31.67],[6.6,37.33]],"id":56606596},{"atl":[[100,1.4],[200,1.05]],"id":56606596},{"atb":[[8,29.86],[9,13.06],[7,34.84]],"id":65788088},{"atl":[[210,0.99],[110,1.27]],"id":65788088},{"atb":[[34,6.33],[44,4.86],[60,4.38]],"id":42099039},{"atl":[[550,0.25],[650,0.32]],"id":42099039},{"atb":[[2.86,112.39],[3.15,48.61],[2.96,106.66]],"id":65293046},{"atl":[[16,13.93],[11,14.8]],"id":65293046},{"atb":[[4.8,55.01],[5.8,21.77],[5.3,48.61]],"id":70003370},{"atl":[[48,4.44],[29,7.59]],"id":70003370},{"atb":[[1.63,331.84],[1.58,360.45],[1.68,153.71]],"id":64927898},{"atl":[[3.7,51.62],[4.4,61.48]],"id":64927898}],"con":true,"img":false}]}
{"op":"mcm","clk":"11450269681","pt":1717319845842,"mc":[{"id":"1.229554915","rc":[{"atl":[[700,0],[490,0]],"id":51562794},{"atl":[[36,0]],"id":46292327},{"atb":[[8.2,0]],"id":56606596},{"atl":[[60,0]],"id":56606596},{"atl":[[34,3.24],[42,0]],"id":70003370},{"atl":[[11.5,0]],"id":65293046},{"atb":[[1.6,0],[1.69,175.26]],"id":64927898}],"con":true,"img":false}]}
{"op":"mcm","clk":"11450269684","pt":1717319845941,"mc":[{"id":"1.229554915","rc":[{"atl":[[390,0.13],[490,2.61]],"id":51562794},{"atl":[[30,4.18]],"id":46292327},{"atb":[[8.8,7.58]],"id":56606596},{"atl":[[50,2.61]],"id":56606596},{"atl":[[10.5,5.34]],"id":65293046}],"con":true,"img":false}]}
{"op":"mcm","clk":"11450269701","pt":1717319846147,"mc":[{"id":"1.229554915","rc":[{"atl":[[28,0]],"id":70003370}],"con":true,"img":false}]}
{"op":"mcm","clk":"11450271059","pt":1717319863373,"mc":[{"id":"1.229554915","rc":[{"spn":13.45,"spf":"NaN","id":46292327},{"atb":[[6.8,0]],"id":56606596},{"atb":[[7.8,0]],"id":65788088},{"spn":305.0,"spf":"NaN","id":42099039},{"atb":[[5.2,0]],"id":70003370},{"spn":17.7,"spf":"NaN","id":70003370},{"atb":[[2.82,0]],"id":65293046},{"atl":[[5.6,0],[4.3,36.62]],"id":64927898},{"spn":2.71,"spf":"NaN","id":64927898}],"con":true,"img":false}]}
{"op":"mcm","clk":"11450271070","pt":1717319863482,"mc":[{"id":"1.229554915","rc":[{"atb":[[7.8,17.31]],"id":56606596},{"atb":[[8.2,14.2]],"id":65788088},{"atb":[[5.9,24.37]],"id":70003370},{"atb":[[3.2,56.81]],"id":65293046}],"con":true,"img":false}]}
{"op":"mcm","clk":"11450275650","pt":1717319922504,"mc":[{"id":"1.229554915","rc":[{"atb":[[8.2,0]],"id":65788088}],"con":true,"img":false}]}
{"op":"mcm","clk":"11450275658","pt":1717319922561,"mc":[{"id":"1.229554915","rc":[{"atb":[[9.2,14.2]],"id":65788088}],"con":true,"img":false}]}
{"op":"mcm","clk":"11450283222","pt":1717320016518,"mc":[{"id":"1.229554915","rc":[{"atl":[[10,0.85]],"id":65293046},{"spn":6.65,"spf":"NaN","id":65293046}],"con":true,"img":false}]}
{"op":"mcm","clk":"11450283230","pt":1717320016617,"mc":[{"id":"1.229554915","rc":[{"atl":[[11,13.93]],"id":65293046}],"con":true,"img":false}]}
{"op":"mcm","clk":"11450283244","pt":1717320016828,"mc":[{"id":"1.229554915","rc":[{"atl":[[48,0]],"id":56606596}],"con":true,"img":false}]}
{"op":"mcm","clk":"11450283254","pt":1717320016927,"mc":[{"id":"1.229554915","rc":[{"atl":[[1000,1.85]],"id":65788088}],"con":true,"img":false}]}
{"op":"mcm","clk":"11450283272","pt":1717320017133,"mc":[{"id":"1.229554915","rc":[{"atl":[[1000,1.85]],"id":56606596},{"atl":[[60,0]],"id":65788088}],"con":true,"img":false}]}
{"op":"mcm","clk":"11450283299","pt":1717320017397,"mc":[{"id":"1.229554915","rc":[{"atl":[[25,0],[1000,2.02]],"id":46292327}],"con":true,"img":false}]}
{"op":"mcm","clk":"11450283345","pt":1717320018019,"mc":[{"id":"1.229554915","rc":[{"atl":[[1000,2.02]],"id":70003370}],"con":true,"img":false}]}
{"op":"mcm","clk":"11450283803","pt":1717320024538,"mc":[{"id":"1.229554915","rc":[{"atl":[[1000,1.2]],"id":56606596},{"atl":[[1000,1.17]],"id":65788088}],"con":true,"img":false}]}
{"op":"mcm","clk":"11450283849","pt":1717320025116,"mc":[{"id":"1.229554915","rc":[{"atl":[[1000,1]],"id":56606596}],"con":true,"img":false}]}
{"op":"mcm","clk":"11450283860","pt":1717320025216,"mc":[{"id":"1.229554915","rc":[{"atl":[[42,0.2]],"id":56606596}],"con":true,"img":false}]}
{"op":"mcm","clk":"11450283899","pt":1717320025726,"mc":[{"id":"1.229554915","rc":[{"atl":[[1000,1]],"id":65788088}],"con":true,"img":false}]}
{"op":"mcm","clk":"11450283906","pt":1717320025832,"mc":[{"id":"1.229554915","rc":[{"atl":[[50,0.17]],"id":65788088}],"con":true,"img":false}]}
{"op":"mcm","clk":"11450283926","pt":1717320026136,"mc":[{"id":"1.229554915","rc":[{"atl":[[1000,1.59]],"id":46292327},{"atl":[[1000,1.47]],"id":70003370}],"con":true,"img":false}]}
{"op":"mcm","clk":"11450284132","pt":1717320028932,"mc":[{"id":"1.229554915","rc":[{"atl":[[1000,1.17]],"id":70003370}],"con":true,"img":false}]}
{"op":"mcm","clk":"11450284138","pt":1717320029035,"mc":[{"id":"1.229554915","rc":[{"atl":[[28,0.3]],"id":70003370}],"con":true,"img":false}]}
{"op":"mcm","clk":"11450284160","pt":1717320029348,"mc":[{"id":"1.229554915","rc":[{"atl":[[1000,1.17]],"id":46292327}],"con":true,"img":false}]}
{"op":"mcm","clk":"11450284168","pt":1717320029446,"mc":[{"id":"1.229554915","rc":[{"atl":[[20,0.42]],"id":46292327}],"con":true,"img":false}]}
{"op":"mcm","clk":"11450286165","pt":1717320060764,"mc":[{"id":"1.229554915","rc":[{"atb":[[17.5,6.06],[20,0]],"id":51562794}],"con":true,"img":false}]}
{"op":"mcm","clk":"11450286238","pt":1717320062085,"mc":[{"id":"1.229554915","rc":[{"atb":[[17.5,0],[20,5.26]],"id":51562794}],"con":true,"img":false}]}
{"op":"mcm","clk":"11450286719","pt":1717320069570,"mc":[{"id":"1.229554915","rc":[{"atb":[[17.5,6.06],[20,0]],"id":51562794}],"con":true,"img":false}]}
{"op":"mcm","clk":"11450288012","pt":1717320088410,"mc":[{"id":"1.229554915","rc":[{"atb":[[17.5,0],[20,5.26]],"id":51562794},{"spn":12.95,"spf":"NaN","id":46292327},{"spn":25.4,"spf":"NaN","id":56606596},{"spn":29.8,"spf":"NaN","id":65788088},{"spn":17.2,"spf":"NaN","id":70003370}],"con":true,"img":false}]}
{"op":"mcm","clk":"11450293008","pt":1717320161400,"mc":[{"id":"1.229554915","rc":[{"atb":[[17.5,6.06],[20,0]],"id":51562794}],"con":true,"img":false}]}
{"op":"mcm","clk":"11450293521","pt":1717320167925,"mc":[{"id":"1.229554915","rc":[{"atb":[[19.5,0],[24,0],[29,0]],"id":51562794},{"atl":[[400,0],[500,0]],"id":51562794},{"atb":[[3.6,0],[3.85,0],[4.2,0]],"id":46292327},{"atl":[[32,0],[21,0]],"id":46292327},{"atb":[[8.6,0],[7.6,0],[6.6,0]],"id":56606596},{"atl":[[100,0],[200,0]],"id":56606596},{"atb":[[8,0],[9,0],[7,0]],"id":65788088},{"atl":[[210,0],[110,0]],"id":65788088},{"atb":[[34,0],[44,0],[60,2.61]],"id":42099039},{"atl":[[550,0],[650,0]],"id":42099039},{"atb":[[4.8,0],[5.8,0],[5.3,0]],"id":70003370},{"atl":[[48,0],[29,2.61]],"id":70003370},{"atb":[[2.86,0],[3.15,0],[2.96,0]],"id":65293046},{"atl":[[16,0],[11,0]],"id":65293046},{"atb":[[1.63,0],[1.58,0],[1.68,0]],"id":64927898},{"atl":[[3.7,0],[4.4,0]],"id":64927898}],"con":true,"img":false}]}
{"op":"mcm","clk":"11450293542","pt":1717320168234,"mc":[{"id":"1.229554915","rc":[{"atl":[[10,0]],"id":65293046}],"con":true,"img":false}]}
{"op":"mcm","clk":"11450293617","pt":1717320169807,"mc":[{"id":"1.229554915","rc":[{"atl":[[42,2.61]],"id":70003370},{"atb":[[1.6,228.1]],"id":64927898},{"atl":[[5.6,26.15]],"id":64927898}],"con":true,"img":false}]}
{"op":"mcm","clk":"11450293624","pt":1717320169910,"mc":[{"id":"1.229554915","rc":[{"atl":[[390,0],[490,0]],"id":51562794},{"atl":[[30,0]],"id":46292327},{"atb":[[8.8,0],[7.8,0]],"id":56606596},{"atl":[[50,0]],"id":56606596},{"atb":[[9.2,0]],"id":65788088},{"atl":[[65,0]],"id":65788088},{"atb":[[5.9,0]],"id":70003370},{"atl":[[34,0]],"id":70003370},{"atb":[[3.2,0]],"id":65293046},{"atl":[[10.5,0]],"id":65293046},{"atb":[[1.69,0]],"id":64927898},{"atl":[[4.3,0]],"id":64927898}],"con":true,"img":false}]}
{"op":"mcm","clk":"11450293631","pt":1717320170013,"mc":[{"id":"1.229554915","rc":[{"atl":[[700,2.61],[490,0.13]],"id":51562794},{"atl":[[36,4.18]],"id":46292327},{"atb":[[8.2,7.58],[6.8,17.31]],"id":56606596},{"atl":[[60,2.61]],"id":56606596},{"atb":[[7.8,14.2]],"id":65788088},{"atl":[[75,2.61]],"id":65788088},{"atb":[[2.82,56.81]],"id":65293046},{"atl":[[11.5,5.34]],"id":65293046},{"atb":[[5.2,24.37]],"id":70003370}],"con":true,"img":false}]}
{"op":"mcm","clk":"11450293644","pt":1717320170220,"mc":[{"id":"1.229554915","rc":[{"atl":[[42,0]],"id":56606596}],"con":true,"img":false}]}
{"op":"mcm","clk":"11450293651","pt":1717320170324,"mc":[{"id":"1.229554915","rc":[{"atl":[[50,0]],"id":65788088}],"con":true,"img":false}]}
{"op":"mcm","clk":"11450294704","pt":1717320186244,"mc":[{"id":"1.229554915","rc":[{"atb":[[19.5,11.3],[24,9.08],[29,3.73]],"id":51562794},{"atl":[[400,0.35],[500,0.41]],"id":51562794},{"atb":[[3.6,80.4],[3.85,73.35],[4.2,32.66]],"id":46292327},{"atl":[[32,6.74],[21,6.96]],"id":46292327},{"atb":[[8.6,13.75],[7.6,31.67],[6.6,37.33]],"id":56606596},{"atl":[[100,1.4],[200,1.05]],"id":56606596},{"atb":[[8,29.86],[9,13.06],[7,34.84]],"id":65788088},{"atl":[[210,0.99],[110,1.27]],"id":65788088},{"atb":[[34,6.33],[44,4.86],[60,4.38]],"id":42099039},{"atl":[[550,0.25],[650,0.32]],"id":42099039},{"atb":[[2.86,112.39],[3.15,48.61],[2.96,106.66]],"id":65293046},{"atl":[[16,13.93],[11,13.93]],"id":65293046},{"atb":[[4.8,55.01],[5.8,21.77],[5.3,48.61]],"id":70003370},{"atl":[[48,4.44],[29,7.59]],"id":70003370},{"atb":[[1.63,331.84],[1.58,360.45],[1.68,153.71]],"id":64927898},{"atl":[[3.7,51.62],[4.4,61.48]],"id":64927898}],"con":true,"img":false}]}
{"op":"mcm","clk":"11450294746","pt":1717320186755,"mc":[{"id":"1.229554915","rc":[{"atb":[[17.5,0],[20,5.26]],"id":51562794}],"con":true,"img":false}]}
{"op":"mcm","clk":"11450295361","pt":1717320195561,"mc":[{"id":"1.229554915","rc":[{"atl":[[3.8,7.66]],"id":64927898}],"con":true,"img":false}]}
{"op":"mcm","clk":"11450295381","pt":1717320195824,"mc":[{"id":"1.229554915","rc":[{"atl":[[10.5,7.66]],"id":65293046}],"con":true,"img":false}]}
{"op":"mcm","clk":"11450295396","pt":1717320196025,"mc":[{"id":"1.229554915","rc":[{"atl":[[32,14.41]],"id":46292327}],"con":true,"img":false}]}
{"op":"mcm","clk":"11450295421","pt":1717320196235,"mc":[{"id":"1.229554915","rc":[{"atl":[[36,10.52]],"id":70003370}],"con":true,"img":false}]}
{"op":"mcm","clk":"11450295441","pt":1717320196442,"mc":[{"id":"1.229554915","rc":[{"atl":[[55,9.66]],"id":56606596}],"con":true,"img":false}]}
{"op":"mcm","clk":"11450295453","pt":1717320196549,"mc":[{"id":"1.229554915","rc":[{"atl":[[28,0]],"id":70003370}],"con":true,"img":false}]}
{"op":"mcm","clk":"11450295472","pt":1717320196755,"mc":[{"id":"1.229554915","rc":[{"atl":[[75,10.28]],"id":65788088}],"con":true,"img":false}]}
{"op":"mcm","clk":"11450295508","pt":1717320197124,"mc":[{"id":"1.229554915","rc":[{"atb":[[1.55,11.07]],"id":64927898}],"con":true,"img":false}]}
{"op":"mcm","clk":"11450295524","pt":1717320197337,"mc":[{"id":"1.229554915","rc":[{"atb":[[2.88,11.07]],"id":65293046}],"con":true,"img":false}]}
{"op":"mcm","clk":"11450295540","pt":1717320197545,"mc":[{"id":"1.229554915","rc":[{"atb":[[5.8,11.07]],"id":46292327}],"con":true,"img":false}]}
{"op":"mcm","clk":"11450295564","pt":1717320197849,"mc":[{"id":"1.229554915","rc":[{"atb":[[6,11.07]],"id":70003370}],"con":true,"img":false}]}
{"op":"mcm","clk":"11450295584","pt":1717320198161,"mc":[{"id":"1.229554915","rc":[{"atb":[[8.2,18.65]],"id":56606596}],"con":true,"img":false}]}
{"op":"mcm","clk":"11450295599","pt":1717320198368,"mc":[{"id":"1.229554915","rc":[{"atb":[[9.8,11.07]],"id":65788088}],"con":true,"img":false}]}
{"op":"mcm","clk":"11450295614","pt":1717320198530,"mc":[{"id":"1.229554915","rc":[{"atb":[[32,11.07]],"id":51562794}],"con":true,"img":false}]}
{"op":"mcm","clk":"11450297234","pt":1717320224898,"mc":[{"id":"1.229554915","rc":[{"atb":[[30,0]],"id":51562794},{"atl":[[700,0],[490,0]],"id":51562794},{"spn":216.0,"spf":"NaN","id":51562794},{"atl":[[36,0]],"id":46292327},{"atb":[[8.2,11.07]],"id":56606596},{"atl":[[60,0]],"id":56606596},{"spn":26.3,"spf":"NaN","id":56606596},{"atb":[[9.6,0]],"id":65788088},{"atl":[[75,7.66]],"id":65788088},{"spn":32.4,"spf":"NaN","id":65788088},{"atl":[[34,3.24],[42,0]],"id":70003370},{"spn":17.7,"spf":"NaN","id":70003370},{"atl":[[11.5,0]],"id":65293046},{"spn":6.9,"spf":"NaN","id":65293046},{"atb":[[1.6,0],[1.69,175.26]],"id":64927898}],"con":true,"img":false}]}
{"op":"mcm","clk":"11450297239","pt":1717320225008,"mc":[{"id":"1.229554915","rc":[{"atb":[[34,2.61]],"id":51562794},{"atl":[[480,0.13],[490,2.61]],"id":51562794},{"atl":[[30,4.18]],"id":46292327},{"atb":[[8.8,7.58]],"id":56606596},{"atl":[[50,2.61]],"id":56606596},{"atb":[[10,7.01]],"id":65788088},{"atl":[[65,2.61]],"id":65788088},{"atl":[[10.5,13.01]],"id":65293046}],"con":true,"img":false}]}
{"op":"mcm","clk":"11450297328","pt":1717320226098,"mc":[{"id":"1.229554915","rc":[{"atl":[[10.5,5.34]],"id":65293046}],"con":true,"img":false}]}
{"op":"mcm","clk":"11450297330","pt":1717320226199,"mc":[{"id":"1.229554915","rc":[{"atl":[[10,7.66]],"id":65293046}],"con":true,"img":false}]}
{"op":"mcm","clk":"11450297406","pt":1717320227207,"mc":[{"id":"1.229554915","rc":[{"atb":[[32,0]],"id":51562794}],"con":true,"img":false}]}
{"op":"mcm","clk":"11450297422","pt":1717320227301,"mc":[{"id":"1.229554915","rc":[{"atb":[[34,13.69]],"id":51562794}],"con":true,"img":false}]}
{"op":"mcm","clk":"11450298222","pt":1717320240412,"mc":[{"id":"1.229554915","rc":[{"atb":[[6.8,0]],"id":56606596},{"atb":[[7.8,0]],"id":65788088},{"atb":[[2.82,0]],"id":65293046},{"atb":[[5.2,0]],"id":70003370},{"atl":[[5.6,0],[4.3,36.62]],"id":64927898}],"con":true,"img":false}]}
{"op":"mcm","clk":"11450298231","pt":1717320240522,"mc":[{"id":"1.229554915","rc":[{"atb":[[7.8,17.31]],"id":56606596},{"atb":[[8.2,14.2]],"id":65788088},{"atb":[[3.2,56.81]],"id":65293046},{"atb":[[5.9,24.37]],"id":70003370}],"con":true,"img":false}]}
{"op":"mcm","clk":"11450300315","pt":1717320270548,"mc":[{"id":"1.229554915","rc":[{"atb":[[34,11.07]],"id":51562794},{"atl":[[480,0]],"id":51562794}],"con":true,"img":false}]}
{"op":"mcm","clk":"11450300318","pt":1717320270658,"mc":[{"id":"1.229554915","rc":[{"atb":[[36,2.61]],"id":51562794},{"atl":[[390,0.13]],"id":51562794}],"con":true,"img":false}]}
{"op":"mcm","clk":"11450302527","pt":1717320305088,"mc":[{"id":"1.229554915","rc":[{"spn":213.0,"spf":"NaN","id":51562794},{"spn":26.4,"spf":"NaN","id":56606596},{"atb":[[8.2,0]],"id":65788088},{"spn":32.5,"spf":"NaN","id":65788088},{"spn":6.65,"spf":"NaN","id":65293046}],"con":true,"img":false}]}
{"op":"mcm","clk":"11450302536","pt":1717320305193,"mc":[{"id":"1.229554915","rc":[{"atb":[[9.2,14.2]],"id":65788088}],"con":true,"img":false}]}
{"op":"mcm","clk":"11450309911","pt":1717320427774,"mc":[{"id":"1.229554915","rc":[{"atl":[[3.65,5.07]],"id":64927898},{"spn":2.69,"spf":"NaN","id":64927898}],"con":true,"img":false}]}
{"op":"mcm","clk":"11450310364","pt":1717320434206,"mc":[{"id":"1.229554915","rc":[{"atl":[[55,7.66],[60,2]],"id":56606596}],"con":true,"img":false}]}
{"op":"mcm","clk":"11450312149","pt":1717320462114,"mc":[{"id":"1.229554915","rc":[{"atl":[[390,0]],"id":51562794},{"atl":[[10.5,0]],"id":65293046}],"con":true,"img":false}]}
{"op":"mcm","clk":"11450312154","pt":1717320462219,"mc":[{"id":"1.229554915","rc":[{"atl":[[470,0.13]],"id":51562794},{"atl":[[11.5,5.34]],"id":65293046}],"con":true,"img":false}]}
{"op":"mcm","clk":"11450312183","pt":1717320462732,"mc":[{"id":"1.229554915","rc":[{"atl":[[10,0]],"id":65293046}],"con":true,"img":false}]}
{"op":"mcm","clk":"11450312191","pt":1717320462843,"mc":[{"id":"1.229554915","rc":[{"atl":[[10.5,7.66]],"id":65293046}],"con":true,"img":false}]}
{"op":"mcm","clk":"11450312514","pt":1717320467549,"mc":[{"id":"1.229554915","rc":[{"atl":[[490,0]],"id":51562794}],"con":true,"img":false}]}
{"op":"mcm","clk":"11450312520","pt":1717320467668,"mc":[{"id":"1.229554915","rc":[{"atl":[[810,2.61]],"id":51562794}],"con":true,"img":false}]}
{"op":"mcm","clk":"11450312887","pt":1717320474245,"mc":[{"id":"1.229554915","rc":[{"atl":[[470,0]],"id":51562794},{"atl":[[26,0]],"id":46292327}],"con":true,"img":false}]}
{"op":"mcm","clk":"11450312891","pt":1717320474350,"mc":[{"id":"1.229554915","rc":[{"atl":[[480,0.13]],"id":51562794},{"atl":[[28,2.61]],"id":46292327}],"con":true,"img":false}]}
{"op":"mcm","clk":"11450312896","pt":1717320474454,"mc":[{"id":"1.229554915","rc":[{"atl":[[20,0]],"id":46292327}],"con":true,"img":false}]}
{"op":"mcm","clk":"11450313010","pt":1717320476438,"mc":[{"id":"1.229554915","rc":[{"atb":[[3.3,0]],"id":65293046},{"atl":[[4.1,0]],"id":64927898}],"con":true,"img":false}]}
{"op":"mcm","clk":"11450313016","pt":1717320476537,"mc":[{"id":"1.229554915","rc":[{"atb":[[3.35,24.39]],"id":65293046},{"atl":[[3.95,17.53]],"id":64927898}],"con":true,"img":false}]}
{"op":"mcm","clk":"11450313222","pt":1717320480647,"mc":[{"id":"1.229554915","rc":[{"atl":[[70,0],[75,9.66]],"id":65788088},{"atl":[[36,7.66],[38,2.7]],"id":70003370}],"con":true,"img":false}]}
{"op":"mcm","clk":"11450313504","pt":1717320485438,"mc":[{"id":"1.229554915","rc":[{"atl":[[36,10.52],[38,0]],"id":70003370}],"con":true,"img":false}]}
{"op":"mcm","clk":"11450313580","pt":1717320486885,"mc":[{"id":"1.229554915","rc":[{"atl":[[36,7.66],[38,2.7]],"id":70003370}],"con":true,"img":false}]}
{"op":"mcm","clk":"11450313615","pt":1717320487668,"mc":[{"id":"1.229554915","rc":[{"atl":[[36,10.52]],"id":70003370}],"con":true,"img":false}]}
{"op":"mcm","clk":"11450313619","pt":1717320487771,"mc":[{"id":"1.229554915","rc":[{"atl":[[38,0]],"id":70003370}],"con":true,"img":false}]}
{"op":"mcm","clk":"11450313691","pt":1717320489183,"mc":[{"id":"1.229554915","rc":[{"atl":[[480,0]],"id":51562794},{"spn":218.0,"spf":"NaN","id":51562794},{"spn":13.45,"spf":"NaN","id":46292327},{"spn":6.92,"spf":"NaN","id":65293046}],"con":true,"img":false}]}
{"op":"mcm","clk":"11450313698","pt":1717320489289,"mc":[{"id":"1.229554915","rc":[{"atl":[[490,0.13]],"id":51562794}],"con":true,"img":false}]}
{"op":"mcm","clk":"11450313776","pt":1717320490949,"mc":[{"id":"1.229554915","rc":[{"atb":[[5.9,0]],"id":46292327}],"con":true,"img":false}]}
{"op":"mcm","clk":"11450313784","pt":1717320491061,"mc":[{"id":"1.229554915","rc":[{"atb":[[6,11.45]],"id":46292327}],"con":true,"img":false}]}
{"op":"mcm","clk":"11450313929","pt":1717320493392,"mc":[{"id":"1.229554915","rc":[{"atl":[[65,0]],"id":65788088}],"con":true,"img":false}]}
{"op":"mcm","clk":"11450313936","pt":1717320493496,"mc":[{"id":"1.229554915","rc":[{"atl":[[70,2.61]],"id":65788088}],"con":true,"img":false}]}
{"op":"mcm","clk":"11450313942","pt":1717320493600,"mc":[{"id":"1.229554915","rc":[{"atb":[[19.5,0],[24,0],[29,0]],"id":51562794},{"atl":[[400,0],[500,0]],"id":51562794},{"atb":[[3.6,0],[3.85,0],[4.2,0]],"id":46292327},{"atl":[[32,7.66],[21,0]],"id":46292327},{"atb":[[8.6,0],[7.6,0],[6.6,0]],"id":56606596},{"atl":[[100,0],[200,0]],"id":56606596},{"atb":[[8,0],[9,0],[7,0]],"id":65788088},{"atl":[[210,0],[110,0]],"id":65788088},{"atb":[[34,0],[44,0],[60,2.61]],"id":42099039},{"atl":[[550,0],[650,0]],"id":42099039},{"atb":[[4.8,0],[5.8,0],[5.3,0]],"id":70003370},{"atl":[[48,0],[29,2.61]],"id":70003370},{"atb":[[2.86,0],[3.15,0],[2.96,0]],"id":65293046},{"atl":[[16,0],[11,0]],"id":65293046},{"atb":[[1.63,0],[1.58,0],[1.68,0]],"id":64927898},{"atl":[[3.7,0],[4.4,0]],"id":64927898}],"con":true,"img":false}]}
{"op":"mcm","clk":"11450314008","pt":1717320494594,"mc":[{"id":"1.229554915","rc":[{"atl":[[10.5,0]],"id":65293046}],"con":true,"img":false}]}
{"op":"mcm","clk":"11450314015","pt":1717320494700,"mc":[{"id":"1.229554915","rc":[{"atl":[[11,7.66]],"id":65293046}],"con":true,"img":false}]}
{"op":"mcm","clk":"11450314136","pt":1717320496589,"mc":[{"id":"1.229554915","rc":[{"atl":[[3.65,0]],"id":64927898}],"con":true,"img":false}]}
{"op":"mcm","clk":"11450314202","pt":1717320497587,"mc":[{"id":"1.229554915","rc":[{"atl":[[3.8,0]],"id":64927898}],"con":true,"img":false}]}
{"op":"mcm","clk":"11450314206","pt":1717320497683,"mc":[{"id":"1.229554915","rc":[{"atl":[[3.9,7.66]],"id":64927898}],"con":true,"img":false}]}
{"op":"mcm","clk":"11450314860","pt":1717320508292,"mc":[{"id":"1.229554915","rc":[{"atl":[[590,0.09]],"id":51562794},{"atb":[[1.56,228.1]],"id":64927898},{"atl":[[5.3,28.25]],"id":64927898}],"con":true,"img":false}]}
{"op":"mcm","clk":"11450314868","pt":1717320508395,"mc":[{"id":"1.229554915","rc":[{"atl":[[490,0]],"id":51562794},{"atb":[[7.8,0]],"id":56606596},{"atb":[[9.2,0]],"id":65788088},{"atb":[[3.2,0]],"id":65293046},{"atb":[[1.69,0]],"id":64927898},{"atl":[[4.3,0]],"id":64927898}],"con":true,"img":false}]}
{"op":"mcm","clk":"11450314870","pt":1717320508499,"mc":[{"id":"1.229554915","rc":[{"atb":[[6.8,17.31]],"id":56606596},{"atb":[[7.8,14.2]],"id":65788088},{"atb":[[2.88,67.88]],"id":65293046}],"con":true,"img":false}]}
{"op":"mcm","clk":"11450315154","pt":1717320512385,"mc":[{"id":"1.229554915","rc":[{"atb":[[19.5,11.3],[24,9.08],[29,3.73]],"id":51562794},{"atl":[[590,0],[810,0],[400,0.35],[500,0.41]],"id":51562794},{"atb":[[3.6,80.4],[3.85,73.35],[4.2,32.66]],"id":46292327},{"atl":[[32,14.41],[21,6.96],[28,0]],"id":46292327},{"atb":[[8.6,13.75],[7.6,31.67],[6.6,37.33]],"id":56606596},{"atl":[[100,1.4],[200,1.05]],"id":56606596},{"atb":[[7.4,32.66],[8.4,28.25],[9.4,12.44]],"id":65788088},{"atl":[[140,1],[240,0.87]],"id":65788088},{"atb":[[34,6.33],[44,4.86],[60,4.38]],"id":42099039},{"atl":[[550,0.25],[650,0.32]],"id":42099039},{"atb":[[2.9,110.03],[3,104.53],[3.25,46.45]],"id":65293046},{"atl":[[17,13.06],[12,12.67]],"id":65293046},{"atb":[[4.8,55.01],[5.8,21.77],[5.3,48.61]],"id":70003370},{"atl":[[48,4.44],[29,4.97]],"id":70003370},{"atb":[[1.73,0],[1.64,163.33],[1.59,354.34],[1.54,387.15]],"id":64927898},{"atl":[[4,69.68],[3.5,55.74]],"id":64927898}],"con":true,"img":false}]}
{"op":"mcm","clk":"11450315165","pt":1717320512492,"mc":[{"id":"1.229554915","rc":[{"atl":[[790,0.09],[970,2.61]],"id":51562794},{"atl":[[29,2.61]],"id":46292327},{"atl":[[32,2.61]],"id":70003370},{"atb":[[1.65,76.86]],"id":64927898}],"con":true,"img":false}]}
{"op":"mcm","clk":"11450315186","pt":1717320512801,"mc":[{"id":"1.229554915","rc":[{"atl":[[3.9,0]],"id":64927898}],"con":true,"img":false}]}
{"op":"mcm","clk":"11450315197","pt":1717320512937,"mc":[{"id":"1.229554915","rc":[{"atl":[[3.8,7.66]],"id":64927898}],"con":true,"img":false}]}
{"op":"mcm","clk":"11450315325","pt":1717320514609,"mc":[{"id":"1.229554915","rc":[{"atl":[[3.45,5.15]],"id":64927898}],"con":true,"img":false}]}
{"op":"mcm","clk":"11450323761","pt":1717320536565,"mc":[{"id":"1.229554915","rc":[{"atb":[[6,0]],"id":46292327},{"atb":[[6.4,0]],"id":70003370},{"atl":[[3.95,0]],"id":64927898}],"con":true,"img":false}]}
{"op":"mcm","clk":"11450323766","pt":1717320536618,"mc":[{"id":"1.229554915","rc":[{"atb":[[6.4,11.45]],"id":46292327},{"atb":[[6.6,10.39]],"id":70003370},{"atl":[[3.75,17.53]],"id":64927898}],"con":true,"img":false}]}
{"op":"mcm","clk":"11450323823","pt":1717320537440,"mc":[{"id":"1.229554915","rc":[{"atb":[[5.8,0]],"id":46292327}],"con":true,"img":false}]}
{"op":"mcm","clk":"11450323832","pt":1717320537540,"mc":[{"id":"1.229554915","rc":[{"atb":[[5,11.07]],"id":46292327}],"con":true,"img":false}]}
{"op":"mcm","clk":"11450323918","pt":1717320538638,"mc":[{"id":"1.229554915","rc":[{"atb":[[5,0]],"id":46292327}],"con":true,"img":false}]}
{"op":"mcm","clk":"11450323923","pt":1717320538731,"mc":[{"id":"1.229554915","rc":[{"atb":[[5.8,11.07]],"id":46292327}],"con":true,"img":false}]}
{"op":"mcm","clk":"11450323980","pt":1717320539715,"mc":[{"id":"1.229554915","rc":[{"atl":[[34,0],[42,2.44]],"id":46292327},{"atl":[[75,7.66]],"id":65788088},{"atl":[[46,2.22]],"id":70003370}],"con":true,"img":false}]}
{"op":"mcm","clk":"11450323991","pt":1717320539826,"mc":[{"id":"1.229554915","rc":[{"atl":[[36,7.66]],"id":70003370}],"con":true,"img":false}]}
{"op":"mcm","clk":"11450324176","pt":1717320542159,"mc":[{"id":"1.229554915","rc":[{"atl":[[75,2],[60,0]],"id":56606596},{"atl":[[40,2.56],[46,0]],"id":70003370}],"con":true,"img":false}]}
{"op":"mcm","clk":"11450324184","pt":1717320542243,"mc":[{"id":"1.229554915","rc":[{"atl":[[30,0]],"id":46292327},{"atl":[[55,0]],"id":65788088},{"atb":[[1.56,0],[1.41,294.54]],"id":64927898}],"con":true,"img":false}]}
{"op":"mcm","clk":"11450324193","pt":1717320542359,"mc":[{"id":"1.229554915","rc":[{"atl":[[32,18.59]],"id":46292327},{"atl":[[60,2.61]],"id":65788088}],"con":true,"img":false}]}
{"op":"mcm","clk":"11450324301","pt":1717320543637,"mc":[{"id":"1.229554915","rc":[{"atl":[[32,14.41],[40,3.13]],"id":46292327}],"con":true,"img":false}]}
{"op":"mcm","clk":"11450324765","pt":1717320549444,"mc":[{"id":"1.229554915","rc":[{"atb":[[19.5,0],[24,0],[29,0]],"id":51562794},{"atl":[[400,0],[890,0.06],[500,0]],"id":51562794},{"spn":413.0,"spf":"NaN","id":51562794},{"atb":[[3.6,0],[3.85,0],[4.2,0]],"id":46292327},{"atl":[[32,7.66],[21,0]],"id":46292327},{"spn":17.7,"spf":"NaN","id":46292327},{"atb":[[8.6,0],[7.6,0],[6.6,0]],"id":56606596},{"atl":[[100,0],[200,0]],"id":56606596},{"atb":[[7.4,0],[8.4,0],[9.4,0]],"id":65788088},{"atl":[[140,0],[240,0]],"id":65788088},{"spn":35.0,"spf":"NaN","id":65788088},{"atb":[[34,0],[44,0],[60,2.61]],"id":42099039},{"atl":[[550,0],[650,0]],"id":42099039},{"spn":520.0,"spf":"NaN","id":42099039},{"atb":[[4.8,0],[5.8,0],[5.3,0]],"id":70003370},{"atl":[[48,0],[29,0]],"id":70003370},{"spn":19.3,"spf":"NaN","id":70003370},{"atb":[[2.9,0],[3,0],[3.25,0]],"id":65293046},{"atl":[[17,0],[12,0]],"id":65293046},{"spn":7.17,"spf":"NaN","id":65293046},{"atb":[[1.64,0],[1.59,0],[1.54,0]],"id":64927898},{"atl":[[4,0],[3.5,0]],"id":64927898},{"spn":2.55,"spf":"NaN","id":64927898}],"con":true,"img":false}]}
{"op":"mcm","clk":"11450324776","pt":1717320549546,"mc":[{"id":"1.229554915","rc":[{"atl":[[790,0]],"id":51562794},{"atl":[[38,2.7],[42,0]],"id":46292327},{"atl":[[40,0],[42,2.44]],"id":70003370}],"con":true,"img":false}]}
{"op":"mcm","clk":"11450324899","pt":1717320551054,"mc":[{"id":"1.229554915","rc":[{"atl":[[3.45,0]],"id":64927898}],"con":true,"img":false}]}
{"op":"mcm","clk":"11450325412","pt":1717320557046,"mc":[{"id":"1.229554915","rc":[{"atl":[[3.7,5.14]],"id":64927898}],"con":true,"img":false}]}
{"op":"mcm","clk":"11450325724","pt":1717320560969,"mc":[{"id":"1.229554915","rc":[{"atl":[[38,0],[40,5.69]],"id":46292327},{"atl":[[42,0],[44,2.33]],"id":70003370}],"con":true,"img":false}]}
{"op":"mcm","clk":"11450325742","pt":1717320561241,"mc":[{"id":"1.229554915","rc":[{"atl":[[29,0]],"id":46292327},{"atb":[[1.65,0]],"id":64927898}],"con":true,"img":false}]}
{"op":"mcm","clk":"11450325751","pt":1717320561335,"mc":[{"id":"1.229554915","rc":[{"atl":[[30,2.61]],"id":46292327},{"atb":[[1.6,76.86]],"id":64927898}],"con":true,"img":false}]}
{"op":"mcm","clk":"11450325766","pt":1717320561545,"mc":[{"id":"1.229554915","rc":[{"atl":[[32,0]],"id":70003370},{"atl":[[11.5,0]],"id":65293046}],"con":true,"img":false}]}
{"op":"mcm","clk":"11450325773","pt":1717320561649,"mc":[{"id":"1.229554915","rc":[{"atl":[[13,5.34]],"id":65293046},{"atl":[[34,5.86]],"id":70003370}],"con":true,"img":false}]}
{"op":"mcm","clk":"11450325812","pt":1717320562168,"mc":[{"id":"1.229554915","rc":[{"atl":[[11,0]],"id":65293046}],"con":true,"img":false}]}
{"op":"mcm","clk":"11450325818","pt":1717320562271,"mc":[{"id":"1.229554915","rc":[{"atl":[[12.5,7.66]],"id":65293046}],"con":true,"img":false}]}
{"op":"mcm","clk":"11450326122","pt":1717320566363,"mc":[{"id":"1.229554915","rc":[{"atb":[[6.4,0]],"id":46292327},{"atl":[[3.75,0]],"id":64927898}],"con":true,"img":false}]}
{"op":"mcm","clk":"11450326131","pt":1717320566467,"mc":[{"id":"1.229554915","rc":[{"atb":[[6.6,11.45]],"id":46292327},{"atl":[[3.55,17.53]],"id":64927898}],"con":true,"img":false}]}
{"op":"mcm","clk":"11450326166","pt":1717320566878,"mc":[{"id":"1.229554915","rc":[{"atb":[[3.35,0]],"id":65293046},{"atb":[[6.6,0]],"id":70003370}],"con":true,"img":false}]}
{"op":"mcm","clk":"11450326176","pt":1717320566984,"mc":[{"id":"1.229554915","rc":[{"atb":[[7,10.39]],"id":70003370},{"atb":[[3.55,24.39]],"id":65293046}],"con":true,"img":false}]}
{"op":"mcm","clk":"11450326204","pt":1717320567346,"mc":[{"id":"1.229554915","rc":[{"atb":[[36,0]],"id":51562794},{"atb":[[6.8,0]],"id":56606596}],"con":true,"img":false}]}
{"op":"mcm","clk":"11450326210","pt":1717320567447,"mc":[{"id":"1.229554915","rc":[{"atb":[[40,2.61]],"id":51562794},{"atb":[[8.4,17.31]],"id":56606596}],"con":true,"img":false}]}
{"op":"mcm","clk":"11450326221","pt":1717320567558,"mc":[{"id":"1.229554915","rc":[{"atb":[[19.5,11.3],[24,9.08],[29,3.73]],"id":51562794},{"atl":[[400,0.35],[500,0.41]],"id":51562794},{"atb":[[3.6,80.4],[3.85,73.35],[4.2,32.66]],"id":46292327},{"atl":[[32,14.41],[21,6.96]],"id":46292327},{"atb":[[8.6,13.75],[7.6,31.67],[6.6,37.33]],"id":56606596},{"atl":[[100,1.4],[200,1.05]],"id":56606596},{"atb":[[7.4,32.66],[8.4,28.25],[9.4,12.44]],"id":65788088},{"atl":[[140,1],[240,0.87]],"id":65788088},{"atb":[[34,6.33],[44,4.86],[60,4.38]],"id":42099039},{"atl":[[550,0.25],[650,0.32]],"id":42099039},{"atb":[[4.8,55.01],[5.8,21.77],[5.3,48.61]],"id":70003370},{"atl":[[48,4.44],[29,4.97]],"id":70003370},{"atb":[[2.9,110.03],[3,104.53],[3.25,46.45]],"id":65293046},{"atl":[[17,13.06],[12,12.67]],"id":65293046},{"atb":[[1.43,243.09],[1.33,633.51],[1.38,550.16]],"id":64927898},{"atl":[[2.9,73.35],[3.25,92.91]],"id":64927898}],"con":true,"img":false}]}
{"op":"mcm","clk":"11450326253","pt":1717320567878,"mc":[{"id":"1.229554915","rc":[{"atl":[[12.5,0]],"id":65293046}],"con":true,"img":false}]}
{"op":"mcm","clk":"11450326264","pt":1717320567975,"mc":[{"id":"1.229554915","rc":[{"atl":[[11.5,7.66]],"id":65293046}],"con":true,"img":false}]}
{"op":"mcm","clk":"11450326290","pt":1717320568283,"mc":[{"id":"1.229554915","rc":[{"atb":[[10,18.37],[7.8,0]],"id":65788088}],"con":true,"img":false}]}
{"op":"mcm","clk":"11450326323","pt":1717320568756,"mc":[{"id":"1.229554915","rc":[{"atl":[[3.7,0]],"id":64927898}],"con":true,"img":false}]}
{"op":"mcm","clk":"11450326423","pt":1717320570053,"mc":[{"id":"1.229554915","rc":[{"atb":[[38,3.13],[25,0]],"id":51562794}],"con":true,"img":false}]}
{"op":"mcm","clk":"11450326491","pt":1717320570971,"mc":[{"id":"1.229554915","rc":[{"atl":[[40,2.56]],"id":70003370}],"con":true,"img":false}]}
{"op":"mcm","clk":"11450326501","pt":1717320571082,"mc":[{"id":"1.229554915","rc":[{"atl":[[44,0]],"id":70003370}],"con":true,"img":false}]}
{"op":"mcm","clk":"11450326553","pt":1717320571752,"mc":[{"id":"1.229554915","rc":[{"atl":[[2.88,5.78]],"id":64927898}],"con":true,"img":false}]}
{"op":"mcm","clk":"11450326592","pt":1717320572261,"mc":[{"id":"1.229554915","rc":[{"atl":[[18.5,6.42],[15.5,0]],"id":65293046},{"atb":[[1.6,0]],"id":64927898}],"con":true,"img":false}]}
{"op":"mcm","clk":"11450326598","pt":1717320572360,"mc":[{"id":"1.229554915","rc":[{"atb":[[1.53,76.86]],"id":64927898}],"con":true,"img":false}]}
{"op":"mcm","clk":"11450326681","pt":1717320573357,"mc":[{"id":"1.229554915","rc":[{"atb":[[1.55,0]],"id":64927898}],"con":true,"img":false}]}
{"op":"mcm","clk":"11450326692","pt":1717320573462,"mc":[{"id":"1.229554915","rc":[{"atb":[[1.54,11.07]],"id":64927898}],"con":true,"img":false}]}
{"op":"mcm","clk":"11450326775","pt":1717320574589,"mc":[{"id":"1.229554915","rc":[{"atb":[[38,0]],"id":51562794}],"con":true,"img":false}]}
{"op":"mcm","clk":"11450326784","pt":1717320574648,"mc":[{"id":"1.229554915","rc":[{"atb":[[36,3.13]],"id":51562794}],"con":true,"img":false}]}
{"op":"mcm","clk":"11450327662","pt":1717320587415,"mc":[{"id":"1.229554915","rc":[{"atl":[[44,0]],"id":56606596},{"atb":[[7,0]],"id":70003370}],"con":true,"img":false}]}
{"op":"mcm","clk":"11450327667","pt":1717320587507,"mc":[{"id":"1.229554915","rc":[{"atl":[[48,2.61]],"id":56606596},{"atb":[[6.6,10.39]],"id":70003370}],"con":true,"img":false}]}
{"op":"mcm","clk":"11450327879","pt":1717320590516,"mc":[{"id":"1.229554915","rc":[{"atl":[[3.8,0]],"id":64927898}],"con":true,"img":false}]}
{"op":"mcm","clk":"11450327887","pt":1717320590578,"mc":[{"id":"1.229554915","rc":[{"atl":[[3.1,7.66]],"id":64927898}],"con":true,"img":false}]}
{"op":"mcm","clk":"11450327915","pt":1717320590994,"mc":[{"id":"1.229554915","rc":[{"atl":[[32,6.74]],"id":46292327}],"con":true,"img":false}]}
{"op":"mcm","clk":"11450327921","pt":1717320591100,"mc":[{"id":"1.229554915","rc":[{"atl":[[40,13.36]],"id":46292327}],"con":true,"img":false}]}
{"op":"mcm","clk":"11450327942","pt":1717320591410,"mc":[{"id":"1.229554915","rc":[{"atl":[[36,0]],"id":70003370}],"con":true,"img":false}]}
{"op":"mcm","clk":"11450327949","pt":1717320591513,"mc":[{"id":"1.229554915","rc":[{"atl":[[42,7.66]],"id":70003370}],"con":true,"img":false}]}
{"op":"mcm","clk":"11450327968","pt":1717320591815,"mc":[{"id":"1.229554915","rc":[{"atl":[[55,0]],"id":56606596}],"con":true,"img":false}]}
{"op":"mcm","clk":"11450327973","pt":1717320591919,"mc":[{"id":"1.229554915","rc":[{"atl":[[80,7.66]],"id":56606596}],"con":true,"img":false}]}
{"op":"mcm","clk":"11450327997","pt":1717320592188,"mc":[{"id":"1.229554915","rc":[{"atl":[[75,0]],"id":65788088}],"con":true,"img":false}]}
{"op":"mcm","clk":"11450328007","pt":1717320592294,"mc":[{"id":"1.229554915","rc":[{"atl":[[110,7.66]],"id":65788088}],"con":true,"img":false}]}
{"op":"mcm","clk":"11450328034","pt":1717320592709,"mc":[{"id":"1.229554915","rc":[{"atb":[[1.54,0]],"id":64927898}],"con":true,"img":false}]}
{"op":"mcm","clk":"11450328039","pt":1717320592806,"mc":[{"id":"1.229554915","rc":[{"atb":[[1.3,11.07]],"id":64927898}],"con":true,"img":false}]}
{"op":"mcm","clk":"11450328063","pt":1717320593121,"mc":[{"id":"1.229554915","rc":[{"atb":[[2.88,56.81]],"id":65293046}],"con":true,"img":false}]}
{"op":"mcm","clk":"11450328069","pt":1717320593218,"mc":[{"id":"1.229554915","rc":[{"atb":[[3.15,11.07]],"id":65293046}],"con":true,"img":false}]}
{"op":"mcm","clk":"11450328098","pt":1717320593505,"mc":[{"id":"1.229554915","rc":[{"atb":[[5.8,0]],"id":46292327},{"atb":[[10,11.36]],"id":65788088}],"con":true,"img":false}]}
{"op":"mcm","clk":"11450328106","pt":1717320593593,"mc":[{"id":"1.229554915","rc":[{"atb":[[6.4,11.07]],"id":46292327},{"atb":[[10.5,7.01]],"id":65788088}],"con":true,"img":false}]}
{"op":"mcm","clk":"11450328125","pt":1717320593901,"mc":[{"id":"1.229554915","rc":[{"atb":[[6,0]],"id":70003370}],"con":true,"img":false}]}
{"op":"mcm","clk":"11450328134","pt":1717320594007,"mc":[{"id":"1.229554915","rc":[{"atb":[[6.6,21.46]],"id":70003370}],"con":true,"img":false}]}
{"op":"mcm","clk":"11450328149","pt":1717320594313,"mc":[{"id":"1.229554915","rc":[{"atb":[[8.2,0]],"id":56606596}],"con":true,"img":false}]}
{"op":"mcm","clk":"11450328156","pt":1717320594408,"mc":[{"id":"1.229554915","rc":[{"atb":[[9,11.07]],"id":56606596}],"con":true,"img":false}]}
{"op":"mcm","clk":"11450328171","pt":1717320594616,"mc":[{"id":"1.229554915","rc":[{"atb":[[9.8,0]],"id":65788088}],"con":true,"img":false}]}
{"op":"mcm","clk":"11450328183","pt":1717320594825,"mc":[{"id":"1.229554915","rc":[{"atb":[[10.5,18.09]],"id":65788088}],"con":true,"img":false}]}
{"op":"mcm","clk":"11450328208","pt":1717320595091,"mc":[{"id":"1.229554915","rc":[{"atb":[[34,0]],"id":51562794}],"con":true,"img":false}]}
{"op":"mcm","clk":"11450328214","pt":1717320595198,"mc":[{"id":"1.229554915","rc":[{"atb":[[42,11.07]],"id":51562794}],"con":true,"img":false}]}
{"op":"mcm","clk":"11450328280","pt":1717320596326,"mc":[{"id":"1.229554915","rc":[{"atb":[[10.5,7.01]],"id":65788088}],"con":true,"img":false}]}
{"op":"mcm","clk":"11450328287","pt":1717320596431,"mc":[{"id":"1.229554915","rc":[{"atb":[[11,11.07]],"id":65788088}],"con":true,"img":false}]}
{"op":"mcm","clk":"11450328394","pt":1717320598106,"mc":[{"id":"1.229554915","rc":[{"atb":[[3.55,0]],"id":65293046}],"con":true,"img":false}]}
{"op":"mcm","clk":"11450328402","pt":1717320598210,"mc":[{"id":"1.229554915","rc":[{"atb":[[3.65,24.39]],"id":65293046}],"con":true,"img":false}]}
{"op":"mcm","clk":"11450328943","pt":1717320604552,"mc":[{"id":"1.229554915","rc":[{"atb":[[19.5,0],[24,0],[29,0]],"id":51562794},{"atl":[[400,0],[500,0]],"id":51562794},{"atb":[[3.6,0],[3.85,0],[4.2,0]],"id":46292327},{"atl":[[32,0],[21,0]],"id":46292327},{"atb":[[8.6,0],[7.6,0],[6.6,0]],"id":56606596},{"atl":[[100,0],[200,0]],"id":56606596},{"atb":[[7.4,0],[8.4,0],[9.4,0]],"id":65788088},{"atl":[[140,0],[240,0]],"id":65788088},{"atb":[[34,0],[44,0],[60,2.61]],"id":42099039},{"atl":[[550,0],[650,0]],"id":42099039},{"atb":[[2.9,0],[3,0],[3.25,0]],"id":65293046},{"atl":[[17,0],[12,0]],"id":65293046},{"atb":[[4.8,0],[5.8,0],[5.3,0]],"id":70003370},{"atl":[[48,0],[29,0]],"id":70003370},{"atb":[[1.43,0],[1.33,0],[1.38,0]],"id":64927898},{"atl":[[2.9,0],[3.25,0]],"id":64927898}],"con":true,"img":false}]}
{"op":"mcm","clk":"11450328949","pt":1717320604656,"mc":[{"id":"1.229554915","rc":[{"atl":[[36,2.86],[40,10.8]],"id":46292327}],"con":true,"img":false}]}
{"op":"mcm","clk":"11450329037","pt":1717320605855,"mc":[{"id":"1.229554915","rc":[{"atl":[[11.5,0]],"id":65293046}],"con":true,"img":false}]}
{"op":"mcm","clk":"11450329044","pt":1717320605961,"mc":[{"id":"1.229554915","rc":[{"atl":[[12.5,7.66]],"id":65293046}],"con":true,"img":false}]}
{"op":"mcm","clk":"11450329257","pt":1717320608661,"mc":[{"id":"1.229554915","rc":[{"atl":[[2.88,0]],"id":64927898}],"con":true,"img":false}]}
{"op":"mcm","clk":"11450329271","pt":1717320608977,"mc":[{"id":"1.229554915","rc":[{"atb":[[30,4.18]],"id":51562794},{"atb":[[8.4,0]],"id":56606596},{"atl":[[50,0]],"id":56606596},{"atb":[[8.4,13.82]],"id":65788088},{"atl":[[70,0]],"id":65788088},{"atl":[[34,0]],"id":70003370},{"atb":[[1.53,0]],"id":64927898},{"atl":[[3.55,0]],"id":64927898}],"con":true,"img":false}]}
{"op":"mcm","clk":"11450329280","pt":1717320609072,"mc":[{"id":"1.229554915","rc":[{"atb":[[36,0]],"id":51562794},{"atb":[[7.4,17.31]],"id":56606596},{"atl":[[70,2.61]],"id":56606596},{"atb":[[10,0]],"id":65788088},{"atl":[[85,2.61]],"id":65788088},{"atl":[[32,2.61],[40,5.8]],"id":70003370},{"atb":[[1.56,76.86]],"id":64927898},{"atl":[[3.1,0],[3.5,17.53]],"id":64927898}],"con":true,"img":false}]}
{"op":"mcm","clk":"11450329287","pt":1717320609177,"mc":[{"id":"1.229554915","rc":[{"atl":[[3.5,25.2]],"id":64927898}],"con":true,"img":false}]}
{"op":"mcm","clk":"11450329368","pt":1717320610473,"mc":[{"id":"1.229554915","rc":[{"spn":466.0,"spf":"NaN","id":51562794},{"spn":18.3,"spf":"NaN","id":46292327},{"spn":28.5,"spf":"NaN","id":56606596},{"spn":35.5,"spf":"NaN","id":65788088},{"spn":8.07,"spf":"NaN","id":65293046},{"atl":[[3.5,17.53]],"id":64927898},{"spn":2.53,"spf":"NaN","id":64927898}],"con":true,"img":false}]}
{"op":"mcm","clk":"11450329373","pt":1717320610578,"mc":[{"id":"1.229554915","rc":[{"atl":[[3.45,7.66]],"id":64927898}],"con":true,"img":false}]}
{"op":"mcm","clk":"11450329639","pt":1717320613951,"mc":[{"id":"1.229554915","rc":[{"atl":[[1000,1.85]],"id":65788088}],"con":true,"img":false}]}
{"op":"mcm","clk":"11450329793","pt":1717320615976,"mc":[{"id":"1.229554915","rc":[{"atl":[[1000,1.15]],"id":65788088}],"con":true,"img":false}]}
{"op":"mcm","clk":"11450329993","pt":1717320618669,"mc":[{"id":"1.229554915","rc":[{"atb":[[6.6,0]],"id":46292327},{"atb":[[8.8,0]],"id":56606596},{"atl":[[60,0],[1000,1]],"id":65788088}],"con":true,"img":false}]}
{"op":"mcm","clk":"11450330001","pt":1717320618773,"mc":[{"id":"1.229554915","rc":[{"atb":[[6.2,11.45]],"id":46292327},{"atb":[[9.2,7.58]],"id":56606596},{"atl":[[65,2.61],[55,0.15]],"id":65788088}],"con":true,"img":false}]}
{"op":"mcm","clk":"11450330074","pt":1717320619699,"mc":[{"id":"1.229554915","rc":[{"atb":[[9,0]],"id":56606596}],"con":true,"img":false}]}
{"op":"mcm","clk":"11450330083","pt":1717320619801,"mc":[{"id":"1.229554915","rc":[{"atb":[[9.4,11.07]],"id":56606596}],"con":true,"img":false}]}
{"op":"mcm","clk":"11450330398","pt":1717320623597,"mc":[{"id":"1.229554915","rc":[{"atb":[[32,6.74],[42,13.62],[26,8.36]],"id":51562794},{"atl":[[570,0.36],[470,0.29]],"id":51562794},{"atb":[[4.8,27.5],[4.3,63.35],[3.9,72.08]],"id":46292327},{"atl":[[38,5.65],[24,6.05]],"id":46292327},{"atb":[[9.2,33.07],[10.5,11],[8.2,29.03]],"id":56606596},{"atl":[[280,0.74],[180,0.77]],"id":56606596},{"atb":[[9,26.13],[10,23.22],[12.5,9.08]],"id":65788088},{"atl":[[310,0.67],[210,0.66]],"id":65788088},{"atb":[[34,6.33],[44,4.86],[60,4.38]],"id":42099039},{"atl":[[550,0.25],[650,0.32]],"id":42099039},{"atb":[[5.6,45.44],[5.1,50.98],[6.2,20.1]],"id":70003370},{"atl":[[70,3.02],[38,3.76]],"id":70003370},{"atb":[[3.4,87.1],[3.15,108.31],[3.65,63.84]],"id":65293046},{"atl":[[16.5,8.99],[23,9.5]],"id":65293046},{"atb":[[1.25,836.24],[1.3,707.94],[1.35,298.66]],"id":64927898},{"atl":[[2.82,76.57],[3.05,101.98]],"id":64927898}],"con":true,"img":false}]}
{"op":"mcm","clk":"11450330480","pt":1717320624476,"mc":[{"id":"1.229554915","rc":[{"atl":[[3.45,0]],"id":64927898}],"con":true,"img":false}]}
{"op":"mcm","clk":"11450330491","pt":1717320624580,"mc":[{"id":"1.229554915","rc":[{"atl":[[3.1,7.66]],"id":64927898}],"con":true,"img":false}]}
{"op":"mcm","clk":"11450330574","pt":1717320625408,"mc":[{"id":"1.229554915","rc":[{"atb":[[9.4,0]],"id":56606596}],"con":true,"img":false}]}
{"op":"mcm","clk":"11450330584","pt":1717320625467,"mc":[{"id":"1.229554915","rc":[{"atb":[[10,11.07]],"id":56606596}],"con":true,"img":false}]}
{"op":"mcm","clk":"11450330602","pt":1717320625675,"mc":[{"id":"1.229554915","rc":[{"atb":[[11,0]],"id":65788088}],"con":true,"img":false}]}
{"op":"mcm","clk":"11450330610","pt":1717320625774,"mc":[{"id":"1.229554915","rc":[{"atb":[[11.5,11.07]],"id":65788088}],"con":true,"img":false}]}
{"op":"mcm","clk":"11450330638","pt":1717320626085,"mc":[{"id":"1.229554915","rc":[{"atl":[[2.8,8.5]],"id":64927898}],"con":true,"img":false}]}
{"op":"mcm","clk":"11450330662","pt":1717320626395,"mc":[{"id":"1.229554915","rc":[{"atb":[[3.45,45.91]],"id":65293046}],"con":true,"img":false}]}
{"op":"mcm","clk":"11450330669","pt":1717320626496,"mc":[{"id":"1.229554915","rc":[{"atl":[[890,0],[970,0]],"id":51562794},{"atb":[[10.5,0]],"id":65788088},{"atb":[[2.88,0]],"id":65293046}],"con":true,"img":false}]}
{"op":"mcm","clk":"11450330675","pt":1717320626603,"mc":[{"id":"1.229554915","rc":[{"atl":[[970,0.06]],"id":51562794},{"atb":[[11.5,18.09]],"id":65788088}],"con":true,"img":false}]}
{"op":"mcm","clk":"11450331598","pt":1717320637921,"mc":[{"id":"1.229554915","rc":[{"atl":[[1000,1.85]],"id":65788088}],"con":true,"img":false}]}
{"op":"mcm","clk":"11450331610","pt":1717320638024,"mc":[{"id":"1.229554915","rc":[{"atl":[[55,0]],"id":65788088}],"con":true,"img":false}]}
{"op":"mcm","clk":"11450331688","pt":1717320638921,"mc":[{"id":"1.229554915","rc":[{"atl":[[1000,1.15]],"id":65788088}],"con":true,"img":false}]}
{"op":"mcm","clk":"11450331746","pt":1717320639585,"mc":[{"id":"1.229554915","rc":[{"atl":[[1000,1]],"id":65788088}],"con":true,"img":false}]}
{"op":"mcm","clk":"11450331754","pt":1717320639688,"mc":[{"id":"1.229554915","rc":[{"atl":[[60,0.15]],"id":65788088}],"con":true,"img":false}]}
{"op":"mcm","clk":"11450331954","pt":1717320642313,"mc":[{"id":"1.229554915","rc":[{"atb":[[40,0]],"id":51562794},{"atl":[[30,0]],"id":46292327},{"atb":[[1.41,0],[1.53,228.1]],"id":64927898}],"con":true,"img":false}]}
{"op":"mcm","clk":"11450331963","pt":1717320642416,"mc":[{"id":"1.229554915","rc":[{"atb":[[44,2.61]],"id":51562794},{"atl":[[29,2.61]],"id":46292327}],"con":true,"img":false}]}
{"op":"mcm","clk":"11450332360","pt":1717320647196,"mc":[{"id":"1.229554915","rc":[{"atl":[[48,0]],"id":56606596}],"con":true,"img":false}]}
{"op":"mcm","clk":"11450332366","pt":1717320647300,"mc":[{"id":"1.229554915","rc":[{"atl":[[85,2],[55,2.61]],"id":56606596}],"con":true,"img":false}]}
{"op":"mcm","clk":"11450332372","pt":1717320647401,"mc":[{"id":"1.229554915","rc":[{"atl":[[75,0]],"id":56606596}],"con":true,"img":false}]}
{"op":"mcm","clk":"11450332979","pt":1717320656308,"mc":[{"id":"1.229554915","rc":[{"atb":[[9.2,25.49]],"id":56606596},{"atb":[[11.5,11.07]],"id":65788088},{"atl":[[3.5,0]],"id":64927898}],"con":true,"img":false}]}
{"op":"mcm","clk":"11450332986","pt":1717320656416,"mc":[{"id":"1.229554915","rc":[{"atb":[[11,7.58]],"id":56606596},{"atb":[[12,7.01]],"id":65788088},{"atl":[[3.45,17.53]],"id":64927898}],"con":true,"img":false}]}
{"op":"mcm","clk":"11450333276","pt":1717320660323,"mc":[{"id":"1.229554915","rc":[{"atb":[[32,0],[42,11.07],[26,0]],"id":51562794},{"atl":[[570,0],[470,0]],"id":51562794},{"atb":[[4.8,0],[4.3,0],[3.9,0]],"id":46292327},{"atl":[[38,0],[24,0]],"id":46292327},{"atb":[[9,0],[10,0],[12.5,0]],"id":65788088},{"atl":[[310,0],[210,0]],"id":65788088},{"atb":[[3.4,0],[3.15,11.07],[3.65,24.39]],"id":65293046},{"atl":[[16.5,0],[23,0]],"id":65293046},{"atb":[[5.6,0],[5.1,0],[6.2,0]],"id":70003370},{"atl":[[70,0],[38,0]],"id":70003370}],"con":true,"img":false}]}
{"op":"mcm","clk":"11450334254","pt":1717320672964,"mc":[{"id":"1.229554915","rc":[{"atb":[[30,0]],"id":51562794},{"spn":507.0,"spf":"NaN","id":51562794},{"spn":17.7,"spf":"NaN","id":46292327},{"atb":[[7.4,0],[9.4,14.01]],"id":56606596},{"spn":33.0,"spf":"NaN","id":56606596},{"spn":36.0,"spf":"NaN","id":65788088},{"spn":305.0,"spf":"NaN","id":42099039},{"atb":[[3.45,0]],"id":65293046},{"spn":2.18,"spf":"NaN","id":64927898}],"con":true,"img":false}]}
{"op":"mcm","clk":"11450334261","pt":1717320673026,"mc":[{"id":"1.229554915","rc":[{"atb":[[34,4.18]],"id":51562794},{"atb":[[3.1,45.91]],"id":65293046}],"con":true,"img":false}]}
{"op":"mcm","clk":"11450334351","pt":1717320673955,"mc":[{"id":"1.229554915","rc":[{"atb":[[34,10.52],[44,5.04],[27,8.04]],"id":51562794},{"atl":[[580,0.36],[480,0.29]],"id":51562794},{"atb":[[4.8,27.5],[4.3,63.35],[3.9,72.08]],"id":46292327},{"atl":[[38,5.65],[24,6.05]],"id":46292327},{"atb":[[11,20.9],[13.5,8.36],[9.4,24.88]],"id":65788088},{"atl":[[320,0.65],[220,0.63]],"id":65788088},{"atb":[[3.4,87.1],[3.15,108.31],[3.65,63.84]],"id":65293046},{"atl":[[16.5,8.99],[23,9.5]],"id":65293046},{"atb":[[5.6,45.44],[5.1,50.98],[6.2,20.1]],"id":70003370},{"atl":[[70,3.02],[38,3.76]],"id":70003370}],"con":true,"img":false}]}
{"op":"mcm","clk":"11450336251","pt":1717320698278,"mc":[{"id":"1.229554915","rc":[{"atl":[[1000,1.85]],"id":65293046}],"con":true,"img":false}]}
{"op":"mcm","clk":"11450336264","pt":1717320698486,"mc":[{"id":"1.229554915","rc":[{"atl":[[1000,2.02]],"id":70003370}],"con":true,"img":false}]}
{"op":"mcm","clk":"11450336379","pt":1717320699992,"mc":[{"id":"1.229554915","rc":[{"atl":[[1000,1.7]],"id":65293046}],"con":true,"img":false}]}
{"op":"mcm","clk":"11450336415","pt":1717320700467,"mc":[{"id":"1.229554915","rc":[{"atl":[[1000,1.45]],"id":70003370}],"con":true,"img":false}]}
{"op":"mcm","clk":"11450336543","pt":1717320701868,"mc":[{"id":"1.229554915","rc":[{"atl":[[1000,1]],"id":65293046}],"con":true,"img":false}]}
{"op":"mcm","clk":"11450336552","pt":1717320701983,"mc":[{"id":"1.229554915","rc":[{"atl":[[12,0.7]],"id":65293046}],"con":true,"img":false}]}
{"op":"mcm","clk":"11450336742","pt":1717320704178,"mc":[{"id":"1.229554915","rc":[{"atl":[[1000,1.17]],"id":70003370}],"con":true,"img":false}]}
{"op":"mcm","clk":"11450336751","pt":1717320704282,"mc":[{"id":"1.229554915","rc":[{"atl":[[30,0.28]],"id":70003370}],"con":true,"img":false}]}
{"op":"mcm","clk":"11450337889","pt":1717320717912,"mc":[{"id":"1.229554915","rc":[{"atl":[[3.1,0]],"id":64927898}],"con":true,"img":false}]}
{"op":"mcm","clk":"11450337899","pt":1717320718016,"mc":[{"id":"1.229554915","rc":[{"atl":[[3,7.66]],"id":64927898}],"con":true,"img":false}]}
{"op":"mcm","clk":"11450337922","pt":1717320718283,"mc":[{"id":"1.229554915","rc":[{"atl":[[40,3.13]],"id":46292327}],"con":true,"img":false}]}
{"op":"mcm","clk":"11450337931","pt":1717320718387,"mc":[{"id":"1.229554915","rc":[{"atl":[[36,10.52]],"id":46292327}],"con":true,"img":false}]}
{"op":"mcm","clk":"11450337963","pt":1717320718698,"mc":[{"id":"1.229554915","rc":[{"atl":[[42,0]],"id":70003370}],"con":true,"img":false}]}
{"op":"mcm","clk":"11450337975","pt":1717320718804,"mc":[{"id":"1.229554915","rc":[{"atl":[[38,11.43]],"id":70003370}],"con":true,"img":false}]}
{"op":"mcm","clk":"11450338000","pt":1717320719110,"mc":[{"id":"1.229554915","rc":[{"atl":[[80,0]],"id":56606596}],"con":true,"img":false}]}
{"op":"mcm","clk":"11450338006","pt":1717320719210,"mc":[{"id":"1.229554915","rc":[{"atl":[[95,7.66]],"id":56606596}],"con":true,"img":false}]}
{"op":"mcm","clk":"11450338033","pt":1717320719477,"mc":[{"id":"1.229554915","rc":[{"atl":[[110,0]],"id":65788088}],"con":true,"img":false}]}
{"op":"mcm","clk":"11450338039","pt":1717320719580,"mc":[{"id":"1.229554915","rc":[{"atl":[[140,7.66]],"id":65788088}],"con":true,"img":false}]}
{"op":"mcm","clk":"11450338076","pt":1717320720001,"mc":[{"id":"1.229554915","rc":[{"atb":[[1.3,696.87]],"id":64927898}],"con":true,"img":false}]}
{"op":"mcm","clk":"11450338081","pt":1717320720099,"mc":[{"id":"1.229554915","rc":[{"atb":[[1.29,11.07]],"id":64927898}],"con":true,"img":false}]}
{"op":"mcm","clk":"11450338109","pt":1717320720416,"mc":[{"id":"1.229554915","rc":[{"atb":[[3.15,97.23]],"id":65293046}],"con":true,"img":false}]}
{"op":"mcm","clk":"11450338118","pt":1717320720514,"mc":[{"id":"1.229554915","rc":[{"atb":[[3.3,11.07]],"id":65293046}],"con":true,"img":false}]}
{"op":"mcm","clk":"11450338141","pt":1717320720788,"mc":[{"id":"1.229554915","rc":[{"atb":[[6.4,0]],"id":46292327}],"con":true,"img":false}]}
{"op":"mcm","clk":"11450338148","pt":1717320720895,"mc":[{"id":"1.229554915","rc":[{"atb":[[6.2,22.53]],"id":46292327}],"con":true,"img":false}]}
{"op":"mcm","clk":"11450338170","pt":1717320721200,"mc":[{"id":"1.229554915","rc":[{"atb":[[6.6,10.39]],"id":70003370}],"con":true,"img":false}]}
{"op":"mcm","clk":"11450338178","pt":1717320721299,"mc":[{"id":"1.229554915","rc":[{"atb":[[6.2,31.17]],"id":70003370}],"con":true,"img":false}]}
{"op":"mcm","clk":"11450338203","pt":1717320721608,"mc":[{"id":"1.229554915","rc":[{"atb":[[10,0]],"id":56606596}],"con":true,"img":false}]}
{"op":"mcm","clk":"11450338215","pt":1717320721711,"mc":[{"id":"1.229554915","rc":[{"atb":[[10.5,22.08]],"id":56606596}],"con":true,"img":false}]}
{"op":"mcm","clk":"11450338238","pt":1717320722023,"mc":[{"id":"1.229554915","rc":[{"atb":[[11.5,0]],"id":65788088}],"con":true,"img":false}]}
{"op":"mcm","clk":"11450338248","pt":1717320722083,"mc":[{"id":"1.229554915","rc":[{"atb":[[13.5,19.43]],"id":65788088}],"con":true,"img":false}]}
{"op":"mcm","clk":"11450338272","pt":1717320722395,"mc":[{"id":"1.229554915","rc":[{"atb":[[42,0]],"id":51562794}],"con":true,"img":false}]}
{"op":"mcm","clk":"11450338824","pt":1717320728985,"mc":[{"id":"1.229554915","rc":[{"atb":[[34,6.33]],"id":51562794},{"atl":[[40,0]],"id":46292327},{"atb":[[12,0]],"id":65788088},{"atb":[[6.4,19.85],[5.9,0]],"id":70003370},{"atl":[[40,2.56]],"id":70003370},{"atl":[[18.5,0]],"id":65293046}],"con":true,"img":false}]}
{"op":"mcm","clk":"11450338831","pt":1717320729136,"mc":[{"id":"1.229554915","rc":[{"atb":[[36,4.18]],"id":51562794},{"atl":[[34,3.13]],"id":46292327},{"atb":[[11.5,7.01]],"id":65788088},{"atl":[[16,6.42]],"id":65293046},{"atl":[[36,3.24]],"id":70003370}],"con":true,"img":false}]}
{"op":"mcm","clk":"11450338887","pt":1717320729812,"mc":[{"id":"1.229554915","rc":[{"atl":[[30,0]],"id":70003370}],"con":true,"img":false}]}
{"op":"mcm","clk":"11450339928","pt":1717320742337,"mc":[{"id":"1.229554915","rc":[{"spn":262.0,"spf":"NaN","id":51562794},{"spn":15.1,"spf":"NaN","id":46292327},{"atb":[[8.4,0]],"id":65788088},{"spn":36.75,"spf":"NaN","id":65788088},{"atb":[[3.1,0]],"id":65293046},{"spn":7.82,"spf":"NaN","id":65293046}],"con":true,"img":false}]}
{"op":"mcm","clk":"11450339938","pt":1717320742437,"mc":[{"id":"1.229554915","rc":[{"atb":[[9.6,13.82]],"id":65788088},{"atb":[[3.45,45.91]],"id":65293046}],"con":true,"img":false}]}
{"op":"mcm","clk":"11450342543","pt":1717320774434,"mc":[{"id":"1.229554915","rc":[{"atb":[[1.29,0]],"id":64927898}],"con":true,"img":false}]}
{"op":"mcm","clk":"11450342550","pt":1717320774536,"mc":[{"id":"1.229554915","rc":[{"atb":[[1.22,11.07]],"id":64927898}],"con":true,"img":false}]}
{"op":"mcm","clk":"11450342562","pt":1717320774748,"mc":[{"id":"1.229554915","rc":[{"atb":[[3.3,0]],"id":65293046}],"con":true,"img":false}]}
{"op":"mcm","clk":"11450342572","pt":1717320774802,"mc":[{"id":"1.229554915","rc":[{"atb":[[3.1,11.07]],"id":65293046}],"con":true,"img":false}]}
{"op":"mcm","clk":"11450342593","pt":1717320775113,"mc":[{"id":"1.229554915","rc":[{"atb":[[6.2,11.45]],"id":46292327}],"con":true,"img":false}]}
{"op":"mcm","clk":"11450342601","pt":1717320775218,"mc":[{"id":"1.229554915","rc":[{"atb":[[5.9,11.07]],"id":46292327}],"con":true,"img":false}]}
{"op":"mcm","clk":"11450342619","pt":1717320775529,"mc":[{"id":"1.229554915","rc":[{"atb":[[6.2,20.1]],"id":70003370}],"con":true,"img":false}]}
{"op":"mcm","clk":"11450342625","pt":1717320775633,"mc":[{"id":"1.229554915","rc":[{"atb":[[6,11.07]],"id":70003370}],"con":true,"img":false}]}
{"op":"mcm","clk":"11450342656","pt":1717320776048,"mc":[{"id":"1.229554915","rc":[{"atb":[[10.5,11]],"id":56606596}],"con":true,"img":false}]}
{"op":"mcm","clk":"11450342664","pt":1717320776150,"mc":[{"id":"1.229554915","rc":[{"atb":[[10,11.07]],"id":56606596}],"con":true,"img":false}]}
{"op":"mcm","clk":"11450342691","pt":1717320776415,"mc":[{"id":"1.229554915","rc":[{"atb":[[13.5,8.36]],"id":65788088}],"con":true,"img":false}]}
{"op":"mcm","clk":"11450342699","pt":1717320776514,"mc":[{"id":"1.229554915","rc":[{"atb":[[13,11.07]],"id":65788088}],"con":true,"img":false}]}
{"op":"mcm","clk":"11450343102","pt":1717320781447,"mc":[{"id":"1.229554915","rc":[{"atb":[[20,0],[25,4.17]],"id":51562794},{"atl":[[85,0]],"id":56606596},{"atb":[[1.75,0],[1.95,105.26]],"id":65293046}],"con":true,"img":false}]}
{"op":"mcm","clk":"11450343340","pt":1717320784260,"mc":[{"id":"1.229554915","rc":[{"atb":[[34,9.36],[25,0]],"id":51562794},{"atb":[[2,100],[1.95,0]],"id":65293046}],"con":true,"img":false}]}
{"op":"mcm","clk":"11450343694","pt":1717320788861,"mc":[{"id":"1.229554915","rc":[{"atb":[[1.98,0],[2.06,94.34]],"id":56606596},{"atb":[[11,10]],"id":42099039}],"con":true,"img":false}]}
{"op":"mcm","clk":"11450343703","pt":1717320788915,"mc":[{"id":"1.229554915","rc":[{"atb":[[32,0]],"id":42099039}],"con":true,"img":false}]}
{"op":"mcm","clk":"11450345580","pt":1717320812769,"mc":[{"id":"1.229554915","rc":[{"atl":[[70,0],[55,0]],"id":56606596},{"spn":53.0,"spf":"NaN","id":56606596},{"atl":[[65,0],[85,0]],"id":65788088},{"atb":[[1.53,0],[1.39,335.87]],"id":64927898}],"con":true,"img":false}]}
{"op":"mcm","clk":"11450345588","pt":1717320812871,"mc":[{"id":"1.229554915","rc":[{"atl":[[85,2.61],[60,2.61]],"id":56606596},{"atl":[[80,2.61],[110,2.61]],"id":65788088}],"con":true,"img":false}]}
{"op":"mcm","clk":"11450345986","pt":1717320817688,"mc":[{"id":"1.229554915","rc":[{"atl":[[970,0]],"id":51562794},{"atb":[[1.56,0]],"id":64927898}],"con":true,"img":false}]}
{"op":"mcm","clk":"11450345995","pt":1717320817794,"mc":[{"id":"1.229554915","rc":[{"atb":[[1.53,76.86]],"id":64927898}],"con":true,"img":false}]}
{"op":"mcm","clk":"11450346008","pt":1717320817898,"mc":[{"id":"1.229554915","rc":[{"atl":[[60,0]],"id":65788088}],"con":true,"img":false}]}
{"op":"mcm","clk":"11450346904","pt":1717320828972,"mc":[{"id":"1.229554915","rc":[{"atl":[[3.25,24.93],[3.45,0]],"id":64927898}],"con":true,"img":false}]}
{"op":"mcm","clk":"11450347745","pt":1717320838895,"mc":[{"id":"1.229554915","rc":[{"atb":[[11.5,0],[14,4.31]],"id":65788088}],"con":true,"img":false}]}
{"op":"mcm","clk":"11450348394","pt":1717320845631,"mc":[{"id":"1.229554915","rc":[{"atl":[[38,14.13],[40,0]],"id":70003370}],"con":true,"img":false}]}
{"op":"mcm","clk":"11450349592","pt":1717320858929,"mc":[{"id":"1.229554915","rc":[{"atb":[[11.5,9.74],[9.6,0]],"id":65788088},{"atb":[[3.45,0]],"id":65293046},{"atl":[[4.3,36.62],[5.3,0]],"id":64927898}],"con":true,"img":false}]}
{"op":"mcm","clk":"11450349600","pt":1717320858981,"mc":[{"id":"1.229554915","rc":[{"atb":[[3.7,45.91]],"id":65293046}],"con":true,"img":false}]}
{"op":"mcm","clk":"11450350437","pt":1717320868907,"mc":[{"id":"1.229554915","rc":[{"atb":[[36,0],[46,2.61]],"id":51562794}],"con":true,"img":false}]}
{"op":"mcm","clk":"11450352627","pt":1717320894438,"mc":[{"id":"1.229554915","rc":[{"spn":263.0,"spf":"NaN","id":51562794},{"spn":35.5,"spf":"NaN","id":56606596},{"spn":47.0,"spf":"NaN","id":65788088},{"spn":7.85,"spf":"NaN","id":65293046},{"atb":[[1.22,0]],"id":64927898},{"spn":2.16,"spf":"NaN","id":64927898}],"con":true,"img":false}]}
{"op":"mcm","clk":"11450352635","pt":1717320894534,"mc":[{"id":"1.229554915","rc":[{"atb":[[1.26,11.07]],"id":64927898}],"con":true,"img":false}]}
{"op":"mcm","clk":"11450352660","pt":1717320894850,"mc":[{"id":"1.229554915","rc":[{"atb":[[3.1,0]],"id":65293046}],"con":true,"img":false}]}
{"op":"mcm","clk":"11450352664","pt":1717320894948,"mc":[{"id":"1.229554915","rc":[{"atb":[[3.2,11.07]],"id":65293046}],"con":true,"img":false}]}
{"op":"mcm","clk":"11450352688","pt":1717320895259,"mc":[{"id":"1.229554915","rc":[{"atb":[[5.9,0]],"id":46292327}],"con":true,"img":false}]}
{"op":"mcm","clk":"11450352695","pt":1717320895360,"mc":[{"id":"1.229554915","rc":[{"atb":[[6,11.07]],"id":46292327}],"con":true,"img":false}]}
{"op":"mcm","clk":"11450352711","pt":1717320895626,"mc":[{"id":"1.229554915","rc":[{"atb":[[6,0]],"id":70003370}],"con":true,"img":false}]}
{"op":"mcm","clk":"11450352715","pt":1717320895726,"mc":[{"id":"1.229554915","rc":[{"atb":[[6.2,31.17]],"id":70003370}],"con":true,"img":false}]}
{"op":"mcm","clk":"11450352741","pt":1717320896139,"mc":[{"id":"1.229554915","rc":[{"atb":[[10,0]],"id":56606596}],"con":true,"img":false}]}
{"op":"mcm","clk":"11450352747","pt":1717320896243,"mc":[{"id":"1.229554915","rc":[{"atb":[[10.5,22.08]],"id":56606596}],"con":true,"img":false}]}
{"op":"mcm","clk":"11450352767","pt":1717320896554,"mc":[{"id":"1.229554915","rc":[{"atb":[[13,0]],"id":65788088}],"con":true,"img":false}]}
{"op":"mcm","clk":"11450352773","pt":1717320896655,"mc":[{"id":"1.229554915","rc":[{"atb":[[13.5,19.43]],"id":65788088}],"con":true,"img":false}]}
{"op":"mcm","clk":"11450354552","pt":1717320917564,"mc":[{"id":"1.229554915","rc":[{"atl":[[60,0]],"id":56606596},{"atb":[[6.4,0],[6.6,0]],"id":70003370},{"atl":[[13,0]],"id":65293046}],"con":true,"img":false}]}
{"op":"mcm","clk":"11450354560","pt":1717320917668,"mc":[{"id":"1.229554915","rc":[{"atl":[[65,2.61]],"id":56606596},{"atb":[[6.4,10.39],[5.7,19.85]],"id":70003370},{"atl":[[14,5.34]],"id":65293046}],"con":true,"img":false}]}
{"op":"mcm","clk":"11450354573","pt":1717320917874,"mc":[{"id":"1.229554915","rc":[{"atl":[[12,0]],"id":65293046}],"con":true,"img":false}]}
{"op":"mcm","clk":"11450354619","pt":1717320918453,"mc":[{"id":"1.229554915","rc":[{"atl":[[12.5,0]],"id":65293046}],"con":true,"img":false}]}
{"op":"mcm","clk":"11450354625","pt":1717320918553,"mc":[{"id":"1.229554915","rc":[{"atl":[[13.5,7.66]],"id":65293046}],"con":true,"img":false}]}
{"op":"mcm","clk":"11450355462","pt":1717320928990,"mc":[{"id":"1.229554915","rc":[{"atl":[[32,0]],"id":70003370}],"con":true,"img":false}]}
{"op":"mcm","clk":"11450355471","pt":1717320929093,"mc":[{"id":"1.229554915","rc":[{"atl":[[30,2.61]],"id":70003370}],"con":true,"img":false}]}
{"op":"mcm","clk":"11450356292","pt":1717320938983,"mc":[{"id":"1.229554915","rc":[{"atb":[[3.65,39.44]],"id":65293046},{"atl":[[3.25,0]],"id":64927898}],"con":true,"img":false}]}
{"op":"mcm","clk":"11450356300","pt":1717320939084,"mc":[{"id":"1.229554915","rc":[{"atb":[[3.8,24.39]],"id":65293046},{"atl":[[3,32.6]],"id":64927898}],"con":true,"img":false}]}
{"op":"mcm","clk":"11450357552","pt":1717320954788,"mc":[{"id":"1.229554915","rc":[{"spn":38.0,"spf":"NaN","id":56606596},{"spn":8.65,"spf":"NaN","id":65293046},{"spn":18.2,"spf":"NaN","id":70003370},{"atb":[[1.26,0]],"id":64927898}],"con":true,"img":false}]}
{"op":"mcm","clk":"11450357560","pt":1717320954891,"mc":[{"id":"1.229554915","rc":[{"atb":[[1.29,11.07]],"id":64927898}],"con":true,"img":false}]}
{"op":"mcm","clk":"11450357586","pt":1717320955198,"mc":[{"id":"1.229554915","rc":[{"atb":[[3.2,0]],"id":65293046}],"con":true,"img":false}]}
{"op":"mcm","clk":"11450357597","pt":1717320955303,"mc":[{"id":"1.229554915","rc":[{"atb":[[3.3,11.07]],"id":65293046}],"con":true,"img":false}]}
{"op":"mcm","clk":"11450357621","pt":1717320955613,"mc":[{"id":"1.229554915","rc":[{"atb":[[6,0]],"id":46292327}],"con":true,"img":false}]}
{"op":"mcm","clk":"11450357628","pt":1717320955718,"mc":[{"id":"1.229554915","rc":[{"atb":[[6.2,22.53]],"id":46292327}],"con":true,"img":false}]}
{"op":"mcm","clk":"11450357873","pt":1717320958891,"mc":[{"id":"1.229554915","rc":[{"atl":[[14,0]],"id":65293046}],"con":true,"img":false}]}
{"op":"mcm","clk":"11450357881","pt":1717320958998,"mc":[{"id":"1.229554915","rc":[{"atl":[[13,5.34]],"id":65293046}],"con":true,"img":false}]}
{"op":"mcm","clk":"11450357923","pt":1717320959613,"mc":[{"id":"1.229554915","rc":[{"atl":[[13.5,0]],"id":65293046}],"con":true,"img":false}]}
{"op":"mcm","clk":"11450357930","pt":1717320959715,"mc":[{"id":"1.229554915","rc":[{"atl":[[12.5,7.66]],"id":65293046}],"con":true,"img":false}]}
{"op":"mcm","clk":"11450358722","pt":1717320968931,"mc":[{"id":"1.229554915","rc":[{"atl":[[13,0]],"id":65293046}],"con":true,"img":false}]}
{"op":"mcm","clk":"11450358736","pt":1717320969035,"mc":[{"id":"1.229554915","rc":[{"atl":[[14,5.34]],"id":65293046}],"con":true,"img":false}]}
{"op":"mcm","clk":"11450358754","pt":1717320969196,"mc":[{"id":"1.229554915","rc":[{"atl":[[12.5,0]],"id":65293046}],"con":true,"img":false}]}
{"op":"mcm","clk":"11450358759","pt":1717320969299,"mc":[{"id":"1.229554915","rc":[{"atl":[[15,7.66]],"id":65293046}],"con":true,"img":false}]}
{"op":"mcm","clk":"11450358837","pt":1717320970332,"mc":[{"id":"1.229554915","rc":[{"atl":[[15,0]],"id":65293046}],"con":true,"img":false}]}
{"op":"mcm","clk":"11450358846","pt":1717320970436,"mc":[{"id":"1.229554915","rc":[{"atl":[[13.5,7.66]],"id":65293046}],"con":true,"img":false}]}
{"op":"mcm","clk":"11450359396","pt":1717320977617,"mc":[{"id":"1.229554915","rc":[{"atl":[[95,0]],"id":56606596}],"con":true,"img":false}]}
{"op":"mcm","clk":"11450359402","pt":1717320977713,"mc":[{"id":"1.229554915","rc":[{"atl":[[110,7.66]],"id":56606596}],"con":true,"img":false}]}
{"op":"mcm","clk":"11450359429","pt":1717320978134,"mc":[{"id":"1.229554915","rc":[{"atb":[[1.29,0]],"id":64927898}],"con":true,"img":false}]}
{"op":"mcm","clk":"11450359437","pt":1717320978240,"mc":[{"id":"1.229554915","rc":[{"atb":[[1.27,11.07]],"id":64927898}],"con":true,"img":false}]}
{"op":"mcm","clk":"11450359458","pt":1717320978548,"mc":[{"id":"1.229554915","rc":[{"atb":[[3.3,0]],"id":65293046}],"con":true,"img":false}]}
{"op":"mcm","clk":"11450359468","pt":1717320978658,"mc":[{"id":"1.229554915","rc":[{"atb":[[3.35,11.07]],"id":65293046}],"con":true,"img":false}]}
{"op":"mcm","clk":"11450359496","pt":1717320979069,"mc":[{"id":"1.229554915","rc":[{"atb":[[10.5,11]],"id":56606596}],"con":true,"img":false}]}
{"op":"mcm","clk":"11450359500","pt":1717320979122,"mc":[{"id":"1.229554915","rc":[{"atb":[[11.5,11.07]],"id":56606596}],"con":true,"img":false}]}
{"op":"mcm","clk":"11450360377","pt":1717320990281,"mc":[{"id":"1.229554915","rc":[{"atb":[[34,3.03],[44,2.61],[27,0]],"id":51562794},{"atl":[[580,0],[480,0]],"id":51562794},{"atb":[[4.8,0],[4.3,0],[3.9,0]],"id":46292327},{"atl":[[38,0],[24,0]],"id":46292327},{"atb":[[9.2,0],[10.5,0],[8.2,0]],"id":56606596},{"atl":[[280,0],[180,0]],"id":56606596},{"atb":[[11,0],[13.5,11.07],[9.4,0]],"id":65788088},{"atl":[[320,0],[220,0]],"id":65788088},{"atb":[[34,0],[44,0],[60,2.61]],"id":42099039},{"atl":[[550,0],[650,0]],"id":42099039},{"atb":[[3.4,0],[3.15,0],[3.65,0]],"id":65293046},{"atl":[[16.5,0],[23,0]],"id":65293046},{"atb":[[5.6,0],[5.1,0],[6.2,11.07]],"id":70003370},{"atl":[[70,0],[38,10.36]],"id":70003370},{"atb":[[1.25,0],[1.3,0],[1.35,0]],"id":64927898},{"atl":[[2.82,0],[3.05,0]],"id":64927898}],"con":true,"img":false}]}
{"op":"mcm","clk":"11450360392","pt":1717320990439,"mc":[{"id":"1.229554915","rc":[{"atl":[[36,7.66],[38,2.7]],"id":46292327}],"con":true,"img":false}]}
{"op":"mcm","clk":"11450360489","pt":1717320991635,"mc":[{"id":"1.229554915","rc":[{"atl":[[2.8,0]],"id":64927898}],"con":true,"img":false}]}
{"op":"mcm","clk":"11450360853","pt":1717320995720,"mc":[{"id":"1.229554915","rc":[{"atl":[[2.98,5.68]],"id":64927898}],"con":true,"img":false}]}
{"op":"mcm","clk":"11450361102","pt":1717320998877,"mc":[{"id":"1.229554915","rc":[{"atb":[[36,3.66]],"id":51562794}],"con":true,"img":false}]}
{"op":"mcm","clk":"11450361110","pt":1717320998981,"mc":[{"id":"1.229554915","rc":[{"atb":[[46,0]],"id":51562794},{"atl":[[34,0]],"id":46292327},{"atb":[[11.5,0]],"id":65788088},{"atb":[[3.7,0]],"id":65293046},{"atl":[[16,0]],"id":65293046},{"atl":[[3,7.66]],"id":64927898}],"con":true,"img":false}]}
{"op":"mcm","clk":"11450361121","pt":1717320999085,"mc":[{"id":"1.229554915","rc":[{"atl":[[36,10.8]],"id":46292327},{"atb":[[9.8,9.74]],"id":65788088},{"atb":[[3.25,45.91]],"id":65293046},{"atl":[[19.5,6.42]],"id":65293046},{"atl":[[3.25,24.93]],"id":64927898}],"con":true,"img":false}]}
{"op":"mcm","clk":"11450361217","pt":1717321000284,"mc":[{"id":"1.229554915","rc":[{"atl":[[2.98,0]],"id":64927898}],"con":true,"img":false}]}
{"op":"mcm","clk":"11450361292","pt":1717321001377,"mc":[{"id":"1.229554915","rc":[{"atl":[[3,0]],"id":64927898}],"con":true,"img":false}]}
{"op":"mcm","clk":"11450361302","pt":1717321001477,"mc":[{"id":"1.229554915","rc":[{"atl":[[3.2,7.66]],"id":64927898}],"con":true,"img":false}]}
{"op":"mcm","clk":"11450362078","pt":1717321011721,"mc":[{"id":"1.229554915","rc":[{"atb":[[34,9.36],[44,5.04],[27,8.04]],"id":51562794},{"atl":[[580,0.36],[480,0.29]],"id":51562794},{"atb":[[4.8,27.5],[4.3,63.35],[3.9,72.08]],"id":46292327},{"atl":[[38,8.35],[24,6.05]],"id":46292327},{"atb":[[9.2,25.49],[10.5,11],[8.2,29.03]],"id":56606596},{"atl":[[280,0.74],[180,0.77]],"id":56606596},{"atb":[[11,20.9],[13.5,19.43],[9.4,24.88]],"id":65788088},{"atl":[[320,0.65],[220,0.63]],"id":65788088},{"atb":[[34,6.33],[44,4.86],[60,4.38]],"id":42099039},{"atl":[[550,0.25],[650,0.32]],"id":42099039},{"atb":[[3.4,87.1],[3.15,97.23],[3.65,39.44]],"id":65293046},{"atl":[[16.5,8.99],[23,9.5]],"id":65293046},{"atb":[[5.6,45.44],[5.1,50.98],[6.2,31.17]],"id":70003370},{"atl":[[70,3.02],[38,14.13]],"id":70003370},{"atb":[[1.25,836.24],[1.3,696.87],[1.35,298.66]],"id":64927898},{"atl":[[2.82,76.57],[3.05,101.98]],"id":64927898}],"con":true,"img":false}]}
{"op":"mcm","clk":"11450362124","pt":1717321012194,"mc":[{"id":"1.229554915","rc":[{"atl":[[3.2,0]],"id":64927898}],"con":true,"img":false}]}
{"op":"mcm","clk":"11450362131","pt":1717321012296,"mc":[{"id":"1.229554915","rc":[{"atl":[[3,7.66]],"id":64927898}],"con":true,"img":false}]}
{"op":"mcm","clk":"11450362148","pt":1717321012606,"mc":[{"id":"1.229554915","rc":[{"atl":[[2.8,8.7]],"id":64927898}],"con":true,"img":false}]}
{"op":"mcm","clk":"11450362671","pt":1717321018912,"mc":[{"id":"1.229554915","rc":[{"spn":262.0,"spf":"NaN","id":51562794},{"atb":[[11,0],[12,5.1]],"id":56606596},{"spn":38.5,"spf":"NaN","id":56606596}],"con":true,"img":false}]}
{"op":"mcm","clk":"11450364271","pt":1717321038930,"mc":[{"id":"1.229554915","rc":[{"atl":[[14,0]],"id":65293046}],"con":true,"img":false}]}
{"op":"mcm","clk":"11450364310","pt":1717321039065,"mc":[{"id":"1.229554915","rc":[{"atl":[[13,5.34]],"id":65293046}],"con":true,"img":false}]}
{"op":"mcm","clk":"11450364372","pt":1717321039609,"mc":[{"id":"1.229554915","rc":[{"atl":[[13.5,0]],"id":65293046}],"con":true,"img":false}]}
{"op":"mcm","clk":"11450364381","pt":1717321039718,"mc":[{"id":"1.229554915","rc":[{"atl":[[12.5,7.66]],"id":65293046}],"con":true,"img":false}]}
{"op":"mcm","clk":"11450364697","pt":1717321044348,"mc":[{"id":"1.229554915","rc":[{"atb":[[2,0],[2.1,90.91]],"id":65293046}],"con":true,"img":false}]}
{"op":"mcm","clk":"11450364966","pt":1717321048046,"mc":[{"id":"1.229554915","rc":[{"atb":[[1.4,19.62]],"id":64927898}],"con":true,"img":false}]}
{"op":"mcm","clk":"11450365043","pt":1717321048940,"mc":[{"id":"1.229554915","rc":[{"atl":[[36,7.66]],"id":46292327},{"atl":[[13,0]],"id":65293046},{"atl":[[3.25,0]],"id":64927898}],"con":true,"img":false}]}
{"op":"mcm","clk":"11450365048","pt":1717321049060,"mc":[{"id":"1.229554915","rc":[{"atl":[[34,3.13]],"id":46292327},{"atl":[[14,5.34]],"id":65293046},{"atl":[[3,32.6]],"id":64927898}],"con":true,"img":false}]}
{"op":"mcm","clk":"11450365070","pt":1717321049324,"mc":[{"id":"1.229554915","rc":[{"atl":[[12.5,0]],"id":65293046}],"con":true,"img":false}]}
{"op":"mcm","clk":"11450365078","pt":1717321049432,"mc":[{"id":"1.229554915","rc":[{"atl":[[16,7.66]],"id":65293046}],"con":true,"img":false}]}
{"op":"mcm","clk":"11450365165","pt":1717321050627,"mc":[{"id":"1.229554915","rc":[{"atl":[[16,0]],"id":65293046}],"con":true,"img":false}]}
{"op":"mcm","clk":"11450365173","pt":1717321050796,"mc":[{"id":"1.229554915","rc":[{"atl":[[13.5,7.66]],"id":65293046}],"con":true,"img":false}]}
{"op":"mcm","clk":"11450365596","pt":1717321056566,"mc":[{"id":"1.229554915","rc":[{"atb":[[3.5,0],[3.75,36.36]],"id":46292327}],"con":true,"img":false}]}
{"op":"mcm","clk":"11450365751","pt":1717321058855,"mc":[{"id":"1.229554915","rc":[{"atb":[[46,2.61]],"id":51562794}],"con":true,"img":false}]}
{"op":"mcm","clk":"11450365760","pt":1717321058952,"mc":[{"id":"1.229554915","rc":[{"atb":[[36,0]],"id":51562794},{"atb":[[9.8,0]],"id":65788088},{"atb":[[3.25,0]],"id":65293046},{"atl":[[19.5,0]],"id":65293046}],"con":true,"img":false}]}
{"op":"mcm","clk":"11450365768","pt":1717321059064,"mc":[{"id":"1.229554915","rc":[{"atb":[[11.5,9.74]],"id":65788088},{"atb":[[3.7,45.91]],"id":65293046},{"atl":[[16,6.42]],"id":65293046}],"con":true,"img":false}]}
{"op":"mcm","clk":"11450367116","pt":1717321078986,"mc":[{"id":"1.229554915","rc":[{"spn":263.0,"spf":"NaN","id":51562794},{"atl":[[14,0]],"id":65293046}],"con":true,"img":false}]}
{"op":"mcm","clk":"11450367119","pt":1717321079093,"mc":[{"id":"1.229554915","rc":[{"atl":[[13,5.34]],"id":65293046}],"con":true,"img":false}]}
{"op":"mcm","clk":"11450367178","pt":1717321079978,"mc":[{"id":"1.229554915","rc":[{"atl":[[13.5,0]],"id":65293046}],"con":true,"img":false}]}
{"op":"mcm","clk":"11450367185","pt":1717321080084,"mc":[{"id":"1.229554915","rc":[{"atl":[[12.5,7.66]],"id":65293046}],"con":true,"img":false}]}
{"op":"mcm","clk":"11450367811","pt":1717321088977,"mc":[{"id":"1.229554915","rc":[{"atl":[[13,0]],"id":65293046}],"con":true,"img":false}]}
{"op":"mcm","clk":"11450367822","pt":1717321089093,"mc":[{"id":"1.229554915","rc":[{"atl":[[14,5.34]],"id":65293046}],"con":true,"img":false}]}
{"op":"mcm","clk":"11450367846","pt":1717321089390,"mc":[{"id":"1.229554915","rc":[{"atl":[[12.5,0]],"id":65293046}],"con":true,"img":false}]}
{"op":"mcm","clk":"11450367853","pt":1717321089489,"mc":[{"id":"1.229554915","rc":[{"atl":[[13.5,7.66]],"id":65293046}],"con":true,"img":false}]}
{"op":"mcm","clk":"11450369856","pt":1717321118933,"mc":[{"id":"1.229554915","rc":[{"atl":[[14,0]],"id":65293046}],"con":true,"img":false}]}
{"op":"mcm","clk":"11450369864","pt":1717321119048,"mc":[{"id":"1.229554915","rc":[{"atl":[[13,5.34]],"id":65293046}],"con":true,"img":false}]}
{"op":"mcm","clk":"11450369926","pt":1717321120025,"mc":[{"id":"1.229554915","rc":[{"atl":[[13.5,0]],"id":65293046}],"con":true,"img":false}]}
{"op":"mcm","clk":"11450369928","pt":1717321120129,"mc":[{"id":"1.229554915","rc":[{"atl":[[12.5,7.66]],"id":65293046}],"con":true,"img":false}]}
{"op":"mcm","clk":"11450370525","pt":1717321128942,"mc":[{"id":"1.229554915","rc":[{"atl":[[13,0]],"id":65293046}],"con":true,"img":false}]}
{"op":"mcm","clk":"11450370533","pt":1717321129036,"mc":[{"id":"1.229554915","rc":[{"atl":[[14,5.34]],"id":65293046}],"con":true,"img":false}]}
{"op":"mcm","clk":"11450370566","pt":1717321129449,"mc":[{"id":"1.229554915","rc":[{"atl":[[12.5,0]],"id":65293046}],"con":true,"img":false}]}
{"op":"mcm","clk":"11450370573","pt":1717321129550,"mc":[{"id":"1.229554915","rc":[{"atl":[[13.5,7.66]],"id":65293046}],"con":true,"img":false}]}
{"op":"mcm","clk":"11450372645","pt":1717321158980,"mc":[{"id":"1.229554915","rc":[{"atl":[[14,0]],"id":65293046}],"con":true,"img":false}]}
{"op":"mcm","clk":"11450372651","pt":1717321159078,"mc":[{"id":"1.229554915","rc":[{"atl":[[13,5.34]],"id":65293046}],"con":true,"img":false}]}
{"op":"mcm","clk":"11450372693","pt":1717321159552,"mc":[{"id":"1.229554915","rc":[{"atl":[[13.5,0]],"id":65293046}],"con":true,"img":false}]}
{"op":"mcm","clk":"11450372702","pt":1717321159656,"mc":[{"id":"1.229554915","rc":[{"atl":[[12.5,7.66]],"id":65293046}],"con":true,"img":false}]}
{"op":"mcm","clk":"11450373344","pt":1717321169001,"mc":[{"id":"1.229554915","rc":[{"atl":[[13,0]],"id":65293046}],"con":true,"img":false}]}
{"op":"mcm","clk":"11450373357","pt":1717321169103,"mc":[{"id":"1.229554915","rc":[{"atl":[[14,5.34]],"id":65293046}],"con":true,"img":false}]}
{"op":"mcm","clk":"11450373409","pt":1717321169985,"mc":[{"id":"1.229554915","rc":[{"atl":[[12.5,0]],"id":65293046}],"con":true,"img":false}]}
{"op":"mcm","clk":"11450373416","pt":1717321170092,"mc":[{"id":"1.229554915","rc":[{"atl":[[13.5,7.66]],"id":65293046}],"con":true,"img":false}]}
{"op":"mcm","clk":"11450375179","pt":1717321198959,"mc":[{"id":"1.229554915","rc":[{"atl":[[14,0]],"id":65293046}],"con":true,"img":false}]}
{"op":"mcm","clk":"11450375185","pt":1717321199060,"mc":[{"id":"1.229554915","rc":[{"atl":[[13,5.34]],"id":65293046}],"con":true,"img":false}]}
{"op":"mcm","clk":"11450375205","pt":1717321199372,"mc":[{"id":"1.229554915","rc":[{"atl":[[13.5,0]],"id":65293046}],"con":true,"img":false}]}
{"op":"mcm","clk":"11450375210","pt":1717321199478,"mc":[{"id":"1.229554915","rc":[{"atl":[[15.5,7.66]],"id":65293046}],"con":true,"img":false}]}
{"op":"mcm","clk":"11450375288","pt":1717321200670,"mc":[{"id":"1.229554915","rc":[{"atl":[[15.5,0]],"id":65293046}],"con":true,"img":false}]}
{"op":"mcm","clk":"11450375296","pt":1717321200771,"mc":[{"id":"1.229554915","rc":[{"atl":[[12.5,7.66]],"id":65293046}],"con":true,"img":false}]}
{"op":"mcm","clk":"11450375388","pt":1717321202182,"mc":[{"id":"1.229554915","rc":[{"atl":[[1000,2.02]],"id":46292327}],"con":true,"img":false}]}
{"op":"mcm","clk":"11450375408","pt":1717321202385,"mc":[{"id":"1.229554915","rc":[{"atl":[[1000,1.85]],"id":65293046}],"con":true,"img":false}]}
{"op":"mcm","clk":"11450375422","pt":1717321202651,"mc":[{"id":"1.229554915","rc":[{"atl":[[1000,1.85]],"id":56606596},{"atl":[[1000,2.02]],"id":70003370}],"con":true,"img":false}]}
{"op":"mcm","clk":"11450375442","pt":1717321202960,"mc":[{"id":"1.229554915","rc":[{"atl":[[1000,1.85]],"id":65788088}],"con":true,"img":false}]}
{"op":"mcm","clk":"11450375583","pt":1717321205081,"mc":[{"id":"1.229554915","rc":[{"atl":[[1000,1.53]],"id":46292327}],"con":true,"img":false}]}
{"op":"mcm","clk":"11450375618","pt":1717321205552,"mc":[{"id":"1.229554915","rc":[{"atl":[[1000,1.68]],"id":65293046}],"con":true,"img":false}]}
{"op":"mcm","clk":"11450375669","pt":1717321206496,"mc":[{"id":"1.229554915","rc":[{"atl":[[1000,1.46]],"id":70003370}],"con":true,"img":false}]}
{"op":"mcm","clk":"11450375683","pt":1717321206848,"mc":[{"id":"1.229554915","rc":[{"atl":[[1000,1.11]],"id":65788088}],"con":true,"img":false}]}
{"op":"mcm","clk":"11450375690","pt":1717321206952,"mc":[{"id":"1.229554915","rc":[{"atl":[[1000,1.14]],"id":56606596}],"con":true,"img":false}]}
{"op":"mcm","clk":"11450375782","pt":1717321208965,"mc":[{"id":"1.229554915","rc":[{"atl":[[1000,1.17]],"id":46292327},{"atl":[[13,0]],"id":65293046}],"con":true,"img":false}]}
{"op":"mcm","clk":"11450375787","pt":1717321209071,"mc":[{"id":"1.229554915","rc":[{"atl":[[14,5.34]],"id":65293046}],"con":true,"img":false}]}
{"op":"mcm","clk":"11450375794","pt":1717321209177,"mc":[{"id":"1.229554915","rc":[{"atl":[[23,0.36]],"id":46292327}],"con":true,"img":false}]}
{"op":"mcm","clk":"11450375838","pt":1717321210159,"mc":[{"id":"1.229554915","rc":[{"atl":[[12.5,0]],"id":65293046}],"con":true,"img":false}]}
{"op":"mcm","clk":"11450375842","pt":1717321210260,"mc":[{"id":"1.229554915","rc":[{"atl":[[13.5,7.66],[1000,1]],"id":65293046}],"con":true,"img":false}]}
{"op":"mcm","clk":"11450375848","pt":1717321210364,"mc":[{"id":"1.229554915","rc":[{"atl":[[12.5,0.68]],"id":65293046}],"con":true,"img":false}]}
{"op":"mcm","clk":"11450375907","pt":1717321211860,"mc":[{"id":"1.229554915","rc":[{"atl":[[1000,1.17]],"id":70003370}],"con":true,"img":false}]}
{"op":"mcm","clk":"11450375914","pt":1717321211958,"mc":[{"id":"1.229554915","rc":[{"atl":[[29,0.28]],"id":70003370}],"con":true,"img":false}]}
{"op":"mcm","clk":"11450375951","pt":1717321212787,"mc":[{"id":"1.229554915","rc":[{"atl":[[1000,1]],"id":65788088}],"con":true,"img":false}]}
{"op":"mcm","clk":"11450375957","pt":1717321212886,"mc":[{"id":"1.229554915","rc":[{"atl":[[75,0.11]],"id":65788088}],"con":true,"img":false}]}
{"op":"mcm","clk":"11450375973","pt":1717321213152,"mc":[{"id":"1.229554915","rc":[{"atl":[[1000,1]],"id":56606596}],"con":true,"img":false}]}
{"op":"mcm","clk":"11450375981","pt":1717321213303,"mc":[{"id":"1.229554915","rc":[{"atl":[[60,0.14]],"id":56606596}],"con":true,"img":false}]}
{"op":"mcm","clk":"11450377535","pt":1717321238993,"mc":[{"id":"1.229554915","rc":[{"atl":[[29,0]],"id":46292327},{"spn":14.6,"spf":"NaN","id":46292327},{"spn":36.0,"spf":"NaN","id":56606596},{"spn":44.5,"spf":"NaN","id":65788088},{"spn":17.7,"spf":"NaN","id":70003370},{"atl":[[14,0]],"id":65293046},{"spn":8.15,"spf":"NaN","id":65293046}],"con":true,"img":false}]}
{"op":"mcm","clk":"11450377542","pt":1717321239096,"mc":[{"id":"1.229554915","rc":[{"atl":[[28,2.61]],"id":46292327},{"atl":[[13,5.34]],"id":65293046}],"con":true,"img":false}]}
{"op":"mcm","clk":"11450377568","pt":1717321239509,"mc":[{"id":"1.229554915","rc":[{"atl":[[13.5,0]],"id":65293046}],"con":true,"img":false}]}
{"op":"mcm","clk":"11450377575","pt":1717321239612,"mc":[{"id":"1.229554915","rc":[{"atl":[[12.5,8.35]],"id":65293046}],"con":true,"img":false}]}
{"op":"mcm","clk":"11450377608","pt":1717321240284,"mc":[{"id":"1.229554915","rc":[{"atl":[[12.5,7.66]],"id":65293046}],"con":true,"img":false}]}
{"op":"mcm","clk":"11450377613","pt":1717321240389,"mc":[{"id":"1.229554915","rc":[{"atl":[[1000,1.85]],"id":65293046}],"con":true,"img":false}]}
{"op":"mcm","clk":"11450377626","pt":1717321240600,"mc":[{"id":"1.229554915","rc":[{"atl":[[23,0]],"id":46292327}],"con":true,"img":false}]}
{"op":"mcm","clk":"11450377657","pt":1717321241220,"mc":[{"id":"1.229554915","rc":[{"atl":[[1000,1.68]],"id":65293046}],"con":true,"img":false}]}
{"op":"mcm","clk":"11450377679","pt":1717321241585,"mc":[{"id":"1.229554915","rc":[{"atl":[[1000,2.02]],"id":46292327}],"con":true,"img":false}]}
{"op":"mcm","clk":"11450377734","pt":1717321242517,"mc":[{"id":"1.229554915","rc":[{"atl":[[1000,1]],"id":65293046}],"con":true,"img":false}]}
{"op":"mcm","clk":"11450377741","pt":1717321242620,"mc":[{"id":"1.229554915","rc":[{"atl":[[13,6.02]],"id":65293046}],"con":true,"img":false}]}
{"op":"mcm","clk":"11450377803","pt":1717321243707,"mc":[{"id":"1.229554915","rc":[{"atl":[[1000,1.53]],"id":46292327}],"con":true,"img":false}]}
{"op":"mcm","clk":"11450377860","pt":1717321244390,"mc":[{"id":"1.229554915","rc":[{"atl":[[1000,1.85]],"id":65293046}],"con":true,"img":false}]}
{"op":"mcm","clk":"11450377891","pt":1717321244907,"mc":[{"id":"1.229554915","rc":[{"atl":[[1000,1.17]],"id":46292327}],"con":true,"img":false}]}
{"op":"mcm","clk":"11450377896","pt":1717321245011,"mc":[{"id":"1.229554915","rc":[{"atl":[[27,0.36]],"id":46292327},{"atl":[[13,5.34]],"id":65293046}],"con":true,"img":false}]}
{"op":"mcm","clk":"11450377936","pt":1717321245689,"mc":[{"id":"1.229554915","rc":[{"atl":[[1000,1.7]],"id":65293046}],"con":true,"img":false}]}
{"op":"mcm","clk":"11450377971","pt":1717321246414,"mc":[{"id":"1.229554915","rc":[{"atl":[[1000,2.02]],"id":46292327}],"con":true,"img":false}]}
{"op":"mcm","clk":"11450377980","pt":1717321246518,"mc":[{"id":"1.229554915","rc":[{"atl":[[1000,1]],"id":65293046}],"con":true,"img":false}]}
{"op":"mcm","clk":"11450377987","pt":1717321246623,"mc":[{"id":"1.229554915","rc":[{"atl":[[12,0.7]],"id":65293046}],"con":true,"img":false}]}
{"op":"mcm","clk":"11450377996","pt":1717321246726,"mc":[{"id":"1.229554915","rc":[{"atl":[[27,0]],"id":46292327}],"con":true,"img":false}]}
{"op":"mcm","clk":"11450378040","pt":1717321247458,"mc":[{"id":"1.229554915","rc":[{"atl":[[1000,1.55]],"id":46292327}],"con":true,"img":false}]}
{"op":"mcm","clk":"11450378066","pt":1717321247815,"mc":[{"id":"1.229554915","rc":[{"atl":[[1000,1.17]],"id":46292327}],"con":true,"img":false}]}
{"op":"mcm","clk":"11450378071","pt":1717321247918,"mc":[{"id":"1.229554915","rc":[{"atl":[[22,0.38]],"id":46292327}],"con":true,"img":false}]}
{"op":"mcm","clk":"11450378114","pt":1717321248910,"mc":[{"id":"1.229554915","rc":[{"atl":[[13,0]],"id":65293046}],"con":true,"img":false}]}
{"op":"mcm","clk":"11450378121","pt":1717321249009,"mc":[{"id":"1.229554915","rc":[{"atl":[[14,5.34]],"id":65293046}],"con":true,"img":false}]}
{"op":"mcm","clk":"11450378152","pt":1717321249727,"mc":[{"id":"1.229554915","rc":[{"atl":[[12.5,0]],"id":65293046}],"con":true,"img":false}]}
{"op":"mcm","clk":"11450378161","pt":1717321249832,"mc":[{"id":"1.229554915","rc":[{"atl":[[13.5,7.66]],"id":65293046}],"con":true,"img":false}]}
{"op":"mcm","clk":"11450379672","pt":1717321272913,"mc":[{"id":"1.229554915","rc":[{"atl":[[1000,1.85]],"id":65293046}],"con":true,"img":false}]}
{"op":"mcm","clk":"11450379697","pt":1717321273224,"mc":[{"id":"1.229554915","rc":[{"atl":[[12,0]],"id":65293046}],"con":true,"img":false}]}
{"op":"mcm","clk":"11450379713","pt":1717321273537,"mc":[{"id":"1.229554915","rc":[{"atl":[[1000,2.02]],"id":46292327}],"con":true,"img":false}]}
{"op":"mcm","clk":"11450379807","pt":1717321274629,"mc":[{"id":"1.229554915","rc":[{"atl":[[22,0]],"id":46292327}],"con":true,"img":false}]}
{"op":"mcm","clk":"11450379831","pt":1717321274940,"mc":[{"id":"1.229554915","rc":[{"atl":[[1000,1.7]],"id":65293046}],"con":true,"img":false}]}
{"op":"mcm","clk":"11450379976","pt":1717321277114,"mc":[{"id":"1.229554915","rc":[{"atl":[[1000,1]],"id":65293046}],"con":true,"img":false}]}
{"op":"mcm","clk":"11450379982","pt":1717321277217,"mc":[{"id":"1.229554915","rc":[{"atl":[[13,0.7]],"id":65293046}],"con":true,"img":false}]}
{"op":"mcm","clk":"11450380096","pt":1717321279047,"mc":[{"id":"1.229554915","rc":[{"atl":[[14,0]],"id":65293046}],"con":true,"img":false}]}
{"op":"mcm","clk":"11450380104","pt":1717321279154,"mc":[{"id":"1.229554915","rc":[{"atl":[[1000,2.87]],"id":46292327},{"atl":[[13,6.04]],"id":65293046}],"con":true,"img":false}]}
{"op":"mcm","clk":"11450380125","pt":1717321279563,"mc":[{"id":"1.229554915","rc":[{"atl":[[13.5,0]],"id":65293046}],"con":true,"img":false}]}
{"op":"mcm","clk":"11450380130","pt":1717321279662,"mc":[{"id":"1.229554915","rc":[{"atl":[[12.5,7.66]],"id":65293046}],"con":true,"img":false}]}
{"op":"mcm","clk":"11450380171","pt":1717321280236,"mc":[{"id":"1.229554915","rc":[{"atl":[[1000,2.43]],"id":46292327}],"con":true,"img":false}]}
{"op":"mcm","clk":"11450380229","pt":1717321281066,"mc":[{"id":"1.229554915","rc":[{"atl":[[1000,2.02]],"id":46292327}],"con":true,"img":false}]}
{"op":"mcm","clk":"11450380236","pt":1717321281122,"mc":[{"id":"1.229554915","rc":[{"atl":[[21,0.4]],"id":46292327}],"con":true,"img":false}]}
{"op":"mcm","clk":"11450380783","pt":1717321288961,"mc":[{"id":"1.229554915","rc":[{"atl":[[13,0.7]],"id":65293046}],"con":true,"img":false}]}
{"op":"mcm","clk":"11450380789","pt":1717321289064,"mc":[{"id":"1.229554915","rc":[{"atl":[[14,5.34]],"id":65293046}],"con":true,"img":false}]}
{"op":"mcm","clk":"11450380817","pt":1717321289475,"mc":[{"id":"1.229554915","rc":[{"atl":[[12.5,0]],"id":65293046}],"con":true,"img":false}]}
{"op":"mcm","clk":"11450380827","pt":1717321289527,"mc":[{"id":"1.229554915","rc":[{"atl":[[13.5,7.66]],"id":65293046}],"con":true,"img":false}]}
{"op":"mcm","clk":"11450381655","pt":1717321302881,"mc":[{"id":"1.229554915","rc":[{"atl":[[21,0]],"id":46292327},{"spn":15.1,"spf":"NaN","id":46292327},{"spn":8.4,"spf":"NaN","id":65293046}],"con":true,"img":false}]}
{"op":"mcm","clk":"11450382285","pt":1717321314011,"mc":[{"id":"1.229554915","rc":[{"atb":[[34,3.03],[44,2.61],[27,0]],"id":51562794},{"atl":[[580,0],[480,0]],"id":51562794},{"atb":[[4.8,0],[4.3,0],[3.9,0]],"id":46292327},{"atl":[[38,2.7],[24,0]],"id":46292327},{"atb":[[9.2,0],[10.5,0],[8.2,0]],"id":56606596},{"atl":[[280,0],[180,0]],"id":56606596},{"atb":[[11,0],[13.5,11.07],[9.4,0]],"id":65788088},{"atl":[[320,0],[220,0]],"id":65788088},{"atb":[[34,0],[44,0],[60,2.61]],"id":42099039},{"atl":[[550,0],[650,0]],"id":42099039},{"atb":[[3.4,0],[3.15,0],[3.65,0]],"id":65293046},{"atl":[[16.5,0],[23,0]],"id":65293046},{"atb":[[5.6,0],[5.1,0],[6.2,11.07]],"id":70003370},{"atl":[[70,0],[38,10.36]],"id":70003370},{"atb":[[1.25,0],[1.3,0],[1.35,0]],"id":64927898},{"atl":[[2.82,0],[3.05,0]],"id":64927898}],"con":true,"img":false}]}
{"op":"mcm","clk":"11450382466","pt":1717321316982,"mc":[{"id":"1.229554915","rc":[{"atl":[[2.8,0]],"id":64927898}],"con":true,"img":false}]}
{"op":"mcm","clk":"11450382602","pt":1717321318904,"mc":[{"id":"1.229554915","rc":[{"atb":[[36,3.66],[46,0]],"id":51562794},{"atl":[[34,0]],"id":46292327},{"atb":[[11.5,0]],"id":65788088},{"atb":[[3.7,0]],"id":65293046},{"atl":[[16,0]],"id":65293046},{"atl":[[3,7.66]],"id":64927898}],"con":true,"img":false}]}
{"op":"mcm","clk":"11450382611","pt":1717321319008,"mc":[{"id":"1.229554915","rc":[{"atl":[[36,10.8]],"id":46292327},{"atb":[[9.8,9.74]],"id":65788088},{"atb":[[3.25,45.91]],"id":65293046},{"atl":[[19.5,6.42]],"id":65293046},{"atl":[[3.25,24.93]],"id":64927898}],"con":true,"img":false}]}
{"op":"mcm","clk":"11450382671","pt":1717321319886,"mc":[{"id":"1.229554915","rc":[{"atl":[[3,0]],"id":64927898}],"con":true,"img":false}]}
{"op":"mcm","clk":"11450382674","pt":1717321319987,"mc":[{"id":"1.229554915","rc":[{"atl":[[3.2,7.66]],"id":64927898}],"con":true,"img":false}]}
{"op":"mcm","clk":"11450383457","pt":1717321332852,"mc":[{"id":"1.229554915","rc":[{"atb":[[34,9.36],[44,5.04],[27,8.04]],"id":51562794},{"atl":[[580,0.36],[480,0.29]],"id":51562794},{"atb":[[4.8,27.5],[4.3,63.35],[3.9,72.08]],"id":46292327},{"atl":[[38,8.35],[24,6.05]],"id":46292327},{"atb":[[9.2,25.49],[10.5,11],[8.2,29.03]],"id":56606596},{"atl":[[280,0.74],[180,0.77]],"id":56606596},{"atb":[[11,20.9],[13.5,19.43],[9.4,24.88]],"id":65788088},{"atl":[[320,0.65],[220,0.63]],"id":65788088},{"atb":[[34,6.33],[44,4.86],[60,4.38]],"id":42099039},{"atl":[[550,0.25],[650,0.32]],"id":42099039},{"atb":[[3.4,87.1],[3.15,97.23],[3.65,39.44]],"id":65293046},{"atl":[[16.5,8.99],[23,9.5]],"id":65293046},{"atb":[[5.6,45.44],[5.1,50.98],[6.2,31.17]],"id":70003370},{"atl":[[70,3.02],[38,14.13]],"id":70003370},{"atb":[[1.25,836.24],[1.3,696.87],[1.35,298.66]],"id":64927898},{"atl":[[2.82,76.57],[3.05,101.98]],"id":64927898}],"con":true,"img":false}]}
{"op":"mcm","clk":"11450383496","pt":1717321333380,"mc":[{"id":"1.229554915","rc":[{"atl":[[3.2,0]],"id":64927898}],"con":true,"img":false}]}
{"op":"mcm","clk":"11450383508","pt":1717321333486,"mc":[{"id":"1.229554915","rc":[{"atl":[[3,7.66]],"id":64927898}],"con":true,"img":false}]}
{"op":"mcm","clk":"11450383628","pt":1717321335254,"mc":[{"id":"1.229554915","rc":[{"atl":[[2.8,8.58]],"id":64927898}],"con":true,"img":false}]}
{"op":"mcm","clk":"11450385016","pt":1717321359101,"mc":[{"id":"1.229554915","rc":[{"atl":[[14,0]],"id":65293046}],"con":true,"img":false}]}
{"op":"mcm","clk":"11450385024","pt":1717321359208,"mc":[{"id":"1.229554915","rc":[{"atl":[[13,6.04]],"id":65293046}],"con":true,"img":false}]}
{"op":"mcm","clk":"11450385039","pt":1717321359467,"mc":[{"id":"1.229554915","rc":[{"atl":[[13,5.34]],"id":65293046}],"con":true,"img":false}]}
{"op":"mcm","clk":"11450385068","pt":1717321359981,"mc":[{"id":"1.229554915","rc":[{"atl":[[13.5,0]],"id":65293046}],"con":true,"img":false}]}
{"op":"mcm","clk":"11450385074","pt":1717321360088,"mc":[{"id":"1.229554915","rc":[{"atl":[[12.5,7.66]],"id":65293046}],"con":true,"img":false}]}
{"op":"mcm","clk":"11450385553","pt":1717321368418,"mc":[{"id":"1.229554915","rc":[{"spn":262.0,"spf":"NaN","id":51562794},{"atl":[[36,7.66]],"id":46292327},{"spn":8.15,"spf":"NaN","id":65293046},{"atl":[[3.25,0]],"id":64927898}],"con":true,"img":false}]}
{"op":"mcm","clk":"11450385561","pt":1717321368515,"mc":[{"id":"1.229554915","rc":[{"atl":[[34,3.13]],"id":46292327},{"atl":[[3,32.6]],"id":64927898}],"con":true,"img":false}]}
{"op":"mcm","clk":"11450385589","pt":1717321368878,"mc":[{"id":"1.229554915","rc":[{"atl":[[13,0]],"id":65293046}],"con":true,"img":false}]}
{"op":"mcm","clk":"11450385596","pt":1717321368991,"mc":[{"id":"1.229554915","rc":[{"atl":[[14,5.34]],"id":65293046}],"con":true,"img":false}]}
{"op":"mcm","clk":"11450385626","pt":1717321369377,"mc":[{"id":"1.229554915","rc":[{"atl":[[12.5,0]],"id":65293046}],"con":true,"img":false}]}
{"op":"mcm","clk":"11450385632","pt":1717321369482,"mc":[{"id":"1.229554915","rc":[{"atl":[[13.5,7.66]],"id":65293046}],"con":true,"img":false}]}
{"op":"mcm","clk":"11450385959","pt":1717321374913,"mc":[{"id":"1.229554915","rc":[{"atl":[[3,24.93]],"id":64927898}],"con":true,"img":false}]}
{"op":"mcm","clk":"11450385964","pt":1717321375012,"mc":[{"id":"1.229554915","rc":[{"atl":[[4.5,7.66]],"id":64927898}],"con":true,"img":false}]}
{"op":"mcm","clk":"11450385982","pt":1717321375423,"mc":[{"id":"1.229554915","rc":[{"atl":[[13.5,0]],"id":65293046}],"con":true,"img":false}]}
{"op":"mcm","clk":"11450385987","pt":1717321375476,"mc":[{"id":"1.229554915","rc":[{"atl":[[15.5,7.66]],"id":65293046}],"con":true,"img":false}]}
{"op":"mcm","clk":"11450386148","pt":1717321378891,"mc":[{"id":"1.229554915","rc":[{"atb":[[36,0],[46,2.61]],"id":51562794},{"atl":[[19.5,0],[15,8.03]],"id":65293046}],"con":true,"img":false}]}
{"op":"mcm","clk":"11450386157","pt":1717321379045,"mc":[{"id":"1.229554915","rc":[{"atb":[[9.8,0]],"id":65788088},{"atb":[[3.25,0]],"id":65293046}],"con":true,"img":false}]}
{"op":"mcm","clk":"11450386165","pt":1717321379215,"mc":[{"id":"1.229554915","rc":[{"atb":[[11.5,9.74]],"id":65788088},{"atb":[[3.7,45.91]],"id":65293046}],"con":true,"img":false}]}
{"op":"mcm","clk":"11450386538","pt":1717321384911,"mc":[{"id":"1.229554915","rc":[{"atl":[[80,4.61]],"id":65788088}],"con":true,"img":false}]}
{"op":"mcm","clk":"11450386545","pt":1717321385018,"mc":[{"id":"1.229554915","rc":[{"atl":[[80,2.61],[100,2]],"id":65788088}],"con":true,"img":false}]}
{"op":"mcm","clk":"11450386549","pt":1717321385120,"mc":[{"id":"1.229554915","rc":[{"atl":[[80,4.61],[100,0]],"id":65788088}],"con":true,"img":false}]}
{"op":"mcm","clk":"11450386556","pt":1717321385224,"mc":[{"id":"1.229554915","rc":[{"atl":[[80,2.61],[100,2]],"id":65788088}],"con":true,"img":false}]}
{"op":"mcm","clk":"11450386571","pt":1717321385384,"mc":[{"id":"1.229554915","rc":[{"atl":[[100,0]],"id":65788088}],"con":true,"img":false}]}
{"op":"mcm","clk":"11450386577","pt":1717321385487,"mc":[{"id":"1.229554915","rc":[{"atl":[[80,4.61]],"id":65788088}],"con":true,"img":false}]}
{"op":"mcm","clk":"11450386698","pt":1717321387203,"mc":[{"id":"1.229554915","rc":[{"atl":[[970,2]],"id":51562794},{"atl":[[23,3.57]],"id":46292327},{"atb":[[13,2]],"id":56606596},{"atl":[[65,4.61]],"id":56606596},{"atb":[[80,2]],"id":42099039},{"atl":[[970,2]],"id":42099039},{"atb":[[6.8,3.41]],"id":70003370},{"atl":[[30,4.61]],"id":70003370}],"con":true,"img":false}]}
{"op":"mcm","clk":"11450386704","pt":1717321387307,"mc":[{"id":"1.229554915","rc":[{"atl":[[65,2.61],[80,2]],"id":56606596},{"atl":[[34,2],[30,2.61]],"id":70003370}],"con":true,"img":false}]}
{"op":"mcm","clk":"11450386711","pt":1717321387435,"mc":[{"id":"1.229554915","rc":[{"atl":[[65,4.61]],"id":56606596},{"atl":[[34,0],[30,4.61]],"id":70003370}],"con":true,"img":false}]}
{"op":"mcm","clk":"11450386724","pt":1717321387543,"mc":[{"id":"1.229554915","rc":[{"atl":[[80,0]],"id":56606596},{"atl":[[34,2]],"id":70003370}],"con":true,"img":false}]}
{"op":"mcm","clk":"11450386726","pt":1717321387593,"mc":[{"id":"1.229554915","rc":[{"atl":[[30,2.61]],"id":70003370}],"con":true,"img":false}]}
{"op":"mcm","clk":"11450386733","pt":1717321387695,"mc":[{"id":"1.229554915","rc":[{"atl":[[34,0]],"id":70003370}],"con":true,"img":false}]}
{"op":"mcm","clk":"11450386740","pt":1717321387798,"mc":[{"id":"1.229554915","rc":[{"atl":[[30,4.61]],"id":70003370}],"con":true,"img":false}]}
{"op":"mcm","clk":"11450386753","pt":1717321388003,"mc":[{"id":"1.229554915","rc":[{"atb":[[13,0]],"id":56606596},{"trd":[[13,3.99]],"ltp":13.0,"tv":3.99,"id":56606596},{"atl":[[1000,3.35]],"id":65293046}],"con":true,"img":false}]}
{"op":"mcm","clk":"11450386764","pt":1717321388311,"mc":[{"id":"1.229554915","rc":[{"atl":[[1000,2.02]],"id":65293046}],"con":true,"img":false}]}
{"op":"mcm","clk":"11450386790","pt":1717321388621,"mc":[{"id":"1.229554915","rc":[{"atl":[[1000,1]],"id":65293046}],"con":true,"img":false}]}
{"op":"mcm","clk":"11450386799","pt":1717321388724,"mc":[{"id":"1.229554915","rc":[{"atl":[[13,1.02]],"id":65293046}],"con":true,"img":false}]}
{"op":"mcm","clk":"11450386805","pt":1717321388826,"mc":[{"id":"1.229554915","rc":[{"atb":[[1.39,372.42]],"id":64927898}],"con":true,"img":false}]}
{"op":"mcm","clk":"11450386812","pt":1717321388882,"mc":[{"id":"1.229554915","rc":[{"atb":[[42,1.21]],"id":51562794}],"con":true,"img":false}]}
{"op":"mcm","clk":"11450386821","pt":1717321388985,"mc":[{"id":"1.229554915","rc":[{"atb":[[12.5,4.06]],"id":65788088}],"con":true,"img":false}]}
{"op":"mcm","clk":"11450386832","pt":1717321389194,"mc":[{"id":"1.229554915","rc":[{"atb":[[5.6,9.07]],"id":46292327}],"con":true,"img":false}]}
{"op":"mcm","clk":"11450386843","pt":1717321389400,"mc":[{"id":"1.229554915","rc":[{"atb":[[11,4.62]],"id":56606596}],"con":true,"img":false}]}
{"op":"mcm","clk":"11450386856","pt":1717321389608,"mc":[{"id":"1.229554915","rc":[{"atb":[[6.2,39.36]],"id":70003370}],"con":true,"img":false}]}
{"op":"mcm","clk":"11450386862","pt":1717321389708,"mc":[{"id":"1.229554915","rc":[{"atb":[[75,0.68]],"id":42099039}],"con":true,"img":false}]}
{"op":"mcm","clk":"11450386868","pt":1717321389810,"mc":[{"id":"1.229554915","rc":[{"atb":[[3.45,14.73]],"id":65293046}],"con":true,"img":false}]}
{"op":"mcm","clk":"11450388687","pt":1717321418174,"mc":[{"id":"1.229554915","rc":[{"atb":[[13,2]],"id":56606596}],"con":true,"img":false}]}
{"op":"mcm","clk":"11450388745","pt":1717321419070,"mc":[{"id":"1.229554915","rc":[{"atb":[[60,1.77]],"id":42099039}],"con":true,"img":false}]}
{"op":"mcm","clk":"11450388750","pt":1717321419168,"mc":[{"id":"1.229554915","rc":[{"atb":[[85,2.61]],"id":42099039}],"con":true,"img":false}]}
{"op":"mcm","clk":"11450388787","pt":1717321419839,"mc":[{"id":"1.229554915","rc":[{"atb":[[13,0]],"id":56606596},{"trd":[[13,7.99]],"ltp":13.0,"tv":7.99,"id":56606596}],"con":true,"img":false}]}
{"op":"mcm","clk":"11450389497","pt":1717321432652,"mc":[{"id":"1.229554915","rc":[{"spn":263.0,"spf":"NaN","id":51562794},{"spn":14.6,"spf":"NaN","id":46292327},{"spn":317.5,"spf":"NaN","id":42099039},{"spn":8.4,"spf":"NaN","id":65293046},{"spn":17.9,"spf":"NaN","id":70003370},{"atb":[[1.53,98.27]],"id":64927898}],"con":true,"img":false}]}
{"op":"mcm","clk":"11450389566","pt":1717321433753,"mc":[{"id":"1.229554915","rc":[{"atl":[[36,0]],"id":46292327}],"con":true,"img":false}]}
{"op":"mcm","clk":"11450389589","pt":1717321434070,"mc":[{"id":"1.229554915","rc":[{"atl":[[38,6.46]],"id":70003370}],"con":true,"img":false}]}
{"op":"mcm","clk":"11450389603","pt":1717321434377,"mc":[{"id":"1.229554915","rc":[{"atl":[[140,0]],"id":65788088}],"con":true,"img":false}]}
{"op":"mcm","clk":"11450389621","pt":1717321434639,"mc":[{"id":"1.229554915","rc":[{"atb":[[6.2,28.29]],"id":70003370}],"con":true,"img":false}]}
{"op":"mcm","clk":"11450389639","pt":1717321434945,"mc":[{"id":"1.229554915","rc":[{"atb":[[13.5,8.36]],"id":65788088}],"con":true,"img":false}]}
{"op":"mcm","clk":"11450389654","pt":1717321435268,"mc":[{"id":"1.229554915","rc":[{"atb":[[6.2,11.45]],"id":46292327}],"con":true,"img":false}]}
{"op":"mcm","clk":"11450389678","pt":1717321435572,"mc":[{"id":"1.229554915","rc":[{"atl":[[110,0]],"id":56606596}],"con":true,"img":false}]}
{"op":"mcm","clk":"11450389702","pt":1717321435838,"mc":[{"id":"1.229554915","rc":[{"atb":[[1.27,0]],"id":64927898}],"con":true,"img":false}]}
{"op":"mcm","clk":"11450389726","pt":1717321436147,"mc":[{"id":"1.229554915","rc":[{"atb":[[3.35,0]],"id":65293046}],"con":true,"img":false}]}
{"op":"mcm","clk":"11450389751","pt":1717321436460,"mc":[{"id":"1.229554915","rc":[{"atb":[[11.5,0]],"id":56606596}],"con":true,"img":false}]}
{"op":"mcm","clk":"11450389771","pt":1717321436775,"mc":[{"id":"1.229554915","rc":[{"atl":[[4.5,0]],"id":64927898}],"con":true,"img":false}]}
{"op":"mcm","clk":"11450389784","pt":1717321436979,"mc":[{"id":"1.229554915","rc":[{"atl":[[15.5,0]],"id":65293046}],"con":true,"img":false}]}
{"op":"mcm","clk":"11450389892","pt":1717321438956,"mc":[{"id":"1.229554915","rc":[{"atl":[[34,0]],"id":46292327},{"atb":[[12,0]],"id":56606596},{"atl":[[15,0]],"id":65293046}],"con":true,"img":false}]}
{"op":"mcm","clk":"11450389899","pt":1717321439060,"mc":[{"id":"1.229554915","rc":[{"atl":[[36,3.13]],"id":46292327},{"atb":[[11,9.72]],"id":56606596},{"atl":[[16,8.03]],"id":65293046}],"con":true,"img":false}]}
{"op":"mcm","clk":"11450390557","pt":1717321449982,"mc":[{"id":"1.229554915","rc":[{"atb":[[13,2]],"id":56606596}],"con":true,"img":false}]}
{"op":"mcm","clk":"11450390574","pt":1717321450184,"mc":[{"id":"1.229554915","rc":[{"atb":[[3.65,43.34]],"id":65293046},{"atb":[[1.45,22.88]],"id":64927898},{"atl":[[3.4,4.48]],"id":64927898}],"con":true,"img":false}]}
{"op":"mcm","clk":"11450390651","pt":1717321451490,"mc":[{"id":"1.229554915","rc":[{"atb":[[13,0]],"id":56606596},{"trd":[[13,11.99]],"ltp":13.0,"tv":11.99,"id":56606596}],"con":true,"img":false}]}
{"op":"mcm","clk":"11450390657","pt":1717321451592,"mc":[{"id":"1.229554915","rc":[{"atl":[[60,1.44]],"id":56606596}],"con":true,"img":false}]}
{"op":"mcm","clk":"11450392548","pt":1717321481637,"mc":[{"id":"1.229554915","rc":[{"atb":[[13,2]],"id":56606596}],"con":true,"img":false}]}
{"op":"mcm","clk":"11450392628","pt":1717321482708,"mc":[{"id":"1.229554915","rc":[{"atb":[[1.45,0]],"id":64927898}],"con":true,"img":false}]}
{"op":"mcm","clk":"11450392747","pt":1717321484024,"mc":[{"id":"1.229554915","rc":[{"atb":[[13,0]],"id":56606596},{"trd":[[13,15.99]],"ltp":13.0,"tv":15.99,"id":56606596}],"con":true,"img":false}]}
{"op":"mcm","clk":"11450392796","pt":1717321484538,"mc":[{"id":"1.229554915","rc":[{"atl":[[55,1.56]],"id":56606596}],"con":true,"img":false}]}
{"op":"mcm","clk":"11450392809","pt":1717321484745,"mc":[{"id":"1.229554915","rc":[{"atl":[[65,2.61],[55,3.56]],"id":56606596}],"con":true,"img":false}]}
{"op":"mcm","clk":"11450392819","pt":1717321484847,"mc":[{"id":"1.229554915","rc":[{"atl":[[65,4.61],[55,1.56]],"id":56606596}],"con":true,"img":false}]}
{"op":"mcm","clk":"11450393175","pt":1717321489939,"mc":[{"id":"1.229554915","rc":[{"atl":[[50,2.08],[55,3.56],[60,0.14]],"id":56606596}],"con":true,"img":false}]}
{"op":"mcm","clk":"11450393181","pt":1717321490037,"mc":[{"id":"1.229554915","rc":[{"atl":[[65,2.61]],"id":56606596}],"con":true,"img":false}]}
{"op":"mcm","clk":"11450393186","pt":1717321490146,"mc":[{"id":"1.229554915","rc":[{"atl":[[50,0]],"id":56606596}],"con":true,"img":false}]}
{"op":"mcm","clk":"11450393763","pt":1717321499822,"mc":[{"id":"1.229554915","rc":[{"spn":33.0,"spf":"NaN","id":56606596},{"atl":[[2.78,3]],"id":64927898},{"spn":2.15,"spf":"NaN","id":64927898}],"con":true,"img":false}]}
{"op":"mcm","clk":"11450393783","pt":1717321500134,"mc":[{"id":"1.229554915","rc":[{"atl":[[55,2]],"id":56606596}],"con":true,"img":false}]}
{"op":"mcm","clk":"11450393791","pt":1717321500241,"mc":[{"id":"1.229554915","rc":[{"atl":[[65,4.61]],"id":56606596}],"con":true,"img":false}]}
{"op":"mcm","clk":"11450393802","pt":1717321500345,"mc":[{"id":"1.229554915","rc":[{"atl":[[65,2.61],[80,2],[55,0]],"id":56606596}],"con":true,"img":false}]}
{"op":"mcm","clk":"11450393820","pt":1717321500552,"mc":[{"id":"1.229554915","rc":[{"atl":[[80,0]],"id":56606596}],"con":true,"img":false}]}
{"op":"mcm","clk":"11450393837","pt":1717321500762,"mc":[{"id":"1.229554915","rc":[{"atl":[[65,4.61]],"id":56606596},{"atl":[[2.8,0]],"id":64927898}],"con":true,"img":false}]}
{"op":"mcm","clk":"11450393868","pt":1717321501233,"mc":[{"id":"1.229554915","rc":[{"atb":[[4.1,16.13]],"id":65788088}],"con":true,"img":false}]}
{"op":"mcm","clk":"11450394265","pt":1717321506633,"mc":[{"id":"1.229554915","rc":[{"atb":[[1.45,22.88]],"id":64927898}],"con":true,"img":false}]}
