{"op":"mcm","clk":"11449075384","pt":1717303241522,"mc":[{"id":"1.229554908","marketDefinition":{"bspMarket":false,"turnInPlayEnabled":false,"persistenceEnabled":false,"marketBaseRate":7.0,"eventId":"33318908","eventTypeId":"4339","numberOfWinners":1,"bettingType":"ODDS","marketType":"QUINELLA","marketTime":"2024-06-02T09:20:00.000Z","suspendTime":"2024-06-02T09:20:00.000Z","bspReconciled":false,"complete":true,"inPlay":false,"crossMatching":false,"runnersVoidable":false,"numberOfActiveRunners":10,"betDelay":0,"status":"OPEN","runners":[{"status":"ACTIVE","sortPriority":1,"id":52671542,"name":"1 - 2 / 2 - 1"},{"status":"ACTIVE","sortPriority":2,"id":52671544,"name":"1 - 4 / 4 - 1"},{"status":"ACTIVE","sortPriority":3,"id":52671545,"name":"1 - 6 / 6 - 1"},{"status":"ACTIVE","sortPriority":4,"id":52671546,"name":"1 - 8 / 8 - 1"},{"status":"ACTIVE","sortPriority":5,"id":52671548,"name":"2 - 4 / 4 - 2"},{"status":"ACTIVE","sortPriority":6,"id":52671549,"name":"2 - 6 / 6 - 2"},{"status":"ACTIVE","sortPriority":7,"id":52671550,"name":"2 - 8 / 8 - 2"},{"status":"ACTIVE","sortPriority":8,"id":52671554,"name":"4 - 6 / 6 - 4"},{"status":"ACTIVE","sortPriority":9,"id":52671555,"name":"4 - 8 / 8 - 4"},{"status":"ACTIVE","sortPriority":10,"id":52671556,"name":"6 - 8 / 8 - 6"}],"regulators":["MR_INT"],"venue":"Murray Bridge","countryCode":"AU","discountAllowed":true,"timezone":"Australia/Adelaide","openDate":"2024-06-02T08:21:00.000Z","version":5962801918,"name":"Quinella","eventName":"Murray Bridge (AUS) 2nd Jun"},"rc":[],"con":true,"img":false}]}
{"op":"mcm","clk":"11449095056","pt":1717303714149,"mc":[{"id":"1.229554908","rc":[{"atb":[[4.9,20.12],[4.4,30.77],[5.9,5.34],[5.4,11.89]],"id":52671550},{"atb":[[2.38,37.91],[2.28,61.31],[2.18,88.67],[2.48,17.67]],"id":52671546},{"atb":[[300,0.35],[350,0.23],[400,0.13],[450,0.06]],"id":52671549},{"atb":[[17,4.9],[19.5,2.83],[24,1.14],[14.5,7.75]],"id":52671548},{"atb":[[17.5,6.34],[20,4.13],[25,2.18],[30,0.9]],"id":52671542},{"atb":[[130,0.41],[65,1.64],[180,0.15],[90,0.88]],"id":52671545},{"atb":[[9.6,3.04],[8.6,6.89],[7.6,11.89],[6.6,18.68]],"id":52671544},{"atb":[[2,26.16],[1.85,123.1],[1.9,87.2],[1.95,55.07]],"id":52671555},{"atb":[[140,0.19],[70,1.14],[95,0.55],[48,2.23]],"id":52671554},{"atb":[[32,0.84],[18,6.15],[21,3.92],[26,2.09]],"id":52671556}],"con":true,"img":false}]}
{"op":"mcm","clk":"11449099382","pt":1717303849562,"mc":[{"id":"1.229554908","rc":[{"atb":[[3.4,101.62],[3.9,36.04]],"id":52671550},{"atb":[[2.32,79.18],[2.12,217.77]],"id":52671546},{"atb":[[290,0.84],[390,0.26]],"id":52671549},{"atb":[[9.8,11.87],[7.8,35.86]],"id":52671548},{"atb":[[11,10.45],[8.4,32.96]],"id":52671542},{"atb":[[34,3.16],[22,11.61]],"id":52671545},{"atb":[[5.1,25.49],[4.1,78.68]],"id":52671544},{"atb":[[1.82,297.44],[1.92,113.61]],"id":52671555},{"atb":[[18.5,13.93],[27,4.01]],"id":52671554},{"atb":[[9,30.48],[12.5,9.08]],"id":52671556}],"con":true,"img":false}]}
{"op":"mcm","clk":"11449112530","pt":1717304231714,"mc":[{"id":"1.229554908","rc":[{"atb":[[4.9,0],[4.4,0],[5.9,0],[5.4,0]],"id":52671550},{"atb":[[300,0],[350,0],[400,0],[450,0]],"id":52671549},{"atb":[[130,0],[65,0],[180,0],[90,0]],"id":52671545},{"atb":[[9.6,0],[8.6,0],[7.6,0],[6.6,0]],"id":52671544}],"con":true,"img":false}]}
{"op":"mcm","clk":"11449112536","pt":1717304231820,"mc":[{"id":"1.229554908","rc":[{"atb":[[2,0],[1.85,0],[1.9,0],[1.95,0]],"id":52671555}],"con":true,"img":false}]}
{"op":"mcm","clk":"11449112584","pt":1717304232739,"mc":[{"id":"1.229554908","rc":[{"atb":[[3.95,35.47],[4.9,13.41],[4.4,23.08],[5.4,5.94]],"id":52671550},{"atb":[[260,0.4],[310,0.26],[360,0.15],[410,0.06]],"id":52671549},{"atb":[[170,0.16],[85,0.94],[120,0.44],[60,1.77]],"id":52671545},{"atb":[[8,11.21],[9,6.54],[10,2.91],[7,17.44]],"id":52671544}],"con":true,"img":false}]}
{"op":"mcm","clk":"11449112590","pt":1717304232794,"mc":[{"id":"1.229554908","rc":[{"atb":[[2,52.32],[1.9,116.26],[1.95,82.6],[2.1,23.78]],"id":52671555}],"con":true,"img":false}]}
{"op":"mcm","clk":"11449127679","pt":1717304401620,"mc":[{"id":"1.229554908","rc":[{"atb":[[3.95,0],[4.9,0],[4.4,0],[5.4,0]],"id":52671550},{"atb":[[2.38,0],[2.28,0],[2.18,0],[2.48,0]],"id":52671546},{"atb":[[260,0],[310,0],[360,0],[410,0]],"id":52671549},{"atb":[[2,0],[1.9,0],[1.95,0],[2.1,0]],"id":52671555},{"atb":[[140,0],[70,0],[95,0],[48,0]],"id":52671554}],"con":true,"img":false}]}
{"op":"mcm","clk":"11449127734","pt":1717304402320,"mc":[{"id":"1.229554908","rc":[{"atb":[[4.5,29.89],[5,19.62],[5.5,11.63],[6,5.23]],"id":52671550},{"atb":[[2.24,84.38],[2.54,16.99],[2.44,36.33],[2.34,58.56]],"id":52671546},{"atb":[[280,0.38],[330,0.24],[380,0.14],[430,0.06]],"id":52671549},{"atb":[[2.06,24.68],[1.98,53.39],[1.88,118.9],[1.93,84.38]],"id":52671555},{"atb":[[130,0.2],[65,1.22],[90,0.59],[46,2.32]],"id":52671554}],"con":true,"img":false}]}
{"op":"mcm","clk":"11449154965","pt":1717304856222,"mc":[{"id":"1.229554908","rc":[{"atb":[[4.5,0],[5,0],[5.5,0],[6,0]],"id":52671550}],"con":true,"img":false}]}
{"op":"mcm","clk":"11449154973","pt":1717304856327,"mc":[{"id":"1.229554908","rc":[{"atb":[[280,0],[330,0],[380,0],[430,0]],"id":52671549}],"con":true,"img":false}]}
{"op":"mcm","clk":"11449155025","pt":1717304857103,"mc":[{"id":"1.229554908","rc":[{"atb":[[5.6,5.69],[5.1,12.76],[4.6,21.8],[4.1,33.76]],"id":52671550},{"atb":[[260,0.4],[310,0.26],[360,0.15],[410,0.06]],"id":52671549}],"con":true,"img":false}]}
{"op":"mcm","clk":"11449158952","pt":1717304911270,"mc":[{"id":"1.229554908","rc":[{"atb":[[170,0],[85,0],[120,0],[60,0]],"id":52671545}],"con":true,"img":false}]}
{"op":"mcm","clk":"11449158959","pt":1717304911371,"mc":[{"id":"1.229554908","rc":[{"atb":[[2.06,0],[1.98,0],[1.88,0],[1.93,0]],"id":52671555}],"con":true,"img":false}]}
{"op":"mcm","clk":"11449158999","pt":1717304911986,"mc":[{"id":"1.229554908","rc":[{"atb":[[130,0.41],[65,1.64],[180,0.15],[90,0.88]],"id":52671545}],"con":true,"img":false}]}
{"op":"mcm","clk":"11449159008","pt":1717304912093,"mc":[{"id":"1.229554908","rc":[{"atb":[[2,26.16],[1.85,123.1],[1.9,87.2],[1.95,55.07]],"id":52671555}],"con":true,"img":false}]}
{"op":"mcm","clk":"11449159921","pt":1717304924475,"mc":[{"id":"1.229554908","rc":[{"atb":[[130,0],[65,0],[180,0],[90,0]],"id":52671545}],"con":true,"img":false}]}
{"op":"mcm","clk":"11449159979","pt":1717304925196,"mc":[{"id":"1.229554908","rc":[{"atb":[[170,0.16],[85,0.94],[120,0.44],[60,1.77]],"id":52671545}],"con":true,"img":false}]}
{"op":"mcm","clk":"11449162736","pt":1717304962318,"mc":[{"id":"1.229554908","rc":[{"atb":[[17,0],[19.5,0],[24,0],[14.5,0]],"id":52671548}],"con":true,"img":false}]}
{"op":"mcm","clk":"11449162805","pt":1717304963139,"mc":[{"id":"1.229554908","rc":[{"atb":[[17.5,4.76],[20,2.75],[25,1.09],[15,7.48]],"id":52671548}],"con":true,"img":false}]}
{"op":"mcm","clk":"11449181039","pt":1717305226653,"mc":[{"id":"1.229554908","rc":[{"atb":[[17.5,0],[20,0],[25,0],[15,0]],"id":52671548}],"con":true,"img":false}]}
{"op":"mcm","clk":"11449181092","pt":1717305227323,"mc":[{"id":"1.229554908","rc":[{"atb":[[16.5,5.06],[19,2.91],[23,1.19],[14,8.05]],"id":52671548}],"con":true,"img":false}]}
{"op":"mcm","clk":"11449222776","pt":1717305798839,"mc":[{"id":"1.229554908","rc":[{"atb":[[260,0],[310,0],[360,0],[410,0]],"id":52671549}],"con":true,"img":false}]}
{"op":"mcm","clk":"11449222828","pt":1717305799510,"mc":[{"id":"1.229554908","rc":[{"atb":[[290,1.11],[340,0.15],[390,0.34],[240,0.44]],"id":52671549}],"con":true,"img":false}]}
{"op":"mcm","clk":"11449234427","pt":1717305967768,"mc":[{"id":"1.229554908","rc":[{"atb":[[130,0]],"id":52671554}],"con":true,"img":false}]}
{"op":"mcm","clk":"11449234433","pt":1717305967866,"mc":[{"id":"1.229554908","rc":[{"atb":[[65,0],[90,0],[46,0]],"id":52671554}],"con":true,"img":false}]}
{"op":"mcm","clk":"11449234485","pt":1717305968489,"mc":[{"id":"1.229554908","rc":[{"atb":[[140,0.19]],"id":52671554}],"con":true,"img":false}]}
{"op":"mcm","clk":"11449234493","pt":1717305968546,"mc":[{"id":"1.229554908","rc":[{"atb":[[70,1.14],[95,0.55],[48,2.23]],"id":52671554}],"con":true,"img":false}]}
{"op":"mcm","clk":"11449268421","pt":1717306426608,"mc":[{"id":"1.229554908","rc":[{"atb":[[2,0],[1.85,0],[1.9,0],[1.95,0]],"id":52671555}],"con":true,"img":false}]}
{"op":"mcm","clk":"11449268467","pt":1717306427330,"mc":[{"id":"1.229554908","rc":[{"atb":[[2,52.32],[1.9,116.26],[1.95,82.6],[2.1,23.78]],"id":52671555}],"con":true,"img":false}]}
{"op":"mcm","clk":"11449327105","pt":1717307225296,"mc":[{"id":"1.229554908","rc":[{"atb":[[290,0.84],[340,0],[390,0.26],[240,0]],"id":52671549}],"con":true,"img":false}]}
{"op":"mcm","clk":"11449327151","pt":1717307226014,"mc":[{"id":"1.229554908","rc":[{"atb":[[260,0.4],[310,0.26],[360,0.15],[410,0.06]],"id":52671549}],"con":true,"img":false}]}
{"op":"mcm","clk":"11449339116","pt":1717307401514,"mc":[{"id":"1.229554908","rc":[{"atb":[[2.24,0],[2.54,0],[2.44,0],[2.34,0]],"id":52671546},{"atb":[[2,0],[1.9,0],[1.95,0],[2.1,0]],"id":52671555}],"con":true,"img":false}]}
{"op":"mcm","clk":"11449339163","pt":1717307402236,"mc":[{"id":"1.229554908","rc":[{"atb":[[2.56,16.77],[2.36,57.7],[2.46,35.83],[2.26,83.04]],"id":52671546},{"atb":[[1.99,52.85],[1.89,117.57],[1.94,83.48],[2.08,24.22]],"id":52671555}],"con":true,"img":false}]}
{"op":"mcm","clk":"11449342311","pt":1717307456955,"mc":[{"id":"1.229554908","rc":[{"atb":[[1.99,0],[1.89,0],[1.94,0],[2.08,0]],"id":52671555}],"con":true,"img":false}]}
{"op":"mcm","clk":"11449342320","pt":1717307457060,"mc":[{"id":"1.229554908","rc":[{"atb":[[16.5,0],[19,0],[23,0],[14,0]],"id":52671548},{"atb":[[8,0],[9,0],[10,0],[7,0]],"id":52671544}],"con":true,"img":false}]}
{"op":"mcm","clk":"11449342364","pt":1717307457726,"mc":[{"id":"1.229554908","rc":[{"atb":[[6.4,19.38],[7.4,12.26],[8.4,7.07],[9.4,3.11]],"id":52671544},{"atb":[[1.92,198.92],[1.97,53.93],[2.04,25.15],[1.87,120.27]],"id":52671555}],"con":true,"img":false}]}
{"op":"mcm","clk":"11449342370","pt":1717307457827,"mc":[{"id":"1.229554908","rc":[{"atb":[[4.8,6.89],[4.3,15.85],[3.9,27.06],[3.65,39.48]],"id":52671548}],"con":true,"img":false}]}
{"op":"mcm","clk":"11449365489","pt":1717308004047,"mc":[{"id":"1.229554908","rc":[{"atb":[[260,0],[310,0],[360,0],[410,0]],"id":52671549},{"atb":[[170,0],[85,0],[120,0],[60,0]],"id":52671545},{"atb":[[1.92,113.61],[1.97,0],[2.04,0],[1.87,0]],"id":52671555}],"con":true,"img":false}]}
{"op":"mcm","clk":"11449365501","pt":1717308004157,"mc":[{"id":"1.229554908","rc":[{"atb":[[5.6,0],[5.1,0],[4.6,0],[4.1,0]],"id":52671550}],"con":true,"img":false}]}
{"op":"mcm","clk":"11449365546","pt":1717308004728,"mc":[{"id":"1.229554908","rc":[{"atb":[[300,0.35],[350,0.23],[400,0.13],[450,0.06]],"id":52671549},{"atb":[[130,0.41],[65,1.64],[180,0.15],[90,0.88]],"id":52671545},{"atb":[[2,26.16],[1.85,123.1],[1.9,87.2],[1.95,55.07]],"id":52671555}],"con":true,"img":false}]}
{"op":"mcm","clk":"11449365556","pt":1717308004832,"mc":[{"id":"1.229554908","rc":[{"atb":[[4.9,20.12],[4.4,30.77],[5.9,5.34],[5.4,11.89]],"id":52671550}],"con":true,"img":false}]}
{"op":"mcm","clk":"11449378865","pt":1717308286273,"mc":[{"id":"1.229554908","rc":[{"atb":[[130,0],[65,0],[180,0],[90,0]],"id":52671545}],"con":true,"img":false}]}
{"op":"mcm","clk":"11449378876","pt":1717308286482,"mc":[{"id":"1.229554908","rc":[{"atb":[[300,0],[350,0],[400,0],[450,0]],"id":52671549}],"con":true,"img":false}]}
{"op":"mcm","clk":"11449378913","pt":1717308286999,"mc":[{"id":"1.229554908","rc":[{"atb":[[170,0.16],[85,0.94],[120,0.44],[60,1.77]],"id":52671545}],"con":true,"img":false}]}
{"op":"mcm","clk":"11449378921","pt":1717308287200,"mc":[{"id":"1.229554908","rc":[{"atb":[[260,0.4],[310,0.26],[360,0.15],[410,0.06]],"id":52671549}],"con":true,"img":false}]}
{"op":"mcm","clk":"11449391980","pt":1717308486704,"mc":[{"id":"1.229554908","rc":[{"atb":[[260,0],[310,0],[360,0],[410,0]],"id":52671549}],"con":true,"img":false}]}
{"op":"mcm","clk":"11449392030","pt":1717308487383,"mc":[{"id":"1.229554908","rc":[{"atb":[[290,1.11],[340,0.15],[390,0.34],[240,0.44]],"id":52671549}],"con":true,"img":false}]}
{"op":"mcm","clk":"11449429489","pt":1717309009899,"mc":[{"id":"1.229554908","rc":[{"atb":[[6.4,0],[7.4,0],[8.4,0],[9.4,0]],"id":52671544}],"con":true,"img":false}]}
{"op":"mcm","clk":"11449429539","pt":1717309010575,"mc":[{"id":"1.229554908","rc":[{"atb":[[9.6,3.04],[8.6,6.89],[7.6,11.89],[6.6,18.68]],"id":52671544}],"con":true,"img":false}]}
{"op":"mcm","clk":"11449437678","pt":1717309131933,"mc":[{"id":"1.229554908","rc":[{"atb":[[9.6,0],[8.6,0],[7.6,0],[6.6,0]],"id":52671544},{"atb":[[140,0],[70,0],[95,0],[48,0]],"id":52671554}],"con":true,"img":false}]}
{"op":"mcm","clk":"11449437717","pt":1717309132604,"mc":[{"id":"1.229554908","rc":[{"atb":[[130,0.2],[65,1.22],[90,0.59],[46,2.32]],"id":52671554}],"con":true,"img":false}]}
{"op":"mcm","clk":"11449437726","pt":1717309132708,"mc":[{"id":"1.229554908","rc":[{"atb":[[6.4,19.38],[7.4,12.26],[8.4,7.07],[9.4,3.11]],"id":52671544}],"con":true,"img":false}]}
{"op":"mcm","clk":"11449438626","pt":1717309147323,"mc":[{"id":"1.229554908","rc":[{"atb":[[130,0],[65,0],[90,0],[46,0]],"id":52671554}],"con":true,"img":false}]}
{"op":"mcm","clk":"11449438668","pt":1717309148057,"mc":[{"id":"1.229554908","rc":[{"atb":[[140,0.19],[70,1.14],[95,0.55],[48,2.23]],"id":52671554}],"con":true,"img":false}]}
{"op":"mcm","clk":"11449442619","pt":1717309210109,"mc":[{"id":"1.229554908","rc":[{"atb":[[2,0],[1.85,0],[1.9,0],[1.95,0]],"id":52671555}],"con":true,"img":false}]}
{"op":"mcm","clk":"11449442667","pt":1717309210797,"mc":[{"id":"1.229554908","rc":[{"atb":[[1.92,198.92],[1.97,53.93],[2.04,25.15],[1.87,120.27]],"id":52671555}],"con":true,"img":false}]}
{"op":"mcm","clk":"11449447774","pt":1717309289068,"mc":[{"id":"1.229554908","rc":[{"atb":[[32,0],[18,0],[21,0],[26,0]],"id":52671556}],"con":true,"img":false}]}
{"op":"mcm","clk":"11449447818","pt":1717309289783,"mc":[{"id":"1.229554908","rc":[{"atb":[[36,0.75],[19,5.81],[23,3.57],[28,1.94]],"id":52671556}],"con":true,"img":false}]}
{"op":"mcm","clk":"11449448635","pt":1717309303200,"mc":[{"id":"1.229554908","rc":[{"atb":[[3.4,0],[3.9,0]],"id":52671550},{"atb":[[2.32,0],[2.12,0]],"id":52671546},{"atb":[[290,0.27],[390,0.07]],"id":52671549},{"atb":[[9.8,0],[7.8,0]],"id":52671548},{"atb":[[11,0],[8.4,0]],"id":52671542},{"atb":[[34,0],[22,0]],"id":52671545},{"atb":[[5.1,0],[4.1,0]],"id":52671544},{"atb":[[1.82,0],[1.92,85.3]],"id":52671555},{"atb":[[18.5,0],[27,0]],"id":52671554},{"atb":[[9,0],[12.5,0]],"id":52671556}],"con":true,"img":false}]}
{"op":"mcm","clk":"11449450083","pt":1717309323534,"mc":[{"id":"1.229554908","rc":[{"atb":[[1.92,0],[1.97,0],[2.04,0],[1.87,0]],"id":52671555}],"con":true,"img":false}]}
{"op":"mcm","clk":"11449450136","pt":1717309324206,"mc":[{"id":"1.229554908","rc":[{"atb":[[2.02,25.65],[1.91,86.24],[1.96,54.5],[1.86,121.67]],"id":52671555}],"con":true,"img":false}]}
{"op":"mcm","clk":"11449450408","pt":1717309328037,"mc":[{"id":"1.229554908","rc":[{"atb":[[1.99,246.36],[2.18,88.58]],"id":52671546},{"atb":[[8,34.84],[10,11.61]],"id":52671548},{"atb":[[10.5,11],[8.2,33.87]],"id":52671542},{"atb":[[32,3.37],[21,12.19]],"id":52671545},{"atb":[[4.3,73.9],[5.3,24.31]],"id":52671544}],"con":true,"img":false}]}
{"op":"mcm","clk":"11449450415","pt":1717309328143,"mc":[{"id":"1.229554908","rc":[{"atb":[[3.25,108.4],[3.75,38]],"id":52671550},{"atb":[[270,0.9],[370,0.28]],"id":52671549},{"atb":[[1.99,105.58],[1.89,274.05]],"id":52671555},{"atb":[[19.5,13.18],[29,3.73]],"id":52671554},{"atb":[[12,9.5],[8.8,31.27]],"id":52671556}],"con":true,"img":false}]}
{"op":"mcm","clk":"11449450876","pt":1717309334347,"mc":[{"id":"1.229554908","rc":[{"atb":[[2.02,0],[1.91,0],[1.96,0],[1.86,0]],"id":52671555}],"con":true,"img":false}]}
{"op":"mcm","clk":"11449450937","pt":1717309335124,"mc":[{"id":"1.229554908","rc":[{"atb":[[2,26.16],[1.85,123.1],[1.9,87.2],[1.95,55.07]],"id":52671555}],"con":true,"img":false}]}
{"op":"mcm","clk":"11449451530","pt":1717309344563,"mc":[{"id":"1.229554908","rc":[{"atb":[[3.25,0],[3.75,0]],"id":52671550},{"atb":[[1.99,0],[2.18,0]],"id":52671546},{"atb":[[270,0],[370,0]],"id":52671549},{"atb":[[8,0],[10,0]],"id":52671548},{"atb":[[10.5,0],[8.2,0]],"id":52671542},{"atb":[[32,0],[21,0]],"id":52671545},{"atb":[[4.3,0],[5.3,0]],"id":52671544},{"atb":[[1.99,0],[1.89,0]],"id":52671555},{"atb":[[19.5,0],[29,0]],"id":52671554},{"atb":[[12,0],[8.8,0]],"id":52671556}],"con":true,"img":false}]}
{"op":"mcm","clk":"11449453334","pt":1717309368988,"mc":[{"id":"1.229554908","rc":[{"atb":[[3.2,110.86],[3.7,38.71]],"id":52671550},{"atb":[[550,0.44],[650,0.16]],"id":52671549},{"atb":[[1.96,108.88],[1.86,283.6]],"id":52671555},{"atb":[[70,2.65],[38,6.59]],"id":52671554},{"atb":[[10,27.1],[15,7.46]],"id":52671556}],"con":true,"img":false}]}
{"op":"mcm","clk":"11449453343","pt":1717309369096,"mc":[{"id":"1.229554908","rc":[{"atb":[[2.12,93.32],[1.96,254.06]],"id":52671546},{"atb":[[10.5,11],[8.2,33.87]],"id":52671548},{"atb":[[8.6,32.09],[11.5,9.95]],"id":52671542},{"atb":[[85,2.18],[44,5.67]],"id":52671545},{"atb":[[4.5,69.68],[5.5,23.22]],"id":52671544}],"con":true,"img":false}]}
{"op":"mcm","clk":"11449454187","pt":1717309383479,"mc":[{"id":"1.229554908","rc":[{"atb":[[36,0],[19,0],[23,0],[28,0]],"id":52671556}],"con":true,"img":false}]}
{"op":"mcm","clk":"11449454225","pt":1717309384110,"mc":[{"id":"1.229554908","rc":[{"atb":[[3.2,0],[3.7,0]],"id":52671550},{"atb":[[2.12,0],[1.96,0]],"id":52671546},{"atb":[[550,0],[650,0]],"id":52671549},{"atb":[[10.5,0],[8.2,0]],"id":52671548},{"atb":[[8.6,0],[11.5,0]],"id":52671542},{"atb":[[85,0.94],[44,0]],"id":52671545},{"atb":[[4.5,0],[5.5,0]],"id":52671544},{"atb":[[1.96,0],[1.86,0]],"id":52671555},{"atb":[[70,1.14],[38,0]],"id":52671554},{"atb":[[10,0],[15,0]],"id":52671556}],"con":true,"img":false}]}
{"op":"mcm","clk":"11449454230","pt":1717309384200,"mc":[{"id":"1.229554908","rc":[{"atb":[[32,0.84],[18,6.15],[21,3.92],[26,2.09]],"id":52671556}],"con":true,"img":false}]}
{"op":"mcm","clk":"11449455409","pt":1717309403522,"mc":[{"id":"1.229554908","rc":[{"atb":[[3.85,36.67],[3.35,103.78]],"id":52671550},{"atb":[[1.95,256.74],[2.1,95.02]],"id":52671546},{"atb":[[550,0.44],[650,0.16]],"id":52671549},{"atb":[[8.6,32.09],[11.5,9.95]],"id":52671548},{"atb":[[9,30.48],[12.5,9.08]],"id":52671542},{"atb":[[46,2.32],[28,9.03]],"id":52671545},{"atb":[[4.5,69.68],[5.5,23.22]],"id":52671544},{"atb":[[1.85,410.05],[1.95,165.1]],"id":52671555},{"atb":[[40,2.67],[25,10.16]],"id":52671554},{"atb":[[13.5,8.36],[9.4,29.03]],"id":52671556}],"con":true,"img":false}]}
{"op":"mcm","clk":"11449456328","pt":1717309418833,"mc":[{"id":"1.229554908","rc":[{"atb":[[3.85,0],[3.35,0]],"id":52671550},{"atb":[[1.95,0],[2.1,0]],"id":52671546},{"atb":[[550,0],[650,0]],"id":52671549},{"atb":[[8.6,0],[11.5,0]],"id":52671548},{"atb":[[9,0],[12.5,0]],"id":52671542},{"atb":[[46,0],[28,0]],"id":52671545},{"atb":[[4.5,0],[5.5,0]],"id":52671544},{"atb":[[1.85,123.1],[1.95,55.07]],"id":52671555},{"atb":[[40,0],[25,0]],"id":52671554},{"atb":[[13.5,0],[9.4,0]],"id":52671556}],"con":true,"img":false}]}
{"op":"mcm","clk":"11449456555","pt":1717309422252,"mc":[{"id":"1.229554908","rc":[{"atb":[[4.8,0],[4.3,0],[3.9,0],[3.65,0]],"id":52671548}],"con":true,"img":false}]}
{"op":"mcm","clk":"11449456561","pt":1717309422353,"mc":[{"id":"1.229554908","rc":[{"atb":[[2,0],[1.85,0],[1.9,0],[1.95,0]],"id":52671555}],"con":true,"img":false}]}
{"op":"mcm","clk":"11449456597","pt":1717309422922,"mc":[{"id":"1.229554908","rc":[{"atb":[[5.1,6.38],[4.6,14.53],[4.1,25.32],[3.8,37.37]],"id":52671548}],"con":true,"img":false}]}
{"op":"mcm","clk":"11449456608","pt":1717309423073,"mc":[{"id":"1.229554908","rc":[{"atb":[[1.82,127.6],[1.92,56.87],[1.97,26.97],[1.87,90.2]],"id":52671555}],"con":true,"img":false}]}
{"op":"mcm","clk":"11449457812","pt":1717309441687,"mc":[{"id":"1.229554908","rc":[{"atb":[[3.45,99.55],[3.95,35.43]],"id":52671550},{"atb":[[570,0.18],[470,0.51]],"id":52671549},{"atb":[[1.99,105.58],[1.89,274.05]],"id":52671555},{"atb":[[36,2.98],[23,11.08]],"id":52671554},{"atb":[[12,9.5],[8.8,31.27]],"id":52671556}],"con":true,"img":false}]}
{"op":"mcm","clk":"11449457820","pt":1717309441782,"mc":[{"id":"1.229554908","rc":[{"atb":[[1.99,105.58],[1.89,274.05]],"id":52671546},{"atb":[[9.2,29.74],[13,8.71]],"id":52671548},{"atb":[[9.2,29.74],[13,8.71]],"id":52671542},{"atb":[[36,2.98],[23,11.08]],"id":52671545},{"atb":[[5.6,22.72],[4.6,67.75]],"id":52671544}],"con":true,"img":false}]}
{"op":"mcm","clk":"11449457928","pt":1717309443381,"mc":[{"id":"1.229554908","rc":[{"atb":[[32,0],[18,0],[21,0],[26,0]],"id":52671556}],"con":true,"img":false}]}
{"op":"mcm","clk":"11449457981","pt":1717309444055,"mc":[{"id":"1.229554908","rc":[{"atb":[[36,0.75],[19,5.81],[23,3.57],[28,1.94]],"id":52671556}],"con":true,"img":false}]}
{"op":"mcm","clk":"11449459046","pt":1717309460211,"mc":[{"id":"1.229554908","rc":[{"atb":[[3.45,0],[3.95,0]],"id":52671550},{"atb":[[1.99,0],[1.89,0]],"id":52671546},{"atb":[[570,0],[470,0]],"id":52671549},{"atb":[[9.2,0],[13,0]],"id":52671548},{"atb":[[9.2,0],[13,0]],"id":52671542},{"atb":[[36,0],[23,0]],"id":52671545},{"atb":[[5.6,0],[4.6,0]],"id":52671544},{"atb":[[1.99,0],[1.89,0]],"id":52671555},{"atb":[[36,0],[23,0]],"id":52671554},{"atb":[[12,0],[8.8,0]],"id":52671556}],"con":true,"img":false}]}
{"op":"mcm","clk":"11449459286","pt":1717309463590,"mc":[{"id":"1.229554908","rc":[{"atb":[[36,0],[19,0],[23,0],[28,0]],"id":52671556}],"con":true,"img":false}]}
{"op":"mcm","clk":"11449459340","pt":1717309464311,"mc":[{"id":"1.229554908","rc":[{"atb":[[34,0.8],[18.5,5.98],[22,3.74],[27,2.01]],"id":52671556}],"con":true,"img":false}]}
{"op":"mcm","clk":"11449461424","pt":1717309496544,"mc":[{"id":"1.229554908","rc":[{"atb":[[3.4,101.62],[3.9,36.04]],"id":52671550},{"atb":[[2.24,84.29],[2.04,234.52]],"id":52671546},{"atb":[[550,0.44],[650,0.16]],"id":52671549},{"atb":[[12,9.5],[8.8,31.27]],"id":52671548},{"atb":[[13.5,8.36],[9.4,29.03]],"id":52671542},{"atb":[[50,2.13],[30,8.41]],"id":52671545},{"atb":[[5.7,22.24],[4.7,65.92]],"id":52671544},{"atb":[[1.77,316.75],[1.87,210.35]],"id":52671555},{"atb":[[38,2.82],[24,10.6]],"id":52671554},{"atb":[[9.2,29.74],[13,8.71]],"id":52671556}],"con":true,"img":false}]}
{"op":"mcm","clk":"11449462429","pt":1717309511641,"mc":[{"id":"1.229554908","rc":[{"atb":[[3.4,0],[3.9,0]],"id":52671550},{"atb":[[2.24,0],[2.04,0]],"id":52671546},{"atb":[[550,0],[650,0]],"id":52671549},{"atb":[[12,0],[8.8,0]],"id":52671548},{"atb":[[13.5,0],[9.4,0]],"id":52671542},{"atb":[[50,0],[30,0]],"id":52671545},{"atb":[[5.7,0],[4.7,0]],"id":52671544},{"atb":[[1.77,0],[1.87,90.2]],"id":52671555},{"atb":[[38,0],[24,0]],"id":52671554},{"atb":[[9.2,0],[13,0]],"id":52671556}],"con":true,"img":false}]}
{"op":"mcm","clk":"11449464084","pt":1717309535573,"mc":[{"id":"1.229554908","rc":[{"atb":[[3.8,37.33],[3.3,106.04]],"id":52671550},{"atb":[[1.97,251.44],[2.14,91.69]],"id":52671546},{"atb":[[550,0.44],[650,0.16]],"id":52671549},{"atb":[[9,30.48],[12.5,9.08]],"id":52671548},{"atb":[[9.2,29.74],[13,8.71]],"id":52671542},{"atb":[[48,2.22],[29,8.71]],"id":52671545},{"atb":[[4.8,64.18],[5.8,21.77]],"id":52671544},{"atb":[[1.82,425.05],[1.92,170.49]],"id":52671555},{"atb":[[42,2.54],[26,9.75]],"id":52671554},{"atb":[[9.2,29.74],[13,8.71]],"id":52671556}],"con":true,"img":false}]}
{"op":"mcm","clk":"11449468189","pt":1717309595203,"mc":[{"id":"1.229554908","rc":[{"atb":[[170,0],[85,0],[120,0],[60,0]],"id":52671545},{"atb":[[140,0],[70,0],[95,0],[48,0]],"id":52671554},{"atb":[[34,0],[18.5,0],[22,0],[27,0]],"id":52671556}],"con":true,"img":false}]}
{"op":"mcm","clk":"11449468234","pt":1717309595923,"mc":[{"id":"1.229554908","rc":[{"atb":[[150,0.18],[75,1.06],[100,0.53],[50,2.13]],"id":52671545},{"atb":[[130,0.2],[65,1.22],[90,0.59],[46,2.32]],"id":52671554},{"atb":[[16,6.97],[18.5,4.48],[22,2.49],[27,1]],"id":52671556}],"con":true,"img":false}]}
{"op":"mcm","clk":"11449471763","pt":1717309643654,"mc":[{"id":"1.229554908","rc":[{"atb":[[3.8,0],[3.3,0]],"id":52671550},{"atb":[[1.97,0],[2.14,0]],"id":52671546},{"atb":[[550,0],[650,0]],"id":52671549},{"atb":[[9,0],[12.5,0]],"id":52671548},{"atb":[[9.2,0],[13,0]],"id":52671542},{"atb":[[48,0],[29,0]],"id":52671545},{"atb":[[4.8,0],[5.8,0]],"id":52671544},{"atb":[[1.82,127.6],[1.92,56.87]],"id":52671555},{"atb":[[42,0],[26,0]],"id":52671554},{"atb":[[9.2,0],[13,0]],"id":52671556}],"con":true,"img":false}]}
{"op":"mcm","clk":"11449471816","pt":1717309644376,"mc":[{"id":"1.229554908","rc":[{"atb":[[290,0],[340,0],[390,0],[240,0]],"id":52671549}],"con":true,"img":false}]}
{"op":"mcm","clk":"11449471879","pt":1717309645062,"mc":[{"id":"1.229554908","rc":[{"atb":[[350,0.15],[400,0.07]],"id":52671549}],"con":true,"img":false}]}
{"op":"mcm","clk":"11449471888","pt":1717309645161,"mc":[{"id":"1.229554908","rc":[{"atb":[[300,0.26],[250,0.42]],"id":52671549}],"con":true,"img":false}]}
{"op":"mcm","clk":"11449473519","pt":1717309667229,"mc":[{"id":"1.229554908","rc":[{"atb":[[3.45,99.55],[3.95,35.43]],"id":52671550},{"atb":[[1.95,256.74],[2.1,95.02]],"id":52671546},{"atb":[[550,0.44],[650,0.16]],"id":52671549},{"atb":[[9.2,29.74],[13,8.71]],"id":52671548},{"atb":[[13.5,8.36],[9.4,29.03]],"id":52671542},{"atb":[[65,1.63],[36,6.96]],"id":52671545},{"atb":[[4.8,64.18],[5.8,21.77]],"id":52671544},{"atb":[[1.8,304.88],[1.9,116.14]],"id":52671555},{"atb":[[48,2.22],[29,8.71]],"id":52671554},{"atb":[[13.5,8.36],[9.4,29.03]],"id":52671556}],"con":true,"img":false}]}
{"op":"mcm","clk":"11449474643","pt":1717309682719,"mc":[{"id":"1.229554908","rc":[{"atb":[[3.45,0],[3.95,0]],"id":52671550},{"atb":[[1.95,0],[2.1,0]],"id":52671546},{"atb":[[550,0],[650,0]],"id":52671549},{"atb":[[9.2,0],[13,0]],"id":52671548},{"atb":[[13.5,0],[9.4,0]],"id":52671542},{"atb":[[65,0],[36,0]],"id":52671545},{"atb":[[4.8,0],[5.8,0]],"id":52671544},{"atb":[[1.8,0],[1.9,0]],"id":52671555},{"atb":[[48,0],[29,0]],"id":52671554},{"atb":[[13.5,0],[9.4,0]],"id":52671556}],"con":true,"img":false}]}
{"op":"mcm","clk":"11449476652","pt":1717309708258,"mc":[{"id":"1.229554908","rc":[{"atb":[[3.45,99.55],[3.95,35.43]],"id":52671550},{"atb":[[1.94,259.47],[2.08,96.78]],"id":52671546},{"atb":[[550,0.44],[650,0.16]],"id":52671549},{"atb":[[9.2,29.74],[13,8.71]],"id":52671548},{"atb":[[13.5,8.36],[9.4,29.03]],"id":52671542},{"atb":[[95,1.11],[48,5.18]],"id":52671545},{"atb":[[4.8,64.18],[5.8,21.77]],"id":52671544},{"atb":[[1.79,308.74],[1.89,117.44]],"id":52671555},{"atb":[[70,1.51],[38,6.59]],"id":52671554},{"atb":[[9.6,28.36],[14,8.04]],"id":52671556}],"con":true,"img":false}]}
{"op":"mcm","clk":"11449490082","pt":1717309799634,"mc":[{"id":"1.229554908","rc":[{"atb":[[4.9,0],[4.4,0],[5.9,0],[5.4,0]],"id":52671550},{"atb":[[17.5,0],[20,0],[25,0],[30,0]],"id":52671542},{"atb":[[16,0],[18.5,0],[22,0],[27,0]],"id":52671556}],"con":true,"img":false}]}
{"op":"mcm","clk":"11449490143","pt":1717309800371,"mc":[{"id":"1.229554908","rc":[{"atb":[[5.6,11.37],[5.1,19.14],[4.6,29.07],[6.2,5.03]],"id":52671550},{"atb":[[36,0.75],[19,5.81],[23,3.57],[28,1.94]],"id":52671542},{"atb":[[17.5,4.76],[20,2.75],[25,1.09],[15,7.48]],"id":52671556}],"con":true,"img":false}]}
{"op":"mcm","clk":"11449491245","pt":1717309814571,"mc":[{"id":"1.229554908","rc":[{"atb":[[5.6,0],[5.1,0],[4.6,0],[6.2,0]],"id":52671550},{"atb":[[36,0],[19,0],[23,0],[28,0]],"id":52671542}],"con":true,"img":false}]}
{"op":"mcm","clk":"11449491296","pt":1717309815248,"mc":[{"id":"1.229554908","rc":[{"atb":[[5.6,5.69],[5.1,12.76],[4.6,21.8],[4.1,33.76]],"id":52671550},{"atb":[[17.5,6.34],[20,4.13],[25,2.18],[30,0.9]],"id":52671542}],"con":true,"img":false}]}
{"op":"mcm","clk":"11449491436","pt":1717309817131,"mc":[{"id":"1.229554908","rc":[{"atb":[[5.6,0],[5.1,0],[4.6,0],[4.1,0]],"id":52671550},{"atb":[[17.5,0],[20,0],[25,0],[30,0]],"id":52671542}],"con":true,"img":false}]}
{"op":"mcm","clk":"11449491487","pt":1717309817895,"mc":[{"id":"1.229554908","rc":[{"atb":[[5.6,11.37],[5.1,19.14],[4.6,29.07],[6.2,5.03]],"id":52671550},{"atb":[[36,0.75],[19,5.81],[23,3.57],[28,1.94]],"id":52671542}],"con":true,"img":false}]}
{"op":"mcm","clk":"11449492161","pt":1717309827565,"mc":[{"id":"1.229554908","rc":[{"atb":[[5.6,0],[5.1,0],[4.6,0],[6.2,0]],"id":52671550},{"atb":[[36,0],[19,0],[23,0],[28,0]],"id":52671542}],"con":true,"img":false}]}
{"op":"mcm","clk":"11449492223","pt":1717309828295,"mc":[{"id":"1.229554908","rc":[{"atb":[[5.6,5.69],[5.1,12.76],[4.6,21.8],[4.1,33.76]],"id":52671550},{"atb":[[17.5,6.34],[20,4.13],[25,2.18],[30,0.9]],"id":52671542}],"con":true,"img":false}]}
{"op":"mcm","clk":"11449493501","pt":1717309847574,"mc":[{"id":"1.229554908","rc":[{"atb":[[1.82,0],[1.92,0],[1.97,0],[1.87,0]],"id":52671555}],"con":true,"img":false}]}
{"op":"mcm","clk":"11449493539","pt":1717309848294,"mc":[{"id":"1.229554908","rc":[{"atb":[[1.83,94.55],[1.88,59.45],[1.78,134.15],[1.93,28.13]],"id":52671555}],"con":true,"img":false}]}
{"op":"mcm","clk":"11449495570","pt":1717309879434,"mc":[{"id":"1.229554908","rc":[{"atb":[[3.45,0],[3.95,0]],"id":52671550},{"atb":[[1.94,0],[2.08,0]],"id":52671546},{"atb":[[550,0],[650,0]],"id":52671549},{"atb":[[9.2,0],[13,0]],"id":52671548},{"atb":[[13.5,0],[9.4,0]],"id":52671542},{"atb":[[95,0],[48,0]],"id":52671545},{"atb":[[4.8,0],[5.8,0]],"id":52671544},{"atb":[[1.79,0],[1.89,0]],"id":52671555},{"atb":[[70,0],[38,0]],"id":52671554},{"atb":[[9.6,0],[14,0]],"id":52671556}],"con":true,"img":false}]}
{"op":"mcm","clk":"11449496112","pt":1717309888001,"mc":[{"id":"1.229554908","rc":[{"atb":[[3.4,101.62],[3.9,36.04]],"id":52671550},{"atb":[[1.92,265.11],[2.04,100.51]],"id":52671546},{"atb":[[550,0.44],[650,0.16]],"id":52671549},{"atb":[[9.2,29.74],[13,8.71]],"id":52671548},{"atb":[[13.5,8.36],[9.4,29.03]],"id":52671542},{"atb":[[90,1.17],[46,5.42]],"id":52671545},{"atb":[[4.8,64.18],[5.8,21.77]],"id":52671544},{"atb":[[1.81,301.11],[1.91,114.86]],"id":52671555},{"atb":[[75,1.41],[40,6.25]],"id":52671554},{"atb":[[9.6,28.36],[14,8.04]],"id":52671556}],"con":true,"img":false}]}
{"op":"mcm","clk":"11449516232","pt":1717310225168,"mc":[{"id":"1.229554908","rc":[{"atb":[[6.4,0],[7.4,0],[8.4,0],[9.4,0]],"id":52671544}],"con":true,"img":false}]}
{"op":"mcm","clk":"11449516266","pt":1717310225882,"mc":[{"id":"1.229554908","rc":[{"atb":[[11,2.62],[7.4,16.35],[8.4,10.61],[9.4,6.23]],"id":52671544}],"con":true,"img":false}]}
{"op":"mcm","clk":"11449528865","pt":1717310431836,"mc":[{"id":"1.229554908","rc":[{"atb":[[3.4,0],[3.9,0]],"id":52671550},{"atb":[[1.92,0],[2.04,0]],"id":52671546},{"atb":[[550,0],[650,0]],"id":52671549},{"atb":[[9.2,0],[13,0]],"id":52671548},{"atb":[[13.5,0],[9.4,0]],"id":52671542},{"atb":[[90,0],[46,0]],"id":52671545},{"atb":[[4.8,0],[5.8,0]],"id":52671544},{"atb":[[1.81,0],[1.91,0]],"id":52671555},{"atb":[[75,0],[40,0]],"id":52671554},{"atb":[[9.6,0],[14,0]],"id":52671556}],"con":true,"img":false}]}
{"op":"mcm","clk":"11449530484","pt":1717310457770,"mc":[{"id":"1.229554908","rc":[{"atb":[[1.92,265.11],[2.04,100.51]],"id":52671546},{"atb":[[9.2,29.74],[13,8.71]],"id":52671548},{"atb":[[13.5,8.36],[9.4,29.03]],"id":52671542},{"atb":[[90,1.17],[46,5.42]],"id":52671545},{"atb":[[4.8,64.18],[5.8,21.77]],"id":52671544}],"con":true,"img":false}]}
{"op":"mcm","clk":"11449530494","pt":1717310457874,"mc":[{"id":"1.229554908","rc":[{"atb":[[3.4,101.62],[3.9,36.04]],"id":52671550},{"atb":[[550,0.44],[650,0.16]],"id":52671549},{"atb":[[1.81,301.11],[1.91,114.86]],"id":52671555},{"atb":[[75,1.41],[40,6.25]],"id":52671554},{"atb":[[9.6,28.36],[14,8.04]],"id":52671556}],"con":true,"img":false}]}
{"op":"mcm","clk":"11449530617","pt":1717310459681,"mc":[{"id":"1.229554908","rc":[{"atb":[[11,0],[7.4,0],[8.4,0],[9.4,0]],"id":52671544}],"con":true,"img":false}]}
{"op":"mcm","clk":"11449530674","pt":1717310460356,"mc":[{"id":"1.229554908","rc":[{"atb":[[9.6,6.08],[8.6,10.33],[11.5,2.49],[7.6,15.85]],"id":52671544}],"con":true,"img":false}]}
{"op":"mcm","clk":"11449532107","pt":1717310486406,"mc":[{"id":"1.229554908","rc":[{"atb":[[4.1,0]],"id":52671548}],"con":true,"img":false}]}
{"op":"mcm","clk":"11449532113","pt":1717310486507,"mc":[{"id":"1.229554908","rc":[{"atb":[[5.1,0],[4.6,0],[3.8,0]],"id":52671548}],"con":true,"img":false}]}
{"op":"mcm","clk":"11449532148","pt":1717310487085,"mc":[{"id":"1.229554908","rc":[{"atb":[[4.4,23.08]],"id":52671548}],"con":true,"img":false}]}
{"op":"mcm","clk":"11449532158","pt":1717310487192,"mc":[{"id":"1.229554908","rc":[{"atb":[[3.95,35.47],[4.9,13.41],[5.4,5.94]],"id":52671548}],"con":true,"img":false}]}
{"op":"mcm","clk":"11449543822","pt":1717310686351,"mc":[{"id":"1.229554908","rc":[{"atb":[[350,0],[400,0]],"id":52671549}],"con":true,"img":false}]}
{"op":"mcm","clk":"11449543852","pt":1717310686865,"mc":[{"id":"1.229554908","rc":[{"atb":[[300,0],[250,0]],"id":52671549}],"con":true,"img":false}]}
{"op":"mcm","clk":"11449543865","pt":1717310687072,"mc":[{"id":"1.229554908","rc":[{"atb":[[450,0.12],[500,0.05]],"id":52671549}],"con":true,"img":false}]}
{"op":"mcm","clk":"11449543894","pt":1717310687537,"mc":[{"id":"1.229554908","rc":[{"atb":[[350,0.3],[400,0.2]],"id":52671549}],"con":true,"img":false}]}
{"op":"mcm","clk":"11449553472","pt":1717310851282,"mc":[{"id":"1.229554908","rc":[{"atb":[[5.6,0],[5.1,0],[4.6,0],[4.1,0]],"id":52671550},{"atb":[[17.5,0],[20,0],[25,0],[30,0]],"id":52671542}],"con":true,"img":false}]}
{"op":"mcm","clk":"11449553504","pt":1717310852003,"mc":[{"id":"1.229554908","rc":[{"atb":[[4.5,29.89],[5,19.62],[5.5,11.63],[6,5.23]],"id":52671550},{"atb":[[36,0.75],[19,5.81],[23,3.57],[28,1.94]],"id":52671542}],"con":true,"img":false}]}
{"op":"mcm","clk":"11449572150","pt":1717311196001,"mc":[{"id":"1.229554908","rc":[{"atb":[[4.5,0],[5,0],[5.5,0],[6,0]],"id":52671550},{"atb":[[350,0],[400,0]],"id":52671549},{"atb":[[9.6,0],[8.6,0],[11.5,0],[7.6,0]],"id":52671544}],"con":true,"img":false}]}
{"op":"mcm","clk":"11449572158","pt":1717311196103,"mc":[{"id":"1.229554908","rc":[{"atb":[[36,0],[19,0],[23,0],[28,0]],"id":52671542}],"con":true,"img":false}]}
{"op":"mcm","clk":"11449572189","pt":1717311196719,"mc":[{"id":"1.229554908","rc":[{"atb":[[5.6,11.37],[5.1,19.14],[4.6,29.07],[6.2,5.03]],"id":52671550},{"atb":[[380,0.28],[430,0.18]],"id":52671549},{"atb":[[7.2,16.88],[9.2,6.38],[10.5,2.75],[8.2,10.9]],"id":52671544}],"con":true,"img":false}]}
{"op":"mcm","clk":"11449572195","pt":1717311196820,"mc":[{"id":"1.229554908","rc":[{"atb":[[34,0.8],[18.5,5.98],[22,3.74],[27,2.01]],"id":52671542}],"con":true,"img":false}]}
{"op":"mcm","clk":"11449572229","pt":1717311197592,"mc":[{"id":"1.229554908","rc":[{"atb":[[380,0],[430,0]],"id":52671549}],"con":true,"img":false}]}
{"op":"mcm","clk":"11449572253","pt":1717311198310,"mc":[{"id":"1.229554908","rc":[{"atb":[[370,0.28],[420,0.19]],"id":52671549}],"con":true,"img":false}]}
{"op":"mcm","clk":"11449589750","pt":1717311498509,"mc":[{"id":"1.229554908","rc":[{"atb":[[3.4,0],[3.9,0]],"id":52671550},{"atb":[[1.92,0],[2.04,0]],"id":52671546},{"atb":[[550,0],[650,0]],"id":52671549},{"atb":[[9.2,0],[13,0]],"id":52671548},{"atb":[[13.5,0],[9.4,0]],"id":52671542},{"atb":[[90,0],[46,0]],"id":52671545},{"atb":[[4.8,0],[5.8,0]],"id":52671544},{"atb":[[1.81,0],[1.91,0]],"id":52671555},{"atb":[[75,0],[40,0]],"id":52671554},{"atb":[[9.6,0],[14,0]],"id":52671556}],"con":true,"img":false}]}
{"op":"mcm","clk":"11449590382","pt":1717311508887,"mc":[{"id":"1.229554908","rc":[{"atb":[[3.4,101.62],[3.9,36.04]],"id":52671550},{"atb":[[1.92,265.11],[2.04,100.51]],"id":52671546},{"atb":[[550,0.44],[650,0.16]],"id":52671549},{"atb":[[9.2,29.74],[13,8.71]],"id":52671548},{"atb":[[13.5,8.36],[9.4,29.03]],"id":52671542},{"atb":[[90,1.17],[46,5.42]],"id":52671545},{"atb":[[4.8,64.18],[5.8,21.77]],"id":52671544},{"atb":[[1.81,301.11],[1.91,114.86]],"id":52671555},{"atb":[[75,1.41],[40,6.25]],"id":52671554},{"atb":[[9.6,28.36],[14,8.04]],"id":52671556}],"con":true,"img":false}]}
{"op":"mcm","clk":"11449596635","pt":1717311627925,"mc":[{"id":"1.229554908","rc":[{"atb":[[450,0],[500,0]],"id":52671549}],"con":true,"img":false}]}
{"op":"mcm","clk":"11449596683","pt":1717311628640,"mc":[{"id":"1.229554908","rc":[{"atb":[[520,0.05],[470,0.11]],"id":52671549}],"con":true,"img":false}]}
{"op":"mcm","clk":"11449599905","pt":1717311688816,"mc":[{"id":"1.229554908","rc":[{"atb":[[34,0],[18.5,0],[22,0],[27,0]],"id":52671542},{"atb":[[7.2,0],[9.2,0],[10.5,0],[8.2,0]],"id":52671544}],"con":true,"img":false}]}
{"op":"mcm","clk":"11449599941","pt":1717311689482,"mc":[{"id":"1.229554908","rc":[{"atb":[[36,0.75],[19,5.81],[23,3.57],[28,1.94]],"id":52671542},{"atb":[[9.6,6.08],[8.6,10.33],[11.5,2.49],[7.6,15.85]],"id":52671544}],"con":true,"img":false}]}
{"op":"mcm","clk":"11449600256","pt":1717311695224,"mc":[{"id":"1.229554908","rc":[{"atb":[[36,0],[19,0],[23,0],[28,0]],"id":52671542},{"atb":[[9.6,0],[8.6,0],[11.5,0],[7.6,0]],"id":52671544}],"con":true,"img":false}]}
{"op":"mcm","clk":"11449600298","pt":1717311695949,"mc":[{"id":"1.229554908","rc":[{"atb":[[34,0.8],[18.5,5.98],[22,3.74],[27,2.01]],"id":52671542},{"atb":[[7.2,16.88],[9.2,6.38],[10.5,2.75],[8.2,10.9]],"id":52671544}],"con":true,"img":false}]}
{"op":"mcm","clk":"11449619711","pt":1717312057684,"mc":[{"id":"1.229554908","rc":[{"atb":[[520,0],[370,0],[420,0],[470,0]],"id":52671549}],"con":true,"img":false}]}
{"op":"mcm","clk":"11449619716","pt":1717312057790,"mc":[{"id":"1.229554908","rc":[{"atb":[[5.6,0],[5.1,0],[4.6,0],[6.2,0]],"id":52671550}],"con":true,"img":false}]}
{"op":"mcm","clk":"11449619745","pt":1717312058358,"mc":[{"id":"1.229554908","rc":[{"atb":[[350,0.3],[400,0.2],[450,0.12],[500,0.05]],"id":52671549}],"con":true,"img":false}]}
{"op":"mcm","clk":"11449619757","pt":1717312058590,"mc":[{"id":"1.229554908","rc":[{"atb":[[4.5,29.89],[5,19.62],[5.5,11.63],[6,5.23]],"id":52671550}],"con":true,"img":false}]}
{"op":"mcm","clk":"11449640553","pt":1717312587478,"mc":[{"id":"1.229554908","rc":[{"atb":[[3.4,0],[3.9,0]],"id":52671550},{"atb":[[1.92,0],[2.04,0]],"id":52671546},{"atb":[[550,0],[650,0]],"id":52671549},{"atb":[[9.2,0],[13,0]],"id":52671548},{"atb":[[13.5,0],[9.4,0]],"id":52671542},{"atb":[[90,0],[46,0]],"id":52671545},{"atb":[[4.8,0],[5.8,0]],"id":52671544},{"atb":[[1.81,0],[1.91,0]],"id":52671555},{"atb":[[75,0],[40,0]],"id":52671554},{"atb":[[9.6,0],[14,0]],"id":52671556}],"con":true,"img":false}]}
{"op":"mcm","clk":"11449640837","pt":1717312594357,"mc":[{"id":"1.229554908","rc":[{"atb":[[3.4,101.62],[3.9,36.04]],"id":52671550},{"atb":[[1.92,265.11],[2.04,100.51]],"id":52671546},{"atb":[[550,0.44],[650,0.16]],"id":52671549},{"atb":[[9.2,29.74],[13,8.71]],"id":52671548},{"atb":[[13.5,8.36],[9.4,29.03]],"id":52671542},{"atb":[[90,1.17],[46,5.42]],"id":52671545},{"atb":[[4.8,64.18],[5.8,21.77]],"id":52671544},{"atb":[[1.81,301.11],[1.91,114.86]],"id":52671555},{"atb":[[75,1.41],[40,6.25]],"id":52671554},{"atb":[[9.6,28.36],[14,8.04]],"id":52671556}],"con":true,"img":false}]}
{"op":"mcm","clk":"11449648349","pt":1717312778922,"mc":[{"id":"1.229554908","rc":[{"atb":[[3.95,0],[4.9,0],[4.4,0],[5.4,0]],"id":52671548},{"atb":[[1.83,0],[1.88,0],[1.78,0],[1.93,0]],"id":52671555}],"con":true,"img":false}]}
{"op":"mcm","clk":"11449648368","pt":1717312779439,"mc":[{"id":"1.229554908","rc":[{"atb":[[4.5,0],[5,0],[5.5,0],[6,0]],"id":52671550}],"con":true,"img":false}]}
{"op":"mcm","clk":"11449648377","pt":1717312779642,"mc":[{"id":"1.229554908","rc":[{"atb":[[3.85,36.72],[5.2,6.23],[4.2,24.52],[4.7,14.14]],"id":52671548},{"atb":[[1.83,126.06],[1.98,26.69],[1.88,89.18],[1.93,56.26]],"id":52671555}],"con":true,"img":false}]}
{"op":"mcm","clk":"11449648396","pt":1717312780155,"mc":[{"id":"1.229554908","rc":[{"atb":[[5.6,11.37],[5.1,19.14],[4.6,29.07],[6.2,5.03]],"id":52671550}],"con":true,"img":false}]}
{"op":"mcm","clk":"11449648921","pt":1717312792942,"mc":[{"id":"1.229554908","rc":[{"atb":[[5.6,0],[5.1,0],[4.6,0],[6.2,0]],"id":52671550}],"con":true,"img":false}]}
{"op":"mcm","clk":"11449648947","pt":1717312793611,"mc":[{"id":"1.229554908","rc":[{"atb":[[4.5,29.89],[5,19.62],[5.5,11.63],[6,5.23]],"id":52671550}],"con":true,"img":false}]}
{"op":"mcm","clk":"11449649059","pt":1717312796724,"mc":[{"id":"1.229554908","rc":[{"atb":[[3.85,0],[5.2,0],[4.2,0],[4.7,0]],"id":52671548},{"atb":[[1.83,0],[1.98,0],[1.88,0],[1.93,0]],"id":52671555}],"con":true,"img":false}]}
{"op":"mcm","clk":"11449649087","pt":1717312797444,"mc":[{"id":"1.229554908","rc":[{"atb":[[3.95,35.47],[4.9,13.41],[4.4,23.08],[5.4,5.94]],"id":52671548},{"atb":[[1.83,94.55],[1.88,59.45],[1.78,134.15],[1.93,28.13]],"id":52671555}],"con":true,"img":false}]}
{"op":"mcm","clk":"11449649577","pt":1717312808874,"mc":[{"id":"1.229554908","rc":[{"atb":[[3.95,0],[4.9,0],[4.4,0],[5.4,0]],"id":52671548}],"con":true,"img":false}]}
{"op":"mcm","clk":"11449649610","pt":1717312809543,"mc":[{"id":"1.229554908","rc":[{"atb":[[3.85,36.72],[5.2,6.23],[4.2,24.52],[4.7,14.14]],"id":52671548}],"con":true,"img":false}]}
{"op":"mcm","clk":"11449652383","pt":1717312868036,"mc":[{"id":"1.229554908","rc":[{"atb":[[350,0],[400,0],[450,0],[500,0]],"id":52671549},{"atb":[[34,0],[18.5,0],[22,0],[27,0]],"id":52671542}],"con":true,"img":false}]}
{"op":"mcm","clk":"11449652413","pt":1717312868751,"mc":[{"id":"1.229554908","rc":[{"atb":[[520,0.05],[370,0.28],[420,0.19],[470,0.11]],"id":52671549},{"atb":[[32,0.84],[18,6.15],[21,3.92],[26,2.09]],"id":52671542}],"con":true,"img":false}]}
{"op":"mcm","clk":"11449658175","pt":1717313009689,"mc":[{"id":"1.229554908","rc":[{"atb":[[520,0],[370,0],[420,0],[470,0]],"id":52671549}],"con":true,"img":false}]}
{"op":"mcm","clk":"11449658203","pt":1717313010361,"mc":[{"id":"1.229554908","rc":[{"atb":[[350,0.3],[400,0.2],[450,0.12],[500,0.05]],"id":52671549}],"con":true,"img":false}]}
{"op":"mcm","clk":"11449680084","pt":1717313441226,"mc":[{"id":"1.229554908","rc":[{"atb":[[3.4,0],[3.9,0]],"id":52671550},{"atb":[[1.92,0],[2.04,0]],"id":52671546},{"atb":[[550,0],[650,0]],"id":52671549},{"atb":[[9.2,0],[13,0]],"id":52671548},{"atb":[[13.5,0],[9.4,0]],"id":52671542},{"atb":[[90,0],[46,0]],"id":52671545},{"atb":[[4.8,0],[5.8,0]],"id":52671544},{"atb":[[1.81,0],[1.91,0]],"id":52671555},{"atb":[[75,0],[40,0]],"id":52671554},{"atb":[[9.6,0],[14,0]],"id":52671556}],"con":true,"img":false}]}
{"op":"mcm","clk":"11449680671","pt":1717313449233,"mc":[{"id":"1.229554908","rc":[{"atb":[[3.4,101.62],[3.9,36.04]],"id":52671550},{"atb":[[550,0.44],[650,0.16]],"id":52671549},{"atb":[[1.81,301.11],[1.91,114.86]],"id":52671555},{"atb":[[75,1.41],[40,6.25]],"id":52671554},{"atb":[[9.6,28.36],[14,8.04]],"id":52671556}],"con":true,"img":false}]}
{"op":"mcm","clk":"11449680679","pt":1717313449330,"mc":[{"id":"1.229554908","rc":[{"atb":[[1.92,265.11],[2.04,100.51]],"id":52671546},{"atb":[[9.2,29.74],[13,8.71]],"id":52671548},{"atb":[[13.5,8.36],[9.4,29.03]],"id":52671542},{"atb":[[90,1.17],[46,5.42]],"id":52671545},{"atb":[[4.8,64.18],[5.8,21.77]],"id":52671544}],"con":true,"img":false}]}
{"op":"mcm","clk":"11449686687","pt":1717313523457,"mc":[{"id":"1.229554908","rc":[{"atb":[[1.83,0],[1.78,0]],"id":52671555}],"con":true,"img":false}]}
{"op":"mcm","clk":"11449686693","pt":1717313523511,"mc":[{"id":"1.229554908","rc":[{"atb":[[1.88,0],[1.93,0]],"id":52671555}],"con":true,"img":false}]}
{"op":"mcm","clk":"11449686744","pt":1717313524133,"mc":[{"id":"1.229554908","rc":[{"atb":[[1.83,126.06],[1.98,26.69]],"id":52671555}],"con":true,"img":false}]}
{"op":"mcm","clk":"11449686756","pt":1717313524240,"mc":[{"id":"1.229554908","rc":[{"atb":[[1.88,89.18],[1.93,56.26]],"id":52671555}],"con":true,"img":false}]}
{"op":"mcm","clk":"11449692067","pt":1717313587590,"mc":[{"id":"1.229554908","rc":[{"atb":[[18,0]],"id":52671542}],"con":true,"img":false}]}
{"op":"mcm","clk":"11449692076","pt":1717313587699,"mc":[{"id":"1.229554908","rc":[{"atb":[[32,0],[21,0],[26,0]],"id":52671542}],"con":true,"img":false}]}
{"op":"mcm","clk":"11449692124","pt":1717313588312,"mc":[{"id":"1.229554908","rc":[{"atb":[[19,5.81]],"id":52671542}],"con":true,"img":false}]}
{"op":"mcm","clk":"11449692132","pt":1717313588415,"mc":[{"id":"1.229554908","rc":[{"atb":[[36,0.75],[23,3.57],[28,1.94]],"id":52671542}],"con":true,"img":false}]}
{"op":"mcm","clk":"11449708589","pt":1717313791108,"mc":[{"id":"1.229554908","rc":[{"atb":[[4.5,0],[5,0],[5.5,0],[6,0]],"id":52671550},{"atb":[[350,0],[400,0],[450,0],[500,0]],"id":52671549}],"con":true,"img":false}]}
{"op":"mcm","clk":"11449708650","pt":1717313791791,"mc":[{"id":"1.229554908","rc":[{"atb":[[5.6,11.37],[5.1,19.14],[4.6,29.07],[6.2,5.03]],"id":52671550},{"atb":[[520,0.05],[370,0.28],[420,0.19],[470,0.11]],"id":52671549}],"con":true,"img":false}]}
{"op":"mcm","clk":"11449718238","pt":1717313900704,"mc":[{"id":"1.229554908","rc":[{"atb":[[2.56,0],[2.36,0],[2.46,0],[2.26,0]],"id":52671546}],"con":true,"img":false}]}
{"op":"mcm","clk":"11449718309","pt":1717313901434,"mc":[{"id":"1.229554908","rc":[{"atb":[[2.36,38.47],[2.46,17.92],[2.26,62.28],[2.16,90.2]],"id":52671546}],"con":true,"img":false}]}
{"op":"mcm","clk":"11449723853","pt":1717313961672,"mc":[{"id":"1.229554908","rc":[{"atb":[[5.6,0],[5.1,0],[4.6,0],[6.2,0]],"id":52671550},{"atb":[[520,0],[370,0],[420,0],[470,0]],"id":52671549}],"con":true,"img":false}]}
{"op":"mcm","clk":"11449723921","pt":1717313962350,"mc":[{"id":"1.229554908","rc":[{"atb":[[4.5,29.89],[5,19.62],[5.5,11.63],[6,5.23]],"id":52671550},{"atb":[[350,0.3],[400,0.2],[450,0.12],[500,0.05]],"id":52671549}],"con":true,"img":false}]}
{"op":"mcm","clk":"11449750449","pt":1717314247810,"mc":[{"id":"1.229554908","rc":[{"atb":[[3.85,0],[5.2,0],[4.2,0],[4.7,0]],"id":52671548},{"atb":[[1.83,0],[1.98,0],[1.88,0],[1.93,0]],"id":52671555}],"con":true,"img":false}]}
{"op":"mcm","clk":"11449750509","pt":1717314248539,"mc":[{"id":"1.229554908","rc":[{"atb":[[3.95,35.47],[4.9,13.41],[4.4,23.08],[5.4,5.94]],"id":52671548},{"atb":[[1.83,94.55],[1.88,59.45],[1.78,134.15],[1.93,28.13]],"id":52671555}],"con":true,"img":false}]}
{"op":"mcm","clk":"11449751125","pt":1717314254414,"mc":[{"id":"1.229554908","rc":[{"atb":[[3.95,0],[4.9,0],[4.4,0],[5.4,0]],"id":52671548}],"con":true,"img":false}]}
{"op":"mcm","clk":"11449751190","pt":1717314255095,"mc":[{"id":"1.229554908","rc":[{"atb":[[3.85,36.72],[5.2,6.23],[4.2,24.52],[4.7,14.14]],"id":52671548}],"con":true,"img":false}]}
{"op":"mcm","clk":"11449753595","pt":1717314283452,"mc":[{"id":"1.229554908","rc":[{"atb":[[3.4,0],[3.9,0]],"id":52671550},{"atb":[[1.92,0],[2.04,0]],"id":52671546},{"atb":[[550,0],[650,0]],"id":52671549},{"atb":[[9.2,0],[13,0]],"id":52671548},{"atb":[[13.5,0],[9.4,0]],"id":52671542},{"atb":[[90,0],[46,0]],"id":52671545},{"atb":[[4.8,0],[5.8,0]],"id":52671544},{"atb":[[1.81,0],[1.91,0]],"id":52671555},{"atb":[[75,0],[40,0]],"id":52671554},{"atb":[[9.6,0],[14,0]],"id":52671556}],"con":true,"img":false}]}
{"op":"mcm","clk":"11449754582","pt":1717314295554,"mc":[{"id":"1.229554908","rc":[{"atb":[[3.4,101.62],[3.9,36.04]],"id":52671550},{"atb":[[1.92,265.11],[2.04,100.51]],"id":52671546},{"atb":[[550,0.44],[650,0.16]],"id":52671549},{"atb":[[9.2,29.74],[13,8.71]],"id":52671548},{"atb":[[13.5,8.36],[9.4,29.03]],"id":52671542},{"atb":[[90,1.17],[46,5.42]],"id":52671545},{"atb":[[4.8,64.18],[5.8,21.77]],"id":52671544},{"atb":[[1.81,301.11],[1.91,114.86]],"id":52671555},{"atb":[[75,1.41],[40,6.25]],"id":52671554},{"atb":[[9.6,28.36],[14,8.04]],"id":52671556}],"con":true,"img":false}]}
{"op":"mcm","clk":"11449774367","pt":1717314516947,"mc":[{"id":"1.229554908","rc":[{"atb":[[2.36,0],[2.46,0],[2.26,0],[2.16,0]],"id":52671546}],"con":true,"img":false}]}
{"op":"mcm","clk":"11449774435","pt":1717314517675,"mc":[{"id":"1.229554908","rc":[{"atb":[[2.38,37.91],[2.28,61.31],[2.18,88.67],[2.48,17.67]],"id":52671546}],"con":true,"img":false}]}
{"op":"mcm","clk":"11449781332","pt":1717314595426,"mc":[{"id":"1.229554908","rc":[{"atb":[[36,0],[19,0],[23,0],[28,0]],"id":52671542}],"con":true,"img":false}]}
{"op":"mcm","clk":"11449781338","pt":1717314595530,"mc":[{"id":"1.229554908","rc":[{"atb":[[4.5,0],[5,0],[5.5,0],[6,0]],"id":52671550}],"con":true,"img":false}]}
{"op":"mcm","clk":"11449781389","pt":1717314596150,"mc":[{"id":"1.229554908","rc":[{"atb":[[34,0.8],[18.5,5.98],[22,3.74],[27,2.01]],"id":52671542}],"con":true,"img":false}]}
{"op":"mcm","clk":"11449781398","pt":1717314596253,"mc":[{"id":"1.229554908","rc":[{"atb":[[5.6,11.37],[5.1,19.14],[4.6,29.07],[6.2,5.03]],"id":52671550}],"con":true,"img":false}]}
{"op":"mcm","clk":"11449781750","pt":1717314600844,"mc":[{"id":"1.229554908","rc":[{"atb":[[34,0],[18.5,0],[22,0],[27,0]],"id":52671542}],"con":true,"img":false}]}
{"op":"mcm","clk":"11449781800","pt":1717314601569,"mc":[{"id":"1.229554908","rc":[{"atb":[[36,0.75],[19,5.81],[23,3.57],[28,1.94]],"id":52671542}],"con":true,"img":false}]}
{"op":"mcm","clk":"11449781836","pt":1717314602087,"mc":[{"id":"1.229554908","rc":[{"atb":[[5.6,0],[5.1,0],[4.6,0],[6.2,0]],"id":52671550}],"con":true,"img":false}]}
{"op":"mcm","clk":"11449781912","pt":1717314602811,"mc":[{"id":"1.229554908","rc":[{"atb":[[4.5,29.89],[5,19.62],[5.5,11.63],[6,5.23]],"id":52671550}],"con":true,"img":false}]}
{"op":"mcm","clk":"11449801148","pt":1717314829342,"mc":[{"id":"1.229554908","rc":[{"atb":[[1.83,0],[1.88,0],[1.93,0]],"id":52671555}],"con":true,"img":false}]}
{"op":"mcm","clk":"11449801155","pt":1717314829447,"mc":[{"id":"1.229554908","rc":[{"atb":[[1.78,0]],"id":52671555}],"con":true,"img":false}]}
{"op":"mcm","clk":"11449801201","pt":1717314830066,"mc":[{"id":"1.229554908","rc":[{"atb":[[1.98,26.69],[1.88,89.18],[1.93,56.26]],"id":52671555}],"con":true,"img":false}]}
{"op":"mcm","clk":"11449801211","pt":1717314830165,"mc":[{"id":"1.229554908","rc":[{"atb":[[1.83,126.06]],"id":52671555}],"con":true,"img":false}]}
{"op":"mcm","clk":"11449826758","pt":1717315113545,"mc":[{"id":"1.229554908","rc":[{"atb":[[36,0],[19,0],[23,0],[28,0]],"id":52671542}],"con":true,"img":false}]}
{"op":"mcm","clk":"11449826812","pt":1717315114263,"mc":[{"id":"1.229554908","rc":[{"atb":[[34,0.8],[18.5,5.98],[22,3.74],[27,2.01]],"id":52671542}],"con":true,"img":false}]}
{"op":"mcm","clk":"11449837917","pt":1717315160931,"mc":[{"id":"1.229554908","rc":[{"atb":[[3.4,0],[3.9,0]],"id":52671550},{"atb":[[1.92,0],[2.04,0]],"id":52671546},{"atb":[[550,0],[650,0]],"id":52671549},{"atb":[[9.2,0],[13,0]],"id":52671548},{"atb":[[13.5,0],[9.4,0]],"id":52671542},{"atb":[[90,0],[46,0]],"id":52671545},{"atb":[[4.8,0],[5.8,0]],"id":52671544},{"atb":[[1.81,0],[1.91,0]],"id":52671555},{"atb":[[75,0],[40,0]],"id":52671554},{"atb":[[9.6,0],[14,0]],"id":52671556}],"con":true,"img":false}]}
{"op":"mcm","clk":"11449843010","pt":1717315211575,"mc":[{"id":"1.229554908","rc":[{"atb":[[3.4,101.62],[3.9,36.04]],"id":52671550},{"atb":[[1.92,265.11],[2.04,100.51]],"id":52671546},{"atb":[[550,0.44],[650,0.16]],"id":52671549},{"atb":[[9.2,29.74],[13,8.71]],"id":52671548},{"atb":[[13.5,8.36],[9.4,29.03]],"id":52671542},{"atb":[[90,1.17],[46,5.42]],"id":52671545},{"atb":[[4.8,64.18],[5.8,21.77]],"id":52671544},{"atb":[[1.81,301.11],[1.91,114.86]],"id":52671555},{"atb":[[75,1.41],[40,6.25]],"id":52671554},{"atb":[[9.6,28.36],[14,8.04]],"id":52671556}],"con":true,"img":false}]}
{"op":"mcm","clk":"11449882977","pt":1717315608572,"mc":[{"id":"1.229554908","rc":[{"atb":[[34,0],[18.5,0],[22,0],[27,0]],"id":52671542}],"con":true,"img":false}]}
{"op":"mcm","clk":"11449883059","pt":1717315609257,"mc":[{"id":"1.229554908","rc":[{"atb":[[36,0.75],[19,5.81],[23,3.57],[28,1.94]],"id":52671542}],"con":true,"img":false}]}
{"op":"mcm","clk":"11449888951","pt":1717315666838,"mc":[{"id":"1.229554908","rc":[{"atb":[[4.5,0],[5,0],[5.5,0],[6,0]],"id":52671550},{"atb":[[2.38,0],[2.28,0],[2.18,0],[2.48,0]],"id":52671546},{"atb":[[350,0],[400,0],[450,0],[500,0]],"id":52671549},{"atb":[[36,0],[19,0],[23,0],[28,0]],"id":52671542}],"con":true,"img":false}]}
{"op":"mcm","clk":"11449889041","pt":1717315667717,"mc":[{"id":"1.229554908","rc":[{"atb":[[5.6,11.37],[5.1,19.14],[4.6,29.07],[6.2,5.03]],"id":52671550},{"atb":[[2.32,59.45],[2.42,36.84],[2.22,85.76],[2.52,17.21]],"id":52671546},{"atb":[[300,0.35],[350,0.23],[400,0.13],[450,0.06]],"id":52671549},{"atb":[[34,0.8],[18.5,5.98],[22,3.74],[27,2.01]],"id":52671542}],"con":true,"img":false}]}
{"op":"mcm","clk":"11449893637","pt":1717315712464,"mc":[{"id":"1.229554908","rc":[{"atb":[[3.4,0],[3.9,0]],"id":52671550},{"atb":[[1.92,0],[2.04,0]],"id":52671546},{"atb":[[550,0],[650,0]],"id":52671549},{"atb":[[9.2,0],[13,0]],"id":52671548},{"atb":[[13.5,0],[9.4,0]],"id":52671542},{"atb":[[90,0],[46,0]],"id":52671545},{"atb":[[4.8,0],[5.8,0]],"id":52671544},{"atb":[[1.81,0],[1.91,0]],"id":52671555},{"atb":[[75,0],[40,0]],"id":52671554},{"atb":[[9.6,0],[14,0]],"id":52671556}],"con":true,"img":false}]}
{"op":"mcm","clk":"11449897727","pt":1717315750469,"mc":[{"id":"1.229554908","rc":[{"atb":[[1.83,0],[1.98,0],[1.88,0],[1.93,0]],"id":52671555}],"con":true,"img":false}]}
{"op":"mcm","clk":"11449897799","pt":1717315751203,"mc":[{"id":"1.229554908","rc":[{"atb":[[1.83,94.55],[1.88,59.45],[1.78,134.15],[1.93,28.13]],"id":52671555}],"con":true,"img":false}]}
{"op":"mcm","clk":"11449898352","pt":1717315756209,"mc":[{"id":"1.229554908","rc":[{"atb":[[1.83,0],[1.88,0],[1.78,0],[1.93,0]],"id":52671555}],"con":true,"img":false}]}
{"op":"mcm","clk":"11449898430","pt":1717315756886,"mc":[{"id":"1.229554908","rc":[{"atb":[[1.83,126.06],[1.98,26.69],[1.88,89.18],[1.93,56.26]],"id":52671555}],"con":true,"img":false}]}
{"op":"mcm","clk":"11449899234","pt":1717315764715,"mc":[{"id":"1.229554908","rc":[{"atb":[[3.45,99.55],[3.95,35.43]],"id":52671550},{"atb":[[2.12,93.32],[1.96,254.06]],"id":52671546},{"atb":[[550,0.44],[650,0.16]],"id":52671549},{"atb":[[9,30.48],[12.5,9.08]],"id":52671548},{"atb":[[9.2,29.74],[13,8.71]],"id":52671542},{"atb":[[44,2.43],[27,9.38]],"id":52671545},{"atb":[[5.6,22.72],[4.6,67.75]],"id":52671544},{"atb":[[1.81,301.11],[1.91,114.86]],"id":52671555},{"atb":[[36,2.98],[23,11.08]],"id":52671554},{"atb":[[9.2,29.74],[13,8.71]],"id":52671556}],"con":true,"img":false}]}
{"op":"mcm","clk":"11449909635","pt":1717315865654,"mc":[{"id":"1.229554908","rc":[{"atb":[[300,0],[350,0],[400,0],[450,0]],"id":52671549}],"con":true,"img":false}]}
{"op":"mcm","clk":"11449909724","pt":1717315866335,"mc":[{"id":"1.229554908","rc":[{"atb":[[260,0.4],[310,0.26],[360,0.15],[410,0.06]],"id":52671549}],"con":true,"img":false}]}
{"op":"mcm","clk":"11449924790","pt":1717316009617,"mc":[{"id":"1.229554908","rc":[{"atb":[[3.45,0],[3.95,0]],"id":52671550},{"atb":[[2.12,0],[1.96,0]],"id":52671546},{"atb":[[550,0],[650,0]],"id":52671549},{"atb":[[9,0],[12.5,0]],"id":52671548},{"atb":[[9.2,0],[13,0]],"id":52671542},{"atb":[[44,0],[27,0]],"id":52671545},{"atb":[[5.6,0],[4.6,0]],"id":52671544},{"atb":[[1.81,0],[1.91,0]],"id":52671555},{"atb":[[36,0],[23,0]],"id":52671554},{"atb":[[9.2,0],[13,0]],"id":52671556}],"con":true,"img":false}]}
{"op":"mcm","clk":"11449928213","pt":1717316044489,"mc":[{"id":"1.229554908","rc":[{"atb":[[3.45,99.55],[3.95,35.43]],"id":52671550},{"atb":[[550,0.44],[650,0.16]],"id":52671549},{"atb":[[1.81,301.11],[1.91,114.86]],"id":52671555},{"atb":[[36,2.98],[23,11.08]],"id":52671554},{"atb":[[9.2,29.74],[13,8.71]],"id":52671556}],"con":true,"img":false}]}
{"op":"mcm","clk":"11449928225","pt":1717316044601,"mc":[{"id":"1.229554908","rc":[{"atb":[[2.12,93.32],[1.96,254.06]],"id":52671546},{"atb":[[9,30.48],[12.5,9.08]],"id":52671548},{"atb":[[9.2,29.74],[13,8.71]],"id":52671542},{"atb":[[44,2.43],[27,9.38]],"id":52671545},{"atb":[[5.6,22.72],[4.6,67.75]],"id":52671544}],"con":true,"img":false}]}
{"op":"mcm","clk":"11449933955","pt":1717316106625,"mc":[{"id":"1.229554908","rc":[{"atb":[[2.32,0],[2.42,0],[2.22,0],[2.52,0]],"id":52671546}],"con":true,"img":false}]}
{"op":"mcm","clk":"11449934018","pt":1717316107354,"mc":[{"id":"1.229554908","rc":[{"atb":[[2.24,84.38],[2.54,16.99],[2.44,36.33],[2.34,58.56]],"id":52671546}],"con":true,"img":false}]}
{"op":"mcm","clk":"11449934911","pt":1717316117249,"mc":[{"id":"1.229554908","rc":[{"atb":[[1.83,0],[1.98,0],[1.88,0],[1.93,0]],"id":52671555}],"con":true,"img":false}]}
{"op":"mcm","clk":"11449934982","pt":1717316117974,"mc":[{"id":"1.229554908","rc":[{"atb":[[1.82,127.6],[1.92,56.87],[1.97,26.97],[1.87,90.2]],"id":52671555}],"con":true,"img":false}]}
{"op":"mcm","clk":"11449952451","pt":1717316311642,"mc":[{"id":"1.229554908","rc":[{"atb":[[5.6,0],[5.1,0],[4.6,0],[6.2,0]],"id":52671550},{"atb":[[34,0],[18.5,0],[22,0],[27,0]],"id":52671542}],"con":true,"img":false}]}
{"op":"mcm","clk":"11449952508","pt":1717316312313,"mc":[{"id":"1.229554908","rc":[{"atb":[[2.54,50.96],[2.74,15.04],[2.64,31.9],[2.44,72.66]],"id":52671550},{"atb":[[16.5,1.69],[9.6,12.17],[11.5,7.48],[14,4.02]],"id":52671542}],"con":true,"img":false}]}
{"op":"mcm","clk":"11449958672","pt":1717316391901,"mc":[{"id":"1.229554908","rc":[{"atb":[[16.5,0],[9.6,0],[11.5,0],[14,0]],"id":52671542}],"con":true,"img":false}]}
{"op":"mcm","clk":"11449959210","pt":1717316398480,"mc":[{"id":"1.229554908","rc":[{"atb":[[16,1.74],[11,7.85],[13.5,4.19],[9.4,12.46]],"id":52671542}],"con":true,"img":false}]}
{"op":"mcm","clk":"11449959375","pt":1717316400316,"mc":[{"id":"1.229554908","rc":[{"atb":[[1.08,86.39]],"id":52671550},{"atl":[[230,2]],"id":52671550},{"atb":[[1.26,142.96]],"id":52671546},{"atl":[[40,2]],"id":52671546},{"atb":[[200,2]],"id":52671549},{"atb":[[13,8.33]],"id":52671548},{"atb":[[4.3,16.56]],"id":52671542},{"atb":[[70,2]],"id":52671545},{"atb":[[4.3,27.78]],"id":52671544},{"atl":[[410,2]],"id":52671544},{"atb":[[1.05,205.08]],"id":52671555},{"atl":[[28,2]],"id":52671555},{"atb":[[60,2]],"id":52671554},{"atb":[[12,9.09]],"id":52671556}],"con":true,"img":false}]}
{"op":"mcm","clk":"11449959578","pt":1717316402809,"mc":[{"id":"1.229554908","rc":[{"atb":[[260,0],[310,0],[360,0],[410,0]],"id":52671549}],"con":true,"img":false}]}
{"op":"mcm","clk":"11449959648","pt":1717316403496,"mc":[{"id":"1.229554908","rc":[{"atb":[[280,0.38],[330,0.24],[380,0.14],[430,0.06]],"id":52671549}],"con":true,"img":false}]}
{"op":"mcm","clk":"11449959821","pt":1717316405503,"mc":[{"id":"1.229554908","rc":[{"atb":[[1.18,168.78],[1.26,0]],"id":52671546}],"con":true,"img":false}]}
{"op":"mcm","clk":"11449960004","pt":1717316407789,"mc":[{"id":"1.229554908","rc":[{"atb":[[280,0],[330,0],[380,0],[430,0]],"id":52671549},{"atb":[[150,0],[75,0],[100,0],[50,0]],"id":52671545}],"con":true,"img":false}]}
{"op":"mcm","clk":"11449960012","pt":1717316407882,"mc":[{"id":"1.229554908","rc":[{"atb":[[44,4.76]],"id":52671545}],"con":true,"img":false}]}
{"op":"mcm","clk":"11449960021","pt":1717316407987,"mc":[{"id":"1.229554908","rc":[{"atb":[[70,0]],"id":52671545}],"con":true,"img":false}]}
{"op":"mcm","clk":"11449960091","pt":1717316408820,"mc":[{"id":"1.229554908","rc":[{"atb":[[270,0.39],[320,0.25],[370,0.14],[420,0.06]],"id":52671549},{"atb":[[140,0.19],[70,1.14],[95,0.55],[48,2.23]],"id":52671545}],"con":true,"img":false}]}
{"op":"mcm","clk":"11449960340","pt":1717316411895,"mc":[{"id":"1.229554908","rc":[{"atb":[[270,0],[320,0],[370,0],[420,0]],"id":52671549}],"con":true,"img":false}]}
{"op":"mcm","clk":"11449960407","pt":1717316412625,"mc":[{"id":"1.229554908","rc":[{"atb":[[270,0.39],[320,0.25],[370,0.14],[420,0.06]],"id":52671549}],"con":true,"img":false}]}
{"op":"mcm","clk":"11449961496","pt":1717316425424,"mc":[{"id":"1.229554908","rc":[{"atb":[[270,0],[320,0],[370,0],[420,0]],"id":52671549}],"con":true,"img":false}]}
{"op":"mcm","clk":"11449961558","pt":1717316426154,"mc":[{"id":"1.229554908","rc":[{"atb":[[280,0.38],[330,0.24],[380,0.14],[430,0.06]],"id":52671549}],"con":true,"img":false}]}
{"op":"mcm","clk":"11449962024","pt":1717316431947,"mc":[{"id":"1.229554908","rc":[{"atb":[[280,0],[330,0],[380,0],[430,0]],"id":52671549}],"con":true,"img":false}]}
{"op":"mcm","clk":"11449962072","pt":1717316432666,"mc":[{"id":"1.229554908","rc":[{"atb":[[270,0.39],[320,0.25],[370,0.14],[420,0.06]],"id":52671549}],"con":true,"img":false}]}
{"op":"mcm","clk":"11449962468","pt":1717316437438,"mc":[{"id":"1.229554908","rc":[{"atb":[[65,2],[44,2.43]],"id":52671545}],"con":true,"img":false}]}
{"op":"mcm","clk":"11449965993","pt":1717316485213,"mc":[{"id":"1.229554908","rc":[{"atb":[[65,0],[75,2]],"id":52671545},{"atb":[[70,2],[60,0]],"id":52671554}],"con":true,"img":false}]}
{"op":"mcm","clk":"11449967837","pt":1717316511954,"mc":[{"id":"1.229554908","rc":[{"atb":[[1.82,0],[1.92,0],[1.97,0],[1.87,0]],"id":52671555}],"con":true,"img":false}]}
{"op":"mcm","clk":"11449967890","pt":1717316512628,"mc":[{"id":"1.229554908","rc":[{"atb":[[1.99,79.27],[2.18,22.17],[1.94,111.32],[2.08,48.44]],"id":52671555}],"con":true,"img":false}]}
{"op":"mcm","clk":"11449970486","pt":1717316552457,"mc":[{"id":"1.229554908","rc":[{"atb":[[3.45,0],[3.95,0]],"id":52671550},{"atb":[[2.12,0],[1.96,0]],"id":52671546},{"atb":[[550,0],[650,0]],"id":52671549},{"atb":[[9,0],[12.5,0]],"id":52671548},{"atb":[[9.2,0],[13,0]],"id":52671542},{"atb":[[44,0],[27,0]],"id":52671545},{"atb":[[5.6,0],[4.6,0]],"id":52671544},{"atb":[[1.81,0],[1.91,0]],"id":52671555},{"atb":[[36,0],[23,0]],"id":52671554},{"atb":[[9.2,0],[13,0]],"id":52671556}],"con":true,"img":false}]}
{"op":"mcm","clk":"11449970493","pt":1717316552561,"mc":[{"id":"1.229554908","rc":[{"atb":[[5.3,16.66]],"id":52671548}],"con":true,"img":false}]}
{"op":"mcm","clk":"11449970502","pt":1717316552663,"mc":[{"id":"1.229554908","rc":[{"atb":[[13,0]],"id":52671548}],"con":true,"img":false}]}
{"op":"mcm","clk":"11449971658","pt":1717316571125,"mc":[{"id":"1.229554908","rc":[{"atb":[[3.45,99.55],[3.95,35.43]],"id":52671550},{"atb":[[550,0.44],[650,0.16]],"id":52671549},{"atb":[[1.81,301.11],[1.91,114.86]],"id":52671555},{"atb":[[36,2.98],[23,11.08]],"id":52671554},{"atb":[[9.2,29.74],[13,8.71]],"id":52671556}],"con":true,"img":false}]}
{"op":"mcm","clk":"11449971667","pt":1717316571229,"mc":[{"id":"1.229554908","rc":[{"atb":[[2.12,93.32],[1.96,254.06]],"id":52671546},{"atb":[[9,30.48],[12.5,9.08]],"id":52671548},{"atb":[[9.2,29.74],[13,8.71]],"id":52671542},{"atb":[[44,2.43],[27,9.38]],"id":52671545},{"atb":[[5.6,22.72],[4.6,67.75]],"id":52671544}],"con":true,"img":false}]}
{"op":"mcm","clk":"11449971674","pt":1717316571282,"mc":[{"id":"1.229554908","rc":[{"atb":[[5.3,0],[13,8.33]],"id":52671548}],"con":true,"img":false}]}
{"op":"mcm","clk":"11449980084","pt":1717316686828,"mc":[{"id":"1.229554908","rc":[{"atb":[[2.54,0],[2.74,0],[2.64,0],[2.44,0]],"id":52671550}],"con":true,"img":false}]}
{"op":"mcm","clk":"11449980133","pt":1717316687547,"mc":[{"id":"1.229554908","rc":[{"atb":[[5.6,11.37],[4.6,29.07],[6.2,5.03]],"id":52671550}],"con":true,"img":false}]}
{"op":"mcm","clk":"11449980157","pt":1717316687864,"mc":[{"id":"1.229554908","rc":[{"atb":[[5.1,19.14]],"id":52671550}],"con":true,"img":false}]}
{"op":"mcm","clk":"11449989470","pt":1717316817618,"mc":[{"id":"1.229554908","rc":[{"atb":[[1.99,0],[2.18,0],[1.94,0],[2.08,0]],"id":52671555}],"con":true,"img":false}]}
{"op":"mcm","clk":"11449989531","pt":1717316818296,"mc":[{"id":"1.229554908","rc":[{"atb":[[2.06,49.36],[1.98,80.08],[1.93,112.51],[2.16,22.55]],"id":52671555}],"con":true,"img":false}]}
{"op":"mcm","clk":"11449999418","pt":1717316939030,"mc":[{"id":"1.229554908","rc":[{"atb":[[3.45,0],[3.95,0]],"id":52671550},{"atb":[[2.12,0],[1.96,0]],"id":52671546},{"atb":[[550,0],[650,0]],"id":52671549},{"atb":[[9,0],[12.5,0]],"id":52671548},{"atb":[[9.2,0],[13,0]],"id":52671542},{"atb":[[44,0],[27,0]],"id":52671545},{"atb":[[5.6,0],[4.6,0]],"id":52671544},{"atb":[[1.81,0],[1.91,0]],"id":52671555},{"atb":[[36,0],[23,0]],"id":52671554},{"atb":[[9.2,0],[13,0]],"id":52671556}],"con":true,"img":false}]}
{"op":"mcm","clk":"11449999428","pt":1717316939135,"mc":[{"id":"1.229554908","rc":[{"atb":[[5.3,16.66]],"id":52671548}],"con":true,"img":false}]}
{"op":"mcm","clk":"11449999435","pt":1717316939239,"mc":[{"id":"1.229554908","rc":[{"atb":[[13,0]],"id":52671548}],"con":true,"img":false}]}
{"op":"mcm","clk":"11450000408","pt":1717316949998,"mc":[{"id":"1.229554908","rc":[{"atb":[[3.45,99.55],[3.95,35.43]],"id":52671550},{"atb":[[2.12,93.32],[1.96,254.06]],"id":52671546},{"atb":[[550,0.44],[650,0.16]],"id":52671549},{"atb":[[9,30.48],[12.5,9.08]],"id":52671548},{"atb":[[9.2,29.74],[13,8.71]],"id":52671542},{"atb":[[44,2.43],[27,9.38]],"id":52671545},{"atb":[[5.6,22.72],[4.6,67.75]],"id":52671544},{"atb":[[1.81,301.11],[1.91,114.86]],"id":52671555},{"atb":[[36,2.98],[23,11.08]],"id":52671554},{"atb":[[9.2,29.74],[13,8.71]],"id":52671556}],"con":true,"img":false}]}
{"op":"mcm","clk":"11450000416","pt":1717316950116,"mc":[{"id":"1.229554908","rc":[{"atb":[[5.3,0],[13,8.33]],"id":52671548}],"con":true,"img":false}]}
{"op":"mcm","clk":"11450007066","pt":1717317024456,"mc":[{"id":"1.229554908","rc":[{"atb":[[6.2,0]],"id":52671550}],"con":true,"img":false}]}
{"op":"mcm","clk":"11450007078","pt":1717317024554,"mc":[{"id":"1.229554908","rc":[{"atb":[[5.6,0],[4.6,0]],"id":52671550}],"con":true,"img":false}]}
{"op":"mcm","clk":"11450007116","pt":1717317024861,"mc":[{"id":"1.229554908","rc":[{"atb":[[5.1,0]],"id":52671550}],"con":true,"img":false}]}
{"op":"mcm","clk":"11450007147","pt":1717317025166,"mc":[{"id":"1.229554908","rc":[{"atb":[[6.4,4.84]],"id":52671550}],"con":true,"img":false}]}
{"op":"mcm","clk":"11450007152","pt":1717317025273,"mc":[{"id":"1.229554908","rc":[{"atb":[[5.7,11.13],[4.7,28.28]],"id":52671550}],"con":true,"img":false}]}
{"op":"mcm","clk":"11450007189","pt":1717317025681,"mc":[{"id":"1.229554908","rc":[{"atb":[[5.2,18.68]],"id":52671550}],"con":true,"img":false}]}
{"op":"mcm","clk":"11450008103","pt":1717317035269,"mc":[{"id":"1.229554908","rc":[{"atb":[[2.24,0],[2.54,0],[2.44,0],[2.34,0]],"id":52671546}],"con":true,"img":false}]}
{"op":"mcm","clk":"11450008179","pt":1717317035992,"mc":[{"id":"1.229554908","rc":[{"atb":[[2.38,18.95],[2.28,40.88],[2.18,66.51],[2.08,96.89]],"id":52671546}],"con":true,"img":false}]}
{"op":"mcm","clk":"11450013144","pt":1717317085441,"mc":[{"id":"1.229554908","rc":[{"atb":[[1.18,0],[1.26,168.78]],"id":52671546}],"con":true,"img":false}]}
{"op":"mcm","clk":"11450013170","pt":1717317085747,"mc":[{"id":"1.229554908","rc":[{"atb":[[6.4,0],[5.2,0],[5.7,0],[4.7,0]],"id":52671550},{"atb":[[2.38,0],[2.28,0],[2.18,0],[2.08,0]],"id":52671546},{"atb":[[270,0],[320,0],[370,0],[420,0]],"id":52671549},{"atb":[[2.06,0],[1.98,0],[1.93,0],[2.16,0]],"id":52671555}],"con":true,"img":false}]}
{"op":"mcm","clk":"11450013232","pt":1717317086418,"mc":[{"id":"1.229554908","rc":[{"atb":[[5.6,11.37],[5.1,19.14],[4.6,29.07],[6.2,5.03]],"id":52671550},{"atb":[[2.24,84.38],[2.54,16.99],[2.44,36.33],[2.34,58.56]],"id":52671546},{"atb":[[260,0.4],[310,0.26],[360,0.15],[410,0.06]],"id":52671549},{"atb":[[2.02,51.29],[1.91,229.85],[2.12,23.35],[1.96,81.75]],"id":52671555}],"con":true,"img":false}]}
{"op":"mcm","clk":"11450013810","pt":1717317092755,"mc":[{"id":"1.229554908","rc":[{"atb":[[1.18,168.78],[1.26,0]],"id":52671546}],"con":true,"img":false}]}
{"op":"mcm","clk":"11450013848","pt":1717317093123,"mc":[{"id":"1.229554908","rc":[{"atb":[[2.24,0],[2.54,0],[2.44,0],[2.34,0]],"id":52671546}],"con":true,"img":false}]}
{"op":"mcm","clk":"11450013928","pt":1717317093951,"mc":[{"id":"1.229554908","rc":[{"atb":[[2.38,18.95],[2.28,40.88],[2.18,66.51],[2.08,96.89]],"id":52671546}],"con":true,"img":false}]}
{"op":"mcm","clk":"11450015841","pt":1717317115696,"mc":[{"id":"1.229554908","rc":[{"atb":[[1.18,0],[1.26,168.78]],"id":52671546}],"con":true,"img":false}]}
{"op":"mcm","clk":"11450040241","pt":1717317351952,"mc":[{"id":"1.229554908","rc":[{"atb":[[3.45,0],[3.95,0]],"id":52671550},{"atb":[[2.12,0],[1.96,0]],"id":52671546},{"atb":[[550,0],[650,0]],"id":52671549},{"atb":[[9,0],[12.5,0]],"id":52671548},{"atb":[[9.2,0],[13,0]],"id":52671542},{"atb":[[44,0],[27,0]],"id":52671545},{"atb":[[5.6,0],[4.6,0]],"id":52671544},{"atb":[[1.81,0],[1.91,114.98]],"id":52671555},{"atb":[[36,0],[23,0]],"id":52671554},{"atb":[[9.2,0],[13,0]],"id":52671556}],"con":true,"img":false}]}
{"op":"mcm","clk":"11450040247","pt":1717317352052,"mc":[{"id":"1.229554908","rc":[{"atb":[[5.3,16.66]],"id":52671548}],"con":true,"img":false}]}
{"op":"mcm","clk":"11450040257","pt":1717317352164,"mc":[{"id":"1.229554908","rc":[{"atb":[[13,0]],"id":52671548}],"con":true,"img":false}]}
{"op":"mcm","clk":"11450043545","pt":1717317383593,"mc":[{"id":"1.229554908","rc":[{"atb":[[5.6,0],[5.1,0],[4.6,0],[6.2,0]],"id":52671550},{"atb":[[260,0],[310,0],[360,0],[410,0]],"id":52671549}],"con":true,"img":false}]}
{"op":"mcm","clk":"11450043625","pt":1717317384269,"mc":[{"id":"1.229554908","rc":[{"atb":[[6.4,4.84],[5.2,18.68],[5.7,11.13],[4.7,28.28]],"id":52671550},{"atb":[[310,0.34],[360,0.22],[410,0.13],[460,0.06]],"id":52671549}],"con":true,"img":false}]}
{"op":"mcm","clk":"11450044140","pt":1717317388995,"mc":[{"id":"1.229554908","rc":[{"atb":[[3.45,99.55],[3.95,35.43]],"id":52671550},{"atb":[[2.12,93.32],[1.96,254.06]],"id":52671546},{"atb":[[550,0.44],[650,0.16]],"id":52671549},{"atb":[[9,30.48],[12.5,9.08]],"id":52671548},{"atb":[[9.2,29.74],[13,8.71]],"id":52671542},{"atb":[[44,2.43],[27,9.38]],"id":52671545},{"atb":[[5.6,22.72],[4.6,67.75]],"id":52671544},{"atb":[[1.81,301.11],[1.91,229.85]],"id":52671555},{"atb":[[36,2.98],[23,11.08]],"id":52671554},{"atb":[[9.2,29.74],[13,8.71]],"id":52671556}],"con":true,"img":false}]}
{"op":"mcm","clk":"11450044159","pt":1717317389203,"mc":[{"id":"1.229554908","rc":[{"atb":[[5.3,0],[13,8.33]],"id":52671548}],"con":true,"img":false}]}
{"op":"mcm","clk":"11450044244","pt":1717317389984,"mc":[{"id":"1.229554908","rc":[{"atb":[[6.4,0],[5.2,0],[5.7,0],[4.7,0]],"id":52671550},{"atb":[[310,0],[360,0],[410,0],[460,0]],"id":52671549}],"con":true,"img":false}]}
{"op":"mcm","clk":"11450044282","pt":1717317390293,"mc":[{"id":"1.229554908","rc":[{"atb":[[2.38,0],[2.28,0],[2.18,0],[2.08,0]],"id":52671546}],"con":true,"img":false}]}
{"op":"mcm","clk":"11450044318","pt":1717317390663,"mc":[{"id":"1.229554908","rc":[{"atb":[[5.6,11.37],[5.1,19.14],[4.6,29.07],[6.2,5.03]],"id":52671550},{"atb":[[260,0.4],[310,0.26],[360,0.15],[410,0.06]],"id":52671549}],"con":true,"img":false}]}
{"op":"mcm","clk":"11450044354","pt":1717317390973,"mc":[{"id":"1.229554908","rc":[{"atb":[[2.24,84.38],[2.44,36.33],[2.34,58.56]],"id":52671546}],"con":true,"img":false}]}
{"op":"mcm","clk":"11450044361","pt":1717317391075,"mc":[{"id":"1.229554908","rc":[{"atb":[[2.54,16.99]],"id":52671546}],"con":true,"img":false}]}
{"op":"mcm","clk":"11450052882","pt":1717317474650,"mc":[{"id":"1.229554908","rc":[{"atb":[[1.18,168.78]],"id":52671546}],"con":true,"img":false}]}
{"op":"mcm","clk":"11450052890","pt":1717317474756,"mc":[{"id":"1.229554908","rc":[{"atb":[[1.26,0]],"id":52671546}],"con":true,"img":false}]}
{"op":"mcm","clk":"11450052916","pt":1717317475063,"mc":[{"id":"1.229554908","rc":[{"atb":[[1.18,0],[1.24,168.78]],"id":52671546},{"atb":[[2.02,0],[2.12,0],[1.91,114.86],[1.96,0]],"id":52671555}],"con":true,"img":false}]}
{"op":"mcm","clk":"11450052926","pt":1717317475169,"mc":[{"id":"1.229554908","rc":[{"atb":[[1.18,168.78],[1.24,0]],"id":52671546}],"con":true,"img":false}]}
{"op":"mcm","clk":"11450052998","pt":1717317475893,"mc":[{"id":"1.229554908","rc":[{"atb":[[1.18,0],[1.26,168.78]],"id":52671546},{"atb":[[2.06,49.36],[1.98,80.08],[1.93,112.51],[2.16,22.55]],"id":52671555}],"con":true,"img":false}]}
{"op":"mcm","clk":"11450053070","pt":1717317476569,"mc":[{"id":"1.229554908","rc":[{"atb":[[2.06,0],[1.98,0],[1.93,0],[2.16,0]],"id":52671555}],"con":true,"img":false}]}
{"op":"mcm","clk":"11450053126","pt":1717317477285,"mc":[{"id":"1.229554908","rc":[{"atb":[[2.02,51.29],[1.91,229.85],[2.12,23.35],[1.96,81.75]],"id":52671555}],"con":true,"img":false}]}
{"op":"mcm","clk":"11450062252","pt":1717317579477,"mc":[{"id":"1.229554908","rc":[{"atb":[[1.18,168.78]],"id":52671546}],"con":true,"img":false}]}
{"op":"mcm","clk":"11450062261","pt":1717317579580,"mc":[{"id":"1.229554908","rc":[{"atb":[[1.26,0]],"id":52671546}],"con":true,"img":false}]}
{"op":"mcm","clk":"11450062288","pt":1717317579891,"mc":[{"id":"1.229554908","rc":[{"atb":[[2.02,0],[2.12,0],[1.91,114.86],[1.96,0]],"id":52671555}],"con":true,"img":false}]}
{"op":"mcm","clk":"11450062351","pt":1717317580567,"mc":[{"id":"1.229554908","rc":[{"atb":[[2.06,49.36],[1.98,80.08],[1.93,112.51],[2.16,22.55]],"id":52671555}],"con":true,"img":false}]}
{"op":"mcm","clk":"11450062388","pt":1717317580974,"mc":[{"id":"1.229554908","rc":[{"atb":[[1.18,0],[1.24,168.78]],"id":52671546}],"con":true,"img":false}]}
{"op":"mcm","clk":"11450062559","pt":1717317583007,"mc":[{"id":"1.229554908","rc":[{"atb":[[1.18,168.78],[1.24,0]],"id":52671546}],"con":true,"img":false}]}
{"op":"mcm","clk":"11450062584","pt":1717317583266,"mc":[{"id":"1.229554908","rc":[{"atb":[[1.18,0],[1.24,168.78]],"id":52671546}],"con":true,"img":false}]}
{"op":"mcm","clk":"11450062652","pt":1717317584092,"mc":[{"id":"1.229554908","rc":[{"atb":[[1.18,168.78]],"id":52671546}],"con":true,"img":false}]}
{"op":"mcm","clk":"11450062659","pt":1717317584195,"mc":[{"id":"1.229554908","rc":[{"atb":[[1.24,0]],"id":52671546}],"con":true,"img":false}]}
{"op":"mcm","clk":"11450063098","pt":1717317588772,"mc":[{"id":"1.229554908","rc":[{"atb":[[1.18,0],[1.24,168.78]],"id":52671546}],"con":true,"img":false}]}
{"op":"mcm","clk":"11450063125","pt":1717317589075,"mc":[{"id":"1.229554908","rc":[{"atb":[[2.06,0],[1.98,0],[1.93,0],[2.16,0]],"id":52671555}],"con":true,"img":false}]}
{"op":"mcm","clk":"11450063185","pt":1717317589805,"mc":[{"id":"1.229554908","rc":[{"atb":[[2.02,51.29],[1.91,229.85],[2.12,23.35],[1.96,81.75]],"id":52671555}],"con":true,"img":false}]}
{"op":"mcm","clk":"11450066369","pt":1717317625022,"mc":[{"id":"1.229554908","rc":[{"atb":[[1.24,0],[1.17,168.78]],"id":52671546}],"con":true,"img":false}]}
{"op":"mcm","clk":"11450069286","pt":1717317657306,"mc":[{"id":"1.229554908","rc":[{"atb":[[260,0],[310,0],[360,0],[410,0]],"id":52671549}],"con":true,"img":false}]}
{"op":"mcm","clk":"11450069371","pt":1717317657979,"mc":[{"id":"1.229554908","rc":[{"atb":[[360,0.22],[410,0.13],[460,0.06]],"id":52671549}],"con":true,"img":false}]}
{"op":"mcm","clk":"11450069380","pt":1717317658084,"mc":[{"id":"1.229554908","rc":[{"atb":[[310,0.34]],"id":52671549}],"con":true,"img":false}]}
{"op":"mcm","clk":"11450076063","pt":1717317730372,"mc":[{"id":"1.229554908","rc":[{"atb":[[3.45,0],[3.95,0]],"id":52671550},{"atb":[[2.12,0],[1.96,0]],"id":52671546},{"atb":[[550,0],[650,0]],"id":52671549},{"atb":[[9,0],[12.5,0]],"id":52671548},{"atb":[[9.2,0],[13,0]],"id":52671542},{"atb":[[44,0],[27,0]],"id":52671545},{"atb":[[5.6,0],[4.6,0]],"id":52671544},{"atb":[[1.81,0],[1.91,114.98]],"id":52671555},{"atb":[[36,0],[23,0]],"id":52671554},{"atb":[[9.2,0],[13,0]],"id":52671556}],"con":true,"img":false}]}
{"op":"mcm","clk":"11450076071","pt":1717317730477,"mc":[{"id":"1.229554908","rc":[{"atb":[[5.3,16.66],[13,0]],"id":52671548}],"con":true,"img":false}]}
{"op":"mcm","clk":"11450078649","pt":1717317758644,"mc":[{"id":"1.229554908","rc":[{"atb":[[310,0],[360,0],[410,0],[460,0]],"id":52671549}],"con":true,"img":false}]}
{"op":"mcm","clk":"11450078721","pt":1717317759368,"mc":[{"id":"1.229554908","rc":[{"atb":[[280,0.38],[330,0.24],[380,0.14],[430,0.06]],"id":52671549}],"con":true,"img":false}]}
{"op":"mcm","clk":"11450079213","pt":1717317764868,"mc":[{"id":"1.229554908","rc":[{"atb":[[3.45,99.55],[3.95,35.43]],"id":52671550},{"atb":[[2.12,93.32],[1.96,254.06]],"id":52671546},{"atb":[[550,0.44],[650,0.16]],"id":52671549},{"atb":[[9,30.48],[12.5,9.08]],"id":52671548},{"atb":[[9.2,29.74],[13,8.71]],"id":52671542},{"atb":[[44,2.43],[27,9.38]],"id":52671545},{"atb":[[5.6,22.72],[4.6,67.75]],"id":52671544},{"atb":[[1.81,301.11],[1.91,229.85]],"id":52671555},{"atb":[[36,2.98],[23,11.08]],"id":52671554},{"atb":[[9.2,29.74],[13,8.71]],"id":52671556}],"con":true,"img":false}]}
{"op":"mcm","clk":"11450079225","pt":1717317764969,"mc":[{"id":"1.229554908","rc":[{"atb":[[5.3,0],[13,8.33]],"id":52671548}],"con":true,"img":false}]}
{"op":"mcm","clk":"11450079653","pt":1717317769361,"mc":[{"id":"1.229554908","rc":[{"atb":[[1.26,168.78],[1.17,0]],"id":52671546}],"con":true,"img":false}]}
{"op":"mcm","clk":"11450079690","pt":1717317769721,"mc":[{"id":"1.229554908","rc":[{"atb":[[280,0],[330,0],[380,0],[430,0]],"id":52671549}],"con":true,"img":false}]}
{"op":"mcm","clk":"11450079744","pt":1717317770445,"mc":[{"id":"1.229554908","rc":[{"atb":[[260,0.4],[310,0.26],[360,0.15],[410,0.06]],"id":52671549}],"con":true,"img":false}]}
{"op":"mcm","clk":"11450111188","pt":1717318130993,"mc":[{"id":"1.229554908","rc":[{"atb":[[3.45,0],[3.95,0]],"id":52671550},{"atb":[[2.12,0],[1.96,0]],"id":52671546},{"atb":[[550,0],[650,0]],"id":52671549},{"atb":[[9,0],[12.5,0]],"id":52671548},{"atb":[[9.2,0],[13,0]],"id":52671542},{"atb":[[44,0],[27,0]],"id":52671545},{"atb":[[5.6,0],[4.6,0]],"id":52671544},{"atb":[[1.81,0],[1.91,114.98]],"id":52671555},{"atb":[[36,0],[23,0]],"id":52671554},{"atb":[[9.2,0],[13,0]],"id":52671556}],"con":true,"img":false}]}
{"op":"mcm","clk":"11450111193","pt":1717318131093,"mc":[{"id":"1.229554908","rc":[{"atb":[[5.3,16.66]],"id":52671548}],"con":true,"img":false}]}
{"op":"mcm","clk":"11450111204","pt":1717318131201,"mc":[{"id":"1.229554908","rc":[{"atb":[[13,0]],"id":52671548}],"con":true,"img":false}]}
{"op":"mcm","clk":"11450111803","pt":1717318138007,"mc":[{"id":"1.229554908","rc":[{"atb":[[2.24,0],[2.54,0],[2.44,0],[2.34,0]],"id":52671546},{"atb":[[260,0],[310,0],[360,0],[410,0]],"id":52671549}],"con":true,"img":false}]}
{"op":"mcm","clk":"11450111813","pt":1717318138116,"mc":[{"id":"1.229554908","rc":[{"atb":[[1.26,0],[1.24,337.56]],"id":52671546}],"con":true,"img":false}]}
{"op":"mcm","clk":"11450111861","pt":1717318138678,"mc":[{"id":"1.229554908","rc":[{"atb":[[2.4,37.37],[2.5,17.44],[2.3,60.36],[2.2,87.2]],"id":52671546},{"atb":[[310,0.34],[360,0.22],[410,0.13],[460,0.06]],"id":52671549}],"con":true,"img":false}]}
{"op":"mcm","clk":"11450112520","pt":1717318145620,"mc":[{"id":"1.229554908","rc":[{"atb":[[310,0],[360,0],[410,0],[460,0]],"id":52671549}],"con":true,"img":false}]}
{"op":"mcm","clk":"11450112584","pt":1717318146299,"mc":[{"id":"1.229554908","rc":[{"atb":[[260,0.4],[310,0.26],[360,0.15],[410,0.06]],"id":52671549}],"con":true,"img":false}]}
{"op":"mcm","clk":"11450115672","pt":1717318180660,"mc":[{"id":"1.229554908","rc":[{"atb":[[1.18,120.74],[1.24,0]],"id":52671546}],"con":true,"img":false}]}
{"op":"mcm","clk":"11450115705","pt":1717318181020,"mc":[{"id":"1.229554908","rc":[{"atb":[[2.4,0],[2.5,0],[2.3,0],[2.2,0]],"id":52671546},{"atb":[[2.02,0],[2.12,0],[1.91,0],[1.96,0]],"id":52671555}],"con":true,"img":false}]}
{"op":"mcm","clk":"11450115767","pt":1717318181751,"mc":[{"id":"1.229554908","rc":[{"atb":[[2.38,18.95],[2.28,40.88],[2.18,66.51],[2.08,96.89]],"id":52671546},{"atb":[[2.06,49.36],[1.98,80.08],[1.93,112.51],[2.16,22.55]],"id":52671555}],"con":true,"img":false}]}
{"op":"mcm","clk":"11450116028","pt":1717318184562,"mc":[{"id":"1.229554908","rc":[{"atb":[[1.18,0],[1.26,120.74]],"id":52671546}],"con":true,"img":false}]}
{"op":"mcm","clk":"11450116054","pt":1717318184873,"mc":[{"id":"1.229554908","rc":[{"atb":[[2.06,0],[1.98,0],[1.93,0],[2.16,0]],"id":52671555}],"con":true,"img":false}]}
{"op":"mcm","clk":"11450116136","pt":1717318185660,"mc":[{"id":"1.229554908","rc":[{"atb":[[2.02,51.29],[2.12,23.35],[1.91,114.98],[1.96,81.75]],"id":52671555}],"con":true,"img":false}]}
{"op":"mcm","clk":"11450116440","pt":1717318188562,"mc":[{"id":"1.229554908","rc":[{"atb":[[2.12,93.32],[1.96,254.06]],"id":52671546},{"atb":[[9,30.48],[12.5,9.08]],"id":52671548},{"atb":[[9.2,29.74],[13,8.71]],"id":52671542},{"atb":[[44,2.43],[27,9.38]],"id":52671545},{"atb":[[5.6,22.72],[4.6,67.75]],"id":52671544}],"con":true,"img":false}]}
{"op":"mcm","clk":"11450116455","pt":1717318188663,"mc":[{"id":"1.229554908","rc":[{"atb":[[3.45,99.55],[3.95,35.43]],"id":52671550},{"atb":[[550,0.44],[650,0.16]],"id":52671549},{"atb":[[13,8.33]],"id":52671548},{"atb":[[1.81,301.11],[1.91,229.85]],"id":52671555},{"atb":[[36,2.98],[23,11.08]],"id":52671554},{"atb":[[9.2,29.74],[13,8.71]],"id":52671556}],"con":true,"img":false}]}
{"op":"mcm","clk":"11450116466","pt":1717318188769,"mc":[{"id":"1.229554908","rc":[{"atb":[[5.3,0]],"id":52671548}],"con":true,"img":false}]}
{"op":"mcm","clk":"11450117585","pt":1717318201586,"mc":[{"id":"1.229554908","rc":[{"atb":[[2.36,11.54],[2.32,11.89]],"id":52671546},{"atl":[[4.3,4.75],[4.5,2.92]],"id":52671546},{"atl":[[80,2.79],[90,4.68]],"id":52671542}],"con":true,"img":false}]}
{"op":"mcm","clk":"11450117592","pt":1717318201695,"mc":[{"id":"1.229554908","rc":[{"atl":[[10.5,4.3],[11.5,3.65]],"id":52671550},{"atb":[[16.5,3.1],[17.5,3.94]],"id":52671548},{"atl":[[70,3.24],[80,4.27]],"id":52671548},{"atb":[[85,4.05],[95,3.8]],"id":52671545},{"atl":[[390,3.58],[410,2.73]],"id":52671545},{"atl":[[22,3.35],[24,4.7]],"id":52671544},{"atb":[[1.91,247.1],[1.93,16.87]],"id":52671555},{"atl":[[3.6,6.03],[3.5,6.27]],"id":52671555},{"atb":[[70,5.36],[60,3.9]],"id":52671554},{"atl":[[310,3.23],[330,3.52]],"id":52671554},{"atb":[[16,3.28],[15,10.95]],"id":52671556},{"atl":[[44,2.76],[48,2.89]],"id":52671556}],"con":true,"img":false}]}
{"op":"mcm","clk":"11450117600","pt":1717318201794,"mc":[{"id":"1.229554908","rc":[{"atl":[[9,7.68],[40,0]],"id":52671546},{"atl":[[55,2]],"id":52671544},{"atl":[[7.6,12.32]],"id":52671555}],"con":true,"img":false}]}
{"op":"mcm","clk":"11450117608","pt":1717318201892,"mc":[{"id":"1.229554908","rc":[{"atl":[[23,4.55],[230,0]],"id":52671550},{"atl":[[410,0]],"id":52671544},{"atl":[[28,0]],"id":52671555}],"con":true,"img":false}]}
{"op":"mcm","clk":"11450117787","pt":1717318203785,"mc":[{"id":"1.229554908","rc":[{"atl":[[65,3],[70,0]],"id":52671548},{"atl":[[3.45,6.4],[3.5,0]],"id":52671555},{"atl":[[42,3.73],[44,0]],"id":52671556}],"con":true,"img":false}]}
{"op":"mcm","clk":"11450118641","pt":1717318213757,"mc":[{"id":"1.229554908","rc":[{"atl":[[65,0],[70,3.41]],"id":52671548},{"atl":[[3.45,0],[3.5,6.27]],"id":52671555},{"atl":[[42,0],[44,3.4]],"id":52671556}],"con":true,"img":false}]}
{"op":"mcm","clk":"11450138842","pt":1717318448197,"mc":[{"id":"1.229554908","rc":[{"atb":[[17.5,0],[18,4.2]],"id":52671548}],"con":true,"img":false}]}
{"op":"mcm","clk":"11450139297","pt":1717318453573,"mc":[{"id":"1.229554908","rc":[{"atb":[[17.5,4.09],[18,0]],"id":52671548}],"con":true,"img":false}]}
{"op":"mcm","clk":"11450142080","pt":1717318485016,"mc":[{"id":"1.229554908","rc":[{"atb":[[3.45,0],[3.95,0]],"id":52671550},{"atb":[[2.12,0],[1.96,0]],"id":52671546},{"atb":[[550,0],[650,0]],"id":52671549},{"atb":[[9,0],[12.5,0]],"id":52671548},{"atb":[[9.2,0],[13,0]],"id":52671542},{"atb":[[44,0],[27,0]],"id":52671545},{"atb":[[5.6,0],[4.6,0]],"id":52671544},{"atb":[[1.81,0],[1.91,132.23]],"id":52671555},{"atb":[[36,0],[23,0]],"id":52671554},{"atb":[[9.2,0],[13,0]],"id":52671556}],"con":true,"img":false}]}
{"op":"mcm","clk":"11450142835","pt":1717318493532,"mc":[{"id":"1.229554908","rc":[{"atb":[[1.18,87.19],[1.16,98.09]],"id":52671550},{"atb":[[4.4,3.84],[4.2,4.9]],"id":52671544}],"con":true,"img":false}]}
{"op":"mcm","clk":"11450142846","pt":1717318493632,"mc":[{"id":"1.229554908","rc":[{"atb":[[150,3.02],[170,3.92]],"id":52671549},{"atb":[[4.4,2.62],[4.2,4.9]],"id":52671542}],"con":true,"img":false}]}
{"op":"mcm","clk":"11450144976","pt":1717318517683,"mc":[{"id":"1.229554908","rc":[{"atb":[[3.45,99.55],[3.95,35.43]],"id":52671550},{"atb":[[2.12,93.32],[1.96,254.06]],"id":52671546},{"atb":[[550,0.44],[650,0.16]],"id":52671549},{"atb":[[9,30.48],[12.5,9.08]],"id":52671548},{"atb":[[9.2,29.74],[13,8.71]],"id":52671542},{"atb":[[44,2.43],[27,9.38]],"id":52671545},{"atb":[[5.6,22.72],[4.6,67.75]],"id":52671544},{"atb":[[1.81,301.11],[1.91,247.1]],"id":52671555},{"atb":[[36,2.98],[23,11.08]],"id":52671554},{"atb":[[9.2,29.74],[13,8.71]],"id":52671556}],"con":true,"img":false}]}
{"op":"mcm","clk":"11450148408","pt":1717318557805,"mc":[{"id":"1.229554908","rc":[{"atb":[[1.18,133.02],[1.26,0]],"id":52671546},{"atb":[[13,0],[14,7.69]],"id":52671548}],"con":true,"img":false}]}
{"op":"mcm","clk":"11450148432","pt":1717318558117,"mc":[{"id":"1.229554908","rc":[{"atb":[[2.36,0],[2.18,79.81]],"id":52671546},{"atb":[[260,0],[310,0],[360,0],[410,0]],"id":52671549},{"atb":[[90,4.53],[95,0.55]],"id":52671545},{"atb":[[2.02,0],[1.97,16.18],[2.12,0],[1.91,132.11],[1.96,0],[1.93,0]],"id":52671555},{"atb":[[70,2],[75,4.3]],"id":52671554},{"atb":[[16,0],[16.5,4.43]],"id":52671556}],"con":true,"img":false}]}
{"op":"mcm","clk":"11450148482","pt":1717318558836,"mc":[{"id":"1.229554908","rc":[{"atb":[[280,0.38],[330,0.24],[380,0.14],[430,0.06]],"id":52671549},{"atb":[[2.06,49.36],[1.98,80.08],[1.93,112.51],[2.16,22.55]],"id":52671555}],"con":true,"img":false}]}
{"op":"mcm","clk":"11450148953","pt":1717318564040,"mc":[{"id":"1.229554908","rc":[{"atl":[[65,4.25],[70,0]],"id":52671548}],"con":true,"img":false}]}
{"op":"mcm","clk":"11450149337","pt":1717318568118,"mc":[{"id":"1.229554908","rc":[{"atb":[[2.32,0],[2.14,13.77]],"id":52671546},{"atb":[[1.95,16.52]],"id":52671555},{"atl":[[3.45,6.4],[3.5,0]],"id":52671555},{"atl":[[44,0],[46,4.31]],"id":52671556}],"con":true,"img":false}]}
{"op":"mcm","clk":"11450150284","pt":1717318578107,"mc":[{"id":"1.229554908","rc":[{"atb":[[1.91,114.86]],"id":52671555}],"con":true,"img":false}]}
{"op":"mcm","clk":"11450170656","pt":1717318790842,"mc":[{"id":"1.229554908","rc":[{"atb":[[1.18,0],[1.26,159.62]],"id":52671546}],"con":true,"img":false}]}
{"op":"mcm","clk":"11450170675","pt":1717318791149,"mc":[{"id":"1.229554908","rc":[{"atb":[[2.36,11.54],[2.18,66.51]],"id":52671546},{"atb":[[280,0],[330,0],[380,0],[430,0]],"id":52671549},{"atb":[[90,0],[95,3.81]],"id":52671545},{"atb":[[2.06,0],[1.98,0],[1.97,0],[1.93,16.87],[2.16,0]],"id":52671555},{"atb":[[70,5.69],[75,0]],"id":52671554},{"atb":[[16.5,0],[16,3.2]],"id":52671556}],"con":true,"img":false}]}
{"op":"mcm","clk":"11450170731","pt":1717318791866,"mc":[{"id":"1.229554908","rc":[{"atb":[[260,0.4],[310,0.26],[360,0.15],[410,0.06]],"id":52671549},{"atb":[[2.02,51.29],[1.91,229.85],[2.12,23.35],[1.96,81.75]],"id":52671555}],"con":true,"img":false}]}
{"op":"mcm","clk":"11450171568","pt":1717318801189,"mc":[{"id":"1.229554908","rc":[{"atb":[[2.32,11.89]],"id":52671546},{"atl":[[65,0],[70,2.87]],"id":52671548},{"atb":[[1.91,247.1],[1.95,0]],"id":52671555},{"atl":[[3.45,0],[3.5,6.27]],"id":52671555},{"atl":[[44,3.74],[46,0]],"id":52671556}],"con":true,"img":false}]}
{"op":"mcm","clk":"11450171986","pt":1717318804700,"mc":[{"id":"1.229554908","rc":[{"atb":[[2.14,0]],"id":52671546}],"con":true,"img":false}]}
{"op":"mcm","clk":"11450176920","pt":1717318857156,"mc":[{"id":"1.229554908","rc":[{"atb":[[3.45,0],[3.95,0]],"id":52671550},{"atb":[[2.12,0],[1.96,0]],"id":52671546},{"atb":[[550,0],[650,0]],"id":52671549},{"atb":[[9,0],[12.5,0]],"id":52671548},{"atb":[[9.2,0],[13,0]],"id":52671542},{"atb":[[44,0],[27,0]],"id":52671545},{"atb":[[5.6,0],[4.6,0]],"id":52671544},{"atb":[[1.81,0],[1.91,132.23]],"id":52671555},{"atb":[[36,0],[23,0]],"id":52671554},{"atb":[[9.2,0],[13,0]],"id":52671556}],"con":true,"img":false}]}
{"op":"mcm","clk":"11450179947","pt":1717318888291,"mc":[{"id":"1.229554908","rc":[{"atb":[[3.45,99.55],[3.95,35.43]],"id":52671550},{"atb":[[2.12,93.32],[1.96,254.06]],"id":52671546},{"atb":[[550,0.44],[650,0.16]],"id":52671549},{"atb":[[9,30.48],[12.5,9.08]],"id":52671548},{"atb":[[9.2,29.74],[13,8.71]],"id":52671542},{"atb":[[44,2.43],[27,9.38]],"id":52671545},{"atb":[[5.6,22.72],[4.6,67.75]],"id":52671544},{"atb":[[1.81,301.11],[1.91,247.1]],"id":52671555},{"atb":[[36,2.98],[23,11.08]],"id":52671554},{"atb":[[9.2,29.74],[13,8.71]],"id":52671556}],"con":true,"img":false}]}
{"op":"mcm","clk":"11450180538","pt":1717318894334,"mc":[{"id":"1.229554908","rc":[{"atb":[[1.18,133.02],[1.26,0]],"id":52671546}],"con":true,"img":false}]}
{"op":"mcm","clk":"11450180571","pt":1717318894646,"mc":[{"id":"1.229554908","rc":[{"atb":[[2.36,0],[2.18,79.81]],"id":52671546},{"atb":[[90,3.58],[95,0.55]],"id":52671545},{"atb":[[1.97,16.18],[1.93,0]],"id":52671555},{"atb":[[70,2],[75,4.35]],"id":52671554},{"atb":[[16,0],[16.5,3.45]],"id":52671556}],"con":true,"img":false}]}
{"op":"mcm","clk":"11450180701","pt":1717318895842,"mc":[{"id":"1.229554908","rc":[{"atb":[[2.32,0]],"id":52671546},{"atl":[[65,3],[70,0]],"id":52671548},{"atl":[[3.45,6.4],[3.5,0]],"id":52671555},{"atl":[[44,0],[46,3.3]],"id":52671556}],"con":true,"img":false}]}
{"op":"mcm","clk":"11450180897","pt":1717318897864,"mc":[{"id":"1.229554908","rc":[{"atb":[[1.18,0],[1.26,173.14]],"id":52671546}],"con":true,"img":false}]}
{"op":"mcm","clk":"11450180932","pt":1717318898199,"mc":[{"id":"1.229554908","rc":[{"atb":[[2.36,11.54]],"id":52671546},{"atb":[[90,0],[95,4.21]],"id":52671545},{"atb":[[1.97,0],[1.93,16.87]],"id":52671555},{"atb":[[70,4.97],[75,0]],"id":52671554},{"atb":[[16.5,0],[16,4.57]],"id":52671556}],"con":true,"img":false}]}
{"op":"mcm","clk":"11450181112","pt":1717318899946,"mc":[{"id":"1.229554908","rc":[{"atl":[[3.45,0],[3.5,6.27]],"id":52671555},{"atl":[[44,3.6],[46,0]],"id":52671556}],"con":true,"img":false}]}
{"op":"mcm","clk":"11450181121","pt":1717318900048,"mc":[{"id":"1.229554908","rc":[{"atl":[[65,0],[70,3.02]],"id":52671548}],"con":true,"img":false}]}
{"op":"mcm","clk":"11450181884","pt":1717318908172,"mc":[{"id":"1.229554908","rc":[{"atb":[[2.32,11.89]],"id":52671546}],"con":true,"img":false}]}
{"op":"mcm","clk":"11450182776","pt":1717318918164,"mc":[{"id":"1.229554908","rc":[{"atb":[[2.18,66.51]],"id":52671546}],"con":true,"img":false}]}
{"op":"mcm","clk":"11450197759","pt":1717319076383,"mc":[{"id":"1.229554908","rc":[{"atb":[[1.18,133.02],[1.26,0]],"id":52671546}],"con":true,"img":false}]}
{"op":"mcm","clk":"11450197782","pt":1717319076694,"mc":[{"id":"1.229554908","rc":[{"atb":[[2.36,0],[2.18,79.81]],"id":52671546},{"atb":[[260,0],[310,0],[360,0],[410,0]],"id":52671549},{"atb":[[90,4.2],[95,0.55]],"id":52671545},{"atb":[[2.02,0],[1.97,16.18],[2.12,0],[1.91,132.11],[1.96,0],[1.93,0]],"id":52671555},{"atb":[[70,2],[75,3.19]],"id":52671554},{"atb":[[16,0],[16.5,3.13]],"id":52671556}],"con":true,"img":false}]}
{"op":"mcm","clk":"11450197813","pt":1717319077012,"mc":[{"id":"1.229554908","rc":[{"atl":[[65,3.58],[70,0]],"id":52671548},{"atl":[[3.45,6.4],[3.5,0]],"id":52671555},{"atl":[[44,0],[46,2.66]],"id":52671556}],"con":true,"img":false}]}
{"op":"mcm","clk":"11450197847","pt":1717319077373,"mc":[{"id":"1.229554908","rc":[{"atb":[[260,0.4],[310,0.26],[360,0.15],[410,0.06]],"id":52671549},{"atb":[[2.02,51.29],[1.91,247.1],[2.12,23.35],[1.96,81.75]],"id":52671555}],"con":true,"img":false}]}
{"op":"mcm","clk":"11450197912","pt":1717319078204,"mc":[{"id":"1.229554908","rc":[{"atb":[[2.32,0]],"id":52671546},{"atl":[[70,3.85]],"id":52671548},{"atl":[[3.45,0],[3.5,6.27]],"id":52671555},{"atl":[[44,2.94],[46,0]],"id":52671556}],"con":true,"img":false}]}
{"op":"mcm","clk":"11450197921","pt":1717319078301,"mc":[{"id":"1.229554908","rc":[{"atl":[[65,0]],"id":52671548}],"con":true,"img":false}]}
{"op":"mcm","clk":"11450198088","pt":1717319080011,"mc":[{"id":"1.229554908","rc":[{"atb":[[2.36,11.54]],"id":52671546},{"atl":[[65,3.66],[70,0]],"id":52671548},{"atb":[[90,0],[95,3.65]],"id":52671545}],"con":true,"img":false}]}
{"op":"mcm","clk":"11450198162","pt":1717319080895,"mc":[{"id":"1.229554908","rc":[{"atl":[[65,0],[70,4.2]],"id":52671548}],"con":true,"img":false}]}
{"op":"mcm","clk":"11450198227","pt":1717319081616,"mc":[{"id":"1.229554908","rc":[{"atb":[[1.97,0],[1.93,16.87]],"id":52671555},{"atl":[[3.45,6.4],[3.5,0]],"id":52671555},{"atb":[[70,6.7],[75,0]],"id":52671554}],"con":true,"img":false}]}
{"op":"mcm","clk":"11450198276","pt":1717319082096,"mc":[{"id":"1.229554908","rc":[{"atb":[[2.36,0]],"id":52671546},{"atb":[[90,3.14]],"id":52671545}],"con":true,"img":false}]}
{"op":"mcm","clk":"11450198287","pt":1717319082196,"mc":[{"id":"1.229554908","rc":[{"atb":[[95,0.55]],"id":52671545}],"con":true,"img":false}]}
{"op":"mcm","clk":"11450198736","pt":1717319086839,"mc":[{"id":"1.229554908","rc":[{"atb":[[1.18,0],[1.26,173.14]],"id":52671546}],"con":true,"img":false}]}
{"op":"mcm","clk":"11450199039","pt":1717319090022,"mc":[{"id":"1.229554908","rc":[{"atb":[[2.36,11.54]],"id":52671546}],"con":true,"img":false}]}
{"op":"mcm","clk":"11450199214","pt":1717319091627,"mc":[{"id":"1.229554908","rc":[{"atl":[[3.45,0],[3.5,6.27]],"id":52671555}],"con":true,"img":false}]}
{"op":"mcm","clk":"11450199253","pt":1717319092101,"mc":[{"id":"1.229554908","rc":[{"atb":[[90,0],[95,3.88]],"id":52671545}],"con":true,"img":false}]}
{"op":"mcm","clk":"11450199306","pt":1717319092616,"mc":[{"id":"1.229554908","rc":[{"atb":[[16.5,0],[16,3.26]],"id":52671556}],"con":true,"img":false}]}
{"op":"mcm","clk":"11450200016","pt":1717319100027,"mc":[{"id":"1.229554908","rc":[{"atb":[[2.32,11.89]],"id":52671546}],"con":true,"img":false}]}
{"op":"mcm","clk":"11450201048","pt":1717319110023,"mc":[{"id":"1.229554908","rc":[{"atb":[[2.18,66.51]],"id":52671546}],"con":true,"img":false}]}
{"op":"mcm","clk":"11450208333","pt":1717319182607,"mc":[{"id":"1.229554908","rc":[{"atb":[[3.45,0],[3.95,0]],"id":52671550},{"atb":[[2.12,0],[1.96,0]],"id":52671546},{"atb":[[550,0],[650,0]],"id":52671549},{"atb":[[9,0],[12.5,0]],"id":52671548},{"atb":[[9.2,0],[13,0]],"id":52671542},{"atb":[[44,0],[27,0]],"id":52671545},{"atb":[[5.6,0],[4.6,0]],"id":52671544},{"atb":[[1.81,0],[1.91,132.23]],"id":52671555},{"atb":[[36,0],[23,0]],"id":52671554},{"atb":[[9.2,0],[13,0]],"id":52671556}],"con":true,"img":false}]}
{"op":"mcm","clk":"11450211546","pt":1717319214150,"mc":[{"id":"1.229554908","rc":[{"atb":[[3.45,99.55],[3.95,35.43]],"id":52671550},{"atb":[[2.12,93.32],[1.96,254.06]],"id":52671546},{"atb":[[550,0.44],[650,0.16]],"id":52671549},{"atb":[[9,30.48],[12.5,9.08]],"id":52671548},{"atb":[[9.2,29.74],[13,8.71]],"id":52671542},{"atb":[[44,2.43],[27,9.38]],"id":52671545},{"atb":[[5.6,22.72],[4.6,67.75]],"id":52671544},{"atb":[[1.81,301.11],[1.91,247.1]],"id":52671555},{"atb":[[36,2.98],[23,11.08]],"id":52671554},{"atb":[[9.2,29.74],[13,8.71]],"id":52671556}],"con":true,"img":false}]}
{"op":"mcm","clk":"11450216164","pt":1717319258670,"mc":[{"id":"1.229554908","rc":[{"atb":[[1.18,133.02],[1.26,0]],"id":52671546}],"con":true,"img":false}]}
{"op":"mcm","clk":"11450216200","pt":1717319258975,"mc":[{"id":"1.229554908","rc":[{"atb":[[2.36,0],[1.18,0],[1.26,133.02],[2.18,79.81]],"id":52671546},{"atb":[[260,0],[310,0],[360,0],[410,0]],"id":52671549},{"atb":[[90,2.86],[95,0.55]],"id":52671545},{"atb":[[2.02,0],[1.97,16.18],[2.12,0],[1.91,132.11],[1.96,0],[1.93,0]],"id":52671555},{"atb":[[70,2],[75,3.39]],"id":52671554},{"atb":[[16.5,4.16]],"id":52671556}],"con":true,"img":false}]}
{"op":"mcm","clk":"11450216209","pt":1717319259081,"mc":[{"id":"1.229554908","rc":[{"atb":[[16,0]],"id":52671556}],"con":true,"img":false}]}
{"op":"mcm","clk":"11450216228","pt":1717319259286,"mc":[{"id":"1.229554908","rc":[{"atl":[[65,2.84],[70,0]],"id":52671548},{"atl":[[3.45,6.4]],"id":52671555},{"atl":[[46,4.67]],"id":52671556}],"con":true,"img":false}]}
{"op":"mcm","clk":"11450216238","pt":1717319259391,"mc":[{"id":"1.229554908","rc":[{"atl":[[3.5,0]],"id":52671555},{"atl":[[44,0]],"id":52671556}],"con":true,"img":false}]}
{"op":"mcm","clk":"11450216250","pt":1717319259593,"mc":[{"id":"1.229554908","rc":[{"atb":[[1.18,173.14],[1.26,0]],"id":52671546}],"con":true,"img":false}]}
{"op":"mcm","clk":"11450216260","pt":1717319259696,"mc":[{"id":"1.229554908","rc":[{"atb":[[260,0.4],[310,0.26],[360,0.15],[410,0.06]],"id":52671549},{"atb":[[2.02,51.29],[1.91,247.1],[2.12,23.35],[1.96,81.75]],"id":52671555}],"con":true,"img":false}]}
{"op":"mcm","clk":"11450216285","pt":1717319259865,"mc":[{"id":"1.229554908","rc":[{"atb":[[2.32,0]],"id":52671546}],"con":true,"img":false}]}
{"op":"mcm","clk":"11450216409","pt":1717319261003,"mc":[{"id":"1.229554908","rc":[{"atb":[[1.18,0],[1.26,173.14]],"id":52671546}],"con":true,"img":false}]}
{"op":"mcm","clk":"11450216435","pt":1717319261264,"mc":[{"id":"1.229554908","rc":[{"atb":[[2.36,11.54]],"id":52671546},{"atb":[[90,0],[95,5.09]],"id":52671545},{"atb":[[1.97,0],[1.93,16.87]],"id":52671555},{"atb":[[70,5.04],[75,0]],"id":52671554},{"atb":[[16.5,0],[16,2.85]],"id":52671556}],"con":true,"img":false}]}
{"op":"mcm","clk":"11450216456","pt":1717319261470,"mc":[{"id":"1.229554908","rc":[{"atb":[[1.18,173.14]],"id":52671546}],"con":true,"img":false}]}
{"op":"mcm","clk":"11450216474","pt":1717319261577,"mc":[{"id":"1.229554908","rc":[{"atb":[[1.26,0]],"id":52671546}],"con":true,"img":false}]}
{"op":"mcm","clk":"11450216495","pt":1717319261785,"mc":[{"id":"1.229554908","rc":[{"atl":[[65,0],[70,2.85]],"id":52671548},{"atb":[[2.02,0],[2.12,0],[1.91,132.11],[1.96,0]],"id":52671555}],"con":true,"img":false}]}
{"op":"mcm","clk":"11450216576","pt":1717319262581,"mc":[{"id":"1.229554908","rc":[{"atb":[[2.06,49.36],[1.98,80.08],[1.93,129.39],[2.16,22.55]],"id":52671555}],"con":true,"img":false}]}
{"op":"mcm","clk":"11450216610","pt":1717319262892,"mc":[{"id":"1.229554908","rc":[{"atb":[[260,0],[310,0],[360,0],[410,0]],"id":52671549},{"atl":[[65,3.06],[70,0]],"id":52671548}],"con":true,"img":false}]}
{"op":"mcm","clk":"11450216656","pt":1717319263263,"mc":[{"id":"1.229554908","rc":[{"atb":[[2.06,0],[1.98,0],[1.93,16.87],[2.16,0]],"id":52671555}],"con":true,"img":false}]}
{"op":"mcm","clk":"11450216689","pt":1717319263570,"mc":[{"id":"1.229554908","rc":[{"atb":[[260,0.4],[310,0.26],[360,0.15],[410,0.06]],"id":52671549}],"con":true,"img":false}]}
{"op":"mcm","clk":"11450216728","pt":1717319263978,"mc":[{"id":"1.229554908","rc":[{"atb":[[2.02,51.29],[1.91,247.1],[2.12,23.35],[1.96,81.75]],"id":52671555}],"con":true,"img":false}]}
{"op":"mcm","clk":"11450217360","pt":1717319269998,"mc":[{"id":"1.229554908","rc":[{"atb":[[1.18,0],[1.26,173.14]],"id":52671546}],"con":true,"img":false}]}
{"op":"mcm","clk":"11450217485","pt":1717319271293,"mc":[{"id":"1.229554908","rc":[{"atb":[[2.32,11.89]],"id":52671546}],"con":true,"img":false}]}
{"op":"mcm","clk":"11450217531","pt":1717319271809,"mc":[{"id":"1.229554908","rc":[{"atl":[[3.45,0],[3.5,6.27]],"id":52671555},{"atl":[[44,4.29],[46,0]],"id":52671556}],"con":true,"img":false}]}
{"op":"mcm","clk":"11450217625","pt":1717319272899,"mc":[{"id":"1.229554908","rc":[{"atl":[[65,0],[70,3.36]],"id":52671548}],"con":true,"img":false}]}
{"op":"mcm","clk":"11450218456","pt":1717319281399,"mc":[{"id":"1.229554908","rc":[{"atb":[[2.18,66.51]],"id":52671546}],"con":true,"img":false}]}
{"op":"mcm","clk":"11450228413","pt":1717319388717,"mc":[{"id":"1.229554908","rc":[{"atb":[[3.45,0],[3.95,0]],"id":52671550},{"atb":[[2.12,0],[1.96,0]],"id":52671546},{"atb":[[550,0],[650,0]],"id":52671549},{"atb":[[9,0],[12.5,0]],"id":52671548},{"atb":[[9.2,0],[13,0]],"id":52671542},{"atb":[[44,0],[27,0]],"id":52671545},{"atb":[[5.6,0],[4.6,0]],"id":52671544},{"atb":[[1.81,0],[1.91,132.23]],"id":52671555},{"atb":[[36,0],[23,0]],"id":52671554},{"atb":[[9.2,0],[13,0]],"id":52671556}],"con":true,"img":false}]}
{"op":"mcm","clk":"11450230358","pt":1717319410122,"mc":[{"id":"1.229554908","rc":[{"atb":[[2.12,93.32],[1.96,254.06]],"id":52671546},{"atb":[[9,30.48],[12.5,9.08]],"id":52671548},{"atb":[[9.2,29.74],[13,8.71]],"id":52671542},{"atb":[[44,2.43],[27,9.38]],"id":52671545},{"atb":[[5.6,22.72],[4.6,67.75]],"id":52671544}],"con":true,"img":false}]}
{"op":"mcm","clk":"11450230365","pt":1717319410226,"mc":[{"id":"1.229554908","rc":[{"atb":[[3.45,99.55],[3.95,35.43]],"id":52671550},{"atb":[[550,0.44],[650,0.16]],"id":52671549},{"atb":[[1.81,301.11],[1.91,247.1]],"id":52671555},{"atb":[[36,2.98],[23,11.08]],"id":52671554},{"atb":[[9.2,29.74],[13,8.71]],"id":52671556}],"con":true,"img":false}]}
{"op":"mcm","clk":"11450232863","pt":1717319436442,"mc":[{"id":"1.229554908","rc":[{"atb":[[1.18,133.02],[1.26,0]],"id":52671546}],"con":true,"img":false}]}
{"op":"mcm","clk":"11450232893","pt":1717319436754,"mc":[{"id":"1.229554908","rc":[{"atb":[[2.36,0],[2.18,79.81]],"id":52671546},{"atb":[[260,0],[310,0],[360,0],[410,0]],"id":52671549},{"atb":[[90,3.4],[95,0.55]],"id":52671545},{"atb":[[1.97,16.18],[1.93,0]],"id":52671555},{"atb":[[70,2],[75,3.39]],"id":52671554},{"atb":[[16,0],[16.5,2.91]],"id":52671556}],"con":true,"img":false}]}
{"op":"mcm","clk":"11450232903","pt":1717319436863,"mc":[{"id":"1.229554908","rc":[{"atb":[[2.02,0],[2.12,0],[1.91,132.11],[1.96,0]],"id":52671555}],"con":true,"img":false}]}
{"op":"mcm","clk":"11450232911","pt":1717319436961,"mc":[{"id":"1.229554908","rc":[{"atl":[[65,4.34],[70,0]],"id":52671548},{"atl":[[3.45,6.4],[3.5,0]],"id":52671555},{"atl":[[44,0],[46,2.99]],"id":52671556}],"con":true,"img":false}]}
{"op":"mcm","clk":"11450232939","pt":1717319437276,"mc":[{"id":"1.229554908","rc":[{"atb":[[1.18,0],[1.26,159.62]],"id":52671546}],"con":true,"img":false}]}
{"op":"mcm","clk":"11450232955","pt":1717319437475,"mc":[{"id":"1.229554908","rc":[{"atb":[[280,0.38],[330,0.24],[380,0.14],[430,0.06]],"id":52671549}],"con":true,"img":false}]}
{"op":"mcm","clk":"11450232966","pt":1717319437580,"mc":[{"id":"1.229554908","rc":[{"atb":[[2.36,11.54],[2.32,0]],"id":52671546},{"atb":[[90,0],[95,3.82]],"id":52671545},{"atb":[[1.97,0],[1.93,16.87]],"id":52671555},{"atb":[[70,6.57],[75,0]],"id":52671554},{"atb":[[16.5,0],[16,3.45]],"id":52671556}],"con":true,"img":false}]}
{"op":"mcm","clk":"11450232977","pt":1717319437649,"mc":[{"id":"1.229554908","rc":[{"atb":[[2.02,51.29],[1.91,247.1],[2.12,23.35],[1.96,81.75]],"id":52671555}],"con":true,"img":false}]}
{"op":"mcm","clk":"11450233036","pt":1717319438366,"mc":[{"id":"1.229554908","rc":[{"atb":[[280,0],[330,0],[380,0],[430,0]],"id":52671549}],"con":true,"img":false}]}
{"op":"mcm","clk":"11450233079","pt":1717319438776,"mc":[{"id":"1.229554908","rc":[{"atb":[[1.18,173.14],[1.26,0]],"id":52671546}],"con":true,"img":false}]}
{"op":"mcm","clk":"11450233104","pt":1717319439087,"mc":[{"id":"1.229554908","rc":[{"atb":[[2.36,0]],"id":52671546},{"atb":[[280,0.38],[330,0.24],[380,0.14],[430,0.06]],"id":52671549},{"atl":[[65,0],[70,3.36]],"id":52671548},{"atb":[[90,3.16],[95,0.55]],"id":52671545},{"atb":[[2.02,0],[1.97,16.18],[2.12,0],[1.91,132.11],[1.96,0],[1.93,0]],"id":52671555},{"atl":[[3.45,0],[3.5,6.27]],"id":52671555},{"atb":[[70,2],[75,3.7]],"id":52671554},{"atb":[[16,0],[16.5,4.16]],"id":52671556},{"atl":[[44,3.25],[46,0]],"id":52671556}],"con":true,"img":false}]}
{"op":"mcm","clk":"11450233168","pt":1717319439767,"mc":[{"id":"1.229554908","rc":[{"atb":[[2.06,49.36],[1.98,80.08],[1.93,112.51],[2.16,22.55]],"id":52671555}],"con":true,"img":false}]}
{"op":"mcm","clk":"11450233197","pt":1717319440074,"mc":[{"id":"1.229554908","rc":[{"atb":[[2.36,11.54]],"id":52671546},{"atl":[[65,4.13],[70,0]],"id":52671548},{"atb":[[90,0],[95,3.41]],"id":52671545},{"atb":[[1.97,0],[1.93,129.39]],"id":52671555},{"atl":[[3.45,6.4],[3.5,0]],"id":52671555},{"atb":[[70,5.36],[75,0]],"id":52671554},{"atb":[[16.5,0],[16,4.14]],"id":52671556},{"atl":[[44,0],[46,3.54]],"id":52671556}],"con":true,"img":false}]}
{"op":"mcm","clk":"11450233584","pt":1717319443796,"mc":[{"id":"1.229554908","rc":[{"atl":[[65,0],[70,4.56]],"id":52671548},{"atl":[[3.45,0],[3.5,6.27]],"id":52671555},{"atl":[[44,3.92],[46,0]],"id":52671556}],"con":true,"img":false}]}
{"op":"mcm","clk":"11450233670","pt":1717319444751,"mc":[{"id":"1.229554908","rc":[{"atb":[[280,0],[330,0],[380,0],[430,0]],"id":52671549}],"con":true,"img":false}]}
{"op":"mcm","clk":"11450233746","pt":1717319445481,"mc":[{"id":"1.229554908","rc":[{"atb":[[1.18,0],[1.26,173.14]],"id":52671546},{"atb":[[260,0.4],[310,0.26],[360,0.15],[410,0.06]],"id":52671549},{"atb":[[2.06,0],[1.98,0],[1.93,16.87],[2.16,0]],"id":52671555}],"con":true,"img":false}]}
{"op":"mcm","clk":"11450233818","pt":1717319446163,"mc":[{"id":"1.229554908","rc":[{"atb":[[1.91,247.1],[2.12,23.35]],"id":52671555}],"con":true,"img":false}]}
{"op":"mcm","clk":"11450233826","pt":1717319446267,"mc":[{"id":"1.229554908","rc":[{"atb":[[2.02,51.29],[1.96,81.75]],"id":52671555}],"con":true,"img":false}]}
{"op":"mcm","clk":"11450234217","pt":1717319450686,"mc":[{"id":"1.229554908","rc":[{"atb":[[2.32,11.89]],"id":52671546}],"con":true,"img":false}]}
{"op":"mcm","clk":"11450234666","pt":1717319455092,"mc":[{"id":"1.229554908","rc":[{"atb":[[1.26,0],[1.17,159.62]],"id":52671546}],"con":true,"img":false}]}
{"op":"mcm","clk":"11450234699","pt":1717319455358,"mc":[{"id":"1.229554908","rc":[{"atb":[[70,2]],"id":52671554}],"con":true,"img":false}]}
{"op":"mcm","clk":"11450234845","pt":1717319456874,"mc":[{"id":"1.229554908","rc":[{"atb":[[2.16,13.52]],"id":52671546}],"con":true,"img":false}]}
{"op":"mcm","clk":"11450234862","pt":1717319457083,"mc":[{"id":"1.229554908","rc":[{"atb":[[2.36,0],[2.32,0],[2.18,66.51]],"id":52671546},{"atb":[[95,0.55],[100,3.34]],"id":52671545},{"atb":[[2,15.69],[1.93,0]],"id":52671555},{"atb":[[90,3.82]],"id":52671554},{"atb":[[18,4.3]],"id":52671556}],"con":true,"img":false}]}
{"op":"mcm","clk":"11450234933","pt":1717319457806,"mc":[{"id":"1.229554908","rc":[{"atb":[[16,0]],"id":52671556}],"con":true,"img":false}]}
{"op":"mcm","clk":"11450235656","pt":1717319465485,"mc":[{"id":"1.229554908","rc":[{"atb":[[2.12,107.34]],"id":52671546},{"atb":[[1.98,16.01]],"id":52671555},{"atl":[[3.45,6.4],[3.5,0]],"id":52671555},{"atb":[[80,3.89]],"id":52671554},{"atl":[[310,0],[320,3.56]],"id":52671554},{"atb":[[17,4.32]],"id":52671556}],"con":true,"img":false}]}
{"op":"mcm","clk":"11450236527","pt":1717319475467,"mc":[{"id":"1.229554908","rc":[{"atb":[[1.91,229.85]],"id":52671555},{"atb":[[60,0]],"id":52671554},{"atl":[[310,3.59],[320,0]],"id":52671554},{"atb":[[15,7.48]],"id":52671556},{"atl":[[44,0],[46,4.13]],"id":52671556}],"con":true,"img":false}]}
{"op":"mcm","clk":"11450236608","pt":1717319476288,"mc":[{"id":"1.229554908","rc":[{"atb":[[1.26,159.62],[1.17,0]],"id":52671546}],"con":true,"img":false}]}
{"op":"mcm","clk":"11450236637","pt":1717319476602,"mc":[{"id":"1.229554908","rc":[{"atb":[[2.36,11.54],[2.16,0]],"id":52671546},{"atl":[[65,3.27],[70,0]],"id":52671548},{"atb":[[95,5.26],[100,0]],"id":52671545},{"atb":[[2,0],[1.93,16.87]],"id":52671555},{"atb":[[70,6.27],[90,0.59]],"id":52671554},{"atb":[[16,4.67],[18,0]],"id":52671556}],"con":true,"img":false}]}
{"op":"mcm","clk":"11450236660","pt":1717319476902,"mc":[{"id":"1.229554908","rc":[{"atl":[[42,3.95]],"id":52671556}],"con":true,"img":false}]}
{"op":"mcm","clk":"11450236696","pt":1717319477311,"mc":[{"id":"1.229554908","rc":[{"atl":[[46,0]],"id":52671556}],"con":true,"img":false}]}
{"op":"mcm","clk":"11450236713","pt":1717319477522,"mc":[{"id":"1.229554908","rc":[{"atb":[[1.98,0]],"id":52671555},{"atb":[[80,0]],"id":52671554},{"atb":[[17,0]],"id":52671556}],"con":true,"img":false}]}
{"op":"mcm","clk":"11450237486","pt":1717319486524,"mc":[{"id":"1.229554908","rc":[{"atb":[[2.32,11.89]],"id":52671546},{"atb":[[1.91,247.1]],"id":52671555},{"atb":[[60,2.72]],"id":52671554}],"con":true,"img":false}]}
{"op":"mcm","clk":"11450237708","pt":1717319488808,"mc":[{"id":"1.229554908","rc":[{"atb":[[15,10.77]],"id":52671556}],"con":true,"img":false}]}
{"op":"mcm","clk":"11450238194","pt":1717319494035,"mc":[{"id":"1.229554908","rc":[{"atb":[[1.26,0]],"id":52671546}],"con":true,"img":false}]}
{"op":"mcm","clk":"11450238204","pt":1717319494140,"mc":[{"id":"1.229554908","rc":[{"atb":[[1.18,133.02]],"id":52671546}],"con":true,"img":false}]}
{"op":"mcm","clk":"11450238714","pt":1717319500344,"mc":[{"id":"1.229554908","rc":[{"atb":[[1.18,0],[1.26,133.02]],"id":52671546}],"con":true,"img":false}]}
{"op":"mcm","clk":"11450239989","pt":1717319514256,"mc":[{"id":"1.229554908","rc":[{"atb":[[2.12,93.32]],"id":52671546}],"con":true,"img":false}]}
{"op":"mcm","clk":"11450242243","pt":1717319537826,"mc":[{"id":"1.229554908","rc":[{"atl":[[65,0],[70,4.7]],"id":52671548},{"atl":[[3.45,0],[3.5,6.27]],"id":52671555},{"atl":[[42,0],[44,2.66]],"id":52671556}],"con":true,"img":false}]}
{"op":"mcm","clk":"11450244928","pt":1717319566413,"mc":[{"id":"1.229554908","rc":[{"atl":[[23,0],[14,7.69]],"id":52671550},{"atb":[[2.4,11.89],[1.26,0]],"id":52671546},{"atl":[[9,0],[27,3.85]],"id":52671546},{"atb":[[46,2],[200,0]],"id":52671549},{"atb":[[3.6,18.18],[14,0]],"id":52671548},{"atl":[[65,2]],"id":52671548},{"atl":[[80,4.79]],"id":52671542},{"atb":[[75,0],[46,2.22]],"id":52671545},{"atb":[[4.3,0],[3.4,21.8]],"id":52671544},{"atl":[[21,3.36],[55,0]],"id":52671544},{"atb":[[2,81.75],[1.05,0]],"id":52671555},{"atl":[[4,12.32],[7.6,0]],"id":52671555},{"atb":[[70,4.27],[13,5.06]],"id":52671554},{"atl":[[310,5.59]],"id":52671554},{"atb":[[20,7.43],[12,0]],"id":52671556},{"atl":[[390,2]],"id":52671556}],"con":true,"img":false}]}
{"op":"mcm","clk":"11450244947","pt":1717319566580,"mc":[{"id":"1.229554908","rc":[{"atb":[[2.36,0],[2.34,11.71]],"id":52671546},{"atb":[[260,0],[310,0],[360,0],[410,0]],"id":52671549},{"atl":[[80,2.79],[85,2]],"id":52671542},{"atb":[[95,0.55],[100,4.56]],"id":52671545},{"atb":[[1.92,17.06]],"id":52671555},{"atb":[[70,0],[80,3.81]],"id":52671554},{"atb":[[16,0],[17.5,9.45]],"id":52671556}],"con":true,"img":false}]}
{"op":"mcm","clk":"11450244959","pt":1717319566682,"mc":[{"id":"1.229554908","rc":[{"atb":[[5.5,5]],"id":52671550},{"atl":[[8.6,5]],"id":52671550},{"atb":[[3.15,5]],"id":52671546},{"atl":[[13,5]],"id":52671546},{"atb":[[150,5]],"id":52671545},{"atb":[[1.93,0]],"id":52671555}],"con":true,"img":false}]}
{"op":"mcm","clk":"11450244969","pt":1717319566781,"mc":[{"id":"1.229554908","rc":[{"atl":[[10,14.4]],"id":52671550},{"atb":[[2.4,40.75]],"id":52671546},{"atl":[[4.3,0],[4.5,0],[13,8.59]],"id":52671546},{"atb":[[170,0]],"id":52671549},{"atl":[[1000,0.16]],"id":52671549},{"atb":[[16.5,0],[17.5,0]],"id":52671548},{"atl":[[34,5],[75,2.16]],"id":52671548},{"atb":[[14,5]],"id":52671542},{"atl":[[75,2.16],[80,0],[40,5],[85,6.28]],"id":52671542},{"atb":[[150,6.08]],"id":52671545},{"atl":[[390,1.49],[450,4.39]],"id":52671545},{"atb":[[7.2,0],[9.2,0],[10.5,0],[8.2,0]],"id":52671544},{"atl":[[21,11.36],[22,0],[14.5,5]],"id":52671544},{"atb":[[2.12,67.87],[2.48,5]],"id":52671555},{"atl":[[3.6,50.55],[3.35,5]],"id":52671555},{"atb":[[130,0],[65,0],[90,0],[46,0],[60,0]],"id":52671554},{"atl":[[150,5],[300,0.53]],"id":52671554},{"atb":[[25,12.77]],"id":52671556},{"atl":[[130,3.1],[44,0],[48,0],[120,5]],"id":52671556}],"con":true,"img":false}]}
{"op":"mcm","clk":"11450244979","pt":1717319566886,"mc":[{"id":"1.229554908","rc":[{"atb":[[2.4,28.86],[2.68,11.89]],"id":52671546},{"atl":[[65,0],[32,3.23]],"id":52671548},{"atl":[[21,8],[14,5.01]],"id":52671544}],"con":true,"img":false}]}
{"op":"mcm","clk":"11450244998","pt":1717319567092,"mc":[{"id":"1.229554908","rc":[{"atb":[[160,5]],"id":52671549}],"con":true,"img":false}]}
{"op":"mcm","clk":"11450245016","pt":1717319567298,"mc":[{"id":"1.229554908","rc":[{"atl":[[13,21.94]],"id":52671546},{"atb":[[300,0.17],[350,0.07],[200,0.53],[250,0.31]],"id":52671549},{"atl":[[120,6.35]],"id":52671556}],"con":true,"img":false}]}
{"op":"mcm","clk":"11450245066","pt":1717319567767,"mc":[{"id":"1.229554908","rc":[{"atl":[[24,0]],"id":52671544},{"atb":[[1.92,0]],"id":52671555},{"atb":[[80,0]],"id":52671554}],"con":true,"img":false}]}
{"op":"mcm","clk":"11450245085","pt":1717319568023,"mc":[{"id":"1.229554908","rc":[{"atb":[[6,5]],"id":52671548},{"atl":[[40,0],[42,5]],"id":52671542},{"atb":[[5.2,12.46],[4.9,5],[5.7,5.57],[4.2,37.61],[4.7,28.73]],"id":52671544},{"atl":[[14.5,0],[15.5,5]],"id":52671544},{"atb":[[70,0.38],[38,7.13],[48,1.11],[29,3.74]],"id":52671554},{"atb":[[24,5],[25,1.09]],"id":52671556}],"con":true,"img":false}]}
{"op":"mcm","clk":"11450245109","pt":1717319568280,"mc":[{"id":"1.229554908","rc":[{"atb":[[38,11.46]],"id":52671554}],"con":true,"img":false}]}
{"op":"mcm","clk":"11450245147","pt":1717319568694,"mc":[{"id":"1.229554908","rc":[{"atl":[[410,0]],"id":52671545},{"atb":[[1.92,17.06]],"id":52671555}],"con":true,"img":false}]}
{"op":"mcm","clk":"11450245157","pt":1717319568795,"mc":[{"id":"1.229554908","rc":[{"atb":[[34,3.32],[38,15.12]],"id":52671554},{"atb":[[24,11.97]],"id":52671556}],"con":true,"img":false}]}
{"op":"mcm","clk":"11450245196","pt":1717319569165,"mc":[{"id":"1.229554908","rc":[{"atl":[[24,4.23],[26,3.07]],"id":52671544}],"con":true,"img":false}]}
{"op":"mcm","clk":"11450245291","pt":1717319570296,"mc":[{"id":"1.229554908","rc":[{"atl":[[16,5],[15.5,0]],"id":52671544}],"con":true,"img":false}]}
{"op":"mcm","clk":"11450245318","pt":1717319570603,"mc":[{"id":"1.229554908","rc":[{"atb":[[23,5],[24,0]],"id":52671556}],"con":true,"img":false}]}
{"op":"mcm","clk":"11450245455","pt":1717319572000,"mc":[{"id":"1.229554908","rc":[{"atl":[[70,2]],"id":52671542},{"atl":[[14,0],[15.5,6.9]],"id":52671544}],"con":true,"img":false}]}
{"op":"mcm","clk":"11450245463","pt":1717319572103,"mc":[{"id":"1.229554908","rc":[{"atl":[[85,4.28]],"id":52671542}],"con":true,"img":false}]}
{"op":"mcm","clk":"11450245722","pt":1717319574905,"mc":[{"id":"1.229554908","rc":[{"atl":[[14,4.68]],"id":52671546},{"atl":[[470,2.88]],"id":52671545},{"atb":[[16.5,2.65]],"id":52671556},{"atl":[[150,3.02]],"id":52671556}],"con":true,"img":false}]}
{"op":"mcm","clk":"11450246146","pt":1717319579591,"mc":[{"id":"1.229554908","rc":[{"atl":[[8.6,20.1]],"id":52671550},{"atb":[[3.2,25.38]],"id":52671546},{"atl":[[42,8.91]],"id":52671542},{"atl":[[15.5,17.94]],"id":52671544},{"atl":[[3.35,73.18]],"id":52671555}],"con":true,"img":false}]}
{"op":"mcm","clk":"11450246158","pt":1717319579697,"mc":[{"id":"1.229554908","rc":[{"atb":[[2.48,87.23]],"id":52671555},{"atl":[[150,6.08]],"id":52671554}],"con":true,"img":false}]}
{"op":"mcm","clk":"11450246214","pt":1717319580320,"mc":[{"id":"1.229554908","rc":[{"atl":[[10,0]],"id":52671550},{"atb":[[2.4,0]],"id":52671546},{"atl":[[75,0]],"id":52671542},{"atl":[[21,0]],"id":52671544},{"atl":[[3.6,6.03]],"id":52671555}],"con":true,"img":false}]}
{"op":"mcm","clk":"11450246224","pt":1717319580426,"mc":[{"id":"1.229554908","rc":[{"atb":[[2.12,23.35]],"id":52671555},{"atl":[[300,0]],"id":52671554}],"con":true,"img":false}]}
{"op":"mcm","clk":"11450246355","pt":1717319581930,"mc":[{"id":"1.229554908","rc":[{"atb":[[15,7.48]],"id":52671556}],"con":true,"img":false}]}
{"op":"mcm","clk":"11450246413","pt":1717319582512,"mc":[{"id":"1.229554908","rc":[{"atb":[[3.45,0],[3.95,0]],"id":52671550},{"atb":[[2.12,0],[1.96,0]],"id":52671546},{"atb":[[550,0],[650,0]],"id":52671549},{"atb":[[9,0],[12.5,0]],"id":52671548},{"atb":[[9.2,0],[13,0]],"id":52671542},{"atb":[[44,0],[27,0]],"id":52671545},{"atb":[[5.6,0],[4.6,0]],"id":52671544},{"atb":[[1.81,0],[1.91,132.23]],"id":52671555},{"atb":[[36,0],[23,0]],"id":52671554},{"atb":[[9.2,0],[13,0]],"id":52671556}],"con":true,"img":false}]}
{"op":"mcm","clk":"11450246480","pt":1717319583006,"mc":[{"id":"1.229554908","rc":[{"atb":[[6,20.05]],"id":52671548}],"con":true,"img":false}]}
{"op":"mcm","clk":"11450246904","pt":1717319587723,"mc":[{"id":"1.229554908","rc":[{"atb":[[2.36,11.54],[2.34,0]],"id":52671546},{"atb":[[160,8.56]],"id":52671549},{"atb":[[5.8,3.1],[6,24.4]],"id":52671548},{"atb":[[95,3.21],[100,0]],"id":52671545},{"atb":[[1.92,0],[1.93,16.87]],"id":52671555},{"atb":[[16,2.97],[17.5,4.76]],"id":52671556}],"con":true,"img":false}]}
{"op":"mcm","clk":"11450247110","pt":1717319590157,"mc":[{"id":"1.229554908","rc":[{"atb":[[16.5,0]],"id":52671556}],"con":true,"img":false}]}
{"op":"mcm","clk":"11450247605","pt":1717319595636,"mc":[{"id":"1.229554908","rc":[{"atb":[[3.45,99.55],[3.95,35.43]],"id":52671550},{"atb":[[2.12,93.32],[1.96,254.06]],"id":52671546},{"atb":[[550,0.44],[650,0.16]],"id":52671549},{"atb":[[9,30.48],[12.5,9.08]],"id":52671548},{"atb":[[9.2,29.74],[13,8.71]],"id":52671542},{"atb":[[44,2.43],[27,9.38]],"id":52671545},{"atb":[[5.6,22.72],[4.6,67.75]],"id":52671544},{"atb":[[1.81,301.11],[1.91,247.1]],"id":52671555},{"atb":[[36,2.98],[23,11.08]],"id":52671554},{"atb":[[9.2,29.74],[13,8.71],[15,11.68]],"id":52671556}],"con":true,"img":false}]}
{"op":"mcm","clk":"11450247697","pt":1717319596519,"mc":[{"id":"1.229554908","rc":[{"atb":[[2.36,0],[2.34,11.71]],"id":52671546},{"atb":[[1.93,0]],"id":52671555},{"atl":[[310,2]],"id":52671554}],"con":true,"img":false}]}
{"op":"mcm","clk":"11450247893","pt":1717319598827,"mc":[{"id":"1.229554908","rc":[{"atl":[[32,0],[34,8.03]],"id":52671548}],"con":true,"img":false}]}
{"op":"mcm","clk":"11450247921","pt":1717319599235,"mc":[{"id":"1.229554908","rc":[{"atl":[[34,12.89]],"id":52671548}],"con":true,"img":false}]}
{"op":"mcm","clk":"11450247981","pt":1717319599910,"mc":[{"id":"1.229554908","rc":[{"atl":[[75,0]],"id":52671548}],"con":true,"img":false}]}
{"op":"mcm","clk":"11450248016","pt":1717319600425,"mc":[{"id":"1.229554908","rc":[{"atl":[[85,0],[100,3.68]],"id":52671542},{"atl":[[350,4.45]],"id":52671554}],"con":true,"img":false}]}
{"op":"mcm","clk":"11450248020","pt":1717319600525,"mc":[{"id":"1.229554908","rc":[{"atb":[[2.36,11.54],[2.34,0]],"id":52671546},{"atl":[[70,0],[75,4.25]],"id":52671548},{"atb":[[1.93,16.87]],"id":52671555},{"atl":[[3.4,6.53],[3.5,0]],"id":52671555}],"con":true,"img":false}]}
{"op":"mcm","clk":"11450248341","pt":1717319604507,"mc":[{"id":"1.229554908","rc":[{"atl":[[70,4.63],[75,0]],"id":52671548},{"atl":[[90,0],[95,3.39]],"id":52671542},{"atl":[[23,3.51],[24,0]],"id":52671544},{"atl":[[3.4,0],[3.3,6.82]],"id":52671555}],"con":true,"img":false}]}
{"op":"mcm","clk":"11450248369","pt":1717319605027,"mc":[{"id":"1.229554908","rc":[{"atl":[[3.25,71.2]],"id":52671555}],"con":true,"img":false}]}
{"op":"mcm","clk":"11450248437","pt":1717319605846,"mc":[{"id":"1.229554908","rc":[{"atl":[[3.35,5]],"id":52671555}],"con":true,"img":false}]}
{"op":"mcm","clk":"11450248631","pt":1717319607822,"mc":[{"id":"1.229554908","rc":[{"atl":[[42,0],[44,5]],"id":52671542},{"atl":[[15.5,6.9]],"id":52671544}],"con":true,"img":false}]}
{"op":"mcm","clk":"11450248692","pt":1717319608544,"mc":[{"id":"1.229554908","rc":[{"atl":[[65,2.5]],"id":52671542},{"atl":[[16,15.69]],"id":52671544}],"con":true,"img":false}]}
{"op":"mcm","clk":"11450249012","pt":1717319612118,"mc":[{"id":"1.229554908","rc":[{"atl":[[3.4,6.53]],"id":52671555}],"con":true,"img":false}]}
{"op":"mcm","clk":"11450249315","pt":1717319615736,"mc":[{"id":"1.229554908","rc":[{"atb":[[16,11.79]],"id":52671542},{"atl":[[90,4.6],[95,0]],"id":52671542},{"atl":[[23,0],[24,2.64]],"id":52671544},{"atl":[[3.6,0]],"id":52671555}],"con":true,"img":false}]}
{"op":"mcm","clk":"11450249415","pt":1717319616952,"mc":[{"id":"1.229554908","rc":[{"atb":[[3.6,0],[3.1,36.36]],"id":52671548},{"atb":[[13,0]],"id":52671554},{"atl":[[310,0],[240,2]],"id":52671554}],"con":true,"img":false}]}
{"op":"mcm","clk":"11450249421","pt":1717319617035,"mc":[{"id":"1.229554908","rc":[{"atb":[[10.5,7.07]],"id":52671554}],"con":true,"img":false}]}
{"op":"mcm","clk":"11450249454","pt":1717319617342,"mc":[{"id":"1.229554908","rc":[{"atl":[[13,18.35],[13.5,4.23]],"id":52671546},{"atb":[[300,0],[150,0],[160,5],[350,0],[200,0],[250,0]],"id":52671549},{"atb":[[5.8,0],[6,0]],"id":52671548},{"atl":[[360,5],[420,3.88],[450,0]],"id":52671545},{"atb":[[5.2,0],[5.7,0],[4.2,4.9],[4.7,7.52]],"id":52671544},{"atl":[[3.45,6.4],[3.3,0]],"id":52671555},{"atb":[[32,3.84],[70,0],[38,4.33],[48,0],[29,0]],"id":52671554},{"atl":[[130,8.11],[120,1.34]],"id":52671556}],"con":true,"img":false}]}
{"op":"mcm","clk":"11450249504","pt":1717319617856,"mc":[{"id":"1.229554908","rc":[{"atb":[[5,5]],"id":52671548},{"atl":[[350,0.46]],"id":52671545},{"atb":[[32,8.85]],"id":52671554}],"con":true,"img":false}]}
{"op":"mcm","clk":"11450249511","pt":1717319617953,"mc":[{"id":"1.229554908","rc":[{"atb":[[6.2,20.13]],"id":52671550}],"con":true,"img":false}]}
{"op":"mcm","clk":"11450249517","pt":1717319618058,"mc":[{"id":"1.229554908","rc":[{"atb":[[130,0.81],[280,0.09],[180,0.44],[230,0.23]],"id":52671549},{"atb":[[4.9,25.13],[4.4,34.62],[5.9,5.34],[5.4,11.89]],"id":52671544},{"atb":[[32,11.38],[42,1.28],[26,4.19],[55,0.49]],"id":52671554}],"con":true,"img":false}]}
{"op":"mcm","clk":"11450249526","pt":1717319618161,"mc":[{"id":"1.229554908","rc":[{"atl":[[3.4,0]],"id":52671555},{"atb":[[34,0]],"id":52671554}],"con":true,"img":false}]}
{"op":"mcm","clk":"11450249533","pt":1717319618265,"mc":[{"id":"1.229554908","rc":[{"atb":[[2.16,86.21]],"id":52671550},{"atb":[[8.6,2],[46,0]],"id":52671549},{"atb":[[8.6,4.86]],"id":52671545}],"con":true,"img":false}]}
{"op":"mcm","clk":"11450249542","pt":1717319618325,"mc":[{"id":"1.229554908","rc":[{"atb":[[5.8,5],[1.08,0]],"id":52671550},{"atb":[[3.35,5],[3.15,0]],"id":52671546},{"atb":[[14,0]],"id":52671542},{"atb":[[46,0]],"id":52671545},{"atl":[[16,10.68],[15.5,11.9]],"id":52671544},{"atb":[[2.58,5],[2.48,82.23]],"id":52671555},{"atb":[[23,0],[24,5]],"id":52671556}],"con":true,"img":false}]}
{"op":"mcm","clk":"11450249548","pt":1717319618451,"mc":[{"id":"1.229554908","rc":[{"atb":[[5.5,0]],"id":52671550},{"atb":[[14.5,5]],"id":52671542}],"con":true,"img":false}]}
{"op":"mcm","clk":"11450249554","pt":1717319618532,"mc":[{"id":"1.229554908","rc":[{"atb":[[85,0],[95,0.55]],"id":52671545},{"atb":[[32,7.54]],"id":52671554}],"con":true,"img":false}]}
{"op":"mcm","clk":"11450249561","pt":1717319618632,"mc":[{"id":"1.229554908","rc":[{"atl":[[390,0]],"id":52671545}],"con":true,"img":false}]}
{"op":"mcm","clk":"11450249570","pt":1717319618737,"mc":[{"id":"1.229554908","rc":[{"atb":[[3.35,19.56]],"id":52671546},{"atb":[[2.58,47.61]],"id":52671555}],"con":true,"img":false}]}
{"op":"mcm","clk":"11450249634","pt":1717319619458,"mc":[{"id":"1.229554908","rc":[{"atb":[[6.2,5.03]],"id":52671550},{"atb":[[3.2,0]],"id":52671546},{"atl":[[42,5],[44,0]],"id":52671542},{"atl":[[16,15.69],[15.5,6.9]],"id":52671544},{"atb":[[2.48,0]],"id":52671555}],"con":true,"img":false}]}
{"op":"mcm","clk":"11450249692","pt":1717319620042,"mc":[{"id":"1.229554908","rc":[{"atl":[[42,8.91]],"id":52671542}],"con":true,"img":false}]}
{"op":"mcm","clk":"11450249702","pt":1717319620146,"mc":[{"id":"1.229554908","rc":[{"atb":[[5.8,20.1]],"id":52671550},{"atb":[[5.1,5],[4.9,20.12]],"id":52671544}],"con":true,"img":false}]}
{"op":"mcm","clk":"11450249738","pt":1717319620554,"mc":[{"id":"1.229554908","rc":[{"atb":[[2.36,0],[2.32,0]],"id":52671546},{"atb":[[16,0],[17,2.7]],"id":52671556}],"con":true,"img":false}]}
{"op":"mcm","clk":"11450249749","pt":1717319620760,"mc":[{"id":"1.229554908","rc":[{"atl":[[75,2.66]],"id":52671548},{"atl":[[410,2.81],[420,0]],"id":52671545}],"con":true,"img":false}]}
{"op":"mcm","clk":"11450249759","pt":1717319620864,"mc":[{"id":"1.229554908","rc":[{"atl":[[70,0]],"id":52671548},{"atl":[[65,0]],"id":52671542}],"con":true,"img":false}]}
{"op":"mcm","clk":"11450249815","pt":1717319621440,"mc":[{"id":"1.229554908","rc":[{"atb":[[2.3,12.07],[2.26,12.45]],"id":52671546},{"atl":[[75,0],[80,0]],"id":52671548},{"atl":[[420,2.74]],"id":52671545}],"con":true,"img":false}]}
{"op":"mcm","clk":"11450249827","pt":1717319621553,"mc":[{"id":"1.229554908","rc":[{"atl":[[410,0]],"id":52671545}],"con":true,"img":false}]}
{"op":"mcm","clk":"11450249871","pt":1717319622058,"mc":[{"id":"1.229554908","rc":[{"atb":[[8.6,8.52],[10.5,0]],"id":52671554}],"con":true,"img":false}]}
{"op":"mcm","clk":"11450249947","pt":1717319622481,"mc":[{"id":"1.229554908","rc":[{"atb":[[2.36,11.54],[2.3,0]],"id":52671546},{"atl":[[75,4.37],[85,3.96]],"id":52671548},{"atl":[[410,2.82],[420,0]],"id":52671545},{"atb":[[16,4.37],[17,0]],"id":52671556}],"con":true,"img":false}]}
{"op":"mcm","clk":"11450250007","pt":1717319623167,"mc":[{"id":"1.229554908","rc":[{"atl":[[70,4.38],[80,4.09]],"id":52671548}],"con":true,"img":false}]}
{"op":"mcm","clk":"11450250119","pt":1717319624364,"mc":[{"id":"1.229554908","rc":[{"atb":[[3.45,0],[3.95,0]],"id":52671550},{"atb":[[2.12,0],[1.96,0]],"id":52671546},{"atb":[[550,0],[650,0]],"id":52671549},{"atb":[[9,0],[12.5,0]],"id":52671548},{"atb":[[9.2,0],[13,0]],"id":52671542},{"atb":[[44,0],[27,0]],"id":52671545},{"atb":[[5.6,0],[4.6,0]],"id":52671544},{"atb":[[1.81,0],[1.91,132.23]],"id":52671555},{"atb":[[36,0],[23,0]],"id":52671554},{"atb":[[9.2,0],[13,0]],"id":52671556}],"con":true,"img":false}]}
{"op":"mcm","clk":"11450250148","pt":1717319624630,"mc":[{"id":"1.229554908","rc":[{"atl":[[3.55,6.15]],"id":52671555}],"con":true,"img":false}]}
{"op":"mcm","clk":"11450250165","pt":1717319624843,"mc":[{"id":"1.229554908","rc":[{"atb":[[5.2,23.11]],"id":52671548}],"con":true,"img":false}]}
{"op":"mcm","clk":"11450250350","pt":1717319626661,"mc":[{"id":"1.229554908","rc":[{"atb":[[1.18,0],[2.3,12.07]],"id":52671550},{"atb":[[2.36,0],[2.32,11.89]],"id":52671546},{"atb":[[4.9,4.09],[4.7,17.89]],"id":52671548},{"atl":[[70,0],[80,0]],"id":52671548},{"atb":[[4.5,4.18],[4.4,0]],"id":52671542},{"atb":[[4.5,3.86],[4.4,30.77]],"id":52671544},{"atb":[[1.91,114.98],[1.93,0]],"id":52671555},{"atb":[[16,0],[17,3.91]],"id":52671556}],"con":true,"img":false}]}
{"op":"mcm","clk":"11450250581","pt":1717319629265,"mc":[{"id":"1.229554908","rc":[{"atl":[[70,4.09],[75,0]],"id":52671548},{"atl":[[410,0],[420,2.85]],"id":52671545}],"con":true,"img":false}]}
{"op":"mcm","clk":"11450250710","pt":1717319630863,"mc":[{"id":"1.229554908","rc":[{"atl":[[10,3.05],[10.5,0]],"id":52671550},{"atl":[[85,4.16],[90,0]],"id":52671542},{"atl":[[400,4.42],[420,0]],"id":52671545},{"atl":[[310,3.79],[330,0]],"id":52671554}],"con":true,"img":false}]}
{"op":"mcm","clk":"11450250916","pt":1717319633356,"mc":[{"id":"1.229554908","rc":[{"atb":[[2.78,39.12],[2.68,0]],"id":52671546}],"con":true,"img":false}]}
{"op":"mcm","clk":"11450250949","pt":1717319633665,"mc":[{"id":"1.229554908","rc":[{"atb":[[2.32,0],[2.34,11.71]],"id":52671546},{"atl":[[85,0],[90,4.52]],"id":52671542},{"atl":[[400,0],[420,3.31]],"id":52671545}],"con":true,"img":false}]}
{"op":"mcm","clk":"11450250966","pt":1717319633869,"mc":[{"id":"1.229554908","rc":[{"atl":[[42,0],[44,5]],"id":52671542},{"atb":[[16,3.99]],"id":52671556}],"con":true,"img":false}]}
{"op":"mcm","clk":"11450251037","pt":1717319634654,"mc":[{"id":"1.229554908","rc":[{"atl":[[65,2.5]],"id":52671542}],"con":true,"img":false}]}
{"op":"mcm","clk":"11450251301","pt":1717319637974,"mc":[{"id":"1.229554908","rc":[{"atb":[[2.26,12.45]],"id":52671550},{"atl":[[330,2.73]],"id":52671554}],"con":true,"img":false}]}
{"op":"mcm","clk":"11450251515","pt":1717319640770,"mc":[{"id":"1.229554908","rc":[{"atb":[[2.3,12.07]],"id":52671546},{"atl":[[440,3.44]],"id":52671545}],"con":true,"img":false}]}
{"op":"mcm","clk":"11450251531","pt":1717319640977,"mc":[{"id":"1.229554908","rc":[{"atb":[[15,7.48]],"id":52671556}],"con":true,"img":false}]}
{"op":"mcm","clk":"11450251788","pt":1717319643783,"mc":[{"id":"1.229554908","rc":[{"atb":[[5.6,0],[5.1,0],[4.6,0],[1.16,0],[6.2,0]],"id":52671550},{"atb":[[2.26,0]],"id":52671546},{"atl":[[470,0]],"id":52671545},{"atb":[[2.02,0],[2.12,0],[1.91,0],[1.96,98.1],[1.94,16.69]],"id":52671555},{"atl":[[350,0]],"id":52671554},{"atb":[[17,0]],"id":52671556}],"con":true,"img":false}]}
{"op":"mcm","clk":"11450251804","pt":1717319643991,"mc":[{"id":"1.229554908","rc":[{"atl":[[18,5.88],[14,0]],"id":52671550},{"atl":[[70,0],[90,6.52]],"id":52671542},{"atl":[[4,0],[4.7,12.8]],"id":52671555},{"atl":[[300,2],[240,0]],"id":52671554},{"atl":[[390,0],[500,2]],"id":52671556}],"con":true,"img":false}]}
{"op":"mcm","clk":"11450251835","pt":1717319644300,"mc":[{"id":"1.229554908","rc":[{"atb":[[2.32,11.89],[2.34,0]],"id":52671546},{"atl":[[85,2.9],[90,2]],"id":52671542},{"atl":[[400,4.39],[420,0]],"id":52671545},{"atb":[[1.92,17.06]],"id":52671555}],"con":true,"img":false}]}
{"op":"mcm","clk":"11450251854","pt":1717319644507,"mc":[{"id":"1.229554908","rc":[{"atb":[[6.4,4.84],[5.2,18.68],[5.7,11.13],[4.7,28.28]],"id":52671550},{"atb":[[2.02,51.29],[2.12,23.35],[1.91,114.98]],"id":52671555}],"con":true,"img":false}]}
{"op":"mcm","clk":"11450251905","pt":1717319645075,"mc":[{"id":"1.229554908","rc":[{"atl":[[10,0],[10.5,2.64]],"id":52671550}],"con":true,"img":false}]}
{"op":"mcm","clk":"11450251954","pt":1717319645692,"mc":[{"id":"1.229554908","rc":[{"atl":[[44,8.73]],"id":52671542}],"con":true,"img":false}]}
{"op":"mcm","clk":"11450252014","pt":1717319646366,"mc":[{"id":"1.229554908","rc":[{"atl":[[65,0]],"id":52671542}],"con":true,"img":false}]}
{"op":"mcm","clk":"11450252277","pt":1717319649371,"mc":[{"id":"1.229554908","rc":[{"atl":[[65,4.1]],"id":52671548},{"atl":[[23,3.21],[24,0]],"id":52671544},{"atb":[[1.96,81.75]],"id":52671555},{"atb":[[23,5],[24,0]],"id":52671556}],"con":true,"img":false}]}
{"op":"mcm","clk":"11450252295","pt":1717319649476,"mc":[{"id":"1.229554908","rc":[{"atl":[[70,0]],"id":52671548},{"atb":[[17,3.05]],"id":52671556}],"con":true,"img":false}]}
{"op":"mcm","clk":"11450252381","pt":1717319650604,"mc":[{"id":"1.229554908","rc":[{"atl":[[16,0],[16.5,5]],"id":52671544}],"con":true,"img":false}]}
{"op":"mcm","clk":"11450252389","pt":1717319650709,"mc":[{"id":"1.229554908","rc":[{"atl":[[16,6.67],[15.5,0]],"id":52671544}],"con":true,"img":false}]}
{"op":"mcm","clk":"11450252423","pt":1717319651073,"mc":[{"id":"1.229554908","rc":[{"atl":[[18,0],[14.5,7.3]],"id":52671550},{"atl":[[80,2],[90,0]],"id":52671542},{"atl":[[4,12.8],[4.7,0]],"id":52671555},{"atl":[[300,0],[240,2]],"id":52671554},{"atl":[[400,2],[500,0]],"id":52671556}],"con":true,"img":false}]}
{"op":"mcm","clk":"11450252431","pt":1717319651181,"mc":[{"id":"1.229554908","rc":[{"atl":[[420,4.55]],"id":52671545}],"con":true,"img":false}]}
{"op":"mcm","clk":"11450252436","pt":1717319651282,"mc":[{"id":"1.229554908","rc":[{"atl":[[16.5,15.34]],"id":52671544}],"con":true,"img":false}]}
{"op":"mcm","clk":"11450252448","pt":1717319651387,"mc":[{"id":"1.229554908","rc":[{"atl":[[13,13.35],[13.5,0],[14.5,7.72]],"id":52671546},{"atb":[[130,0],[280,0],[180,0],[230,0]],"id":52671549},{"atb":[[4.8,4.12],[5.2,6.23],[4.9,0]],"id":52671548},{"atl":[[360,0]],"id":52671545},{"atb":[[5.9,20.88]],"id":52671544}],"con":true,"img":false}]}
{"op":"mcm","clk":"11450252497","pt":1717319651907,"mc":[{"id":"1.229554908","rc":[{"atb":[[160,5.11]],"id":52671549}],"con":true,"img":false}]}
{"op":"mcm","clk":"11450252502","pt":1717319652001,"mc":[{"id":"1.229554908","rc":[{"atl":[[44,0],[46,5]],"id":52671542},{"atl":[[440,0]],"id":52671545},{"atl":[[16.5,0],[17,5]],"id":52671544}],"con":true,"img":false}]}
{"op":"mcm","clk":"11450252528","pt":1717319652314,"mc":[{"id":"1.229554908","rc":[{"atb":[[2.36,11.54],[2.32,0]],"id":52671546}],"con":true,"img":false}]}
{"op":"mcm","clk":"11450252543","pt":1717319652488,"mc":[{"id":"1.229554908","rc":[{"atb":[[2.02,0],[2.12,0],[1.91,0],[1.94,0]],"id":52671555},{"atb":[[16,0],[17,0]],"id":52671556}],"con":true,"img":false}]}
{"op":"mcm","clk":"11450252550","pt":1717319652589,"mc":[{"id":"1.229554908","rc":[{"atl":[[14,0]],"id":52671546},{"atb":[[8,3.81],[8.4,4.37]],"id":52671549},{"atl":[[65,0]],"id":52671548},{"atb":[[4.7,0]],"id":52671544}],"con":true,"img":false}]}
{"op":"mcm","clk":"11450252560","pt":1717319652679,"mc":[{"id":"1.229554908","rc":[{"atl":[[75,2.16]],"id":52671542}],"con":true,"img":false}]}
{"op":"mcm","clk":"11450252566","pt":1717319652820,"mc":[{"id":"1.229554908","rc":[{"atl":[[34,7.88]],"id":52671548}],"con":true,"img":false}]}
{"op":"mcm","clk":"11450252573","pt":1717319652882,"mc":[{"id":"1.229554908","rc":[{"atl":[[30,5]],"id":52671548}],"con":true,"img":false}]}
{"op":"mcm","clk":"11450252580","pt":1717319652995,"mc":[{"id":"1.229554908","rc":[{"atl":[[32,3.23],[34,4.85]],"id":52671548}],"con":true,"img":false}]}
{"op":"mcm","clk":"11450252616","pt":1717319653416,"mc":[{"id":"1.229554908","rc":[{"atb":[[2.02,51.29],[2.12,23.35],[1.91,114.98]],"id":52671555}],"con":true,"img":false}]}
{"op":"mcm","clk":"11450252621","pt":1717319653515,"mc":[{"id":"1.229554908","rc":[{"atl":[[30,10.53]],"id":52671548}],"con":true,"img":false}]}
{"op":"mcm","clk":"11450252639","pt":1717319653714,"mc":[{"id":"1.229554908","rc":[{"atb":[[4.1,33.71],[3.55,95.64]],"id":52671550},{"atb":[[2.06,98.61],[1.93,262.26]],"id":52671546},{"atb":[[550,0.44],[650,0.16]],"id":52671549},{"atb":[[9.2,29.74],[13,8.71]],"id":52671548},{"atb":[[13.5,12.55],[9.4,41.49]],"id":52671542},{"atb":[[42,2.54],[26,9.75]],"id":52671545},{"atb":[[5.6,22.72],[4.6,67.75]],"id":52671544},{"atb":[[1.81,301.11],[1.91,229.85]],"id":52671555},{"atb":[[38,7.15],[24,10.6]],"id":52671554},{"atb":[[9,30.48],[12.5,9.08]],"id":52671556}],"con":true,"img":false}]}
{"op":"mcm","clk":"11450252686","pt":1717319654190,"mc":[{"id":"1.229554908","rc":[{"atl":[[34,0]],"id":52671548}],"con":true,"img":false}]}
{"op":"mcm","clk":"11450252695","pt":1717319654298,"mc":[{"id":"1.229554908","rc":[{"atb":[[1.94,16.69]],"id":52671555},{"atl":[[160,5]],"id":52671554},{"atb":[[25,7.76]],"id":52671556}],"con":true,"img":false}]}
{"op":"mcm","clk":"11450252707","pt":1717319654406,"mc":[{"id":"1.229554908","rc":[{"atb":[[5.8,0]],"id":52671550},{"atb":[[2.36,0],[2.32,11.89]],"id":52671546},{"atl":[[65,3.56]],"id":52671548},{"atl":[[17,0],[18,5]],"id":52671544},{"atl":[[150,0]],"id":52671554},{"atb":[[16,2.93],[17,2.89]],"id":52671556}],"con":true,"img":false}]}
{"op":"mcm","clk":"11450252765","pt":1717319655111,"mc":[{"id":"1.229554908","rc":[{"atb":[[5.6,5]],"id":52671550},{"atl":[[18,0]],"id":52671544},{"atl":[[150,6.08],[160,0]],"id":52671554},{"atb":[[25,1.09]],"id":52671556}],"con":true,"img":false}]}
{"op":"mcm","clk":"11450252785","pt":1717319655322,"mc":[{"id":"1.229554908","rc":[{"atl":[[16,0],[22,4.76]],"id":52671544}],"con":true,"img":false}]}
{"op":"mcm","clk":"11450252822","pt":1717319655690,"mc":[{"id":"1.229554908","rc":[{"atl":[[22,12.38]],"id":52671544}],"con":true,"img":false}]}
{"op":"mcm","clk":"11450252828","pt":1717319655805,"mc":[{"id":"1.229554908","rc":[{"atl":[[17,5]],"id":52671544},{"atb":[[23,12.28]],"id":52671556}],"con":true,"img":false}]}
{"op":"mcm","clk":"11450252851","pt":1717319656112,"mc":[{"id":"1.229554908","rc":[{"atl":[[34,5],[30,0]],"id":52671548}],"con":true,"img":false}]}
{"op":"mcm","clk":"11450252863","pt":1717319656205,"mc":[{"id":"1.229554908","rc":[{"atl":[[220,2],[240,0]],"id":52671554}],"con":true,"img":false}]}
{"op":"mcm","clk":"11450252893","pt":1717319656512,"mc":[{"id":"1.229554908","rc":[{"atb":[[5.6,0],[5.5,5]],"id":52671550},{"atl":[[21,5],[14.5,0]],"id":52671550},{"atb":[[3.1,0],[3.4,36.36]],"id":52671548},{"atl":[[80,0],[46,8.56],[110,2]],"id":52671542},{"atb":[[2,0],[1.79,102.6]],"id":52671555},{"atl":[[4,0],[3.4,41.67]],"id":52671555},{"atb":[[17.5,10.82],[20,2.75]],"id":52671556},{"atl":[[350,2],[400,0]],"id":52671556}],"con":true,"img":false}]}
{"op":"mcm","clk":"11450252918","pt":1717319656826,"mc":[{"id":"1.229554908","rc":[{"atl":[[10.5,0]],"id":52671550},{"atl":[[13.5,9.11],[14.5,2.71]],"id":52671546},{"atl":[[370,5]],"id":52671545},{"atb":[[5.1,0],[4.9,0],[4.4,0],[5.9,0],[5.4,0]],"id":52671544},{"atb":[[2.22,5],[2.58,0]],"id":52671555},{"atl":[[3.35,0],[2.96,5]],"id":52671555},{"atb":[[32,5],[38,2.82],[42,0],[26,0],[55,0]],"id":52671554},{"atl":[[130,0],[120,10.31]],"id":52671556}],"con":true,"img":false}]}
{"op":"mcm","clk":"11450252930","pt":1717319656930,"mc":[{"id":"1.229554908","rc":[{"atb":[[5,0],[5.8,5]],"id":52671548},{"atl":[[32,8.39]],"id":52671548}],"con":true,"img":false}]}
{"op":"mcm","clk":"11450252954","pt":1717319657205,"mc":[{"id":"1.229554908","rc":[{"atl":[[8.6,15.09],[12,5]],"id":52671550},{"atb":[[290,0.27],[340,0.15],[390,0.07],[240,0.44]],"id":52671549},{"atl":[[75,0]],"id":52671542}],"con":true,"img":false}]}
{"op":"mcm","clk":"11450252964","pt":1717319657303,"mc":[{"id":"1.229554908","rc":[{"atb":[[4.9,5]],"id":52671544},{"atl":[[2.96,20.05]],"id":52671555}],"con":true,"img":false}]}
{"op":"mcm","clk":"11450252981","pt":1717319657508,"mc":[{"id":"1.229554908","rc":[{"atb":[[5.6,28.41],[5.1,12.76],[4.6,101.9],[4.1,33.76]],"id":52671544},{"atb":[[2.12,38.41]],"id":52671555},{"atb":[[32,10.17],[38,4.24],[24,15.16],[48,0.55],[29,2.8]],"id":52671554}],"con":true,"img":false}]}
{"op":"mcm","clk":"11450253033","pt":1717319658076,"mc":[{"id":"1.229554908","rc":[{"atl":[[3.25,0]],"id":52671555}],"con":true,"img":false}]}
{"op":"mcm","clk":"11450253091","pt":1717319658803,"mc":[{"id":"1.229554908","rc":[{"atl":[[12.5,4.49]],"id":52671550}],"con":true,"img":false}]}
{"op":"mcm","clk":"11450253234","pt":1717319660418,"mc":[{"id":"1.229554908","rc":[{"atl":[[16.5,5.01]],"id":52671544}],"con":true,"img":false}]}
{"op":"mcm","clk":"11450253243","pt":1717319660508,"mc":[{"id":"1.229554908","rc":[{"atl":[[22,7.62]],"id":52671544}],"con":true,"img":false}]}
{"op":"mcm","clk":"11450253315","pt":1717319661230,"mc":[{"id":"1.229554908","rc":[{"atl":[[75,2.84]],"id":52671548}],"con":true,"img":false}]}
{"op":"mcm","clk":"11450253327","pt":1717319661287,"mc":[{"id":"1.229554908","rc":[{"atl":[[190,2],[220,0]],"id":52671554}],"con":true,"img":false}]}
{"op":"mcm","clk":"11450253353","pt":1717319661598,"mc":[{"id":"1.229554908","rc":[{"atb":[[3.85,71.81],[3.4,0]],"id":52671548}],"con":true,"img":false}]}
{"op":"mcm","clk":"11450253455","pt":1717319662728,"mc":[{"id":"1.229554908","rc":[{"atl":[[32,5.16],[34,8.03]],"id":52671548}],"con":true,"img":false}]}
{"op":"mcm","clk":"11450253480","pt":1717319662995,"mc":[{"id":"1.229554908","rc":[{"atl":[[370,9.11]],"id":52671545},{"atb":[[1.98,16.01],[1.94,0]],"id":52671555},{"atb":[[16,0],[17,0]],"id":52671556}],"con":true,"img":false}]}
{"op":"mcm","clk":"11450253493","pt":1717319663101,"mc":[{"id":"1.229554908","rc":[{"atb":[[2.36,11.54],[2.32,0]],"id":52671546},{"atl":[[85,0]],"id":52671548},{"atl":[[400,0]],"id":52671545},{"atb":[[2.02,0],[2.12,15.05],[1.91,114.86]],"id":52671555},{"atl":[[290,3.92],[310,0]],"id":52671554}],"con":true,"img":false}]}
{"op":"mcm","clk":"11450253502","pt":1717319663202,"mc":[{"id":"1.229554908","rc":[{"atl":[[65,0],[70,3.25],[75,0]],"id":52671548},{"atb":[[32,5.16],[38,2.82],[48,0],[24,10.6],[29,0]],"id":52671554},{"atl":[[110,3.79],[120,6.35]],"id":52671556}],"con":true,"img":false}]}
{"op":"mcm","clk":"11450253559","pt":1717319663726,"mc":[{"id":"1.229554908","rc":[{"atb":[[28,5]],"id":52671554},{"atl":[[100,1.65]],"id":52671556}],"con":true,"img":false}]}
{"op":"mcm","clk":"11450253566","pt":1717319663817,"mc":[{"id":"1.229554908","rc":[{"atb":[[2.06,49.36],[1.93,112.51],[2.16,22.55]],"id":52671555}],"con":true,"img":false}]}
{"op":"mcm","clk":"11450253571","pt":1717319663918,"mc":[{"id":"1.229554908","rc":[{"atb":[[36,1.5],[23,4.76],[28,7.92]],"id":52671554}],"con":true,"img":false}]}
{"op":"mcm","clk":"11450253581","pt":1717319664022,"mc":[{"id":"1.229554908","rc":[{"atb":[[2.36,0],[2.32,11.89]],"id":52671546},{"atl":[[370,5],[400,4.52]],"id":52671545},{"atb":[[1.98,0],[1.94,16.69]],"id":52671555},{"atb":[[46,0.58]],"id":52671554},{"atl":[[290,0],[310,3.85]],"id":52671554},{"atb":[[16,4.45],[17,3.65]],"id":52671556}],"con":true,"img":false}]}
{"op":"mcm","clk":"11450253625","pt":1717319664390,"mc":[{"id":"1.229554908","rc":[{"atl":[[65,4.52]],"id":52671548},{"atl":[[120,5]],"id":52671556}],"con":true,"img":false}]}
{"op":"mcm","clk":"11450253795","pt":1717319666417,"mc":[{"id":"1.229554908","rc":[{"atl":[[370,0]],"id":52671545}],"con":true,"img":false}]}
{"op":"mcm","clk":"11450253803","pt":1717319666520,"mc":[{"id":"1.229554908","rc":[{"atl":[[360,5]],"id":52671545}],"con":true,"img":false}]}
{"op":"mcm","clk":"11450253819","pt":1717319666721,"mc":[{"id":"1.229554908","rc":[{"atb":[[2.36,11.54],[2.32,0]],"id":52671546},{"atl":[[65,0],[75,3.53]],"id":52671548},{"atl":[[85,0],[90,2.66]],"id":52671542},{"atl":[[390,4.03],[400,0]],"id":52671545},{"atl":[[23,0],[24,4.16]],"id":52671544},{"atb":[[1.98,16.01],[1.94,0]],"id":52671555},{"atl":[[3.45,0],[3.3,6.82]],"id":52671555},{"atb":[[16,0],[17,0]],"id":52671556}],"con":true,"img":false}]}
{"op":"mcm","clk":"11450253866","pt":1717319667194,"mc":[{"id":"1.229554908","rc":[{"atl":[[34,5],[36,2.86]],"id":52671548}],"con":true,"img":false}]}
{"op":"mcm","clk":"11450253893","pt":1717319667503,"mc":[{"id":"1.229554908","rc":[{"atb":[[5.8,5],[5.5,0]],"id":52671550},{"atb":[[3.35,14.55],[3.5,5]],"id":52671546},{"atb":[[22,5],[14.5,0]],"id":52671542},{"atb":[[23,7.28],[24,5]],"id":52671556}],"con":true,"img":false}]}
{"op":"mcm","clk":"11450253938","pt":1717319668015,"mc":[{"id":"1.229554908","rc":[{"atb":[[3.5,38.74]],"id":52671546},{"atb":[[23,7.28]],"id":52671542}],"con":true,"img":false}]}
{"op":"mcm","clk":"11450253945","pt":1717319668120,"mc":[{"id":"1.229554908","rc":[{"atb":[[2.22,57.74]],"id":52671555}],"con":true,"img":false}]}
{"op":"mcm","clk":"11450253999","pt":1717319668590,"mc":[{"id":"1.229554908","rc":[{"atl":[[44,5],[46,3.56]],"id":52671542}],"con":true,"img":false}]}
{"op":"mcm","clk":"11450254007","pt":1717319668696,"mc":[{"id":"1.229554908","rc":[{"atb":[[3.35,0]],"id":52671546},{"atb":[[16,1.74]],"id":52671542}],"con":true,"img":false}]}
{"op":"mcm","clk":"11450254025","pt":1717319668903,"mc":[{"id":"1.229554908","rc":[{"atb":[[2.12,0]],"id":52671555}],"con":true,"img":false}]}
{"op":"mcm","clk":"11450254032","pt":1717319669003,"mc":[{"id":"1.229554908","rc":[{"atl":[[44,8.73]],"id":52671542}],"con":true,"img":false}]}
{"op":"mcm","clk":"11450254095","pt":1717319669725,"mc":[{"id":"1.229554908","rc":[{"atl":[[46,0]],"id":52671542}],"con":true,"img":false}]}
{"op":"mcm","clk":"11450254175","pt":1717319670614,"mc":[{"id":"1.229554908","rc":[{"atl":[[130,4]],"id":52671556}],"con":true,"img":false}]}
{"op":"mcm","clk":"11450254252","pt":1717319671495,"mc":[{"id":"1.229554908","rc":[{"atb":[[5.8,0],[5.7,16.14]],"id":52671550},{"atl":[[70,0]],"id":52671548},{"atl":[[150,0]],"id":52671556}],"con":true,"img":false}]}
{"op":"mcm","clk":"11450254292","pt":1717319672009,"mc":[{"id":"1.229554908","rc":[{"atb":[[2.36,0],[2.32,11.89]],"id":52671546},{"atb":[[2.02,15.38],[1.98,0]],"id":52671555}],"con":true,"img":false}]}
{"op":"mcm","clk":"11450254301","pt":1717319672116,"mc":[{"id":"1.229554908","rc":[{"atb":[[2.06,0],[1.93,0],[2.16,0]],"id":52671555},{"atb":[[21,5]],"id":52671556}],"con":true,"img":false}]}
{"op":"mcm","clk":"11450254313","pt":1717319672217,"mc":[{"id":"1.229554908","rc":[{"atl":[[17,0],[17.5,5]],"id":52671544},{"atb":[[23,0],[24,0]],"id":52671556}],"con":true,"img":false}]}
{"op":"mcm","clk":"11450254332","pt":1717319672427,"mc":[{"id":"1.229554908","rc":[{"atb":[[5.6,5],[5.7,11.13]],"id":52671550},{"atl":[[16.5,0],[17,6.25]],"id":52671544}],"con":true,"img":false}]}
{"op":"mcm","clk":"11450254361","pt":1717319672832,"mc":[{"id":"1.229554908","rc":[{"atl":[[17.5,14.71]],"id":52671544},{"atb":[[2.02,92.33],[2.22,79.18],[2.12,46.71]],"id":52671555}],"con":true,"img":false}]}
{"op":"mcm","clk":"11450254416","pt":1717319673204,"mc":[{"id":"1.229554908","rc":[{"atl":[[85,4.67]],"id":52671548},{"atl":[[44,3.72],[46,5]],"id":52671542},{"atl":[[17.5,9.71]],"id":52671544}],"con":true,"img":false}]}
{"op":"mcm","clk":"11450254427","pt":1717319673306,"mc":[{"id":"1.229554908","rc":[{"atl":[[44,0]],"id":52671542},{"atl":[[18,5]],"id":52671544}],"con":true,"img":false}]}
{"op":"mcm","clk":"11450254449","pt":1717319673510,"mc":[{"id":"1.229554908","rc":[{"atl":[[17.5,0],[22,0]],"id":52671544}],"con":true,"img":false}]}
{"op":"mcm","clk":"11450254457","pt":1717319673610,"mc":[{"id":"1.229554908","rc":[{"atl":[[17,0]],"id":52671544}],"con":true,"img":false}]}
{"op":"mcm","clk":"11450254468","pt":1717319673718,"mc":[{"id":"1.229554908","rc":[{"atl":[[17.5,6.06]],"id":52671544}],"con":true,"img":false}]}
{"op":"mcm","clk":"11450254496","pt":1717319674027,"mc":[{"id":"1.229554908","rc":[{"atl":[[85,1.9]],"id":52671542}],"con":true,"img":false}]}
{"op":"mcm","clk":"11450254516","pt":1717319674232,"mc":[{"id":"1.229554908","rc":[{"atl":[[18,14.42]],"id":52671544}],"con":true,"img":false}]}
{"op":"mcm","clk":"11450254552","pt":1717319674495,"mc":[{"id":"1.229554908","rc":[{"atl":[[17,5],[18,9.42]],"id":52671544}],"con":true,"img":false}]}
{"op":"mcm","clk":"11450254563","pt":1717319674598,"mc":[{"id":"1.229554908","rc":[{"atl":[[16.5,6.06],[17.5,0]],"id":52671544}],"con":true,"img":false}]}
{"op":"mcm","clk":"11450254621","pt":1717319675216,"mc":[{"id":"1.229554908","rc":[{"atl":[[17,0],[18,14.42]],"id":52671544}],"con":true,"img":false}]}
{"op":"mcm","clk":"11450254866","pt":1717319678270,"mc":[{"id":"1.229554908","rc":[{"atl":[[34,8.03],[36,0]],"id":52671548}],"con":true,"img":false}]}
{"op":"mcm","clk":"11450254896","pt":1717319678539,"mc":[{"id":"1.229554908","rc":[{"atb":[[4.1,0],[3.55,0]],"id":52671550},{"atb":[[2.06,0],[1.93,0]],"id":52671546},{"atb":[[550,0],[650,0]],"id":52671549},{"atb":[[9.2,0],[13,0]],"id":52671548},{"atb":[[13.5,4.19],[9.4,12.46]],"id":52671542},{"atb":[[42,0],[26,0]],"id":52671545},{"atb":[[5.6,5.69],[4.6,34.15]],"id":52671544},{"atb":[[1.99,15.85],[1.81,0],[1.91,0]],"id":52671555},{"atl":[[3.4,48.2]],"id":52671555},{"atb":[[38,0],[24,0]],"id":52671554},{"atb":[[9,0],[12.5,0]],"id":52671556}],"con":true,"img":false}]}
{"op":"mcm","clk":"11450254909","pt":1717319678749,"mc":[{"id":"1.229554908","rc":[{"atl":[[70,3.75],[75,0]],"id":52671548},{"atl":[[85,5.66],[90,0]],"id":52671542},{"atl":[[360,7.92],[390,0]],"id":52671545},{"atl":[[3.45,6.4],[3.3,0]],"id":52671555},{"atl":[[270,4.15]],"id":52671554}],"con":true,"img":false}]}
{"op":"mcm","clk":"11450254918","pt":1717319678842,"mc":[{"id":"1.229554908","rc":[{"atl":[[310,0]],"id":52671554}],"con":true,"img":false}]}
{"op":"mcm","clk":"11450254937","pt":1717319679003,"mc":[{"id":"1.229554908","rc":[{"atb":[[5.8,20.29]],"id":52671548},{"atl":[[16.5,0],[17.5,6.06]],"id":52671544}],"con":true,"img":false}]}
{"op":"mcm","clk":"11450254964","pt":1717319679345,"mc":[{"id":"1.229554908","rc":[{"atl":[[46,8.56]],"id":52671542}],"con":true,"img":false}]}
{"op":"mcm","clk":"11450255012","pt":1717319680018,"mc":[{"id":"1.229554908","rc":[{"atb":[[4.8,0],[5.8,24.95]],"id":52671548},{"atl":[[85,3.75]],"id":52671542},{"atb":[[1.92,0]],"id":52671555},{"atl":[[3.4,41.67]],"id":52671555},{"atb":[[10.5,3.96],[11.5,4.29]],"id":52671556}],"con":true,"img":false}]}
{"op":"mcm","clk":"11450255120","pt":1717319681320,"mc":[{"id":"1.229554908","rc":[{"atl":[[46,3.56]],"id":52671542}],"con":true,"img":false}]}
{"op":"mcm","clk":"11450255128","pt":1717319681421,"mc":[{"id":"1.229554908","rc":[{"atl":[[46,0],[48,5]],"id":52671542}],"con":true,"img":false}]}
{"op":"mcm","clk":"11450255151","pt":1717319681750,"mc":[{"id":"1.229554908","rc":[{"atl":[[18,0],[18.5,5]],"id":52671544}],"con":true,"img":false}]}
{"op":"mcm","clk":"11450255157","pt":1717319681840,"mc":[{"id":"1.229554908","rc":[{"atl":[[3.85,26.46],[3.4,0]],"id":52671555},{"atl":[[190,0],[230,2]],"id":52671554},{"atl":[[350,0],[450,2]],"id":52671556}],"con":true,"img":false}]}
{"op":"mcm","clk":"11450255177","pt":1717319682145,"mc":[{"id":"1.229554908","rc":[{"atl":[[80,2.02]],"id":52671542}],"con":true,"img":false}]}
{"op":"mcm","clk":"11450255293","pt":1717319683446,"mc":[{"id":"1.229554908","rc":[{"atl":[[17.5,0],[18,5.88]],"id":52671544}],"con":true,"img":false}]}
{"op":"mcm","clk":"11450255347","pt":1717319683961,"mc":[{"id":"1.229554908","rc":[{"atl":[[23,7.28]],"id":52671544}],"con":true,"img":false}]}
{"op":"mcm","clk":"11450255378","pt":1717319684216,"mc":[{"id":"1.229554908","rc":[{"atl":[[48,8.41]],"id":52671542}],"con":true,"img":false}]}
{"op":"mcm","clk":"11450255441","pt":1717319684941,"mc":[{"id":"1.229554908","rc":[{"atl":[[80,0]],"id":52671542}],"con":true,"img":false}]}
{"op":"mcm","clk":"11450255460","pt":1717319685146,"mc":[{"id":"1.229554908","rc":[{"atl":[[380,4.48]],"id":52671545},{"atl":[[290,4.26]],"id":52671554}],"con":true,"img":false}]}
{"op":"mcm","clk":"11450255578","pt":1717319686355,"mc":[{"id":"1.229554908","rc":[{"atb":[[5.6,3.06]],"id":52671548}],"con":true,"img":false}]}
{"op":"mcm","clk":"11450255603","pt":1717319686661,"mc":[{"id":"1.229554908","rc":[{"atb":[[2.36,11.54],[2.32,0]],"id":52671546},{"atl":[[420,0]],"id":52671545},{"atb":[[2.02,0],[2.22,57.74],[2.12,0],[1.96,0],[1.94,16.69]],"id":52671555},{"atl":[[330,0]],"id":52671554}],"con":true,"img":false}]}
{"op":"mcm","clk":"11450255642","pt":1717319687020,"mc":[{"id":"1.229554908","rc":[{"atl":[[85,0],[90,3.05]],"id":52671542},{"atl":[[270,0],[290,0],[240,4.2]],"id":52671554}],"con":true,"img":false}]}
{"op":"mcm","clk":"11450255667","pt":1717319687330,"mc":[{"id":"1.229554908","rc":[{"atb":[[2.02,51.29],[2.12,23.35],[1.91,114.98],[1.96,81.75]],"id":52671555}],"con":true,"img":false}]}
{"op":"mcm","clk":"11450255698","pt":1717319687851,"mc":[{"id":"1.229554908","rc":[{"atl":[[19.5,5.41],[27,0]],"id":52671546},{"atb":[[4.3,30.3]],"id":52671548},{"atl":[[95,2]],"id":52671542},{"atl":[[880,2]],"id":52671545},{"atb":[[3.4,0],[3,18.46]],"id":52671544},{"atb":[[1.79,0],[2.02,132.39]],"id":52671555},{"atl":[[4.5,26.46],[3.85,0]],"id":52671555},{"atl":[[310,2],[230,0]],"id":52671554}],"con":true,"img":false}]}
{"op":"mcm","clk":"11450255702","pt":1717319687952,"mc":[{"id":"1.229554908","rc":[{"atb":[[3.85,36.72]],"id":52671548},{"atl":[[110,0]],"id":52671542}],"con":true,"img":false}]}
{"op":"mcm","clk":"11450255724","pt":1717319688257,"mc":[{"id":"1.229554908","rc":[{"atl":[[13.5,5],[9.4,4.35]],"id":52671546},{"atb":[[5.8,20.29],[7,4.03],[4.7,14.14]],"id":52671548},{"atb":[[22,0],[23,0],[15.5,5]],"id":52671542},{"atb":[[150,0],[110,5]],"id":52671545},{"atl":[[310,4.33],[360,5]],"id":52671545},{"atb":[[5.6,0],[5.1,0],[4.5,0],[4.6,0],[4.1,0],[4.9,0]],"id":52671544},{"atb":[[1.99,0],[2.54,5],[2.22,52.73]],"id":52671555},{"atl":[[3.4,5],[2.96,15.05]],"id":52671555},{"atb":[[32,10.17],[28,2.91]],"id":52671554}],"con":true,"img":false}]}
{"op":"mcm","clk":"11450255761","pt":1717319688626,"mc":[{"id":"1.229554908","rc":[{"atl":[[300,0.53]],"id":52671545},{"atb":[[4.2,9.91]],"id":52671544},{"atb":[[2.54,37.22]],"id":52671555}],"con":true,"img":false}]}
{"op":"mcm","clk":"11450255769","pt":1717319688727,"mc":[{"id":"1.229554908","rc":[{"atl":[[9.2,19.54]],"id":52671546},{"atl":[[34,5],[30,3.45]],"id":52671548}],"con":true,"img":false}]}
{"op":"mcm","clk":"11450255787","pt":1717319688936,"mc":[{"id":"1.229554908","rc":[{"atb":[[15.5,10.64]],"id":52671542},{"atb":[[110,6.47]],"id":52671545}],"con":true,"img":false}]}
{"op":"mcm","clk":"11450255800","pt":1717319689042,"mc":[{"id":"1.229554908","rc":[{"atb":[[2.36,0],[2.34,11.71]],"id":52671546},{"atb":[[3.6,40.24],[3.85,27.54],[1.01,7.52],[4.2,26.26],[4.7,7.07]],"id":52671544},{"atb":[[1.94,0]],"id":52671555},{"atb":[[11.5,0],[13,4]],"id":52671556}],"con":true,"img":false}]}
{"op":"mcm","clk":"11450255822","pt":1717319689253,"mc":[{"id":"1.229554908","rc":[{"atb":[[7,17.61]],"id":52671548},{"atl":[[30,8.97]],"id":52671548}],"con":true,"img":false}]}
{"op":"mcm","clk":"11450255832","pt":1717319689352,"mc":[{"id":"1.229554908","rc":[{"atl":[[350,0]],"id":52671545},{"atb":[[2.22,0]],"id":52671555}],"con":true,"img":false}]}
{"op":"mcm","clk":"11450255844","pt":1717319689453,"mc":[{"id":"1.229554908","rc":[{"atl":[[13,0]],"id":52671546}],"con":true,"img":false}]}
{"op":"mcm","clk":"11450255897","pt":1717319689929,"mc":[{"id":"1.229554908","rc":[{"atl":[[16.5,6.45],[19.5,0]],"id":52671546},{"atb":[[5.8,5]],"id":52671548},{"atl":[[32,0]],"id":52671548},{"atl":[[75,2]],"id":52671542},{"atl":[[710,2],[880,0]],"id":52671545},{"atl":[[310,0],[250,2]],"id":52671554},{"atl":[[360,2],[450,0]],"id":52671556}],"con":true,"img":false}]}
{"op":"mcm","clk":"11450255908","pt":1717319690031,"mc":[{"id":"1.229554908","rc":[{"atl":[[95,0]],"id":52671542}],"con":true,"img":false}]}
{"op":"mcm","clk":"11450255928","pt":1717319690234,"mc":[{"id":"1.229554908","rc":[{"atl":[[34,8.03],[30,5.52]],"id":52671548}],"con":true,"img":false}]}
{"op":"mcm","clk":"11450255956","pt":1717319690546,"mc":[{"id":"1.229554908","rc":[{"atb":[[2.36,11.54],[2.34,0]],"id":52671546},{"atl":[[65,4.32],[70,0]],"id":52671548},{"atl":[[310,0],[320,3.66]],"id":52671545}],"con":true,"img":false}]}
{"op":"mcm","clk":"11450255966","pt":1717319690656,"mc":[{"id":"1.229554908","rc":[{"atl":[[85,3.69],[90,0]],"id":52671542},{"atb":[[1.92,17.06],[1.94,16.69]],"id":52671555},{"atl":[[3.45,0],[3.4,11.54]],"id":52671555},{"atb":[[13,0]],"id":52671556}],"con":true,"img":false}]}
{"op":"mcm","clk":"11450255976","pt":1717319690759,"mc":[{"id":"1.229554908","rc":[{"atb":[[3.6,93.81],[4.2,32.66]],"id":52671550},{"atb":[[2.24,84.29],[2.04,234.52]],"id":52671546},{"atb":[[260,0.94],[360,0.29]],"id":52671549},{"atb":[[9.2,29.74],[13,8.71]],"id":52671548},{"atb":[[9.8,27.71],[14.5,7.74]],"id":52671542},{"atb":[[18.5,13.93],[27,4.01]],"id":52671545},{"atb":[[4.8,64.18],[5.8,21.77]],"id":52671544},{"atb":[[1.77,316.75],[1.87,120.15]],"id":52671555},{"atb":[[16.5,15.73],[23,9.51]],"id":52671554},{"atb":[[7.2,39.33],[9.2,12.74]],"id":52671556}],"con":true,"img":false}]}
{"op":"mcm","clk":"11450256050","pt":1717319691537,"mc":[{"id":"1.229554908","rc":[{"atl":[[65,0],[70,3.36]],"id":52671548},{"atl":[[85,0],[90,3.23]],"id":52671542},{"atl":[[310,4.44],[320,0]],"id":52671545},{"atl":[[3.45,6.4],[3.4,5]],"id":52671555}],"con":true,"img":false}]}
{"op":"mcm","clk":"11450256190","pt":1717319693345,"mc":[{"id":"1.229554908","rc":[{"atl":[[34,5],[36,2.86]],"id":52671548},{"atl":[[4,26.46],[4.5,0]],"id":52671555},{"atl":[[260,3.83],[230,2],[250,0]],"id":52671554}],"con":true,"img":false}]}
{"op":"mcm","clk":"11450256233","pt":1717319693959,"mc":[{"id":"1.229554908","rc":[{"atl":[[32,3.23],[36,0]],"id":52671548},{"atl":[[17.5,9.71]],"id":52671544}],"con":true,"img":false}]}
{"op":"mcm","clk":"11450256239","pt":1717319694063,"mc":[{"id":"1.229554908","rc":[{"atl":[[17,5.88],[18,0]],"id":52671544}],"con":true,"img":false}]}
{"op":"mcm","clk":"11450256253","pt":1717319694265,"mc":[{"id":"1.229554908","rc":[{"atb":[[2.34,11.71]],"id":52671546},{"atl":[[330,3.98]],"id":52671545}],"con":true,"img":false}]}
{"op":"mcm","clk":"11450256263","pt":1717319694372,"mc":[{"id":"1.229554908","rc":[{"atb":[[2.36,0]],"id":52671546},{"atl":[[70,0],[75,4.46]],"id":52671548},{"atl":[[310,0]],"id":52671545},{"atb":[[1.94,0],[1.93,16.87]],"id":52671555},{"atl":[[3.45,0],[3.35,6.68]],"id":52671555},{"atl":[[240,0]],"id":52671554},{"atb":[[13,4.63]],"id":52671556}],"con":true,"img":false}]}
{"op":"mcm","clk":"11450256286","pt":1717319694631,"mc":[{"id":"1.229554908","rc":[{"atl":[[23,0]],"id":52671544}],"con":true,"img":false}]}
{"op":"mcm","clk":"11450256374","pt":1717319695783,"mc":[{"id":"1.229554908","rc":[{"atb":[[2.36,11.54],[2.34,0]],"id":52671546},{"atl":[[65,3.22],[75,0]],"id":52671548},{"atl":[[85,3.21],[90,0]],"id":52671542},{"atl":[[330,0],[340,3.48]],"id":52671545},{"atb":[[1.94,16.69],[1.93,0]],"id":52671555},{"atb":[[13,0]],"id":52671556}],"con":true,"img":false}]}
{"op":"mcm","clk":"11450256543","pt":1717319697469,"mc":[{"id":"1.229554908","rc":[{"atl":[[65,0],[75,3.22]],"id":52671548},{"atl":[[85,0],[90,3.27]],"id":52671542},{"atl":[[330,3.95],[340,0]],"id":52671545}],"con":true,"img":false}]}
{"op":"mcm","clk":"11450256596","pt":1717319698136,"mc":[{"id":"1.229554908","rc":[{"atl":[[32,0],[36,2.86]],"id":52671548}],"con":true,"img":false}]}
{"op":"mcm","clk":"11450256664","pt":1717319698958,"mc":[{"id":"1.229554908","rc":[{"atb":[[16,12.43]],"id":52671542},{"atb":[[140,1.34]],"id":52671545}],"con":true,"img":false}]}
{"op":"mcm","clk":"11450256710","pt":1717319699425,"mc":[{"id":"1.229554908","rc":[{"atl":[[280,3.95]],"id":52671554}],"con":true,"img":false}]}
{"op":"mcm","clk":"11450256717","pt":1717319699527,"mc":[{"id":"1.229554908","rc":[{"atb":[[2.36,0],[2.34,11.71]],"id":52671546},{"atb":[[1.94,0],[1.93,16.87]],"id":52671555},{"atb":[[13,4.63]],"id":52671556}],"con":true,"img":false}]}
{"op":"mcm","clk":"11450256725","pt":1717319699634,"mc":[{"id":"1.229554908","rc":[{"atb":[[15.5,5]],"id":52671542},{"atb":[[110,5]],"id":52671545}],"con":true,"img":false}]}
{"op":"mcm","clk":"11450256777","pt":1717319700262,"mc":[{"id":"1.229554908","rc":[{"atl":[[34,0],[30,10.53]],"id":52671548}],"con":true,"img":false}]}
{"op":"mcm","clk":"11450256813","pt":1717319700676,"mc":[{"id":"1.229554908","rc":[{"atl":[[30,5]],"id":52671548}],"con":true,"img":false}]}
{"op":"mcm","clk":"11450256904","pt":1717319701463,"mc":[{"id":"1.229554908","rc":[{"atl":[[34,4.85]],"id":52671548}],"con":true,"img":false}]}
{"op":"mcm","clk":"11450256946","pt":1717319701883,"mc":[{"id":"1.229554908","rc":[{"atb":[[2.36,11.54],[2.34,0]],"id":52671546},{"atl":[[65,3.35],[75,0]],"id":52671548},{"atl":[[85,4.43],[90,0]],"id":52671542},{"atl":[[330,0],[340,3.94]],"id":52671545},{"atb":[[1.94,16.69],[1.93,0]],"id":52671555},{"atb":[[13,0]],"id":52671556}],"con":true,"img":false}]}
{"op":"mcm","clk":"11450256984","pt":1717319702197,"mc":[{"id":"1.229554908","rc":[{"atl":[[70,2],[75,0]],"id":52671542},{"atl":[[560,2],[710,0]],"id":52671545},{"atl":[[210,2],[230,0]],"id":52671554},{"atb":[[17.5,4.76],[15.5,6.9]],"id":52671556}],"con":true,"img":false}]}
{"op":"mcm","clk":"11450256996","pt":1717319702257,"mc":[{"id":"1.229554908","rc":[{"atl":[[17.5,0]],"id":52671544}],"con":true,"img":false}]}
{"op":"mcm","clk":"11450257008","pt":1717319702353,"mc":[{"id":"1.229554908","rc":[{"atl":[[17,0],[18,5.88]],"id":52671544}],"con":true,"img":false}]}
{"op":"mcm","clk":"11450257017","pt":1717319702457,"mc":[{"id":"1.229554908","rc":[{"atl":[[8.6,0]],"id":52671550},{"atb":[[140,0],[70,0],[95,0],[48,0]],"id":52671545},{"atb":[[4.2,21.36]],"id":52671544},{"atl":[[3.35,0],[3.4,11.54]],"id":52671555},{"atl":[[130,5],[150,1.07]],"id":52671554},{"atl":[[110,0]],"id":52671556}],"con":true,"img":false}]}
{"op":"mcm","clk":"11450257027","pt":1717319702559,"mc":[{"id":"1.229554908","rc":[{"atl":[[100,5.17]],"id":52671556}],"con":true,"img":false}]}
{"op":"mcm","clk":"11450257058","pt":1717319702881,"mc":[{"id":"1.229554908","rc":[{"atl":[[130,6.24]],"id":52671554}],"con":true,"img":false}]}
{"op":"mcm","clk":"11450257072","pt":1717319702979,"mc":[{"id":"1.229554908","rc":[{"atl":[[18,15.3]],"id":52671544}],"con":true,"img":false}]}
{"op":"mcm","clk":"11450257085","pt":1717319703077,"mc":[{"id":"1.229554908","rc":[{"atl":[[18,20.3],[18.5,0]],"id":52671544}],"con":true,"img":false}]}
{"op":"mcm","clk":"11450257096","pt":1717319703133,"mc":[{"id":"1.229554908","rc":[{"atl":[[12,19.57]],"id":52671550},{"atb":[[85,0.62],[44,2.43],[110,6.47],[120,0.22],[60,1.33]],"id":52671545}],"con":true,"img":false}]}
{"op":"mcm","clk":"11450257108","pt":1717319703235,"mc":[{"id":"1.229554908","rc":[{"atl":[[32,3.23],[36,0]],"id":52671548},{"atb":[[36,0]],"id":52671554}],"con":true,"img":false}]}
{"op":"mcm","clk":"11450257141","pt":1717319703546,"mc":[{"id":"1.229554908","rc":[{"atl":[[150,0]],"id":52671554}],"con":true,"img":false}]}
{"op":"mcm","clk":"11450257188","pt":1717319703966,"mc":[{"id":"1.229554908","rc":[{"atl":[[13.5,0],[9.4,9.35]],"id":52671546},{"atb":[[7.2,5],[5.8,0]],"id":52671548},{"atl":[[360,0],[210,5]],"id":52671545},{"atb":[[40,1.34]],"id":52671554},{"atl":[[100,10.18],[120,0]],"id":52671556}],"con":true,"img":false}]}
{"op":"mcm","clk":"11450257197","pt":1717319704064,"mc":[{"id":"1.229554908","rc":[{"atl":[[32,0],[30,8.45]],"id":52671548}],"con":true,"img":false}]}
{"op":"mcm","clk":"11450257232","pt":1717319704379,"mc":[{"id":"1.229554908","rc":[{"atl":[[210,5.77]],"id":52671545}],"con":true,"img":false}]}
{"op":"mcm","clk":"11450257291","pt":1717319705051,"mc":[{"id":"1.229554908","rc":[{"atl":[[300,0]],"id":52671545}],"con":true,"img":false}]}
{"op":"mcm","clk":"11450257326","pt":1717319705465,"mc":[{"id":"1.229554908","rc":[{"atl":[[260,0],[220,3.13]],"id":52671554}],"con":true,"img":false}]}
{"op":"mcm","clk":"11450257480","pt":1717319707274,"mc":[{"id":"1.229554908","rc":[{"atl":[[21,0],[14.5,7.41]],"id":52671550},{"atl":[[16.5,0],[12,9.09]],"id":52671546},{"atb":[[4.3,0],[5.3,17.42]],"id":52671548},{"atl":[[70,0],[100,5.68]],"id":52671542},{"atl":[[560,0],[790,2]],"id":52671545},{"atb":[[3,0],[3.9,34.48]],"id":52671544},{"atb":[[1.83,120.48],[2.02,51.29]],"id":52671555},{"atl":[[4,0],[3.4,41.64]],"id":52671555},{"atl":[[290,2],[210,0]],"id":52671554},{"atb":[[10.5,14.49],[15.5,0]],"id":52671556},{"atl":[[360,0],[200,2]],"id":52671556}],"con":true,"img":false}]}
{"op":"mcm","clk":"11450257506","pt":1717319707583,"mc":[{"id":"1.229554908","rc":[{"atl":[[9,5],[11,3.01],[11.5,0],[12,14.56]],"id":52671550},{"atl":[[7.4,2.75],[9.4,5]],"id":52671546},{"atl":[[65,0],[70,4.28]],"id":52671548},{"atl":[[85,0],[90,2.85]],"id":52671542},{"atl":[[260,5],[290,3.25],[340,0],[210,0.76]],"id":52671545},{"atb":[[6,5],[4.2,16.35],[5.9,32.69]],"id":52671544},{"atb":[[2.24,5],[2.54,0]],"id":52671555},{"atl":[[3.4,30.1],[2.98,5],[3.5,6.27]],"id":52671555},{"atb":[[40,0],[46,4.14]],"id":52671554},{"atl":[[65,2.98],[100,6.66]],"id":52671556}],"con":true,"img":false}]}
{"op":"mcm","clk":"11450257536","pt":1717319707947,"mc":[{"id":"1.229554908","rc":[{"atl":[[7.2,25.83]],"id":52671546}],"con":true,"img":false}]}
{"op":"mcm","clk":"11450257548","pt":1717319708049,"mc":[{"id":"1.229554908","rc":[{"atl":[[60,2.71]],"id":52671556}],"con":true,"img":false}]}
{"op":"mcm","clk":"11450257558","pt":1717319708153,"mc":[{"id":"1.229554908","rc":[{"atl":[[34,7.88],[30,5]],"id":52671548}],"con":true,"img":false}]}
{"op":"mcm","clk":"11450257568","pt":1717319708254,"mc":[{"id":"1.229554908","rc":[{"atb":[[1.01,0]],"id":52671544},{"atb":[[2.12,53.48]],"id":52671555},{"atb":[[32,5],[48,1.11]],"id":52671554}],"con":true,"img":false}]}
{"op":"mcm","clk":"11450257595","pt":1717319708667,"mc":[{"id":"1.229554908","rc":[{"atl":[[9.2,0]],"id":52671546},{"atb":[[120,1.56]],"id":52671545}],"con":true,"img":false}]}
{"op":"mcm","clk":"11450257612","pt":1717319708877,"mc":[{"id":"1.229554908","rc":[{"atl":[[100,5]],"id":52671556}],"con":true,"img":false}]}
{"op":"mcm","clk":"11450257676","pt":1717319709546,"mc":[{"id":"1.229554908","rc":[{"atl":[[18,5.88],[18.5,5]],"id":52671544},{"atb":[[20,7.76],[21,0],[11.5,4.02]],"id":52671556}],"con":true,"img":false}]}
{"op":"mcm","clk":"11450257684","pt":1717319709652,"mc":[{"id":"1.229554908","rc":[{"atb":[[110,5]],"id":52671545}],"con":true,"img":false}]}
{"op":"mcm","clk":"11450257708","pt":1717319709962,"mc":[{"id":"1.229554908","rc":[{"atl":[[130,0],[140,5]],"id":52671554}],"con":true,"img":false}]}
{"op":"mcm","clk":"11450257732","pt":1717319710270,"mc":[{"id":"1.229554908","rc":[{"atl":[[18.5,14.16]],"id":52671544}],"con":true,"img":false}]}
{"op":"mcm","clk":"11450257761","pt":1717319710681,"mc":[{"id":"1.229554908","rc":[{"atl":[[140,6.15]],"id":52671554}],"con":true,"img":false}]}
{"op":"mcm","clk":"11450257788","pt":1717319710997,"mc":[{"id":"1.229554908","rc":[{"atb":[[5.6,0],[5.7,16.14]],"id":52671550},{"atl":[[34,12.89],[30,0]],"id":52671548},{"atl":[[48,0],[50,5]],"id":52671542}],"con":true,"img":false}]}
{"op":"mcm","clk":"11450257849","pt":1717319711562,"mc":[{"id":"1.229554908","rc":[{"atl":[[240,2.62]],"id":52671554}],"con":true,"img":false}]}
{"op":"mcm","clk":"11450257857","pt":1717319711665,"mc":[{"id":"1.229554908","rc":[{"atl":[[85,1.9]],"id":52671542}],"con":true,"img":false}]}
{"op":"mcm","clk":"11450257927","pt":1717319712397,"mc":[{"id":"1.229554908","rc":[{"atb":[[6.4,0],[5.2,0],[5.7,5],[4.7,0]],"id":52671550},{"atb":[[2.36,0],[2.38,30.33]],"id":52671546},{"atl":[[280,2.91],[290,0]],"id":52671545},{"atb":[[1.91,0],[1.96,98.1],[1.94,0]],"id":52671555},{"atl":[[280,0]],"id":52671554},{"atb":[[11.5,0],[12,4.11]],"id":52671556}],"con":true,"img":false}]}
{"op":"mcm","clk":"11450257957","pt":1717319712655,"mc":[{"id":"1.229554908","rc":[{"atl":[[10.5,4.64],[11,0]],"id":52671550},{"atl":[[950,4.6],[970,4.58]],"id":52671549},{"atl":[[90,0],[95,3.98]],"id":52671542},{"atl":[[24,0],[25,4.45]],"id":52671544},{"atl":[[3.45,6.4],[3.5,0]],"id":52671555},{"atl":[[210,3.01],[220,0],[240,0]],"id":52671554}],"con":true,"img":false}]}
{"op":"mcm","clk":"11450257968","pt":1717319712759,"mc":[{"id":"1.229554908","rc":[{"atb":[[5.7,17.06]],"id":52671550},{"atl":[[18,15.3]],"id":52671544}],"con":true,"img":false}]}
{"op":"mcm","clk":"11450257977","pt":1717319712863,"mc":[{"id":"1.229554908","rc":[{"atl":[[9,17.06]],"id":52671550}],"con":true,"img":false}]}
{"op":"mcm","clk":"11450258004","pt":1717319713179,"mc":[{"id":"1.229554908","rc":[{"atb":[[5.6,11.37],[5.1,19.14],[4.6,29.07],[6.2,5.03]],"id":52671550},{"atl":[[940,0.17]],"id":52671549},{"atb":[[1.92,130.79]],"id":52671555}],"con":true,"img":false}]}
{"op":"mcm","clk":"11450258035","pt":1717319713485,"mc":[{"id":"1.229554908","rc":[{"atl":[[18.5,5]],"id":52671544}],"con":true,"img":false}]}
{"op":"mcm","clk":"11450258045","pt":1717319713586,"mc":[{"id":"1.229554908","rc":[{"atl":[[12,0]],"id":52671550}],"con":true,"img":false}]}
{"op":"mcm","clk":"11450258056","pt":1717319713690,"mc":[{"id":"1.229554908","rc":[{"atb":[[2.38,18.95],[2.52,10.32]],"id":52671546},{"atb":[[1.96,81.75]],"id":52671555},{"atb":[[11.5,3.5],[12,0]],"id":52671556}],"con":true,"img":false}]}
{"op":"mcm","clk":"11450258064","pt":1717319713744,"mc":[{"id":"1.229554908","rc":[{"atb":[[1.93,16.87]],"id":52671555}],"con":true,"img":false}]}
{"op":"mcm","clk":"11450258080","pt":1717319713952,"mc":[{"id":"1.229554908","rc":[{"atl":[[1000,0]],"id":52671549}],"con":true,"img":false}]}
{"op":"mcm","clk":"11450258099","pt":1717319714155,"mc":[{"id":"1.229554908","rc":[{"atb":[[5.8,5],[5.7,12.05]],"id":52671550},{"atb":[[3.5,33.73],[3.65,5]],"id":52671546},{"atb":[[21,5],[15.5,0]],"id":52671542}],"con":true,"img":false}]}
{"op":"mcm","clk":"11450258140","pt":1717319714569,"mc":[{"id":"1.229554908","rc":[{"atl":[[10.5,0],[11,3.6]],"id":52671550},{"atb":[[3.65,51.34]],"id":52671546},{"atl":[[880,4.63],[950,0]],"id":52671549},{"atl":[[32,5.16]],"id":52671548},{"atb":[[22,7.62]],"id":52671542},{"atl":[[260,8.86],[280,0]],"id":52671545},{"atl":[[190,3.23]],"id":52671554}],"con":true,"img":false}]}
{"op":"mcm","clk":"11450258223","pt":1717319715302,"mc":[{"id":"1.229554908","rc":[{"atl":[[34,8.03]],"id":52671548},{"atb":[[16,1.74]],"id":52671542}],"con":true,"img":false}]}
{"op":"mcm","clk":"11450258235","pt":1717319715352,"mc":[{"id":"1.229554908","rc":[{"atb":[[3.5,0]],"id":52671546}],"con":true,"img":false}]}
{"op":"mcm","clk":"11450258256","pt":1717319715567,"mc":[{"id":"1.229554908","rc":[{"atb":[[3.6,0],[4.2,0]],"id":52671550},{"atb":[[2.24,0],[2.04,0]],"id":52671546},{"atb":[[260,0],[360,0]],"id":52671549},{"atb":[[9.2,0],[13,0]],"id":52671548},{"atb":[[9.8,0],[14.5,0]],"id":52671542},{"atb":[[18.5,0],[27,0]],"id":52671545},{"atb":[[4.8,0],[5.8,0]],"id":52671544},{"atb":[[1.77,0],[1.87,0]],"id":52671555},{"atb":[[16.5,0],[23,4.76]],"id":52671554},{"atb":[[7.2,0],[9.2,0]],"id":52671556}],"con":true,"img":false}]}
{"op":"mcm","clk":"11450258302","pt":1717319715982,"mc":[{"id":"1.229554908","rc":[{"atb":[[20,2.75],[21,5]],"id":52671556}],"con":true,"img":false}]}
{"op":"mcm","clk":"11450258315","pt":1717319716083,"mc":[{"id":"1.229554908","rc":[{"atb":[[7.2,20.29],[7,13.57],[8.4,4.35]],"id":52671548}],"con":true,"img":false}]}
{"op":"mcm","clk":"11450258349","pt":1717319716392,"mc":[{"id":"1.229554908","rc":[{"atb":[[4.5,2.91],[4.3,4.75]],"id":52671544}],"con":true,"img":false}]}
{"op":"mcm","clk":"11450258381","pt":1717319716756,"mc":[{"id":"1.229554908","rc":[{"atb":[[7,0]],"id":52671548}],"con":true,"img":false}]}
{"op":"mcm","clk":"11450258413","pt":1717319717174,"mc":[{"id":"1.229554908","rc":[{"atb":[[6,23.15]],"id":52671544},{"atb":[[48,4.53]],"id":52671554}],"con":true,"img":false}]}
{"op":"mcm","clk":"11450258435","pt":1717319717386,"mc":[{"id":"1.229554908","rc":[{"atl":[[790,0],[890,2]],"id":52671545}],"con":true,"img":false}]}
{"op":"mcm","clk":"11450258473","pt":1717319717699,"mc":[{"id":"1.229554908","rc":[{"atl":[[270,4.54]],"id":52671545},{"atl":[[70,3.2]],"id":52671556}],"con":true,"img":false}]}
{"op":"mcm","clk":"11450258487","pt":1717319717804,"mc":[{"id":"1.229554908","rc":[{"atb":[[110,0],[120,6.57]],"id":52671545},{"atl":[[260,5]],"id":52671545},{"atb":[[2.24,72.82]],"id":52671555},{"atl":[[65,0]],"id":52671556}],"con":true,"img":false}]}
{"op":"mcm","clk":"11450258498","pt":1717319717857,"mc":[{"id":"1.229554908","rc":[{"atb":[[5.9,0]],"id":52671544},{"atb":[[46,0.58]],"id":52671554}],"con":true,"img":false}]}
{"op":"mcm","clk":"11450258557","pt":1717319718484,"mc":[{"id":"1.229554908","rc":[{"atb":[[2.12,23.35]],"id":52671555}],"con":true,"img":false}]}
{"op":"mcm","clk":"11450258616","pt":1717319719000,"mc":[{"id":"1.229554908","rc":[{"atb":[[5.6,0],[5.1,0],[4.6,0],[6.2,0]],"id":52671550},{"atb":[[1.92,17.06]],"id":52671555}],"con":true,"img":false}]}
{"op":"mcm","clk":"11450258670","pt":1717319719477,"mc":[{"id":"1.229554908","rc":[{"atb":[[2.48,10.6]],"id":52671546},{"atl":[[7.8,4.27]],"id":52671546}],"con":true,"img":false}]}
{"op":"mcm","clk":"11450258700","pt":1717319719781,"mc":[{"id":"1.229554908","rc":[{"atb":[[4.5,29.89],[5,19.62],[5.5,11.63],[6,5.23]],"id":52671550}],"con":true,"img":false}]}
{"op":"mcm","clk":"11450258765","pt":1717319720350,"mc":[{"id":"1.229554908","rc":[{"atl":[[900,4.24]],"id":52671549}],"con":true,"img":false}]}
{"op":"mcm","clk":"11450258816","pt":1717319720763,"mc":[{"id":"1.229554908","rc":[{"atl":[[18.5,0]],"id":52671544}],"con":true,"img":false}]}
{"op":"mcm","clk":"11450258828","pt":1717319720868,"mc":[{"id":"1.229554908","rc":[{"atl":[[18,20.3]],"id":52671544}],"con":true,"img":false}]}
{"op":"mcm","clk":"11450258856","pt":1717319721176,"mc":[{"id":"1.229554908","rc":[{"atl":[[50,8.27]],"id":52671542}],"con":true,"img":false}]}
{"op":"mcm","clk":"11450258924","pt":1717319721904,"mc":[{"id":"1.229554908","rc":[{"atb":[[8,3.71]],"id":52671548},{"atl":[[85,0]],"id":52671542}],"con":true,"img":false}]}
{"op":"mcm","clk":"11450258932","pt":1717319722003,"mc":[{"id":"1.229554908","rc":[{"atb":[[2.3,0]],"id":52671546},{"atl":[[14.5,0]],"id":52671546},{"atl":[[970,0]],"id":52671549},{"atl":[[48,5],[50,3.26]],"id":52671542}],"con":true,"img":false}]}
{"op":"mcm","clk":"11450258994","pt":1717319722680,"mc":[{"id":"1.229554908","rc":[{"atl":[[870,0.18]],"id":52671549}],"con":true,"img":false}]}
{"op":"mcm","clk":"11450259005","pt":1717319722783,"mc":[{"id":"1.229554908","rc":[{"atb":[[5.8,0],[5.7,17.06]],"id":52671550},{"atb":[[5.6,0]],"id":52671548}],"con":true,"img":false}]}
{"op":"mcm","clk":"11450259051","pt":1717319723192,"mc":[{"id":"1.229554908","rc":[{"atl":[[10.5,3.35],[11,0]],"id":52671550},{"atl":[[880,0],[900,0]],"id":52671549},{"atl":[[270,0],[320,3.91]],"id":52671545},{"atl":[[3.45,0],[3.3,6.82]],"id":52671555},{"atl":[[190,0],[220,4.44]],"id":52671554}],"con":true,"img":false}]}
{"op":"mcm","clk":"11450259093","pt":1717319723506,"mc":[{"id":"1.229554908","rc":[{"atl":[[80,3.9]],"id":52671556}],"con":true,"img":false}]}
{"op":"mcm","clk":"11450259109","pt":1717319723662,"mc":[{"id":"1.229554908","rc":[{"atl":[[940,0]],"id":52671549}],"con":true,"img":false}]}
{"op":"mcm","clk":"11450259136","pt":1717319723878,"mc":[{"id":"1.229554908","rc":[{"atb":[[8,3.79],[8.4,4.45]],"id":52671545},{"atl":[[210,0]],"id":52671545},{"atl":[[150,5]],"id":52671554}],"con":true,"img":false}]}
{"op":"mcm","clk":"11450259148","pt":1717319723984,"mc":[{"id":"1.229554908","rc":[{"atl":[[140,0],[210,0]],"id":52671554}],"con":true,"img":false}]}
{"op":"mcm","clk":"11450259214","pt":1717319724588,"mc":[{"id":"1.229554908","rc":[{"atl":[[260,5.62]],"id":52671545}],"con":true,"img":false}]}
{"op":"mcm","clk":"11450259234","pt":1717319724799,"mc":[{"id":"1.229554908","rc":[{"atl":[[280,0.57]],"id":52671554}],"con":true,"img":false}]}
{"op":"mcm","clk":"11450259296","pt":1717319725473,"mc":[{"id":"1.229554908","rc":[{"atb":[[8.4,18.65]],"id":52671548}],"con":true,"img":false}]}
{"op":"mcm","clk":"11450259370","pt":1717319726303,"mc":[{"id":"1.229554908","rc":[{"atb":[[7.2,5]],"id":52671548}],"con":true,"img":false}]}
{"op":"mcm","clk":"11450259405","pt":1717319726670,"mc":[{"id":"1.229554908","rc":[{"atl":[[48,0],[50,8.27]],"id":52671542},{"atl":[[130,0]],"id":52671556}],"con":true,"img":false}]}
{"op":"mcm","clk":"11450259476","pt":1717319727402,"mc":[{"id":"1.229554908","rc":[{"atb":[[3.6,93.81],[4.2,32.66]],"id":52671550},{"atb":[[2.24,84.29],[2.04,234.52]],"id":52671546},{"atb":[[260,0.94],[360,0.29]],"id":52671549},{"atb":[[9.2,29.74],[13,8.71]],"id":52671548},{"atb":[[9.8,27.71],[14.5,7.74]],"id":52671542},{"atb":[[18.5,13.93],[27,4.01]],"id":52671545},{"atb":[[4.8,64.18],[5.8,21.77]],"id":52671544},{"atb":[[1.77,316.75],[1.87,120.15]],"id":52671555},{"atb":[[16.5,15.73],[23,9.51]],"id":52671554},{"atb":[[7.2,39.33],[9.2,12.74]],"id":52671556}],"con":true,"img":false}]}
{"op":"mcm","clk":"11450259496","pt":1717319727606,"mc":[{"id":"1.229554908","rc":[{"atl":[[32,8.39],[34,5]],"id":52671548}],"con":true,"img":false}]}
{"op":"mcm","clk":"11450259590","pt":1717319728797,"mc":[{"id":"1.229554908","rc":[{"atl":[[11.5,4.33]],"id":52671550},{"atl":[[3.4,36.63]],"id":52671555},{"atl":[[240,3.45]],"id":52671554}],"con":true,"img":false}]}
{"op":"mcm","clk":"11450259652","pt":1717319729514,"mc":[{"id":"1.229554908","rc":[{"atl":[[340,4.55]],"id":52671545}],"con":true,"img":false}]}
{"op":"mcm","clk":"11450259958","pt":1717319732983,"mc":[{"id":"1.229554908","rc":[{"atl":[[12.5,0]],"id":52671550},{"atl":[[380,0]],"id":52671545},{"atl":[[3.55,0]],"id":52671555}],"con":true,"img":false}]}
{"op":"mcm","clk":"11450260046","pt":1717319733809,"mc":[{"id":"1.229554908","rc":[{"atb":[[32,0],[40,5]],"id":52671554}],"con":true,"img":false}]}
{"op":"mcm","clk":"11450260066","pt":1717319734017,"mc":[{"id":"1.229554908","rc":[{"atl":[[140,1.15]],"id":52671554}],"con":true,"img":false}]}
{"op":"mcm","clk":"11450260121","pt":1717319734693,"mc":[{"id":"1.229554908","rc":[{"atl":[[280,0]],"id":52671554}],"con":true,"img":false}]}
{"op":"mcm","clk":"11450260159","pt":1717319735102,"mc":[{"id":"1.229554908","rc":[{"atl":[[300,4.59],[320,0]],"id":52671545}],"con":true,"img":false}]}
{"op":"mcm","clk":"11450260331","pt":1717319736920,"mc":[{"id":"1.229554908","rc":[{"atl":[[300,0],[320,2.64]],"id":52671545}],"con":true,"img":false}]}
{"op":"mcm","clk":"11450260508","pt":1717319739028,"mc":[{"id":"1.229554908","rc":[{"atl":[[10,4.56],[10.5,0]],"id":52671550},{"atl":[[3.35,6.68]],"id":52671555},{"atl":[[220,0],[230,4.57]],"id":52671554}],"con":true,"img":false}]}
{"op":"mcm","clk":"11450260517","pt":1717319739092,"mc":[{"id":"1.229554908","rc":[{"atl":[[3.3,0]],"id":52671555}],"con":true,"img":false}]}
{"op":"mcm","clk":"11450260542","pt":1717319739404,"mc":[{"id":"1.229554908","rc":[{"atl":[[160,2],[200,0]],"id":52671556}],"con":true,"img":false}]}
{"op":"mcm","clk":"11450260570","pt":1717319739718,"mc":[{"id":"1.229554908","rc":[{"atl":[[260,0.61],[280,5]],"id":52671545},{"atl":[[70,0],[55,4.38]],"id":52671556}],"con":true,"img":false}]}
{"op":"mcm","clk":"11450260582","pt":1717319739872,"mc":[{"id":"1.229554908","rc":[{"atl":[[10,0],[10.5,3.24]],"id":52671550},{"atl":[[970,2.74]],"id":52671549},{"atl":[[90,3.79],[95,0]],"id":52671542},{"atl":[[300,2.61],[320,0]],"id":52671545},{"atl":[[24,2.74],[25,0]],"id":52671544},{"atl":[[210,4.37],[230,0]],"id":52671554}],"con":true,"img":false}]}
{"op":"mcm","clk":"11450260608","pt":1717319740182,"mc":[{"id":"1.229554908","rc":[{"atl":[[55,7.35]],"id":52671556}],"con":true,"img":false}]}
{"op":"mcm","clk":"11450260654","pt":1717319740700,"mc":[{"id":"1.229554908","rc":[{"atl":[[10,3.5],[10.5,0]],"id":52671550},{"atl":[[970,0]],"id":52671549},{"atl":[[90,0],[95,4.05]],"id":52671542},{"atl":[[300,0],[320,4.56]],"id":52671545},{"atl":[[230,4.45]],"id":52671554}],"con":true,"img":false}]}
{"op":"mcm","clk":"11450260663","pt":1717319740803,"mc":[{"id":"1.229554908","rc":[{"atl":[[24,0],[25,4.47]],"id":52671544},{"atl":[[210,0]],"id":52671554}],"con":true,"img":false}]}
{"op":"mcm","clk":"11450260673","pt":1717319740909,"mc":[{"id":"1.229554908","rc":[{"atl":[[60,0]],"id":52671556}],"con":true,"img":false}]}
{"op":"mcm","clk":"11450260712","pt":1717319741322,"mc":[{"id":"1.229554908","rc":[{"atb":[[8.6,0],[5.4,2]],"id":52671549},{"atb":[[4.3,0],[5.4,15.37]],"id":52671542},{"atb":[[8.6,0],[10.5,6.46]],"id":52671545},{"atb":[[8.6,0],[10.5,9.54]],"id":52671554}],"con":true,"img":false}]}
{"op":"mcm","clk":"11450260739","pt":1717319741582,"mc":[{"id":"1.229554908","rc":[{"atl":[[10,0],[10.5,4.38]],"id":52671550},{"atb":[[8,0],[8.4,0]],"id":52671549},{"atl":[[970,4.23]],"id":52671549},{"atb":[[9.8,4.55]],"id":52671548},{"atl":[[90,3.01]],"id":52671542},{"atl":[[300,3.87],[320,0]],"id":52671545},{"atb":[[5.6,3.3],[4.5,0]],"id":52671544},{"atl":[[24,2.91],[25,0]],"id":52671544},{"atl":[[210,2.73],[230,0]],"id":52671554},{"atb":[[10.5,10.53],[11.5,0]],"id":52671556}],"con":true,"img":false}]}
{"op":"mcm","clk":"11450260744","pt":1717319741682,"mc":[{"id":"1.229554908","rc":[{"atb":[[8.4,14.29]],"id":52671548},{"atl":[[95,0]],"id":52671542}],"con":true,"img":false}]}
{"op":"mcm","clk":"11450260858","pt":1717319742874,"mc":[{"id":"1.229554908","rc":[{"atl":[[10.5,0]],"id":52671550},{"atl":[[970,0]],"id":52671549},{"atl":[[320,3.2]],"id":52671545}],"con":true,"img":false}]}
{"op":"mcm","clk":"11450260868","pt":1717319742973,"mc":[{"id":"1.229554908","rc":[{"atl":[[10,4.1]],"id":52671550},{"atl":[[90,0],[95,4.55]],"id":52671542},{"atl":[[300,0]],"id":52671545},{"atl":[[24,0],[25,4.09]],"id":52671544},{"atl":[[140,0],[210,0],[230,3.26]],"id":52671554}],"con":true,"img":false}]}
{"op":"mcm","clk":"11450260891","pt":1717319743181,"mc":[{"id":"1.229554908","rc":[{"atl":[[10.5,10.53],[14.5,0]],"id":52671550},{"atl":[[12,0],[8.4,8.56]],"id":52671546},{"atb":[[5.3,0],[5.9,14.15]],"id":52671548},{"atl":[[32,5.16],[42,2.44]],"id":52671548},{"atl":[[80,2],[100,3.68]],"id":52671542},{"atl":[[680,2],[890,0]],"id":52671545},{"atb":[[4.3,35.05],[3.9,0]],"id":52671544},{"atb":[[1.83,0],[2.04,96.15]],"id":52671555},{"atl":[[4.1,21.73],[3.4,6.53]],"id":52671555},{"atb":[[48,3.41]],"id":52671554},{"atl":[[290,0],[390,2]],"id":52671554},{"atb":[[9,12.5],[10.5,0]],"id":52671556},{"atl":[[130,2],[160,0]],"id":52671556}],"con":true,"img":false}]}
{"op":"mcm","clk":"11450260921","pt":1717319743492,"mc":[{"id":"1.229554908","rc":[{"atb":[[4.5,0],[5,0],[5.5,0],[6,0],[5.7,0]],"id":52671550},{"atl":[[5.8,2.79],[7.4,0]],"id":52671546},{"atb":[[10,3.14],[13.5,12.81],[9.8,0]],"id":52671548},{"atb":[[16.5,5],[21,0],[22,0]],"id":52671542},{"atl":[[280,0],[240,5]],"id":52671545},{"atb":[[2.24,67.81],[2.56,5]],"id":52671555},{"atl":[[3.35,0],[2.98,0]],"id":52671555},{"atl":[[46,4.11],[55,2.96]],"id":52671556}],"con":true,"img":false}]}
{"op":"mcm","clk":"11450260945","pt":1717319743702,"mc":[{"id":"1.229554908","rc":[{"atl":[[150,6.08]],"id":52671554}],"con":true,"img":false}]}
{"op":"mcm","clk":"11450260965","pt":1717319743919,"mc":[{"id":"1.229554908","rc":[{"atb":[[4.8,5]],"id":52671550},{"atl":[[5.7,34.09]],"id":52671546},{"atl":[[240,5.67]],"id":52671545},{"atb":[[2.56,35.13]],"id":52671555},{"atb":[[55,0.97]],"id":52671554}],"con":true,"img":false}]}
{"op":"mcm","clk":"11450260986","pt":1717319744218,"mc":[{"id":"1.229554908","rc":[{"atb":[[5.2,12.46],[5.7,5.57],[4.2,65.37],[3.65,6.17],[4.7,21.21]],"id":52671550},{"atb":[[8.4,0]],"id":52671548},{"atb":[[16,11.59]],"id":52671542},{"atl":[[3.45,5]],"id":52671555}],"con":true,"img":false}]}
{"op":"mcm","clk":"11450261007","pt":1717319744374,"mc":[{"id":"1.229554908","rc":[{"atl":[[3.5,6.27]],"id":52671555},{"atb":[[60,2.71]],"id":52671554}],"con":true,"img":false}]}
{"op":"mcm","clk":"11450261035","pt":1717319744686,"mc":[{"id":"1.229554908","rc":[{"atl":[[7.2,0]],"id":52671546},{"atl":[[260,0]],"id":52671545},{"atb":[[2.24,0]],"id":52671555}],"con":true,"img":false}]}
{"op":"mcm","clk":"11450261067","pt":1717319745104,"mc":[{"id":"1.229554908","rc":[{"atl":[[44,2.33]],"id":52671548},{"atb":[[48,0]],"id":52671554}],"con":true,"img":false}]}
{"op":"mcm","clk":"11450261077","pt":1717319745206,"mc":[{"id":"1.229554908","rc":[{"atl":[[42,0]],"id":52671548}],"con":true,"img":false}]}
{"op":"mcm","clk":"11450261089","pt":1717319745316,"mc":[{"id":"1.229554908","rc":[{"atl":[[34,0],[29,5]],"id":52671548}],"con":true,"img":false}]}
{"op":"mcm","clk":"11450261098","pt":1717319745413,"mc":[{"id":"1.229554908","rc":[{"atb":[[5.2,0],[5.7,0],[4.2,32.66],[4.7,0]],"id":52671550},{"atl":[[3.35,6.68],[3.4,0]],"id":52671555},{"atb":[[9.6,3.58],[10,3.6]],"id":52671556}],"con":true,"img":false}]}
{"op":"mcm","clk":"11450261130","pt":1717319745783,"mc":[{"id":"1.229554908","rc":[{"atl":[[29,10.73]],"id":52671548}],"con":true,"img":false}]}
{"op":"mcm","clk":"11450261152","pt":1717319746088,"mc":[{"id":"1.229554908","rc":[{"atb":[[5.6,5.69],[5.1,12.76],[4.6,21.8],[4.1,33.76]],"id":52671550}],"con":true,"img":false}]}
{"op":"mcm","clk":"11450261179","pt":1717319746502,"mc":[{"id":"1.229554908","rc":[{"atl":[[32,0]],"id":52671548}],"con":true,"img":false}]}
{"op":"mcm","clk":"11450261235","pt":1717319747074,"mc":[{"id":"1.229554908","rc":[{"atl":[[240,0.66],[250,5]],"id":52671545},{"atb":[[25,7.76]],"id":52671556}],"con":true,"img":false}]}
{"op":"mcm","clk":"11450261259","pt":1717319747382,"mc":[{"id":"1.229554908","rc":[{"atl":[[160,5]],"id":52671554}],"con":true,"img":false}]}
{"op":"mcm","clk":"11450261268","pt":1717319747487,"mc":[{"id":"1.229554908","rc":[{"atl":[[10,0],[10.5,14.27]],"id":52671550},{"atl":[[810,3.12],[830,4.16]],"id":52671549},{"atl":[[70,0],[75,3.29]],"id":52671548},{"atl":[[95,0]],"id":52671542},{"atl":[[320,0],[240,4.13]],"id":52671545},{"atl":[[25,0]],"id":52671544},{"atl":[[150,0],[180,3.23],[230,0]],"id":52671554}],"con":true,"img":false}]}
{"op":"mcm","clk":"11450261298","pt":1717319747794,"mc":[{"id":"1.229554908","rc":[{"atl":[[270,5],[240,3.46],[250,0]],"id":52671545}],"con":true,"img":false}]}
{"op":"mcm","clk":"11450261309","pt":1717319747900,"mc":[{"id":"1.229554908","rc":[{"atl":[[18,15.3]],"id":52671544}],"con":true,"img":false}]}
{"op":"mcm","clk":"11450261316","pt":1717319748001,"mc":[{"id":"1.229554908","rc":[{"atl":[[800,0.19]],"id":52671549},{"atl":[[17,5]],"id":52671544}],"con":true,"img":false}]}
{"op":"mcm","clk":"11450261325","pt":1717319748116,"mc":[{"id":"1.229554908","rc":[{"atl":[[17.5,6.06],[18,9.42]],"id":52671544}],"con":true,"img":false}]}
{"op":"mcm","clk":"11450261332","pt":1717319748206,"mc":[{"id":"1.229554908","rc":[{"atl":[[160,6.01]],"id":52671554}],"con":true,"img":false}]}
{"op":"mcm","clk":"11450261340","pt":1717319748311,"mc":[{"id":"1.229554908","rc":[{"atl":[[120,3.55]],"id":52671542},{"atb":[[5.4,3.73]],"id":52671544},{"atl":[[28,4.42]],"id":52671544}],"con":true,"img":false}]}
{"op":"mcm","clk":"11450261351","pt":1717319748417,"mc":[{"id":"1.229554908","rc":[{"atl":[[17,15.02]],"id":52671544}],"con":true,"img":false}]}
{"op":"mcm","clk":"11450261367","pt":1717319748623,"mc":[{"id":"1.229554908","rc":[{"atl":[[680,0],[760,2]],"id":52671545}],"con":true,"img":false}]}
{"op":"mcm","clk":"11450261385","pt":1717319748827,"mc":[{"id":"1.229554908","rc":[{"atl":[[5.8,7.8],[6,3.05],[9.4,0]],"id":52671546},{"atl":[[870,0]],"id":52671549},{"atb":[[7.2,0],[12,5]],"id":52671548},{"atl":[[270,0],[260,5]],"id":52671545},{"atl":[[44,5],[100,0]],"id":52671556}],"con":true,"img":false}]}
{"op":"mcm","clk":"11450261391","pt":1717319748878,"mc":[{"id":"1.229554908","rc":[{"atl":[[260,8.93],[240,0]],"id":52671545},{"atl":[[48,3.51]],"id":52671556}],"con":true,"img":false}]}
{"op":"mcm","clk":"11450261399","pt":1717319748980,"mc":[{"id":"1.229554908","rc":[{"atl":[[46,0]],"id":52671556}],"con":true,"img":false}]}
{"op":"mcm","clk":"11450261405","pt":1717319749087,"mc":[{"id":"1.229554908","rc":[{"atl":[[46,3.56]],"id":52671556}],"con":true,"img":false}]}
{"op":"mcm","clk":"11450261414","pt":1717319749192,"mc":[{"id":"1.229554908","rc":[{"atb":[[4.3,30.3]],"id":52671544},{"atl":[[18,0]],"id":52671544}],"con":true,"img":false}]}
{"op":"mcm","clk":"11450261430","pt":1717319749394,"mc":[{"id":"1.229554908","rc":[{"atl":[[250,0.64]],"id":52671545}],"con":true,"img":false}]}
{"op":"mcm","clk":"11450261441","pt":1717319749498,"mc":[{"id":"1.229554908","rc":[{"atl":[[44,0],[48,8.52]],"id":52671556}],"con":true,"img":false}]}
{"op":"mcm","clk":"11450261467","pt":1717319749910,"mc":[{"id":"1.229554908","rc":[{"atl":[[55,0]],"id":52671556}],"con":true,"img":false}]}
{"op":"mcm","clk":"11450261599","pt":1717319751821,"mc":[{"id":"1.229554908","rc":[{"atb":[[2.5,10.46],[2.52,0]],"id":52671546},{"atl":[[7.8,0]],"id":52671546},{"atb":[[1.92,0],[1.93,0]],"id":52671555}],"con":true,"img":false}]}
{"op":"mcm","clk":"11450261606","pt":1717319751925,"mc":[{"id":"1.229554908","rc":[{"atl":[[10.5,10.53],[11,3.66]],"id":52671550},{"atl":[[810,0]],"id":52671549},{"atl":[[95,2.69],[100,0]],"id":52671542},{"atl":[[24,2.89],[26,0]],"id":52671544},{"atl":[[3.35,0],[3.4,6.53]],"id":52671555}],"con":true,"img":false}]}
{"op":"mcm","clk":"11450261620","pt":1717319752132,"mc":[{"id":"1.229554908","rc":[{"atl":[[3.4,11.54]],"id":52671555}],"con":true,"img":false}]}
{"op":"mcm","clk":"11450261628","pt":1717319752187,"mc":[{"id":"1.229554908","rc":[{"atl":[[7.2,5],[9,12.05]],"id":52671550},{"atb":[[7.2,5],[6,18.14]],"id":52671544},{"atb":[[1.9,116.26]],"id":52671555},{"atl":[[3.45,0]],"id":52671555}],"con":true,"img":false}]}
{"op":"mcm","clk":"11450261663","pt":1717319752601,"mc":[{"id":"1.229554908","rc":[{"atl":[[7,24.36]],"id":52671550},{"atb":[[7.4,25.03]],"id":52671544}],"con":true,"img":false}]}
{"op":"mcm","clk":"11450261679","pt":1717319752706,"mc":[{"id":"1.229554908","rc":[{"atb":[[3.6,0],[4.2,0]],"id":52671550},{"atb":[[2.24,0],[3.6,5],[2.04,0]],"id":52671546},{"atb":[[260,0],[360,0]],"id":52671549},{"atl":[[850,3.22]],"id":52671549},{"atb":[[9.6,4.48],[9.2,0],[13,0]],"id":52671548},{"atb":[[9.8,0],[14.5,0]],"id":52671542},{"atb":[[18.5,0],[27,0]],"id":52671545},{"atb":[[4.8,0],[5.8,0]],"id":52671544},{"atb":[[1.89,17.63],[1.91,17.24],[1.77,0],[1.87,0]],"id":52671555},{"atb":[[16.5,0],[23,4.76]],"id":52671554},{"atl":[[200,2.86]],"id":52671554},{"atb":[[7.2,0],[9.2,0]],"id":52671556}],"con":true,"img":false}]}
{"op":"mcm","clk":"11450261690","pt":1717319752809,"mc":[{"id":"1.229554908","rc":[{"atb":[[3.65,0]],"id":52671546}],"con":true,"img":false}]}
{"op":"mcm","clk":"11450261722","pt":1717319753122,"mc":[{"id":"1.229554908","rc":[{"atb":[[16.5,15.34]],"id":52671542},{"atl":[[160,0],[170,5]],"id":52671554}],"con":true,"img":false}]}
{"op":"mcm","clk":"11450261743","pt":1717319753328,"mc":[{"id":"1.229554908","rc":[{"atl":[[9,0]],"id":52671550},{"atb":[[6,0]],"id":52671544}],"con":true,"img":false}]}
{"op":"mcm","clk":"11450261764","pt":1717319753488,"mc":[{"id":"1.229554908","rc":[{"atb":[[2.78,58.37]],"id":52671546},{"atl":[[70,2]],"id":52671542}],"con":true,"img":false}]}
{"op":"mcm","clk":"11450261771","pt":1717319753588,"mc":[{"id":"1.229554908","rc":[{"atl":[[9.2,12.2],[10.5,0]],"id":52671550},{"atl":[[7.2,15.62],[8.4,0]],"id":52671546},{"atb":[[7.4,14.15],[5.9,0]],"id":52671548},{"atl":[[36,2.86],[44,0]],"id":52671548},{"atl":[[80,0]],"id":52671542},{"atl":[[640,2],[760,0]],"id":52671545},{"atb":[[4.3,0],[5.1,16.35]],"id":52671544},{"atl":[[16.5,6.06],[17.5,0]],"id":52671544},{"atb":[[2.04,0],[2.16,70.28]],"id":52671555},{"atl":[[4.1,0],[3.65,23.1]],"id":52671555},{"atl":[[340,2],[390,0]],"id":52671554},{"atb":[[9,0],[10.5,10.02]],"id":52671556}],"con":true,"img":false}]}
{"op":"mcm","clk":"11450261794","pt":1717319753801,"mc":[{"id":"1.229554908","rc":[{"atb":[[5.6,2.91],[5.4,6.13]],"id":52671549},{"atb":[[8,0]],"id":52671548},{"atb":[[16,1.74]],"id":52671542},{"atl":[[170,5.95]],"id":52671554}],"con":true,"img":false}]}
{"op":"mcm","clk":"11450261804","pt":1717319753905,"mc":[{"id":"1.229554908","rc":[{"atl":[[5.8,5],[5.7,38.42]],"id":52671546},{"atb":[[5.6,2.75],[4.5,0]],"id":52671542},{"atb":[[10,4.33],[8.4,0]],"id":52671545},{"atl":[[240,0]],"id":52671554}],"con":true,"img":false}]}
{"op":"mcm","clk":"11450261829","pt":1717319754111,"mc":[{"id":"1.229554908","rc":[{"atl":[[260,5],[280,3.81]],"id":52671545},{"atl":[[24,0],[25,3.23]],"id":52671544},{"atl":[[180,0]],"id":52671554},{"atl":[[55,3.64]],"id":52671556}],"con":true,"img":false}]}
{"op":"mcm","clk":"11450261842","pt":1717319754216,"mc":[{"id":"1.229554908","rc":[{"atl":[[10.5,3.17],[11,0]],"id":52671550},{"atl":[[830,0],[930,3.13]],"id":52671549},{"atl":[[95,0],[100,4.13]],"id":52671542},{"atl":[[26,3.8]],"id":52671544},{"atl":[[3.35,6.68],[3.4,5]],"id":52671555}],"con":true,"img":false}]}
{"op":"mcm","clk":"11450261855","pt":1717319754328,"mc":[{"id":"1.229554908","rc":[{"atb":[[3.6,0],[3.55,5]],"id":52671546},{"atl":[[260,0],[270,5],[250,0]],"id":52671545},{"atl":[[170,0.94],[180,5]],"id":52671554}],"con":true,"img":false}]}
{"op":"mcm","clk":"11450261886","pt":1717319754633,"mc":[{"id":"1.229554908","rc":[{"atl":[[170,0]],"id":52671554}],"con":true,"img":false}]}
{"op":"mcm","clk":"11450261924","pt":1717319754996,"mc":[{"id":"1.229554908","rc":[{"atl":[[270,0],[280,4.38],[290,5]],"id":52671545},{"atl":[[180,0],[190,5]],"id":52671554}],"con":true,"img":false}]}
{"op":"mcm","clk":"11450261947","pt":1717319755307,"mc":[{"id":"1.229554908","rc":[{"atl":[[850,0]],"id":52671549},{"atl":[[25,0]],"id":52671544},{"atl":[[180,0.89]],"id":52671554},{"atl":[[80,0]],"id":52671556}],"con":true,"img":false}]}
{"op":"mcm","clk":"11450261972","pt":1717319755720,"mc":[{"id":"1.229554908","rc":[{"atl":[[280,3.81]],"id":52671545},{"atl":[[180,5.9],[190,0]],"id":52671554}],"con":true,"img":false}]}
{"op":"mcm","clk":"11450262084","pt":1717319757115,"mc":[{"id":"1.229554908","rc":[{"atl":[[16.5,16.39]],"id":52671544}],"con":true,"img":false}]}
{"op":"mcm","clk":"11450262133","pt":1717319757793,"mc":[{"id":"1.229554908","rc":[{"atl":[[17,5]],"id":52671544},{"atl":[[220,3.2]],"id":52671554}],"con":true,"img":false}]}
{"op":"mcm","clk":"11450262187","pt":1717319758510,"mc":[{"id":"1.229554908","rc":[{"atb":[[3.6,5],[3.55,0]],"id":52671546},{"atb":[[16.5,10.33],[17,5]],"id":52671542}],"con":true,"img":false}]}
{"op":"mcm","clk":"11450262237","pt":1717319759335,"mc":[{"id":"1.229554908","rc":[{"atl":[[950,3.41]],"id":52671549},{"atb":[[9.6,2.91]],"id":52671545},{"atl":[[300,3.85]],"id":52671545}],"con":true,"img":false}]}
{"op":"mcm","clk":"11450262248","pt":1717319759491,"mc":[{"id":"1.229554908","rc":[{"atl":[[65,2],[70,0]],"id":52671542}],"con":true,"img":false}]}
{"op":"mcm","clk":"11450262268","pt":1717319759799,"mc":[{"id":"1.229554908","rc":[{"atl":[[48,5],[55,8.65]],"id":52671556}],"con":true,"img":false}]}
{"op":"mcm","clk":"11450262278","pt":1717319759903,"mc":[{"id":"1.229554908","rc":[{"atl":[[48,0]],"id":52671556}],"con":true,"img":false}]}
{"op":"mcm","clk":"11450262322","pt":1717319760522,"mc":[{"id":"1.229554908","rc":[{"atb":[[21,0],[24,5]],"id":52671556}],"con":true,"img":false}]}
{"op":"mcm","clk":"11450262365","pt":1717319761042,"mc":[{"id":"1.229554908","rc":[{"atb":[[3.6,0]],"id":52671546},{"trd":[[3.6,10.01]],"ltp":3.6,"tv":10.01,"id":52671546}],"con":true,"img":false}]}
{"op":"mcm","clk":"11450262427","pt":1717319761712,"mc":[{"id":"1.229554908","rc":[{"atb":[[3.6,5]],"id":52671546},{"atl":[[5.6,5.32]],"id":52671546},{"atb":[[17,15.02]],"id":52671542},{"atb":[[8,0]],"id":52671545},{"atl":[[340,0]],"id":52671545}],"con":true,"img":false}]}
{"op":"mcm","clk":"11450262439","pt":1717319761816,"mc":[{"id":"1.229554908","rc":[{"trd":[[46,2.61]],"ltp":46.0,"tv":2.61,"id":52671556},{"atl":[[46,2.25]],"id":52671556}],"con":true,"img":false}]}
{"op":"mcm","clk":"11450262467","pt":1717319762125,"mc":[{"id":"1.229554908","rc":[{"atl":[[5.5,23.71]],"id":52671546}],"con":true,"img":false}]}
{"op":"mcm","clk":"11450262478","pt":1717319762228,"mc":[{"id":"1.229554908","rc":[{"atb":[[3.65,23.71]],"id":52671546}],"con":true,"img":false}]}
{"op":"mcm","clk":"11450262485","pt":1717319762333,"mc":[{"id":"1.229554908","rc":[{"atb":[[3.1,10.6]],"id":52671546}],"con":true,"img":false}]}
{"op":"mcm","clk":"11450262492","pt":1717319762435,"mc":[{"id":"1.229554908","rc":[{"atb":[[2.78,19.25]],"id":52671546}],"con":true,"img":false}]}
{"op":"mcm","clk":"11450262504","pt":1717319762540,"mc":[{"id":"1.229554908","rc":[{"atb":[[16.5,0]],"id":52671542},{"atb":[[26,1.39]],"id":52671556}],"con":true,"img":false}]}
{"op":"mcm","clk":"11450262516","pt":1717319762642,"mc":[{"id":"1.229554908","rc":[{"atl":[[46,0]],"id":52671556}],"con":true,"img":false}]}
{"op":"mcm","clk":"11450262550","pt":1717319762902,"mc":[{"id":"1.229554908","rc":[{"atb":[[2.78,0]],"id":52671546},{"atl":[[5.7,4.33]],"id":52671546}],"con":true,"img":false}]}
{"op":"mcm","clk":"11450262563","pt":1717319763003,"mc":[{"id":"1.229554908","rc":[{"atb":[[27,6.16]],"id":52671556}],"con":true,"img":false}]}
{"op":"mcm","clk":"11450262594","pt":1717319763316,"mc":[{"id":"1.229554908","rc":[{"atl":[[55,11.61]],"id":52671556}],"con":true,"img":false}]}
{"op":"mcm","clk":"11450262618","pt":1717319763577,"mc":[{"id":"1.229554908","rc":[{"atb":[[2.5,9.42]],"id":52671546}],"con":true,"img":false}]}
{"op":"mcm","clk":"11450262634","pt":1717319763733,"mc":[{"id":"1.229554908","rc":[{"atb":[[25,1.09]],"id":52671556}],"con":true,"img":false}]}
{"op":"mcm","clk":"11450262745","pt":1717319764821,"mc":[{"id":"1.229554908","rc":[{"atb":[[3.4,101.62],[3.9,36.04]],"id":52671550},{"atb":[[2.36,76.85],[2.16,210.26]],"id":52671546},{"atb":[[300,0.35],[200,1.22]],"id":52671549},{"atb":[[9,30.48],[12.5,9.08]],"id":52671548},{"atb":[[9.8,27.71],[14.5,7.74]],"id":52671542},{"atb":[[19.5,13.18],[29,3.73]],"id":52671545},{"atb":[[5.1,75.84],[6.2,20.1]],"id":52671544},{"atl":[[16.5,21.4],[17,0]],"id":52671544},{"atb":[[1.73,334.11],[1.83,125.93]],"id":52671555},{"atb":[[16.5,15.73],[23,9.51]],"id":52671554},{"atb":[[9,13.06],[7,40.65]],"id":52671556}],"con":true,"img":false}]}
{"op":"mcm","clk":"11450262755","pt":1717319764924,"mc":[{"id":"1.229554908","rc":[{"atl":[[65,4.65]],"id":52671556}],"con":true,"img":false}]}
{"op":"mcm","clk":"11450262775","pt":1717319765234,"mc":[{"id":"1.229554908","rc":[{"atl":[[280,4.38]],"id":52671545}],"con":true,"img":false}]}
{"op":"mcm","clk":"11450262822","pt":1717319765901,"mc":[{"id":"1.229554908","rc":[{"atl":[[44,5],[50,3.26]],"id":52671542}],"con":true,"img":false}]}
{"op":"mcm","clk":"11450262851","pt":1717319766311,"mc":[{"id":"1.229554908","rc":[{"atl":[[44,8.73]],"id":52671542}],"con":true,"img":false}]}
{"op":"mcm","clk":"11450262905","pt":1717319767032,"mc":[{"id":"1.229554908","rc":[{"atl":[[50,0]],"id":52671542}],"con":true,"img":false}]}
{"op":"mcm","clk":"11450263074","pt":1717319769360,"mc":[{"id":"1.229554908","rc":[{"atl":[[44,0],[46,5]],"id":52671542}],"con":true,"img":false}]}
{"op":"mcm","clk":"11450263112","pt":1717319769917,"mc":[{"id":"1.229554908","rc":[{"atl":[[50,3.61]],"id":52671556}],"con":true,"img":false}]}
{"op":"mcm","clk":"11450263120","pt":1717319770018,"mc":[{"id":"1.229554908","rc":[{"atb":[[2.5,0],[2.48,0]],"id":52671546},{"atl":[[930,0],[960,3.85]],"id":52671549},{"atl":[[46,0],[60,2.71]],"id":52671542},{"atb":[[1.89,0],[1.91,0]],"id":52671555},{"atl":[[200,0],[210,2.88]],"id":52671554},{"atl":[[55,7.97]],"id":52671556}],"con":true,"img":false}]}
{"op":"mcm","clk":"11450263132","pt":1717319770223,"mc":[{"id":"1.229554908","rc":[{"atl":[[5.4,5.32]],"id":52671546}],"con":true,"img":false}]}
{"op":"mcm","clk":"11450263160","pt":1717319770637,"mc":[{"id":"1.229554908","rc":[{"atl":[[5.3,23.92]],"id":52671546}],"con":true,"img":false}]}
{"op":"mcm","clk":"11450263166","pt":1717319770739,"mc":[{"id":"1.229554908","rc":[{"atl":[[44,5]],"id":52671542}],"con":true,"img":false}]}
{"op":"mcm","clk":"11450263180","pt":1717319770946,"mc":[{"id":"1.229554908","rc":[{"atl":[[5.6,0]],"id":52671546},{"atb":[[28,1.39]],"id":52671556}],"con":true,"img":false}]}
{"op":"mcm","clk":"11450263200","pt":1717319771254,"mc":[{"id":"1.229554908","rc":[{"atb":[[2.86,40.88]],"id":52671546}],"con":true,"img":false}]}
{"op":"mcm","clk":"11450263207","pt":1717319771357,"mc":[{"id":"1.229554908","rc":[{"atb":[[3.1,0]],"id":52671546}],"con":true,"img":false}]}
{"op":"mcm","clk":"11450263219","pt":1717319771461,"mc":[{"id":"1.229554908","rc":[{"atl":[[5.5,0]],"id":52671546},{"atb":[[28,7.32]],"id":52671556}],"con":true,"img":false}]}
{"op":"mcm","clk":"11450263226","pt":1717319771516,"mc":[{"id":"1.229554908","rc":[{"atl":[[950,0]],"id":52671549}],"con":true,"img":false}]}
{"op":"mcm","clk":"11450263259","pt":1717319772029,"mc":[{"id":"1.229554908","rc":[{"atb":[[2.38,29.2],[2.34,10.55]],"id":52671546},{"atl":[[960,0]],"id":52671549},{"atl":[[70,2.8],[75,0]],"id":52671548},{"atl":[[90,4.07],[100,0]],"id":52671542},{"atl":[[280,0.57],[340,3.46]],"id":52671545},{"atl":[[25,3.98],[26,0]],"id":52671544},{"atl":[[3.45,6.4],[3.35,0]],"id":52671555},{"atl":[[210,0],[240,4.65]],"id":52671554},{"atb":[[26,0]],"id":52671556}],"con":true,"img":false}]}
{"op":"mcm","clk":"11450263266","pt":1717319772132,"mc":[{"id":"1.229554908","rc":[{"atb":[[27,0]],"id":52671556}],"con":true,"img":false}]}
{"op":"mcm","clk":"11450263451","pt":1717319774046,"mc":[{"id":"1.229554908","rc":[{"atl":[[11,3.85]],"id":52671550},{"atl":[[70,0],[75,3.29]],"id":52671548},{"atl":[[320,3.84]],"id":52671545},{"atl":[[25,0]],"id":52671544},{"atl":[[3.45,0]],"id":52671555},{"atl":[[220,0]],"id":52671554}],"con":true,"img":false}]}
{"op":"mcm","clk":"11450263462","pt":1717319774151,"mc":[{"id":"1.229554908","rc":[{"atl":[[10.5,0]],"id":52671550},{"atl":[[300,0]],"id":52671545},{"atl":[[24,3.84]],"id":52671544},{"atl":[[250,3.47]],"id":52671554}],"con":true,"img":false}]}
{"op":"mcm","clk":"11450263524","pt":1717319774767,"mc":[{"id":"1.229554908","rc":[{"atl":[[34,3.03],[36,0]],"id":52671548},{"atl":[[44,8.73]],"id":52671542}],"con":true,"img":false}]}
{"op":"mcm","clk":"11450263552","pt":1717319775027,"mc":[{"id":"1.229554908","rc":[{"atl":[[5.8,8.13],[5.7,0]],"id":52671546},{"atl":[[240,0]],"id":52671554}],"con":true,"img":false}]}
{"op":"mcm","clk":"11450263574","pt":1717319775336,"mc":[{"id":"1.229554908","rc":[{"atl":[[10.5,4.15],[11,0]],"id":52671550},{"atl":[[65,4.34],[75,0]],"id":52671548},{"atl":[[85,4.69],[90,0]],"id":52671542},{"atl":[[320,0],[330,4.38]],"id":52671545},{"atl":[[3.45,6.4]],"id":52671555}],"con":true,"img":false}]}
{"op":"mcm","clk":"11450263581","pt":1717319775438,"mc":[{"id":"1.229554908","rc":[{"atl":[[60,0]],"id":52671542}],"con":true,"img":false}]}
{"op":"mcm","clk":"11450263694","pt":1717319776632,"mc":[{"id":"1.229554908","rc":[{"atl":[[65,0],[70,4.59]],"id":52671548},{"atl":[[85,0],[90,2.95]],"id":52671542},{"atl":[[330,0]],"id":52671545},{"atl":[[24,0],[25,4.38]],"id":52671544},{"atl":[[3.45,0]],"id":52671555}],"con":true,"img":false}]}
{"op":"mcm","clk":"11450263743","pt":1717319777152,"mc":[{"id":"1.229554908","rc":[{"atb":[[75,5],[40,0]],"id":52671554}],"con":true,"img":false}]}
{"op":"mcm","clk":"11450263789","pt":1717319777669,"mc":[{"id":"1.229554908","rc":[{"atb":[[80,2.02]],"id":52671554}],"con":true,"img":false}]}
{"op":"mcm","clk":"11450263849","pt":1717319778343,"mc":[{"id":"1.229554908","rc":[{"atl":[[10.5,0],[11,4.34]],"id":52671550},{"atl":[[70,0],[75,3.34]],"id":52671548},{"atl":[[280,0],[320,4.49]],"id":52671545},{"atl":[[24,3.35],[25,0]],"id":52671544},{"atb":[[60,0]],"id":52671554}],"con":true,"img":false}]}
{"op":"mcm","clk":"11450263869","pt":1717319778552,"mc":[{"id":"1.229554908","rc":[{"atl":[[5.2,5.32]],"id":52671546}],"con":true,"img":false}]}
{"op":"mcm","clk":"11450263894","pt":1717319778858,"mc":[{"id":"1.229554908","rc":[{"atl":[[270,3.51]],"id":52671554}],"con":true,"img":false}]}
{"op":"mcm","clk":"11450263901","pt":1717319778959,"mc":[{"id":"1.229554908","rc":[{"atl":[[5.1,29.36]],"id":52671546}],"con":true,"img":false}]}
{"op":"mcm","clk":"11450263911","pt":1717319779064,"mc":[{"id":"1.229554908","rc":[{"atl":[[290,5.56]],"id":52671545}],"con":true,"img":false}]}
{"op":"mcm","clk":"11450263914","pt":1717319779165,"mc":[{"id":"1.229554908","rc":[{"atb":[[2.56,30.12],[2.54,5]],"id":52671555}],"con":true,"img":false}]}
