{"op":"mcm","clk":"11449075393","pt":1717303241532,"mc":[{"id":"1.229554902","marketDefinition":{"bspMarket":false,"turnInPlayEnabled":false,"persistenceEnabled":false,"marketBaseRate":7.0,"eventId":"33318908","eventTypeId":"4339","numberOfWinners":1,"bettingType":"ODDS","marketType":"EXACTA","marketTime":"2024-06-02T08:59:00.000Z","suspendTime":"2024-06-02T08:59:00.000Z","bspReconciled":false,"complete":true,"inPlay":false,"crossMatching":true,"runnersVoidable":false,"numberOfActiveRunners":30,"betDelay":0,"status":"OPEN","runners":[{"status":"ACTIVE","sortPriority":1,"id":52385882,"name":"1 - 2"},{"status":"ACTIVE","sortPriority":2,"id":52385884,"name":"1 - 4"},{"status":"ACTIVE","sortPriority":3,"id":52385885,"name":"1 - 5"},{"status":"ACTIVE","sortPriority":4,"id":52385887,"name":"1 - 7"},{"status":"ACTIVE","sortPriority":5,"id":52385888,"name":"1 - 8"},{"status":"ACTIVE","sortPriority":6,"id":52385889,"name":"2 - 1"},{"status":"ACTIVE","sortPriority":7,"id":52385891,"name":"2 - 4"},{"status":"ACTIVE","sortPriority":8,"id":52385892,"name":"2 - 5"},{"status":"ACTIVE","sortPriority":9,"id":52385894,"name":"2 - 7"},{"status":"ACTIVE","sortPriority":10,"id":52385895,"name":"2 - 8"},{"status":"ACTIVE","sortPriority":11,"id":52385903,"name":"4 - 1"},{"status":"ACTIVE","sortPriority":12,"id":52385904,"name":"4 - 2"},{"status":"ACTIVE","sortPriority":13,"id":52385906,"name":"4 - 5"},{"status":"ACTIVE","sortPriority":14,"id":52385908,"name":"4 - 7"},{"status":"ACTIVE","sortPriority":15,"id":52385909,"name":"4 - 8"},{"status":"ACTIVE","sortPriority":16,"id":52385910,"name":"5 - 1"},{"status":"ACTIVE","sortPriority":17,"id":52385911,"name":"5 - 2"},{"status":"ACTIVE","sortPriority":18,"id":52385913,"name":"5 - 4"},{"status":"ACTIVE","sortPriority":19,"id":52385915,"name":"5 - 7"},{"status":"ACTIVE","sortPriority":20,"id":52385916,"name":"5 - 8"},{"status":"ACTIVE","sortPriority":21,"id":52385924,"name":"7 - 1"},{"status":"ACTIVE","sortPriority":22,"id":52385925,"name":"7 - 2"},{"status":"ACTIVE","sortPriority":23,"id":52385927,"name":"7 - 4"},{"status":"ACTIVE","sortPriority":24,"id":52385928,"name":"7 - 5"},{"status":"ACTIVE","sortPriority":25,"id":52385930,"name":"7 - 8"},{"status":"ACTIVE","sortPriority":26,"id":52385931,"name":"8 - 1"},{"status":"ACTIVE","sortPriority":27,"id":52385932,"name":"8 - 2"},{"status":"ACTIVE","sortPriority":28,"id":52385934,"name":"8 - 4"},{"status":"ACTIVE","sortPriority":29,"id":52385935,"name":"8 - 5"},{"status":"ACTIVE","sortPriority":30,"id":52385937,"name":"8 - 7"}],"regulators":["MR_INT"],"venue":"Murray Bridge","countryCode":"AU","discountAllowed":true,"timezone":"Australia/Adelaide","openDate":"2024-06-02T08:21:00.000Z","version":5962801940,"name":"Exacta","eventName":"Murray Bridge (AUS) 2nd Jun"},"rc":[],"con":true,"img":false}]}
{"op":"mcm","clk":"11449095056","pt":1717303714149,"mc":[{"id":"1.229554902","rc":[{"atb":[[840,0.13],[890,0.09],[940,0.06],[990,0.03]],"id":52385894},{"atb":[[170,0.31],[85,1.25],[220,0.12],[120,0.66]],"id":52385895},{"atb":[[160,0.16],[80,0.99],[110,0.48],[55,1.94]],"id":52385927},{"atb":[[70,0.76],[38,2.83],[95,0.28],[48,1.67]],"id":52385928},{"atb":[[130,0.2],[65,1.22],[90,0.59],[46,2.32]],"id":52385924},{"atb":[[65,0.82],[36,2.99],[90,0.29],[46,1.74]],"id":52385908},{"atb":[[17.5,1.59],[10,11.63],[12.5,6.82],[15,3.74]],"id":52385934},{"atb":[[85,0.62],[44,2.43],[120,0.22],[60,1.33]],"id":52385904},{"atb":[[8,3.74],[5.5,23.25],[6,15.7],[7,8.72]],"id":52385916},{"atb":[[9.2,9.57],[10.5,5.51],[8.2,14.53],[13,2.18]],"id":52385884}],"con":true,"img":false}]}
{"op":"mcm","clk":"11449095072","pt":1717303714618,"mc":[{"id":"1.229554902","rc":[{"atb":[[3.1,24.91],[3.35,11.13],[2.84,56.87],[2.94,40.45]],"id":52385910},{"atb":[[8,11.21],[9,6.54],[10,2.91],[7,17.44]],"id":52385906},{"atb":[[70,0.38],[38,2.12],[48,1.11],[29,3.74]],"id":52385887},{"atb":[[130,0.41],[65,1.64],[180,0.15],[90,0.88]],"id":52385889},{"atb":[[8,3.74],[5.5,23.25],[6,15.7],[7,8.72]],"id":52385885},{"atb":[[130,0.2],[65,1.22],[90,0.59],[46,2.32]],"id":52385892},{"atb":[[840,0.13],[890,0.09],[940,0.06],[990,0.03]],"id":52385925},{"atb":[[11,2.62],[7.4,16.35],[8.4,10.61],[9.4,6.23]],"id":52385935},{"atb":[[70,0.76],[38,2.83],[95,0.28],[48,1.67]],"id":52385937},{"atb":[[9,13.08],[10,8.72],[12.5,4.55],[15,1.87]],"id":52385931},{"atb":[[32,2.53],[42,1.28],[26,4.19],[55,0.49]],"id":52385911},{"atb":[[2.86,28.13],[2.66,63.03],[2.96,13.35],[2.76,44.59]],"id":52385913},{"atb":[[17.5,1.59],[10,11.63],[12.5,6.82],[15,3.74]],"id":52385909},{"atb":[[11,5.23],[13.5,2.09],[8.4,14.14],[9.4,9.34]],"id":52385888},{"atb":[[65,0.82],[36,2.99],[90,0.29],[46,1.74]],"id":52385882},{"atb":[[32,1.69],[42,0.64],[21,5.23],[26,3.14]],"id":52385915},{"atb":[[160,0.33],[80,1.32],[210,0.13],[110,0.72]],"id":52385891},{"atb":[[9.6,9.12],[8.6,13.77],[11.5,4.98],[14,2.01]],"id":52385903},{"atb":[[160,0.16],[80,0.99],[110,0.48],[55,1.94]],"id":52385930},{"atb":[[85,0.62],[44,2.43],[120,0.22],[60,1.33]],"id":52385932}],"con":true,"img":false}]}
{"op":"mcm","clk":"11449096090","pt":1717303745750,"mc":[{"id":"1.229554902","rc":[{"atb":[[130,0],[65,0],[90,0],[46,0]],"id":52385924},{"atb":[[9.6,0],[8.6,0],[11.5,0],[14,0]],"id":52385903}],"con":true,"img":false}]}
{"op":"mcm","clk":"11449096125","pt":1717303746771,"mc":[{"id":"1.229554902","rc":[{"atb":[[12,4.76],[9.8,8.92],[8.8,13.41],[14.5,1.94]],"id":52385903}],"con":true,"img":false}]}
{"op":"mcm","clk":"11449096323","pt":1717303752954,"mc":[{"id":"1.229554902","rc":[{"atb":[[140,0.19],[70,1.14],[95,0.55],[48,2.23]],"id":52385924}],"con":true,"img":false}]}
{"op":"mcm","clk":"11449099376","pt":1717303849458,"mc":[{"id":"1.229554902","rc":[{"atb":[[3.25,108.4],[3.75,38]],"id":52385910},{"atb":[[3.95,82.67],[4.9,26.8]],"id":52385906},{"atb":[[19,13.55],[28,3.87]],"id":52385908},{"atb":[[16.5,15.73],[23,4.75]],"id":52385887},{"atb":[[20,12.83],[30,3.6]],"id":52385889},{"atb":[[4.6,29.03],[3.8,87.1]],"id":52385916},{"atb":[[3.6,93.81],[4.2,32.66]],"id":52385885},{"atb":[[550,0.44],[650,0.16]],"id":52385894},{"atb":[[36,2.98],[23,11.08]],"id":52385927},{"atb":[[16,16.26],[22,4.97]],"id":52385892},{"atb":[[550,0.44],[650,0.16]],"id":52385925},{"atb":[[5.1,25.49],[4.1,78.68]],"id":52385935},{"atb":[[20,12.83],[30,3.6]],"id":52385904},{"atb":[[19.5,13.18],[29,3.73]],"id":52385937},{"atb":[[5.3,56.72],[6.6,18.66]],"id":52385931},{"atb":[[18,6.14],[13,20.32]],"id":52385911},{"atb":[[4.3,31.67],[3.65,92.03]],"id":52385913},{"atb":[[5.8,50.81],[7.6,15.83]],"id":52385909},{"atb":[[5.1,59.49],[6.2,20.1]],"id":52385888},{"atb":[[17.5,14.77],[25,4.35]],"id":52385882},{"atb":[[18,6.14],[13,20.32]],"id":52385915},{"atb":[[4.9,62.54],[5.9,21.33]],"id":52385884},{"atb":[[44,2.43],[27,9.38]],"id":52385895},{"atb":[[21,5.22],[15.5,16.82]],"id":52385928},{"atb":[[40,2.67],[25,10.16]],"id":52385891},{"atb":[[19,13.55],[28,3.87]],"id":52385924},{"atb":[[5.8,50.81],[7.6,15.83]],"id":52385934},{"atb":[[5.1,59.49],[6.2,20.1]],"id":52385903},{"atb":[[38,2.82],[24,10.6]],"id":52385930},{"atb":[[34,3.16],[22,11.61]],"id":52385932}],"con":true,"img":false}]}
{"op":"mcm","clk":"11449099411","pt":1717303850436,"mc":[{"id":"1.229554902","rc":[{"atb":[[2.86,0],[2.66,0],[2.96,0],[2.76,0]],"id":52385913}],"con":true,"img":false}]}
{"op":"mcm","clk":"11449099429","pt":1717303851105,"mc":[{"id":"1.229554902","rc":[{"atb":[[2.86,28.13],[2.66,63.03],[2.96,13.35],[2.76,44.59]],"id":52385913}],"con":true,"img":false}]}
{"op":"mcm","clk":"11449182626","pt":1717305248480,"mc":[{"id":"1.229554902","rc":[{"atb":[[3.1,0],[3.35,0],[2.84,0],[2.94,0]],"id":52385910},{"atb":[[8,0],[9,0],[10,0],[7,0]],"id":52385906},{"atb":[[8,0],[5.5,0],[6,0],[7,0]],"id":52385916}],"con":true,"img":false}]}
{"op":"mcm","clk":"11449182680","pt":1717305249306,"mc":[{"id":"1.229554902","rc":[{"atb":[[7.2,16.88],[9.2,6.38],[10.5,2.75],[8.2,10.9]],"id":52385906},{"atb":[[6.4,4.84],[5.2,18.68],[5.7,11.13],[4.7,28.28]],"id":52385916}],"con":true,"img":false}]}
{"op":"mcm","clk":"11449182688","pt":1717305249358,"mc":[{"id":"1.229554902","rc":[{"atb":[[4.8,27.54],[5.8,10.9],[5.3,18.25],[6.6,4.67]],"id":52385910}],"con":true,"img":false}]}
{"op":"mcm","clk":"11449189791","pt":1717305345764,"mc":[{"id":"1.229554902","rc":[{"atb":[[2.86,0],[2.66,0],[2.96,0],[2.76,0]],"id":52385913}],"con":true,"img":false}]}
{"op":"mcm","clk":"11449189840","pt":1717305346437,"mc":[{"id":"1.229554902","rc":[{"atb":[[3.45,42.71],[3.95,17.74],[3.7,29.07],[4.4,7.7]],"id":52385913}],"con":true,"img":false}]}
{"op":"mcm","clk":"11449270306","pt":1717306451953,"mc":[{"id":"1.229554902","rc":[{"atb":[[3.45,0],[3.95,0],[3.7,0],[4.4,0]],"id":52385913}],"con":true,"img":false}]}
{"op":"mcm","clk":"11449270366","pt":1717306452678,"mc":[{"id":"1.229554902","rc":[{"atb":[[3.45,42.71],[3.95,17.74],[3.7,29.07],[4.4,7.7]],"id":52385913}],"con":true,"img":false}]}
{"op":"mcm","clk":"11449276413","pt":1717306536602,"mc":[{"id":"1.229554902","rc":[{"atb":[[70,0],[38,0],[48,0],[29,0]],"id":52385887},{"atb":[[130,0],[65,0],[180,0],[90,0]],"id":52385889},{"atb":[[160,0],[80,0],[110,0],[55,0]],"id":52385927},{"atb":[[130,0],[65,0],[90,0],[46,0]],"id":52385892}],"con":true,"img":false}]}
{"op":"mcm","clk":"11449276419","pt":1717306536720,"mc":[{"id":"1.229554902","rc":[{"atb":[[65,0],[36,0],[90,0],[46,0]],"id":52385908},{"atb":[[70,0],[38,0],[95,0],[48,0]],"id":52385937}],"con":true,"img":false}]}
{"op":"mcm","clk":"11449276431","pt":1717306536808,"mc":[{"id":"1.229554902","rc":[{"atb":[[65,0],[36,0],[90,0],[46,0]],"id":52385882},{"atb":[[32,0],[42,0],[21,0],[26,0]],"id":52385915},{"atb":[[170,0],[85,0],[220,0],[120,0]],"id":52385895},{"atb":[[70,0],[38,0],[95,0],[48,0]],"id":52385928},{"atb":[[160,0],[80,0],[210,0],[110,0]],"id":52385891},{"atb":[[140,0],[70,0],[95,0],[48,0]],"id":52385924},{"atb":[[160,0],[80,0],[110,0],[55,0]],"id":52385930},{"atb":[[85,0],[44,0],[120,0],[60,0]],"id":52385932}],"con":true,"img":false}]}
{"op":"mcm","clk":"11449276468","pt":1717306537270,"mc":[{"id":"1.229554902","rc":[{"atb":[[75,0.36],[40,2.01],[50,1.07],[30,3.61]],"id":52385887},{"atb":[[150,0.35],[75,1.41],[200,0.13],[100,0.8]],"id":52385889},{"atb":[[170,0.16],[85,0.94],[120,0.44],[60,1.77]],"id":52385927},{"atb":[[140,0.19],[70,1.14],[95,0.55],[48,2.23]],"id":52385892}],"con":true,"img":false}]}
{"op":"mcm","clk":"11449276478","pt":1717306537374,"mc":[{"id":"1.229554902","rc":[{"atb":[[70,0.76],[38,2.83],[95,0.28],[48,1.67]],"id":52385908},{"atb":[[75,0.71],[40,2.68],[100,0.27],[50,1.6]],"id":52385937}],"con":true,"img":false}]}
{"op":"mcm","clk":"11449276487","pt":1717306537475,"mc":[{"id":"1.229554902","rc":[{"atb":[[130,0.41],[65,1.64],[180,0.15],[90,0.88]],"id":52385930}],"con":true,"img":false}]}
{"op":"mcm","clk":"11449276495","pt":1717306537578,"mc":[{"id":"1.229554902","rc":[{"atb":[[70,0.76],[38,2.83],[95,0.28],[48,1.67]],"id":52385882},{"atb":[[34,1.59],[44,0.61],[22,4.98],[27,3.02]],"id":52385915},{"atb":[[140,0.57],[190,0.28],[95,1.11],[240,0.11]],"id":52385895},{"atb":[[80,0.66],[42,2.55],[110,0.24],[55,1.45]],"id":52385928},{"atb":[[130,0.61],[180,0.29],[90,1.18],[230,0.12]],"id":52385891},{"atb":[[150,0.18],[75,1.06],[100,0.53],[50,2.13]],"id":52385924},{"atb":[[130,0.2],[65,1.22],[90,0.59],[46,2.32]],"id":52385932}],"con":true,"img":false}]}
{"op":"mcm","clk":"11449342311","pt":1717307456955,"mc":[{"id":"1.229554902","rc":[{"atb":[[6.4,0],[5.2,0],[5.7,0],[4.7,0]],"id":52385916},{"atb":[[11,0],[7.4,0],[8.4,0],[9.4,0]],"id":52385935},{"atb":[[75,0],[40,0],[100,0],[50,0]],"id":52385937},{"atb":[[9,0],[10,0],[12.5,0],[15,0]],"id":52385931},{"atb":[[34,0],[44,0],[22,0],[27,0]],"id":52385915},{"atb":[[140,0],[190,0],[95,0],[240,0]],"id":52385895},{"atb":[[80,0],[42,0],[110,0],[55,0]],"id":52385928},{"atb":[[17.5,0],[10,0],[12.5,0],[15,0]],"id":52385934},{"atb":[[130,0],[65,0],[180,0],[90,0]],"id":52385930},{"atb":[[130,0],[65,0],[90,0],[46,0]],"id":52385932}],"con":true,"img":false}]}
{"op":"mcm","clk":"11449342358","pt":1717307457623,"mc":[{"id":"1.229554902","rc":[{"atb":[[170,0.31],[85,1.25],[220,0.12],[120,0.66]],"id":52385895}],"con":true,"img":false}]}
{"op":"mcm","clk":"11449342364","pt":1717307457726,"mc":[{"id":"1.229554902","rc":[{"atb":[[4.5,29.89],[5,19.62],[5.5,11.63],[6,5.23]],"id":52385916},{"atb":[[4.3,7.93],[3.4,43.6],[3.9,18.04],[3.65,29.61]],"id":52385935},{"atb":[[19.5,18.84],[38,0.71],[24,3.41],[29,5.6]],"id":52385937},{"atb":[[8,14.95],[9,9.81],[10,5.81],[12.5,2.28]],"id":52385931},{"atb":[[32,1.69],[42,0.64],[21,5.23],[26,3.14]],"id":52385915},{"atb":[[70,0.76],[38,2.83],[95,0.28],[48,1.67]],"id":52385928},{"atb":[[8,11.21],[9,6.54],[10,2.91],[7,17.44]],"id":52385934},{"atb":[[130,0.2],[65,1.22],[90,0.59],[46,2.32]],"id":52385930},{"atb":[[32,3.37],[80,0.33],[42,1.92],[55,0.97]],"id":52385932}],"con":true,"img":false}]}
{"op":"mcm","clk":"11449352157","pt":1717307687114,"mc":[{"id":"1.229554902","rc":[{"atb":[[3.45,0],[3.95,0],[3.7,0],[4.4,0]],"id":52385913}],"con":true,"img":false}]}
{"op":"mcm","clk":"11449352200","pt":1717307687833,"mc":[{"id":"1.229554902","rc":[{"atb":[[6.8,9.02],[7.8,3.85],[5.9,16.01],[5.4,23.78]],"id":52385913}],"con":true,"img":false}]}
{"op":"mcm","clk":"11449367045","pt":1717308032562,"mc":[{"id":"1.229554902","rc":[{"atb":[[3.25,0],[3.75,0]],"id":52385910},{"atb":[[3.95,0],[4.9,0]],"id":52385906},{"atb":[[19,0],[28,0]],"id":52385908},{"atb":[[16.5,0],[23,0]],"id":52385887},{"atb":[[20,0],[30,0]],"id":52385889},{"atb":[[4.6,0],[3.8,0]],"id":52385916},{"atb":[[3.6,0],[4.2,0]],"id":52385885},{"atb":[[550,0],[650,0]],"id":52385894},{"atb":[[36,0],[23,0]],"id":52385927},{"atb":[[16,0],[22,0]],"id":52385892},{"atb":[[550,0],[650,0]],"id":52385925},{"atb":[[5.1,0],[4.1,0]],"id":52385935},{"atb":[[20,0],[30,0]],"id":52385904},{"atb":[[19.5,5.66],[29,1.87]],"id":52385937},{"atb":[[5.3,0],[6.6,0]],"id":52385931},{"atb":[[18,0],[13,0]],"id":52385911},{"atb":[[4.3,0],[3.65,0]],"id":52385913},{"atb":[[5.8,0],[7.6,0]],"id":52385909},{"atb":[[5.1,0],[6.2,0]],"id":52385888},{"atb":[[17.5,0],[25,0]],"id":52385882},{"atb":[[18,0],[13,0]],"id":52385915},{"atb":[[4.9,0],[5.9,0]],"id":52385884},{"atb":[[44,0],[27,0]],"id":52385895},{"atb":[[21,0],[15.5,0]],"id":52385928},{"atb":[[40,0],[25,0]],"id":52385891},{"atb":[[19,0],[28,0]],"id":52385924},{"atb":[[5.8,0],[7.6,0]],"id":52385934},{"atb":[[5.1,0],[6.2,0]],"id":52385903},{"atb":[[38,0],[24,0]],"id":52385930},{"atb":[[34,0],[22,0]],"id":52385932}],"con":true,"img":false}]}
{"op":"mcm","clk":"11449367317","pt":1717308038674,"mc":[{"id":"1.229554902","rc":[{"atb":[[3.25,108.4],[3.75,38]],"id":52385910},{"atb":[[3.95,82.67],[4.9,26.8]],"id":52385906},{"atb":[[19,13.55],[28,3.87]],"id":52385908},{"atb":[[16.5,15.73],[23,4.75]],"id":52385887},{"atb":[[20,12.83],[30,3.6]],"id":52385889},{"atb":[[4.6,29.03],[3.8,87.1]],"id":52385916},{"atb":[[3.6,93.81],[4.2,32.66]],"id":52385885},{"atb":[[550,0.44],[650,0.16]],"id":52385894},{"atb":[[36,2.98],[23,11.08]],"id":52385927},{"atb":[[16,16.26],[22,4.97]],"id":52385892},{"atb":[[550,0.44],[650,0.16]],"id":52385925},{"atb":[[5.1,25.49],[4.1,78.68]],"id":52385935},{"atb":[[20,12.83],[30,3.6]],"id":52385904},{"atb":[[19.5,18.84],[29,5.6]],"id":52385937},{"atb":[[5.3,56.72],[6.6,18.66]],"id":52385931},{"atb":[[18,6.14],[13,20.32]],"id":52385911},{"atb":[[4.3,31.67],[3.65,92.03]],"id":52385913},{"atb":[[5.8,50.81],[7.6,15.83]],"id":52385909},{"atb":[[5.1,59.49],[6.2,20.1]],"id":52385888},{"atb":[[17.5,14.77],[25,4.35]],"id":52385882},{"atb":[[18,6.14],[13,20.32]],"id":52385915},{"atb":[[4.9,62.54],[5.9,21.33]],"id":52385884},{"atb":[[44,2.43],[27,9.38]],"id":52385895},{"atb":[[21,5.22],[15.5,16.82]],"id":52385928},{"atb":[[40,2.67],[25,10.16]],"id":52385891},{"atb":[[19,13.55],[28,3.87]],"id":52385924},{"atb":[[5.8,50.81],[7.6,15.83]],"id":52385934},{"atb":[[5.1,59.49],[6.2,20.1]],"id":52385903},{"atb":[[38,2.82],[24,10.6]],"id":52385930},{"atb":[[34,3.16],[22,11.61]],"id":52385932}],"con":true,"img":false}]}
{"op":"mcm","clk":"11449437351","pt":1717309126726,"mc":[{"id":"1.229554902","rc":[{"atb":[[3.25,0],[3.75,0]],"id":52385910},{"atb":[[3.95,0],[4.9,0]],"id":52385906},{"atb":[[19,0],[28,0]],"id":52385908},{"atb":[[16.5,0],[23,0]],"id":52385887},{"atb":[[20,0],[30,0]],"id":52385889},{"atb":[[4.6,0],[3.8,0]],"id":52385916},{"atb":[[3.6,0],[4.2,0]],"id":52385885},{"atb":[[550,0],[650,0]],"id":52385894},{"atb":[[36,0],[23,0]],"id":52385927},{"atb":[[16,0],[22,0]],"id":52385892},{"atb":[[550,0],[650,0]],"id":52385925},{"atb":[[5.1,0],[4.1,0]],"id":52385935},{"atb":[[20,0],[30,0]],"id":52385904},{"atb":[[19.5,5.66],[29,1.87]],"id":52385937},{"atb":[[5.3,0],[6.6,0]],"id":52385931},{"atb":[[18,0],[13,0]],"id":52385911},{"atb":[[4.3,0],[3.65,0]],"id":52385913},{"atb":[[5.8,0],[7.6,0]],"id":52385909},{"atb":[[5.1,0],[6.2,0]],"id":52385888},{"atb":[[17.5,0],[25,0]],"id":52385882},{"atb":[[18,0],[13,0]],"id":52385915},{"atb":[[4.9,0],[5.9,0]],"id":52385884},{"atb":[[44,0],[27,0]],"id":52385895},{"atb":[[21,0],[15.5,0]],"id":52385928},{"atb":[[40,0],[25,0]],"id":52385891},{"atb":[[19,0],[28,0]],"id":52385924},{"atb":[[5.8,0],[7.6,0]],"id":52385934},{"atb":[[5.1,0],[6.2,0]],"id":52385903},{"atb":[[38,0],[24,0]],"id":52385930},{"atb":[[34,0],[22,0]],"id":52385932}],"con":true,"img":false}]}
{"op":"mcm","clk":"11449438870","pt":1717309151566,"mc":[{"id":"1.229554902","rc":[{"atb":[[3.25,108.4],[3.75,38]],"id":52385910},{"atb":[[3.95,82.67],[4.9,26.8]],"id":52385906},{"atb":[[19,13.55],[28,3.87]],"id":52385908},{"atb":[[16.5,15.73],[23,4.75]],"id":52385887},{"atb":[[20,12.83],[30,3.6]],"id":52385889},{"atb":[[4.6,29.03],[3.8,87.1]],"id":52385916},{"atb":[[3.6,93.81],[4.2,32.66]],"id":52385885},{"atb":[[550,0.44],[650,0.16]],"id":52385894},{"atb":[[36,2.98],[23,11.08]],"id":52385927},{"atb":[[16,16.26],[22,4.97]],"id":52385892},{"atb":[[550,0.44],[650,0.16]],"id":52385925},{"atb":[[5.1,25.49],[4.1,78.68]],"id":52385935},{"atb":[[20,12.83],[30,3.6]],"id":52385904},{"atb":[[19.5,18.84],[29,5.6]],"id":52385937},{"atb":[[5.3,56.72],[6.6,18.66]],"id":52385931},{"atb":[[18,6.14],[13,20.32]],"id":52385911},{"atb":[[4.3,31.67],[3.65,92.03]],"id":52385913},{"atb":[[5.8,50.81],[7.6,15.83]],"id":52385909},{"atb":[[5.1,59.49],[6.2,20.1]],"id":52385888},{"atb":[[17.5,14.77],[25,4.35]],"id":52385882},{"atb":[[18,6.14],[13,20.32]],"id":52385915},{"atb":[[4.9,62.54],[5.9,21.33]],"id":52385884},{"atb":[[44,2.43],[27,9.38]],"id":52385895},{"atb":[[21,5.22],[15.5,16.82]],"id":52385928},{"atb":[[40,2.67],[25,10.16]],"id":52385891},{"atb":[[19,13.55],[28,3.87]],"id":52385924},{"atb":[[5.8,50.81],[7.6,15.83]],"id":52385934},{"atb":[[5.1,59.49],[6.2,20.1]],"id":52385903},{"atb":[[38,2.82],[24,10.6]],"id":52385930},{"atb":[[34,3.16],[22,11.61]],"id":52385932}],"con":true,"img":false}]}
{"op":"mcm","clk":"11449439219","pt":1717309156544,"mc":[{"id":"1.229554902","rc":[{"atb":[[4.8,0],[5.8,0],[5.3,0],[6.6,0]],"id":52385910},{"atb":[[75,0],[40,0],[50,0],[30,0]],"id":52385887},{"atb":[[150,0],[75,0],[200,0],[100,0]],"id":52385889},{"atb":[[4.5,0],[5,0],[5.5,0],[6,0]],"id":52385916},{"atb":[[8,0],[5.5,0],[6,0],[7,0]],"id":52385885},{"atb":[[840,0],[890,0],[940,0],[990,0]],"id":52385894},{"atb":[[8,0],[9,0],[10,0],[12.5,0]],"id":52385931},{"atb":[[11,0],[13.5,0],[8.4,0],[9.4,0]],"id":52385888},{"atb":[[70,0],[38,0],[95,0],[48,0]],"id":52385882},{"atb":[[9.2,0],[10.5,0],[8.2,0],[13,0]],"id":52385884},{"atb":[[170,0],[85,0],[220,0],[120,0]],"id":52385895},{"atb":[[70,0],[38,0],[95,0],[48,0]],"id":52385928},{"atb":[[150,0],[75,0],[100,0],[50,0]],"id":52385924},{"atb":[[8,0],[9,0],[10,0],[7,0]],"id":52385934},{"atb":[[12,0],[9.8,0],[8.8,0],[14.5,0]],"id":52385903},{"atb":[[130,0],[65,0],[90,0],[46,0]],"id":52385930},{"atb":[[32,0],[80,0],[42,0],[55,0]],"id":52385932}],"con":true,"img":false}]}
{"op":"mcm","clk":"11449439265","pt":1717309157266,"mc":[{"id":"1.229554902","rc":[{"atb":[[3.45,42.71],[3.95,17.74],[3.7,29.07],[4.4,7.7]],"id":52385916},{"atb":[[540,0.1],[590,0.04],[440,0.24],[490,0.16]],"id":52385894},{"atb":[[85,0.62],[44,4.87],[120,0.22],[60,1.33]],"id":52385895},{"atb":[[65,0.41],[36,2.24],[46,1.16],[28,3.88]],"id":52385928},{"atb":[[6.8,18.04],[9.8,2.97],[8.8,6.71],[7.8,11.54]],"id":52385934},{"atb":[[75,0.71],[40,2.68],[100,0.27],[50,1.6]],"id":52385930},{"atb":[[34,5.55],[44,1.22],[27,4.02],[60,0.44]],"id":52385932}],"con":true,"img":false}]}
{"op":"mcm","clk":"11449439383","pt":1717309159282,"mc":[{"id":"1.229554902","rc":[{"atb":[[3.45,0],[3.95,0],[3.7,0],[4.4,0]],"id":52385916},{"atb":[[540,0],[590,0],[440,0],[490,0]],"id":52385894},{"atb":[[65,0],[36,0],[46,0],[28,0]],"id":52385928},{"atb":[[75,0],[40,0],[100,0],[50,0]],"id":52385930}],"con":true,"img":false}]}
{"op":"mcm","clk":"11449439392","pt":1717309159333,"mc":[{"id":"1.229554902","rc":[{"atb":[[6.8,0],[9.8,0],[8.8,0],[7.8,0]],"id":52385934}],"con":true,"img":false}]}
{"op":"mcm","clk":"11449439402","pt":1717309159437,"mc":[{"id":"1.229554902","rc":[{"atb":[[34,3.16],[44,0],[27,0],[60,0]],"id":52385932}],"con":true,"img":false}]}
{"op":"mcm","clk":"11449439438","pt":1717309159955,"mc":[{"id":"1.229554902","rc":[{"atb":[[3.45,42.71],[3.95,17.74],[3.7,29.07],[4.4,7.7]],"id":52385916},{"atb":[[540,0.1],[590,0.04],[440,0.24],[490,0.16]],"id":52385894},{"atb":[[65,0.41],[36,2.24],[46,1.16],[28,3.88]],"id":52385928}],"con":true,"img":false}]}
{"op":"mcm","clk":"11449439443","pt":1717309160056,"mc":[{"id":"1.229554902","rc":[{"atb":[[6.8,18.04],[9.8,2.97],[8.8,6.71],[7.8,11.54]],"id":52385934},{"atb":[[75,0.71],[40,2.68],[100,0.27],[50,1.6]],"id":52385930}],"con":true,"img":false}]}
{"op":"mcm","clk":"11449439451","pt":1717309160160,"mc":[{"id":"1.229554902","rc":[{"atb":[[34,5.55],[44,1.22],[27,4.02],[60,0.44]],"id":52385932}],"con":true,"img":false}]}
{"op":"mcm","clk":"11449440769","pt":1717309180863,"mc":[{"id":"1.229554902","rc":[{"atb":[[170,0],[85,0],[120,0],[60,0]],"id":52385927},{"atb":[[840,0],[890,0],[940,0],[990,0]],"id":52385925},{"atb":[[4.3,0],[3.4,0],[3.9,0],[3.65,0]],"id":52385935},{"atb":[[38,0],[19.5,13.18],[24,0],[29,3.73]],"id":52385937},{"atb":[[6.8,0],[7.8,0],[5.9,0],[5.4,0]],"id":52385913},{"atb":[[32,0],[42,0],[21,0],[26,0]],"id":52385915},{"atb":[[6.8,0],[9.8,0],[8.8,0],[7.8,0]],"id":52385934},{"atb":[[34,3.16],[44,0],[27,0],[60,0]],"id":52385932}],"con":true,"img":false}]}
{"op":"mcm","clk":"11449440811","pt":1717309181587,"mc":[{"id":"1.229554902","rc":[{"atb":[[75,0.71],[40,2.68],[100,0.27],[50,1.6]],"id":52385927},{"atb":[[520,0.1],[570,0.05],[420,0.25],[470,0.17]],"id":52385925},{"atb":[[3.2,11.89],[2.88,41.74],[2.98,26.43],[2.78,58.78]],"id":52385935},{"atb":[[18,4.61],[21,2.62],[26,1.05],[15.5,7.21]],"id":52385937},{"atb":[[4.3,39.6],[3.4,43.6],[3.9,18.04],[3.65,121.65]],"id":52385913},{"atb":[[16,5.23],[18.5,2.99],[22,1.25],[13.5,8.37]],"id":52385915},{"atb":[[5.8,67.17],[5.3,24.33],[7.6,19.8],[6.6,9.34]],"id":52385934},{"atb":[[32,2.53],[42,1.28],[26,4.19],[55,0.49]],"id":52385932}],"con":true,"img":false}]}
{"op":"mcm","clk":"11449442398","pt":1717309206895,"mc":[{"id":"1.229554902","rc":[{"atb":[[3.25,0],[3.75,0]],"id":52385910},{"atb":[[3.95,0],[4.9,0]],"id":52385906},{"atb":[[19,0],[28,0]],"id":52385908},{"atb":[[16.5,0],[23,0]],"id":52385887},{"atb":[[20,0],[30,0]],"id":52385889},{"atb":[[4.6,0],[3.8,0]],"id":52385916},{"atb":[[3.6,0],[4.2,0]],"id":52385885},{"atb":[[550,0],[650,0]],"id":52385894},{"atb":[[36,0],[23,0]],"id":52385927},{"atb":[[16,0],[22,0]],"id":52385892},{"atb":[[550,0],[650,0]],"id":52385925},{"atb":[[5.1,0],[4.1,0]],"id":52385935},{"atb":[[20,0],[30,0]],"id":52385904},{"atb":[[19.5,0],[29,0]],"id":52385937},{"atb":[[5.3,0],[6.6,0]],"id":52385931},{"atb":[[18,0],[13,0]],"id":52385911},{"atb":[[4.3,7.93],[3.65,29.61]],"id":52385913},{"atb":[[5.8,0],[7.6,0]],"id":52385909},{"atb":[[5.1,0],[6.2,0]],"id":52385888},{"atb":[[17.5,0],[25,0]],"id":52385882},{"atb":[[18,0],[13,0]],"id":52385915},{"atb":[[4.9,0],[5.9,0]],"id":52385884},{"atb":[[44,2.43],[27,0]],"id":52385895},{"atb":[[21,0],[15.5,0]],"id":52385928},{"atb":[[40,0],[25,0]],"id":52385891},{"atb":[[19,0],[28,0]],"id":52385924},{"atb":[[5.8,16.35],[7.6,3.97]],"id":52385934},{"atb":[[5.1,0],[6.2,0]],"id":52385903},{"atb":[[38,0],[24,0]],"id":52385930},{"atb":[[34,0],[22,0]],"id":52385932}],"con":true,"img":false}]}
{"op":"mcm","clk":"11449443354","pt":1717309221028,"mc":[{"id":"1.229554902","rc":[{"atb":[[4,34.84],[3.5,97.56]],"id":52385910},{"atb":[[4.8,27.5],[3.9,84.1]],"id":52385906},{"atb":[[16,16.26],[22,4.97]],"id":52385908},{"atb":[[16,16.26],[22,4.97]],"id":52385887},{"atb":[[32,3.37],[21,12.19]],"id":52385889},{"atb":[[4,34.84],[3.5,97.56]],"id":52385916},{"atb":[[4.8,27.5],[3.9,84.1]],"id":52385885},{"atb":[[550,0.44],[650,0.16]],"id":52385894},{"atb":[[17.5,14.77],[25,4.35]],"id":52385927},{"atb":[[19.5,5.65],[14.5,18.06]],"id":52385892},{"atb":[[550,0.44],[650,0.16]],"id":52385925},{"atb":[[4.8,27.5],[3.9,84.1]],"id":52385935},{"atb":[[18,14.34],[26,4.18]],"id":52385904},{"atb":[[16,16.26],[22,4.97]],"id":52385937},{"atb":[[7.4,16.33],[5.7,51.89]],"id":52385931},{"atb":[[16.5,6.74],[11.5,23.22]],"id":52385911},{"atb":[[3.45,99.55],[3.95,35.43]],"id":52385913},{"atb":[[5.6,53.02],[7.2,16.86]],"id":52385909},{"atb":[[7.4,16.33],[5.7,51.89]],"id":52385888},{"atb":[[18,14.34],[26,4.18]],"id":52385882},{"atb":[[9.8,27.71],[14.5,7.74]],"id":52385915},{"atb":[[5.6,53.02],[7.2,16.86]],"id":52385884},{"atb":[[32,3.37],[21,12.19]],"id":52385895},{"atb":[[18,6.14],[13,20.32]],"id":52385928},{"atb":[[20,12.83],[30,3.6]],"id":52385891},{"atb":[[18,14.34],[26,4.18]],"id":52385924},{"atb":[[5.6,53.02],[7.2,16.86]],"id":52385934},{"atb":[[5.6,53.02],[7.2,16.86]],"id":52385903},{"atb":[[18,14.34],[26,4.18]],"id":52385930},{"atb":[[18,14.34],[26,8.37]],"id":52385932}],"con":true,"img":false}]}
{"op":"mcm","clk":"11449447236","pt":1717309280771,"mc":[{"id":"1.229554902","marketDefinition":{"bspMarket":false,"turnInPlayEnabled":false,"persistenceEnabled":false,"marketBaseRate":7.0,"eventId":"33318908","eventTypeId":"4339","numberOfWinners":1,"bettingType":"ODDS","marketType":"EXACTA","marketTime":"2024-06-02T08:59:00.000Z","suspendTime":"2024-06-02T08:59:00.000Z","bspReconciled":false,"complete":true,"inPlay":false,"crossMatching":true,"runnersVoidable":false,"numberOfActiveRunners":30,"betDelay":0,"status":"SUSPENDED","runners":[{"status":"ACTIVE","sortPriority":1,"id":52385882,"name":"1 - 2"},{"status":"ACTIVE","sortPriority":2,"id":52385884,"name":"1 - 4"},{"status":"ACTIVE","sortPriority":3,"id":52385885,"name":"1 - 5"},{"status":"ACTIVE","sortPriority":4,"id":52385887,"name":"1 - 7"},{"status":"ACTIVE","sortPriority":5,"id":52385888,"name":"1 - 8"},{"status":"ACTIVE","sortPriority":6,"id":52385889,"name":"2 - 1"},{"status":"ACTIVE","sortPriority":7,"id":52385891,"name":"2 - 4"},{"status":"ACTIVE","sortPriority":8,"id":52385892,"name":"2 - 5"},{"status":"ACTIVE","sortPriority":9,"id":52385894,"name":"2 - 7"},{"status":"ACTIVE","sortPriority":10,"id":52385895,"name":"2 - 8"},{"status":"ACTIVE","sortPriority":11,"id":52385903,"name":"4 - 1"},{"status":"ACTIVE","sortPriority":12,"id":52385904,"name":"4 - 2"},{"status":"ACTIVE","sortPriority":13,"id":52385906,"name":"4 - 5"},{"status":"ACTIVE","sortPriority":14,"id":52385908,"name":"4 - 7"},{"status":"ACTIVE","sortPriority":15,"id":52385909,"name":"4 - 8"},{"status":"ACTIVE","sortPriority":16,"id":52385910,"name":"5 - 1"},{"status":"ACTIVE","sortPriority":17,"id":52385911,"name":"5 - 2"},{"status":"ACTIVE","sortPriority":18,"id":52385913,"name":"5 - 4"},{"status":"ACTIVE","sortPriority":19,"id":52385915,"name":"5 - 7"},{"status":"ACTIVE","sortPriority":20,"id":52385916,"name":"5 - 8"},{"status":"ACTIVE","sortPriority":21,"id":52385924,"name":"7 - 1"},{"status":"ACTIVE","sortPriority":22,"id":52385925,"name":"7 - 2"},{"status":"ACTIVE","sortPriority":23,"id":52385927,"name":"7 - 4"},{"status":"ACTIVE","sortPriority":24,"id":52385928,"name":"7 - 5"},{"status":"ACTIVE","sortPriority":25,"id":52385930,"name":"7 - 8"},{"status":"ACTIVE","sortPriority":26,"id":52385931,"name":"8 - 1"},{"status":"ACTIVE","sortPriority":27,"id":52385932,"name":"8 - 2"},{"status":"ACTIVE","sortPriority":28,"id":52385934,"name":"8 - 4"},{"status":"ACTIVE","sortPriority":29,"id":52385935,"name":"8 - 5"},{"status":"ACTIVE","sortPriority":30,"id":52385937,"name":"8 - 7"}],"regulators":["MR_INT"],"venue":"Murray Bridge","countryCode":"AU","discountAllowed":true,"timezone":"Australia/Adelaide","openDate":"2024-06-02T08:21:00.000Z","version":5962889458,"name":"Exacta","eventName":"Murray Bridge (AUS) 2nd Jun"},"rc":[],"con":true,"img":false}]}
{"op":"mcm","clk":"11449448973","pt":1717309307619,"mc":[{"id":"1.229554902","marketDefinition":{"bspMarket":false,"turnInPlayEnabled":false,"persistenceEnabled":false,"marketBaseRate":7.0,"eventId":"33318908","eventTypeId":"4339","numberOfWinners":1,"bettingType":"ODDS","marketType":"EXACTA","marketTime":"2024-06-02T08:59:00.000Z","suspendTime":"2024-06-02T08:59:00.000Z","bspReconciled":false,"complete":true,"inPlay":false,"crossMatching":false,"runnersVoidable":false,"numberOfActiveRunners":30,"betDelay":0,"status":"SUSPENDED","runners":[{"status":"ACTIVE","sortPriority":1,"id":52385882,"name":"1 - 2"},{"status":"ACTIVE","sortPriority":2,"id":52385884,"name":"1 - 4"},{"status":"ACTIVE","sortPriority":3,"id":52385885,"name":"1 - 5"},{"status":"ACTIVE","sortPriority":4,"id":52385887,"name":"1 - 7"},{"status":"ACTIVE","sortPriority":5,"id":52385888,"name":"1 - 8"},{"status":"ACTIVE","sortPriority":6,"id":52385889,"name":"2 - 1"},{"status":"ACTIVE","sortPriority":7,"id":52385891,"name":"2 - 4"},{"status":"ACTIVE","sortPriority":8,"id":52385892,"name":"2 - 5"},{"status":"ACTIVE","sortPriority":9,"id":52385894,"name":"2 - 7"},{"status":"ACTIVE","sortPriority":10,"id":52385895,"name":"2 - 8"},{"status":"ACTIVE","sortPriority":11,"id":52385903,"name":"4 - 1"},{"status":"ACTIVE","sortPriority":12,"id":52385904,"name":"4 - 2"},{"status":"ACTIVE","sortPriority":13,"id":52385906,"name":"4 - 5"},{"status":"ACTIVE","sortPriority":14,"id":52385908,"name":"4 - 7"},{"status":"ACTIVE","sortPriority":15,"id":52385909,"name":"4 - 8"},{"status":"ACTIVE","sortPriority":16,"id":52385910,"name":"5 - 1"},{"status":"ACTIVE","sortPriority":17,"id":52385911,"name":"5 - 2"},{"status":"ACTIVE","sortPriority":18,"id":52385913,"name":"5 - 4"},{"status":"ACTIVE","sortPriority":19,"id":52385915,"name":"5 - 7"},{"status":"ACTIVE","sortPriority":20,"id":52385916,"name":"5 - 8"},{"status":"ACTIVE","sortPriority":21,"id":52385924,"name":"7 - 1"},{"status":"ACTIVE","sortPriority":22,"id":52385925,"name":"7 - 2"},{"status":"ACTIVE","sortPriority":23,"id":52385927,"name":"7 - 4"},{"status":"ACTIVE","sortPriority":24,"id":52385928,"name":"7 - 5"},{"status":"ACTIVE","sortPriority":25,"id":52385930,"name":"7 - 8"},{"status":"ACTIVE","sortPriority":26,"id":52385931,"name":"8 - 1"},{"status":"ACTIVE","sortPriority":27,"id":52385932,"name":"8 - 2"},{"status":"ACTIVE","sortPriority":28,"id":52385934,"name":"8 - 4"},{"status":"ACTIVE","sortPriority":29,"id":52385935,"name":"8 - 5"},{"status":"ACTIVE","sortPriority":30,"id":52385937,"name":"8 - 7"}],"regulators":["MR_INT"],"venue":"Murray Bridge","countryCode":"AU","discountAllowed":true,"timezone":"Australia/Adelaide","openDate":"2024-06-02T08:21:00.000Z","version":5962889996,"name":"Exacta","eventName":"Murray Bridge (AUS) 2nd Jun"},"rc":[],"con":true,"img":false}]}
{"op":"mcm","clk":"11449448973","pt":1717309307619,"mc":[{"id":"1.229554902","rc":[{"atb":[[4,0],[3.5,0]],"id":52385910},{"atb":[[4.8,0],[7.2,0],[9.2,0],[10.5,0],[8.2,0],[3.9,0]],"id":52385906},{"atb":[[16,0],[70,0],[38,0],[22,0],[95,0],[48,0]],"id":52385908},{"atb":[[16,0],[22,0]],"id":52385887},{"atb":[[32,0],[21,0]],"id":52385889},{"atb":[[4,0],[3.45,0],[3.95,0],[3.7,0],[4.4,0],[3.5,0]],"id":52385916},{"atb":[[4.8,0],[3.9,0]],"id":52385885},{"atb":[[540,0],[550,0],[590,0],[650,0],[440,0],[490,0]],"id":52385894},{"atb":[[17.5,0],[75,0],[40,0],[100,0],[50,0],[25,0]],"id":52385927},{"atb":[[140,0],[70,0],[19.5,0],[95,0],[48,0],[14.5,0]],"id":52385892},{"atb":[[520,0],[570,0],[550,0],[650,0],[420,0],[470,0]],"id":52385925},{"atb":[[4.8,0],[3.2,0],[2.88,0],[2.98,0],[3.9,0],[2.78,0]],"id":52385935},{"atb":[[18,0],[85,0],[44,0],[26,0],[120,0],[60,0]],"id":52385904},{"atb":[[16,0],[18,0],[21,0],[22,0],[26,0],[15.5,0]],"id":52385937},{"atb":[[7.4,0],[5.7,0]],"id":52385931},{"atb":[[32,0],[16.5,0],[42,0],[11.5,0],[26,0],[55,0]],"id":52385911},{"atb":[[3.45,0],[4.3,0],[3.95,0],[3.4,0],[3.9,0],[3.65,0]],"id":52385913},{"atb":[[5.6,0],[17.5,0],[7.2,0],[10,0],[12.5,0],[15,0]],"id":52385909},{"atb":[[7.4,0],[5.7,0]],"id":52385888},{"atb":[[18,0],[26,0]],"id":52385882},{"atb":[[16,0],[18.5,0],[22,0],[9.8,0],[13.5,0],[14.5,0]],"id":52385915},{"atb":[[5.6,0],[7.2,0]],"id":52385884},{"atb":[[32,0],[85,0],[21,0],[44,0],[120,0],[60,0]],"id":52385895},{"atb":[[65,0],[36,0],[18,0],[46,0],[13,0],[28,0]],"id":52385928},{"atb":[[130,0],[20,0],[180,0],[90,0],[230,0],[30,0]],"id":52385891},{"atb":[[18,0],[26,0]],"id":52385924},{"atb":[[5.6,0],[7.2,0],[5.8,0],[5.3,0],[7.6,0],[6.6,0]],"id":52385934},{"atb":[[5.6,0],[7.2,0]],"id":52385903},{"atb":[[75,0],[18,0],[40,0],[100,0],[50,0],[26,0]],"id":52385930},{"atb":[[32,0],[18,0],[42,0],[26,0],[55,0]],"id":52385932}],"con":true,"img":false}]}
{"op":"mcm","clk":"11449449050","pt":1717309308821,"mc":[{"id":"1.229554902","marketDefinition":{"bspMarket":false,"turnInPlayEnabled":false,"persistenceEnabled":false,"marketBaseRate":7.0,"eventId":"33318908","eventTypeId":"4339","numberOfWinners":1,"bettingType":"ODDS","marketType":"EXACTA","marketTime":"2024-06-02T08:59:00.000Z","suspendTime":"2024-06-02T08:59:00.000Z","bspReconciled":false,"complete":true,"inPlay":false,"crossMatching":false,"runnersVoidable":false,"numberOfActiveRunners":0,"betDelay":0,"status":"CLOSED","settledTime":"2024-06-02T06:21:47.000Z","runners":[{"status":"REMOVED","sortPriority":1,"removalDate":"2024-06-02T06:21:47.000Z","id":52385882,"name":"1 - 2"},{"status":"REMOVED","sortPriority":2,"removalDate":"2024-06-02T06:21:47.000Z","id":52385884,"name":"1 - 4"},{"status":"REMOVED","sortPriority":3,"removalDate":"2024-06-02T06:21:47.000Z","id":52385885,"name":"1 - 5"},{"status":"REMOVED","sortPriority":4,"removalDate":"2024-06-02T06:21:47.000Z","id":52385887,"name":"1 - 7"},{"status":"REMOVED","sortPriority":5,"removalDate":"2024-06-02T06:21:47.000Z","id":52385888,"name":"1 - 8"},{"status":"REMOVED","sortPriority":6,"removalDate":"2024-06-02T06:21:47.000Z","id":52385889,"name":"2 - 1"},{"status":"REMOVED","sortPriority":7,"removalDate":"2024-06-02T06:21:47.000Z","id":52385891,"name":"2 - 4"},{"status":"REMOVED","sortPriority":8,"removalDate":"2024-06-02T06:21:47.000Z","id":52385892,"name":"2 - 5"},{"status":"REMOVED","sortPriority":9,"removalDate":"2024-06-02T06:21:47.000Z","id":52385894,"name":"2 - 7"},{"status":"REMOVED","sortPriority":10,"removalDate":"2024-06-02T06:21:47.000Z","id":52385895,"name":"2 - 8"},{"status":"REMOVED","sortPriority":11,"removalDate":"2024-06-02T06:21:47.000Z","id":52385903,"name":"4 - 1"},{"status":"REMOVED","sortPriority":12,"removalDate":"2024-06-02T06:21:47.000Z","id":52385904,"name":"4 - 2"},{"status":"REMOVED","sortPriority":13,"removalDate":"2024-06-02T06:21:47.000Z","id":52385906,"name":"4 - 5"},{"status":"REMOVED","sortPriority":14,"removalDate":"2024-06-02T06:21:47.000Z","id":52385908,"name":"4 - 7"},{"status":"REMOVED","sortPriority":15,"removalDate":"2024-06-02T06:21:47.000Z","id":52385909,"name":"4 - 8"},{"status":"REMOVED","sortPriority":16,"removalDate":"2024-06-02T06:21:47.000Z","id":52385910,"name":"5 - 1"},{"status":"REMOVED","sortPriority":17,"removalDate":"2024-06-02T06:21:47.000Z","id":52385911,"name":"5 - 2"},{"status":"REMOVED","sortPriority":18,"removalDate":"2024-06-02T06:21:47.000Z","id":52385913,"name":"5 - 4"},{"status":"REMOVED","sortPriority":19,"removalDate":"2024-06-02T06:21:47.000Z","id":52385915,"name":"5 - 7"},{"status":"REMOVED","sortPriority":20,"removalDate":"2024-06-02T06:21:47.000Z","id":52385916,"name":"5 - 8"},{"status":"REMOVED","sortPriority":21,"removalDate":"2024-06-02T06:21:47.000Z","id":52385924,"name":"7 - 1"},{"status":"REMOVED","sortPriority":22,"removalDate":"2024-06-02T06:21:47.000Z","id":52385925,"name":"7 - 2"},{"status":"REMOVED","sortPriority":23,"removalDate":"2024-06-02T06:21:47.000Z","id":52385927,"name":"7 - 4"},{"status":"REMOVED","sortPriority":24,"removalDate":"2024-06-02T06:21:47.000Z","id":52385928,"name":"7 - 5"},{"status":"REMOVED","sortPriority":25,"removalDate":"2024-06-02T06:21:47.000Z","id":52385930,"name":"7 - 8"},{"status":"REMOVED","sortPriority":26,"removalDate":"2024-06-02T06:21:47.000Z","id":52385931,"name":"8 - 1"},{"status":"REMOVED","sortPriority":27,"removalDate":"2024-06-02T06:21:47.000Z","id":52385932,"name":"8 - 2"},{"status":"REMOVED","sortPriority":28,"removalDate":"2024-06-02T06:21:47.000Z","id":52385934,"name":"8 - 4"},{"status":"REMOVED","sortPriority":29,"removalDate":"2024-06-02T06:21:47.000Z","id":52385935,"name":"8 - 5"},{"status":"REMOVED","sortPriority":30,"removalDate":"2024-06-02T06:21:47.000Z","id":52385937,"name":"8 - 7"}],"regulators":["MR_INT"],"venue":"Murray Bridge","countryCode":"AU","discountAllowed":true,"timezone":"Australia/Adelaide","openDate":"2024-06-02T08:21:00.000Z","version":5962890002,"name":"Exacta","eventName":"Murray Bridge (AUS) 2nd Jun"},"rc":[],"con":true,"img":false}]}
