{"op":"mcm","clk":"11448351869","pt":1717289088271,"mc":[{"id":"1.229554894","marketDefinition":{"bspMarket":false,"turnInPlayEnabled":false,"persistenceEnabled":false,"marketBaseRate":7.0,"eventId":"33318908","eventTypeId":"4339","numberOfWinners":1,"bettingType":"ODDS","marketType":"MATCH_BET","marketTime":"2024-06-02T08:21:00.000Z","suspendTime":"2024-06-02T08:21:00.000Z","bspReconciled":false,"complete":true,"inPlay":false,"crossMatching":true,"runnersVoidable":false,"numberOfActiveRunners":2,"betDelay":0,"status":"OPEN","runners":[{"status":"ACTIVE","sortPriority":1,"id":70003365,"name":"4. Bookaloo"},{"status":"ACTIVE","sortPriority":2,"id":70003367,"name":"8. Apilla"}],"regulators":["MR_INT"],"venue":"Murray Bridge","countryCode":"AU","discountAllowed":true,"timezone":"Australia/Adelaide","openDate":"2024-06-02T08:21:00.000Z","version":5962433796,"name":"Bookaloo v Apilla","eventName":"Murray Bridge (AUS) 2nd Jun"},"rc":[],"con":true,"img":false}]}
{"op":"mcm","clk":"11448366403","pt":1717289278043,"mc":[{"id":"1.229554894","rc":[{"atb":[[1.58,13.52],[1.48,16.34]],"id":70003367},{"atb":[[2.02,7.69],[2.22,6.43]],"id":70003365}],"con":true,"img":false}]}
{"op":"mcm","clk":"11448449904","pt":1717290485765,"mc":[{"id":"1.229554894","rc":[{"atb":[[1.58,0],[1.48,0]],"id":70003367},{"atb":[[2.02,0],[2.22,0]],"id":70003365}],"con":true,"img":false}]}
{"op":"mcm","clk":"11448450360","pt":1717290493660,"mc":[{"id":"1.229554894","rc":[{"atb":[[1.42,18.68],[1.52,15.09]],"id":70003367},{"atb":[[2.14,6.88],[2.34,5.85]],"id":70003365}],"con":true,"img":false}]}
{"op":"mcm","clk":"11448451088","pt":1717290505987,"mc":[{"id":"1.229554894","rc":[{"atb":[[1.42,0],[1.52,0]],"id":70003367},{"atb":[[2.14,0],[2.34,0]],"id":70003365}],"con":true,"img":false}]}
{"op":"mcm","clk":"11448451644","pt":1717290515494,"mc":[{"id":"1.229554894","rc":[{"atb":[[1.4,19.61],[1.5,15.69]],"id":70003367},{"atb":[[2.4,5.6],[2.2,6.53]],"id":70003365}],"con":true,"img":false}]}
{"op":"mcm","clk":"11448452959","pt":1717290537143,"mc":[{"id":"1.229554894","rc":[{"atb":[[1.4,0],[1.5,0]],"id":70003367},{"atb":[[2.4,0],[2.2,0]],"id":70003365}],"con":true,"img":false}]}
{"op":"mcm","clk":"11448453486","pt":1717290545869,"mc":[{"id":"1.229554894","rc":[{"atb":[[1.4,19.61],[1.5,15.69]],"id":70003367},{"atb":[[2.4,5.6],[2.2,6.53]],"id":70003365}],"con":true,"img":false}]}
{"op":"mcm","clk":"11448455672","pt":1717290576906,"mc":[{"id":"1.229554894","rc":[{"atb":[[1.4,0],[1.5,0]],"id":70003367},{"atb":[[2.4,0],[2.2,0]],"id":70003365}],"con":true,"img":false}]}
{"op":"mcm","clk":"11448456059","pt":1717290583604,"mc":[{"id":"1.229554894","rc":[{"atb":[[1.49,16.01],[1.39,20.12]],"id":70003367},{"atb":[[2.42,5.52],[2.22,6.43]],"id":70003365}],"con":true,"img":false}]}
{"op":"mcm","clk":"11448459584","pt":1717290647283,"mc":[{"id":"1.229554894","rc":[{"atb":[[1.49,0],[1.39,0]],"id":70003367},{"atb":[[2.42,0],[2.22,0]],"id":70003365}],"con":true,"img":false}]}
{"op":"mcm","clk":"11448459972","pt":1717290655707,"mc":[{"id":"1.229554894","rc":[{"atb":[[1.49,16.01],[1.39,20.12]],"id":70003367},{"atb":[[2.42,5.52],[2.22,6.43]],"id":70003365}],"con":true,"img":false}]}
{"op":"mcm","clk":"11448461417","pt":1717290680524,"mc":[{"id":"1.229554894","rc":[{"atb":[[1.49,0],[1.39,0]],"id":70003367},{"atb":[[2.42,0],[2.22,0]],"id":70003365}],"con":true,"img":false}]}
{"op":"mcm","clk":"11448462212","pt":1717290691902,"mc":[{"id":"1.229554894","rc":[{"atb":[[1.37,21.2],[1.47,16.69]],"id":70003367},{"atb":[[2.28,6.13],[2.48,5.3]],"id":70003365}],"con":true,"img":false}]}
{"op":"mcm","clk":"11448463739","pt":1717290717742,"mc":[{"id":"1.229554894","rc":[{"atb":[[1.37,0],[1.47,0]],"id":70003367},{"atb":[[2.28,0],[2.48,0]],"id":70003365}],"con":true,"img":false}]}
{"op":"mcm","clk":"11448465282","pt":1717290743288,"mc":[{"id":"1.229554894","rc":[{"atb":[[1.37,21.2],[1.47,16.69]],"id":70003367},{"atb":[[2.28,6.13],[2.48,5.3]],"id":70003365}],"con":true,"img":false}]}
{"op":"mcm","clk":"11448474826","pt":1717290912477,"mc":[{"id":"1.229554894","rc":[{"atb":[[1.37,0],[1.47,0]],"id":70003367},{"atb":[[2.28,0],[2.48,0]],"id":70003365}],"con":true,"img":false}]}
{"op":"mcm","clk":"11448475142","pt":1717290917393,"mc":[{"id":"1.229554894","rc":[{"atb":[[1.43,18.24],[1.33,23.77]],"id":70003367},{"atb":[[2.4,5.6],[2.6,4.9]],"id":70003365}],"con":true,"img":false}]}
{"op":"mcm","clk":"11448476918","pt":1717290945627,"mc":[{"id":"1.229554894","rc":[{"atb":[[1.43,0],[1.33,0]],"id":70003367},{"atb":[[2.4,0],[2.6,0]],"id":70003365}],"con":true,"img":false}]}
{"op":"mcm","clk":"11448477487","pt":1717290954750,"mc":[{"id":"1.229554894","rc":[{"atb":[[1.43,18.24],[1.33,23.77]],"id":70003367},{"atb":[[2.4,5.6],[2.6,4.9]],"id":70003365}],"con":true,"img":false}]}
{"op":"mcm","clk":"11448482360","pt":1717291031786,"mc":[{"id":"1.229554894","rc":[{"atb":[[1.43,0],[1.33,0]],"id":70003367},{"atb":[[2.4,0],[2.6,0]],"id":70003365}],"con":true,"img":false}]}
{"op":"mcm","clk":"11448483015","pt":1717291041104,"mc":[{"id":"1.229554894","rc":[{"atb":[[1.43,18.24],[1.33,23.77]],"id":70003367},{"atb":[[2.4,5.6],[2.6,4.9]],"id":70003365}],"con":true,"img":false}]}
{"op":"mcm","clk":"11448491817","pt":1717291173850,"mc":[{"id":"1.229554894","rc":[{"atb":[[1.43,0],[1.33,0]],"id":70003367},{"atb":[[2.4,0],[2.6,0]],"id":70003365}],"con":true,"img":false}]}
{"op":"mcm","clk":"11448492666","pt":1717291186782,"mc":[{"id":"1.229554894","rc":[{"atb":[[1.44,17.83],[1.54,14.53]],"id":70003367},{"atb":[[2.3,6.03],[2.1,7.13]],"id":70003365}],"con":true,"img":false}]}
{"op":"mcm","clk":"11448494247","pt":1717291211930,"mc":[{"id":"1.229554894","rc":[{"atb":[[1.44,0],[1.54,0]],"id":70003367},{"atb":[[2.3,0],[2.1,0]],"id":70003365}],"con":true,"img":false}]}
{"op":"mcm","clk":"11448494993","pt":1717291222496,"mc":[{"id":"1.229554894","rc":[{"atb":[[1.44,17.83],[1.54,14.53]],"id":70003367},{"atb":[[2.3,6.03],[2.1,7.13]],"id":70003365}],"con":true,"img":false}]}
{"op":"mcm","clk":"11448496468","pt":1717291244133,"mc":[{"id":"1.229554894","rc":[{"atb":[[1.44,0],[1.54,0]],"id":70003367},{"atb":[[2.3,0],[2.1,0]],"id":70003365}],"con":true,"img":false}]}
{"op":"mcm","clk":"11448497030","pt":1717291252168,"mc":[{"id":"1.229554894","rc":[{"atb":[[1.6,13.07],[1.5,15.69]],"id":70003367},{"atb":[[1.98,8],[2.16,6.76]],"id":70003365}],"con":true,"img":false}]}
{"op":"mcm","clk":"11448497991","pt":1717291267478,"mc":[{"id":"1.229554894","rc":[{"atb":[[1.6,0],[1.5,0]],"id":70003367},{"atb":[[1.98,0],[2.16,0]],"id":70003365}],"con":true,"img":false}]}
{"op":"mcm","clk":"11448498628","pt":1717291277078,"mc":[{"id":"1.229554894","rc":[{"atb":[[1.62,12.65],[1.52,15.09]],"id":70003367},{"atb":[[2.12,7],[1.96,8.17]],"id":70003365}],"con":true,"img":false}]}
{"op":"mcm","clk":"11448500201","pt":1717291300007,"mc":[{"id":"1.229554894","rc":[{"atb":[[1.62,0],[1.52,0]],"id":70003367},{"atb":[[2.12,0],[1.96,0]],"id":70003365}],"con":true,"img":false}]}
{"op":"mcm","clk":"11448500719","pt":1717291307927,"mc":[{"id":"1.229554894","rc":[{"atb":[[1.62,12.65],[1.52,15.09]],"id":70003367},{"atb":[[2.12,7],[1.96,8.17]],"id":70003365}],"con":true,"img":false}]}
{"op":"mcm","clk":"11448505177","pt":1717291373191,"mc":[{"id":"1.229554894","rc":[{"atb":[[1.62,0],[1.52,0]],"id":70003367},{"atb":[[2.12,0],[1.96,0]],"id":70003365}],"con":true,"img":false}]}
{"op":"mcm","clk":"11448506046","pt":1717291384677,"mc":[{"id":"1.229554894","rc":[{"atb":[[1.62,12.65],[1.52,15.09]],"id":70003367},{"atb":[[2.12,7],[1.96,8.17]],"id":70003365}],"con":true,"img":false}]}
{"op":"mcm","clk":"11448507525","pt":1717291405810,"mc":[{"id":"1.229554894","rc":[{"atb":[[1.62,0],[1.52,0]],"id":70003367},{"atb":[[2.12,0],[1.96,0]],"id":70003365}],"con":true,"img":false}]}
{"op":"mcm","clk":"11448507967","pt":1717291412383,"mc":[{"id":"1.229554894","rc":[{"atb":[[1.64,12.26],[1.54,14.53]],"id":70003367},{"atb":[[1.95,8.26],[2.1,7.13]],"id":70003365}],"con":true,"img":false}]}
{"op":"mcm","clk":"11448516305","pt":1717291543772,"mc":[{"id":"1.229554894","rc":[{"atb":[[1.64,0],[1.54,0]],"id":70003367},{"atb":[[1.95,0],[2.1,0]],"id":70003365}],"con":true,"img":false}]}
{"op":"mcm","clk":"11448516748","pt":1717291550972,"mc":[{"id":"1.229554894","rc":[{"atb":[[1.59,13.29],[1.69,11.37]],"id":70003367},{"atb":[[2,7.84],[1.9,8.72]],"id":70003365}],"con":true,"img":false}]}
{"op":"mcm","clk":"11448517440","pt":1717291562288,"mc":[{"id":"1.229554894","rc":[{"atb":[[1.59,0],[1.69,0]],"id":70003367},{"atb":[[2,0],[1.9,0]],"id":70003365}],"con":true,"img":false}]}
{"op":"mcm","clk":"11448517838","pt":1717291568298,"mc":[{"id":"1.229554894","rc":[{"atb":[[1.59,13.29],[1.69,11.37]],"id":70003367},{"atb":[[2,7.84],[1.9,8.72]],"id":70003365}],"con":true,"img":false}]}
{"op":"mcm","clk":"11448520458","pt":1717291614238,"mc":[{"id":"1.229554894","rc":[{"atb":[[1.59,0],[1.69,0]],"id":70003367},{"atb":[[2,0],[1.9,0]],"id":70003365}],"con":true,"img":false}]}
{"op":"mcm","clk":"11448520760","pt":1717291619576,"mc":[{"id":"1.229554894","rc":[{"atb":[[1.6,13.07],[1.7,11.21]],"id":70003367},{"atb":[[2,7.84],[1.9,8.72]],"id":70003365}],"con":true,"img":false}]}
{"op":"mcm","clk":"11448521421","pt":1717291630105,"mc":[{"id":"1.229554894","rc":[{"atb":[[1.6,0],[1.7,0]],"id":70003367},{"atb":[[2,0],[1.9,0]],"id":70003365}],"con":true,"img":false}]}
{"op":"mcm","clk":"11448521774","pt":1717291635884,"mc":[{"id":"1.229554894","rc":[{"atb":[[1.6,13.07],[1.7,11.21]],"id":70003367},{"atb":[[2,7.84],[1.9,8.72]],"id":70003365}],"con":true,"img":false}]}
{"op":"mcm","clk":"11448527332","pt":1717291733107,"mc":[{"id":"1.229554894","rc":[{"atb":[[1.6,0],[1.7,0]],"id":70003367},{"atb":[[2,0],[1.9,0]],"id":70003365}],"con":true,"img":false}]}
{"op":"mcm","clk":"11448527774","pt":1717291740829,"mc":[{"id":"1.229554894","rc":[{"atb":[[1.6,13.07],[1.7,11.21]],"id":70003367},{"atb":[[2,7.84],[1.9,8.72]],"id":70003365}],"con":true,"img":false}]}
{"op":"mcm","clk":"11448528399","pt":1717291751018,"mc":[{"id":"1.229554894","rc":[{"atb":[[1.6,0],[1.7,0]],"id":70003367},{"atb":[[2,0],[1.9,0]],"id":70003365}],"con":true,"img":false}]}
{"op":"mcm","clk":"11448528857","pt":1717291758159,"mc":[{"id":"1.229554894","rc":[{"atb":[[1.6,13.07],[1.7,11.21]],"id":70003367},{"atb":[[2,7.84],[1.9,8.72]],"id":70003365}],"con":true,"img":false}]}
{"op":"mcm","clk":"11448777241","pt":1717296235499,"mc":[{"id":"1.229554894","rc":[{"atb":[[1.6,0],[1.7,0]],"id":70003367},{"atb":[[2,0],[1.9,0]],"id":70003365}],"con":true,"img":false}]}
{"op":"mcm","clk":"11448778319","pt":1717296263687,"mc":[{"id":"1.229554894","rc":[{"atb":[[1.6,13.07],[1.7,11.21]],"id":70003367},{"atb":[[2,7.84],[1.9,8.72]],"id":70003365}],"con":true,"img":false}]}
{"op":"mcm","clk":"11448990874","pt":1717301393980,"mc":[{"id":"1.229554894","rc":[{"atb":[[1.6,0],[1.7,0]],"id":70003367},{"atb":[[2,0],[1.9,0]],"id":70003365}],"con":true,"img":false}]}
{"op":"mcm","clk":"11448992393","pt":1717301420517,"mc":[{"id":"1.229554894","rc":[{"atb":[[1.73,10.75],[1.63,12.45]],"id":70003367},{"atb":[[1.97,8.08],[1.87,9.01]],"id":70003365}],"con":true,"img":false}]}
{"op":"mcm","clk":"11448993604","pt":1717301444870,"mc":[{"id":"1.229554894","rc":[{"atb":[[1.73,0],[1.63,0]],"id":70003367},{"atb":[[1.97,0],[1.87,0]],"id":70003365}],"con":true,"img":false}]}
{"op":"mcm","clk":"11448994250","pt":1717301457065,"mc":[{"id":"1.229554894","rc":[{"atb":[[1.73,10.75],[1.63,12.45]],"id":70003367},{"atb":[[1.97,8.08],[1.87,9.01]],"id":70003365}],"con":true,"img":false}]}
{"op":"mcm","clk":"11449002382","pt":1717301606922,"mc":[{"id":"1.229554894","rc":[{"atb":[[1.73,0],[1.63,0]],"id":70003367},{"atb":[[1.97,0],[1.87,0]],"id":70003365}],"con":true,"img":false}]}
{"op":"mcm","clk":"11449003978","pt":1717301637681,"mc":[{"id":"1.229554894","rc":[{"atb":[[1.75,10.46],[1.65,12.07]],"id":70003367},{"atb":[[1.96,8.17],[1.86,9.12]],"id":70003365}],"con":true,"img":false}]}
{"op":"mcm","clk":"11449012695","pt":1717301809743,"mc":[{"id":"1.229554894","rc":[{"atb":[[1.75,0],[1.65,0]],"id":70003367},{"atb":[[1.96,0],[1.86,0]],"id":70003365}],"con":true,"img":false}]}
{"op":"mcm","clk":"11449014024","pt":1717301838586,"mc":[{"id":"1.229554894","rc":[{"atb":[[1.75,10.46],[1.65,12.07]],"id":70003367},{"atb":[[1.96,8.17],[1.86,9.12]],"id":70003365}],"con":true,"img":false}]}
{"op":"mcm","clk":"11449015142","pt":1717301864401,"mc":[{"id":"1.229554894","rc":[{"atb":[[1.75,0],[1.65,0]],"id":70003367},{"atb":[[1.96,0],[1.86,0]],"id":70003365}],"con":true,"img":false}]}
{"op":"mcm","clk":"11449015693","pt":1717301876517,"mc":[{"id":"1.229554894","rc":[{"atb":[[1.67,11.71],[1.77,10.19]],"id":70003367},{"atb":[[1.85,9.23],[1.95,8.26]],"id":70003365}],"con":true,"img":false}]}
{"op":"mcm","clk":"11449020027","pt":1717301965559,"mc":[{"id":"1.229554894","rc":[{"atb":[[1.67,0],[1.77,0]],"id":70003367},{"atb":[[1.85,0],[1.95,0]],"id":70003365}],"con":true,"img":false}]}
{"op":"mcm","clk":"11449021328","pt":1717301995912,"mc":[{"id":"1.229554894","rc":[{"atb":[[1.67,11.71],[1.77,10.19]],"id":70003367},{"atb":[[1.85,9.23],[1.95,8.26]],"id":70003365}],"con":true,"img":false}]}
{"op":"mcm","clk":"11449022551","pt":1717302023434,"mc":[{"id":"1.229554894","rc":[{"atb":[[1.67,0],[1.77,0]],"id":70003367},{"atb":[[1.85,0],[1.95,0]],"id":70003365}],"con":true,"img":false}]}
{"op":"mcm","clk":"11449023125","pt":1717302036453,"mc":[{"id":"1.229554894","rc":[{"atb":[[1.81,9.68],[1.71,11.05]],"id":70003367},{"atb":[[1.83,9.45],[1.93,8.43]],"id":70003365}],"con":true,"img":false}]}
{"op":"mcm","clk":"11449024254","pt":1717302063805,"mc":[{"id":"1.229554894","rc":[{"atb":[[1.81,0],[1.71,0]],"id":70003367},{"atb":[[1.83,0],[1.93,0]],"id":70003365}],"con":true,"img":false}]}
{"op":"mcm","clk":"11449025396","pt":1717302090914,"mc":[{"id":"1.229554894","rc":[{"atb":[[1.79,9.93],[1.69,11.37]],"id":70003367},{"atb":[[1.84,9.34],[1.94,8.34]],"id":70003365}],"con":true,"img":false}]}
{"op":"mcm","clk":"11449025877","pt":1717302103368,"mc":[{"id":"1.229554894","rc":[{"atb":[[1.79,0],[1.69,0]],"id":70003367},{"atb":[[1.84,0],[1.94,0]],"id":70003365}],"con":true,"img":false}]}
{"op":"mcm","clk":"11449026267","pt":1717302113379,"mc":[{"id":"1.229554894","rc":[{"atb":[[1.82,9.56],[1.72,10.89]],"id":70003367},{"atb":[[1.82,9.56],[1.92,8.52]],"id":70003365}],"con":true,"img":false}]}
{"op":"mcm","clk":"11449222807","pt":1717305799206,"mc":[{"id":"1.229554894","rc":[{"atb":[[1.82,0],[1.72,0]],"id":70003367},{"atb":[[1.82,0],[1.92,0]],"id":70003365}],"con":true,"img":false}]}
{"op":"mcm","clk":"11449223866","pt":1717305813633,"mc":[{"id":"1.229554894","rc":[{"atb":[[1.73,10.75],[1.83,9.45]],"id":70003367},{"atb":[[1.81,9.68],[1.91,8.62]],"id":70003365}],"con":true,"img":false}]}
{"op":"mcm","clk":"11449228515","pt":1717305881485,"mc":[{"id":"1.229554894","rc":[{"atb":[[1.73,0],[1.83,0]],"id":70003367},{"atb":[[1.81,0],[1.91,0]],"id":70003365}],"con":true,"img":false}]}
{"op":"mcm","clk":"11449230796","pt":1717305912587,"mc":[{"id":"1.229554894","rc":[{"atb":[[1.73,10.75],[1.83,9.45]],"id":70003367},{"atb":[[1.81,9.68],[1.91,8.62]],"id":70003365}],"con":true,"img":false}]}
{"op":"mcm","clk":"11449233584","pt":1717305955949,"mc":[{"id":"1.229554894","rc":[{"atb":[[1.73,0],[1.83,0]],"id":70003367},{"atb":[[1.81,0],[1.91,0]],"id":70003365}],"con":true,"img":false}]}
{"op":"mcm","clk":"11449235522","pt":1717305983693,"mc":[{"id":"1.229554894","rc":[{"atb":[[1.73,10.75],[1.83,9.45]],"id":70003367},{"atb":[[1.81,9.68],[1.91,8.62]],"id":70003365}],"con":true,"img":false}]}
{"op":"mcm","clk":"11449237634","pt":1717306014418,"mc":[{"id":"1.229554894","rc":[{"atb":[[1.73,0],[1.83,0]],"id":70003367},{"atb":[[1.81,0],[1.91,0]],"id":70003365}],"con":true,"img":false}]}
{"op":"mcm","clk":"11449239495","pt":1717306042624,"mc":[{"id":"1.229554894","rc":[{"atb":[[1.73,10.75],[1.83,9.45]],"id":70003367},{"atb":[[1.81,9.68],[1.91,8.62]],"id":70003365}],"con":true,"img":false}]}
{"op":"mcm","clk":"11449258068","pt":1717306290438,"mc":[{"id":"1.229554894","rc":[{"atb":[[1.73,0],[1.83,0]],"id":70003367},{"atb":[[1.81,0],[1.91,0]],"id":70003365}],"con":true,"img":false}]}
{"op":"mcm","clk":"11449259122","pt":1717306303983,"mc":[{"id":"1.229554894","rc":[{"atb":[[1.77,10.19],[1.87,9.01]],"id":70003367},{"atb":[[1.79,9.93],[1.89,8.81]],"id":70003365}],"con":true,"img":false}]}
{"op":"mcm","clk":"11449262379","pt":1717306345732,"mc":[{"id":"1.229554894","rc":[{"atb":[[1.77,0],[1.87,0]],"id":70003367},{"atb":[[1.79,0],[1.89,0]],"id":70003365}],"con":true,"img":false}]}
{"op":"mcm","clk":"11449264590","pt":1717306375284,"mc":[{"id":"1.229554894","rc":[{"atb":[[1.8,9.8],[1.9,8.72]],"id":70003367},{"atb":[[1.86,9.12],[1.76,10.32]],"id":70003365}],"con":true,"img":false}]}
{"op":"mcm","clk":"11449301937","pt":1717306870185,"mc":[{"id":"1.229554894","rc":[{"atb":[[1.8,0],[1.9,0]],"id":70003367},{"atb":[[1.86,0],[1.76,0]],"id":70003365}],"con":true,"img":false}]}
{"op":"mcm","clk":"11449305698","pt":1717306920948,"mc":[{"id":"1.229554894","rc":[{"atb":[[1.8,9.8],[1.9,8.72]],"id":70003367},{"atb":[[1.86,9.12],[1.76,10.32]],"id":70003365}],"con":true,"img":false}]}
{"op":"mcm","clk":"11449334068","pt":1717307327945,"mc":[{"id":"1.229554894","rc":[{"atb":[[1.8,0],[1.9,0]],"id":70003367},{"atb":[[1.86,0],[1.76,0]],"id":70003365}],"con":true,"img":false}]}
{"op":"mcm","clk":"11449335808","pt":1717307354570,"mc":[{"id":"1.229554894","rc":[{"atb":[[1.8,9.8],[1.9,8.72]],"id":70003367},{"atb":[[1.86,9.12],[1.76,10.32]],"id":70003365}],"con":true,"img":false}]}
{"op":"mcm","clk":"11449341394","pt":1717307438903,"mc":[{"id":"1.229554894","rc":[{"atb":[[1.8,0],[1.9,0]],"id":70003367},{"atb":[[1.86,0],[1.76,0]],"id":70003365}],"con":true,"img":false}]}
{"op":"mcm","clk":"11449342048","pt":1717307452010,"mc":[{"id":"1.229554894","rc":[{"atb":[[1.88,8.92],[1.78,10.06]],"id":70003367},{"atb":[[1.88,8.92],[1.78,10.06]],"id":70003365}],"con":true,"img":false}]}
{"op":"mcm","clk":"11449358208","pt":1717307830444,"mc":[{"id":"1.229554894","rc":[{"atb":[[1.02,8.87]],"id":70003367},{"atl":[[1000,0.85]],"id":70003367},{"atb":[[1.03,5.92]],"id":70003365},{"atl":[[990,0.85]],"id":70003365}],"con":true,"img":false}]}
{"op":"mcm","clk":"11449363588","pt":1717307963207,"mc":[{"id":"1.229554894","rc":[{"atb":[[1.88,0],[1.78,0]],"id":70003367},{"atb":[[1.88,0],[1.78,0]],"id":70003365}],"con":true,"img":false}]}
{"op":"mcm","clk":"11449365070","pt":1717307998867,"mc":[{"id":"1.229554894","rc":[{"atb":[[1.88,8.92],[1.78,10.06]],"id":70003367},{"atb":[[1.88,8.92],[1.78,10.06]],"id":70003365}],"con":true,"img":false}]}
{"op":"mcm","clk":"11449433535","pt":1717309070258,"mc":[{"id":"1.229554894","rc":[{"atb":[[1.88,0],[1.78,0]],"id":70003367},{"atb":[[1.88,0],[1.78,0]],"id":70003365}],"con":true,"img":false}]}
{"op":"mcm","clk":"11449435536","pt":1717309098907,"mc":[{"id":"1.229554894","rc":[{"atb":[[1.88,8.92],[1.78,10.06]],"id":70003367},{"atb":[[1.88,8.92],[1.78,10.06]],"id":70003365}],"con":true,"img":false}]}
{"op":"mcm","clk":"11449497935","pt":1717309918839,"mc":[{"id":"1.229554894","rc":[{"atb":[[1.88,0],[1.78,0]],"id":70003367},{"atb":[[1.88,0],[1.78,0]],"id":70003365}],"con":true,"img":false}]}
{"op":"mcm","clk":"11449499427","pt":1717309943952,"mc":[{"id":"1.229554894","rc":[{"atb":[[1.88,8.92],[1.78,10.06]],"id":70003367},{"atb":[[1.88,8.92],[1.78,10.06]],"id":70003365}],"con":true,"img":false}]}
{"op":"mcm","clk":"11449550478","pt":1717310796927,"mc":[{"id":"1.229554894","rc":[{"atb":[[1.88,0],[1.78,0]],"id":70003367},{"atb":[[1.88,0],[1.78,0]],"id":70003365}],"con":true,"img":false}]}
{"op":"mcm","clk":"11449552522","pt":1717310833683,"mc":[{"id":"1.229554894","rc":[{"atb":[[1.88,8.92],[1.78,10.06]],"id":70003367},{"atb":[[1.88,8.92],[1.78,10.06]],"id":70003365}],"con":true,"img":false}]}
{"op":"mcm","clk":"11449586391","pt":1717311437388,"mc":[{"id":"1.229554894","rc":[{"atl":[[1000,0.17]],"id":70003367},{"atl":[[990,0.17]],"id":70003365}],"con":true,"img":false}]}
{"op":"mcm","clk":"11449590870","pt":1717311518992,"mc":[{"id":"1.229554894","rc":[{"atb":[[1.03,118.44]],"id":70003367},{"atl":[[960,1.04]],"id":70003367},{"atb":[[1.03,96.25]],"id":70003365},{"atl":[[990,2.19]],"id":70003365}],"con":true,"img":false}]}
{"op":"mcm","clk":"11449601391","pt":1717311718543,"mc":[{"id":"1.229554894","rc":[{"atb":[[1.88,0],[1.78,0]],"id":70003367},{"atb":[[1.88,0],[1.78,0]],"id":70003365}],"con":true,"img":false}]}
{"op":"mcm","clk":"11449603133","pt":1717311751590,"mc":[{"id":"1.229554894","rc":[{"atb":[[1.88,8.92],[1.78,10.06]],"id":70003367},{"atb":[[1.88,8.92],[1.78,10.06]],"id":70003365}],"con":true,"img":false}]}
{"op":"mcm","clk":"11449639293","pt":1717312554877,"mc":[{"id":"1.229554894","rc":[{"atb":[[1.88,0],[1.78,0]],"id":70003367},{"atb":[[1.88,0],[1.78,0]],"id":70003365}],"con":true,"img":false}]}
{"op":"mcm","clk":"11449639754","pt":1717312566647,"mc":[{"id":"1.229554894","rc":[{"atb":[[1.88,8.92],[1.78,10.06]],"id":70003367},{"atb":[[1.88,8.92],[1.78,10.06]],"id":70003365}],"con":true,"img":false}]}
{"op":"mcm","clk":"11449652040","pt":1717312860343,"mc":[{"id":"1.229554894","rc":[{"atl":[[19,2]],"id":70003367},{"atl":[[22,2.2]],"id":70003365}],"con":true,"img":false}]}
{"op":"mcm","clk":"11449652051","pt":1717312860546,"mc":[{"id":"1.229554894","rc":[{"atl":[[2.36,11.03],[2.4,14.29],[2.44,17.36],[2.48,20.27]],"id":70003367},{"atl":[[2.72,17.44],[2.6,9.38],[2.64,12.2],[2.68,14.88]],"id":70003365}],"con":true,"img":false}]}
{"op":"mcm","clk":"11449653673","pt":1717312897481,"mc":[{"id":"1.229554894","rc":[{"atl":[[19,0],[5.8,20.83]],"id":70003367},{"atl":[[6.4,18.52],[22,0]],"id":70003365}],"con":true,"img":false}]}
{"op":"mcm","clk":"11449655964","pt":1717312955983,"mc":[{"id":"1.229554894","rc":[{"atb":[[1.88,0],[1.78,0]],"id":70003367},{"atb":[[1.88,0],[1.78,0]],"id":70003365}],"con":true,"img":false}]}
{"op":"mcm","clk":"11449656051","pt":1717312958204,"mc":[{"id":"1.229554894","rc":[{"atb":[[1.41,36.59],[1.37,67.57],[1.39,51.28],[1.35,85.71]],"id":70003367},{"atb":[[1.46,43.48],[1.44,56.82],[1.42,71.43],[1.48,31.25]],"id":70003365}],"con":true,"img":false}]}
{"op":"mcm","clk":"11449656387","pt":1717312965929,"mc":[{"id":"1.229554894","rc":[{"atb":[[1.88,8.92],[1.78,10.06]],"id":70003367},{"atb":[[1.88,8.92],[1.78,10.06]],"id":70003365}],"con":true,"img":false}]}
{"op":"mcm","clk":"11449658596","pt":1717313021495,"mc":[{"id":"1.229554894","rc":[{"atb":[[1.48,0]],"id":70003365}],"con":true,"img":false}]}
{"op":"mcm","clk":"11449658601","pt":1717313021596,"mc":[{"id":"1.229554894","rc":[{"atl":[[2.6,0],[2.58,9.49]],"id":70003365}],"con":true,"img":false}]}
{"op":"mcm","clk":"11449658728","pt":1717313024730,"mc":[{"id":"1.229554894","rc":[{"atl":[[2.6,9.38],[2.58,0]],"id":70003365}],"con":true,"img":false}]}
{"op":"mcm","clk":"11449658738","pt":1717313024881,"mc":[{"id":"1.229554894","rc":[{"atb":[[1.41,0]],"id":70003367},{"atl":[[2.6,0],[2.58,9.49]],"id":70003365}],"con":true,"img":false}]}
{"op":"mcm","clk":"11449658778","pt":1717313025805,"mc":[{"id":"1.229554894","rc":[{"atl":[[2.6,9.38],[2.58,0]],"id":70003365}],"con":true,"img":false}]}
{"op":"mcm","clk":"11449658793","pt":1717313026018,"mc":[{"id":"1.229554894","rc":[{"atl":[[2.6,0],[2.58,9.49]],"id":70003365}],"con":true,"img":false}]}
{"op":"mcm","clk":"11449658914","pt":1717313028426,"mc":[{"id":"1.229554894","rc":[{"atl":[[2.6,9.38]],"id":70003365}],"con":true,"img":false}]}
{"op":"mcm","clk":"11449658921","pt":1717313028526,"mc":[{"id":"1.229554894","rc":[{"atl":[[2.58,0]],"id":70003365}],"con":true,"img":false}]}
{"op":"mcm","clk":"11449659858","pt":1717313050669,"mc":[{"id":"1.229554894","rc":[{"atl":[[2.6,0],[2.58,9.49]],"id":70003365}],"con":true,"img":false}]}
{"op":"mcm","clk":"11449660229","pt":1717313059621,"mc":[{"id":"1.229554894","rc":[{"atl":[[2.6,9.38],[2.58,0]],"id":70003365}],"con":true,"img":false}]}
{"op":"mcm","clk":"11449660351","pt":1717313062339,"mc":[{"id":"1.229554894","rc":[{"atl":[[2.36,0],[2.34,11.19]],"id":70003367}],"con":true,"img":false}]}
{"op":"mcm","clk":"11449660357","pt":1717313062439,"mc":[{"id":"1.229554894","rc":[{"atl":[[2.32,11.36]],"id":70003367}],"con":true,"img":false}]}
{"op":"mcm","clk":"11449660636","pt":1717313070765,"mc":[{"id":"1.229554894","rc":[{"atl":[[2.34,0],[2.48,0]],"id":70003367}],"con":true,"img":false}]}
{"op":"mcm","clk":"11449660711","pt":1717313072460,"mc":[{"id":"1.229554894","rc":[{"atl":[[2.36,14.71]],"id":70003367}],"con":true,"img":false}]}
{"op":"mcm","clk":"11449660933","pt":1717313078775,"mc":[{"id":"1.229554894","rc":[{"atl":[[2.32,0],[2.34,11.19]],"id":70003367}],"con":true,"img":false}]}
{"op":"mcm","clk":"11449664094","pt":1717313143261,"mc":[{"id":"1.229554894","rc":[{"atb":[[1.88,0],[1.78,0]],"id":70003367},{"atb":[[1.88,0],[1.78,0]],"id":70003365}],"con":true,"img":false}]}
{"op":"mcm","clk":"11449664127","pt":1717313143832,"mc":[{"id":"1.229554894","rc":[{"atb":[[1.42,35.71]],"id":70003367},{"atb":[[1.53,28.3]],"id":70003365}],"con":true,"img":false}]}
{"op":"mcm","clk":"11449664384","pt":1717313150855,"mc":[{"id":"1.229554894","rc":[{"atb":[[1.39,89.74]],"id":70003367},{"atb":[[1.5,30],[1.53,0]],"id":70003365}],"con":true,"img":false}]}
{"op":"mcm","clk":"11449664387","pt":1717313150956,"mc":[{"id":"1.229554894","rc":[{"atb":[[1.42,0],[1.39,38.46]],"id":70003367}],"con":true,"img":false}]}
{"op":"mcm","clk":"11449664524","pt":1717313153542,"mc":[{"id":"1.229554894","rc":[{"atl":[[2.32,11.36],[2.34,0]],"id":70003367}],"con":true,"img":false}]}
{"op":"mcm","clk":"11449664834","pt":1717313160843,"mc":[{"id":"1.229554894","rc":[{"atb":[[1.48,41.67]],"id":70003365}],"con":true,"img":false}]}
{"op":"mcm","clk":"11449664941","pt":1717313163474,"mc":[{"id":"1.229554894","rc":[{"atb":[[1.42,0]],"id":70003365}],"con":true,"img":false}]}
{"op":"mcm","clk":"11449664947","pt":1717313163578,"mc":[{"id":"1.229554894","rc":[{"atb":[[1.37,54.05]],"id":70003367}],"con":true,"img":false}]}
{"op":"mcm","clk":"11449665160","pt":1717313168466,"mc":[{"id":"1.229554894","rc":[{"atl":[[2.32,0],[2.34,11.19]],"id":70003367}],"con":true,"img":false}]}
{"op":"mcm","clk":"11449665503","pt":1717313176402,"mc":[{"id":"1.229554894","rc":[{"atb":[[1.88,8.92],[1.78,10.06]],"id":70003367},{"atb":[[1.88,8.92],[1.78,10.06]],"id":70003365}],"con":true,"img":false}]}
{"op":"mcm","clk":"11449666142","pt":1717313191808,"mc":[{"id":"1.229554894","rc":[{"atl":[[2.6,0],[2.58,9.49]],"id":70003365}],"con":true,"img":false}]}
{"op":"mcm","clk":"11449666574","pt":1717313200926,"mc":[{"id":"1.229554894","rc":[{"atl":[[2.36,11.03],[2.34,0]],"id":70003367},{"atl":[[2.6,9.38],[2.58,0]],"id":70003365}],"con":true,"img":false}]}
{"op":"mcm","clk":"11449666804","pt":1717313205516,"mc":[{"id":"1.229554894","rc":[{"atl":[[2.6,0],[2.66,9.04]],"id":70003365}],"con":true,"img":false}]}
{"op":"mcm","clk":"11449667070","pt":1717313210501,"mc":[{"id":"1.229554894","rc":[{"atl":[[2.64,0]],"id":70003365}],"con":true,"img":false}]}
{"op":"mcm","clk":"11449667096","pt":1717313210910,"mc":[{"id":"1.229554894","rc":[{"atl":[[2.48,20.27]],"id":70003367}],"con":true,"img":false}]}
{"op":"mcm","clk":"11449667339","pt":1717313215510,"mc":[{"id":"1.229554894","rc":[{"atb":[[1.88,0],[1.78,0]],"id":70003367},{"atb":[[1.88,0],[1.78,0]],"id":70003365},{"atl":[[2.7,11.76]],"id":70003365}],"con":true,"img":false}]}
{"op":"mcm","clk":"11449667351","pt":1717313215726,"mc":[{"id":"1.229554894","rc":[{"atb":[[1.4,37.5]],"id":70003367}],"con":true,"img":false}]}
{"op":"mcm","clk":"11449668017","pt":1717313230061,"mc":[{"id":"1.229554894","rc":[{"atb":[[1.88,8.92],[1.78,10.06]],"id":70003367},{"atb":[[1.88,8.92],[1.78,10.06]],"id":70003365}],"con":true,"img":false}]}
{"op":"mcm","clk":"11449670111","pt":1717313273218,"mc":[{"id":"1.229554894","rc":[{"atb":[[1.88,0],[1.78,0]],"id":70003367},{"atb":[[1.88,0],[1.78,0]],"id":70003365}],"con":true,"img":false}]}
{"op":"mcm","clk":"11449671569","pt":1717313301739,"mc":[{"id":"1.229554894","rc":[{"atb":[[1.88,8.92],[1.78,10.06]],"id":70003367},{"atb":[[1.88,8.92],[1.78,10.06]],"id":70003365}],"con":true,"img":false}]}
{"op":"mcm","clk":"11449673061","pt":1717313329596,"mc":[{"id":"1.229554894","rc":[{"atb":[[1.88,0],[1.78,0]],"id":70003367},{"atb":[[1.88,0],[1.78,0]],"id":70003365}],"con":true,"img":false}]}
{"op":"mcm","clk":"11449673642","pt":1717313340501,"mc":[{"id":"1.229554894","rc":[{"atb":[[1.88,8.92],[1.78,10.06]],"id":70003367},{"atb":[[1.88,8.92],[1.78,10.06]],"id":70003365}],"con":true,"img":false}]}
{"op":"mcm","clk":"11449676841","pt":1717313393936,"mc":[{"id":"1.229554894","rc":[{"atl":[[2.36,0],[2.34,11.19]],"id":70003367},{"atl":[[2.66,0],[2.64,9.15]],"id":70003365}],"con":true,"img":false}]}
{"op":"mcm","clk":"11449678401","pt":1717313415574,"mc":[{"id":"1.229554894","rc":[{"atl":[[2.36,11.03]],"id":70003367},{"atl":[[2.66,9.04]],"id":70003365}],"con":true,"img":false}]}
{"op":"mcm","clk":"11449678406","pt":1717313415677,"mc":[{"id":"1.229554894","rc":[{"atl":[[2.34,0]],"id":70003367},{"atl":[[2.64,0]],"id":70003365}],"con":true,"img":false}]}
{"op":"mcm","clk":"11449678831","pt":1717313421855,"mc":[{"id":"1.229554894","rc":[{"atb":[[1.4,0],[1.39,0]],"id":70003367},{"atl":[[2.36,0],[2.4,10.71]],"id":70003367},{"atb":[[1.5,0],[1.48,0]],"id":70003365},{"atl":[[2.7,20.58]],"id":70003365}],"con":true,"img":false}]}
{"op":"mcm","clk":"11449678863","pt":1717313421955,"mc":[{"id":"1.229554894","rc":[{"atl":[[2.66,0],[2.7,8.82]],"id":70003365}],"con":true,"img":false}]}
{"op":"mcm","clk":"11449679451","pt":1717313431893,"mc":[{"id":"1.229554894","rc":[{"atl":[[2.36,11.03]],"id":70003367},{"atl":[[2.66,9.04]],"id":70003365}],"con":true,"img":false}]}
{"op":"mcm","clk":"11449684562","pt":1717313496885,"mc":[{"id":"1.229554894","rc":[{"atl":[[2.34,11.19]],"id":70003367},{"atl":[[2.66,0],[2.64,9.15]],"id":70003365}],"con":true,"img":false}]}
{"op":"mcm","clk":"11449684572","pt":1717313496987,"mc":[{"id":"1.229554894","rc":[{"atl":[[2.36,0]],"id":70003367}],"con":true,"img":false}]}
{"op":"mcm","clk":"11449703761","pt":1717313733840,"mc":[{"id":"1.229554894","rc":[{"atb":[[1.88,0],[1.78,0]],"id":70003367},{"atb":[[1.88,0],[1.78,0]],"id":70003365}],"con":true,"img":false}]}
{"op":"mcm","clk":"11449703788","pt":1717313734151,"mc":[{"id":"1.229554894","rc":[{"atb":[[1.39,38.46]],"id":70003367},{"atb":[[1.48,31.25]],"id":70003365}],"con":true,"img":false}]}
{"op":"mcm","clk":"11449704566","pt":1717313744104,"mc":[{"id":"1.229554894","rc":[{"atb":[[1.35,157.14]],"id":70003367},{"atb":[[1.42,71.43]],"id":70003365}],"con":true,"img":false}]}
{"op":"mcm","clk":"11449704572","pt":1717313744206,"mc":[{"id":"1.229554894","rc":[{"atb":[[1.35,71.43]],"id":70003367}],"con":true,"img":false}]}
{"op":"mcm","clk":"11449705303","pt":1717313752774,"mc":[{"id":"1.229554894","rc":[{"atb":[[1.88,8.92],[1.78,10.06]],"id":70003367},{"atb":[[1.88,8.92],[1.78,10.06]],"id":70003365}],"con":true,"img":false}]}
{"op":"mcm","clk":"11449706455","pt":1717313766754,"mc":[{"id":"1.229554894","rc":[{"atl":[[2.36,11.03],[2.34,0]],"id":70003367},{"atl":[[2.64,0],[2.6,9.38],[2.58,9.49]],"id":70003365}],"con":true,"img":false}]}
{"op":"mcm","clk":"11449706463","pt":1717313766856,"mc":[{"id":"1.229554894","rc":[{"atb":[[1.39,0]],"id":70003367}],"con":true,"img":false}]}
{"op":"mcm","clk":"11449706599","pt":1717313768348,"mc":[{"id":"1.229554894","rc":[{"atl":[[2.72,0],[2.6,0],[2.68,0]],"id":70003365}],"con":true,"img":false}]}
{"op":"mcm","clk":"11449707363","pt":1717313776808,"mc":[{"id":"1.229554894","rc":[{"atl":[[2.62,12.35]],"id":70003365}],"con":true,"img":false}]}
{"op":"mcm","clk":"11449708213","pt":1717313786823,"mc":[{"id":"1.229554894","rc":[{"atl":[[2.66,15.06]],"id":70003365}],"con":true,"img":false}]}
{"op":"mcm","clk":"11449736707","pt":1717314096394,"mc":[{"id":"1.229554894","rc":[{"atb":[[1.88,0],[1.78,0]],"id":70003367},{"atb":[[1.88,0],[1.78,0]],"id":70003365}],"con":true,"img":false}]}
{"op":"mcm","clk":"11449736747","pt":1717314096812,"mc":[{"id":"1.229554894","rc":[{"atb":[[1.38,39.47]],"id":70003367}],"con":true,"img":false}]}
{"op":"mcm","clk":"11449737629","pt":1717314106807,"mc":[{"id":"1.229554894","rc":[{"atb":[[1.36,55.56]],"id":70003367}],"con":true,"img":false}]}
{"op":"mcm","clk":"11449739258","pt":1717314124126,"mc":[{"id":"1.229554894","rc":[{"atb":[[1.88,8.92],[1.78,10.06]],"id":70003367},{"atb":[[1.88,8.92],[1.78,10.06]],"id":70003365}],"con":true,"img":false}]}
{"op":"mcm","clk":"11449763580","pt":1717314396739,"mc":[{"id":"1.229554894","rc":[{"atl":[[2.36,0],[2.34,11.19]],"id":70003367},{"atb":[[1.48,0]],"id":70003365},{"atl":[[2.6,9.38],[2.58,0]],"id":70003365}],"con":true,"img":false}]}
{"op":"mcm","clk":"11449763935","pt":1717314401226,"mc":[{"id":"1.229554894","rc":[{"atl":[[2.36,11.03]],"id":70003367},{"atl":[[2.58,9.49]],"id":70003365}],"con":true,"img":false}]}
{"op":"mcm","clk":"11449763943","pt":1717314401338,"mc":[{"id":"1.229554894","rc":[{"atl":[[2.34,0]],"id":70003367},{"atl":[[2.6,0]],"id":70003365}],"con":true,"img":false}]}
{"op":"mcm","clk":"11449764792","pt":1717314411242,"mc":[{"id":"1.229554894","rc":[{"atl":[[2.6,9.38]],"id":70003365}],"con":true,"img":false}]}
{"op":"mcm","clk":"11449764803","pt":1717314411350,"mc":[{"id":"1.229554894","rc":[{"atl":[[2.36,0],[2.34,11.19]],"id":70003367},{"atl":[[2.58,0]],"id":70003365}],"con":true,"img":false}]}
{"op":"mcm","clk":"11449766639","pt":1717314431677,"mc":[{"id":"1.229554894","rc":[{"atb":[[1.88,0],[1.78,0]],"id":70003367},{"atb":[[1.88,0],[1.78,0]],"id":70003365}],"con":true,"img":false}]}
{"op":"mcm","clk":"11449766663","pt":1717314431839,"mc":[{"id":"1.229554894","rc":[{"atb":[[1.39,38.46],[1.38,0]],"id":70003367},{"atb":[[1.48,31.25]],"id":70003365}],"con":true,"img":false}]}
{"op":"mcm","clk":"11449767141","pt":1717314436654,"mc":[{"id":"1.229554894","rc":[{"atb":[[1.47,31.91]],"id":70003365}],"con":true,"img":false}]}
{"op":"mcm","clk":"11449767148","pt":1717314436758,"mc":[{"id":"1.229554894","rc":[{"atb":[[1.48,0]],"id":70003365}],"con":true,"img":false}]}
{"op":"mcm","clk":"11449767271","pt":1717314438142,"mc":[{"id":"1.229554894","rc":[{"atl":[[2.36,11.03]],"id":70003367},{"atl":[[2.62,21.61]],"id":70003365}],"con":true,"img":false}]}
{"op":"mcm","clk":"11449767282","pt":1717314438245,"mc":[{"id":"1.229554894","rc":[{"atl":[[2.34,0]],"id":70003367},{"atl":[[2.6,0],[2.62,9.26]],"id":70003365}],"con":true,"img":false}]}
{"op":"mcm","clk":"11449767953","pt":1717314446185,"mc":[{"id":"1.229554894","rc":[{"atb":[[1.88,8.92],[1.78,10.06]],"id":70003367},{"atb":[[1.88,8.92],[1.78,10.06]],"id":70003365}],"con":true,"img":false}]}
{"op":"mcm","clk":"11449768131","pt":1717314448189,"mc":[{"id":"1.229554894","rc":[{"atl":[[2.66,12.05]],"id":70003365}],"con":true,"img":false}]}
{"op":"mcm","clk":"11449768942","pt":1717314458185,"mc":[{"id":"1.229554894","rc":[{"atl":[[2.7,14.71]],"id":70003365}],"con":true,"img":false}]}
{"op":"mcm","clk":"11449769785","pt":1717314468176,"mc":[{"id":"1.229554894","rc":[{"atl":[[2.74,17.24]],"id":70003365}],"con":true,"img":false}]}
{"op":"mcm","clk":"11449782186","pt":1717314606314,"mc":[{"id":"1.229554894","rc":[{"atb":[[1.39,0]],"id":70003367}],"con":true,"img":false}]}
{"op":"mcm","clk":"11449782192","pt":1717314606417,"mc":[{"id":"1.229554894","rc":[{"atl":[[2.36,0],[2.42,10.56]],"id":70003367},{"atl":[[2.7,23.53]],"id":70003365}],"con":true,"img":false}]}
{"op":"mcm","clk":"11449782196","pt":1717314606472,"mc":[{"id":"1.229554894","rc":[{"atl":[[2.62,0],[2.7,8.82]],"id":70003365}],"con":true,"img":false}]}
{"op":"mcm","clk":"11449782383","pt":1717314609002,"mc":[{"id":"1.229554894","rc":[{"atl":[[2.4,0],[2.36,11.03]],"id":70003367},{"atl":[[2.66,0],[2.62,9.26]],"id":70003365}],"con":true,"img":false}]}
{"op":"mcm","clk":"11449782570","pt":1717314611415,"mc":[{"id":"1.229554894","rc":[{"atl":[[2.36,0]],"id":70003367},{"atl":[[2.62,0]],"id":70003365}],"con":true,"img":false}]}
{"op":"mcm","clk":"11449782641","pt":1717314612294,"mc":[{"id":"1.229554894","rc":[{"atl":[[2.36,11.03]],"id":70003367},{"atl":[[2.62,9.26]],"id":70003365}],"con":true,"img":false}]}
{"op":"mcm","clk":"11449783457","pt":1717314622340,"mc":[{"id":"1.229554894","rc":[{"atl":[[2.66,12.05]],"id":70003365}],"con":true,"img":false}]}
{"op":"mcm","clk":"11449784879","pt":1717314640567,"mc":[{"id":"1.229554894","rc":[{"atl":[[2.36,0]],"id":70003367},{"atl":[[2.62,0]],"id":70003365}],"con":true,"img":false}]}
{"op":"mcm","clk":"11449785011","pt":1717314642271,"mc":[{"id":"1.229554894","rc":[{"atl":[[2.64,9.15]],"id":70003365}],"con":true,"img":false}]}
{"op":"mcm","clk":"11449785035","pt":1717314642599,"mc":[{"id":"1.229554894","rc":[{"atl":[[2.36,11.03]],"id":70003367},{"atl":[[2.64,0],[2.58,9.49]],"id":70003365}],"con":true,"img":false}]}
{"op":"mcm","clk":"11449785066","pt":1717314642964,"mc":[{"id":"1.229554894","rc":[{"atl":[[2.36,0]],"id":70003367},{"atl":[[2.64,9.15],[2.58,0]],"id":70003365}],"con":true,"img":false}]}
{"op":"mcm","clk":"11449785842","pt":1717314652597,"mc":[{"id":"1.229554894","rc":[{"atl":[[2.46,13.7]],"id":70003367}],"con":true,"img":false}]}
{"op":"mcm","clk":"11449786573","pt":1717314661301,"mc":[{"id":"1.229554894","rc":[{"atl":[[2.4,10.71],[2.42,0]],"id":70003367},{"atl":[[2.64,0],[2.62,9.26]],"id":70003365}],"con":true,"img":false}]}
{"op":"mcm","clk":"11449786987","pt":1717314665911,"mc":[{"id":"1.229554894","rc":[{"atl":[[2.4,0],[2.38,10.87]],"id":70003367},{"atl":[[2.6,9.38],[2.62,0]],"id":70003365}],"con":true,"img":false}]}
{"op":"mcm","clk":"11449787047","pt":1717314666632,"mc":[{"id":"1.229554894","rc":[{"atb":[[1.88,0],[1.78,0]],"id":70003367},{"atb":[[1.88,0],[1.78,0]],"id":70003365}],"con":true,"img":false}]}
{"op":"mcm","clk":"11449787058","pt":1717314666687,"mc":[{"id":"1.229554894","rc":[{"atb":[[1.44,34.09]],"id":70003367},{"atl":[[2.36,11.03],[2.38,0]],"id":70003367},{"atb":[[1.49,30.61]],"id":70003365},{"atl":[[2.58,9.49]],"id":70003365}],"con":true,"img":false}]}
{"op":"mcm","clk":"11449787067","pt":1717314666790,"mc":[{"id":"1.229554894","rc":[{"atb":[[1.47,0]],"id":70003365},{"atl":[[2.6,0]],"id":70003365}],"con":true,"img":false}]}
{"op":"mcm","clk":"11449787446","pt":1717314671309,"mc":[{"id":"1.229554894","rc":[{"atl":[[2.36,0],[2.38,10.87]],"id":70003367},{"atl":[[2.6,9.38],[2.58,0]],"id":70003365}],"con":true,"img":false}]}
{"op":"mcm","clk":"11449788412","pt":1717314681376,"mc":[{"id":"1.229554894","rc":[{"atb":[[1.42,47.62]],"id":70003367}],"con":true,"img":false}]}
{"op":"mcm","clk":"11449788961","pt":1717314686841,"mc":[{"id":"1.229554894","rc":[{"atb":[[1.35,0]],"id":70003367},{"atl":[[2.4,10.71],[2.38,0]],"id":70003367},{"atl":[[2.56,9.62],[2.6,0]],"id":70003365}],"con":true,"img":false}]}
{"op":"mcm","clk":"11449789853","pt":1717314696849,"mc":[{"id":"1.229554894","rc":[{"atb":[[1.4,62.5]],"id":70003367},{"atl":[[2.6,12.5]],"id":70003365}],"con":true,"img":false}]}
{"op":"mcm","clk":"11449789916","pt":1717314697724,"mc":[{"id":"1.229554894","rc":[{"atb":[[1.36,0]],"id":70003367},{"atl":[[2.74,0],[2.66,0],[2.7,0]],"id":70003365}],"con":true,"img":false}]}
{"op":"mcm","clk":"11449789967","pt":1717314698243,"mc":[{"id":"1.229554894","rc":[{"atb":[[1.88,8.92],[1.78,10.06]],"id":70003367},{"atb":[[1.88,8.92],[1.78,10.06]],"id":70003365}],"con":true,"img":false}]}
{"op":"mcm","clk":"11449790761","pt":1717314706832,"mc":[{"id":"1.229554894","rc":[{"atl":[[2.64,15.24]],"id":70003365}],"con":true,"img":false}]}
{"op":"mcm","clk":"11449791588","pt":1717314716789,"mc":[{"id":"1.229554894","rc":[{"atl":[[2.68,17.86]],"id":70003365}],"con":true,"img":false}]}
{"op":"mcm","clk":"11449791920","pt":1717314720695,"mc":[{"id":"1.229554894","rc":[{"atl":[[2.54,9.74]],"id":70003365}],"con":true,"img":false}]}
{"op":"mcm","clk":"11449791933","pt":1717314720803,"mc":[{"id":"1.229554894","rc":[{"atb":[[1.44,0],[1.42,0]],"id":70003367},{"atb":[[1.49,0]],"id":70003365},{"atl":[[2.56,0]],"id":70003365}],"con":true,"img":false}]}
{"op":"mcm","clk":"11449792131","pt":1717314723000,"mc":[{"id":"1.229554894","rc":[{"atl":[[2.36,11.03]],"id":70003367},{"atl":[[2.56,9.62]],"id":70003365}],"con":true,"img":false}]}
{"op":"mcm","clk":"11449792140","pt":1717314723103,"mc":[{"id":"1.229554894","rc":[{"atl":[[2.4,0]],"id":70003367},{"atl":[[2.54,0]],"id":70003365}],"con":true,"img":false}]}
{"op":"mcm","clk":"11449792879","pt":1717314731732,"mc":[{"id":"1.229554894","rc":[{"atb":[[1.88,0],[1.78,0]],"id":70003367},{"atb":[[1.88,0],[1.78,0]],"id":70003365}],"con":true,"img":false}]}
{"op":"mcm","clk":"11449792921","pt":1717314732196,"mc":[{"id":"1.229554894","rc":[{"atb":[[1.42,35.71]],"id":70003367},{"atb":[[1.47,31.91]],"id":70003365}],"con":true,"img":false}]}
{"op":"mcm","clk":"11449793324","pt":1717314737132,"mc":[{"id":"1.229554894","rc":[{"atb":[[1.88,8.92],[1.78,10.06]],"id":70003367},{"atb":[[1.88,8.92],[1.78,10.06]],"id":70003365}],"con":true,"img":false}]}
{"op":"mcm","clk":"11449796703","pt":1717314777055,"mc":[{"id":"1.229554894","rc":[{"atb":[[1.88,0],[1.78,0]],"id":70003367},{"atb":[[1.88,0],[1.78,0]],"id":70003365}],"con":true,"img":false}]}
{"op":"mcm","clk":"11449797469","pt":1717314786209,"mc":[{"id":"1.229554894","rc":[{"atb":[[1.44,34.09]],"id":70003367},{"atl":[[2.36,0],[2.38,10.87]],"id":70003367},{"atb":[[1.49,30.61],[1.47,0]],"id":70003365},{"atl":[[2.5,10]],"id":70003365}],"con":true,"img":false}]}
{"op":"mcm","clk":"11449797478","pt":1717314786314,"mc":[{"id":"1.229554894","rc":[{"atl":[[2.56,0]],"id":70003365}],"con":true,"img":false}]}
{"op":"mcm","clk":"11449798310","pt":1717314796216,"mc":[{"id":"1.229554894","rc":[{"atl":[[2.54,12.99]],"id":70003365}],"con":true,"img":false}]}
{"op":"mcm","clk":"11449798933","pt":1717314804338,"mc":[{"id":"1.229554894","rc":[{"atl":[[2.6,0],[2.64,0],[2.68,0]],"id":70003365}],"con":true,"img":false}]}
{"op":"mcm","clk":"11449799075","pt":1717314806236,"mc":[{"id":"1.229554894","rc":[{"atl":[[2.58,15.82]],"id":70003365}],"con":true,"img":false}]}
{"op":"mcm","clk":"11449799957","pt":1717314816230,"mc":[{"id":"1.229554894","rc":[{"atl":[[2.62,18.52]],"id":70003365}],"con":true,"img":false}]}
{"op":"mcm","clk":"11449800959","pt":1717314827264,"mc":[{"id":"1.229554894","rc":[{"atb":[[1.88,8.92],[1.78,10.06]],"id":70003367},{"atb":[[1.88,8.92],[1.78,10.06]],"id":70003365}],"con":true,"img":false}]}
{"op":"mcm","clk":"11449822832","pt":1717315069804,"mc":[{"id":"1.229554894","rc":[{"atb":[[1.44,0],[1.42,0]],"id":70003367},{"atb":[[1.49,0]],"id":70003365}],"con":true,"img":false}]}
{"op":"mcm","clk":"11449823725","pt":1717315079807,"mc":[{"id":"1.229554894","rc":[{"atl":[[2.56,9.62],[2.5,0]],"id":70003365}],"con":true,"img":false}]}
{"op":"mcm","clk":"11449823745","pt":1717315080009,"mc":[{"id":"1.229554894","rc":[{"atl":[[2.54,0]],"id":70003365}],"con":true,"img":false}]}
{"op":"mcm","clk":"11449824606","pt":1717315089836,"mc":[{"id":"1.229554894","rc":[{"atl":[[2.6,12.5]],"id":70003365}],"con":true,"img":false}]}
{"op":"mcm","clk":"11449836720","pt":1717315147889,"mc":[{"id":"1.229554894","rc":[{"atl":[[2.4,10.71]],"id":70003367}],"con":true,"img":false}]}
{"op":"mcm","clk":"11449836732","pt":1717315148038,"mc":[{"id":"1.229554894","rc":[{"atl":[[2.38,0]],"id":70003367}],"con":true,"img":false}]}
{"op":"mcm","clk":"11449836740","pt":1717315148094,"mc":[{"id":"1.229554894","rc":[{"atl":[[2.4,0],[2.44,0],[2.48,0]],"id":70003367}],"con":true,"img":false}]}
{"op":"mcm","clk":"11449836762","pt":1717315148298,"mc":[{"id":"1.229554894","rc":[{"atl":[[5.8,0],[20,5.26]],"id":70003367}],"con":true,"img":false}]}
{"op":"mcm","clk":"11449836819","pt":1717315149116,"mc":[{"id":"1.229554894","rc":[{"atl":[[2.38,10.87]],"id":70003367}],"con":true,"img":false}]}
{"op":"mcm","clk":"11449837753","pt":1717315159102,"mc":[{"id":"1.229554894","rc":[{"atl":[[2.42,14.08]],"id":70003367}],"con":true,"img":false}]}
{"op":"mcm","clk":"11449837761","pt":1717315159206,"mc":[{"id":"1.229554894","rc":[{"atl":[[20,0],[6,20]],"id":70003367}],"con":true,"img":false}]}
{"op":"mcm","clk":"11449837792","pt":1717315159522,"mc":[{"id":"1.229554894","rc":[{"atl":[[2.34,11.19]],"id":70003367},{"atl":[[2.56,0],[2.5,10]],"id":70003365}],"con":true,"img":false}]}
{"op":"mcm","clk":"11449837815","pt":1717315159824,"mc":[{"id":"1.229554894","rc":[{"atl":[[2.4,10.71],[2.34,0]],"id":70003367},{"atl":[[2.54,9.74],[2.5,0],[2.52,9.87]],"id":70003365}],"con":true,"img":false}]}
{"op":"mcm","clk":"11449837894","pt":1717315160729,"mc":[{"id":"1.229554894","rc":[{"atb":[[1.88,0],[1.78,0]],"id":70003367},{"atl":[[2.38,0],[2.34,11.19]],"id":70003367},{"atb":[[1.88,0],[1.78,0]],"id":70003365},{"atl":[[2.56,9.62],[2.54,0],[2.5,10],[2.52,0],[2.6,0],[2.58,0],[2.62,0]],"id":70003365}],"con":true,"img":false}]}
{"op":"mcm","clk":"11449837907","pt":1717315160824,"mc":[{"id":"1.229554894","rc":[{"atl":[[6.2,19.23]],"id":70003365}],"con":true,"img":false}]}
{"op":"mcm","clk":"11449837917","pt":1717315160931,"mc":[{"id":"1.229554894","rc":[{"atb":[[1.44,34.09]],"id":70003367},{"atb":[[1.49,30.61]],"id":70003365},{"atl":[[6.4,0]],"id":70003365}],"con":true,"img":false}]}
{"op":"mcm","clk":"11449838163","pt":1717315163415,"mc":[{"id":"1.229554894","rc":[{"atb":[[1.42,35.71]],"id":70003367},{"atl":[[2.38,10.87]],"id":70003367},{"atb":[[1.49,0],[1.47,31.91]],"id":70003365},{"atl":[[2.5,0]],"id":70003365}],"con":true,"img":false}]}
{"op":"mcm","clk":"11449838176","pt":1717315163521,"mc":[{"id":"1.229554894","rc":[{"atb":[[1.44,0]],"id":70003367},{"atl":[[2.34,0]],"id":70003367},{"atl":[[6.2,0],[21,5]],"id":70003365}],"con":true,"img":false}]}
{"op":"mcm","clk":"11449838926","pt":1717315171646,"mc":[{"id":"1.229554894","rc":[{"atb":[[1.44,34.09]],"id":70003367},{"atl":[[2.38,0]],"id":70003367},{"atb":[[1.49,30.61],[1.47,0]],"id":70003365},{"atl":[[2.54,9.74],[2.5,10]],"id":70003365}],"con":true,"img":false}]}
{"op":"mcm","clk":"11449838939","pt":1717315171750,"mc":[{"id":"1.229554894","rc":[{"atl":[[2.34,11.19]],"id":70003367},{"atl":[[6.2,19.23]],"id":70003365}],"con":true,"img":false}]}
{"op":"mcm","clk":"11449838949","pt":1717315171849,"mc":[{"id":"1.229554894","rc":[{"atl":[[21,0]],"id":70003365}],"con":true,"img":false}]}
{"op":"mcm","clk":"11449838982","pt":1717315172118,"mc":[{"id":"1.229554894","rc":[{"atb":[[1.44,0]],"id":70003367},{"atl":[[2.38,10.87]],"id":70003367},{"atb":[[1.47,31.91]],"id":70003365}],"con":true,"img":false}]}
{"op":"mcm","clk":"11449838992","pt":1717315172220,"mc":[{"id":"1.229554894","rc":[{"atl":[[2.34,0]],"id":70003367},{"atb":[[1.49,0]],"id":70003365},{"atl":[[2.5,0]],"id":70003365}],"con":true,"img":false}]}
{"op":"mcm","clk":"11449839229","pt":1717315174443,"mc":[{"id":"1.229554894","rc":[{"atb":[[1.44,34.09]],"id":70003367},{"atb":[[1.49,30.61],[1.47,0]],"id":70003365},{"atl":[[2.54,0]],"id":70003365}],"con":true,"img":false}]}
{"op":"mcm","clk":"11449839260","pt":1717315174757,"mc":[{"id":"1.229554894","rc":[{"atl":[[2.38,0],[2.34,11.19]],"id":70003367},{"atl":[[2.5,10],[2.52,9.87]],"id":70003365}],"con":true,"img":false}]}
{"op":"mcm","clk":"11449839397","pt":1717315176048,"mc":[{"id":"1.229554894","rc":[{"atl":[[2.38,10.87]],"id":70003367},{"atl":[[2.54,9.74],[2.5,0]],"id":70003365}],"con":true,"img":false}]}
{"op":"mcm","clk":"11449839406","pt":1717315176152,"mc":[{"id":"1.229554894","rc":[{"atl":[[2.34,0]],"id":70003367}],"con":true,"img":false}]}
{"op":"mcm","clk":"11449839714","pt":1717315179230,"mc":[{"id":"1.229554894","rc":[{"atl":[[2.38,0]],"id":70003367},{"atl":[[2.52,0]],"id":70003365}],"con":true,"img":false}]}
{"op":"mcm","clk":"11449839933","pt":1717315181546,"mc":[{"id":"1.229554894","rc":[{"atb":[[1.41,36.59],[1.44,0]],"id":70003367},{"atb":[[1.49,0],[1.47,31.91]],"id":70003365}],"con":true,"img":false}]}
{"op":"mcm","clk":"11449840344","pt":1717315185874,"mc":[{"id":"1.229554894","rc":[{"atb":[[1.42,0]],"id":70003367},{"atl":[[2.4,0],[2.46,10.27],[2.44,10.42]],"id":70003367},{"atl":[[2.5,10]],"id":70003365}],"con":true,"img":false}]}
{"op":"mcm","clk":"11449840379","pt":1717315186241,"mc":[{"id":"1.229554894","rc":[{"atl":[[2.42,0]],"id":70003367}],"con":true,"img":false}]}
{"op":"mcm","clk":"11449840954","pt":1717315192342,"mc":[{"id":"1.229554894","rc":[{"atb":[[1.46,32.61],[1.47,0]],"id":70003365},{"atl":[[2.52,9.87]],"id":70003365}],"con":true,"img":false}]}
{"op":"mcm","clk":"11449840963","pt":1717315192445,"mc":[{"id":"1.229554894","rc":[{"atl":[[2.5,0]],"id":70003365}],"con":true,"img":false}]}
{"op":"mcm","clk":"11449841280","pt":1717315195858,"mc":[{"id":"1.229554894","rc":[{"atb":[[1.39,51.28]],"id":70003367},{"atl":[[2.48,13.51]],"id":70003367}],"con":true,"img":false}]}
{"op":"mcm","clk":"11449841833","pt":1717315200975,"mc":[{"id":"1.229554894","rc":[{"atb":[[1.88,8.92],[1.78,10.06]],"id":70003367},{"atb":[[1.88,8.92],[1.78,10.06]],"id":70003365}],"con":true,"img":false}]}
{"op":"mcm","clk":"11449841996","pt":1717315202381,"mc":[{"id":"1.229554894","rc":[{"atl":[[2.56,12.82]],"id":70003365}],"con":true,"img":false}]}
{"op":"mcm","clk":"11449842392","pt":1717315205866,"mc":[{"id":"1.229554894","rc":[{"atl":[[2.52,16.45]],"id":70003367}],"con":true,"img":false}]}
{"op":"mcm","clk":"11449842903","pt":1717315210692,"mc":[{"id":"1.229554894","rc":[{"atb":[[1.46,0]],"id":70003365}],"con":true,"img":false}]}
{"op":"mcm","clk":"11449843101","pt":1717315212366,"mc":[{"id":"1.229554894","rc":[{"atl":[[2.38,10.87],[2.44,0]],"id":70003367},{"atl":[[2.5,10]],"id":70003365}],"con":true,"img":false}]}
{"op":"mcm","clk":"11449843231","pt":1717315213663,"mc":[{"id":"1.229554894","rc":[{"atl":[[2.5,0]],"id":70003365}],"con":true,"img":false}]}
{"op":"mcm","clk":"11449844134","pt":1717315222415,"mc":[{"id":"1.229554894","rc":[{"atl":[[2.6,15.62]],"id":70003365}],"con":true,"img":false}]}
{"op":"mcm","clk":"11449846516","pt":1717315247732,"mc":[{"id":"1.229554894","rc":[{"atb":[[1.88,0],[1.78,0]],"id":70003367},{"atb":[[1.88,0],[1.78,0]],"id":70003365}],"con":true,"img":false}]}
{"op":"mcm","clk":"11449846627","pt":1717315248306,"mc":[{"id":"1.229554894","rc":[{"atb":[[1.41,0],[1.45,33.33]],"id":70003367},{"atb":[[1.52,28.85]],"id":70003365}],"con":true,"img":false}]}
{"op":"mcm","clk":"11449846804","pt":1717315249917,"mc":[{"id":"1.229554894","rc":[{"atb":[[1.46,32.61],[1.45,0]],"id":70003367},{"atb":[[1.48,31.25],[1.52,0]],"id":70003365}],"con":true,"img":false}]}
{"op":"mcm","clk":"11449846934","pt":1717315251344,"mc":[{"id":"1.229554894","rc":[{"atb":[[1.46,0],[1.47,31.91]],"id":70003367},{"atl":[[2.4,10.71],[2.38,0]],"id":70003367},{"atl":[[2.52,0]],"id":70003365}],"con":true,"img":false}]}
{"op":"mcm","clk":"11449847217","pt":1717315254250,"mc":[{"id":"1.229554894","rc":[{"atb":[[1.46,32.61],[1.47,0]],"id":70003367}],"con":true,"img":false}]}
{"op":"mcm","clk":"11449847547","pt":1717315258119,"mc":[{"id":"1.229554894","rc":[{"atb":[[1.8,9.8],[1.9,8.72]],"id":70003367},{"atb":[[1.85,9.23],[1.75,10.46]],"id":70003365}],"con":true,"img":false}]}
{"op":"mcm","clk":"11449847717","pt":1717315259909,"mc":[{"id":"1.229554894","rc":[{"atl":[[2.58,12.66]],"id":70003365}],"con":true,"img":false}]}
{"op":"mcm","clk":"11449847821","pt":1717315261154,"mc":[{"id":"1.229554894","rc":[{"atb":[[1.6,2]],"id":70003367},{"atl":[[2.28,2]],"id":70003367},{"atb":[[1.86,2]],"id":70003365},{"atl":[[2.5,2]],"id":70003365}],"con":true,"img":false}]}
{"op":"mcm","clk":"11449848356","pt":1717315266243,"mc":[{"id":"1.229554894","rc":[{"atl":[[2.3,2],[2.28,0]],"id":70003367}],"con":true,"img":false}]}
{"op":"mcm","clk":"11449848375","pt":1717315266497,"mc":[{"id":"1.229554894","rc":[{"atl":[[2.4,0],[2.38,10.87]],"id":70003367},{"atl":[[2.54,0],[2.52,9.87]],"id":70003365}],"con":true,"img":false}]}
{"op":"mcm","clk":"11449848518","pt":1717315267956,"mc":[{"id":"1.229554894","rc":[{"atl":[[2.54,9.74]],"id":70003365}],"con":true,"img":false}]}
{"op":"mcm","clk":"11449848527","pt":1717315268054,"mc":[{"id":"1.229554894","rc":[{"atl":[[2.38,0],[2.34,11.19]],"id":70003367},{"atl":[[2.52,0]],"id":70003365}],"con":true,"img":false}]}
{"op":"mcm","clk":"11449849458","pt":1717315277969,"mc":[{"id":"1.229554894","rc":[{"atl":[[2.38,14.49]],"id":70003367}],"con":true,"img":false}]}
{"op":"mcm","clk":"11449849642","pt":1717315279676,"mc":[{"id":"1.229554894","rc":[{"atl":[[2.52,0],[2.48,0]],"id":70003367}],"con":true,"img":false}]}
{"op":"mcm","clk":"11449850451","pt":1717315287999,"mc":[{"id":"1.229554894","rc":[{"atl":[[2.42,17.61]],"id":70003367}],"con":true,"img":false}]}
{"op":"mcm","clk":"11449851183","pt":1717315295523,"mc":[{"id":"1.229554894","rc":[{"atb":[[1.8,0],[1.9,0]],"id":70003367},{"atb":[[1.85,0],[1.75,0]],"id":70003365}],"con":true,"img":false}]}
{"op":"mcm","clk":"11449851196","pt":1717315295583,"mc":[{"id":"1.229554894","rc":[{"atb":[[1.74,2]],"id":70003365}],"con":true,"img":false}]}
{"op":"mcm","clk":"11449851204","pt":1717315295685,"mc":[{"id":"1.229554894","rc":[{"atl":[[2.3,0],[2.28,2]],"id":70003367},{"atb":[[1.86,0]],"id":70003365}],"con":true,"img":false}]}
{"op":"mcm","clk":"11449851437","pt":1717315298000,"mc":[{"id":"1.229554894","rc":[{"atb":[[1.44,45.45]],"id":70003367}],"con":true,"img":false}]}
{"op":"mcm","clk":"11449851690","pt":1717315300715,"mc":[{"id":"1.229554894","rc":[{"atb":[[1.74,0],[1.76,2]],"id":70003365}],"con":true,"img":false}]}
{"op":"mcm","clk":"11449852174","pt":1717315305714,"mc":[{"id":"1.229554894","rc":[{"atb":[[1.46,43.48]],"id":70003365}],"con":true,"img":false}]}
{"op":"mcm","clk":"11449852379","pt":1717315307987,"mc":[{"id":"1.229554894","rc":[{"atb":[[1.37,0],[1.42,59.52]],"id":70003367}],"con":true,"img":false}]}
{"op":"mcm","clk":"11449853323","pt":1717315318016,"mc":[{"id":"1.229554894","rc":[{"atb":[[1.4,137.5]],"id":70003367}],"con":true,"img":false}]}
{"op":"mcm","clk":"11449853334","pt":1717315318117,"mc":[{"id":"1.229554894","rc":[{"atb":[[1.4,75],[1.39,0]],"id":70003367}],"con":true,"img":false}]}
{"op":"mcm","clk":"11449853636","pt":1717315320819,"mc":[{"id":"1.229554894","rc":[{"atl":[[2.36,2],[2.28,0]],"id":70003367},{"atb":[[1.71,2],[1.76,0]],"id":70003365}],"con":true,"img":false}]}
{"op":"mcm","clk":"11449854046","pt":1717315324750,"mc":[{"id":"1.229554894","rc":[{"atb":[[1.7,2],[1.71,0]],"id":70003365}],"con":true,"img":false}]}
{"op":"mcm","clk":"11449854444","pt":1717315328623,"mc":[{"id":"1.229554894","rc":[{"atl":[[2.38,16.49]],"id":70003367}],"con":true,"img":false}]}
{"op":"mcm","clk":"11449854454","pt":1717315328721,"mc":[{"id":"1.229554894","rc":[{"atl":[[2.36,0]],"id":70003367}],"con":true,"img":false}]}
{"op":"mcm","clk":"11449854561","pt":1717315329854,"mc":[{"id":"1.229554894","rc":[{"atb":[[1.66,2]],"id":70003365}],"con":true,"img":false}]}
{"op":"mcm","clk":"11449854569","pt":1717315329957,"mc":[{"id":"1.229554894","rc":[{"atb":[[1.7,0]],"id":70003365}],"con":true,"img":false}]}
{"op":"mcm","clk":"11449854719","pt":1717315331356,"mc":[{"id":"1.229554894","rc":[{"atb":[[1.83,9.45],[1.93,8.43]],"id":70003367},{"atb":[[1.81,9.68],[1.71,11.05]],"id":70003365}],"con":true,"img":false}]}
{"op":"mcm","clk":"11449854981","pt":1717315333728,"mc":[{"id":"1.229554894","rc":[{"atl":[[2.42,19.61]],"id":70003367}],"con":true,"img":false}]}
{"op":"mcm","clk":"11449854992","pt":1717315333833,"mc":[{"id":"1.229554894","rc":[{"atl":[[2.38,14.49]],"id":70003367}],"con":true,"img":false}]}
{"op":"mcm","clk":"11449855108","pt":1717315334961,"mc":[{"id":"1.229554894","rc":[{"atb":[[1.82,2]],"id":70003365}],"con":true,"img":false}]}
{"op":"mcm","clk":"11449855116","pt":1717315335063,"mc":[{"id":"1.229554894","rc":[{"atb":[[1.66,0]],"id":70003365}],"con":true,"img":false}]}
{"op":"mcm","clk":"11449858490","pt":1717315367587,"mc":[{"id":"1.229554894","rc":[{"atb":[[1.83,0],[1.93,0]],"id":70003367},{"atb":[[1.81,0],[1.71,0]],"id":70003365}],"con":true,"img":false}]}
{"op":"mcm","clk":"11449858498","pt":1717315367691,"mc":[{"id":"1.229554894","rc":[{"atl":[[2.38,16.49]],"id":70003367}],"con":true,"img":false}]}
{"op":"mcm","clk":"11449858509","pt":1717315367795,"mc":[{"id":"1.229554894","rc":[{"atl":[[2.42,17.61]],"id":70003367},{"atb":[[1.82,0],[1.69,2]],"id":70003365}],"con":true,"img":false}]}
{"op":"mcm","clk":"11449858890","pt":1717315371464,"mc":[{"id":"1.229554894","rc":[{"atb":[[1.46,0],[1.44,34.09]],"id":70003367},{"atb":[[1.46,32.61],[1.48,0]],"id":70003365}],"con":true,"img":false}]}
{"op":"mcm","clk":"11449859539","pt":1717315378477,"mc":[{"id":"1.229554894","rc":[{"atb":[[1.83,9.45],[1.93,8.43]],"id":70003367},{"atb":[[1.81,9.68],[1.71,11.05]],"id":70003365}],"con":true,"img":false}]}
{"op":"mcm","clk":"11449859549","pt":1717315378584,"mc":[{"id":"1.229554894","rc":[{"atl":[[2.42,19.61],[2.44,10.42]],"id":70003367},{"atb":[[1.82,2],[1.69,0]],"id":70003365},{"atl":[[2.5,12]],"id":70003365}],"con":true,"img":false}]}
{"op":"mcm","clk":"11449859560","pt":1717315378685,"mc":[{"id":"1.229554894","rc":[{"atl":[[2.38,14.49],[2.34,0]],"id":70003367},{"atl":[[2.54,0]],"id":70003365}],"con":true,"img":false}]}
{"op":"mcm","clk":"11449859825","pt":1717315381421,"mc":[{"id":"1.229554894","rc":[{"atl":[[2.38,0]],"id":70003367}],"con":true,"img":false}]}
{"op":"mcm","clk":"11449859875","pt":1717315381991,"mc":[{"id":"1.229554894","rc":[{"atb":[[1.44,0]],"id":70003367},{"atl":[[2.42,2]],"id":70003367}],"con":true,"img":false}]}
{"op":"mcm","clk":"11449860121","pt":1717315384527,"mc":[{"id":"1.229554894","rc":[{"atl":[[2.4,2]],"id":70003367}],"con":true,"img":false}]}
{"op":"mcm","clk":"11449860131","pt":1717315384600,"mc":[{"id":"1.229554894","rc":[{"atl":[[2.42,0]],"id":70003367}],"con":true,"img":false}]}
{"op":"mcm","clk":"11449860497","pt":1717315388611,"mc":[{"id":"1.229554894","rc":[{"atl":[[2.48,13.51]],"id":70003367}],"con":true,"img":false}]}
{"op":"mcm","clk":"11449861243","pt":1717315396332,"mc":[{"id":"1.229554894","rc":[{"atb":[[1.6,0]],"id":70003367},{"atl":[[2.4,0]],"id":70003367},{"atb":[[1.82,0]],"id":70003365},{"atl":[[2.5,10]],"id":70003365}],"con":true,"img":false}]}
{"op":"mcm","clk":"11449861487","pt":1717315398708,"mc":[{"id":"1.229554894","rc":[{"atl":[[2.52,16.45]],"id":70003367}],"con":true,"img":false}]}
{"op":"mcm","clk":"11449864595","pt":1717315429472,"mc":[{"id":"1.229554894","rc":[{"atl":[[2.44,0],[2.34,11.19]],"id":70003367},{"atl":[[2.54,9.74],[2.5,0]],"id":70003365}],"con":true,"img":false}]}
{"op":"mcm","clk":"11449865205","pt":1717315435206,"mc":[{"id":"1.229554894","rc":[{"atl":[[2.44,10.42],[2.34,0]],"id":70003367},{"atl":[[2.5,10]],"id":70003365}],"con":true,"img":false}]}
{"op":"mcm","clk":"11449865215","pt":1717315435310,"mc":[{"id":"1.229554894","rc":[{"atl":[[2.54,0]],"id":70003365}],"con":true,"img":false}]}
{"op":"mcm","clk":"11449865750","pt":1717315440286,"mc":[{"id":"1.229554894","rc":[{"atl":[[2.44,0],[2.34,11.19]],"id":70003367},{"atl":[[2.54,9.74],[2.5,0]],"id":70003365}],"con":true,"img":false}]}
{"op":"mcm","clk":"11449866674","pt":1717315448732,"mc":[{"id":"1.229554894","rc":[{"atl":[[2.44,10.42],[2.34,0]],"id":70003367},{"atl":[[2.54,0],[2.5,10]],"id":70003365}],"con":true,"img":false}]}
{"op":"mcm","clk":"11449867563","pt":1717315457150,"mc":[{"id":"1.229554894","rc":[{"atl":[[2.44,0],[2.34,11.19]],"id":70003367},{"atl":[[2.54,9.74],[2.5,0]],"id":70003365}],"con":true,"img":false}]}
{"op":"mcm","clk":"11449867665","pt":1717315458189,"mc":[{"id":"1.229554894","rc":[{"atl":[[2.44,10.42],[2.34,0]],"id":70003367},{"atl":[[2.54,0],[2.5,10]],"id":70003365}],"con":true,"img":false}]}
{"op":"mcm","clk":"11449868083","pt":1717315462365,"mc":[{"id":"1.229554894","rc":[{"atl":[[2.44,0],[2.34,11.19]],"id":70003367},{"atl":[[2.54,9.74],[2.5,0]],"id":70003365}],"con":true,"img":false}]}
{"op":"mcm","clk":"11449869172","pt":1717315472392,"mc":[{"id":"1.229554894","rc":[{"atl":[[2.38,14.49]],"id":70003367}],"con":true,"img":false}]}
{"op":"mcm","clk":"11449869937","pt":1717315478903,"mc":[{"id":"1.229554894","rc":[{"atb":[[1.6,2]],"id":70003367},{"atl":[[2.38,16.49],[2.52,0],[2.48,0]],"id":70003367},{"atb":[[1.82,2]],"id":70003365},{"atl":[[2.5,2]],"id":70003365}],"con":true,"img":false}]}
{"op":"mcm","clk":"11449869950","pt":1717315479016,"mc":[{"id":"1.229554894","rc":[{"atl":[[2.5,0],[2.52,2]],"id":70003365}],"con":true,"img":false}]}
{"op":"mcm","clk":"11449870323","pt":1717315482379,"mc":[{"id":"1.229554894","rc":[{"atl":[[2.42,17.61]],"id":70003367}],"con":true,"img":false}]}
{"op":"mcm","clk":"11449876890","pt":1717315546760,"mc":[{"id":"1.229554894","rc":[{"atl":[[2.36,11.03],[2.34,0]],"id":70003367}],"con":true,"img":false}]}
{"op":"mcm","clk":"11449878842","pt":1717315567800,"mc":[{"id":"1.229554894","rc":[{"atb":[[1.83,0],[1.93,0]],"id":70003367},{"atb":[[1.81,0],[1.71,0]],"id":70003365}],"con":true,"img":false}]}
{"op":"mcm","clk":"11449878851","pt":1717315567905,"mc":[{"id":"1.229554894","rc":[{"atl":[[2.36,0],[2.4,10.71],[2.38,10.87],[2.34,2]],"id":70003367},{"atb":[[1.82,0],[1.72,2]],"id":70003365},{"atl":[[2.54,0],[2.52,11.87]],"id":70003365}],"con":true,"img":false}]}
{"op":"mcm","clk":"11449879117","pt":1717315570613,"mc":[{"id":"1.229554894","rc":[{"atb":[[1.45,33.33]],"id":70003367},{"atl":[[2.38,0]],"id":70003367},{"atb":[[1.47,31.91]],"id":70003365},{"atl":[[2.54,9.74],[2.52,2]],"id":70003365}],"con":true,"img":false}]}
{"op":"mcm","clk":"11449879521","pt":1717315574445,"mc":[{"id":"1.229554894","rc":[{"atb":[[1.44,34.09]],"id":70003367},{"atl":[[2.4,0],[2.42,10.56]],"id":70003367},{"atb":[[1.45,33.33]],"id":70003365},{"atl":[[2.56,9.62],[2.54,0]],"id":70003365}],"con":true,"img":false}]}
{"op":"mcm","clk":"11449879534","pt":1717315574502,"mc":[{"id":"1.229554894","rc":[{"atb":[[1.45,0]],"id":70003367},{"atb":[[1.47,0]],"id":70003365}],"con":true,"img":false}]}
{"op":"mcm","clk":"11449879760","pt":1717315576934,"mc":[{"id":"1.229554894","rc":[{"atb":[[1.45,33.33]],"id":70003367},{"atl":[[2.4,10.71]],"id":70003367},{"atb":[[1.46,0],[1.47,31.91]],"id":70003365},{"atl":[[2.54,9.74]],"id":70003365}],"con":true,"img":false}]}
{"op":"mcm","clk":"11449879932","pt":1717315578502,"mc":[{"id":"1.229554894","rc":[{"atb":[[1.45,0]],"id":70003367},{"atl":[[2.4,0]],"id":70003367},{"atb":[[1.47,0]],"id":70003365},{"atl":[[2.54,0]],"id":70003365}],"con":true,"img":false}]}
{"op":"mcm","clk":"11449879954","pt":1717315578717,"mc":[{"id":"1.229554894","rc":[{"atb":[[1.45,33.33]],"id":70003367},{"atl":[[2.4,10.71]],"id":70003367},{"atb":[[1.47,31.91]],"id":70003365},{"atl":[[2.54,9.74]],"id":70003365}],"con":true,"img":false}]}
{"op":"mcm","clk":"11449880470","pt":1717315583536,"mc":[{"id":"1.229554894","rc":[{"atb":[[1.45,0]],"id":70003367},{"atb":[[1.47,0]],"id":70003365}],"con":true,"img":false}]}
{"op":"mcm","clk":"11449880481","pt":1717315583636,"mc":[{"id":"1.229554894","rc":[{"atl":[[2.4,0]],"id":70003367},{"atl":[[2.54,0]],"id":70003365}],"con":true,"img":false}]}
{"op":"mcm","clk":"11449880648","pt":1717315585344,"mc":[{"id":"1.229554894","rc":[{"atb":[[1.45,33.33]],"id":70003367},{"atl":[[2.4,10.71]],"id":70003367},{"atb":[[1.47,31.91]],"id":70003365},{"atl":[[2.54,9.74]],"id":70003365}],"con":true,"img":false}]}
{"op":"mcm","clk":"11449880710","pt":1717315585926,"mc":[{"id":"1.229554894","rc":[{"atb":[[1.45,0]],"id":70003367},{"atl":[[2.4,0]],"id":70003367},{"atb":[[1.47,0]],"id":70003365},{"atl":[[2.54,0]],"id":70003365}],"con":true,"img":false}]}
{"op":"mcm","clk":"11449880795","pt":1717315586697,"mc":[{"id":"1.229554894","rc":[{"atb":[[1.45,33.33]],"id":70003367},{"atl":[[2.4,10.71]],"id":70003367},{"atb":[[1.47,31.91]],"id":70003365},{"atl":[[2.54,9.74]],"id":70003365}],"con":true,"img":false}]}
{"op":"mcm","clk":"11449880945","pt":1717315588312,"mc":[{"id":"1.229554894","rc":[{"atb":[[1.45,0],[1.38,39.47]],"id":70003367},{"atb":[[1.4,37.5],[1.47,0]],"id":70003365}],"con":true,"img":false}]}
{"op":"mcm","clk":"11449881190","pt":1717315590550,"mc":[{"id":"1.229554894","rc":[{"atb":[[1.44,0]],"id":70003367},{"atb":[[1.45,0]],"id":70003365}],"con":true,"img":false}]}
{"op":"mcm","clk":"11449881242","pt":1717315591024,"mc":[{"id":"1.229554894","rc":[{"atb":[[1.42,0]],"id":70003367},{"atb":[[1.44,0]],"id":70003365}],"con":true,"img":false}]}
{"op":"mcm","clk":"11449881276","pt":1717315591343,"mc":[{"id":"1.229554894","rc":[{"atb":[[1.4,0]],"id":70003367},{"atl":[[2.4,12.71],[2.34,0]],"id":70003367},{"atb":[[1.72,0],[1.42,0],[1.69,2]],"id":70003365}],"con":true,"img":false}]}
{"op":"mcm","clk":"11449881361","pt":1717315592227,"mc":[{"id":"1.229554894","rc":[{"atl":[[2.4,2]],"id":70003367},{"atl":[[2.54,0]],"id":70003365}],"con":true,"img":false}]}
{"op":"mcm","clk":"11449881545","pt":1717315594040,"mc":[{"id":"1.229554894","rc":[{"atl":[[2.4,12.71]],"id":70003367},{"atl":[[2.54,9.74]],"id":70003365}],"con":true,"img":false}]}
{"op":"mcm","clk":"11449881692","pt":1717315595544,"mc":[{"id":"1.229554894","rc":[{"atl":[[2.4,2]],"id":70003367},{"atl":[[2.54,0]],"id":70003365}],"con":true,"img":false}]}
{"op":"mcm","clk":"11449881731","pt":1717315595955,"mc":[{"id":"1.229554894","rc":[{"atl":[[2.4,0],[2.38,2]],"id":70003367}],"con":true,"img":false}]}
{"op":"mcm","clk":"11449881758","pt":1717315596227,"mc":[{"id":"1.229554894","rc":[{"atl":[[2.4,2],[2.38,0]],"id":70003367},{"atb":[[1.68,2],[1.69,0]],"id":70003365}],"con":true,"img":false}]}
{"op":"mcm","clk":"11449881997","pt":1717315598967,"mc":[{"id":"1.229554894","rc":[{"atl":[[2.4,12.71]],"id":70003367},{"atl":[[2.54,9.74]],"id":70003365}],"con":true,"img":false}]}
{"op":"mcm","clk":"11449882004","pt":1717315599065,"mc":[{"id":"1.229554894","rc":[{"atb":[[1.6,0],[1.61,2]],"id":70003367},{"atl":[[2.5,2],[2.52,0]],"id":70003365}],"con":true,"img":false}]}
{"op":"mcm","clk":"11449882301","pt":1717315602030,"mc":[{"id":"1.229554894","rc":[{"atb":[[1.83,9.45],[1.93,8.43]],"id":70003367},{"atb":[[1.81,9.68],[1.71,11.05]],"id":70003365}],"con":true,"img":false}]}
{"op":"mcm","clk":"11449882321","pt":1717315602244,"mc":[{"id":"1.229554894","rc":[{"atb":[[1.82,2],[1.68,0]],"id":70003365}],"con":true,"img":false}]}
{"op":"mcm","clk":"11449882757","pt":1717315606348,"mc":[{"id":"1.229554894","rc":[{"atl":[[2.4,2],[2.44,10.42]],"id":70003367},{"atl":[[2.54,0],[2.58,9.49]],"id":70003365}],"con":true,"img":false}]}
{"op":"mcm","clk":"11449883123","pt":1717315609770,"mc":[{"id":"1.229554894","rc":[{"atl":[[2.4,12.71]],"id":70003367},{"atl":[[2.54,9.74],[2.6,25]],"id":70003365}],"con":true,"img":false}]}
{"op":"mcm","clk":"11449883133","pt":1717315609871,"mc":[{"id":"1.229554894","rc":[{"atl":[[2.56,0],[2.6,9.38]],"id":70003365}],"con":true,"img":false}]}
{"op":"mcm","clk":"11449883282","pt":1717315611077,"mc":[{"id":"1.229554894","rc":[{"atl":[[2.54,0]],"id":70003365}],"con":true,"img":false}]}
{"op":"mcm","clk":"11449883340","pt":1717315611545,"mc":[{"id":"1.229554894","rc":[{"atl":[[2.58,0]],"id":70003365}],"con":true,"img":false}]}
{"op":"mcm","clk":"11449884140","pt":1717315619763,"mc":[{"id":"1.229554894","rc":[{"atl":[[2.64,12.2]],"id":70003365}],"con":true,"img":false}]}
{"op":"mcm","clk":"11449885233","pt":1717315629759,"mc":[{"id":"1.229554894","rc":[{"atl":[[2.68,14.88]],"id":70003365}],"con":true,"img":false}]}
{"op":"mcm","clk":"11449885258","pt":1717315630064,"mc":[{"id":"1.229554894","rc":[{"atl":[[2.4,2]],"id":70003367},{"atl":[[2.62,9.26]],"id":70003365}],"con":true,"img":false}]}
{"op":"mcm","clk":"11449885265","pt":1717315630171,"mc":[{"id":"1.229554894","rc":[{"atl":[[2.6,0]],"id":70003365}],"con":true,"img":false}]}
{"op":"mcm","clk":"11449885402","pt":1717315631567,"mc":[{"id":"1.229554894","rc":[{"atl":[[2.4,12.71],[2.38,10.87]],"id":70003367},{"atb":[[1.4,0]],"id":70003365},{"atl":[[2.56,9.62],[2.6,9.38],[2.58,9.49]],"id":70003365}],"con":true,"img":false}]}
{"op":"mcm","clk":"11449885418","pt":1717315631773,"mc":[{"id":"1.229554894","rc":[{"atl":[[2.4,2],[2.42,0],[2.38,0],[2.46,0]],"id":70003367},{"atl":[[2.56,0],[2.6,0],[2.64,0],[2.68,0]],"id":70003365}],"con":true,"img":false}]}
{"op":"mcm","clk":"11449885431","pt":1717315631882,"mc":[{"id":"1.229554894","rc":[{"atl":[[2.44,0]],"id":70003367},{"atl":[[2.58,0],[2.62,0]],"id":70003365}],"con":true,"img":false}]}
{"op":"mcm","clk":"11449885439","pt":1717315631981,"mc":[{"id":"1.229554894","rc":[{"atl":[[2.54,19.48],[2.5,20],[2.42,14.08],[2.38,10.87],[2.46,17.12]],"id":70003367},{"atl":[[2.56,9.62],[2.6,9.38],[2.64,15.24],[2.66,15.06],[2.58,9.49],[2.62,12.35],[2.68,17.86],[2.7,17.65]],"id":70003365}],"con":true,"img":false}]}
{"op":"mcm","clk":"11449885449","pt":1717315632084,"mc":[{"id":"1.229554894","rc":[{"atl":[[2.4,0],[2.36,8.94],[19.5,5.41],[6,0]],"id":70003367},{"atl":[[2.56,0],[6.2,0],[21,5],[2.6,0],[2.64,0],[2.66,0],[2.58,0],[2.62,0],[2.68,0],[2.7,0]],"id":70003365}],"con":true,"img":false}]}
{"op":"mcm","clk":"11449885858","pt":1717315635873,"mc":[{"id":"1.229554894","rc":[{"atl":[[2.54,0],[2.42,10.56],[2.38,0]],"id":70003367},{"atl":[[2.56,9.62],[2.6,12.5],[2.64,15.24],[2.68,17.86]],"id":70003365}],"con":true,"img":false}]}
{"op":"mcm","clk":"11449885997","pt":1717315637173,"mc":[{"id":"1.229554894","rc":[{"atl":[[2.4,12.71],[2.42,0],[2.44,10.42]],"id":70003367},{"atl":[[2.56,0],[2.54,9.74]],"id":70003365}],"con":true,"img":false}]}
{"op":"mcm","clk":"11449886010","pt":1717315637275,"mc":[{"id":"1.229554894","rc":[{"atl":[[2.36,0]],"id":70003367}],"con":true,"img":false}]}
{"op":"mcm","clk":"11449886125","pt":1717315638369,"mc":[{"id":"1.229554894","rc":[{"atl":[[2.54,0],[2.52,9.87]],"id":70003365}],"con":true,"img":false}]}
{"op":"mcm","clk":"11449886409","pt":1717315641477,"mc":[{"id":"1.229554894","rc":[{"atl":[[19.5,0],[6,20]],"id":70003367},{"atl":[[21,0],[6.2,19.23]],"id":70003365}],"con":true,"img":false}]}
{"op":"mcm","clk":"11449886565","pt":1717315642919,"mc":[{"id":"1.229554894","rc":[{"atb":[[1.83,0],[1.93,0]],"id":70003367},{"atb":[[1.81,0],[1.71,0]],"id":70003365}],"con":true,"img":false}]}
{"op":"mcm","clk":"11449886576","pt":1717315643026,"mc":[{"id":"1.229554894","rc":[{"atl":[[2.4,0],[2.34,2]],"id":70003367},{"atl":[[2.56,9.62],[2.52,0]],"id":70003365}],"con":true,"img":false}]}
{"op":"mcm","clk":"11449886589","pt":1717315643084,"mc":[{"id":"1.229554894","rc":[{"atb":[[1.82,0],[1.72,2]],"id":70003365}],"con":true,"img":false}]}
{"op":"mcm","clk":"11449886613","pt":1717315643299,"mc":[{"id":"1.229554894","rc":[{"atb":[[1.4,37.5],[1.36,69.44],[1.34,88.24],[1.38,52.63]],"id":70003365}],"con":true,"img":false}]}
{"op":"mcm","clk":"11449886794","pt":1717315644973,"mc":[{"id":"1.229554894","rc":[{"atb":[[1.72,0],[1.71,2]],"id":70003365},{"atl":[[2.56,0],[2.58,9.49]],"id":70003365}],"con":true,"img":false}]}
{"op":"mcm","clk":"11449886884","pt":1717315645915,"mc":[{"id":"1.229554894","rc":[{"atb":[[1.4,37.5]],"id":70003367}],"con":true,"img":false}]}
{"op":"mcm","clk":"11449887117","pt":1717315648096,"mc":[{"id":"1.229554894","rc":[{"atl":[[2.36,2],[2.34,0]],"id":70003367}],"con":true,"img":false}]}
{"op":"mcm","clk":"11449887294","pt":1717315649705,"mc":[{"id":"1.229554894","rc":[{"atb":[[1.4,0]],"id":70003367},{"atl":[[2.4,10.71]],"id":70003367},{"atl":[[2.54,9.74],[2.58,0]],"id":70003365}],"con":true,"img":false}]}
{"op":"mcm","clk":"11449887312","pt":1717315649913,"mc":[{"id":"1.229554894","rc":[{"atl":[[2.4,0]],"id":70003367}],"con":true,"img":false}]}
{"op":"mcm","clk":"11449887387","pt":1717315650683,"mc":[{"id":"1.229554894","rc":[{"atl":[[2.54,0],[2.58,9.49]],"id":70003365}],"con":true,"img":false}]}
{"op":"mcm","clk":"11449887474","pt":1717315651719,"mc":[{"id":"1.229554894","rc":[{"atb":[[1.37,40.54],[1.38,0]],"id":70003367},{"atb":[[1.4,0],[1.43,34.88]],"id":70003365}],"con":true,"img":false}]}
{"op":"mcm","clk":"11449887502","pt":1717315651981,"mc":[{"id":"1.229554894","rc":[{"atb":[[1.4,37.5]],"id":70003365},{"atl":[[2.6,21.88]],"id":70003365}],"con":true,"img":false}]}
{"op":"mcm","clk":"11449887510","pt":1717315652132,"mc":[{"id":"1.229554894","rc":[{"atb":[[1.38,39.47]],"id":70003367},{"atl":[[2.4,10.71]],"id":70003367},{"atb":[[1.43,0]],"id":70003365},{"atl":[[2.6,9.38],[2.58,0]],"id":70003365}],"con":true,"img":false}]}
{"op":"mcm","clk":"11449887629","pt":1717315653325,"mc":[{"id":"1.229554894","rc":[{"atb":[[1.38,0]],"id":70003367},{"atl":[[2.4,0]],"id":70003367},{"atb":[[1.4,0],[1.43,34.88]],"id":70003365},{"atl":[[2.58,9.49]],"id":70003365}],"con":true,"img":false}]}
{"op":"mcm","clk":"11449887670","pt":1717315653686,"mc":[{"id":"1.229554894","rc":[{"atl":[[2.4,10.71]],"id":70003367},{"atl":[[2.58,0]],"id":70003365}],"con":true,"img":false}]}
{"op":"mcm","clk":"11449887881","pt":1717315655703,"mc":[{"id":"1.229554894","rc":[{"atl":[[2.58,9.49]],"id":70003365}],"con":true,"img":false}]}
{"op":"mcm","clk":"11449888014","pt":1717315657106,"mc":[{"id":"1.229554894","rc":[{"atb":[[1.39,38.46]],"id":70003367},{"atl":[[2.4,0],[2.42,10.56],[2.38,10.87]],"id":70003367},{"atl":[[2.56,9.62],[2.58,0]],"id":70003365}],"con":true,"img":false}]}
{"op":"mcm","clk":"11449888026","pt":1717315657205,"mc":[{"id":"1.229554894","rc":[{"atb":[[1.6,2],[1.61,0]],"id":70003367}],"con":true,"img":false}]}
{"op":"mcm","clk":"11449888044","pt":1717315657413,"mc":[{"id":"1.229554894","rc":[{"atl":[[2.38,0],[2.44,0]],"id":70003367}],"con":true,"img":false}]}
{"op":"mcm","clk":"11449888243","pt":1717315659419,"mc":[{"id":"1.229554894","rc":[{"atb":[[1.39,0]],"id":70003367},{"atl":[[2.4,10.71],[2.42,0],[2.44,10.42]],"id":70003367},{"atl":[[2.56,0],[2.58,9.49]],"id":70003365}],"con":true,"img":false}]}
{"op":"mcm","clk":"11449888300","pt":1717315659896,"mc":[{"id":"1.229554894","rc":[{"atb":[[1.39,38.46]],"id":70003367},{"atl":[[2.4,0],[2.42,10.56]],"id":70003367},{"atl":[[2.56,9.62],[2.58,0]],"id":70003365}],"con":true,"img":false}]}
{"op":"mcm","clk":"11449888531","pt":1717315662342,"mc":[{"id":"1.229554894","rc":[{"atb":[[1.83,9.45],[1.93,8.43]],"id":70003367},{"atb":[[1.81,9.68],[1.71,13.05]],"id":70003365}],"con":true,"img":false}]}
{"op":"mcm","clk":"11449888541","pt":1717315662441,"mc":[{"id":"1.229554894","rc":[{"atb":[[1.6,0],[1.61,2]],"id":70003367},{"atl":[[2.36,0],[2.42,12.56]],"id":70003367},{"atb":[[1.67,2],[1.71,11.05]],"id":70003365}],"con":true,"img":false}]}
{"op":"mcm","clk":"11449888549","pt":1717315662503,"mc":[{"id":"1.229554894","rc":[{"atb":[[1.82,2],[1.67,0]],"id":70003365}],"con":true,"img":false}]}
{"op":"mcm","clk":"11449888914","pt":1717315666425,"mc":[{"id":"1.229554894","rc":[{"atb":[[1.39,0]],"id":70003367}],"con":true,"img":false}]}
{"op":"mcm","clk":"11449889562","pt":1717315673207,"mc":[{"id":"1.229554894","rc":[{"atl":[[2.56,0],[2.54,9.74],[2.52,9.87]],"id":70003365}],"con":true,"img":false}]}
{"op":"mcm","clk":"11449889572","pt":1717315673317,"mc":[{"id":"1.229554894","rc":[{"atl":[[2.4,10.71],[2.42,2]],"id":70003367}],"con":true,"img":false}]}
{"op":"mcm","clk":"11449889579","pt":1717315673419,"mc":[{"id":"1.229554894","rc":[{"atl":[[2.38,4.22]],"id":70003367}],"con":true,"img":false}]}
{"op":"mcm","clk":"11449889590","pt":1717315673518,"mc":[{"id":"1.229554894","rc":[{"atl":[[2.42,0]],"id":70003367}],"con":true,"img":false}]}
{"op":"mcm","clk":"11449889598","pt":1717315673616,"mc":[{"id":"1.229554894","rc":[{"atl":[[2.42,2]],"id":70003367}],"con":true,"img":false}]}
{"op":"mcm","clk":"11449889609","pt":1717315673723,"mc":[{"id":"1.229554894","rc":[{"atl":[[2.38,0]],"id":70003367}],"con":true,"img":false}]}
{"op":"mcm","clk":"11449889731","pt":1717315674958,"mc":[{"id":"1.229554894","rc":[{"atl":[[2.54,0],[2.68,0]],"id":70003365}],"con":true,"img":false}]}
{"op":"mcm","clk":"11449890351","pt":1717315681063,"mc":[{"id":"1.229554894","rc":[{"atl":[[2.48,2]],"id":70003365}],"con":true,"img":false}]}
{"op":"mcm","clk":"11449890360","pt":1717315681116,"mc":[{"id":"1.229554894","rc":[{"atl":[[2.5,0]],"id":70003365}],"con":true,"img":false}]}
{"op":"mcm","clk":"11449890610","pt":1717315683243,"mc":[{"id":"1.229554894","rc":[{"atl":[[2.56,12.82]],"id":70003365}],"con":true,"img":false}]}
{"op":"mcm","clk":"11449890729","pt":1717315684341,"mc":[{"id":"1.229554894","rc":[{"atl":[[2.5,2],[2.48,0]],"id":70003365}],"con":true,"img":false}]}
{"op":"mcm","clk":"11449891185","pt":1717315688747,"mc":[{"id":"1.229554894","rc":[{"atl":[[2.4,0],[2.42,12.56]],"id":70003367},{"atl":[[2.56,9.62],[2.52,0]],"id":70003365}],"con":true,"img":false}]}
{"op":"mcm","clk":"11449891215","pt":1717315689056,"mc":[{"id":"1.229554894","rc":[{"atl":[[2.4,10.71],[2.42,2]],"id":70003367},{"atl":[[2.52,9.87]],"id":70003365}],"con":true,"img":false}]}
{"op":"mcm","clk":"11449891238","pt":1717315689262,"mc":[{"id":"1.229554894","rc":[{"atl":[[2.42,0],[2.38,4.22]],"id":70003367}],"con":true,"img":false}]}
{"op":"mcm","clk":"11449891249","pt":1717315689360,"mc":[{"id":"1.229554894","rc":[{"atl":[[2.42,2],[2.38,0]],"id":70003367}],"con":true,"img":false}]}
{"op":"mcm","clk":"11449891278","pt":1717315689626,"mc":[{"id":"1.229554894","rc":[{"atl":[[2.4,0],[2.42,12.56]],"id":70003367},{"atl":[[2.52,0]],"id":70003365}],"con":true,"img":false}]}
{"op":"mcm","clk":"11449891603","pt":1717315693064,"mc":[{"id":"1.229554894","rc":[{"atl":[[2.4,10.71]],"id":70003367}],"con":true,"img":false}]}
{"op":"mcm","clk":"11449891612","pt":1717315693146,"mc":[{"id":"1.229554894","rc":[{"atl":[[2.42,2]],"id":70003367},{"atl":[[2.52,9.87]],"id":70003365}],"con":true,"img":false}]}
{"op":"mcm","clk":"11449891807","pt":1717315694746,"mc":[{"id":"1.229554894","rc":[{"atl":[[2.5,0],[2.48,2]],"id":70003365}],"con":true,"img":false}]}
{"op":"mcm","clk":"11449892005","pt":1717315696669,"mc":[{"id":"1.229554894","rc":[{"atl":[[2.42,12.56]],"id":70003367}],"con":true,"img":false}]}
{"op":"mcm","clk":"11449892020","pt":1717315696778,"mc":[{"id":"1.229554894","rc":[{"atl":[[2.4,0]],"id":70003367},{"atl":[[2.52,0]],"id":70003365}],"con":true,"img":false}]}
{"op":"mcm","clk":"11449892130","pt":1717315697866,"mc":[{"id":"1.229554894","rc":[{"atl":[[2.4,10.71],[2.42,2]],"id":70003367},{"atl":[[2.52,9.87]],"id":70003365}],"con":true,"img":false}]}
{"op":"mcm","clk":"11449892839","pt":1717315704353,"mc":[{"id":"1.229554894","rc":[{"atl":[[2.4,0],[2.42,12.56]],"id":70003367},{"atl":[[2.52,0]],"id":70003365}],"con":true,"img":false}]}
{"op":"mcm","clk":"11449892970","pt":1717315705699,"mc":[{"id":"1.229554894","rc":[{"atl":[[2.4,10.71],[2.42,2]],"id":70003367},{"atl":[[2.52,9.87]],"id":70003365}],"con":true,"img":false}]}
{"op":"mcm","clk":"11449893549","pt":1717315711780,"mc":[{"id":"1.229554894","rc":[{"atl":[[2.4,0],[2.42,12.56]],"id":70003367},{"atl":[[2.52,0],[2.62,9.26]],"id":70003365}],"con":true,"img":false}]}
{"op":"mcm","clk":"11449893588","pt":1717315712098,"mc":[{"id":"1.229554894","rc":[{"atb":[[1.83,0],[1.93,0]],"id":70003367},{"atb":[[1.81,0],[1.71,0]],"id":70003365}],"con":true,"img":false}]}
{"op":"mcm","clk":"11449893599","pt":1717315712196,"mc":[{"id":"1.229554894","rc":[{"atl":[[2.36,2],[2.4,10.71],[2.42,0]],"id":70003367},{"atl":[[2.56,0],[2.58,9.49]],"id":70003365}],"con":true,"img":false}]}
{"op":"mcm","clk":"11449893610","pt":1717315712303,"mc":[{"id":"1.229554894","rc":[{"atb":[[1.82,0],[1.7,2]],"id":70003365}],"con":true,"img":false}]}
{"op":"mcm","clk":"11449894190","pt":1717315717676,"mc":[{"id":"1.229554894","rc":[{"atb":[[1.38,39.47]],"id":70003367},{"atb":[[1.46,32.61],[1.43,0],[1.45,33.33]],"id":70003365},{"atl":[[2.56,9.62],[2.58,0]],"id":70003365}],"con":true,"img":false}]}
{"op":"mcm","clk":"11449894254","pt":1717315718248,"mc":[{"id":"1.229554894","rc":[{"atb":[[1.38,0]],"id":70003367},{"atl":[[2.36,0],[2.38,2]],"id":70003367},{"atb":[[1.46,0],[1.7,0],[1.69,2]],"id":70003365}],"con":true,"img":false}]}
{"op":"mcm","clk":"11449894355","pt":1717315719045,"mc":[{"id":"1.229554894","rc":[{"atl":[[2.56,0]],"id":70003365}],"con":true,"img":false}]}
{"op":"mcm","clk":"11449894592","pt":1717315720965,"mc":[{"id":"1.229554894","rc":[{"atl":[[2.56,9.62]],"id":70003365}],"con":true,"img":false}]}
{"op":"mcm","clk":"11449894776","pt":1717315722441,"mc":[{"id":"1.229554894","rc":[{"atl":[[2.5,2],[2.48,0]],"id":70003365}],"con":true,"img":false}]}
{"op":"mcm","clk":"11449894887","pt":1717315723326,"mc":[{"id":"1.229554894","rc":[{"atl":[[2.36,2],[2.38,0]],"id":70003367},{"atb":[[1.7,2],[1.69,0]],"id":70003365},{"atl":[[2.56,0]],"id":70003365}],"con":true,"img":false}]}
{"op":"mcm","clk":"11449895129","pt":1717315725560,"mc":[{"id":"1.229554894","rc":[{"atl":[[2.56,9.62]],"id":70003365}],"con":true,"img":false}]}
{"op":"mcm","clk":"11449895207","pt":1717315726335,"mc":[{"id":"1.229554894","rc":[{"atb":[[1.42,35.71]],"id":70003367},{"atl":[[2.56,0]],"id":70003365}],"con":true,"img":false}]}
{"op":"mcm","clk":"11449895343","pt":1717315727635,"mc":[{"id":"1.229554894","rc":[{"atl":[[2.5,0],[2.48,2]],"id":70003365}],"con":true,"img":false}]}
{"op":"mcm","clk":"11449895513","pt":1717315729359,"mc":[{"id":"1.229554894","rc":[{"atl":[[2.42,10.56]],"id":70003367},{"atl":[[2.54,9.74]],"id":70003365}],"con":true,"img":false}]}
{"op":"mcm","clk":"11449895523","pt":1717315729460,"mc":[{"id":"1.229554894","rc":[{"atl":[[2.4,0]],"id":70003367}],"con":true,"img":false}]}
{"op":"mcm","clk":"11449895584","pt":1717315730030,"mc":[{"id":"1.229554894","rc":[{"atb":[[1.41,36.59],[1.42,0]],"id":70003367},{"atb":[[1.44,34.09],[1.45,0]],"id":70003365}],"con":true,"img":false}]}
{"op":"mcm","clk":"11449895859","pt":1717315732874,"mc":[{"id":"1.229554894","rc":[{"atb":[[1.42,35.71]],"id":70003367},{"atl":[[2.42,0],[2.46,10.27]],"id":70003367},{"atb":[[1.44,0],[1.45,33.33]],"id":70003365},{"atl":[[2.54,0],[2.58,9.49]],"id":70003365}],"con":true,"img":false}]}
{"op":"mcm","clk":"11449895928","pt":1717315733450,"mc":[{"id":"1.229554894","rc":[{"atb":[[1.42,0]],"id":70003367},{"atl":[[2.42,10.56]],"id":70003367},{"atb":[[1.44,34.09],[1.45,0]],"id":70003365},{"atl":[[2.54,9.74],[2.58,0]],"id":70003365}],"con":true,"img":false}]}
{"op":"mcm","clk":"11449896078","pt":1717315734854,"mc":[{"id":"1.229554894","rc":[{"atb":[[1.42,35.71]],"id":70003367},{"atl":[[2.42,0]],"id":70003367},{"atb":[[1.44,0],[1.45,33.33]],"id":70003365},{"atl":[[2.54,0],[2.58,9.49]],"id":70003365}],"con":true,"img":false}]}
{"op":"mcm","clk":"11449896633","pt":1717315740688,"mc":[{"id":"1.229554894","rc":[{"atl":[[2.42,10.56]],"id":70003367},{"atl":[[2.54,9.74],[2.58,0]],"id":70003365}],"con":true,"img":false}]}
{"op":"mcm","clk":"11449896641","pt":1717315740743,"mc":[{"id":"1.229554894","rc":[{"atl":[[2.36,0],[2.3,2]],"id":70003367},{"atb":[[1.74,2]],"id":70003365},{"atl":[[2.48,12.14]],"id":70003365}],"con":true,"img":false}]}
{"op":"mcm","clk":"11449896651","pt":1717315740850,"mc":[{"id":"1.229554894","rc":[{"atb":[[1.42,0]],"id":70003367},{"atb":[[1.44,34.09],[1.45,0],[1.7,0]],"id":70003365},{"atl":[[2.54,0]],"id":70003365}],"con":true,"img":false}]}
{"op":"mcm","clk":"11449896691","pt":1717315741272,"mc":[{"id":"1.229554894","rc":[{"atl":[[2.42,0]],"id":70003367},{"atl":[[2.52,9.87],[2.48,2]],"id":70003365}],"con":true,"img":false}]}
{"op":"mcm","clk":"11449896785","pt":1717315742044,"mc":[{"id":"1.229554894","rc":[{"atl":[[2.44,0]],"id":70003367},{"atl":[[2.5,2],[2.48,0]],"id":70003365}],"con":true,"img":false}]}
{"op":"mcm","clk":"11449896810","pt":1717315742252,"mc":[{"id":"1.229554894","rc":[{"atb":[[1.42,35.71]],"id":70003367},{"atb":[[1.45,33.33]],"id":70003365}],"con":true,"img":false}]}
{"op":"mcm","clk":"11449896822","pt":1717315742409,"mc":[{"id":"1.229554894","rc":[{"atb":[[1.44,0]],"id":70003365}],"con":true,"img":false}]}
{"op":"mcm","clk":"11449896911","pt":1717315743088,"mc":[{"id":"1.229554894","rc":[{"atl":[[2.42,10.56]],"id":70003367},{"atl":[[2.52,0],[2.48,10.14]],"id":70003365}],"con":true,"img":false}]}
{"op":"mcm","clk":"11449896925","pt":1717315743190,"mc":[{"id":"1.229554894","rc":[{"atl":[[2.5,0],[2.48,12.14]],"id":70003365}],"con":true,"img":false}]}
{"op":"mcm","clk":"11449896937","pt":1717315743247,"mc":[{"id":"1.229554894","rc":[{"atl":[[2.5,2],[2.48,10.14]],"id":70003365}],"con":true,"img":false}]}
{"op":"mcm","clk":"11449897006","pt":1717315743774,"mc":[{"id":"1.229554894","rc":[{"atl":[[2.5,0],[2.48,12.14]],"id":70003365}],"con":true,"img":false}]}
{"op":"mcm","clk":"11449897194","pt":1717315745279,"mc":[{"id":"1.229554894","rc":[{"atb":[[1.42,0]],"id":70003367},{"atb":[[1.44,34.09],[1.45,0]],"id":70003365}],"con":true,"img":false}]}
{"op":"mcm","clk":"11449897226","pt":1717315745690,"mc":[{"id":"1.229554894","rc":[{"atb":[[1.42,35.71]],"id":70003367},{"atl":[[2.42,0]],"id":70003367},{"atb":[[1.44,0],[1.45,33.33]],"id":70003365},{"atl":[[2.52,9.87],[2.48,2]],"id":70003365}],"con":true,"img":false}]}
{"op":"mcm","clk":"11449897275","pt":1717315746058,"mc":[{"id":"1.229554894","rc":[{"atl":[[2.3,0],[2.42,10.56],[2.28,2]],"id":70003367},{"atb":[[1.74,0],[1.76,2]],"id":70003365},{"atl":[[2.52,0],[2.48,12.14]],"id":70003365}],"con":true,"img":false}]}
{"op":"mcm","clk":"11449897535","pt":1717315748592,"mc":[{"id":"1.229554894","rc":[{"atb":[[1.42,0]],"id":70003367},{"atb":[[1.44,34.09],[1.45,0]],"id":70003365}],"con":true,"img":false}]}
{"op":"mcm","clk":"11449897570","pt":1717315748901,"mc":[{"id":"1.229554894","rc":[{"atl":[[2.5,2],[2.48,10.14]],"id":70003365}],"con":true,"img":false}]}
{"op":"mcm","clk":"11449897616","pt":1717315749377,"mc":[{"id":"1.229554894","rc":[{"atl":[[2.52,9.87]],"id":70003365}],"con":true,"img":false}]}
{"op":"mcm","clk":"11449897625","pt":1717315749478,"mc":[{"id":"1.229554894","rc":[{"atl":[[2.42,0]],"id":70003367},{"atl":[[2.48,0]],"id":70003365}],"con":true,"img":false}]}
{"op":"mcm","clk":"11449898095","pt":1717315753812,"mc":[{"id":"1.229554894","rc":[{"atb":[[1.84,9.34],[1.74,10.6]],"id":70003367},{"atb":[[1.81,9.68],[1.91,8.62]],"id":70003365}],"con":true,"img":false}]}
{"op":"mcm","clk":"11449898120","pt":1717315753976,"mc":[{"id":"1.229554894","rc":[{"atb":[[1.88,2],[1.76,0]],"id":70003365}],"con":true,"img":false}]}
{"op":"mcm","clk":"11449898229","pt":1717315755065,"mc":[{"id":"1.229554894","rc":[{"atl":[[2.5,0],[2.52,11.87]],"id":70003365}],"con":true,"img":false}]}
{"op":"mcm","clk":"11449898343","pt":1717315756106,"mc":[{"id":"1.229554894","rc":[{"atl":[[2.5,13.33]],"id":70003367}],"con":true,"img":false}]}
{"op":"mcm","clk":"11449898488","pt":1717315757409,"mc":[{"id":"1.229554894","rc":[{"atl":[[2.5,2],[2.52,9.87]],"id":70003365}],"con":true,"img":false}]}
{"op":"mcm","clk":"11449898751","pt":1717315760005,"mc":[{"id":"1.229554894","rc":[{"atl":[[2.5,0],[2.52,11.87]],"id":70003365}],"con":true,"img":false}]}
{"op":"mcm","clk":"11449899370","pt":1717315766123,"mc":[{"id":"1.229554894","rc":[{"atl":[[2.54,16.23]],"id":70003367}],"con":true,"img":false}]}
{"op":"mcm","clk":"11449899676","pt":1717315768933,"mc":[{"id":"1.229554894","rc":[{"atl":[[2.5,2],[2.52,9.87]],"id":70003365}],"con":true,"img":false}]}
{"op":"mcm","clk":"11449900439","pt":1717315776108,"mc":[{"id":"1.229554894","rc":[{"atl":[[2.58,18.99]],"id":70003367}],"con":true,"img":false}]}
{"op":"mcm","clk":"11449900602","pt":1717315777830,"mc":[{"id":"1.229554894","rc":[{"atb":[[1.61,0]],"id":70003367},{"atl":[[2.28,0]],"id":70003367},{"atb":[[1.88,0]],"id":70003365},{"atl":[[2.5,0]],"id":70003365}],"con":true,"img":false}]}
{"op":"mcm","clk":"11449903249","pt":1717315803868,"mc":[{"id":"1.229554894","rc":[{"atb":[[1.84,0],[1.74,0]],"id":70003367},{"atb":[[1.81,0],[1.91,0]],"id":70003365}],"con":true,"img":false}]}
{"op":"mcm","clk":"11449903888","pt":1717315809963,"mc":[{"id":"1.229554894","rc":[{"atb":[[1.39,51.28]],"id":70003367},{"atb":[[1.42,47.62]],"id":70003365}],"con":true,"img":false}]}
{"op":"mcm","clk":"11449904401","pt":1717315815061,"mc":[{"id":"1.229554894","rc":[{"atb":[[1.34,0]],"id":70003365}],"con":true,"img":false}]}
{"op":"mcm","clk":"11449904883","pt":1717315819990,"mc":[{"id":"1.229554894","rc":[{"atb":[[1.37,67.57]],"id":70003367},{"atb":[[1.4,62.5]],"id":70003365}],"con":true,"img":false}]}
{"op":"mcm","clk":"11449905016","pt":1717315821444,"mc":[{"id":"1.229554894","rc":[{"atb":[[1.36,0]],"id":70003365}],"con":true,"img":false}]}
{"op":"mcm","clk":"11449905058","pt":1717315821868,"mc":[{"id":"1.229554894","rc":[{"atb":[[1.88,8.92],[1.78,10.06]],"id":70003367},{"atb":[[1.88,8.92],[1.78,10.06]],"id":70003365}],"con":true,"img":false}]}
{"op":"mcm","clk":"11449905805","pt":1717315829171,"mc":[{"id":"1.229554894","rc":[{"atl":[[2.42,10.56],[2.46,0]],"id":70003367},{"atl":[[2.52,0],[2.48,10.14]],"id":70003365}],"con":true,"img":false}]}
{"op":"mcm","clk":"11449906826","pt":1717315839116,"mc":[{"id":"1.229554894","rc":[{"atl":[[2.46,13.7]],"id":70003367},{"atl":[[2.52,13.16]],"id":70003365}],"con":true,"img":false}]}
{"op":"mcm","clk":"11449907371","pt":1717315844495,"mc":[{"id":"1.229554894","rc":[{"atl":[[2.58,0]],"id":70003367},{"atl":[[2.64,0],[2.62,0]],"id":70003365}],"con":true,"img":false}]}
{"op":"mcm","clk":"11449907867","pt":1717315849108,"mc":[{"id":"1.229554894","rc":[{"atl":[[2.56,16.03]],"id":70003365}],"con":true,"img":false}]}
{"op":"mcm","clk":"11449910107","pt":1717315870234,"mc":[{"id":"1.229554894","rc":[{"atb":[[1.88,0],[1.78,0]],"id":70003367},{"atb":[[1.88,0],[1.78,0]],"id":70003365}],"con":true,"img":false}]}
{"op":"mcm","clk":"11449910709","pt":1717315875556,"mc":[{"id":"1.229554894","rc":[{"atb":[[1.35,85.71]],"id":70003367}],"con":true,"img":false}]}
{"op":"mcm","clk":"11449910795","pt":1717315876339,"mc":[{"id":"1.229554894","rc":[{"atb":[[1.41,0],[1.38,39.47]],"id":70003367},{"atb":[[1.46,32.61],[1.44,0]],"id":70003365}],"con":true,"img":false}]}
{"op":"mcm","clk":"11449910816","pt":1717315876542,"mc":[{"id":"1.229554894","rc":[{"atb":[[1.39,0]],"id":70003367}],"con":true,"img":false}]}
{"op":"mcm","clk":"11449911302","pt":1717315881158,"mc":[{"id":"1.229554894","rc":[{"atb":[[1.37,40.54],[1.38,0]],"id":70003367},{"atb":[[1.46,0],[1.45,33.33]],"id":70003365},{"atl":[[2.48,0]],"id":70003365}],"con":true,"img":false}]}
{"op":"mcm","clk":"11449911315","pt":1717315881258,"mc":[{"id":"1.229554894","rc":[{"atl":[[2.42,0],[2.44,10.42]],"id":70003367},{"atl":[[2.5,10]],"id":70003365}],"con":true,"img":false}]}
{"op":"mcm","clk":"11449911347","pt":1717315881562,"mc":[{"id":"1.229554894","rc":[{"atl":[[2.46,10.27],[2.44,0]],"id":70003367},{"atl":[[2.5,0],[2.52,9.87]],"id":70003365}],"con":true,"img":false}]}
{"op":"mcm","clk":"11449911364","pt":1717315881720,"mc":[{"id":"1.229554894","rc":[{"atl":[[2.44,10.42]],"id":70003367},{"atl":[[2.5,10]],"id":70003365}],"con":true,"img":false}]}
{"op":"mcm","clk":"11449911394","pt":1717315882083,"mc":[{"id":"1.229554894","rc":[{"atl":[[2.44,0]],"id":70003367},{"atl":[[2.5,0]],"id":70003365}],"con":true,"img":false}]}
{"op":"mcm","clk":"11449911448","pt":1717315882452,"mc":[{"id":"1.229554894","rc":[{"atb":[[1.38,39.47]],"id":70003367},{"atb":[[1.46,32.61],[1.45,0]],"id":70003365}],"con":true,"img":false}]}
{"op":"mcm","clk":"11449911487","pt":1717315882863,"mc":[{"id":"1.229554894","rc":[{"atl":[[2.42,10.56]],"id":70003367},{"atb":[[1.45,33.33]],"id":70003365},{"atl":[[2.48,10.14]],"id":70003365}],"con":true,"img":false}]}
{"op":"mcm","clk":"11449911497","pt":1717315882966,"mc":[{"id":"1.229554894","rc":[{"atb":[[1.38,0]],"id":70003367},{"atb":[[1.46,0]],"id":70003365}],"con":true,"img":false}]}
{"op":"mcm","clk":"11449911541","pt":1717315883240,"mc":[{"id":"1.229554894","rc":[{"atb":[[1.38,39.47]],"id":70003367},{"atl":[[2.42,0]],"id":70003367},{"atb":[[1.46,32.61],[1.45,0]],"id":70003365},{"atl":[[2.48,0]],"id":70003365}],"con":true,"img":false}]}
{"op":"mcm","clk":"11449911580","pt":1717315883565,"mc":[{"id":"1.229554894","rc":[{"atl":[[2.42,10.56]],"id":70003367},{"atl":[[2.48,10.14]],"id":70003365}],"con":true,"img":false}]}
{"op":"mcm","clk":"11449911963","pt":1717315887162,"mc":[{"id":"1.229554894","rc":[{"atb":[[1.38,0]],"id":70003367},{"atb":[[1.46,0],[1.45,33.33]],"id":70003365}],"con":true,"img":false}]}
{"op":"mcm","clk":"11449912023","pt":1717315887830,"mc":[{"id":"1.229554894","rc":[{"atb":[[1.46,32.61],[1.45,0]],"id":70003365},{"atl":[[2.48,0]],"id":70003365}],"con":true,"img":false}]}
{"op":"mcm","clk":"11449912033","pt":1717315887938,"mc":[{"id":"1.229554894","rc":[{"atb":[[1.38,39.47]],"id":70003367},{"atl":[[2.42,0]],"id":70003367}],"con":true,"img":false}]}
{"op":"mcm","clk":"11449912064","pt":1717315888250,"mc":[{"id":"1.229554894","rc":[{"atl":[[2.42,10.56]],"id":70003367},{"atb":[[1.46,0],[1.45,33.33]],"id":70003365},{"atl":[[2.48,10.14]],"id":70003365}],"con":true,"img":false}]}
{"op":"mcm","clk":"11449912076","pt":1717315888352,"mc":[{"id":"1.229554894","rc":[{"atb":[[1.38,0]],"id":70003367}],"con":true,"img":false}]}
{"op":"mcm","clk":"11449912223","pt":1717315889666,"mc":[{"id":"1.229554894","rc":[{"atl":[[2.42,0]],"id":70003367},{"atl":[[2.48,0]],"id":70003365}],"con":true,"img":false}]}
{"op":"mcm","clk":"11449912412","pt":1717315891457,"mc":[{"id":"1.229554894","rc":[{"atl":[[2.44,10.42]],"id":70003367},{"atl":[[2.5,10]],"id":70003365}],"con":true,"img":false}]}
{"op":"mcm","clk":"11449912471","pt":1717315892076,"mc":[{"id":"1.229554894","rc":[{"atb":[[1.61,2]],"id":70003367},{"atl":[[2.38,2]],"id":70003367},{"atb":[[1.69,2]],"id":70003365},{"atl":[[2.48,2]],"id":70003365}],"con":true,"img":false}]}
{"op":"mcm","clk":"11449912691","pt":1717315894047,"mc":[{"id":"1.229554894","rc":[{"atl":[[2.44,0]],"id":70003367},{"atl":[[2.5,0]],"id":70003365}],"con":true,"img":false}]}
{"op":"mcm","clk":"11449912990","pt":1717315896660,"mc":[{"id":"1.229554894","rc":[{"atl":[[2.44,10.42]],"id":70003367},{"atl":[[2.5,10]],"id":70003365}],"con":true,"img":false}]}
{"op":"mcm","clk":"11449913028","pt":1717315897077,"mc":[{"id":"1.229554894","rc":[{"atl":[[2.44,0]],"id":70003367},{"atl":[[2.5,0]],"id":70003365}],"con":true,"img":false}]}
{"op":"mcm","clk":"11449913040","pt":1717315897181,"mc":[{"id":"1.229554894","rc":[{"atb":[[1.7,2],[1.69,0]],"id":70003365}],"con":true,"img":false}]}
{"op":"mcm","clk":"11449913085","pt":1717315897590,"mc":[{"id":"1.229554894","rc":[{"atl":[[2.44,10.42]],"id":70003367},{"atl":[[2.5,10]],"id":70003365}],"con":true,"img":false}]}
{"op":"mcm","clk":"11449913109","pt":1717315897753,"mc":[{"id":"1.229554894","rc":[{"atb":[[1.7,0],[1.69,2]],"id":70003365}],"con":true,"img":false}]}
{"op":"mcm","clk":"11449913397","pt":1717315900462,"mc":[{"id":"1.229554894","rc":[{"atl":[[2.36,2],[2.38,0]],"id":70003367}],"con":true,"img":false}]}
{"op":"mcm","clk":"11449913667","pt":1717315902849,"mc":[{"id":"1.229554894","rc":[{"atb":[[1.7,2],[1.69,0]],"id":70003365}],"con":true,"img":false}]}
{"op":"mcm","clk":"11449913773","pt":1717315903896,"mc":[{"id":"1.229554894","rc":[{"atl":[[2.42,10.56],[2.44,0]],"id":70003367}],"con":true,"img":false}]}
{"op":"mcm","clk":"11449914014","pt":1717315906258,"mc":[{"id":"1.229554894","rc":[{"atb":[[1.42,35.71]],"id":70003367},{"atl":[[2.42,0],[2.44,10.42]],"id":70003367},{"atb":[[1.46,32.61]],"id":70003365}],"con":true,"img":false}]}
{"op":"mcm","clk":"11449914024","pt":1717315906362,"mc":[{"id":"1.229554894","rc":[{"atb":[[1.45,0]],"id":70003365}],"con":true,"img":false}]}
{"op":"mcm","clk":"11449914034","pt":1717315906461,"mc":[{"id":"1.229554894","rc":[{"atb":[[1.38,0]],"id":70003365}],"con":true,"img":false}]}
{"op":"mcm","clk":"11449914065","pt":1717315906778,"mc":[{"id":"1.229554894","rc":[{"atb":[[1.88,8.92],[1.78,10.06]],"id":70003367},{"atb":[[1.88,8.92],[1.78,10.06]],"id":70003365}],"con":true,"img":false}]}
{"op":"mcm","clk":"11449914171","pt":1717315907960,"mc":[{"id":"1.229554894","rc":[{"atb":[[1.88,10.92],[1.7,0]],"id":70003365}],"con":true,"img":false}]}
{"op":"mcm","clk":"11449914838","pt":1717315914806,"mc":[{"id":"1.229554894","rc":[{"atl":[[2.42,10.56],[2.44,0]],"id":70003367},{"atl":[[2.54,9.74],[2.5,0]],"id":70003365}],"con":true,"img":false}]}
{"op":"mcm","clk":"11449914859","pt":1717315914962,"mc":[{"id":"1.229554894","rc":[{"atl":[[2.52,0]],"id":70003365}],"con":true,"img":false}]}
{"op":"mcm","clk":"11449915935","pt":1717315924928,"mc":[{"id":"1.229554894","rc":[{"atl":[[2.58,12.66]],"id":70003365}],"con":true,"img":false}]}
{"op":"mcm","clk":"11449916985","pt":1717315934828,"mc":[{"id":"1.229554894","rc":[{"atl":[[2.54,0],[2.52,9.87]],"id":70003365}],"con":true,"img":false}]}
{"op":"mcm","clk":"11449917065","pt":1717315935608,"mc":[{"id":"1.229554894","rc":[{"atl":[[2.42,0]],"id":70003367}],"con":true,"img":false}]}
{"op":"mcm","clk":"11449917570","pt":1717315940325,"mc":[{"id":"1.229554894","rc":[{"atl":[[2.36,0],[2.38,2]],"id":70003367}],"con":true,"img":false}]}
{"op":"mcm","clk":"11449917970","pt":1717315944547,"mc":[{"id":"1.229554894","rc":[{"atl":[[2.58,18.99]],"id":70003367}],"con":true,"img":false}]}
{"op":"mcm","clk":"11449918419","pt":1717315948641,"mc":[{"id":"1.229554894","rc":[{"atb":[[1.88,0],[1.78,0]],"id":70003367},{"atb":[[1.88,2],[1.78,0]],"id":70003365}],"con":true,"img":false}]}
{"op":"mcm","clk":"11449918444","pt":1717315948832,"mc":[{"id":"1.229554894","rc":[{"atb":[[1.88,0],[1.69,2]],"id":70003365}],"con":true,"img":false}]}
{"op":"mcm","clk":"11449918603","pt":1717315950244,"mc":[{"id":"1.229554894","rc":[{"atb":[[1.44,34.09]],"id":70003367},{"atb":[[1.47,31.91]],"id":70003365}],"con":true,"img":false}]}
{"op":"mcm","clk":"11449919184","pt":1717315955924,"mc":[{"id":"1.229554894","rc":[{"atb":[[1.41,36.59],[1.44,0],[1.43,2],[1.61,0]],"id":70003367},{"atl":[[2.56,0],[2.52,0],[2.6,0],[2.58,0],[3.25,2],[2.48,0],[3.65,5.66]],"id":70003365}],"con":true,"img":false}]}
{"op":"mcm","clk":"11449919202","pt":1717315956134,"mc":[{"id":"1.229554894","rc":[{"atb":[[1.42,0]],"id":70003367},{"atl":[[2.24,2],[2.38,0]],"id":70003367},{"atb":[[1.79,2],[1.69,0]],"id":70003365}],"con":true,"img":false}]}
{"op":"mcm","clk":"11449919224","pt":1717315956344,"mc":[{"id":"1.229554894","rc":[{"atl":[[2.24,0],[2.22,2]],"id":70003367},{"atb":[[1.8,2],[1.79,0]],"id":70003365}],"con":true,"img":false}]}
{"op":"mcm","clk":"11449920042","pt":1717315964091,"mc":[{"id":"1.229554894","rc":[{"atb":[[1.77,10.19],[1.87,9.01]],"id":70003367},{"atb":[[1.79,9.93],[1.89,8.81]],"id":70003365}],"con":true,"img":false}]}
{"op":"mcm","clk":"11449920062","pt":1717315964250,"mc":[{"id":"1.229554894","rc":[{"atb":[[1.8,0],[1.9,2]],"id":70003365}],"con":true,"img":false}]}
{"op":"mcm","clk":"11449920184","pt":1717315965343,"mc":[{"id":"1.229554894","rc":[{"atl":[[3.75,7.27]],"id":70003365}],"con":true,"img":false}]}
{"op":"mcm","clk":"11449920220","pt":1717315965754,"mc":[{"id":"1.229554894","rc":[{"atl":[[2.24,2],[2.22,0]],"id":70003367}],"con":true,"img":false}]}
{"op":"mcm","clk":"11449920231","pt":1717315965865,"mc":[{"id":"1.229554894","rc":[{"atl":[[2.42,10.56],[2.46,0]],"id":70003367}],"con":true,"img":false}]}
{"op":"mcm","clk":"11449920337","pt":1717315966853,"mc":[{"id":"1.229554894","rc":[{"atl":[[3.2,2],[3.25,0]],"id":70003365}],"con":true,"img":false}]}
{"op":"mcm","clk":"11449920813","pt":1717315971162,"mc":[{"id":"1.229554894","rc":[{"atl":[[2.24,0],[2.44,2]],"id":70003367}],"con":true,"img":false}]}
{"op":"mcm","clk":"11449920822","pt":1717315971265,"mc":[{"id":"1.229554894","rc":[{"atl":[[2.44,0],[2.26,2]],"id":70003367}],"con":true,"img":false}]}
{"op":"mcm","clk":"11449920891","pt":1717315971947,"mc":[{"id":"1.229554894","rc":[{"atb":[[1.43,0],[1.52,2]],"id":70003367},{"atl":[[2.8,2],[3.2,6.82]],"id":70003365}],"con":true,"img":false}]}
{"op":"mcm","clk":"11449920899","pt":1717315972042,"mc":[{"id":"1.229554894","rc":[{"atl":[[2.24,2],[2.26,0]],"id":70003367}],"con":true,"img":false}]}
{"op":"mcm","clk":"11449921245","pt":1717315975171,"mc":[{"id":"1.229554894","rc":[{"atl":[[2.46,13.7]],"id":70003367}],"con":true,"img":false}]}
{"op":"mcm","clk":"11449921443","pt":1717315977081,"mc":[{"id":"1.229554894","rc":[{"atl":[[2.58,0]],"id":70003367}],"con":true,"img":false}]}
{"op":"mcm","clk":"11449921458","pt":1717315977191,"mc":[{"id":"1.229554894","rc":[{"atl":[[2.24,0],[2.46,15.7]],"id":70003367},{"atl":[[3.1,7.14],[2.68,2]],"id":70003365}],"con":true,"img":false}]}
{"op":"mcm","clk":"11449921468","pt":1717315977239,"mc":[{"id":"1.229554894","rc":[{"atl":[[2.3,2],[2.46,13.7]],"id":70003367},{"atl":[[2.8,0]],"id":70003365}],"con":true,"img":false}]}
{"op":"mcm","clk":"11449922070","pt":1717315982395,"mc":[{"id":"1.229554894","rc":[{"atl":[[2.3,0],[2.34,2]],"id":70003367}],"con":true,"img":false}]}
{"op":"mcm","clk":"11449922376","pt":1717315985026,"mc":[{"id":"1.229554894","rc":[{"atb":[[1.46,0],[1.47,0]],"id":70003365}],"con":true,"img":false}]}
{"op":"mcm","clk":"11449922404","pt":1717315985288,"mc":[{"id":"1.229554894","rc":[{"atl":[[2.74,2],[3.1,0],[3.15,6.98],[2.68,0]],"id":70003365}],"con":true,"img":false}]}
{"op":"mcm","clk":"11449922959","pt":1717315990590,"mc":[{"id":"1.229554894","rc":[{"atl":[[2.4,10.71],[2.42,0],[2.38,10.87]],"id":70003367}],"con":true,"img":false}]}
{"op":"mcm","clk":"11449923013","pt":1717315991228,"mc":[{"id":"1.229554894","rc":[{"atl":[[2.42,10.56]],"id":70003367}],"con":true,"img":false}]}
{"op":"mcm","clk":"11449923021","pt":1717315991310,"mc":[{"id":"1.229554894","rc":[{"atl":[[2.4,0],[2.38,0]],"id":70003367}],"con":true,"img":false}]}
{"op":"mcm","clk":"11449923087","pt":1717315992031,"mc":[{"id":"1.229554894","rc":[{"atl":[[2.4,10.71],[2.42,0],[2.38,10.87]],"id":70003367}],"con":true,"img":false}]}
{"op":"mcm","clk":"11449923123","pt":1717315992397,"mc":[{"id":"1.229554894","rc":[{"atl":[[2.4,0],[2.54,0],[2.5,0],[2.42,10.56],[2.38,0],[2.46,0],[2.48,10.14]],"id":70003367}],"con":true,"img":false}]}
{"op":"mcm","clk":"11449923293","pt":1717315994208,"mc":[{"id":"1.229554894","rc":[{"atl":[[3.25,8.89]],"id":70003365}],"con":true,"img":false}]}
{"op":"mcm","clk":"11449923340","pt":1717315994726,"mc":[{"id":"1.229554894","rc":[{"atl":[[2.42,0]],"id":70003367},{"atl":[[3.2,0],[3.75,0]],"id":70003365}],"con":true,"img":false}]}
{"op":"mcm","clk":"11449923439","pt":1717315995710,"mc":[{"id":"1.229554894","rc":[{"atl":[[2.36,2],[2.42,10.56],[2.34,0]],"id":70003367}],"con":true,"img":false}]}
{"op":"mcm","clk":"11449923459","pt":1717315995915,"mc":[{"id":"1.229554894","rc":[{"atl":[[2.72,2],[2.74,0]],"id":70003365}],"con":true,"img":false}]}
{"op":"mcm","clk":"11449923572","pt":1717315997102,"mc":[{"id":"1.229554894","rc":[{"atl":[[2.42,0],[2.46,10.27]],"id":70003367}],"con":true,"img":false}]}
{"op":"mcm","clk":"11449923581","pt":1717315997211,"mc":[{"id":"1.229554894","rc":[{"atl":[[2.42,10.56]],"id":70003367}],"con":true,"img":false}]}
{"op":"mcm","clk":"11449923952","pt":1717316000834,"mc":[{"id":"1.229554894","rc":[{"atl":[[2.36,0],[2.44,2]],"id":70003367}],"con":true,"img":false}]}
{"op":"mcm","clk":"11449924186","pt":1717316003005,"mc":[{"id":"1.229554894","rc":[{"atl":[[3.35,10.64]],"id":70003365}],"con":true,"img":false}]}
{"op":"mcm","clk":"11449924307","pt":1717316004301,"mc":[{"id":"1.229554894","rc":[{"atb":[[1.63,2],[1.52,0]],"id":70003367},{"atl":[[2.72,0],[2.6,9.38],[3.15,0],[2.48,2]],"id":70003365}],"con":true,"img":false}]}
{"op":"mcm","clk":"11449924351","pt":1717316004817,"mc":[{"id":"1.229554894","rc":[{"atl":[[2.4,10.71],[2.42,0]],"id":70003367}],"con":true,"img":false}]}
{"op":"mcm","clk":"11449924364","pt":1717316004921,"mc":[{"id":"1.229554894","rc":[{"atl":[[2.5,10],[2.48,0]],"id":70003365}],"con":true,"img":false}]}
{"op":"mcm","clk":"11449924390","pt":1717316005128,"mc":[{"id":"1.229554894","rc":[{"atl":[[2.4,0]],"id":70003367}],"con":true,"img":false}]}
{"op":"mcm","clk":"11449924615","pt":1717316007546,"mc":[{"id":"1.229554894","rc":[{"atl":[[2.42,10.56],[2.46,0]],"id":70003367}],"con":true,"img":false}]}
{"op":"mcm","clk":"11449924625","pt":1717316007596,"mc":[{"id":"1.229554894","rc":[{"atl":[[2.4,10]],"id":70003367}],"con":true,"img":false}]}
{"op":"mcm","clk":"11449924635","pt":1717316007697,"mc":[{"id":"1.229554894","rc":[{"atl":[[2.44,0]],"id":70003367}],"con":true,"img":false}]}
{"op":"mcm","clk":"11449924647","pt":1717316007809,"mc":[{"id":"1.229554894","rc":[{"atl":[[2.44,10]],"id":70003367}],"con":true,"img":false}]}
{"op":"mcm","clk":"11449924655","pt":1717316007907,"mc":[{"id":"1.229554894","rc":[{"atl":[[2.4,0]],"id":70003367}],"con":true,"img":false}]}
{"op":"mcm","clk":"11449924783","pt":1717316009514,"mc":[{"id":"1.229554894","rc":[{"atb":[[1.77,0],[1.87,0]],"id":70003367},{"atb":[[1.79,0],[1.89,0]],"id":70003365}],"con":true,"img":false}]}
{"op":"mcm","clk":"11449924790","pt":1717316009617,"mc":[{"id":"1.229554894","rc":[{"atb":[[1.63,0],[1.62,10]],"id":70003367},{"atb":[[1.9,0],[1.66,10]],"id":70003365}],"con":true,"img":false}]}
{"op":"mcm","clk":"11449924797","pt":1717316009720,"mc":[{"id":"1.229554894","rc":[{"atb":[[1.43,34.88]],"id":70003367},{"atb":[[1.46,32.61]],"id":70003365}],"con":true,"img":false}]}
{"op":"mcm","clk":"11449925024","pt":1717316012214,"mc":[{"id":"1.229554894","rc":[{"atl":[[2.4,10.71],[2.42,0],[2.46,10.27]],"id":70003367}],"con":true,"img":false}]}
{"op":"mcm","clk":"11449925080","pt":1717316012730,"mc":[{"id":"1.229554894","rc":[{"atb":[[1.44,34.09],[1.43,0]],"id":70003367},{"atl":[[2.4,0],[2.44,20.42]],"id":70003367},{"atb":[[1.48,31.25]],"id":70003365}],"con":true,"img":false}]}
{"op":"mcm","clk":"11449925093","pt":1717316012841,"mc":[{"id":"1.229554894","rc":[{"atb":[[1.44,0],[1.45,33.33]],"id":70003367},{"atl":[[2.42,10.56],[2.44,10]],"id":70003367}],"con":true,"img":false}]}
{"op":"mcm","clk":"11449925304","pt":1717316015220,"mc":[{"id":"1.229554894","rc":[{"atb":[[1.47,31.91]],"id":70003367},{"atb":[[1.48,0],[1.47,31.91]],"id":70003365}],"con":true,"img":false}]}
{"op":"mcm","clk":"11449925314","pt":1717316015328,"mc":[{"id":"1.229554894","rc":[{"atb":[[1.45,0]],"id":70003367}],"con":true,"img":false}]}
{"op":"mcm","clk":"11449925326","pt":1717316015584,"mc":[{"id":"1.229554894","rc":[{"atl":[[2.4,10.71]],"id":70003367}],"con":true,"img":false}]}
{"op":"mcm","clk":"11449925341","pt":1717316015735,"mc":[{"id":"1.229554894","rc":[{"atl":[[2.38,10],[2.44,0]],"id":70003367}],"con":true,"img":false}]}
{"op":"mcm","clk":"11449925345","pt":1717316015840,"mc":[{"id":"1.229554894","rc":[{"atl":[[2.44,10]],"id":70003367}],"con":true,"img":false}]}
{"op":"mcm","clk":"11449925357","pt":1717316015949,"mc":[{"id":"1.229554894","rc":[{"atl":[[2.38,0]],"id":70003367}],"con":true,"img":false}]}
{"op":"mcm","clk":"11449925371","pt":1717316016153,"mc":[{"id":"1.229554894","rc":[{"atl":[[2.4,0],[2.38,10.87]],"id":70003367}],"con":true,"img":false}]}
{"op":"mcm","clk":"11449925385","pt":1717316016261,"mc":[{"id":"1.229554894","rc":[{"atl":[[2.36,10],[2.44,0]],"id":70003367}],"con":true,"img":false}]}
{"op":"mcm","clk":"11449925395","pt":1717316016361,"mc":[{"id":"1.229554894","rc":[{"atl":[[2.36,0],[2.42,20.56]],"id":70003367}],"con":true,"img":false}]}
{"op":"mcm","clk":"11449925446","pt":1717316016824,"mc":[{"id":"1.229554894","rc":[{"atl":[[2.38,0]],"id":70003367}],"con":true,"img":false}]}
{"op":"mcm","clk":"11449925522","pt":1717316017645,"mc":[{"id":"1.229554894","rc":[{"atl":[[2.38,10.87]],"id":70003367}],"con":true,"img":false}]}
{"op":"mcm","clk":"11449925861","pt":1717316021422,"mc":[{"id":"1.229554894","rc":[{"atl":[[2.42,10.56],[2.44,10]],"id":70003367}],"con":true,"img":false}]}
{"op":"mcm","clk":"11449925957","pt":1717316022351,"mc":[{"id":"1.229554894","rc":[{"atl":[[2.38,0]],"id":70003367},{"atb":[[1.66,0],[1.65,10]],"id":70003365}],"con":true,"img":false}]}
{"op":"mcm","clk":"11449925986","pt":1717316022555,"mc":[{"id":"1.229554894","rc":[{"atl":[[2.46,20.27],[2.44,0]],"id":70003367}],"con":true,"img":false}]}
{"op":"mcm","clk":"11449926070","pt":1717316023227,"mc":[{"id":"1.229554894","rc":[{"atl":[[2.42,0]],"id":70003367}],"con":true,"img":false}]}
{"op":"mcm","clk":"11449926109","pt":1717316023641,"mc":[{"id":"1.229554894","rc":[{"atl":[[2.64,12.2]],"id":70003365}],"con":true,"img":false}]}
{"op":"mcm","clk":"11449926136","pt":1717316023853,"mc":[{"id":"1.229554894","rc":[{"atl":[[3.35,0],[3.25,0],[3.65,0]],"id":70003365}],"con":true,"img":false}]}
{"op":"mcm","clk":"11449926326","pt":1717316025968,"mc":[{"id":"1.229554894","rc":[{"atb":[[1.45,44.44]],"id":70003367},{"atl":[[2.5,13.33]],"id":70003367}],"con":true,"img":false}]}
{"op":"mcm","clk":"11449926367","pt":1717316026335,"mc":[{"id":"1.229554894","rc":[{"atb":[[1.45,33.33],[1.47,0],[1.35,0]],"id":70003367},{"atl":[[2.52,9.87],[2.46,10],[2.44,10.42]],"id":70003367},{"atb":[[1.45,33.33],[1.47,0]],"id":70003365}],"con":true,"img":false}]}
{"op":"mcm","clk":"11449926375","pt":1717316026432,"mc":[{"id":"1.229554894","rc":[{"atl":[[2.42,2],[2.46,0]],"id":70003367}],"con":true,"img":false}]}
{"op":"mcm","clk":"11449926496","pt":1717316027679,"mc":[{"id":"1.229554894","rc":[{"atb":[[1.45,0],[1.43,34.88]],"id":70003367},{"atl":[[2.44,0]],"id":70003367},{"atb":[[1.46,0],[1.51,29.41]],"id":70003365}],"con":true,"img":false}]}
{"op":"mcm","clk":"11449926673","pt":1717316029342,"mc":[{"id":"1.229554894","rc":[{"atb":[[1.45,33.33]],"id":70003367},{"atb":[[1.51,0]],"id":70003365}],"con":true,"img":false}]}
{"op":"mcm","clk":"11449926901","pt":1717316031564,"mc":[{"id":"1.229554894","rc":[{"atl":[[2.46,2]],"id":70003367}],"con":true,"img":false}]}
{"op":"mcm","clk":"11449926911","pt":1717316031668,"mc":[{"id":"1.229554894","rc":[{"atl":[[2.42,0]],"id":70003367}],"con":true,"img":false}]}
{"op":"mcm","clk":"11449927029","pt":1717316032760,"mc":[{"id":"1.229554894","rc":[{"atl":[[2.5,10],[2.48,0]],"id":70003367}],"con":true,"img":false}]}
{"op":"mcm","clk":"11449927150","pt":1717316033850,"mc":[{"id":"1.229554894","rc":[{"atb":[[1.45,0]],"id":70003367},{"atb":[[1.51,29.41]],"id":70003365}],"con":true,"img":false}]}
{"op":"mcm","clk":"11449927259","pt":1717316034938,"mc":[{"id":"1.229554894","rc":[{"atl":[[2.48,10.14]],"id":70003367}],"con":true,"img":false}]}
{"op":"mcm","clk":"11449927405","pt":1717316036284,"mc":[{"id":"1.229554894","rc":[{"atb":[[1.45,33.33]],"id":70003367},{"atb":[[1.51,0]],"id":70003365}],"con":true,"img":false}]}
{"op":"mcm","clk":"11449927415","pt":1717316036335,"mc":[{"id":"1.229554894","rc":[{"atb":[[1.62,0],[1.61,2]],"id":70003367},{"atl":[[2.48,0]],"id":70003367},{"atl":[[2.48,10.14]],"id":70003365}],"con":true,"img":false}]}
{"op":"mcm","clk":"11449927563","pt":1717316037989,"mc":[{"id":"1.229554894","rc":[{"atb":[[1.64,2],[1.65,0]],"id":70003365}],"con":true,"img":false}]}
{"op":"mcm","clk":"11449927695","pt":1717316039304,"mc":[{"id":"1.229554894","rc":[{"atb":[[1.45,0]],"id":70003367},{"atb":[[1.51,29.41]],"id":70003365}],"con":true,"img":false}]}
{"op":"mcm","clk":"11449927754","pt":1717316039878,"mc":[{"id":"1.229554894","rc":[{"atl":[[2.48,10.14]],"id":70003367}],"con":true,"img":false}]}
{"op":"mcm","clk":"11449928201","pt":1717316044386,"mc":[{"id":"1.229554894","rc":[{"atb":[[1.77,10.19],[1.87,9.01]],"id":70003367},{"atb":[[1.79,9.93],[1.89,8.81]],"id":70003365}],"con":true,"img":false}]}
{"op":"mcm","clk":"11449928225","pt":1717316044601,"mc":[{"id":"1.229554894","rc":[{"atb":[[1.64,0],[1.9,2]],"id":70003365}],"con":true,"img":false}]}
{"op":"mcm","clk":"11449928474","pt":1717316047288,"mc":[{"id":"1.229554894","rc":[{"atl":[[2.52,13.16]],"id":70003365}],"con":true,"img":false}]}
{"op":"mcm","clk":"11449928532","pt":1717316047860,"mc":[{"id":"1.229554894","rc":[{"atl":[[2.52,13.16]],"id":70003367}],"con":true,"img":false}]}
{"op":"mcm","clk":"11449929066","pt":1717316053390,"mc":[{"id":"1.229554894","rc":[{"atl":[[2.52,9.87],[2.48,0]],"id":70003367},{"atb":[[1.51,0]],"id":70003365}],"con":true,"img":false}]}
{"op":"mcm","clk":"11449929103","pt":1717316053705,"mc":[{"id":"1.229554894","rc":[{"atl":[[2.5,0]],"id":70003367}],"con":true,"img":false}]}
{"op":"mcm","clk":"11449929267","pt":1717316055205,"mc":[{"id":"1.229554894","rc":[{"atl":[[2.56,16.03]],"id":70003365}],"con":true,"img":false}]}
{"op":"mcm","clk":"11449929322","pt":1717316055678,"mc":[{"id":"1.229554894","rc":[{"atl":[[2.64,0]],"id":70003365}],"con":true,"img":false}]}
{"op":"mcm","clk":"11449929373","pt":1717316056303,"mc":[{"id":"1.229554894","rc":[{"atl":[[2.5,10]],"id":70003367},{"atl":[[2.5,20],[2.48,0]],"id":70003365}],"con":true,"img":false}]}
{"op":"mcm","clk":"11449929507","pt":1717316057801,"mc":[{"id":"1.229554894","rc":[{"atl":[[2.46,12.27]],"id":70003367}],"con":true,"img":false}]}
{"op":"mcm","clk":"11449929517","pt":1717316057913,"mc":[{"id":"1.229554894","rc":[{"atl":[[2.5,10],[2.52,9.87]],"id":70003365}],"con":true,"img":false}]}
{"op":"mcm","clk":"11449929624","pt":1717316058995,"mc":[{"id":"1.229554894","rc":[{"atl":[[2.44,10.42]],"id":70003367},{"atl":[[2.48,10.14]],"id":70003365}],"con":true,"img":false}]}
{"op":"mcm","clk":"11449929633","pt":1717316059101,"mc":[{"id":"1.229554894","rc":[{"atl":[[2.42,4.51],[2.46,10.27]],"id":70003367}],"con":true,"img":false}]}
{"op":"mcm","clk":"11449929831","pt":1717316061474,"mc":[{"id":"1.229554894","rc":[{"atl":[[2.42,15.07],[2.44,0]],"id":70003367}],"con":true,"img":false}]}
{"op":"mcm","clk":"11449930108","pt":1717316064326,"mc":[{"id":"1.229554894","rc":[{"atl":[[2.42,10.56],[2.46,12.27]],"id":70003367}],"con":true,"img":false}]}
{"op":"mcm","clk":"11449930328","pt":1717316066704,"mc":[{"id":"1.229554894","rc":[{"atl":[[2.42,0],[2.44,10.42]],"id":70003367}],"con":true,"img":false}]}
{"op":"mcm","clk":"11449930339","pt":1717316066807,"mc":[{"id":"1.229554894","rc":[{"atl":[[2.42,10.56]],"id":70003367}],"con":true,"img":false}]}
{"op":"mcm","clk":"11449930350","pt":1717316066912,"mc":[{"id":"1.229554894","rc":[{"atl":[[2.44,0]],"id":70003367}],"con":true,"img":false}]}
{"op":"mcm","clk":"11449930778","pt":1717316072124,"mc":[{"id":"1.229554894","rc":[{"atl":[[2.4,10.71],[2.42,0]],"id":70003367}],"con":true,"img":false}]}
{"op":"mcm","clk":"11449930789","pt":1717316072233,"mc":[{"id":"1.229554894","rc":[{"atl":[[2.42,10.56]],"id":70003367}],"con":true,"img":false}]}
{"op":"mcm","clk":"11449930798","pt":1717316072279,"mc":[{"id":"1.229554894","rc":[{"atl":[[2.4,0]],"id":70003367}],"con":true,"img":false}]}
{"op":"mcm","clk":"11449931259","pt":1717316077407,"mc":[{"id":"1.229554894","rc":[{"atl":[[2.36,2],[2.46,10.27]],"id":70003367}],"con":true,"img":false}]}
{"op":"mcm","clk":"11449931269","pt":1717316077514,"mc":[{"id":"1.229554894","rc":[{"atl":[[2.4,10.71],[2.42,0]],"id":70003367}],"con":true,"img":false}]}
{"op":"mcm","clk":"11449931293","pt":1717316077820,"mc":[{"id":"1.229554894","rc":[{"atl":[[2.4,0],[2.42,10.56]],"id":70003367}],"con":true,"img":false}]}
{"op":"mcm","clk":"11449931581","pt":1717316080912,"mc":[{"id":"1.229554894","rc":[{"atl":[[2.58,9.49],[2.48,0]],"id":70003365}],"con":true,"img":false}]}
{"op":"mcm","clk":"11449931616","pt":1717316081331,"mc":[{"id":"1.229554894","rc":[{"atl":[[2.4,10.71],[2.42,0]],"id":70003367},{"atl":[[2.52,0],[2.7,8.82]],"id":70003365}],"con":true,"img":false}]}
{"op":"mcm","clk":"11449931647","pt":1717316081638,"mc":[{"id":"1.229554894","rc":[{"atl":[[2.4,0],[2.42,10.56]],"id":70003367},{"atl":[[2.56,0]],"id":70003365}],"con":true,"img":false}]}
{"op":"mcm","clk":"11449931667","pt":1717316081847,"mc":[{"id":"1.229554894","rc":[{"atl":[[2.4,10.71],[2.42,0]],"id":70003367},{"atl":[[2.58,0]],"id":70003365}],"con":true,"img":false}]}
{"op":"mcm","clk":"11449931705","pt":1717316082215,"mc":[{"id":"1.229554894","rc":[{"atl":[[2.6,0]],"id":70003365}],"con":true,"img":false}]}
{"op":"mcm","clk":"11449931724","pt":1717316082424,"mc":[{"id":"1.229554894","rc":[{"atl":[[2.4,0],[2.42,10.56]],"id":70003367}],"con":true,"img":false}]}
{"op":"mcm","clk":"11449931732","pt":1717316082525,"mc":[{"id":"1.229554894","rc":[{"atl":[[2.36,0],[2.4,10.71],[2.42,0],[2.38,10]],"id":70003367}],"con":true,"img":false}]}
{"op":"mcm","clk":"11449931769","pt":1717316082939,"mc":[{"id":"1.229554894","rc":[{"atl":[[2.4,0],[2.42,10.56]],"id":70003367}],"con":true,"img":false}]}
{"op":"mcm","clk":"11449931826","pt":1717316083407,"mc":[{"id":"1.229554894","rc":[{"atl":[[2.4,10.71],[2.42,0]],"id":70003367}],"con":true,"img":false}]}
{"op":"mcm","clk":"11449931915","pt":1717316084342,"mc":[{"id":"1.229554894","rc":[{"atb":[[1.77,0],[1.87,0]],"id":70003367},{"atb":[[1.79,0],[1.89,0]],"id":70003365}],"con":true,"img":false}]}
{"op":"mcm","clk":"11449931932","pt":1717316084548,"mc":[{"id":"1.229554894","rc":[{"atb":[[1.63,10],[1.45,33.33],[1.61,0]],"id":70003367},{"atb":[[1.9,0],[1.5,30],[1.69,10]],"id":70003365}],"con":true,"img":false}]}
{"op":"mcm","clk":"11449931968","pt":1717316084916,"mc":[{"id":"1.229554894","rc":[{"atb":[[1.46,32.61],[1.45,0]],"id":70003367},{"atb":[[1.46,32.61],[1.5,0]],"id":70003365}],"con":true,"img":false}]}
{"op":"mcm","clk":"11449931996","pt":1717316085230,"mc":[{"id":"1.229554894","rc":[{"atl":[[2.4,0],[2.42,10.56]],"id":70003367}],"con":true,"img":false}]}
{"op":"mcm","clk":"11449932101","pt":1717316086320,"mc":[{"id":"1.229554894","rc":[{"atb":[[1.46,0],[1.47,31.91]],"id":70003367},{"atb":[[1.46,0],[1.44,34.09]],"id":70003365}],"con":true,"img":false}]}
{"op":"mcm","clk":"11449932123","pt":1717316086530,"mc":[{"id":"1.229554894","rc":[{"atl":[[2.42,0]],"id":70003367}],"con":true,"img":false}]}
{"op":"mcm","clk":"11449932135","pt":1717316086631,"mc":[{"id":"1.229554894","rc":[{"atb":[[1.45,0]],"id":70003365}],"con":true,"img":false}]}
{"op":"mcm","clk":"11449932157","pt":1717316086838,"mc":[{"id":"1.229554894","rc":[{"atl":[[2.46,0]],"id":70003367}],"con":true,"img":false}]}
{"op":"mcm","clk":"11449932175","pt":1717316087047,"mc":[{"id":"1.229554894","rc":[{"atl":[[2.5,0]],"id":70003367}],"con":true,"img":false}]}
{"op":"mcm","clk":"11449932792","pt":1717316093623,"mc":[{"id":"1.229554894","rc":[{"atb":[[1.45,44.44]],"id":70003367},{"atl":[[2.56,12.82]],"id":70003367},{"atb":[[1.38,78.95]],"id":70003365},{"atl":[[2.74,11.49]],"id":70003365}],"con":true,"img":false}]}
{"op":"mcm","clk":"11449933079","pt":1717316097134,"mc":[{"id":"1.229554894","rc":[{"atb":[[1.37,0]],"id":70003367}],"con":true,"img":false}]}
{"op":"mcm","clk":"11449933171","pt":1717316098384,"mc":[{"id":"1.229554894","rc":[{"atb":[[1.73,10.75],[1.83,9.45]],"id":70003367},{"atb":[[1.81,9.68],[1.91,8.62]],"id":70003365}],"con":true,"img":false}]}
{"op":"mcm","clk":"11449933187","pt":1717316098545,"mc":[{"id":"1.229554894","rc":[{"atb":[[1.92,10],[1.69,0]],"id":70003365}],"con":true,"img":false}]}
{"op":"mcm","clk":"11449933387","pt":1717316100721,"mc":[{"id":"1.229554894","rc":[{"atl":[[2.6,15.62]],"id":70003367},{"atl":[[2.78,14.04]],"id":70003365}],"con":true,"img":false}]}
{"op":"mcm","clk":"11449933394","pt":1717316100825,"mc":[{"id":"1.229554894","rc":[{"atb":[[1.84,4.26]],"id":70003367},{"atl":[[2.48,4.52]],"id":70003365}],"con":true,"img":false}]}
{"op":"mcm","clk":"11449933658","pt":1717316103471,"mc":[{"id":"1.229554894","rc":[{"atb":[[1.45,0],[1.47,0]],"id":70003367},{"atl":[[2.5,10]],"id":70003367}],"con":true,"img":false}]}
{"op":"mcm","clk":"11449934097","pt":1717316108074,"mc":[{"id":"1.229554894","rc":[{"atl":[[2.5,0]],"id":70003367}],"con":true,"img":false}]}
{"op":"mcm","clk":"11449934276","pt":1717316110355,"mc":[{"id":"1.229554894","rc":[{"atl":[[2.64,18.29]],"id":70003367}],"con":true,"img":false}]}
{"op":"mcm","clk":"11449934782","pt":1717316115751,"mc":[{"id":"1.229554894","rc":[{"atl":[[2.4,10],[2.38,0]],"id":70003367}],"con":true,"img":false}]}
{"op":"mcm","clk":"11449934905","pt":1717316117147,"mc":[{"id":"1.229554894","rc":[{"atl":[[2.48,10.14]],"id":70003367}],"con":true,"img":false}]}
{"op":"mcm","clk":"11449934911","pt":1717316117249,"mc":[{"id":"1.229554894","rc":[{"atl":[[2.52,0]],"id":70003367}],"con":true,"img":false}]}
{"op":"mcm","clk":"11449935279","pt":1717316121392,"mc":[{"id":"1.229554894","rc":[{"atl":[[2.46,10.27],[2.48,0]],"id":70003367}],"con":true,"img":false}]}
{"op":"mcm","clk":"11449935887","pt":1717316127968,"mc":[{"id":"1.229554894","rc":[{"atl":[[2.5,13.33]],"id":70003367}],"con":true,"img":false}]}
{"op":"mcm","clk":"11449936123","pt":1717316130306,"mc":[{"id":"1.229554894","rc":[{"atl":[[2.56,0],[2.6,0],[2.64,0]],"id":70003367}],"con":true,"img":false}]}
{"op":"mcm","clk":"11449936512","pt":1717316134599,"mc":[{"id":"1.229554894","rc":[{"atl":[[2.54,16.23]],"id":70003367}],"con":true,"img":false}]}
{"op":"mcm","clk":"11449936702","pt":1717316136575,"mc":[{"id":"1.229554894","rc":[{"atl":[[2.4,0],[2.5,23.33]],"id":70003367}],"con":true,"img":false}]}
{"op":"mcm","clk":"11449936745","pt":1717316137096,"mc":[{"id":"1.229554894","rc":[{"atl":[[2.46,0],[2.48,10.14]],"id":70003367}],"con":true,"img":false}]}
{"op":"mcm","clk":"11449936766","pt":1717316137302,"mc":[{"id":"1.229554894","rc":[{"atl":[[2.5,20],[2.48,0]],"id":70003367}],"con":true,"img":false}]}
{"op":"mcm","clk":"11449936804","pt":1717316137729,"mc":[{"id":"1.229554894","rc":[{"atb":[[1.73,0],[1.83,0]],"id":70003367},{"atb":[[1.81,0],[1.91,0]],"id":70003365}],"con":true,"img":false}]}
{"op":"mcm","clk":"11449936815","pt":1717316137829,"mc":[{"id":"1.229554894","rc":[{"atb":[[1.92,0],[1.58,10]],"id":70003365}],"con":true,"img":false}]}
{"op":"mcm","clk":"11449936825","pt":1717316137930,"mc":[{"id":"1.229554894","rc":[{"atb":[[1.44,0],[1.5,30]],"id":70003365}],"con":true,"img":false}]}
{"op":"mcm","clk":"11449936843","pt":1717316138094,"mc":[{"id":"1.229554894","rc":[{"atb":[[1.5,0]],"id":70003365}],"con":true,"img":false}]}
{"op":"mcm","clk":"11449936854","pt":1717316138187,"mc":[{"id":"1.229554894","rc":[{"atb":[[1.51,29.41]],"id":70003365}],"con":true,"img":false}]}
{"op":"mcm","clk":"11449936943","pt":1717316139286,"mc":[{"id":"1.229554894","rc":[{"atb":[[1.5,30],[1.51,0]],"id":70003365}],"con":true,"img":false}]}
{"op":"mcm","clk":"11449936982","pt":1717316139868,"mc":[{"id":"1.229554894","rc":[{"atb":[[1.5,0],[1.51,29.41]],"id":70003365}],"con":true,"img":false}]}
{"op":"mcm","clk":"11449937140","pt":1717316141495,"mc":[{"id":"1.229554894","rc":[{"atl":[[2.46,10.27]],"id":70003367}],"con":true,"img":false}]}
{"op":"mcm","clk":"11449937160","pt":1717316141699,"mc":[{"id":"1.229554894","rc":[{"atl":[[2.54,26.23]],"id":70003367}],"con":true,"img":false}]}
{"op":"mcm","clk":"11449937171","pt":1717316141803,"mc":[{"id":"1.229554894","rc":[{"atl":[[2.5,10]],"id":70003367},{"atl":[[2.6,9.38]],"id":70003365}],"con":true,"img":false}]}
{"op":"mcm","clk":"11449937190","pt":1717316142011,"mc":[{"id":"1.229554894","rc":[{"atl":[[2.46,0],[2.48,10.14]],"id":70003367}],"con":true,"img":false}]}
{"op":"mcm","clk":"11449937201","pt":1717316142115,"mc":[{"id":"1.229554894","rc":[{"atl":[[2.54,16.23],[2.5,20]],"id":70003367}],"con":true,"img":false}]}
{"op":"mcm","clk":"11449937208","pt":1717316142214,"mc":[{"id":"1.229554894","rc":[{"atl":[[2.54,26.23]],"id":70003367}],"con":true,"img":false}]}
{"op":"mcm","clk":"11449937217","pt":1717316142318,"mc":[{"id":"1.229554894","rc":[{"atl":[[2.5,10]],"id":70003367}],"con":true,"img":false}]}
{"op":"mcm","clk":"11449937272","pt":1717316142888,"mc":[{"id":"1.229554894","rc":[{"atb":[[1.59,10],[1.58,0]],"id":70003365}],"con":true,"img":false}]}
{"op":"mcm","clk":"11449937345","pt":1717316143613,"mc":[{"id":"1.229554894","rc":[{"atl":[[2.44,10.42],[2.6,9.38],[2.48,0]],"id":70003367},{"atb":[[1.59,0],[1.54,10]],"id":70003365}],"con":true,"img":false}]}
{"op":"mcm","clk":"11449937403","pt":1717316144197,"mc":[{"id":"1.229554894","rc":[{"atl":[[2.42,10.56],[2.44,0]],"id":70003367}],"con":true,"img":false}]}
{"op":"mcm","clk":"11449937641","pt":1717316146896,"mc":[{"id":"1.229554894","rc":[{"atl":[[2.56,9.62],[2.6,0]],"id":70003365}],"con":true,"img":false}]}
{"op":"mcm","clk":"11449937679","pt":1717316147310,"mc":[{"id":"1.229554894","rc":[{"atl":[[2.54,16.23],[2.48,10]],"id":70003367}],"con":true,"img":false}]}
{"op":"mcm","clk":"11449937803","pt":1717316148711,"mc":[{"id":"1.229554894","rc":[{"atb":[[1.63,10],[1.54,0]],"id":70003365}],"con":true,"img":false}]}
{"op":"mcm","clk":"11449937978","pt":1717316150413,"mc":[{"id":"1.229554894","rc":[{"atl":[[2.46,13.7]],"id":70003367}],"con":true,"img":false}]}
{"op":"mcm","clk":"11449938025","pt":1717316150929,"mc":[{"id":"1.229554894","rc":[{"atl":[[2.6,0]],"id":70003367}],"con":true,"img":false}]}
{"op":"mcm","clk":"11449938065","pt":1717316151343,"mc":[{"id":"1.229554894","rc":[{"atl":[[2.42,0],[2.44,10.42]],"id":70003367}],"con":true,"img":false}]}
{"op":"mcm","clk":"11449938077","pt":1717316151402,"mc":[{"id":"1.229554894","rc":[{"atl":[[2.64,9.15]],"id":70003367},{"atb":[[1.64,5.01]],"id":70003365}],"con":true,"img":false}]}
{"op":"mcm","clk":"11449938082","pt":1717316151500,"mc":[{"id":"1.229554894","rc":[{"atl":[[2.4,3.88],[2.52,9.87],[2.44,0]],"id":70003367}],"con":true,"img":false}]}
{"op":"mcm","clk":"11449938092","pt":1717316151656,"mc":[{"id":"1.229554894","rc":[{"atl":[[2.54,0],[2.5,0],[2.46,0],[2.64,0]],"id":70003367}],"con":true,"img":false}]}
{"op":"mcm","clk":"11449938103","pt":1717316151707,"mc":[{"id":"1.229554894","rc":[{"atl":[[2.44,10.42]],"id":70003367}],"con":true,"img":false}]}
{"op":"mcm","clk":"11449938109","pt":1717316151819,"mc":[{"id":"1.229554894","rc":[{"atl":[[2.48,20.14]],"id":70003367},{"atl":[[2.56,0],[2.52,9.87]],"id":70003365}],"con":true,"img":false}]}
{"op":"mcm","clk":"11449938117","pt":1717316151915,"mc":[{"id":"1.229554894","rc":[{"atl":[[2.44,0]],"id":70003367},{"atl":[[2.5,20]],"id":70003365}],"con":true,"img":false}]}
{"op":"mcm","clk":"11449938126","pt":1717316152021,"mc":[{"id":"1.229554894","rc":[{"atl":[[2.52,0]],"id":70003365}],"con":true,"img":false}]}
{"op":"mcm","clk":"11449938134","pt":1717316152120,"mc":[{"id":"1.229554894","rc":[{"atl":[[2.78,0]],"id":70003365}],"con":true,"img":false}]}
{"op":"mcm","clk":"11449938153","pt":1717316152331,"mc":[{"id":"1.229554894","rc":[{"atl":[[2.5,10],[2.48,10]],"id":70003367},{"atl":[[2.48,14.66]],"id":70003365}],"con":true,"img":false}]}
{"op":"mcm","clk":"11449938165","pt":1717316152435,"mc":[{"id":"1.229554894","rc":[{"atl":[[2.38,2],[2.48,0]],"id":70003367}],"con":true,"img":false}]}
{"op":"mcm","clk":"11449938198","pt":1717316152743,"mc":[{"id":"1.229554894","rc":[{"atl":[[2.46,10.27]],"id":70003367}],"con":true,"img":false}]}
{"op":"mcm","clk":"11449938220","pt":1717316152951,"mc":[{"id":"1.229554894","rc":[{"atl":[[2.46,0],[2.48,10.14]],"id":70003367}],"con":true,"img":false}]}
{"op":"mcm","clk":"11449938229","pt":1717316153011,"mc":[{"id":"1.229554894","rc":[{"atl":[[2.46,10.27],[2.48,0]],"id":70003367},{"atl":[[2.48,4.52]],"id":70003365}],"con":true,"img":false}]}
{"op":"mcm","clk":"11449938235","pt":1717316153107,"mc":[{"id":"1.229554894","rc":[{"atl":[[2.44,10.42]],"id":70003367}],"con":true,"img":false}]}
{"op":"mcm","clk":"11449938256","pt":1717316153321,"mc":[{"id":"1.229554894","rc":[{"atl":[[2.44,0],[2.48,10.14]],"id":70003367},{"atl":[[2.48,14.66]],"id":70003365}],"con":true,"img":false}]}
{"op":"mcm","clk":"11449938271","pt":1717316153528,"mc":[{"id":"1.229554894","rc":[{"atl":[[2.46,0]],"id":70003367}],"con":true,"img":false}]}
{"op":"mcm","clk":"11449938304","pt":1717316153838,"mc":[{"id":"1.229554894","rc":[{"atb":[[1.63,0],[1.65,2]],"id":70003365}],"con":true,"img":false}]}
{"op":"mcm","clk":"11449938359","pt":1717316154408,"mc":[{"id":"1.229554894","rc":[{"atl":[[2.46,10.27]],"id":70003367}],"con":true,"img":false}]}
{"op":"mcm","clk":"11449938393","pt":1717316154732,"mc":[{"id":"1.229554894","rc":[{"atb":[[1.73,10.75],[1.83,9.45]],"id":70003367},{"atb":[[1.81,9.68],[1.91,8.62]],"id":70003365}],"con":true,"img":false}]}
{"op":"mcm","clk":"11449938404","pt":1717316154834,"mc":[{"id":"1.229554894","rc":[{"atl":[[2.46,0]],"id":70003367}],"con":true,"img":false}]}
{"op":"mcm","clk":"11449938415","pt":1717316154943,"mc":[{"id":"1.229554894","rc":[{"atl":[[2.38,5.9]],"id":70003367},{"atb":[[1.65,6.98]],"id":70003365}],"con":true,"img":false}]}
{"op":"mcm","clk":"11449938422","pt":1717316155045,"mc":[{"id":"1.229554894","rc":[{"atl":[[2.48,0]],"id":70003367}],"con":true,"img":false}]}
{"op":"mcm","clk":"11449938768","pt":1717316158942,"mc":[{"id":"1.229554894","rc":[{"atb":[[1.91,13.38],[1.65,4.98]],"id":70003365}],"con":true,"img":false}]}
{"op":"mcm","clk":"11449938807","pt":1717316159448,"mc":[{"id":"1.229554894","rc":[{"atl":[[2.52,13.16]],"id":70003365}],"con":true,"img":false}]}
{"op":"mcm","clk":"11449938812","pt":1717316159499,"mc":[{"id":"1.229554894","rc":[{"atl":[[2.46,10.27],[2.48,4.52]],"id":70003365}],"con":true,"img":false}]}
{"op":"mcm","clk":"11449938828","pt":1717316159710,"mc":[{"id":"1.229554894","rc":[{"atl":[[2.74,0],[2.52,0]],"id":70003365}],"con":true,"img":false}]}
{"op":"mcm","clk":"11449938895","pt":1717316160536,"mc":[{"id":"1.229554894","rc":[{"atl":[[2.54,12.99]],"id":70003367}],"con":true,"img":false}]}
{"op":"mcm","clk":"11449938957","pt":1717316161106,"mc":[{"id":"1.229554894","rc":[{"atb":[[1.51,0]],"id":70003365}],"con":true,"img":false}]}
{"op":"mcm","clk":"11449938980","pt":1717316161315,"mc":[{"id":"1.229554894","rc":[{"atl":[[2.5,0]],"id":70003367}],"con":true,"img":false}]}
{"op":"mcm","clk":"11449939255","pt":1717316164022,"mc":[{"id":"1.229554894","rc":[{"atb":[[1.9,4.76]],"id":70003365}],"con":true,"img":false}]}
{"op":"mcm","clk":"11449939267","pt":1717316164127,"mc":[{"id":"1.229554894","rc":[{"atb":[[1.91,8.62]],"id":70003365}],"con":true,"img":false}]}
{"op":"mcm","clk":"11449939392","pt":1717316165528,"mc":[{"id":"1.229554894","rc":[{"atl":[[2.5,23.33]],"id":70003365}],"con":true,"img":false}]}
{"op":"mcm","clk":"11449939476","pt":1717316166556,"mc":[{"id":"1.229554894","rc":[{"atl":[[2.56,12.82]],"id":70003367}],"con":true,"img":false}]}
{"op":"mcm","clk":"11449939772","pt":1717316169513,"mc":[{"id":"1.229554894","rc":[{"atl":[[2.5,10]],"id":70003367}],"con":true,"img":false}]}
{"op":"mcm","clk":"11449939781","pt":1717316169617,"mc":[{"id":"1.229554894","rc":[{"atb":[[1.89,2.26],[1.9,0]],"id":70003365},{"atl":[[2.44,10.42]],"id":70003365}],"con":true,"img":false}]}
{"op":"mcm","clk":"11449939790","pt":1717316169720,"mc":[{"id":"1.229554894","rc":[{"atl":[[2.5,0]],"id":70003367},{"atl":[[2.5,13.33],[2.44,12.68]],"id":70003365}],"con":true,"img":false}]}
{"op":"mcm","clk":"11449939992","pt":1717316171953,"mc":[{"id":"1.229554894","rc":[{"atl":[[2.5,10]],"id":70003367}],"con":true,"img":false}]}
{"op":"mcm","clk":"11449940334","pt":1717316175163,"mc":[{"id":"1.229554894","rc":[{"atl":[[2.5,0],[2.48,10.14]],"id":70003367}],"con":true,"img":false}]}
{"op":"mcm","clk":"11449940374","pt":1717316175526,"mc":[{"id":"1.229554894","rc":[{"atl":[[2.48,18.03]],"id":70003365}],"con":true,"img":false}]}
{"op":"mcm","clk":"11449940394","pt":1717316175740,"mc":[{"id":"1.229554894","rc":[{"atl":[[2.5,0],[2.46,0],[2.7,0]],"id":70003365}],"con":true,"img":false}]}
{"op":"mcm","clk":"11449940403","pt":1717316175844,"mc":[{"id":"1.229554894","rc":[{"atl":[[2.5,10],[2.48,0]],"id":70003367}],"con":true,"img":false}]}
{"op":"mcm","clk":"11449940934","pt":1717316181254,"mc":[{"id":"1.229554894","rc":[{"atl":[[2.52,16.45]],"id":70003365}],"con":true,"img":false}]}
{"op":"mcm","clk":"11449940970","pt":1717316181764,"mc":[{"id":"1.229554894","rc":[{"atl":[[2.5,0]],"id":70003367}],"con":true,"img":false}]}
{"op":"mcm","clk":"11449941434","pt":1717316186671,"mc":[{"id":"1.229554894","rc":[{"atb":[[1.89,0],[1.88,2.26]],"id":70003365}],"con":true,"img":false}]}
{"op":"mcm","clk":"11449941467","pt":1717316186984,"mc":[{"id":"1.229554894","rc":[{"atl":[[2.56,19.23]],"id":70003365}],"con":true,"img":false}]}
{"op":"mcm","clk":"11449941511","pt":1717316187455,"mc":[{"id":"1.229554894","rc":[{"atl":[[2.6,15.62]],"id":70003367}],"con":true,"img":false}]}
{"op":"mcm","clk":"11449941874","pt":1717316191554,"mc":[{"id":"1.229554894","rc":[{"atl":[[2.42,10.56],[2.44,2.26]],"id":70003365}],"con":true,"img":false}]}
{"op":"mcm","clk":"11449941935","pt":1717316192186,"mc":[{"id":"1.229554894","rc":[{"atb":[[1.73,0],[1.83,0]],"id":70003367},{"atb":[[1.81,0],[1.91,0]],"id":70003365}],"con":true,"img":false}]}
{"op":"mcm","clk":"11449941955","pt":1717316192393,"mc":[{"id":"1.229554894","rc":[{"atb":[[1.88,0],[1.66,2.26]],"id":70003365}],"con":true,"img":false}]}
{"op":"mcm","clk":"11449942348","pt":1717316196499,"mc":[{"id":"1.229554894","rc":[{"atl":[[2.56,9.62],[2.52,0]],"id":70003367}],"con":true,"img":false}]}
{"op":"mcm","clk":"11449942372","pt":1717316196813,"mc":[{"id":"1.229554894","rc":[{"atl":[[2.56,0],[2.54,0],[2.6,0]],"id":70003367}],"con":true,"img":false}]}
{"op":"mcm","clk":"11449942562","pt":1717316198889,"mc":[{"id":"1.229554894","rc":[{"atb":[[1.42,0]],"id":70003365}],"con":true,"img":false}]}
{"op":"mcm","clk":"11449942625","pt":1717316199665,"mc":[{"id":"1.229554894","rc":[{"atl":[[2.42,0],[2.46,10.27]],"id":70003365}],"con":true,"img":false}]}
{"op":"mcm","clk":"11449942661","pt":1717316200079,"mc":[{"id":"1.229554894","rc":[{"atl":[[2.42,10.56],[2.46,0]],"id":70003365}],"con":true,"img":false}]}
{"op":"mcm","clk":"11449942670","pt":1717316200185,"mc":[{"id":"1.229554894","rc":[{"atl":[[2.42,0],[2.46,10.27]],"id":70003365}],"con":true,"img":false}]}
{"op":"mcm","clk":"11449942740","pt":1717316200986,"mc":[{"id":"1.229554894","rc":[{"atb":[[1.4,0],[1.38,0]],"id":70003365}],"con":true,"img":false}]}
{"op":"mcm","clk":"11449942954","pt":1717316203479,"mc":[{"id":"1.229554894","rc":[{"atl":[[2.46,0],[2.44,12.68]],"id":70003365}],"con":true,"img":false}]}
{"op":"mcm","clk":"11449942970","pt":1717316203588,"mc":[{"id":"1.229554894","rc":[{"atb":[[1.88,8.92],[1.78,10.06]],"id":70003367},{"atb":[[1.88,8.92],[1.78,10.06]],"id":70003365}],"con":true,"img":false}]}
{"op":"mcm","clk":"11449942993","pt":1717316203795,"mc":[{"id":"1.229554894","rc":[{"atb":[[1.79,4.88]],"id":70003365}],"con":true,"img":false}]}
{"op":"mcm","clk":"11449943005","pt":1717316203906,"mc":[{"id":"1.229554894","rc":[{"atb":[[1.89,2.26],[1.66,0]],"id":70003365}],"con":true,"img":false}]}
{"op":"mcm","clk":"11449943076","pt":1717316204572,"mc":[{"id":"1.229554894","rc":[{"atl":[[2.46,10.27],[2.44,2.26]],"id":70003365}],"con":true,"img":false}]}
{"op":"mcm","clk":"11449943096","pt":1717316204777,"mc":[{"id":"1.229554894","rc":[{"atb":[[1.89,4.05]],"id":70003367},{"atl":[[2.42,4.77]],"id":70003365}],"con":true,"img":false}]}
{"op":"mcm","clk":"11449943393","pt":1717316208092,"mc":[{"id":"1.229554894","rc":[{"atl":[[2.56,9.62],[2.6,12.5],[2.64,15.24],[2.68,17.86]],"id":70003367},{"atl":[[2.5,10],[2.46,0]],"id":70003365}],"con":true,"img":false}]}
{"op":"mcm","clk":"11449943407","pt":1717316208293,"mc":[{"id":"1.229554894","rc":[{"atl":[[2.48,4.52]],"id":70003365}],"con":true,"img":false}]}
{"op":"mcm","clk":"11449943594","pt":1717316210781,"mc":[{"id":"1.229554894","rc":[{"atl":[[2.56,0],[2.6,0],[2.64,0]],"id":70003367},{"atl":[[2.44,12.68]],"id":70003365}],"con":true,"img":false}]}
{"op":"mcm","clk":"11449943603","pt":1717316210883,"mc":[{"id":"1.229554894","rc":[{"atb":[[1.69,3.98]],"id":70003367},{"atb":[[1.89,0],[1.88,13.58]],"id":70003365},{"atl":[[2.38,4.66]],"id":70003365}],"con":true,"img":false}]}
{"op":"mcm","clk":"11449943612","pt":1717316210990,"mc":[{"id":"1.229554894","rc":[{"atb":[[1.63,0]],"id":70003367},{"atl":[[2.44,10.42]],"id":70003365}],"con":true,"img":false}]}
{"op":"mcm","clk":"11449943752","pt":1717316212510,"mc":[{"id":"1.229554894","rc":[{"atl":[[2.56,9.62]],"id":70003367},{"atl":[[2.44,0]],"id":70003365}],"con":true,"img":false}]}
{"op":"mcm","clk":"11449943805","pt":1717316212981,"mc":[{"id":"1.229554894","rc":[{"atl":[[2.56,0]],"id":70003367},{"atl":[[2.44,10.42]],"id":70003365}],"con":true,"img":false}]}
{"op":"mcm","clk":"11449943866","pt":1717316213703,"mc":[{"id":"1.229554894","rc":[{"atl":[[2.42,15.33],[2.46,10.27],[2.44,0]],"id":70003365}],"con":true,"img":false}]}
{"op":"mcm","clk":"11449943964","pt":1717316214697,"mc":[{"id":"1.229554894","rc":[{"atl":[[2.56,0],[2.42,4.77],[2.52,0]],"id":70003365}],"con":true,"img":false}]}
{"op":"mcm","clk":"11449944295","pt":1717316218790,"mc":[{"id":"1.229554894","rc":[{"atl":[[2.5,13.33]],"id":70003365}],"con":true,"img":false}]}
{"op":"mcm","clk":"11449944766","pt":1717316223725,"mc":[{"id":"1.229554894","rc":[{"atl":[[2.46,0],[2.48,14.66]],"id":70003365}],"con":true,"img":false}]}
{"op":"mcm","clk":"11449944794","pt":1717316224090,"mc":[{"id":"1.229554894","rc":[{"atb":[[1.84,4.84],[1.88,8.92]],"id":70003365}],"con":true,"img":false}]}
{"op":"mcm","clk":"11449945241","pt":1717316228705,"mc":[{"id":"1.229554894","rc":[{"atl":[[2.52,13.16]],"id":70003365}],"con":true,"img":false}]}
{"op":"mcm","clk":"11449945279","pt":1717316229122,"mc":[{"id":"1.229554894","rc":[{"atb":[[1.84,0],[1.85,4.65]],"id":70003365}],"con":true,"img":false}]}
{"op":"mcm","clk":"11449945671","pt":1717316233538,"mc":[{"id":"1.229554894","rc":[{"atl":[[2.56,16.03]],"id":70003365}],"con":true,"img":false}]}
{"op":"mcm","clk":"11449945965","pt":1717316236761,"mc":[{"id":"1.229554894","rc":[{"atb":[[1.88,0],[1.78,0]],"id":70003367},{"atb":[[1.88,0],[1.78,0]],"id":70003365}],"con":true,"img":false}]}
{"op":"mcm","clk":"11449945975","pt":1717316236818,"mc":[{"id":"1.229554894","rc":[{"atl":[[2.4,10.71],[2.48,4.52]],"id":70003365}],"con":true,"img":false}]}
{"op":"mcm","clk":"11449945985","pt":1717316236924,"mc":[{"id":"1.229554894","rc":[{"atl":[[2.68,0]],"id":70003367},{"atb":[[1.8,4.65],[1.85,0]],"id":70003365}],"con":true,"img":false}]}
{"op":"mcm","clk":"11449946298","pt":1717316239848,"mc":[{"id":"1.229554894","rc":[{"atl":[[2.4,0],[2.46,10.27]],"id":70003365}],"con":true,"img":false}]}
{"op":"mcm","clk":"11449946323","pt":1717316240057,"mc":[{"id":"1.229554894","rc":[{"atl":[[2.38,15.53],[2.46,0]],"id":70003365}],"con":true,"img":false}]}
{"op":"mcm","clk":"11449946337","pt":1717316240165,"mc":[{"id":"1.229554894","rc":[{"atb":[[1.81,4.87]],"id":70003365},{"atl":[[2.36,4.78]],"id":70003365}],"con":true,"img":false}]}
{"op":"mcm","clk":"11449946354","pt":1717316240318,"mc":[{"id":"1.229554894","rc":[{"atb":[[1.8,0],[1.82,4.78]],"id":70003365}],"con":true,"img":false}]}
{"op":"mcm","clk":"11449946418","pt":1717316240957,"mc":[{"id":"1.229554894","rc":[{"atl":[[2.38,4.66],[2.46,10.27]],"id":70003365}],"con":true,"img":false}]}
{"op":"mcm","clk":"11449946763","pt":1717316244843,"mc":[{"id":"1.229554894","rc":[{"atl":[[2.42,15.33],[2.46,0]],"id":70003365}],"con":true,"img":false}]}
{"op":"mcm","clk":"11449946888","pt":1717316246350,"mc":[{"id":"1.229554894","rc":[{"atl":[[2.42,4.77],[2.38,15.53]],"id":70003365}],"con":true,"img":false}]}
{"op":"mcm","clk":"11449946987","pt":1717316247355,"mc":[{"id":"1.229554894","rc":[{"atl":[[2.38,4.66],[2.46,10.27]],"id":70003365}],"con":true,"img":false}]}
{"op":"mcm","clk":"11449947457","pt":1717316251960,"mc":[{"id":"1.229554894","rc":[{"atl":[[2.42,15.33],[2.46,0]],"id":70003365}],"con":true,"img":false}]}
{"op":"mcm","clk":"11449947691","pt":1717316254557,"mc":[{"id":"1.229554894","rc":[{"atl":[[2.4,10.71],[2.42,4.77]],"id":70003365}],"con":true,"img":false}]}
{"op":"mcm","clk":"11449947834","pt":1717316256144,"mc":[{"id":"1.229554894","rc":[{"atl":[[2.4,0],[2.42,15.33]],"id":70003365}],"con":true,"img":false}]}
{"op":"mcm","clk":"11449947846","pt":1717316256347,"mc":[{"id":"1.229554894","rc":[{"atl":[[2.44,10.42]],"id":70003365}],"con":true,"img":false}]}
{"op":"mcm","clk":"11449947856","pt":1717316256452,"mc":[{"id":"1.229554894","rc":[{"atl":[[2.42,4.77]],"id":70003365}],"con":true,"img":false}]}
{"op":"mcm","clk":"11449948066","pt":1717316259140,"mc":[{"id":"1.229554894","rc":[{"atl":[[6.2,0],[5.5,15.2],[2.38,15.53],[2.44,0]],"id":70003365}],"con":true,"img":false}]}
{"op":"mcm","clk":"11449948350","pt":1717316262049,"mc":[{"id":"1.229554894","rc":[{"atl":[[2.32,4.78],[2.38,10.87]],"id":70003365}],"con":true,"img":false}]}
{"op":"mcm","clk":"11449948468","pt":1717316263448,"mc":[{"id":"1.229554894","rc":[{"atl":[[2.42,18.85]],"id":70003365}],"con":true,"img":false}]}
{"op":"mcm","clk":"11449948492","pt":1717316263760,"mc":[{"id":"1.229554894","rc":[{"atl":[[2.56,0],[2.52,0]],"id":70003365}],"con":true,"img":false}]}
{"op":"mcm","clk":"11449948623","pt":1717316265361,"mc":[{"id":"1.229554894","rc":[{"atb":[[1.82,0],[1.8,2.39]],"id":70003365},{"atl":[[2.32,16.14]],"id":70003365}],"con":true,"img":false}]}
{"op":"mcm","clk":"11449948685","pt":1717316266390,"mc":[{"id":"1.229554894","rc":[{"atl":[[2.3,4.8]],"id":70003365}],"con":true,"img":false}]}
{"op":"mcm","clk":"11449948753","pt":1717316267166,"mc":[{"id":"1.229554894","rc":[{"atl":[[2.34,4.79]],"id":70003365}],"con":true,"img":false}]}
{"op":"mcm","clk":"11449948760","pt":1717316267269,"mc":[{"id":"1.229554894","rc":[{"atl":[[2.32,11.36]],"id":70003365}],"con":true,"img":false}]}
{"op":"mcm","clk":"11449948937","pt":1717316269853,"mc":[{"id":"1.229554894","rc":[{"atb":[[1.81,0]],"id":70003365}],"con":true,"img":false}]}
{"op":"mcm","clk":"11449948970","pt":1717316270369,"mc":[{"id":"1.229554894","rc":[{"atb":[[1.81,9.68],[1.91,8.62]],"id":70003367},{"atb":[[1.84,9.34],[1.74,10.6]],"id":70003365}],"con":true,"img":false}]}
{"op":"mcm","clk":"11449949267","pt":1717316274004,"mc":[{"id":"1.229554894","rc":[{"atl":[[2.36,15.81]],"id":70003365}],"con":true,"img":false}]}
{"op":"mcm","clk":"11449949275","pt":1717316274108,"mc":[{"id":"1.229554894","rc":[{"atl":[[2.32,0]],"id":70003365}],"con":true,"img":false}]}
{"op":"mcm","clk":"11449949285","pt":1717316274213,"mc":[{"id":"1.229554894","rc":[{"atl":[[2.5,0],[2.42,4.77],[2.38,0]],"id":70003365}],"con":true,"img":false}]}
{"op":"mcm","clk":"11449949412","pt":1717316275866,"mc":[{"id":"1.229554894","rc":[{"atl":[[2.34,15.98]],"id":70003365}],"con":true,"img":false}]}
{"op":"mcm","clk":"11449949461","pt":1717316276486,"mc":[{"id":"1.229554894","rc":[{"atl":[[2.32,11.36]],"id":70003365}],"con":true,"img":false}]}
{"op":"mcm","clk":"11449949496","pt":1717316276900,"mc":[{"id":"1.229554894","rc":[{"atb":[[1.81,4.87]],"id":70003365}],"con":true,"img":false}]}
{"op":"mcm","clk":"11449949617","pt":1717316278297,"mc":[{"id":"1.229554894","rc":[{"atl":[[2.32,0]],"id":70003365}],"con":true,"img":false}]}
{"op":"mcm","clk":"11449949640","pt":1717316278602,"mc":[{"id":"1.229554894","rc":[{"atl":[[2.34,4.79]],"id":70003365}],"con":true,"img":false}]}
{"op":"mcm","clk":"11449949773","pt":1717316280613,"mc":[{"id":"1.229554894","rc":[{"atl":[[2.4,14.29]],"id":70003365}],"con":true,"img":false}]}
{"op":"mcm","clk":"11449949873","pt":1717316282222,"mc":[{"id":"1.229554894","rc":[{"atb":[[1.8,0]],"id":70003365},{"atl":[[2.34,15.98]],"id":70003365}],"con":true,"img":false}]}
{"op":"mcm","clk":"11449949885","pt":1717316282324,"mc":[{"id":"1.229554894","rc":[{"atb":[[1.92,3.98],[1.51,36.59],[1.69,0]],"id":70003367},{"atl":[[6,0],[2.64,9.8]],"id":70003367},{"atb":[[1.56,96.25],[1.81,9.66]],"id":70003365},{"atl":[[5.5,0],[2.64,9.59],[2.26,4.79],[2.34,11.19]],"id":70003365}],"con":true,"img":false}]}
{"op":"mcm","clk":"11449949974","pt":1717316283313,"mc":[{"id":"1.229554894","rc":[{"atl":[[2.34,0]],"id":70003365}],"con":true,"img":false}]}
{"op":"mcm","clk":"11449950214","pt":1717316286218,"mc":[{"id":"1.229554894","rc":[{"atl":[[2.44,17.36]],"id":70003365}],"con":true,"img":false}]}
{"op":"mcm","clk":"11449950231","pt":1717316286375,"mc":[{"id":"1.229554894","rc":[{"atb":[[1.64,0],[1.82,4.8]],"id":70003365}],"con":true,"img":false}]}
{"op":"mcm","clk":"11449950305","pt":1717316287406,"mc":[{"id":"1.229554894","rc":[{"atb":[[1.64,36.59],[1.92,0],[1.91,12.52],[1.51,0]],"id":70003367},{"atl":[[2.5,9.6],[2.64,0]],"id":70003365}],"con":true,"img":false}]}
{"op":"mcm","clk":"11449950537","pt":1717316290094,"mc":[{"id":"1.229554894","rc":[{"atl":[[2.48,24.79]],"id":70003365}],"con":true,"img":false}]}
{"op":"mcm","clk":"11449951307","pt":1717316298991,"mc":[{"id":"1.229554894","rc":[{"atb":[[1.89,8.03]],"id":70003367},{"atl":[[2.38,10.87]],"id":70003365}],"con":true,"img":false}]}
{"op":"mcm","clk":"11449951315","pt":1717316299093,"mc":[{"id":"1.229554894","rc":[{"atb":[[1.91,8.62]],"id":70003367},{"atl":[[2.36,4.78]],"id":70003365}],"con":true,"img":false}]}
{"op":"mcm","clk":"11449951712","pt":1717316303538,"mc":[{"id":"1.229554894","rc":[{"atb":[[1.8,4.8]],"id":70003365},{"atl":[[2.5,0],[2.32,11.36],[2.46,9.6]],"id":70003365}],"con":true,"img":false}]}
{"op":"mcm","clk":"11449951723","pt":1717316303641,"mc":[{"id":"1.229554894","rc":[{"atb":[[1.81,4.87]],"id":70003365},{"atl":[[2.38,0]],"id":70003365}],"con":true,"img":false}]}
{"op":"mcm","clk":"11449951730","pt":1717316303700,"mc":[{"id":"1.229554894","rc":[{"atb":[[1.92,4.15]],"id":70003367},{"atl":[[2.24,4.65],[2.48,20.27]],"id":70003365}],"con":true,"img":false}]}
{"op":"mcm","clk":"11449951740","pt":1717316303804,"mc":[{"id":"1.229554894","rc":[{"atl":[[2.22,4.8],[2.26,0]],"id":70003365}],"con":true,"img":false}]}
{"op":"mcm","clk":"11449951761","pt":1717316304008,"mc":[{"id":"1.229554894","rc":[{"atb":[[1.81,9.67]],"id":70003365},{"atl":[[2.32,0],[2.34,11.19]],"id":70003365}],"con":true,"img":false}]}
{"op":"mcm","clk":"11449951780","pt":1717316304110,"mc":[{"id":"1.229554894","rc":[{"atb":[[1.92,8.13],[1.89,4.05]],"id":70003367},{"atb":[[1.8,0]],"id":70003365}],"con":true,"img":false}]}
{"op":"mcm","clk":"11449952015","pt":1717316306921,"mc":[{"id":"1.229554894","rc":[{"atb":[[1.81,0],[1.91,0]],"id":70003367},{"atb":[[1.84,0],[1.74,0]],"id":70003365}],"con":true,"img":false}]}
{"op":"mcm","clk":"11449952237","pt":1717316309153,"mc":[{"id":"1.229554894","rc":[{"atb":[[1.81,4.87],[1.77,4.8]],"id":70003365},{"atl":[[2.28,11.72],[2.34,0]],"id":70003365}],"con":true,"img":false}]}
{"op":"mcm","clk":"11449952298","pt":1717316309937,"mc":[{"id":"1.229554894","rc":[{"atb":[[1.93,4.04]],"id":70003367},{"atl":[[2.34,11.19],[2.42,0],[2.2,4.79]],"id":70003365}],"con":true,"img":false}]}
{"op":"mcm","clk":"11449952309","pt":1717316310037,"mc":[{"id":"1.229554894","rc":[{"atl":[[2.22,0],[2.28,0],[2.18,4.8]],"id":70003365}],"con":true,"img":false}]}
{"op":"mcm","clk":"11449952317","pt":1717316310153,"mc":[{"id":"1.229554894","rc":[{"atb":[[1.64,0],[1.72,3.98],[1.92,4.15],[1.57,36.59]],"id":70003367},{"atl":[[2.3,9.6]],"id":70003365}],"con":true,"img":false}]}
{"op":"mcm","clk":"11449952326","pt":1717316310246,"mc":[{"id":"1.229554894","rc":[{"atl":[[2.18,0]],"id":70003365}],"con":true,"img":false}]}
{"op":"mcm","clk":"11449952634","pt":1717316313814,"mc":[{"id":"1.229554894","rc":[{"atl":[[2.28,11.72],[2.34,0]],"id":70003365}],"con":true,"img":false}]}
{"op":"mcm","clk":"11449952661","pt":1717316314129,"mc":[{"id":"1.229554894","rc":[{"atl":[[2.28,0],[2.34,11.19]],"id":70003365}],"con":true,"img":false}]}
{"op":"mcm","clk":"11449952766","pt":1717316315262,"mc":[{"id":"1.229554894","rc":[{"atl":[[2.3,4.8],[2.28,4.8]],"id":70003365}],"con":true,"img":false}]}
{"op":"mcm","clk":"11449952782","pt":1717316315424,"mc":[{"id":"1.229554894","rc":[{"atb":[[1.82,0]],"id":70003365}],"con":true,"img":false}]}
{"op":"mcm","clk":"11449952789","pt":1717316315539,"mc":[{"id":"1.229554894","rc":[{"atb":[[1.75,4.73]],"id":70003365}],"con":true,"img":false}]}
{"op":"mcm","clk":"11449952794","pt":1717316315647,"mc":[{"id":"1.229554894","rc":[{"atb":[[2.06,7.4],[1.93,12.48]],"id":70003367},{"atb":[[1.56,110.26],[1.77,0],[1.66,11.89]],"id":70003365}],"con":true,"img":false}]}
{"op":"mcm","clk":"11449952931","pt":1717316317248,"mc":[{"id":"1.229554894","rc":[{"atl":[[2.26,11.9],[2.34,0]],"id":70003365}],"con":true,"img":false}]}
{"op":"mcm","clk":"11449952997","pt":1717316318065,"mc":[{"id":"1.229554894","rc":[{"atl":[[2.4,0],[2.44,0],[2.26,0]],"id":70003365}],"con":true,"img":false}]}
{"op":"mcm","clk":"11449953147","pt":1717316319848,"mc":[{"id":"1.229554894","rc":[{"atl":[[2.64,0],[2.76,11.82]],"id":70003367}],"con":true,"img":false}]}
{"op":"mcm","clk":"11449953204","pt":1717316320468,"mc":[{"id":"1.229554894","rc":[{"atl":[[2.36,15.81]],"id":70003365}],"con":true,"img":false}]}
{"op":"mcm","clk":"11449953305","pt":1717316321551,"mc":[{"id":"1.229554894","rc":[{"atl":[[2.36,4.78]],"id":70003365}],"con":true,"img":false}]}
{"op":"mcm","clk":"11449953351","pt":1717316322067,"mc":[{"id":"1.229554894","rc":[{"atb":[[1.84,0],[2.08,4]],"id":70003367}],"con":true,"img":false}]}
{"op":"mcm","clk":"11449953413","pt":1717316322752,"mc":[{"id":"1.229554894","rc":[{"atb":[[1.9,33.14]],"id":70003367}],"con":true,"img":false}]}
{"op":"mcm","clk":"11449953839","pt":1717316327861,"mc":[{"id":"1.229554894","rc":[{"atb":[[1.81,0]],"id":70003365}],"con":true,"img":false}]}
{"op":"mcm","clk":"11449953880","pt":1717316328271,"mc":[{"id":"1.229554894","rc":[{"atb":[[1.9,0]],"id":70003367}],"con":true,"img":false}]}
{"op":"mcm","clk":"11449954256","pt":1717316333078,"mc":[{"id":"1.229554894","rc":[{"atl":[[2.38,10.87]],"id":70003365}],"con":true,"img":false}]}
{"op":"mcm","clk":"11449954298","pt":1717316333693,"mc":[{"id":"1.229554894","rc":[{"atl":[[2.38,0]],"id":70003365}],"con":true,"img":false}]}
{"op":"mcm","clk":"11449954305","pt":1717316333796,"mc":[{"id":"1.229554894","rc":[{"atb":[[1.75,0],[1.76,10]],"id":70003365},{"atl":[[2.28,0],[2.34,10]],"id":70003365}],"con":true,"img":false}]}
{"op":"mcm","clk":"11449954333","pt":1717316334164,"mc":[{"id":"1.229554894","rc":[{"atb":[[1.9,33.14]],"id":70003367}],"con":true,"img":false}]}
{"op":"mcm","clk":"11449954409","pt":1717316335188,"mc":[{"id":"1.229554894","rc":[{"atb":[[1.75,10],[1.76,0]],"id":70003365},{"atl":[[2.28,10],[2.34,0]],"id":70003365}],"con":true,"img":false}]}
{"op":"mcm","clk":"11449954461","pt":1717316335965,"mc":[{"id":"1.229554894","rc":[{"atb":[[1.62,36.59],[1.57,0]],"id":70003367},{"atb":[[1.74,10],[1.75,0]],"id":70003365}],"con":true,"img":false}]}
{"op":"mcm","clk":"11449954483","pt":1717316336270,"mc":[{"id":"1.229554894","rc":[{"atl":[[2.38,10.87]],"id":70003365}],"con":true,"img":false}]}
{"op":"mcm","clk":"11449954633","pt":1717316337968,"mc":[{"id":"1.229554894","rc":[{"atb":[[1.79,0]],"id":70003365},{"trd":[[1.79,9.77]],"ltp":1.79,"tv":9.77,"id":70003365},{"atl":[[1.79,20.11]],"id":70003365}],"con":true,"img":false}]}
{"op":"mcm","clk":"11449954642","pt":1717316338074,"mc":[{"id":"1.229554894","rc":[{"atb":[[1.74,0],[1.67,10]],"id":70003365},{"trd":[[1.79,49.99]],"ltp":1.79,"tv":49.99,"id":70003365},{"atl":[[1.79,0]],"id":70003365}],"con":true,"img":false}]}
{"op":"mcm","clk":"11449954652","pt":1717316338171,"mc":[{"id":"1.229554894","rc":[{"atb":[[1.9,0],[2.08,31.62]],"id":70003367},{"atb":[[1.56,14.01],[1.51,96.25]],"id":70003365},{"atl":[[1.92,10.71]],"id":70003365}],"con":true,"img":false}]}
{"op":"mcm","clk":"11449954693","pt":1717316338787,"mc":[{"id":"1.229554894","rc":[{"atb":[[2.08,4]],"id":70003367}],"con":true,"img":false}]}
{"op":"mcm","clk":"11449954722","pt":1717316339198,"mc":[{"id":"1.229554894","rc":[{"atb":[[1.94,31.72]],"id":70003367}],"con":true,"img":false}]}
{"op":"mcm","clk":"11449954920","pt":1717316341378,"mc":[{"id":"1.229554894","rc":[{"atl":[[2.4,10.73]],"id":70003367},{"atl":[[1.94,10.77]],"id":70003365}],"con":true,"img":false}]}
{"op":"mcm","clk":"11449954941","pt":1717316341683,"mc":[{"id":"1.229554894","rc":[{"atb":[[1.94,0],[2.08,31.62]],"id":70003367},{"atb":[[1.67,54.51]],"id":70003365},{"atl":[[2.36,0],[1.91,4.93]],"id":70003365}],"con":true,"img":false}]}
{"op":"mcm","clk":"11449954952","pt":1717316341789,"mc":[{"id":"1.229554894","rc":[{"atb":[[1.68,4.95]],"id":70003365}],"con":true,"img":false}]}
{"op":"mcm","clk":"11449954963","pt":1717316341991,"mc":[{"id":"1.229554894","rc":[{"atb":[[1.89,0],[2.1,3.94]],"id":70003367},{"atb":[[1.67,44.51],[1.69,21.48]],"id":70003365}],"con":true,"img":false}]}
{"op":"mcm","clk":"11449954968","pt":1717316342093,"mc":[{"id":"1.229554894","rc":[{"atl":[[2.36,0.78]],"id":70003367},{"atl":[[1.9,0.78]],"id":70003365}],"con":true,"img":false}]}
{"op":"mcm","clk":"11449955003","pt":1717316342667,"mc":[{"id":"1.229554894","rc":[{"atl":[[2.36,0.42]],"id":70003367},{"atl":[[1.9,0.47]],"id":70003365}],"con":true,"img":false}]}
{"op":"mcm","clk":"11449955059","pt":1717316343280,"mc":[{"id":"1.229554894","rc":[{"atl":[[2.36,0]],"id":70003367},{"atb":[[1.7,42.6]],"id":70003365},{"atl":[[1.9,0]],"id":70003365}],"con":true,"img":false}]}
{"op":"mcm","clk":"11449955068","pt":1717316343383,"mc":[{"id":"1.229554894","rc":[{"atl":[[1000,0.59]],"id":70003367},{"atl":[[1000,0.47]],"id":70003365}],"con":true,"img":false}]}
{"op":"mcm","clk":"11449955148","pt":1717316344366,"mc":[{"id":"1.229554894","rc":[{"trd":[[2.38,3.77]],"ltp":2.38,"tv":3.77,"id":70003367},{"atl":[[2.38,2.12]],"id":70003367},{"trd":[[1.72,5.23]],"ltp":1.72,"tv":5.23,"id":70003365}],"con":true,"img":false}]}
{"op":"mcm","clk":"11449955162","pt":1717316344570,"mc":[{"id":"1.229554894","rc":[{"atl":[[2.36,8.79],[2.68,12.87],[2.76,0]],"id":70003367},{"atb":[[1.55,96.25],[1.51,0]],"id":70003365},{"atl":[[1.9,10.83]],"id":70003365}],"con":true,"img":false}]}
{"op":"mcm","clk":"11449955169","pt":1717316344675,"mc":[{"id":"1.229554894","rc":[{"atb":[[1.7,0],[1.69,64.7]],"id":70003365}],"con":true,"img":false}]}
{"op":"mcm","clk":"11449955179","pt":1717316344779,"mc":[{"id":"1.229554894","rc":[{"atl":[[2.34,3.93]],"id":70003367},{"atb":[[1.71,4.93]],"id":70003365}],"con":true,"img":false}]}
{"op":"mcm","clk":"11449955254","pt":1717316345706,"mc":[{"id":"1.229554894","rc":[{"atl":[[2.38,0]],"id":70003365}],"con":true,"img":false}]}
{"op":"mcm","clk":"11449955353","pt":1717316347096,"mc":[{"id":"1.229554894","rc":[{"atb":[[1.72,15.66],[1.69,43.22]],"id":70003365}],"con":true,"img":false}]}
{"op":"mcm","clk":"11449955404","pt":1717316347669,"mc":[{"id":"1.229554894","rc":[{"atb":[[1.72,57.08]],"id":70003365}],"con":true,"img":false}]}
{"op":"mcm","clk":"11449955419","pt":1717316347974,"mc":[{"id":"1.229554894","rc":[{"atl":[[2.38,9.98]],"id":70003367}],"con":true,"img":false}]}
{"op":"mcm","clk":"11449955710","pt":1717316352219,"mc":[{"id":"1.229554894","rc":[{"atl":[[2.62,18.78],[2.68,0]],"id":70003367},{"atb":[[1.55,0],[1.58,96.25]],"id":70003365},{"atl":[[2.58,19.6],[2.46,0]],"id":70003365}],"con":true,"img":false}]}
{"op":"mcm","clk":"11449955742","pt":1717316352586,"mc":[{"id":"1.229554894","rc":[{"atb":[[1.73,4.88]],"id":70003365}],"con":true,"img":false}]}
{"op":"mcm","clk":"11449955749","pt":1717316352683,"mc":[{"id":"1.229554894","rc":[{"atb":[[1.72,41.42],[1.74,15.65]],"id":70003365}],"con":true,"img":false}]}
{"op":"mcm","clk":"11449955760","pt":1717316352893,"mc":[{"id":"1.229554894","rc":[{"atb":[[1.65,0],[1.75,4.85]],"id":70003365}],"con":true,"img":false}]}
{"op":"mcm","clk":"11449955769","pt":1717316352994,"mc":[{"id":"1.229554894","rc":[{"atb":[[1.76,10]],"id":70003365}],"con":true,"img":false}]}
{"op":"mcm","clk":"11449955778","pt":1717316353098,"mc":[{"id":"1.229554894","rc":[{"atb":[[1.74,0]],"id":70003365}],"con":true,"img":false}]}
{"op":"mcm","clk":"11449955785","pt":1717316353200,"mc":[{"id":"1.229554894","rc":[{"atb":[[1.67,0]],"id":70003365}],"con":true,"img":false}]}
{"op":"mcm","clk":"11449956182","pt":1717316358725,"mc":[{"id":"1.229554894","rc":[{"atb":[[1.56,36.59]],"id":70003367}],"con":true,"img":false}]}
{"op":"mcm","clk":"11449956190","pt":1717316358829,"mc":[{"id":"1.229554894","rc":[{"atb":[[1.62,0]],"id":70003367}],"con":true,"img":false}]}
{"op":"mcm","clk":"11449956199","pt":1717316358932,"mc":[{"id":"1.229554894","rc":[{"atb":[[1.68,0],[1.77,4.84]],"id":70003365}],"con":true,"img":false}]}
{"op":"mcm","clk":"11449956205","pt":1717316359035,"mc":[{"id":"1.229554894","rc":[{"atb":[[1.78,10]],"id":70003365}],"con":true,"img":false}]}
{"op":"mcm","clk":"11449956213","pt":1717316359137,"mc":[{"id":"1.229554894","rc":[{"atb":[[1.76,0]],"id":70003365}],"con":true,"img":false}]}
{"op":"mcm","clk":"11449956225","pt":1717316359242,"mc":[{"id":"1.229554894","rc":[{"atb":[[1.74,40.3]],"id":70003365}],"con":true,"img":false}]}
{"op":"mcm","clk":"11449956376","pt":1717316361247,"mc":[{"id":"1.229554894","rc":[{"atb":[[2.1,0]],"id":70003367},{"atl":[[2.32,6.78]],"id":70003367},{"atl":[[1.91,0]],"id":70003365}],"con":true,"img":false}]}
{"op":"mcm","clk":"11449956392","pt":1717316361450,"mc":[{"id":"1.229554894","rc":[{"atl":[[1.9,0]],"id":70003365}],"con":true,"img":false}]}
{"op":"mcm","clk":"11449956596","pt":1717316363931,"mc":[{"id":"1.229554894","rc":[{"atl":[[1.95,4.15]],"id":70003365}],"con":true,"img":false}]}
{"op":"mcm","clk":"11449956932","pt":1717316368361,"mc":[{"id":"1.229554894","rc":[{"atl":[[1.95,6.82]],"id":70003365}],"con":true,"img":false}]}
{"op":"mcm","clk":"11449957645","pt":1717316377784,"mc":[{"id":"1.229554894","rc":[{"atl":[[2.32,0]],"id":70003367}],"con":true,"img":false}]}
{"op":"mcm","clk":"11449957667","pt":1717316378042,"mc":[{"id":"1.229554894","rc":[{"atb":[[1.56,0],[1.61,36.59]],"id":70003367}],"con":true,"img":false}]}
{"op":"mcm","clk":"11449957686","pt":1717316378357,"mc":[{"id":"1.229554894","rc":[{"atl":[[1.92,13.39]],"id":70003365}],"con":true,"img":false}]}
{"op":"mcm","clk":"11449957909","pt":1717316381194,"mc":[{"id":"1.229554894","rc":[{"atl":[[2.32,11.27]],"id":70003367},{"atl":[[1.94,13.39]],"id":70003365}],"con":true,"img":false}]}
{"op":"mcm","clk":"11449957939","pt":1717316381565,"mc":[{"id":"1.229554894","rc":[{"atl":[[2.4,3.88]],"id":70003367}],"con":true,"img":false}]}
{"op":"mcm","clk":"11449957986","pt":1717316382391,"mc":[{"id":"1.229554894","rc":[{"atl":[[1.8,16.48]],"id":70003365}],"con":true,"img":false}]}
{"op":"mcm","clk":"11449957999","pt":1717316382498,"mc":[{"id":"1.229554894","rc":[{"atb":[[2.1,3.92]],"id":70003367},{"trd":[[1.8,19.73]],"ltp":1.8,"tv":19.73,"id":70003365},{"atl":[[1.8,6.61],[1.91,4.95]],"id":70003365}],"con":true,"img":false}]}
{"op":"mcm","clk":"11449958011","pt":1717316382658,"mc":[{"id":"1.229554894","rc":[{"trd":[[1.8,32.97]],"ltp":1.8,"tv":32.97,"id":70003365},{"atl":[[1.8,0]],"id":70003365}],"con":true,"img":false}]}
{"op":"mcm","clk":"11449958095","pt":1717316383585,"mc":[{"id":"1.229554894","rc":[{"atl":[[1.9,13.47]],"id":70003365}],"con":true,"img":false}]}
{"op":"mcm","clk":"11449958113","pt":1717316383792,"mc":[{"id":"1.229554894","rc":[{"atl":[[1.9,0]],"id":70003365}],"con":true,"img":false}]}
{"op":"mcm","clk":"11449958127","pt":1717316384048,"mc":[{"id":"1.229554894","rc":[{"atl":[[2.3,3.88]],"id":70003367},{"atb":[[1.71,0]],"id":70003365}],"con":true,"img":false}]}
{"op":"mcm","clk":"11449958130","pt":1717316384151,"mc":[{"id":"1.229554894","rc":[{"atb":[[1.78,15.02]],"id":70003365}],"con":true,"img":false}]}
{"op":"mcm","clk":"11449958136","pt":1717316384254,"mc":[{"id":"1.229554894","rc":[{"atb":[[1.69,0]],"id":70003365}],"con":true,"img":false}]}
{"op":"mcm","clk":"11449958147","pt":1717316384356,"mc":[{"id":"1.229554894","rc":[{"atb":[[1.78,10]],"id":70003365}],"con":true,"img":false}]}
{"op":"mcm","clk":"11449958267","pt":1717316385966,"mc":[{"id":"1.229554894","rc":[{"atl":[[1.9,13.47]],"id":70003365}],"con":true,"img":false}]}
{"op":"mcm","clk":"11449958287","pt":1717316386272,"mc":[{"id":"1.229554894","rc":[{"atb":[[1.76,39.24]],"id":70003365}],"con":true,"img":false}]}
{"op":"mcm","clk":"11449958300","pt":1717316386589,"mc":[{"id":"1.229554894","rc":[{"atl":[[1.95,0]],"id":70003365}],"con":true,"img":false}]}
{"op":"mcm","clk":"11449958365","pt":1717316387465,"mc":[{"id":"1.229554894","rc":[{"atl":[[2.3,0],[1.89,5.01]],"id":70003365}],"con":true,"img":false}]}
{"op":"mcm","clk":"11449958423","pt":1717316388278,"mc":[{"id":"1.229554894","rc":[{"atl":[[2.28,11.27]],"id":70003367}],"con":true,"img":false}]}
{"op":"mcm","clk":"11449958446","pt":1717316388588,"mc":[{"id":"1.229554894","rc":[{"atl":[[2.38,2.12]],"id":70003367}],"con":true,"img":false}]}
{"op":"mcm","clk":"11449958614","pt":1717316391067,"mc":[{"id":"1.229554894","rc":[{"atb":[[1.78,9.51]],"id":70003365},{"trd":[[1.78,0.97]],"ltp":1.78,"tv":0.97,"id":70003365}],"con":true,"img":false}]}
{"op":"mcm","clk":"11449958645","pt":1717316391582,"mc":[{"id":"1.229554894","rc":[{"atl":[[2.3,0]],"id":70003367},{"atb":[[1.77,0]],"id":70003365}],"con":true,"img":false}]}
{"op":"mcm","clk":"11449958791","pt":1717316393192,"mc":[{"id":"1.229554894","rc":[{"atl":[[2.58,0],[2.46,19.6]],"id":70003365}],"con":true,"img":false}]}
{"op":"mcm","clk":"11449959192","pt":1717316398326,"mc":[{"id":"1.229554894","rc":[{"atb":[[2.06,0],[1.93,4.04]],"id":70003367},{"atb":[[1.56,0],[1.66,0]],"id":70003365}],"con":true,"img":false}]}
{"op":"mcm","clk":"11449959210","pt":1717316398480,"mc":[{"id":"1.229554894","rc":[{"atl":[[1.9,0]],"id":70003365}],"con":true,"img":false}]}
{"op":"mcm","clk":"11449959215","pt":1717316398585,"mc":[{"id":"1.229554894","rc":[{"atb":[[1.66,36.59]],"id":70003367}],"con":true,"img":false}]}
{"op":"mcm","clk":"11449959222","pt":1717316398687,"mc":[{"id":"1.229554894","rc":[{"atb":[[1.61,0]],"id":70003367}],"con":true,"img":false}]}
{"op":"mcm","clk":"11449959285","pt":1717316399423,"mc":[{"id":"1.229554894","rc":[{"atl":[[2.34,0]],"id":70003367},{"atb":[[1.75,0]],"id":70003365}],"con":true,"img":false}]}
{"op":"mcm","clk":"11449959305","pt":1717316399630,"mc":[{"id":"1.229554894","rc":[{"atl":[[2.36,12.55]],"id":70003367}],"con":true,"img":false}]}
{"op":"mcm","clk":"11449959329","pt":1717316399793,"mc":[{"id":"1.229554894","rc":[{"atl":[[2.36,8.79]],"id":70003367}],"con":true,"img":false}]}
{"op":"mcm","clk":"11449959349","pt":1717316399994,"mc":[{"id":"1.229554894","rc":[{"atl":[[2.32,0],[2.28,0]],"id":70003367}],"con":true,"img":false}]}
{"op":"mcm","clk":"11449959365","pt":1717316400206,"mc":[{"id":"1.229554894","rc":[{"atl":[[2.38,0]],"id":70003367},{"atb":[[1.73,0]],"id":70003365}],"con":true,"img":false}]}
{"op":"mcm","clk":"11449959375","pt":1717316400316,"mc":[{"id":"1.229554894","rc":[{"atb":[[1.72,0],[1.74,0],[1.76,0]],"id":70003365}],"con":true,"img":false}]}
{"op":"mcm","clk":"11449959396","pt":1717316400521,"mc":[{"id":"1.229554894","rc":[{"atl":[[2.38,10.02]],"id":70003367},{"atb":[[1.58,0],[1.13,105.76]],"id":70003365},{"atl":[[1.88,12.11]],"id":70003365}],"con":true,"img":false}]}
{"op":"mcm","clk":"11449959405","pt":1717316400575,"mc":[{"id":"1.229554894","rc":[{"atl":[[2.4,0]],"id":70003367},{"atb":[[1.36,41.38],[1.32,77.6],[1.3,99.32],[1.34,58.42]],"id":70003365}],"con":true,"img":false}]}
{"op":"mcm","clk":"11449959413","pt":1717316400677,"mc":[{"id":"1.229554894","rc":[{"atb":[[1.36,142.38],[1.78,4.09],[1.13,0]],"id":70003365},{"trd":[[1.78,11.81]],"ltp":1.78,"tv":11.81,"id":70003365},{"atl":[[1.87,5.31],[2.24,0],[1.88,0]],"id":70003365}],"con":true,"img":false}]}
{"op":"mcm","clk":"11449959420","pt":1717316400784,"mc":[{"id":"1.229554894","rc":[{"atl":[[2.6,3.67]],"id":70003367},{"atb":[[1.36,180.64],[1.45,10],[1.78,0],[1.62,48.1]],"id":70003365},{"atl":[[1.87,6.72]],"id":70003365}],"con":true,"img":false}]}
{"op":"mcm","clk":"11449959427","pt":1717316400889,"mc":[{"id":"1.229554894","rc":[{"atl":[[2.36,0],[2.38,0]],"id":70003367},{"atb":[[1.36,38.26],[1.63,5.34],[1.37,5.34],[1.53,96.2]],"id":70003365}],"con":true,"img":false}]}
{"op":"mcm","clk":"11449959433","pt":1717316400992,"mc":[{"id":"1.229554894","rc":[{"atl":[[2.72,22.46],[2.62,0]],"id":70003367}],"con":true,"img":false}]}
{"op":"mcm","clk":"11449959452","pt":1717316401204,"mc":[{"id":"1.229554894","rc":[{"atl":[[1000,0]],"id":70003365}],"con":true,"img":false}]}
{"op":"mcm","clk":"11449959457","pt":1717316401300,"mc":[{"id":"1.229554894","rc":[{"atb":[[1.62,0]],"id":70003365},{"atl":[[1.86,0.47]],"id":70003365}],"con":true,"img":false}]}
{"op":"mcm","clk":"11449959463","pt":1717316401406,"mc":[{"id":"1.229554894","rc":[{"atb":[[2.1,4.77]],"id":70003367},{"atb":[[1.63,6.19]],"id":70003365}],"con":true,"img":false}]}
{"op":"mcm","clk":"11449959468","pt":1717316401510,"mc":[{"id":"1.229554894","rc":[{"atb":[[2.12,1.64]],"id":70003367}],"con":true,"img":false}]}
{"op":"mcm","clk":"11449959491","pt":1717316401768,"mc":[{"id":"1.229554894","rc":[{"atb":[[1.59,50.54]],"id":70003365}],"con":true,"img":false}]}
{"op":"mcm","clk":"11449959524","pt":1717316402184,"mc":[{"id":"1.229554894","rc":[{"atb":[[1.92,0],[2.12,5.38]],"id":70003367},{"atl":[[1.86,5.71],[2.2,0]],"id":70003365}],"con":true,"img":false}]}
{"op":"mcm","clk":"11449959549","pt":1717316402495,"mc":[{"id":"1.229554894","rc":[{"atb":[[1.36,0],[1.34,0]],"id":70003365}],"con":true,"img":false}]}
{"op":"mcm","clk":"11449959560","pt":1717316402600,"mc":[{"id":"1.229554894","rc":[{"atb":[[2.1,4.46]],"id":70003367},{"atb":[[1.63,5.89]],"id":70003365}],"con":true,"img":false}]}
{"op":"mcm","clk":"11449959569","pt":1717316402708,"mc":[{"id":"1.229554894","rc":[{"atl":[[2.58,18.08]],"id":70003367},{"atl":[[1.85,24.66]],"id":70003365}],"con":true,"img":false}]}
{"op":"mcm","clk":"11449959578","pt":1717316402809,"mc":[{"id":"1.229554894","rc":[{"atb":[[1.59,0],[1.32,0],[1.3,0]],"id":70003365}],"con":true,"img":false}]}
{"op":"mcm","clk":"11449959589","pt":1717316402917,"mc":[{"id":"1.229554894","rc":[{"atl":[[1.84,5.26],[1.91,0]],"id":70003365}],"con":true,"img":false}]}
{"op":"mcm","clk":"11449959602","pt":1717316403019,"mc":[{"id":"1.229554894","rc":[{"atl":[[1000,0.17]],"id":70003367},{"atl":[[1.86,5.24]],"id":70003365}],"con":true,"img":false}]}
{"op":"mcm","clk":"11449959608","pt":1717316403123,"mc":[{"id":"1.229554894","rc":[{"atl":[[2.56,0.42]],"id":70003367},{"atl":[[1.94,0],[1000,0.47]],"id":70003365}],"con":true,"img":false}]}
{"op":"mcm","clk":"11449959618","pt":1717316403229,"mc":[{"id":"1.229554894","rc":[{"atb":[[2.1,3.92]],"id":70003367}],"con":true,"img":false}]}
{"op":"mcm","clk":"11449959629","pt":1717316403282,"mc":[{"id":"1.229554894","rc":[{"atb":[[2.12,5.92]],"id":70003367}],"con":true,"img":false}]}
{"op":"mcm","clk":"11449959648","pt":1717316403496,"mc":[{"id":"1.229554894","rc":[{"atl":[[2.82,21.76],[2.72,0]],"id":70003367},{"atb":[[1.49,102.1],[1.53,0]],"id":70003365},{"atl":[[1.83,5.62],[1.87,5.31],[2.36,19.6],[2.46,0]],"id":70003365}],"con":true,"img":false}]}
{"op":"mcm","clk":"11449959669","pt":1717316403700,"mc":[{"id":"1.229554894","rc":[{"atb":[[1.72,38.86],[1.66,0]],"id":70003367}],"con":true,"img":false}]}
{"op":"mcm","clk":"11449959675","pt":1717316403803,"mc":[{"id":"1.229554894","rc":[{"atb":[[2.18,25.27],[2.08,4]],"id":70003367},{"atb":[[1.63,5.34]],"id":70003365}],"con":true,"img":false}]}
{"op":"mcm","clk":"11449959686","pt":1717316403905,"mc":[{"id":"1.229554894","rc":[{"atb":[[2.12,4.28]],"id":70003367},{"atb":[[1.5,0.55]],"id":70003365}],"con":true,"img":false}]}
{"op":"mcm","clk":"11449959729","pt":1717316404421,"mc":[{"id":"1.229554894","rc":[{"atb":[[2.12,3.73]],"id":70003367}],"con":true,"img":false}]}
{"op":"mcm","clk":"11449959741","pt":1717316404525,"mc":[{"id":"1.229554894","rc":[{"atb":[[2.2,0.54]],"id":70003367}],"con":true,"img":false}]}
{"op":"mcm","clk":"11449959752","pt":1717316404604,"mc":[{"id":"1.229554894","rc":[{"atl":[[1.82,5.28]],"id":70003365}],"con":true,"img":false}]}
{"op":"mcm","clk":"11449959760","pt":1717316404682,"mc":[{"id":"1.229554894","rc":[{"atb":[[2.2,4.25],[1.93,0]],"id":70003367},{"atl":[[1.89,0]],"id":70003365}],"con":true,"img":false}]}
{"op":"mcm","clk":"11449959774","pt":1717316404889,"mc":[{"id":"1.229554894","rc":[{"atl":[[1.81,12.62]],"id":70003365}],"con":true,"img":false}]}
{"op":"mcm","clk":"11449959787","pt":1717316405094,"mc":[{"id":"1.229554894","rc":[{"atl":[[1.81,0]],"id":70003365}],"con":true,"img":false}]}
{"op":"mcm","clk":"11449959941","pt":1717316407107,"mc":[{"id":"1.229554894","rc":[{"atl":[[1.81,12.62]],"id":70003365}],"con":true,"img":false}]}
{"op":"mcm","clk":"11449959951","pt":1717316407211,"mc":[{"id":"1.229554894","rc":[{"atl":[[1.83,0],[1.81,14.07]],"id":70003365}],"con":true,"img":false}]}
{"op":"mcm","clk":"11449960012","pt":1717316407882,"mc":[{"id":"1.229554894","rc":[{"atl":[[1.92,0]],"id":70003365}],"con":true,"img":false}]}
{"op":"mcm","clk":"11449960077","pt":1717316408611,"mc":[{"id":"1.229554894","rc":[{"atl":[[1.8,5.37],[1.87,0]],"id":70003365}],"con":true,"img":false}]}
{"op":"mcm","clk":"11449960091","pt":1717316408820,"mc":[{"id":"1.229554894","rc":[{"trd":[[2.58,1.16],[2.56,0.42]],"ltp":2.58,"tv":1.57,"id":70003367},{"atl":[[2.56,0],[2.58,16.91]],"id":70003367},{"atb":[[1.63,0]],"id":70003365},{"trd":[[1.63,12.53],[1.64,0.65]],"ltp":1.63,"tv":13.18,"id":70003365}],"con":true,"img":false}]}
{"op":"mcm","clk":"11449960097","pt":1717316408921,"mc":[{"id":"1.229554894","rc":[{"atb":[[1.45,112.65],[1.49,0]],"id":70003365}],"con":true,"img":false}]}
{"op":"mcm","clk":"11449960104","pt":1717316409023,"mc":[{"id":"1.229554894","rc":[{"atb":[[1.45,10],[1.38,113.2]],"id":70003365}],"con":true,"img":false}]}
{"op":"mcm","clk":"11449960120","pt":1717316409183,"mc":[{"id":"1.229554894","rc":[{"atb":[[1.5,0]],"id":70003365}],"con":true,"img":false}]}
{"op":"mcm","clk":"11449960131","pt":1717316409289,"mc":[{"id":"1.229554894","rc":[{"atb":[[1.39,0.55]],"id":70003365}],"con":true,"img":false}]}
{"op":"mcm","clk":"11449960154","pt":1717316409605,"mc":[{"id":"1.229554894","rc":[{"atb":[[1.28,49.19],[1.26,70.63],[1.22,125.21],[1.24,95.64]],"id":70003365}],"con":true,"img":false}]}
{"op":"mcm","clk":"11449960193","pt":1717316410010,"mc":[{"id":"1.229554894","rc":[{"atl":[[2.56,3.61]],"id":70003367},{"atb":[[1.46,5.46]],"id":70003365}],"con":true,"img":false}]}
{"op":"mcm","clk":"11449960199","pt":1717316410117,"mc":[{"id":"1.229554894","rc":[{"atb":[[1.47,5.46],[1.38,0],[1.52,26.57]],"id":70003365}],"con":true,"img":false}]}
{"op":"mcm","clk":"11449960225","pt":1717316410429,"mc":[{"id":"1.229554894","rc":[{"atb":[[1.39,0]],"id":70003365}],"con":true,"img":false}]}
{"op":"mcm","clk":"11449960234","pt":1717316410529,"mc":[{"id":"1.229554894","rc":[{"atb":[[1.02,10.37]],"id":70003367},{"atb":[[1.53,0.55]],"id":70003365}],"con":true,"img":false}]}
{"op":"mcm","clk":"11449960248","pt":1717316410688,"mc":[{"id":"1.229554894","rc":[{"atb":[[1.02,9.37]],"id":70003367}],"con":true,"img":false}]}
{"op":"mcm","clk":"11449960263","pt":1717316410898,"mc":[{"id":"1.229554894","rc":[{"atb":[[1.02,8.87]],"id":70003367},{"atl":[[1.79,11.18]],"id":70003365}],"con":true,"img":false}]}
{"op":"mcm","clk":"11449960270","pt":1717316410998,"mc":[{"id":"1.229554894","rc":[{"trd":[[2.56,1.42]],"ltp":2.56,"tv":1.42,"id":70003367},{"atl":[[2.56,3.11]],"id":70003367}],"con":true,"img":false}]}
{"op":"mcm","clk":"11449960291","pt":1717316411305,"mc":[{"id":"1.229554894","rc":[{"atb":[[2.24,24.05]],"id":70003367},{"atb":[[1.55,54.23]],"id":70003365},{"atl":[[1.79,12.65],[1.81,12.62]],"id":70003365}],"con":true,"img":false}]}
{"op":"mcm","clk":"11449960301","pt":1717316411410,"mc":[{"id":"1.229554894","rc":[{"atl":[[1.85,12.33]],"id":70003365}],"con":true,"img":false}]}
{"op":"mcm","clk":"11449960320","pt":1717316411633,"mc":[{"id":"1.229554894","rc":[{"atb":[[2.2,3.71]],"id":70003367},{"atb":[[1.53,0]],"id":70003365}],"con":true,"img":false}]}
{"op":"mcm","clk":"11449960326","pt":1717316411733,"mc":[{"id":"1.229554894","rc":[{"atb":[[2.26,0.54]],"id":70003367},{"atb":[[1.56,0.55]],"id":70003365}],"con":true,"img":false}]}
{"op":"mcm","clk":"11449960361","pt":1717316412105,"mc":[{"id":"1.229554894","rc":[{"atb":[[2.26,4.17],[2.08,0]],"id":70003367},{"atl":[[1.78,5.42],[1.86,0]],"id":70003365}],"con":true,"img":false}]}
{"op":"mcm","clk":"11449960450","pt":1717316413088,"mc":[{"id":"1.229554894","rc":[{"atl":[[1.77,11.32]],"id":70003365}],"con":true,"img":false}]}
{"op":"mcm","clk":"11449960470","pt":1717316413292,"mc":[{"id":"1.229554894","rc":[{"atl":[[1.84,0],[1.85,0],[1.76,5.45]],"id":70003365}],"con":true,"img":false}]}
{"op":"mcm","clk":"11449960506","pt":1717316413603,"mc":[{"id":"1.229554894","rc":[{"atb":[[1.72,3.98],[1.78,36.59]],"id":70003367}],"con":true,"img":false}]}
{"op":"mcm","clk":"11449960526","pt":1717316413811,"mc":[{"id":"1.229554894","rc":[{"atb":[[2.28,23.29]],"id":70003367}],"con":true,"img":false}]}
{"op":"mcm","clk":"11449960536","pt":1717316414023,"mc":[{"id":"1.229554894","rc":[{"atb":[[1.56,0]],"id":70003365}],"con":true,"img":false}]}
{"op":"mcm","clk":"11449960545","pt":1717316414130,"mc":[{"id":"1.229554894","rc":[{"atb":[[1.55,54.78],[1.52,0]],"id":70003365}],"con":true,"img":false}]}
{"op":"mcm","clk":"11449960556","pt":1717316414224,"mc":[{"id":"1.229554894","rc":[{"atb":[[1.56,5.32],[1.5,26.57]],"id":70003365},{"atl":[[1.78,0],[1.76,0]],"id":70003365}],"con":true,"img":false}]}
{"op":"mcm","clk":"11449960563","pt":1717316414336,"mc":[{"id":"1.229554894","rc":[{"atl":[[1.79,17.95]],"id":70003365}],"con":true,"img":false}]}
{"op":"mcm","clk":"11449960571","pt":1717316414425,"mc":[{"id":"1.229554894","rc":[{"atl":[[1.77,0]],"id":70003365}],"con":true,"img":false}]}
{"op":"mcm","clk":"11449960583","pt":1717316414632,"mc":[{"id":"1.229554894","rc":[{"atb":[[1.55,54.23]],"id":70003365}],"con":true,"img":false}]}
{"op":"mcm","clk":"11449960593","pt":1717316414734,"mc":[{"id":"1.229554894","rc":[{"atb":[[1.56,5.87]],"id":70003365}],"con":true,"img":false}]}
{"op":"mcm","clk":"11449960603","pt":1717316414836,"mc":[{"id":"1.229554894","rc":[{"atb":[[2.28,0]],"id":70003367}],"con":true,"img":false}]}
{"op":"mcm","clk":"11449960619","pt":1717316415047,"mc":[{"id":"1.229554894","rc":[{"atb":[[2,7.84],[1.9,8.72]],"id":70003367},{"atb":[[1.6,13.07],[1.7,11.21]],"id":70003365}],"con":true,"img":false}]}
{"op":"mcm","clk":"11449960639","pt":1717316415209,"mc":[{"id":"1.229554894","rc":[{"atb":[[1.55,0]],"id":70003365}],"con":true,"img":false}]}
{"op":"mcm","clk":"11449960663","pt":1717316415519,"mc":[{"id":"1.229554894","rc":[{"atb":[[1.71,5.33]],"id":70003365}],"con":true,"img":false}]}
{"op":"mcm","clk":"11449960676","pt":1717316415725,"mc":[{"id":"1.229554894","rc":[{"atb":[[1.64,46.6]],"id":70003365}],"con":true,"img":false}]}
{"op":"mcm","clk":"11449960685","pt":1717316415825,"mc":[{"id":"1.229554894","rc":[{"atb":[[1.45,0],[1.67,11.92]],"id":70003365}],"con":true,"img":false}]}
{"op":"mcm","clk":"11449960704","pt":1717316416138,"mc":[{"id":"1.229554894","rc":[{"atb":[[1.5,0]],"id":70003365},{"atl":[[1.79,12.65]],"id":70003365}],"con":true,"img":false}]}
{"op":"mcm","clk":"11449960712","pt":1717316416238,"mc":[{"id":"1.229554894","rc":[{"atb":[[1.53,26.57]],"id":70003365}],"con":true,"img":false}]}
{"op":"mcm","clk":"11449960900","pt":1717316418514,"mc":[{"id":"1.229554894","rc":[{"atl":[[1.79,23.31]],"id":70003365}],"con":true,"img":false}]}
{"op":"mcm","clk":"11449961031","pt":1717316420223,"mc":[{"id":"1.229554894","rc":[{"atb":[[2.26,0.54]],"id":70003367}],"con":true,"img":false}]}
{"op":"mcm","clk":"11449961088","pt":1717316420951,"mc":[{"id":"1.229554894","rc":[{"atb":[[1.7,19.51],[1.67,0]],"id":70003365}],"con":true,"img":false}]}
{"op":"mcm","clk":"11449961367","pt":1717316423847,"mc":[{"id":"1.229554894","rc":[{"atb":[[1.7,11.21],[1.68,11.92]],"id":70003365}],"con":true,"img":false}]}
{"op":"mcm","clk":"11449961376","pt":1717316423948,"mc":[{"id":"1.229554894","rc":[{"atb":[[2.26,4.23]],"id":70003367},{"atb":[[1.71,0]],"id":70003365},{"atl":[[1.78,5.31]],"id":70003365}],"con":true,"img":false}]}
{"op":"mcm","clk":"11449961400","pt":1717316424208,"mc":[{"id":"1.229554894","rc":[{"atb":[[2.28,23.29]],"id":70003367},{"atb":[[1.7,16.56]],"id":70003365}],"con":true,"img":false}]}
{"op":"mcm","clk":"11449961571","pt":1717316426264,"mc":[{"id":"1.229554894","rc":[{"atb":[[1.53,0]],"id":70003365}],"con":true,"img":false}]}
{"op":"mcm","clk":"11449961578","pt":1717316426315,"mc":[{"id":"1.229554894","rc":[{"atb":[[1.51,26.57]],"id":70003365}],"con":true,"img":false}]}
{"op":"mcm","clk":"11449961618","pt":1717316426826,"mc":[{"id":"1.229554894","rc":[{"atb":[[2.3,3.66],[2.1,0]],"id":70003367},{"atb":[[1.7,11.21]],"id":70003365}],"con":true,"img":false}]}
{"op":"mcm","clk":"11449961666","pt":1717316427547,"mc":[{"id":"1.229554894","rc":[{"atb":[[1.28,0]],"id":70003365}],"con":true,"img":false}]}
{"op":"mcm","clk":"11449961699","pt":1717316428014,"mc":[{"id":"1.229554894","rc":[{"atb":[[1.26,0],[1.24,0]],"id":70003365}],"con":true,"img":false}]}
{"op":"mcm","clk":"11449961754","pt":1717316428738,"mc":[{"id":"1.229554894","rc":[{"atb":[[1.7,16.61]],"id":70003365}],"con":true,"img":false}]}
{"op":"mcm","clk":"11449961763","pt":1717316428842,"mc":[{"id":"1.229554894","rc":[{"atb":[[2.3,0]],"id":70003367}],"con":true,"img":false}]}
{"op":"mcm","clk":"11449961773","pt":1717316428946,"mc":[{"id":"1.229554894","rc":[{"atb":[[1.68,0],[1.71,21.99]],"id":70003365}],"con":true,"img":false}]}
{"op":"mcm","clk":"11449961920","pt":1717316430759,"mc":[{"id":"1.229554894","rc":[{"atl":[[1000,1.36]],"id":70003365}],"con":true,"img":false}]}
{"op":"mcm","clk":"11449961960","pt":1717316431124,"mc":[{"id":"1.229554894","rc":[{"atl":[[1000,0.62]],"id":70003365}],"con":true,"img":false}]}
{"op":"mcm","clk":"11449961988","pt":1717316431435,"mc":[{"id":"1.229554894","rc":[{"atb":[[2.3,3.62]],"id":70003367},{"atb":[[1.7,11.21]],"id":70003365},{"atl":[[1000,0.47]],"id":70003365}],"con":true,"img":false}]}
{"op":"mcm","clk":"11449961998","pt":1717316431534,"mc":[{"id":"1.229554894","rc":[{"atb":[[1.65,5.48],[1.71,21.84]],"id":70003365},{"trd":[[1.71,0.29]],"ltp":1.71,"tv":0.29,"id":70003365}],"con":true,"img":false}]}
{"op":"mcm","clk":"11449962002","pt":1717316431637,"mc":[{"id":"1.229554894","rc":[{"atl":[[1.79,21.84]],"id":70003365}],"con":true,"img":false}]}
{"op":"mcm","clk":"11449962197","pt":1717316434067,"mc":[{"id":"1.229554894","rc":[{"atb":[[1.71,0]],"id":70003365},{"atl":[[2.36,0],[2.26,19.6]],"id":70003365}],"con":true,"img":false}]}
{"op":"mcm","clk":"11449962243","pt":1717316434548,"mc":[{"id":"1.229554894","rc":[{"atb":[[1.78,0],[1.88,34.88]],"id":70003367}],"con":true,"img":false}]}
{"op":"mcm","clk":"11449962300","pt":1717316435266,"mc":[{"id":"1.229554894","rc":[{"atb":[[2.3,0],[2.28,20.29]],"id":70003367},{"trd":[[2.28,5.99],[2.3,7.23]],"ltp":2.28,"tv":13.22,"id":70003367}],"con":true,"img":false}]}
{"op":"mcm","clk":"11449962308","pt":1717316435367,"mc":[{"id":"1.229554894","rc":[{"atl":[[2.54,3.96]],"id":70003367}],"con":true,"img":false}]}
{"op":"mcm","clk":"11449962316","pt":1717316435470,"mc":[{"id":"1.229554894","rc":[{"atl":[[1.77,22.12]],"id":70003365}],"con":true,"img":false}]}
{"op":"mcm","clk":"11449962327","pt":1717316435576,"mc":[{"id":"1.229554894","rc":[{"atb":[[2.3,3.59]],"id":70003367}],"con":true,"img":false}]}
{"op":"mcm","clk":"11449962334","pt":1717316435627,"mc":[{"id":"1.229554894","rc":[{"atl":[[1.77,0]],"id":70003365}],"con":true,"img":false}]}
{"op":"mcm","clk":"11449962423","pt":1717316436971,"mc":[{"id":"1.229554894","rc":[{"atb":[[2.3,0]],"id":70003367},{"trd":[[2.3,14.43]],"ltp":2.3,"tv":14.43,"id":70003367},{"atl":[[2.3,6.34]],"id":70003367}],"con":true,"img":false}]}
{"op":"mcm","clk":"11449962434","pt":1717316437076,"mc":[{"id":"1.229554894","rc":[{"trd":[[2.3,27.11]],"ltp":2.3,"tv":27.11,"id":70003367},{"atl":[[2.3,0],[2.52,3.59]],"id":70003367}],"con":true,"img":false}]}
{"op":"mcm","clk":"11449962442","pt":1717316437176,"mc":[{"id":"1.229554894","rc":[{"atl":[[2.54,0],[2.48,5.29]],"id":70003367}],"con":true,"img":false}]}
{"op":"mcm","clk":"11449962453","pt":1717316437231,"mc":[{"id":"1.229554894","rc":[{"atl":[[2.5,3.92],[2.48,0]],"id":70003367}],"con":true,"img":false}]}
{"op":"mcm","clk":"11449962472","pt":1717316437538,"mc":[{"id":"1.229554894","rc":[{"atl":[[1.77,22.36]],"id":70003365}],"con":true,"img":false}]}
{"op":"mcm","clk":"11449962488","pt":1717316437749,"mc":[{"id":"1.229554894","rc":[{"atl":[[2.48,3.59]],"id":70003367}],"con":true,"img":false}]}
{"op":"mcm","clk":"11449962496","pt":1717316437849,"mc":[{"id":"1.229554894","rc":[{"atl":[[2.5,0],[2.48,7.51]],"id":70003367}],"con":true,"img":false}]}
{"op":"mcm","clk":"11449962505","pt":1717316437952,"mc":[{"id":"1.229554894","rc":[{"atb":[[2.3,3.62]],"id":70003367},{"atl":[[2.5,3.92],[2.48,3.59]],"id":70003367},{"atl":[[1.76,5.44]],"id":70003365}],"con":true,"img":false}]}
{"op":"mcm","clk":"11449962516","pt":1717316438085,"mc":[{"id":"1.229554894","rc":[{"atl":[[2.5,0],[2.48,7.51]],"id":70003367},{"atl":[[1.81,0]],"id":70003365}],"con":true,"img":false}]}
{"op":"mcm","clk":"11449962524","pt":1717316438158,"mc":[{"id":"1.229554894","rc":[{"atl":[[2.5,3.6],[2.48,3.59]],"id":70003367}],"con":true,"img":false}]}
{"op":"mcm","clk":"11449962529","pt":1717316438260,"mc":[{"id":"1.229554894","rc":[{"atl":[[2.5,0],[2.48,7.2]],"id":70003367}],"con":true,"img":false}]}
{"op":"mcm","clk":"11449962535","pt":1717316438365,"mc":[{"id":"1.229554894","rc":[{"atl":[[2.5,3.6],[2.48,3.59]],"id":70003367}],"con":true,"img":false}]}
{"op":"mcm","clk":"11449962540","pt":1717316438465,"mc":[{"id":"1.229554894","rc":[{"atl":[[2.5,0],[2.48,7.2]],"id":70003367}],"con":true,"img":false}]}
{"op":"mcm","clk":"11449962547","pt":1717316438570,"mc":[{"id":"1.229554894","rc":[{"atl":[[2.5,3.6],[2.48,3.59]],"id":70003367}],"con":true,"img":false}]}
{"op":"mcm","clk":"11449962552","pt":1717316438674,"mc":[{"id":"1.229554894","rc":[{"atl":[[2.5,0],[2.48,7.2]],"id":70003367}],"con":true,"img":false}]}
{"op":"mcm","clk":"11449962557","pt":1717316438776,"mc":[{"id":"1.229554894","rc":[{"atl":[[2.5,3.6],[2.48,3.59]],"id":70003367}],"con":true,"img":false}]}
{"op":"mcm","clk":"11449962564","pt":1717316438830,"mc":[{"id":"1.229554894","rc":[{"atl":[[2.5,0],[2.48,7.2]],"id":70003367}],"con":true,"img":false}]}
{"op":"mcm","clk":"11449962581","pt":1717316439041,"mc":[{"id":"1.229554894","rc":[{"atl":[[2.82,0],[2.5,3.61],[2.94,10.89],[2.48,3.59]],"id":70003367}],"con":true,"img":false}]}
{"op":"mcm","clk":"11449962633","pt":1717316439656,"mc":[{"id":"1.229554894","rc":[{"atl":[[1.76,0]],"id":70003365}],"con":true,"img":false}]}
{"op":"mcm","clk":"11449962644","pt":1717316439759,"mc":[{"id":"1.229554894","rc":[{"atb":[[1.7,5.97]],"id":70003365},{"trd":[[1.7,10.46]],"ltp":1.7,"tv":10.46,"id":70003365}],"con":true,"img":false}]}
{"op":"mcm","clk":"11449962648","pt":1717316439862,"mc":[{"id":"1.229554894","rc":[{"atb":[[1.63,16.52]],"id":70003365}],"con":true,"img":false}]}
{"op":"mcm","clk":"11449963043","pt":1717316444563,"mc":[{"id":"1.229554894","rc":[{"atb":[[1.64,60.51],[1.63,0],[1.7,2.05]],"id":70003365},{"trd":[[1.7,18.31]],"ltp":1.7,"tv":18.31,"id":70003365}],"con":true,"img":false}]}
{"op":"mcm","clk":"11449963052","pt":1717316444664,"mc":[{"id":"1.229554894","rc":[{"atl":[[1.76,5.42]],"id":70003365}],"con":true,"img":false}]}
{"op":"mcm","clk":"11449963065","pt":1717316444871,"mc":[{"id":"1.229554894","rc":[{"atl":[[1.75,20.53]],"id":70003365}],"con":true,"img":false}]}
{"op":"mcm","clk":"11449963076","pt":1717316445078,"mc":[{"id":"1.229554894","rc":[{"atl":[[1.79,0]],"id":70003365}],"con":true,"img":false}]}
{"op":"mcm","clk":"11449963086","pt":1717316445281,"mc":[{"id":"1.229554894","rc":[{"atb":[[2.18,0]],"id":70003367}],"con":true,"img":false}]}
{"op":"mcm","clk":"11449963271","pt":1717316447763,"mc":[{"id":"1.229554894","rc":[{"atb":[[1.78,3.61],[1.93,8.72],[1.72,0],[1.88,0]],"id":70003367},{"atl":[[2.5,0],[2.52,7.2]],"id":70003367},{"atl":[[2.26,0],[2.16,19.6]],"id":70003365}],"con":true,"img":false}]}
{"op":"mcm","clk":"11449963287","pt":1717316447969,"mc":[{"id":"1.229554894","rc":[{"atl":[[1.75,0]],"id":70003365}],"con":true,"img":false}]}
{"op":"mcm","clk":"11449963337","pt":1717316448853,"mc":[{"id":"1.229554894","rc":[{"atl":[[1.76,0]],"id":70003365}],"con":true,"img":false}]}
{"op":"mcm","clk":"11449963350","pt":1717316449058,"mc":[{"id":"1.229554894","rc":[{"atb":[[1.64,46.6],[1.66,5.43]],"id":70003365},{"atl":[[1.78,15.29]],"id":70003365}],"con":true,"img":false}]}
{"op":"mcm","clk":"11449963368","pt":1717316449368,"mc":[{"id":"1.229554894","rc":[{"atb":[[1.37,0],[1.67,5.41]],"id":70003365}],"con":true,"img":false}]}
{"op":"mcm","clk":"11449963395","pt":1717316449780,"mc":[{"id":"1.229554894","rc":[{"atl":[[1.76,5.4]],"id":70003365}],"con":true,"img":false}]}
{"op":"mcm","clk":"11449963402","pt":1717316449888,"mc":[{"id":"1.229554894","rc":[{"atb":[[1.93,0],[1.86,34.88]],"id":70003367}],"con":true,"img":false}]}
{"op":"mcm","clk":"11449963450","pt":1717316450561,"mc":[{"id":"1.229554894","rc":[{"atb":[[2.1,25.12]],"id":70003367}],"con":true,"img":false}]}
{"op":"mcm","clk":"11449963477","pt":1717316450874,"mc":[{"id":"1.229554894","rc":[{"atb":[[1.7,0]],"id":70003365},{"trd":[[1.7,22.42]],"ltp":1.7,"tv":22.42,"id":70003365},{"atl":[[1.7,47.94]],"id":70003365}],"con":true,"img":false}]}
{"op":"mcm","clk":"11449963508","pt":1717316451282,"mc":[{"id":"1.229554894","rc":[{"atb":[[2.34,22.25]],"id":70003367},{"atb":[[1.64,0],[1.63,47.34]],"id":70003365}],"con":true,"img":false}]}
{"op":"mcm","clk":"11449963521","pt":1717316451488,"mc":[{"id":"1.229554894","rc":[{"trd":[[2.48,7.19]],"ltp":2.48,"tv":7.19,"id":70003367},{"atl":[[2.58,0],[2.48,0]],"id":70003367},{"atl":[[1.74,13.25]],"id":70003365}],"con":true,"img":false}]}
{"op":"mcm","clk":"11449963545","pt":1717316451796,"mc":[{"id":"1.229554894","rc":[{"atb":[[1.63,0]],"id":70003365}],"con":true,"img":false}]}
{"op":"mcm","clk":"11449963579","pt":1717316452264,"mc":[{"id":"1.229554894","rc":[{"atl":[[2.5,3.59]],"id":70003367},{"atb":[[1.61,48.89]],"id":70003365}],"con":true,"img":false}]}
{"op":"mcm","clk":"11449963621","pt":1717316452777,"mc":[{"id":"1.229554894","rc":[{"atl":[[2.28,0],[2.18,5.44]],"id":70003365}],"con":true,"img":false}]}
{"op":"mcm","clk":"11449963627","pt":1717316452879,"mc":[{"id":"1.229554894","rc":[{"atl":[[2.52,3.59],[2.48,3.61]],"id":70003367}],"con":true,"img":false}]}
{"op":"mcm","clk":"11449963639","pt":1717316453086,"mc":[{"id":"1.229554894","rc":[{"atl":[[2.46,3.61],[2.6,0]],"id":70003367}],"con":true,"img":false}]}
{"op":"mcm","clk":"11449963697","pt":1717316454174,"mc":[{"id":"1.229554894","rc":[{"atb":[[1.64,5.44],[1.66,0]],"id":70003365}],"con":true,"img":false}]}
{"op":"mcm","clk":"11449963714","pt":1717316454382,"mc":[{"id":"1.229554894","rc":[{"atl":[[2.46,0]],"id":70003367}],"con":true,"img":false}]}
{"op":"mcm","clk":"11449963749","pt":1717316454793,"mc":[{"id":"1.229554894","rc":[{"atl":[[2.48,7.19]],"id":70003367}],"con":true,"img":false}]}
{"op":"mcm","clk":"11449963768","pt":1717316455000,"mc":[{"id":"1.229554894","rc":[{"atb":[[1.92,15.7],[1.86,0]],"id":70003367}],"con":true,"img":false}]}
{"op":"mcm","clk":"11449964030","pt":1717316458766,"mc":[{"id":"1.229554894","rc":[{"atl":[[1.74,21.58],[1.78,5.31]],"id":70003365}],"con":true,"img":false}]}
{"op":"mcm","clk":"11449964063","pt":1717316459284,"mc":[{"id":"1.229554894","rc":[{"atl":[[2.46,3.6]],"id":70003367},{"atb":[[1.64,0],[1.65,10.92]],"id":70003365}],"con":true,"img":false}]}
{"op":"mcm","clk":"11449964073","pt":1717316459385,"mc":[{"id":"1.229554894","rc":[{"atl":[[2.56,0]],"id":70003367}],"con":true,"img":false}]}
{"op":"mcm","clk":"11449964080","pt":1717316459489,"mc":[{"id":"1.229554894","rc":[{"atl":[[2.46,7.22],[2.48,3.58]],"id":70003367}],"con":true,"img":false}]}
{"op":"mcm","clk":"11449964109","pt":1717316459800,"mc":[{"id":"1.229554894","rc":[{"atl":[[1.77,0],[1.75,21.47]],"id":70003365}],"con":true,"img":false}]}
{"op":"mcm","clk":"11449964123","pt":1717316460004,"mc":[{"id":"1.229554894","rc":[{"atl":[[2.46,3.62]],"id":70003367}],"con":true,"img":false}]}
{"op":"mcm","clk":"11449964167","pt":1717316460579,"mc":[{"id":"1.229554894","rc":[{"atb":[[1.78,38.49],[1.92,0]],"id":70003367},{"atl":[[2.8,7.19],[2.94,0]],"id":70003367},{"atl":[[2.3,10.88],[2.16,0]],"id":70003365}],"con":true,"img":false}]}
{"op":"mcm","clk":"11449964236","pt":1717316461588,"mc":[{"id":"1.229554894","rc":[{"atb":[[2.12,0],[2.36,3.55]],"id":70003367},{"atl":[[2.5,0],[2.48,0]],"id":70003367},{"atb":[[1.67,0]],"id":70003365},{"atl":[[1.73,5.56],[1.82,0]],"id":70003365}],"con":true,"img":false}]}
{"op":"mcm","clk":"11449964249","pt":1717316461792,"mc":[{"id":"1.229554894","rc":[{"atb":[[1.56,59.13],[1.5,26.16],[1.61,0],[1.47,0]],"id":70003365},{"atl":[[1.72,21.8]],"id":70003365}],"con":true,"img":false}]}
{"op":"mcm","clk":"11449964254","pt":1717316461896,"mc":[{"id":"1.229554894","rc":[{"atl":[[2.52,0]],"id":70003367}],"con":true,"img":false}]}
{"op":"mcm","clk":"11449964260","pt":1717316462001,"mc":[{"id":"1.229554894","rc":[{"atl":[[3.45,9.83],[3.35,8.2],[3.25,6.42],[3.55,11.33]],"id":70003367}],"con":true,"img":false}]}
{"op":"mcm","clk":"11449964265","pt":1717316462108,"mc":[{"id":"1.229554894","rc":[{"atl":[[1.75,0]],"id":70003365}],"con":true,"img":false}]}
{"op":"mcm","clk":"11449964279","pt":1717316462270,"mc":[{"id":"1.229554894","rc":[{"atb":[[1.56,5.87]],"id":70003365}],"con":true,"img":false}]}
{"op":"mcm","clk":"11449964282","pt":1717316462372,"mc":[{"id":"1.229554894","rc":[{"atb":[[1.65,5.44]],"id":70003365},{"atl":[[1.71,5.67],[1.8,0]],"id":70003365}],"con":true,"img":false}]}
{"op":"mcm","clk":"11449964291","pt":1717316462484,"mc":[{"id":"1.229554894","rc":[{"atl":[[2.78,3.47]],"id":70003367},{"atb":[[1.61,5.73]],"id":70003365}],"con":true,"img":false}]}
{"op":"mcm","clk":"11449964310","pt":1717316462806,"mc":[{"id":"1.229554894","rc":[{"atb":[[1.56,59.13]],"id":70003365}],"con":true,"img":false}]}
{"op":"mcm","clk":"11449964322","pt":1717316462903,"mc":[{"id":"1.229554894","rc":[{"atl":[[3.25,0]],"id":70003367},{"atb":[[1.51,0]],"id":70003365}],"con":true,"img":false}]}
{"op":"mcm","clk":"11449964333","pt":1717316463002,"mc":[{"id":"1.229554894","rc":[{"atb":[[1.49,26.57]],"id":70003365}],"con":true,"img":false}]}
{"op":"mcm","clk":"11449964443","pt":1717316464399,"mc":[{"id":"1.229554894","rc":[{"atb":[[1.62,9.41]],"id":70003365}],"con":true,"img":false}]}
{"op":"mcm","clk":"11449964453","pt":1717316464502,"mc":[{"id":"1.229554894","rc":[{"atb":[[1.65,0]],"id":70003365}],"con":true,"img":false}]}
{"op":"mcm","clk":"11449964461","pt":1717316464605,"mc":[{"id":"1.229554894","rc":[{"atl":[[2.46,0],[2.76,10]],"id":70003367},{"atb":[[1.63,5.73]],"id":70003365}],"con":true,"img":false}]}
{"op":"mcm","clk":"11449964464","pt":1717316464707,"mc":[{"id":"1.229554894","rc":[{"atl":[[2.8,0],[2.88,9.83]],"id":70003367},{"atb":[[1.64,5.74]],"id":70003365}],"con":true,"img":false}]}
{"op":"mcm","clk":"11449964469","pt":1717316464762,"mc":[{"id":"1.229554894","rc":[{"atb":[[2.24,0]],"id":70003367},{"atl":[[2.74,3.48]],"id":70003367},{"atb":[[1.62,0]],"id":70003365},{"atl":[[1.69,22.16]],"id":70003365}],"con":true,"img":false}]}
{"op":"mcm","clk":"11449964495","pt":1717316465078,"mc":[{"id":"1.229554894","rc":[{"atl":[[1.74,0]],"id":70003365}],"con":true,"img":false}]}
{"op":"mcm","clk":"11449964539","pt":1717316465702,"mc":[{"id":"1.229554894","rc":[{"atb":[[1.78,3.61],[1.88,36.59]],"id":70003367},{"atl":[[2.3,0],[2.2,11.24]],"id":70003365}],"con":true,"img":false}]}
{"op":"mcm","clk":"11449964548","pt":1717316465805,"mc":[{"id":"1.229554894","rc":[{"atl":[[1.7,0]],"id":70003365}],"con":true,"img":false}]}
{"op":"mcm","clk":"11449964555","pt":1717316465906,"mc":[{"id":"1.229554894","rc":[{"atl":[[1.68,47.94]],"id":70003365}],"con":true,"img":false}]}
{"op":"mcm","clk":"11449964563","pt":1717316466011,"mc":[{"id":"1.229554894","rc":[{"atl":[[1.69,0]],"id":70003365}],"con":true,"img":false}]}
{"op":"mcm","clk":"11449964590","pt":1717316466278,"mc":[{"id":"1.229554894","rc":[{"atb":[[2.48,20.15]],"id":70003367},{"atl":[[1.66,37.36]],"id":70003365}],"con":true,"img":false}]}
{"op":"mcm","clk":"11449964625","pt":1717316466789,"mc":[{"id":"1.229554894","rc":[{"atb":[[2.48,0]],"id":70003367},{"atb":[[1.56,58.58]],"id":70003365}],"con":true,"img":false}]}
{"op":"mcm","clk":"11449964632","pt":1717316466894,"mc":[{"id":"1.229554894","rc":[{"atl":[[1.67,22.4]],"id":70003365}],"con":true,"img":false}]}
{"op":"mcm","clk":"11449964660","pt":1717316467307,"mc":[{"id":"1.229554894","rc":[{"atb":[[2.42,21]],"id":70003367}],"con":true,"img":false}]}
{"op":"mcm","clk":"11449964702","pt":1717316467878,"mc":[{"id":"1.229554894","rc":[{"atb":[[1.83,10],[1.78,0]],"id":70003367}],"con":true,"img":false}]}
{"op":"mcm","clk":"11449964854","pt":1717316469688,"mc":[{"id":"1.229554894","rc":[{"atl":[[2.72,10],[2.76,0]],"id":70003367}],"con":true,"img":false}]}
{"op":"mcm","clk":"11449964865","pt":1717316469894,"mc":[{"id":"1.229554894","rc":[{"atb":[[1.94,15.7],[1.88,0]],"id":70003367},{"atb":[[1.63,19.8],[1.44,110.73],[1.5,0]],"id":70003365}],"con":true,"img":false}]}
{"op":"mcm","clk":"11449964873","pt":1717316469997,"mc":[{"id":"1.229554894","rc":[{"atb":[[1.64,0],[1.63,5.73],[1.62,14.07]],"id":70003365}],"con":true,"img":false}]}
{"op":"mcm","clk":"11449964894","pt":1717316470308,"mc":[{"id":"1.229554894","rc":[{"atb":[[2.28,0]],"id":70003367},{"atb":[[1.59,50.54]],"id":70003365}],"con":true,"img":false}]}
{"op":"mcm","clk":"11449964926","pt":1717316470673,"mc":[{"id":"1.229554894","rc":[{"atb":[[1.63,0]],"id":70003365}],"con":true,"img":false}]}
{"op":"mcm","clk":"11449964944","pt":1717316470980,"mc":[{"id":"1.229554894","rc":[{"atb":[[2.1,0]],"id":70003367}],"con":true,"img":false}]}
{"op":"mcm","clk":"11449964956","pt":1717316471085,"mc":[{"id":"1.229554894","rc":[{"atb":[[2.16,25.12]],"id":70003367}],"con":true,"img":false}]}
{"op":"mcm","clk":"11449964979","pt":1717316471294,"mc":[{"id":"1.229554894","rc":[{"atb":[[2.5,19.88]],"id":70003367},{"atl":[[1.66,0]],"id":70003365}],"con":true,"img":false}]}
{"op":"mcm","clk":"11449965009","pt":1717316471808,"mc":[{"id":"1.229554894","rc":[{"atb":[[2.5,0]],"id":70003367}],"con":true,"img":false}]}
{"op":"mcm","clk":"11449965022","pt":1717316471972,"mc":[{"id":"1.229554894","rc":[{"atl":[[1.67,0]],"id":70003365}],"con":true,"img":false}]}
{"op":"mcm","clk":"11449965046","pt":1717316472273,"mc":[{"id":"1.229554894","rc":[{"atb":[[2.46,20.42]],"id":70003367}],"con":true,"img":false}]}
{"op":"mcm","clk":"11449965129","pt":1717316473307,"mc":[{"id":"1.229554894","rc":[{"atb":[[1.61,0]],"id":70003365}],"con":true,"img":false}]}
{"op":"mcm","clk":"11449965180","pt":1717316473773,"mc":[{"id":"1.229554894","rc":[{"atb":[[1.59,0],[1.58,51.41]],"id":70003365}],"con":true,"img":false}]}
{"op":"mcm","clk":"11449965189","pt":1717316473879,"mc":[{"id":"1.229554894","rc":[{"atl":[[2.7,3.36]],"id":70003367},{"atb":[[1.6,19.04]],"id":70003365}],"con":true,"img":false}]}
{"op":"mcm","clk":"11449965261","pt":1717316474908,"mc":[{"id":"1.229554894","rc":[{"atl":[[2.72,0],[2.68,3.52]],"id":70003367}],"con":true,"img":false}]}
{"op":"mcm","clk":"11449965275","pt":1717316475117,"mc":[{"id":"1.229554894","rc":[{"atb":[[1.62,0],[1.49,0],[1.61,20.43]],"id":70003365}],"con":true,"img":false}]}
{"op":"mcm","clk":"11449965282","pt":1717316475223,"mc":[{"id":"1.229554894","rc":[{"atb":[[1.47,26.57]],"id":70003365}],"con":true,"img":false}]}
{"op":"mcm","clk":"11449965418","pt":1717316477182,"mc":[{"id":"1.229554894","rc":[{"atl":[[1.68,0]],"id":70003365}],"con":true,"img":false}]}
{"op":"mcm","clk":"11449965422","pt":1717316477283,"mc":[{"id":"1.229554894","rc":[{"atl":[[1.62,47.94]],"id":70003365}],"con":true,"img":false}]}
{"op":"mcm","clk":"11449965429","pt":1717316477387,"mc":[{"id":"1.229554894","rc":[{"trd":[[1.62,2]],"ltp":1.62,"tv":2.0,"id":70003365},{"atl":[[1.62,46.94]],"id":70003365}],"con":true,"img":false}]}
{"op":"mcm","clk":"11449965462","pt":1717316477805,"mc":[{"id":"1.229554894","rc":[{"atb":[[2.34,0]],"id":70003367}],"con":true,"img":false}]}
{"op":"mcm","clk":"11449965469","pt":1717316477912,"mc":[{"id":"1.229554894","rc":[{"atl":[[2.66,3.36]],"id":70003367}],"con":true,"img":false}]}
{"op":"mcm","clk":"11449965486","pt":1717316478222,"mc":[{"id":"1.229554894","rc":[{"atb":[[2.44,3.45],[2.2,0]],"id":70003367},{"atl":[[3.35,0]],"id":70003367}],"con":true,"img":false}]}
{"op":"mcm","clk":"11449965495","pt":1717316478323,"mc":[{"id":"1.229554894","rc":[{"atb":[[1.58,0]],"id":70003365}],"con":true,"img":false}]}
{"op":"mcm","clk":"11449965520","pt":1717316478589,"mc":[{"id":"1.229554894","rc":[{"atl":[[2.66,0]],"id":70003367}],"con":true,"img":false}]}
{"op":"mcm","clk":"11449965534","pt":1717316478791,"mc":[{"id":"1.229554894","rc":[{"atb":[[2.52,19.62]],"id":70003367},{"atb":[[1.58,51.41]],"id":70003365}],"con":true,"img":false}]}
{"op":"mcm","clk":"11449965552","pt":1717316479002,"mc":[{"id":"1.229554894","rc":[{"atb":[[1.6,13.07]],"id":70003365}],"con":true,"img":false}]}
{"op":"mcm","clk":"11449965578","pt":1717316479310,"mc":[{"id":"1.229554894","rc":[{"atb":[[2.42,0]],"id":70003367},{"atb":[[1.58,0]],"id":70003365}],"con":true,"img":false}]}
{"op":"mcm","clk":"11449965582","pt":1717316479413,"mc":[{"id":"1.229554894","rc":[{"atb":[[1.94,0],[1.99,15.7]],"id":70003367},{"atl":[[2.88,0],[2.98,9.83]],"id":70003367}],"con":true,"img":false}]}
{"op":"mcm","clk":"11449965586","pt":1717316479616,"mc":[{"id":"1.229554894","rc":[{"atl":[[1.62,0]],"id":70003365}],"con":true,"img":false}]}
{"op":"mcm","clk":"11449965592","pt":1717316479721,"mc":[{"id":"1.229554894","rc":[{"atb":[[1.61,0]],"id":70003365},{"trd":[[1.61,40.86]],"ltp":1.61,"tv":40.86,"id":70003365},{"atl":[[1.61,26.51]],"id":70003365}],"con":true,"img":false}]}
{"op":"mcm","clk":"11449965598","pt":1717316479838,"mc":[{"id":"1.229554894","rc":[{"atb":[[2.26,0.54],[2.48,3.39],[2.4,21.3],[2.52,0],[2.46,0]],"id":70003367},{"atl":[[2.7,0]],"id":70003367},{"atb":[[1.58,51.41]],"id":70003365}],"con":true,"img":false}]}
{"op":"mcm","clk":"11449965603","pt":1717316479929,"mc":[{"id":"1.229554894","rc":[{"atb":[[1.57,6.15]],"id":70003365},{"atl":[[1.62,5.08]],"id":70003365}],"con":true,"img":false}]}
{"op":"mcm","clk":"11449965612","pt":1717316479986,"mc":[{"id":"1.229554894","rc":[{"trd":[[2.62,4.33]],"ltp":2.62,"tv":4.33,"id":70003367},{"atl":[[2.72,3.46],[2.68,0]],"id":70003367},{"trd":[[1.61,47.92]],"ltp":1.61,"tv":47.92,"id":70003365},{"atl":[[1.61,19.45]],"id":70003365}],"con":true,"img":false}]}
{"op":"mcm","clk":"11449965636","pt":1717316480294,"mc":[{"id":"1.229554894","rc":[{"atb":[[1.56,5.32],[1.58,0]],"id":70003365}],"con":true,"img":false}]}
{"op":"mcm","clk":"11449965669","pt":1717316480809,"mc":[{"id":"1.229554894","rc":[{"atb":[[2.46,20.42]],"id":70003367},{"atb":[[1.51,58.48]],"id":70003365}],"con":true,"img":false}]}
{"op":"mcm","clk":"11449965677","pt":1717316480913,"mc":[{"id":"1.229554894","rc":[{"atb":[[1.6,0]],"id":70003365},{"trd":[[1.6,26.15]],"ltp":1.6,"tv":26.15,"id":70003365}],"con":true,"img":false}]}
{"op":"mcm","clk":"11449965697","pt":1717316481143,"mc":[{"id":"1.229554894","rc":[{"atb":[[1.6,5.91]],"id":70003365}],"con":true,"img":false}]}
{"op":"mcm","clk":"11449965704","pt":1717316481224,"mc":[{"id":"1.229554894","rc":[{"trd":[[1.61,49.92]],"ltp":1.61,"tv":49.92,"id":70003365},{"atl":[[1.61,18.45]],"id":70003365}],"con":true,"img":false}]}
{"op":"mcm","clk":"11449965745","pt":1717316481801,"mc":[{"id":"1.229554894","rc":[{"atl":[[2.74,0]],"id":70003367}],"con":true,"img":false}]}
{"op":"mcm","clk":"11449965751","pt":1717316481899,"mc":[{"id":"1.229554894","rc":[{"atl":[[3.45,0],[2.76,3.42]],"id":70003367}],"con":true,"img":false}]}
{"op":"mcm","clk":"11449965757","pt":1717316481999,"mc":[{"id":"1.229554894","rc":[{"atl":[[2.72,0]],"id":70003367}],"con":true,"img":false}]}
{"op":"mcm","clk":"11449965762","pt":1717316482110,"mc":[{"id":"1.229554894","rc":[{"atl":[[2.1,11.24],[2.2,0]],"id":70003365}],"con":true,"img":false}]}
{"op":"mcm","clk":"11449965769","pt":1717316482211,"mc":[{"id":"1.229554894","rc":[{"atl":[[2.76,6.68]],"id":70003367}],"con":true,"img":false}]}
{"op":"mcm","clk":"11449965774","pt":1717316482315,"mc":[{"id":"1.229554894","rc":[{"atb":[[1.51,0]],"id":70003365}],"con":true,"img":false}]}
{"op":"mcm","clk":"11449965813","pt":1717316482828,"mc":[{"id":"1.229554894","rc":[{"atb":[[1.51,58.48]],"id":70003365}],"con":true,"img":false}]}
{"op":"mcm","clk":"11449965852","pt":1717316483302,"mc":[{"id":"1.229554894","rc":[{"atb":[[1.47,0]],"id":70003365}],"con":true,"img":false}]}
{"op":"mcm","clk":"11449965860","pt":1717316483402,"mc":[{"id":"1.229554894","rc":[{"atb":[[1.45,26.57]],"id":70003365}],"con":true,"img":false}]}
{"op":"mcm","clk":"11449965907","pt":1717316484022,"mc":[{"id":"1.229554894","rc":[{"atb":[[1.57,0]],"id":70003365}],"con":true,"img":false}]}
{"op":"mcm","clk":"11449965928","pt":1717316484280,"mc":[{"id":"1.229554894","rc":[{"atb":[[1.46,70.3],[1.51,0]],"id":70003365}],"con":true,"img":false}]}
{"op":"mcm","clk":"11449965956","pt":1717316484696,"mc":[{"id":"1.229554894","rc":[{"atl":[[1.61,0]],"id":70003365}],"con":true,"img":false}]}
{"op":"mcm","clk":"11449965962","pt":1717316484798,"mc":[{"id":"1.229554894","rc":[{"atb":[[1.6,0]],"id":70003365},{"trd":[[1.6,37.97]],"ltp":1.6,"tv":37.97,"id":70003365},{"atl":[[1.6,12.54]],"id":70003365}],"con":true,"img":false}]}
{"op":"mcm","clk":"11449965971","pt":1717316484906,"mc":[{"id":"1.229554894","rc":[{"atl":[[2.76,3.42]],"id":70003367},{"atl":[[1.62,0]],"id":70003365}],"con":true,"img":false}]}
