{"op":"mcm","clk":"11448127642","pt":1717286034979,"mc":[{"id":"1.229554921","marketDefinition":{"bspMarket":true,"turnInPlayEnabled":false,"persistenceEnabled":false,"marketBaseRate":7.0,"eventId":"33318908","eventTypeId":"4339","numberOfWinners":2,"bettingType":"ODDS","marketType":"PLACE","marketTime":"2024-06-02T10:24:00.000Z","suspendTime":"2024-06-02T10:24:00.000Z","bspReconciled":false,"complete":true,"inPlay":false,"crossMatching":true,"runnersVoidable":false,"numberOfActiveRunners":7,"betDelay":0,"status":"OPEN","runners":[{"status":"ACTIVE","sortPriority":1,"id":65460404,"name":"1. Give Me Room"},{"status":"ACTIVE","sortPriority":2,"id":52671121,"name":"2. Elegant Ritzy"},{"status":"ACTIVE","sortPriority":3,"id":62262930,"name":"3. Canya Candy"},{"status":"ACTIVE","sortPriority":4,"id":69577417,"name":"4. Alpha Bloke"},{"status":"ACTIVE","sortPriority":5,"id":69421986,"name":"6. Back to Work"},{"status":"ACTIVE","sortPriority":6,"id":64546979,"name":"7. Sheas Entity"},{"status":"ACTIVE","sortPriority":7,"id":70003371,"name":"8. Yumali"}],"regulators":["MR_INT"],"venue":"Murray Bridge","countryCode":"AU","discountAllowed":true,"timezone":"Australia/Adelaide","openDate":"2024-06-02T08:21:00.000Z","version":5962317641,"name":"To Be Placed","eventName":"Murray Bridge (AUS) 2nd Jun"},"rc":[],"con":true,"img":false}]}
{"op":"mcm","clk":"11448258036","pt":1717287872067,"mc":[{"id":"1.229554921","rc":[{"atb":[[1.97,23.94],[1.87,40.04]],"id":52671121},{"atl":[[8.4,0.07]],"id":52671121},{"spn":5.18,"spf":"NaN","id":52671121},{"atb":[[1.82,28.33],[1.72,48.39]],"id":62262930},{"atl":[[7.4,0.08]],"id":62262930},{"spn":4.61,"spf":"NaN","id":62262930},{"atb":[[2.86,18.73],[3.15,10.8]],"id":69577417},{"spn":"Infinity","spf":"NaN","id":69577417},{"atb":[[4.8,6.11],[3.9,12.01]],"id":69421986},{"spn":"Infinity","spf":"NaN","id":69421986},{"atb":[[1.85,40.99],[1.95,24.45]],"id":65460404},{"atl":[[8.2,0.07]],"id":65460404},{"spn":5.07,"spf":"NaN","id":65460404},{"atb":[[2.82,19.14],[3.05,11.33]],"id":64546979},{"spn":"Infinity","spf":"NaN","id":64546979},{"atb":[[1.59,59.05],[1.69,33.66]],"id":70003371},{"atl":[[6.6,0.09]],"id":70003371},{"spn":4.14,"spf":"NaN","id":70003371}],"con":true,"img":false}]}
{"op":"mcm","clk":"11448259658","pt":1717287895503,"mc":[{"id":"1.229554921","rc":[{"atb":[[1.97,0],[1.87,0]],"id":52671121},{"atl":[[8.4,0]],"id":52671121},{"atb":[[1.82,0],[1.72,0]],"id":62262930},{"atl":[[7.4,0]],"id":62262930},{"atb":[[2.86,0],[3.15,0]],"id":69577417},{"atb":[[4.8,0],[3.9,0]],"id":69421986},{"atb":[[1.85,0],[1.95,0]],"id":65460404},{"atl":[[8.2,0]],"id":65460404},{"atb":[[2.82,0],[3.05,0]],"id":64546979},{"atb":[[1.59,0],[1.69,0]],"id":70003371},{"atl":[[6.6,0]],"id":70003371}],"con":true,"img":false}]}
{"op":"mcm","clk":"11448260604","pt":1717287908538,"mc":[{"id":"1.229554921","rc":[{"atb":[[1.99,23.46],[1.89,39.14]],"id":52671121},{"atl":[[8.6,0.06]],"id":52671121},{"atb":[[1.82,28.33],[1.72,48.39]],"id":62262930},{"atl":[[7.4,0.08]],"id":62262930},{"atb":[[2.82,19.14],[3.05,11.33]],"id":69577417},{"atb":[[3.7,12.9],[4.4,6.83]],"id":69421986},{"atb":[[1.83,41.97],[1.93,24.97]],"id":65460404},{"atl":[[8.2,0.07]],"id":65460404},{"atb":[[3.1,11.05],[2.84,18.93]],"id":64546979},{"atb":[[1.73,31.81],[1.63,55.3]],"id":70003371},{"atl":[[6.8,0.08]],"id":70003371}],"con":true,"img":false}]}
{"op":"mcm","clk":"11448264328","pt":1717287962571,"mc":[{"id":"1.229554921","rc":[{"atb":[[1.99,0],[1.89,0]],"id":52671121},{"atl":[[8.6,0]],"id":52671121},{"spn":"NaN","spf":"NaN","id":52671121},{"atb":[[1.82,0],[1.72,0]],"id":62262930},{"atl":[[7.4,0]],"id":62262930},{"spn":"NaN","spf":"NaN","id":62262930},{"atb":[[2.82,0],[3.05,0]],"id":69577417},{"spn":"NaN","spf":"NaN","id":69577417},{"atb":[[3.7,0],[4.4,0]],"id":69421986},{"spn":"NaN","spf":"NaN","id":69421986},{"atb":[[1.83,0],[1.93,0]],"id":65460404},{"atl":[[8.2,0]],"id":65460404},{"spn":"NaN","spf":"NaN","id":65460404},{"atb":[[3.1,0],[2.84,0]],"id":64546979},{"spn":"NaN","spf":"NaN","id":64546979},{"atb":[[1.73,0],[1.63,0]],"id":70003371},{"atl":[[6.8,0]],"id":70003371},{"spn":"NaN","spf":"NaN","id":70003371}],"con":true,"img":false}]}
{"op":"mcm","clk":"11448265026","pt":1717287972421,"mc":[{"id":"1.229554921","rc":[{"atb":[[1.83,41.97],[1.93,24.97]],"id":52671121},{"atl":[[8.2,0.07]],"id":52671121},{"atb":[[1.84,27.65],[1.74,47.08]],"id":62262930},{"atl":[[7.6,0.07]],"id":62262930},{"atb":[[2.82,19.14],[3.05,11.33]],"id":69577417},{"atb":[[4.5,6.63],[3.75,12.67]],"id":69421986},{"atb":[[2,23.22],[1.9,38.71]],"id":65460404},{"atl":[[8.6,0.06]],"id":65460404},{"atb":[[3.1,11.05],[2.84,18.93]],"id":64546979},{"atb":[[1.6,58.07],[1.7,33.18]],"id":70003371},{"atl":[[6.6,0.09]],"id":70003371}],"con":true,"img":false}]}
{"op":"mcm","clk":"11448277247","pt":1717288128429,"mc":[{"id":"1.229554921","marketDefinition":{"bspMarket":true,"turnInPlayEnabled":false,"persistenceEnabled":false,"marketBaseRate":7.0,"eventId":"33318908","eventTypeId":"4339","numberOfWinners":2,"bettingType":"ODDS","marketType":"PLACE","marketTime":"2024-06-02T10:24:00.000Z","suspendTime":"2024-06-02T10:24:00.000Z","bspReconciled":false,"complete":true,"inPlay":false,"crossMatching":true,"runnersVoidable":false,"numberOfActiveRunners":7,"betDelay":0,"status":"OPEN","runners":[{"status":"ACTIVE","sortPriority":1,"id":65460404,"name":"1. Give Me Room"},{"status":"ACTIVE","sortPriority":2,"id":52671121,"name":"2. Elegant Ritzy"},{"status":"ACTIVE","sortPriority":3,"id":62262930,"name":"3. Canya Candy"},{"status":"ACTIVE","sortPriority":4,"id":69577417,"name":"4. Alpha Bloke"},{"status":"ACTIVE","sortPriority":5,"id":69421986,"name":"6. Back to Work"},{"status":"ACTIVE","sortPriority":6,"id":64546979,"name":"7. Sheas Entity"},{"status":"ACTIVE","sortPriority":7,"id":70003371,"name":"8. Yumali"}],"regulators":["MR_INT"],"venue":"Murray Bridge","countryCode":"AU","discountAllowed":true,"timezone":"Australia/Adelaide","openDate":"2024-06-02T08:21:00.000Z","version":5962317641,"name":"To Be Placed","eventName":"Murray Bridge (AUS) 2nd Jun"},"rc":[{"atb":[[1.83,41.97],[1.93,24.97]],"id":52671121},{"atl":[[8.2,0.07]],"id":52671121},{"spn":5.06,"spf":"NaN","id":52671121},{"atb":[[1.84,27.65],[1.74,47.08]],"id":62262930},{"atl":[[7.6,0.07]],"id":62262930},{"spn":4.72,"spf":"NaN","id":62262930},{"atb":[[2.82,19.14],[3.05,11.33]],"id":69577417},{"spn":"Infinity","spf":"NaN","id":69577417},{"atb":[[4.5,6.63],[3.75,12.67]],"id":69421986},{"spn":"Infinity","spf":"NaN","id":69421986},{"atb":[[2,23.22],[1.9,38.71]],"id":65460404},{"atl":[[8.6,0.06]],"id":65460404},{"spn":5.3,"spf":"NaN","id":65460404},{"atb":[[3.1,11.05],[2.84,18.93]],"id":64546979},{"spn":"Infinity","spf":"NaN","id":64546979},{"atb":[[1.6,58.07],[1.7,33.18]],"id":70003371},{"atl":[[6.6,0.09]],"id":70003371},{"spn":4.15,"spf":"NaN","id":70003371}],"con":true,"img":true}]}
{"op":"mcm","clk":"11448289496","pt":1717288232637,"mc":[{"id":"1.229554921","rc":[{"atb":[[1.83,0],[1.93,0]],"id":52671121},{"atl":[[8.2,0]],"id":52671121},{"spn":4.72,"spf":"NaN","id":62262930},{"atb":[[2.82,0],[3.05,0]],"id":69577417},{"spn":"Infinity","spf":"NaN","id":69421986},{"spn":5.3,"spf":"NaN","id":65460404},{"atb":[[3.1,0],[2.84,0]],"id":64546979},{"spn":4.15,"spf":"NaN","id":70003371}],"con":true,"img":false}]}
{"op":"mcm","clk":"11448290414","pt":1717288245743,"mc":[{"id":"1.229554921","rc":[{"atb":[[1.98,23.7],[1.88,39.59]],"id":52671121},{"atl":[[8.4,0.07]],"id":52671121},{"atb":[[2.86,18.73],[3.15,10.8]],"id":69577417},{"atb":[[2.86,18.73],[3.15,10.8]],"id":64546979}],"con":true,"img":false}]}
{"op":"mcm","clk":"11448292481","pt":1717288274170,"mc":[{"id":"1.229554921","rc":[{"atb":[[1.98,0],[1.88,0]],"id":52671121},{"atl":[[8.4,0]],"id":52671121},{"atb":[[4.5,0],[3.75,0]],"id":69421986},{"atb":[[2.86,0],[3.15,0]],"id":64546979},{"atb":[[1.6,0],[1.7,0]],"id":70003371},{"atl":[[6.6,0]],"id":70003371}],"con":true,"img":false}]}
{"op":"mcm","clk":"11448293813","pt":1717288291678,"mc":[{"id":"1.229554921","rc":[{"atb":[[1.96,24.19],[1.86,40.51]],"id":52671121},{"atl":[[8.4,0.07]],"id":52671121},{"atb":[[4.6,6.45],[3.8,12.44]],"id":69421986},{"atb":[[3.2,10.55],[2.88,18.53]],"id":64546979},{"atb":[[1.58,60.07],[1.68,34.15]],"id":70003371},{"atl":[[6.4,0.09]],"id":70003371}],"con":true,"img":false}]}
{"op":"mcm","clk":"11448298280","pt":1717288351487,"mc":[{"id":"1.229554921","rc":[{"spn":5.18,"spf":"NaN","id":52671121},{"atb":[[2.86,0],[3.15,0]],"id":69577417},{"spn":"Infinity","spf":"NaN","id":64546979},{"atb":[[1.58,0],[1.68,0]],"id":70003371},{"atl":[[6.4,0]],"id":70003371},{"spn":"NaN","spf":"NaN","id":70003371}],"con":true,"img":false}]}
{"op":"mcm","clk":"11448300795","pt":1717288383947,"mc":[{"id":"1.229554921","rc":[{"atb":[[2.82,19.14],[3.05,11.33]],"id":69577417},{"atb":[[1.58,60.07],[1.68,34.15]],"id":70003371},{"atl":[[6.4,0.09]],"id":70003371}],"con":true,"img":false}]}
{"op":"mcm","clk":"11448333303","pt":1717288850361,"mc":[{"id":"1.229554921","rc":[{"atb":[[1.96,0],[1.86,0]],"id":52671121},{"atl":[[8.4,0]],"id":52671121},{"spn":"NaN","spf":"NaN","id":52671121},{"spn":"Infinity","spf":"NaN","id":69577417},{"atb":[[4.6,0],[3.8,0]],"id":69421986},{"spn":"NaN","spf":"NaN","id":69421986},{"atb":[[3.2,0],[2.88,0]],"id":64546979},{"spn":"NaN","spf":"NaN","id":64546979},{"spn":4.04,"spf":"NaN","id":70003371}],"con":true,"img":false}]}
{"op":"mcm","clk":"11448333837","pt":1717288858085,"mc":[{"id":"1.229554921","rc":[{"atb":[[2,23.22],[1.9,38.71]],"id":52671121},{"atl":[[8.6,0.06]],"id":52671121},{"atb":[[3.85,12.22],[4.7,6.27]],"id":69421986},{"atb":[[2.9,18.33],[3.25,10.32]],"id":64546979}],"con":true,"img":false}]}
{"op":"mcm","clk":"11448334392","pt":1717288865050,"mc":[{"id":"1.229554921","rc":[{"atb":[[2,0],[1.9,0]],"id":52671121},{"atl":[[8.6,0]],"id":52671121},{"atb":[[1.84,0],[1.74,0]],"id":62262930},{"atl":[[7.6,0]],"id":62262930},{"atb":[[2.82,0],[3.05,0]],"id":69577417},{"atb":[[3.85,0],[4.7,0]],"id":69421986},{"atb":[[2.9,0],[3.25,0]],"id":64546979},{"atb":[[1.58,0],[1.68,0]],"id":70003371},{"atl":[[6.4,0]],"id":70003371}],"con":true,"img":false}]}
{"op":"mcm","clk":"11448334643","pt":1717288868471,"mc":[{"id":"1.229554921","rc":[{"atb":[[1.86,27.01],[1.76,45.84]],"id":52671121},{"atl":[[7.6,0.07]],"id":52671121},{"atb":[[1.8,29.03],[1.7,49.77]],"id":62262930},{"atl":[[7.2,0.08]],"id":62262930},{"atb":[[2.86,18.73],[3.15,10.8]],"id":69577417},{"atb":[[3.95,11.81],[4.9,5.95]],"id":69421986},{"atb":[[3.4,9.67],[2.96,17.77]],"id":64546979},{"atb":[[1.71,32.71],[1.61,57.12]],"id":70003371},{"atl":[[6.6,0.09]],"id":70003371}],"con":true,"img":false}]}
{"op":"mcm","clk":"11448337342","pt":1717288902695,"mc":[{"id":"1.229554921","rc":[{"atb":[[1.86,0],[1.76,0]],"id":52671121},{"atl":[[7.6,0]],"id":52671121},{"atb":[[1.8,0],[1.7,0]],"id":62262930},{"atl":[[7.2,0]],"id":62262930},{"atb":[[3.95,0],[4.9,0]],"id":69421986},{"atb":[[2,0],[1.9,0]],"id":65460404},{"atl":[[8.6,0]],"id":65460404},{"atb":[[3.4,0],[2.96,0]],"id":64546979}],"con":true,"img":false}]}
{"op":"mcm","clk":"11448338017","pt":1717288911145,"mc":[{"id":"1.229554921","rc":[{"atb":[[1.86,27.01],[1.76,45.84]],"id":52671121},{"atl":[[7.6,0.07]],"id":52671121},{"spn":4.73,"spf":"NaN","id":52671121},{"atb":[[1.73,47.72],[1.83,27.98]],"id":62262930},{"atl":[[7.4,0.08]],"id":62262930},{"spn":4.61,"spf":"NaN","id":62262930},{"atb":[[4.5,6.63],[3.75,12.67]],"id":69421986},{"spn":"Infinity","spf":"NaN","id":69421986},{"atb":[[1.84,41.48],[1.94,24.7]],"id":65460404},{"atl":[[8.2,0.07]],"id":65460404},{"spn":5.07,"spf":"NaN","id":65460404},{"atb":[[2.92,18.14],[3.3,10.09]],"id":64546979},{"spn":"Infinity","spf":"NaN","id":64546979},{"spn":4.15,"spf":"NaN","id":70003371}],"con":true,"img":false}]}
{"op":"mcm","clk":"11448340009","pt":1717288935857,"mc":[{"id":"1.229554921","rc":[{"atb":[[1.86,0],[1.76,0]],"id":52671121},{"atl":[[7.6,0]],"id":52671121},{"atb":[[1.73,0],[1.83,0]],"id":62262930},{"atl":[[7.4,0]],"id":62262930},{"atb":[[4.5,0],[3.75,0]],"id":69421986},{"atb":[[1.84,0],[1.94,0]],"id":65460404},{"atl":[[8.2,0]],"id":65460404}],"con":true,"img":false}]}
{"op":"mcm","clk":"11448341146","pt":1717288949762,"mc":[{"id":"1.229554921","rc":[{"atb":[[1.73,47.72],[1.83,27.98]],"id":52671121},{"atl":[[7.4,0.08]],"id":52671121},{"atb":[[1.82,28.33],[1.72,48.39]],"id":62262930},{"atl":[[7.4,0.08]],"id":62262930},{"atb":[[4.8,6.11],[3.9,12.01]],"id":69421986},{"atb":[[1.98,23.7],[1.88,39.59]],"id":65460404},{"atl":[[8.4,0.07]],"id":65460404}],"con":true,"img":false}]}
{"op":"mcm","clk":"11448344112","pt":1717288986613,"mc":[{"id":"1.229554921","rc":[{"atb":[[1.73,0],[1.83,0]],"id":52671121},{"atl":[[7.4,0]],"id":52671121},{"spn":"NaN","spf":"NaN","id":52671121},{"atb":[[1.82,0],[1.72,0]],"id":62262930},{"atl":[[7.4,0]],"id":62262930},{"spn":"NaN","spf":"NaN","id":62262930},{"atb":[[2.86,0],[3.15,0]],"id":69577417},{"spn":"NaN","spf":"NaN","id":69577417},{"atb":[[4.8,0],[3.9,0]],"id":69421986},{"spn":"NaN","spf":"NaN","id":69421986},{"atb":[[1.98,0],[1.88,0]],"id":65460404},{"atl":[[8.4,0]],"id":65460404},{"spn":"NaN","spf":"NaN","id":65460404},{"atb":[[2.92,0],[3.3,0]],"id":64546979},{"spn":"NaN","spf":"NaN","id":64546979}],"con":true,"img":false}]}
{"op":"mcm","clk":"11448345399","pt":1717289003637,"mc":[{"id":"1.229554921","rc":[{"atb":[[1.73,47.72],[1.83,27.98]],"id":52671121},{"atl":[[7.4,0.08]],"id":52671121},{"atb":[[1.86,27.01],[1.76,45.84]],"id":62262930},{"atl":[[7.6,0.07]],"id":62262930},{"atb":[[3.1,11.05],[2.84,18.93]],"id":69577417},{"atb":[[5.2,5.52],[4.2,10.88]],"id":69421986},{"atb":[[1.96,24.19],[1.86,40.51]],"id":65460404},{"atl":[[8.4,0.07]],"id":65460404},{"atb":[[3.4,9.67],[2.96,17.77]],"id":64546979}],"con":true,"img":false}]}
{"op":"mcm","clk":"11448348105","pt":1717289037488,"mc":[{"id":"1.229554921","rc":[{"atb":[[1.73,0],[1.83,0]],"id":52671121},{"atl":[[7.4,0]],"id":52671121},{"atb":[[3.1,0],[2.84,0]],"id":69577417}],"con":true,"img":false}]}
{"op":"mcm","clk":"11448348777","pt":1717289046331,"mc":[{"id":"1.229554921","rc":[{"atb":[[1.82,28.33],[1.72,48.39]],"id":52671121},{"atl":[[7.4,0.08]],"id":52671121},{"atb":[[2.82,19.14],[3.05,11.33]],"id":69577417}],"con":true,"img":false}]}
{"op":"mcm","clk":"11448361840","pt":1717289213256,"mc":[{"id":"1.229554921","rc":[{"atb":[[1.82,0],[1.72,0]],"id":52671121},{"atl":[[7.4,0]],"id":52671121},{"atb":[[1.86,0],[1.76,0]],"id":62262930},{"atl":[[7.6,0]],"id":62262930},{"spn":"Infinity","spf":"NaN","id":69577417},{"atb":[[5.2,0],[4.2,0]],"id":69421986},{"spn":5.18,"spf":"NaN","id":65460404},{"spn":"Infinity","spf":"NaN","id":64546979}],"con":true,"img":false}]}
{"op":"mcm","clk":"11448362206","pt":1717289218276,"mc":[{"id":"1.229554921","rc":[{"atb":[[1.64,54.44],[1.74,31.39]],"id":52671121},{"atl":[[6.8,0.08]],"id":52671121},{"atb":[[1.79,44.1],[1.89,26.1]],"id":62262930},{"atl":[[7.8,0.07]],"id":62262930},{"atb":[[4.3,10.55],[5.3,5.4]],"id":69421986}],"con":true,"img":false}]}
{"op":"mcm","clk":"11448367939","pt":1717289300806,"mc":[{"id":"1.229554921","rc":[{"atb":[[1.64,0],[1.74,0]],"id":52671121},{"atl":[[6.8,0]],"id":52671121},{"atb":[[1.79,0],[1.89,0]],"id":62262930},{"atl":[[7.8,0]],"id":62262930},{"atb":[[2.82,0],[3.05,0]],"id":69577417},{"spn":"NaN","spf":"NaN","id":69577417},{"atb":[[4.3,0],[5.3,0]],"id":69421986},{"atb":[[1.96,0],[1.86,0]],"id":65460404},{"atl":[[8.4,0]],"id":65460404},{"spn":"NaN","spf":"NaN","id":65460404},{"atb":[[3.4,0],[2.96,0]],"id":64546979},{"spn":"NaN","spf":"NaN","id":64546979}],"con":true,"img":false}]}
{"op":"mcm","clk":"11448368462","pt":1717289309031,"mc":[{"id":"1.229554921","rc":[{"atb":[[1.72,32.26],[1.62,56.19]],"id":52671121},{"atl":[[6.8,0.08]],"id":52671121},{"atb":[[1.8,43.55],[1.9,25.8]],"id":62262930},{"atl":[[8,0.07]],"id":62262930},{"atb":[[3.1,11.05],[2.84,18.93]],"id":69577417},{"atb":[[4.3,10.55],[5.3,5.4]],"id":69421986},{"atb":[[2.06,21.91],[1.93,37.46]],"id":65460404},{"atl":[[9,0.06]],"id":65460404},{"atb":[[3.45,9.47],[2.98,17.59]],"id":64546979}],"con":true,"img":false}]}
{"op":"mcm","clk":"11448370211","pt":1717289334655,"mc":[{"id":"1.229554921","rc":[{"atb":[[1.72,0],[1.62,0]],"id":52671121},{"atl":[[6.8,0]],"id":52671121},{"atb":[[3.1,0],[2.84,0]],"id":69577417},{"atb":[[4.3,0],[5.3,0]],"id":69421986},{"atb":[[2.06,0],[1.93,0]],"id":65460404},{"atl":[[9,0]],"id":65460404},{"atb":[[3.45,0],[2.98,0]],"id":64546979}],"con":true,"img":false}]}
{"op":"mcm","clk":"11448371094","pt":1717289347354,"mc":[{"id":"1.229554921","rc":[{"atb":[[1.71,32.71],[1.61,57.12]],"id":52671121},{"atl":[[6.6,0.09]],"id":52671121},{"atb":[[3.1,11.05],[2.84,18.93]],"id":69577417},{"atb":[[4.5,9.95],[5.5,5.16]],"id":69421986},{"atb":[[2.02,22.77],[1.91,38.29]],"id":65460404},{"atl":[[8.6,0.06]],"id":65460404},{"atb":[[3.55,9.1],[3.05,16.99]],"id":64546979}],"con":true,"img":false}]}
{"op":"mcm","clk":"11448375264","pt":1717289407363,"mc":[{"id":"1.229554921","rc":[{"atb":[[1.71,0],[1.61,0]],"id":52671121},{"atl":[[6.6,0]],"id":52671121},{"spn":4.95,"spf":"NaN","id":62262930},{"spn":"Infinity","spf":"NaN","id":69577417},{"spn":"Infinity","spf":"NaN","id":69421986},{"atb":[[2.02,0],[1.91,0]],"id":65460404},{"atl":[[8.6,0]],"id":65460404},{"spn":"Infinity","spf":"NaN","id":64546979}],"con":true,"img":false}]}
{"op":"mcm","clk":"11448375724","pt":1717289413579,"mc":[{"id":"1.229554921","rc":[{"atb":[[1.73,31.81],[1.63,55.3]],"id":52671121},{"atl":[[6.8,0.08]],"id":52671121},{"atb":[[1.97,23.94],[1.87,40.04]],"id":65460404},{"atl":[[8.4,0.07]],"id":65460404}],"con":true,"img":false}]}
{"op":"mcm","clk":"11448376631","pt":1717289426362,"mc":[{"id":"1.229554921","rc":[{"atb":[[3.1,0],[2.84,0]],"id":69577417},{"atb":[[4.5,0],[5.5,0]],"id":69421986}],"con":true,"img":false}]}
{"op":"mcm","clk":"11448377226","pt":1717289434418,"mc":[{"id":"1.229554921","rc":[{"atb":[[2.9,18.33],[3.25,10.32]],"id":69577417},{"atb":[[4.5,9.95],[5.5,5.16]],"id":69421986}],"con":true,"img":false}]}
{"op":"mcm","clk":"11448378852","pt":1717289456920,"mc":[{"id":"1.229554921","rc":[{"atb":[[1.73,0],[1.63,0]],"id":52671121},{"atl":[[6.8,0]],"id":52671121},{"atb":[[4.5,0],[5.5,0]],"id":69421986},{"atb":[[1.97,0],[1.87,0]],"id":65460404},{"atl":[[8.4,0]],"id":65460404}],"con":true,"img":false}]}
{"op":"mcm","clk":"11448379529","pt":1717289465530,"mc":[{"id":"1.229554921","rc":[{"atb":[[1.73,31.81],[1.63,55.3]],"id":52671121},{"atl":[[6.8,0.08]],"id":52671121},{"atb":[[4.5,9.95],[5.5,5.16]],"id":69421986},{"atb":[[1.99,23.46],[1.89,39.14]],"id":65460404},{"atl":[[8.6,0.06]],"id":65460404}],"con":true,"img":false}]}
{"op":"mcm","clk":"11448381074","pt":1717289487539,"mc":[{"id":"1.229554921","rc":[{"atb":[[1.73,0],[1.63,0]],"id":52671121},{"atl":[[6.8,0]],"id":52671121},{"atb":[[1.8,0],[1.9,0]],"id":62262930},{"atl":[[8,0]],"id":62262930},{"spn":"NaN","spf":"NaN","id":62262930},{"atb":[[2.9,0],[3.25,0]],"id":69577417},{"spn":"NaN","spf":"NaN","id":69577417},{"atb":[[4.5,0],[5.5,0]],"id":69421986},{"spn":"NaN","spf":"NaN","id":69421986},{"atb":[[1.99,0],[1.89,0]],"id":65460404},{"atl":[[8.6,0]],"id":65460404},{"atb":[[3.55,0],[3.05,0]],"id":64546979},{"spn":"NaN","spf":"NaN","id":64546979},{"atb":[[1.71,0],[1.61,0]],"id":70003371},{"atl":[[6.6,0]],"id":70003371},{"spn":"NaN","spf":"NaN","id":70003371}],"con":true,"img":false}]}
{"op":"mcm","clk":"11448381758","pt":1717289496483,"mc":[{"id":"1.229554921","rc":[{"atb":[[1.72,32.26],[1.62,56.19]],"id":52671121},{"atl":[[6.8,0.08]],"id":52671121},{"atb":[[1.86,27.01],[1.76,45.84]],"id":62262930},{"atl":[[7.6,0.07]],"id":62262930},{"atb":[[2.9,18.33],[3.25,10.32]],"id":69577417},{"atb":[[4.3,10.55],[5.3,5.4]],"id":69421986},{"atb":[[1.94,37.06],[2.08,21.5]],"id":65460404},{"atl":[[9.2,0.06]],"id":65460404},{"atb":[[3.4,9.67],[2.96,17.77]],"id":64546979},{"atb":[[1.58,60.07],[1.68,34.15]],"id":70003371},{"atl":[[6.4,0.09]],"id":70003371}],"con":true,"img":false}]}
{"op":"mcm","clk":"11448383601","pt":1717289521104,"mc":[{"id":"1.229554921","rc":[{"atb":[[1.72,0],[1.62,0]],"id":52671121},{"atl":[[6.8,0]],"id":52671121},{"atb":[[1.86,0],[1.76,0]],"id":62262930},{"atl":[[7.6,0]],"id":62262930},{"atb":[[4.3,0],[5.3,0]],"id":69421986},{"atb":[[1.94,0],[2.08,0]],"id":65460404},{"atl":[[9.2,0]],"id":65460404}],"con":true,"img":false}]}
{"op":"mcm","clk":"11448384375","pt":1717289531138,"mc":[{"id":"1.229554921","rc":[{"atb":[[1.6,58.07],[1.7,33.18]],"id":52671121},{"atl":[[6.6,0.09]],"id":52671121},{"atb":[[1.88,26.39],[1.78,44.66]],"id":62262930},{"atl":[[7.8,0.07]],"id":62262930},{"atb":[[4.9,8.93],[5.9,4.73]],"id":69421986},{"atb":[[2.02,22.77],[1.91,38.29]],"id":65460404},{"atl":[[8.6,0.06]],"id":65460404}],"con":true,"img":false}]}
{"op":"mcm","clk":"11448452965","pt":1717290537252,"mc":[{"id":"1.229554921","rc":[{"atb":[[1.6,0],[1.7,0]],"id":52671121},{"atl":[[6.6,0]],"id":52671121},{"atb":[[1.88,0],[1.78,0]],"id":62262930},{"atl":[[7.8,0]],"id":62262930},{"atb":[[2.9,0],[3.25,0]],"id":69577417},{"atb":[[4.9,0],[5.9,0]],"id":69421986},{"atb":[[2.02,0],[1.91,0]],"id":65460404},{"atl":[[8.6,0]],"id":65460404},{"atb":[[3.4,0],[2.96,0]],"id":64546979},{"atb":[[1.58,0],[1.68,0]],"id":70003371},{"atl":[[6.4,0]],"id":70003371}],"con":true,"img":false}]}
{"op":"mcm","clk":"11448453477","pt":1717290545756,"mc":[{"id":"1.229554921","rc":[{"atb":[[1.72,32.26],[1.62,56.19]],"id":52671121},{"atl":[[6.8,0.08]],"id":52671121},{"atb":[[1.85,40.99],[1.95,24.45]],"id":62262930},{"atl":[[8.2,0.07]],"id":62262930},{"atb":[[3.35,9.88],[2.94,17.96]],"id":69577417},{"atb":[[6.4,4.3],[5.2,8.29]],"id":69421986},{"atb":[[1.67,52],[1.77,30.16]],"id":65460404},{"atl":[[7,0.08]],"id":65460404},{"atb":[[3.85,8.15],[3.35,14.82]],"id":64546979},{"atb":[[1.6,58.07],[1.7,33.18]],"id":70003371},{"atl":[[6.6,0.09]],"id":70003371}],"con":true,"img":false}]}
{"op":"mcm","clk":"11448454336","pt":1717290557091,"mc":[{"id":"1.229554921","rc":[{"atb":[[1.72,0],[1.62,0]],"id":52671121},{"atl":[[6.8,0]],"id":52671121},{"atb":[[3.35,0],[2.94,0]],"id":69577417},{"atb":[[6.4,0],[5.2,0]],"id":69421986},{"atb":[[1.67,0],[1.77,0]],"id":65460404},{"atl":[[7,0]],"id":65460404},{"atb":[[3.85,0],[3.35,0]],"id":64546979},{"atb":[[1.6,0],[1.7,0]],"id":70003371},{"atl":[[6.6,0]],"id":70003371}],"con":true,"img":false}]}
{"op":"mcm","clk":"11448454922","pt":1717290565164,"mc":[{"id":"1.229554921","rc":[{"atb":[[1.75,30.97],[1.65,53.6]],"id":52671121},{"atl":[[7,0.08]],"id":52671121},{"atb":[[3.35,9.88],[2.94,17.96]],"id":69577417},{"atb":[[4.4,10.24],[5.4,5.27]],"id":69421986},{"atb":[[1.79,29.4],[1.69,50.49]],"id":65460404},{"atl":[[7.2,0.08]],"id":65460404},{"atb":[[3.4,14.51],[3.9,8]],"id":64546979},{"atb":[[1.57,61.12],[1.67,34.67]],"id":70003371},{"atl":[[6.4,0.09]],"id":70003371}],"con":true,"img":false}]}
{"op":"mcm","clk":"11448455687","pt":1717290577115,"mc":[{"id":"1.229554921","rc":[{"atb":[[1.75,0],[1.65,0]],"id":52671121},{"atl":[[7,0]],"id":52671121},{"atb":[[1.85,0],[1.95,0]],"id":62262930},{"atl":[[8.2,0]],"id":62262930},{"atb":[[3.35,0],[2.94,0]],"id":69577417},{"atb":[[4.4,0],[5.4,0]],"id":69421986},{"atb":[[1.79,0],[1.69,0]],"id":65460404},{"atl":[[7.2,0]],"id":65460404},{"atb":[[3.4,0],[3.9,0]],"id":64546979}],"con":true,"img":false}]}
{"op":"mcm","clk":"11448456054","pt":1717290583503,"mc":[{"id":"1.229554921","rc":[{"atb":[[1.73,31.81],[1.63,55.3]],"id":52671121},{"atl":[[6.8,0.08]],"id":52671121},{"atb":[[1.98,23.7],[1.88,39.59]],"id":62262930},{"atl":[[8.4,0.07]],"id":62262930},{"atb":[[3.35,9.88],[2.94,17.96]],"id":69577417},{"atb":[[4.8,9.17],[5.8,4.83]],"id":69421986},{"atb":[[1.75,30.97],[1.65,53.6]],"id":65460404},{"atl":[[7,0.08]],"id":65460404},{"atb":[[3.8,8.29],[3.3,15.15]],"id":64546979}],"con":true,"img":false}]}
{"op":"mcm","clk":"11448459594","pt":1717290647490,"mc":[{"id":"1.229554921","rc":[{"atb":[[1.73,0],[1.63,0]],"id":52671121},{"atl":[[6.8,0]],"id":52671121},{"atb":[[1.98,0],[1.88,0]],"id":62262930},{"atl":[[8.4,0]],"id":62262930},{"atb":[[3.35,0],[2.94,0]],"id":69577417},{"atb":[[4.8,0],[5.8,0]],"id":69421986},{"atb":[[1.75,0],[1.65,0]],"id":65460404},{"atl":[[7,0]],"id":65460404},{"atb":[[3.8,0],[3.3,0]],"id":64546979},{"atb":[[1.57,0],[1.67,0]],"id":70003371},{"atl":[[6.4,0]],"id":70003371}],"con":true,"img":false}]}
{"op":"mcm","clk":"11448459972","pt":1717290655707,"mc":[{"id":"1.229554921","rc":[{"atb":[[1.71,32.71],[1.61,57.12]],"id":52671121},{"atl":[[6.6,0.09]],"id":52671121},{"atb":[[1.84,41.48],[1.94,24.7]],"id":62262930},{"atl":[[8.2,0.07]],"id":62262930},{"atb":[[3.4,9.67],[2.96,17.77]],"id":69577417},{"atb":[[5.1,8.49],[6.2,4.46]],"id":69421986},{"atb":[[1.79,29.4],[1.69,50.49]],"id":65460404},{"atl":[[7.2,0.08]],"id":65460404},{"atb":[[3.85,8.15],[3.35,14.82]],"id":64546979},{"atb":[[1.6,58.07],[1.7,33.18]],"id":70003371},{"atl":[[6.6,0.09]],"id":70003371}],"con":true,"img":false}]}
{"op":"mcm","clk":"11448461417","pt":1717290680524,"mc":[{"id":"1.229554921","rc":[{"atb":[[5.1,0],[6.2,0]],"id":69421986},{"atb":[[3.85,0],[3.35,0]],"id":64546979}],"con":true,"img":false}]}
{"op":"mcm","clk":"11448462200","pt":1717290691801,"mc":[{"id":"1.229554921","rc":[{"atb":[[4.9,8.93],[5.9,4.73]],"id":69421986},{"atb":[[4,7.74],[3.5,13.93]],"id":64546979}],"con":true,"img":false}]}
{"op":"mcm","clk":"11448463739","pt":1717290717742,"mc":[{"id":"1.229554921","rc":[{"atb":[[1.71,0],[1.61,0]],"id":52671121},{"atl":[[6.6,0]],"id":52671121},{"atb":[[1.84,0],[1.94,0]],"id":62262930},{"atl":[[8.2,0]],"id":62262930},{"spn":"Infinity","spf":"NaN","id":69577417},{"atb":[[4.9,0],[5.9,0]],"id":69421986},{"atb":[[1.79,0],[1.69,0]],"id":65460404},{"atl":[[7.2,0]],"id":65460404},{"atb":[[4,0],[3.5,0]],"id":64546979},{"atb":[[1.6,0],[1.7,0]],"id":70003371},{"atl":[[6.6,0]],"id":70003371}],"con":true,"img":false}]}
{"op":"mcm","clk":"11448464660","pt":1717290732657,"mc":[{"id":"1.229554921","rc":[{"atb":[[1.73,31.81],[1.63,55.3]],"id":52671121},{"atl":[[6.8,0.08]],"id":52671121},{"atb":[[1.97,23.94],[1.87,40.04]],"id":62262930},{"atl":[[8.4,0.07]],"id":62262930},{"atb":[[5,8.71],[6,4.64]],"id":69421986},{"atb":[[1.64,54.44],[1.74,31.39]],"id":65460404},{"atl":[[6.8,0.08]],"id":65460404},{"atb":[[3.25,15.48],[3.75,8.44]],"id":64546979},{"atb":[[1.6,58.07],[1.7,33.18]],"id":70003371},{"atl":[[6.6,0.09]],"id":70003371}],"con":true,"img":false}]}
{"op":"mcm","clk":"11448465960","pt":1717290755917,"mc":[{"id":"1.229554921","rc":[{"atb":[[1.73,0],[1.63,0]],"id":52671121},{"atl":[[6.8,0]],"id":52671121},{"atb":[[5,0],[6,0]],"id":69421986},{"atb":[[1.64,0],[1.74,0]],"id":65460404},{"atl":[[6.8,0]],"id":65460404}],"con":true,"img":false}]}
{"op":"mcm","clk":"11448466590","pt":1717290765676,"mc":[{"id":"1.229554921","rc":[{"atb":[[1.72,32.26],[1.62,56.19]],"id":52671121},{"atl":[[6.8,0.08]],"id":52671121},{"atb":[[5.3,8.1],[6.6,4.14]],"id":69421986},{"atb":[[1.66,52.79],[1.76,30.56]],"id":65460404},{"atl":[[7,0.08]],"id":65460404}],"con":true,"img":false}]}
{"op":"mcm","clk":"11448467888","pt":1717290786624,"mc":[{"id":"1.229554921","rc":[{"atb":[[1.72,0],[1.62,0]],"id":52671121},{"atl":[[6.8,0]],"id":52671121},{"atb":[[1.97,0],[1.87,0]],"id":62262930},{"atl":[[8.4,0]],"id":62262930},{"atb":[[5.3,0],[6.6,0]],"id":69421986},{"atb":[[1.66,0],[1.76,0]],"id":65460404},{"atl":[[7,0]],"id":65460404},{"spn":"Infinity","spf":"NaN","id":64546979},{"atb":[[1.6,0],[1.7,0]],"id":70003371},{"atl":[[6.6,0]],"id":70003371}],"con":true,"img":false}]}
{"op":"mcm","clk":"11448468353","pt":1717290794328,"mc":[{"id":"1.229554921","rc":[{"atb":[[1.6,58.07],[1.7,33.18]],"id":52671121},{"atl":[[6.6,0.09]],"id":52671121},{"atb":[[1.82,42.49],[1.92,25.24]],"id":62262930},{"atl":[[8,0.07]],"id":62262930},{"atb":[[5.6,5.04],[4.6,9.67]],"id":69421986},{"atb":[[1.78,29.77],[1.68,51.23]],"id":65460404},{"atl":[[7.2,0.08]],"id":65460404},{"atb":[[1.73,31.81],[1.63,55.3]],"id":70003371},{"atl":[[6.8,0.08]],"id":70003371}],"con":true,"img":false}]}
{"op":"mcm","clk":"11448629980","pt":1717293528420,"mc":[{"id":"1.229554921","marketDefinition":{"bspMarket":true,"turnInPlayEnabled":false,"persistenceEnabled":false,"marketBaseRate":7.0,"eventId":"33318908","eventTypeId":"4339","numberOfWinners":2,"bettingType":"ODDS","marketType":"PLACE","marketTime":"2024-06-02T10:24:00.000Z","suspendTime":"2024-06-02T10:24:00.000Z","bspReconciled":false,"complete":true,"inPlay":false,"crossMatching":true,"runnersVoidable":false,"numberOfActiveRunners":7,"betDelay":0,"status":"OPEN","runners":[{"status":"ACTIVE","sortPriority":1,"id":65460404,"name":"1. Give Me Room"},{"status":"ACTIVE","sortPriority":2,"id":52671121,"name":"2. Elegant Ritzy"},{"status":"ACTIVE","sortPriority":3,"id":62262930,"name":"3. Canya Candy"},{"status":"ACTIVE","sortPriority":4,"id":69577417,"name":"4. Alpha Bloke"},{"status":"ACTIVE","sortPriority":5,"id":69421986,"name":"6. Back to Work"},{"status":"ACTIVE","sortPriority":6,"id":64546979,"name":"7. Sheas Entity"},{"status":"ACTIVE","sortPriority":7,"id":70003371,"name":"8. Yumali"}],"regulators":["MR_INT"],"venue":"Murray Bridge","countryCode":"AU","discountAllowed":true,"timezone":"Australia/Adelaide","openDate":"2024-06-02T08:21:00.000Z","version":5962317641,"name":"To Be Placed","eventName":"Murray Bridge (AUS) 2nd Jun"},"rc":[{"atb":[[1.6,58.07],[1.7,33.18]],"id":52671121},{"atl":[[6.6,0.09]],"id":52671121},{"spn":4.15,"spf":"NaN","id":52671121},{"atb":[[1.82,42.49],[1.92,25.24]],"id":62262930},{"atl":[[8,0.07]],"id":62262930},{"spn":4.96,"spf":"NaN","id":62262930},{"atb":[[3.4,9.67],[2.96,17.77]],"id":69577417},{"spn":"Infinity","spf":"NaN","id":69577417},{"atb":[[5.6,5.04],[4.6,9.67]],"id":69421986},{"spn":"Infinity","spf":"NaN","id":69421986},{"atb":[[1.78,29.77],[1.68,51.23]],"id":65460404},{"atl":[[7.2,0.08]],"id":65460404},{"spn":4.49,"spf":"NaN","id":65460404},{"atb":[[3.25,15.48],[3.75,8.44]],"id":64546979},{"spn":"Infinity","spf":"NaN","id":64546979},{"atb":[[1.73,31.81],[1.63,55.3]],"id":70003371},{"atl":[[6.8,0.08]],"id":70003371},{"spn":4.26,"spf":"NaN","id":70003371}],"con":true,"img":true}]}
{"op":"mcm","clk":"11449667351","pt":1717313215726,"mc":[{"id":"1.229554921","rc":[{"atb":[[1.6,0],[1.7,0]],"id":52671121},{"atl":[[6.6,0]],"id":52671121},{"atb":[[1.82,0],[1.92,0]],"id":62262930},{"atl":[[8,0]],"id":62262930},{"atb":[[3.4,0],[2.96,0]],"id":69577417},{"spn":"NaN","spf":"NaN","id":69577417},{"atb":[[5.6,0],[4.6,0]],"id":69421986},{"atb":[[1.78,0],[1.68,0]],"id":65460404},{"atl":[[7.2,0]],"id":65460404},{"atb":[[3.25,0],[3.75,0]],"id":64546979},{"spn":"NaN","spf":"NaN","id":64546979},{"atb":[[1.73,0],[1.63,0]],"id":70003371},{"atl":[[6.8,0]],"id":70003371}],"con":true,"img":false}]}
{"op":"mcm","clk":"11449668017","pt":1717313230061,"mc":[{"id":"1.229554921","rc":[{"atb":[[1.72,32.26],[1.62,56.19]],"id":52671121},{"atl":[[6.8,0.08]],"id":52671121},{"atb":[[1.83,41.97],[1.93,24.97]],"id":62262930},{"atl":[[8.2,0.07]],"id":62262930},{"atb":[[3.35,9.88],[2.94,17.96]],"id":69577417},{"atb":[[4.9,8.93],[5.9,4.73]],"id":69421986},{"atb":[[1.73,31.81],[1.63,55.3]],"id":65460404},{"atl":[[6.8,0.08]],"id":65460404},{"atb":[[4,7.74],[3.5,13.93]],"id":64546979},{"atb":[[1.64,54.44],[1.74,31.39]],"id":70003371},{"atl":[[6.8,0.08]],"id":70003371}],"con":true,"img":false}]}
{"op":"mcm","clk":"11449670111","pt":1717313273218,"mc":[{"id":"1.229554921","rc":[{"atb":[[1.72,0],[1.62,0]],"id":52671121},{"atl":[[6.8,0]],"id":52671121},{"atb":[[1.83,0],[1.93,0]],"id":62262930},{"atl":[[8.2,0]],"id":62262930},{"atb":[[3.35,0],[2.94,0]],"id":69577417},{"atb":[[4.9,0],[5.9,0]],"id":69421986},{"atb":[[1.73,0],[1.63,0]],"id":65460404},{"atl":[[6.8,0]],"id":65460404},{"atb":[[4,0],[3.5,0]],"id":64546979}],"con":true,"img":false}]}
{"op":"mcm","clk":"11449671034","pt":1717313291048,"mc":[{"id":"1.229554921","rc":[{"atb":[[1.58,60.07],[1.68,34.15]],"id":52671121},{"atl":[[6.4,0.09]],"id":52671121},{"spn":4.04,"spf":"NaN","id":52671121},{"atb":[[1.96,24.19],[1.86,40.51]],"id":62262930},{"atl":[[8.4,0.07]],"id":62262930},{"spn":5.18,"spf":"NaN","id":62262930},{"atb":[[3.45,9.47],[2.98,17.59]],"id":69577417},{"spn":"Infinity","spf":"NaN","id":69577417},{"atb":[[6.4,4.3],[5.2,8.29]],"id":69421986},{"spn":"Infinity","spf":"NaN","id":69421986},{"atb":[[1.73,31.81],[1.63,55.3]],"id":65460404},{"atl":[[6.8,0.08]],"id":65460404},{"spn":4.26,"spf":"NaN","id":65460404},{"atb":[[4.1,7.49],[3.55,13.66]],"id":64546979},{"spn":"Infinity","spf":"NaN","id":64546979},{"spn":4.27,"spf":"NaN","id":70003371}],"con":true,"img":false}]}
{"op":"mcm","clk":"11449673061","pt":1717313329596,"mc":[{"id":"1.229554921","rc":[{"atb":[[1.96,0],[1.86,0]],"id":62262930},{"atl":[[8.4,0]],"id":62262930},{"atb":[[6.4,0],[5.2,0]],"id":69421986},{"atb":[[4.1,0],[3.55,0]],"id":64546979}],"con":true,"img":false}]}
{"op":"mcm","clk":"11449673642","pt":1717313340501,"mc":[{"id":"1.229554921","rc":[{"atb":[[1.97,23.94],[1.87,40.04]],"id":62262930},{"atl":[[8.4,0.07]],"id":62262930},{"atb":[[5.7,4.94],[4.7,9.41]],"id":69421986},{"atb":[[4.1,7.49],[3.55,13.66]],"id":64546979}],"con":true,"img":false}]}
{"op":"mcm","clk":"11449680084","pt":1717313441226,"mc":[{"id":"1.229554921","rc":[{"spn":5.18,"spf":"NaN","id":62262930},{"atb":[[4.1,0],[3.55,0]],"id":64546979},{"spn":"NaN","spf":"NaN","id":64546979}],"con":true,"img":false}]}
{"op":"mcm","clk":"11449680658","pt":1717313449128,"mc":[{"id":"1.229554921","rc":[{"atb":[[4.3,7.03],[3.65,13.14]],"id":64546979}],"con":true,"img":false}]}
{"op":"mcm","clk":"11449693440","pt":1717313604823,"mc":[{"id":"1.229554921","rc":[{"atb":[[1.97,0],[1.87,0]],"id":62262930},{"atl":[[8.4,0]],"id":62262930},{"spn":"NaN","spf":"NaN","id":62262930},{"spn":"Infinity","spf":"NaN","id":64546979}],"con":true,"img":false}]}
{"op":"mcm","clk":"11449695107","pt":1717313624185,"mc":[{"id":"1.229554921","rc":[{"atb":[[1.99,23.46],[1.89,39.14]],"id":62262930},{"atl":[[8.6,0.06]],"id":62262930}],"con":true,"img":false}]}
{"op":"mcm","clk":"11449753604","pt":1717314283549,"mc":[{"id":"1.229554921","rc":[{"atb":[[1.58,0],[1.68,0]],"id":52671121},{"atl":[[6.4,0]],"id":52671121},{"spn":"NaN","spf":"NaN","id":52671121},{"atb":[[1.99,0],[1.89,0]],"id":62262930},{"atl":[[8.6,0]],"id":62262930},{"atb":[[3.45,0],[2.98,0]],"id":69577417},{"spn":"NaN","spf":"NaN","id":69577417},{"atb":[[5.7,0],[4.7,0]],"id":69421986},{"spn":"NaN","spf":"NaN","id":69421986},{"atb":[[1.73,0],[1.63,0]],"id":65460404},{"atl":[[6.8,0]],"id":65460404},{"spn":"NaN","spf":"NaN","id":65460404},{"atb":[[4.3,0],[3.65,0]],"id":64546979},{"spn":"NaN","spf":"NaN","id":64546979},{"atb":[[1.64,0],[1.74,0]],"id":70003371},{"atl":[[6.8,0]],"id":70003371},{"spn":"NaN","spf":"NaN","id":70003371}],"con":true,"img":false}]}
{"op":"mcm","clk":"11449754572","pt":1717314295496,"mc":[{"id":"1.229554921","rc":[{"atb":[[1.57,61.12],[1.67,34.67]],"id":52671121},{"atl":[[6.4,0.09]],"id":52671121},{"atb":[[1.96,24.19],[1.86,40.51]],"id":62262930},{"atl":[[8.4,0.07]],"id":62262930},{"atb":[[3.45,9.47],[2.98,17.59]],"id":69577417},{"atb":[[5.7,4.94],[4.7,9.41]],"id":69421986},{"atb":[[1.75,30.97],[1.65,53.6]],"id":65460404},{"atl":[[7,0.08]],"id":65460404},{"atb":[[3.6,13.4],[4.2,7.26]],"id":64546979},{"atb":[[1.73,31.81],[1.63,55.3]],"id":70003371},{"atl":[[6.8,0.08]],"id":70003371}],"con":true,"img":false}]}
{"op":"mcm","clk":"11449819649","pt":1717315037868,"mc":[{"id":"1.229554921","rc":[{"atb":[[1.03,6.04]],"id":52671121},{"atl":[[1000,0.85]],"id":52671121},{"spn":4.03,"spf":"NaN","id":52671121},{"atb":[[1.03,6.04]],"id":62262930},{"atl":[[990,0.85]],"id":62262930},{"spn":5.18,"spf":"NaN","id":62262930},{"atb":[[1.03,6.04]],"id":69577417},{"atl":[[990,0.85]],"id":69577417},{"spn":496.72,"spf":"NaN","id":69577417},{"atb":[[1.02,9.05]],"id":69421986},{"atl":[[1000,0.85]],"id":69421986},{"spn":502.85,"spf":"NaN","id":69421986},{"atb":[[1.01,18.11]],"id":65460404},{"atl":[[1000,0.85]],"id":65460404},{"spn":4.37,"spf":"NaN","id":65460404},{"atb":[[1.02,9.05]],"id":64546979},{"atl":[[990,0.85]],"id":64546979},{"spn":497.1,"spf":"NaN","id":64546979},{"atb":[[1.02,9.05]],"id":70003371},{"atl":[[1000,0.85]],"id":70003371},{"spn":4.26,"spf":"NaN","id":70003371}],"con":true,"img":false}]}
{"op":"mcm","clk":"11449862803","pt":1717315411973,"mc":[{"id":"1.229554921","rc":[{"atb":[[1.57,0],[1.67,0]],"id":52671121},{"atl":[[6.4,0]],"id":52671121},{"spn":500.51,"spf":"NaN","id":52671121},{"atb":[[1.96,0],[1.86,0]],"id":62262930},{"atl":[[8.4,0]],"id":62262930},{"spn":495.51,"spf":"NaN","id":62262930},{"atb":[[3.45,0],[2.98,0]],"id":69577417},{"spn":495.51,"spf":"NaN","id":69577417},{"atb":[[5.7,0],[4.7,0]],"id":69421986},{"spn":500.51,"spf":"NaN","id":69421986},{"atb":[[1.75,0],[1.65,0]],"id":65460404},{"atl":[[7,0]],"id":65460404},{"spn":500.5,"spf":"NaN","id":65460404},{"atb":[[3.6,0],[4.2,0]],"id":64546979},{"spn":495.51,"spf":"NaN","id":64546979},{"atb":[[1.73,0],[1.63,0]],"id":70003371},{"atl":[[6.8,0]],"id":70003371},{"spn":500.51,"spf":"NaN","id":70003371}],"con":true,"img":false}]}
{"op":"mcm","clk":"11449865331","pt":1717315436507,"mc":[{"id":"1.229554921","rc":[{"atb":[[1.72,32.26],[1.62,56.19]],"id":52671121},{"atl":[[6.8,0.08]],"id":52671121},{"atb":[[2,23.22],[1.9,38.71]],"id":62262930},{"atl":[[8.6,0.06]],"id":62262930},{"atb":[[3,17.42],[3.5,9.29]],"id":69577417},{"atb":[[4.8,9.17],[5.8,4.83]],"id":69421986},{"atb":[[1.58,60.07],[1.68,34.15]],"id":65460404},{"atl":[[6.4,0.09]],"id":65460404},{"atb":[[3.6,13.4],[4.2,7.26]],"id":64546979},{"atb":[[1.6,58.07],[1.7,33.18]],"id":70003371},{"atl":[[6.6,0.09]],"id":70003371}],"con":true,"img":false}]}
{"op":"mcm","clk":"11449893691","pt":1717315712981,"mc":[{"id":"1.229554921","rc":[{"atb":[[1.72,0],[1.62,0]],"id":52671121},{"atl":[[6.8,0]],"id":52671121},{"atb":[[2,0],[1.9,0]],"id":62262930},{"atl":[[8.6,0]],"id":62262930},{"spn":496.75,"spf":"NaN","id":69577417},{"atb":[[4.8,0],[5.8,0]],"id":69421986},{"atb":[[1.58,0],[1.68,0]],"id":65460404},{"atl":[[6.4,0]],"id":65460404},{"spn":497.1,"spf":"NaN","id":64546979},{"spn":4.15,"spf":"NaN","id":70003371}],"con":true,"img":false}]}
{"op":"mcm","clk":"11449896899","pt":1717315742980,"mc":[{"id":"1.229554921","rc":[{"atb":[[1.55,63.35],[1.65,35.73]],"id":52671121},{"atl":[[6.2,0.09]],"id":52671121},{"atb":[[1.99,23.46],[1.89,39.14]],"id":62262930},{"atl":[[8.6,0.06]],"id":62262930},{"atb":[[7.4,3.63],[5.7,7.41]],"id":69421986},{"atb":[[1.71,32.71],[1.61,57.12]],"id":65460404},{"atl":[[6.6,0.09]],"id":65460404}],"con":true,"img":false}]}
{"op":"mcm","clk":"11449970493","pt":1717316552561,"mc":[{"id":"1.229554921","rc":[{"atb":[[1.55,0],[1.65,0]],"id":52671121},{"atl":[[6.2,0]],"id":52671121},{"atb":[[1.99,0],[1.89,0]],"id":62262930},{"atl":[[8.6,0]],"id":62262930},{"atb":[[3,0],[3.5,0]],"id":69577417},{"spn":495.51,"spf":"NaN","id":69577417},{"atb":[[7.4,0],[5.7,0]],"id":69421986},{"atb":[[1.71,0],[1.61,0]],"id":65460404},{"atl":[[6.6,0]],"id":65460404},{"atb":[[3.6,0],[4.2,0]],"id":64546979},{"spn":495.51,"spf":"NaN","id":64546979},{"atb":[[1.6,0],[1.7,0]],"id":70003371},{"atl":[[6.6,0]],"id":70003371},{"spn":500.51,"spf":"NaN","id":70003371}],"con":true,"img":false}]}
{"op":"mcm","clk":"11449971651","pt":1717316571019,"mc":[{"id":"1.229554921","rc":[{"atb":[[1.57,61.12],[1.67,34.67]],"id":52671121},{"atl":[[6.4,0.09]],"id":52671121},{"atb":[[1.84,41.48],[1.94,24.7]],"id":62262930},{"atl":[[8.2,0.07]],"id":62262930},{"atb":[[3.45,9.47],[2.98,17.59]],"id":69577417},{"atb":[[5.8,7.26],[7.6,3.52]],"id":69421986},{"atb":[[1.73,31.81],[1.63,55.3]],"id":65460404},{"atl":[[6.8,0.08]],"id":65460404},{"atb":[[4.1,7.49],[3.55,13.66]],"id":64546979},{"atb":[[1.71,32.71],[1.61,57.12]],"id":70003371},{"atl":[[6.6,0.09]],"id":70003371}],"con":true,"img":false}]}
{"op":"mcm","clk":"11450051667","pt":1717317460704,"mc":[{"id":"1.229554921","rc":[{"atb":[[1.57,0],[1.67,0]],"id":52671121},{"atl":[[6.4,0]],"id":52671121},{"atb":[[1.84,0],[1.94,0]],"id":62262930},{"atl":[[8.2,0]],"id":62262930},{"atb":[[3.45,0],[2.98,0]],"id":69577417},{"atb":[[5.8,0],[7.6,0]],"id":69421986},{"atb":[[1.73,0],[1.63,0]],"id":65460404},{"atl":[[6.8,0]],"id":65460404},{"atb":[[4.1,0],[3.55,0]],"id":64546979},{"atb":[[1.71,0],[1.61,0]],"id":70003371},{"atl":[[6.6,0]],"id":70003371}],"con":true,"img":false}]}
{"op":"mcm","clk":"11450053344","pt":1717317479764,"mc":[{"id":"1.229554921","rc":[{"atb":[[1.55,63.35],[1.65,35.73]],"id":52671121},{"atl":[[6.2,0.09]],"id":52671121},{"atb":[[1.92,37.87],[2.04,22.33]],"id":62262930},{"atl":[[9,0.06]],"id":62262930},{"atb":[[3.6,8.93],[3.1,16.58]],"id":69577417},{"atb":[[5.5,7.74],[7,3.87]],"id":69421986},{"atb":[[1.58,60.07],[1.68,34.15]],"id":65460404},{"atl":[[6.4,0.09]],"id":65460404},{"atb":[[3.6,13.4],[4.2,7.26]],"id":64546979},{"atb":[[1.72,32.26],[1.62,56.19]],"id":70003371},{"atl":[[6.8,0.08]],"id":70003371}],"con":true,"img":false}]}
{"op":"mcm","clk":"11450128152","pt":1717318323973,"mc":[{"id":"1.229554921","rc":[{"atb":[[1.55,0],[1.65,0]],"id":52671121},{"atl":[[6.2,0]],"id":52671121},{"atb":[[1.92,0],[2.04,0]],"id":62262930},{"atl":[[9,0]],"id":62262930},{"atb":[[3.6,0],[3.1,0]],"id":69577417},{"atb":[[5.5,0],[7,0]],"id":69421986},{"atb":[[1.58,0],[1.68,0]],"id":65460404},{"atl":[[6.4,0]],"id":65460404},{"atb":[[3.6,0],[4.2,0]],"id":64546979},{"atb":[[1.72,0],[1.62,0]],"id":70003371},{"atl":[[6.8,0]],"id":70003371}],"con":true,"img":false}]}
{"op":"mcm","clk":"11450129268","pt":1717318336095,"mc":[{"id":"1.229554921","rc":[{"atb":[[1.58,60.07],[1.68,34.15]],"id":52671121},{"atl":[[6.4,0.09]],"id":52671121},{"atb":[[1.97,23.94],[1.87,40.04]],"id":62262930},{"atl":[[8.4,0.07]],"id":62262930},{"atb":[[3.45,9.47],[2.98,17.59]],"id":69577417},{"atb":[[6.8,4],[5.4,7.92]],"id":69421986},{"atb":[[1.73,31.81],[1.63,55.3]],"id":65460404},{"atl":[[6.8,0.08]],"id":65460404},{"atb":[[4.1,7.49],[3.55,13.66]],"id":64546979},{"atb":[[1.6,58.07],[1.7,33.18]],"id":70003371},{"atl":[[6.6,0.09]],"id":70003371}],"con":true,"img":false}]}
{"op":"mcm","clk":"11450149867","pt":1717318573541,"mc":[{"id":"1.229554921","rc":[{"atb":[[1.59,49.65],[1.37,170.55]],"id":52671121},{"atl":[[8.6,5.5],[9.2,7.84]],"id":52671121},{"spn":4.04,"spf":"NaN","id":52671121},{"atb":[[1.56,93.42],[1.88,33.29]],"id":62262930},{"atl":[[12.5,3.64],[13.5,4.18]],"id":62262930},{"spn":5.18,"spf":"NaN","id":62262930},{"atb":[[3.8,14.94],[3.4,23.7]],"id":69577417},{"atl":[[50,5.23]],"id":69577417},{"spn":26.9,"spf":"NaN","id":69577417},{"atb":[[8.8,5.36],[7.8,7.92]],"id":69421986},{"atl":[[200,0.2],[210,2.61]],"id":69421986},{"spn":104.4,"spf":"NaN","id":69421986},{"atb":[[1.64,45.77],[1.34,176.31]],"id":65460404},{"atl":[[8.2,5.81],[8.8,7.84]],"id":65460404},{"spn":4.26,"spf":"NaN","id":65460404},{"atb":[[4.2,16.63],[4.7,11.31]],"id":64546979},{"atl":[[70,5.23]],"id":64546979},{"spn":37.35,"spf":"NaN","id":64546979},{"atb":[[1.37,167.41],[1.61,48.02]],"id":70003371},{"atl":[[8.8,5.36],[9.4,7.32]],"id":70003371},{"spn":4.15,"spf":"NaN","id":70003371}],"con":true,"img":false}]}
{"op":"mcm","clk":"11450154634","pt":1717318623470,"mc":[{"id":"1.229554921","rc":[{"atb":[[8.8,0]],"id":69421986}],"con":true,"img":false}]}
{"op":"mcm","clk":"11450154643","pt":1717318623572,"mc":[{"id":"1.229554921","rc":[{"atb":[[9,5.36]],"id":69421986}],"con":true,"img":false}]}
{"op":"mcm","clk":"11450154999","pt":1717318627255,"mc":[{"id":"1.229554921","rc":[{"atl":[[1000,0.17]],"id":52671121},{"atl":[[990,0.17]],"id":62262930},{"atl":[[990,0.17]],"id":69577417},{"atl":[[1000,0.17]],"id":69421986},{"atl":[[1000,0.17]],"id":65460404},{"atl":[[990,0.17]],"id":64546979},{"atl":[[1000,0.17]],"id":70003371}],"con":true,"img":false}]}
{"op":"mcm","clk":"11450157558","pt":1717318650512,"mc":[{"id":"1.229554921","rc":[{"atb":[[1.88,0]],"id":62262930},{"spn":104.5,"spf":"NaN","id":69421986}],"con":true,"img":false}]}
{"op":"mcm","clk":"11450157570","pt":1717318650614,"mc":[{"id":"1.229554921","rc":[{"atb":[[1.98,33.29]],"id":62262930}],"con":true,"img":false}]}
{"op":"mcm","clk":"11450208386","pt":1717319182971,"mc":[{"id":"1.229554921","rc":[{"atb":[[1.58,0],[1.68,0]],"id":52671121},{"atl":[[6.4,0]],"id":52671121},{"spn":5.09,"spf":"NaN","id":52671121},{"atb":[[1.97,0],[1.87,0]],"id":62262930},{"atl":[[8.4,0]],"id":62262930},{"spn":7.24,"spf":"NaN","id":62262930},{"atb":[[3.45,0],[2.98,0]],"id":69577417},{"atb":[[6.8,0],[5.4,0]],"id":69421986},{"atb":[[1.73,0],[1.63,0]],"id":65460404},{"atl":[[6.8,0]],"id":65460404},{"spn":4.92,"spf":"NaN","id":65460404},{"atb":[[4.1,0],[3.55,0]],"id":64546979},{"atb":[[1.6,0],[1.7,0]],"id":70003371},{"atl":[[6.6,0]],"id":70003371},{"spn":5.2,"spf":"NaN","id":70003371}],"con":true,"img":false}]}
{"op":"mcm","clk":"11450208838","pt":1717319187300,"mc":[{"id":"1.229554921","rc":[{"atb":[[1.59,0]],"id":52671121},{"atb":[[1.98,0]],"id":62262930},{"atb":[[1.64,0]],"id":65460404},{"atb":[[1.61,0]],"id":70003371}],"con":true,"img":false}]}
{"op":"mcm","clk":"11450208850","pt":1717319187404,"mc":[{"id":"1.229554921","rc":[{"atb":[[1.41,49.65]],"id":52671121},{"atb":[[1.64,33.29]],"id":62262930},{"atb":[[1.39,45.77]],"id":65460404},{"atb":[[1.42,48.02]],"id":70003371}],"con":true,"img":false}]}
{"op":"mcm","clk":"11450210488","pt":1717319203422,"mc":[{"id":"1.229554921","rc":[{"atb":[[1.6,58.07],[1.7,33.18]],"id":52671121},{"atl":[[6.6,0.09]],"id":52671121},{"atb":[[1.85,40.99],[1.95,24.45]],"id":62262930},{"atl":[[8.2,0.07]],"id":62262930},{"atb":[[3.35,9.88],[2.94,17.96]],"id":69577417},{"atb":[[8,3.31],[6,6.96]],"id":69421986},{"atb":[[1.71,32.71],[1.61,57.12]],"id":65460404},{"atl":[[6.6,0.09]],"id":65460404},{"atb":[[4.1,7.49],[3.55,13.66]],"id":64546979},{"atb":[[1.71,32.71],[1.61,57.12]],"id":70003371},{"atl":[[6.6,0.09]],"id":70003371}],"con":true,"img":false}]}
{"op":"mcm","clk":"11450216190","pt":1717319258870,"mc":[{"id":"1.229554921","rc":[{"atb":[[1.41,0]],"id":52671121},{"spn":4.15,"spf":"NaN","id":52671121},{"atb":[[1.64,0]],"id":62262930},{"spn":5.07,"spf":"NaN","id":62262930},{"atb":[[1.39,0]],"id":65460404},{"spn":4.15,"spf":"NaN","id":65460404},{"atb":[[1.42,0]],"id":70003371},{"spn":4.15,"spf":"NaN","id":70003371}],"con":true,"img":false}]}
{"op":"mcm","clk":"11450216200","pt":1717319258975,"mc":[{"id":"1.229554921","rc":[{"atb":[[1.61,49.65]],"id":52671121},{"atb":[[1.96,33.29]],"id":62262930},{"atb":[[1.62,45.77]],"id":65460404},{"atb":[[1.62,48.02]],"id":70003371}],"con":true,"img":false}]}
{"op":"mcm","clk":"11450247262","pt":1717319591812,"mc":[{"id":"1.229554921","rc":[{"spn":5.08,"spf":"NaN","id":62262930},{"spl":[[1.01,2.61]],"id":70003371},{"spn":1.71,"spf":1.0,"id":70003371}],"con":true,"img":false}]}
{"op":"mcm","clk":"11450277316","pt":1717319943225,"mc":[{"id":"1.229554921","rc":[{"atl":[[50,2.61]],"id":69577417},{"atl":[[70,2.61]],"id":64546979}],"con":true,"img":false}]}
{"op":"mcm","clk":"11450277319","pt":1717319943325,"mc":[{"id":"1.229554921","rc":[{"atl":[[55,2.61]],"id":69577417},{"atl":[[75,2.61]],"id":64546979}],"con":true,"img":false}]}
{"op":"mcm","clk":"11450279069","pt":1717319964945,"mc":[{"id":"1.229554921","rc":[{"atb":[[1.6,0],[1.7,0]],"id":52671121},{"atl":[[6.6,0]],"id":52671121},{"atb":[[1.85,0],[1.95,0]],"id":62262930},{"atl":[[8.2,0]],"id":62262930},{"atb":[[3.35,0],[2.94,0]],"id":69577417},{"atb":[[1.71,0],[1.61,0]],"id":65460404},{"atl":[[6.6,0]],"id":65460404},{"atb":[[4.1,0],[3.55,0]],"id":64546979}],"con":true,"img":false}]}
{"op":"mcm","clk":"11450279287","pt":1717319967467,"mc":[{"id":"1.229554921","rc":[{"atb":[[4.7,0]],"id":64546979}],"con":true,"img":false}]}
{"op":"mcm","clk":"11450279293","pt":1717319967528,"mc":[{"id":"1.229554921","rc":[{"atb":[[4.9,11.31]],"id":64546979}],"con":true,"img":false}]}
{"op":"mcm","clk":"11450279779","pt":1717319974026,"mc":[{"id":"1.229554921","rc":[{"atb":[[1.61,0]],"id":52671121},{"atb":[[1.96,0]],"id":62262930},{"atb":[[1.62,0]],"id":65460404}],"con":true,"img":false}]}
{"op":"mcm","clk":"11450279787","pt":1717319974129,"mc":[{"id":"1.229554921","rc":[{"atb":[[1.39,49.65]],"id":52671121},{"atb":[[1.64,33.29]],"id":62262930},{"atb":[[1.39,45.77]],"id":65460404}],"con":true,"img":false}]}
{"op":"mcm","clk":"11450280020","pt":1717319977073,"mc":[{"id":"1.229554921","rc":[{"atb":[[1.64,36.29],[1.54,64.52]],"id":52671121},{"atl":[[6,0.1]],"id":52671121},{"atb":[[1.97,23.94],[1.87,40.04]],"id":62262930},{"atl":[[8.4,0.07]],"id":62262930},{"atb":[[3.6,8.93],[3.1,16.58]],"id":69577417},{"atb":[[1.72,32.26],[1.62,56.19]],"id":65460404},{"atl":[[6.8,0.08]],"id":65460404},{"atb":[[4.3,7.03],[3.65,13.14]],"id":64546979}],"con":true,"img":false}]}
{"op":"mcm","clk":"11450281611","pt":1717319996711,"mc":[{"id":"1.229554921","rc":[{"atb":[[1.37,0]],"id":52671121},{"atb":[[3.8,0]],"id":69577417},{"atl":[[50,0],[55,0]],"id":69577417},{"atl":[[8.8,0]],"id":65460404}],"con":true,"img":false}]}
{"op":"mcm","clk":"11450281623","pt":1717319996780,"mc":[{"id":"1.229554921","rc":[{"atb":[[1.31,170.55]],"id":52671121},{"atb":[[4,14.94]],"id":69577417},{"atl":[[60,5.23]],"id":69577417},{"atl":[[9.4,7.84]],"id":65460404}],"con":true,"img":false}]}
{"op":"mcm","clk":"11450282287","pt":1717320005021,"mc":[{"id":"1.229554921","rc":[{"atb":[[1.64,0],[1.54,0]],"id":52671121},{"atl":[[6,0]],"id":52671121},{"spn":4.99,"spf":"NaN","id":52671121},{"atb":[[1.97,0],[1.87,0]],"id":62262930},{"atl":[[8.4,0]],"id":62262930},{"spn":7.07,"spf":"NaN","id":62262930},{"atb":[[3.6,0],[3.1,0]],"id":69577417},{"spn":32.0,"spf":"NaN","id":69577417},{"atb":[[8,0],[6,0]],"id":69421986},{"atb":[[1.72,0],[1.62,0]],"id":65460404},{"atl":[[6.8,0]],"id":65460404},{"spn":4.79,"spf":"NaN","id":65460404},{"atb":[[4.3,0],[3.65,0]],"id":64546979},{"spn":37.45,"spf":"NaN","id":64546979},{"atb":[[1.71,0],[1.61,0]],"id":70003371},{"atl":[[6.6,0]],"id":70003371},{"spn":1.62,"spf":1.0,"id":70003371}],"con":true,"img":false}]}
{"op":"mcm","clk":"11450283138","pt":1717320015425,"mc":[{"id":"1.229554921","rc":[{"atb":[[1.4,87.1],[1.5,46.45]],"id":52671121},{"atl":[[4.5,0.15]],"id":52671121},{"atb":[[2.02,22.77],[1.91,38.29]],"id":62262930},{"atl":[[8.6,0.06]],"id":62262930},{"atb":[[3.45,14.21],[3.95,7.87]],"id":69577417},{"atb":[[5.3,8.1],[6.6,4.14]],"id":69421986},{"atb":[[1.64,54.44],[1.74,31.39]],"id":65460404},{"atl":[[6.8,0.08]],"id":65460404},{"atb":[[4.5,6.63],[3.75,12.67]],"id":64546979},{"atb":[[1.73,31.81],[1.63,55.3]],"id":70003371},{"atl":[[6.8,0.08]],"id":70003371}],"con":true,"img":false}]}
{"op":"mcm","clk":"11450283860","pt":1717320025216,"mc":[{"id":"1.229554921","rc":[{"atb":[[1.64,0]],"id":62262930},{"atb":[[9,0]],"id":69421986},{"atb":[[1.39,0]],"id":65460404}],"con":true,"img":false}]}
{"op":"mcm","clk":"11450283871","pt":1717320025331,"mc":[{"id":"1.229554921","rc":[{"atb":[[1.98,33.29]],"id":62262930},{"atb":[[3.4,0]],"id":69577417},{"atb":[[9.4,5.36]],"id":69421986},{"atb":[[1.63,45.77]],"id":65460404}],"con":true,"img":false}]}
{"op":"mcm","clk":"11450283880","pt":1717320025429,"mc":[{"id":"1.229554921","rc":[{"atb":[[3.65,23.7]],"id":69577417}],"con":true,"img":false}]}
{"op":"mcm","clk":"11450284713","pt":1717320037222,"mc":[{"id":"1.229554921","rc":[{"atb":[[1.4,0],[1.5,0]],"id":52671121},{"atl":[[4.5,0]],"id":52671121},{"atb":[[5.3,0],[6.6,0]],"id":69421986},{"atb":[[1.64,0],[1.74,0]],"id":65460404},{"atl":[[6.8,0]],"id":65460404},{"atb":[[1.73,0],[1.63,0]],"id":70003371},{"atl":[[6.8,0]],"id":70003371}],"con":true,"img":false}]}
{"op":"mcm","clk":"11450284849","pt":1717320039550,"mc":[{"id":"1.229554921","rc":[{"atb":[[1.39,0]],"id":52671121}],"con":true,"img":false}]}
{"op":"mcm","clk":"11450284859","pt":1717320039653,"mc":[{"id":"1.229554921","rc":[{"atb":[[1.51,49.65]],"id":52671121}],"con":true,"img":false}]}
{"op":"mcm","clk":"11450285057","pt":1717320042544,"mc":[{"id":"1.229554921","rc":[{"atb":[[7.8,0]],"id":69421986}],"con":true,"img":false}]}
{"op":"mcm","clk":"11450285066","pt":1717320042645,"mc":[{"id":"1.229554921","rc":[{"atb":[[8.2,7.92]],"id":69421986}],"con":true,"img":false}]}
{"op":"mcm","clk":"11450285282","pt":1717320045750,"mc":[{"id":"1.229554921","rc":[{"atb":[[1.43,81.02],[1.53,43.82]],"id":52671121},{"atl":[[4.8,0.13]],"id":52671121},{"atb":[[5.5,7.74],[7,3.87]],"id":69421986},{"atb":[[1.66,52.79],[1.76,30.56]],"id":65460404},{"atl":[[7,0.08]],"id":65460404},{"atb":[[1.6,58.07],[1.7,33.18]],"id":70003371},{"atl":[[6.6,0.09]],"id":70003371}],"con":true,"img":false}]}
{"op":"mcm","clk":"11450285931","pt":1717320056843,"mc":[{"id":"1.229554921","rc":[{"atl":[[9.2,0]],"id":52671121},{"atb":[[1.63,0]],"id":65460404},{"atb":[[1.62,0]],"id":70003371}],"con":true,"img":false}]}
{"op":"mcm","clk":"11450285949","pt":1717320056949,"mc":[{"id":"1.229554921","rc":[{"atl":[[8.2,7.84]],"id":52671121},{"atb":[[1.67,45.77]],"id":65460404},{"atb":[[1.61,48.02]],"id":70003371}],"con":true,"img":false}]}
{"op":"mcm","clk":"11450286284","pt":1717320062868,"mc":[{"id":"1.229554921","rc":[{"atb":[[1.98,0]],"id":62262930}],"con":true,"img":false}]}
{"op":"mcm","clk":"11450286288","pt":1717320062964,"mc":[{"id":"1.229554921","rc":[{"atb":[[2.04,33.29]],"id":62262930}],"con":true,"img":false}]}
{"op":"mcm","clk":"11450286909","pt":1717320072505,"mc":[{"id":"1.229554921","rc":[{"atb":[[1.43,0],[1.53,0]],"id":52671121},{"atl":[[4.8,0]],"id":52671121},{"spn":4.85,"spf":"NaN","id":52671121},{"atb":[[2.02,0],[1.91,0]],"id":62262930},{"atl":[[8.6,0]],"id":62262930},{"spn":7.27,"spf":"NaN","id":62262930},{"atb":[[3.45,0],[3.95,0]],"id":69577417},{"spn":104.7,"spf":"NaN","id":69421986},{"atb":[[1.66,0],[1.76,0]],"id":65460404},{"atl":[[7,0]],"id":65460404},{"spn":4.93,"spf":"NaN","id":65460404},{"atb":[[4.5,0],[3.75,0]],"id":64546979},{"atb":[[1.6,0],[1.7,0]],"id":70003371},{"atl":[[6.6,0]],"id":70003371},{"spn":1.61,"spf":1.0,"id":70003371}],"con":true,"img":false}]}
{"op":"mcm","clk":"11450287230","pt":1717320076783,"mc":[{"id":"1.229554921","rc":[{"atb":[[1.51,0]],"id":52671121},{"atl":[[8.6,0]],"id":52671121}],"con":true,"img":false}]}
{"op":"mcm","clk":"11450287239","pt":1717320076886,"mc":[{"id":"1.229554921","rc":[{"atb":[[1.54,49.65]],"id":52671121},{"atl":[[7.6,5.5]],"id":52671121}],"con":true,"img":false}]}
{"op":"mcm","clk":"11450287939","pt":1717320087284,"mc":[{"id":"1.229554921","rc":[{"atb":[[1.43,81.02],[1.53,43.82]],"id":52671121},{"atl":[[4.8,0.13]],"id":52671121},{"atb":[[1.98,35.55],[2.16,20.02]],"id":62262930},{"atl":[[9.6,0.06]],"id":62262930},{"atb":[[3.25,15.48],[3.75,8.44]],"id":69577417},{"atb":[[1.67,97.78],[1.77,30.16]],"id":65460404},{"atl":[[7,0.08]],"id":65460404},{"atb":[[4.5,6.63],[3.75,12.67]],"id":64546979},{"atb":[[1.55,63.35],[1.65,35.73]],"id":70003371},{"atl":[[6.2,0.09]],"id":70003371}],"con":true,"img":false}]}
{"op":"mcm","clk":"11450288823","pt":1717320101402,"mc":[{"id":"1.229554921","rc":[{"atb":[[2.04,0]],"id":62262930}],"con":true,"img":false}]}
{"op":"mcm","clk":"11450288831","pt":1717320101501,"mc":[{"id":"1.229554921","rc":[{"atb":[[1.99,33.29]],"id":62262930}],"con":true,"img":false}]}
{"op":"mcm","clk":"11450289698","pt":1717320114643,"mc":[{"id":"1.229554921","rc":[{"atb":[[1.43,0],[1.53,0]],"id":52671121},{"atl":[[4.8,0]],"id":52671121},{"atb":[[1.98,0],[2.16,0]],"id":62262930},{"atl":[[9.6,0]],"id":62262930},{"atb":[[3.25,0],[3.75,0]],"id":69577417},{"atb":[[5.5,0],[7,0]],"id":69421986},{"atb":[[1.67,45.77],[1.77,0]],"id":65460404},{"atl":[[7,0]],"id":65460404},{"atb":[[4.5,0],[3.75,0]],"id":64546979}],"con":true,"img":false}]}
{"op":"mcm","clk":"11450290273","pt":1717320122461,"mc":[{"id":"1.229554921","rc":[{"atb":[[1.34,0]],"id":65460404},{"atb":[[4.2,0]],"id":64546979},{"atb":[[1.61,0]],"id":70003371}],"con":true,"img":false}]}
{"op":"mcm","clk":"11450290285","pt":1717320122597,"mc":[{"id":"1.229554921","rc":[{"atb":[[1.36,176.31]],"id":65460404},{"atb":[[4.4,16.63]],"id":64546979},{"atb":[[1.66,48.02]],"id":70003371}],"con":true,"img":false}]}
{"op":"mcm","clk":"11450290812","pt":1717320129762,"mc":[{"id":"1.229554921","rc":[{"atb":[[1.42,82.96],[1.52,44.66]],"id":52671121},{"atl":[[4.7,0.14]],"id":52671121},{"atb":[[2,34.84],[2.2,19.35]],"id":62262930},{"atl":[[9.8,0.05]],"id":62262930},{"atb":[[3.25,15.48],[3.75,8.44]],"id":69577417},{"atb":[[5.3,8.1],[6.6,4.14]],"id":69421986},{"atb":[[1.73,31.81],[1.63,55.3]],"id":65460404},{"atl":[[6.8,0.08]],"id":65460404},{"atb":[[4.6,6.45],[3.8,12.44]],"id":64546979}],"con":true,"img":false}]}
{"op":"mcm","clk":"11450293208","pt":1717320163720,"mc":[{"id":"1.229554921","rc":[{"atb":[[1.54,0]],"id":52671121},{"spn":3.11,"spf":"NaN","id":52671121},{"atb":[[1.99,0]],"id":62262930},{"spn":6.0,"spf":"NaN","id":62262930},{"atb":[[1.67,0]],"id":65460404},{"spn":4.26,"spf":"NaN","id":65460404},{"spn":1.66,"spf":1.0,"id":70003371}],"con":true,"img":false}]}
{"op":"mcm","clk":"11450293222","pt":1717320163820,"mc":[{"id":"1.229554921","rc":[{"atb":[[1.53,49.65]],"id":52671121},{"atb":[[2.02,33.29]],"id":62262930},{"atb":[[1.64,45.77]],"id":65460404}],"con":true,"img":false}]}
{"op":"mcm","clk":"11450296500","pt":1717320212666,"mc":[{"id":"1.229554921","rc":[{"atl":[[75,0]],"id":64546979}],"con":true,"img":false}]}
{"op":"mcm","clk":"11450296507","pt":1717320212768,"mc":[{"id":"1.229554921","rc":[{"atl":[[80,2.61]],"id":64546979}],"con":true,"img":false}]}
{"op":"mcm","clk":"11450298216","pt":1717320240320,"mc":[{"id":"1.229554921","rc":[{"atl":[[6,23.26]],"id":52671121},{"spn":3.11,"spf":"NaN","id":52671121},{"atl":[[7,6.83]],"id":65460404}],"con":true,"img":false}]}
{"op":"mcm","clk":"11450298222","pt":1717320240412,"mc":[{"id":"1.229554921","rc":[{"atb":[[1.54,49.66]],"id":52671121},{"atl":[[7.4,5.51]],"id":52671121},{"atb":[[1.79,66.58]],"id":62262930},{"atl":[[12,3.64]],"id":62262930},{"atb":[[3,30.44]],"id":69577417},{"atl":[[55,2]],"id":69577417},{"atb":[[2.48,13.3]],"id":69421986},{"atl":[[120,2]],"id":69421986},{"atb":[[1.64,109.41]],"id":65460404},{"atl":[[8,5.81]],"id":65460404},{"atb":[[2.72,23.76]],"id":64546979},{"atl":[[70,4.61]],"id":64546979},{"atb":[[1.5,96.06]],"id":70003371},{"atl":[[8.6,5.37]],"id":70003371}],"con":true,"img":false}]}
{"op":"mcm","clk":"11450299816","pt":1717320263735,"mc":[{"id":"1.229554921","rc":[{"atl":[[6,0]],"id":52671121}],"con":true,"img":false}]}
{"op":"mcm","clk":"11450300807","pt":1717320277574,"mc":[{"id":"1.229554921","rc":[{"atb":[[1.79,0],[1.84,66.58]],"id":62262930},{"atb":[[3,0],[3.3,29.9]],"id":69577417},{"atb":[[2.58,13.3],[2.48,0]],"id":69421986},{"atl":[[110,2],[120,0]],"id":69421986},{"atb":[[1.64,45.77],[1.71,109.42]],"id":65460404},{"atl":[[8,0],[6.8,5.89]],"id":65460404},{"atb":[[2.72,0],[2.84,23.76]],"id":64546979},{"atb":[[1.5,0],[1.53,96.06]],"id":70003371}],"con":true,"img":false}]}
{"op":"mcm","clk":"11450301022","pt":1717320281261,"mc":[{"id":"1.229554921","rc":[{"atb":[[1.53,0]],"id":52671121},{"atb":[[4,0]],"id":69577417},{"atl":[[60,2.61]],"id":69577417},{"atl":[[200,0],[110,2.38]],"id":69421986}],"con":true,"img":false}]}
{"op":"mcm","clk":"11450301031","pt":1717320281363,"mc":[{"id":"1.229554921","rc":[{"atb":[[1.55,49.65],[1.53,99.32]],"id":52671121},{"atb":[[4.2,14.94]],"id":69577417},{"atl":[[50,2.61],[60,4.61]],"id":69577417}],"con":true,"img":false}]}
{"op":"mcm","clk":"11450301036","pt":1717320281471,"mc":[{"id":"1.229554921","rc":[{"atb":[[1.54,0]],"id":52671121},{"atl":[[55,0]],"id":69577417}],"con":true,"img":false}]}
{"op":"mcm","clk":"11450302616","pt":1717320306302,"mc":[{"id":"1.229554921","rc":[{"atb":[[1.42,0],[1.52,0]],"id":52671121},{"atl":[[4.7,0]],"id":52671121},{"spn":4.47,"spf":"NaN","id":52671121},{"spn":27.1,"spf":"NaN","id":69577417},{"atb":[[5.3,0],[6.6,0]],"id":69421986},{"spn":59.7,"spf":"NaN","id":69421986},{"atb":[[1.73,0],[1.63,0]],"id":65460404},{"atl":[[6.8,5.81]],"id":65460404},{"spn":4.25,"spf":"NaN","id":65460404},{"atb":[[4.6,0],[3.8,0]],"id":64546979}],"con":true,"img":false}]}
{"op":"mcm","clk":"11450302626","pt":1717320306395,"mc":[{"id":"1.229554921","rc":[{"atb":[[1.65,153.85]],"id":65460404}],"con":true,"img":false}]}
{"op":"mcm","clk":"11450302633","pt":1717320306503,"mc":[{"id":"1.229554921","rc":[{"atb":[[1.71,0]],"id":65460404}],"con":true,"img":false}]}
{"op":"mcm","clk":"11450302873","pt":1717320310324,"mc":[{"id":"1.229554921","rc":[{"atb":[[1.55,0]],"id":52671121},{"atb":[[9.4,0]],"id":69421986},{"atl":[[170,0.24],[110,2]],"id":69421986}],"con":true,"img":false}]}
{"op":"mcm","clk":"11450302884","pt":1717320310425,"mc":[{"id":"1.229554921","rc":[{"atb":[[1.54,49.65]],"id":52671121},{"atb":[[9.8,5.36]],"id":69421986}],"con":true,"img":false}]}
{"op":"mcm","clk":"11450302890","pt":1717320310477,"mc":[{"id":"1.229554921","rc":[{"atb":[[1.32,198.64],[1.53,0]],"id":52671121}],"con":true,"img":false}]}
{"op":"mcm","clk":"11450303355","pt":1717320317377,"mc":[{"id":"1.229554921","rc":[{"atb":[[1.64,0]],"id":65460404}],"con":true,"img":false}]}
{"op":"mcm","clk":"11450303359","pt":1717320317479,"mc":[{"id":"1.229554921","rc":[{"atb":[[1.37,270.27],[1.65,0],[1.66,45.77]],"id":65460404}],"con":true,"img":false}]}
{"op":"mcm","clk":"11450303396","pt":1717320318101,"mc":[{"id":"1.229554921","rc":[{"atb":[[1.55,170.56],[1.32,0]],"id":52671121},{"atl":[[50,4.65],[60,2.61]],"id":69577417}],"con":true,"img":false}]}
{"op":"mcm","clk":"11450303916","pt":1717320326605,"mc":[{"id":"1.229554921","rc":[{"atb":[[1.4,87.1],[1.5,46.45]],"id":52671121},{"atl":[[4.5,0.15]],"id":52671121},{"atb":[[5.3,8.1],[6.6,4.14]],"id":69421986},{"atb":[[1.71,32.71],[1.61,57.12]],"id":65460404},{"atl":[[6.6,0.09]],"id":65460404},{"atb":[[4.8,6.11],[3.9,12.01]],"id":64546979}],"con":true,"img":false}]}
{"op":"mcm","clk":"11450304308","pt":1717320333096,"mc":[{"id":"1.229554921","rc":[{"atb":[[1.54,0]],"id":52671121}],"con":true,"img":false}]}
{"op":"mcm","clk":"11450304316","pt":1717320333204,"mc":[{"id":"1.229554921","rc":[{"atb":[[1.51,49.65]],"id":52671121}],"con":true,"img":false}]}
{"op":"mcm","clk":"11450304323","pt":1717320333300,"mc":[{"id":"1.229554921","rc":[{"atb":[[1.55,0],[1.51,245.73]],"id":52671121}],"con":true,"img":false}]}
{"op":"mcm","clk":"11450304891","pt":1717320342822,"mc":[{"id":"1.229554921","rc":[{"atb":[[1.71,78.49]],"id":65460404}],"con":true,"img":false}]}
{"op":"mcm","clk":"11450304897","pt":1717320342923,"mc":[{"id":"1.229554921","rc":[{"atb":[[1.37,0]],"id":65460404}],"con":true,"img":false}]}
{"op":"mcm","clk":"11450305408","pt":1717320352151,"mc":[{"id":"1.229554921","rc":[{"atb":[[1.66,0]],"id":65460404}],"con":true,"img":false}]}
{"op":"mcm","clk":"11450305417","pt":1717320352256,"mc":[{"id":"1.229554921","rc":[{"atb":[[1.62,45.77]],"id":65460404}],"con":true,"img":false}]}
{"op":"mcm","clk":"11450306340","pt":1717320369783,"mc":[{"id":"1.229554921","rc":[{"spn":3.0,"spf":"NaN","id":52671121},{"atl":[[110,0],[120,2]],"id":69421986},{"spn":64.9,"spf":"NaN","id":69421986},{"atb":[[1.67,149.25]],"id":65460404},{"spn":4.15,"spf":"NaN","id":65460404},{"atb":[[2.84,0],[2.7,24.04]],"id":64546979}],"con":true,"img":false}]}
{"op":"mcm","clk":"11450306344","pt":1717320369880,"mc":[{"id":"1.229554921","rc":[{"atb":[[1.71,32.71]],"id":65460404}],"con":true,"img":false}]}
{"op":"mcm","clk":"11450306346","pt":1717320369983,"mc":[{"id":"1.229554921","rc":[{"atb":[[1.63,158.73]],"id":65460404}],"con":true,"img":false}]}
{"op":"mcm","clk":"11450306350","pt":1717320370089,"mc":[{"id":"1.229554921","rc":[{"atb":[[1.67,0]],"id":65460404}],"con":true,"img":false}]}
{"op":"mcm","clk":"11450306399","pt":1717320370969,"mc":[{"id":"1.229554921","rc":[{"atb":[[1.51,196.08]],"id":52671121}],"con":true,"img":false}]}
{"op":"mcm","clk":"11450306403","pt":1717320371076,"mc":[{"id":"1.229554921","rc":[{"atb":[[1.52,49.65]],"id":52671121}],"con":true,"img":false}]}
{"op":"mcm","clk":"11450306407","pt":1717320371174,"mc":[{"id":"1.229554921","rc":[{"atb":[[1.53,49.66]],"id":52671121}],"con":true,"img":false}]}
{"op":"mcm","clk":"11450306414","pt":1717320371280,"mc":[{"id":"1.229554921","rc":[{"atb":[[1.51,0]],"id":52671121}],"con":true,"img":false}]}
{"op":"mcm","clk":"11450306861","pt":1717320378991,"mc":[{"id":"1.229554921","rc":[{"atb":[[1.63,0],[1.67,65.44]],"id":65460404}],"con":true,"img":false}]}
{"op":"mcm","clk":"11450307545","pt":1717320389490,"mc":[{"id":"1.229554921","rc":[{"atl":[[110,0.38]],"id":69421986},{"atb":[[1.62,0]],"id":65460404}],"con":true,"img":false}]}
{"op":"mcm","clk":"11450307553","pt":1717320389595,"mc":[{"id":"1.229554921","rc":[{"atl":[[170,0]],"id":69421986},{"atb":[[1.68,45.77]],"id":65460404}],"con":true,"img":false}]}
{"op":"mcm","clk":"11450308123","pt":1717320400340,"mc":[{"id":"1.229554921","rc":[{"atb":[[1.4,0],[1.5,0]],"id":52671121},{"atl":[[4.5,0]],"id":52671121},{"atb":[[2,0],[2.2,0]],"id":62262930},{"atl":[[9.8,0]],"id":62262930},{"atb":[[3.25,0],[3.75,0]],"id":69577417},{"atb":[[5.3,0],[6.6,0]],"id":69421986},{"atb":[[1.71,0],[1.61,0]],"id":65460404},{"atl":[[6.6,0]],"id":65460404},{"atb":[[4.8,0],[3.9,0]],"id":64546979},{"atb":[[1.55,0],[1.65,0]],"id":70003371},{"atl":[[6.2,0]],"id":70003371}],"con":true,"img":false}]}
{"op":"mcm","clk":"11450308653","pt":1717320408294,"mc":[{"id":"1.229554921","rc":[{"atb":[[2.02,0]],"id":62262930},{"atb":[[1.66,0]],"id":70003371}],"con":true,"img":false}]}
{"op":"mcm","clk":"11450308660","pt":1717320408400,"mc":[{"id":"1.229554921","rc":[{"atb":[[1.84,0],[1.57,133.16],[1.85,33.29]],"id":62262930},{"atb":[[1.54,48.02],[1.53,0],[1.38,192.12]],"id":70003371}],"con":true,"img":false}]}
{"op":"mcm","clk":"11450308800","pt":1717320410888,"mc":[{"id":"1.229554921","rc":[{"atb":[[1.45,77.43],[1.55,42.23]],"id":52671121},{"atl":[[5,0.13]],"id":52671121},{"atb":[[2.06,21.91],[1.93,37.46]],"id":62262930},{"atl":[[9,0.06]],"id":62262930},{"atb":[[3.4,14.51],[3.9,8]],"id":69577417},{"atb":[[6.8,4],[5.4,7.92]],"id":69421986},{"atb":[[1.73,31.81],[1.63,55.3]],"id":65460404},{"atl":[[6.8,5.89]],"id":65460404},{"atb":[[3.7,12.9],[4.4,23.46]],"id":64546979},{"atb":[[1.6,58.07],[1.7,33.18]],"id":70003371},{"atl":[[6.6,0.09]],"id":70003371}],"con":true,"img":false}]}
{"op":"mcm","clk":"11450308808","pt":1717320410992,"mc":[{"id":"1.229554921","rc":[{"atb":[[1.56,49.66],[1.53,0]],"id":52671121}],"con":true,"img":false}]}
{"op":"mcm","clk":"11450309228","pt":1717320418283,"mc":[{"id":"1.229554921","rc":[{"atb":[[1.58,6.76]],"id":52671121},{"atb":[[1.97,4.04]],"id":62262930},{"atb":[[1.76,5.16]],"id":65460404}],"con":true,"img":false}]}
{"op":"mcm","clk":"11450309236","pt":1717320418401,"mc":[{"id":"1.229554921","rc":[{"atb":[[1.56,0],[1.59,42.24]],"id":52671121}],"con":true,"img":false}]}
{"op":"mcm","clk":"11450309245","pt":1717320418457,"mc":[{"id":"1.229554921","rc":[{"atb":[[1.73,5.37]],"id":70003371}],"con":true,"img":false}]}
{"op":"mcm","clk":"11450309905","pt":1717320427709,"mc":[{"id":"1.229554921","rc":[{"atb":[[1.52,0]],"id":52671121}],"con":true,"img":false}]}
{"op":"mcm","clk":"11450309911","pt":1717320427774,"mc":[{"id":"1.229554921","rc":[{"atb":[[1.54,49.65]],"id":52671121}],"con":true,"img":false}]}
{"op":"mcm","clk":"11450310304","pt":1717320433205,"mc":[{"id":"1.229554921","rc":[{"atb":[[1.58,0]],"id":52671121},{"spn":3.29,"spf":"NaN","id":52671121},{"spn":5.53,"spf":"NaN","id":62262930},{"spn":59.9,"spf":"NaN","id":69421986},{"spn":4.28,"spf":"NaN","id":65460404},{"spn":1.73,"spf":1.0,"id":70003371}],"con":true,"img":false}]}
{"op":"mcm","clk":"11450310309","pt":1717320433318,"mc":[{"id":"1.229554921","rc":[{"atb":[[1.56,84.48],[1.59,0]],"id":52671121}],"con":true,"img":false}]}
{"op":"mcm","clk":"11450310315","pt":1717320433408,"mc":[{"id":"1.229554921","rc":[{"atb":[[1.61,6.43]],"id":52671121}],"con":true,"img":false}]}
{"op":"mcm","clk":"11450311008","pt":1717320443828,"mc":[{"id":"1.229554921","rc":[{"atb":[[1.79,93.42]],"id":62262930}],"con":true,"img":false}]}
{"op":"mcm","clk":"11450311015","pt":1717320443886,"mc":[{"id":"1.229554921","rc":[{"atb":[[1.57,0]],"id":62262930},{"atb":[[1.5,167.42],[1.38,0]],"id":70003371}],"con":true,"img":false}]}
{"op":"mcm","clk":"11450311338","pt":1717320448597,"mc":[{"id":"1.229554921","rc":[{"atb":[[1.54,0]],"id":52671121}],"con":true,"img":false}]}
{"op":"mcm","clk":"11450311345","pt":1717320448702,"mc":[{"id":"1.229554921","rc":[{"atb":[[1.46,49.65]],"id":52671121}],"con":true,"img":false}]}
{"op":"mcm","clk":"11450312557","pt":1717320468539,"mc":[{"id":"1.229554921","rc":[{"atb":[[1.56,0],[1.62,42.24]],"id":52671121}],"con":true,"img":false}]}
{"op":"mcm","clk":"11450312708","pt":1717320471142,"mc":[{"id":"1.229554921","rc":[{"atb":[[1.85,0]],"id":62262930},{"atb":[[1.54,0]],"id":70003371}],"con":true,"img":false}]}
{"op":"mcm","clk":"11450312714","pt":1717320471247,"mc":[{"id":"1.229554921","rc":[{"atb":[[2.08,33.29]],"id":62262930},{"atb":[[1.61,48.02]],"id":70003371}],"con":true,"img":false}]}
{"op":"mcm","clk":"11450313094","pt":1717320477943,"mc":[{"id":"1.229554921","rc":[{"atb":[[1.61,0]],"id":52671121},{"atb":[[1.97,0]],"id":62262930}],"con":true,"img":false}]}
{"op":"mcm","clk":"11450313103","pt":1717320478051,"mc":[{"id":"1.229554921","rc":[{"atb":[[1.56,84.48],[1.62,0]],"id":52671121}],"con":true,"img":false}]}
{"op":"mcm","clk":"11450313108","pt":1717320478152,"mc":[{"id":"1.229554921","rc":[{"atb":[[1.64,6.13]],"id":52671121},{"atb":[[2.12,3.5]],"id":62262930}],"con":true,"img":false}]}
{"op":"mcm","clk":"11450314547","pt":1717320503381,"mc":[{"id":"1.229554921","rc":[{"atb":[[1.56,0],[1.65,42.24]],"id":52671121},{"spn":3.32,"spf":"NaN","id":52671121},{"spn":5.56,"spf":"NaN","id":62262930}],"con":true,"img":false}]}
{"op":"mcm","clk":"11450315112","pt":1717320511806,"mc":[{"id":"1.229554921","rc":[{"atl":[[8.2,0]],"id":52671121}],"con":true,"img":false}]}
{"op":"mcm","clk":"11450315117","pt":1717320511909,"mc":[{"id":"1.229554921","rc":[{"atl":[[7.6,13.35]],"id":52671121}],"con":true,"img":false}]}
{"op":"mcm","clk":"11450325332","pt":1717320556260,"mc":[{"id":"1.229554921","rc":[{"atb":[[1.47,9.06]],"id":52671121}],"con":true,"img":false}]}
{"op":"mcm","clk":"11450325363","pt":1717320556564,"mc":[{"id":"1.229554921","rc":[{"atb":[[1.82,5.19]],"id":62262930}],"con":true,"img":false}]}
{"op":"mcm","clk":"11450325371","pt":1717320556670,"mc":[{"id":"1.229554921","rc":[{"atb":[[1.79,0],[1.84,93.42]],"id":62262930},{"atl":[[110,2.38],[120,0]],"id":69421986},{"atb":[[1.67,0],[1.71,55.31]],"id":65460404},{"atb":[[2.86,25.82],[2.7,0]],"id":64546979}],"con":true,"img":false}]}
{"op":"mcm","clk":"11450325392","pt":1717320556840,"mc":[{"id":"1.229554921","rc":[{"atb":[[1.62,6.86]],"id":70003371}],"con":true,"img":false}]}
{"op":"mcm","clk":"11450325431","pt":1717320557250,"mc":[{"id":"1.229554921","rc":[{"atb":[[1.64,0]],"id":52671121}],"con":true,"img":false}]}
{"op":"mcm","clk":"11450325443","pt":1717320557359,"mc":[{"id":"1.229554921","rc":[{"atb":[[1.56,84.48],[1.65,0]],"id":52671121}],"con":true,"img":false}]}
{"op":"mcm","clk":"11450326290","pt":1717320568283,"mc":[{"id":"1.229554921","rc":[{"spn":3.28,"spf":"NaN","id":52671121},{"atb":[[1.68,0]],"id":65460404}],"con":true,"img":false}]}
{"op":"mcm","clk":"11450326296","pt":1717320568336,"mc":[{"id":"1.229554921","rc":[{"atb":[[1.64,45.77]],"id":65460404}],"con":true,"img":false}]}
{"op":"mcm","clk":"11450328199","pt":1717320594986,"mc":[{"id":"1.229554921","rc":[{"atb":[[1.47,0]],"id":52671121},{"atb":[[1.82,0]],"id":62262930}],"con":true,"img":false}]}
{"op":"mcm","clk":"11450329594","pt":1717320613378,"mc":[{"id":"1.229554921","rc":[{"atb":[[1.58,6.76]],"id":52671121}],"con":true,"img":false}]}
{"op":"mcm","clk":"11450329605","pt":1717320613481,"mc":[{"id":"1.229554921","rc":[{"atb":[[1.56,0],[1.59,42.24]],"id":52671121}],"con":true,"img":false}]}
{"op":"mcm","clk":"11450330798","pt":1717320628104,"mc":[{"id":"1.229554921","rc":[{"atb":[[1.58,0]],"id":52671121}],"con":true,"img":false}]}
{"op":"mcm","clk":"11450330806","pt":1717320628208,"mc":[{"id":"1.229554921","rc":[{"atb":[[1.56,84.48],[1.59,0]],"id":52671121}],"con":true,"img":false}]}
{"op":"mcm","clk":"11450330814","pt":1717320628311,"mc":[{"id":"1.229554921","rc":[{"atb":[[1.61,6.43]],"id":52671121},{"spn":3.3,"spf":"NaN","id":52671121}],"con":true,"img":false}]}
{"op":"mcm","clk":"11450331494","pt":1717320636411,"mc":[{"id":"1.229554921","rc":[{"atb":[[1.87,4.89]],"id":62262930}],"con":true,"img":false}]}
{"op":"mcm","clk":"11450333357","pt":1717320661421,"mc":[{"id":"1.229554921","rc":[{"atb":[[1.56,0],[1.62,42.24]],"id":52671121}],"con":true,"img":false}]}
{"op":"mcm","clk":"11450334261","pt":1717320673026,"mc":[{"id":"1.229554921","rc":[{"atb":[[1.61,0]],"id":52671121}],"con":true,"img":false}]}
{"op":"mcm","clk":"11450334270","pt":1717320673127,"mc":[{"id":"1.229554921","rc":[{"atb":[[1.56,84.48],[1.62,0]],"id":52671121}],"con":true,"img":false}]}
{"op":"mcm","clk":"11450334290","pt":1717320673273,"mc":[{"id":"1.229554921","rc":[{"atb":[[1.64,6.13]],"id":52671121}],"con":true,"img":false}]}
{"op":"mcm","clk":"11450334592","pt":1717320676667,"mc":[{"id":"1.229554921","rc":[{"atl":[[130,2]],"id":69421986},{"atb":[[1.68,63.64],[1.71,0]],"id":65460404},{"atb":[[2.86,0],[2.74,36.38]],"id":64546979}],"con":true,"img":false}]}
{"op":"mcm","clk":"11450334598","pt":1717320676767,"mc":[{"id":"1.229554921","rc":[{"atl":[[110,0.38]],"id":69421986}],"con":true,"img":false}]}
{"op":"mcm","clk":"11450335041","pt":1717320681964,"mc":[{"id":"1.229554921","rc":[{"atl":[[110,0]],"id":69421986}],"con":true,"img":false}]}
{"op":"mcm","clk":"11450335048","pt":1717320682068,"mc":[{"id":"1.229554921","rc":[{"atl":[[120,0.38]],"id":69421986}],"con":true,"img":false}]}
{"op":"mcm","clk":"11450336543","pt":1717320701868,"mc":[{"id":"1.229554921","rc":[{"spn":3.32,"spf":"NaN","id":52671121},{"spn":64.9,"spf":"NaN","id":69421986},{"atb":[[1.64,0]],"id":65460404}],"con":true,"img":false}]}
{"op":"mcm","clk":"11450336552","pt":1717320701983,"mc":[{"id":"1.229554921","rc":[{"atb":[[1.69,45.77]],"id":65460404}],"con":true,"img":false}]}
{"op":"mcm","clk":"11450336914","pt":1717320705980,"mc":[{"id":"1.229554921","rc":[{"atb":[[1.56,0],[1.65,42.24]],"id":52671121}],"con":true,"img":false}]}
{"op":"mcm","clk":"11450337281","pt":1717320710599,"mc":[{"id":"1.229554921","rc":[{"atb":[[1.47,9.06]],"id":52671121}],"con":true,"img":false}]}
{"op":"mcm","clk":"11450340449","pt":1717320748313,"mc":[{"id":"1.229554921","rc":[{"atb":[[1.64,0]],"id":52671121}],"con":true,"img":false}]}
{"op":"mcm","clk":"11450340457","pt":1717320748414,"mc":[{"id":"1.229554921","rc":[{"atb":[[1.56,84.48],[1.65,0]],"id":52671121}],"con":true,"img":false}]}
{"op":"mcm","clk":"11450340736","pt":1717320752241,"mc":[{"id":"1.229554921","rc":[{"atb":[[1.47,0]],"id":52671121}],"con":true,"img":false}]}
{"op":"mcm","clk":"11450341629","pt":1717320763234,"mc":[{"id":"1.229554921","rc":[{"atb":[[1.58,6.76]],"id":52671121},{"spn":3.29,"spf":"NaN","id":52671121}],"con":true,"img":false}]}
{"op":"mcm","clk":"11450341639","pt":1717320763342,"mc":[{"id":"1.229554921","rc":[{"atb":[[1.56,0],[1.59,42.24]],"id":52671121}],"con":true,"img":false}]}
{"op":"mcm","clk":"11450342830","pt":1717320778228,"mc":[{"id":"1.229554921","rc":[{"atb":[[1.58,0]],"id":52671121}],"con":true,"img":false}]}
{"op":"mcm","clk":"11450342839","pt":1717320778330,"mc":[{"id":"1.229554921","rc":[{"atb":[[1.56,84.48]],"id":52671121}],"con":true,"img":false}]}
{"op":"mcm","clk":"11450342850","pt":1717320778434,"mc":[{"id":"1.229554921","rc":[{"atb":[[1.59,0],[1.61,6.43]],"id":52671121}],"con":true,"img":false}]}
{"op":"mcm","clk":"11450344103","pt":1717320794046,"mc":[{"id":"1.229554921","rc":[{"atb":[[1.45,0],[1.55,0]],"id":52671121},{"atl":[[5,0]],"id":52671121},{"atb":[[2.06,0],[1.93,0]],"id":62262930},{"atl":[[9,0]],"id":62262930},{"atb":[[3.4,0],[3.9,0]],"id":69577417},{"atb":[[6.8,0],[5.4,0]],"id":69421986},{"atb":[[1.73,0],[1.63,0]],"id":65460404},{"atl":[[6.8,5.81]],"id":65460404},{"atb":[[3.7,0],[4.4,16.63]],"id":64546979},{"atb":[[1.6,0],[1.7,0]],"id":70003371},{"atl":[[6.6,0]],"id":70003371}],"con":true,"img":false}]}
{"op":"mcm","clk":"11450344195","pt":1717320795251,"mc":[{"id":"1.229554921","rc":[{"atb":[[1.56,0],[1.62,49.66]],"id":52671121}],"con":true,"img":false}]}
{"op":"mcm","clk":"11450345232","pt":1717320808460,"mc":[{"id":"1.229554921","rc":[{"atb":[[1.61,0]],"id":52671121}],"con":true,"img":false}]}
{"op":"mcm","clk":"11450345244","pt":1717320808565,"mc":[{"id":"1.229554921","rc":[{"atb":[[1.62,0],[1.47,99.32]],"id":52671121}],"con":true,"img":false}]}
{"op":"mcm","clk":"11450345255","pt":1717320808669,"mc":[{"id":"1.229554921","rc":[{"atb":[[1.64,6.13]],"id":52671121}],"con":true,"img":false}]}
{"op":"mcm","clk":"11450345263","pt":1717320808770,"mc":[{"id":"1.229554921","rc":[{"atb":[[1.65,49.66]],"id":52671121}],"con":true,"img":false}]}
{"op":"mcm","clk":"11450345272","pt":1717320808874,"mc":[{"id":"1.229554921","rc":[{"atb":[[1.47,0]],"id":52671121}],"con":true,"img":false}]}
{"op":"mcm","clk":"11450345295","pt":1717320809084,"mc":[{"id":"1.229554921","rc":[{"atb":[[1.43,81.02],[1.53,43.82]],"id":52671121},{"atl":[[4.8,0.13]],"id":52671121},{"atb":[[2.12,24.24],[1.96,36.29]],"id":62262930},{"atl":[[9.4,0.06]],"id":62262930},{"atb":[[3.15,16.2],[3.65,32.46]],"id":69577417},{"atb":[[6.4,4.3],[5.2,8.29]],"id":69421986},{"atb":[[1.66,52.79],[1.76,35.72]],"id":65460404},{"atl":[[7,6.91]],"id":65460404},{"atb":[[4.6,6.45],[3.8,12.44]],"id":64546979},{"atb":[[1.59,59.05],[1.69,33.66]],"id":70003371},{"atl":[[6.6,0.09]],"id":70003371}],"con":true,"img":false}]}
{"op":"mcm","clk":"11450345410","pt":1717320810689,"mc":[{"id":"1.229554921","rc":[{"atb":[[1.61,0]],"id":70003371}],"con":true,"img":false}]}
{"op":"mcm","clk":"11450345416","pt":1717320810739,"mc":[{"id":"1.229554921","rc":[{"atb":[[1.6,48.02]],"id":70003371}],"con":true,"img":false}]}
{"op":"mcm","clk":"11450346409","pt":1717320823086,"mc":[{"id":"1.229554921","rc":[{"atb":[[2.12,20.73]],"id":62262930},{"atb":[[1.73,0]],"id":70003371}],"con":true,"img":false}]}
{"op":"mcm","clk":"11450346986","pt":1717320829903,"mc":[{"id":"1.229554921","rc":[{"atb":[[1.46,0]],"id":52671121},{"spn":3.22,"spf":"NaN","id":52671121},{"atb":[[2.08,0]],"id":62262930},{"spn":5.76,"spf":"NaN","id":62262930},{"spn":1.69,"spf":1.0,"id":70003371}],"con":true,"img":false}]}
{"op":"mcm","clk":"11450346993","pt":1717320830006,"mc":[{"id":"1.229554921","rc":[{"atb":[[1.54,49.65]],"id":52671121},{"atb":[[1.97,33.29]],"id":62262930}],"con":true,"img":false}]}
{"op":"mcm","clk":"11450347724","pt":1717320838688,"mc":[{"id":"1.229554921","rc":[{"atb":[[1.72,5.44]],"id":70003371}],"con":true,"img":false}]}
{"op":"mcm","clk":"11450347736","pt":1717320838792,"mc":[{"id":"1.229554921","rc":[{"atb":[[2,3.92]],"id":62262930}],"con":true,"img":false}]}
{"op":"mcm","clk":"11450348218","pt":1717320843805,"mc":[{"id":"1.229554921","rc":[{"atb":[[2.8,2.36]],"id":64546979}],"con":true,"img":false}]}
{"op":"mcm","clk":"11450348249","pt":1717320844120,"mc":[{"id":"1.229554921","rc":[{"atb":[[1.62,0]],"id":70003371}],"con":true,"img":false}]}
{"op":"mcm","clk":"11450349918","pt":1717320862932,"mc":[{"id":"1.229554921","rc":[{"atl":[[130,0],[110,2]],"id":69421986},{"atb":[[2.36,23.76],[2.74,0]],"id":64546979}],"con":true,"img":false}]}
{"op":"mcm","clk":"11450350421","pt":1717320868698,"mc":[{"id":"1.229554921","rc":[{"atb":[[1.76,30.56]],"id":65460404}],"con":true,"img":false}]}
{"op":"mcm","clk":"11450351023","pt":1717320875340,"mc":[{"id":"1.229554921","rc":[{"atb":[[2.8,0]],"id":64546979}],"con":true,"img":false}]}
{"op":"mcm","clk":"11450351064","pt":1717320875911,"mc":[{"id":"1.229554921","rc":[{"atb":[[1.61,6.98]],"id":70003371}],"con":true,"img":false}]}
{"op":"mcm","clk":"11450351272","pt":1717320878544,"mc":[{"id":"1.229554921","rc":[{"atb":[[1.68,0],[1.71,61.12]],"id":65460404}],"con":true,"img":false}]}
{"op":"mcm","clk":"11450351718","pt":1717320883513,"mc":[{"id":"1.229554921","rc":[{"atb":[[1.64,0]],"id":52671121},{"atb":[[1.74,5.3]],"id":65460404}],"con":true,"img":false}]}
{"op":"mcm","clk":"11450351728","pt":1717320883615,"mc":[{"id":"1.229554921","rc":[{"atb":[[1.55,99.32]],"id":52671121}],"con":true,"img":false}]}
{"op":"mcm","clk":"11450351737","pt":1717320883718,"mc":[{"id":"1.229554921","rc":[{"atb":[[1.65,0]],"id":52671121}],"con":true,"img":false}]}
{"op":"mcm","clk":"11450351767","pt":1717320884031,"mc":[{"id":"1.229554921","rc":[{"atl":[[170,0.24],[120,0]],"id":69421986},{"atb":[[1.69,0]],"id":65460404}],"con":true,"img":false}]}
{"op":"mcm","clk":"11450351772","pt":1717320884129,"mc":[{"id":"1.229554921","rc":[{"atb":[[1.67,45.77]],"id":65460404}],"con":true,"img":false}]}
{"op":"mcm","clk":"11450352581","pt":1717320893863,"mc":[{"id":"1.229554921","rc":[{"spn":3.17,"spf":"NaN","id":52671121},{"spn":59.9,"spf":"NaN","id":69421986},{"atb":[[2.36,0],[2.86,23.76]],"id":64546979},{"spn":1.72,"spf":1.0,"id":70003371}],"con":true,"img":false}]}
{"op":"mcm","clk":"11450352941","pt":1717320898728,"mc":[{"id":"1.229554921","rc":[{"atb":[[1.57,6.88]],"id":52671121}],"con":true,"img":false}]}
{"op":"mcm","clk":"11450354296","pt":1717320914407,"mc":[{"id":"1.229554921","rc":[{"atb":[[1.55,0],[1.58,49.66]],"id":52671121}],"con":true,"img":false}]}
{"op":"mcm","clk":"11450354413","pt":1717320915858,"mc":[{"id":"1.229554921","rc":[{"atb":[[1.72,52.79]],"id":65460404}],"con":true,"img":false}]}
{"op":"mcm","clk":"11450354423","pt":1717320915960,"mc":[{"id":"1.229554921","rc":[{"atb":[[1.71,0]],"id":65460404}],"con":true,"img":false}]}
{"op":"mcm","clk":"11450354448","pt":1717320916268,"mc":[{"id":"1.229554921","rc":[{"atb":[[1.45,9.46]],"id":52671121}],"con":true,"img":false}]}
{"op":"mcm","clk":"11450355446","pt":1717320928782,"mc":[{"id":"1.229554921","rc":[{"atb":[[1.57,0]],"id":52671121},{"atb":[[1.74,0]],"id":65460404}],"con":true,"img":false}]}
{"op":"mcm","clk":"11450355453","pt":1717320928886,"mc":[{"id":"1.229554921","rc":[{"atb":[[1.55,99.32]],"id":52671121}],"con":true,"img":false}]}
{"op":"mcm","clk":"11450355462","pt":1717320928990,"mc":[{"id":"1.229554921","rc":[{"atb":[[1.6,6.53],[1.58,0]],"id":52671121},{"atb":[[1.75,5.23]],"id":65460404}],"con":true,"img":false}]}
{"op":"mcm","clk":"11450355471","pt":1717320929093,"mc":[{"id":"1.229554921","rc":[{"atb":[[1.55,0],[1.61,49.66]],"id":52671121}],"con":true,"img":false}]}
{"op":"mcm","clk":"11450355653","pt":1717320931165,"mc":[{"id":"1.229554921","rc":[{"atb":[[1.71,61.12]],"id":65460404}],"con":true,"img":false}]}
{"op":"mcm","clk":"11450355664","pt":1717320931265,"mc":[{"id":"1.229554921","rc":[{"atb":[[1.72,0]],"id":65460404}],"con":true,"img":false}]}
{"op":"mcm","clk":"11450356682","pt":1717320943713,"mc":[{"id":"1.229554921","rc":[{"atb":[[1.6,0]],"id":52671121}],"con":true,"img":false}]}
{"op":"mcm","clk":"11450356693","pt":1717320943777,"mc":[{"id":"1.229554921","rc":[{"atb":[[1.55,99.32],[1.61,0]],"id":52671121}],"con":true,"img":false}]}
{"op":"mcm","clk":"11450356704","pt":1717320943879,"mc":[{"id":"1.229554921","rc":[{"atb":[[1.63,6.22]],"id":52671121}],"con":true,"img":false}]}
{"op":"mcm","clk":"11450356711","pt":1717320943983,"mc":[{"id":"1.229554921","rc":[{"atb":[[1.64,49.66],[1.55,0]],"id":52671121}],"con":true,"img":false}]}
{"op":"mcm","clk":"11450357366","pt":1717320952604,"mc":[{"id":"1.229554921","rc":[{"atb":[[1.45,0]],"id":52671121}],"con":true,"img":false}]}
{"op":"mcm","clk":"11450358082","pt":1717320961391,"mc":[{"id":"1.229554921","rc":[{"spn":3.22,"spf":"NaN","id":52671121},{"atb":[[1.72,52.79],[1.71,0]],"id":65460404}],"con":true,"img":false}]}
{"op":"mcm","clk":"11450361470","pt":1717321003874,"mc":[{"id":"1.229554921","rc":[{"atb":[[1.75,0]],"id":65460404}],"con":true,"img":false}]}
{"op":"mcm","clk":"11450361938","pt":1717321009889,"mc":[{"id":"1.229554921","rc":[{"atb":[[1.6,0]],"id":70003371}],"con":true,"img":false}]}
{"op":"mcm","clk":"11450361944","pt":1717321009990,"mc":[{"id":"1.229554921","rc":[{"atb":[[1.7,48.02]],"id":70003371}],"con":true,"img":false}]}
{"op":"mcm","clk":"11450362685","pt":1717321019075,"mc":[{"id":"1.229554921","rc":[{"atb":[[1.75,5.23]],"id":65460404},{"atb":[[1.72,0]],"id":70003371}],"con":true,"img":false}]}
{"op":"mcm","clk":"11450362698","pt":1717321019283,"mc":[{"id":"1.229554921","rc":[{"atb":[[1.73,5.36]],"id":70003371}],"con":true,"img":false}]}
{"op":"mcm","clk":"11450363015","pt":1717321023615,"mc":[{"id":"1.229554921","rc":[{"atb":[[1.61,0]],"id":70003371},{"spn":1.73,"spf":1.0,"id":70003371}],"con":true,"img":false}]}
{"op":"mcm","clk":"11450363121","pt":1717321024819,"mc":[{"id":"1.229554921","rc":[{"atb":[[1.63,0]],"id":52671121}],"con":true,"img":false}]}
{"op":"mcm","clk":"11450363138","pt":1717321025023,"mc":[{"id":"1.229554921","rc":[{"atb":[[1.64,0],[1.55,99.32]],"id":52671121}],"con":true,"img":false}]}
{"op":"mcm","clk":"11450363337","pt":1717321027523,"mc":[{"id":"1.229554921","rc":[{"atb":[[1.7,0]],"id":70003371}],"con":true,"img":false}]}
{"op":"mcm","clk":"11450363342","pt":1717321027622,"mc":[{"id":"1.229554921","rc":[{"atb":[[1.6,48.02]],"id":70003371}],"con":true,"img":false}]}
{"op":"mcm","clk":"11450363946","pt":1717321035034,"mc":[{"id":"1.229554921","rc":[{"atb":[[1.57,6.88]],"id":52671121}],"con":true,"img":false}]}
{"op":"mcm","clk":"11450364088","pt":1717321036652,"mc":[{"id":"1.229554921","rc":[{"atb":[[1.72,0],[1.71,61.12]],"id":65460404}],"con":true,"img":false}]}
{"op":"mcm","clk":"11450365433","pt":1717321054244,"mc":[{"id":"1.229554921","rc":[{"atb":[[1.55,0],[1.58,49.66]],"id":52671121}],"con":true,"img":false}]}
{"op":"mcm","clk":"11450366129","pt":1717321063674,"mc":[{"id":"1.229554921","rc":[{"atb":[[1.57,0]],"id":52671121}],"con":true,"img":false}]}
{"op":"mcm","clk":"11450366135","pt":1717321063726,"mc":[{"id":"1.229554921","rc":[{"atb":[[1.58,0],[1.55,99.32]],"id":52671121}],"con":true,"img":false}]}
{"op":"mcm","clk":"11450366141","pt":1717321063830,"mc":[{"id":"1.229554921","rc":[{"atb":[[1.6,6.53],[1.45,9.46]],"id":52671121}],"con":true,"img":false}]}
{"op":"mcm","clk":"11450366172","pt":1717321064346,"mc":[{"id":"1.229554921","rc":[{"atb":[[1.61,6.98]],"id":70003371}],"con":true,"img":false}]}
{"op":"mcm","clk":"11450367334","pt":1717321082057,"mc":[{"id":"1.229554921","rc":[{"atl":[[110,0],[120,2]],"id":69421986}],"con":true,"img":false}]}
{"op":"mcm","clk":"11450367432","pt":1717321083304,"mc":[{"id":"1.229554921","rc":[{"atb":[[1.55,0],[1.61,49.66]],"id":52671121}],"con":true,"img":false}]}
{"op":"mcm","clk":"11450368162","pt":1717321093917,"mc":[{"id":"1.229554921","rc":[{"atb":[[1.6,0]],"id":52671121},{"spn":3.2,"spf":"NaN","id":52671121},{"spn":64.9,"spf":"NaN","id":69421986}],"con":true,"img":false}]}
{"op":"mcm","clk":"11450368183","pt":1717321094121,"mc":[{"id":"1.229554921","rc":[{"atb":[[1.55,99.32],[1.61,0]],"id":52671121}],"con":true,"img":false}]}
{"op":"mcm","clk":"11450368206","pt":1717321094383,"mc":[{"id":"1.229554921","rc":[{"atb":[[1.63,6.22]],"id":52671121}],"con":true,"img":false}]}
{"op":"mcm","clk":"11450368574","pt":1717321099697,"mc":[{"id":"1.229554921","rc":[{"atb":[[1.45,0]],"id":52671121}],"con":true,"img":false}]}
{"op":"mcm","clk":"11450369083","pt":1717321106884,"mc":[{"id":"1.229554921","rc":[{"atb":[[1.73,0]],"id":70003371}],"con":true,"img":false}]}
{"op":"mcm","clk":"11450369254","pt":1717321109624,"mc":[{"id":"1.229554921","rc":[{"atb":[[1.75,0]],"id":65460404}],"con":true,"img":false}]}
{"op":"mcm","clk":"11450369259","pt":1717321109722,"mc":[{"id":"1.229554921","rc":[{"atb":[[1.72,5.44]],"id":70003371}],"con":true,"img":false}]}
{"op":"mcm","clk":"11450369531","pt":1717321113815,"mc":[{"id":"1.229554921","rc":[{"atl":[[110,0.38]],"id":69421986}],"con":true,"img":false}]}
{"op":"mcm","clk":"11450369539","pt":1717321113922,"mc":[{"id":"1.229554921","rc":[{"atl":[[170,0]],"id":69421986}],"con":true,"img":false}]}
{"op":"mcm","clk":"11450370091","pt":1717321122618,"mc":[{"id":"1.229554921","rc":[{"atb":[[1.64,49.66]],"id":52671121}],"con":true,"img":false}]}
{"op":"mcm","clk":"11450370098","pt":1717321122723,"mc":[{"id":"1.229554921","rc":[{"atb":[[1.55,0]],"id":52671121}],"con":true,"img":false}]}
{"op":"mcm","clk":"11450370203","pt":1717321124232,"mc":[{"id":"1.229554921","rc":[{"atb":[[1.74,5.3]],"id":65460404}],"con":true,"img":false}]}
{"op":"mcm","clk":"11450370514","pt":1717321128728,"mc":[{"id":"1.229554921","rc":[{"atl":[[130,2]],"id":69421986},{"atb":[[1.68,61.12]],"id":65460404}],"con":true,"img":false}]}
{"op":"mcm","clk":"11450370519","pt":1717321128829,"mc":[{"id":"1.229554921","rc":[{"atl":[[120,0]],"id":69421986},{"atb":[[1.71,0]],"id":65460404}],"con":true,"img":false}]}
{"op":"mcm","clk":"11450370648","pt":1717321130841,"mc":[{"id":"1.229554921","rc":[{"atl":[[110,0]],"id":69421986}],"con":true,"img":false}]}
{"op":"mcm","clk":"11450370658","pt":1717321130946,"mc":[{"id":"1.229554921","rc":[{"atl":[[120,0.38]],"id":69421986}],"con":true,"img":false}]}
{"op":"mcm","clk":"11450372150","pt":1717321151965,"mc":[{"id":"1.229554921","rc":[{"atb":[[1.64,0],[1.33,99.32]],"id":52671121},{"atb":[[1.84,0],[1.74,54.03]],"id":62262930},{"atb":[[2.92,46.11],[3.3,0]],"id":69577417},{"atb":[[2.58,0]],"id":69421986},{"atl":[[130,0],[200,2]],"id":69421986},{"atb":[[1.68,0],[1.49,97.22]],"id":65460404},{"atb":[[2.86,0],[2.28,24.9]],"id":64546979}],"con":true,"img":false}]}
{"op":"mcm","clk":"11450372196","pt":1717321152584,"mc":[{"id":"1.229554921","rc":[{"atl":[[190,0.21]],"id":69421986}],"con":true,"img":false}]}
{"op":"mcm","clk":"11450372205","pt":1717321152690,"mc":[{"id":"1.229554921","rc":[{"atl":[[120,0]],"id":69421986}],"con":true,"img":false}]}
{"op":"mcm","clk":"11450372505","pt":1717321156953,"mc":[{"id":"1.229554921","rc":[{"spn":3.21,"spf":"NaN","id":52671121},{"spn":99.9,"spf":"NaN","id":69421986},{"atb":[[1.54,97.22],[1.49,0]],"id":65460404},{"spn":1.72,"spf":1.0,"id":70003371}],"con":true,"img":false}]}
{"op":"mcm","clk":"11450372569","pt":1717321157989,"mc":[{"id":"1.229554921","rc":[{"atb":[[1.43,0],[1.53,0]],"id":52671121},{"atl":[[4.8,0]],"id":52671121},{"atb":[[2.12,0],[1.96,0]],"id":62262930},{"atl":[[9.4,0]],"id":62262930},{"atb":[[3.15,0],[3.65,23.7]],"id":69577417},{"atb":[[6.4,0],[5.2,0]],"id":69421986},{"atb":[[1.66,0],[1.76,0]],"id":65460404},{"atl":[[7,6.83]],"id":65460404},{"atb":[[4.6,0],[3.8,0]],"id":64546979},{"atb":[[1.59,0],[1.69,0]],"id":70003371},{"atl":[[6.6,0]],"id":70003371}],"con":true,"img":false}]}
{"op":"mcm","clk":"11450372969","pt":1717321163090,"mc":[{"id":"1.229554921","rc":[{"atb":[[2,0]],"id":62262930},{"atb":[[1.72,0]],"id":70003371}],"con":true,"img":false}]}
{"op":"mcm","clk":"11450372978","pt":1717321163194,"mc":[{"id":"1.229554921","rc":[{"atb":[[1.5,0],[1.53,167.42]],"id":70003371}],"con":true,"img":false}]}
{"op":"mcm","clk":"11450373282","pt":1717321167968,"mc":[{"id":"1.229554921","rc":[{"atb":[[1.54,0]],"id":52671121},{"atb":[[1.97,0]],"id":62262930},{"atb":[[1.67,0]],"id":65460404},{"atb":[[1.6,0]],"id":70003371}],"con":true,"img":false}]}
{"op":"mcm","clk":"11450373291","pt":1717321168065,"mc":[{"id":"1.229554921","rc":[{"atb":[[1.34,49.65]],"id":52671121},{"atb":[[1.75,33.29]],"id":62262930},{"atb":[[1.55,45.77]],"id":65460404},{"atb":[[1.54,48.02]],"id":70003371}],"con":true,"img":false}]}
{"op":"mcm","clk":"11450373399","pt":1717321169779,"mc":[{"id":"1.229554921","rc":[{"atb":[[1.63,0]],"id":52671121},{"atb":[[1.78,5.03]],"id":62262930},{"atb":[[1.56,7.01]],"id":70003371}],"con":true,"img":false}]}
{"op":"mcm","clk":"11450373723","pt":1717321174693,"mc":[{"id":"1.229554921","rc":[{"atb":[[1.4,87.1],[1.5,46.45]],"id":52671121},{"atl":[[4.5,0.15]],"id":52671121},{"atb":[[1.95,36.67],[2.1,21.11]],"id":62262930},{"atl":[[9.2,0.06]],"id":62262930},{"atb":[[3.85,8.15],[3.35,14.82]],"id":69577417},{"atb":[[6.8,4],[5.4,7.92]],"id":69421986},{"atb":[[1.72,32.26],[1.62,56.19]],"id":65460404},{"atl":[[6.8,5.89]],"id":65460404},{"atb":[[4.6,6.45],[3.8,12.44]],"id":64546979},{"atb":[[1.72,32.26],[1.62,56.19]],"id":70003371},{"atl":[[6.8,0.08]],"id":70003371}],"con":true,"img":false}]}
{"op":"mcm","clk":"11450374075","pt":1717321179986,"mc":[{"id":"1.229554921","rc":[{"atb":[[1.36,133.57],[1.33,0]],"id":52671121},{"atb":[[1.83,42.24],[1.74,0]],"id":62262930},{"atb":[[2.92,0],[3.15,29.78]],"id":69577417},{"atb":[[2.56,23.76],[2.28,0]],"id":64546979}],"con":true,"img":false}]}
{"op":"mcm","clk":"11450374170","pt":1717321181645,"mc":[{"id":"1.229554921","rc":[{"atb":[[1.87,0]],"id":62262930}],"con":true,"img":false}]}
{"op":"mcm","clk":"11450374190","pt":1717321181951,"mc":[{"id":"1.229554921","rc":[{"atb":[[1.42,10.14]],"id":52671121}],"con":true,"img":false}]}
{"op":"mcm","clk":"11450374209","pt":1717321182459,"mc":[{"id":"1.229554921","rc":[{"atb":[[1.64,6.65]],"id":65460404}],"con":true,"img":false}]}
{"op":"mcm","clk":"11450374376","pt":1717321184854,"mc":[{"id":"1.229554921","rc":[{"atb":[[1.52,7.55]],"id":52671121},{"atl":[[50,2.04]],"id":69577417},{"atl":[[210,0]],"id":69421986},{"atb":[[1.74,0]],"id":65460404},{"atb":[[1.56,0]],"id":70003371}],"con":true,"img":false}]}
{"op":"mcm","clk":"11450374384","pt":1717321184959,"mc":[{"id":"1.229554921","rc":[{"atb":[[1.78,0]],"id":62262930},{"atl":[[60,7.23]],"id":69577417},{"atl":[[190,2.83],[500,2]],"id":69421986}],"con":true,"img":false}]}
{"op":"mcm","clk":"11450374392","pt":1717321185061,"mc":[{"id":"1.229554921","rc":[{"atl":[[50,0]],"id":69577417},{"atl":[[200,0]],"id":69421986},{"atb":[[1.75,5.23]],"id":65460404},{"atb":[[1.75,5.23]],"id":70003371}],"con":true,"img":false}]}
{"op":"mcm","clk":"11450374400","pt":1717321185164,"mc":[{"id":"1.229554921","rc":[{"atb":[[1.99,3.96]],"id":62262930}],"con":true,"img":false}]}
{"op":"mcm","clk":"11450375367","pt":1717321201875,"mc":[{"id":"1.229554921","rc":[{"atl":[[190,0.21]],"id":69421986}],"con":true,"img":false}]}
{"op":"mcm","clk":"11450375371","pt":1717321201970,"mc":[{"id":"1.229554921","rc":[{"atl":[[210,2.61]],"id":69421986}],"con":true,"img":false}]}
{"op":"mcm","clk":"11450375941","pt":1717321212577,"mc":[{"id":"1.229554921","rc":[{"atl":[[210,4.61]],"id":69421986}],"con":true,"img":false}]}
{"op":"mcm","clk":"11450375945","pt":1717321212680,"mc":[{"id":"1.229554921","rc":[{"atl":[[500,0]],"id":69421986}],"con":true,"img":false}]}
{"op":"mcm","clk":"11450376206","pt":1717321216782,"mc":[{"id":"1.229554921","rc":[{"atb":[[1.34,0]],"id":52671121},{"atb":[[1.75,0]],"id":62262930},{"atb":[[1.55,0]],"id":65460404},{"atb":[[1.54,0]],"id":70003371}],"con":true,"img":false}]}
{"op":"mcm","clk":"11450376214","pt":1717321216883,"mc":[{"id":"1.229554921","rc":[{"atb":[[1.51,49.65]],"id":52671121},{"atb":[[1.96,33.29]],"id":62262930},{"atb":[[1.63,45.77]],"id":65460404},{"atb":[[1.63,48.02]],"id":70003371}],"con":true,"img":false}]}
{"op":"mcm","clk":"11450376530","pt":1717321222618,"mc":[{"id":"1.229554921","rc":[{"spn":3.01,"spf":"NaN","id":52671121},{"spn":5.65,"spf":"NaN","id":62262930},{"spn":32.1,"spf":"NaN","id":69577417},{"spn":4.27,"spf":"NaN","id":65460404},{"atb":[[1.61,0]],"id":70003371},{"spn":1.75,"spf":1.0,"id":70003371}],"con":true,"img":false}]}
{"op":"mcm","clk":"11450376537","pt":1717321222723,"mc":[{"id":"1.229554921","rc":[{"atb":[[1.58,7.34]],"id":62262930}],"con":true,"img":false}]}
{"op":"mcm","clk":"11450376981","pt":1717321229620,"mc":[{"id":"1.229554921","rc":[{"atb":[[1.52,0]],"id":52671121},{"atb":[[1.99,0]],"id":62262930}],"con":true,"img":false}]}
{"op":"mcm","clk":"11450376998","pt":1717321229824,"mc":[{"id":"1.229554921","rc":[{"atb":[[1.53,7.41]],"id":52671121},{"atb":[[2,3.92]],"id":62262930}],"con":true,"img":false}]}
{"op":"mcm","clk":"11450378789","pt":1717321260232,"mc":[{"id":"1.229554921","rc":[{"atb":[[1.64,6.65]],"id":70003371}],"con":true,"img":false}]}
{"op":"mcm","clk":"11450378856","pt":1717321261043,"mc":[{"id":"1.229554921","rc":[{"atl":[[210,2]],"id":69421986}],"con":true,"img":false}]}
{"op":"mcm","clk":"11450378864","pt":1717321261118,"mc":[{"id":"1.229554921","rc":[{"atl":[[200,2.61]],"id":69421986}],"con":true,"img":false}]}
{"op":"mcm","clk":"11450378878","pt":1717321261279,"mc":[{"id":"1.229554921","rc":[{"atl":[[210,0],[500,2]],"id":69421986}],"con":true,"img":false}]}
{"op":"mcm","clk":"11450379602","pt":1717321271933,"mc":[{"id":"1.229554921","rc":[{"atb":[[1.83,0],[1.77,66.58]],"id":62262930},{"atb":[[2.56,0],[2.38,24.9]],"id":64546979}],"con":true,"img":false}]}
{"op":"mcm","clk":"11450380726","pt":1717321288177,"mc":[{"id":"1.229554921","rc":[{"spn":3.01,"spf":"NaN","id":52671121},{"atl":[[200,4.61]],"id":69421986}],"con":true,"img":false}]}
{"op":"mcm","clk":"11450380734","pt":1717321288232,"mc":[{"id":"1.229554921","rc":[{"atl":[[210,2],[500,0]],"id":69421986}],"con":true,"img":false}]}
{"op":"mcm","clk":"11450380742","pt":1717321288336,"mc":[{"id":"1.229554921","rc":[{"atl":[[200,2.61]],"id":69421986}],"con":true,"img":false}]}
{"op":"mcm","clk":"11450381009","pt":1717321292573,"mc":[{"id":"1.229554921","rc":[{"atb":[[1.58,0]],"id":62262930}],"con":true,"img":false}]}
{"op":"mcm","clk":"11450382575","pt":1717321318493,"mc":[{"id":"1.229554921","rc":[{"atl":[[60,4.61]],"id":69577417}],"con":true,"img":false}]}
{"op":"mcm","clk":"11450382582","pt":1717321318596,"mc":[{"id":"1.229554921","rc":[{"atl":[[55,2.61]],"id":69577417}],"con":true,"img":false}]}
{"op":"mcm","clk":"11450383261","pt":1717321329852,"mc":[{"id":"1.229554921","rc":[{"atb":[[1.8,5.32]],"id":62262930}],"con":true,"img":false}]}
{"op":"mcm","clk":"11450388540","pt":1717321415741,"mc":[{"id":"1.229554921","rc":[{"spn":29.6,"spf":"NaN","id":69577417},{"atl":[[7,0]],"id":65460404}],"con":true,"img":false}]}
{"op":"mcm","clk":"11450388545","pt":1717321415842,"mc":[{"id":"1.229554921","rc":[{"atl":[[8,11.8],[6.8,0.08]],"id":65460404}],"con":true,"img":false}]}
{"op":"mcm","clk":"11450388561","pt":1717321416049,"mc":[{"id":"1.229554921","rc":[{"atl":[[6.8,6.09]],"id":65460404}],"con":true,"img":false}]}
{"op":"mcm","clk":"11450390028","pt":1717321441253,"mc":[{"id":"1.229554921","rc":[{"atl":[[8,0],[6.6,6.1]],"id":65460404}],"con":true,"img":false}]}
{"op":"mcm","clk":"11450394593","pt":1717321511551,"mc":[{"id":"1.229554921","rc":[{"atb":[[1.4,0],[1.5,0]],"id":52671121},{"atl":[[4.5,0]],"id":52671121},{"spn":4.46,"spf":"NaN","id":52671121},{"atb":[[1.95,0],[2.1,0]],"id":62262930},{"atl":[[9.2,0]],"id":62262930},{"spn":7.0,"spf":"NaN","id":62262930},{"atb":[[3.85,0],[3.35,0]],"id":69577417},{"atb":[[6.8,0],[5.4,0]],"id":69421986},{"atb":[[1.72,0],[1.62,0]],"id":65460404},{"atl":[[6.8,6.01]],"id":65460404},{"spn":4.17,"spf":"NaN","id":65460404},{"atb":[[4.6,0],[3.8,0]],"id":64546979},{"atb":[[1.72,0],[1.62,0]],"id":70003371},{"atl":[[6.8,0]],"id":70003371}],"con":true,"img":false}]}
{"op":"mcm","clk":"11450395514","pt":1717321524665,"mc":[{"id":"1.229554921","rc":[{"atb":[[1.42,0]],"id":52671121},{"atb":[[1.64,0]],"id":65460404},{"atb":[[1.64,0]],"id":70003371}],"con":true,"img":false}]}
{"op":"mcm","clk":"11450395783","pt":1717321528648,"mc":[{"id":"1.229554921","rc":[{"atb":[[1.51,0]],"id":52671121},{"atb":[[1.96,0]],"id":62262930},{"atb":[[1.63,0]],"id":65460404},{"atb":[[1.63,0]],"id":70003371}],"con":true,"img":false}]}
{"op":"mcm","clk":"11450395792","pt":1717321528751,"mc":[{"id":"1.229554921","rc":[{"atb":[[1.37,49.65]],"id":52671121},{"atb":[[1.78,33.29]],"id":62262930},{"atb":[[1.55,45.77]],"id":65460404},{"atb":[[1.54,48.02]],"id":70003371}],"con":true,"img":false}]}
{"op":"mcm","clk":"11450396044","pt":1717321532180,"mc":[{"id":"1.229554921","rc":[{"atb":[[1.4,87.1],[1.5,46.45]],"id":52671121},{"atl":[[4.5,0.15]],"id":52671121},{"atb":[[1.97,35.92],[2.14,20.37]],"id":62262930},{"atl":[[9.4,0.06]],"id":62262930},{"atb":[[3.25,15.48],[3.75,8.44]],"id":69577417},{"atb":[[5.6,7.57],[7.2,3.74]],"id":69421986},{"atb":[[1.73,31.81],[1.63,55.3]],"id":65460404},{"atl":[[6.8,6.09]],"id":65460404},{"atb":[[4.8,6.11],[3.9,12.01]],"id":64546979},{"atb":[[1.59,59.05],[1.69,33.66]],"id":70003371},{"atl":[[6.6,0.09]],"id":70003371}],"con":true,"img":false}]}
{"op":"mcm","clk":"11450396053","pt":1717321532279,"mc":[{"id":"1.229554921","rc":[{"atb":[[2,0]],"id":62262930},{"atb":[[1.75,0]],"id":70003371}],"con":true,"img":false}]}
{"op":"mcm","clk":"11450396115","pt":1717321532901,"mc":[{"id":"1.229554921","rc":[{"atb":[[2,3.92]],"id":62262930},{"atb":[[1.75,0]],"id":65460404},{"atb":[[1.72,5.44]],"id":70003371}],"con":true,"img":false}]}
{"op":"mcm","clk":"11450396133","pt":1717321533056,"mc":[{"id":"1.229554921","rc":[{"atb":[[1.76,5.16]],"id":65460404}],"con":true,"img":false}]}
{"op":"mcm","clk":"11450398001","pt":1717321561404,"mc":[{"id":"1.229554921","rc":[{"atb":[[1.66,6.45]],"id":65460404}],"con":true,"img":false}]}
{"op":"mcm","clk":"11450398038","pt":1717321561916,"mc":[{"id":"1.229554921","rc":[{"atb":[[1.42,10.14]],"id":52671121},{"atb":[[1.61,6.98]],"id":70003371}],"con":true,"img":false}]}
{"op":"mcm","clk":"11450400070","pt":1717321589162,"mc":[{"id":"1.229554921","rc":[{"atb":[[1.37,0]],"id":52671121},{"spn":3.01,"spf":"NaN","id":52671121},{"atb":[[1.78,0]],"id":62262930},{"spn":5.77,"spf":"NaN","id":62262930},{"atb":[[1.55,0]],"id":65460404},{"spn":4.18,"spf":"NaN","id":65460404},{"atb":[[1.54,0]],"id":70003371},{"spn":1.72,"spf":1.0,"id":70003371}],"con":true,"img":false}]}
{"op":"mcm","clk":"11450400079","pt":1717321589265,"mc":[{"id":"1.229554921","rc":[{"atb":[[1.51,49.65]],"id":52671121},{"atb":[[1.98,33.29]],"id":62262930},{"atb":[[1.64,45.77]],"id":65460404},{"atb":[[1.6,48.02]],"id":70003371}],"con":true,"img":false}]}
{"op":"mcm","clk":"11450400368","pt":1717321593217,"mc":[{"id":"1.229554921","rc":[{"atb":[[1.53,0]],"id":52671121}],"con":true,"img":false}]}
{"op":"mcm","clk":"11450400583","pt":1717321596077,"mc":[{"id":"1.229554921","rc":[{"atb":[[1.53,7.4]],"id":52671121},{"atb":[[2,0]],"id":62262930}],"con":true,"img":false}]}
{"op":"mcm","clk":"11450400597","pt":1717321596283,"mc":[{"id":"1.229554921","rc":[{"atb":[[2.02,3.84]],"id":62262930}],"con":true,"img":false}]}
{"op":"mcm","clk":"11450421260","pt":1717321850344,"mc":[{"id":"1.229554921","rc":[{"atb":[[1.4,0],[1.5,0]],"id":52671121},{"atl":[[4.5,0]],"id":52671121},{"spn":4.46,"spf":"NaN","id":52671121},{"atb":[[1.97,0],[2.14,0]],"id":62262930},{"atl":[[9.4,0]],"id":62262930},{"spn":7.01,"spf":"NaN","id":62262930},{"atb":[[3.25,0],[3.75,0]],"id":69577417},{"atb":[[5.6,0],[7.2,0]],"id":69421986},{"atb":[[1.73,0],[1.63,0]],"id":65460404},{"atl":[[6.8,6.01]],"id":65460404},{"atb":[[4.8,0],[3.9,0]],"id":64546979},{"atb":[[1.59,0],[1.69,0]],"id":70003371},{"atl":[[6.6,0]],"id":70003371}],"con":true,"img":false}]}
{"op":"mcm","clk":"11450421365","pt":1717321851397,"mc":[{"id":"1.229554921","rc":[{"atb":[[1.51,0]],"id":52671121},{"atb":[[1.98,0]],"id":62262930},{"atb":[[1.64,0]],"id":65460404},{"atb":[[1.6,0]],"id":70003371}],"con":true,"img":false}]}
{"op":"mcm","clk":"11450421373","pt":1717321851500,"mc":[{"id":"1.229554921","rc":[{"atb":[[1.37,49.65]],"id":52671121},{"atb":[[1.78,33.29]],"id":62262930},{"atb":[[1.55,45.77]],"id":65460404},{"atb":[[1.54,48.02]],"id":70003371}],"con":true,"img":false}]}
{"op":"mcm","clk":"11450422454","pt":1717321864135,"mc":[{"id":"1.229554921","rc":[{"atb":[[1.42,0]],"id":52671121},{"atb":[[1.66,0]],"id":65460404},{"atb":[[1.61,0]],"id":70003371}],"con":true,"img":false}]}
{"op":"mcm","clk":"11450422631","pt":1717321866320,"mc":[{"id":"1.229554921","rc":[{"atb":[[2.02,0]],"id":62262930}],"con":true,"img":false}]}
{"op":"mcm","clk":"11450422834","pt":1717321868751,"mc":[{"id":"1.229554921","rc":[{"atb":[[1.81,4.84]],"id":62262930}],"con":true,"img":false}]}
{"op":"mcm","clk":"11450422882","pt":1717321869337,"mc":[{"id":"1.229554921","rc":[{"atb":[[1.45,77.43],[1.55,42.23]],"id":52671121},{"atl":[[5,0.13]],"id":52671121},{"atb":[[2.12,20.73],[1.96,36.29]],"id":62262930},{"atl":[[9.4,0.06]],"id":62262930},{"atb":[[3.25,15.48],[3.75,8.44]],"id":69577417},{"atb":[[6.4,4.3],[5.2,8.29]],"id":69421986},{"atb":[[1.72,32.26],[1.62,56.19]],"id":65460404},{"atl":[[6.8,6.09]],"id":65460404},{"atb":[[4.3,7.03],[3.65,13.14]],"id":64546979},{"atb":[[1.72,37.71],[1.62,56.19]],"id":70003371},{"atl":[[6.8,0.08]],"id":70003371}],"con":true,"img":false}]}
{"op":"mcm","clk":"11450424541","pt":1717321889760,"mc":[{"id":"1.229554921","rc":[{"atb":[[1.53,0]],"id":52671121}],"con":true,"img":false}]}
{"op":"mcm","clk":"11450424552","pt":1717321889860,"mc":[{"id":"1.229554921","rc":[{"atb":[[1.81,0]],"id":62262930}],"con":true,"img":false}]}
{"op":"mcm","clk":"11450424561","pt":1717321889966,"mc":[{"id":"1.229554921","rc":[{"atb":[[1.72,32.26]],"id":70003371}],"con":true,"img":false}]}
{"op":"mcm","clk":"11450424609","pt":1717321890536,"mc":[{"id":"1.229554921","rc":[{"atb":[[1.57,6.88]],"id":52671121},{"atb":[[2,3.92]],"id":62262930}],"con":true,"img":false}]}
{"op":"mcm","clk":"11450424616","pt":1717321890640,"mc":[{"id":"1.229554921","rc":[{"atb":[[1.75,5.22]],"id":70003371}],"con":true,"img":false}]}
{"op":"mcm","clk":"11450425232","pt":1717321898461,"mc":[{"id":"1.229554921","rc":[{"atb":[[4.9,0]],"id":64546979}],"con":true,"img":false}]}
{"op":"mcm","clk":"11450425242","pt":1717321898565,"mc":[{"id":"1.229554921","rc":[{"atb":[[5.2,11.31]],"id":64546979}],"con":true,"img":false}]}
{"op":"mcm","clk":"11450425446","pt":1717321901159,"mc":[{"id":"1.229554921","rc":[{"atb":[[1.64,6.65]],"id":65460404}],"con":true,"img":false}]}
{"op":"mcm","clk":"11450425483","pt":1717321901667,"mc":[{"id":"1.229554921","rc":[{"atb":[[1.47,9.06]],"id":52671121}],"con":true,"img":false}]}
{"op":"mcm","clk":"11450425527","pt":1717321902186,"mc":[{"id":"1.229554921","rc":[{"atb":[[1.64,6.65]],"id":70003371}],"con":true,"img":false}]}
{"op":"mcm","clk":"11450425655","pt":1717321903399,"mc":[{"id":"1.229554921","rc":[{"atb":[[1.45,0],[1.55,0]],"id":52671121},{"atl":[[5,0]],"id":52671121},{"atb":[[3.25,0],[3.75,0]],"id":69577417},{"atb":[[6.4,0],[5.2,0]],"id":69421986},{"atb":[[1.72,0],[1.62,0]],"id":65460404},{"atl":[[6.8,6.01]],"id":65460404},{"atb":[[4.3,0],[3.65,0]],"id":64546979},{"atb":[[1.72,0],[1.62,0]],"id":70003371},{"atl":[[6.8,0]],"id":70003371}],"con":true,"img":false}]}
{"op":"mcm","clk":"11450425820","pt":1717321905071,"mc":[{"id":"1.229554921","rc":[{"atb":[[1.75,0]],"id":70003371}],"con":true,"img":false}]}
{"op":"mcm","clk":"11450425849","pt":1717321905383,"mc":[{"id":"1.229554921","rc":[{"atb":[[1.49,96.06],[1.53,0]],"id":70003371}],"con":true,"img":false}]}
{"op":"mcm","clk":"11450426126","pt":1717321908762,"mc":[{"id":"1.229554921","rc":[{"atb":[[1.56,7.01]],"id":70003371}],"con":true,"img":false}]}
{"op":"mcm","clk":"11450426478","pt":1717321913596,"mc":[{"id":"1.229554921","rc":[{"atb":[[1.56,41.48],[1.46,75.74]],"id":52671121},{"atl":[[5.1,0.12]],"id":52671121},{"spn":3.33,"spf":"NaN","id":52671121},{"spn":5.76,"spf":"NaN","id":62262930},{"atb":[[3.8,8.29],[3.3,15.15]],"id":69577417},{"atb":[[6.4,4.3],[5.2,8.29]],"id":69421986},{"atb":[[1.73,31.81],[1.63,55.3]],"id":65460404},{"atl":[[6.8,6.09]],"id":65460404},{"atb":[[4.6,6.45],[3.8,12.44]],"id":64546979},{"spn":37.6,"spf":"NaN","id":64546979},{"atb":[[1.71,32.71],[1.61,57.12]],"id":70003371},{"atl":[[6.6,0.09]],"id":70003371},{"spn":1.71,"spf":1.0,"id":70003371}],"con":true,"img":false}]}
{"op":"mcm","clk":"11450426643","pt":1717321915376,"mc":[{"id":"1.229554921","rc":[{"atb":[[1.37,0]],"id":52671121},{"atb":[[1.78,0]],"id":62262930},{"atb":[[1.55,0]],"id":65460404},{"atb":[[1.54,0]],"id":70003371}],"con":true,"img":false}]}
{"op":"mcm","clk":"11450426651","pt":1717321915479,"mc":[{"id":"1.229554921","rc":[{"atb":[[1.47,58.72]],"id":52671121},{"atb":[[1.97,33.29]],"id":62262930},{"atb":[[1.64,52.43]],"id":65460404},{"atb":[[1.62,48.02]],"id":70003371}],"con":true,"img":false}]}
{"op":"mcm","clk":"11450428142","pt":1717321930486,"mc":[{"id":"1.229554921","rc":[{"atb":[[1.76,0]],"id":65460404}],"con":true,"img":false}]}
{"op":"mcm","clk":"11450428174","pt":1717321930799,"mc":[{"id":"1.229554921","rc":[{"atb":[[1.57,0]],"id":52671121},{"atb":[[1.56,0]],"id":70003371}],"con":true,"img":false}]}
{"op":"mcm","clk":"11450428329","pt":1717321932309,"mc":[{"id":"1.229554921","rc":[{"atb":[[1.58,6.76]],"id":52671121},{"atb":[[1.74,5.3]],"id":70003371}],"con":true,"img":false}]}
{"op":"mcm","clk":"11450428400","pt":1717321932785,"mc":[{"id":"1.229554921","rc":[{"atb":[[4.4,0]],"id":64546979}],"con":true,"img":false}]}
{"op":"mcm","clk":"11450428412","pt":1717321932889,"mc":[{"id":"1.229554921","rc":[{"atb":[[4.6,23.08]],"id":64546979}],"con":true,"img":false}]}
{"op":"mcm","clk":"11450429380","pt":1717321942386,"mc":[{"id":"1.229554921","rc":[{"atb":[[1.47,49.65]],"id":52671121},{"atb":[[1.64,45.77]],"id":65460404},{"atb":[[1.64,0]],"id":70003371}],"con":true,"img":false}]}
{"op":"mcm","clk":"11450430131","pt":1717321951005,"mc":[{"id":"1.229554921","rc":[{"atb":[[1.76,5.16]],"id":65460404}],"con":true,"img":false}]}
{"op":"mcm","clk":"11450432876","pt":1717321984955,"mc":[{"id":"1.229554921","rc":[{"spn":3.34,"spf":"NaN","id":52671121},{"atb":[[1.66,6.45]],"id":65460404},{"spn":1.74,"spf":1.0,"id":70003371}],"con":true,"img":false}]}
{"op":"mcm","clk":"11450432894","pt":1717321985165,"mc":[{"id":"1.229554921","rc":[{"atb":[[1.48,8.87]],"id":52671121}],"con":true,"img":false}]}
{"op":"mcm","clk":"11450432925","pt":1717321985470,"mc":[{"id":"1.229554921","rc":[{"atb":[[1.63,6.76]],"id":70003371}],"con":true,"img":false}]}
{"op":"mcm","clk":"11450439792","pt":1717322064408,"mc":[{"id":"1.229554921","rc":[{"atb":[[1.85,66.58],[1.77,0]],"id":62262930},{"atb":[[1.54,0],[1.48,97.22]],"id":65460404},{"atb":[[2.38,0],[3,24.9]],"id":64546979},{"atb":[[1.58,96.06],[1.49,0]],"id":70003371}],"con":true,"img":false}]}
{"op":"mcm","clk":"11450439810","pt":1717322064608,"mc":[{"id":"1.229554921","rc":[{"atb":[[2.32,35.54],[3,0]],"id":64546979}],"con":true,"img":false}]}
{"op":"mcm","clk":"11450441299","pt":1717322078378,"mc":[{"id":"1.229554921","rc":[{"atb":[[1.54,97.22],[1.48,0]],"id":65460404},{"atb":[[3.2,24.9],[2.32,0]],"id":64546979}],"con":true,"img":false}]}
{"op":"mcm","clk":"11450441308","pt":1717322078478,"mc":[{"id":"1.229554921","rc":[{"atb":[[3.2,0]],"id":64546979}],"con":true,"img":false}]}
{"op":"mcm","clk":"11450441318","pt":1717322078589,"mc":[{"id":"1.229554921","rc":[{"atb":[[2.56,35.54]],"id":64546979}],"con":true,"img":false}]}
{"op":"mcm","clk":"11450442081","pt":1717322087211,"mc":[{"id":"1.229554921","rc":[{"atb":[[1.8,0]],"id":62262930}],"con":true,"img":false}]}
{"op":"mcm","clk":"11450445189","pt":1717322125115,"mc":[{"id":"1.229554921","rc":[{"atb":[[1.88,4.84]],"id":62262930}],"con":true,"img":false}]}
{"op":"mcm","clk":"11450449676","pt":1717322177094,"mc":[{"id":"1.229554921","rc":[{"atl":[[6.8,0.08]],"id":65460404}],"con":true,"img":false}]}
{"op":"mcm","clk":"11450449686","pt":1717322177192,"mc":[{"id":"1.229554921","rc":[{"atl":[[8,6.19]],"id":65460404}],"con":true,"img":false}]}
{"op":"mcm","clk":"11450449692","pt":1717322177291,"mc":[{"id":"1.229554921","rc":[{"atl":[[6.6,0]],"id":65460404}],"con":true,"img":false}]}
{"op":"mcm","clk":"11450449703","pt":1717322177396,"mc":[{"id":"1.229554921","rc":[{"atl":[[6.4,2.24]],"id":65460404}],"con":true,"img":false}]}
{"op":"mcm","clk":"11450449718","pt":1717322177607,"mc":[{"id":"1.229554921","rc":[{"atl":[[8,0]],"id":65460404}],"con":true,"img":false}]}
{"op":"mcm","clk":"11450449757","pt":1717322177974,"mc":[{"id":"1.229554921","rc":[{"atl":[[6.2,5.1]],"id":65460404}],"con":true,"img":false}]}
{"op":"mcm","clk":"11450451224","pt":1717322195420,"mc":[{"id":"1.229554921","rc":[{"atl":[[6.4,0],[6,2.24]],"id":65460404},{"spn":3.88,"spf":"NaN","id":65460404}],"con":true,"img":false}]}
{"op":"mcm","clk":"11450451530","pt":1717322198430,"mc":[{"id":"1.229554921","rc":[{"atb":[[1.85,0],[1.77,54.03]],"id":62262930},{"atb":[[2.56,0],[2.38,35.54]],"id":64546979}],"con":true,"img":false}]}
{"op":"mcm","clk":"11450451842","pt":1717322201639,"mc":[{"id":"1.229554921","rc":[{"atb":[[1.88,0]],"id":62262930}],"con":true,"img":false}]}
{"op":"mcm","clk":"11450452371","pt":1717322207247,"mc":[{"id":"1.229554921","rc":[{"atb":[[1.56,0],[1.46,0]],"id":52671121},{"atl":[[5.1,0]],"id":52671121},{"atb":[[2.12,0],[1.96,0]],"id":62262930},{"atl":[[9.4,0]],"id":62262930},{"atb":[[3.8,0],[3.3,0]],"id":69577417},{"atb":[[6.4,0],[5.2,0]],"id":69421986},{"atb":[[1.73,0],[1.63,0]],"id":65460404},{"atl":[[6.8,0]],"id":65460404},{"atb":[[4.6,16.63],[3.8,0]],"id":64546979},{"atb":[[1.71,0],[1.61,0]],"id":70003371},{"atl":[[6.6,0]],"id":70003371}],"con":true,"img":false}]}
{"op":"mcm","clk":"11450452822","pt":1717322211943,"mc":[{"id":"1.229554921","rc":[{"atb":[[1.47,0]],"id":52671121},{"atb":[[1.97,0]],"id":62262930},{"atb":[[1.64,0]],"id":65460404},{"atb":[[1.62,0]],"id":70003371}],"con":true,"img":false}]}
{"op":"mcm","clk":"11450452833","pt":1717322212049,"mc":[{"id":"1.229554921","rc":[{"atb":[[1.37,49.65]],"id":52671121},{"atb":[[1.78,33.29]],"id":62262930},{"atb":[[1.55,45.77]],"id":65460404},{"atb":[[1.59,48.02]],"id":70003371}],"con":true,"img":false}]}
{"op":"mcm","clk":"11450453810","pt":1717322222466,"mc":[{"id":"1.229554921","rc":[{"atb":[[1.01,138.04]],"id":52671121},{"atl":[[970,0.85]],"id":52671121},{"atb":[[1.03,87.84]],"id":62262930},{"atl":[[970,0.85]],"id":62262930},{"atb":[[1.02,107.37]],"id":69577417},{"atl":[[980,0.85]],"id":69577417},{"atb":[[1.01,114.18]],"id":69421986},{"atl":[[980,1.81]],"id":69421986},{"atb":[[1.03,140.6]],"id":65460404},{"atl":[[970,1.15]],"id":65460404},{"atb":[[1.01,98.84]],"id":64546979},{"atl":[[990,1.05]],"id":64546979},{"atb":[[1.02,113.02]],"id":70003371},{"atl":[[960,1.55]],"id":70003371}],"con":true,"img":false}]}
{"op":"mcm","clk":"11450453998","pt":1717322224569,"mc":[{"id":"1.229554921","rc":[{"atb":[[2,0]],"id":62262930}],"con":true,"img":false}]}
{"op":"mcm","clk":"11450454063","pt":1717322225299,"mc":[{"id":"1.229554921","rc":[{"atb":[[1.43,81.02],[1.53,43.82]],"id":52671121},{"atl":[[4.8,0.13]],"id":52671121},{"atb":[[2.06,21.91],[1.93,37.46]],"id":62262930},{"atl":[[9,0.06]],"id":62262930},{"atb":[[3.85,8.15],[3.35,14.82]],"id":69577417},{"atb":[[7.8,3.41],[5.9,7.1]],"id":69421986},{"atb":[[1.71,32.71],[1.61,57.12]],"id":65460404},{"atl":[[6.6,0.09]],"id":65460404},{"atb":[[4.5,6.63],[3.75,12.67]],"id":64546979},{"atb":[[1.71,32.71],[1.61,57.12]],"id":70003371},{"atl":[[6.6,0.09]],"id":70003371}],"con":true,"img":false}]}
{"op":"mcm","clk":"11450455555","pt":1717322239983,"mc":[{"id":"1.229554921","rc":[{"atb":[[1.48,0]],"id":52671121},{"atb":[[1.66,0]],"id":65460404}],"con":true,"img":false}]}
{"op":"mcm","clk":"11450455574","pt":1717322240174,"mc":[{"id":"1.229554921","rc":[{"atb":[[1.8,5.32]],"id":62262930}],"con":true,"img":false}]}
{"op":"mcm","clk":"11450456721","pt":1717322251898,"mc":[{"id":"1.229554921","rc":[{"atb":[[1.59,0]],"id":70003371}],"con":true,"img":false}]}
{"op":"mcm","clk":"11450456731","pt":1717322252001,"mc":[{"id":"1.229554921","rc":[{"atb":[[1.62,48.02]],"id":70003371}],"con":true,"img":false}]}
{"op":"mcm","clk":"11450457676","pt":1717322261890,"mc":[{"id":"1.229554921","rc":[{"atb":[[1.37,0]],"id":52671121},{"spn":3.19,"spf":"NaN","id":52671121},{"atb":[[1.78,0]],"id":62262930},{"spn":5.53,"spf":"NaN","id":62262930},{"atb":[[1.55,0]],"id":65460404}],"con":true,"img":false}]}
{"op":"mcm","clk":"11450457682","pt":1717322261995,"mc":[{"id":"1.229554921","rc":[{"atb":[[1.54,49.65]],"id":52671121},{"atb":[[2.08,33.29]],"id":62262930},{"atb":[[1.62,45.77]],"id":65460404}],"con":true,"img":false}]}
{"op":"mcm","clk":"11450458527","pt":1717322272201,"mc":[{"id":"1.229554921","rc":[{"atb":[[1.63,6.76]],"id":65460404}],"con":true,"img":false}]}
{"op":"mcm","clk":"11450458552","pt":1717322272411,"mc":[{"id":"1.229554921","rc":[{"atb":[[1.45,9.46]],"id":52671121}],"con":true,"img":false}]}
{"op":"mcm","clk":"11450459903","pt":1717322287729,"mc":[{"id":"1.229554921","rc":[{"atb":[[1.58,0]],"id":52671121},{"atb":[[1.76,0]],"id":65460404}],"con":true,"img":false}]}
{"op":"mcm","clk":"11450466128","pt":1717322361880,"mc":[{"id":"1.229554921","rc":[{"spn":3.17,"spf":"NaN","id":52671121},{"spn":5.54,"spf":"NaN","id":62262930},{"atb":[[1.62,0]],"id":65460404},{"spn":3.85,"spf":"NaN","id":65460404}],"con":true,"img":false}]}
{"op":"mcm","clk":"11450466140","pt":1717322361980,"mc":[{"id":"1.229554921","rc":[{"atb":[[1.72,45.77]],"id":65460404}],"con":true,"img":false}]}
{"op":"mcm","clk":"11450467028","pt":1717322371890,"mc":[{"id":"1.229554921","rc":[{"atb":[[1.36,0]],"id":65460404}],"con":true,"img":false}]}
{"op":"mcm","clk":"11450467034","pt":1717322371998,"mc":[{"id":"1.229554921","rc":[{"atb":[[1.39,176.31]],"id":65460404}],"con":true,"img":false}]}
{"op":"mcm","clk":"11450467728","pt":1717322380394,"mc":[{"id":"1.229554921","rc":[{"atl":[[6.2,0]],"id":65460404}],"con":true,"img":false}]}
{"op":"mcm","clk":"11450467738","pt":1717322380492,"mc":[{"id":"1.229554921","rc":[{"atl":[[8,5.81]],"id":65460404}],"con":true,"img":false}]}
{"op":"mcm","clk":"11450467747","pt":1717322380591,"mc":[{"id":"1.229554921","rc":[{"atl":[[6,0]],"id":65460404}],"con":true,"img":false}]}
{"op":"mcm","clk":"11450467757","pt":1717322380695,"mc":[{"id":"1.229554921","rc":[{"atl":[[6.8,6.01]],"id":65460404}],"con":true,"img":false}]}
{"op":"mcm","clk":"11450467765","pt":1717322380799,"mc":[{"id":"1.229554921","rc":[{"atl":[[8,0],[6.6,5.9]],"id":65460404}],"con":true,"img":false}]}
{"op":"mcm","clk":"11450471112","pt":1717322415527,"mc":[{"id":"1.229554921","rc":[{"atl":[[6.8,0]],"id":65460404}],"con":true,"img":false}]}
{"op":"mcm","clk":"11450471125","pt":1717322415631,"mc":[{"id":"1.229554921","rc":[{"atl":[[8,11.8],[6.6,0.09]],"id":65460404}],"con":true,"img":false}]}
{"op":"mcm","clk":"11450471166","pt":1717322416046,"mc":[{"id":"1.229554921","rc":[{"atl":[[6.4,1.54]],"id":65460404}],"con":true,"img":false}]}
{"op":"mcm","clk":"11450471176","pt":1717322416152,"mc":[{"id":"1.229554921","rc":[{"atl":[[8,0],[6.4,3.54]],"id":65460404}],"con":true,"img":false}]}
{"op":"mcm","clk":"11450471423","pt":1717322418450,"mc":[{"id":"1.229554921","rc":[{"atb":[[1.56,7.01]],"id":52671121},{"atb":[[1.75,5.23]],"id":65460404}],"con":true,"img":false}]}
{"op":"mcm","clk":"11450471433","pt":1717322418574,"mc":[{"id":"1.229554921","rc":[{"atb":[[2.12,3.5]],"id":62262930}],"con":true,"img":false}]}
{"op":"mcm","clk":"11450485415","pt":1717322584217,"mc":[{"id":"1.229554921","rc":[{"atb":[[1.43,0],[1.53,0]],"id":52671121},{"atl":[[4.8,0]],"id":52671121},{"spn":4.48,"spf":"NaN","id":52671121},{"atb":[[2.06,0],[1.93,0]],"id":62262930},{"atl":[[9,0]],"id":62262930},{"spn":7.06,"spf":"NaN","id":62262930},{"atb":[[3.85,0],[3.35,0]],"id":69577417},{"atb":[[7.8,0],[5.9,0]],"id":69421986},{"atb":[[1.71,0],[1.61,0]],"id":65460404},{"atl":[[6.6,0]],"id":65460404},{"spn":4.07,"spf":"NaN","id":65460404},{"atb":[[4.5,0],[3.75,0]],"id":64546979},{"atb":[[1.71,0],[1.61,0]],"id":70003371},{"atl":[[6.6,0]],"id":70003371}],"con":true,"img":false}]}
{"op":"mcm","clk":"11450486094","pt":1717322591900,"mc":[{"id":"1.229554921","rc":[{"atb":[[1.54,0]],"id":52671121},{"atb":[[2.08,0]],"id":62262930},{"atb":[[1.72,0]],"id":65460404},{"atb":[[1.62,0]],"id":70003371}],"con":true,"img":false}]}
{"op":"mcm","clk":"11450486108","pt":1717322592003,"mc":[{"id":"1.229554921","rc":[{"atb":[[1.37,49.65]],"id":52671121},{"atb":[[1.78,33.29]],"id":62262930},{"atb":[[1.55,45.77]],"id":65460404},{"atb":[[1.59,48.02]],"id":70003371}],"con":true,"img":false}]}
{"op":"mcm","clk":"11450486952","pt":1717322601544,"mc":[{"id":"1.229554921","rc":[{"atb":[[1.56,48.49],[1.46,75.74]],"id":52671121},{"atl":[[5.1,0.12]],"id":52671121},{"atb":[[2,23.22],[1.9,38.71]],"id":62262930},{"atl":[[8.6,0.06]],"id":62262930},{"atb":[[3.2,15.83],[3.7,8.6]],"id":69577417},{"atb":[[5.6,7.57],[7.2,3.74]],"id":69421986},{"atb":[[1.72,32.26],[1.62,56.19]],"id":65460404},{"atl":[[6.8,0.08]],"id":65460404},{"atb":[[3.7,12.9],[4.4,6.83]],"id":64546979},{"atb":[[1.73,31.81],[1.63,62.07]],"id":70003371},{"atl":[[6.8,0.08]],"id":70003371}],"con":true,"img":false}]}
{"op":"mcm","clk":"11450487231","pt":1717322604417,"mc":[{"id":"1.229554921","rc":[{"atb":[[2.12,0]],"id":62262930}],"con":true,"img":false}]}
{"op":"mcm","clk":"11450487244","pt":1717322604626,"mc":[{"id":"1.229554921","rc":[{"atb":[[1.56,41.48]],"id":52671121}],"con":true,"img":false}]}
{"op":"mcm","clk":"11450487258","pt":1717322604831,"mc":[{"id":"1.229554921","rc":[{"atb":[[1.74,0]],"id":70003371}],"con":true,"img":false}]}
{"op":"mcm","clk":"11450487288","pt":1717322605248,"mc":[{"id":"1.229554921","rc":[{"atb":[[1.58,6.76]],"id":52671121}],"con":true,"img":false}]}
{"op":"mcm","clk":"11450487304","pt":1717322605409,"mc":[{"id":"1.229554921","rc":[{"atb":[[1.76,5.16]],"id":70003371}],"con":true,"img":false}]}
{"op":"mcm","clk":"11450488677","pt":1717322620187,"mc":[{"id":"1.229554921","rc":[{"atb":[[1.45,0]],"id":52671121},{"atb":[[1.63,0]],"id":65460404}],"con":true,"img":false}]}
{"op":"mcm","clk":"11450489258","pt":1717322625759,"mc":[{"id":"1.229554921","rc":[{"atb":[[1.94,4.17]],"id":62262930}],"con":true,"img":false}]}
{"op":"mcm","clk":"11450489747","pt":1717322631974,"mc":[{"id":"1.229554921","rc":[{"atb":[[1.37,0]],"id":52671121},{"atb":[[1.78,0]],"id":62262930},{"atb":[[1.55,0]],"id":65460404},{"atb":[[1.59,0]],"id":70003371}],"con":true,"img":false}]}
{"op":"mcm","clk":"11450489754","pt":1717322632061,"mc":[{"id":"1.229554921","rc":[{"atb":[[1.47,49.65]],"id":52671121},{"atb":[[2.02,33.29]],"id":62262930},{"atb":[[1.63,45.77]],"id":65460404},{"atb":[[1.64,48.02]],"id":70003371}],"con":true,"img":false}]}
{"op":"mcm","clk":"11450490108","pt":1717322636445,"mc":[{"id":"1.229554921","rc":[{"atl":[[6.4,2]],"id":65460404}],"con":true,"img":false}]}
{"op":"mcm","clk":"11450490116","pt":1717322636549,"mc":[{"id":"1.229554921","rc":[{"atl":[[8,5.81]],"id":65460404}],"con":true,"img":false}]}
{"op":"mcm","clk":"11450490124","pt":1717322636654,"mc":[{"id":"1.229554921","rc":[{"atl":[[6.4,2.18]],"id":65460404}],"con":true,"img":false}]}
{"op":"mcm","clk":"11450490592","pt":1717322642405,"mc":[{"id":"1.229554921","rc":[{"atb":[[1.59,2.13]],"id":52671121},{"atb":[[2.08,2.13]],"id":62262930},{"atb":[[1.75,7.36]],"id":65460404},{"atb":[[1.76,7.29]],"id":70003371}],"con":true,"img":false}]}
{"op":"mcm","clk":"11450490604","pt":1717322642501,"mc":[{"id":"1.229554921","rc":[{"atl":[[6.4,4.36]],"id":65460404}],"con":true,"img":false}]}
{"op":"mcm","clk":"11450490623","pt":1717322642614,"mc":[{"id":"1.229554921","rc":[{"atl":[[8,0]],"id":65460404}],"con":true,"img":false}]}
{"op":"mcm","clk":"11450491043","pt":1717322646291,"mc":[{"id":"1.229554921","rc":[{"spn":3.34,"spf":"NaN","id":52671121},{"atb":[[1.94,0]],"id":62262930},{"spn":5.34,"spf":"NaN","id":62262930},{"spn":1.76,"spf":1.0,"id":70003371}],"con":true,"img":false}]}
{"op":"mcm","clk":"11450491065","pt":1717322646497,"mc":[{"id":"1.229554921","rc":[{"atb":[[2.06,3.7]],"id":62262930}],"con":true,"img":false}]}
{"op":"mcm","clk":"11450492143","pt":1717322659277,"mc":[{"id":"1.229554921","rc":[{"atb":[[1.64,6.65]],"id":65460404},{"atb":[[1.63,55.3]],"id":70003371}],"con":true,"img":false}]}
{"op":"mcm","clk":"11450492166","pt":1717322659587,"mc":[{"id":"1.229554921","rc":[{"atb":[[1.48,8.87]],"id":52671121}],"con":true,"img":false}]}
{"op":"mcm","clk":"11450492639","pt":1717322665330,"mc":[{"id":"1.229554921","rc":[{"atb":[[1.82,54.03],[1.77,0]],"id":62262930},{"atb":[[1.46,140.61],[1.54,0]],"id":65460404},{"atb":[[1.73,53.96],[2.38,0]],"id":64546979},{"atb":[[1.63,151.36],[1.58,0]],"id":70003371}],"con":true,"img":false}]}
{"op":"mcm","clk":"11450492651","pt":1717322665384,"mc":[{"id":"1.229554921","rc":[{"atb":[[2.2,53.96]],"id":64546979}],"con":true,"img":false}]}
{"op":"mcm","clk":"11450492662","pt":1717322665491,"mc":[{"id":"1.229554921","rc":[{"atb":[[1.73,0]],"id":64546979}],"con":true,"img":false}]}
{"op":"mcm","clk":"11450493641","pt":1717322676534,"mc":[{"id":"1.229554921","rc":[{"atb":[[3.2,0],[3.7,0]],"id":69577417}],"con":true,"img":false}]}
{"op":"mcm","clk":"11450493821","pt":1717322678530,"mc":[{"id":"1.229554921","rc":[{"atb":[[2.2,0],[1.94,53.96]],"id":64546979}],"con":true,"img":false}]}
{"op":"mcm","clk":"11450493835","pt":1717322678632,"mc":[{"id":"1.229554921","rc":[{"atb":[[2.32,53.96]],"id":64546979}],"con":true,"img":false}]}
{"op":"mcm","clk":"11450493845","pt":1717322678740,"mc":[{"id":"1.229554921","rc":[{"atb":[[1.94,0]],"id":64546979}],"con":true,"img":false}]}
{"op":"mcm","clk":"11450494713","pt":1717322688875,"mc":[{"id":"1.229554921","rc":[{"atb":[[3.25,15.48],[3.75,8.44]],"id":69577417}],"con":true,"img":false}]}
{"op":"mcm","clk":"11450494948","pt":1717322691670,"mc":[{"id":"1.229554921","rc":[{"atb":[[1.8,0]],"id":62262930},{"atb":[[1.66,6.45]],"id":70003371}],"con":true,"img":false}]}
{"op":"mcm","clk":"11450496575","pt":1717322710119,"mc":[{"id":"1.229554921","rc":[{"atb":[[1.56,0],[1.46,0]],"id":52671121},{"atl":[[5.1,0]],"id":52671121},{"spn":4.49,"spf":"NaN","id":52671121},{"atb":[[3.25,0],[3.75,0]],"id":69577417},{"atb":[[1.72,0],[1.62,0]],"id":65460404},{"atl":[[6.8,0]],"id":65460404},{"atb":[[3.7,0],[4.4,0]],"id":64546979}],"con":true,"img":false}]}
{"op":"mcm","clk":"11450496723","pt":1717322711802,"mc":[{"id":"1.229554921","rc":[{"atb":[[1.59,0],[1.51,2.13]],"id":52671121},{"atb":[[1.67,2.13],[1.75,5.23]],"id":65460404}],"con":true,"img":false}]}
{"op":"mcm","clk":"11450496829","pt":1717322713105,"mc":[{"id":"1.229554921","rc":[{"atb":[[4,3.4]],"id":69577417}],"con":true,"img":false}]}
{"op":"mcm","clk":"11450497334","pt":1717322718131,"mc":[{"id":"1.229554921","rc":[{"atb":[[1.56,41.48],[1.46,75.74]],"id":52671121},{"atl":[[5.1,0.12]],"id":52671121},{"atb":[[3.4,14.51],[3.9,8]],"id":69577417},{"atb":[[1.57,61.12],[1.67,36.8]],"id":65460404},{"atl":[[6.4,4.45]],"id":65460404},{"atb":[[3.85,12.22],[4.7,6.27]],"id":64546979}],"con":true,"img":false}]}
{"op":"mcm","clk":"11450497695","pt":1717322721920,"mc":[{"id":"1.229554921","rc":[{"atb":[[1.47,0]],"id":52671121},{"atb":[[1.63,0]],"id":65460404}],"con":true,"img":false}]}
{"op":"mcm","clk":"11450497706","pt":1717322722024,"mc":[{"id":"1.229554921","rc":[{"atb":[[1.37,49.65]],"id":52671121},{"atb":[[1.47,45.77]],"id":65460404}],"con":true,"img":false}]}
{"op":"mcm","clk":"11450498504","pt":1717322729626,"mc":[{"id":"1.229554921","rc":[{"atb":[[1.64,0]],"id":65460404}],"con":true,"img":false}]}
{"op":"mcm","clk":"11450498523","pt":1717322729836,"mc":[{"id":"1.229554921","rc":[{"atb":[[1.85,5.01]],"id":62262930}],"con":true,"img":false}]}
{"op":"mcm","clk":"11450499538","pt":1717322740461,"mc":[{"id":"1.229554921","rc":[{"atb":[[1.56,0],[1.46,0]],"id":52671121},{"atl":[[5.1,0]],"id":52671121},{"atb":[[5.6,0],[7.2,0]],"id":69421986},{"atb":[[1.57,0],[1.67,2.13]],"id":65460404},{"atl":[[6.4,4.36]],"id":65460404}],"con":true,"img":false}]}
{"op":"mcm","clk":"11450499902","pt":1717322744284,"mc":[{"id":"1.229554921","rc":[{"atb":[[1.67,0],[1.5,2.13]],"id":65460404}],"con":true,"img":false}]}
{"op":"mcm","clk":"11450499949","pt":1717322744652,"mc":[{"id":"1.229554921","rc":[{"atb":[[1.39,186.84]],"id":65460404}],"con":true,"img":false}]}
{"op":"mcm","clk":"11450500224","pt":1717322747685,"mc":[{"id":"1.229554921","rc":[{"atb":[[1.39,176.31]],"id":65460404}],"con":true,"img":false}]}
{"op":"mcm","clk":"11450500402","pt":1717322749776,"mc":[{"id":"1.229554921","rc":[{"atb":[[1.44,79.18],[1.54,43.01]],"id":52671121},{"atl":[[4.9,0.13]],"id":52671121},{"atb":[[6.8,4],[5.4,7.92]],"id":69421986},{"atb":[[1.58,60.07],[1.68,34.15]],"id":65460404},{"atl":[[6.4,4.45]],"id":65460404}],"con":true,"img":false}]}
{"op":"mcm","clk":"11450500592","pt":1717322751866,"mc":[{"id":"1.229554921","rc":[{"atb":[[3.95,19.28],[3.65,0]],"id":69577417}],"con":true,"img":false}]}
{"op":"mcm","clk":"11450501011","pt":1717322756455,"mc":[{"id":"1.229554921","rc":[{"atb":[[1.57,2.13],[1.51,0]],"id":52671121}],"con":true,"img":false}]}
{"op":"mcm","clk":"11450502384","pt":1717322770488,"mc":[{"id":"1.229554921","rc":[{"atb":[[1.48,0]],"id":52671121},{"spn":3.24,"spf":"NaN","id":52671121}],"con":true,"img":false}]}
{"op":"mcm","clk":"11450502419","pt":1717322770794,"mc":[{"id":"1.229554921","rc":[{"atb":[[3.25,1.89]],"id":69577417}],"con":true,"img":false}]}
{"op":"mcm","clk":"11450502435","pt":1717322771003,"mc":[{"id":"1.229554921","rc":[{"atb":[[1.6,7.09]],"id":65460404}],"con":true,"img":false}]}
{"op":"mcm","clk":"11450502695","pt":1717322773799,"mc":[{"id":"1.229554921","rc":[{"atb":[[1.58,0]],"id":52671121},{"atb":[[1.75,0]],"id":65460404}],"con":true,"img":false}]}
{"op":"mcm","clk":"11450502957","pt":1717322776302,"mc":[{"id":"1.229554921","rc":[{"atb":[[1.31,183.71]],"id":52671121}],"con":true,"img":false}]}
{"op":"mcm","clk":"11450503477","pt":1717322781905,"mc":[{"id":"1.229554921","rc":[{"atb":[[1.37,0]],"id":52671121},{"atb":[[1.47,0]],"id":65460404}],"con":true,"img":false}]}
{"op":"mcm","clk":"11450503486","pt":1717322782006,"mc":[{"id":"1.229554921","rc":[{"atb":[[1.45,49.65]],"id":52671121},{"atb":[[1.59,45.77]],"id":65460404}],"con":true,"img":false}]}
{"op":"mcm","clk":"11450504433","pt":1717322792140,"mc":[{"id":"1.229554921","rc":[{"atb":[[1.31,170.55]],"id":52671121}],"con":true,"img":false}]}
{"op":"mcm","clk":"11450504524","pt":1717322793078,"mc":[{"id":"1.229554921","rc":[{"atb":[[1.64,58.29]],"id":70003371}],"con":true,"img":false}]}
{"op":"mcm","clk":"11450504677","pt":1717322794736,"mc":[{"id":"1.229554921","rc":[{"atb":[[1.56,7.01]],"id":52671121},{"atb":[[1.71,5.52]],"id":65460404}],"con":true,"img":false}]}
{"op":"mcm","clk":"11450505038","pt":1717322798450,"mc":[{"id":"1.229554921","rc":[{"atl":[[80,0]],"id":64546979}],"con":true,"img":false}]}
{"op":"mcm","clk":"11450505048","pt":1717322798551,"mc":[{"id":"1.229554921","rc":[{"atb":[[2.32,0],[2.1,53.96]],"id":64546979},{"atl":[[85,2.61]],"id":64546979},{"atb":[[1.63,55.3],[1.53,140.22]],"id":70003371}],"con":true,"img":false}]}
{"op":"mcm","clk":"11450505210","pt":1717322800434,"mc":[{"id":"1.229554921","rc":[{"atb":[[1.57,10.53]],"id":65460404}],"con":true,"img":false}]}
{"op":"mcm","clk":"11450505230","pt":1717322800744,"mc":[{"id":"1.229554921","rc":[{"atb":[[1.46,9.26]],"id":52671121}],"con":true,"img":false}]}
{"op":"mcm","clk":"11450506278","pt":1717322812174,"mc":[{"id":"1.229554921","rc":[{"atb":[[1.57,8.29]],"id":65460404}],"con":true,"img":false}]}
{"op":"mcm","clk":"11450507101","pt":1717322821850,"mc":[{"id":"1.229554921","rc":[{"atb":[[5.2,0]],"id":64546979}],"con":true,"img":false}]}
{"op":"mcm","clk":"11450507109","pt":1717322821991,"mc":[{"id":"1.229554921","rc":[{"atb":[[5.5,11.31]],"id":64546979}],"con":true,"img":false}]}
{"op":"mcm","clk":"11450507884","pt":1717322830581,"mc":[{"id":"1.229554921","rc":[{"atb":[[1.48,8.59]],"id":52671121},{"spn":3.23,"spf":"NaN","id":52671121},{"spn":4.05,"spf":"NaN","id":65460404},{"spn":37.75,"spf":"NaN","id":64546979}],"con":true,"img":false}]}
{"op":"mcm","clk":"11450509016","pt":1717322841894,"mc":[{"id":"1.229554921","rc":[{"atb":[[1.45,0]],"id":52671121},{"atb":[[4.9,13.64]],"id":64546979}],"con":true,"img":false}]}
{"op":"mcm","clk":"11450509027","pt":1717322841995,"mc":[{"id":"1.229554921","rc":[{"atb":[[1.47,49.65]],"id":52671121},{"atb":[[4.6,0]],"id":64546979}],"con":true,"img":false}]}
{"op":"mcm","clk":"11450509970","pt":1717322852477,"mc":[{"id":"1.229554921","rc":[{"atb":[[1.57,10.53]],"id":65460404}],"con":true,"img":false}]}
{"op":"mcm","clk":"11450513512","pt":1717322886787,"mc":[{"id":"1.229554921","rc":[{"atb":[[1.48,0]],"id":52671121}],"con":true,"img":false}]}
{"op":"mcm","clk":"11450513616","pt":1717322887889,"mc":[{"id":"1.229554921","rc":[{"atb":[[1.47,58.24]],"id":52671121}],"con":true,"img":false}]}
{"op":"mcm","clk":"11450515129","pt":1717322902033,"mc":[{"id":"1.229554921","rc":[{"atb":[[1.47,49.65]],"id":52671121},{"atb":[[1.57,0]],"id":65460404}],"con":true,"img":false}]}
{"op":"mcm","clk":"11450516239","pt":1717322911848,"mc":[{"id":"1.229554921","rc":[{"atb":[[1.47,0]],"id":52671121}],"con":true,"img":false}]}
{"op":"mcm","clk":"11450516249","pt":1717322911952,"mc":[{"id":"1.229554921","rc":[{"atb":[[1.45,49.65]],"id":52671121}],"con":true,"img":false}]}
{"op":"mcm","clk":"11450518041","pt":1717322928278,"mc":[{"id":"1.229554921","rc":[{"atb":[[1.44,0],[1.54,0]],"id":52671121},{"atl":[[4.9,0]],"id":52671121},{"atb":[[2,0],[1.9,0]],"id":62262930},{"atl":[[8.6,0]],"id":62262930},{"atb":[[3.4,0],[3.9,0]],"id":69577417},{"atb":[[6.8,0],[5.4,0]],"id":69421986},{"atb":[[1.58,0],[1.68,0]],"id":65460404},{"atl":[[6.4,4.36]],"id":65460404},{"atb":[[3.85,0],[4.7,0]],"id":64546979},{"atb":[[1.73,0],[1.63,0]],"id":70003371},{"atl":[[6.8,0]],"id":70003371}],"con":true,"img":false}]}
{"op":"mcm","clk":"11450518313","pt":1717322931280,"mc":[{"id":"1.229554921","rc":[{"atb":[[1.57,0],[1.49,2.13]],"id":52671121},{"atb":[[1.63,2.13],[1.5,0]],"id":65460404},{"atb":[[1.76,5.16],[1.69,2.13]],"id":70003371}],"con":true,"img":false}]}
{"op":"mcm","clk":"11450518383","pt":1717322931873,"mc":[{"id":"1.229554921","rc":[{"atb":[[1.45,0]],"id":52671121},{"atb":[[2.02,0]],"id":62262930},{"atb":[[1.59,0]],"id":65460404}],"con":true,"img":false}]}
{"op":"mcm","clk":"11450518394","pt":1717322931972,"mc":[{"id":"1.229554921","rc":[{"atb":[[1.37,49.65]],"id":52671121},{"atb":[[1.83,33.29]],"id":62262930},{"atb":[[1.47,45.77]],"id":65460404},{"atb":[[1.64,48.02]],"id":70003371}],"con":true,"img":false}]}
{"op":"mcm","clk":"11450518501","pt":1717322933074,"mc":[{"id":"1.229554921","rc":[{"atb":[[1.64,9.19]],"id":62262930}],"con":true,"img":false}]}
{"op":"mcm","clk":"11450518595","pt":1717322933964,"mc":[{"id":"1.229554921","rc":[{"atb":[[1.64,0]],"id":62262930}],"con":true,"img":false}]}
{"op":"mcm","clk":"11450518853","pt":1717322936567,"mc":[{"id":"1.229554921","rc":[{"atb":[[1.31,185.29]],"id":52671121}],"con":true,"img":false}]}
{"op":"mcm","clk":"11450518863","pt":1717322936675,"mc":[{"id":"1.229554921","rc":[{"atb":[[2.06,0]],"id":62262930},{"atb":[[1.76,0]],"id":70003371}],"con":true,"img":false}]}
{"op":"mcm","clk":"11450519179","pt":1717322939753,"mc":[{"id":"1.229554921","rc":[{"atb":[[1.4,10.27]],"id":70003371}],"con":true,"img":false}]}
{"op":"mcm","clk":"11450519304","pt":1717322940865,"mc":[{"id":"1.229554921","rc":[{"atb":[[1.4,0]],"id":70003371}],"con":true,"img":false}]}
{"op":"mcm","clk":"11450519440","pt":1717322941891,"mc":[{"id":"1.229554921","rc":[{"atb":[[1.64,0]],"id":70003371}],"con":true,"img":false}]}
{"op":"mcm","clk":"11450519451","pt":1717322941970,"mc":[{"id":"1.229554921","rc":[{"atb":[[1.54,48.02]],"id":70003371}],"con":true,"img":false}]}
{"op":"mcm","clk":"11450519515","pt":1717322942603,"mc":[{"id":"1.229554921","rc":[{"atb":[[1.41,84.98],[1.51,45.54]],"id":52671121},{"atl":[[4.6,0.14]],"id":52671121},{"atb":[[2.12,20.73],[1.96,36.29]],"id":62262930},{"atl":[[9.4,0.06]],"id":62262930},{"atb":[[3.6,13.4],[4.2,22.2]],"id":69577417},{"atb":[[5.6,7.57],[7.2,3.74]],"id":69421986},{"atb":[[1.59,59.05],[1.69,33.66]],"id":65460404},{"atl":[[6.6,0.09]],"id":65460404},{"atb":[[3.85,12.22],[4.7,6.27]],"id":64546979},{"atb":[[1.59,59.05],[1.69,35.79]],"id":70003371},{"atl":[[6.6,0.09]],"id":70003371}],"con":true,"img":false}]}
{"op":"mcm","clk":"11450519521","pt":1717322942702,"mc":[{"id":"1.229554921","rc":[{"atb":[[1.31,170.55]],"id":52671121}],"con":true,"img":false}]}
{"op":"mcm","clk":"11450519589","pt":1717322943294,"mc":[{"id":"1.229554921","rc":[{"atb":[[1.54,2.13],[1.49,0]],"id":52671121}],"con":true,"img":false}]}
{"op":"mcm","clk":"11450519661","pt":1717322943882,"mc":[{"id":"1.229554921","rc":[{"atb":[[4,0]],"id":69577417}],"con":true,"img":false}]}
{"op":"mcm","clk":"11450519791","pt":1717322945082,"mc":[{"id":"1.229554921","rc":[{"atb":[[4,3.39]],"id":69577417}],"con":true,"img":false}]}
{"op":"mcm","clk":"11450520320","pt":1717322950096,"mc":[{"id":"1.229554921","rc":[{"atb":[[1.38,10.53]],"id":65460404}],"con":true,"img":false}]}
{"op":"mcm","clk":"11450520455","pt":1717322951401,"mc":[{"id":"1.229554921","rc":[{"atb":[[1.46,0]],"id":52671121},{"atb":[[3.25,0]],"id":69577417},{"atb":[[1.6,0]],"id":65460404},{"atb":[[1.66,0]],"id":70003371}],"con":true,"img":false}]}
{"op":"mcm","clk":"11450521617","pt":1717322962795,"mc":[{"id":"1.229554921","rc":[{"spn":3.08,"spf":"NaN","id":52671121},{"atb":[[2,3.92]],"id":62262930},{"spn":5.76,"spf":"NaN","id":62262930},{"atb":[[1.72,5.44]],"id":70003371},{"spn":1.72,"spf":1.0,"id":70003371}],"con":true,"img":false}]}
{"op":"mcm","clk":"11450521626","pt":1717322962831,"mc":[{"id":"1.229554921","rc":[{"atb":[[1.71,0]],"id":65460404}],"con":true,"img":false}]}
{"op":"mcm","clk":"11450521745","pt":1717322964007,"mc":[{"id":"1.229554921","rc":[{"atb":[[1.72,5.44]],"id":65460404}],"con":true,"img":false}]}
{"op":"mcm","clk":"11450523038","pt":1717322978573,"mc":[{"id":"1.229554921","rc":[{"atb":[[1.38,0]],"id":65460404}],"con":true,"img":false}]}
{"op":"mcm","clk":"11450523110","pt":1717322979358,"mc":[{"id":"1.229554921","rc":[{"atb":[[1.64,9.1]],"id":62262930}],"con":true,"img":false}]}
{"op":"mcm","clk":"11450523122","pt":1717322979515,"mc":[{"id":"1.229554921","rc":[{"atb":[[1.64,0]],"id":62262930}],"con":true,"img":false}]}
{"op":"mcm","clk":"11450523364","pt":1717322981878,"mc":[{"id":"1.229554921","rc":[{"atb":[[1.37,0]],"id":52671121},{"atb":[[1.83,0]],"id":62262930},{"atb":[[1.47,0]],"id":65460404},{"atb":[[1.54,0]],"id":70003371}],"con":true,"img":false}]}
{"op":"mcm","clk":"11450523374","pt":1717322981976,"mc":[{"id":"1.229554921","rc":[{"atb":[[1.52,49.65]],"id":52671121},{"atb":[[1.97,33.29]],"id":62262930},{"atb":[[1.6,45.77]],"id":65460404},{"atb":[[1.7,48.02]],"id":70003371}],"con":true,"img":false}]}
{"op":"mcm","clk":"11450523415","pt":1717322982392,"mc":[{"id":"1.229554921","rc":[{"atb":[[1.61,6.98]],"id":65460404}],"con":true,"img":false}]}
{"op":"mcm","clk":"11450523452","pt":1717322982809,"mc":[{"id":"1.229554921","rc":[{"atb":[[1.31,185.29]],"id":52671121},{"atb":[[1.61,6.98]],"id":70003371}],"con":true,"img":false}]}
{"op":"mcm","clk":"11450523478","pt":1717322982968,"mc":[{"id":"1.229554921","rc":[{"atb":[[1.43,9.91]],"id":52671121}],"con":true,"img":false}]}
{"op":"mcm","clk":"11450523578","pt":1717322983919,"mc":[{"id":"1.229554921","rc":[{"atb":[[1.73,2.13],[1.69,33.66]],"id":70003371}],"con":true,"img":false}]}
{"op":"mcm","clk":"11450524344","pt":1717322991998,"mc":[{"id":"1.229554921","rc":[{"atb":[[1.31,170.55]],"id":52671121},{"atb":[[3.95,0]],"id":69577417}],"con":true,"img":false}]}
{"op":"mcm","clk":"11450524353","pt":1717322992100,"mc":[{"id":"1.229554921","rc":[{"atb":[[4.1,19.28]],"id":69577417}],"con":true,"img":false}]}
{"op":"mcm","clk":"11450524371","pt":1717322992310,"mc":[{"id":"1.229554921","rc":[{"atb":[[4,0]],"id":69577417}],"con":true,"img":false}]}
{"op":"mcm","clk":"11450524434","pt":1717322992987,"mc":[{"id":"1.229554921","rc":[{"atb":[[1.65,10.27]],"id":70003371}],"con":true,"img":false}]}
{"op":"mcm","clk":"11450524483","pt":1717322993403,"mc":[{"id":"1.229554921","rc":[{"atb":[[4,3.39]],"id":69577417}],"con":true,"img":false}]}
{"op":"mcm","clk":"11450524673","pt":1717322995594,"mc":[{"id":"1.229554921","rc":[{"atb":[[1.6,56.43]],"id":65460404}],"con":true,"img":false}]}
{"op":"mcm","clk":"11450525159","pt":1717323001228,"mc":[{"id":"1.229554921","rc":[{"atb":[[1.72,0]],"id":70003371}],"con":true,"img":false}]}
{"op":"mcm","clk":"11450525205","pt":1717323001706,"mc":[{"id":"1.229554921","rc":[{"atb":[[1.73,7.5]],"id":70003371}],"con":true,"img":false}]}
{"op":"mcm","clk":"11450525706","pt":1717323006817,"mc":[{"id":"1.229554921","rc":[{"atb":[[1.6,45.77]],"id":65460404},{"atb":[[1.65,0]],"id":70003371}],"con":true,"img":false}]}
{"op":"mcm","clk":"11450525827","pt":1717323007916,"mc":[{"id":"1.229554921","rc":[{"atb":[[1.56,0]],"id":52671121}],"con":true,"img":false}]}
{"op":"mcm","clk":"11450526958","pt":1717323019449,"mc":[{"id":"1.229554921","rc":[{"atb":[[1.61,0]],"id":70003371}],"con":true,"img":false}]}
{"op":"mcm","clk":"11450527386","pt":1717323023468,"mc":[{"id":"1.229554921","rc":[{"spn":3.07,"spf":"NaN","id":52671121},{"atb":[[1.52,9]],"id":62262930},{"spn":4.06,"spf":"NaN","id":65460404},{"spn":1.73,"spf":1.0,"id":70003371}],"con":true,"img":false}]}
{"op":"mcm","clk":"11450527405","pt":1717323023634,"mc":[{"id":"1.229554921","rc":[{"atb":[[1.52,0]],"id":62262930}],"con":true,"img":false}]}
{"op":"mcm","clk":"11450527456","pt":1717323024148,"mc":[{"id":"1.229554921","rc":[{"atb":[[1.54,9.39]],"id":52671121}],"con":true,"img":false}]}
{"op":"mcm","clk":"11450527722","pt":1717323026651,"mc":[{"id":"1.229554921","rc":[{"atb":[[1.34,14.74]],"id":52671121}],"con":true,"img":false}]}
{"op":"mcm","clk":"11450528244","pt":1717323032074,"mc":[{"id":"1.229554921","rc":[{"atb":[[1.34,0]],"id":52671121}],"con":true,"img":false}]}
{"op":"mcm","clk":"11450528709","pt":1717323036358,"mc":[{"id":"1.229554921","rc":[{"atb":[[1.66,10.27]],"id":70003371}],"con":true,"img":false}]}
{"op":"mcm","clk":"11450528946","pt":1717323038916,"mc":[{"id":"1.229554921","rc":[{"atb":[[1.61,17.64]],"id":65460404}],"con":true,"img":false}]}
{"op":"mcm","clk":"11450529747","pt":1717323046790,"mc":[{"id":"1.229554921","rc":[{"atb":[[1.41,0],[1.51,0]],"id":52671121},{"atl":[[4.6,0]],"id":52671121},{"atb":[[2.12,0],[1.96,0]],"id":62262930},{"atl":[[9.4,0]],"id":62262930},{"atb":[[3.6,0],[4.2,14.94]],"id":69577417},{"atb":[[5.6,0],[7.2,0]],"id":69421986},{"atb":[[1.59,0],[1.69,0]],"id":65460404},{"atl":[[6.6,0]],"id":65460404},{"atb":[[3.85,0],[4.7,0]],"id":64546979},{"atb":[[1.59,0],[1.69,0]],"id":70003371},{"atl":[[6.6,0]],"id":70003371}],"con":true,"img":false}]}
{"op":"mcm","clk":"11450529814","pt":1717323047371,"mc":[{"id":"1.229554921","rc":[{"atb":[[4,4.98]],"id":69577417}],"con":true,"img":false}]}
{"op":"mcm","clk":"11450529826","pt":1717323047478,"mc":[{"id":"1.229554921","rc":[{"atb":[[4,3.59]],"id":69577417}],"con":true,"img":false}]}
{"op":"mcm","clk":"11450530262","pt":1717323051973,"mc":[{"id":"1.229554921","rc":[{"atb":[[1.52,0]],"id":52671121},{"atb":[[1.97,0]],"id":62262930},{"atb":[[1.6,0]],"id":65460404},{"atb":[[1.7,0]],"id":70003371}],"con":true,"img":false}]}
{"op":"mcm","clk":"11450530275","pt":1717323052075,"mc":[{"id":"1.229554921","rc":[{"atb":[[1.37,49.65]],"id":52671121},{"atb":[[1.83,33.29]],"id":62262930},{"atb":[[1.62,45.77],[1.61,6.98]],"id":65460404},{"atb":[[1.67,48.02],[1.66,0]],"id":70003371}],"con":true,"img":false}]}
{"op":"mcm","clk":"11450530347","pt":1717323052899,"mc":[{"id":"1.229554921","rc":[{"atb":[[1.46,2.13],[1.54,7.26]],"id":52671121},{"atb":[[1.88,2.13],[2.08,0]],"id":62262930}],"con":true,"img":false}]}
{"op":"mcm","clk":"11450530423","pt":1717323053493,"mc":[{"id":"1.229554921","rc":[{"atb":[[1.49,47.4],[1.39,89.34]],"id":52671121},{"atl":[[4.4,0.15]],"id":52671121},{"atb":[[1.95,36.67],[2.1,21.11]],"id":62262930},{"atl":[[9.2,0.06]],"id":62262930},{"atb":[[4.1,26.77],[3.55,13.66]],"id":69577417},{"atb":[[6.8,4],[5.4,7.92]],"id":69421986},{"atb":[[1.58,60.07],[1.68,34.15]],"id":65460404},{"atl":[[6.4,4.45]],"id":65460404},{"atb":[[4,11.61],[5,5.8]],"id":64546979},{"atb":[[1.72,32.26],[1.62,56.19]],"id":70003371},{"atl":[[6.8,0.08]],"id":70003371}],"con":true,"img":false}]}
{"op":"mcm","clk":"11450531184","pt":1717323061680,"mc":[{"id":"1.229554921","rc":[{"atb":[[1.43,0]],"id":52671121},{"atb":[[1.61,0]],"id":65460404}],"con":true,"img":false}]}
{"op":"mcm","clk":"11450531275","pt":1717323062577,"mc":[{"id":"1.229554921","rc":[{"atb":[[1.64,6.65]],"id":70003371}],"con":true,"img":false}]}
{"op":"mcm","clk":"11450531541","pt":1717323065101,"mc":[{"id":"1.229554921","rc":[{"atb":[[1.63,0],[1.71,2.13]],"id":65460404}],"con":true,"img":false}]}
{"op":"mcm","clk":"11450531562","pt":1717323065311,"mc":[{"id":"1.229554921","rc":[{"atb":[[1.64,9.46]],"id":62262930}],"con":true,"img":false}]}
{"op":"mcm","clk":"11450531683","pt":1717323066413,"mc":[{"id":"1.229554921","rc":[{"atb":[[1.73,2.13]],"id":70003371}],"con":true,"img":false}]}
{"op":"mcm","clk":"11450531698","pt":1717323066609,"mc":[{"id":"1.229554921","rc":[{"atb":[[1.75,5.22]],"id":70003371}],"con":true,"img":false}]}
{"op":"mcm","clk":"11450531882","pt":1717323068300,"mc":[{"id":"1.229554921","rc":[{"atb":[[1.31,185.29]],"id":52671121}],"con":true,"img":false}]}
{"op":"mcm","clk":"11450532248","pt":1717323071899,"mc":[{"id":"1.229554921","rc":[{"atb":[[1.62,0]],"id":65460404},{"atb":[[1.67,0]],"id":70003371}],"con":true,"img":false}]}
{"op":"mcm","clk":"11450532253","pt":1717323072002,"mc":[{"id":"1.229554921","rc":[{"atb":[[1.59,45.77]],"id":65460404},{"atb":[[1.63,48.02]],"id":70003371}],"con":true,"img":false}]}
{"op":"mcm","clk":"11450532807","pt":1717323077625,"mc":[{"id":"1.229554921","rc":[{"atb":[[1.4,10.27]],"id":70003371}],"con":true,"img":false}]}
{"op":"mcm","clk":"11450533036","pt":1717323079927,"mc":[{"id":"1.229554921","rc":[{"atb":[[1.38,10.53]],"id":65460404}],"con":true,"img":false}]}
{"op":"mcm","clk":"11450534003","pt":1717323088965,"mc":[{"id":"1.229554921","rc":[{"atb":[[1.31,170.55]],"id":52671121},{"spn":2.97,"spf":"NaN","id":52671121},{"spn":5.65,"spf":"NaN","id":62262930},{"atb":[[1.38,0]],"id":65460404},{"spn":1.75,"spf":1.0,"id":70003371}],"con":true,"img":false}]}
{"op":"mcm","clk":"11450534083","pt":1717323089799,"mc":[{"id":"1.229554921","rc":[{"atb":[[1.6,7.09]],"id":65460404}],"con":true,"img":false}]}
{"op":"mcm","clk":"11450534177","pt":1717323090535,"mc":[{"id":"1.229554921","rc":[{"atb":[[1.41,10.39]],"id":52671121}],"con":true,"img":false}]}
{"op":"mcm","clk":"11450534338","pt":1717323091992,"mc":[{"id":"1.229554921","rc":[{"atb":[[1.37,0]],"id":52671121},{"atb":[[1.83,0]],"id":62262930}],"con":true,"img":false}]}
{"op":"mcm","clk":"11450534349","pt":1717323092093,"mc":[{"id":"1.229554921","rc":[{"atb":[[1.5,49.65]],"id":52671121},{"atb":[[1.96,33.29]],"id":62262930}],"con":true,"img":false}]}
{"op":"mcm","clk":"11450534368","pt":1717323092308,"mc":[{"id":"1.229554921","rc":[{"atb":[[1.64,0]],"id":62262930}],"con":true,"img":false}]}
{"op":"mcm","clk":"11450534493","pt":1717323093517,"mc":[{"id":"1.229554921","rc":[{"atb":[[1.46,0],[1.53,2.13]],"id":52671121}],"con":true,"img":false}]}
{"op":"mcm","clk":"11450535333","pt":1717323102015,"mc":[{"id":"1.229554921","rc":[{"atb":[[1.4,0]],"id":70003371}],"con":true,"img":false}]}
{"op":"mcm","clk":"11450535661","pt":1717323105082,"mc":[{"id":"1.229554921","rc":[{"atb":[[2.02,7.08]],"id":62262930}],"con":true,"img":false}]}
{"op":"mcm","clk":"11450535681","pt":1717323105291,"mc":[{"id":"1.229554921","rc":[{"atb":[[2.02,0]],"id":62262930}],"con":true,"img":false}]}
{"op":"mcm","clk":"11450535890","pt":1717323107893,"mc":[{"id":"1.229554921","rc":[{"atb":[[1.31,185.29]],"id":52671121}],"con":true,"img":false}]}
{"op":"mcm","clk":"11450536820","pt":1717323116712,"mc":[{"id":"1.229554921","rc":[{"atb":[[1.66,10.27]],"id":70003371}],"con":true,"img":false}]}
{"op":"mcm","clk":"11450537023","pt":1717323118950,"mc":[{"id":"1.229554921","rc":[{"atb":[[1.61,10.53]],"id":65460404}],"con":true,"img":false}]}
{"op":"mcm","clk":"11450537815","pt":1717323126749,"mc":[{"id":"1.229554921","rc":[{"atb":[[2.3,10],[2.38,5],[2.46,2.5],[2.1,26.79]],"id":62262930},{"atl":[[4.8,2.5],[5.6,10],[11,5.68],[5.2,5]],"id":62262930}],"con":true,"img":false}]}
{"op":"mcm","clk":"11450537829","pt":1717323126857,"mc":[{"id":"1.229554921","rc":[{"atb":[[1.64,2.5],[1.6,5],[1.56,10],[1.54,16.84]],"id":52671121},{"atl":[[7.2,9.58],[3.7,10],[3.3,2.5],[3.5,5]],"id":52671121},{"atl":[[6.2,3.64],[12,0]],"id":62262930},{"atb":[[4,0],[5,2.5],[4.6,5],[4.2,31.1]],"id":69577417},{"atl":[[11.5,2.5],[50,1.63],[13.5,5],[15.5,10]],"id":69577417},{"atb":[[7.2,2.5],[6.4,5],[10,4.97],[5.8,10]],"id":69421986},{"atl":[[34,2.5],[42,5],[180,0.45]],"id":69421986},{"atb":[[1.76,5],[1.72,23.88],[1.8,2.5],[1.61,0]],"id":65460404},{"atl":[[4,10],[3.6,2.5],[6.2,8.44],[3.8,5]],"id":65460404},{"atb":[[4.5,10],[5.5,19.13],[5.3,2.5],[4.9,18.64]],"id":64546979},{"atl":[[16,5],[65,1.25],[18,10],[14,2.5]],"id":64546979},{"atb":[[1.89,10],[1.93,5],[1.97,2.5],[1.75,13.17],[1.66,0]],"id":70003371},{"atl":[[3.95,10],[3.55,2.5],[8.4,7.95],[3.75,5]],"id":70003371}],"con":true,"img":false}]}
{"op":"mcm","clk":"11450537838","pt":1717323126912,"mc":[{"id":"1.229554921","rc":[{"atb":[[1.31,170.55]],"id":52671121},{"atl":[[7.4,0],[4.4,5.66]],"id":52671121},{"atl":[[26,2.62],[60,2.61]],"id":69577417},{"atl":[[190,2.21],[210,0]],"id":69421986},{"atl":[[6.4,2.27]],"id":65460404},{"atl":[[70,2.61],[26,2.62]],"id":64546979},{"atl":[[8.6,0],[4.2,5.37]],"id":70003371}],"con":true,"img":false}]}
{"op":"mcm","clk":"11450537845","pt":1717323127018,"mc":[{"id":"1.229554921","rc":[{"atl":[[4.5,5.81]],"id":65460404}],"con":true,"img":false}]}
{"op":"mcm","clk":"11450537998","pt":1717323128630,"mc":[{"id":"1.229554921","rc":[{"atb":[[1.54,9.58]],"id":52671121},{"atb":[[2,0]],"id":62262930},{"atb":[[1.72,18.44]],"id":65460404}],"con":true,"img":false}]}
{"op":"mcm","clk":"11450538133","pt":1717323129937,"mc":[{"id":"1.229554921","rc":[{"atb":[[1.59,2.13],[1.53,0]],"id":52671121},{"atb":[[1.71,0],[1.75,2.13]],"id":65460404}],"con":true,"img":false}]}
{"op":"mcm","clk":"11450538176","pt":1717323130344,"mc":[{"id":"1.229554921","rc":[{"atl":[[4.1,10]],"id":52671121},{"atl":[[4.1,10]],"id":65460404},{"atl":[[22,4.76]],"id":64546979},{"atl":[[3.95,17.5]],"id":70003371}],"con":true,"img":false}]}
{"op":"mcm","clk":"11450538185","pt":1717323130454,"mc":[{"id":"1.229554921","rc":[{"atl":[[4.4,0.15]],"id":52671121},{"atl":[[4.5,0]],"id":65460404},{"atl":[[26,0]],"id":64546979},{"atl":[[4.2,0]],"id":70003371}],"con":true,"img":false}]}
{"op":"mcm","clk":"11450538675","pt":1717323135143,"mc":[{"id":"1.229554921","rc":[{"atl":[[5.6,17.5],[6.2,0]],"id":62262930}],"con":true,"img":false}]}
{"op":"mcm","clk":"11450539272","pt":1717323141089,"mc":[{"id":"1.229554921","rc":[{"atb":[[1.39,0],[1.49,0]],"id":52671121},{"atl":[[4.4,0]],"id":52671121},{"atb":[[1.95,0],[2.1,5.68]],"id":62262930},{"atl":[[9.2,0]],"id":62262930},{"atb":[[4.1,19.28],[3.55,0]],"id":69577417},{"atb":[[6.8,0],[5.4,0]],"id":69421986},{"atb":[[1.58,0],[1.68,0]],"id":65460404},{"atl":[[6.4,2.18]],"id":65460404},{"atb":[[4,0],[5,0]],"id":64546979},{"atb":[[1.72,0],[1.62,0]],"id":70003371},{"atl":[[6.8,0]],"id":70003371}],"con":true,"img":false}]}
{"op":"mcm","clk":"11450539363","pt":1717323141882,"mc":[{"id":"1.229554921","rc":[{"atb":[[1.5,0]],"id":52671121},{"atl":[[7.6,5.5]],"id":52671121},{"atb":[[1.96,0]],"id":62262930},{"atb":[[2.9,29.94],[4.1,0]],"id":69577417},{"atb":[[5,13.47],[8.2,0],[9.8,0]],"id":69421986},{"atb":[[1.59,0]],"id":65460404},{"atb":[[5.5,7.82],[4.9,5],[3.15,24.76]],"id":64546979},{"atb":[[1.63,0]],"id":70003371}],"con":true,"img":false}]}
{"op":"mcm","clk":"11450539378","pt":1717323141983,"mc":[{"id":"1.229554921","rc":[{"atb":[[1.41,60.05]],"id":52671121},{"atl":[[8.4,7.84]],"id":52671121},{"atb":[[1.86,33.29]],"id":62262930},{"atb":[[6.6,5.36]],"id":69421986},{"atb":[[1.52,45.77]],"id":65460404},{"atb":[[5,11.31]],"id":64546979},{"atb":[[1.54,48.02]],"id":70003371}],"con":true,"img":false}]}
{"op":"mcm","clk":"11450539392","pt":1717323142052,"mc":[{"id":"1.229554921","rc":[{"atb":[[10,0]],"id":69421986},{"atb":[[5.5,0]],"id":64546979}],"con":true,"img":false}]}
{"op":"mcm","clk":"11450539403","pt":1717323142156,"mc":[{"id":"1.229554921","rc":[{"atb":[[7.2,6.25]],"id":69421986},{"atb":[[5.3,8.12]],"id":64546979}],"con":true,"img":false}]}
{"op":"mcm","clk":"11450539644","pt":1717323144185,"mc":[{"id":"1.229554921","rc":[{"atb":[[2.46,10]],"id":62262930},{"atl":[[4.7,7.5]],"id":62262930}],"con":true,"img":false}]}
{"op":"mcm","clk":"11450539659","pt":1717323144289,"mc":[{"id":"1.229554921","rc":[{"atb":[[1.64,8.12]],"id":52671121},{"atl":[[3.1,5.62]],"id":52671121},{"atb":[[2.1,0]],"id":62262930},{"atl":[[11,0]],"id":62262930},{"atb":[[5,10]],"id":69577417},{"atl":[[11,7.5]],"id":69577417},{"atb":[[7.4,7.5]],"id":69421986},{"atl":[[32,2.58]],"id":69421986},{"atb":[[1.8,8.12]],"id":65460404},{"atl":[[3.5,5.62]],"id":65460404},{"atl":[[13.5,6.4]],"id":64546979},{"atb":[[1.98,7.5]],"id":70003371},{"atl":[[3.55,10]],"id":70003371}],"con":true,"img":false}]}
{"op":"mcm","clk":"11450539676","pt":1717323144353,"mc":[{"id":"1.229554921","rc":[{"atb":[[4.2,24.94]],"id":69577417},{"atl":[[50,0]],"id":69577417},{"atl":[[190,0.21],[95,2]],"id":69421986},{"atl":[[65,0]],"id":64546979}],"con":true,"img":false}]}
{"op":"mcm","clk":"11450539689","pt":1717323144451,"mc":[{"id":"1.229554921","rc":[{"atb":[[1.54,0]],"id":52671121},{"atl":[[7.2,0]],"id":52671121},{"atb":[[7.2,2.5]],"id":69421986},{"atl":[[180,0]],"id":69421986},{"atb":[[1.72,10]],"id":65460404},{"atl":[[6.2,0]],"id":65460404},{"atb":[[1.75,5.22]],"id":70003371},{"atl":[[8.4,0]],"id":70003371}],"con":true,"img":false}]}
{"op":"mcm","clk":"11450539883","pt":1717323146165,"mc":[{"id":"1.229554921","rc":[{"atb":[[1.59,0],[1.63,2.13]],"id":52671121},{"atb":[[1.79,2.13],[1.75,0]],"id":65460404}],"con":true,"img":false}]}
{"op":"mcm","clk":"11450540356","pt":1717323150360,"mc":[{"id":"1.229554921","rc":[{"atb":[[1.43,9.13]],"id":52671121},{"spn":2.37,"spf":"NaN","id":52671121},{"atb":[[1.89,4.41]],"id":62262930},{"spn":3.58,"spf":"NaN","id":62262930},{"spn":8.0,"spf":"NaN","id":69577417},{"spn":19.7,"spf":"NaN","id":69421986},{"atb":[[1.54,7.26]],"id":65460404},{"spn":2.65,"spf":"NaN","id":65460404},{"spn":9.4,"spf":"NaN","id":64546979},{"spn":1.98,"spf":1.0,"id":70003371}],"con":true,"img":false}]}
{"op":"mcm","clk":"11450540523","pt":1717323151978,"mc":[{"id":"1.229554921","rc":[{"atl":[[12.5,0]],"id":62262930},{"atl":[[8.8,0]],"id":70003371}],"con":true,"img":false}]}
{"op":"mcm","clk":"11450540535","pt":1717323152080,"mc":[{"id":"1.229554921","rc":[{"atl":[[10.5,3.64]],"id":62262930},{"atl":[[7.8,5.36]],"id":70003371}],"con":true,"img":false}]}
{"op":"mcm","clk":"11450540612","pt":1717323152809,"mc":[{"id":"1.229554921","rc":[{"atb":[[1.4,87.1],[1.5,46.45]],"id":52671121},{"atl":[[4.5,0.15]],"id":52671121},{"atb":[[2,23.22],[1.9,38.71]],"id":62262930},{"atl":[[8.6,0.06]],"id":62262930},{"atb":[[3.6,13.4],[4.2,32.2]],"id":69577417},{"atb":[[7.4,11.13],[5.7,7.41]],"id":69421986},{"atb":[[1.59,59.05],[1.69,33.66]],"id":65460404},{"atl":[[6.6,0.09]],"id":65460404},{"atb":[[4.8,6.11],[3.9,12.01]],"id":64546979},{"atb":[[1.62,56.19],[1.72,32.26]],"id":70003371},{"atl":[[6.8,0.08]],"id":70003371}],"con":true,"img":false}]}
{"op":"mcm","clk":"11450540995","pt":1717323155999,"mc":[{"id":"1.229554921","rc":[{"atb":[[1.45,10.53]],"id":65460404}],"con":true,"img":false}]}
{"op":"mcm","clk":"11450541126","pt":1717323157103,"mc":[{"id":"1.229554921","rc":[{"atl":[[6.4,0]],"id":65460404}],"con":true,"img":false}]}
{"op":"mcm","clk":"11450541526","pt":1717323160567,"mc":[{"id":"1.229554921","rc":[{"atb":[[1.41,49.65]],"id":52671121},{"atb":[[1.6,0]],"id":65460404},{"atb":[[1.64,0]],"id":70003371}],"con":true,"img":false}]}
{"op":"mcm","clk":"11450541667","pt":1717323161921,"mc":[{"id":"1.229554921","rc":[{"atl":[[65,2.61],[190,0]],"id":69421986}],"con":true,"img":false}]}
{"op":"mcm","clk":"11450541681","pt":1717323162027,"mc":[{"id":"1.229554921","rc":[{"atb":[[2.9,0]],"id":69577417},{"atl":[[55,0]],"id":69577417},{"atl":[[70,0]],"id":64546979}],"con":true,"img":false}]}
{"op":"mcm","clk":"11450541695","pt":1717323162092,"mc":[{"id":"1.229554921","rc":[{"atb":[[2.74,29.94]],"id":69577417},{"atl":[[25,2.61]],"id":69577417},{"atl":[[34,2.61]],"id":64546979}],"con":true,"img":false}]}
{"op":"mcm","clk":"11450542727","pt":1717323171915,"mc":[{"id":"1.229554921","rc":[{"atb":[[1.43,0]],"id":52671121},{"atb":[[1.89,0]],"id":62262930},{"atb":[[6.6,0]],"id":69421986},{"atl":[[200,0]],"id":69421986},{"atb":[[1.54,0]],"id":65460404}],"con":true,"img":false}]}
{"op":"mcm","clk":"11450542738","pt":1717323172015,"mc":[{"id":"1.229554921","rc":[{"atb":[[7.6,5.36]],"id":69421986},{"atl":[[80,2.61]],"id":69421986},{"atb":[[2.2,53.96],[2.1,0]],"id":64546979}],"con":true,"img":false}]}
{"op":"mcm","clk":"11450542750","pt":1717323172122,"mc":[{"id":"1.229554921","rc":[{"atb":[[7.8,5.68]],"id":69421986}],"con":true,"img":false}]}
{"op":"mcm","clk":"11450542759","pt":1717323172225,"mc":[{"id":"1.229554921","rc":[{"atb":[[7.4,3.63]],"id":69421986}],"con":true,"img":false}]}
{"op":"mcm","clk":"11450542883","pt":1717323173324,"mc":[{"id":"1.229554921","rc":[{"atb":[[1.52,7.55]],"id":52671121},{"atb":[[1.94,4.17]],"id":62262930}],"con":true,"img":false}]}
{"op":"mcm","clk":"11450542898","pt":1717323173390,"mc":[{"id":"1.229554921","rc":[{"atb":[[1.72,15.44]],"id":65460404}],"con":true,"img":false}]}
{"op":"mcm","clk":"11450543891","pt":1717323181868,"mc":[{"id":"1.229554921","rc":[{"atb":[[1.39,0],[1.47,127.65]],"id":65460404}],"con":true,"img":false}]}
{"op":"mcm","clk":"11450543905","pt":1717323181975,"mc":[{"id":"1.229554921","rc":[{"atb":[[1.31,0]],"id":52671121},{"atb":[[1.56,0],[1.86,0]],"id":62262930},{"atl":[[60,0]],"id":69577417},{"atl":[[85,0]],"id":64546979},{"atb":[[1.37,0]],"id":70003371}],"con":true,"img":false}]}
{"op":"mcm","clk":"11450543914","pt":1717323182030,"mc":[{"id":"1.229554921","rc":[{"atb":[[1.41,220.21]],"id":52671121},{"atb":[[2.02,33.29],[1.61,93.42]],"id":62262930},{"atl":[[34,2.61]],"id":69577417},{"atl":[[42,2.61]],"id":64546979},{"atb":[[1.43,167.41]],"id":70003371}],"con":true,"img":false}]}
{"op":"mcm","clk":"11450544932","pt":1717323190873,"mc":[{"id":"1.229554921","rc":[{"atb":[[1.94,0]],"id":62262930}],"con":true,"img":false}]}
{"op":"mcm","clk":"11450544952","pt":1717323191073,"mc":[{"id":"1.229554921","rc":[{"atb":[[2.06,3.7]],"id":62262930}],"con":true,"img":false}]}
{"op":"mcm","clk":"11450545035","pt":1717323191861,"mc":[{"id":"1.229554921","rc":[{"atb":[[1.41,170.55]],"id":52671121},{"atb":[[1.52,0]],"id":65460404},{"atb":[[1.54,0]],"id":70003371}],"con":true,"img":false}]}
{"op":"mcm","clk":"11450545043","pt":1717323191962,"mc":[{"id":"1.229554921","rc":[{"atb":[[1.51,49.65]],"id":52671121},{"atb":[[1.6,45.77]],"id":65460404},{"atb":[[1.73,50.15]],"id":70003371}],"con":true,"img":false}]}
{"op":"mcm","clk":"11450545793","pt":1717323199072,"mc":[{"id":"1.229554921","rc":[{"atl":[[3.6,0],[3.8,0],[3.55,2.5],[3.75,5],[4,0],[3.45,7.5],[3.95,10]],"id":65460404},{"atb":[[1.98,12.5],[1.89,0],[2.04,11.88],[1.94,10],[1.93,0],[1.97,0]],"id":70003371}],"con":true,"img":false}]}
{"op":"mcm","clk":"11450545819","pt":1717323199279,"mc":[{"id":"1.229554921","rc":[{"atl":[[3.5,0]],"id":65460404},{"atb":[[1.98,5]],"id":70003371}],"con":true,"img":false}]}
{"op":"mcm","clk":"11450546079","pt":1717323201783,"mc":[{"id":"1.229554921","rc":[{"atb":[[1.61,6.98]],"id":65460404}],"con":true,"img":false}]}
{"op":"mcm","clk":"11450546106","pt":1717323201989,"mc":[{"id":"1.229554921","rc":[{"atb":[[1.45,0]],"id":65460404}],"con":true,"img":false}]}
{"op":"mcm","clk":"11450546140","pt":1717323202261,"mc":[{"id":"1.229554921","rc":[{"atb":[[1.43,9.91]],"id":52671121}],"con":true,"img":false}]}
{"op":"mcm","clk":"11450546236","pt":1717323203102,"mc":[{"id":"1.229554921","rc":[{"atb":[[1.62,10.53]],"id":65460404}],"con":true,"img":false}]}
{"op":"mcm","clk":"11450547082","pt":1717323210995,"mc":[{"id":"1.229554921","rc":[{"atb":[[1.52,0]],"id":52671121},{"spn":19.9,"spf":"NaN","id":69421986},{"spn":2.62,"spf":"NaN","id":65460404},{"atb":[[1.75,0]],"id":70003371},{"spn":2.04,"spf":1.0,"id":70003371}],"con":true,"img":false}]}
{"op":"mcm","clk":"11450547145","pt":1717323211518,"mc":[{"id":"1.229554921","rc":[{"atb":[[1.53,7.41]],"id":52671121}],"con":true,"img":false}]}
{"op":"mcm","clk":"11450547193","pt":1717323211884,"mc":[{"id":"1.229554921","rc":[{"atb":[[7.6,0]],"id":69421986}],"con":true,"img":false}]}
{"op":"mcm","clk":"11450547206","pt":1717323211991,"mc":[{"id":"1.229554921","rc":[{"atb":[[1.64,0],[1.6,0],[1.56,0]],"id":52671121},{"atl":[[3.1,0],[3.7,0],[3.3,0],[3.5,0]],"id":52671121},{"atb":[[2.3,0],[2.38,0],[2.46,0]],"id":62262930},{"atl":[[4.8,0],[5.6,7.5],[5.2,0],[4.7,0]],"id":62262930},{"atb":[[5,0],[4.6,0],[4.2,22.2]],"id":69577417},{"atl":[[11,0],[11.5,0],[13.5,0],[15.5,0]],"id":69577417},{"atb":[[8,5.36],[7.2,0],[6.4,0],[5.8,0],[7.8,0]],"id":69421986},{"atl":[[32,0],[34,0],[42,0]],"id":69421986},{"atb":[[1.76,0],[1.8,0],[1.72,5.44]],"id":65460404},{"atl":[[3.45,0],[3.95,0],[3.55,0],[3.75,0]],"id":65460404},{"atb":[[4.5,0],[5.3,0],[4.9,0]],"id":64546979},{"atl":[[16,0],[18,0],[13.5,0],[14,0]],"id":64546979},{"atb":[[1.98,0],[2.04,0],[1.94,0]],"id":70003371},{"atl":[[3.95,7.5],[3.55,0],[3.75,0]],"id":70003371}],"con":true,"img":false}]}
{"op":"mcm","clk":"11450547215","pt":1717323212091,"mc":[{"id":"1.229554921","rc":[{"atl":[[23,4.55],[26,0]],"id":69577417}],"con":true,"img":false}]}
{"op":"mcm","clk":"11450547227","pt":1717323212200,"mc":[{"id":"1.229554921","rc":[{"atl":[[4.1,0],[7.4,10.15]],"id":52671121},{"atl":[[5.6,0],[10,7.57]],"id":62262930},{"atl":[[23,0],[25,5.23]],"id":69577417},{"atl":[[8,10.09],[4.1,0]],"id":65460404},{"atl":[[34,5.64],[22,0]],"id":64546979},{"atl":[[3.95,0],[7.6,7.59]],"id":70003371}],"con":true,"img":false}]}
{"op":"mcm","clk":"11450547236","pt":1717323212318,"mc":[{"id":"1.229554921","rc":[{"atl":[[32,3.23],[25,2.61]],"id":69577417},{"atl":[[34,2.61],[40,2.56]],"id":64546979}],"con":true,"img":false}]}
{"op":"mcm","clk":"11450547255","pt":1717323212478,"mc":[{"id":"1.229554921","rc":[{"atl":[[8.8,2.2]],"id":62262930},{"atl":[[6.4,2.28]],"id":65460404},{"atl":[[34,5.23],[40,0]],"id":64546979},{"atl":[[6.4,9.83]],"id":70003371}],"con":true,"img":false}]}
{"op":"mcm","clk":"11450547267","pt":1717323212580,"mc":[{"id":"1.229554921","rc":[{"atl":[[10,0],[8.8,5.84]],"id":62262930},{"atl":[[6.4,4.56]],"id":65460404},{"atl":[[34,2.61],[40,2.56]],"id":64546979},{"atl":[[6.2,7.59],[7.6,0]],"id":70003371}],"con":true,"img":false}]}
{"op":"mcm","clk":"11450547279","pt":1717323212716,"mc":[{"id":"1.229554921","rc":[{"atl":[[10,4.19],[8.8,2.2]],"id":62262930},{"atl":[[8,0]],"id":65460404}],"con":true,"img":false}]}
{"op":"mcm","clk":"11450547292","pt":1717323212774,"mc":[{"id":"1.229554921","rc":[{"atl":[[10,0],[8.8,6.39]],"id":62262930}],"con":true,"img":false}]}
{"op":"mcm","clk":"11450547320","pt":1717323213026,"mc":[{"id":"1.229554921","rc":[{"atb":[[1.39,14.74]],"id":52671121},{"atb":[[2.04,7.08]],"id":62262930},{"atb":[[4,3.4]],"id":69577417},{"atb":[[3.35,4.38]],"id":64546979},{"atb":[[1.67,10.27]],"id":70003371}],"con":true,"img":false}]}
{"op":"mcm","clk":"11450547376","pt":1717323213493,"mc":[{"id":"1.229554921","rc":[{"atl":[[6.4,0]],"id":70003371}],"con":true,"img":false}]}
{"op":"mcm","clk":"11450547397","pt":1717323213701,"mc":[{"id":"1.229554921","rc":[{"atl":[[5.9,9.23]],"id":70003371}],"con":true,"img":false}]}
{"op":"mcm","clk":"11450547450","pt":1717323214171,"mc":[{"id":"1.229554921","rc":[{"atb":[[4,0]],"id":69577417}],"con":true,"img":false}]}
{"op":"mcm","clk":"11450547568","pt":1717323215219,"mc":[{"id":"1.229554921","rc":[{"atb":[[1.63,0],[1.54,2.13]],"id":52671121},{"atb":[[1.88,0],[2.1,2.13]],"id":62262930},{"atb":[[1.72,7.57],[1.79,0]],"id":65460404}],"con":true,"img":false}]}
{"op":"mcm","clk":"11450547668","pt":1717323216306,"mc":[{"id":"1.229554921","rc":[{"atl":[[5.9,0]],"id":70003371}],"con":true,"img":false}]}
{"op":"mcm","clk":"11450547694","pt":1717323216514,"mc":[{"id":"1.229554921","rc":[{"atl":[[5.5,1.8]],"id":70003371}],"con":true,"img":false}]}
{"op":"mcm","clk":"11450548014","pt":1717323219694,"mc":[{"id":"1.229554921","rc":[{"atl":[[32,0],[25,5.23]],"id":69577417}],"con":true,"img":false}]}
{"op":"mcm","clk":"11450548024","pt":1717323219796,"mc":[{"id":"1.229554921","rc":[{"atl":[[32,3.23],[25,2.61]],"id":69577417}],"con":true,"img":false}]}
{"op":"mcm","clk":"11450548044","pt":1717323220006,"mc":[{"id":"1.229554921","rc":[{"atl":[[34,5.23],[40,0]],"id":64546979},{"atl":[[6.2,0],[5.5,3.8]],"id":70003371}],"con":true,"img":false}]}
{"op":"mcm","clk":"11450548226","pt":1717323221831,"mc":[{"id":"1.229554921","rc":[{"atb":[[1.4,0],[1.5,0]],"id":52671121},{"atl":[[4.5,0]],"id":52671121},{"atb":[[2,0],[1.9,0]],"id":62262930},{"atl":[[8.6,0]],"id":62262930},{"atb":[[3.6,0],[4.2,14.94]],"id":69577417},{"atb":[[7.4,0],[5.7,0]],"id":69421986},{"atb":[[1.59,0],[1.69,0]],"id":65460404},{"atl":[[6.6,0]],"id":65460404},{"atb":[[4.8,0],[3.9,0]],"id":64546979},{"atb":[[1.72,0],[1.62,0]],"id":70003371},{"atl":[[6.8,0]],"id":70003371}],"con":true,"img":false}]}
{"op":"mcm","clk":"11450548237","pt":1717323221931,"mc":[{"id":"1.229554921","rc":[{"atb":[[1.41,0],[1.3,210.31]],"id":52671121},{"atl":[[10.5,0]],"id":62262930},{"atl":[[34,0],[25,0]],"id":69577417},{"atl":[[65,0],[80,0],[160,0.26]],"id":69421986},{"atb":[[1.36,166.37],[1.6,0],[1.47,0]],"id":65460404},{"atl":[[34,2.62],[42,0]],"id":64546979},{"atb":[[1.73,2.13],[1.43,0]],"id":70003371}],"con":true,"img":false}]}
{"op":"mcm","clk":"11450548248","pt":1717323222041,"mc":[{"id":"1.229554921","rc":[{"atb":[[1.39,0]],"id":52671121},{"atb":[[2.04,0]],"id":62262930},{"atl":[[12,3.64]],"id":62262930},{"atl":[[55,2.61],[30,2.61]],"id":69577417},{"atl":[[95,0],[200,2.61],[510,2]],"id":69421986},{"atb":[[1.62,56.3]],"id":65460404},{"atl":[[65,2.61],[80,2.61]],"id":64546979},{"atb":[[1.63,48.02],[1.38,167.41]],"id":70003371}],"con":true,"img":false}]}
{"op":"mcm","clk":"11450548612","pt":1717323225209,"mc":[{"id":"1.229554921","rc":[{"atl":[[65,4.61],[34,0]],"id":64546979}],"con":true,"img":false}]}
{"op":"mcm","clk":"11450548619","pt":1717323225307,"mc":[{"id":"1.229554921","rc":[{"atl":[[65,2.61],[75,2]],"id":64546979}],"con":true,"img":false}]}
{"op":"mcm","clk":"11450548858","pt":1717323227409,"mc":[{"id":"1.229554921","rc":[{"atl":[[65,4.61],[75,0]],"id":64546979}],"con":true,"img":false}]}
{"op":"mcm","clk":"11450548871","pt":1717323227512,"mc":[{"id":"1.229554921","rc":[{"atl":[[75,2]],"id":64546979}],"con":true,"img":false}]}
{"op":"mcm","clk":"11450548883","pt":1717323227613,"mc":[{"id":"1.229554921","rc":[{"atl":[[65,2.61]],"id":64546979}],"con":true,"img":false}]}
{"op":"mcm","clk":"11450548897","pt":1717323227714,"mc":[{"id":"1.229554921","rc":[{"atl":[[65,4.61]],"id":64546979}],"con":true,"img":false}]}
{"op":"mcm","clk":"11450548908","pt":1717323227820,"mc":[{"id":"1.229554921","rc":[{"atl":[[75,0]],"id":64546979}],"con":true,"img":false}]}
{"op":"mcm","clk":"11450549057","pt":1717323229334,"mc":[{"id":"1.229554921","rc":[{"atl":[[200,4.61],[510,0]],"id":69421986}],"con":true,"img":false}]}
{"op":"mcm","clk":"11450549355","pt":1717323231945,"mc":[{"id":"1.229554921","rc":[{"atb":[[1.51,0]],"id":52671121},{"atl":[[7.6,0]],"id":52671121},{"atb":[[2.02,0]],"id":62262930},{"atb":[[1.62,10.53]],"id":65460404},{"atb":[[1.63,0]],"id":70003371}],"con":true,"img":false}]}
{"op":"mcm","clk":"11450549369","pt":1717323232050,"mc":[{"id":"1.229554921","rc":[{"atb":[[1.37,49.65]],"id":52671121},{"atl":[[8.2,13.89],[7.4,0],[6.6,5.5]],"id":52671121},{"atb":[[1.83,33.29]],"id":62262930},{"atb":[[1.62,0],[1.47,45.77]],"id":65460404},{"atb":[[3.35,0]],"id":64546979},{"atb":[[1.67,0],[1.54,48.02]],"id":70003371}],"con":true,"img":false}]}
{"op":"mcm","clk":"11450549629","pt":1717323234137,"mc":[{"id":"1.229554921","rc":[{"atb":[[1.37,143.83],[1.47,49.42]],"id":52671121},{"atl":[[4.3,0.15]],"id":52671121},{"atb":[[1.92,37.87],[2.04,22.33]],"id":62262930},{"atl":[[9,0.06]],"id":62262930},{"atb":[[4.1,7.49],[3.55,13.66]],"id":69577417},{"atb":[[5.3,8.1],[6.6,4.14]],"id":69421986},{"atb":[[1.59,59.05],[1.69,33.66]],"id":65460404},{"atl":[[6.6,0.09]],"id":65460404},{"atb":[[3.95,11.81],[4.9,5.95]],"id":64546979},{"atb":[[1.64,54.44],[1.74,31.39]],"id":70003371},{"atl":[[6.8,0.08]],"id":70003371}],"con":true,"img":false}]}
{"op":"mcm","clk":"11450550148","pt":1717323238735,"mc":[{"id":"1.229554921","rc":[{"atb":[[3.25,1.89]],"id":69577417}],"con":true,"img":false}]}
{"op":"mcm","clk":"11450550152","pt":1717323238834,"mc":[{"id":"1.229554921","rc":[{"atb":[[1.43,0]],"id":52671121}],"con":true,"img":false}]}
{"op":"mcm","clk":"11450550208","pt":1717323239254,"mc":[{"id":"1.229554921","rc":[{"atl":[[6.4,7.85],[8.2,0]],"id":52671121}],"con":true,"img":false}]}
{"op":"mcm","clk":"11450550400","pt":1717323240934,"mc":[{"id":"1.229554921","rc":[{"atb":[[1.46,108.7],[1.44,170.45],[1.42,250],[1.48,41.67]],"id":52671121},{"atl":[[2.56,48.08],[2.52,32.89],[2.6,78.12],[2.48,13.51]],"id":52671121},{"atl":[[4.3,22.73],[4.5,35.71],[3.95,6.78],[4.1,16.13]],"id":62262930},{"atl":[[16.5,8.06],[13.5,1.6],[14.5,3.7],[15.5,5.17]],"id":69577417},{"atl":[[2.8,41.67],[2.72,11.63],[2.84,67.93],[2.76,28.41]],"id":65460404},{"atb":[[5.6,4.35],[5,42.56],[5.2,17.86],[5.4,11.36]],"id":64546979},{"atl":[[19.5,1.08],[21,2.5],[23,3.41],[25,5.21]],"id":64546979}],"con":true,"img":false}]}
{"op":"mcm","clk":"11450550415","pt":1717323241045,"mc":[{"id":"1.229554921","rc":[{"atl":[[6.2,3.64],[8.8,2.19]],"id":62262930},{"atl":[[32,0],[26,2.62]],"id":69577417},{"atl":[[38,1],[42,1.22],[46,1.67],[50,2.55]],"id":69421986},{"atl":[[4.5,4.56],[6.4,2.28]],"id":65460404},{"atl":[[65,2.61],[26,2.62]],"id":64546979},{"atl":[[3.35,53.19],[3.15,23.26],[3.25,33.33],[3.05,9.76]],"id":70003371}],"con":true,"img":false}]}
{"op":"mcm","clk":"11450550425","pt":1717323241149,"mc":[{"id":"1.229554921","rc":[{"atl":[[200,2.61],[110,2]],"id":69421986},{"atl":[[5.5,1.8],[4.2,31.25]],"id":70003371}],"con":true,"img":false}]}
{"op":"mcm","clk":"11450550526","pt":1717323241948,"mc":[{"id":"1.229554921","rc":[{"atl":[[55,0]],"id":69577417},{"atb":[[8,0]],"id":69421986},{"atl":[[160,0]],"id":69421986},{"atb":[[5,31.25]],"id":64546979},{"atl":[[65,0]],"id":64546979}],"con":true,"img":false}]}
{"op":"mcm","clk":"11450550536","pt":1717323242053,"mc":[{"id":"1.229554921","rc":[{"atl":[[60,2.61]],"id":69577417},{"atb":[[9.4,5.36]],"id":69421986},{"atl":[[190,0.26]],"id":69421986},{"atb":[[5.5,11.31]],"id":64546979},{"atl":[[60,2.61]],"id":64546979}],"con":true,"img":false}]}
{"op":"mcm","clk":"11450550897","pt":1717323245341,"mc":[{"id":"1.229554921","rc":[{"atb":[[4,3.6]],"id":69577417}],"con":true,"img":false}]}
{"op":"mcm","clk":"11450551015","pt":1717323246342,"mc":[{"id":"1.229554921","rc":[{"atl":[[6.4,0],[4.4,29.41]],"id":52671121}],"con":true,"img":false}]}
{"op":"mcm","clk":"11450551028","pt":1717323246542,"mc":[{"id":"1.229554921","rc":[{"atb":[[4,0]],"id":69577417}],"con":true,"img":false}]}
{"op":"mcm","clk":"11450551599","pt":1717323251870,"mc":[{"id":"1.229554921","rc":[{"atb":[[4.2,0],[1.17,100]],"id":69577417},{"atb":[[1.17,100],[9.4,0]],"id":69421986},{"atb":[[5.5,0],[1.17,100]],"id":64546979}],"con":true,"img":false}]}
{"op":"mcm","clk":"11450551616","pt":1717323252004,"mc":[{"id":"1.229554921","rc":[{"atb":[[3.75,14.94]],"id":69577417},{"atb":[[8,5.36]],"id":69421986},{"atb":[[4.7,11.31]],"id":64546979}],"con":true,"img":false}]}
{"op":"mcm","clk":"11450552590","pt":1717323261881,"mc":[{"id":"1.229554921","rc":[{"atl":[[8.4,0],[5.9,13.07]],"id":52671121},{"atb":[[2.74,0]],"id":69577417},{"atb":[[5,0],[7,8.98]],"id":69421986},{"atl":[[7,9.94],[9.4,0]],"id":65460404},{"atb":[[3.15,0],[4.2,16.63]],"id":64546979}],"con":true,"img":false}]}
{"op":"mcm","clk":"11450552600","pt":1717323261982,"mc":[{"id":"1.229554921","rc":[{"atb":[[3.35,29.94]],"id":69577417}],"con":true,"img":false}]}
{"op":"mcm","clk":"11450552728","pt":1717323263096,"mc":[{"id":"1.229554921","rc":[{"atb":[[1.46,117.66]],"id":52671121}],"con":true,"img":false}]}
{"op":"mcm","clk":"11450553704","pt":1717323271882,"mc":[{"id":"1.229554921","rc":[{"atb":[[1.37,94.17],[1.49,34.16]],"id":52671121},{"atl":[[4.3,12.83],[6.6,0]],"id":52671121},{"spn":2.01,"spf":"NaN","id":52671121},{"atb":[[1.83,0]],"id":62262930},{"atl":[[12,0],[8.4,5.65]],"id":62262930},{"spn":3.02,"spf":"NaN","id":62262930},{"spn":8.8,"spf":"NaN","id":69577417},{"atl":[[190,0],[100,0.42]],"id":69421986},{"spn":23.0,"spf":"NaN","id":69421986},{"atb":[[1.47,0]],"id":65460404},{"atl":[[5.8,8.72],[8.2,0]],"id":65460404},{"spn":2.22,"spf":"NaN","id":65460404},{"atl":[[60,0]],"id":64546979},{"spn":12.55,"spf":"NaN","id":64546979},{"atb":[[1.54,0]],"id":70003371},{"atl":[[6.2,8.04],[7.8,0]],"id":70003371},{"spn":1.74,"spf":1.0,"id":70003371}],"con":true,"img":false}]}
{"op":"mcm","clk":"11450553715","pt":1717323271983,"mc":[{"id":"1.229554921","rc":[{"atb":[[2.06,37]],"id":62262930},{"atb":[[1.6,45.77]],"id":65460404},{"atl":[[44,2.61]],"id":64546979},{"atb":[[1.65,48.02]],"id":70003371}],"con":true,"img":false}]}
{"op":"mcm","clk":"11450553845","pt":1717323273086,"mc":[{"id":"1.229554921","rc":[{"atb":[[1.59,69.58]],"id":65460404},{"atb":[[1.64,64.84]],"id":70003371}],"con":true,"img":false}]}
{"op":"mcm","clk":"11450553907","pt":1717323273708,"mc":[{"id":"1.229554921","rc":[{"atb":[[1.48,50.54]],"id":52671121}],"con":true,"img":false}]}
{"op":"mcm","clk":"11450553954","pt":1717323274080,"mc":[{"id":"1.229554921","rc":[{"atb":[[3.25,0]],"id":69577417}],"con":true,"img":false}]}
{"op":"mcm","clk":"11450554166","pt":1717323276106,"mc":[{"id":"1.229554921","rc":[{"atb":[[3.6,3.4]],"id":69577417}],"con":true,"img":false}]}
{"op":"mcm","clk":"11450554511","pt":1717323279106,"mc":[{"id":"1.229554921","rc":[{"atb":[[1.64,2.5],[1.6,5],[1.56,10],[1.54,36.93]],"id":52671121},{"atl":[[2.48,48.31]],"id":52671121},{"atb":[[2.3,10],[2.38,5],[2.46,2.5],[2.1,30.97]],"id":62262930},{"atl":[[3.95,33.9]],"id":62262930},{"atb":[[4.5,5],[4.1,24.14],[4.9,2.5]],"id":69577417},{"atl":[[11.5,2.5],[13,6.65],[13.5,6.6],[15.5,15.17]],"id":69577417},{"atb":[[8.2,4.36],[7.4,2.5],[6.6,9.14],[5.9,10]],"id":69421986},{"atl":[[34,2.5],[36,2.29],[42,6.22]],"id":69421986},{"atb":[[1.72,17.57],[1.8,2.5],[1.76,5]],"id":65460404},{"atb":[[5.3,2.5],[5.6,10.17]],"id":64546979},{"atl":[[17.5,10],[19,4.44],[13.5,2.5],[15.5,5]],"id":64546979},{"atb":[[2,2.5],[1.92,10],[1.74,72.38],[1.96,5]],"id":70003371},{"atl":[[3.05,48.78]],"id":70003371}],"con":true,"img":false}]}
{"op":"mcm","clk":"11450554520","pt":1717323279217,"mc":[{"id":"1.229554921","rc":[{"atb":[[1.46,108.7]],"id":52671121},{"atl":[[5.6,21.74],[6.2,0]],"id":62262930},{"atb":[[3.6,0]],"id":69577417},{"atb":[[1.72,47.6],[1.59,59.05]],"id":65460404},{"atl":[[2.72,41.66]],"id":65460404},{"atl":[[23,6.99],[26,0]],"id":64546979},{"atb":[[1.64,54.44]],"id":70003371},{"atl":[[3.85,35.09],[4.2,0]],"id":70003371}],"con":true,"img":false}]}
{"op":"mcm","clk":"11450554622","pt":1717323280108,"mc":[{"id":"1.229554921","rc":[{"atb":[[1.59,2.13],[1.54,34.8]],"id":52671121}],"con":true,"img":false}]}
{"op":"mcm","clk":"11450554832","pt":1717323281910,"mc":[{"id":"1.229554921","rc":[{"atb":[[4.7,0]],"id":64546979}],"con":true,"img":false}]}
{"op":"mcm","clk":"11450554839","pt":1717323282015,"mc":[{"id":"1.229554921","rc":[{"atb":[[5.5,11.31]],"id":64546979}],"con":true,"img":false}]}
{"op":"mcm","clk":"11450554886","pt":1717323282392,"mc":[{"id":"1.229554921","rc":[{"atl":[[4.5,0],[3.9,34.48]],"id":65460404},{"atb":[[2.02,98.04],[2.2,0]],"id":64546979}],"con":true,"img":false}]}
{"op":"mcm","clk":"11450555027","pt":1717323283689,"mc":[{"id":"1.229554921","rc":[{"atl":[[8.8,0]],"id":62262930},{"atl":[[5.5,0]],"id":70003371}],"con":true,"img":false}]}
{"op":"mcm","clk":"11450555127","pt":1717323284528,"mc":[{"id":"1.229554921","rc":[{"atb":[[2.06,33.29]],"id":62262930},{"atb":[[1.72,42.16]],"id":65460404}],"con":true,"img":false}]}
{"op":"mcm","clk":"11450555692","pt":1717323289444,"mc":[{"id":"1.229554921","rc":[{"atl":[[2.42,14.08],[3.8,35.71],[4.4,0],[2.48,34.8]],"id":52671121},{"atl":[[3.95,27.12],[4.1,6.45]],"id":62262930},{"atl":[[85,2],[110,0]],"id":69421986},{"atb":[[1.46,0],[1.51,140.61]],"id":65460404},{"atb":[[2.26,79.37],[2.02,0]],"id":64546979},{"atb":[[1.53,0],[1.61,140.22]],"id":70003371},{"atl":[[3.85,0],[3.7,37.04],[3.15,9.3],[3.05,39.02]],"id":70003371}],"con":true,"img":false}]}
{"op":"mcm","clk":"11450555704","pt":1717323289542,"mc":[{"id":"1.229554921","rc":[{"atl":[[4,6.67]],"id":62262930},{"atl":[[3.1,9.52]],"id":70003371}],"con":true,"img":false}]}
{"op":"mcm","clk":"11450555715","pt":1717323289606,"mc":[{"id":"1.229554921","rc":[{"atl":[[3.95,0]],"id":62262930},{"atb":[[2.26,0],[2.1,90.91]],"id":64546979},{"atl":[[3.05,0]],"id":70003371}],"con":true,"img":false}]}
{"op":"mcm","clk":"11450555728","pt":1717323289710,"mc":[{"id":"1.229554921","rc":[{"atl":[[4,16.51]],"id":62262930}],"con":true,"img":false}]}
{"op":"mcm","clk":"11450555736","pt":1717323289841,"mc":[{"id":"1.229554921","rc":[{"atl":[[3.1,23.64]],"id":70003371}],"con":true,"img":false}]}
{"op":"mcm","clk":"11450555975","pt":1717323291932,"mc":[{"id":"1.229554921","rc":[{"atl":[[4.3,0.15]],"id":52671121},{"atl":[[10.5,5.5],[13.5,0]],"id":62262930},{"atl":[[60,0]],"id":69577417},{"atl":[[200,0]],"id":69421986},{"atb":[[4.2,0]],"id":64546979},{"atl":[[80,0]],"id":64546979},{"atl":[[7.4,9.41],[9.4,0]],"id":70003371}],"con":true,"img":false}]}
{"op":"mcm","clk":"11450555985","pt":1717323292031,"mc":[{"id":"1.229554921","rc":[{"atl":[[4.8,12.68]],"id":52671121},{"atl":[[34,2.61]],"id":69577417},{"atl":[[110,2.61]],"id":69421986},{"atb":[[4,16.63]],"id":64546979},{"atl":[[42,2.61]],"id":64546979}],"con":true,"img":false}]}
{"op":"mcm","clk":"11450556141","pt":1717323293446,"mc":[{"id":"1.229554921","rc":[{"atb":[[1.64,16.81]],"id":52671121},{"atl":[[2.42,28.39]],"id":52671121},{"atb":[[2.46,14.84]],"id":62262930},{"atb":[[4.9,11.2]],"id":69577417},{"atl":[[11.5,10.12]],"id":69577417},{"atl":[[32,2.58]],"id":69421986},{"atb":[[2,16.98]],"id":70003371}],"con":true,"img":false}]}
{"op":"mcm","clk":"11450556150","pt":1717323293498,"mc":[{"id":"1.229554921","rc":[{"atb":[[1.54,0]],"id":52671121},{"atb":[[2.1,2.13]],"id":62262930},{"atb":[[4.1,17.49]],"id":69577417},{"atl":[[13,0]],"id":69577417},{"atl":[[36,0]],"id":69421986},{"atl":[[13,6.67]],"id":64546979}],"con":true,"img":false}]}
{"op":"mcm","clk":"11450556156","pt":1717323293604,"mc":[{"id":"1.229554921","rc":[{"atl":[[2.48,0]],"id":52671121},{"atb":[[1.8,55.05]],"id":65460404},{"atl":[[19,0]],"id":64546979},{"atb":[[1.74,31.39]],"id":70003371}],"con":true,"img":false}]}
{"op":"mcm","clk":"11450556179","pt":1717323293811,"mc":[{"id":"1.229554921","rc":[{"atb":[[1.72,12.13]],"id":65460404}],"con":true,"img":false}]}
{"op":"mcm","clk":"11450556752","pt":1717323299637,"mc":[{"id":"1.229554921","rc":[{"atl":[[2.46,34.25]],"id":52671121}],"con":true,"img":false}]}
{"op":"mcm","clk":"11450557008","pt":1717323301938,"mc":[{"id":"1.229554921","rc":[{"atb":[[2.06,0]],"id":62262930},{"atl":[[30,0]],"id":69577417}],"con":true,"img":false}]}
{"op":"mcm","clk":"11450557018","pt":1717323302041,"mc":[{"id":"1.229554921","rc":[{"atb":[[2.12,33.29]],"id":62262930},{"atl":[[29,2.61]],"id":69577417}],"con":true,"img":false}]}
{"op":"mcm","clk":"11450557512","pt":1717323306215,"mc":[{"id":"1.229554921","rc":[{"atb":[[1.83,4.72]],"id":65460404}],"con":true,"img":false}]}
{"op":"mcm","clk":"11450557528","pt":1717323306428,"mc":[{"id":"1.229554921","rc":[{"atb":[[2.16,3.38]],"id":62262930},{"atb":[[1.68,5.77]],"id":70003371}],"con":true,"img":false}]}
{"op":"mcm","clk":"11450557649","pt":1717323307461,"mc":[{"id":"1.229554921","rc":[{"atb":[[1.59,69.58]],"id":65460404}],"con":true,"img":false}]}
{"op":"mcm","clk":"11450557661","pt":1717323307522,"mc":[{"id":"1.229554921","rc":[{"atb":[[1.59,59.05]],"id":65460404}],"con":true,"img":false}]}
{"op":"mcm","clk":"11450557684","pt":1717323307730,"mc":[{"id":"1.229554921","rc":[{"atb":[[1.83,57.27]],"id":65460404}],"con":true,"img":false}]}
{"op":"mcm","clk":"11450557691","pt":1717323307831,"mc":[{"id":"1.229554921","rc":[{"atb":[[1.8,2.5]],"id":65460404}],"con":true,"img":false}]}
{"op":"mcm","clk":"11450557896","pt":1717323309625,"mc":[{"id":"1.229554921","rc":[{"atl":[[2.56,0],[2.5,50],[2.52,0],[2.6,0]],"id":52671121}],"con":true,"img":false}]}
{"op":"mcm","clk":"11450557906","pt":1717323309730,"mc":[{"id":"1.229554921","rc":[{"atl":[[3.6,5],[3.8,45.71],[3.4,2.5]],"id":52671121}],"con":true,"img":false}]}
{"op":"mcm","clk":"11450557975","pt":1717323310350,"mc":[{"id":"1.229554921","rc":[{"atl":[[60,5]],"id":52671121},{"atl":[[60,5]],"id":65460404}],"con":true,"img":false}]}
{"op":"mcm","clk":"11450558105","pt":1717323311546,"mc":[{"id":"1.229554921","rc":[{"atb":[[1.61,0]],"id":65460404}],"con":true,"img":false}]}
{"op":"mcm","clk":"11450558144","pt":1717323311916,"mc":[{"id":"1.229554921","rc":[{"atb":[[2.12,0]],"id":62262930},{"atb":[[5,10.46],[3.75,0]],"id":69577417},{"atl":[[80,2.61],[100,0]],"id":69421986},{"atb":[[5.5,0]],"id":64546979},{"atl":[[44,0]],"id":64546979},{"atb":[[1.65,0]],"id":70003371}],"con":true,"img":false}]}
{"op":"mcm","clk":"11450558157","pt":1717323312018,"mc":[{"id":"1.229554921","rc":[{"atb":[[2.06,33.29]],"id":62262930},{"atb":[[5.7,11.31]],"id":64546979},{"atl":[[32,2.61]],"id":64546979},{"atb":[[1.75,48.02]],"id":70003371}],"con":true,"img":false}]}
{"op":"mcm","clk":"11450558168","pt":1717323312118,"mc":[{"id":"1.229554921","rc":[{"atb":[[5,23]],"id":69577417},{"atb":[[5.7,23.94]],"id":64546979}],"con":true,"img":false}]}
{"op":"mcm","clk":"11450558183","pt":1717323312226,"mc":[{"id":"1.229554921","rc":[{"atb":[[4.9,2.5]],"id":69577417},{"atb":[[5.6,4.35]],"id":64546979}],"con":true,"img":false}]}
{"op":"mcm","clk":"11450558852","pt":1717323318353,"mc":[{"id":"1.229554921","rc":[{"atb":[[1.53,0]],"id":52671121}],"con":true,"img":false}]}
{"op":"mcm","clk":"11450558992","pt":1717323319565,"mc":[{"id":"1.229554921","rc":[{"atl":[[2.54,81.17]],"id":52671121}],"con":true,"img":false}]}
{"op":"mcm","clk":"11450559238","pt":1717323321965,"mc":[{"id":"1.229554921","rc":[{"atl":[[29,0]],"id":69577417},{"atb":[[8,0]],"id":69421986}],"con":true,"img":false}]}
{"op":"mcm","clk":"11450559250","pt":1717323322071,"mc":[{"id":"1.229554921","rc":[{"atl":[[26,5.23]],"id":69577417},{"atb":[[8.2,0],[8.4,5.36]],"id":69421986}],"con":true,"img":false}]}
{"op":"mcm","clk":"11450559260","pt":1717323322171,"mc":[{"id":"1.229554921","rc":[{"atb":[[7.8,3.81]],"id":69421986}],"con":true,"img":false}]}
{"op":"mcm","clk":"11450559798","pt":1717323326857,"mc":[{"id":"1.229554921","rc":[{"atb":[[1.5,7.85]],"id":52671121}],"con":true,"img":false}]}
{"op":"mcm","clk":"11450560384","pt":1717323331891,"mc":[{"id":"1.229554921","rc":[{"spn":2.03,"spf":"NaN","id":52671121},{"spn":3.23,"spf":"NaN","id":62262930},{"atb":[[5,12.54]],"id":69577417},{"spn":8.25,"spf":"NaN","id":69577417},{"spn":20.2,"spf":"NaN","id":69421986},{"spn":2.27,"spf":"NaN","id":65460404},{"spn":9.35,"spf":"NaN","id":64546979},{"atb":[[1.45,137.59]],"id":70003371},{"spn":2.0,"spf":1.0,"id":70003371}],"con":true,"img":false}]}
{"op":"mcm","clk":"11450560393","pt":1717323331981,"mc":[{"id":"1.229554921","rc":[{"atb":[[4.6,10.46]],"id":69577417},{"atb":[[1.38,0]],"id":70003371}],"con":true,"img":false}]}
{"op":"mcm","clk":"11450560840","pt":1717323335687,"mc":[{"id":"1.229554921","rc":[{"atb":[[8.6,3.81]],"id":69421986}],"con":true,"img":false}]}
{"op":"mcm","clk":"11450560853","pt":1717323335741,"mc":[{"id":"1.229554921","rc":[{"atb":[[7.8,0]],"id":69421986}],"con":true,"img":false}]}
{"op":"mcm","clk":"11450561013","pt":1717323337193,"mc":[{"id":"1.229554921","rc":[{"atb":[[4.9,0],[4.5,0],[5.1,2.5],[4.1,7.49],[4.7,5]],"id":69577417},{"atb":[[7.4,0],[7.6,2.5],[6.6,4.14],[5.9,0]],"id":69421986},{"atb":[[5.3,0],[5.5,2.5]],"id":64546979}],"con":true,"img":false}]}
{"op":"mcm","clk":"11450561025","pt":1717323337252,"mc":[{"id":"1.229554921","rc":[{"atb":[[5.1,11.2]],"id":69577417}],"con":true,"img":false}]}
{"op":"mcm","clk":"11450561038","pt":1717323337356,"mc":[{"id":"1.229554921","rc":[{"atb":[[5,0]],"id":69577417}],"con":true,"img":false}]}
{"op":"mcm","clk":"11450561121","pt":1717323338183,"mc":[{"id":"1.229554921","rc":[{"atb":[[4.1,10.89]],"id":69577417}],"con":true,"img":false}]}
{"op":"mcm","clk":"11450561521","pt":1717323341883,"mc":[{"id":"1.229554921","rc":[{"atb":[[4.6,0]],"id":69577417},{"atb":[[5.7,12.63]],"id":64546979}],"con":true,"img":false}]}
{"op":"mcm","clk":"11450561534","pt":1717323341985,"mc":[{"id":"1.229554921","rc":[{"atb":[[4.2,10.46]],"id":69577417},{"atb":[[5.8,11.31]],"id":64546979}],"con":true,"img":false}]}
{"op":"mcm","clk":"11450561545","pt":1717323342089,"mc":[{"id":"1.229554921","rc":[{"atb":[[5.8,20.06]],"id":64546979}],"con":true,"img":false}]}
{"op":"mcm","clk":"11450561558","pt":1717323342192,"mc":[{"id":"1.229554921","rc":[{"atb":[[5.7,0]],"id":64546979}],"con":true,"img":false}]}
{"op":"mcm","clk":"11450561694","pt":1717323343403,"mc":[{"id":"1.229554921","rc":[{"atb":[[1.37,0],[1.47,0]],"id":52671121},{"atl":[[4.3,0]],"id":52671121},{"atb":[[1.92,0],[2.04,0]],"id":62262930},{"atl":[[9,0]],"id":62262930},{"atb":[[4.1,3.4],[3.55,0]],"id":69577417},{"atb":[[5.3,0],[6.6,0]],"id":69421986},{"atb":[[1.59,0],[1.69,0]],"id":65460404},{"atl":[[6.6,0]],"id":65460404},{"atb":[[4.9,0],[3.95,0]],"id":64546979},{"atb":[[1.64,0],[1.74,0]],"id":70003371},{"atl":[[6.8,0]],"id":70003371}],"con":true,"img":false}]}
{"op":"mcm","clk":"11450561783","pt":1717323344086,"mc":[{"id":"1.229554921","rc":[{"atb":[[4.1,0]],"id":69577417}],"con":true,"img":false}]}
{"op":"mcm","clk":"11450561924","pt":1717323345187,"mc":[{"id":"1.229554921","rc":[{"atb":[[1.83,52.55]],"id":65460404}],"con":true,"img":false}]}
{"op":"mcm","clk":"11450561936","pt":1717323345295,"mc":[{"id":"1.229554921","rc":[{"atb":[[1.83,0]],"id":65460404}],"con":true,"img":false}]}
{"op":"mcm","clk":"11450561949","pt":1717323345401,"mc":[{"id":"1.229554921","rc":[{"atb":[[1.81,52.55]],"id":65460404}],"con":true,"img":false}]}
{"op":"mcm","clk":"11450562168","pt":1717323347498,"mc":[{"id":"1.229554921","rc":[{"atb":[[1.59,11.24]],"id":65460404}],"con":true,"img":false}]}
{"op":"mcm","clk":"11450562644","pt":1717323351883,"mc":[{"id":"1.229554921","rc":[{"atb":[[3.8,14.94],[4.2,0]],"id":69577417}],"con":true,"img":false}]}
{"op":"mcm","clk":"11450562656","pt":1717323351986,"mc":[{"id":"1.229554921","rc":[{"atb":[[1.3,0]],"id":52671121},{"atb":[[2.06,0]],"id":62262930},{"atb":[[1.36,0],[1.6,0]],"id":65460404},{"atb":[[4,0]],"id":64546979},{"atb":[[1.75,0]],"id":70003371}],"con":true,"img":false}]}
{"op":"mcm","clk":"11450562666","pt":1717323352087,"mc":[{"id":"1.229554921","rc":[{"atb":[[1.32,210.31]],"id":52671121},{"atb":[[1.83,33.29]],"id":62262930},{"atb":[[1.43,166.37],[1.53,45.77]],"id":65460404},{"atb":[[3.7,16.63]],"id":64546979},{"atb":[[1.62,48.02]],"id":70003371}],"con":true,"img":false}]}
{"op":"mcm","clk":"11450563077","pt":1717323355888,"mc":[{"id":"1.229554921","rc":[{"atl":[[3.6,0],[3.4,0],[3.8,35.71]],"id":52671121}],"con":true,"img":false}]}
{"op":"mcm","clk":"11450563425","pt":1717323359017,"mc":[{"id":"1.229554921","rc":[{"atb":[[1.42,332.96],[1.52,44.66]],"id":52671121},{"atl":[[4.7,0.14]],"id":52671121},{"atb":[[1.99,35.19],[2.18,19.68]],"id":62262930},{"atl":[[9.6,0.06]],"id":62262930},{"atb":[[4.1,7.49],[3.55,13.66]],"id":69577417},{"atb":[[5.3,8.1],[6.6,4.14]],"id":69421986},{"atb":[[1.58,60.07],[1.68,34.15]],"id":65460404},{"atl":[[6.4,2.37]],"id":65460404},{"atb":[[4,11.61],[5,37.05]],"id":64546979},{"atb":[[1.57,61.12],[1.67,34.67]],"id":70003371},{"atl":[[6.4,0.09]],"id":70003371}],"con":true,"img":false}]}
{"op":"mcm","clk":"11450564023","pt":1717323364305,"mc":[{"id":"1.229554921","rc":[{"atb":[[4.1,10.89]],"id":69577417}],"con":true,"img":false}]}
{"op":"mcm","clk":"11450564223","pt":1717323366018,"mc":[{"id":"1.229554921","rc":[{"atb":[[1.5,0]],"id":52671121}],"con":true,"img":false}]}
{"op":"mcm","clk":"11450564235","pt":1717323366127,"mc":[{"id":"1.229554921","rc":[{"atb":[[1.68,0]],"id":70003371}],"con":true,"img":false}]}
{"op":"mcm","clk":"11450564345","pt":1717323366912,"mc":[{"id":"1.229554921","rc":[{"atb":[[1.59,0]],"id":65460404}],"con":true,"img":false}]}
{"op":"mcm","clk":"11450564380","pt":1717323367216,"mc":[{"id":"1.229554921","rc":[{"atb":[[1.54,7.26]],"id":52671121},{"atb":[[1.7,5.6]],"id":70003371}],"con":true,"img":false}]}
{"op":"mcm","clk":"11450564925","pt":1717323371909,"mc":[{"id":"1.229554921","rc":[{"atb":[[5.8,8.75]],"id":64546979}],"con":true,"img":false}]}
{"op":"mcm","clk":"11450564939","pt":1717323372018,"mc":[{"id":"1.229554921","rc":[{"atb":[[5.8,0],[5.9,11.31]],"id":64546979}],"con":true,"img":false}]}
{"op":"mcm","clk":"11450564954","pt":1717323372116,"mc":[{"id":"1.229554921","rc":[{"atb":[[5.9,18.32]],"id":64546979}],"con":true,"img":false}]}
{"op":"mcm","clk":"11450565080","pt":1717323373110,"mc":[{"id":"1.229554921","rc":[{"atb":[[1.5,10.53]],"id":65460404}],"con":true,"img":false}]}
{"op":"mcm","clk":"11450565187","pt":1717323373841,"mc":[{"id":"1.229554921","rc":[{"atb":[[1.46,0],[1.44,0],[1.48,8.87]],"id":52671121},{"atl":[[2.4,14.29],[2.42,14.31]],"id":52671121},{"atl":[[38,0],[42,5],[46,0],[50,0]],"id":69421986},{"atl":[[2.72,30.03],[2.7,11.76]],"id":65460404}],"con":true,"img":false}]}
{"op":"mcm","clk":"11450565201","pt":1717323373947,"mc":[{"id":"1.229554921","rc":[{"atl":[[16,1.33],[13.5,5]],"id":69577417}],"con":true,"img":false}]}
{"op":"mcm","clk":"11450565213","pt":1717323374014,"mc":[{"id":"1.229554921","rc":[{"atl":[[2.4,35.74]],"id":52671121},{"atl":[[2.7,41.89]],"id":65460404}],"con":true,"img":false}]}
{"op":"mcm","clk":"11450565222","pt":1717323374116,"mc":[{"id":"1.229554921","rc":[{"atl":[[2.4,21.45],[2.42,28.39]],"id":52671121},{"atl":[[14.5,0]],"id":69577417},{"atl":[[2.72,41.66],[2.7,30.13]],"id":65460404}],"con":true,"img":false}]}
{"op":"mcm","clk":"11450565233","pt":1717323374213,"mc":[{"id":"1.229554921","rc":[{"atl":[[2.72,11.63]],"id":65460404}],"con":true,"img":false}]}
{"op":"mcm","clk":"11450565250","pt":1717323374373,"mc":[{"id":"1.229554921","rc":[{"atl":[[2.44,13.89],[2.42,14.31]],"id":52671121},{"atl":[[15.5,10]],"id":69577417},{"atl":[[2.72,0],[2.74,11.49]],"id":65460404},{"atl":[[19.5,0],[20,1.05]],"id":64546979}],"con":true,"img":false}]}
{"op":"mcm","clk":"11450565258","pt":1717323374430,"mc":[{"id":"1.229554921","rc":[{"atl":[[2.42,0]],"id":52671121}],"con":true,"img":false}]}
{"op":"mcm","clk":"11450565268","pt":1717323374529,"mc":[{"id":"1.229554921","rc":[{"atl":[[2.7,0]],"id":65460404}],"con":true,"img":false}]}
{"op":"mcm","clk":"11450565284","pt":1717323374635,"mc":[{"id":"1.229554921","rc":[{"atl":[[2.4,0]],"id":52671121},{"atl":[[2.74,41.41]],"id":65460404}],"con":true,"img":false}]}
{"op":"mcm","clk":"11450565294","pt":1717323374742,"mc":[{"id":"1.229554921","rc":[{"atl":[[2.44,36.91]],"id":52671121},{"atl":[[6.4,0.09]],"id":65460404}],"con":true,"img":false}]}
{"op":"mcm","clk":"11450565311","pt":1717323374943,"mc":[{"id":"1.229554921","rc":[{"atl":[[2.42,14.08],[2.44,23.02]],"id":52671121},{"atl":[[2.72,11.63],[2.74,29.92]],"id":65460404},{"atl":[[19.5,1.08],[20,0]],"id":64546979}],"con":true,"img":false}]}
{"op":"mcm","clk":"11450565465","pt":1717323376143,"mc":[{"id":"1.229554921","rc":[{"atl":[[2.42,0],[2.44,36.91]],"id":52671121},{"atl":[[2.72,0],[2.74,41.41]],"id":65460404},{"atl":[[19.5,0],[20,1.05]],"id":64546979}],"con":true,"img":false}]}
{"op":"mcm","clk":"11450565495","pt":1717323376357,"mc":[{"id":"1.229554921","rc":[{"atl":[[2.42,14.08],[2.44,23.02]],"id":52671121}],"con":true,"img":false}]}
{"op":"mcm","clk":"11450565621","pt":1717323377249,"mc":[{"id":"1.229554921","rc":[{"atl":[[2.72,11.63],[2.74,29.92]],"id":65460404},{"atl":[[19.5,1.08],[20,0]],"id":64546979}],"con":true,"img":false}]}
{"op":"mcm","clk":"11450565777","pt":1717323378555,"mc":[{"id":"1.229554921","rc":[{"atb":[[1.83,0]],"id":62262930},{"atb":[[3.8,0]],"id":69577417},{"atb":[[1.53,0]],"id":65460404},{"atb":[[1.62,0]],"id":70003371}],"con":true,"img":false}]}
{"op":"mcm","clk":"11450565791","pt":1717323378615,"mc":[{"id":"1.229554921","rc":[{"atb":[[2,33.29]],"id":62262930},{"atb":[[4.2,14.94]],"id":69577417},{"atb":[[1.59,45.77]],"id":65460404},{"atb":[[1.68,48.02]],"id":70003371}],"con":true,"img":false}]}
{"op":"mcm","clk":"11450565849","pt":1717323379146,"mc":[{"id":"1.229554921","rc":[{"atb":[[4.1,7.49]],"id":69577417}],"con":true,"img":false}]}
{"op":"mcm","clk":"11450565914","pt":1717323379760,"mc":[{"id":"1.229554921","rc":[{"atl":[[13.5,6.6]],"id":69577417},{"atl":[[38,1],[42,6.22],[46,1.67],[50,2.55]],"id":69421986}],"con":true,"img":false}]}
{"op":"mcm","clk":"11450566182","pt":1717323381743,"mc":[{"id":"1.229554921","rc":[{"atl":[[4.8,0]],"id":52671121},{"atl":[[6.2,0]],"id":70003371}],"con":true,"img":false}]}
{"op":"mcm","clk":"11450566195","pt":1717323381842,"mc":[{"id":"1.229554921","rc":[{"atl":[[4.7,12.82]],"id":52671121},{"atl":[[6,8.04]],"id":70003371}],"con":true,"img":false}]}
{"op":"mcm","clk":"11450566216","pt":1717323382050,"mc":[{"id":"1.229554921","rc":[{"atb":[[1.5,0]],"id":65460404}],"con":true,"img":false}]}
{"op":"mcm","clk":"11450566536","pt":1717323384460,"mc":[{"id":"1.229554921","rc":[{"atb":[[1.53,55.27]],"id":52671121}],"con":true,"img":false}]}
{"op":"mcm","clk":"11450566551","pt":1717323384570,"mc":[{"id":"1.229554921","rc":[{"atb":[[1.49,0]],"id":52671121}],"con":true,"img":false}]}
{"op":"mcm","clk":"11450566581","pt":1717323384875,"mc":[{"id":"1.229554921","rc":[{"atb":[[1.7,0]],"id":70003371}],"con":true,"img":false}]}
{"op":"mcm","clk":"11450566610","pt":1717323385166,"mc":[{"id":"1.229554921","rc":[{"atb":[[1.71,5.52]],"id":70003371}],"con":true,"img":false}]}
{"op":"mcm","clk":"11450566674","pt":1717323385637,"mc":[{"id":"1.229554921","rc":[{"atb":[[1.48,0]],"id":52671121}],"con":true,"img":false}]}
{"op":"mcm","clk":"11450566738","pt":1717323386259,"mc":[{"id":"1.229554921","rc":[{"atb":[[1.63,6.76]],"id":70003371}],"con":true,"img":false}]}
{"op":"mcm","clk":"11450566770","pt":1717323386569,"mc":[{"id":"1.229554921","rc":[{"atl":[[2.42,37.25]],"id":52671121},{"atl":[[2.72,41.66]],"id":65460404}],"con":true,"img":false}]}
{"op":"mcm","clk":"11450566786","pt":1717323386673,"mc":[{"id":"1.229554921","rc":[{"atl":[[2.44,0]],"id":52671121},{"atl":[[2.74,0]],"id":65460404}],"con":true,"img":false}]}
{"op":"mcm","clk":"11450566810","pt":1717323386836,"mc":[{"id":"1.229554921","rc":[{"atl":[[13.5,5]],"id":69577417},{"atl":[[38,0],[42,5],[46,0],[50,0]],"id":69421986}],"con":true,"img":false}]}
{"op":"mcm","clk":"11450566975","pt":1717323388350,"mc":[{"id":"1.229554921","rc":[{"atl":[[17,3.12]],"id":69577417}],"con":true,"img":false}]}
{"op":"mcm","clk":"11450567065","pt":1717323389134,"mc":[{"id":"1.229554921","rc":[{"atb":[[4.1,10.89]],"id":69577417}],"con":true,"img":false}]}
{"op":"mcm","clk":"11450567117","pt":1717323389551,"mc":[{"id":"1.229554921","rc":[{"atb":[[5.9,7.01]],"id":64546979}],"con":true,"img":false}]}
{"op":"mcm","clk":"11450567129","pt":1717323389657,"mc":[{"id":"1.229554921","rc":[{"atb":[[5.6,15.66]],"id":64546979}],"con":true,"img":false}]}
{"op":"mcm","clk":"11450567139","pt":1717323389762,"mc":[{"id":"1.229554921","rc":[{"atb":[[5.9,0]],"id":64546979}],"con":true,"img":false}]}
{"op":"mcm","clk":"11450567152","pt":1717323389861,"mc":[{"id":"1.229554921","rc":[{"atb":[[5.7,8.75]],"id":64546979}],"con":true,"img":false}]}
{"op":"mcm","clk":"11450567254","pt":1717323390862,"mc":[{"id":"1.229554921","rc":[{"atb":[[1.57,0],[1.67,0]],"id":70003371},{"atl":[[6.4,0]],"id":70003371}],"con":true,"img":false}]}
{"op":"mcm","clk":"11450567311","pt":1717323391385,"mc":[{"id":"1.229554921","rc":[{"atl":[[13.5,6.6]],"id":69577417},{"atl":[[38,1],[42,6.22],[46,1.67],[50,2.55]],"id":69421986}],"con":true,"img":false}]}
{"op":"mcm","clk":"11450567362","pt":1717323391859,"mc":[{"id":"1.229554921","rc":[{"atl":[[13.5,5]],"id":69577417},{"atl":[[38,0],[42,5],[46,0],[50,0]],"id":69421986}],"con":true,"img":false}]}
{"op":"mcm","clk":"11450567373","pt":1717323391965,"mc":[{"id":"1.229554921","rc":[{"atb":[[4.1,7.49]],"id":69577417},{"spn":8.3,"spf":"NaN","id":69577417},{"spn":20.3,"spf":"NaN","id":69421986},{"spn":2.26,"spf":"NaN","id":65460404}],"con":true,"img":false}]}
{"op":"mcm","clk":"11450567407","pt":1717323392283,"mc":[{"id":"1.229554921","rc":[{"atb":[[2.16,0]],"id":62262930}],"con":true,"img":false}]}
{"op":"mcm","clk":"11450567443","pt":1717323392600,"mc":[{"id":"1.229554921","rc":[{"atb":[[1.64,14.31],[1.6,0]],"id":52671121},{"atb":[[1.82,0],[1.88,54.03]],"id":62262930},{"atl":[[4,9.84]],"id":62262930},{"atb":[[4.8,5],[4.4,10],[3.45,29.95],[5.1,8.7],[5.2,2.5],[3.15,0],[4.7,0]],"id":69577417},{"atl":[[11.5,7.62],[13,2.5],[13.5,0],[15,5],[15.5,0]],"id":69577417},{"atl":[[3.9,0],[3.65,37.74]],"id":65460404},{"atb":[[2.32,75.76],[2.1,0],[5.5,0],[5.7,11.25]],"id":64546979},{"atl":[[3.1,14.12],[3.05,9.76]],"id":70003371}],"con":true,"img":false}]}
{"op":"mcm","clk":"11450567455","pt":1717323392656,"mc":[{"id":"1.229554921","rc":[{"atb":[[1.57,2.5]],"id":52671121},{"atl":[[4.1,0],[4.2,6.25]],"id":62262930},{"atb":[[1.91,98.85]],"id":64546979},{"atl":[[3,10],[3.05,0]],"id":70003371}],"con":true,"img":false}]}
{"op":"mcm","clk":"11450567467","pt":1717323392760,"mc":[{"id":"1.229554921","rc":[{"atb":[[1.64,0],[1.56,0]],"id":52671121},{"atb":[[5.2,10]],"id":69577417},{"atl":[[11.5,0]],"id":69577417},{"atb":[[7.6,0],[7,13.98],[7.8,2.5]],"id":69421986},{"atb":[[2.32,0]],"id":64546979},{"atl":[[3.05,14.48]],"id":70003371}],"con":true,"img":false}]}
{"op":"mcm","clk":"11450567481","pt":1717323392873,"mc":[{"id":"1.229554921","rc":[{"atl":[[4,0]],"id":62262930},{"atb":[[5.1,0]],"id":69577417},{"atl":[[12.5,6.96]],"id":69577417},{"atl":[[3.1,0]],"id":70003371}],"con":true,"img":false}]}
{"op":"mcm","clk":"11450567491","pt":1717323392973,"mc":[{"id":"1.229554921","rc":[{"atb":[[1.62,36.42]],"id":52671121},{"atl":[[4.2,21.13]],"id":62262930}],"con":true,"img":false}]}
{"op":"mcm","clk":"11450567502","pt":1717323393071,"mc":[{"id":"1.229554921","rc":[{"atl":[[5,2.5],[5.4,5]],"id":62262930}],"con":true,"img":false}]}
{"op":"mcm","clk":"11450567658","pt":1717323394281,"mc":[{"id":"1.229554921","rc":[{"atl":[[2.4,14.29]],"id":52671121},{"atl":[[2.7,11.76]],"id":65460404},{"atb":[[5.6,11.31],[5.9,4.08]],"id":64546979}],"con":true,"img":false}]}
{"op":"mcm","clk":"11450567667","pt":1717323394383,"mc":[{"id":"1.229554921","rc":[{"atl":[[2.42,23.17]],"id":52671121},{"atl":[[2.72,30.03]],"id":65460404}],"con":true,"img":false}]}
{"op":"mcm","clk":"11450567679","pt":1717323394488,"mc":[{"id":"1.229554921","rc":[{"atl":[[2.4,50.69]],"id":52671121},{"atl":[[2.7,41.89]],"id":65460404}],"con":true,"img":false}]}
{"op":"mcm","clk":"11450567691","pt":1717323394543,"mc":[{"id":"1.229554921","rc":[{"atl":[[2.42,0]],"id":52671121}],"con":true,"img":false}]}
{"op":"mcm","clk":"11450567708","pt":1717323394700,"mc":[{"id":"1.229554921","rc":[{"atl":[[2.72,0]],"id":65460404}],"con":true,"img":false}]}
{"op":"mcm","clk":"11450567919","pt":1717323396477,"mc":[{"id":"1.229554921","rc":[{"atl":[[2.4,36.4],[2.5,13.33]],"id":52671121},{"atl":[[2.78,11.24],[2.7,30.13]],"id":65460404}],"con":true,"img":false}]}
{"op":"mcm","clk":"11450567924","pt":1717323396577,"mc":[{"id":"1.229554921","rc":[{"atl":[[2.4,0]],"id":52671121},{"atl":[[2.7,0]],"id":65460404}],"con":true,"img":false}]}
{"op":"mcm","clk":"11450567935","pt":1717323396680,"mc":[{"id":"1.229554921","rc":[{"atl":[[3.35,2.5],[2.44,35.68],[3.55,5],[3.75,10]],"id":52671121},{"atl":[[2.74,29.74]],"id":65460404}],"con":true,"img":false}]}
{"op":"mcm","clk":"11450568029","pt":1717323397479,"mc":[{"id":"1.229554921","rc":[{"atb":[[1.6,10.53]],"id":65460404}],"con":true,"img":false}]}
{"op":"mcm","clk":"11450568191","pt":1717323398680,"mc":[{"id":"1.229554921","rc":[{"atb":[[1.6,58.07],[1.7,33.18]],"id":70003371},{"atl":[[6.6,0.09]],"id":70003371}],"con":true,"img":false}]}
{"op":"mcm","clk":"11450568257","pt":1717323399193,"mc":[{"id":"1.229554921","rc":[{"atl":[[2.46,0]],"id":52671121},{"atl":[[2.76,0]],"id":65460404}],"con":true,"img":false}]}
{"op":"mcm","clk":"11450568284","pt":1717323399415,"mc":[{"id":"1.229554921","rc":[{"atl":[[2.44,0]],"id":52671121},{"atl":[[2.74,0]],"id":65460404}],"con":true,"img":false}]}
{"op":"mcm","clk":"11450568308","pt":1717323399572,"mc":[{"id":"1.229554921","rc":[{"atl":[[2.48,36.76]],"id":52671121},{"atl":[[2.78,41.98]],"id":65460404}],"con":true,"img":false}]}
{"op":"mcm","clk":"11450568344","pt":1717323399877,"mc":[{"id":"1.229554921","rc":[{"atl":[[18,4.41]],"id":69577417}],"con":true,"img":false}]}
{"op":"mcm","clk":"11450568409","pt":1717323400359,"mc":[{"id":"1.229554921","rc":[{"atb":[[5,5.8],[5.2,0],[5.9,0],[5.4,0]],"id":64546979}],"con":true,"img":false}]}
