{"op":"mcm","clk":"11448127653","pt":1717286034988,"mc":[{"id":"1.229554916","marketDefinition":{"bspMarket":true,"turnInPlayEnabled":false,"persistenceEnabled":false,"marketBaseRate":7.0,"eventId":"33318908","eventTypeId":"4339","numberOfWinners":3,"bettingType":"ODDS","marketType":"PLACE","marketTime":"2024-06-02T10:03:00.000Z","suspendTime":"2024-06-02T10:03:00.000Z","bspReconciled":false,"complete":true,"inPlay":false,"crossMatching":true,"runnersVoidable":false,"numberOfActiveRunners":8,"betDelay":0,"status":"OPEN","runners":[{"status":"ACTIVE","sortPriority":1,"id":65293046,"name":"1. Beast Cut Loose"},{"status":"ACTIVE","sortPriority":2,"id":42099039,"name":"2. Thatll Do Neo"},{"status":"ACTIVE","sortPriority":3,"id":70003370,"name":"3. Ki Ki"},{"status":"ACTIVE","sortPriority":4,"id":56606596,"name":"4. Senna Wick"},{"status":"ACTIVE","sortPriority":5,"id":46292327,"name":"5. Immense"},{"status":"ACTIVE","sortPriority":6,"id":65788088,"name":"6. Bundy Baz"},{"status":"ACTIVE","sortPriority":7,"id":51562794,"name":"7. Chasing Boyd"},{"status":"ACTIVE","sortPriority":8,"id":64927898,"name":"8. Tilley Swamp"}],"regulators":["MR_INT"],"venue":"Murray Bridge","countryCode":"AU","discountAllowed":true,"timezone":"Australia/Adelaide","openDate":"2024-06-02T08:21:00.000Z","version":5962317648,"name":"To Be Placed","eventName":"Murray Bridge (AUS) 2nd Jun"},"rc":[],"con":true,"img":false}]}
{"op":"mcm","clk":"11448260604","pt":1717287908538,"mc":[{"id":"1.229554916","rc":[{"atb":[[1.82,42.49],[1.92,25.24]],"id":46292327},{"atl":[[8,0.07]],"id":46292327},{"spn":4.96,"spf":"NaN","id":46292327},{"atb":[[1.8,43.55],[1.9,25.8]],"id":65788088},{"atl":[[8,0.07]],"id":65788088},{"spn":4.95,"spf":"NaN","id":65788088},{"atb":[[1.41,56.65],[1.31,112.39]],"id":70003370},{"atl":[[4.1,0.16]],"id":70003370},{"spn":2.75,"spf":"NaN","id":70003370},{"atb":[[1.01,5807.26]],"id":65293046},{"atl":[[2.56,0.33]],"id":65293046},{"spn":1.78,"spf":"NaN","id":65293046},{"atb":[[1.01,5807.26]],"id":64927898},{"atl":[[2.3,0.4]],"id":64927898},{"spn":1.65,"spf":"NaN","id":64927898}],"con":true,"img":false}]}
{"op":"mcm","clk":"11448262192","pt":1717287930135,"mc":[{"id":"1.229554916","rc":[{"atb":[[1.82,0],[1.92,0]],"id":46292327},{"atl":[[8,0]],"id":46292327},{"atb":[[1.8,0],[1.9,0]],"id":65788088},{"atl":[[8,0]],"id":65788088},{"atb":[[1.41,0],[1.31,0]],"id":70003370},{"atl":[[4.1,0]],"id":70003370},{"atb":[[1.01,0]],"id":65293046},{"atl":[[2.56,0]],"id":65293046},{"atb":[[1.01,0]],"id":64927898},{"atl":[[2.3,0]],"id":64927898}],"con":true,"img":false}]}
{"op":"mcm","clk":"11448262804","pt":1717287939632,"mc":[{"id":"1.229554916","rc":[{"atb":[[4.3,7.03],[3.65,13.14]],"id":51562794},{"atb":[[2.32,17.59],[2.12,31.1]],"id":46292327},{"atl":[[10.5,0.05]],"id":46292327},{"atb":[[2.02,34.15],[2.22,19.03]],"id":56606596},{"atl":[[9.8,0.05]],"id":56606596},{"atb":[[2.32,17.59],[2.12,31.1]],"id":65788088},{"atl":[[10.5,0.05]],"id":65788088},{"atb":[[5.6,5.04],[4.6,9.67]],"id":42099039},{"atb":[[1.01,3484.35],[1.09,258.09]],"id":65293046},{"atl":[[2.9,0.27]],"id":65293046},{"atb":[[1.66,52.79],[1.76,30.56]],"id":70003370},{"atl":[[7,0.08]],"id":70003370},{"atb":[[1.01,5807.26]],"id":64927898},{"atl":[[2.52,0.34]],"id":64927898}],"con":true,"img":false}]}
{"op":"mcm","clk":"11448266392","pt":1717287995361,"mc":[{"id":"1.229554916","rc":[{"atb":[[4.3,0],[3.65,0]],"id":51562794},{"spn":"NaN","spf":"NaN","id":51562794},{"atb":[[2.32,0],[2.12,0]],"id":46292327},{"atl":[[10.5,0]],"id":46292327},{"spn":"NaN","spf":"NaN","id":46292327},{"atb":[[2.02,0],[2.22,0]],"id":56606596},{"atl":[[9.8,0]],"id":56606596},{"spn":"NaN","spf":"NaN","id":56606596},{"atb":[[2.32,0],[2.12,0]],"id":65788088},{"atl":[[10.5,0]],"id":65788088},{"spn":"NaN","spf":"NaN","id":65788088},{"atb":[[5.6,0],[4.6,0]],"id":42099039},{"spn":"NaN","spf":"NaN","id":42099039},{"atb":[[1.01,0],[1.09,0]],"id":65293046},{"atl":[[2.9,0]],"id":65293046},{"spn":"NaN","spf":"NaN","id":65293046},{"atb":[[1.66,0],[1.76,0]],"id":70003370},{"atl":[[7,0]],"id":70003370},{"spn":"NaN","spf":"NaN","id":70003370},{"atb":[[1.01,0]],"id":64927898},{"atl":[[2.52,0]],"id":64927898},{"spn":"NaN","spf":"NaN","id":64927898}],"con":true,"img":false}]}
{"op":"mcm","clk":"11448266886","pt":1717288003942,"mc":[{"id":"1.229554916","rc":[{"atb":[[3.7,12.9],[4.4,6.83]],"id":51562794},{"atb":[[2.28,18.14],[2.08,32.26]],"id":46292327},{"atl":[[10.5,0.05]],"id":46292327},{"atb":[[2.24,18.73],[2.04,33.5]],"id":56606596},{"atl":[[10,0.05]],"id":56606596},{"atb":[[2.38,16.83],[2.18,29.52]],"id":65788088},{"atl":[[11,0.05]],"id":65788088},{"atb":[[5.1,5.66],[4.1,11.23]],"id":42099039},{"atb":[[1.01,3484.35],[1.07,331.84]],"id":65293046},{"atl":[[2.88,0.27]],"id":65293046},{"atb":[[1.79,29.4],[1.69,50.49]],"id":70003370},{"atl":[[7.2,0.08]],"id":70003370},{"atb":[[1.01,5807.26]],"id":64927898},{"atl":[[2.48,0.35]],"id":64927898}],"con":true,"img":false}]}
{"op":"mcm","clk":"11448270147","pt":1717288057327,"mc":[{"id":"1.229554916","rc":[{"atb":[[3.7,0],[4.4,0]],"id":51562794},{"atb":[[2.28,0],[2.08,0]],"id":46292327},{"atl":[[10.5,0]],"id":46292327},{"atb":[[2.24,0],[2.04,0]],"id":56606596},{"atl":[[10,0]],"id":56606596},{"atb":[[2.38,0],[2.18,0]],"id":65788088},{"atl":[[11,0]],"id":65788088},{"atb":[[5.1,0],[4.1,0]],"id":42099039},{"atb":[[1.79,0],[1.69,0]],"id":70003370},{"atl":[[7.2,0]],"id":70003370},{"atb":[[1.01,0],[1.07,0]],"id":65293046},{"atl":[[2.88,0]],"id":65293046},{"atb":[[1.01,0]],"id":64927898},{"atl":[[2.48,0]],"id":64927898}],"con":true,"img":false}]}
{"op":"mcm","clk":"11448270978","pt":1717288067734,"mc":[{"id":"1.229554916","rc":[{"atb":[[3.7,12.9],[4.4,6.83]],"id":51562794},{"atb":[[2.14,30.56],[2.34,17.33]],"id":46292327},{"atl":[[10.5,0.05]],"id":46292327},{"atb":[[2.24,18.73],[2.04,33.5]],"id":56606596},{"atl":[[10,0.05]],"id":56606596},{"atb":[[2.38,16.83],[2.18,29.52]],"id":65788088},{"atl":[[11,0.05]],"id":65788088},{"atb":[[4.8,6.11],[3.9,12.01]],"id":42099039},{"atb":[[1.01,3484.35],[1.07,331.84]],"id":65293046},{"atl":[[2.88,0.27]],"id":65293046},{"atb":[[1.84,27.65],[1.74,47.08]],"id":70003370},{"atl":[[7.6,0.07]],"id":70003370},{"atb":[[1.01,5807.26]],"id":64927898},{"atl":[[2.42,0.36]],"id":64927898}],"con":true,"img":false}]}
{"op":"mcm","clk":"11448277245","pt":1717288128429,"mc":[{"id":"1.229554916","marketDefinition":{"bspMarket":true,"turnInPlayEnabled":false,"persistenceEnabled":false,"marketBaseRate":7.0,"eventId":"33318908","eventTypeId":"4339","numberOfWinners":3,"bettingType":"ODDS","marketType":"PLACE","marketTime":"2024-06-02T10:03:00.000Z","suspendTime":"2024-06-02T10:03:00.000Z","bspReconciled":false,"complete":true,"inPlay":false,"crossMatching":true,"runnersVoidable":false,"numberOfActiveRunners":8,"betDelay":0,"status":"OPEN","runners":[{"status":"ACTIVE","sortPriority":1,"id":65293046,"name":"1. Beast Cut Loose"},{"status":"ACTIVE","sortPriority":2,"id":42099039,"name":"2. Thatll Do Neo"},{"status":"ACTIVE","sortPriority":3,"id":70003370,"name":"3. Ki Ki"},{"status":"ACTIVE","sortPriority":4,"id":56606596,"name":"4. Senna Wick"},{"status":"ACTIVE","sortPriority":5,"id":46292327,"name":"5. Immense"},{"status":"ACTIVE","sortPriority":6,"id":65788088,"name":"6. Bundy Baz"},{"status":"ACTIVE","sortPriority":7,"id":51562794,"name":"7. Chasing Boyd"},{"status":"ACTIVE","sortPriority":8,"id":64927898,"name":"8. Tilley Swamp"}],"regulators":["MR_INT"],"venue":"Murray Bridge","countryCode":"AU","discountAllowed":true,"timezone":"Australia/Adelaide","openDate":"2024-06-02T08:21:00.000Z","version":5962317648,"name":"To Be Placed","eventName":"Murray Bridge (AUS) 2nd Jun"},"rc":[{"atb":[[3.7,12.9],[4.4,6.83]],"id":51562794},{"spn":"Infinity","spf":"NaN","id":51562794},{"atb":[[2.14,30.56],[2.34,17.33]],"id":46292327},{"atl":[[10.5,0.05]],"id":46292327},{"spn":6.42,"spf":"NaN","id":46292327},{"atb":[[2.24,18.73],[2.04,33.5]],"id":56606596},{"atl":[[10,0.05]],"id":56606596},{"spn":6.12,"spf":"NaN","id":56606596},{"atb":[[2.38,16.83],[2.18,29.52]],"id":65788088},{"atl":[[11,0.05]],"id":65788088},{"spn":6.69,"spf":"NaN","id":65788088},{"atb":[[4.8,6.11],[3.9,12.01]],"id":42099039},{"spn":"Infinity","spf":"NaN","id":42099039},{"atb":[[1.84,27.65],[1.74,47.08]],"id":70003370},{"atl":[[7.6,0.07]],"id":70003370},{"spn":4.72,"spf":"NaN","id":70003370},{"atb":[[1.01,3484.35],[1.07,331.84]],"id":65293046},{"atl":[[2.88,0.27]],"id":65293046},{"spn":1.97,"spf":"NaN","id":65293046},{"atb":[[1.01,5807.26]],"id":64927898},{"atl":[[2.42,0.36]],"id":64927898},{"spn":1.71,"spf":"NaN","id":64927898}],"con":true,"img":true}]}
{"op":"mcm","clk":"11448292472","pt":1717288274058,"mc":[{"id":"1.229554916","rc":[{"atb":[[3.7,0],[4.4,0]],"id":51562794},{"atb":[[2.14,0],[2.34,0]],"id":46292327},{"atl":[[10.5,0]],"id":46292327},{"atb":[[2.24,0],[2.04,0]],"id":56606596},{"atl":[[10,0]],"id":56606596},{"atb":[[2.38,0],[2.18,0]],"id":65788088},{"atl":[[11,0]],"id":65788088},{"atb":[[4.8,0],[3.9,0]],"id":42099039},{"atb":[[1.84,0],[1.74,0]],"id":70003370},{"atl":[[7.6,0]],"id":70003370},{"atb":[[1.01,0],[1.07,0]],"id":65293046},{"atl":[[2.88,0]],"id":65293046},{"atb":[[1.01,0]],"id":64927898},{"atl":[[2.42,0]],"id":64927898}],"con":true,"img":false}]}
{"op":"mcm","clk":"11448300795","pt":1717288383947,"mc":[{"id":"1.229554916","rc":[{"atb":[[3.6,13.4],[4.2,7.26]],"id":51562794},{"spn":"Infinity","spf":"NaN","id":51562794},{"atb":[[1.01,3484.35],[1.09,258.09]],"id":65293046},{"atl":[[2.9,0.27]],"id":65293046},{"spn":1.99,"spf":"NaN","id":65293046}],"con":true,"img":false}]}
{"op":"mcm","clk":"11448317707","pt":1717288629759,"mc":[{"id":"1.229554916","rc":[{"atb":[[3.6,0],[4.2,0]],"id":51562794},{"spn":"NaN","spf":"NaN","id":51562794},{"atb":[[1.01,0],[1.09,0]],"id":65293046},{"atl":[[2.9,0]],"id":65293046},{"spn":"NaN","spf":"NaN","id":65293046}],"con":true,"img":false}]}
{"op":"mcm","clk":"11448323056","pt":1717288701352,"mc":[{"id":"1.229554916","rc":[{"atb":[[3.95,11.81],[4.9,5.95]],"id":51562794},{"spn":"Infinity","spf":"NaN","id":51562794},{"atb":[[1.64,36.29],[1.54,64.52]],"id":46292327},{"atl":[[6,0.1]],"id":46292327},{"spn":3.82,"spf":"NaN","id":46292327},{"atb":[[2.36,17.08],[2.16,30.03]],"id":56606596},{"atl":[[11,0.05]],"id":56606596},{"spn":6.68,"spf":"NaN","id":56606596},{"atb":[[2.54,15.08],[2.34,26]],"id":65788088},{"atl":[[15,0.03]],"id":65788088},{"spn":8.77,"spf":"NaN","id":65788088},{"atb":[[6.8,4],[5.4,7.92]],"id":42099039},{"spn":"Infinity","spf":"NaN","id":42099039},{"atb":[[1.14,165.92],[1.04,871.08]],"id":65293046},{"atl":[[2.94,0.27]],"id":65293046},{"spn":2.04,"spf":"NaN","id":65293046},{"atb":[[1.97,23.94],[1.87,40.04]],"id":70003370},{"atl":[[8.4,0.07]],"id":70003370},{"spn":5.18,"spf":"NaN","id":70003370},{"atb":[[1.01,5807.26]],"id":64927898},{"atl":[[2.46,0.35]],"id":64927898},{"spn":1.73,"spf":"NaN","id":64927898}],"con":true,"img":false}]}
{"op":"mcm","clk":"11448325043","pt":1717288727655,"mc":[{"id":"1.229554916","rc":[{"atb":[[1.64,0],[1.54,0]],"id":46292327},{"atl":[[6,0]],"id":46292327},{"atb":[[6.8,0],[5.4,0]],"id":42099039},{"atb":[[1.14,0],[1.04,0]],"id":65293046},{"atl":[[2.94,0]],"id":65293046}],"con":true,"img":false}]}
{"op":"mcm","clk":"11448326201","pt":1717288744502,"mc":[{"id":"1.229554916","rc":[{"atb":[[1.51,68.32],[1.61,38.08]],"id":46292327},{"atl":[[5.7,0.1]],"id":46292327},{"atb":[[7.8,3.41],[5.9,7.1]],"id":42099039},{"atb":[[1.07,497.76],[1.17,136.64]],"id":65293046},{"atl":[[3,0.26]],"id":65293046}],"con":true,"img":false}]}
{"op":"mcm","clk":"11448327939","pt":1717288767617,"mc":[{"id":"1.229554916","rc":[{"atb":[[3.95,0],[4.9,0]],"id":51562794},{"spn":"NaN","spf":"NaN","id":51562794},{"atb":[[1.51,0],[1.61,0]],"id":46292327},{"atl":[[5.7,0]],"id":46292327},{"spn":"NaN","spf":"NaN","id":46292327},{"atb":[[2.54,0],[2.34,0]],"id":65788088},{"atl":[[15,0]],"id":65788088},{"spn":"NaN","spf":"NaN","id":65788088},{"spn":2.08,"spf":"NaN","id":65293046}],"con":true,"img":false}]}
{"op":"mcm","clk":"11448328753","pt":1717288778134,"mc":[{"id":"1.229554916","rc":[{"atb":[[3.85,12.22],[4.7,6.27]],"id":51562794},{"atb":[[1.51,68.32],[1.61,38.08]],"id":46292327},{"atl":[[5.7,0.1]],"id":46292327},{"atb":[[2.28,27.22],[2.48,15.69]],"id":65788088},{"atl":[[13.5,0.04]],"id":65788088}],"con":true,"img":false}]}
{"op":"mcm","clk":"11448494247","pt":1717291211930,"mc":[{"id":"1.229554916","rc":[{"atb":[[3.85,0],[4.7,0]],"id":51562794},{"atb":[[1.51,0],[1.61,0]],"id":46292327},{"atl":[[5.7,0]],"id":46292327},{"atb":[[2.36,0],[2.16,0]],"id":56606596},{"atl":[[11,0]],"id":56606596},{"spn":"NaN","spf":"NaN","id":56606596},{"atb":[[2.28,0],[2.48,0]],"id":65788088},{"atl":[[13.5,0]],"id":65788088},{"atb":[[7.8,0],[5.9,0]],"id":42099039},{"spn":"NaN","spf":"NaN","id":42099039},{"atb":[[1.97,0],[1.87,0]],"id":70003370},{"atl":[[8.4,0]],"id":70003370},{"spn":"NaN","spf":"NaN","id":70003370},{"atb":[[1.01,0]],"id":64927898},{"atl":[[2.46,0]],"id":64927898},{"spn":"NaN","spf":"NaN","id":64927898}],"con":true,"img":false}]}
{"op":"mcm","clk":"11448494993","pt":1717291222496,"mc":[{"id":"1.229554916","rc":[{"atb":[[4.8,6.11],[3.9,12.01]],"id":51562794},{"atb":[[1.64,36.29],[1.54,64.52]],"id":46292327},{"atl":[[6,0.1]],"id":46292327},{"atb":[[2.36,17.08],[2.16,30.03]],"id":56606596},{"atl":[[11,0.05]],"id":56606596},{"atb":[[2.46,15.9],[2.26,27.65]],"id":65788088},{"atl":[[12.5,0.04]],"id":65788088},{"atb":[[5.8,7.26],[7.6,3.52]],"id":42099039},{"atb":[[1.85,40.99],[1.95,24.45]],"id":70003370},{"atl":[[8.2,0.07]],"id":70003370},{"atb":[[1.01,5807.26]],"id":64927898},{"atl":[[2.46,0.35]],"id":64927898}],"con":true,"img":false}]}
{"op":"mcm","clk":"11448629977","pt":1717293528419,"mc":[{"id":"1.229554916","marketDefinition":{"bspMarket":true,"turnInPlayEnabled":false,"persistenceEnabled":false,"marketBaseRate":7.0,"eventId":"33318908","eventTypeId":"4339","numberOfWinners":3,"bettingType":"ODDS","marketType":"PLACE","marketTime":"2024-06-02T10:03:00.000Z","suspendTime":"2024-06-02T10:03:00.000Z","bspReconciled":false,"complete":true,"inPlay":false,"crossMatching":true,"runnersVoidable":false,"numberOfActiveRunners":8,"betDelay":0,"status":"OPEN","runners":[{"status":"ACTIVE","sortPriority":1,"id":65293046,"name":"1. Beast Cut Loose"},{"status":"ACTIVE","sortPriority":2,"id":42099039,"name":"2. Thatll Do Neo"},{"status":"ACTIVE","sortPriority":3,"id":70003370,"name":"3. Ki Ki"},{"status":"ACTIVE","sortPriority":4,"id":56606596,"name":"4. Senna Wick"},{"status":"ACTIVE","sortPriority":5,"id":46292327,"name":"5. Immense"},{"status":"ACTIVE","sortPriority":6,"id":65788088,"name":"6. Bundy Baz"},{"status":"ACTIVE","sortPriority":7,"id":51562794,"name":"7. Chasing Boyd"},{"status":"ACTIVE","sortPriority":8,"id":64927898,"name":"8. Tilley Swamp"}],"regulators":["MR_INT"],"venue":"Murray Bridge","countryCode":"AU","discountAllowed":true,"timezone":"Australia/Adelaide","openDate":"2024-06-02T08:21:00.000Z","version":5962317648,"name":"To Be Placed","eventName":"Murray Bridge (AUS) 2nd Jun"},"rc":[{"atb":[[4.8,6.11],[3.9,12.01]],"id":51562794},{"spn":"Infinity","spf":"NaN","id":51562794},{"atb":[[1.64,36.29],[1.54,64.52]],"id":46292327},{"atl":[[6,0.1]],"id":46292327},{"spn":3.82,"spf":"NaN","id":46292327},{"atb":[[2.36,17.08],[2.16,30.03]],"id":56606596},{"atl":[[11,0.05]],"id":56606596},{"spn":6.68,"spf":"NaN","id":56606596},{"atb":[[2.46,15.9],[2.26,27.65]],"id":65788088},{"atl":[[12.5,0.04]],"id":65788088},{"spn":7.48,"spf":"NaN","id":65788088},{"atb":[[5.8,7.26],[7.6,3.52]],"id":42099039},{"spn":"Infinity","spf":"NaN","id":42099039},{"atb":[[1.85,40.99],[1.95,24.45]],"id":70003370},{"atl":[[8.2,0.07]],"id":70003370},{"spn":5.07,"spf":"NaN","id":70003370},{"atb":[[1.07,497.76],[1.17,136.64]],"id":65293046},{"atl":[[3,0.26]],"id":65293046},{"spn":2.08,"spf":"NaN","id":65293046},{"atb":[[1.01,5807.26]],"id":64927898},{"atl":[[2.46,0.35]],"id":64927898},{"spn":1.73,"spf":"NaN","id":64927898}],"con":true,"img":true}]}
{"op":"mcm","clk":"11449377567","pt":1717308263185,"mc":[{"id":"1.229554916","rc":[{"atb":[[4.8,0],[3.9,0]],"id":51562794},{"spn":3.82,"spf":"NaN","id":46292327},{"atb":[[2.36,0],[2.16,0]],"id":56606596},{"atl":[[11,0]],"id":56606596},{"spn":7.48,"spf":"NaN","id":65788088},{"spn":"Infinity","spf":"NaN","id":42099039},{"atb":[[1.85,0],[1.95,0]],"id":70003370},{"atl":[[8.2,0]],"id":70003370},{"atb":[[1.07,0],[1.17,0]],"id":65293046},{"atl":[[3,0]],"id":65293046},{"spn":"NaN","spf":"NaN","id":65293046},{"atb":[[1.01,0]],"id":64927898},{"atl":[[2.46,0]],"id":64927898}],"con":true,"img":false}]}
{"op":"mcm","clk":"11449380116","pt":1717308306835,"mc":[{"id":"1.229554916","rc":[{"atb":[[4,11.61],[5,5.8]],"id":51562794},{"atb":[[2.36,17.08],[2.16,30.03]],"id":56606596},{"atl":[[11,0.05]],"id":56606596},{"atb":[[1.18,129.05],[1.08,435.54]],"id":65293046},{"atl":[[3,0.26]],"id":65293046},{"atb":[[1.83,41.97],[1.93,24.97]],"id":70003370},{"atl":[[8.2,0.07]],"id":70003370},{"atb":[[1.01,5807.26]],"id":64927898},{"atl":[[2.44,0.36]],"id":64927898}],"con":true,"img":false}]}
{"op":"mcm","clk":"11449383812","pt":1717308364817,"mc":[{"id":"1.229554916","rc":[{"atb":[[4,0],[5,0]],"id":51562794},{"atb":[[1.64,0],[1.54,0]],"id":46292327},{"atl":[[6,0]],"id":46292327},{"spn":"NaN","spf":"NaN","id":46292327},{"atb":[[2.36,0],[2.16,0]],"id":56606596},{"atl":[[11,0]],"id":56606596},{"atb":[[2.46,0],[2.26,0]],"id":65788088},{"atl":[[12.5,0]],"id":65788088},{"spn":"NaN","spf":"NaN","id":65788088},{"atb":[[1.83,0],[1.93,0]],"id":70003370},{"atl":[[8.2,0]],"id":70003370},{"atb":[[1.18,0],[1.08,0]],"id":65293046},{"atl":[[3,0]],"id":65293046},{"atb":[[1.01,0]],"id":64927898},{"atl":[[2.44,0]],"id":64927898}],"con":true,"img":false}]}
{"op":"mcm","clk":"11449385225","pt":1717308387157,"mc":[{"id":"1.229554916","rc":[{"atb":[[3.95,11.81],[4.9,5.95]],"id":51562794},{"atb":[[1.6,38.71],[1.5,69.68]],"id":46292327},{"atl":[[5.6,0.11]],"id":46292327},{"atb":[[2.24,28.09],[2.44,16.12]],"id":56606596},{"atl":[[12,0.04]],"id":56606596},{"atb":[[2.42,24.53],[2.62,14.34]],"id":65788088},{"atl":[[17,0.03]],"id":65788088},{"atb":[[2,23.22],[1.9,38.71]],"id":70003370},{"atl":[[8.6,0.06]],"id":70003370},{"atb":[[1.03,1161.45],[1.13,178.68]],"id":65293046},{"atl":[[2.94,0.27]],"id":65293046},{"atb":[[1.01,5807.26]],"id":64927898},{"atl":[[2.4,0.37]],"id":64927898}],"con":true,"img":false}]}
{"op":"mcm","clk":"11449480366","pt":1717309728420,"mc":[{"id":"1.229554916","marketDefinition":{"bspMarket":true,"turnInPlayEnabled":false,"persistenceEnabled":false,"marketBaseRate":7.0,"eventId":"33318908","eventTypeId":"4339","numberOfWinners":3,"bettingType":"ODDS","marketType":"PLACE","marketTime":"2024-06-02T10:03:00.000Z","suspendTime":"2024-06-02T10:03:00.000Z","bspReconciled":false,"complete":true,"inPlay":false,"crossMatching":true,"runnersVoidable":false,"numberOfActiveRunners":8,"betDelay":0,"status":"OPEN","runners":[{"status":"ACTIVE","sortPriority":1,"id":65293046,"name":"1. Beast Cut Loose"},{"status":"ACTIVE","sortPriority":2,"id":42099039,"name":"2. Thatll Do Neo"},{"status":"ACTIVE","sortPriority":3,"id":70003370,"name":"3. Ki Ki"},{"status":"ACTIVE","sortPriority":4,"id":56606596,"name":"4. Senna Wick"},{"status":"ACTIVE","sortPriority":5,"id":46292327,"name":"5. Immense"},{"status":"ACTIVE","sortPriority":6,"id":65788088,"name":"6. Bundy Baz"},{"status":"ACTIVE","sortPriority":7,"id":51562794,"name":"7. Chasing Boyd"},{"status":"ACTIVE","sortPriority":8,"id":64927898,"name":"8. Tilley Swamp"}],"regulators":["MR_INT"],"venue":"Murray Bridge","countryCode":"AU","discountAllowed":true,"timezone":"Australia/Adelaide","openDate":"2024-06-02T08:21:00.000Z","version":5962317648,"name":"To Be Placed","eventName":"Murray Bridge (AUS) 2nd Jun"},"rc":[{"atb":[[3.95,11.81],[4.9,5.95]],"id":51562794},{"spn":"Infinity","spf":"NaN","id":51562794},{"atb":[[1.6,38.71],[1.5,69.68]],"id":46292327},{"atl":[[5.6,0.11]],"id":46292327},{"spn":3.6,"spf":"NaN","id":46292327},{"atb":[[2.24,28.09],[2.44,16.12]],"id":56606596},{"atl":[[12,0.04]],"id":56606596},{"spn":7.22,"spf":"NaN","id":56606596},{"atb":[[2.42,24.53],[2.62,14.34]],"id":65788088},{"atl":[[17,0.03]],"id":65788088},{"spn":9.81,"spf":"NaN","id":65788088},{"atb":[[5.8,7.26],[7.6,3.52]],"id":42099039},{"spn":"Infinity","spf":"NaN","id":42099039},{"atb":[[2,23.22],[1.9,38.71]],"id":70003370},{"atl":[[8.6,0.06]],"id":70003370},{"spn":5.3,"spf":"NaN","id":70003370},{"atb":[[1.03,1161.45],[1.13,178.68]],"id":65293046},{"atl":[[2.94,0.27]],"id":65293046},{"spn":2.03,"spf":"NaN","id":65293046},{"atb":[[1.01,5807.26]],"id":64927898},{"atl":[[2.4,0.37]],"id":64927898},{"spn":1.7,"spf":"NaN","id":64927898}],"con":true,"img":true}]}
{"op":"mcm","clk":"11449546546","pt":1717310732834,"mc":[{"id":"1.229554916","rc":[{"atb":[[3.95,0],[4.9,0]],"id":51562794},{"atb":[[1.6,0],[1.5,0]],"id":46292327},{"atl":[[5.6,0]],"id":46292327},{"spn":7.22,"spf":"NaN","id":56606596},{"atb":[[2.42,0],[2.62,0]],"id":65788088},{"atl":[[17,0]],"id":65788088},{"atb":[[2,0],[1.9,0]],"id":70003370},{"atl":[[8.6,0]],"id":70003370},{"atb":[[1.03,0],[1.13,0]],"id":65293046},{"atl":[[2.94,0]],"id":65293046},{"atb":[[1.01,0]],"id":64927898},{"atl":[[2.4,0]],"id":64927898}],"con":true,"img":false}]}
{"op":"mcm","clk":"11449550487","pt":1717310796983,"mc":[{"id":"1.229554916","rc":[{"atb":[[5.8,0],[7.6,0]],"id":42099039},{"spn":"NaN","spf":"NaN","id":42099039}],"con":true,"img":false}]}
{"op":"mcm","clk":"11449552522","pt":1717310833683,"mc":[{"id":"1.229554916","rc":[{"atb":[[5.1,5.66],[4.1,11.23]],"id":51562794},{"atb":[[1.6,38.71],[1.5,69.68]],"id":46292327},{"atl":[[5.6,0.11]],"id":46292327},{"atb":[[2.4,24.88],[2.6,14.51]],"id":65788088},{"atl":[[16.5,0.03]],"id":65788088},{"atb":[[5.5,7.74],[7,3.87]],"id":42099039},{"atb":[[1.83,41.97],[1.93,24.97]],"id":70003370},{"atl":[[8.2,0.07]],"id":70003370},{"atb":[[1.01,5807.26]],"id":64927898},{"atl":[[2.4,0.37]],"id":64927898}],"con":true,"img":false}]}
{"op":"mcm","clk":"11449609361","pt":1717311864504,"mc":[{"id":"1.229554916","rc":[{"atb":[[5.1,0],[4.1,0]],"id":51562794},{"atb":[[1.6,0],[1.5,0]],"id":46292327},{"atl":[[5.6,0]],"id":46292327},{"atb":[[2.24,0],[2.44,0]],"id":56606596},{"atl":[[12,0]],"id":56606596},{"spn":"NaN","spf":"NaN","id":56606596},{"atb":[[2.4,0],[2.6,0]],"id":65788088},{"atl":[[16.5,0]],"id":65788088},{"atb":[[5.5,0],[7,0]],"id":42099039},{"atb":[[1.83,0],[1.93,0]],"id":70003370},{"atl":[[8.2,0]],"id":70003370},{"atb":[[1.01,0]],"id":64927898},{"atl":[[2.4,0]],"id":64927898}],"con":true,"img":false}]}
{"op":"mcm","clk":"11449610109","pt":1717311877450,"mc":[{"id":"1.229554916","rc":[{"atb":[[3.85,12.22],[4.7,6.27]],"id":51562794},{"atb":[[1.51,68.32],[1.61,38.08]],"id":46292327},{"atl":[[5.7,0.1]],"id":46292327},{"atb":[[2.54,15.08],[2.34,26]],"id":56606596},{"atl":[[15,0.03]],"id":56606596},{"atb":[[2.4,24.88],[2.6,14.51]],"id":65788088},{"atl":[[16.5,0.03]],"id":65788088},{"atb":[[5.5,7.74],[7,3.87]],"id":42099039},{"atb":[[1.79,44.1],[1.89,26.1]],"id":70003370},{"atl":[[7.8,0.07]],"id":70003370},{"atb":[[1.07,497.76],[1.17,136.64]],"id":65293046},{"atl":[[3,0.26]],"id":65293046},{"atb":[[1.01,5807.26]],"id":64927898},{"atl":[[2.4,0.37]],"id":64927898}],"con":true,"img":false}]}
{"op":"mcm","clk":"11449614850","pt":1717311962244,"mc":[{"id":"1.229554916","rc":[{"spn":"Infinity","spf":"NaN","id":51562794},{"spn":3.65,"spf":"NaN","id":46292327},{"spn":8.77,"spf":"NaN","id":56606596},{"spn":9.55,"spf":"NaN","id":65788088},{"spn":"Infinity","spf":"NaN","id":42099039},{"atb":[[1.07,0],[1.17,0]],"id":65293046},{"atl":[[3,0]],"id":65293046},{"spn":4.84,"spf":"NaN","id":70003370},{"spn":1.7,"spf":"NaN","id":64927898}],"con":true,"img":false}]}
{"op":"mcm","clk":"11449615556","pt":1717311975906,"mc":[{"id":"1.229554916","rc":[{"atb":[[1.07,497.76],[1.17,136.64]],"id":65293046},{"atl":[[3,0.26]],"id":65293046}],"con":true,"img":false}]}
{"op":"mcm","clk":"11449655964","pt":1717312955983,"mc":[{"id":"1.229554916","rc":[{"atb":[[3.85,0],[4.7,0]],"id":51562794},{"spn":"NaN","spf":"NaN","id":51562794},{"atb":[[1.51,0],[1.61,0]],"id":46292327},{"atl":[[5.7,0]],"id":46292327},{"spn":"NaN","spf":"NaN","id":46292327},{"atb":[[2.54,0],[2.34,0]],"id":56606596},{"atl":[[15,0]],"id":56606596},{"spn":"NaN","spf":"NaN","id":56606596},{"atb":[[2.4,0],[2.6,0]],"id":65788088},{"atl":[[16.5,0]],"id":65788088},{"spn":"NaN","spf":"NaN","id":65788088},{"atb":[[5.5,0],[7,0]],"id":42099039},{"spn":"NaN","spf":"NaN","id":42099039},{"atb":[[1.07,0],[1.17,0]],"id":65293046},{"atl":[[3,0]],"id":65293046},{"atb":[[1.79,0],[1.89,0]],"id":70003370},{"atl":[[7.8,0]],"id":70003370},{"spn":"NaN","spf":"NaN","id":70003370},{"atb":[[1.01,0]],"id":64927898},{"atl":[[2.4,0]],"id":64927898},{"spn":"NaN","spf":"NaN","id":64927898}],"con":true,"img":false}]}
{"op":"mcm","clk":"11449738237","pt":1717314113455,"mc":[{"id":"1.229554916","rc":[{"atb":[[3.85,12.22],[4.7,6.27]],"id":51562794},{"spn":"Infinity","spf":"NaN","id":51562794},{"atb":[[1.6,38.71],[1.5,69.68]],"id":46292327},{"atl":[[5.6,0.11]],"id":46292327},{"spn":3.6,"spf":"NaN","id":46292327},{"atb":[[2.42,16.35],[2.22,28.56]],"id":56606596},{"atl":[[11.5,0.05]],"id":56606596},{"spn":6.96,"spf":"NaN","id":56606596},{"atb":[[2.4,24.88],[2.6,14.51]],"id":65788088},{"atl":[[16.5,0.03]],"id":65788088},{"spn":9.55,"spf":"NaN","id":65788088},{"atb":[[5.6,7.57],[7.2,3.74]],"id":42099039},{"spn":"Infinity","spf":"NaN","id":42099039},{"atb":[[1.2,116.14],[1.1,348.43]],"id":65293046},{"atl":[[3.05,0.25]],"id":65293046},{"spn":2.12,"spf":"NaN","id":65293046},{"atb":[[1.97,23.94],[1.87,40.04]],"id":70003370},{"atl":[[8.4,0.07]],"id":70003370},{"spn":5.18,"spf":"NaN","id":70003370},{"atb":[[1.01,5807.26]],"id":64927898},{"atl":[[2.4,0.37]],"id":64927898},{"spn":1.7,"spf":"NaN","id":64927898}],"con":true,"img":false}]}
{"op":"mcm","clk":"11449745188","pt":1717314192134,"mc":[{"id":"1.229554916","rc":[{"atb":[[3.85,0],[4.7,0]],"id":51562794},{"spn":"NaN","spf":"NaN","id":51562794},{"atb":[[1.6,0],[1.5,0]],"id":46292327},{"atl":[[5.6,0]],"id":46292327},{"spn":"NaN","spf":"NaN","id":46292327},{"atb":[[2.42,0],[2.22,0]],"id":56606596},{"atl":[[11.5,0]],"id":56606596},{"spn":"NaN","spf":"NaN","id":56606596},{"atb":[[2.4,0],[2.6,0]],"id":65788088},{"atl":[[16.5,0]],"id":65788088},{"spn":"NaN","spf":"NaN","id":65788088},{"atb":[[5.6,0],[7.2,0]],"id":42099039},{"spn":"NaN","spf":"NaN","id":42099039},{"atb":[[1.97,0],[1.87,0]],"id":70003370},{"atl":[[8.4,0]],"id":70003370},{"spn":"NaN","spf":"NaN","id":70003370},{"atb":[[1.2,0],[1.1,0]],"id":65293046},{"atl":[[3.05,0]],"id":65293046},{"spn":"NaN","spf":"NaN","id":65293046},{"atb":[[1.01,0]],"id":64927898},{"atl":[[2.4,0]],"id":64927898},{"spn":"NaN","spf":"NaN","id":64927898}],"con":true,"img":false}]}
{"op":"mcm","clk":"11449746551","pt":1717314206858,"mc":[{"id":"1.229554916","rc":[{"atb":[[3.95,11.81],[4.9,5.95]],"id":51562794},{"atb":[[1.59,39.36],[1.49,71.11]],"id":46292327},{"atl":[[5.5,0.11]],"id":46292327},{"atb":[[2.5,15.48],[2.3,26.8]],"id":56606596},{"atl":[[14,0.04]],"id":56606596},{"atb":[[2.54,15.08],[2.34,26]],"id":65788088},{"atl":[[15,0.03]],"id":65788088},{"atb":[[7.8,3.41],[5.9,7.1]],"id":42099039},{"atb":[[1.2,116.14],[1.1,348.43]],"id":65293046},{"atl":[[3.05,0.25]],"id":65293046},{"atb":[[1.81,43.01],[1.91,25.52]],"id":70003370},{"atl":[[8,0.07]],"id":70003370},{"atb":[[1.01,5807.26]],"id":64927898},{"atl":[[2.4,0.37]],"id":64927898}],"con":true,"img":false}]}
{"op":"mcm","clk":"11449830310","pt":1717315128433,"mc":[{"id":"1.229554916","marketDefinition":{"bspMarket":true,"turnInPlayEnabled":false,"persistenceEnabled":false,"marketBaseRate":7.0,"eventId":"33318908","eventTypeId":"4339","numberOfWinners":3,"bettingType":"ODDS","marketType":"PLACE","marketTime":"2024-06-02T10:03:00.000Z","suspendTime":"2024-06-02T10:03:00.000Z","bspReconciled":false,"complete":true,"inPlay":false,"crossMatching":true,"runnersVoidable":false,"numberOfActiveRunners":8,"betDelay":0,"status":"OPEN","runners":[{"status":"ACTIVE","sortPriority":1,"id":65293046,"name":"1. Beast Cut Loose"},{"status":"ACTIVE","sortPriority":2,"id":42099039,"name":"2. Thatll Do Neo"},{"status":"ACTIVE","sortPriority":3,"id":70003370,"name":"3. Ki Ki"},{"status":"ACTIVE","sortPriority":4,"id":56606596,"name":"4. Senna Wick"},{"status":"ACTIVE","sortPriority":5,"id":46292327,"name":"5. Immense"},{"status":"ACTIVE","sortPriority":6,"id":65788088,"name":"6. Bundy Baz"},{"status":"ACTIVE","sortPriority":7,"id":51562794,"name":"7. Chasing Boyd"},{"status":"ACTIVE","sortPriority":8,"id":64927898,"name":"8. Tilley Swamp"}],"regulators":["MR_INT"],"venue":"Murray Bridge","countryCode":"AU","discountAllowed":true,"timezone":"Australia/Adelaide","openDate":"2024-06-02T08:21:00.000Z","version":5962317648,"name":"To Be Placed","eventName":"Murray Bridge (AUS) 2nd Jun"},"rc":[{"atb":[[3.95,11.81],[4.9,5.95]],"id":51562794},{"spn":"Infinity","spf":"NaN","id":51562794},{"atb":[[1.59,39.36],[1.49,71.11]],"id":46292327},{"atl":[[5.5,0.11]],"id":46292327},{"spn":3.54,"spf":"NaN","id":46292327},{"atb":[[2.5,15.48],[2.3,26.8]],"id":56606596},{"atl":[[14,0.04]],"id":56606596},{"spn":8.25,"spf":"NaN","id":56606596},{"atb":[[2.54,15.08],[2.34,26]],"id":65788088},{"atl":[[15,0.03]],"id":65788088},{"spn":8.77,"spf":"NaN","id":65788088},{"atb":[[7.8,3.41],[5.9,7.1]],"id":42099039},{"spn":"Infinity","spf":"NaN","id":42099039},{"atb":[[1.2,116.14],[1.1,348.43]],"id":65293046},{"atl":[[3.05,0.25]],"id":65293046},{"spn":2.12,"spf":"NaN","id":65293046},{"atb":[[1.81,43.01],[1.91,25.52]],"id":70003370},{"atl":[[8,0.07]],"id":70003370},{"spn":4.95,"spf":"NaN","id":70003370},{"atb":[[1.01,5807.26]],"id":64927898},{"atl":[[2.4,0.37]],"id":64927898},{"spn":1.7,"spf":"NaN","id":64927898}],"con":true,"img":true}]}
{"op":"mcm","clk":"11449837934","pt":1717315161128,"mc":[{"id":"1.229554916","rc":[{"atb":[[3.95,0],[4.9,0]],"id":51562794},{"spn":"Infinity","spf":"NaN","id":51562794},{"atb":[[1.59,0],[1.49,0]],"id":46292327},{"atl":[[5.5,0]],"id":46292327},{"spn":3.54,"spf":"NaN","id":46292327},{"atb":[[2.5,0],[2.3,0]],"id":56606596},{"atl":[[14,0]],"id":56606596},{"spn":8.25,"spf":"NaN","id":56606596},{"atb":[[2.54,0],[2.34,0]],"id":65788088},{"atl":[[15,0]],"id":65788088},{"spn":8.77,"spf":"NaN","id":65788088},{"atb":[[7.8,0],[5.9,0]],"id":42099039},{"spn":"Infinity","spf":"NaN","id":42099039},{"atb":[[1.2,0],[1.1,0]],"id":65293046},{"atl":[[3.05,0]],"id":65293046},{"spn":2.12,"spf":"NaN","id":65293046},{"atb":[[1.81,0],[1.91,0]],"id":70003370},{"atl":[[8,0]],"id":70003370},{"spn":4.95,"spf":"NaN","id":70003370},{"atb":[[1.01,0]],"id":64927898},{"atl":[[2.4,0]],"id":64927898},{"spn":1.7,"spf":"NaN","id":64927898}],"con":true,"img":false}]}
{"op":"mcm","clk":"11449841686","pt":1717315199991,"mc":[{"id":"1.229554916","rc":[{"atb":[[3.95,11.81],[4.9,5.95]],"id":51562794},{"atb":[[1.58,40.04],[1.48,72.59]],"id":46292327},{"atl":[[5.4,0.12]],"id":46292327},{"spn":3.49,"spf":"NaN","id":46292327},{"atb":[[2.46,15.9],[2.26,27.65]],"id":56606596},{"atl":[[12.5,0.04]],"id":56606596},{"spn":7.48,"spf":"NaN","id":56606596},{"atb":[[2.38,25.24],[2.58,14.7]],"id":65788088},{"atl":[[13.5,0.04]],"id":65788088},{"spn":8.04,"spf":"NaN","id":65788088},{"atb":[[5.6,7.57],[7.2,3.74]],"id":42099039},{"atb":[[1.19,122.25],[1.09,387.15]],"id":65293046},{"atl":[[3.05,0.25]],"id":65293046},{"spn":2.12,"spf":"NaN","id":65293046},{"atb":[[1.96,24.19],[1.86,40.51]],"id":70003370},{"atl":[[8.4,0.07]],"id":70003370},{"spn":5.18,"spf":"NaN","id":70003370},{"atb":[[1.01,5807.26]],"id":64927898},{"atl":[[2.4,0.37]],"id":64927898}],"con":true,"img":false}]}
{"op":"mcm","clk":"11449851251","pt":1717315296202,"mc":[{"id":"1.229554916","rc":[{"atb":[[3.95,0],[4.9,0]],"id":51562794},{"spn":"NaN","spf":"NaN","id":51562794},{"atb":[[1.58,0],[1.48,0]],"id":46292327},{"atl":[[5.4,0]],"id":46292327},{"spn":"NaN","spf":"NaN","id":46292327},{"atb":[[2.46,0],[2.26,0]],"id":56606596},{"atl":[[12.5,0]],"id":56606596},{"spn":"NaN","spf":"NaN","id":56606596},{"atb":[[2.38,0],[2.58,0]],"id":65788088},{"atl":[[13.5,0]],"id":65788088},{"spn":"NaN","spf":"NaN","id":65788088},{"atb":[[5.6,0],[7.2,0]],"id":42099039},{"spn":"NaN","spf":"NaN","id":42099039},{"atb":[[1.96,0],[1.86,0]],"id":70003370},{"atl":[[8.4,0]],"id":70003370},{"spn":"NaN","spf":"NaN","id":70003370},{"atb":[[1.19,0],[1.09,0]],"id":65293046},{"atl":[[3.05,0]],"id":65293046},{"spn":"NaN","spf":"NaN","id":65293046},{"atb":[[1.01,0]],"id":64927898},{"atl":[[2.4,0]],"id":64927898},{"spn":"NaN","spf":"NaN","id":64927898}],"con":true,"img":false}]}
{"op":"mcm","clk":"11449896887","pt":1717315742884,"mc":[{"id":"1.229554916","rc":[{"atb":[[4.6,6.45],[3.8,12.44]],"id":51562794},{"spn":"Infinity","spf":"NaN","id":51562794},{"atb":[[1.51,68.32],[1.61,38.08]],"id":46292327},{"atl":[[5.7,0.1]],"id":46292327},{"spn":3.65,"spf":"NaN","id":46292327},{"atb":[[2.56,14.88],[2.36,25.61]],"id":65788088},{"atl":[[15.5,0.03]],"id":65788088},{"spn":9.03,"spf":"NaN","id":65788088},{"atb":[[5.6,7.57],[7.2,3.74]],"id":42099039},{"spn":"Infinity","spf":"NaN","id":42099039}],"con":true,"img":false}]}
{"op":"mcm","clk":"11449924797","pt":1717316009720,"mc":[{"id":"1.229554916","rc":[{"atb":[[4.6,0],[3.8,0]],"id":51562794},{"spn":"NaN","spf":"NaN","id":51562794},{"atb":[[1.51,0],[1.61,0]],"id":46292327},{"atl":[[5.7,0]],"id":46292327},{"spn":"NaN","spf":"NaN","id":46292327},{"atb":[[2.56,0],[2.36,0]],"id":65788088},{"atl":[[15.5,0]],"id":65788088},{"spn":"NaN","spf":"NaN","id":65788088},{"atb":[[5.6,0],[7.2,0]],"id":42099039},{"spn":"NaN","spf":"NaN","id":42099039}],"con":true,"img":false}]}
{"op":"mcm","clk":"11449995452","pt":1717316891206,"mc":[{"id":"1.229554916","rc":[{"atb":[[4.8,6.11],[3.9,12.01]],"id":51562794},{"spn":"Infinity","spf":"NaN","id":51562794},{"atb":[[1.6,38.71],[1.5,69.68]],"id":46292327},{"atl":[[5.6,0.11]],"id":46292327},{"spn":3.6,"spf":"NaN","id":46292327},{"atb":[[2.46,15.9],[2.26,27.65]],"id":56606596},{"atl":[[12.5,0.04]],"id":56606596},{"spn":7.48,"spf":"NaN","id":56606596},{"atb":[[2.54,15.08],[2.34,26]],"id":65788088},{"atl":[[15,0.03]],"id":65788088},{"spn":8.77,"spf":"NaN","id":65788088},{"atb":[[6.8,4],[5.4,7.92]],"id":42099039},{"spn":"Infinity","spf":"NaN","id":42099039},{"atb":[[1.85,40.99],[1.95,24.45]],"id":70003370},{"atl":[[8.2,0.07]],"id":70003370},{"spn":5.07,"spf":"NaN","id":70003370},{"atb":[[1.2,116.14],[1.1,348.43]],"id":65293046},{"atl":[[3.05,0.25]],"id":65293046},{"spn":2.12,"spf":"NaN","id":65293046},{"atb":[[1.01,5807.26]],"id":64927898},{"atl":[[2.4,0.37]],"id":64927898},{"spn":1.7,"spf":"NaN","id":64927898}],"con":true,"img":false}]}
{"op":"mcm","clk":"11450003970","pt":1717316992450,"mc":[{"id":"1.229554916","rc":[{"atb":[[4.8,0],[3.9,0]],"id":51562794},{"spn":"NaN","spf":"NaN","id":51562794},{"atb":[[1.6,0],[1.5,0]],"id":46292327},{"atl":[[5.6,0]],"id":46292327},{"spn":"NaN","spf":"NaN","id":46292327},{"atb":[[2.46,0],[2.26,0]],"id":56606596},{"atl":[[12.5,0]],"id":56606596},{"spn":"NaN","spf":"NaN","id":56606596},{"atb":[[2.54,0],[2.34,0]],"id":65788088},{"atl":[[15,0]],"id":65788088},{"spn":"NaN","spf":"NaN","id":65788088},{"atb":[[6.8,0],[5.4,0]],"id":42099039},{"spn":"NaN","spf":"NaN","id":42099039},{"atb":[[1.85,0],[1.95,0]],"id":70003370},{"atl":[[8.2,0]],"id":70003370},{"spn":"NaN","spf":"NaN","id":70003370},{"atb":[[1.2,0],[1.1,0]],"id":65293046},{"atl":[[3.05,0]],"id":65293046},{"spn":"NaN","spf":"NaN","id":65293046},{"atb":[[1.01,0]],"id":64927898},{"atl":[[2.4,0]],"id":64927898},{"spn":"NaN","spf":"NaN","id":64927898}],"con":true,"img":false}]}
{"op":"mcm","clk":"11450029245","pt":1717317249153,"mc":[{"id":"1.229554916","rc":[{"atb":[[4,13.95],[3.45,16.74]],"id":51562794},{"atl":[[60,5.23]],"id":51562794},{"spn":32.0,"spf":"NaN","id":51562794},{"atb":[[1.42,93.42],[1.52,56.34]],"id":46292327},{"atl":[[11.5,3.98],[12,3.56]],"id":46292327},{"spn":6.51,"spf":"NaN","id":46292327},{"atb":[[1.62,66.96],[1.76,38.54]],"id":56606596},{"atl":[[16,2.78],[17,2.61]],"id":56606596},{"spn":8.88,"spf":"NaN","id":56606596},{"atb":[[1.87,33.67],[1.71,55.14]],"id":65788088},{"atl":[[18,2.61],[19.5,2.61]],"id":65788088},{"spn":9.93,"spf":"NaN","id":65788088},{"atb":[[5.8,8.72],[5,9.43]],"id":42099039},{"atl":[[140,2.91]],"id":42099039},{"spn":72.9,"spf":"NaN","id":42099039},{"atb":[[1.18,190.37],[1.22,76.09]],"id":65293046},{"atl":[[6,6.85],[5.4,9.51]],"id":65293046},{"spn":3.31,"spf":"NaN","id":65293046},{"atb":[[1.44,90.36],[1.54,54.25]],"id":70003370},{"atl":[[11.5,3.98],[12.5,3.45]],"id":70003370},{"spn":6.52,"spf":"NaN","id":70003370},{"atb":[[1.09,172.79],[1.08,531.02]],"id":64927898},{"atl":[[3.45,17.08],[3.75,15.69]],"id":64927898},{"spn":2.27,"spf":"NaN","id":64927898}],"con":true,"img":false}]}
{"op":"mcm","clk":"11450030978","pt":1717317266292,"mc":[{"id":"1.229554916","rc":[{"atb":[[1.09,99.3]],"id":64927898}],"con":true,"img":false}]}
{"op":"mcm","clk":"11450034031","pt":1717317295788,"mc":[{"id":"1.229554916","rc":[{"atb":[[5.8,0]],"id":42099039}],"con":true,"img":false}]}
{"op":"mcm","clk":"11450034041","pt":1717317295890,"mc":[{"id":"1.229554916","rc":[{"atb":[[6,8.72]],"id":42099039}],"con":true,"img":false}]}
{"op":"mcm","clk":"11450089837","pt":1717317888702,"mc":[{"id":"1.229554916","rc":[{"atb":[[4.5,6.63],[3.75,12.67]],"id":51562794},{"spn":32.25,"spf":"NaN","id":51562794},{"atb":[[1.42,176.38],[1.52,101]],"id":46292327},{"atl":[[4.7,0.14]],"id":46292327},{"spn":3.11,"spf":"NaN","id":46292327},{"atb":[[2.46,15.9],[2.26,27.65]],"id":56606596},{"atl":[[12.5,0.04]],"id":56606596},{"spn":7.48,"spf":"NaN","id":56606596},{"atb":[[2.54,15.08],[2.34,26]],"id":65788088},{"atl":[[15,0.03]],"id":65788088},{"spn":8.77,"spf":"NaN","id":65788088},{"atb":[[5.5,7.74],[7,3.87]],"id":42099039},{"spn":73.5,"spf":"NaN","id":42099039},{"atb":[[1.97,23.94],[1.87,40.04]],"id":70003370},{"atl":[[8.4,0.07]],"id":70003370},{"spn":5.18,"spf":"NaN","id":70003370},{"atb":[[1.12,290.36],[1.22,181.68]],"id":65293046},{"atl":[[3.1,0.25]],"id":65293046},{"spn":2.16,"spf":"NaN","id":65293046},{"atb":[[1.01,5807.26]],"id":64927898},{"atl":[[2.44,0.36]],"id":64927898},{"spn":1.76,"spf":"NaN","id":64927898}],"con":true,"img":false}]}
{"op":"mcm","clk":"11450095189","pt":1717317947951,"mc":[{"id":"1.229554916","rc":[{"atb":[[1.76,0]],"id":56606596},{"atb":[[1.87,0]],"id":65788088},{"atb":[[1.54,0]],"id":70003370}],"con":true,"img":false}]}
{"op":"mcm","clk":"11450095200","pt":1717317948055,"mc":[{"id":"1.229554916","rc":[{"atb":[[1.84,38.54]],"id":56606596},{"atb":[[1.93,33.67]],"id":65788088},{"atb":[[1.6,54.25]],"id":70003370}],"con":true,"img":false}]}
{"op":"mcm","clk":"11450103162","pt":1717318041880,"mc":[{"id":"1.229554916","rc":[{"atb":[[2,3.92]],"id":70003370},{"spn":5.2,"spf":"NaN","id":70003370},{"atb":[[1.23,17.06]],"id":65293046},{"spn":2.16,"spf":"NaN","id":65293046}],"con":true,"img":false}]}
{"op":"mcm","clk":"11450103183","pt":1717318042092,"mc":[{"id":"1.229554916","rc":[{"atb":[[1.54,7.26]],"id":46292327},{"atb":[[2.32,2.97]],"id":56606596}],"con":true,"img":false}]}
{"op":"mcm","clk":"11450103198","pt":1717318042303,"mc":[{"id":"1.229554916","rc":[{"atb":[[2.4,2.8]],"id":65788088}],"con":true,"img":false}]}
{"op":"mcm","clk":"11450109374","pt":1717318109855,"mc":[{"id":"1.229554916","rc":[{"atb":[[3.45,0]],"id":51562794},{"spn":3.12,"spf":"NaN","id":46292327}],"con":true,"img":false}]}
{"op":"mcm","clk":"11450109383","pt":1717318109969,"mc":[{"id":"1.229554916","rc":[{"atb":[[3.8,16.74]],"id":51562794}],"con":true,"img":false}]}
{"op":"mcm","clk":"11450150234","pt":1717318577536,"mc":[{"id":"1.229554916","rc":[{"atb":[[4.5,0],[3.75,0]],"id":51562794},{"spn":32.0,"spf":"NaN","id":51562794},{"atb":[[1.42,93.42],[1.52,56.34]],"id":46292327},{"atl":[[4.7,0]],"id":46292327},{"spn":6.52,"spf":"NaN","id":46292327},{"atb":[[2.46,0],[2.26,0]],"id":56606596},{"atl":[[12.5,0]],"id":56606596},{"spn":9.16,"spf":"NaN","id":56606596},{"atb":[[2.54,0],[2.34,0]],"id":65788088},{"atl":[[15,0]],"id":65788088},{"spn":10.2,"spf":"NaN","id":65788088},{"atb":[[5.5,0],[7,0]],"id":42099039},{"spn":73.0,"spf":"NaN","id":42099039},{"atb":[[1.12,0],[1.22,76.09]],"id":65293046},{"atl":[[3.1,0]],"id":65293046},{"spn":3.31,"spf":"NaN","id":65293046},{"atb":[[1.97,0],[1.87,0]],"id":70003370},{"atl":[[8.4,0]],"id":70003370},{"spn":6.75,"spf":"NaN","id":70003370},{"atb":[[1.01,0]],"id":64927898},{"atl":[[2.44,0]],"id":64927898},{"spn":2.27,"spf":"NaN","id":64927898}],"con":true,"img":false}]}
{"op":"mcm","clk":"11450150693","pt":1717318582477,"mc":[{"id":"1.229554916","rc":[{"atb":[[2.32,0]],"id":56606596},{"atb":[[2.4,0]],"id":65788088}],"con":true,"img":false}]}
{"op":"mcm","clk":"11450150932","pt":1717318584914,"mc":[{"id":"1.229554916","rc":[{"atb":[[3.8,0]],"id":51562794}],"con":true,"img":false}]}
{"op":"mcm","clk":"11450150940","pt":1717318585017,"mc":[{"id":"1.229554916","rc":[{"atb":[[3.5,16.74]],"id":51562794}],"con":true,"img":false}]}
{"op":"mcm","clk":"11450151751","pt":1717318593147,"mc":[{"id":"1.229554916","rc":[{"atb":[[3.7,12.9],[4.4,6.83]],"id":51562794},{"atb":[[1.51,68.32],[1.61,38.08]],"id":46292327},{"atl":[[5.7,0.1]],"id":46292327},{"atb":[[2.5,15.48],[2.3,26.8]],"id":56606596},{"atl":[[14,0.04]],"id":56606596},{"atb":[[2.42,24.53],[2.62,14.34]],"id":65788088},{"atl":[[17,0.03]],"id":65788088},{"atb":[[5.6,7.57],[7.2,3.74]],"id":42099039},{"atb":[[1.18,319.43],[1.08,435.54]],"id":65293046},{"atl":[[3,0.26]],"id":65293046},{"atb":[[1.83,41.97],[1.93,24.97]],"id":70003370},{"atl":[[8.2,0.07]],"id":70003370},{"atb":[[1.01,5807.26]],"id":64927898},{"atl":[[2.4,0.37]],"id":64927898}],"con":true,"img":false}]}
{"op":"mcm","clk":"11450152300","pt":1717318598336,"mc":[{"id":"1.229554916","rc":[{"atb":[[1.54,0]],"id":46292327}],"con":true,"img":false}]}
{"op":"mcm","clk":"11450156309","pt":1717318639070,"mc":[{"id":"1.229554916","rc":[{"atb":[[1.01,17.18]],"id":51562794},{"atl":[[990,0.85]],"id":51562794},{"spn":32.2,"spf":"NaN","id":51562794},{"atb":[[1.01,17.18]],"id":46292327},{"atl":[[990,0.85]],"id":46292327},{"spn":3.65,"spf":"NaN","id":46292327},{"atb":[[1.01,17.18]],"id":56606596},{"atl":[[1000,0.85]],"id":56606596},{"spn":8.25,"spf":"NaN","id":56606596},{"atb":[[1.02,8.59]],"id":65788088},{"atl":[[990,0.85]],"id":65788088},{"spn":9.81,"spf":"NaN","id":65788088},{"atb":[[1.01,17.18]],"id":42099039},{"atl":[[1000,0.85]],"id":42099039},{"spn":73.6,"spf":"NaN","id":42099039},{"atb":[[1.01,17.18]],"id":70003370},{"atl":[[990,0.85]],"id":70003370},{"spn":5.1,"spf":"NaN","id":70003370},{"atb":[[1.01,17.18]],"id":65293046},{"atl":[[990,0.85]],"id":65293046},{"spn":2.11,"spf":"NaN","id":65293046},{"atb":[[1.03,5.72]],"id":64927898},{"atl":[[990,0.85]],"id":64927898},{"spn":1.74,"spf":"NaN","id":64927898}],"con":true,"img":false}]}
{"op":"mcm","clk":"11450156789","pt":1717318643473,"mc":[{"id":"1.229554916","rc":[{"atb":[[2,0]],"id":70003370}],"con":true,"img":false}]}
{"op":"mcm","clk":"11450158092","pt":1717318655932,"mc":[{"id":"1.229554916","rc":[{"atb":[[3.5,0]],"id":51562794},{"atb":[[1.42,0],[1.52,75.45]],"id":46292327},{"atb":[[1.6,0],[1.84,34.88]],"id":70003370}],"con":true,"img":false}]}
{"op":"mcm","clk":"11450158101","pt":1717318655993,"mc":[{"id":"1.229554916","rc":[{"atb":[[3.75,16.74]],"id":51562794},{"atb":[[1.62,56.34]],"id":46292327}],"con":true,"img":false}]}
{"op":"mcm","clk":"11450164515","pt":1717318722578,"mc":[{"id":"1.229554916","rc":[{"atb":[[4,0]],"id":51562794},{"spn":3.66,"spf":"NaN","id":46292327},{"atb":[[5,0]],"id":42099039},{"spn":5.06,"spf":"NaN","id":70003370}],"con":true,"img":false}]}
{"op":"mcm","clk":"11450164522","pt":1717318722683,"mc":[{"id":"1.229554916","rc":[{"atb":[[4.5,13.95]],"id":51562794},{"atb":[[5.7,9.43]],"id":42099039}],"con":true,"img":false}]}
{"op":"mcm","clk":"11450164650","pt":1717318724082,"mc":[{"id":"1.229554916","rc":[{"atb":[[3.7,0],[4.4,0]],"id":51562794},{"atb":[[1.51,0],[1.61,0]],"id":46292327},{"atl":[[5.7,0]],"id":46292327},{"atb":[[2.5,0],[2.3,0]],"id":56606596},{"atl":[[14,0]],"id":56606596},{"atb":[[2.42,0],[2.62,0]],"id":65788088},{"atl":[[17,0]],"id":65788088},{"atb":[[5.6,0],[7.2,0]],"id":42099039},{"atb":[[1.83,0],[1.93,0]],"id":70003370},{"atl":[[8.2,0]],"id":70003370},{"atb":[[1.18,190.37],[1.08,0]],"id":65293046},{"atl":[[3,0]],"id":65293046},{"atb":[[1.01,0]],"id":64927898},{"atl":[[2.4,0]],"id":64927898}],"con":true,"img":false}]}
{"op":"mcm","clk":"11450166515","pt":1717318744722,"mc":[{"id":"1.229554916","rc":[{"atb":[[4.5,0]],"id":51562794},{"atb":[[1.43,91.25],[1.62,0],[1.52,0]],"id":46292327},{"atb":[[5.7,0]],"id":42099039},{"atb":[[1.84,0],[1.54,54.25]],"id":70003370}],"con":true,"img":false}]}
{"op":"mcm","clk":"11450166526","pt":1717318744824,"mc":[{"id":"1.229554916","rc":[{"atb":[[4,13.95]],"id":51562794},{"atb":[[1.52,56.34]],"id":46292327},{"atb":[[5.1,9.43]],"id":42099039}],"con":true,"img":false}]}
{"op":"mcm","clk":"11450170712","pt":1717318791659,"mc":[{"id":"1.229554916","rc":[{"spn":32.0,"spf":"NaN","id":51562794},{"spn":6.51,"spf":"NaN","id":46292327},{"spn":8.92,"spf":"NaN","id":56606596},{"spn":9.96,"spf":"NaN","id":65788088},{"spn":73.0,"spf":"NaN","id":42099039},{"spn":6.52,"spf":"NaN","id":70003370},{"atb":[[1.22,0]],"id":65293046},{"spn":3.31,"spf":"NaN","id":65293046},{"spn":2.27,"spf":"NaN","id":64927898}],"con":true,"img":false}]}
{"op":"mcm","clk":"11450170721","pt":1717318791763,"mc":[{"id":"1.229554916","rc":[{"atb":[[1.24,76.09]],"id":65293046}],"con":true,"img":false}]}
{"op":"mcm","clk":"11450188856","pt":1717318980254,"mc":[{"id":"1.229554916","rc":[{"atl":[[6.4,5.33]],"id":65293046},{"spn":3.32,"spf":"NaN","id":65293046}],"con":true,"img":false}]}
{"op":"mcm","clk":"11450188874","pt":1717318980457,"mc":[{"id":"1.229554916","rc":[{"atb":[[2.1,30.69]],"id":51562794},{"atl":[[55,2]],"id":51562794},{"atl":[[11,3.57]],"id":46292327},{"atb":[[1.1,105.52]],"id":56606596},{"atl":[[16,5.4]],"id":56606596},{"atb":[[1.15,88.82]],"id":65788088},{"atl":[[18,5.23]],"id":65788088},{"atb":[[3.25,18.16]],"id":42099039},{"atl":[[140,4.91]],"id":42099039},{"atl":[[5.3,6.85]],"id":65293046},{"atl":[[11,3.46]],"id":70003370},{"atl":[[3.9,32.78]],"id":64927898}],"con":true,"img":false}]}
{"op":"mcm","clk":"11450188883","pt":1717318980556,"mc":[{"id":"1.229554916","rc":[{"atl":[[16,2.78],[17,8.19]],"id":56606596},{"atl":[[18,2.61],[19.5,7.85]],"id":65788088},{"atl":[[140,2.91],[430,2]],"id":42099039}],"con":true,"img":false}]}
{"op":"mcm","clk":"11450188893","pt":1717318980666,"mc":[{"id":"1.229554916","rc":[{"atl":[[16,5.4],[17,2.61]],"id":56606596},{"atl":[[18,5.23],[19.5,2.61]],"id":65788088},{"atl":[[140,4.91],[430,0]],"id":42099039}],"con":true,"img":false}]}
{"op":"mcm","clk":"11450188903","pt":1717318980767,"mc":[{"id":"1.229554916","rc":[{"atl":[[16,2.78],[17,8.19]],"id":56606596},{"atl":[[18,2.61],[19.5,7.85]],"id":65788088},{"atl":[[430,2]],"id":42099039}],"con":true,"img":false}]}
{"op":"mcm","clk":"11450188919","pt":1717318980875,"mc":[{"id":"1.229554916","rc":[{"atl":[[140,2.91]],"id":42099039}],"con":true,"img":false}]}
{"op":"mcm","clk":"11450188975","pt":1717318981445,"mc":[{"id":"1.229554916","rc":[{"atb":[[2.5,30.69]],"id":51562794},{"atb":[[4.2,18.16]],"id":42099039}],"con":true,"img":false}]}
{"op":"mcm","clk":"11450188989","pt":1717318981548,"mc":[{"id":"1.229554916","rc":[{"atb":[[2.1,0]],"id":51562794},{"atb":[[3.25,0]],"id":42099039},{"atl":[[140,4.91],[430,0]],"id":42099039}],"con":true,"img":false}]}
{"op":"mcm","clk":"11450189666","pt":1717318988344,"mc":[{"id":"1.229554916","rc":[{"atb":[[2.5,0],[2.1,33.48]],"id":51562794},{"atb":[[3.25,18.88],[4.2,0]],"id":42099039}],"con":true,"img":false}]}
{"op":"mcm","clk":"11450192628","pt":1717319019799,"mc":[{"id":"1.229554916","rc":[{"atl":[[11.5,0]],"id":46292327}],"con":true,"img":false}]}
{"op":"mcm","clk":"11450192640","pt":1717319019903,"mc":[{"id":"1.229554916","rc":[{"atl":[[10.5,3.98],[11,0],[11.5,7.14]],"id":46292327}],"con":true,"img":false}]}
{"op":"mcm","clk":"11450192662","pt":1717319020113,"mc":[{"id":"1.229554916","rc":[{"atl":[[10,3.99],[11.5,0]],"id":46292327}],"con":true,"img":false}]}
{"op":"mcm","clk":"11450193221","pt":1717319025442,"mc":[{"id":"1.229554916","rc":[{"atb":[[3.25,0],[4.2,18.16]],"id":42099039}],"con":true,"img":false}]}
{"op":"mcm","clk":"11450193851","pt":1717319032352,"mc":[{"id":"1.229554916","rc":[{"atl":[[60,2.61]],"id":51562794}],"con":true,"img":false}]}
{"op":"mcm","clk":"11450193862","pt":1717319032407,"mc":[{"id":"1.229554916","rc":[{"atl":[[50,2.61],[60,4.61]],"id":51562794}],"con":true,"img":false}]}
{"op":"mcm","clk":"11450193870","pt":1717319032516,"mc":[{"id":"1.229554916","rc":[{"atl":[[270,2],[55,0],[60,2.61]],"id":51562794}],"con":true,"img":false}]}
{"op":"mcm","clk":"11450193879","pt":1717319032616,"mc":[{"id":"1.229554916","rc":[{"atl":[[50,4.65]],"id":51562794}],"con":true,"img":false}]}
{"op":"mcm","clk":"11450193891","pt":1717319032724,"mc":[{"id":"1.229554916","rc":[{"atl":[[270,0],[50,2.61],[60,4.61]],"id":51562794}],"con":true,"img":false}]}
{"op":"mcm","clk":"11450193900","pt":1717319032824,"mc":[{"id":"1.229554916","rc":[{"atl":[[50,4.65],[60,2.61]],"id":51562794}],"con":true,"img":false}]}
{"op":"mcm","clk":"11450193909","pt":1717319032931,"mc":[{"id":"1.229554916","rc":[{"atl":[[60,4.61]],"id":51562794}],"con":true,"img":false}]}
{"op":"mcm","clk":"11450193918","pt":1717319033033,"mc":[{"id":"1.229554916","rc":[{"atl":[[50,2.61]],"id":51562794}],"con":true,"img":false}]}
{"op":"mcm","clk":"11450193930","pt":1717319033137,"mc":[{"id":"1.229554916","rc":[{"atl":[[50,4.65],[60,2.61]],"id":51562794}],"con":true,"img":false}]}
{"op":"mcm","clk":"11450193938","pt":1717319033240,"mc":[{"id":"1.229554916","rc":[{"atl":[[60,4.61]],"id":51562794}],"con":true,"img":false}]}
{"op":"mcm","clk":"11450193947","pt":1717319033348,"mc":[{"id":"1.229554916","rc":[{"atl":[[50,2.61]],"id":51562794}],"con":true,"img":false}]}
{"op":"mcm","clk":"11450194001","pt":1717319033919,"mc":[{"id":"1.229554916","rc":[{"atb":[[3.25,18.88],[4.2,0]],"id":42099039}],"con":true,"img":false}]}
{"op":"mcm","clk":"11450194525","pt":1717319039867,"mc":[{"id":"1.229554916","rc":[{"atb":[[3.25,0],[4.2,18.16]],"id":42099039}],"con":true,"img":false}]}
{"op":"mcm","clk":"11450194993","pt":1717319044645,"mc":[{"id":"1.229554916","rc":[{"spn":27.0,"spf":"NaN","id":51562794},{"spn":5.76,"spf":"NaN","id":46292327},{"spn":6.27,"spf":"NaN","id":70003370},{"atl":[[6.4,0]],"id":65293046},{"spn":3.27,"spf":"NaN","id":65293046}],"con":true,"img":false}]}
{"op":"mcm","clk":"11450195243","pt":1717319047750,"mc":[{"id":"1.229554916","rc":[{"atb":[[4,25.56],[5,5.8]],"id":51562794},{"atb":[[1.62,37.46],[1.52,123.34]],"id":46292327},{"atl":[[5.8,0.1]],"id":46292327},{"atb":[[2.32,26.39],[2.52,15.28]],"id":56606596},{"atl":[[14.5,0.03]],"id":56606596},{"atb":[[2.56,14.88],[2.36,25.61]],"id":65788088},{"atl":[[15.5,0.03]],"id":65788088}],"con":true,"img":false}]}
{"op":"mcm","clk":"11450195252","pt":1717319047860,"mc":[{"id":"1.229554916","rc":[{"atl":[[16,5.57],[17,2.61]],"id":56606596},{"atl":[[18,5.23],[19.5,2.61]],"id":65788088}],"con":true,"img":false}]}
{"op":"mcm","clk":"11450195384","pt":1717319049670,"mc":[{"id":"1.229554916","rc":[{"atb":[[1.64,6.13]],"id":46292327},{"atb":[[1.23,0]],"id":65293046},{"atb":[[1.56,7.01]],"id":70003370}],"con":true,"img":false}]}
{"op":"mcm","clk":"11450195413","pt":1717319050034,"mc":[{"id":"1.229554916","rc":[{"atb":[[1.25,15.7]],"id":65293046}],"con":true,"img":false}]}
{"op":"mcm","clk":"11450196709","pt":1717319064970,"mc":[{"id":"1.229554916","rc":[{"atb":[[2.38,2.84]],"id":56606596},{"atb":[[2.42,2.76]],"id":65788088}],"con":true,"img":false}]}
{"op":"mcm","clk":"11450197124","pt":1717319069795,"mc":[{"id":"1.229554916","rc":[{"atl":[[50,4.65]],"id":51562794}],"con":true,"img":false}]}
{"op":"mcm","clk":"11450197138","pt":1717319069908,"mc":[{"id":"1.229554916","rc":[{"atl":[[60,2.61]],"id":51562794}],"con":true,"img":false}]}
{"op":"mcm","clk":"11450197243","pt":1717319071091,"mc":[{"id":"1.229554916","rc":[{"atb":[[6,0]],"id":42099039}],"con":true,"img":false}]}
{"op":"mcm","clk":"11450197253","pt":1717319071202,"mc":[{"id":"1.229554916","rc":[{"atb":[[6.2,8.72]],"id":42099039}],"con":true,"img":false}]}
{"op":"mcm","clk":"11450198129","pt":1717319080479,"mc":[{"id":"1.229554916","rc":[{"atb":[[4,11.61]],"id":51562794},{"atb":[[1.52,67]],"id":46292327}],"con":true,"img":false}]}
{"op":"mcm","clk":"11450198139","pt":1717319080585,"mc":[{"id":"1.229554916","rc":[{"atb":[[4.2,13.95]],"id":51562794},{"atb":[[1.63,56.34]],"id":46292327}],"con":true,"img":false}]}
{"op":"mcm","clk":"11450198600","pt":1717319085423,"mc":[{"id":"1.229554916","rc":[{"atb":[[4,0],[5,0]],"id":51562794},{"atb":[[1.62,0],[1.52,0]],"id":46292327},{"atl":[[5.8,0]],"id":46292327},{"atb":[[2.32,0],[2.52,0]],"id":56606596},{"atl":[[14.5,0]],"id":56606596},{"atb":[[2.56,0],[2.36,0]],"id":65788088},{"atl":[[15.5,0]],"id":65788088}],"con":true,"img":false}]}
{"op":"mcm","clk":"11450199508","pt":1717319094493,"mc":[{"id":"1.229554916","rc":[{"atb":[[1.64,0]],"id":46292327}],"con":true,"img":false}]}
{"op":"mcm","clk":"11450199560","pt":1717319095009,"mc":[{"id":"1.229554916","rc":[{"atb":[[1.66,5.94]],"id":46292327}],"con":true,"img":false}]}
{"op":"mcm","clk":"11450199938","pt":1717319099209,"mc":[{"id":"1.229554916","rc":[{"atb":[[2.38,0]],"id":56606596}],"con":true,"img":false}]}
{"op":"mcm","clk":"11450200039","pt":1717319100235,"mc":[{"id":"1.229554916","rc":[{"atb":[[4,11.61],[5,5.8]],"id":51562794},{"atb":[[1.59,39.36],[1.49,71.11]],"id":46292327},{"atl":[[5.5,0.11]],"id":46292327},{"atb":[[2.28,27.22],[2.48,15.69]],"id":56606596},{"atl":[[13.5,0.04]],"id":56606596},{"atb":[[2.38,25.24],[2.58,14.7]],"id":65788088},{"atl":[[13.5,0.04]],"id":65788088},{"atb":[[6.8,6],[8.8,2.97]],"id":42099039},{"atb":[[1.19,122.25],[1.09,387.15]],"id":65293046},{"atl":[[3.05,0.25]],"id":65293046},{"atb":[[1.82,42.49],[1.92,25.24]],"id":70003370},{"atl":[[8,0.07]],"id":70003370},{"atb":[[1.01,5807.26]],"id":64927898},{"atl":[[2.38,0.37]],"id":64927898}],"con":true,"img":false}]}
{"op":"mcm","clk":"11450200110","pt":1717319100928,"mc":[{"id":"1.229554916","rc":[{"atb":[[4.1,13.07],[3.75,0]],"id":51562794}],"con":true,"img":false}]}
{"op":"mcm","clk":"11450200125","pt":1717319101028,"mc":[{"id":"1.229554916","rc":[{"atb":[[1.63,0]],"id":46292327}],"con":true,"img":false}]}
{"op":"mcm","clk":"11450200135","pt":1717319101136,"mc":[{"id":"1.229554916","rc":[{"atb":[[1.6,56.34]],"id":46292327}],"con":true,"img":false}]}
{"op":"mcm","clk":"11450201048","pt":1717319110023,"mc":[{"id":"1.229554916","rc":[{"spn":27.5,"spf":"NaN","id":51562794},{"spn":3.58,"spf":"NaN","id":46292327},{"spn":7.99,"spf":"NaN","id":56606596},{"spn":8.04,"spf":"NaN","id":65788088},{"spn":74.4,"spf":"NaN","id":42099039},{"atb":[[1.56,0]],"id":70003370},{"spn":4.96,"spf":"NaN","id":70003370},{"spn":2.15,"spf":"NaN","id":65293046},{"spn":1.73,"spf":"NaN","id":64927898}],"con":true,"img":false}]}
{"op":"mcm","clk":"11450201063","pt":1717319110238,"mc":[{"id":"1.229554916","rc":[{"atb":[[1.96,4.09]],"id":70003370}],"con":true,"img":false}]}
{"op":"mcm","clk":"11450202607","pt":1717319124836,"mc":[{"id":"1.229554916","rc":[{"atb":[[2.34,2.92]],"id":56606596},{"atb":[[2.42,0]],"id":65788088}],"con":true,"img":false}]}
{"op":"mcm","clk":"11450202624","pt":1717319125035,"mc":[{"id":"1.229554916","rc":[{"atb":[[2.44,2.72]],"id":65788088}],"con":true,"img":false}]}
{"op":"mcm","clk":"11450205061","pt":1717319150662,"mc":[{"id":"1.229554916","rc":[{"atb":[[1.43,0]],"id":46292327},{"atb":[[6.2,0]],"id":42099039},{"atb":[[1.83,35.29],[1.54,0]],"id":70003370},{"atb":[[1.18,0]],"id":65293046},{"atb":[[1.09,0]],"id":64927898}],"con":true,"img":false}]}
{"op":"mcm","clk":"11450205069","pt":1717319150715,"mc":[{"id":"1.229554916","rc":[{"atb":[[1.5,91.25]],"id":46292327},{"atb":[[7,8.72]],"id":42099039},{"atb":[[1.2,190.37]],"id":65293046},{"atb":[[1.1,99.3]],"id":64927898}],"con":true,"img":false}]}
{"op":"mcm","clk":"11450207360","pt":1717319173368,"mc":[{"id":"1.229554916","rc":[{"atb":[[1.66,0]],"id":46292327},{"spn":3.55,"spf":"NaN","id":46292327},{"spn":4.98,"spf":"NaN","id":70003370},{"spn":1.74,"spf":"NaN","id":64927898}],"con":true,"img":false}]}
{"op":"mcm","clk":"11450208573","pt":1717319184586,"mc":[{"id":"1.229554916","rc":[{"atb":[[1.62,6.32]],"id":46292327}],"con":true,"img":false}]}
{"op":"mcm","clk":"11450212939","pt":1717319227834,"mc":[{"id":"1.229554916","rc":[{"atb":[[4.2,0]],"id":51562794}],"con":true,"img":false}]}
{"op":"mcm","clk":"11450212952","pt":1717319227946,"mc":[{"id":"1.229554916","rc":[{"atb":[[5.1,13.95]],"id":51562794}],"con":true,"img":false}]}
{"op":"mcm","clk":"11450218882","pt":1717319285816,"mc":[{"id":"1.229554916","rc":[{"atb":[[2.5,25.34],[2.1,0]],"id":51562794},{"spn":27.55,"spf":"NaN","id":51562794},{"spn":3.56,"spf":"NaN","id":46292327},{"atb":[[4.2,0],[4.7,17.68]],"id":42099039}],"con":true,"img":false}]}
{"op":"mcm","clk":"11450233785","pt":1717319445895,"mc":[{"id":"1.229554916","rc":[{"atb":[[4,0],[5,0]],"id":51562794},{"atb":[[1.59,0],[1.49,0]],"id":46292327},{"atl":[[5.5,0]],"id":46292327},{"spn":5.81,"spf":"NaN","id":46292327},{"atb":[[2.28,0],[2.48,0]],"id":56606596},{"atl":[[13.5,0]],"id":56606596},{"spn":9.17,"spf":"NaN","id":56606596},{"atb":[[2.38,0],[2.58,0]],"id":65788088},{"atl":[[13.5,0]],"id":65788088},{"spn":10.22,"spf":"NaN","id":65788088},{"atb":[[6.8,0],[8.8,0]],"id":42099039},{"spn":73.5,"spf":"NaN","id":42099039},{"atb":[[1.19,0],[1.09,0]],"id":65293046},{"atl":[[3.05,0]],"id":65293046},{"spn":3.27,"spf":"NaN","id":65293046},{"atb":[[1.82,0],[1.92,0]],"id":70003370},{"atl":[[8,0]],"id":70003370},{"spn":6.48,"spf":"NaN","id":70003370},{"atb":[[1.01,0]],"id":64927898},{"atl":[[2.38,0]],"id":64927898},{"spn":2.27,"spf":"NaN","id":64927898}],"con":true,"img":false}]}
{"op":"mcm","clk":"11450235259","pt":1717319461288,"mc":[{"id":"1.229554916","rc":[{"atb":[[2.34,0]],"id":56606596}],"con":true,"img":false}]}
{"op":"mcm","clk":"11450235644","pt":1717319465379,"mc":[{"id":"1.229554916","rc":[{"atb":[[5.1,0],[4.1,0]],"id":51562794},{"atb":[[1.6,0],[1.5,0]],"id":46292327},{"atb":[[7,0]],"id":42099039},{"atb":[[1.55,53.26]],"id":70003370}],"con":true,"img":false}]}
{"op":"mcm","clk":"11450235656","pt":1717319465485,"mc":[{"id":"1.229554916","rc":[{"atb":[[3.6,13.07],[1.85,50.68],[4.2,13.95]],"id":51562794},{"atb":[[1.43,91.25],[1.52,56.34]],"id":46292327},{"atb":[[6.2,8.72]],"id":42099039},{"atb":[[1.83,0]],"id":70003370}],"con":true,"img":false}]}
{"op":"mcm","clk":"11450235667","pt":1717319465587,"mc":[{"id":"1.229554916","rc":[{"atb":[[2.5,0]],"id":51562794}],"con":true,"img":false}]}
{"op":"mcm","clk":"11450238492","pt":1717319497716,"mc":[{"id":"1.229554916","rc":[{"atb":[[2.5,33.94]],"id":51562794}],"con":true,"img":false}]}
{"op":"mcm","clk":"11450238498","pt":1717319497817,"mc":[{"id":"1.229554916","rc":[{"atb":[[1.85,0]],"id":51562794}],"con":true,"img":false}]}
{"op":"mcm","clk":"11450238749","pt":1717319500761,"mc":[{"id":"1.229554916","rc":[{"atb":[[3.95,11.81],[4.9,5.95]],"id":51562794},{"atb":[[1.63,36.87],[1.53,65.74]],"id":46292327},{"atl":[[5.9,0.1]],"id":46292327},{"atb":[[2.54,15.08],[2.34,26]],"id":56606596},{"atl":[[15,0.03]],"id":56606596},{"atb":[[2.38,25.24],[2.58,14.7]],"id":65788088},{"atl":[[13.5,0.04]],"id":65788088},{"atb":[[8.6,3.05],[6.6,6.22]],"id":42099039},{"atb":[[1.86,27.01],[1.76,45.84]],"id":70003370},{"atl":[[7.6,0.07]],"id":70003370},{"atb":[[1.2,306.52],[1.1,348.43]],"id":65293046},{"atl":[[3.05,0.25]],"id":65293046},{"atb":[[1.01,5807.26]],"id":64927898},{"atl":[[2.36,0.38]],"id":64927898}],"con":true,"img":false}]}
{"op":"mcm","clk":"11450240101","pt":1717319515446,"mc":[{"id":"1.229554916","rc":[{"spn":27.45,"spf":"NaN","id":51562794},{"atb":[[1.62,0]],"id":46292327},{"spn":3.76,"spf":"NaN","id":46292327},{"spn":8.77,"spf":"NaN","id":56606596},{"spn":8.04,"spf":"NaN","id":65788088},{"spn":74.3,"spf":"NaN","id":42099039},{"spn":2.15,"spf":"NaN","id":65293046},{"spn":4.78,"spf":"NaN","id":70003370},{"spn":1.73,"spf":"NaN","id":64927898}],"con":true,"img":false}]}
{"op":"mcm","clk":"11450240427","pt":1717319519186,"mc":[{"id":"1.229554916","rc":[{"atb":[[2.44,0]],"id":65788088},{"atb":[[1.96,0]],"id":70003370}],"con":true,"img":false}]}
{"op":"mcm","clk":"11450242535","pt":1717319541000,"mc":[{"id":"1.229554916","rc":[{"atb":[[1.52,0]],"id":46292327},{"atb":[[1.55,0],[1.87,33.67]],"id":70003370}],"con":true,"img":false}]}
{"op":"mcm","clk":"11450242552","pt":1717319541154,"mc":[{"id":"1.229554916","rc":[{"atb":[[1.64,56.34]],"id":46292327}],"con":true,"img":false}]}
{"op":"mcm","clk":"11450248122","pt":1717319601923,"mc":[{"id":"1.229554916","rc":[{"atb":[[3.6,0]],"id":51562794},{"spn":3.77,"spf":"NaN","id":46292327},{"spn":4.73,"spf":"NaN","id":70003370}],"con":true,"img":false}]}
{"op":"mcm","clk":"11450248127","pt":1717319602021,"mc":[{"id":"1.229554916","rc":[{"atb":[[4,13.07]],"id":51562794}],"con":true,"img":false}]}
{"op":"mcm","clk":"11450255378","pt":1717319684216,"mc":[{"id":"1.229554916","rc":[{"atb":[[2.5,0],[2.1,26.16]],"id":51562794},{"atb":[[3.25,17.44],[4.7,0]],"id":42099039}],"con":true,"img":false}]}
{"op":"mcm","clk":"11450255414","pt":1717319684629,"mc":[{"id":"1.229554916","rc":[{"atb":[[2.5,24.89],[2.1,0]],"id":51562794},{"atb":[[3.25,0],[4.7,17.32]],"id":42099039}],"con":true,"img":false}]}
{"op":"mcm","clk":"11450255431","pt":1717319684835,"mc":[{"id":"1.229554916","rc":[{"atb":[[2.5,0],[2.1,26.16]],"id":51562794},{"atb":[[3.25,17.44],[4.7,0]],"id":42099039}],"con":true,"img":false}]}
{"op":"mcm","clk":"11450255844","pt":1717319689453,"mc":[{"id":"1.229554916","rc":[{"atb":[[2.5,24.89],[2.1,0]],"id":51562794},{"atb":[[3.25,0],[4.7,17.32]],"id":42099039}],"con":true,"img":false}]}
{"op":"mcm","clk":"11450257957","pt":1717319712655,"mc":[{"id":"1.229554916","rc":[{"atb":[[1.67,5.85]],"id":46292327},{"atb":[[2.4,2.8]],"id":56606596},{"atb":[[2.44,2.72]],"id":65788088},{"atb":[[1.9,4.36]],"id":70003370}],"con":true,"img":false}]}
{"op":"mcm","clk":"11450262352","pt":1717319760937,"mc":[{"id":"1.229554916","rc":[{"atb":[[4.2,0]],"id":51562794},{"spn":3.78,"spf":"NaN","id":46292327},{"spn":4.75,"spf":"NaN","id":70003370}],"con":true,"img":false}]}
{"op":"mcm","clk":"11450262365","pt":1717319761042,"mc":[{"id":"1.229554916","rc":[{"atb":[[5,13.95]],"id":51562794}],"con":true,"img":false}]}
{"op":"mcm","clk":"11450264891","pt":1717319790657,"mc":[{"id":"1.229554916","rc":[{"atb":[[3.95,0],[4.9,0]],"id":51562794},{"atb":[[1.63,0],[1.53,0]],"id":46292327},{"atl":[[5.9,0]],"id":46292327},{"atb":[[2.54,0],[2.34,0]],"id":56606596},{"atl":[[15,0]],"id":56606596},{"atb":[[2.38,0],[2.58,0]],"id":65788088},{"atl":[[13.5,0]],"id":65788088},{"atb":[[8.6,0],[6.6,0]],"id":42099039},{"atb":[[1.86,0],[1.76,0]],"id":70003370},{"atl":[[7.6,0]],"id":70003370},{"atb":[[1.2,190.37],[1.1,0]],"id":65293046},{"atl":[[3.05,0]],"id":65293046},{"atb":[[1.01,0]],"id":64927898},{"atl":[[2.36,0]],"id":64927898}],"con":true,"img":false}]}
{"op":"mcm","clk":"11450265108","pt":1717319793056,"mc":[{"id":"1.229554916","rc":[{"atb":[[4,0],[5,0]],"id":51562794},{"atb":[[1.64,0]],"id":46292327},{"atb":[[1.55,53.26],[1.87,0]],"id":70003370}],"con":true,"img":false}]}
{"op":"mcm","clk":"11450265121","pt":1717319793160,"mc":[{"id":"1.229554916","rc":[{"atb":[[3.6,13.07],[1.85,49.78],[4.2,13.95]],"id":51562794},{"atb":[[1.52,56.34]],"id":46292327}],"con":true,"img":false}]}
{"op":"mcm","clk":"11450265128","pt":1717319793266,"mc":[{"id":"1.229554916","rc":[{"atb":[[2.5,0]],"id":51562794}],"con":true,"img":false}]}
{"op":"mcm","clk":"11450265744","pt":1717319800396,"mc":[{"id":"1.229554916","rc":[{"atb":[[2.4,0]],"id":56606596}],"con":true,"img":false}]}
{"op":"mcm","clk":"11450266062","pt":1717319803684,"mc":[{"id":"1.229554916","rc":[{"atb":[[3.95,11.81],[4.9,5.95]],"id":51562794},{"atb":[[1.51,68.32],[1.61,38.08]],"id":46292327},{"atl":[[5.7,0.1]],"id":46292327},{"atb":[[2.24,28.09],[2.44,16.12]],"id":56606596},{"atl":[[12,0.04]],"id":56606596},{"atb":[[2.4,24.88],[2.6,14.51]],"id":65788088},{"atl":[[16.5,0.03]],"id":65788088},{"atb":[[6.4,6.45],[8.4,3.13]],"id":42099039},{"atb":[[1.81,43.01],[1.91,25.52]],"id":70003370},{"atl":[[8,0.07]],"id":70003370},{"atb":[[1.2,306.52],[1.1,348.43]],"id":65293046},{"atl":[[3.05,0.25]],"id":65293046},{"atb":[[1.01,5807.26]],"id":64927898},{"atl":[[2.38,0.37]],"id":64927898}],"con":true,"img":false}]}
{"op":"mcm","clk":"11450267139","pt":1717319815984,"mc":[{"id":"1.229554916","rc":[{"atb":[[2.28,3.06]],"id":56606596}],"con":true,"img":false}]}
{"op":"mcm","clk":"11450267146","pt":1717319816086,"mc":[{"id":"1.229554916","rc":[{"atb":[[2.44,0]],"id":65788088},{"atb":[[1.9,0]],"id":70003370}],"con":true,"img":false}]}
{"op":"mcm","clk":"11450267162","pt":1717319816291,"mc":[{"id":"1.229554916","rc":[{"atb":[[2.46,2.68]],"id":65788088},{"atb":[[1.95,4.13]],"id":70003370}],"con":true,"img":false}]}
{"op":"mcm","clk":"11450267645","pt":1717319822198,"mc":[{"id":"1.229554916","rc":[{"atb":[[2.5,33.48],[1.85,0]],"id":51562794},{"spn":3.68,"spf":"NaN","id":46292327},{"spn":7.22,"spf":"NaN","id":56606596},{"spn":9.55,"spf":"NaN","id":65788088},{"spn":74.2,"spf":"NaN","id":42099039},{"spn":4.97,"spf":"NaN","id":70003370},{"spn":1.74,"spf":"NaN","id":64927898}],"con":true,"img":false}]}
{"op":"mcm","clk":"11450269955","pt":1717319849838,"mc":[{"id":"1.229554916","rc":[{"atb":[[3.6,0]],"id":51562794},{"atb":[[1.43,0],[1.52,131.79]],"id":46292327}],"con":true,"img":false}]}
{"op":"mcm","clk":"11450269964","pt":1717319849941,"mc":[{"id":"1.229554916","rc":[{"atb":[[4,13.07]],"id":51562794}],"con":true,"img":false}]}
{"op":"mcm","clk":"11450270885","pt":1717319861263,"mc":[{"id":"1.229554916","rc":[{"atb":[[1.67,0]],"id":46292327}],"con":true,"img":false}]}
{"op":"mcm","clk":"11450271397","pt":1717319867379,"mc":[{"id":"1.229554916","rc":[{"atb":[[1.52,75.45]],"id":46292327},{"atb":[[1.82,35.72],[1.55,0]],"id":70003370}],"con":true,"img":false}]}
{"op":"mcm","clk":"11450271406","pt":1717319867481,"mc":[{"id":"1.229554916","rc":[{"atb":[[1.62,56.34]],"id":46292327}],"con":true,"img":false}]}
{"op":"mcm","clk":"11450272088","pt":1717319876064,"mc":[{"id":"1.229554916","rc":[{"atb":[[1.64,6.13]],"id":46292327}],"con":true,"img":false}]}
{"op":"mcm","clk":"11450275650","pt":1717319922504,"mc":[{"id":"1.229554916","rc":[{"atb":[[4.2,0]],"id":51562794},{"spn":3.67,"spf":"NaN","id":46292327},{"atb":[[6.2,0]],"id":42099039}],"con":true,"img":false}]}
{"op":"mcm","clk":"11450275658","pt":1717319922561,"mc":[{"id":"1.229554916","rc":[{"atb":[[5,13.95]],"id":51562794},{"atb":[[6.6,8.72]],"id":42099039}],"con":true,"img":false}]}
{"op":"mcm","clk":"11450286161","pt":1717320060667,"mc":[{"id":"1.229554916","rc":[{"atb":[[2.5,0],[2.1,26.16]],"id":51562794},{"spn":27.5,"spf":"NaN","id":51562794},{"atb":[[3.25,17.44],[4.7,0]],"id":42099039}],"con":true,"img":false}]}
{"op":"mcm","clk":"11450286238","pt":1717320062085,"mc":[{"id":"1.229554916","rc":[{"atb":[[2.5,24.89],[2.1,0]],"id":51562794},{"atb":[[3.25,0],[4.7,17.32]],"id":42099039}],"con":true,"img":false}]}
{"op":"mcm","clk":"11450286455","pt":1717320065553,"mc":[{"id":"1.229554916","rc":[{"atb":[[2.5,0]],"id":51562794},{"atb":[[4.7,0]],"id":42099039}],"con":true,"img":false}]}
{"op":"mcm","clk":"11450286461","pt":1717320065655,"mc":[{"id":"1.229554916","rc":[{"atb":[[2.1,26.16]],"id":51562794},{"atb":[[3.25,17.44]],"id":42099039}],"con":true,"img":false}]}
{"op":"mcm","clk":"11450288263","pt":1717320091987,"mc":[{"id":"1.229554916","rc":[{"atb":[[2.5,24.89],[2.1,0]],"id":51562794},{"atb":[[3.25,0],[4.7,17.32]],"id":42099039}],"con":true,"img":false}]}
{"op":"mcm","clk":"11450293008","pt":1717320161400,"mc":[{"id":"1.229554916","rc":[{"atb":[[2.5,0],[2.1,26.16]],"id":51562794},{"atb":[[3.25,17.44],[4.7,0]],"id":42099039}],"con":true,"img":false}]}
{"op":"mcm","clk":"11450293521","pt":1717320167925,"mc":[{"id":"1.229554916","rc":[{"atb":[[3.95,0],[4.9,0]],"id":51562794},{"atb":[[1.51,0],[1.61,0]],"id":46292327},{"atl":[[5.7,0]],"id":46292327},{"atb":[[2.24,0],[2.44,0]],"id":56606596},{"atl":[[12,0]],"id":56606596},{"atb":[[2.4,0],[2.6,0]],"id":65788088},{"atl":[[16.5,0]],"id":65788088},{"atb":[[6.4,0],[8.4,0]],"id":42099039},{"atb":[[1.81,0],[1.91,0]],"id":70003370},{"atl":[[8,0]],"id":70003370},{"atb":[[1.2,190.37],[1.1,0]],"id":65293046},{"atl":[[3.05,0]],"id":65293046},{"atb":[[1.01,0]],"id":64927898},{"atl":[[2.38,0]],"id":64927898}],"con":true,"img":false}]}
{"op":"mcm","clk":"11450293574","pt":1717320168923,"mc":[{"id":"1.229554916","rc":[{"atb":[[2.28,0]],"id":56606596}],"con":true,"img":false}]}
{"op":"mcm","clk":"11450294232","pt":1717320179532,"mc":[{"id":"1.229554916","rc":[{"atb":[[4,0],[5,0]],"id":51562794},{"atb":[[1.43,91.25],[1.62,0]],"id":46292327},{"atb":[[6.6,0]],"id":42099039},{"atb":[[1.55,53.26]],"id":70003370}],"con":true,"img":false}]}
{"op":"mcm","clk":"11450294239","pt":1717320179643,"mc":[{"id":"1.229554916","rc":[{"atb":[[3.6,13.07],[1.85,52.32],[2.1,0],[4.2,13.95]],"id":51562794},{"atb":[[1.52,56.34]],"id":46292327},{"atb":[[6.2,8.72]],"id":42099039},{"atb":[[1.82,0]],"id":70003370}],"con":true,"img":false}]}
{"op":"mcm","clk":"11450294704","pt":1717320186244,"mc":[{"id":"1.229554916","rc":[{"atb":[[3.95,11.81],[4.9,5.95]],"id":51562794},{"atb":[[1.59,39.36],[1.49,71.11]],"id":46292327},{"atl":[[5.5,0.11]],"id":46292327},{"atb":[[2.46,15.9],[2.26,27.65]],"id":56606596},{"atl":[[12.5,0.04]],"id":56606596},{"atb":[[2.54,15.08],[2.34,26]],"id":65788088},{"atl":[[15,0.03]],"id":65788088},{"atb":[[8,3.31],[6,6.96]],"id":42099039},{"atb":[[1.84,41.48],[1.94,24.7]],"id":70003370},{"atl":[[8.2,0.07]],"id":70003370},{"atb":[[1.19,122.25],[1.09,387.15]],"id":65293046},{"atl":[[3.05,0.25]],"id":65293046},{"atb":[[1.01,5807.26]],"id":64927898},{"atl":[[2.4,0.37]],"id":64927898}],"con":true,"img":false}]}
{"op":"mcm","clk":"11450294746","pt":1717320186755,"mc":[{"id":"1.229554916","rc":[{"atb":[[3.25,0],[4.7,17.32]],"id":42099039}],"con":true,"img":false}]}
{"op":"mcm","clk":"11450295161","pt":1717320192827,"mc":[{"id":"1.229554916","rc":[{"atb":[[1.95,0]],"id":70003370}],"con":true,"img":false}]}
{"op":"mcm","clk":"11450295196","pt":1717320193339,"mc":[{"id":"1.229554916","rc":[{"atb":[[1.98,4.01]],"id":70003370}],"con":true,"img":false}]}
{"op":"mcm","clk":"11450296012","pt":1717320204737,"mc":[{"id":"1.229554916","rc":[{"atb":[[2.5,34.76]],"id":51562794}],"con":true,"img":false}]}
{"op":"mcm","clk":"11450296023","pt":1717320204845,"mc":[{"id":"1.229554916","rc":[{"atb":[[1.85,0]],"id":51562794}],"con":true,"img":false}]}
{"op":"mcm","clk":"11450296234","pt":1717320208154,"mc":[{"id":"1.229554916","rc":[{"atb":[[2.32,2.97]],"id":56606596}],"con":true,"img":false}]}
{"op":"mcm","clk":"11450297354","pt":1717320226481,"mc":[{"id":"1.229554916","rc":[{"spn":27.45,"spf":"NaN","id":51562794},{"spn":3.57,"spf":"NaN","id":46292327},{"spn":7.48,"spf":"NaN","id":56606596},{"spn":8.77,"spf":"NaN","id":65788088},{"spn":74.0,"spf":"NaN","id":42099039},{"spn":5.09,"spf":"NaN","id":70003370},{"atl":[[6.2,7.66]],"id":65293046},{"spn":1.75,"spf":"NaN","id":64927898}],"con":true,"img":false}]}
{"op":"mcm","clk":"11450297513","pt":1717320229011,"mc":[{"id":"1.229554916","rc":[{"atb":[[2.46,0]],"id":65788088}],"con":true,"img":false}]}
{"op":"mcm","clk":"11450298061","pt":1717320237603,"mc":[{"id":"1.229554916","rc":[{"atb":[[2.4,2.8]],"id":65788088}],"con":true,"img":false}]}
{"op":"mcm","clk":"11450299079","pt":1717320252816,"mc":[{"id":"1.229554916","rc":[{"atb":[[1.64,0]],"id":46292327}],"con":true,"img":false}]}
{"op":"mcm","clk":"11450300137","pt":1717320268048,"mc":[{"id":"1.229554916","rc":[{"atb":[[1.61,6.43]],"id":46292327}],"con":true,"img":false}]}
{"op":"mcm","clk":"11450302195","pt":1717320300097,"mc":[{"id":"1.229554916","rc":[{"atb":[[3.6,0]],"id":51562794},{"atb":[[1.43,0]],"id":46292327},{"spn":3.55,"spf":"NaN","id":46292327}],"con":true,"img":false}]}
{"op":"mcm","clk":"11450302201","pt":1717320300197,"mc":[{"id":"1.229554916","rc":[{"atb":[[4,13.07]],"id":51562794},{"atb":[[1.5,91.25]],"id":46292327}],"con":true,"img":false}]}
{"op":"mcm","clk":"11450304756","pt":1717320340848,"mc":[{"id":"1.229554916","rc":[{"atb":[[2.5,0],[2.1,26.16]],"id":51562794},{"atb":[[3.25,17.44],[4.7,0]],"id":42099039}],"con":true,"img":false}]}
{"op":"mcm","clk":"11450305124","pt":1717320346637,"mc":[{"id":"1.229554916","rc":[{"atb":[[1.52,0]],"id":46292327},{"atb":[[1.55,0],[1.85,34.46]],"id":70003370}],"con":true,"img":false}]}
{"op":"mcm","clk":"11450305133","pt":1717320346766,"mc":[{"id":"1.229554916","rc":[{"atb":[[1.6,56.34]],"id":46292327}],"con":true,"img":false}]}
{"op":"mcm","clk":"11450305165","pt":1717320347456,"mc":[{"id":"1.229554916","rc":[{"atb":[[2.5,24.89],[2.1,0]],"id":51562794},{"atb":[[3.25,0],[4.7,17.32]],"id":42099039}],"con":true,"img":false}]}
{"op":"mcm","clk":"11450305683","pt":1717320357330,"mc":[{"id":"1.229554916","rc":[{"atb":[[1.61,0]],"id":46292327}],"con":true,"img":false}]}
{"op":"mcm","clk":"11450305693","pt":1717320357534,"mc":[{"id":"1.229554916","rc":[{"atb":[[1.62,6.33]],"id":46292327}],"con":true,"img":false}]}
{"op":"mcm","clk":"11450306676","pt":1717320375782,"mc":[{"id":"1.229554916","rc":[{"spn":3.56,"spf":"NaN","id":46292327},{"atb":[[5.1,0],[6.2,15.98]],"id":42099039}],"con":true,"img":false}]}
{"op":"mcm","clk":"11450309236","pt":1717320418401,"mc":[{"id":"1.229554916","rc":[{"atb":[[4.2,0]],"id":51562794},{"atb":[[6.2,7.26]],"id":42099039}],"con":true,"img":false}]}
{"op":"mcm","clk":"11450309245","pt":1717320418457,"mc":[{"id":"1.229554916","rc":[{"atb":[[5,13.95]],"id":51562794},{"atb":[[6.4,8.72]],"id":42099039}],"con":true,"img":false}]}
{"op":"mcm","clk":"11450309807","pt":1717320426477,"mc":[{"id":"1.229554916","rc":[{"atl":[[140,4.61]],"id":42099039},{"atl":[[3.45,0]],"id":64927898}],"con":true,"img":false}]}
{"op":"mcm","clk":"11450309817","pt":1717320426631,"mc":[{"id":"1.229554916","rc":[{"atl":[[100,0.3]],"id":42099039},{"atl":[[3.15,17.08]],"id":64927898}],"con":true,"img":false}]}
{"op":"mcm","clk":"11450310573","pt":1717320437781,"mc":[{"id":"1.229554916","rc":[{"atl":[[60,0]],"id":51562794},{"spn":27.5,"spf":"NaN","id":51562794},{"spn":54.0,"spf":"NaN","id":42099039}],"con":true,"img":false}]}
{"op":"mcm","clk":"11450310577","pt":1717320437886,"mc":[{"id":"1.229554916","rc":[{"atl":[[65,2.61]],"id":51562794}],"con":true,"img":false}]}
{"op":"mcm","clk":"11450311544","pt":1717320452137,"mc":[{"id":"1.229554916","rc":[{"atb":[[5.2,8.98]],"id":42099039}],"con":true,"img":false}]}
{"op":"mcm","clk":"11450311550","pt":1717320452186,"mc":[{"id":"1.229554916","rc":[{"atb":[[6.2,0]],"id":42099039}],"con":true,"img":false}]}
{"op":"mcm","clk":"11450311769","pt":1717320455836,"mc":[{"id":"1.229554916","rc":[{"atl":[[3.75,0]],"id":64927898}],"con":true,"img":false}]}
{"op":"mcm","clk":"11450311775","pt":1717320455937,"mc":[{"id":"1.229554916","rc":[{"atl":[[3.4,15.69]],"id":64927898}],"con":true,"img":false}]}
{"op":"mcm","clk":"11450311920","pt":1717320458017,"mc":[{"id":"1.229554916","rc":[{"atb":[[6.4,0]],"id":42099039}],"con":true,"img":false}]}
{"op":"mcm","clk":"11450311927","pt":1717320458121,"mc":[{"id":"1.229554916","rc":[{"atb":[[6.2,8.72]],"id":42099039}],"con":true,"img":false}]}
{"op":"mcm","clk":"11450312208","pt":1717320463151,"mc":[{"id":"1.229554916","rc":[{"atl":[[6.2,0]],"id":65293046}],"con":true,"img":false}]}
{"op":"mcm","clk":"11450312286","pt":1717320464446,"mc":[{"id":"1.229554916","rc":[{"atb":[[4,17.44]],"id":42099039}],"con":true,"img":false}]}
{"op":"mcm","clk":"11450312290","pt":1717320464554,"mc":[{"id":"1.229554916","rc":[{"atb":[[4.7,0]],"id":42099039}],"con":true,"img":false}]}
{"op":"mcm","clk":"11450312645","pt":1717320470178,"mc":[{"id":"1.229554916","rc":[{"atb":[[4.5,17.32]],"id":42099039}],"con":true,"img":false}]}
{"op":"mcm","clk":"11450312650","pt":1717320470259,"mc":[{"id":"1.229554916","rc":[{"atb":[[4,0]],"id":42099039}],"con":true,"img":false}]}
{"op":"mcm","clk":"11450313069","pt":1717320477470,"mc":[{"id":"1.229554916","rc":[{"atl":[[65,0]],"id":51562794}],"con":true,"img":false}]}
{"op":"mcm","clk":"11450313075","pt":1717320477529,"mc":[{"id":"1.229554916","rc":[{"atl":[[70,2.61]],"id":51562794}],"con":true,"img":false}]}
{"op":"mcm","clk":"11450313504","pt":1717320485438,"mc":[{"id":"1.229554916","rc":[{"atb":[[2.5,0],[2.74,24.89]],"id":51562794}],"con":true,"img":false}]}
{"op":"mcm","clk":"11450313942","pt":1717320493600,"mc":[{"id":"1.229554916","rc":[{"atb":[[3.95,0],[4.9,0]],"id":51562794},{"atb":[[1.59,0],[1.49,0]],"id":46292327},{"atl":[[5.5,0]],"id":46292327},{"atb":[[2.46,0],[2.26,0]],"id":56606596},{"atl":[[12.5,0]],"id":56606596},{"atb":[[2.54,0],[2.34,0]],"id":65788088},{"atl":[[15,0]],"id":65788088},{"atb":[[8,0],[6,0]],"id":42099039},{"atb":[[1.19,0],[1.09,0]],"id":65293046},{"atl":[[3.05,0]],"id":65293046},{"atb":[[1.84,0],[1.94,0]],"id":70003370},{"atl":[[8.2,0]],"id":70003370},{"atb":[[1.01,0]],"id":64927898},{"atl":[[2.4,0]],"id":64927898}],"con":true,"img":false}]}
{"op":"mcm","clk":"11450313956","pt":1717320493810,"mc":[{"id":"1.229554916","rc":[{"atl":[[3.7,32.78],[3.9,0]],"id":64927898}],"con":true,"img":false}]}
{"op":"mcm","clk":"11450314313","pt":1717320499562,"mc":[{"id":"1.229554916","rc":[{"spn":5.81,"spf":"NaN","id":46292327},{"spn":9.16,"spf":"NaN","id":56606596},{"spn":10.2,"spf":"NaN","id":65788088},{"atl":[[140,2]],"id":42099039},{"spn":53.1,"spf":"NaN","id":42099039},{"spn":6.49,"spf":"NaN","id":70003370},{"spn":3.27,"spf":"NaN","id":65293046},{"spn":2.12,"spf":"NaN","id":64927898}],"con":true,"img":false}]}
{"op":"mcm","clk":"11450314317","pt":1717320499679,"mc":[{"id":"1.229554916","rc":[{"atl":[[100,2.91]],"id":42099039}],"con":true,"img":false}]}
{"op":"mcm","clk":"11450314322","pt":1717320499776,"mc":[{"id":"1.229554916","rc":[{"atl":[[140,0],[410,2]],"id":42099039}],"con":true,"img":false}]}
{"op":"mcm","clk":"11450314326","pt":1717320499874,"mc":[{"id":"1.229554916","rc":[{"atl":[[100,4.91],[410,0]],"id":42099039}],"con":true,"img":false}]}
{"op":"mcm","clk":"11450314352","pt":1717320500286,"mc":[{"id":"1.229554916","rc":[{"atb":[[1.5,0]],"id":46292327},{"atb":[[1.56,52.31],[1.85,0]],"id":70003370}],"con":true,"img":false}]}
{"op":"mcm","clk":"11450314360","pt":1717320500390,"mc":[{"id":"1.229554916","rc":[{"atb":[[1.44,91.25]],"id":46292327}],"con":true,"img":false}]}
{"op":"mcm","clk":"11450314821","pt":1717320507674,"mc":[{"id":"1.229554916","rc":[{"atb":[[2.32,0]],"id":56606596}],"con":true,"img":false}]}
{"op":"mcm","clk":"11450315154","pt":1717320512385,"mc":[{"id":"1.229554916","rc":[{"atl":[[17,0]],"id":56606596},{"atl":[[19.5,0]],"id":65788088},{"atb":[[1.1,0]],"id":64927898}],"con":true,"img":false}]}
{"op":"mcm","clk":"11450315165","pt":1717320512492,"mc":[{"id":"1.229554916","rc":[{"atb":[[4,24.69],[5,19.76]],"id":51562794},{"atb":[[1.45,77.43],[1.55,42.23]],"id":46292327},{"atl":[[5,0.13]],"id":46292327},{"atb":[[2.24,28.09],[2.44,16.12]],"id":56606596},{"atl":[[12,0.04],[15.5,2.61]],"id":56606596},{"atb":[[2.64,14.16],[2.44,24.19]],"id":65788088},{"atl":[[17.5,2.64]],"id":65788088},{"atb":[[6.4,6.45],[8.4,3.13]],"id":42099039},{"atb":[[1.83,41.97],[1.93,24.97]],"id":70003370},{"atl":[[8.2,0.07]],"id":70003370},{"atb":[[1.19,122.25],[1.09,387.15]],"id":65293046},{"atl":[[3.05,0.25]],"id":65293046},{"atb":[[1.01,5807.26],[1.08,630.32]],"id":64927898},{"atl":[[2.36,0.38]],"id":64927898}],"con":true,"img":false}]}
{"op":"mcm","clk":"11450316324","pt":1717320528221,"mc":[{"id":"1.229554916","rc":[{"atl":[[3.15,0]],"id":64927898}],"con":true,"img":false}]}
{"op":"mcm","clk":"11450323185","pt":1717320528624,"mc":[{"id":"1.229554916","rc":[{"atl":[[2.9,17.08]],"id":64927898}],"con":true,"img":false}]}
{"op":"mcm","clk":"11450323761","pt":1717320536565,"mc":[{"id":"1.229554916","rc":[{"atl":[[70,0]],"id":51562794}],"con":true,"img":false}]}
{"op":"mcm","clk":"11450323766","pt":1717320536618,"mc":[{"id":"1.229554916","rc":[{"atl":[[75,2.61]],"id":51562794}],"con":true,"img":false}]}
{"op":"mcm","clk":"11450323904","pt":1717320538430,"mc":[{"id":"1.229554916","rc":[{"atb":[[2.28,3.06]],"id":56606596},{"atb":[[2.4,0]],"id":65788088}],"con":true,"img":false}]}
{"op":"mcm","clk":"11450323918","pt":1717320538638,"mc":[{"id":"1.229554916","rc":[{"atb":[[2.5,2.61]],"id":65788088}],"con":true,"img":false}]}
{"op":"mcm","clk":"11450324176","pt":1717320542159,"mc":[{"id":"1.229554916","rc":[{"atl":[[75,0]],"id":51562794},{"atl":[[15.5,0]],"id":56606596},{"atl":[[17.5,0.03]],"id":65788088},{"atb":[[1.06,707.85],[1.08,99.3]],"id":64927898}],"con":true,"img":false}]}
{"op":"mcm","clk":"11450324184","pt":1717320542243,"mc":[{"id":"1.229554916","rc":[{"atl":[[80,2.61]],"id":51562794},{"atl":[[17,2.61]],"id":56606596},{"atl":[[19,2.61]],"id":65788088}],"con":true,"img":false}]}
{"op":"mcm","clk":"11450324776","pt":1717320549546,"mc":[{"id":"1.229554916","rc":[{"atb":[[4,13.07],[5,13.95]],"id":51562794},{"atb":[[1.45,0],[1.55,0]],"id":46292327},{"atl":[[5,0]],"id":46292327},{"atb":[[2.24,0],[2.44,0]],"id":56606596},{"atl":[[12,0]],"id":56606596},{"atb":[[2.64,0],[2.44,0]],"id":65788088},{"atl":[[17.5,0]],"id":65788088},{"atb":[[6.4,0],[8.4,0]],"id":42099039},{"atb":[[1.19,0],[1.09,0]],"id":65293046},{"atl":[[3.05,0]],"id":65293046},{"atb":[[1.83,0],[1.93,0]],"id":70003370},{"atl":[[8.2,0]],"id":70003370},{"atb":[[1.01,0]],"id":64927898},{"atl":[[2.36,0]],"id":64927898}],"con":true,"img":false}]}
{"op":"mcm","clk":"11450325627","pt":1717320559527,"mc":[{"id":"1.229554916","rc":[{"atl":[[100,2.3]],"id":42099039}],"con":true,"img":false}]}
{"op":"mcm","clk":"11450325633","pt":1717320559628,"mc":[{"id":"1.229554916","rc":[{"spn":9.14,"spf":"NaN","id":56606596},{"spn":10.25,"spf":"NaN","id":65788088},{"atl":[[95,2.61],[410,2]],"id":42099039},{"spn":50.6,"spf":"NaN","id":42099039},{"spn":1.99,"spf":"NaN","id":64927898}],"con":true,"img":false}]}
{"op":"mcm","clk":"11450325638","pt":1717320559734,"mc":[{"id":"1.229554916","rc":[{"atl":[[95,4.61],[100,0.3]],"id":42099039}],"con":true,"img":false}]}
{"op":"mcm","clk":"11450325647","pt":1717320559836,"mc":[{"id":"1.229554916","rc":[{"atl":[[410,0]],"id":42099039}],"con":true,"img":false}]}
{"op":"mcm","clk":"11450326204","pt":1717320567346,"mc":[{"id":"1.229554916","rc":[{"atb":[[1.6,0]],"id":46292327}],"con":true,"img":false}]}
{"op":"mcm","clk":"11450326210","pt":1717320567447,"mc":[{"id":"1.229554916","rc":[{"atb":[[1.52,56.34]],"id":46292327}],"con":true,"img":false}]}
{"op":"mcm","clk":"11450326221","pt":1717320567558,"mc":[{"id":"1.229554916","rc":[{"atb":[[3.95,11.81],[4.9,5.95]],"id":51562794},{"atb":[[1.51,68.32],[1.61,38.08]],"id":46292327},{"atl":[[5.7,0.1]],"id":46292327},{"atb":[[2.42,16.35],[2.22,28.56]],"id":56606596},{"atl":[[11.5,0.05]],"id":56606596},{"atb":[[2.46,23.86],[2.66,13.99]],"id":65788088},{"atl":[[18,5.26]],"id":65788088},{"atb":[[8.6,3.05],[6.6,6.22]],"id":42099039},{"atb":[[1.85,40.99],[1.95,24.45]],"id":70003370},{"atl":[[8.2,0.07]],"id":70003370},{"atb":[[1.2,306.52],[1.1,348.43]],"id":65293046},{"atl":[[3.05,0.25]],"id":65293046},{"atb":[[1.01,5807.26]],"id":64927898},{"atl":[[2.3,0.4]],"id":64927898}],"con":true,"img":false}]}
{"op":"mcm","clk":"11450326272","pt":1717320568079,"mc":[{"id":"1.229554916","rc":[{"atb":[[2.28,0]],"id":56606596}],"con":true,"img":false}]}
{"op":"mcm","clk":"11450326285","pt":1717320568178,"mc":[{"id":"1.229554916","rc":[{"atb":[[1.62,0]],"id":46292327},{"atb":[[1.98,0]],"id":70003370}],"con":true,"img":false}]}
{"op":"mcm","clk":"11450327406","pt":1717320583463,"mc":[{"id":"1.229554916","rc":[{"atb":[[2.5,0]],"id":65788088}],"con":true,"img":false}]}
{"op":"mcm","clk":"11450327430","pt":1717320583871,"mc":[{"id":"1.229554916","rc":[{"atb":[[4,0]],"id":51562794},{"atl":[[3.1,20.4],[3.4,0]],"id":64927898}],"con":true,"img":false}]}
{"op":"mcm","clk":"11450327436","pt":1717320583979,"mc":[{"id":"1.229554916","rc":[{"atb":[[4.4,13.07]],"id":51562794}],"con":true,"img":false}]}
{"op":"mcm","clk":"11450328943","pt":1717320604552,"mc":[{"id":"1.229554916","rc":[{"atb":[[3.95,0],[4.9,0]],"id":51562794},{"atb":[[1.51,0],[1.61,0]],"id":46292327},{"atl":[[5.7,0]],"id":46292327},{"atb":[[2.42,0],[2.22,0]],"id":56606596},{"atl":[[11.5,0]],"id":56606596},{"atb":[[2.46,0],[2.66,0]],"id":65788088},{"atl":[[18,5.23]],"id":65788088},{"atb":[[8.6,0],[6.6,0]],"id":42099039},{"atb":[[1.85,0],[1.95,0]],"id":70003370},{"atl":[[8.2,0]],"id":70003370},{"atb":[[1.2,190.37],[1.1,0]],"id":65293046},{"atl":[[3.05,0]],"id":65293046},{"atb":[[1.01,0]],"id":64927898},{"atl":[[2.3,0]],"id":64927898}],"con":true,"img":false}]}
{"op":"mcm","clk":"11450329639","pt":1717320613951,"mc":[{"id":"1.229554916","rc":[{"atb":[[5,0]],"id":51562794},{"atb":[[1.93,0]],"id":65788088},{"atl":[[90,0.47],[100,0]],"id":42099039},{"atl":[[11.5,0]],"id":70003370}],"con":true,"img":false}]}
{"op":"mcm","clk":"11450329646","pt":1717320614056,"mc":[{"id":"1.229554916","rc":[{"atb":[[5.2,13.95]],"id":51562794},{"atb":[[1.99,33.67]],"id":65788088},{"atl":[[10.5,3.98],[11,0],[12,6.92]],"id":70003370}],"con":true,"img":false}]}
{"op":"mcm","clk":"11450329653","pt":1717320614163,"mc":[{"id":"1.229554916","rc":[{"atl":[[10,3.99]],"id":70003370}],"con":true,"img":false}]}
{"op":"mcm","clk":"11450329660","pt":1717320614261,"mc":[{"id":"1.229554916","rc":[{"atl":[[12,0]],"id":70003370}],"con":true,"img":false}]}
{"op":"mcm","clk":"11450330398","pt":1717320623597,"mc":[{"id":"1.229554916","rc":[{"atb":[[6.4,4.3],[5.2,22.25]],"id":51562794},{"spn":28.2,"spf":"NaN","id":51562794},{"atb":[[1.42,82.96],[1.52,101]],"id":46292327},{"atl":[[4.7,0.14]],"id":46292327},{"spn":3.11,"spf":"NaN","id":46292327},{"atb":[[2.68,13.82],[2.48,23.54]],"id":56606596},{"atl":[[18.5,0.03]],"id":56606596},{"spn":9.34,"spf":"NaN","id":56606596},{"atb":[[2.56,22.33],[2.76,13.19]],"id":65788088},{"spn":10.38,"spf":"NaN","id":65788088},{"atb":[[5.8,7.26],[7.6,3.52]],"id":42099039},{"spn":48.8,"spf":"NaN","id":42099039},{"atb":[[1.79,44.1],[1.89,26.1]],"id":70003370},{"atl":[[7.8,0.07]],"id":70003370},{"spn":4.84,"spf":"NaN","id":70003370},{"atb":[[1.18,129.05],[1.08,435.54]],"id":65293046},{"atl":[[3,0.26]],"id":65293046},{"spn":2.12,"spf":"NaN","id":65293046},{"atb":[[1.01,5807.26]],"id":64927898},{"atl":[[2.22,0.42]],"id":64927898},{"spn":1.65,"spf":"NaN","id":64927898}],"con":true,"img":false}]}
{"op":"mcm","clk":"11450330698","pt":1717320626913,"mc":[{"id":"1.229554916","rc":[{"atb":[[1.62,0]],"id":56606596},{"atb":[[1.94,41.65],[1.71,0]],"id":65788088},{"atl":[[95,2]],"id":42099039}],"con":true,"img":false}]}
{"op":"mcm","clk":"11450330708","pt":1717320626968,"mc":[{"id":"1.229554916","rc":[{"atb":[[1.72,66.96]],"id":56606596},{"atl":[[90,3.08],[410,2]],"id":42099039}],"con":true,"img":false}]}
{"op":"mcm","clk":"11450330716","pt":1717320627071,"mc":[{"id":"1.229554916","rc":[{"atl":[[95,0]],"id":42099039}],"con":true,"img":false}]}
{"op":"mcm","clk":"11450330848","pt":1717320628678,"mc":[{"id":"1.229554916","rc":[{"atb":[[1.54,7.26]],"id":46292327},{"atb":[[1.93,4.22]],"id":70003370}],"con":true,"img":false}]}
{"op":"mcm","clk":"11450330915","pt":1717320629398,"mc":[{"id":"1.229554916","rc":[{"atb":[[1.94,0]],"id":65788088},{"atl":[[90,0.47]],"id":42099039}],"con":true,"img":false}]}
{"op":"mcm","clk":"11450330922","pt":1717320629501,"mc":[{"id":"1.229554916","rc":[{"atb":[[1.81,41.65]],"id":65788088},{"atl":[[100,2.61]],"id":42099039}],"con":true,"img":false}]}
{"op":"mcm","clk":"11450332100","pt":1717320644029,"mc":[{"id":"1.229554916","rc":[{"atb":[[2.54,2.55]],"id":56606596},{"atb":[[2.62,2.42]],"id":65788088}],"con":true,"img":false}]}
{"op":"mcm","clk":"11450332385","pt":1717320647611,"mc":[{"id":"1.229554916","rc":[{"atl":[[100,4.61],[410,0]],"id":42099039}],"con":true,"img":false}]}
{"op":"mcm","clk":"11450332986","pt":1717320656416,"mc":[{"id":"1.229554916","rc":[{"atb":[[5.3,9.73],[5.2,8.29]],"id":51562794},{"atb":[[1.99,0]],"id":65788088}],"con":true,"img":false}]}
{"op":"mcm","clk":"11450332992","pt":1717320656517,"mc":[{"id":"1.229554916","rc":[{"atb":[[2.04,33.67]],"id":65788088}],"con":true,"img":false}]}
{"op":"mcm","clk":"11450333276","pt":1717320660323,"mc":[{"id":"1.229554916","rc":[{"atb":[[6.4,0],[5.2,0]],"id":51562794},{"atb":[[1.42,0],[1.52,56.34]],"id":46292327},{"atl":[[4.7,0]],"id":46292327},{"atb":[[2.56,0],[2.76,0]],"id":65788088},{"atb":[[1.79,0],[1.89,0]],"id":70003370},{"atl":[[7.8,0]],"id":70003370},{"atb":[[1.18,0],[1.08,0]],"id":65293046},{"atl":[[3,0]],"id":65293046}],"con":true,"img":false}]}
{"op":"mcm","clk":"11450333381","pt":1717320661632,"mc":[{"id":"1.229554916","rc":[{"atb":[[1.84,0]],"id":56606596}],"con":true,"img":false}]}
{"op":"mcm","clk":"11450333388","pt":1717320661735,"mc":[{"id":"1.229554916","rc":[{"atb":[[1.97,38.54]],"id":56606596}],"con":true,"img":false}]}
{"op":"mcm","clk":"11450334314","pt":1717320673541,"mc":[{"id":"1.229554916","rc":[{"atb":[[2.62,0]],"id":65788088}],"con":true,"img":false}]}
{"op":"mcm","clk":"11450334341","pt":1717320673851,"mc":[{"id":"1.229554916","rc":[{"atb":[[6.4,4.3],[5.2,8.29]],"id":51562794},{"atb":[[1.48,48.39],[1.38,91.69]],"id":46292327},{"atl":[[4.4,0.15]],"id":46292327},{"atb":[[2.64,21.24],[2.84,12.62]],"id":65788088},{"atb":[[1.07,497.76],[1.17,136.64]],"id":65293046},{"atl":[[3,0.26]],"id":65293046},{"atb":[[1.88,26.39],[1.78,44.66]],"id":70003370},{"atl":[[7.8,0.07]],"id":70003370}],"con":true,"img":false}]}
{"op":"mcm","clk":"11450335548","pt":1717320688697,"mc":[{"id":"1.229554916","rc":[{"spn":2.97,"spf":"NaN","id":46292327},{"atb":[[1.01,2.35]],"id":65788088},{"spn":10.42,"spf":"NaN","id":65788088},{"spn":4.86,"spf":"NaN","id":70003370}],"con":true,"img":false}]}
{"op":"mcm","clk":"11450335565","pt":1717320688884,"mc":[{"id":"1.229554916","rc":[{"atb":[[1.01,2.3]],"id":65788088}],"con":true,"img":false}]}
{"op":"mcm","clk":"11450335582","pt":1717320689086,"mc":[{"id":"1.229554916","rc":[{"atb":[[1.01,0]],"id":65788088}],"con":true,"img":false}]}
{"op":"mcm","clk":"11450335591","pt":1717320689147,"mc":[{"id":"1.229554916","rc":[{"atb":[[2.7,2.3]],"id":65788088}],"con":true,"img":false}]}
{"op":"mcm","clk":"11450335761","pt":1717320691480,"mc":[{"id":"1.229554916","rc":[{"atb":[[1.52,34.16]],"id":46292327},{"atl":[[12,0]],"id":46292327}],"con":true,"img":false}]}
{"op":"mcm","clk":"11450335765","pt":1717320691584,"mc":[{"id":"1.229554916","rc":[{"atl":[[10.5,7.55]],"id":46292327}],"con":true,"img":false}]}
{"op":"mcm","clk":"11450336829","pt":1717320705182,"mc":[{"id":"1.229554916","rc":[{"atb":[[5.2,0]],"id":42099039}],"con":true,"img":false}]}
{"op":"mcm","clk":"11450336840","pt":1717320705282,"mc":[{"id":"1.229554916","rc":[{"atb":[[5.9,8.98]],"id":42099039}],"con":true,"img":false}]}
{"op":"mcm","clk":"11450338022","pt":1717320719376,"mc":[{"id":"1.229554916","rc":[{"atb":[[1.44,0]],"id":46292327},{"atb":[[1.56,0]],"id":70003370}],"con":true,"img":false}]}
{"op":"mcm","clk":"11450338033","pt":1717320719477,"mc":[{"id":"1.229554916","rc":[{"atb":[[1.49,91.25]],"id":46292327},{"atb":[[1.79,37.08]],"id":70003370}],"con":true,"img":false}]}
{"op":"mcm","clk":"11450339220","pt":1717320734007,"mc":[{"id":"1.229554916","rc":[{"atb":[[1.93,0]],"id":70003370}],"con":true,"img":false}]}
{"op":"mcm","clk":"11450340377","pt":1717320747327,"mc":[{"id":"1.229554916","rc":[{"atb":[[1.49,0]],"id":46292327},{"atl":[[17,0]],"id":56606596},{"atl":[[19,0]],"id":65788088},{"atb":[[1.08,0]],"id":64927898}],"con":true,"img":false}]}
{"op":"mcm","clk":"11450340387","pt":1717320747426,"mc":[{"id":"1.229554916","rc":[{"atb":[[1.39,91.25]],"id":46292327},{"atl":[[18.5,2.64]],"id":56606596},{"atl":[[22,2.61]],"id":65788088},{"atb":[[1.07,99.3]],"id":64927898}],"con":true,"img":false}]}
{"op":"mcm","clk":"11450340501","pt":1717320749040,"mc":[{"id":"1.229554916","rc":[{"atb":[[1.92,4.26]],"id":70003370},{"spn":4.86,"spf":"NaN","id":70003370},{"spn":1.64,"spf":"NaN","id":64927898}],"con":true,"img":false}]}
{"op":"mcm","clk":"11450341710","pt":1717320764269,"mc":[{"id":"1.229554916","rc":[{"atb":[[5.3,0]],"id":51562794},{"atl":[[10.5,3.56]],"id":46292327},{"atb":[[2.04,0]],"id":65788088},{"atl":[[2.6,26.15]],"id":64927898}],"con":true,"img":false}]}
{"op":"mcm","clk":"11450341719","pt":1717320764328,"mc":[{"id":"1.229554916","rc":[{"atb":[[5.5,9.73]],"id":51562794},{"atl":[[9.2,3.98]],"id":46292327},{"atb":[[2.14,33.67]],"id":65788088},{"atl":[[2.9,0]],"id":64927898}],"con":true,"img":false}]}
{"op":"mcm","clk":"11450341725","pt":1717320764431,"mc":[{"id":"1.229554916","rc":[{"atl":[[9,3.99]],"id":46292327}],"con":true,"img":false}]}
{"op":"mcm","clk":"11450341736","pt":1717320764533,"mc":[{"id":"1.229554916","rc":[{"atl":[[10,0]],"id":46292327}],"con":true,"img":false}]}
{"op":"mcm","clk":"11450343340","pt":1717320784260,"mc":[{"id":"1.229554916","rc":[{"atb":[[2.74,0],[3.5,21.04]],"id":51562794},{"atb":[[1.1,0],[1.17,61.36]],"id":56606596},{"atb":[[1.15,0],[1.3,48.71]],"id":65788088}],"con":true,"img":false}]}
{"op":"mcm","clk":"11450343505","pt":1717320786433,"mc":[{"id":"1.229554916","rc":[{"atb":[[5.3,9.41],[4.4,0]],"id":51562794},{"atb":[[1.81,0]],"id":65788088},{"atl":[[12.5,0]],"id":70003370},{"atl":[[3.1,0]],"id":64927898}],"con":true,"img":false}]}
{"op":"mcm","clk":"11450343512","pt":1717320786532,"mc":[{"id":"1.229554916","rc":[{"atb":[[1.91,41.65]],"id":65788088},{"atl":[[11,3.45]],"id":70003370},{"atl":[[2.86,20.4]],"id":64927898}],"con":true,"img":false}]}
{"op":"mcm","clk":"11450344073","pt":1717320793628,"mc":[{"id":"1.229554916","rc":[{"atb":[[1.92,8.89]],"id":70003370}],"con":true,"img":false}]}
{"op":"mcm","clk":"11450344080","pt":1717320793730,"mc":[{"id":"1.229554916","rc":[{"atb":[[1.25,32.74]],"id":65293046}],"con":true,"img":false}]}
{"op":"mcm","clk":"11450344103","pt":1717320794046,"mc":[{"id":"1.229554916","rc":[{"atb":[[1.54,15.16]],"id":46292327}],"con":true,"img":false}]}
{"op":"mcm","clk":"11450344125","pt":1717320794361,"mc":[{"id":"1.229554916","rc":[{"atb":[[2.54,5.32]],"id":56606596}],"con":true,"img":false}]}
{"op":"mcm","clk":"11450344149","pt":1717320794674,"mc":[{"id":"1.229554916","rc":[{"atb":[[2.7,4.81]],"id":65788088}],"con":true,"img":false}]}
{"op":"mcm","clk":"11450345885","pt":1717320816496,"mc":[{"id":"1.229554916","rc":[{"atb":[[6.2,0]],"id":42099039},{"atb":[[1.24,0]],"id":65293046}],"con":true,"img":false}]}
{"op":"mcm","clk":"11450345896","pt":1717320816598,"mc":[{"id":"1.229554916","rc":[{"atb":[[6,8.72]],"id":42099039},{"atb":[[1.26,76.09]],"id":65293046}],"con":true,"img":false}]}
{"op":"mcm","clk":"11450345986","pt":1717320817688,"mc":[{"id":"1.229554916","rc":[{"atb":[[5.9,0]],"id":42099039}],"con":true,"img":false}]}
{"op":"mcm","clk":"11450345995","pt":1717320817794,"mc":[{"id":"1.229554916","rc":[{"atb":[[5.1,8.98]],"id":42099039}],"con":true,"img":false}]}
{"op":"mcm","clk":"11450346484","pt":1717320823869,"mc":[{"id":"1.229554916","rc":[{"atb":[[1.25,17.04]],"id":65293046}],"con":true,"img":false}]}
{"op":"mcm","clk":"11450346504","pt":1717320824074,"mc":[{"id":"1.229554916","rc":[{"atb":[[1.27,14.53]],"id":65293046}],"con":true,"img":false}]}
{"op":"mcm","clk":"11450346676","pt":1717320826369,"mc":[{"id":"1.229554916","rc":[{"atb":[[2.14,0]],"id":65788088}],"con":true,"img":false}]}
{"op":"mcm","clk":"11450346684","pt":1717320826474,"mc":[{"id":"1.229554916","rc":[{"atb":[[2.16,33.67]],"id":65788088}],"con":true,"img":false}]}
{"op":"mcm","clk":"11450348384","pt":1717320845526,"mc":[{"id":"1.229554916","rc":[{"atb":[[1.25,0]],"id":65293046}],"con":true,"img":false}]}
{"op":"mcm","clk":"11450350220","pt":1717320866409,"mc":[{"id":"1.229554916","rc":[{"atb":[[5.1,0]],"id":42099039}],"con":true,"img":false}]}
{"op":"mcm","clk":"11450350229","pt":1717320866513,"mc":[{"id":"1.229554916","rc":[{"atb":[[5.9,8.98]],"id":42099039}],"con":true,"img":false}]}
{"op":"mcm","clk":"11450351162","pt":1717320877143,"mc":[{"id":"1.229554916","rc":[{"atb":[[1.27,30.32]],"id":65293046},{"spn":2.13,"spf":"NaN","id":65293046}],"con":true,"img":false}]}
{"op":"mcm","clk":"11450353605","pt":1717320906357,"mc":[{"id":"1.229554916","rc":[{"atb":[[1.26,0]],"id":65293046}],"con":true,"img":false}]}
{"op":"mcm","clk":"11450353613","pt":1717320906460,"mc":[{"id":"1.229554916","rc":[{"atb":[[1.28,76.09]],"id":65293046}],"con":true,"img":false}]}
{"op":"mcm","clk":"11450354038","pt":1717320911275,"mc":[{"id":"1.229554916","rc":[{"atb":[[1.27,14.53]],"id":65293046}],"con":true,"img":false}]}
{"op":"mcm","clk":"11450354271","pt":1717320914077,"mc":[{"id":"1.229554916","rc":[{"atb":[[1.27,0]],"id":65293046}],"con":true,"img":false}]}
{"op":"mcm","clk":"11450354292","pt":1717320914281,"mc":[{"id":"1.229554916","rc":[{"atb":[[1.29,13.53]],"id":65293046}],"con":true,"img":false}]}
{"op":"mcm","clk":"11450354471","pt":1717320916476,"mc":[{"id":"1.229554916","rc":[{"atb":[[1.28,0]],"id":65293046}],"con":true,"img":false}]}
{"op":"mcm","clk":"11450354476","pt":1717320916579,"mc":[{"id":"1.229554916","rc":[{"atb":[[1.23,76.09]],"id":65293046}],"con":true,"img":false}]}
{"op":"mcm","clk":"11450354552","pt":1717320917564,"mc":[{"id":"1.229554916","rc":[{"atl":[[18,2.62]],"id":65788088}],"con":true,"img":false}]}
{"op":"mcm","clk":"11450354560","pt":1717320917668,"mc":[{"id":"1.229554916","rc":[{"atl":[[18,0],[21,2.61],[22,7.37]],"id":65788088}],"con":true,"img":false}]}
{"op":"mcm","clk":"11450356091","pt":1717320936395,"mc":[{"id":"1.229554916","rc":[{"atb":[[6,0]],"id":42099039}],"con":true,"img":false}]}
{"op":"mcm","clk":"11450356102","pt":1717320936497,"mc":[{"id":"1.229554916","rc":[{"atb":[[6.2,8.72]],"id":42099039}],"con":true,"img":false}]}
{"op":"mcm","clk":"11450357441","pt":1717320953434,"mc":[{"id":"1.229554916","rc":[{"spn":11.92,"spf":"NaN","id":65788088},{"atb":[[1.24,17.75]],"id":65293046},{"spn":2.14,"spf":"NaN","id":65293046}],"con":true,"img":false}]}
{"op":"mcm","clk":"11450360377","pt":1717320990281,"mc":[{"id":"1.229554916","rc":[{"atb":[[6.4,0],[5.2,0]],"id":51562794},{"atb":[[1.48,0],[1.38,0]],"id":46292327},{"atl":[[4.4,0]],"id":46292327},{"atb":[[2.68,0],[2.48,0]],"id":56606596},{"atl":[[18.5,2.61]],"id":56606596},{"atb":[[2.64,0],[2.84,0]],"id":65788088},{"atb":[[5.8,0],[7.6,0]],"id":42099039},{"atb":[[1.07,0],[1.17,0]],"id":65293046},{"atl":[[3,0]],"id":65293046},{"atb":[[1.88,0],[1.78,0]],"id":70003370},{"atl":[[7.8,0]],"id":70003370},{"atb":[[1.01,0]],"id":64927898},{"atl":[[2.22,0]],"id":64927898}],"con":true,"img":false}]}
{"op":"mcm","clk":"11450360732","pt":1717320994200,"mc":[{"id":"1.229554916","rc":[{"atb":[[1.29,0]],"id":65293046}],"con":true,"img":false}]}
{"op":"mcm","clk":"11450360823","pt":1717320995354,"mc":[{"id":"1.229554916","rc":[{"atb":[[2.54,2.76]],"id":56606596},{"atb":[[2.7,2.5]],"id":65788088}],"con":true,"img":false}]}
{"op":"mcm","clk":"11450360911","pt":1717320996384,"mc":[{"id":"1.229554916","rc":[{"atb":[[4.6,11.5]],"id":51562794},{"atb":[[1.51,57.44]],"id":70003370}],"con":true,"img":false}]}
{"op":"mcm","clk":"11450360920","pt":1717320996488,"mc":[{"id":"1.229554916","rc":[{"atb":[[5.3,0]],"id":51562794},{"atb":[[5.9,0]],"id":42099039},{"atb":[[1.79,0]],"id":70003370}],"con":true,"img":false}]}
{"op":"mcm","clk":"11450360927","pt":1717320996545,"mc":[{"id":"1.229554916","rc":[{"atb":[[5.3,8.98]],"id":42099039}],"con":true,"img":false}]}
{"op":"mcm","clk":"11450361461","pt":1717321003775,"mc":[{"id":"1.229554916","rc":[{"atb":[[1.24,34.1]],"id":65293046}],"con":true,"img":false}]}
{"op":"mcm","clk":"11450362070","pt":1717321011617,"mc":[{"id":"1.229554916","rc":[{"atb":[[5,8.71],[6,4.64]],"id":51562794},{"atb":[[1.43,81.02],[1.53,43.82]],"id":46292327},{"atl":[[4.8,0.13]],"id":46292327},{"atb":[[2.64,14.16],[2.44,24.19]],"id":56606596},{"atl":[[17.5,0.03]],"id":56606596},{"atb":[[2.88,12.35],[2.68,20.73]],"id":65788088},{"atb":[[6.2,15.42],[8.2,3.22]],"id":42099039},{"atb":[[1.15,154.86],[1.05,696.87]],"id":65293046},{"atl":[[2.98,0.26]],"id":65293046},{"atb":[[1.84,27.65],[1.74,47.08]],"id":70003370},{"atl":[[7.6,0.07]],"id":70003370},{"atb":[[1.01,5807.26]],"id":64927898},{"atl":[[2.22,0.42]],"id":64927898}],"con":true,"img":false}]}
{"op":"mcm","clk":"11450362482","pt":1717321016377,"mc":[{"id":"1.229554916","rc":[{"spn":28.0,"spf":"NaN","id":51562794},{"spn":3.17,"spf":"NaN","id":46292327},{"spn":9.32,"spf":"NaN","id":56606596},{"spn":11.94,"spf":"NaN","id":65788088},{"spn":49.1,"spf":"NaN","id":42099039},{"atb":[[1.23,0]],"id":65293046},{"spn":2.11,"spf":"NaN","id":65293046},{"spn":4.76,"spf":"NaN","id":70003370}],"con":true,"img":false}]}
{"op":"mcm","clk":"11450362492","pt":1717321016480,"mc":[{"id":"1.229554916","rc":[{"atb":[[1.25,76.09]],"id":65293046}],"con":true,"img":false}]}
{"op":"mcm","clk":"11450362643","pt":1717321018600,"mc":[{"id":"1.229554916","rc":[{"atb":[[1.54,7.89]],"id":46292327},{"atb":[[1.24,17.75]],"id":65293046}],"con":true,"img":false}]}
{"op":"mcm","clk":"11450362661","pt":1717321018807,"mc":[{"id":"1.229554916","rc":[{"atb":[[1.55,7.13]],"id":46292327},{"atb":[[1.26,15.09]],"id":65293046}],"con":true,"img":false}]}
{"op":"mcm","clk":"11450363161","pt":1717321025336,"mc":[{"id":"1.229554916","rc":[{"atb":[[1.54,0]],"id":46292327},{"atb":[[2.54,0]],"id":56606596},{"atb":[[2.7,0]],"id":65788088},{"atb":[[1.24,0]],"id":65293046},{"atb":[[1.92,4.26]],"id":70003370}],"con":true,"img":false}]}
{"op":"mcm","clk":"11450363875","pt":1717321034415,"mc":[{"id":"1.229554916","rc":[{"atb":[[2.5,2.61]],"id":56606596}],"con":true,"img":false}]}
{"op":"mcm","clk":"11450363880","pt":1717321034521,"mc":[{"id":"1.229554916","rc":[{"atb":[[1.01,2.35]],"id":65788088}],"con":true,"img":false}]}
{"op":"mcm","clk":"11450363946","pt":1717321035034,"mc":[{"id":"1.229554916","rc":[{"atb":[[1.01,2.25]],"id":65788088}],"con":true,"img":false}]}
{"op":"mcm","clk":"11450363983","pt":1717321035451,"mc":[{"id":"1.229554916","rc":[{"atb":[[1.01,0]],"id":65788088}],"con":true,"img":false}]}
{"op":"mcm","clk":"11450363992","pt":1717321035551,"mc":[{"id":"1.229554916","rc":[{"atb":[[2.74,2.25]],"id":65788088}],"con":true,"img":false}]}
{"op":"mcm","clk":"11450364076","pt":1717321036439,"mc":[{"id":"1.229554916","rc":[{"atb":[[1.54,54.25],[1.52,0]],"id":46292327}],"con":true,"img":false}]}
{"op":"mcm","clk":"11450364697","pt":1717321044348,"mc":[{"id":"1.229554916","rc":[{"atb":[[2.74,19.46],[3.5,0]],"id":51562794},{"atb":[[4.5,0],[3,24.41]],"id":42099039}],"con":true,"img":false}]}
{"op":"mcm","clk":"11450365043","pt":1717321048940,"mc":[{"id":"1.229554916","rc":[{"atb":[[1.55,0]],"id":46292327}],"con":true,"img":false}]}
{"op":"mcm","clk":"11450365057","pt":1717321049164,"mc":[{"id":"1.229554916","rc":[{"atb":[[1.56,7.01]],"id":46292327}],"con":true,"img":false}]}
{"op":"mcm","clk":"11450365544","pt":1717321055843,"mc":[{"id":"1.229554916","rc":[{"atb":[[1.26,31.48]],"id":65293046}],"con":true,"img":false}]}
{"op":"mcm","clk":"11450365579","pt":1717321056359,"mc":[{"id":"1.229554916","rc":[{"atb":[[1.87,4.89]],"id":70003370}],"con":true,"img":false}]}
{"op":"mcm","clk":"11450365588","pt":1717321056463,"mc":[{"id":"1.229554916","rc":[{"atb":[[4.6,0]],"id":51562794},{"atb":[[1.39,0]],"id":46292327},{"atb":[[1.51,0],[1.75,39.06]],"id":70003370}],"con":true,"img":false}]}
{"op":"mcm","clk":"11450365596","pt":1717321056566,"mc":[{"id":"1.229554916","rc":[{"atb":[[5.1,11.5]],"id":51562794},{"atb":[[1.44,91.25]],"id":46292327}],"con":true,"img":false}]}
{"op":"mcm","clk":"11450365606","pt":1717321056668,"mc":[{"id":"1.229554916","rc":[{"atb":[[2.5,5.45]],"id":56606596}],"con":true,"img":false}]}
{"op":"mcm","clk":"11450365623","pt":1717321056880,"mc":[{"id":"1.229554916","rc":[{"atb":[[1.56,14.62]],"id":46292327}],"con":true,"img":false}]}
{"op":"mcm","clk":"11450365637","pt":1717321057088,"mc":[{"id":"1.229554916","rc":[{"atb":[[2.74,4.69]],"id":65788088}],"con":true,"img":false}]}
{"op":"mcm","clk":"11450366166","pt":1717321064243,"mc":[{"id":"1.229554916","rc":[{"atb":[[1.92,0]],"id":70003370}],"con":true,"img":false}]}
{"op":"mcm","clk":"11450366965","pt":1717321076365,"mc":[{"id":"1.229554916","rc":[{"atb":[[1.25,0]],"id":65293046}],"con":true,"img":false}]}
{"op":"mcm","clk":"11450366972","pt":1717321076454,"mc":[{"id":"1.229554916","rc":[{"spn":3.18,"spf":"NaN","id":46292327},{"atb":[[1.27,76.09]],"id":65293046},{"spn":2.12,"spf":"NaN","id":65293046},{"spn":4.73,"spf":"NaN","id":70003370}],"con":true,"img":false}]}
{"op":"mcm","clk":"11450367159","pt":1717321079672,"mc":[{"id":"1.229554916","rc":[{"atb":[[1.26,16.38]],"id":65293046},{"atb":[[1.87,9.41]],"id":70003370}],"con":true,"img":false}]}
{"op":"mcm","clk":"11450367200","pt":1717321080297,"mc":[{"id":"1.229554916","rc":[{"atb":[[1.28,14.02]],"id":65293046}],"con":true,"img":false}]}
{"op":"mcm","clk":"11450367656","pt":1717321086406,"mc":[{"id":"1.229554916","rc":[{"atb":[[1.27,0]],"id":65293046}],"con":true,"img":false}]}
{"op":"mcm","clk":"11450367662","pt":1717321086508,"mc":[{"id":"1.229554916","rc":[{"atb":[[1.23,76.09]],"id":65293046}],"con":true,"img":false}]}
{"op":"mcm","clk":"11450368482","pt":1717321098506,"mc":[{"id":"1.229554916","rc":[{"atb":[[1.26,0]],"id":65293046}],"con":true,"img":false}]}
{"op":"mcm","clk":"11450368824","pt":1717321103218,"mc":[{"id":"1.229554916","rc":[{"atb":[[2.74,0],[3.5,18.44]],"id":51562794},{"atb":[[4,20.8],[3,0]],"id":42099039}],"con":true,"img":false}]}
{"op":"mcm","clk":"11450368901","pt":1717321104407,"mc":[{"id":"1.229554916","rc":[{"atb":[[2.74,19.46],[3.5,0]],"id":51562794},{"atb":[[4,0],[3,24.41]],"id":42099039}],"con":true,"img":false}]}
{"op":"mcm","clk":"11450369589","pt":1717321114638,"mc":[{"id":"1.229554916","rc":[{"atb":[[2.74,0],[3.5,18.44]],"id":51562794},{"atb":[[4,20.8],[3,0]],"id":42099039}],"con":true,"img":false}]}
{"op":"mcm","clk":"11450369657","pt":1717321115835,"mc":[{"id":"1.229554916","rc":[{"atb":[[3.5,0]],"id":51562794},{"atb":[[4,0]],"id":42099039}],"con":true,"img":false}]}
{"op":"mcm","clk":"11450369663","pt":1717321115944,"mc":[{"id":"1.229554916","rc":[{"atb":[[2.74,19.46]],"id":51562794},{"atb":[[3,24.41]],"id":42099039}],"con":true,"img":false}]}
{"op":"mcm","clk":"11450370981","pt":1717321135849,"mc":[{"id":"1.229554916","rc":[{"atb":[[2.74,0],[3.5,18.44]],"id":51562794},{"atb":[[4,20.8],[3,0]],"id":42099039},{"atb":[[1.24,17.75]],"id":65293046}],"con":true,"img":false}]}
{"op":"mcm","clk":"11450372827","pt":1717321161276,"mc":[{"id":"1.229554916","rc":[{"atb":[[1.28,0]],"id":65293046},{"spn":2.11,"spf":"NaN","id":65293046}],"con":true,"img":false}]}
{"op":"mcm","clk":"11450373373","pt":1717321169261,"mc":[{"id":"1.229554916","rc":[{"atb":[[1.24,34.1]],"id":65293046}],"con":true,"img":false}]}
{"op":"mcm","clk":"11450375038","pt":1717321196361,"mc":[{"id":"1.229554916","rc":[{"atb":[[1.23,0]],"id":65293046}],"con":true,"img":false}]}
{"op":"mcm","clk":"11450375048","pt":1717321196467,"mc":[{"id":"1.229554916","rc":[{"atb":[[1.25,76.09]],"id":65293046}],"con":true,"img":false}]}
{"op":"mcm","clk":"11450375210","pt":1717321199478,"mc":[{"id":"1.229554916","rc":[{"atb":[[1.24,17.75]],"id":65293046}],"con":true,"img":false}]}
{"op":"mcm","clk":"11450375249","pt":1717321200050,"mc":[{"id":"1.229554916","rc":[{"atb":[[1.26,15.09]],"id":65293046}],"con":true,"img":false}]}
{"op":"mcm","clk":"11450376688","pt":1717321224893,"mc":[{"id":"1.229554916","rc":[{"atb":[[1.24,0]],"id":65293046},{"spn":2.12,"spf":"NaN","id":65293046}],"con":true,"img":false}]}
{"op":"mcm","clk":"11450378898","pt":1717321261637,"mc":[{"id":"1.229554916","rc":[{"atb":[[1.26,31.48]],"id":65293046}],"con":true,"img":false}]}
{"op":"mcm","clk":"11450380592","pt":1717321286459,"mc":[{"id":"1.229554916","rc":[{"atb":[[1.25,0]],"id":65293046}],"con":true,"img":false}]}
{"op":"mcm","clk":"11450380599","pt":1717321286562,"mc":[{"id":"1.229554916","rc":[{"atb":[[1.27,76.09]],"id":65293046}],"con":true,"img":false}]}
{"op":"mcm","clk":"11450381009","pt":1717321292573,"mc":[{"id":"1.229554916","rc":[{"atb":[[1.26,16.38]],"id":65293046}],"con":true,"img":false}]}
{"op":"mcm","clk":"11450381027","pt":1717321292730,"mc":[{"id":"1.229554916","rc":[{"atb":[[1.28,14.02]],"id":65293046}],"con":true,"img":false}]}
{"op":"mcm","clk":"11450381072","pt":1717321293354,"mc":[{"id":"1.229554916","rc":[{"atb":[[1.26,0]],"id":65293046}],"con":true,"img":false}]}
{"op":"mcm","clk":"11450381263","pt":1717321296476,"mc":[{"id":"1.229554916","rc":[{"atb":[[1.27,0]],"id":65293046}],"con":true,"img":false}]}
{"op":"mcm","clk":"11450381271","pt":1717321296584,"mc":[{"id":"1.229554916","rc":[{"atb":[[1.23,76.09]],"id":65293046}],"con":true,"img":false}]}
{"op":"mcm","clk":"11450382285","pt":1717321314011,"mc":[{"id":"1.229554916","rc":[{"atb":[[5,0],[6,0]],"id":51562794},{"atb":[[1.43,0],[1.53,0]],"id":46292327},{"atl":[[4.8,0]],"id":46292327},{"atb":[[2.64,0],[2.44,0]],"id":56606596},{"atl":[[17.5,0]],"id":56606596},{"atb":[[2.88,0],[2.68,0]],"id":65788088},{"atb":[[6.2,8.72],[8.2,0]],"id":42099039},{"atb":[[1.15,0],[1.05,0]],"id":65293046},{"atl":[[2.98,0]],"id":65293046},{"atb":[[1.84,0],[1.74,0]],"id":70003370},{"atl":[[7.6,0]],"id":70003370},{"atb":[[1.01,0]],"id":64927898},{"atl":[[2.22,0]],"id":64927898}],"con":true,"img":false}]}
{"op":"mcm","clk":"11450382417","pt":1717321316409,"mc":[{"id":"1.229554916","rc":[{"atb":[[1.46,36.39],[1.54,0]],"id":46292327},{"atb":[[1.51,57.44],[1.75,0]],"id":70003370}],"con":true,"img":false}]}
{"op":"mcm","clk":"11450382428","pt":1717321316514,"mc":[{"id":"1.229554916","rc":[{"atb":[[5.1,0]],"id":51562794},{"atb":[[1.44,0]],"id":46292327}],"con":true,"img":false}]}
{"op":"mcm","clk":"11450382436","pt":1717321316618,"mc":[{"id":"1.229554916","rc":[{"atb":[[4.6,11.5]],"id":51562794},{"atb":[[1.38,91.25]],"id":46292327}],"con":true,"img":false}]}
{"op":"mcm","clk":"11450382817","pt":1717321322299,"mc":[{"id":"1.229554916","rc":[{"atb":[[2.5,2.83]],"id":56606596},{"atb":[[2.74,2.44]],"id":65788088}],"con":true,"img":false}]}
{"op":"mcm","clk":"11450383329","pt":1717321330840,"mc":[{"id":"1.229554916","rc":[{"atb":[[1.56,7.01]],"id":46292327},{"atb":[[2.5,0]],"id":56606596},{"atb":[[2.74,0]],"id":65788088},{"atb":[[1.87,4.51]],"id":70003370}],"con":true,"img":false}]}
{"op":"mcm","clk":"11450383352","pt":1717321331249,"mc":[{"id":"1.229554916","rc":[{"atb":[[1.24,17.75]],"id":65293046}],"con":true,"img":false}]}
{"op":"mcm","clk":"11450383457","pt":1717321332852,"mc":[{"id":"1.229554916","rc":[{"atb":[[4.9,8.93],[5.9,4.73]],"id":51562794},{"atb":[[1.43,81.02],[1.53,43.82]],"id":46292327},{"atl":[[4.8,0.13]],"id":46292327},{"atb":[[2.46,23.86],[2.66,13.99]],"id":56606596},{"atl":[[18,0.03]],"id":56606596},{"atb":[[2.82,12.76],[2.62,21.5]],"id":65788088},{"atb":[[7.4,3.63],[5.7,7.41]],"id":42099039},{"atb":[[1.18,129.05],[1.08,435.54]],"id":65293046},{"atl":[[3,0.26]],"id":65293046},{"atb":[[1.86,27.01],[1.76,45.84]],"id":70003370},{"atl":[[7.6,0.07]],"id":70003370},{"atb":[[1.01,5807.26]],"id":64927898},{"atl":[[2.2,0.43]],"id":64927898}],"con":true,"img":false}]}
{"op":"mcm","clk":"11450383781","pt":1717321337845,"mc":[{"id":"1.229554916","rc":[{"atb":[[1.87,0]],"id":70003370}],"con":true,"img":false}]}
{"op":"mcm","clk":"11450383799","pt":1717321338052,"mc":[{"id":"1.229554916","rc":[{"atb":[[1.89,4.41]],"id":70003370}],"con":true,"img":false}]}
{"op":"mcm","clk":"11450384720","pt":1717321354102,"mc":[{"id":"1.229554916","rc":[{"spn":27.95,"spf":"NaN","id":51562794},{"atb":[[2.52,2.58]],"id":56606596},{"spn":9.33,"spf":"NaN","id":56606596},{"atb":[[1.01,2.35]],"id":65788088},{"spn":11.91,"spf":"NaN","id":65788088},{"spn":48.7,"spf":"NaN","id":42099039},{"spn":4.74,"spf":"NaN","id":70003370},{"spn":2.14,"spf":"NaN","id":65293046},{"spn":1.63,"spf":"NaN","id":64927898}],"con":true,"img":false}]}
{"op":"mcm","clk":"11450384743","pt":1717321354364,"mc":[{"id":"1.229554916","rc":[{"atb":[[1.01,2.33]],"id":65788088}],"con":true,"img":false}]}
{"op":"mcm","clk":"11450384785","pt":1717321354993,"mc":[{"id":"1.229554916","rc":[{"atb":[[1.01,0]],"id":65788088}],"con":true,"img":false}]}
{"op":"mcm","clk":"11450384792","pt":1717321355092,"mc":[{"id":"1.229554916","rc":[{"atb":[[2.68,2.33]],"id":65788088}],"con":true,"img":false}]}
{"op":"mcm","clk":"11450384941","pt":1717321357583,"mc":[{"id":"1.229554916","rc":[{"atb":[[2.74,19.46]],"id":51562794},{"atb":[[3,17.44]],"id":42099039}],"con":true,"img":false}]}
{"op":"mcm","clk":"11450384948","pt":1717321357690,"mc":[{"id":"1.229554916","rc":[{"atb":[[3.5,0]],"id":51562794},{"atb":[[4,0]],"id":42099039}],"con":true,"img":false}]}
{"op":"mcm","clk":"11450385051","pt":1717321359679,"mc":[{"id":"1.229554916","rc":[{"atb":[[3.5,18.67]],"id":51562794},{"atb":[[4,17.32]],"id":42099039}],"con":true,"img":false}]}
{"op":"mcm","clk":"11450385055","pt":1717321359776,"mc":[{"id":"1.229554916","rc":[{"atb":[[2.74,0]],"id":51562794},{"atb":[[3,0]],"id":42099039}],"con":true,"img":false}]}
{"op":"mcm","clk":"11450385063","pt":1717321359883,"mc":[{"id":"1.229554916","rc":[{"atb":[[2.74,19.46],[3.5,0]],"id":51562794},{"atb":[[4,0],[3,17.44]],"id":42099039}],"con":true,"img":false}]}
{"op":"mcm","clk":"11450385108","pt":1717321360609,"mc":[{"id":"1.229554916","rc":[{"atb":[[2.74,0],[3.5,18.67]],"id":51562794},{"atb":[[4,17.32],[3,0]],"id":42099039}],"con":true,"img":false}]}
{"op":"mcm","clk":"11450385115","pt":1717321360710,"mc":[{"id":"1.229554916","rc":[{"atb":[[3.5,0]],"id":51562794},{"atb":[[3,17.32]],"id":42099039}],"con":true,"img":false}]}
{"op":"mcm","clk":"11450385118","pt":1717321360768,"mc":[{"id":"1.229554916","rc":[{"atb":[[2.74,19.46]],"id":51562794},{"atb":[[4,0]],"id":42099039}],"con":true,"img":false}]}
{"op":"mcm","clk":"11450385167","pt":1717321361902,"mc":[{"id":"1.229554916","rc":[{"atb":[[4,17.26],[3,0]],"id":42099039}],"con":true,"img":false}]}
{"op":"mcm","clk":"11450385207","pt":1717321362589,"mc":[{"id":"1.229554916","rc":[{"atb":[[3,17.44]],"id":42099039}],"con":true,"img":false}]}
{"op":"mcm","clk":"11450385214","pt":1717321362693,"mc":[{"id":"1.229554916","rc":[{"atb":[[4,0]],"id":42099039}],"con":true,"img":false}]}
{"op":"mcm","clk":"11450385424","pt":1717321366386,"mc":[{"id":"1.229554916","rc":[{"atb":[[1.54,54.25]],"id":46292327}],"con":true,"img":false}]}
{"op":"mcm","clk":"11450385428","pt":1717321366487,"mc":[{"id":"1.229554916","rc":[{"atb":[[1.46,0]],"id":46292327}],"con":true,"img":false}]}
{"op":"mcm","clk":"11450385521","pt":1717321368001,"mc":[{"id":"1.229554916","rc":[{"atb":[[1.28,0]],"id":65293046}],"con":true,"img":false}]}
{"op":"mcm","clk":"11450385553","pt":1717321368418,"mc":[{"id":"1.229554916","rc":[{"atb":[[4.6,0]],"id":51562794},{"atb":[[1.38,0]],"id":46292327},{"atb":[[5.3,0]],"id":42099039},{"atb":[[1.51,0],[1.77,38.05]],"id":70003370}],"con":true,"img":false}]}
{"op":"mcm","clk":"11450385561","pt":1717321368515,"mc":[{"id":"1.229554916","rc":[{"atb":[[5,11.5]],"id":51562794},{"atb":[[1.44,91.25]],"id":46292327},{"atb":[[5.8,8.98]],"id":42099039},{"atb":[[1.24,34.1]],"id":65293046}],"con":true,"img":false}]}
{"op":"mcm","clk":"11450385829","pt":1717321372787,"mc":[{"id":"1.229554916","rc":[{"atb":[[1.89,9.2]],"id":70003370}],"con":true,"img":false}]}
{"op":"mcm","clk":"11450385843","pt":1717321372995,"mc":[{"id":"1.229554916","rc":[{"atb":[[2.52,5.38]],"id":56606596}],"con":true,"img":false}]}
{"op":"mcm","clk":"11450385860","pt":1717321373302,"mc":[{"id":"1.229554916","rc":[{"atb":[[1.56,14.62]],"id":46292327}],"con":true,"img":false}]}
{"op":"mcm","clk":"11450385892","pt":1717321373775,"mc":[{"id":"1.229554916","rc":[{"atb":[[2.68,4.87]],"id":65788088}],"con":true,"img":false}]}
{"op":"mcm","clk":"11450385924","pt":1717321374290,"mc":[{"id":"1.229554916","rc":[{"atb":[[3.5,18.67]],"id":51562794}],"con":true,"img":false}]}
{"op":"mcm","clk":"11450385929","pt":1717321374391,"mc":[{"id":"1.229554916","rc":[{"atb":[[2.74,0]],"id":51562794}],"con":true,"img":false}]}
{"op":"mcm","clk":"11450386005","pt":1717321375896,"mc":[{"id":"1.229554916","rc":[{"atb":[[4,17.32]],"id":42099039}],"con":true,"img":false}]}
{"op":"mcm","clk":"11450386013","pt":1717321375992,"mc":[{"id":"1.229554916","rc":[{"atb":[[3,0]],"id":42099039}],"con":true,"img":false}]}
{"op":"mcm","clk":"11450386531","pt":1717321384811,"mc":[{"id":"1.229554916","rc":[{"atb":[[1.56,7.6]],"id":46292327}],"con":true,"img":false}]}
{"op":"mcm","clk":"11450386564","pt":1717321385282,"mc":[{"id":"1.229554916","rc":[{"atb":[[1.56,14.62]],"id":46292327}],"con":true,"img":false}]}
{"op":"mcm","clk":"11450387333","pt":1717321396423,"mc":[{"id":"1.229554916","rc":[{"atb":[[6.2,0]],"id":42099039},{"atb":[[1.23,0]],"id":65293046}],"con":true,"img":false}]}
{"op":"mcm","clk":"11450387341","pt":1717321396543,"mc":[{"id":"1.229554916","rc":[{"atb":[[6.4,8.72]],"id":42099039},{"atb":[[1.25,76.09]],"id":65293046}],"con":true,"img":false}]}
{"op":"mcm","clk":"11450387757","pt":1717321402710,"mc":[{"id":"1.229554916","rc":[{"atb":[[1.24,17.75]],"id":65293046}],"con":true,"img":false}]}
{"op":"mcm","clk":"11450387771","pt":1717321402933,"mc":[{"id":"1.229554916","rc":[{"atb":[[1.26,15.09]],"id":65293046}],"con":true,"img":false}]}
{"op":"mcm","clk":"11450387964","pt":1717321406455,"mc":[{"id":"1.229554916","rc":[{"atb":[[5.5,0]],"id":51562794}],"con":true,"img":false}]}
{"op":"mcm","clk":"11450387973","pt":1717321406555,"mc":[{"id":"1.229554916","rc":[{"atb":[[6,9.73]],"id":51562794}],"con":true,"img":false}]}
{"op":"mcm","clk":"11450388232","pt":1717321411016,"mc":[{"id":"1.229554916","rc":[{"atb":[[1.24,0]],"id":65293046}],"con":true,"img":false}]}
{"op":"mcm","clk":"11450390633","pt":1717321451178,"mc":[{"id":"1.229554916","rc":[{"spn":28.0,"spf":"NaN","id":51562794},{"atb":[[1.26,31.48]],"id":65293046},{"spn":2.13,"spf":"NaN","id":65293046}],"con":true,"img":false}]}
{"op":"mcm","clk":"11450391068","pt":1717321457572,"mc":[{"id":"1.229554916","rc":[{"atb":[[1.43,90.59]],"id":46292327},{"atb":[[1.9,8.1]],"id":56606596},{"atb":[[1.21,19.14]],"id":65293046},{"atb":[[1.05,48.8]],"id":64927898}],"con":true,"img":false}]}
{"op":"mcm","clk":"11450392051","pt":1717321473812,"mc":[{"id":"1.229554916","rc":[{"atb":[[2.74,19.46]],"id":51562794},{"atb":[[3,17.44]],"id":42099039}],"con":true,"img":false}]}
{"op":"mcm","clk":"11450392057","pt":1717321473918,"mc":[{"id":"1.229554916","rc":[{"atb":[[3.5,0]],"id":51562794},{"atb":[[4,0]],"id":42099039}],"con":true,"img":false}]}
{"op":"mcm","clk":"11450392140","pt":1717321475428,"mc":[{"id":"1.229554916","rc":[{"atb":[[2.74,0],[3.5,18.67]],"id":51562794},{"atb":[[4,17.32],[3,0]],"id":42099039}],"con":true,"img":false}]}
{"op":"mcm","clk":"11450392208","pt":1717321476532,"mc":[{"id":"1.229554916","rc":[{"atb":[[1.25,0]],"id":65293046}],"con":true,"img":false}]}
{"op":"mcm","clk":"11450392215","pt":1717321476628,"mc":[{"id":"1.229554916","rc":[{"atb":[[1.27,76.09]],"id":65293046}],"con":true,"img":false}]}
{"op":"mcm","clk":"11450393023","pt":1717321487611,"mc":[{"id":"1.229554916","rc":[{"atb":[[1.26,15.09]],"id":65293046}],"con":true,"img":false}]}
{"op":"mcm","clk":"11450393112","pt":1717321488947,"mc":[{"id":"1.229554916","rc":[{"atb":[[1.26,0]],"id":65293046}],"con":true,"img":false}]}
{"op":"mcm","clk":"11450393542","pt":1717321496454,"mc":[{"id":"1.229554916","rc":[{"atb":[[1.27,0]],"id":65293046}],"con":true,"img":false}]}
{"op":"mcm","clk":"11450393550","pt":1717321496511,"mc":[{"id":"1.229554916","rc":[{"atb":[[1.9,0]],"id":56606596},{"atb":[[1.23,76.09]],"id":65293046}],"con":true,"img":false}]}
{"op":"mcm","clk":"11450393626","pt":1717321497545,"mc":[{"id":"1.229554916","rc":[{"atb":[[2.16,43.24]],"id":65788088},{"atb":[[1.77,46.64]],"id":70003370}],"con":true,"img":false}]}
{"op":"mcm","clk":"11450394669","pt":1717321512640,"mc":[{"id":"1.229554916","rc":[{"atb":[[1.24,16.35]],"id":65293046},{"spn":2.12,"spf":"NaN","id":65293046}],"con":true,"img":false}]}
{"op":"mcm","clk":"11450394744","pt":1717321513753,"mc":[{"id":"1.229554916","rc":[{"atl":[[2.68,6.3]],"id":64927898}],"con":true,"img":false}]}
{"op":"mcm","clk":"11450394817","pt":1717321514784,"mc":[{"id":"1.229554916","rc":[{"atb":[[1.97,46.64]],"id":56606596}],"con":true,"img":false}]}
{"op":"mcm","clk":"11450395613","pt":1717321526056,"mc":[{"id":"1.229554916","rc":[{"atb":[[1.24,34.1]],"id":65293046}],"con":true,"img":false}]}
{"op":"mcm","clk":"11450397008","pt":1717321546487,"mc":[{"id":"1.229554916","rc":[{"atb":[[1.23,0]],"id":65293046}],"con":true,"img":false}]}
{"op":"mcm","clk":"11450397015","pt":1717321546588,"mc":[{"id":"1.229554916","rc":[{"atb":[[1.25,76.09]],"id":65293046}],"con":true,"img":false}]}
{"op":"mcm","clk":"11450397552","pt":1717321554513,"mc":[{"id":"1.229554916","rc":[{"atb":[[1.24,17.75]],"id":65293046}],"con":true,"img":false}]}
{"op":"mcm","clk":"11450397567","pt":1717321554718,"mc":[{"id":"1.229554916","rc":[{"atb":[[1.26,15.09]],"id":65293046}],"con":true,"img":false}]}
{"op":"mcm","clk":"11450397732","pt":1717321557414,"mc":[{"id":"1.229554916","rc":[{"atb":[[1.21,0]],"id":65293046}],"con":true,"img":false}]}
{"op":"mcm","clk":"11450397739","pt":1717321557509,"mc":[{"id":"1.229554916","rc":[{"atb":[[1.21,19.14]],"id":65293046}],"con":true,"img":false}]}
{"op":"mcm","clk":"11450398223","pt":1717321564106,"mc":[{"id":"1.229554916","rc":[{"atb":[[1.24,0]],"id":65293046}],"con":true,"img":false}]}
{"op":"mcm","clk":"11450400807","pt":1717321599084,"mc":[{"id":"1.229554916","rc":[{"atb":[[1.26,31.48]],"id":65293046},{"spn":2.13,"spf":"NaN","id":65293046}],"con":true,"img":false}]}
{"op":"mcm","clk":"11450402408","pt":1717321621343,"mc":[{"id":"1.229554916","rc":[{"atb":[[1.21,0]],"id":65293046}],"con":true,"img":false}]}
{"op":"mcm","clk":"11450402469","pt":1717321622034,"mc":[{"id":"1.229554916","rc":[{"atb":[[6,0]],"id":51562794},{"atb":[[1.25,0]],"id":65293046}],"con":true,"img":false}]}
{"op":"mcm","clk":"11450402477","pt":1717321622133,"mc":[{"id":"1.229554916","rc":[{"atb":[[5.4,9.73]],"id":51562794},{"atb":[[1.27,76.09]],"id":65293046}],"con":true,"img":false}]}
{"op":"mcm","clk":"11450402502","pt":1717321622438,"mc":[{"id":"1.229554916","rc":[{"atb":[[1.25,19.14]],"id":65293046}],"con":true,"img":false}]}
{"op":"mcm","clk":"11450403352","pt":1717321633567,"mc":[{"id":"1.229554916","rc":[{"atb":[[1.26,15.09]],"id":65293046}],"con":true,"img":false}]}
{"op":"mcm","clk":"11450403437","pt":1717321634552,"mc":[{"id":"1.229554916","rc":[{"atb":[[1.27,0]],"id":65293046}],"con":true,"img":false}]}
{"op":"mcm","clk":"11450403447","pt":1717321634657,"mc":[{"id":"1.229554916","rc":[{"atb":[[1.25,0],[1.23,76.09]],"id":65293046}],"con":true,"img":false}]}
{"op":"mcm","clk":"11450404540","pt":1717321649668,"mc":[{"id":"1.229554916","rc":[{"atb":[[5.4,0]],"id":51562794}],"con":true,"img":false}]}
{"op":"mcm","clk":"11450404546","pt":1717321649772,"mc":[{"id":"1.229554916","rc":[{"atb":[[6,9.73]],"id":51562794}],"con":true,"img":false}]}
{"op":"mcm","clk":"11450404643","pt":1717321651068,"mc":[{"id":"1.229554916","rc":[{"atb":[[2.74,19.46]],"id":51562794},{"atb":[[4,0],[3,17.44]],"id":42099039}],"con":true,"img":false}]}
{"op":"mcm","clk":"11450404649","pt":1717321651173,"mc":[{"id":"1.229554916","rc":[{"atb":[[3.5,0]],"id":51562794}],"con":true,"img":false}]}
{"op":"mcm","clk":"11450406111","pt":1717321670997,"mc":[{"id":"1.229554916","rc":[{"atb":[[1.24,17.75]],"id":65293046}],"con":true,"img":false}]}
{"op":"mcm","clk":"11450406136","pt":1717321671404,"mc":[{"id":"1.229554916","rc":[{"atb":[[1.21,19.14]],"id":65293046}],"con":true,"img":false}]}
{"op":"mcm","clk":"11450406688","pt":1717321678828,"mc":[{"id":"1.229554916","rc":[{"atb":[[4.9,0],[5.9,0]],"id":51562794},{"atb":[[1.43,9.57],[1.53,0]],"id":46292327},{"atl":[[4.8,0]],"id":46292327},{"atb":[[2.46,0],[2.66,0]],"id":56606596},{"atl":[[18,0]],"id":56606596},{"atb":[[2.82,0],[2.62,0]],"id":65788088},{"atb":[[7.4,0],[5.7,0]],"id":42099039},{"atb":[[1.18,0],[1.08,0]],"id":65293046},{"atl":[[3,0]],"id":65293046},{"atb":[[1.86,0],[1.76,0]],"id":70003370},{"atl":[[7.6,0]],"id":70003370},{"atb":[[1.01,0]],"id":64927898},{"atl":[[2.2,0]],"id":64927898}],"con":true,"img":false}]}
{"op":"mcm","clk":"11450406746","pt":1717321679634,"mc":[{"id":"1.229554916","rc":[{"atb":[[1.51,57.44]],"id":70003370}],"con":true,"img":false}]}
{"op":"mcm","clk":"11450406752","pt":1717321679710,"mc":[{"id":"1.229554916","rc":[{"atb":[[6,0]],"id":51562794},{"atb":[[1.44,0]],"id":46292327},{"atb":[[1.77,8.59]],"id":70003370}],"con":true,"img":false}]}
{"op":"mcm","clk":"11450406758","pt":1717321679817,"mc":[{"id":"1.229554916","rc":[{"atb":[[5.4,9.73]],"id":51562794},{"atb":[[1.43,11],[1.38,91.25]],"id":46292327},{"atb":[[2.16,33.67]],"id":65788088},{"atb":[[1.77,0]],"id":70003370}],"con":true,"img":false}]}
{"op":"mcm","clk":"11450406772","pt":1717321680025,"mc":[{"id":"1.229554916","rc":[{"atb":[[1.43,9.57]],"id":46292327}],"con":true,"img":false}]}
{"op":"mcm","clk":"11450406833","pt":1717321680915,"mc":[{"id":"1.229554916","rc":[{"atb":[[2.08,9.57]],"id":65788088},{"atb":[[1.48,8.59]],"id":70003370}],"con":true,"img":false}]}
{"op":"mcm","clk":"11450406952","pt":1717321682530,"mc":[{"id":"1.229554916","rc":[{"atb":[[1.05,52.07]],"id":64927898}],"con":true,"img":false}]}
{"op":"mcm","clk":"11450406967","pt":1717321682739,"mc":[{"id":"1.229554916","rc":[{"atb":[[1.05,48.8]],"id":64927898}],"con":true,"img":false}]}
{"op":"mcm","clk":"11450406975","pt":1717321682842,"mc":[{"id":"1.229554916","rc":[{"atb":[[1.21,0]],"id":65293046}],"con":true,"img":false}]}
{"op":"mcm","clk":"11450408129","pt":1717321698177,"mc":[{"id":"1.229554916","rc":[{"atb":[[4.8,9.17],[5.8,4.83]],"id":51562794},{"atb":[[1.49,47.4],[1.39,89.34]],"id":46292327},{"atl":[[4.4,0.15]],"id":46292327},{"atb":[[2.46,23.86],[2.66,13.99]],"id":56606596},{"atl":[[18,0.03]],"id":56606596},{"atb":[[2.88,12.35],[2.68,25.61]],"id":65788088},{"atb":[[5.8,16.24],[7.6,3.52]],"id":42099039},{"atb":[[1.07,497.76],[1.17,136.64]],"id":65293046},{"atl":[[3,0.26]],"id":65293046},{"atb":[[1.85,27.33],[1.75,46.45]],"id":70003370},{"atl":[[7.6,0.07]],"id":70003370},{"atb":[[1.01,5807.26]],"id":64927898},{"atl":[[2.24,0.42]],"id":64927898}],"con":true,"img":false}]}
{"op":"mcm","clk":"11450408417","pt":1717321701746,"mc":[{"id":"1.229554916","rc":[{"atb":[[2.52,2.8]],"id":56606596},{"atb":[[2.68,23.27]],"id":65788088},{"atb":[[1.26,0]],"id":65293046}],"con":true,"img":false}]}
{"op":"mcm","clk":"11450408462","pt":1717321702268,"mc":[{"id":"1.229554916","rc":[{"atb":[[1.54,0]],"id":46292327},{"atb":[[1.24,34.1]],"id":65293046}],"con":true,"img":false}]}
{"op":"mcm","clk":"11450408473","pt":1717321702368,"mc":[{"id":"1.229554916","rc":[{"atb":[[1.5,54.25]],"id":46292327}],"con":true,"img":false}]}
{"op":"mcm","clk":"11450408987","pt":1717321709562,"mc":[{"id":"1.229554916","rc":[{"atb":[[1.56,7.01]],"id":46292327},{"atb":[[2.68,20.73]],"id":65788088},{"atb":[[1.89,4.41]],"id":70003370}],"con":true,"img":false}]}
{"op":"mcm","clk":"11450409529","pt":1717321716773,"mc":[{"id":"1.229554916","rc":[{"atb":[[1.21,19.14]],"id":65293046}],"con":true,"img":false}]}
{"op":"mcm","clk":"11450410156","pt":1717321724782,"mc":[{"id":"1.229554916","rc":[{"atb":[[2.52,5.38]],"id":56606596},{"atb":[[1.01,2.35]],"id":65788088}],"con":true,"img":false}]}
{"op":"mcm","clk":"11450410182","pt":1717321725094,"mc":[{"id":"1.229554916","rc":[{"atb":[[1.48,0]],"id":70003370}],"con":true,"img":false}]}
{"op":"mcm","clk":"11450410297","pt":1717321726492,"mc":[{"id":"1.229554916","rc":[{"atb":[[1.01,2.25]],"id":65788088}],"con":true,"img":false}]}
{"op":"mcm","clk":"11450410371","pt":1717321727327,"mc":[{"id":"1.229554916","rc":[{"atb":[[5.4,0]],"id":51562794},{"atb":[[1.23,0]],"id":65293046}],"con":true,"img":false}]}
{"op":"mcm","clk":"11450410383","pt":1717321727383,"mc":[{"id":"1.229554916","rc":[{"atb":[[5.9,9.73]],"id":51562794},{"atb":[[1.01,0]],"id":65788088},{"atb":[[1.25,76.09]],"id":65293046}],"con":true,"img":false}]}
{"op":"mcm","clk":"11450410391","pt":1717321727483,"mc":[{"id":"1.229554916","rc":[{"atb":[[2.74,2.25]],"id":65788088}],"con":true,"img":false}]}
{"op":"mcm","clk":"11450410591","pt":1717321729915,"mc":[{"id":"1.229554916","rc":[{"atb":[[1.21,0]],"id":65293046}],"con":true,"img":false}]}
{"op":"mcm","clk":"11450410786","pt":1717321732207,"mc":[{"id":"1.229554916","rc":[{"spn":27.95,"spf":"NaN","id":51562794},{"spn":2.98,"spf":"NaN","id":46292327},{"spn":11.94,"spf":"NaN","id":65788088},{"spn":48.8,"spf":"NaN","id":42099039},{"spn":2.12,"spf":"NaN","id":65293046},{"atb":[[1.76,38.54]],"id":70003370},{"spn":1.65,"spf":"NaN","id":64927898}],"con":true,"img":false}]}
{"op":"mcm","clk":"11450410796","pt":1717321732365,"mc":[{"id":"1.229554916","rc":[{"atb":[[1.51,0]],"id":70003370}],"con":true,"img":false}]}
{"op":"mcm","clk":"11450410976","pt":1717321734404,"mc":[{"id":"1.229554916","rc":[{"atb":[[1.48,8.59]],"id":70003370}],"con":true,"img":false}]}
{"op":"mcm","clk":"11450411196","pt":1717321737215,"mc":[{"id":"1.229554916","rc":[{"atb":[[1.38,0]],"id":46292327}],"con":true,"img":false}]}
{"op":"mcm","clk":"11450411206","pt":1717321737319,"mc":[{"id":"1.229554916","rc":[{"atb":[[1.4,91.25]],"id":46292327}],"con":true,"img":false}]}
{"op":"mcm","clk":"11450411687","pt":1717321742601,"mc":[{"id":"1.229554916","rc":[{"atb":[[1.89,0]],"id":70003370}],"con":true,"img":false}]}
{"op":"mcm","clk":"11450411711","pt":1717321742806,"mc":[{"id":"1.229554916","rc":[{"atb":[[1.24,17.75]],"id":65293046}],"con":true,"img":false}]}
{"op":"mcm","clk":"11450411759","pt":1717321743222,"mc":[{"id":"1.229554916","rc":[{"atb":[[1.26,15.09]],"id":65293046}],"con":true,"img":false}]}
{"op":"mcm","clk":"11450412312","pt":1717321749310,"mc":[{"id":"1.229554916","rc":[{"atb":[[1.88,4.84]],"id":70003370}],"con":true,"img":false}]}
{"op":"mcm","clk":"11450412413","pt":1717321750611,"mc":[{"id":"1.229554916","rc":[{"atb":[[1.52,8.19]],"id":46292327}],"con":true,"img":false}]}
{"op":"mcm","clk":"11450412471","pt":1717321751123,"mc":[{"id":"1.229554916","rc":[{"atb":[[2.74,4.69]],"id":65788088}],"con":true,"img":false}]}
{"op":"mcm","clk":"11450412491","pt":1717321751337,"mc":[{"id":"1.229554916","rc":[{"atb":[[1.24,0]],"id":65293046}],"con":true,"img":false}]}
{"op":"mcm","clk":"11450412816","pt":1717321754826,"mc":[{"id":"1.229554916","rc":[{"atb":[[6.4,0]],"id":42099039}],"con":true,"img":false}]}
{"op":"mcm","clk":"11450412822","pt":1717321754932,"mc":[{"id":"1.229554916","rc":[{"atb":[[6.6,8.72]],"id":42099039}],"con":true,"img":false}]}
{"op":"mcm","clk":"11450413312","pt":1717321761019,"mc":[{"id":"1.229554916","rc":[{"atb":[[1.23,19.14]],"id":65293046}],"con":true,"img":false}]}
{"op":"mcm","clk":"11450413733","pt":1717321765844,"mc":[{"id":"1.229554916","rc":[{"atb":[[1.88,9.29]],"id":70003370}],"con":true,"img":false}]}
{"op":"mcm","clk":"11450413969","pt":1717321768859,"mc":[{"id":"1.229554916","rc":[{"atb":[[1.48,0]],"id":70003370}],"con":true,"img":false}]}
{"op":"mcm","clk":"11450414728","pt":1717321777354,"mc":[{"id":"1.229554916","rc":[{"atb":[[6.6,0]],"id":42099039}],"con":true,"img":false}]}
{"op":"mcm","clk":"11450414739","pt":1717321777456,"mc":[{"id":"1.229554916","rc":[{"atb":[[6.8,8.72]],"id":42099039}],"con":true,"img":false}]}
{"op":"mcm","clk":"11450415232","pt":1717321782460,"mc":[{"id":"1.229554916","rc":[{"atb":[[4.8,0],[5.8,0]],"id":51562794},{"atb":[[1.49,0],[1.39,0]],"id":46292327},{"atl":[[4.4,0]],"id":46292327},{"atb":[[2.46,0],[2.66,0]],"id":56606596},{"atl":[[18,0]],"id":56606596},{"atb":[[2.88,0],[2.68,0]],"id":65788088},{"atb":[[5.8,8.98],[7.6,0]],"id":42099039},{"atb":[[1.85,0],[1.75,0]],"id":70003370},{"atl":[[7.6,0]],"id":70003370},{"atb":[[1.07,0],[1.17,0]],"id":65293046},{"atl":[[3,0]],"id":65293046},{"atb":[[1.01,0]],"id":64927898},{"atl":[[2.24,0]],"id":64927898}],"con":true,"img":false}]}
{"op":"mcm","clk":"11450415347","pt":1717321783659,"mc":[{"id":"1.229554916","rc":[{"atb":[[1.48,8.59]],"id":70003370}],"con":true,"img":false}]}
{"op":"mcm","clk":"11450415399","pt":1717321784285,"mc":[{"id":"1.229554916","rc":[{"atb":[[1.56,0]],"id":46292327}],"con":true,"img":false}]}
{"op":"mcm","clk":"11450415461","pt":1717321784855,"mc":[{"id":"1.229554916","rc":[{"atb":[[5.9,0]],"id":51562794},{"atb":[[6.8,0]],"id":42099039},{"atb":[[1.51,57.44],[1.76,0]],"id":70003370}],"con":true,"img":false}]}
{"op":"mcm","clk":"11450415469","pt":1717321784959,"mc":[{"id":"1.229554916","rc":[{"atb":[[5.4,9.73]],"id":51562794},{"atb":[[6.2,8.72]],"id":42099039}],"con":true,"img":false}]}
{"op":"mcm","clk":"11450415986","pt":1717321791483,"mc":[{"id":"1.229554916","rc":[{"atb":[[5.1,8.49],[6.2,4.46]],"id":51562794},{"atb":[[1.41,84.98],[1.51,45.54]],"id":46292327},{"atl":[[4.6,0.14]],"id":46292327},{"atb":[[2.72,13.5],[2.52,28.31]],"id":56606596},{"atb":[[2.64,21.24],[2.84,12.62]],"id":65788088},{"atb":[[5.8,16.24],[7.6,3.52]],"id":42099039},{"atb":[[1.85,27.33],[1.75,46.45]],"id":70003370},{"atl":[[7.6,0.07]],"id":70003370},{"atb":[[1.16,145.18],[1.06,580.72]],"id":65293046},{"atl":[[2.98,0.26]],"id":65293046},{"atb":[[1.01,5807.26]],"id":64927898},{"atl":[[2.2,0.43]],"id":64927898}],"con":true,"img":false}]}
{"op":"mcm","clk":"11450416145","pt":1717321793359,"mc":[{"id":"1.229554916","rc":[{"spn":28.1,"spf":"NaN","id":51562794},{"atb":[[1.52,0]],"id":46292327},{"spn":3.05,"spf":"NaN","id":46292327},{"atb":[[2.52,25.5]],"id":56606596},{"spn":9.36,"spf":"NaN","id":56606596},{"atb":[[2.74,2.25]],"id":65788088},{"spn":11.92,"spf":"NaN","id":65788088},{"spn":4.74,"spf":"NaN","id":70003370},{"spn":2.12,"spf":"NaN","id":65293046},{"spn":1.63,"spf":"NaN","id":64927898}],"con":true,"img":false}]}
{"op":"mcm","clk":"11450416177","pt":1717321793665,"mc":[{"id":"1.229554916","rc":[{"atb":[[1.26,31.48]],"id":65293046}],"con":true,"img":false}]}
{"op":"mcm","clk":"11450417188","pt":1717321804597,"mc":[{"id":"1.229554916","rc":[{"atb":[[1.53,7.4]],"id":46292327},{"atb":[[2.52,22.92]],"id":56606596}],"con":true,"img":false}]}
{"op":"mcm","clk":"11450417202","pt":1717321804806,"mc":[{"id":"1.229554916","rc":[{"atb":[[2.58,2.48]],"id":56606596}],"con":true,"img":false}]}
{"op":"mcm","clk":"11450417748","pt":1717321810475,"mc":[{"id":"1.229554916","rc":[{"atb":[[1.48,0]],"id":70003370}],"con":true,"img":false}]}
{"op":"mcm","clk":"11450418433","pt":1717321817463,"mc":[{"id":"1.229554916","rc":[{"atb":[[1.25,0]],"id":65293046}],"con":true,"img":false}]}
{"op":"mcm","clk":"11450418444","pt":1717321817571,"mc":[{"id":"1.229554916","rc":[{"atb":[[1.27,76.09]],"id":65293046}],"con":true,"img":false}]}
{"op":"mcm","clk":"11450418666","pt":1717321819967,"mc":[{"id":"1.229554916","rc":[{"atb":[[1.5,0]],"id":46292327}],"con":true,"img":false}]}
{"op":"mcm","clk":"11450418676","pt":1717321820068,"mc":[{"id":"1.229554916","rc":[{"atb":[[1.52,54.25]],"id":46292327},{"atb":[[1.23,0]],"id":65293046}],"con":true,"img":false}]}
{"op":"mcm","clk":"11450418778","pt":1717321821162,"mc":[{"id":"1.229554916","rc":[{"atb":[[1.25,19.14]],"id":65293046}],"con":true,"img":false}]}
{"op":"mcm","clk":"11450418896","pt":1717321822561,"mc":[{"id":"1.229554916","rc":[{"atb":[[1.43,0]],"id":46292327}],"con":true,"img":false}]}
{"op":"mcm","clk":"11450419120","pt":1717321824544,"mc":[{"id":"1.229554916","rc":[{"atb":[[2.08,0]],"id":65788088}],"con":true,"img":false}]}
{"op":"mcm","clk":"11450419156","pt":1717321824964,"mc":[{"id":"1.229554916","rc":[{"atb":[[1.51,0],[1.76,38.54]],"id":70003370}],"con":true,"img":false}]}
{"op":"mcm","clk":"11450419314","pt":1717321826775,"mc":[{"id":"1.229554916","rc":[{"atb":[[1.53,0]],"id":46292327},{"atb":[[1.26,16.38]],"id":65293046}],"con":true,"img":false}]}
{"op":"mcm","clk":"11450419341","pt":1717321827083,"mc":[{"id":"1.229554916","rc":[{"atb":[[1.54,7.26]],"id":46292327},{"atb":[[1.28,14.02]],"id":65293046}],"con":true,"img":false}]}
{"op":"mcm","clk":"11450419350","pt":1717321827188,"mc":[{"id":"1.229554916","rc":[{"atb":[[1.48,14.74]],"id":70003370}],"con":true,"img":false}]}
{"op":"mcm","clk":"11450419357","pt":1717321827240,"mc":[{"id":"1.229554916","rc":[{"atb":[[1.25,0]],"id":65293046}],"con":true,"img":false}]}
{"op":"mcm","clk":"11450419374","pt":1717321827451,"mc":[{"id":"1.229554916","rc":[{"atb":[[1.27,0]],"id":65293046}],"con":true,"img":false}]}
{"op":"mcm","clk":"11450419383","pt":1717321827554,"mc":[{"id":"1.229554916","rc":[{"atb":[[1.23,76.09]],"id":65293046}],"con":true,"img":false}]}
{"op":"mcm","clk":"11450419458","pt":1717321828591,"mc":[{"id":"1.229554916","rc":[{"atb":[[2.16,43.24]],"id":65788088}],"con":true,"img":false}]}
{"op":"mcm","clk":"11450419565","pt":1717321830000,"mc":[{"id":"1.229554916","rc":[{"atb":[[1.4,0]],"id":46292327}],"con":true,"img":false}]}
{"op":"mcm","clk":"11450419576","pt":1717321830062,"mc":[{"id":"1.229554916","rc":[{"atb":[[1.42,91.25]],"id":46292327}],"con":true,"img":false}]}
{"op":"mcm","clk":"11450419669","pt":1717321831349,"mc":[{"id":"1.229554916","rc":[{"atb":[[2.58,5.18]],"id":56606596}],"con":true,"img":false}]}
{"op":"mcm","clk":"11450419681","pt":1717321831551,"mc":[{"id":"1.229554916","rc":[{"atb":[[2.7,2.5]],"id":65788088}],"con":true,"img":false}]}
{"op":"mcm","clk":"11450419688","pt":1717321831659,"mc":[{"id":"1.229554916","rc":[{"atb":[[1.26,0]],"id":65293046}],"con":true,"img":false}]}
{"op":"mcm","clk":"11450419705","pt":1717321831868,"mc":[{"id":"1.229554916","rc":[{"atb":[[2.16,33.67]],"id":65788088}],"con":true,"img":false}]}
{"op":"mcm","clk":"11450419720","pt":1717321831981,"mc":[{"id":"1.229554916","rc":[{"atb":[[1.54,15.16]],"id":46292327}],"con":true,"img":false}]}
{"op":"mcm","clk":"11450420623","pt":1717321842506,"mc":[{"id":"1.229554916","rc":[{"atb":[[5,0],[5.2,9.41]],"id":51562794}],"con":true,"img":false}]}
{"op":"mcm","clk":"11450421219","pt":1717321849920,"mc":[{"id":"1.229554916","rc":[{"atb":[[1.48,0]],"id":70003370}],"con":true,"img":false}]}
{"op":"mcm","clk":"11450421229","pt":1717321850026,"mc":[{"id":"1.229554916","rc":[{"atb":[[5.4,0]],"id":51562794}],"con":true,"img":false}]}
{"op":"mcm","clk":"11450421236","pt":1717321850081,"mc":[{"id":"1.229554916","rc":[{"atb":[[5.6,9.73]],"id":51562794}],"con":true,"img":false}]}
{"op":"mcm","clk":"11450422050","pt":1717321860125,"mc":[{"id":"1.229554916","rc":[{"spn":3.07,"spf":"NaN","id":46292327},{"atb":[[1.28,31.67]],"id":65293046},{"atl":[[5.2,17.65]],"id":65293046},{"spn":2.13,"spf":"NaN","id":65293046}],"con":true,"img":false}]}
{"op":"mcm","clk":"11450422059","pt":1717321860229,"mc":[{"id":"1.229554916","rc":[{"atb":[[1.56,2.5],[1.21,19.14],[1.48,10],[1.52,5]],"id":65293046},{"atl":[[3.45,10],[3.25,5],[3.05,2.5]],"id":65293046}],"con":true,"img":false}]}
{"op":"mcm","clk":"11450422077","pt":1717321860436,"mc":[{"id":"1.229554916","rc":[{"atl":[[16.5,10],[48,1.7],[12.5,2.5],[14.5,5]],"id":51562794},{"atb":[[1.98,2.5]],"id":56606596},{"atl":[[4.6,2.5],[5,5],[5.4,10],[15.5,5.52]],"id":56606596},{"atl":[[20,3.85],[5.5,2.5],[6.6,10],[5.9,5]],"id":65788088},{"atb":[[5.3,5],[4.9,10],[5.7,2.5]],"id":42099039},{"atl":[[17,5],[19,10],[85,0.95],[15,2.5]],"id":42099039},{"atb":[[1.21,0]],"id":65293046},{"atl":[[3.7,2.5],[9.8,9.09],[3.9,5],[4.2,10]],"id":70003370},{"atb":[[1.09,2.5],[1.07,155.52],[1.05,53.8]],"id":64927898},{"atl":[[2.02,10],[1.97,5],[2.58,50.63],[1.93,2.5]],"id":64927898}],"con":true,"img":false}]}
{"op":"mcm","clk":"11450422084","pt":1717321860542,"mc":[{"id":"1.229554916","rc":[{"atl":[[16,2.78],[10.5,10]],"id":56606596},{"atl":[[22,2.61],[12,9.09]],"id":65788088},{"atl":[[100,2.61],[55,2]],"id":42099039},{"atl":[[10,0],[6.8,10]],"id":70003370},{"atb":[[1.05,47.84]],"id":64927898},{"atl":[[2.68,0]],"id":64927898}],"con":true,"img":false}]}
{"op":"mcm","clk":"11450422166","pt":1717321861532,"mc":[{"id":"1.229554916","rc":[{"atb":[[1.44,9.36]],"id":46292327}],"con":true,"img":false}]}
{"op":"mcm","clk":"11450422506","pt":1717321864759,"mc":[{"id":"1.229554916","rc":[{"atb":[[2.74,0]],"id":65788088}],"con":true,"img":false}]}
{"op":"mcm","clk":"11450422514","pt":1717321864840,"mc":[{"id":"1.229554916","rc":[{"atb":[[2.28,2.5],[2.2,5]],"id":65788088}],"con":true,"img":false}]}
{"op":"mcm","clk":"11450422597","pt":1717321865846,"mc":[{"id":"1.229554916","rc":[{"atb":[[1.76,48.11]],"id":70003370}],"con":true,"img":false}]}
{"op":"mcm","clk":"11450422763","pt":1717321867931,"mc":[{"id":"1.229554916","rc":[{"atb":[[2.12,9.57]],"id":65788088}],"con":true,"img":false}]}
{"op":"mcm","clk":"11450422799","pt":1717321868347,"mc":[{"id":"1.229554916","rc":[{"atb":[[1.01,2.35]],"id":65788088}],"con":true,"img":false}]}
{"op":"mcm","clk":"11450422856","pt":1717321869018,"mc":[{"id":"1.229554916","rc":[{"atb":[[1.01,2.3]],"id":65788088}],"con":true,"img":false}]}
{"op":"mcm","clk":"11450422903","pt":1717321869540,"mc":[{"id":"1.229554916","rc":[{"atb":[[1.01,0]],"id":65788088}],"con":true,"img":false}]}
{"op":"mcm","clk":"11450422910","pt":1717321869639,"mc":[{"id":"1.229554916","rc":[{"atb":[[2.7,4.81]],"id":65788088}],"con":true,"img":false}]}
{"op":"mcm","clk":"11450422953","pt":1717321870112,"mc":[{"id":"1.229554916","rc":[{"atb":[[1.24,17.75]],"id":65293046}],"con":true,"img":false}]}
{"op":"mcm","clk":"11450423558","pt":1717321877646,"mc":[{"id":"1.229554916","rc":[{"atb":[[1.56,8.12]],"id":65293046},{"atl":[[2.8,5.62]],"id":65293046}],"con":true,"img":false}]}
{"op":"mcm","clk":"11450423575","pt":1717321877853,"mc":[{"id":"1.229554916","rc":[{"atb":[[1.28,14.02]],"id":65293046},{"atl":[[5.2,0]],"id":65293046}],"con":true,"img":false}]}
{"op":"mcm","clk":"11450423585","pt":1717321877958,"mc":[{"id":"1.229554916","rc":[{"atl":[[12,7.27]],"id":51562794},{"atl":[[4.5,11.38]],"id":56606596},{"atl":[[5.4,11.25]],"id":65788088},{"atl":[[14.5,5.93]],"id":42099039},{"atl":[[3.65,14.48]],"id":70003370},{"atb":[[1.09,13.75]],"id":64927898},{"atl":[[1.88,11.25]],"id":64927898}],"con":true,"img":false}]}
{"op":"mcm","clk":"11450423594","pt":1717321878060,"mc":[{"id":"1.229554916","rc":[{"atl":[[48,0]],"id":51562794},{"atl":[[15.5,0]],"id":56606596},{"atl":[[20,0]],"id":65788088},{"atl":[[85,0]],"id":42099039},{"atl":[[9.8,0]],"id":70003370},{"atb":[[1.07,99.3]],"id":64927898},{"atl":[[2.58,0]],"id":64927898}],"con":true,"img":false}]}
{"op":"mcm","clk":"11450423741","pt":1717321880157,"mc":[{"id":"1.229554916","rc":[{"atb":[[2.12,0]],"id":65788088}],"con":true,"img":false}]}
{"op":"mcm","clk":"11450424154","pt":1717321885076,"mc":[{"id":"1.229554916","rc":[{"atl":[[21,0],[11.5,3.98]],"id":65788088},{"atl":[[90,0],[50,2.61]],"id":42099039},{"atl":[[10.5,0],[6.6,7.47]],"id":70003370},{"atl":[[5.4,0]],"id":65293046}],"con":true,"img":false}]}
{"op":"mcm","clk":"11450424165","pt":1717321885134,"mc":[{"id":"1.229554916","rc":[{"atl":[[4.8,9.51]],"id":65293046}],"con":true,"img":false}]}
{"op":"mcm","clk":"11450424576","pt":1717321890123,"mc":[{"id":"1.229554916","rc":[{"atl":[[16,0],[10,4.65]],"id":56606596}],"con":true,"img":false}]}
{"op":"mcm","clk":"11450425358","pt":1717321900072,"mc":[{"id":"1.229554916","rc":[{"atl":[[9.2,0],[8.2,5.81]],"id":46292327}],"con":true,"img":false}]}
{"op":"mcm","clk":"11450425367","pt":1717321900173,"mc":[{"id":"1.229554916","rc":[{"atl":[[8,3.99],[9,0]],"id":46292327},{"atb":[[2.16,0]],"id":65788088}],"con":true,"img":false}]}
{"op":"mcm","clk":"11450425375","pt":1717321900271,"mc":[{"id":"1.229554916","rc":[{"atb":[[2.18,33.67]],"id":65788088}],"con":true,"img":false}]}
{"op":"mcm","clk":"11450425608","pt":1717321902971,"mc":[{"id":"1.229554916","rc":[{"atb":[[5.1,0],[6.2,0]],"id":51562794},{"atb":[[1.41,0],[1.51,0]],"id":46292327},{"atl":[[4.6,0]],"id":46292327},{"atb":[[2.72,0],[2.52,0]],"id":56606596},{"atb":[[2.64,0],[2.84,0]],"id":65788088},{"atb":[[5.8,8.98],[7.6,0]],"id":42099039},{"atb":[[1.16,0],[1.06,0]],"id":65293046},{"atl":[[2.98,0]],"id":65293046},{"atb":[[1.85,0],[1.75,0]],"id":70003370},{"atl":[[7.6,0]],"id":70003370},{"atb":[[1.01,0]],"id":64927898},{"atl":[[2.2,0]],"id":64927898}],"con":true,"img":false}]}
{"op":"mcm","clk":"11450425618","pt":1717321903079,"mc":[{"id":"1.229554916","rc":[{"atb":[[5.6,22.25],[4.6,2.5],[3.9,10],[4.2,5]],"id":51562794},{"atb":[[6.2,16.92]],"id":42099039},{"atb":[[1.58,5],[1.54,10],[1.62,2.5]],"id":70003370}],"con":true,"img":false}]}
{"op":"mcm","clk":"11450425630","pt":1717321903181,"mc":[{"id":"1.229554916","rc":[{"atb":[[1.97,45.1]],"id":56606596},{"atb":[[1.76,44.45]],"id":70003370}],"con":true,"img":false}]}
{"op":"mcm","clk":"11450425655","pt":1717321903399,"mc":[{"id":"1.229554916","rc":[{"atb":[[1.97,46.64]],"id":56606596},{"atb":[[1.76,48.11]],"id":70003370}],"con":true,"img":false}]}
{"op":"mcm","clk":"11450425820","pt":1717321905071,"mc":[{"id":"1.229554916","rc":[{"atb":[[4.6,14]],"id":51562794},{"atb":[[1.52,56.34]],"id":70003370}],"con":true,"img":false}]}
{"op":"mcm","clk":"11450425830","pt":1717321905172,"mc":[{"id":"1.229554916","rc":[{"atb":[[5.2,0]],"id":51562794},{"atb":[[1.76,9.57]],"id":70003370}],"con":true,"img":false}]}
{"op":"mcm","clk":"11450425841","pt":1717321905279,"mc":[{"id":"1.229554916","rc":[{"atb":[[1.76,0]],"id":70003370}],"con":true,"img":false}]}
{"op":"mcm","clk":"11450425899","pt":1717321905855,"mc":[{"id":"1.229554916","rc":[{"atb":[[2.58,2.48]],"id":56606596},{"atb":[[2.7,2.3]],"id":65788088},{"atb":[[1.88,4.45]],"id":70003370}],"con":true,"img":false}]}
{"op":"mcm","clk":"11450426135","pt":1717321908863,"mc":[{"id":"1.229554916","rc":[{"atb":[[2.58,0]],"id":56606596},{"atb":[[2.7,0]],"id":65788088},{"atb":[[1.28,0]],"id":65293046}],"con":true,"img":false}]}
{"op":"mcm","clk":"11450426141","pt":1717321908966,"mc":[{"id":"1.229554916","rc":[{"atb":[[1.98,14.79]],"id":56606596},{"atb":[[2.28,10]],"id":65788088}],"con":true,"img":false}]}
{"op":"mcm","clk":"11450426174","pt":1717321909485,"mc":[{"id":"1.229554916","rc":[{"atb":[[1.24,34.1]],"id":65293046}],"con":true,"img":false}]}
{"op":"mcm","clk":"11450426490","pt":1717321913706,"mc":[{"id":"1.229554916","rc":[{"atb":[[6.4,4.3],[5.2,8.29]],"id":51562794},{"atb":[[1.41,84.98],[1.51,45.54]],"id":46292327},{"atl":[[4.6,0.14]],"id":46292327},{"atb":[[2.46,23.86],[2.66,13.99]],"id":56606596},{"atl":[[18,0.03]],"id":56606596},{"atb":[[2.64,21.24],[2.84,12.62]],"id":65788088},{"atb":[[5.8,16.24],[7.6,3.52]],"id":42099039},{"atb":[[1.07,497.76],[1.17,136.64]],"id":65293046},{"atl":[[3,0.26]],"id":65293046},{"atb":[[1.84,27.65],[1.74,47.08]],"id":70003370},{"atl":[[7.6,0.07]],"id":70003370},{"atb":[[1.01,5807.26]],"id":64927898},{"atl":[[2.22,0.42]],"id":64927898}],"con":true,"img":false}]}
{"op":"mcm","clk":"11450426508","pt":1717321913868,"mc":[{"id":"1.229554916","rc":[{"atb":[[1.97,45.71]],"id":56606596}],"con":true,"img":false}]}
{"op":"mcm","clk":"11450427057","pt":1717321920092,"mc":[{"id":"1.229554916","rc":[{"atl":[[9.8,4.52]],"id":70003370}],"con":true,"img":false}]}
{"op":"mcm","clk":"11450427065","pt":1717321920194,"mc":[{"id":"1.229554916","rc":[{"spn":9.2,"spf":"NaN","id":51562794},{"spn":3.58,"spf":"NaN","id":56606596},{"spn":4.12,"spf":"NaN","id":65788088},{"spn":11.05,"spf":"NaN","id":42099039},{"atl":[[11,0]],"id":70003370},{"spn":2.76,"spf":"NaN","id":70003370},{"spn":2.18,"spf":"NaN","id":65293046},{"spn":1.48,"spf":"NaN","id":64927898}],"con":true,"img":false}]}
{"op":"mcm","clk":"11450427347","pt":1717321922776,"mc":[{"id":"1.229554916","rc":[{"atl":[[9.2,4.78],[10.5,0]],"id":46292327}],"con":true,"img":false}]}
{"op":"mcm","clk":"11450428119","pt":1717321930174,"mc":[{"id":"1.229554916","rc":[{"atl":[[6.4,10],[5.8,5],[5.5,0],[6.6,0],[5.9,0],[5.4,13.75]],"id":65788088},{"atl":[[16.5,5],[17,0],[18.5,10],[19,0],[14.5,8.43],[15,0]],"id":42099039},{"atl":[[3.85,5],[4.1,10],[3.7,0],[3.9,0],[4.2,0],[3.65,16.98]],"id":70003370},{"atl":[[3.45,0],[3.2,5],[3,2.76],[3.25,0],[3.05,0]],"id":65293046}],"con":true,"img":false}]}
{"op":"mcm","clk":"11450428129","pt":1717321930280,"mc":[{"id":"1.229554916","rc":[{"atb":[[2.52,2.58]],"id":56606596},{"atb":[[1.01,2.35]],"id":65788088}],"con":true,"img":false}]}
{"op":"mcm","clk":"11450428153","pt":1717321930589,"mc":[{"id":"1.229554916","rc":[{"atb":[[1.01,2.3]],"id":65788088}],"con":true,"img":false}]}
{"op":"mcm","clk":"11450428214","pt":1717321931209,"mc":[{"id":"1.229554916","rc":[{"atb":[[1.01,0]],"id":65788088}],"con":true,"img":false}]}
{"op":"mcm","clk":"11450428224","pt":1717321931269,"mc":[{"id":"1.229554916","rc":[{"atb":[[2.7,2.3]],"id":65788088}],"con":true,"img":false}]}
{"op":"mcm","clk":"11450428619","pt":1717321935179,"mc":[{"id":"1.229554916","rc":[{"atb":[[1.23,0]],"id":65293046}],"con":true,"img":false}]}
{"op":"mcm","clk":"11450428632","pt":1717321935279,"mc":[{"id":"1.229554916","rc":[{"atb":[[1.25,76.09]],"id":65293046}],"con":true,"img":false}]}
{"op":"mcm","clk":"11450428964","pt":1717321938113,"mc":[{"id":"1.229554916","rc":[{"atb":[[1.24,16.35]],"id":65293046}],"con":true,"img":false}]}
{"op":"mcm","clk":"11450428984","pt":1717321938319,"mc":[{"id":"1.229554916","rc":[{"atb":[[1.87,4.89]],"id":70003370}],"con":true,"img":false}]}
{"op":"mcm","clk":"11450429011","pt":1717321938629,"mc":[{"id":"1.229554916","rc":[{"atb":[[2.52,5.38]],"id":56606596}],"con":true,"img":false}]}
{"op":"mcm","clk":"11450429021","pt":1717321938683,"mc":[{"id":"1.229554916","rc":[{"atb":[[2.7,4.81]],"id":65788088}],"con":true,"img":false}]}
{"op":"mcm","clk":"11450429406","pt":1717321942693,"mc":[{"id":"1.229554916","rc":[{"atb":[[2.18,0]],"id":65788088},{"atb":[[1.75,39.06],[1.52,0]],"id":70003370}],"con":true,"img":false}]}
{"op":"mcm","clk":"11450429417","pt":1717321942796,"mc":[{"id":"1.229554916","rc":[{"atb":[[2.22,33.67]],"id":65788088}],"con":true,"img":false}]}
{"op":"mcm","clk":"11450429513","pt":1717321943781,"mc":[{"id":"1.229554916","rc":[{"atb":[[1.74,56.9]],"id":70003370}],"con":true,"img":false}]}
{"op":"mcm","clk":"11450429762","pt":1717321946578,"mc":[{"id":"1.229554916","rc":[{"atb":[[3.5,18.33]],"id":51562794}],"con":true,"img":false}]}
{"op":"mcm","clk":"11450429777","pt":1717321946631,"mc":[{"id":"1.229554916","rc":[{"atb":[[2.74,0]],"id":51562794},{"atb":[[4,17.32],[3,0]],"id":42099039}],"con":true,"img":false}]}
{"op":"mcm","clk":"11450429842","pt":1717321947312,"mc":[{"id":"1.229554916","rc":[{"atb":[[1.97,46.64]],"id":56606596}],"con":true,"img":false}]}
{"op":"mcm","clk":"11450429887","pt":1717321947784,"mc":[{"id":"1.229554916","rc":[{"atb":[[1.74,47.08]],"id":70003370}],"con":true,"img":false}]}
{"op":"mcm","clk":"11450430216","pt":1717321952041,"mc":[{"id":"1.229554916","rc":[{"atb":[[1.24,0]],"id":65293046}],"con":true,"img":false}]}
{"op":"mcm","clk":"11450430236","pt":1717321952201,"mc":[{"id":"1.229554916","rc":[{"atb":[[1.26,15.09]],"id":65293046}],"con":true,"img":false}]}
{"op":"mcm","clk":"11450430466","pt":1717321954726,"mc":[{"id":"1.229554916","rc":[{"atb":[[5.6,9.73],[4.6,11.5],[3.9,0],[4.2,0]],"id":51562794},{"atl":[[16.5,0],[12,0],[12.5,0],[14.5,0]],"id":51562794},{"atb":[[1.98,0]],"id":56606596},{"atl":[[4.5,0],[4.6,0],[5,0],[5.4,0]],"id":56606596},{"atb":[[2.28,0],[2.2,0]],"id":65788088},{"atl":[[6.4,0],[5.8,0],[5.4,0]],"id":65788088},{"atb":[[6.2,8.72],[5.3,0],[4.9,0],[5.7,0]],"id":42099039},{"atl":[[16.5,0],[18.5,0],[14.5,0]],"id":42099039},{"atb":[[1.56,0],[1.48,0],[1.52,0]],"id":65293046},{"atl":[[2.8,0],[3.2,0],[3,0.26]],"id":65293046},{"atb":[[1.58,0],[1.54,0],[1.62,0]],"id":70003370},{"atl":[[3.85,0],[4.1,0],[3.65,0]],"id":70003370},{"atb":[[1.09,0],[1.05,42.84]],"id":64927898},{"atl":[[2.02,0],[1.97,0],[1.88,0],[1.93,0]],"id":64927898}],"con":true,"img":false}]}
{"op":"mcm","clk":"11450430475","pt":1717321954819,"mc":[{"id":"1.229554916","rc":[{"atl":[[44,2.33],[50,2.61]],"id":51562794}],"con":true,"img":false}]}
{"op":"mcm","clk":"11450430483","pt":1717321954922,"mc":[{"id":"1.229554916","rc":[{"atl":[[44,0],[50,4.65]],"id":51562794}],"con":true,"img":false}]}
{"op":"mcm","clk":"11450430494","pt":1717321955028,"mc":[{"id":"1.229554916","rc":[{"atl":[[75,2],[50,2.61]],"id":51562794}],"con":true,"img":false}]}
{"op":"mcm","clk":"11450430503","pt":1717321955131,"mc":[{"id":"1.229554916","rc":[{"atl":[[50,4.65]],"id":51562794}],"con":true,"img":false}]}
{"op":"mcm","clk":"11450430514","pt":1717321955236,"mc":[{"id":"1.229554916","rc":[{"atb":[[4.6,0],[5.3,9.41]],"id":51562794},{"atl":[[75,0]],"id":51562794}],"con":true,"img":false}]}
{"op":"mcm","clk":"11450430550","pt":1717321955701,"mc":[{"id":"1.229554916","rc":[{"atb":[[2.12,6.01]],"id":65788088},{"atb":[[1.21,19.14]],"id":65293046},{"atl":[[2.48,6.3]],"id":64927898}],"con":true,"img":false}]}
{"op":"mcm","clk":"11450430713","pt":1717321957728,"mc":[{"id":"1.229554916","rc":[{"atl":[[9.2,5.1],[6.6,0]],"id":70003370}],"con":true,"img":false}]}
{"op":"mcm","clk":"11450430723","pt":1717321957835,"mc":[{"id":"1.229554916","rc":[{"atl":[[9,10.08],[6.8,0]],"id":70003370}],"con":true,"img":false}]}
{"op":"mcm","clk":"11450430918","pt":1717321960229,"mc":[{"id":"1.229554916","rc":[{"atb":[[2.22,0]],"id":65788088}],"con":true,"img":false}]}
{"op":"mcm","clk":"11450430927","pt":1717321960333,"mc":[{"id":"1.229554916","rc":[{"atb":[[2.12,0],[2.18,33.67]],"id":65788088}],"con":true,"img":false}]}
{"op":"mcm","clk":"11450431215","pt":1717321963818,"mc":[{"id":"1.229554916","rc":[{"atl":[[5,3.14]],"id":65293046}],"con":true,"img":false}]}
{"op":"mcm","clk":"11450431698","pt":1717321970134,"mc":[{"id":"1.229554916","rc":[{"atb":[[1.88,0]],"id":70003370}],"con":true,"img":false}]}
{"op":"mcm","clk":"11450431935","pt":1717321973366,"mc":[{"id":"1.229554916","rc":[{"atb":[[1.87,9.41]],"id":70003370}],"con":true,"img":false}]}
{"op":"mcm","clk":"11450432233","pt":1717321976652,"mc":[{"id":"1.229554916","rc":[{"atb":[[1.51,14.17]],"id":70003370}],"con":true,"img":false}]}
{"op":"mcm","clk":"11450432328","pt":1717321977843,"mc":[{"id":"1.229554916","rc":[{"atb":[[1.51,0]],"id":70003370}],"con":true,"img":false}]}
{"op":"mcm","clk":"11450432433","pt":1717321979245,"mc":[{"id":"1.229554916","rc":[{"atb":[[1.26,31.48]],"id":65293046}],"con":true,"img":false}]}
{"op":"mcm","clk":"11450432609","pt":1717321981373,"mc":[{"id":"1.229554916","rc":[{"spn":28.2,"spf":"NaN","id":51562794},{"spn":6.33,"spf":"NaN","id":56606596},{"spn":7.17,"spf":"NaN","id":65788088},{"spn":28.8,"spf":"NaN","id":42099039},{"atb":[[1.01,18.18]],"id":65293046},{"spn":2.13,"spf":"NaN","id":65293046},{"spn":4.73,"spf":"NaN","id":70003370},{"spn":1.64,"spf":"NaN","id":64927898}],"con":true,"img":false}]}
{"op":"mcm","clk":"11450432894","pt":1717321985165,"mc":[{"id":"1.229554916","rc":[{"atb":[[1.17,100]],"id":51562794},{"atb":[[1.17,100]],"id":42099039}],"con":true,"img":false}]}
{"op":"mcm","clk":"11450432906","pt":1717321985268,"mc":[{"id":"1.229554916","rc":[{"atl":[[9.2,0]],"id":70003370}],"con":true,"img":false}]}
{"op":"mcm","clk":"11450432914","pt":1717321985365,"mc":[{"id":"1.229554916","rc":[{"atl":[[8.8,5.1]],"id":70003370}],"con":true,"img":false}]}
{"op":"mcm","clk":"11450432925","pt":1717321985470,"mc":[{"id":"1.229554916","rc":[{"atl":[[9.6,10.16],[9,0]],"id":70003370}],"con":true,"img":false}]}
{"op":"mcm","clk":"11450432998","pt":1717321986188,"mc":[{"id":"1.229554916","rc":[{"atb":[[1.05,56.72]],"id":64927898}],"con":true,"img":false}]}
{"op":"mcm","clk":"11450433129","pt":1717321987957,"mc":[{"id":"1.229554916","rc":[{"atb":[[2.18,43.24]],"id":65788088}],"con":true,"img":false}]}
{"op":"mcm","clk":"11450433431","pt":1717321992562,"mc":[{"id":"1.229554916","rc":[{"atl":[[9.6,0],[8.6,5.11]],"id":70003370}],"con":true,"img":false}]}
{"op":"mcm","clk":"11450433925","pt":1717321998276,"mc":[{"id":"1.229554916","rc":[{"atb":[[2.18,33.67]],"id":65788088}],"con":true,"img":false}]}
{"op":"mcm","clk":"11450434389","pt":1717322002795,"mc":[{"id":"1.229554916","rc":[{"atb":[[1.25,0]],"id":65293046}],"con":true,"img":false}]}
{"op":"mcm","clk":"11450434400","pt":1717322002904,"mc":[{"id":"1.229554916","rc":[{"atb":[[1.27,76.09]],"id":65293046}],"con":true,"img":false}]}
{"op":"mcm","clk":"11450434445","pt":1717322003420,"mc":[{"id":"1.229554916","rc":[{"atl":[[5,0]],"id":65293046}],"con":true,"img":false}]}
{"op":"mcm","clk":"11450434549","pt":1717322004506,"mc":[{"id":"1.229554916","rc":[{"atl":[[5,3.14]],"id":65293046}],"con":true,"img":false}]}
{"op":"mcm","clk":"11450434593","pt":1717322004921,"mc":[{"id":"1.229554916","rc":[{"atl":[[21,1],[23,2.27],[25,3.12],[27,4.81]],"id":51562794},{"atb":[[1.46,250],[1.44,0],[1.5,100],[1.48,156.25],[1.52,92.71]],"id":46292327},{"atl":[[2.92,26.04],[2.88,10.64],[3,62.5],[2.96,38.27]],"id":46292327},{"atl":[[5.1,4.88],[5.3,11.63],[5.5,16.67],[5.7,26.6]],"id":56606596},{"atl":[[5.6,4.35],[6.4,23.15],[5.8,10.42],[6,15]],"id":65788088},{"atb":[[6.2,12.57],[5.5,27.78],[5.7,15.96],[5.9,10.2]],"id":42099039},{"atl":[[32,1.61],[36,2.14],[40,3.21],[29,1]],"id":42099039},{"atb":[[1.21,257.24],[1.19,250],[1.23,86.96],[1.17,386.64]],"id":65293046},{"atl":[[2.36,36.76],[2.4,53.57],[5,0],[2.32,15.15],[2.44,86.81]],"id":65293046},{"atl":[[2.92,26.04],[2.88,10.64],[3,62.5],[2.96,38.27]],"id":70003370},{"atb":[[1.02,250]],"id":64927898}],"con":true,"img":false}]}
{"op":"mcm","clk":"11450434601","pt":1717322004977,"mc":[{"id":"1.229554916","rc":[{"atl":[[44,2.33],[50,2.61]],"id":51562794},{"atl":[[8,0],[6.8,4.79]],"id":46292327},{"atl":[[5.1,2.85]],"id":65293046},{"atl":[[8.6,0],[6.8,5.11]],"id":70003370}],"con":true,"img":false}]}
{"op":"mcm","clk":"11450434621","pt":1717322005287,"mc":[{"id":"1.229554916","rc":[{"atb":[[5.3,0]],"id":51562794}],"con":true,"img":false}]}
{"op":"mcm","clk":"11450434629","pt":1717322005389,"mc":[{"id":"1.229554916","rc":[{"atb":[[4.7,9.41]],"id":51562794}],"con":true,"img":false}]}
{"op":"mcm","clk":"11450434828","pt":1717322007783,"mc":[{"id":"1.229554916","rc":[{"atb":[[5.6,0],[3.5,34.54],[4.7,0]],"id":51562794},{"atb":[[1.91,0]],"id":65788088},{"atb":[[5.8,7.26],[4.1,12.17]],"id":42099039},{"atb":[[1.36,110.44],[1.44,0],[1.75,48.76]],"id":70003370},{"atl":[[4.3,13.07],[2.86,0],[2.6,0],[3.9,14.43]],"id":64927898}],"con":true,"img":false}]}
{"op":"mcm","clk":"11450434832","pt":1717322007930,"mc":[{"id":"1.229554916","rc":[{"atb":[[4.1,9.73]],"id":51562794},{"atb":[[1.81,41.65]],"id":65788088},{"atb":[[1.75,39.06]],"id":70003370},{"atl":[[2.48,0]],"id":64927898}],"con":true,"img":false}]}
{"op":"mcm","clk":"11450434992","pt":1717322010323,"mc":[{"id":"1.229554916","rc":[{"atb":[[1.42,0],[1.34,115.4]],"id":46292327}],"con":true,"img":false}]}
{"op":"mcm","clk":"11450435144","pt":1717322012297,"mc":[{"id":"1.229554916","rc":[{"atb":[[1.97,38.54]],"id":56606596}],"con":true,"img":false}]}
{"op":"mcm","clk":"11450435189","pt":1717322012817,"mc":[{"id":"1.229554916","rc":[{"atb":[[2.18,0]],"id":65788088},{"atb":[[6.2,3.85]],"id":42099039},{"atb":[[1.75,0]],"id":70003370}],"con":true,"img":false}]}
{"op":"mcm","clk":"11450435200","pt":1717322012921,"mc":[{"id":"1.229554916","rc":[{"atb":[[2.06,33.67]],"id":65788088},{"atb":[[6,8.72]],"id":42099039},{"atb":[[1.49,39.06]],"id":70003370}],"con":true,"img":false}]}
{"op":"mcm","clk":"11450435249","pt":1717322013437,"mc":[{"id":"1.229554916","rc":[{"atb":[[1.84,8.1]],"id":56606596}],"con":true,"img":false}]}
{"op":"mcm","clk":"11450435437","pt":1717322015420,"mc":[{"id":"1.229554916","rc":[{"atl":[[2.86,10.75],[2.9,26.32],[2.98,63.13],[2.94,38.66]],"id":64927898}],"con":true,"img":false}]}
{"op":"mcm","clk":"11450435460","pt":1717322015724,"mc":[{"id":"1.229554916","rc":[{"atb":[[1.26,16.38]],"id":65293046}],"con":true,"img":false}]}
{"op":"mcm","clk":"11450435483","pt":1717322015931,"mc":[{"id":"1.229554916","rc":[{"atb":[[1.28,14.02]],"id":65293046}],"con":true,"img":false}]}
{"op":"mcm","clk":"11450435611","pt":1717322017906,"mc":[{"id":"1.229554916","rc":[{"atb":[[1.05,0]],"id":64927898}],"con":true,"img":false}]}
{"op":"mcm","clk":"11450435662","pt":1717322018626,"mc":[{"id":"1.229554916","rc":[{"atb":[[1.96,9.57]],"id":65788088}],"con":true,"img":false}]}
{"op":"mcm","clk":"11450435694","pt":1717322019037,"mc":[{"id":"1.229554916","rc":[{"atb":[[2.74,57.47],[3.5,16.21]],"id":51562794},{"atb":[[1.56,35.71],[1.52,54.25]],"id":46292327},{"atb":[[4,0],[6.2,0],[5.5,0],[3,50],[5.7,0],[5.9,0]],"id":42099039}],"con":true,"img":false}]}
{"op":"mcm","clk":"11450435725","pt":1717322019403,"mc":[{"id":"1.229554916","rc":[{"atb":[[1.56,0],[1.52,92.71]],"id":46292327},{"atb":[[6.2,3.85],[5.5,27.78],[5.7,15.96],[5.9,10.2]],"id":42099039}],"con":true,"img":false}]}
{"op":"mcm","clk":"11450435784","pt":1717322020242,"mc":[{"id":"1.229554916","rc":[{"atl":[[5.1,0]],"id":65293046}],"con":true,"img":false}]}
{"op":"mcm","clk":"11450435806","pt":1717322020543,"mc":[{"id":"1.229554916","rc":[{"atb":[[1.26,0]],"id":65293046}],"con":true,"img":false}]}
{"op":"mcm","clk":"11450435827","pt":1717322020751,"mc":[{"id":"1.229554916","rc":[{"atb":[[1.56,35.71],[1.52,54.25]],"id":46292327},{"atb":[[6.2,0],[5.5,0],[5.7,0],[5.9,0]],"id":42099039}],"con":true,"img":false}]}
{"op":"mcm","clk":"11450435837","pt":1717322020856,"mc":[{"id":"1.229554916","rc":[{"atb":[[4.6,2.5],[3.9,10],[4.2,5]],"id":51562794},{"atl":[[17,10],[20,4.21],[13,2.5],[15,5]],"id":51562794},{"atb":[[1.98,2.5]],"id":56606596},{"atl":[[4.8,2.5],[5.6,10],[5,19.22],[5.2,5]],"id":56606596},{"atb":[[2.28,2.5],[2.12,10],[2.2,5]],"id":65788088},{"atl":[[5.6,6.85],[5.5,17.28],[6,20]],"id":65788088},{"atl":[[17.5,5],[19.5,10],[28,2.96],[15.5,2.5]],"id":42099039},{"atb":[[1.28,81.77],[1.46,10],[1.54,2.5],[1.5,5]],"id":65293046},{"atl":[[2.32,75.76]],"id":65293046},{"atb":[[1.58,5],[1.54,10],[1.62,2.5]],"id":70003370},{"atl":[[2.88,50.92]],"id":70003370},{"atb":[[1.09,2.5],[1.07,127.1],[1.05,5]],"id":64927898},{"atl":[[1.98,5],[2.04,10],[2.84,27.8],[1.94,2.5]],"id":64927898}],"con":true,"img":false}]}
{"op":"mcm","clk":"11450435847","pt":1717322020910,"mc":[{"id":"1.229554916","rc":[{"atb":[[1.84,0]],"id":56606596},{"atb":[[1.96,0]],"id":65788088},{"atb":[[1.21,238.1]],"id":65293046}],"con":true,"img":false}]}
{"op":"mcm","clk":"11450435858","pt":1717322021067,"mc":[{"id":"1.229554916","rc":[{"atb":[[1.56,0],[1.52,92.71]],"id":46292327},{"atb":[[5.3,5],[4.9,10],[5.9,10.2],[6.2,3.85],[5.5,27.78],[5.7,18.46]],"id":42099039}],"con":true,"img":false}]}
{"op":"mcm","clk":"11450435912","pt":1717322021554,"mc":[{"id":"1.229554916","rc":[{"atb":[[1.56,35.71],[1.52,54.25]],"id":46292327},{"atb":[[5.9,0],[6.2,0],[5.5,0],[5.7,2.5]],"id":42099039}],"con":true,"img":false}]}
{"op":"mcm","clk":"11450435934","pt":1717322021708,"mc":[{"id":"1.229554916","rc":[{"atb":[[1.56,0],[1.52,92.71]],"id":46292327},{"atb":[[5.9,10.2],[6.2,3.85],[5.5,27.78],[5.7,18.46]],"id":42099039}],"con":true,"img":false}]}
{"op":"mcm","clk":"11450436068","pt":1717322023254,"mc":[{"id":"1.229554916","rc":[{"atb":[[1.56,35.71],[1.52,54.25]],"id":46292327},{"atb":[[5.9,0],[6.2,0],[5.5,0],[5.7,2.5]],"id":42099039}],"con":true,"img":false}]}
{"op":"mcm","clk":"11450436084","pt":1717322023448,"mc":[{"id":"1.229554916","rc":[{"atb":[[1.56,0],[1.52,92.71]],"id":46292327},{"atb":[[5.9,10.2],[6.2,3.85],[5.5,27.78],[5.7,18.46]],"id":42099039}],"con":true,"img":false}]}
{"op":"mcm","clk":"11450436191","pt":1717322024722,"mc":[{"id":"1.229554916","rc":[{"atl":[[2.32,60.61],[2.42,14.08]],"id":65293046},{"atl":[[1.76,26.32],[2.86,0]],"id":64927898}],"con":true,"img":false}]}
{"op":"mcm","clk":"11450436199","pt":1717322024825,"mc":[{"id":"1.229554916","rc":[{"atl":[[2.32,0]],"id":65293046}],"con":true,"img":false}]}
{"op":"mcm","clk":"11450436208","pt":1717322024927,"mc":[{"id":"1.229554916","rc":[{"atl":[[2.36,71.83]],"id":65293046}],"con":true,"img":false}]}
{"op":"mcm","clk":"11450436240","pt":1717322025346,"mc":[{"id":"1.229554916","rc":[{"atb":[[4.1,0]],"id":42099039},{"atb":[[1.07,27.8]],"id":64927898}],"con":true,"img":false}]}
{"op":"mcm","clk":"11450436251","pt":1717322025442,"mc":[{"id":"1.229554916","rc":[{"atb":[[3.6,12.17]],"id":42099039},{"atb":[[1.08,99.3]],"id":64927898}],"con":true,"img":false}]}
{"op":"mcm","clk":"11450436288","pt":1717322025815,"mc":[{"id":"1.229554916","rc":[{"atb":[[2.74,0],[3.5,56.21]],"id":51562794},{"atb":[[3,0],[4,33.33]],"id":42099039}],"con":true,"img":false}]}
{"op":"mcm","clk":"11450436301","pt":1717322025932,"mc":[{"id":"1.229554916","rc":[{"atl":[[2.36,35.07]],"id":65293046}],"con":true,"img":false}]}
{"op":"mcm","clk":"11450436321","pt":1717322026135,"mc":[{"id":"1.229554916","rc":[{"atl":[[2.36,0]],"id":65293046}],"con":true,"img":false}]}
{"op":"mcm","clk":"11450436328","pt":1717322026238,"mc":[{"id":"1.229554916","rc":[{"atl":[[2.38,18.06],[2.96,2.5]],"id":65293046}],"con":true,"img":false}]}
{"op":"mcm","clk":"11450436345","pt":1717322026454,"mc":[{"id":"1.229554916","rc":[{"atb":[[1.5,114.45]],"id":46292327}],"con":true,"img":false}]}
{"op":"mcm","clk":"11450436478","pt":1717322027840,"mc":[{"id":"1.229554916","rc":[{"atl":[[50,0]],"id":51562794},{"atl":[[8.2,0],[6,8.37]],"id":46292327},{"atl":[[6.4,7.74],[8.8,0]],"id":70003370}],"con":true,"img":false}]}
{"op":"mcm","clk":"11450436486","pt":1717322027943,"mc":[{"id":"1.229554916","rc":[{"atl":[[24,2.61]],"id":51562794}],"con":true,"img":false}]}
{"op":"mcm","clk":"11450436682","pt":1717322030331,"mc":[{"id":"1.229554916","rc":[{"atl":[[50,0]],"id":42099039}],"con":true,"img":false}]}
{"op":"mcm","clk":"11450436693","pt":1717322030433,"mc":[{"id":"1.229554916","rc":[{"atl":[[28,5.57]],"id":42099039}],"con":true,"img":false}]}
{"op":"mcm","clk":"11450436827","pt":1717322031843,"mc":[{"id":"1.229554916","rc":[{"atb":[[6.4,0],[5.2,0]],"id":51562794},{"atb":[[1.41,0],[1.51,0]],"id":46292327},{"atl":[[4.6,0]],"id":46292327},{"atb":[[2.46,0],[2.66,0]],"id":56606596},{"atl":[[18,0]],"id":56606596},{"atb":[[2.64,0],[2.84,0]],"id":65788088},{"atb":[[5.8,0],[7.6,0]],"id":42099039},{"atb":[[1.84,0],[1.74,0]],"id":70003370},{"atl":[[7.6,0]],"id":70003370},{"atb":[[1.07,0],[1.17,250]],"id":65293046},{"atl":[[3,0]],"id":65293046},{"atb":[[1.01,0]],"id":64927898},{"atl":[[2.22,0]],"id":64927898}],"con":true,"img":false}]}
{"op":"mcm","clk":"11450436847","pt":1717322032052,"mc":[{"id":"1.229554916","rc":[{"atb":[[5.1,7.5]],"id":51562794},{"atb":[[6.2,14.14]],"id":42099039}],"con":true,"img":false}]}
{"op":"mcm","clk":"11450436922","pt":1717322032834,"mc":[{"id":"1.229554916","rc":[{"atb":[[1.97,0]],"id":56606596},{"atb":[[2.06,0]],"id":65788088},{"atl":[[4.8,0]],"id":65293046}],"con":true,"img":false}]}
{"op":"mcm","clk":"11450436931","pt":1717322032940,"mc":[{"id":"1.229554916","rc":[{"atb":[[1.84,38.54]],"id":56606596},{"atb":[[1.96,33.67]],"id":65788088},{"atl":[[4.3,9.51]],"id":65293046}],"con":true,"img":false}]}
{"op":"mcm","clk":"11450437019","pt":1717322033841,"mc":[{"id":"1.229554916","rc":[{"atb":[[2.52,2.8]],"id":56606596},{"atb":[[2.7,2.5]],"id":65788088}],"con":true,"img":false}]}
{"op":"mcm","clk":"11450437112","pt":1717322034826,"mc":[{"id":"1.229554916","rc":[{"atb":[[1.5,111.95]],"id":46292327}],"con":true,"img":false}]}
{"op":"mcm","clk":"11450437126","pt":1717322035032,"mc":[{"id":"1.229554916","rc":[{"atl":[[2.4,0],[2.46,34.25]],"id":65293046},{"atl":[[1.78,64.1]],"id":64927898}],"con":true,"img":false}]}
{"op":"mcm","clk":"11450437136","pt":1717322035139,"mc":[{"id":"1.229554916","rc":[{"atl":[[12.5,6.96]],"id":51562794},{"atl":[[4.7,5.76]],"id":56606596},{"atl":[[15,5.71]],"id":42099039},{"atb":[[1.54,20.56]],"id":65293046},{"atl":[[2.38,0]],"id":65293046},{"atb":[[1.09,25.99]],"id":64927898},{"atl":[[1.75,23.49]],"id":64927898}],"con":true,"img":false}]}
{"op":"mcm","clk":"11450437149","pt":1717322035242,"mc":[{"id":"1.229554916","rc":[{"atl":[[20,0]],"id":51562794},{"atl":[[5,0]],"id":56606596},{"atl":[[28,2.61]],"id":42099039},{"atb":[[1.28,14.02]],"id":65293046},{"atl":[[2.4,18.06]],"id":65293046},{"atb":[[1.07,0]],"id":64927898},{"atl":[[2.84,0]],"id":64927898}],"con":true,"img":false}]}
{"op":"mcm","clk":"11450437408","pt":1717322038048,"mc":[{"id":"1.229554916","rc":[{"atb":[[5.1,12.38],[4.5,35.71],[4.9,12.82],[4.7,20.27]],"id":51562794}],"con":true,"img":false}]}
{"op":"mcm","clk":"11450437605","pt":1717322040382,"mc":[{"id":"1.229554916","rc":[{"atl":[[2.48,28.27]],"id":64927898}],"con":true,"img":false}]}
{"op":"mcm","clk":"11450437612","pt":1717322040438,"mc":[{"id":"1.229554916","rc":[{"atl":[[3.9,0]],"id":64927898}],"con":true,"img":false}]}
{"op":"mcm","clk":"11450437654","pt":1717322040961,"mc":[{"id":"1.229554916","rc":[{"atb":[[5.1,20.87],[6.2,4.46]],"id":51562794},{"atb":[[1.44,79.18],[1.54,58.17]],"id":46292327},{"atl":[[4.9,0.13]],"id":46292327},{"atb":[[2.46,23.86],[2.66,13.99]],"id":56606596},{"atl":[[18,0.03]],"id":56606596},{"atb":[[2.82,12.76],[2.62,21.5]],"id":65788088},{"atb":[[7.4,3.63],[5.7,25.87]],"id":42099039},{"atb":[[1.14,165.92],[1.04,871.08]],"id":65293046},{"atl":[[2.94,0.27]],"id":65293046},{"atb":[[1.79,44.1],[1.89,26.1]],"id":70003370},{"atl":[[7.8,0.07]],"id":70003370},{"atb":[[1.01,5807.26]],"id":64927898},{"atl":[[2.22,0.42]],"id":64927898}],"con":true,"img":false}]}
{"op":"mcm","clk":"11450437850","pt":1717322042837,"mc":[{"id":"1.229554916","rc":[{"spn":9.35,"spf":"NaN","id":51562794},{"spn":2.21,"spf":"NaN","id":46292327},{"spn":3.68,"spf":"NaN","id":56606596},{"spn":4.16,"spf":"NaN","id":65788088},{"atl":[[28,0]],"id":42099039},{"spn":11.2,"spf":"NaN","id":42099039},{"spn":2.38,"spf":"NaN","id":70003370},{"spn":1.97,"spf":"NaN","id":65293046},{"spn":1.42,"spf":"NaN","id":64927898}],"con":true,"img":false}]}
{"op":"mcm","clk":"11450437857","pt":1717322042940,"mc":[{"id":"1.229554916","rc":[{"atl":[[34,2.61]],"id":42099039}],"con":true,"img":false}]}
{"op":"mcm","clk":"11450438035","pt":1717322045171,"mc":[{"id":"1.229554916","rc":[{"atl":[[2.5,50]],"id":65293046},{"atl":[[2.98,0],[2.94,0],[1.8,93.75],[2.9,0]],"id":64927898}],"con":true,"img":false}]}
{"op":"mcm","clk":"11450438052","pt":1717322045323,"mc":[{"id":"1.229554916","rc":[{"atb":[[1.24,142.78]],"id":65293046}],"con":true,"img":false}]}
{"op":"mcm","clk":"11450438062","pt":1717322045432,"mc":[{"id":"1.229554916","rc":[{"atb":[[1.2,0]],"id":65293046},{"atb":[[1.06,0]],"id":64927898}],"con":true,"img":false}]}
{"op":"mcm","clk":"11450438073","pt":1717322045534,"mc":[{"id":"1.229554916","rc":[{"atb":[[1.07,707.85]],"id":64927898}],"con":true,"img":false}]}
{"op":"mcm","clk":"11450438135","pt":1717322046149,"mc":[{"id":"1.229554916","rc":[{"atb":[[7.4,11.66]],"id":42099039}],"con":true,"img":false}]}
{"op":"mcm","clk":"11450438146","pt":1717322046256,"mc":[{"id":"1.229554916","rc":[{"atb":[[6.2,3.85]],"id":42099039}],"con":true,"img":false}]}
{"op":"mcm","clk":"11450438227","pt":1717322047144,"mc":[{"id":"1.229554916","rc":[{"atb":[[1.07,756.65]],"id":64927898}],"con":true,"img":false}]}
{"op":"mcm","clk":"11450438293","pt":1717322047873,"mc":[{"id":"1.229554916","rc":[{"atl":[[80,0]],"id":51562794},{"atl":[[7,6.53]],"id":46292327},{"atl":[[18.5,0]],"id":56606596},{"atl":[[22,0]],"id":65788088},{"atl":[[100,0]],"id":42099039},{"atl":[[4.8,9.01]],"id":65293046},{"atl":[[7.6,6.02]],"id":70003370}],"con":true,"img":false}]}
{"op":"mcm","clk":"11450438302","pt":1717322047980,"mc":[{"id":"1.229554916","rc":[{"atl":[[38,2.61]],"id":51562794},{"atl":[[9.2,0]],"id":46292327},{"atl":[[13.5,2.61]],"id":56606596},{"atl":[[15,2.61]],"id":65788088},{"atl":[[38,2.61]],"id":42099039},{"atl":[[6,0]],"id":65293046},{"atl":[[9.8,0]],"id":70003370}],"con":true,"img":false}]}
{"op":"mcm","clk":"11450438323","pt":1717322048136,"mc":[{"id":"1.229554916","rc":[{"atl":[[60,5]],"id":46292327},{"atl":[[60,5]],"id":65293046},{"atl":[[60,5]],"id":70003370},{"atl":[[60,5]],"id":64927898}],"con":true,"img":false}]}
{"op":"mcm","clk":"11450438548","pt":1717322050933,"mc":[{"id":"1.229554916","rc":[{"atb":[[1.54,50.28]],"id":46292327},{"atb":[[2.7,0]],"id":65788088},{"atb":[[1.28,29.24]],"id":65293046},{"atb":[[1.87,4.51]],"id":70003370}],"con":true,"img":false}]}
{"op":"mcm","clk":"11450438810","pt":1717322054143,"mc":[{"id":"1.229554916","rc":[{"atb":[[1.5,114.45]],"id":46292327}],"con":true,"img":false}]}
{"op":"mcm","clk":"11450438891","pt":1717322055077,"mc":[{"id":"1.229554916","rc":[{"atl":[[1.82,152.44]],"id":64927898}],"con":true,"img":false}]}
{"op":"mcm","clk":"11450438922","pt":1717322055389,"mc":[{"id":"1.229554916","rc":[{"atl":[[6.4,0]],"id":70003370}],"con":true,"img":false}]}
{"op":"mcm","clk":"11450438933","pt":1717322055488,"mc":[{"id":"1.229554916","rc":[{"atl":[[6.2,7.74]],"id":70003370},{"atl":[[4.3,0],[3.9,14.43]],"id":65293046}],"con":true,"img":false}]}
{"op":"mcm","clk":"11450439031","pt":1717322056482,"mc":[{"id":"1.229554916","rc":[{"atb":[[1.5,100]],"id":46292327}],"con":true,"img":false}]}
{"op":"mcm","clk":"11450439044","pt":1717322056583,"mc":[{"id":"1.229554916","rc":[{"atb":[[1.96,8.1]],"id":56606596}],"con":true,"img":false}]}
{"op":"mcm","clk":"11450439177","pt":1717322057991,"mc":[{"id":"1.229554916","rc":[{"atb":[[1.84,0]],"id":56606596},{"atb":[[1.96,0]],"id":65788088}],"con":true,"img":false}]}
{"op":"mcm","clk":"11450439185","pt":1717322058086,"mc":[{"id":"1.229554916","rc":[{"atb":[[2.06,38.54]],"id":56606596},{"atb":[[2.14,33.67]],"id":65788088}],"con":true,"img":false}]}
{"op":"mcm","clk":"11450439402","pt":1717322060385,"mc":[{"id":"1.229554916","rc":[{"atl":[[4.3,0],[2.86,23.01]],"id":64927898}],"con":true,"img":false}]}
{"op":"mcm","clk":"11450439634","pt":1717322062883,"mc":[{"id":"1.229554916","rc":[{"atb":[[1.52,38.46]],"id":46292327},{"atl":[[6,0]],"id":46292327}],"con":true,"img":false}]}
{"op":"mcm","clk":"11450439647","pt":1717322062987,"mc":[{"id":"1.229554916","rc":[{"atb":[[1.55,54.25]],"id":46292327},{"atl":[[5.7,8.37]],"id":46292327}],"con":true,"img":false}]}
{"op":"mcm","clk":"11450440285","pt":1717322069121,"mc":[{"id":"1.229554916","rc":[{"atb":[[1.63,9.7]],"id":70003370}],"con":true,"img":false}]}
{"op":"mcm","clk":"11450440421","pt":1717322070480,"mc":[{"id":"1.229554916","rc":[{"atb":[[4.1,0]],"id":51562794},{"atb":[[3.6,0]],"id":42099039},{"atb":[[1.49,0]],"id":70003370}],"con":true,"img":false}]}
{"op":"mcm","clk":"11450440433","pt":1717322070585,"mc":[{"id":"1.229554916","rc":[{"atb":[[5.2,9.73]],"id":51562794},{"atb":[[4.1,12.17]],"id":42099039},{"atb":[[1.56,39.06]],"id":70003370}],"con":true,"img":false}]}
{"op":"mcm","clk":"11450440452","pt":1717322070794,"mc":[{"id":"1.229554916","rc":[{"atb":[[1.96,0]],"id":56606596}],"con":true,"img":false}]}
{"op":"mcm","clk":"11450440768","pt":1717322073496,"mc":[{"id":"1.229554916","rc":[{"atb":[[4.9,16.33]],"id":51562794}],"con":true,"img":false}]}
{"op":"mcm","clk":"11450440901","pt":1717322074793,"mc":[{"id":"1.229554916","rc":[{"atb":[[4.9,3.51],[3.5,16.21],[5.1,15.99],[2.74,57.47],[4.7,0]],"id":51562794},{"atb":[[3,50],[5.9,0],[4,0],[6.2,0],[5.5,0],[5.7,9.91]],"id":42099039}],"con":true,"img":false}]}
{"op":"mcm","clk":"11450440936","pt":1717322075203,"mc":[{"id":"1.229554916","rc":[{"atb":[[2.74,0],[3.5,56.21]],"id":51562794},{"atb":[[3,0],[5.9,10.2],[4,33.33],[6.2,3.85],[5.5,27.78],[5.7,25.87]],"id":42099039}],"con":true,"img":false}]}
{"op":"mcm","clk":"11450441119","pt":1717322076813,"mc":[{"id":"1.229554916","rc":[{"atb":[[3.5,16.21]],"id":51562794},{"atb":[[4,0],[6.2,0],[5.5,0],[5.7,9.91],[5.9,0]],"id":42099039}],"con":true,"img":false}]}
{"op":"mcm","clk":"11450441130","pt":1717322076869,"mc":[{"id":"1.229554916","rc":[{"atb":[[2.74,57.47]],"id":51562794},{"atb":[[3,50]],"id":42099039}],"con":true,"img":false}]}
{"op":"mcm","clk":"11450441147","pt":1717322077022,"mc":[{"id":"1.229554916","rc":[{"atb":[[6.2,3.85],[5.5,27.78],[5.7,25.87],[5.9,10.2]],"id":42099039}],"con":true,"img":false}]}
{"op":"mcm","clk":"11450441266","pt":1717322078009,"mc":[{"id":"1.229554916","rc":[{"atb":[[4.9,0]],"id":51562794},{"atb":[[1.63,0]],"id":70003370}],"con":true,"img":false}]}
{"op":"mcm","clk":"11450441341","pt":1717322078795,"mc":[{"id":"1.229554916","rc":[{"atl":[[15,8.21],[15.5,0],[17.5,0],[17,5],[19.5,0],[19,10]],"id":42099039}],"con":true,"img":false}]}
{"op":"mcm","clk":"11450441410","pt":1717322079424,"mc":[{"id":"1.229554916","rc":[{"atb":[[1.54,43.01]],"id":46292327},{"atb":[[2.52,5.38]],"id":56606596},{"atb":[[1.01,2.35]],"id":65788088},{"atb":[[1.87,0]],"id":70003370}],"con":true,"img":false}]}
{"op":"mcm","clk":"11450441430","pt":1717322079639,"mc":[{"id":"1.229554916","rc":[{"atb":[[1.57,6.88]],"id":46292327},{"atb":[[1.01,2.33]],"id":65788088},{"atb":[[1.93,4.22]],"id":70003370}],"con":true,"img":false}]}
{"op":"mcm","clk":"11450441453","pt":1717322079917,"mc":[{"id":"1.229554916","rc":[{"atb":[[1.01,0]],"id":65788088}],"con":true,"img":false}]}
{"op":"mcm","clk":"11450441465","pt":1717322080034,"mc":[{"id":"1.229554916","rc":[{"atb":[[2.68,2.33]],"id":65788088},{"atb":[[1.46,0],[1.51,5],[1.55,26.6],[1.54,18.06],[1.5,0],[1.47,10]],"id":65293046}],"con":true,"img":false}]}
{"op":"mcm","clk":"11450441483","pt":1717322080228,"mc":[{"id":"1.229554916","rc":[{"atb":[[1.54,0]],"id":65293046}],"con":true,"img":false}]}
{"op":"mcm","clk":"11450441589","pt":1717322081381,"mc":[{"id":"1.229554916","rc":[{"atb":[[2.74,0],[3.5,56.21]],"id":51562794},{"atb":[[3,0],[4,33.33]],"id":42099039}],"con":true,"img":false}]}
{"op":"mcm","clk":"11450441721","pt":1717322082881,"mc":[{"id":"1.229554916","rc":[{"atb":[[1.45,87.19]],"id":46292327}],"con":true,"img":false}]}
{"op":"mcm","clk":"11450441731","pt":1717322082985,"mc":[{"id":"1.229554916","rc":[{"atb":[[1.34,0]],"id":46292327}],"con":true,"img":false}]}
{"op":"mcm","clk":"11450441821","pt":1717322083772,"mc":[{"id":"1.229554916","rc":[{"atb":[[1.52,52.91]],"id":46292327}],"con":true,"img":false}]}
{"op":"mcm","clk":"11450441923","pt":1717322085267,"mc":[{"id":"1.229554916","rc":[{"atl":[[4.8,0],[5.6,0],[5.1,9.88],[5.2,0],[4.7,8.26]],"id":56606596}],"con":true,"img":false}]}
{"op":"mcm","clk":"11450441931","pt":1717322085375,"mc":[{"id":"1.229554916","rc":[{"atb":[[1.81,51.27]],"id":56606596},{"atb":[[1.08,630.32]],"id":64927898}],"con":true,"img":false}]}
{"op":"mcm","clk":"11450441941","pt":1717322085474,"mc":[{"id":"1.229554916","rc":[{"atb":[[1.72,0]],"id":56606596},{"atb":[[1.81,0]],"id":65788088},{"atb":[[1.36,0]],"id":70003370},{"atb":[[1.07,48.8]],"id":64927898}],"con":true,"img":false}]}
{"op":"mcm","clk":"11450441949","pt":1717322085579,"mc":[{"id":"1.229554916","rc":[{"atb":[[1.9,41.65]],"id":65788088},{"atb":[[1.42,110.44]],"id":70003370}],"con":true,"img":false}]}
{"op":"mcm","clk":"11450442066","pt":1717322086999,"mc":[{"id":"1.229554916","rc":[{"atb":[[1.07,45.66]],"id":64927898}],"con":true,"img":false}]}
{"op":"mcm","clk":"11450442076","pt":1717322087102,"mc":[{"id":"1.229554916","rc":[{"atb":[[1.07,48.8]],"id":64927898}],"con":true,"img":false}]}
{"op":"mcm","clk":"11450442307","pt":1717322090511,"mc":[{"id":"1.229554916","rc":[{"atl":[[10,0]],"id":56606596}],"con":true,"img":false}]}
{"op":"mcm","clk":"11450442315","pt":1717322090607,"mc":[{"id":"1.229554916","rc":[{"atl":[[11,4.65]],"id":56606596}],"con":true,"img":false}]}
{"op":"mcm","clk":"11450442396","pt":1717322091802,"mc":[{"id":"1.229554916","rc":[{"atb":[[1.57,14.35]],"id":46292327}],"con":true,"img":false}]}
{"op":"mcm","clk":"11450442406","pt":1717322091907,"mc":[{"id":"1.229554916","rc":[{"atb":[[1.93,8.8]],"id":70003370}],"con":true,"img":false}]}
{"op":"mcm","clk":"11450442444","pt":1717322092375,"mc":[{"id":"1.229554916","rc":[{"atb":[[2.68,4.87]],"id":65788088}],"con":true,"img":false}]}
{"op":"mcm","clk":"11450442576","pt":1717322094134,"mc":[{"id":"1.229554916","rc":[{"atb":[[2.06,46.64]],"id":56606596}],"con":true,"img":false}]}
{"op":"mcm","clk":"11450442740","pt":1717322096626,"mc":[{"id":"1.229554916","rc":[{"atb":[[2.2,14.72]],"id":65788088}],"con":true,"img":false}]}
{"op":"mcm","clk":"11450443284","pt":1717322103227,"mc":[{"id":"1.229554916","rc":[{"atb":[[2.74,57.47],[3.5,16.21]],"id":51562794},{"spn":2.22,"spf":"NaN","id":46292327},{"atb":[[3,50],[5.9,0],[4,0],[6.2,0],[5.5,0],[5.7,9.91]],"id":42099039},{"spn":2.4,"spf":"NaN","id":70003370},{"atb":[[1.26,76.92],[1.23,0]],"id":65293046},{"spn":1.97,"spf":"NaN","id":65293046},{"atb":[[1.04,250]],"id":64927898}],"con":true,"img":false}]}
{"op":"mcm","clk":"11450443472","pt":1717322105522,"mc":[{"id":"1.229554916","rc":[{"atb":[[4.1,0]],"id":42099039}],"con":true,"img":false}]}
{"op":"mcm","clk":"11450443480","pt":1717322105627,"mc":[{"id":"1.229554916","rc":[{"atb":[[3.75,12.17]],"id":42099039}],"con":true,"img":false}]}
{"op":"mcm","clk":"11450443557","pt":1717322106509,"mc":[{"id":"1.229554916","rc":[{"atb":[[2.06,38.54]],"id":56606596},{"atb":[[2.2,4.99]],"id":65788088}],"con":true,"img":false}]}
{"op":"mcm","clk":"11450443896","pt":1717322110538,"mc":[{"id":"1.229554916","rc":[{"atb":[[6,0]],"id":42099039}],"con":true,"img":false}]}
{"op":"mcm","clk":"11450443905","pt":1717322110638,"mc":[{"id":"1.229554916","rc":[{"atb":[[5.8,8.72]],"id":42099039}],"con":true,"img":false}]}
{"op":"mcm","clk":"11450444028","pt":1717322112138,"mc":[{"id":"1.229554916","rc":[{"atb":[[1.24,351.11]],"id":65293046}],"con":true,"img":false}]}
{"op":"mcm","clk":"11450444439","pt":1717322116948,"mc":[{"id":"1.229554916","rc":[{"atb":[[1.26,0],[1.24,142.78]],"id":65293046},{"atb":[[1.02,0],[1.07,0],[1.04,0]],"id":64927898}],"con":true,"img":false}]}
{"op":"mcm","clk":"11450444631","pt":1717322118825,"mc":[{"id":"1.229554916","rc":[{"atl":[[19,1.11],[21,0]],"id":51562794},{"atl":[[2.8,11.11]],"id":46292327},{"atl":[[5.1,5],[4.6,5.56]],"id":56606596},{"atl":[[5.6,2.5],[5.3,4.65]],"id":65788088},{"atl":[[23,1]],"id":42099039}],"con":true,"img":false}]}
{"op":"mcm","clk":"11450444640","pt":1717322118934,"mc":[{"id":"1.229554916","rc":[{"atl":[[2.88,0]],"id":46292327},{"atl":[[4.6,19.16]],"id":56606596},{"atl":[[5.4,17.39]],"id":65788088},{"atl":[[29,0]],"id":42099039}],"con":true,"img":false}]}
{"op":"mcm","clk":"11450444647","pt":1717322119035,"mc":[{"id":"1.229554916","rc":[{"atl":[[4.7,2.5]],"id":56606596},{"atl":[[5.5,0]],"id":65788088}],"con":true,"img":false}]}
{"op":"mcm","clk":"11450444678","pt":1717322119445,"mc":[{"id":"1.229554916","rc":[{"atb":[[1.96,8.1]],"id":56606596}],"con":true,"img":false}]}
{"op":"mcm","clk":"11450444766","pt":1717322120540,"mc":[{"id":"1.229554916","rc":[{"atb":[[1.96,0]],"id":56606596}],"con":true,"img":false}]}
{"op":"mcm","clk":"11450444956","pt":1717322122622,"mc":[{"id":"1.229554916","rc":[{"atl":[[2.78,11.24]],"id":46292327},{"atb":[[1.02,250]],"id":64927898}],"con":true,"img":false}]}
{"op":"mcm","clk":"11450444967","pt":1717322122726,"mc":[{"id":"1.229554916","rc":[{"atl":[[20,1.05]],"id":51562794},{"atl":[[3,0],[2.78,0],[2.76,11.36]],"id":46292327},{"atl":[[23,0]],"id":42099039},{"atl":[[2.86,53.76]],"id":70003370}],"con":true,"img":false}]}
{"op":"mcm","clk":"11450444981","pt":1717322122839,"mc":[{"id":"1.229554916","rc":[{"atl":[[19,0]],"id":51562794},{"atb":[[1.48,41.67],[1.52,14.45]],"id":46292327},{"atl":[[2.8,0]],"id":46292327},{"atl":[[4.5,5.71],[4.6,13.6]],"id":56606596},{"atl":[[22,1]],"id":42099039},{"atl":[[2.88,0],[2.84,10.87]],"id":70003370}],"con":true,"img":false}]}
{"op":"mcm","clk":"11450444995","pt":1717322122938,"mc":[{"id":"1.229554916","rc":[{"atl":[[20,0]],"id":51562794},{"atb":[[1.52,52.91]],"id":46292327},{"atl":[[2.8,11.11],[2.76,0]],"id":46292327},{"atl":[[4.6,19.16],[5,5]],"id":56606596},{"atl":[[22,0],[23,1]],"id":42099039},{"atl":[[2.88,10.64],[2.86,43.01]],"id":70003370}],"con":true,"img":false}]}
{"op":"mcm","clk":"11450445002","pt":1717322123038,"mc":[{"id":"1.229554916","rc":[{"atl":[[19,1.11]],"id":51562794},{"atl":[[4.5,0]],"id":56606596},{"atl":[[2.84,0]],"id":70003370}],"con":true,"img":false}]}
{"op":"mcm","clk":"11450445077","pt":1717322123820,"mc":[{"id":"1.229554916","rc":[{"atl":[[18.5,1.14],[19,0]],"id":51562794},{"atl":[[2.78,11.24],[2.76,11.36]],"id":46292327},{"atl":[[5.3,0],[4.9,5.13],[5.5,0],[5.7,0]],"id":56606596},{"atl":[[5.3,0],[5.2,4.76]],"id":65788088},{"atl":[[22,1],[23,0]],"id":42099039},{"atl":[[2.88,0],[2.86,53.76],[2.84,10.87]],"id":70003370}],"con":true,"img":false}]}
{"op":"mcm","clk":"11450445086","pt":1717322123982,"mc":[{"id":"1.229554916","rc":[{"atb":[[1.52,14.45]],"id":46292327},{"atl":[[4.6,13.6],[5,0]],"id":56606596}],"con":true,"img":false}]}
{"op":"mcm","clk":"11450445150","pt":1717322124650,"mc":[{"id":"1.229554916","rc":[{"atl":[[18.5,0],[20,1.05]],"id":51562794},{"atb":[[1.5,0]],"id":46292327},{"atl":[[2.78,0],[2.96,0]],"id":46292327},{"atl":[[5.3,4.65],[5.2,0]],"id":65788088},{"atl":[[2.86,43.01],[3,0]],"id":70003370}],"con":true,"img":false}]}
{"op":"mcm","clk":"11450445180","pt":1717322125010,"mc":[{"id":"1.229554916","rc":[{"atl":[[19.5,1.08],[20,0],[21,1]],"id":51562794},{"atb":[[1.52,52.91]],"id":46292327},{"atl":[[2.78,11.24],[2.76,0]],"id":46292327},{"atl":[[4.6,19.16],[5,5],[4.9,0]],"id":56606596},{"atl":[[5.3,0],[5.2,4.76]],"id":65788088},{"atl":[[22,0],[23,1]],"id":42099039},{"atl":[[2.88,10.64],[2.86,53.76],[2.84,0]],"id":70003370}],"con":true,"img":false}]}
{"op":"mcm","clk":"11450445199","pt":1717322125220,"mc":[{"id":"1.229554916","rc":[{"atl":[[19.5,0],[27,0]],"id":51562794},{"atb":[[1.52,14.45]],"id":46292327},{"atl":[[2.78,0]],"id":46292327},{"atl":[[4.6,13.6]],"id":56606596},{"atl":[[5.3,4.65],[5.2,0]],"id":65788088},{"atl":[[2.86,43.01]],"id":70003370}],"con":true,"img":false}]}
{"op":"mcm","clk":"11450445462","pt":1717322129120,"mc":[{"id":"1.229554916","rc":[{"atb":[[2.22,9.72]],"id":65788088}],"con":true,"img":false}]}
{"op":"mcm","clk":"11450445648","pt":1717322131251,"mc":[{"id":"1.229554916","rc":[{"atl":[[5.2,13.24]],"id":65788088}],"con":true,"img":false}]}
{"op":"mcm","clk":"11450445656","pt":1717322131345,"mc":[{"id":"1.229554916","rc":[{"atl":[[5.4,0]],"id":65788088}],"con":true,"img":false}]}
{"op":"mcm","clk":"11450445883","pt":1717322133676,"mc":[{"id":"1.229554916","rc":[{"atl":[[19,1.11]],"id":51562794},{"atb":[[1.52,52.91]],"id":46292327},{"atl":[[2.84,27.17]],"id":46292327},{"atl":[[4.6,19.16]],"id":56606596},{"atl":[[25,2.08]],"id":42099039},{"atl":[[3,62.5]],"id":70003370}],"con":true,"img":false}]}
{"op":"mcm","clk":"11450445901","pt":1717322133838,"mc":[{"id":"1.229554916","rc":[{"atl":[[5.5,11.11]],"id":65788088}],"con":true,"img":false}]}
{"op":"mcm","clk":"11450445977","pt":1717322134562,"mc":[{"id":"1.229554916","rc":[{"atl":[[6.4,0],[5.8,0],[6,5]],"id":65788088},{"atl":[[40,0]],"id":42099039}],"con":true,"img":false}]}
{"op":"mcm","clk":"11450446094","pt":1717322135654,"mc":[{"id":"1.229554916","rc":[{"atb":[[2.22,0]],"id":65788088},{"atl":[[38,0]],"id":42099039}],"con":true,"img":false}]}
{"op":"mcm","clk":"11450446104","pt":1717322135768,"mc":[{"id":"1.229554916","rc":[{"atl":[[44,2.61]],"id":42099039}],"con":true,"img":false}]}
{"op":"mcm","clk":"11450446303","pt":1717322138137,"mc":[{"id":"1.229554916","rc":[{"atb":[[1.52,14.45]],"id":46292327},{"atl":[[2.76,11.36]],"id":46292327},{"atl":[[22,1],[23,0]],"id":42099039},{"atl":[[2.88,0],[2.84,10.87]],"id":70003370}],"con":true,"img":false}]}
{"op":"mcm","clk":"11450446308","pt":1717322138242,"mc":[{"id":"1.229554916","rc":[{"atl":[[19,0]],"id":51562794},{"atl":[[4.6,13.6]],"id":56606596},{"atl":[[2.84,49.98]],"id":70003370}],"con":true,"img":false}]}
{"op":"mcm","clk":"11450446313","pt":1717322138342,"mc":[{"id":"1.229554916","rc":[{"atl":[[2.86,0]],"id":70003370}],"con":true,"img":false}]}
{"op":"mcm","clk":"11450446342","pt":1717322138769,"mc":[{"id":"1.229554916","rc":[{"atl":[[19,1.11]],"id":51562794},{"atb":[[1.52,52.91]],"id":46292327},{"atl":[[4.6,19.16]],"id":56606596}],"con":true,"img":false}]}
{"op":"mcm","clk":"11450446370","pt":1717322139176,"mc":[{"id":"1.229554916","rc":[{"atb":[[2.74,0],[3,50]],"id":51562794},{"atl":[[19,0],[20,1.05]],"id":51562794},{"atb":[[1.52,14.45]],"id":46292327},{"atl":[[2.74,11.49],[2.76,0]],"id":46292327},{"atl":[[4.6,13.6],[4.9,5.13]],"id":56606596},{"atl":[[5.2,18]],"id":65788088},{"atb":[[3,0],[3.5,40]],"id":42099039}],"con":true,"img":false}]}
{"op":"mcm","clk":"11450446378","pt":1717322139282,"mc":[{"id":"1.229554916","rc":[{"atl":[[18.5,1.14]],"id":51562794},{"atl":[[2.78,11.24]],"id":46292327},{"atl":[[4.5,5.71]],"id":56606596},{"atl":[[22,0],[23,1]],"id":42099039},{"atl":[[2.88,10.64],[2.84,39.11]],"id":70003370}],"con":true,"img":false}]}
{"op":"mcm","clk":"11450446388","pt":1717322139386,"mc":[{"id":"1.229554916","rc":[{"atl":[[19,1.11],[20,0]],"id":51562794},{"atb":[[1.52,52.91]],"id":46292327},{"atl":[[2.74,0]],"id":46292327},{"atl":[[4.5,19.95],[4.6,19.16]],"id":56606596},{"atl":[[2.84,0]],"id":70003370}],"con":true,"img":false}]}
{"op":"mcm","clk":"11450446396","pt":1717322139492,"mc":[{"id":"1.229554916","rc":[{"atl":[[4.6,5.56]],"id":56606596},{"atl":[[2.88,49.75]],"id":70003370}],"con":true,"img":false}]}
{"op":"mcm","clk":"11450446455","pt":1717322140272,"mc":[{"id":"1.229554916","rc":[{"atb":[[1.07,48.8]],"id":64927898}],"con":true,"img":false}]}
{"op":"mcm","clk":"11450446471","pt":1717322140478,"mc":[{"id":"1.229554916","rc":[{"atl":[[19,0],[25,0]],"id":51562794},{"atb":[[1.52,14.45]],"id":46292327},{"atl":[[2.74,11.49],[2.78,0]],"id":46292327},{"atl":[[22,1],[23,0]],"id":42099039},{"atl":[[2.88,39.11],[2.84,10.87]],"id":70003370}],"con":true,"img":false}]}
{"op":"mcm","clk":"11450446494","pt":1717322140739,"mc":[{"id":"1.229554916","rc":[{"atl":[[18.5,0],[20,1.05]],"id":51562794},{"atb":[[1.52,52.91]],"id":46292327},{"atl":[[2.74,0],[2.78,11.24]],"id":46292327},{"atl":[[4.5,14.24]],"id":56606596},{"atl":[[22,0],[23,1]],"id":42099039},{"atl":[[2.88,49.75],[2.84,0]],"id":70003370}],"con":true,"img":false}]}
{"op":"mcm","clk":"11450446508","pt":1717322140944,"mc":[{"id":"1.229554916","rc":[{"atl":[[18.5,1.14]],"id":51562794},{"atb":[[1.52,14.45]],"id":46292327},{"atl":[[2.74,11.49],[2.78,0]],"id":46292327},{"atl":[[4.5,19.95]],"id":56606596},{"atl":[[22,1],[23,0]],"id":42099039},{"atl":[[2.88,39.11],[2.84,10.87]],"id":70003370}],"con":true,"img":false}]}
{"op":"mcm","clk":"11450446524","pt":1717322141154,"mc":[{"id":"1.229554916","rc":[{"atl":[[18.5,0]],"id":51562794},{"atb":[[1.52,52.91]],"id":46292327},{"atl":[[2.74,0],[2.78,11.24]],"id":46292327},{"atl":[[4.5,14.24]],"id":56606596},{"atl":[[22,0],[23,1]],"id":42099039},{"atl":[[2.88,49.75],[2.84,0]],"id":70003370}],"con":true,"img":false}]}
{"op":"mcm","clk":"11450446532","pt":1717322141309,"mc":[{"id":"1.229554916","rc":[{"atb":[[3,0],[3.45,40.82],[5.1,18.49],[4.6,0],[6.2,13.43],[3.9,0],[4.2,0],[4.7,5]],"id":51562794},{"atl":[[44,0],[18.5,5.71],[19,1.11]],"id":51562794},{"atb":[[1.58,43.02],[1.96,2.5],[1.92,5],[1.57,45.5],[1.88,10]],"id":46292327},{"atl":[[3.1,9.52],[6.8,0],[4.4,29.41],[2.74,31.15]],"id":46292327},{"atb":[[2.36,2.5],[1.98,0],[2.28,5],[1.9,51.27],[2.2,10],[1.17,0]],"id":56606596},{"atl":[[10.5,0],[4.7,28.01]],"id":56606596},{"atb":[[2.82,30.67],[2.54,5],[2.12,0],[2.62,24],[1.8,28.66],[2.28,0],[2.46,10],[1.3,0],[2.2,0]],"id":65788088},{"atl":[[5.5,33.33],[12,0]],"id":65788088},{"atb":[[5.6,5],[5.3,0],[6,2.5],[4.9,0],[5.7,7.41]],"id":42099039},{"atl":[[55,0],[27,3.85]],"id":42099039},{"atb":[[1.58,0],[1.62,0],[1.96,2.5],[1.93,47.91],[1.92,5],[1.54,0],[1.88,10],[1.29,36.1]],"id":70003370},{"atl":[[2.92,10.42],[3.7,37.04],[6.8,0]],"id":70003370},{"atb":[[1.47,41.6]],"id":65293046},{"atl":[[5.3,0],[2.76,11.36],[2.42,0],[2.96,0],[3.65,36.12]],"id":65293046},{"atb":[[1.14,2.5],[1.06,10],[1.09,23.49],[1.1,5],[1.05,97.6]],"id":64927898},{"atl":[[1.78,157.85],[3.7,0]],"id":64927898}],"con":true,"img":false}]}
{"op":"mcm","clk":"11450446539","pt":1717322141361,"mc":[{"id":"1.229554916","rc":[{"atb":[[1.52,38.46]],"id":46292327},{"atl":[[2.78,0]],"id":46292327},{"atl":[[2.88,39.11]],"id":70003370},{"atb":[[1.12,56.34]],"id":64927898}],"con":true,"img":false}]}
{"op":"mcm","clk":"11450446550","pt":1717322141470,"mc":[{"id":"1.229554916","rc":[{"atb":[[5.1,10.99]],"id":51562794},{"atb":[[1.58,0],[1.75,45.51]],"id":46292327},{"atl":[[2.8,0],[2.92,0],[2.74,0],[2.84,0]],"id":46292327},{"atl":[[2.88,0]],"id":70003370},{"atl":[[3.4,41.67],[3.65,0]],"id":65293046},{"atb":[[1.09,0]],"id":64927898}],"con":true,"img":false}]}
{"op":"mcm","clk":"11450446557","pt":1717322141569,"mc":[{"id":"1.229554916","rc":[{"atl":[[16.5,6.45],[18.5,1.14],[19,0]],"id":51562794},{"atb":[[1.48,0],[1.52,0]],"id":46292327},{"atl":[[2.82,15.83]],"id":46292327},{"atl":[[4.5,19.95]],"id":56606596},{"atl":[[22,1],[23,0],[24,4.35],[27,0]],"id":42099039},{"atl":[[2.92,46.94],[3.45,40.82],[3.7,0]],"id":70003370},{"atl":[[2.44,0],[3.15,46.51]],"id":65293046},{"atb":[[1.07,0]],"id":64927898}],"con":true,"img":false}]}
{"op":"mcm","clk":"11450446564","pt":1717322141673,"mc":[{"id":"1.229554916","rc":[{"atl":[[4,5],[3.8,2.5],[4.4,39.41]],"id":46292327},{"atl":[[3.65,2.5]],"id":70003370},{"atl":[[2.4,0],[3.4,0]],"id":65293046}],"con":true,"img":false}]}
{"op":"mcm","clk":"11450446572","pt":1717322141778,"mc":[{"id":"1.229554916","rc":[{"atl":[[2.82,0]],"id":46292327}],"con":true,"img":false}]}
{"op":"mcm","clk":"11450446578","pt":1717322141880,"mc":[{"id":"1.229554916","rc":[{"atl":[[2.44,41.56]],"id":65293046}],"con":true,"img":false}]}
{"op":"mcm","clk":"11450446586","pt":1717322141983,"mc":[{"id":"1.229554916","rc":[{"atl":[[3.1,20.41]],"id":46292327}],"con":true,"img":false}]}
{"op":"mcm","clk":"11450446601","pt":1717322142147,"mc":[{"id":"1.229554916","rc":[{"atb":[[1.57,38.62]],"id":46292327}],"con":true,"img":false}]}
{"op":"mcm","clk":"11450446615","pt":1717322142353,"mc":[{"id":"1.229554916","rc":[{"atl":[[18.5,0],[20,0]],"id":51562794},{"atb":[[1.78,5.03]],"id":46292327},{"atl":[[4.5,14.24]],"id":56606596},{"atl":[[2.46,0]],"id":65293046}],"con":true,"img":false}]}
{"op":"mcm","clk":"11450446620","pt":1717322142453,"mc":[{"id":"1.229554916","rc":[{"atl":[[2.44,0]],"id":65293046}],"con":true,"img":false}]}
{"op":"mcm","clk":"11450446628","pt":1717322142610,"mc":[{"id":"1.229554916","rc":[{"atl":[[2.5,99.44]],"id":65293046}],"con":true,"img":false}]}
{"op":"mcm","clk":"11450446657","pt":1717322142870,"mc":[{"id":"1.229554916","rc":[{"atl":[[20,1.05]],"id":51562794},{"atl":[[4.6,0]],"id":56606596}],"con":true,"img":false}]}
{"op":"mcm","clk":"11450446677","pt":1717322143076,"mc":[{"id":"1.229554916","rc":[{"atl":[[55,6.94]],"id":51562794},{"atl":[[11,45.85],[5.7,0]],"id":46292327},{"atb":[[1.67,90.16]],"id":56606596},{"atl":[[17,27.85],[4.5,0]],"id":56606596},{"atb":[[1.81,80.34]],"id":65788088},{"atl":[[19.5,23.32]],"id":65788088},{"atb":[[3.55,36.96]],"id":42099039},{"atl":[[65,5.81]],"id":42099039},{"atb":[[1.22,117.33]],"id":65293046},{"atl":[[6,65.82]],"id":65293046},{"atb":[[1.35,139.68]],"id":70003370},{"atl":[[9.8,41.81]],"id":70003370},{"atb":[[1.04,285.17]],"id":64927898},{"atl":[[3.5,92.94]],"id":64927898}],"con":true,"img":false}]}
{"op":"mcm","clk":"11450446686","pt":1717322143181,"mc":[{"id":"1.229554916","rc":[{"atl":[[38,0]],"id":51562794},{"atl":[[7.6,8.37],[7,0]],"id":46292327},{"atb":[[1.81,0]],"id":56606596},{"atl":[[4.6,21.17],[13.5,0]],"id":56606596},{"atb":[[1.9,0]],"id":65788088},{"atl":[[15,0]],"id":65788088},{"atb":[[3.75,0]],"id":42099039},{"atl":[[44,0]],"id":42099039},{"atb":[[1.42,0]],"id":70003370},{"atl":[[7.6,0]],"id":70003370},{"atb":[[1.24,0]],"id":65293046},{"atl":[[4.8,0]],"id":65293046},{"atb":[[1.08,99.3]],"id":64927898},{"atl":[[2.86,0]],"id":64927898}],"con":true,"img":false}]}
{"op":"mcm","clk":"11450446689","pt":1717322143281,"mc":[{"id":"1.229554916","rc":[{"atl":[[2.5,49.44]],"id":65293046}],"con":true,"img":false}]}
{"op":"mcm","clk":"11450446704","pt":1717322143385,"mc":[{"id":"1.229554916","rc":[{"atl":[[2.5,0]],"id":65293046}],"con":true,"img":false}]}
{"op":"mcm","clk":"11450446712","pt":1717322143441,"mc":[{"id":"1.229554916","rc":[{"atl":[[2.54,28.47],[3.7,5],[3.9,24.43],[3.5,2.5]],"id":65293046}],"con":true,"img":false}]}
{"op":"mcm","clk":"11450446720","pt":1717322143544,"mc":[{"id":"1.229554916","rc":[{"atb":[[1.23,86.96]],"id":65293046},{"atl":[[2.54,0]],"id":65293046}],"con":true,"img":false}]}
{"op":"mcm","clk":"11450446727","pt":1717322143646,"mc":[{"id":"1.229554916","rc":[{"atl":[[22,0],[23,1]],"id":42099039},{"atl":[[2.76,39.83]],"id":65293046}],"con":true,"img":false}]}
{"op":"mcm","clk":"11450446773","pt":1717322144268,"mc":[{"id":"1.229554916","rc":[{"atl":[[19,1.11]],"id":51562794},{"atl":[[4.6,26.73]],"id":56606596}],"con":true,"img":false}]}
{"op":"mcm","clk":"11450446891","pt":1717322145559,"mc":[{"id":"1.229554916","rc":[{"atl":[[6,0]],"id":65293046}],"con":true,"img":false}]}
{"op":"mcm","clk":"11450446901","pt":1717322145664,"mc":[{"id":"1.229554916","rc":[{"atl":[[7.4,65.82]],"id":65293046}],"con":true,"img":false}]}
{"op":"mcm","clk":"11450446961","pt":1717322146444,"mc":[{"id":"1.229554916","rc":[{"atl":[[4.9,30.77],[4.7,2.5]],"id":56606596}],"con":true,"img":false}]}
{"op":"mcm","clk":"11450446993","pt":1717322146868,"mc":[{"id":"1.229554916","rc":[{"atb":[[1.8,0],[1.93,34.01]],"id":65788088}],"con":true,"img":false}]}
{"op":"mcm","clk":"11450447029","pt":1717322147440,"mc":[{"id":"1.229554916","rc":[{"atl":[[5.4,11.36]],"id":65788088}],"con":true,"img":false}]}
{"op":"mcm","clk":"11450447060","pt":1717322147852,"mc":[{"id":"1.229554916","rc":[{"atl":[[4.5,5.71]],"id":56606596}],"con":true,"img":false}]}
{"op":"mcm","clk":"11450447072","pt":1717322148057,"mc":[{"id":"1.229554916","rc":[{"atl":[[24,0]],"id":51562794}],"con":true,"img":false}]}
{"op":"mcm","clk":"11450447086","pt":1717322148167,"mc":[{"id":"1.229554916","rc":[{"atl":[[29,2.61]],"id":51562794}],"con":true,"img":false}]}
{"op":"mcm","clk":"11450447144","pt":1717322148895,"mc":[{"id":"1.229554916","rc":[{"atl":[[3.9,10]],"id":65293046}],"con":true,"img":false}]}
{"op":"mcm","clk":"11450447153","pt":1717322148986,"mc":[{"id":"1.229554916","rc":[{"atl":[[4.7,14.43]],"id":65293046}],"con":true,"img":false}]}
{"op":"mcm","clk":"11450447211","pt":1717322149555,"mc":[{"id":"1.229554916","rc":[{"atl":[[3.2,22.73]],"id":46292327},{"atl":[[2.96,25.51]],"id":70003370}],"con":true,"img":false}]}
{"op":"mcm","clk":"11450447268","pt":1717322150488,"mc":[{"id":"1.229554916","rc":[{"atl":[[19,0]],"id":51562794},{"atl":[[4.8,5.26],[4.5,0]],"id":56606596}],"con":true,"img":false}]}
{"op":"mcm","clk":"11450447275","pt":1717322150597,"mc":[{"id":"1.229554916","rc":[{"atl":[[5.2,13.24],[5.4,4.55]],"id":65788088}],"con":true,"img":false}]}
{"op":"mcm","clk":"11450447282","pt":1717322150697,"mc":[{"id":"1.229554916","rc":[{"atl":[[4.6,21.17]],"id":56606596},{"atl":[[5.5,26.66]],"id":65788088}],"con":true,"img":false}]}
{"op":"mcm","clk":"11450447309","pt":1717322151011,"mc":[{"id":"1.229554916","rc":[{"atl":[[5.3,0]],"id":65788088}],"con":true,"img":false}]}
{"op":"mcm","clk":"11450447316","pt":1717322151074,"mc":[{"id":"1.229554916","rc":[{"atl":[[5.2,0]],"id":65788088}],"con":true,"img":false}]}
{"op":"mcm","clk":"11450447324","pt":1717322151173,"mc":[{"id":"1.229554916","rc":[{"atl":[[5.6,24.24],[5.5,4.44]],"id":65788088}],"con":true,"img":false}]}
{"op":"mcm","clk":"11450447330","pt":1717322151278,"mc":[{"id":"1.229554916","rc":[{"atl":[[5.3,18.6]],"id":65788088}],"con":true,"img":false}]}
{"op":"mcm","clk":"11450447363","pt":1717322151694,"mc":[{"id":"1.229554916","rc":[{"atl":[[5.4,0]],"id":65788088}],"con":true,"img":false}]}
{"op":"mcm","clk":"11450447383","pt":1717322151900,"mc":[{"id":"1.229554916","rc":[{"atl":[[2.8,27.78]],"id":65293046}],"con":true,"img":false}]}
{"op":"mcm","clk":"11450447394","pt":1717322152002,"mc":[{"id":"1.229554916","rc":[{"atl":[[27,2.88]],"id":42099039}],"con":true,"img":false}]}
{"op":"mcm","clk":"11450447445","pt":1717322152573,"mc":[{"id":"1.229554916","rc":[{"atl":[[5.3,0]],"id":65788088}],"con":true,"img":false}]}
{"op":"mcm","clk":"11450447455","pt":1717322152677,"mc":[{"id":"1.229554916","rc":[{"atl":[[5.6,2.5],[6,25],[5.4,18.18]],"id":65788088}],"con":true,"img":false}]}
{"op":"mcm","clk":"11450447492","pt":1717322153092,"mc":[{"id":"1.229554916","rc":[{"atl":[[11,0]],"id":56606596}],"con":true,"img":false}]}
{"op":"mcm","clk":"11450447498","pt":1717322153145,"mc":[{"id":"1.229554916","rc":[{"atl":[[10.5,4.65]],"id":56606596}],"con":true,"img":false}]}
