{"op":"mcm","clk":"11449075386","pt":1717303241523,"mc":[{"id":"1.229554932","marketDefinition":{"bspMarket":false,"turnInPlayEnabled":false,"persistenceEnabled":false,"marketBaseRate":7.0,"eventId":"33318908","eventTypeId":"4339","numberOfWinners":1,"bettingType":"ODDS","marketType":"EXACTA","marketTime":"2024-06-02T11:02:00.000Z","suspendTime":"2024-06-02T11:02:00.000Z","bspReconciled":false,"complete":true,"inPlay":false,"crossMatching":true,"runnersVoidable":false,"numberOfActiveRunners":12,"betDelay":0,"status":"OPEN","runners":[{"status":"ACTIVE","sortPriority":1,"id":52385884,"name":"1 - 4"},{"status":"ACTIVE","sortPriority":2,"id":52385886,"name":"1 - 6"},{"status":"ACTIVE","sortPriority":3,"id":52385888,"name":"1 - 8"},{"status":"ACTIVE","sortPriority":4,"id":52385903,"name":"4 - 1"},{"status":"ACTIVE","sortPriority":5,"id":52385907,"name":"4 - 6"},{"status":"ACTIVE","sortPriority":6,"id":52385909,"name":"4 - 8"},{"status":"ACTIVE","sortPriority":7,"id":52385917,"name":"6 - 1"},{"status":"ACTIVE","sortPriority":8,"id":52385920,"name":"6 - 4"},{"status":"ACTIVE","sortPriority":9,"id":52385923,"name":"6 - 8"},{"status":"ACTIVE","sortPriority":10,"id":52385931,"name":"8 - 1"},{"status":"ACTIVE","sortPriority":11,"id":52385934,"name":"8 - 4"},{"status":"ACTIVE","sortPriority":12,"id":52385936,"name":"8 - 6"}],"regulators":["MR_INT"],"venue":"Murray Bridge","countryCode":"AU","discountAllowed":true,"timezone":"Australia/Adelaide","openDate":"2024-06-02T08:21:00.000Z","version":5962801924,"name":"Exacta","eventName":"Murray Bridge (AUS) 2nd Jun"},"rc":[],"con":true,"img":false}]}
{"op":"mcm","clk":"11449099382","pt":1717303849562,"mc":[{"id":"1.229554932","rc":[{"atb":[[9.8,27.71],[14.5,7.74]],"id":52385907},{"atb":[[3.7,90.33],[4.4,30.74]],"id":52385909},{"atb":[[13.5,8.36],[9.4,29.03]],"id":52385886},{"atb":[[2.4,174.21],[2.6,65.33]],"id":52385903},{"atb":[[3.85,36.67],[3.35,103.78]],"id":52385888},{"atb":[[2.5,69.68],[2.3,187.62]],"id":52385884}],"con":true,"img":false}]}
{"op":"mcm","clk":"11449099388","pt":1717303849619,"mc":[{"id":"1.229554932","rc":[{"atb":[[32,3.37],[21,12.19]],"id":52385923},{"atb":[[5.2,24.88],[4.2,76.22]],"id":52385934},{"atb":[[18,6.14],[13,20.32]],"id":52385920},{"atb":[[18.5,13.93],[27,4.01]],"id":52385936},{"atb":[[4,81.3],[5,26.13]],"id":52385931},{"atb":[[17.5,6.33],[12.5,21.2]],"id":52385917}],"con":true,"img":false}]}
{"op":"mcm","clk":"11449371144","pt":1717308120469,"mc":[{"id":"1.229554932","rc":[{"atb":[[160,0.16],[80,0.99],[110,0.48],[55,1.94]],"id":52385923},{"atb":[[17.5,6.34],[20,4.13],[25,2.18],[30,0.9]],"id":52385907},{"atb":[[5,26.16],[5.5,17.44],[6,10.46],[7,4.36]],"id":52385909},{"atb":[[11,2.62],[7.4,16.35],[8.4,10.61],[9.4,6.23]],"id":52385934},{"atb":[[18,4.61],[21,2.62],[26,1.05],[15.5,7.21]],"id":52385886},{"atb":[[2.8,43.6],[2.9,27.54],[3,13.08],[2.7,61.55]],"id":52385903},{"atb":[[34,3.17],[85,0.31],[44,1.83],[60,0.88]],"id":52385920},{"atb":[[65,0.82],[36,2.99],[90,0.29],[46,1.74]],"id":52385936},{"atb":[[4.5,29.89],[5,19.62],[5.5,11.63],[6,5.23]],"id":52385888},{"atb":[[6.8,18.04],[9.8,2.97],[8.8,6.71],[7.8,11.54]],"id":52385931},{"atb":[[2.86,42.19],[3.15,12.17],[2.96,26.69],[2.76,59.45]],"id":52385884},{"atb":[[75,0.36],[40,2.01],[50,1.07],[30,3.61]],"id":52385917}],"con":true,"img":false}]}
{"op":"mcm","clk":"11449371597","pt":1717308131121,"mc":[{"id":"1.229554932","rc":[{"atb":[[4.5,0],[5,0],[5.5,0],[6,0]],"id":52385888},{"atb":[[6.8,0],[9.8,0],[8.8,0],[7.8,0]],"id":52385931},{"atb":[[2.86,0],[3.15,0],[2.96,0],[2.76,0]],"id":52385884},{"atb":[[75,0],[40,0],[50,0],[30,0]],"id":52385917}],"con":true,"img":false}]}
{"op":"mcm","clk":"11449371635","pt":1717308131806,"mc":[{"id":"1.229554932","rc":[{"atb":[[6.4,4.84],[5.2,18.68],[5.7,11.13],[4.7,28.28]],"id":52385888},{"atb":[[7.2,16.88],[9.2,6.38],[10.5,2.75],[8.2,10.9]],"id":52385931},{"atb":[[3.1,24.91],[3.35,11.13],[2.84,56.87],[2.94,40.45]],"id":52385884},{"atb":[[32,3.37],[80,0.33],[42,1.92],[55,0.97]],"id":52385917}],"con":true,"img":false}]}
{"op":"mcm","clk":"11449436817","pt":1717309118923,"mc":[{"id":"1.229554932","rc":[{"atb":[[3.1,0],[3.35,0],[2.84,0],[2.94,0]],"id":52385884}],"con":true,"img":false}]}
{"op":"mcm","clk":"11449436866","pt":1717309119594,"mc":[{"id":"1.229554932","rc":[{"atb":[[2.86,42.19],[3.15,12.17],[2.96,26.69],[2.76,59.45]],"id":52385884}],"con":true,"img":false}]}
{"op":"mcm","clk":"11449497945","pt":1717309918992,"mc":[{"id":"1.229554932","rc":[{"atb":[[160,0],[80,0],[110,0],[55,0]],"id":52385923},{"atb":[[5,0],[5.5,0],[6,0],[7,0]],"id":52385909},{"atb":[[18,0],[21,0],[26,0],[15.5,0]],"id":52385886},{"atb":[[34,0],[85,0],[44,0],[60,0]],"id":52385920},{"atb":[[32,0],[80,0],[42,0],[55,0]],"id":52385917}],"con":true,"img":false}]}
{"op":"mcm","clk":"11449497993","pt":1717309919718,"mc":[{"id":"1.229554932","rc":[{"atb":[[170,0.16],[85,0.94],[120,0.44],[60,1.77]],"id":52385923},{"atb":[[6.8,4.51],[4.9,26.83],[5.9,10.68],[5.4,17.84]],"id":52385909},{"atb":[[16,6.97],[18.5,4.48],[22,2.49],[27,1]],"id":52385886},{"atb":[[65,0.82],[36,2.99],[90,0.29],[46,1.74]],"id":52385920},{"atb":[[34,3.17],[85,0.31],[44,1.83],[60,0.88]],"id":52385917}],"con":true,"img":false}]}
{"op":"mcm","clk":"11449552090","pt":1717310825536,"mc":[{"id":"1.229554932","rc":[{"atb":[[2.86,0],[3.15,0],[2.96,0],[2.76,0]],"id":52385884}],"con":true,"img":false}]}
{"op":"mcm","clk":"11449552121","pt":1717310826261,"mc":[{"id":"1.229554932","rc":[{"atb":[[3.1,24.91],[3.35,11.13],[2.84,56.87],[2.94,40.45]],"id":52385884}],"con":true,"img":false}]}
{"op":"mcm","clk":"11449557375","pt":1717310919290,"mc":[{"id":"1.229554932","rc":[{"atb":[[3.1,0],[3.35,0],[2.84,0],[2.94,0]],"id":52385884}],"con":true,"img":false}]}
{"op":"mcm","clk":"11449557422","pt":1717310920170,"mc":[{"id":"1.229554932","rc":[{"atb":[[2.86,42.19],[3.15,12.17],[2.96,26.69],[2.76,59.45]],"id":52385884}],"con":true,"img":false}]}
{"op":"mcm","clk":"11449592139","pt":1717311545533,"mc":[{"id":"1.229554932","rc":[{"atb":[[5.4,0]],"id":52385909}],"con":true,"img":false}]}
{"op":"mcm","clk":"11449592178","pt":1717311546205,"mc":[{"id":"1.229554932","rc":[{"atb":[[5.5,17.44]],"id":52385909}],"con":true,"img":false}]}
{"op":"mcm","clk":"11449593346","pt":1717311567454,"mc":[{"id":"1.229554932","rc":[{"atb":[[6.8,0]],"id":52385909}],"con":true,"img":false}]}
{"op":"mcm","clk":"11449593390","pt":1717311568173,"mc":[{"id":"1.229554932","rc":[{"atb":[[4.9,0]],"id":52385909}],"con":true,"img":false}]}
{"op":"mcm","clk":"11449593395","pt":1717311568279,"mc":[{"id":"1.229554932","rc":[{"atb":[[5.9,0]],"id":52385909}],"con":true,"img":false}]}
{"op":"mcm","clk":"11449593438","pt":1717311568838,"mc":[{"id":"1.229554932","rc":[{"atb":[[5,26.16],[7,4.36]],"id":52385909}],"con":true,"img":false}]}
{"op":"mcm","clk":"11449593447","pt":1717311569039,"mc":[{"id":"1.229554932","rc":[{"atb":[[6,10.46]],"id":52385909}],"con":true,"img":false}]}
{"op":"mcm","clk":"11449624324","pt":1717312169412,"mc":[{"id":"1.229554932","rc":[{"atb":[[32,0],[21,0]],"id":52385923},{"atb":[[9.8,0],[14.5,0]],"id":52385907},{"atb":[[3.7,0],[4.4,0]],"id":52385909},{"atb":[[13.5,0],[9.4,0]],"id":52385886},{"atb":[[5.2,0],[4.2,0]],"id":52385934},{"atb":[[2.4,0],[2.6,0]],"id":52385903},{"atb":[[18,0],[13,0]],"id":52385920},{"atb":[[3.85,0],[3.35,0]],"id":52385888},{"atb":[[18.5,0],[27,0]],"id":52385936},{"atb":[[4,0],[5,0]],"id":52385931},{"atb":[[2.5,0],[2.3,0]],"id":52385884},{"atb":[[17.5,0],[12.5,0]],"id":52385917}],"con":true,"img":false}]}
{"op":"mcm","clk":"11449625470","pt":1717312196390,"mc":[{"id":"1.229554932","rc":[{"atb":[[9.8,27.71],[14.5,7.74]],"id":52385907},{"atb":[[32,3.37],[21,12.19]],"id":52385923},{"atb":[[3.7,90.33],[4.4,30.74]],"id":52385909},{"atb":[[5.2,24.88],[4.2,76.22]],"id":52385934},{"atb":[[13.5,8.36],[9.4,29.03]],"id":52385886},{"atb":[[2.4,174.21],[2.6,65.33]],"id":52385903},{"atb":[[18.5,13.93],[27,4.01]],"id":52385936},{"atb":[[3.85,36.67],[3.35,103.78]],"id":52385888},{"atb":[[18,6.14],[13,20.32]],"id":52385920},{"atb":[[4,81.3],[5,26.13]],"id":52385931},{"atb":[[2.5,69.68],[2.3,187.62]],"id":52385884},{"atb":[[17.5,6.33],[12.5,21.2]],"id":52385917}],"con":true,"img":false}]}
{"op":"mcm","clk":"11449626450","pt":1717312220585,"mc":[{"id":"1.229554932","rc":[{"atb":[[32,0],[21,0]],"id":52385923},{"atb":[[9.8,0],[14.5,0]],"id":52385907},{"atb":[[3.7,0],[4.4,0]],"id":52385909},{"atb":[[13.5,0],[9.4,0]],"id":52385886},{"atb":[[5.2,0],[4.2,0]],"id":52385934},{"atb":[[2.4,0],[2.6,0]],"id":52385903},{"atb":[[18.5,0],[27,0]],"id":52385936},{"atb":[[18,0],[13,0]],"id":52385920},{"atb":[[3.85,0],[3.35,0]],"id":52385888},{"atb":[[4,0],[5,0]],"id":52385931},{"atb":[[2.5,0],[2.3,0]],"id":52385884},{"atb":[[17.5,0],[12.5,0]],"id":52385917}],"con":true,"img":false}]}
{"op":"mcm","clk":"11449626906","pt":1717312229610,"mc":[{"id":"1.229554932","rc":[{"atb":[[9.8,27.71],[14.5,7.74]],"id":52385907},{"atb":[[32,3.37],[21,12.19]],"id":52385923},{"atb":[[3.7,90.33],[4.4,30.74]],"id":52385909},{"atb":[[13.5,8.36],[9.4,29.03]],"id":52385886},{"atb":[[5.2,24.88],[4.2,76.22]],"id":52385934},{"atb":[[2.4,174.21],[2.6,65.33]],"id":52385903},{"atb":[[18,6.14],[13,20.32]],"id":52385920},{"atb":[[18.5,13.93],[27,4.01]],"id":52385936},{"atb":[[3.85,36.67],[3.35,103.78]],"id":52385888},{"atb":[[4,81.3],[5,26.13]],"id":52385931},{"atb":[[2.5,69.68],[2.3,187.62]],"id":52385884},{"atb":[[17.5,6.33],[12.5,21.2]],"id":52385917}],"con":true,"img":false}]}
{"op":"mcm","clk":"11449630237","pt":1717312316541,"mc":[{"id":"1.229554932","rc":[{"atb":[[5,0],[5.5,0],[6,0],[7,0]],"id":52385909},{"atb":[[11,0],[7.4,0],[8.4,0],[9.4,0]],"id":52385934}],"con":true,"img":false}]}
{"op":"mcm","clk":"11449630260","pt":1717312317212,"mc":[{"id":"1.229554932","rc":[{"atb":[[5.6,17.06],[7.2,4.22],[5.1,25.52],[6.2,10.06]],"id":52385909},{"atb":[[9.6,6.08],[8.6,10.33],[11.5,2.49],[7.6,15.85]],"id":52385934}],"con":true,"img":false}]}
{"op":"mcm","clk":"11449632431","pt":1717312371107,"mc":[{"id":"1.229554932","rc":[{"atb":[[2.8,0],[2.9,0],[3,0],[2.7,0]],"id":52385903}],"con":true,"img":false}]}
{"op":"mcm","clk":"11449632458","pt":1717312371775,"mc":[{"id":"1.229554932","rc":[{"atb":[[2.82,43.12],[2.92,27.25],[2.72,60.84],[3.05,12.76]],"id":52385903}],"con":true,"img":false}]}
{"op":"mcm","clk":"11449645970","pt":1717312718913,"mc":[{"id":"1.229554932","rc":[{"atb":[[65,0],[36,0],[90,0],[46,0]],"id":52385936},{"atb":[[2.86,0],[3.15,0],[2.96,0],[2.76,0]],"id":52385884}],"con":true,"img":false}]}
{"op":"mcm","clk":"11449645991","pt":1717312719633,"mc":[{"id":"1.229554932","rc":[{"atb":[[70,0.76],[38,2.83],[95,0.28],[48,1.67]],"id":52385936},{"atb":[[2.82,43.12],[2.92,27.25],[2.72,60.84],[3.05,12.76]],"id":52385884}],"con":true,"img":false}]}
{"op":"mcm","clk":"11449686772","pt":1717313524444,"mc":[{"id":"1.229554932","rc":[{"atb":[[170,0],[85,0],[120,0],[60,0]],"id":52385923},{"atb":[[17.5,0],[20,0],[25,0],[30,0]],"id":52385907},{"atb":[[2.82,0],[2.92,0],[2.72,0],[3.05,0]],"id":52385884}],"con":true,"img":false}]}
{"op":"mcm","clk":"11449686824","pt":1717313525160,"mc":[{"id":"1.229554932","rc":[{"atb":[[130,0.41],[65,1.64],[180,0.15],[90,0.88]],"id":52385923},{"atb":[[32,0.84],[18,6.15],[21,3.92],[26,2.09]],"id":52385907},{"atb":[[2.74,60.13],[3.1,12.46],[2.84,42.65],[2.94,26.97]],"id":52385884}],"con":true,"img":false}]}
{"op":"mcm","clk":"11449686983","pt":1717313527017,"mc":[{"id":"1.229554932","rc":[{"atb":[[2.74,0],[3.1,0],[2.84,0],[2.94,0]],"id":52385884}],"con":true,"img":false}]}
{"op":"mcm","clk":"11449687032","pt":1717313527740,"mc":[{"id":"1.229554932","rc":[{"atb":[[2.86,42.19],[3.15,12.17],[2.96,26.69],[2.76,59.45]],"id":52385884}],"con":true,"img":false}]}
{"op":"mcm","clk":"11449687990","pt":1717313538454,"mc":[{"id":"1.229554932","rc":[{"atb":[[2.86,0],[3.15,0],[2.96,0],[2.76,0]],"id":52385884}],"con":true,"img":false}]}
{"op":"mcm","clk":"11449688055","pt":1717313539175,"mc":[{"id":"1.229554932","rc":[{"atb":[[2.82,43.12],[2.92,27.25],[2.72,60.84],[3.05,12.76]],"id":52385884}],"con":true,"img":false}]}
{"op":"mcm","clk":"11449862846","pt":1717315412340,"mc":[{"id":"1.229554932","rc":[{"atb":[[32,0],[21,0]],"id":52385923},{"atb":[[9.8,0],[14.5,0]],"id":52385907},{"atb":[[3.7,0],[4.4,0]],"id":52385909},{"atb":[[5.2,0],[4.2,0]],"id":52385934},{"atb":[[13.5,0],[9.4,0]],"id":52385886},{"atb":[[2.4,0],[2.6,0]],"id":52385903},{"atb":[[18.5,0],[27,0]],"id":52385936},{"atb":[[3.85,0],[3.35,0]],"id":52385888},{"atb":[[18,0],[13,0]],"id":52385920},{"atb":[[4,0],[5,0]],"id":52385931},{"atb":[[2.5,0],[2.3,0]],"id":52385884},{"atb":[[17.5,0],[12.5,0]],"id":52385917}],"con":true,"img":false}]}
{"op":"mcm","clk":"11449866542","pt":1717315447498,"mc":[{"id":"1.229554932","rc":[{"atb":[[32,3.37],[21,12.19]],"id":52385923},{"atb":[[9.8,27.71],[14.5,7.74]],"id":52385907},{"atb":[[3.7,90.33],[4.4,30.74]],"id":52385909},{"atb":[[5.2,24.88],[4.2,76.22]],"id":52385934},{"atb":[[13.5,8.36],[9.4,29.03]],"id":52385886},{"atb":[[2.4,174.21],[2.6,65.33]],"id":52385903},{"atb":[[3.85,36.67],[3.35,103.78]],"id":52385888},{"atb":[[18,6.14],[13,20.32]],"id":52385920},{"atb":[[18.5,13.93],[27,4.01]],"id":52385936},{"atb":[[4,81.3],[5,26.13]],"id":52385931},{"atb":[[2.5,69.68],[2.3,187.62]],"id":52385884},{"atb":[[17.5,6.33],[12.5,21.2]],"id":52385917}],"con":true,"img":false}]}
{"op":"mcm","clk":"11449874231","pt":1717315519793,"mc":[{"id":"1.229554932","rc":[{"atb":[[9.8,0],[14.5,0]],"id":52385907},{"atb":[[32,0],[21,0]],"id":52385923},{"atb":[[3.7,0],[4.4,0]],"id":52385909},{"atb":[[13.5,0],[9.4,0]],"id":52385886},{"atb":[[5.2,0],[4.2,0]],"id":52385934},{"atb":[[2.4,0],[2.6,0]],"id":52385903},{"atb":[[18.5,0],[27,0]],"id":52385936},{"atb":[[18,0],[13,0]],"id":52385920},{"atb":[[3.85,0],[3.35,0]],"id":52385888},{"atb":[[4,0],[5,0]],"id":52385931},{"atb":[[2.5,0],[2.3,0]],"id":52385884},{"atb":[[17.5,0],[12.5,0]],"id":52385917}],"con":true,"img":false}]}
{"op":"mcm","clk":"11449875288","pt":1717315530581,"mc":[{"id":"1.229554932","rc":[{"atb":[[9.8,27.71],[14.5,7.74]],"id":52385907},{"atb":[[4.6,29.03],[3.8,87.1]],"id":52385909},{"atb":[[9.2,29.74],[13,8.71]],"id":52385886},{"atb":[[2.42,171.76],[2.62,64.52]],"id":52385903},{"atb":[[3.25,108.4],[3.75,38]],"id":52385888},{"atb":[[2.28,190.55],[2.48,70.62]],"id":52385884}],"con":true,"img":false}]}
{"op":"mcm","clk":"11449876409","pt":1717315541988,"mc":[{"id":"1.229554932","rc":[{"atb":[[32,3.37],[21,12.19]],"id":52385923},{"atb":[[4.3,73.9],[5.3,24.31]],"id":52385934},{"atb":[[18,6.14],[13,20.32]],"id":52385920},{"atb":[[18.5,13.93],[27,4.01]],"id":52385936},{"atb":[[3.95,82.67],[4.9,26.8]],"id":52385931},{"atb":[[17,6.53],[12,22.17]],"id":52385917}],"con":true,"img":false}]}
{"op":"mcm","clk":"11449938382","pt":1717316154630,"mc":[{"id":"1.229554932","rc":[{"atb":[[9.6,0],[8.6,0],[11.5,0],[7.6,0]],"id":52385934},{"atb":[[6.4,0],[5.2,0],[5.7,0],[4.7,0]],"id":52385888}],"con":true,"img":false}]}
{"op":"mcm","clk":"11449938461","pt":1717316155404,"mc":[{"id":"1.229554932","rc":[{"atb":[[11,2.62],[7.4,16.35],[8.4,10.61],[9.4,6.23]],"id":52385934},{"atb":[[5.6,11.37],[5.1,19.14],[4.6,29.07],[6.2,5.03]],"id":52385888}],"con":true,"img":false}]}
{"op":"mcm","clk":"11449939800","pt":1717316169827,"mc":[{"id":"1.229554932","rc":[{"atb":[[130,0],[65,0],[180,0],[90,0]],"id":52385923},{"atb":[[5.6,0],[7.2,0],[5.1,0],[6.2,0]],"id":52385909},{"atb":[[16,0],[18.5,0],[22,0],[27,0]],"id":52385886},{"atb":[[5.6,0],[5.1,0],[4.6,0],[6.2,0]],"id":52385888},{"atb":[[65,0],[36,0],[90,0],[46,0]],"id":52385920},{"atb":[[70,0],[38,0],[95,0],[48,0]],"id":52385936}],"con":true,"img":false}]}
{"op":"mcm","clk":"11449939870","pt":1717316170547,"mc":[{"id":"1.229554932","rc":[{"atb":[[170,0.16],[85,0.94],[120,0.44],[60,1.77]],"id":52385923},{"atb":[[6.4,9.69],[7.4,4.09],[5.2,24.91],[5.7,16.69]],"id":52385909},{"atb":[[18,4.61],[21,2.62],[26,1.05],[15.5,7.21]],"id":52385886},{"atb":[[70,0.76],[38,2.83],[95,0.28],[48,1.67]],"id":52385920},{"atb":[[65,0.82],[36,2.99],[90,0.29],[46,1.74]],"id":52385936},{"atb":[[4.9,20.12],[4.4,30.77],[5.9,5.34],[5.4,11.89]],"id":52385888}],"con":true,"img":false}]}
{"op":"mcm","clk":"11449953153","pt":1717316319949,"mc":[{"id":"1.229554932","rc":[{"atb":[[6.4,0],[7.4,0],[5.2,0],[5.7,0]],"id":52385909},{"atb":[[70,0],[38,0],[95,0],[48,0]],"id":52385920}],"con":true,"img":false}]}
{"op":"mcm","clk":"11449953219","pt":1717316320646,"mc":[{"id":"1.229554932","rc":[{"atb":[[5.6,17.06],[7.2,4.22],[5.1,25.52],[6.2,10.06]],"id":52385909},{"atb":[[65,0.82],[36,2.99],[90,0.29],[46,1.74]],"id":52385920}],"con":true,"img":false}]}
{"op":"mcm","clk":"11449970518","pt":1717316552873,"mc":[{"id":"1.229554932","rc":[{"atb":[[32,0],[21,0]],"id":52385923},{"atb":[[9.8,0],[14.5,0]],"id":52385907},{"atb":[[4.6,0],[3.8,0]],"id":52385909},{"atb":[[9.2,0],[13,0]],"id":52385886},{"atb":[[4.3,0],[5.3,0]],"id":52385934},{"atb":[[2.42,0],[2.62,0]],"id":52385903},{"atb":[[18,0],[13,0]],"id":52385920},{"atb":[[3.25,0],[3.75,0]],"id":52385888},{"atb":[[18.5,0],[27,0]],"id":52385936},{"atb":[[3.95,0],[4.9,0]],"id":52385931},{"atb":[[2.28,0],[2.48,0]],"id":52385884},{"atb":[[17,0],[12,0]],"id":52385917}],"con":true,"img":false}]}
{"op":"mcm","clk":"11449972397","pt":1717316581815,"mc":[{"id":"1.229554932","rc":[{"atb":[[32,3.37],[21,12.19]],"id":52385923},{"atb":[[9.8,27.71],[14.5,7.74]],"id":52385907},{"atb":[[4.6,29.03],[3.8,87.1]],"id":52385909},{"atb":[[4.3,73.9],[5.3,24.31]],"id":52385934},{"atb":[[9.2,29.74],[13,8.71]],"id":52385886},{"atb":[[2.42,171.76],[2.62,64.52]],"id":52385903},{"atb":[[18.5,13.93],[27,4.01]],"id":52385936},{"atb":[[18,6.14],[13,20.32]],"id":52385920},{"atb":[[3.25,108.4],[3.75,38]],"id":52385888},{"atb":[[3.95,82.67],[4.9,26.8]],"id":52385931},{"atb":[[2.28,190.55],[2.48,70.62]],"id":52385884},{"atb":[[17,6.53],[12,22.17]],"id":52385917}],"con":true,"img":false}]}
{"op":"mcm","clk":"11450020045","pt":1717317157642,"mc":[{"id":"1.229554932","rc":[{"atb":[[11,0],[7.4,0],[8.4,0],[9.4,0]],"id":52385934}],"con":true,"img":false}]}
{"op":"mcm","clk":"11450020123","pt":1717317158362,"mc":[{"id":"1.229554932","rc":[{"atb":[[9.6,6.08],[11.5,2.49],[7.6,15.85]],"id":52385934}],"con":true,"img":false}]}
{"op":"mcm","clk":"11450020134","pt":1717317158465,"mc":[{"id":"1.229554932","rc":[{"atb":[[8.6,10.33]],"id":52385934}],"con":true,"img":false}]}
{"op":"mcm","clk":"11450035226","pt":1717317306298,"mc":[{"id":"1.229554932","rc":[{"atb":[[5.6,0],[7.2,0],[5.1,0],[6.2,0]],"id":52385909},{"atb":[[65,0],[36,0],[90,0],[46,0]],"id":52385920}],"con":true,"img":false}]}
{"op":"mcm","clk":"11450035314","pt":1717317307023,"mc":[{"id":"1.229554932","rc":[{"atb":[[6.4,9.69],[7.4,4.09],[5.2,24.91],[5.7,16.69]],"id":52385909},{"atb":[[70,0.76],[38,2.83],[95,0.28],[48,1.67]],"id":52385920}],"con":true,"img":false}]}
{"op":"mcm","clk":"11450068130","pt":1717317644469,"mc":[{"id":"1.229554932","rc":[{"atb":[[9.8,0],[14.5,0]],"id":52385907},{"atb":[[32,0],[21,0]],"id":52385923},{"atb":[[4.6,0],[3.8,0]],"id":52385909},{"atb":[[4.3,0],[5.3,0]],"id":52385934},{"atb":[[9.2,0],[13,0]],"id":52385886},{"atb":[[2.42,0],[2.62,0]],"id":52385903},{"atb":[[18,0],[13,0]],"id":52385920},{"atb":[[18.5,0],[27,0]],"id":52385936},{"atb":[[3.25,0],[3.75,0]],"id":52385888},{"atb":[[3.95,0],[4.9,0]],"id":52385931},{"atb":[[2.28,0],[2.48,0]],"id":52385884},{"atb":[[17,0],[12,0]],"id":52385917}],"con":true,"img":false}]}
{"op":"mcm","clk":"11450071091","pt":1717317676202,"mc":[{"id":"1.229554932","rc":[{"atb":[[9.8,27.71],[14.5,7.74]],"id":52385907},{"atb":[[32,3.37],[21,12.19]],"id":52385923},{"atb":[[4.6,29.03],[3.8,87.1]],"id":52385909},{"atb":[[4.3,73.9],[5.3,24.31]],"id":52385934},{"atb":[[9.2,29.74],[13,8.71]],"id":52385886},{"atb":[[2.42,171.76],[2.62,64.52]],"id":52385903},{"atb":[[18.5,13.93],[27,4.01]],"id":52385936},{"atb":[[18,6.14],[13,20.32]],"id":52385920},{"atb":[[3.25,108.4],[3.75,38]],"id":52385888},{"atb":[[3.95,82.67],[4.9,26.8]],"id":52385931},{"atb":[[2.28,190.55],[2.48,70.62]],"id":52385884},{"atb":[[17,6.53],[12,22.17]],"id":52385917}],"con":true,"img":false}]}
{"op":"mcm","clk":"11450083402","pt":1717317813744,"mc":[{"id":"1.229554932","rc":[{"atb":[[170,0],[85,0],[120,0],[60,0]],"id":52385923},{"atb":[[6.4,0],[7.4,0],[5.2,0],[5.7,0]],"id":52385909},{"atb":[[18,0],[21,0],[26,0],[15.5,0]],"id":52385886},{"atb":[[4.9,0],[4.4,0],[5.9,0],[5.4,0]],"id":52385888},{"atb":[[65,0],[36,0],[90,0],[46,0]],"id":52385936}],"con":true,"img":false}]}
{"op":"mcm","clk":"11450083449","pt":1717317814418,"mc":[{"id":"1.229554932","rc":[{"atb":[[130,0.41],[65,1.64],[180,0.15],[90,0.88]],"id":52385923},{"atb":[[5.6,17.06],[7.2,4.22],[5.1,25.52],[6.2,10.06]],"id":52385909},{"atb":[[16,6.97],[18.5,4.48],[22,2.49],[27,1]],"id":52385886},{"atb":[[75,0.71],[40,2.68],[100,0.27],[50,1.6]],"id":52385936},{"atb":[[4.5,29.89],[5,19.62],[5.5,11.63],[6,5.23]],"id":52385888}],"con":true,"img":false}]}
{"op":"mcm","clk":"11450125834","pt":1717318297159,"mc":[{"id":"1.229554932","rc":[{"atb":[[2.82,0],[2.92,0],[2.72,0],[3.05,0]],"id":52385903}],"con":true,"img":false}]}
{"op":"mcm","clk":"11450125898","pt":1717318297882,"mc":[{"id":"1.229554932","rc":[{"atb":[[2.86,42.19],[3.15,12.17],[2.96,26.69],[2.76,59.45]],"id":52385903}],"con":true,"img":false}]}
{"op":"mcm","clk":"11450128184","pt":1717318324261,"mc":[{"id":"1.229554932","rc":[{"atb":[[32,0],[21,0]],"id":52385923},{"atb":[[9.8,0],[14.5,0]],"id":52385907},{"atb":[[4.6,0],[3.8,0]],"id":52385909},{"atb":[[9.2,0],[13,0]],"id":52385886},{"atb":[[4.3,0],[5.3,0]],"id":52385934},{"atb":[[2.42,0],[2.62,0]],"id":52385903},{"atb":[[18.5,0],[27,0]],"id":52385936},{"atb":[[3.25,0],[3.75,0]],"id":52385888},{"atb":[[18,0],[13,0]],"id":52385920},{"atb":[[3.95,0],[4.9,0]],"id":52385931},{"atb":[[2.28,0],[2.48,0]],"id":52385884},{"atb":[[17,0],[12,0]],"id":52385917}],"con":true,"img":false}]}
{"op":"mcm","clk":"11450129281","pt":1717318336161,"mc":[{"id":"1.229554932","rc":[{"atb":[[16.5,6.74],[11.5,23.22]],"id":52385907},{"atb":[[42,2.54],[26,9.75]],"id":52385923},{"atb":[[4.6,29.03],[3.8,87.1]],"id":52385909},{"atb":[[9.6,28.36],[14,8.04]],"id":52385886},{"atb":[[4.3,73.9],[5.3,24.31]],"id":52385934},{"atb":[[2.64,63.73],[2.44,169.37]],"id":52385903},{"atb":[[3.15,113.44],[3.65,39.44]],"id":52385888},{"atb":[[19.5,5.65],[14.5,18.06]],"id":52385920},{"atb":[[32,3.37],[21,12.19]],"id":52385936},{"atb":[[4.8,27.5],[3.9,84.1]],"id":52385931},{"atb":[[2.46,71.59],[2.26,193.57]],"id":52385884},{"atb":[[18.5,5.97],[13.5,19.51]],"id":52385917}],"con":true,"img":false}]}
{"op":"mcm","clk":"11450133842","pt":1717318390322,"mc":[{"id":"1.229554932","rc":[{"atb":[[16.5,0],[11.5,0]],"id":52385907},{"atb":[[42,0],[26,0]],"id":52385923},{"atb":[[4.6,0],[3.8,0]],"id":52385909},{"atb":[[9.6,0],[14,0]],"id":52385886},{"atb":[[4.3,0],[5.3,0]],"id":52385934},{"atb":[[2.64,0],[2.44,0]],"id":52385903},{"atb":[[3.15,0],[3.65,0]],"id":52385888},{"atb":[[32,0],[21,0]],"id":52385936},{"atb":[[19.5,0],[14.5,0]],"id":52385920},{"atb":[[4.8,0],[3.9,0]],"id":52385931},{"atb":[[2.46,0],[2.26,0]],"id":52385884},{"atb":[[18.5,0],[13.5,0]],"id":52385917}],"con":true,"img":false}]}
{"op":"mcm","clk":"11450134739","pt":1717318401349,"mc":[{"id":"1.229554932","rc":[{"atb":[[16,6.96],[11,24.39]],"id":52385907},{"atb":[[40,2.67],[25,10.16]],"id":52385923},{"atb":[[4.6,29.03],[3.8,87.1]],"id":52385909},{"atb":[[9.6,28.36],[14,8.04]],"id":52385886},{"atb":[[5.2,24.88],[4.2,76.22]],"id":52385934},{"atb":[[2.64,63.73],[2.44,169.37]],"id":52385903},{"atb":[[3.15,113.44],[3.65,39.44]],"id":52385888},{"atb":[[20,12.83],[30,3.6]],"id":52385936},{"atb":[[19.5,5.65],[14.5,18.06]],"id":52385920},{"atb":[[4.8,27.5],[3.9,84.1]],"id":52385931},{"atb":[[2.28,190.55],[2.48,70.62]],"id":52385884},{"atb":[[18.5,5.97],[13.5,19.51]],"id":52385917}],"con":true,"img":false}]}
{"op":"mcm","clk":"11450157581","pt":1717318650717,"mc":[{"id":"1.229554932","rc":[{"atb":[[5.6,0],[7.2,0],[5.1,0],[6.2,0]],"id":52385909}],"con":true,"img":false}]}
{"op":"mcm","clk":"11450157649","pt":1717318651388,"mc":[{"id":"1.229554932","rc":[{"atb":[[6.4,9.69],[7.4,4.09],[5.2,24.91],[5.7,16.69]],"id":52385909}],"con":true,"img":false}]}
{"op":"mcm","clk":"11450164697","pt":1717318724600,"mc":[{"id":"1.229554932","rc":[{"atb":[[16,0],[11,0]],"id":52385907},{"atb":[[40,0],[25,0]],"id":52385923},{"atb":[[4.6,0],[3.8,0]],"id":52385909},{"atb":[[9.6,0],[14,0]],"id":52385886},{"atb":[[5.2,0],[4.2,0]],"id":52385934},{"atb":[[2.64,0],[2.44,0]],"id":52385903},{"atb":[[20,0],[30,0]],"id":52385936},{"atb":[[19.5,0],[14.5,0]],"id":52385920},{"atb":[[3.15,0],[3.65,0]],"id":52385888},{"atb":[[4.8,0],[3.9,0]],"id":52385931},{"atb":[[2.28,0],[2.48,0]],"id":52385884},{"atb":[[18.5,0],[13.5,0]],"id":52385917}],"con":true,"img":false}]}
{"op":"mcm","clk":"11450166947","pt":1717318748658,"mc":[{"id":"1.229554932","rc":[{"atb":[[2.86,0],[3.15,0],[2.96,0],[2.76,0]],"id":52385903}],"con":true,"img":false}]}
{"op":"mcm","clk":"11450167020","pt":1717318749328,"mc":[{"id":"1.229554932","rc":[{"atb":[[2.86,42.19],[3.15,12.17],[2.96,26.69],[2.76,59.45]],"id":52385903}],"con":true,"img":false}]}
{"op":"mcm","clk":"11450167438","pt":1717318753411,"mc":[{"id":"1.229554932","rc":[{"atb":[[16,6.96],[11,24.39]],"id":52385907},{"atb":[[4.6,29.03],[3.8,87.1]],"id":52385909},{"atb":[[9.6,28.36],[14,8.04]],"id":52385886},{"atb":[[2.64,63.73],[2.44,169.37]],"id":52385903},{"atb":[[3.15,113.44],[3.65,39.44]],"id":52385888},{"atb":[[2.28,190.55],[2.48,70.62]],"id":52385884}],"con":true,"img":false}]}
{"op":"mcm","clk":"11450167448","pt":1717318753533,"mc":[{"id":"1.229554932","rc":[{"atb":[[40,2.67],[25,10.16]],"id":52385923},{"atb":[[5.2,24.88],[4.2,76.22]],"id":52385934},{"atb":[[20,12.83],[30,3.6]],"id":52385936},{"atb":[[19.5,5.65],[14.5,18.06]],"id":52385920},{"atb":[[4.8,27.5],[3.9,84.1]],"id":52385931},{"atb":[[18.5,5.97],[13.5,19.51]],"id":52385917}],"con":true,"img":false}]}
{"op":"mcm","clk":"11450180992","pt":1717318898744,"mc":[{"id":"1.229554932","rc":[{"atb":[[2.86,0],[3.15,0],[2.96,0],[2.76,0]],"id":52385903}],"con":true,"img":false}]}
{"op":"mcm","clk":"11450181056","pt":1717318899474,"mc":[{"id":"1.229554932","rc":[{"atb":[[2.82,43.12],[2.92,27.25],[2.72,60.84],[3.05,12.76]],"id":52385903}],"con":true,"img":false}]}
{"op":"mcm","clk":"11450229791","pt":1717319403902,"mc":[{"id":"1.229554932","rc":[{"atb":[[7.4,0]],"id":52385909}],"con":true,"img":false}]}
{"op":"mcm","clk":"11450229803","pt":1717319404016,"mc":[{"id":"1.229554932","rc":[{"atb":[[6.4,0],[5.2,0],[5.7,0]],"id":52385909}],"con":true,"img":false}]}
{"op":"mcm","clk":"11450229874","pt":1717319404625,"mc":[{"id":"1.229554932","rc":[{"atb":[[7.6,3.97]],"id":52385909}],"con":true,"img":false}]}
{"op":"mcm","clk":"11450229882","pt":1717319404727,"mc":[{"id":"1.229554932","rc":[{"atb":[[5.8,16.35],[5.3,24.33],[6.6,9.34]],"id":52385909}],"con":true,"img":false}]}
{"op":"mcm","clk":"11450246467","pt":1717319582903,"mc":[{"id":"1.229554932","rc":[{"atb":[[40,0],[25,0]],"id":52385923},{"atb":[[16,0],[11,0]],"id":52385907},{"atb":[[4.6,0],[3.8,0]],"id":52385909},{"atb":[[5.2,0],[4.2,0]],"id":52385934},{"atb":[[9.6,0],[14,0]],"id":52385886},{"atb":[[2.64,0],[2.44,0]],"id":52385903},{"atb":[[20,0],[30,0]],"id":52385936},{"atb":[[19.5,0],[14.5,0]],"id":52385920},{"atb":[[3.15,0],[3.65,0]],"id":52385888},{"atb":[[4.8,0],[3.9,0]],"id":52385931},{"atb":[[2.28,0],[2.48,0]],"id":52385884},{"atb":[[18.5,0],[13.5,0]],"id":52385917}],"con":true,"img":false}]}
{"op":"mcm","clk":"11450247605","pt":1717319595636,"mc":[{"id":"1.229554932","rc":[{"atb":[[40,2.67],[25,10.16]],"id":52385923},{"atb":[[16,6.96],[11,24.39]],"id":52385907},{"atb":[[4.6,29.03],[3.8,87.1]],"id":52385909},{"atb":[[5.2,24.88],[4.2,76.22]],"id":52385934},{"atb":[[9.6,28.36],[14,8.04]],"id":52385886},{"atb":[[2.64,63.73],[2.44,169.37]],"id":52385903},{"atb":[[20,12.83],[30,3.6]],"id":52385936},{"atb":[[19.5,5.65],[14.5,18.06]],"id":52385920},{"atb":[[3.15,113.44],[3.65,39.44]],"id":52385888},{"atb":[[4.8,27.5],[3.9,84.1]],"id":52385931},{"atb":[[2.28,190.55],[2.48,70.62]],"id":52385884},{"atb":[[18.5,5.97],[13.5,19.51]],"id":52385917}],"con":true,"img":false}]}
{"op":"mcm","clk":"11450275363","pt":1717319918892,"mc":[{"id":"1.229554932","rc":[{"atb":[[32,0],[18,0],[21,0],[26,0]],"id":52385907},{"atb":[[2.82,0],[2.92,0],[2.72,0],[3.05,0]],"id":52385884}],"con":true,"img":false}]}
{"op":"mcm","clk":"11450275400","pt":1717319919564,"mc":[{"id":"1.229554932","rc":[{"atb":[[36,0.75],[19,5.81],[23,3.57],[28,1.94]],"id":52385907},{"atb":[[2.8,43.6],[2.9,27.54],[3,13.08],[2.7,61.55]],"id":52385884}],"con":true,"img":false}]}
{"op":"mcm","clk":"11450308144","pt":1717320400600,"mc":[{"id":"1.229554932","rc":[{"atb":[[16,0],[11,0]],"id":52385907},{"atb":[[40,0],[25,0]],"id":52385923},{"atb":[[4.6,0],[3.8,0]],"id":52385909},{"atb":[[9.6,0],[14,0]],"id":52385886},{"atb":[[5.2,0],[4.2,0]],"id":52385934},{"atb":[[2.64,0],[2.44,0]],"id":52385903},{"atb":[[3.15,0],[3.65,0]],"id":52385888},{"atb":[[19.5,0],[14.5,0]],"id":52385920},{"atb":[[20,0],[30,0]],"id":52385936},{"atb":[[4.8,0],[3.9,0]],"id":52385931},{"atb":[[2.28,0],[2.48,0]],"id":52385884},{"atb":[[18.5,0],[13.5,0]],"id":52385917}],"con":true,"img":false}]}
{"op":"mcm","clk":"11450308808","pt":1717320410992,"mc":[{"id":"1.229554932","rc":[{"atb":[[40,2.67],[25,10.16]],"id":52385923},{"atb":[[5.2,24.88],[4.2,76.22]],"id":52385934},{"atb":[[20,12.83],[30,3.6]],"id":52385936},{"atb":[[19.5,5.65],[14.5,18.06]],"id":52385920},{"atb":[[4.8,27.5],[3.9,84.1]],"id":52385931},{"atb":[[18.5,5.97],[13.5,19.51]],"id":52385917}],"con":true,"img":false}]}
{"op":"mcm","clk":"11450308813","pt":1717320411094,"mc":[{"id":"1.229554932","rc":[{"atb":[[16,6.96],[11,24.39]],"id":52385907},{"atb":[[4.6,29.03],[3.8,87.1]],"id":52385909},{"atb":[[9.6,28.36],[14,8.04]],"id":52385886},{"atb":[[2.64,63.73],[2.44,169.37]],"id":52385903},{"atb":[[3.15,113.44],[3.65,39.44]],"id":52385888},{"atb":[[2.28,190.55],[2.48,70.62]],"id":52385884}],"con":true,"img":false}]}
{"op":"mcm","clk":"11450312275","pt":1717320464242,"mc":[{"id":"1.229554932","rc":[{"atb":[[36,0],[19,0],[23,0],[28,0]],"id":52385907},{"atb":[[130,0],[65,0],[180,0],[90,0]],"id":52385923},{"atb":[[5.8,0],[5.3,0],[7.6,0],[6.6,0]],"id":52385909},{"atb":[[9.6,0],[8.6,0],[11.5,0],[7.6,0]],"id":52385934},{"atb":[[70,0],[38,0],[95,0],[48,0]],"id":52385920},{"atb":[[75,0],[40,0],[100,0],[50,0]],"id":52385936},{"atb":[[2.8,0],[2.9,0],[3,0],[2.7,0]],"id":52385884}],"con":true,"img":false}]}
{"op":"mcm","clk":"11450312323","pt":1717320465052,"mc":[{"id":"1.229554932","rc":[{"atb":[[140,0.38],[70,1.52],[190,0.14],[95,0.84]],"id":52385923},{"atb":[[32,1.69],[42,0.64],[21,5.23],[26,3.14]],"id":52385907},{"atb":[[8,3.74],[5.5,23.25],[6,15.7],[7,8.72]],"id":52385909},{"atb":[[12,2.38],[9.8,5.94],[8.8,10.06],[7.8,15.39]],"id":52385934},{"atb":[[75,0.71],[40,2.68],[100,0.27],[50,1.6]],"id":52385920},{"atb":[[85,0.62],[44,2.43],[120,0.22],[60,1.33]],"id":52385936},{"atb":[[2.32,79.27],[2.42,55.26],[2.52,34.42],[2.62,16.15]],"id":52385884}],"con":true,"img":false}]}
{"op":"mcm","clk":"11450312418","pt":1717320465944,"mc":[{"id":"1.229554932","rc":[{"atb":[[8,0],[5.5,0],[6,0],[7,0]],"id":52385909}],"con":true,"img":false}]}
{"op":"mcm","clk":"11450312472","pt":1717320466619,"mc":[{"id":"1.229554932","rc":[{"atb":[[5.8,16.35],[5.3,24.33],[7.6,3.97],[6.6,9.34]],"id":52385909}],"con":true,"img":false}]}
{"op":"mcm","clk":"11450312830","pt":1717320473263,"mc":[{"id":"1.229554932","rc":[{"atb":[[5.8,0],[5.3,0],[7.6,0],[6.6,0]],"id":52385909}],"con":true,"img":false}]}
{"op":"mcm","clk":"11450312871","pt":1717320473943,"mc":[{"id":"1.229554932","rc":[{"atb":[[8,3.74],[5.5,23.25],[6,15.7],[7,8.72]],"id":52385909}],"con":true,"img":false}]}
{"op":"mcm","clk":"11450313190","pt":1717320480065,"mc":[{"id":"1.229554932","rc":[{"atb":[[8,0],[5.5,0],[6,0],[7,0]],"id":52385909}],"con":true,"img":false}]}
{"op":"mcm","clk":"11450313225","pt":1717320480749,"mc":[{"id":"1.229554932","rc":[{"atb":[[5.8,16.35],[5.3,24.33],[7.6,3.97],[6.6,9.34]],"id":52385909}],"con":true,"img":false}]}
{"op":"mcm","clk":"11450314972","pt":1717320510123,"mc":[{"id":"1.229554932","rc":[{"atb":[[12,0],[9.8,0],[8.8,0],[7.8,0]],"id":52385934}],"con":true,"img":false}]}
{"op":"mcm","clk":"11450315031","pt":1717320510813,"mc":[{"id":"1.229554932","rc":[{"atb":[[8,14.95],[9,9.81],[10,5.81],[12.5,2.28]],"id":52385934}],"con":true,"img":false}]}
{"op":"mcm","clk":"11450324812","pt":1717320549962,"mc":[{"id":"1.229554932","rc":[{"atb":[[40,0],[25,0]],"id":52385923},{"atb":[[16,0],[11,0]],"id":52385907},{"atb":[[4.6,0],[3.8,0]],"id":52385909},{"atb":[[5.2,0],[4.2,0]],"id":52385934},{"atb":[[9.6,0],[14,0]],"id":52385886},{"atb":[[2.64,0],[2.44,0]],"id":52385903},{"atb":[[20,0],[30,0]],"id":52385936},{"atb":[[19.5,0],[14.5,0]],"id":52385920},{"atb":[[3.15,0],[3.65,0]],"id":52385888},{"atb":[[4.8,0],[3.9,0]],"id":52385931},{"atb":[[2.28,0],[2.48,0]],"id":52385884},{"atb":[[18.5,0],[13.5,0]],"id":52385917}],"con":true,"img":false}]}
{"op":"mcm","clk":"11450326242","pt":1717320567768,"mc":[{"id":"1.229554932","rc":[{"atb":[[50,2.13],[30,8.41]],"id":52385923},{"atb":[[18,6.14],[13,20.32]],"id":52385907},{"atb":[[4,81.3],[5,26.13]],"id":52385909},{"atb":[[13.5,8.36],[9.4,29.03]],"id":52385886},{"atb":[[5.7,22.24],[4.7,65.92]],"id":52385934},{"atb":[[2.5,162.6],[2.7,61.48]],"id":52385903},{"atb":[[21,5.22],[15.5,16.82]],"id":52385920},{"atb":[[3,121.95],[3.5,41.81]],"id":52385888},{"atb":[[40,2.67],[25,10.16]],"id":52385936},{"atb":[[4.8,27.5],[3.9,84.1]],"id":52385931},{"atb":[[2.36,76.85],[2.16,210.26]],"id":52385884},{"atb":[[18.5,5.97],[13.5,19.51]],"id":52385917}],"con":true,"img":false}]}
{"op":"mcm","clk":"11450328976","pt":1717320604967,"mc":[{"id":"1.229554932","rc":[{"atb":[[50,0],[30,0]],"id":52385923},{"atb":[[18,0],[13,0]],"id":52385907},{"atb":[[4,0],[5,0]],"id":52385909},{"atb":[[13.5,0],[9.4,0]],"id":52385886},{"atb":[[5.7,0],[4.7,0]],"id":52385934},{"atb":[[2.5,0],[2.7,0]],"id":52385903},{"atb":[[40,0],[25,0]],"id":52385936},{"atb":[[21,0],[15.5,0]],"id":52385920},{"atb":[[3,0],[3.5,0]],"id":52385888},{"atb":[[4.8,0],[3.9,0]],"id":52385931},{"atb":[[2.36,0],[2.16,0]],"id":52385884},{"atb":[[18.5,0],[13.5,0]],"id":52385917}],"con":true,"img":false}]}
{"op":"mcm","clk":"11450331330","pt":1717320634287,"mc":[{"id":"1.229554932","rc":[{"atb":[[19.5,5.65],[14.5,18.06]],"id":52385907},{"atb":[[4,81.3],[5,26.13]],"id":52385909},{"atb":[[10,27.1],[15,7.46]],"id":52385886},{"atb":[[2.5,162.6],[2.7,61.48]],"id":52385903},{"atb":[[3.45,42.66],[2.98,123.18]],"id":52385888},{"atb":[[2.14,213.95],[2.34,78]],"id":52385884}],"con":true,"img":false}]}
{"op":"mcm","clk":"11450331344","pt":1717320634448,"mc":[{"id":"1.229554932","rc":[{"atb":[[100,1.05],[50,4.97]],"id":52385923},{"atb":[[5.7,22.24],[4.7,65.92]],"id":52385934},{"atb":[[18,14.34],[26,4.18]],"id":52385920},{"atb":[[65,1.63],[36,6.96]],"id":52385936},{"atb":[[4.8,27.5],[3.9,84.1]],"id":52385931},{"atb":[[20,5.5],[15,17.42]],"id":52385917}],"con":true,"img":false}]}
{"op":"mcm","clk":"11450333309","pt":1717320660743,"mc":[{"id":"1.229554932","rc":[{"atb":[[100,0],[50,0]],"id":52385923},{"atb":[[19.5,0],[14.5,0]],"id":52385907},{"atb":[[4,0],[5,0]],"id":52385909},{"atb":[[5.7,0],[4.7,0]],"id":52385934},{"atb":[[10,0],[15,0]],"id":52385886},{"atb":[[2.5,0],[2.7,0]],"id":52385903},{"atb":[[65,0],[36,0]],"id":52385936},{"atb":[[18,0],[26,0]],"id":52385920},{"atb":[[3.45,0],[2.98,0]],"id":52385888},{"atb":[[4.8,0],[3.9,0]],"id":52385931},{"atb":[[2.14,0],[2.34,0]],"id":52385884},{"atb":[[20,0],[15,0]],"id":52385917}],"con":true,"img":false}]}
{"op":"mcm","clk":"11450334365","pt":1717320674090,"mc":[{"id":"1.229554932","rc":[{"atb":[[19.5,5.65],[14.5,18.06]],"id":52385907},{"atb":[[100,1.05],[50,4.97]],"id":52385923},{"atb":[[4,81.3],[5,26.13]],"id":52385909},{"atb":[[10,27.1],[15,7.46]],"id":52385886},{"atb":[[5.7,22.24],[4.7,65.92]],"id":52385934},{"atb":[[2.5,162.6],[2.7,61.48]],"id":52385903},{"atb":[[18,14.34],[26,4.18]],"id":52385920},{"atb":[[65,1.63],[36,6.96]],"id":52385936},{"atb":[[3.45,42.66],[2.98,123.18]],"id":52385888},{"atb":[[4.8,27.5],[3.9,84.1]],"id":52385931},{"atb":[[2.14,213.95],[2.34,78]],"id":52385884},{"atb":[[20,5.5],[15,17.42]],"id":52385917}],"con":true,"img":false}]}
{"op":"mcm","clk":"11450338740","pt":1717320727902,"mc":[{"id":"1.229554932","rc":[{"atb":[[140,0],[70,0],[190,0],[95,0]],"id":52385923},{"atb":[[32,0],[42,0],[21,0],[26,0]],"id":52385907},{"atb":[[75,0],[40,0],[100,0],[50,0]],"id":52385920},{"atb":[[85,0],[44,0],[120,0],[60,0]],"id":52385936},{"atb":[[7.2,0],[9.2,0],[10.5,0],[8.2,0]],"id":52385931},{"atb":[[34,0],[85,0],[44,0],[60,0]],"id":52385917}],"con":true,"img":false}]}
{"op":"mcm","clk":"11450338792","pt":1717320728619,"mc":[{"id":"1.229554932","rc":[{"atb":[[140,0.75],[290,0.09],[190,0.41],[240,0.22]],"id":52385923},{"atb":[[40,1.34],[50,0.53],[25,4.36],[30,2.71]],"id":52385907},{"atb":[[150,0.18],[75,1.06],[100,0.53],[50,2.13]],"id":52385920},{"atb":[[150,0.18],[75,1.06],[100,0.53],[50,2.13]],"id":52385936},{"atb":[[11,2.62],[7.4,16.35],[8.4,10.61],[9.4,6.23]],"id":52385931},{"atb":[[80,0.66],[42,2.55],[110,0.24],[55,1.45]],"id":52385917}],"con":true,"img":false}]}
{"op":"mcm","clk":"11450365145","pt":1717321050365,"mc":[{"id":"1.229554932","rc":[{"atb":[[5.8,0],[5.3,0],[7.6,0],[6.6,0]],"id":52385909}],"con":true,"img":false}]}
{"op":"mcm","clk":"11450365190","pt":1717321051043,"mc":[{"id":"1.229554932","rc":[{"atb":[[8,3.74],[5.5,23.25],[6,15.7],[7,8.72]],"id":52385909}],"con":true,"img":false}]}
{"op":"mcm","clk":"11450367022","pt":1717321077383,"mc":[{"id":"1.229554932","rc":[{"atb":[[8,0],[9,0],[12.5,0]],"id":52385934}],"con":true,"img":false}]}
{"op":"mcm","clk":"11450367025","pt":1717321077486,"mc":[{"id":"1.229554932","rc":[{"atb":[[10,0]],"id":52385934}],"con":true,"img":false}]}
{"op":"mcm","clk":"11450367064","pt":1717321078059,"mc":[{"id":"1.229554932","rc":[{"atb":[[9.2,12.76],[10.5,8.26],[15.5,1.81]],"id":52385934}],"con":true,"img":false}]}
{"op":"mcm","clk":"11450367074","pt":1717321078264,"mc":[{"id":"1.229554932","rc":[{"atb":[[13,4.36]],"id":52385934}],"con":true,"img":false}]}
{"op":"mcm","clk":"11450377335","pt":1717321235231,"mc":[{"id":"1.229554932","rc":[{"atb":[[40,0],[50,0],[25,0],[30,0]],"id":52385907},{"atb":[[9.2,0],[10.5,0],[13,0],[15.5,0]],"id":52385934}],"con":true,"img":false}]}
{"op":"mcm","clk":"11450377375","pt":1717321235998,"mc":[{"id":"1.229554932","rc":[{"atb":[[38,1.41],[48,0.55],[24,4.55],[29,2.8]],"id":52385907},{"atb":[[9,13.08],[10,8.72],[12.5,4.55],[15,1.87]],"id":52385934}],"con":true,"img":false}]}
{"op":"mcm","clk":"11450379303","pt":1717321268136,"mc":[{"id":"1.229554932","rc":[{"atb":[[19.5,0],[14.5,0]],"id":52385907},{"atb":[[100,0],[50,0]],"id":52385923},{"atb":[[4,0],[5,0]],"id":52385909},{"atb":[[5.7,0],[4.7,0]],"id":52385934},{"atb":[[10,0],[15,0]],"id":52385886},{"atb":[[2.5,0],[2.7,0]],"id":52385903},{"atb":[[18,0],[26,0]],"id":52385920},{"atb":[[65,0],[36,0]],"id":52385936},{"atb":[[3.45,0],[2.98,0]],"id":52385888},{"atb":[[4.8,0],[3.9,0]],"id":52385931},{"atb":[[2.14,0],[2.34,0]],"id":52385884},{"atb":[[20,0],[15,0]],"id":52385917}],"con":true,"img":false}]}
{"op":"mcm","clk":"11450380297","pt":1717321282051,"mc":[{"id":"1.229554932","rc":[{"atb":[[19.5,5.65],[14.5,18.06]],"id":52385907},{"atb":[[100,1.05],[50,4.97]],"id":52385923},{"atb":[[4,81.3],[5,26.13]],"id":52385909},{"atb":[[10,27.1],[15,7.46]],"id":52385886},{"atb":[[5.7,22.24],[4.7,65.92]],"id":52385934},{"atb":[[2.5,162.6],[2.7,61.48]],"id":52385903},{"atb":[[18,14.34],[26,4.18]],"id":52385920},{"atb":[[65,1.63],[36,6.96]],"id":52385936},{"atb":[[3.45,42.66],[2.98,123.18]],"id":52385888},{"atb":[[4.8,27.5],[3.9,84.1]],"id":52385931},{"atb":[[2.14,213.95],[2.34,78]],"id":52385884},{"atb":[[20,5.5],[15,17.42]],"id":52385917}],"con":true,"img":false}]}
{"op":"mcm","clk":"11450390445","pt":1717321448096,"mc":[{"id":"1.229554932","rc":[{"atb":[[7,0]],"id":52385909},{"atb":[[2.32,0],[2.42,0],[2.52,0],[2.62,0]],"id":52385884}],"con":true,"img":false}]}
{"op":"mcm","clk":"11450390485","pt":1717321448786,"mc":[{"id":"1.229554932","rc":[{"atb":[[8.8,6.71]],"id":52385909},{"atb":[[2.4,56.05],[2.5,34.88],[2.3,80.49],[2.6,16.35]],"id":52385884}],"con":true,"img":false}]}
{"op":"mcm","clk":"11450390565","pt":1717321450089,"mc":[{"id":"1.229554932","rc":[{"atb":[[8.8,0]],"id":52385909}],"con":true,"img":false}]}
{"op":"mcm","clk":"11450390612","pt":1717321450763,"mc":[{"id":"1.229554932","rc":[{"atb":[[7,8.72]],"id":52385909}],"con":true,"img":false}]}
{"op":"mcm","clk":"11450409723","pt":1717321719309,"mc":[{"id":"1.229554932","rc":[{"atb":[[140,0],[290,0],[190,0],[240,0]],"id":52385923},{"atb":[[150,0],[75,0],[100,0],[50,0]],"id":52385936}],"con":true,"img":false}]}
{"op":"mcm","clk":"11450409780","pt":1717321720000,"mc":[{"id":"1.229554932","rc":[{"atb":[[300,0.09],[150,0.7],[200,0.39],[250,0.21]],"id":52385923},{"atb":[[160,0.16],[80,0.99],[110,0.48],[55,1.94]],"id":52385936}],"con":true,"img":false}]}
{"op":"mcm","clk":"11450410616","pt":1717321730226,"mc":[{"id":"1.229554932","rc":[{"atb":[[38,0],[48,0],[24,0],[29,0]],"id":52385907}],"con":true,"img":false}]}
{"op":"mcm","clk":"11450410684","pt":1717321730900,"mc":[{"id":"1.229554932","rc":[{"atb":[[40,1.34],[50,0.53],[25,4.36],[30,2.71]],"id":52385907}],"con":true,"img":false}]}
{"op":"mcm","clk":"11450412326","pt":1717321749515,"mc":[{"id":"1.229554932","rc":[{"atb":[[8,0],[5.5,0],[6,0],[7,0]],"id":52385909},{"atb":[[2.4,0],[2.5,0],[2.3,0],[2.6,0]],"id":52385884}],"con":true,"img":false}]}
{"op":"mcm","clk":"11450412378","pt":1717321750241,"mc":[{"id":"1.229554932","rc":[{"atb":[[9.6,3.04],[8.6,6.89],[7.6,11.89],[6.6,18.68]],"id":52385909},{"atb":[[2.56,16.77],[2.36,57.7],[2.46,35.83],[2.26,83.04]],"id":52385884}],"con":true,"img":false}]}
{"op":"mcm","clk":"11450445397","pt":1717322128282,"mc":[{"id":"1.229554932","rc":[{"atb":[[19.5,11.3],[14.5,36.13]],"id":52385907},{"atb":[[4,162.6],[5,52.26]],"id":52385909},{"atb":[[10,54.2],[15,14.93]],"id":52385886},{"atb":[[2.5,325.2],[2.7,122.97]],"id":52385903},{"atb":[[3.45,85.33],[2.98,246.36]],"id":52385888},{"atb":[[2.14,427.9],[2.34,156.01]],"id":52385884}],"con":true,"img":false}]}
{"op":"mcm","clk":"11450445402","pt":1717322128338,"mc":[{"id":"1.229554932","rc":[{"atb":[[100,2.11],[50,9.95]],"id":52385923},{"atb":[[5.7,44.48],[4.7,131.84]],"id":52385934},{"atb":[[65,3.26],[36,13.93]],"id":52385936},{"atb":[[18,28.69],[26,8.36]],"id":52385920},{"atb":[[4.8,55.01],[3.9,168.21]],"id":52385931},{"atb":[[20,11],[15,34.84]],"id":52385917}],"con":true,"img":false}]}
{"op":"mcm","clk":"11450470113","pt":1717322405215,"mc":[{"id":"1.229554932","rc":[{"atb":[[4.5,0],[5,0],[5.5,0],[6,0]],"id":52385888}],"con":true,"img":false}]}
{"op":"mcm","clk":"11450470199","pt":1717322406004,"mc":[{"id":"1.229554932","rc":[{"atb":[[3.85,36.72],[5.2,6.23],[4.2,24.52],[4.7,14.14]],"id":52385888}],"con":true,"img":false}]}
{"op":"mcm","clk":"11450480572","pt":1717322520487,"mc":[{"id":"1.229554932","rc":[{"atb":[[26,2]],"id":52385923},{"atb":[[9.2,7.07]],"id":52385907},{"atl":[[870,2]],"id":52385907},{"atb":[[3.15,30.59]],"id":52385909},{"atl":[[340,2]],"id":52385909},{"atb":[[4.4,21.81]],"id":52385934},{"atl":[[520,2]],"id":52385934},{"atb":[[6.6,11.47]],"id":52385886},{"atl":[[730,2]],"id":52385886},{"atb":[[1.92,103.97]],"id":52385903},{"atl":[[18,2]],"id":52385903},{"atb":[[2.78,56.18]],"id":52385888},{"atl":[[220,2]],"id":52385888},{"atb":[[25,2.94]],"id":52385936},{"atb":[[26,12.36]],"id":52385920},{"atb":[[2.78,26.96]],"id":52385931},{"atl":[[490,2]],"id":52385931},{"atb":[[1.78,128.21]],"id":52385884},{"atl":[[13,2]],"id":52385884},{"atb":[[26,4]],"id":52385917}],"con":true,"img":false}]}
{"op":"mcm","clk":"11450483411","pt":1717322557675,"mc":[{"id":"1.229554932","rc":[{"atb":[[9.2,0],[10.5,7.07]],"id":52385907},{"atb":[[32,2],[26,0]],"id":52385923},{"atb":[[3.15,0],[3.5,30.59]],"id":52385909},{"atb":[[7.6,11.47],[6.6,0]],"id":52385886},{"atb":[[5.1,24.39],[4.4,0]],"id":52385934},{"atb":[[1.92,0],[2.04,96.15]],"id":52385903},{"atb":[[25,0],[30,2.94]],"id":52385936},{"atb":[[1.88,113.64],[1.78,0]],"id":52385884}],"con":true,"img":false}]}
{"op":"mcm","clk":"11450490356","pt":1717322639593,"mc":[{"id":"1.229554932","rc":[{"atb":[[100,1.05],[50,4.97]],"id":52385923},{"atb":[[19.5,5.65],[14.5,18.06]],"id":52385907},{"atb":[[4,81.3],[5,26.13]],"id":52385909},{"atb":[[5.7,22.24],[4.7,65.92]],"id":52385934},{"atb":[[10,27.1],[15,7.46]],"id":52385886},{"atb":[[2.5,162.6],[2.7,61.48]],"id":52385903},{"atb":[[65,1.63],[36,6.96]],"id":52385936},{"atb":[[3.45,42.66],[2.98,123.18]],"id":52385888},{"atb":[[18,14.34],[26,8.18]],"id":52385920},{"atb":[[4.8,27.5],[3.9,84.1]],"id":52385931},{"atb":[[2.14,213.95],[2.34,78]],"id":52385884},{"atb":[[20,5.5],[15,17.42]],"id":52385917}],"con":true,"img":false}]}
{"op":"mcm","clk":"11450491173","pt":1717322647806,"mc":[{"id":"1.229554932","rc":[{"atb":[[10.5,0],[14,7.07]],"id":52385907},{"atb":[[3.5,0],[3.75,30.59]],"id":52385909},{"atl":[[330,2],[340,0]],"id":52385909},{"atl":[[520,0],[510,2]],"id":52385934},{"atb":[[8.6,11.47],[7.6,0]],"id":52385886},{"atb":[[2.04,0],[2.14,87.72]],"id":52385903},{"atl":[[17.5,2],[18,0]],"id":52385903},{"atl":[[190,2],[220,0]],"id":52385888},{"atb":[[34,3.03],[26,4.18]],"id":52385920},{"atl":[[470,2],[490,0]],"id":52385931},{"atl":[[11.5,2],[13,0]],"id":52385884},{"atb":[[34,3.03],[26,0]],"id":52385917}],"con":true,"img":false}]}
{"op":"mcm","clk":"11450491414","pt":1717322650804,"mc":[{"id":"1.229554932","rc":[{"atl":[[820,2],[870,0]],"id":52385907},{"atl":[[700,2],[730,0]],"id":52385886},{"atb":[[1.88,0],[1.94,106.38]],"id":52385884}],"con":true,"img":false}]}
{"op":"mcm","clk":"11450491515","pt":1717322652008,"mc":[{"id":"1.229554932","rc":[{"atb":[[19.5,11.3],[14.5,36.13]],"id":52385907},{"atb":[[100,2.11],[50,9.95]],"id":52385923},{"atb":[[4,162.6],[5,52.26]],"id":52385909},{"atb":[[10,54.2],[15,14.93]],"id":52385886},{"atb":[[5.7,44.48],[4.7,131.84]],"id":52385934},{"atb":[[2.5,325.2],[2.7,122.97]],"id":52385903},{"atb":[[18,28.69],[26,8.36]],"id":52385920},{"atb":[[3.45,85.33],[2.98,246.36]],"id":52385888},{"atb":[[65,3.26],[36,13.93]],"id":52385936},{"atb":[[4.8,55.01],[3.9,168.21]],"id":52385931},{"atb":[[2.14,427.9],[2.34,156.01]],"id":52385884},{"atb":[[20,11],[15,34.84]],"id":52385917}],"con":true,"img":false}]}
{"op":"mcm","clk":"11450494285","pt":1717322683654,"mc":[{"id":"1.229554932","rc":[{"atl":[[330,0],[320,2]],"id":52385909},{"atl":[[16.5,2],[17.5,0]],"id":52385903}],"con":true,"img":false}]}
{"op":"mcm","clk":"11450502419","pt":1717322770794,"mc":[{"id":"1.229554932","rc":[{"atb":[[10.5,8.72],[14,0]],"id":52385907},{"atb":[[1.88,113.64],[1.94,0]],"id":52385884}],"con":true,"img":false}]}
{"op":"mcm","clk":"11450504411","pt":1717322791832,"mc":[{"id":"1.229554932","rc":[{"atb":[[40,0],[50,0],[25,0],[30,0]],"id":52385907},{"atb":[[300,0],[150,0],[200,0],[250,0]],"id":52385923},{"atb":[[9.6,0],[8.6,0],[7.6,0],[6.6,0]],"id":52385909},{"atb":[[16,0],[18.5,0],[22,0],[27,0]],"id":52385886},{"atb":[[150,0],[75,0],[100,0],[50,0]],"id":52385920},{"atb":[[160,0],[80,0],[110,0],[55,0]],"id":52385936},{"atb":[[80,0],[42,0],[110,0],[55,0]],"id":52385917}],"con":true,"img":false}]}
{"op":"mcm","clk":"11450504426","pt":1717322792039,"mc":[{"id":"1.229554932","rc":[{"atb":[[34,0],[27,3.85]],"id":52385920},{"atb":[[34,0],[21,5]],"id":52385917}],"con":true,"img":false}]}
{"op":"mcm","clk":"11450504503","pt":1717322792829,"mc":[{"id":"1.229554932","rc":[{"atb":[[300,0.17],[350,0.07],[200,0.53],[250,0.31]],"id":52385923},{"atb":[[34,2.38],[44,1.22],[27,4.02],[60,0.44]],"id":52385907},{"atb":[[170,0.16],[85,0.94],[120,0.44],[60,1.77]],"id":52385936},{"atb":[[130,0.2],[65,1.22],[90,0.59],[46,2.32]],"id":52385917}],"con":true,"img":false}]}
{"op":"mcm","clk":"11450504509","pt":1717322792931,"mc":[{"id":"1.229554932","rc":[{"atb":[[6.8,18.04],[9.8,2.97],[8.8,6.71],[7.8,11.54]],"id":52385909},{"atb":[[17,6.54],[19.5,4.24],[24,2.28],[29,0.94]],"id":52385886},{"atb":[[130,0.41],[65,1.64],[180,0.15],[90,0.88]],"id":52385920}],"con":true,"img":false}]}
{"op":"mcm","clk":"11450507276","pt":1717322823672,"mc":[{"id":"1.229554932","rc":[{"atb":[[6.8,0],[9.8,0],[8.8,0],[7.8,0]],"id":52385909}],"con":true,"img":false}]}
{"op":"mcm","clk":"11450507352","pt":1717322824388,"mc":[{"id":"1.229554932","rc":[{"atb":[[9.6,3.04],[8.6,6.89],[7.6,11.89],[6.6,18.68]],"id":52385909}],"con":true,"img":false}]}
{"op":"mcm","clk":"11450507539","pt":1717322826477,"mc":[{"id":"1.229554932","rc":[{"atb":[[30,3.45]],"id":52385917}],"con":true,"img":false}]}
{"op":"mcm","clk":"11450507546","pt":1717322826608,"mc":[{"id":"1.229554932","rc":[{"atb":[[21,0]],"id":52385917}],"con":true,"img":false}]}
{"op":"mcm","clk":"11450526054","pt":1717323010212,"mc":[{"id":"1.229554932","rc":[{"atb":[[100,1.05],[50,4.97]],"id":52385923},{"atb":[[19.5,5.65],[14.5,18.06]],"id":52385907},{"atb":[[4,81.3],[5,26.13]],"id":52385909},{"atb":[[10,27.1],[15,7.46]],"id":52385886},{"atb":[[5.7,22.24],[4.7,65.92]],"id":52385934},{"atb":[[2.5,162.6],[2.7,61.48]],"id":52385903},{"atb":[[18,14.34],[26,4.18]],"id":52385920},{"atb":[[65,1.63],[36,6.96]],"id":52385936},{"atb":[[3.45,42.66],[2.98,123.18]],"id":52385888},{"atb":[[4.8,27.5],[3.9,84.1]],"id":52385931},{"atb":[[2.14,213.95],[2.34,78]],"id":52385884},{"atb":[[20,5.5],[15,17.42]],"id":52385917}],"con":true,"img":false}]}
{"op":"mcm","clk":"11450527434","pt":1717323023937,"mc":[{"id":"1.229554932","rc":[{"atb":[[100,2.11],[50,9.95]],"id":52385923},{"atb":[[19.5,11.3],[14.5,36.13]],"id":52385907},{"atb":[[4,162.6],[5,52.26]],"id":52385909},{"atb":[[10,54.2],[15,14.93]],"id":52385886},{"atb":[[5.7,44.48],[4.7,131.84]],"id":52385934},{"atb":[[2.5,325.2],[2.7,122.97]],"id":52385903},{"atb":[[18,28.69],[26,8.36]],"id":52385920},{"atb":[[3.45,85.33],[2.98,246.36]],"id":52385888},{"atb":[[65,3.26],[36,13.93]],"id":52385936},{"atb":[[4.8,55.01],[3.9,168.21]],"id":52385931},{"atb":[[2.14,427.9],[2.34,156.01]],"id":52385884},{"atb":[[20,11],[15,34.84]],"id":52385917}],"con":true,"img":false}]}
{"op":"mcm","clk":"11450542687","pt":1717323171499,"mc":[{"id":"1.229554932","rc":[{"atb":[[300,0],[350,0],[200,0],[250,0]],"id":52385923},{"atb":[[34,0],[44,0],[27,0],[60,0]],"id":52385907},{"atb":[[17,0],[19.5,0],[24,0],[29,0]],"id":52385886},{"atb":[[170,0],[85,0],[120,0],[60,0]],"id":52385936},{"atb":[[130,0],[65,0],[180,0],[90,0]],"id":52385920},{"atb":[[130,0],[65,0],[90,0],[46,0]],"id":52385917}],"con":true,"img":false}]}
{"op":"mcm","clk":"11450542698","pt":1717323171602,"mc":[{"id":"1.229554932","rc":[{"atb":[[21,5],[30,0]],"id":52385917}],"con":true,"img":false}]}
{"op":"mcm","clk":"11450542759","pt":1717323172225,"mc":[{"id":"1.229554932","rc":[{"atb":[[300,0.09],[150,0.7],[200,0.39],[250,0.21]],"id":52385923},{"atb":[[40,1.34],[50,0.53],[25,4.36],[30,2.71]],"id":52385907},{"atb":[[16,6.97],[18.5,4.48],[22,2.49],[27,1]],"id":52385886},{"atb":[[150,0.18],[75,1.06],[100,0.53],[50,2.13]],"id":52385920},{"atb":[[160,0.16],[80,0.99],[110,0.48],[55,1.94]],"id":52385936},{"atb":[[80,0.66],[42,2.55],[110,0.24],[55,1.45]],"id":52385917}],"con":true,"img":false}]}
{"op":"mcm","clk":"11450542770","pt":1717323172289,"mc":[{"id":"1.229554932","rc":[{"atb":[[21,0],[30,3.45]],"id":52385917}],"con":true,"img":false}]}
{"op":"mcm","clk":"11450561728","pt":1717323343674,"mc":[{"id":"1.229554932","rc":[{"atb":[[19.5,5.65],[14.5,18.06]],"id":52385907},{"atb":[[100,1.05],[50,4.97]],"id":52385923},{"atb":[[4,81.3],[5,26.13]],"id":52385909},{"atb":[[10,27.1],[15,7.46]],"id":52385886},{"atb":[[5.7,22.24],[4.7,65.92]],"id":52385934},{"atb":[[2.5,162.6],[2.7,61.48]],"id":52385903},{"atb":[[18,14.34],[26,4.18]],"id":52385920},{"atb":[[65,1.63],[36,6.96]],"id":52385936},{"atb":[[3.45,42.66],[2.98,123.18]],"id":52385888},{"atb":[[4.8,27.5],[3.9,84.1]],"id":52385931},{"atb":[[2.14,213.95],[2.34,78]],"id":52385884},{"atb":[[20,5.5],[15,17.42]],"id":52385917}],"con":true,"img":false}]}
{"op":"mcm","clk":"11450563452","pt":1717323359233,"mc":[{"id":"1.229554932","rc":[{"atb":[[100,2.11],[50,9.95]],"id":52385923},{"atb":[[19.5,11.3],[14.5,36.13]],"id":52385907},{"atb":[[4,162.6],[5,52.26]],"id":52385909},{"atb":[[5.7,44.48],[4.7,131.84]],"id":52385934},{"atb":[[10,54.2],[15,14.93]],"id":52385886},{"atb":[[2.5,325.2],[2.7,122.97]],"id":52385903},{"atb":[[3.45,85.33],[2.98,246.36]],"id":52385888},{"atb":[[65,3.26],[36,13.93]],"id":52385936},{"atb":[[18,28.69],[26,8.36]],"id":52385920},{"atb":[[4.8,55.01],[3.9,168.21]],"id":52385931},{"atb":[[2.14,427.9],[2.34,156.01]],"id":52385884},{"atb":[[20,11],[15,34.84]],"id":52385917}],"con":true,"img":false}]}
{"op":"mcm","clk":"11450592001","pt":1717323620105,"mc":[{"id":"1.229554932","rc":[{"atb":[[40,0],[50,0],[25,0],[30,0]],"id":52385907},{"atb":[[300,0],[150,0],[200,0],[250,0]],"id":52385923},{"atb":[[16,0],[18.5,0],[22,0],[27,0]],"id":52385886},{"atb":[[160,0],[80,0],[110,0],[55,0]],"id":52385936},{"atb":[[150,0],[75,0],[100,0],[50,0]],"id":52385920},{"atb":[[80,0],[42,0],[110,0],[55,0]],"id":52385917}],"con":true,"img":false}]}
{"op":"mcm","clk":"11450592021","pt":1717323620309,"mc":[{"id":"1.229554932","rc":[{"atb":[[21,5],[30,0]],"id":52385917}],"con":true,"img":false}]}
{"op":"mcm","clk":"11450592068","pt":1717323620826,"mc":[{"id":"1.229554932","rc":[{"atb":[[300,0.17],[350,0.07],[200,0.53],[250,0.31]],"id":52385923},{"atb":[[34,2.38],[44,1.22],[27,4.02],[60,0.44]],"id":52385907},{"atb":[[17,6.54],[19.5,4.24],[24,2.28],[29,0.94]],"id":52385886},{"atb":[[130,0.41],[65,1.64],[180,0.15],[90,0.88]],"id":52385920},{"atb":[[170,0.16],[85,0.94],[120,0.44],[60,1.77]],"id":52385936},{"atb":[[130,0.2],[65,1.22],[90,0.59],[46,2.32]],"id":52385917}],"con":true,"img":false}]}
{"op":"mcm","clk":"11450594735","pt":1717323646452,"mc":[{"id":"1.229554932","rc":[{"atb":[[21,0],[30,3.45]],"id":52385917}],"con":true,"img":false}]}
{"op":"mcm","clk":"11450598085","pt":1717323680285,"mc":[{"id":"1.229554932","rc":[{"atb":[[19.5,5.65],[14.5,18.06]],"id":52385907},{"atb":[[100,1.05],[50,4.97]],"id":52385923},{"atb":[[4,81.3],[5,26.13]],"id":52385909},{"atb":[[10,27.1],[15,7.46]],"id":52385886},{"atb":[[5.7,22.24],[4.7,65.92]],"id":52385934},{"atb":[[2.5,162.6],[2.7,61.48]],"id":52385903},{"atb":[[65,1.63],[36,6.96]],"id":52385936},{"atb":[[18,14.34],[26,4.18]],"id":52385920},{"atb":[[3.45,42.66],[2.98,123.18]],"id":52385888},{"atb":[[4.8,27.5],[3.9,84.1]],"id":52385931},{"atb":[[2.14,213.95],[2.34,78]],"id":52385884},{"atb":[[20,5.5],[15,17.42]],"id":52385917}],"con":true,"img":false}]}
{"op":"mcm","clk":"11450599088","pt":1717323691811,"mc":[{"id":"1.229554932","rc":[{"atb":[[19.5,11.3],[14.5,36.13]],"id":52385907},{"atb":[[100,2.11],[50,9.95]],"id":52385923},{"atb":[[4,162.6],[5,52.26]],"id":52385909},{"atb":[[10,54.2],[15,14.93]],"id":52385886},{"atb":[[5.7,44.48],[4.7,131.84]],"id":52385934},{"atb":[[2.5,325.2],[2.7,122.97]],"id":52385903},{"atb":[[3.45,85.33],[2.98,246.36]],"id":52385888},{"atb":[[18,28.69],[26,8.36]],"id":52385920},{"atb":[[65,3.26],[36,13.93]],"id":52385936},{"atb":[[4.8,55.01],[3.9,168.21]],"id":52385931},{"atb":[[2.14,427.9],[2.34,156.01]],"id":52385884},{"atb":[[20,11],[15,34.84]],"id":52385917}],"con":true,"img":false}]}
{"op":"mcm","clk":"11450614276","pt":1717323847517,"mc":[{"id":"1.229554932","rc":[{"atb":[[10.5,0],[14,7.69]],"id":52385907},{"atb":[[34,3.03],[27,0]],"id":52385920},{"atl":[[180,2],[190,0]],"id":52385888},{"atl":[[11,2],[11.5,0]],"id":52385884}],"con":true,"img":false}]}
{"op":"mcm","clk":"11450614565","pt":1717323850002,"mc":[{"id":"1.229554932","rc":[{"atl":[[820,0],[800,2]],"id":52385907},{"atl":[[680,2]],"id":52385886},{"atl":[[16,2]],"id":52385903},{"atb":[[1.88,0]],"id":52385884}],"con":true,"img":false}]}
{"op":"mcm","clk":"11450614575","pt":1717323850101,"mc":[{"id":"1.229554932","rc":[{"atl":[[700,0]],"id":52385886},{"atl":[[16.5,0]],"id":52385903},{"atb":[[1.94,106.38]],"id":52385884}],"con":true,"img":false}]}
{"op":"mcm","clk":"11450626477","pt":1717323970067,"mc":[{"id":"1.229554932","rc":[{"atb":[[10.5,8.06],[14,0]],"id":52385907},{"atl":[[680,0],[700,2]],"id":52385886},{"atl":[[16,0],[16.5,4]],"id":52385903},{"atb":[[1.88,113.64],[1.94,0]],"id":52385884}],"con":true,"img":false}]}
{"op":"mcm","clk":"11450632132","pt":1717324032347,"mc":[{"id":"1.229554932","rc":[{"atb":[[19.5,5.65],[14.5,18.06]],"id":52385907},{"atb":[[100,1.05],[50,4.97]],"id":52385923},{"atb":[[4,81.3],[5,26.13]],"id":52385909},{"atb":[[10,27.1],[15,7.46]],"id":52385886},{"atb":[[5.7,22.24],[4.7,65.92]],"id":52385934},{"atb":[[2.5,162.6],[2.7,61.48]],"id":52385903},{"atb":[[18,14.34],[26,4.18]],"id":52385920},{"atb":[[3.45,42.66],[2.98,123.18]],"id":52385888},{"atb":[[65,1.63],[36,6.96]],"id":52385936},{"atb":[[4.8,27.5],[3.9,84.1]],"id":52385931},{"atb":[[2.14,213.95],[2.34,78]],"id":52385884},{"atb":[[20,5.5],[15,17.42]],"id":52385917}],"con":true,"img":false}]}
{"op":"mcm","clk":"11450633156","pt":1717324044655,"mc":[{"id":"1.229554932","rc":[{"atb":[[100,2.11],[50,9.95]],"id":52385923},{"atb":[[19.5,11.3],[14.5,36.13]],"id":52385907},{"atb":[[4,162.6],[5,52.26]],"id":52385909},{"atb":[[5.7,44.48],[4.7,131.84]],"id":52385934},{"atb":[[10,54.2],[15,14.93]],"id":52385886},{"atb":[[2.5,325.2],[2.7,122.97]],"id":52385903},{"atb":[[3.45,85.33],[2.98,246.36]],"id":52385888},{"atb":[[65,3.26],[36,13.93]],"id":52385936},{"atb":[[18,28.69],[26,8.36]],"id":52385920},{"atb":[[4.8,55.01],[3.9,168.21]],"id":52385931},{"atb":[[2.14,427.9],[2.34,156.01]],"id":52385884},{"atb":[[20,11],[15,34.84]],"id":52385917}],"con":true,"img":false}]}
{"op":"mcm","clk":"11450649496","pt":1717324218974,"mc":[{"id":"1.229554932","rc":[{"atb":[[3.85,0],[5.2,0],[4.2,0],[4.7,0]],"id":52385888}],"con":true,"img":false}]}
{"op":"mcm","clk":"11450649571","pt":1717324219669,"mc":[{"id":"1.229554932","rc":[{"atb":[[4,26.16],[4.5,14.95],[5,6.54],[3.75,38.05]],"id":52385888}],"con":true,"img":false}]}
{"op":"mcm","clk":"11450658196","pt":1717324302240,"mc":[{"id":"1.229554932","rc":[{"atb":[[34,0],[44,0],[27,0],[60,0]],"id":52385907},{"atb":[[300,0],[350,0],[200,0],[250,0]],"id":52385923},{"atb":[[17,0],[19.5,0],[24,0],[29,0]],"id":52385886},{"atb":[[4,0],[4.5,0],[5,0],[3.75,0]],"id":52385888},{"atb":[[130,0],[65,0],[180,0],[90,0]],"id":52385920},{"atb":[[170,0],[85,0],[120,0],[60,0]],"id":52385936},{"atb":[[130,0],[65,0],[90,0],[46,0]],"id":52385917}],"con":true,"img":false}]}
{"op":"mcm","clk":"11450658207","pt":1717324302343,"mc":[{"id":"1.229554932","rc":[{"atb":[[34,0],[27,3.85]],"id":52385920},{"atb":[[21,5]],"id":52385917}],"con":true,"img":false}]}
{"op":"mcm","clk":"11450658221","pt":1717324302448,"mc":[{"id":"1.229554932","rc":[{"atb":[[30,0]],"id":52385917}],"con":true,"img":false}]}
{"op":"mcm","clk":"11450658458","pt":1717324304444,"mc":[{"id":"1.229554932","rc":[{"atb":[[300,0.09],[150,0.7],[200,0.39],[250,0.21]],"id":52385923},{"atb":[[40,1.34],[50,0.53],[25,4.36],[30,2.71]],"id":52385907},{"atb":[[16,6.97],[18.5,4.48],[22,2.49],[27,1]],"id":52385886},{"atb":[[150,0.18],[75,1.06],[100,0.53],[50,2.13]],"id":52385920},{"atb":[[160,0.16],[80,0.99],[110,0.48],[55,1.94]],"id":52385936},{"atb":[[3.85,36.72],[5.2,6.23],[4.2,24.52],[4.7,14.14]],"id":52385888},{"atb":[[80,0.66],[42,2.55],[110,0.24],[55,1.45]],"id":52385917}],"con":true,"img":false}]}
{"op":"mcm","clk":"11450658470","pt":1717324304551,"mc":[{"id":"1.229554932","rc":[{"atb":[[30,3.45]],"id":52385917}],"con":true,"img":false}]}
{"op":"mcm","clk":"11450658488","pt":1717324304663,"mc":[{"id":"1.229554932","rc":[{"atb":[[21,0]],"id":52385917}],"con":true,"img":false}]}
{"op":"mcm","clk":"11450658556","pt":1717324305134,"mc":[{"id":"1.229554932","rc":[{"atb":[[300,0],[150,0],[200,0],[250,0]],"id":52385923},{"atb":[[40,0],[50,0],[25,0],[30,0]],"id":52385907},{"atb":[[16,0],[18.5,0],[22,0],[27,0]],"id":52385886},{"atb":[[160,0],[80,0],[110,0],[55,0]],"id":52385936},{"atb":[[150,0],[75,0],[100,0],[50,0]],"id":52385920},{"atb":[[80,0],[42,0],[110,0],[55,0]],"id":52385917}],"con":true,"img":false}]}
{"op":"mcm","clk":"11450658564","pt":1717324305238,"mc":[{"id":"1.229554932","rc":[{"atb":[[21,5],[30,0]],"id":52385917}],"con":true,"img":false}]}
{"op":"mcm","clk":"11450658629","pt":1717324305825,"mc":[{"id":"1.229554932","rc":[{"atb":[[34,2.38],[44,1.22],[27,4.02],[60,0.44]],"id":52385907},{"atb":[[300,0.17],[350,0.07],[200,0.53],[250,0.31]],"id":52385923},{"atb":[[17,6.54],[19.5,4.24],[24,2.28],[29,0.94]],"id":52385886},{"atb":[[130,0.41],[65,1.64],[180,0.15],[90,0.88]],"id":52385920},{"atb":[[170,0.16],[85,0.94],[120,0.44],[60,1.77]],"id":52385936},{"atb":[[130,0.2],[65,1.22],[90,0.59],[46,2.32]],"id":52385917}],"con":true,"img":false}]}
{"op":"mcm","clk":"11450658646","pt":1717324306020,"mc":[{"id":"1.229554932","rc":[{"atb":[[21,0],[30,3.45]],"id":52385917}],"con":true,"img":false}]}
{"op":"mcm","clk":"11450660884","pt":1717324326889,"mc":[{"id":"1.229554932","rc":[{"atb":[[140,3.84],[160,3.32]],"id":52385923},{"atb":[[28,3.28],[30,4.03]],"id":52385907},{"atl":[[130,3.05],[110,3.5]],"id":52385907},{"atb":[[7.2,2.66],[7.6,16.24]],"id":52385909},{"atl":[[16,4.27],[15,3.79]],"id":52385909},{"atb":[[17.5,4.59],[18.5,3.25]],"id":52385886},{"atl":[[70,2.64],[80,3.17]],"id":52385886},{"atb":[[10.5,3.25],[9.8,4.37]],"id":52385934},{"atl":[[32,2.9],[36,4.16]],"id":52385934},{"atb":[[2.92,35.42],[2.96,8]],"id":52385903},{"atl":[[6.4,4.64],[6,4.1]],"id":52385903},{"atb":[[75,4.43],[85,4.65]],"id":52385936},{"atl":[[440,4.64],[460,3.31]],"id":52385936},{"atb":[[95,3.88],[110,3.33]],"id":52385920},{"atl":[[660,4.68],[680,3.7]],"id":52385920},{"atl":[[10.5,3.28],[9.8,2.98]],"id":52385888},{"atl":[[26,3.56],[28,3.8]],"id":52385931},{"atb":[[2.36,69.24],[2.4,11.21]],"id":52385884},{"atl":[[4.3,4.75],[4.1,5.06]],"id":52385884},{"atb":[[65,4.46],[75,2.85]],"id":52385917},{"atl":[[530,3.55],[550,3.41]],"id":52385917}],"con":true,"img":false}]}
{"op":"mcm","clk":"11450660895","pt":1717324327049,"mc":[{"id":"1.229554932","rc":[{"atl":[[800,0],[450,2]],"id":52385907},{"atl":[[36,2.86],[320,0]],"id":52385909},{"atl":[[310,2],[700,0]],"id":52385886},{"atl":[[120,2],[510,0]],"id":52385934},{"atl":[[16.5,0],[5.9,4.11]],"id":52385903},{"atl":[[180,0],[22,4.76]],"id":52385888},{"atl":[[95,2],[470,0]],"id":52385931},{"atl":[[4.5,9.82],[11,0]],"id":52385884}],"con":true,"img":false}]}
{"op":"mcm","clk":"11450666060","pt":1717324370760,"mc":[{"id":"1.229554932","rc":[{"atb":[[19.5,5.65],[14.5,18.06]],"id":52385907},{"atb":[[100,1.05],[50,4.97]],"id":52385923},{"atb":[[4,81.3],[5,26.13]],"id":52385909},{"atb":[[5.7,22.24],[4.7,65.92]],"id":52385934},{"atb":[[10,27.1],[15,7.46]],"id":52385886},{"atb":[[2.5,162.6],[2.7,61.48]],"id":52385903},{"atb":[[3.45,42.66],[2.98,123.18]],"id":52385888},{"atb":[[18,14.34],[26,4.18]],"id":52385920},{"atb":[[65,1.63],[36,6.96]],"id":52385936},{"atb":[[4.8,27.5],[3.9,84.1]],"id":52385931},{"atb":[[2.14,213.95],[2.34,78]],"id":52385884},{"atb":[[20,5.5],[15,17.42]],"id":52385917}],"con":true,"img":false}]}
{"op":"mcm","clk":"11450667842","pt":1717324387305,"mc":[{"id":"1.229554932","rc":[{"atb":[[19.5,11.3],[14.5,36.13]],"id":52385907},{"atb":[[100,2.11],[50,9.95]],"id":52385923},{"atb":[[4,162.6],[5,52.26]],"id":52385909},{"atb":[[10,54.2],[15,14.93]],"id":52385886},{"atb":[[5.7,44.48],[4.7,131.84]],"id":52385934},{"atb":[[2.5,325.2],[2.7,122.97]],"id":52385903},{"atb":[[3.45,85.33],[2.98,246.36]],"id":52385888},{"atb":[[18,28.69],[26,8.36]],"id":52385920},{"atb":[[65,3.26],[36,13.93]],"id":52385936},{"atb":[[4.8,55.01],[3.9,168.21]],"id":52385931},{"atb":[[2.14,427.9],[2.34,156.01]],"id":52385884},{"atb":[[20,11],[15,34.84]],"id":52385917}],"con":true,"img":false}]}
{"op":"mcm","clk":"11450668309","pt":1717324391176,"mc":[{"id":"1.229554932","rc":[{"atb":[[80,3.21],[85,0.94]],"id":52385936}],"con":true,"img":false}]}
{"op":"mcm","clk":"11450668605","pt":1717324393606,"mc":[{"id":"1.229554932","rc":[{"atb":[[80,0]],"id":52385936}],"con":true,"img":false}]}
{"op":"mcm","clk":"11450669725","pt":1717324403170,"mc":[{"id":"1.229554932","rc":[{"atb":[[85,5.64]],"id":52385936}],"con":true,"img":false}]}
{"op":"mcm","clk":"11450682912","pt":1717324510079,"mc":[{"id":"1.229554932","rc":[{"atb":[[80,3.67],[85,0.94]],"id":52385936}],"con":true,"img":false}]}
{"op":"mcm","clk":"11450690037","pt":1717324575856,"mc":[{"id":"1.229554932","rc":[{"atb":[[3.85,0],[5.2,0],[4.2,0],[4.7,0]],"id":52385888}],"con":true,"img":false}]}
{"op":"mcm","clk":"11450690128","pt":1717324576532,"mc":[{"id":"1.229554932","rc":[{"atb":[[4,26.16],[4.5,14.95],[5,6.54],[3.75,38.05]],"id":52385888}],"con":true,"img":false}]}
{"op":"mcm","clk":"11450690627","pt":1717324581249,"mc":[{"id":"1.229554932","rc":[{"atb":[[80,0],[85,3.72]],"id":52385936}],"con":true,"img":false}]}
{"op":"mcm","clk":"11450692911","pt":1717324599761,"mc":[{"id":"1.229554932","rc":[{"atb":[[85,0.94]],"id":52385936}],"con":true,"img":false}]}
{"op":"mcm","clk":"11450692922","pt":1717324599866,"mc":[{"id":"1.229554932","rc":[{"atb":[[80,4.09]],"id":52385936}],"con":true,"img":false}]}
{"op":"mcm","clk":"11450693121","pt":1717324601593,"mc":[{"id":"1.229554932","rc":[{"atb":[[80,0],[85,5.51]],"id":52385936}],"con":true,"img":false}]}
{"op":"mcm","clk":"11450695231","pt":1717324619407,"mc":[{"id":"1.229554932","rc":[{"atb":[[80,2.71],[85,0.94]],"id":52385936}],"con":true,"img":false}]}
{"op":"mcm","clk":"11450695485","pt":1717324621497,"mc":[{"id":"1.229554932","rc":[{"atl":[[4.5,0],[4.6,10.12]],"id":52385884}],"con":true,"img":false}]}
{"op":"mcm","clk":"11450696343","pt":1717324628929,"mc":[{"id":"1.229554932","rc":[{"atb":[[80,0],[85,3.73]],"id":52385936}],"con":true,"img":false}]}
{"op":"mcm","clk":"11450696667","pt":1717324631757,"mc":[{"id":"1.229554932","rc":[{"atb":[[80,4.16],[85,0.94]],"id":52385936}],"con":true,"img":false}]}
{"op":"mcm","clk":"11450697359","pt":1717324637607,"mc":[{"id":"1.229554932","rc":[{"atb":[[80,0],[85,3.71]],"id":52385936}],"con":true,"img":false}]}
{"op":"mcm","clk":"11450698835","pt":1717324649834,"mc":[{"id":"1.229554932","rc":[{"atb":[[80,4.25],[85,0.94]],"id":52385936}],"con":true,"img":false}]}
{"op":"mcm","clk":"11450699568","pt":1717324655844,"mc":[{"id":"1.229554932","rc":[{"atb":[[80,0],[85,5.28]],"id":52385936}],"con":true,"img":false}]}
{"op":"mcm","clk":"11450700145","pt":1717324661180,"mc":[{"id":"1.229554932","rc":[{"atb":[[80,4.04],[85,0.94]],"id":52385936}],"con":true,"img":false}]}
{"op":"mcm","clk":"11450700589","pt":1717324664892,"mc":[{"id":"1.229554932","rc":[{"atb":[[80,0],[85,4.63]],"id":52385936}],"con":true,"img":false}]}
{"op":"mcm","clk":"11450702572","pt":1717324682407,"mc":[{"id":"1.229554932","rc":[{"atb":[[80,4.67],[85,0.94]],"id":52385936}],"con":true,"img":false}]}
{"op":"mcm","clk":"11450703053","pt":1717324686135,"mc":[{"id":"1.229554932","rc":[{"atb":[[80,0],[85,4.05]],"id":52385936}],"con":true,"img":false}]}
{"op":"mcm","clk":"11450704036","pt":1717324695107,"mc":[{"id":"1.229554932","rc":[{"atb":[[80,4.41],[85,0.94]],"id":52385936}],"con":true,"img":false}]}
{"op":"mcm","clk":"11450704318","pt":1717324697933,"mc":[{"id":"1.229554932","rc":[{"atb":[[80,0],[85,5.1]],"id":52385936}],"con":true,"img":false}]}
{"op":"mcm","clk":"11450704626","pt":1717324701221,"mc":[{"id":"1.229554932","rc":[{"atb":[[80,3.59],[85,0.94]],"id":52385936}],"con":true,"img":false}]}
{"op":"mcm","clk":"11450705289","pt":1717324707339,"mc":[{"id":"1.229554932","rc":[{"atb":[[80,0],[85,4.96]],"id":52385936}],"con":true,"img":false}]}
{"op":"mcm","clk":"11450705818","pt":1717324712427,"mc":[{"id":"1.229554932","rc":[{"atb":[[100,1.05],[50,4.97]],"id":52385923},{"atb":[[19.5,5.65],[14.5,18.06]],"id":52385907},{"atb":[[4,81.3],[5,26.13]],"id":52385909},{"atb":[[5.7,22.24],[4.7,65.92]],"id":52385934},{"atb":[[10,27.1],[15,7.46]],"id":52385886},{"atb":[[2.5,162.6],[2.7,61.48]],"id":52385903},{"atb":[[65,1.63],[36,6.96]],"id":52385936},{"atb":[[3.45,42.66],[2.98,123.18]],"id":52385888},{"atb":[[18,14.34],[26,4.18]],"id":52385920},{"atb":[[4.8,27.5],[3.9,84.1]],"id":52385931},{"atb":[[2.14,213.95],[2.34,78]],"id":52385884},{"atb":[[20,5.5],[15,17.42]],"id":52385917}],"con":true,"img":false}]}
{"op":"mcm","clk":"11450706663","pt":1717324721573,"mc":[{"id":"1.229554932","rc":[{"atb":[[80,4.29],[85,0.94]],"id":52385936}],"con":true,"img":false}]}
{"op":"mcm","clk":"11450707029","pt":1717324725277,"mc":[{"id":"1.229554932","rc":[{"atb":[[80,0],[85,3.79]],"id":52385936}],"con":true,"img":false}]}
{"op":"mcm","clk":"11450707053","pt":1717324725487,"mc":[{"id":"1.229554932","rc":[{"atb":[[100,2.11],[50,9.95]],"id":52385923},{"atb":[[19.5,11.3],[14.5,36.13]],"id":52385907},{"atb":[[4,162.6],[5,52.26]],"id":52385909},{"atb":[[5.7,44.48],[4.7,131.84]],"id":52385934},{"atb":[[10,54.2],[15,14.93]],"id":52385886},{"atb":[[2.5,325.2],[2.7,122.97]],"id":52385903},{"atb":[[65,3.26],[36,13.93]],"id":52385936},{"atb":[[3.45,85.33],[2.98,246.36]],"id":52385888},{"atb":[[18,28.69],[26,8.36]],"id":52385920},{"atb":[[4.8,55.01],[3.9,168.21]],"id":52385931},{"atb":[[2.14,427.9],[2.34,156.01]],"id":52385884},{"atb":[[20,11],[15,34.84]],"id":52385917}],"con":true,"img":false}]}
{"op":"mcm","clk":"11450708740","pt":1717324741795,"mc":[{"id":"1.229554932","rc":[{"atb":[[80,3.96],[85,0.94]],"id":52385936}],"con":true,"img":false}]}
{"op":"mcm","clk":"11450708893","pt":1717324743192,"mc":[{"id":"1.229554932","rc":[{"atb":[[80,0],[85,5.15]],"id":52385936}],"con":true,"img":false}]}
{"op":"mcm","clk":"11450710497","pt":1717324758249,"mc":[{"id":"1.229554932","rc":[{"atb":[[80,3.73]],"id":52385936}],"con":true,"img":false}]}
{"op":"mcm","clk":"11450710520","pt":1717324758359,"mc":[{"id":"1.229554932","rc":[{"atb":[[85,0.94]],"id":52385936}],"con":true,"img":false}]}
{"op":"mcm","clk":"11450710838","pt":1717324761372,"mc":[{"id":"1.229554932","rc":[{"atb":[[80,0],[85,3.73]],"id":52385936}],"con":true,"img":false}]}
{"op":"mcm","clk":"11450711423","pt":1717324766871,"mc":[{"id":"1.229554932","rc":[{"atb":[[80,3.35]],"id":52385936}],"con":true,"img":false}]}
{"op":"mcm","clk":"11450711434","pt":1717324766970,"mc":[{"id":"1.229554932","rc":[{"atb":[[85,0.94]],"id":52385936}],"con":true,"img":false}]}
{"op":"mcm","clk":"11450717976","pt":1717324831353,"mc":[{"id":"1.229554932","rc":[{"atb":[[80,0],[85,4.38]],"id":52385936}],"con":true,"img":false}]}
{"op":"mcm","clk":"11450724774","pt":1717324899491,"mc":[{"id":"1.229554932","rc":[{"atb":[[18.5,0]],"id":52385886},{"atb":[[70,3.92],[85,0.94]],"id":52385936}],"con":true,"img":false}]}
{"op":"mcm","clk":"11450724854","pt":1717324900427,"mc":[{"id":"1.229554932","rc":[{"atb":[[300,0],[160,0],[350,0],[200,0],[250,0]],"id":52385923},{"atb":[[34,0],[44,0],[27,0],[60,0],[30,0]],"id":52385907},{"atb":[[7.4,2.83],[7.6,11.89]],"id":52385909},{"atb":[[17.5,0],[17,3.2],[19.5,0],[24,0],[29,0]],"id":52385886},{"atb":[[75,0],[170,0],[85,0],[120,0],[60,0]],"id":52385936},{"atb":[[130,0],[65,0],[180,0],[90,0],[110,0]],"id":52385920},{"atb":[[4,0],[4.5,0],[5,0],[3.75,0]],"id":52385888},{"atb":[[2.4,0],[2.38,11.37]],"id":52385884},{"atb":[[130,0],[65,3.23],[75,0],[90,0],[46,0],[60,3.32]],"id":52385917}],"con":true,"img":false}]}
{"op":"mcm","clk":"11450724917","pt":1717324901112,"mc":[{"id":"1.229554932","rc":[{"atb":[[34,2.38],[44,1.22],[27,4.02],[60,0.44]],"id":52385907},{"atl":[[550,2],[450,0]],"id":52385907},{"atb":[[300,0.17],[350,0.07],[200,0.53],[250,0.31]],"id":52385923},{"atb":[[17,9.75],[19.5,4.24],[24,2.28],[29,0.94]],"id":52385886},{"atl":[[310,0],[380,2]],"id":52385886},{"atl":[[6.2,8.22],[5.9,0]],"id":52385903},{"atb":[[4,26.16],[4.5,14.95],[5,6.54],[3.75,38.05]],"id":52385888},{"atb":[[170,0.16],[85,0.94],[120,0.44],[60,1.77]],"id":52385936},{"atb":[[130,0.41],[65,1.64],[180,0.15],[90,0.88]],"id":52385920},{"atl":[[4.6,0],[5,10.12]],"id":52385884},{"atb":[[65,4.46],[130,0.2],[90,0.59],[46,2.32]],"id":52385917}],"con":true,"img":false}]}
{"op":"mcm","clk":"11450724948","pt":1717324901425,"mc":[{"id":"1.229554932","rc":[{"atb":[[65,1.22]],"id":52385917}],"con":true,"img":false}]}
{"op":"mcm","clk":"11450725117","pt":1717324903192,"mc":[{"id":"1.229554932","rc":[{"atb":[[160,3.8]],"id":52385923},{"atb":[[7.4,0],[7.6,15.02]],"id":52385909},{"atb":[[17.5,4.2]],"id":52385886},{"atb":[[110,4.62]],"id":52385920},{"atb":[[2.4,11.21],[2.38,0]],"id":52385884}],"con":true,"img":false}]}
{"op":"mcm","clk":"11450725127","pt":1717324903298,"mc":[{"id":"1.229554932","rc":[{"atb":[[30,4.5]],"id":52385907},{"atb":[[75,4.31]],"id":52385917}],"con":true,"img":false}]}
{"op":"mcm","clk":"11450725543","pt":1717324907905,"mc":[{"id":"1.229554932","rc":[{"atb":[[30,0]],"id":52385907},{"atb":[[160,0]],"id":52385923},{"atb":[[7.4,3.73],[7.6,11.89]],"id":52385909},{"atb":[[110,0]],"id":52385920},{"atb":[[2.4,0],[2.38,11.37]],"id":52385884},{"atb":[[75,0]],"id":52385917}],"con":true,"img":false}]}
{"op":"mcm","clk":"11450725549","pt":1717324908003,"mc":[{"id":"1.229554932","rc":[{"atb":[[17.5,0]],"id":52385886}],"con":true,"img":false}]}
{"op":"mcm","clk":"11450725700","pt":1717324909505,"mc":[{"id":"1.229554932","rc":[{"atb":[[60,4.61]],"id":52385936}],"con":true,"img":false}]}
{"op":"mcm","clk":"11450726041","pt":1717324913251,"mc":[{"id":"1.229554932","rc":[{"atb":[[26,3.08]],"id":52385907},{"atb":[[120,3.29]],"id":52385923},{"atb":[[16,4.54]],"id":52385886}],"con":true,"img":false}]}
{"op":"mcm","clk":"11450726049","pt":1717324913312,"mc":[{"id":"1.229554932","rc":[{"atb":[[85,4.19]],"id":52385920},{"atb":[[50,4.51]],"id":52385917}],"con":true,"img":false}]}
{"op":"mcm","clk":"11450726167","pt":1717324914507,"mc":[{"id":"1.229554932","rc":[{"atl":[[550,0],[470,2]],"id":52385907},{"atl":[[330,2],[380,0]],"id":52385886},{"atl":[[6.2,0],[5.9,4.65]],"id":52385903},{"atl":[[5,0],[4.6,10.12]],"id":52385884}],"con":true,"img":false}]}
{"op":"mcm","clk":"11450726470","pt":1717324917832,"mc":[{"id":"1.229554932","rc":[{"atl":[[15,0],[15.5,2.64]],"id":52385909},{"atl":[[3.95,5.32]],"id":52385884}],"con":true,"img":false}]}
{"op":"mcm","clk":"11450726481","pt":1717324917937,"mc":[{"id":"1.229554932","rc":[{"atl":[[4.1,0]],"id":52385884}],"con":true,"img":false}]}
{"op":"mcm","clk":"11450726951","pt":1717324921926,"mc":[{"id":"1.229554932","rc":[{"atb":[[70,0],[85,5.56]],"id":52385936}],"con":true,"img":false}]}
{"op":"mcm","clk":"11450727423","pt":1717324927146,"mc":[{"id":"1.229554932","rc":[{"atb":[[28,0],[30,4.61]],"id":52385907},{"atb":[[140,0],[160,2.72]],"id":52385923},{"atb":[[7.4,0],[7.6,15.16]],"id":52385909},{"atb":[[17,6.54],[18.5,3.85]],"id":52385886},{"atb":[[95,0],[110,4.13]],"id":52385920},{"atb":[[2.4,11.21],[2.38,0]],"id":52385884},{"atb":[[75,4.04],[60,0]],"id":52385917}],"con":true,"img":false}]}
{"op":"mcm","clk":"11450727832","pt":1717324931920,"mc":[{"id":"1.229554932","rc":[{"atb":[[75,3]],"id":52385936}],"con":true,"img":false}]}
{"op":"mcm","clk":"11450728337","pt":1717324937173,"mc":[{"id":"1.229554932","rc":[{"atb":[[140,2.72]],"id":52385923},{"atb":[[28,3.33]],"id":52385907},{"atl":[[15,4.29],[15.5,0]],"id":52385909},{"atb":[[17.5,3.7]],"id":52385886},{"atb":[[95,4.15]],"id":52385920},{"atl":[[3.95,0],[4.1,5.06]],"id":52385884},{"atb":[[65,4.64]],"id":52385917}],"con":true,"img":false}]}
{"op":"mcm","clk":"11450728798","pt":1717324941960,"mc":[{"id":"1.229554932","rc":[{"atb":[[60,1.77]],"id":52385936}],"con":true,"img":false}]}
{"op":"mcm","clk":"11450729323","pt":1717324947178,"mc":[{"id":"1.229554932","rc":[{"atb":[[26,0]],"id":52385907},{"atb":[[120,0]],"id":52385923},{"atb":[[16,0]],"id":52385886},{"atb":[[85,0]],"id":52385920},{"atb":[[50,0]],"id":52385917}],"con":true,"img":false}]}
{"op":"mcm","clk":"11450732453","pt":1717324981835,"mc":[{"id":"1.229554932","rc":[{"atb":[[150,3.7],[160,0]],"id":52385923},{"atb":[[7.4,3.48],[7.6,11.89]],"id":52385909},{"atb":[[2.48,10.6]],"id":52385884},{"atb":[[80,3.9]],"id":52385917}],"con":true,"img":false}]}
{"op":"mcm","clk":"11450732464","pt":1717324981944,"mc":[{"id":"1.229554932","rc":[{"atb":[[2.4,0]],"id":52385884},{"atb":[[75,0]],"id":52385917}],"con":true,"img":false}]}
{"op":"mcm","clk":"11450733310","pt":1717324991838,"mc":[{"id":"1.229554932","rc":[{"atb":[[2.44,10.89]],"id":52385884}],"con":true,"img":false}]}
{"op":"mcm","clk":"11450733684","pt":1717324995852,"mc":[{"id":"1.229554932","rc":[{"atb":[[7.4,0],[7.6,14.83]],"id":52385909},{"atb":[[2.4,11.21]],"id":52385884}],"con":true,"img":false}]}
{"op":"mcm","clk":"11450733693","pt":1717324995947,"mc":[{"id":"1.229554932","rc":[{"atb":[[150,0],[160,4.39]],"id":52385923},{"atb":[[2.44,0],[2.48,0]],"id":52385884},{"atb":[[75,4.32],[80,0]],"id":52385917}],"con":true,"img":false}]}
{"op":"mcm","clk":"11450733941","pt":1717324998346,"mc":[{"id":"1.229554932","rc":[{"atb":[[150,4.44],[160,0]],"id":52385923},{"atb":[[7.4,3.14],[7.6,11.89]],"id":52385909},{"atb":[[2.4,0],[2.48,10.6]],"id":52385884},{"atb":[[75,0],[80,4.54]],"id":52385917}],"con":true,"img":false}]}
{"op":"mcm","clk":"11450734036","pt":1717324999128,"mc":[{"id":"1.229554932","rc":[{"atb":[[160,4.65]],"id":52385923},{"atb":[[2.4,11.21],[2.48,0]],"id":52385884}],"con":true,"img":false}]}
{"op":"mcm","clk":"11450734049","pt":1717324999236,"mc":[{"id":"1.229554932","rc":[{"atb":[[150,0]],"id":52385923},{"atb":[[7.4,0],[7.6,15.88]],"id":52385909},{"atb":[[75,4.66],[80,0]],"id":52385917}],"con":true,"img":false}]}
{"op":"mcm","clk":"11450734147","pt":1717325000323,"mc":[{"id":"1.229554932","rc":[{"atb":[[80,4.5]],"id":52385936}],"con":true,"img":false}]}
{"op":"mcm","clk":"11450734157","pt":1717325000425,"mc":[{"id":"1.229554932","rc":[{"atb":[[85,0.94]],"id":52385936}],"con":true,"img":false}]}
{"op":"mcm","clk":"11450734360","pt":1717325002252,"mc":[{"id":"1.229554932","rc":[{"atb":[[80,0],[85,4.49]],"id":52385936}],"con":true,"img":false}]}
{"op":"mcm","clk":"11450734459","pt":1717325003441,"mc":[{"id":"1.229554932","rc":[{"atb":[[150,4.66],[160,0]],"id":52385923},{"atb":[[7.4,4.22],[7.6,11.89]],"id":52385909},{"atb":[[2.4,0],[2.48,10.6]],"id":52385884},{"atb":[[75,0],[80,4.33]],"id":52385917}],"con":true,"img":false}]}
{"op":"mcm","clk":"11450734616","pt":1717325005264,"mc":[{"id":"1.229554932","rc":[{"atb":[[150,0],[160,2.92]],"id":52385923},{"atb":[[7.4,0],[7.6,14.94]],"id":52385909},{"atb":[[2.4,11.21],[2.48,0]],"id":52385884},{"atb":[[75,2.97],[80,0]],"id":52385917}],"con":true,"img":false}]}
{"op":"mcm","clk":"11450735442","pt":1717325013863,"mc":[{"id":"1.229554932","rc":[{"atb":[[140,0],[160,0]],"id":52385923},{"atb":[[30,0]],"id":52385907},{"atb":[[7.4,3.64],[7.6,11.89]],"id":52385909},{"atb":[[17,9.33],[18.5,0]],"id":52385886},{"atb":[[110,0]],"id":52385920},{"atb":[[2.4,0],[2.38,11.37]],"id":52385884},{"atb":[[75,0],[60,2.8]],"id":52385917}],"con":true,"img":false}]}
{"op":"mcm","clk":"11450735544","pt":1717325014885,"mc":[{"id":"1.229554932","rc":[{"atb":[[140,3.68],[160,2.86]],"id":52385923},{"atb":[[30,4.03]],"id":52385907},{"atb":[[7.4,0],[7.6,15.05]],"id":52385909},{"atb":[[17.5,0],[18.5,4]],"id":52385886},{"atb":[[110,3.8]],"id":52385920},{"atb":[[2.4,11.21],[2.38,0]],"id":52385884},{"atb":[[65,1.22],[75,4.06]],"id":52385917}],"con":true,"img":false}]}
{"op":"mcm","clk":"11450735577","pt":1717325015150,"mc":[{"id":"1.229554932","rc":[{"atb":[[80,2.83],[85,0.94]],"id":52385936}],"con":true,"img":false}]}
{"op":"mcm","clk":"11450735593","pt":1717325015248,"mc":[{"id":"1.229554932","rc":[{"atb":[[120,2.95]],"id":52385923}],"con":true,"img":false}]}
{"op":"mcm","clk":"11450735907","pt":1717325018673,"mc":[{"id":"1.229554932","rc":[{"atb":[[120,0]],"id":52385923},{"atb":[[85,5.11]],"id":52385936}],"con":true,"img":false}]}
{"op":"mcm","clk":"11450735915","pt":1717325018777,"mc":[{"id":"1.229554932","rc":[{"atb":[[80,0]],"id":52385936}],"con":true,"img":false}]}
{"op":"mcm","clk":"11450737149","pt":1717325032381,"mc":[{"id":"1.229554932","rc":[{"atb":[[80,4.29],[85,0.94]],"id":52385936}],"con":true,"img":false}]}
{"op":"mcm","clk":"11450737351","pt":1717325034410,"mc":[{"id":"1.229554932","rc":[{"atb":[[100,1.05],[50,4.97]],"id":52385923},{"atb":[[19.5,5.65],[14.5,18.06]],"id":52385907},{"atb":[[4,81.3],[5,26.13]],"id":52385909},{"atb":[[10,27.1],[15,7.46]],"id":52385886},{"atb":[[5.7,22.24],[4.7,65.92]],"id":52385934},{"atb":[[2.5,162.6],[2.7,61.48]],"id":52385903},{"atb":[[65,1.63],[36,6.96]],"id":52385936},{"atb":[[18,14.34],[26,4.18]],"id":52385920},{"atb":[[3.45,42.66],[2.98,123.18]],"id":52385888},{"atb":[[4.8,27.5],[3.9,84.1]],"id":52385931},{"atb":[[2.14,213.95],[2.34,78]],"id":52385884},{"atb":[[20,5.5],[15,17.42]],"id":52385917}],"con":true,"img":false}]}
{"op":"mcm","clk":"11450737500","pt":1717325035991,"mc":[{"id":"1.229554932","rc":[{"atb":[[80,0],[85,3.59]],"id":52385936}],"con":true,"img":false}]}
{"op":"mcm","clk":"11450738360","pt":1717325045102,"mc":[{"id":"1.229554932","rc":[{"atb":[[19.5,11.3],[14.5,36.13]],"id":52385907},{"atb":[[100,2.11],[50,9.95]],"id":52385923},{"atb":[[4,162.6],[5,52.26]],"id":52385909},{"atb":[[10,54.2],[15,14.93]],"id":52385886},{"atb":[[5.7,44.48],[4.7,131.84]],"id":52385934},{"atb":[[2.5,325.2],[2.7,122.97]],"id":52385903},{"atb":[[65,3.26],[36,13.93]],"id":52385936},{"atb":[[3.45,85.33],[2.98,246.36]],"id":52385888},{"atb":[[18,28.69],[26,8.36]],"id":52385920},{"atb":[[4.8,55.01],[3.9,168.21]],"id":52385931},{"atb":[[2.14,427.9],[2.34,156.01]],"id":52385884},{"atb":[[20,11],[15,34.84]],"id":52385917}],"con":true,"img":false}]}
{"op":"mcm","clk":"11450738890","pt":1717325050724,"mc":[{"id":"1.229554932","rc":[{"atb":[[80,3.6]],"id":52385936}],"con":true,"img":false}]}
{"op":"mcm","clk":"11450738900","pt":1717325050826,"mc":[{"id":"1.229554932","rc":[{"atb":[[85,0.94]],"id":52385936}],"con":true,"img":false}]}
{"op":"mcm","clk":"11450744826","pt":1717325113195,"mc":[{"id":"1.229554932","rc":[{"atb":[[4,0],[4.5,0],[5,0],[3.75,0]],"id":52385888}],"con":true,"img":false}]}
{"op":"mcm","clk":"11450744853","pt":1717325113401,"mc":[{"id":"1.229554932","rc":[{"atb":[[85,4.67]],"id":52385936}],"con":true,"img":false}]}
{"op":"mcm","clk":"11450744867","pt":1717325113516,"mc":[{"id":"1.229554932","rc":[{"atb":[[80,0]],"id":52385936}],"con":true,"img":false}]}
{"op":"mcm","clk":"11450744911","pt":1717325113949,"mc":[{"id":"1.229554932","rc":[{"atb":[[4,26.16],[4.5,14.95],[5,6.54],[3.75,38.05]],"id":52385888}],"con":true,"img":false}]}
{"op":"mcm","clk":"11450745284","pt":1717325117596,"mc":[{"id":"1.229554932","rc":[{"atb":[[150,4.39],[160,0]],"id":52385923},{"atb":[[7.4,2.99]],"id":52385909},{"atb":[[4,0],[4.5,0],[5,0],[3.75,0]],"id":52385888},{"atb":[[2.4,0],[2.48,10.6]],"id":52385884},{"atb":[[75,0],[80,3.96]],"id":52385917}],"con":true,"img":false}]}
{"op":"mcm","clk":"11450745295","pt":1717325117700,"mc":[{"id":"1.229554932","rc":[{"atb":[[7.6,11.89]],"id":52385909}],"con":true,"img":false}]}
{"op":"mcm","clk":"11450745352","pt":1717325118323,"mc":[{"id":"1.229554932","rc":[{"atb":[[3.85,36.72],[5.2,6.23],[4.2,24.52],[4.7,14.14]],"id":52385888}],"con":true,"img":false}]}
{"op":"mcm","clk":"11450745921","pt":1717325123588,"mc":[{"id":"1.229554932","rc":[{"atl":[[4.5,10.12],[4.6,0]],"id":52385884}],"con":true,"img":false}]}
{"op":"mcm","clk":"11450745966","pt":1717325123909,"mc":[{"id":"1.229554932","rc":[{"atb":[[160,3]],"id":52385923},{"atb":[[7.4,0],[7.6,15.59]],"id":52385909},{"atb":[[2.4,11.21]],"id":52385884},{"atb":[[75,3.7]],"id":52385917}],"con":true,"img":false}]}
{"op":"mcm","clk":"11450745978","pt":1717325123998,"mc":[{"id":"1.229554932","rc":[{"atb":[[150,0]],"id":52385923},{"atb":[[2.48,0]],"id":52385884},{"atb":[[80,0]],"id":52385917}],"con":true,"img":false}]}
{"op":"mcm","clk":"11450746505","pt":1717325128956,"mc":[{"id":"1.229554932","rc":[{"atb":[[150,3.36]],"id":52385923},{"atb":[[2.48,10.6]],"id":52385884}],"con":true,"img":false}]}
{"op":"mcm","clk":"11450746518","pt":1717325129011,"mc":[{"id":"1.229554932","rc":[{"atb":[[160,0]],"id":52385923},{"atb":[[7.4,3.4],[7.6,11.89]],"id":52385909},{"atb":[[2.4,0]],"id":52385884},{"atb":[[75,0],[80,3.57]],"id":52385917}],"con":true,"img":false}]}
{"op":"mcm","clk":"11450747208","pt":1717325135329,"mc":[{"id":"1.229554932","rc":[{"atb":[[150,0]],"id":52385923},{"atb":[[7.4,0]],"id":52385909}],"con":true,"img":false}]}
{"op":"mcm","clk":"11450747712","pt":1717325140231,"mc":[{"id":"1.229554932","rc":[{"atb":[[150,3.93]],"id":52385923}],"con":true,"img":false}]}
{"op":"mcm","clk":"11450748226","pt":1717325145319,"mc":[{"id":"1.229554932","rc":[{"atb":[[2.44,10.89]],"id":52385884}],"con":true,"img":false}]}
{"op":"mcm","clk":"11450748334","pt":1717325146315,"mc":[{"id":"1.229554932","rc":[{"atb":[[70,3.45]],"id":52385917}],"con":true,"img":false}]}
{"op":"mcm","clk":"11450748345","pt":1717325146421,"mc":[{"id":"1.229554932","rc":[{"atb":[[7.4,2.7]],"id":52385909}],"con":true,"img":false}]}
{"op":"mcm","clk":"11450748387","pt":1717325146836,"mc":[{"id":"1.229554932","rc":[{"atb":[[150,0]],"id":52385923},{"atb":[[2.44,0]],"id":52385884}],"con":true,"img":false}]}
{"op":"mcm","clk":"11450748442","pt":1717325147354,"mc":[{"id":"1.229554932","rc":[{"atb":[[7.6,16.35]],"id":52385909},{"atb":[[75,3.95]],"id":52385917}],"con":true,"img":false}]}
{"op":"mcm","clk":"11450748451","pt":1717325147456,"mc":[{"id":"1.229554932","rc":[{"atb":[[160,3.96]],"id":52385923},{"atb":[[2.4,11.21],[2.48,0]],"id":52385884},{"atb":[[80,0]],"id":52385917}],"con":true,"img":false}]}
{"op":"mcm","clk":"11450752267","pt":1717325186024,"mc":[{"id":"1.229554932","rc":[{"atb":[[160,0]],"id":52385923},{"atb":[[7.6,11.89]],"id":52385909},{"atb":[[18.5,0]],"id":52385886},{"atb":[[85,0.94]],"id":52385936},{"atb":[[2.4,0]],"id":52385884},{"atb":[[75,0],[60,0]],"id":52385917}],"con":true,"img":false}]}
{"op":"mcm","clk":"11450752450","pt":1717325187898,"mc":[{"id":"1.229554932","rc":[{"atb":[[75,0]],"id":52385936}],"con":true,"img":false}]}
{"op":"mcm","clk":"11450752912","pt":1717325192853,"mc":[{"id":"1.229554932","rc":[{"atb":[[7.4,0]],"id":52385909}],"con":true,"img":false}]}
{"op":"mcm","clk":"11450753527","pt":1717325199119,"mc":[{"id":"1.229554932","rc":[{"atb":[[30,0]],"id":52385907},{"atb":[[110,0]],"id":52385920},{"atb":[[70,0]],"id":52385917}],"con":true,"img":false}]}
{"op":"mcm","clk":"11450754103","pt":1717325204653,"mc":[{"id":"1.229554932","rc":[{"atb":[[10.5,0],[15,7.14]],"id":52385907},{"atb":[[5.7,65.76]],"id":52385934},{"atb":[[36,2.86],[27,0]],"id":52385920},{"atb":[[1.88,0],[1.95,105.26]],"id":52385884},{"atl":[[4.5,0],[4.2,10.12]],"id":52385884}],"con":true,"img":false}]}
{"op":"mcm","clk":"11450754118","pt":1717325204754,"mc":[{"id":"1.229554932","rc":[{"atb":[[5.1,0]],"id":52385934}],"con":true,"img":false}]}
{"op":"mcm","clk":"11450754148","pt":1717325205029,"mc":[{"id":"1.229554932","rc":[{"atl":[[110,0]],"id":52385907},{"atl":[[70,0]],"id":52385886},{"atl":[[660,0]],"id":52385920},{"atl":[[440,0]],"id":52385936},{"atl":[[9.8,0]],"id":52385888},{"atl":[[530,0]],"id":52385917}],"con":true,"img":false}]}
{"op":"mcm","clk":"11450754276","pt":1717325206369,"mc":[{"id":"1.229554932","rc":[{"atl":[[460,0]],"id":52385936},{"atl":[[680,0]],"id":52385920},{"atl":[[550,0]],"id":52385917}],"con":true,"img":false}]}
{"op":"mcm","clk":"11450758182","pt":1717325243206,"mc":[{"id":"1.229554932","rc":[{"atb":[[19.5,5.65],[14.5,18.06]],"id":52385907},{"atb":[[100,1.05],[50,4.97]],"id":52385923},{"atb":[[4,81.3],[5,26.13]],"id":52385909},{"atb":[[10,27.1],[15,7.46]],"id":52385886},{"atb":[[5.7,43.52],[4.7,65.92]],"id":52385934},{"atb":[[2.5,162.6],[2.7,61.48]],"id":52385903},{"atb":[[18,14.34],[26,4.18]],"id":52385920},{"atb":[[65,1.63],[36,6.96]],"id":52385936},{"atb":[[3.45,42.66],[2.98,123.18]],"id":52385888},{"atb":[[4.8,27.5],[3.9,84.1]],"id":52385931},{"atb":[[2.14,213.95],[2.34,78]],"id":52385884},{"atb":[[20,5.5],[15,17.42]],"id":52385917}],"con":true,"img":false}]}
{"op":"mcm","clk":"11450758835","pt":1717325249817,"mc":[{"id":"1.229554932","rc":[{"atb":[[19.5,11.3],[14.5,36.13]],"id":52385907},{"atb":[[4,162.6],[5,52.26]],"id":52385909},{"atb":[[10,54.2],[15,14.93]],"id":52385886},{"atb":[[2.5,325.2],[2.7,122.97]],"id":52385903},{"atb":[[3.45,85.33],[2.98,246.36]],"id":52385888},{"atb":[[2.14,427.9],[2.34,156.01]],"id":52385884}],"con":true,"img":false}]}
{"op":"mcm","clk":"11450758847","pt":1717325249921,"mc":[{"id":"1.229554932","rc":[{"atb":[[100,2.11],[50,9.95]],"id":52385923},{"atb":[[5.7,65.76],[4.7,131.84]],"id":52385934},{"atb":[[18,28.69],[26,8.36]],"id":52385920},{"atb":[[65,3.26],[36,13.93]],"id":52385936},{"atb":[[4.8,55.01],[3.9,168.21]],"id":52385931},{"atb":[[20,11],[15,34.84]],"id":52385917}],"con":true,"img":false}]}
{"op":"mcm","clk":"11450766939","pt":1717325324717,"mc":[{"id":"1.229554932","rc":[{"atb":[[1.89,112.36],[1.95,0]],"id":52385884},{"atl":[[4.4,10.12],[4.2,0]],"id":52385884}],"con":true,"img":false}]}
{"op":"mcm","clk":"11450768267","pt":1717325337734,"mc":[{"id":"1.229554932","rc":[{"atb":[[100,1.05],[50,4.97]],"id":52385923},{"atb":[[19.5,5.65],[14.5,18.06]],"id":52385907},{"atb":[[4,81.3],[5,26.13]],"id":52385909},{"atb":[[5.7,43.52],[4.7,65.92]],"id":52385934},{"atb":[[10,27.1],[15,7.46]],"id":52385886},{"atb":[[2.5,162.6],[2.7,61.48]],"id":52385903},{"atb":[[65,1.63],[36,6.96]],"id":52385936},{"atb":[[18,14.34],[26,4.18]],"id":52385920},{"atb":[[3.45,42.66],[2.98,123.18]],"id":52385888},{"atb":[[4.8,27.5],[3.9,84.1]],"id":52385931},{"atb":[[2.14,213.95],[2.34,78]],"id":52385884},{"atb":[[20,5.5],[15,17.42]],"id":52385917}],"con":true,"img":false}]}
{"op":"mcm","clk":"11450768826","pt":1717325342643,"mc":[{"id":"1.229554932","rc":[{"atb":[[100,2.11],[50,9.95]],"id":52385923},{"atb":[[19.5,11.3],[14.5,36.13]],"id":52385907},{"atb":[[4,162.6],[5,52.26]],"id":52385909},{"atb":[[10,54.2],[15,14.93]],"id":52385886},{"atb":[[5.7,65.76],[4.7,131.84]],"id":52385934},{"atb":[[2.5,325.2],[2.7,122.97]],"id":52385903},{"atb":[[18,28.69],[26,8.36]],"id":52385920},{"atb":[[65,3.26],[36,13.93]],"id":52385936},{"atb":[[3.45,85.33],[2.98,246.36]],"id":52385888},{"atb":[[4.8,55.01],[3.9,168.21]],"id":52385931},{"atb":[[2.14,427.9],[2.34,156.01]],"id":52385884},{"atb":[[20,11],[15,34.84]],"id":52385917}],"con":true,"img":false}]}
{"op":"mcm","clk":"11450769981","pt":1717325353854,"mc":[{"id":"1.229554932","rc":[{"atb":[[17,6.54]],"id":52385886}],"con":true,"img":false}]}
{"op":"mcm","clk":"11450774756","pt":1717325396104,"mc":[{"id":"1.229554932","rc":[{"atb":[[100,1.05],[50,4.97]],"id":52385923},{"atb":[[19.5,5.65],[14.5,18.06]],"id":52385907},{"atb":[[4,81.3],[5,26.13]],"id":52385909},{"atb":[[10,27.1],[15,7.46]],"id":52385886},{"atb":[[5.7,43.52],[4.7,65.92]],"id":52385934},{"atb":[[2.5,162.6],[2.7,61.48]],"id":52385903},{"atb":[[65,1.63],[36,6.96]],"id":52385936},{"atb":[[18,14.34],[26,4.18]],"id":52385920},{"atb":[[3.45,42.66],[2.98,123.18]],"id":52385888},{"atb":[[4.8,27.5],[3.9,84.1]],"id":52385931},{"atb":[[2.14,213.95],[2.34,78]],"id":52385884},{"atb":[[20,5.5],[15,17.42]],"id":52385917}],"con":true,"img":false}]}
{"op":"mcm","clk":"11450775270","pt":1717325400974,"mc":[{"id":"1.229554932","rc":[{"atb":[[160,0.65],[80,3.08]],"id":52385923},{"atb":[[19,5.8],[14,18.76]],"id":52385907},{"atb":[[4.3,73.9],[5.3,24.31]],"id":52385909},{"atb":[[9.8,27.71],[14.5,7.74]],"id":52385886},{"atb":[[6.4,19.35],[5.2,58.07]],"id":52385934},{"atb":[[2.4,174.21],[2.6,65.33]],"id":52385903},{"atb":[[3.15,113.44],[3.65,39.44]],"id":52385888},{"atb":[[95,1.11],[48,5.18]],"id":52385936},{"atb":[[17.5,14.77],[25,4.35]],"id":52385920},{"atb":[[5.1,25.49],[4.1,78.68]],"id":52385931},{"atb":[[1.98,248.88],[2.16,90.11]],"id":52385884},{"atb":[[19.5,5.65],[14.5,18.06]],"id":52385917}],"con":true,"img":false}]}
{"op":"mcm","clk":"11450776520","pt":1717325411428,"mc":[{"id":"1.229554932","rc":[{"atl":[[15,0]],"id":52385909},{"atl":[[4.1,0]],"id":52385884}],"con":true,"img":false}]}
{"op":"mcm","clk":"11450777106","pt":1717325415605,"mc":[{"id":"1.229554932","rc":[{"atb":[[5,25]],"id":52385934}],"con":true,"img":false}]}
{"op":"mcm","clk":"11450777120","pt":1717325415698,"mc":[{"id":"1.229554932","rc":[{"atb":[[5.7,22.24]],"id":52385934}],"con":true,"img":false}]}
{"op":"mcm","clk":"11450778159","pt":1717325424695,"mc":[{"id":"1.229554932","rc":[{"atl":[[6,0]],"id":52385903}],"con":true,"img":false}]}
{"op":"mcm","clk":"11450778170","pt":1717325424842,"mc":[{"id":"1.229554932","rc":[{"atl":[[6.2,9.3],[5.9,0]],"id":52385903}],"con":true,"img":false}]}
{"op":"mcm","clk":"11450778798","pt":1717325430914,"mc":[{"id":"1.229554932","rc":[{"atb":[[19,0],[14,0]],"id":52385907},{"atb":[[160,0],[80,0]],"id":52385923},{"atb":[[4.3,0],[5.3,0]],"id":52385909},{"atb":[[6.4,0],[5.2,0]],"id":52385934},{"atb":[[9.8,0],[14.5,0]],"id":52385886},{"atb":[[2.4,0],[2.6,0]],"id":52385903},{"atb":[[3.15,0],[3.65,0]],"id":52385888},{"atb":[[17.5,0],[25,0]],"id":52385920},{"atb":[[95,0],[48,0]],"id":52385936},{"atb":[[5.1,0],[4.1,0]],"id":52385931},{"atb":[[1.98,0],[2.16,0]],"id":52385884},{"atb":[[19.5,0],[14.5,0]],"id":52385917}],"con":true,"img":false}]}
{"op":"mcm","clk":"11450779168","pt":1717325434437,"mc":[{"id":"1.229554932","rc":[{"atb":[[19,5.8],[14,18.76]],"id":52385907},{"atb":[[160,0.65],[80,3.08]],"id":52385923},{"atb":[[4.3,73.9],[5.3,24.31]],"id":52385909},{"atb":[[6.4,19.35],[5.2,58.07]],"id":52385934},{"atb":[[9.8,27.71],[14.5,7.74]],"id":52385886},{"atb":[[2.4,174.21],[2.6,65.33]],"id":52385903},{"atb":[[95,1.11],[48,5.18]],"id":52385936},{"atb":[[3.15,113.44],[3.65,39.44]],"id":52385888},{"atb":[[17.5,14.77],[25,4.35]],"id":52385920},{"atb":[[5.1,25.49],[4.1,78.68]],"id":52385931},{"atb":[[1.98,248.88],[2.16,90.11]],"id":52385884},{"atb":[[19.5,5.65],[14.5,18.06]],"id":52385917}],"con":true,"img":false}]}
{"op":"mcm","clk":"11450779937","pt":1717325441867,"mc":[{"id":"1.229554932","rc":[{"atb":[[19,0],[14,0]],"id":52385907},{"atb":[[160,0],[80,0]],"id":52385923},{"atb":[[4.3,0],[5.3,0]],"id":52385909},{"atb":[[6.4,0],[5.2,0]],"id":52385934},{"atb":[[9.8,0],[14.5,0]],"id":52385886},{"atb":[[2.4,0],[2.6,0]],"id":52385903},{"atb":[[95,0],[48,0]],"id":52385936},{"atb":[[17.5,0],[25,0]],"id":52385920},{"atb":[[3.15,0],[3.65,0]],"id":52385888},{"atb":[[5.1,0],[4.1,0]],"id":52385931},{"atb":[[1.98,0],[2.16,0]],"id":52385884},{"atb":[[19.5,0],[14.5,0]],"id":52385917}],"con":true,"img":false}]}
{"op":"mcm","clk":"11450780637","pt":1717325448239,"mc":[{"id":"1.229554932","rc":[{"atb":[[160,0.65],[80,3.08]],"id":52385923},{"atb":[[6.4,19.35],[5.2,58.07]],"id":52385934},{"atb":[[17.5,14.77],[25,4.35]],"id":52385920},{"atb":[[95,1.11],[48,5.18]],"id":52385936},{"atb":[[5.1,25.49],[4.1,78.68]],"id":52385931},{"atb":[[19.5,5.65],[14.5,18.06]],"id":52385917}],"con":true,"img":false}]}
{"op":"mcm","clk":"11450780647","pt":1717325448391,"mc":[{"id":"1.229554932","rc":[{"atb":[[19,5.8],[14,18.76]],"id":52385907},{"atb":[[4.3,73.9],[5.3,24.31]],"id":52385909},{"atb":[[9.8,27.71],[14.5,7.74]],"id":52385886},{"atb":[[2.4,174.21],[2.6,65.33]],"id":52385903},{"atb":[[3.15,113.44],[3.65,39.44]],"id":52385888},{"atb":[[1.98,248.88],[2.16,90.11]],"id":52385884}],"con":true,"img":false}]}
{"op":"mcm","clk":"11450790304","pt":1717325536630,"mc":[{"id":"1.229554932","rc":[{"atb":[[19,0],[14,0]],"id":52385907},{"atb":[[160,0],[80,0]],"id":52385923},{"atb":[[4.3,0],[5.3,0]],"id":52385909},{"atb":[[9.8,0],[14.5,0]],"id":52385886},{"atb":[[6.4,0],[5.2,0]],"id":52385934},{"atb":[[2.4,0],[2.6,0]],"id":52385903},{"atb":[[3.15,0],[3.65,0]],"id":52385888},{"atb":[[17.5,0],[25,0]],"id":52385920},{"atb":[[95,0],[48,0]],"id":52385936},{"atb":[[5.1,0],[4.1,0]],"id":52385931},{"atb":[[1.98,0],[2.16,0]],"id":52385884},{"atb":[[19.5,0],[14.5,0]],"id":52385917}],"con":true,"img":false}]}
{"op":"mcm","clk":"11450791157","pt":1717325544324,"mc":[{"id":"1.229554932","rc":[{"atb":[[160,0.65],[80,3.08]],"id":52385923},{"atb":[[6.4,19.35],[5.2,58.07]],"id":52385934},{"atb":[[95,1.11],[48,5.18]],"id":52385936},{"atb":[[17.5,14.77],[25,4.35]],"id":52385920},{"atb":[[5.1,25.49],[4.1,78.68]],"id":52385931},{"atb":[[19.5,5.65],[14.5,18.06]],"id":52385917}],"con":true,"img":false}]}
{"op":"mcm","clk":"11450791170","pt":1717325544431,"mc":[{"id":"1.229554932","rc":[{"atb":[[19,5.8],[14,18.76]],"id":52385907},{"atb":[[4.3,73.9],[5.3,24.31]],"id":52385909},{"atb":[[9.8,27.71],[14.5,7.74]],"id":52385886},{"atb":[[2.4,174.21],[2.6,65.33]],"id":52385903},{"atb":[[3.15,113.44],[3.65,39.44]],"id":52385888},{"atb":[[1.98,248.88],[2.16,90.11]],"id":52385884}],"con":true,"img":false}]}
{"op":"mcm","clk":"11450800411","pt":1717325627565,"mc":[{"id":"1.229554932","rc":[{"atb":[[19,0],[14,0]],"id":52385907},{"atb":[[160,0],[80,0]],"id":52385923},{"atb":[[4.3,0],[5.3,0]],"id":52385909},{"atb":[[9.8,0],[14.5,0]],"id":52385886},{"atb":[[6.4,0],[5.2,0]],"id":52385934},{"atb":[[2.4,0],[2.6,0]],"id":52385903},{"atb":[[3.15,0],[3.65,0]],"id":52385888},{"atb":[[95,0],[48,0]],"id":52385936},{"atb":[[17.5,0],[25,0]],"id":52385920},{"atb":[[5.1,0],[4.1,0]],"id":52385931},{"atb":[[1.98,0],[2.16,0]],"id":52385884},{"atb":[[19.5,0],[14.5,0]],"id":52385917}],"con":true,"img":false}]}
{"op":"mcm","clk":"11450801046","pt":1717325633458,"mc":[{"id":"1.229554932","rc":[{"atb":[[160,0.65],[80,3.08]],"id":52385923},{"atb":[[19,5.8],[14,18.76]],"id":52385907},{"atb":[[4.3,73.9],[5.3,24.31]],"id":52385909},{"atb":[[9.8,27.71],[14.5,7.74]],"id":52385886},{"atb":[[6.4,19.35],[5.2,58.07]],"id":52385934},{"atb":[[2.4,174.21],[2.6,65.33]],"id":52385903},{"atb":[[17.5,14.77],[25,4.35]],"id":52385920},{"atb":[[95,1.11],[48,5.18]],"id":52385936},{"atb":[[3.15,113.44],[3.65,39.44]],"id":52385888},{"atb":[[5.1,25.49],[4.1,78.68]],"id":52385931},{"atb":[[1.98,248.88],[2.16,90.11]],"id":52385884},{"atb":[[19.5,5.65],[14.5,18.06]],"id":52385917}],"con":true,"img":false}]}
{"op":"mcm","clk":"11450804196","pt":1717325661592,"mc":[{"id":"1.229554932","rc":[{"atb":[[10.5,0]],"id":52385934},{"atb":[[2.36,57.7]],"id":52385884}],"con":true,"img":false}]}
{"op":"mcm","clk":"11450804895","pt":1717325668104,"mc":[{"id":"1.229554932","rc":[{"atb":[[20,5.26],[15,0]],"id":52385907},{"atb":[[4,114.63],[3.75,0]],"id":52385909},{"atb":[[5,0],[6,20]],"id":52385934},{"atb":[[8.6,0],[10,38.21]],"id":52385886},{"atl":[[18,5.88],[22,0]],"id":52385888},{"atl":[[4.4,0],[4.2,7.44]],"id":52385884}],"con":true,"img":false}]}
{"op":"mcm","clk":"11450804922","pt":1717325668413,"mc":[{"id":"1.229554932","rc":[{"atl":[[80,0]],"id":52385886}],"con":true,"img":false}]}
{"op":"mcm","clk":"11450804934","pt":1717325668517,"mc":[{"id":"1.229554932","rc":[{"atl":[[130,0]],"id":52385907},{"atl":[[330,0],[360,2]],"id":52385886},{"atl":[[32,0]],"id":52385934},{"atl":[[26,0]],"id":52385931}],"con":true,"img":false}]}
{"op":"mcm","clk":"11450804945","pt":1717325668576,"mc":[{"id":"1.229554932","rc":[{"atl":[[470,0],[510,2]],"id":52385907}],"con":true,"img":false}]}
{"op":"mcm","clk":"11450808210","pt":1717325699804,"mc":[{"id":"1.229554932","rc":[{"atb":[[19,0],[14,0]],"id":52385907},{"atb":[[160,0],[80,0]],"id":52385923},{"atb":[[4.3,0],[5.3,0]],"id":52385909},{"atb":[[9.8,0],[14.5,0]],"id":52385886},{"atb":[[6.4,0],[5.2,0]],"id":52385934},{"atb":[[2.4,0],[2.6,0]],"id":52385903},{"atb":[[3.15,0],[3.65,0]],"id":52385888},{"atb":[[95,0],[48,0]],"id":52385936},{"atb":[[17.5,0],[25,0]],"id":52385920},{"atb":[[5.1,0],[4.1,0]],"id":52385931},{"atb":[[1.98,0],[2.16,0]],"id":52385884},{"atb":[[19.5,0],[14.5,0]],"id":52385917}],"con":true,"img":false}]}
{"op":"mcm","clk":"11450808891","pt":1717325705784,"mc":[{"id":"1.229554932","rc":[{"atb":[[16,16.26],[22,4.97]],"id":52385907},{"atb":[[300,0.52],[200,1.75]],"id":52385923},{"atb":[[5.6,22.72],[4.6,67.75]],"id":52385909},{"atb":[[5.6,53.02],[7.2,16.86]],"id":52385934},{"atb":[[10.5,25.67],[15.5,7.2]],"id":52385886},{"atb":[[2.42,171.76],[2.62,64.52]],"id":52385903},{"atb":[[3.55,40.99],[3.05,118.97]],"id":52385888},{"atb":[[20,12.83],[30,3.6]],"id":52385920},{"atb":[[220,0.47],[120,2.49]],"id":52385936},{"atb":[[5.2,24.88],[4.2,76.22]],"id":52385931},{"atb":[[2.02,102.47],[1.91,268.02]],"id":52385884},{"atb":[[21,5.22],[15.5,16.82]],"id":52385917}],"con":true,"img":false}]}
{"op":"mcm","clk":"11450809979","pt":1717325715471,"mc":[{"id":"1.229554932","rc":[{"atb":[[16,0],[22,0]],"id":52385907},{"atb":[[300,0.17],[200,0.53]],"id":52385923},{"atb":[[5.6,0],[4.6,0]],"id":52385909},{"atb":[[10.5,0],[15.5,0]],"id":52385886},{"atb":[[5.6,0],[7.2,0]],"id":52385934},{"atb":[[2.42,0],[2.62,0]],"id":52385903},{"atb":[[20,0],[30,0]],"id":52385920},{"atb":[[220,0],[120,0.44]],"id":52385936},{"atb":[[3.55,0],[3.05,0]],"id":52385888},{"atb":[[5.2,0],[4.2,0]],"id":52385931},{"atb":[[2.02,0],[1.91,0]],"id":52385884},{"atb":[[21,0],[15.5,0]],"id":52385917}],"con":true,"img":false}]}
{"op":"mcm","clk":"11450810518","pt":1717325720670,"mc":[{"id":"1.229554932","rc":[{"atb":[[300,0.52],[200,1.75]],"id":52385923},{"atb":[[16,16.26],[22,4.97]],"id":52385907},{"atb":[[5.6,22.72],[4.6,67.75]],"id":52385909},{"atb":[[10.5,25.67],[15.5,7.2]],"id":52385886},{"atb":[[5.6,53.02],[7.2,16.86]],"id":52385934},{"atb":[[2.42,171.76],[2.62,64.52]],"id":52385903},{"atb":[[3.55,40.99],[3.05,118.97]],"id":52385888},{"atb":[[20,12.83],[30,3.6]],"id":52385920},{"atb":[[220,0.47],[120,2.49]],"id":52385936},{"atb":[[5.2,24.88],[4.2,76.22]],"id":52385931},{"atb":[[2.02,102.47],[1.91,268.02]],"id":52385884},{"atb":[[21,5.22],[15.5,16.82]],"id":52385917}],"con":true,"img":false}]}
{"op":"mcm","clk":"11450811394","pt":1717325729210,"mc":[{"id":"1.229554932","rc":[{"atb":[[300,0.17],[200,0.53]],"id":52385923},{"atb":[[16,0],[22,0]],"id":52385907},{"atb":[[5.6,0],[4.6,0]],"id":52385909},{"atb":[[10.5,0],[15.5,0]],"id":52385886},{"atb":[[5.6,0],[7.2,0]],"id":52385934},{"atb":[[2.42,0],[2.62,0]],"id":52385903},{"atb":[[3.55,0],[3.05,0]],"id":52385888},{"atb":[[220,0],[120,0.44]],"id":52385936},{"atb":[[20,0],[30,0]],"id":52385920},{"atb":[[5.2,0],[4.2,0]],"id":52385931},{"atb":[[2.02,0],[1.91,0]],"id":52385884},{"atb":[[21,0],[15.5,0]],"id":52385917}],"con":true,"img":false}]}
{"op":"mcm","clk":"11450811479","pt":1717325729999,"mc":[{"id":"1.229554932","rc":[{"atl":[[16,0]],"id":52385909}],"con":true,"img":false}]}
{"op":"mcm","clk":"11450811489","pt":1717325730109,"mc":[{"id":"1.229554932","rc":[{"atl":[[38,2.7]],"id":52385909}],"con":true,"img":false}]}
{"op":"mcm","clk":"11450811497","pt":1717325730213,"mc":[{"id":"1.229554932","rc":[{"atl":[[36,0]],"id":52385909}],"con":true,"img":false}]}
{"op":"mcm","clk":"11450812025","pt":1717325734895,"mc":[{"id":"1.229554932","rc":[{"atb":[[280,0.37],[180,1.36]],"id":52385923},{"atb":[[16,16.26],[22,4.97]],"id":52385907},{"atb":[[5.7,22.24],[4.7,65.92]],"id":52385909},{"atb":[[5.6,53.02],[7.2,16.86]],"id":52385934},{"atb":[[10,65.31],[15,14.93]],"id":52385886},{"atb":[[2.46,167.06],[2.66,62.96]],"id":52385903},{"atb":[[210,0.5],[110,2.23]],"id":52385936},{"atb":[[20,12.83],[30,3.6]],"id":52385920},{"atb":[[3,121.95],[3.5,41.81]],"id":52385888},{"atb":[[5.1,25.49],[4.1,78.68]],"id":52385931},{"atb":[[2,104.53],[1.9,271]],"id":52385884},{"atb":[[21,5.22],[15.5,16.82]],"id":52385917}],"con":true,"img":false}]}
{"op":"mcm","clk":"11450812753","pt":1717325741838,"mc":[{"id":"1.229554932","rc":[{"atb":[[16,0],[22,0]],"id":52385907},{"atb":[[280,0],[180,0]],"id":52385923},{"atb":[[5.7,0],[4.7,0]],"id":52385909},{"atb":[[5.6,0],[7.2,0]],"id":52385934},{"atb":[[10,38.21],[15,7.46]],"id":52385886},{"atb":[[2.46,0],[2.66,0]],"id":52385903},{"atb":[[210,0],[110,0]],"id":52385936},{"atb":[[20,0],[30,0]],"id":52385920},{"atb":[[3,0],[3.5,0]],"id":52385888},{"atb":[[5.1,0],[4.1,0]],"id":52385931},{"atb":[[2,0],[1.9,0]],"id":52385884},{"atb":[[21,0],[15.5,0]],"id":52385917}],"con":true,"img":false}]}
{"op":"mcm","clk":"11450813214","pt":1717325746041,"mc":[{"id":"1.229554932","rc":[{"atb":[[330,0.31],[230,1.06]],"id":52385923},{"atb":[[16.5,15.73],[23,4.75]],"id":52385907},{"atb":[[5.7,22.24],[4.7,65.92]],"id":52385909},{"atb":[[5.6,53.02],[7.2,16.86]],"id":52385934},{"atb":[[10.5,25.67],[15.5,7.2]],"id":52385886},{"atb":[[2.46,167.06],[2.66,62.96]],"id":52385903},{"atb":[[150,1.63],[250,0.41]],"id":52385936},{"atb":[[34,3.16],[22,11.61]],"id":52385920},{"atb":[[3,121.95],[3.5,41.81]],"id":52385888},{"atb":[[5.1,25.49],[4.1,78.68]],"id":52385931},{"atb":[[2,104.53],[1.9,271]],"id":52385884},{"atb":[[16,16.26],[22,4.97]],"id":52385917}],"con":true,"img":false}]}
{"op":"mcm","clk":"11450814199","pt":1717325756854,"mc":[{"id":"1.229554932","rc":[{"atb":[[16.5,0],[23,0]],"id":52385907},{"atb":[[330,0],[230,0]],"id":52385923},{"atb":[[5.7,0],[4.7,0]],"id":52385909},{"atb":[[10.5,0],[15.5,0]],"id":52385886},{"atb":[[5.6,0],[7.2,0]],"id":52385934},{"atb":[[2.46,0],[2.66,0]],"id":52385903},{"atb":[[3,0],[3.5,0]],"id":52385888},{"atb":[[150,0],[250,0]],"id":52385936},{"atb":[[34,0],[22,0]],"id":52385920},{"atb":[[5.1,0],[4.1,0]],"id":52385931},{"atb":[[2,0],[1.9,0]],"id":52385884},{"atb":[[16,0],[22,0]],"id":52385917}],"con":true,"img":false}]}
{"op":"mcm","clk":"11450814559","pt":1717325760796,"mc":[{"id":"1.229554932","rc":[{"atb":[[18,14.34],[26,4.18]],"id":52385907},{"atb":[[310,0.78],[410,0.25]],"id":52385923},{"atb":[[5.7,22.24],[4.7,65.92]],"id":52385909},{"atb":[[16.5,6.74],[11.5,23.22]],"id":52385886},{"atb":[[5.6,53.02],[7.2,16.86]],"id":52385934},{"atb":[[2.64,63.73],[2.44,169.37]],"id":52385903},{"atb":[[320,0.32],[220,1.11]],"id":52385936},{"atb":[[40,2.67],[25,10.16]],"id":52385920},{"atb":[[3,121.95],[3.5,41.81]],"id":52385888},{"atb":[[5.1,25.49],[4.1,78.68]],"id":52385931},{"atb":[[2,104.53],[1.9,271]],"id":52385884},{"atb":[[17,15.24],[24,4.54]],"id":52385917}],"con":true,"img":false}]}
{"op":"mcm","clk":"11450817270","pt":1717325788166,"mc":[{"id":"1.229554932","rc":[{"atl":[[560,2],[510,0]],"id":52385907},{"atl":[[38,0],[42,2.44]],"id":52385909},{"atl":[[360,0],[390,2]],"id":52385886}],"con":true,"img":false}]}
{"op":"mcm","clk":"11450818217","pt":1717325797889,"mc":[{"id":"1.229554932","rc":[{"atb":[[3.25,44.44]],"id":52385888},{"atb":[[4.2,31.25]],"id":52385931},{"atb":[[1.89,0],[1.35,166.1]],"id":52385884}],"con":true,"img":false}]}
{"op":"mcm","clk":"11450818226","pt":1717325797941,"mc":[{"id":"1.229554932","rc":[{"atb":[[2.78,0]],"id":52385888},{"atb":[[2.78,0]],"id":52385931}],"con":true,"img":false}]}
{"op":"mcm","clk":"11450818256","pt":1717325798250,"mc":[{"id":"1.229554932","rc":[{"atb":[[2.96,0]],"id":52385903}],"con":true,"img":false}]}
{"op":"mcm","clk":"11450819628","pt":1717325811467,"mc":[{"id":"1.229554932","rc":[{"atb":[[1.02,155.94]],"id":52385907},{"atb":[[1.04,121]],"id":52385923},{"atb":[[1.03,128.67]],"id":52385909},{"atb":[[1.03,125.26]],"id":52385886},{"atb":[[1.03,135.49]],"id":52385934},{"atb":[[1.04,117.59]],"id":52385903},{"atb":[[1.04,87.77]],"id":52385888},{"atb":[[1.04,101.4]],"id":52385920},{"atb":[[1.04,78.39]],"id":52385936},{"atb":[[1.02,115.89]],"id":52385931},{"atb":[[1.02,96.29]],"id":52385884},{"atb":[[1.03,100.55]],"id":52385917}],"con":true,"img":false}]}
{"op":"mcm","clk":"11450820000","pt":1717325814689,"mc":[{"id":"1.229554932","rc":[{"atb":[[18,0],[26,0]],"id":52385907},{"atb":[[310,0],[410,0]],"id":52385923},{"atb":[[5.7,0],[4.7,0]],"id":52385909},{"atb":[[16.5,0],[11.5,0]],"id":52385886},{"atb":[[5.6,0],[7.2,0]],"id":52385934},{"atb":[[2.64,0],[2.44,0]],"id":52385903},{"atb":[[3,0],[3.5,0]],"id":52385888},{"atb":[[40,0],[25,0]],"id":52385920},{"atb":[[320,0],[220,0]],"id":52385936},{"atb":[[5.1,0],[4.1,0]],"id":52385931},{"atb":[[2,0],[1.9,0]],"id":52385884},{"atb":[[17,0],[24,0]],"id":52385917}],"con":true,"img":false}]}
{"op":"mcm","clk":"11450820768","pt":1717325822417,"mc":[{"id":"1.229554932","rc":[{"atb":[[310,0.78],[410,0.25]],"id":52385923},{"atb":[[5.6,53.02],[7.2,16.86]],"id":52385934},{"atb":[[40,2.67],[25,10.16]],"id":52385920},{"atb":[[320,0.32],[220,1.11]],"id":52385936},{"atb":[[5.1,25.49],[4.1,78.68]],"id":52385931},{"atb":[[17,15.24],[24,4.54]],"id":52385917}],"con":true,"img":false}]}
{"op":"mcm","clk":"11450820782","pt":1717325822523,"mc":[{"id":"1.229554932","rc":[{"atb":[[18,14.34],[26,4.18]],"id":52385907},{"atb":[[5.7,22.24],[4.7,65.92]],"id":52385909},{"atb":[[16.5,6.74],[11.5,23.22]],"id":52385886},{"atb":[[2.64,63.73],[2.44,169.37]],"id":52385903},{"atb":[[3,121.95],[3.5,41.81]],"id":52385888},{"atb":[[2,104.53],[1.9,271]],"id":52385884}],"con":true,"img":false}]}
{"op":"mcm","clk":"11450822071","pt":1717325833131,"mc":[{"id":"1.229554932","rc":[{"atb":[[18,0],[26,0]],"id":52385907},{"atb":[[310,0],[410,0]],"id":52385923},{"atb":[[5.7,0],[4.7,0]],"id":52385909},{"atb":[[16.5,0],[11.5,0]],"id":52385886},{"atb":[[5.6,0],[7.2,0]],"id":52385934},{"atb":[[2.64,0],[2.44,0]],"id":52385903},{"atb":[[3,0],[3.5,0]],"id":52385888},{"atb":[[320,0],[220,0]],"id":52385936},{"atb":[[40,0],[25,0]],"id":52385920},{"atb":[[5.1,0],[4.1,0]],"id":52385931},{"atb":[[2,0],[1.9,0]],"id":52385884},{"atb":[[17,0],[24,0]],"id":52385917}],"con":true,"img":false}]}
{"op":"mcm","clk":"11450822100","pt":1717325833398,"mc":[{"id":"1.229554932","rc":[{"atb":[[20,0],[5.5,22.22]],"id":52385907},{"atl":[[560,0],[500,2]],"id":52385907},{"atb":[[32,0],[17,6.25]],"id":52385923},{"atl":[[870,2]],"id":52385923},{"atb":[[4,81.3],[5.3,23.26]],"id":52385909},{"atl":[[42,0],[60,2]],"id":52385909},{"atb":[[10,27.1],[3.4,41.67]],"id":52385886},{"atl":[[310,2],[390,0]],"id":52385886},{"atb":[[7.4,15.62],[6,0]],"id":52385934},{"atb":[[2.14,0],[2.94,43.13]],"id":52385903},{"atl":[[6.2,0],[11,10]],"id":52385903},{"atb":[[36,0],[9,12.5]],"id":52385920},{"atl":[[710,2]],"id":52385920},{"atb":[[3.8,35.71],[3.25,0]],"id":52385888},{"atl":[[18,0],[15,6.56]],"id":52385888},{"atb":[[10,11.11],[30,0]],"id":52385936},{"atl":[[750,2]],"id":52385936},{"atl":[[95,0],[60,2]],"id":52385931},{"atl":[[5.7,12.2],[4.2,0]],"id":52385884},{"atb":[[7,16.67],[30,0]],"id":52385917},{"atl":[[580,2]],"id":52385917}],"con":true,"img":false}]}
{"op":"mcm","clk":"11450822108","pt":1717325833500,"mc":[{"id":"1.229554932","rc":[{"atb":[[3.9,34.48]],"id":52385886},{"atl":[[15,0]],"id":52385888},{"atl":[[5.7,0]],"id":52385884}],"con":true,"img":false}]}
{"op":"mcm","clk":"11450822119","pt":1717325833609,"mc":[{"id":"1.229554932","rc":[{"atb":[[17,0],[21,5]],"id":52385923},{"atl":[[840,2],[870,0]],"id":52385923},{"atb":[[5.5,0],[6.6,17.86]],"id":52385907},{"atl":[[460,2],[500,0]],"id":52385907},{"atb":[[3.1,35.42],[2.94,0]],"id":52385903},{"atl":[[9.2,10],[11,0]],"id":52385903},{"atl":[[12.5,6.56]],"id":52385888},{"atb":[[11,10]],"id":52385920},{"atl":[[650,2]],"id":52385920},{"atb":[[10,0],[12.5,8.7]],"id":52385936},{"atl":[[680,2],[750,0]],"id":52385936},{"atl":[[5.1,12.2]],"id":52385884},{"atb":[[8.6,13.16],[7,0]],"id":52385917}],"con":true,"img":false}]}
{"op":"mcm","clk":"11450822123","pt":1717325833707,"mc":[{"id":"1.229554932","rc":[{"atb":[[3.4,0]],"id":52385886},{"atb":[[9,0]],"id":52385920},{"atl":[[710,0]],"id":52385920}],"con":true,"img":false}]}
{"op":"mcm","clk":"11450822137","pt":1717325833815,"mc":[{"id":"1.229554932","rc":[{"atb":[[140,0]],"id":52385923},{"atb":[[28,0]],"id":52385907},{"atl":[[6.4,0]],"id":52385903},{"atb":[[95,0]],"id":52385920}],"con":true,"img":false}]}
{"op":"mcm","clk":"11450822421","pt":1717325836312,"mc":[{"id":"1.229554932","rc":[{"atb":[[1.03,5.72]],"id":52385907},{"atl":[[990,0.85]],"id":52385907},{"atb":[[1.01,17.17]],"id":52385923},{"atb":[[1.02,8.58]],"id":52385909},{"atl":[[1000,0.85]],"id":52385909},{"atb":[[1.02,8.58]],"id":52385886},{"atl":[[990,0.85]],"id":52385886},{"atb":[[1.02,8.58]],"id":52385934},{"atl":[[1000,0.85]],"id":52385934},{"atb":[[1.02,8.58]],"id":52385903},{"atl":[[990,0.85]],"id":52385903},{"atb":[[1.03,5.72]],"id":52385920},{"atl":[[990,0.85]],"id":52385920},{"atb":[[1.01,17.17]],"id":52385936},{"atb":[[1.03,5.72]],"id":52385888},{"atl":[[1000,0.85]],"id":52385888},{"atb":[[1.03,5.72]],"id":52385931},{"atl":[[990,0.85]],"id":52385931},{"atb":[[1.03,5.72]],"id":52385884},{"atl":[[1000,0.85]],"id":52385884},{"atb":[[1.02,8.58]],"id":52385917},{"atl":[[990,0.85]],"id":52385917}],"con":true,"img":false}]}
{"op":"mcm","clk":"11450822436","pt":1717325836423,"mc":[{"id":"1.229554932","rc":[{"atl":[[400,2],[60,0]],"id":52385909}],"con":true,"img":false}]}
{"op":"mcm","clk":"11450822554","pt":1717325837617,"mc":[{"id":"1.229554932","rc":[{"atl":[[9.2,0],[42,2.44]],"id":52385903}],"con":true,"img":false}]}
{"op":"mcm","clk":"11450822913","pt":1717325841143,"mc":[{"id":"1.229554932","rc":[{"atb":[[18,14.34],[26,4.18]],"id":52385907},{"atb":[[310,0.78],[410,0.25]],"id":52385923},{"atb":[[5.7,22.24],[4.7,65.92]],"id":52385909},{"atb":[[5.6,53.02],[7.2,16.86]],"id":52385934},{"atb":[[16.5,6.74],[11.5,23.22]],"id":52385886},{"atb":[[2.64,63.73],[2.44,169.37]],"id":52385903},{"atb":[[40,2.67],[25,10.16]],"id":52385920},{"atb":[[3,121.95],[3.5,41.81]],"id":52385888},{"atb":[[320,0.32],[220,1.11]],"id":52385936},{"atb":[[5.1,25.49],[4.1,78.68]],"id":52385931},{"atb":[[2,104.53],[1.9,271]],"id":52385884},{"atb":[[17,15.24],[24,4.54]],"id":52385917}],"con":true,"img":false}]}
{"op":"mcm","clk":"11450822926","pt":1717325841243,"mc":[{"id":"1.229554932","rc":[{"atb":[[320,0],[220,0]],"id":52385936},{"trd":[[220,2.22],[320,0.65]],"ltp":220.0,"tv":2.87,"id":52385936}],"con":true,"img":false}]}
{"op":"mcm","clk":"11450823099","pt":1717325842747,"mc":[{"id":"1.229554932","rc":[{"atl":[[570,2],[580,0]],"id":52385917}],"con":true,"img":false}]}
{"op":"mcm","clk":"11450823733","pt":1717325848641,"mc":[{"id":"1.229554932","rc":[{"atl":[[42,0],[44,2.33]],"id":52385903}],"con":true,"img":false}]}
{"op":"mcm","clk":"11450824292","pt":1717325853660,"mc":[{"id":"1.229554932","rc":[{"atl":[[440,2],[460,0]],"id":52385907},{"atb":[[32,3.23],[21,0]],"id":52385923},{"atl":[[330,2],[400,0]],"id":52385909},{"atb":[[4.4,29.41],[3.9,0]],"id":52385886},{"atl":[[90,2],[120,0]],"id":52385934},{"atb":[[2.88,53.19],[3.1,0]],"id":52385903},{"atb":[[17,6.25],[12.5,0]],"id":52385936},{"atl":[[650,0],[670,2]],"id":52385920},{"atl":[[17.5,6.06],[12.5,0]],"id":52385888},{"atb":[[8.6,0],[9.8,11.36]],"id":52385917}],"con":true,"img":false}]}
{"op":"mcm","clk":"11450824305","pt":1717325853758,"mc":[{"id":"1.229554932","rc":[{"atl":[[44,0],[25,2]],"id":52385903}],"con":true,"img":false}]}
{"op":"mcm","clk":"11450824876","pt":1717325858946,"mc":[{"id":"1.229554932","rc":[{"atl":[[24,2],[25,0]],"id":52385903}],"con":true,"img":false}]}
{"op":"mcm","clk":"11450826776","pt":1717325875490,"mc":[{"id":"1.229554932","rc":[{"atl":[[330,0],[320,2]],"id":52385909},{"atb":[[3.95,33.9],[3.8,0]],"id":52385888}],"con":true,"img":false}]}
{"op":"mcm","clk":"11450827848","pt":1717325885974,"mc":[{"id":"1.229554932","rc":[{"atb":[[2.82,98.07],[2.88,0]],"id":52385903}],"con":true,"img":false}]}
{"op":"mcm","clk":"11450828421","pt":1717325891004,"mc":[{"id":"1.229554932","rc":[{"atl":[[430,2],[440,0]],"id":52385907},{"atl":[[320,0],[330,2]],"id":52385909},{"atl":[[24,0]],"id":52385903}],"con":true,"img":false}]}
{"op":"mcm","clk":"11450828435","pt":1717325891105,"mc":[{"id":"1.229554932","rc":[{"atl":[[23,2]],"id":52385903}],"con":true,"img":false}]}
{"op":"mcm","clk":"11450828467","pt":1717325891367,"mc":[{"id":"1.229554932","rc":[{"atl":[[28,0]],"id":52385931}],"con":true,"img":false}]}
{"op":"mcm","clk":"11450828481","pt":1717325891468,"mc":[{"id":"1.229554932","rc":[{"atl":[[450,2],[60,0]],"id":52385931}],"con":true,"img":false}]}
{"op":"mcm","clk":"11450829033","pt":1717325896189,"mc":[{"id":"1.229554932","rc":[{"atl":[[330,0],[320,2]],"id":52385909}],"con":true,"img":false}]}
{"op":"mcm","clk":"11450829760","pt":1717325902785,"mc":[{"id":"1.229554932","rc":[{"atl":[[320,0],[330,2]],"id":52385909},{"atl":[[450,0],[460,2]],"id":52385931}],"con":true,"img":false}]}
{"op":"mcm","clk":"11450829902","pt":1717325904335,"mc":[{"id":"1.229554932","rc":[{"atl":[[570,0],[620,2]],"id":52385917}],"con":true,"img":false}]}
{"op":"mcm","clk":"11450829916","pt":1717325904437,"mc":[{"id":"1.229554932","rc":[{"atl":[[430,0],[450,2]],"id":52385907},{"atl":[[310,0],[330,2]],"id":52385886},{"atl":[[670,0],[700,2]],"id":52385920}],"con":true,"img":false}]}
{"op":"mcm","clk":"11450829980","pt":1717325905009,"mc":[{"id":"1.229554932","rc":[{"atl":[[570,2]],"id":52385917}],"con":true,"img":false}]}
{"op":"mcm","clk":"11450829992","pt":1717325905113,"mc":[{"id":"1.229554932","rc":[{"atl":[[620,0]],"id":52385917}],"con":true,"img":false}]}
{"op":"mcm","clk":"11450830256","pt":1717325907708,"mc":[{"id":"1.229554932","rc":[{"atl":[[320,2]],"id":52385909}],"con":true,"img":false}]}
{"op":"mcm","clk":"11450830265","pt":1717325907809,"mc":[{"id":"1.229554932","rc":[{"atl":[[330,0]],"id":52385909}],"con":true,"img":false}]}
{"op":"mcm","clk":"11450830427","pt":1717325909513,"mc":[{"id":"1.229554932","rc":[{"atl":[[430,2],[450,0]],"id":52385907},{"atl":[[310,2],[330,0]],"id":52385886},{"atl":[[670,2],[700,0]],"id":52385920}],"con":true,"img":false}]}
{"op":"mcm","clk":"11450830509","pt":1717325910337,"mc":[{"id":"1.229554932","rc":[{"atl":[[430,0],[450,2]],"id":52385907},{"atl":[[310,0],[320,2]],"id":52385886},{"atl":[[670,0],[710,2]],"id":52385920},{"atl":[[570,0],[610,2]],"id":52385917}],"con":true,"img":false}]}
{"op":"mcm","clk":"11450830760","pt":1717325912722,"mc":[{"id":"1.229554932","rc":[{"atb":[[19.5,5.41]],"id":52385936},{"atl":[[4.9,9.52]],"id":52385884}],"con":true,"img":false}]}
{"op":"mcm","clk":"11450830772","pt":1717325912821,"mc":[{"id":"1.229554932","rc":[{"atl":[[320,0],[330,2]],"id":52385909},{"atb":[[17,0]],"id":52385936},{"atl":[[460,0],[450,2]],"id":52385931},{"atl":[[5.1,0]],"id":52385884}],"con":true,"img":false}]}
{"op":"mcm","clk":"11450830975","pt":1717325914643,"mc":[{"id":"1.229554932","rc":[{"atb":[[18,0],[26,0]],"id":52385907},{"atb":[[310,0],[410,0]],"id":52385923},{"atb":[[5.7,0],[4.7,0]],"id":52385909},{"atb":[[16.5,0],[11.5,0]],"id":52385886},{"atb":[[5.6,0],[7.2,0]],"id":52385934},{"atb":[[2.64,0],[2.44,0]],"id":52385903},{"atb":[[40,0],[25,0]],"id":52385920},{"atb":[[3,0],[3.5,0]],"id":52385888},{"atb":[[5.1,0],[4.1,0]],"id":52385931},{"atb":[[2,0],[1.9,0]],"id":52385884},{"atb":[[17,0],[24,0]],"id":52385917}],"con":true,"img":false}]}
{"op":"mcm","clk":"11450831055","pt":1717325915423,"mc":[{"id":"1.229554932","rc":[{"atl":[[310,2],[320,0]],"id":52385886}],"con":true,"img":false}]}
{"op":"mcm","clk":"11450831154","pt":1717325916421,"mc":[{"id":"1.229554932","rc":[{"atl":[[300,2]],"id":52385886}],"con":true,"img":false}]}
{"op":"mcm","clk":"11450831163","pt":1717325916522,"mc":[{"id":"1.229554932","rc":[{"atl":[[310,0]],"id":52385886}],"con":true,"img":false}]}
{"op":"mcm","clk":"11450831219","pt":1717325917038,"mc":[{"id":"1.229554932","rc":[{"atl":[[320,2]],"id":52385886}],"con":true,"img":false}]}
{"op":"mcm","clk":"11450831226","pt":1717325917138,"mc":[{"id":"1.229554932","rc":[{"atl":[[300,0]],"id":52385886}],"con":true,"img":false}]}
{"op":"mcm","clk":"11450831245","pt":1717325917345,"mc":[{"id":"1.229554932","rc":[{"atl":[[300,2],[320,0]],"id":52385886}],"con":true,"img":false}]}
{"op":"mcm","clk":"11450831308","pt":1717325917809,"mc":[{"id":"1.229554932","rc":[{"atl":[[440,2]],"id":52385907},{"atl":[[680,2],[710,0]],"id":52385920},{"atl":[[580,2],[610,0]],"id":52385917}],"con":true,"img":false}]}
{"op":"mcm","clk":"11450831315","pt":1717325917914,"mc":[{"id":"1.229554932","rc":[{"atl":[[450,0]],"id":52385907}],"con":true,"img":false}]}
{"op":"mcm","clk":"11450831414","pt":1717325918748,"mc":[{"id":"1.229554932","rc":[{"atl":[[300,0],[320,2]],"id":52385886}],"con":true,"img":false}]}
{"op":"mcm","clk":"11450831666","pt":1717325921030,"mc":[{"id":"1.229554932","rc":[{"atl":[[440,0],[450,2]],"id":52385907},{"atl":[[680,0],[710,2]],"id":52385920},{"atl":[[580,0],[610,2]],"id":52385917}],"con":true,"img":false}]}
{"op":"mcm","clk":"11450831823","pt":1717325922426,"mc":[{"id":"1.229554932","rc":[{"atb":[[17.5,14.84],[25,4.37]],"id":52385907},{"atb":[[340,0.72],[440,0.24]],"id":52385923},{"atb":[[5.6,22.81],[4.6,68.03]],"id":52385909},{"atb":[[17,13.1],[12,22.26]],"id":52385886},{"atb":[[5.6,53.24],[7.2,16.92]],"id":52385934},{"atb":[[2.38,177.47],[2.58,66.43]],"id":52385903},{"atb":[[40,2.68],[25,10.2]],"id":52385920},{"atb":[[3.6,40.36],[3.1,116.62]],"id":52385888},{"atb":[[5.2,24.99],[4.2,107.78]],"id":52385931},{"atb":[[2,104.96],[1.9,272.13]],"id":52385884},{"atb":[[17.5,14.84],[25,4.37]],"id":52385917}],"con":true,"img":false}]}
{"op":"mcm","clk":"11450831956","pt":1717325923670,"mc":[{"id":"1.229554932","rc":[{"atl":[[290,2],[330,0]],"id":52385909},{"atl":[[75,2]],"id":52385934},{"atl":[[19.5,2]],"id":52385903},{"atl":[[17.5,0],[15.5,6.56]],"id":52385888},{"atl":[[430,2],[450,0]],"id":52385931},{"atl":[[4.5,9.52],[4.9,0]],"id":52385884}],"con":true,"img":false}]}
{"op":"mcm","clk":"11450831967","pt":1717325923779,"mc":[{"id":"1.229554932","rc":[{"atl":[[90,0]],"id":52385934},{"atl":[[23,0]],"id":52385903}],"con":true,"img":false}]}
{"op":"mcm","clk":"11450831980","pt":1717325923874,"mc":[{"id":"1.229554932","rc":[{"atl":[[300,2],[320,0]],"id":52385886}],"con":true,"img":false}]}
{"op":"mcm","clk":"11450832235","pt":1717325926159,"mc":[{"id":"1.229554932","rc":[{"atl":[[430,2],[450,0]],"id":52385907},{"atl":[[640,2],[710,0]],"id":52385920},{"atl":[[570,2],[610,0]],"id":52385917}],"con":true,"img":false}]}
{"op":"mcm","clk":"11450832447","pt":1717325928063,"mc":[{"id":"1.229554932","rc":[{"atl":[[300,0],[320,2]],"id":52385886}],"con":true,"img":false}]}
{"op":"mcm","clk":"11450832460","pt":1717325928166,"mc":[{"id":"1.229554932","rc":[{"atl":[[290,0],[300,2]],"id":52385909},{"atb":[[11,0],[13.5,8]],"id":52385920},{"atl":[[430,0],[420,2]],"id":52385931}],"con":true,"img":false}]}
{"op":"mcm","clk":"11450839214","pt":1717325929296,"mc":[{"id":"1.229554932","rc":[{"atl":[[430,0],[450,2]],"id":52385907},{"atl":[[640,0],[710,2]],"id":52385920},{"atl":[[570,0],[610,2]],"id":52385917}],"con":true,"img":false}]}
{"op":"mcm","clk":"11450839241","pt":1717325929457,"mc":[{"id":"1.229554932","rc":[{"atl":[[300,2],[320,0]],"id":52385886}],"con":true,"img":false}]}
{"op":"mcm","clk":"11450839414","pt":1717325931271,"mc":[{"id":"1.229554932","rc":[{"atl":[[430,2]],"id":52385907},{"atl":[[640,2],[710,0]],"id":52385920},{"atl":[[570,2],[610,0]],"id":52385917}],"con":true,"img":false}]}
{"op":"mcm","clk":"11450839427","pt":1717325931373,"mc":[{"id":"1.229554932","rc":[{"atl":[[450,0]],"id":52385907}],"con":true,"img":false}]}
{"op":"mcm","clk":"11450839643","pt":1717325933156,"mc":[{"id":"1.229554932","rc":[{"atl":[[430,0],[440,2]],"id":52385907},{"atl":[[320,2]],"id":52385886},{"atl":[[640,0],[700,2]],"id":52385920},{"atl":[[570,0],[610,2]],"id":52385917}],"con":true,"img":false}]}
{"op":"mcm","clk":"11450839656","pt":1717325933263,"mc":[{"id":"1.229554932","rc":[{"atl":[[300,0]],"id":52385886}],"con":true,"img":false}]}
{"op":"mcm","clk":"11450839722","pt":1717325933885,"mc":[{"id":"1.229554932","rc":[{"atl":[[290,2]],"id":52385909},{"atl":[[19,2]],"id":52385903}],"con":true,"img":false}]}
{"op":"mcm","clk":"11450839728","pt":1717325933975,"mc":[{"id":"1.229554932","rc":[{"atl":[[300,0]],"id":52385909},{"atl":[[19.5,0]],"id":52385903}],"con":true,"img":false}]}
{"op":"mcm","clk":"11450840234","pt":1717325939000,"mc":[{"id":"1.229554932","rc":[{"atb":[[5.3,0],[4.7,27.03]],"id":52385909},{"atl":[[270,2],[290,0]],"id":52385909},{"atl":[[65,2],[75,0]],"id":52385934},{"atb":[[2.82,43.12],[2.86,53.76]],"id":52385903},{"atl":[[19,0],[20,4]],"id":52385903},{"atl":[[14.5,6.56],[15.5,0]],"id":52385888},{"atb":[[16,6.67],[19.5,0]],"id":52385936},{"atl":[[670,2],[680,0]],"id":52385936},{"atl":[[410,2],[420,0]],"id":52385931},{"atl":[[4.5,0],[4.7,14.28]],"id":52385884}],"con":true,"img":false}]}
{"op":"mcm","clk":"11450840344","pt":1717325940409,"mc":[{"id":"1.229554932","rc":[{"atl":[[440,0],[450,2]],"id":52385907},{"atl":[[710,2]],"id":52385920}],"con":true,"img":false}]}
{"op":"mcm","clk":"11450840354","pt":1717325940468,"mc":[{"id":"1.229554932","rc":[{"atl":[[700,0]],"id":52385920}],"con":true,"img":false}]}
{"op":"mcm","clk":"11450840464","pt":1717325941603,"mc":[{"id":"1.229554932","rc":[{"atb":[[8.4,3.32]],"id":52385909},{"atb":[[3.5,6.68]],"id":52385903},{"atl":[[4.8,5.4]],"id":52385903},{"atb":[[5.3,4.41]],"id":52385888},{"atl":[[8.8,3.45]],"id":52385888},{"atb":[[2.72,8.09]],"id":52385884},{"atl":[[3.85,6.38]],"id":52385884}],"con":true,"img":false}]}
{"op":"mcm","clk":"11450840522","pt":1717325942176,"mc":[{"id":"1.229554932","rc":[{"atb":[[17.5,0],[25,0]],"id":52385907},{"atb":[[340,0],[440,0]],"id":52385923},{"atb":[[5.6,0],[4.6,0]],"id":52385909},{"atb":[[5.6,0],[7.2,0]],"id":52385934},{"atb":[[17,6.54],[12,0]],"id":52385886},{"atb":[[2.38,0],[2.58,0]],"id":52385903},{"atb":[[3.6,0],[3.1,0]],"id":52385888},{"atb":[[40,0],[25,0]],"id":52385920},{"atb":[[5.2,0],[4.2,31.25]],"id":52385931},{"atb":[[2,0],[1.9,0]],"id":52385884},{"atb":[[17.5,0],[25,0]],"id":52385917}],"con":true,"img":false}]}
{"op":"mcm","clk":"11450840711","pt":1717325944100,"mc":[{"id":"1.229554932","rc":[{"atl":[[270,0],[260,2]],"id":52385909},{"atb":[[6.2,19.23],[7.4,0]],"id":52385934},{"atl":[[12.5,6.73],[14.5,0]],"id":52385888},{"atl":[[670,0],[650,2]],"id":52385936},{"atl":[[410,0],[400,2]],"id":52385931}],"con":true,"img":false}]}
{"op":"mcm","clk":"11450840731","pt":1717325944310,"mc":[{"id":"1.229554932","rc":[{"atb":[[3.5,0]],"id":52385903},{"atl":[[4.8,0]],"id":52385903},{"atb":[[5.3,0]],"id":52385888},{"atl":[[8.8,0]],"id":52385888},{"atb":[[2.72,0]],"id":52385884},{"atl":[[3.85,0]],"id":52385884}],"con":true,"img":false}]}
{"op":"mcm","clk":"11450840740","pt":1717325944371,"mc":[{"id":"1.229554932","rc":[{"atl":[[20,0],[21,5]],"id":52385903},{"atl":[[4.8,12.76],[4.7,0]],"id":52385884}],"con":true,"img":false}]}
{"op":"mcm","clk":"11450840801","pt":1717325944888,"mc":[{"id":"1.229554932","rc":[{"atb":[[32,0],[44,2.33]],"id":52385923},{"atb":[[7.6,15.15],[6.6,0]],"id":52385907},{"atb":[[5.5,22.22],[8.4,0],[4.7,0]],"id":52385909},{"atb":[[6.2,0],[7.6,15.15]],"id":52385934},{"atb":[[4.4,0],[5.4,22.73]],"id":52385886},{"atb":[[2.86,0],[3.1,35.42]],"id":52385903},{"atb":[[3.95,0],[4.2,55.77]],"id":52385888},{"atb":[[16,0],[18.5,5.71]],"id":52385936},{"atb":[[18,20.22],[13.5,0]],"id":52385920},{"atb":[[9.8,0],[13,8.33]],"id":52385917}],"con":true,"img":false}]}
{"op":"mcm","clk":"11450840958","pt":1717325946488,"mc":[{"id":"1.229554932","rc":[{"atl":[[320,0],[340,2]],"id":52385886},{"atl":[[700,2],[710,0]],"id":52385920},{"atl":[[610,0],[620,2]],"id":52385917}],"con":true,"img":false}]}
{"op":"mcm","clk":"11450840991","pt":1717325946901,"mc":[{"id":"1.229554932","rc":[{"atb":[[350,0.37],[250,1.3]],"id":52385923},{"atb":[[16.5,15.79],[23,4.77]],"id":52385907},{"atb":[[5.6,22.81],[4.6,68.03]],"id":52385909},{"atb":[[16,7],[11,24.48]],"id":52385886},{"atb":[[5.6,53.24],[7.2,16.92]],"id":52385934},{"atb":[[2.4,174.93],[2.6,65.6]],"id":52385903},{"atb":[[32,3.38],[21,12.24]],"id":52385920},{"atb":[[3.6,40.36],[3.1,116.62]],"id":52385888},{"atb":[[5.2,24.99],[4.2,107.78]],"id":52385931},{"atb":[[2,104.96],[1.9,272.13]],"id":52385884},{"atb":[[16,16.32],[22,4.99]],"id":52385917}],"con":true,"img":false}]}
{"op":"mcm","clk":"11450841093","pt":1717325947898,"mc":[{"id":"1.229554932","rc":[{"atl":[[320,2]],"id":52385886},{"atl":[[700,0],[710,2]],"id":52385920},{"atl":[[610,2]],"id":52385917}],"con":true,"img":false}]}
{"op":"mcm","clk":"11450841102","pt":1717325947998,"mc":[{"id":"1.229554932","rc":[{"atl":[[340,0]],"id":52385886},{"atl":[[620,0]],"id":52385917}],"con":true,"img":false}]}
{"op":"mcm","clk":"11450841180","pt":1717325948706,"mc":[{"id":"1.229554932","rc":[{"atl":[[320,0],[340,2]],"id":52385886},{"atl":[[700,2],[710,0]],"id":52385920},{"atl":[[610,0],[620,2]],"id":52385917}],"con":true,"img":false}]}
{"op":"mcm","clk":"11450841190","pt":1717325948810,"mc":[{"id":"1.229554932","rc":[{"atl":[[320,2],[340,0]],"id":52385886},{"atl":[[700,0],[710,2]],"id":52385920},{"atl":[[620,0],[610,2]],"id":52385917}],"con":true,"img":false}]}
{"op":"mcm","clk":"11450841215","pt":1717325949080,"mc":[{"id":"1.229554932","rc":[{"atl":[[260,0],[270,2]],"id":52385909},{"atl":[[320,0],[340,2]],"id":52385886},{"atl":[[700,2],[710,0]],"id":52385920},{"atl":[[610,0],[620,2]],"id":52385917}],"con":true,"img":false}]}
{"op":"mcm","clk":"11450841251","pt":1717325949488,"mc":[{"id":"1.229554932","rc":[{"atl":[[4.8,0],[4.7,9.52]],"id":52385884}],"con":true,"img":false}]}
{"op":"mcm","clk":"11450841413","pt":1717325951504,"mc":[{"id":"1.229554932","rc":[{"atb":[[8.4,3.32]],"id":52385909}],"con":true,"img":false}]}
{"op":"mcm","clk":"11450841463","pt":1717325951941,"mc":[{"id":"1.229554932","rc":[{"atl":[[710,2]],"id":52385920}],"con":true,"img":false}]}
{"op":"mcm","clk":"11450841485","pt":1717325952107,"mc":[{"id":"1.229554932","rc":[{"atl":[[700,0]],"id":52385920}],"con":true,"img":false}]}
{"op":"mcm","clk":"11450841739","pt":1717325954221,"mc":[{"id":"1.229554932","rc":[{"atl":[[270,0],[280,2]],"id":52385909},{"atl":[[320,2]],"id":52385886},{"atl":[[12.5,0],[14.5,7.41]],"id":52385888},{"atl":[[400,0],[410,2]],"id":52385931},{"atl":[[4.6,9.52],[4.7,0]],"id":52385884},{"atl":[[610,2]],"id":52385917}],"con":true,"img":false}]}
{"op":"mcm","clk":"11450841751","pt":1717325954281,"mc":[{"id":"1.229554932","rc":[{"atl":[[340,0]],"id":52385886},{"atl":[[620,0]],"id":52385917}],"con":true,"img":false}]}
{"op":"mcm","clk":"11450841814","pt":1717325954909,"mc":[{"id":"1.229554932","rc":[{"atl":[[440,2],[450,0]],"id":52385907}],"con":true,"img":false}]}
{"op":"mcm","clk":"11450842043","pt":1717325957432,"mc":[{"id":"1.229554932","rc":[{"atb":[[16.5,0],[23,0]],"id":52385907},{"atb":[[350,0.07],[250,0.31]],"id":52385923},{"atb":[[5.6,0],[4.6,0]],"id":52385909},{"atb":[[16,0],[11,0]],"id":52385886},{"atb":[[5.6,0],[7.2,0]],"id":52385934},{"atb":[[2.4,0],[2.6,0]],"id":52385903},{"atb":[[3.6,0],[3.1,0]],"id":52385888},{"atb":[[32,0],[21,0]],"id":52385920},{"atb":[[5.2,0],[4.2,31.25]],"id":52385931},{"atb":[[2,0],[1.9,0]],"id":52385884},{"atb":[[16,0],[22,0]],"id":52385917}],"con":true,"img":false}]}
{"op":"mcm","clk":"11450842064","pt":1717325957696,"mc":[{"id":"1.229554932","rc":[{"atl":[[440,0],[450,2]],"id":52385907}],"con":true,"img":false}]}
{"op":"mcm","clk":"11450842276","pt":1717325959996,"mc":[{"id":"1.229554932","rc":[{"atl":[[440,2]],"id":52385907},{"atl":[[320,0],[330,2]],"id":52385886},{"atl":[[700,2],[710,0]],"id":52385920}],"con":true,"img":false}]}
{"op":"mcm","clk":"11450842285","pt":1717325960092,"mc":[{"id":"1.229554932","rc":[{"atl":[[450,0]],"id":52385907}],"con":true,"img":false}]}
{"op":"mcm","clk":"11450842402","pt":1717325961391,"mc":[{"id":"1.229554932","rc":[{"atl":[[440,0],[450,2]],"id":52385907},{"atl":[[330,0],[320,2]],"id":52385886},{"atl":[[700,0],[710,2]],"id":52385920}],"con":true,"img":false}]}
{"op":"mcm","clk":"11450842636","pt":1717325964324,"mc":[{"id":"1.229554932","rc":[{"atb":[[16.5,15.79],[23,4.77]],"id":52385907},{"atb":[[300,0.52],[200,1.76]],"id":52385923},{"atb":[[4.4,72.03],[5.4,23.85]],"id":52385909},{"atb":[[16.5,6.76],[11.5,23.32]],"id":52385886},{"atb":[[5.3,56.95],[6.6,18.74]],"id":52385934},{"atb":[[2.64,64],[2.44,170.07]],"id":52385903},{"atb":[[34,3.18],[22,11.66]],"id":52385920},{"atb":[[3,122.45],[3.5,41.98]],"id":52385888},{"atb":[[4,81.63],[5,26.24]],"id":52385931},{"atb":[[2.12,93.71],[1.96,255.12]],"id":52385884},{"atb":[[16.5,15.79],[23,4.77]],"id":52385917}],"con":true,"img":false}]}
{"op":"mcm","clk":"11450842675","pt":1717325964803,"mc":[{"id":"1.229554932","rc":[{"atl":[[290,2]],"id":52385909}],"con":true,"img":false}]}
{"op":"mcm","clk":"11450842687","pt":1717325964904,"mc":[{"id":"1.229554932","rc":[{"atl":[[280,0]],"id":52385909}],"con":true,"img":false}]}
{"op":"mcm","clk":"11450842830","pt":1717325966559,"mc":[{"id":"1.229554932","rc":[{"atl":[[440,2],[450,0]],"id":52385907},{"atl":[[700,2],[710,0]],"id":52385920}],"con":true,"img":false}]}
{"op":"mcm","clk":"11450842837","pt":1717325966654,"mc":[{"id":"1.229554932","rc":[{"atl":[[610,0]],"id":52385917}],"con":true,"img":false}]}
{"op":"mcm","clk":"11450842844","pt":1717325966759,"mc":[{"id":"1.229554932","rc":[{"atl":[[330,2]],"id":52385886},{"atl":[[700,0],[690,2]],"id":52385920},{"atl":[[620,2]],"id":52385917}],"con":true,"img":false}]}
{"op":"mcm","clk":"11450842853","pt":1717325966862,"mc":[{"id":"1.229554932","rc":[{"atl":[[320,0]],"id":52385886},{"atl":[[690,0],[700,2]],"id":52385920},{"atl":[[620,0],[610,2]],"id":52385917}],"con":true,"img":false}]}
{"op":"mcm","clk":"11450842862","pt":1717325966966,"mc":[{"id":"1.229554932","rc":[{"atl":[[330,0],[320,2]],"id":52385886},{"atl":[[700,0],[690,2]],"id":52385920},{"atl":[[610,0],[620,2]],"id":52385917}],"con":true,"img":false}]}
{"op":"mcm","clk":"11450843112","pt":1717325969579,"mc":[{"id":"1.229554932","rc":[{"atl":[[700,2]],"id":52385920}],"con":true,"img":false}]}
{"op":"mcm","clk":"11450843123","pt":1717325969682,"mc":[{"id":"1.229554932","rc":[{"atl":[[690,0]],"id":52385920}],"con":true,"img":false}]}
{"op":"mcm","clk":"11450843367","pt":1717325972065,"mc":[{"id":"1.229554932","rc":[{"atl":[[610,2]],"id":52385917}],"con":true,"img":false}]}
{"op":"mcm","clk":"11450843382","pt":1717325972167,"mc":[{"id":"1.229554932","rc":[{"atl":[[620,0]],"id":52385917}],"con":true,"img":false}]}
{"op":"mcm","clk":"11450843403","pt":1717325972375,"mc":[{"id":"1.229554932","rc":[{"atb":[[16.5,0],[23,0]],"id":52385907},{"atb":[[300,0.17],[200,0.53]],"id":52385923},{"atb":[[4.4,0],[5.4,0]],"id":52385909},{"atb":[[16.5,0],[11.5,0]],"id":52385886},{"atb":[[5.3,0],[6.6,0]],"id":52385934},{"atb":[[2.64,0],[2.44,0]],"id":52385903},{"atb":[[34,0],[22,0]],"id":52385920},{"atb":[[3,0],[3.5,0]],"id":52385888},{"atb":[[4,0],[5,0]],"id":52385931},{"atb":[[2.12,0],[1.96,0]],"id":52385884},{"atb":[[16.5,0],[23,0]],"id":52385917}],"con":true,"img":false}]}
{"op":"mcm","clk":"11450843662","pt":1717325974774,"mc":[{"id":"1.229554932","rc":[{"atl":[[620,2]],"id":52385917}],"con":true,"img":false}]}
{"op":"mcm","clk":"11450843675","pt":1717325974878,"mc":[{"id":"1.229554932","rc":[{"atl":[[610,0]],"id":52385917}],"con":true,"img":false}]}
{"op":"mcm","clk":"11450843683","pt":1717325974982,"mc":[{"id":"1.229554932","rc":[{"atb":[[8.4,0]],"id":52385909}],"con":true,"img":false}]}
{"op":"mcm","clk":"11450843728","pt":1717325975295,"mc":[{"id":"1.229554932","rc":[{"atl":[[290,0],[300,2]],"id":52385909},{"atl":[[21,0],[22,4.76]],"id":52385903},{"atl":[[12.5,6.56],[14.5,0]],"id":52385888}],"con":true,"img":false}]}
{"op":"mcm","clk":"11450843741","pt":1717325975349,"mc":[{"id":"1.229554932","rc":[{"atl":[[4.5,9.52],[4.6,0]],"id":52385884}],"con":true,"img":false}]}
{"op":"mcm","clk":"11450843789","pt":1717325975763,"mc":[{"id":"1.229554932","rc":[{"atb":[[5.5,0],[6,20]],"id":52385909},{"atb":[[8.6,13.16],[7.6,0]],"id":52385934},{"atb":[[18.5,0],[22,4.76]],"id":52385936},{"atl":[[410,0],[420,2]],"id":52385931},{"atl":[[4.5,0],[4.2,4.76]],"id":52385884}],"con":true,"img":false}]}
{"op":"mcm","clk":"11450843942","pt":1717325977272,"mc":[{"id":"1.229554932","rc":[{"atb":[[18,14.4],[26,4.2]],"id":52385907},{"atb":[[290,0.84],[390,0.27]],"id":52385923},{"atb":[[4.4,72.03],[5.4,23.85]],"id":52385909},{"atb":[[5.3,56.95],[6.6,18.74]],"id":52385934},{"atb":[[17.5,6.36],[12.5,21.29]],"id":52385886},{"atb":[[2.64,64],[2.44,170.07]],"id":52385903},{"atb":[[3,122.45],[3.5,41.98]],"id":52385888},{"atb":[[42,2.55],[26,13.97]],"id":52385920},{"atb":[[4,81.63],[5,26.24]],"id":52385931},{"atb":[[1.95,257.8],[2.1,95.42]],"id":52385884},{"atb":[[17.5,14.84],[25,4.37]],"id":52385917}],"con":true,"img":false}]}
{"op":"mcm","clk":"11450844004","pt":1717325977898,"mc":[{"id":"1.229554932","rc":[{"atl":[[300,0],[320,2]],"id":52385909},{"atl":[[22,0],[24,4.35]],"id":52385903},{"atl":[[12.5,0],[14.5,7.41]],"id":52385888}],"con":true,"img":false}]}
{"op":"mcm","clk":"11450844258","pt":1717325980495,"mc":[{"id":"1.229554932","rc":[{"atl":[[310,2]],"id":52385909},{"atl":[[19.5,2.6]],"id":52385903}],"con":true,"img":false}]}
{"op":"mcm","clk":"11450844267","pt":1717325980599,"mc":[{"id":"1.229554932","rc":[{"atb":[[22,4.76],[7.6,0]],"id":52385907},{"atl":[[680,2],[440,0]],"id":52385907},{"atb":[[65,2],[44,0]],"id":52385923},{"atl":[[840,0]],"id":52385923},{"atl":[[320,0]],"id":52385909},{"atb":[[10.5,10.53],[5.4,0]],"id":52385886},{"atl":[[320,0],[490,2]],"id":52385886},{"atl":[[24,0]],"id":52385903},{"atl":[[10,3.28],[14.5,0]],"id":52385888},{"atb":[[18,14.34],[60,2]],"id":52385920},{"atl":[[700,0]],"id":52385920},{"atl":[[650,0]],"id":52385936},{"atb":[[13,0],[55,2]],"id":52385917},{"atl":[[620,0]],"id":52385917}],"con":true,"img":false}]}
{"op":"mcm","clk":"11450844297","pt":1717325980862,"mc":[{"id":"1.229554932","rc":[{"atb":[[22,0],[55,2]],"id":52385936},{"atl":[[400,2],[420,0]],"id":52385931}],"con":true,"img":false}]}
{"op":"mcm","clk":"11450844708","pt":1717325984874,"mc":[{"id":"1.229554932","rc":[{"atl":[[8.2,3.76]],"id":52385888}],"con":true,"img":false}]}
{"op":"mcm","clk":"11450844736","pt":1717325985181,"mc":[{"id":"1.229554932","rc":[{"atl":[[8.2,0]],"id":52385888}],"con":true,"img":false}]}
{"op":"mcm","clk":"11450844836","pt":1717325986075,"mc":[{"id":"1.229554932","rc":[{"atl":[[690,2]],"id":52385907},{"atl":[[490,0],[510,2]],"id":52385886}],"con":true,"img":false}]}
{"op":"mcm","clk":"11450844850","pt":1717325986180,"mc":[{"id":"1.229554932","rc":[{"atl":[[680,0]],"id":52385907}],"con":true,"img":false}]}
{"op":"mcm","clk":"11450844862","pt":1717325986278,"mc":[{"id":"1.229554932","rc":[{"atb":[[18,0],[26,0]],"id":52385907},{"atb":[[290,0],[390,0]],"id":52385923},{"atb":[[4.4,0],[5.4,0]],"id":52385909},{"atb":[[17.5,0],[12.5,0]],"id":52385886},{"atb":[[5.3,0],[6.6,0]],"id":52385934},{"atb":[[2.64,0],[2.44,0]],"id":52385903},{"atb":[[3,0],[3.5,0]],"id":52385888},{"atb":[[42,0],[26,4.18]],"id":52385920},{"atb":[[4,0],[5,0]],"id":52385931},{"atb":[[1.95,0],[2.1,0]],"id":52385884},{"atb":[[17.5,0],[25,0]],"id":52385917}],"con":true,"img":false}]}
{"op":"mcm","clk":"11450845403","pt":1717325991181,"mc":[{"id":"1.229554932","rc":[{"atl":[[690,0],[700,2]],"id":52385907},{"atl":[[19.5,0],[22,4.76]],"id":52385903},{"atl":[[390,2],[400,0]],"id":52385931}],"con":true,"img":false}]}
{"op":"mcm","clk":"11450845440","pt":1717325991489,"mc":[{"id":"1.229554932","rc":[{"atb":[[27,7.87]],"id":52385907},{"atl":[[710,2]],"id":52385907}],"con":true,"img":false}]}
{"op":"mcm","clk":"11450845446","pt":1717325991591,"mc":[{"id":"1.229554932","rc":[{"atb":[[22,0]],"id":52385907},{"atl":[[700,0]],"id":52385907}],"con":true,"img":false}]}
{"op":"mcm","clk":"11450845577","pt":1717325992997,"mc":[{"id":"1.229554932","rc":[{"atb":[[19.5,11.32],[14.5,36.2]],"id":52385907},{"atb":[[65,5.82],[130,0.81]],"id":52385923},{"atb":[[4.4,72.03],[5.4,23.85]],"id":52385909},{"atb":[[9.6,28.47],[14,8.07]],"id":52385886},{"atb":[[5.3,56.95],[6.6,18.74]],"id":52385934},{"atb":[[2.46,167.75],[2.66,63.23]],"id":52385903},{"atb":[[3,122.45],[3.5,41.98]],"id":52385888},{"atb":[[17.5,14.84],[25,4.37]],"id":52385920},{"atb":[[4,81.63],[5,26.24]],"id":52385931},{"atb":[[1.97,252.49],[2.14,306.02]],"id":52385884},{"atb":[[19,5.83],[14,18.83]],"id":52385917}],"con":true,"img":false}]}
{"op":"mcm","clk":"11450845936","pt":1717325996527,"mc":[{"id":"1.229554932","rc":[{"atl":[[720,2]],"id":52385907},{"atl":[[520,2],[510,0]],"id":52385886}],"con":true,"img":false}]}
{"op":"mcm","clk":"11450845948","pt":1717325996629,"mc":[{"id":"1.229554932","rc":[{"atl":[[710,0]],"id":52385907}],"con":true,"img":false}]}
{"op":"mcm","clk":"11450846103","pt":1717325998028,"mc":[{"id":"1.229554932","rc":[{"atl":[[8.2,3.76]],"id":52385888}],"con":true,"img":false}]}
{"op":"mcm","clk":"11450846216","pt":1717325999322,"mc":[{"id":"1.229554932","rc":[{"atb":[[19.5,5.65],[14.5,18.06]],"id":52385907},{"atb":[[130,0],[65,2]],"id":52385923},{"atb":[[4.4,0],[5.4,0]],"id":52385909},{"atb":[[9.6,0],[14,0]],"id":52385886},{"atb":[[5.3,0],[6.6,0]],"id":52385934},{"atb":[[2.46,0],[2.66,0]],"id":52385903},{"atb":[[3,0],[3.5,0]],"id":52385888},{"atb":[[17.5,0],[25,0]],"id":52385920},{"atb":[[4,0],[5,0]],"id":52385931},{"atb":[[1.97,0],[2.14,213.95]],"id":52385884},{"atb":[[19,0],[14,0]],"id":52385917}],"con":true,"img":false}]}
{"op":"mcm","clk":"11450846244","pt":1717325999632,"mc":[{"id":"1.229554932","rc":[{"atl":[[8.2,0]],"id":52385888}],"con":true,"img":false}]}
{"op":"mcm","clk":"11450846497","pt":1717326001625,"mc":[{"id":"1.229554932","rc":[{"atb":[[19.5,11.32],[14.5,36.2]],"id":52385907},{"atb":[[65,5.82],[130,0.81]],"id":52385923},{"atb":[[4.4,72.03],[5.4,23.85]],"id":52385909},{"atb":[[9.6,28.47],[14,8.07]],"id":52385886},{"atl":[[520,0],[510,2]],"id":52385886},{"atb":[[5.3,56.95],[6.6,18.74]],"id":52385934},{"atb":[[2.46,167.75],[2.66,63.23]],"id":52385903},{"atb":[[3,122.45],[3.5,41.98]],"id":52385888},{"atb":[[17.5,14.84],[25,4.37]],"id":52385920},{"atb":[[4,81.63],[5,26.24]],"id":52385931},{"atb":[[1.97,252.49],[2.14,306.02]],"id":52385884},{"atb":[[19,5.83],[14,18.83]],"id":52385917}],"con":true,"img":false}]}
{"op":"mcm","clk":"11450846510","pt":1717326001731,"mc":[{"id":"1.229554932","rc":[{"atb":[[27,4.02],[30,3.45]],"id":52385907},{"atl":[[720,0],[730,2]],"id":52385907},{"atl":[[520,2],[510,0]],"id":52385886}],"con":true,"img":false}]}
{"op":"mcm","clk":"11450847087","pt":1717326006648,"mc":[{"id":"1.229554932","rc":[{"atl":[[380,2],[390,0]],"id":52385931}],"con":true,"img":false}]}
{"op":"mcm","clk":"11450847474","pt":1717326010136,"mc":[{"id":"1.229554932","rc":[{"atb":[[19.5,5.65],[14.5,18.06]],"id":52385907},{"atb":[[130,0],[65,2]],"id":52385923},{"atb":[[4.4,0],[5.4,0]],"id":52385909},{"atb":[[9.6,0],[14,0]],"id":52385886},{"atb":[[5.3,0],[6.6,0]],"id":52385934},{"atb":[[2.46,0],[2.66,0]],"id":52385903},{"atb":[[17.5,0],[25,0]],"id":52385920},{"atb":[[3,0],[3.5,0]],"id":52385888},{"atb":[[4,0],[5,0]],"id":52385931},{"atb":[[1.97,0],[2.14,213.95]],"id":52385884},{"atb":[[19,0],[14,0]],"id":52385917}],"con":true,"img":false}]}
{"op":"mcm","clk":"11450847614","pt":1717326011845,"mc":[{"id":"1.229554932","rc":[{"atl":[[730,0],[740,2]],"id":52385907},{"atl":[[290,2],[310,0]],"id":52385909},{"atl":[[520,0],[530,2]],"id":52385886},{"atb":[[7.2,16.13],[8.6,0]],"id":52385934},{"atl":[[22,0],[23,4.55]],"id":52385903},{"atl":[[360,2],[380,0]],"id":52385931}],"con":true,"img":false}]}
{"op":"mcm","clk":"11450847690","pt":1717326012530,"mc":[{"id":"1.229554932","rc":[{"atb":[[10.5,25.78],[15.5,7.24]],"id":52385907},{"atb":[[5.6,22.81],[4.6,68.03]],"id":52385909},{"atb":[[9.8,11.92],[7.8,36.01]],"id":52385886},{"atb":[[2.46,167.75],[2.66,63.23]],"id":52385903},{"atb":[[3.15,113.91],[3.65,39.6]],"id":52385888},{"atb":[[1.98,249.91],[2.16,90.48]],"id":52385884}],"con":true,"img":false}]}
{"op":"mcm","clk":"11450847707","pt":1717326012628,"mc":[{"id":"1.229554932","rc":[{"atb":[[40,2.68],[25,10.2]],"id":52385923},{"atb":[[5.6,53.24],[7.2,33.05]],"id":52385934},{"atb":[[18.5,5.99],[13.5,19.59]],"id":52385920},{"atb":[[5.2,24.99],[4.2,107.78]],"id":52385931},{"atb":[[10,27.21],[15,24.91]],"id":52385917}],"con":true,"img":false}]}
{"op":"mcm","clk":"11450847737","pt":1717326012947,"mc":[{"id":"1.229554932","rc":[{"atl":[[8.2,3.76]],"id":52385888}],"con":true,"img":false}]}
{"op":"mcm","clk":"11450847761","pt":1717326013123,"mc":[{"id":"1.229554932","rc":[{"atl":[[8.2,0]],"id":52385888}],"con":true,"img":false}]}
{"op":"mcm","clk":"11450847903","pt":1717326014151,"mc":[{"id":"1.229554932","rc":[{"atb":[[4.9,5.34]],"id":52385888}],"con":true,"img":false}]}
{"op":"mcm","clk":"11450847927","pt":1717326014358,"mc":[{"id":"1.229554932","rc":[{"atb":[[4.9,0]],"id":52385888}],"con":true,"img":false}]}
{"op":"mcm","clk":"11450848194","pt":1717326017067,"mc":[{"id":"1.229554932","rc":[{"atl":[[280,2],[290,0]],"id":52385909},{"atl":[[65,0],[55,2]],"id":52385934},{"atl":[[530,0],[520,2]],"id":52385886},{"atl":[[23,0],[25,4.17]],"id":52385903},{"atb":[[3.8,35.71],[4.2,24.52]],"id":52385888},{"atl":[[1000,2]],"id":52385936},{"atl":[[330,2],[360,0]],"id":52385931}],"con":true,"img":false}]}
{"op":"mcm","clk":"11450848435","pt":1717326019311,"mc":[{"id":"1.229554932","rc":[{"atl":[[8.4,3.91]],"id":52385888}],"con":true,"img":false}]}
{"op":"mcm","clk":"11450848447","pt":1717326019416,"mc":[{"id":"1.229554932","rc":[{"atb":[[40,0],[25,0]],"id":52385923},{"atb":[[10.5,0],[15.5,0]],"id":52385907},{"atb":[[5.6,0],[4.6,0]],"id":52385909},{"atb":[[5.6,0],[7.2,16.13]],"id":52385934},{"atb":[[9.8,0],[7.8,0]],"id":52385886},{"atb":[[2.46,0],[2.66,0]],"id":52385903},{"atb":[[3.15,0],[3.65,0]],"id":52385888},{"atb":[[18.5,0],[13.5,0]],"id":52385920},{"atb":[[5.2,0],[4.2,31.25]],"id":52385931},{"atb":[[1.98,0],[2.16,0]],"id":52385884},{"atb":[[10,0],[15,17.42]],"id":52385917}],"con":true,"img":false}]}
{"op":"mcm","clk":"11450848548","pt":1717326020410,"mc":[{"id":"1.229554932","rc":[{"atb":[[4.9,5.34]],"id":52385888}],"con":true,"img":false}]}
{"op":"mcm","clk":"11450848566","pt":1717326020568,"mc":[{"id":"1.229554932","rc":[{"atl":[[8.4,0]],"id":52385888}],"con":true,"img":false}]}
{"op":"mcm","clk":"11450848680","pt":1717326021812,"mc":[{"id":"1.229554932","rc":[{"atb":[[10.5,25.78],[15.5,7.24]],"id":52385907},{"atb":[[5.7,22.33],[4.7,66.19]],"id":52385909},{"atb":[[9.8,11.92],[7.8,36.01]],"id":52385886},{"atb":[[2.46,167.75],[2.66,63.23]],"id":52385903},{"atb":[[3.15,113.91],[3.65,39.6]],"id":52385888},{"atb":[[1.97,252.49],[2.14,306.02]],"id":52385884}],"con":true,"img":false}]}
{"op":"mcm","clk":"11450848686","pt":1717326021865,"mc":[{"id":"1.229554932","rc":[{"atb":[[40,2.68],[25,10.2]],"id":52385923},{"atb":[[5.6,53.24],[7.2,33.05]],"id":52385934},{"atb":[[18.5,5.99],[13.5,19.59]],"id":52385920},{"atb":[[5.2,24.99],[4.2,107.78]],"id":52385931},{"atb":[[10,27.21],[15,24.91]],"id":52385917}],"con":true,"img":false}]}
{"op":"mcm","clk":"11450848702","pt":1717326022073,"mc":[{"id":"1.229554932","rc":[{"atl":[[520,0],[530,2]],"id":52385886},{"atl":[[25,0],[26,4]],"id":52385903}],"con":true,"img":false}]}
{"op":"mcm","clk":"11450848714","pt":1717326022179,"mc":[{"id":"1.229554932","rc":[{"atl":[[48,2.13],[55,0]],"id":52385934},{"atl":[[330,0],[320,2]],"id":52385931}],"con":true,"img":false}]}
{"op":"mcm","clk":"11450848898","pt":1717326024047,"mc":[{"id":"1.229554932","rc":[{"atb":[[34,5.41],[30,0]],"id":52385907}],"con":true,"img":false}]}
{"op":"mcm","clk":"11450848912","pt":1717326024103,"mc":[{"id":"1.229554932","rc":[{"atb":[[4.9,0]],"id":52385888}],"con":true,"img":false}]}
{"op":"mcm","clk":"11450848925","pt":1717326024208,"mc":[{"id":"1.229554932","rc":[{"atl":[[530,0],[540,2]],"id":52385886}],"con":true,"img":false}]}
{"op":"mcm","clk":"11450849252","pt":1717326027111,"mc":[{"id":"1.229554932","rc":[{"atl":[[750,2]],"id":52385907},{"atl":[[280,0],[300,2]],"id":52385909}],"con":true,"img":false}]}
{"op":"mcm","clk":"11450849263","pt":1717326027215,"mc":[{"id":"1.229554932","rc":[{"atl":[[740,0]],"id":52385907},{"atl":[[540,0],[530,2]],"id":52385886},{"atl":[[24,2.42],[26,0]],"id":52385903}],"con":true,"img":false}]}
{"op":"mcm","clk":"11450849952","pt":1717326033487,"mc":[{"id":"1.229554932","rc":[{"atb":[[2.56,13.78]],"id":52385884},{"trd":[[2.56,5.98]],"ltp":2.56,"tv":5.98,"id":52385884}],"con":true,"img":false}]}
{"op":"mcm","clk":"11450850260","pt":1717326036230,"mc":[{"id":"1.229554932","rc":[{"atb":[[10.5,0],[15.5,0]],"id":52385907},{"atb":[[40,0],[25,0]],"id":52385923},{"atb":[[5.7,0],[4.7,0]],"id":52385909},{"atb":[[9.8,0],[7.8,0]],"id":52385886},{"atb":[[5.6,0],[7.2,16.13]],"id":52385934},{"atb":[[2.46,0],[2.66,0]],"id":52385903},{"atb":[[3.15,0],[3.65,0]],"id":52385888},{"atb":[[18.5,0],[13.5,0]],"id":52385920},{"atb":[[5.2,0],[4.2,31.25]],"id":52385931},{"atb":[[1.97,0],[2.14,213.95]],"id":52385884},{"atb":[[10,0],[15,17.42]],"id":52385917}],"con":true,"img":false}]}
{"op":"mcm","clk":"11450850353","pt":1717326037330,"mc":[{"id":"1.229554932","rc":[{"atl":[[290,2]],"id":52385909},{"atl":[[25,4.17]],"id":52385903}],"con":true,"img":false}]}
{"op":"mcm","clk":"11450850365","pt":1717326037429,"mc":[{"id":"1.229554932","rc":[{"atb":[[34,2.38],[26,4]],"id":52385907},{"atl":[[710,2],[750,0]],"id":52385907},{"atl":[[300,0]],"id":52385909},{"atl":[[530,0],[500,2]],"id":52385886},{"atl":[[24,0]],"id":52385903}],"con":true,"img":false}]}
{"op":"mcm","clk":"11450850895","pt":1717326042520,"mc":[{"id":"1.229554932","rc":[{"atb":[[10.5,25.78],[15.5,7.24]],"id":52385907},{"atl":[[690,2]],"id":52385907},{"atb":[[36,2.99],[23,11.13]],"id":52385923},{"atb":[[4.5,69.97],[5.5,23.32]],"id":52385909},{"atb":[[9.8,11.92],[7.8,36.01]],"id":52385886},{"atb":[[6.8,18.09],[5.4,55.66]],"id":52385934},{"atb":[[2.72,121.86],[2.52,161.12]],"id":52385903},{"atl":[[22,2.51],[25,0]],"id":52385903},{"atb":[[18.5,5.99],[13.5,19.59]],"id":52385920},{"atb":[[4,33.33],[3.8,0],[3.55,41.16],[3.05,119.47]],"id":52385888},{"atb":[[4,81.63],[5,26.24]],"id":52385931},{"atl":[[320,0],[340,2]],"id":52385931},{"atb":[[2.24,84.64],[2.04,235.49]],"id":52385884},{"atb":[[10,27.21],[15,24.91]],"id":52385917}],"con":true,"img":false}]}
{"op":"mcm","clk":"11450850906","pt":1717326042625,"mc":[{"id":"1.229554932","rc":[{"atl":[[710,0]],"id":52385907}],"con":true,"img":false}]}
{"op":"mcm","clk":"11450851005","pt":1717326043524,"mc":[{"id":"1.229554932","rc":[{"atb":[[4.9,5.34]],"id":52385888}],"con":true,"img":false}]}
{"op":"mcm","clk":"11450851283","pt":1717326046537,"mc":[{"id":"1.229554932","rc":[{"atl":[[60,2]],"id":52385934}],"con":true,"img":false}]}
{"op":"mcm","clk":"11450851289","pt":1717326046641,"mc":[{"id":"1.229554932","rc":[{"atl":[[48,0]],"id":52385934}],"con":true,"img":false}]}
{"op":"mcm","clk":"11450851388","pt":1717326047523,"mc":[{"id":"1.229554932","rc":[{"atl":[[710,2]],"id":52385907},{"atl":[[520,2]],"id":52385886}],"con":true,"img":false}]}
{"op":"mcm","clk":"11450851396","pt":1717326047624,"mc":[{"id":"1.229554932","rc":[{"atl":[[690,0]],"id":52385907},{"atl":[[280,2],[290,0]],"id":52385909},{"atl":[[500,0]],"id":52385886},{"atl":[[330,2],[340,0]],"id":52385931}],"con":true,"img":false}]}
{"op":"mcm","clk":"11450851571","pt":1717326049544,"mc":[{"id":"1.229554932","rc":[{"atb":[[10.5,0],[15.5,0]],"id":52385907},{"atb":[[36,0],[23,0]],"id":52385923},{"atb":[[4.5,0],[5.5,0]],"id":52385909},{"atb":[[9.8,0],[7.8,0]],"id":52385886},{"atb":[[6.8,0],[5.4,0]],"id":52385934},{"atb":[[2.72,60.84],[2.52,0]],"id":52385903},{"atb":[[3.55,0],[3.05,0]],"id":52385888},{"atb":[[18.5,0],[13.5,0]],"id":52385920},{"atb":[[4,0],[5,0]],"id":52385931},{"atb":[[2.24,0],[2.04,0]],"id":52385884},{"atb":[[10,0],[15,17.42]],"id":52385917}],"con":true,"img":false}]}
{"op":"mcm","clk":"11450851901","pt":1717326052927,"mc":[{"id":"1.229554932","rc":[{"atl":[[700,2],[710,0]],"id":52385907},{"atl":[[21,2],[22,0]],"id":52385903},{"atl":[[330,0],[340,2]],"id":52385931}],"con":true,"img":false}]}
{"op":"mcm","clk":"11450851936","pt":1717326053349,"mc":[{"id":"1.229554932","rc":[{"atb":[[16,7],[11,24.48]],"id":52385907},{"atb":[[36,2.99],[23,11.13]],"id":52385923},{"atb":[[5.6,22.81],[4.6,68.03]],"id":52385909},{"atb":[[6.8,18.09],[5.4,55.66]],"id":52385934},{"atb":[[9.8,11.92],[7.8,36.01]],"id":52385886},{"atb":[[2.54,159.03],[2.74,60.32]],"id":52385903},{"atb":[[3.45,85.5],[2.98,246.87]],"id":52385888},{"atb":[[18.5,5.99],[13.5,19.59]],"id":52385920},{"atb":[[4,81.63],[5,26.24]],"id":52385931},{"atb":[[2.24,84.64],[2.04,235.49]],"id":52385884},{"atb":[[10,27.21],[15,24.91]],"id":52385917}],"con":true,"img":false}]}
{"op":"mcm","clk":"11450852402","pt":1717326057947,"mc":[{"id":"1.229554932","rc":[{"atl":[[520,0],[510,2]],"id":52385886}],"con":true,"img":false}]}
{"op":"mcm","clk":"11450852412","pt":1717326058052,"mc":[{"id":"1.229554932","rc":[{"atl":[[700,0],[690,2]],"id":52385907},{"atl":[[340,0],[350,2]],"id":52385931}],"con":true,"img":false}]}
{"op":"mcm","clk":"11450852640","pt":1717326060146,"mc":[{"id":"1.229554932","rc":[{"atb":[[4.9,0]],"id":52385888}],"con":true,"img":false}]}
{"op":"mcm","clk":"11450852680","pt":1717326060571,"mc":[{"id":"1.229554932","rc":[{"atb":[[16,0],[11,0]],"id":52385907},{"atb":[[36,0],[23,0]],"id":52385923},{"atb":[[5.6,0],[4.6,0]],"id":52385909},{"atb":[[9.8,0],[7.8,0]],"id":52385886},{"atb":[[6.8,0],[5.4,0]],"id":52385934},{"atb":[[2.54,0],[2.74,0]],"id":52385903},{"atb":[[3.45,42.66],[2.98,123.18]],"id":52385888},{"atb":[[18.5,0],[13.5,0]],"id":52385920},{"atb":[[4,0],[5,0]],"id":52385931},{"atb":[[2.24,0],[2.04,0]],"id":52385884},{"atb":[[10,0],[15,17.42]],"id":52385917}],"con":true,"img":false}]}
{"op":"mcm","clk":"11450852741","pt":1717326061250,"mc":[{"id":"1.229554932","rc":[{"atb":[[4.9,5.34]],"id":52385888}],"con":true,"img":false}]}
{"op":"mcm","clk":"11450852783","pt":1717326061618,"mc":[{"id":"1.229554932","rc":[{"atl":[[690,0],[700,2]],"id":52385907},{"atl":[[280,0],[290,2]],"id":52385909},{"atl":[[520,2],[510,0]],"id":52385886},{"atl":[[21,0],[23,4]],"id":52385903},{"atb":[[4,0],[4.9,0],[4.2,55.77]],"id":52385888},{"atl":[[350,0],[370,2]],"id":52385931}],"con":true,"img":false}]}
{"op":"mcm","clk":"11450853037","pt":1717326064226,"mc":[{"id":"1.229554932","rc":[{"atb":[[10.5,25.78],[15.5,7.24]],"id":52385907},{"atb":[[40,2.68],[25,10.2]],"id":52385923},{"atb":[[4.8,64.45],[5.8,21.86]],"id":52385909},{"atb":[[9.6,12.2],[7.6,37.1]],"id":52385886},{"atb":[[7.4,16.4],[5.7,74.34]],"id":52385934},{"atb":[[2.5,325.88],[2.7,123.23]],"id":52385903},{"atb":[[3.55,41.16],[3.05,119.47]],"id":52385888},{"atb":[[18.5,5.99],[13.5,19.59]],"id":52385920},{"atb":[[5.2,24.99],[4.2,107.78]],"id":52385931},{"atb":[[1.97,252.49],[2.14,306.02]],"id":52385884},{"atb":[[10,27.21],[15,24.91]],"id":52385917}],"con":true,"img":false}]}
{"op":"mcm","clk":"11450853463","pt":1717326068336,"mc":[{"id":"1.229554932","rc":[{"atb":[[26,0]],"id":52385907},{"atl":[[700,0],[680,2]],"id":52385907},{"atl":[[290,0],[300,2]],"id":52385909},{"atl":[[520,0],[500,2]],"id":52385886},{"atl":[[10,0],[10.5,9.84]],"id":52385888},{"atl":[[370,0],[380,2]],"id":52385931}],"con":true,"img":false}]}
{"op":"mcm","clk":"11450853472","pt":1717326068440,"mc":[{"id":"1.229554932","rc":[{"atb":[[21,5]],"id":52385907},{"atl":[[1000,4.62]],"id":52385936},{"atl":[[1000,3.52]],"id":52385884}],"con":true,"img":false}]}
{"op":"mcm","clk":"11450853603","pt":1717326069537,"mc":[{"id":"1.229554932","rc":[{"atl":[[1000,2]],"id":52385936},{"atl":[[1000,0.9]],"id":52385884}],"con":true,"img":false}]}
{"op":"mcm","clk":"11450853727","pt":1717326070575,"mc":[{"id":"1.229554932","rc":[{"atl":[[1000,2]],"id":52385936},{"atl":[[1000,0.85]],"id":52385884}],"con":true,"img":false}]}
{"op":"mcm","clk":"11450853735","pt":1717326070632,"mc":[{"id":"1.229554932","rc":[{"atb":[[170,0.15]],"id":52385936},{"trd":[[170,0.01]],"ltp":170.0,"tv":0.01,"id":52385936},{"atb":[[2.56,13.72]],"id":52385884},{"trd":[[2.56,6.1]],"ltp":2.56,"tv":6.1,"id":52385884}],"con":true,"img":false}]}
{"op":"mcm","clk":"11450853789","pt":1717326071149,"mc":[{"id":"1.229554932","rc":[{"atl":[[510,2]],"id":52385886}],"con":true,"img":false}]}
{"op":"mcm","clk":"11450853796","pt":1717326071251,"mc":[{"id":"1.229554932","rc":[{"atl":[[500,0]],"id":52385886}],"con":true,"img":false}]}
{"op":"mcm","clk":"11450853888","pt":1717326072035,"mc":[{"id":"1.229554932","rc":[{"atb":[[10.5,0],[15.5,0]],"id":52385907},{"atb":[[40,0],[25,0]],"id":52385923},{"atb":[[4.8,0],[5.8,0]],"id":52385909},{"atb":[[9.6,0],[7.6,0]],"id":52385886},{"atb":[[7.4,0],[5.7,22.24]],"id":52385934},{"atb":[[2.5,162.6],[2.7,61.48]],"id":52385903},{"atb":[[3.55,0],[3.05,0]],"id":52385888},{"atb":[[18.5,0],[13.5,0]],"id":52385920},{"atb":[[5.2,0],[4.2,31.25]],"id":52385931},{"atb":[[1.97,0],[2.14,213.95]],"id":52385884},{"atb":[[10,0],[15,17.42]],"id":52385917}],"con":true,"img":false}]}
{"op":"mcm","clk":"11450854038","pt":1717326073347,"mc":[{"id":"1.229554932","rc":[{"atl":[[300,0],[310,2]],"id":52385909},{"atb":[[7.2,0],[8.2,13.89]],"id":52385934},{"atl":[[22,2.42],[23,0]],"id":52385903},{"atl":[[1000,0]],"id":52385936},{"atl":[[380,0],[400,2]],"id":52385931}],"con":true,"img":false}]}
{"op":"mcm","clk":"11450854247","pt":1717326075224,"mc":[{"id":"1.229554932","rc":[{"atb":[[1.02,5000]],"id":52385923},{"atb":[[1.02,5155.94]],"id":52385907},{"atb":[[1.02,5008.58]],"id":52385909},{"atb":[[1.02,5008.58]],"id":52385934},{"atb":[[1.02,5008.58]],"id":52385886},{"atb":[[1.02,5008.58]],"id":52385903},{"atb":[[1.02,5000]],"id":52385936},{"atb":[[1.02,5000]],"id":52385920},{"atb":[[1.02,5000]],"id":52385888},{"atb":[[1.02,5115.89]],"id":52385931},{"atb":[[1.02,5096.29]],"id":52385884},{"atb":[[1.02,5008.58]],"id":52385917}],"con":true,"img":false}]}
{"op":"mcm","clk":"11450854314","pt":1717326075801,"mc":[{"id":"1.229554932","rc":[{"atb":[[10.5,25.78],[15.5,7.24]],"id":52385907},{"atb":[[40,2.68],[25,10.2]],"id":52385923},{"atb":[[4.8,64.45],[5.8,21.86]],"id":52385909},{"atb":[[9.6,12.2],[7.6,37.1]],"id":52385886},{"atb":[[7.4,16.4],[5.7,74.34]],"id":52385934},{"atb":[[2.5,325.88],[2.7,123.23]],"id":52385903},{"atb":[[3.55,41.16],[3.05,119.47]],"id":52385888},{"atb":[[18.5,5.99],[13.5,19.59]],"id":52385920},{"atb":[[5.2,24.99],[4.2,107.78]],"id":52385931},{"atb":[[1.97,252.49],[2.14,306.02]],"id":52385884},{"atb":[[10,27.21],[15,24.91]],"id":52385917}],"con":true,"img":false}]}
{"op":"mcm","clk":"11450854437","pt":1717326076881,"mc":[{"id":"1.229554932","rc":[{"atl":[[300,2],[310,0]],"id":52385909}],"con":true,"img":false}]}
{"op":"mcm","clk":"11450854599","pt":1717326078398,"mc":[{"id":"1.229554932","rc":[{"atl":[[680,0],[690,2]],"id":52385907},{"atl":[[300,0],[310,2]],"id":52385909},{"atl":[[22,0],[23,4.55]],"id":52385903}],"con":true,"img":false}]}
{"op":"mcm","clk":"11450855017","pt":1717326082790,"mc":[{"id":"1.229554932","rc":[{"atb":[[10.5,0],[15.5,0]],"id":52385907},{"atb":[[40,0],[25,0]],"id":52385923},{"atb":[[4.8,0],[5.8,0]],"id":52385909},{"atb":[[9.6,0],[7.6,0]],"id":52385886},{"atb":[[7.4,0],[5.7,22.24]],"id":52385934},{"atb":[[2.5,162.6],[2.7,61.48]],"id":52385903},{"atb":[[18.5,0],[13.5,0]],"id":52385920},{"atb":[[3.55,0],[3.05,0]],"id":52385888},{"atb":[[5.2,0],[4.2,31.25]],"id":52385931},{"atb":[[1.97,0],[2.14,213.95]],"id":52385884},{"atb":[[10,0],[15,17.42]],"id":52385917}],"con":true,"img":false}]}
{"op":"mcm","clk":"11450855145","pt":1717326083936,"mc":[{"id":"1.229554932","rc":[{"atl":[[310,0],[320,2]],"id":52385909},{"atl":[[23,0],[24,4.35]],"id":52385903},{"atl":[[390,2],[400,0]],"id":52385931}],"con":true,"img":false}]}
{"op":"mcm","clk":"11450855154","pt":1717326084033,"mc":[{"id":"1.229554932","rc":[{"atl":[[310,2],[320,0]],"id":52385909},{"atl":[[23,2.7],[24,0]],"id":52385903}],"con":true,"img":false}]}
{"op":"mcm","clk":"11450855484","pt":1717326087309,"mc":[{"id":"1.229554932","rc":[{"atb":[[16,7],[11,24.48]],"id":52385907},{"atb":[[36,2.99],[23,11.13]],"id":52385923},{"atb":[[5.6,22.81],[4.6,68.03]],"id":52385909},{"atb":[[6.8,18.09],[5.4,55.66]],"id":52385934},{"atb":[[9.8,11.92],[7.8,36.01]],"id":52385886},{"atb":[[2.54,159.03],[2.74,60.32]],"id":52385903},{"atb":[[3.45,85.5],[2.98,246.87]],"id":52385888},{"atb":[[18.5,5.99],[13.5,19.59]],"id":52385920},{"atb":[[4,81.63],[5,26.24]],"id":52385931},{"atb":[[2.24,84.64],[2.04,235.49]],"id":52385884},{"atb":[[10,27.21],[15,24.91]],"id":52385917}],"con":true,"img":false}]}
{"op":"mcm","clk":"11450855619","pt":1717326088606,"mc":[{"id":"1.229554932","rc":[{"atl":[[690,0],[680,2]],"id":52385907},{"atl":[[310,0],[320,2]],"id":52385909},{"atl":[[510,0],[500,2]],"id":52385886},{"atl":[[390,0],[400,2]],"id":52385931}],"con":true,"img":false}]}
{"op":"mcm","clk":"11450855820","pt":1717326090537,"mc":[{"id":"1.229554932","rc":[{"atb":[[2.56,0]],"id":52385884},{"trd":[[2.56,33.54]],"ltp":2.56,"tv":33.54,"id":52385884},{"atl":[[2.56,10.86]],"id":52385884}],"con":true,"img":false}]}
{"op":"mcm","clk":"11450855830","pt":1717326090641,"mc":[{"id":"1.229554932","rc":[{"trd":[[2.56,55.28]],"ltp":2.56,"tv":55.28,"id":52385884},{"atl":[[2.56,0],[2.92,21.74]],"id":52385884}],"con":true,"img":false}]}
{"op":"mcm","clk":"11450855843","pt":1717326090739,"mc":[{"id":"1.229554932","rc":[{"atb":[[65,0]],"id":52385923},{"atb":[[5.1,24.39],[6,0]],"id":52385909},{"atb":[[10.5,0],[8.8,12.82]],"id":52385886},{"atb":[[3.1,0],[2.98,48.19]],"id":52385903},{"atb":[[3.6,38.46],[4.2,24.52]],"id":52385888},{"atb":[[60,0]],"id":52385920},{"atb":[[55,0]],"id":52385936},{"atl":[[4.2,0]],"id":52385884},{"atb":[[55,0]],"id":52385917}],"con":true,"img":false}]}
{"op":"mcm","clk":"11450855854","pt":1717326090842,"mc":[{"id":"1.229554932","rc":[{"atb":[[65,2]],"id":52385923},{"atl":[[680,0],[750,2]],"id":52385907},{"atb":[[5.1,0],[6,20]],"id":52385909},{"atl":[[320,0],[360,2]],"id":52385909},{"atb":[[10.5,10.53],[8.8,0]],"id":52385886},{"atl":[[520,2],[500,0]],"id":52385886},{"atl":[[90,2],[60,0]],"id":52385934},{"atb":[[3.1,35.42],[2.98,0]],"id":52385903},{"atl":[[23,0],[27,3.85]],"id":52385903},{"atb":[[55,2]],"id":52385936},{"atb":[[3.6,0],[4.1,32.26]],"id":52385888},{"atl":[[10.5,3.28],[11,10]],"id":52385888},{"atb":[[60,2]],"id":52385920},{"atl":[[400,0],[420,2]],"id":52385931},{"atl":[[2.92,0],[4.2,31.25]],"id":52385884},{"atb":[[55,2]],"id":52385917}],"con":true,"img":false}]}
{"op":"mcm","clk":"11450855903","pt":1717326091217,"mc":[{"id":"1.229554932","rc":[{"atb":[[3.1,36.28]],"id":52385903},{"atb":[[38,0.87]],"id":52385936},{"atb":[[2.48,0.86]],"id":52385884},{"atb":[[20,6.42]],"id":52385917}],"con":true,"img":false}]}
{"op":"mcm","clk":"11450855925","pt":1717326091421,"mc":[{"id":"1.229554932","rc":[{"atb":[[17,6.25],[21,0]],"id":52385907},{"atb":[[65,0]],"id":52385923},{"atb":[[5,51.13],[6,0]],"id":52385909},{"atb":[[8.2,0],[7,16.67]],"id":52385934},{"atb":[[10.5,0],[8.2,13.89]],"id":52385886},{"atb":[[3.1,0.86],[2.96,49.06]],"id":52385903},{"atb":[[55,0]],"id":52385936},{"atb":[[4.1,0],[3.55,39.22]],"id":52385888},{"atb":[[60,0]],"id":52385920},{"atb":[[55,0]],"id":52385917}],"con":true,"img":false}]}
{"op":"mcm","clk":"11450855936","pt":1717326091518,"mc":[{"id":"1.229554932","rc":[{"atb":[[50,7.01]],"id":52385923},{"atb":[[44,2.33]],"id":52385936},{"atb":[[46,2.22]],"id":52385920},{"atb":[[44,2.33]],"id":52385917}],"con":true,"img":false}]}
{"op":"mcm","clk":"11450855956","pt":1717326091727,"mc":[{"id":"1.229554932","rc":[{"atl":[[1000,0.78]],"id":52385923},{"atl":[[1000,0.78]],"id":52385920},{"atb":[[4.9,5.34]],"id":52385888},{"atl":[[10.5,4.06]],"id":52385888},{"atl":[[1000,0.78]],"id":52385917}],"con":true,"img":false}]}
{"op":"mcm","clk":"11450855966","pt":1717326091832,"mc":[{"id":"1.229554932","rc":[{"atb":[[50,7.91]],"id":52385923},{"atb":[[9,3.49]],"id":52385909},{"atb":[[3.1,0.85]],"id":52385903},{"atb":[[2.48,1.71]],"id":52385884},{"atl":[[3.25,7.2]],"id":52385884}],"con":true,"img":false}]}
{"op":"mcm","clk":"11450855975","pt":1717326091939,"mc":[{"id":"1.229554932","rc":[{"atb":[[3.05,13.63]],"id":52385903}],"con":true,"img":false}]}
{"op":"mcm","clk":"11450855982","pt":1717326092039,"mc":[{"id":"1.229554932","rc":[{"atb":[[44,0],[55,2]],"id":52385917}],"con":true,"img":false}]}
{"op":"mcm","clk":"11450855990","pt":1717326092139,"mc":[{"id":"1.229554932","rc":[{"atl":[[26,2.35],[27,0]],"id":52385903}],"con":true,"img":false}]}
{"op":"mcm","clk":"11450856016","pt":1717326092407,"mc":[{"id":"1.229554932","rc":[{"atl":[[1000,0.32]],"id":52385923},{"atl":[[10.5,3.6]],"id":52385888},{"atl":[[1000,0.28]],"id":52385920},{"atl":[[1000,0.29]],"id":52385917}],"con":true,"img":false}]}
{"op":"mcm","clk":"11450856031","pt":1717326092511,"mc":[{"id":"1.229554932","rc":[{"atb":[[3.1,0.69]],"id":52385903},{"atb":[[2.48,1.53]],"id":52385884}],"con":true,"img":false}]}
{"op":"mcm","clk":"11450856094","pt":1717326093125,"mc":[{"id":"1.229554932","rc":[{"atl":[[70,2]],"id":52385934},{"atl":[[22,2],[26,0]],"id":52385903},{"atl":[[10,3.6],[11,0]],"id":52385888},{"atl":[[1000,2.29]],"id":52385917}],"con":true,"img":false}]}
{"op":"mcm","clk":"11450856105","pt":1717326093235,"mc":[{"id":"1.229554932","rc":[{"atl":[[90,0]],"id":52385934}],"con":true,"img":false}]}
{"op":"mcm","clk":"11450856148","pt":1717326093706,"mc":[{"id":"1.229554932","rc":[{"atl":[[690,2],[750,0]],"id":52385907},{"atl":[[320,2],[360,0]],"id":52385909},{"atl":[[500,2]],"id":52385886},{"atl":[[400,2],[420,0]],"id":52385931},{"atl":[[1000,0.29]],"id":52385917}],"con":true,"img":false}]}
{"op":"mcm","clk":"11450856156","pt":1717326093808,"mc":[{"id":"1.229554932","rc":[{"atl":[[520,0]],"id":52385886}],"con":true,"img":false}]}
{"op":"mcm","clk":"11450856166","pt":1717326093910,"mc":[{"id":"1.229554932","rc":[{"atb":[[2.48,1.49]],"id":52385884}],"con":true,"img":false}]}
{"op":"mcm","clk":"11450856237","pt":1717326094744,"mc":[{"id":"1.229554932","rc":[{"atl":[[3.25,0]],"id":52385884}],"con":true,"img":false}]}
{"op":"mcm","clk":"11450856342","pt":1717326095724,"mc":[{"id":"1.229554932","rc":[{"atb":[[9,0]],"id":52385909}],"con":true,"img":false}]}
{"op":"mcm","clk":"11450856362","pt":1717326095929,"mc":[{"id":"1.229554932","rc":[{"atb":[[3.1,1.54]],"id":52385903},{"atb":[[4.9,0]],"id":52385888},{"atb":[[2.48,2.35]],"id":52385884}],"con":true,"img":false}]}
{"op":"mcm","clk":"11450856428","pt":1717326096549,"mc":[{"id":"1.229554932","rc":[{"atb":[[17,0],[23,4.55]],"id":52385907},{"atb":[[5,26.13],[5.9,20.41]],"id":52385909},{"atb":[[10.5,10.53],[8.2,0]],"id":52385886},{"atb":[[8.6,13.16],[7,0]],"id":52385934},{"atb":[[3.1,15.17],[2.96,0]],"id":52385903},{"atb":[[4.1,32.26],[3.55,0]],"id":52385888}],"con":true,"img":false}]}
{"op":"mcm","clk":"11450856471","pt":1717326096912,"mc":[{"id":"1.229554932","rc":[{"atb":[[3.05,12.76]],"id":52385903}],"con":true,"img":false}]}
{"op":"mcm","clk":"11450856479","pt":1717326097015,"mc":[{"id":"1.229554932","rc":[{"atb":[[3.1,16.04]],"id":52385903}],"con":true,"img":false}]}
{"op":"mcm","clk":"11450856562","pt":1717326097844,"mc":[{"id":"1.229554932","rc":[{"atl":[[3.1,7.46]],"id":52385884}],"con":true,"img":false}]}
{"op":"mcm","clk":"11450856606","pt":1717326098256,"mc":[{"id":"1.229554932","rc":[{"atl":[[21,2],[22,0]],"id":52385903}],"con":true,"img":false}]}
{"op":"mcm","clk":"11450856623","pt":1717326098414,"mc":[{"id":"1.229554932","rc":[{"atb":[[3.1,15.47]],"id":52385903},{"atb":[[2.48,1.75]],"id":52385884}],"con":true,"img":false}]}
{"op":"mcm","clk":"11450856649","pt":1717326098730,"mc":[{"id":"1.229554932","rc":[{"atl":[[690,0],[680,2]],"id":52385907},{"atl":[[310,2],[320,0]],"id":52385909},{"atl":[[20,2],[21,0]],"id":52385903},{"atl":[[400,0],[410,2]],"id":52385931}],"con":true,"img":false}]}
{"op":"mcm","clk":"11450856663","pt":1717326098838,"mc":[{"id":"1.229554932","rc":[{"atl":[[3.1,0]],"id":52385884}],"con":true,"img":false}]}
{"op":"mcm","clk":"11450857055","pt":1717326102561,"mc":[{"id":"1.229554932","rc":[{"atb":[[16,0],[11,0]],"id":52385907},{"atb":[[36,0],[23,0]],"id":52385923},{"atb":[[5.6,0],[4.6,0]],"id":52385909},{"atb":[[9.8,0],[7.8,0]],"id":52385886},{"atb":[[6.8,0],[5.4,0]],"id":52385934},{"atb":[[2.54,0],[2.74,0]],"id":52385903},{"atb":[[3.45,42.66],[2.98,123.18]],"id":52385888},{"atb":[[18.5,0],[13.5,0]],"id":52385920},{"atb":[[4,0],[5,0]],"id":52385931},{"atb":[[2.24,0],[2.04,0]],"id":52385884},{"atb":[[10,0],[15,17.42]],"id":52385917}],"con":true,"img":false}]}
{"op":"mcm","clk":"11450857184","pt":1717326103857,"mc":[{"id":"1.229554932","rc":[{"atl":[[660,2],[680,0]],"id":52385907},{"atl":[[490,2],[500,0]],"id":52385886},{"atl":[[19.5,2]],"id":52385903},{"atl":[[10,0],[10.5,10.8]],"id":52385888}],"con":true,"img":false}]}
{"op":"mcm","clk":"11450857195","pt":1717326103958,"mc":[{"id":"1.229554932","rc":[{"atl":[[20,0]],"id":52385903}],"con":true,"img":false}]}
{"op":"mcm","clk":"11450857232","pt":1717326104326,"mc":[{"id":"1.229554932","rc":[{"atl":[[10.5,10.48]],"id":52385888}],"con":true,"img":false}]}
{"op":"mcm","clk":"11450857241","pt":1717326104435,"mc":[{"id":"1.229554932","rc":[{"atl":[[1000,1.17]],"id":52385888}],"con":true,"img":false}]}
{"op":"mcm","clk":"11450857282","pt":1717326104857,"mc":[{"id":"1.229554932","rc":[{"atl":[[310,0],[320,2]],"id":52385909},{"atb":[[9.2,12.2]],"id":52385934},{"atb":[[3.1,1.84],[3.05,48.18]],"id":52385903},{"atl":[[410,0],[420,2]],"id":52385931}],"con":true,"img":false}]}
{"op":"mcm","clk":"11450857290","pt":1717326104953,"mc":[{"id":"1.229554932","rc":[{"atb":[[8.6,0]],"id":52385934}],"con":true,"img":false}]}
{"op":"mcm","clk":"11450857312","pt":1717326105262,"mc":[{"id":"1.229554932","rc":[{"atb":[[13.5,19]],"id":52385907},{"atb":[[20,12]],"id":52385923},{"atb":[[5.2,48]],"id":52385909},{"atb":[[6.8,37]],"id":52385934},{"atb":[[9.6,26]],"id":52385886},{"atb":[[3.1,0.97],[2.6,96]],"id":52385903},{"atb":[[3.3,76]],"id":52385888},{"atb":[[19,13]],"id":52385920},{"atb":[[22,11]],"id":52385936},{"atb":[[5.6,45]],"id":52385931},{"atb":[[2.04,123]],"id":52385884},{"atl":[[10.5,12]],"id":52385884},{"atb":[[19,13]],"id":52385917}],"con":true,"img":false}]}
{"op":"mcm","clk":"11450857322","pt":1717326105365,"mc":[{"id":"1.229554932","rc":[{"atb":[[3.05,49.05]],"id":52385903}],"con":true,"img":false}]}
{"op":"mcm","clk":"11450857386","pt":1717326105936,"mc":[{"id":"1.229554932","rc":[{"atl":[[10.5,3.28],[11,10]],"id":52385888}],"con":true,"img":false}]}
{"op":"mcm","clk":"11450857408","pt":1717326106144,"mc":[{"id":"1.229554932","rc":[{"atl":[[660,0],[670,2]],"id":52385907}],"con":true,"img":false}]}
{"op":"mcm","clk":"11450857424","pt":1717326106251,"mc":[{"id":"1.229554932","rc":[{"atl":[[1000,0.85]],"id":52385888}],"con":true,"img":false}]}
{"op":"mcm","clk":"11450857436","pt":1717326106351,"mc":[{"id":"1.229554932","rc":[{"atl":[[10.5,3.6]],"id":52385888}],"con":true,"img":false}]}
{"op":"mcm","clk":"11450857445","pt":1717326106451,"mc":[{"id":"1.229554932","rc":[{"atb":[[16,7],[11,24.48]],"id":52385907},{"atb":[[36,2.99],[23,11.13]],"id":52385923},{"atb":[[5.6,22.81],[4.6,68.03]],"id":52385909},{"atb":[[6.8,55.09],[5.4,55.66]],"id":52385934},{"atb":[[9.8,11.92],[7.8,36.01]],"id":52385886},{"atb":[[2.54,159.03],[2.74,60.32]],"id":52385903},{"atb":[[3.45,85.5],[2.98,246.87]],"id":52385888},{"atb":[[13.5,19.59],[18.5,5.99]],"id":52385920},{"atb":[[4,81.63],[5,26.24]],"id":52385931},{"atb":[[2.24,84.64],[2.04,358.49]],"id":52385884},{"atb":[[10,27.21],[15,24.91]],"id":52385917}],"con":true,"img":false}]}
{"op":"mcm","clk":"11450857635","pt":1717326108741,"mc":[{"id":"1.229554932","rc":[{"atb":[[2.48,1.23]],"id":52385884},{"trd":[[2.48,1.04]],"ltp":2.48,"tv":1.04,"id":52385884}],"con":true,"img":false}]}
{"op":"mcm","clk":"11450857643","pt":1717326108851,"mc":[{"id":"1.229554932","rc":[{"atb":[[23,0]],"id":52385907},{"atb":[[3,50],[3.05,13.63]],"id":52385903},{"atl":[[11,0],[11.5,9.52]],"id":52385888}],"con":true,"img":false}]}
{"op":"mcm","clk":"11450857652","pt":1717326108952,"mc":[{"id":"1.229554932","rc":[{"atb":[[19,5.56]],"id":52385907},{"atl":[[670,0],[650,2]],"id":52385907},{"atl":[[18,2],[19.5,0]],"id":52385903}],"con":true,"img":false}]}
{"op":"mcm","clk":"11450857699","pt":1717326109463,"mc":[{"id":"1.229554932","rc":[{"atl":[[4.1,0.85]],"id":52385884}],"con":true,"img":false}]}
{"op":"mcm","clk":"11450857711","pt":1717326109564,"mc":[{"id":"1.229554932","rc":[{"atb":[[2.48,0.92]],"id":52385884}],"con":true,"img":false}]}
{"op":"mcm","clk":"11450857718","pt":1717326109668,"mc":[{"id":"1.229554932","rc":[{"atl":[[5.5,5]],"id":52385903}],"con":true,"img":false}]}
{"op":"mcm","clk":"11450857750","pt":1717326109936,"mc":[{"id":"1.229554932","rc":[{"atb":[[4.9,5.34]],"id":52385888}],"con":true,"img":false}]}
{"op":"mcm","clk":"11450857828","pt":1717326110657,"mc":[{"id":"1.229554932","rc":[{"atl":[[4.1,0.48]],"id":52385884}],"con":true,"img":false}]}
{"op":"mcm","clk":"11450857878","pt":1717326111169,"mc":[{"id":"1.229554932","rc":[{"atb":[[3.5,6.68]],"id":52385903},{"atl":[[9,3.44]],"id":52385888}],"con":true,"img":false}]}
{"op":"mcm","clk":"11450857945","pt":1717326111740,"mc":[{"id":"1.229554932","rc":[{"atb":[[3.1,0.28]],"id":52385903}],"con":true,"img":false}]}
{"op":"mcm","clk":"11450857956","pt":1717326111849,"mc":[{"id":"1.229554932","rc":[{"atb":[[3.5,0],[1.05,0.69]],"id":52385903},{"atl":[[5.5,0]],"id":52385903}],"con":true,"img":false}]}
{"op":"mcm","clk":"11450858010","pt":1717326112358,"mc":[{"id":"1.229554932","rc":[{"atb":[[1.05,0]],"id":52385903}],"con":true,"img":false}]}
{"op":"mcm","clk":"11450858018","pt":1717326112458,"mc":[{"id":"1.229554932","rc":[{"atb":[[3.1,0.97]],"id":52385903}],"con":true,"img":false}]}
{"op":"mcm","clk":"11450858132","pt":1717326113452,"mc":[{"id":"1.229554932","rc":[{"atb":[[16,0],[11,0]],"id":52385907},{"atb":[[36,0],[23,0]],"id":52385923},{"atb":[[5.6,0],[4.6,0]],"id":52385909},{"atb":[[9.8,0],[7.8,0]],"id":52385886},{"atb":[[6.8,37],[5.4,0]],"id":52385934},{"atb":[[2.54,0],[2.74,0]],"id":52385903},{"atb":[[3.45,42.66],[2.98,123.18]],"id":52385888},{"atb":[[13.5,0],[18.5,0]],"id":52385920},{"atb":[[4,0],[5,0]],"id":52385931},{"atb":[[2.24,0],[2.04,123]],"id":52385884},{"atb":[[10,0],[15,17.42]],"id":52385917}],"con":true,"img":false}]}
{"op":"mcm","clk":"11450858177","pt":1717326113859,"mc":[{"id":"1.229554932","rc":[{"atl":[[310,2],[320,0]],"id":52385909}],"con":true,"img":false}]}
{"op":"mcm","clk":"11450858201","pt":1717326114069,"mc":[{"id":"1.229554932","rc":[{"atl":[[17.5,2],[18,0]],"id":52385903}],"con":true,"img":false}]}
{"op":"mcm","clk":"11450858278","pt":1717326114752,"mc":[{"id":"1.229554932","rc":[{"atb":[[3,0],[2.96,43.13]],"id":52385903}],"con":true,"img":false}]}
{"op":"mcm","clk":"11450858312","pt":1717326115167,"mc":[{"id":"1.229554932","rc":[{"atb":[[4.9,0]],"id":52385888}],"con":true,"img":false}]}
{"op":"mcm","clk":"11450858318","pt":1717326115264,"mc":[{"id":"1.229554932","rc":[{"atb":[[4.9,5.34]],"id":52385888}],"con":true,"img":false}]}
{"op":"mcm","clk":"11450858360","pt":1717326115675,"mc":[{"id":"1.229554932","rc":[{"atb":[[34,3.18],[22,11.66]],"id":52385923},{"atb":[[10.5,25.78],[15.5,7.24]],"id":52385907},{"atb":[[4.5,69.97],[5.5,23.32]],"id":52385909},{"atb":[[5.3,56.95],[6.6,18.74]],"id":52385934},{"atb":[[9.8,11.92],[7.8,36.01]],"id":52385886},{"atb":[[2.72,121.86],[2.52,161.12]],"id":52385903},{"atb":[[3,122.45],[3.5,41.98]],"id":52385888},{"atb":[[13.5,19.59],[18.5,5.99]],"id":52385920},{"atb":[[4,81.63],[5,26.24]],"id":52385931},{"atb":[[2.28,82],[2.08,226.77]],"id":52385884},{"atb":[[10,27.21],[15,24.91]],"id":52385917}],"con":true,"img":false}]}
{"op":"mcm","clk":"11450858623","pt":1717326118064,"mc":[{"id":"1.229554932","rc":[{"atl":[[3.5,0.52]],"id":52385903}],"con":true,"img":false}]}
{"op":"mcm","clk":"11450858637","pt":1717326118276,"mc":[{"id":"1.229554932","rc":[{"atb":[[4.9,0]],"id":52385888},{"atl":[[9,0]],"id":52385888}],"con":true,"img":false}]}
{"op":"mcm","clk":"11450858711","pt":1717326118944,"mc":[{"id":"1.229554932","rc":[{"atl":[[310,0],[320,2]],"id":52385909},{"atb":[[9.2,0],[9.8,15.73]],"id":52385934},{"atl":[[490,0],[500,2]],"id":52385886},{"atb":[[2.92,78.55],[2.96,0]],"id":52385903},{"atl":[[11.5,0],[12,9.09]],"id":52385888},{"atb":[[44,0],[60,3.77]],"id":52385936},{"atl":[[420,0],[430,2]],"id":52385931}],"con":true,"img":false}]}
{"op":"mcm","clk":"11450858750","pt":1717326119356,"mc":[{"id":"1.229554932","rc":[{"atl":[[70,0],[36,0],[90,2]],"id":52385934},{"atl":[[10.5,3.28]],"id":52385888}],"con":true,"img":false}]}
{"op":"mcm","clk":"11450858760","pt":1717326119464,"mc":[{"id":"1.229554932","rc":[{"atl":[[90,0],[480,2]],"id":52385934},{"atl":[[1000,1.17]],"id":52385888}],"con":true,"img":false}]}
{"op":"mcm","clk":"11450858839","pt":1717326120289,"mc":[{"id":"1.229554932","rc":[{"atb":[[2.5,262.6],[2.6,0]],"id":52385903},{"atb":[[2.04,0],[2.02,124]],"id":52385884}],"con":true,"img":false}]}
{"op":"mcm","clk":"11450858915","pt":1717326121067,"mc":[{"id":"1.229554932","rc":[{"atb":[[2.86,53.76]],"id":52385903}],"con":true,"img":false}]}
{"op":"mcm","clk":"11450858920","pt":1717326121165,"mc":[{"id":"1.229554932","rc":[{"atb":[[2.92,35.42]],"id":52385903}],"con":true,"img":false}]}
{"op":"mcm","clk":"11450859187","pt":1717326123713,"mc":[{"id":"1.229554932","rc":[{"atb":[[2.46,0],[2.48,0]],"id":52385884},{"trd":[[2.46,71.67],[2.48,2.9]],"ltp":2.46,"tv":74.57,"id":52385884},{"atl":[[2.46,94.02]],"id":52385884}],"con":true,"img":false}]}
{"op":"mcm","clk":"11450859207","pt":1717326123920,"mc":[{"id":"1.229554932","rc":[{"trd":[[2.46,259.72]],"ltp":2.46,"tv":259.72,"id":52385884},{"atl":[[2.46,0],[2.96,51.02]],"id":52385884}],"con":true,"img":false}]}
{"op":"mcm","clk":"11450859218","pt":1717326124024,"mc":[{"id":"1.229554932","rc":[{"atl":[[12,0],[12.5,8.7]],"id":52385888},{"atl":[[430,0],[440,2]],"id":52385931},{"atl":[[4.2,0]],"id":52385884}],"con":true,"img":false}]}
{"op":"mcm","clk":"11450859234","pt":1717326124128,"mc":[{"id":"1.229554932","rc":[{"atl":[[2.96,0],[4.2,31.25]],"id":52385884}],"con":true,"img":false}]}
{"op":"mcm","clk":"11450859254","pt":1717326124342,"mc":[{"id":"1.229554932","rc":[{"atb":[[10.5,0],[15.5,0]],"id":52385907},{"atb":[[34,0],[22,0]],"id":52385923},{"atb":[[4.5,0],[5.5,0]],"id":52385909},{"atb":[[5.3,0],[6.6,0]],"id":52385934},{"atb":[[9.8,0],[7.8,0]],"id":52385886},{"atb":[[2.72,60.84],[2.52,0]],"id":52385903},{"atl":[[5.5,3.71]],"id":52385903},{"atb":[[3,0],[4.9,5.34],[3.5,0]],"id":52385888},{"atb":[[13.5,0],[18.5,0]],"id":52385920},{"atb":[[4,0],[5,0]],"id":52385931},{"atb":[[2.28,0],[2.08,0]],"id":52385884},{"atl":[[1000,1.7]],"id":52385884},{"atb":[[10,0],[15,17.42]],"id":52385917}],"con":true,"img":false}]}
{"op":"mcm","clk":"11450859263","pt":1717326124442,"mc":[{"id":"1.229554932","rc":[{"atl":[[17.5,0],[5.4,2]],"id":52385903},{"atl":[[4.1,1.33]],"id":52385884}],"con":true,"img":false}]}
{"op":"mcm","clk":"11450859332","pt":1717326125017,"mc":[{"id":"1.229554932","rc":[{"atb":[[3.1,0.28]],"id":52385903},{"atl":[[4.1,1.11]],"id":52385884}],"con":true,"img":false}]}
{"op":"mcm","clk":"11450859342","pt":1717326125126,"mc":[{"id":"1.229554932","rc":[{"atb":[[1.05,0.69]],"id":52385903}],"con":true,"img":false}]}
{"op":"mcm","clk":"11450859396","pt":1717326125539,"mc":[{"id":"1.229554932","rc":[{"atl":[[1000,1.19]],"id":52385884}],"con":true,"img":false}]}
{"op":"mcm","clk":"11450859447","pt":1717326126166,"mc":[{"id":"1.229554932","rc":[{"atl":[[1000,0.85]],"id":52385884}],"con":true,"img":false}]}
{"op":"mcm","clk":"11450859456","pt":1717326126219,"mc":[{"id":"1.229554932","rc":[{"atl":[[4.1,1.45]],"id":52385884}],"con":true,"img":false}]}
{"op":"mcm","clk":"11450859486","pt":1717326126526,"mc":[{"id":"1.229554932","rc":[{"atl":[[3.1,7.46]],"id":52385884}],"con":true,"img":false}]}
{"op":"mcm","clk":"11450859493","pt":1717326126630,"mc":[{"id":"1.229554932","rc":[{"atl":[[650,0],[660,2]],"id":52385907},{"atb":[[10.5,10.53],[9.8,4.37]],"id":52385934},{"atl":[[480,0],[490,2]],"id":52385934},{"atl":[[12,6.56],[12.5,0]],"id":52385888}],"con":true,"img":false}]}
{"op":"mcm","clk":"11450859512","pt":1717326126840,"mc":[{"id":"1.229554932","rc":[{"atl":[[4.1,0.82]],"id":52385884}],"con":true,"img":false}]}
{"op":"mcm","clk":"11450859526","pt":1717326126943,"mc":[{"id":"1.229554932","rc":[{"atl":[[3.05,0.63]],"id":52385884}],"con":true,"img":false}]}
{"op":"mcm","clk":"11450859544","pt":1717326127149,"mc":[{"id":"1.229554932","rc":[{"atl":[[3.1,0]],"id":52385884}],"con":true,"img":false}]}
{"op":"mcm","clk":"11450859571","pt":1717326127408,"mc":[{"id":"1.229554932","rc":[{"atl":[[3.05,0]],"id":52385884}],"con":true,"img":false}]}
{"op":"mcm","clk":"11450859581","pt":1717326127510,"mc":[{"id":"1.229554932","rc":[{"atl":[[4,0.63]],"id":52385884}],"con":true,"img":false}]}
{"op":"mcm","clk":"11450859590","pt":1717326127613,"mc":[{"id":"1.229554932","rc":[{"atb":[[9.4,3.62]],"id":52385909}],"con":true,"img":false}]}
{"op":"mcm","clk":"11450859614","pt":1717326127819,"mc":[{"id":"1.229554932","rc":[{"atl":[[4,1.48]],"id":52385884}],"con":true,"img":false}]}
{"op":"mcm","clk":"11450859638","pt":1717326128026,"mc":[{"id":"1.229554932","rc":[{"atb":[[9.6,3.92]],"id":52385909},{"atl":[[3.5,0]],"id":52385903},{"atl":[[4,3.48],[4.1,0.34],[4.2,0]],"id":52385884}],"con":true,"img":false}]}
{"op":"mcm","clk":"11450859644","pt":1717326128129,"mc":[{"id":"1.229554932","rc":[{"atl":[[16,5.71],[3.2,0.52],[5.4,0]],"id":52385903},{"atl":[[4,3.96]],"id":52385884}],"con":true,"img":false}]}
{"op":"mcm","clk":"11450859664","pt":1717326128340,"mc":[{"id":"1.229554932","rc":[{"atl":[[5.5,0]],"id":52385903}],"con":true,"img":false}]}
{"op":"mcm","clk":"11450859675","pt":1717326128444,"mc":[{"id":"1.229554932","rc":[{"atl":[[660,0],[720,2]],"id":52385907},{"atl":[[320,0],[360,2]],"id":52385909},{"atl":[[520,2],[490,0]],"id":52385934},{"atl":[[530,2],[500,0]],"id":52385886},{"atl":[[12,0],[14,7.69]],"id":52385888},{"atl":[[440,0],[470,2]],"id":52385931},{"atl":[[4,3.35]],"id":52385884}],"con":true,"img":false}]}
{"op":"mcm","clk":"11450859724","pt":1717326129063,"mc":[{"id":"1.229554932","rc":[{"atb":[[9.4,0]],"id":52385909}],"con":true,"img":false}]}
{"op":"mcm","clk":"11450859754","pt":1717326129323,"mc":[{"id":"1.229554932","rc":[{"atb":[[4.9,0]],"id":52385888}],"con":true,"img":false}]}
{"op":"mcm","clk":"11450859766","pt":1717326129431,"mc":[{"id":"1.229554932","rc":[{"atb":[[16,6.67],[19,0]],"id":52385907},{"atl":[[340,2],[360,0]],"id":52385909},{"atb":[[2.86,0],[2.64,60.98]],"id":52385903}],"con":true,"img":false}]}
{"op":"mcm","clk":"11450859841","pt":1717326130152,"mc":[{"id":"1.229554932","rc":[{"atb":[[2.5,329.27],[2.64,0]],"id":52385903},{"atb":[[4.8,24.53],[4.1,0]],"id":52385888},{"atb":[[7.8,14.71],[4.2,0]],"id":52385931},{"atb":[[1.35,0]],"id":52385884}],"con":true,"img":false}]}
{"op":"mcm","clk":"11450859851","pt":1717326130254,"mc":[{"id":"1.229554932","rc":[{"atl":[[16,0],[38,2.7]],"id":52385903}],"con":true,"img":false}]}
{"op":"mcm","clk":"11450859885","pt":1717326130567,"mc":[{"id":"1.229554932","rc":[{"atb":[[9.6,3.04]],"id":52385909},{"atl":[[530,2]],"id":52385934},{"atl":[[15.5,6.9]],"id":52385888}],"con":true,"img":false}]}
{"op":"mcm","clk":"11450859893","pt":1717326130617,"mc":[{"id":"1.229554932","rc":[{"atl":[[520,0]],"id":52385934},{"atl":[[14,0]],"id":52385888}],"con":true,"img":false}]}
{"op":"mcm","clk":"11450859924","pt":1717326130930,"mc":[{"id":"1.229554932","rc":[{"atb":[[10.5,25.78],[15.5,7.24]],"id":52385907},{"atb":[[34,3.18],[22,11.66]],"id":52385923},{"atb":[[4.5,69.97],[5.5,23.32]],"id":52385909},{"atb":[[5.3,56.95],[6.6,18.74]],"id":52385934},{"atb":[[9.8,11.92],[7.8,36.01]],"id":52385886},{"atb":[[2.72,121.86],[2.52,161.12]],"id":52385903},{"atb":[[3,122.45],[3.5,41.98]],"id":52385888},{"atb":[[13.5,19.59],[18.5,5.99]],"id":52385920},{"atb":[[4,81.63],[5,26.24]],"id":52385931},{"atb":[[2.28,82],[2.08,226.77]],"id":52385884},{"atb":[[10,27.21],[15,24.91]],"id":52385917}],"con":true,"img":false}]}
{"op":"mcm","clk":"11450860063","pt":1717326132333,"mc":[{"id":"1.229554932","rc":[{"atl":[[310,2],[340,0]],"id":52385909}],"con":true,"img":false}]}
{"op":"mcm","clk":"11450860219","pt":1717326133531,"mc":[{"id":"1.229554932","rc":[{"atl":[[630,2],[720,0]],"id":52385907},{"atl":[[530,0],[510,2]],"id":52385934},{"atl":[[530,0],[500,2]],"id":52385886},{"atl":[[13,6.56],[15.5,0]],"id":52385888},{"atl":[[440,2],[470,0]],"id":52385931}],"con":true,"img":false}]}
{"op":"mcm","clk":"11450860277","pt":1717326134053,"mc":[{"id":"1.229554932","rc":[{"atb":[[4.8,0],[4.7,41.17]],"id":52385888}],"con":true,"img":false}]}
{"op":"mcm","clk":"11450860330","pt":1717326134521,"mc":[{"id":"1.229554932","rc":[{"atb":[[16,0],[18.5,5.71]],"id":52385907}],"con":true,"img":false}]}
{"op":"mcm","clk":"11450860409","pt":1717326135347,"mc":[{"id":"1.229554932","rc":[{"atb":[[7,36]],"id":52385934},{"atb":[[1.98,126]],"id":52385884}],"con":true,"img":false}]}
{"op":"mcm","clk":"11450860418","pt":1717326135453,"mc":[{"id":"1.229554932","rc":[{"atb":[[6.8,0]],"id":52385934},{"atb":[[2.02,0]],"id":52385884}],"con":true,"img":false}]}
{"op":"mcm","clk":"11450860442","pt":1717326135659,"mc":[{"id":"1.229554932","rc":[{"atl":[[630,0],[650,2]],"id":52385907},{"atl":[[520,2],[500,0]],"id":52385886}],"con":true,"img":false}]}
{"op":"mcm","clk":"11450860668","pt":1717326137424,"mc":[{"id":"1.229554932","rc":[{"atl":[[300,2]],"id":52385909}],"con":true,"img":false}]}
{"op":"mcm","clk":"11450860677","pt":1717326137527,"mc":[{"id":"1.229554932","rc":[{"atl":[[310,0]],"id":52385909}],"con":true,"img":false}]}
{"op":"mcm","clk":"11450860777","pt":1717326138670,"mc":[{"id":"1.229554932","rc":[{"atl":[[490,2],[510,0]],"id":52385934},{"atl":[[430,2],[440,0]],"id":52385931}],"con":true,"img":false}]}
{"op":"mcm","clk":"11450860823","pt":1717326139135,"mc":[{"id":"1.229554932","rc":[{"atl":[[490,0],[500,2]],"id":52385934},{"atl":[[520,0],[510,2]],"id":52385886},{"atl":[[430,0],[440,2]],"id":52385931}],"con":true,"img":false}]}
{"op":"mcm","clk":"11450860859","pt":1717326139550,"mc":[{"id":"1.229554932","rc":[{"atl":[[300,0],[310,2]],"id":52385909}],"con":true,"img":false}]}
{"op":"mcm","clk":"11450860949","pt":1717326140385,"mc":[{"id":"1.229554932","rc":[{"atb":[[10.5,0],[15.5,0]],"id":52385907},{"atb":[[34,0],[22,0]],"id":52385923},{"atb":[[4.5,0],[5.5,0]],"id":52385909},{"atb":[[5.3,0],[6.6,0]],"id":52385934},{"atb":[[9.8,0],[7.8,0]],"id":52385886},{"atb":[[2.72,60.84],[2.52,0]],"id":52385903},{"atb":[[3,0],[3.5,0]],"id":52385888},{"atb":[[13.5,0],[18.5,0]],"id":52385920},{"atb":[[4,0],[5,0]],"id":52385931},{"atb":[[2.28,0],[2.08,0]],"id":52385884},{"atb":[[10,0],[15,17.42]],"id":52385917}],"con":true,"img":false}]}
{"op":"mcm","clk":"11450861241","pt":1717326142885,"mc":[{"id":"1.229554932","rc":[{"atl":[[520,2],[510,0]],"id":52385886}],"con":true,"img":false}]}
{"op":"mcm","clk":"11450861413","pt":1717326144288,"mc":[{"id":"1.229554932","rc":[{"atl":[[650,0],[660,2]],"id":52385907},{"atl":[[310,0],[320,2]],"id":52385909},{"atl":[[520,0],[510,2]],"id":52385886},{"atl":[[500,0],[510,2]],"id":52385934},{"atl":[[12.5,6.56],[13,0]],"id":52385888}],"con":true,"img":false}]}
{"op":"mcm","clk":"11450861477","pt":1717326144874,"mc":[{"id":"1.229554932","rc":[{"atl":[[660,0],[650,2]],"id":52385907},{"atl":[[310,2],[320,0]],"id":52385909},{"atl":[[510,0],[500,2]],"id":52385934},{"atl":[[3.2,0]],"id":52385903},{"atl":[[12.5,0],[13,8.33]],"id":52385888},{"atl":[[430,2],[440,0]],"id":52385931}],"con":true,"img":false}]}
{"op":"mcm","clk":"11450861529","pt":1717326145379,"mc":[{"id":"1.229554932","rc":[{"atb":[[36,2.99],[23,11.13]],"id":52385923},{"atb":[[5.3,56.95],[6.6,18.74]],"id":52385934},{"atb":[[3.1,0],[3.05,13.39]],"id":52385903},{"trd":[[3.05,0.48],[3.1,0.56]],"ltp":3.05,"tv":1.04,"id":52385903},{"atb":[[13.5,19.59],[18.5,5.99]],"id":52385920},{"atb":[[4,81.63],[5,26.24]],"id":52385931},{"atb":[[10,27.21],[15,24.91]],"id":52385917}],"con":true,"img":false}]}
{"op":"mcm","clk":"11450861541","pt":1717326145480,"mc":[{"id":"1.229554932","rc":[{"atb":[[10.5,25.78],[15.5,7.24]],"id":52385907},{"atb":[[4.5,69.97],[5.5,23.32]],"id":52385909},{"atb":[[8,34.99],[10,38.76]],"id":52385886},{"atb":[[2.5,492.55],[2.7,123.23]],"id":52385903},{"atb":[[3.55,41.16],[3.05,119.47]],"id":52385888},{"atb":[[2.28,82],[2.08,226.77]],"id":52385884}],"con":true,"img":false}]}
{"op":"mcm","clk":"11450861604","pt":1717326145951,"mc":[{"id":"1.229554932","rc":[{"atl":[[36,0.85]],"id":52385903}],"con":true,"img":false}]}
{"op":"mcm","clk":"11450861878","pt":1717326148456,"mc":[{"id":"1.229554932","rc":[{"atl":[[36,0.26]],"id":52385903}],"con":true,"img":false}]}
{"op":"mcm","clk":"11450861992","pt":1717326149285,"mc":[{"id":"1.229554932","rc":[{"atl":[[650,0],[640,2]],"id":52385907},{"atl":[[12.5,6.56],[13,0]],"id":52385888}],"con":true,"img":false}]}
{"op":"mcm","clk":"11450862155","pt":1717326150686,"mc":[{"id":"1.229554932","rc":[{"atl":[[300,2],[310,0]],"id":52385909},{"atl":[[490,2],[500,0]],"id":52385934}],"con":true,"img":false}]}
{"op":"mcm","clk":"11450862549","pt":1717326154481,"mc":[{"id":"1.229554932","rc":[{"atl":[[300,0],[310,2]],"id":52385909},{"atl":[[500,2]],"id":52385934}],"con":true,"img":false}]}
{"op":"mcm","clk":"11450862556","pt":1717326154585,"mc":[{"id":"1.229554932","rc":[{"atl":[[490,0]],"id":52385934}],"con":true,"img":false}]}
{"op":"mcm","clk":"11450862725","pt":1717326156300,"mc":[{"id":"1.229554932","rc":[{"atb":[[10.5,0],[15.5,0]],"id":52385907},{"atb":[[36,0],[23,0]],"id":52385923},{"atb":[[4.5,0],[5.5,0]],"id":52385909},{"atb":[[5.3,0],[6.6,0]],"id":52385934},{"atb":[[8,0],[10,27.1]],"id":52385886},{"atb":[[2.5,329.27],[2.7,61.48]],"id":52385903},{"atb":[[3.55,0],[3.05,0]],"id":52385888},{"atb":[[13.5,0],[18.5,0]],"id":52385920},{"atb":[[4,0],[5,0]],"id":52385931},{"atb":[[2.28,0],[2.08,0]],"id":52385884},{"atb":[[10,0],[15,17.42]],"id":52385917}],"con":true,"img":false}]}
{"op":"mcm","clk":"11450862786","pt":1717326156971,"mc":[{"id":"1.229554932","rc":[{"atb":[[7,52.67]],"id":52385934},{"atl":[[19,2]],"id":52385903},{"atb":[[5.2,23.81],[7.8,0]],"id":52385931},{"atb":[[1.89,112.36]],"id":52385884}],"con":true,"img":false}]}
{"op":"mcm","clk":"11450862796","pt":1717326157073,"mc":[{"id":"1.229554932","rc":[{"atb":[[10.5,0]],"id":52385934},{"atl":[[38,0]],"id":52385903}],"con":true,"img":false}]}
{"op":"mcm","clk":"11450862811","pt":1717326157284,"mc":[{"id":"1.229554932","rc":[{"atb":[[7.2,0]],"id":52385909}],"con":true,"img":false}]}
{"op":"mcm","clk":"11450862823","pt":1717326157394,"mc":[{"id":"1.229554932","rc":[{"atb":[[9.8,0]],"id":52385934}],"con":true,"img":false}]}
{"op":"mcm","clk":"11450862906","pt":1717326158472,"mc":[{"id":"1.229554932","rc":[{"atl":[[36,0]],"id":52385903}],"con":true,"img":false}]}
{"op":"mcm","clk":"11450862912","pt":1717326158575,"mc":[{"id":"1.229554932","rc":[{"atl":[[18.5,0.26]],"id":52385903}],"con":true,"img":false}]}
{"op":"mcm","clk":"11450863003","pt":1717326159619,"mc":[{"id":"1.229554932","rc":[{"atl":[[640,0],[650,2]],"id":52385907},{"atl":[[300,2],[310,0]],"id":52385909},{"atl":[[490,2],[500,0]],"id":52385934},{"atb":[[4.6,27.78],[4.7,14.14]],"id":52385888},{"atl":[[12,6.56],[12.5,0]],"id":52385888},{"atl":[[430,0],[420,2]],"id":52385931}],"con":true,"img":false}]}
{"op":"mcm","clk":"11450863343","pt":1717326163193,"mc":[{"id":"1.229554932","rc":[{"atb":[[10.5,25.78],[15.5,7.24]],"id":52385907},{"atb":[[36,2.99],[23,11.13]],"id":52385923},{"atb":[[4.5,69.97],[5.5,23.32]],"id":52385909},{"atb":[[5.3,56.95],[6.6,18.74]],"id":52385934},{"atb":[[8,34.99],[10,38.76]],"id":52385886},{"atb":[[2.5,492.55],[2.7,123.23]],"id":52385903},{"atb":[[3.55,41.16],[3.05,119.47]],"id":52385888},{"atb":[[13.5,19.59],[18.5,5.99]],"id":52385920},{"atb":[[4,81.63],[5,26.24]],"id":52385931},{"atb":[[2.28,82],[2.08,226.77]],"id":52385884},{"atb":[[10,27.21],[15,24.91]],"id":52385917}],"con":true,"img":false}]}
{"op":"mcm","clk":"11450863393","pt":1717326163713,"mc":[{"id":"1.229554932","rc":[{"atl":[[650,0],[640,2]],"id":52385907}],"con":true,"img":false}]}
{"op":"mcm","clk":"11450863482","pt":1717326164703,"mc":[{"id":"1.229554932","rc":[{"atl":[[300,0],[310,2]],"id":52385909},{"atl":[[420,0],[430,2]],"id":52385931}],"con":true,"img":false}]}
{"op":"mcm","clk":"11450863536","pt":1717326165481,"mc":[{"id":"1.229554932","rc":[{"atb":[[6.8,37]],"id":52385934},{"atb":[[3.5,71]],"id":52385888}],"con":true,"img":false}]}
{"op":"mcm","clk":"11450863545","pt":1717326165591,"mc":[{"id":"1.229554932","rc":[{"atb":[[7,16.67]],"id":52385934},{"atl":[[520,2],[510,0]],"id":52385886},{"atb":[[3.3,0]],"id":52385888}],"con":true,"img":false}]}
{"op":"mcm","clk":"11450863568","pt":1717326165896,"mc":[{"id":"1.229554932","rc":[{"atl":[[660,2]],"id":52385907}],"con":true,"img":false}]}
{"op":"mcm","clk":"11450863579","pt":1717326166001,"mc":[{"id":"1.229554932","rc":[{"atl":[[640,0]],"id":52385907}],"con":true,"img":false}]}
{"op":"mcm","clk":"11450863594","pt":1717326166206,"mc":[{"id":"1.229554932","rc":[{"atb":[[18.5,0],[22,4.76]],"id":52385907},{"atb":[[2.82,98.07],[2.5,425.88]],"id":52385903}],"con":true,"img":false}]}
{"op":"mcm","clk":"11450863653","pt":1717326166884,"mc":[{"id":"1.229554932","rc":[{"atl":[[310,0],[330,2]],"id":52385909}],"con":true,"img":false}]}
{"op":"mcm","clk":"11450863776","pt":1717326168028,"mc":[{"id":"1.229554932","rc":[{"atl":[[680,2]],"id":52385907}],"con":true,"img":false}]}
{"op":"mcm","clk":"11450863788","pt":1717326168184,"mc":[{"id":"1.229554932","rc":[{"atl":[[660,0]],"id":52385907}],"con":true,"img":false}]}
{"op":"mcm","clk":"11450863902","pt":1717326169240,"mc":[{"id":"1.229554932","marketDefinition":{"bspMarket":false,"turnInPlayEnabled":false,"persistenceEnabled":false,"marketBaseRate":7.0,"eventId":"33318908","eventTypeId":"4339","numberOfWinners":1,"bettingType":"ODDS","marketType":"EXACTA","marketTime":"2024-06-02T11:02:00.000Z","suspendTime":"2024-06-02T11:02:00.000Z","bspReconciled":false,"complete":true,"inPlay":false,"crossMatching":true,"runnersVoidable":false,"numberOfActiveRunners":12,"betDelay":0,"status":"SUSPENDED","runners":[{"status":"ACTIVE","sortPriority":1,"id":52385884,"name":"1 - 4"},{"status":"ACTIVE","sortPriority":2,"id":52385886,"name":"1 - 6"},{"status":"ACTIVE","sortPriority":3,"id":52385888,"name":"1 - 8"},{"status":"ACTIVE","sortPriority":4,"id":52385903,"name":"4 - 1"},{"status":"ACTIVE","sortPriority":5,"id":52385907,"name":"4 - 6"},{"status":"ACTIVE","sortPriority":6,"id":52385909,"name":"4 - 8"},{"status":"ACTIVE","sortPriority":7,"id":52385917,"name":"6 - 1"},{"status":"ACTIVE","sortPriority":8,"id":52385920,"name":"6 - 4"},{"status":"ACTIVE","sortPriority":9,"id":52385923,"name":"6 - 8"},{"status":"ACTIVE","sortPriority":10,"id":52385931,"name":"8 - 1"},{"status":"ACTIVE","sortPriority":11,"id":52385934,"name":"8 - 4"},{"status":"ACTIVE","sortPriority":12,"id":52385936,"name":"8 - 6"}],"regulators":["MR_INT"],"venue":"Murray Bridge","countryCode":"AU","discountAllowed":true,"timezone":"Australia/Adelaide","openDate":"2024-06-02T08:21:00.000Z","version":5963171710,"name":"Exacta","eventName":"Murray Bridge (AUS) 2nd Jun"},"rc":[],"con":true,"img":false}]}
{"op":"mcm","clk":"11450863902","pt":1717326169240,"mc":[{"id":"1.229554932","rc":[{"atb":[[34,0],[19.5,0],[1.03,0],[10.5,0],[44,0],[22,0],[1.02,0],[27,0],[13.5,0],[14.5,0],[60,0],[15.5,0]],"id":52385907},{"atl":[[680,0],[990,0]],"id":52385907},{"atb":[[300,0],[36,0],[1.01,0],[20,0],[350,0],[23,0],[1.02,0],[200,0],[100,0],[50,0],[1.04,0],[250,0]],"id":52385923},{"atl":[[1000,0]],"id":52385923},{"atb":[[9.6,0],[4,0],[8.6,0],[4.5,0],[5,0],[1.03,0],[5.5,0],[1.02,0],[7.6,0],[5.2,0],[6.6,0],[5.9,0]],"id":52385909},{"atl":[[330,0],[1000,0]],"id":52385909},{"atb":[[9,0],[10,0],[1.03,0],[5.3,0],[1.02,0],[6.8,0],[12.5,0],[5.7,0],[7,0],[6.6,0],[15,0],[4.7,0]],"id":52385934},{"atl":[[490,0],[1000,0]],"id":52385934},{"atb":[[9.6,0],[8,0],[17,0],[19.5,0],[10,0],[1.03,0],[10.5,0],[1.02,0],[24,0],[29,0],[15,0]],"id":52385886},{"atl":[[520,0],[990,0]],"id":52385886},{"atb":[[2.82,0],[2.92,0],[2.72,0],[2.5,0],[1.02,0],[1.05,0],[3.05,0],[1.04,0],[2.7,0]],"id":52385903},{"atl":[[18.5,0],[19,0],[990,0]],"id":52385903},{"atb":[[3.85,0],[1.03,0],[3.55,0],[2.98,0],[3.5,0],[3.05,0],[3.45,0],[4.6,0],[1.02,0],[5.2,0],[4.2,0],[1.04,0],[4.7,0]],"id":52385888},{"atl":[[10.5,0],[12,0],[1000,0]],"id":52385888},{"atb":[[130,0],[1.03,0],[180,0],[46,0],[13.5,0],[65,0],[18.5,0],[18,0],[19,0],[90,0],[1.02,0],[26,0],[1.04,0]],"id":52385920},{"atl":[[990,0],[1000,0]],"id":52385920},{"atb":[[65,0],[36,0],[38,0],[1.01,0],[170,0],[85,0],[22,0],[1.02,0],[120,0],[60,0],[1.04,0]],"id":52385936},{"atb":[[5.6,0],[4.8,0],[4,0],[5,0],[1.03,0],[11,0],[7.4,0],[1.02,0],[5.2,0],[3.9,0],[8.4,0],[9.4,0]],"id":52385931},{"atl":[[430,0],[990,0]],"id":52385931},{"atb":[[2.36,0],[1.98,0],[1.89,0],[1.03,0],[1.02,0],[2.28,0],[2.26,0],[2.14,0],[2.34,0],[2.08,0]],"id":52385884},{"atl":[[4,0],[4.3,0],[10.5,0],[4.1,0],[1000,0]],"id":52385884},{"atb":[[130,0],[65,0],[19,0],[20,0],[10,0],[1.03,0],[90,0],[46,0],[1.02,0],[55,0],[15,0]],"id":52385917},{"atl":[[990,0],[1000,0]],"id":52385917}],"con":true,"img":false}]}
{"op":"mcm","clk":"11450868263","pt":1717326215699,"mc":[{"id":"1.229554932","rc":[{"trd":[[3.1,0],[3.05,0]],"ltp":3.1,"tv":0.0,"id":52385903},{"trd":[[320,0],[170,0],[220,0]],"ltp":320.0,"tv":0.0,"id":52385936},{"trd":[[2.56,0],[2.46,0],[2.48,0]],"ltp":2.56,"tv":0.0,"id":52385884}],"con":true,"img":false}]}
{"op":"mcm","clk":"11450868364","pt":1717326216720,"mc":[{"id":"1.229554932","marketDefinition":{"bspMarket":false,"turnInPlayEnabled":false,"persistenceEnabled":false,"marketBaseRate":7.0,"eventId":"33318908","eventTypeId":"4339","numberOfWinners":1,"bettingType":"ODDS","marketType":"EXACTA","marketTime":"2024-06-02T11:02:00.000Z","suspendTime":"2024-06-02T11:02:00.000Z","bspReconciled":false,"complete":true,"inPlay":false,"crossMatching":false,"runnersVoidable":false,"numberOfActiveRunners":0,"betDelay":0,"status":"CLOSED","settledTime":"2024-06-02T11:03:33.000Z","runners":[{"status":"LOSER","sortPriority":1,"id":52385884,"name":"1 - 4"},{"status":"LOSER","sortPriority":2,"id":52385886,"name":"1 - 6"},{"status":"WINNER","sortPriority":3,"id":52385888,"name":"1 - 8"},{"status":"LOSER","sortPriority":4,"id":52385903,"name":"4 - 1"},{"status":"LOSER","sortPriority":5,"id":52385907,"name":"4 - 6"},{"status":"LOSER","sortPriority":6,"id":52385909,"name":"4 - 8"},{"status":"LOSER","sortPriority":7,"id":52385917,"name":"6 - 1"},{"status":"LOSER","sortPriority":8,"id":52385920,"name":"6 - 4"},{"status":"LOSER","sortPriority":9,"id":52385923,"name":"6 - 8"},{"status":"LOSER","sortPriority":10,"id":52385931,"name":"8 - 1"},{"status":"LOSER","sortPriority":11,"id":52385934,"name":"8 - 4"},{"status":"LOSER","sortPriority":12,"id":52385936,"name":"8 - 6"}],"regulators":["MR_INT"],"venue":"Murray Bridge","countryCode":"AU","discountAllowed":true,"timezone":"Australia/Adelaide","openDate":"2024-06-02T08:21:00.000Z","version":5963173500,"name":"Exacta","eventName":"Murray Bridge (AUS) 2nd Jun"},"rc":[],"con":true,"img":false}]}
