{"op":"mcm","clk":"11448127640","pt":1717286034978,"mc":[{"id":"1.229554925","marketDefinition":{"bspMarket":true,"turnInPlayEnabled":false,"persistenceEnabled":false,"marketBaseRate":7.0,"eventId":"33318908","eventTypeId":"4339","numberOfWinners":1,"bettingType":"ODDS","marketType":"WIN","marketTime":"2024-06-02T10:45:00.000Z","suspendTime":"2024-06-02T10:45:00.000Z","bspReconciled":false,"complete":true,"inPlay":false,"crossMatching":true,"runnersVoidable":false,"numberOfActiveRunners":6,"betDelay":0,"status":"OPEN","runners":[{"status":"ACTIVE","sortPriority":1,"id":40917581,"name":"1. Sophia Palms"},{"status":"ACTIVE","sortPriority":2,"id":47148562,"name":"2. Under Siege"},{"status":"ACTIVE","sortPriority":3,"id":49546922,"name":"4. Uno Whiskey"},{"status":"ACTIVE","sortPriority":4,"id":70003372,"name":"5. Southern Sun"},{"status":"ACTIVE","sortPriority":5,"id":48638605,"name":"7. Lochinvar Aloisi"},{"status":"ACTIVE","sortPriority":6,"id":64343695,"name":"8. Punching Poncho"}],"regulators":["MR_INT"],"venue":"Murray Bridge","countryCode":"AU","discountAllowed":true,"timezone":"Australia/Adelaide","openDate":"2024-06-02T08:21:00.000Z","version":5962317636,"name":"R8 530m Heat","eventName":"Murray Bridge (AUS) 2nd Jun"},"rc":[],"con":true,"img":false}]}
{"op":"mcm","clk":"11448135508","pt":1717286146257,"mc":[{"id":"1.229554925","marketDefinition":{"bspMarket":true,"turnInPlayEnabled":false,"persistenceEnabled":false,"marketBaseRate":7.0,"eventId":"33318908","eventTypeId":"4339","numberOfWinners":1,"bettingType":"ODDS","marketType":"WIN","marketTime":"2024-06-02T10:41:00.000Z","suspendTime":"2024-06-02T10:41:00.000Z","bspReconciled":false,"complete":true,"inPlay":false,"crossMatching":true,"runnersVoidable":false,"numberOfActiveRunners":6,"betDelay":0,"status":"OPEN","runners":[{"status":"ACTIVE","sortPriority":1,"id":40917581,"name":"1. Sophia Palms"},{"status":"ACTIVE","sortPriority":2,"id":47148562,"name":"2. Under Siege"},{"status":"ACTIVE","sortPriority":3,"id":49546922,"name":"4. Uno Whiskey"},{"status":"ACTIVE","sortPriority":4,"id":70003372,"name":"5. Southern Sun"},{"status":"ACTIVE","sortPriority":5,"id":48638605,"name":"7. Lochinvar Aloisi"},{"status":"ACTIVE","sortPriority":6,"id":64343695,"name":"8. Punching Poncho"}],"regulators":["MR_INT"],"venue":"Murray Bridge","countryCode":"AU","discountAllowed":true,"timezone":"Australia/Adelaide","openDate":"2024-06-02T08:21:00.000Z","version":5962327449,"name":"R8 530m Heat","eventName":"Murray Bridge (AUS) 2nd Jun"},"rc":[],"con":true,"img":false}]}
{"op":"mcm","clk":"11448170113","pt":1717286665498,"mc":[{"id":"1.229554925","rc":[{"spl":[[1.01,31.39]],"id":70003372},{"spn":1.0,"spf":1.0,"id":70003372}],"con":true,"img":false}]}
{"op":"mcm","clk":"11448266886","pt":1717288003942,"mc":[{"id":"1.229554925","rc":[{"atb":[[2.86,56.19],[2.66,125.93],[2.76,118.78]],"id":47148562},{"atl":[[9.8,15.83],[14.5,15.48]],"id":47148562},{"spn":6.33,"spf":"NaN","id":47148562},{"atb":[[17,6.53],[12,19],[14.5,15.48]],"id":64343695},{"atl":[[350,0.59],[250,0.55]],"id":64343695},{"spn":133.5,"spf":"NaN","id":64343695},{"atb":[[5.8,43.55],[7.6,15.83],[6.6,37.33]],"id":48638605},{"atl":[[75,1.88],[150,1.4]],"id":48638605},{"spn":41.3,"spf":"NaN","id":48638605},{"atb":[[3.4,87.1],[3.15,97.23],[3.65,39.44]],"id":49546922},{"atl":[[16.5,8.99],[23,9.5]],"id":49546922},{"spn":10.07,"spf":"NaN","id":49546922},{"atb":[[1.79,264.63],[1.89,117.44],[1.84,248.88]],"id":70003372},{"atl":[[5.1,33.99],[6.2,40.2]],"id":70003372},{"spn":1.89,"spf":1.0,"id":70003372},{"atb":[[38,2.82],[24,9.08],[29,7.46]],"id":40917581},{"atl":[[550,0.38],[450,0.3]],"id":40917581},{"spn":244.0,"spf":"NaN","id":40917581}],"con":true,"img":false}]}
{"op":"mcm","clk":"11448270153","pt":1717288057431,"mc":[{"id":"1.229554925","rc":[{"atb":[[2.86,0],[2.66,0],[2.76,0]],"id":47148562},{"atl":[[9.8,0],[14.5,0]],"id":47148562},{"atb":[[17,0],[12,0],[14.5,0]],"id":64343695},{"atl":[[350,0],[250,0]],"id":64343695},{"atb":[[5.8,0],[7.6,0],[6.6,0]],"id":48638605},{"atl":[[75,0],[150,0]],"id":48638605},{"atb":[[3.4,0],[3.15,0],[3.65,0]],"id":49546922},{"atl":[[16.5,0],[23,0]],"id":49546922},{"atb":[[1.79,0],[1.89,0],[1.84,0]],"id":70003372},{"atl":[[5.1,0],[6.2,0]],"id":70003372},{"atb":[[38,0],[24,0],[29,0]],"id":40917581},{"atl":[[550,0],[450,0]],"id":40917581}],"con":true,"img":false}]}
{"op":"mcm","clk":"11448270978","pt":1717288067734,"mc":[{"id":"1.229554925","rc":[{"atb":[[2.86,56.19],[2.66,125.93],[2.76,118.78]],"id":47148562},{"atl":[[9.8,15.83],[14.5,15.48]],"id":47148562},{"atb":[[17,6.53],[12,19],[14.5,15.48]],"id":64343695},{"atl":[[350,0.59],[250,0.55]],"id":64343695},{"atb":[[5.8,43.55],[7.6,15.83],[6.6,37.33]],"id":48638605},{"atl":[[75,1.88],[150,1.4]],"id":48638605},{"atb":[[3.4,87.1],[3.15,97.23],[3.65,39.44]],"id":49546922},{"atl":[[16.5,8.99],[23,9.5]],"id":49546922},{"atb":[[1.79,264.63],[1.89,117.44],[1.84,248.88]],"id":70003372},{"atl":[[5.1,33.99],[6.2,40.2]],"id":70003372},{"atb":[[38,2.82],[24,9.08],[29,7.46]],"id":40917581},{"atl":[[550,0.38],[450,0.3]],"id":40917581}],"con":true,"img":false}]}
{"op":"mcm","clk":"11448277248","pt":1717288128429,"mc":[{"id":"1.229554925","marketDefinition":{"bspMarket":true,"turnInPlayEnabled":false,"persistenceEnabled":false,"marketBaseRate":7.0,"eventId":"33318908","eventTypeId":"4339","numberOfWinners":1,"bettingType":"ODDS","marketType":"WIN","marketTime":"2024-06-02T10:41:00.000Z","suspendTime":"2024-06-02T10:41:00.000Z","bspReconciled":false,"complete":true,"inPlay":false,"crossMatching":true,"runnersVoidable":false,"numberOfActiveRunners":6,"betDelay":0,"status":"OPEN","runners":[{"status":"ACTIVE","sortPriority":1,"id":40917581,"name":"1. Sophia Palms"},{"status":"ACTIVE","sortPriority":2,"id":47148562,"name":"2. Under Siege"},{"status":"ACTIVE","sortPriority":3,"id":49546922,"name":"4. Uno Whiskey"},{"status":"ACTIVE","sortPriority":4,"id":70003372,"name":"5. Southern Sun"},{"status":"ACTIVE","sortPriority":5,"id":48638605,"name":"7. Lochinvar Aloisi"},{"status":"ACTIVE","sortPriority":6,"id":64343695,"name":"8. Punching Poncho"}],"regulators":["MR_INT"],"venue":"Murray Bridge","countryCode":"AU","discountAllowed":true,"timezone":"Australia/Adelaide","openDate":"2024-06-02T08:21:00.000Z","version":5962327449,"name":"R8 530m Heat","eventName":"Murray Bridge (AUS) 2nd Jun"},"rc":[{"atb":[[2.86,56.19],[2.66,125.93],[2.76,118.78]],"id":47148562},{"atl":[[9.8,15.83],[14.5,15.48]],"id":47148562},{"spn":6.33,"spf":"NaN","id":47148562},{"atb":[[17,6.53],[12,19],[14.5,15.48]],"id":64343695},{"atl":[[350,0.59],[250,0.55]],"id":64343695},{"spn":133.5,"spf":"NaN","id":64343695},{"atb":[[5.8,43.55],[7.6,15.83],[6.6,37.33]],"id":48638605},{"atl":[[75,1.88],[150,1.4]],"id":48638605},{"spn":41.3,"spf":"NaN","id":48638605},{"atb":[[3.4,87.1],[3.15,97.23],[3.65,39.44]],"id":49546922},{"atl":[[16.5,8.99],[23,9.5]],"id":49546922},{"spn":10.07,"spf":"NaN","id":49546922},{"spl":[[1.01,31.39]],"id":70003372},{"atb":[[1.79,264.63],[1.89,117.44],[1.84,248.88]],"id":70003372},{"atl":[[5.1,33.99],[6.2,40.2]],"id":70003372},{"spn":1.89,"spf":1.0,"id":70003372},{"atb":[[38,2.82],[24,9.08],[29,7.46]],"id":40917581},{"atl":[[550,0.38],[450,0.3]],"id":40917581},{"spn":244.0,"spf":"NaN","id":40917581}],"con":true,"img":true}]}
{"op":"mcm","clk":"11448289496","pt":1717288232637,"mc":[{"id":"1.229554925","rc":[{"atb":[[17,0],[12,0],[14.5,0]],"id":64343695},{"atl":[[350,0],[250,0]],"id":64343695},{"spn":"NaN","spf":"NaN","id":64343695},{"atb":[[5.8,0],[7.6,0],[6.6,0]],"id":48638605},{"atl":[[75,0],[150,0]],"id":48638605},{"spn":"NaN","spf":"NaN","id":48638605},{"atb":[[38,0],[24,0],[29,0]],"id":40917581},{"atl":[[550,0],[450,0]],"id":40917581},{"spn":"NaN","spf":"NaN","id":40917581}],"con":true,"img":false}]}
{"op":"mcm","clk":"11448290414","pt":1717288245743,"mc":[{"id":"1.229554925","rc":[{"atb":[[17,6.53],[12,19],[14.5,15.48]],"id":64343695},{"atl":[[350,0.59],[250,0.55]],"id":64343695},{"atb":[[5.6,45.44],[7.2,16.86],[6.2,40.2]],"id":48638605},{"atl":[[65,2.17],[130,1.62]],"id":48638605},{"atb":[[17,13.06],[19.5,11.3],[24,4.54]],"id":40917581},{"atl":[[340,0.41],[440,0.47]],"id":40917581}],"con":true,"img":false}]}
{"op":"mcm","clk":"11448292488","pt":1717288274268,"mc":[{"id":"1.229554925","rc":[{"atb":[[2.86,0],[2.66,0],[2.76,0]],"id":47148562},{"atl":[[9.8,0],[14.5,0]],"id":47148562},{"atb":[[17,0],[12,0],[14.5,0]],"id":64343695},{"atl":[[350,0],[250,0]],"id":64343695},{"atb":[[5.6,0],[7.2,0],[6.2,0]],"id":48638605},{"atl":[[65,0],[130,0]],"id":48638605},{"atb":[[3.4,0],[3.15,0],[3.65,0]],"id":49546922},{"atl":[[16.5,0],[23,0]],"id":49546922},{"atb":[[1.79,0],[1.89,0],[1.84,0]],"id":70003372},{"atl":[[5.1,0],[6.2,0]],"id":70003372},{"atb":[[17,0],[19.5,0],[24,0]],"id":40917581},{"atl":[[340,0],[440,0]],"id":40917581}],"con":true,"img":false}]}
{"op":"mcm","clk":"11448293813","pt":1717288291678,"mc":[{"id":"1.229554925","rc":[{"atb":[[2.86,56.19],[2.66,125.93],[2.76,118.78]],"id":47148562},{"atl":[[9.8,15.83],[14.5,15.48]],"id":47148562},{"atb":[[9.2,25.49],[10.5,11],[8.2,29.03]],"id":64343695},{"atl":[[280,0.74],[180,0.77]],"id":64343695},{"atb":[[5.6,45.44],[7.2,16.86],[6.2,40.2]],"id":48638605},{"atl":[[65,2.17],[130,1.62]],"id":48638605},{"atb":[[3.25,92.91],[3.5,83.62],[3.75,38]],"id":49546922},{"atl":[[17.5,8.44],[25,8.71]],"id":49546922},{"atb":[[1.79,264.63],[1.89,117.44],[1.84,248.88]],"id":70003372},{"atl":[[5.1,33.99],[6.2,40.2]],"id":70003372},{"atb":[[17,13.06],[19.5,11.3],[24,4.54]],"id":40917581},{"atl":[[340,0.41],[440,0.47]],"id":40917581}],"con":true,"img":false}]}
{"op":"mcm","clk":"11448298286","pt":1717288351588,"mc":[{"id":"1.229554925","rc":[{"atb":[[2.86,0],[2.66,0],[2.76,0]],"id":47148562},{"atl":[[9.8,0],[14.5,0]],"id":47148562},{"spn":"NaN","spf":"NaN","id":47148562},{"atb":[[9.2,0],[10.5,0],[8.2,0]],"id":64343695},{"atl":[[280,0],[180,0]],"id":64343695},{"atb":[[5.6,0],[7.2,0],[6.2,0]],"id":48638605},{"atl":[[65,0],[130,0]],"id":48638605},{"atb":[[3.25,0],[3.5,0],[3.75,0]],"id":49546922},{"atl":[[17.5,0],[25,0]],"id":49546922},{"spn":"NaN","spf":"NaN","id":49546922},{"atb":[[1.79,0],[1.89,0],[1.84,0]],"id":70003372},{"atl":[[5.1,0],[6.2,0]],"id":70003372},{"spn":1.0,"spf":1.0,"id":70003372},{"atb":[[17,0],[19.5,0],[24,0]],"id":40917581},{"atl":[[340,0],[440,0]],"id":40917581}],"con":true,"img":false}]}
{"op":"mcm","clk":"11448300819","pt":1717288384246,"mc":[{"id":"1.229554925","rc":[{"atb":[[2.86,56.19],[2.66,125.93],[2.76,118.78]],"id":47148562},{"atl":[[9.8,15.83],[14.5,15.48]],"id":47148562},{"atb":[[9,26.13],[10,23.22],[12.5,9.08]],"id":64343695},{"atl":[[310,0.67],[210,0.66]],"id":64343695},{"atb":[[5.6,45.44],[7.2,16.86],[6.2,40.2]],"id":48638605},{"atl":[[65,2.17],[130,1.62]],"id":48638605},{"atb":[[3.25,92.91],[3.5,83.62],[3.75,38]],"id":49546922},{"atl":[[17.5,8.44],[25,8.71]],"id":49546922},{"atb":[[1.73,286.38],[1.83,125.93],[1.78,268.02]],"id":70003372},{"atl":[[4.5,39.81],[5.5,46.45]],"id":70003372},{"atb":[[19.5,11.3],[24,9.08],[29,3.73]],"id":40917581},{"atl":[[400,0.35],[500,0.41]],"id":40917581}],"con":true,"img":false}]}
{"op":"mcm","clk":"11448305326","pt":1717288449310,"mc":[{"id":"1.229554925","rc":[{"atb":[[2.86,0],[2.66,0],[2.76,0]],"id":47148562},{"atl":[[9.8,0],[14.5,0]],"id":47148562},{"atb":[[9,0],[10,0],[12.5,0]],"id":64343695},{"atl":[[310,0],[210,0]],"id":64343695},{"atb":[[5.6,0],[7.2,0],[6.2,0]],"id":48638605},{"atl":[[65,0],[130,0]],"id":48638605},{"atb":[[3.25,0],[3.5,0],[3.75,0]],"id":49546922},{"atl":[[17.5,0],[25,0]],"id":49546922},{"atb":[[1.73,0],[1.83,0],[1.78,0]],"id":70003372},{"atl":[[4.5,0],[5.5,0]],"id":70003372},{"atb":[[19.5,0],[24,0],[29,0]],"id":40917581},{"atl":[[400,0],[500,0]],"id":40917581}],"con":true,"img":false}]}
{"op":"mcm","clk":"11448307458","pt":1717288481177,"mc":[{"id":"1.229554925","rc":[{"atb":[[2.86,56.19],[2.66,125.93],[2.76,118.78]],"id":47148562},{"atl":[[9.8,15.83],[14.5,15.48]],"id":47148562},{"atb":[[11,20.9],[13.5,8.36],[9.4,24.88]],"id":64343695},{"atl":[[320,0.65],[220,0.63]],"id":64343695},{"atb":[[5.6,45.44],[7.2,16.86],[6.2,40.2]],"id":48638605},{"atl":[[65,2.17],[130,1.62]],"id":48638605},{"atb":[[2.86,112.39],[2.96,53.33],[2.76,118.78]],"id":49546922},{"atl":[[10.5,14.66],[15.5,14.41]],"id":49546922},{"atb":[[1.73,286.38],[1.83,125.93],[1.78,268.02]],"id":70003372},{"atl":[[4.5,39.81],[5.5,46.45]],"id":70003372},{"atb":[[19.5,11.3],[24,9.08],[29,3.73]],"id":40917581},{"atl":[[400,0.35],[500,0.41]],"id":40917581}],"con":true,"img":false}]}
{"op":"mcm","clk":"11448310805","pt":1717288529482,"mc":[{"id":"1.229554925","rc":[{"spn":6.33,"spf":"NaN","id":47148562},{"atb":[[11,0],[13.5,0],[9.4,0]],"id":64343695},{"atl":[[320,0],[220,0]],"id":64343695},{"spn":36.1,"spf":"NaN","id":48638605},{"atb":[[2.86,0],[2.96,0],[2.76,0]],"id":49546922},{"atl":[[10.5,0],[15.5,0]],"id":49546922},{"atb":[[1.73,0],[1.83,0],[1.78,0]],"id":70003372},{"atl":[[4.5,0],[5.5,0]],"id":70003372},{"atb":[[19.5,0],[24,0],[29,0]],"id":40917581},{"atl":[[400,0],[500,0]],"id":40917581}],"con":true,"img":false}]}
{"op":"mcm","clk":"11448312152","pt":1717288548667,"mc":[{"id":"1.229554925","rc":[{"atb":[[12,19],[9.8,23.75],[14.5,7.74]],"id":64343695},{"atl":[[330,0.63],[230,0.6]],"id":64343695},{"atb":[[2.86,56.19],[2.66,125.93],[2.76,118.78]],"id":49546922},{"atl":[[9.8,15.83],[14.5,15.48]],"id":49546922},{"atb":[[1.79,264.63],[1.89,117.44],[1.84,248.88]],"id":70003372},{"atl":[[5.1,33.99],[6.2,40.2]],"id":70003372},{"atb":[[19.5,11.3],[24,9.08],[29,3.73]],"id":40917581},{"atl":[[400,0.35],[500,0.41]],"id":40917581}],"con":true,"img":false}]}
{"op":"mcm","clk":"11448330087","pt":1717288800135,"mc":[{"id":"1.229554925","rc":[{"atb":[[2.86,0],[2.66,0],[2.76,0]],"id":47148562},{"atl":[[9.8,0],[14.5,0]],"id":47148562},{"spn":"NaN","spf":"NaN","id":47148562},{"atb":[[12,0],[9.8,0],[14.5,0]],"id":64343695},{"atl":[[330,0],[230,0]],"id":64343695},{"atb":[[2.86,0],[2.66,0],[2.76,0]],"id":49546922},{"atl":[[9.8,0],[14.5,0]],"id":49546922},{"spn":1.89,"spf":1.0,"id":70003372},{"spn":214.5,"spf":"NaN","id":40917581}],"con":true,"img":false}]}
{"op":"mcm","clk":"11448330740","pt":1717288810059,"mc":[{"id":"1.229554925","rc":[{"atb":[[2.86,56.19],[2.66,125.93],[2.76,118.78]],"id":47148562},{"atl":[[9.8,15.83],[14.5,15.48]],"id":47148562},{"atb":[[12,19],[9.8,23.75],[14.5,7.74]],"id":64343695},{"atl":[[330,0.63],[230,0.6]],"id":64343695},{"atb":[[2.72,60.77],[2.52,137.53],[2.62,129.05]],"id":49546922},{"atl":[[9,17.42],[12.5,18.18]],"id":49546922}],"con":true,"img":false}]}
{"op":"mcm","clk":"11448332054","pt":1717288831250,"mc":[{"id":"1.229554925","rc":[{"atb":[[2.86,0],[2.66,0],[2.76,0]],"id":47148562},{"atl":[[9.8,0],[14.5,0]],"id":47148562},{"atb":[[12,0],[9.8,0],[14.5,0]],"id":64343695},{"atl":[[330,0],[230,0]],"id":64343695},{"atb":[[5.6,0],[7.2,0],[6.2,0]],"id":48638605},{"atl":[[65,0],[130,0]],"id":48638605},{"atb":[[2.72,0],[2.52,0],[2.62,0]],"id":49546922},{"atl":[[9,0],[12.5,0]],"id":49546922},{"atb":[[1.79,0],[1.89,0],[1.84,0]],"id":70003372},{"atl":[[5.1,0],[6.2,0]],"id":70003372}],"con":true,"img":false}]}
{"op":"mcm","clk":"11448332531","pt":1717288838850,"mc":[{"id":"1.229554925","rc":[{"atb":[[2.8,116.14],[2.9,55.01],[2.7,122.97]],"id":47148562},{"atl":[[10,15.48],[15,14.93]],"id":47148562},{"atb":[[12,19],[9.8,23.75],[14.5,7.74]],"id":64343695},{"atl":[[330,0.63],[230,0.6]],"id":64343695},{"atb":[[5.8,43.55],[7.6,15.83],[6.6,37.33]],"id":48638605},{"atl":[[75,1.88],[150,1.4]],"id":48638605},{"atb":[[2.72,60.77],[2.52,137.53],[2.62,129.05]],"id":49546922},{"atl":[[9,17.42],[12.5,18.18]],"id":49546922},{"atb":[[1.79,264.63],[1.89,117.44],[1.84,248.88]],"id":70003372},{"atl":[[5.1,33.99],[6.2,40.2]],"id":70003372}],"con":true,"img":false}]}
{"op":"mcm","clk":"11448333310","pt":1717288850467,"mc":[{"id":"1.229554925","rc":[{"atb":[[2.8,0],[2.9,0],[2.7,0]],"id":47148562},{"atl":[[10,0],[15,0]],"id":47148562},{"atb":[[12,0],[9.8,0],[14.5,0]],"id":64343695},{"atl":[[330,0],[230,0]],"id":64343695},{"atb":[[5.8,0],[7.6,0],[6.6,0]],"id":48638605},{"atl":[[75,0],[150,0]],"id":48638605},{"atb":[[2.72,0],[2.52,0],[2.62,0]],"id":49546922},{"atl":[[9,0],[12.5,0]],"id":49546922},{"atb":[[19.5,0],[24,0],[29,0]],"id":40917581},{"atl":[[400,0],[500,0]],"id":40917581}],"con":true,"img":false}]}
{"op":"mcm","clk":"11448333846","pt":1717288858189,"mc":[{"id":"1.229554925","rc":[{"atb":[[2.86,112.39],[2.96,53.33],[2.76,118.78]],"id":47148562},{"atl":[[10.5,14.66],[15.5,14.41]],"id":47148562},{"atb":[[10.5,22],[13,17.42],[15.5,7.2]],"id":64343695},{"atl":[[340,0.61],[240,0.58]],"id":64343695},{"atb":[[5.8,43.55],[7.6,15.83],[6.6,37.33]],"id":48638605},{"atl":[[75,1.88],[150,1.4]],"id":48638605},{"atb":[[2.72,60.77],[2.52,137.53],[2.62,129.05]],"id":49546922},{"atl":[[9,17.42],[12.5,18.18]],"id":49546922},{"atb":[[38,2.82],[24,9.08],[29,7.46]],"id":40917581},{"atl":[[550,0.38],[450,0.3]],"id":40917581}],"con":true,"img":false}]}
{"op":"mcm","clk":"11448336313","pt":1717288889878,"mc":[{"id":"1.229554925","rc":[{"atb":[[2.86,0],[2.96,0],[2.76,0]],"id":47148562},{"atl":[[10.5,0],[15.5,0]],"id":47148562},{"atb":[[10.5,0],[13,0],[15.5,0]],"id":64343695},{"atl":[[340,0],[240,0]],"id":64343695},{"atb":[[5.8,0],[7.6,0],[6.6,0]],"id":48638605},{"atl":[[75,0],[150,0]],"id":48638605},{"spn":"NaN","spf":"NaN","id":48638605},{"atb":[[2.72,0],[2.52,0],[2.62,0]],"id":49546922},{"atl":[[9,0],[12.5,0]],"id":49546922},{"atb":[[38,0],[24,0],[29,0]],"id":40917581},{"atl":[[550,0],[450,0]],"id":40917581},{"spn":"NaN","spf":"NaN","id":40917581}],"con":true,"img":false}]}
{"op":"mcm","clk":"11448336545","pt":1717288892675,"mc":[{"id":"1.229554925","rc":[{"atb":[[2.86,112.39],[2.96,53.33],[2.76,118.78]],"id":47148562},{"atl":[[10.5,14.66],[15.5,14.41]],"id":47148562},{"atb":[[10.5,22],[13,17.42],[15.5,7.2]],"id":64343695},{"atl":[[340,0.61],[240,0.58]],"id":64343695},{"atb":[[7.2,33.71],[6.2,40.2],[8.2,14.51]],"id":48638605},{"atl":[[90,1.56],[180,1.16]],"id":48638605},{"atb":[[2.56,134.01],[2.46,143.19],[2.66,62.96]],"id":49546922},{"atl":[[8.6,18.33],[11.5,19.91]],"id":49546922},{"atb":[[32,6.74],[42,2.54],[26,8.36]],"id":40917581},{"atl":[[570,0.36],[470,0.29]],"id":40917581}],"con":true,"img":false}]}
{"op":"mcm","clk":"11448344112","pt":1717288986613,"mc":[{"id":"1.229554925","rc":[{"atb":[[2.86,0],[2.96,0],[2.76,0]],"id":47148562},{"atl":[[10.5,0],[15.5,0]],"id":47148562},{"spn":127.75,"spf":"NaN","id":64343695},{"spn":49.1,"spf":"NaN","id":48638605},{"spn":5.63,"spf":"NaN","id":49546922},{"atb":[[1.79,0],[1.89,0],[1.84,0]],"id":70003372},{"atl":[[5.1,0],[6.2,0]],"id":70003372},{"spn":1.0,"spf":1.0,"id":70003372},{"spn":256.0,"spf":"NaN","id":40917581}],"con":true,"img":false}]}
{"op":"mcm","clk":"11448345387","pt":1717289003541,"mc":[{"id":"1.229554925","rc":[{"atb":[[2.88,111.2],[2.98,52.79],[2.78,117.44]],"id":47148562},{"atl":[[10.5,14.66],[15.5,14.41]],"id":47148562},{"atb":[[1.79,264.63],[1.89,117.44],[1.84,248.88]],"id":70003372},{"atl":[[5.1,33.99],[6.2,40.2]],"id":70003372}],"con":true,"img":false}]}
{"op":"mcm","clk":"11448350573","pt":1717289071605,"mc":[{"id":"1.229554925","rc":[{"spn":6.74,"spf":"NaN","id":47148562},{"atb":[[10.5,0],[13,0],[15.5,0]],"id":64343695},{"atl":[[340,0],[240,0]],"id":64343695},{"spn":"NaN","spf":"NaN","id":64343695},{"atb":[[7.2,0],[6.2,0],[8.2,0]],"id":48638605},{"atl":[[90,0],[180,0]],"id":48638605},{"spn":"NaN","spf":"NaN","id":48638605},{"atb":[[1.79,0],[1.89,0],[1.84,0]],"id":70003372},{"atl":[[5.1,0],[6.2,0]],"id":70003372}],"con":true,"img":false}]}
{"op":"mcm","clk":"11448351093","pt":1717289078691,"mc":[{"id":"1.229554925","rc":[{"atb":[[16.5,6.74],[11.5,19.91],[14,16.08]],"id":64343695},{"atl":[[350,0.59],[250,0.55]],"id":64343695},{"atb":[[8.6,13.75],[7.6,31.67],[6.6,37.33]],"id":48638605},{"atl":[[100,1.4],[200,1.05]],"id":48638605},{"atb":[[1.79,264.63],[1.89,117.44],[1.84,248.88]],"id":70003372},{"atl":[[5.1,33.99],[6.2,40.2]],"id":70003372}],"con":true,"img":false}]}
{"op":"mcm","clk":"11448355207","pt":1717289130591,"mc":[{"id":"1.229554925","rc":[{"atb":[[16.5,0],[11.5,0],[14,0]],"id":64343695},{"atl":[[350,0],[250,0]],"id":64343695},{"atb":[[8.6,0],[7.6,0],[6.6,0]],"id":48638605},{"atl":[[100,0],[200,0]],"id":48638605},{"atb":[[32,0],[42,0],[26,0]],"id":40917581},{"atl":[[570,0],[470,0]],"id":40917581}],"con":true,"img":false}]}
{"op":"mcm","clk":"11448355883","pt":1717289139416,"mc":[{"id":"1.229554925","rc":[{"atb":[[16.5,6.74],[11.5,19.91],[14,16.08]],"id":64343695},{"atl":[[350,0.59],[250,0.55]],"id":64343695},{"spn":133.25,"spf":"NaN","id":64343695},{"atb":[[8.6,13.75],[7.6,31.67],[6.6,37.33]],"id":48638605},{"atl":[[100,1.4],[200,1.05]],"id":48638605},{"spn":54.3,"spf":"NaN","id":48638605},{"spn":1.89,"spf":1.0,"id":70003372},{"atb":[[38,2.82],[24,9.08],[29,7.46]],"id":40917581},{"atl":[[550,0.38],[450,0.3]],"id":40917581},{"spn":244.0,"spf":"NaN","id":40917581}],"con":true,"img":false}]}
{"op":"mcm","clk":"11448357429","pt":1717289159719,"mc":[{"id":"1.229554925","rc":[{"atb":[[38,0],[24,0],[29,0]],"id":40917581},{"atl":[[550,0],[450,0]],"id":40917581}],"con":true,"img":false}]}
{"op":"mcm","clk":"11448357912","pt":1717289165668,"mc":[{"id":"1.229554925","rc":[{"atb":[[32,6.74],[42,2.54],[26,8.36]],"id":40917581},{"atl":[[570,0.36],[470,0.29]],"id":40917581}],"con":true,"img":false}]}
{"op":"mcm","clk":"11448516312","pt":1717291543831,"mc":[{"id":"1.229554925","rc":[{"atb":[[2.88,0],[2.98,0],[2.78,0]],"id":47148562},{"atl":[[10.5,0],[15.5,0]],"id":47148562},{"spn":"NaN","spf":"NaN","id":47148562},{"atb":[[16.5,0],[11.5,0],[14,0]],"id":64343695},{"atl":[[350,0],[250,0]],"id":64343695},{"spn":"NaN","spf":"NaN","id":64343695},{"atb":[[8.6,0],[7.6,0],[6.6,0]],"id":48638605},{"atl":[[100,0],[200,0]],"id":48638605},{"spn":"NaN","spf":"NaN","id":48638605},{"atb":[[2.56,0],[2.46,0],[2.66,0]],"id":49546922},{"atl":[[8.6,0],[11.5,0]],"id":49546922},{"spn":"NaN","spf":"NaN","id":49546922},{"atb":[[1.79,0],[1.89,0],[1.84,0]],"id":70003372},{"atl":[[5.1,0],[6.2,0]],"id":70003372},{"spn":1.0,"spf":1.0,"id":70003372},{"atb":[[32,0],[42,0],[26,0]],"id":40917581},{"atl":[[570,0],[470,0]],"id":40917581},{"spn":"NaN","spf":"NaN","id":40917581}],"con":true,"img":false}]}
{"op":"mcm","clk":"11448516748","pt":1717291550972,"mc":[{"id":"1.229554925","rc":[{"atb":[[2.88,111.2],[2.98,52.79],[2.78,117.44]],"id":47148562},{"atl":[[10.5,14.66],[15.5,14.41]],"id":47148562},{"atb":[[16.5,6.74],[11.5,19.91],[14,16.08]],"id":64343695},{"atl":[[350,0.59],[250,0.55]],"id":64343695},{"atb":[[8.6,13.75],[7.6,31.67],[6.6,37.33]],"id":48638605},{"atl":[[100,1.4],[200,1.05]],"id":48638605},{"atb":[[2.72,60.77],[2.52,137.53],[2.62,129.05]],"id":49546922},{"atl":[[9,17.42],[12.5,18.18]],"id":49546922},{"atb":[[1.73,286.38],[1.83,125.93],[1.78,268.02]],"id":70003372},{"atl":[[4.5,39.81],[5.5,46.45]],"id":70003372},{"atb":[[32,6.74],[42,2.54],[26,8.36]],"id":40917581},{"atl":[[570,0.36],[470,0.29]],"id":40917581}],"con":true,"img":false}]}
{"op":"mcm","clk":"11448517449","pt":1717291562388,"mc":[{"id":"1.229554925","rc":[{"atb":[[2.88,0],[2.98,0],[2.78,0]],"id":47148562},{"atl":[[10.5,0],[15.5,0]],"id":47148562},{"atb":[[16.5,0],[11.5,0],[14,0]],"id":64343695},{"atl":[[350,0],[250,0]],"id":64343695},{"atb":[[2.72,0],[2.52,0],[2.62,0]],"id":49546922},{"atl":[[9,0],[12.5,0]],"id":49546922},{"atb":[[1.73,0],[1.83,0],[1.78,0]],"id":70003372},{"atl":[[4.5,0],[5.5,0]],"id":70003372},{"atb":[[32,0],[42,0],[26,0]],"id":40917581},{"atl":[[570,0],[470,0]],"id":40917581}],"con":true,"img":false}]}
{"op":"mcm","clk":"11448517838","pt":1717291568298,"mc":[{"id":"1.229554925","rc":[{"atb":[[3.1,49.77],[2.84,113.61],[2.94,107.76]],"id":47148562},{"atl":[[16,13.93],[11,13.93]],"id":47148562},{"atb":[[16.5,6.74],[11.5,19.91],[14,16.08]],"id":64343695},{"atl":[[350,0.59],[250,0.55]],"id":64343695},{"atb":[[2.72,60.77],[2.52,137.53],[2.62,129.05]],"id":49546922},{"atl":[[9,17.42],[12.5,18.18]],"id":49546922},{"atb":[[1.73,286.38],[1.83,125.93],[1.78,268.02]],"id":70003372},{"atl":[[4.5,39.81],[5.5,46.45]],"id":70003372},{"atb":[[32,6.74],[42,2.54],[26,8.36]],"id":40917581},{"atl":[[570,0.36],[470,0.29]],"id":40917581}],"con":true,"img":false}]}
{"op":"mcm","clk":"11448521432","pt":1717291630165,"mc":[{"id":"1.229554925","rc":[{"spn":7.05,"spf":"NaN","id":47148562},{"atb":[[16.5,0],[11.5,0],[14,0]],"id":64343695},{"atl":[[350,0],[250,0]],"id":64343695},{"atb":[[8.6,0],[7.6,0],[6.6,0]],"id":48638605},{"atl":[[100,0],[200,0]],"id":48638605},{"spn":5.86,"spf":"NaN","id":49546922},{"spn":1.83,"spf":1.0,"id":70003372},{"atb":[[32,0],[42,0],[26,0]],"id":40917581},{"atl":[[570,0],[470,0]],"id":40917581}],"con":true,"img":false}]}
{"op":"mcm","clk":"11448521774","pt":1717291635884,"mc":[{"id":"1.229554925","rc":[{"atb":[[17,6.53],[12,19],[14.5,15.48]],"id":64343695},{"atl":[[350,0.59],[250,0.55]],"id":64343695},{"atb":[[8.6,13.75],[7.6,31.67],[6.6,37.33]],"id":48638605},{"atl":[[100,1.4],[200,1.05]],"id":48638605},{"atb":[[32,6.74],[42,2.54],[26,8.36]],"id":40917581},{"atl":[[570,0.36],[470,0.29]],"id":40917581}],"con":true,"img":false}]}
{"op":"mcm","clk":"11448522288","pt":1717291645993,"mc":[{"id":"1.229554925","rc":[{"atb":[[3.1,0],[2.84,0],[2.94,0]],"id":47148562},{"atl":[[16,0],[11,0]],"id":47148562},{"atb":[[8.6,0],[7.6,0],[6.6,0]],"id":48638605},{"atl":[[100,0],[200,0]],"id":48638605},{"atb":[[2.72,0],[2.52,0],[2.62,0]],"id":49546922},{"atl":[[9,0],[12.5,0]],"id":49546922}],"con":true,"img":false}]}
{"op":"mcm","clk":"11448522564","pt":1717291651915,"mc":[{"id":"1.229554925","rc":[{"atb":[[3.1,49.77],[2.84,113.61],[2.94,107.76]],"id":47148562},{"atl":[[16,13.93],[11,13.93]],"id":47148562},{"atb":[[8.6,13.75],[7.6,31.67],[6.6,37.33]],"id":48638605},{"atl":[[100,1.4],[200,1.05]],"id":48638605},{"atb":[[2.72,60.77],[2.52,137.53],[2.62,129.05]],"id":49546922},{"atl":[[9,17.42],[12.5,18.18]],"id":49546922}],"con":true,"img":false}]}
{"op":"mcm","clk":"11448523124","pt":1717291661917,"mc":[{"id":"1.229554925","rc":[{"atb":[[3.1,0],[2.84,0],[2.94,0]],"id":47148562},{"atl":[[16,0],[11,0]],"id":47148562},{"atb":[[17,0],[12,0],[14.5,0]],"id":64343695},{"atl":[[350,0],[250,0]],"id":64343695},{"atb":[[8.6,0],[7.6,0],[6.6,0]],"id":48638605},{"atl":[[100,0],[200,0]],"id":48638605},{"atb":[[2.72,0],[2.52,0],[2.62,0]],"id":49546922},{"atl":[[9,0],[12.5,0]],"id":49546922},{"atb":[[1.73,0],[1.83,0],[1.78,0]],"id":70003372},{"atl":[[4.5,0],[5.5,0]],"id":70003372},{"atb":[[32,0],[42,0],[26,0]],"id":40917581},{"atl":[[570,0],[470,0]],"id":40917581}],"con":true,"img":false}]}
{"op":"mcm","clk":"11448523428","pt":1717291667331,"mc":[{"id":"1.229554925","rc":[{"atb":[[3.1,49.77],[2.84,113.61],[2.94,107.76]],"id":47148562},{"atl":[[16,13.93],[11,13.93]],"id":47148562},{"atb":[[18,6.14],[13,17.42],[15.5,14.41]],"id":64343695},{"atl":[[260,0.53],[360,0.58]],"id":64343695},{"atb":[[8,29.86],[9,13.06],[7,34.84]],"id":48638605},{"atl":[[210,0.99],[110,1.27]],"id":48638605},{"atb":[[2.72,60.77],[2.52,137.53],[2.62,129.05]],"id":49546922},{"atl":[[9,17.42],[12.5,18.18]],"id":49546922},{"atb":[[1.79,132.31],[1.74,282.51],[1.69,302.98]],"id":70003372},{"atl":[[4.3,42.23],[5.3,48.61]],"id":70003372},{"atb":[[34,6.33],[44,2.43],[27,8.04]],"id":40917581},{"atl":[[580,0.36],[480,0.29]],"id":40917581}],"con":true,"img":false}]}
{"op":"mcm","clk":"11448527332","pt":1717291733107,"mc":[{"id":"1.229554925","rc":[{"atb":[[3.1,0],[2.84,0],[2.94,0]],"id":47148562},{"atl":[[16,0],[11,0]],"id":47148562},{"spn":"NaN","spf":"NaN","id":47148562},{"atb":[[18,0],[13,0],[15.5,0]],"id":64343695},{"atl":[[260,0],[360,0]],"id":64343695},{"spn":59.5,"spf":"NaN","id":48638605},{"atb":[[2.72,0],[2.52,0],[2.62,0]],"id":49546922},{"atl":[[9,0],[12.5,0]],"id":49546922},{"spn":"NaN","spf":"NaN","id":49546922},{"atb":[[1.79,0],[1.74,0],[1.69,0]],"id":70003372},{"atl":[[4.3,0],[5.3,0]],"id":70003372},{"spn":1.0,"spf":1.0,"id":70003372},{"atb":[[34,0],[44,0],[27,0]],"id":40917581},{"atl":[[580,0],[480,0]],"id":40917581}],"con":true,"img":false}]}
{"op":"mcm","clk":"11448527774","pt":1717291740829,"mc":[{"id":"1.229554925","rc":[{"atb":[[3.1,49.77],[2.84,113.61],[2.94,107.76]],"id":47148562},{"atl":[[16,13.93],[11,13.93]],"id":47148562},{"atb":[[17,6.53],[12,19],[14.5,15.48]],"id":64343695},{"atl":[[350,0.59],[250,0.55]],"id":64343695},{"atb":[[2.72,60.77],[2.52,137.53],[2.62,129.05]],"id":49546922},{"atl":[[9,17.42],[12.5,18.18]],"id":49546922},{"atb":[[1.79,132.31],[1.74,282.51],[1.69,302.98]],"id":70003372},{"atl":[[4.3,42.23],[5.3,48.61]],"id":70003372},{"atb":[[32,6.74],[42,2.54],[26,8.36]],"id":40917581},{"atl":[[570,0.36],[470,0.29]],"id":40917581}],"con":true,"img":false}]}
{"op":"mcm","clk":"11448528407","pt":1717291751125,"mc":[{"id":"1.229554925","rc":[{"atb":[[3.1,0],[2.84,0],[2.94,0]],"id":47148562},{"atl":[[16,0],[11,0]],"id":47148562},{"atb":[[17,0],[12,0],[14.5,0]],"id":64343695},{"atl":[[350,0],[250,0]],"id":64343695},{"atb":[[8,0],[9,0],[7,0]],"id":48638605},{"atl":[[210,0],[110,0]],"id":48638605},{"atb":[[2.72,0],[2.52,0],[2.62,0]],"id":49546922},{"atl":[[9,0],[12.5,0]],"id":49546922},{"atb":[[1.79,0],[1.74,0],[1.69,0]],"id":70003372},{"atl":[[4.3,0],[5.3,0]],"id":70003372},{"atb":[[32,0],[42,0],[26,0]],"id":40917581},{"atl":[[570,0],[470,0]],"id":40917581}],"con":true,"img":false}]}
{"op":"mcm","clk":"11448528848","pt":1717291758052,"mc":[{"id":"1.229554925","rc":[{"atb":[[2.86,112.39],[3.15,48.61],[2.96,106.66]],"id":47148562},{"atl":[[16,13.93],[11,13.93]],"id":47148562},{"atb":[[18,6.14],[13,17.42],[15.5,14.41]],"id":64343695},{"atl":[[260,0.53],[360,0.58]],"id":64343695},{"atb":[[8,29.86],[9,13.06],[7,34.84]],"id":48638605},{"atl":[[210,0.99],[110,1.27]],"id":48638605},{"atb":[[2.72,60.77],[2.52,137.53],[2.62,129.05]],"id":49546922},{"atl":[[9,17.42],[12.5,18.18]],"id":49546922},{"atb":[[1.79,132.31],[1.74,282.51],[1.69,302.98]],"id":70003372},{"atl":[[4.3,42.23],[5.3,48.61]],"id":70003372},{"atb":[[34,6.33],[44,2.43],[27,8.04]],"id":40917581},{"atl":[[580,0.36],[480,0.29]],"id":40917581}],"con":true,"img":false}]}
{"op":"mcm","clk":"11448629982","pt":1717293528420,"mc":[{"id":"1.229554925","marketDefinition":{"bspMarket":true,"turnInPlayEnabled":false,"persistenceEnabled":false,"marketBaseRate":7.0,"eventId":"33318908","eventTypeId":"4339","numberOfWinners":1,"bettingType":"ODDS","marketType":"WIN","marketTime":"2024-06-02T10:41:00.000Z","suspendTime":"2024-06-02T10:41:00.000Z","bspReconciled":false,"complete":true,"inPlay":false,"crossMatching":true,"runnersVoidable":false,"numberOfActiveRunners":6,"betDelay":0,"status":"OPEN","runners":[{"status":"ACTIVE","sortPriority":1,"id":40917581,"name":"1. Sophia Palms"},{"status":"ACTIVE","sortPriority":2,"id":47148562,"name":"2. Under Siege"},{"status":"ACTIVE","sortPriority":3,"id":49546922,"name":"4. Uno Whiskey"},{"status":"ACTIVE","sortPriority":4,"id":70003372,"name":"5. Southern Sun"},{"status":"ACTIVE","sortPriority":5,"id":48638605,"name":"7. Lochinvar Aloisi"},{"status":"ACTIVE","sortPriority":6,"id":64343695,"name":"8. Punching Poncho"}],"regulators":["MR_INT"],"venue":"Murray Bridge","countryCode":"AU","discountAllowed":true,"timezone":"Australia/Adelaide","openDate":"2024-06-02T08:21:00.000Z","version":5962327449,"name":"R8 530m Heat","eventName":"Murray Bridge (AUS) 2nd Jun"},"rc":[{"atb":[[2.86,112.39],[3.15,48.61],[2.96,106.66]],"id":47148562},{"atl":[[16,13.93],[11,13.93]],"id":47148562},{"spn":7.07,"spf":"NaN","id":47148562},{"atb":[[18,6.14],[13,17.42],[15.5,14.41]],"id":64343695},{"atl":[[260,0.53],[360,0.58]],"id":64343695},{"spn":139.0,"spf":"NaN","id":64343695},{"atb":[[8,29.86],[9,13.06],[7,34.84]],"id":48638605},{"atl":[[210,0.99],[110,1.27]],"id":48638605},{"spn":59.5,"spf":"NaN","id":48638605},{"atb":[[2.72,60.77],[2.52,137.53],[2.62,129.05]],"id":49546922},{"atl":[[9,17.42],[12.5,18.18]],"id":49546922},{"spn":5.86,"spf":"NaN","id":49546922},{"spl":[[1.01,31.39]],"id":70003372},{"atb":[[1.79,132.31],[1.74,282.51],[1.69,302.98]],"id":70003372},{"atl":[[4.3,42.23],[5.3,48.61]],"id":70003372},{"spn":1.79,"spf":1.0,"id":70003372},{"atb":[[34,6.33],[44,2.43],[27,8.04]],"id":40917581},{"atl":[[580,0.36],[480,0.29]],"id":40917581},{"spn":262.0,"spf":"NaN","id":40917581}],"con":true,"img":true}]}
{"op":"mcm","clk":"11449026502","pt":1717302118975,"mc":[{"id":"1.229554925","rc":[{"spn":7.07,"spf":"NaN","id":47148562},{"spn":139.0,"spf":"NaN","id":64343695},{"spn":5.86,"spf":"NaN","id":49546922},{"atl":[[1.99,10.46]],"id":70003372},{"spn":1.79,"spf":1.0,"id":70003372},{"spn":262.0,"spf":"NaN","id":40917581}],"con":true,"img":false}]}
{"op":"mcm","clk":"11449033530","pt":1717302278386,"mc":[{"id":"1.229554925","rc":[{"atl":[[1.99,20.92]],"id":70003372}],"con":true,"img":false}]}
{"op":"mcm","clk":"11449042450","pt":1717302494999,"mc":[{"id":"1.229554925","rc":[{"atl":[[1.99,10.46]],"id":70003372}],"con":true,"img":false}]}
{"op":"mcm","clk":"11449191514","pt":1717305368262,"mc":[{"id":"1.229554925","rc":[{"atl":[[2.2,4.73]],"id":70003372}],"con":true,"img":false}]}
{"op":"mcm","clk":"11449191787","pt":1717305372253,"mc":[{"id":"1.229554925","rc":[{"trd":[[1.99,9.46]],"ltp":1.99,"tv":9.46,"id":70003372},{"atl":[[1.99,5.72]],"id":70003372}],"con":true,"img":false}]}
{"op":"mcm","clk":"11449358405","pt":1717307834775,"mc":[{"id":"1.229554925","rc":[{"atb":[[1.01,17.76]],"id":47148562},{"atl":[[990,0.85]],"id":47148562},{"atb":[[1.01,17.76]],"id":64343695},{"atl":[[990,0.85]],"id":64343695},{"atb":[[1.01,17.76]],"id":48638605},{"atl":[[990,0.85]],"id":48638605},{"atb":[[1.02,8.87]],"id":49546922},{"atl":[[990,0.85]],"id":49546922},{"atb":[[1.02,8.87]],"id":70003372},{"atl":[[1000,0.85]],"id":70003372},{"atb":[[1.03,5.92]],"id":40917581},{"atl":[[990,0.85]],"id":40917581}],"con":true,"img":false}]}
{"op":"mcm","clk":"11449586745","pt":1717311443722,"mc":[{"id":"1.229554925","rc":[{"atl":[[990,0.17]],"id":47148562},{"atl":[[990,0.17]],"id":64343695},{"atl":[[990,0.17]],"id":48638605},{"atl":[[990,0.17]],"id":49546922},{"atl":[[1000,0.17]],"id":70003372},{"atl":[[990,0.17]],"id":40917581}],"con":true,"img":false}]}
{"op":"mcm","clk":"11449629795","pt":1717312305714,"mc":[{"id":"1.229554925","rc":[{"atl":[[1.9,1.99]],"id":70003372}],"con":true,"img":false}]}
{"op":"mcm","clk":"11449664990","pt":1717313164864,"mc":[{"id":"1.229554925","rc":[{"atl":[[8,5.23]],"id":47148562},{"spn":5.57,"spf":"NaN","id":47148562}],"con":true,"img":false}]}
{"op":"mcm","clk":"11449665564","pt":1717313177894,"mc":[{"id":"1.229554925","rc":[{"atl":[[90,26.15]],"id":47148562}],"con":true,"img":false}]}
{"op":"mcm","clk":"11449741833","pt":1717314153599,"mc":[{"id":"1.229554925","rc":[{"atb":[[2.86,0],[3.15,0],[2.96,0]],"id":47148562},{"atl":[[16,0],[11,0]],"id":47148562},{"spn":4.5,"spf":"NaN","id":47148562},{"atb":[[18,0],[13,0],[15.5,0]],"id":64343695},{"atl":[[260,0],[360,0]],"id":64343695},{"spn":495.5,"spf":"NaN","id":64343695},{"atb":[[8,0],[9,0],[7,0]],"id":48638605},{"atl":[[210,0],[110,0]],"id":48638605},{"spn":495.5,"spf":"NaN","id":48638605},{"atb":[[2.72,0],[2.52,0],[2.62,0]],"id":49546922},{"atl":[[9,0],[12.5,0]],"id":49546922},{"spn":495.51,"spf":"NaN","id":49546922},{"atb":[[1.79,0],[1.74,0],[1.69,0]],"id":70003372},{"atl":[[4.3,0],[5.3,0]],"id":70003372},{"spn":1.01,"spf":1.0,"id":70003372},{"atb":[[34,0],[44,0],[27,0]],"id":40917581},{"atl":[[580,0],[480,0]],"id":40917581},{"spn":495.51,"spf":"NaN","id":40917581}],"con":true,"img":false}]}
{"op":"mcm","clk":"11449742661","pt":1717314164082,"mc":[{"id":"1.229554925","rc":[{"atb":[[2.86,112.39],[3.15,48.61],[2.96,106.66]],"id":47148562},{"atl":[[16,13.93],[11,13.93]],"id":47148562},{"atb":[[18,6.14],[13,17.42],[15.5,14.41]],"id":64343695},{"atl":[[260,0.53],[360,0.58]],"id":64343695},{"atb":[[8,29.86],[9,13.06],[7,34.84]],"id":48638605},{"atl":[[210,0.99],[110,1.27]],"id":48638605},{"atb":[[2.72,60.77],[2.52,137.53],[2.62,129.05]],"id":49546922},{"atl":[[9,17.42],[12.5,18.18]],"id":49546922},{"atb":[[1.79,132.31],[1.74,282.51],[1.69,302.98]],"id":70003372},{"atl":[[4.3,42.23],[5.3,48.61]],"id":70003372},{"atb":[[34,6.33],[44,2.43],[27,8.04]],"id":40917581},{"atl":[[580,0.36],[480,0.29]],"id":40917581}],"con":true,"img":false}]}
{"op":"mcm","clk":"11449756789","pt":1717314321017,"mc":[{"id":"1.229554925","rc":[{"spn":5.57,"spf":"NaN","id":47148562},{"atb":[[18,0],[13,0],[15.5,0]],"id":64343695},{"atl":[[260,0],[360,0]],"id":64343695},{"atb":[[8,0],[9,0],[7,0]],"id":48638605},{"atl":[[210,0],[110,0]],"id":48638605},{"spn":5.86,"spf":"NaN","id":49546922},{"spn":1.79,"spf":1.0,"id":70003372},{"spn":262.0,"spf":"NaN","id":40917581}],"con":true,"img":false}]}
{"op":"mcm","clk":"11449757847","pt":1717314333535,"mc":[{"id":"1.229554925","rc":[{"atb":[[18,6.14],[13,17.42],[15.5,14.41]],"id":64343695},{"atl":[[260,0.53],[360,0.58]],"id":64343695},{"atb":[[8,29.86],[9,13.06],[7,34.84]],"id":48638605},{"atl":[[210,0.99],[110,1.27]],"id":48638605}],"con":true,"img":false}]}
{"op":"mcm","clk":"11449759684","pt":1717314355289,"mc":[{"id":"1.229554925","rc":[{"atb":[[18,0],[13,0],[15.5,0]],"id":64343695},{"atl":[[260,0],[360,0]],"id":64343695},{"atb":[[8,0],[9,0],[7,0]],"id":48638605},{"atl":[[210,0],[110,0]],"id":48638605}],"con":true,"img":false}]}
{"op":"mcm","clk":"11449760287","pt":1717314362280,"mc":[{"id":"1.229554925","rc":[{"atb":[[18,6.14],[13,17.42],[15.5,14.41]],"id":64343695},{"atl":[[260,0.53],[360,0.58]],"id":64343695},{"atb":[[8,29.86],[9,13.06],[7,34.84]],"id":48638605},{"atl":[[210,0.99],[110,1.27]],"id":48638605}],"con":true,"img":false}]}
{"op":"mcm","clk":"11449830318","pt":1717315128435,"mc":[{"id":"1.229554925","marketDefinition":{"bspMarket":true,"turnInPlayEnabled":false,"persistenceEnabled":false,"marketBaseRate":7.0,"eventId":"33318908","eventTypeId":"4339","numberOfWinners":1,"bettingType":"ODDS","marketType":"WIN","marketTime":"2024-06-02T10:41:00.000Z","suspendTime":"2024-06-02T10:41:00.000Z","bspReconciled":false,"complete":true,"inPlay":false,"crossMatching":true,"runnersVoidable":false,"numberOfActiveRunners":6,"betDelay":0,"status":"OPEN","runners":[{"status":"ACTIVE","sortPriority":1,"id":40917581,"name":"1. Sophia Palms"},{"status":"ACTIVE","sortPriority":2,"id":47148562,"name":"2. Under Siege"},{"status":"ACTIVE","sortPriority":3,"id":49546922,"name":"4. Uno Whiskey"},{"status":"ACTIVE","sortPriority":4,"id":70003372,"name":"5. Southern Sun"},{"status":"ACTIVE","sortPriority":5,"id":48638605,"name":"7. Lochinvar Aloisi"},{"status":"ACTIVE","sortPriority":6,"id":64343695,"name":"8. Punching Poncho"}],"regulators":["MR_INT"],"venue":"Murray Bridge","countryCode":"AU","discountAllowed":true,"timezone":"Australia/Adelaide","openDate":"2024-06-02T08:21:00.000Z","version":5962327449,"name":"R8 530m Heat","eventName":"Murray Bridge (AUS) 2nd Jun"},"rc":[{"atb":[[1.01,17.76],[2.86,112.39],[3.15,48.61],[2.96,106.66]],"id":47148562},{"atl":[[8,5.23],[16,13.93],[11,13.93],[90,26.15],[990,0.17]],"id":47148562},{"spn":5.57,"spf":"NaN","id":47148562},{"atb":[[18,6.14],[1.01,17.76],[13,17.42],[15.5,14.41]],"id":64343695},{"atl":[[260,0.53],[360,0.58],[990,0.17]],"id":64343695},{"spn":139.0,"spf":"NaN","id":64343695},{"atb":[[8,29.86],[9,13.06],[1.01,17.76],[7,34.84]],"id":48638605},{"atl":[[210,0.99],[110,1.27],[990,0.17]],"id":48638605},{"spn":59.5,"spf":"NaN","id":48638605},{"atb":[[2.72,60.77],[2.52,137.53],[1.02,8.87],[2.62,129.05]],"id":49546922},{"atl":[[9,17.42],[12.5,18.18],[990,0.17]],"id":49546922},{"spn":5.86,"spf":"NaN","id":49546922},{"spl":[[1.01,31.39]],"id":70003372},{"atb":[[1.79,132.31],[1.74,282.51],[1.02,8.87],[1.69,302.98]],"id":70003372},{"trd":[[1.99,9.46]],"ltp":1.99,"tv":9.46,"id":70003372},{"atl":[[1.99,5.72],[4.3,42.23],[5.3,48.61],[1.9,1.99],[2.2,4.73],[1000,0.17]],"id":70003372},{"spn":1.79,"spf":1.0,"id":70003372},{"atb":[[34,6.33],[1.03,5.92],[44,2.43],[27,8.04]],"id":40917581},{"atl":[[580,0.36],[480,0.29],[990,0.17]],"id":40917581},{"spn":262.0,"spf":"NaN","id":40917581}],"con":true,"img":true}]}
{"op":"mcm","clk":"11449839819","pt":1717315180253,"mc":[{"id":"1.229554925","rc":[{"atb":[[1.51,98.04]],"id":47148562},{"atl":[[34,10]],"id":47148562},{"spn":139.0,"spf":"NaN","id":64343695},{"spn":59.5,"spf":"NaN","id":48638605},{"atl":[[34,10]],"id":49546922},{"atl":[[34,10]],"id":70003372},{"atb":[[6.2,9.62],[4.1,16.13],[2.12,44.64],[1.51,98.04],[3.05,24.39]],"id":40917581}],"con":true,"img":false}]}
{"op":"mcm","clk":"11449851019","pt":1717315293608,"mc":[{"id":"1.229554925","rc":[{"atb":[[4.1,16.13],[2.12,44.64],[3.05,24.39]],"id":64343695},{"atb":[[2.12,44.64],[3.05,24.39]],"id":48638605}],"con":true,"img":false}]}
{"op":"mcm","clk":"11449851026","pt":1717315293695,"mc":[{"id":"1.229554925","rc":[{"atb":[[1.51,98.04]],"id":64343695},{"atb":[[1.51,98.04]],"id":48638605}],"con":true,"img":false}]}
{"op":"mcm","clk":"11449851287","pt":1717315296619,"mc":[{"id":"1.229554925","rc":[{"atb":[[2.86,0],[3.15,0],[2.96,0]],"id":47148562},{"atl":[[16,0],[11,0]],"id":47148562},{"atb":[[18,0],[13,0],[15.5,0]],"id":64343695},{"atl":[[260,0],[360,0]],"id":64343695},{"atb":[[8,0],[9,0],[7,0]],"id":48638605},{"atl":[[210,0],[110,0]],"id":48638605},{"atb":[[2.72,0],[2.52,0],[2.62,0]],"id":49546922},{"atl":[[9,0],[12.5,0]],"id":49546922},{"atb":[[1.79,0],[1.74,0],[1.69,0]],"id":70003372},{"atl":[[4.3,0],[5.3,0]],"id":70003372},{"atb":[[34,0],[44,0],[27,0]],"id":40917581},{"atl":[[580,0],[480,0]],"id":40917581}],"con":true,"img":false}]}
{"op":"mcm","clk":"11449853624","pt":1717315320716,"mc":[{"id":"1.229554925","rc":[{"atb":[[2.86,112.39],[3.15,48.61],[2.96,106.66]],"id":47148562},{"atl":[[16,13.93],[11,13.93]],"id":47148562},{"atb":[[18,6.14],[13,17.42],[15.5,14.41]],"id":64343695},{"atl":[[260,0.53],[360,0.58]],"id":64343695},{"atb":[[8,29.86],[9,13.06],[7,34.84]],"id":48638605},{"atl":[[210,0.99],[110,1.27]],"id":48638605},{"atb":[[2.72,60.77],[2.52,137.53],[2.62,129.05]],"id":49546922},{"atl":[[9,17.42],[12.5,18.18]],"id":49546922},{"atb":[[1.79,132.31],[1.74,282.51],[1.69,302.98]],"id":70003372},{"atl":[[4.3,42.23],[5.3,48.61]],"id":70003372},{"atb":[[34,6.33],[44,2.43],[27,8.04]],"id":40917581},{"atl":[[580,0.36],[480,0.29]],"id":40917581}],"con":true,"img":false}]}
{"op":"mcm","clk":"11449893722","pt":1717315713296,"mc":[{"id":"1.229554925","rc":[{"atb":[[2.86,0],[3.15,0],[2.96,0]],"id":47148562},{"atl":[[16,0],[11,0]],"id":47148562},{"spn":4.75,"spf":"NaN","id":47148562},{"atb":[[18,0],[13,0],[15.5,0]],"id":64343695},{"atl":[[260,0],[360,0]],"id":64343695},{"spn":497.05,"spf":"NaN","id":64343695},{"atb":[[2.72,0],[2.52,0],[2.62,0]],"id":49546922},{"atl":[[9,0],[12.5,0]],"id":49546922},{"spn":17.51,"spf":"NaN","id":49546922},{"atb":[[34,0],[44,0],[27,0]],"id":40917581},{"atl":[[580,0],[480,0]],"id":40917581},{"spn":498.1,"spf":"NaN","id":40917581}],"con":true,"img":false}]}
{"op":"mcm","clk":"11449896899","pt":1717315742980,"mc":[{"id":"1.229554925","rc":[{"atb":[[2.86,112.39],[3.15,48.61],[2.96,106.66]],"id":47148562},{"atl":[[16,13.93],[11,13.93]],"id":47148562},{"atb":[[18,6.14],[13,17.42],[15.5,14.41]],"id":64343695},{"atl":[[260,0.53],[360,0.58]],"id":64343695},{"atb":[[2.72,60.77],[2.52,137.53],[2.62,129.05]],"id":49546922},{"atl":[[9,17.42],[12.5,18.18]],"id":49546922},{"atb":[[34,6.33],[44,2.43],[27,8.04]],"id":40917581},{"atl":[[580,0.36],[480,0.29]],"id":40917581}],"con":true,"img":false}]}
{"op":"mcm","clk":"11449959192","pt":1717316398326,"mc":[{"id":"1.229554925","rc":[{"atb":[[2.86,0],[3.15,0],[2.96,0]],"id":47148562},{"atl":[[16,0],[11,0]],"id":47148562},{"atb":[[18,0],[13,0],[15.5,0]],"id":64343695},{"atl":[[260,0],[360,0]],"id":64343695},{"atb":[[8,0],[9,0],[7,0]],"id":48638605},{"atl":[[210,0],[110,0]],"id":48638605},{"spn":496.52,"spf":"NaN","id":48638605},{"atb":[[2.72,0],[2.52,0],[2.62,0]],"id":49546922},{"atl":[[9,0],[12.5,0]],"id":49546922},{"atb":[[1.79,0],[1.74,0],[1.69,0]],"id":70003372},{"atl":[[4.3,0],[5.3,0]],"id":70003372},{"spn":1.01,"spf":1.0,"id":70003372},{"atb":[[34,0],[44,0],[27,0]],"id":40917581},{"atl":[[580,0],[480,0]],"id":40917581}],"con":true,"img":false}]}
{"op":"mcm","clk":"11449960628","pt":1717316415104,"mc":[{"id":"1.229554925","rc":[{"atb":[[2.86,112.39],[3.15,48.61],[2.96,106.66]],"id":47148562},{"atl":[[16,13.93],[11,13.93]],"id":47148562},{"atb":[[18,6.14],[13,17.42],[15.5,14.41]],"id":64343695},{"atl":[[260,0.53],[360,0.58]],"id":64343695},{"atb":[[8,29.86],[9,13.06],[7,34.84]],"id":48638605},{"atl":[[210,0.99],[110,1.27]],"id":48638605},{"atb":[[2.72,60.77],[2.52,137.53],[2.62,129.05]],"id":49546922},{"atl":[[9,17.42],[12.5,18.18]],"id":49546922},{"atb":[[1.79,132.31],[1.74,282.51],[1.69,302.98]],"id":70003372},{"atl":[[4.3,42.23],[5.3,48.61]],"id":70003372},{"atb":[[34,6.33],[44,2.43],[27,8.04]],"id":40917581},{"atl":[[580,0.36],[480,0.29]],"id":40917581}],"con":true,"img":false}]}
{"op":"mcm","clk":"11450006605","pt":1717317019843,"mc":[{"id":"1.229554925","rc":[{"atl":[[1000,1]],"id":47148562},{"spn":5.57,"spf":"NaN","id":47148562},{"atl":[[1000,1]],"id":64343695},{"spn":139.0,"spf":"NaN","id":64343695},{"atl":[[1000,1]],"id":48638605},{"spn":59.5,"spf":"NaN","id":48638605},{"atl":[[1000,1]],"id":49546922},{"spn":5.86,"spf":"NaN","id":49546922},{"atl":[[1000,1.17]],"id":70003372},{"spn":1.79,"spf":1.0,"id":70003372},{"atl":[[1000,1]],"id":40917581},{"spn":262.0,"spf":"NaN","id":40917581}],"con":true,"img":false}]}
{"op":"mcm","clk":"11450057427","pt":1717317526522,"mc":[{"id":"1.229554925","rc":[{"atb":[[2.86,0],[3.15,0],[2.96,0]],"id":47148562},{"atl":[[16,0],[11,0]],"id":47148562},{"spn":4.75,"spf":"NaN","id":47148562},{"atb":[[18,0],[13,0],[15.5,0]],"id":64343695},{"atl":[[260,0],[360,0]],"id":64343695},{"spn":497.05,"spf":"NaN","id":64343695},{"atb":[[8,0],[9,0],[7,0]],"id":48638605},{"atl":[[210,0],[110,0]],"id":48638605},{"spn":496.52,"spf":"NaN","id":48638605},{"atb":[[2.72,0],[2.52,0],[2.62,0]],"id":49546922},{"atl":[[9,0],[12.5,0]],"id":49546922},{"spn":17.51,"spf":"NaN","id":49546922},{"atb":[[1.79,0],[1.74,0],[1.69,0]],"id":70003372},{"atl":[[4.3,0],[5.3,0]],"id":70003372},{"spn":1.01,"spf":1.0,"id":70003372},{"atb":[[34,0],[44,0],[27,0]],"id":40917581},{"atl":[[580,0],[480,0]],"id":40917581},{"spn":498.1,"spf":"NaN","id":40917581}],"con":true,"img":false}]}
{"op":"mcm","clk":"11450059564","pt":1717317550136,"mc":[{"id":"1.229554925","rc":[{"atb":[[2.86,112.39],[3.15,48.61],[2.96,106.66]],"id":47148562},{"atl":[[16,13.93],[11,13.93]],"id":47148562},{"atb":[[18,6.14],[13,17.42],[15.5,14.41]],"id":64343695},{"atl":[[260,0.53],[360,0.58]],"id":64343695},{"atb":[[8,29.86],[9,13.06],[7,34.84]],"id":48638605},{"atl":[[210,0.99],[110,1.27]],"id":48638605},{"atb":[[2.72,60.77],[2.52,137.53],[2.62,129.05]],"id":49546922},{"atl":[[9,17.42],[12.5,18.18]],"id":49546922},{"atb":[[1.79,132.31],[1.74,282.51],[1.69,302.98]],"id":70003372},{"atl":[[4.3,42.23],[5.3,48.61]],"id":70003372},{"atb":[[34,6.33],[44,2.43],[27,8.04]],"id":40917581},{"atl":[[580,0.36],[480,0.29]],"id":40917581}],"con":true,"img":false}]}
{"op":"mcm","clk":"11450070571","pt":1717317670821,"mc":[{"id":"1.229554925","rc":[{"spn":5.57,"spf":"NaN","id":47148562},{"spn":139.0,"spf":"NaN","id":64343695},{"spn":59.5,"spf":"NaN","id":48638605},{"spn":5.86,"spf":"NaN","id":49546922},{"atl":[[16,10]],"id":70003372},{"spn":1.79,"spf":1.0,"id":70003372},{"spn":262.0,"spf":"NaN","id":40917581}],"con":true,"img":false}]}
{"op":"mcm","clk":"11450133799","pt":1717318389906,"mc":[{"id":"1.229554925","rc":[{"atb":[[2.86,0],[3.15,0],[2.96,0]],"id":47148562},{"atl":[[16,0],[11,0]],"id":47148562},{"spn":4.75,"spf":"NaN","id":47148562},{"atb":[[18,0],[13,0],[15.5,0]],"id":64343695},{"atl":[[260,0],[360,0]],"id":64343695},{"spn":497.05,"spf":"NaN","id":64343695},{"atb":[[8,0],[9,0],[7,0]],"id":48638605},{"atl":[[210,0],[110,0]],"id":48638605},{"spn":496.52,"spf":"NaN","id":48638605},{"atb":[[2.72,0],[2.52,0],[2.62,0]],"id":49546922},{"atl":[[9,0],[12.5,0]],"id":49546922},{"spn":17.51,"spf":"NaN","id":49546922},{"atb":[[1.79,0],[1.74,0],[1.69,0]],"id":70003372},{"atl":[[4.3,0],[5.3,0]],"id":70003372},{"spn":1.01,"spf":1.0,"id":70003372},{"atb":[[34,0],[44,0],[27,0]],"id":40917581},{"atl":[[580,0],[480,0]],"id":40917581},{"spn":498.1,"spf":"NaN","id":40917581}],"con":true,"img":false}]}
{"op":"mcm","clk":"11450134730","pt":1717318401243,"mc":[{"id":"1.229554925","rc":[{"atb":[[2.86,112.39],[3.15,48.61],[2.96,106.66]],"id":47148562},{"atl":[[16,13.93],[11,13.93]],"id":47148562},{"atb":[[18,6.14],[13,17.42],[15.5,14.41]],"id":64343695},{"atl":[[260,0.53],[360,0.58]],"id":64343695},{"atb":[[8,29.86],[9,13.06],[7,34.84]],"id":48638605},{"atl":[[210,0.99],[110,1.27]],"id":48638605},{"atb":[[2.72,60.77],[2.52,137.53],[2.62,129.05]],"id":49546922},{"atl":[[9,17.42],[12.5,18.18]],"id":49546922},{"atb":[[1.79,132.31],[1.74,282.51],[1.69,302.98]],"id":70003372},{"atl":[[4.3,42.23],[5.3,48.61]],"id":70003372},{"atb":[[34,6.33],[44,2.43],[27,8.04]],"id":40917581},{"atl":[[580,0.36],[480,0.29]],"id":40917581}],"con":true,"img":false}]}
{"op":"mcm","clk":"11450214744","pt":1717319245580,"mc":[{"id":"1.229554925","rc":[{"atb":[[2.86,0],[3.15,0],[2.96,0]],"id":47148562},{"atl":[[16,0],[11,0]],"id":47148562},{"atb":[[18,0],[13,0],[15.5,0]],"id":64343695},{"atl":[[260,0],[360,0]],"id":64343695},{"atb":[[8,0],[9,0],[7,0]],"id":48638605},{"atl":[[210,0],[110,0]],"id":48638605},{"atb":[[2.72,0],[2.52,0],[2.62,0]],"id":49546922},{"atl":[[9,0],[12.5,0]],"id":49546922},{"atb":[[1.79,0],[1.74,0],[1.69,0]],"id":70003372},{"atl":[[4.3,0],[5.3,0]],"id":70003372},{"atb":[[34,0],[44,0],[27,0]],"id":40917581},{"atl":[[580,0],[480,0]],"id":40917581}],"con":true,"img":false}]}
{"op":"mcm","clk":"11450217182","pt":1717319268291,"mc":[{"id":"1.229554925","rc":[{"atb":[[2.86,112.39],[3.15,48.61],[2.96,106.66]],"id":47148562},{"atl":[[16,13.93],[11,13.93]],"id":47148562},{"atb":[[18,6.14],[13,17.42],[15.5,14.41]],"id":64343695},{"atl":[[260,0.53],[360,0.58]],"id":64343695},{"atb":[[8,29.86],[9,13.06],[7,34.84]],"id":48638605},{"atl":[[210,0.99],[110,1.27]],"id":48638605},{"atb":[[2.72,60.77],[2.52,137.53],[2.62,129.05]],"id":49546922},{"atl":[[9,17.42],[12.5,18.18]],"id":49546922},{"atb":[[1.79,132.31],[1.74,282.51],[1.69,302.98]],"id":70003372},{"atl":[[4.3,42.23],[5.3,48.61]],"id":70003372},{"atb":[[34,6.33],[44,2.43],[27,8.04]],"id":40917581},{"atl":[[580,0.36],[480,0.29]],"id":40917581}],"con":true,"img":false}]}
{"op":"mcm","clk":"11450241502","pt":1717319529809,"mc":[{"id":"1.229554925","rc":[{"atb":[[2.98,58.13],[3.05,27.37]],"id":47148562},{"atl":[[10.5,12.11],[9.8,6.37]],"id":47148562},{"spn":5.57,"spf":"NaN","id":47148562},{"atb":[[16,3.74],[13.5,8.22]],"id":64343695},{"atl":[[140,0.4],[200,2.61]],"id":64343695},{"spn":79.0,"spf":"NaN","id":64343695},{"atb":[[9.2,6.84],[8.2,14.71]],"id":48638605},{"atl":[[65,2.61],[48,2.61]],"id":48638605},{"spn":28.6,"spf":"NaN","id":48638605},{"atb":[[2.82,30.83],[2.64,69.86]],"id":49546922},{"atl":[[8.8,21.88]],"id":49546922},{"spn":5.81,"spf":"NaN","id":49546922},{"atb":[[1.75,61.85],[1.53,209.76]],"id":70003372},{"atl":[[3.8,20.03],[4.2,34.74]],"id":70003372},{"spn":1.79,"spf":1.0,"id":70003372},{"atb":[[38,3.66],[48,2.61]],"id":40917581},{"spn":264.0,"spf":"NaN","id":40917581}],"con":true,"img":false}]}
{"op":"mcm","clk":"11450252675","pt":1717319654084,"mc":[{"id":"1.229554925","rc":[{"atb":[[3.05,0]],"id":47148562}],"con":true,"img":false}]}
{"op":"mcm","clk":"11450252686","pt":1717319654190,"mc":[{"id":"1.229554925","rc":[{"atb":[[3.2,27.37]],"id":47148562}],"con":true,"img":false}]}
{"op":"mcm","clk":"11450253025","pt":1717319658022,"mc":[{"id":"1.229554925","rc":[{"spl":[[1.01,52.31]],"id":70003372}],"con":true,"img":false}]}
{"op":"mcm","clk":"11450258528","pt":1717319718170,"mc":[{"id":"1.229554925","rc":[{"atb":[[3.2,32.53]],"id":47148562},{"spn":5.6,"spf":"NaN","id":47148562}],"con":true,"img":false}]}
{"op":"mcm","clk":"11450258549","pt":1717319718377,"mc":[{"id":"1.229554925","rc":[{"atb":[[2.76,6.44]],"id":49546922}],"con":true,"img":false}]}
{"op":"mcm","clk":"11450262485","pt":1717319762333,"mc":[{"id":"1.229554925","rc":[{"atb":[[2.64,0]],"id":49546922}],"con":true,"img":false}]}
{"op":"mcm","clk":"11450262492","pt":1717319762435,"mc":[{"id":"1.229554925","rc":[{"atb":[[2.74,69.86]],"id":49546922}],"con":true,"img":false}]}
{"op":"mcm","clk":"11450263911","pt":1717319779064,"mc":[{"id":"1.229554925","rc":[{"atb":[[2.76,0]],"id":49546922}],"con":true,"img":false}]}
{"op":"mcm","clk":"11450266749","pt":1717319811178,"mc":[{"id":"1.229554925","rc":[{"atb":[[2.78,6.37]],"id":49546922}],"con":true,"img":false}]}
{"op":"mcm","clk":"11450286930","pt":1717320072780,"mc":[{"id":"1.229554925","rc":[{"atb":[[2.86,0],[3.15,0],[2.96,0]],"id":47148562},{"atl":[[16,0],[11,0]],"id":47148562},{"atb":[[18,0],[13,0],[15.5,0]],"id":64343695},{"atl":[[260,0],[360,0]],"id":64343695},{"spn":78.0,"spf":"NaN","id":64343695},{"atb":[[8,0],[9,0],[7,0]],"id":48638605},{"atl":[[210,0],[110,0]],"id":48638605},{"atb":[[2.72,0],[2.52,0],[2.62,0]],"id":49546922},{"atl":[[9,0],[12.5,0]],"id":49546922},{"atb":[[1.79,0],[1.74,0],[1.69,0]],"id":70003372},{"atl":[[4.3,0],[5.3,0]],"id":70003372},{"spn":1.75,"spf":1.0,"id":70003372},{"atb":[[34,0],[44,0],[27,0]],"id":40917581},{"atl":[[580,0],[480,0]],"id":40917581},{"spn":519.0,"spf":"NaN","id":40917581}],"con":true,"img":false}]}
{"op":"mcm","clk":"11450287440","pt":1717320079380,"mc":[{"id":"1.229554925","rc":[{"atb":[[3.2,5.16],[2.64,70.18],[2.98,0]],"id":47148562},{"atl":[[10.5,0],[13.5,9.2]],"id":47148562},{"atb":[[2.74,0]],"id":49546922},{"atl":[[12,10.41],[8.8,7.19]],"id":49546922},{"atb":[[1.75,0]],"id":70003372},{"atl":[[5.1,27.11],[4.2,0]],"id":70003372}],"con":true,"img":false}]}
{"op":"mcm","clk":"11450287446","pt":1717320079477,"mc":[{"id":"1.229554925","rc":[{"atb":[[3.05,27.37]],"id":47148562},{"atb":[[2.46,69.86]],"id":49546922},{"atb":[[1.67,61.85]],"id":70003372}],"con":true,"img":false}]}
{"op":"mcm","clk":"11450287894","pt":1717320086602,"mc":[{"id":"1.229554925","rc":[{"atb":[[1.54,21]],"id":70003372}],"con":true,"img":false}]}
{"op":"mcm","clk":"11450287905","pt":1717320086709,"mc":[{"id":"1.229554925","rc":[{"atb":[[3.2,0]],"id":47148562},{"atb":[[2.78,0]],"id":49546922}],"con":true,"img":false}]}
{"op":"mcm","clk":"11450287949","pt":1717320087390,"mc":[{"id":"1.229554925","rc":[{"atb":[[2.86,112.39],[3.15,48.61],[2.96,106.66]],"id":47148562},{"atl":[[16,13.93],[11,13.93]],"id":47148562},{"atb":[[18,6.14],[13,17.42],[15.5,14.41]],"id":64343695},{"atl":[[260,0.53],[360,0.58]],"id":64343695},{"atb":[[8,29.86],[9,13.06],[7,34.84]],"id":48638605},{"atl":[[210,0.99],[110,1.27]],"id":48638605},{"atb":[[2.72,60.77],[2.52,137.53],[2.62,129.05]],"id":49546922},{"atl":[[9,17.42],[12.5,18.18]],"id":49546922},{"atb":[[1.79,132.31],[1.74,282.51],[1.69,302.98]],"id":70003372},{"atl":[[4.3,42.23],[5.3,48.61]],"id":70003372},{"atb":[[34,6.33],[44,2.43],[27,8.04]],"id":40917581},{"atl":[[580,0.36],[480,0.29]],"id":40917581}],"con":true,"img":false}]}
{"op":"mcm","clk":"11450289344","pt":1717320109194,"mc":[{"id":"1.229554925","rc":[{"atb":[[3.2,5.16]],"id":47148562}],"con":true,"img":false}]}
{"op":"mcm","clk":"11450289352","pt":1717320109298,"mc":[{"id":"1.229554925","rc":[{"atb":[[2.76,6.44]],"id":49546922}],"con":true,"img":false}]}
{"op":"mcm","clk":"11450289379","pt":1717320109708,"mc":[{"id":"1.229554925","rc":[{"atb":[[1.54,0]],"id":70003372}],"con":true,"img":false}]}
{"op":"mcm","clk":"11450292973","pt":1717320160888,"mc":[{"id":"1.229554925","rc":[{"atb":[[2.64,0],[2.98,58.13]],"id":47148562},{"atl":[[10.5,12.11],[13.5,0]],"id":47148562},{"spn":79.0,"spf":"NaN","id":64343695},{"atl":[[12,0],[8.8,21.88]],"id":49546922},{"atl":[[5.1,0],[4.2,34.74]],"id":70003372},{"spn":1.79,"spf":1.0,"id":70003372},{"spn":264.0,"spf":"NaN","id":40917581}],"con":true,"img":false}]}
{"op":"mcm","clk":"11450292978","pt":1717320160988,"mc":[{"id":"1.229554925","rc":[{"atb":[[3.05,0]],"id":47148562},{"atb":[[2.46,0]],"id":49546922},{"atb":[[1.67,0]],"id":70003372}],"con":true,"img":false}]}
{"op":"mcm","clk":"11450292984","pt":1717320161092,"mc":[{"id":"1.229554925","rc":[{"atb":[[3.2,32.53]],"id":47148562},{"atb":[[2.74,69.86]],"id":49546922},{"atb":[[1.75,61.85]],"id":70003372}],"con":true,"img":false}]}
{"op":"mcm","clk":"11450293946","pt":1717320174502,"mc":[{"id":"1.229554925","rc":[{"atb":[[2.76,0]],"id":49546922}],"con":true,"img":false}]}
{"op":"mcm","clk":"11450296486","pt":1717320212458,"mc":[{"id":"1.229554925","rc":[{"atb":[[2.78,6.37]],"id":49546922}],"con":true,"img":false}]}
{"op":"mcm","clk":"11450360410","pt":1717320990650,"mc":[{"id":"1.229554925","rc":[{"atb":[[2.86,0],[3.15,0],[2.96,0]],"id":47148562},{"atl":[[16,0],[11,0]],"id":47148562},{"atb":[[18,0],[13,0],[15.5,0]],"id":64343695},{"atl":[[260,0],[360,0]],"id":64343695},{"spn":78.0,"spf":"NaN","id":64343695},{"atb":[[8,0],[9,0],[7,0]],"id":48638605},{"atl":[[210,0],[110,0]],"id":48638605},{"atb":[[2.72,0],[2.52,0],[2.62,0]],"id":49546922},{"atl":[[9,0],[12.5,0]],"id":49546922},{"atb":[[1.79,0],[1.74,0],[1.69,0]],"id":70003372},{"atl":[[4.3,0],[5.3,0]],"id":70003372},{"spn":1.75,"spf":1.0,"id":70003372},{"atb":[[34,0],[44,0],[27,0]],"id":40917581},{"atl":[[580,0],[480,0]],"id":40917581},{"spn":519.0,"spf":"NaN","id":40917581}],"con":true,"img":false}]}
{"op":"mcm","clk":"11450361743","pt":1717321007195,"mc":[{"id":"1.229554925","rc":[{"atb":[[3.2,5.16]],"id":47148562},{"atb":[[2.74,0]],"id":49546922},{"atb":[[1.75,0]],"id":70003372}],"con":true,"img":false}]}
{"op":"mcm","clk":"11450361748","pt":1717321007297,"mc":[{"id":"1.229554925","rc":[{"atb":[[3.05,27.37]],"id":47148562},{"atb":[[2.46,69.86]],"id":49546922},{"atb":[[1.67,61.85]],"id":70003372}],"con":true,"img":false}]}
{"op":"mcm","clk":"11450362070","pt":1717321011617,"mc":[{"id":"1.229554925","rc":[{"atb":[[2.86,112.39],[3.15,48.61],[2.96,106.66]],"id":47148562},{"atl":[[16,13.93],[11,13.93]],"id":47148562},{"atb":[[18,6.14],[13,17.42],[15.5,14.41]],"id":64343695},{"atl":[[260,0.53],[360,0.58]],"id":64343695},{"atb":[[8,29.86],[9,13.06],[7,34.84]],"id":48638605},{"atl":[[210,0.99],[110,1.27]],"id":48638605},{"atb":[[2.72,60.77],[2.52,137.53],[2.62,129.05]],"id":49546922},{"atl":[[9,17.42],[12.5,18.18]],"id":49546922},{"atb":[[1.79,132.31],[1.74,282.51],[1.69,302.98]],"id":70003372},{"atl":[[4.3,42.23],[5.3,48.61]],"id":70003372},{"atb":[[34,6.33],[44,2.43],[27,8.04]],"id":40917581},{"atl":[[580,0.36],[480,0.29]],"id":40917581}],"con":true,"img":false}]}
{"op":"mcm","clk":"11450362131","pt":1717321012296,"mc":[{"id":"1.229554925","rc":[{"atb":[[2.78,0]],"id":49546922}],"con":true,"img":false}]}
{"op":"mcm","clk":"11450365284","pt":1717321052453,"mc":[{"id":"1.229554925","rc":[{"spn":79.0,"spf":"NaN","id":64343695},{"atb":[[2.76,6.44]],"id":49546922},{"spn":1.79,"spf":1.0,"id":70003372},{"spn":264.0,"spf":"NaN","id":40917581}],"con":true,"img":false}]}
{"op":"mcm","clk":"11450366514","pt":1717321069058,"mc":[{"id":"1.229554925","rc":[{"atb":[[3.05,0]],"id":47148562},{"atb":[[1.67,0]],"id":70003372}],"con":true,"img":false}]}
{"op":"mcm","clk":"11450366522","pt":1717321069165,"mc":[{"id":"1.229554925","rc":[{"atb":[[3.2,32.53]],"id":47148562},{"atb":[[1.75,61.85]],"id":70003372}],"con":true,"img":false}]}
{"op":"mcm","clk":"11450368437","pt":1717321097685,"mc":[{"id":"1.229554925","rc":[{"atb":[[2.46,0]],"id":49546922}],"con":true,"img":false}]}
{"op":"mcm","clk":"11450368440","pt":1717321097787,"mc":[{"id":"1.229554925","rc":[{"atb":[[2.74,69.86]],"id":49546922}],"con":true,"img":false}]}
{"op":"mcm","clk":"11450370323","pt":1717321126270,"mc":[{"id":"1.229554925","rc":[{"atb":[[2.76,0]],"id":49546922}],"con":true,"img":false}]}
{"op":"mcm","clk":"11450373625","pt":1717321173202,"mc":[{"id":"1.229554925","rc":[{"atb":[[2.78,6.37]],"id":49546922}],"con":true,"img":false}]}
{"op":"mcm","clk":"11450375895","pt":1717321211696,"mc":[{"id":"1.229554925","rc":[{"trd":[[480,0.58]],"ltp":480.0,"tv":0.58,"id":40917581},{"atl":[[480,0]],"id":40917581},{"spn":314.0,"spf":"NaN","id":40917581}],"con":true,"img":false}]}
{"op":"mcm","clk":"11450378801","pt":1717321260440,"mc":[{"id":"1.229554925","rc":[{"atb":[[2.94,51.55]],"id":47148562},{"atl":[[13.5,8]],"id":47148562},{"atb":[[6.2,19.23]],"id":64343695},{"atl":[[340,2]],"id":64343695},{"atb":[[3.75,36.36]],"id":48638605},{"atl":[[70,2]],"id":48638605},{"atb":[[2.22,81.97]],"id":49546922},{"atl":[[48,2.13]],"id":49546922},{"atb":[[1.17,419.52]],"id":70003372},{"atl":[[3.85,35.09]],"id":70003372},{"atb":[[19,5.56]],"id":40917581}],"con":true,"img":false}]}
{"op":"mcm","clk":"11450379611","pt":1717321272033,"mc":[{"id":"1.229554925","rc":[{"atb":[[2.8,55.56],[2.94,0]],"id":47148562},{"atb":[[3.35,42.55],[3.75,0]],"id":48638605},{"atl":[[70,0],[75,2]],"id":48638605}],"con":true,"img":false}]}
{"op":"mcm","clk":"11450382299","pt":1717321314272,"mc":[{"id":"1.229554925","rc":[{"atb":[[2.86,0],[3.15,0],[2.96,0]],"id":47148562},{"atl":[[16,0],[11,0]],"id":47148562},{"atb":[[18,0],[13,0],[15.5,0]],"id":64343695},{"atl":[[260,0],[360,0]],"id":64343695},{"atb":[[8,0],[9,0],[7,0]],"id":48638605},{"atl":[[210,0],[110,0]],"id":48638605},{"atb":[[2.72,0],[2.52,0],[2.62,0]],"id":49546922},{"atl":[[9,0],[12.5,0]],"id":49546922},{"atb":[[1.79,0],[1.74,0],[1.69,0]],"id":70003372},{"atl":[[4.3,0],[5.3,0]],"id":70003372},{"atb":[[34,0],[44,0],[27,0]],"id":40917581},{"atl":[[580,0]],"id":40917581}],"con":true,"img":false}]}
{"op":"mcm","clk":"11450382388","pt":1717321315992,"mc":[{"id":"1.229554925","rc":[{"atb":[[3.2,5.16],[2.98,0]],"id":47148562},{"atl":[[10.5,0],[13.5,17.2]],"id":47148562},{"atb":[[2.74,0]],"id":49546922},{"atl":[[12,10.41],[8.8,7.19]],"id":49546922},{"atb":[[1.75,0]],"id":70003372},{"atl":[[4.2,0]],"id":70003372}],"con":true,"img":false}]}
{"op":"mcm","clk":"11450382395","pt":1717321316098,"mc":[{"id":"1.229554925","rc":[{"atb":[[2.82,58.13],[3.05,27.37]],"id":47148562},{"atb":[[2.46,69.86]],"id":49546922},{"atb":[[1.67,61.85]],"id":70003372},{"atl":[[3.8,54.78]],"id":70003372}],"con":true,"img":false}]}
{"op":"mcm","clk":"11450382489","pt":1717321317402,"mc":[{"id":"1.229554925","rc":[{"atb":[[3.2,0]],"id":47148562},{"atb":[[2.78,0]],"id":49546922}],"con":true,"img":false}]}
{"op":"mcm","clk":"11450382498","pt":1717321317505,"mc":[{"id":"1.229554925","rc":[{"atb":[[1.54,21]],"id":70003372}],"con":true,"img":false}]}
{"op":"mcm","clk":"11450383477","pt":1717321333068,"mc":[{"id":"1.229554925","rc":[{"atb":[[2.86,112.33],[3.15,48.59],[2.96,106.6]],"id":47148562},{"atl":[[16,13.94],[11,13.94]],"id":47148562},{"spn":5.57,"spf":"NaN","id":47148562},{"atb":[[18,6.14],[13,17.41],[15.5,14.4]],"id":64343695},{"atl":[[260,0.53],[360,0.58]],"id":64343695},{"atb":[[8,29.84],[9,13.05],[7,34.82]],"id":48638605},{"atl":[[210,0.99],[110,1.28]],"id":48638605},{"atb":[[2.72,60.74],[2.52,137.46],[2.62,128.97]],"id":49546922},{"atl":[[9,17.43],[12.5,18.19]],"id":49546922},{"atb":[[1.79,132.24],[1.74,282.35],[1.69,302.81]],"id":70003372},{"atl":[[4.3,42.27],[5.3,48.66]],"id":70003372},{"atb":[[34,8.03],[44,3.08],[27,10.2]],"id":40917581},{"atl":[[580,0.21],[480,0.17]],"id":40917581},{"spn":264.0,"spf":"NaN","id":40917581}],"con":true,"img":false}]}
{"op":"mcm","clk":"11450383677","pt":1717321335980,"mc":[{"id":"1.229554925","rc":[{"trd":[[480,0.93]],"ltp":480.0,"tv":0.93,"id":40917581},{"atl":[[480,0]],"id":40917581}],"con":true,"img":false}]}
{"op":"mcm","clk":"11450384708","pt":1717321353894,"mc":[{"id":"1.229554925","rc":[{"atb":[[1.54,0]],"id":70003372}],"con":true,"img":false}]}
{"op":"mcm","clk":"11450384720","pt":1717321354102,"mc":[{"id":"1.229554925","rc":[{"atb":[[3.2,5.16]],"id":47148562}],"con":true,"img":false}]}
{"op":"mcm","clk":"11450384726","pt":1717321354156,"mc":[{"id":"1.229554925","rc":[{"atb":[[2.76,6.44]],"id":49546922}],"con":true,"img":false}]}
{"op":"mcm","clk":"11450386086","pt":1717321377594,"mc":[{"id":"1.229554925","rc":[{"atb":[[2.82,0],[3.05,0]],"id":47148562},{"atl":[[10.5,12.11],[13.5,8]],"id":47148562},{"atb":[[2.46,0]],"id":49546922},{"atl":[[12,0],[8.8,21.88]],"id":49546922},{"atb":[[1.67,0]],"id":70003372}],"con":true,"img":false}]}
{"op":"mcm","clk":"11450386090","pt":1717321377695,"mc":[{"id":"1.229554925","rc":[{"atb":[[3.2,32.53],[2.98,58.13]],"id":47148562},{"atb":[[2.74,69.86]],"id":49546922},{"atb":[[1.75,61.85]],"id":70003372}],"con":true,"img":false}]}
{"op":"mcm","clk":"11450386232","pt":1717321380601,"mc":[{"id":"1.229554925","rc":[{"atb":[[2.76,0]],"id":49546922}],"con":true,"img":false}]}
{"op":"mcm","clk":"11450389399","pt":1717321431078,"mc":[{"id":"1.229554925","rc":[{"spn":5.6,"spf":"NaN","id":47148562},{"atb":[[2.78,6.37]],"id":49546922},{"spn":314.0,"spf":"NaN","id":40917581}],"con":true,"img":false}]}
{"op":"mcm","clk":"11450406719","pt":1717321679237,"mc":[{"id":"1.229554925","rc":[{"atb":[[2.86,0],[3.15,0],[2.96,0]],"id":47148562},{"atl":[[16,0],[11,0]],"id":47148562},{"atb":[[18,0],[13,0],[15.5,0]],"id":64343695},{"atl":[[260,0],[360,0]],"id":64343695},{"spn":78.0,"spf":"NaN","id":64343695},{"atb":[[8,0],[9,0],[7,0]],"id":48638605},{"atl":[[210,0],[110,0]],"id":48638605},{"atb":[[2.72,0],[2.52,0],[2.62,0]],"id":49546922},{"atl":[[9,0],[12.5,0]],"id":49546922},{"atb":[[1.79,0],[1.74,0],[1.69,0]],"id":70003372},{"atl":[[4.3,0],[5.3,0]],"id":70003372},{"spn":1.75,"spf":1.0,"id":70003372},{"atb":[[34,0],[44,0],[27,0]],"id":40917581},{"atl":[[580,0]],"id":40917581},{"spn":519.0,"spf":"NaN","id":40917581}],"con":true,"img":false}]}
{"op":"mcm","clk":"11450407831","pt":1717321693628,"mc":[{"id":"1.229554925","rc":[{"atb":[[3.2,5.16],[2.98,0]],"id":47148562},{"atl":[[10.5,0],[13.5,17.2]],"id":47148562},{"atb":[[2.74,0]],"id":49546922},{"atl":[[12,10.41],[8.8,7.19]],"id":49546922},{"atb":[[1.75,0]],"id":70003372}],"con":true,"img":false}]}
{"op":"mcm","clk":"11450407840","pt":1717321693730,"mc":[{"id":"1.229554925","rc":[{"atb":[[2.82,58.13],[3.05,27.37]],"id":47148562},{"atb":[[2.46,69.86]],"id":49546922},{"atb":[[1.67,61.85]],"id":70003372}],"con":true,"img":false}]}
{"op":"mcm","clk":"11450407992","pt":1717321696049,"mc":[{"id":"1.229554925","rc":[{"atb":[[3.2,0]],"id":47148562},{"atb":[[2.78,0]],"id":49546922},{"atb":[[1.54,21]],"id":70003372}],"con":true,"img":false}]}
{"op":"mcm","clk":"11450408129","pt":1717321698177,"mc":[{"id":"1.229554925","rc":[{"atb":[[2.86,112.29],[3.15,48.57],[2.96,106.57]],"id":47148562},{"atl":[[16,13.95],[11,13.95]],"id":47148562},{"atb":[[18,6.14],[13,17.4],[15.5,14.4]],"id":64343695},{"atl":[[260,0.53],[360,0.58]],"id":64343695},{"atb":[[8,29.83],[9,13.05],[7,34.81]],"id":48638605},{"atl":[[210,0.99],[110,1.28]],"id":48638605},{"atb":[[2.72,60.71],[2.52,137.41],[2.62,128.93]],"id":49546922},{"atl":[[9,17.44],[12.5,18.2]],"id":49546922},{"atb":[[1.79,132.2],[1.74,282.26],[1.69,302.71]],"id":70003372},{"atl":[[4.3,42.29],[5.3,48.68]],"id":70003372},{"atb":[[34,9.04],[44,3.46],[27,11.47]],"id":40917581},{"atl":[[580,0.13],[480,0.1]],"id":40917581}],"con":true,"img":false}]}
{"op":"mcm","clk":"11450410343","pt":1717321727008,"mc":[{"id":"1.229554925","rc":[{"atb":[[2.76,6.44]],"id":49546922}],"con":true,"img":false}]}
{"op":"mcm","clk":"11450410352","pt":1717321727114,"mc":[{"id":"1.229554925","rc":[{"atb":[[3.2,5.16]],"id":47148562}],"con":true,"img":false}]}
{"op":"mcm","clk":"11450410383","pt":1717321727383,"mc":[{"id":"1.229554925","rc":[{"atb":[[1.54,0]],"id":70003372}],"con":true,"img":false}]}
{"op":"mcm","clk":"11450412471","pt":1717321751123,"mc":[{"id":"1.229554925","rc":[{"atl":[[10.5,12.11]],"id":47148562},{"spn":79.0,"spf":"NaN","id":64343695},{"atl":[[8.8,21.88]],"id":49546922},{"spn":1.79,"spf":1.0,"id":70003372},{"spn":264.0,"spf":"NaN","id":40917581}],"con":true,"img":false}]}
{"op":"mcm","clk":"11450412480","pt":1717321751226,"mc":[{"id":"1.229554925","rc":[{"atb":[[2.82,0],[3.05,0]],"id":47148562},{"atl":[[13.5,8]],"id":47148562},{"atb":[[2.46,0]],"id":49546922},{"atl":[[12,0]],"id":49546922},{"atb":[[1.67,0]],"id":70003372}],"con":true,"img":false}]}
{"op":"mcm","clk":"11450412491","pt":1717321751337,"mc":[{"id":"1.229554925","rc":[{"atb":[[3.2,32.53],[2.98,58.13]],"id":47148562},{"atb":[[2.74,69.86]],"id":49546922},{"atb":[[1.75,61.85]],"id":70003372}],"con":true,"img":false}]}
{"op":"mcm","clk":"11450414383","pt":1717321773462,"mc":[{"id":"1.229554925","rc":[{"atb":[[2.76,0]],"id":49546922}],"con":true,"img":false}]}
{"op":"mcm","clk":"11450417638","pt":1717321809378,"mc":[{"id":"1.229554925","rc":[{"atb":[[2.78,6.37]],"id":49546922}],"con":true,"img":false}]}
{"op":"mcm","clk":"11450417824","pt":1717321811301,"mc":[{"id":"1.229554925","rc":[{"atb":[[1.04,0.85]],"id":40917581}],"con":true,"img":false}]}
{"op":"mcm","clk":"11450418055","pt":1717321813849,"mc":[{"id":"1.229554925","rc":[{"atl":[[1000,1.85]],"id":48638605}],"con":true,"img":false}]}
{"op":"mcm","clk":"11450418251","pt":1717321815581,"mc":[{"id":"1.229554925","rc":[{"atb":[[1.04,0.17]],"id":40917581}],"con":true,"img":false}]}
{"op":"mcm","clk":"11450418377","pt":1717321816889,"mc":[{"id":"1.229554925","rc":[{"atl":[[1000,1.18]],"id":48638605}],"con":true,"img":false}]}
{"op":"mcm","clk":"11450418708","pt":1717321820383,"mc":[{"id":"1.229554925","rc":[{"atb":[[1.04,0]],"id":40917581}],"con":true,"img":false}]}
{"op":"mcm","clk":"11450418716","pt":1717321820484,"mc":[{"id":"1.229554925","rc":[{"atb":[[50,0.17]],"id":40917581}],"con":true,"img":false}]}
{"op":"mcm","clk":"11450418982","pt":1717321823454,"mc":[{"id":"1.229554925","rc":[{"atl":[[1000,1]],"id":48638605}],"con":true,"img":false}]}
{"op":"mcm","clk":"11450418992","pt":1717321823561,"mc":[{"id":"1.229554925","rc":[{"atl":[[46,0.18]],"id":48638605}],"con":true,"img":false}]}
{"op":"mcm","clk":"11450438283","pt":1717322047773,"mc":[{"id":"1.229554925","rc":[{"atb":[[2.8,0],[3,50]],"id":47148562},{"atb":[[3.35,0],[3.9,34.48]],"id":48638605},{"atl":[[65,4.61],[75,0]],"id":48638605},{"spn":27.6,"spf":"NaN","id":48638605},{"spn":265.0,"spf":"NaN","id":40917581}],"con":true,"img":false}]}
{"op":"mcm","clk":"11450438708","pt":1717322052848,"mc":[{"id":"1.229554925","rc":[{"atb":[[3,0],[2.94,51.55]],"id":47148562},{"atl":[[65,2.61],[70,2]],"id":48638605}],"con":true,"img":false}]}
{"op":"mcm","clk":"11450438735","pt":1717322053157,"mc":[{"id":"1.229554925","rc":[{"atl":[[46,0]],"id":48638605}],"con":true,"img":false}]}
{"op":"mcm","clk":"11450440013","pt":1717322066482,"mc":[{"id":"1.229554925","rc":[{"atb":[[2.86,0],[3.15,0],[2.96,0]],"id":47148562},{"atl":[[16,0],[11,0]],"id":47148562},{"atb":[[18,0],[13,0],[15.5,0]],"id":64343695},{"atl":[[260,0],[360,0]],"id":64343695},{"atb":[[8,0],[9,0],[7,0]],"id":48638605},{"atl":[[210,0],[110,0]],"id":48638605},{"atb":[[2.72,0],[2.52,0],[2.62,0]],"id":49546922},{"atl":[[9,0],[12.5,0]],"id":49546922},{"atb":[[1.79,0],[1.74,0],[1.69,0]],"id":70003372},{"atl":[[4.3,0],[5.3,0]],"id":70003372},{"atb":[[34,0],[44,0],[27,0]],"id":40917581},{"atl":[[580,0],[480,0]],"id":40917581}],"con":true,"img":false}]}
{"op":"mcm","clk":"11450440477","pt":1717322071000,"mc":[{"id":"1.229554925","rc":[{"atb":[[3.2,27.37]],"id":47148562}],"con":true,"img":false}]}
{"op":"mcm","clk":"11450440496","pt":1717322071206,"mc":[{"id":"1.229554925","rc":[{"atb":[[1.54,21]],"id":70003372}],"con":true,"img":false}]}
{"op":"mcm","clk":"11450441483","pt":1717322080228,"mc":[{"id":"1.229554925","rc":[{"atb":[[3.2,0],[2.98,0]],"id":47148562},{"atl":[[10.5,0],[13.5,17.2]],"id":47148562},{"atb":[[2.74,0]],"id":49546922},{"atl":[[12,10.41],[8.8,7.19]],"id":49546922},{"atb":[[1.75,0]],"id":70003372}],"con":true,"img":false}]}
{"op":"mcm","clk":"11450441501","pt":1717322080400,"mc":[{"id":"1.229554925","rc":[{"atb":[[2.96,58.13],[2.94,0],[2.14,87.72],[3.05,27.37]],"id":47148562},{"atb":[[2.46,69.86]],"id":49546922},{"atb":[[1.67,61.85]],"id":70003372}],"con":true,"img":false}]}
{"op":"mcm","clk":"11450441642","pt":1717322082108,"mc":[{"id":"1.229554925","rc":[{"atb":[[2.14,0],[2.94,51.55]],"id":47148562}],"con":true,"img":false}]}
{"op":"mcm","clk":"11450441765","pt":1717322083299,"mc":[{"id":"1.229554925","rc":[{"atb":[[2.86,112.29],[3.15,48.57],[2.96,164.7]],"id":47148562},{"atl":[[16,13.95],[11,13.95]],"id":47148562},{"atb":[[18,6.14],[13,17.4],[15.5,14.4]],"id":64343695},{"atl":[[260,0.53],[360,0.58]],"id":64343695},{"atb":[[8,29.83],[9,13.05],[7,34.81]],"id":48638605},{"atl":[[210,0.99],[110,1.28]],"id":48638605},{"atb":[[2.72,60.71],[2.52,137.41],[2.62,128.93]],"id":49546922},{"atl":[[9,17.44],[12.5,18.2]],"id":49546922},{"atb":[[1.79,132.2],[1.74,282.26],[1.69,302.71]],"id":70003372},{"atl":[[4.3,42.29],[5.3,48.68]],"id":70003372},{"atb":[[34,9.04],[44,3.46],[27,11.47]],"id":40917581},{"atl":[[580,0.13],[480,0.1]],"id":40917581}],"con":true,"img":false}]}
{"op":"mcm","clk":"11450441799","pt":1717322083611,"mc":[{"id":"1.229554925","rc":[{"atb":[[50,0]],"id":40917581}],"con":true,"img":false}]}
{"op":"mcm","clk":"11450443472","pt":1717322105522,"mc":[{"id":"1.229554925","rc":[{"atb":[[2.78,0]],"id":49546922},{"atb":[[1.54,0]],"id":70003372}],"con":true,"img":false}]}
{"op":"mcm","clk":"11450443485","pt":1717322105729,"mc":[{"id":"1.229554925","rc":[{"atb":[[3.2,5.16]],"id":47148562}],"con":true,"img":false}]}
{"op":"mcm","clk":"11450446396","pt":1717322139492,"mc":[{"id":"1.229554925","rc":[{"atb":[[2.96,106.57],[3.05,0]],"id":47148562},{"atl":[[10.5,12.11],[13.5,8]],"id":47148562},{"spn":28.6,"spf":"NaN","id":48638605},{"atb":[[2.46,0]],"id":49546922},{"atl":[[12,0],[8.8,21.88]],"id":49546922},{"atb":[[1.67,0]],"id":70003372},{"spn":264.0,"spf":"NaN","id":40917581}],"con":true,"img":false}]}
{"op":"mcm","clk":"11450446402","pt":1717322139547,"mc":[{"id":"1.229554925","rc":[{"atb":[[3.2,32.53],[2.98,58.13]],"id":47148562},{"atb":[[2.74,69.86]],"id":49546922},{"atb":[[1.75,61.85]],"id":70003372}],"con":true,"img":false}]}
{"op":"mcm","clk":"11450447216","pt":1717322149659,"mc":[{"id":"1.229554925","rc":[{"atb":[[2.78,6.37]],"id":49546922}],"con":true,"img":false}]}
{"op":"mcm","clk":"11450448899","pt":1717322168883,"mc":[{"id":"1.229554925","rc":[{"atb":[[3.35,42.55]],"id":48638605},{"atl":[[75,2]],"id":48638605}],"con":true,"img":false}]}
{"op":"mcm","clk":"11450448913","pt":1717322168989,"mc":[{"id":"1.229554925","rc":[{"atb":[[2.8,55.56],[2.94,0]],"id":47148562},{"atb":[[3.9,0]],"id":48638605},{"atl":[[70,0]],"id":48638605}],"con":true,"img":false}]}
{"op":"mcm","clk":"11450470655","pt":1717322411080,"mc":[{"id":"1.229554925","rc":[{"atb":[[1.04,0.85]],"id":40917581}],"con":true,"img":false}]}
{"op":"mcm","clk":"11450470830","pt":1717322412651,"mc":[{"id":"1.229554925","rc":[{"atl":[[1000,1.85]],"id":48638605}],"con":true,"img":false}]}
{"op":"mcm","clk":"11450471011","pt":1717322414533,"mc":[{"id":"1.229554925","rc":[{"atb":[[1.04,0.17]],"id":40917581}],"con":true,"img":false}]}
{"op":"mcm","clk":"11450471093","pt":1717322415318,"mc":[{"id":"1.229554925","rc":[{"atl":[[1000,1.18]],"id":48638605}],"con":true,"img":false}]}
{"op":"mcm","clk":"11450471541","pt":1717322419351,"mc":[{"id":"1.229554925","rc":[{"atb":[[1.04,0]],"id":40917581}],"con":true,"img":false}]}
{"op":"mcm","clk":"11450471556","pt":1717322419453,"mc":[{"id":"1.229554925","rc":[{"atb":[[50,0.17]],"id":40917581}],"con":true,"img":false}]}
{"op":"mcm","clk":"11450471691","pt":1717322420860,"mc":[{"id":"1.229554925","rc":[{"atl":[[1000,1]],"id":48638605}],"con":true,"img":false}]}
{"op":"mcm","clk":"11450471702","pt":1717322420961,"mc":[{"id":"1.229554925","rc":[{"atl":[[46,0.18]],"id":48638605}],"con":true,"img":false}]}
{"op":"mcm","clk":"11450476568","pt":1717322471127,"mc":[{"id":"1.229554925","rc":[{"atb":[[2.86,0],[3.15,0],[2.96,0]],"id":47148562},{"atl":[[16,0],[11,0]],"id":47148562},{"atb":[[18,0],[13,0],[15.5,0]],"id":64343695},{"atl":[[260,0],[360,0]],"id":64343695},{"spn":78.0,"spf":"NaN","id":64343695},{"atb":[[8,0],[9,0],[7,0]],"id":48638605},{"atl":[[210,0],[110,0]],"id":48638605},{"spn":27.6,"spf":"NaN","id":48638605},{"atb":[[2.72,0],[2.52,0],[2.62,0]],"id":49546922},{"atl":[[9,0],[12.5,0]],"id":49546922},{"atb":[[1.79,0],[1.74,0],[1.69,0]],"id":70003372},{"atl":[[4.3,0],[5.3,0]],"id":70003372},{"spn":1.75,"spf":1.0,"id":70003372},{"atb":[[34,0],[44,0],[27,0]],"id":40917581},{"atl":[[580,0],[480,0]],"id":40917581},{"spn":520.0,"spf":"NaN","id":40917581}],"con":true,"img":false}]}
{"op":"mcm","clk":"11450476622","pt":1717322471703,"mc":[{"id":"1.229554925","rc":[{"atb":[[50,0]],"id":40917581}],"con":true,"img":false}]}
{"op":"mcm","clk":"11450476644","pt":1717322472012,"mc":[{"id":"1.229554925","rc":[{"atb":[[1.04,0.85]],"id":40917581}],"con":true,"img":false}]}
{"op":"mcm","clk":"11450476673","pt":1717322472325,"mc":[{"id":"1.229554925","rc":[{"atb":[[1.04,0.17]],"id":40917581}],"con":true,"img":false}]}
{"op":"mcm","clk":"11450476700","pt":1717322472643,"mc":[{"id":"1.229554925","rc":[{"atb":[[1.04,0]],"id":40917581}],"con":true,"img":false}]}
{"op":"mcm","clk":"11450476713","pt":1717322472745,"mc":[{"id":"1.229554925","rc":[{"atb":[[40,0.17]],"id":40917581}],"con":true,"img":false}]}
{"op":"mcm","clk":"11450476740","pt":1717322473015,"mc":[{"id":"1.229554925","rc":[{"atb":[[1.05,0.85]],"id":40917581}],"con":true,"img":false}]}
{"op":"mcm","clk":"11450476761","pt":1717322473334,"mc":[{"id":"1.229554925","rc":[{"atb":[[40,0],[1.05,0.15]],"id":40917581}],"con":true,"img":false}]}
{"op":"mcm","clk":"11450476783","pt":1717322473640,"mc":[{"id":"1.229554925","rc":[{"atb":[[1.05,0]],"id":40917581}],"con":true,"img":false}]}
{"op":"mcm","clk":"11450476792","pt":1717322473697,"mc":[{"id":"1.229554925","rc":[{"atb":[[55,0.15]],"id":40917581}],"con":true,"img":false}]}
{"op":"mcm","clk":"11450477274","pt":1717322479849,"mc":[{"id":"1.229554925","rc":[{"atb":[[3.2,5.16],[2.98,0]],"id":47148562},{"atl":[[10.5,0],[13.5,17.2]],"id":47148562},{"atb":[[2.74,0]],"id":49546922},{"atl":[[12,10.41],[8.8,7.19]],"id":49546922},{"atb":[[1.75,0]],"id":70003372}],"con":true,"img":false}]}
{"op":"mcm","clk":"11450477285","pt":1717322479953,"mc":[{"id":"1.229554925","rc":[{"atb":[[2.82,58.13],[3.05,27.37]],"id":47148562},{"atb":[[2.46,69.86]],"id":49546922},{"atb":[[1.67,61.85]],"id":70003372}],"con":true,"img":false}]}
{"op":"mcm","clk":"11450478011","pt":1717322489056,"mc":[{"id":"1.229554925","rc":[{"atb":[[3.2,0]],"id":47148562},{"atb":[[2.78,0]],"id":49546922}],"con":true,"img":false}]}
{"op":"mcm","clk":"11450478027","pt":1717322489262,"mc":[{"id":"1.229554925","rc":[{"atb":[[1.54,21]],"id":70003372}],"con":true,"img":false}]}
{"op":"mcm","clk":"11450478117","pt":1717322490363,"mc":[{"id":"1.229554925","rc":[{"atb":[[2.86,112.29],[3.15,48.57],[2.96,106.57]],"id":47148562},{"atl":[[16,13.95],[11,13.95]],"id":47148562},{"atb":[[18,6.14],[13,17.4],[15.5,14.4]],"id":64343695},{"atl":[[260,0.53],[360,0.58]],"id":64343695},{"atb":[[8,29.83],[9,13.05],[7,34.81]],"id":48638605},{"atl":[[210,0.99],[110,1.28]],"id":48638605},{"atb":[[2.72,60.71],[2.52,137.41],[2.62,128.93]],"id":49546922},{"atl":[[9,17.44],[12.5,18.2]],"id":49546922},{"atb":[[1.79,132.2],[1.74,282.26],[1.69,302.71]],"id":70003372},{"atl":[[4.3,42.29],[5.3,48.68]],"id":70003372},{"atb":[[34,9.04],[44,3.46],[27,11.47]],"id":40917581},{"atl":[[580,0.13],[480,0.1]],"id":40917581}],"con":true,"img":false}]}
{"op":"mcm","clk":"11450479006","pt":1717322501755,"mc":[{"id":"1.229554925","rc":[{"atb":[[55,0]],"id":40917581}],"con":true,"img":false}]}
{"op":"mcm","clk":"11450479027","pt":1717322502061,"mc":[{"id":"1.229554925","rc":[{"atb":[[1.05,0.85]],"id":40917581}],"con":true,"img":false}]}
{"op":"mcm","clk":"11450479067","pt":1717322502748,"mc":[{"id":"1.229554925","rc":[{"atb":[[1.05,0.15]],"id":40917581}],"con":true,"img":false}]}
{"op":"mcm","clk":"11450479143","pt":1717322503366,"mc":[{"id":"1.229554925","rc":[{"atb":[[1.05,0]],"id":40917581}],"con":true,"img":false}]}
{"op":"mcm","clk":"11450479156","pt":1717322503473,"mc":[{"id":"1.229554925","rc":[{"atb":[[50,0.15]],"id":40917581}],"con":true,"img":false}]}
{"op":"mcm","clk":"11450480541","pt":1717322520082,"mc":[{"id":"1.229554925","rc":[{"atb":[[3.05,0]],"id":47148562}],"con":true,"img":false}]}
{"op":"mcm","clk":"11450480549","pt":1717322520175,"mc":[{"id":"1.229554925","rc":[{"atb":[[3.2,27.37]],"id":47148562}],"con":true,"img":false}]}
{"op":"mcm","clk":"11450480802","pt":1717322523577,"mc":[{"id":"1.229554925","rc":[{"atb":[[1.67,0]],"id":70003372}],"con":true,"img":false}]}
{"op":"mcm","clk":"11450480809","pt":1717322523681,"mc":[{"id":"1.229554925","rc":[{"atb":[[1.75,61.85]],"id":70003372}],"con":true,"img":false}]}
{"op":"mcm","clk":"11450480882","pt":1717322524777,"mc":[{"id":"1.229554925","rc":[{"atb":[[1.54,0]],"id":70003372}],"con":true,"img":false}]}
{"op":"mcm","clk":"11450480890","pt":1717322524883,"mc":[{"id":"1.229554925","rc":[{"atb":[[3.2,32.53]],"id":47148562}],"con":true,"img":false}]}
{"op":"mcm","clk":"11450480905","pt":1717322525084,"mc":[{"id":"1.229554925","rc":[{"atb":[[2.76,6.44]],"id":49546922}],"con":true,"img":false}]}
{"op":"mcm","clk":"11450481122","pt":1717322527694,"mc":[{"id":"1.229554925","rc":[{"atb":[[2.86,0],[3.15,0],[2.96,0]],"id":47148562},{"atl":[[16,0],[11,0]],"id":47148562},{"atb":[[18,0],[13,0],[15.5,0]],"id":64343695},{"atl":[[260,0],[360,0]],"id":64343695},{"atb":[[8,0],[9,0],[7,0]],"id":48638605},{"atl":[[210,0],[110,0]],"id":48638605},{"atb":[[2.72,0],[2.52,0],[2.62,0]],"id":49546922},{"atl":[[9,0],[12.5,0]],"id":49546922},{"atb":[[1.79,0],[1.74,0],[1.69,0]],"id":70003372},{"atl":[[4.3,0],[5.3,0]],"id":70003372},{"atb":[[34,0],[44,0],[27,0]],"id":40917581},{"atl":[[580,0],[480,0]],"id":40917581}],"con":true,"img":false}]}
{"op":"mcm","clk":"11450481694","pt":1717322534816,"mc":[{"id":"1.229554925","rc":[{"atb":[[3.2,5.16]],"id":47148562},{"atb":[[1.75,0]],"id":70003372},{"spn":1.53,"spf":1.0,"id":70003372}],"con":true,"img":false}]}
{"op":"mcm","clk":"11450481705","pt":1717322534894,"mc":[{"id":"1.229554925","rc":[{"atb":[[3.05,27.37]],"id":47148562},{"atb":[[1.67,61.85]],"id":70003372}],"con":true,"img":false}]}
{"op":"mcm","clk":"11450482349","pt":1717322542712,"mc":[{"id":"1.229554925","rc":[{"atb":[[2.86,112.29],[3.15,48.57],[2.96,106.57]],"id":47148562},{"atl":[[16,13.95],[11,13.95]],"id":47148562},{"atb":[[17,6.52],[12,18.98],[14.5,15.47]],"id":64343695},{"atl":[[350,0.6],[250,0.55]],"id":64343695},{"atb":[[8,29.83],[9,13.05],[7,34.81]],"id":48638605},{"atl":[[210,0.99],[110,1.28]],"id":48638605},{"atb":[[2.72,60.71],[2.52,137.41],[2.62,128.93]],"id":49546922},{"atl":[[9,17.44],[12.5,18.2]],"id":49546922},{"atb":[[1.73,286.13],[1.83,125.82],[1.78,267.78]],"id":70003372},{"atl":[[4.5,39.87],[5.5,46.52]],"id":70003372},{"atb":[[32,9.62],[42,3.63],[26,11.92]],"id":40917581},{"atl":[[570,0.13],[470,0.1]],"id":40917581}],"con":true,"img":false}]}
{"op":"mcm","clk":"11450482374","pt":1717322543082,"mc":[{"id":"1.229554925","rc":[{"atb":[[50,0],[1.05,0.85]],"id":40917581}],"con":true,"img":false}]}
{"op":"mcm","clk":"11450482450","pt":1717322543974,"mc":[{"id":"1.229554925","rc":[{"atb":[[3.2,9.6]],"id":47148562},{"atb":[[1.05,0.15]],"id":40917581}],"con":true,"img":false}]}
{"op":"mcm","clk":"11450482492","pt":1717322544548,"mc":[{"id":"1.229554925","rc":[{"atb":[[1.05,0]],"id":40917581}],"con":true,"img":false}]}
{"op":"mcm","clk":"11450482501","pt":1717322544651,"mc":[{"id":"1.229554925","rc":[{"atb":[[44,0.15]],"id":40917581}],"con":true,"img":false}]}
{"op":"mcm","clk":"11450484376","pt":1717322571101,"mc":[{"id":"1.229554925","rc":[{"atb":[[3.05,0]],"id":47148562},{"atb":[[1.67,0]],"id":70003372}],"con":true,"img":false}]}
{"op":"mcm","clk":"11450484384","pt":1717322571203,"mc":[{"id":"1.229554925","rc":[{"atb":[[3.2,36.97]],"id":47148562},{"atb":[[1.74,61.85]],"id":70003372}],"con":true,"img":false}]}
{"op":"mcm","clk":"11450485448","pt":1717322584532,"mc":[{"id":"1.229554925","rc":[{"atb":[[2.86,0],[3.15,0],[2.96,0]],"id":47148562},{"atl":[[16,0],[11,0]],"id":47148562},{"atb":[[17,0],[12,0],[14.5,0]],"id":64343695},{"atl":[[350,0],[250,0]],"id":64343695},{"atb":[[8,0],[9,0],[7,0]],"id":48638605},{"atl":[[210,0],[110,0]],"id":48638605},{"atb":[[2.72,0],[2.52,0],[2.62,0]],"id":49546922},{"atl":[[9,0],[12.5,0]],"id":49546922},{"atb":[[32,0],[42,0],[26,0]],"id":40917581},{"atl":[[570,0],[470,0]],"id":40917581}],"con":true,"img":false}]}
{"op":"mcm","clk":"11450485559","pt":1717322585995,"mc":[{"id":"1.229554925","rc":[{"atb":[[3.2,32.53]],"id":47148562}],"con":true,"img":false}]}
{"op":"mcm","clk":"11450486058","pt":1717322591533,"mc":[{"id":"1.229554925","rc":[{"atb":[[1.04,0.85]],"id":40917581}],"con":true,"img":false}]}
{"op":"mcm","clk":"11450486081","pt":1717322591793,"mc":[{"id":"1.229554925","rc":[{"atb":[[44,0]],"id":40917581}],"con":true,"img":false}]}
{"op":"mcm","clk":"11450486117","pt":1717322592131,"mc":[{"id":"1.229554925","rc":[{"atb":[[1.04,0.17]],"id":40917581}],"con":true,"img":false}]}
{"op":"mcm","clk":"11450486169","pt":1717322592826,"mc":[{"id":"1.229554925","rc":[{"atb":[[1.04,0]],"id":40917581}],"con":true,"img":false}]}
{"op":"mcm","clk":"11450486181","pt":1717322592932,"mc":[{"id":"1.229554925","rc":[{"atb":[[50,0.17]],"id":40917581}],"con":true,"img":false}]}
{"op":"mcm","clk":"11450486601","pt":1717322597315,"mc":[{"id":"1.229554925","rc":[{"atb":[[3.2,27.37]],"id":47148562},{"atb":[[2.76,0]],"id":49546922},{"spn":1.83,"spf":1.0,"id":70003372}],"con":true,"img":false}]}
{"op":"mcm","clk":"11450486967","pt":1717322601652,"mc":[{"id":"1.229554925","rc":[{"atb":[[2.86,112.29],[3.15,48.57],[2.96,106.57]],"id":47148562},{"atl":[[16,13.95],[11,13.95]],"id":47148562},{"atb":[[17,6.52],[12,18.98],[14.5,15.47]],"id":64343695},{"atl":[[350,0.6],[250,0.55]],"id":64343695},{"atb":[[8,29.83],[9,13.05],[7,34.81]],"id":48638605},{"atl":[[210,0.99],[110,1.28]],"id":48638605},{"atb":[[2.72,60.71],[2.52,137.41],[2.62,128.93]],"id":49546922},{"atl":[[9,17.44],[12.5,18.2]],"id":49546922},{"atb":[[32,9.62],[42,3.63],[26,11.92]],"id":40917581},{"atl":[[570,0.13],[470,0.1]],"id":40917581}],"con":true,"img":false}]}
{"op":"mcm","clk":"11450487387","pt":1717322606345,"mc":[{"id":"1.229554925","rc":[{"atb":[[2.82,0]],"id":47148562},{"atl":[[10.5,12.11],[13.5,8]],"id":47148562}],"con":true,"img":false}]}
{"op":"mcm","clk":"11450487399","pt":1717322606453,"mc":[{"id":"1.229554925","rc":[{"atb":[[2.98,58.13]],"id":47148562}],"con":true,"img":false}]}
{"op":"mcm","clk":"11450488545","pt":1717322618869,"mc":[{"id":"1.229554925","rc":[{"atb":[[13.5,0]],"id":64343695},{"atb":[[2.46,0]],"id":49546922}],"con":true,"img":false}]}
{"op":"mcm","clk":"11450488558","pt":1717322618973,"mc":[{"id":"1.229554925","rc":[{"atb":[[15,8.22]],"id":64343695},{"atb":[[2.74,69.86]],"id":49546922}],"con":true,"img":false}]}
{"op":"mcm","clk":"11450490272","pt":1717322638585,"mc":[{"id":"1.229554925","rc":[{"atb":[[2.82,0]],"id":49546922}],"con":true,"img":false}]}
{"op":"mcm","clk":"11450490280","pt":1717322638690,"mc":[{"id":"1.229554925","rc":[{"atb":[[2.88,30.83]],"id":49546922}],"con":true,"img":false}]}
{"op":"mcm","clk":"11450490333","pt":1717322639379,"mc":[{"id":"1.229554925","rc":[{"atb":[[2.86,0],[3.15,0],[2.96,0]],"id":47148562},{"atl":[[16,0],[11,0]],"id":47148562},{"atb":[[8,0],[9,0],[7,0]],"id":48638605},{"atl":[[210,0],[110,0]],"id":48638605},{"atb":[[2.72,0],[2.52,0],[2.62,0]],"id":49546922},{"atl":[[9,0],[12.5,0]],"id":49546922}],"con":true,"img":false}]}
{"op":"mcm","clk":"11450490446","pt":1717322640764,"mc":[{"id":"1.229554925","rc":[{"atb":[[3.2,32.53]],"id":47148562},{"atb":[[2.78,6.37]],"id":49546922}],"con":true,"img":false}]}
{"op":"mcm","clk":"11450491500","pt":1717322651795,"mc":[{"id":"1.229554925","rc":[{"atb":[[2.86,112.29],[3.15,48.57],[2.96,106.57]],"id":47148562},{"atl":[[16,13.95],[11,13.95]],"id":47148562},{"atb":[[8,29.83],[9,13.05],[7,34.81]],"id":48638605},{"atl":[[210,0.99],[110,1.28]],"id":48638605},{"atb":[[2.72,60.71],[2.52,137.41],[2.62,128.93]],"id":49546922},{"atl":[[9,17.44],[12.5,18.2]],"id":49546922}],"con":true,"img":false}]}
{"op":"mcm","clk":"11450505715","pt":1717322805472,"mc":[{"id":"1.229554925","rc":[{"atb":[[2.86,0],[3.15,0],[2.96,0]],"id":47148562},{"atl":[[16,0],[11,0]],"id":47148562},{"atb":[[17,0],[12,0],[14.5,0]],"id":64343695},{"atl":[[350,0],[250,0]],"id":64343695},{"atb":[[8,0],[9,0],[7,0]],"id":48638605},{"atl":[[210,0],[110,0]],"id":48638605},{"atb":[[2.72,0],[2.52,0],[2.62,0]],"id":49546922},{"atl":[[9,0],[12.5,0]],"id":49546922},{"spn":5.84,"spf":"NaN","id":49546922},{"atb":[[1.73,0],[1.83,0],[1.78,0]],"id":70003372},{"atl":[[4.5,0],[5.5,0]],"id":70003372},{"spn":1.74,"spf":1.0,"id":70003372},{"atb":[[32,0],[42,0],[26,0]],"id":40917581},{"atl":[[570,0],[470,0]],"id":40917581}],"con":true,"img":false}]}
{"op":"mcm","clk":"11450505747","pt":1717322805747,"mc":[{"id":"1.229554925","rc":[{"atb":[[50,0]],"id":40917581}],"con":true,"img":false}]}
{"op":"mcm","clk":"11450506032","pt":1717322809472,"mc":[{"id":"1.229554925","rc":[{"atl":[[10.5,0],[13.5,17.2]],"id":47148562}],"con":true,"img":false}]}
{"op":"mcm","clk":"11450506042","pt":1717322809570,"mc":[{"id":"1.229554925","rc":[{"atb":[[3.2,5.16],[2.98,0]],"id":47148562},{"atb":[[15,0]],"id":64343695},{"atb":[[2.74,0]],"id":49546922},{"atb":[[1.74,0]],"id":70003372}],"con":true,"img":false}]}
{"op":"mcm","clk":"11450506054","pt":1717322809680,"mc":[{"id":"1.229554925","rc":[{"atb":[[2.82,58.13],[3.05,27.37]],"id":47148562},{"atb":[[12.5,8.22]],"id":64343695},{"atb":[[2.5,69.86]],"id":49546922},{"atb":[[1.66,61.85]],"id":70003372}],"con":true,"img":false}]}
{"op":"mcm","clk":"11450506752","pt":1717322817769,"mc":[{"id":"1.229554925","rc":[{"atb":[[3.2,0]],"id":47148562},{"atb":[[2.78,0]],"id":49546922},{"atb":[[1.54,21]],"id":70003372}],"con":true,"img":false}]}
{"op":"mcm","clk":"11450507006","pt":1717322820789,"mc":[{"id":"1.229554925","rc":[{"atb":[[2.86,112.29],[3.15,48.57],[2.96,106.57]],"id":47148562},{"atl":[[16,13.95],[11,13.95]],"id":47148562},{"atb":[[17,6.52],[12,18.98],[14.5,15.47]],"id":64343695},{"atl":[[350,0.6],[250,0.55]],"id":64343695},{"atb":[[8,29.83],[9,13.05],[7,34.81]],"id":48638605},{"atl":[[210,0.99],[110,1.28]],"id":48638605},{"atb":[[2.72,60.71],[2.52,137.41],[2.62,128.93]],"id":49546922},{"atl":[[9,17.44],[12.5,18.2]],"id":49546922},{"atb":[[1.73,286.13],[1.83,125.82],[1.78,267.78]],"id":70003372},{"atl":[[4.5,39.87],[5.5,46.52]],"id":70003372},{"atb":[[32,9.62],[42,3.63],[26,11.92]],"id":40917581},{"atl":[[570,0.13],[470,0.1]],"id":40917581}],"con":true,"img":false}]}
{"op":"mcm","clk":"11450510217","pt":1717322855175,"mc":[{"id":"1.229554925","rc":[{"atb":[[1.54,0]],"id":70003372}],"con":true,"img":false}]}
{"op":"mcm","clk":"11450510240","pt":1717322855384,"mc":[{"id":"1.229554925","rc":[{"atb":[[3.2,5.16]],"id":47148562}],"con":true,"img":false}]}
{"op":"mcm","clk":"11450510271","pt":1717322855646,"mc":[{"id":"1.229554925","rc":[{"atb":[[2.76,6.44]],"id":49546922}],"con":true,"img":false}]}
{"op":"mcm","clk":"11450510471","pt":1717322857780,"mc":[{"id":"1.229554925","rc":[{"atb":[[3.2,9.55]],"id":47148562}],"con":true,"img":false}]}
{"op":"mcm","clk":"11450510687","pt":1717322860056,"mc":[{"id":"1.229554925","rc":[{"atb":[[3.05,0]],"id":47148562},{"atb":[[1.66,0]],"id":70003372}],"con":true,"img":false}]}
{"op":"mcm","clk":"11450510696","pt":1717322860159,"mc":[{"id":"1.229554925","rc":[{"atb":[[3.2,36.92]],"id":47148562},{"atb":[[1.74,61.85]],"id":70003372}],"con":true,"img":false}]}
{"op":"mcm","clk":"11450512403","pt":1717322876271,"mc":[{"id":"1.229554925","rc":[{"atb":[[2.82,0]],"id":47148562},{"atl":[[10.5,12.11],[13.5,8]],"id":47148562},{"atb":[[12.5,0]],"id":64343695},{"spn":78.5,"spf":"NaN","id":64343695},{"atb":[[2.5,0]],"id":49546922},{"spn":1.83,"spf":1.0,"id":70003372},{"spn":259.0,"spf":"NaN","id":40917581}],"con":true,"img":false}]}
{"op":"mcm","clk":"11450512413","pt":1717322876373,"mc":[{"id":"1.229554925","rc":[{"atb":[[2.98,58.13]],"id":47148562},{"atb":[[15,8.22]],"id":64343695},{"atb":[[2.74,69.86]],"id":49546922}],"con":true,"img":false}]}
{"op":"mcm","clk":"11450514517","pt":1717322896026,"mc":[{"id":"1.229554925","rc":[{"atb":[[2.76,0]],"id":49546922}],"con":true,"img":false}]}
{"op":"mcm","clk":"11450519107","pt":1717322939070,"mc":[{"id":"1.229554925","rc":[{"atb":[[2.78,6.37]],"id":49546922}],"con":true,"img":false}]}
{"op":"mcm","clk":"11450531641","pt":1717323065992,"mc":[{"id":"1.229554925","rc":[{"atb":[[3.25,2.55]],"id":47148562},{"spn":5.62,"spf":"NaN","id":47148562},{"atb":[[17.5,2.13]],"id":64343695},{"spn":78.75,"spf":"NaN","id":64343695},{"atb":[[9.4,2.55]],"id":48638605},{"spn":27.7,"spf":"NaN","id":48638605},{"atb":[[2.94,2.55]],"id":49546922},{"spn":5.87,"spf":"NaN","id":49546922}],"con":true,"img":false}]}
{"op":"mcm","clk":"11450532059","pt":1717323070084,"mc":[{"id":"1.229554925","rc":[{"atb":[[3.2,32.53]],"id":47148562}],"con":true,"img":false}]}
{"op":"mcm","clk":"11450532645","pt":1717323076023,"mc":[{"id":"1.229554925","rc":[{"atb":[[3.25,6.91]],"id":47148562}],"con":true,"img":false}]}
{"op":"mcm","clk":"11450533340","pt":1717323082598,"mc":[{"id":"1.229554925","rc":[{"atb":[[16,6.94]],"id":64343695}],"con":true,"img":false}]}
{"op":"mcm","clk":"11450533360","pt":1717323082814,"mc":[{"id":"1.229554925","rc":[{"atb":[[8.6,5.95]],"id":48638605}],"con":true,"img":false}]}
{"op":"mcm","clk":"11450533379","pt":1717323083018,"mc":[{"id":"1.229554925","rc":[{"atb":[[1.66,30.82]],"id":70003372}],"con":true,"img":false}]}
{"op":"mcm","clk":"11450533392","pt":1717323083131,"mc":[{"id":"1.229554925","rc":[{"atb":[[2.68,19.09]],"id":49546922}],"con":true,"img":false}]}
{"op":"mcm","clk":"11450533402","pt":1717323083230,"mc":[{"id":"1.229554925","rc":[{"atb":[[2.96,123.85]],"id":47148562}],"con":true,"img":false}]}
{"op":"mcm","clk":"11450533409","pt":1717323083332,"mc":[{"id":"1.229554925","rc":[{"atb":[[44,1.16]],"id":40917581}],"con":true,"img":false}]}
{"op":"mcm","clk":"11450535416","pt":1717323102695,"mc":[{"id":"1.229554925","rc":[{"atb":[[16,3.2]],"id":64343695}],"con":true,"img":false}]}
{"op":"mcm","clk":"11450535427","pt":1717323102799,"mc":[{"id":"1.229554925","rc":[{"atb":[[17.5,5.87]],"id":64343695}],"con":true,"img":false}]}
{"op":"mcm","clk":"11450536402","pt":1717323112709,"mc":[{"id":"1.229554925","rc":[{"atb":[[38,0]],"id":40917581}],"con":true,"img":false}]}
{"op":"mcm","clk":"11450536415","pt":1717323112812,"mc":[{"id":"1.229554925","rc":[{"atb":[[44,4.82]],"id":40917581}],"con":true,"img":false}]}
{"op":"mcm","clk":"11450538409","pt":1717323132640,"mc":[{"id":"1.229554925","rc":[{"atb":[[8.2,0]],"id":48638605}],"con":true,"img":false}]}
{"op":"mcm","clk":"11450538420","pt":1717323132738,"mc":[{"id":"1.229554925","rc":[{"atb":[[8.8,14.71]],"id":48638605}],"con":true,"img":false}]}
{"op":"mcm","clk":"11450539313","pt":1717323141456,"mc":[{"id":"1.229554925","rc":[{"atb":[[2.86,0],[3.15,0],[2.96,17.28]],"id":47148562},{"atl":[[16,0],[11,0]],"id":47148562},{"atb":[[17,0],[12,0],[14.5,0]],"id":64343695},{"atl":[[350,0],[250,0]],"id":64343695},{"atb":[[8,0],[9,0],[7,0]],"id":48638605},{"atl":[[210,0],[110,0]],"id":48638605},{"atb":[[2.72,0],[2.52,0],[2.62,0]],"id":49546922},{"atl":[[9,0],[12.5,0]],"id":49546922},{"atb":[[1.73,0],[1.83,0],[1.78,0]],"id":70003372},{"atl":[[4.5,0],[5.5,0]],"id":70003372},{"atb":[[32,0],[42,0],[26,0]],"id":40917581},{"atl":[[570,0],[470,0]],"id":40917581}],"con":true,"img":false}]}
{"op":"mcm","clk":"11450539471","pt":1717323142667,"mc":[{"id":"1.229554925","rc":[{"atb":[[3.2,5.16]],"id":47148562},{"atl":[[10.5,0],[13.5,17.2]],"id":47148562},{"atb":[[15,0]],"id":64343695},{"atb":[[2.74,0]],"id":49546922},{"atb":[[1.74,0]],"id":70003372}],"con":true,"img":false}]}
{"op":"mcm","clk":"11450539486","pt":1717323142771,"mc":[{"id":"1.229554925","rc":[{"atb":[[3.05,27.37]],"id":47148562},{"atb":[[12.5,8.22]],"id":64343695},{"atb":[[2.7,69.86]],"id":49546922},{"atb":[[1.67,61.85]],"id":70003372}],"con":true,"img":false}]}
{"op":"mcm","clk":"11450540463","pt":1717323151396,"mc":[{"id":"1.229554925","rc":[{"atb":[[3.2,0]],"id":47148562},{"atb":[[2.78,0]],"id":49546922}],"con":true,"img":false}]}
{"op":"mcm","clk":"11450540485","pt":1717323151566,"mc":[{"id":"1.229554925","rc":[{"atb":[[1.54,21]],"id":70003372}],"con":true,"img":false}]}
{"op":"mcm","clk":"11450540612","pt":1717323152809,"mc":[{"id":"1.229554925","rc":[{"atb":[[2.86,112.29],[3.15,48.57],[2.96,123.85]],"id":47148562},{"atl":[[16,13.95],[11,13.95]],"id":47148562},{"atb":[[17,6.52],[12,18.98],[14.5,15.47]],"id":64343695},{"atl":[[350,0.6],[250,0.55]],"id":64343695},{"atb":[[8,29.83],[9,13.05],[7,34.81]],"id":48638605},{"atl":[[210,0.99],[110,1.28]],"id":48638605},{"atb":[[2.72,60.71],[2.52,137.41],[2.62,128.93]],"id":49546922},{"atl":[[9,17.44],[12.5,18.2]],"id":49546922},{"atb":[[1.73,286.13],[1.83,125.82],[1.78,267.78]],"id":70003372},{"atl":[[4.5,39.87],[5.5,46.52]],"id":70003372},{"atb":[[32,9.62],[42,3.63],[26,11.92]],"id":40917581},{"atl":[[570,0.13],[470,0.1]],"id":40917581}],"con":true,"img":false}]}
{"op":"mcm","clk":"11450543697","pt":1717323180350,"mc":[{"id":"1.229554925","rc":[{"atb":[[1.54,0]],"id":70003372}],"con":true,"img":false}]}
{"op":"mcm","clk":"11450543754","pt":1717323180720,"mc":[{"id":"1.229554925","rc":[{"atb":[[3.2,5.16]],"id":47148562},{"atb":[[2.76,6.44]],"id":49546922}],"con":true,"img":false}]}
{"op":"mcm","clk":"11450544081","pt":1717323183653,"mc":[{"id":"1.229554925","rc":[{"atb":[[1.87,2.11]],"id":70003372}],"con":true,"img":false}]}
{"op":"mcm","clk":"11450545117","pt":1717323192768,"mc":[{"id":"1.229554925","rc":[{"atb":[[3.05,0]],"id":47148562},{"atb":[[2.7,0]],"id":49546922},{"atb":[[1.67,0]],"id":70003372},{"spn":1.83,"spf":1.0,"id":70003372}],"con":true,"img":false}]}
{"op":"mcm","clk":"11450545127","pt":1717323192872,"mc":[{"id":"1.229554925","rc":[{"atb":[[3.2,32.53]],"id":47148562},{"atb":[[2.74,69.86]],"id":49546922},{"atb":[[1.74,61.85]],"id":70003372}],"con":true,"img":false}]}
{"op":"mcm","clk":"11450546183","pt":1717323202676,"mc":[{"id":"1.229554925","rc":[{"atb":[[12.5,0]],"id":64343695}],"con":true,"img":false}]}
{"op":"mcm","clk":"11450546191","pt":1717323202779,"mc":[{"id":"1.229554925","rc":[{"atl":[[10.5,12.11],[13.5,8]],"id":47148562},{"atb":[[15,8.22]],"id":64343695}],"con":true,"img":false}]}
{"op":"mcm","clk":"11450547082","pt":1717323210995,"mc":[{"id":"1.229554925","rc":[{"atb":[[2.76,0]],"id":49546922}],"con":true,"img":false}]}
{"op":"mcm","clk":"11450551194","pt":1717323248091,"mc":[{"id":"1.229554925","rc":[{"atb":[[3.8,35.71]],"id":48638605},{"atl":[[65,4.61]],"id":48638605}],"con":true,"img":false}]}
{"op":"mcm","clk":"11450551202","pt":1717323248133,"mc":[{"id":"1.229554925","rc":[{"atb":[[2.8,0],[3,50]],"id":47148562},{"atb":[[3.35,0]],"id":48638605},{"atl":[[75,0]],"id":48638605}],"con":true,"img":false}]}
{"op":"mcm","clk":"11450551315","pt":1717323249268,"mc":[{"id":"1.229554925","rc":[{"atb":[[3,0],[2.94,51.55]],"id":47148562},{"atl":[[65,2.61],[70,2]],"id":48638605}],"con":true,"img":false}]}
{"op":"mcm","clk":"11450551616","pt":1717323252004,"mc":[{"id":"1.229554925","rc":[{"atb":[[2.78,6.37]],"id":49546922}],"con":true,"img":false}]}
{"op":"mcm","clk":"11450564619","pt":1717323369258,"mc":[{"id":"1.229554925","rc":[{"atb":[[2.8,55.56],[2.94,0]],"id":47148562},{"atb":[[3.35,42.55],[3.8,0]],"id":48638605}],"con":true,"img":false}]}
{"op":"mcm","clk":"11450570002","pt":1717323412727,"mc":[{"id":"1.229554925","rc":[{"atb":[[8.8,0]],"id":48638605}],"con":true,"img":false}]}
{"op":"mcm","clk":"11450570016","pt":1717323412830,"mc":[{"id":"1.229554925","rc":[{"atb":[[9.2,21.56]],"id":48638605}],"con":true,"img":false}]}
{"op":"mcm","clk":"11450571144","pt":1717323422638,"mc":[{"id":"1.229554925","rc":[{"atb":[[9.2,6.84]],"id":48638605}],"con":true,"img":false}]}
{"op":"mcm","clk":"11450571169","pt":1717323422850,"mc":[{"id":"1.229554925","rc":[{"atb":[[8.8,14.71]],"id":48638605}],"con":true,"img":false}]}
{"op":"mcm","clk":"11450577219","pt":1717323472711,"mc":[{"id":"1.229554925","rc":[{"atb":[[8.8,0]],"id":48638605}],"con":true,"img":false}]}
{"op":"mcm","clk":"11450577231","pt":1717323472819,"mc":[{"id":"1.229554925","rc":[{"atb":[[9.2,21.56]],"id":48638605}],"con":true,"img":false}]}
{"op":"mcm","clk":"11450578293","pt":1717323482757,"mc":[{"id":"1.229554925","rc":[{"atb":[[9.2,6.84]],"id":48638605}],"con":true,"img":false}]}
{"op":"mcm","clk":"11450578308","pt":1717323482822,"mc":[{"id":"1.229554925","rc":[{"atb":[[8.8,14.71]],"id":48638605}],"con":true,"img":false}]}
{"op":"mcm","clk":"11450578795","pt":1717323487255,"mc":[{"id":"1.229554925","rc":[{"atb":[[2.86,0],[3.15,0],[2.96,17.28]],"id":47148562},{"atl":[[16,0],[11,0]],"id":47148562},{"atb":[[17,0],[12,0],[14.5,0]],"id":64343695},{"atl":[[350,0],[250,0]],"id":64343695},{"atb":[[8,0],[9,0],[7,0]],"id":48638605},{"atl":[[210,0],[110,0]],"id":48638605},{"atb":[[2.72,0],[2.52,0],[2.62,0]],"id":49546922},{"atl":[[9,0],[12.5,0]],"id":49546922},{"atb":[[1.73,0],[1.83,0],[1.78,0]],"id":70003372},{"atl":[[4.5,0],[5.5,0]],"id":70003372},{"atb":[[32,0],[42,0],[26,0]],"id":40917581},{"atl":[[570,0],[470,0]],"id":40917581}],"con":true,"img":false}]}
{"op":"mcm","clk":"11450579380","pt":1717323492651,"mc":[{"id":"1.229554925","rc":[{"atb":[[3.2,5.16]],"id":47148562},{"atl":[[10.5,0],[13.5,17.2]],"id":47148562},{"atb":[[15,0]],"id":64343695},{"atb":[[2.74,0]],"id":49546922},{"atb":[[1.74,0]],"id":70003372}],"con":true,"img":false}]}
{"op":"mcm","clk":"11450579392","pt":1717323492755,"mc":[{"id":"1.229554925","rc":[{"atb":[[3.05,27.37]],"id":47148562},{"atb":[[12.5,8.22]],"id":64343695},{"atb":[[2.7,69.86]],"id":49546922},{"atb":[[1.67,61.85]],"id":70003372}],"con":true,"img":false}]}
{"op":"mcm","clk":"11450579855","pt":1717323496987,"mc":[{"id":"1.229554925","rc":[{"atb":[[2.86,112.29],[3.15,48.57],[2.96,123.85]],"id":47148562},{"atl":[[16,13.95],[11,13.95]],"id":47148562},{"atb":[[17,6.52],[12,18.98],[14.5,15.47]],"id":64343695},{"atl":[[350,0.6],[250,0.55]],"id":64343695},{"atb":[[8,29.83],[9,13.05],[7,34.81]],"id":48638605},{"atl":[[210,0.99],[110,1.28]],"id":48638605},{"atb":[[2.72,60.71],[2.52,137.41],[2.62,128.93]],"id":49546922},{"atl":[[9,17.44],[12.5,18.2]],"id":49546922},{"atb":[[1.73,286.13],[1.83,125.82],[1.78,267.78]],"id":70003372},{"atl":[[4.5,39.87],[5.5,46.52]],"id":70003372},{"atb":[[32,9.62],[42,3.63],[26,11.92]],"id":40917581},{"atl":[[570,0.13],[470,0.1]],"id":40917581}],"con":true,"img":false}]}
{"op":"mcm","clk":"11450582719","pt":1717323524786,"mc":[{"id":"1.229554925","rc":[{"atb":[[2.78,0]],"id":49546922}],"con":true,"img":false}]}
{"op":"mcm","clk":"11450583575","pt":1717323532675,"mc":[{"id":"1.229554925","rc":[{"atb":[[3.05,0]],"id":47148562},{"atb":[[2.7,0]],"id":49546922},{"atb":[[1.67,0]],"id":70003372}],"con":true,"img":false}]}
{"op":"mcm","clk":"11450583586","pt":1717323532779,"mc":[{"id":"1.229554925","rc":[{"atb":[[3.2,32.53]],"id":47148562},{"atb":[[2.74,69.86]],"id":49546922},{"atb":[[1.74,61.85]],"id":70003372}],"con":true,"img":false}]}
{"op":"mcm","clk":"11450584549","pt":1717323542710,"mc":[{"id":"1.229554925","rc":[{"atl":[[10.5,12.11],[13.5,8]],"id":47148562},{"atb":[[12.5,0]],"id":64343695}],"con":true,"img":false}]}
{"op":"mcm","clk":"11450584558","pt":1717323542821,"mc":[{"id":"1.229554925","rc":[{"atb":[[15,8.22]],"id":64343695}],"con":true,"img":false}]}
{"op":"mcm","clk":"11450586303","pt":1717323561346,"mc":[{"id":"1.229554925","rc":[{"atb":[[2.78,6.37]],"id":49546922}],"con":true,"img":false}]}
{"op":"mcm","clk":"11450586569","pt":1717323563758,"mc":[{"id":"1.229554925","rc":[{"atb":[[3.5,2.61]],"id":47148562},{"atb":[[3.2,2.61]],"id":49546922}],"con":true,"img":false}]}
{"op":"mcm","clk":"11450586733","pt":1717323565029,"mc":[{"id":"1.229554925","rc":[{"atb":[[3.25,4.36]],"id":47148562},{"atb":[[2.94,0]],"id":49546922}],"con":true,"img":false}]}
{"op":"mcm","clk":"11450586860","pt":1717323566229,"mc":[{"id":"1.229554925","rc":[{"atb":[[3.25,0]],"id":47148562}],"con":true,"img":false}]}
{"op":"mcm","clk":"11450590292","pt":1717323602682,"mc":[{"id":"1.229554925","rc":[{"spn":5.75,"spf":"NaN","id":47148562},{"atb":[[8.8,0]],"id":48638605},{"spn":6.0,"spf":"NaN","id":49546922}],"con":true,"img":false}]}
{"op":"mcm","clk":"11450590304","pt":1717323602790,"mc":[{"id":"1.229554925","rc":[{"atb":[[9.2,21.56]],"id":48638605}],"con":true,"img":false}]}
{"op":"mcm","clk":"11450591314","pt":1717323612895,"mc":[{"id":"1.229554925","rc":[{"atl":[[65,4.61],[70,0]],"id":48638605}],"con":true,"img":false}]}
{"op":"mcm","clk":"11450591426","pt":1717323613984,"mc":[{"id":"1.229554925","rc":[{"atl":[[46,0]],"id":48638605}],"con":true,"img":false}]}
{"op":"mcm","clk":"11450591641","pt":1717323616316,"mc":[{"id":"1.229554925","rc":[{"atl":[[1000,1.85]],"id":48638605}],"con":true,"img":false}]}
{"op":"mcm","clk":"11450591981","pt":1717323619898,"mc":[{"id":"1.229554925","rc":[{"atl":[[1000,1.18]],"id":48638605}],"con":true,"img":false}]}
{"op":"mcm","clk":"11450592068","pt":1717323620826,"mc":[{"id":"1.229554925","rc":[{"atl":[[1000,1]],"id":48638605}],"con":true,"img":false}]}
{"op":"mcm","clk":"11450592077","pt":1717323620901,"mc":[{"id":"1.229554925","rc":[{"atl":[[60,0.18]],"id":48638605}],"con":true,"img":false}]}
{"op":"mcm","clk":"11450592224","pt":1717323622295,"mc":[{"id":"1.229554925","rc":[{"atl":[[60,0],[1000,1.85]],"id":48638605}],"con":true,"img":false}]}
{"op":"mcm","clk":"11450592304","pt":1717323623023,"mc":[{"id":"1.229554925","rc":[{"atl":[[1000,1.18]],"id":48638605}],"con":true,"img":false}]}
{"op":"mcm","clk":"11450592342","pt":1717323623335,"mc":[{"id":"1.229554925","rc":[{"atl":[[1000,1]],"id":48638605}],"con":true,"img":false}]}
{"op":"mcm","clk":"11450592350","pt":1717323623391,"mc":[{"id":"1.229554925","rc":[{"atl":[[46,0.18]],"id":48638605}],"con":true,"img":false}]}
{"op":"mcm","clk":"11450595218","pt":1717323651069,"mc":[{"id":"1.229554925","rc":[{"spl":[[1.01,1.56]],"id":64343695},{"spl":[[1.01,1.04]],"id":48638605},{"spl":[[1.01,1.56]],"id":40917581}],"con":true,"img":false}]}
{"op":"mcm","clk":"11450596404","pt":1717323663655,"mc":[{"id":"1.229554925","rc":[{"atb":[[19.5,2]],"id":64343695},{"atl":[[200,4.61]],"id":64343695},{"spn":19.5,"spf":1.0,"id":64343695},{"atb":[[9.6,2]],"id":48638605},{"atl":[[48,4.61]],"id":48638605},{"spn":9.6,"spf":1.0,"id":48638605},{"atb":[[50,2]],"id":40917581},{"atl":[[990,2.17]],"id":40917581},{"spn":50.0,"spf":1.0,"id":40917581}],"con":true,"img":false}]}
{"op":"mcm","clk":"11450596689","pt":1717323666470,"mc":[{"id":"1.229554925","rc":[{"atb":[[17.5,3.74]],"id":64343695},{"atb":[[9.4,0]],"id":48638605}],"con":true,"img":false}]}
{"op":"mcm","clk":"11450596856","pt":1717323667987,"mc":[{"id":"1.229554925","rc":[{"atb":[[9.8,2.55]],"id":48638605}],"con":true,"img":false}]}
{"op":"mcm","clk":"11450600145","pt":1717323702743,"mc":[{"id":"1.229554925","rc":[{"atb":[[48,0]],"id":40917581}],"con":true,"img":false}]}
{"op":"mcm","clk":"11450600161","pt":1717323702894,"mc":[{"id":"1.229554925","rc":[{"atb":[[55,2.61]],"id":40917581}],"con":true,"img":false}]}
{"op":"mcm","clk":"11450602095","pt":1717323723867,"mc":[{"id":"1.229554925","rc":[{"atb":[[2.94,5.37]],"id":47148562},{"spn":9.8,"spf":1.0,"id":48638605},{"atb":[[2.8,5.82]],"id":49546922},{"spn":55.0,"spf":1.0,"id":40917581}],"con":true,"img":false}]}
{"op":"mcm","clk":"11450602201","pt":1717323724856,"mc":[{"id":"1.229554925","rc":[{"atb":[[2.96,2.11]],"id":49546922}],"con":true,"img":false}]}
{"op":"mcm","clk":"11450603710","pt":1717323739166,"mc":[{"id":"1.229554925","rc":[{"atb":[[2.94,4.04]],"id":49546922}],"con":true,"img":false}]}
{"op":"mcm","clk":"11450607573","pt":1717323780753,"mc":[{"id":"1.229554925","rc":[{"atl":[[3.95,3.63]],"id":70003372}],"con":true,"img":false}]}
{"op":"mcm","clk":"11450614299","pt":1717323847685,"mc":[{"id":"1.229554925","rc":[{"atb":[[2.86,0],[3.15,0],[2.96,17.28]],"id":47148562},{"atl":[[16,0],[11,0]],"id":47148562},{"atb":[[12,0],[14.5,0],[17,0]],"id":64343695},{"atl":[[350,0],[250,0]],"id":64343695},{"atb":[[8,0],[9,0],[7,0]],"id":48638605},{"atl":[[210,0],[110,0]],"id":48638605},{"atb":[[2.72,0],[2.62,0],[2.52,0]],"id":49546922},{"atl":[[9,0],[12.5,0]],"id":49546922},{"atb":[[1.73,0],[1.83,0],[1.78,0]],"id":70003372},{"atl":[[4.5,0],[5.5,0]],"id":70003372},{"spn":1.74,"spf":1.0,"id":70003372},{"atb":[[32,0],[42,0],[26,0]],"id":40917581},{"atl":[[570,0],[470,0]],"id":40917581}],"con":true,"img":false}]}
{"op":"mcm","clk":"11450614314","pt":1717323847790,"mc":[{"id":"1.229554925","rc":[{"atl":[[990,0.17],[1000,3]],"id":40917581}],"con":true,"img":false}]}
{"op":"mcm","clk":"11450614327","pt":1717323847894,"mc":[{"id":"1.229554925","rc":[{"atb":[[2.94,0]],"id":47148562}],"con":true,"img":false}]}
{"op":"mcm","clk":"11450614462","pt":1717323849006,"mc":[{"id":"1.229554925","rc":[{"atb":[[2.94,5.37]],"id":47148562}],"con":true,"img":false}]}
{"op":"mcm","clk":"11450614538","pt":1717323849788,"mc":[{"id":"1.229554925","rc":[{"atb":[[1.64,13.08]],"id":70003372}],"con":true,"img":false}]}
{"op":"mcm","clk":"11450614873","pt":1717323852674,"mc":[{"id":"1.229554925","rc":[{"atb":[[3.2,5.16]],"id":47148562},{"atl":[[10.5,0],[13.5,17.2]],"id":47148562},{"atb":[[15,0]],"id":64343695},{"atb":[[9.2,6.84]],"id":48638605},{"atb":[[1.74,0]],"id":70003372},{"atl":[[5,27.79],[3.8,20.03]],"id":70003372}],"con":true,"img":false}]}
{"op":"mcm","clk":"11450614886","pt":1717323852781,"mc":[{"id":"1.229554925","rc":[{"atb":[[3.05,27.37]],"id":47148562},{"atb":[[12.5,8.22]],"id":64343695},{"atb":[[8.8,14.71]],"id":48638605},{"atb":[[1.67,61.85]],"id":70003372}],"con":true,"img":false}]}
{"op":"mcm","clk":"11450615027","pt":1717323853981,"mc":[{"id":"1.229554925","rc":[{"atb":[[3.25,2.11]],"id":47148562},{"atb":[[1.87,0],[1.71,2.11]],"id":70003372}],"con":true,"img":false}]}
{"op":"mcm","clk":"11450616149","pt":1717323863247,"mc":[{"id":"1.229554925","rc":[{"atb":[[2.86,112.29],[3.15,48.57],[2.96,123.85]],"id":47148562},{"atl":[[16,13.95],[11,13.95]],"id":47148562},{"atb":[[12,18.98],[14.5,15.47],[17,6.52]],"id":64343695},{"atl":[[350,0.6],[250,0.55]],"id":64343695},{"atb":[[8,29.83],[9,13.05],[7,34.81]],"id":48638605},{"atl":[[210,0.99],[110,1.28]],"id":48638605},{"atb":[[2.72,60.71],[2.62,128.93],[2.52,137.41]],"id":49546922},{"atl":[[9,17.44],[12.5,18.2]],"id":49546922},{"atb":[[1.73,286.13],[1.83,125.82],[1.78,267.78]],"id":70003372},{"atl":[[4.5,39.87],[5.5,46.52]],"id":70003372},{"atb":[[32,9.62],[42,3.63],[26,11.92]],"id":40917581},{"atl":[[570,0.13],[470,0.1]],"id":40917581}],"con":true,"img":false}]}
{"op":"mcm","clk":"11450617045","pt":1717323871127,"mc":[{"id":"1.229554925","rc":[{"atb":[[2.94,4.82]],"id":47148562}],"con":true,"img":false}]}
{"op":"mcm","clk":"11450619885","pt":1717323899564,"mc":[{"id":"1.229554925","rc":[{"atb":[[2.94,5.37]],"id":47148562},{"atb":[[1.64,0]],"id":70003372}],"con":true,"img":false}]}
{"op":"mcm","clk":"11450619971","pt":1717323900457,"mc":[{"id":"1.229554925","rc":[{"atb":[[2.94,0]],"id":47148562}],"con":true,"img":false}]}
{"op":"mcm","clk":"11450620207","pt":1717323902769,"mc":[{"id":"1.229554925","rc":[{"atb":[[3.05,0]],"id":47148562},{"atb":[[1.67,0]],"id":70003372}],"con":true,"img":false}]}
{"op":"mcm","clk":"11450620216","pt":1717323902872,"mc":[{"id":"1.229554925","rc":[{"atb":[[3.2,32.53]],"id":47148562},{"atb":[[1.74,61.85]],"id":70003372}],"con":true,"img":false}]}
{"op":"mcm","clk":"11450621155","pt":1717323912684,"mc":[{"id":"1.229554925","rc":[{"atl":[[10.5,12.11],[13.5,8]],"id":47148562},{"atb":[[12.5,0]],"id":64343695},{"atb":[[8.8,0]],"id":48638605},{"atl":[[5,0],[3.8,59.74]],"id":70003372},{"spn":1.83,"spf":1.0,"id":70003372}],"con":true,"img":false}]}
{"op":"mcm","clk":"11450621163","pt":1717323912788,"mc":[{"id":"1.229554925","rc":[{"atb":[[15,8.22]],"id":64343695},{"atb":[[9.2,21.56]],"id":48638605}],"con":true,"img":false}]}
{"op":"mcm","clk":"11450621410","pt":1717323914861,"mc":[{"id":"1.229554925","rc":[{"atb":[[1.64,16.71]],"id":70003372}],"con":true,"img":false}]}
{"op":"mcm","clk":"11450622899","pt":1717323930098,"mc":[{"id":"1.229554925","rc":[{"atb":[[19.5,0]],"id":64343695},{"atl":[[200,2.61]],"id":64343695},{"atb":[[9.6,0]],"id":48638605},{"atl":[[48,2.61]],"id":48638605},{"atb":[[50,0]],"id":40917581},{"atl":[[1000,1]],"id":40917581}],"con":true,"img":false}]}
{"op":"mcm","clk":"11450623073","pt":1717323931717,"mc":[{"id":"1.229554925","rc":[{"atb":[[18,2.13]],"id":64343695}],"con":true,"img":false}]}
{"op":"mcm","clk":"11450623949","pt":1717323940935,"mc":[{"id":"1.229554925","rc":[{"atb":[[2.8,0],[2.94,51.55]],"id":47148562},{"atl":[[12,9.09],[13.5,0]],"id":47148562},{"atb":[[19.5,2]],"id":64343695},{"atl":[[290,2],[340,0],[200,4.61]],"id":64343695},{"atb":[[3.35,0],[3.75,36.36],[9.6,2]],"id":48638605},{"atl":[[60,2]],"id":48638605},{"atl":[[3.45,35.09],[3.85,0]],"id":70003372},{"atb":[[50,2]],"id":40917581},{"atl":[[1000,3]],"id":40917581}],"con":true,"img":false}]}
{"op":"mcm","clk":"11450623959","pt":1717323940996,"mc":[{"id":"1.229554925","rc":[{"atl":[[65,2.61],[60,4]],"id":48638605}],"con":true,"img":false}]}
{"op":"mcm","clk":"11450624108","pt":1717323942667,"mc":[{"id":"1.229554925","rc":[{"atl":[[4.4,32.69]],"id":70003372}],"con":true,"img":false}]}
{"op":"mcm","clk":"11450624117","pt":1717323942724,"mc":[{"id":"1.229554925","rc":[{"atl":[[3.8,20.03]],"id":70003372}],"con":true,"img":false}]}
{"op":"mcm","clk":"11450624127","pt":1717323942831,"mc":[{"id":"1.229554925","rc":[{"atb":[[1.64,0]],"id":70003372}],"con":true,"img":false}]}
{"op":"mcm","clk":"11450624291","pt":1717323944123,"mc":[{"id":"1.229554925","rc":[{"atb":[[18,0]],"id":64343695}],"con":true,"img":false}]}
{"op":"mcm","clk":"11450624469","pt":1717323946030,"mc":[{"id":"1.229554925","rc":[{"atl":[[48,4.61],[60,2]],"id":48638605}],"con":true,"img":false}]}
{"op":"mcm","clk":"11450624480","pt":1717323946087,"mc":[{"id":"1.229554925","rc":[{"atl":[[48,2.61],[60,4]],"id":48638605}],"con":true,"img":false}]}
{"op":"mcm","clk":"11450624621","pt":1717323947795,"mc":[{"id":"1.229554925","rc":[{"atl":[[8.6,10.42],[48,0]],"id":49546922},{"atb":[[1.26,251.66],[1.17,0]],"id":70003372}],"con":true,"img":false}]}
{"op":"mcm","clk":"11450624897","pt":1717323951188,"mc":[{"id":"1.229554925","rc":[{"atb":[[3.1,47.62],[2.94,0]],"id":47148562},{"atl":[[48,4.61]],"id":48638605}],"con":true,"img":false}]}
{"op":"mcm","clk":"11450624904","pt":1717323951297,"mc":[{"id":"1.229554925","rc":[{"atl":[[60,2]],"id":48638605}],"con":true,"img":false}]}
{"op":"mcm","clk":"11450625154","pt":1717323954091,"mc":[{"id":"1.229554925","rc":[{"atb":[[2.94,5.37]],"id":47148562}],"con":true,"img":false}]}
{"op":"mcm","clk":"11450625758","pt":1717323961315,"mc":[{"id":"1.229554925","rc":[{"atb":[[2.94,0]],"id":47148562}],"con":true,"img":false}]}
{"op":"mcm","clk":"11450625777","pt":1717323961520,"mc":[{"id":"1.229554925","rc":[{"atl":[[3.95,0]],"id":70003372}],"con":true,"img":false}]}
{"op":"mcm","clk":"11450625791","pt":1717323961630,"mc":[{"id":"1.229554925","rc":[{"atl":[[3.95,3.63]],"id":70003372}],"con":true,"img":false}]}
{"op":"mcm","clk":"11450625890","pt":1717323962724,"mc":[{"id":"1.229554925","rc":[{"atl":[[3.8,0]],"id":70003372}],"con":true,"img":false}]}
{"op":"mcm","clk":"11450625898","pt":1717323962822,"mc":[{"id":"1.229554925","rc":[{"atl":[[3.7,20.03]],"id":70003372}],"con":true,"img":false}]}
{"op":"mcm","clk":"11450626340","pt":1717323968552,"mc":[{"id":"1.229554925","rc":[{"atb":[[1.4,1.7]],"id":40917581}],"con":true,"img":false}]}
{"op":"mcm","clk":"11450626364","pt":1717323968860,"mc":[{"id":"1.229554925","rc":[{"atb":[[1.03,1.7]],"id":47148562},{"atb":[[1.08,1.7]],"id":48638605}],"con":true,"img":false}]}
{"op":"mcm","clk":"11450626386","pt":1717323969124,"mc":[{"id":"1.229554925","rc":[{"atl":[[1000,2.7]],"id":47148562},{"atb":[[1.03,1.7]],"id":49546922}],"con":true,"img":false}]}
{"op":"mcm","clk":"11450626404","pt":1717323969336,"mc":[{"id":"1.229554925","rc":[{"atl":[[1000,2.7]],"id":49546922}],"con":true,"img":false}]}
{"op":"mcm","clk":"11450626417","pt":1717323969443,"mc":[{"id":"1.229554925","rc":[{"atb":[[1.16,1.7]],"id":64343695}],"con":true,"img":false}]}
{"op":"mcm","clk":"11450626448","pt":1717323969750,"mc":[{"id":"1.229554925","rc":[{"atb":[[1.4,0.01]],"id":40917581}],"con":true,"img":false}]}
{"op":"mcm","clk":"11450626477","pt":1717323970067,"mc":[{"id":"1.229554925","rc":[{"atl":[[1000,2.7]],"id":48638605}],"con":true,"img":false}]}
{"op":"mcm","clk":"11450626508","pt":1717323970331,"mc":[{"id":"1.229554925","rc":[{"atb":[[1.03,0.23]],"id":47148562},{"atl":[[1000,1.11]],"id":47148562}],"con":true,"img":false}]}
{"op":"mcm","clk":"11450626543","pt":1717323970640,"mc":[{"id":"1.229554925","rc":[{"atb":[[1.08,0.08]],"id":48638605},{"atb":[[1.03,0.26]],"id":49546922}],"con":true,"img":false}]}
{"op":"mcm","clk":"11450626587","pt":1717323970955,"mc":[{"id":"1.229554925","rc":[{"atb":[[1.16,0.04]],"id":64343695}],"con":true,"img":false}]}
{"op":"mcm","clk":"11450626608","pt":1717323971113,"mc":[{"id":"1.229554925","rc":[{"atb":[[1.4,0]],"id":40917581}],"con":true,"img":false}]}
{"op":"mcm","clk":"11450626622","pt":1717323971217,"mc":[{"id":"1.229554925","rc":[{"atb":[[60,0.01]],"id":40917581}],"con":true,"img":false}]}
{"op":"mcm","clk":"11450626657","pt":1717323971638,"mc":[{"id":"1.229554925","rc":[{"atb":[[2.86,0],[3.15,0],[2.96,17.28]],"id":47148562},{"atl":[[16,0],[11,0]],"id":47148562},{"atb":[[1.4,1.7]],"id":64343695},{"atb":[[8,0],[9,0],[7,0]],"id":48638605},{"atl":[[210,0],[110,0]],"id":48638605},{"atb":[[2.72,0],[2.62,0],[2.52,0]],"id":49546922},{"atl":[[9,0],[12.5,0]],"id":49546922},{"atb":[[1.73,0],[1.83,0],[1.78,0]],"id":70003372},{"atl":[[4.5,0],[5.5,0]],"id":70003372},{"atb":[[32,0],[42,0],[26,0]],"id":40917581},{"atl":[[570,0],[470,0]],"id":40917581}],"con":true,"img":false}]}
{"op":"mcm","clk":"11450626665","pt":1717323971740,"mc":[{"id":"1.229554925","rc":[{"atb":[[1.06,1.7]],"id":47148562}],"con":true,"img":false}]}
{"op":"mcm","clk":"11450626672","pt":1717323971848,"mc":[{"id":"1.229554925","rc":[{"atl":[[3.95,0]],"id":70003372}],"con":true,"img":false}]}
{"op":"mcm","clk":"11450626683","pt":1717323971952,"mc":[{"id":"1.229554925","rc":[{"atb":[[1.06,1.7]],"id":49546922}],"con":true,"img":false}]}
{"op":"mcm","clk":"11450626727","pt":1717323972324,"mc":[{"id":"1.229554925","rc":[{"atb":[[1.16,1.7]],"id":48638605}],"con":true,"img":false}]}
{"op":"mcm","clk":"11450626751","pt":1717323972645,"mc":[{"id":"1.229554925","rc":[{"atl":[[13.5,9.2]],"id":47148562}],"con":true,"img":false}]}
{"op":"mcm","clk":"11450626762","pt":1717323972748,"mc":[{"id":"1.229554925","rc":[{"atl":[[10.5,0]],"id":47148562},{"atb":[[9.2,6.84]],"id":48638605},{"atb":[[2.74,0]],"id":49546922},{"spn":5.9,"spf":"NaN","id":49546922},{"atl":[[4.4,0]],"id":70003372},{"spn":1.74,"spf":1.0,"id":70003372},{"spn":55.05,"spf":1.0,"id":40917581}],"con":true,"img":false}]}
{"op":"mcm","clk":"11450626772","pt":1717323972850,"mc":[{"id":"1.229554925","rc":[{"atb":[[8.8,14.71]],"id":48638605},{"atb":[[2.7,69.86]],"id":49546922},{"atl":[[5,32.69]],"id":70003372}],"con":true,"img":false}]}
{"op":"mcm","clk":"11450626792","pt":1717323972955,"mc":[{"id":"1.229554925","rc":[{"atl":[[1000,1.01]],"id":48638605}],"con":true,"img":false}]}
{"op":"mcm","clk":"11450626837","pt":1717323973483,"mc":[{"id":"1.229554925","rc":[{"atb":[[1.03,0]],"id":47148562},{"atb":[[1.4,0.01]],"id":64343695}],"con":true,"img":false}]}
{"op":"mcm","clk":"11450626842","pt":1717323973539,"mc":[{"id":"1.229554925","rc":[{"atb":[[3.55,0.23]],"id":47148562}],"con":true,"img":false}]}
{"op":"mcm","clk":"11450626852","pt":1717323973648,"mc":[{"id":"1.229554925","rc":[{"atb":[[1.85,2.61]],"id":70003372}],"con":true,"img":false}]}
{"op":"mcm","clk":"11450626863","pt":1717323973752,"mc":[{"id":"1.229554925","rc":[{"atb":[[1.06,0.12]],"id":49546922}],"con":true,"img":false}]}
{"op":"mcm","clk":"11450626873","pt":1717323973857,"mc":[{"id":"1.229554925","rc":[{"atb":[[1.06,0.11]],"id":47148562},{"atb":[[1.62,9.19]],"id":70003372}],"con":true,"img":false}]}
{"op":"mcm","clk":"11450626921","pt":1717323974229,"mc":[{"id":"1.229554925","rc":[{"atl":[[1000,1]],"id":47148562}],"con":true,"img":false}]}
{"op":"mcm","clk":"11450626930","pt":1717323974337,"mc":[{"id":"1.229554925","rc":[{"atl":[[7.8,0.11]],"id":47148562}],"con":true,"img":false}]}
{"op":"mcm","clk":"11450626939","pt":1717323974438,"mc":[{"id":"1.229554925","rc":[{"atb":[[1.16,0.04]],"id":48638605}],"con":true,"img":false}]}
{"op":"mcm","clk":"11450626962","pt":1717323974650,"mc":[{"id":"1.229554925","rc":[{"atb":[[1.03,0]],"id":49546922}],"con":true,"img":false}]}
{"op":"mcm","clk":"11450626970","pt":1717323974757,"mc":[{"id":"1.229554925","rc":[{"atb":[[3.25,0.26]],"id":49546922}],"con":true,"img":false}]}
{"op":"mcm","clk":"11450626993","pt":1717323975063,"mc":[{"id":"1.229554925","rc":[{"atb":[[1.08,0]],"id":48638605}],"con":true,"img":false}]}
{"op":"mcm","clk":"11450627002","pt":1717323975168,"mc":[{"id":"1.229554925","rc":[{"atb":[[10,0.08]],"id":48638605}],"con":true,"img":false}]}
{"op":"mcm","clk":"11450627024","pt":1717323975432,"mc":[{"id":"1.229554925","rc":[{"atb":[[3.4,32.54]],"id":47148562},{"atb":[[4.3,30.3],[3.75,0]],"id":48638605},{"atb":[[2.22,0],[2.36,11.64]],"id":49546922}],"con":true,"img":false}]}
{"op":"mcm","clk":"11450627039","pt":1717323975535,"mc":[{"id":"1.229554925","rc":[{"atb":[[3.1,0]],"id":47148562},{"atb":[[2.8,0]],"id":49546922}],"con":true,"img":false}]}
{"op":"mcm","clk":"11450627049","pt":1717323975637,"mc":[{"id":"1.229554925","rc":[{"atb":[[1.16,0]],"id":64343695},{"atb":[[2.8,5.82]],"id":49546922}],"con":true,"img":false}]}
{"op":"mcm","clk":"11450627059","pt":1717323975742,"mc":[{"id":"1.229554925","rc":[{"atb":[[20,0.04]],"id":64343695}],"con":true,"img":false}]}
{"op":"mcm","clk":"11450627112","pt":1717323976157,"mc":[{"id":"1.229554925","rc":[{"atb":[[1.4,0]],"id":64343695}],"con":true,"img":false}]}
{"op":"mcm","clk":"11450627125","pt":1717323976263,"mc":[{"id":"1.229554925","rc":[{"atb":[[20,0.05]],"id":64343695}],"con":true,"img":false}]}
{"op":"mcm","clk":"11450627150","pt":1717323976532,"mc":[{"id":"1.229554925","rc":[{"atl":[[1000,1]],"id":48638605},{"atb":[[1.06,0]],"id":49546922}],"con":true,"img":false}]}
{"op":"mcm","clk":"11450627161","pt":1717323976636,"mc":[{"id":"1.229554925","rc":[{"atl":[[46,0.2]],"id":48638605},{"atb":[[3.25,0.39]],"id":49546922}],"con":true,"img":false}]}
{"op":"mcm","clk":"11450627187","pt":1717323976946,"mc":[{"id":"1.229554925","rc":[{"atb":[[1.06,0]],"id":47148562}],"con":true,"img":false}]}
{"op":"mcm","clk":"11450627194","pt":1717323977042,"mc":[{"id":"1.229554925","rc":[{"atb":[[3.55,0.35]],"id":47148562}],"con":true,"img":false}]}
{"op":"mcm","clk":"11450627298","pt":1717323978139,"mc":[{"id":"1.229554925","rc":[{"atb":[[1.16,0]],"id":48638605}],"con":true,"img":false}]}
{"op":"mcm","clk":"11450627312","pt":1717323978296,"mc":[{"id":"1.229554925","rc":[{"atb":[[10,0.12]],"id":48638605}],"con":true,"img":false}]}
{"op":"mcm","clk":"11450627329","pt":1717323978456,"mc":[{"id":"1.229554925","rc":[{"atb":[[3.55,2.91]],"id":47148562}],"con":true,"img":false}]}
{"op":"mcm","clk":"11450627340","pt":1717323978562,"mc":[{"id":"1.229554925","rc":[{"atb":[[1.8,1.7]],"id":40917581}],"con":true,"img":false}]}
{"op":"mcm","clk":"11450627421","pt":1717323979397,"mc":[{"id":"1.229554925","rc":[{"atb":[[1.8,0]],"id":40917581}],"con":true,"img":false}]}
{"op":"mcm","clk":"11450627470","pt":1717323979871,"mc":[{"id":"1.229554925","rc":[{"atb":[[3.2,5.16]],"id":47148562},{"atb":[[1.74,0]],"id":70003372},{"atb":[[1.8,0]],"id":40917581}],"con":true,"img":false}]}
{"op":"mcm","clk":"11450627479","pt":1717323979974,"mc":[{"id":"1.229554925","rc":[{"atb":[[3.15,27.37]],"id":47148562},{"atb":[[1.67,61.85]],"id":70003372},{"atb":[[60,0.02]],"id":40917581}],"con":true,"img":false}]}
{"op":"mcm","clk":"11450627530","pt":1717323980646,"mc":[{"id":"1.229554925","rc":[{"atb":[[44,1.16]],"id":40917581}],"con":true,"img":false}]}
{"op":"mcm","clk":"11450627537","pt":1717323980753,"mc":[{"id":"1.229554925","rc":[{"atb":[[36,3.66]],"id":40917581}],"con":true,"img":false}]}
{"op":"mcm","clk":"11450627552","pt":1717323980962,"mc":[{"id":"1.229554925","rc":[{"atb":[[2.86,112.29],[3.15,75.94],[2.96,123.85]],"id":47148562},{"atl":[[16,13.95],[11,13.95]],"id":47148562},{"atb":[[8,29.83],[9,13.05],[7,34.81]],"id":48638605},{"atl":[[210,0.99],[110,1.28]],"id":48638605},{"atb":[[2.72,60.71],[2.62,128.93],[2.52,137.41]],"id":49546922},{"atl":[[9,17.44],[12.5,18.2]],"id":49546922},{"atb":[[1.79,132.2],[1.74,282.26],[1.69,302.71]],"id":70003372},{"atl":[[4.3,42.29],[5.3,48.68]],"id":70003372},{"atb":[[38,4.02],[24,12.96],[29,10.65]],"id":40917581},{"atl":[[550,0.13],[450,0.1]],"id":40917581}],"con":true,"img":false}]}
{"op":"mcm","clk":"11450627590","pt":1717323981384,"mc":[{"id":"1.229554925","rc":[{"atl":[[9.8,0]],"id":47148562},{"atb":[[36,0],[29,15.36]],"id":40917581},{"atl":[[990,0.22]],"id":40917581}],"con":true,"img":false}]}
{"op":"mcm","clk":"11450627602","pt":1717323981441,"mc":[{"id":"1.229554925","rc":[{"atl":[[10.5,6.37]],"id":47148562}],"con":true,"img":false}]}
{"op":"mcm","clk":"11450627665","pt":1717323982063,"mc":[{"id":"1.229554925","rc":[{"trd":[[450,0.1]],"ltp":450.0,"tv":0.1,"id":40917581},{"atl":[[450,0.05]],"id":40917581}],"con":true,"img":false}]}
{"op":"mcm","clk":"11450627725","pt":1717323982753,"mc":[{"id":"1.229554925","rc":[{"atb":[[8.8,0]],"id":48638605}],"con":true,"img":false}]}
{"op":"mcm","clk":"11450627736","pt":1717323982862,"mc":[{"id":"1.229554925","rc":[{"atb":[[8.2,14.71]],"id":48638605}],"con":true,"img":false}]}
{"op":"mcm","clk":"11450628104","pt":1717323987381,"mc":[{"id":"1.229554925","rc":[{"atb":[[1.02,2]],"id":47148562}],"con":true,"img":false}]}
{"op":"mcm","clk":"11450628168","pt":1717323987954,"mc":[{"id":"1.229554925","rc":[{"atb":[[1.02,10.87]],"id":49546922}],"con":true,"img":false}]}
{"op":"mcm","clk":"11450628223","pt":1717323988682,"mc":[{"id":"1.229554925","rc":[{"atb":[[1.02,10.87]],"id":70003372}],"con":true,"img":false}]}
{"op":"mcm","clk":"11450628267","pt":1717323989257,"mc":[{"id":"1.229554925","rc":[{"atb":[[55,0]],"id":40917581}],"con":true,"img":false}]}
{"op":"mcm","clk":"11450628278","pt":1717323989360,"mc":[{"id":"1.229554925","rc":[{"atb":[[44,3.16],[46,2.61],[50,0]],"id":40917581}],"con":true,"img":false}]}
{"op":"mcm","clk":"11450628287","pt":1717323989465,"mc":[{"id":"1.229554925","rc":[{"atb":[[1.02,2]],"id":48638605}],"con":true,"img":false}]}
{"op":"mcm","clk":"11450628444","pt":1717323991389,"mc":[{"id":"1.229554925","rc":[{"atb":[[29,10.65]],"id":40917581},{"atl":[[980,2.61]],"id":40917581}],"con":true,"img":false}]}
{"op":"mcm","clk":"11450628456","pt":1717323991492,"mc":[{"id":"1.229554925","rc":[{"atb":[[25,4.7]],"id":40917581},{"atl":[[970,2],[1000,1]],"id":40917581}],"con":true,"img":false}]}
{"op":"mcm","clk":"11450628707","pt":1717323993896,"mc":[{"id":"1.229554925","rc":[{"atb":[[1.02,0]],"id":47148562}],"con":true,"img":false}]}
{"op":"mcm","clk":"11450628720","pt":1717323994000,"mc":[{"id":"1.229554925","rc":[{"atb":[[3.6,2]],"id":47148562}],"con":true,"img":false}]}
{"op":"mcm","clk":"11450628743","pt":1717323994266,"mc":[{"id":"1.229554925","rc":[{"atb":[[1.02,8.87]],"id":49546922}],"con":true,"img":false}]}
{"op":"mcm","clk":"11450628754","pt":1717323994378,"mc":[{"id":"1.229554925","rc":[{"atb":[[3.25,2.39]],"id":49546922}],"con":true,"img":false}]}
{"op":"mcm","clk":"11450628797","pt":1717323994889,"mc":[{"id":"1.229554925","rc":[{"atb":[[1.02,0]],"id":48638605}],"con":true,"img":false}]}
{"op":"mcm","clk":"11450628805","pt":1717323994990,"mc":[{"id":"1.229554925","rc":[{"atb":[[10,2.12]],"id":48638605}],"con":true,"img":false}]}
{"op":"mcm","clk":"11450628815","pt":1717323995092,"mc":[{"id":"1.229554925","rc":[{"atb":[[10,4.12],[9.6,0]],"id":48638605}],"con":true,"img":false}]}
{"op":"mcm","clk":"11450628944","pt":1717323996607,"mc":[{"id":"1.229554925","rc":[{"atb":[[3.3,2.55]],"id":49546922}],"con":true,"img":false}]}
{"op":"mcm","clk":"11450628957","pt":1717323996661,"mc":[{"id":"1.229554925","rc":[{"atb":[[3.55,0.35]],"id":47148562},{"atb":[[9.8,0]],"id":48638605}],"con":true,"img":false}]}
{"op":"mcm","clk":"11450629057","pt":1717323997887,"mc":[{"id":"1.229554925","rc":[{"atb":[[3.6,0]],"id":47148562}],"con":true,"img":false}]}
{"op":"mcm","clk":"11450629068","pt":1717323997991,"mc":[{"id":"1.229554925","rc":[{"atb":[[3.55,2.35]],"id":47148562}],"con":true,"img":false}]}
{"op":"mcm","clk":"11450629095","pt":1717323998301,"mc":[{"id":"1.229554925","rc":[{"atb":[[3.25,0.39]],"id":49546922},{"atb":[[46,0]],"id":40917581}],"con":true,"img":false}]}
{"op":"mcm","clk":"11450629108","pt":1717323998357,"mc":[{"id":"1.229554925","rc":[{"atb":[[3.35,2]],"id":49546922},{"atb":[[30,2.61]],"id":40917581}],"con":true,"img":false}]}
{"op":"mcm","clk":"11450629216","pt":1717323999707,"mc":[{"id":"1.229554925","rc":[{"atb":[[3.6,2.55],[2.86,0],[3.15,27.37],[2.96,17.28]],"id":47148562},{"atl":[[16,0],[11,0]],"id":47148562},{"atb":[[12,0],[14.5,0],[17,0]],"id":64343695},{"atl":[[350,0],[250,0]],"id":64343695},{"atb":[[8,0],[9,0],[7,0]],"id":48638605},{"atl":[[210,0],[110,0]],"id":48638605},{"atb":[[2.72,0],[2.62,0],[2.52,0]],"id":49546922},{"atl":[[9,0],[12.5,0]],"id":49546922},{"atb":[[1.79,0],[1.74,0],[1.69,0]],"id":70003372},{"atl":[[4.3,0],[5.3,0]],"id":70003372},{"atb":[[38,0],[24,0],[29,0]],"id":40917581},{"atl":[[550,0],[450,0]],"id":40917581}],"con":true,"img":false}]}
{"op":"mcm","clk":"11450629226","pt":1717323999813,"mc":[{"id":"1.229554925","rc":[{"atl":[[970,0],[980,4.61]],"id":40917581}],"con":true,"img":false}]}
{"op":"mcm","clk":"11450629233","pt":1717323999870,"mc":[{"id":"1.229554925","rc":[{"atl":[[980,2.61],[990,2.22]],"id":40917581}],"con":true,"img":false}]}
{"op":"mcm","clk":"11450629288","pt":1717324000497,"mc":[{"id":"1.229554925","rc":[{"atb":[[3,5.37]],"id":47148562}],"con":true,"img":false}]}
{"op":"mcm","clk":"11450629367","pt":1717324001179,"mc":[{"id":"1.229554925","rc":[{"atb":[[3.3,0]],"id":49546922}],"con":true,"img":false}]}
{"op":"mcm","clk":"11450629477","pt":1717324002275,"mc":[{"id":"1.229554925","rc":[{"atb":[[3.2,0]],"id":47148562},{"atb":[[2.78,0]],"id":49546922},{"atb":[[1.54,21]],"id":70003372}],"con":true,"img":false}]}
{"op":"mcm","clk":"11450629527","pt":1717324002692,"mc":[{"id":"1.229554925","rc":[{"atb":[[15,0]],"id":64343695},{"atb":[[21,6.8],[25,0]],"id":40917581},{"atl":[[990,2.17]],"id":40917581}],"con":true,"img":false}]}
{"op":"mcm","clk":"11450629537","pt":1717324002794,"mc":[{"id":"1.229554925","rc":[{"atb":[[12.5,8.22]],"id":64343695},{"atl":[[770,0.05]],"id":40917581}],"con":true,"img":false}]}
{"op":"mcm","clk":"11450629623","pt":1717324003676,"mc":[{"id":"1.229554925","rc":[{"atb":[[3.55,0.35]],"id":47148562}],"con":true,"img":false}]}
{"op":"mcm","clk":"11450629633","pt":1717324003777,"mc":[{"id":"1.229554925","rc":[{"atb":[[3.65,2]],"id":47148562}],"con":true,"img":false}]}
{"op":"mcm","clk":"11450629673","pt":1717324004300,"mc":[{"id":"1.229554925","rc":[{"atb":[[3.4,2.55]],"id":49546922}],"con":true,"img":false}]}
{"op":"mcm","clk":"11450629699","pt":1717324004512,"mc":[{"id":"1.229554925","rc":[{"atb":[[3.35,0]],"id":49546922}],"con":true,"img":false}]}
{"op":"mcm","clk":"11450629709","pt":1717324004608,"mc":[{"id":"1.229554925","rc":[{"atb":[[3.25,2.39]],"id":49546922}],"con":true,"img":false}]}
{"op":"mcm","clk":"11450629720","pt":1717324004712,"mc":[{"id":"1.229554925","rc":[{"atb":[[2.86,112.28],[3.15,75.94],[2.96,123.84]],"id":47148562},{"atl":[[16,13.95],[11,13.95]],"id":47148562},{"atb":[[12,18.98],[14.5,15.47],[17,6.52]],"id":64343695},{"atl":[[350,0.6],[250,0.55]],"id":64343695},{"atb":[[8,29.83],[9,13.05],[7,34.8]],"id":48638605},{"atl":[[210,0.99],[110,1.28]],"id":48638605},{"atb":[[2.58,132.18],[2.78,58.66],[2.68,143.4]],"id":49546922},{"atl":[[13.5,16.75],[9.4,16.61]],"id":49546922},{"atb":[[1.79,132.18],[1.74,282.23],[1.69,302.68]],"id":70003372},{"atl":[[4.3,42.29],[5.3,48.69]],"id":70003372},{"atb":[[38,4.15],[24,13.37],[29,10.98]],"id":40917581},{"atl":[[550,0.1],[450,0.08]],"id":40917581}],"con":true,"img":false}]}
{"op":"mcm","clk":"11450629753","pt":1717324004977,"mc":[{"id":"1.229554925","rc":[{"atl":[[770,2.05],[990,0.17]],"id":40917581}],"con":true,"img":false}]}
{"op":"mcm","clk":"11450629763","pt":1717324005080,"mc":[{"id":"1.229554925","rc":[{"atl":[[770,0.05],[970,2]],"id":40917581}],"con":true,"img":false}]}
{"op":"mcm","clk":"11450629774","pt":1717324005192,"mc":[{"id":"1.229554925","rc":[{"atl":[[770,2.05],[970,0]],"id":40917581}],"con":true,"img":false}]}
{"op":"mcm","clk":"11450629787","pt":1717324005292,"mc":[{"id":"1.229554925","rc":[{"atl":[[770,0.05],[970,2]],"id":40917581}],"con":true,"img":false}]}
{"op":"mcm","clk":"11450629796","pt":1717324005400,"mc":[{"id":"1.229554925","rc":[{"atl":[[770,2.05],[970,0]],"id":40917581}],"con":true,"img":false}]}
{"op":"mcm","clk":"11450629810","pt":1717324005501,"mc":[{"id":"1.229554925","rc":[{"atl":[[970,2]],"id":40917581}],"con":true,"img":false}]}
{"op":"mcm","clk":"11450629821","pt":1717324005603,"mc":[{"id":"1.229554925","rc":[{"atl":[[770,0.05],[970,0]],"id":40917581}],"con":true,"img":false}]}
{"op":"mcm","clk":"11450629830","pt":1717324005707,"mc":[{"id":"1.229554925","rc":[{"atl":[[970,2]],"id":40917581}],"con":true,"img":false}]}
{"op":"mcm","clk":"11450629869","pt":1717324006181,"mc":[{"id":"1.229554925","rc":[{"atb":[[3.6,0]],"id":47148562}],"con":true,"img":false}]}
{"op":"mcm","clk":"11450629971","pt":1717324007582,"mc":[{"id":"1.229554925","rc":[{"atl":[[3.9,3.63]],"id":70003372}],"con":true,"img":false}]}
{"op":"mcm","clk":"11450629989","pt":1717324007792,"mc":[{"id":"1.229554925","rc":[{"atb":[[3.65,0]],"id":47148562}],"con":true,"img":false}]}
{"op":"mcm","clk":"11450630001","pt":1717324007901,"mc":[{"id":"1.229554925","rc":[{"atb":[[3.55,2.35]],"id":47148562}],"con":true,"img":false}]}
{"op":"mcm","clk":"11450630043","pt":1717324008216,"mc":[{"id":"1.229554925","rc":[{"atb":[[3.25,0.39]],"id":49546922}],"con":true,"img":false}]}
{"op":"mcm","clk":"11450630053","pt":1717324008310,"mc":[{"id":"1.229554925","rc":[{"atb":[[3.45,2]],"id":49546922}],"con":true,"img":false}]}
{"op":"mcm","clk":"11450630118","pt":1717324008989,"mc":[{"id":"1.229554925","rc":[{"atb":[[3.7,2.55]],"id":47148562}],"con":true,"img":false}]}
{"op":"mcm","clk":"11450630182","pt":1717324009818,"mc":[{"id":"1.229554925","rc":[{"atl":[[8.4,3.04]],"id":49546922},{"atl":[[960,0.02]],"id":40917581}],"con":true,"img":false}]}
{"op":"mcm","clk":"11450630199","pt":1717324009979,"mc":[{"id":"1.229554925","rc":[{"atb":[[3,0]],"id":47148562}],"con":true,"img":false}]}
{"op":"mcm","clk":"11450630238","pt":1717324010503,"mc":[{"id":"1.229554925","rc":[{"atb":[[3.4,0]],"id":49546922}],"con":true,"img":false}]}
{"op":"mcm","clk":"11450630265","pt":1717324010817,"mc":[{"id":"1.229554925","rc":[{"atb":[[3.55,0.35]],"id":47148562},{"atl":[[770,2.05]],"id":40917581}],"con":true,"img":false}]}
{"op":"mcm","clk":"11450630276","pt":1717324010926,"mc":[{"id":"1.229554925","rc":[{"atb":[[3.75,2]],"id":47148562},{"atl":[[960,2.02],[970,0]],"id":40917581}],"con":true,"img":false}]}
{"op":"mcm","clk":"11450630284","pt":1717324011029,"mc":[{"id":"1.229554925","rc":[{"atl":[[770,0.05]],"id":40917581}],"con":true,"img":false}]}
{"op":"mcm","clk":"11450630293","pt":1717324011087,"mc":[{"id":"1.229554925","rc":[{"atl":[[960,2]],"id":40917581}],"con":true,"img":false}]}
{"op":"mcm","clk":"11450630301","pt":1717324011186,"mc":[{"id":"1.229554925","rc":[{"atl":[[770,2.05],[960,0]],"id":40917581}],"con":true,"img":false}]}
{"op":"mcm","clk":"11450630429","pt":1717324012696,"mc":[{"id":"1.229554925","rc":[{"atb":[[3.15,48.57]],"id":47148562},{"atb":[[17.5,0]],"id":64343695}],"con":true,"img":false}]}
{"op":"mcm","clk":"11450630438","pt":1717324012801,"mc":[{"id":"1.229554925","rc":[{"atb":[[3.45,27.37]],"id":47148562},{"atb":[[16.5,3.74]],"id":64343695}],"con":true,"img":false}]}
{"op":"mcm","clk":"11450630503","pt":1717324013628,"mc":[{"id":"1.229554925","rc":[{"atl":[[770,2]],"id":40917581}],"con":true,"img":false}]}
{"op":"mcm","clk":"11450630513","pt":1717324013690,"mc":[{"id":"1.229554925","rc":[{"atb":[[3.7,0]],"id":47148562},{"atl":[[920,0.05]],"id":40917581}],"con":true,"img":false}]}
{"op":"mcm","clk":"11450630555","pt":1717324014210,"mc":[{"id":"1.229554925","rc":[{"atb":[[3.45,0]],"id":49546922}],"con":true,"img":false}]}
{"op":"mcm","clk":"11450630561","pt":1717324014315,"mc":[{"id":"1.229554925","rc":[{"atb":[[3.25,2.39]],"id":49546922}],"con":true,"img":false}]}
{"op":"mcm","clk":"11450630725","pt":1717324016339,"mc":[{"id":"1.229554925","rc":[{"atl":[[770,0],[920,2.05]],"id":40917581}],"con":true,"img":false}]}
{"op":"mcm","clk":"11450630730","pt":1717324016395,"mc":[{"id":"1.229554925","rc":[{"atl":[[920,0.05],[970,2]],"id":40917581}],"con":true,"img":false}]}
{"op":"mcm","clk":"11450630739","pt":1717324016502,"mc":[{"id":"1.229554925","rc":[{"atb":[[3.3,2.55]],"id":49546922},{"atl":[[920,2.05],[970,0]],"id":40917581}],"con":true,"img":false}]}
{"op":"mcm","clk":"11450630745","pt":1717324016608,"mc":[{"id":"1.229554925","rc":[{"atl":[[970,2]],"id":40917581}],"con":true,"img":false}]}
{"op":"mcm","clk":"11450630750","pt":1717324016707,"mc":[{"id":"1.229554925","rc":[{"atl":[[920,0.05]],"id":40917581}],"con":true,"img":false}]}
{"op":"mcm","clk":"11450630761","pt":1717324016816,"mc":[{"id":"1.229554925","rc":[{"atl":[[920,2.05],[970,0]],"id":40917581}],"con":true,"img":false}]}
{"op":"mcm","clk":"11450630785","pt":1717324017120,"mc":[{"id":"1.229554925","rc":[{"atb":[[3.75,0]],"id":47148562}],"con":true,"img":false}]}
{"op":"mcm","clk":"11450630795","pt":1717324017224,"mc":[{"id":"1.229554925","rc":[{"atb":[[3.55,2.35]],"id":47148562}],"con":true,"img":false}]}
{"op":"mcm","clk":"11450630888","pt":1717324018123,"mc":[{"id":"1.229554925","rc":[{"atb":[[1.62,13.08]],"id":70003372}],"con":true,"img":false}]}
{"op":"mcm","clk":"11450630928","pt":1717324018637,"mc":[{"id":"1.229554925","rc":[{"atb":[[1.54,0]],"id":70003372}],"con":true,"img":false}]}
{"op":"mcm","clk":"11450630946","pt":1717324018807,"mc":[{"id":"1.229554925","rc":[{"atb":[[3.2,5.16]],"id":47148562}],"con":true,"img":false}]}
{"op":"mcm","clk":"11450630955","pt":1717324018908,"mc":[{"id":"1.229554925","rc":[{"atb":[[2.82,6.22]],"id":49546922}],"con":true,"img":false}]}
{"op":"mcm","clk":"11450630994","pt":1717324019426,"mc":[{"id":"1.229554925","rc":[{"atb":[[3.6,2.55]],"id":47148562}],"con":true,"img":false}]}
{"op":"mcm","clk":"11450631052","pt":1717324020220,"mc":[{"id":"1.229554925","rc":[{"atb":[[3.55,0.35]],"id":47148562}],"con":true,"img":false}]}
{"op":"mcm","clk":"11450631061","pt":1717324020314,"mc":[{"id":"1.229554925","rc":[{"atb":[[3.65,2]],"id":47148562}],"con":true,"img":false}]}
{"op":"mcm","clk":"11450631100","pt":1717324020734,"mc":[{"id":"1.229554925","rc":[{"atb":[[3.25,0.39]],"id":49546922}],"con":true,"img":false}]}
{"op":"mcm","clk":"11450631109","pt":1717324020850,"mc":[{"id":"1.229554925","rc":[{"atb":[[3.35,2]],"id":49546922}],"con":true,"img":false}]}
{"op":"mcm","clk":"11450631162","pt":1717324021331,"mc":[{"id":"1.229554925","rc":[{"atb":[[3.5,0]],"id":47148562}],"con":true,"img":false}]}
{"op":"mcm","clk":"11450631168","pt":1717324021421,"mc":[{"id":"1.229554925","rc":[{"atb":[[3.7,2.61]],"id":47148562}],"con":true,"img":false}]}
{"op":"mcm","clk":"11450631248","pt":1717324022419,"mc":[{"id":"1.229554925","rc":[{"atb":[[3.6,0]],"id":47148562},{"atb":[[3.3,0]],"id":49546922}],"con":true,"img":false}]}
{"op":"mcm","clk":"11450631545","pt":1717324025347,"mc":[{"id":"1.229554925","rc":[{"atb":[[3.75,2.55],[3.65,0]],"id":47148562},{"atb":[[3.4,2.55]],"id":49546922}],"con":true,"img":false}]}
{"op":"mcm","clk":"11450631553","pt":1717324025402,"mc":[{"id":"1.229554925","rc":[{"atb":[[3.75,4.55]],"id":47148562}],"con":true,"img":false}]}
{"op":"mcm","clk":"11450631585","pt":1717324025819,"mc":[{"id":"1.229554925","rc":[{"atb":[[3.35,0]],"id":49546922}],"con":true,"img":false}]}
{"op":"mcm","clk":"11450631598","pt":1717324025921,"mc":[{"id":"1.229554925","rc":[{"atb":[[3.25,2.39]],"id":49546922}],"con":true,"img":false}]}
{"op":"mcm","clk":"11450631990","pt":1717324030324,"mc":[{"id":"1.229554925","rc":[{"atb":[[3.25,0.39]],"id":49546922}],"con":true,"img":false}]}
{"op":"mcm","clk":"11450632001","pt":1717324030426,"mc":[{"id":"1.229554925","rc":[{"atb":[[3.45,2]],"id":49546922}],"con":true,"img":false}]}
{"op":"mcm","clk":"11450632190","pt":1717324033134,"mc":[{"id":"1.229554925","rc":[{"spn":5.77,"spf":"NaN","id":47148562},{"spn":19.51,"spf":1.0,"id":64343695},{"spn":10.0,"spf":1.0,"id":48638605},{"atb":[[3.4,0]],"id":49546922},{"spn":5.92,"spf":"NaN","id":49546922},{"spn":1.79,"spf":1.0,"id":70003372},{"spn":44.26,"spf":1.0,"id":40917581}],"con":true,"img":false}]}
{"op":"mcm","clk":"11450632488","pt":1717324036945,"mc":[{"id":"1.229554925","rc":[{"atb":[[3.45,0]],"id":49546922}],"con":true,"img":false}]}
{"op":"mcm","clk":"11450632493","pt":1717324037046,"mc":[{"id":"1.229554925","rc":[{"atb":[[3.25,2.39]],"id":49546922}],"con":true,"img":false}]}
{"op":"mcm","clk":"11450632682","pt":1717324039242,"mc":[{"id":"1.229554925","rc":[{"atb":[[3.3,2.55]],"id":49546922}],"con":true,"img":false}]}
{"op":"mcm","clk":"11450632829","pt":1717324040953,"mc":[{"id":"1.229554925","rc":[{"atb":[[3.25,0.39]],"id":49546922}],"con":true,"img":false}]}
{"op":"mcm","clk":"11450632837","pt":1717324041056,"mc":[{"id":"1.229554925","rc":[{"atb":[[3.35,2]],"id":49546922}],"con":true,"img":false}]}
{"op":"mcm","clk":"11450632970","pt":1717324042768,"mc":[{"id":"1.229554925","rc":[{"atl":[[10.5,0]],"id":47148562},{"atb":[[16.5,0]],"id":64343695},{"atl":[[65,0],[48,2]],"id":48638605},{"atl":[[8.8,0]],"id":49546922},{"atb":[[1.67,0]],"id":70003372},{"atl":[[3.7,0]],"id":70003372},{"atb":[[30,0]],"id":40917581},{"atl":[[920,2]],"id":40917581}],"con":true,"img":false}]}
{"op":"mcm","clk":"11450632977","pt":1717324042829,"mc":[{"id":"1.229554925","rc":[{"atl":[[10,6.37]],"id":47148562},{"atb":[[17.5,3.74]],"id":64343695},{"atl":[[46,2.82],[48,0],[110,3.28],[55,2.61]],"id":48638605},{"atl":[[8.4,10.23]],"id":49546922},{"atb":[[1.62,0],[1.75,61.85]],"id":70003372},{"atl":[[3.65,20.03]],"id":70003372},{"atb":[[46,2.61]],"id":40917581},{"atl":[[870,0.05],[920,0],[970,2]],"id":40917581}],"con":true,"img":false}]}
{"op":"mcm","clk":"11450633062","pt":1717324043759,"mc":[{"id":"1.229554925","rc":[{"atb":[[3.3,0]],"id":49546922},{"atb":[[48,0.52]],"id":40917581},{"atl":[[960,0.02]],"id":40917581}],"con":true,"img":false}]}
{"op":"mcm","clk":"11450633089","pt":1717324043971,"mc":[{"id":"1.229554925","rc":[{"atb":[[1.83,2.11],[1.71,0]],"id":70003372},{"atb":[[44,1.16],[48,2.52]],"id":40917581}],"con":true,"img":false}]}
{"op":"mcm","clk":"11450633109","pt":1717324044135,"mc":[{"id":"1.229554925","rc":[{"atb":[[48,0.52]],"id":40917581}],"con":true,"img":false}]}
{"op":"mcm","clk":"11450633121","pt":1717324044233,"mc":[{"id":"1.229554925","rc":[{"atb":[[48,2.52]],"id":40917581}],"con":true,"img":false}]}
{"op":"mcm","clk":"11450633134","pt":1717324044448,"mc":[{"id":"1.229554925","rc":[{"atb":[[3.2,10.53]],"id":47148562}],"con":true,"img":false}]}
{"op":"mcm","clk":"11450633165","pt":1717324044778,"mc":[{"id":"1.229554925","rc":[{"atb":[[3.35,0]],"id":49546922}],"con":true,"img":false}]}
{"op":"mcm","clk":"11450633178","pt":1717324044838,"mc":[{"id":"1.229554925","rc":[{"atb":[[3.25,2.39]],"id":49546922}],"con":true,"img":false}]}
{"op":"mcm","clk":"11450633338","pt":1717324046746,"mc":[{"id":"1.229554925","rc":[{"atb":[[3.3,2.55]],"id":49546922}],"con":true,"img":false}]}
{"op":"mcm","clk":"11450633449","pt":1717324047945,"mc":[{"id":"1.229554925","rc":[{"atb":[[3.2,5.16]],"id":47148562},{"atl":[[46,4.82],[110,1.28]],"id":48638605},{"atb":[[3.25,0.39]],"id":49546922},{"atl":[[870,2.05],[970,0]],"id":40917581}],"con":true,"img":false}]}
{"op":"mcm","clk":"11450633463","pt":1717324048071,"mc":[{"id":"1.229554925","rc":[{"atl":[[46,2.82],[55,4.61]],"id":48638605},{"atb":[[3.35,2]],"id":49546922},{"atl":[[870,0.05],[960,2.02]],"id":40917581}],"con":true,"img":false}]}
{"op":"mcm","clk":"11450633468","pt":1717324048177,"mc":[{"id":"1.229554925","rc":[{"atl":[[46,4.82]],"id":48638605},{"atl":[[870,2.05],[960,0.02]],"id":40917581}],"con":true,"img":false}]}
{"op":"mcm","clk":"11450633475","pt":1717324048255,"mc":[{"id":"1.229554925","rc":[{"atl":[[55,2.61]],"id":48638605}],"con":true,"img":false}]}
{"op":"mcm","clk":"11450633537","pt":1717324048834,"mc":[{"id":"1.229554925","rc":[{"atl":[[960,0]],"id":40917581}],"con":true,"img":false}]}
{"op":"mcm","clk":"11450633625","pt":1717324049973,"mc":[{"id":"1.229554925","rc":[{"atb":[[3.3,0]],"id":49546922}],"con":true,"img":false}]}
{"op":"mcm","clk":"11450633697","pt":1717324050862,"mc":[{"id":"1.229554925","rc":[{"atb":[[3.35,0]],"id":49546922}],"con":true,"img":false}]}
{"op":"mcm","clk":"11450633715","pt":1717324050971,"mc":[{"id":"1.229554925","rc":[{"atb":[[3.25,2.39]],"id":49546922}],"con":true,"img":false}]}
{"op":"mcm","clk":"11450633867","pt":1717324052633,"mc":[{"id":"1.229554925","rc":[{"atl":[[10.5,12.11]],"id":47148562},{"atl":[[9.2,13.97]],"id":49546922},{"atb":[[40,3.13]],"id":40917581}],"con":true,"img":false}]}
{"op":"mcm","clk":"11450633876","pt":1717324052738,"mc":[{"id":"1.229554925","rc":[{"atl":[[13.5,0]],"id":47148562},{"atb":[[12.5,0]],"id":64343695},{"atb":[[2.7,0]],"id":49546922},{"atl":[[12,0]],"id":49546922},{"atl":[[5,0]],"id":70003372},{"atb":[[21,0]],"id":40917581}],"con":true,"img":false}]}
{"op":"mcm","clk":"11450633885","pt":1717324052838,"mc":[{"id":"1.229554925","rc":[{"atb":[[15,8.22]],"id":64343695},{"atb":[[2.8,75.68]],"id":49546922},{"atl":[[4.2,32.69]],"id":70003372}],"con":true,"img":false}]}
{"op":"mcm","clk":"11450633896","pt":1717324052944,"mc":[{"id":"1.229554925","rc":[{"atb":[[3.3,2.55]],"id":49546922}],"con":true,"img":false}]}
{"op":"mcm","clk":"11450633963","pt":1717324053769,"mc":[{"id":"1.229554925","rc":[{"atb":[[3.25,0.39]],"id":49546922}],"con":true,"img":false}]}
{"op":"mcm","clk":"11450633972","pt":1717324053875,"mc":[{"id":"1.229554925","rc":[{"atb":[[3.35,2]],"id":49546922}],"con":true,"img":false}]}
{"op":"mcm","clk":"11450634161","pt":1717324056107,"mc":[{"id":"1.229554925","rc":[{"atb":[[3.3,0]],"id":49546922}],"con":true,"img":false}]}
{"op":"mcm","clk":"11450634233","pt":1717324056936,"mc":[{"id":"1.229554925","rc":[{"atb":[[3.35,0]],"id":49546922}],"con":true,"img":false}]}
{"op":"mcm","clk":"11450634243","pt":1717324056995,"mc":[{"id":"1.229554925","rc":[{"atb":[[3.25,2.39]],"id":49546922}],"con":true,"img":false}]}
{"op":"mcm","clk":"11450634409","pt":1717324059014,"mc":[{"id":"1.229554925","rc":[{"atb":[[3.3,2.55]],"id":49546922}],"con":true,"img":false}]}
{"op":"mcm","clk":"11450634679","pt":1717324062339,"mc":[{"id":"1.229554925","rc":[{"atb":[[3.25,0.39]],"id":49546922}],"con":true,"img":false}]}
{"op":"mcm","clk":"11450634686","pt":1717324062438,"mc":[{"id":"1.229554925","rc":[{"atb":[[3.35,2]],"id":49546922}],"con":true,"img":false}]}
{"op":"mcm","clk":"11450634708","pt":1717324062707,"mc":[{"id":"1.229554925","rc":[{"atl":[[870,2]],"id":40917581}],"con":true,"img":false}]}
{"op":"mcm","clk":"11450634723","pt":1717324062811,"mc":[{"id":"1.229554925","rc":[{"atl":[[860,0.05],[970,2]],"id":40917581}],"con":true,"img":false}]}
{"op":"mcm","clk":"11450634733","pt":1717324062914,"mc":[{"id":"1.229554925","rc":[{"atl":[[870,0]],"id":40917581}],"con":true,"img":false}]}
{"op":"mcm","clk":"11450634766","pt":1717324063329,"mc":[{"id":"1.229554925","rc":[{"atl":[[960,0.02]],"id":40917581}],"con":true,"img":false}]}
{"op":"mcm","clk":"11450634913","pt":1717324065042,"mc":[{"id":"1.229554925","rc":[{"atb":[[3.3,0]],"id":49546922}],"con":true,"img":false}]}
{"op":"mcm","clk":"11450635016","pt":1717324066049,"mc":[{"id":"1.229554925","rc":[{"atb":[[3.35,0]],"id":49546922}],"con":true,"img":false}]}
{"op":"mcm","clk":"11450635027","pt":1717324066154,"mc":[{"id":"1.229554925","rc":[{"atb":[[3.25,2.39]],"id":49546922}],"con":true,"img":false}]}
{"op":"mcm","clk":"11450635078","pt":1717324066622,"mc":[{"id":"1.229554925","rc":[{"atb":[[3.2,50.61],[3.4,0]],"id":47148562},{"atb":[[4.3,0],[3.75,36.36]],"id":48638605},{"atl":[[70,2],[60,0]],"id":48638605},{"atb":[[2.8,69.86]],"id":49546922}],"con":true,"img":false}]}
{"op":"mcm","clk":"11450635089","pt":1717324066729,"mc":[{"id":"1.229554925","rc":[{"atb":[[2.8,75.68]],"id":49546922}],"con":true,"img":false}]}
{"op":"mcm","clk":"11450635205","pt":1717324067935,"mc":[{"id":"1.229554925","rc":[{"atl":[[860,2.05],[970,0]],"id":40917581}],"con":true,"img":false}]}
{"op":"mcm","clk":"11450635215","pt":1717324068037,"mc":[{"id":"1.229554925","rc":[{"atb":[[3.3,2.55]],"id":49546922}],"con":true,"img":false}]}
{"op":"mcm","clk":"11450635224","pt":1717324068144,"mc":[{"id":"1.229554925","rc":[{"atl":[[860,0.05]],"id":40917581}],"con":true,"img":false}]}
{"op":"mcm","clk":"11450635237","pt":1717324068251,"mc":[{"id":"1.229554925","rc":[{"atl":[[960,2.02]],"id":40917581}],"con":true,"img":false}]}
{"op":"mcm","clk":"11450635552","pt":1717324071625,"mc":[{"id":"1.229554925","rc":[{"atb":[[3.25,0.39]],"id":49546922}],"con":true,"img":false}]}
{"op":"mcm","clk":"11450635559","pt":1717324071733,"mc":[{"id":"1.229554925","rc":[{"atb":[[3.35,2]],"id":49546922}],"con":true,"img":false}]}
{"op":"mcm","clk":"11450635648","pt":1717324072764,"mc":[{"id":"1.229554925","rc":[{"atb":[[3.45,0]],"id":47148562},{"atl":[[46,2.2],[55,0]],"id":48638605}],"con":true,"img":false}]}
{"op":"mcm","clk":"11450635659","pt":1717324072862,"mc":[{"id":"1.229554925","rc":[{"atb":[[3.25,29.48]],"id":47148562},{"atl":[[65,2.61],[70,0],[44,2.61],[46,0.2],[100,2],[110,3.28]],"id":48638605}],"con":true,"img":false}]}
{"op":"mcm","clk":"11450635700","pt":1717324073335,"mc":[{"id":"1.229554925","rc":[{"atl":[[860,2.05]],"id":40917581}],"con":true,"img":false}]}
{"op":"mcm","clk":"11450635710","pt":1717324073439,"mc":[{"id":"1.229554925","rc":[{"atb":[[3.2,45.45]],"id":47148562},{"atb":[[2.82,0]],"id":49546922},{"atl":[[960,0.02]],"id":40917581}],"con":true,"img":false}]}
{"op":"mcm","clk":"11450635731","pt":1717324073741,"mc":[{"id":"1.229554925","rc":[{"atl":[[960,0]],"id":40917581}],"con":true,"img":false}]}
{"op":"mcm","clk":"11450635760","pt":1717324074052,"mc":[{"id":"1.229554925","rc":[{"atb":[[3.3,0]],"id":49546922}],"con":true,"img":false}]}
{"op":"mcm","clk":"11450635844","pt":1717324074934,"mc":[{"id":"1.229554925","rc":[{"atb":[[3.35,0]],"id":49546922}],"con":true,"img":false}]}
{"op":"mcm","clk":"11450635856","pt":1717324075040,"mc":[{"id":"1.229554925","rc":[{"atb":[[3.25,2.39]],"id":49546922}],"con":true,"img":false}]}
{"op":"mcm","clk":"11450636045","pt":1717324077272,"mc":[{"id":"1.229554925","rc":[{"atb":[[3.3,2.55]],"id":49546922}],"con":true,"img":false}]}
{"op":"mcm","clk":"11450636099","pt":1717324077944,"mc":[{"id":"1.229554925","rc":[{"atl":[[44,4.61],[110,1.28]],"id":48638605}],"con":true,"img":false}]}
{"op":"mcm","clk":"11450636108","pt":1717324078048,"mc":[{"id":"1.229554925","rc":[{"atl":[[60,2]],"id":48638605}],"con":true,"img":false}]}
{"op":"mcm","clk":"11450636120","pt":1717324078150,"mc":[{"id":"1.229554925","rc":[{"atl":[[44,2.61]],"id":48638605}],"con":true,"img":false}]}
{"op":"mcm","clk":"11450636157","pt":1717324078668,"mc":[{"id":"1.229554925","rc":[{"atb":[[3.25,0.39]],"id":49546922}],"con":true,"img":false}]}
{"op":"mcm","clk":"11450636168","pt":1717324078772,"mc":[{"id":"1.229554925","rc":[{"atb":[[3.35,2]],"id":49546922}],"con":true,"img":false}]}
{"op":"mcm","clk":"11450636415","pt":1717324081852,"mc":[{"id":"1.229554925","rc":[{"atl":[[70,2],[100,0]],"id":48638605},{"atb":[[3.3,0]],"id":49546922}],"con":true,"img":false}]}
{"op":"mcm","clk":"11450636430","pt":1717324081960,"mc":[{"id":"1.229554925","rc":[{"atl":[[44,4.61]],"id":48638605}],"con":true,"img":false}]}
{"op":"mcm","clk":"11450636441","pt":1717324082059,"mc":[{"id":"1.229554925","rc":[{"atl":[[60,0]],"id":48638605}],"con":true,"img":false}]}
{"op":"mcm","clk":"11450636517","pt":1717324082785,"mc":[{"id":"1.229554925","rc":[{"atb":[[46,0]],"id":40917581}],"con":true,"img":false}]}
{"op":"mcm","clk":"11450636530","pt":1717324082849,"mc":[{"id":"1.229554925","rc":[{"atb":[[46,2],[50,2.61]],"id":40917581}],"con":true,"img":false}]}
{"op":"mcm","clk":"11450636543","pt":1717324082945,"mc":[{"id":"1.229554925","rc":[{"atb":[[48,0.52]],"id":40917581}],"con":true,"img":false}]}
{"op":"mcm","clk":"11450636550","pt":1717324083051,"mc":[{"id":"1.229554925","rc":[{"atb":[[3.35,0]],"id":49546922}],"con":true,"img":false}]}
{"op":"mcm","clk":"11450636564","pt":1717324083157,"mc":[{"id":"1.229554925","rc":[{"atb":[[3.25,2.39]],"id":49546922}],"con":true,"img":false}]}
{"op":"mcm","clk":"11450636594","pt":1717324083465,"mc":[{"id":"1.229554925","rc":[{"atb":[[48,0]],"id":40917581}],"con":true,"img":false}]}
{"op":"mcm","clk":"11450636612","pt":1717324083678,"mc":[{"id":"1.229554925","rc":[{"atb":[[19.5,0]],"id":64343695},{"atl":[[200,2.61]],"id":64343695},{"atb":[[10,2.12]],"id":48638605},{"atl":[[44,2.61]],"id":48638605},{"atb":[[46,0]],"id":40917581},{"atl":[[860,0.05]],"id":40917581}],"con":true,"img":false}]}
{"op":"mcm","clk":"11450636641","pt":1717324083940,"mc":[{"id":"1.229554925","rc":[{"atb":[[3.3,2.55]],"id":49546922}],"con":true,"img":false}]}
{"op":"mcm","clk":"11450636716","pt":1717324084872,"mc":[{"id":"1.229554925","rc":[{"atb":[[1.68,9.19]],"id":70003372}],"con":true,"img":false}]}
{"op":"mcm","clk":"11450636836","pt":1717324086270,"mc":[{"id":"1.229554925","rc":[{"atb":[[3,5.37]],"id":47148562}],"con":true,"img":false}]}
{"op":"mcm","clk":"11450636871","pt":1717324086642,"mc":[{"id":"1.229554925","rc":[{"atb":[[3.25,0.39]],"id":49546922}],"con":true,"img":false}]}
{"op":"mcm","clk":"11450636883","pt":1717324086740,"mc":[{"id":"1.229554925","rc":[{"atb":[[3.35,2]],"id":49546922}],"con":true,"img":false}]}
{"op":"mcm","clk":"11450636974","pt":1717324087985,"mc":[{"id":"1.229554925","rc":[{"atb":[[2.86,0],[3.15,0],[2.96,17.28]],"id":47148562},{"atl":[[16,0],[11,0]],"id":47148562},{"atb":[[12,0],[14.5,0],[17,0],[18,2.13]],"id":64343695},{"atl":[[350,0],[250,0]],"id":64343695},{"atb":[[8,0],[9,0],[7,0]],"id":48638605},{"atl":[[210,0],[110,0]],"id":48638605},{"atb":[[2.58,0],[2.78,0],[2.68,19.09]],"id":49546922},{"atl":[[13.5,0],[9.4,0]],"id":49546922},{"atb":[[1.79,0],[1.74,0],[1.69,0]],"id":70003372},{"atl":[[4.3,0],[5.3,0]],"id":70003372},{"atb":[[38,0],[24,0],[29,0]],"id":40917581},{"atl":[[550,0],[450,0]],"id":40917581}],"con":true,"img":false}]}
{"op":"mcm","clk":"11450637117","pt":1717324089554,"mc":[{"id":"1.229554925","rc":[{"atb":[[3.3,0]],"id":49546922}],"con":true,"img":false}]}
{"op":"mcm","clk":"11450637247","pt":1717324091055,"mc":[{"id":"1.229554925","rc":[{"atl":[[7.8,0]],"id":47148562}],"con":true,"img":false}]}
{"op":"mcm","clk":"11450637261","pt":1717324091267,"mc":[{"id":"1.229554925","rc":[{"atb":[[60,0]],"id":40917581}],"con":true,"img":false}]}
{"op":"mcm","clk":"11450637303","pt":1717324091886,"mc":[{"id":"1.229554925","rc":[{"atb":[[3.35,0],[3.4,2.55]],"id":49546922}],"con":true,"img":false}]}
{"op":"mcm","clk":"11450637308","pt":1717324091990,"mc":[{"id":"1.229554925","rc":[{"atb":[[3.25,2.39]],"id":49546922}],"con":true,"img":false}]}
{"op":"mcm","clk":"11450637362","pt":1717324092670,"mc":[{"id":"1.229554925","rc":[{"atl":[[12.5,9.96]],"id":49546922},{"atb":[[32,4.18]],"id":40917581}],"con":true,"img":false}]}
{"op":"mcm","clk":"11450637374","pt":1717324092776,"mc":[{"id":"1.229554925","rc":[{"atl":[[10.5,0]],"id":47148562},{"atb":[[17.5,0],[15,0]],"id":64343695},{"atl":[[44,0]],"id":48638605},{"atb":[[2.8,5.82]],"id":49546922},{"atl":[[9.2,0],[8.4,3.04]],"id":49546922},{"atb":[[1.68,0],[1.75,0]],"id":70003372},{"atl":[[4.2,0]],"id":70003372},{"atb":[[40,0],[50,0]],"id":40917581},{"atl":[[860,0]],"id":40917581}],"con":true,"img":false}]}
{"op":"mcm","clk":"11450637384","pt":1717324092878,"mc":[{"id":"1.229554925","rc":[{"atl":[[11.5,12.11]],"id":47148562},{"atb":[[16.5,3.74],[12.5,8.22]],"id":64343695},{"atl":[[48,2.61]],"id":48638605},{"atb":[[3.25,2.26],[2.7,69.86]],"id":49546922},{"atl":[[9,7.19]],"id":49546922},{"atb":[[1.67,61.85]],"id":70003372},{"atl":[[5,32.69]],"id":70003372},{"atb":[[46,2.61]],"id":40917581},{"atl":[[920,0.05]],"id":40917581}],"con":true,"img":false}]}
{"op":"mcm","clk":"11450637402","pt":1717324093088,"mc":[{"id":"1.229554925","rc":[{"atb":[[3.55,0.23]],"id":47148562}],"con":true,"img":false}]}
{"op":"mcm","clk":"11450637453","pt":1717324093559,"mc":[{"id":"1.229554925","rc":[{"spn":5.87,"spf":"NaN","id":47148562},{"spn":18.07,"spf":1.0,"id":64343695},{"spn":5.9,"spf":"NaN","id":49546922},{"spn":1.68,"spf":1.0,"id":70003372},{"atb":[[48,0.52]],"id":40917581},{"spn":46.74,"spf":1.0,"id":40917581}],"con":true,"img":false}]}
{"op":"mcm","clk":"11450637477","pt":1717324093878,"mc":[{"id":"1.229554925","rc":[{"atb":[[3.25,0.26]],"id":49546922}],"con":true,"img":false}]}
{"op":"mcm","clk":"11450637494","pt":1717324093977,"mc":[{"id":"1.229554925","rc":[{"atb":[[2.86,112.28],[3.15,48.57],[2.96,123.84]],"id":47148562},{"atl":[[16,13.95],[11,13.95]],"id":47148562},{"atb":[[12,18.98],[14.5,15.47],[17,6.52]],"id":64343695},{"atl":[[350,0.6],[250,0.55]],"id":64343695},{"atb":[[8,29.83],[9,13.05],[7,34.8]],"id":48638605},{"atl":[[210,0.99],[110,1.28]],"id":48638605},{"atb":[[2.58,132.18],[3.45,2],[2.78,58.66],[2.68,143.4]],"id":49546922},{"atl":[[13.5,16.75],[9.4,16.61]],"id":49546922},{"atb":[[1.79,132.18],[1.74,282.23],[1.69,302.68]],"id":70003372},{"atl":[[4.3,42.29],[5.3,48.69]],"id":70003372},{"atb":[[38,4.15],[24,13.37],[29,10.98]],"id":40917581},{"atl":[[550,0.1],[450,0.08]],"id":40917581}],"con":true,"img":false}]}
{"op":"mcm","clk":"11450637563","pt":1717324094762,"mc":[{"id":"1.229554925","rc":[{"atb":[[10,2.08]],"id":48638605}],"con":true,"img":false}]}
{"op":"mcm","clk":"11450637586","pt":1717324095081,"mc":[{"id":"1.229554925","rc":[{"atb":[[20,0.04]],"id":64343695}],"con":true,"img":false}]}
{"op":"mcm","clk":"11450637595","pt":1717324095185,"mc":[{"id":"1.229554925","rc":[{"atb":[[3.25,0]],"id":49546922}],"con":true,"img":false}]}
{"op":"mcm","clk":"11450637603","pt":1717324095279,"mc":[{"id":"1.229554925","rc":[{"atb":[[3.55,0]],"id":47148562}],"con":true,"img":false}]}
{"op":"mcm","clk":"11450637611","pt":1717324095385,"mc":[{"id":"1.229554925","rc":[{"atb":[[1.07,1.7]],"id":47148562},{"atb":[[1.06,1.7]],"id":49546922}],"con":true,"img":false}]}
{"op":"mcm","clk":"11450637626","pt":1717324095590,"mc":[{"id":"1.229554925","rc":[{"atl":[[1000,2.7]],"id":47148562}],"con":true,"img":false}]}
{"op":"mcm","clk":"11450637628","pt":1717324095644,"mc":[{"id":"1.229554925","rc":[{"atb":[[1.16,1.7]],"id":48638605}],"con":true,"img":false}]}
{"op":"mcm","clk":"11450637645","pt":1717324095857,"mc":[{"id":"1.229554925","rc":[{"atl":[[46,0.18]],"id":48638605},{"atb":[[3.4,0]],"id":49546922}],"con":true,"img":false}]}
{"op":"mcm","clk":"11450637654","pt":1717324095963,"mc":[{"id":"1.229554925","rc":[{"atb":[[1.07,0.11]],"id":47148562}],"con":true,"img":false}]}
{"op":"mcm","clk":"11450637672","pt":1717324096161,"mc":[{"id":"1.229554925","rc":[{"atb":[[1.27,1.7]],"id":64343695}],"con":true,"img":false}]}
{"op":"mcm","clk":"11450637692","pt":1717324096370,"mc":[{"id":"1.229554925","rc":[{"atb":[[1.06,0.11]],"id":49546922}],"con":true,"img":false}]}
{"op":"mcm","clk":"11450637730","pt":1717324096783,"mc":[{"id":"1.229554925","rc":[{"atb":[[10,2],[1.16,0.04]],"id":48638605}],"con":true,"img":false}]}
{"op":"mcm","clk":"11450637741","pt":1717324096885,"mc":[{"id":"1.229554925","rc":[{"atb":[[1.07,0]],"id":47148562}],"con":true,"img":false}]}
{"op":"mcm","clk":"11450637751","pt":1717324096990,"mc":[{"id":"1.229554925","rc":[{"atb":[[3.8,0.11]],"id":47148562}],"con":true,"img":false}]}
{"op":"mcm","clk":"11450637781","pt":1717324097259,"mc":[{"id":"1.229554925","rc":[{"atb":[[3.45,0]],"id":49546922}],"con":true,"img":false}]}
{"op":"mcm","clk":"11450637787","pt":1717324097371,"mc":[{"id":"1.229554925","rc":[{"atl":[[1000,1.11]],"id":47148562},{"atb":[[3.25,2]],"id":49546922}],"con":true,"img":false}]}
{"op":"mcm","clk":"11450637798","pt":1717324097465,"mc":[{"id":"1.229554925","rc":[{"atb":[[1.27,0.02]],"id":64343695}],"con":true,"img":false}]}
{"op":"mcm","clk":"11450637819","pt":1717324097679,"mc":[{"id":"1.229554925","rc":[{"atb":[[20,0]],"id":64343695},{"atb":[[10,0]],"id":48638605}],"con":true,"img":false}]}
{"op":"mcm","clk":"11450637828","pt":1717324097779,"mc":[{"id":"1.229554925","rc":[{"atb":[[9.4,2]],"id":48638605}],"con":true,"img":false}]}
{"op":"mcm","clk":"11450637852","pt":1717324098090,"mc":[{"id":"1.229554925","rc":[{"atb":[[1.06,0]],"id":49546922}],"con":true,"img":false}]}
{"op":"mcm","clk":"11450637862","pt":1717324098192,"mc":[{"id":"1.229554925","rc":[{"atb":[[3.45,0.11]],"id":49546922}],"con":true,"img":false}]}
{"op":"mcm","clk":"11450637891","pt":1717324098459,"mc":[{"id":"1.229554925","rc":[{"atb":[[1.03,1.7]],"id":49546922}],"con":true,"img":false}]}
{"op":"mcm","clk":"11450637909","pt":1717324098771,"mc":[{"id":"1.229554925","rc":[{"atl":[[1000,1]],"id":47148562}],"con":true,"img":false}]}
{"op":"mcm","clk":"11450637919","pt":1717324098878,"mc":[{"id":"1.229554925","rc":[{"atl":[[7.8,0.11]],"id":47148562}],"con":true,"img":false}]}
{"op":"mcm","clk":"11450637929","pt":1717324098985,"mc":[{"id":"1.229554925","rc":[{"atb":[[1.16,0]],"id":48638605}],"con":true,"img":false}]}
{"op":"mcm","clk":"11450637938","pt":1717324099087,"mc":[{"id":"1.229554925","rc":[{"atb":[[10.5,0.04]],"id":48638605},{"atb":[[1.4,1.7]],"id":40917581}],"con":true,"img":false}]}
{"op":"mcm","clk":"11450637959","pt":1717324099390,"mc":[{"id":"1.229554925","rc":[{"atl":[[1000,1]],"id":49546922},{"atb":[[60,0]],"id":40917581}],"con":true,"img":false}]}
{"op":"mcm","clk":"11450637972","pt":1717324099494,"mc":[{"id":"1.229554925","rc":[{"atb":[[1.04,1.7]],"id":47148562}],"con":true,"img":false}]}
{"op":"mcm","clk":"11450637987","pt":1717324099699,"mc":[{"id":"1.229554925","rc":[{"atb":[[9.6,2.55]],"id":48638605},{"atb":[[3.3,2.55]],"id":49546922}],"con":true,"img":false}]}
{"op":"mcm","clk":"11450637995","pt":1717324099761,"mc":[{"id":"1.229554925","rc":[{"atb":[[1.03,0.24]],"id":49546922}],"con":true,"img":false}]}
{"op":"mcm","clk":"11450638005","pt":1717324099862,"mc":[{"id":"1.229554925","rc":[{"atb":[[1.27,0]],"id":64343695}],"con":true,"img":false}]}
{"op":"mcm","clk":"11450638012","pt":1717324099964,"mc":[{"id":"1.229554925","rc":[{"atb":[[18.5,0.02]],"id":64343695}],"con":true,"img":false}]}
{"op":"mcm","clk":"11450638037","pt":1717324100385,"mc":[{"id":"1.229554925","rc":[{"atb":[[1.08,1.7]],"id":48638605},{"atb":[[1.8,1.7]],"id":40917581}],"con":true,"img":false}]}
{"op":"mcm","clk":"11450638060","pt":1717324100584,"mc":[{"id":"1.229554925","rc":[{"atl":[[1000,2.7]],"id":48638605}],"con":true,"img":false}]}
{"op":"mcm","clk":"11450638075","pt":1717324100696,"mc":[{"id":"1.229554925","rc":[{"atb":[[1.03,0]],"id":49546922}],"con":true,"img":false}]}
{"op":"mcm","clk":"11450638085","pt":1717324100791,"mc":[{"id":"1.229554925","rc":[{"atb":[[3.5,0.24]],"id":49546922}],"con":true,"img":false}]}
{"op":"mcm","clk":"11450638094","pt":1717324100899,"mc":[{"id":"1.229554925","rc":[{"atb":[[1.8,0]],"id":40917581}],"con":true,"img":false}]}
{"op":"mcm","clk":"11450638119","pt":1717324101166,"mc":[{"id":"1.229554925","rc":[{"atb":[[1.16,1.7]],"id":64343695},{"atb":[[3.25,0]],"id":49546922}],"con":true,"img":false}]}
{"op":"mcm","clk":"11450638128","pt":1717324101267,"mc":[{"id":"1.229554925","rc":[{"atb":[[3.35,2]],"id":49546922}],"con":true,"img":false}]}
{"op":"mcm","clk":"11450638144","pt":1717324101472,"mc":[{"id":"1.229554925","rc":[{"atb":[[1.04,0.22]],"id":47148562},{"atb":[[1.8,0]],"id":40917581}],"con":true,"img":false}]}
{"op":"mcm","clk":"11450638152","pt":1717324101572,"mc":[{"id":"1.229554925","rc":[{"atb":[[48,0.53]],"id":40917581}],"con":true,"img":false}]}
{"op":"mcm","clk":"11450638178","pt":1717324101898,"mc":[{"id":"1.229554925","rc":[{"atb":[[9.4,0]],"id":48638605}],"con":true,"img":false}]}
{"op":"mcm","clk":"11450638189","pt":1717324101987,"mc":[{"id":"1.229554925","rc":[{"atb":[[9.8,2]],"id":48638605},{"atb":[[1.4,0.01]],"id":40917581}],"con":true,"img":false}]}
{"op":"mcm","clk":"11450638239","pt":1717324102460,"mc":[{"id":"1.229554925","rc":[{"atl":[[1000,1.01]],"id":48638605}],"con":true,"img":false}]}
{"op":"mcm","clk":"11450638286","pt":1717324102983,"mc":[{"id":"1.229554925","rc":[{"atb":[[1.08,0.08]],"id":48638605}],"con":true,"img":false}]}
{"op":"mcm","clk":"11450638379","pt":1717324103862,"mc":[{"id":"1.229554925","rc":[{"atb":[[1.16,0.04]],"id":64343695}],"con":true,"img":false}]}
{"op":"mcm","clk":"11450638428","pt":1717324104382,"mc":[{"id":"1.229554925","rc":[{"atb":[[9.6,0]],"id":48638605},{"atb":[[3.3,0]],"id":49546922}],"con":true,"img":false}]}
{"op":"mcm","clk":"11450638434","pt":1717324104490,"mc":[{"id":"1.229554925","rc":[{"atb":[[1.04,0]],"id":47148562}],"con":true,"img":false}]}
{"op":"mcm","clk":"11450638444","pt":1717324104589,"mc":[{"id":"1.229554925","rc":[{"atb":[[3.8,0.33]],"id":47148562}],"con":true,"img":false}]}
{"op":"mcm","clk":"11450638481","pt":1717324105003,"mc":[{"id":"1.229554925","rc":[{"atb":[[1.4,0]],"id":40917581}],"con":true,"img":false}]}
{"op":"mcm","clk":"11450638490","pt":1717324105106,"mc":[{"id":"1.229554925","rc":[{"atb":[[48,0.55]],"id":40917581}],"con":true,"img":false}]}
{"op":"mcm","clk":"11450638519","pt":1717324105475,"mc":[{"id":"1.229554925","rc":[{"atl":[[1000,1]],"id":48638605}],"con":true,"img":false}]}
{"op":"mcm","clk":"11450638529","pt":1717324105581,"mc":[{"id":"1.229554925","rc":[{"atl":[[46,0.2]],"id":48638605}],"con":true,"img":false}]}
{"op":"mcm","clk":"11450638550","pt":1717324105891,"mc":[{"id":"1.229554925","rc":[{"atb":[[1.08,0]],"id":48638605}],"con":true,"img":false}]}
{"op":"mcm","clk":"11450638557","pt":1717324105993,"mc":[{"id":"1.229554925","rc":[{"atb":[[10.5,0.12]],"id":48638605}],"con":true,"img":false}]}
{"op":"mcm","clk":"11450638657","pt":1717324107196,"mc":[{"id":"1.229554925","rc":[{"atb":[[1.16,0]],"id":64343695}],"con":true,"img":false}]}
{"op":"mcm","clk":"11450638668","pt":1717324107297,"mc":[{"id":"1.229554925","rc":[{"atb":[[18.5,0.06]],"id":64343695}],"con":true,"img":false}]}
{"op":"mcm","clk":"11450638702","pt":1717324107613,"mc":[{"id":"1.229554925","rc":[{"atb":[[10,2.55]],"id":48638605},{"atb":[[3.4,2.55]],"id":49546922}],"con":true,"img":false}]}
{"op":"mcm","clk":"11450638764","pt":1717324108204,"mc":[{"id":"1.229554925","rc":[{"atl":[[1000,2.7]],"id":49546922}],"con":true,"img":false}]}
{"op":"mcm","clk":"11450638817","pt":1717324108821,"mc":[{"id":"1.229554925","rc":[{"atb":[[3.35,0]],"id":49546922}],"con":true,"img":false}]}
{"op":"mcm","clk":"11450638828","pt":1717324108926,"mc":[{"id":"1.229554925","rc":[{"atb":[[3.45,2.11]],"id":49546922}],"con":true,"img":false}]}
{"op":"mcm","clk":"11450638859","pt":1717324109299,"mc":[{"id":"1.229554925","rc":[{"atb":[[9.8,0]],"id":48638605}],"con":true,"img":false}]}
{"op":"mcm","clk":"11450638869","pt":1717324109406,"mc":[{"id":"1.229554925","rc":[{"atb":[[1.02,2]],"id":48638605}],"con":true,"img":false}]}
{"op":"mcm","clk":"11450638971","pt":1717324110609,"mc":[{"id":"1.229554925","rc":[{"atb":[[3.25,34.52]],"id":47148562}],"con":true,"img":false}]}
{"op":"mcm","clk":"11450638993","pt":1717324110814,"mc":[{"id":"1.229554925","rc":[{"atb":[[2.82,6.22],[3.4,0]],"id":49546922}],"con":true,"img":false}]}
{"op":"mcm","clk":"11450639035","pt":1717324111287,"mc":[{"id":"1.229554925","rc":[{"atl":[[1000,1.1]],"id":49546922}],"con":true,"img":false}]}
{"op":"mcm","clk":"11450639492","pt":1717324116202,"mc":[{"id":"1.229554925","rc":[{"atl":[[1000,1]],"id":49546922}],"con":true,"img":false}]}
{"op":"mcm","clk":"11450639503","pt":1717324116300,"mc":[{"id":"1.229554925","rc":[{"atl":[[8.2,0.1]],"id":49546922}],"con":true,"img":false}]}
{"op":"mcm","clk":"11450639980","pt":1717324121808,"mc":[{"id":"1.229554925","rc":[{"atb":[[19.5,2]],"id":64343695},{"atl":[[200,4.61]],"id":64343695},{"atb":[[10,4.55]],"id":48638605},{"atl":[[48,4.61]],"id":48638605},{"atb":[[46,4.61]],"id":40917581},{"atl":[[920,2.05]],"id":40917581}],"con":true,"img":false}]}
{"op":"mcm","clk":"11450640058","pt":1717324122750,"mc":[{"id":"1.229554925","rc":[{"atl":[[9,0]],"id":49546922},{"atl":[[920,2]],"id":40917581}],"con":true,"img":false}]}
{"op":"mcm","clk":"11450640069","pt":1717324122841,"mc":[{"id":"1.229554925","rc":[{"atl":[[8.4,10.23]],"id":49546922},{"atl":[[870,0.05]],"id":40917581}],"con":true,"img":false}]}
{"op":"mcm","clk":"11450640117","pt":1717324123418,"mc":[{"id":"1.229554925","rc":[{"atb":[[18,0]],"id":64343695}],"con":true,"img":false}]}
{"op":"mcm","clk":"11450640232","pt":1717324124614,"mc":[{"id":"1.229554925","rc":[{"atb":[[1.61,9.19]],"id":70003372}],"con":true,"img":false}]}
{"op":"mcm","clk":"11450640435","pt":1717324126907,"mc":[{"id":"1.229554925","rc":[{"atl":[[870,2.05]],"id":40917581}],"con":true,"img":false}]}
{"op":"mcm","clk":"11450640442","pt":1717324127012,"mc":[{"id":"1.229554925","rc":[{"atl":[[870,0.05],[920,0],[970,2]],"id":40917581}],"con":true,"img":false}]}
{"op":"mcm","clk":"11450640447","pt":1717324127116,"mc":[{"id":"1.229554925","rc":[{"atl":[[960,0.02]],"id":40917581}],"con":true,"img":false}]}
{"op":"mcm","clk":"11450640454","pt":1717324127222,"mc":[{"id":"1.229554925","rc":[{"atl":[[870,2.05]],"id":40917581}],"con":true,"img":false}]}
{"op":"mcm","clk":"11450640464","pt":1717324127330,"mc":[{"id":"1.229554925","rc":[{"atl":[[870,0.05],[960,2.02],[970,0]],"id":40917581}],"con":true,"img":false}]}
{"op":"mcm","clk":"11450640472","pt":1717324127429,"mc":[{"id":"1.229554925","rc":[{"atl":[[870,2.05],[960,0.02]],"id":40917581}],"con":true,"img":false}]}
{"op":"mcm","clk":"11450640479","pt":1717324127532,"mc":[{"id":"1.229554925","rc":[{"atl":[[960,2.02]],"id":40917581}],"con":true,"img":false}]}
{"op":"mcm","clk":"11450640485","pt":1717324127642,"mc":[{"id":"1.229554925","rc":[{"atl":[[870,0.05]],"id":40917581}],"con":true,"img":false}]}
{"op":"mcm","clk":"11450640491","pt":1717324127746,"mc":[{"id":"1.229554925","rc":[{"atl":[[960,0.02]],"id":40917581}],"con":true,"img":false}]}
{"op":"mcm","clk":"11450640498","pt":1717324127846,"mc":[{"id":"1.229554925","rc":[{"atl":[[870,2.05]],"id":40917581}],"con":true,"img":false}]}
{"op":"mcm","clk":"11450640576","pt":1717324128806,"mc":[{"id":"1.229554925","rc":[{"atl":[[960,0]],"id":40917581}],"con":true,"img":false}]}
{"op":"mcm","clk":"11450640922","pt":1717324132737,"mc":[{"id":"1.229554925","rc":[{"atl":[[11.5,0]],"id":47148562},{"atb":[[16.5,0]],"id":64343695},{"atb":[[1.67,0]],"id":70003372}],"con":true,"img":false}]}
{"op":"mcm","clk":"11450640937","pt":1717324132846,"mc":[{"id":"1.229554925","rc":[{"atl":[[10.5,12.11]],"id":47148562},{"atb":[[17.5,3.74]],"id":64343695},{"atb":[[1.75,61.85]],"id":70003372}],"con":true,"img":false}]}
{"op":"mcm","clk":"11450641782","pt":1717324142640,"mc":[{"id":"1.229554925","rc":[{"atb":[[12.5,0]],"id":64343695},{"atl":[[48,2]],"id":48638605},{"atb":[[2.7,0]],"id":49546922},{"atl":[[9.2,13.97]],"id":49546922},{"atl":[[5,0]],"id":70003372},{"atb":[[40,3.13]],"id":40917581},{"atl":[[870,2]],"id":40917581}],"con":true,"img":false}]}
{"op":"mcm","clk":"11450641791","pt":1717324142752,"mc":[{"id":"1.229554925","rc":[{"atb":[[15,8.22]],"id":64343695},{"atl":[[46,2.82]],"id":48638605},{"atb":[[2.8,75.68]],"id":49546922},{"atl":[[12.5,0]],"id":49546922},{"atl":[[4.2,32.69]],"id":70003372},{"atb":[[32,0]],"id":40917581},{"atl":[[860,0.05],[970,2]],"id":40917581}],"con":true,"img":false}]}
{"op":"mcm","clk":"11450641798","pt":1717324142855,"mc":[{"id":"1.229554925","rc":[{"atl":[[65,4.61],[48,0]],"id":48638605}],"con":true,"img":false}]}
{"op":"mcm","clk":"11450641805","pt":1717324142954,"mc":[{"id":"1.229554925","rc":[{"atb":[[1.61,0]],"id":70003372},{"atl":[[870,0]],"id":40917581}],"con":true,"img":false}]}
{"op":"mcm","clk":"11450641832","pt":1717324143261,"mc":[{"id":"1.229554925","rc":[{"atl":[[960,0.02]],"id":40917581}],"con":true,"img":false}]}
{"op":"mcm","clk":"11450642294","pt":1717324147924,"mc":[{"id":"1.229554925","rc":[{"atl":[[65,2.61],[46,4.82]],"id":48638605},{"atl":[[860,2.05],[970,0]],"id":40917581}],"con":true,"img":false}]}
{"op":"mcm","clk":"11450642378","pt":1717324148766,"mc":[{"id":"1.229554925","rc":[{"atl":[[960,0]],"id":40917581}],"con":true,"img":false}]}
{"op":"mcm","clk":"11450643712","pt":1717324162460,"mc":[{"id":"1.229554925","rc":[{"spn":5.8,"spf":"NaN","id":47148562},{"spn":19.5,"spf":1.0,"id":64343695},{"spn":10.06,"spf":1.0,"id":48638605},{"spn":5.85,"spf":"NaN","id":49546922},{"atb":[[1.68,9.19]],"id":70003372},{"spn":1.79,"spf":1.0,"id":70003372},{"spn":46.7,"spf":1.0,"id":40917581}],"con":true,"img":false}]}
{"op":"mcm","clk":"11450643743","pt":1717324162654,"mc":[{"id":"1.229554925","rc":[{"atl":[[860,2]],"id":40917581}],"con":true,"img":false}]}
{"op":"mcm","clk":"11450643761","pt":1717324162782,"mc":[{"id":"1.229554925","rc":[{"atl":[[860,0],[850,0.05],[970,2]],"id":40917581}],"con":true,"img":false}]}
{"op":"mcm","clk":"11450643782","pt":1717324162969,"mc":[{"id":"1.229554925","rc":[{"atl":[[850,2.05],[970,0]],"id":40917581}],"con":true,"img":false}]}
{"op":"mcm","clk":"11450644117","pt":1717324166369,"mc":[{"id":"1.229554925","rc":[{"atb":[[2.82,0]],"id":49546922}],"con":true,"img":false}]}
{"op":"mcm","clk":"11450644282","pt":1717324167984,"mc":[{"id":"1.229554925","rc":[{"atb":[[1.68,0]],"id":70003372}],"con":true,"img":false}]}
{"op":"mcm","clk":"11450644725","pt":1717324172689,"mc":[{"id":"1.229554925","rc":[{"atl":[[46,2.2]],"id":48638605}],"con":true,"img":false}]}
{"op":"mcm","clk":"11450644735","pt":1717324172797,"mc":[{"id":"1.229554925","rc":[{"atl":[[65,4.61],[44,2.61],[46,0.2]],"id":48638605}],"con":true,"img":false}]}
{"op":"mcm","clk":"11450645210","pt":1717324177893,"mc":[{"id":"1.229554925","rc":[{"atl":[[65,2.61],[44,4.61]],"id":48638605}],"con":true,"img":false}]}
{"op":"mcm","clk":"11450645219","pt":1717324177993,"mc":[{"id":"1.229554925","rc":[{"atl":[[44,2.61]],"id":48638605}],"con":true,"img":false}]}
{"op":"mcm","clk":"11450645232","pt":1717324178107,"mc":[{"id":"1.229554925","rc":[{"atl":[[44,4.61]],"id":48638605}],"con":true,"img":false}]}
{"op":"mcm","clk":"11450645735","pt":1717324182764,"mc":[{"id":"1.229554925","rc":[{"atl":[[850,2]],"id":40917581}],"con":true,"img":false}]}
{"op":"mcm","clk":"11450645747","pt":1717324182867,"mc":[{"id":"1.229554925","rc":[{"atl":[[850,0],[840,0.05],[970,2]],"id":40917581}],"con":true,"img":false}]}
{"op":"mcm","clk":"11450645782","pt":1717324183180,"mc":[{"id":"1.229554925","rc":[{"atl":[[960,0.02]],"id":40917581}],"con":true,"img":false}]}
{"op":"mcm","clk":"11450645797","pt":1717324183388,"mc":[{"id":"1.229554925","rc":[{"atb":[[1.01,1]],"id":40917581}],"con":true,"img":false}]}
{"op":"mcm","clk":"11450646266","pt":1717324187991,"mc":[{"id":"1.229554925","rc":[{"atl":[[840,2.05]],"id":40917581}],"con":true,"img":false}]}
{"op":"mcm","clk":"11450646277","pt":1717324188085,"mc":[{"id":"1.229554925","rc":[{"atl":[[840,0.05],[970,0]],"id":40917581}],"con":true,"img":false}]}
{"op":"mcm","clk":"11450646290","pt":1717324188184,"mc":[{"id":"1.229554925","rc":[{"atl":[[840,2.05]],"id":40917581}],"con":true,"img":false}]}
{"op":"mcm","clk":"11450646375","pt":1717324189173,"mc":[{"id":"1.229554925","rc":[{"atl":[[960,0]],"id":40917581}],"con":true,"img":false}]}
{"op":"mcm","clk":"11450647292","pt":1717324198326,"mc":[{"id":"1.229554925","rc":[{"atb":[[1.69,311.87]],"id":70003372}],"con":true,"img":false}]}
{"op":"mcm","clk":"11450647643","pt":1717324201460,"mc":[{"id":"1.229554925","rc":[{"atb":[[2.86,0],[3.15,0],[2.96,17.28]],"id":47148562},{"atl":[[16,0],[11,0]],"id":47148562},{"atb":[[12,0],[14.5,0],[17,0]],"id":64343695},{"atl":[[350,0],[250,0]],"id":64343695},{"atb":[[8,0],[9,0],[7,0]],"id":48638605},{"atl":[[210,0],[110,0]],"id":48638605},{"atb":[[2.58,0],[2.78,0],[2.68,19.09]],"id":49546922},{"atl":[[13.5,0],[9.4,0]],"id":49546922},{"atb":[[1.79,0],[1.74,0],[1.69,9.19]],"id":70003372},{"atl":[[4.3,0],[5.3,0]],"id":70003372},{"atb":[[38,0],[24,0],[29,0]],"id":40917581},{"atl":[[550,0],[450,0]],"id":40917581}],"con":true,"img":false}]}
{"op":"mcm","clk":"11450647660","pt":1717324201524,"mc":[{"id":"1.229554925","rc":[{"atl":[[980,4.61]],"id":40917581}],"con":true,"img":false}]}
{"op":"mcm","clk":"11450647675","pt":1717324201634,"mc":[{"id":"1.229554925","rc":[{"atl":[[840,0.05],[980,2.61]],"id":40917581}],"con":true,"img":false}]}
{"op":"mcm","clk":"11450647689","pt":1717324201727,"mc":[{"id":"1.229554925","rc":[{"atl":[[46,0.01]],"id":48638605},{"atl":[[980,4.61]],"id":40917581}],"con":true,"img":false}]}
{"op":"mcm","clk":"11450647834","pt":1717324202731,"mc":[{"id":"1.229554925","rc":[{"atl":[[10.5,0],[14.5,8.52]],"id":47148562},{"atb":[[17.5,0],[15,0]],"id":64343695},{"atl":[[44,2]],"id":48638605},{"atb":[[2.8,5.82]],"id":49546922},{"atl":[[9.2,0],[12.5,9.96],[8.4,3.04]],"id":49546922},{"atb":[[1.75,0]],"id":70003372},{"atl":[[4.2,0]],"id":70003372},{"atb":[[32,4.18],[40,0]],"id":40917581},{"atl":[[840,0]],"id":40917581}],"con":true,"img":false}]}
{"op":"mcm","clk":"11450647851","pt":1717324202845,"mc":[{"id":"1.229554925","rc":[{"atb":[[16.5,3.74],[12.5,8.22]],"id":64343695},{"atl":[[48,2.61]],"id":48638605},{"atb":[[2.7,69.86]],"id":49546922},{"atl":[[9,7.19]],"id":49546922},{"atb":[[1.67,61.85],[1.69,0]],"id":70003372},{"atl":[[5,32.69]],"id":70003372},{"atl":[[920,0.05]],"id":40917581}],"con":true,"img":false}]}
{"op":"mcm","clk":"11450647863","pt":1717324202941,"mc":[{"id":"1.229554925","rc":[{"atl":[[65,4.61],[44,0]],"id":48638605}],"con":true,"img":false}]}
{"op":"mcm","clk":"11450647876","pt":1717324203036,"mc":[{"id":"1.229554925","rc":[{"atl":[[48,4.61]],"id":48638605}],"con":true,"img":false}]}
{"op":"mcm","clk":"11450647887","pt":1717324203095,"mc":[{"id":"1.229554925","rc":[{"atl":[[65,2.61]],"id":48638605}],"con":true,"img":false}]}
{"op":"mcm","clk":"11450648472","pt":1717324208746,"mc":[{"id":"1.229554925","rc":[{"atb":[[2.86,112.28],[3.15,48.57],[2.96,123.84]],"id":47148562},{"atl":[[16,13.95],[11,13.95]],"id":47148562},{"atb":[[12,18.98],[14.5,15.47],[17,6.52]],"id":64343695},{"atl":[[350,0.6],[250,0.55]],"id":64343695},{"atb":[[8,29.83],[9,13.05],[7,34.8]],"id":48638605},{"atl":[[210,0.99],[110,1.28]],"id":48638605},{"atb":[[2.58,132.18],[2.78,58.66],[2.68,143.4]],"id":49546922},{"atl":[[13.5,16.75],[9.4,16.61]],"id":49546922},{"atb":[[1.79,132.18],[1.74,282.23],[1.69,302.68]],"id":70003372},{"atl":[[4.3,42.29],[5.3,48.69]],"id":70003372},{"atb":[[38,4.15],[24,13.37],[29,10.98]],"id":40917581},{"atl":[[550,0.1],[450,0.08]],"id":40917581}],"con":true,"img":false}]}
{"op":"mcm","clk":"11450648483","pt":1717324208859,"mc":[{"id":"1.229554925","rc":[{"atl":[[920,2.05],[980,2.61]],"id":40917581}],"con":true,"img":false}]}
{"op":"mcm","clk":"11450648497","pt":1717324208959,"mc":[{"id":"1.229554925","rc":[{"atl":[[920,0.05],[970,2]],"id":40917581}],"con":true,"img":false}]}
{"op":"mcm","clk":"11450648509","pt":1717324209057,"mc":[{"id":"1.229554925","rc":[{"atl":[[920,2.05],[970,0]],"id":40917581}],"con":true,"img":false}]}
{"op":"mcm","clk":"11450648629","pt":1717324210316,"mc":[{"id":"1.229554925","rc":[{"atl":[[1000,2.7]],"id":47148562}],"con":true,"img":false}]}
{"op":"mcm","clk":"11450648744","pt":1717324211552,"mc":[{"id":"1.229554925","rc":[{"atl":[[1000,1.05]],"id":47148562}],"con":true,"img":false}]}
{"op":"mcm","clk":"11450648821","pt":1717324212340,"mc":[{"id":"1.229554925","rc":[{"atl":[[1000,1]],"id":47148562}],"con":true,"img":false}]}
{"op":"mcm","clk":"11450648826","pt":1717324212442,"mc":[{"id":"1.229554925","rc":[{"atl":[[7.8,0.16]],"id":47148562}],"con":true,"img":false}]}
{"op":"mcm","clk":"11450649321","pt":1717324217363,"mc":[{"id":"1.229554925","rc":[{"atb":[[3.8,0.22]],"id":47148562}],"con":true,"img":false}]}
{"op":"mcm","clk":"11450649354","pt":1717324217667,"mc":[{"id":"1.229554925","rc":[{"atl":[[7.8,0.05]],"id":47148562}],"con":true,"img":false}]}
{"op":"mcm","clk":"11450649386","pt":1717324217977,"mc":[{"id":"1.229554925","rc":[{"atb":[[3.45,2]],"id":49546922}],"con":true,"img":false}]}
{"op":"mcm","clk":"11450649424","pt":1717324218252,"mc":[{"id":"1.229554925","rc":[{"atb":[[10.5,0.08]],"id":48638605}],"con":true,"img":false}]}
{"op":"mcm","clk":"11450649436","pt":1717324218354,"mc":[{"id":"1.229554925","rc":[{"atl":[[1000,2.7]],"id":47148562}],"con":true,"img":false}]}
{"op":"mcm","clk":"11450649467","pt":1717324218670,"mc":[{"id":"1.229554925","rc":[{"atb":[[1.07,1.7]],"id":47148562}],"con":true,"img":false}]}
{"op":"mcm","clk":"11450649475","pt":1717324218767,"mc":[{"id":"1.229554925","rc":[{"atl":[[1000,1.11]],"id":47148562}],"con":true,"img":false}]}
{"op":"mcm","clk":"11450649496","pt":1717324218974,"mc":[{"id":"1.229554925","rc":[{"atb":[[1.06,1.7]],"id":49546922}],"con":true,"img":false}]}
{"op":"mcm","clk":"11450649518","pt":1717324219184,"mc":[{"id":"1.229554925","rc":[{"atb":[[18.5,0.04]],"id":64343695}],"con":true,"img":false}]}
{"op":"mcm","clk":"11450649538","pt":1717324219353,"mc":[{"id":"1.229554925","rc":[{"atl":[[1000,1]],"id":47148562}],"con":true,"img":false}]}
{"op":"mcm","clk":"11450649546","pt":1717324219459,"mc":[{"id":"1.229554925","rc":[{"atb":[[1.07,0.11]],"id":47148562},{"atl":[[7.8,0.16]],"id":47148562},{"atb":[[1.06,0.11]],"id":49546922}],"con":true,"img":false}]}
{"op":"mcm","clk":"11450649586","pt":1717324219800,"mc":[{"id":"1.229554925","rc":[{"atb":[[1.16,1.7]],"id":48638605},{"atl":[[1000,2.7]],"id":48638605},{"atb":[[48,0.53]],"id":40917581}],"con":true,"img":false}]}
{"op":"mcm","clk":"11450649615","pt":1717324219978,"mc":[{"id":"1.229554925","rc":[{"atb":[[3.8,0]],"id":47148562}],"con":true,"img":false}]}
{"op":"mcm","clk":"11450649625","pt":1717324220079,"mc":[{"id":"1.229554925","rc":[{"atb":[[1.07,0]],"id":47148562}],"con":true,"img":false}]}
{"op":"mcm","clk":"11450649638","pt":1717324220185,"mc":[{"id":"1.229554925","rc":[{"atb":[[3.8,0.11]],"id":47148562}],"con":true,"img":false}]}
{"op":"mcm","clk":"11450649652","pt":1717324220290,"mc":[{"id":"1.229554925","rc":[{"atb":[[3.5,0]],"id":49546922},{"atb":[[1.4,1.7]],"id":40917581}],"con":true,"img":false}]}
{"op":"mcm","clk":"11450649683","pt":1717324220557,"mc":[{"id":"1.229554925","rc":[{"atb":[[1.04,1.7]],"id":47148562}],"con":true,"img":false}]}
{"op":"mcm","clk":"11450649697","pt":1717324220661,"mc":[{"id":"1.229554925","rc":[{"atb":[[1.06,0]],"id":49546922},{"atb":[[1.4,0.01]],"id":40917581}],"con":true,"img":false}]}
{"op":"mcm","clk":"11450649713","pt":1717324220759,"mc":[{"id":"1.229554925","rc":[{"atb":[[3.5,0.11]],"id":49546922}],"con":true,"img":false}]}
{"op":"mcm","clk":"11450649726","pt":1717324220866,"mc":[{"id":"1.229554925","rc":[{"atb":[[1.03,1.7]],"id":49546922}],"con":true,"img":false}]}
{"op":"mcm","clk":"11450649736","pt":1717324220970,"mc":[{"id":"1.229554925","rc":[{"atb":[[1.04,0.22]],"id":47148562}],"con":true,"img":false}]}
{"op":"mcm","clk":"11450649746","pt":1717324221076,"mc":[{"id":"1.229554925","rc":[{"atl":[[1000,1]],"id":48638605}],"con":true,"img":false}]}
{"op":"mcm","clk":"11450649772","pt":1717324221278,"mc":[{"id":"1.229554925","rc":[{"atb":[[48,0.52],[1.4,0]],"id":40917581}],"con":true,"img":false}]}
{"op":"mcm","clk":"11450649784","pt":1717324221379,"mc":[{"id":"1.229554925","rc":[{"atb":[[48,0.54]],"id":40917581}],"con":true,"img":false}]}
{"op":"mcm","clk":"11450649805","pt":1717324221588,"mc":[{"id":"1.229554925","rc":[{"atb":[[1.16,0.04]],"id":48638605}],"con":true,"img":false}]}
{"op":"mcm","clk":"11450649818","pt":1717324221651,"mc":[{"id":"1.229554925","rc":[{"atb":[[1.04,0]],"id":47148562},{"atl":[[1000,1]],"id":48638605}],"con":true,"img":false}]}
{"op":"mcm","clk":"11450649831","pt":1717324221757,"mc":[{"id":"1.229554925","rc":[{"atb":[[3.8,0.33]],"id":47148562},{"atl":[[46,0.02]],"id":48638605}],"con":true,"img":false}]}
{"op":"mcm","clk":"11450649843","pt":1717324221859,"mc":[{"id":"1.229554925","rc":[{"atb":[[1.03,0.24]],"id":49546922}],"con":true,"img":false}]}
{"op":"mcm","clk":"11450649893","pt":1717324222373,"mc":[{"id":"1.229554925","rc":[{"atb":[[1.16,0]],"id":48638605},{"atb":[[1.03,0]],"id":49546922}],"con":true,"img":false}]}
{"op":"mcm","clk":"11450649906","pt":1717324222476,"mc":[{"id":"1.229554925","rc":[{"atb":[[10.5,0.12]],"id":48638605},{"atb":[[3.5,0.36]],"id":49546922},{"spn":46.69,"spf":1.0,"id":40917581}],"con":true,"img":false}]}
{"op":"mcm","clk":"11450649984","pt":1717324223060,"mc":[{"id":"1.229554925","rc":[{"atb":[[10.5,0.04]],"id":48638605}],"con":true,"img":false}]}
{"op":"mcm","clk":"11450650022","pt":1717324223365,"mc":[{"id":"1.229554925","rc":[{"atl":[[46,0]],"id":48638605}],"con":true,"img":false}]}
{"op":"mcm","clk":"11450650052","pt":1717324223671,"mc":[{"id":"1.229554925","rc":[{"atb":[[1.4,1.7]],"id":64343695}],"con":true,"img":false}]}
{"op":"mcm","clk":"11450650063","pt":1717324223773,"mc":[{"id":"1.229554925","rc":[{"atb":[[1.8,1.7]],"id":40917581}],"con":true,"img":false}]}
{"op":"mcm","clk":"11450650117","pt":1717324224298,"mc":[{"id":"1.229554925","rc":[{"atb":[[18.5,0]],"id":64343695},{"atb":[[2.82,6.22]],"id":49546922}],"con":true,"img":false}]}
{"op":"mcm","clk":"11450650171","pt":1717324224667,"mc":[{"id":"1.229554925","rc":[{"atb":[[1.08,1.7]],"id":48638605},{"atl":[[1000,2.7]],"id":48638605}],"con":true,"img":false}]}
{"op":"mcm","clk":"11450650205","pt":1717324224988,"mc":[{"id":"1.229554925","rc":[{"atb":[[1.16,1.7]],"id":64343695}],"con":true,"img":false}]}
{"op":"mcm","clk":"11450650234","pt":1717324225197,"mc":[{"id":"1.229554925","rc":[{"atb":[[1.08,0.08]],"id":48638605}],"con":true,"img":false}]}
{"op":"mcm","clk":"11450650267","pt":1717324225460,"mc":[{"id":"1.229554925","rc":[{"atb":[[1.16,0.04]],"id":64343695},{"atl":[[1000,1.01]],"id":48638605}],"con":true,"img":false}]}
{"op":"mcm","clk":"11450650323","pt":1717324225985,"mc":[{"id":"1.229554925","rc":[{"atb":[[1.08,0]],"id":48638605}],"con":true,"img":false}]}
{"op":"mcm","clk":"11450650333","pt":1717324226080,"mc":[{"id":"1.229554925","rc":[{"atb":[[10.5,0.12]],"id":48638605}],"con":true,"img":false}]}
{"op":"mcm","clk":"11450650351","pt":1717324226288,"mc":[{"id":"1.229554925","rc":[{"atb":[[1.8,0]],"id":40917581}],"con":true,"img":false}]}
{"op":"mcm","clk":"11450650376","pt":1717324226456,"mc":[{"id":"1.229554925","rc":[{"atl":[[1000,1]],"id":48638605}],"con":true,"img":false}]}
{"op":"mcm","clk":"11450650386","pt":1717324226566,"mc":[{"id":"1.229554925","rc":[{"atb":[[1.4,0.01]],"id":64343695},{"atl":[[46,0.02]],"id":48638605}],"con":true,"img":false}]}
{"op":"mcm","clk":"11450650439","pt":1717324227073,"mc":[{"id":"1.229554925","rc":[{"atb":[[1.16,0]],"id":64343695}],"con":true,"img":false}]}
{"op":"mcm","clk":"11450650452","pt":1717324227186,"mc":[{"id":"1.229554925","rc":[{"atb":[[20,0.04]],"id":64343695}],"con":true,"img":false}]}
{"op":"mcm","clk":"11450650489","pt":1717324227485,"mc":[{"id":"1.229554925","rc":[{"atb":[[1.8,0]],"id":40917581}],"con":true,"img":false}]}
{"op":"mcm","clk":"11450650505","pt":1717324227589,"mc":[{"id":"1.229554925","rc":[{"atb":[[48,0.55]],"id":40917581}],"con":true,"img":false}]}
{"op":"mcm","clk":"11450650542","pt":1717324227865,"mc":[{"id":"1.229554925","rc":[{"atb":[[1.4,0]],"id":64343695}],"con":true,"img":false}]}
{"op":"mcm","clk":"11450650553","pt":1717324227968,"mc":[{"id":"1.229554925","rc":[{"atb":[[20,0.05]],"id":64343695}],"con":true,"img":false}]}
{"op":"mcm","clk":"11450651008","pt":1717324232503,"mc":[{"id":"1.229554925","rc":[{"atb":[[1.61,9.19]],"id":70003372}],"con":true,"img":false}]}
{"op":"mcm","clk":"11450651029","pt":1717324232670,"mc":[{"id":"1.229554925","rc":[{"atl":[[48,2]],"id":48638605},{"atl":[[9,0]],"id":49546922},{"atl":[[920,2]],"id":40917581}],"con":true,"img":false}]}
{"op":"mcm","clk":"11450651042","pt":1717324232776,"mc":[{"id":"1.229554925","rc":[{"atl":[[65,4.61],[46,2.64],[48,0]],"id":48638605},{"atl":[[8.4,10.23]],"id":49546922},{"atl":[[870,0.05],[920,0],[970,2]],"id":40917581}],"con":true,"img":false}]}
{"op":"mcm","clk":"11450651056","pt":1717324232879,"mc":[{"id":"1.229554925","rc":[{"atl":[[65,2.61],[100,2]],"id":48638605}],"con":true,"img":false}]}
{"op":"mcm","clk":"11450651069","pt":1717324232983,"mc":[{"id":"1.229554925","rc":[{"atl":[[46,4.64],[100,0]],"id":48638605},{"atl":[[8.2,0]],"id":49546922},{"atl":[[870,2.05],[970,0]],"id":40917581}],"con":true,"img":false}]}
{"op":"mcm","clk":"11450651079","pt":1717324233083,"mc":[{"id":"1.229554925","rc":[{"atl":[[65,4.61],[46,2.64]],"id":48638605},{"atl":[[870,0.05],[970,2]],"id":40917581}],"con":true,"img":false}]}
{"op":"mcm","clk":"11450651147","pt":1717324233706,"mc":[{"id":"1.229554925","rc":[{"atl":[[960,0.02]],"id":40917581}],"con":true,"img":false}]}
{"op":"mcm","clk":"11450651154","pt":1717324233807,"mc":[{"id":"1.229554925","rc":[{"atl":[[870,2.05],[970,0]],"id":40917581}],"con":true,"img":false}]}
{"op":"mcm","clk":"11450651162","pt":1717324233873,"mc":[{"id":"1.229554925","rc":[{"atl":[[1000,2.7]],"id":49546922}],"con":true,"img":false}]}
{"op":"mcm","clk":"11450651264","pt":1717324234906,"mc":[{"id":"1.229554925","rc":[{"atl":[[960,0]],"id":40917581}],"con":true,"img":false}]}
{"op":"mcm","clk":"11450651362","pt":1717324235800,"mc":[{"id":"1.229554925","rc":[{"atl":[[1000,1.1]],"id":49546922}],"con":true,"img":false}]}
{"op":"mcm","clk":"11450651475","pt":1717324236836,"mc":[{"id":"1.229554925","rc":[{"atl":[[1000,1]],"id":49546922}],"con":true,"img":false}]}
{"op":"mcm","clk":"11450651491","pt":1717324236941,"mc":[{"id":"1.229554925","rc":[{"atl":[[8.2,0.1]],"id":49546922}],"con":true,"img":false}]}
{"op":"mcm","clk":"11450651716","pt":1717324239047,"mc":[{"id":"1.229554925","rc":[{"atb":[[16.5,0]],"id":64343695},{"atb":[[1.67,0]],"id":70003372}],"con":true,"img":false}]}
{"op":"mcm","clk":"11450651731","pt":1717324239152,"mc":[{"id":"1.229554925","rc":[{"atb":[[17.5,3.74]],"id":64343695},{"atb":[[1.75,61.85]],"id":70003372}],"con":true,"img":false}]}
{"op":"mcm","clk":"11450653109","pt":1717324252687,"mc":[{"id":"1.229554925","rc":[{"atl":[[10.5,12.11],[14.5,0]],"id":47148562},{"atb":[[12.5,0]],"id":64343695},{"atb":[[2.7,0]],"id":49546922},{"atl":[[9.2,13.97],[12.5,0]],"id":49546922},{"atl":[[5,0]],"id":70003372},{"atb":[[32,0],[40,3.13]],"id":40917581}],"con":true,"img":false}]}
{"op":"mcm","clk":"11450653121","pt":1717324252781,"mc":[{"id":"1.229554925","rc":[{"atb":[[15,8.22]],"id":64343695},{"atb":[[2.8,75.68]],"id":49546922},{"atb":[[1.61,0]],"id":70003372},{"atl":[[4.2,32.69]],"id":70003372}],"con":true,"img":false}]}
{"op":"mcm","clk":"11450653856","pt":1717324260581,"mc":[{"id":"1.229554925","rc":[{"atb":[[3.8,7.16]],"id":47148562},{"atl":[[7.8,3.2]],"id":47148562},{"atb":[[10.5,2.23]],"id":48638605}],"con":true,"img":false}]}
{"op":"mcm","clk":"11450653871","pt":1717324260689,"mc":[{"id":"1.229554925","rc":[{"atl":[[65,2.61],[46,4.64]],"id":48638605}],"con":true,"img":false}]}
{"op":"mcm","clk":"11450654058","pt":1717324262464,"mc":[{"id":"1.229554925","rc":[{"atb":[[3.75,2]],"id":47148562},{"atb":[[10,2]],"id":48638605}],"con":true,"img":false}]}
{"op":"mcm","clk":"11450654087","pt":1717324262672,"mc":[{"id":"1.229554925","rc":[{"atl":[[870,2]],"id":40917581}],"con":true,"img":false}]}
{"op":"mcm","clk":"11450654098","pt":1717324262777,"mc":[{"id":"1.229554925","rc":[{"atl":[[860,0.05]],"id":40917581}],"con":true,"img":false}]}
{"op":"mcm","clk":"11450654115","pt":1717324262882,"mc":[{"id":"1.229554925","rc":[{"atb":[[2.82,0]],"id":49546922},{"atl":[[870,0],[970,2]],"id":40917581}],"con":true,"img":false}]}
{"op":"mcm","clk":"11450654128","pt":1717324262986,"mc":[{"id":"1.229554925","rc":[{"atl":[[860,2.05],[970,0]],"id":40917581}],"con":true,"img":false}]}
{"op":"mcm","clk":"11450654196","pt":1717324263769,"mc":[{"id":"1.229554925","rc":[{"atb":[[3.75,0]],"id":47148562}],"con":true,"img":false}]}
{"op":"mcm","clk":"11450654205","pt":1717324263871,"mc":[{"id":"1.229554925","rc":[{"atb":[[3.85,2]],"id":47148562}],"con":true,"img":false}]}
{"op":"mcm","clk":"11450654300","pt":1717324264868,"mc":[{"id":"1.229554925","rc":[{"atb":[[1.69,311.87]],"id":70003372}],"con":true,"img":false}]}
{"op":"mcm","clk":"11450654412","pt":1717324265800,"mc":[{"id":"1.229554925","rc":[{"atb":[[3.9,2.55]],"id":47148562},{"atb":[[11,2.13]],"id":48638605}],"con":true,"img":false}]}
{"op":"mcm","clk":"11450654421","pt":1717324265855,"mc":[{"id":"1.229554925","rc":[{"atb":[[11,4.13]],"id":48638605}],"con":true,"img":false}]}
{"op":"mcm","clk":"11450654437","pt":1717324265957,"mc":[{"id":"1.229554925","rc":[{"atb":[[10,0],[10.5,4.23],[11,2.13]],"id":48638605}],"con":true,"img":false}]}
{"op":"mcm","clk":"11450654448","pt":1717324266117,"mc":[{"id":"1.229554925","rc":[{"atb":[[3,0],[2.1,69.04],[3.2,0]],"id":47148562},{"atl":[[20,5.26],[12,0]],"id":47148562},{"atb":[[5.3,23.26],[19.5,0],[6.2,0]],"id":64343695},{"atl":[[260,1],[280,1],[290,0],[300,1],[320,1],[200,6.61]],"id":64343695},{"atb":[[8.2,21.65],[7.4,19.53],[7.8,11.03],[3.75,0],[8.6,8.58],[1.91,27.77]],"id":48638605},{"atl":[[70,0],[34,1.52],[38,2.03],[42,3.05],[85,2],[30,1]],"id":48638605},{"atb":[[2.8,69.86],[2.36,0],[1.32,23.28]],"id":49546922},{"atl":[[9,6.25],[10.5,7.89],[11.5,21.42],[9.4,18.99],[8.6,2.63],[9.8,5.68]],"id":49546922},{"atl":[[2.76,20.04],[3.45,0],[3.9,0]],"id":70003372}],"con":true,"img":false}]}
{"op":"mcm","clk":"11450654461","pt":1717324266270,"mc":[{"id":"1.229554925","rc":[{"atb":[[3,5.37]],"id":47148562},{"atl":[[34,3.52],[46,2.64]],"id":48638605},{"atb":[[1.87,34.87],[1.32,0]],"id":49546922},{"atl":[[11.5,11.9],[9.6,11.63]],"id":49546922}],"con":true,"img":false}]}
{"op":"mcm","clk":"11450654476","pt":1717324266381,"mc":[{"id":"1.229554925","rc":[{"atl":[[34,1.52],[46,4.64]],"id":48638605}],"con":true,"img":false}]}
{"op":"mcm","clk":"11450654483","pt":1717324266479,"mc":[{"id":"1.229554925","rc":[{"atl":[[65,4.61],[46,2.64]],"id":48638605}],"con":true,"img":false}]}
{"op":"mcm","clk":"11450654540","pt":1717324267158,"mc":[{"id":"1.229554925","rc":[{"atb":[[3.85,0]],"id":47148562}],"con":true,"img":false}]}
{"op":"mcm","clk":"11450654550","pt":1717324267265,"mc":[{"id":"1.229554925","rc":[{"atb":[[3.95,2]],"id":47148562},{"atl":[[32,0.63]],"id":48638605}],"con":true,"img":false}]}
{"op":"mcm","clk":"11450654561","pt":1717324267420,"mc":[{"id":"1.229554925","rc":[{"atl":[[46,4.64]],"id":48638605}],"con":true,"img":false}]}
{"op":"mcm","clk":"11450654574","pt":1717324267528,"mc":[{"id":"1.229554925","rc":[{"atl":[[65,2.61],[46,2.64]],"id":48638605}],"con":true,"img":false}]}
{"op":"mcm","clk":"11450654578","pt":1717324267578,"mc":[{"id":"1.229554925","rc":[{"atl":[[46,4.64]],"id":48638605}],"con":true,"img":false}]}
{"op":"mcm","clk":"11450654716","pt":1717324268784,"mc":[{"id":"1.229554925","rc":[{"atb":[[18,2.13]],"id":64343695}],"con":true,"img":false}]}
{"op":"mcm","clk":"11450654743","pt":1717324268995,"mc":[{"id":"1.229554925","rc":[{"atb":[[1.17,100]],"id":40917581}],"con":true,"img":false}]}
{"op":"mcm","clk":"11450654757","pt":1717324269101,"mc":[{"id":"1.229554925","rc":[{"atb":[[1.17,100]],"id":47148562},{"atb":[[1.17,100]],"id":64343695},{"atb":[[1.17,100]],"id":48638605},{"atb":[[1.17,100]],"id":49546922}],"con":true,"img":false}]}
{"op":"mcm","clk":"11450654886","pt":1717324270402,"mc":[{"id":"1.229554925","rc":[{"atb":[[3.9,0]],"id":47148562}],"con":true,"img":false}]}
{"op":"mcm","clk":"11450655116","pt":1717324272698,"mc":[{"id":"1.229554925","rc":[{"atl":[[8.4,3.04]],"id":49546922}],"con":true,"img":false}]}
{"op":"mcm","clk":"11450655124","pt":1717324272804,"mc":[{"id":"1.229554925","rc":[{"atl":[[8.8,7.19]],"id":49546922}],"con":true,"img":false}]}
{"op":"mcm","clk":"11450655151","pt":1717324272960,"mc":[{"id":"1.229554925","rc":[{"atl":[[28,1],[30,0]],"id":48638605},{"atl":[[10.5,0],[11.5,0]],"id":49546922}],"con":true,"img":false}]}
{"op":"mcm","clk":"11450655176","pt":1717324273173,"mc":[{"id":"1.229554925","rc":[{"atb":[[2.1,0],[2.96,174.86]],"id":47148562},{"atl":[[17,6.25],[20,0]],"id":47148562},{"atb":[[5.3,0],[6.6,17.86]],"id":64343695},{"atb":[[2.9,44.64],[1.91,0]],"id":48638605},{"atl":[[60,2],[85,0]],"id":48638605},{"atl":[[2.54,20.04],[2.76,0]],"id":70003372}],"con":true,"img":false}]}
{"op":"mcm","clk":"11450655211","pt":1717324273485,"mc":[{"id":"1.229554925","rc":[{"atb":[[4,2.55],[3.95,0]],"id":47148562}],"con":true,"img":false}]}
{"op":"mcm","clk":"11450655222","pt":1717324273588,"mc":[{"id":"1.229554925","rc":[{"atb":[[3.85,2]],"id":47148562}],"con":true,"img":false}]}
{"op":"mcm","clk":"11450656155","pt":1717324282727,"mc":[{"id":"1.229554925","rc":[{"atb":[[3.25,7.14]],"id":47148562},{"spn":5.9,"spf":"NaN","id":47148562},{"spn":18.07,"spf":1.0,"id":64343695},{"spn":11.0,"spf":1.0,"id":48638605},{"atl":[[3.65,0]],"id":70003372},{"spn":46.7,"spf":1.0,"id":40917581}],"con":true,"img":false}]}
{"op":"mcm","clk":"11450656166","pt":1717324282780,"mc":[{"id":"1.229554925","rc":[{"atb":[[3.2,27.37]],"id":47148562},{"atl":[[3.6,20.03]],"id":70003372}],"con":true,"img":false}]}
{"op":"mcm","clk":"11450656181","pt":1717324282988,"mc":[{"id":"1.229554925","rc":[{"atb":[[3.1,44.64],[2.9,0]],"id":48638605}],"con":true,"img":false}]}
{"op":"mcm","clk":"11450656252","pt":1717324283714,"mc":[{"id":"1.229554925","rc":[{"atl":[[30,1.72]],"id":48638605}],"con":true,"img":false}]}
{"op":"mcm","clk":"11450656672","pt":1717324287922,"mc":[{"id":"1.229554925","rc":[{"atb":[[1.69,302.68]],"id":70003372}],"con":true,"img":false}]}
{"op":"mcm","clk":"11450656760","pt":1717324288927,"mc":[{"id":"1.229554925","rc":[{"atb":[[4,5.5]],"id":47148562},{"atb":[[48,0.88]],"id":40917581}],"con":true,"img":false}]}
{"op":"mcm","clk":"11450656778","pt":1717324289088,"mc":[{"id":"1.229554925","rc":[{"atb":[[3.2,6.29]],"id":49546922}],"con":true,"img":false}]}
{"op":"mcm","clk":"11450656785","pt":1717324289197,"mc":[{"id":"1.229554925","rc":[{"atb":[[1.02,4.35]],"id":48638605}],"con":true,"img":false}]}
{"op":"mcm","clk":"11450656804","pt":1717324289405,"mc":[{"id":"1.229554925","rc":[{"atb":[[1.01,20.12]],"id":64343695}],"con":true,"img":false}]}
{"op":"mcm","clk":"11450656812","pt":1717324289538,"mc":[{"id":"1.229554925","rc":[{"atb":[[1.02,3.06]],"id":48638605}],"con":true,"img":false}]}
{"op":"mcm","clk":"11450656824","pt":1717324289609,"mc":[{"id":"1.229554925","rc":[{"atb":[[3.25,2.11],[2.96,0]],"id":49546922}],"con":true,"img":false}]}
{"op":"mcm","clk":"11450656835","pt":1717324289712,"mc":[{"id":"1.229554925","rc":[{"atb":[[1.01,18.41]],"id":64343695}],"con":true,"img":false}]}
{"op":"mcm","clk":"11450656846","pt":1717324289816,"mc":[{"id":"1.229554925","rc":[{"atb":[[4,11.51]],"id":47148562},{"atb":[[1.02,2]],"id":48638605}],"con":true,"img":false}]}
{"op":"mcm","clk":"11450656862","pt":1717324289975,"mc":[{"id":"1.229554925","rc":[{"atb":[[11,3.19]],"id":48638605}],"con":true,"img":false}]}
{"op":"mcm","clk":"11450656876","pt":1717324290083,"mc":[{"id":"1.229554925","rc":[{"atb":[[10.5,2.23],[11.5,2]],"id":48638605}],"con":true,"img":false}]}
{"op":"mcm","clk":"11450656890","pt":1717324290237,"mc":[{"id":"1.229554925","rc":[{"atb":[[1.01,17.76]],"id":64343695}],"con":true,"img":false}]}
{"op":"mcm","clk":"11450656899","pt":1717324290300,"mc":[{"id":"1.229554925","rc":[{"atb":[[18,2.78]],"id":64343695}],"con":true,"img":false}]}
{"op":"mcm","clk":"11450657169","pt":1717324292706,"mc":[{"id":"1.229554925","rc":[{"atl":[[860,2]],"id":40917581}],"con":true,"img":false}]}
{"op":"mcm","clk":"11450657180","pt":1717324292809,"mc":[{"id":"1.229554925","rc":[{"atl":[[850,0.05],[970,2]],"id":40917581}],"con":true,"img":false}]}
{"op":"mcm","clk":"11450657194","pt":1717324292911,"mc":[{"id":"1.229554925","rc":[{"atl":[[860,0]],"id":40917581}],"con":true,"img":false}]}
