{"op":"mcm","clk":"11448351865","pt":1717289088271,"mc":[{"id":"1.229554934","marketDefinition":{"bspMarket":false,"turnInPlayEnabled":false,"persistenceEnabled":false,"marketBaseRate":7.0,"eventId":"33318908","eventTypeId":"4339","numberOfWinners":1,"bettingType":"ODDS","marketType":"MATCH_BET","marketTime":"2024-06-02T11:02:00.000Z","suspendTime":"2024-06-02T11:02:00.000Z","bspReconciled":false,"complete":true,"inPlay":false,"crossMatching":true,"runnersVoidable":false,"numberOfActiveRunners":2,"betDelay":0,"status":"OPEN","runners":[{"status":"ACTIVE","sortPriority":1,"id":47530316,"name":"1. Balonne Boy"},{"status":"ACTIVE","sortPriority":2,"id":65894825,"name":"4. Shipway"}],"regulators":["MR_INT"],"venue":"Murray Bridge","countryCode":"AU","discountAllowed":true,"timezone":"Australia/Adelaide","openDate":"2024-06-02T08:21:00.000Z","version":5962433794,"name":"Balonne Boy v Shipway","eventName":"Murray Bridge (AUS) 2nd Jun"},"rc":[],"con":true,"img":false}]}
{"op":"mcm","clk":"11448366403","pt":1717289278043,"mc":[{"id":"1.229554934","rc":[{"atb":[[1.79,9.93],[1.69,11.37]],"id":47530316},{"atb":[[1.84,9.34],[1.94,8.34]],"id":65894825}],"con":true,"img":false}]}
{"op":"mcm","clk":"11449358024","pt":1717307826134,"mc":[{"id":"1.229554934","rc":[{"atb":[[1.01,17.76]],"id":47530316},{"atl":[[1000,0.85]],"id":47530316},{"atb":[[1.02,8.87]],"id":65894825},{"atl":[[990,0.85]],"id":65894825}],"con":true,"img":false}]}
{"op":"mcm","clk":"11449585866","pt":1717311429079,"mc":[{"id":"1.229554934","rc":[{"atl":[[1000,0.17]],"id":47530316},{"atl":[[990,0.17]],"id":65894825}],"con":true,"img":false}]}
{"op":"mcm","clk":"11449624324","pt":1717312169412,"mc":[{"id":"1.229554934","rc":[{"atb":[[1.79,0],[1.69,0]],"id":47530316},{"atb":[[1.84,0],[1.94,0]],"id":65894825}],"con":true,"img":false}]}
{"op":"mcm","clk":"11449624998","pt":1717312185760,"mc":[{"id":"1.229554934","rc":[{"atb":[[1.79,9.93],[1.69,11.37]],"id":47530316},{"atb":[[1.84,9.34],[1.94,8.34]],"id":65894825}],"con":true,"img":false}]}
{"op":"mcm","clk":"11449626456","pt":1717312220693,"mc":[{"id":"1.229554934","rc":[{"atb":[[1.79,0],[1.69,0]],"id":47530316},{"atb":[[1.84,0],[1.94,0]],"id":65894825}],"con":true,"img":false}]}
{"op":"mcm","clk":"11449626906","pt":1717312229610,"mc":[{"id":"1.229554934","rc":[{"atb":[[1.79,9.93],[1.69,11.37]],"id":47530316},{"atb":[[1.84,9.34],[1.94,8.34]],"id":65894825}],"con":true,"img":false}]}
{"op":"mcm","clk":"11449862846","pt":1717315412340,"mc":[{"id":"1.229554934","rc":[{"atb":[[1.79,0],[1.69,0]],"id":47530316},{"atb":[[1.84,0],[1.94,0]],"id":65894825}],"con":true,"img":false}]}
{"op":"mcm","clk":"11449866531","pt":1717315447341,"mc":[{"id":"1.229554934","rc":[{"atb":[[1.79,9.93],[1.69,11.37]],"id":47530316},{"atb":[[1.84,9.34],[1.94,8.34]],"id":65894825}],"con":true,"img":false}]}
{"op":"mcm","clk":"11449874242","pt":1717315519850,"mc":[{"id":"1.229554934","rc":[{"atb":[[1.79,0],[1.69,0]],"id":47530316},{"atb":[[1.84,0],[1.94,0]],"id":65894825}],"con":true,"img":false}]}
{"op":"mcm","clk":"11449875277","pt":1717315530484,"mc":[{"id":"1.229554934","rc":[{"atb":[[1.75,10.46],[1.65,12.07]],"id":47530316},{"atb":[[1.97,8.08],[1.87,9.01]],"id":65894825}],"con":true,"img":false}]}
{"op":"mcm","clk":"11449970527","pt":1717316552974,"mc":[{"id":"1.229554934","rc":[{"atb":[[1.75,0],[1.65,0]],"id":47530316},{"atb":[[1.97,0],[1.87,0]],"id":65894825}],"con":true,"img":false}]}
{"op":"mcm","clk":"11449971658","pt":1717316571125,"mc":[{"id":"1.229554934","rc":[{"atb":[[1.75,10.46],[1.65,12.07]],"id":47530316},{"atb":[[1.97,8.08],[1.87,9.01]],"id":65894825}],"con":true,"img":false}]}
{"op":"mcm","clk":"11450068130","pt":1717317644469,"mc":[{"id":"1.229554934","rc":[{"atb":[[1.75,0],[1.65,0]],"id":47530316},{"atb":[[1.97,0],[1.87,0]],"id":65894825}],"con":true,"img":false}]}
{"op":"mcm","clk":"11450071068","pt":1717317675988,"mc":[{"id":"1.229554934","rc":[{"atb":[[1.75,10.46],[1.65,12.07]],"id":47530316},{"atb":[[1.97,8.08],[1.87,9.01]],"id":65894825}],"con":true,"img":false}]}
{"op":"mcm","clk":"11450128184","pt":1717318324261,"mc":[{"id":"1.229554934","rc":[{"atb":[[1.75,0],[1.65,0]],"id":47530316},{"atb":[[1.97,0],[1.87,0]],"id":65894825}],"con":true,"img":false}]}
{"op":"mcm","clk":"11450129268","pt":1717318336095,"mc":[{"id":"1.229554934","rc":[{"atb":[[1.72,10.89],[1.62,12.65]],"id":47530316},{"atb":[[1.98,8],[1.88,8.92]],"id":65894825}],"con":true,"img":false}]}
{"op":"mcm","clk":"11450133842","pt":1717318390322,"mc":[{"id":"1.229554934","rc":[{"atb":[[1.72,0],[1.62,0]],"id":47530316},{"atb":[[1.98,0],[1.88,0]],"id":65894825}],"con":true,"img":false}]}
{"op":"mcm","clk":"11450134730","pt":1717318401243,"mc":[{"id":"1.229554934","rc":[{"atb":[[1.73,10.75],[1.63,12.45]],"id":47530316},{"atb":[[1.98,8],[1.88,8.92]],"id":65894825}],"con":true,"img":false}]}
{"op":"mcm","clk":"11450164697","pt":1717318724600,"mc":[{"id":"1.229554934","rc":[{"atb":[[1.73,0],[1.63,0]],"id":47530316},{"atb":[[1.98,0],[1.88,0]],"id":65894825}],"con":true,"img":false}]}
{"op":"mcm","clk":"11450166303","pt":1717318742709,"mc":[{"id":"1.229554934","rc":[{"atb":[[1.73,10.75],[1.63,12.45]],"id":47530316},{"atb":[[1.98,8],[1.88,8.92]],"id":65894825}],"con":true,"img":false}]}
{"op":"mcm","clk":"11450246467","pt":1717319582903,"mc":[{"id":"1.229554934","rc":[{"atb":[[1.73,0],[1.63,0]],"id":47530316},{"atb":[[1.98,0],[1.88,0]],"id":65894825}],"con":true,"img":false}]}
{"op":"mcm","clk":"11450247605","pt":1717319595636,"mc":[{"id":"1.229554934","rc":[{"atb":[[1.73,10.75],[1.63,12.45]],"id":47530316},{"atb":[[1.98,8],[1.88,8.92]],"id":65894825}],"con":true,"img":false}]}
{"op":"mcm","clk":"11450308144","pt":1717320400600,"mc":[{"id":"1.229554934","rc":[{"atb":[[1.73,0],[1.63,0]],"id":47530316},{"atb":[[1.98,0],[1.88,0]],"id":65894825}],"con":true,"img":false}]}
{"op":"mcm","clk":"11450308808","pt":1717320410992,"mc":[{"id":"1.229554934","rc":[{"atb":[[1.73,10.75],[1.63,12.45]],"id":47530316},{"atb":[[1.98,8],[1.88,8.92]],"id":65894825}],"con":true,"img":false}]}
{"op":"mcm","clk":"11450324812","pt":1717320549962,"mc":[{"id":"1.229554934","rc":[{"atb":[[1.73,0],[1.63,0]],"id":47530316},{"atb":[[1.98,0],[1.88,0]],"id":65894825}],"con":true,"img":false}]}
{"op":"mcm","clk":"11450326232","pt":1717320567665,"mc":[{"id":"1.229554934","rc":[{"atb":[[1.6,13.07],[1.5,15.69]],"id":47530316},{"atb":[[1.99,7.92],[2.18,6.64]],"id":65894825}],"con":true,"img":false}]}
{"op":"mcm","clk":"11450328982","pt":1717320605069,"mc":[{"id":"1.229554934","rc":[{"atb":[[1.6,0],[1.5,0]],"id":47530316},{"atb":[[1.99,0],[2.18,0]],"id":65894825}],"con":true,"img":false}]}
{"op":"mcm","clk":"11450330398","pt":1717320623597,"mc":[{"id":"1.229554934","rc":[{"atb":[[1.58,13.52],[1.48,16.34]],"id":47530316},{"atb":[[2,7.84],[2.2,6.53]],"id":65894825}],"con":true,"img":false}]}
{"op":"mcm","clk":"11450333315","pt":1717320660844,"mc":[{"id":"1.229554934","rc":[{"atb":[[1.58,0],[1.48,0]],"id":47530316},{"atb":[[2,0],[2.2,0]],"id":65894825}],"con":true,"img":false}]}
{"op":"mcm","clk":"11450334351","pt":1717320673955,"mc":[{"id":"1.229554934","rc":[{"atb":[[1.58,13.52],[1.48,16.34]],"id":47530316},{"atb":[[2,7.84],[2.2,6.53]],"id":65894825}],"con":true,"img":false}]}
{"op":"mcm","clk":"11450379303","pt":1717321268136,"mc":[{"id":"1.229554934","rc":[{"atb":[[1.58,0],[1.48,0]],"id":47530316},{"atb":[[2,0],[2.2,0]],"id":65894825}],"con":true,"img":false}]}
{"op":"mcm","clk":"11450380285","pt":1717321281946,"mc":[{"id":"1.229554934","rc":[{"atb":[[1.58,13.52],[1.48,16.34]],"id":47530316},{"atb":[[2,7.84],[2.2,6.53]],"id":65894825}],"con":true,"img":false}]}
{"op":"mcm","clk":"11450445397","pt":1717322128282,"mc":[{"id":"1.229554934","rc":[{"atb":[[1.58,27.05],[1.48,32.69]],"id":47530316},{"atb":[[2,15.69],[2.2,13.07]],"id":65894825}],"con":true,"img":false}]}
{"op":"mcm","clk":"11450480572","pt":1717322520487,"mc":[{"id":"1.229554934","rc":[{"atb":[[1.26,59.76]],"id":47530316},{"atl":[[5.6,2]],"id":47530316},{"atb":[[1.22,28.78]],"id":65894825},{"atl":[[7.4,2]],"id":65894825}],"con":true,"img":false}]}
{"op":"mcm","clk":"11450480581","pt":1717322520608,"mc":[{"id":"1.229554934","rc":[{"atl":[[2.24,16.13],[2.32,22.73],[2.28,19.53],[2.2,12.5]],"id":47530316},{"atl":[[3.45,12.24],[3.35,10.64],[3.15,6.98],[3.25,8.89]],"id":65894825}],"con":true,"img":false}]}
{"op":"mcm","clk":"11450480591","pt":1717322520708,"mc":[{"id":"1.229554934","rc":[{"atb":[[1.28,28.78],[1.22,0]],"id":65894825},{"atl":[[3.35,26.51],[7.4,0]],"id":65894825}],"con":true,"img":false}]}
{"op":"mcm","clk":"11450483411","pt":1717322557675,"mc":[{"id":"1.229554934","rc":[{"atb":[[1.26,0],[1.32,59.76]],"id":47530316},{"atl":[[5.6,0],[2.92,35.66]],"id":47530316}],"con":true,"img":false}]}
{"op":"mcm","clk":"11450490356","pt":1717322639593,"mc":[{"id":"1.229554934","rc":[{"atb":[[1.58,13.52],[1.48,16.34]],"id":47530316},{"atb":[[2,7.84],[2.2,6.53]],"id":65894825}],"con":true,"img":false}]}
{"op":"mcm","clk":"11450491173","pt":1717322647806,"mc":[{"id":"1.229554934","rc":[{"atl":[[2.92,0],[2.74,35.66]],"id":47530316},{"atb":[[1.28,0],[1.33,18.83]],"id":65894825}],"con":true,"img":false}]}
{"op":"mcm","clk":"11450491510","pt":1717322651899,"mc":[{"id":"1.229554934","rc":[{"atb":[[1.58,27.05],[1.48,32.69]],"id":47530316},{"atb":[[2,15.69],[2.2,13.07]],"id":65894825}],"con":true,"img":false}]}
{"op":"mcm","clk":"11450502419","pt":1717322770794,"mc":[{"id":"1.229554934","rc":[{"atl":[[2.92,39.06],[2.74,0]],"id":47530316}],"con":true,"img":false}]}
{"op":"mcm","clk":"11450526067","pt":1717323010311,"mc":[{"id":"1.229554934","rc":[{"atb":[[1.58,13.52],[1.48,16.34]],"id":47530316},{"atb":[[2,7.84],[2.2,6.53]],"id":65894825}],"con":true,"img":false}]}
{"op":"mcm","clk":"11450526527","pt":1717323015330,"mc":[{"id":"1.229554934","rc":[{"atl":[[3.15,0],[3.25,6.67]],"id":65894825}],"con":true,"img":false}]}
{"op":"mcm","clk":"11450526537","pt":1717323015435,"mc":[{"id":"1.229554934","rc":[{"atl":[[3.45,45.42]],"id":65894825}],"con":true,"img":false}]}
{"op":"mcm","clk":"11450526553","pt":1717323015539,"mc":[{"id":"1.229554934","rc":[{"atl":[[3.35,10.64]],"id":65894825}],"con":true,"img":false}]}
{"op":"mcm","clk":"11450527424","pt":1717323023843,"mc":[{"id":"1.229554934","rc":[{"atb":[[1.58,27.05],[1.48,32.69]],"id":47530316},{"atb":[[2,15.69],[2.2,13.07]],"id":65894825}],"con":true,"img":false}]}
{"op":"mcm","clk":"11450527581","pt":1717323025345,"mc":[{"id":"1.229554934","rc":[{"atl":[[3.35,19.15]],"id":65894825}],"con":true,"img":false}]}
{"op":"mcm","clk":"11450527592","pt":1717323025448,"mc":[{"id":"1.229554934","rc":[{"atl":[[3.35,8.51]],"id":65894825}],"con":true,"img":false}]}
{"op":"mcm","clk":"11450528595","pt":1717323035369,"mc":[{"id":"1.229554934","rc":[{"atl":[[3.45,55.62]],"id":65894825}],"con":true,"img":false}]}
{"op":"mcm","clk":"11450528605","pt":1717323035476,"mc":[{"id":"1.229554934","rc":[{"atl":[[3.45,43.38]],"id":65894825}],"con":true,"img":false}]}
{"op":"mcm","clk":"11450529616","pt":1717323045380,"mc":[{"id":"1.229554934","rc":[{"atl":[[3.55,11.76]],"id":65894825}],"con":true,"img":false}]}
{"op":"mcm","clk":"11450561742","pt":1717323343776,"mc":[{"id":"1.229554934","rc":[{"atb":[[1.58,13.52],[1.48,16.34]],"id":47530316},{"atb":[[2,7.84],[2.2,6.53]],"id":65894825}],"con":true,"img":false}]}
{"op":"mcm","clk":"11450563440","pt":1717323359137,"mc":[{"id":"1.229554934","rc":[{"atb":[[1.58,27.05],[1.48,32.69]],"id":47530316},{"atb":[[2,15.69],[2.2,13.07]],"id":65894825}],"con":true,"img":false}]}
{"op":"mcm","clk":"11450598085","pt":1717323680285,"mc":[{"id":"1.229554934","rc":[{"atb":[[1.58,13.52],[1.48,16.34]],"id":47530316},{"atb":[[2,7.84],[2.2,6.53]],"id":65894825}],"con":true,"img":false}]}
{"op":"mcm","clk":"11450599076","pt":1717323691709,"mc":[{"id":"1.229554934","rc":[{"atb":[[1.58,27.05],[1.48,32.69]],"id":47530316},{"atb":[[2,15.69],[2.2,13.07]],"id":65894825}],"con":true,"img":false}]}
{"op":"mcm","clk":"11450614276","pt":1717323847517,"mc":[{"id":"1.229554934","rc":[{"atl":[[2.92,0],[2.74,35.66]],"id":47530316}],"con":true,"img":false}]}
{"op":"mcm","clk":"11450626477","pt":1717323970067,"mc":[{"id":"1.229554934","rc":[{"atl":[[2.92,39.06],[2.74,0]],"id":47530316}],"con":true,"img":false}]}
{"op":"mcm","clk":"11450632145","pt":1717324032453,"mc":[{"id":"1.229554934","rc":[{"atb":[[1.58,13.52],[1.48,16.34]],"id":47530316},{"atb":[[2,7.84],[2.2,6.53]],"id":65894825}],"con":true,"img":false}]}
{"op":"mcm","clk":"11450633144","pt":1717324044547,"mc":[{"id":"1.229554934","rc":[{"atb":[[1.58,27.05],[1.48,32.69]],"id":47530316},{"atb":[[2,15.69],[2.2,13.07]],"id":65894825}],"con":true,"img":false}]}
{"op":"mcm","clk":"11450666060","pt":1717324370760,"mc":[{"id":"1.229554934","rc":[{"atb":[[1.58,13.52],[1.48,16.34]],"id":47530316},{"atb":[[2,7.84],[2.2,6.53]],"id":65894825}],"con":true,"img":false}]}
{"op":"mcm","clk":"11450667829","pt":1717324387198,"mc":[{"id":"1.229554934","rc":[{"atb":[[1.58,27.05],[1.48,32.69]],"id":47530316},{"atb":[[2,15.69],[2.2,13.07]],"id":65894825}],"con":true,"img":false}]}
{"op":"mcm","clk":"11450705818","pt":1717324712427,"mc":[{"id":"1.229554934","rc":[{"atb":[[1.58,13.52],[1.48,16.34]],"id":47530316},{"atb":[[2,7.84],[2.2,6.53]],"id":65894825}],"con":true,"img":false}]}
{"op":"mcm","clk":"11450707053","pt":1717324725487,"mc":[{"id":"1.229554934","rc":[{"atb":[[1.58,27.05],[1.48,32.69]],"id":47530316},{"atb":[[2,15.69],[2.2,13.07]],"id":65894825}],"con":true,"img":false}]}
{"op":"mcm","clk":"11450737351","pt":1717325034410,"mc":[{"id":"1.229554934","rc":[{"atb":[[1.58,13.52],[1.48,16.34]],"id":47530316},{"atb":[[2,7.84],[2.2,6.53]],"id":65894825}],"con":true,"img":false}]}
{"op":"mcm","clk":"11450738342","pt":1717325044990,"mc":[{"id":"1.229554934","rc":[{"atb":[[1.58,27.05],[1.48,32.69]],"id":47530316},{"atb":[[2,15.69],[2.2,13.07]],"id":65894825}],"con":true,"img":false}]}
{"op":"mcm","clk":"11450754118","pt":1717325204754,"mc":[{"id":"1.229554934","rc":[{"atb":[[1.59,2]],"id":47530316},{"atl":[[2.92,0],[2.74,35.66],[2.28,21.53]],"id":47530316},{"atb":[[1.85,2]],"id":65894825},{"atl":[[3,2]],"id":65894825}],"con":true,"img":false}]}
{"op":"mcm","clk":"11450754129","pt":1717325204859,"mc":[{"id":"1.229554934","rc":[{"atl":[[3.2,8.51]],"id":65894825}],"con":true,"img":false}]}
{"op":"mcm","clk":"11450754139","pt":1717325204918,"mc":[{"id":"1.229554934","rc":[{"atl":[[3.45,10.2],[3.2,0],[3.35,20.27]],"id":65894825}],"con":true,"img":false}]}
{"op":"mcm","clk":"11450754148","pt":1717325205029,"mc":[{"id":"1.229554934","rc":[{"atl":[[3.35,8.51],[3.25,17.18]],"id":65894825}],"con":true,"img":false}]}
{"op":"mcm","clk":"11450756655","pt":1717325229543,"mc":[{"id":"1.229554934","rc":[{"atl":[[3,0],[2.98,2]],"id":65894825}],"con":true,"img":false}]}
{"op":"mcm","clk":"11450756666","pt":1717325229648,"mc":[{"id":"1.229554934","rc":[{"atl":[[3.2,10.2],[3.25,6.67]],"id":65894825}],"con":true,"img":false}]}
{"op":"mcm","clk":"11450756673","pt":1717325229750,"mc":[{"id":"1.229554934","rc":[{"atl":[[3.2,0],[3.25,18.87]],"id":65894825}],"con":true,"img":false}]}
{"op":"mcm","clk":"11450756721","pt":1717325230269,"mc":[{"id":"1.229554934","rc":[{"atl":[[3,2],[2.98,0]],"id":65894825}],"con":true,"img":false}]}
{"op":"mcm","clk":"11450758182","pt":1717325243206,"mc":[{"id":"1.229554934","rc":[{"atb":[[1.58,13.52],[1.48,16.34]],"id":47530316},{"atb":[[2,7.84],[2.2,6.53]],"id":65894825}],"con":true,"img":false}]}
{"op":"mcm","clk":"11450758835","pt":1717325249817,"mc":[{"id":"1.229554934","rc":[{"atb":[[1.58,27.05],[1.48,32.69]],"id":47530316},{"atb":[[2,15.69],[2.2,13.07]],"id":65894825}],"con":true,"img":false}]}
{"op":"mcm","clk":"11450762410","pt":1717325283848,"mc":[{"id":"1.229554934","rc":[{"atl":[[3,0],[3.05,2]],"id":65894825}],"con":true,"img":false}]}
{"op":"mcm","clk":"11450762442","pt":1717325284054,"mc":[{"id":"1.229554934","rc":[{"atl":[[3.35,29.38],[3.25,6.67]],"id":65894825}],"con":true,"img":false}]}
{"op":"mcm","clk":"11450762871","pt":1717325287943,"mc":[{"id":"1.229554934","rc":[{"atl":[[3,2],[3.05,0]],"id":65894825}],"con":true,"img":false}]}
{"op":"mcm","clk":"11450762883","pt":1717325288046,"mc":[{"id":"1.229554934","rc":[{"atl":[[3.35,8.51],[3.25,16.87]],"id":65894825}],"con":true,"img":false}]}
{"op":"mcm","clk":"11450762897","pt":1717325288252,"mc":[{"id":"1.229554934","rc":[{"atl":[[3,0],[3.05,2]],"id":65894825}],"con":true,"img":false}]}
{"op":"mcm","clk":"11450763419","pt":1717325293144,"mc":[{"id":"1.229554934","rc":[{"atl":[[3.35,27.38],[3.25,6.67]],"id":65894825}],"con":true,"img":false}]}
{"op":"mcm","clk":"11450765051","pt":1717325307784,"mc":[{"id":"1.229554934","rc":[{"atl":[[3,2],[3.05,0]],"id":65894825}],"con":true,"img":false}]}
{"op":"mcm","clk":"11450765063","pt":1717325307886,"mc":[{"id":"1.229554934","rc":[{"atl":[[3.35,8.51],[3.25,16.87]],"id":65894825}],"con":true,"img":false}]}
{"op":"mcm","clk":"11450765603","pt":1717325312912,"mc":[{"id":"1.229554934","rc":[{"atl":[[3,0],[3.05,2]],"id":65894825}],"con":true,"img":false}]}
{"op":"mcm","clk":"11450765618","pt":1717325312970,"mc":[{"id":"1.229554934","rc":[{"atl":[[3.35,27.38]],"id":65894825}],"con":true,"img":false}]}
{"op":"mcm","clk":"11450765630","pt":1717325313082,"mc":[{"id":"1.229554934","rc":[{"atl":[[3.25,6.67]],"id":65894825}],"con":true,"img":false}]}
{"op":"mcm","clk":"11450766125","pt":1717325317589,"mc":[{"id":"1.229554934","rc":[{"atl":[[3,2],[3.05,0]],"id":65894825}],"con":true,"img":false}]}
{"op":"mcm","clk":"11450766135","pt":1717325317683,"mc":[{"id":"1.229554934","rc":[{"atl":[[3.35,8.51],[3.25,16.87]],"id":65894825}],"con":true,"img":false}]}
{"op":"mcm","clk":"11450766237","pt":1717325318576,"mc":[{"id":"1.229554934","rc":[{"atl":[[3,0],[3.05,2]],"id":65894825}],"con":true,"img":false}]}
{"op":"mcm","clk":"11450766255","pt":1717325318720,"mc":[{"id":"1.229554934","rc":[{"atl":[[3.35,27.38],[3.25,6.67]],"id":65894825}],"con":true,"img":false}]}
{"op":"mcm","clk":"11450766939","pt":1717325324717,"mc":[{"id":"1.229554934","rc":[{"atl":[[2.86,43.06]],"id":47530316}],"con":true,"img":false}]}
{"op":"mcm","clk":"11450766956","pt":1717325324821,"mc":[{"id":"1.229554934","rc":[{"atl":[[2.74,0]],"id":47530316}],"con":true,"img":false}]}
{"op":"mcm","clk":"11450767143","pt":1717325326421,"mc":[{"id":"1.229554934","rc":[{"atl":[[3,2]],"id":65894825}],"con":true,"img":false}]}
{"op":"mcm","clk":"11450767154","pt":1717325326525,"mc":[{"id":"1.229554934","rc":[{"atl":[[3.05,0]],"id":65894825}],"con":true,"img":false}]}
{"op":"mcm","clk":"11450767207","pt":1717325327001,"mc":[{"id":"1.229554934","rc":[{"atl":[[3,0],[3.05,2]],"id":65894825}],"con":true,"img":false}]}
{"op":"mcm","clk":"11450767226","pt":1717325327104,"mc":[{"id":"1.229554934","rc":[{"atl":[[3.35,8.51],[3.4,13.34]],"id":65894825}],"con":true,"img":false}]}
{"op":"mcm","clk":"11450768083","pt":1717325335722,"mc":[{"id":"1.229554934","rc":[{"atl":[[3,2],[3.05,0]],"id":65894825}],"con":true,"img":false}]}
{"op":"mcm","clk":"11450768267","pt":1717325337734,"mc":[{"id":"1.229554934","rc":[{"atb":[[1.58,13.52],[1.48,16.34]],"id":47530316},{"atb":[[2,7.84],[2.2,6.53]],"id":65894825}],"con":true,"img":false}]}
{"op":"mcm","clk":"11450768600","pt":1717325340826,"mc":[{"id":"1.229554934","rc":[{"atl":[[3,0],[3.05,2]],"id":65894825}],"con":true,"img":false}]}
{"op":"mcm","clk":"11450768741","pt":1717325342063,"mc":[{"id":"1.229554934","rc":[{"atb":[[1.59,0]],"id":47530316},{"atl":[[2.28,19.53]],"id":47530316},{"atb":[[1.85,0]],"id":65894825},{"atl":[[3.05,0]],"id":65894825}],"con":true,"img":false}]}
{"op":"mcm","clk":"11450768810","pt":1717325342538,"mc":[{"id":"1.229554934","rc":[{"atb":[[1.58,27.05],[1.48,32.69]],"id":47530316},{"atb":[[2,15.69],[2.2,13.07]],"id":65894825}],"con":true,"img":false}]}
{"op":"mcm","clk":"11450775285","pt":1717325401078,"mc":[{"id":"1.229554934","rc":[{"atl":[[2.2,0],[2.16,12.93]],"id":47530316}],"con":true,"img":false}]}
{"op":"mcm","clk":"11450776288","pt":1717325409303,"mc":[{"id":"1.229554934","rc":[{"atl":[[3.25,0],[3.3,6.52]],"id":65894825}],"con":true,"img":false}]}
{"op":"mcm","clk":"11450776481","pt":1717325411118,"mc":[{"id":"1.229554934","rc":[{"atl":[[2.2,16.67]],"id":47530316}],"con":true,"img":false}]}
{"op":"mcm","clk":"11450777436","pt":1717325418605,"mc":[{"id":"1.229554934","rc":[{"atl":[[2.32,0]],"id":47530316}],"con":true,"img":false}]}
{"op":"mcm","clk":"11450778122","pt":1717325424428,"mc":[{"id":"1.229554934","rc":[{"atl":[[3.25,6.67]],"id":65894825}],"con":true,"img":false}]}
{"op":"mcm","clk":"11450778134","pt":1717325424529,"mc":[{"id":"1.229554934","rc":[{"atl":[[3.3,0]],"id":65894825}],"con":true,"img":false}]}
{"op":"mcm","clk":"11450778798","pt":1717325430914,"mc":[{"id":"1.229554934","rc":[{"atb":[[1.58,13.52],[1.48,16.34]],"id":47530316},{"atb":[[2,7.84],[2.2,6.53]],"id":65894825}],"con":true,"img":false}]}
{"op":"mcm","clk":"11450779168","pt":1717325434437,"mc":[{"id":"1.229554934","rc":[{"atb":[[1.58,27.05],[1.48,32.69]],"id":47530316},{"atb":[[2,15.69],[2.2,13.07]],"id":65894825}],"con":true,"img":false}]}
{"op":"mcm","clk":"11450779949","pt":1717325441960,"mc":[{"id":"1.229554934","rc":[{"atb":[[1.58,13.52],[1.48,16.34]],"id":47530316},{"atb":[[2,7.84],[2.2,6.53]],"id":65894825}],"con":true,"img":false}]}
{"op":"mcm","clk":"11450780637","pt":1717325448239,"mc":[{"id":"1.229554934","rc":[{"atb":[[1.58,27.05],[1.48,32.69]],"id":47530316},{"atb":[[2,15.69],[2.2,13.07]],"id":65894825}],"con":true,"img":false}]}
{"op":"mcm","clk":"11450785228","pt":1717325491062,"mc":[{"id":"1.229554934","rc":[{"atl":[[2.2,29.17]],"id":47530316}],"con":true,"img":false}]}
{"op":"mcm","clk":"11450785235","pt":1717325491158,"mc":[{"id":"1.229554934","rc":[{"atl":[[2.2,12.49],[2.16,0]],"id":47530316}],"con":true,"img":false}]}
{"op":"mcm","clk":"11450786341","pt":1717325501105,"mc":[{"id":"1.229554934","rc":[{"atl":[[2.32,22.73]],"id":47530316}],"con":true,"img":false}]}
{"op":"mcm","clk":"11450790304","pt":1717325536630,"mc":[{"id":"1.229554934","rc":[{"atb":[[1.58,13.52],[1.48,16.34]],"id":47530316},{"atb":[[2,7.84],[2.2,6.53]],"id":65894825}],"con":true,"img":false}]}
{"op":"mcm","clk":"11450791157","pt":1717325544324,"mc":[{"id":"1.229554934","rc":[{"atb":[[1.58,27.05],[1.48,32.69]],"id":47530316},{"atb":[[2,15.69],[2.2,13.07]],"id":65894825}],"con":true,"img":false}]}
{"op":"mcm","clk":"11450792673","pt":1717325557629,"mc":[{"id":"1.229554934","rc":[{"atl":[[2.18,12.71],[2.2,0],[2.16,12.93]],"id":47530316}],"con":true,"img":false}]}
{"op":"mcm","clk":"11450792698","pt":1717325557835,"mc":[{"id":"1.229554934","rc":[{"atl":[[2.32,0],[2.18,0]],"id":47530316}],"con":true,"img":false}]}
{"op":"mcm","clk":"11450793946","pt":1717325568044,"mc":[{"id":"1.229554934","rc":[{"atl":[[2.2,16.67]],"id":47530316}],"con":true,"img":false}]}
{"op":"mcm","clk":"11450800411","pt":1717325627565,"mc":[{"id":"1.229554934","rc":[{"atb":[[1.58,13.52],[1.48,16.34]],"id":47530316},{"atb":[[2,7.84],[2.2,6.53]],"id":65894825}],"con":true,"img":false}]}
{"op":"mcm","clk":"11450801046","pt":1717325633458,"mc":[{"id":"1.229554934","rc":[{"atb":[[1.58,27.05],[1.48,32.69]],"id":47530316},{"atb":[[2,15.69],[2.2,13.07]],"id":65894825}],"con":true,"img":false}]}
{"op":"mcm","clk":"11450804185","pt":1717325661489,"mc":[{"id":"1.229554934","rc":[{"atl":[[3.35,6.38],[3.25,0]],"id":65894825}],"con":true,"img":false}]}
{"op":"mcm","clk":"11450804196","pt":1717325661592,"mc":[{"id":"1.229554934","rc":[{"atl":[[3.45,29.92]],"id":65894825}],"con":true,"img":false}]}
{"op":"mcm","clk":"11450804210","pt":1717325661694,"mc":[{"id":"1.229554934","rc":[{"atl":[[3.4,0]],"id":65894825}],"con":true,"img":false}]}
{"op":"mcm","clk":"11450804218","pt":1717325661795,"mc":[{"id":"1.229554934","rc":[{"atl":[[3.55,48.06]],"id":65894825}],"con":true,"img":false}]}
{"op":"mcm","clk":"11450804230","pt":1717325661896,"mc":[{"id":"1.229554934","rc":[{"atl":[[3.45,10.2]],"id":65894825}],"con":true,"img":false}]}
{"op":"mcm","clk":"11450804260","pt":1717325662206,"mc":[{"id":"1.229554934","rc":[{"atl":[[3.25,6.67]],"id":65894825}],"con":true,"img":false}]}
{"op":"mcm","clk":"11450804275","pt":1717325662262,"mc":[{"id":"1.229554934","rc":[{"atl":[[3.45,22.96],[3.55,11.76]],"id":65894825}],"con":true,"img":false}]}
{"op":"mcm","clk":"11450804363","pt":1717325663093,"mc":[{"id":"1.229554934","rc":[{"atl":[[3.25,0]],"id":65894825}],"con":true,"img":false}]}
{"op":"mcm","clk":"11450804477","pt":1717325664071,"mc":[{"id":"1.229554934","rc":[{"atl":[[3.25,6.67]],"id":65894825}],"con":true,"img":false}]}
{"op":"mcm","clk":"11450804895","pt":1717325668104,"mc":[{"id":"1.229554934","rc":[{"atl":[[3.25,0]],"id":65894825}],"con":true,"img":false}]}
{"op":"mcm","clk":"11450804903","pt":1717325668204,"mc":[{"id":"1.229554934","rc":[{"atb":[[1.59,2]],"id":47530316},{"atl":[[2.86,0],[2.22,2],[2.12,13.39],[2.66,32.8],[2.16,0],[2.14,13.16]],"id":47530316},{"atb":[[1.4,28.78],[1.88,2],[1.33,0]],"id":65894825},{"atl":[[3.1,2]],"id":65894825}],"con":true,"img":false}]}
{"op":"mcm","clk":"11450804911","pt":1717325668312,"mc":[{"id":"1.229554934","rc":[{"atl":[[3.45,10.2],[3.55,41.1]],"id":65894825}],"con":true,"img":false}]}
{"op":"mcm","clk":"11450805088","pt":1717325669917,"mc":[{"id":"1.229554934","rc":[{"atl":[[2.24,0],[2.12,0],[2.28,0],[2.2,0]],"id":47530316}],"con":true,"img":false}]}
{"op":"mcm","clk":"11450805097","pt":1717325670022,"mc":[{"id":"1.229554934","rc":[{"atl":[[3.25,6.67]],"id":65894825}],"con":true,"img":false}]}
{"op":"mcm","clk":"11450805346","pt":1717325672309,"mc":[{"id":"1.229554934","rc":[{"atl":[[3.25,0]],"id":65894825}],"con":true,"img":false}]}
{"op":"mcm","clk":"11450805466","pt":1717325673308,"mc":[{"id":"1.229554934","rc":[{"atb":[[1.88,0],[1.93,2]],"id":65894825}],"con":true,"img":false}]}
{"op":"mcm","clk":"11450805478","pt":1717325673408,"mc":[{"id":"1.229554934","rc":[{"atl":[[2.12,13.39]],"id":47530316},{"atl":[[3.25,6.67]],"id":65894825}],"con":true,"img":false}]}
{"op":"mcm","clk":"11450805569","pt":1717325674033,"mc":[{"id":"1.229554934","rc":[{"atl":[[3.35,16.58],[3.55,11.76]],"id":65894825}],"con":true,"img":false}]}
{"op":"mcm","clk":"11450805626","pt":1717325674504,"mc":[{"id":"1.229554934","rc":[{"atl":[[2.12,0]],"id":47530316},{"atl":[[3.25,0]],"id":65894825}],"con":true,"img":false}]}
{"op":"mcm","clk":"11450805888","pt":1717325677184,"mc":[{"id":"1.229554934","rc":[{"atl":[[2.12,13.39]],"id":47530316}],"con":true,"img":false}]}
{"op":"mcm","clk":"11450805979","pt":1717325678117,"mc":[{"id":"1.229554934","rc":[{"atl":[[2.12,0]],"id":47530316}],"con":true,"img":false}]}
{"op":"mcm","clk":"11450806099","pt":1717325679305,"mc":[{"id":"1.229554934","rc":[{"atl":[[2.12,13.39]],"id":47530316}],"con":true,"img":false}]}
{"op":"mcm","clk":"11450806125","pt":1717325679512,"mc":[{"id":"1.229554934","rc":[{"atl":[[2.12,0]],"id":47530316}],"con":true,"img":false}]}
{"op":"mcm","clk":"11450806295","pt":1717325681118,"mc":[{"id":"1.229554934","rc":[{"atl":[[2.12,13.39],[2.2,2]],"id":47530316}],"con":true,"img":false}]}
{"op":"mcm","clk":"11450806307","pt":1717325681218,"mc":[{"id":"1.229554934","rc":[{"atl":[[2.22,0]],"id":47530316}],"con":true,"img":false}]}
{"op":"mcm","clk":"11450806329","pt":1717325681422,"mc":[{"id":"1.229554934","rc":[{"atl":[[2.12,0]],"id":47530316}],"con":true,"img":false}]}
{"op":"mcm","clk":"11450806385","pt":1717325681897,"mc":[{"id":"1.229554934","rc":[{"atl":[[3.45,8.16]],"id":65894825}],"con":true,"img":false}]}
{"op":"mcm","clk":"11450806447","pt":1717325682525,"mc":[{"id":"1.229554934","rc":[{"atl":[[2.12,13.39]],"id":47530316}],"con":true,"img":false}]}
{"op":"mcm","clk":"11450806520","pt":1717325683093,"mc":[{"id":"1.229554934","rc":[{"atl":[[2.12,0]],"id":47530316}],"con":true,"img":false}]}
{"op":"mcm","clk":"11450806852","pt":1717325686223,"mc":[{"id":"1.229554934","rc":[{"atl":[[2.22,2],[2.2,0]],"id":47530316}],"con":true,"img":false}]}
{"op":"mcm","clk":"11450807021","pt":1717325687720,"mc":[{"id":"1.229554934","rc":[{"atl":[[3.3,6.52]],"id":65894825}],"con":true,"img":false}]}
{"op":"mcm","clk":"11450807033","pt":1717325687824,"mc":[{"id":"1.229554934","rc":[{"atl":[[2.12,13.39]],"id":47530316},{"atl":[[3.35,6.38],[3.3,14.68]],"id":65894825}],"con":true,"img":false}]}
{"op":"mcm","clk":"11450807044","pt":1717325687928,"mc":[{"id":"1.229554934","rc":[{"atl":[[2.22,0],[2.1,6.7]],"id":47530316},{"atl":[[3.35,23.06],[3.3,6.52]],"id":65894825}],"con":true,"img":false}]}
{"op":"mcm","clk":"11450807051","pt":1717325688029,"mc":[{"id":"1.229554934","rc":[{"atl":[[2.1,0],[2.14,15.16]],"id":47530316}],"con":true,"img":false}]}
{"op":"mcm","clk":"11450807856","pt":1717325696070,"mc":[{"id":"1.229554934","rc":[{"atl":[[2.16,17.24]],"id":47530316}],"con":true,"img":false}]}
{"op":"mcm","clk":"11450807871","pt":1717325696172,"mc":[{"id":"1.229554934","rc":[{"atl":[[2.16,19.24]],"id":47530316}],"con":true,"img":false}]}
{"op":"mcm","clk":"11450807884","pt":1717325696277,"mc":[{"id":"1.229554934","rc":[{"atl":[[2.14,13.16]],"id":47530316}],"con":true,"img":false}]}
{"op":"mcm","clk":"11450808210","pt":1717325699804,"mc":[{"id":"1.229554934","rc":[{"atb":[[1.58,13.52],[1.48,16.34]],"id":47530316},{"atb":[[2,7.84],[2.2,6.53]],"id":65894825}],"con":true,"img":false}]}
{"op":"mcm","clk":"11450808702","pt":1717325704158,"mc":[{"id":"1.229554934","rc":[{"atl":[[2.2,20.83]],"id":47530316}],"con":true,"img":false}]}
{"op":"mcm","clk":"11450808878","pt":1717325705677,"mc":[{"id":"1.229554934","rc":[{"atb":[[1.43,18.24],[1.53,14.8]],"id":47530316},{"atb":[[2.32,5.94],[2.12,7]],"id":65894825}],"con":true,"img":false}]}
{"op":"mcm","clk":"11450809895","pt":1717325714797,"mc":[{"id":"1.229554934","rc":[{"atl":[[3.2,6.82],[3.3,0]],"id":65894825}],"con":true,"img":false}]}
{"op":"mcm","clk":"11450809979","pt":1717325715471,"mc":[{"id":"1.229554934","rc":[{"atb":[[1.43,0],[1.53,0]],"id":47530316},{"atb":[[2.32,0],[2.12,0]],"id":65894825}],"con":true,"img":false}]}
{"op":"mcm","clk":"11450810518","pt":1717325720670,"mc":[{"id":"1.229554934","rc":[{"atb":[[1.43,18.24],[1.53,14.8]],"id":47530316},{"atb":[[2.32,5.94],[2.12,7]],"id":65894825}],"con":true,"img":false}]}
{"op":"mcm","clk":"11450811079","pt":1717325726004,"mc":[{"id":"1.229554934","rc":[{"atl":[[3.05,2.97]],"id":65894825}],"con":true,"img":false}]}
{"op":"mcm","clk":"11450811090","pt":1717325726102,"mc":[{"id":"1.229554934","rc":[{"atl":[[3.1,0],[3.35,6.38],[3.3,11.76]],"id":65894825}],"con":true,"img":false}]}
{"op":"mcm","clk":"11450811404","pt":1717325729316,"mc":[{"id":"1.229554934","rc":[{"atb":[[1.43,0],[1.53,0]],"id":47530316},{"atb":[[2.32,0],[2.12,0]],"id":65894825}],"con":true,"img":false}]}
{"op":"mcm","clk":"11450811435","pt":1717325729582,"mc":[{"id":"1.229554934","rc":[{"atl":[[3.3,18.28]],"id":65894825}],"con":true,"img":false}]}
{"op":"mcm","clk":"11450811448","pt":1717325729687,"mc":[{"id":"1.229554934","rc":[{"atl":[[3.2,0]],"id":65894825}],"con":true,"img":false}]}
{"op":"mcm","clk":"11450811457","pt":1717325729789,"mc":[{"id":"1.229554934","rc":[{"atl":[[3.45,0],[3.35,0],[3.55,0]],"id":65894825}],"con":true,"img":false}]}
{"op":"mcm","clk":"11450811601","pt":1717325731208,"mc":[{"id":"1.229554934","rc":[{"atl":[[7.2,16.13],[3.3,6.52]],"id":65894825}],"con":true,"img":false}]}
{"op":"mcm","clk":"11450812014","pt":1717325734791,"mc":[{"id":"1.229554934","rc":[{"atl":[[3.1,2]],"id":65894825}],"con":true,"img":false}]}
{"op":"mcm","clk":"11450812025","pt":1717325734895,"mc":[{"id":"1.229554934","rc":[{"atb":[[1.4,19.61],[1.5,15.69]],"id":47530316},{"atb":[[2.38,5.68],[2.18,6.64]],"id":65894825},{"atl":[[3.3,13.04],[3.05,0]],"id":65894825}],"con":true,"img":false}]}
{"op":"mcm","clk":"11450812038","pt":1717325734996,"mc":[{"id":"1.229554934","rc":[{"atl":[[7.2,0]],"id":65894825}],"con":true,"img":false}]}
{"op":"mcm","clk":"11450812047","pt":1717325735103,"mc":[{"id":"1.229554934","rc":[{"atl":[[7.2,15.04]],"id":65894825}],"con":true,"img":false}]}
{"op":"mcm","clk":"11450812056","pt":1717325735204,"mc":[{"id":"1.229554934","rc":[{"atl":[[3.3,6.52]],"id":65894825}],"con":true,"img":false}]}
{"op":"mcm","clk":"11450812136","pt":1717325736030,"mc":[{"id":"1.229554934","rc":[{"atb":[[1.59,0]],"id":47530316},{"atl":[[2.16,17.24]],"id":47530316},{"atb":[[1.93,0]],"id":65894825},{"atl":[[3.1,0]],"id":65894825}],"con":true,"img":false}]}
{"op":"mcm","clk":"11450812268","pt":1717325737214,"mc":[{"id":"1.229554934","rc":[{"atl":[[3.4,8.33]],"id":65894825}],"con":true,"img":false}]}
{"op":"mcm","clk":"11450812483","pt":1717325739186,"mc":[{"id":"1.229554934","rc":[{"atl":[[2.12,0]],"id":47530316}],"con":true,"img":false}]}
{"op":"mcm","clk":"11450812554","pt":1717325739820,"mc":[{"id":"1.229554934","rc":[{"atl":[[3.4,6.25],[3.3,0]],"id":65894825}],"con":true,"img":false}]}
{"op":"mcm","clk":"11450812565","pt":1717325739926,"mc":[{"id":"1.229554934","rc":[{"atl":[[2.12,13.39]],"id":47530316}],"con":true,"img":false}]}
{"op":"mcm","clk":"11450812623","pt":1717325740493,"mc":[{"id":"1.229554934","rc":[{"atl":[[3.3,6.52]],"id":65894825}],"con":true,"img":false}]}
{"op":"mcm","clk":"11450812753","pt":1717325741838,"mc":[{"id":"1.229554934","rc":[{"atb":[[1.4,0],[1.5,0]],"id":47530316},{"atb":[[2.38,0],[2.18,0]],"id":65894825}],"con":true,"img":false}]}
{"op":"mcm","clk":"11450813214","pt":1717325746041,"mc":[{"id":"1.229554934","rc":[{"atb":[[1.4,19.61],[1.5,15.69]],"id":47530316},{"atb":[[2.38,5.68],[2.18,6.64]],"id":65894825}],"con":true,"img":false}]}
{"op":"mcm","clk":"11450813326","pt":1717325747336,"mc":[{"id":"1.229554934","rc":[{"atl":[[3.3,0]],"id":65894825}],"con":true,"img":false}]}
{"op":"mcm","clk":"11450813382","pt":1717325747907,"mc":[{"id":"1.229554934","rc":[{"atl":[[3.5,8]],"id":65894825}],"con":true,"img":false}]}
{"op":"mcm","clk":"11450813395","pt":1717325748016,"mc":[{"id":"1.229554934","rc":[{"atl":[[7.2,0],[3.45,12.5]],"id":65894825}],"con":true,"img":false}]}
{"op":"mcm","clk":"11450813406","pt":1717325748121,"mc":[{"id":"1.229554934","rc":[{"atl":[[3.5,26.75]],"id":65894825}],"con":true,"img":false}]}
{"op":"mcm","clk":"11450813416","pt":1717325748218,"mc":[{"id":"1.229554934","rc":[{"atl":[[3.45,0]],"id":65894825}],"con":true,"img":false}]}
{"op":"mcm","clk":"11450813427","pt":1717325748323,"mc":[{"id":"1.229554934","rc":[{"atl":[[7.2,16.13],[3.5,8]],"id":65894825}],"con":true,"img":false}]}
{"op":"mcm","clk":"11450814069","pt":1717325755148,"mc":[{"id":"1.229554934","rc":[{"atl":[[3.6,9.62]],"id":65894825}],"con":true,"img":false}]}
{"op":"mcm","clk":"11450814077","pt":1717325755208,"mc":[{"id":"1.229554934","rc":[{"atl":[[7.2,0],[3.55,14.25]],"id":65894825}],"con":true,"img":false}]}
{"op":"mcm","clk":"11450814199","pt":1717325756854,"mc":[{"id":"1.229554934","rc":[{"atb":[[1.4,0],[1.5,0]],"id":47530316},{"atb":[[2.38,0],[2.18,0]],"id":65894825}],"con":true,"img":false}]}
{"op":"mcm","clk":"11450814559","pt":1717325760796,"mc":[{"id":"1.229554934","rc":[{"atb":[[1.4,19.61],[1.5,15.69]],"id":47530316},{"atb":[[2.38,5.68],[2.18,6.64]],"id":65894825}],"con":true,"img":false}]}
{"op":"mcm","clk":"11450814587","pt":1717325761109,"mc":[{"id":"1.229554934","rc":[{"atl":[[3.3,6.52]],"id":65894825}],"con":true,"img":false}]}
{"op":"mcm","clk":"11450814605","pt":1717325761313,"mc":[{"id":"1.229554934","rc":[{"atl":[[3.3,0]],"id":65894825}],"con":true,"img":false}]}
{"op":"mcm","clk":"11450814793","pt":1717325763333,"mc":[{"id":"1.229554934","rc":[{"atl":[[3.3,6.52]],"id":65894825}],"con":true,"img":false}]}
{"op":"mcm","clk":"11450814802","pt":1717325763437,"mc":[{"id":"1.229554934","rc":[{"atl":[[3.3,13.04]],"id":65894825}],"con":true,"img":false}]}
{"op":"mcm","clk":"11450814817","pt":1717325763494,"mc":[{"id":"1.229554934","rc":[{"atl":[[3.55,0]],"id":65894825}],"con":true,"img":false}]}
{"op":"mcm","clk":"11450815269","pt":1717325768140,"mc":[{"id":"1.229554934","rc":[{"atl":[[3.3,6.52],[3.5,27.29]],"id":65894825}],"con":true,"img":false}]}
{"op":"mcm","clk":"11450815296","pt":1717325768297,"mc":[{"id":"1.229554934","rc":[{"atl":[[3.3,0]],"id":65894825}],"con":true,"img":false}]}
{"op":"mcm","clk":"11450815485","pt":1717325770208,"mc":[{"id":"1.229554934","rc":[{"atl":[[3.7,11.11]],"id":65894825}],"con":true,"img":false}]}
{"op":"mcm","clk":"11450815730","pt":1717325772858,"mc":[{"id":"1.229554934","rc":[{"atl":[[3.6,43.16],[3.5,8]],"id":65894825}],"con":true,"img":false}]}
{"op":"mcm","clk":"11450817279","pt":1717325788268,"mc":[{"id":"1.229554934","rc":[{"atl":[[3.4,0],[3.3,6.52]],"id":65894825}],"con":true,"img":false}]}
{"op":"mcm","clk":"11450817288","pt":1717325788324,"mc":[{"id":"1.229554934","rc":[{"atl":[[3.6,9.62],[3.5,20.5]],"id":65894825}],"con":true,"img":false}]}
{"op":"mcm","clk":"11450817298","pt":1717325788428,"mc":[{"id":"1.229554934","rc":[{"atl":[[3.6,24.14]],"id":65894825}],"con":true,"img":false}]}
{"op":"mcm","clk":"11450817307","pt":1717325788531,"mc":[{"id":"1.229554934","rc":[{"atl":[[3.5,8]],"id":65894825}],"con":true,"img":false}]}
{"op":"mcm","clk":"11450817938","pt":1717325794845,"mc":[{"id":"1.229554934","rc":[{"atl":[[3.4,8.33]],"id":65894825}],"con":true,"img":false}]}
{"op":"mcm","clk":"11450817945","pt":1717325794949,"mc":[{"id":"1.229554934","rc":[{"atl":[[3.5,21.04]],"id":65894825}],"con":true,"img":false}]}
{"op":"mcm","clk":"11450817954","pt":1717325795052,"mc":[{"id":"1.229554934","rc":[{"atl":[[3.6,9.62]],"id":65894825}],"con":true,"img":false}]}
{"op":"mcm","clk":"11450818246","pt":1717325798147,"mc":[{"id":"1.229554934","rc":[{"atl":[[3.7,0]],"id":65894825}],"con":true,"img":false}]}
{"op":"mcm","clk":"11450818330","pt":1717325799079,"mc":[{"id":"1.229554934","rc":[{"atl":[[2.12,0]],"id":47530316}],"con":true,"img":false}]}
{"op":"mcm","clk":"11450818536","pt":1717325801157,"mc":[{"id":"1.229554934","rc":[{"atl":[[2.12,13.39]],"id":47530316}],"con":true,"img":false}]}
{"op":"mcm","clk":"11450818656","pt":1717325802349,"mc":[{"id":"1.229554934","rc":[{"atl":[[3.4,6.25],[3.3,0]],"id":65894825}],"con":true,"img":false}]}
{"op":"mcm","clk":"11450818667","pt":1717325802449,"mc":[{"id":"1.229554934","rc":[{"atl":[[3.6,36.91]],"id":65894825}],"con":true,"img":false}]}
{"op":"mcm","clk":"11450818672","pt":1717325802551,"mc":[{"id":"1.229554934","rc":[{"atl":[[3.5,8]],"id":65894825}],"con":true,"img":false}]}
{"op":"mcm","clk":"11450818745","pt":1717325803182,"mc":[{"id":"1.229554934","rc":[{"atl":[[3.3,6.52]],"id":65894825}],"con":true,"img":false}]}
{"op":"mcm","clk":"11450818773","pt":1717325803385,"mc":[{"id":"1.229554934","rc":[{"atl":[[3.3,0]],"id":65894825}],"con":true,"img":false}]}
{"op":"mcm","clk":"11450818787","pt":1717325803489,"mc":[{"id":"1.229554934","rc":[{"atl":[[2.12,0]],"id":47530316}],"con":true,"img":false}]}
{"op":"mcm","clk":"11450818800","pt":1717325803591,"mc":[{"id":"1.229554934","rc":[{"atl":[[3.3,6.52]],"id":65894825}],"con":true,"img":false}]}
{"op":"mcm","clk":"11450818817","pt":1717325803694,"mc":[{"id":"1.229554934","rc":[{"atl":[[2.12,13.39]],"id":47530316}],"con":true,"img":false}]}
{"op":"mcm","clk":"11450818854","pt":1717325804088,"mc":[{"id":"1.229554934","rc":[{"atl":[[2.12,0]],"id":47530316},{"atl":[[3.3,0]],"id":65894825}],"con":true,"img":false}]}
{"op":"mcm","clk":"11450818919","pt":1717325804661,"mc":[{"id":"1.229554934","rc":[{"atl":[[2.12,13.39]],"id":47530316}],"con":true,"img":false}]}
{"op":"mcm","clk":"11450818969","pt":1717325805174,"mc":[{"id":"1.229554934","rc":[{"atl":[[3.3,6.52]],"id":65894825}],"con":true,"img":false}]}
{"op":"mcm","clk":"11450819197","pt":1717325807596,"mc":[{"id":"1.229554934","rc":[{"atl":[[3.6,9.62],[3.5,20.77]],"id":65894825}],"con":true,"img":false}]}
{"op":"mcm","clk":"11450819348","pt":1717325808890,"mc":[{"id":"1.229554934","rc":[{"atl":[[3.3,0]],"id":65894825}],"con":true,"img":false}]}
{"op":"mcm","clk":"11450819628","pt":1717325811467,"mc":[{"id":"1.229554934","rc":[{"atl":[[3.7,11.11]],"id":65894825}],"con":true,"img":false}]}
{"op":"mcm","clk":"11450819683","pt":1717325811880,"mc":[{"id":"1.229554934","rc":[{"atl":[[3.6,36.64],[3.5,8]],"id":65894825}],"con":true,"img":false}]}
{"op":"mcm","clk":"11450819757","pt":1717325812497,"mc":[{"id":"1.229554934","rc":[{"atb":[[1.03,112.48]],"id":47530316},{"atl":[[990,1.91]],"id":47530316},{"atb":[[1.02,140.11]],"id":65894825},{"atl":[[980,0.85]],"id":65894825}],"con":true,"img":false}]}
{"op":"mcm","clk":"11450820016","pt":1717325814893,"mc":[{"id":"1.229554934","rc":[{"atb":[[1.4,0],[1.5,0]],"id":47530316},{"atb":[[2.38,0],[2.18,0]],"id":65894825}],"con":true,"img":false}]}
{"op":"mcm","clk":"11450820768","pt":1717325822417,"mc":[{"id":"1.229554934","rc":[{"atb":[[1.4,19.61],[1.5,15.69]],"id":47530316},{"atb":[[2.38,5.68],[2.18,6.64]],"id":65894825}],"con":true,"img":false}]}
{"op":"mcm","clk":"11450820782","pt":1717325822523,"mc":[{"id":"1.229554934","rc":[{"atl":[[2.12,0],[2.1,13.64]],"id":47530316}],"con":true,"img":false}]}
{"op":"mcm","clk":"11450820906","pt":1717325823410,"mc":[{"id":"1.229554934","rc":[{"atl":[[2.12,13.39],[2.1,0]],"id":47530316}],"con":true,"img":false}]}
{"op":"mcm","clk":"11450821892","pt":1717325831735,"mc":[{"id":"1.229554934","rc":[{"atb":[[1.58,1.48]],"id":47530316},{"trd":[[1.58,24.09]],"ltp":1.58,"tv":24.09,"id":47530316}],"con":true,"img":false}]}
{"op":"mcm","clk":"11450822082","pt":1717325833192,"mc":[{"id":"1.229554934","rc":[{"atb":[[1.4,0],[1.5,0]],"id":47530316},{"atb":[[2.38,0],[2.18,0]],"id":65894825}],"con":true,"img":false}]}
{"op":"mcm","clk":"11450822100","pt":1717325833398,"mc":[{"id":"1.229554934","rc":[{"atb":[[1.21,65.12],[1.32,0],[1.42,2]],"id":47530316},{"atl":[[2.66,0],[2.16,19.24],[2.34,30.63]],"id":47530316},{"atb":[[1.4,0],[1.88,2],[1.13,140.11]],"id":65894825},{"atl":[[3.6,9.62],[3.7,5.56],[3.4,0],[4.4,19.11],[3.3,2]],"id":65894825}],"con":true,"img":false}]}
{"op":"mcm","clk":"11450822108","pt":1717325833500,"mc":[{"id":"1.229554934","rc":[{"atl":[[2.34,0]],"id":47530316},{"atb":[[1.13,0]],"id":65894825},{"atl":[[4.4,0]],"id":65894825}],"con":true,"img":false}]}
{"op":"mcm","clk":"11450822119","pt":1717325833609,"mc":[{"id":"1.229554934","rc":[{"atl":[[2.18,26.78]],"id":47530316},{"atb":[[1.31,140.11]],"id":65894825},{"atl":[[3.9,13.56]],"id":65894825}],"con":true,"img":false}]}
{"op":"mcm","clk":"11450822652","pt":1717325838642,"mc":[{"id":"1.229554934","rc":[{"atl":[[3.5,0]],"id":65894825}],"con":true,"img":false}]}
{"op":"mcm","clk":"11450822716","pt":1717325839219,"mc":[{"id":"1.229554934","rc":[{"atl":[[3.6,0],[3.8,7.14]],"id":65894825}],"con":true,"img":false}]}
{"op":"mcm","clk":"11450822913","pt":1717325841143,"mc":[{"id":"1.229554934","rc":[{"atb":[[1.12,36.27],[1.02,217.64]],"id":47530316},{"atb":[[2.38,10.05],[2.18,11.75]],"id":65894825}],"con":true,"img":false}]}
{"op":"mcm","clk":"11450823343","pt":1717325844963,"mc":[{"id":"1.229554934","rc":[{"atl":[[3.9,22.18]],"id":65894825}],"con":true,"img":false}]}
{"op":"mcm","clk":"11450823733","pt":1717325848641,"mc":[{"id":"1.229554934","rc":[{"atl":[[3.75,5.45]],"id":65894825}],"con":true,"img":false}]}
{"op":"mcm","clk":"11450823745","pt":1717325848740,"mc":[{"id":"1.229554934","rc":[{"atl":[[3.7,0]],"id":65894825}],"con":true,"img":false}]}
{"op":"mcm","clk":"11450823942","pt":1717325850544,"mc":[{"id":"1.229554934","rc":[{"atb":[[1.36,140.11]],"id":65894825}],"con":true,"img":false}]}
{"op":"mcm","clk":"11450823953","pt":1717325850650,"mc":[{"id":"1.229554934","rc":[{"atb":[[1.31,0]],"id":65894825}],"con":true,"img":false}]}
{"op":"mcm","clk":"11450824292","pt":1717325853660,"mc":[{"id":"1.229554934","rc":[{"atb":[[1.21,0],[1.54,2],[1.32,65.12],[1.42,0]],"id":47530316},{"atl":[[2.18,0],[2.26,38.48]],"id":47530316},{"atb":[[1.88,0],[1.93,3.27]],"id":65894825},{"atl":[[3.8,14.59],[3.3,6.52],[3.9,8.62],[3.05,3.27]],"id":65894825}],"con":true,"img":false}]}
{"op":"mcm","clk":"11450824305","pt":1717325853758,"mc":[{"id":"1.229554934","rc":[{"atl":[[2.12,0]],"id":47530316}],"con":true,"img":false}]}
{"op":"mcm","clk":"11450824315","pt":1717325853862,"mc":[{"id":"1.229554934","rc":[{"atl":[[3.4,6.25],[3.3,0]],"id":65894825}],"con":true,"img":false}]}
{"op":"mcm","clk":"11450824328","pt":1717325853921,"mc":[{"id":"1.229554934","rc":[{"atl":[[3.4,16.04]],"id":65894825}],"con":true,"img":false}]}
{"op":"mcm","clk":"11450824342","pt":1717325854028,"mc":[{"id":"1.229554934","rc":[{"atl":[[3.8,7.14]],"id":65894825}],"con":true,"img":false}]}
{"op":"mcm","clk":"11450824374","pt":1717325854337,"mc":[{"id":"1.229554934","rc":[{"atl":[[3.4,9.79],[3.3,6.52]],"id":65894825}],"con":true,"img":false}]}
{"op":"mcm","clk":"11450824408","pt":1717325854692,"mc":[{"id":"1.229554934","rc":[{"atb":[[2.38,7.05]],"id":65894825},{"trd":[[2.38,5.99]],"ltp":2.38,"tv":5.99,"id":65894825}],"con":true,"img":false}]}
{"op":"mcm","clk":"11450824433","pt":1717325854852,"mc":[{"id":"1.229554934","rc":[{"atl":[[3.4,16.04],[3.3,0]],"id":65894825}],"con":true,"img":false}]}
{"op":"mcm","clk":"11450824495","pt":1717325855471,"mc":[{"id":"1.229554934","rc":[{"atl":[[3.4,9.79],[3.3,6.52]],"id":65894825}],"con":true,"img":false}]}
{"op":"mcm","clk":"11450824529","pt":1717325855739,"mc":[{"id":"1.229554934","rc":[{"atb":[[1.36,0],[1.54,140.11]],"id":65894825}],"con":true,"img":false}]}
{"op":"mcm","clk":"11450824655","pt":1717325856971,"mc":[{"id":"1.229554934","rc":[{"atl":[[2.18,16.95]],"id":47530316}],"con":true,"img":false}]}
{"op":"mcm","clk":"11450824664","pt":1717325857033,"mc":[{"id":"1.229554934","rc":[{"atl":[[2.18,18.95],[2.16,17.24]],"id":47530316}],"con":true,"img":false}]}
{"op":"mcm","clk":"11450824709","pt":1717325857442,"mc":[{"id":"1.229554934","rc":[{"atl":[[3.4,16.04]],"id":65894825}],"con":true,"img":false}]}
{"op":"mcm","clk":"11450824719","pt":1717325857549,"mc":[{"id":"1.229554934","rc":[{"atl":[[3,3.27],[3.3,0],[3.05,0]],"id":65894825}],"con":true,"img":false}]}
{"op":"mcm","clk":"11450824744","pt":1717325857755,"mc":[{"id":"1.229554934","rc":[{"atl":[[3.75,24.76]],"id":65894825}],"con":true,"img":false}]}
{"op":"mcm","clk":"11450824754","pt":1717325857860,"mc":[{"id":"1.229554934","rc":[{"atb":[[1.37,65.12],[1.32,0]],"id":47530316},{"atl":[[3.4,0],[3.3,6.52]],"id":65894825}],"con":true,"img":false}]}
{"op":"mcm","clk":"11450824778","pt":1717325858064,"mc":[{"id":"1.229554934","rc":[{"atl":[[3.4,6.25]],"id":65894825}],"con":true,"img":false}]}
{"op":"mcm","clk":"11450824788","pt":1717325858160,"mc":[{"id":"1.229554934","rc":[{"atl":[[3.3,0]],"id":65894825}],"con":true,"img":false}]}
{"op":"mcm","clk":"11450824844","pt":1717325858635,"mc":[{"id":"1.229554934","rc":[{"atl":[[3.3,6.52]],"id":65894825}],"con":true,"img":false}]}
{"op":"mcm","clk":"11450824857","pt":1717325858738,"mc":[{"id":"1.229554934","rc":[{"atl":[[3.4,0]],"id":65894825}],"con":true,"img":false}]}
{"op":"mcm","clk":"11450824876","pt":1717325858946,"mc":[{"id":"1.229554934","rc":[{"atb":[[1.55,2]],"id":47530316}],"con":true,"img":false}]}
{"op":"mcm","clk":"11450824891","pt":1717325859051,"mc":[{"id":"1.229554934","rc":[{"atb":[[1.54,0]],"id":47530316}],"con":true,"img":false}]}
{"op":"mcm","clk":"11450824975","pt":1717325859873,"mc":[{"id":"1.229554934","rc":[{"atl":[[3.4,6.25]],"id":65894825}],"con":true,"img":false}]}
{"op":"mcm","clk":"11450824983","pt":1717325859976,"mc":[{"id":"1.229554934","rc":[{"atl":[[3.3,0]],"id":65894825}],"con":true,"img":false}]}
{"op":"mcm","clk":"11450825001","pt":1717325860140,"mc":[{"id":"1.229554934","rc":[{"atl":[[3.3,6.52]],"id":65894825}],"con":true,"img":false}]}
{"op":"mcm","clk":"11450825009","pt":1717325860249,"mc":[{"id":"1.229554934","rc":[{"atl":[[3.4,0]],"id":65894825}],"con":true,"img":false}]}
{"op":"mcm","clk":"11450825027","pt":1717325860452,"mc":[{"id":"1.229554934","rc":[{"atl":[[3.4,6.25],[3.3,0]],"id":65894825}],"con":true,"img":false}]}
{"op":"mcm","clk":"11450825068","pt":1717325860861,"mc":[{"id":"1.229554934","rc":[{"atb":[[1.54,0],[1.7,140.11]],"id":65894825}],"con":true,"img":false}]}
{"op":"mcm","clk":"11450825256","pt":1717325862668,"mc":[{"id":"1.229554934","rc":[{"atl":[[2.94,3.27]],"id":65894825}],"con":true,"img":false}]}
{"op":"mcm","clk":"11450825276","pt":1717325862775,"mc":[{"id":"1.229554934","rc":[{"atl":[[3,0]],"id":65894825}],"con":true,"img":false}]}
{"op":"mcm","clk":"11450825364","pt":1717325863486,"mc":[{"id":"1.229554934","rc":[{"atl":[[2.92,3.27]],"id":65894825}],"con":true,"img":false}]}
{"op":"mcm","clk":"11450825380","pt":1717325863564,"mc":[{"id":"1.229554934","rc":[{"atl":[[3.4,13.39],[2.94,0]],"id":65894825}],"con":true,"img":false}]}
{"op":"mcm","clk":"11450825397","pt":1717325863671,"mc":[{"id":"1.229554934","rc":[{"atl":[[3.75,5.45]],"id":65894825}],"con":true,"img":false}]}
{"op":"mcm","clk":"11450825644","pt":1717325865757,"mc":[{"id":"1.229554934","rc":[{"atl":[[3.5,8]],"id":65894825}],"con":true,"img":false}]}
{"op":"mcm","clk":"11450825698","pt":1717325866166,"mc":[{"id":"1.229554934","rc":[{"atl":[[3.9,0],[3.75,0]],"id":65894825}],"con":true,"img":false}]}
{"op":"mcm","clk":"11450825973","pt":1717325868561,"mc":[{"id":"1.229554934","rc":[{"atl":[[2.9,3.27]],"id":65894825}],"con":true,"img":false}]}
{"op":"mcm","clk":"11450825984","pt":1717325868657,"mc":[{"id":"1.229554934","rc":[{"atl":[[2.92,0]],"id":65894825}],"con":true,"img":false}]}
{"op":"mcm","clk":"11450826243","pt":1717325871065,"mc":[{"id":"1.229554934","rc":[{"atl":[[3.6,9.62]],"id":65894825}],"con":true,"img":false}]}
{"op":"mcm","clk":"11450826545","pt":1717325873672,"mc":[{"id":"1.229554934","rc":[{"atl":[[2.86,3.27]],"id":65894825}],"con":true,"img":false}]}
{"op":"mcm","clk":"11450826555","pt":1717325873772,"mc":[{"id":"1.229554934","rc":[{"atl":[[2.9,0],[3.4,6.25],[3.15,9.62]],"id":65894825}],"con":true,"img":false}]}
{"op":"mcm","clk":"11450826608","pt":1717325874290,"mc":[{"id":"1.229554934","rc":[{"atl":[[2.86,0],[2.84,3.27]],"id":65894825}],"con":true,"img":false}]}
{"op":"mcm","clk":"11450826776","pt":1717325875490,"mc":[{"id":"1.229554934","rc":[{"atb":[[1.56,2],[1.55,0]],"id":47530316}],"con":true,"img":false}]}
{"op":"mcm","clk":"11450826843","pt":1717325876164,"mc":[{"id":"1.229554934","rc":[{"atl":[[3.7,11.11]],"id":65894825}],"con":true,"img":false}]}
{"op":"mcm","clk":"11450827129","pt":1717325879375,"mc":[{"id":"1.229554934","rc":[{"atl":[[3.8,0]],"id":65894825}],"con":true,"img":false}]}
{"op":"mcm","clk":"11450827384","pt":1717325881469,"mc":[{"id":"1.229554934","rc":[{"atl":[[2.86,3.27],[2.84,0]],"id":65894825}],"con":true,"img":false}]}
{"op":"mcm","clk":"11450827390","pt":1717325881567,"mc":[{"id":"1.229554934","rc":[{"atl":[[3.4,19.14]],"id":65894825}],"con":true,"img":false}]}
{"op":"mcm","clk":"11450827404","pt":1717325881674,"mc":[{"id":"1.229554934","rc":[{"atl":[[3.15,0]],"id":65894825}],"con":true,"img":false}]}
{"op":"mcm","clk":"11450827792","pt":1717325885403,"mc":[{"id":"1.229554934","rc":[{"atl":[[2.24,36.19],[2.26,0]],"id":47530316}],"con":true,"img":false}]}
{"op":"mcm","clk":"11450828221","pt":1717325889189,"mc":[{"id":"1.229554934","rc":[{"atb":[[1.7,0],[1.75,133.33]],"id":65894825}],"con":true,"img":false}]}
{"op":"mcm","clk":"11450828230","pt":1717325889292,"mc":[{"id":"1.229554934","rc":[{"atl":[[2.84,3.27]],"id":65894825}],"con":true,"img":false}]}
{"op":"mcm","clk":"11450828239","pt":1717325889398,"mc":[{"id":"1.229554934","rc":[{"atl":[[2.86,0]],"id":65894825}],"con":true,"img":false}]}
{"op":"mcm","clk":"11450828456","pt":1717325891312,"mc":[{"id":"1.229554934","rc":[{"atl":[[3.35,6.38],[3.4,12.89]],"id":65894825}],"con":true,"img":false}]}
{"op":"mcm","clk":"11450828828","pt":1717325894423,"mc":[{"id":"1.229554934","rc":[{"atl":[[2.8,3.27],[2.84,0]],"id":65894825}],"con":true,"img":false}]}
{"op":"mcm","clk":"11450829033","pt":1717325896189,"mc":[{"id":"1.229554934","rc":[{"atb":[[1.57,2]],"id":47530316}],"con":true,"img":false}]}
{"op":"mcm","clk":"11450829048","pt":1717325896293,"mc":[{"id":"1.229554934","rc":[{"atb":[[1.56,0]],"id":47530316}],"con":true,"img":false}]}
{"op":"mcm","clk":"11450829503","pt":1717325900303,"mc":[{"id":"1.229554934","rc":[{"atl":[[3.35,0],[3.4,19.14],[3.3,6.52]],"id":65894825}],"con":true,"img":false}]}
{"op":"mcm","clk":"11450829631","pt":1717325901498,"mc":[{"id":"1.229554934","rc":[{"atl":[[3.7,0]],"id":65894825}],"con":true,"img":false}]}
{"op":"mcm","clk":"11450829980","pt":1717325905009,"mc":[{"id":"1.229554934","rc":[{"atl":[[3.7,11.11],[3.3,0]],"id":65894825}],"con":true,"img":false}]}
{"op":"mcm","clk":"11450830052","pt":1717325905640,"mc":[{"id":"1.229554934","rc":[{"atl":[[2.8,0],[2.78,3.27]],"id":65894825}],"con":true,"img":false}]}
{"op":"mcm","clk":"11450830247","pt":1717325907604,"mc":[{"id":"1.229554934","rc":[{"atl":[[2.8,3.27],[2.78,0],[3.3,6.52]],"id":65894825}],"con":true,"img":false}]}
{"op":"mcm","clk":"11450830256","pt":1717325907708,"mc":[{"id":"1.229554934","rc":[{"atl":[[3.4,0],[3.3,16.14]],"id":65894825}],"con":true,"img":false}]}
{"op":"mcm","clk":"11450830265","pt":1717325907809,"mc":[{"id":"1.229554934","rc":[{"atl":[[3.7,0]],"id":65894825}],"con":true,"img":false}]}
{"op":"mcm","clk":"11450830273","pt":1717325907911,"mc":[{"id":"1.229554934","rc":[{"atl":[[3.3,9.62]],"id":65894825}],"con":true,"img":false}]}
{"op":"mcm","clk":"11450830298","pt":1717325908223,"mc":[{"id":"1.229554934","rc":[{"atl":[[3.4,6.25]],"id":65894825}],"con":true,"img":false}]}
{"op":"mcm","clk":"11450830442","pt":1717325909721,"mc":[{"id":"1.229554934","rc":[{"atl":[[2.78,3.27]],"id":65894825}],"con":true,"img":false}]}
{"op":"mcm","clk":"11450830454","pt":1717325909825,"mc":[{"id":"1.229554934","rc":[{"atl":[[2.8,0]],"id":65894825}],"con":true,"img":false}]}
{"op":"mcm","clk":"11450830509","pt":1717325910337,"mc":[{"id":"1.229554934","rc":[{"atl":[[3.4,0],[3.55,5.88]],"id":65894825}],"con":true,"img":false}]}
{"op":"mcm","clk":"11450830532","pt":1717325910497,"mc":[{"id":"1.229554934","rc":[{"atl":[[3.5,0]],"id":65894825}],"con":true,"img":false}]}
{"op":"mcm","clk":"11450830543","pt":1717325910600,"mc":[{"id":"1.229554934","rc":[{"atl":[[2.64,3.27],[2.78,0]],"id":65894825}],"con":true,"img":false}]}
{"op":"mcm","clk":"11450830564","pt":1717325910809,"mc":[{"id":"1.229554934","rc":[{"atl":[[2.74,3.27],[2.64,0]],"id":65894825}],"con":true,"img":false}]}
{"op":"mcm","clk":"11450830748","pt":1717325912620,"mc":[{"id":"1.229554934","rc":[{"atl":[[3.4,6.25]],"id":65894825}],"con":true,"img":false}]}
{"op":"mcm","clk":"11450830772","pt":1717325912821,"mc":[{"id":"1.229554934","rc":[{"atb":[[1.57,0],[1.55,2]],"id":47530316},{"atl":[[2.24,0],[2.22,36.19]],"id":47530316}],"con":true,"img":false}]}
{"op":"mcm","clk":"11450830856","pt":1717325913604,"mc":[{"id":"1.229554934","rc":[{"atl":[[3.3,16.14]],"id":65894825}],"con":true,"img":false}]}
{"op":"mcm","clk":"11450830892","pt":1717325913912,"mc":[{"id":"1.229554934","rc":[{"atl":[[3.3,9.62]],"id":65894825}],"con":true,"img":false}]}
{"op":"mcm","clk":"11450830975","pt":1717325914643,"mc":[{"id":"1.229554934","rc":[{"atb":[[1.12,0],[1.02,0]],"id":47530316},{"atb":[[2.38,0],[2.18,0]],"id":65894825}],"con":true,"img":false}]}
{"op":"mcm","clk":"11450831219","pt":1717325917038,"mc":[{"id":"1.229554934","rc":[{"atl":[[3.45,6.12],[3.4,0]],"id":65894825}],"con":true,"img":false}]}
{"op":"mcm","clk":"11450831245","pt":1717325917345,"mc":[{"id":"1.229554934","rc":[{"atl":[[3.45,0]],"id":65894825}],"con":true,"img":false}]}
{"op":"mcm","clk":"11450831315","pt":1717325917914,"mc":[{"id":"1.229554934","rc":[{"atl":[[2.22,0]],"id":47530316},{"atl":[[3.45,6.12]],"id":65894825}],"con":true,"img":false}]}
{"op":"mcm","clk":"11450831330","pt":1717325918020,"mc":[{"id":"1.229554934","rc":[{"atl":[[2.2,55.31]],"id":47530316}],"con":true,"img":false}]}
{"op":"mcm","clk":"11450831428","pt":1717325918847,"mc":[{"id":"1.229554934","rc":[{"atl":[[3.45,0]],"id":65894825}],"con":true,"img":false}]}
{"op":"mcm","clk":"11450831450","pt":1717325919055,"mc":[{"id":"1.229554934","rc":[{"atl":[[3.45,6.12]],"id":65894825}],"con":true,"img":false}]}
{"op":"mcm","clk":"11450831633","pt":1717325920717,"mc":[{"id":"1.229554934","rc":[{"atl":[[3.45,0]],"id":65894825}],"con":true,"img":false}]}
{"op":"mcm","clk":"11450831644","pt":1717325920822,"mc":[{"id":"1.229554934","rc":[{"atb":[[1.8,125]],"id":65894825}],"con":true,"img":false}]}
{"op":"mcm","clk":"11450831653","pt":1717325920925,"mc":[{"id":"1.229554934","rc":[{"atb":[[1.75,0]],"id":65894825}],"con":true,"img":false}]}
{"op":"mcm","clk":"11450831678","pt":1717325921130,"mc":[{"id":"1.229554934","rc":[{"atl":[[3.45,6.12]],"id":65894825}],"con":true,"img":false}]}
{"op":"mcm","clk":"11450831723","pt":1717325921545,"mc":[{"id":"1.229554934","rc":[{"atl":[[2.72,2]],"id":65894825}],"con":true,"img":false}]}
{"op":"mcm","clk":"11450831732","pt":1717325921646,"mc":[{"id":"1.229554934","rc":[{"atl":[[2.74,0]],"id":65894825}],"con":true,"img":false}]}
{"op":"mcm","clk":"11450831799","pt":1717325922218,"mc":[{"id":"1.229554934","rc":[{"atl":[[2.74,2]],"id":65894825}],"con":true,"img":false}]}
{"op":"mcm","clk":"11450831811","pt":1717325922321,"mc":[{"id":"1.229554934","rc":[{"atb":[[1.44,13.29],[1.54,10.83]],"id":47530316},{"atb":[[2.3,9.07],[2.1,10.73]],"id":65894825},{"atl":[[2.72,0]],"id":65894825}],"con":true,"img":false}]}
{"op":"mcm","clk":"11450831904","pt":1717325923162,"mc":[{"id":"1.229554934","rc":[{"atb":[[1.56,2],[1.55,0]],"id":47530316}],"con":true,"img":false}]}
{"op":"mcm","clk":"11450832157","pt":1717325925477,"mc":[{"id":"1.229554934","rc":[{"atl":[[3.55,13.72]],"id":65894825}],"con":true,"img":false}]}
{"op":"mcm","clk":"11450832172","pt":1717325925579,"mc":[{"id":"1.229554934","rc":[{"atl":[[3.55,7.84]],"id":65894825}],"con":true,"img":false}]}
{"op":"mcm","clk":"11450832447","pt":1717325928063,"mc":[{"id":"1.229554934","rc":[{"atb":[[1.55,2]],"id":47530316},{"atl":[[3.55,13.72]],"id":65894825}],"con":true,"img":false}]}
{"op":"mcm","clk":"11450832460","pt":1717325928166,"mc":[{"id":"1.229554934","rc":[{"atb":[[1.56,0]],"id":47530316},{"atl":[[3.45,0],[3.55,5.88]],"id":65894825}],"con":true,"img":false}]}
{"op":"mcm","clk":"11450839388","pt":1717325930959,"mc":[{"id":"1.229554934","rc":[{"atl":[[2.72,3.27],[3.45,6.12],[2.74,0]],"id":65894825}],"con":true,"img":false}]}
{"op":"mcm","clk":"11450839444","pt":1717325931481,"mc":[{"id":"1.229554934","rc":[{"atl":[[3.4,6.25]],"id":65894825}],"con":true,"img":false}]}
{"op":"mcm","clk":"11450839686","pt":1717325933566,"mc":[{"id":"1.229554934","rc":[{"atl":[[3.4,0],[3.5,6]],"id":65894825}],"con":true,"img":false}]}
{"op":"mcm","clk":"11450839722","pt":1717325933885,"mc":[{"id":"1.229554934","rc":[{"atl":[[3.45,0]],"id":65894825}],"con":true,"img":false}]}
{"op":"mcm","clk":"11450839728","pt":1717325933975,"mc":[{"id":"1.229554934","rc":[{"atb":[[1.56,2]],"id":47530316}],"con":true,"img":false}]}
{"op":"mcm","clk":"11450839751","pt":1717325934087,"mc":[{"id":"1.229554934","rc":[{"atb":[[1.55,0]],"id":47530316}],"con":true,"img":false}]}
{"op":"mcm","clk":"11450839791","pt":1717325934451,"mc":[{"id":"1.229554934","rc":[{"atl":[[2.72,0],[2.7,3.27]],"id":65894825}],"con":true,"img":false}]}
{"op":"mcm","clk":"11450839836","pt":1717325934862,"mc":[{"id":"1.229554934","rc":[{"atl":[[3.4,6.25]],"id":65894825}],"con":true,"img":false}]}
{"op":"mcm","clk":"11450839899","pt":1717325935485,"mc":[{"id":"1.229554934","rc":[{"atl":[[3.4,0]],"id":65894825}],"con":true,"img":false}]}
{"op":"mcm","clk":"11450840234","pt":1717325939000,"mc":[{"id":"1.229554934","rc":[{"atl":[[3.6,7.69]],"id":65894825}],"con":true,"img":false}]}
{"op":"mcm","clk":"11450840354","pt":1717325940468,"mc":[{"id":"1.229554934","rc":[{"atl":[[3.45,6.12]],"id":65894825}],"con":true,"img":false}]}
{"op":"mcm","clk":"11450840522","pt":1717325942176,"mc":[{"id":"1.229554934","rc":[{"atb":[[1.44,0],[1.54,0]],"id":47530316},{"atb":[[2.3,0],[2.1,0]],"id":65894825}],"con":true,"img":false}]}
{"op":"mcm","clk":"11450840528","pt":1717325942274,"mc":[{"id":"1.229554934","rc":[{"atb":[[1.96,2]],"id":65894825}],"con":true,"img":false}]}
{"op":"mcm","clk":"11450840539","pt":1717325942381,"mc":[{"id":"1.229554934","rc":[{"atb":[[1.8,0],[1.85,117.65],[1.93,0]],"id":65894825}],"con":true,"img":false}]}
{"op":"mcm","clk":"11450840689","pt":1717325943786,"mc":[{"id":"1.229554934","rc":[{"atl":[[3.45,0]],"id":65894825}],"con":true,"img":false}]}
{"op":"mcm","clk":"11450840740","pt":1717325944371,"mc":[{"id":"1.229554934","rc":[{"atl":[[3.7,9.26]],"id":65894825}],"con":true,"img":false}]}
{"op":"mcm","clk":"11450840958","pt":1717325946488,"mc":[{"id":"1.229554934","rc":[{"atl":[[3.3,16.14],[3.5,0]],"id":65894825}],"con":true,"img":false}]}
{"op":"mcm","clk":"11450840983","pt":1717325946803,"mc":[{"id":"1.229554934","rc":[{"atb":[[1.44,13.29],[1.54,10.83]],"id":47530316},{"atb":[[2.3,9.07],[2.1,10.73]],"id":65894825}],"con":true,"img":false}]}
{"op":"mcm","clk":"11450841060","pt":1717325947577,"mc":[{"id":"1.229554934","rc":[{"atl":[[2.72,3.27],[2.7,0]],"id":65894825}],"con":true,"img":false}]}
{"op":"mcm","clk":"11450841075","pt":1717325947687,"mc":[{"id":"1.229554934","rc":[{"atl":[[3.55,25.29],[3.3,6.52]],"id":65894825}],"con":true,"img":false}]}
{"op":"mcm","clk":"11450841194","pt":1717325948870,"mc":[{"id":"1.229554934","rc":[{"atl":[[3.3,0]],"id":65894825}],"con":true,"img":false}]}
{"op":"mcm","clk":"11450841215","pt":1717325949080,"mc":[{"id":"1.229554934","rc":[{"atb":[[1.55,2]],"id":47530316},{"atl":[[3.3,6.52]],"id":65894825}],"con":true,"img":false}]}
{"op":"mcm","clk":"11450841224","pt":1717325949178,"mc":[{"id":"1.229554934","rc":[{"atb":[[1.56,0]],"id":47530316}],"con":true,"img":false}]}
{"op":"mcm","clk":"11450841413","pt":1717325951504,"mc":[{"id":"1.229554934","rc":[{"atl":[[3.3,0]],"id":65894825}],"con":true,"img":false}]}
{"op":"mcm","clk":"11450841574","pt":1717325952987,"mc":[{"id":"1.229554934","rc":[{"atl":[[3.65,7.55]],"id":65894825}],"con":true,"img":false}]}
{"op":"mcm","clk":"11450842240","pt":1717325959625,"mc":[{"id":"1.229554934","rc":[{"atb":[[1.54,12.83]],"id":47530316}],"con":true,"img":false}]}
{"op":"mcm","clk":"11450842245","pt":1717325959682,"mc":[{"id":"1.229554934","rc":[{"atb":[[1.55,0]],"id":47530316}],"con":true,"img":false}]}
{"op":"mcm","clk":"11450842665","pt":1717325964697,"mc":[{"id":"1.229554934","rc":[{"atl":[[3.4,6.25],[3.55,19.41]],"id":65894825}],"con":true,"img":false}]}
{"op":"mcm","clk":"11450842687","pt":1717325964904,"mc":[{"id":"1.229554934","rc":[{"atl":[[2.72,0],[2.74,3.27]],"id":65894825}],"con":true,"img":false}]}
{"op":"mcm","clk":"11450842695","pt":1717325965009,"mc":[{"id":"1.229554934","rc":[{"atl":[[3.4,13.94]],"id":65894825}],"con":true,"img":false}]}
{"op":"mcm","clk":"11450842702","pt":1717325965110,"mc":[{"id":"1.229554934","rc":[{"atl":[[3.55,0]],"id":65894825}],"con":true,"img":false}]}
{"op":"mcm","clk":"11450842741","pt":1717325965574,"mc":[{"id":"1.229554934","rc":[{"atl":[[3.55,5.88]],"id":65894825}],"con":true,"img":false}]}
{"op":"mcm","clk":"11450842747","pt":1717325965673,"mc":[{"id":"1.229554934","rc":[{"atl":[[3.4,7.69]],"id":65894825}],"con":true,"img":false}]}
{"op":"mcm","clk":"11450842823","pt":1717325966448,"mc":[{"id":"1.229554934","rc":[{"atl":[[3.45,6.12],[3.4,13.94],[3.55,0]],"id":65894825}],"con":true,"img":false}]}
{"op":"mcm","clk":"11450842837","pt":1717325966654,"mc":[{"id":"1.229554934","rc":[{"atl":[[3.45,0],[3.4,7.69],[3.5,6],[3.65,0]],"id":65894825}],"con":true,"img":false}]}
{"op":"mcm","clk":"11450842844","pt":1717325966759,"mc":[{"id":"1.229554934","rc":[{"atl":[[3.3,6.52]],"id":65894825}],"con":true,"img":false}]}
{"op":"mcm","clk":"11450842853","pt":1717325966862,"mc":[{"id":"1.229554934","rc":[{"atl":[[3.7,0]],"id":65894825}],"con":true,"img":false}]}
{"op":"mcm","clk":"11450842862","pt":1717325966966,"mc":[{"id":"1.229554934","rc":[{"atl":[[3.3,0]],"id":65894825}],"con":true,"img":false}]}
{"op":"mcm","clk":"11450842882","pt":1717325967192,"mc":[{"id":"1.229554934","rc":[{"atl":[[3.3,6.52]],"id":65894825}],"con":true,"img":false}]}
{"op":"mcm","clk":"11450843187","pt":1717325970253,"mc":[{"id":"1.229554934","rc":[{"atb":[[1.9,111.11]],"id":65894825}],"con":true,"img":false}]}
{"op":"mcm","clk":"11450843201","pt":1717325970356,"mc":[{"id":"1.229554934","rc":[{"atb":[[1.85,0]],"id":65894825},{"atl":[[3.3,0]],"id":65894825}],"con":true,"img":false}]}
{"op":"mcm","clk":"11450843241","pt":1717325970771,"mc":[{"id":"1.229554934","rc":[{"atl":[[3.7,9.26]],"id":65894825}],"con":true,"img":false}]}
{"op":"mcm","clk":"11450843403","pt":1717325972375,"mc":[{"id":"1.229554934","rc":[{"atb":[[1.44,0],[1.54,2]],"id":47530316},{"atb":[[2.3,0],[2.1,0]],"id":65894825}],"con":true,"img":false}]}
{"op":"mcm","clk":"11450843558","pt":1717325973682,"mc":[{"id":"1.229554934","rc":[{"atl":[[2.74,0],[2.78,2]],"id":65894825}],"con":true,"img":false}]}
{"op":"mcm","clk":"11450843602","pt":1717325974148,"mc":[{"id":"1.229554934","rc":[{"atl":[[3.8,10.71]],"id":65894825}],"con":true,"img":false}]}
{"op":"mcm","clk":"11450843683","pt":1717325974982,"mc":[{"id":"1.229554934","rc":[{"atl":[[3.4,13.94],[3.5,0]],"id":65894825}],"con":true,"img":false}]}
{"op":"mcm","clk":"11450843741","pt":1717325975349,"mc":[{"id":"1.229554934","rc":[{"atb":[[1.54,0],[1.51,2]],"id":47530316},{"atl":[[2.78,0]],"id":65894825}],"con":true,"img":false}]}
{"op":"mcm","clk":"11450843754","pt":1717325975456,"mc":[{"id":"1.229554934","rc":[{"atl":[[3.6,23.63],[3.4,6.25],[2.84,2]],"id":65894825}],"con":true,"img":false}]}
{"op":"mcm","clk":"11450843764","pt":1717325975556,"mc":[{"id":"1.229554934","rc":[{"atl":[[3.7,30.89]],"id":65894825}],"con":true,"img":false}]}
{"op":"mcm","clk":"11450843775","pt":1717325975660,"mc":[{"id":"1.229554934","rc":[{"atl":[[3.6,7.69]],"id":65894825}],"con":true,"img":false}]}
{"op":"mcm","clk":"11450843789","pt":1717325975763,"mc":[{"id":"1.229554934","rc":[{"atl":[[3.6,35.57],[3.7,9.26]],"id":65894825}],"con":true,"img":false}]}
{"op":"mcm","clk":"11450843800","pt":1717325975868,"mc":[{"id":"1.229554934","rc":[{"atb":[[1.28,65.12],[1.37,0],[1.51,0],[1.47,2]],"id":47530316},{"atb":[[1.79,126.58],[1.9,0]],"id":65894825},{"atl":[[3.45,6.12],[3.4,0],[2.84,0]],"id":65894825}],"con":true,"img":false}]}
{"op":"mcm","clk":"11450843811","pt":1717325975971,"mc":[{"id":"1.229554934","rc":[{"atl":[[3.05,2]],"id":65894825}],"con":true,"img":false}]}
{"op":"mcm","clk":"11450843838","pt":1717325976283,"mc":[{"id":"1.229554934","rc":[{"atl":[[3.5,6]],"id":65894825}],"con":true,"img":false}]}
{"op":"mcm","clk":"11450843846","pt":1717325976385,"mc":[{"id":"1.229554934","rc":[{"atl":[[3.45,0]],"id":65894825}],"con":true,"img":false}]}
{"op":"mcm","clk":"11450843865","pt":1717325976592,"mc":[{"id":"1.229554934","rc":[{"atl":[[3.45,6.12],[3.5,0]],"id":65894825}],"con":true,"img":false}]}
{"op":"mcm","clk":"11450843942","pt":1717325977272,"mc":[{"id":"1.229554934","rc":[{"atb":[[1.44,13.29],[1.54,10.83]],"id":47530316},{"atb":[[2.3,9.07],[2.1,10.73]],"id":65894825}],"con":true,"img":false}]}
{"op":"mcm","clk":"11450843958","pt":1717325977481,"mc":[{"id":"1.229554934","rc":[{"atl":[[3.45,0],[3.5,6]],"id":65894825}],"con":true,"img":false}]}
{"op":"mcm","clk":"11450843968","pt":1717325977586,"mc":[{"id":"1.229554934","rc":[{"atl":[[2,22],[1.97,15],[2.18,68.95],[1.95,10],[2.08,33]],"id":47530316}],"con":true,"img":false}]}
{"op":"mcm","clk":"11450843979","pt":1717325977688,"mc":[{"id":"1.229554934","rc":[{"atl":[[2,24],[2.02,17.24],[2.18,66.95],[2.2,20.83]],"id":47530316}],"con":true,"img":false}]}
{"op":"mcm","clk":"11450844004","pt":1717325977898,"mc":[{"id":"1.229554934","rc":[{"atl":[[3.45,6.12],[3.5,0]],"id":65894825}],"con":true,"img":false}]}
{"op":"mcm","clk":"11450844086","pt":1717325978573,"mc":[{"id":"1.229554934","rc":[{"atl":[[3.5,6]],"id":65894825}],"con":true,"img":false}]}
{"op":"mcm","clk":"11450844097","pt":1717325978674,"mc":[{"id":"1.229554934","rc":[{"atl":[[3.45,0]],"id":65894825}],"con":true,"img":false}]}
{"op":"mcm","clk":"11450844109","pt":1717325978781,"mc":[{"id":"1.229554934","rc":[{"atl":[[2,22],[2.02,19.24]],"id":47530316},{"atb":[[1.9,3.27],[1.96,0]],"id":65894825},{"atl":[[3.45,6.12],[3.5,0]],"id":65894825}],"con":true,"img":false}]}
{"op":"mcm","clk":"11450844267","pt":1717325980599,"mc":[{"id":"1.229554934","rc":[{"atb":[[1.47,0]],"id":47530316},{"atl":[[3.45,0],[3.6,7.69],[3.05,0],[3.65,5.66]],"id":65894825}],"con":true,"img":false}]}
{"op":"mcm","clk":"11450844281","pt":1717325980705,"mc":[{"id":"1.229554934","rc":[{"atb":[[1.42,2]],"id":47530316},{"atl":[[3.85,18.52],[3.25,3.27]],"id":65894825}],"con":true,"img":false}]}
{"op":"mcm","clk":"11450844289","pt":1717325980763,"mc":[{"id":"1.229554934","rc":[{"atl":[[3.6,0]],"id":65894825}],"con":true,"img":false}]}
{"op":"mcm","clk":"11450844320","pt":1717325981069,"mc":[{"id":"1.229554934","rc":[{"atb":[[1.79,0],[1.97,103.09]],"id":65894825}],"con":true,"img":false}]}
{"op":"mcm","clk":"11450844409","pt":1717325982002,"mc":[{"id":"1.229554934","rc":[{"atb":[[1.2,10],[1.18,15],[1.15,22],[1.11,33],[1.06,50]],"id":47530316}],"con":true,"img":false}]}
{"op":"mcm","clk":"11450844614","pt":1717325983874,"mc":[{"id":"1.229554934","rc":[{"atl":[[3.75,7.27]],"id":65894825}],"con":true,"img":false}]}
{"op":"mcm","clk":"11450844874","pt":1717325986378,"mc":[{"id":"1.229554934","rc":[{"atb":[[1.44,0],[1.54,0]],"id":47530316},{"atb":[[2.3,0],[2.1,0]],"id":65894825}],"con":true,"img":false}]}
{"op":"mcm","clk":"11450844884","pt":1717325986485,"mc":[{"id":"1.229554934","rc":[{"atb":[[1.28,0],[1.17,33]],"id":47530316}],"con":true,"img":false}]}
{"op":"mcm","clk":"11450845211","pt":1717325989396,"mc":[{"id":"1.229554934","rc":[{"atb":[[2,20.92],[1.97,0]],"id":65894825}],"con":true,"img":false}]}
{"op":"mcm","clk":"11450845403","pt":1717325991181,"mc":[{"id":"1.229554934","rc":[{"atl":[[3.45,2]],"id":65894825}],"con":true,"img":false}]}
{"op":"mcm","clk":"11450845416","pt":1717325991286,"mc":[{"id":"1.229554934","rc":[{"atb":[[1.42,0]],"id":47530316},{"atl":[[3.85,0],[3.7,0],[3.8,0],[3.25,0],[3.65,0],[3.75,0]],"id":65894825}],"con":true,"img":false}]}
{"op":"mcm","clk":"11450845430","pt":1717325991387,"mc":[{"id":"1.229554934","rc":[{"atb":[[1.39,2]],"id":47530316},{"atb":[[2,7.84],[2.04,20.93]],"id":65894825},{"atl":[[4.2,14.54]],"id":65894825}],"con":true,"img":false}]}
{"op":"mcm","clk":"11450845440","pt":1717325991489,"mc":[{"id":"1.229554934","rc":[{"atb":[[1.27,15],[1.17,0]],"id":47530316},{"atl":[[4,6.67],[11,10],[4.4,8.82],[3.9,5.17],[4.2,7.81]],"id":65894825}],"con":true,"img":false}]}
{"op":"mcm","clk":"11450845446","pt":1717325991591,"mc":[{"id":"1.229554934","rc":[{"atb":[[1.27,0],[1.17,33]],"id":47530316},{"atl":[[4.2,18.15]],"id":65894825}],"con":true,"img":false}]}
{"op":"mcm","clk":"11450845457","pt":1717325991693,"mc":[{"id":"1.229554934","rc":[{"atl":[[11,0]],"id":65894825}],"con":true,"img":false}]}
{"op":"mcm","clk":"11450845577","pt":1717325992997,"mc":[{"id":"1.229554934","rc":[{"atb":[[1.44,13.29],[1.54,10.83]],"id":47530316},{"atb":[[2.3,9.07],[2.1,10.73]],"id":65894825}],"con":true,"img":false}]}
{"op":"mcm","clk":"11450845588","pt":1717325993102,"mc":[{"id":"1.229554934","rc":[{"atb":[[1.27,21.66]],"id":47530316}],"con":true,"img":false}]}
{"op":"mcm","clk":"11450845601","pt":1717325993211,"mc":[{"id":"1.229554934","rc":[{"atb":[[1.17,0]],"id":47530316}],"con":true,"img":false}]}
{"op":"mcm","clk":"11450846216","pt":1717325999322,"mc":[{"id":"1.229554934","rc":[{"atb":[[1.44,0],[1.54,0]],"id":47530316},{"atb":[[2.3,0],[2.1,0]],"id":65894825}],"con":true,"img":false}]}
{"op":"mcm","clk":"11450846227","pt":1717325999423,"mc":[{"id":"1.229554934","rc":[{"atb":[[1.17,33]],"id":47530316}],"con":true,"img":false}]}
{"op":"mcm","clk":"11450846233","pt":1717325999526,"mc":[{"id":"1.229554934","rc":[{"atb":[[1.27,0]],"id":47530316}],"con":true,"img":false}]}
{"op":"mcm","clk":"11450846276","pt":1717325999998,"mc":[{"id":"1.229554934","rc":[{"atl":[[2.12,13.39],[2.14,0]],"id":47530316}],"con":true,"img":false}]}
{"op":"mcm","clk":"11450846440","pt":1717326001207,"mc":[{"id":"1.229554934","rc":[{"atb":[[2.04,0],[2.08,13.08]],"id":65894825}],"con":true,"img":false}]}
{"op":"mcm","clk":"11450846497","pt":1717326001625,"mc":[{"id":"1.229554934","rc":[{"atb":[[1.44,13.29],[1.54,10.83]],"id":47530316},{"atb":[[2.3,9.07],[2.1,10.73]],"id":65894825}],"con":true,"img":false}]}
{"op":"mcm","clk":"11450846510","pt":1717326001731,"mc":[{"id":"1.229554934","rc":[{"atb":[[1.27,21.66]],"id":47530316}],"con":true,"img":false}]}
{"op":"mcm","clk":"11450846524","pt":1717326001839,"mc":[{"id":"1.229554934","rc":[{"atb":[[1.17,0]],"id":47530316}],"con":true,"img":false}]}
{"op":"mcm","clk":"11450847483","pt":1717326010239,"mc":[{"id":"1.229554934","rc":[{"atb":[[1.44,0],[1.54,0]],"id":47530316},{"atb":[[2.3,0],[2.1,0]],"id":65894825}],"con":true,"img":false}]}
{"op":"mcm","clk":"11450847493","pt":1717326010344,"mc":[{"id":"1.229554934","rc":[{"atb":[[1.27,0],[1.17,33]],"id":47530316},{"atb":[[2.1,13.08]],"id":65894825}],"con":true,"img":false}]}
{"op":"mcm","clk":"11450847504","pt":1717326010447,"mc":[{"id":"1.229554934","rc":[{"atb":[[2.08,0]],"id":65894825}],"con":true,"img":false}]}
{"op":"mcm","clk":"11450847622","pt":1717326011948,"mc":[{"id":"1.229554934","rc":[{"atl":[[3.85,5.26],[3.9,0]],"id":65894825}],"con":true,"img":false}]}
{"op":"mcm","clk":"11450847690","pt":1717326012530,"mc":[{"id":"1.229554934","rc":[{"atb":[[1.44,13.29],[1.54,10.83]],"id":47530316},{"atb":[[2.28,9.22],[2.08,10.92]],"id":65894825}],"con":true,"img":false}]}
{"op":"mcm","clk":"11450847725","pt":1717326012844,"mc":[{"id":"1.229554934","rc":[{"atb":[[1.28,21.66],[1.17,0]],"id":47530316}],"con":true,"img":false}]}
{"op":"mcm","clk":"11450848194","pt":1717326017067,"mc":[{"id":"1.229554934","rc":[{"atb":[[2.14,15.76]],"id":65894825},{"atl":[[3.85,0],[3.9,5.17]],"id":65894825}],"con":true,"img":false}]}
{"op":"mcm","clk":"11450848204","pt":1717326017125,"mc":[{"id":"1.229554934","rc":[{"atb":[[2.1,0]],"id":65894825}],"con":true,"img":false}]}
{"op":"mcm","clk":"11450848216","pt":1717326017230,"mc":[{"id":"1.229554934","rc":[{"atl":[[3.45,0],[3.5,2]],"id":65894825}],"con":true,"img":false}]}
{"op":"mcm","clk":"11450848278","pt":1717326017746,"mc":[{"id":"1.229554934","rc":[{"atb":[[1.28,0]],"id":47530316},{"atb":[[2.14,0]],"id":65894825}],"con":true,"img":false}]}
{"op":"mcm","clk":"11450848294","pt":1717326017853,"mc":[{"id":"1.229554934","rc":[{"atb":[[1.23,21.66]],"id":47530316},{"atb":[[1.95,71.69]],"id":65894825}],"con":true,"img":false}]}
{"op":"mcm","clk":"11450848459","pt":1717326019476,"mc":[{"id":"1.229554934","rc":[{"atb":[[1.44,0],[1.54,0]],"id":47530316},{"atb":[[2.28,0],[2.08,0]],"id":65894825}],"con":true,"img":false}]}
{"op":"mcm","clk":"11450848474","pt":1717326019679,"mc":[{"id":"1.229554934","rc":[{"atb":[[1.23,0]],"id":47530316}],"con":true,"img":false}]}
{"op":"mcm","clk":"11450848484","pt":1717326019786,"mc":[{"id":"1.229554934","rc":[{"atb":[[1.17,33]],"id":47530316}],"con":true,"img":false}]}
{"op":"mcm","clk":"11450848548","pt":1717326020410,"mc":[{"id":"1.229554934","rc":[{"atl":[[2.12,0]],"id":47530316}],"con":true,"img":false}]}
{"op":"mcm","clk":"11450848686","pt":1717326021865,"mc":[{"id":"1.229554934","rc":[{"atb":[[1.43,13.6],[1.53,11.03]],"id":47530316},{"atb":[[2.32,8.94],[2.12,10.53]],"id":65894825}],"con":true,"img":false}]}
{"op":"mcm","clk":"11450848714","pt":1717326022179,"mc":[{"id":"1.229554934","rc":[{"atl":[[2.14,13.16]],"id":47530316},{"atl":[[3.95,5.08],[3.9,0]],"id":65894825}],"con":true,"img":false}]}
{"op":"mcm","clk":"11450848898","pt":1717326024047,"mc":[{"id":"1.229554934","rc":[{"atl":[[4,15.49],[3.95,0],[3.5,0],[3.3,3.27],[4.2,7.81],[3.75,5.45]],"id":65894825}],"con":true,"img":false}]}
{"op":"mcm","clk":"11450848925","pt":1717326024208,"mc":[{"id":"1.229554934","rc":[{"atb":[[2.12,26.01],[1.95,0]],"id":65894825}],"con":true,"img":false}]}
{"op":"mcm","clk":"11450849035","pt":1717326024886,"mc":[{"id":"1.229554934","rc":[{"atb":[[1.29,22.08],[1.17,0]],"id":47530316}],"con":true,"img":false}]}
{"op":"mcm","clk":"11450849208","pt":1717326026592,"mc":[{"id":"1.229554934","rc":[{"atl":[[3.85,7.02]],"id":65894825}],"con":true,"img":false}]}
{"op":"mcm","clk":"11450849263","pt":1717326027215,"mc":[{"id":"1.229554934","rc":[{"atb":[[2.12,10.53],[2.16,15.48]],"id":65894825},{"atl":[[4,8.82],[3.85,5.26],[4.4,0],[3.3,0],[4.2,0],[3.75,0]],"id":65894825}],"con":true,"img":false}]}
{"op":"mcm","clk":"11450849274","pt":1717326027316,"mc":[{"id":"1.229554934","rc":[{"atl":[[4,0],[4.1,14.08],[3.4,3.27]],"id":65894825}],"con":true,"img":false}]}
{"op":"mcm","clk":"11450849308","pt":1717326027422,"mc":[{"id":"1.229554934","rc":[{"atb":[[1.29,0]],"id":47530316},{"atb":[[1.98,71.69]],"id":65894825}],"con":true,"img":false}]}
{"op":"mcm","clk":"11450849317","pt":1717326027521,"mc":[{"id":"1.229554934","rc":[{"atb":[[1.24,22.08]],"id":47530316},{"atb":[[2.16,0]],"id":65894825}],"con":true,"img":false}]}
{"op":"mcm","clk":"11450849343","pt":1717326027783,"mc":[{"id":"1.229554934","rc":[{"atb":[[1.98,0],[2.16,15.48]],"id":65894825}],"con":true,"img":false}]}
{"op":"mcm","clk":"11450849566","pt":1717326029803,"mc":[{"id":"1.229554934","rc":[{"atl":[[3.95,6.78]],"id":65894825}],"con":true,"img":false}]}
{"op":"mcm","clk":"11450849817","pt":1717326032305,"mc":[{"id":"1.229554934","rc":[{"atl":[[4.1,22.14]],"id":65894825}],"con":true,"img":false}]}
{"op":"mcm","clk":"11450850101","pt":1717326034727,"mc":[{"id":"1.229554934","rc":[{"atl":[[4.3,9.09]],"id":65894825}],"con":true,"img":false}]}
{"op":"mcm","clk":"11450850173","pt":1717326035402,"mc":[{"id":"1.229554934","rc":[{"atb":[[2.2,24.41],[2.16,0]],"id":65894825}],"con":true,"img":false}]}
{"op":"mcm","clk":"11450850273","pt":1717326036338,"mc":[{"id":"1.229554934","rc":[{"atb":[[1.43,0],[1.53,0]],"id":47530316},{"atb":[[2.32,0],[2.12,0]],"id":65894825}],"con":true,"img":false}]}
{"op":"mcm","clk":"11450850282","pt":1717326036392,"mc":[{"id":"1.229554934","rc":[{"atb":[[1.17,33]],"id":47530316}],"con":true,"img":false}]}
{"op":"mcm","clk":"11450850293","pt":1717326036492,"mc":[{"id":"1.229554934","rc":[{"atb":[[1.24,0]],"id":47530316}],"con":true,"img":false}]}
{"op":"mcm","clk":"11450850895","pt":1717326042520,"mc":[{"id":"1.229554934","rc":[{"atb":[[1.43,13.6],[1.53,11.03]],"id":47530316},{"atb":[[2.32,8.94],[2.12,10.53],[2.18,48.84],[2.2,6.53]],"id":65894825},{"atl":[[3.85,0],[3.7,5.56],[3.4,0],[3.3,2]],"id":65894825}],"con":true,"img":false}]}
{"op":"mcm","clk":"11450850906","pt":1717326042625,"mc":[{"id":"1.229554934","rc":[{"atl":[[4.1,8.06],[3.9,9.09]],"id":65894825}],"con":true,"img":false}]}
{"op":"mcm","clk":"11450850920","pt":1717326042733,"mc":[{"id":"1.229554934","rc":[{"atb":[[1.29,22.08],[1.17,0]],"id":47530316}],"con":true,"img":false}]}
{"op":"mcm","clk":"11450851132","pt":1717326044819,"mc":[{"id":"1.229554934","rc":[{"atl":[[3.8,7.14]],"id":65894825}],"con":true,"img":false}]}
{"op":"mcm","clk":"11450851185","pt":1717326045394,"mc":[{"id":"1.229554934","rc":[{"atl":[[4.3,0],[3.95,0],[4.1,0]],"id":65894825}],"con":true,"img":false}]}
{"op":"mcm","clk":"11450851348","pt":1717326047166,"mc":[{"id":"1.229554934","rc":[{"atl":[[3.9,17.71]],"id":65894825}],"con":true,"img":false}]}
{"op":"mcm","clk":"11450851396","pt":1717326047624,"mc":[{"id":"1.229554934","rc":[{"atl":[[3.25,2],[3.3,0],[3.65,5.66]],"id":65894825}],"con":true,"img":false}]}
{"op":"mcm","clk":"11450851406","pt":1717326047727,"mc":[{"id":"1.229554934","rc":[{"atl":[[3.85,11.12]],"id":65894825}],"con":true,"img":false}]}
{"op":"mcm","clk":"11450851414","pt":1717326047832,"mc":[{"id":"1.229554934","rc":[{"atl":[[3.9,8.62]],"id":65894825}],"con":true,"img":false}]}
{"op":"mcm","clk":"11450851580","pt":1717326049646,"mc":[{"id":"1.229554934","rc":[{"atb":[[1.43,0],[1.53,0]],"id":47530316},{"atb":[[2.32,0],[2.12,0]],"id":65894825}],"con":true,"img":false}]}
{"op":"mcm","clk":"11450851586","pt":1717326049697,"mc":[{"id":"1.229554934","rc":[{"atb":[[1.17,33]],"id":47530316}],"con":true,"img":false}]}
{"op":"mcm","clk":"11450851592","pt":1717326049800,"mc":[{"id":"1.229554934","rc":[{"atb":[[1.29,0]],"id":47530316}],"con":true,"img":false}]}
{"op":"mcm","clk":"11450851601","pt":1717326049904,"mc":[{"id":"1.229554934","rc":[{"atb":[[2.22,1.89]],"id":65894825}],"con":true,"img":false}]}
{"op":"mcm","clk":"11450851609","pt":1717326050012,"mc":[{"id":"1.229554934","rc":[{"atb":[[2.18,0],[2.2,14.38]],"id":65894825}],"con":true,"img":false}]}
{"op":"mcm","clk":"11450851672","pt":1717326050532,"mc":[{"id":"1.229554934","rc":[{"atb":[[2.22,0]],"id":65894825}],"con":true,"img":false}]}
{"op":"mcm","clk":"11450851901","pt":1717326052927,"mc":[{"id":"1.229554934","rc":[{"atb":[[1.44,2],[1.39,0]],"id":47530316},{"atb":[[2.18,28.78],[2.2,6.53]],"id":65894825},{"atl":[[3.6,5.77],[3.85,0],[3.25,0],[3.15,2],[3.65,0],[3.75,11.12]],"id":65894825}],"con":true,"img":false}]}
{"op":"mcm","clk":"11450851936","pt":1717326053349,"mc":[{"id":"1.229554934","rc":[{"atb":[[1.4,14.62],[1.5,11.7]],"id":47530316},{"atb":[[2.38,8.55],[2.18,38.78]],"id":65894825}],"con":true,"img":false}]}
{"op":"mcm","clk":"11450851977","pt":1717326053611,"mc":[{"id":"1.229554934","rc":[{"atb":[[1.51,1.8]],"id":47530316}],"con":true,"img":false}]}
{"op":"mcm","clk":"11450852087","pt":1717326054808,"mc":[{"id":"1.229554934","rc":[{"atb":[[1.31,15],[1.17,0]],"id":47530316}],"con":true,"img":false}]}
{"op":"mcm","clk":"11450852476","pt":1717326058625,"mc":[{"id":"1.229554934","rc":[{"atb":[[1.67,15.69]],"id":47530316}],"con":true,"img":false}]}
{"op":"mcm","clk":"11450852510","pt":1717326058940,"mc":[{"id":"1.229554934","rc":[{"atb":[[1.51,0]],"id":47530316}],"con":true,"img":false}]}
{"op":"mcm","clk":"11450852541","pt":1717326059150,"mc":[{"id":"1.229554934","rc":[{"atb":[[2.2,31.39]],"id":65894825}],"con":true,"img":false}]}
{"op":"mcm","clk":"11450852680","pt":1717326060571,"mc":[{"id":"1.229554934","rc":[{"atb":[[1.2,0],[1.18,0],[1.4,0],[1.15,0],[1.11,0],[1.5,0],[1.06,0]],"id":47530316},{"atl":[[2,0],[1.97,0],[2.18,16.95],[1.95,0],[2.08,0]],"id":47530316},{"atb":[[2.38,0],[2.18,28.78]],"id":65894825}],"con":true,"img":false}]}
{"op":"mcm","clk":"11450852696","pt":1717326060729,"mc":[{"id":"1.229554934","rc":[{"atl":[[2.02,0],[2.16,19.24]],"id":47530316},{"atb":[[2.22,1.89],[2.18,0],[2.2,60.17]],"id":65894825}],"con":true,"img":false}]}
{"op":"mcm","clk":"11450852730","pt":1717326061147,"mc":[{"id":"1.229554934","rc":[{"atb":[[2.2,35.31],[2.14,26.16]],"id":65894825}],"con":true,"img":false}]}
{"op":"mcm","clk":"11450852750","pt":1717326061355,"mc":[{"id":"1.229554934","rc":[{"atb":[[2.22,0]],"id":65894825}],"con":true,"img":false}]}
{"op":"mcm","clk":"11450852758","pt":1717326061460,"mc":[{"id":"1.229554934","rc":[{"atb":[[2,0],[2.2,0],[2.14,0]],"id":65894825},{"trd":[[2,15.69],[2.2,70.63],[2.14,52.31]],"ltp":2.0,"tv":138.63,"id":65894825},{"atl":[[2,192.26]],"id":65894825}],"con":true,"img":false}]}
{"op":"mcm","clk":"11450852772","pt":1717326061565,"mc":[{"id":"1.229554934","rc":[{"atb":[[1.31,0]],"id":47530316},{"atb":[[1.9,0]],"id":65894825},{"trd":[[2,215.69]],"ltp":2.0,"tv":215.69,"id":65894825},{"atl":[[2,92.26]],"id":65894825}],"con":true,"img":false}]}
{"op":"mcm","clk":"11450852783","pt":1717326061618,"mc":[{"id":"1.229554934","rc":[{"atb":[[1.26,65.12]],"id":47530316},{"atb":[[1.59,140.11],[1.79,2]],"id":65894825}],"con":true,"img":false}]}
{"op":"mcm","clk":"11450852789","pt":1717326061724,"mc":[{"id":"1.229554934","rc":[{"atb":[[1.44,0]],"id":47530316},{"atb":[[1.89,14.26],[1.84,18.13],[1.88,11.54],[1.91,11.15],[1.9,8.46],[1.86,14.75],[1.93,8.19],[1.87,17.5]],"id":65894825},{"atl":[[3.6,0],[5.1,14.28],[2.3,6.88],[3.7,0],[3.8,0],[3.15,0],[3.75,0]],"id":65894825}],"con":true,"img":false}]}
{"op":"mcm","clk":"11450852801","pt":1717326061829,"mc":[{"id":"1.229554934","rc":[{"atb":[[1.41,2]],"id":47530316},{"atb":[[1.79,0],[1.87,19.5]],"id":65894825},{"atl":[[3.35,2]],"id":65894825}],"con":true,"img":false}]}
{"op":"mcm","clk":"11450852812","pt":1717326061933,"mc":[{"id":"1.229554934","rc":[{"atb":[[1.89,0],[1.84,0],[1.88,0],[1.91,0],[1.9,0],[1.86,0],[1.93,0],[1.87,2]],"id":65894825},{"atl":[[1.99,5.08]],"id":65894825}],"con":true,"img":false}]}
{"op":"mcm","clk":"11450852832","pt":1717326062139,"mc":[{"id":"1.229554934","rc":[{"atb":[[2.02,29.1]],"id":47530316},{"trd":[[2.02,0.25]],"ltp":2.02,"tv":0.25,"id":47530316},{"atl":[[2.14,14.01]],"id":47530316},{"atb":[[1.87,36.28]],"id":65894825}],"con":true,"img":false}]}
{"op":"mcm","clk":"11450852842","pt":1717326062245,"mc":[{"id":"1.229554934","rc":[{"atb":[[2.02,20.07]],"id":47530316},{"trd":[[2.02,18.31]],"ltp":2.02,"tv":18.31,"id":47530316},{"atb":[[1.6,1.04]],"id":65894825},{"atl":[[1.99,0]],"id":65894825}],"con":true,"img":false}]}
{"op":"mcm","clk":"11450852867","pt":1717326062455,"mc":[{"id":"1.229554934","rc":[{"atb":[[1.89,14.26],[1.91,11.15],[1.87,53.78],[1.93,8.19]],"id":65894825},{"atl":[[4,15.5],[5.1,0]],"id":65894825}],"con":true,"img":false}]}
{"op":"mcm","clk":"11450852888","pt":1717326062614,"mc":[{"id":"1.229554934","rc":[{"atb":[[2.02,0]],"id":47530316}],"con":true,"img":false}]}
{"op":"mcm","clk":"11450852898","pt":1717326062718,"mc":[{"id":"1.229554934","rc":[{"atl":[[2.14,13.16]],"id":47530316}],"con":true,"img":false}]}
{"op":"mcm","clk":"11450852908","pt":1717326062823,"mc":[{"id":"1.229554934","rc":[{"atl":[[970,0.85]],"id":47530316}],"con":true,"img":false}]}
{"op":"mcm","clk":"11450852936","pt":1717326063134,"mc":[{"id":"1.229554934","rc":[{"atb":[[2,29.82]],"id":47530316},{"atb":[[1.89,47.77]],"id":65894825}],"con":true,"img":false}]}
{"op":"mcm","clk":"11450853037","pt":1717326064226,"mc":[{"id":"1.229554934","rc":[{"atb":[[1.4,32.61],[1.5,26.09]],"id":47530316},{"atb":[[1.81,4.88],[1.71,5.57]],"id":65894825}],"con":true,"img":false}]}
{"op":"mcm","clk":"11450853058","pt":1717326064436,"mc":[{"id":"1.229554934","rc":[{"atb":[[1.92,8.28]],"id":65894825}],"con":true,"img":false}]}
{"op":"mcm","clk":"11450853070","pt":1717326064539,"mc":[{"id":"1.229554934","rc":[{"atb":[[1.93,0]],"id":65894825}],"con":true,"img":false}]}
{"op":"mcm","clk":"11450853084","pt":1717326064643,"mc":[{"id":"1.229554934","rc":[{"atb":[[1.92,0],[1.93,8.19]],"id":65894825}],"con":true,"img":false}]}
{"op":"mcm","clk":"11450853218","pt":1717326065846,"mc":[{"id":"1.229554934","rc":[{"atl":[[2.18,18.95]],"id":47530316},{"atb":[[1.59,0],[1.9,47.78]],"id":65894825}],"con":true,"img":false}]}
{"op":"mcm","clk":"11450853227","pt":1717326065948,"mc":[{"id":"1.229554934","rc":[{"atl":[[2.16,17.24]],"id":47530316}],"con":true,"img":false}]}
{"op":"mcm","clk":"11450853258","pt":1717326066256,"mc":[{"id":"1.229554934","rc":[{"atb":[[2,0]],"id":47530316},{"trd":[[2,67.19]],"ltp":2.0,"tv":67.19,"id":47530316},{"trd":[[2,223.23]],"ltp":2.0,"tv":223.23,"id":65894825},{"atl":[[2,84.71]],"id":65894825}],"con":true,"img":false}]}
{"op":"mcm","clk":"11450853287","pt":1717326066575,"mc":[{"id":"1.229554934","rc":[{"atb":[[1.92,8.28],[1.93,0]],"id":65894825}],"con":true,"img":false}]}
{"op":"mcm","clk":"11450853455","pt":1717326068231,"mc":[{"id":"1.229554934","rc":[{"atb":[[1.86,2],[1.87,51.78]],"id":65894825}],"con":true,"img":false}]}
{"op":"mcm","clk":"11450853525","pt":1717326068962,"mc":[{"id":"1.229554934","rc":[{"atb":[[1.92,0],[1.9,56.24]],"id":65894825}],"con":true,"img":false}]}
{"op":"mcm","clk":"11450853550","pt":1717326069225,"mc":[{"id":"1.229554934","rc":[{"atb":[[1.89,56.32],[1.91,0]],"id":65894825}],"con":true,"img":false}]}
{"op":"mcm","clk":"11450853564","pt":1717326069329,"mc":[{"id":"1.229554934","rc":[{"atb":[[1.89,42.06]],"id":65894825}],"con":true,"img":false}]}
{"op":"mcm","clk":"11450853616","pt":1717326069647,"mc":[{"id":"1.229554934","rc":[{"atb":[[1.9,47.78]],"id":65894825}],"con":true,"img":false}]}
{"op":"mcm","clk":"11450853649","pt":1717326069956,"mc":[{"id":"1.229554934","rc":[{"atb":[[1.9,56.24]],"id":65894825}],"con":true,"img":false}]}
{"op":"mcm","clk":"11450853695","pt":1717326070369,"mc":[{"id":"1.229554934","rc":[{"atb":[[1.92,8.28]],"id":65894825}],"con":true,"img":false}]}
{"op":"mcm","clk":"11450853809","pt":1717326071357,"mc":[{"id":"1.229554934","rc":[{"atb":[[1.92,0]],"id":65894825}],"con":true,"img":false}]}
{"op":"mcm","clk":"11450853824","pt":1717326071459,"mc":[{"id":"1.229554934","rc":[{"atl":[[2,0]],"id":65894825}],"con":true,"img":false}]}
{"op":"mcm","clk":"11450853835","pt":1717326071564,"mc":[{"id":"1.229554934","rc":[{"atb":[[1.92,8.28]],"id":65894825},{"atl":[[3.7,5.56]],"id":65894825}],"con":true,"img":false}]}
{"op":"mcm","clk":"11450853846","pt":1717326071667,"mc":[{"id":"1.229554934","rc":[{"atb":[[1.89,8.55],[1.9,8.46],[1.87,17.5],[1.93,42.07]],"id":65894825}],"con":true,"img":false}]}
{"op":"mcm","clk":"11450853867","pt":1717326071824,"mc":[{"id":"1.229554934","rc":[{"atl":[[2.12,1.41]],"id":47530316},{"atb":[[1.92,0],[1.6,0],[1.9,58.81],[1.93,0]],"id":65894825},{"atl":[[2.3,0],[3.7,0],[3.75,5.45]],"id":65894825}],"con":true,"img":false}]}
{"op":"mcm","clk":"11450853877","pt":1717326071928,"mc":[{"id":"1.229554934","rc":[{"atl":[[2.12,3.41],[1000,2.17]],"id":47530316},{"atb":[[1.94,1.04],[1.87,84.86]],"id":65894825},{"atl":[[3.35,0],[3.3,2]],"id":65894825}],"con":true,"img":false}]}
{"op":"mcm","clk":"11450853888","pt":1717326072035,"mc":[{"id":"1.229554934","rc":[{"atl":[[2.12,1.41],[2.18,16.95],[2.16,19.24]],"id":47530316},{"atb":[[1.9,8.46],[1.94,9.59]],"id":65894825},{"atl":[[4,0],[3.95,10.9]],"id":65894825}],"con":true,"img":false}]}
{"op":"mcm","clk":"11450853894","pt":1717326072139,"mc":[{"id":"1.229554934","rc":[{"atl":[[2.12,3.41],[2.16,17.24]],"id":47530316},{"atb":[[1.89,68.41],[1.91,1.89],[1.87,17.5]],"id":65894825}],"con":true,"img":false}]}
{"op":"mcm","clk":"11450853914","pt":1717326072300,"mc":[{"id":"1.229554934","rc":[{"atb":[[1.94,1.04]],"id":65894825}],"con":true,"img":false}]}
{"op":"mcm","clk":"11450853924","pt":1717326072353,"mc":[{"id":"1.229554934","rc":[{"atb":[[1.89,8.55],[1.94,9.5]],"id":65894825},{"atl":[[3.75,6.3]],"id":65894825}],"con":true,"img":false}]}
{"op":"mcm","clk":"11450853966","pt":1717326072769,"mc":[{"id":"1.229554934","rc":[{"atb":[[1.91,0]],"id":65894825}],"con":true,"img":false}]}
{"op":"mcm","clk":"11450854038","pt":1717326073347,"mc":[{"id":"1.229554934","rc":[{"atb":[[1.92,2],[1.86,0]],"id":65894825}],"con":true,"img":false}]}
{"op":"mcm","clk":"11450854046","pt":1717326073451,"mc":[{"id":"1.229554934","rc":[{"atl":[[3.35,2],[3.8,5.36],[3.3,0],[3.75,0.42]],"id":65894825}],"con":true,"img":false}]}
{"op":"mcm","clk":"11450854128","pt":1717326074188,"mc":[{"id":"1.229554934","rc":[{"atl":[[3.75,0]],"id":65894825}],"con":true,"img":false}]}
{"op":"mcm","clk":"11450854137","pt":1717326074293,"mc":[{"id":"1.229554934","rc":[{"atl":[[3.8,5.78]],"id":65894825}],"con":true,"img":false}]}
{"op":"mcm","clk":"11450854247","pt":1717326075224,"mc":[{"id":"1.229554934","rc":[{"atb":[[1.88,11.54]],"id":65894825},{"atl":[[3.9,6.9]],"id":65894825}],"con":true,"img":false}]}
{"op":"mcm","clk":"11450854449","pt":1717326076989,"mc":[{"id":"1.229554934","rc":[{"atl":[[4,8.33]],"id":65894825}],"con":true,"img":false}]}
{"op":"mcm","clk":"11450854460","pt":1717326077090,"mc":[{"id":"1.229554934","rc":[{"atb":[[1.9,0]],"id":65894825}],"con":true,"img":false}]}
{"op":"mcm","clk":"11450854599","pt":1717326078398,"mc":[{"id":"1.229554934","rc":[{"atb":[[1.41,0]],"id":47530316},{"atb":[[1.92,0],[1.91,2]],"id":65894825},{"atl":[[3.45,2],[3.35,0],[3.8,0.42],[3.9,5.17]],"id":65894825}],"con":true,"img":false}]}
{"op":"mcm","clk":"11450854606","pt":1717326078496,"mc":[{"id":"1.229554934","rc":[{"atb":[[1.39,2]],"id":47530316},{"atl":[[3.95,0],[4.2,13.8]],"id":65894825}],"con":true,"img":false}]}
{"op":"mcm","clk":"11450854619","pt":1717326078599,"mc":[{"id":"1.229554934","rc":[{"atb":[[1.9,8.46]],"id":65894825}],"con":true,"img":false}]}
{"op":"mcm","clk":"11450854646","pt":1717326078910,"mc":[{"id":"1.229554934","rc":[{"atl":[[3.8,0]],"id":65894825}],"con":true,"img":false}]}
{"op":"mcm","clk":"11450854659","pt":1717326079013,"mc":[{"id":"1.229554934","rc":[{"atl":[[3.9,5.59]],"id":65894825}],"con":true,"img":false}]}
{"op":"mcm","clk":"11450854787","pt":1717326080311,"mc":[{"id":"1.229554934","rc":[{"atl":[[4,6.67]],"id":65894825}],"con":true,"img":false}]}
{"op":"mcm","clk":"11450854940","pt":1717326082011,"mc":[{"id":"1.229554934","rc":[{"atl":[[4.2,21.61]],"id":65894825}],"con":true,"img":false}]}
{"op":"mcm","clk":"11450855017","pt":1717326082790,"mc":[{"id":"1.229554934","rc":[{"atb":[[1.4,0],[1.5,0]],"id":47530316},{"atb":[[1.81,0],[1.71,0]],"id":65894825}],"con":true,"img":false}]}
{"op":"mcm","clk":"11450855112","pt":1717326083625,"mc":[{"id":"1.229554934","rc":[{"atl":[[3.45,0],[3.5,2]],"id":65894825}],"con":true,"img":false}]}
{"op":"mcm","clk":"11450855121","pt":1717326083721,"mc":[{"id":"1.229554934","rc":[{"atl":[[4.4,8.82]],"id":65894825}],"con":true,"img":false}]}
{"op":"mcm","clk":"11450855145","pt":1717326083936,"mc":[{"id":"1.229554934","rc":[{"atb":[[1.9,0]],"id":65894825}],"con":true,"img":false}]}
{"op":"mcm","clk":"11450855154","pt":1717326084033,"mc":[{"id":"1.229554934","rc":[{"atb":[[1.91,0],[1.9,2]],"id":65894825},{"atl":[[3.85,5.26],[3.95,5.08],[3.9,0.42]],"id":65894825}],"con":true,"img":false}]}
{"op":"mcm","clk":"11450855166","pt":1717326084093,"mc":[{"id":"1.229554934","rc":[{"atb":[[1.92,2],[1.9,0]],"id":65894825}],"con":true,"img":false}]}
{"op":"mcm","clk":"11450855176","pt":1717326084199,"mc":[{"id":"1.229554934","rc":[{"atb":[[1.9,8.46]],"id":65894825},{"atl":[[4,0],[4.4,0],[4.2,13.8]],"id":65894825}],"con":true,"img":false}]}
{"op":"mcm","clk":"11450855184","pt":1717326084293,"mc":[{"id":"1.229554934","rc":[{"atl":[[3.9,0]],"id":65894825}],"con":true,"img":false}]}
{"op":"mcm","clk":"11450855189","pt":1717326084400,"mc":[{"id":"1.229554934","rc":[{"atl":[[3.85,5.68]],"id":65894825}],"con":true,"img":false}]}
{"op":"mcm","clk":"11450855237","pt":1717326084924,"mc":[{"id":"1.229554934","rc":[{"atb":[[1.9,0]],"id":65894825}],"con":true,"img":false}]}
{"op":"mcm","clk":"11450855254","pt":1717326085129,"mc":[{"id":"1.229554934","rc":[{"atb":[[1.9,8.46]],"id":65894825}],"con":true,"img":false}]}
{"op":"mcm","clk":"11450855276","pt":1717326085337,"mc":[{"id":"1.229554934","rc":[{"atb":[[1.9,0],[1.93,8.19]],"id":65894825}],"con":true,"img":false}]}
{"op":"mcm","clk":"11450855295","pt":1717326085499,"mc":[{"id":"1.229554934","rc":[{"atb":[[1.9,8.46]],"id":65894825}],"con":true,"img":false}]}
{"op":"mcm","clk":"11450855303","pt":1717326085603,"mc":[{"id":"1.229554934","rc":[{"atb":[[1.93,0]],"id":65894825}],"con":true,"img":false}]}
{"op":"mcm","clk":"11450855393","pt":1717326086425,"mc":[{"id":"1.229554934","rc":[{"atb":[[1.9,0],[1.93,8.19]],"id":65894825}],"con":true,"img":false}]}
{"op":"mcm","clk":"11450855427","pt":1717326086735,"mc":[{"id":"1.229554934","rc":[{"atb":[[1.9,8.46]],"id":65894825}],"con":true,"img":false}]}
{"op":"mcm","clk":"11450855439","pt":1717326086834,"mc":[{"id":"1.229554934","rc":[{"atb":[[1.93,0]],"id":65894825}],"con":true,"img":false}]}
{"op":"mcm","clk":"11450855457","pt":1717326086995,"mc":[{"id":"1.229554934","rc":[{"atb":[[1.87,0]],"id":65894825}],"con":true,"img":false}]}
{"op":"mcm","clk":"11450855464","pt":1717326087094,"mc":[{"id":"1.229554934","rc":[{"atb":[[1.93,8.19]],"id":65894825}],"con":true,"img":false}]}
{"op":"mcm","clk":"11450855472","pt":1717326087200,"mc":[{"id":"1.229554934","rc":[{"atb":[[1.9,0]],"id":65894825}],"con":true,"img":false}]}
{"op":"mcm","clk":"11450855484","pt":1717326087309,"mc":[{"id":"1.229554934","rc":[{"atb":[[1.4,32.61],[1.5,26.09]],"id":47530316},{"atb":[[1.81,4.88],[1.71,5.57]],"id":65894825}],"con":true,"img":false}]}
{"op":"mcm","clk":"11450855500","pt":1717326087518,"mc":[{"id":"1.229554934","rc":[{"atb":[[1.9,8.46],[1.93,0]],"id":65894825}],"con":true,"img":false}]}
{"op":"mcm","clk":"11450855581","pt":1717326088298,"mc":[{"id":"1.229554934","rc":[{"atb":[[1.93,8.19]],"id":65894825}],"con":true,"img":false}]}
{"op":"mcm","clk":"11450855619","pt":1717326088606,"mc":[{"id":"1.229554934","rc":[{"atb":[[1.92,0],[1.91,2]],"id":65894825},{"atl":[[3.85,0.42],[3.9,5.17]],"id":65894825}],"con":true,"img":false}]}
{"op":"mcm","clk":"11450855641","pt":1717326088816,"mc":[{"id":"1.229554934","rc":[{"atl":[[3.45,2],[3.5,0]],"id":65894825}],"con":true,"img":false}]}
{"op":"mcm","clk":"11450855649","pt":1717326088930,"mc":[{"id":"1.229554934","rc":[{"atb":[[1.95,1.89]],"id":65894825}],"con":true,"img":false}]}
{"op":"mcm","clk":"11450855666","pt":1717326089127,"mc":[{"id":"1.229554934","rc":[{"atb":[[1.93,0]],"id":65894825}],"con":true,"img":false}]}
{"op":"mcm","clk":"11450855694","pt":1717326089444,"mc":[{"id":"1.229554934","rc":[{"atl":[[3.85,0]],"id":65894825}],"con":true,"img":false}]}
{"op":"mcm","clk":"11450855703","pt":1717326089546,"mc":[{"id":"1.229554934","rc":[{"atb":[[1.95,0],[1.93,8.19]],"id":65894825},{"atl":[[3.9,5.59]],"id":65894825}],"con":true,"img":false}]}
{"op":"mcm","clk":"11450855723","pt":1717326089706,"mc":[{"id":"1.229554934","rc":[{"atb":[[1.93,0]],"id":65894825}],"con":true,"img":false}]}
{"op":"mcm","clk":"11450855752","pt":1717326090016,"mc":[{"id":"1.229554934","rc":[{"atb":[[1.93,8.19]],"id":65894825}],"con":true,"img":false}]}
{"op":"mcm","clk":"11450855820","pt":1717326090537,"mc":[{"id":"1.229554934","rc":[{"atl":[[1000,3.06]],"id":47530316}],"con":true,"img":false}]}
{"op":"mcm","clk":"11450855843","pt":1717326090739,"mc":[{"id":"1.229554934","rc":[{"atb":[[1.93,0]],"id":65894825}],"con":true,"img":false}]}
{"op":"mcm","clk":"11450855868","pt":1717326090903,"mc":[{"id":"1.229554934","rc":[{"atl":[[1000,2.32]],"id":47530316},{"atb":[[1.93,8.19]],"id":65894825},{"atl":[[3.8,5.36]],"id":65894825}],"con":true,"img":false}]}
{"op":"mcm","clk":"11450855890","pt":1717326091114,"mc":[{"id":"1.229554934","rc":[{"atl":[[3.9,5.17]],"id":65894825}],"con":true,"img":false}]}
{"op":"mcm","clk":"11450855903","pt":1717326091217,"mc":[{"id":"1.229554934","rc":[{"atl":[[3.8,5.78]],"id":65894825}],"con":true,"img":false}]}
{"op":"mcm","clk":"11450855914","pt":1717326091320,"mc":[{"id":"1.229554934","rc":[{"atl":[[1000,2.17]],"id":47530316}],"con":true,"img":false}]}
{"op":"mcm","clk":"11450855925","pt":1717326091421,"mc":[{"id":"1.229554934","rc":[{"atb":[[1.67,15.54]],"id":47530316},{"trd":[[1.67,0.3]],"ltp":1.67,"tv":0.3,"id":47530316}],"con":true,"img":false}]}
{"op":"mcm","clk":"11450855936","pt":1717326091518,"mc":[{"id":"1.229554934","rc":[{"atb":[[1.93,0]],"id":65894825}],"con":true,"img":false}]}
{"op":"mcm","clk":"11450855944","pt":1717326091626,"mc":[{"id":"1.229554934","rc":[{"atb":[[1.93,8.19]],"id":65894825}],"con":true,"img":false}]}
{"op":"mcm","clk":"11450856000","pt":1717326092239,"mc":[{"id":"1.229554934","rc":[{"atb":[[1.93,0]],"id":65894825},{"atl":[[3.75,5.45]],"id":65894825}],"con":true,"img":false}]}
{"op":"mcm","clk":"11450856074","pt":1717326092923,"mc":[{"id":"1.229554934","rc":[{"atl":[[3.8,5.36]],"id":65894825}],"con":true,"img":false}]}
{"op":"mcm","clk":"11450856088","pt":1717326093023,"mc":[{"id":"1.229554934","rc":[{"atl":[[3.75,5.87]],"id":65894825}],"con":true,"img":false}]}
{"op":"mcm","clk":"11450856141","pt":1717326093595,"mc":[{"id":"1.229554934","rc":[{"atb":[[1.86,14.75]],"id":65894825}],"con":true,"img":false}]}
{"op":"mcm","clk":"11450856148","pt":1717326093706,"mc":[{"id":"1.229554934","rc":[{"atb":[[1.85,2],[1.91,0]],"id":65894825}],"con":true,"img":false}]}
{"op":"mcm","clk":"11450856156","pt":1717326093808,"mc":[{"id":"1.229554934","rc":[{"atl":[[2.14,0],[2.16,12.93]],"id":47530316}],"con":true,"img":false}]}
{"op":"mcm","clk":"11450856166","pt":1717326093910,"mc":[{"id":"1.229554934","rc":[{"atl":[[3.35,2]],"id":65894825}],"con":true,"img":false}]}
{"op":"mcm","clk":"11450856177","pt":1717326094015,"mc":[{"id":"1.229554934","rc":[{"atl":[[3.45,0]],"id":65894825}],"con":true,"img":false}]}
{"op":"mcm","clk":"11450856293","pt":1717326095208,"mc":[{"id":"1.229554934","rc":[{"atl":[[2.2,37.5]],"id":47530316}],"con":true,"img":false}]}
{"op":"mcm","clk":"11450856306","pt":1717326095306,"mc":[{"id":"1.229554934","rc":[{"atl":[[2.2,16.67]],"id":47530316}],"con":true,"img":false}]}
{"op":"mcm","clk":"11450856452","pt":1717326096707,"mc":[{"id":"1.229554934","rc":[{"atl":[[2.24,20.16]],"id":47530316}],"con":true,"img":false}]}
{"op":"mcm","clk":"11450856663","pt":1717326098838,"mc":[{"id":"1.229554934","rc":[{"atl":[[3.7,5.56],[3.9,15.89],[4.2,0],[3.75,0.42]],"id":65894825}],"con":true,"img":false}]}
{"op":"mcm","clk":"11450856681","pt":1717326099037,"mc":[{"id":"1.229554934","rc":[{"atl":[[3.35,0],[3.25,2]],"id":65894825}],"con":true,"img":false}]}
{"op":"mcm","clk":"11450856732","pt":1717326099554,"mc":[{"id":"1.229554934","rc":[{"atl":[[3.75,0]],"id":65894825}],"con":true,"img":false}]}
{"op":"mcm","clk":"11450856741","pt":1717326099653,"mc":[{"id":"1.229554934","rc":[{"atl":[[3.7,5.98]],"id":65894825}],"con":true,"img":false}]}
{"op":"mcm","clk":"11450857061","pt":1717326102615,"mc":[{"id":"1.229554934","rc":[{"atb":[[1.4,0],[1.5,0]],"id":47530316},{"atb":[[1.81,0],[1.71,0]],"id":65894825}],"con":true,"img":false}]}
{"op":"mcm","clk":"11450857184","pt":1717326103857,"mc":[{"id":"1.229554934","rc":[{"atb":[[1.85,0],[1.87,2]],"id":65894825},{"atl":[[3.6,5.77],[3.7,0.42]],"id":65894825}],"con":true,"img":false}]}
{"op":"mcm","clk":"11450857210","pt":1717326104132,"mc":[{"id":"1.229554934","rc":[{"atl":[[3.2,2],[3.25,0]],"id":65894825}],"con":true,"img":false}]}
{"op":"mcm","clk":"11450857217","pt":1717326104224,"mc":[{"id":"1.229554934","rc":[{"atl":[[3.8,10.72],[3.9,5.17]],"id":65894825}],"con":true,"img":false}]}
{"op":"mcm","clk":"11450857262","pt":1717326104639,"mc":[{"id":"1.229554934","rc":[{"atb":[[1.67,1.79]],"id":47530316},{"trd":[[1.67,27.79]],"ltp":1.67,"tv":27.79,"id":47530316}],"con":true,"img":false}]}
{"op":"mcm","clk":"11450857273","pt":1717326104744,"mc":[{"id":"1.229554934","rc":[{"atb":[[1.9,0],[1.94,17.6]],"id":65894825}],"con":true,"img":false}]}
{"op":"mcm","clk":"11450857282","pt":1717326104857,"mc":[{"id":"1.229554934","rc":[{"atb":[[1.89,26.52],[1.94,9.14]],"id":65894825}],"con":true,"img":false}]}
{"op":"mcm","clk":"11450857302","pt":1717326105156,"mc":[{"id":"1.229554934","rc":[{"atb":[[1.9,8.46],[1.94,1.04]],"id":65894825}],"con":true,"img":false}]}
{"op":"mcm","clk":"11450857379","pt":1717326105840,"mc":[{"id":"1.229554934","rc":[{"atb":[[1.91,1.89],[1.94,0]],"id":65894825}],"con":true,"img":false}]}
{"op":"mcm","clk":"11450857386","pt":1717326105936,"mc":[{"id":"1.229554934","rc":[{"atb":[[1.9,9.5]],"id":65894825}],"con":true,"img":false}]}
{"op":"mcm","clk":"11450857436","pt":1717326106351,"mc":[{"id":"1.229554934","rc":[{"atb":[[1.4,32.61],[1.5,26.09]],"id":47530316},{"atb":[[1.81,4.88],[1.71,5.57]],"id":65894825}],"con":true,"img":false}]}
{"op":"mcm","clk":"11450857501","pt":1717326107023,"mc":[{"id":"1.229554934","rc":[{"atb":[[1.51,2.84]],"id":47530316}],"con":true,"img":false}]}
{"op":"mcm","clk":"11450857603","pt":1717326108326,"mc":[{"id":"1.229554934","rc":[{"atb":[[1.9,1.04],[1.94,8.1]],"id":65894825}],"con":true,"img":false}]}
{"op":"mcm","clk":"11450857643","pt":1717326108851,"mc":[{"id":"1.229554934","rc":[{"atb":[[1.45,2],[1.39,0]],"id":47530316},{"atl":[[3.6,0],[3.55,5.88]],"id":65894825}],"con":true,"img":false}]}
{"op":"mcm","clk":"11450857652","pt":1717326108952,"mc":[{"id":"1.229554934","rc":[{"atb":[[1.91,0],[1.9,0]],"id":65894825}],"con":true,"img":false}]}
{"op":"mcm","clk":"11450857660","pt":1717326109057,"mc":[{"id":"1.229554934","rc":[{"atb":[[1.89,8.55],[1.88,46.16],[1.94,9.14]],"id":65894825}],"con":true,"img":false}]}
{"op":"mcm","clk":"11450857680","pt":1717326109264,"mc":[{"id":"1.229554934","rc":[{"atl":[[3.2,0],[3.15,2]],"id":65894825}],"con":true,"img":false}]}
{"op":"mcm","clk":"11450857692","pt":1717326109365,"mc":[{"id":"1.229554934","rc":[{"atl":[[3.7,8.3],[3.8,5.36]],"id":65894825}],"con":true,"img":false}]}
{"op":"mcm","clk":"11450857726","pt":1717326109772,"mc":[{"id":"1.229554934","rc":[{"atb":[[1.9,8.46]],"id":65894825},{"atl":[[3.7,7.88]],"id":65894825}],"con":true,"img":false}]}
{"op":"mcm","clk":"11450857737","pt":1717326109832,"mc":[{"id":"1.229554934","rc":[{"atb":[[1.94,1.04]],"id":65894825},{"atl":[[3.55,6.3]],"id":65894825}],"con":true,"img":false}]}
{"op":"mcm","clk":"11450857750","pt":1717326109936,"mc":[{"id":"1.229554934","rc":[{"atb":[[1.94,9.59]],"id":65894825}],"con":true,"img":false}]}
{"op":"mcm","clk":"11450857760","pt":1717326110040,"mc":[{"id":"1.229554934","rc":[{"atb":[[1.88,11.54]],"id":65894825}],"con":true,"img":false}]}
{"op":"mcm","clk":"11450857769","pt":1717326110138,"mc":[{"id":"1.229554934","rc":[{"atb":[[1.94,8.55]],"id":65894825}],"con":true,"img":false}]}
{"op":"mcm","clk":"11450857781","pt":1717326110242,"mc":[{"id":"1.229554934","rc":[{"atb":[[1.9,9.5]],"id":65894825}],"con":true,"img":false}]}
{"op":"mcm","clk":"11450857828","pt":1717326110657,"mc":[{"id":"1.229554934","rc":[{"atb":[[1.9,8.46]],"id":65894825}],"con":true,"img":false}]}
{"op":"mcm","clk":"11450857838","pt":1717326110764,"mc":[{"id":"1.229554934","rc":[{"atb":[[1.94,9.59]],"id":65894825}],"con":true,"img":false}]}
{"op":"mcm","clk":"11450857859","pt":1717326110967,"mc":[{"id":"1.229554934","rc":[{"atl":[[3.65,7.55]],"id":65894825}],"con":true,"img":false}]}
{"op":"mcm","clk":"11450857901","pt":1717326111328,"mc":[{"id":"1.229554934","rc":[{"atl":[[3.95,0],[3.8,0],[3.9,0]],"id":65894825}],"con":true,"img":false}]}
{"op":"mcm","clk":"11450857978","pt":1717326112051,"mc":[{"id":"1.229554934","rc":[{"atb":[[1.94,17.69]],"id":65894825}],"con":true,"img":false}]}
{"op":"mcm","clk":"11450857987","pt":1717326112151,"mc":[{"id":"1.229554934","rc":[{"atb":[[1.89,26.61],[1.9,0],[1.94,1.04]],"id":65894825}],"con":true,"img":false}]}
{"op":"mcm","clk":"11450858010","pt":1717326112358,"mc":[{"id":"1.229554934","rc":[{"atb":[[1.94,9.14]],"id":65894825}],"con":true,"img":false}]}
{"op":"mcm","clk":"11450858018","pt":1717326112458,"mc":[{"id":"1.229554934","rc":[{"atb":[[1.89,8.55],[1.88,39.2],[1.9,1.89],[1.94,8.1]],"id":65894825}],"con":true,"img":false}]}
{"op":"mcm","clk":"11450858029","pt":1717326112566,"mc":[{"id":"1.229554934","rc":[{"atb":[[1.9,2.93]],"id":65894825}],"con":true,"img":false}]}
{"op":"mcm","clk":"11450858098","pt":1717326113142,"mc":[{"id":"1.229554934","rc":[{"atb":[[1.9,0]],"id":65894825}],"con":true,"img":false}]}
{"op":"mcm","clk":"11450858112","pt":1717326113240,"mc":[{"id":"1.229554934","rc":[{"atb":[[1.9,8.46],[1.94,1.04]],"id":65894825}],"con":true,"img":false}]}
{"op":"mcm","clk":"11450858132","pt":1717326113452,"mc":[{"id":"1.229554934","rc":[{"atb":[[1.4,0],[1.5,0]],"id":47530316},{"atb":[[1.81,0],[1.71,0]],"id":65894825}],"con":true,"img":false}]}
{"op":"mcm","clk":"11450858158","pt":1717326113652,"mc":[{"id":"1.229554934","rc":[{"atb":[[1.51,0]],"id":47530316},{"atb":[[1.91,1.89],[1.94,0]],"id":65894825}],"con":true,"img":false}]}
{"op":"mcm","clk":"11450858167","pt":1717326113756,"mc":[{"id":"1.229554934","rc":[{"atb":[[1.49,1.03]],"id":47530316},{"atb":[[1.9,9.5]],"id":65894825}],"con":true,"img":false}]}
{"op":"mcm","clk":"11450858177","pt":1717326113859,"mc":[{"id":"1.229554934","rc":[{"atb":[[1.9,1.04],[1.94,8.1]],"id":65894825}],"con":true,"img":false}]}
{"op":"mcm","clk":"11450858188","pt":1717326113976,"mc":[{"id":"1.229554934","rc":[{"atb":[[1.88,41.2],[1.87,0]],"id":65894825},{"atl":[[3.5,6]],"id":65894825}],"con":true,"img":false}]}
{"op":"mcm","clk":"11450858201","pt":1717326114069,"mc":[{"id":"1.229554934","rc":[{"atb":[[1.9,9.5],[1.94,0]],"id":65894825}],"con":true,"img":false}]}
{"op":"mcm","clk":"11450858223","pt":1717326114375,"mc":[{"id":"1.229554934","rc":[{"atl":[[3.1,2]],"id":65894825}],"con":true,"img":false}]}
{"op":"mcm","clk":"11450858239","pt":1717326114434,"mc":[{"id":"1.229554934","rc":[{"atb":[[1.9,1.04],[1.94,8.1]],"id":65894825},{"atl":[[3.15,0]],"id":65894825}],"con":true,"img":false}]}
{"op":"mcm","clk":"11450858253","pt":1717326114541,"mc":[{"id":"1.229554934","rc":[{"atl":[[3.55,5.88]],"id":65894825}],"con":true,"img":false}]}
{"op":"mcm","clk":"11450858266","pt":1717326114639,"mc":[{"id":"1.229554934","rc":[{"atl":[[3.6,12],[3.7,0],[3.5,6.42]],"id":65894825}],"con":true,"img":false}]}
{"op":"mcm","clk":"11450858285","pt":1717326114855,"mc":[{"id":"1.229554934","rc":[{"atb":[[1.91,0],[1.9,0]],"id":65894825}],"con":true,"img":false}]}
{"op":"mcm","clk":"11450858294","pt":1717326114956,"mc":[{"id":"1.229554934","rc":[{"atb":[[1.94,9.14]],"id":65894825}],"con":true,"img":false}]}
{"op":"mcm","clk":"11450858304","pt":1717326115057,"mc":[{"id":"1.229554934","rc":[{"atb":[[1.94,18.29]],"id":65894825}],"con":true,"img":false}]}
{"op":"mcm","clk":"11450858312","pt":1717326115167,"mc":[{"id":"1.229554934","rc":[{"atb":[[1.88,13.54]],"id":65894825}],"con":true,"img":false}]}
{"op":"mcm","clk":"11450858356","pt":1717326115525,"mc":[{"id":"1.229554934","rc":[{"atb":[[1.92,11.03]],"id":65894825},{"atl":[[3.6,19.69]],"id":65894825}],"con":true,"img":false}]}
{"op":"mcm","clk":"11450858360","pt":1717326115675,"mc":[{"id":"1.229554934","rc":[{"atb":[[1.9,8.46],[1.94,10.19]],"id":65894825}],"con":true,"img":false}]}
{"op":"mcm","clk":"11450858374","pt":1717326115783,"mc":[{"id":"1.229554934","rc":[{"atb":[[1.42,31.06],[1.52,25.08]],"id":47530316},{"atb":[[1.79,5],[1.91,21.23],[1.69,5.73]],"id":65894825}],"con":true,"img":false}]}
{"op":"mcm","clk":"11450858386","pt":1717326115843,"mc":[{"id":"1.229554934","rc":[{"atb":[[1.9,29.69],[1.94,1.04]],"id":65894825}],"con":true,"img":false}]}
{"op":"mcm","clk":"11450858402","pt":1717326115944,"mc":[{"id":"1.229554934","rc":[{"atb":[[1.91,0]],"id":65894825}],"con":true,"img":false}]}
{"op":"mcm","clk":"11450858409","pt":1717326116043,"mc":[{"id":"1.229554934","rc":[{"atb":[[1.49,0],[1.53,1.8]],"id":47530316},{"atb":[[1.9,8.46],[1.94,11.03]],"id":65894825}],"con":true,"img":false}]}
{"op":"mcm","clk":"11450858424","pt":1717326116148,"mc":[{"id":"1.229554934","rc":[{"atb":[[1.53,2.84]],"id":47530316},{"atb":[[1.92,12.07]],"id":65894825}],"con":true,"img":false}]}
{"op":"mcm","clk":"11450858437","pt":1717326116255,"mc":[{"id":"1.229554934","rc":[{"atb":[[1.92,1.04]],"id":65894825}],"con":true,"img":false}]}
{"op":"mcm","clk":"11450858623","pt":1717326118064,"mc":[{"id":"1.229554934","rc":[{"atb":[[1.9,0],[1.95,8.01]],"id":65894825}],"con":true,"img":false}]}
{"op":"mcm","clk":"11450858630","pt":1717326118166,"mc":[{"id":"1.229554934","rc":[{"atb":[[1.92,23.1],[1.9,8.46],[1.94,0],[1.95,0]],"id":65894825}],"con":true,"img":false}]}
{"op":"mcm","clk":"11450858653","pt":1717326118477,"mc":[{"id":"1.229554934","rc":[{"atb":[[1.53,3.69]],"id":47530316},{"atb":[[1.93,2.74]],"id":65894825}],"con":true,"img":false}]}
{"op":"mcm","clk":"11450858678","pt":1717326118685,"mc":[{"id":"1.229554934","rc":[{"atb":[[1.9,0],[1.95,8.01]],"id":65894825}],"con":true,"img":false}]}
{"op":"mcm","clk":"11450858700","pt":1717326118889,"mc":[{"id":"1.229554934","rc":[{"atb":[[1.9,8.46],[1.95,0]],"id":65894825}],"con":true,"img":false}]}
{"op":"mcm","clk":"11450858750","pt":1717326119356,"mc":[{"id":"1.229554934","rc":[{"atb":[[1.89,10.55],[1.88,11.54]],"id":65894825}],"con":true,"img":false}]}
{"op":"mcm","clk":"11450858760","pt":1717326119464,"mc":[{"id":"1.229554934","rc":[{"atl":[[2.98,2]],"id":65894825}],"con":true,"img":false}]}
{"op":"mcm","clk":"11450858772","pt":1717326119565,"mc":[{"id":"1.229554934","rc":[{"atl":[[3.1,0]],"id":65894825}],"con":true,"img":false}]}
{"op":"mcm","clk":"11450858806","pt":1717326119877,"mc":[{"id":"1.229554934","rc":[{"atb":[[1.26,0],[1.33,65.12]],"id":47530316}],"con":true,"img":false}]}
{"op":"mcm","clk":"11450858879","pt":1717326120657,"mc":[{"id":"1.229554934","rc":[{"atl":[[2.12,16.34]],"id":47530316}],"con":true,"img":false}]}
{"op":"mcm","clk":"11450858891","pt":1717326120757,"mc":[{"id":"1.229554934","rc":[{"atl":[[1000,0.17]],"id":47530316}],"con":true,"img":false}]}
{"op":"mcm","clk":"11450858906","pt":1717326120961,"mc":[{"id":"1.229554934","rc":[{"atb":[[1.53,3.1]],"id":47530316},{"atb":[[1.93,2.15]],"id":65894825}],"con":true,"img":false}]}
{"op":"mcm","clk":"11450859218","pt":1717326124024,"mc":[{"id":"1.229554934","rc":[{"atl":[[2.18,12.71],[2.16,0]],"id":47530316}],"con":true,"img":false}]}
{"op":"mcm","clk":"11450859254","pt":1717326124342,"mc":[{"id":"1.229554934","rc":[{"atb":[[1.42,0],[1.52,0]],"id":47530316},{"atb":[[1.79,0],[1.69,0]],"id":65894825}],"con":true,"img":false}]}
{"op":"mcm","clk":"11450859278","pt":1717326124545,"mc":[{"id":"1.229554934","rc":[{"atb":[[1.53,2.06]],"id":47530316}],"con":true,"img":false}]}
{"op":"mcm","clk":"11450859286","pt":1717326124649,"mc":[{"id":"1.229554934","rc":[{"atb":[[1.49,1.03],[1.53,0.25]],"id":47530316}],"con":true,"img":false}]}
{"op":"mcm","clk":"11450859342","pt":1717326125126,"mc":[{"id":"1.229554934","rc":[{"atl":[[2.22,16.39]],"id":47530316}],"con":true,"img":false}]}
{"op":"mcm","clk":"11450859486","pt":1717326126526,"mc":[{"id":"1.229554934","rc":[{"atb":[[1.89,2],[1.88,0],[1.9,0],[1.86,0],[1.87,8.75]],"id":65894825},{"atl":[[3,2],[3.4,6.25],[2.98,0],[3.5,0.42]],"id":65894825}],"con":true,"img":false}]}
{"op":"mcm","clk":"11450859493","pt":1717326126630,"mc":[{"id":"1.229554934","rc":[{"atl":[[3.45,6.12],[3.4,0]],"id":65894825}],"con":true,"img":false}]}
{"op":"mcm","clk":"11450859500","pt":1717326126734,"mc":[{"id":"1.229554934","rc":[{"atl":[[3.5,0]],"id":65894825}],"con":true,"img":false}]}
{"op":"mcm","clk":"11450859512","pt":1717326126840,"mc":[{"id":"1.229554934","rc":[{"atl":[[3.4,0.42]],"id":65894825}],"con":true,"img":false}]}
{"op":"mcm","clk":"11450859560","pt":1717326127355,"mc":[{"id":"1.229554934","rc":[{"atl":[[3.4,0]],"id":65894825}],"con":true,"img":false}]}
{"op":"mcm","clk":"11450859571","pt":1717326127408,"mc":[{"id":"1.229554934","rc":[{"atb":[[1.87,0]],"id":65894825},{"atl":[[3.45,6.54]],"id":65894825}],"con":true,"img":false}]}
{"op":"mcm","clk":"11450859590","pt":1717326127613,"mc":[{"id":"1.229554934","rc":[{"atl":[[2.18,0],[2.1,13.64]],"id":47530316},{"atl":[[3.45,0.42],[3.5,6]],"id":65894825}],"con":true,"img":false}]}
{"op":"mcm","clk":"11450859604","pt":1717326127717,"mc":[{"id":"1.229554934","rc":[{"atb":[[1.83,15.29],[1.81,18.8],[1.85,11.94],[1.87,8.75]],"id":65894825},{"atl":[[3.45,6.54],[3.5,0]],"id":65894825}],"con":true,"img":false}]}
{"op":"mcm","clk":"11450859614","pt":1717326127819,"mc":[{"id":"1.229554934","rc":[{"atb":[[1.53,0]],"id":47530316}],"con":true,"img":false}]}
{"op":"mcm","clk":"11450859627","pt":1717326127923,"mc":[{"id":"1.229554934","rc":[{"atb":[[1.14,0.25]],"id":47530316}],"con":true,"img":false}]}
{"op":"mcm","clk":"11450859664","pt":1717326128340,"mc":[{"id":"1.229554934","rc":[{"atl":[[2.12,14.93]],"id":47530316}],"con":true,"img":false}]}
{"op":"mcm","clk":"11450859675","pt":1717326128444,"mc":[{"id":"1.229554934","rc":[{"atl":[[2.12,0],[2.2,47.24],[2.08,1.41]],"id":47530316},{"atb":[[1.83,0],[1.85,0],[1.87,0]],"id":65894825}],"con":true,"img":false}]}
{"op":"mcm","clk":"11450859702","pt":1717326128856,"mc":[{"id":"1.229554934","rc":[{"atl":[[2.08,0]],"id":47530316}],"con":true,"img":false}]}
{"op":"mcm","clk":"11450859754","pt":1717326129323,"mc":[{"id":"1.229554934","rc":[{"atb":[[1.87,8.75]],"id":65894825}],"con":true,"img":false}]}
{"op":"mcm","clk":"11450859766","pt":1717326129431,"mc":[{"id":"1.229554934","rc":[{"atb":[[1.56,2],[1.45,0],[1.39,65.12]],"id":47530316},{"atb":[[1.92,25.1],[1.89,0]],"id":65894825},{"atl":[[3.35,6.38]],"id":65894825}],"con":true,"img":false}]}
{"op":"mcm","clk":"11450859780","pt":1717326129530,"mc":[{"id":"1.229554934","rc":[{"atb":[[1.33,0]],"id":47530316},{"atl":[[3.45,6.97],[3.6,7.69]],"id":65894825}],"con":true,"img":false}]}
{"op":"mcm","clk":"11450859797","pt":1717326129737,"mc":[{"id":"1.229554934","rc":[{"atb":[[1.87,0]],"id":65894825},{"atl":[[3.45,6.55],[3.6,0],[3.65,0]],"id":65894825}],"con":true,"img":false}]}
{"op":"mcm","clk":"11450859808","pt":1717326129840,"mc":[{"id":"1.229554934","rc":[{"atl":[[3.35,6.8]],"id":65894825}],"con":true,"img":false}]}
{"op":"mcm","clk":"11450859821","pt":1717326129948,"mc":[{"id":"1.229554934","rc":[{"atb":[[1.93,0.26]],"id":65894825}],"con":true,"img":false}]}
{"op":"mcm","clk":"11450859831","pt":1717326130048,"mc":[{"id":"1.229554934","rc":[{"atl":[[3.45,12.67],[3.35,0.42]],"id":65894825}],"con":true,"img":false}]}
{"op":"mcm","clk":"11450859841","pt":1717326130152,"mc":[{"id":"1.229554934","rc":[{"atb":[[1.83,9.17]],"id":65894825}],"con":true,"img":false}]}
{"op":"mcm","clk":"11450859863","pt":1717326130359,"mc":[{"id":"1.229554934","rc":[{"atl":[[3.35,0]],"id":65894825}],"con":true,"img":false}]}
{"op":"mcm","clk":"11450859878","pt":1717326130461,"mc":[{"id":"1.229554934","rc":[{"atl":[[3.4,0.42]],"id":65894825}],"con":true,"img":false}]}
{"op":"mcm","clk":"11450859885","pt":1717326130567,"mc":[{"id":"1.229554934","rc":[{"atl":[[2.22,77.27],[2.2,18.67]],"id":47530316}],"con":true,"img":false}]}
{"op":"mcm","clk":"11450859924","pt":1717326130930,"mc":[{"id":"1.229554934","rc":[{"atb":[[1.42,31.06],[1.52,25.08]],"id":47530316},{"atb":[[1.79,5],[1.93,0],[1.69,5.73]],"id":65894825}],"con":true,"img":false}]}
{"op":"mcm","clk":"11450859933","pt":1717326131034,"mc":[{"id":"1.229554934","rc":[{"atb":[[1.49,0]],"id":47530316},{"atb":[[1.92,24.06],[1.13,0.26]],"id":65894825}],"con":true,"img":false}]}
{"op":"mcm","clk":"11450859943","pt":1717326131137,"mc":[{"id":"1.229554934","rc":[{"atb":[[1.83,11.17],[1.92,0],[1.81,64.56]],"id":65894825},{"atl":[[3.55,13.72]],"id":65894825}],"con":true,"img":false}]}
{"op":"mcm","clk":"11450859953","pt":1717326131243,"mc":[{"id":"1.229554934","rc":[{"atb":[[1.81,45.76]],"id":65894825},{"atl":[[3.55,7.84]],"id":65894825}],"con":true,"img":false}]}
{"op":"mcm","clk":"11450859991","pt":1717326131662,"mc":[{"id":"1.229554934","rc":[{"atb":[[1.53,1.03]],"id":47530316},{"atb":[[1.83,12.21]],"id":65894825},{"atl":[[3,0],[2.78,2]],"id":65894825}],"con":true,"img":false}]}
{"op":"mcm","clk":"11450860001","pt":1717326131761,"mc":[{"id":"1.229554934","rc":[{"atl":[[2.12,13.39],[2.1,0]],"id":47530316},{"atb":[[1.84,1.89]],"id":65894825},{"atl":[[2.8,2],[2.78,0]],"id":65894825}],"con":true,"img":false}]}
{"op":"mcm","clk":"11450860051","pt":1717326132227,"mc":[{"id":"1.229554934","rc":[{"atb":[[1.79,21.06]],"id":65894825},{"atl":[[3.65,9.43]],"id":65894825}],"con":true,"img":false}]}
{"op":"mcm","clk":"11450860063","pt":1717326132333,"mc":[{"id":"1.229554934","rc":[{"atb":[[1.87,8.75]],"id":65894825}],"con":true,"img":false}]}
{"op":"mcm","clk":"11450860073","pt":1717326132434,"mc":[{"id":"1.229554934","rc":[{"atl":[[2.1,1.41]],"id":47530316}],"con":true,"img":false}]}
{"op":"mcm","clk":"11450860114","pt":1717326132645,"mc":[{"id":"1.229554934","rc":[{"atb":[[1.87,0]],"id":65894825},{"atl":[[3.35,6.38]],"id":65894825}],"con":true,"img":false}]}
{"op":"mcm","clk":"11450860128","pt":1717326132750,"mc":[{"id":"1.229554934","rc":[{"atl":[[2.8,0],[3.35,0],[2.78,2]],"id":65894825}],"con":true,"img":false}]}
{"op":"mcm","clk":"11450860206","pt":1717326133427,"mc":[{"id":"1.229554934","rc":[{"atb":[[1.14,0]],"id":47530316},{"atb":[[1.13,0]],"id":65894825}],"con":true,"img":false}]}
{"op":"mcm","clk":"11450860219","pt":1717326133531,"mc":[{"id":"1.229554934","rc":[{"atb":[[1.53,1.29]],"id":47530316},{"atl":[[2.22,16.39],[2.2,16.67],[2.1,16.8]],"id":47530316},{"atb":[[1.84,2.15]],"id":65894825}],"con":true,"img":false}]}
{"op":"mcm","clk":"11450860233","pt":1717326133635,"mc":[{"id":"1.229554934","rc":[{"atb":[[1.77,19.77]],"id":65894825},{"atl":[[3.75,10.91]],"id":65894825}],"con":true,"img":false}]}
{"op":"mcm","clk":"11450860375","pt":1717326134935,"mc":[{"id":"1.229554934","rc":[{"atb":[[1.87,8.75]],"id":65894825}],"con":true,"img":false}]}
{"op":"mcm","clk":"11450860383","pt":1717326135038,"mc":[{"id":"1.229554934","rc":[{"atb":[[1.83,3.04]],"id":65894825},{"atl":[[3.35,6.38]],"id":65894825}],"con":true,"img":false}]}
{"op":"mcm","clk":"11450860392","pt":1717326135142,"mc":[{"id":"1.229554934","rc":[{"atb":[[1.77,0]],"id":65894825},{"atl":[[3.45,6.55]],"id":65894825}],"con":true,"img":false}]}
{"op":"mcm","clk":"11450860402","pt":1717326135244,"mc":[{"id":"1.229554934","rc":[{"atb":[[1.83,2]],"id":65894825}],"con":true,"img":false}]}
{"op":"mcm","clk":"11450860409","pt":1717326135347,"mc":[{"id":"1.229554934","rc":[{"atb":[[1.87,9.79]],"id":65894825}],"con":true,"img":false}]}
{"op":"mcm","clk":"11450860418","pt":1717326135453,"mc":[{"id":"1.229554934","rc":[{"atb":[[1.84,0.26]],"id":65894825}],"con":true,"img":false}]}
{"op":"mcm","clk":"11450860452","pt":1717326135762,"mc":[{"id":"1.229554934","rc":[{"atl":[[3.4,0]],"id":65894825}],"con":true,"img":false}]}
{"op":"mcm","clk":"11450860460","pt":1717326135865,"mc":[{"id":"1.229554934","rc":[{"atl":[[3.35,6.8]],"id":65894825}],"con":true,"img":false}]}
{"op":"mcm","clk":"11450860474","pt":1717326135979,"mc":[{"id":"1.229554934","rc":[{"atb":[[1.84,0]],"id":65894825}],"con":true,"img":false}]}
{"op":"mcm","clk":"11450860483","pt":1717326136077,"mc":[{"id":"1.229554934","rc":[{"atb":[[1.13,0.26]],"id":65894825}],"con":true,"img":false}]}
{"op":"mcm","clk":"11450860491","pt":1717326136127,"mc":[{"id":"1.229554934","rc":[{"atb":[[1.85,11.94]],"id":65894825},{"atl":[[3.45,14.71]],"id":65894825}],"con":true,"img":false}]}
{"op":"mcm","clk":"11450860502","pt":1717326136230,"mc":[{"id":"1.229554934","rc":[{"atb":[[1.83,0],[1.87,21.59]],"id":65894825},{"atl":[[2.78,0],[2.76,2]],"id":65894825}],"con":true,"img":false}]}
{"op":"mcm","clk":"11450860512","pt":1717326136334,"mc":[{"id":"1.229554934","rc":[{"atb":[[1.81,12.53]],"id":65894825},{"atl":[[3.45,8.16],[3.35,14.64]],"id":65894825}],"con":true,"img":false}]}
{"op":"mcm","clk":"11450860523","pt":1717326136443,"mc":[{"id":"1.229554934","rc":[{"atl":[[3.75,0]],"id":65894825}],"con":true,"img":false}]}
{"op":"mcm","clk":"11450860542","pt":1717326136543,"mc":[{"id":"1.229554934","rc":[{"atb":[[1.88,1.89]],"id":65894825}],"con":true,"img":false}]}
{"op":"mcm","clk":"11450860621","pt":1717326137060,"mc":[{"id":"1.229554934","rc":[{"atb":[[1.83,9.17]],"id":65894825}],"con":true,"img":false}]}
{"op":"mcm","clk":"11450860634","pt":1717326137165,"mc":[{"id":"1.229554934","rc":[{"atb":[[1.87,12.84]],"id":65894825}],"con":true,"img":false}]}
{"op":"mcm","clk":"11450860645","pt":1717326137267,"mc":[{"id":"1.229554934","rc":[{"atb":[[1.85,0]],"id":65894825},{"atl":[[3.45,6.12],[3.35,8.26]],"id":65894825}],"con":true,"img":false}]}
{"op":"mcm","clk":"11450860694","pt":1717326137735,"mc":[{"id":"1.229554934","rc":[{"atb":[[1.88,0]],"id":65894825}],"con":true,"img":false}]}
{"op":"mcm","clk":"11450860739","pt":1717326138252,"mc":[{"id":"1.229554934","rc":[{"atb":[[1.77,19.77]],"id":65894825},{"atl":[[3.75,10.91]],"id":65894825}],"con":true,"img":false}]}
{"op":"mcm","clk":"11450860962","pt":1717326140487,"mc":[{"id":"1.229554934","rc":[{"atb":[[1.42,0],[1.52,0]],"id":47530316},{"atb":[[1.79,16.06],[1.69,0]],"id":65894825}],"con":true,"img":false}]}
{"op":"mcm","clk":"11450860985","pt":1717326140749,"mc":[{"id":"1.229554934","rc":[{"atb":[[1.53,0.25]],"id":47530316}],"con":true,"img":false}]}
{"op":"mcm","clk":"11450860990","pt":1717326140853,"mc":[{"id":"1.229554934","rc":[{"atb":[[1.53,0]],"id":47530316}],"con":true,"img":false}]}
{"op":"mcm","clk":"11450861004","pt":1717326140957,"mc":[{"id":"1.229554934","rc":[{"atb":[[1.14,0.25]],"id":47530316},{"atl":[[3.45,0],[3.5,6]],"id":65894825}],"con":true,"img":false}]}
{"op":"mcm","clk":"11450861058","pt":1717326141377,"mc":[{"id":"1.229554934","rc":[{"atl":[[2.9,2],[2.76,0]],"id":65894825}],"con":true,"img":false}]}
{"op":"mcm","clk":"11450861071","pt":1717326141482,"mc":[{"id":"1.229554934","rc":[{"atl":[[3.35,0.42],[3.15,7.84]],"id":65894825}],"con":true,"img":false}]}
{"op":"mcm","clk":"11450861082","pt":1717326141534,"mc":[{"id":"1.229554934","rc":[{"atl":[[3.35,10.26]],"id":65894825}],"con":true,"img":false}]}
{"op":"mcm","clk":"11450861089","pt":1717326141638,"mc":[{"id":"1.229554934","rc":[{"atl":[[3.15,0]],"id":65894825}],"con":true,"img":false}]}
{"op":"mcm","clk":"11450861218","pt":1717326142677,"mc":[{"id":"1.229554934","rc":[{"atb":[[1.83,0],[1.87,21.59]],"id":65894825}],"con":true,"img":false}]}
{"op":"mcm","clk":"11450861228","pt":1717326142785,"mc":[{"id":"1.229554934","rc":[{"atl":[[3.4,6.25],[3.5,0]],"id":65894825}],"con":true,"img":false}]}
{"op":"mcm","clk":"11450861258","pt":1717326143092,"mc":[{"id":"1.229554934","rc":[{"atb":[[1.83,9.17],[1.87,12.84]],"id":65894825},{"atl":[[3.4,0],[3.5,6]],"id":65894825}],"con":true,"img":false}]}
{"op":"mcm","clk":"11450861367","pt":1717326143766,"mc":[{"id":"1.229554934","rc":[{"atb":[[1.83,0],[1.87,21.59]],"id":65894825},{"atl":[[3.4,6.25],[3.5,0]],"id":65894825}],"con":true,"img":false}]}
{"op":"mcm","clk":"11450861413","pt":1717326144288,"mc":[{"id":"1.229554934","rc":[{"atb":[[1.56,0]],"id":47530316}],"con":true,"img":false}]}
{"op":"mcm","clk":"11450861434","pt":1717326144443,"mc":[{"id":"1.229554934","rc":[{"atb":[[1.54,2]],"id":47530316},{"atl":[[2.92,2],[2.9,0]],"id":65894825}],"con":true,"img":false}]}
{"op":"mcm","clk":"11450861445","pt":1717326144548,"mc":[{"id":"1.229554934","rc":[{"atb":[[1.83,9.17],[1.87,12.84]],"id":65894825}],"con":true,"img":false}]}
{"op":"mcm","clk":"11450861477","pt":1717326144874,"mc":[{"id":"1.229554934","rc":[{"atb":[[1.83,0],[1.87,21.59]],"id":65894825},{"atl":[[3.4,0],[3.5,6]],"id":65894825}],"con":true,"img":false}]}
{"op":"mcm","clk":"11450861489","pt":1717326144963,"mc":[{"id":"1.229554934","rc":[{"atb":[[1.57,2],[1.54,0]],"id":47530316},{"atb":[[1.82,2],[1.81,34.55]],"id":65894825}],"con":true,"img":false}]}
{"op":"mcm","clk":"11450861497","pt":1717326145066,"mc":[{"id":"1.229554934","rc":[{"atb":[[1.83,9.17],[1.87,1.04]],"id":65894825}],"con":true,"img":false}]}
{"op":"mcm","clk":"11450861504","pt":1717326145169,"mc":[{"id":"1.229554934","rc":[{"atb":[[1.82,0],[1.81,12.53],[1.84,11.17]],"id":65894825}],"con":true,"img":false}]}
{"op":"mcm","clk":"11450861516","pt":1717326145272,"mc":[{"id":"1.229554934","rc":[{"atb":[[1.84,0],[1.87,12.21]],"id":65894825}],"con":true,"img":false}]}
{"op":"mcm","clk":"11450861529","pt":1717326145379,"mc":[{"id":"1.229554934","rc":[{"atb":[[1.44,29.64],[1.54,24.16]],"id":47530316},{"atb":[[1.66,5.99],[1.76,5.2]],"id":65894825}],"con":true,"img":false}]}
{"op":"mcm","clk":"11450861562","pt":1717326145693,"mc":[{"id":"1.229554934","rc":[{"atb":[[1.55,1.8]],"id":47530316}],"con":true,"img":false}]}
{"op":"mcm","clk":"11450861665","pt":1717326146677,"mc":[{"id":"1.229554934","rc":[{"atl":[[2.92,0],[2.98,2]],"id":65894825}],"con":true,"img":false}]}
{"op":"mcm","clk":"11450861675","pt":1717326146781,"mc":[{"id":"1.229554934","rc":[{"atl":[[2.98,0],[2.94,2]],"id":65894825}],"con":true,"img":false}]}
{"op":"mcm","clk":"11450861732","pt":1717326147354,"mc":[{"id":"1.229554934","rc":[{"atb":[[1.83,0],[1.86,8.85]],"id":65894825}],"con":true,"img":false}]}
{"op":"mcm","clk":"11450861801","pt":1717326147773,"mc":[{"id":"1.229554934","rc":[{"atb":[[1.83,9.17]],"id":65894825},{"atl":[[3.4,6.25]],"id":65894825}],"con":true,"img":false}]}
{"op":"mcm","clk":"11450861812","pt":1717326147875,"mc":[{"id":"1.229554934","rc":[{"atb":[[1.86,0]],"id":65894825},{"atl":[[3.5,0]],"id":65894825}],"con":true,"img":false}]}
{"op":"mcm","clk":"11450861824","pt":1717326147981,"mc":[{"id":"1.229554934","rc":[{"atl":[[2.92,2],[3.4,0],[3.55,0],[3.5,6],[2.94,0],[3.65,0],[3.75,0]],"id":65894825}],"con":true,"img":false}]}
{"op":"mcm","clk":"11450861949","pt":1717326148868,"mc":[{"id":"1.229554934","rc":[{"atb":[[1.83,0],[1.86,8.85]],"id":65894825}],"con":true,"img":false}]}
{"op":"mcm","clk":"11450861959","pt":1717326148972,"mc":[{"id":"1.229554934","rc":[{"atl":[[3.4,6.25]],"id":65894825}],"con":true,"img":false}]}
{"op":"mcm","clk":"11450861973","pt":1717326149075,"mc":[{"id":"1.229554934","rc":[{"atb":[[1.83,9.17],[1.86,0]],"id":65894825}],"con":true,"img":false}]}
{"op":"mcm","clk":"11450861992","pt":1717326149285,"mc":[{"id":"1.229554934","rc":[{"atl":[[3.4,0]],"id":65894825}],"con":true,"img":false}]}
{"op":"mcm","clk":"11450862081","pt":1717326149958,"mc":[{"id":"1.229554934","rc":[{"atl":[[3.3,6.52]],"id":65894825}],"con":true,"img":false}]}
{"op":"mcm","clk":"11450862101","pt":1717326150167,"mc":[{"id":"1.229554934","rc":[{"atl":[[3.3,0]],"id":65894825}],"con":true,"img":false}]}
{"op":"mcm","clk":"11450862164","pt":1717326150790,"mc":[{"id":"1.229554934","rc":[{"atl":[[2,2.9]],"id":65894825}],"con":true,"img":false}]}
{"op":"mcm","clk":"11450862174","pt":1717326150897,"mc":[{"id":"1.229554934","rc":[{"trd":[[2,229.05]],"ltp":2.0,"tv":229.05,"id":65894825},{"atl":[[2,0],[3.05,6]],"id":65894825}],"con":true,"img":false}]}
{"op":"mcm","clk":"11450862188","pt":1717326151010,"mc":[{"id":"1.229554934","rc":[{"atl":[[1000,1.27]],"id":47530316},{"atb":[[1.87,11.17]],"id":65894825},{"atl":[[3.35,0.42]],"id":65894825}],"con":true,"img":false}]}
{"op":"mcm","clk":"11450862209","pt":1717326151157,"mc":[{"id":"1.229554934","rc":[{"atl":[[1000,0.27]],"id":47530316},{"atb":[[1.82,2],[1.81,32.87],[1.87,0]],"id":65894825}],"con":true,"img":false}]}
{"op":"mcm","clk":"11450862227","pt":1717326151366,"mc":[{"id":"1.229554934","rc":[{"atl":[[1000,0.17]],"id":47530316}],"con":true,"img":false}]}
{"op":"mcm","clk":"11450862239","pt":1717326151475,"mc":[{"id":"1.229554934","rc":[{"atl":[[1.99,0.1]],"id":47530316},{"atb":[[1.83,10.26]],"id":65894825}],"con":true,"img":false}]}
{"op":"mcm","clk":"11450862265","pt":1717326151676,"mc":[{"id":"1.229554934","rc":[{"atb":[[1.84,1.89]],"id":65894825}],"con":true,"img":false}]}
{"op":"mcm","clk":"11450862312","pt":1717326152092,"mc":[{"id":"1.229554934","rc":[{"atl":[[3.6,7.69]],"id":65894825}],"con":true,"img":false}]}
{"op":"mcm","clk":"11450862404","pt":1717326152972,"mc":[{"id":"1.229554934","rc":[{"atl":[[3.35,8.42],[3.05,0]],"id":65894825}],"con":true,"img":false}]}
{"op":"mcm","clk":"11450862412","pt":1717326153076,"mc":[{"id":"1.229554934","rc":[{"atl":[[3.7,9.26]],"id":65894825}],"con":true,"img":false}]}
{"op":"mcm","clk":"11450862442","pt":1717326153391,"mc":[{"id":"1.229554934","rc":[{"atl":[[2.94,2]],"id":65894825}],"con":true,"img":false}]}
{"op":"mcm","clk":"11450862450","pt":1717326153493,"mc":[{"id":"1.229554934","rc":[{"atl":[[2.92,0]],"id":65894825}],"con":true,"img":false}]}
{"op":"mcm","clk":"11450862508","pt":1717326154068,"mc":[{"id":"1.229554934","rc":[{"atl":[[3.8,10.71]],"id":65894825}],"con":true,"img":false}]}
{"op":"mcm","clk":"11450862725","pt":1717326156300,"mc":[{"id":"1.229554934","rc":[{"atb":[[1.44,0],[1.54,0]],"id":47530316},{"atb":[[1.84,3.89],[1.66,0],[1.76,0]],"id":65894825}],"con":true,"img":false}]}
{"op":"mcm","clk":"11450862733","pt":1717326156398,"mc":[{"id":"1.229554934","rc":[{"atb":[[1.82,0],[1.81,12.53],[1.84,5.89]],"id":65894825}],"con":true,"img":false}]}
{"op":"mcm","clk":"11450862745","pt":1717326156505,"mc":[{"id":"1.229554934","rc":[{"atb":[[1.59,2],[1.57,0],[1.55,0]],"id":47530316}],"con":true,"img":false}]}
{"op":"mcm","clk":"11450862762","pt":1717326156660,"mc":[{"id":"1.229554934","rc":[{"atl":[[3.5,0],[3.3,6.52]],"id":65894825}],"con":true,"img":false}]}
{"op":"mcm","clk":"11450862771","pt":1717326156763,"mc":[{"id":"1.229554934","rc":[{"atl":[[2.12,0],[2.2,12.5]],"id":47530316}],"con":true,"img":false}]}
{"op":"mcm","clk":"11450862786","pt":1717326156971,"mc":[{"id":"1.229554934","rc":[{"atb":[[1.83,9.17]],"id":65894825},{"atl":[[3.35,8]],"id":65894825}],"con":true,"img":false}]}
{"op":"mcm","clk":"11450862796","pt":1717326157073,"mc":[{"id":"1.229554934","rc":[{"atb":[[1.84,6.98]],"id":65894825},{"atl":[[3.3,6.94]],"id":65894825}],"con":true,"img":false}]}
{"op":"mcm","clk":"11450862811","pt":1717326157284,"mc":[{"id":"1.229554934","rc":[{"atl":[[2.1,15.39]],"id":47530316}],"con":true,"img":false}]}
{"op":"mcm","clk":"11450862823","pt":1717326157394,"mc":[{"id":"1.229554934","rc":[{"atl":[[2.2,30.89],[2.1,0]],"id":47530316},{"atl":[[3.3,0.42],[3.5,6]],"id":65894825}],"con":true,"img":false}]}
{"op":"mcm","clk":"11450862858","pt":1717326157799,"mc":[{"id":"1.229554934","rc":[{"atl":[[2.24,16.13]],"id":47530316}],"con":true,"img":false}]}
{"op":"mcm","clk":"11450862863","pt":1717326157902,"mc":[{"id":"1.229554934","rc":[{"atl":[[2.18,1.41]],"id":47530316}],"con":true,"img":false}]}
{"op":"mcm","clk":"11450862894","pt":1717326158264,"mc":[{"id":"1.229554934","rc":[{"atl":[[3.3,6.94],[3.5,0]],"id":65894825}],"con":true,"img":false}]}
{"op":"mcm","clk":"11450862906","pt":1717326158472,"mc":[{"id":"1.229554934","rc":[{"atl":[[2.98,2],[2.94,0]],"id":65894825}],"con":true,"img":false}]}
{"op":"mcm","clk":"11450862912","pt":1717326158575,"mc":[{"id":"1.229554934","rc":[{"atl":[[3.35,0],[3.05,7.69]],"id":65894825}],"con":true,"img":false}]}
{"op":"mcm","clk":"11450862933","pt":1717326158784,"mc":[{"id":"1.229554934","rc":[{"atl":[[2.28,19.53]],"id":47530316}],"con":true,"img":false}]}
{"op":"mcm","clk":"11450862980","pt":1717326159299,"mc":[{"id":"1.229554934","rc":[{"atl":[[3.4,8.33]],"id":65894825}],"con":true,"img":false}]}
{"op":"mcm","clk":"11450863003","pt":1717326159619,"mc":[{"id":"1.229554934","rc":[{"atl":[[3.6,0],[3.7,0],[3.4,0],[3.8,0],[3.55,5.88],[3.3,0.42]],"id":65894825}],"con":true,"img":false}]}
{"op":"mcm","clk":"11450863076","pt":1717326160594,"mc":[{"id":"1.229554934","rc":[{"atl":[[3.65,7.55]],"id":65894825}],"con":true,"img":false}]}
{"op":"mcm","clk":"11450863089","pt":1717326160694,"mc":[{"id":"1.229554934","rc":[{"atl":[[3.3,10.11]],"id":65894825}],"con":true,"img":false}]}
{"op":"mcm","clk":"11450863098","pt":1717326160799,"mc":[{"id":"1.229554934","rc":[{"atl":[[3.05,0]],"id":65894825}],"con":true,"img":false}]}
{"op":"mcm","clk":"11450863106","pt":1717326160904,"mc":[{"id":"1.229554934","rc":[{"atl":[[3.55,18],[3.3,0.42]],"id":65894825}],"con":true,"img":false}]}
{"op":"mcm","clk":"11450863124","pt":1717326161118,"mc":[{"id":"1.229554934","rc":[{"atl":[[3.3,0]],"id":65894825}],"con":true,"img":false}]}
{"op":"mcm","clk":"11450863136","pt":1717326161221,"mc":[{"id":"1.229554934","rc":[{"atl":[[3.5,0.42]],"id":65894825}],"con":true,"img":false}]}
{"op":"mcm","clk":"11450863174","pt":1717326161585,"mc":[{"id":"1.229554934","rc":[{"atl":[[3.75,9.09]],"id":65894825}],"con":true,"img":false}]}
{"op":"mcm","clk":"11450863272","pt":1717326162723,"mc":[{"id":"1.229554934","rc":[{"atl":[[3.3,6.52]],"id":65894825}],"con":true,"img":false}]}
{"op":"mcm","clk":"11450863343","pt":1717326163193,"mc":[{"id":"1.229554934","rc":[{"atb":[[1.44,29.64],[1.54,24.16]],"id":47530316},{"atb":[[1.66,5.99],[1.76,5.2]],"id":65894825}],"con":true,"img":false}]}
{"op":"mcm","clk":"11450863393","pt":1717326163713,"mc":[{"id":"1.229554934","rc":[{"atl":[[3.4,8.33]],"id":65894825}],"con":true,"img":false}]}
{"op":"mcm","clk":"11450863402","pt":1717326163817,"mc":[{"id":"1.229554934","rc":[{"atl":[[3.35,8.52]],"id":65894825}],"con":true,"img":false}]}
{"op":"mcm","clk":"11450863410","pt":1717326163920,"mc":[{"id":"1.229554934","rc":[{"atl":[[3.55,5.88]],"id":65894825}],"con":true,"img":false}]}
{"op":"mcm","clk":"11450863435","pt":1717326164182,"mc":[{"id":"1.229554934","rc":[{"atl":[[3.5,0]],"id":65894825}],"con":true,"img":false}]}
{"op":"mcm","clk":"11450863446","pt":1717326164288,"mc":[{"id":"1.229554934","rc":[{"atl":[[3.3,6.94]],"id":65894825}],"con":true,"img":false}]}
{"op":"mcm","clk":"11450863455","pt":1717326164390,"mc":[{"id":"1.229554934","rc":[{"atl":[[3.55,0],[3.65,0],[3.75,0]],"id":65894825}],"con":true,"img":false}]}
{"op":"mcm","clk":"11450863482","pt":1717326164703,"mc":[{"id":"1.229554934","rc":[{"atl":[[3.5,10]],"id":65894825}],"con":true,"img":false}]}
{"op":"mcm","clk":"11450863545","pt":1717326165591,"mc":[{"id":"1.229554934","rc":[{"atl":[[3.45,6.12],[3.3,0.42]],"id":65894825}],"con":true,"img":false}]}
{"op":"mcm","clk":"11450863602","pt":1717326166311,"mc":[{"id":"1.229554934","rc":[{"atb":[[1.59,0],[1.49,2],[1.39,0]],"id":47530316},{"atb":[[1.82,2],[1.84,4.98]],"id":65894825},{"atl":[[3.35,14.9]],"id":65894825}],"con":true,"img":false}]}
{"op":"mcm","clk":"11450863605","pt":1717326166416,"mc":[{"id":"1.229554934","rc":[{"atb":[[1.34,32.7]],"id":47530316}],"con":true,"img":false}]}
{"op":"mcm","clk":"11450863814","pt":1717326168493,"mc":[{"id":"1.229554934","rc":[{"atb":[[1.14,0]],"id":47530316}],"con":true,"img":false}]}
{"op":"mcm","clk":"11450863824","pt":1717326168599,"mc":[{"id":"1.229554934","rc":[{"atb":[[1.55,0.25]],"id":47530316}],"con":true,"img":false}]}
{"op":"mcm","clk":"11450863874","pt":1717326169024,"mc":[{"id":"1.229554934","marketDefinition":{"bspMarket":false,"turnInPlayEnabled":false,"persistenceEnabled":false,"marketBaseRate":7.0,"eventId":"33318908","eventTypeId":"4339","numberOfWinners":1,"bettingType":"ODDS","marketType":"MATCH_BET","marketTime":"2024-06-02T11:02:00.000Z","suspendTime":"2024-06-02T11:02:00.000Z","bspReconciled":false,"complete":true,"inPlay":false,"crossMatching":true,"runnersVoidable":false,"numberOfActiveRunners":2,"betDelay":0,"status":"SUSPENDED","runners":[{"status":"ACTIVE","sortPriority":1,"id":47530316,"name":"1. Balonne Boy"},{"status":"ACTIVE","sortPriority":2,"id":65894825,"name":"4. Shipway"}],"regulators":["MR_INT"],"venue":"Murray Bridge","countryCode":"AU","discountAllowed":true,"timezone":"Australia/Adelaide","openDate":"2024-06-02T08:21:00.000Z","version":5963171708,"name":"Balonne Boy v Shipway","eventName":"Murray Bridge (AUS) 2nd Jun"},"rc":[],"con":true,"img":false}]}
{"op":"mcm","clk":"11450863874","pt":1717326169024,"mc":[{"id":"1.229554934","rc":[{"atb":[[1.44,0],[1.01,0],[1.03,0],[1.58,0],[1.55,0],[1.67,0],[1.54,0],[1.49,0],[1.48,0],[1.34,0]],"id":47530316},{"atl":[[2.24,0],[1.99,0],[2.22,0],[2.28,0],[2.18,0],[2.2,0],[970,0],[990,0],[1000,0]],"id":47530316},{"atb":[[1.83,0],[1.82,0],[1.79,0],[1.81,0],[1.84,0],[1.02,0],[1.77,0],[1.13,0],[1.66,0],[1.76,0]],"id":65894825},{"atl":[[3.45,0],[3.35,0],[3.4,0],[2.98,0],[3.3,0],[3.5,0],[980,0],[990,0]],"id":65894825}],"con":true,"img":false}]}
{"op":"mcm","clk":"11450868602","pt":1717326219500,"mc":[{"id":"1.229554934","marketDefinition":{"bspMarket":false,"turnInPlayEnabled":false,"persistenceEnabled":false,"marketBaseRate":7.0,"eventId":"33318908","eventTypeId":"4339","numberOfWinners":1,"bettingType":"ODDS","marketType":"MATCH_BET","marketTime":"2024-06-02T11:02:00.000Z","suspendTime":"2024-06-02T11:02:00.000Z","bspReconciled":false,"complete":true,"inPlay":false,"crossMatching":true,"runnersVoidable":false,"numberOfActiveRunners":2,"betDelay":0,"status":"SUSPENDED","runners":[{"status":"ACTIVE","sortPriority":1,"id":47530316,"name":"1. Balonne Boy"},{"status":"ACTIVE","sortPriority":2,"id":65894825,"name":"4. Shipway"}],"regulators":["MR_INT"],"venue":"Murray Bridge","countryCode":"AU","discountAllowed":true,"timezone":"Australia/Adelaide","openDate":"2024-06-02T08:21:00.000Z","version":5963173504,"name":"Balonne Boy v Shipway","eventName":"Murray Bridge (AUS) 2nd Jun"},"rc":[],"con":true,"img":false}]}
{"op":"mcm","clk":"11450868678","pt":1717326220385,"mc":[{"id":"1.229554934","rc":[{"trd":[[2,0],[2.02,0],[1.58,0],[1.67,0]],"ltp":2.0,"tv":0.0,"id":47530316},{"trd":[[2,0],[2.38,0],[2.2,0],[2.14,0]],"ltp":2.0,"tv":0.0,"id":65894825}],"con":true,"img":false}]}
{"op":"mcm","clk":"11450868802","pt":1717326221729,"mc":[{"id":"1.229554934","marketDefinition":{"bspMarket":false,"turnInPlayEnabled":false,"persistenceEnabled":false,"marketBaseRate":7.0,"eventId":"33318908","eventTypeId":"4339","numberOfWinners":1,"bettingType":"ODDS","marketType":"MATCH_BET","marketTime":"2024-06-02T11:02:00.000Z","suspendTime":"2024-06-02T11:02:00.000Z","bspReconciled":false,"complete":true,"inPlay":false,"crossMatching":false,"runnersVoidable":false,"numberOfActiveRunners":0,"betDelay":0,"status":"CLOSED","settledTime":"2024-06-02T11:03:38.000Z","runners":[{"status":"WINNER","sortPriority":1,"id":47530316,"name":"1. Balonne Boy"},{"status":"LOSER","sortPriority":2,"id":65894825,"name":"4. Shipway"}],"regulators":["MR_INT"],"venue":"Murray Bridge","countryCode":"AU","discountAllowed":true,"timezone":"Australia/Adelaide","openDate":"2024-06-02T08:21:00.000Z","version":5963173516,"name":"Balonne Boy v Shipway","eventName":"Murray Bridge (AUS) 2nd Jun"},"rc":[],"con":true,"img":false}]}
