{"op":"mcm","clk":"11448127649","pt":1717286034987,"mc":[{"id":"1.229554930","marketDefinition":{"bspMarket":true,"turnInPlayEnabled":false,"persistenceEnabled":false,"marketBaseRate":7.0,"eventId":"33318908","eventTypeId":"4339","numberOfWinners":1,"bettingType":"ODDS","marketType":"WIN","marketTime":"2024-06-02T11:09:00.000Z","suspendTime":"2024-06-02T11:09:00.000Z","bspReconciled":false,"complete":true,"inPlay":false,"crossMatching":true,"runnersVoidable":false,"numberOfActiveRunners":4,"betDelay":0,"status":"OPEN","runners":[{"status":"ACTIVE","sortPriority":1,"id":47530316,"name":"1. Balonne Boy"},{"status":"ACTIVE","sortPriority":2,"id":65894825,"name":"4. Shipway"},{"status":"ACTIVE","sortPriority":3,"id":44736449,"name":"6. Confer"},{"status":"ACTIVE","sortPriority":4,"id":66826631,"name":"8. Waltowa"}],"regulators":["MR_INT"],"venue":"Murray Bridge","countryCode":"AU","discountAllowed":true,"timezone":"Australia/Adelaide","openDate":"2024-06-02T08:21:00.000Z","version":5962317646,"name":"R9 530m Heat","eventName":"Murray Bridge (AUS) 2nd Jun"},"rc":[],"con":true,"img":false}]}
{"op":"mcm","clk":"11448135583","pt":1717286147259,"mc":[{"id":"1.229554930","marketDefinition":{"bspMarket":true,"turnInPlayEnabled":false,"persistenceEnabled":false,"marketBaseRate":7.0,"eventId":"33318908","eventTypeId":"4339","numberOfWinners":1,"bettingType":"ODDS","marketType":"WIN","marketTime":"2024-06-02T11:02:00.000Z","suspendTime":"2024-06-02T11:02:00.000Z","bspReconciled":false,"complete":true,"inPlay":false,"crossMatching":true,"runnersVoidable":false,"numberOfActiveRunners":4,"betDelay":0,"status":"OPEN","runners":[{"status":"ACTIVE","sortPriority":1,"id":47530316,"name":"1. Balonne Boy"},{"status":"ACTIVE","sortPriority":2,"id":65894825,"name":"4. Shipway"},{"status":"ACTIVE","sortPriority":3,"id":44736449,"name":"6. Confer"},{"status":"ACTIVE","sortPriority":4,"id":66826631,"name":"8. Waltowa"}],"regulators":["MR_INT"],"venue":"Murray Bridge","countryCode":"AU","discountAllowed":true,"timezone":"Australia/Adelaide","openDate":"2024-06-02T08:21:00.000Z","version":5962327492,"name":"R9 530m Heat","eventName":"Murray Bridge (AUS) 2nd Jun"},"rc":[],"con":true,"img":false}]}
{"op":"mcm","clk":"11448266886","pt":1717288003942,"mc":[{"id":"1.229554930","rc":[{"atb":[[4.3,31.67],[3.9,72.08],[3.65,78.88]],"id":66826631},{"atl":[[34,6.33],[22,6.63]],"id":66826631},{"spn":13.15,"spf":"NaN","id":66826631},{"atb":[[1.73,286.38],[1.83,125.93],[1.78,268.02]],"id":47530316},{"atl":[[4.5,39.81],[5.5,46.45]],"id":47530316},{"spn":3.16,"spf":"NaN","id":47530316},{"atb":[[17,13.06],[19.5,5.65],[14.5,15.48]],"id":44736449},{"atl":[[300,0.46],[400,0.52]],"id":44736449},{"spn":159.75,"spf":"NaN","id":44736449},{"atb":[[1.83,251.88],[1.88,237.56],[1.93,112.39]],"id":65894825},{"atl":[[5.6,30.29],[7.2,33.71]],"id":65894825},{"spn":3.76,"spf":"NaN","id":65894825}],"con":true,"img":false}]}
{"op":"mcm","clk":"11448270153","pt":1717288057431,"mc":[{"id":"1.229554930","rc":[{"atb":[[4.3,0],[3.9,0],[3.65,0]],"id":66826631},{"atl":[[34,0],[22,0]],"id":66826631},{"atb":[[1.73,0],[1.83,0],[1.78,0]],"id":47530316},{"atl":[[4.5,0],[5.5,0]],"id":47530316},{"atb":[[17,0],[19.5,0],[14.5,0]],"id":44736449},{"atl":[[300,0],[400,0]],"id":44736449},{"atb":[[1.83,0],[1.88,0],[1.93,0]],"id":65894825},{"atl":[[5.6,0],[7.2,0]],"id":65894825}],"con":true,"img":false}]}
{"op":"mcm","clk":"11448270978","pt":1717288067734,"mc":[{"id":"1.229554930","rc":[{"atb":[[4.3,31.67],[3.9,72.08],[3.65,78.88]],"id":66826631},{"atl":[[34,6.33],[22,6.63]],"id":66826631},{"atb":[[1.73,286.38],[1.83,125.93],[1.78,268.02]],"id":47530316},{"atl":[[4.5,39.81],[5.5,46.45]],"id":47530316},{"atb":[[1.83,251.88],[1.88,237.56],[1.93,112.39]],"id":65894825},{"atl":[[5.6,30.29],[7.2,33.71]],"id":65894825},{"atb":[[17,13.06],[19.5,5.65],[14.5,15.48]],"id":44736449},{"atl":[[300,0.46],[400,0.52]],"id":44736449}],"con":true,"img":false}]}
{"op":"mcm","clk":"11448277250","pt":1717288128429,"mc":[{"id":"1.229554930","marketDefinition":{"bspMarket":true,"turnInPlayEnabled":false,"persistenceEnabled":false,"marketBaseRate":7.0,"eventId":"33318908","eventTypeId":"4339","numberOfWinners":1,"bettingType":"ODDS","marketType":"WIN","marketTime":"2024-06-02T11:02:00.000Z","suspendTime":"2024-06-02T11:02:00.000Z","bspReconciled":false,"complete":true,"inPlay":false,"crossMatching":true,"runnersVoidable":false,"numberOfActiveRunners":4,"betDelay":0,"status":"OPEN","runners":[{"status":"ACTIVE","sortPriority":1,"id":47530316,"name":"1. Balonne Boy"},{"status":"ACTIVE","sortPriority":2,"id":65894825,"name":"4. Shipway"},{"status":"ACTIVE","sortPriority":3,"id":44736449,"name":"6. Confer"},{"status":"ACTIVE","sortPriority":4,"id":66826631,"name":"8. Waltowa"}],"regulators":["MR_INT"],"venue":"Murray Bridge","countryCode":"AU","discountAllowed":true,"timezone":"Australia/Adelaide","openDate":"2024-06-02T08:21:00.000Z","version":5962327492,"name":"R9 530m Heat","eventName":"Murray Bridge (AUS) 2nd Jun"},"rc":[{"atb":[[4.3,31.67],[3.9,72.08],[3.65,78.88]],"id":66826631},{"atl":[[34,6.33],[22,6.63]],"id":66826631},{"spn":13.15,"spf":"NaN","id":66826631},{"atb":[[1.73,286.38],[1.83,125.93],[1.78,268.02]],"id":47530316},{"atl":[[4.5,39.81],[5.5,46.45]],"id":47530316},{"spn":3.16,"spf":"NaN","id":47530316},{"atb":[[1.83,251.88],[1.88,237.56],[1.93,112.39]],"id":65894825},{"atl":[[5.6,30.29],[7.2,33.71]],"id":65894825},{"spn":3.76,"spf":"NaN","id":65894825},{"atb":[[17,13.06],[19.5,5.65],[14.5,15.48]],"id":44736449},{"atl":[[300,0.46],[400,0.52]],"id":44736449},{"spn":159.75,"spf":"NaN","id":44736449}],"con":true,"img":true}]}
{"op":"mcm","clk":"11448292488","pt":1717288274268,"mc":[{"id":"1.229554930","rc":[{"atb":[[4.3,0],[3.9,0],[3.65,0]],"id":66826631},{"atl":[[34,0],[22,0]],"id":66826631},{"spn":"NaN","spf":"NaN","id":66826631},{"atb":[[1.73,0],[1.83,0],[1.78,0]],"id":47530316},{"atl":[[4.5,0],[5.5,0]],"id":47530316},{"spn":"NaN","spf":"NaN","id":47530316},{"atb":[[1.83,0],[1.88,0],[1.93,0]],"id":65894825},{"atl":[[5.6,0],[7.2,0]],"id":65894825},{"spn":"NaN","spf":"NaN","id":65894825},{"atb":[[17,0],[19.5,0],[14.5,0]],"id":44736449},{"atl":[[300,0],[400,0]],"id":44736449},{"spn":"NaN","spf":"NaN","id":44736449}],"con":true,"img":false}]}
{"op":"mcm","clk":"11448293813","pt":1717288291678,"mc":[{"id":"1.229554930","rc":[{"atb":[[4.3,31.67],[3.9,72.08],[3.65,78.88]],"id":66826631},{"atl":[[34,6.33],[22,6.63]],"id":66826631},{"atb":[[1.73,286.38],[1.83,125.93],[1.78,268.02]],"id":47530316},{"atl":[[4.5,39.81],[5.5,46.45]],"id":47530316},{"atb":[[17,13.06],[19.5,11.3],[24,4.54]],"id":44736449},{"atl":[[340,0.41],[440,0.47]],"id":44736449},{"atb":[[1.91,229.73],[1.96,108.88],[1.86,243.09]],"id":65894825},{"atl":[[7.8,30.74],[5.9,28.44]],"id":65894825}],"con":true,"img":false}]}
{"op":"mcm","clk":"11448298295","pt":1717288351691,"mc":[{"id":"1.229554930","rc":[{"atb":[[4.3,0],[3.9,0],[3.65,0]],"id":66826631},{"atl":[[34,0],[22,0]],"id":66826631},{"atb":[[1.73,0],[1.83,0],[1.78,0]],"id":47530316},{"atl":[[4.5,0],[5.5,0]],"id":47530316},{"atb":[[17,0],[19.5,0],[24,0]],"id":44736449},{"atl":[[340,0],[440,0]],"id":44736449},{"atb":[[1.91,0],[1.96,0],[1.86,0]],"id":65894825},{"atl":[[7.8,0],[5.9,0]],"id":65894825}],"con":true,"img":false}]}
{"op":"mcm","clk":"11448300795","pt":1717288383947,"mc":[{"id":"1.229554930","rc":[{"atb":[[4.3,31.67],[3.9,72.08],[3.65,78.88]],"id":66826631},{"atl":[[34,6.33],[22,6.63]],"id":66826631},{"atb":[[1.73,286.38],[1.83,125.93],[1.78,268.02]],"id":47530316},{"atl":[[4.5,39.81],[5.5,46.45]],"id":47530316},{"atb":[[1.98,106.66],[1.88,237.56],[1.93,224.79]],"id":65894825},{"atl":[[6.2,26.8],[8.2,29.03]],"id":65894825},{"atb":[[17.5,12.67],[20,11],[25,4.35]],"id":44736449},{"atl":[[350,0.39],[450,0.46]],"id":44736449}],"con":true,"img":false}]}
{"op":"mcm","clk":"11448629984","pt":1717293528421,"mc":[{"id":"1.229554930","marketDefinition":{"bspMarket":true,"turnInPlayEnabled":false,"persistenceEnabled":false,"marketBaseRate":7.0,"eventId":"33318908","eventTypeId":"4339","numberOfWinners":1,"bettingType":"ODDS","marketType":"WIN","marketTime":"2024-06-02T11:02:00.000Z","suspendTime":"2024-06-02T11:02:00.000Z","bspReconciled":false,"complete":true,"inPlay":false,"crossMatching":true,"runnersVoidable":false,"numberOfActiveRunners":4,"betDelay":0,"status":"OPEN","runners":[{"status":"ACTIVE","sortPriority":1,"id":47530316,"name":"1. Balonne Boy"},{"status":"ACTIVE","sortPriority":2,"id":65894825,"name":"4. Shipway"},{"status":"ACTIVE","sortPriority":3,"id":44736449,"name":"6. Confer"},{"status":"ACTIVE","sortPriority":4,"id":66826631,"name":"8. Waltowa"}],"regulators":["MR_INT"],"venue":"Murray Bridge","countryCode":"AU","discountAllowed":true,"timezone":"Australia/Adelaide","openDate":"2024-06-02T08:21:00.000Z","version":5962327492,"name":"R9 530m Heat","eventName":"Murray Bridge (AUS) 2nd Jun"},"rc":[{"atb":[[4.3,31.67],[3.9,72.08],[3.65,78.88]],"id":66826631},{"atl":[[34,6.33],[22,6.63]],"id":66826631},{"spn":13.15,"spf":"NaN","id":66826631},{"atb":[[1.73,286.38],[1.83,125.93],[1.78,268.02]],"id":47530316},{"atl":[[4.5,39.81],[5.5,46.45]],"id":47530316},{"spn":3.16,"spf":"NaN","id":47530316},{"atb":[[1.98,106.66],[1.88,237.56],[1.93,224.79]],"id":65894825},{"atl":[[6.2,26.8],[8.2,29.03]],"id":65894825},{"spn":4.09,"spf":"NaN","id":65894825},{"atb":[[17.5,12.67],[20,11],[25,4.35]],"id":44736449},{"atl":[[350,0.39],[450,0.46]],"id":44736449},{"spn":187.5,"spf":"NaN","id":44736449}],"con":true,"img":true}]}
{"op":"mcm","clk":"11449586443","pt":1717311438619,"mc":[{"id":"1.229554930","rc":[{"atb":[[1.02,8.94]],"id":66826631},{"atl":[[1000,0.85]],"id":66826631},{"spn":13.15,"spf":"NaN","id":66826631},{"atb":[[1.03,5.96]],"id":47530316},{"atl":[[1000,0.85]],"id":47530316},{"spn":3.16,"spf":"NaN","id":47530316},{"atb":[[1.02,8.94]],"id":65894825},{"atl":[[990,0.85]],"id":65894825},{"spn":4.09,"spf":"NaN","id":65894825},{"atb":[[1.03,5.96]],"id":44736449},{"atl":[[1000,0.85]],"id":44736449},{"spn":187.5,"spf":"NaN","id":44736449}],"con":true,"img":false}]}
{"op":"mcm","clk":"11449624324","pt":1717312169412,"mc":[{"id":"1.229554930","rc":[{"atb":[[1.73,0],[1.83,0],[1.78,0]],"id":47530316},{"atl":[[4.5,0],[5.5,0]],"id":47530316},{"spn":500.51,"spf":"NaN","id":47530316},{"atb":[[1.98,0],[1.88,0],[1.93,0]],"id":65894825},{"atl":[[6.2,0],[8.2,0]],"id":65894825},{"spn":495.51,"spf":"NaN","id":65894825}],"con":true,"img":false}]}
{"op":"mcm","clk":"11449624990","pt":1717312185655,"mc":[{"id":"1.229554930","rc":[{"atb":[[1.73,286.38],[1.83,125.93],[1.78,268.02]],"id":47530316},{"atl":[[4.5,39.81],[5.5,46.45]],"id":47530316},{"atb":[[1.98,106.66],[1.88,237.56],[1.93,224.79]],"id":65894825},{"atl":[[6.2,26.8],[8.2,29.03]],"id":65894825}],"con":true,"img":false}]}
{"op":"mcm","clk":"11449626450","pt":1717312220585,"mc":[{"id":"1.229554930","rc":[{"atb":[[1.73,0],[1.83,0],[1.78,0]],"id":47530316},{"atl":[[4.5,0],[5.5,0]],"id":47530316},{"atb":[[1.98,0],[1.88,0],[1.93,0]],"id":65894825},{"atl":[[6.2,0],[8.2,0]],"id":65894825}],"con":true,"img":false}]}
{"op":"mcm","clk":"11449626906","pt":1717312229610,"mc":[{"id":"1.229554930","rc":[{"atb":[[1.73,286.38],[1.83,125.93],[1.78,268.02]],"id":47530316},{"atl":[[4.5,39.81],[5.5,46.45]],"id":47530316},{"spn":3.16,"spf":"NaN","id":47530316},{"atb":[[1.98,106.66],[1.88,237.56],[1.93,224.79]],"id":65894825},{"atl":[[6.2,26.8],[8.2,29.03]],"id":65894825},{"spn":4.09,"spf":"NaN","id":65894825}],"con":true,"img":false}]}
{"op":"mcm","clk":"11449818615","pt":1717315027257,"mc":[{"id":"1.229554930","rc":[{"atl":[[1000,0.17]],"id":66826631},{"atl":[[1000,0.17]],"id":47530316},{"atl":[[990,0.17]],"id":65894825},{"atl":[[1000,0.17]],"id":44736449}],"con":true,"img":false}]}
{"op":"mcm","clk":"11449839924","pt":1717315181440,"mc":[{"id":"1.229554930","rc":[{"atb":[[1.51,98.04]],"id":66826631},{"atb":[[1.51,98.04]],"id":44736449}],"con":true,"img":false}]}
{"op":"mcm","clk":"11449854250","pt":1717315326713,"mc":[{"id":"1.229554930","rc":[{"atb":[[6.2,9.62],[4.1,16.13],[3.05,24.39]],"id":44736449}],"con":true,"img":false}]}
{"op":"mcm","clk":"11449854260","pt":1717315326814,"mc":[{"id":"1.229554930","rc":[{"atl":[[34,10]],"id":47530316},{"atb":[[2.12,44.64]],"id":44736449},{"atl":[[34,10]],"id":65894825}],"con":true,"img":false}]}
{"op":"mcm","clk":"11449862835","pt":1717315412239,"mc":[{"id":"1.229554930","rc":[{"atb":[[4.3,0],[3.9,0],[3.65,0]],"id":66826631},{"atl":[[34,0],[22,0]],"id":66826631},{"spn":500.75,"spf":"NaN","id":66826631},{"atb":[[1.73,0],[1.83,0],[1.78,0]],"id":47530316},{"atl":[[4.5,0],[5.5,0]],"id":47530316},{"spn":17.51,"spf":"NaN","id":47530316},{"atb":[[17.5,0],[20,0],[25,0]],"id":44736449},{"atl":[[350,0],[450,0]],"id":44736449},{"spn":503.1,"spf":"NaN","id":44736449},{"atb":[[1.98,0],[1.88,0],[1.93,0]],"id":65894825},{"atl":[[6.2,0],[8.2,0]],"id":65894825},{"spn":17.51,"spf":"NaN","id":65894825}],"con":true,"img":false}]}
{"op":"mcm","clk":"11449865331","pt":1717315436507,"mc":[{"id":"1.229554930","rc":[{"atb":[[4.3,31.67],[3.9,72.08],[3.65,78.88]],"id":66826631},{"atl":[[34,6.33],[22,6.63]],"id":66826631},{"atb":[[1.73,286.38],[1.83,125.93],[1.78,268.02]],"id":47530316},{"atl":[[4.5,39.81],[5.5,46.45]],"id":47530316},{"atb":[[1.98,106.66],[1.88,237.56],[1.93,224.79]],"id":65894825},{"atl":[[6.2,26.8],[8.2,29.03]],"id":65894825},{"atb":[[17.5,12.67],[20,11],[25,4.35]],"id":44736449},{"atl":[[350,0.39],[450,0.46]],"id":44736449}],"con":true,"img":false}]}
{"op":"mcm","clk":"11449874231","pt":1717315519793,"mc":[{"id":"1.229554930","rc":[{"spn":13.15,"spf":"NaN","id":66826631},{"atb":[[1.73,0],[1.83,0],[1.78,0]],"id":47530316},{"atl":[[4.5,0],[5.5,0]],"id":47530316},{"atb":[[17.5,0],[20,0],[25,0]],"id":44736449},{"atl":[[350,0],[450,0]],"id":44736449},{"atb":[[1.98,0],[1.88,0],[1.93,0]],"id":65894825},{"atl":[[6.2,0],[8.2,0]],"id":65894825}],"con":true,"img":false}]}
{"op":"mcm","clk":"11449875277","pt":1717315530484,"mc":[{"id":"1.229554930","rc":[{"atb":[[1.79,132.31],[1.74,282.51],[1.69,302.98]],"id":47530316},{"atl":[[4.3,42.23],[5.3,48.61]],"id":47530316},{"atb":[[2.02,102.47],[1.91,229.73],[1.96,217.77]],"id":65894825},{"atl":[[6.4,25.8],[8.4,28.25]],"id":65894825},{"atb":[[17.5,12.67],[20,11],[25,4.35]],"id":44736449},{"atl":[[350,0.39],[450,0.46]],"id":44736449}],"con":true,"img":false}]}
{"op":"mcm","clk":"11449970518","pt":1717316552873,"mc":[{"id":"1.229554930","rc":[{"atb":[[4.3,0],[3.9,0],[3.65,0]],"id":66826631},{"atl":[[34,0],[22,0]],"id":66826631},{"spn":500.75,"spf":"NaN","id":66826631},{"atb":[[1.79,0],[1.74,0],[1.69,0]],"id":47530316},{"atl":[[4.3,0],[5.3,0]],"id":47530316},{"atb":[[17.5,0],[20,0],[25,0]],"id":44736449},{"atl":[[350,0],[450,0]],"id":44736449},{"atb":[[2.02,0],[1.91,0],[1.96,0]],"id":65894825},{"atl":[[6.4,0],[8.4,0]],"id":65894825}],"con":true,"img":false}]}
{"op":"mcm","clk":"11449971651","pt":1717316571019,"mc":[{"id":"1.229554930","rc":[{"atb":[[4.3,31.67],[3.9,72.08],[3.65,78.88]],"id":66826631},{"atl":[[34,6.33],[22,6.63]],"id":66826631},{"atb":[[1.79,132.31],[1.74,282.51],[1.69,302.98]],"id":47530316},{"atl":[[4.3,42.23],[5.3,48.61]],"id":47530316},{"atb":[[2.02,102.47],[1.91,229.73],[1.96,217.77]],"id":65894825},{"atl":[[6.4,25.8],[8.4,28.25]],"id":65894825},{"atb":[[17.5,12.67],[20,11],[25,4.35]],"id":44736449},{"atl":[[350,0.39],[450,0.46]],"id":44736449}],"con":true,"img":false}]}
{"op":"mcm","clk":"11449972431","pt":1717316582291,"mc":[{"id":"1.229554930","rc":[{"atl":[[4,3.33]],"id":47530316}],"con":true,"img":false}]}
{"op":"mcm","clk":"11449972439","pt":1717316582393,"mc":[{"id":"1.229554930","rc":[{"atl":[[5.6,2.38]],"id":65894825}],"con":true,"img":false}]}
{"op":"mcm","clk":"11449982010","pt":1717316714285,"mc":[{"id":"1.229554930","rc":[{"spn":13.15,"spf":"NaN","id":66826631},{"atl":[[4,8.15]],"id":47530316},{"spn":2.89,"spf":"NaN","id":47530316},{"spn":3.81,"spf":"NaN","id":65894825},{"spn":187.5,"spf":"NaN","id":44736449}],"con":true,"img":false}]}
{"op":"mcm","clk":"11449982017","pt":1717316714387,"mc":[{"id":"1.229554930","rc":[{"atl":[[5.6,5.83]],"id":65894825}],"con":true,"img":false}]}
{"op":"mcm","clk":"11449985424","pt":1717316763444,"mc":[{"id":"1.229554930","rc":[{"atl":[[4,4.82]],"id":47530316}],"con":true,"img":false}]}
{"op":"mcm","clk":"11449986626","pt":1717316778730,"mc":[{"id":"1.229554930","rc":[{"atl":[[5.6,3.45]],"id":65894825}],"con":true,"img":false}]}
{"op":"mcm","clk":"11449998649","pt":1717316930155,"mc":[{"id":"1.229554930","rc":[{"atl":[[4,0]],"id":47530316},{"spn":3.04,"spf":"NaN","id":47530316}],"con":true,"img":false}]}
{"op":"mcm","clk":"11450001871","pt":1717316966996,"mc":[{"id":"1.229554930","rc":[{"atl":[[5.6,0]],"id":65894825}],"con":true,"img":false}]}
{"op":"mcm","clk":"11450005079","pt":1717317004128,"mc":[{"id":"1.229554930","rc":[{"atl":[[4,4.82]],"id":47530316},{"spn":2.89,"spf":"NaN","id":47530316},{"atl":[[5.6,3.45]],"id":65894825}],"con":true,"img":false}]}
{"op":"mcm","clk":"11450006837","pt":1717317022170,"mc":[{"id":"1.229554930","rc":[{"atl":[[5.6,5.83]],"id":65894825}],"con":true,"img":false}]}
{"op":"mcm","clk":"11450006849","pt":1717317022277,"mc":[{"id":"1.229554930","rc":[{"atl":[[4,8.15]],"id":47530316}],"con":true,"img":false}]}
{"op":"mcm","clk":"11450021923","pt":1717317176674,"mc":[{"id":"1.229554930","rc":[{"atl":[[1000,1.17]],"id":66826631},{"atl":[[1000,1.17]],"id":47530316},{"atl":[[1000,1]],"id":65894825},{"atl":[[1000,1.17]],"id":44736449}],"con":true,"img":false}]}
{"op":"mcm","clk":"11450025125","pt":1717317208241,"mc":[{"id":"1.229554930","rc":[{"atl":[[4,3.33]],"id":47530316}],"con":true,"img":false}]}
{"op":"mcm","clk":"11450025651","pt":1717317213533,"mc":[{"id":"1.229554930","rc":[{"atl":[[4,0]],"id":47530316}],"con":true,"img":false}]}
{"op":"mcm","clk":"11450027190","pt":1717317228443,"mc":[{"id":"1.229554930","rc":[{"atl":[[5.6,3.45]],"id":65894825}],"con":true,"img":false}]}
{"op":"mcm","clk":"11450028789","pt":1717317244338,"mc":[{"id":"1.229554930","rc":[{"atl":[[4,3.33]],"id":47530316},{"atl":[[5.6,5.83]],"id":65894825}],"con":true,"img":false}]}
{"op":"mcm","clk":"11450028985","pt":1717317246457,"mc":[{"id":"1.229554930","rc":[{"atl":[[5.6,2.38]],"id":65894825}],"con":true,"img":false}]}
{"op":"mcm","clk":"11450033193","pt":1717317287301,"mc":[{"id":"1.229554930","rc":[{"atl":[[5.6,5.83]],"id":65894825}],"con":true,"img":false}]}
{"op":"mcm","clk":"11450033204","pt":1717317287405,"mc":[{"id":"1.229554930","rc":[{"atl":[[4,8.15]],"id":47530316}],"con":true,"img":false}]}
{"op":"mcm","clk":"11450049489","pt":1717317438858,"mc":[{"id":"1.229554930","rc":[{"atl":[[4,4.82]],"id":47530316}],"con":true,"img":false}]}
{"op":"mcm","clk":"11450051238","pt":1717317455575,"mc":[{"id":"1.229554930","rc":[{"atl":[[5.6,3.45]],"id":65894825}],"con":true,"img":false}]}
{"op":"mcm","clk":"11450052387","pt":1717317468851,"mc":[{"id":"1.229554930","rc":[{"atl":[[4,8.15]],"id":47530316},{"atl":[[5.6,5.83]],"id":65894825}],"con":true,"img":false}]}
{"op":"mcm","clk":"11450053496","pt":1717317481585,"mc":[{"id":"1.229554930","rc":[{"atl":[[4,3.33]],"id":47530316}],"con":true,"img":false}]}
{"op":"mcm","clk":"11450055060","pt":1717317498897,"mc":[{"id":"1.229554930","rc":[{"atl":[[5.6,2.38]],"id":65894825}],"con":true,"img":false}]}
{"op":"mcm","clk":"11450059482","pt":1717317549349,"mc":[{"id":"1.229554930","rc":[{"atl":[[4,8.15]],"id":47530316}],"con":true,"img":false}]}
{"op":"mcm","clk":"11450059503","pt":1717317549556,"mc":[{"id":"1.229554930","rc":[{"atl":[[5.6,5.83]],"id":65894825}],"con":true,"img":false}]}
{"op":"mcm","clk":"11450068130","pt":1717317644469,"mc":[{"id":"1.229554930","rc":[{"atb":[[4.3,0],[3.9,0],[3.65,0]],"id":66826631},{"atl":[[34,0],[22,0]],"id":66826631},{"spn":500.75,"spf":"NaN","id":66826631},{"atb":[[1.79,0],[1.74,0],[1.69,0]],"id":47530316},{"atl":[[4.3,0],[5.3,0]],"id":47530316},{"spn":2.51,"spf":"NaN","id":47530316},{"atb":[[2.02,0],[1.91,0],[1.96,0]],"id":65894825},{"atl":[[6.4,0],[8.4,0]],"id":65894825},{"spn":3.31,"spf":"NaN","id":65894825},{"atb":[[17.5,0],[20,0],[25,0]],"id":44736449},{"atl":[[350,0],[450,0]],"id":44736449},{"spn":503.1,"spf":"NaN","id":44736449}],"con":true,"img":false}]}
{"op":"mcm","clk":"11450068955","pt":1717317653304,"mc":[{"id":"1.229554930","rc":[{"atl":[[4,4.82]],"id":47530316}],"con":true,"img":false}]}
{"op":"mcm","clk":"11450070037","pt":1717317665303,"mc":[{"id":"1.229554930","rc":[{"atb":[[4.3,31.67],[3.9,72.08],[3.65,78.88]],"id":66826631},{"atl":[[34,6.33],[22,6.63]],"id":66826631},{"atb":[[1.79,132.31],[1.74,282.51],[1.69,302.98]],"id":47530316},{"atl":[[4.3,42.23],[5.3,48.61]],"id":47530316},{"atb":[[2.02,102.47],[1.91,229.73],[1.96,217.77]],"id":65894825},{"atl":[[6.4,25.8],[8.4,28.25]],"id":65894825},{"atb":[[17.5,12.67],[20,11],[25,4.35]],"id":44736449},{"atl":[[350,0.39],[450,0.46]],"id":44736449}],"con":true,"img":false}]}
{"op":"mcm","clk":"11450070350","pt":1717317668413,"mc":[{"id":"1.229554930","rc":[{"atl":[[5.6,3.45]],"id":65894825}],"con":true,"img":false}]}
{"op":"mcm","clk":"11450076919","pt":1717317739564,"mc":[{"id":"1.229554930","rc":[{"spn":13.15,"spf":"NaN","id":66826631},{"atl":[[4,0]],"id":47530316},{"spn":3.04,"spf":"NaN","id":47530316},{"spn":3.81,"spf":"NaN","id":65894825},{"spn":187.5,"spf":"NaN","id":44736449}],"con":true,"img":false}]}
{"op":"mcm","clk":"11450082005","pt":1717317796847,"mc":[{"id":"1.229554930","rc":[{"atl":[[5.6,0]],"id":65894825}],"con":true,"img":false}]}
{"op":"mcm","clk":"11450084359","pt":1717317824633,"mc":[{"id":"1.229554930","rc":[{"atl":[[5.6,3.45]],"id":65894825}],"con":true,"img":false}]}
{"op":"mcm","clk":"11450084368","pt":1717317824839,"mc":[{"id":"1.229554930","rc":[{"atl":[[4,4.82]],"id":47530316}],"con":true,"img":false}]}
{"op":"mcm","clk":"11450091575","pt":1717317908032,"mc":[{"id":"1.229554930","rc":[{"atl":[[4,8.15]],"id":47530316},{"spn":2.89,"spf":"NaN","id":47530316}],"con":true,"img":false}]}
{"op":"mcm","clk":"11450091589","pt":1717317908240,"mc":[{"id":"1.229554930","rc":[{"atl":[[5.6,5.83]],"id":65894825}],"con":true,"img":false}]}
{"op":"mcm","clk":"11450100862","pt":1717318017449,"mc":[{"id":"1.229554930","rc":[{"atl":[[4,3.33]],"id":47530316}],"con":true,"img":false}]}
{"op":"mcm","clk":"11450104192","pt":1717318053193,"mc":[{"id":"1.229554930","rc":[{"atl":[[5.6,2.38]],"id":65894825}],"con":true,"img":false}]}
{"op":"mcm","clk":"11450107865","pt":1717318092657,"mc":[{"id":"1.229554930","rc":[{"atl":[[5.6,5.83]],"id":65894825}],"con":true,"img":false}]}
{"op":"mcm","clk":"11450107872","pt":1717318092785,"mc":[{"id":"1.229554930","rc":[{"atl":[[4,8.15]],"id":47530316}],"con":true,"img":false}]}
{"op":"mcm","clk":"11450108847","pt":1717318103945,"mc":[{"id":"1.229554930","rc":[{"atl":[[4,4.82]],"id":47530316}],"con":true,"img":false}]}
{"op":"mcm","clk":"11450110259","pt":1717318120265,"mc":[{"id":"1.229554930","rc":[{"atl":[[5.6,3.45]],"id":65894825}],"con":true,"img":false}]}
{"op":"mcm","clk":"11450111407","pt":1717318134002,"mc":[{"id":"1.229554930","rc":[{"atl":[[4,8.15]],"id":47530316},{"atl":[[5.6,5.83]],"id":65894825}],"con":true,"img":false}]}
{"op":"mcm","clk":"11450124361","pt":1717318279641,"mc":[{"id":"1.229554930","rc":[{"atl":[[4,3.33]],"id":47530316}],"con":true,"img":false}]}
{"op":"mcm","clk":"11450127327","pt":1717318314748,"mc":[{"id":"1.229554930","rc":[{"atl":[[4,0]],"id":47530316}],"con":true,"img":false}]}
{"op":"mcm","clk":"11450127542","pt":1717318317345,"mc":[{"id":"1.229554930","rc":[{"atl":[[5.6,2.38]],"id":65894825}],"con":true,"img":false}]}
{"op":"mcm","clk":"11450128184","pt":1717318324261,"mc":[{"id":"1.229554930","rc":[{"atb":[[1.79,0],[1.74,0],[1.69,0]],"id":47530316},{"atl":[[4.3,0],[5.3,0]],"id":47530316},{"atb":[[2.02,0],[1.91,0],[1.96,0]],"id":65894825},{"atl":[[6.4,0],[8.4,0]],"id":65894825},{"atb":[[17.5,0],[20,0],[25,0]],"id":44736449},{"atl":[[350,0],[450,0]],"id":44736449}],"con":true,"img":false}]}
{"op":"mcm","clk":"11450128845","pt":1717318331374,"mc":[{"id":"1.229554930","rc":[{"atl":[[5.6,0]],"id":65894825}],"con":true,"img":false}]}
{"op":"mcm","clk":"11450129268","pt":1717318336095,"mc":[{"id":"1.229554930","rc":[{"atb":[[1.79,132.31],[1.74,282.51],[1.69,302.98]],"id":47530316},{"atl":[[4.3,42.23],[5.3,48.61]],"id":47530316},{"atb":[[1.99,211.17],[1.94,222.4],[2.08,96.78]],"id":65894825},{"atl":[[8.6,27.5],[6.6,24.88]],"id":65894825},{"atb":[[19.5,11.3],[24,9.08],[29,3.73]],"id":44736449},{"atl":[[400,0.35],[500,0.41]],"id":44736449}],"con":true,"img":false}]}
{"op":"mcm","clk":"11450130809","pt":1717318354101,"mc":[{"id":"1.229554930","rc":[{"atl":[[3.75,3.55]],"id":47530316},{"spn":2.77,"spf":"NaN","id":47530316},{"spn":214.5,"spf":"NaN","id":44736449},{"atl":[[5.4,2.47]],"id":65894825},{"spn":3.74,"spf":"NaN","id":65894825}],"con":true,"img":false}]}
{"op":"mcm","clk":"11450132742","pt":1717318377087,"mc":[{"id":"1.229554930","rc":[{"atl":[[3.75,8.69]],"id":47530316}],"con":true,"img":false}]}
{"op":"mcm","clk":"11450132761","pt":1717318377299,"mc":[{"id":"1.229554930","rc":[{"atl":[[5.4,6.04]],"id":65894825}],"con":true,"img":false}]}
{"op":"mcm","clk":"11450133833","pt":1717318390220,"mc":[{"id":"1.229554930","rc":[{"atb":[[1.79,0],[1.74,0],[1.69,0]],"id":47530316},{"atl":[[4.3,0],[5.3,0]],"id":47530316},{"atb":[[1.99,0],[1.94,0],[2.08,0]],"id":65894825},{"atl":[[8.6,0],[6.6,0]],"id":65894825}],"con":true,"img":false}]}
{"op":"mcm","clk":"11450134721","pt":1717318401138,"mc":[{"id":"1.229554930","rc":[{"atb":[[1.73,286.38],[1.83,125.93],[1.78,268.02]],"id":47530316},{"atl":[[4.5,39.81],[5.5,46.45]],"id":47530316},{"atb":[[2.02,204.95],[2.12,93.32],[1.96,217.77]],"id":65894825},{"atl":[[6.8,24.02],[8.8,26.8]],"id":65894825}],"con":true,"img":false}]}
{"op":"mcm","clk":"11450146385","pt":1717318534997,"mc":[{"id":"1.229554930","rc":[{"atl":[[3.75,5.13]],"id":47530316},{"spn":2.79,"spf":"NaN","id":47530316},{"spn":3.76,"spf":"NaN","id":65894825}],"con":true,"img":false}]}
{"op":"mcm","clk":"11450147702","pt":1717318549822,"mc":[{"id":"1.229554930","rc":[{"atl":[[5.4,3.57]],"id":65894825}],"con":true,"img":false}]}
{"op":"mcm","clk":"11450149045","pt":1717318564923,"mc":[{"id":"1.229554930","rc":[{"atl":[[3.6,3.7]],"id":47530316},{"atl":[[5,2.66]],"id":65894825}],"con":true,"img":false}]}
{"op":"mcm","clk":"11450152498","pt":1717318600453,"mc":[{"id":"1.229554930","rc":[{"atl":[[3.75,0]],"id":47530316},{"spn":2.71,"spf":"NaN","id":47530316},{"spn":3.56,"spf":"NaN","id":65894825}],"con":true,"img":false}]}
{"op":"mcm","clk":"11450154621","pt":1717318623363,"mc":[{"id":"1.229554930","rc":[{"atl":[[5.4,0]],"id":65894825}],"con":true,"img":false}]}
{"op":"mcm","clk":"11450157558","pt":1717318650512,"mc":[{"id":"1.229554930","rc":[{"atl":[[3.6,9.05]],"id":47530316}],"con":true,"img":false}]}
{"op":"mcm","clk":"11450157581","pt":1717318650717,"mc":[{"id":"1.229554930","rc":[{"atl":[[5,6.52]],"id":65894825}],"con":true,"img":false}]}
{"op":"mcm","clk":"11450164687","pt":1717318724496,"mc":[{"id":"1.229554930","rc":[{"atb":[[4.3,0],[3.9,0],[3.65,0]],"id":66826631},{"atl":[[34,0],[22,0]],"id":66826631},{"spn":500.75,"spf":"NaN","id":66826631},{"atb":[[1.73,0],[1.83,0],[1.78,0]],"id":47530316},{"atl":[[4.5,0],[5.5,0]],"id":47530316},{"spn":2.31,"spf":"NaN","id":47530316},{"atb":[[2.02,0],[2.12,0],[1.96,0]],"id":65894825},{"atl":[[6.8,0],[8.8,0]],"id":65894825},{"spn":3.01,"spf":"NaN","id":65894825},{"atb":[[19.5,0],[24,0],[29,0]],"id":44736449},{"atl":[[400,0],[500,0]],"id":44736449},{"spn":503.1,"spf":"NaN","id":44736449}],"con":true,"img":false}]}
{"op":"mcm","clk":"11450166293","pt":1717318742600,"mc":[{"id":"1.229554930","rc":[{"atb":[[4.3,31.67],[3.9,72.08],[3.65,78.88]],"id":66826631},{"atl":[[34,6.33],[22,6.63]],"id":66826631},{"atb":[[1.73,286.38],[1.83,125.93],[1.78,268.02]],"id":47530316},{"atl":[[4.5,39.81],[5.5,46.45]],"id":47530316},{"atb":[[2.02,204.95],[2.12,93.32],[1.96,217.77]],"id":65894825},{"atl":[[6.8,24.02],[8.8,26.8]],"id":65894825},{"atb":[[19.5,11.3],[24,9.08],[29,3.73]],"id":44736449},{"atl":[[400,0.35],[500,0.41]],"id":44736449}],"con":true,"img":false}]}
{"op":"mcm","clk":"11450167213","pt":1717318750932,"mc":[{"id":"1.229554930","rc":[{"atl":[[3.6,5.35]],"id":47530316}],"con":true,"img":false}]}
{"op":"mcm","clk":"11450168564","pt":1717318765904,"mc":[{"id":"1.229554930","rc":[{"atl":[[5,3.86]],"id":65894825}],"con":true,"img":false}]}
{"op":"mcm","clk":"11450172629","pt":1717318811326,"mc":[{"id":"1.229554930","rc":[{"spn":13.15,"spf":"NaN","id":66826631},{"atl":[[3.6,9.05]],"id":47530316},{"spn":2.71,"spf":"NaN","id":47530316},{"atl":[[5,6.52]],"id":65894825},{"spn":3.56,"spf":"NaN","id":65894825},{"spn":214.5,"spf":"NaN","id":44736449}],"con":true,"img":false}]}
{"op":"mcm","clk":"11450176350","pt":1717318851513,"mc":[{"id":"1.229554930","rc":[{"atl":[[3.6,3.7]],"id":47530316}],"con":true,"img":false}]}
{"op":"mcm","clk":"11450179094","pt":1717318879061,"mc":[{"id":"1.229554930","rc":[{"atl":[[5,2.66]],"id":65894825}],"con":true,"img":false}]}
{"op":"mcm","clk":"11450184143","pt":1717318932798,"mc":[{"id":"1.229554930","rc":[{"atl":[[3.6,9.05]],"id":47530316}],"con":true,"img":false}]}
{"op":"mcm","clk":"11450184164","pt":1717318933005,"mc":[{"id":"1.229554930","rc":[{"atl":[[5,6.52]],"id":65894825}],"con":true,"img":false}]}
{"op":"mcm","clk":"11450191328","pt":1717319006567,"mc":[{"id":"1.229554930","rc":[{"atl":[[3.6,5.35]],"id":47530316}],"con":true,"img":false}]}
{"op":"mcm","clk":"11450192797","pt":1717319021614,"mc":[{"id":"1.229554930","rc":[{"atl":[[5,3.86]],"id":65894825}],"con":true,"img":false}]}
{"op":"mcm","clk":"11450194233","pt":1717319036550,"mc":[{"id":"1.229554930","rc":[{"atl":[[3.6,9.05]],"id":47530316},{"atl":[[5,6.52]],"id":65894825}],"con":true,"img":false}]}
{"op":"mcm","clk":"11450202842","pt":1717319127633,"mc":[{"id":"1.229554930","rc":[{"atl":[[3.6,3.7]],"id":47530316}],"con":true,"img":false}]}
{"op":"mcm","clk":"11450207129","pt":1717319171089,"mc":[{"id":"1.229554930","rc":[{"atl":[[5,2.66]],"id":65894825}],"con":true,"img":false}]}
{"op":"mcm","clk":"11450210826","pt":1717319206686,"mc":[{"id":"1.229554930","rc":[{"atl":[[3.6,9.05]],"id":47530316}],"con":true,"img":false}]}
{"op":"mcm","clk":"11450210845","pt":1717319206893,"mc":[{"id":"1.229554930","rc":[{"atl":[[5,6.52]],"id":65894825}],"con":true,"img":false}]}
{"op":"mcm","clk":"11450212804","pt":1717319226547,"mc":[{"id":"1.229554930","rc":[{"atl":[[3.6,5.35]],"id":47530316}],"con":true,"img":false}]}
{"op":"mcm","clk":"11450214306","pt":1717319241612,"mc":[{"id":"1.229554930","rc":[{"atl":[[5,3.86]],"id":65894825}],"con":true,"img":false}]}
{"op":"mcm","clk":"11450215972","pt":1717319256655,"mc":[{"id":"1.229554930","rc":[{"atl":[[3.6,9.05]],"id":47530316},{"atl":[[5,6.52]],"id":65894825}],"con":true,"img":false}]}
{"op":"mcm","clk":"11450217523","pt":1717319271704,"mc":[{"id":"1.229554930","rc":[{"atl":[[16,10]],"id":47530316},{"atl":[[16,10]],"id":65894825}],"con":true,"img":false}]}
{"op":"mcm","clk":"11450230234","pt":1717319408722,"mc":[{"id":"1.229554930","rc":[{"atl":[[3.6,3.7]],"id":47530316}],"con":true,"img":false}]}
{"op":"mcm","clk":"11450233555","pt":1717319443465,"mc":[{"id":"1.229554930","rc":[{"atl":[[3.6,0]],"id":47530316}],"con":true,"img":false}]}
{"op":"mcm","clk":"11450235006","pt":1717319458484,"mc":[{"id":"1.229554930","rc":[{"atl":[[5,3.86]],"id":65894825}],"con":true,"img":false}]}
{"op":"mcm","clk":"11450236371","pt":1717319473494,"mc":[{"id":"1.229554930","rc":[{"spn":3.16,"spf":"NaN","id":47530316},{"atl":[[5,6.52]],"id":65894825}],"con":true,"img":false}]}
{"op":"mcm","clk":"11450236380","pt":1717319473596,"mc":[{"id":"1.229554930","rc":[{"atl":[[3.6,3.7]],"id":47530316}],"con":true,"img":false}]}
{"op":"mcm","clk":"11450236720","pt":1717319477621,"mc":[{"id":"1.229554930","rc":[{"atl":[[5,2.66]],"id":65894825}],"con":true,"img":false}]}
{"op":"mcm","clk":"11450239011","pt":1717319503851,"mc":[{"id":"1.229554930","rc":[{"atl":[[3.6,9.05]],"id":47530316},{"atl":[[5,6.52]],"id":65894825}],"con":true,"img":false}]}
{"op":"mcm","clk":"11450246447","pt":1717319582799,"mc":[{"id":"1.229554930","rc":[{"atb":[[4.3,0],[3.9,0],[3.65,0]],"id":66826631},{"atl":[[34,0],[22,0]],"id":66826631},{"spn":500.75,"spf":"NaN","id":66826631},{"atb":[[1.73,0],[1.83,0],[1.78,0]],"id":47530316},{"atl":[[4.5,0],[5.5,0]],"id":47530316},{"spn":2.31,"spf":"NaN","id":47530316},{"atb":[[2.02,0],[2.12,0],[1.96,0]],"id":65894825},{"atl":[[6.8,0],[8.8,0]],"id":65894825},{"spn":3.01,"spf":"NaN","id":65894825},{"atb":[[19.5,0],[24,0],[29,0]],"id":44736449},{"atl":[[400,0],[500,0]],"id":44736449},{"spn":503.1,"spf":"NaN","id":44736449}],"con":true,"img":false}]}
{"op":"mcm","clk":"11450247591","pt":1717319595533,"mc":[{"id":"1.229554930","rc":[{"atb":[[4.3,31.67],[3.9,72.08],[3.65,78.88]],"id":66826631},{"atl":[[34,6.33],[22,6.63]],"id":66826631},{"atb":[[1.73,286.38],[1.83,125.93],[1.78,268.02]],"id":47530316},{"atl":[[4.5,39.81],[5.5,46.45]],"id":47530316},{"atb":[[2.02,204.95],[2.12,93.32],[1.96,217.77]],"id":65894825},{"atl":[[6.8,24.02],[8.8,26.8]],"id":65894825},{"atb":[[19.5,11.3],[24,9.08],[29,3.73]],"id":44736449},{"atl":[[400,0.35],[500,0.41]],"id":44736449}],"con":true,"img":false}]}
{"op":"mcm","clk":"11450252645","pt":1717319653809,"mc":[{"id":"1.229554930","rc":[{"spn":13.15,"spf":"NaN","id":66826631},{"spn":2.71,"spf":"NaN","id":47530316},{"atl":[[5,3.86]],"id":65894825},{"spn":3.56,"spf":"NaN","id":65894825},{"spn":214.5,"spf":"NaN","id":44736449}],"con":true,"img":false}]}
{"op":"mcm","clk":"11450254015","pt":1717319668793,"mc":[{"id":"1.229554930","rc":[{"atl":[[3.6,5.35]],"id":47530316}],"con":true,"img":false}]}
{"op":"mcm","clk":"11450258423","pt":1717319717279,"mc":[{"id":"1.229554930","rc":[{"atl":[[3.6,9.05]],"id":47530316},{"atl":[[5,6.52]],"id":65894825}],"con":true,"img":false}]}
{"op":"mcm","clk":"11450258487","pt":1717319717804,"mc":[{"id":"1.229554930","rc":[{"atl":[[3.6,3.7]],"id":47530316}],"con":true,"img":false}]}
{"op":"mcm","clk":"11450263869","pt":1717319778552,"mc":[{"id":"1.229554930","rc":[{"atl":[[5,2.66]],"id":65894825}],"con":true,"img":false}]}
{"op":"mcm","clk":"11450266706","pt":1717319810604,"mc":[{"id":"1.229554930","rc":[{"atl":[[3.6,9.05]],"id":47530316},{"atl":[[5,6.52]],"id":65894825}],"con":true,"img":false}]}
{"op":"mcm","clk":"11450274237","pt":1717319903652,"mc":[{"id":"1.229554930","rc":[{"atl":[[3.6,5.35]],"id":47530316}],"con":true,"img":false}]}
{"op":"mcm","clk":"11450275350","pt":1717319918686,"mc":[{"id":"1.229554930","rc":[{"atl":[[5,3.86]],"id":65894825}],"con":true,"img":false}]}
{"op":"mcm","clk":"11450276523","pt":1717319933606,"mc":[{"id":"1.229554930","rc":[{"atl":[[3.6,9.05]],"id":47530316},{"atl":[[5,6.52]],"id":65894825}],"con":true,"img":false}]}
{"op":"mcm","clk":"11450281747","pt":1717319998312,"mc":[{"id":"1.229554930","rc":[{"atl":[[3.6,3.7]],"id":47530316}],"con":true,"img":false}]}
{"op":"mcm","clk":"11450284505","pt":1717320033442,"mc":[{"id":"1.229554930","rc":[{"atl":[[5,2.66]],"id":65894825}],"con":true,"img":false}]}
{"op":"mcm","clk":"11450287799","pt":1717320085575,"mc":[{"id":"1.229554930","rc":[{"atl":[[3.6,9.05]],"id":47530316}],"con":true,"img":false}]}
{"op":"mcm","clk":"11450287817","pt":1717320085777,"mc":[{"id":"1.229554930","rc":[{"atl":[[5,6.52]],"id":65894825}],"con":true,"img":false}]}
{"op":"mcm","clk":"11450290130","pt":1717320120625,"mc":[{"id":"1.229554930","rc":[{"atl":[[3.6,5.35]],"id":47530316}],"con":true,"img":false}]}
{"op":"mcm","clk":"11450291201","pt":1717320135242,"mc":[{"id":"1.229554930","rc":[{"atl":[[5,3.86]],"id":65894825}],"con":true,"img":false}]}
{"op":"mcm","clk":"11450292329","pt":1717320151861,"mc":[{"id":"1.229554930","rc":[{"atl":[[3.6,9.05]],"id":47530316},{"atl":[[5,6.52]],"id":65894825}],"con":true,"img":false}]}
{"op":"mcm","clk":"11450300005","pt":1717320265924,"mc":[{"id":"1.229554930","rc":[{"atl":[[3.6,3.7]],"id":47530316}],"con":true,"img":false}]}
{"op":"mcm","clk":"11450301725","pt":1717320291767,"mc":[{"id":"1.229554930","rc":[{"atl":[[5,2.66]],"id":65894825}],"con":true,"img":false}]}
{"op":"mcm","clk":"11450303676","pt":1717320322778,"mc":[{"id":"1.229554930","rc":[{"atl":[[3.6,9.05]],"id":47530316}],"con":true,"img":false}]}
{"op":"mcm","clk":"11450303690","pt":1717320322986,"mc":[{"id":"1.229554930","rc":[{"atl":[[5,6.52]],"id":65894825}],"con":true,"img":false}]}
{"op":"mcm","clk":"11450304273","pt":1717320332518,"mc":[{"id":"1.229554930","rc":[{"atl":[[3.6,5.35]],"id":47530316}],"con":true,"img":false}]}
{"op":"mcm","clk":"11450305172","pt":1717320347619,"mc":[{"id":"1.229554930","rc":[{"atl":[[5,3.86]],"id":65894825}],"con":true,"img":false}]}
{"op":"mcm","clk":"11450305953","pt":1717320362679,"mc":[{"id":"1.229554930","rc":[{"atl":[[3.6,9.05]],"id":47530316},{"atl":[[5,6.52]],"id":65894825}],"con":true,"img":false}]}
{"op":"mcm","clk":"11450308136","pt":1717320400500,"mc":[{"id":"1.229554930","rc":[{"atb":[[4.3,0],[3.9,0],[3.65,0]],"id":66826631},{"atl":[[34,0],[22,0]],"id":66826631},{"spn":500.75,"spf":"NaN","id":66826631},{"atb":[[1.73,0],[1.83,0],[1.78,0]],"id":47530316},{"atl":[[4.5,0],[5.5,0]],"id":47530316},{"spn":2.31,"spf":"NaN","id":47530316},{"atb":[[2.02,0],[2.12,0],[1.96,0]],"id":65894825},{"atl":[[6.8,0],[8.8,0]],"id":65894825},{"spn":3.01,"spf":"NaN","id":65894825},{"atb":[[19.5,0],[24,0],[29,0]],"id":44736449},{"atl":[[400,0],[500,0]],"id":44736449},{"spn":503.1,"spf":"NaN","id":44736449}],"con":true,"img":false}]}
{"op":"mcm","clk":"11450308800","pt":1717320410888,"mc":[{"id":"1.229554930","rc":[{"atb":[[4.3,31.67],[3.9,72.08],[3.65,78.88]],"id":66826631},{"atl":[[34,6.33],[22,6.63]],"id":66826631},{"atb":[[1.73,286.38],[1.83,125.93],[1.78,268.02]],"id":47530316},{"atl":[[4.5,39.81],[5.5,46.45]],"id":47530316},{"atb":[[2.02,204.95],[2.12,93.32],[1.96,217.77]],"id":65894825},{"atl":[[6.8,24.02],[8.8,26.8]],"id":65894825},{"atb":[[19.5,11.3],[24,9.08],[29,3.73]],"id":44736449},{"atl":[[400,0.35],[500,0.41]],"id":44736449}],"con":true,"img":false}]}
{"op":"mcm","clk":"11450318682","pt":1717320528418,"mc":[{"id":"1.229554930","marketDefinition":{"bspMarket":true,"turnInPlayEnabled":false,"persistenceEnabled":false,"marketBaseRate":7.0,"eventId":"33318908","eventTypeId":"4339","numberOfWinners":1,"bettingType":"ODDS","marketType":"WIN","marketTime":"2024-06-02T11:02:00.000Z","suspendTime":"2024-06-02T11:02:00.000Z","bspReconciled":false,"complete":true,"inPlay":false,"crossMatching":true,"runnersVoidable":false,"numberOfActiveRunners":4,"betDelay":0,"status":"OPEN","runners":[{"status":"ACTIVE","sortPriority":1,"id":47530316,"name":"1. Balonne Boy"},{"status":"ACTIVE","sortPriority":2,"id":65894825,"name":"4. Shipway"},{"status":"ACTIVE","sortPriority":3,"id":44736449,"name":"6. Confer"},{"status":"ACTIVE","sortPriority":4,"id":66826631,"name":"8. Waltowa"}],"regulators":["MR_INT"],"venue":"Murray Bridge","countryCode":"AU","discountAllowed":true,"timezone":"Australia/Adelaide","openDate":"2024-06-02T08:21:00.000Z","version":5962327492,"name":"R9 530m Heat","eventName":"Murray Bridge (AUS) 2nd Jun"},"rc":[{"atb":[[4.3,31.67],[1.02,8.94],[1.51,98.04],[3.9,72.08],[3.65,78.88]],"id":66826631},{"atl":[[34,6.33],[22,6.63],[1000,1.17]],"id":66826631},{"spn":13.15,"spf":"NaN","id":66826631},{"atb":[[1.73,286.38],[1.83,125.93],[1.03,5.96],[1.78,268.02]],"id":47530316},{"atl":[[16,10],[3.6,9.05],[34,10],[4.5,39.81],[5.5,46.45],[1000,1.17]],"id":47530316},{"spn":2.71,"spf":"NaN","id":47530316},{"atb":[[2.02,204.95],[1.02,8.94],[2.12,93.32],[1.96,217.77]],"id":65894825},{"atl":[[16,10],[34,10],[5,6.52],[6.8,24.02],[8.8,26.8],[990,0.17],[1000,1]],"id":65894825},{"spn":3.56,"spf":"NaN","id":65894825},{"atb":[[19.5,11.3],[1.03,5.96],[6.2,9.62],[4.1,16.13],[24,9.08],[2.12,44.64],[1.51,98.04],[29,3.73],[3.05,24.39]],"id":44736449},{"atl":[[400,0.35],[500,0.41],[1000,1.17]],"id":44736449},{"spn":214.5,"spf":"NaN","id":44736449}],"con":true,"img":true}]}
{"op":"mcm","clk":"11450323297","pt":1717320530224,"mc":[{"id":"1.229554930","rc":[{"spn":13.15,"spf":"NaN","id":66826631},{"atl":[[3.6,3.7]],"id":47530316},{"spn":2.71,"spf":"NaN","id":47530316},{"spn":3.56,"spf":"NaN","id":65894825},{"spn":214.5,"spf":"NaN","id":44736449}],"con":true,"img":false}]}
{"op":"mcm","clk":"11450324812","pt":1717320549962,"mc":[{"id":"1.229554930","rc":[{"atb":[[4.3,0],[3.9,0],[3.65,0]],"id":66826631},{"atl":[[34,0],[22,0]],"id":66826631},{"atb":[[1.73,0],[1.83,0],[1.78,0]],"id":47530316},{"atl":[[4.5,0],[5.5,0]],"id":47530316},{"atb":[[2.02,0],[2.12,0],[1.96,0]],"id":65894825},{"atl":[[6.8,0],[8.8,0]],"id":65894825},{"atb":[[19.5,0],[24,0],[29,0]],"id":44736449},{"atl":[[400,0],[500,0]],"id":44736449}],"con":true,"img":false}]}
{"op":"mcm","clk":"11450325371","pt":1717320556670,"mc":[{"id":"1.229554930","rc":[{"atl":[[3.6,0]],"id":47530316}],"con":true,"img":false}]}
{"op":"mcm","clk":"11450325710","pt":1717320560767,"mc":[{"id":"1.229554930","rc":[{"atl":[[5,2.66]],"id":65894825}],"con":true,"img":false}]}
{"op":"mcm","clk":"11450326232","pt":1717320567665,"mc":[{"id":"1.229554930","rc":[{"atb":[[4.3,31.67],[3.9,72.08],[3.65,78.88]],"id":66826631},{"atl":[[34,6.33],[22,6.63]],"id":66826631},{"atb":[[1.44,475.13],[1.54,193.57],[1.49,426.65]],"id":47530316},{"atl":[[3.6,80.4],[3.1,66.37]],"id":47530316},{"atb":[[2.02,204.95],[2.12,93.32],[1.96,217.77]],"id":65894825},{"atl":[[6.8,24.02],[8.8,26.8]],"id":65894825},{"atb":[[19.5,11.3],[24,9.08],[29,3.73]],"id":44736449},{"atl":[[400,0.35],[500,0.41]],"id":44736449}],"con":true,"img":false}]}
{"op":"mcm","clk":"11450326553","pt":1717320571752,"mc":[{"id":"1.229554930","rc":[{"atl":[[5,0]],"id":65894825}],"con":true,"img":false}]}
{"op":"mcm","clk":"11450328686","pt":1717320601767,"mc":[{"id":"1.229554930","rc":[{"spn":2.32,"spf":"NaN","id":47530316},{"atl":[[1000,3.35]],"id":65894825},{"spn":4.46,"spf":"NaN","id":65894825}],"con":true,"img":false}]}
{"op":"mcm","clk":"11450328705","pt":1717320601977,"mc":[{"id":"1.229554930","rc":[{"atl":[[1000,3.15]],"id":65894825}],"con":true,"img":false}]}
{"op":"mcm","clk":"11450328725","pt":1717320602186,"mc":[{"id":"1.229554930","rc":[{"atl":[[1000,1]],"id":65894825}],"con":true,"img":false}]}
{"op":"mcm","clk":"11450328735","pt":1717320602248,"mc":[{"id":"1.229554930","rc":[{"atl":[[6.2,2.15]],"id":65894825}],"con":true,"img":false}]}
{"op":"mcm","clk":"11450328976","pt":1717320604967,"mc":[{"id":"1.229554930","rc":[{"atb":[[1.44,0],[1.54,0],[1.49,0]],"id":47530316},{"atl":[[3.6,0],[3.1,0]],"id":47530316},{"atb":[[2.02,0],[2.12,0],[1.96,0]],"id":65894825},{"atl":[[6.8,0],[8.8,0]],"id":65894825},{"atb":[[19.5,0],[24,0],[29,0]],"id":44736449},{"atl":[[400,0],[500,0]],"id":44736449}],"con":true,"img":false}]}
{"op":"mcm","clk":"11450330398","pt":1717320623597,"mc":[{"id":"1.229554930","rc":[{"atb":[[1.44,475.13],[1.54,193.57],[1.49,426.65]],"id":47530316},{"atl":[[3.6,80.4],[3.1,66.37]],"id":47530316},{"atb":[[38,2.82],[24,9.08],[29,7.46]],"id":44736449},{"atl":[[550,0.38],[450,0.3]],"id":44736449},{"atb":[[2.06,197.22],[1.98,213.33],[2.16,90.11]],"id":65894825},{"atl":[[9,26.13],[7,23.22]],"id":65894825}],"con":true,"img":false}]}
{"op":"mcm","clk":"11450333309","pt":1717320660743,"mc":[{"id":"1.229554930","rc":[{"atb":[[1.44,0],[1.54,0],[1.49,0]],"id":47530316},{"atl":[[3.6,0],[2.92,6.6],[3.1,0]],"id":47530316},{"atb":[[38,0],[24,0],[29,0]],"id":44736449},{"atl":[[550,0],[450,0]],"id":44736449},{"atb":[[2.06,0],[1.98,0],[2.16,0]],"id":65894825},{"atl":[[9,0],[7,0]],"id":65894825}],"con":true,"img":false}]}
{"op":"mcm","clk":"11450333324","pt":1717320660945,"mc":[{"id":"1.229554930","rc":[{"atl":[[6.4,3.01]],"id":65894825}],"con":true,"img":false}]}
{"op":"mcm","clk":"11450334341","pt":1717320673851,"mc":[{"id":"1.229554930","rc":[{"atb":[[1.44,475.13],[1.54,193.57],[1.49,426.65]],"id":47530316},{"atl":[[3.6,80.4],[3.1,66.37]],"id":47530316},{"spn":2.23,"spf":"NaN","id":47530316},{"atb":[[2.06,197.22],[1.98,213.33],[2.16,90.11]],"id":65894825},{"atl":[[9,26.13],[7,23.22]],"id":65894825},{"spn":4.18,"spf":"NaN","id":65894825},{"atb":[[38,2.82],[24,9.08],[29,7.46]],"id":44736449},{"atl":[[550,0.38],[450,0.3]],"id":44736449},{"spn":244.0,"spf":"NaN","id":44736449}],"con":true,"img":false}]}
{"op":"mcm","clk":"11450343292","pt":1717320783638,"mc":[{"id":"1.229554930","rc":[{"atl":[[6.2,0]],"id":65894825},{"spn":4.28,"spf":"NaN","id":65894825}],"con":true,"img":false}]}
{"op":"mcm","clk":"11450344466","pt":1717320798735,"mc":[{"id":"1.229554930","rc":[{"atl":[[1000,3.35]],"id":65894825}],"con":true,"img":false}]}
{"op":"mcm","clk":"11450344482","pt":1717320799047,"mc":[{"id":"1.229554930","rc":[{"atl":[[1000,3.08]],"id":65894825}],"con":true,"img":false}]}
{"op":"mcm","clk":"11450344496","pt":1717320799256,"mc":[{"id":"1.229554930","rc":[{"atl":[[1000,1]],"id":65894825}],"con":true,"img":false}]}
{"op":"mcm","clk":"11450344503","pt":1717320799356,"mc":[{"id":"1.229554930","rc":[{"atl":[[6.4,5.1]],"id":65894825}],"con":true,"img":false}]}
{"op":"mcm","clk":"11450349314","pt":1717320855920,"mc":[{"id":"1.229554930","rc":[{"atl":[[2.92,0]],"id":47530316},{"spn":2.32,"spf":"NaN","id":47530316}],"con":true,"img":false}]}
{"op":"mcm","clk":"11450353643","pt":1717320906770,"mc":[{"id":"1.229554930","rc":[{"atl":[[6.4,2.08]],"id":65894825}],"con":true,"img":false}]}
{"op":"mcm","clk":"11450355728","pt":1717320931990,"mc":[{"id":"1.229554930","rc":[{"atl":[[2.92,6.6]],"id":47530316},{"spn":2.23,"spf":"NaN","id":47530316}],"con":true,"img":false}]}
{"op":"mcm","clk":"11450355744","pt":1717320932196,"mc":[{"id":"1.229554930","rc":[{"atl":[[6.4,5.1]],"id":65894825}],"con":true,"img":false}]}
{"op":"mcm","clk":"11450360705","pt":1717320993892,"mc":[{"id":"1.229554930","rc":[{"atl":[[6.4,3.01]],"id":65894825}],"con":true,"img":false}]}
{"op":"mcm","clk":"11450361889","pt":1717321009168,"mc":[{"id":"1.229554930","rc":[{"atl":[[1000,3.35]],"id":65894825}],"con":true,"img":false}]}
{"op":"mcm","clk":"11450361904","pt":1717321009374,"mc":[{"id":"1.229554930","rc":[{"atl":[[1000,3.08]],"id":65894825}],"con":true,"img":false}]}
{"op":"mcm","clk":"11450361919","pt":1717321009579,"mc":[{"id":"1.229554930","rc":[{"atl":[[1000,1]],"id":65894825}],"con":true,"img":false}]}
{"op":"mcm","clk":"11450361927","pt":1717321009683,"mc":[{"id":"1.229554930","rc":[{"atl":[[6.4,5.1]],"id":65894825}],"con":true,"img":false}]}
{"op":"mcm","clk":"11450370295","pt":1717321125833,"mc":[{"id":"1.229554930","rc":[{"atl":[[2.92,0]],"id":47530316},{"spn":2.32,"spf":"NaN","id":47530316}],"con":true,"img":false}]}
{"op":"mcm","clk":"11450373582","pt":1717321172579,"mc":[{"id":"1.229554930","rc":[{"atl":[[6.4,2.08]],"id":65894825}],"con":true,"img":false}]}
{"op":"mcm","clk":"11450375434","pt":1717321202858,"mc":[{"id":"1.229554930","rc":[{"atl":[[6.4,0]],"id":65894825},{"spn":4.58,"spf":"NaN","id":65894825}],"con":true,"img":false}]}
{"op":"mcm","clk":"11450376096","pt":1717321214977,"mc":[{"id":"1.229554930","rc":[{"atl":[[2.92,6.6]],"id":47530316}],"con":true,"img":false}]}
{"op":"mcm","clk":"11450376108","pt":1717321215175,"mc":[{"id":"1.229554930","rc":[{"atl":[[6.4,3.01]],"id":65894825}],"con":true,"img":false}]}
{"op":"mcm","clk":"11450376434","pt":1717321220868,"mc":[{"id":"1.229554930","rc":[{"atl":[[1000,3.35]],"id":65894825}],"con":true,"img":false}]}
{"op":"mcm","clk":"11450376450","pt":1717321221071,"mc":[{"id":"1.229554930","rc":[{"atl":[[1000,3.08]],"id":65894825}],"con":true,"img":false}]}
{"op":"mcm","clk":"11450376462","pt":1717321221285,"mc":[{"id":"1.229554930","rc":[{"atl":[[1000,1]],"id":65894825}],"con":true,"img":false}]}
{"op":"mcm","clk":"11450376471","pt":1717321221383,"mc":[{"id":"1.229554930","rc":[{"atl":[[6.4,5.1]],"id":65894825}],"con":true,"img":false}]}
{"op":"mcm","clk":"11450379293","pt":1717321268026,"mc":[{"id":"1.229554930","rc":[{"atb":[[4.3,0],[3.9,0],[3.65,0]],"id":66826631},{"atl":[[34,0],[22,0]],"id":66826631},{"spn":500.75,"spf":"NaN","id":66826631},{"atb":[[1.44,0],[1.54,0],[1.49,0]],"id":47530316},{"atl":[[3.6,0],[3.1,0]],"id":47530316},{"spn":1.97,"spf":"NaN","id":47530316},{"atb":[[2.06,0],[1.98,0],[2.16,0]],"id":65894825},{"atl":[[9,0],[7,0]],"id":65894825},{"spn":3.71,"spf":"NaN","id":65894825},{"atb":[[38,0],[24,0],[29,0]],"id":44736449},{"atl":[[550,0],[450,0]],"id":44736449},{"spn":503.1,"spf":"NaN","id":44736449}],"con":true,"img":false}]}
{"op":"mcm","clk":"11450380285","pt":1717321281946,"mc":[{"id":"1.229554930","rc":[{"atb":[[4.3,31.67],[3.9,72.08],[3.65,78.88]],"id":66826631},{"atl":[[34,6.33],[22,6.63]],"id":66826631},{"atb":[[1.44,475.13],[1.54,193.57],[1.49,426.65]],"id":47530316},{"atl":[[3.6,80.4],[3.1,66.37]],"id":47530316},{"atb":[[38,2.82],[24,9.08],[29,7.46]],"id":44736449},{"atl":[[550,0.38],[450,0.3]],"id":44736449},{"atb":[[2.06,197.22],[1.98,213.33],[2.16,90.11]],"id":65894825},{"atl":[[9,26.13],[7,23.22]],"id":65894825}],"con":true,"img":false}]}
{"op":"mcm","clk":"11450388125","pt":1717321409043,"mc":[{"id":"1.229554930","rc":[{"spn":13.15,"spf":"NaN","id":66826631},{"spn":2.23,"spf":"NaN","id":47530316},{"spn":244.0,"spf":"NaN","id":44736449},{"atl":[[6.4,3.01]],"id":65894825},{"spn":4.28,"spf":"NaN","id":65894825}],"con":true,"img":false}]}
{"op":"mcm","clk":"11450389191","pt":1717321427368,"mc":[{"id":"1.229554930","rc":[{"atl":[[1000,3.35]],"id":65894825}],"con":true,"img":false}]}
{"op":"mcm","clk":"11450389203","pt":1717321427634,"mc":[{"id":"1.229554930","rc":[{"atl":[[1000,3.08]],"id":65894825}],"con":true,"img":false}]}
{"op":"mcm","clk":"11450389216","pt":1717321427840,"mc":[{"id":"1.229554930","rc":[{"atl":[[1000,1]],"id":65894825}],"con":true,"img":false}]}
{"op":"mcm","clk":"11450389224","pt":1717321427946,"mc":[{"id":"1.229554930","rc":[{"atl":[[6.4,5.1]],"id":65894825}],"con":true,"img":false}]}
{"op":"mcm","clk":"11450389347","pt":1717321430136,"mc":[{"id":"1.229554930","rc":[{"atl":[[2.92,0]],"id":47530316}],"con":true,"img":false}]}
{"op":"mcm","clk":"11450391790","pt":1717321469816,"mc":[{"id":"1.229554930","rc":[{"spn":2.32,"spf":"NaN","id":47530316},{"atl":[[6.4,2.08]],"id":65894825}],"con":true,"img":false}]}
{"op":"mcm","clk":"11450394375","pt":1717321508546,"mc":[{"id":"1.229554930","rc":[{"atl":[[2.92,6.6]],"id":47530316}],"con":true,"img":false}]}
{"op":"mcm","clk":"11450394389","pt":1717321508751,"mc":[{"id":"1.229554930","rc":[{"atl":[[6.4,5.1]],"id":65894825}],"con":true,"img":false}]}
{"op":"mcm","clk":"11450401878","pt":1717321613938,"mc":[{"id":"1.229554930","rc":[{"spn":2.23,"spf":"NaN","id":47530316},{"atl":[[6.4,3.01]],"id":65894825}],"con":true,"img":false}]}
{"op":"mcm","clk":"11450402453","pt":1717321621824,"mc":[{"id":"1.229554930","rc":[{"atl":[[1000,3.35]],"id":65894825}],"con":true,"img":false}]}
{"op":"mcm","clk":"11450402469","pt":1717321622034,"mc":[{"id":"1.229554930","rc":[{"atl":[[1000,3.08]],"id":65894825}],"con":true,"img":false}]}
{"op":"mcm","clk":"11450402488","pt":1717321622236,"mc":[{"id":"1.229554930","rc":[{"atl":[[1000,1]],"id":65894825}],"con":true,"img":false}]}
{"op":"mcm","clk":"11450402497","pt":1717321622332,"mc":[{"id":"1.229554930","rc":[{"atl":[[6.4,5.1]],"id":65894825}],"con":true,"img":false}]}
{"op":"mcm","clk":"11450407950","pt":1717321695329,"mc":[{"id":"1.229554930","rc":[{"atl":[[2.92,0]],"id":47530316},{"spn":2.32,"spf":"NaN","id":47530316}],"con":true,"img":false}]}
{"op":"mcm","clk":"11450410285","pt":1717321726284,"mc":[{"id":"1.229554930","rc":[{"atl":[[6.4,2.08]],"id":65894825}],"con":true,"img":false}]}
{"op":"mcm","clk":"11450414273","pt":1717321772328,"mc":[{"id":"1.229554930","rc":[{"atl":[[2.92,6.6]],"id":47530316},{"spn":2.23,"spf":"NaN","id":47530316}],"con":true,"img":false}]}
{"op":"mcm","clk":"11450414286","pt":1717321772534,"mc":[{"id":"1.229554930","rc":[{"atl":[[6.4,5.1]],"id":65894825}],"con":true,"img":false}]}
{"op":"mcm","clk":"11450418945","pt":1717321823078,"mc":[{"id":"1.229554930","rc":[{"atl":[[6.4,3.01]],"id":65894825}],"con":true,"img":false}]}
{"op":"mcm","clk":"11450420711","pt":1717321843490,"mc":[{"id":"1.229554930","rc":[{"atl":[[1000,3.35]],"id":65894825}],"con":true,"img":false}]}
{"op":"mcm","clk":"11450420729","pt":1717321843698,"mc":[{"id":"1.229554930","rc":[{"atl":[[1000,3.08]],"id":65894825}],"con":true,"img":false}]}
{"op":"mcm","clk":"11450420744","pt":1717321843903,"mc":[{"id":"1.229554930","rc":[{"atl":[[1000,1]],"id":65894825}],"con":true,"img":false}]}
{"op":"mcm","clk":"11450420755","pt":1717321844006,"mc":[{"id":"1.229554930","rc":[{"atl":[[6.4,5.1]],"id":65894825}],"con":true,"img":false}]}
{"op":"mcm","clk":"11450434183","pt":1717322001186,"mc":[{"id":"1.229554930","rc":[{"atl":[[2.92,0]],"id":47530316},{"spn":2.32,"spf":"NaN","id":47530316}],"con":true,"img":false}]}
{"op":"mcm","clk":"11450436747","pt":1717322031059,"mc":[{"id":"1.229554930","rc":[{"atl":[[6.4,3.01]],"id":65894825}],"con":true,"img":false}]}
{"op":"mcm","clk":"11450437759","pt":1717322041961,"mc":[{"id":"1.229554930","rc":[{"atl":[[6.4,0]],"id":65894825}],"con":true,"img":false}]}
{"op":"mcm","clk":"11450438650","pt":1717322052278,"mc":[{"id":"1.229554930","rc":[{"atl":[[1000,3.35]],"id":65894825}],"con":true,"img":false}]}
{"op":"mcm","clk":"11450438666","pt":1717322052481,"mc":[{"id":"1.229554930","rc":[{"atl":[[1000,3.08]],"id":65894825}],"con":true,"img":false}]}
{"op":"mcm","clk":"11450438686","pt":1717322052641,"mc":[{"id":"1.229554930","rc":[{"atl":[[1000,1]],"id":65894825}],"con":true,"img":false}]}
{"op":"mcm","clk":"11450438697","pt":1717322052746,"mc":[{"id":"1.229554930","rc":[{"atl":[[6.4,2.08]],"id":65894825}],"con":true,"img":false}]}
{"op":"mcm","clk":"11450440350","pt":1717322069799,"mc":[{"id":"1.229554930","rc":[{"atl":[[2.92,6.6]],"id":47530316},{"spn":2.23,"spf":"NaN","id":47530316}],"con":true,"img":false}]}
{"op":"mcm","clk":"11450440414","pt":1717322070426,"mc":[{"id":"1.229554930","rc":[{"atl":[[6.4,5.1]],"id":65894825}],"con":true,"img":false}]}
{"op":"mcm","clk":"11450445390","pt":1717322128178,"mc":[{"id":"1.229554930","rc":[{"atb":[[4.3,63.35],[3.9,144.17],[3.65,157.77]],"id":66826631},{"atl":[[34,12.67],[22,13.27]],"id":66826631},{"atb":[[1.44,950.27],[1.54,387.15],[1.49,853.31]],"id":47530316},{"atl":[[3.6,160.81],[3.1,132.74]],"id":47530316},{"atb":[[2.06,394.45],[1.98,426.66],[2.16,180.22]],"id":65894825},{"atl":[[9,52.26],[7,46.45]],"id":65894825},{"atb":[[38,5.65],[24,18.17],[29,14.93]],"id":44736449},{"atl":[[550,0.76],[450,0.61]],"id":44736449}],"con":true,"img":false}]}
{"op":"mcm","clk":"11450455928","pt":1717322244181,"mc":[{"id":"1.229554930","rc":[{"atl":[[6.4,3.01]],"id":65894825}],"con":true,"img":false}]}
{"op":"mcm","clk":"11450456846","pt":1717322253301,"mc":[{"id":"1.229554930","rc":[{"atl":[[2.92,0]],"id":47530316}],"con":true,"img":false}]}
{"op":"mcm","clk":"11450460145","pt":1717322290642,"mc":[{"id":"1.229554930","rc":[{"atl":[[6.4,0]],"id":65894825}],"con":true,"img":false}]}
{"op":"mcm","clk":"11450463418","pt":1717322329829,"mc":[{"id":"1.229554930","rc":[{"atl":[[2.92,6.6]],"id":47530316},{"spn":4.58,"spf":"NaN","id":65894825}],"con":true,"img":false}]}
{"op":"mcm","clk":"11450463426","pt":1717322329934,"mc":[{"id":"1.229554930","rc":[{"atl":[[6.4,3.01]],"id":65894825}],"con":true,"img":false}]}
{"op":"mcm","clk":"11450470840","pt":1717322412760,"mc":[{"id":"1.229554930","rc":[{"atl":[[1000,3.35]],"id":65894825},{"spn":4.28,"spf":"NaN","id":65894825}],"con":true,"img":false}]}
{"op":"mcm","clk":"11450470861","pt":1717322412920,"mc":[{"id":"1.229554930","rc":[{"atl":[[1000,3.08]],"id":65894825}],"con":true,"img":false}]}
{"op":"mcm","clk":"11450470894","pt":1717322413233,"mc":[{"id":"1.229554930","rc":[{"atl":[[1000,1]],"id":65894825}],"con":true,"img":false}]}
{"op":"mcm","clk":"11450470904","pt":1717322413344,"mc":[{"id":"1.229554930","rc":[{"atl":[[6.4,5.1]],"id":65894825}],"con":true,"img":false}]}
{"op":"mcm","clk":"11450480572","pt":1717322520487,"mc":[{"id":"1.229554930","rc":[{"atb":[[1.91,109.89]],"id":66826631},{"atl":[[44,2.33]],"id":66826631},{"atb":[[1.35,285.71]],"id":47530316},{"atl":[[4.3,30.3]],"id":47530316},{"atb":[[1.5,200]],"id":65894825},{"atl":[[6.2,19.23]],"id":65894825},{"spn":4.18,"spf":"NaN","id":65894825}],"con":true,"img":false}]}
{"op":"mcm","clk":"11450480836","pt":1717322524096,"mc":[{"id":"1.229554930","rc":[{"atl":[[2.92,0]],"id":47530316}],"con":true,"img":false}]}
{"op":"mcm","clk":"11450483910","pt":1717322564686,"mc":[{"id":"1.229554930","rc":[{"atl":[[6.4,2.08]],"id":65894825}],"con":true,"img":false}]}
{"op":"mcm","clk":"11450483916","pt":1717322564789,"mc":[{"id":"1.229554930","rc":[{"atl":[[6.4,20.6],[6.2,0]],"id":65894825}],"con":true,"img":false}]}
{"op":"mcm","clk":"11450486431","pt":1717322595601,"mc":[{"id":"1.229554930","rc":[{"atl":[[2.92,6.6]],"id":47530316},{"spn":4.28,"spf":"NaN","id":65894825}],"con":true,"img":false}]}
{"op":"mcm","clk":"11450486447","pt":1717322595806,"mc":[{"id":"1.229554930","rc":[{"atl":[[5.9,3.26]],"id":65894825}],"con":true,"img":false}]}
{"op":"mcm","clk":"11450486940","pt":1717322601441,"mc":[{"id":"1.229554930","rc":[{"atl":[[6.4,2.08],[5.8,20.61]],"id":65894825}],"con":true,"img":false}]}
{"op":"mcm","clk":"11450486988","pt":1717322601864,"mc":[{"id":"1.229554930","rc":[{"atl":[[6.4,0]],"id":65894825}],"con":true,"img":false}]}
{"op":"mcm","clk":"11450488975","pt":1717322623136,"mc":[{"id":"1.229554930","rc":[{"atl":[[5.4,2.47]],"id":65894825}],"con":true,"img":false}]}
{"op":"mcm","clk":"11450488983","pt":1717322623237,"mc":[{"id":"1.229554930","rc":[{"atl":[[5.8,0],[5.4,5.73]],"id":65894825}],"con":true,"img":false}]}
{"op":"mcm","clk":"11450490356","pt":1717322639593,"mc":[{"id":"1.229554930","rc":[{"atb":[[4.3,31.67],[3.9,72.08],[3.65,78.88]],"id":66826631},{"atl":[[34,6.33],[22,6.63]],"id":66826631},{"atb":[[1.44,475.13],[1.54,193.57],[1.49,426.65]],"id":47530316},{"atl":[[3.6,80.4],[3.1,66.37]],"id":47530316},{"atb":[[2.06,197.22],[1.98,213.33],[2.16,90.11]],"id":65894825},{"atl":[[9,26.13],[7,23.22]],"id":65894825},{"atb":[[38,2.82],[24,9.08],[29,7.46]],"id":44736449},{"atl":[[550,0.38],[450,0.3]],"id":44736449}],"con":true,"img":false}]}
{"op":"mcm","clk":"11450491173","pt":1717322647806,"mc":[{"id":"1.229554930","rc":[{"atb":[[1.91,0],[1.77,129.87]],"id":66826631},{"atb":[[1.58,172.41],[1.5,0]],"id":65894825}],"con":true,"img":false}]}
{"op":"mcm","clk":"11450491510","pt":1717322651899,"mc":[{"id":"1.229554930","rc":[{"atb":[[4.3,63.35],[3.9,144.17],[3.65,157.77]],"id":66826631},{"atl":[[34,12.67],[22,13.27]],"id":66826631},{"atb":[[1.44,950.27],[1.54,387.15],[1.49,853.31]],"id":47530316},{"atl":[[3.6,160.81],[3.1,132.74]],"id":47530316},{"atb":[[2.06,394.45],[1.98,426.66],[2.16,180.22]],"id":65894825},{"atl":[[9,52.26],[7,46.45]],"id":65894825},{"atb":[[38,5.65],[24,18.17],[29,14.93]],"id":44736449},{"atl":[[550,0.76],[450,0.61]],"id":44736449}],"con":true,"img":false}]}
{"op":"mcm","clk":"11450494285","pt":1717322683654,"mc":[{"id":"1.229554930","rc":[{"atb":[[1.77,0],[2.14,87.72]],"id":66826631},{"spn":3.78,"spf":"NaN","id":65894825}],"con":true,"img":false}]}
{"op":"mcm","clk":"11450502419","pt":1717322770794,"mc":[{"id":"1.229554930","rc":[{"atb":[[1.91,109.89],[2.14,0]],"id":66826631},{"atb":[[1.58,0],[1.5,200]],"id":65894825}],"con":true,"img":false}]}
{"op":"mcm","clk":"11450504122","pt":1717322788740,"mc":[{"id":"1.229554930","rc":[{"atl":[[2.92,0]],"id":47530316}],"con":true,"img":false}]}
{"op":"mcm","clk":"11450506360","pt":1717322813165,"mc":[{"id":"1.229554930","rc":[{"atl":[[5.4,3.26]],"id":65894825}],"con":true,"img":false}]}
{"op":"mcm","clk":"11450506368","pt":1717322813296,"mc":[{"id":"1.229554930","rc":[{"atl":[[5.8,20.83],[5.4,0]],"id":65894825}],"con":true,"img":false}]}
{"op":"mcm","clk":"11450506700","pt":1717322817088,"mc":[{"id":"1.229554930","rc":[{"atl":[[5.9,0]],"id":65894825}],"con":true,"img":false}]}
{"op":"mcm","clk":"11450506793","pt":1717322818350,"mc":[{"id":"1.229554930","rc":[{"atl":[[6.8,17.24]],"id":65894825}],"con":true,"img":false}]}
{"op":"mcm","clk":"11450506801","pt":1717322818462,"mc":[{"id":"1.229554930","rc":[{"atl":[[5.8,0]],"id":65894825}],"con":true,"img":false}]}
{"op":"mcm","clk":"11450507681","pt":1717322828177,"mc":[{"id":"1.229554930","rc":[{"atl":[[1000,3.35]],"id":65894825}],"con":true,"img":false}]}
{"op":"mcm","clk":"11450507707","pt":1717322828484,"mc":[{"id":"1.229554930","rc":[{"atl":[[1000,3.15]],"id":65894825}],"con":true,"img":false}]}
{"op":"mcm","clk":"11450507732","pt":1717322828754,"mc":[{"id":"1.229554930","rc":[{"atl":[[1000,1]],"id":65894825}],"con":true,"img":false}]}
{"op":"mcm","clk":"11450507740","pt":1717322828861,"mc":[{"id":"1.229554930","rc":[{"atl":[[6.2,2.15]],"id":65894825}],"con":true,"img":false}]}
{"op":"mcm","clk":"11450509511","pt":1717322847503,"mc":[{"id":"1.229554930","rc":[{"spn":2.32,"spf":"NaN","id":47530316},{"atl":[[6.2,19.39],[6.8,0]],"id":65894825},{"spn":4.18,"spf":"NaN","id":65894825}],"con":true,"img":false}]}
{"op":"mcm","clk":"11450510141","pt":1717322854244,"mc":[{"id":"1.229554930","rc":[{"atl":[[2.92,6.6]],"id":47530316},{"atl":[[5.7,3.38]],"id":65894825}],"con":true,"img":false}]}
{"op":"mcm","clk":"11450512945","pt":1717322881373,"mc":[{"id":"1.229554930","rc":[{"atl":[[5.6,19.39],[6.2,2.15]],"id":65894825}],"con":true,"img":false}]}
{"op":"mcm","clk":"11450526054","pt":1717323010212,"mc":[{"id":"1.229554930","rc":[{"atb":[[4.3,31.67],[3.9,72.08],[3.65,78.88]],"id":66826631},{"atl":[[34,6.33],[22,6.63]],"id":66826631},{"atb":[[1.44,475.13],[1.54,193.57],[1.49,426.65]],"id":47530316},{"atl":[[3.6,80.4],[3.1,66.37]],"id":47530316},{"spn":2.23,"spf":"NaN","id":47530316},{"atb":[[2.06,197.22],[1.98,213.33],[2.16,90.11]],"id":65894825},{"atl":[[9,26.13],[7,23.22]],"id":65894825},{"spn":3.88,"spf":"NaN","id":65894825},{"atb":[[38,2.82],[24,9.08],[29,7.46]],"id":44736449},{"atl":[[550,0.38],[450,0.3]],"id":44736449}],"con":true,"img":false}]}
{"op":"mcm","clk":"11450526156","pt":1717323011317,"mc":[{"id":"1.229554930","rc":[{"atl":[[1000,2.03]],"id":66826631}],"con":true,"img":false}]}
{"op":"mcm","clk":"11450526315","pt":1717323013036,"mc":[{"id":"1.229554930","rc":[{"atl":[[1000,1.58]],"id":66826631}],"con":true,"img":false}]}
{"op":"mcm","clk":"11450526498","pt":1717323015018,"mc":[{"id":"1.229554930","rc":[{"atl":[[1000,1.17]],"id":66826631}],"con":true,"img":false}]}
{"op":"mcm","clk":"11450526507","pt":1717323015125,"mc":[{"id":"1.229554930","rc":[{"atl":[[21,0.4]],"id":66826631}],"con":true,"img":false}]}
{"op":"mcm","clk":"11450527424","pt":1717323023843,"mc":[{"id":"1.229554930","rc":[{"atb":[[4.3,63.35],[3.9,144.17],[3.65,157.77]],"id":66826631},{"atl":[[34,12.67],[22,13.27]],"id":66826631},{"atb":[[1.44,950.27],[1.54,387.15],[1.49,853.31]],"id":47530316},{"atl":[[3.6,160.81],[3.1,132.74]],"id":47530316},{"atb":[[38,5.65],[24,18.17],[29,14.93]],"id":44736449},{"atl":[[550,0.76],[450,0.61]],"id":44736449},{"atb":[[2.06,394.45],[1.98,426.66],[2.16,180.22]],"id":65894825},{"atl":[[9,52.26],[7,46.45]],"id":65894825}],"con":true,"img":false}]}
{"op":"mcm","clk":"11450527969","pt":1717323029255,"mc":[{"id":"1.229554930","rc":[{"atl":[[6.2,0]],"id":65894825}],"con":true,"img":false}]}
{"op":"mcm","clk":"11450529275","pt":1717323042253,"mc":[{"id":"1.229554930","rc":[{"atl":[[2.92,0]],"id":47530316}],"con":true,"img":false}]}
{"op":"mcm","clk":"11450531329","pt":1717323063204,"mc":[{"id":"1.229554930","rc":[{"atl":[[5.2,2.56]],"id":65894825}],"con":true,"img":false}]}
{"op":"mcm","clk":"11450531345","pt":1717323063338,"mc":[{"id":"1.229554930","rc":[{"atl":[[5.6,0],[5.2,5.94]],"id":65894825}],"con":true,"img":false}]}
{"op":"mcm","clk":"11450531371","pt":1717323063519,"mc":[{"id":"1.229554930","rc":[{"atl":[[5.6,19.39],[5.2,2.56]],"id":65894825}],"con":true,"img":false}]}
{"op":"mcm","clk":"11450531603","pt":1717323065723,"mc":[{"id":"1.229554930","rc":[{"atl":[[5.7,0]],"id":65894825}],"con":true,"img":false}]}
{"op":"mcm","clk":"11450534664","pt":1717323095187,"mc":[{"id":"1.229554930","rc":[{"spn":12.65,"spf":"NaN","id":66826631},{"spn":2.32,"spf":"NaN","id":47530316},{"atl":[[5.6,0],[5.2,21.95]],"id":65894825},{"spn":3.68,"spf":"NaN","id":65894825}],"con":true,"img":false}]}
{"op":"mcm","clk":"11450536378","pt":1717323112500,"mc":[{"id":"1.229554930","rc":[{"atl":[[2.92,6.6]],"id":47530316}],"con":true,"img":false}]}
{"op":"mcm","clk":"11450536402","pt":1717323112709,"mc":[{"id":"1.229554930","rc":[{"atl":[[4.8,4.01]],"id":65894825}],"con":true,"img":false}]}
{"op":"mcm","clk":"11450537792","pt":1717323126541,"mc":[{"id":"1.229554930","rc":[{"atl":[[5.2,2.56],[4.7,21.96]],"id":65894825}],"con":true,"img":false}]}
{"op":"mcm","clk":"11450551038","pt":1717323246649,"mc":[{"id":"1.229554930","rc":[{"spn":2.23,"spf":"NaN","id":47530316},{"atl":[[5.2,0]],"id":65894825},{"spn":3.43,"spf":"NaN","id":65894825}],"con":true,"img":false}]}
{"op":"mcm","clk":"11450558852","pt":1717323318353,"mc":[{"id":"1.229554930","rc":[{"atl":[[4.4,3.03]],"id":65894825},{"spn":3.28,"spf":"NaN","id":65894825}],"con":true,"img":false}]}
{"op":"mcm","clk":"11450558876","pt":1717323318560,"mc":[{"id":"1.229554930","rc":[{"atl":[[4.3,4.01],[4.7,0]],"id":65894825}],"con":true,"img":false}]}
{"op":"mcm","clk":"11450559569","pt":1717323324832,"mc":[{"id":"1.229554930","rc":[{"atl":[[2.92,0]],"id":47530316}],"con":true,"img":false}]}
{"op":"mcm","clk":"11450561728","pt":1717323343674,"mc":[{"id":"1.229554930","rc":[{"atb":[[4.3,31.67],[3.9,72.08],[3.65,78.88]],"id":66826631},{"atl":[[34,6.33],[22,6.63]],"id":66826631},{"atb":[[1.44,475.13],[1.54,193.57],[1.49,426.65]],"id":47530316},{"atl":[[3.6,80.4],[3.1,66.37]],"id":47530316},{"atb":[[2.06,197.22],[1.98,213.33],[2.16,90.11]],"id":65894825},{"atl":[[9,26.13],[7,23.22]],"id":65894825},{"atb":[[38,2.82],[24,9.08],[29,7.46]],"id":44736449},{"atl":[[550,0.38],[450,0.3]],"id":44736449}],"con":true,"img":false}]}
{"op":"mcm","clk":"11450563425","pt":1717323359017,"mc":[{"id":"1.229554930","rc":[{"atb":[[4.3,63.35],[3.9,144.17],[3.65,157.77]],"id":66826631},{"atl":[[34,12.67],[22,13.27]],"id":66826631},{"atb":[[1.44,950.27],[1.54,387.15],[1.49,853.31]],"id":47530316},{"atl":[[3.6,160.81],[3.1,132.74]],"id":47530316},{"atb":[[38,5.65],[24,18.17],[29,14.93]],"id":44736449},{"atl":[[550,0.76],[450,0.61]],"id":44736449},{"atb":[[2.06,394.45],[1.98,426.66],[2.16,180.22]],"id":65894825},{"atl":[[9,52.26],[7,46.45]],"id":65894825}],"con":true,"img":false}]}
{"op":"mcm","clk":"11450565576","pt":1717323376932,"mc":[{"id":"1.229554930","rc":[{"atl":[[4.8,0]],"id":65894825}],"con":true,"img":false}]}
{"op":"mcm","clk":"11450570363","pt":1717323415642,"mc":[{"id":"1.229554930","rc":[{"atl":[[2.92,6.6]],"id":47530316},{"spn":3.23,"spf":"NaN","id":65894825}],"con":true,"img":false}]}
{"op":"mcm","clk":"11450570390","pt":1717323415851,"mc":[{"id":"1.229554930","rc":[{"atl":[[6.4,3.01]],"id":65894825}],"con":true,"img":false}]}
{"op":"mcm","clk":"11450581364","pt":1717323511465,"mc":[{"id":"1.229554930","rc":[{"atl":[[4.4,0]],"id":65894825}],"con":true,"img":false}]}
{"op":"mcm","clk":"11450581372","pt":1717323511563,"mc":[{"id":"1.229554930","rc":[{"atl":[[4.3,0],[6.2,19.23]],"id":65894825}],"con":true,"img":false}]}
{"op":"mcm","clk":"11450583557","pt":1717323532461,"mc":[{"id":"1.229554930","rc":[{"atl":[[1000,3.35]],"id":65894825}],"con":true,"img":false}]}
{"op":"mcm","clk":"11450583575","pt":1717323532675,"mc":[{"id":"1.229554930","rc":[{"atl":[[1000,3.33]],"id":65894825}],"con":true,"img":false}]}
{"op":"mcm","clk":"11450583602","pt":1717323532982,"mc":[{"id":"1.229554930","rc":[{"atl":[[1000,1]],"id":65894825}],"con":true,"img":false}]}
{"op":"mcm","clk":"11450583621","pt":1717323533096,"mc":[{"id":"1.229554930","rc":[{"atl":[[5.7,2.33]],"id":65894825}],"con":true,"img":false}]}
{"op":"mcm","clk":"11450584152","pt":1717323538781,"mc":[{"id":"1.229554930","rc":[{"atl":[[6.2,0],[5.7,5.35]],"id":65894825}],"con":true,"img":false}]}
{"op":"mcm","clk":"11450584162","pt":1717323538885,"mc":[{"id":"1.229554930","rc":[{"atl":[[6.2,19.23],[5.7,2.33]],"id":65894825}],"con":true,"img":false}]}
{"op":"mcm","clk":"11450584172","pt":1717323538993,"mc":[{"id":"1.229554930","rc":[{"atl":[[6.2,0]],"id":65894825}],"con":true,"img":false}]}
{"op":"mcm","clk":"11450584179","pt":1717323539098,"mc":[{"id":"1.229554930","rc":[{"atl":[[5.7,7.69]],"id":65894825}],"con":true,"img":false}]}
{"op":"mcm","clk":"11450592083","pt":1717323620990,"mc":[{"id":"1.229554930","rc":[{"atl":[[2.92,0]],"id":47530316},{"spn":2.32,"spf":"NaN","id":47530316},{"spn":3.93,"spf":"NaN","id":65894825}],"con":true,"img":false}]}
{"op":"mcm","clk":"11450596782","pt":1717323667353,"mc":[{"id":"1.229554930","rc":[{"spl":[[1.01,0.81]],"id":66826631},{"spl":[[1.01,1.56]],"id":44736449}],"con":true,"img":false}]}
{"op":"mcm","clk":"11450597280","pt":1717323671884,"mc":[{"id":"1.229554930","rc":[{"atl":[[6.4,0]],"id":65894825}],"con":true,"img":false}]}
{"op":"mcm","clk":"11450598076","pt":1717323680182,"mc":[{"id":"1.229554930","rc":[{"atb":[[4.3,31.67],[3.9,72.08],[3.65,78.88]],"id":66826631},{"atl":[[34,6.33],[22,6.63]],"id":66826631},{"atb":[[1.44,475.13],[1.54,193.57],[1.49,426.65]],"id":47530316},{"atl":[[3.6,80.4],[3.1,66.37]],"id":47530316},{"atb":[[2.06,197.22],[1.98,213.33],[2.16,90.11]],"id":65894825},{"atl":[[9,26.13],[7,23.22]],"id":65894825},{"atb":[[38,2.82],[24,9.08],[29,7.46]],"id":44736449},{"atl":[[550,0.38],[450,0.3]],"id":44736449}],"con":true,"img":false}]}
{"op":"mcm","clk":"11450599076","pt":1717323691709,"mc":[{"id":"1.229554930","rc":[{"atb":[[4.3,63.35],[3.9,144.17],[3.65,157.77]],"id":66826631},{"atl":[[34,12.67],[22,13.27]],"id":66826631},{"spn":4.3,"spf":1.0,"id":66826631},{"atb":[[1.44,950.27],[1.54,387.15],[1.49,853.31]],"id":47530316},{"atl":[[3.6,160.81],[3.1,132.74]],"id":47530316},{"atb":[[2.06,394.45],[1.98,426.66],[2.16,180.22]],"id":65894825},{"atl":[[9,52.26],[7,46.45]],"id":65894825},{"atb":[[38,5.65],[24,18.17],[29,14.93]],"id":44736449},{"atl":[[550,0.76],[450,0.61]],"id":44736449},{"spn":38.0,"spf":1.0,"id":44736449}],"con":true,"img":false}]}
{"op":"mcm","clk":"11450599460","pt":1717323695205,"mc":[{"id":"1.229554930","rc":[{"atl":[[2.92,6.6]],"id":47530316}],"con":true,"img":false}]}
{"op":"mcm","clk":"11450599474","pt":1717323695311,"mc":[{"id":"1.229554930","rc":[{"atl":[[6.4,3.01]],"id":65894825}],"con":true,"img":false}]}
{"op":"mcm","clk":"11450601655","pt":1717323719735,"mc":[{"id":"1.229554930","rc":[{"atl":[[5.7,5.36]],"id":65894825}],"con":true,"img":false}]}
{"op":"mcm","clk":"11450601664","pt":1717323719839,"mc":[{"id":"1.229554930","rc":[{"atl":[[6.2,19.23],[5.7,0]],"id":65894825}],"con":true,"img":false}]}
{"op":"mcm","clk":"11450602366","pt":1717323726449,"mc":[{"id":"1.229554930","rc":[{"atl":[[6,4.42]],"id":65894825}],"con":true,"img":false}]}
{"op":"mcm","clk":"11450603683","pt":1717323738861,"mc":[{"id":"1.229554930","rc":[{"atl":[[1000,3.35]],"id":65894825}],"con":true,"img":false}]}
{"op":"mcm","clk":"11450603701","pt":1717323739063,"mc":[{"id":"1.229554930","rc":[{"atl":[[1000,3.33]],"id":65894825}],"con":true,"img":false}]}
{"op":"mcm","clk":"11450603735","pt":1717323739372,"mc":[{"id":"1.229554930","rc":[{"atl":[[1000,1]],"id":65894825}],"con":true,"img":false}]}
{"op":"mcm","clk":"11450603742","pt":1717323739475,"mc":[{"id":"1.229554930","rc":[{"atl":[[5.7,2.33]],"id":65894825}],"con":true,"img":false}]}
{"op":"mcm","clk":"11450603891","pt":1717323741257,"mc":[{"id":"1.229554930","rc":[{"atl":[[6,0]],"id":65894825}],"con":true,"img":false}]}
{"op":"mcm","clk":"11450604258","pt":1717323744976,"mc":[{"id":"1.229554930","rc":[{"atl":[[6.2,0],[5.7,5.35]],"id":65894825}],"con":true,"img":false}]}
{"op":"mcm","clk":"11450604271","pt":1717323745076,"mc":[{"id":"1.229554930","rc":[{"atl":[[6.2,19.23],[5.7,2.33]],"id":65894825}],"con":true,"img":false}]}
{"op":"mcm","clk":"11450604279","pt":1717323745179,"mc":[{"id":"1.229554930","rc":[{"atl":[[6.2,0],[5.7,7.69]],"id":65894825}],"con":true,"img":false}]}
{"op":"mcm","clk":"11450614276","pt":1717323847517,"mc":[{"id":"1.229554930","rc":[{"atb":[[1.91,0],[2.28,78.13]],"id":66826631},{"spn":2.23,"spf":"NaN","id":47530316},{"atb":[[1.58,172.41],[1.5,0]],"id":65894825}],"con":true,"img":false}]}
{"op":"mcm","clk":"11450614873","pt":1717323852674,"mc":[{"id":"1.229554930","rc":[{"atb":[[2.28,0],[2.14,87.72]],"id":66826631}],"con":true,"img":false}]}
{"op":"mcm","clk":"11450622760","pt":1717323928486,"mc":[{"id":"1.229554930","rc":[{"atl":[[2.92,0]],"id":47530316},{"spn":2.32,"spf":"NaN","id":47530316}],"con":true,"img":false}]}
{"op":"mcm","clk":"11450623029","pt":1717323931298,"mc":[{"id":"1.229554930","rc":[{"atl":[[3.05,7.54]],"id":47530316}],"con":true,"img":false}]}
{"op":"mcm","clk":"11450623291","pt":1717323933805,"mc":[{"id":"1.229554930","rc":[{"atl":[[5.7,5.36]],"id":65894825}],"con":true,"img":false}]}
{"op":"mcm","clk":"11450623299","pt":1717323933915,"mc":[{"id":"1.229554930","rc":[{"atl":[[6.2,19.23]],"id":65894825}],"con":true,"img":false}]}
{"op":"mcm","clk":"11450623311","pt":1717323934011,"mc":[{"id":"1.229554930","rc":[{"atl":[[5.7,0]],"id":65894825}],"con":true,"img":false}]}
{"op":"mcm","clk":"11450623385","pt":1717323934898,"mc":[{"id":"1.229554930","rc":[{"atl":[[6,4.37]],"id":65894825}],"con":true,"img":false}]}
{"op":"mcm","clk":"11450623397","pt":1717323934998,"mc":[{"id":"1.229554930","rc":[{"atl":[[6.2,0],[5.9,4.37]],"id":65894825}],"con":true,"img":false}]}
{"op":"mcm","clk":"11450623641","pt":1717323937700,"mc":[{"id":"1.229554930","rc":[{"atl":[[6,0]],"id":65894825}],"con":true,"img":false}]}
{"op":"mcm","clk":"11450623869","pt":1717323940106,"mc":[{"id":"1.229554930","rc":[{"atl":[[6.2,19.23]],"id":65894825}],"con":true,"img":false}]}
{"op":"mcm","clk":"11450623876","pt":1717323940209,"mc":[{"id":"1.229554930","rc":[{"atl":[[5.9,0]],"id":65894825}],"con":true,"img":false}]}
{"op":"mcm","clk":"11450624196","pt":1717323943430,"mc":[{"id":"1.229554930","rc":[{"atl":[[6,4.41]],"id":65894825}],"con":true,"img":false}]}
{"op":"mcm","clk":"11450624844","pt":1717323950611,"mc":[{"id":"1.229554930","rc":[{"atl":[[1000,3.35]],"id":65894825}],"con":true,"img":false}]}
{"op":"mcm","clk":"11450624856","pt":1717323950818,"mc":[{"id":"1.229554930","rc":[{"atl":[[1000,3.33]],"id":65894825}],"con":true,"img":false}]}
{"op":"mcm","clk":"11450624885","pt":1717323951031,"mc":[{"id":"1.229554930","rc":[{"atl":[[1000,1]],"id":65894825}],"con":true,"img":false}]}
{"op":"mcm","clk":"11450624888","pt":1717323951136,"mc":[{"id":"1.229554930","rc":[{"atl":[[5.7,2.33]],"id":65894825}],"con":true,"img":false}]}
{"op":"mcm","clk":"11450625034","pt":1717323952696,"mc":[{"id":"1.229554930","rc":[{"atl":[[6,0]],"id":65894825}],"con":true,"img":false}]}
{"op":"mcm","clk":"11450625913","pt":1717323963031,"mc":[{"id":"1.229554930","rc":[{"atl":[[5.7,5.35]],"id":65894825}],"con":true,"img":false}]}
{"op":"mcm","clk":"11450625924","pt":1717323963142,"mc":[{"id":"1.229554930","rc":[{"atl":[[6.2,0]],"id":65894825}],"con":true,"img":false}]}
{"op":"mcm","clk":"11450626163","pt":1717323966624,"mc":[{"id":"1.229554930","rc":[{"atl":[[6.4,0]],"id":65894825}],"con":true,"img":false}]}
{"op":"mcm","clk":"11450626477","pt":1717323970067,"mc":[{"id":"1.229554930","rc":[{"atb":[[1.91,109.89],[2.14,0]],"id":66826631},{"atb":[[1.5,200]],"id":65894825}],"con":true,"img":false}]}
{"op":"mcm","clk":"11450626489","pt":1717323970118,"mc":[{"id":"1.229554930","rc":[{"atb":[[1.58,0]],"id":65894825}],"con":true,"img":false}]}
{"op":"mcm","clk":"11450629301","pt":1717324000602,"mc":[{"id":"1.229554930","rc":[{"atl":[[2.92,6.6]],"id":47530316},{"spn":2.23,"spf":"NaN","id":47530316}],"con":true,"img":false}]}
{"op":"mcm","clk":"11450629323","pt":1717324000766,"mc":[{"id":"1.229554930","rc":[{"atl":[[6.4,3.01]],"id":65894825}],"con":true,"img":false}]}
{"op":"mcm","clk":"11450629633","pt":1717324003777,"mc":[{"id":"1.229554930","rc":[{"atl":[[3.05,0]],"id":47530316}],"con":true,"img":false}]}
{"op":"mcm","clk":"11450632132","pt":1717324032347,"mc":[{"id":"1.229554930","rc":[{"atb":[[4.3,31.67],[3.9,72.08],[3.65,78.88]],"id":66826631},{"atl":[[34,6.33],[22,6.63]],"id":66826631},{"atb":[[1.44,475.13],[1.54,193.57],[1.49,426.65]],"id":47530316},{"atl":[[3.6,80.4],[3.1,66.37]],"id":47530316},{"atb":[[2.06,197.22],[1.98,213.33],[2.16,90.11]],"id":65894825},{"atl":[[9,26.13],[7,23.22]],"id":65894825},{"atb":[[38,2.82],[24,9.08],[29,7.46]],"id":44736449},{"atl":[[550,0.38],[450,0.3]],"id":44736449}],"con":true,"img":false}]}
{"op":"mcm","clk":"11450633144","pt":1717324044547,"mc":[{"id":"1.229554930","rc":[{"atb":[[4.3,63.35],[3.9,144.17],[3.65,157.77]],"id":66826631},{"atl":[[34,12.67],[22,13.27]],"id":66826631},{"atb":[[1.44,950.27],[1.54,387.15],[1.49,853.31]],"id":47530316},{"atl":[[3.6,160.81],[3.1,132.74]],"id":47530316},{"atb":[[2.06,394.45],[1.98,426.66],[2.16,180.22]],"id":65894825},{"atl":[[9,52.26],[7,46.45]],"id":65894825},{"atb":[[38,5.65],[24,18.17],[29,14.93]],"id":44736449},{"atl":[[550,0.76],[450,0.61]],"id":44736449}],"con":true,"img":false}]}
{"op":"mcm","clk":"11450640848","pt":1717324131836,"mc":[{"id":"1.229554930","rc":[{"atl":[[5.7,3.02]],"id":65894825}],"con":true,"img":false}]}
{"op":"mcm","clk":"11450640850","pt":1717324131937,"mc":[{"id":"1.229554930","rc":[{"atl":[[6.2,19.23],[5.7,0]],"id":65894825}],"con":true,"img":false}]}
{"op":"mcm","clk":"11450641038","pt":1717324133624,"mc":[{"id":"1.229554930","rc":[{"atl":[[6,4.45]],"id":65894825}],"con":true,"img":false}]}
{"op":"mcm","clk":"11450641045","pt":1717324133732,"mc":[{"id":"1.229554930","rc":[{"atl":[[6.2,0],[5.9,4.45]],"id":65894825}],"con":true,"img":false}]}
{"op":"mcm","clk":"11450641318","pt":1717324136850,"mc":[{"id":"1.229554930","rc":[{"atl":[[6,0]],"id":65894825}],"con":true,"img":false}]}
{"op":"mcm","clk":"11450641462","pt":1717324138931,"mc":[{"id":"1.229554930","rc":[{"atl":[[6.2,19.23],[5.9,0]],"id":65894825}],"con":true,"img":false}]}
{"op":"mcm","clk":"11450641763","pt":1717324142431,"mc":[{"id":"1.229554930","rc":[{"atl":[[6,4.44]],"id":65894825}],"con":true,"img":false}]}
{"op":"mcm","clk":"11450642958","pt":1717324154741,"mc":[{"id":"1.229554930","rc":[{"atl":[[5.9,4.44]],"id":65894825}],"con":true,"img":false}]}
{"op":"mcm","clk":"11450642968","pt":1717324154853,"mc":[{"id":"1.229554930","rc":[{"atl":[[6.2,0]],"id":65894825}],"con":true,"img":false}]}
{"op":"mcm","clk":"11450643185","pt":1717324157661,"mc":[{"id":"1.229554930","rc":[{"atl":[[6,0]],"id":65894825}],"con":true,"img":false}]}
{"op":"mcm","clk":"11450643193","pt":1717324157760,"mc":[{"id":"1.229554930","rc":[{"atl":[[6.2,19.23]],"id":65894825}],"con":true,"img":false}]}
{"op":"mcm","clk":"11450643203","pt":1717324157868,"mc":[{"id":"1.229554930","rc":[{"atl":[[5.9,0]],"id":65894825}],"con":true,"img":false}]}
{"op":"mcm","clk":"11450643536","pt":1717324160982,"mc":[{"id":"1.229554930","rc":[{"atl":[[6,4.4]],"id":65894825}],"con":true,"img":false}]}
{"op":"mcm","clk":"11450643558","pt":1717324161149,"mc":[{"id":"1.229554930","rc":[{"atl":[[6.2,0],[5.9,4.4]],"id":65894825}],"con":true,"img":false}]}
{"op":"mcm","clk":"11450643869","pt":1717324163654,"mc":[{"id":"1.229554930","rc":[{"atl":[[6,0]],"id":65894825}],"con":true,"img":false}]}
{"op":"mcm","clk":"11450644104","pt":1717324166266,"mc":[{"id":"1.229554930","rc":[{"atl":[[6.2,19.23],[5.9,0]],"id":65894825}],"con":true,"img":false}]}
{"op":"mcm","clk":"11450644148","pt":1717324166687,"mc":[{"id":"1.229554930","rc":[{"atl":[[6,4.38]],"id":65894825}],"con":true,"img":false}]}
{"op":"mcm","clk":"11450645643","pt":1717324181883,"mc":[{"id":"1.229554930","rc":[{"atl":[[6.2,0],[5.9,4.38]],"id":65894825}],"con":true,"img":false}]}
{"op":"mcm","clk":"11450645917","pt":1717324184693,"mc":[{"id":"1.229554930","rc":[{"atl":[[6,0]],"id":65894825}],"con":true,"img":false}]}
{"op":"mcm","clk":"11450646178","pt":1717324187096,"mc":[{"id":"1.229554930","rc":[{"atl":[[6.2,19.23],[5.9,0]],"id":65894825}],"con":true,"img":false}]}
{"op":"mcm","clk":"11450646232","pt":1717324187714,"mc":[{"id":"1.229554930","rc":[{"atl":[[6,4.36]],"id":65894825}],"con":true,"img":false}]}
{"op":"mcm","clk":"11450648123","pt":1717324205325,"mc":[{"id":"1.229554930","rc":[{"atl":[[1000,3.35]],"id":65894825},{"spn":4.08,"spf":"NaN","id":65894825}],"con":true,"img":false}]}
{"op":"mcm","clk":"11450648271","pt":1717324206816,"mc":[{"id":"1.229554930","rc":[{"atl":[[1000,3.33]],"id":65894825}],"con":true,"img":false}]}
{"op":"mcm","clk":"11450648295","pt":1717324207024,"mc":[{"id":"1.229554930","rc":[{"atl":[[1000,1]],"id":65894825}],"con":true,"img":false}]}
{"op":"mcm","clk":"11450648315","pt":1717324207235,"mc":[{"id":"1.229554930","rc":[{"atl":[[5.7,2.33]],"id":65894825}],"con":true,"img":false}]}
{"op":"mcm","clk":"11450648343","pt":1717324207540,"mc":[{"id":"1.229554930","rc":[{"atl":[[5.7,6.69]],"id":65894825}],"con":true,"img":false}]}
{"op":"mcm","clk":"11450648354","pt":1717324207643,"mc":[{"id":"1.229554930","rc":[{"atl":[[6.2,0]],"id":65894825}],"con":true,"img":false}]}
{"op":"mcm","clk":"11450648509","pt":1717324209057,"mc":[{"id":"1.229554930","rc":[{"atl":[[6,0]],"id":65894825}],"con":true,"img":false}]}
{"op":"mcm","clk":"11450650022","pt":1717324223365,"mc":[{"id":"1.229554930","rc":[{"atl":[[2.92,0]],"id":47530316}],"con":true,"img":false}]}
{"op":"mcm","clk":"11450650063","pt":1717324223773,"mc":[{"id":"1.229554930","rc":[{"atl":[[3.05,7.54]],"id":47530316}],"con":true,"img":false}]}
{"op":"mcm","clk":"11450653955","pt":1717324261575,"mc":[{"id":"1.229554930","rc":[{"atl":[[6.4,0]],"id":65894825}],"con":true,"img":false}]}
{"op":"mcm","clk":"11450657820","pt":1717324298744,"mc":[{"id":"1.229554930","rc":[{"atl":[[2.92,6.6]],"id":47530316},{"spn":3.93,"spf":"NaN","id":65894825}],"con":true,"img":false}]}
{"op":"mcm","clk":"11450657833","pt":1717324298802,"mc":[{"id":"1.229554930","rc":[{"atl":[[6.4,3.01]],"id":65894825}],"con":true,"img":false}]}
{"op":"mcm","clk":"11450657862","pt":1717324299163,"mc":[{"id":"1.229554930","rc":[{"atl":[[3.05,0]],"id":47530316}],"con":true,"img":false}]}
{"op":"mcm","clk":"11450664295","pt":1717324354364,"mc":[{"id":"1.229554930","rc":[{"atb":[[1.5,15.7]],"id":47530316},{"atb":[[2.1,7.13]],"id":65894825}],"con":true,"img":false}]}
{"op":"mcm","clk":"11450666055","pt":1717324370658,"mc":[{"id":"1.229554930","rc":[{"atb":[[4.3,31.67],[3.9,72.08],[3.65,78.88]],"id":66826631},{"atl":[[34,6.33],[22,6.63]],"id":66826631},{"atb":[[1.44,475.13],[1.54,193.57],[1.49,426.65]],"id":47530316},{"atl":[[3.6,80.4],[3.1,66.37]],"id":47530316},{"atb":[[2.06,197.22],[1.98,213.33],[2.16,90.11]],"id":65894825},{"atl":[[9,26.13],[7,23.22]],"id":65894825},{"atb":[[38,2.82],[24,9.08],[29,7.46]],"id":44736449},{"atl":[[550,0.38],[450,0.3]],"id":44736449}],"con":true,"img":false}]}
{"op":"mcm","clk":"11450667813","pt":1717324387087,"mc":[{"id":"1.229554930","rc":[{"atb":[[4.3,63.35],[3.9,144.17],[3.65,157.77]],"id":66826631},{"atl":[[34,12.67],[22,13.27]],"id":66826631},{"atb":[[1.44,950.27],[1.54,387.15],[1.49,853.31]],"id":47530316},{"atl":[[3.6,160.81],[3.1,132.74]],"id":47530316},{"atb":[[38,5.65],[24,18.17],[29,14.93]],"id":44736449},{"atl":[[550,0.76],[450,0.61]],"id":44736449},{"atb":[[2.06,394.45],[1.98,426.66],[2.16,180.22]],"id":65894825},{"atl":[[9,52.26],[7,46.45]],"id":65894825}],"con":true,"img":false}]}
{"op":"mcm","clk":"11450668219","pt":1717324390484,"mc":[{"id":"1.229554930","rc":[{"atl":[[5.7,4.36]],"id":65894825}],"con":true,"img":false}]}
{"op":"mcm","clk":"11450668235","pt":1717324390592,"mc":[{"id":"1.229554930","rc":[{"atl":[[6.2,19.23]],"id":65894825}],"con":true,"img":false}]}
{"op":"mcm","clk":"11450668241","pt":1717324390692,"mc":[{"id":"1.229554930","rc":[{"atl":[[5.7,0]],"id":65894825}],"con":true,"img":false}]}
{"op":"mcm","clk":"11450668500","pt":1717324392759,"mc":[{"id":"1.229554930","rc":[{"atl":[[6,4.48]],"id":65894825}],"con":true,"img":false}]}
{"op":"mcm","clk":"11450670326","pt":1717324408490,"mc":[{"id":"1.229554930","rc":[{"atl":[[1000,3.35]],"id":65894825}],"con":true,"img":false}]}
{"op":"mcm","clk":"11450670353","pt":1717324408698,"mc":[{"id":"1.229554930","rc":[{"atl":[[1000,3.33]],"id":65894825}],"con":true,"img":false}]}
{"op":"mcm","clk":"11450670379","pt":1717324408914,"mc":[{"id":"1.229554930","rc":[{"atl":[[1000,1]],"id":65894825}],"con":true,"img":false}]}
{"op":"mcm","clk":"11450670391","pt":1717324409015,"mc":[{"id":"1.229554930","rc":[{"atl":[[5.7,2.33]],"id":65894825}],"con":true,"img":false}]}
{"op":"mcm","clk":"11450670403","pt":1717324409120,"mc":[{"id":"1.229554930","rc":[{"atl":[[6.2,0],[5.9,4.48]],"id":65894825}],"con":true,"img":false}]}
{"op":"mcm","clk":"11450670627","pt":1717324410903,"mc":[{"id":"1.229554930","rc":[{"atl":[[6,0]],"id":65894825}],"con":true,"img":false}]}
{"op":"mcm","clk":"11450672561","pt":1717324427303,"mc":[{"id":"1.229554930","rc":[{"atl":[[5.7,5.35],[5.9,0]],"id":65894825}],"con":true,"img":false}]}
{"op":"mcm","clk":"11450682858","pt":1717324509554,"mc":[{"id":"1.229554930","rc":[{"atl":[[2.92,0]],"id":47530316},{"spn":2.32,"spf":"NaN","id":47530316}],"con":true,"img":false}]}
{"op":"mcm","clk":"11450682955","pt":1717324510391,"mc":[{"id":"1.229554930","rc":[{"atl":[[3.05,7.73]],"id":47530316}],"con":true,"img":false}]}
{"op":"mcm","clk":"11450686565","pt":1717324543407,"mc":[{"id":"1.229554930","rc":[{"atl":[[6.4,0]],"id":65894825}],"con":true,"img":false}]}
{"op":"mcm","clk":"11450690563","pt":1717324580776,"mc":[{"id":"1.229554930","rc":[{"atl":[[2.92,6.6]],"id":47530316},{"spn":2.23,"spf":"NaN","id":47530316}],"con":true,"img":false}]}
{"op":"mcm","clk":"11450690586","pt":1717324580937,"mc":[{"id":"1.229554930","rc":[{"atl":[[6.4,3.01]],"id":65894825}],"con":true,"img":false}]}
{"op":"mcm","clk":"11450690813","pt":1717324582766,"mc":[{"id":"1.229554930","rc":[{"atl":[[3.05,0]],"id":47530316}],"con":true,"img":false}]}
{"op":"mcm","clk":"11450692822","pt":1717324599298,"mc":[{"id":"1.229554930","rc":[{"atl":[[5.7,3.02]],"id":65894825}],"con":true,"img":false}]}
{"op":"mcm","clk":"11450692838","pt":1717324599350,"mc":[{"id":"1.229554930","rc":[{"atl":[[6.2,19.23],[5.7,0]],"id":65894825}],"con":true,"img":false}]}
{"op":"mcm","clk":"11450693068","pt":1717324601064,"mc":[{"id":"1.229554930","rc":[{"atl":[[6,4.37]],"id":65894825}],"con":true,"img":false}]}
{"op":"mcm","clk":"11450694799","pt":1717324615698,"mc":[{"id":"1.229554930","rc":[{"atl":[[6.2,0],[5.9,4.37]],"id":65894825}],"con":true,"img":false}]}
{"op":"mcm","clk":"11450694985","pt":1717324617311,"mc":[{"id":"1.229554930","rc":[{"atl":[[1000,3.35]],"id":65894825}],"con":true,"img":false}]}
{"op":"mcm","clk":"11450695009","pt":1717324617523,"mc":[{"id":"1.229554930","rc":[{"atl":[[1000,3.08]],"id":65894825}],"con":true,"img":false}]}
{"op":"mcm","clk":"11450695032","pt":1717324617682,"mc":[{"id":"1.229554930","rc":[{"atl":[[1000,1]],"id":65894825}],"con":true,"img":false}]}
{"op":"mcm","clk":"11450695044","pt":1717324617789,"mc":[{"id":"1.229554930","rc":[{"atl":[[6.4,5.1]],"id":65894825}],"con":true,"img":false}]}
{"op":"mcm","clk":"11450695161","pt":1717324618774,"mc":[{"id":"1.229554930","rc":[{"atl":[[6,0]],"id":65894825}],"con":true,"img":false}]}
{"op":"mcm","clk":"11450695174","pt":1717324618890,"mc":[{"id":"1.229554930","rc":[{"atl":[[6.2,19.23],[5.9,0]],"id":65894825}],"con":true,"img":false}]}
{"op":"mcm","clk":"11450696282","pt":1717324628405,"mc":[{"id":"1.229554930","rc":[{"atl":[[6,4.45]],"id":65894825}],"con":true,"img":false}]}
{"op":"mcm","clk":"11450696297","pt":1717324628521,"mc":[{"id":"1.229554930","rc":[{"atl":[[6.2,0],[5.9,5.1]],"id":65894825}],"con":true,"img":false}]}
{"op":"mcm","clk":"11450696593","pt":1717324631126,"mc":[{"id":"1.229554930","rc":[{"atl":[[6,0]],"id":65894825}],"con":true,"img":false}]}
{"op":"mcm","clk":"11450696605","pt":1717324631234,"mc":[{"id":"1.229554930","rc":[{"atl":[[6.2,19.23],[5.9,0]],"id":65894825}],"con":true,"img":false}]}
{"op":"mcm","clk":"11450697311","pt":1717324637141,"mc":[{"id":"1.229554930","rc":[{"atl":[[6,4.44]],"id":65894825}],"con":true,"img":false}]}
{"op":"mcm","clk":"11450698537","pt":1717324647273,"mc":[{"id":"1.229554930","rc":[{"atl":[[6.2,0],[5.9,5.1]],"id":65894825},{"spn":4.03,"spf":"NaN","id":65894825}],"con":true,"img":false}]}
{"op":"mcm","clk":"11450698765","pt":1717324649256,"mc":[{"id":"1.229554930","rc":[{"atl":[[6,0]],"id":65894825}],"con":true,"img":false}]}
{"op":"mcm","clk":"11450698771","pt":1717324649358,"mc":[{"id":"1.229554930","rc":[{"atl":[[6.2,19.23],[5.9,0]],"id":65894825}],"con":true,"img":false}]}
{"op":"mcm","clk":"11450699509","pt":1717324655376,"mc":[{"id":"1.229554930","rc":[{"atl":[[6,4.41]],"id":65894825}],"con":true,"img":false}]}
{"op":"mcm","clk":"11450699535","pt":1717324655538,"mc":[{"id":"1.229554930","rc":[{"atl":[[6.2,0],[5.9,5.1]],"id":65894825}],"con":true,"img":false}]}
{"op":"mcm","clk":"11450699812","pt":1717324658140,"mc":[{"id":"1.229554930","rc":[{"atl":[[6,0]],"id":65894825}],"con":true,"img":false}]}
{"op":"mcm","clk":"11450700089","pt":1717324660644,"mc":[{"id":"1.229554930","rc":[{"atl":[[6.2,19.23],[5.9,0]],"id":65894825}],"con":true,"img":false}]}
{"op":"mcm","clk":"11450700532","pt":1717324664375,"mc":[{"id":"1.229554930","rc":[{"atl":[[6,4.45]],"id":65894825}],"con":true,"img":false}]}
{"op":"mcm","clk":"11450701886","pt":1717324676447,"mc":[{"id":"1.229554930","rc":[{"atl":[[6.2,0],[5.9,5.1]],"id":65894825}],"con":true,"img":false}]}
{"op":"mcm","clk":"11450702246","pt":1717324679411,"mc":[{"id":"1.229554930","rc":[{"atl":[[6,0]],"id":65894825}],"con":true,"img":false}]}
{"op":"mcm","clk":"11450702490","pt":1717324681619,"mc":[{"id":"1.229554930","rc":[{"atl":[[6.2,19.23],[5.9,0]],"id":65894825}],"con":true,"img":false}]}
{"op":"mcm","clk":"11450703011","pt":1717324685716,"mc":[{"id":"1.229554930","rc":[{"atl":[[6,4.41]],"id":65894825}],"con":true,"img":false}]}
{"op":"mcm","clk":"11450703715","pt":1717324692033,"mc":[{"id":"1.229554930","rc":[{"atl":[[6.2,0],[5.9,5.1]],"id":65894825}],"con":true,"img":false}]}
{"op":"mcm","clk":"11450703963","pt":1717324694435,"mc":[{"id":"1.229554930","rc":[{"atl":[[6,0]],"id":65894825}],"con":true,"img":false}]}
{"op":"mcm","clk":"11450703979","pt":1717324694630,"mc":[{"id":"1.229554930","rc":[{"atl":[[6.2,19.23],[5.9,0]],"id":65894825}],"con":true,"img":false}]}
{"op":"mcm","clk":"11450704272","pt":1717324697455,"mc":[{"id":"1.229554930","rc":[{"atl":[[6,4.37]],"id":65894825}],"con":true,"img":false}]}
{"op":"mcm","clk":"11450704293","pt":1717324697620,"mc":[{"id":"1.229554930","rc":[{"atl":[[6.2,0],[5.9,5.1]],"id":65894825}],"con":true,"img":false}]}
{"op":"mcm","clk":"11450704548","pt":1717324700532,"mc":[{"id":"1.229554930","rc":[{"atl":[[6,0]],"id":65894825}],"con":true,"img":false}]}
{"op":"mcm","clk":"11450704557","pt":1717324700641,"mc":[{"id":"1.229554930","rc":[{"atl":[[6.2,19.23]],"id":65894825}],"con":true,"img":false}]}
{"op":"mcm","clk":"11450704565","pt":1717324700743,"mc":[{"id":"1.229554930","rc":[{"atl":[[5.9,0]],"id":65894825}],"con":true,"img":false}]}
{"op":"mcm","clk":"11450705183","pt":1717324706551,"mc":[{"id":"1.229554930","rc":[{"atl":[[6,4.47]],"id":65894825}],"con":true,"img":false}]}
{"op":"mcm","clk":"11450705808","pt":1717324712379,"mc":[{"id":"1.229554930","rc":[{"atb":[[4.3,31.67],[3.9,72.08],[3.65,78.88]],"id":66826631},{"atl":[[34,6.33],[22,6.63]],"id":66826631},{"atb":[[1.44,475.13],[1.54,193.57],[1.49,426.65]],"id":47530316},{"atl":[[3.6,80.4],[3.1,66.37]],"id":47530316},{"atb":[[2.06,197.22],[1.98,213.33],[2.16,90.11]],"id":65894825},{"atl":[[9,26.13],[7,23.22]],"id":65894825},{"spn":4.08,"spf":"NaN","id":65894825},{"atb":[[38,2.82],[24,9.08],[29,7.46]],"id":44736449},{"atl":[[550,0.38],[450,0.3]],"id":44736449}],"con":true,"img":false}]}
{"op":"mcm","clk":"11450706135","pt":1717324715928,"mc":[{"id":"1.229554930","rc":[{"atl":[[5.9,5.1]],"id":65894825}],"con":true,"img":false}]}
{"op":"mcm","clk":"11450706144","pt":1717324716028,"mc":[{"id":"1.229554930","rc":[{"atl":[[6.2,0]],"id":65894825}],"con":true,"img":false}]}
{"op":"mcm","clk":"11450706383","pt":1717324718726,"mc":[{"id":"1.229554930","rc":[{"atl":[[6,0]],"id":65894825}],"con":true,"img":false}]}
{"op":"mcm","clk":"11450706614","pt":1717324721056,"mc":[{"id":"1.229554930","rc":[{"atl":[[6.2,19.23]],"id":65894825}],"con":true,"img":false}]}
{"op":"mcm","clk":"11450706621","pt":1717324721160,"mc":[{"id":"1.229554930","rc":[{"atl":[[5.9,0]],"id":65894825}],"con":true,"img":false}]}
{"op":"mcm","clk":"11450706980","pt":1717324724757,"mc":[{"id":"1.229554930","rc":[{"atl":[[6,4.44]],"id":65894825}],"con":true,"img":false}]}
{"op":"mcm","clk":"11450707053","pt":1717324725487,"mc":[{"id":"1.229554930","rc":[{"atb":[[4.3,63.35],[3.9,144.17],[3.65,157.77]],"id":66826631},{"atl":[[34,12.67],[22,13.27]],"id":66826631},{"atb":[[1.44,950.27],[1.54,387.15],[1.49,853.31]],"id":47530316},{"atl":[[3.6,160.81],[3.1,132.74]],"id":47530316},{"atb":[[2.06,394.45],[1.98,426.66],[2.16,180.22]],"id":65894825},{"atl":[[9,52.26],[7,46.45]],"id":65894825},{"atb":[[38,5.65],[24,18.17],[29,14.93]],"id":44736449},{"atl":[[550,0.76],[450,0.61]],"id":44736449}],"con":true,"img":false}]}
{"op":"mcm","clk":"11450708143","pt":1717324736194,"mc":[{"id":"1.229554930","rc":[{"atl":[[6.2,0],[5.9,5.1]],"id":65894825}],"con":true,"img":false}]}
{"op":"mcm","clk":"11450708492","pt":1717324739582,"mc":[{"id":"1.229554930","rc":[{"atl":[[6,0]],"id":65894825}],"con":true,"img":false}]}
{"op":"mcm","clk":"11450708685","pt":1717324741307,"mc":[{"id":"1.229554930","rc":[{"atl":[[6.2,19.23],[5.9,0]],"id":65894825}],"con":true,"img":false}]}
{"op":"mcm","clk":"11450708840","pt":1717324742677,"mc":[{"id":"1.229554930","rc":[{"atl":[[6,4.37]],"id":65894825}],"con":true,"img":false}]}
{"op":"mcm","clk":"11450710278","pt":1717324756167,"mc":[{"id":"1.229554930","rc":[{"atl":[[5.9,5.1]],"id":65894825}],"con":true,"img":false}]}
{"op":"mcm","clk":"11450710290","pt":1717324756277,"mc":[{"id":"1.229554930","rc":[{"atl":[[6.2,0]],"id":65894825}],"con":true,"img":false}]}
{"op":"mcm","clk":"11450710428","pt":1717324757671,"mc":[{"id":"1.229554930","rc":[{"atl":[[6,0]],"id":65894825}],"con":true,"img":false}]}
{"op":"mcm","clk":"11450710441","pt":1717324757776,"mc":[{"id":"1.229554930","rc":[{"atl":[[6.2,19.23]],"id":65894825}],"con":true,"img":false}]}
{"op":"mcm","clk":"11450710449","pt":1717324757827,"mc":[{"id":"1.229554930","rc":[{"atl":[[5.9,0]],"id":65894825}],"con":true,"img":false}]}
{"op":"mcm","clk":"11450710773","pt":1717324760850,"mc":[{"id":"1.229554930","rc":[{"atl":[[6,4.44]],"id":65894825}],"con":true,"img":false}]}
{"op":"mcm","clk":"11450711372","pt":1717324766449,"mc":[{"id":"1.229554930","rc":[{"atl":[[2.92,0]],"id":47530316}],"con":true,"img":false}]}
{"op":"mcm","clk":"11450711726","pt":1717324769681,"mc":[{"id":"1.229554930","rc":[{"atl":[[3.05,7.64]],"id":47530316}],"con":true,"img":false}]}
{"op":"mcm","clk":"11450711988","pt":1717324772498,"mc":[{"id":"1.229554930","rc":[{"spn":2.29,"spf":"NaN","id":47530316},{"atl":[[6.2,0],[5.9,5.1]],"id":65894825},{"spn":4.03,"spf":"NaN","id":65894825}],"con":true,"img":false}]}
{"op":"mcm","clk":"11450712381","pt":1717324775778,"mc":[{"id":"1.229554930","rc":[{"atl":[[6,0]],"id":65894825}],"con":true,"img":false}]}
{"op":"mcm","clk":"11450712390","pt":1717324775882,"mc":[{"id":"1.229554930","rc":[{"atl":[[6.2,19.23]],"id":65894825}],"con":true,"img":false}]}
{"op":"mcm","clk":"11450712402","pt":1717324775987,"mc":[{"id":"1.229554930","rc":[{"atl":[[5.9,0]],"id":65894825}],"con":true,"img":false}]}
{"op":"mcm","clk":"11450712974","pt":1717324781581,"mc":[{"id":"1.229554930","rc":[{"atl":[[6,4.47]],"id":65894825}],"con":true,"img":false}]}
{"op":"mcm","clk":"11450712987","pt":1717324781713,"mc":[{"id":"1.229554930","rc":[{"atl":[[5.9,5.1]],"id":65894825}],"con":true,"img":false}]}
{"op":"mcm","clk":"11450713005","pt":1717324781812,"mc":[{"id":"1.229554930","rc":[{"atl":[[6.2,0]],"id":65894825}],"con":true,"img":false}]}
{"op":"mcm","clk":"11450713310","pt":1717324784597,"mc":[{"id":"1.229554930","rc":[{"atl":[[6,0]],"id":65894825}],"con":true,"img":false}]}
{"op":"mcm","clk":"11450713549","pt":1717324786789,"mc":[{"id":"1.229554930","rc":[{"atl":[[6.2,19.23]],"id":65894825}],"con":true,"img":false}]}
{"op":"mcm","clk":"11450713561","pt":1717324786883,"mc":[{"id":"1.229554930","rc":[{"atl":[[5.9,0]],"id":65894825}],"con":true,"img":false}]}
{"op":"mcm","clk":"11450713676","pt":1717324788019,"mc":[{"id":"1.229554930","rc":[{"atl":[[6,4.43]],"id":65894825}],"con":true,"img":false}]}
{"op":"mcm","clk":"11450714510","pt":1717324796231,"mc":[{"id":"1.229554930","rc":[{"atl":[[5.9,5.1]],"id":65894825}],"con":true,"img":false}]}
{"op":"mcm","clk":"11450714518","pt":1717324796312,"mc":[{"id":"1.229554930","rc":[{"atl":[[6.2,0]],"id":65894825}],"con":true,"img":false}]}
{"op":"mcm","clk":"11450714660","pt":1717324797819,"mc":[{"id":"1.229554930","rc":[{"atl":[[6.4,3.01]],"id":65894825}],"con":true,"img":false}]}
{"op":"mcm","clk":"11450714857","pt":1717324799800,"mc":[{"id":"1.229554930","rc":[{"atl":[[6,0]],"id":65894825}],"con":true,"img":false}]}
{"op":"mcm","clk":"11450715006","pt":1717324801318,"mc":[{"id":"1.229554930","rc":[{"atl":[[6.2,19.23]],"id":65894825}],"con":true,"img":false}]}
{"op":"mcm","clk":"11450715013","pt":1717324801425,"mc":[{"id":"1.229554930","rc":[{"atl":[[5.9,0]],"id":65894825}],"con":true,"img":false}]}
{"op":"mcm","clk":"11450715203","pt":1717324803246,"mc":[{"id":"1.229554930","rc":[{"atl":[[6,4.48]],"id":65894825}],"con":true,"img":false}]}
{"op":"mcm","clk":"11450715973","pt":1717324811453,"mc":[{"id":"1.229554930","rc":[{"atl":[[6.4,0]],"id":65894825}],"con":true,"img":false}]}
{"op":"mcm","clk":"11450716389","pt":1717324815635,"mc":[{"id":"1.229554930","rc":[{"atl":[[6.2,0],[5.9,19.23]],"id":65894825}],"con":true,"img":false}]}
{"op":"mcm","clk":"11450716403","pt":1717324815740,"mc":[{"id":"1.229554930","rc":[{"atl":[[1000,3.35]],"id":65894825}],"con":true,"img":false}]}
{"op":"mcm","clk":"11450716422","pt":1717324815944,"mc":[{"id":"1.229554930","rc":[{"atl":[[1000,3.33]],"id":65894825}],"con":true,"img":false}]}
{"op":"mcm","clk":"11450716449","pt":1717324816256,"mc":[{"id":"1.229554930","rc":[{"atl":[[1000,1]],"id":65894825}],"con":true,"img":false}]}
{"op":"mcm","clk":"11450716458","pt":1717324816358,"mc":[{"id":"1.229554930","rc":[{"atl":[[5.7,2.33]],"id":65894825}],"con":true,"img":false}]}
{"op":"mcm","clk":"11450716469","pt":1717324816460,"mc":[{"id":"1.229554930","rc":[{"atl":[[5.7,6.81],[5.9,0]],"id":65894825}],"con":true,"img":false}]}
{"op":"mcm","clk":"11450716635","pt":1717324817967,"mc":[{"id":"1.229554930","rc":[{"atl":[[6,0]],"id":65894825}],"con":true,"img":false}]}
{"op":"mcm","clk":"11450717923","pt":1717324830876,"mc":[{"id":"1.229554930","rc":[{"atl":[[2.92,6.6]],"id":47530316}],"con":true,"img":false}]}
{"op":"mcm","clk":"11450717943","pt":1717324831084,"mc":[{"id":"1.229554930","rc":[{"atl":[[6.4,3.01]],"id":65894825}],"con":true,"img":false}]}
{"op":"mcm","clk":"11450718168","pt":1717324833168,"mc":[{"id":"1.229554930","rc":[{"atl":[[3.05,0]],"id":47530316},{"spn":2.23,"spf":"NaN","id":47530316},{"spn":3.93,"spf":"NaN","id":65894825}],"con":true,"img":false}]}
{"op":"mcm","clk":"11450724721","pt":1717324899019,"mc":[{"id":"1.229554930","rc":[{"atb":[[1.6,2.61]],"id":47530316},{"spn":2.26,"spf":"NaN","id":47530316},{"atb":[[2.5,2.61]],"id":65894825},{"spn":4.1,"spf":"NaN","id":65894825}],"con":true,"img":false}]}
{"op":"mcm","clk":"11450724828","pt":1717324900107,"mc":[{"id":"1.229554930","rc":[{"atl":[[38,2.7],[44,0]],"id":66826631},{"atl":[[1000,3.17]],"id":44736449}],"con":true,"img":false}]}
{"op":"mcm","clk":"11450725092","pt":1717324903035,"mc":[{"id":"1.229554930","rc":[{"atl":[[4.3,0],[5.3,23.26]],"id":47530316},{"atb":[[1.26,380.22],[1.5,0]],"id":65894825}],"con":true,"img":false}]}
{"op":"mcm","clk":"11450726905","pt":1717324921455,"mc":[{"id":"1.229554930","rc":[{"atb":[[50,2]],"id":44736449},{"atl":[[990,2]],"id":44736449}],"con":true,"img":false}]}
{"op":"mcm","clk":"11450731658","pt":1717324972605,"mc":[{"id":"1.229554930","rc":[{"atb":[[1.5,0]],"id":47530316},{"spn":50.0,"spf":1.0,"id":44736449},{"atb":[[2.1,0]],"id":65894825}],"con":true,"img":false}]}
{"op":"mcm","clk":"11450734083","pt":1717324999551,"mc":[{"id":"1.229554930","rc":[{"atl":[[5.7,4.48]],"id":65894825}],"con":true,"img":false}]}
{"op":"mcm","clk":"11450734101","pt":1717324999802,"mc":[{"id":"1.229554930","rc":[{"atl":[[6.2,19.23]],"id":65894825}],"con":true,"img":false}]}
{"op":"mcm","clk":"11450734109","pt":1717324999850,"mc":[{"id":"1.229554930","rc":[{"atl":[[5.7,0]],"id":65894825}],"con":true,"img":false}]}
{"op":"mcm","clk":"11450734305","pt":1717325001772,"mc":[{"id":"1.229554930","rc":[{"atl":[[6,4.48]],"id":65894825}],"con":true,"img":false}]}
{"op":"mcm","clk":"11450735272","pt":1717325012138,"mc":[{"id":"1.229554930","rc":[{"atl":[[5.9,4.48]],"id":65894825}],"con":true,"img":false}]}
{"op":"mcm","clk":"11450735288","pt":1717325012256,"mc":[{"id":"1.229554930","rc":[{"atl":[[6.2,0]],"id":65894825}],"con":true,"img":false}]}
{"op":"mcm","clk":"11450735498","pt":1717325014436,"mc":[{"id":"1.229554930","rc":[{"atl":[[6,0]],"id":65894825}],"con":true,"img":false}]}
{"op":"mcm","clk":"11450735514","pt":1717325014573,"mc":[{"id":"1.229554930","rc":[{"atl":[[6.2,19.23]],"id":65894825}],"con":true,"img":false}]}
{"op":"mcm","clk":"11450735522","pt":1717325014675,"mc":[{"id":"1.229554930","rc":[{"atl":[[5.9,0]],"id":65894825}],"con":true,"img":false}]}
{"op":"mcm","clk":"11450735861","pt":1717325018169,"mc":[{"id":"1.229554930","rc":[{"atl":[[6,4.41]],"id":65894825}],"con":true,"img":false}]}
{"op":"mcm","clk":"11450735884","pt":1717325018466,"mc":[{"id":"1.229554930","rc":[{"atl":[[2.92,0]],"id":47530316}],"con":true,"img":false}]}
{"op":"mcm","clk":"11450736068","pt":1717325020460,"mc":[{"id":"1.229554930","rc":[{"atl":[[3.05,7.69]],"id":47530316}],"con":true,"img":false}]}
{"op":"mcm","clk":"11450736676","pt":1717325026773,"mc":[{"id":"1.229554930","rc":[{"atl":[[5.9,4.41]],"id":65894825}],"con":true,"img":false}]}
{"op":"mcm","clk":"11450736684","pt":1717325026869,"mc":[{"id":"1.229554930","rc":[{"atl":[[6.2,0]],"id":65894825}],"con":true,"img":false}]}
{"op":"mcm","clk":"11450736902","pt":1717325029096,"mc":[{"id":"1.229554930","rc":[{"atl":[[6,0]],"id":65894825}],"con":true,"img":false}]}
{"op":"mcm","clk":"11450737107","pt":1717325031903,"mc":[{"id":"1.229554930","rc":[{"atl":[[6.2,19.23],[5.9,0]],"id":65894825}],"con":true,"img":false}]}
{"op":"mcm","clk":"11450737341","pt":1717325034304,"mc":[{"id":"1.229554930","rc":[{"atb":[[4.3,31.67],[3.9,72.08],[3.65,78.88]],"id":66826631},{"atl":[[34,6.33],[22,6.63]],"id":66826631},{"atb":[[1.44,475.13],[1.54,193.57],[1.49,426.65]],"id":47530316},{"atl":[[3.6,80.4],[3.1,66.37]],"id":47530316},{"spn":2.32,"spf":"NaN","id":47530316},{"atb":[[2.06,197.22],[1.98,213.33],[2.16,90.11]],"id":65894825},{"atl":[[9,26.13],[7,23.22]],"id":65894825},{"spn":4.35,"spf":"NaN","id":65894825},{"atb":[[38,2.82],[24,9.08],[29,7.46]],"id":44736449},{"atl":[[550,0.38],[450,0.3]],"id":44736449}],"con":true,"img":false}]}
{"op":"mcm","clk":"11450737446","pt":1717325035470,"mc":[{"id":"1.229554930","rc":[{"atl":[[6,4.48]],"id":65894825}],"con":true,"img":false}]}
{"op":"mcm","clk":"11450737763","pt":1717325039177,"mc":[{"id":"1.229554930","rc":[{"atl":[[2.86,3]],"id":47530316}],"con":true,"img":false}]}
{"op":"mcm","clk":"11450738032","pt":1717325041905,"mc":[{"id":"1.229554930","rc":[{"atl":[[3.05,0]],"id":47530316}],"con":true,"img":false}]}
{"op":"mcm","clk":"11450738235","pt":1717325043876,"mc":[{"id":"1.229554930","rc":[{"atl":[[6.2,0],[5.9,4.48]],"id":65894825}],"con":true,"img":false}]}
{"op":"mcm","clk":"11450738331","pt":1717325044930,"mc":[{"id":"1.229554930","rc":[{"atb":[[4.3,63.35],[3.9,144.17],[3.65,157.77]],"id":66826631},{"atl":[[34,12.67],[22,13.27]],"id":66826631},{"atb":[[1.44,950.27],[1.54,387.15],[1.49,853.31]],"id":47530316},{"atl":[[3.6,160.81],[3.1,132.74]],"id":47530316},{"atb":[[2.06,394.45],[1.98,426.66],[2.16,180.22]],"id":65894825},{"atl":[[9,52.26],[7,46.45]],"id":65894825},{"atb":[[38,5.65],[24,18.17],[29,14.93]],"id":44736449},{"atl":[[550,0.76],[450,0.61]],"id":44736449}],"con":true,"img":false}]}
{"op":"mcm","clk":"11450738599","pt":1717325047597,"mc":[{"id":"1.229554930","rc":[{"atl":[[6,0]],"id":65894825}],"con":true,"img":false}]}
{"op":"mcm","clk":"11450738743","pt":1717325049008,"mc":[{"id":"1.229554930","rc":[{"atl":[[6.2,19.23]],"id":65894825}],"con":true,"img":false}]}
{"op":"mcm","clk":"11450738759","pt":1717325049120,"mc":[{"id":"1.229554930","rc":[{"atl":[[5.9,0]],"id":65894825}],"con":true,"img":false}]}
{"op":"mcm","clk":"11450738835","pt":1717325050102,"mc":[{"id":"1.229554930","rc":[{"atl":[[6.4,0]],"id":65894825}],"con":true,"img":false}]}
{"op":"mcm","clk":"11450738845","pt":1717325050205,"mc":[{"id":"1.229554930","rc":[{"atl":[[6.8,17.24]],"id":65894825}],"con":true,"img":false}]}
{"op":"mcm","clk":"11450738855","pt":1717325050314,"mc":[{"id":"1.229554930","rc":[{"atl":[[6.2,0]],"id":65894825}],"con":true,"img":false}]}
{"op":"mcm","clk":"11450739168","pt":1717325053429,"mc":[{"id":"1.229554930","rc":[{"atl":[[6.6,4.44]],"id":65894825}],"con":true,"img":false}]}
{"op":"mcm","clk":"11450739266","pt":1717325054428,"mc":[{"id":"1.229554930","rc":[{"atl":[[2.86,0]],"id":47530316}],"con":true,"img":false}]}
{"op":"mcm","clk":"11450739539","pt":1717325057399,"mc":[{"id":"1.229554930","rc":[{"atl":[[3.05,7.66]],"id":47530316}],"con":true,"img":false}]}
{"op":"mcm","clk":"11450739892","pt":1717325061326,"mc":[{"id":"1.229554930","rc":[{"atl":[[2.86,3]],"id":47530316}],"con":true,"img":false}]}
{"op":"mcm","clk":"11450739954","pt":1717325061999,"mc":[{"id":"1.229554930","rc":[{"atl":[[6.4,17.24]],"id":65894825}],"con":true,"img":false}]}
{"op":"mcm","clk":"11450739963","pt":1717325062102,"mc":[{"id":"1.229554930","rc":[{"atl":[[6.8,0]],"id":65894825}],"con":true,"img":false}]}
{"op":"mcm","clk":"11450739997","pt":1717325062418,"mc":[{"id":"1.229554930","rc":[{"atl":[[3.05,0]],"id":47530316}],"con":true,"img":false}]}
{"op":"mcm","clk":"11450740308","pt":1717325066012,"mc":[{"id":"1.229554930","rc":[{"atl":[[6.6,0]],"id":65894825}],"con":true,"img":false}]}
{"op":"mcm","clk":"11450740402","pt":1717325067104,"mc":[{"id":"1.229554930","rc":[{"atl":[[6.8,17.24]],"id":65894825}],"con":true,"img":false}]}
{"op":"mcm","clk":"11450740415","pt":1717325067207,"mc":[{"id":"1.229554930","rc":[{"atl":[[6.4,0]],"id":65894825}],"con":true,"img":false}]}
{"op":"mcm","clk":"11450740790","pt":1717325071733,"mc":[{"id":"1.229554930","rc":[{"atl":[[6.6,4.46]],"id":65894825}],"con":true,"img":false}]}
{"op":"mcm","clk":"11450741239","pt":1717325076458,"mc":[{"id":"1.229554930","rc":[{"atl":[[2.86,0]],"id":47530316}],"con":true,"img":false}]}
{"op":"mcm","clk":"11450741321","pt":1717325077147,"mc":[{"id":"1.229554930","rc":[{"atl":[[3.05,7.69]],"id":47530316}],"con":true,"img":false}]}
{"op":"mcm","clk":"11450741487","pt":1717325078751,"mc":[{"id":"1.229554930","rc":[{"atl":[[6.4,17.24],[6.8,0]],"id":65894825}],"con":true,"img":false}]}
{"op":"mcm","clk":"11450741662","pt":1717325080682,"mc":[{"id":"1.229554930","rc":[{"atl":[[6.6,0]],"id":65894825}],"con":true,"img":false}]}
{"op":"mcm","clk":"11450741932","pt":1717325083544,"mc":[{"id":"1.229554930","rc":[{"atl":[[2.86,3]],"id":47530316}],"con":true,"img":false}]}
{"op":"mcm","clk":"11450741959","pt":1717325083855,"mc":[{"id":"1.229554930","rc":[{"atl":[[6.8,17.24]],"id":65894825}],"con":true,"img":false}]}
{"op":"mcm","clk":"11450741968","pt":1717325083960,"mc":[{"id":"1.229554930","rc":[{"atl":[[6.4,0]],"id":65894825}],"con":true,"img":false}]}
{"op":"mcm","clk":"11450742168","pt":1717325086242,"mc":[{"id":"1.229554930","rc":[{"atl":[[6.6,4.37]],"id":65894825}],"con":true,"img":false}]}
{"op":"mcm","clk":"11450742205","pt":1717325086558,"mc":[{"id":"1.229554930","rc":[{"atl":[[3.05,0]],"id":47530316}],"con":true,"img":false}]}
{"op":"mcm","clk":"11450742529","pt":1717325090258,"mc":[{"id":"1.229554930","rc":[{"atl":[[6.4,17.24]],"id":65894825}],"con":true,"img":false}]}
{"op":"mcm","clk":"11450742537","pt":1717325090354,"mc":[{"id":"1.229554930","rc":[{"atl":[[6.8,0]],"id":65894825}],"con":true,"img":false}]}
{"op":"mcm","clk":"11450742632","pt":1717325091444,"mc":[{"id":"1.229554930","rc":[{"atl":[[2.92,6.6]],"id":47530316}],"con":true,"img":false}]}
{"op":"mcm","clk":"11450742652","pt":1717325091656,"mc":[{"id":"1.229554930","rc":[{"atl":[[5.9,3.26]],"id":65894825}],"con":true,"img":false}]}
{"op":"mcm","clk":"11450742664","pt":1717325091758,"mc":[{"id":"1.229554930","rc":[{"atl":[[6.4,0],[5.8,4.37]],"id":65894825}],"con":true,"img":false}]}
{"op":"mcm","clk":"11450742741","pt":1717325092683,"mc":[{"id":"1.229554930","rc":[{"atl":[[6.6,0]],"id":65894825}],"con":true,"img":false}]}
{"op":"mcm","clk":"11450743342","pt":1717325098779,"mc":[{"id":"1.229554930","rc":[{"atl":[[2.86,0]],"id":47530316},{"spn":2.26,"spf":"NaN","id":47530316},{"spn":4.15,"spf":"NaN","id":65894825}],"con":true,"img":false}]}
{"op":"mcm","clk":"11450744059","pt":1717325105670,"mc":[{"id":"1.229554930","rc":[{"atl":[[2.86,3]],"id":47530316}],"con":true,"img":false}]}
{"op":"mcm","clk":"11450745352","pt":1717325118323,"mc":[{"id":"1.229554930","rc":[{"atl":[[1000,3.35]],"id":65894825}],"con":true,"img":false}]}
{"op":"mcm","clk":"11450745384","pt":1717325118584,"mc":[{"id":"1.229554930","rc":[{"atl":[[1000,3.08]],"id":65894825}],"con":true,"img":false}]}
{"op":"mcm","clk":"11450745403","pt":1717325118798,"mc":[{"id":"1.229554930","rc":[{"atl":[[1000,1]],"id":65894825}],"con":true,"img":false}]}
{"op":"mcm","clk":"11450745416","pt":1717325118901,"mc":[{"id":"1.229554930","rc":[{"atl":[[6.4,2.08]],"id":65894825}],"con":true,"img":false}]}
{"op":"mcm","clk":"11450745625","pt":1717325120925,"mc":[{"id":"1.229554930","rc":[{"atl":[[2.86,0]],"id":47530316}],"con":true,"img":false}]}
{"op":"mcm","clk":"11450746382","pt":1717325127909,"mc":[{"id":"1.229554930","rc":[{"atl":[[2.86,3]],"id":47530316}],"con":true,"img":false}]}
{"op":"mcm","clk":"11450747991","pt":1717325143136,"mc":[{"id":"1.229554930","rc":[{"atl":[[2.86,0]],"id":47530316}],"con":true,"img":false}]}
{"op":"mcm","clk":"11450748668","pt":1717325149951,"mc":[{"id":"1.229554930","rc":[{"atl":[[2.86,3]],"id":47530316}],"con":true,"img":false}]}
{"op":"mcm","clk":"11450750227","pt":1717325165172,"mc":[{"id":"1.229554930","rc":[{"atl":[[2.86,0]],"id":47530316}],"con":true,"img":false}]}
{"op":"mcm","clk":"11450750946","pt":1717325172195,"mc":[{"id":"1.229554930","rc":[{"atl":[[2.86,3]],"id":47530316}],"con":true,"img":false}]}
{"op":"mcm","clk":"11450751857","pt":1717325181688,"mc":[{"id":"1.229554930","rc":[{"atb":[[50,0]],"id":44736449},{"atl":[[990,0]],"id":44736449}],"con":true,"img":false}]}
{"op":"mcm","clk":"11450752388","pt":1717325187422,"mc":[{"id":"1.229554930","rc":[{"atl":[[2.86,0]],"id":47530316}],"con":true,"img":false}]}
{"op":"mcm","clk":"11450753022","pt":1717325194017,"mc":[{"id":"1.229554930","rc":[{"atl":[[2.9,3]],"id":47530316}],"con":true,"img":false}]}
{"op":"mcm","clk":"11450753495","pt":1717325198848,"mc":[{"id":"1.229554930","rc":[{"atb":[[50,2]],"id":44736449},{"atl":[[990,2]],"id":44736449}],"con":true,"img":false}]}
{"op":"mcm","clk":"11450754118","pt":1717325204754,"mc":[{"id":"1.229554930","rc":[{"atb":[[1.91,0],[1.77,129.87]],"id":66826631},{"atl":[[1000,1.17]],"id":44736449}],"con":true,"img":false}]}
{"op":"mcm","clk":"11450754569","pt":1717325209234,"mc":[{"id":"1.229554930","rc":[{"atl":[[2.9,0]],"id":47530316}],"con":true,"img":false}]}
{"op":"mcm","clk":"11450754626","pt":1717325209752,"mc":[{"id":"1.229554930","rc":[{"atl":[[32,3.23]],"id":66826631},{"atb":[[1.26,384.62]],"id":47530316},{"atl":[[3.45,40.82]],"id":47530316},{"atb":[[1.58,172.41]],"id":65894825}],"con":true,"img":false}]}
{"op":"mcm","clk":"11450754633","pt":1717325209856,"mc":[{"id":"1.229554930","rc":[{"atl":[[38,0]],"id":66826631},{"atb":[[1.35,0]],"id":47530316},{"atl":[[5.3,0]],"id":47530316},{"atb":[[1.26,0]],"id":65894825}],"con":true,"img":false}]}
{"op":"mcm","clk":"11450754661","pt":1717325210022,"mc":[{"id":"1.229554930","rc":[{"atl":[[21,0],[1000,2.03]],"id":66826631}],"con":true,"img":false}]}
{"op":"mcm","clk":"11450754688","pt":1717325210336,"mc":[{"id":"1.229554930","rc":[{"atl":[[1000,1.58]],"id":66826631}],"con":true,"img":false}]}
{"op":"mcm","clk":"11450754732","pt":1717325210858,"mc":[{"id":"1.229554930","rc":[{"atl":[[1000,1.17]],"id":66826631}],"con":true,"img":false}]}
{"op":"mcm","clk":"11450754742","pt":1717325210964,"mc":[{"id":"1.229554930","rc":[{"atl":[[30,0.4]],"id":66826631}],"con":true,"img":false}]}
{"op":"mcm","clk":"11450754803","pt":1717325211646,"mc":[{"id":"1.229554930","rc":[{"atl":[[30,0],[1000,2.03]],"id":66826631}],"con":true,"img":false}]}
{"op":"mcm","clk":"11450754832","pt":1717325211961,"mc":[{"id":"1.229554930","rc":[{"atl":[[1000,1.6]],"id":66826631}],"con":true,"img":false}]}
{"op":"mcm","clk":"11450754867","pt":1717325212221,"mc":[{"id":"1.229554930","rc":[{"atl":[[1000,1.17]],"id":66826631}],"con":true,"img":false}]}
{"op":"mcm","clk":"11450754884","pt":1717325212323,"mc":[{"id":"1.229554930","rc":[{"atl":[[20,0.42]],"id":66826631}],"con":true,"img":false}]}
{"op":"mcm","clk":"11450755139","pt":1717325215036,"mc":[{"id":"1.229554930","rc":[{"atb":[[2.42,70.42],[1.77,0]],"id":66826631}],"con":true,"img":false}]}
{"op":"mcm","clk":"11450755214","pt":1717325215866,"mc":[{"id":"1.229554930","rc":[{"atl":[[2.86,3]],"id":47530316}],"con":true,"img":false}]}
{"op":"mcm","clk":"11450756463","pt":1717325227671,"mc":[{"id":"1.229554930","rc":[{"atb":[[1.02,1.7]],"id":47530316},{"spn":2.23,"spf":"NaN","id":47530316},{"atb":[[1.02,10.65]],"id":65894825}],"con":true,"img":false}]}
{"op":"mcm","clk":"11450756496","pt":1717325227970,"mc":[{"id":"1.229554930","rc":[{"atl":[[1000,2.88]],"id":47530316},{"atb":[[1.4,1.7]],"id":44736449}],"con":true,"img":false}]}
{"op":"mcm","clk":"11450756530","pt":1717325228282,"mc":[{"id":"1.229554930","rc":[{"atb":[[1.04,1.7]],"id":66826631}],"con":true,"img":false}]}
{"op":"mcm","clk":"11450756537","pt":1717325228346,"mc":[{"id":"1.229554930","rc":[{"atb":[[1.02,0.52]],"id":47530316}],"con":true,"img":false}]}
{"op":"mcm","clk":"11450756569","pt":1717325228653,"mc":[{"id":"1.229554930","rc":[{"atb":[[1.02,9.28]],"id":65894825},{"atl":[[1000,2.7]],"id":65894825}],"con":true,"img":false}]}
{"op":"mcm","clk":"11450756596","pt":1717325228967,"mc":[{"id":"1.229554930","rc":[{"atb":[[1.04,0.19]],"id":66826631},{"atl":[[1000,2.88]],"id":66826631}],"con":true,"img":false}]}
{"op":"mcm","clk":"11450756623","pt":1717325229281,"mc":[{"id":"1.229554930","rc":[{"atb":[[1.4,0.01]],"id":44736449}],"con":true,"img":false}]}
{"op":"mcm","clk":"11450756631","pt":1717325229385,"mc":[{"id":"1.229554930","rc":[{"atb":[[1.02,0]],"id":47530316}],"con":true,"img":false}]}
{"op":"mcm","clk":"11450756649","pt":1717325229494,"mc":[{"id":"1.229554930","rc":[{"atb":[[1.61,0.52]],"id":47530316}],"con":true,"img":false}]}
{"op":"mcm","clk":"11450756695","pt":1717325229964,"mc":[{"id":"1.229554930","rc":[{"atb":[[1.02,8.94]],"id":65894825},{"atl":[[1000,1.15]],"id":65894825}],"con":true,"img":false}]}
{"op":"mcm","clk":"11450756708","pt":1717325230066,"mc":[{"id":"1.229554930","rc":[{"atb":[[2.52,0.34]],"id":65894825}],"con":true,"img":false}]}
{"op":"mcm","clk":"11450756739","pt":1717325230377,"mc":[{"id":"1.229554930","rc":[{"atb":[[1.04,0]],"id":66826631}],"con":true,"img":false}]}
{"op":"mcm","clk":"11450756750","pt":1717325230481,"mc":[{"id":"1.229554930","rc":[{"atb":[[4.4,0.19]],"id":66826631}],"con":true,"img":false}]}
{"op":"mcm","clk":"11450756794","pt":1717325230846,"mc":[{"id":"1.229554930","rc":[{"atl":[[1000,1.22]],"id":66826631}],"con":true,"img":false}]}
{"op":"mcm","clk":"11450756813","pt":1717325231050,"mc":[{"id":"1.229554930","rc":[{"atl":[[2.86,0]],"id":47530316}],"con":true,"img":false}]}
{"op":"mcm","clk":"11450756827","pt":1717325231155,"mc":[{"id":"1.229554930","rc":[{"atb":[[1.4,0]],"id":44736449}],"con":true,"img":false}]}
{"op":"mcm","clk":"11450756832","pt":1717325231256,"mc":[{"id":"1.229554930","rc":[{"atb":[[55,0.01]],"id":44736449}],"con":true,"img":false}]}
{"op":"mcm","clk":"11450756864","pt":1717325231670,"mc":[{"id":"1.229554930","rc":[{"atl":[[1000,1]],"id":65894825}],"con":true,"img":false}]}
{"op":"mcm","clk":"11450756876","pt":1717325231774,"mc":[{"id":"1.229554930","rc":[{"atl":[[5.7,0.15]],"id":65894825}],"con":true,"img":false}]}
{"op":"mcm","clk":"11450756914","pt":1717325232290,"mc":[{"id":"1.229554930","rc":[{"atl":[[1000,1.17]],"id":66826631}],"con":true,"img":false}]}
{"op":"mcm","clk":"11450756923","pt":1717325232395,"mc":[{"id":"1.229554930","rc":[{"atl":[[21,0.04]],"id":66826631}],"con":true,"img":false}]}
{"op":"mcm","clk":"11450757604","pt":1717325237747,"mc":[{"id":"1.229554930","rc":[{"atl":[[2.86,3]],"id":47530316}],"con":true,"img":false}]}
{"op":"mcm","clk":"11450757702","pt":1717325238696,"mc":[{"id":"1.229554930","rc":[{"atl":[[2.86,0]],"id":47530316}],"con":true,"img":false}]}
{"op":"mcm","clk":"11450758182","pt":1717325243206,"mc":[{"id":"1.229554930","rc":[{"atb":[[4.3,31.67],[3.9,72.08],[3.65,78.88]],"id":66826631},{"atl":[[34,6.33],[22,6.63]],"id":66826631},{"atb":[[1.44,475.13],[1.54,193.57],[1.49,426.65]],"id":47530316},{"atl":[[3.6,80.4],[3.1,66.37]],"id":47530316},{"atb":[[2.06,197.22],[1.98,213.33],[2.16,90.11]],"id":65894825},{"atl":[[9,26.13],[7,23.22]],"id":65894825},{"atb":[[38,2.82],[24,9.08],[29,7.46]],"id":44736449},{"atl":[[550,0.38],[450,0.3]],"id":44736449}],"con":true,"img":false}]}
{"op":"mcm","clk":"11450758526","pt":1717325246502,"mc":[{"id":"1.229554930","rc":[{"atl":[[2.86,3]],"id":47530316}],"con":true,"img":false}]}
{"op":"mcm","clk":"11450758835","pt":1717325249817,"mc":[{"id":"1.229554930","rc":[{"atb":[[4.3,63.35],[3.9,144.17],[3.65,157.77]],"id":66826631},{"atl":[[34,12.67],[22,13.27]],"id":66826631},{"atb":[[1.44,950.27],[1.54,387.15],[1.49,853.31]],"id":47530316},{"atl":[[3.6,160.81],[3.1,132.74]],"id":47530316},{"atb":[[38,5.65],[24,18.17],[29,14.93]],"id":44736449},{"atl":[[550,0.76],[450,0.61]],"id":44736449},{"atb":[[2.06,394.45],[1.98,426.66],[2.16,180.22]],"id":65894825},{"atl":[[9,52.26],[7,46.45]],"id":65894825}],"con":true,"img":false}]}
{"op":"mcm","clk":"11450759971","pt":1717325261725,"mc":[{"id":"1.229554930","rc":[{"atl":[[2.86,0]],"id":47530316}],"con":true,"img":false}]}
{"op":"mcm","clk":"11450760728","pt":1717325268318,"mc":[{"id":"1.229554930","rc":[{"atl":[[2.86,3]],"id":47530316}],"con":true,"img":false}]}
{"op":"mcm","clk":"11450761463","pt":1717325275344,"mc":[{"id":"1.229554930","rc":[{"atl":[[2.92,0]],"id":47530316}],"con":true,"img":false}]}
{"op":"mcm","clk":"11450761672","pt":1717325277527,"mc":[{"id":"1.229554930","rc":[{"atb":[[1.02,2]],"id":47530316}],"con":true,"img":false}]}
{"op":"mcm","clk":"11450761726","pt":1717325278149,"mc":[{"id":"1.229554930","rc":[{"atb":[[1.02,10.94]],"id":65894825}],"con":true,"img":false}]}
{"op":"mcm","clk":"11450761842","pt":1717325279149,"mc":[{"id":"1.229554930","rc":[{"atb":[[1.02,10.94]],"id":66826631}],"con":true,"img":false}]}
{"op":"mcm","clk":"11450762174","pt":1717325281863,"mc":[{"id":"1.229554930","rc":[{"atb":[[1.02,0]],"id":47530316}],"con":true,"img":false}]}
{"op":"mcm","clk":"11450762187","pt":1717325281921,"mc":[{"id":"1.229554930","rc":[{"atb":[[1.61,2.52]],"id":47530316}],"con":true,"img":false}]}
{"op":"mcm","clk":"11450762218","pt":1717325282231,"mc":[{"id":"1.229554930","rc":[{"atb":[[1.02,8.94]],"id":65894825}],"con":true,"img":false}]}
{"op":"mcm","clk":"11450762231","pt":1717325282336,"mc":[{"id":"1.229554930","rc":[{"atb":[[2.52,2.34]],"id":65894825}],"con":true,"img":false}]}
{"op":"mcm","clk":"11450762286","pt":1717325282751,"mc":[{"id":"1.229554930","rc":[{"atb":[[1.02,8.94]],"id":66826631}],"con":true,"img":false}]}
{"op":"mcm","clk":"11450762291","pt":1717325282854,"mc":[{"id":"1.229554930","rc":[{"atb":[[4.4,2.19]],"id":66826631}],"con":true,"img":false}]}
{"op":"mcm","clk":"11450762365","pt":1717325283539,"mc":[{"id":"1.229554930","rc":[{"atl":[[2.86,0]],"id":47530316}],"con":true,"img":false}]}
{"op":"mcm","clk":"11450762382","pt":1717325283644,"mc":[{"id":"1.229554930","rc":[{"atb":[[4.5,5.68]],"id":66826631}],"con":true,"img":false}]}
{"op":"mcm","clk":"11450762560","pt":1717325285045,"mc":[{"id":"1.229554930","rc":[{"atb":[[4.4,0.19]],"id":66826631},{"atl":[[3.05,7.75]],"id":47530316}],"con":true,"img":false}]}
{"op":"mcm","clk":"11450762567","pt":1717325285151,"mc":[{"id":"1.229554930","rc":[{"atb":[[4.6,2]],"id":66826631}],"con":true,"img":false}]}
{"op":"mcm","clk":"11450762661","pt":1717325285973,"mc":[{"id":"1.229554930","rc":[{"atb":[[4.5,0]],"id":66826631}],"con":true,"img":false}]}
{"op":"mcm","clk":"11450762683","pt":1717325286176,"mc":[{"id":"1.229554930","rc":[{"atl":[[3,6.39]],"id":47530316}],"con":true,"img":false}]}
{"op":"mcm","clk":"11450762853","pt":1717325287739,"mc":[{"id":"1.229554930","rc":[{"atb":[[4.6,0]],"id":66826631},{"spn":4.32,"spf":1.0,"id":66826631},{"spn":2.3,"spf":"NaN","id":47530316},{"spn":4.11,"spf":"NaN","id":65894825},{"spn":50.05,"spf":1.0,"id":44736449}],"con":true,"img":false}]}
{"op":"mcm","clk":"11450762864","pt":1717325287839,"mc":[{"id":"1.229554930","rc":[{"atb":[[4.4,2.19]],"id":66826631}],"con":true,"img":false}]}
{"op":"mcm","clk":"11450762883","pt":1717325288046,"mc":[{"id":"1.229554930","rc":[{"atb":[[4.5,5.68]],"id":66826631},{"atl":[[3.05,0]],"id":47530316}],"con":true,"img":false}]}
{"op":"mcm","clk":"11450763138","pt":1717325290448,"mc":[{"id":"1.229554930","rc":[{"atb":[[4.4,0.19]],"id":66826631}],"con":true,"img":false}]}
{"op":"mcm","clk":"11450763153","pt":1717325290548,"mc":[{"id":"1.229554930","rc":[{"atb":[[4.6,2]],"id":66826631}],"con":true,"img":false}]}
{"op":"mcm","clk":"11450763163","pt":1717325290653,"mc":[{"id":"1.229554930","rc":[{"atl":[[2.76,3]],"id":47530316}],"con":true,"img":false}]}
{"op":"mcm","clk":"11450763282","pt":1717325291747,"mc":[{"id":"1.229554930","rc":[{"atb":[[4.5,0]],"id":66826631},{"atl":[[3,0]],"id":47530316}],"con":true,"img":false}]}
{"op":"mcm","clk":"11450763427","pt":1717325293246,"mc":[{"id":"1.229554930","rc":[{"atb":[[4.6,0]],"id":66826631}],"con":true,"img":false}]}
{"op":"mcm","clk":"11450763439","pt":1717325293351,"mc":[{"id":"1.229554930","rc":[{"atb":[[4.4,2.19]],"id":66826631}],"con":true,"img":false}]}
{"op":"mcm","clk":"11450763484","pt":1717325293761,"mc":[{"id":"1.229554930","rc":[{"atb":[[4.5,5.68]],"id":66826631}],"con":true,"img":false}]}
{"op":"mcm","clk":"11450763500","pt":1717325293964,"mc":[{"id":"1.229554930","rc":[{"atb":[[4.4,6.63]],"id":66826631}],"con":true,"img":false}]}
{"op":"mcm","clk":"11450763655","pt":1717325295278,"mc":[{"id":"1.229554930","rc":[{"atb":[[4.4,4.63]],"id":66826631}],"con":true,"img":false}]}
{"op":"mcm","clk":"11450763666","pt":1717325295378,"mc":[{"id":"1.229554930","rc":[{"atb":[[4.6,2]],"id":66826631}],"con":true,"img":false}]}
{"op":"mcm","clk":"11450763727","pt":1717325295856,"mc":[{"id":"1.229554930","rc":[{"atb":[[4.5,0]],"id":66826631}],"con":true,"img":false}]}
{"op":"mcm","clk":"11450763868","pt":1717325297159,"mc":[{"id":"1.229554930","rc":[{"atb":[[4.4,0.19]],"id":66826631}],"con":true,"img":false}]}
{"op":"mcm","clk":"11450763982","pt":1717325298145,"mc":[{"id":"1.229554930","rc":[{"atb":[[4.6,0]],"id":66826631}],"con":true,"img":false}]}
{"op":"mcm","clk":"11450763992","pt":1717325298257,"mc":[{"id":"1.229554930","rc":[{"atb":[[4.4,2.19]],"id":66826631}],"con":true,"img":false}]}
{"op":"mcm","clk":"11450764044","pt":1717325298776,"mc":[{"id":"1.229554930","rc":[{"atb":[[4.5,5.68]],"id":66826631},{"atb":[[1.56,14.02]],"id":47530316},{"atb":[[2.2,6.53]],"id":65894825},{"atl":[[6.4,0]],"id":65894825}],"con":true,"img":false}]}
{"op":"mcm","clk":"11450764260","pt":1717325300486,"mc":[{"id":"1.229554930","rc":[{"atb":[[4.4,0.19]],"id":66826631}],"con":true,"img":false}]}
{"op":"mcm","clk":"11450764273","pt":1717325300590,"mc":[{"id":"1.229554930","rc":[{"atb":[[4.6,2]],"id":66826631}],"con":true,"img":false}]}
{"op":"mcm","clk":"11450764327","pt":1717325301063,"mc":[{"id":"1.229554930","rc":[{"atb":[[4.5,0]],"id":66826631}],"con":true,"img":false}]}
{"op":"mcm","clk":"11450764533","pt":1717325302993,"mc":[{"id":"1.229554930","rc":[{"atb":[[4.6,0]],"id":66826631}],"con":true,"img":false}]}
{"op":"mcm","clk":"11450764547","pt":1717325303092,"mc":[{"id":"1.229554930","rc":[{"atb":[[4.4,2.19]],"id":66826631}],"con":true,"img":false}]}
{"op":"mcm","clk":"11450764621","pt":1717325303779,"mc":[{"id":"1.229554930","rc":[{"atb":[[4.5,5.68]],"id":66826631},{"atl":[[2.76,0]],"id":47530316}],"con":true,"img":false}]}
{"op":"mcm","clk":"11450764781","pt":1717325305285,"mc":[{"id":"1.229554930","rc":[{"atb":[[4.4,0.19]],"id":66826631}],"con":true,"img":false}]}
{"op":"mcm","clk":"11450764791","pt":1717325305395,"mc":[{"id":"1.229554930","rc":[{"atb":[[4.6,2]],"id":66826631}],"con":true,"img":false}]}
{"op":"mcm","clk":"11450764835","pt":1717325305806,"mc":[{"id":"1.229554930","rc":[{"atb":[[4.5,0]],"id":66826631}],"con":true,"img":false}]}
{"op":"mcm","clk":"11450764888","pt":1717325306275,"mc":[{"id":"1.229554930","rc":[{"atl":[[3.05,7.68]],"id":47530316}],"con":true,"img":false}]}
{"op":"mcm","clk":"11450764924","pt":1717325306583,"mc":[{"id":"1.229554930","rc":[{"atl":[[3,6.39]],"id":47530316}],"con":true,"img":false}]}
{"op":"mcm","clk":"11450765031","pt":1717325307574,"mc":[{"id":"1.229554930","rc":[{"atb":[[4.6,0]],"id":66826631}],"con":true,"img":false}]}
{"op":"mcm","clk":"11450765040","pt":1717325307680,"mc":[{"id":"1.229554930","rc":[{"atb":[[4.4,2.19]],"id":66826631}],"con":true,"img":false}]}
{"op":"mcm","clk":"11450765096","pt":1717325308301,"mc":[{"id":"1.229554930","rc":[{"atb":[[4.5,5.68]],"id":66826631}],"con":true,"img":false}]}
{"op":"mcm","clk":"11450765197","pt":1717325309384,"mc":[{"id":"1.229554930","rc":[{"atl":[[3.05,0]],"id":47530316}],"con":true,"img":false}]}
{"op":"mcm","clk":"11450765217","pt":1717325309620,"mc":[{"id":"1.229554930","rc":[{"atb":[[4.4,0.19]],"id":66826631}],"con":true,"img":false}]}
{"op":"mcm","clk":"11450765227","pt":1717325309702,"mc":[{"id":"1.229554930","rc":[{"atb":[[4.6,2]],"id":66826631}],"con":true,"img":false}]}
{"op":"mcm","clk":"11450765295","pt":1717325310274,"mc":[{"id":"1.229554930","rc":[{"atl":[[2.72,3]],"id":47530316}],"con":true,"img":false}]}
{"op":"mcm","clk":"11450765329","pt":1717325310579,"mc":[{"id":"1.229554930","rc":[{"atb":[[4.5,0]],"id":66826631},{"atl":[[3,0]],"id":47530316}],"con":true,"img":false}]}
{"op":"mcm","clk":"11450765544","pt":1717325312391,"mc":[{"id":"1.229554930","rc":[{"atb":[[4.6,0]],"id":66826631}],"con":true,"img":false}]}
{"op":"mcm","clk":"11450765559","pt":1717325312496,"mc":[{"id":"1.229554930","rc":[{"atb":[[4.4,2.19]],"id":66826631}],"con":true,"img":false}]}
{"op":"mcm","clk":"11450765618","pt":1717325312970,"mc":[{"id":"1.229554930","rc":[{"atb":[[4.5,5.68]],"id":66826631}],"con":true,"img":false}]}
{"op":"mcm","clk":"11450765835","pt":1717325314884,"mc":[{"id":"1.229554930","rc":[{"atl":[[2.72,0]],"id":47530316}],"con":true,"img":false}]}
{"op":"mcm","clk":"11450765871","pt":1717325315197,"mc":[{"id":"1.229554930","rc":[{"atb":[[4.4,0.19]],"id":66826631}],"con":true,"img":false}]}
{"op":"mcm","clk":"11450765881","pt":1717325315299,"mc":[{"id":"1.229554930","rc":[{"atb":[[4.6,2]],"id":66826631}],"con":true,"img":false}]}
{"op":"mcm","clk":"11450765980","pt":1717325316286,"mc":[{"id":"1.229554930","rc":[{"atb":[[4.5,0]],"id":66826631}],"con":true,"img":false}]}
{"op":"mcm","clk":"11450766104","pt":1717325317376,"mc":[{"id":"1.229554930","rc":[{"atb":[[4.6,0]],"id":66826631}],"con":true,"img":false}]}
{"op":"mcm","clk":"11450766112","pt":1717325317482,"mc":[{"id":"1.229554930","rc":[{"atb":[[4.4,2.19]],"id":66826631}],"con":true,"img":false}]}
{"op":"mcm","clk":"11450766212","pt":1717325318409,"mc":[{"id":"1.229554930","rc":[{"atb":[[4.5,5.68],[4.4,6.66]],"id":66826631}],"con":true,"img":false}]}
{"op":"mcm","clk":"11450766255","pt":1717325318720,"mc":[{"id":"1.229554930","rc":[{"atl":[[3.05,7.54]],"id":47530316}],"con":true,"img":false}]}
{"op":"mcm","clk":"11450766331","pt":1717325319402,"mc":[{"id":"1.229554930","rc":[{"atb":[[4.4,4.66]],"id":66826631},{"atl":[[3,6.39]],"id":47530316}],"con":true,"img":false}]}
{"op":"mcm","clk":"11450766343","pt":1717325319505,"mc":[{"id":"1.229554930","rc":[{"atb":[[4.6,2]],"id":66826631}],"con":true,"img":false}]}
{"op":"mcm","clk":"11450766415","pt":1717325320223,"mc":[{"id":"1.229554930","rc":[{"atb":[[4.5,0]],"id":66826631}],"con":true,"img":false}]}
{"op":"mcm","clk":"11450766523","pt":1717325321171,"mc":[{"id":"1.229554930","rc":[{"atl":[[2.72,3]],"id":47530316}],"con":true,"img":false}]}
{"op":"mcm","clk":"11450766544","pt":1717325321382,"mc":[{"id":"1.229554930","rc":[{"atb":[[4.4,0.19]],"id":66826631}],"con":true,"img":false}]}
{"op":"mcm","clk":"11450766581","pt":1717325321701,"mc":[{"id":"1.229554930","rc":[{"atl":[[3,0],[3.05,0]],"id":47530316}],"con":true,"img":false}]}
{"op":"mcm","clk":"11450766591","pt":1717325321798,"mc":[{"id":"1.229554930","rc":[{"atb":[[4.6,0]],"id":66826631}],"con":true,"img":false}]}
{"op":"mcm","clk":"11450766596","pt":1717325321901,"mc":[{"id":"1.229554930","rc":[{"atb":[[4.5,2]],"id":66826631}],"con":true,"img":false}]}
{"op":"mcm","clk":"11450766762","pt":1717325323412,"mc":[{"id":"1.229554930","rc":[{"atl":[[2.72,0]],"id":47530316}],"con":true,"img":false}]}
{"op":"mcm","clk":"11450766939","pt":1717325324717,"mc":[{"id":"1.229554930","rc":[{"atb":[[2.42,0],[2.14,87.72]],"id":66826631},{"atl":[[3.45,0],[3.65,37.74]],"id":47530316}],"con":true,"img":false}]}
{"op":"mcm","clk":"11450766963","pt":1717325324920,"mc":[{"id":"1.229554930","rc":[{"atl":[[1000,3.35]],"id":65894825}],"con":true,"img":false}]}
{"op":"mcm","clk":"11450766996","pt":1717325325129,"mc":[{"id":"1.229554930","rc":[{"atl":[[1000,3.08]],"id":65894825}],"con":true,"img":false}]}
{"op":"mcm","clk":"11450767038","pt":1717325325497,"mc":[{"id":"1.229554930","rc":[{"atl":[[1000,1]],"id":65894825}],"con":true,"img":false}]}
{"op":"mcm","clk":"11450767055","pt":1717325325594,"mc":[{"id":"1.229554930","rc":[{"atl":[[6.4,2.08]],"id":65894825}],"con":true,"img":false}]}
{"op":"mcm","clk":"11450767121","pt":1717325326317,"mc":[{"id":"1.229554930","rc":[{"atb":[[4.5,0]],"id":66826631}],"con":true,"img":false}]}
{"op":"mcm","clk":"11450767143","pt":1717325326421,"mc":[{"id":"1.229554930","rc":[{"atb":[[4.4,2.19]],"id":66826631}],"con":true,"img":false}]}
{"op":"mcm","clk":"11450767185","pt":1717325326789,"mc":[{"id":"1.229554930","rc":[{"atb":[[4.5,5.68]],"id":66826631}],"con":true,"img":false}]}
{"op":"mcm","clk":"11450767262","pt":1717325327411,"mc":[{"id":"1.229554930","rc":[{"atl":[[3.05,7.64]],"id":47530316}],"con":true,"img":false}]}
{"op":"mcm","clk":"11450767288","pt":1717325327725,"mc":[{"id":"1.229554930","rc":[{"atl":[[3,6.39]],"id":47530316}],"con":true,"img":false}]}
{"op":"mcm","clk":"11450767399","pt":1717325328727,"mc":[{"id":"1.229554930","rc":[{"atb":[[4.4,0.19]],"id":66826631}],"con":true,"img":false}]}
{"op":"mcm","clk":"11450767410","pt":1717325328824,"mc":[{"id":"1.229554930","rc":[{"atb":[[4.6,2]],"id":66826631}],"con":true,"img":false}]}
{"op":"mcm","clk":"11450767451","pt":1717325329335,"mc":[{"id":"1.229554930","rc":[{"atb":[[4.5,0]],"id":66826631}],"con":true,"img":false}]}
{"op":"mcm","clk":"11450767500","pt":1717325329910,"mc":[{"id":"1.229554930","rc":[{"atl":[[2.72,3]],"id":47530316}],"con":true,"img":false}]}
{"op":"mcm","clk":"11450767571","pt":1717325330129,"mc":[{"id":"1.229554930","rc":[{"atl":[[3,0]],"id":47530316}],"con":true,"img":false}]}
{"op":"mcm","clk":"11450767596","pt":1717325330433,"mc":[{"id":"1.229554930","rc":[{"atl":[[3.05,0]],"id":47530316}],"con":true,"img":false}]}
{"op":"mcm","clk":"11450767625","pt":1717325330700,"mc":[{"id":"1.229554930","rc":[{"atb":[[4.6,0]],"id":66826631}],"con":true,"img":false}]}
{"op":"mcm","clk":"11450767633","pt":1717325330806,"mc":[{"id":"1.229554930","rc":[{"atb":[[4.4,2.19]],"id":66826631}],"con":true,"img":false}]}
{"op":"mcm","clk":"11450767715","pt":1717325331627,"mc":[{"id":"1.229554930","rc":[{"atb":[[4.5,5.68]],"id":66826631}],"con":true,"img":false}]}
{"op":"mcm","clk":"11450767752","pt":1717325332097,"mc":[{"id":"1.229554930","rc":[{"atl":[[2.72,0]],"id":47530316}],"con":true,"img":false}]}
{"op":"mcm","clk":"11450767843","pt":1717325333025,"mc":[{"id":"1.229554930","rc":[{"atb":[[4.4,0.19]],"id":66826631}],"con":true,"img":false}]}
{"op":"mcm","clk":"11450767854","pt":1717325333127,"mc":[{"id":"1.229554930","rc":[{"atb":[[4.6,2]],"id":66826631}],"con":true,"img":false}]}
{"op":"mcm","clk":"11450767913","pt":1717325333743,"mc":[{"id":"1.229554930","rc":[{"atb":[[4.5,0]],"id":66826631}],"con":true,"img":false}]}
{"op":"mcm","clk":"11450768061","pt":1717325335512,"mc":[{"id":"1.229554930","rc":[{"atb":[[4.6,0]],"id":66826631}],"con":true,"img":false}]}
{"op":"mcm","clk":"11450768071","pt":1717325335617,"mc":[{"id":"1.229554930","rc":[{"atb":[[4.4,2.19]],"id":66826631}],"con":true,"img":false}]}
{"op":"mcm","clk":"11450768141","pt":1717325336340,"mc":[{"id":"1.229554930","rc":[{"atb":[[4.5,5.68]],"id":66826631}],"con":true,"img":false}]}
{"op":"mcm","clk":"11450768152","pt":1717325336444,"mc":[{"id":"1.229554930","rc":[{"atb":[[4.4,6.67]],"id":66826631}],"con":true,"img":false}]}
{"op":"mcm","clk":"11450768182","pt":1717325336711,"mc":[{"id":"1.229554930","rc":[{"atl":[[3.05,7.64]],"id":47530316}],"con":true,"img":false}]}
{"op":"mcm","clk":"11450768220","pt":1717325337122,"mc":[{"id":"1.229554930","rc":[{"atb":[[4.4,4.67]],"id":66826631},{"atl":[[3,6.39]],"id":47530316}],"con":true,"img":false}]}
{"op":"mcm","clk":"11450768227","pt":1717325337228,"mc":[{"id":"1.229554930","rc":[{"atb":[[4.6,2]],"id":66826631}],"con":true,"img":false}]}
{"op":"mcm","clk":"11450768258","pt":1717325337631,"mc":[{"id":"1.229554930","rc":[{"atb":[[4.3,31.67],[3.9,72.08],[3.65,78.88]],"id":66826631},{"atl":[[34,6.33],[22,6.63]],"id":66826631},{"atb":[[1.44,475.13],[1.54,193.57],[1.49,426.65]],"id":47530316},{"atl":[[3.6,80.4],[3.1,66.37]],"id":47530316},{"atb":[[2.06,197.22],[1.98,213.33],[2.16,90.11]],"id":65894825},{"atl":[[9,26.13],[7,23.22]],"id":65894825},{"atb":[[38,2.82],[24,9.08],[29,7.46]],"id":44736449},{"atl":[[550,0.38],[450,0.3]],"id":44736449}],"con":true,"img":false}]}
{"op":"mcm","clk":"11450768275","pt":1717325337837,"mc":[{"id":"1.229554930","rc":[{"atb":[[4.5,0]],"id":66826631}],"con":true,"img":false}]}
{"op":"mcm","clk":"11450768349","pt":1717325338569,"mc":[{"id":"1.229554930","rc":[{"atl":[[5.9,0]],"id":65894825}],"con":true,"img":false}]}
{"op":"mcm","clk":"11450768359","pt":1717325338675,"mc":[{"id":"1.229554930","rc":[{"atl":[[5.8,0]],"id":65894825}],"con":true,"img":false}]}
{"op":"mcm","clk":"11450768366","pt":1717325338731,"mc":[{"id":"1.229554930","rc":[{"atl":[[2.72,3]],"id":47530316},{"atl":[[6.2,19.23]],"id":65894825}],"con":true,"img":false}]}
{"op":"mcm","clk":"11450768413","pt":1717325339256,"mc":[{"id":"1.229554930","rc":[{"atl":[[3,0]],"id":47530316}],"con":true,"img":false}]}
{"op":"mcm","clk":"11450768439","pt":1717325339413,"mc":[{"id":"1.229554930","rc":[{"atb":[[4.4,0.19]],"id":66826631},{"atl":[[6,4.26]],"id":65894825}],"con":true,"img":false}]}
{"op":"mcm","clk":"11450768469","pt":1717325339733,"mc":[{"id":"1.229554930","rc":[{"atl":[[6,8.63]],"id":65894825}],"con":true,"img":false}]}
{"op":"mcm","clk":"11450768494","pt":1717325339936,"mc":[{"id":"1.229554930","rc":[{"atl":[[3.05,0]],"id":47530316}],"con":true,"img":false}]}
{"op":"mcm","clk":"11450768520","pt":1717325340144,"mc":[{"id":"1.229554930","rc":[{"atb":[[4.6,0]],"id":66826631}],"con":true,"img":false}]}
{"op":"mcm","clk":"11450768531","pt":1717325340245,"mc":[{"id":"1.229554930","rc":[{"atb":[[4.4,2.19]],"id":66826631}],"con":true,"img":false}]}
{"op":"mcm","clk":"11450768561","pt":1717325340512,"mc":[{"id":"1.229554930","rc":[{"atb":[[4.5,5.68]],"id":66826631}],"con":true,"img":false}]}
{"op":"mcm","clk":"11450768614","pt":1717325340926,"mc":[{"id":"1.229554930","rc":[{"atl":[[2.72,0]],"id":47530316}],"con":true,"img":false}]}
{"op":"mcm","clk":"11450768729","pt":1717325341913,"mc":[{"id":"1.229554930","rc":[{"atb":[[4.4,0.19]],"id":66826631}],"con":true,"img":false}]}
{"op":"mcm","clk":"11450768741","pt":1717325342063,"mc":[{"id":"1.229554930","rc":[{"atb":[[4.6,2]],"id":66826631},{"atb":[[50,0]],"id":44736449},{"atl":[[990,0]],"id":44736449}],"con":true,"img":false}]}
{"op":"mcm","clk":"11450768810","pt":1717325342538,"mc":[{"id":"1.229554930","rc":[{"atb":[[4.5,0],[4.3,63.35],[3.9,144.17],[3.65,157.77]],"id":66826631},{"atl":[[34,12.67],[22,13.27]],"id":66826631},{"atb":[[1.44,950.27],[1.54,387.15],[1.49,853.31]],"id":47530316},{"atl":[[3.6,160.81],[3.1,132.74]],"id":47530316},{"atb":[[38,5.65],[24,18.17],[29,14.93]],"id":44736449},{"atl":[[550,0.76],[450,0.61]],"id":44736449},{"atb":[[2.06,394.45],[1.98,426.66],[2.16,180.22]],"id":65894825},{"atl":[[9,52.26],[7,46.45]],"id":65894825}],"con":true,"img":false}]}
{"op":"mcm","clk":"11450768991","pt":1717325344052,"mc":[{"id":"1.229554930","rc":[{"atb":[[4.6,0]],"id":66826631}],"con":true,"img":false}]}
{"op":"mcm","clk":"11450768999","pt":1717325344149,"mc":[{"id":"1.229554930","rc":[{"atb":[[4.4,2.19]],"id":66826631}],"con":true,"img":false}]}
{"op":"mcm","clk":"11450769076","pt":1717325344839,"mc":[{"id":"1.229554930","rc":[{"atb":[[4.5,5.68]],"id":66826631}],"con":true,"img":false}]}
{"op":"mcm","clk":"11450769159","pt":1717325345756,"mc":[{"id":"1.229554930","rc":[{"atl":[[3.05,7.75]],"id":47530316}],"con":true,"img":false}]}
{"op":"mcm","clk":"11450769219","pt":1717325346231,"mc":[{"id":"1.229554930","rc":[{"atl":[[3,6.39]],"id":47530316}],"con":true,"img":false}]}
{"op":"mcm","clk":"11450769249","pt":1717325346541,"mc":[{"id":"1.229554930","rc":[{"atb":[[4.4,0.19]],"id":66826631}],"con":true,"img":false}]}
{"op":"mcm","clk":"11450769262","pt":1717325346643,"mc":[{"id":"1.229554930","rc":[{"atb":[[4.6,2]],"id":66826631}],"con":true,"img":false}]}
{"op":"mcm","clk":"11450769310","pt":1717325347058,"mc":[{"id":"1.229554930","rc":[{"atb":[[4.5,0]],"id":66826631}],"con":true,"img":false}]}
{"op":"mcm","clk":"11450769352","pt":1717325347435,"mc":[{"id":"1.229554930","rc":[{"atl":[[2.78,3]],"id":47530316}],"con":true,"img":false}]}
{"op":"mcm","clk":"11450769373","pt":1717325347639,"mc":[{"id":"1.229554930","rc":[{"atl":[[6.2,0],[5.9,8.63]],"id":65894825}],"con":true,"img":false}]}
{"op":"mcm","clk":"11450769422","pt":1717325348152,"mc":[{"id":"1.229554930","rc":[{"spn":4.6,"spf":1.0,"id":66826631},{"atl":[[3,0]],"id":47530316},{"spn":2.19,"spf":"NaN","id":47530316},{"atl":[[6,4.37]],"id":65894825},{"spn":38.18,"spf":1.0,"id":44736449}],"con":true,"img":false}]}
{"op":"mcm","clk":"11450769443","pt":1717325348357,"mc":[{"id":"1.229554930","rc":[{"atl":[[5.8,4.4]],"id":65894825}],"con":true,"img":false}]}
{"op":"mcm","clk":"11450769489","pt":1717325348827,"mc":[{"id":"1.229554930","rc":[{"atl":[[6,0]],"id":65894825}],"con":true,"img":false}]}
{"op":"mcm","clk":"11450769506","pt":1717325349033,"mc":[{"id":"1.229554930","rc":[{"atl":[[3.05,0]],"id":47530316},{"atb":[[2.52,2]],"id":65894825}],"con":true,"img":false}]}
{"op":"mcm","clk":"11450769518","pt":1717325349140,"mc":[{"id":"1.229554930","rc":[{"atb":[[4.6,0]],"id":66826631},{"atb":[[1.61,2]],"id":47530316}],"con":true,"img":false}]}
{"op":"mcm","clk":"11450769523","pt":1717325349235,"mc":[{"id":"1.229554930","rc":[{"atb":[[4.4,2.19]],"id":66826631}],"con":true,"img":false}]}
{"op":"mcm","clk":"11450769565","pt":1717325349758,"mc":[{"id":"1.229554930","rc":[{"atb":[[4.5,5.68]],"id":66826631},{"atl":[[2.78,0]],"id":47530316}],"con":true,"img":false}]}
{"op":"mcm","clk":"11450769638","pt":1717325350435,"mc":[{"id":"1.229554930","rc":[{"atl":[[5.7,0]],"id":65894825}],"con":true,"img":false}]}
{"op":"mcm","clk":"11450769658","pt":1717325350642,"mc":[{"id":"1.229554930","rc":[{"atb":[[55,0]],"id":44736449}],"con":true,"img":false}]}
{"op":"mcm","clk":"11450769722","pt":1717325351269,"mc":[{"id":"1.229554930","rc":[{"atb":[[4.4,2]],"id":66826631}],"con":true,"img":false}]}
{"op":"mcm","clk":"11450769750","pt":1717325351565,"mc":[{"id":"1.229554930","rc":[{"atl":[[21,0]],"id":66826631}],"con":true,"img":false}]}
{"op":"mcm","clk":"11450769796","pt":1717325351939,"mc":[{"id":"1.229554930","rc":[{"atb":[[4.4,0]],"id":66826631}],"con":true,"img":false}]}
{"op":"mcm","clk":"11450769809","pt":1717325352040,"mc":[{"id":"1.229554930","rc":[{"atb":[[4.6,2]],"id":66826631}],"con":true,"img":false}]}
{"op":"mcm","clk":"11450769896","pt":1717325352926,"mc":[{"id":"1.229554930","rc":[{"atb":[[4.5,0]],"id":66826631}],"con":true,"img":false}]}
{"op":"mcm","clk":"11450769933","pt":1717325353341,"mc":[{"id":"1.229554930","rc":[{"atl":[[20,0]],"id":66826631}],"con":true,"img":false}]}
{"op":"mcm","clk":"11450769985","pt":1717325353961,"mc":[{"id":"1.229554930","rc":[{"atl":[[1000,2.03]],"id":66826631}],"con":true,"img":false}]}
{"op":"mcm","clk":"11450770005","pt":1717325354163,"mc":[{"id":"1.229554930","rc":[{"atb":[[1.03,1.7]],"id":65894825}],"con":true,"img":false}]}
{"op":"mcm","clk":"11450770019","pt":1717325354268,"mc":[{"id":"1.229554930","rc":[{"atb":[[4.6,0]],"id":66826631}],"con":true,"img":false}]}
{"op":"mcm","clk":"11450770029","pt":1717325354325,"mc":[{"id":"1.229554930","rc":[{"atb":[[4.4,2]],"id":66826631}],"con":true,"img":false}]}
{"op":"mcm","clk":"11450770039","pt":1717325354528,"mc":[{"id":"1.229554930","rc":[{"atb":[[4.5,5.68]],"id":66826631},{"atb":[[1.02,1.7]],"id":47530316}],"con":true,"img":false}]}
{"op":"mcm","clk":"11450770060","pt":1717325354688,"mc":[{"id":"1.229554930","rc":[{"atl":[[3.05,7.68]],"id":47530316}],"con":true,"img":false}]}
{"op":"mcm","clk":"11450770075","pt":1717325354793,"mc":[{"id":"1.229554930","rc":[{"atl":[[1000,1.17]],"id":47530316}],"con":true,"img":false}]}
{"op":"mcm","clk":"11450770089","pt":1717325354927,"mc":[{"id":"1.229554930","rc":[{"atl":[[1000,2.7]],"id":65894825}],"con":true,"img":false}]}
{"op":"mcm","clk":"11450770113","pt":1717325355103,"mc":[{"id":"1.229554930","rc":[{"atl":[[1000,3.73]],"id":66826631}],"con":true,"img":false}]}
{"op":"mcm","clk":"11450770124","pt":1717325355210,"mc":[{"id":"1.229554930","rc":[{"atb":[[1.04,1.7]],"id":66826631},{"atl":[[1000,3.3]],"id":66826631}],"con":true,"img":false}]}
{"op":"mcm","clk":"11450770137","pt":1717325355310,"mc":[{"id":"1.229554930","rc":[{"atl":[[3,6.39]],"id":47530316}],"con":true,"img":false}]}
{"op":"mcm","clk":"11450770150","pt":1717325355420,"mc":[{"id":"1.229554930","rc":[{"atb":[[1.4,1.7]],"id":44736449}],"con":true,"img":false}]}
{"op":"mcm","clk":"11450770162","pt":1717325355625,"mc":[{"id":"1.229554930","rc":[{"atb":[[1.03,0.33]],"id":65894825}],"con":true,"img":false}]}
{"op":"mcm","clk":"11450770172","pt":1717325355727,"mc":[{"id":"1.229554930","rc":[{"atb":[[1.02,3.4]],"id":47530316}],"con":true,"img":false}]}
{"op":"mcm","clk":"11450770192","pt":1717325355935,"mc":[{"id":"1.229554930","rc":[{"atl":[[1000,1.15]],"id":65894825}],"con":true,"img":false}]}
{"op":"mcm","clk":"11450770206","pt":1717325355988,"mc":[{"id":"1.229554930","rc":[{"atb":[[4.4,0]],"id":66826631}],"con":true,"img":false}]}
{"op":"mcm","clk":"11450770217","pt":1717325356095,"mc":[{"id":"1.229554930","rc":[{"atb":[[4.6,2]],"id":66826631}],"con":true,"img":false}]}
{"op":"mcm","clk":"11450770231","pt":1717325356196,"mc":[{"id":"1.229554930","rc":[{"atl":[[2.8,3]],"id":47530316}],"con":true,"img":false}]}
{"op":"mcm","clk":"11450770240","pt":1717325356300,"mc":[{"id":"1.229554930","rc":[{"atl":[[1000,1.64]],"id":66826631}],"con":true,"img":false}]}
{"op":"mcm","clk":"11450770254","pt":1717325356404,"mc":[{"id":"1.229554930","rc":[{"atb":[[1.04,0.18]],"id":66826631}],"con":true,"img":false}]}
{"op":"mcm","clk":"11450770268","pt":1717325356510,"mc":[{"id":"1.229554930","rc":[{"atl":[[5.7,4.41],[5.9,0]],"id":65894825}],"con":true,"img":false}]}
{"op":"mcm","clk":"11450770303","pt":1717325356817,"mc":[{"id":"1.229554930","rc":[{"atb":[[4.5,0]],"id":66826631},{"atl":[[1000,1.22]],"id":66826631},{"atl":[[3,0]],"id":47530316},{"atl":[[5.8,0]],"id":65894825},{"atb":[[1.4,0.01]],"id":44736449}],"con":true,"img":false}]}
{"op":"mcm","clk":"11450770314","pt":1717325356919,"mc":[{"id":"1.229554930","rc":[{"atl":[[21,0.42]],"id":66826631},{"atl":[[6.4,20.6],[5.7,0]],"id":65894825}],"con":true,"img":false}]}
{"op":"mcm","clk":"11450770342","pt":1717325357128,"mc":[{"id":"1.229554930","rc":[{"atb":[[1.03,0]],"id":65894825}],"con":true,"img":false}]}
{"op":"mcm","clk":"11450770358","pt":1717325357230,"mc":[{"id":"1.229554930","rc":[{"atb":[[2.54,0.33]],"id":65894825}],"con":true,"img":false}]}
{"op":"mcm","clk":"11450770398","pt":1717325357645,"mc":[{"id":"1.229554930","rc":[{"atl":[[6.2,4.48]],"id":65894825}],"con":true,"img":false}]}
{"op":"mcm","clk":"11450770429","pt":1717325357806,"mc":[{"id":"1.229554930","rc":[{"atl":[[3.05,0]],"id":47530316},{"atl":[[6.4,2.08],[6,20]],"id":65894825}],"con":true,"img":false}]}
{"op":"mcm","clk":"11450770445","pt":1717325357905,"mc":[{"id":"1.229554930","rc":[{"atl":[[1000,2.07]],"id":66826631}],"con":true,"img":false}]}
{"op":"mcm","clk":"11450770461","pt":1717325358012,"mc":[{"id":"1.229554930","rc":[{"atl":[[1000,1]],"id":65894825}],"con":true,"img":false}]}
{"op":"mcm","clk":"11450770475","pt":1717325358111,"mc":[{"id":"1.229554930","rc":[{"atl":[[5.7,0.15]],"id":65894825}],"con":true,"img":false}]}
{"op":"mcm","clk":"11450770487","pt":1717325358216,"mc":[{"id":"1.229554930","rc":[{"atl":[[5.9,4.32]],"id":65894825}],"con":true,"img":false}]}
{"op":"mcm","clk":"11450770497","pt":1717325358324,"mc":[{"id":"1.229554930","rc":[{"atl":[[21,0]],"id":66826631},{"atl":[[5.8,4.48],[6,0]],"id":65894825}],"con":true,"img":false}]}
{"op":"mcm","clk":"11450770509","pt":1717325358425,"mc":[{"id":"1.229554930","rc":[{"atb":[[1.02,2.23]],"id":47530316}],"con":true,"img":false}]}
{"op":"mcm","clk":"11450770521","pt":1717325358530,"mc":[{"id":"1.229554930","rc":[{"atl":[[1000,2.88]],"id":47530316}],"con":true,"img":false}]}
{"op":"mcm","clk":"11450770531","pt":1717325358631,"mc":[{"id":"1.229554930","rc":[{"atb":[[4.6,0]],"id":66826631}],"con":true,"img":false}]}
{"op":"mcm","clk":"11450770545","pt":1717325358734,"mc":[{"id":"1.229554930","rc":[{"atb":[[4.4,2]],"id":66826631}],"con":true,"img":false}]}
{"op":"mcm","clk":"11450770555","pt":1717325358839,"mc":[{"id":"1.229554930","rc":[{"atl":[[1000,1.65]],"id":66826631}],"con":true,"img":false}]}
{"op":"mcm","clk":"11450770578","pt":1717325358995,"mc":[{"id":"1.229554930","rc":[{"atl":[[1000,1.61]],"id":66826631}],"con":true,"img":false}]}
{"op":"mcm","clk":"11450770589","pt":1717325359100,"mc":[{"id":"1.229554930","rc":[{"atl":[[21,0.04]],"id":66826631}],"con":true,"img":false}]}
{"op":"mcm","clk":"11450770598","pt":1717325359203,"mc":[{"id":"1.229554930","rc":[{"atl":[[5.9,0]],"id":65894825}],"con":true,"img":false}]}
{"op":"mcm","clk":"11450770613","pt":1717325359461,"mc":[{"id":"1.229554930","rc":[{"atb":[[4.5,5.68],[1.04,0]],"id":66826631}],"con":true,"img":false}]}
{"op":"mcm","clk":"11450770628","pt":1717325359514,"mc":[{"id":"1.229554930","rc":[{"atb":[[4.6,0.18]],"id":66826631},{"atl":[[1000,1.17]],"id":66826631}],"con":true,"img":false}]}
{"op":"mcm","clk":"11450770641","pt":1717325359621,"mc":[{"id":"1.229554930","rc":[{"atl":[[19.5,0.43]],"id":66826631}],"con":true,"img":false}]}
{"op":"mcm","clk":"11450770697","pt":1717325360096,"mc":[{"id":"1.229554930","rc":[{"atb":[[1.4,0]],"id":44736449}],"con":true,"img":false}]}
{"op":"mcm","clk":"11450770705","pt":1717325360203,"mc":[{"id":"1.229554930","rc":[{"atb":[[4.4,0]],"id":66826631},{"atb":[[40,0.01]],"id":44736449}],"con":true,"img":false}]}
{"op":"mcm","clk":"11450770717","pt":1717325360309,"mc":[{"id":"1.229554930","rc":[{"atb":[[4.6,2.18]],"id":66826631}],"con":true,"img":false}]}
{"op":"mcm","clk":"11450770806","pt":1717325361238,"mc":[{"id":"1.229554930","rc":[{"atb":[[4.5,0]],"id":66826631}],"con":true,"img":false}]}
{"op":"mcm","clk":"11450770831","pt":1717325361449,"mc":[{"id":"1.229554930","rc":[{"atb":[[1.02,1.7]],"id":47530316}],"con":true,"img":false}]}
{"op":"mcm","clk":"11450770843","pt":1717325361499,"mc":[{"id":"1.229554930","rc":[{"atb":[[1.62,0.52]],"id":47530316}],"con":true,"img":false}]}
{"op":"mcm","clk":"11450770876","pt":1717325361815,"mc":[{"id":"1.229554930","rc":[{"atl":[[1000,1.46]],"id":47530316}],"con":true,"img":false}]}
{"op":"mcm","clk":"11450771037","pt":1717325363217,"mc":[{"id":"1.229554930","rc":[{"atl":[[1000,1.17]],"id":47530316}],"con":true,"img":false}]}
{"op":"mcm","clk":"11450771046","pt":1717325363316,"mc":[{"id":"1.229554930","rc":[{"atl":[[3.05,0.28]],"id":47530316}],"con":true,"img":false}]}
{"op":"mcm","clk":"11450771060","pt":1717325363422,"mc":[{"id":"1.229554930","rc":[{"atl":[[5.8,0],[6,4.63]],"id":65894825}],"con":true,"img":false}]}
{"op":"mcm","clk":"11450771107","pt":1717325363835,"mc":[{"id":"1.229554930","rc":[{"atl":[[5.9,4.32]],"id":65894825}],"con":true,"img":false}]}
{"op":"mcm","clk":"11450771423","pt":1717325366411,"mc":[{"id":"1.229554930","rc":[{"atl":[[6.2,0]],"id":65894825}],"con":true,"img":false}]}
{"op":"mcm","clk":"11450771797","pt":1717325369936,"mc":[{"id":"1.229554930","rc":[{"atl":[[2.92,6.6]],"id":47530316}],"con":true,"img":false}]}
{"op":"mcm","clk":"11450771816","pt":1717325370150,"mc":[{"id":"1.229554930","rc":[{"atl":[[6.4,5.1]],"id":65894825}],"con":true,"img":false}]}
{"op":"mcm","clk":"11450771937","pt":1717325371440,"mc":[{"id":"1.229554930","rc":[{"atl":[[2.8,0]],"id":47530316}],"con":true,"img":false}]}
{"op":"mcm","clk":"11450772019","pt":1717325372161,"mc":[{"id":"1.229554930","rc":[{"atl":[[5.8,4.63],[6,0]],"id":65894825}],"con":true,"img":false}]}
{"op":"mcm","clk":"11450772085","pt":1717325372632,"mc":[{"id":"1.229554930","rc":[{"atl":[[5.9,0]],"id":65894825}],"con":true,"img":false}]}
{"op":"mcm","clk":"11450772098","pt":1717325372735,"mc":[{"id":"1.229554930","rc":[{"atl":[[5.8,0],[6.2,19.23]],"id":65894825}],"con":true,"img":false}]}
{"op":"mcm","clk":"11450772183","pt":1717325373458,"mc":[{"id":"1.229554930","rc":[{"atl":[[6,4.26]],"id":65894825}],"con":true,"img":false}]}
{"op":"mcm","clk":"11450772206","pt":1717325373665,"mc":[{"id":"1.229554930","rc":[{"atl":[[6.2,0],[5.9,5.1]],"id":65894825}],"con":true,"img":false}]}
{"op":"mcm","clk":"11450772264","pt":1717325374240,"mc":[{"id":"1.229554930","rc":[{"atl":[[6,0]],"id":65894825}],"con":true,"img":false}]}
{"op":"mcm","clk":"11450772273","pt":1717325374348,"mc":[{"id":"1.229554930","rc":[{"atl":[[6.2,19.23],[5.9,0]],"id":65894825}],"con":true,"img":false}]}
{"op":"mcm","clk":"11450772368","pt":1717325375225,"mc":[{"id":"1.229554930","rc":[{"atl":[[6,4.26]],"id":65894825}],"con":true,"img":false}]}
{"op":"mcm","clk":"11450772378","pt":1717325375329,"mc":[{"id":"1.229554930","rc":[{"atl":[[6.2,0],[5.9,5.1]],"id":65894825}],"con":true,"img":false}]}
{"op":"mcm","clk":"11450772478","pt":1717325376363,"mc":[{"id":"1.229554930","rc":[{"atl":[[6,0]],"id":65894825}],"con":true,"img":false}]}
{"op":"mcm","clk":"11450772492","pt":1717325376472,"mc":[{"id":"1.229554930","rc":[{"atl":[[6.2,19.23],[5.9,0]],"id":65894825}],"con":true,"img":false}]}
{"op":"mcm","clk":"11450772626","pt":1717325377361,"mc":[{"id":"1.229554930","rc":[{"atl":[[6,4.26]],"id":65894825}],"con":true,"img":false}]}
{"op":"mcm","clk":"11450772638","pt":1717325377460,"mc":[{"id":"1.229554930","rc":[{"atl":[[5.9,5.1]],"id":65894825}],"con":true,"img":false}]}
{"op":"mcm","clk":"11450772651","pt":1717325377563,"mc":[{"id":"1.229554930","rc":[{"atl":[[6.2,0]],"id":65894825}],"con":true,"img":false}]}
{"op":"mcm","clk":"11450772714","pt":1717325378028,"mc":[{"id":"1.229554930","rc":[{"atl":[[2.78,3]],"id":47530316}],"con":true,"img":false}]}
{"op":"mcm","clk":"11450772735","pt":1717325378247,"mc":[{"id":"1.229554930","rc":[{"atl":[[6,0]],"id":65894825}],"con":true,"img":false}]}
{"op":"mcm","clk":"11450772808","pt":1717325378861,"mc":[{"id":"1.229554930","rc":[{"atb":[[50,2]],"id":44736449},{"atl":[[990,2]],"id":44736449}],"con":true,"img":false}]}
{"op":"mcm","clk":"11450773262","pt":1717325382556,"mc":[{"id":"1.229554930","rc":[{"atl":[[6.2,19.23],[5.9,0]],"id":65894825}],"con":true,"img":false}]}
{"op":"mcm","clk":"11450773300","pt":1717325382868,"mc":[{"id":"1.229554930","rc":[{"atl":[[6,4.26]],"id":65894825}],"con":true,"img":false}]}
{"op":"mcm","clk":"11450773331","pt":1717325383071,"mc":[{"id":"1.229554930","rc":[{"atb":[[1.26,0],[1.35,28.04]],"id":47530316}],"con":true,"img":false}]}
{"op":"mcm","clk":"11450773655","pt":1717325385979,"mc":[{"id":"1.229554930","rc":[{"atl":[[19.5,0]],"id":66826631}],"con":true,"img":false}]}
{"op":"mcm","clk":"11450773731","pt":1717325386551,"mc":[{"id":"1.229554930","rc":[{"atl":[[1000,2.03]],"id":66826631}],"con":true,"img":false}]}
{"op":"mcm","clk":"11450773829","pt":1717325387379,"mc":[{"id":"1.229554930","rc":[{"atl":[[1000,1.61]],"id":66826631}],"con":true,"img":false}]}
{"op":"mcm","clk":"11450773937","pt":1717325388273,"mc":[{"id":"1.229554930","rc":[{"atl":[[1000,1.17]],"id":66826631}],"con":true,"img":false}]}
{"op":"mcm","clk":"11450773950","pt":1717325388377,"mc":[{"id":"1.229554930","rc":[{"atl":[[20,0.43]],"id":66826631}],"con":true,"img":false}]}
{"op":"mcm","clk":"11450774257","pt":1717325391080,"mc":[{"id":"1.229554930","rc":[{"atl":[[6.2,0],[5.9,5.1]],"id":65894825}],"con":true,"img":false}]}
{"op":"mcm","clk":"11450774319","pt":1717325391750,"mc":[{"id":"1.229554930","rc":[{"atl":[[6,0]],"id":65894825}],"con":true,"img":false}]}
{"op":"mcm","clk":"11450774327","pt":1717325391854,"mc":[{"id":"1.229554930","rc":[{"atl":[[6.2,19.23],[5.9,0]],"id":65894825}],"con":true,"img":false}]}
{"op":"mcm","clk":"11450774401","pt":1717325392682,"mc":[{"id":"1.229554930","rc":[{"atl":[[6,4.26]],"id":65894825}],"con":true,"img":false}]}
{"op":"mcm","clk":"11450774418","pt":1717325392783,"mc":[{"id":"1.229554930","rc":[{"atl":[[6.2,0],[5.9,5.1]],"id":65894825}],"con":true,"img":false}]}
{"op":"mcm","clk":"11450774474","pt":1717325393253,"mc":[{"id":"1.229554930","rc":[{"atl":[[2.78,0]],"id":47530316}],"con":true,"img":false}]}
{"op":"mcm","clk":"11450774493","pt":1717325393464,"mc":[{"id":"1.229554930","rc":[{"atl":[[6,0]],"id":65894825}],"con":true,"img":false}]}
{"op":"mcm","clk":"11450774504","pt":1717325393565,"mc":[{"id":"1.229554930","rc":[{"atl":[[6.2,19.23]],"id":65894825}],"con":true,"img":false}]}
{"op":"mcm","clk":"11450774515","pt":1717325393668,"mc":[{"id":"1.229554930","rc":[{"atl":[[5.9,0]],"id":65894825}],"con":true,"img":false}]}
{"op":"mcm","clk":"11450774632","pt":1717325394651,"mc":[{"id":"1.229554930","rc":[{"atl":[[6,4.26]],"id":65894825}],"con":true,"img":false}]}
{"op":"mcm","clk":"11450774742","pt":1717325395946,"mc":[{"id":"1.229554930","rc":[{"atb":[[4.3,31.67],[3.9,72.08],[3.65,78.88]],"id":66826631},{"atl":[[34,6.33],[22,6.63]],"id":66826631}],"con":true,"img":false}]}
{"op":"mcm","clk":"11450775139","pt":1717325399900,"mc":[{"id":"1.229554930","rc":[{"atl":[[2.72,3]],"id":47530316}],"con":true,"img":false}]}
{"op":"mcm","clk":"11450775260","pt":1717325400870,"mc":[{"id":"1.229554930","rc":[{"atb":[[4.8,55.01],[4.3,95.02],[5.3,24.31]],"id":66826631},{"atl":[[44,4.86],[27,5.36]],"id":66826631}],"con":true,"img":false}]}
{"op":"mcm","clk":"11450775360","pt":1717325401603,"mc":[{"id":"1.229554930","rc":[{"atb":[[4.6,0.18]],"id":66826631}],"con":true,"img":false}]}
{"op":"mcm","clk":"11450775370","pt":1717325401702,"mc":[{"id":"1.229554930","rc":[{"atb":[[5.4,2]],"id":66826631}],"con":true,"img":false}]}
{"op":"mcm","clk":"11450775406","pt":1717325401966,"mc":[{"id":"1.229554930","rc":[{"atl":[[6.2,0],[5.9,5.1]],"id":65894825}],"con":true,"img":false}]}
{"op":"mcm","clk":"11450775463","pt":1717325402486,"mc":[{"id":"1.229554930","rc":[{"atl":[[6,0]],"id":65894825}],"con":true,"img":false}]}
{"op":"mcm","clk":"11450776027","pt":1717325407115,"mc":[{"id":"1.229554930","rc":[{"atl":[[6.2,19.23]],"id":65894825}],"con":true,"img":false}]}
{"op":"mcm","clk":"11450776044","pt":1717325407215,"mc":[{"id":"1.229554930","rc":[{"atl":[[5.9,0]],"id":65894825}],"con":true,"img":false}]}
{"op":"mcm","clk":"11450776062","pt":1717325407379,"mc":[{"id":"1.229554930","rc":[{"atl":[[6,4.26]],"id":65894825}],"con":true,"img":false}]}
{"op":"mcm","clk":"11450777019","pt":1717325415022,"mc":[{"id":"1.229554930","rc":[{"spn":5.4,"spf":1.0,"id":66826631},{"atl":[[2.72,0]],"id":47530316},{"spn":2.27,"spf":"NaN","id":47530316},{"spn":4.12,"spf":"NaN","id":65894825},{"spn":50.0,"spf":1.0,"id":44736449}],"con":true,"img":false}]}
{"op":"mcm","clk":"11450777071","pt":1717325415293,"mc":[{"id":"1.229554930","rc":[{"atl":[[6.2,0],[5.9,5.1]],"id":65894825}],"con":true,"img":false}]}
{"op":"mcm","clk":"11450777146","pt":1717325415907,"mc":[{"id":"1.229554930","rc":[{"atl":[[6,0]],"id":65894825}],"con":true,"img":false}]}
{"op":"mcm","clk":"11450777172","pt":1717325416116,"mc":[{"id":"1.229554930","rc":[{"atl":[[6.2,19.23],[5.9,0]],"id":65894825}],"con":true,"img":false}]}
{"op":"mcm","clk":"11450777236","pt":1717325416790,"mc":[{"id":"1.229554930","rc":[{"atl":[[6,4.26]],"id":65894825}],"con":true,"img":false}]}
{"op":"mcm","clk":"11450777246","pt":1717325416896,"mc":[{"id":"1.229554930","rc":[{"atl":[[5.9,5.1]],"id":65894825}],"con":true,"img":false}]}
{"op":"mcm","clk":"11450777262","pt":1717325416997,"mc":[{"id":"1.229554930","rc":[{"atl":[[6.2,0]],"id":65894825}],"con":true,"img":false}]}
{"op":"mcm","clk":"11450777334","pt":1717325417616,"mc":[{"id":"1.229554930","rc":[{"atl":[[6,0]],"id":65894825}],"con":true,"img":false}]}
{"op":"mcm","clk":"11450777624","pt":1717325420317,"mc":[{"id":"1.229554930","rc":[{"atb":[[5.5,4.64]],"id":66826631}],"con":true,"img":false}]}
{"op":"mcm","clk":"11450777683","pt":1717325420904,"mc":[{"id":"1.229554930","rc":[{"atb":[[5.4,0]],"id":66826631}],"con":true,"img":false}]}
{"op":"mcm","clk":"11450777698","pt":1717325421000,"mc":[{"id":"1.229554930","rc":[{"atb":[[5.6,2]],"id":66826631}],"con":true,"img":false}]}
{"op":"mcm","clk":"11450777718","pt":1717325421205,"mc":[{"id":"1.229554930","rc":[{"atb":[[5.5,0]],"id":66826631}],"con":true,"img":false}]}
{"op":"mcm","clk":"11450777780","pt":1717325421717,"mc":[{"id":"1.229554930","rc":[{"atl":[[2.46,3]],"id":47530316}],"con":true,"img":false}]}
{"op":"mcm","clk":"11450777812","pt":1717325422029,"mc":[{"id":"1.229554930","rc":[{"atl":[[6.2,19.23],[5.9,0]],"id":65894825}],"con":true,"img":false}]}
{"op":"mcm","clk":"11450777886","pt":1717325422715,"mc":[{"id":"1.229554930","rc":[{"atl":[[6,4.26]],"id":65894825}],"con":true,"img":false}]}
{"op":"mcm","clk":"11450777991","pt":1717325423542,"mc":[{"id":"1.229554930","rc":[{"atb":[[5.6,0]],"id":66826631}],"con":true,"img":false}]}
{"op":"mcm","clk":"11450778006","pt":1717325423642,"mc":[{"id":"1.229554930","rc":[{"atb":[[5.4,2]],"id":66826631}],"con":true,"img":false}]}
{"op":"mcm","clk":"11450778044","pt":1717325423906,"mc":[{"id":"1.229554930","rc":[{"atb":[[5.5,4.64]],"id":66826631}],"con":true,"img":false}]}
{"op":"mcm","clk":"11450778102","pt":1717325424216,"mc":[{"id":"1.229554930","rc":[{"atl":[[2.46,0]],"id":47530316}],"con":true,"img":false}]}
{"op":"mcm","clk":"11450778311","pt":1717325426141,"mc":[{"id":"1.229554930","rc":[{"atb":[[5.4,0]],"id":66826631}],"con":true,"img":false}]}
{"op":"mcm","clk":"11450778326","pt":1717325426208,"mc":[{"id":"1.229554930","rc":[{"atb":[[5.6,2]],"id":66826631}],"con":true,"img":false}]}
{"op":"mcm","clk":"11450778375","pt":1717325426615,"mc":[{"id":"1.229554930","rc":[{"atb":[[5.5,0]],"id":66826631}],"con":true,"img":false}]}
{"op":"mcm","clk":"11450778546","pt":1717325428429,"mc":[{"id":"1.229554930","rc":[{"atb":[[5.6,0]],"id":66826631}],"con":true,"img":false}]}
{"op":"mcm","clk":"11450778555","pt":1717325428533,"mc":[{"id":"1.229554930","rc":[{"atb":[[5.4,2]],"id":66826631}],"con":true,"img":false}]}
{"op":"mcm","clk":"11450778580","pt":1717325428736,"mc":[{"id":"1.229554930","rc":[{"atb":[[5.5,4.64]],"id":66826631}],"con":true,"img":false}]}
{"op":"mcm","clk":"11450778727","pt":1717325430133,"mc":[{"id":"1.229554930","rc":[{"atl":[[6.2,0],[5.9,5.1]],"id":65894825}],"con":true,"img":false}]}
{"op":"mcm","clk":"11450778768","pt":1717325430551,"mc":[{"id":"1.229554930","rc":[{"atl":[[2.48,3]],"id":47530316}],"con":true,"img":false}]}
{"op":"mcm","clk":"11450778782","pt":1717325430711,"mc":[{"id":"1.229554930","rc":[{"atb":[[5.4,0]],"id":66826631},{"atl":[[6,0]],"id":65894825}],"con":true,"img":false}]}
{"op":"mcm","clk":"11450778789","pt":1717325430816,"mc":[{"id":"1.229554930","rc":[{"atb":[[4.8,0],[5.6,2],[4.3,31.67],[5.3,0]],"id":66826631},{"atl":[[44,0],[27,0]],"id":66826631},{"atb":[[1.44,475.13],[1.54,193.57],[1.49,426.65]],"id":47530316},{"atl":[[3.6,80.4],[3.1,66.37]],"id":47530316},{"atb":[[2.06,197.22],[1.98,213.33],[2.16,90.11]],"id":65894825},{"atl":[[9,26.13],[7,23.22]],"id":65894825},{"atb":[[38,2.82],[24,9.08],[29,7.46]],"id":44736449},{"atl":[[550,0.38],[450,0.3]],"id":44736449}],"con":true,"img":false}]}
{"op":"mcm","clk":"11450778872","pt":1717325431845,"mc":[{"id":"1.229554930","rc":[{"atb":[[5.5,0]],"id":66826631}],"con":true,"img":false}]}
{"op":"mcm","clk":"11450778955","pt":1717325432532,"mc":[{"id":"1.229554930","rc":[{"atb":[[5.6,0]],"id":66826631}],"con":true,"img":false}]}
{"op":"mcm","clk":"11450778971","pt":1717325432624,"mc":[{"id":"1.229554930","rc":[{"atb":[[4.4,2]],"id":66826631}],"con":true,"img":false}]}
{"op":"mcm","clk":"11450779015","pt":1717325433037,"mc":[{"id":"1.229554930","rc":[{"atb":[[4.5,5.68]],"id":66826631}],"con":true,"img":false}]}
{"op":"mcm","clk":"11450779145","pt":1717325434234,"mc":[{"id":"1.229554930","rc":[{"atb":[[4.4,0]],"id":66826631}],"con":true,"img":false}]}
{"op":"mcm","clk":"11450779157","pt":1717325434332,"mc":[{"id":"1.229554930","rc":[{"atb":[[4.8,55.01],[4.3,95.02],[4.6,2.18],[5.3,24.31]],"id":66826631},{"atl":[[44,4.86],[27,5.36]],"id":66826631},{"atb":[[1.44,950.27],[1.54,387.15],[1.49,853.31]],"id":47530316},{"atl":[[3.6,160.81],[3.1,132.74]],"id":47530316},{"atb":[[38,5.65],[24,18.17],[29,14.93]],"id":44736449},{"atl":[[550,0.76],[450,0.61]],"id":44736449},{"atb":[[2.06,394.45],[1.98,426.66],[2.16,180.22]],"id":65894825},{"atl":[[9,52.26],[7,46.45]],"id":65894825}],"con":true,"img":false}]}
{"op":"mcm","clk":"11450779248","pt":1717325435120,"mc":[{"id":"1.229554930","rc":[{"atl":[[2.48,0]],"id":47530316}],"con":true,"img":false}]}
{"op":"mcm","clk":"11450779265","pt":1717325435225,"mc":[{"id":"1.229554930","rc":[{"atl":[[6.2,19.23],[5.9,0]],"id":65894825}],"con":true,"img":false}]}
{"op":"mcm","clk":"11450779327","pt":1717325435741,"mc":[{"id":"1.229554930","rc":[{"atb":[[4.5,0]],"id":66826631}],"con":true,"img":false}]}
{"op":"mcm","clk":"11450779350","pt":1717325435946,"mc":[{"id":"1.229554930","rc":[{"atl":[[6,4.26]],"id":65894825}],"con":true,"img":false}]}
{"op":"mcm","clk":"11450779369","pt":1717325436150,"mc":[{"id":"1.229554930","rc":[{"atl":[[6,8.68]],"id":65894825}],"con":true,"img":false}]}
{"op":"mcm","clk":"11450779461","pt":1717325437033,"mc":[{"id":"1.229554930","rc":[{"atb":[[4.6,0.18]],"id":66826631}],"con":true,"img":false}]}
{"op":"mcm","clk":"11450779473","pt":1717325437136,"mc":[{"id":"1.229554930","rc":[{"atb":[[5.4,2]],"id":66826631}],"con":true,"img":false}]}
{"op":"mcm","clk":"11450779530","pt":1717325437754,"mc":[{"id":"1.229554930","rc":[{"atb":[[5.5,4.64]],"id":66826631}],"con":true,"img":false}]}
{"op":"mcm","clk":"11450779628","pt":1717325438846,"mc":[{"id":"1.229554930","rc":[{"atb":[[5.4,0]],"id":66826631}],"con":true,"img":false}]}
{"op":"mcm","clk":"11450779636","pt":1717325438942,"mc":[{"id":"1.229554930","rc":[{"atb":[[5.6,2]],"id":66826631}],"con":true,"img":false}]}
{"op":"mcm","clk":"11450779701","pt":1717325439518,"mc":[{"id":"1.229554930","rc":[{"atb":[[5.5,0]],"id":66826631}],"con":true,"img":false}]}
{"op":"mcm","clk":"11450779847","pt":1717325440929,"mc":[{"id":"1.229554930","rc":[{"atb":[[5.6,0]],"id":66826631}],"con":true,"img":false}]}
{"op":"mcm","clk":"11450779859","pt":1717325441027,"mc":[{"id":"1.229554930","rc":[{"atb":[[5.4,2]],"id":66826631}],"con":true,"img":false}]}
{"op":"mcm","clk":"11450779899","pt":1717325441444,"mc":[{"id":"1.229554930","rc":[{"atl":[[2.5,3]],"id":47530316}],"con":true,"img":false}]}
{"op":"mcm","clk":"11450779911","pt":1717325441550,"mc":[{"id":"1.229554930","rc":[{"atb":[[5.5,4.64]],"id":66826631}],"con":true,"img":false}]}
{"op":"mcm","clk":"11450779937","pt":1717325441867,"mc":[{"id":"1.229554930","rc":[{"atb":[[4.8,0],[4.3,31.67],[5.3,0]],"id":66826631},{"atl":[[44,0],[27,0]],"id":66826631},{"atb":[[1.44,475.13],[1.54,193.57],[1.49,426.65]],"id":47530316},{"atl":[[3.6,80.4],[3.1,66.37]],"id":47530316},{"atb":[[2.06,197.22],[1.98,213.33],[2.16,90.11]],"id":65894825},{"atl":[[9,26.13],[7,23.22]],"id":65894825},{"atb":[[38,2.82],[24,9.08],[29,7.46]],"id":44736449},{"atl":[[550,0.38],[450,0.3]],"id":44736449}],"con":true,"img":false}]}
{"op":"mcm","clk":"11450780107","pt":1717325443260,"mc":[{"id":"1.229554930","rc":[{"atl":[[6.2,0],[5.9,8.68]],"id":65894825}],"con":true,"img":false}]}
{"op":"mcm","clk":"11450780119","pt":1717325443371,"mc":[{"id":"1.229554930","rc":[{"atb":[[5.4,0]],"id":66826631}],"con":true,"img":false}]}
{"op":"mcm","clk":"11450780134","pt":1717325443466,"mc":[{"id":"1.229554930","rc":[{"atb":[[1.02,10.94]],"id":66826631}],"con":true,"img":false}]}
{"op":"mcm","clk":"11450780272","pt":1717325444567,"mc":[{"id":"1.229554930","rc":[{"atb":[[5.5,0]],"id":66826631},{"atl":[[6,4.42]],"id":65894825}],"con":true,"img":false}]}
{"op":"mcm","clk":"11450780298","pt":1717325444760,"mc":[{"id":"1.229554930","rc":[{"atl":[[5.8,4.4]],"id":65894825}],"con":true,"img":false}]}
{"op":"mcm","clk":"11450780341","pt":1717325445134,"mc":[{"id":"1.229554930","rc":[{"atb":[[1.02,8.94]],"id":66826631},{"atl":[[6,0]],"id":65894825}],"con":true,"img":false}]}
{"op":"mcm","clk":"11450780357","pt":1717325445244,"mc":[{"id":"1.229554930","rc":[{"atb":[[4.4,2]],"id":66826631}],"con":true,"img":false}]}
{"op":"mcm","clk":"11450780386","pt":1717325445556,"mc":[{"id":"1.229554930","rc":[{"atb":[[4.5,5.68]],"id":66826631}],"con":true,"img":false}]}
{"op":"mcm","clk":"11450780424","pt":1717325445954,"mc":[{"id":"1.229554930","rc":[{"atl":[[2.5,0]],"id":47530316}],"con":true,"img":false}]}
{"op":"mcm","clk":"11450780574","pt":1717325447561,"mc":[{"id":"1.229554930","rc":[{"atb":[[4.4,0]],"id":66826631}],"con":true,"img":false}]}
{"op":"mcm","clk":"11450780586","pt":1717325447661,"mc":[{"id":"1.229554930","rc":[{"atb":[[4.6,2.18]],"id":66826631}],"con":true,"img":false}]}
{"op":"mcm","clk":"11450780637","pt":1717325448239,"mc":[{"id":"1.229554930","rc":[{"atb":[[4.8,55.01],[4.3,95.02],[5.3,24.31]],"id":66826631},{"atl":[[44,4.86],[27,5.36]],"id":66826631},{"atb":[[1.44,950.27],[1.54,387.15],[1.49,853.31]],"id":47530316},{"atl":[[3.6,160.81],[3.1,132.74]],"id":47530316},{"atb":[[2.06,394.45],[1.98,426.66],[2.16,180.22]],"id":65894825},{"atl":[[9,52.26],[7,46.45]],"id":65894825},{"atb":[[38,5.65],[24,18.17],[29,14.93]],"id":44736449},{"atl":[[550,0.76],[450,0.61]],"id":44736449}],"con":true,"img":false}]}
{"op":"mcm","clk":"11450780669","pt":1717325448564,"mc":[{"id":"1.229554930","rc":[{"atl":[[20,0],[1000,2.03]],"id":66826631}],"con":true,"img":false}]}
{"op":"mcm","clk":"11450780677","pt":1717325448657,"mc":[{"id":"1.229554930","rc":[{"atb":[[4.5,0]],"id":66826631}],"con":true,"img":false}]}
{"op":"mcm","clk":"11450780693","pt":1717325448864,"mc":[{"id":"1.229554930","rc":[{"atl":[[1000,1.61]],"id":66826631}],"con":true,"img":false}]}
{"op":"mcm","clk":"11450780721","pt":1717325449166,"mc":[{"id":"1.229554930","rc":[{"atl":[[1000,1.17]],"id":66826631}],"con":true,"img":false}]}
{"op":"mcm","clk":"11450780729","pt":1717325449270,"mc":[{"id":"1.229554930","rc":[{"atl":[[26,0.43]],"id":66826631}],"con":true,"img":false}]}
{"op":"mcm","clk":"11450780772","pt":1717325449639,"mc":[{"id":"1.229554930","rc":[{"atb":[[4.6,0.18]],"id":66826631}],"con":true,"img":false}]}
{"op":"mcm","clk":"11450780785","pt":1717325449747,"mc":[{"id":"1.229554930","rc":[{"atb":[[5.4,2]],"id":66826631}],"con":true,"img":false}]}
{"op":"mcm","clk":"11450780817","pt":1717325450058,"mc":[{"id":"1.229554930","rc":[{"atb":[[5.5,4.64]],"id":66826631}],"con":true,"img":false}]}
{"op":"mcm","clk":"11450780926","pt":1717325451141,"mc":[{"id":"1.229554930","rc":[{"atl":[[5.7,4.56],[5.9,0]],"id":65894825}],"con":true,"img":false}]}
{"op":"mcm","clk":"11450780970","pt":1717325451556,"mc":[{"id":"1.229554930","rc":[{"atb":[[5.4,0]],"id":66826631}],"con":true,"img":false}]}
{"op":"mcm","clk":"11450780978","pt":1717325451660,"mc":[{"id":"1.229554930","rc":[{"atb":[[5.6,2]],"id":66826631}],"con":true,"img":false}]}
{"op":"mcm","clk":"11450781040","pt":1717325452280,"mc":[{"id":"1.229554930","rc":[{"atb":[[5.5,0]],"id":66826631},{"atl":[[5.8,0]],"id":65894825}],"con":true,"img":false}]}
{"op":"mcm","clk":"11450781051","pt":1717325452339,"mc":[{"id":"1.229554930","rc":[{"atl":[[2.46,3]],"id":47530316},{"atl":[[6.2,19.23],[5.7,0.15]],"id":65894825}],"con":true,"img":false}]}
{"op":"mcm","clk":"11450781115","pt":1717325453059,"mc":[{"id":"1.229554930","rc":[{"atl":[[21,1.31]],"id":66826631},{"atl":[[2.44,1.26]],"id":47530316},{"atl":[[5.6,1.26]],"id":65894825},{"atl":[[540,1.26]],"id":44736449}],"con":true,"img":false}]}
{"op":"mcm","clk":"11450781126","pt":1717325453164,"mc":[{"id":"1.229554930","rc":[{"atl":[[5.6,3.26],[6.2,0]],"id":65894825},{"atl":[[540,3.26],[990,0]],"id":44736449}],"con":true,"img":false}]}
{"op":"mcm","clk":"11450781137","pt":1717325453267,"mc":[{"id":"1.229554930","rc":[{"atl":[[540,1.26]],"id":44736449}],"con":true,"img":false}]}
{"op":"mcm","clk":"11450781151","pt":1717325453376,"mc":[{"id":"1.229554930","rc":[{"atl":[[540,3.26]],"id":44736449}],"con":true,"img":false}]}
{"op":"mcm","clk":"11450781207","pt":1717325453849,"mc":[{"id":"1.229554930","rc":[{"atb":[[5.6,0]],"id":66826631}],"con":true,"img":false}]}
{"op":"mcm","clk":"11450781221","pt":1717325453944,"mc":[{"id":"1.229554930","rc":[{"atb":[[5.4,2]],"id":66826631}],"con":true,"img":false}]}
{"op":"mcm","clk":"11450781293","pt":1717325454674,"mc":[{"id":"1.229554930","rc":[{"atl":[[540,2]],"id":44736449}],"con":true,"img":false}]}
{"op":"mcm","clk":"11450781303","pt":1717325454768,"mc":[{"id":"1.229554930","rc":[{"atb":[[5.5,4.64]],"id":66826631}],"con":true,"img":false}]}
{"op":"mcm","clk":"11450781392","pt":1717325455654,"mc":[{"id":"1.229554930","rc":[{"atb":[[5.4,0]],"id":66826631}],"con":true,"img":false}]}
{"op":"mcm","clk":"11450781400","pt":1717325455759,"mc":[{"id":"1.229554930","rc":[{"atb":[[5.6,2]],"id":66826631}],"con":true,"img":false}]}
{"op":"mcm","clk":"11450781443","pt":1717325456169,"mc":[{"id":"1.229554930","rc":[{"atb":[[5.5,0]],"id":66826631}],"con":true,"img":false}]}
{"op":"mcm","clk":"11450781624","pt":1717325458287,"mc":[{"id":"1.229554930","rc":[{"atl":[[540,0],[990,2]],"id":44736449}],"con":true,"img":false}]}
{"op":"mcm","clk":"11450781732","pt":1717325459378,"mc":[{"id":"1.229554930","rc":[{"atb":[[5.6,0]],"id":66826631}],"con":true,"img":false}]}
{"op":"mcm","clk":"11450781746","pt":1717325459479,"mc":[{"id":"1.229554930","rc":[{"atb":[[5.4,2]],"id":66826631}],"con":true,"img":false}]}
{"op":"mcm","clk":"11450781759","pt":1717325459690,"mc":[{"id":"1.229554930","rc":[{"atb":[[5.5,4.64]],"id":66826631}],"con":true,"img":false}]}
{"op":"mcm","clk":"11450781927","pt":1717325461504,"mc":[{"id":"1.229554930","rc":[{"atb":[[5.4,0]],"id":66826631}],"con":true,"img":false}]}
{"op":"mcm","clk":"11450781937","pt":1717325461609,"mc":[{"id":"1.229554930","rc":[{"atb":[[5.6,2]],"id":66826631}],"con":true,"img":false}]}
{"op":"mcm","clk":"11450781965","pt":1717325461920,"mc":[{"id":"1.229554930","rc":[{"atl":[[26,0]],"id":66826631}],"con":true,"img":false}]}
{"op":"mcm","clk":"11450782036","pt":1717325462492,"mc":[{"id":"1.229554930","rc":[{"atb":[[5.5,0]],"id":66826631}],"con":true,"img":false}]}
{"op":"mcm","clk":"11450782237","pt":1717325464002,"mc":[{"id":"1.229554930","rc":[{"atb":[[5.6,0]],"id":66826631}],"con":true,"img":false}]}
{"op":"mcm","clk":"11450782250","pt":1717325464107,"mc":[{"id":"1.229554930","rc":[{"atb":[[5.4,2]],"id":66826631}],"con":true,"img":false}]}
{"op":"mcm","clk":"11450782272","pt":1717325464314,"mc":[{"id":"1.229554930","rc":[{"atb":[[5.5,4.64]],"id":66826631}],"con":true,"img":false}]}
{"op":"mcm","clk":"11450782478","pt":1717325466128,"mc":[{"id":"1.229554930","rc":[{"atb":[[5.4,0]],"id":66826631}],"con":true,"img":false}]}
{"op":"mcm","clk":"11450782488","pt":1717325466183,"mc":[{"id":"1.229554930","rc":[{"atb":[[5.6,2]],"id":66826631}],"con":true,"img":false}]}
{"op":"mcm","clk":"11450782567","pt":1717325467117,"mc":[{"id":"1.229554930","rc":[{"atb":[[5.5,0]],"id":66826631}],"con":true,"img":false}]}
{"op":"mcm","clk":"11450782604","pt":1717325467531,"mc":[{"id":"1.229554930","rc":[{"atl":[[2.46,0]],"id":47530316}],"con":true,"img":false}]}
{"op":"mcm","clk":"11450782705","pt":1717325468524,"mc":[{"id":"1.229554930","rc":[{"atb":[[5.6,0]],"id":66826631}],"con":true,"img":false}]}
{"op":"mcm","clk":"11450782718","pt":1717325468626,"mc":[{"id":"1.229554930","rc":[{"atb":[[5.4,2]],"id":66826631}],"con":true,"img":false}]}
{"op":"mcm","clk":"11450782797","pt":1717325469301,"mc":[{"id":"1.229554930","rc":[{"atb":[[5.5,4.64]],"id":66826631}],"con":true,"img":false}]}
{"op":"mcm","clk":"11450782981","pt":1717325470919,"mc":[{"id":"1.229554930","rc":[{"atb":[[5.4,0]],"id":66826631}],"con":true,"img":false}]}
{"op":"mcm","clk":"11450782991","pt":1717325471024,"mc":[{"id":"1.229554930","rc":[{"atb":[[5.6,2]],"id":66826631}],"con":true,"img":false}]}
{"op":"mcm","clk":"11450783057","pt":1717325471548,"mc":[{"id":"1.229554930","rc":[{"atb":[[5.5,0]],"id":66826631}],"con":true,"img":false}]}
{"op":"mcm","clk":"11450783244","pt":1717325473207,"mc":[{"id":"1.229554930","rc":[{"atb":[[5.6,0]],"id":66826631}],"con":true,"img":false}]}
{"op":"mcm","clk":"11450783252","pt":1717325473314,"mc":[{"id":"1.229554930","rc":[{"atb":[[5.4,2]],"id":66826631}],"con":true,"img":false}]}
{"op":"mcm","clk":"11450783292","pt":1717325473735,"mc":[{"id":"1.229554930","rc":[{"atl":[[2.42,3]],"id":47530316}],"con":true,"img":false}]}
{"op":"mcm","clk":"11450783299","pt":1717325473832,"mc":[{"id":"1.229554930","rc":[{"atb":[[5.5,4.64]],"id":66826631}],"con":true,"img":false}]}
{"op":"mcm","clk":"11450783387","pt":1717325474619,"mc":[{"id":"1.229554930","rc":[{"atl":[[2.44,0]],"id":47530316}],"con":true,"img":false}]}
{"op":"mcm","clk":"11450783449","pt":1717325475140,"mc":[{"id":"1.229554930","rc":[{"spn":5.5,"spf":1.0,"id":66826631},{"spn":2.02,"spf":"NaN","id":47530316},{"atb":[[2.54,0]],"id":65894825},{"spn":4.06,"spf":"NaN","id":65894825}],"con":true,"img":false}]}
{"op":"mcm","clk":"11450783482","pt":1717325475345,"mc":[{"id":"1.229554930","rc":[{"atb":[[5.4,0]],"id":66826631}],"con":true,"img":false}]}
{"op":"mcm","clk":"11450783492","pt":1717325475449,"mc":[{"id":"1.229554930","rc":[{"atb":[[5.6,2]],"id":66826631}],"con":true,"img":false}]}
{"op":"mcm","clk":"11450783502","pt":1717325475508,"mc":[{"id":"1.229554930","rc":[{"atl":[[2.4,1.26]],"id":47530316}],"con":true,"img":false}]}
{"op":"mcm","clk":"11450783551","pt":1717325476025,"mc":[{"id":"1.229554930","rc":[{"atb":[[40,0]],"id":44736449}],"con":true,"img":false}]}
{"op":"mcm","clk":"11450783565","pt":1717325476133,"mc":[{"id":"1.229554930","rc":[{"atb":[[5.5,0]],"id":66826631}],"con":true,"img":false}]}
{"op":"mcm","clk":"11450783575","pt":1717325476235,"mc":[{"id":"1.229554930","rc":[{"atl":[[5.7,0]],"id":65894825}],"con":true,"img":false}]}
{"op":"mcm","clk":"11450783603","pt":1717325476443,"mc":[{"id":"1.229554930","rc":[{"atl":[[21,1.26]],"id":66826631}],"con":true,"img":false}]}
{"op":"mcm","clk":"11450783656","pt":1717325476808,"mc":[{"id":"1.229554930","rc":[{"atb":[[4.6,0]],"id":66826631}],"con":true,"img":false}]}
{"op":"mcm","clk":"11450783693","pt":1717325477115,"mc":[{"id":"1.229554930","rc":[{"atl":[[5.6,2]],"id":65894825}],"con":true,"img":false}]}
{"op":"mcm","clk":"11450783704","pt":1717325477223,"mc":[{"id":"1.229554930","rc":[{"atl":[[6.2,19.23]],"id":65894825}],"con":true,"img":false}]}
{"op":"mcm","clk":"11450783714","pt":1717325477321,"mc":[{"id":"1.229554930","rc":[{"atl":[[5.6,0]],"id":65894825}],"con":true,"img":false}]}
{"op":"mcm","clk":"11450783734","pt":1717325477529,"mc":[{"id":"1.229554930","rc":[{"atb":[[5.6,0]],"id":66826631},{"atl":[[6,4.26]],"id":65894825}],"con":true,"img":false}]}
{"op":"mcm","clk":"11450783743","pt":1717325477633,"mc":[{"id":"1.229554930","rc":[{"atb":[[5.4,2]],"id":66826631}],"con":true,"img":false}]}
{"op":"mcm","clk":"11450783785","pt":1717325478046,"mc":[{"id":"1.229554930","rc":[{"atl":[[5.8,1.26]],"id":65894825}],"con":true,"img":false}]}
{"op":"mcm","clk":"11450783821","pt":1717325478356,"mc":[{"id":"1.229554930","rc":[{"atl":[[6,0]],"id":65894825}],"con":true,"img":false}]}
{"op":"mcm","clk":"11450783842","pt":1717325478515,"mc":[{"id":"1.229554930","rc":[{"atb":[[5.5,4.64]],"id":66826631}],"con":true,"img":false}]}
{"op":"mcm","clk":"11450783918","pt":1717325479245,"mc":[{"id":"1.229554930","rc":[{"atb":[[5.4,0]],"id":66826631}],"con":true,"img":false}]}
{"op":"mcm","clk":"11450783931","pt":1717325479345,"mc":[{"id":"1.229554930","rc":[{"atb":[[5.6,2]],"id":66826631}],"con":true,"img":false}]}
{"op":"mcm","clk":"11450783959","pt":1717325479555,"mc":[{"id":"1.229554930","rc":[{"atb":[[5.5,0]],"id":66826631}],"con":true,"img":false}]}
{"op":"mcm","clk":"11450784006","pt":1717325479929,"mc":[{"id":"1.229554930","rc":[{"atl":[[5.8,0]],"id":65894825}],"con":true,"img":false}]}
{"op":"mcm","clk":"11450784024","pt":1717325480138,"mc":[{"id":"1.229554930","rc":[{"atb":[[1.02,0],[1.62,0]],"id":47530316}],"con":true,"img":false}]}
{"op":"mcm","clk":"11450784047","pt":1717325480342,"mc":[{"id":"1.229554930","rc":[{"atl":[[6,4.26]],"id":65894825}],"con":true,"img":false}]}
{"op":"mcm","clk":"11450784102","pt":1717325480758,"mc":[{"id":"1.229554930","rc":[{"atl":[[5.6,1.26]],"id":65894825}],"con":true,"img":false}]}
{"op":"mcm","clk":"11450784131","pt":1717325480921,"mc":[{"id":"1.229554930","rc":[{"atb":[[1.4,1.7]],"id":44736449}],"con":true,"img":false}]}
{"op":"mcm","clk":"11450784151","pt":1717325481124,"mc":[{"id":"1.229554930","rc":[{"atl":[[6,0]],"id":65894825}],"con":true,"img":false}]}
{"op":"mcm","clk":"11450784166","pt":1717325481330,"mc":[{"id":"1.229554930","rc":[{"atb":[[5.6,0]],"id":66826631},{"atb":[[1.03,1.7]],"id":65894825}],"con":true,"img":false}]}
{"op":"mcm","clk":"11450784176","pt":1717325481433,"mc":[{"id":"1.229554930","rc":[{"atb":[[5.4,2]],"id":66826631},{"atl":[[1000,2.7]],"id":65894825}],"con":true,"img":false}]}
{"op":"mcm","clk":"11450784231","pt":1717325481951,"mc":[{"id":"1.229554930","rc":[{"atb":[[5.5,4.64],[1.05,1.7]],"id":66826631}],"con":true,"img":false}]}
{"op":"mcm","clk":"11450784253","pt":1717325482158,"mc":[{"id":"1.229554930","rc":[{"atl":[[1000,2.88]],"id":66826631}],"con":true,"img":false}]}
{"op":"mcm","clk":"11450784391","pt":1717325483461,"mc":[{"id":"1.229554930","rc":[{"atb":[[5.4,0]],"id":66826631}],"con":true,"img":false}]}
{"op":"mcm","clk":"11450784405","pt":1717325483557,"mc":[{"id":"1.229554930","rc":[{"atb":[[5.6,2]],"id":66826631}],"con":true,"img":false}]}
{"op":"mcm","clk":"11450784423","pt":1717325483761,"mc":[{"id":"1.229554930","rc":[{"atl":[[1000,1.22]],"id":66826631},{"atb":[[1.4,0.01]],"id":44736449}],"con":true,"img":false}]}
{"op":"mcm","clk":"11450784457","pt":1717325484023,"mc":[{"id":"1.229554930","rc":[{"atb":[[1.05,0.15]],"id":66826631},{"atb":[[1.03,0.33]],"id":65894825}],"con":true,"img":false}]}
{"op":"mcm","clk":"11450784471","pt":1717325484135,"mc":[{"id":"1.229554930","rc":[{"atl":[[5.6,0]],"id":65894825}],"con":true,"img":false}]}
{"op":"mcm","clk":"11450784480","pt":1717325484227,"mc":[{"id":"1.229554930","rc":[{"atb":[[5.5,0]],"id":66826631}],"con":true,"img":false}]}
{"op":"mcm","clk":"11450784523","pt":1717325484675,"mc":[{"id":"1.229554930","rc":[{"atl":[[3.05,0]],"id":47530316}],"con":true,"img":false}]}
{"op":"mcm","clk":"11450784583","pt":1717325485145,"mc":[{"id":"1.229554930","rc":[{"atl":[[1000,1.15]],"id":65894825}],"con":true,"img":false}]}
{"op":"mcm","clk":"11450784623","pt":1717325485650,"mc":[{"id":"1.229554930","rc":[{"atb":[[5.6,0]],"id":66826631},{"atl":[[6,4.26]],"id":65894825}],"con":true,"img":false}]}
{"op":"mcm","clk":"11450784631","pt":1717325485754,"mc":[{"id":"1.229554930","rc":[{"atb":[[5.4,2]],"id":66826631},{"atl":[[5.9,5.1]],"id":65894825}],"con":true,"img":false}]}
{"op":"mcm","clk":"11450784640","pt":1717325485860,"mc":[{"id":"1.229554930","rc":[{"atl":[[6.2,0]],"id":65894825}],"con":true,"img":false}]}
{"op":"mcm","clk":"11450784679","pt":1717325486229,"mc":[{"id":"1.229554930","rc":[{"atb":[[1.4,0]],"id":44736449}],"con":true,"img":false}]}
{"op":"mcm","clk":"11450784694","pt":1717325486327,"mc":[{"id":"1.229554930","rc":[{"atb":[[55,0.01]],"id":44736449}],"con":true,"img":false}]}
{"op":"mcm","clk":"11450784731","pt":1717325486643,"mc":[{"id":"1.229554930","rc":[{"atl":[[1000,1.17]],"id":66826631},{"atl":[[6,0]],"id":65894825}],"con":true,"img":false}]}
{"op":"mcm","clk":"11450784740","pt":1717325486747,"mc":[{"id":"1.229554930","rc":[{"atl":[[20,0.04]],"id":66826631},{"atl":[[5.8,1.26],[6.2,19.23],[5.9,0]],"id":65894825}],"con":true,"img":false}]}
{"op":"mcm","clk":"11450784750","pt":1717325486851,"mc":[{"id":"1.229554930","rc":[{"atb":[[5.5,4.64]],"id":66826631},{"atl":[[5.8,6.36],[6.2,0]],"id":65894825}],"con":true,"img":false}]}
{"op":"mcm","clk":"11450784793","pt":1717325487262,"mc":[{"id":"1.229554930","rc":[{"atb":[[1.05,0]],"id":66826631}],"con":true,"img":false}]}
{"op":"mcm","clk":"11450784808","pt":1717325487366,"mc":[{"id":"1.229554930","rc":[{"atb":[[5.7,0.15]],"id":66826631}],"con":true,"img":false}]}
{"op":"mcm","clk":"11450784857","pt":1717325487732,"mc":[{"id":"1.229554930","rc":[{"atb":[[5.4,0]],"id":66826631}],"con":true,"img":false}]}
{"op":"mcm","clk":"11450784866","pt":1717325487835,"mc":[{"id":"1.229554930","rc":[{"atb":[[5.6,2]],"id":66826631},{"atb":[[1.03,0]],"id":65894825}],"con":true,"img":false}]}
{"op":"mcm","clk":"11450784878","pt":1717325487937,"mc":[{"id":"1.229554930","rc":[{"atb":[[2.54,0.33]],"id":65894825}],"con":true,"img":false}]}
{"op":"mcm","clk":"11450784886","pt":1717325488040,"mc":[{"id":"1.229554930","rc":[{"atb":[[5.5,0]],"id":66826631}],"con":true,"img":false}]}
{"op":"mcm","clk":"11450784930","pt":1717325488455,"mc":[{"id":"1.229554930","rc":[{"atl":[[5.8,5.1]],"id":65894825}],"con":true,"img":false}]}
{"op":"mcm","clk":"11450784946","pt":1717325488563,"mc":[{"id":"1.229554930","rc":[{"atl":[[5.8,0],[6.2,19.23]],"id":65894825}],"con":true,"img":false}]}
{"op":"mcm","clk":"11450784973","pt":1717325488841,"mc":[{"id":"1.229554930","rc":[{"atl":[[2.42,0]],"id":47530316}],"con":true,"img":false}]}
{"op":"mcm","clk":"11450785023","pt":1717325489246,"mc":[{"id":"1.229554930","rc":[{"atl":[[6,4.26]],"id":65894825}],"con":true,"img":false}]}
{"op":"mcm","clk":"11450785039","pt":1717325489352,"mc":[{"id":"1.229554930","rc":[{"atl":[[5.6,1.26]],"id":65894825}],"con":true,"img":false}]}
{"op":"mcm","clk":"11450785062","pt":1717325489561,"mc":[{"id":"1.229554930","rc":[{"atl":[[1000,2.88]],"id":47530316}],"con":true,"img":false}]}
{"op":"mcm","clk":"11450785117","pt":1717325490057,"mc":[{"id":"1.229554930","rc":[{"atl":[[6,0]],"id":65894825}],"con":true,"img":false}]}
{"op":"mcm","clk":"11450785187","pt":1717325490683,"mc":[{"id":"1.229554930","rc":[{"atl":[[1000,1]],"id":65894825}],"con":true,"img":false}]}
{"op":"mcm","clk":"11450785193","pt":1717325490746,"mc":[{"id":"1.229554930","rc":[{"atl":[[5.5,0.15]],"id":65894825}],"con":true,"img":false}]}
{"op":"mcm","clk":"11450785228","pt":1717325491062,"mc":[{"id":"1.229554930","rc":[{"atb":[[2.28,78.13],[2.14,0]],"id":66826631},{"atl":[[5.6,0]],"id":65894825},{"atb":[[50,0]],"id":44736449},{"atl":[[990,0]],"id":44736449}],"con":true,"img":false}]}
{"op":"mcm","clk":"11450785266","pt":1717325491471,"mc":[{"id":"1.229554930","rc":[{"atl":[[6,4.26]],"id":65894825}],"con":true,"img":false}]}
{"op":"mcm","clk":"11450785317","pt":1717325491947,"mc":[{"id":"1.229554930","rc":[{"atl":[[2.4,0]],"id":47530316},{"atl":[[5.8,1.26]],"id":65894825}],"con":true,"img":false}]}
{"op":"mcm","clk":"11450785378","pt":1717325492464,"mc":[{"id":"1.229554930","rc":[{"atl":[[6,0]],"id":65894825}],"con":true,"img":false}]}
{"op":"mcm","clk":"11450785420","pt":1717325492834,"mc":[{"id":"1.229554930","rc":[{"atl":[[2.5,1.26]],"id":47530316}],"con":true,"img":false}]}
{"op":"mcm","clk":"11450785461","pt":1717325493244,"mc":[{"id":"1.229554930","rc":[{"atb":[[1.02,1.7]],"id":47530316}],"con":true,"img":false}]}
{"op":"mcm","clk":"11450785634","pt":1717325494960,"mc":[{"id":"1.229554930","rc":[{"atl":[[2.48,3]],"id":47530316}],"con":true,"img":false}]}
{"op":"mcm","clk":"11450785673","pt":1717325495376,"mc":[{"id":"1.229554930","rc":[{"atb":[[1.02,0.52]],"id":47530316},{"atl":[[2.5,0]],"id":47530316}],"con":true,"img":false}]}
{"op":"mcm","clk":"11450785715","pt":1717325495688,"mc":[{"id":"1.229554930","rc":[{"atl":[[1000,1.53]],"id":47530316}],"con":true,"img":false}]}
{"op":"mcm","clk":"11450785758","pt":1717325495958,"mc":[{"id":"1.229554930","rc":[{"atl":[[5.8,6.36]],"id":65894825}],"con":true,"img":false}]}
{"op":"mcm","clk":"11450785772","pt":1717325496060,"mc":[{"id":"1.229554930","rc":[{"atl":[[6.2,0]],"id":65894825}],"con":true,"img":false}]}
{"op":"mcm","clk":"11450785796","pt":1717325496264,"mc":[{"id":"1.229554930","rc":[{"atl":[[2.46,1.26]],"id":47530316}],"con":true,"img":false}]}
{"op":"mcm","clk":"11450785853","pt":1717325496782,"mc":[{"id":"1.229554930","rc":[{"atb":[[1.02,0]],"id":47530316}],"con":true,"img":false}]}
{"op":"mcm","clk":"11450785868","pt":1717325496891,"mc":[{"id":"1.229554930","rc":[{"atb":[[1.62,0.52]],"id":47530316}],"con":true,"img":false}]}
{"op":"mcm","clk":"11450785887","pt":1717325497046,"mc":[{"id":"1.229554930","rc":[{"atl":[[5.8,5.1]],"id":65894825}],"con":true,"img":false}]}
{"op":"mcm","clk":"11450785941","pt":1717325497559,"mc":[{"id":"1.229554930","rc":[{"atl":[[1000,1.17]],"id":47530316}],"con":true,"img":false}]}
{"op":"mcm","clk":"11450785954","pt":1717325497674,"mc":[{"id":"1.229554930","rc":[{"atl":[[2.38,0.35]],"id":47530316}],"con":true,"img":false}]}
{"op":"mcm","clk":"11450786341","pt":1717325501105,"mc":[{"id":"1.229554930","rc":[{"atl":[[5.8,0],[6.2,19.23]],"id":65894825}],"con":true,"img":false}]}
{"op":"mcm","clk":"11450786378","pt":1717325501460,"mc":[{"id":"1.229554930","rc":[{"atl":[[6,4.26]],"id":65894825}],"con":true,"img":false}]}
{"op":"mcm","clk":"11450787162","pt":1717325508387,"mc":[{"id":"1.229554930","rc":[{"atl":[[6.2,0],[5.9,5.1]],"id":65894825}],"con":true,"img":false}]}
{"op":"mcm","clk":"11450787236","pt":1717325509117,"mc":[{"id":"1.229554930","rc":[{"atl":[[6,0]],"id":65894825}],"con":true,"img":false}]}
{"op":"mcm","clk":"11450787348","pt":1717325510213,"mc":[{"id":"1.229554930","rc":[{"atl":[[2.48,0]],"id":47530316}],"con":true,"img":false}]}
{"op":"mcm","clk":"11450787692","pt":1717325513400,"mc":[{"id":"1.229554930","rc":[{"atl":[[6.4,3.01]],"id":65894825}],"con":true,"img":false}]}
{"op":"mcm","clk":"11450787712","pt":1717325513505,"mc":[{"id":"1.229554930","rc":[{"atl":[[6.2,19.23],[5.9,0]],"id":65894825}],"con":true,"img":false}]}
{"op":"mcm","clk":"11450787731","pt":1717325513710,"mc":[{"id":"1.229554930","rc":[{"atl":[[6,4.26]],"id":65894825}],"con":true,"img":false}]}
{"op":"mcm","clk":"11450787960","pt":1717325515588,"mc":[{"id":"1.229554930","rc":[{"atl":[[6.2,0],[5.9,4.26]],"id":65894825}],"con":true,"img":false}]}
{"op":"mcm","clk":"11450788021","pt":1717325516211,"mc":[{"id":"1.229554930","rc":[{"atl":[[2.44,3]],"id":47530316}],"con":true,"img":false}]}
{"op":"mcm","clk":"11450788057","pt":1717325516481,"mc":[{"id":"1.229554930","rc":[{"atl":[[6,0]],"id":65894825}],"con":true,"img":false}]}
{"op":"mcm","clk":"11450788121","pt":1717325516997,"mc":[{"id":"1.229554930","rc":[{"atl":[[2.46,0]],"id":47530316}],"con":true,"img":false}]}
{"op":"mcm","clk":"11450788215","pt":1717325517799,"mc":[{"id":"1.229554930","rc":[{"atl":[[2.42,1.26]],"id":47530316}],"con":true,"img":false}]}
{"op":"mcm","clk":"11450788537","pt":1717325520678,"mc":[{"id":"1.229554930","rc":[{"atl":[[6.2,19.23],[5.9,0]],"id":65894825}],"con":true,"img":false}]}
{"op":"mcm","clk":"11450788578","pt":1717325521001,"mc":[{"id":"1.229554930","rc":[{"atl":[[6,4.26]],"id":65894825}],"con":true,"img":false}]}
{"op":"mcm","clk":"11450788620","pt":1717325521410,"mc":[{"id":"1.229554930","rc":[{"atb":[[1.01,1]],"id":47530316}],"con":true,"img":false}]}
{"op":"mcm","clk":"11450788786","pt":1717325522704,"mc":[{"id":"1.229554930","rc":[{"atl":[[5.9,4.26]],"id":65894825}],"con":true,"img":false}]}
{"op":"mcm","clk":"11450788802","pt":1717325522802,"mc":[{"id":"1.229554930","rc":[{"atl":[[6.2,0]],"id":65894825}],"con":true,"img":false}]}
{"op":"mcm","clk":"11450788890","pt":1717325523488,"mc":[{"id":"1.229554930","rc":[{"atl":[[6,0]],"id":65894825}],"con":true,"img":false}]}
{"op":"mcm","clk":"11450788906","pt":1717325523595,"mc":[{"id":"1.229554930","rc":[{"atl":[[6.2,19.23],[5.9,0]],"id":65894825}],"con":true,"img":false}]}
{"op":"mcm","clk":"11450788996","pt":1717325524331,"mc":[{"id":"1.229554930","rc":[{"atl":[[6,4.26]],"id":65894825}],"con":true,"img":false}]}
{"op":"mcm","clk":"11450789665","pt":1717325530311,"mc":[{"id":"1.229554930","rc":[{"atb":[[1.17,100]],"id":66826631},{"atb":[[1.17,100]],"id":44736449}],"con":true,"img":false}]}
{"op":"mcm","clk":"11450789702","pt":1717325530719,"mc":[{"id":"1.229554930","rc":[{"atl":[[6.2,0],[5.9,4.26]],"id":65894825}],"con":true,"img":false}]}
{"op":"mcm","clk":"11450789759","pt":1717325531298,"mc":[{"id":"1.229554930","rc":[{"atl":[[6,0]],"id":65894825}],"con":true,"img":false}]}
{"op":"mcm","clk":"11450789770","pt":1717325531397,"mc":[{"id":"1.229554930","rc":[{"atl":[[2.44,0]],"id":47530316},{"atl":[[6.2,19.23]],"id":65894825}],"con":true,"img":false}]}
{"op":"mcm","clk":"11450789778","pt":1717325531504,"mc":[{"id":"1.229554930","rc":[{"atl":[[5.9,0]],"id":65894825}],"con":true,"img":false}]}
{"op":"mcm","clk":"11450789885","pt":1717325532429,"mc":[{"id":"1.229554930","rc":[{"atl":[[2.42,0]],"id":47530316},{"atl":[[6,4.26]],"id":65894825}],"con":true,"img":false}]}
{"op":"mcm","clk":"11450789920","pt":1717325532687,"mc":[{"id":"1.229554930","rc":[{"atl":[[6,8.62]],"id":65894825}],"con":true,"img":false}]}
{"op":"mcm","clk":"11450789985","pt":1717325533305,"mc":[{"id":"1.229554930","rc":[{"atl":[[2.5,1.26]],"id":47530316}],"con":true,"img":false}]}
{"op":"mcm","clk":"11450790304","pt":1717325536630,"mc":[{"id":"1.229554930","rc":[{"atb":[[4.8,0],[4.3,31.67],[5.3,0]],"id":66826631},{"atl":[[44,0],[27,0]],"id":66826631},{"spn":5.61,"spf":1.0,"id":66826631},{"atb":[[1.44,475.13],[1.54,193.57],[1.49,426.65]],"id":47530316},{"atl":[[3.6,80.4],[3.1,66.37]],"id":47530316},{"spn":2.0,"spf":"NaN","id":47530316},{"atb":[[2.06,197.22],[1.98,213.33],[2.16,90.11]],"id":65894825},{"atl":[[9,26.13],[7,23.22]],"id":65894825},{"spn":4.02,"spf":"NaN","id":65894825},{"atb":[[38,2.82],[24,9.08],[29,7.46]],"id":44736449},{"atl":[[550,0.38],[450,0.3]],"id":44736449},{"spn":38.18,"spf":1.0,"id":44736449}],"con":true,"img":false}]}
{"op":"mcm","clk":"11450790384","pt":1717325537411,"mc":[{"id":"1.229554930","rc":[{"atl":[[2.48,3]],"id":47530316}],"con":true,"img":false}]}
{"op":"mcm","clk":"11450790411","pt":1717325537620,"mc":[{"id":"1.229554930","rc":[{"atl":[[990,1.26]],"id":44736449}],"con":true,"img":false}]}
{"op":"mcm","clk":"11450790503","pt":1717325538453,"mc":[{"id":"1.229554930","rc":[{"atl":[[2.5,0]],"id":47530316},{"atl":[[5.9,8.62]],"id":65894825}],"con":true,"img":false}]}
{"op":"mcm","clk":"11450790516","pt":1717325538557,"mc":[{"id":"1.229554930","rc":[{"atl":[[6.2,0]],"id":65894825}],"con":true,"img":false}]}
{"op":"mcm","clk":"11450790537","pt":1717325538716,"mc":[{"id":"1.229554930","rc":[{"atl":[[6,4.36]],"id":65894825}],"con":true,"img":false}]}
{"op":"mcm","clk":"11450790549","pt":1717325538821,"mc":[{"id":"1.229554930","rc":[{"atb":[[5.6,0]],"id":66826631}],"con":true,"img":false}]}
{"op":"mcm","clk":"11450790559","pt":1717325538973,"mc":[{"id":"1.229554930","rc":[{"atb":[[1.02,10.94]],"id":66826631},{"atl":[[5.8,4.4]],"id":65894825}],"con":true,"img":false}]}
{"op":"mcm","clk":"11450790580","pt":1717325539128,"mc":[{"id":"1.229554930","rc":[{"atl":[[5.7,4.41],[5.9,0]],"id":65894825}],"con":true,"img":false}]}
{"op":"mcm","clk":"11450790598","pt":1717325539336,"mc":[{"id":"1.229554930","rc":[{"atl":[[2.46,1.26]],"id":47530316}],"con":true,"img":false}]}
{"op":"mcm","clk":"11450790671","pt":1717325540016,"mc":[{"id":"1.229554930","rc":[{"atl":[[5.8,0]],"id":65894825}],"con":true,"img":false}]}
{"op":"mcm","clk":"11450790692","pt":1717325540216,"mc":[{"id":"1.229554930","rc":[{"atl":[[5.6,4.56],[5.7,0],[5.9,4.56]],"id":65894825}],"con":true,"img":false}]}
{"op":"mcm","clk":"11450790706","pt":1717325540322,"mc":[{"id":"1.229554930","rc":[{"atl":[[5.6,5.83]],"id":65894825}],"con":true,"img":false}]}
{"op":"mcm","clk":"11450790789","pt":1717325541041,"mc":[{"id":"1.229554930","rc":[{"atb":[[1.02,8.94]],"id":66826631}],"con":true,"img":false}]}
{"op":"mcm","clk":"11450790801","pt":1717325541100,"mc":[{"id":"1.229554930","rc":[{"atb":[[4.4,2]],"id":66826631}],"con":true,"img":false}]}
{"op":"mcm","clk":"11450790887","pt":1717325541928,"mc":[{"id":"1.229554930","rc":[{"atb":[[4.4,6.41]],"id":66826631}],"con":true,"img":false}]}
{"op":"mcm","clk":"11450790937","pt":1717325542446,"mc":[{"id":"1.229554930","rc":[{"atl":[[6,0]],"id":65894825}],"con":true,"img":false}]}
{"op":"mcm","clk":"11450791157","pt":1717325544324,"mc":[{"id":"1.229554930","rc":[{"atb":[[4.8,55.01],[4.3,95.02],[5.3,24.31]],"id":66826631},{"atl":[[44,4.86],[27,5.36]],"id":66826631},{"atb":[[1.44,950.27],[1.54,387.15],[1.49,853.31]],"id":47530316},{"atl":[[3.6,160.81],[3.1,132.74]],"id":47530316},{"atb":[[2.06,394.45],[1.98,426.66],[2.16,180.22]],"id":65894825},{"atl":[[9,52.26],[7,46.45]],"id":65894825},{"atb":[[38,5.65],[24,18.17],[29,14.93]],"id":44736449},{"atl":[[550,0.76],[450,0.61]],"id":44736449}],"con":true,"img":false}]}
{"op":"mcm","clk":"11450791380","pt":1717325546345,"mc":[{"id":"1.229554930","rc":[{"atb":[[4.4,4.41]],"id":66826631}],"con":true,"img":false}]}
{"op":"mcm","clk":"11450791392","pt":1717325546449,"mc":[{"id":"1.229554930","rc":[{"atb":[[5.4,2]],"id":66826631}],"con":true,"img":false}]}
{"op":"mcm","clk":"11450791476","pt":1717325547128,"mc":[{"id":"1.229554930","rc":[{"atl":[[5.5,4.71],[5.9,0]],"id":65894825}],"con":true,"img":false}]}
{"op":"mcm","clk":"11450791578","pt":1717325547944,"mc":[{"id":"1.229554930","rc":[{"atb":[[4.4,0]],"id":66826631}],"con":true,"img":false}]}
{"op":"mcm","clk":"11450791588","pt":1717325548046,"mc":[{"id":"1.229554930","rc":[{"atl":[[5.6,4.56]],"id":65894825}],"con":true,"img":false}]}
{"op":"mcm","clk":"11450791596","pt":1717325548148,"mc":[{"id":"1.229554930","rc":[{"atl":[[5.6,0]],"id":65894825}],"con":true,"img":false}]}
{"op":"mcm","clk":"11450791608","pt":1717325548253,"mc":[{"id":"1.229554930","rc":[{"atl":[[5.4,4.73]],"id":65894825}],"con":true,"img":false}]}
{"op":"mcm","clk":"11450791658","pt":1717325548829,"mc":[{"id":"1.229554930","rc":[{"atl":[[5.3,1.26]],"id":65894825}],"con":true,"img":false}]}
{"op":"mcm","clk":"11450791752","pt":1717325549658,"mc":[{"id":"1.229554930","rc":[{"atl":[[5.4,0]],"id":65894825}],"con":true,"img":false}]}
{"op":"mcm","clk":"11450792118","pt":1717325552741,"mc":[{"id":"1.229554930","rc":[{"atl":[[2.48,0]],"id":47530316}],"con":true,"img":false}]}
{"op":"mcm","clk":"11450792160","pt":1717325553148,"mc":[{"id":"1.229554930","rc":[{"atl":[[2.46,0]],"id":47530316}],"con":true,"img":false}]}
{"op":"mcm","clk":"11450792244","pt":1717325553935,"mc":[{"id":"1.229554930","rc":[{"atl":[[5.3,4.28]],"id":65894825}],"con":true,"img":false}]}
{"op":"mcm","clk":"11450792253","pt":1717325554039,"mc":[{"id":"1.229554930","rc":[{"atl":[[2.54,1.26]],"id":47530316},{"atl":[[5.5,0.15]],"id":65894825}],"con":true,"img":false}]}
{"op":"mcm","clk":"11450792267","pt":1717325554142,"mc":[{"id":"1.229554930","rc":[{"atb":[[1.01,2.35]],"id":66826631}],"con":true,"img":false}]}
{"op":"mcm","clk":"11450792298","pt":1717325554460,"mc":[{"id":"1.229554930","rc":[{"atb":[[1.01,2.18]],"id":66826631}],"con":true,"img":false}]}
{"op":"mcm","clk":"11450792332","pt":1717325554765,"mc":[{"id":"1.229554930","rc":[{"atb":[[1.01,0]],"id":66826631}],"con":true,"img":false}]}
{"op":"mcm","clk":"11450792348","pt":1717325554874,"mc":[{"id":"1.229554930","rc":[{"atb":[[5.4,4.18]],"id":66826631},{"atl":[[5.3,3.02]],"id":65894825}],"con":true,"img":false}]}
{"op":"mcm","clk":"11450792359","pt":1717325554975,"mc":[{"id":"1.229554930","rc":[{"spl":[[1.01,53.13]],"id":66826631}],"con":true,"img":false}]}
{"op":"mcm","clk":"11450792412","pt":1717325555348,"mc":[{"id":"1.229554930","rc":[{"atb":[[5.5,4.64]],"id":66826631}],"con":true,"img":false}]}
{"op":"mcm","clk":"11450792458","pt":1717325555766,"mc":[{"id":"1.229554930","rc":[{"atb":[[5.4,2.18]],"id":66826631}],"con":true,"img":false}]}
{"op":"mcm","clk":"11450792471","pt":1717325555870,"mc":[{"id":"1.229554930","rc":[{"atb":[[5.6,2]],"id":66826631}],"con":true,"img":false}]}
{"op":"mcm","clk":"11450792551","pt":1717325556548,"mc":[{"id":"1.229554930","rc":[{"atl":[[2.54,0]],"id":47530316}],"con":true,"img":false}]}
{"op":"mcm","clk":"11450792557","pt":1717325556646,"mc":[{"id":"1.229554930","rc":[{"atb":[[5.5,0]],"id":66826631}],"con":true,"img":false}]}
{"op":"mcm","clk":"11450792663","pt":1717325557575,"mc":[{"id":"1.229554930","rc":[{"atl":[[2.5,1.26]],"id":47530316},{"atl":[[4.3,15.15],[4.5,21.43],[4.1,6.45],[4.7,33.78]],"id":65894825}],"con":true,"img":false}]}
{"op":"mcm","clk":"11450792673","pt":1717325557629,"mc":[{"id":"1.229554930","rc":[{"atb":[[50,2]],"id":44736449},{"atl":[[990,3.26]],"id":44736449}],"con":true,"img":false}]}
{"op":"mcm","clk":"11450792752","pt":1717325558356,"mc":[{"id":"1.229554930","rc":[{"atl":[[4,1.26]],"id":65894825}],"con":true,"img":false}]}
{"op":"mcm","clk":"11450792781","pt":1717325558665,"mc":[{"id":"1.229554930","rc":[{"atl":[[2.46,3]],"id":47530316}],"con":true,"img":false}]}
{"op":"mcm","clk":"11450792843","pt":1717325559179,"mc":[{"id":"1.229554930","rc":[{"atl":[[2.5,0]],"id":47530316}],"con":true,"img":false}]}
{"op":"mcm","clk":"11450792912","pt":1717325559647,"mc":[{"id":"1.229554930","rc":[{"atb":[[50,2.31]],"id":44736449}],"con":true,"img":false}]}
{"op":"mcm","clk":"11450792961","pt":1717325560063,"mc":[{"id":"1.229554930","rc":[{"atl":[[2.44,1.26]],"id":47530316}],"con":true,"img":false}]}
{"op":"mcm","clk":"11450792995","pt":1717325560372,"mc":[{"id":"1.229554930","rc":[{"atb":[[4.3,132.9],[4.9,5.13],[4.5,21.43],[4.7,13.51]],"id":66826631},{"atl":[[16.5,4.84],[17.5,7.58],[14.5,1.48],[15.5,3.45]],"id":66826631},{"atb":[[1.17,42.06],[1.35,0]],"id":47530316},{"atl":[[2.6,78.12],[2.48,13.51],[2.56,48.08],[2.52,32.89]],"id":47530316},{"atb":[[1.51,178.95]],"id":65894825},{"atl":[[4.3,0],[4.5,0],[4.1,0],[4.7,0]],"id":65894825}],"con":true,"img":false}]}
{"op":"mcm","clk":"11450793007","pt":1717325560475,"mc":[{"id":"1.229554930","rc":[{"atb":[[1.58,0]],"id":65894825}],"con":true,"img":false}]}
