{"op":"mcm","clk":"11448127655","pt":1717286034989,"mc":[{"id":"1.229554911","marketDefinition":{"bspMarket":true,"turnInPlayEnabled":false,"persistenceEnabled":false,"marketBaseRate":7.0,"eventId":"33318908","eventTypeId":"4339","numberOfWinners":2,"bettingType":"ODDS","marketType":"PLACE","marketTime":"2024-06-02T09:42:00.000Z","suspendTime":"2024-06-02T09:42:00.000Z","bspReconciled":false,"complete":true,"inPlay":false,"crossMatching":true,"runnersVoidable":false,"numberOfActiveRunners":6,"betDelay":0,"status":"OPEN","runners":[{"status":"ACTIVE","sortPriority":1,"id":69676139,"name":"1. Kilkerran"},{"status":"ACTIVE","sortPriority":2,"id":54867443,"name":"2. Pumpkin Party"},{"status":"ACTIVE","sortPriority":3,"id":52272946,"name":"3. Irish Gem"},{"status":"ACTIVE","sortPriority":4,"id":55943164,"name":"5. Lektra Ringo"},{"status":"ACTIVE","sortPriority":5,"id":70003369,"name":"6. Rickis Burner"},{"status":"ACTIVE","sortPriority":6,"id":69033911,"name":"7. Elegant Evie"}],"regulators":["MR_INT"],"venue":"Murray Bridge","countryCode":"AU","discountAllowed":true,"timezone":"Australia/Adelaide","openDate":"2024-06-02T08:21:00.000Z","version":5962317652,"name":"To Be Placed","eventName":"Murray Bridge (AUS) 2nd Jun"},"rc":[],"con":true,"img":false}]}
{"op":"mcm","clk":"11448135505","pt":1717286146256,"mc":[{"id":"1.229554911","marketDefinition":{"bspMarket":true,"turnInPlayEnabled":false,"persistenceEnabled":false,"marketBaseRate":7.0,"eventId":"33318908","eventTypeId":"4339","numberOfWinners":2,"bettingType":"ODDS","marketType":"PLACE","marketTime":"2024-06-02T09:38:00.000Z","suspendTime":"2024-06-02T09:38:00.000Z","bspReconciled":false,"complete":true,"inPlay":false,"crossMatching":true,"runnersVoidable":false,"numberOfActiveRunners":6,"betDelay":0,"status":"OPEN","runners":[{"status":"ACTIVE","sortPriority":1,"id":69676139,"name":"1. Kilkerran"},{"status":"ACTIVE","sortPriority":2,"id":54867443,"name":"2. Pumpkin Party"},{"status":"ACTIVE","sortPriority":3,"id":52272946,"name":"3. Irish Gem"},{"status":"ACTIVE","sortPriority":4,"id":55943164,"name":"5. Lektra Ringo"},{"status":"ACTIVE","sortPriority":5,"id":70003369,"name":"6. Rickis Burner"},{"status":"ACTIVE","sortPriority":6,"id":69033911,"name":"7. Elegant Evie"}],"regulators":["MR_INT"],"venue":"Murray Bridge","countryCode":"AU","discountAllowed":true,"timezone":"Australia/Adelaide","openDate":"2024-06-02T08:21:00.000Z","version":5962327402,"name":"To Be Placed","eventName":"Murray Bridge (AUS) 2nd Jun"},"rc":[],"con":true,"img":false}]}
{"op":"mcm","clk":"11448258036","pt":1717287872067,"mc":[{"id":"1.229554911","rc":[{"atb":[[1.94,37.06],[2.08,21.5]],"id":70003369},{"atl":[[9.2,0.06]],"id":70003369},{"spn":5.64,"spf":"NaN","id":70003369},{"atb":[[2.56,14.88],[2.36,25.61]],"id":69033911},{"atl":[[15.5,0.03]],"id":69033911},{"spn":9.03,"spf":"NaN","id":69033911},{"atb":[[1.01,5807.26]],"id":69676139},{"atl":[[2.78,0.29]],"id":69676139},{"spn":1.89,"spf":"NaN","id":69676139},{"atb":[[10.5,2.44],[8.2,4.83]],"id":52272946},{"spn":"Infinity","spf":"NaN","id":52272946},{"atb":[[1.8,43.55],[1.9,25.8]],"id":55943164},{"atl":[[8,0.07]],"id":55943164},{"spn":4.95,"spf":"NaN","id":55943164},{"atb":[[2.54,15.08],[2.34,26]],"id":54867443},{"atl":[[15,0.03]],"id":54867443},{"spn":8.77,"spf":"NaN","id":54867443}],"con":true,"img":false}]}
{"op":"mcm","clk":"11448259645","pt":1717287895294,"mc":[{"id":"1.229554911","rc":[{"atb":[[1.94,0],[2.08,0]],"id":70003369},{"atl":[[9.2,0]],"id":70003369},{"atb":[[2.56,0],[2.36,0]],"id":69033911},{"atl":[[15.5,0]],"id":69033911},{"atb":[[1.01,0]],"id":69676139},{"atl":[[2.78,0]],"id":69676139},{"atb":[[10.5,0],[8.2,0]],"id":52272946},{"atb":[[1.8,0],[1.9,0]],"id":55943164},{"atl":[[8,0]],"id":55943164},{"atb":[[2.54,0],[2.34,0]],"id":54867443},{"atl":[[15,0]],"id":54867443}],"con":true,"img":false}]}
{"op":"mcm","clk":"11448260594","pt":1717287908430,"mc":[{"id":"1.229554911","rc":[{"atb":[[1.95,36.67],[2.1,21.11]],"id":70003369},{"atl":[[9.2,0.06]],"id":70003369},{"atb":[[2.32,26.39],[2.52,15.28]],"id":69033911},{"atl":[[14.5,0.03]],"id":69033911},{"atb":[[1.01,5807.26]],"id":69676139},{"atl":[[2.8,0.29]],"id":69676139},{"atb":[[11,2.32],[8.4,4.7]],"id":52272946},{"atb":[[1.8,43.55],[1.9,25.8]],"id":55943164},{"atl":[[8,0.07]],"id":55943164},{"atb":[[2.5,15.48],[2.3,26.8]],"id":54867443},{"atl":[[14,0.04]],"id":54867443}],"con":true,"img":false}]}
{"op":"mcm","clk":"11448264320","pt":1717287962466,"mc":[{"id":"1.229554911","rc":[{"atb":[[1.95,0],[2.1,0]],"id":70003369},{"atl":[[9.2,0]],"id":70003369},{"spn":"NaN","spf":"NaN","id":70003369},{"atb":[[2.32,0],[2.52,0]],"id":69033911},{"atl":[[14.5,0]],"id":69033911},{"spn":"NaN","spf":"NaN","id":69033911},{"atb":[[1.01,0]],"id":69676139},{"atl":[[2.8,0]],"id":69676139},{"spn":"NaN","spf":"NaN","id":69676139},{"atb":[[11,0],[8.4,0]],"id":52272946},{"spn":"NaN","spf":"NaN","id":52272946},{"atb":[[1.8,0],[1.9,0]],"id":55943164},{"atl":[[8,0]],"id":55943164},{"spn":"NaN","spf":"NaN","id":55943164},{"atb":[[2.5,0],[2.3,0]],"id":54867443},{"atl":[[14,0]],"id":54867443},{"spn":"NaN","spf":"NaN","id":54867443}],"con":true,"img":false}]}
{"op":"mcm","clk":"11448265018","pt":1717287972318,"mc":[{"id":"1.229554911","rc":[{"atb":[[1.94,37.06],[2.08,21.5]],"id":70003369},{"atl":[[9.2,0.06]],"id":70003369},{"atb":[[2.38,25.24],[2.58,14.7]],"id":69033911},{"atl":[[13.5,0.04]],"id":69033911},{"atb":[[1.01,5807.26]],"id":69676139},{"atl":[[2.8,0.29]],"id":69676139},{"atb":[[10.5,2.44],[8.2,4.83]],"id":52272946},{"atb":[[1.86,27.01],[1.76,45.84]],"id":55943164},{"atl":[[7.6,0.07]],"id":55943164},{"atb":[[2.32,26.39],[2.52,15.28]],"id":54867443},{"atl":[[14.5,0.03]],"id":54867443}],"con":true,"img":false}]}
{"op":"mcm","clk":"11448277243","pt":1717288128429,"mc":[{"id":"1.229554911","marketDefinition":{"bspMarket":true,"turnInPlayEnabled":false,"persistenceEnabled":false,"marketBaseRate":7.0,"eventId":"33318908","eventTypeId":"4339","numberOfWinners":2,"bettingType":"ODDS","marketType":"PLACE","marketTime":"2024-06-02T09:38:00.000Z","suspendTime":"2024-06-02T09:38:00.000Z","bspReconciled":false,"complete":true,"inPlay":false,"crossMatching":true,"runnersVoidable":false,"numberOfActiveRunners":6,"betDelay":0,"status":"OPEN","runners":[{"status":"ACTIVE","sortPriority":1,"id":69676139,"name":"1. Kilkerran"},{"status":"ACTIVE","sortPriority":2,"id":54867443,"name":"2. Pumpkin Party"},{"status":"ACTIVE","sortPriority":3,"id":52272946,"name":"3. Irish Gem"},{"status":"ACTIVE","sortPriority":4,"id":55943164,"name":"5. Lektra Ringo"},{"status":"ACTIVE","sortPriority":5,"id":70003369,"name":"6. Rickis Burner"},{"status":"ACTIVE","sortPriority":6,"id":69033911,"name":"7. Elegant Evie"}],"regulators":["MR_INT"],"venue":"Murray Bridge","countryCode":"AU","discountAllowed":true,"timezone":"Australia/Adelaide","openDate":"2024-06-02T08:21:00.000Z","version":5962327402,"name":"To Be Placed","eventName":"Murray Bridge (AUS) 2nd Jun"},"rc":[{"atb":[[1.94,37.06],[2.08,21.5]],"id":70003369},{"atl":[[9.2,0.06]],"id":70003369},{"spn":5.64,"spf":"NaN","id":70003369},{"atb":[[2.38,25.24],[2.58,14.7]],"id":69033911},{"atl":[[13.5,0.04]],"id":69033911},{"spn":8.04,"spf":"NaN","id":69033911},{"atb":[[1.01,5807.26]],"id":69676139},{"atl":[[2.8,0.29]],"id":69676139},{"spn":1.9,"spf":"NaN","id":69676139},{"atb":[[10.5,2.44],[8.2,4.83]],"id":52272946},{"spn":"Infinity","spf":"NaN","id":52272946},{"atb":[[1.86,27.01],[1.76,45.84]],"id":55943164},{"atl":[[7.6,0.07]],"id":55943164},{"spn":4.73,"spf":"NaN","id":55943164},{"atb":[[2.32,26.39],[2.52,15.28]],"id":54867443},{"atl":[[14.5,0.03]],"id":54867443},{"spn":8.51,"spf":"NaN","id":54867443}],"con":true,"img":true}]}
{"op":"mcm","clk":"11448292464","pt":1717288273959,"mc":[{"id":"1.229554911","rc":[{"atb":[[1.94,0],[2.08,0]],"id":70003369},{"atl":[[9.2,0]],"id":70003369},{"spn":8.04,"spf":"NaN","id":69033911},{"atb":[[1.01,0]],"id":69676139},{"atl":[[2.8,0]],"id":69676139},{"spn":"Infinity","spf":"NaN","id":52272946},{"atb":[[1.86,0],[1.76,0]],"id":55943164},{"atl":[[7.6,0]],"id":55943164},{"spn":8.51,"spf":"NaN","id":54867443}],"con":true,"img":false}]}
{"op":"mcm","clk":"11448293804","pt":1717288291623,"mc":[{"id":"1.229554911","rc":[{"atb":[[1.84,41.48],[1.94,24.7]],"id":70003369},{"atl":[[8.2,0.07]],"id":70003369},{"atb":[[1.01,5807.26]],"id":69676139},{"atl":[[2.78,0.29]],"id":69676139},{"atb":[[1.8,43.55],[1.9,25.8]],"id":55943164},{"atl":[[8,0.07]],"id":55943164}],"con":true,"img":false}]}
{"op":"mcm","clk":"11448298280","pt":1717288351487,"mc":[{"id":"1.229554911","rc":[{"atb":[[1.84,0],[1.94,0]],"id":70003369},{"atl":[[8.2,0]],"id":70003369},{"atb":[[2.38,0],[2.58,0]],"id":69033911},{"atl":[[13.5,0]],"id":69033911},{"spn":"NaN","spf":"NaN","id":69033911},{"atb":[[1.01,0]],"id":69676139},{"atl":[[2.78,0]],"id":69676139},{"atb":[[1.8,0],[1.9,0]],"id":55943164},{"atl":[[8,0]],"id":55943164},{"atb":[[2.32,0],[2.52,0]],"id":54867443},{"atl":[[14.5,0]],"id":54867443},{"spn":"NaN","spf":"NaN","id":54867443}],"con":true,"img":false}]}
{"op":"mcm","clk":"11448300795","pt":1717288383947,"mc":[{"id":"1.229554911","rc":[{"atb":[[1.82,42.49],[1.92,25.24]],"id":70003369},{"atl":[[8,0.07]],"id":70003369},{"atb":[[2.42,24.53],[2.62,14.34]],"id":69033911},{"atl":[[17,0.03]],"id":69033911},{"atb":[[1.01,5807.26]],"id":69676139},{"atl":[[2.78,0.29]],"id":69676139},{"atb":[[1.8,43.55],[1.9,25.8]],"id":55943164},{"atl":[[8,0.07]],"id":55943164},{"atb":[[2.42,24.53],[2.62,14.34]],"id":54867443},{"atl":[[17,0.03]],"id":54867443}],"con":true,"img":false}]}
{"op":"mcm","clk":"11448629974","pt":1717293528419,"mc":[{"id":"1.229554911","marketDefinition":{"bspMarket":true,"turnInPlayEnabled":false,"persistenceEnabled":false,"marketBaseRate":7.0,"eventId":"33318908","eventTypeId":"4339","numberOfWinners":2,"bettingType":"ODDS","marketType":"PLACE","marketTime":"2024-06-02T09:38:00.000Z","suspendTime":"2024-06-02T09:38:00.000Z","bspReconciled":false,"complete":true,"inPlay":false,"crossMatching":true,"runnersVoidable":false,"numberOfActiveRunners":6,"betDelay":0,"status":"OPEN","runners":[{"status":"ACTIVE","sortPriority":1,"id":69676139,"name":"1. Kilkerran"},{"status":"ACTIVE","sortPriority":2,"id":54867443,"name":"2. Pumpkin Party"},{"status":"ACTIVE","sortPriority":3,"id":52272946,"name":"3. Irish Gem"},{"status":"ACTIVE","sortPriority":4,"id":55943164,"name":"5. Lektra Ringo"},{"status":"ACTIVE","sortPriority":5,"id":70003369,"name":"6. Rickis Burner"},{"status":"ACTIVE","sortPriority":6,"id":69033911,"name":"7. Elegant Evie"}],"regulators":["MR_INT"],"venue":"Murray Bridge","countryCode":"AU","discountAllowed":true,"timezone":"Australia/Adelaide","openDate":"2024-06-02T08:21:00.000Z","version":5962327402,"name":"To Be Placed","eventName":"Murray Bridge (AUS) 2nd Jun"},"rc":[{"atb":[[1.82,42.49],[1.92,25.24]],"id":70003369},{"atl":[[8,0.07]],"id":70003369},{"spn":4.96,"spf":"NaN","id":70003369},{"atb":[[2.42,24.53],[2.62,14.34]],"id":69033911},{"atl":[[17,0.03]],"id":69033911},{"spn":9.81,"spf":"NaN","id":69033911},{"atb":[[1.01,5807.26]],"id":69676139},{"atl":[[2.78,0.29]],"id":69676139},{"spn":1.89,"spf":"NaN","id":69676139},{"atb":[[10.5,2.44],[8.2,4.83]],"id":52272946},{"spn":"Infinity","spf":"NaN","id":52272946},{"atb":[[1.8,43.55],[1.9,25.8]],"id":55943164},{"atl":[[8,0.07]],"id":55943164},{"spn":4.95,"spf":"NaN","id":55943164},{"atb":[[2.42,24.53],[2.62,14.34]],"id":54867443},{"atl":[[17,0.03]],"id":54867443},{"spn":9.81,"spf":"NaN","id":54867443}],"con":true,"img":true}]}
{"op":"mcm","clk":"11448643905","pt":1717293690063,"mc":[{"id":"1.229554911","rc":[{"spn":4.96,"spf":"NaN","id":70003369},{"spn":9.81,"spf":"NaN","id":69033911},{"spn":1.89,"spf":"NaN","id":69676139},{"atb":[[10.5,0],[8.2,0]],"id":52272946},{"spn":"NaN","spf":"NaN","id":52272946},{"spn":4.95,"spf":"NaN","id":55943164},{"spn":9.81,"spf":"NaN","id":54867443}],"con":true,"img":false}]}
{"op":"mcm","clk":"11448644389","pt":1717293699752,"mc":[{"id":"1.229554911","rc":[{"atb":[[8,4.97],[10,2.57]],"id":52272946}],"con":true,"img":false}]}
{"op":"mcm","clk":"11448885247","pt":1717298928436,"mc":[{"id":"1.229554911","marketDefinition":{"bspMarket":true,"turnInPlayEnabled":false,"persistenceEnabled":false,"marketBaseRate":7.0,"eventId":"33318908","eventTypeId":"4339","numberOfWinners":2,"bettingType":"ODDS","marketType":"PLACE","marketTime":"2024-06-02T09:38:00.000Z","suspendTime":"2024-06-02T09:38:00.000Z","bspReconciled":false,"complete":true,"inPlay":false,"crossMatching":true,"runnersVoidable":false,"numberOfActiveRunners":6,"betDelay":0,"status":"OPEN","runners":[{"status":"ACTIVE","sortPriority":1,"id":69676139,"name":"1. Kilkerran"},{"status":"ACTIVE","sortPriority":2,"id":54867443,"name":"2. Pumpkin Party"},{"status":"ACTIVE","sortPriority":3,"id":52272946,"name":"3. Irish Gem"},{"status":"ACTIVE","sortPriority":4,"id":55943164,"name":"5. Lektra Ringo"},{"status":"ACTIVE","sortPriority":5,"id":70003369,"name":"6. Rickis Burner"},{"status":"ACTIVE","sortPriority":6,"id":69033911,"name":"7. Elegant Evie"}],"regulators":["MR_INT"],"venue":"Murray Bridge","countryCode":"AU","discountAllowed":true,"timezone":"Australia/Adelaide","openDate":"2024-06-02T08:21:00.000Z","version":5962327402,"name":"To Be Placed","eventName":"Murray Bridge (AUS) 2nd Jun"},"rc":[{"atb":[[1.82,42.49],[1.92,25.24]],"id":70003369},{"atl":[[8,0.07]],"id":70003369},{"spn":4.96,"spf":"NaN","id":70003369},{"atb":[[2.42,24.53],[2.62,14.34]],"id":69033911},{"atl":[[17,0.03]],"id":69033911},{"spn":9.81,"spf":"NaN","id":69033911},{"atb":[[1.01,5807.26]],"id":69676139},{"atl":[[2.78,0.29]],"id":69676139},{"spn":1.89,"spf":"NaN","id":69676139},{"atb":[[8,4.97],[10,2.57]],"id":52272946},{"spn":"Infinity","spf":"NaN","id":52272946},{"atb":[[1.8,43.55],[1.9,25.8]],"id":55943164},{"atl":[[8,0.07]],"id":55943164},{"spn":4.95,"spf":"NaN","id":55943164},{"atb":[[2.42,24.53],[2.62,14.34]],"id":54867443},{"atl":[[17,0.03]],"id":54867443},{"spn":9.81,"spf":"NaN","id":54867443}],"con":true,"img":true}]}
{"op":"mcm","clk":"11449524698","pt":1717310362917,"mc":[{"id":"1.229554911","rc":[{"atb":[[1.82,0],[1.92,0]],"id":70003369},{"atl":[[8,0]],"id":70003369},{"spn":"NaN","spf":"NaN","id":70003369},{"atb":[[2.42,0],[2.62,0]],"id":69033911},{"atl":[[17,0]],"id":69033911},{"spn":"NaN","spf":"NaN","id":69033911},{"atb":[[1.01,0]],"id":69676139},{"atl":[[2.78,0]],"id":69676139},{"spn":"NaN","spf":"NaN","id":69676139},{"atb":[[8,0],[10,0]],"id":52272946},{"atb":[[1.8,0],[1.9,0]],"id":55943164},{"atl":[[8,0]],"id":55943164},{"spn":"NaN","spf":"NaN","id":55943164},{"atb":[[2.42,0],[2.62,0]],"id":54867443},{"atl":[[17,0]],"id":54867443},{"spn":"NaN","spf":"NaN","id":54867443}],"con":true,"img":false}]}
{"op":"mcm","clk":"11449526475","pt":1717310391661,"mc":[{"id":"1.229554911","rc":[{"atb":[[1.85,40.99],[1.95,24.45]],"id":70003369},{"atl":[[8.2,0.07]],"id":70003369},{"atb":[[2.38,25.24],[2.58,14.7]],"id":69033911},{"atl":[[13.5,0.04]],"id":69033911},{"atb":[[1.01,5807.26]],"id":69676139},{"atl":[[2.78,0.29]],"id":69676139},{"atb":[[9.6,2.69],[7.6,5.27]],"id":52272946},{"atb":[[1.83,41.97],[1.93,24.97]],"id":55943164},{"atl":[[8.2,0.07]],"id":55943164},{"atb":[[2.4,24.88],[2.6,14.51]],"id":54867443},{"atl":[[16.5,0.03]],"id":54867443}],"con":true,"img":false}]}
{"op":"mcm","clk":"11449584885","pt":1717311411272,"mc":[{"id":"1.229554911","rc":[{"atb":[[1.85,0],[1.95,0]],"id":70003369},{"atl":[[8.2,0]],"id":70003369},{"atb":[[2.38,0],[2.58,0]],"id":69033911},{"atl":[[13.5,0]],"id":69033911},{"atb":[[1.01,0]],"id":69676139},{"atl":[[2.78,0]],"id":69676139},{"atb":[[9.6,0],[7.6,0]],"id":52272946},{"atb":[[1.83,0],[1.93,0]],"id":55943164},{"atl":[[8.2,0]],"id":55943164},{"atb":[[2.4,0],[2.6,0]],"id":54867443},{"atl":[[16.5,0]],"id":54867443}],"con":true,"img":false}]}
{"op":"mcm","clk":"11449585312","pt":1717311419686,"mc":[{"id":"1.229554911","rc":[{"atb":[[1.96,24.19],[1.86,40.51]],"id":70003369},{"atl":[[8.4,0.07]],"id":70003369},{"atb":[[2.38,25.24],[2.58,14.7]],"id":69033911},{"atl":[[13.5,0.04]],"id":69033911},{"atb":[[1.01,5807.26]],"id":69676139},{"atl":[[2.78,0.29]],"id":69676139},{"atb":[[8,4.97],[10,2.57]],"id":52272946},{"atb":[[1.84,41.48],[1.94,24.7]],"id":55943164},{"atl":[[8.2,0.07]],"id":55943164},{"atb":[[2.38,25.24],[2.58,14.7]],"id":54867443},{"atl":[[13.5,0.04]],"id":54867443}],"con":true,"img":false}]}
{"op":"mcm","clk":"11449586865","pt":1717311446123,"mc":[{"id":"1.229554911","rc":[{"atb":[[1.03,5.78]],"id":70003369},{"atl":[[990,0.85]],"id":70003369},{"atb":[[1.03,5.78]],"id":69033911},{"atl":[[990,0.85]],"id":69033911},{"atb":[[1.01,5824.62]],"id":69676139},{"atl":[[1000,0.85]],"id":69676139},{"atb":[[1.01,17.35]],"id":52272946},{"atl":[[1000,0.85]],"id":52272946},{"atb":[[1.01,17.35]],"id":55943164},{"atl":[[990,0.85]],"id":55943164},{"atb":[[1.01,17.35]],"id":54867443},{"atl":[[990,0.85]],"id":54867443}],"con":true,"img":false}]}
{"op":"mcm","clk":"11449637269","pt":1717312502671,"mc":[{"id":"1.229554911","rc":[{"atb":[[1.96,0],[1.86,0]],"id":70003369},{"atl":[[8.4,0]],"id":70003369},{"spn":495.51,"spf":"NaN","id":70003369},{"atb":[[2.38,0],[2.58,0]],"id":69033911},{"atl":[[13.5,0]],"id":69033911},{"spn":495.51,"spf":"NaN","id":69033911},{"atb":[[1.01,17.35]],"id":69676139},{"atl":[[2.78,0]],"id":69676139},{"spn":500.5,"spf":"NaN","id":69676139},{"atb":[[8,0],[10,0]],"id":52272946},{"spn":500.5,"spf":"NaN","id":52272946},{"atb":[[1.84,0],[1.94,0]],"id":55943164},{"atl":[[8.2,0]],"id":55943164},{"spn":495.5,"spf":"NaN","id":55943164},{"atb":[[2.38,0],[2.58,0]],"id":54867443},{"atl":[[13.5,0]],"id":54867443},{"spn":495.5,"spf":"NaN","id":54867443}],"con":true,"img":false}]}
{"op":"mcm","clk":"11449637957","pt":1717312518476,"mc":[{"id":"1.229554911","rc":[{"atb":[[1.84,41.48],[1.94,24.7]],"id":70003369},{"atl":[[8.2,0.07]],"id":70003369},{"atb":[[2.56,14.88],[2.36,25.61]],"id":69033911},{"atl":[[15.5,0.03]],"id":69033911},{"atb":[[1.01,5824.62]],"id":69676139},{"atl":[[2.8,0.29]],"id":69676139},{"atb":[[8.6,4.58],[11.5,2.21]],"id":52272946},{"atb":[[1.8,43.55],[1.9,25.8]],"id":55943164},{"atl":[[8,0.07]],"id":55943164},{"atb":[[2.4,24.88],[2.6,14.51]],"id":54867443},{"atl":[[16.5,0.03]],"id":54867443}],"con":true,"img":false}]}
{"op":"mcm","clk":"11449693423","pt":1717313604619,"mc":[{"id":"1.229554911","rc":[{"atb":[[1.84,0],[1.94,0]],"id":70003369},{"atl":[[8.2,0]],"id":70003369},{"atb":[[2.56,0],[2.36,0]],"id":69033911},{"atl":[[15.5,0]],"id":69033911},{"atb":[[1.01,17.35]],"id":69676139},{"atl":[[2.8,0]],"id":69676139},{"atb":[[8.6,0],[11.5,0]],"id":52272946},{"atb":[[1.8,0],[1.9,0]],"id":55943164},{"atl":[[8,0]],"id":55943164},{"atb":[[2.4,0],[2.6,0]],"id":54867443},{"atl":[[16.5,0]],"id":54867443}],"con":true,"img":false}]}
{"op":"mcm","clk":"11449695107","pt":1717313624185,"mc":[{"id":"1.229554911","rc":[{"atb":[[1.84,41.48],[1.94,24.7]],"id":70003369},{"atl":[[8.2,0.07]],"id":70003369},{"atb":[[2.4,24.88],[2.6,14.51]],"id":69033911},{"atl":[[16.5,0.03]],"id":69033911},{"atb":[[1.01,5824.62]],"id":69676139},{"atl":[[2.8,0.29]],"id":69676139},{"atb":[[11,2.32],[8.4,4.7]],"id":52272946},{"atb":[[1.82,42.49],[1.92,25.24]],"id":55943164},{"atl":[[8,0.07]],"id":55943164},{"atb":[[2.54,15.08],[2.34,26]],"id":54867443},{"atl":[[15,0.03]],"id":54867443}],"con":true,"img":false}]}
{"op":"mcm","clk":"11449703767","pt":1717313733941,"mc":[{"id":"1.229554911","rc":[{"spn":5.07,"spf":"NaN","id":70003369},{"spn":9.55,"spf":"NaN","id":69033911},{"spn":1.9,"spf":"NaN","id":69676139},{"atb":[[11,0],[8.4,0]],"id":52272946},{"spn":4.96,"spf":"NaN","id":55943164},{"spn":8.77,"spf":"NaN","id":54867443}],"con":true,"img":false}]}
{"op":"mcm","clk":"11449705292","pt":1717313752611,"mc":[{"id":"1.229554911","rc":[{"atb":[[10.5,2.44],[8.2,4.83]],"id":52272946}],"con":true,"img":false}]}
{"op":"mcm","clk":"11449766650","pt":1717314431784,"mc":[{"id":"1.229554911","rc":[{"atb":[[1.84,0],[1.94,0]],"id":70003369},{"atl":[[8.2,0]],"id":70003369},{"spn":495.51,"spf":"NaN","id":70003369},{"atb":[[2.4,0],[2.6,0]],"id":69033911},{"atl":[[16.5,0]],"id":69033911},{"spn":495.51,"spf":"NaN","id":69033911},{"atb":[[1.01,17.35]],"id":69676139},{"atl":[[2.8,0]],"id":69676139},{"spn":500.5,"spf":"NaN","id":69676139},{"atb":[[10.5,0],[8.2,0]],"id":52272946},{"atb":[[1.82,0],[1.92,0]],"id":55943164},{"atl":[[8,0]],"id":55943164},{"spn":495.5,"spf":"NaN","id":55943164},{"atb":[[2.54,0],[2.34,0]],"id":54867443},{"atl":[[15,0]],"id":54867443},{"spn":495.5,"spf":"NaN","id":54867443}],"con":true,"img":false}]}
{"op":"mcm","clk":"11449767940","pt":1717314446074,"mc":[{"id":"1.229554911","rc":[{"atb":[[1.83,41.97],[1.93,24.97]],"id":70003369},{"atl":[[8.2,0.07]],"id":70003369},{"atb":[[2.42,24.53],[2.62,14.34]],"id":69033911},{"atl":[[17,0.03]],"id":69033911},{"atb":[[1.01,5824.62]],"id":69676139},{"atl":[[2.8,0.29]],"id":69676139},{"atb":[[8.6,4.58],[11.5,2.21]],"id":52272946},{"atb":[[1.81,43.01],[1.91,25.52]],"id":55943164},{"atl":[[8,0.07]],"id":55943164},{"atb":[[2.56,14.88],[2.36,25.61]],"id":54867443},{"atl":[[15.5,0.03]],"id":54867443}],"con":true,"img":false}]}
{"op":"mcm","clk":"11449830305","pt":1717315128432,"mc":[{"id":"1.229554911","marketDefinition":{"bspMarket":true,"turnInPlayEnabled":false,"persistenceEnabled":false,"marketBaseRate":7.0,"eventId":"33318908","eventTypeId":"4339","numberOfWinners":2,"bettingType":"ODDS","marketType":"PLACE","marketTime":"2024-06-02T09:38:00.000Z","suspendTime":"2024-06-02T09:38:00.000Z","bspReconciled":false,"complete":true,"inPlay":false,"crossMatching":true,"runnersVoidable":false,"numberOfActiveRunners":6,"betDelay":0,"status":"OPEN","runners":[{"status":"ACTIVE","sortPriority":1,"id":69676139,"name":"1. Kilkerran"},{"status":"ACTIVE","sortPriority":2,"id":54867443,"name":"2. Pumpkin Party"},{"status":"ACTIVE","sortPriority":3,"id":52272946,"name":"3. Irish Gem"},{"status":"ACTIVE","sortPriority":4,"id":55943164,"name":"5. Lektra Ringo"},{"status":"ACTIVE","sortPriority":5,"id":70003369,"name":"6. Rickis Burner"},{"status":"ACTIVE","sortPriority":6,"id":69033911,"name":"7. Elegant Evie"}],"regulators":["MR_INT"],"venue":"Murray Bridge","countryCode":"AU","discountAllowed":true,"timezone":"Australia/Adelaide","openDate":"2024-06-02T08:21:00.000Z","version":5962327402,"name":"To Be Placed","eventName":"Murray Bridge (AUS) 2nd Jun"},"rc":[{"atb":[[1.83,41.97],[1.03,5.78],[1.93,24.97]],"id":70003369},{"atl":[[8.2,0.07],[990,0.85]],"id":70003369},{"spn":5.06,"spf":"NaN","id":70003369},{"atb":[[1.03,5.78],[2.42,24.53],[2.62,14.34]],"id":69033911},{"atl":[[17,0.03],[990,0.85]],"id":69033911},{"spn":9.81,"spf":"NaN","id":69033911},{"atb":[[1.01,5824.62]],"id":69676139},{"atl":[[2.8,0.29],[1000,0.85]],"id":69676139},{"spn":1.9,"spf":"NaN","id":69676139},{"atb":[[8.6,4.58],[1.01,17.35],[11.5,2.21]],"id":52272946},{"atl":[[1000,0.85]],"id":52272946},{"spn":505.75,"spf":"NaN","id":52272946},{"atb":[[1.01,17.35],[1.81,43.01],[1.91,25.52]],"id":55943164},{"atl":[[8,0.07],[990,0.85]],"id":55943164},{"spn":4.95,"spf":"NaN","id":55943164},{"atb":[[2.56,14.88],[2.36,25.61],[1.01,17.35]],"id":54867443},{"atl":[[990,0.85],[15.5,0.03]],"id":54867443},{"spn":9.03,"spf":"NaN","id":54867443}],"con":true,"img":true}]}
{"op":"mcm","clk":"11449851214","pt":1717315295788,"mc":[{"id":"1.229554911","rc":[{"atb":[[1.83,0],[1.93,0]],"id":70003369},{"atl":[[8.2,0]],"id":70003369},{"atb":[[2.42,0],[2.62,0]],"id":69033911},{"atl":[[17,0]],"id":69033911},{"atb":[[1.01,17.35]],"id":69676139},{"atl":[[2.8,0]],"id":69676139},{"atb":[[8.6,0],[11.5,0]],"id":52272946},{"atb":[[1.81,0],[1.91,0]],"id":55943164},{"atl":[[8,0]],"id":55943164},{"atb":[[2.56,0],[2.36,0]],"id":54867443},{"atl":[[15.5,0]],"id":54867443}],"con":true,"img":false}]}
{"op":"mcm","clk":"11449853607","pt":1717315320659,"mc":[{"id":"1.229554911","rc":[{"atb":[[1.79,44.1],[1.89,26.1]],"id":70003369},{"atl":[[7.8,0.07]],"id":70003369},{"atb":[[2.42,24.53],[2.62,14.34]],"id":69033911},{"atl":[[17,0.03]],"id":69033911},{"atb":[[1.01,5824.62]],"id":69676139},{"atl":[[2.82,0.28]],"id":69676139},{"atb":[[8.6,4.58],[11.5,2.21]],"id":52272946},{"atb":[[1.79,44.1],[1.89,26.1]],"id":55943164},{"atl":[[7.8,0.07]],"id":55943164},{"atb":[[2.42,24.53],[2.62,14.34]],"id":54867443},{"atl":[[17,0.03]],"id":54867443}],"con":true,"img":false}]}
{"op":"mcm","clk":"11449936815","pt":1717316137829,"mc":[{"id":"1.229554911","rc":[{"atb":[[1.79,0],[1.89,0]],"id":70003369},{"atl":[[7.8,0]],"id":70003369},{"atb":[[2.42,0],[2.62,0]],"id":69033911},{"atl":[[17,0]],"id":69033911},{"atb":[[1.01,17.35]],"id":69676139},{"atl":[[2.82,0]],"id":69676139},{"atb":[[8.6,0],[11.5,0]],"id":52272946},{"atb":[[1.79,0],[1.89,0]],"id":55943164},{"atl":[[7.8,0]],"id":55943164},{"atb":[[2.42,0],[2.62,0]],"id":54867443},{"atl":[[17,0]],"id":54867443}],"con":true,"img":false}]}
{"op":"mcm","clk":"11449938382","pt":1717316154630,"mc":[{"id":"1.229554911","rc":[{"atb":[[1.85,40.99],[1.95,24.45]],"id":70003369},{"atl":[[8.2,0.07]],"id":70003369},{"atb":[[2.54,15.08],[2.34,26]],"id":69033911},{"atl":[[15,0.03]],"id":69033911},{"atb":[[1.01,5824.62]],"id":69676139},{"atl":[[2.8,0.29]],"id":69676139},{"atb":[[11,2.32],[8.4,4.7]],"id":52272946},{"atb":[[1.84,41.48],[1.94,24.7]],"id":55943164},{"atl":[[8.2,0.07]],"id":55943164},{"atb":[[2.56,14.88],[2.36,25.61]],"id":54867443},{"atl":[[15.5,0.03]],"id":54867443}],"con":true,"img":false}]}
{"op":"mcm","clk":"11449940403","pt":1717316175844,"mc":[{"id":"1.229554911","rc":[{"atb":[[1.64,45.77],[1.55,104.87]],"id":70003369},{"atl":[[12,3.8],[13,4.8]],"id":70003369},{"atb":[[1.95,64.87],[2.08,27.12]],"id":69033911},{"atl":[[20,2.61],[21,3.13]],"id":69033911},{"atb":[[1.12,525.26],[1.14,119.58]],"id":69676139},{"atl":[[4.2,13.07],[4.7,17.26]],"id":69676139},{"atb":[[2.8,23.24],[2.56,37.05]],"id":52272946},{"atl":[[520,0.07],[560,2.61]],"id":52272946},{"atb":[[1.57,51.4],[1.49,118.78]],"id":55943164},{"atl":[[11,4.18],[11.5,5.54]],"id":55943164},{"atb":[[1.98,29.89],[1.84,71.67]],"id":54867443},{"atl":[[18,2.61],[19,3.13]],"id":54867443}],"con":true,"img":false}]}
{"op":"mcm","clk":"11449941943","pt":1717316192286,"mc":[{"id":"1.229554911","rc":[{"atb":[[1.85,0],[1.95,0]],"id":70003369},{"atl":[[8.2,0]],"id":70003369},{"atb":[[1.84,0],[1.94,0]],"id":55943164},{"atl":[[8.2,0]],"id":55943164}],"con":true,"img":false}]}
{"op":"mcm","clk":"11449942954","pt":1717316203479,"mc":[{"id":"1.229554911","rc":[{"atb":[[1.82,42.49],[1.92,25.24]],"id":70003369},{"atl":[[8,0.07]],"id":70003369},{"spn":4.96,"spf":"NaN","id":70003369},{"spn":8.77,"spf":"NaN","id":69033911},{"spn":1.97,"spf":"NaN","id":69676139},{"spn":265.5,"spf":"NaN","id":52272946},{"atb":[[1.8,43.55],[1.9,25.8]],"id":55943164},{"atl":[[8,0.07]],"id":55943164},{"spn":4.95,"spf":"NaN","id":55943164},{"spn":9.03,"spf":"NaN","id":54867443}],"con":true,"img":false}]}
{"op":"mcm","clk":"11449946092","pt":1717316237917,"mc":[{"id":"1.229554911","rc":[{"atb":[[1.64,0],[1.93,31.5]],"id":70003369},{"atb":[[2.08,0]],"id":69033911},{"atb":[[2.8,0],[17.5,2.61]],"id":52272946},{"atb":[[1.57,0],[1.91,32.19]],"id":55943164}],"con":true,"img":false}]}
{"op":"mcm","clk":"11449946099","pt":1717316238012,"mc":[{"id":"1.229554911","rc":[{"atb":[[2.36,27.12]],"id":69033911}],"con":true,"img":false}]}
{"op":"mcm","clk":"11449948499","pt":1717316263861,"mc":[{"id":"1.229554911","rc":[{"spn":4.96,"spf":"NaN","id":70003369},{"atb":[[2.56,0],[15,4.12]],"id":52272946},{"spn":268.75,"spf":"NaN","id":52272946},{"spn":4.95,"spf":"NaN","id":55943164}],"con":true,"img":false}]}
{"op":"mcm","clk":"11449952777","pt":1717316315323,"mc":[{"id":"1.229554911","rc":[{"atb":[[2.36,0]],"id":69033911}],"con":true,"img":false}]}
{"op":"mcm","clk":"11449952782","pt":1717316315424,"mc":[{"id":"1.229554911","rc":[{"atb":[[2.56,27.12]],"id":69033911}],"con":true,"img":false}]}
{"op":"mcm","clk":"11450003947","pt":1717316992140,"mc":[{"id":"1.229554911","rc":[{"atb":[[1.82,0],[1.92,0]],"id":70003369},{"atl":[[8,0]],"id":70003369},{"spn":6.96,"spf":"NaN","id":70003369},{"atb":[[2.54,0],[2.34,0]],"id":69033911},{"atl":[[15,0]],"id":69033911},{"spn":11.28,"spf":"NaN","id":69033911},{"atb":[[1.01,17.35]],"id":69676139},{"atl":[[2.8,0]],"id":69676139},{"spn":2.67,"spf":"NaN","id":69676139},{"atb":[[11,0],[8.4,0]],"id":52272946},{"atb":[[1.8,0],[1.9,0]],"id":55943164},{"atl":[[8,0]],"id":55943164},{"spn":6.45,"spf":"NaN","id":55943164},{"atb":[[2.56,0],[2.36,0]],"id":54867443},{"atl":[[15.5,0]],"id":54867443},{"spn":9.99,"spf":"NaN","id":54867443}],"con":true,"img":false}]}
{"op":"mcm","clk":"11450004650","pt":1717317000462,"mc":[{"id":"1.229554911","rc":[{"atb":[[1.63,46.5],[1.93,0]],"id":70003369},{"atb":[[2.56,0]],"id":69033911},{"atb":[[1.57,51.4],[1.91,0]],"id":55943164}],"con":true,"img":false}]}
{"op":"mcm","clk":"11450004661","pt":1717317000567,"mc":[{"id":"1.229554911","rc":[{"atb":[[2.08,27.12]],"id":69033911}],"con":true,"img":false}]}
{"op":"mcm","clk":"11450006456","pt":1717317018448,"mc":[{"id":"1.229554911","rc":[{"atb":[[1.83,41.97],[1.93,24.97]],"id":70003369},{"atl":[[8.2,0.07]],"id":70003369},{"atb":[[2.4,24.88],[2.6,14.51]],"id":69033911},{"atl":[[16.5,0.03]],"id":69033911},{"atb":[[1.01,5824.62]],"id":69676139},{"atl":[[2.8,0.29]],"id":69676139},{"atb":[[11,2.32],[8.4,4.7]],"id":52272946},{"atb":[[1.81,43.01],[1.91,25.52]],"id":55943164},{"atl":[[8,0.07]],"id":55943164},{"atb":[[2.38,25.24],[2.58,14.7]],"id":54867443},{"atl":[[13.5,0.04]],"id":54867443}],"con":true,"img":false}]}
{"op":"mcm","clk":"11450011242","pt":1717317066921,"mc":[{"id":"1.229554911","rc":[{"atb":[[1.63,0],[1.94,31.16]],"id":70003369},{"spn":5.07,"spf":"NaN","id":70003369},{"atb":[[2.08,0]],"id":69033911},{"spn":9.55,"spf":"NaN","id":69033911},{"spn":1.97,"spf":"NaN","id":69676139},{"atb":[[1.92,31.84],[1.57,0]],"id":55943164},{"spn":4.96,"spf":"NaN","id":55943164},{"spn":8.04,"spf":"NaN","id":54867443}],"con":true,"img":false}]}
{"op":"mcm","clk":"11450011248","pt":1717317067026,"mc":[{"id":"1.229554911","rc":[{"atb":[[2.62,27.12]],"id":69033911}],"con":true,"img":false}]}
{"op":"mcm","clk":"11450053404","pt":1717317480394,"mc":[{"id":"1.229554911","rc":[{"atl":[[11.5,3.8]],"id":70003369},{"atb":[[1.22,52.02]],"id":69033911},{"atl":[[20,5.23]],"id":69033911},{"spn":9.56,"spf":"NaN","id":69033911},{"atl":[[4.5,13.37]],"id":69676139},{"atb":[[8.4,15.74]],"id":52272946},{"atl":[[10.5,4.19]],"id":55943164},{"atb":[[1.22,55.14]],"id":54867443},{"atl":[[18,5.23]],"id":54867443}],"con":true,"img":false}]}
{"op":"mcm","clk":"11450059053","pt":1717317544634,"mc":[{"id":"1.229554911","rc":[{"atl":[[21,0]],"id":69033911},{"atl":[[4.7,0]],"id":69676139},{"atl":[[19,0]],"id":54867443}],"con":true,"img":false}]}
{"op":"mcm","clk":"11450059063","pt":1717317544734,"mc":[{"id":"1.229554911","rc":[{"atl":[[19.5,3.13]],"id":69033911},{"atl":[[4.4,17.26]],"id":69676139},{"atl":[[17.5,3.13]],"id":54867443}],"con":true,"img":false}]}
{"op":"mcm","clk":"11450059073","pt":1717317544837,"mc":[{"id":"1.229554911","rc":[{"atl":[[19,3.14]],"id":69033911},{"atl":[[17,3.14]],"id":54867443}],"con":true,"img":false}]}
{"op":"mcm","clk":"11450059081","pt":1717317544943,"mc":[{"id":"1.229554911","rc":[{"atl":[[20,2.61]],"id":69033911},{"atl":[[18,2.61]],"id":54867443}],"con":true,"img":false}]}
{"op":"mcm","clk":"11450063267","pt":1717317590697,"mc":[{"id":"1.229554911","rc":[{"atl":[[20,0]],"id":69033911},{"atl":[[18,0]],"id":54867443}],"con":true,"img":false}]}
{"op":"mcm","clk":"11450063278","pt":1717317590799,"mc":[{"id":"1.229554911","rc":[{"atl":[[18.5,2.61]],"id":69033911},{"atl":[[16.5,2.61]],"id":54867443}],"con":true,"img":false}]}
{"op":"mcm","clk":"11450063879","pt":1717317597594,"mc":[{"id":"1.229554911","rc":[{"atb":[[1.83,0],[1.93,0]],"id":70003369},{"atl":[[8.2,0]],"id":70003369},{"atb":[[2.4,0],[2.6,0]],"id":69033911},{"atl":[[16.5,0]],"id":69033911},{"atb":[[1.01,17.35]],"id":69676139},{"atl":[[2.8,0]],"id":69676139},{"atb":[[11,0],[8.4,11.04]],"id":52272946},{"atb":[[1.81,0],[1.91,0]],"id":55943164},{"atl":[[8,0]],"id":55943164},{"atb":[[2.38,0],[2.58,0]],"id":54867443},{"atl":[[13.5,0]],"id":54867443}],"con":true,"img":false}]}
{"op":"mcm","clk":"11450064067","pt":1717317599892,"mc":[{"id":"1.229554911","rc":[{"atb":[[1.63,46.5],[1.94,0]],"id":70003369},{"atb":[[2.62,0]],"id":69033911},{"atl":[[19.5,0]],"id":69033911},{"atb":[[1.92,0],[1.58,50.51]],"id":55943164},{"atl":[[17.5,0]],"id":54867443}],"con":true,"img":false}]}
{"op":"mcm","clk":"11450064074","pt":1717317599998,"mc":[{"id":"1.229554911","rc":[{"atb":[[2.08,27.12]],"id":69033911},{"atl":[[18.5,5.75]],"id":69033911},{"atl":[[16.5,5.75]],"id":54867443}],"con":true,"img":false}]}
{"op":"mcm","clk":"11450064092","pt":1717317600204,"mc":[{"id":"1.229554911","rc":[{"atl":[[18,3.14],[19,0]],"id":69033911},{"atl":[[16,3.14],[17,0]],"id":54867443}],"con":true,"img":false}]}
{"op":"mcm","clk":"11450064906","pt":1717317609224,"mc":[{"id":"1.229554911","rc":[{"spn":6.56,"spf":"NaN","id":70003369},{"atl":[[18.5,2.61]],"id":69033911},{"spn":10.04,"spf":"NaN","id":69033911},{"spn":2.67,"spf":"NaN","id":69676139},{"spn":6.04,"spf":"NaN","id":55943164},{"atl":[[16.5,2.61]],"id":54867443},{"spn":8.99,"spf":"NaN","id":54867443}],"con":true,"img":false}]}
{"op":"mcm","clk":"11450064918","pt":1717317609327,"mc":[{"id":"1.229554911","rc":[{"atl":[[21,3.13]],"id":69033911},{"atl":[[19,3.13]],"id":54867443}],"con":true,"img":false}]}
{"op":"mcm","clk":"11450064928","pt":1717317609431,"mc":[{"id":"1.229554911","rc":[{"atl":[[18,0],[18.5,8.32]],"id":69033911},{"atl":[[16,0],[16.5,8.89]],"id":54867443}],"con":true,"img":false}]}
{"op":"mcm","clk":"11450065148","pt":1717317611918,"mc":[{"id":"1.229554911","rc":[{"atb":[[1.96,24.19],[1.86,40.51]],"id":70003369},{"atl":[[8.4,0.07]],"id":70003369},{"atb":[[2.64,14.16],[2.44,24.19]],"id":69033911},{"atl":[[17.5,0.03]],"id":69033911},{"atb":[[1.01,5824.62]],"id":69676139},{"atl":[[2.78,0.29]],"id":69676139},{"atb":[[10.5,2.44],[8.2,4.83]],"id":52272946},{"atb":[[1.79,44.1],[1.89,26.1]],"id":55943164},{"atl":[[7.8,0.07]],"id":55943164},{"atb":[[2.56,14.88],[2.36,25.61]],"id":54867443},{"atl":[[15.5,0.03]],"id":54867443}],"con":true,"img":false}]}
{"op":"mcm","clk":"11450069300","pt":1717317657411,"mc":[{"id":"1.229554911","rc":[{"atb":[[1.63,0],[1.97,30.2]],"id":70003369},{"atb":[[2.08,0]],"id":69033911},{"atb":[[1.58,0],[1.9,32.55]],"id":55943164},{"atb":[[1.98,0]],"id":54867443}],"con":true,"img":false}]}
{"op":"mcm","clk":"11450069313","pt":1717317657465,"mc":[{"id":"1.229554911","rc":[{"atb":[[2.46,27.12]],"id":69033911},{"atb":[[2.02,29.89]],"id":54867443}],"con":true,"img":false}]}
{"op":"mcm","clk":"11450070248","pt":1717317667380,"mc":[{"id":"1.229554911","rc":[{"atl":[[13,0]],"id":70003369},{"atl":[[21,0]],"id":69033911},{"atl":[[11.5,0]],"id":55943164},{"atl":[[16,4.18],[19,0]],"id":54867443}],"con":true,"img":false}]}
{"op":"mcm","clk":"11450070263","pt":1717317667483,"mc":[{"id":"1.229554911","rc":[{"atl":[[11,4.8]],"id":70003369},{"atl":[[18,3.13]],"id":69033911},{"atl":[[10,5.54]],"id":55943164},{"atl":[[16.5,2.61],[15.5,4.22]],"id":54867443}],"con":true,"img":false}]}
{"op":"mcm","clk":"11450070271","pt":1717317667586,"mc":[{"id":"1.229554911","rc":[{"atl":[[10.5,3.8],[11.5,0]],"id":70003369},{"atl":[[17.5,3.17],[18.5,2.61]],"id":69033911},{"atl":[[10.5,0],[9.8,4.19]],"id":55943164}],"con":true,"img":false}]}
{"op":"mcm","clk":"11450071214","pt":1717317677400,"mc":[{"id":"1.229554911","rc":[{"atl":[[11,0]],"id":70003369},{"spn":5.18,"spf":"NaN","id":70003369},{"atl":[[18,0]],"id":69033911},{"spn":10.07,"spf":"NaN","id":69033911},{"spn":1.96,"spf":"NaN","id":69676139},{"atl":[[10,0]],"id":55943164},{"spn":4.85,"spf":"NaN","id":55943164},{"atl":[[16,0],[19,3.13]],"id":54867443},{"spn":9.03,"spf":"NaN","id":54867443}],"con":true,"img":false}]}
{"op":"mcm","clk":"11450071222","pt":1717317677500,"mc":[{"id":"1.229554911","rc":[{"atl":[[12.5,4.8]],"id":70003369},{"atl":[[18.5,8.32],[20,3.13]],"id":69033911},{"atl":[[11.5,5.54]],"id":55943164},{"atl":[[16.5,9.06]],"id":54867443}],"con":true,"img":false}]}
{"op":"mcm","clk":"11450071232","pt":1717317677603,"mc":[{"id":"1.229554911","rc":[{"atl":[[65,2],[17.5,0.03],[18.5,2.61]],"id":69033911},{"atl":[[16.5,2.61],[18.5,5.71],[15.5,0.03]],"id":54867443}],"con":true,"img":false}]}
{"op":"mcm","clk":"11450073107","pt":1717317697435,"mc":[{"id":"1.229554911","rc":[{"atb":[[2.46,0]],"id":69033911}],"con":true,"img":false}]}
{"op":"mcm","clk":"11450073117","pt":1717317697538,"mc":[{"id":"1.229554911","rc":[{"atb":[[2.66,27.12]],"id":69033911}],"con":true,"img":false}]}
{"op":"mcm","clk":"11450074451","pt":1717317712736,"mc":[{"id":"1.229554911","rc":[{"atl":[[18.5,5.23]],"id":69033911}],"con":true,"img":false}]}
{"op":"mcm","clk":"11450074458","pt":1717317712838,"mc":[{"id":"1.229554911","rc":[{"atl":[[65,0],[18.5,2.61],[19.5,2.65]],"id":69033911}],"con":true,"img":false}]}
{"op":"mcm","clk":"11450074474","pt":1717317713046,"mc":[{"id":"1.229554911","rc":[{"atl":[[18.5,5.26],[19.5,0]],"id":69033911}],"con":true,"img":false}]}
{"op":"mcm","clk":"11450076804","pt":1717317738275,"mc":[{"id":"1.229554911","rc":[{"spn":10.08,"spf":"NaN","id":69033911},{"atl":[[19,0]],"id":54867443}],"con":true,"img":false}]}
{"op":"mcm","clk":"11450076816","pt":1717317738377,"mc":[{"id":"1.229554911","rc":[{"atl":[[18,3.13]],"id":54867443}],"con":true,"img":false}]}
{"op":"mcm","clk":"11450076827","pt":1717317738482,"mc":[{"id":"1.229554911","rc":[{"atl":[[16.5,5.23],[18.5,0]],"id":54867443}],"con":true,"img":false}]}
{"op":"mcm","clk":"11450079448","pt":1717317766939,"mc":[{"id":"1.229554911","rc":[{"atl":[[20,0]],"id":69033911}],"con":true,"img":false}]}
{"op":"mcm","clk":"11450079456","pt":1717317767039,"mc":[{"id":"1.229554911","rc":[{"atl":[[18,3.13]],"id":69033911}],"con":true,"img":false}]}
{"op":"mcm","clk":"11450079463","pt":1717317767140,"mc":[{"id":"1.229554911","rc":[{"atl":[[17.5,3.17]],"id":69033911}],"con":true,"img":false}]}
{"op":"mcm","clk":"11450079470","pt":1717317767243,"mc":[{"id":"1.229554911","rc":[{"atl":[[18.5,2.61]],"id":69033911}],"con":true,"img":false}]}
{"op":"mcm","clk":"11450080681","pt":1717317781055,"mc":[{"id":"1.229554911","rc":[{"atl":[[18,0]],"id":69033911}],"con":true,"img":false}]}
{"op":"mcm","clk":"11450080692","pt":1717317781163,"mc":[{"id":"1.229554911","rc":[{"atl":[[18.5,8.32],[20,3.13]],"id":69033911}],"con":true,"img":false}]}
{"op":"mcm","clk":"11450080700","pt":1717317781265,"mc":[{"id":"1.229554911","rc":[{"atl":[[65,2],[17.5,0.03],[18.5,2.61]],"id":69033911}],"con":true,"img":false}]}
{"op":"mcm","clk":"11450083196","pt":1717317810925,"mc":[{"id":"1.229554911","rc":[{"atb":[[1.87,4.89]],"id":54867443}],"con":true,"img":false}]}
{"op":"mcm","clk":"11450083239","pt":1717317811393,"mc":[{"id":"1.229554911","rc":[{"atb":[[1.57,7.47]],"id":70003369}],"con":true,"img":false}]}
{"op":"mcm","clk":"11450083272","pt":1717317811834,"mc":[{"id":"1.229554911","rc":[{"atb":[[1.99,4.3]],"id":69033911}],"con":true,"img":false}]}
{"op":"mcm","clk":"11450083311","pt":1717317812402,"mc":[{"id":"1.229554911","rc":[{"atb":[[1.51,8.35]],"id":55943164}],"con":true,"img":false}]}
{"op":"mcm","clk":"11450083536","pt":1717317815349,"mc":[{"id":"1.229554911","rc":[{"atl":[[18.5,5.23]],"id":69033911}],"con":true,"img":false}]}
{"op":"mcm","clk":"11450083547","pt":1717317815400,"mc":[{"id":"1.229554911","rc":[{"atl":[[65,0]],"id":69033911}],"con":true,"img":false}]}
{"op":"mcm","clk":"11450087647","pt":1717317864288,"mc":[{"id":"1.229554911","rc":[{"atl":[[20,0]],"id":69033911}],"con":true,"img":false}]}
{"op":"mcm","clk":"11450087657","pt":1717317864348,"mc":[{"id":"1.229554911","rc":[{"atl":[[18,3.13]],"id":69033911}],"con":true,"img":false}]}
{"op":"mcm","clk":"11450087666","pt":1717317864453,"mc":[{"id":"1.229554911","rc":[{"atl":[[17.5,3.17],[18.5,2.61]],"id":69033911}],"con":true,"img":false}]}
{"op":"mcm","clk":"11450088094","pt":1717317869464,"mc":[{"id":"1.229554911","rc":[{"atl":[[8.6,1.6]],"id":55943164}],"con":true,"img":false}]}
{"op":"mcm","clk":"11450088104","pt":1717317869568,"mc":[{"id":"1.229554911","rc":[{"atl":[[8.6,5.79],[9.8,0]],"id":55943164}],"con":true,"img":false}]}
{"op":"mcm","clk":"11450088113","pt":1717317869673,"mc":[{"id":"1.229554911","rc":[{"atl":[[9.8,4.19]],"id":55943164}],"con":true,"img":false}]}
{"op":"mcm","clk":"11450088120","pt":1717317869776,"mc":[{"id":"1.229554911","rc":[{"atl":[[8.6,1.59]],"id":55943164}],"con":true,"img":false}]}
{"op":"mcm","clk":"11450088726","pt":1717317876403,"mc":[{"id":"1.229554911","rc":[{"atl":[[18,0]],"id":69033911}],"con":true,"img":false}]}
{"op":"mcm","clk":"11450088737","pt":1717317876497,"mc":[{"id":"1.229554911","rc":[{"atl":[[17.5,0.03],[18.5,8.32],[21,3.13]],"id":69033911}],"con":true,"img":false}]}
{"op":"mcm","clk":"11450091104","pt":1717317902920,"mc":[{"id":"1.229554911","rc":[{"atl":[[8.6,5.79],[9.8,0]],"id":55943164}],"con":true,"img":false}]}
{"op":"mcm","clk":"11450091112","pt":1717317903023,"mc":[{"id":"1.229554911","rc":[{"atl":[[8.6,1.59],[9.8,4.19]],"id":55943164}],"con":true,"img":false}]}
{"op":"mcm","clk":"11450091139","pt":1717317903288,"mc":[{"id":"1.229554911","rc":[{"atl":[[11,0]],"id":55943164}],"con":true,"img":false}]}
{"op":"mcm","clk":"11450091152","pt":1717317903437,"mc":[{"id":"1.229554911","rc":[{"atl":[[9.6,4.18],[8.6,5.79]],"id":55943164}],"con":true,"img":false}]}
{"op":"mcm","clk":"11450091164","pt":1717317903491,"mc":[{"id":"1.229554911","rc":[{"atl":[[9.8,0]],"id":55943164}],"con":true,"img":false}]}
{"op":"mcm","clk":"11450091203","pt":1717317904007,"mc":[{"id":"1.229554911","rc":[{"atb":[[1.94,4.17]],"id":55943164},{"atb":[[2.42,2.76]],"id":54867443}],"con":true,"img":false}]}
{"op":"mcm","clk":"11450091219","pt":1717317904214,"mc":[{"id":"1.229554911","rc":[{"atb":[[2,3.92]],"id":70003369},{"atb":[[1.01,2.35]],"id":69033911}],"con":true,"img":false}]}
{"op":"mcm","clk":"11450091536","pt":1717317907520,"mc":[{"id":"1.229554911","rc":[{"atb":[[1.01,2.28]],"id":69033911}],"con":true,"img":false}]}
{"op":"mcm","clk":"11450091620","pt":1717317908606,"mc":[{"id":"1.229554911","rc":[{"atb":[[1.01,0]],"id":69033911}],"con":true,"img":false}]}
{"op":"mcm","clk":"11450091630","pt":1717317908713,"mc":[{"id":"1.229554911","rc":[{"atb":[[2.72,2.28]],"id":69033911}],"con":true,"img":false}]}
{"op":"mcm","clk":"11450091986","pt":1717317913059,"mc":[{"id":"1.229554911","rc":[{"atl":[[9.6,0]],"id":55943164}],"con":true,"img":false}]}
{"op":"mcm","clk":"11450091993","pt":1717317913109,"mc":[{"id":"1.229554911","rc":[{"atl":[[11,4.18]],"id":55943164}],"con":true,"img":false}]}
{"op":"mcm","clk":"11450094086","pt":1717317935570,"mc":[{"id":"1.229554911","rc":[{"atl":[[21,0]],"id":69033911}],"con":true,"img":false}]}
{"op":"mcm","clk":"11450094097","pt":1717317935627,"mc":[{"id":"1.229554911","rc":[{"atl":[[18,3.13]],"id":69033911}],"con":true,"img":false}]}
{"op":"mcm","clk":"11450094104","pt":1717317935727,"mc":[{"id":"1.229554911","rc":[{"atl":[[17.5,3.17],[18.5,2.61]],"id":69033911}],"con":true,"img":false}]}
{"op":"mcm","clk":"11450094850","pt":1717317944440,"mc":[{"id":"1.229554911","rc":[{"spn":5.2,"spf":"NaN","id":70003369},{"atl":[[18,0]],"id":69033911},{"spn":10.11,"spf":"NaN","id":69033911},{"spn":4.87,"spf":"NaN","id":55943164}],"con":true,"img":false}]}
{"op":"mcm","clk":"11450094860","pt":1717317944540,"mc":[{"id":"1.229554911","rc":[{"atl":[[20,3.13]],"id":69033911}],"con":true,"img":false}]}
{"op":"mcm","clk":"11450094869","pt":1717317944647,"mc":[{"id":"1.229554911","rc":[{"atl":[[17.5,0.03],[18.5,8.32]],"id":69033911}],"con":true,"img":false}]}
{"op":"mcm","clk":"11450094878","pt":1717317944755,"mc":[{"id":"1.229554911","rc":[{"atl":[[18.5,2.61],[19.5,5.41]],"id":69033911}],"con":true,"img":false}]}
{"op":"mcm","clk":"11450097562","pt":1717317977182,"mc":[{"id":"1.229554911","rc":[{"atl":[[18.5,5.75],[19.5,0]],"id":69033911}],"con":true,"img":false}]}
{"op":"mcm","clk":"11450097575","pt":1717317977286,"mc":[{"id":"1.229554911","rc":[{"atl":[[18.5,2.61],[19.5,3.14]],"id":69033911}],"con":true,"img":false}]}
{"op":"mcm","clk":"11450097584","pt":1717317977390,"mc":[{"id":"1.229554911","rc":[{"atl":[[18.5,5.75]],"id":69033911}],"con":true,"img":false}]}
{"op":"mcm","clk":"11450097593","pt":1717317977489,"mc":[{"id":"1.229554911","rc":[{"atl":[[19.5,0]],"id":69033911}],"con":true,"img":false}]}
{"op":"mcm","clk":"11450099366","pt":1717317998819,"mc":[{"id":"1.229554911","rc":[{"atl":[[20,0]],"id":69033911}],"con":true,"img":false}]}
{"op":"mcm","clk":"11450099375","pt":1717317998921,"mc":[{"id":"1.229554911","rc":[{"atl":[[18,3.13]],"id":69033911}],"con":true,"img":false}]}
{"op":"mcm","clk":"11450100258","pt":1717318009532,"mc":[{"id":"1.229554911","rc":[{"atl":[[17.5,3.17]],"id":69033911}],"con":true,"img":false}]}
{"op":"mcm","clk":"11450100265","pt":1717318009630,"mc":[{"id":"1.229554911","rc":[{"atl":[[18.5,2.61]],"id":69033911}],"con":true,"img":false}]}
{"op":"mcm","clk":"11450101971","pt":1717318029362,"mc":[{"id":"1.229554911","rc":[{"atl":[[18,0]],"id":69033911}],"con":true,"img":false}]}
{"op":"mcm","clk":"11450101979","pt":1717318029462,"mc":[{"id":"1.229554911","rc":[{"atl":[[18.5,8.32],[20,3.13]],"id":69033911}],"con":true,"img":false}]}
{"op":"mcm","clk":"11450101985","pt":1717318029565,"mc":[{"id":"1.229554911","rc":[{"atl":[[65,2],[17.5,0.03],[18.5,2.61]],"id":69033911}],"con":true,"img":false}]}
{"op":"mcm","clk":"11450104568","pt":1717318056990,"mc":[{"id":"1.229554911","rc":[{"atl":[[11,0]],"id":55943164}],"con":true,"img":false}]}
{"op":"mcm","clk":"11450104580","pt":1717318057091,"mc":[{"id":"1.229554911","rc":[{"atl":[[8.4,4.18]],"id":55943164}],"con":true,"img":false}]}
{"op":"mcm","clk":"11450104587","pt":1717318057191,"mc":[{"id":"1.229554911","rc":[{"atl":[[8.2,5.55]],"id":55943164}],"con":true,"img":false}]}
{"op":"mcm","clk":"11450104600","pt":1717318057293,"mc":[{"id":"1.229554911","rc":[{"atl":[[8.6,1.59]],"id":55943164}],"con":true,"img":false}]}
{"op":"mcm","clk":"11450104888","pt":1717318060311,"mc":[{"id":"1.229554911","rc":[{"atb":[[1.96,0],[1.86,0]],"id":70003369},{"atl":[[8.4,0]],"id":70003369},{"atb":[[2.64,0],[2.44,0]],"id":69033911},{"atl":[[17.5,0]],"id":69033911},{"atb":[[1.01,17.35]],"id":69676139},{"atl":[[2.78,0]],"id":69676139},{"atb":[[10.5,0],[8.2,0]],"id":52272946},{"atb":[[1.79,0],[1.89,0]],"id":55943164},{"atl":[[7.8,0]],"id":55943164},{"atb":[[2.56,0],[2.36,0]],"id":54867443},{"atl":[[15.5,0]],"id":54867443}],"con":true,"img":false}]}
{"op":"mcm","clk":"11450104907","pt":1717318060524,"mc":[{"id":"1.229554911","rc":[{"atl":[[10.5,0],[11.5,7.6]],"id":70003369}],"con":true,"img":false}]}
{"op":"mcm","clk":"11450104963","pt":1717318061201,"mc":[{"id":"1.229554911","rc":[{"atl":[[65,0],[18.5,5.23]],"id":69033911}],"con":true,"img":false}]}
{"op":"mcm","clk":"11450105831","pt":1717318070326,"mc":[{"id":"1.229554911","rc":[{"atb":[[1.63,46.5],[1.97,0]],"id":70003369},{"spn":6.75,"spf":"NaN","id":70003369},{"atb":[[2.66,0]],"id":69033911},{"spn":10.61,"spf":"NaN","id":69033911},{"spn":2.67,"spf":"NaN","id":69676139},{"atb":[[1.58,50.51],[1.9,0]],"id":55943164},{"spn":5.07,"spf":"NaN","id":55943164},{"spn":9.46,"spf":"NaN","id":54867443}],"con":true,"img":false}]}
{"op":"mcm","clk":"11450105840","pt":1717318070425,"mc":[{"id":"1.229554911","rc":[{"atb":[[2.08,27.12]],"id":69033911}],"con":true,"img":false}]}
{"op":"mcm","clk":"11450106651","pt":1717318078752,"mc":[{"id":"1.229554911","rc":[{"atb":[[1.97,23.94],[1.87,40.04]],"id":70003369},{"atl":[[8.4,0.07]],"id":70003369},{"atb":[[2.4,24.88],[2.6,14.51]],"id":69033911},{"atl":[[16.5,0.03]],"id":69033911},{"atb":[[1.01,5824.62]],"id":69676139},{"atl":[[2.8,0.29]],"id":69676139},{"atb":[[11,2.32],[8.4,15.74]],"id":52272946},{"atb":[[1.79,44.1],[1.89,26.1]],"id":55943164},{"atl":[[7.8,0.07]],"id":55943164},{"atb":[[2.38,25.24],[2.58,14.7]],"id":54867443},{"atl":[[13.5,0.04]],"id":54867443}],"con":true,"img":false}]}
{"op":"mcm","clk":"11450107400","pt":1717318087228,"mc":[{"id":"1.229554911","rc":[{"atb":[[2.42,0]],"id":54867443}],"con":true,"img":false}]}
{"op":"mcm","clk":"11450107425","pt":1717318087528,"mc":[{"id":"1.229554911","rc":[{"atb":[[2.44,2.72]],"id":54867443}],"con":true,"img":false}]}
{"op":"mcm","clk":"11450108361","pt":1717318098352,"mc":[{"id":"1.229554911","rc":[{"atl":[[12,0]],"id":70003369},{"atl":[[8,5.97],[8.4,0]],"id":55943164}],"con":true,"img":false}]}
{"op":"mcm","clk":"11450108369","pt":1717318098447,"mc":[{"id":"1.229554911","rc":[{"atl":[[11,3.8]],"id":70003369},{"atl":[[7.8,5.62]],"id":55943164}],"con":true,"img":false}]}
{"op":"mcm","clk":"11450108377","pt":1717318098550,"mc":[{"id":"1.229554911","rc":[{"atl":[[10.5,4.81],[11.5,0]],"id":70003369},{"atl":[[8.2,0]],"id":55943164}],"con":true,"img":false}]}
{"op":"mcm","clk":"11450108524","pt":1717318100361,"mc":[{"id":"1.229554911","rc":[{"atl":[[8.6,0]],"id":55943164}],"con":true,"img":false}]}
{"op":"mcm","clk":"11450109192","pt":1717318107770,"mc":[{"id":"1.229554911","rc":[{"atl":[[8,0],[11,4.18]],"id":55943164}],"con":true,"img":false}]}
{"op":"mcm","clk":"11450109203","pt":1717318107875,"mc":[{"id":"1.229554911","rc":[{"atl":[[10.5,10.53],[7.8,0.07]],"id":55943164}],"con":true,"img":false}]}
{"op":"mcm","clk":"11450110055","pt":1717318117581,"mc":[{"id":"1.229554911","rc":[{"atb":[[1.63,0],[1.98,29.89]],"id":70003369},{"atb":[[2.08,0]],"id":69033911},{"atl":[[20,0]],"id":69033911},{"atb":[[1.58,0],[1.9,32.55]],"id":55943164}],"con":true,"img":false}]}
{"op":"mcm","clk":"11450110064","pt":1717318117689,"mc":[{"id":"1.229554911","rc":[{"atb":[[2.62,27.12]],"id":69033911},{"atl":[[18,3.13]],"id":69033911}],"con":true,"img":false}]}
{"op":"mcm","clk":"11450110073","pt":1717318117787,"mc":[{"id":"1.229554911","rc":[{"atl":[[17.5,3.14],[18.5,2.61]],"id":69033911}],"con":true,"img":false}]}
{"op":"mcm","clk":"11450111288","pt":1717318132497,"mc":[{"id":"1.229554911","rc":[{"atb":[[2,0]],"id":70003369},{"spn":5.19,"spf":"NaN","id":70003369},{"spn":9.61,"spf":"NaN","id":69033911},{"spn":1.97,"spf":"NaN","id":69676139},{"spn":4.87,"spf":"NaN","id":55943164},{"spn":8.04,"spf":"NaN","id":54867443}],"con":true,"img":false}]}
{"op":"mcm","clk":"11450111305","pt":1717318132707,"mc":[{"id":"1.229554911","rc":[{"atb":[[2.02,3.84]],"id":70003369},{"atl":[[18,0]],"id":69033911}],"con":true,"img":false}]}
{"op":"mcm","clk":"11450111313","pt":1717318132807,"mc":[{"id":"1.229554911","rc":[{"atl":[[17.5,0],[18,3.17],[20,3.13]],"id":69033911}],"con":true,"img":false}]}
{"op":"mcm","clk":"11450112489","pt":1717318145209,"mc":[{"id":"1.229554911","rc":[{"atb":[[2.72,0]],"id":69033911},{"atb":[[1.94,0]],"id":55943164}],"con":true,"img":false}]}
{"op":"mcm","clk":"11450112724","pt":1717318147611,"mc":[{"id":"1.229554911","rc":[{"atb":[[1.01,2.35]],"id":69033911},{"atb":[[1.94,4.17]],"id":55943164}],"con":true,"img":false}]}
{"op":"mcm","clk":"11450112757","pt":1717318147921,"mc":[{"id":"1.229554911","rc":[{"atb":[[1.01,2.33]],"id":69033911}],"con":true,"img":false}]}
{"op":"mcm","clk":"11450112792","pt":1717318148245,"mc":[{"id":"1.229554911","rc":[{"atb":[[1.01,0]],"id":69033911}],"con":true,"img":false}]}
{"op":"mcm","clk":"11450112799","pt":1717318148289,"mc":[{"id":"1.229554911","rc":[{"atb":[[2.68,2.33]],"id":69033911}],"con":true,"img":false}]}
{"op":"mcm","clk":"11450113239","pt":1717318153014,"mc":[{"id":"1.229554911","rc":[{"atl":[[11,0]],"id":55943164}],"con":true,"img":false}]}
{"op":"mcm","clk":"11450113247","pt":1717318153114,"mc":[{"id":"1.229554911","rc":[{"atl":[[10,4.18]],"id":55943164}],"con":true,"img":false}]}
{"op":"mcm","clk":"11450113268","pt":1717318153323,"mc":[{"id":"1.229554911","rc":[{"atl":[[8.6,2.72],[10.5,0],[9.8,5.55]],"id":55943164}],"con":true,"img":false}]}
{"op":"mcm","clk":"11450114262","pt":1717318164148,"mc":[{"id":"1.229554911","rc":[{"atl":[[11,0]],"id":70003369},{"atl":[[18.5,0]],"id":69033911}],"con":true,"img":false}]}
{"op":"mcm","clk":"11450114272","pt":1717318164214,"mc":[{"id":"1.229554911","rc":[{"atl":[[10,3.8]],"id":70003369},{"atl":[[17.5,2.61],[19.5,3.2]],"id":69033911}],"con":true,"img":false}]}
{"op":"mcm","clk":"11450114279","pt":1717318164310,"mc":[{"id":"1.229554911","rc":[{"atl":[[18,0]],"id":69033911}],"con":true,"img":false}]}
{"op":"mcm","clk":"11450114291","pt":1717318164421,"mc":[{"id":"1.229554911","rc":[{"atl":[[10.5,0],[9.8,4.81]],"id":70003369}],"con":true,"img":false}]}
{"op":"mcm","clk":"11450115953","pt":1717318183733,"mc":[{"id":"1.229554911","rc":[{"atl":[[8.6,6.91],[9.8,0]],"id":55943164}],"con":true,"img":false}]}
{"op":"mcm","clk":"11450115993","pt":1717318184197,"mc":[{"id":"1.229554911","rc":[{"atl":[[10,0]],"id":70003369}],"con":true,"img":false}]}
{"op":"mcm","clk":"11450116002","pt":1717318184262,"mc":[{"id":"1.229554911","rc":[{"atl":[[12,3.8]],"id":70003369}],"con":true,"img":false}]}
{"op":"mcm","clk":"11450116010","pt":1717318184382,"mc":[{"id":"1.229554911","rc":[{"atl":[[12,8.68],[9.8,0]],"id":70003369}],"con":true,"img":false}]}
{"op":"mcm","clk":"11450116863","pt":1717318193370,"mc":[{"id":"1.229554911","rc":[{"spn":5.21,"spf":"NaN","id":70003369},{"spn":9.59,"spf":"NaN","id":69033911},{"atl":[[10,0]],"id":55943164}],"con":true,"img":false}]}
{"op":"mcm","clk":"11450116871","pt":1717318193472,"mc":[{"id":"1.229554911","rc":[{"atl":[[8.4,4.18]],"id":55943164}],"con":true,"img":false}]}
{"op":"mcm","clk":"11450116957","pt":1717318194457,"mc":[{"id":"1.229554911","rc":[{"atl":[[17.5,5.75],[19.5,0]],"id":69033911}],"con":true,"img":false}]}
{"op":"mcm","clk":"11450116966","pt":1717318194561,"mc":[{"id":"1.229554911","rc":[{"atl":[[17.5,2.61],[19.5,3.14]],"id":69033911}],"con":true,"img":false}]}
{"op":"mcm","clk":"11450116975","pt":1717318194663,"mc":[{"id":"1.229554911","rc":[{"atl":[[17.5,5.75],[19.5,0]],"id":69033911}],"con":true,"img":false}]}
{"op":"mcm","clk":"11450116984","pt":1717318194766,"mc":[{"id":"1.229554911","rc":[{"atl":[[17.5,2.61],[19.5,3.14]],"id":69033911}],"con":true,"img":false}]}
{"op":"mcm","clk":"11450118650","pt":1717318213869,"mc":[{"id":"1.229554911","rc":[{"atl":[[8.6,2.71],[8.2,5.55]],"id":55943164}],"con":true,"img":false}]}
{"op":"mcm","clk":"11450119654","pt":1717318224797,"mc":[{"id":"1.229554911","rc":[{"atl":[[17.5,5.75],[19.5,0]],"id":69033911}],"con":true,"img":false}]}
{"op":"mcm","clk":"11450119661","pt":1717318224895,"mc":[{"id":"1.229554911","rc":[{"atl":[[17.5,2.61],[19.5,3.14]],"id":69033911}],"con":true,"img":false}]}
{"op":"mcm","clk":"11450119953","pt":1717318228066,"mc":[{"id":"1.229554911","rc":[{"atl":[[12,4.88]],"id":70003369},{"atl":[[20,0]],"id":69033911}],"con":true,"img":false}]}
{"op":"mcm","clk":"11450119958","pt":1717318228220,"mc":[{"id":"1.229554911","rc":[{"atl":[[11.5,3.8]],"id":70003369},{"atl":[[19,3.13]],"id":69033911}],"con":true,"img":false}]}
{"op":"mcm","clk":"11450119966","pt":1717318228272,"mc":[{"id":"1.229554911","rc":[{"atl":[[11,4.81],[12,0]],"id":70003369}],"con":true,"img":false}]}
{"op":"mcm","clk":"11450121884","pt":1717318250991,"mc":[{"id":"1.229554911","rc":[{"atl":[[8,5.97],[8.4,0]],"id":55943164}],"con":true,"img":false}]}
{"op":"mcm","clk":"11450121893","pt":1717318251098,"mc":[{"id":"1.229554911","rc":[{"atl":[[8.2,0],[7.8,5.62]],"id":55943164}],"con":true,"img":false}]}
{"op":"mcm","clk":"11450122208","pt":1717318254511,"mc":[{"id":"1.229554911","rc":[{"atl":[[17.5,5.75],[19.5,0]],"id":69033911}],"con":true,"img":false}]}
{"op":"mcm","clk":"11450122218","pt":1717318254615,"mc":[{"id":"1.229554911","rc":[{"atl":[[17.5,2.61],[18.5,3.14]],"id":69033911}],"con":true,"img":false}]}
{"op":"mcm","clk":"11450122224","pt":1717318254719,"mc":[{"id":"1.229554911","rc":[{"atl":[[17.5,5.75]],"id":69033911}],"con":true,"img":false}]}
{"op":"mcm","clk":"11450122234","pt":1717318254821,"mc":[{"id":"1.229554911","rc":[{"atl":[[18.5,0]],"id":69033911}],"con":true,"img":false}]}
{"op":"mcm","clk":"11450122874","pt":1717318262521,"mc":[{"id":"1.229554911","rc":[{"atl":[[19,0]],"id":69033911}],"con":true,"img":false}]}
{"op":"mcm","clk":"11450122881","pt":1717318262624,"mc":[{"id":"1.229554911","rc":[{"atl":[[20,3.13]],"id":69033911}],"con":true,"img":false}]}
{"op":"mcm","clk":"11450123974","pt":1717318275042,"mc":[{"id":"1.229554911","rc":[{"atl":[[11.5,0]],"id":70003369}],"con":true,"img":false}]}
{"op":"mcm","clk":"11450123979","pt":1717318275143,"mc":[{"id":"1.229554911","rc":[{"atl":[[10.5,3.8]],"id":70003369}],"con":true,"img":false}]}
{"op":"mcm","clk":"11450123987","pt":1717318275246,"mc":[{"id":"1.229554911","rc":[{"atl":[[10,4.81]],"id":70003369}],"con":true,"img":false}]}
{"op":"mcm","clk":"11450123995","pt":1717318275350,"mc":[{"id":"1.229554911","rc":[{"atl":[[11,0]],"id":70003369}],"con":true,"img":false}]}
{"op":"mcm","clk":"11450124841","pt":1717318285266,"mc":[{"id":"1.229554911","rc":[{"atl":[[10.5,0]],"id":70003369}],"con":true,"img":false}]}
{"op":"mcm","clk":"11450124852","pt":1717318285368,"mc":[{"id":"1.229554911","rc":[{"atl":[[10,0],[12,8.68]],"id":70003369}],"con":true,"img":false}]}
{"op":"mcm","clk":"11450125511","pt":1717318293139,"mc":[{"id":"1.229554911","rc":[{"atl":[[8,0]],"id":55943164}],"con":true,"img":false}]}
{"op":"mcm","clk":"11450125521","pt":1717318293241,"mc":[{"id":"1.229554911","rc":[{"atl":[[8.6,13.98],[7.6,5.97],[7.8,0.07]],"id":55943164}],"con":true,"img":false}]}
{"op":"mcm","clk":"11450126526","pt":1717318304934,"mc":[{"id":"1.229554911","rc":[{"atl":[[7.6,0]],"id":55943164}],"con":true,"img":false}]}
{"op":"mcm","clk":"11450126537","pt":1717318305037,"mc":[{"id":"1.229554911","rc":[{"atl":[[8.4,5.97]],"id":55943164}],"con":true,"img":false}]}
{"op":"mcm","clk":"11450127978","pt":1717318322243,"mc":[{"id":"1.229554911","rc":[{"atl":[[8.6,2.72],[8.2,5.98]],"id":55943164}],"con":true,"img":false}]}
{"op":"mcm","clk":"11450128252","pt":1717318325049,"mc":[{"id":"1.229554911","rc":[{"atl":[[12,4.88]],"id":70003369}],"con":true,"img":false}]}
{"op":"mcm","clk":"11450128265","pt":1717318325155,"mc":[{"id":"1.229554911","rc":[{"atl":[[11.5,3.8]],"id":70003369}],"con":true,"img":false}]}
{"op":"mcm","clk":"11450128286","pt":1717318325365,"mc":[{"id":"1.229554911","rc":[{"atl":[[11,4.81],[12,0]],"id":70003369}],"con":true,"img":false}]}
{"op":"mcm","clk":"11450129804","pt":1717318342377,"mc":[{"id":"1.229554911","rc":[{"atl":[[8.6,0]],"id":55943164}],"con":true,"img":false}]}
{"op":"mcm","clk":"11450129976","pt":1717318344355,"mc":[{"id":"1.229554911","rc":[{"atl":[[11,4.18]],"id":55943164}],"con":true,"img":false}]}
{"op":"mcm","clk":"11450129985","pt":1717318344456,"mc":[{"id":"1.229554911","rc":[{"atl":[[8.4,0]],"id":55943164}],"con":true,"img":false}]}
{"op":"mcm","clk":"11450129994","pt":1717318344562,"mc":[{"id":"1.229554911","rc":[{"atl":[[10.5,6.06],[8.2,0]],"id":55943164}],"con":true,"img":false}]}
{"op":"mcm","clk":"11450134158","pt":1717318394008,"mc":[{"id":"1.229554911","rc":[{"atl":[[11,0]],"id":55943164}],"con":true,"img":false}]}
{"op":"mcm","clk":"11450134166","pt":1717318394108,"mc":[{"id":"1.229554911","rc":[{"atl":[[10,4.18]],"id":55943164}],"con":true,"img":false}]}
{"op":"mcm","clk":"11450134173","pt":1717318394212,"mc":[{"id":"1.229554911","rc":[{"atl":[[9.8,5.55]],"id":55943164}],"con":true,"img":false}]}
{"op":"mcm","clk":"11450134182","pt":1717318394317,"mc":[{"id":"1.229554911","rc":[{"atl":[[10.5,0]],"id":55943164}],"con":true,"img":false}]}
{"op":"mcm","clk":"11450134618","pt":1717318399845,"mc":[{"id":"1.229554911","rc":[{"atl":[[8.6,2.72]],"id":55943164}],"con":true,"img":false}]}
{"op":"mcm","clk":"11450134630","pt":1717318399949,"mc":[{"id":"1.229554911","rc":[{"atl":[[8.6,6.91]],"id":55943164}],"con":true,"img":false}]}
{"op":"mcm","clk":"11450134639","pt":1717318399994,"mc":[{"id":"1.229554911","rc":[{"atl":[[9.8,0]],"id":55943164}],"con":true,"img":false}]}
{"op":"mcm","clk":"11450137021","pt":1717318427778,"mc":[{"id":"1.229554911","rc":[{"atb":[[1.97,0],[1.87,0]],"id":70003369},{"atl":[[8.4,0]],"id":70003369},{"atb":[[2.4,0],[2.6,0]],"id":69033911},{"atl":[[16.5,0]],"id":69033911},{"atb":[[1.01,17.35]],"id":69676139},{"atl":[[2.8,0]],"id":69676139},{"atb":[[11,0],[8.4,11.04]],"id":52272946},{"atb":[[1.79,0],[1.89,0]],"id":55943164},{"atl":[[7.8,0]],"id":55943164},{"atb":[[2.38,0],[2.58,0]],"id":54867443},{"atl":[[13.5,0]],"id":54867443}],"con":true,"img":false}]}
{"op":"mcm","clk":"11450138062","pt":1717318439293,"mc":[{"id":"1.229554911","rc":[{"atb":[[1.64,45.77],[1.98,0]],"id":70003369},{"atb":[[1.58,50.51],[1.9,0]],"id":55943164}],"con":true,"img":false}]}
{"op":"mcm","clk":"11450138370","pt":1717318442408,"mc":[{"id":"1.229554911","rc":[{"atb":[[1.97,23.94],[1.87,40.04]],"id":70003369},{"atl":[[8.4,0.07]],"id":70003369},{"atb":[[2.38,25.24],[2.58,14.7]],"id":69033911},{"atl":[[13.5,0.04]],"id":69033911},{"atb":[[1.01,5824.62]],"id":69676139},{"atl":[[2.8,0.29]],"id":69676139},{"atb":[[8.6,4.58],[11.5,2.21]],"id":52272946},{"atb":[[1.81,43.01],[1.91,25.52]],"id":55943164},{"atl":[[8,0.07]],"id":55943164},{"atb":[[2.32,26.39],[2.52,15.28]],"id":54867443},{"atl":[[14.5,0.03]],"id":54867443}],"con":true,"img":false}]}
{"op":"mcm","clk":"11450138762","pt":1717318447190,"mc":[{"id":"1.229554911","rc":[{"atb":[[2.62,0]],"id":69033911}],"con":true,"img":false}]}
{"op":"mcm","clk":"11450138769","pt":1717318447266,"mc":[{"id":"1.229554911","rc":[{"atb":[[2.08,27.12]],"id":69033911}],"con":true,"img":false}]}
{"op":"mcm","clk":"11450141121","pt":1717318474016,"mc":[{"id":"1.229554911","rc":[{"spn":8.09,"spf":"NaN","id":69033911},{"atl":[[10,0]],"id":55943164},{"spn":4.97,"spf":"NaN","id":55943164},{"spn":8.51,"spf":"NaN","id":54867443}],"con":true,"img":false}]}
{"op":"mcm","clk":"11450141132","pt":1717318474119,"mc":[{"id":"1.229554911","rc":[{"atl":[[8.4,4.18]],"id":55943164}],"con":true,"img":false}]}
{"op":"mcm","clk":"11450141138","pt":1717318474218,"mc":[{"id":"1.229554911","rc":[{"atl":[[8.6,2.71],[8.2,5.55]],"id":55943164}],"con":true,"img":false}]}
{"op":"mcm","clk":"11450142607","pt":1717318491348,"mc":[{"id":"1.229554911","rc":[{"atb":[[1.64,0],[1.98,29.89]],"id":70003369},{"atb":[[2.08,0]],"id":69033911},{"atb":[[1.92,31.84],[1.58,0]],"id":55943164}],"con":true,"img":false}]}
{"op":"mcm","clk":"11450142615","pt":1717318491452,"mc":[{"id":"1.229554911","rc":[{"atb":[[2.6,27.12]],"id":69033911}],"con":true,"img":false}]}
{"op":"mcm","clk":"11450142809","pt":1717318493330,"mc":[{"id":"1.229554911","rc":[{"atb":[[2.44,0]],"id":54867443}],"con":true,"img":false}]}
{"op":"mcm","clk":"11450142890","pt":1717318494048,"mc":[{"id":"1.229554911","rc":[{"atb":[[2.38,2.84]],"id":54867443}],"con":true,"img":false}]}
{"op":"mcm","clk":"11450142896","pt":1717318494150,"mc":[{"id":"1.229554911","rc":[{"atb":[[1.94,0]],"id":55943164}],"con":true,"img":false}]}
{"op":"mcm","clk":"11450142976","pt":1717318495028,"mc":[{"id":"1.229554911","rc":[{"atb":[[1.96,4.09]],"id":55943164}],"con":true,"img":false}]}
{"op":"mcm","clk":"11450144141","pt":1717318508470,"mc":[{"id":"1.229554911","rc":[{"atb":[[2.02,0]],"id":70003369},{"atb":[[2.68,0]],"id":69033911}],"con":true,"img":false}]}
{"op":"mcm","clk":"11450144192","pt":1717318509085,"mc":[{"id":"1.229554911","rc":[{"atb":[[2.02,3.84]],"id":70003369},{"atb":[[2.66,2.36]],"id":69033911}],"con":true,"img":false}]}
{"op":"mcm","clk":"11450144942","pt":1717318517368,"mc":[{"id":"1.229554911","rc":[{"atl":[[8,6.05],[8.4,0]],"id":55943164}],"con":true,"img":false}]}
{"op":"mcm","clk":"11450144949","pt":1717318517469,"mc":[{"id":"1.229554911","rc":[{"atl":[[11.5,0]],"id":70003369},{"atl":[[7.8,5.55]],"id":55943164}],"con":true,"img":false}]}
{"op":"mcm","clk":"11450144961","pt":1717318517574,"mc":[{"id":"1.229554911","rc":[{"atl":[[10.5,3.8]],"id":70003369},{"atl":[[8.2,0]],"id":55943164}],"con":true,"img":false}]}
{"op":"mcm","clk":"11450144976","pt":1717318517683,"mc":[{"id":"1.229554911","rc":[{"atl":[[10,4.81]],"id":70003369}],"con":true,"img":false}]}
{"op":"mcm","clk":"11450144982","pt":1717318517785,"mc":[{"id":"1.229554911","rc":[{"atl":[[11,0]],"id":70003369}],"con":true,"img":false}]}
{"op":"mcm","clk":"11450145770","pt":1717318527371,"mc":[{"id":"1.229554911","rc":[{"atl":[[10.5,0]],"id":70003369}],"con":true,"img":false}]}
{"op":"mcm","clk":"11450145780","pt":1717318527475,"mc":[{"id":"1.229554911","rc":[{"atl":[[10,0],[12,8.68]],"id":70003369}],"con":true,"img":false}]}
{"op":"mcm","clk":"11450148414","pt":1717318557907,"mc":[{"id":"1.229554911","rc":[{"spn":8.08,"spf":"NaN","id":69033911},{"atl":[[8,0.07]],"id":55943164},{"spn":4.88,"spf":"NaN","id":55943164}],"con":true,"img":false}]}
{"op":"mcm","clk":"11450148426","pt":1717318558014,"mc":[{"id":"1.229554911","rc":[{"atl":[[7.6,5.97]],"id":55943164}],"con":true,"img":false}]}
{"op":"mcm","clk":"11450148432","pt":1717318558117,"mc":[{"id":"1.229554911","rc":[{"atl":[[7.8,0],[8.4,5.62]],"id":55943164}],"con":true,"img":false}]}
{"op":"mcm","clk":"11450148440","pt":1717318558218,"mc":[{"id":"1.229554911","rc":[{"atl":[[7.8,11.96],[8.4,0]],"id":55943164}],"con":true,"img":false}]}
{"op":"mcm","clk":"11450149380","pt":1717318568530,"mc":[{"id":"1.229554911","rc":[{"atl":[[12,4.88]],"id":70003369}],"con":true,"img":false}]}
{"op":"mcm","clk":"11450149388","pt":1717318568636,"mc":[{"id":"1.229554911","rc":[{"atl":[[11.5,3.8]],"id":70003369}],"con":true,"img":false}]}
{"op":"mcm","clk":"11450149409","pt":1717318568842,"mc":[{"id":"1.229554911","rc":[{"atl":[[11,4.81],[12,0]],"id":70003369}],"con":true,"img":false}]}
{"op":"mcm","clk":"11450152800","pt":1717318603050,"mc":[{"id":"1.229554911","rc":[{"atl":[[8.6,0]],"id":55943164}],"con":true,"img":false}]}
{"op":"mcm","clk":"11450153618","pt":1717318612427,"mc":[{"id":"1.229554911","rc":[{"atb":[[1.03,128.49]],"id":70003369},{"atl":[[990,2.59]],"id":70003369},{"atb":[[1.01,110.77]],"id":69033911},{"atl":[[990,2.4]],"id":69033911},{"atb":[[1.03,168.72]],"id":69676139},{"atl":[[990,1.82]],"id":69676139},{"atb":[[1.03,70.72]],"id":52272946},{"atl":[[970,0.86]],"id":52272946},{"atb":[[1.03,86.91]],"id":55943164},{"atl":[[960,0.86]],"id":55943164},{"atb":[[1.02,192.58]],"id":54867443},{"atl":[[960,2.09]],"id":54867443}],"con":true,"img":false}]}
{"op":"mcm","clk":"11450153979","pt":1717318616677,"mc":[{"id":"1.229554911","rc":[{"atl":[[16,4.18],[18,0]],"id":54867443}],"con":true,"img":false}]}
{"op":"mcm","clk":"11450153986","pt":1717318616732,"mc":[{"id":"1.229554911","rc":[{"atl":[[15.5,4.19]],"id":54867443}],"con":true,"img":false}]}
{"op":"mcm","clk":"11450153994","pt":1717318616833,"mc":[{"id":"1.229554911","rc":[{"atl":[[16.5,2.61]],"id":54867443}],"con":true,"img":false}]}
{"op":"mcm","clk":"11450155432","pt":1717318631401,"mc":[{"id":"1.229554911","rc":[{"spn":4.78,"spf":"NaN","id":55943164},{"atl":[[16,0]],"id":54867443}],"con":true,"img":false}]}
{"op":"mcm","clk":"11450155441","pt":1717318631469,"mc":[{"id":"1.229554911","rc":[{"atl":[[16,4.23],[18.5,4.18],[15.5,0]],"id":54867443}],"con":true,"img":false}]}
{"op":"mcm","clk":"11450155707","pt":1717318633813,"mc":[{"id":"1.229554911","rc":[{"atl":[[990,1.9]],"id":70003369},{"atl":[[990,1.72]],"id":69033911},{"atl":[[1000,0.17]],"id":69676139},{"atl":[[1000,0.17]],"id":52272946},{"atl":[[990,0.17]],"id":55943164},{"atl":[[990,0.17]],"id":54867443}],"con":true,"img":false}]}
{"op":"mcm","clk":"11450157470","pt":1717318649682,"mc":[{"id":"1.229554911","rc":[{"atl":[[16.5,0]],"id":54867443}],"con":true,"img":false}]}
{"op":"mcm","clk":"11450157479","pt":1717318649783,"mc":[{"id":"1.229554911","rc":[{"atl":[[18,4.27],[15.5,2.61]],"id":54867443}],"con":true,"img":false}]}
{"op":"mcm","clk":"11450157489","pt":1717318649887,"mc":[{"id":"1.229554911","rc":[{"atl":[[16,0]],"id":54867443}],"con":true,"img":false}]}
{"op":"mcm","clk":"11450157946","pt":1717318654281,"mc":[{"id":"1.229554911","rc":[{"atl":[[8.6,1.6]],"id":55943164}],"con":true,"img":false}]}
{"op":"mcm","clk":"11450160005","pt":1717318675223,"mc":[{"id":"1.229554911","rc":[{"atl":[[18,0],[15.5,6.8]],"id":54867443}],"con":true,"img":false}]}
{"op":"mcm","clk":"11450171376","pt":1717318799365,"mc":[{"id":"1.229554911","rc":[{"atb":[[1.97,0],[1.87,0]],"id":70003369},{"atl":[[8.4,0]],"id":70003369},{"spn":6.51,"spf":"NaN","id":70003369},{"atb":[[2.38,0],[2.58,0]],"id":69033911},{"atl":[[13.5,0]],"id":69033911},{"spn":10.08,"spf":"NaN","id":69033911},{"atb":[[1.01,17.35]],"id":69676139},{"atl":[[2.8,0]],"id":69676139},{"spn":2.67,"spf":"NaN","id":69676139},{"atb":[[8.6,0],[11.5,0]],"id":52272946},{"atb":[[1.81,0],[1.91,0]],"id":55943164},{"atl":[[8,0]],"id":55943164},{"atb":[[2.32,0],[2.52,0]],"id":54867443},{"atl":[[14.5,0]],"id":54867443},{"spn":8.94,"spf":"NaN","id":54867443}],"con":true,"img":false}]}
{"op":"mcm","clk":"11450173178","pt":1717318816479,"mc":[{"id":"1.229554911","rc":[{"atb":[[1.84,41.48],[1.94,24.7]],"id":70003369},{"atl":[[8.2,0.07]],"id":70003369},{"atb":[[2.38,25.24],[2.58,14.7]],"id":69033911},{"atl":[[13.5,0.04]],"id":69033911},{"atb":[[1.01,5824.62]],"id":69676139},{"atl":[[2.8,0.29]],"id":69676139},{"atb":[[9.6,2.69],[7.6,5.27]],"id":52272946},{"atb":[[1.82,42.49],[1.92,57.09]],"id":55943164},{"atl":[[8,0.07]],"id":55943164},{"atb":[[2.4,24.88],[2.6,14.51]],"id":54867443},{"atl":[[16.5,0.03]],"id":54867443}],"con":true,"img":false}]}
{"op":"mcm","clk":"11450173675","pt":1717318821695,"mc":[{"id":"1.229554911","rc":[{"atl":[[8.6,0]],"id":55943164}],"con":true,"img":false}]}
{"op":"mcm","clk":"11450173949","pt":1717318824697,"mc":[{"id":"1.229554911","rc":[{"atb":[[2.38,0]],"id":54867443}],"con":true,"img":false}]}
{"op":"mcm","clk":"11450173964","pt":1717318824901,"mc":[{"id":"1.229554911","rc":[{"atb":[[2.46,2.68]],"id":54867443}],"con":true,"img":false}]}
{"op":"mcm","clk":"11450174518","pt":1717318831291,"mc":[{"id":"1.229554911","rc":[{"atb":[[1.98,0],[1.55,0]],"id":70003369},{"atl":[[11.5,0],[12.5,0]],"id":70003369},{"atb":[[2.6,0],[1.95,0]],"id":69033911},{"atl":[[17.5,3.14],[20,0]],"id":69033911},{"atb":[[1.12,0],[1.14,0]],"id":69676139},{"atl":[[4.4,0],[4.2,0]],"id":69676139},{"atb":[[17.5,0],[15,0]],"id":52272946},{"atl":[[520,0],[560,0]],"id":52272946},{"atb":[[1.92,25.24],[1.49,0]],"id":55943164},{"atl":[[11.5,0],[7.6,0]],"id":55943164},{"atb":[[2.02,0],[1.84,0]],"id":54867443},{"atl":[[18.5,0],[15.5,4.19]],"id":54867443}],"con":true,"img":false}]}
{"op":"mcm","clk":"11450174528","pt":1717318831400,"mc":[{"id":"1.229554911","rc":[{"atl":[[65,2]],"id":54867443}],"con":true,"img":false}]}
{"op":"mcm","clk":"11450174534","pt":1717318831500,"mc":[{"id":"1.229554911","rc":[{"atl":[[11,0],[30,3.45]],"id":70003369},{"atl":[[65,2],[17.5,0]],"id":69033911},{"atl":[[4.5,0],[12.5,8.7]],"id":69676139},{"atl":[[7.8,0],[29,3.57]],"id":55943164},{"atl":[[15.5,0]],"id":54867443}],"con":true,"img":false}]}
{"op":"mcm","clk":"11450175104","pt":1717318838311,"mc":[{"id":"1.229554911","rc":[{"atb":[[1.56,102.99],[1.95,30.84]],"id":70003369},{"atl":[[12,3.8],[12.5,5.01]],"id":70003369},{"atb":[[2.4,29.89],[1.95,64.87]],"id":69033911},{"atl":[[19,2.61],[20,3.13]],"id":69033911},{"atb":[[1.12,525.26],[1.14,107.09]],"id":69676139},{"atl":[[4.3,19.35],[4.1,13.5]],"id":69676139},{"atb":[[17.5,2.61],[15,4.12]],"id":52272946},{"atl":[[550,2.61],[500,0.08]],"id":52272946},{"atb":[[1.92,57.09],[1.51,122.47]],"id":55943164},{"atl":[[11,4.18],[11.5,5.54]],"id":55943164},{"atb":[[2.02,28.72],[1.85,71.15]],"id":54867443},{"atl":[[17.5,2.61],[18.5,3.66]],"id":54867443}],"con":true,"img":false}]}
{"op":"mcm","clk":"11450175178","pt":1717318839125,"mc":[{"id":"1.229554911","rc":[{"atb":[[1.57,0]],"id":70003369},{"atb":[[1.99,0]],"id":69033911},{"atb":[[1.51,114.12]],"id":55943164},{"atb":[[1.87,0]],"id":54867443}],"con":true,"img":false}]}
{"op":"mcm","clk":"11450176692","pt":1717318855038,"mc":[{"id":"1.229554911","rc":[{"atl":[[65,0],[17.5,5.23]],"id":54867443}],"con":true,"img":false}]}
{"op":"mcm","clk":"11450176700","pt":1717318855134,"mc":[{"id":"1.229554911","rc":[{"atl":[[11.5,3.8],[30,0]],"id":70003369},{"atl":[[65,0],[19,5.23]],"id":69033911},{"atl":[[4.5,27],[12.5,0]],"id":69676139},{"atl":[[10.5,4.19],[29,0]],"id":55943164},{"atl":[[17.5,2.61],[18,2.65]],"id":54867443}],"con":true,"img":false}]}
{"op":"mcm","clk":"11450176737","pt":1717318855538,"mc":[{"id":"1.229554911","rc":[{"atl":[[8.6,1.84]],"id":55943164}],"con":true,"img":false}]}
{"op":"mcm","clk":"11450176745","pt":1717318855645,"mc":[{"id":"1.229554911","rc":[{"atl":[[8.6,6.03]],"id":55943164}],"con":true,"img":false}]}
{"op":"mcm","clk":"11450176755","pt":1717318855745,"mc":[{"id":"1.229554911","rc":[{"atl":[[10.5,0]],"id":55943164}],"con":true,"img":false}]}
{"op":"mcm","clk":"11450178728","pt":1717318875226,"mc":[{"id":"1.229554911","rc":[{"spn":5.11,"spf":"NaN","id":70003369},{"atb":[[2.4,0]],"id":69033911},{"spn":8.08,"spf":"NaN","id":69033911},{"spn":1.97,"spf":"NaN","id":69676139},{"spn":258.75,"spf":"NaN","id":52272946},{"atb":[[1.92,25.24]],"id":55943164},{"atl":[[11,0]],"id":55943164},{"spn":4.98,"spf":"NaN","id":55943164},{"spn":9.55,"spf":"NaN","id":54867443}],"con":true,"img":false}]}
{"op":"mcm","clk":"11450178738","pt":1717318875335,"mc":[{"id":"1.229554911","rc":[{"atb":[[2.6,29.89]],"id":69033911},{"atb":[[1.93,31.84]],"id":55943164},{"atl":[[8.4,4.18]],"id":55943164}],"con":true,"img":false}]}
{"op":"mcm","clk":"11450178818","pt":1717318876161,"mc":[{"id":"1.229554911","rc":[{"atb":[[1.88,4.84]],"id":54867443}],"con":true,"img":false}]}
{"op":"mcm","clk":"11450178843","pt":1717318876369,"mc":[{"id":"1.229554911","rc":[{"atb":[[1.96,8.52]],"id":55943164}],"con":true,"img":false}]}
{"op":"mcm","clk":"11450178867","pt":1717318876571,"mc":[{"id":"1.229554911","rc":[{"atb":[[1.99,4.3]],"id":69033911}],"con":true,"img":false}]}
{"op":"mcm","clk":"11450178904","pt":1717318876881,"mc":[{"id":"1.229554911","rc":[{"atb":[[1.58,7.34]],"id":70003369}],"con":true,"img":false}]}
{"op":"mcm","clk":"11450179094","pt":1717318879061,"mc":[{"id":"1.229554911","rc":[{"atl":[[8.6,1.83],[8.2,5.55]],"id":55943164}],"con":true,"img":false}]}
{"op":"mcm","clk":"11450179577","pt":1717318884576,"mc":[{"id":"1.229554911","rc":[{"atb":[[1.96,4.43]],"id":55943164}],"con":true,"img":false}]}
{"op":"mcm","clk":"11450179619","pt":1717318884990,"mc":[{"id":"1.229554911","rc":[{"atb":[[1.97,4.05]],"id":55943164}],"con":true,"img":false}]}
{"op":"mcm","clk":"11450181078","pt":1717318899630,"mc":[{"id":"1.229554911","rc":[{"atb":[[2.02,0]],"id":70003369},{"atb":[[2.66,0]],"id":69033911}],"con":true,"img":false}]}
{"op":"mcm","clk":"11450181503","pt":1717318904182,"mc":[{"id":"1.229554911","rc":[{"atl":[[12.5,0]],"id":70003369},{"atl":[[20,0]],"id":69033911},{"atl":[[18.5,0]],"id":54867443}],"con":true,"img":false}]}
{"op":"mcm","clk":"11450181514","pt":1717318904283,"mc":[{"id":"1.229554911","rc":[{"atl":[[11,5.01]],"id":70003369},{"atl":[[18.5,3.13]],"id":69033911},{"atl":[[17.5,6.27]],"id":54867443}],"con":true,"img":false}]}
{"op":"mcm","clk":"11450181528","pt":1717318904334,"mc":[{"id":"1.229554911","rc":[{"atl":[[10.5,3.8],[11.5,0]],"id":70003369},{"atl":[[18,3.14],[19,2.61]],"id":69033911},{"atl":[[17,2.65],[18,0]],"id":54867443}],"con":true,"img":false}]}
{"op":"mcm","clk":"11450181724","pt":1717318906466,"mc":[{"id":"1.229554911","rc":[{"atb":[[1.96,0]],"id":55943164}],"con":true,"img":false}]}
{"op":"mcm","clk":"11450182332","pt":1717318913094,"mc":[{"id":"1.229554911","rc":[{"atl":[[8,6.05]],"id":55943164}],"con":true,"img":false}]}
{"op":"mcm","clk":"11450182342","pt":1717318913146,"mc":[{"id":"1.229554911","rc":[{"atl":[[11,0]],"id":70003369},{"atl":[[8.2,0],[7.8,5.55],[8.4,0]],"id":55943164}],"con":true,"img":false}]}
{"op":"mcm","clk":"11450182351","pt":1717318913251,"mc":[{"id":"1.229554911","rc":[{"atl":[[12,8.82]],"id":70003369}],"con":true,"img":false}]}
{"op":"mcm","clk":"11450182476","pt":1717318914744,"mc":[{"id":"1.229554911","rc":[{"atb":[[1.99,3.96]],"id":70003369}],"con":true,"img":false}]}
{"op":"mcm","clk":"11450182485","pt":1717318914847,"mc":[{"id":"1.229554911","rc":[{"atb":[[2.66,2.36]],"id":69033911}],"con":true,"img":false}]}
{"op":"mcm","clk":"11450184552","pt":1717318937099,"mc":[{"id":"1.229554911","rc":[{"spn":5.09,"spf":"NaN","id":70003369},{"atl":[[8.6,0]],"id":55943164},{"spn":4.88,"spf":"NaN","id":55943164}],"con":true,"img":false}]}
{"op":"mcm","clk":"11450186254","pt":1717318952920,"mc":[{"id":"1.229554911","rc":[{"atb":[[1.53,8.03]],"id":55943164}],"con":true,"img":false}]}
{"op":"mcm","clk":"11450186670","pt":1717318957035,"mc":[{"id":"1.229554911","rc":[{"atl":[[18.5,0],[19,0]],"id":69033911},{"atl":[[8,0.07]],"id":55943164},{"atl":[[17.5,2.61]],"id":54867443}],"con":true,"img":false}]}
{"op":"mcm","clk":"11450186679","pt":1717318957138,"mc":[{"id":"1.229554911","rc":[{"atl":[[65,2],[17.5,5.75],[18,0]],"id":69033911},{"atl":[[10.5,5.97],[11,5.62],[7.8,0]],"id":55943164},{"atl":[[16.5,3.69]],"id":54867443}],"con":true,"img":false}]}
{"op":"mcm","clk":"11450186693","pt":1717318957248,"mc":[{"id":"1.229554911","rc":[{"atl":[[65,0],[17,2]],"id":69033911},{"atl":[[10,5.62],[11,0]],"id":55943164},{"atl":[[16,2.65],[17,0]],"id":54867443}],"con":true,"img":false}]}
{"op":"mcm","clk":"11450187465","pt":1717318965211,"mc":[{"id":"1.229554911","rc":[{"atl":[[17.5,2.61]],"id":69033911}],"con":true,"img":false}]}
{"op":"mcm","clk":"11450187478","pt":1717318965318,"mc":[{"id":"1.229554911","rc":[{"atl":[[19.5,3.13]],"id":69033911}],"con":true,"img":false}]}
{"op":"mcm","clk":"11450190214","pt":1717318994045,"mc":[{"id":"1.229554911","rc":[{"atl":[[8.6,2.34]],"id":55943164}],"con":true,"img":false}]}
{"op":"mcm","clk":"11450190222","pt":1717318994150,"mc":[{"id":"1.229554911","rc":[{"atl":[[8.6,7.96],[10,0]],"id":55943164}],"con":true,"img":false}]}
{"op":"mcm","clk":"11450190234","pt":1717318994255,"mc":[{"id":"1.229554911","rc":[{"atl":[[8.6,2.34],[10,5.62]],"id":55943164}],"con":true,"img":false}]}
{"op":"mcm","clk":"11450190243","pt":1717318994355,"mc":[{"id":"1.229554911","rc":[{"atl":[[8.6,8.32],[10,0]],"id":55943164}],"con":true,"img":false}]}
{"op":"mcm","clk":"11450190249","pt":1717318994458,"mc":[{"id":"1.229554911","rc":[{"atl":[[10,5.62]],"id":55943164}],"con":true,"img":false}]}
{"op":"mcm","clk":"11450190257","pt":1717318994561,"mc":[{"id":"1.229554911","rc":[{"atl":[[8.6,2.34]],"id":55943164}],"con":true,"img":false}]}
{"op":"mcm","clk":"11450190270","pt":1717318994665,"mc":[{"id":"1.229554911","rc":[{"atl":[[8.6,8.32],[10,0]],"id":55943164}],"con":true,"img":false}]}
{"op":"mcm","clk":"11450190281","pt":1717318994764,"mc":[{"id":"1.229554911","rc":[{"atl":[[10,5.62]],"id":55943164}],"con":true,"img":false}]}
{"op":"mcm","clk":"11450190287","pt":1717318994867,"mc":[{"id":"1.229554911","rc":[{"atl":[[8.6,2.34]],"id":55943164}],"con":true,"img":false}]}
{"op":"mcm","clk":"11450190296","pt":1717318994973,"mc":[{"id":"1.229554911","rc":[{"atl":[[10.5,0]],"id":55943164}],"con":true,"img":false}]}
{"op":"mcm","clk":"11450190308","pt":1717318995078,"mc":[{"id":"1.229554911","rc":[{"atl":[[8.6,7.89],[10,0],[9.8,5.97]],"id":55943164}],"con":true,"img":false}]}
{"op":"mcm","clk":"11450192619","pt":1717319019706,"mc":[{"id":"1.229554911","rc":[{"spn":4.98,"spf":"NaN","id":55943164},{"atl":[[16.5,0.03]],"id":54867443},{"spn":9.3,"spf":"NaN","id":54867443}],"con":true,"img":false}]}
{"op":"mcm","clk":"11450192628","pt":1717319019799,"mc":[{"id":"1.229554911","rc":[{"atl":[[16,0],[17,2.68],[15.5,3.66]],"id":54867443}],"con":true,"img":false}]}
{"op":"mcm","clk":"11450192640","pt":1717319019903,"mc":[{"id":"1.229554911","rc":[{"atl":[[17,0],[15,2.68]],"id":54867443}],"con":true,"img":false}]}
{"op":"mcm","clk":"11450193210","pt":1717319025343,"mc":[{"id":"1.229554911","rc":[{"atl":[[8.6,5.55]],"id":55943164}],"con":true,"img":false}]}
{"op":"mcm","clk":"11450193221","pt":1717319025442,"mc":[{"id":"1.229554911","rc":[{"atl":[[9.6,5.62]],"id":55943164}],"con":true,"img":false}]}
{"op":"mcm","clk":"11450193235","pt":1717319025505,"mc":[{"id":"1.229554911","rc":[{"atl":[[8.6,0]],"id":55943164}],"con":true,"img":false}]}
{"op":"mcm","clk":"11450193357","pt":1717319026944,"mc":[{"id":"1.229554911","rc":[{"atl":[[9.8,0]],"id":55943164},{"atl":[[15.5,0]],"id":54867443}],"con":true,"img":false}]}
{"op":"mcm","clk":"11450193366","pt":1717319027046,"mc":[{"id":"1.229554911","rc":[{"atl":[[11,5.69],[9.4,5.97]],"id":55943164},{"atl":[[17,2.71],[18,3.66],[15,0]],"id":54867443}],"con":true,"img":false}]}
{"op":"mcm","clk":"11450193375","pt":1717319027105,"mc":[{"id":"1.229554911","rc":[{"atl":[[9.6,0],[9.2,5.69]],"id":55943164}],"con":true,"img":false}]}
{"op":"mcm","clk":"11450193380","pt":1717319027204,"mc":[{"id":"1.229554911","rc":[{"atl":[[11,0]],"id":55943164}],"con":true,"img":false}]}
{"op":"mcm","clk":"11450197264","pt":1717319071352,"mc":[{"id":"1.229554911","rc":[{"atl":[[9.4,0]],"id":55943164}],"con":true,"img":false}]}
{"op":"mcm","clk":"11450197275","pt":1717319071506,"mc":[{"id":"1.229554911","rc":[{"atl":[[9,5.97],[9.2,0],[11,5.76]],"id":55943164}],"con":true,"img":false}]}
{"op":"mcm","clk":"11450197289","pt":1717319071683,"mc":[{"id":"1.229554911","rc":[{"atl":[[11,0],[8.8,5.76]],"id":55943164}],"con":true,"img":false}]}
{"op":"mcm","clk":"11450199560","pt":1717319095009,"mc":[{"id":"1.229554911","rc":[{"atl":[[18,0]],"id":54867443},{"spn":9.55,"spf":"NaN","id":54867443}],"con":true,"img":false}]}
{"op":"mcm","clk":"11450199575","pt":1717319095111,"mc":[{"id":"1.229554911","rc":[{"atl":[[16.5,3.69]],"id":54867443}],"con":true,"img":false}]}
{"op":"mcm","clk":"11450199585","pt":1717319095215,"mc":[{"id":"1.229554911","rc":[{"atl":[[16,2.71],[17,0]],"id":54867443}],"con":true,"img":false}]}
{"op":"mcm","clk":"11450201105","pt":1717319110651,"mc":[{"id":"1.229554911","rc":[{"atl":[[9,0]],"id":55943164}],"con":true,"img":false}]}
{"op":"mcm","clk":"11450201120","pt":1717319110750,"mc":[{"id":"1.229554911","rc":[{"atl":[[8.6,5.97],[11,5.83]],"id":55943164}],"con":true,"img":false}]}
{"op":"mcm","clk":"11450201130","pt":1717319110858,"mc":[{"id":"1.229554911","rc":[{"atl":[[8.8,0],[8.4,5.83]],"id":55943164}],"con":true,"img":false}]}
{"op":"mcm","clk":"11450201140","pt":1717319110957,"mc":[{"id":"1.229554911","rc":[{"atl":[[11,0]],"id":55943164}],"con":true,"img":false}]}
{"op":"mcm","clk":"11450203131","pt":1717319131357,"mc":[{"id":"1.229554911","rc":[{"atl":[[8.6,7.81]],"id":55943164}],"con":true,"img":false}]}
{"op":"mcm","clk":"11450204953","pt":1717319149431,"mc":[{"id":"1.229554911","rc":[{"atl":[[8.6,1.84]],"id":55943164},{"atl":[[16.5,0.03]],"id":54867443}],"con":true,"img":false}]}
{"op":"mcm","clk":"11450204964","pt":1717319149526,"mc":[{"id":"1.229554911","rc":[{"atl":[[8.2,5.97]],"id":55943164},{"atl":[[17,2.74],[15.5,3.66]],"id":54867443}],"con":true,"img":false}]}
{"op":"mcm","clk":"11450204976","pt":1717319149628,"mc":[{"id":"1.229554911","rc":[{"atl":[[8,5.9],[8.4,0]],"id":55943164},{"atl":[[16,0]],"id":54867443}],"con":true,"img":false}]}
{"op":"mcm","clk":"11450205921","pt":1717319159049,"mc":[{"id":"1.229554911","rc":[{"atl":[[15.5,0]],"id":54867443}],"con":true,"img":false}]}
{"op":"mcm","clk":"11450205934","pt":1717319159146,"mc":[{"id":"1.229554911","rc":[{"atl":[[16.5,3.69]],"id":54867443}],"con":true,"img":false}]}
{"op":"mcm","clk":"11450206996","pt":1717319169951,"mc":[{"id":"1.229554911","rc":[{"atl":[[16,2.74]],"id":54867443}],"con":true,"img":false}]}
{"op":"mcm","clk":"11450207006","pt":1717319170055,"mc":[{"id":"1.229554911","rc":[{"atl":[[17,0]],"id":54867443}],"con":true,"img":false}]}
{"op":"mcm","clk":"11450208349","pt":1717319182711,"mc":[{"id":"1.229554911","rc":[{"atb":[[1.84,0],[1.94,0]],"id":70003369},{"atl":[[8.2,0]],"id":70003369},{"atb":[[2.38,0],[2.58,0]],"id":69033911},{"atl":[[13.5,0]],"id":69033911},{"atb":[[1.01,17.35]],"id":69676139},{"atl":[[2.8,0]],"id":69676139},{"atb":[[9.6,0],[7.6,0]],"id":52272946},{"atb":[[1.82,0],[1.92,0]],"id":55943164},{"atl":[[8,5.83]],"id":55943164},{"atb":[[2.4,0],[2.6,0]],"id":54867443},{"atl":[[16.5,3.66]],"id":54867443}],"con":true,"img":false}]}
{"op":"mcm","clk":"11450208362","pt":1717319182818,"mc":[{"id":"1.229554911","rc":[{"atl":[[10.5,0],[11.5,7.6]],"id":70003369},{"atl":[[17,0],[17.5,6.61]],"id":69033911}],"con":true,"img":false}]}
{"op":"mcm","clk":"11450208375","pt":1717319182926,"mc":[{"id":"1.229554911","rc":[{"atl":[[17.5,2.61],[19,4.62]],"id":69033911}],"con":true,"img":false}]}
{"op":"mcm","clk":"11450208386","pt":1717319182971,"mc":[{"id":"1.229554911","rc":[{"atl":[[17.5,5.75]],"id":69033911}],"con":true,"img":false}]}
{"op":"mcm","clk":"11450208399","pt":1717319183137,"mc":[{"id":"1.229554911","rc":[{"atl":[[19,0]],"id":69033911}],"con":true,"img":false}]}
{"op":"mcm","clk":"11450208467","pt":1717319183599,"mc":[{"id":"1.229554911","rc":[{"atb":[[1.64,45.77],[1.95,0]],"id":70003369},{"atb":[[2.6,0]],"id":69033911},{"atb":[[1.58,50.51],[1.93,0]],"id":55943164}],"con":true,"img":false}]}
{"op":"mcm","clk":"11450208479","pt":1717319183698,"mc":[{"id":"1.229554911","rc":[{"atb":[[2.1,29.89]],"id":69033911}],"con":true,"img":false}]}
{"op":"mcm","clk":"11450209390","pt":1717319192586,"mc":[{"id":"1.229554911","rc":[{"atl":[[8.2,0]],"id":55943164}],"con":true,"img":false}]}
{"op":"mcm","clk":"11450209400","pt":1717319192689,"mc":[{"id":"1.229554911","rc":[{"atl":[[8.6,13.5],[7.8,5.97]],"id":55943164}],"con":true,"img":false}]}
{"op":"mcm","clk":"11450209407","pt":1717319192791,"mc":[{"id":"1.229554911","rc":[{"atl":[[8,0],[8.6,1.84],[11,7.67]],"id":55943164}],"con":true,"img":false}]}
{"op":"mcm","clk":"11450209419","pt":1717319192899,"mc":[{"id":"1.229554911","rc":[{"atl":[[7.8,11.95]],"id":55943164}],"con":true,"img":false}]}
{"op":"mcm","clk":"11450209427","pt":1717319193007,"mc":[{"id":"1.229554911","rc":[{"atl":[[8.6,13.8],[11,0],[7.8,5.97]],"id":55943164}],"con":true,"img":false}]}
{"op":"mcm","clk":"11450209435","pt":1717319193104,"mc":[{"id":"1.229554911","rc":[{"atl":[[8.6,1.84],[11,7.82]],"id":55943164}],"con":true,"img":false}]}
{"op":"mcm","clk":"11450209446","pt":1717319193210,"mc":[{"id":"1.229554911","rc":[{"atl":[[7.8,11.95]],"id":55943164}],"con":true,"img":false}]}
{"op":"mcm","clk":"11450209459","pt":1717319193312,"mc":[{"id":"1.229554911","rc":[{"atl":[[8.6,13.8],[11,0]],"id":55943164}],"con":true,"img":false}]}
{"op":"mcm","clk":"11450209470","pt":1717319193413,"mc":[{"id":"1.229554911","rc":[{"atl":[[7.8,5.97]],"id":55943164}],"con":true,"img":false}]}
{"op":"mcm","clk":"11450209479","pt":1717319193518,"mc":[{"id":"1.229554911","rc":[{"atl":[[8.6,1.84],[7.8,17.93]],"id":55943164}],"con":true,"img":false}]}
{"op":"mcm","clk":"11450209493","pt":1717319193577,"mc":[{"id":"1.229554911","rc":[{"atl":[[8.6,13.8]],"id":55943164}],"con":true,"img":false}]}
{"op":"mcm","clk":"11450209504","pt":1717319193677,"mc":[{"id":"1.229554911","rc":[{"atl":[[7.8,5.97]],"id":55943164}],"con":true,"img":false}]}
{"op":"mcm","clk":"11450209515","pt":1717319193782,"mc":[{"id":"1.229554911","rc":[{"atl":[[7.8,19.77]],"id":55943164}],"con":true,"img":false}]}
{"op":"mcm","clk":"11450209529","pt":1717319193888,"mc":[{"id":"1.229554911","rc":[{"atl":[[8.6,1.84]],"id":55943164}],"con":true,"img":false}]}
{"op":"mcm","clk":"11450210100","pt":1717319199991,"mc":[{"id":"1.229554911","rc":[{"atb":[[1.97,0]],"id":55943164}],"con":true,"img":false}]}
{"op":"mcm","clk":"11450210471","pt":1717319203311,"mc":[{"id":"1.229554911","rc":[{"atb":[[1.83,41.97],[1.93,24.97]],"id":70003369},{"atl":[[8.2,0.07]],"id":70003369},{"atb":[[2.42,24.53],[2.62,14.34]],"id":69033911},{"atl":[[17,0.03]],"id":69033911},{"atb":[[1.01,5824.62]],"id":69676139},{"atl":[[2.78,0.29]],"id":69676139},{"atb":[[11,2.32],[8.4,15.74]],"id":52272946},{"atb":[[1.84,41.48],[1.94,24.7]],"id":55943164},{"atl":[[8.2,0.07]],"id":55943164},{"atb":[[2.38,25.24],[2.58,14.7]],"id":54867443},{"atl":[[13.5,0.04]],"id":54867443}],"con":true,"img":false}]}
{"op":"mcm","clk":"11450210629","pt":1717319204510,"mc":[{"id":"1.229554911","rc":[{"atl":[[8.6,0]],"id":55943164}],"con":true,"img":false}]}
{"op":"mcm","clk":"11450211127","pt":1717319209845,"mc":[{"id":"1.229554911","rc":[{"atl":[[8.6,2.34]],"id":55943164}],"con":true,"img":false}]}
{"op":"mcm","clk":"11450211353","pt":1717319212122,"mc":[{"id":"1.229554911","rc":[{"atl":[[12,5.01]],"id":70003369}],"con":true,"img":false}]}
{"op":"mcm","clk":"11450211360","pt":1717319212228,"mc":[{"id":"1.229554911","rc":[{"atl":[[11,3.8]],"id":70003369}],"con":true,"img":false}]}
{"op":"mcm","clk":"11450211372","pt":1717319212329,"mc":[{"id":"1.229554911","rc":[{"atl":[[10.5,5.02]],"id":70003369}],"con":true,"img":false}]}
{"op":"mcm","clk":"11450211380","pt":1717319212431,"mc":[{"id":"1.229554911","rc":[{"atl":[[11.5,0]],"id":70003369}],"con":true,"img":false}]}
{"op":"mcm","clk":"11450211653","pt":1717319215136,"mc":[{"id":"1.229554911","rc":[{"atb":[[1.87,4.51]],"id":55943164}],"con":true,"img":false}]}
{"op":"mcm","clk":"11450212424","pt":1717319222924,"mc":[{"id":"1.229554911","rc":[{"spn":9.83,"spf":"NaN","id":69033911},{"spn":1.96,"spf":"NaN","id":69676139},{"spn":4.87,"spf":"NaN","id":55943164},{"atl":[[16.5,0]],"id":54867443},{"spn":8.04,"spf":"NaN","id":54867443}],"con":true,"img":false}]}
{"op":"mcm","clk":"11450212436","pt":1717319223027,"mc":[{"id":"1.229554911","rc":[{"atl":[[15.5,3.66]],"id":54867443}],"con":true,"img":false}]}
{"op":"mcm","clk":"11450212448","pt":1717319223128,"mc":[{"id":"1.229554911","rc":[{"atl":[[16,0],[15,2.74]],"id":54867443}],"con":true,"img":false}]}
{"op":"mcm","clk":"11450213257","pt":1717319231051,"mc":[{"id":"1.229554911","rc":[{"atl":[[7.8,13.8]],"id":55943164},{"atl":[[15.5,0]],"id":54867443}],"con":true,"img":false}]}
{"op":"mcm","clk":"11450213267","pt":1717319231152,"mc":[{"id":"1.229554911","rc":[{"atl":[[7.6,5.97],[8.4,13.51]],"id":55943164},{"atl":[[17.5,6.27]],"id":54867443}],"con":true,"img":false}]}
{"op":"mcm","clk":"11450213279","pt":1717319231256,"mc":[{"id":"1.229554911","rc":[{"atl":[[7.8,0]],"id":55943164},{"atl":[[17,2.78],[15,0]],"id":54867443}],"con":true,"img":false}]}
{"op":"mcm","clk":"11450214240","pt":1717319240932,"mc":[{"id":"1.229554911","rc":[{"atb":[[1.64,0],[1.94,31.16]],"id":70003369},{"atb":[[1.58,0],[1.85,34.46]],"id":55943164}],"con":true,"img":false}]}
{"op":"mcm","clk":"11450214723","pt":1717319245366,"mc":[{"id":"1.229554911","rc":[{"atl":[[8.6,0]],"id":55943164}],"con":true,"img":false}]}
{"op":"mcm","clk":"11450214735","pt":1717319245472,"mc":[{"id":"1.229554911","rc":[{"atb":[[1.99,0]],"id":70003369},{"atb":[[2.66,0]],"id":69033911},{"atb":[[1.87,0]],"id":55943164},{"atb":[[2.46,0]],"id":54867443}],"con":true,"img":false}]}
{"op":"mcm","clk":"11450214753","pt":1717319245681,"mc":[{"id":"1.229554911","rc":[{"atb":[[1.88,4.45]],"id":55943164}],"con":true,"img":false}]}
{"op":"mcm","clk":"11450215077","pt":1717319248647,"mc":[{"id":"1.229554911","rc":[{"atb":[[2.1,0]],"id":69033911},{"atl":[[19.5,0]],"id":69033911},{"atb":[[1.12,0]],"id":69676139},{"atl":[[7.6,0]],"id":55943164}],"con":true,"img":false}]}
{"op":"mcm","clk":"11450215088","pt":1717319248803,"mc":[{"id":"1.229554911","rc":[{"atb":[[2.64,29.89]],"id":69033911},{"atl":[[17,3.17]],"id":69033911},{"atb":[[1.13,525.26]],"id":69676139},{"atl":[[8.2,6.05],[11,10],[8.4,0]],"id":55943164}],"con":true,"img":false}]}
{"op":"mcm","clk":"11450215114","pt":1717319248969,"mc":[{"id":"1.229554911","rc":[{"atl":[[16.5,3.17],[17.5,2.61]],"id":69033911}],"con":true,"img":false}]}
{"op":"mcm","clk":"11450215308","pt":1717319250786,"mc":[{"id":"1.229554911","rc":[{"atl":[[8,6.05],[11,0]],"id":55943164}],"con":true,"img":false}]}
{"op":"mcm","clk":"11450216157","pt":1717319258568,"mc":[{"id":"1.229554911","rc":[{"atl":[[17,0.03]],"id":69033911},{"atl":[[8.2,0.07]],"id":55943164}],"con":true,"img":false}]}
{"op":"mcm","clk":"11450216164","pt":1717319258670,"mc":[{"id":"1.229554911","rc":[{"atl":[[17,6.28],[19.5,3.13]],"id":69033911},{"atl":[[8,0],[10.5,5.97],[11,6.12]],"id":55943164}],"con":true,"img":false}]}
{"op":"mcm","clk":"11450216179","pt":1717319258766,"mc":[{"id":"1.229554911","rc":[{"atl":[[16.5,0]],"id":69033911}],"con":true,"img":false}]}
{"op":"mcm","clk":"11450216190","pt":1717319258870,"mc":[{"id":"1.229554911","rc":[{"atl":[[17,0.03],[17.5,8.67]],"id":69033911},{"atl":[[10,5.98],[11,0]],"id":55943164}],"con":true,"img":false}]}
{"op":"mcm","clk":"11450216349","pt":1717319260485,"mc":[{"id":"1.229554911","rc":[{"atb":[[1.98,4]],"id":70003369},{"atb":[[1.01,113.13]],"id":69033911},{"atb":[[2.44,2.72]],"id":54867443}],"con":true,"img":false}]}
{"op":"mcm","clk":"11450216373","pt":1717319260701,"mc":[{"id":"1.229554911","rc":[{"atb":[[1.01,113.08]],"id":69033911}],"con":true,"img":false}]}
{"op":"mcm","clk":"11450216395","pt":1717319260895,"mc":[{"id":"1.229554911","rc":[{"atb":[[1.01,110.77]],"id":69033911}],"con":true,"img":false}]}
{"op":"mcm","clk":"11450216409","pt":1717319261003,"mc":[{"id":"1.229554911","rc":[{"atb":[[2.7,2.3]],"id":69033911}],"con":true,"img":false}]}
{"op":"mcm","clk":"11450218778","pt":1717319284618,"mc":[{"id":"1.229554911","rc":[{"spn":5.09,"spf":"NaN","id":70003369},{"spn":9.85,"spf":"NaN","id":69033911},{"spn":5.07,"spf":"NaN","id":55943164},{"atl":[[17.5,2.61]],"id":54867443}],"con":true,"img":false}]}
{"op":"mcm","clk":"11450218787","pt":1717319284722,"mc":[{"id":"1.229554911","rc":[{"atl":[[16.5,3.66]],"id":54867443}],"con":true,"img":false}]}
{"op":"mcm","clk":"11450218794","pt":1717319284825,"mc":[{"id":"1.229554911","rc":[{"atl":[[16,2.78],[17,0]],"id":54867443}],"con":true,"img":false}]}
{"op":"mcm","clk":"11450219271","pt":1717319289648,"mc":[{"id":"1.229554911","rc":[{"atl":[[10.5,0]],"id":55943164}],"con":true,"img":false}]}
{"op":"mcm","clk":"11450219283","pt":1717319289753,"mc":[{"id":"1.229554911","rc":[{"atl":[[9.8,5.97]],"id":55943164}],"con":true,"img":false}]}
{"op":"mcm","clk":"11450219295","pt":1717319289808,"mc":[{"id":"1.229554911","rc":[{"atl":[[9.6,5.98],[10,0]],"id":55943164}],"con":true,"img":false}]}
{"op":"mcm","clk":"11450220274","pt":1717319299660,"mc":[{"id":"1.229554911","rc":[{"atl":[[19.5,0]],"id":69033911}],"con":true,"img":false}]}
{"op":"mcm","clk":"11450220280","pt":1717319299717,"mc":[{"id":"1.229554911","rc":[{"atl":[[17,3.17]],"id":69033911}],"con":true,"img":false}]}
{"op":"mcm","clk":"11450220291","pt":1717319299822,"mc":[{"id":"1.229554911","rc":[{"atl":[[16.5,3.17],[17.5,2.61]],"id":69033911}],"con":true,"img":false}]}
{"op":"mcm","clk":"11450220752","pt":1717319304683,"mc":[{"id":"1.229554911","rc":[{"atl":[[17,0.03]],"id":69033911}],"con":true,"img":false}]}
{"op":"mcm","clk":"11450220763","pt":1717319304785,"mc":[{"id":"1.229554911","rc":[{"atl":[[16.5,0],[17,6.28],[19.5,3.13]],"id":69033911}],"con":true,"img":false}]}
{"op":"mcm","clk":"11450220771","pt":1717319304887,"mc":[{"id":"1.229554911","rc":[{"atl":[[17.5,8.67]],"id":69033911}],"con":true,"img":false}]}
{"op":"mcm","clk":"11450220782","pt":1717319304991,"mc":[{"id":"1.229554911","rc":[{"atl":[[17,0.03],[17.5,2.61],[19,5.56]],"id":69033911}],"con":true,"img":false}]}
{"op":"mcm","clk":"11450220792","pt":1717319305045,"mc":[{"id":"1.229554911","rc":[{"atl":[[17.5,8.67]],"id":69033911}],"con":true,"img":false}]}
{"op":"mcm","clk":"11450220800","pt":1717319305199,"mc":[{"id":"1.229554911","rc":[{"atl":[[19,0]],"id":69033911}],"con":true,"img":false}]}
{"op":"mcm","clk":"11450221736","pt":1717319314595,"mc":[{"id":"1.229554911","rc":[{"atl":[[9.8,0]],"id":55943164}],"con":true,"img":false}]}
{"op":"mcm","clk":"11450221749","pt":1717319314701,"mc":[{"id":"1.229554911","rc":[{"atl":[[11,6.05],[9.4,5.97]],"id":55943164}],"con":true,"img":false}]}
{"op":"mcm","clk":"11450221766","pt":1717319314803,"mc":[{"id":"1.229554911","rc":[{"atl":[[9.6,0],[9.2,5.98]],"id":55943164}],"con":true,"img":false}]}
{"op":"mcm","clk":"11450221773","pt":1717319314906,"mc":[{"id":"1.229554911","rc":[{"atl":[[11,0]],"id":55943164}],"con":true,"img":false}]}
{"op":"mcm","clk":"11450222688","pt":1717319324604,"mc":[{"id":"1.229554911","rc":[{"atl":[[16.5,0]],"id":54867443}],"con":true,"img":false}]}
{"op":"mcm","clk":"11450222699","pt":1717319324707,"mc":[{"id":"1.229554911","rc":[{"atl":[[15.5,3.66]],"id":54867443}],"con":true,"img":false}]}
{"op":"mcm","clk":"11450222709","pt":1717319324811,"mc":[{"id":"1.229554911","rc":[{"atl":[[15,2.78]],"id":54867443}],"con":true,"img":false}]}
{"op":"mcm","clk":"11450222719","pt":1717319324920,"mc":[{"id":"1.229554911","rc":[{"atl":[[16,0]],"id":54867443}],"con":true,"img":false}]}
{"op":"mcm","clk":"11450223112","pt":1717319329691,"mc":[{"id":"1.229554911","rc":[{"atl":[[15.5,0]],"id":54867443}],"con":true,"img":false}]}
{"op":"mcm","clk":"11450223119","pt":1717319329795,"mc":[{"id":"1.229554911","rc":[{"atl":[[17.5,6.27]],"id":54867443}],"con":true,"img":false}]}
{"op":"mcm","clk":"11450223127","pt":1717319329901,"mc":[{"id":"1.229554911","rc":[{"atl":[[17,2.82],[15,0]],"id":54867443}],"con":true,"img":false}]}
{"op":"mcm","clk":"11450223979","pt":1717319339638,"mc":[{"id":"1.229554911","rc":[{"atl":[[9.4,0]],"id":55943164}],"con":true,"img":false}]}
{"op":"mcm","clk":"11450223995","pt":1717319339736,"mc":[{"id":"1.229554911","rc":[{"atl":[[9,5.97]],"id":55943164}],"con":true,"img":false}]}
{"op":"mcm","clk":"11450224006","pt":1717319339835,"mc":[{"id":"1.229554911","rc":[{"atl":[[9.2,0],[11,6.05]],"id":55943164}],"con":true,"img":false}]}
{"op":"mcm","clk":"11450224486","pt":1717319344743,"mc":[{"id":"1.229554911","rc":[{"atl":[[19.5,0]],"id":69033911}],"con":true,"img":false}]}
{"op":"mcm","clk":"11450224497","pt":1717319344849,"mc":[{"id":"1.229554911","rc":[{"atl":[[17,3.17]],"id":69033911}],"con":true,"img":false}]}
{"op":"mcm","clk":"11450224515","pt":1717319345006,"mc":[{"id":"1.229554911","rc":[{"atl":[[16.5,3.17],[17.5,2.61]],"id":69033911}],"con":true,"img":false}]}
{"op":"mcm","clk":"11450224898","pt":1717319349621,"mc":[{"id":"1.229554911","rc":[{"atl":[[17,0.03]],"id":69033911}],"con":true,"img":false}]}
{"op":"mcm","clk":"11450224908","pt":1717319349726,"mc":[{"id":"1.229554911","rc":[{"atl":[[19.5,3.13]],"id":69033911}],"con":true,"img":false}]}
{"op":"mcm","clk":"11450224944","pt":1717319350144,"mc":[{"id":"1.229554911","rc":[{"atl":[[16.5,0],[17,6.28]],"id":69033911}],"con":true,"img":false}]}
{"op":"mcm","clk":"11450224956","pt":1717319350255,"mc":[{"id":"1.229554911","rc":[{"atl":[[17.5,8.67]],"id":69033911}],"con":true,"img":false}]}
{"op":"mcm","clk":"11450224966","pt":1717319350349,"mc":[{"id":"1.229554911","rc":[{"atl":[[17,0.03],[19,5.56]],"id":69033911}],"con":true,"img":false}]}
{"op":"mcm","clk":"11450224979","pt":1717319350456,"mc":[{"id":"1.229554911","rc":[{"atl":[[17.5,2.61]],"id":69033911}],"con":true,"img":false}]}
{"op":"mcm","clk":"11450225391","pt":1717319354665,"mc":[{"id":"1.229554911","rc":[{"atl":[[9,0]],"id":55943164}],"con":true,"img":false}]}
{"op":"mcm","clk":"11450225401","pt":1717319354762,"mc":[{"id":"1.229554911","rc":[{"atl":[[10.5,5.97]],"id":55943164}],"con":true,"img":false}]}
{"op":"mcm","clk":"11450225733","pt":1717319358352,"mc":[{"id":"1.229554911","rc":[{"atl":[[10,5.98],[11,0]],"id":55943164}],"con":true,"img":false}]}
{"op":"mcm","clk":"11450226182","pt":1717319363437,"mc":[{"id":"1.229554911","rc":[{"atl":[[17.5,5.75]],"id":69033911}],"con":true,"img":false}]}
{"op":"mcm","clk":"11450226192","pt":1717319363536,"mc":[{"id":"1.229554911","rc":[{"atl":[[19,0]],"id":69033911}],"con":true,"img":false}]}
{"op":"mcm","clk":"11450226746","pt":1717319369649,"mc":[{"id":"1.229554911","rc":[{"atl":[[17.5,2.61]],"id":54867443}],"con":true,"img":false}]}
{"op":"mcm","clk":"11450226758","pt":1717319369753,"mc":[{"id":"1.229554911","rc":[{"atl":[[16.5,3.66]],"id":54867443}],"con":true,"img":false}]}
{"op":"mcm","clk":"11450226768","pt":1717319369860,"mc":[{"id":"1.229554911","rc":[{"atl":[[16,2.82]],"id":54867443}],"con":true,"img":false}]}
{"op":"mcm","clk":"11450226780","pt":1717319369966,"mc":[{"id":"1.229554911","rc":[{"atl":[[17,0]],"id":54867443}],"con":true,"img":false}]}
{"op":"mcm","clk":"11450227613","pt":1717319379552,"mc":[{"id":"1.229554911","rc":[{"atl":[[10.5,0],[11.5,0]],"id":55943164}],"con":true,"img":false}]}
{"op":"mcm","clk":"11450227622","pt":1717319379655,"mc":[{"id":"1.229554911","rc":[{"atl":[[9.8,11.52]],"id":55943164}],"con":true,"img":false}]}
{"op":"mcm","clk":"11450227630","pt":1717319379760,"mc":[{"id":"1.229554911","rc":[{"atl":[[10,0],[29,3.57]],"id":55943164}],"con":true,"img":false}]}
{"op":"mcm","clk":"11450228058","pt":1717319384599,"mc":[{"id":"1.229554911","rc":[{"atl":[[9.8,5.97]],"id":55943164}],"con":true,"img":false}]}
{"op":"mcm","clk":"11450228065","pt":1717319384658,"mc":[{"id":"1.229554911","rc":[{"atl":[[11,5.54]],"id":55943164}],"con":true,"img":false}]}
{"op":"mcm","clk":"11450228492","pt":1717319389608,"mc":[{"id":"1.229554911","rc":[{"atl":[[11,0]],"id":70003369},{"atl":[[19.5,0]],"id":69033911}],"con":true,"img":false}]}
{"op":"mcm","clk":"11450228502","pt":1717319389706,"mc":[{"id":"1.229554911","rc":[{"atl":[[10,3.8]],"id":70003369},{"atl":[[17,3.17]],"id":69033911}],"con":true,"img":false}]}
{"op":"mcm","clk":"11450228513","pt":1717319389809,"mc":[{"id":"1.229554911","rc":[{"atl":[[9.8,5.02]],"id":70003369},{"atl":[[16.5,3.17]],"id":69033911}],"con":true,"img":false}]}
{"op":"mcm","clk":"11450228520","pt":1717319389863,"mc":[{"id":"1.229554911","rc":[{"atl":[[10.5,0]],"id":70003369},{"atl":[[17.5,2.61]],"id":69033911}],"con":true,"img":false}]}
{"op":"mcm","clk":"11450228935","pt":1717319394596,"mc":[{"id":"1.229554911","rc":[{"atl":[[17,0.03]],"id":69033911}],"con":true,"img":false}]}
{"op":"mcm","clk":"11450228944","pt":1717319394700,"mc":[{"id":"1.229554911","rc":[{"atl":[[16.5,0],[17,6.28],[19.5,3.13]],"id":69033911}],"con":true,"img":false}]}
{"op":"mcm","clk":"11450228953","pt":1717319394805,"mc":[{"id":"1.229554911","rc":[{"atl":[[17,0.03],[17.5,8.67]],"id":69033911}],"con":true,"img":false}]}
{"op":"mcm","clk":"11450228964","pt":1717319394909,"mc":[{"id":"1.229554911","rc":[{"atl":[[17.5,2.61],[19,5.56]],"id":69033911}],"con":true,"img":false}]}
{"op":"mcm","clk":"11450228974","pt":1717319395009,"mc":[{"id":"1.229554911","rc":[{"atl":[[17.5,5.75],[19,0]],"id":69033911}],"con":true,"img":false}]}
{"op":"mcm","clk":"11450228980","pt":1717319395112,"mc":[{"id":"1.229554911","rc":[{"atl":[[17.5,2.61],[19,3.14]],"id":69033911}],"con":true,"img":false}]}
{"op":"mcm","clk":"11450229231","pt":1717319397908,"mc":[{"id":"1.229554911","rc":[{"atl":[[9.6,5.55]],"id":55943164}],"con":true,"img":false}]}
{"op":"mcm","clk":"11450229243","pt":1717319398012,"mc":[{"id":"1.229554911","rc":[{"atl":[[29,0]],"id":55943164}],"con":true,"img":false}]}
{"op":"mcm","clk":"11450230314","pt":1717319409646,"mc":[{"id":"1.229554911","rc":[{"atl":[[16.5,0]],"id":54867443}],"con":true,"img":false}]}
{"op":"mcm","clk":"11450230320","pt":1717319409707,"mc":[{"id":"1.229554911","rc":[{"atl":[[15.5,3.66]],"id":54867443}],"con":true,"img":false}]}
{"op":"mcm","clk":"11450230331","pt":1717319409809,"mc":[{"id":"1.229554911","rc":[{"atl":[[16,0],[15,2.82]],"id":54867443}],"con":true,"img":false}]}
{"op":"mcm","clk":"11450230590","pt":1717319412420,"mc":[{"id":"1.229554911","rc":[{"atl":[[8.6,1.84]],"id":55943164}],"con":true,"img":false}]}
{"op":"mcm","clk":"11450230600","pt":1717319412543,"mc":[{"id":"1.229554911","rc":[{"atl":[[8.6,7.39]],"id":55943164}],"con":true,"img":false}]}
{"op":"mcm","clk":"11450230610","pt":1717319412628,"mc":[{"id":"1.229554911","rc":[{"atl":[[9.6,0]],"id":55943164}],"con":true,"img":false}]}
{"op":"mcm","clk":"11450230635","pt":1717319413039,"mc":[{"id":"1.229554911","rc":[{"atl":[[17.5,5.75],[19,0]],"id":69033911}],"con":true,"img":false}]}
{"op":"mcm","clk":"11450230649","pt":1717319413143,"mc":[{"id":"1.229554911","rc":[{"atl":[[17.5,2.61],[19,3.14]],"id":69033911}],"con":true,"img":false}]}
{"op":"mcm","clk":"11450230771","pt":1717319414746,"mc":[{"id":"1.229554911","rc":[{"atl":[[10,0]],"id":70003369},{"atl":[[15.5,0]],"id":54867443}],"con":true,"img":false}]}
{"op":"mcm","clk":"11450230781","pt":1717319414802,"mc":[{"id":"1.229554911","rc":[{"atl":[[9.6,3.8],[11.5,5.09]],"id":70003369},{"atl":[[17,2.86],[18,3.66]],"id":54867443}],"con":true,"img":false}]}
{"op":"mcm","clk":"11450230790","pt":1717319414907,"mc":[{"id":"1.229554911","rc":[{"atl":[[9.8,0]],"id":70003369},{"atl":[[15,0]],"id":54867443}],"con":true,"img":false}]}
{"op":"mcm","clk":"11450231173","pt":1717319419638,"mc":[{"id":"1.229554911","rc":[{"atl":[[9.8,0]],"id":55943164}],"con":true,"img":false}]}
{"op":"mcm","clk":"11450231183","pt":1717319419744,"mc":[{"id":"1.229554911","rc":[{"atl":[[8.4,5.97]],"id":55943164}],"con":true,"img":false}]}
{"op":"mcm","clk":"11450231191","pt":1717319419848,"mc":[{"id":"1.229554911","rc":[{"atl":[[8.6,1.84],[8.2,6.05]],"id":55943164}],"con":true,"img":false}]}
{"op":"mcm","clk":"11450231688","pt":1717319424655,"mc":[{"id":"1.229554911","rc":[{"atl":[[9.6,0]],"id":70003369}],"con":true,"img":false}]}
{"op":"mcm","clk":"11450231698","pt":1717319424758,"mc":[{"id":"1.229554911","rc":[{"atl":[[11,3.8]],"id":70003369}],"con":true,"img":false}]}
{"op":"mcm","clk":"11450232262","pt":1717319430664,"mc":[{"id":"1.229554911","rc":[{"atl":[[8.6,0]],"id":55943164}],"con":true,"img":false}]}
{"op":"mcm","clk":"11450232293","pt":1717319430969,"mc":[{"id":"1.229554911","rc":[{"atl":[[17.5,5.75],[19,0]],"id":69033911}],"con":true,"img":false}]}
{"op":"mcm","clk":"11450232468","pt":1717319432650,"mc":[{"id":"1.229554911","rc":[{"atl":[[10.5,5.02],[11.5,0]],"id":70003369}],"con":true,"img":false}]}
{"op":"mcm","clk":"11450232697","pt":1717319434668,"mc":[{"id":"1.229554911","rc":[{"atl":[[19.5,0]],"id":69033911},{"atl":[[8.4,0]],"id":55943164}],"con":true,"img":false}]}
{"op":"mcm","clk":"11450232706","pt":1717319434773,"mc":[{"id":"1.229554911","rc":[{"atl":[[17,3.17]],"id":69033911},{"atl":[[10.5,16.5]],"id":55943164}],"con":true,"img":false}]}
{"op":"mcm","clk":"11450232719","pt":1717319434880,"mc":[{"id":"1.229554911","rc":[{"atl":[[8.2,0.07]],"id":55943164}],"con":true,"img":false}]}
{"op":"mcm","clk":"11450234022","pt":1717319448568,"mc":[{"id":"1.229554911","rc":[{"atl":[[16.5,3.17],[17.5,2.61]],"id":69033911}],"con":true,"img":false}]}
{"op":"mcm","clk":"11450234120","pt":1717319449700,"mc":[{"id":"1.229554911","rc":[{"atl":[[17,0.03]],"id":69033911}],"con":true,"img":false}]}
{"op":"mcm","clk":"11450234132","pt":1717319449759,"mc":[{"id":"1.229554911","rc":[{"atl":[[16.5,0],[17,6.28],[19.5,3.13]],"id":69033911}],"con":true,"img":false}]}
{"op":"mcm","clk":"11450234633","pt":1717319454688,"mc":[{"id":"1.229554911","rc":[{"atl":[[18,0]],"id":54867443}],"con":true,"img":false}]}
{"op":"mcm","clk":"11450234642","pt":1717319454785,"mc":[{"id":"1.229554911","rc":[{"atl":[[16.5,3.66]],"id":54867443}],"con":true,"img":false}]}
{"op":"mcm","clk":"11450234651","pt":1717319454914,"mc":[{"id":"1.229554911","rc":[{"atl":[[17,0.03],[17.5,8.67]],"id":69033911},{"atl":[[16,2.86],[17,0]],"id":54867443}],"con":true,"img":false}]}
{"op":"mcm","clk":"11450234659","pt":1717319454988,"mc":[{"id":"1.229554911","rc":[{"atl":[[17.5,2.61],[19,5.56]],"id":69033911}],"con":true,"img":false}]}
{"op":"mcm","clk":"11450235573","pt":1717319464615,"mc":[{"id":"1.229554911","rc":[{"atl":[[10.5,10.53]],"id":55943164}],"con":true,"img":false}]}
{"op":"mcm","clk":"11450235581","pt":1717319464704,"mc":[{"id":"1.229554911","rc":[{"atl":[[10,5.97]],"id":55943164}],"con":true,"img":false}]}
{"op":"mcm","clk":"11450235600","pt":1717319464804,"mc":[{"id":"1.229554911","rc":[{"atl":[[10.5,0],[9.8,5.98]],"id":55943164}],"con":true,"img":false}]}
{"op":"mcm","clk":"11450235805","pt":1717319467184,"mc":[{"id":"1.229554911","rc":[{"atl":[[17.5,5.75],[19,0]],"id":69033911}],"con":true,"img":false}]}
{"op":"mcm","clk":"11450236461","pt":1717319474579,"mc":[{"id":"1.229554911","rc":[{"atl":[[9.6,6.76],[11,0]],"id":55943164}],"con":true,"img":false}]}
{"op":"mcm","clk":"11450237088","pt":1717319482125,"mc":[{"id":"1.229554911","rc":[{"atl":[[9.8,0],[9.4,5.98]],"id":55943164}],"con":true,"img":false}]}
{"op":"mcm","clk":"11450237319","pt":1717319484618,"mc":[{"id":"1.229554911","rc":[{"atl":[[11,0]],"id":70003369},{"atl":[[9.6,0]],"id":55943164}],"con":true,"img":false}]}
{"op":"mcm","clk":"11450237331","pt":1717319484717,"mc":[{"id":"1.229554911","rc":[{"atl":[[10,3.8]],"id":70003369},{"atl":[[11,6.76]],"id":55943164}],"con":true,"img":false}]}
{"op":"mcm","clk":"11450237347","pt":1717319484925,"mc":[{"id":"1.229554911","rc":[{"atl":[[10.5,0],[9.8,5.02]],"id":70003369}],"con":true,"img":false}]}
{"op":"mcm","clk":"11450237786","pt":1717319489626,"mc":[{"id":"1.229554911","rc":[{"atl":[[19.5,0]],"id":69033911},{"atl":[[10,0]],"id":55943164}],"con":true,"img":false}]}
{"op":"mcm","clk":"11450237797","pt":1717319489729,"mc":[{"id":"1.229554911","rc":[{"atl":[[17,3.17]],"id":69033911},{"atl":[[9.2,5.97],[10.5,6.05],[9.4,0]],"id":55943164}],"con":true,"img":false}]}
{"op":"mcm","clk":"11450237807","pt":1717319489832,"mc":[{"id":"1.229554911","rc":[{"atl":[[16.5,3.17],[17.5,2.61]],"id":69033911}],"con":true,"img":false}]}
{"op":"mcm","clk":"11450238249","pt":1717319494618,"mc":[{"id":"1.229554911","rc":[{"atl":[[17,0.03]],"id":69033911},{"atl":[[16.5,0]],"id":54867443}],"con":true,"img":false}]}
{"op":"mcm","clk":"11450238258","pt":1717319494719,"mc":[{"id":"1.229554911","rc":[{"atl":[[19.5,3.13]],"id":69033911},{"atl":[[15.5,3.66]],"id":54867443}],"con":true,"img":false}]}
{"op":"mcm","clk":"11450238269","pt":1717319494832,"mc":[{"id":"1.229554911","rc":[{"atl":[[15,2.86]],"id":54867443}],"con":true,"img":false}]}
{"op":"mcm","clk":"11450238277","pt":1717319494926,"mc":[{"id":"1.229554911","rc":[{"atl":[[16.5,0],[17,6.28]],"id":69033911},{"atl":[[16,0]],"id":54867443}],"con":true,"img":false}]}
{"op":"mcm","clk":"11450238654","pt":1717319499629,"mc":[{"id":"1.229554911","rc":[{"atl":[[15.5,0]],"id":54867443}],"con":true,"img":false}]}
{"op":"mcm","clk":"11450238663","pt":1717319499730,"mc":[{"id":"1.229554911","rc":[{"atl":[[17.5,6.27],[17,2.9],[15,0]],"id":54867443}],"con":true,"img":false}]}
{"op":"mcm","clk":"11450239279","pt":1717319506750,"mc":[{"id":"1.229554911","rc":[{"atl":[[9,6.05],[10.5,0]],"id":55943164}],"con":true,"img":false}]}
{"op":"mcm","clk":"11450239338","pt":1717319507320,"mc":[{"id":"1.229554911","rc":[{"atl":[[8.6,2.72]],"id":55943164}],"con":true,"img":false}]}
{"op":"mcm","clk":"11450239346","pt":1717319507423,"mc":[{"id":"1.229554911","rc":[{"atl":[[8.6,8.7],[9,0]],"id":55943164}],"con":true,"img":false}]}
{"op":"mcm","clk":"11450239358","pt":1717319507524,"mc":[{"id":"1.229554911","rc":[{"atl":[[8.6,2.72],[9,6.05]],"id":55943164}],"con":true,"img":false}]}
{"op":"mcm","clk":"11450239369","pt":1717319507630,"mc":[{"id":"1.229554911","rc":[{"atl":[[8.6,9.49],[9,0]],"id":55943164}],"con":true,"img":false}]}
{"op":"mcm","clk":"11450239381","pt":1717319507730,"mc":[{"id":"1.229554911","rc":[{"atl":[[8.6,2.72],[9,6.05]],"id":55943164}],"con":true,"img":false}]}
{"op":"mcm","clk":"11450239389","pt":1717319507834,"mc":[{"id":"1.229554911","rc":[{"atl":[[8.6,9.49],[9,0]],"id":55943164}],"con":true,"img":false}]}
{"op":"mcm","clk":"11450239402","pt":1717319507950,"mc":[{"id":"1.229554911","rc":[{"atl":[[9,6.05]],"id":55943164}],"con":true,"img":false}]}
{"op":"mcm","clk":"11450239415","pt":1717319508122,"mc":[{"id":"1.229554911","rc":[{"atl":[[8.6,2.72]],"id":55943164}],"con":true,"img":false}]}
{"op":"mcm","clk":"11450239438","pt":1717319508262,"mc":[{"id":"1.229554911","rc":[{"atl":[[8.6,8.77],[9,0]],"id":55943164}],"con":true,"img":false}]}
{"op":"mcm","clk":"11450239451","pt":1717319508366,"mc":[{"id":"1.229554911","rc":[{"atl":[[8.6,2.72],[9,6.05]],"id":55943164}],"con":true,"img":false}]}
{"op":"mcm","clk":"11450240027","pt":1717319514667,"mc":[{"id":"1.229554911","rc":[{"atl":[[17.5,0]],"id":69033911}],"con":true,"img":false}]}
{"op":"mcm","clk":"11450240038","pt":1717319514778,"mc":[{"id":"1.229554911","rc":[{"atl":[[16.5,2.61],[17,0.03]],"id":69033911}],"con":true,"img":false}]}
{"op":"mcm","clk":"11450240049","pt":1717319514878,"mc":[{"id":"1.229554911","rc":[{"atl":[[19,5.56]],"id":69033911}],"con":true,"img":false}]}
{"op":"mcm","clk":"11450241059","pt":1717319525239,"mc":[{"id":"1.229554911","rc":[{"atl":[[8.6,8.7],[9,0]],"id":55943164}],"con":true,"img":false}]}
{"op":"mcm","clk":"11450241483","pt":1717319529603,"mc":[{"id":"1.229554911","rc":[{"atl":[[9.2,0]],"id":55943164}],"con":true,"img":false}]}
{"op":"mcm","clk":"11450241492","pt":1717319529705,"mc":[{"id":"1.229554911","rc":[{"atl":[[8.8,5.97]],"id":55943164}],"con":true,"img":false}]}
{"op":"mcm","clk":"11450241665","pt":1717319531627,"mc":[{"id":"1.229554911","rc":[{"atl":[[16.5,5.23],[19,0]],"id":69033911}],"con":true,"img":false}]}
{"op":"mcm","clk":"11450241677","pt":1717319531730,"mc":[{"id":"1.229554911","rc":[{"atl":[[16.5,2.61],[19,3.14]],"id":69033911}],"con":true,"img":false}]}
{"op":"mcm","clk":"11450242418","pt":1717319539638,"mc":[{"id":"1.229554911","rc":[{"spn":9.6,"spf":"NaN","id":69033911},{"atl":[[17.5,2.61]],"id":54867443}],"con":true,"img":false}]}
{"op":"mcm","clk":"11450242427","pt":1717319539741,"mc":[{"id":"1.229554911","rc":[{"atl":[[16.5,3.66]],"id":54867443}],"con":true,"img":false}]}
{"op":"mcm","clk":"11450242439","pt":1717319539846,"mc":[{"id":"1.229554911","rc":[{"atl":[[16,2.9],[17,0]],"id":54867443}],"con":true,"img":false}]}
{"op":"mcm","clk":"11450242652","pt":1717319542042,"mc":[{"id":"1.229554911","rc":[{"spl":[[1.01,2.61]],"id":55943164}],"con":true,"img":false}]}
{"op":"mcm","clk":"11450243257","pt":1717319548347,"mc":[{"id":"1.229554911","rc":[{"atl":[[16.5,5.23],[19,0]],"id":69033911}],"con":true,"img":false}]}
{"op":"mcm","clk":"11450243402","pt":1717319549642,"mc":[{"id":"1.229554911","rc":[{"atl":[[8.8,0]],"id":55943164}],"con":true,"img":false}]}
{"op":"mcm","clk":"11450243413","pt":1717319549744,"mc":[{"id":"1.229554911","rc":[{"atl":[[8.4,5.97]],"id":55943164}],"con":true,"img":false}]}
{"op":"mcm","clk":"11450243426","pt":1717319549849,"mc":[{"id":"1.229554911","rc":[{"atl":[[8.6,2.72],[8.2,6.05]],"id":55943164}],"con":true,"img":false}]}
{"op":"mcm","clk":"11450245690","pt":1717319574589,"mc":[{"id":"1.229554911","rc":[{"atl":[[8.4,0]],"id":55943164}],"con":true,"img":false}]}
{"op":"mcm","clk":"11450245702","pt":1717319574687,"mc":[{"id":"1.229554911","rc":[{"atl":[[8,5.97]],"id":55943164}],"con":true,"img":false}]}
{"op":"mcm","clk":"11450245710","pt":1717319574790,"mc":[{"id":"1.229554911","rc":[{"atl":[[8.6,14.82],[8.2,0.07]],"id":55943164}],"con":true,"img":false}]}
{"op":"mcm","clk":"11450245722","pt":1717319574905,"mc":[{"id":"1.229554911","rc":[{"atl":[[8.6,2.72],[7.8,5.98]],"id":55943164}],"con":true,"img":false}]}
{"op":"mcm","clk":"11450246146","pt":1717319579591,"mc":[{"id":"1.229554911","rc":[{"atl":[[16.5,0]],"id":54867443}],"con":true,"img":false}]}
{"op":"mcm","clk":"11450246158","pt":1717319579697,"mc":[{"id":"1.229554911","rc":[{"atl":[[15.5,3.66]],"id":54867443}],"con":true,"img":false}]}
{"op":"mcm","clk":"11450246175","pt":1717319579899,"mc":[{"id":"1.229554911","rc":[{"atl":[[16,0],[15,2.9]],"id":54867443}],"con":true,"img":false}]}
{"op":"mcm","clk":"11450246422","pt":1717319582615,"mc":[{"id":"1.229554911","rc":[{"atb":[[1.83,0],[1.93,0]],"id":70003369},{"atl":[[8.2,0]],"id":70003369},{"atb":[[2.42,0],[2.62,0]],"id":69033911},{"atl":[[17,0]],"id":69033911},{"atb":[[1.01,17.35]],"id":69676139},{"atl":[[2.78,0]],"id":69676139},{"atb":[[11,0],[8.4,11.04]],"id":52272946},{"atb":[[1.84,0],[1.94,0]],"id":55943164},{"atl":[[8.2,0]],"id":55943164},{"atb":[[2.38,0],[2.58,0]],"id":54867443},{"atl":[[13.5,0]],"id":54867443}],"con":true,"img":false}]}
{"op":"mcm","clk":"11450246629","pt":1717319584613,"mc":[{"id":"1.229554911","rc":[{"atb":[[1.64,45.77],[1.94,0]],"id":70003369},{"atb":[[2.64,0]],"id":69033911},{"atb":[[1.58,50.51],[1.85,0]],"id":55943164},{"atl":[[15.5,0]],"id":54867443}],"con":true,"img":false}]}
{"op":"mcm","clk":"11450246642","pt":1717319584718,"mc":[{"id":"1.229554911","rc":[{"atb":[[2.1,29.89]],"id":69033911},{"atl":[[18,3.66]],"id":54867443}],"con":true,"img":false}]}
{"op":"mcm","clk":"11450246674","pt":1717319585035,"mc":[{"id":"1.229554911","rc":[{"atl":[[17.5,8.41]],"id":54867443}],"con":true,"img":false}]}
{"op":"mcm","clk":"11450246688","pt":1717319585141,"mc":[{"id":"1.229554911","rc":[{"atl":[[15,0]],"id":54867443}],"con":true,"img":false}]}
{"op":"mcm","clk":"11450247591","pt":1717319595533,"mc":[{"id":"1.229554911","rc":[{"atb":[[1.83,41.97],[1.93,24.97]],"id":70003369},{"atl":[[8.2,0.07]],"id":70003369},{"atb":[[2.42,24.53],[2.62,14.34]],"id":69033911},{"atl":[[17,0.03]],"id":69033911},{"atb":[[1.01,5824.62]],"id":69676139},{"atl":[[2.82,0.28]],"id":69676139},{"atb":[[10.5,2.44],[8.2,4.83]],"id":52272946},{"atb":[[1.79,44.1],[1.89,26.1]],"id":55943164},{"atl":[[7.8,6.05]],"id":55943164},{"atb":[[2.38,25.24],[2.58,14.7]],"id":54867443},{"atl":[[13.5,0.04]],"id":54867443}],"con":true,"img":false}]}
{"op":"mcm","clk":"11450247676","pt":1717319596312,"mc":[{"id":"1.229554911","rc":[{"atb":[[1.88,0]],"id":55943164}],"con":true,"img":false}]}
{"op":"mcm","clk":"11450247956","pt":1717319599648,"mc":[{"id":"1.229554911","rc":[{"spn":1.98,"spf":"NaN","id":69676139},{"atl":[[8,0]],"id":55943164},{"spn":1.89,"spf":1.0,"id":55943164}],"con":true,"img":false}]}
{"op":"mcm","clk":"11450247963","pt":1717319599705,"mc":[{"id":"1.229554911","rc":[{"atl":[[8.6,14.84],[7.6,5.97]],"id":55943164}],"con":true,"img":false}]}
{"op":"mcm","clk":"11450247974","pt":1717319599805,"mc":[{"id":"1.229554911","rc":[{"atl":[[7.8,0.07]],"id":55943164}],"con":true,"img":false}]}
{"op":"mcm","clk":"11450248793","pt":1717319609630,"mc":[{"id":"1.229554911","rc":[{"atl":[[7.6,0]],"id":55943164}],"con":true,"img":false}]}
{"op":"mcm","clk":"11450248801","pt":1717319609735,"mc":[{"id":"1.229554911","rc":[{"atl":[[8.4,5.97]],"id":55943164}],"con":true,"img":false}]}
{"op":"mcm","clk":"11450249306","pt":1717319615637,"mc":[{"id":"1.229554911","rc":[{"atl":[[8.2,6.77]],"id":55943164}],"con":true,"img":false}]}
{"op":"mcm","clk":"11450249315","pt":1717319615736,"mc":[{"id":"1.229554911","rc":[{"atl":[[8.6,2.72]],"id":55943164}],"con":true,"img":false}]}
{"op":"mcm","clk":"11450250148","pt":1717319624630,"mc":[{"id":"1.229554911","rc":[{"atl":[[18,0]],"id":54867443}],"con":true,"img":false}]}
{"op":"mcm","clk":"11450250156","pt":1717319624735,"mc":[{"id":"1.229554911","rc":[{"atl":[[17,3.66]],"id":54867443}],"con":true,"img":false}]}
{"op":"mcm","clk":"11450250165","pt":1717319624843,"mc":[{"id":"1.229554911","rc":[{"atl":[[16.5,3.66],[17.5,2.61]],"id":54867443}],"con":true,"img":false}]}
{"op":"mcm","clk":"11450251037","pt":1717319634654,"mc":[{"id":"1.229554911","rc":[{"atb":[[1.64,0],[1.94,31.16]],"id":70003369},{"atb":[[2.1,0]],"id":69033911},{"atb":[[1.58,0],[1.9,32.55]],"id":55943164}],"con":true,"img":false}]}
{"op":"mcm","clk":"11450251046","pt":1717319634761,"mc":[{"id":"1.229554911","rc":[{"atb":[[2.64,29.89]],"id":69033911}],"con":true,"img":false}]}
{"op":"mcm","clk":"11450251434","pt":1717319639671,"mc":[{"id":"1.229554911","rc":[{"atl":[[8.4,0]],"id":55943164}],"con":true,"img":false}]}
{"op":"mcm","clk":"11450251444","pt":1717319639776,"mc":[{"id":"1.229554911","rc":[{"atl":[[8,5.97],[8.4,6.85]],"id":55943164}],"con":true,"img":false}]}
{"op":"mcm","clk":"11450251451","pt":1717319639878,"mc":[{"id":"1.229554911","rc":[{"atl":[[8.2,0],[7.8,6.05],[8.4,0]],"id":55943164}],"con":true,"img":false}]}
{"op":"mcm","clk":"11450252304","pt":1717319649584,"mc":[{"id":"1.229554911","rc":[{"atl":[[17.5,0]],"id":54867443}],"con":true,"img":false}]}
{"op":"mcm","clk":"11450252309","pt":1717319649678,"mc":[{"id":"1.229554911","rc":[{"atl":[[16,2.61]],"id":54867443}],"con":true,"img":false}]}
{"op":"mcm","clk":"11450252389","pt":1717319650709,"mc":[{"id":"1.229554911","rc":[{"atb":[[1.98,0]],"id":70003369},{"atb":[[2.7,0]],"id":69033911},{"atb":[[2.44,0]],"id":54867443}],"con":true,"img":false}]}
{"op":"mcm","clk":"11450253640","pt":1717319664600,"mc":[{"id":"1.229554911","rc":[{"spn":5.07,"spf":"NaN","id":70003369},{"spn":9.57,"spf":"NaN","id":69033911},{"atl":[[8,0]],"id":55943164},{"spn":1.9,"spf":1.0,"id":55943164},{"atl":[[17,0]],"id":54867443}],"con":true,"img":false}]}
{"op":"mcm","clk":"11450253653","pt":1717319664701,"mc":[{"id":"1.229554911","rc":[{"atl":[[8.6,14.84],[7.6,5.97]],"id":55943164},{"atl":[[16,6.27]],"id":54867443}],"con":true,"img":false}]}
{"op":"mcm","clk":"11450253658","pt":1717319664801,"mc":[{"id":"1.229554911","rc":[{"atl":[[7.8,0.07]],"id":55943164}],"con":true,"img":false}]}
{"op":"mcm","clk":"11450253667","pt":1717319664905,"mc":[{"id":"1.229554911","rc":[{"atl":[[8.6,2.72],[7.8,12.03]],"id":55943164},{"atl":[[16.5,0],[15.5,3.66]],"id":54867443}],"con":true,"img":false}]}
{"op":"mcm","clk":"11450255867","pt":1717319689663,"mc":[{"id":"1.229554911","rc":[{"atl":[[16,3.66]],"id":54867443}],"con":true,"img":false}]}
{"op":"mcm","clk":"11450255875","pt":1717319689718,"mc":[{"id":"1.229554911","rc":[{"atl":[[15,2.61]],"id":54867443}],"con":true,"img":false}]}
{"op":"mcm","clk":"11450257258","pt":1717319704633,"mc":[{"id":"1.229554911","rc":[{"atl":[[16,0]],"id":54867443}],"con":true,"img":false}]}
{"op":"mcm","clk":"11450257265","pt":1717319704737,"mc":[{"id":"1.229554911","rc":[{"atl":[[15,6.27]],"id":54867443}],"con":true,"img":false}]}
{"op":"mcm","clk":"11450257272","pt":1717319704841,"mc":[{"id":"1.229554911","rc":[{"atl":[[14.5,3.66],[15.5,0]],"id":54867443}],"con":true,"img":false}]}
{"op":"mcm","clk":"11450257676","pt":1717319709546,"mc":[{"id":"1.229554911","rc":[{"atl":[[15,2.61]],"id":54867443}],"con":true,"img":false}]}
{"op":"mcm","clk":"11450257684","pt":1717319709652,"mc":[{"id":"1.229554911","rc":[{"atl":[[17.5,3.66]],"id":54867443}],"con":true,"img":false}]}
{"op":"mcm","clk":"11450257813","pt":1717319711253,"mc":[{"id":"1.229554911","rc":[{"atb":[[2.44,2.72]],"id":54867443}],"con":true,"img":false}]}
{"op":"mcm","clk":"11450257836","pt":1717319711462,"mc":[{"id":"1.229554911","rc":[{"atb":[[1.98,4]],"id":70003369},{"atb":[[1.94,4.17]],"id":55943164}],"con":true,"img":false}]}
{"op":"mcm","clk":"11450257857","pt":1717319711665,"mc":[{"id":"1.229554911","rc":[{"atb":[[1.01,113.13]],"id":69033911}],"con":true,"img":false}]}
{"op":"mcm","clk":"11450258015","pt":1717319713277,"mc":[{"id":"1.229554911","rc":[{"atb":[[1.01,113.08]],"id":69033911}],"con":true,"img":false}]}
{"op":"mcm","clk":"11450258091","pt":1717319714058,"mc":[{"id":"1.229554911","rc":[{"atb":[[1.01,110.77]],"id":69033911}],"con":true,"img":false}]}
{"op":"mcm","clk":"11450258099","pt":1717319714155,"mc":[{"id":"1.229554911","rc":[{"atb":[[2.7,2.3]],"id":69033911}],"con":true,"img":false}]}
{"op":"mcm","clk":"11450258916","pt":1717319721793,"mc":[{"id":"1.229554911","rc":[{"atl":[[8.6,0]],"id":55943164}],"con":true,"img":false}]}
{"op":"mcm","clk":"11450258932","pt":1717319722003,"mc":[{"id":"1.229554911","rc":[{"atl":[[8.6,1.62]],"id":55943164}],"con":true,"img":false}]}
{"op":"mcm","clk":"11450272572","pt":1717319882376,"mc":[{"id":"1.229554911","rc":[{"atb":[[1.97,2.13]],"id":70003369},{"spn":5.09,"spf":"NaN","id":70003369},{"spn":9.6,"spf":"NaN","id":69033911},{"atb":[[1.93,2.13]],"id":55943164},{"spn":1.94,"spf":1.0,"id":55943164},{"atb":[[2.64,2.13]],"id":54867443},{"spn":8.07,"spf":"NaN","id":54867443}],"con":true,"img":false}]}
{"op":"mcm","clk":"11450276233","pt":1717319929496,"mc":[{"id":"1.229554911","rc":[{"atb":[[1.83,0],[1.93,0]],"id":70003369},{"atl":[[8.2,0]],"id":70003369},{"atb":[[2.42,0],[2.62,0]],"id":69033911},{"atl":[[17,0]],"id":69033911},{"atb":[[1.01,17.35]],"id":69676139},{"atl":[[2.82,0]],"id":69676139},{"atb":[[10.5,0],[8.2,0]],"id":52272946},{"atb":[[1.79,0],[1.89,0]],"id":55943164},{"atl":[[7.8,11.96]],"id":55943164},{"atb":[[2.38,0],[2.58,0]],"id":54867443},{"atl":[[13.5,0]],"id":54867443}],"con":true,"img":false}]}
{"op":"mcm","clk":"11450276257","pt":1717319929706,"mc":[{"id":"1.229554911","rc":[{"atl":[[14.5,0],[15,9.75]],"id":54867443}],"con":true,"img":false}]}
{"op":"mcm","clk":"11450276592","pt":1717319934588,"mc":[{"id":"1.229554911","rc":[{"atb":[[1.64,45.77],[1.94,0]],"id":70003369},{"atb":[[2.64,0]],"id":69033911},{"atb":[[1.59,49.65],[1.9,0]],"id":55943164}],"con":true,"img":false}]}
{"op":"mcm","clk":"11450276603","pt":1717319934693,"mc":[{"id":"1.229554911","rc":[{"atb":[[2.1,29.89]],"id":69033911}],"con":true,"img":false}]}
{"op":"mcm","clk":"11450276673","pt":1717319935619,"mc":[{"id":"1.229554911","rc":[{"atb":[[2.16,2.13]],"id":69033911}],"con":true,"img":false}]}
{"op":"mcm","clk":"11450276745","pt":1717319936600,"mc":[{"id":"1.229554911","rc":[{"atb":[[1.94,0]],"id":55943164},{"atb":[[2.44,0]],"id":54867443}],"con":true,"img":false}]}
{"op":"mcm","clk":"11450276990","pt":1717319939602,"mc":[{"id":"1.229554911","rc":[{"atb":[[1.83,41.97],[1.93,24.97]],"id":70003369},{"atl":[[8.2,0.07]],"id":70003369},{"atb":[[2.4,24.88],[2.6,14.51]],"id":69033911},{"atl":[[16.5,5.26]],"id":69033911},{"atb":[[1.01,3501.71],[1.02,1161.45]],"id":69676139},{"atl":[[2.82,0.28]],"id":69676139},{"atb":[[8.6,4.58],[11.5,2.21]],"id":52272946},{"atb":[[1.88,26.39],[1.78,44.66]],"id":55943164},{"atl":[[7.8,12.03]],"id":55943164},{"atb":[[2.56,14.88],[2.36,25.61]],"id":54867443},{"atl":[[15.5,0.03]],"id":54867443}],"con":true,"img":false}]}
{"op":"mcm","clk":"11450278072","pt":1717319952005,"mc":[{"id":"1.229554911","rc":[{"atb":[[1.81,4.84]],"id":55943164},{"spn":1.92,"spf":1.0,"id":55943164},{"atb":[[2.42,2.76]],"id":54867443},{"spn":8.82,"spf":"NaN","id":54867443}],"con":true,"img":false}]}
{"op":"mcm","clk":"11450280216","pt":1717319979652,"mc":[{"id":"1.229554911","rc":[{"atb":[[1.64,0],[1.94,31.16]],"id":70003369},{"atb":[[2.1,0]],"id":69033911},{"atb":[[1.59,0],[1.89,32.91]],"id":55943164}],"con":true,"img":false}]}
{"op":"mcm","clk":"11450280220","pt":1717319979752,"mc":[{"id":"1.229554911","rc":[{"atb":[[2.62,29.89]],"id":69033911}],"con":true,"img":false}]}
{"op":"mcm","clk":"11450280363","pt":1717319981776,"mc":[{"id":"1.229554911","rc":[{"atb":[[1.81,0]],"id":55943164}],"con":true,"img":false}]}
{"op":"mcm","clk":"11450280379","pt":1717319981978,"mc":[{"id":"1.229554911","rc":[{"atb":[[1.93,6.34]],"id":55943164}],"con":true,"img":false}]}
{"op":"mcm","clk":"11450281639","pt":1717319996984,"mc":[{"id":"1.229554911","rc":[{"atb":[[1.98,0]],"id":70003369},{"atb":[[2.7,0]],"id":69033911}],"con":true,"img":false}]}
{"op":"mcm","clk":"11450282796","pt":1717320011432,"mc":[{"id":"1.229554911","rc":[{"atb":[[1.98,4]],"id":70003369},{"atb":[[1.01,113.13]],"id":69033911}],"con":true,"img":false}]}
{"op":"mcm","clk":"11450282817","pt":1717320011597,"mc":[{"id":"1.229554911","rc":[{"atb":[[1.01,113.11]],"id":69033911}],"con":true,"img":false}]}
{"op":"mcm","clk":"11450282843","pt":1717320011907,"mc":[{"id":"1.229554911","rc":[{"atb":[[1.01,110.77]],"id":69033911}],"con":true,"img":false}]}
{"op":"mcm","clk":"11450282853","pt":1717320012012,"mc":[{"id":"1.229554911","rc":[{"atb":[[2.68,2.33]],"id":69033911},{"spn":9.59,"spf":"NaN","id":69033911},{"spn":1.93,"spf":1.0,"id":55943164}],"con":true,"img":false}]}
{"op":"mcm","clk":"11450288156","pt":1717320090376,"mc":[{"id":"1.229554911","rc":[{"atl":[[8.6,0]],"id":55943164}],"con":true,"img":false}]}
{"op":"mcm","clk":"11450289241","pt":1717320107631,"mc":[{"id":"1.229554911","rc":[{"atl":[[8.6,2.34]],"id":55943164}],"con":true,"img":false}]}
{"op":"mcm","clk":"11450289677","pt":1717320114325,"mc":[{"id":"1.229554911","rc":[{"atb":[[1.83,0],[1.93,0]],"id":70003369},{"atl":[[8.2,0]],"id":70003369},{"atb":[[1.88,0],[1.78,0]],"id":55943164},{"atl":[[7.8,11.96]],"id":55943164}],"con":true,"img":false}]}
{"op":"mcm","clk":"11450289698","pt":1717320114643,"mc":[{"id":"1.229554911","rc":[{"atb":[[1.64,45.77],[1.94,0]],"id":70003369},{"atb":[[1.6,48.82],[1.89,0]],"id":55943164}],"con":true,"img":false}]}
{"op":"mcm","clk":"11450290616","pt":1717320127067,"mc":[{"id":"1.229554911","rc":[{"atl":[[8,14.29],[7.8,0]],"id":55943164}],"con":true,"img":false}]}
{"op":"mcm","clk":"11450290812","pt":1717320129762,"mc":[{"id":"1.229554911","rc":[{"atb":[[1.85,40.99],[1.95,24.45]],"id":70003369},{"atl":[[8.2,0.07]],"id":70003369},{"atb":[[1.84,41.48],[1.94,24.7]],"id":55943164},{"atl":[[8.2,0.07]],"id":55943164}],"con":true,"img":false}]}
{"op":"mcm","clk":"11450291161","pt":1717320134670,"mc":[{"id":"1.229554911","rc":[{"atl":[[7.6,0]],"id":55943164}],"con":true,"img":false}]}
{"op":"mcm","clk":"11450291170","pt":1717320134780,"mc":[{"id":"1.229554911","rc":[{"atl":[[8,0],[7.8,5.97],[8.4,13.51]],"id":55943164}],"con":true,"img":false}]}
{"op":"mcm","clk":"11450291371","pt":1717320137681,"mc":[{"id":"1.229554911","rc":[{"atl":[[8,11.96]],"id":55943164}],"con":true,"img":false}]}
{"op":"mcm","clk":"11450291379","pt":1717320137741,"mc":[{"id":"1.229554911","rc":[{"atl":[[8.4,0]],"id":55943164}],"con":true,"img":false}]}
{"op":"mcm","clk":"11450291456","pt":1717320138874,"mc":[{"id":"1.229554911","rc":[{"atl":[[8.6,0]],"id":55943164}],"con":true,"img":false}]}
{"op":"mcm","clk":"11450293601","pt":1717320169599,"mc":[{"id":"1.229554911","rc":[{"atb":[[1.64,0],[1.96,30.51]],"id":70003369},{"atb":[[1.6,0],[1.85,34.46]],"id":55943164},{"spn":1.94,"spf":1.0,"id":55943164}],"con":true,"img":false}]}
{"op":"mcm","clk":"11450294105","pt":1717320177234,"mc":[{"id":"1.229554911","rc":[{"atb":[[1.98,0]],"id":70003369},{"atb":[[1.93,2.13]],"id":55943164}],"con":true,"img":false}]}
{"op":"mcm","clk":"11450295098","pt":1717320192044,"mc":[{"id":"1.229554911","rc":[{"atb":[[1.88,4.45]],"id":55943164}],"con":true,"img":false}]}
{"op":"mcm","clk":"11450295119","pt":1717320192250,"mc":[{"id":"1.229554911","rc":[{"atb":[[2,3.92]],"id":70003369}],"con":true,"img":false}]}
{"op":"mcm","clk":"11450299894","pt":1717320264715,"mc":[{"id":"1.229554911","rc":[{"spn":5.1,"spf":"NaN","id":70003369},{"atl":[[4.1,0]],"id":69676139}],"con":true,"img":false}]}
{"op":"mcm","clk":"11450299897","pt":1717320264821,"mc":[{"id":"1.229554911","rc":[{"atl":[[3.75,13.5]],"id":69676139}],"con":true,"img":false}]}
{"op":"mcm","clk":"11450301909","pt":1717320295150,"mc":[{"id":"1.229554911","rc":[{"atl":[[8.6,1.92]],"id":55943164}],"con":true,"img":false}]}
{"op":"mcm","clk":"11450302606","pt":1717320306082,"mc":[{"id":"1.229554911","rc":[{"atb":[[1.85,0],[1.95,0]],"id":70003369},{"atl":[[8.2,0]],"id":70003369},{"atb":[[2.4,0],[2.6,0]],"id":69033911},{"atl":[[16.5,5.23]],"id":69033911},{"atb":[[1.01,17.35],[1.02,0]],"id":69676139},{"atl":[[2.82,0]],"id":69676139},{"atb":[[8.6,0],[11.5,0]],"id":52272946},{"atb":[[1.84,0],[1.94,0]],"id":55943164},{"atl":[[8.2,0]],"id":55943164},{"atb":[[2.56,0],[2.36,0]],"id":54867443},{"atl":[[15.5,0]],"id":54867443}],"con":true,"img":false}]}
{"op":"mcm","clk":"11450302829","pt":1717320309592,"mc":[{"id":"1.229554911","rc":[{"atb":[[1.96,0],[1.65,45.07]],"id":70003369},{"atb":[[2.62,0]],"id":69033911},{"atb":[[1.85,0]],"id":55943164}],"con":true,"img":false}]}
{"op":"mcm","clk":"11450302835","pt":1717320309699,"mc":[{"id":"1.229554911","rc":[{"atb":[[2.1,29.89]],"id":69033911},{"atb":[[1.61,34.46]],"id":55943164}],"con":true,"img":false}]}
{"op":"mcm","clk":"11450303483","pt":1717320319402,"mc":[{"id":"1.229554911","rc":[{"atl":[[8.6,0]],"id":55943164}],"con":true,"img":false}]}
{"op":"mcm","clk":"11450303916","pt":1717320326605,"mc":[{"id":"1.229554911","rc":[{"atb":[[1.8,43.55],[1.9,25.8]],"id":70003369},{"atl":[[8,0.07]],"id":70003369},{"spn":5.0,"spf":"NaN","id":70003369},{"atb":[[2.42,24.53],[2.62,14.34]],"id":69033911},{"atl":[[17,0.03]],"id":69033911},{"atb":[[1.01,5824.62]],"id":69676139},{"atl":[[2.78,0.29]],"id":69676139},{"spn":1.96,"spf":"NaN","id":69676139},{"atb":[[10.5,2.44],[8.2,4.83]],"id":52272946},{"atb":[[1.8,43.55],[1.9,25.8]],"id":55943164},{"atl":[[8,12.03]],"id":55943164},{"spn":1.92,"spf":1.0,"id":55943164},{"atb":[[2.64,16.29],[2.44,24.19]],"id":54867443},{"atl":[[17.5,3.69]],"id":54867443}],"con":true,"img":false}]}
{"op":"mcm","clk":"11450303985","pt":1717320327601,"mc":[{"id":"1.229554911","rc":[{"atb":[[2.42,0]],"id":54867443}],"con":true,"img":false}]}
{"op":"mcm","clk":"11450303997","pt":1717320327811,"mc":[{"id":"1.229554911","rc":[{"atb":[[2.5,2.61]],"id":54867443}],"con":true,"img":false}]}
{"op":"mcm","clk":"11450306077","pt":1717320364682,"mc":[{"id":"1.229554911","rc":[{"atb":[[1.65,0]],"id":70003369},{"atb":[[2.1,0]],"id":69033911},{"atb":[[1.61,0]],"id":55943164}],"con":true,"img":false}]}
{"op":"mcm","clk":"11450306081","pt":1717320364792,"mc":[{"id":"1.229554911","rc":[{"atb":[[2,9.72],[2.42,2.5],[1.91,45.07],[2.26,10],[2.34,5]],"id":70003369},{"atl":[[9.6,5.8],[5.1,5],[5.5,10],[4.7,2.5]],"id":70003369},{"atb":[[3,2.5],[2.64,29.89],[2.84,10],[2.92,5],[2.68,8.61]],"id":69033911},{"atl":[[8,10],[16,5.33],[7.2,5],[6.4,2.5]],"id":69033911},{"atb":[[1.82,2.5],[1.91,34.46],[1.93,11.69]],"id":55943164},{"atl":[[4.8,5],[7.6,9.56],[5.2,10],[4.4,2.5]],"id":55943164}],"con":true,"img":false}]}
{"op":"mcm","clk":"11450306089","pt":1717320364880,"mc":[{"id":"1.229554911","rc":[{"atl":[[8,3.87],[9.8,0]],"id":70003369},{"atl":[[16.5,2.61],[11.5,3.14]],"id":69033911}],"con":true,"img":false}]}
{"op":"mcm","clk":"11450306094","pt":1717320364997,"mc":[{"id":"1.229554911","rc":[{"atb":[[1.18,10],[1.26,2.5],[1.14,201.93],[1.22,5]],"id":69676139},{"atl":[[3.7,29.63],[2.84,10],[2.68,2.5],[2.76,5]],"id":69676139},{"atb":[[2.3,2.5],[2.22,5],[2.14,10]],"id":54867443},{"atl":[[6.2,2.5],[7,5],[7.8,10],[14.5,5.93]],"id":54867443}],"con":true,"img":false}]}
{"op":"mcm","clk":"11450306099","pt":1717320365039,"mc":[{"id":"1.229554911","rc":[{"atl":[[11.5,3.69],[15,2.61]],"id":54867443}],"con":true,"img":false}]}
{"op":"mcm","clk":"11450306497","pt":1717320372673,"mc":[{"id":"1.229554911","rc":[{"atb":[[2,5.8]],"id":70003369},{"atb":[[2.68,6.28]],"id":69033911},{"atb":[[1.88,0]],"id":55943164}],"con":true,"img":false}]}
{"op":"mcm","clk":"11450306515","pt":1717320372981,"mc":[{"id":"1.229554911","rc":[{"atb":[[1.95,4.12]],"id":70003369}],"con":true,"img":false}]}
{"op":"mcm","clk":"11450306520","pt":1717320373084,"mc":[{"id":"1.229554911","rc":[{"atb":[[2.5,0]],"id":54867443}],"con":true,"img":false}]}
{"op":"mcm","clk":"11450306606","pt":1717320374587,"mc":[{"id":"1.229554911","rc":[{"atb":[[1.95,0]],"id":69033911},{"atl":[[5.2,15.17]],"id":69676139},{"atb":[[17.5,0],[11,5.78]],"id":52272946},{"atb":[[1.85,0]],"id":54867443}],"con":true,"img":false}]}
{"op":"mcm","clk":"11450306611","pt":1717320374690,"mc":[{"id":"1.229554911","rc":[{"atb":[[1.82,64.87]],"id":69033911},{"atl":[[4.3,0]],"id":69676139},{"atb":[[13,2.61],[15,0]],"id":52272946},{"atb":[[1.76,71.15]],"id":54867443}],"con":true,"img":false}]}
{"op":"mcm","clk":"11450306909","pt":1717320379613,"mc":[{"id":"1.229554911","rc":[{"atb":[[2.64,0]],"id":69033911}],"con":true,"img":false}]}
{"op":"mcm","clk":"11450306919","pt":1717320379670,"mc":[{"id":"1.229554911","rc":[{"atb":[[2.44,29.89]],"id":69033911}],"con":true,"img":false}]}
{"op":"mcm","clk":"11450307075","pt":1717320382192,"mc":[{"id":"1.229554911","rc":[{"atb":[[2.42,10]],"id":70003369},{"atl":[[4.6,7.5]],"id":70003369},{"atb":[[3,10]],"id":69033911},{"atl":[[6.2,7.5]],"id":69033911},{"atl":[[4.3,16.27]],"id":55943164}],"con":true,"img":false}]}
{"op":"mcm","clk":"11450307088","pt":1717320382400,"mc":[{"id":"1.229554911","rc":[{"atb":[[2,0]],"id":70003369},{"atl":[[9.6,0]],"id":70003369},{"atb":[[2.68,0]],"id":69033911},{"atl":[[16,0]],"id":69033911},{"atb":[[1.26,8.12]],"id":69676139},{"atl":[[2.66,5.62]],"id":69676139},{"atl":[[7.6,0]],"id":55943164},{"atl":[[6,11.25]],"id":54867443}],"con":true,"img":false}]}
{"op":"mcm","clk":"11450307100","pt":1717320382567,"mc":[{"id":"1.229554911","rc":[{"atb":[[1.14,107.09]],"id":69676139},{"atl":[[3.7,0]],"id":69676139},{"atl":[[14.5,0]],"id":54867443}],"con":true,"img":false}]}
{"op":"mcm","clk":"11450307451","pt":1717320387784,"mc":[{"id":"1.229554911","rc":[{"atb":[[1.58,0]],"id":70003369},{"spn":3.51,"spf":"NaN","id":70003369},{"atb":[[1.99,0]],"id":69033911},{"spn":4.6,"spf":"NaN","id":69033911},{"spn":256.5,"spf":"NaN","id":52272946},{"spn":1.93,"spf":1.0,"id":55943164},{"atb":[[1.88,0]],"id":54867443},{"spn":4.32,"spf":"NaN","id":54867443}],"con":true,"img":false}]}
{"op":"mcm","clk":"11450307468","pt":1717320387994,"mc":[{"id":"1.229554911","rc":[{"atb":[[2.5,2.61]],"id":69033911}],"con":true,"img":false}]}
{"op":"mcm","clk":"11450307553","pt":1717320389595,"mc":[{"id":"1.229554911","rc":[{"atb":[[2.02,0]],"id":54867443}],"con":true,"img":false}]}
{"op":"mcm","clk":"11450307559","pt":1717320389698,"mc":[{"id":"1.229554911","rc":[{"atb":[[2.16,28.72]],"id":54867443}],"con":true,"img":false}]}
{"op":"mcm","clk":"11450307811","pt":1717320394571,"mc":[{"id":"1.229554911","rc":[{"atl":[[11,4.18]],"id":54867443}],"con":true,"img":false}]}
{"op":"mcm","clk":"11450307817","pt":1717320394679,"mc":[{"id":"1.229554911","rc":[{"atl":[[16.5,0]],"id":69033911},{"atl":[[3.75,0]],"id":69676139},{"atl":[[15,0]],"id":54867443}],"con":true,"img":false}]}
{"op":"mcm","clk":"11450307822","pt":1717320394781,"mc":[{"id":"1.229554911","rc":[{"atl":[[13.5,2.61]],"id":69033911},{"atl":[[4.4,13.5]],"id":69676139}],"con":true,"img":false}]}
{"op":"mcm","clk":"11450308250","pt":1717320402121,"mc":[{"id":"1.229554911","rc":[{"atb":[[13,0]],"id":52272946}],"con":true,"img":false}]}
{"op":"mcm","clk":"11450308258","pt":1717320402222,"mc":[{"id":"1.229554911","rc":[{"atb":[[14.5,2.61]],"id":52272946}],"con":true,"img":false}]}
{"op":"mcm","clk":"11450308437","pt":1717320404628,"mc":[{"id":"1.229554911","rc":[{"atl":[[10,0]],"id":70003369}],"con":true,"img":false}]}
{"op":"mcm","clk":"11450308446","pt":1717320404725,"mc":[{"id":"1.229554911","rc":[{"atl":[[9.2,3.8]],"id":70003369}],"con":true,"img":false}]}
{"op":"mcm","clk":"11450308698","pt":1717320409122,"mc":[{"id":"1.229554911","rc":[{"atb":[[2.64,28.48]],"id":54867443}],"con":true,"img":false}]}
{"op":"mcm","clk":"11450308731","pt":1717320409592,"mc":[{"id":"1.229554911","rc":[{"atb":[[1.25,66.96]],"id":69676139},{"atl":[[280,0.15]],"id":52272946}],"con":true,"img":false}]}
{"op":"mcm","clk":"11450308738","pt":1717320409701,"mc":[{"id":"1.229554911","rc":[{"atb":[[1.14,0]],"id":69676139},{"atl":[[500,0]],"id":52272946}],"con":true,"img":false}]}
{"op":"mcm","clk":"11450309488","pt":1717320422206,"mc":[{"id":"1.229554911","rc":[{"atb":[[1.95,8.61]],"id":70003369}],"con":true,"img":false}]}
{"op":"mcm","clk":"11450309672","pt":1717320424588,"mc":[{"id":"1.229554911","rc":[{"atl":[[16.5,4.18],[19.5,0]],"id":69033911},{"atb":[[11,0]],"id":52272946},{"atl":[[17.5,0.03]],"id":54867443}],"con":true,"img":false}]}
{"op":"mcm","clk":"11450309678","pt":1717320424692,"mc":[{"id":"1.229554911","rc":[{"atb":[[12.5,5.78]],"id":52272946},{"atl":[[15.5,3.66]],"id":54867443}],"con":true,"img":false}]}
{"op":"mcm","clk":"11450310013","pt":1717320429264,"mc":[{"id":"1.229554911","rc":[{"atb":[[1.22,291.7],[1.13,0]],"id":69676139},{"atl":[[550,0]],"id":52272946}],"con":true,"img":false}]}
{"op":"mcm","clk":"11450310016","pt":1717320429368,"mc":[{"id":"1.229554911","rc":[{"atl":[[300,2.61]],"id":52272946}],"con":true,"img":false}]}
{"op":"mcm","clk":"11450310100","pt":1717320430628,"mc":[{"id":"1.229554911","rc":[{"atl":[[5.1,0],[4.6,10],[5,5],[5.5,0],[4.7,0],[5.4,10]],"id":70003369},{"atb":[[3,7.5],[2.84,0],[2.94,5],[3.05,2.5],[2.92,0],[2.86,10]],"id":69033911},{"atb":[[1.82,0],[1.9,30.8],[1.86,10],[1.94,2.5]],"id":55943164}],"con":true,"img":false}]}
{"op":"mcm","clk":"11450310113","pt":1717320430725,"mc":[{"id":"1.229554911","rc":[{"atl":[[2.52,2.5],[2.6,5],[2.84,0],[2.76,0]],"id":69676139},{"atb":[[2.3,0],[2.22,0],[2.26,5],[2.14,0],[2.34,2.5]],"id":54867443}],"con":true,"img":false}]}
{"op":"mcm","clk":"11450310120","pt":1717320430769,"mc":[{"id":"1.229554911","rc":[{"atb":[[3.05,10]],"id":69033911},{"atl":[[2.64,10.3]],"id":69676139},{"atb":[[1.94,15.02]],"id":55943164},{"atl":[[6.2,0],[6,13.75],[6.8,5],[7.6,10],[7,0],[7.8,0]],"id":54867443}],"con":true,"img":false}]}
{"op":"mcm","clk":"11450310137","pt":1717320431033,"mc":[{"id":"1.229554911","rc":[{"atb":[[3,0]],"id":69033911},{"atl":[[2.66,0]],"id":69676139},{"atb":[[1.93,2.13]],"id":55943164}],"con":true,"img":false}]}
{"op":"mcm","clk":"11450310146","pt":1717320431106,"mc":[{"id":"1.229554911","rc":[{"atb":[[1.97,2.13],[1.93,0]],"id":55943164}],"con":true,"img":false}]}
{"op":"mcm","clk":"11450310343","pt":1717320433793,"mc":[{"id":"1.229554911","rc":[{"atb":[[1.18,0],[1.25,71.96],[1.21,10],[1.26,5.62],[1.22,286.7],[1.29,2.5]],"id":69676139},{"atl":[[4.8,0],[4.3,18.77],[5.1,10],[5.2,0],[4.4,0],[4.7,5]],"id":55943164}],"con":true,"img":false}]}
{"op":"mcm","clk":"11450310348","pt":1717320433878,"mc":[{"id":"1.229554911","rc":[{"atb":[[1.29,10.47]],"id":69676139}],"con":true,"img":false}]}
{"op":"mcm","clk":"11450310352","pt":1717320433994,"mc":[{"id":"1.229554911","rc":[{"atb":[[1.26,0]],"id":69676139}],"con":true,"img":false}]}
{"op":"mcm","clk":"11450310524","pt":1717320436790,"mc":[{"id":"1.229554911","rc":[{"atb":[[1.8,0],[1.9,0]],"id":70003369},{"atl":[[8,3.8]],"id":70003369},{"atb":[[2.42,0],[2.62,0]],"id":69033911},{"atl":[[17,0]],"id":69033911},{"atb":[[1.01,17.35]],"id":69676139},{"atl":[[2.78,0]],"id":69676139},{"atb":[[10.5,0],[8.2,0]],"id":52272946},{"atb":[[1.8,0],[1.9,5]],"id":55943164},{"atl":[[8,11.96]],"id":55943164},{"atb":[[2.64,14.32],[2.44,0]],"id":54867443},{"atl":[[17.5,0]],"id":54867443}],"con":true,"img":false}]}
{"op":"mcm","clk":"11450311071","pt":1717320444710,"mc":[{"id":"1.229554911","rc":[{"atb":[[2.44,0]],"id":69033911},{"atb":[[1.91,0]],"id":55943164},{"atb":[[2.16,0]],"id":54867443},{"atl":[[11,0]],"id":54867443}],"con":true,"img":false}]}
{"op":"mcm","clk":"11450311081","pt":1717320444813,"mc":[{"id":"1.229554911","rc":[{"atb":[[2,29.89]],"id":69033911},{"atb":[[1.87,34.46]],"id":55943164},{"atb":[[1.92,28.72]],"id":54867443},{"atl":[[12.5,4.18]],"id":54867443}],"con":true,"img":false}]}
{"op":"mcm","clk":"11450311216","pt":1717320446894,"mc":[{"id":"1.229554911","rc":[{"atl":[[2.5,15.58]],"id":69676139},{"atb":[[1.97,13.38]],"id":55943164}],"con":true,"img":false}]}
{"op":"mcm","clk":"11450311234","pt":1717320447095,"mc":[{"id":"1.229554911","rc":[{"atl":[[2.64,0]],"id":69676139},{"atb":[[1.94,2.5]],"id":55943164}],"con":true,"img":false}]}
{"op":"mcm","clk":"11450311345","pt":1717320448702,"mc":[{"id":"1.229554911","rc":[{"atb":[[2.5,0]],"id":69033911},{"spn":4.62,"spf":"NaN","id":69033911},{"spn":1.89,"spf":"NaN","id":69676139},{"spn":147.25,"spf":"NaN","id":52272946},{"spn":1.97,"spf":1.0,"id":55943164},{"atb":[[1.96,4.09]],"id":54867443}],"con":true,"img":false}]}
{"op":"mcm","clk":"11450311618","pt":1717320453118,"mc":[{"id":"1.229554911","rc":[{"atb":[[1.91,0]],"id":70003369}],"con":true,"img":false}]}
{"op":"mcm","clk":"11450311624","pt":1717320453224,"mc":[{"id":"1.229554911","rc":[{"atb":[[1.67,45.07]],"id":70003369}],"con":true,"img":false}]}
{"op":"mcm","clk":"11450311730","pt":1717320455160,"mc":[{"id":"1.229554911","rc":[{"atb":[[1.8,43.55],[1.9,25.8]],"id":70003369},{"atl":[[8,3.87]],"id":70003369},{"atb":[[2.64,14.16],[2.44,24.19]],"id":69033911},{"atl":[[17.5,0.03]],"id":69033911},{"atb":[[1.01,5824.62]],"id":69676139},{"atl":[[2.76,0.29]],"id":69676139},{"atb":[[10.5,2.44],[8.2,4.83]],"id":52272946},{"atb":[[1.86,50.51],[1.96,24.19]],"id":55943164},{"atl":[[8.4,0.07]],"id":55943164},{"atb":[[2.42,24.53],[2.62,14.34]],"id":54867443},{"atl":[[17,0.03]],"id":54867443}],"con":true,"img":false}]}
{"op":"mcm","clk":"11450312356","pt":1717320465444,"mc":[{"id":"1.229554911","rc":[{"atb":[[1.95,4.12]],"id":70003369},{"atb":[[1.53,0]],"id":55943164}],"con":true,"img":false}]}
{"op":"mcm","clk":"11450313455","pt":1717320484660,"mc":[{"id":"1.229554911","rc":[{"atb":[[1.67,0]],"id":70003369},{"atb":[[2,0]],"id":69033911}],"con":true,"img":false}]}
{"op":"mcm","clk":"11450313459","pt":1717320484756,"mc":[{"id":"1.229554911","rc":[{"atb":[[1.91,45.07]],"id":70003369},{"atb":[[2.46,29.89]],"id":69033911}],"con":true,"img":false}]}
{"op":"mcm","clk":"11450313698","pt":1717320489289,"mc":[{"id":"1.229554911","rc":[{"atl":[[3.85,26.32],[3.95,42.37],[3.65,7.55],[3.75,18.18]],"id":70003369},{"atl":[[5.8,15.62],[5.4,4.55],[5.6,10.87],[6,25]],"id":69033911},{"atl":[[2,20],[2.04,48.08],[2.12,111.61],[2.08,69.44]],"id":69676139},{"atb":[[9,15.62],[10.5,4.55],[9.8,5.68],[9.4,8.93]],"id":52272946},{"atl":[[5.1,14.88],[5.3,11.63],[5.5,16.67],[5.7,26.6]],"id":55943164},{"atl":[[5.4,17.05],[5.6,27.17],[5,5],[5.2,11.9]],"id":54867443}],"con":true,"img":false}]}
{"op":"mcm","clk":"11450313704","pt":1717320489391,"mc":[{"id":"1.229554911","rc":[{"atl":[[4.5,3.75]],"id":70003369},{"atl":[[5.4,19.55]],"id":69033911},{"atl":[[2.48,7.85]],"id":69676139},{"atl":[[5.9,10.74]],"id":54867443}],"con":true,"img":false}]}
{"op":"mcm","clk":"11450313710","pt":1717320489493,"mc":[{"id":"1.229554911","rc":[{"atl":[[4.6,2.5]],"id":70003369},{"atl":[[6.2,0]],"id":69033911},{"atl":[[2.5,0]],"id":69676139},{"atl":[[6,2.5]],"id":54867443}],"con":true,"img":false}]}
{"op":"mcm","clk":"11450313718","pt":1717320489653,"mc":[{"id":"1.229554911","rc":[{"atl":[[5.2,0]],"id":69676139}],"con":true,"img":false}]}
{"op":"mcm","clk":"11450313723","pt":1717320489753,"mc":[{"id":"1.229554911","rc":[{"atl":[[5.5,15.17]],"id":69676139}],"con":true,"img":false}]}
{"op":"mcm","clk":"11450313926","pt":1717320493289,"mc":[{"id":"1.229554911","rc":[{"atb":[[1.8,0],[1.9,0]],"id":70003369},{"atl":[[8,3.8]],"id":70003369},{"atb":[[2.64,0],[2.44,0]],"id":69033911},{"atl":[[17.5,0]],"id":69033911},{"atb":[[1.01,17.35]],"id":69676139},{"atl":[[2.76,0]],"id":69676139},{"atb":[[1.96,0],[1.86,10]],"id":55943164},{"atl":[[8.4,0]],"id":55943164},{"atb":[[2.42,0],[2.62,0]],"id":54867443},{"atl":[[6.8,0],[17,0],[6,0],[7.6,0]],"id":54867443}],"con":true,"img":false}]}
{"op":"mcm","clk":"11450313962","pt":1717320493869,"mc":[{"id":"1.229554911","rc":[{"atb":[[1.17,100]],"id":52272946}],"con":true,"img":false}]}
{"op":"mcm","clk":"11450314008","pt":1717320494594,"mc":[{"id":"1.229554911","rc":[{"atb":[[1.25,5],[1.22,0]],"id":69676139},{"atl":[[280,0],[300,0]],"id":52272946}],"con":true,"img":false}]}
{"op":"mcm","clk":"11450314015","pt":1717320494700,"mc":[{"id":"1.229554911","rc":[{"atb":[[1.19,66.96],[1.17,370.93]],"id":69676139},{"atl":[[420,0.09],[470,2.61]],"id":52272946}],"con":true,"img":false}]}
{"op":"mcm","clk":"11450314081","pt":1717320495698,"mc":[{"id":"1.229554911","rc":[{"atb":[[1.15,133.33],[1.11,250],[1.09,250],[1.13,250]],"id":69676139},{"atl":[[550,1],[570,1],[590,1],[610,1]],"id":52272946}],"con":true,"img":false}]}
{"op":"mcm","clk":"11450314313","pt":1717320499562,"mc":[{"id":"1.229554911","rc":[{"atb":[[2.46,0]],"id":69033911}],"con":true,"img":false}]}
{"op":"mcm","clk":"11450314317","pt":1717320499679,"mc":[{"id":"1.229554911","rc":[{"atb":[[2.04,29.89]],"id":69033911}],"con":true,"img":false}]}
{"op":"mcm","clk":"11450314336","pt":1717320500082,"mc":[{"id":"1.229554911","rc":[{"atb":[[2.12,66.96],[2.2,16.67],[2.16,45.23],[2.08,115.74]],"id":69033911}],"con":true,"img":false}]}
{"op":"mcm","clk":"11450314390","pt":1717320500805,"mc":[{"id":"1.229554911","rc":[{"atb":[[1.53,8.03]],"id":55943164}],"con":true,"img":false}]}
{"op":"mcm","clk":"11450314413","pt":1717320501070,"mc":[{"id":"1.229554911","rc":[{"atb":[[1.95,8.61]],"id":70003369}],"con":true,"img":false}]}
{"op":"mcm","clk":"11450314608","pt":1717320504306,"mc":[{"id":"1.229554911","rc":[{"atl":[[3.65,22.55]],"id":70003369},{"atl":[[2,42.85]],"id":69676139},{"atl":[[4.9,12.68]],"id":54867443}],"con":true,"img":false}]}
{"op":"mcm","clk":"11450314616","pt":1717320504468,"mc":[{"id":"1.229554911","rc":[{"atl":[[4.5,0]],"id":70003369},{"atl":[[2.48,0]],"id":69676139},{"atl":[[5.9,0]],"id":54867443}],"con":true,"img":false}]}
{"op":"mcm","clk":"11450314622","pt":1717320504678,"mc":[{"id":"1.229554911","rc":[{"atb":[[1.91,0]],"id":70003369}],"con":true,"img":false}]}
{"op":"mcm","clk":"11450314626","pt":1717320504778,"mc":[{"id":"1.229554911","rc":[{"atb":[[1.66,45.07]],"id":70003369}],"con":true,"img":false}]}
{"op":"mcm","clk":"11450314860","pt":1717320508292,"mc":[{"id":"1.229554911","rc":[{"atb":[[2.2,19.94]],"id":69033911}],"con":true,"img":false}]}
{"op":"mcm","clk":"11450314936","pt":1717320509596,"mc":[{"id":"1.229554911","rc":[{"spn":3.03,"spf":"NaN","id":70003369},{"atl":[[12,3.8],[13.5,0]],"id":69033911},{"spn":4.22,"spf":"NaN","id":69033911},{"spn":1.64,"spf":"NaN","id":69676139},{"spn":217.25,"spf":"NaN","id":52272946},{"atl":[[12.5,0]],"id":54867443},{"spn":3.77,"spf":"NaN","id":54867443}],"con":true,"img":false}]}
{"op":"mcm","clk":"11450314942","pt":1717320509698,"mc":[{"id":"1.229554911","rc":[{"atl":[[11.5,7.87]],"id":54867443}],"con":true,"img":false}]}
{"op":"mcm","clk":"11450314955","pt":1717320509901,"mc":[{"id":"1.229554911","rc":[{"atb":[[2.42,0],[2.26,0],[2.34,0]],"id":70003369},{"atl":[[4.6,0],[5,0],[3.65,7.55],[5.4,0]],"id":70003369},{"atb":[[2.86,0],[2.94,0],[3.05,0]],"id":69033911},{"atl":[[8,0],[7.2,0],[6.4,0],[5.4,4.55]],"id":69033911},{"atb":[[1.25,0],[1.21,0],[1.29,0]],"id":69676139},{"atl":[[2,20],[2.52,0],[2.6,0],[2.68,0]],"id":69676139},{"atb":[[1.97,2.13],[1.9,0],[1.86,0],[1.94,0]],"id":55943164},{"atl":[[4.3,0],[5.1,4.88],[4.7,0]],"id":55943164},{"atb":[[2.64,2.13],[2.26,0],[2.34,0]],"id":54867443},{"atl":[[4.9,0]],"id":54867443}],"con":true,"img":false}]}
{"op":"mcm","clk":"11450315136","pt":1717320512176,"mc":[{"id":"1.229554911","rc":[{"atb":[[2.2,16.67]],"id":69033911}],"con":true,"img":false}]}
{"op":"mcm","clk":"11450315154","pt":1717320512385,"mc":[{"id":"1.229554911","rc":[{"atb":[[1.96,24.19],[1.86,40.51]],"id":70003369},{"atl":[[8.4,0.07]],"id":70003369},{"atb":[[2.42,24.53],[2.62,14.34]],"id":69033911},{"atl":[[17,0.03]],"id":69033911},{"atb":[[1.01,5824.62]],"id":69676139},{"atl":[[2.72,0.3]],"id":69676139},{"atb":[[1.84,41.48],[1.94,24.7]],"id":55943164},{"atl":[[8.2,0.07]],"id":55943164},{"atb":[[2.42,24.53],[2.62,14.34]],"id":54867443},{"atl":[[17,0.03]],"id":54867443}],"con":true,"img":false}]}
{"op":"mcm","clk":"11450315165","pt":1717320512492,"mc":[{"id":"1.229554911","rc":[{"atb":[[2.26,2.13],[2.16,43.1]],"id":69033911}],"con":true,"img":false}]}
{"op":"mcm","clk":"11450315325","pt":1717320514609,"mc":[{"id":"1.229554911","rc":[{"atb":[[1.56,0]],"id":70003369},{"atl":[[8,9.77],[9.2,0]],"id":70003369},{"atl":[[4.4,0]],"id":69676139},{"atb":[[14.5,0]],"id":52272946},{"atl":[[420,0]],"id":52272946}],"con":true,"img":false}]}
{"op":"mcm","clk":"11450315334","pt":1717320514711,"mc":[{"id":"1.229554911","rc":[{"atb":[[1.51,102.99]],"id":70003369},{"atl":[[3.45,13.5]],"id":69676139},{"atb":[[17.5,2.61]],"id":52272946},{"atl":[[360,0.09]],"id":52272946}],"con":true,"img":false}]}
{"op":"mcm","clk":"11450315658","pt":1717320519626,"mc":[{"id":"1.229554911","rc":[{"atb":[[1.87,0]],"id":55943164}],"con":true,"img":false}]}
{"op":"mcm","clk":"11450315664","pt":1717320519690,"mc":[{"id":"1.229554911","rc":[{"atb":[[1.85,34.46]],"id":55943164}],"con":true,"img":false}]}
{"op":"mcm","clk":"11450315743","pt":1717320521134,"mc":[{"id":"1.229554911","rc":[{"atb":[[2.3,5],[1.97,22.22],[2.22,10],[2.38,2.5]],"id":70003369},{"atl":[[3.65,27.64]],"id":70003369},{"atb":[[2.62,33.25],[2.94,5],[3.05,2.5],[2.86,10]],"id":69033911},{"atl":[[5.4,22.73]],"id":69033911},{"atb":[[1.28,2.5],[1.2,10],[1.19,169.27],[1.24,5]],"id":69676139},{"atl":[[2,100]],"id":69676139},{"atb":[[1.97,23.35],[1.9,5],[1.86,10],[1.94,27.2]],"id":55943164},{"atl":[[4.3,2.5],[5.1,14.88],[5,20],[4.7,5]],"id":55943164},{"atb":[[2.64,21.81],[2.18,10],[2.26,5],[2.34,2.5]],"id":54867443},{"atl":[[4.9,19.68]],"id":54867443}],"con":true,"img":false}]}
{"op":"mcm","clk":"11450315777","pt":1717320521609,"mc":[{"id":"1.229554911","rc":[{"atb":[[1.22,0],[1.3,54.43]],"id":69033911},{"atb":[[1.15,0],[1.19,274.53]],"id":69676139},{"atb":[[8.4,0],[9.4,19.97]],"id":52272946},{"atb":[[1.22,0],[1.3,55.14]],"id":54867443}],"con":true,"img":false}]}
{"op":"mcm","clk":"11450315785","pt":1717320521714,"mc":[{"id":"1.229554911","rc":[{"atl":[[550,0],[380,1]],"id":52272946},{"atl":[[5,0],[4.9,24.81]],"id":54867443}],"con":true,"img":false}]}
{"op":"mcm","clk":"11450315792","pt":1717320521822,"mc":[{"id":"1.229554911","rc":[{"atb":[[1.15,133.33],[1.19,169.27]],"id":69676139},{"atl":[[2.14,2.99]],"id":69676139},{"atb":[[8,14.29],[9.4,8.93]],"id":52272946}],"con":true,"img":false}]}
{"op":"mcm","clk":"11450315800","pt":1717320521924,"mc":[{"id":"1.229554911","rc":[{"atb":[[9,0],[10.5,2.44],[9.8,0],[9.4,0]],"id":52272946},{"atl":[[550,1],[380,0]],"id":52272946},{"atl":[[5.3,0],[5.1,10],[5.5,0],[5.7,0]],"id":55943164},{"atl":[[5,5],[4.9,19.68]],"id":54867443}],"con":true,"img":false}]}
{"op":"mcm","clk":"11450315884","pt":1717320523121,"mc":[{"id":"1.229554911","rc":[{"atb":[[1.15,0],[1.19,274.53]],"id":69676139},{"atb":[[8,0],[9.4,11.9]],"id":52272946},{"atl":[[7.4,19.53],[6.2,3.85],[6.6,8.93],[7,12.5]],"id":55943164}],"con":true,"img":false}]}
{"op":"mcm","clk":"11450315896","pt":1717320523241,"mc":[{"id":"1.229554911","rc":[{"atb":[[1.65,115.75]],"id":70003369},{"atl":[[8,5.97],[3.8,7.14],[4.9,25.64],[3.65,20.09]],"id":70003369},{"atb":[[2.54,16.67],[1.3,0]],"id":69033911},{"atl":[[11.5,0],[7.8,14.71]],"id":69033911},{"atb":[[1.2,179.28]],"id":69676139},{"atl":[[2,80],[2.58,63.29],[4.5,0],[2.02,19.61]],"id":69676139},{"atb":[[18,3.8],[9.2,2.5],[8.4,5]],"id":52272946},{"atl":[[550,0],[350,0.23],[380,1],[470,4.61],[490,1]],"id":52272946},{"atb":[[1.6,86.92]],"id":55943164},{"atl":[[8,17.86],[6.8,3.45],[7.2,8.06],[5,30],[7.6,11.36]],"id":55943164},{"atb":[[2.64,2.13],[1.54,55.14],[1.3,0]],"id":54867443},{"atl":[[5,0],[11.5,4.18],[4.9,24.81],[5.2,35.71]],"id":54867443}],"con":true,"img":false}]}
{"op":"mcm","clk":"11450315917","pt":1717320523399,"mc":[{"id":"1.229554911","rc":[{"atb":[[1.95,4.48]],"id":70003369},{"atl":[[3.65,0]],"id":70003369},{"atb":[[1.15,133.33],[1.19,169.27]],"id":69676139},{"atl":[[380,0]],"id":52272946},{"atl":[[8,0],[7.4,0],[6.8,0],[7.2,0],[6.2,0],[7.6,0],[6.6,0],[7,0]],"id":55943164}],"con":true,"img":false}]}
{"op":"mcm","clk":"11450315922","pt":1717320523544,"mc":[{"id":"1.229554911","rc":[{"atl":[[3.75,12.86]],"id":70003369},{"atl":[[550,1],[490,0]],"id":52272946},{"atl":[[5,5],[4.9,19.68]],"id":54867443}],"con":true,"img":false}]}
{"op":"mcm","clk":"11450315930","pt":1717320523601,"mc":[{"id":"1.229554911","rc":[{"atl":[[8,17.86],[6.8,3.45],[7.2,8.06],[7.6,11.36]],"id":55943164}],"con":true,"img":false}]}
{"op":"mcm","clk":"11450315969","pt":1717320524011,"mc":[{"id":"1.229554911","rc":[{"atb":[[1.15,0],[1.19,274.53]],"id":69676139},{"atl":[[550,0],[490,1]],"id":52272946},{"atl":[[5,0],[4.9,24.81]],"id":54867443}],"con":true,"img":false}]}
{"op":"mcm","clk":"11450315975","pt":1717320524111,"mc":[{"id":"1.229554911","rc":[{"atb":[[1.65,0]],"id":70003369},{"atb":[[9.4,0]],"id":52272946}],"con":true,"img":false}]}
{"op":"mcm","clk":"11450315986","pt":1717320524219,"mc":[{"id":"1.229554911","rc":[{"atb":[[1.45,128.5]],"id":70003369},{"atb":[[2.4,70.73]],"id":52272946}],"con":true,"img":false}]}
{"op":"mcm","clk":"11450315998","pt":1717320524424,"mc":[{"id":"1.229554911","rc":[{"atl":[[550,1],[490,0]],"id":52272946},{"atl":[[5,5],[4.9,19.68]],"id":54867443}],"con":true,"img":false}]}
{"op":"mcm","clk":"11450316005","pt":1717320524528,"mc":[{"id":"1.229554911","rc":[{"atb":[[1.15,133.33],[1.19,169.27]],"id":69676139}],"con":true,"img":false}]}
{"op":"mcm","clk":"11450316011","pt":1717320524586,"mc":[{"id":"1.229554911","rc":[{"atb":[[2.04,0]],"id":69033911}],"con":true,"img":false}]}
{"op":"mcm","clk":"11450316019","pt":1717320524689,"mc":[{"id":"1.229554911","rc":[{"atb":[[2.44,29.89]],"id":69033911}],"con":true,"img":false}]}
{"op":"mcm","clk":"11450316030","pt":1717320524898,"mc":[{"id":"1.229554911","rc":[{"atb":[[1.19,274.53]],"id":69676139}],"con":true,"img":false}]}
{"op":"mcm","clk":"11450316038","pt":1717320525003,"mc":[{"id":"1.229554911","rc":[{"atb":[[1.15,0]],"id":69676139}],"con":true,"img":false}]}
{"op":"mcm","clk":"11450316094","pt":1717320525722,"mc":[{"id":"1.229554911","rc":[{"atl":[[550,0],[490,1]],"id":52272946},{"atl":[[5,0],[4.9,24.81]],"id":54867443}],"con":true,"img":false}]}
{"op":"mcm","clk":"11450323191","pt":1717320528645,"mc":[{"id":"1.229554911","rc":[{"atl":[[5.2,11.9],[5.4,39.78]],"id":54867443}],"con":true,"img":false}]}
{"op":"mcm","clk":"11450323278","pt":1717320529927,"mc":[{"id":"1.229554911","rc":[{"atb":[[1.54,0],[1.61,55.14]],"id":54867443}],"con":true,"img":false}]}
{"op":"mcm","clk":"11450323539","pt":1717320533571,"mc":[{"id":"1.229554911","rc":[{"atl":[[3.9,17.24]],"id":70003369}],"con":true,"img":false}]}
{"op":"mcm","clk":"11450323626","pt":1717320534646,"mc":[{"id":"1.229554911","rc":[{"atb":[[1.98,29.89],[1.66,0]],"id":70003369},{"atl":[[12,0],[9.8,6.55]],"id":70003369},{"atl":[[5.5,0],[3.9,21.97]],"id":69676139},{"atl":[[470,2]],"id":52272946},{"atb":[[1.51,0]],"id":55943164}],"con":true,"img":false}]}
{"op":"mcm","clk":"11450323632","pt":1717320534715,"mc":[{"id":"1.229554911","rc":[{"atl":[[400,2.61]],"id":52272946},{"atb":[[1.61,114.12]],"id":55943164}],"con":true,"img":false}]}
{"op":"mcm","clk":"11450323644","pt":1717320534865,"mc":[{"id":"1.229554911","rc":[{"atl":[[2.14,0]],"id":69676139}],"con":true,"img":false}]}
{"op":"mcm","clk":"11450323654","pt":1717320534910,"mc":[{"id":"1.229554911","rc":[{"atl":[[450,2],[470,0]],"id":52272946}],"con":true,"img":false}]}
{"op":"mcm","clk":"11450323660","pt":1717320535071,"mc":[{"id":"1.229554911","rc":[{"atl":[[2.12,114.6]],"id":69676139}],"con":true,"img":false}]}
{"op":"mcm","clk":"11450323674","pt":1717320535233,"mc":[{"id":"1.229554911","rc":[{"atb":[[1.17,620.93]],"id":69676139}],"con":true,"img":false}]}
{"op":"mcm","clk":"11450323687","pt":1717320535436,"mc":[{"id":"1.229554911","rc":[{"atb":[[2.38,15.36]],"id":70003369},{"atb":[[3.05,18.15]],"id":69033911},{"atb":[[1.28,53.27]],"id":69676139},{"atl":[[4.2,21.26]],"id":55943164}],"con":true,"img":false}]}
{"op":"mcm","clk":"11450323695","pt":1717320535523,"mc":[{"id":"1.229554911","rc":[{"atb":[[1.97,2.13]],"id":70003369},{"atb":[[2.62,14.34]],"id":69033911},{"atb":[[1.19,172.22]],"id":69676139},{"atl":[[5,0],[4.7,15]],"id":55943164}],"con":true,"img":false}]}
{"op":"mcm","clk":"11450323723","pt":1717320535934,"mc":[{"id":"1.229554911","rc":[{"atl":[[510,1]],"id":52272946}],"con":true,"img":false}]}
{"op":"mcm","clk":"11450323790","pt":1717320536914,"mc":[{"id":"1.229554911","rc":[{"atb":[[1.09,0]],"id":69676139},{"atl":[[610,0]],"id":52272946}],"con":true,"img":false}]}
{"op":"mcm","clk":"11450323977","pt":1717320539619,"mc":[{"id":"1.229554911","rc":[{"atb":[[12.5,0],[15,4.12]],"id":52272946}],"con":true,"img":false}]}
{"op":"mcm","clk":"11450324097","pt":1717320541276,"mc":[{"id":"1.229554911","rc":[{"atl":[[2.12,111.61]],"id":69676139}],"con":true,"img":false}]}
{"op":"mcm","clk":"11450324115","pt":1717320541431,"mc":[{"id":"1.229554911","rc":[{"atl":[[2.12,114.6]],"id":69676139}],"con":true,"img":false}]}
{"op":"mcm","clk":"11450324158","pt":1717320541945,"mc":[{"id":"1.229554911","rc":[{"atl":[[60,5]],"id":69676139},{"atl":[[60,5]],"id":55943164}],"con":true,"img":false}]}
{"op":"mcm","clk":"11450324265","pt":1717320543238,"mc":[{"id":"1.229554911","rc":[{"atl":[[2.12,111.61]],"id":69676139}],"con":true,"img":false}]}
{"op":"mcm","clk":"11450324358","pt":1717320544419,"mc":[{"id":"1.229554911","rc":[{"atb":[[1.19,105.26]],"id":69676139},{"atb":[[1.92,0]],"id":54867443},{"atl":[[11.5,0]],"id":54867443}],"con":true,"img":false}]}
{"op":"mcm","clk":"11450324369","pt":1717320544523,"mc":[{"id":"1.229554911","rc":[{"atb":[[1.21,66.96]],"id":69676139},{"atb":[[2.2,28.72]],"id":54867443},{"atl":[[11,4.18]],"id":54867443}],"con":true,"img":false}]}
{"op":"mcm","clk":"11450324375","pt":1717320544623,"mc":[{"id":"1.229554911","rc":[{"atb":[[1.2,10],[1.22,105.26]],"id":69676139}],"con":true,"img":false}]}
{"op":"mcm","clk":"11450324417","pt":1717320545342,"mc":[{"id":"1.229554911","rc":[{"atb":[[1.15,250]],"id":69676139}],"con":true,"img":false}]}
{"op":"mcm","clk":"11450324444","pt":1717320545755,"mc":[{"id":"1.229554911","rc":[{"atb":[[1.11,0]],"id":69676139}],"con":true,"img":false}]}
{"op":"mcm","clk":"11450324464","pt":1717320546019,"mc":[{"id":"1.229554911","rc":[{"atl":[[530,1]],"id":52272946}],"con":true,"img":false}]}
{"op":"mcm","clk":"11450324489","pt":1717320546445,"mc":[{"id":"1.229554911","rc":[{"atl":[[590,0]],"id":52272946}],"con":true,"img":false}]}
{"op":"mcm","clk":"11450324785","pt":1717320549652,"mc":[{"id":"1.229554911","rc":[{"atb":[[1.98,0]],"id":70003369},{"atb":[[2.44,0]],"id":69033911}],"con":true,"img":false}]}
{"op":"mcm","clk":"11450324796","pt":1717320549758,"mc":[{"id":"1.229554911","rc":[{"atb":[[1.97,32.02]],"id":70003369},{"atb":[[2.64,29.89]],"id":69033911}],"con":true,"img":false}]}
{"op":"mcm","clk":"11450325115","pt":1717320553558,"mc":[{"id":"1.229554911","rc":[{"atb":[[2,3.92]],"id":70003369}],"con":true,"img":false}]}
{"op":"mcm","clk":"11450325131","pt":1717320553763,"mc":[{"id":"1.229554911","rc":[{"atl":[[490,0],[510,0]],"id":52272946}],"con":true,"img":false}]}
{"op":"mcm","clk":"11450325332","pt":1717320556260,"mc":[{"id":"1.229554911","rc":[{"atb":[[2.4,0],[2.14,70.73]],"id":52272946}],"con":true,"img":false}]}
{"op":"mcm","clk":"11450325349","pt":1717320556461,"mc":[{"id":"1.229554911","rc":[{"atb":[[17.5,0],[2.14,0]],"id":52272946}],"con":true,"img":false}]}
{"op":"mcm","clk":"11450325363","pt":1717320556564,"mc":[{"id":"1.229554911","rc":[{"atb":[[18.5,2.61]],"id":52272946}],"con":true,"img":false}]}
{"op":"mcm","clk":"11450325371","pt":1717320556670,"mc":[{"id":"1.229554911","rc":[{"atb":[[18,0],[19,3.93]],"id":52272946}],"con":true,"img":false}]}
{"op":"mcm","clk":"11450325422","pt":1717320557147,"mc":[{"id":"1.229554911","rc":[{"atb":[[1.95,0]],"id":70003369},{"atb":[[1.53,0]],"id":55943164}],"con":true,"img":false}]}
{"op":"mcm","clk":"11450325452","pt":1717320557455,"mc":[{"id":"1.229554911","rc":[{"atb":[[2.2,20.22]],"id":69033911}],"con":true,"img":false}]}
{"op":"mcm","clk":"11450325550","pt":1717320558553,"mc":[{"id":"1.229554911","rc":[{"atl":[[2.12,114.6]],"id":69676139}],"con":true,"img":false}]}
{"op":"mcm","clk":"11450325633","pt":1717320559628,"mc":[{"id":"1.229554911","rc":[{"atl":[[3.45,0]],"id":69676139}],"con":true,"img":false}]}
{"op":"mcm","clk":"11450325638","pt":1717320559734,"mc":[{"id":"1.229554911","rc":[{"atl":[[3.3,13.5]],"id":69676139}],"con":true,"img":false}]}
{"op":"mcm","clk":"11450325710","pt":1717320560767,"mc":[{"id":"1.229554911","rc":[{"atl":[[2.12,111.61]],"id":69676139}],"con":true,"img":false}]}
{"op":"mcm","clk":"11450325735","pt":1717320561129,"mc":[{"id":"1.229554911","rc":[{"atl":[[2.1,2.99]],"id":69676139}],"con":true,"img":false}]}
{"op":"mcm","clk":"11450325995","pt":1717320564649,"mc":[{"id":"1.229554911","rc":[{"atb":[[1.21,0]],"id":69676139}],"con":true,"img":false}]}
{"op":"mcm","clk":"11450326001","pt":1717320564753,"mc":[{"id":"1.229554911","rc":[{"atb":[[1.23,66.96]],"id":69676139}],"con":true,"img":false}]}
{"op":"mcm","clk":"11450326009","pt":1717320564862,"mc":[{"id":"1.229554911","rc":[{"atb":[[1.24,111.54]],"id":69676139}],"con":true,"img":false}]}
{"op":"mcm","clk":"11450326017","pt":1717320564964,"mc":[{"id":"1.229554911","rc":[{"atb":[[1.22,0]],"id":69676139}],"con":true,"img":false}]}
{"op":"mcm","clk":"11450326204","pt":1717320567346,"mc":[{"id":"1.229554911","rc":[{"atl":[[2.1,0]],"id":69676139}],"con":true,"img":false}]}
{"op":"mcm","clk":"11450326232","pt":1717320567665,"mc":[{"id":"1.229554911","rc":[{"atl":[[2.1,2.99]],"id":69676139}],"con":true,"img":false}]}
{"op":"mcm","clk":"11450326308","pt":1717320568547,"mc":[{"id":"1.229554911","rc":[{"atb":[[2,0]],"id":70003369}],"con":true,"img":false}]}
{"op":"mcm","clk":"11450326396","pt":1717320569682,"mc":[{"id":"1.229554911","rc":[{"atb":[[1.51,0]],"id":70003369},{"spn":3.06,"spf":"NaN","id":70003369},{"spn":1.64,"spf":"NaN","id":69676139},{"spn":184.5,"spf":"NaN","id":52272946},{"atl":[[13,5.23],[15.5,0]],"id":54867443}],"con":true,"img":false}]}
{"op":"mcm","clk":"11450326405","pt":1717320569785,"mc":[{"id":"1.229554911","rc":[{"atb":[[1.56,102.99]],"id":70003369}],"con":true,"img":false}]}
{"op":"mcm","clk":"11450326435","pt":1717320570282,"mc":[{"id":"1.229554911","rc":[{"atl":[[150,2.5]],"id":52272946}],"con":true,"img":false}]}
{"op":"mcm","clk":"11450326442","pt":1717320570371,"mc":[{"id":"1.229554911","rc":[{"atl":[[340,0.24]],"id":52272946}],"con":true,"img":false}]}
{"op":"mcm","clk":"11450326450","pt":1717320570461,"mc":[{"id":"1.229554911","rc":[{"atl":[[350,0]],"id":52272946}],"con":true,"img":false}]}
{"op":"mcm","clk":"11450326577","pt":1717320572053,"mc":[{"id":"1.229554911","rc":[{"atl":[[2.1,0]],"id":69676139}],"con":true,"img":false}]}
{"op":"mcm","clk":"11450326784","pt":1717320574648,"mc":[{"id":"1.229554911","rc":[{"atb":[[2.2,0]],"id":54867443}],"con":true,"img":false}]}
{"op":"mcm","clk":"11450326793","pt":1717320574795,"mc":[{"id":"1.229554911","rc":[{"atb":[[1.98,28.72]],"id":54867443}],"con":true,"img":false}]}
{"op":"mcm","clk":"11450327056","pt":1717320579102,"mc":[{"id":"1.229554911","rc":[{"atb":[[1.96,2.5],[1.94,24.7],[1.92,5],[1.88,10],[1.9,0],[1.86,0]],"id":55943164}],"con":true,"img":false}]}
{"op":"mcm","clk":"11450327098","pt":1717320579571,"mc":[{"id":"1.229554911","rc":[{"atb":[[1.17,250]],"id":69676139},{"atl":[[11,0]],"id":55943164}],"con":true,"img":false}]}
{"op":"mcm","clk":"11450327105","pt":1717320579676,"mc":[{"id":"1.229554911","rc":[{"atb":[[1.2,380.93]],"id":69676139},{"atl":[[10,6.76]],"id":55943164}],"con":true,"img":false}]}
{"op":"mcm","clk":"11450327215","pt":1717320581074,"mc":[{"id":"1.229554911","rc":[{"atb":[[9.2,0],[10.5,4.94],[8.4,0]],"id":52272946}],"con":true,"img":false}]}
{"op":"mcm","clk":"11450327417","pt":1717320583671,"mc":[{"id":"1.229554911","rc":[{"atl":[[140,0.58]],"id":52272946}],"con":true,"img":false}]}
{"op":"mcm","clk":"11450327430","pt":1717320583871,"mc":[{"id":"1.229554911","rc":[{"atl":[[340,0]],"id":52272946}],"con":true,"img":false}]}
{"op":"mcm","clk":"11450327478","pt":1717320584604,"mc":[{"id":"1.229554911","rc":[{"atb":[[1.82,0]],"id":69033911},{"atb":[[1.23,0]],"id":69676139},{"atb":[[18.5,0]],"id":52272946}],"con":true,"img":false}]}
{"op":"mcm","clk":"11450327488","pt":1717320584714,"mc":[{"id":"1.229554911","rc":[{"atb":[[1.95,64.87]],"id":69033911},{"atb":[[1.25,66.96],[1.21,250],[1.24,5]],"id":69676139},{"atb":[[19,0],[19.5,2.61]],"id":52272946}],"con":true,"img":false}]}
{"op":"mcm","clk":"11450327496","pt":1717320584812,"mc":[{"id":"1.229554911","rc":[{"atb":[[15.5,4.82]],"id":52272946}],"con":true,"img":false}]}
{"op":"mcm","clk":"11450327662","pt":1717320587415,"mc":[{"id":"1.229554911","rc":[{"atl":[[2.1,3.35]],"id":69676139}],"con":true,"img":false}]}
{"op":"mcm","clk":"11450327706","pt":1717320588238,"mc":[{"id":"1.229554911","rc":[{"atl":[[2.1,0]],"id":69676139}],"con":true,"img":false}]}
{"op":"mcm","clk":"11450327866","pt":1717320590309,"mc":[{"id":"1.229554911","rc":[{"atl":[[2.04,51.07]],"id":69676139}],"con":true,"img":false}]}
{"op":"mcm","clk":"11450327901","pt":1717320590787,"mc":[{"id":"1.229554911","rc":[{"atb":[[1.21,0],[1.26,106.54]],"id":69676139}],"con":true,"img":false}]}
{"op":"mcm","clk":"11450327908","pt":1717320590936,"mc":[{"id":"1.229554911","rc":[{"atb":[[1.28,128.5],[1.45,0]],"id":70003369},{"atl":[[3.8,0],[4.9,0],[5.6,21.74],[2.78,2.31],[4.2,6.25]],"id":70003369},{"atb":[[2.54,0],[2.12,133.92],[2.64,32.39],[2.94,0],[3.05,0],[2.86,0]],"id":69033911},{"atl":[[6.2,19.23],[6,27.5],[4.9,5.13],[7.8,0],[5.4,18.18]],"id":69033911},{"atl":[[2.58,0],[2.1,18.18],[2.02,0],[2.46,68.49]],"id":69676139},{"atb":[[5.3,23.26]],"id":52272946},{"atl":[[150,0],[40,2.5],[360,2.09],[48,5],[450,0]],"id":52272946},{"atb":[[1.6,0],[1.3,52.14]],"id":55943164},{"atl":[[4.3,0],[6.8,0],[5.4,22.73],[6.2,3.85],[4.7,0]],"id":55943164},{"atb":[[2.18,0],[2.26,0],[1.61,0],[2.34,0],[1.76,142.3]],"id":54867443}],"con":true,"img":false}]}
{"op":"mcm","clk":"11450327915","pt":1717320590994,"mc":[{"id":"1.229554911","rc":[{"trd":[[2.78,4.62]],"ltp":2.78,"tv":4.62,"id":70003369},{"atl":[[2.78,0]],"id":70003369},{"atl":[[5.9,10],[5.5,5]],"id":55943164}],"con":true,"img":false}]}
{"op":"mcm","clk":"11450327921","pt":1717320591100,"mc":[{"id":"1.229554911","rc":[{"atb":[[2.4,2.31]],"id":70003369},{"atb":[[2.64,36.24]],"id":69033911},{"atl":[[4.8,3.85]],"id":69033911}],"con":true,"img":false}]}
{"op":"mcm","clk":"11450327928","pt":1717320591198,"mc":[{"id":"1.229554911","rc":[{"atl":[[3.75,0]],"id":70003369},{"atl":[[5.4,0]],"id":69033911},{"atl":[[4.2,0]],"id":55943164}],"con":true,"img":false}]}
{"op":"mcm","clk":"11450327935","pt":1717320591304,"mc":[{"id":"1.229554911","rc":[{"atb":[[2.4,23.47]],"id":70003369}],"con":true,"img":false}]}
{"op":"mcm","clk":"11450327942","pt":1717320591410,"mc":[{"id":"1.229554911","rc":[{"atl":[[3.85,41.59]],"id":70003369},{"atl":[[5.3,18.6]],"id":55943164}],"con":true,"img":false}]}
{"op":"mcm","clk":"11450327949","pt":1717320591513,"mc":[{"id":"1.229554911","rc":[{"atb":[[2.38,2.5]],"id":70003369}],"con":true,"img":false}]}
{"op":"mcm","clk":"11450327968","pt":1717320591815,"mc":[{"id":"1.229554911","rc":[{"atl":[[3.85,15.27]],"id":70003369}],"con":true,"img":false}]}
{"op":"mcm","clk":"11450328047","pt":1717320592916,"mc":[{"id":"1.229554911","rc":[{"atl":[[3.9,0]],"id":70003369}],"con":true,"img":false}]}
{"op":"mcm","clk":"11450328056","pt":1717320593018,"mc":[{"id":"1.229554911","rc":[{"atl":[[5.6,26.74],[3.85,0],[5.2,2.5]],"id":70003369}],"con":true,"img":false}]}
{"op":"mcm","clk":"11450328063","pt":1717320593121,"mc":[{"id":"1.229554911","rc":[{"atl":[[3.95,58.51]],"id":70003369}],"con":true,"img":false}]}
{"op":"mcm","clk":"11450328076","pt":1717320593287,"mc":[{"id":"1.229554911","rc":[{"atl":[[3.95,16.14]],"id":70003369}],"con":true,"img":false}]}
{"op":"mcm","clk":"11450328098","pt":1717320593505,"mc":[{"id":"1.229554911","rc":[{"atl":[[3.95,0]],"id":70003369}],"con":true,"img":false}]}
{"op":"mcm","clk":"11450328106","pt":1717320593593,"mc":[{"id":"1.229554911","rc":[{"atl":[[5.1,5.62]],"id":70003369}],"con":true,"img":false}]}
{"op":"mcm","clk":"11450328171","pt":1717320594616,"mc":[{"id":"1.229554911","rc":[{"atl":[[9.8,0]],"id":70003369},{"atb":[[1.95,0]],"id":69033911},{"atb":[[1.2,10],[1.25,0]],"id":69676139},{"atb":[[19.5,0],[11.5,5.5],[15,0]],"id":52272946},{"atl":[[10,0]],"id":55943164}],"con":true,"img":false}]}
{"op":"mcm","clk":"11450328177","pt":1717320594719,"mc":[{"id":"1.229554911","rc":[{"atb":[[1.24,164.81]],"id":69676139},{"atl":[[2,0]],"id":69676139},{"atb":[[15.5,0]],"id":52272946}],"con":true,"img":false}]}
{"op":"mcm","clk":"11450328183","pt":1717320594825,"mc":[{"id":"1.229554911","rc":[{"atl":[[11.5,6.55]],"id":70003369},{"atb":[[1.85,64.87]],"id":69033911},{"atb":[[1.2,76.96],[1.16,370.93],[1.26,0]],"id":69676139},{"atl":[[2.04,127.99]],"id":69676139},{"atb":[[16,2.61],[12,7.27]],"id":52272946},{"atl":[[11,6.76]],"id":55943164}],"con":true,"img":false}]}
{"op":"mcm","clk":"11450328191","pt":1717320594925,"mc":[{"id":"1.229554911","rc":[{"atb":[[1.21,218.08],[1.24,5]],"id":69676139}],"con":true,"img":false}]}
{"op":"mcm","clk":"11450328208","pt":1717320595091,"mc":[{"id":"1.229554911","rc":[{"atb":[[2.2,16.67]],"id":69033911}],"con":true,"img":false}]}
{"op":"mcm","clk":"11450328219","pt":1717320595302,"mc":[{"id":"1.229554911","rc":[{"trd":[[40,5]],"ltp":40.0,"tv":5.0,"id":52272946},{"atl":[[40,0]],"id":52272946}],"con":true,"img":false}]}
{"op":"mcm","clk":"11450328229","pt":1717320595403,"mc":[{"id":"1.229554911","rc":[{"atb":[[16.5,2.5]],"id":52272946}],"con":true,"img":false}]}
{"op":"mcm","clk":"11450328235","pt":1717320595506,"mc":[{"id":"1.229554911","rc":[{"atl":[[2.04,79.91]],"id":69676139}],"con":true,"img":false}]}
{"op":"mcm","clk":"11450328304","pt":1717320596705,"mc":[{"id":"1.229554911","rc":[{"atl":[[46,1.78]],"id":52272946}],"con":true,"img":false}]}
{"op":"mcm","clk":"11450328311","pt":1717320596803,"mc":[{"id":"1.229554911","rc":[{"atl":[[140,0]],"id":52272946}],"con":true,"img":false}]}
{"op":"mcm","clk":"11450328326","pt":1717320597016,"mc":[{"id":"1.229554911","rc":[{"atb":[[1.28,0],[1.45,128.5]],"id":70003369},{"atl":[[5.6,5],[5.2,14.37]],"id":70003369},{"atb":[[2.32,49.08],[2.12,66.96]],"id":69033911},{"atl":[[5.8,34.85],[6.2,0]],"id":69033911},{"atb":[[6.4,18.52],[5.3,0]],"id":52272946},{"atb":[[1.46,52.14],[1.3,0]],"id":55943164}],"con":true,"img":false}]}
{"op":"mcm","clk":"11450328347","pt":1717320597317,"mc":[{"id":"1.229554911","rc":[{"atl":[[2.08,0]],"id":69676139}],"con":true,"img":false}]}
{"op":"mcm","clk":"11450328377","pt":1717320597838,"mc":[{"id":"1.229554911","rc":[{"atb":[[16.5,6.34]],"id":52272946}],"con":true,"img":false}]}
{"op":"mcm","clk":"11450328384","pt":1717320598010,"mc":[{"id":"1.229554911","rc":[{"atb":[[12,0]],"id":52272946}],"con":true,"img":false}]}
{"op":"mcm","clk":"11450328501","pt":1717320599615,"mc":[{"id":"1.229554911","rc":[{"atl":[[8,0],[11.5,0],[12,3.8],[12.5,5.01]],"id":70003369},{"atb":[[2.64,6.35]],"id":69033911},{"atl":[[3.9,0]],"id":69676139},{"atb":[[11.5,0],[7.6,8.75]],"id":52272946},{"atl":[[360,2],[120,0.35]],"id":52272946}],"con":true,"img":false}]}
{"op":"mcm","clk":"11450328509","pt":1717320599720,"mc":[{"id":"1.229554911","rc":[{"atb":[[2.44,29.89]],"id":69033911},{"atl":[[4.1,21.97]],"id":69676139},{"atl":[[140,2],[360,0]],"id":52272946}],"con":true,"img":false}]}
{"op":"mcm","clk":"11450328533","pt":1717320600021,"mc":[{"id":"1.229554911","rc":[{"atl":[[4.4,14.46]],"id":70003369},{"atl":[[5.1,12.2]],"id":69033911},{"atl":[[2.14,43.86]],"id":69676139},{"atl":[[6.6,8.93]],"id":55943164}],"con":true,"img":false}]}
{"op":"mcm","clk":"11450328917","pt":1717320604283,"mc":[{"id":"1.229554911","rc":[{"atb":[[1.96,0],[1.86,0]],"id":70003369},{"atl":[[4.2,15.15],[8.4,0]],"id":70003369},{"atb":[[2.62,0],[2.42,0]],"id":69033911},{"atl":[[17,0]],"id":69033911},{"atb":[[1.01,17.35]],"id":69676139},{"atl":[[2.72,0]],"id":69676139},{"atb":[[10.5,2.5],[8.2,0]],"id":52272946},{"atb":[[1.84,0],[1.94,0]],"id":55943164},{"atl":[[8.2,0],[5,20]],"id":55943164},{"atb":[[2.42,0],[2.62,0]],"id":54867443},{"atl":[[17,0]],"id":54867443}],"con":true,"img":false}]}
{"op":"mcm","clk":"11450328925","pt":1717320604388,"mc":[{"id":"1.229554911","rc":[{"atl":[[5.1,0]],"id":70003369}],"con":true,"img":false}]}
{"op":"mcm","clk":"11450328929","pt":1717320604496,"mc":[{"id":"1.229554911","rc":[{"atb":[[2.38,14.49],[2.2,0]],"id":69033911},{"atl":[[5.6,0],[5.8,19.23],[6,2.5]],"id":69033911},{"atl":[[5.3,0]],"id":55943164},{"atb":[[1.92,2.5],[1.84,10],[1.88,5]],"id":54867443}],"con":true,"img":false}]}
{"op":"mcm","clk":"11450328949","pt":1717320604656,"mc":[{"id":"1.229554911","rc":[{"atb":[[2.3,15.38],[2.38,0]],"id":69033911},{"atb":[[16,0],[9.6,4.86]],"id":52272946}],"con":true,"img":false}]}
{"op":"mcm","clk":"11450329032","pt":1717320605797,"mc":[{"id":"1.229554911","rc":[{"atl":[[8,0],[7.2,0],[7.6,0]],"id":55943164}],"con":true,"img":false}]}
{"op":"mcm","clk":"11450329037","pt":1717320605855,"mc":[{"id":"1.229554911","rc":[{"atl":[[2.04,76.92]],"id":69676139}],"con":true,"img":false}]}
{"op":"mcm","clk":"11450329044","pt":1717320605961,"mc":[{"id":"1.229554911","rc":[{"atl":[[2.04,0]],"id":69676139}],"con":true,"img":false}]}
{"op":"mcm","clk":"11450329089","pt":1717320606139,"mc":[{"id":"1.229554911","rc":[{"atb":[[2.5,2.13],[2.26,0]],"id":69033911},{"atl":[[2.12,165.2]],"id":69676139}],"con":true,"img":false}]}
{"op":"mcm","clk":"11450329096","pt":1717320606187,"mc":[{"id":"1.229554911","rc":[{"atl":[[2.04,2.99]],"id":69676139}],"con":true,"img":false}]}
{"op":"mcm","clk":"11450329132","pt":1717320606697,"mc":[{"id":"1.229554911","rc":[{"trd":[[46,3.55]],"ltp":46.0,"tv":3.55,"id":52272946},{"atl":[[46,0]],"id":52272946}],"con":true,"img":false}]}
{"op":"mcm","clk":"11450329142","pt":1717320606793,"mc":[{"id":"1.229554911","rc":[{"atb":[[9.8,6.82]],"id":52272946}],"con":true,"img":false}]}
{"op":"mcm","clk":"11450329189","pt":1717320607673,"mc":[{"id":"1.229554911","rc":[{"atl":[[2.04,56.58]],"id":69676139}],"con":true,"img":false}]}
{"op":"mcm","clk":"11450329197","pt":1717320607777,"mc":[{"id":"1.229554911","rc":[{"atl":[[2.12,111.61]],"id":69676139}],"con":true,"img":false}]}
{"op":"mcm","clk":"11450329280","pt":1717320609072,"mc":[{"id":"1.229554911","rc":[{"atl":[[4.6,20.49]],"id":70003369},{"atl":[[2.18,63.56]],"id":69676139},{"atl":[[7,12.5]],"id":55943164}],"con":true,"img":false}]}
{"op":"mcm","clk":"11450329304","pt":1717320609489,"mc":[{"id":"1.229554911","rc":[{"atl":[[46,1.78]],"id":52272946}],"con":true,"img":false}]}
{"op":"mcm","clk":"11450329315","pt":1717320609647,"mc":[{"id":"1.229554911","rc":[{"atb":[[1.97,2.13]],"id":70003369},{"atb":[[2.44,0]],"id":69033911},{"atb":[[1.85,0]],"id":55943164}],"con":true,"img":false}]}
{"op":"mcm","clk":"11450329321","pt":1717320609751,"mc":[{"id":"1.229554911","rc":[{"atb":[[1.83,29.89]],"id":70003369},{"atb":[[2.34,29.89]],"id":69033911},{"atb":[[1.74,34.46]],"id":55943164}],"con":true,"img":false}]}
{"op":"mcm","clk":"11450329515","pt":1717320612392,"mc":[{"id":"1.229554911","rc":[{"atl":[[2.04,53.59]],"id":69676139}],"con":true,"img":false}]}
{"op":"mcm","clk":"11450329527","pt":1717320612455,"mc":[{"id":"1.229554911","rc":[{"atl":[[2.04,0]],"id":69676139}],"con":true,"img":false}]}
{"op":"mcm","clk":"11450329538","pt":1717320612554,"mc":[{"id":"1.229554911","rc":[{"atl":[[2.1,90.91]],"id":69676139}],"con":true,"img":false}]}
{"op":"mcm","clk":"11450329543","pt":1717320612653,"mc":[{"id":"1.229554911","rc":[{"atl":[[2.02,2.99]],"id":69676139}],"con":true,"img":false}]}
{"op":"mcm","clk":"11450329611","pt":1717320613584,"mc":[{"id":"1.229554911","rc":[{"atl":[[5.3,17.44]],"id":69033911},{"atb":[[1.96,0]],"id":54867443}],"con":true,"img":false}]}
{"op":"mcm","clk":"11450329618","pt":1717320613687,"mc":[{"id":"1.229554911","rc":[{"atb":[[1.77,5.09]],"id":55943164}],"con":true,"img":false}]}
{"op":"mcm","clk":"11450329626","pt":1717320613791,"mc":[{"id":"1.229554911","rc":[{"atb":[[2.4,2.8]],"id":69033911}],"con":true,"img":false}]}
{"op":"mcm","clk":"11450329668","pt":1717320614366,"mc":[{"id":"1.229554911","rc":[{"atb":[[2.02,3.84]],"id":54867443}],"con":true,"img":false}]}
{"op":"mcm","clk":"11450329699","pt":1717320614678,"mc":[{"id":"1.229554911","rc":[{"atb":[[1.2,10]],"id":69676139},{"atl":[[2.02,0]],"id":69676139}],"con":true,"img":false}]}
{"op":"mcm","clk":"11450329703","pt":1717320614779,"mc":[{"id":"1.229554911","rc":[{"atb":[[1.15,0],[1.19,0],[1.22,66.96],[1.17,0]],"id":69676139},{"atl":[[390,1]],"id":52272946}],"con":true,"img":false}]}
{"op":"mcm","clk":"11450329709","pt":1717320614882,"mc":[{"id":"1.229554911","rc":[{"atb":[[1.21,0],[1.23,66.97]],"id":69676139}],"con":true,"img":false}]}
{"op":"mcm","clk":"11450329805","pt":1717320616181,"mc":[{"id":"1.229554911","rc":[{"trd":[[46,7.11]],"ltp":46.0,"tv":7.11,"id":52272946},{"atl":[[46,0]],"id":52272946},{"atl":[[7.8,0]],"id":55943164}],"con":true,"img":false}]}
{"op":"mcm","clk":"11450329812","pt":1717320616283,"mc":[{"id":"1.229554911","rc":[{"atl":[[6.8,5.97]],"id":55943164}],"con":true,"img":false}]}
{"op":"mcm","clk":"11450329943","pt":1717320617888,"mc":[{"id":"1.229554911","rc":[{"atl":[[4.8,32.35]],"id":70003369},{"atl":[[7.4,19.53]],"id":55943164}],"con":true,"img":false}]}
{"op":"mcm","clk":"11450329993","pt":1717320618669,"mc":[{"id":"1.229554911","rc":[{"atl":[[400,0]],"id":52272946}],"con":true,"img":false}]}
{"op":"mcm","clk":"11450330001","pt":1717320618773,"mc":[{"id":"1.229554911","rc":[{"atl":[[130,2.61]],"id":52272946}],"con":true,"img":false}]}
{"op":"mcm","clk":"11450330268","pt":1717320622088,"mc":[{"id":"1.229554911","rc":[{"atl":[[46,1.78]],"id":52272946}],"con":true,"img":false}]}
{"op":"mcm","clk":"11450330301","pt":1717320622398,"mc":[{"id":"1.229554911","rc":[{"atl":[[4.8,9.11]],"id":69033911}],"con":true,"img":false}]}
{"op":"mcm","clk":"11450330398","pt":1717320623597,"mc":[{"id":"1.229554911","rc":[{"atb":[[1.97,26.07],[1.87,40.04]],"id":70003369},{"atl":[[8.4,0.07]],"id":70003369},{"atb":[[2.64,20.51],[2.44,24.19]],"id":69033911},{"atl":[[17.5,0.03]],"id":69033911},{"atb":[[1.01,5824.62]],"id":69676139},{"atl":[[2.68,0.31]],"id":69676139},{"atb":[[11,2.32],[8.4,4.7]],"id":52272946},{"atb":[[1.96,26.69],[1.86,40.51]],"id":55943164},{"atl":[[8.4,0.07]],"id":55943164},{"atb":[[2.42,24.53],[2.62,14.34]],"id":54867443},{"atl":[[17,0.03]],"id":54867443}],"con":true,"img":false}]}
{"op":"mcm","clk":"11450330437","pt":1717320624009,"mc":[{"id":"1.229554911","rc":[{"atl":[[4.8,3.85]],"id":69033911}],"con":true,"img":false}]}
{"op":"mcm","clk":"11450330446","pt":1717320624063,"mc":[{"id":"1.229554911","rc":[{"atb":[[11.5,3.66],[9.8,0]],"id":52272946}],"con":true,"img":false}]}
{"op":"mcm","clk":"11450330602","pt":1717320625675,"mc":[{"id":"1.229554911","rc":[{"trd":[[46,7.35]],"ltp":46.0,"tv":7.35,"id":52272946},{"atl":[[46,1.66]],"id":52272946}],"con":true,"img":false}]}
{"op":"mcm","clk":"11450330610","pt":1717320625774,"mc":[{"id":"1.229554911","rc":[{"atl":[[46,4.16]],"id":52272946}],"con":true,"img":false}]}
{"op":"mcm","clk":"11450330619","pt":1717320625879,"mc":[{"id":"1.229554911","rc":[{"atl":[[48,0]],"id":52272946}],"con":true,"img":false}]}
{"op":"mcm","clk":"11450330776","pt":1717320627796,"mc":[{"id":"1.229554911","rc":[{"atl":[[4.8,9.11]],"id":69033911},{"atl":[[4.8,5.26]],"id":54867443}],"con":true,"img":false}]}
{"op":"mcm","clk":"11450330784","pt":1717320627898,"mc":[{"id":"1.229554911","rc":[{"atl":[[4.8,24.94],[4.9,19.68],[5.2,35.71],[5.4,17.05]],"id":54867443}],"con":true,"img":false}]}
{"op":"mcm","clk":"11450330798","pt":1717320628104,"mc":[{"id":"1.229554911","rc":[{"atl":[[4.9,0]],"id":54867443}],"con":true,"img":false}]}
{"op":"mcm","clk":"11450330857","pt":1717320628782,"mc":[{"id":"1.229554911","rc":[{"atl":[[4.8,3.85],[5.5,4.44]],"id":69033911},{"atl":[[4.8,19.68],[5.5,4.44]],"id":54867443}],"con":true,"img":false}]}
{"op":"mcm","clk":"11450330866","pt":1717320628887,"mc":[{"id":"1.229554911","rc":[{"atl":[[4.8,0],[5.4,39.78]],"id":54867443}],"con":true,"img":false}]}
{"op":"mcm","clk":"11450330876","pt":1717320628990,"mc":[{"id":"1.229554911","rc":[{"atl":[[5.1,19.51],[5.5,26.66],[5.2,11.9],[5.4,17.05]],"id":54867443}],"con":true,"img":false}]}
{"op":"mcm","clk":"11450330933","pt":1717320629604,"mc":[{"id":"1.229554911","rc":[{"atl":[[12,0]],"id":70003369},{"atb":[[9.6,0]],"id":52272946}],"con":true,"img":false}]}
{"op":"mcm","clk":"11450330942","pt":1717320629708,"mc":[{"id":"1.229554911","rc":[{"atl":[[9.4,3.8]],"id":70003369},{"spn":3.3,"spf":"NaN","id":70003369},{"spn":3.72,"spf":"NaN","id":69033911},{"spn":1.69,"spf":"NaN","id":69676139},{"atb":[[12,4.86]],"id":52272946},{"spn":31.25,"spf":"NaN","id":52272946},{"spn":3.87,"spf":"NaN","id":54867443}],"con":true,"img":false}]}
{"op":"mcm","clk":"11450330953","pt":1717320629811,"mc":[{"id":"1.229554911","rc":[{"atb":[[2.5,12.13],[2.64,18.01],[2.58,5],[2.66,2.5]],"id":69033911},{"atl":[[4.9,0]],"id":69033911},{"atl":[[5.2,0]],"id":54867443}],"con":true,"img":false}]}
{"op":"mcm","clk":"11450330965","pt":1717320629873,"mc":[{"id":"1.229554911","rc":[{"atb":[[2.66,15.4]],"id":69033911},{"atl":[[4.8,0]],"id":69033911},{"atl":[[5.1,0]],"id":54867443}],"con":true,"img":false}]}
{"op":"mcm","clk":"11450330971","pt":1717320629971,"mc":[{"id":"1.229554911","rc":[{"atb":[[2.64,14.16]],"id":69033911},{"atl":[[5,12.9],[4.9,5.13]],"id":69033911},{"atl":[[5.3,18.6],[4.9,5.13],[5.6,48.91],[6.2,5],[5.5,4.44],[5.7,2.5],[7,10]],"id":54867443}],"con":true,"img":false}]}
{"op":"mcm","clk":"11450330980","pt":1717320630073,"mc":[{"id":"1.229554911","rc":[{"atl":[[2.02,2.99]],"id":69676139}],"con":true,"img":false}]}
{"op":"mcm","clk":"11450330988","pt":1717320630174,"mc":[{"id":"1.229554911","rc":[{"atl":[[2.02,81.42]],"id":69676139}],"con":true,"img":false}]}
{"op":"mcm","clk":"11450330993","pt":1717320630280,"mc":[{"id":"1.229554911","rc":[{"atl":[[2.1,18.18]],"id":69676139}],"con":true,"img":false}]}
{"op":"mcm","clk":"11450331108","pt":1717320631681,"mc":[{"id":"1.229554911","rc":[{"atl":[[2.02,78.43]],"id":69676139}],"con":true,"img":false}]}
{"op":"mcm","clk":"11450331125","pt":1717320631890,"mc":[{"id":"1.229554911","rc":[{"atl":[[2.02,0]],"id":69676139}],"con":true,"img":false}]}
{"op":"mcm","clk":"11450331137","pt":1717320631997,"mc":[{"id":"1.229554911","rc":[{"atl":[[2.12,165.2]],"id":69676139}],"con":true,"img":false}]}
{"op":"mcm","clk":"11450331153","pt":1717320632203,"mc":[{"id":"1.229554911","rc":[{"atl":[[2.02,2.99]],"id":69676139}],"con":true,"img":false}]}
{"op":"mcm","clk":"11450331312","pt":1717320634074,"mc":[{"id":"1.229554911","rc":[{"atb":[[2.44,2.5],[2.36,5],[2.28,10]],"id":55943164}],"con":true,"img":false}]}
{"op":"mcm","clk":"11450331321","pt":1717320634180,"mc":[{"id":"1.229554911","rc":[{"atb":[[2.44,17.5],[1.96,24.19],[1.92,0],[1.88,0]],"id":55943164}],"con":true,"img":false}]}
{"op":"mcm","clk":"11450331330","pt":1717320634287,"mc":[{"id":"1.229554911","rc":[{"atb":[[1.97,2.13]],"id":55943164}],"con":true,"img":false}]}
{"op":"mcm","clk":"11450331358","pt":1717320634601,"mc":[{"id":"1.229554911","rc":[{"atb":[[1.56,0]],"id":70003369},{"atb":[[1.16,0]],"id":69676139},{"atb":[[1.74,0]],"id":55943164}],"con":true,"img":false}]}
{"op":"mcm","clk":"11450331366","pt":1717320634705,"mc":[{"id":"1.229554911","rc":[{"atb":[[1.65,102.99]],"id":70003369},{"atb":[[1.18,370.93]],"id":69676139},{"atb":[[1.87,34.46]],"id":55943164}],"con":true,"img":false}]}
{"op":"mcm","clk":"11450331428","pt":1717320635582,"mc":[{"id":"1.229554911","rc":[{"atl":[[5.4,39.78]],"id":54867443}],"con":true,"img":false}]}
{"op":"mcm","clk":"11450331436","pt":1717320635697,"mc":[{"id":"1.229554911","rc":[{"atl":[[5.6,27.17]],"id":54867443}],"con":true,"img":false}]}
{"op":"mcm","clk":"11450331474","pt":1717320636207,"mc":[{"id":"1.229554911","rc":[{"atb":[[11.5,0],[12.5,3.66]],"id":52272946}],"con":true,"img":false}]}
{"op":"mcm","clk":"11450331621","pt":1717320638081,"mc":[{"id":"1.229554911","rc":[{"atl":[[2.02,0]],"id":69676139}],"con":true,"img":false}]}
{"op":"mcm","clk":"11450331657","pt":1717320638506,"mc":[{"id":"1.229554911","rc":[{"atl":[[2.26,2.97]],"id":69676139}],"con":true,"img":false}]}
{"op":"mcm","clk":"11450331716","pt":1717320639222,"mc":[{"id":"1.229554911","rc":[{"atb":[[1.22,0]],"id":69676139},{"atl":[[3.3,0]],"id":69676139}],"con":true,"img":false}]}
{"op":"mcm","clk":"11450331724","pt":1717320639321,"mc":[{"id":"1.229554911","rc":[{"atb":[[1.24,71.96]],"id":69676139},{"atl":[[3.55,13.5]],"id":69676139}],"con":true,"img":false}]}
{"op":"mcm","clk":"11450331733","pt":1717320639378,"mc":[{"id":"1.229554911","rc":[{"atb":[[1.25,106.54]],"id":69676139}],"con":true,"img":false}]}
{"op":"mcm","clk":"11450331740","pt":1717320639494,"mc":[{"id":"1.229554911","rc":[{"atb":[[1.23,0]],"id":69676139}],"con":true,"img":false}]}
{"op":"mcm","clk":"11450331774","pt":1717320639999,"mc":[{"id":"1.229554911","rc":[{"atl":[[4.8,21.05]],"id":54867443}],"con":true,"img":false}]}
{"op":"mcm","clk":"11450331781","pt":1717320640105,"mc":[{"id":"1.229554911","rc":[{"atl":[[5.3,0]],"id":54867443}],"con":true,"img":false}]}
{"op":"mcm","clk":"11450331801","pt":1717320640384,"mc":[{"id":"1.229554911","rc":[{"atl":[[5,25],[5.2,2.5]],"id":70003369}],"con":true,"img":false}]}
{"op":"mcm","clk":"11450331825","pt":1717320640700,"mc":[{"id":"1.229554911","rc":[{"atb":[[1.36,128.5],[1.45,0]],"id":70003369},{"atl":[[4.4,5.78],[4.2,8.9]],"id":70003369},{"atb":[[2.32,0],[2.58,0],[2.66,12.9],[2.2,66.96]],"id":69033911},{"atl":[[5.8,0],[5.5,26.66],[4.9,0]],"id":69033911},{"atl":[[4.9,0]],"id":54867443}],"con":true,"img":false}]}
{"op":"mcm","clk":"11450331841","pt":1717320640904,"mc":[{"id":"1.229554911","rc":[{"atl":[[4.2,0]],"id":70003369}],"con":true,"img":false}]}
{"op":"mcm","clk":"11450331849","pt":1717320641012,"mc":[{"id":"1.229554911","rc":[{"atl":[[4.6,31.5]],"id":70003369}],"con":true,"img":false}]}
{"op":"mcm","clk":"11450331896","pt":1717320641633,"mc":[{"id":"1.229554911","rc":[{"atl":[[5.1,0]],"id":69033911},{"atl":[[2.12,71.45],[2.1,0]],"id":69676139},{"atl":[[5.4,22.73]],"id":54867443}],"con":true,"img":false}]}
{"op":"mcm","clk":"11450331905","pt":1717320641686,"mc":[{"id":"1.229554911","rc":[{"atl":[[5,0]],"id":69033911},{"atl":[[4.8,0]],"id":54867443}],"con":true,"img":false}]}
{"op":"mcm","clk":"11450331915","pt":1717320641793,"mc":[{"id":"1.229554911","rc":[{"atl":[[5.2,19.05]],"id":69033911},{"atl":[[5.5,26.66],[5.3,14.08],[5.4,0]],"id":54867443}],"con":true,"img":false}]}
{"op":"mcm","clk":"11450331923","pt":1717320641900,"mc":[{"id":"1.229554911","rc":[{"atl":[[5.3,0]],"id":54867443}],"con":true,"img":false}]}
{"op":"mcm","clk":"11450331931","pt":1717320642001,"mc":[{"id":"1.229554911","rc":[{"atl":[[5.4,18.18]],"id":54867443}],"con":true,"img":false}]}
{"op":"mcm","clk":"11450331978","pt":1717320642622,"mc":[{"id":"1.229554911","rc":[{"atl":[[2.26,0]],"id":69676139}],"con":true,"img":false}]}
{"op":"mcm","clk":"11450332008","pt":1717320642888,"mc":[{"id":"1.229554911","rc":[{"atl":[[2.26,1.43]],"id":69676139}],"con":true,"img":false}]}
{"op":"mcm","clk":"11450332023","pt":1717320643092,"mc":[{"id":"1.229554911","rc":[{"atb":[[2.4,0]],"id":69033911},{"atb":[[2.02,0]],"id":54867443}],"con":true,"img":false}]}
{"op":"mcm","clk":"11450332144","pt":1717320644497,"mc":[{"id":"1.229554911","rc":[{"atl":[[2.26,0]],"id":69676139}],"con":true,"img":false}]}
{"op":"mcm","clk":"11450332151","pt":1717320644601,"mc":[{"id":"1.229554911","rc":[{"atl":[[13,0]],"id":54867443}],"con":true,"img":false}]}
{"op":"mcm","clk":"11450332159","pt":1717320644701,"mc":[{"id":"1.229554911","rc":[{"atl":[[2.24,3.35]],"id":69676139},{"atl":[[14,5.23]],"id":54867443}],"con":true,"img":false}]}
{"op":"mcm","clk":"11450332174","pt":1717320645014,"mc":[{"id":"1.229554911","rc":[{"atb":[[2.3,0],[2.12,0],[2.08,0],[2.16,0]],"id":69033911},{"atl":[[4.9,5.13]],"id":69033911},{"atl":[[2.42,14.08],[2.12,53.59],[2.18,0],[2.14,0]],"id":69676139},{"atl":[[7.4,0],[6.2,0],[6.6,0],[7,0]],"id":55943164},{"atl":[[4.9,5.13]],"id":54867443}],"con":true,"img":false}]}
{"op":"mcm","clk":"11450332184","pt":1717320645117,"mc":[{"id":"1.229554911","rc":[{"atl":[[5.1,19.51]],"id":69033911},{"atl":[[5.3,18.6]],"id":54867443}],"con":true,"img":false}]}
{"op":"mcm","clk":"11450332193","pt":1717320645223,"mc":[{"id":"1.229554911","rc":[{"atl":[[5.2,0]],"id":69033911},{"atl":[[2.12,0]],"id":69676139},{"atl":[[5.4,0]],"id":54867443}],"con":true,"img":false}]}
{"op":"mcm","clk":"11450332200","pt":1717320645328,"mc":[{"id":"1.229554911","rc":[{"atl":[[2.24,67.87]],"id":69676139}],"con":true,"img":false}]}
{"op":"mcm","clk":"11450332206","pt":1717320645382,"mc":[{"id":"1.229554911","rc":[{"atl":[[2.66,2.5]],"id":69676139}],"con":true,"img":false}]}
{"op":"mcm","clk":"11450332214","pt":1717320645484,"mc":[{"id":"1.229554911","rc":[{"atl":[[5,0],[5.3,23.26]],"id":70003369}],"con":true,"img":false}]}
{"op":"mcm","clk":"11450332239","pt":1717320645793,"mc":[{"id":"1.229554911","rc":[{"atl":[[5.8,20.83]],"id":69033911}],"con":true,"img":false}]}
{"op":"mcm","clk":"11450332249","pt":1717320645894,"mc":[{"id":"1.229554911","rc":[{"atb":[[2.2,0],[2.08,64.87]],"id":69033911},{"atl":[[5.5,4.44]],"id":69033911}],"con":true,"img":false}]}
{"op":"mcm","clk":"11450332313","pt":1717320646634,"mc":[{"id":"1.229554911","rc":[{"atl":[[2.24,64.52]],"id":69676139}],"con":true,"img":false}]}
{"op":"mcm","clk":"11450332331","pt":1717320646829,"mc":[{"id":"1.229554911","rc":[{"atl":[[2.24,0]],"id":69676139}],"con":true,"img":false}]}
{"op":"mcm","clk":"11450332339","pt":1717320646884,"mc":[{"id":"1.229554911","rc":[{"atl":[[2.22,2.91],[2.46,123.28]],"id":69676139}],"con":true,"img":false}]}
{"op":"mcm","clk":"11450332477","pt":1717320649010,"mc":[{"id":"1.229554911","rc":[{"atl":[[4.6,24.67]],"id":70003369}],"con":true,"img":false}]}
{"op":"mcm","clk":"11450332516","pt":1717320649639,"mc":[{"id":"1.229554911","rc":[{"atb":[[1.83,0]],"id":70003369},{"atb":[[2.34,0]],"id":69033911},{"atl":[[16.5,0]],"id":69033911},{"atl":[[4.1,0],[4.7,17.26]],"id":69676139},{"atb":[[12,0]],"id":52272946}],"con":true,"img":false}]}
{"op":"mcm","clk":"11450332523","pt":1717320649684,"mc":[{"id":"1.229554911","rc":[{"atb":[[1.98,29.89]],"id":70003369},{"atb":[[2.46,29.89]],"id":69033911},{"atl":[[15,4.18]],"id":69033911},{"atb":[[11,7.18]],"id":52272946}],"con":true,"img":false}]}
{"op":"mcm","clk":"11450332651","pt":1717320651821,"mc":[{"id":"1.229554911","rc":[{"atb":[[12.5,0]],"id":52272946}],"con":true,"img":false}]}
{"op":"mcm","clk":"11450332656","pt":1717320651926,"mc":[{"id":"1.229554911","rc":[{"atb":[[11.5,5.95]],"id":52272946},{"atl":[[4.8,21.05]],"id":54867443}],"con":true,"img":false}]}
{"op":"mcm","clk":"11450332666","pt":1717320652086,"mc":[{"id":"1.229554911","rc":[{"atl":[[5.3,23.26],[5.5,4.44]],"id":54867443}],"con":true,"img":false}]}
{"op":"mcm","clk":"11450332729","pt":1717320652927,"mc":[{"id":"1.229554911","rc":[{"atl":[[4.4,27.72]],"id":70003369}],"con":true,"img":false}]}
{"op":"mcm","clk":"11450332740","pt":1717320653131,"mc":[{"id":"1.229554911","rc":[{"atl":[[4.6,13.66]],"id":70003369}],"con":true,"img":false}]}
{"op":"mcm","clk":"11450332756","pt":1717320653302,"mc":[{"id":"1.229554911","rc":[{"atl":[[5.1,31.71]],"id":69033911},{"atl":[[5.1,12.2]],"id":54867443}],"con":true,"img":false}]}
{"op":"mcm","clk":"11450332763","pt":1717320653397,"mc":[{"id":"1.229554911","rc":[{"atl":[[3.55,0]],"id":69676139},{"atl":[[6.8,0]],"id":55943164},{"atl":[[5.3,0],[5.1,36.59]],"id":54867443}],"con":true,"img":false}]}
{"op":"mcm","clk":"11450332771","pt":1717320653508,"mc":[{"id":"1.229554911","rc":[{"atl":[[3.95,13.5]],"id":69676139},{"atl":[[9,5.97]],"id":55943164}],"con":true,"img":false}]}
{"op":"mcm","clk":"11450332787","pt":1717320653710,"mc":[{"id":"1.229554911","rc":[{"atl":[[4.8,20.3]],"id":69033911}],"con":true,"img":false}]}
{"op":"mcm","clk":"11450332799","pt":1717320653918,"mc":[{"id":"1.229554911","rc":[{"atl":[[5.1,12.19]],"id":69033911}],"con":true,"img":false}]}
{"op":"mcm","clk":"11450333039","pt":1717320657240,"mc":[{"id":"1.229554911","rc":[{"atl":[[4.8,51.76]],"id":70003369},{"atl":[[2.22,68.47]],"id":69676139}],"con":true,"img":false}]}
{"op":"mcm","clk":"11450333047","pt":1717320657299,"mc":[{"id":"1.229554911","rc":[{"atl":[[4.8,19.41]],"id":70003369}],"con":true,"img":false}]}
{"op":"mcm","clk":"11450333053","pt":1717320657447,"mc":[{"id":"1.229554911","rc":[{"atl":[[2.46,68.49]],"id":69676139}],"con":true,"img":false}]}
{"op":"mcm","clk":"11450333118","pt":1717320658228,"mc":[{"id":"1.229554911","rc":[{"atb":[[1.92,0],[1.84,0],[1.88,0]],"id":54867443}],"con":true,"img":false}]}
{"op":"mcm","clk":"11450333220","pt":1717320659634,"mc":[{"id":"1.229554911","rc":[{"atb":[[1.24,5]],"id":69676139}],"con":true,"img":false}]}
{"op":"mcm","clk":"11450333228","pt":1717320659734,"mc":[{"id":"1.229554911","rc":[{"atb":[[1.26,66.96],[1.24,164.81]],"id":69676139}],"con":true,"img":false}]}
{"op":"mcm","clk":"11450333235","pt":1717320659839,"mc":[{"id":"1.229554911","rc":[{"atb":[[1.27,106.54],[1.25,0],[1.24,5]],"id":69676139}],"con":true,"img":false}]}
{"op":"mcm","clk":"11450333248","pt":1717320660052,"mc":[{"id":"1.229554911","rc":[{"atb":[[1.97,2.13],[1.87,0]],"id":70003369},{"atl":[[8.4,0]],"id":70003369},{"atb":[[2.64,0],[2.44,0]],"id":69033911},{"atl":[[17.5,0]],"id":69033911},{"atb":[[1.01,17.35]],"id":69676139},{"atl":[[2.68,0]],"id":69676139},{"atb":[[1.96,0],[1.86,0]],"id":55943164},{"atl":[[8.4,0]],"id":55943164},{"atb":[[2.42,0],[2.62,0]],"id":54867443},{"atl":[[17,0]],"id":54867443}],"con":true,"img":false}]}
{"op":"mcm","clk":"11450333267","pt":1717320660260,"mc":[{"id":"1.229554911","rc":[{"atb":[[2.66,0]],"id":69033911},{"atb":[[1.89,5],[1.85,10],[1.93,2.5]],"id":54867443}],"con":true,"img":false}]}
{"op":"mcm","clk":"11450333276","pt":1717320660323,"mc":[{"id":"1.229554911","rc":[{"atb":[[2.5,30.96]],"id":69033911}],"con":true,"img":false}]}
{"op":"mcm","clk":"11450333336","pt":1717320661156,"mc":[{"id":"1.229554911","rc":[{"atl":[[4.3,5.96]],"id":70003369},{"atl":[[4.9,0],[5.4,4.55]],"id":69033911},{"atl":[[8,7.14],[8.4,10.14],[7.6,3.03],[8.8,16.03]],"id":55943164},{"atl":[[4.9,0],[5.4,4.55]],"id":54867443}],"con":true,"img":false}]}
{"op":"mcm","clk":"11450333349","pt":1717320661319,"mc":[{"id":"1.229554911","rc":[{"atl":[[4.8,0]],"id":69033911},{"atl":[[4.8,0],[5.1,12.2],[5.4,27.28]],"id":54867443}],"con":true,"img":false}]}
{"op":"mcm","clk":"11450333357","pt":1717320661421,"mc":[{"id":"1.229554911","rc":[{"atl":[[5.1,0],[5.2,19.05]],"id":69033911},{"atl":[[2.42,84.5],[2.46,0]],"id":69676139},{"atl":[[5.1,0],[5.3,11.02]],"id":54867443}],"con":true,"img":false}]}
{"op":"mcm","clk":"11450333370","pt":1717320661529,"mc":[{"id":"1.229554911","rc":[{"atl":[[5.2,11.02],[5.4,4.55]],"id":54867443}],"con":true,"img":false}]}
{"op":"mcm","clk":"11450333381","pt":1717320661632,"mc":[{"id":"1.229554911","rc":[{"atl":[[5.2,0],[5.4,26.59]],"id":54867443}],"con":true,"img":false}]}
{"op":"mcm","clk":"11450333463","pt":1717320662736,"mc":[{"id":"1.229554911","rc":[{"atb":[[1.36,0],[1.27,128.5]],"id":70003369},{"atl":[[5.3,0]],"id":69033911}],"con":true,"img":false}]}
{"op":"mcm","clk":"11450333616","pt":1717320664653,"mc":[{"id":"1.229554911","rc":[{"atl":[[4.3,20.68]],"id":70003369}],"con":true,"img":false}]}
{"op":"mcm","clk":"11450333629","pt":1717320664706,"mc":[{"id":"1.229554911","rc":[{"atl":[[4.4,5.78]],"id":70003369}],"con":true,"img":false}]}
{"op":"mcm","clk":"11450333942","pt":1717320668818,"mc":[{"id":"1.229554911","rc":[{"atb":[[11,2.32]],"id":52272946}],"con":true,"img":false}]}
{"op":"mcm","clk":"11450333950","pt":1717320668921,"mc":[{"id":"1.229554911","rc":[{"atb":[[8.6,4.86]],"id":52272946}],"con":true,"img":false}]}
{"op":"mcm","clk":"11450333963","pt":1717320669131,"mc":[{"id":"1.229554911","rc":[{"atl":[[5.6,10.87]],"id":69033911},{"atl":[[5.6,10.87]],"id":54867443}],"con":true,"img":false}]}
{"op":"mcm","clk":"11450333982","pt":1717320669232,"mc":[{"id":"1.229554911","rc":[{"atl":[[5.2,0]],"id":69033911},{"atl":[[5.5,26.66],[5.4,4.55]],"id":54867443}],"con":true,"img":false}]}
{"op":"mcm","clk":"11450333990","pt":1717320669335,"mc":[{"id":"1.229554911","rc":[{"atl":[[5.8,0],[5.3,18.6],[5.9,20.41]],"id":69033911}],"con":true,"img":false}]}
{"op":"mcm","clk":"11450334270","pt":1717320673127,"mc":[{"id":"1.229554911","rc":[{"atl":[[2.22,65.57]],"id":69676139}],"con":true,"img":false}]}
{"op":"mcm","clk":"11450334290","pt":1717320673273,"mc":[{"id":"1.229554911","rc":[{"atl":[[2.66,62.74]],"id":69676139}],"con":true,"img":false}]}
{"op":"mcm","clk":"11450334296","pt":1717320673330,"mc":[{"id":"1.229554911","rc":[{"atl":[[2.22,1.43],[2.42,14.08]],"id":69676139}],"con":true,"img":false}]}
{"op":"mcm","clk":"11450334303","pt":1717320673431,"mc":[{"id":"1.229554911","rc":[{"atl":[[2.42,84.5]],"id":69676139}],"con":true,"img":false}]}
{"op":"mcm","clk":"11450334314","pt":1717320673541,"mc":[{"id":"1.229554911","rc":[{"atl":[[2.66,2.5]],"id":69676139}],"con":true,"img":false}]}
{"op":"mcm","clk":"11450334341","pt":1717320673851,"mc":[{"id":"1.229554911","rc":[{"atb":[[1.97,26.07],[1.87,40.04]],"id":70003369},{"atl":[[8.4,0.07]],"id":70003369},{"atb":[[2.4,24.88],[2.6,14.51]],"id":69033911},{"atl":[[16.5,0.03]],"id":69033911},{"atb":[[1.01,5824.62]],"id":69676139},{"atl":[[2.72,0.3]],"id":69676139},{"atb":[[1.97,26.07],[1.87,74.51]],"id":55943164},{"atl":[[8.4,10.21]],"id":55943164},{"atb":[[2.4,24.88],[2.6,14.51]],"id":54867443},{"atl":[[16.5,0.03]],"id":54867443}],"con":true,"img":false}]}
