{"op":"mcm","clk":"11449075383","pt":1717303241522,"mc":[{"id":"1.229554893","marketDefinition":{"bspMarket":false,"turnInPlayEnabled":false,"persistenceEnabled":false,"marketBaseRate":7.0,"eventId":"33318908","eventTypeId":"4339","numberOfWinners":1,"bettingType":"ODDS","marketType":"QUINELLA","marketTime":"2024-06-02T08:21:00.000Z","suspendTime":"2024-06-02T08:21:00.000Z","bspReconciled":false,"complete":true,"inPlay":false,"crossMatching":true,"runnersVoidable":false,"numberOfActiveRunners":10,"betDelay":0,"status":"OPEN","runners":[{"status":"ACTIVE","sortPriority":1,"id":52671542,"name":"1 - 2 / 2 - 1"},{"status":"ACTIVE","sortPriority":2,"id":52671544,"name":"1 - 4 / 4 - 1"},{"status":"ACTIVE","sortPriority":3,"id":52671545,"name":"1 - 6 / 6 - 1"},{"status":"ACTIVE","sortPriority":4,"id":52671546,"name":"1 - 8 / 8 - 1"},{"status":"ACTIVE","sortPriority":5,"id":52671548,"name":"2 - 4 / 4 - 2"},{"status":"ACTIVE","sortPriority":6,"id":52671549,"name":"2 - 6 / 6 - 2"},{"status":"ACTIVE","sortPriority":7,"id":52671550,"name":"2 - 8 / 8 - 2"},{"status":"ACTIVE","sortPriority":8,"id":52671554,"name":"4 - 6 / 6 - 4"},{"status":"ACTIVE","sortPriority":9,"id":52671555,"name":"4 - 8 / 8 - 4"},{"status":"ACTIVE","sortPriority":10,"id":52671556,"name":"6 - 8 / 8 - 6"}],"regulators":["MR_INT"],"venue":"Murray Bridge","countryCode":"AU","discountAllowed":true,"timezone":"Australia/Adelaide","openDate":"2024-06-02T08:21:00.000Z","version":5962801915,"name":"Quinella","eventName":"Murray Bridge (AUS) 2nd Jun"},"rc":[],"con":true,"img":false}]}
{"op":"mcm","clk":"11449094250","pt":1717303691304,"mc":[{"id":"1.229554893","rc":[{"atb":[[2.4,18.68],[2.3,40.24],[2.2,65.4],[2.1,95.12]],"id":52671550},{"atb":[[18,3.08],[21,1.31],[13,8.72],[15.5,5.41]],"id":52671546},{"atb":[[36,0.75],[19,5.81],[23,3.57],[28,1.94]],"id":52671549},{"atb":[[2.54,33.98],[2.64,15.95],[2.44,54.5],[2.34,78.08]],"id":52671548},{"atb":[[18,1.54],[10.5,11.01],[13,6.54],[15.5,3.61]],"id":52671542},{"atb":[[260,0.3],[310,0.17],[360,0.07],[210,0.5]],"id":52671545},{"atb":[[17,4.9],[19.5,2.83],[24,1.14],[14.5,7.75]],"id":52671544},{"atb":[[2.74,60.13],[3.1,12.46],[2.84,42.65],[2.94,26.97]],"id":52671555},{"atb":[[38,1.41],[48,0.55],[24,4.55],[29,2.8]],"id":52671554},{"atb":[[32,1.69],[42,0.64],[21,5.23],[26,3.14]],"id":52671556}],"con":true,"img":false}]}
{"op":"mcm","clk":"11449095056","pt":1717303714149,"mc":[{"id":"1.229554893","rc":[{"atb":[[2.4,37.37],[2.3,80.49],[2.2,130.8],[2.1,190.25]],"id":52671550},{"atb":[[18,6.16],[21,2.62],[13,17.45],[15.5,10.82]],"id":52671546},{"atb":[[36,1.5],[19,11.63],[23,7.14],[28,3.88]],"id":52671549},{"atb":[[2.54,67.96],[2.64,31.91],[2.44,109],[2.34,156.17]],"id":52671548},{"atb":[[18,3.08],[10.5,22.03],[13,13.08],[15.5,7.23]],"id":52671542},{"atb":[[260,0.61],[310,0.34],[360,0.15],[210,1.01]],"id":52671545},{"atb":[[17,9.81],[19.5,5.67],[24,2.28],[14.5,15.5]],"id":52671544},{"atb":[[2.74,120.27],[3.1,24.92],[2.84,85.3],[2.94,53.94]],"id":52671555},{"atb":[[38,2.83],[48,1.11],[24,9.11],[29,5.61]],"id":52671554},{"atb":[[32,3.39],[42,1.28],[21,10.47],[26,6.28]],"id":52671556}],"con":true,"img":false}]}
{"op":"mcm","clk":"11449095079","pt":1717303714930,"mc":[{"id":"1.229554893","rc":[{"atb":[[18,3.08],[21,1.31],[13,8.72],[15.5,5.41]],"id":52671546},{"atb":[[36,0.75],[19,5.81],[23,3.57],[28,1.94]],"id":52671549},{"atb":[[18,1.54],[10.5,11.01],[13,6.54],[15.5,3.61]],"id":52671542},{"atb":[[260,0.3],[310,0.17],[360,0.07],[210,0.5]],"id":52671545},{"atb":[[38,1.41],[48,0.55],[24,4.55],[29,2.8]],"id":52671554}],"con":true,"img":false}]}
{"op":"mcm","clk":"11449095082","pt":1717303715031,"mc":[{"id":"1.229554893","rc":[{"atb":[[2.54,33.98],[2.64,15.95],[2.44,54.5],[2.34,78.08]],"id":52671548},{"atb":[[17,4.9],[19.5,2.83],[24,1.14],[14.5,7.75]],"id":52671544}],"con":true,"img":false}]}
{"op":"mcm","clk":"11449096540","pt":1717303759566,"mc":[{"id":"1.229554893","rc":[{"atb":[[2.4,18.68],[2.3,40.24],[2.2,65.4],[2.1,95.12]],"id":52671550},{"atb":[[2.74,60.13],[3.1,12.46],[2.84,42.65],[2.94,26.97]],"id":52671555},{"atb":[[32,1.69],[42,0.64],[21,5.23],[26,3.14]],"id":52671556}],"con":true,"img":false}]}
{"op":"mcm","clk":"11449099376","pt":1717303849458,"mc":[{"id":"1.229554893","rc":[{"atb":[[7.4,38.1],[9.4,12.44]],"id":52671546},{"atb":[[2.28,190.55],[2.48,70.62]],"id":52671548},{"atb":[[6.8,42.05],[8.8,13.4]],"id":52671542},{"atb":[[310,0.96],[410,0.25]],"id":52671545},{"atb":[[9.8,11.87],[7.8,35.86]],"id":52671544}],"con":true,"img":false}]}
{"op":"mcm","clk":"11449099382","pt":1717303849562,"mc":[{"id":"1.229554893","rc":[{"atb":[[2.36,76.85],[2.16,210.26]],"id":52671550},{"atb":[[9.8,27.71],[14.5,7.74]],"id":52671549},{"atb":[[2.68,62.22],[2.48,164.8]],"id":52671555},{"atb":[[16.5,6.74],[11.5,23.22]],"id":52671554},{"atb":[[16,6.96],[11,24.39]],"id":52671556}],"con":true,"img":false}]}
{"op":"mcm","clk":"11449113936","pt":1717304262370,"mc":[{"id":"1.229554893","rc":[{"atb":[[2.4,0],[2.3,0],[2.2,0],[2.1,0]],"id":52671550},{"atb":[[2.54,0],[2.64,0],[2.44,0],[2.34,0]],"id":52671548},{"atb":[[260,0],[310,0.78],[360,0],[210,0]],"id":52671545},{"atb":[[2.74,0],[3.1,0],[2.84,0],[2.94,0]],"id":52671555}],"con":true,"img":false}]}
{"op":"mcm","clk":"11449113987","pt":1717304263036,"mc":[{"id":"1.229554893","rc":[{"atb":[[2.32,39.64],[2.42,18.42],[2.22,64.32],[2.12,93.42]],"id":52671550},{"atb":[[2.72,15.21],[2.42,73.69],[2.52,51.63],[2.62,32.3]],"id":52671548},{"atb":[[290,0.18],[340,0.08],[190,0.55],[240,0.33]],"id":52671545},{"atb":[[2.86,42.19],[3.15,12.17],[2.96,26.69],[2.76,59.45]],"id":52671555}],"con":true,"img":false}]}
{"op":"mcm","clk":"11449131921","pt":1717304481642,"mc":[{"id":"1.229554893","rc":[{"atb":[[2.32,0],[2.42,0],[2.22,0],[2.12,0]],"id":52671550},{"atb":[[2.72,0],[2.42,0],[2.52,0],[2.62,0]],"id":52671548},{"atb":[[290,0],[340,0],[190,0],[240,0]],"id":52671545}],"con":true,"img":false}]}
{"op":"mcm","clk":"11449131952","pt":1717304482361,"mc":[{"id":"1.229554893","rc":[{"atb":[[2.4,18.68],[2.3,40.24],[2.2,65.4],[2.1,95.12]],"id":52671550},{"atb":[[2.54,33.98],[2.64,15.95],[2.44,54.5],[2.34,78.08]],"id":52671548},{"atb":[[260,0.3],[310,0.96],[360,0.07],[210,0.5]],"id":52671545}],"con":true,"img":false}]}
{"op":"mcm","clk":"11449170601","pt":1717305074617,"mc":[{"id":"1.229554893","rc":[{"atb":[[2.4,0],[2.3,0],[2.2,0],[2.1,0]],"id":52671550},{"atb":[[2.54,0],[2.64,0],[2.44,0],[2.34,0]],"id":52671548},{"atb":[[260,0],[310,0.78],[360,0],[210,0]],"id":52671545}],"con":true,"img":false}]}
{"op":"mcm","clk":"11449170651","pt":1717305075331,"mc":[{"id":"1.229554893","rc":[{"atb":[[2.32,39.64],[2.42,18.42],[2.22,64.32],[2.12,93.42]],"id":52671550},{"atb":[[2.72,15.21],[2.42,73.69],[2.52,51.63],[2.62,32.3]],"id":52671548},{"atb":[[290,0.18],[340,0.08],[190,0.55],[240,0.33]],"id":52671545}],"con":true,"img":false}]}
{"op":"mcm","clk":"11449179725","pt":1717305207657,"mc":[{"id":"1.229554893","rc":[{"atb":[[2.32,0],[2.42,0],[2.22,0],[2.12,0]],"id":52671550},{"atb":[[2.72,0],[2.42,0],[2.52,0],[2.62,0]],"id":52671548}],"con":true,"img":false}]}
{"op":"mcm","clk":"11449179778","pt":1717305208374,"mc":[{"id":"1.229554893","rc":[{"atb":[[2.4,18.68],[2.3,40.24],[2.2,65.4],[2.1,95.12]],"id":52671550},{"atb":[[2.54,33.98],[2.64,15.95],[2.44,54.5],[2.34,78.08]],"id":52671548}],"con":true,"img":false}]}
{"op":"mcm","clk":"11449212048","pt":1717305658056,"mc":[{"id":"1.229554893","rc":[{"atb":[[2.4,0],[2.3,0],[2.2,0],[2.1,0]],"id":52671550},{"atb":[[18,0],[21,0],[13,0],[15.5,0]],"id":52671546},{"atb":[[2.54,0],[2.64,0],[2.44,0],[2.34,0]],"id":52671548},{"atb":[[18,0],[10.5,0],[13,0],[15.5,0]],"id":52671542},{"atb":[[17,0],[19.5,0],[24,0],[14.5,0]],"id":52671544},{"atb":[[2.86,0],[3.15,0],[2.96,0],[2.76,0]],"id":52671555},{"atb":[[38,0],[48,0],[24,0],[29,0]],"id":52671554},{"atb":[[32,0],[42,0],[21,0],[26,0]],"id":52671556}],"con":true,"img":false}]}
{"op":"mcm","clk":"11449212108","pt":1717305658734,"mc":[{"id":"1.229554893","rc":[{"atb":[[1.99,105.69],[2.28,20.44],[2.18,44.34],[2.08,72.66]],"id":52671550},{"atb":[[16,5.23],[18.5,2.99],[22,1.25],[13.5,8.37]],"id":52671546},{"atb":[[2.4,56.05],[2.5,34.88],[2.3,80.49],[2.6,16.35]],"id":52671548},{"atb":[[17,1.64],[12,7.14],[9.8,11.89],[14.5,3.88]],"id":52671542},{"atb":[[17.5,4.76],[20,2.75],[25,1.09],[15,7.48]],"id":52671544},{"atb":[[3.2,11.89],[2.88,41.74],[2.98,26.43],[2.78,58.78]],"id":52671555},{"atb":[[40,1.34],[50,0.53],[25,4.36],[30,2.71]],"id":52671554},{"atb":[[34,1.59],[44,0.61],[22,4.98],[27,3.02]],"id":52671556}],"con":true,"img":false}]}
{"op":"mcm","clk":"11449212363","pt":1717305661635,"mc":[{"id":"1.229554893","rc":[{"atb":[[2.4,0],[2.5,0],[2.3,0],[2.6,0]],"id":52671548},{"atb":[[17,0],[12,0],[9.8,0],[14.5,0]],"id":52671542},{"atb":[[17.5,0],[20,0],[25,0],[15,0]],"id":52671544}],"con":true,"img":false}]}
{"op":"mcm","clk":"11449212425","pt":1717305662320,"mc":[{"id":"1.229554893","rc":[{"atb":[[2.24,84.38],[2.54,16.99],[2.44,36.33],[2.34,58.56]],"id":52671548},{"atb":[[17.5,1.59],[10,11.63],[12.5,6.82],[15,3.74]],"id":52671542},{"atb":[[17,4.9],[19.5,2.83],[24,1.14],[14.5,7.75]],"id":52671544}],"con":true,"img":false}]}
{"op":"mcm","clk":"11449222807","pt":1717305799206,"mc":[{"id":"1.229554893","rc":[{"atb":[[2.36,0],[2.16,0]],"id":52671550},{"atb":[[7.4,0],[9.4,0]],"id":52671546},{"atb":[[9.8,0],[14.5,0]],"id":52671549},{"atb":[[2.28,0],[2.48,0]],"id":52671548},{"atb":[[6.8,0],[8.8,0]],"id":52671542},{"atb":[[310,0],[410,0]],"id":52671545},{"atb":[[9.8,0],[7.8,0]],"id":52671544},{"atb":[[2.68,0],[2.48,0]],"id":52671555},{"atb":[[16.5,0],[11.5,0]],"id":52671554},{"atb":[[16,0],[11,0]],"id":52671556}],"con":true,"img":false}]}
{"op":"mcm","clk":"11449222984","pt":1717305801742,"mc":[{"id":"1.229554893","rc":[{"atb":[[16,0],[18.5,0],[22,0],[13.5,0]],"id":52671546},{"atb":[[17.5,0],[10,0],[12.5,0],[15,0]],"id":52671542}],"con":true,"img":false}]}
{"op":"mcm","clk":"11449223062","pt":1717305802720,"mc":[{"id":"1.229554893","rc":[{"atb":[[18,3.08],[21,1.31],[13,8.72],[15.5,5.41]],"id":52671546},{"atb":[[18,1.54],[10.5,11.01],[13,6.54],[15.5,3.61]],"id":52671542}],"con":true,"img":false}]}
{"op":"mcm","clk":"11449224642","pt":1717305826166,"mc":[{"id":"1.229554893","rc":[{"atb":[[18,0],[10.5,0],[13,0],[15.5,0]],"id":52671542}],"con":true,"img":false}]}
{"op":"mcm","clk":"11449224679","pt":1717305826834,"mc":[{"id":"1.229554893","rc":[{"atb":[[17.5,1.59],[10,11.63],[12.5,6.82],[15,3.74]],"id":52671542}],"con":true,"img":false}]}
{"op":"mcm","clk":"11449225303","pt":1717305835090,"mc":[{"id":"1.229554893","rc":[{"atb":[[2.32,79.18],[2.12,217.77]],"id":52671550},{"atb":[[8,34.84],[10,11.61]],"id":52671546},{"atb":[[9.8,27.71],[14.5,7.74]],"id":52671549},{"atb":[[2.42,73.61],[2.22,199.92]],"id":52671548},{"atb":[[7.2,39.33],[9.2,12.74]],"id":52671542},{"atb":[[540,0.19],[440,0.55]],"id":52671545},{"atb":[[10.5,11],[8.2,33.87]],"id":52671544},{"atb":[[2.54,158.38],[2.74,60.07]],"id":52671555},{"atb":[[17,6.53],[12,22.17]],"id":52671554},{"atb":[[16.5,6.74],[11.5,23.22]],"id":52671556}],"con":true,"img":false}]}
{"op":"mcm","clk":"11449228452","pt":1717305880590,"mc":[{"id":"1.229554893","rc":[{"atb":[[17.5,0],[10,0],[12.5,0],[15,0]],"id":52671542}],"con":true,"img":false}]}
{"op":"mcm","clk":"11449228458","pt":1717305880693,"mc":[{"id":"1.229554893","rc":[{"atb":[[17,0],[19.5,0],[24,0],[14.5,0]],"id":52671544}],"con":true,"img":false}]}
{"op":"mcm","clk":"11449228501","pt":1717305881325,"mc":[{"id":"1.229554893","rc":[{"atb":[[16.5,1.69],[9.6,12.17],[11.5,7.48],[14,4.02]],"id":52671542}],"con":true,"img":false}]}
{"op":"mcm","clk":"11449228509","pt":1717305881380,"mc":[{"id":"1.229554893","rc":[{"atb":[[16.5,5.06],[19,2.91],[23,1.19],[14,8.05]],"id":52671544}],"con":true,"img":false}]}
{"op":"mcm","clk":"11449228515","pt":1717305881485,"mc":[{"id":"1.229554893","rc":[{"atb":[[2.32,0],[2.12,0]],"id":52671550},{"atb":[[8,0],[10,0]],"id":52671546},{"atb":[[9.8,0],[14.5,0]],"id":52671549},{"atb":[[2.42,0],[2.22,0]],"id":52671548},{"atb":[[7.2,0],[9.2,0]],"id":52671542},{"atb":[[540,0],[440,0]],"id":52671545},{"atb":[[10.5,0],[8.2,0]],"id":52671544},{"atb":[[2.54,0],[2.74,0]],"id":52671555},{"atb":[[17,0],[12,0]],"id":52671554},{"atb":[[16.5,0],[11.5,0]],"id":52671556}],"con":true,"img":false}]}
{"op":"mcm","clk":"11449228569","pt":1717305882321,"mc":[{"id":"1.229554893","rc":[{"atb":[[16.5,0],[19,0],[23,0],[14,0]],"id":52671544}],"con":true,"img":false}]}
{"op":"mcm","clk":"11449228613","pt":1717305883004,"mc":[{"id":"1.229554893","rc":[{"atb":[[16.5,5.06],[19,2.91],[23,1.19],[14,8.05]],"id":52671544}],"con":true,"img":false}]}
{"op":"mcm","clk":"11449228646","pt":1717305883528,"mc":[{"id":"1.229554893","rc":[{"atb":[[1.99,0],[2.28,0],[2.18,0],[2.08,0]],"id":52671550},{"atb":[[2.24,0],[2.54,0],[2.44,0],[2.34,0]],"id":52671548},{"atb":[[16.5,0],[9.6,0],[11.5,0],[14,0]],"id":52671542},{"atb":[[3.2,0],[2.88,0],[2.98,0],[2.78,0]],"id":52671555},{"atb":[[40,0],[50,0],[25,0],[30,0]],"id":52671554},{"atb":[[34,0],[44,0],[22,0],[27,0]],"id":52671556}],"con":true,"img":false}]}
{"op":"mcm","clk":"11449228693","pt":1717305884230,"mc":[{"id":"1.229554893","rc":[{"atb":[[2.02,51.29],[2.12,23.35],[1.91,114.98],[1.96,81.75]],"id":52671550},{"atb":[[2.24,42.19],[2.04,100.61],[2.14,68.84],[2.34,19.52]],"id":52671548},{"atb":[[16,1.74],[11,7.85],[13.5,4.19],[9.4,12.46]],"id":52671542},{"atb":[[2.82,57.49],[2.92,40.88],[3.3,11.37],[3.05,25.52]],"id":52671555},{"atb":[[32,2.53],[42,1.28],[26,4.19],[55,0.49]],"id":52671554},{"atb":[[40,1.34],[50,0.53],[25,4.36],[30,2.71]],"id":52671556}],"con":true,"img":false}]}
{"op":"mcm","clk":"11449231488","pt":1717305923383,"mc":[{"id":"1.229554893","rc":[{"atb":[[2.32,79.18],[2.12,241.13]],"id":52671550},{"atb":[[8,34.84],[10,11.61]],"id":52671546},{"atb":[[9.8,27.71],[14.5,7.74]],"id":52671549},{"atb":[[2.42,73.61],[2.22,199.92]],"id":52671548},{"atb":[[7.2,39.33],[9.2,12.74]],"id":52671542},{"atb":[[540,0.19],[440,0.55]],"id":52671545},{"atb":[[10.5,11],[8.2,33.87]],"id":52671544},{"atb":[[2.54,158.38],[2.74,60.07]],"id":52671555},{"atb":[[17,6.53],[12,22.17]],"id":52671554},{"atb":[[16.5,6.74],[11.5,23.22]],"id":52671556}],"con":true,"img":false}]}
{"op":"mcm","clk":"11449233035","pt":1717305947706,"mc":[{"id":"1.229554893","rc":[{"atb":[[36,0],[19,0],[23,0],[28,0]],"id":52671549}],"con":true,"img":false}]}
{"op":"mcm","clk":"11449233084","pt":1717305948435,"mc":[{"id":"1.229554893","rc":[{"atb":[[34,0.8],[18.5,5.98],[22,3.74],[27,2.01]],"id":52671549}],"con":true,"img":false}]}
{"op":"mcm","clk":"11449233584","pt":1717305955949,"mc":[{"id":"1.229554893","rc":[{"atb":[[2.32,0],[2.12,23.35]],"id":52671550},{"atb":[[8,0],[10,0]],"id":52671546},{"atb":[[9.8,0],[14.5,0]],"id":52671549},{"atb":[[2.42,0],[2.22,0]],"id":52671548},{"atb":[[7.2,0],[9.2,0]],"id":52671542},{"atb":[[540,0],[440,0]],"id":52671545},{"atb":[[10.5,0],[8.2,0]],"id":52671544},{"atb":[[2.54,0],[2.74,0]],"id":52671555},{"atb":[[17,0],[12,0]],"id":52671554},{"atb":[[16.5,0],[11.5,0]],"id":52671556}],"con":true,"img":false}]}
{"op":"mcm","clk":"11449236230","pt":1717305994362,"mc":[{"id":"1.229554893","rc":[{"atb":[[2.24,84.29],[2.04,234.52]],"id":52671550},{"atb":[[9.8,11.87],[7.8,35.86]],"id":52671546},{"atb":[[10.5,25.67],[15.5,7.2]],"id":52671549},{"atb":[[2.36,76.85],[2.16,210.26]],"id":52671548},{"atb":[[8,14.93],[6,48.78]],"id":52671542},{"atb":[[530,0.46],[630,0.16]],"id":52671545},{"atb":[[8,34.84],[10,11.61]],"id":52671544},{"atb":[[2.64,148.72],[2.84,56.81]],"id":52671555},{"atb":[[19,5.8],[14,18.76]],"id":52671554},{"atb":[[18.5,5.97],[13.5,19.51]],"id":52671556}],"con":true,"img":false}]}
{"op":"mcm","clk":"11449237634","pt":1717306014418,"mc":[{"id":"1.229554893","rc":[{"atb":[[2.24,0],[2.04,0]],"id":52671550},{"atb":[[9.8,0],[7.8,0]],"id":52671546},{"atb":[[10.5,0],[15.5,0]],"id":52671549},{"atb":[[2.36,0],[2.16,0]],"id":52671548},{"atb":[[8,0],[6,0]],"id":52671542},{"atb":[[530,0],[630,0]],"id":52671545},{"atb":[[8,0],[10,0]],"id":52671544},{"atb":[[2.64,0],[2.84,0]],"id":52671555},{"atb":[[19,0],[14,0]],"id":52671554},{"atb":[[18.5,0],[13.5,0]],"id":52671556}],"con":true,"img":false}]}
{"op":"mcm","clk":"11449239508","pt":1717306042729,"mc":[{"id":"1.229554893","rc":[{"atb":[[9.8,11.87],[7.8,35.86]],"id":52671546},{"atb":[[2.36,76.85],[2.16,210.26]],"id":52671548},{"atb":[[8,14.93],[6,48.78]],"id":52671542},{"atb":[[530,0.46],[630,0.16]],"id":52671545},{"atb":[[8,34.84],[10,11.61]],"id":52671544}],"con":true,"img":false}]}
{"op":"mcm","clk":"11449239519","pt":1717306042833,"mc":[{"id":"1.229554893","rc":[{"atb":[[2.24,84.29],[2.04,234.52]],"id":52671550},{"atb":[[10.5,25.67],[15.5,7.2]],"id":52671549},{"atb":[[2.64,148.72],[2.84,56.81]],"id":52671555},{"atb":[[19,5.8],[14,18.76]],"id":52671554},{"atb":[[18.5,5.97],[13.5,19.51]],"id":52671556}],"con":true,"img":false}]}
{"op":"mcm","clk":"11449241226","pt":1717306068657,"mc":[{"id":"1.229554893","rc":[{"atb":[[2.24,0],[2.04,0]],"id":52671550},{"atb":[[9.8,0],[7.8,0]],"id":52671546},{"atb":[[10.5,0],[15.5,0]],"id":52671549},{"atb":[[2.36,0],[2.16,0]],"id":52671548},{"atb":[[8,0],[6,0]],"id":52671542},{"atb":[[530,0],[630,0]],"id":52671545},{"atb":[[8,0],[10,0]],"id":52671544},{"atb":[[2.64,0],[2.84,0]],"id":52671555},{"atb":[[19,0],[14,0]],"id":52671554},{"atb":[[18.5,0],[13.5,0]],"id":52671556}],"con":true,"img":false}]}
{"op":"mcm","clk":"11449242774","pt":1717306089400,"mc":[{"id":"1.229554893","rc":[{"atb":[[2.24,84.29],[2.04,234.52]],"id":52671550},{"atb":[[9.8,11.87],[7.8,35.86]],"id":52671546},{"atb":[[10.5,25.67],[15.5,7.2]],"id":52671549},{"atb":[[2.36,76.85],[2.16,210.26]],"id":52671548},{"atb":[[8,14.93],[6,48.78]],"id":52671542},{"atb":[[530,0.46],[630,0.16]],"id":52671545},{"atb":[[8,34.84],[10,11.61]],"id":52671544},{"atb":[[2.64,148.72],[2.84,56.81]],"id":52671555},{"atb":[[19,5.8],[14,18.76]],"id":52671554},{"atb":[[18.5,5.97],[13.5,19.51]],"id":52671556}],"con":true,"img":false}]}
{"op":"mcm","clk":"11449252531","pt":1717306219462,"mc":[{"id":"1.229554893","rc":[{"atb":[[290,0],[340,0],[190,0],[240,0]],"id":52671545}],"con":true,"img":false}]}
{"op":"mcm","clk":"11449252590","pt":1717306220186,"mc":[{"id":"1.229554893","rc":[{"atb":[[300,0.26],[350,0.15],[400,0.07],[250,0.42]],"id":52671545}],"con":true,"img":false}]}
{"op":"mcm","clk":"11449258063","pt":1717306290334,"mc":[{"id":"1.229554893","rc":[{"atb":[[2.24,0],[2.04,0]],"id":52671550},{"atb":[[9.8,0],[7.8,0]],"id":52671546},{"atb":[[10.5,0],[15.5,0]],"id":52671549},{"atb":[[2.36,0],[2.16,0]],"id":52671548},{"atb":[[8,0],[6,0]],"id":52671542},{"atb":[[530,0],[630,0]],"id":52671545},{"atb":[[8,0],[10,0]],"id":52671544},{"atb":[[2.64,0],[2.84,0]],"id":52671555},{"atb":[[19,0],[14,0]],"id":52671554},{"atb":[[18.5,0],[13.5,0]],"id":52671556}],"con":true,"img":false}]}
{"op":"mcm","clk":"11449259933","pt":1717306314682,"mc":[{"id":"1.229554893","rc":[{"atb":[[2.06,230.09],[2.26,82.96]],"id":52671550},{"atb":[[9.8,11.87],[7.8,35.86]],"id":52671546},{"atb":[[9.8,27.71],[14.5,7.74]],"id":52671549},{"atb":[[2.32,79.18],[2.12,217.77]],"id":52671548},{"atb":[[7.4,16.33],[5.7,51.89]],"id":52671542},{"atb":[[540,0.19],[440,0.55]],"id":52671545},{"atb":[[8,34.84],[10,11.61]],"id":52671544},{"atb":[[2.92,95.32],[2.72,141.8]],"id":52671555},{"atb":[[18.5,5.97],[13.5,19.51]],"id":52671554},{"atb":[[18.5,5.97],[13.5,19.51]],"id":52671556}],"con":true,"img":false}]}
{"op":"mcm","clk":"11449262379","pt":1717306345732,"mc":[{"id":"1.229554893","rc":[{"atb":[[2.06,0],[2.26,0]],"id":52671550},{"atb":[[9.8,0],[7.8,0]],"id":52671546},{"atb":[[9.8,0],[14.5,0]],"id":52671549},{"atb":[[2.32,0],[2.12,0]],"id":52671548},{"atb":[[7.4,0],[5.7,0]],"id":52671542},{"atb":[[540,0],[440,0]],"id":52671545},{"atb":[[8,0],[10,0]],"id":52671544},{"atb":[[2.92,40.88],[2.72,0]],"id":52671555},{"atb":[[18.5,0],[13.5,0]],"id":52671554},{"atb":[[18.5,0],[13.5,0]],"id":52671556}],"con":true,"img":false}]}
{"op":"mcm","clk":"11449264600","pt":1717306375342,"mc":[{"id":"1.229554893","rc":[{"atb":[[2.3,80.4],[2.1,221.73]],"id":52671550},{"atb":[[8,34.84],[10,11.61]],"id":52671546},{"atb":[[9.6,28.36],[14,8.04]],"id":52671549},{"atb":[[2.02,239.12],[2.22,85.68]],"id":52671548},{"atb":[[5.6,53.02],[7.2,16.86]],"id":52671542},{"atb":[[400,0.68],[500,0.2]],"id":52671545},{"atb":[[9.8,11.87],[7.8,35.86]],"id":52671544},{"atb":[[2.98,52.79],[2.78,137.02]],"id":52671555},{"atb":[[18.5,5.97],[13.5,19.51]],"id":52671554},{"atb":[[18.5,5.97],[13.5,19.51]],"id":52671556}],"con":true,"img":false}]}
{"op":"mcm","clk":"11449283678","pt":1717306631828,"mc":[{"id":"1.229554893","rc":[{"atb":[[34,0],[18.5,0],[22,0],[27,0]],"id":52671549},{"atb":[[16,0],[11,0],[13.5,0],[9.4,0]],"id":52671542},{"atb":[[300,0],[350,0],[400,0.61],[250,0]],"id":52671545}],"con":true,"img":false}]}
{"op":"mcm","clk":"11449283744","pt":1717306632611,"mc":[{"id":"1.229554893","rc":[{"atb":[[16,6.97],[18.5,4.48],[22,2.49],[27,1]],"id":52671549},{"atb":[[9.2,9.57],[10.5,5.51],[8.2,14.53],[13,2.18]],"id":52671542},{"atb":[[260,0.2],[310,0.08],[160,0.66],[210,0.38]],"id":52671545}],"con":true,"img":false}]}
{"op":"mcm","clk":"11449291984","pt":1717306738905,"mc":[{"id":"1.229554893","rc":[{"atb":[[260,0],[310,0],[160,0],[210,0]],"id":52671545}],"con":true,"img":false}]}
{"op":"mcm","clk":"11449292038","pt":1717306739627,"mc":[{"id":"1.229554893","rc":[{"atb":[[300,0.09],[150,0.7],[200,0.39],[250,0.21]],"id":52671545}],"con":true,"img":false}]}
{"op":"mcm","clk":"11449301937","pt":1717306870185,"mc":[{"id":"1.229554893","rc":[{"atb":[[2.3,0],[2.1,0]],"id":52671550},{"atb":[[8,0],[10,0]],"id":52671546},{"atb":[[9.6,0],[14,0]],"id":52671549},{"atb":[[2.02,0],[2.22,0]],"id":52671548},{"atb":[[5.6,0],[7.2,0]],"id":52671542},{"atb":[[400,0],[500,0]],"id":52671545},{"atb":[[9.8,0],[7.8,0]],"id":52671544},{"atb":[[2.98,0],[2.78,0]],"id":52671555},{"atb":[[18.5,0],[13.5,0]],"id":52671554},{"atb":[[18.5,0],[13.5,0]],"id":52671556}],"con":true,"img":false}]}
{"op":"mcm","clk":"11449302239","pt":1717306874172,"mc":[{"id":"1.229554893","rc":[{"atb":[[18,0],[21,0],[13,0],[15.5,0]],"id":52671546}],"con":true,"img":false}]}
{"op":"mcm","clk":"11449302296","pt":1717306874893,"mc":[{"id":"1.229554893","rc":[{"atb":[[17,4.9],[19.5,2.83],[24,1.14],[14.5,7.75]],"id":52671546}],"con":true,"img":false}]}
{"op":"mcm","clk":"11449306428","pt":1717306931781,"mc":[{"id":"1.229554893","rc":[{"atb":[[8,34.84],[10,11.61]],"id":52671546},{"atb":[[2.02,239.12],[2.22,85.68]],"id":52671548},{"atb":[[5.6,53.02],[7.2,16.86]],"id":52671542},{"atb":[[400,0.61],[500,0.2]],"id":52671545},{"atb":[[9.8,11.87],[7.8,35.86]],"id":52671544}],"con":true,"img":false}]}
{"op":"mcm","clk":"11449306439","pt":1717306931838,"mc":[{"id":"1.229554893","rc":[{"atb":[[2.3,80.4],[2.1,221.73]],"id":52671550},{"atb":[[9.6,28.36],[14,8.04]],"id":52671549},{"atb":[[2.98,52.79],[2.78,137.02]],"id":52671555},{"atb":[[18.5,5.97],[13.5,19.51]],"id":52671554},{"atb":[[18.5,5.97],[13.5,19.51]],"id":52671556}],"con":true,"img":false}]}
{"op":"mcm","clk":"11449307395","pt":1717306946588,"mc":[{"id":"1.229554893","rc":[{"atb":[[16.5,0],[19,0],[23,0],[14,0]],"id":52671544}],"con":true,"img":false}]}
{"op":"mcm","clk":"11449307440","pt":1717306947251,"mc":[{"id":"1.229554893","rc":[{"atb":[[18,4.61],[15.5,7.21]],"id":52671544}],"con":true,"img":false}]}
{"op":"mcm","clk":"11449307447","pt":1717306947350,"mc":[{"id":"1.229554893","rc":[{"atb":[[21,2.62],[26,1.05]],"id":52671544}],"con":true,"img":false}]}
{"op":"mcm","clk":"11449307459","pt":1717306947557,"mc":[{"id":"1.229554893","rc":[{"atb":[[2.02,0],[2.12,0],[1.91,0],[1.96,0]],"id":52671550},{"atb":[[2.24,0],[2.04,0],[2.14,0],[2.34,0]],"id":52671548}],"con":true,"img":false}]}
{"op":"mcm","clk":"11449307467","pt":1717306947663,"mc":[{"id":"1.229554893","rc":[{"atb":[[2.82,0],[2.92,0],[3.3,0],[3.05,0]],"id":52671555}],"con":true,"img":false}]}
{"op":"mcm","clk":"11449307506","pt":1717306948278,"mc":[{"id":"1.229554893","rc":[{"atb":[[2.4,18.68],[2.3,120.65],[2.2,65.4],[2.1,316.86]],"id":52671550},{"atb":[[2.32,59.45],[2.22,171.45],[2.42,36.84],[2.52,17.21]],"id":52671548}],"con":true,"img":false}]}
{"op":"mcm","clk":"11449307513","pt":1717306948381,"mc":[{"id":"1.229554893","rc":[{"atb":[[4.6,7.27],[4.1,16.88],[3.8,28.03],[3.55,41.03]],"id":52671555}],"con":true,"img":false}]}
{"op":"mcm","clk":"11449334068","pt":1717307327945,"mc":[{"id":"1.229554893","rc":[{"atb":[[2.3,40.24],[2.1,95.12]],"id":52671550},{"atb":[[8,0],[10,0]],"id":52671546},{"atb":[[9.6,0],[14,0]],"id":52671549},{"atb":[[2.02,0],[2.22,85.76]],"id":52671548},{"atb":[[5.6,0],[7.2,0]],"id":52671542},{"atb":[[400,0],[500,0]],"id":52671545},{"atb":[[9.8,0],[7.8,0]],"id":52671544},{"atb":[[2.98,0],[2.78,0]],"id":52671555},{"atb":[[18.5,0],[13.5,0]],"id":52671554},{"atb":[[18.5,0],[13.5,0]],"id":52671556}],"con":true,"img":false}]}
{"op":"mcm","clk":"11449335823","pt":1717307354674,"mc":[{"id":"1.229554893","rc":[{"atb":[[8,34.84],[10,11.61]],"id":52671546},{"atb":[[2.02,239.12],[2.22,171.45]],"id":52671548},{"atb":[[5.6,53.02],[7.2,16.86]],"id":52671542},{"atb":[[400,0.61],[500,0.2]],"id":52671545},{"atb":[[9.8,11.87],[7.8,35.86]],"id":52671544}],"con":true,"img":false}]}
{"op":"mcm","clk":"11449335833","pt":1717307354781,"mc":[{"id":"1.229554893","rc":[{"atb":[[2.3,120.65],[2.1,316.86]],"id":52671550},{"atb":[[9.6,28.36],[14,8.04]],"id":52671549},{"atb":[[2.98,52.79],[2.78,137.02]],"id":52671555},{"atb":[[18.5,5.97],[13.5,19.51]],"id":52671554},{"atb":[[18.5,5.97],[13.5,19.51]],"id":52671556}],"con":true,"img":false}]}
{"op":"mcm","clk":"11449341394","pt":1717307438903,"mc":[{"id":"1.229554893","rc":[{"atb":[[2.3,40.24],[2.1,95.12]],"id":52671550},{"atb":[[8,0],[10,0]],"id":52671546},{"atb":[[9.6,0],[14,0]],"id":52671549},{"atb":[[2.02,0],[2.22,85.76]],"id":52671548},{"atb":[[5.6,0],[7.2,0]],"id":52671542},{"atb":[[400,0],[500,0]],"id":52671545},{"atb":[[9.8,0],[7.8,0]],"id":52671544},{"atb":[[2.98,0],[2.78,0]],"id":52671555},{"atb":[[18.5,0],[13.5,0]],"id":52671554},{"atb":[[18.5,0],[13.5,0]],"id":52671556}],"con":true,"img":false}]}
{"op":"mcm","clk":"11449342055","pt":1717307452116,"mc":[{"id":"1.229554893","rc":[{"atb":[[2.06,230.09],[2.26,82.96]],"id":52671550},{"atb":[[9.8,11.87],[7.8,35.86]],"id":52671546},{"atb":[[9.6,28.36],[14,8.04]],"id":52671549},{"atb":[[2.06,230.09],[2.26,82.96]],"id":52671548},{"atb":[[5.6,53.02],[7.2,16.86]],"id":52671542},{"atb":[[390,0.62],[490,0.21]],"id":52671545},{"atb":[[9.8,11.87],[7.8,35.86]],"id":52671544},{"atb":[[2.8,135.5],[3,52.26]],"id":52671555},{"atb":[[18.5,5.97],[13.5,19.51]],"id":52671554},{"atb":[[18.5,5.97],[13.5,19.51]],"id":52671556}],"con":true,"img":false}]}
{"op":"mcm","clk":"11449342827","pt":1717307467273,"mc":[{"id":"1.229554893","rc":[{"atb":[[2.4,0],[2.3,0],[2.2,0],[2.1,0]],"id":52671550},{"atb":[[17,0],[19.5,0],[24,0],[14.5,0]],"id":52671546},{"atb":[[18,0],[21,0],[26,0],[15.5,0]],"id":52671544},{"atb":[[4.6,0],[4.1,0],[3.8,0],[3.55,0]],"id":52671555}],"con":true,"img":false}]}
{"op":"mcm","clk":"11449342860","pt":1717307467940,"mc":[{"id":"1.229554893","rc":[{"atb":[[2.36,19.23],[2.06,328.81],[2.26,124.48],[2.16,67.65]],"id":52671550},{"atb":[[16.5,5.06],[19,2.91],[23,1.19],[14,8.05]],"id":52671546},{"atb":[[17.5,4.76],[20,2.75],[25,1.09],[15,7.48]],"id":52671544},{"atb":[[4.3,7.93],[3.4,43.6],[3.9,18.04],[3.65,29.61]],"id":52671555}],"con":true,"img":false}]}
{"op":"mcm","clk":"11449363591","pt":1717307963301,"mc":[{"id":"1.229554893","rc":[{"atb":[[2.06,98.71],[2.26,41.52]],"id":52671550},{"atb":[[9.8,0],[7.8,0]],"id":52671546},{"atb":[[9.6,0],[14,0]],"id":52671549},{"atb":[[2.06,0],[2.26,0]],"id":52671548},{"atb":[[5.6,0],[7.2,0]],"id":52671542},{"atb":[[390,0],[490,0]],"id":52671545},{"atb":[[9.8,0],[7.8,0]],"id":52671544},{"atb":[[2.8,0],[3,0]],"id":52671555},{"atb":[[18.5,0],[13.5,0]],"id":52671554},{"atb":[[18.5,0],[13.5,0]],"id":52671556}],"con":true,"img":false}]}
{"op":"mcm","clk":"11449365902","pt":1717308010249,"mc":[{"id":"1.229554893","rc":[{"atb":[[9.8,11.87],[7.8,35.86]],"id":52671546},{"atb":[[2.06,230.09],[2.26,82.96]],"id":52671548},{"atb":[[5.6,53.02],[7.2,16.86]],"id":52671542},{"atb":[[390,0.62],[490,0.21]],"id":52671545},{"atb":[[9.8,11.87],[7.8,35.86]],"id":52671544}],"con":true,"img":false}]}
{"op":"mcm","clk":"11449365911","pt":1717308010405,"mc":[{"id":"1.229554893","rc":[{"atb":[[2.06,328.81],[2.26,124.48]],"id":52671550},{"atb":[[9.6,28.36],[14,8.04]],"id":52671549},{"atb":[[2.8,135.5],[3,52.26]],"id":52671555},{"atb":[[18.5,5.97],[13.5,19.51]],"id":52671554},{"atb":[[18.5,5.97],[13.5,19.51]],"id":52671556}],"con":true,"img":false}]}
{"op":"mcm","clk":"11449398387","pt":1717308580982,"mc":[{"id":"1.229554893","rc":[{"atb":[[2.36,0],[2.06,230.09],[2.26,82.96],[2.16,0]],"id":52671550},{"atb":[[16.5,0],[19,0],[23,0],[14,0]],"id":52671546},{"atb":[[17.5,0],[20,0],[25,0],[15,0]],"id":52671544},{"atb":[[4.3,0],[3.4,0],[3.9,0],[3.65,0]],"id":52671555}],"con":true,"img":false}]}
{"op":"mcm","clk":"11449398434","pt":1717308581658,"mc":[{"id":"1.229554893","rc":[{"atb":[[2.4,18.68],[2.3,40.24],[2.2,65.4],[2.1,95.12]],"id":52671550},{"atb":[[17,4.9],[19.5,2.83],[24,1.14],[14.5,7.75]],"id":52671546},{"atb":[[18,4.61],[21,2.62],[26,1.05],[15.5,7.21]],"id":52671544},{"atb":[[4.6,7.27],[4.1,16.88],[3.8,28.03],[3.55,41.03]],"id":52671555}],"con":true,"img":false}]}
{"op":"mcm","clk":"11449398984","pt":1717308589556,"mc":[{"id":"1.229554893","rc":[{"atb":[[2.4,0],[2.3,0],[2.2,0],[2.1,0]],"id":52671550},{"atb":[[17,0],[19.5,0],[24,0],[14.5,0]],"id":52671546},{"atb":[[18,0],[21,0],[26,0],[15.5,0]],"id":52671544},{"atb":[[4.6,0],[4.1,0],[3.8,0],[3.55,0]],"id":52671555}],"con":true,"img":false}]}
{"op":"mcm","clk":"11449399037","pt":1717308590274,"mc":[{"id":"1.229554893","rc":[{"atb":[[2.36,19.23],[2.06,328.81],[2.26,124.48],[2.16,67.65]],"id":52671550},{"atb":[[16.5,5.06],[19,2.91],[23,1.19],[14,8.05]],"id":52671546},{"atb":[[17.5,4.76],[20,2.75],[25,1.09],[15,7.48]],"id":52671544},{"atb":[[4.3,7.93],[3.4,43.6],[3.9,18.04],[3.65,29.61]],"id":52671555}],"con":true,"img":false}]}
{"op":"mcm","clk":"11449433543","pt":1717309070311,"mc":[{"id":"1.229554893","rc":[{"atb":[[2.06,98.71],[2.26,41.52]],"id":52671550},{"atb":[[9.8,0],[7.8,0]],"id":52671546},{"atb":[[9.6,0],[14,0]],"id":52671549},{"atb":[[2.06,0],[2.26,0]],"id":52671548},{"atb":[[5.6,0],[7.2,0]],"id":52671542},{"atb":[[390,0],[490,0]],"id":52671545},{"atb":[[9.8,0],[7.8,0]],"id":52671544},{"atb":[[2.8,0],[3,0]],"id":52671555},{"atb":[[18.5,0],[13.5,0]],"id":52671554},{"atb":[[18.5,0],[13.5,0]],"id":52671556}],"con":true,"img":false}]}
{"op":"mcm","clk":"11449436224","pt":1717309109717,"mc":[{"id":"1.229554893","rc":[{"atb":[[2.06,328.81],[2.26,124.48]],"id":52671550},{"atb":[[9.8,11.87],[7.8,35.86]],"id":52671546},{"atb":[[9.6,28.36],[14,8.04]],"id":52671549},{"atb":[[2.06,230.09],[2.26,82.96]],"id":52671548},{"atb":[[5.6,53.02],[7.2,16.86]],"id":52671542},{"atb":[[390,0.62],[490,0.21]],"id":52671545},{"atb":[[9.8,11.87],[7.8,35.86]],"id":52671544},{"atb":[[2.8,135.5],[3,52.26]],"id":52671555},{"atb":[[18.5,5.97],[13.5,19.51]],"id":52671554},{"atb":[[18.5,5.97],[13.5,19.51]],"id":52671556}],"con":true,"img":false}]}
{"op":"mcm","clk":"11449444489","pt":1717309238819,"mc":[{"id":"1.229554893","rc":[{"atb":[[16,0],[18.5,0],[22,0],[27,0]],"id":52671549},{"atb":[[2.32,0],[2.42,0],[2.22,0],[2.52,0]],"id":52671548}],"con":true,"img":false}]}
{"op":"mcm","clk":"11449444533","pt":1717309239543,"mc":[{"id":"1.229554893","rc":[{"atb":[[18,4.61],[21,2.62],[26,1.05],[15.5,7.21]],"id":52671549},{"atb":[[2.4,37.37],[2.5,17.44],[2.3,60.36],[2.2,87.2]],"id":52671548}],"con":true,"img":false}]}
{"op":"mcm","clk":"11449444912","pt":1717309245334,"mc":[{"id":"1.229554893","rc":[{"atb":[[18,0],[21,0],[26,0],[15.5,0]],"id":52671549}],"con":true,"img":false}]}
{"op":"mcm","clk":"11449444951","pt":1717309246052,"mc":[{"id":"1.229554893","rc":[{"atb":[[16,6.97],[18.5,4.48],[22,2.49],[27,1]],"id":52671549}],"con":true,"img":false}]}
{"op":"mcm","clk":"11449445121","pt":1717309248747,"mc":[{"id":"1.229554893","rc":[{"atb":[[16,0],[18.5,0],[22,0],[27,0]],"id":52671549}],"con":true,"img":false}]}
{"op":"mcm","clk":"11449445160","pt":1717309249474,"mc":[{"id":"1.229554893","rc":[{"atb":[[18,4.61],[21,2.62],[26,1.05],[15.5,7.21]],"id":52671549}],"con":true,"img":false}]}
{"op":"mcm","clk":"11449486653","pt":1717309749298,"mc":[{"id":"1.229554893","rc":[{"atb":[[2.4,0],[2.5,0],[2.3,0],[2.2,0]],"id":52671548}],"con":true,"img":false}]}
{"op":"mcm","clk":"11449486698","pt":1717309749976,"mc":[{"id":"1.229554893","rc":[{"atb":[[2.32,59.45],[2.42,36.84],[2.22,85.76],[2.52,17.21]],"id":52671548}],"con":true,"img":false}]}
{"op":"mcm","clk":"11449486860","pt":1717309752299,"mc":[{"id":"1.229554893","rc":[{"atb":[[2.32,0],[2.42,0],[2.22,0],[2.52,0]],"id":52671548}],"con":true,"img":false}]}
{"op":"mcm","clk":"11449486917","pt":1717309753021,"mc":[{"id":"1.229554893","rc":[{"atb":[[2.4,37.37],[2.5,17.44],[2.3,60.36],[2.2,87.2]],"id":52671548}],"con":true,"img":false}]}
{"op":"mcm","clk":"11449497935","pt":1717309918839,"mc":[{"id":"1.229554893","rc":[{"atb":[[2.06,98.71],[2.26,41.52]],"id":52671550},{"atb":[[9.8,0],[7.8,0]],"id":52671546},{"atb":[[9.6,0],[14,0]],"id":52671549},{"atb":[[2.06,0],[2.26,0]],"id":52671548},{"atb":[[5.6,0],[7.2,0]],"id":52671542},{"atb":[[390,0],[490,0]],"id":52671545},{"atb":[[9.8,0],[7.8,0]],"id":52671544},{"atb":[[2.8,0],[3,0]],"id":52671555},{"atb":[[18.5,0],[13.5,0]],"id":52671554},{"atb":[[18.5,0],[13.5,0]],"id":52671556}],"con":true,"img":false}]}
{"op":"mcm","clk":"11449500037","pt":1717309954985,"mc":[{"id":"1.229554893","rc":[{"atb":[[2.06,328.81],[2.26,124.48]],"id":52671550},{"atb":[[9.8,11.87],[7.8,35.86]],"id":52671546},{"atb":[[9.6,28.36],[14,8.04]],"id":52671549},{"atb":[[2.06,230.09],[2.26,82.96]],"id":52671548},{"atb":[[5.6,53.02],[7.2,16.86]],"id":52671542},{"atb":[[390,0.62],[490,0.21]],"id":52671545},{"atb":[[9.8,11.87],[7.8,35.86]],"id":52671544},{"atb":[[2.8,135.5],[3,52.26]],"id":52671555},{"atb":[[18.5,5.97],[13.5,19.51]],"id":52671554},{"atb":[[18.5,5.97],[13.5,19.51]],"id":52671556}],"con":true,"img":false}]}
{"op":"mcm","clk":"11449501254","pt":1717309976293,"mc":[{"id":"1.229554893","rc":[{"atb":[[18,0],[21,0],[26,0],[15.5,0]],"id":52671549}],"con":true,"img":false}]}
{"op":"mcm","clk":"11449501293","pt":1717309976970,"mc":[{"id":"1.229554893","rc":[{"atb":[[16,6.97],[18.5,4.48],[22,2.49],[27,1]],"id":52671549}],"con":true,"img":false}]}
{"op":"mcm","clk":"11449532194","pt":1717310488017,"mc":[{"id":"1.229554893","rc":[{"atb":[[2.06,98.71],[2.26,41.52]],"id":52671550},{"atb":[[9.8,0],[7.8,0]],"id":52671546},{"atb":[[9.6,0],[14,0]],"id":52671549},{"atb":[[2.06,0],[2.26,0]],"id":52671548},{"atb":[[5.6,0],[7.2,0]],"id":52671542},{"atb":[[390,0],[490,0]],"id":52671545},{"atb":[[9.8,0],[7.8,0]],"id":52671544},{"atb":[[2.8,0],[3,0]],"id":52671555},{"atb":[[18.5,0],[13.5,0]],"id":52671554},{"atb":[[18.5,0],[13.5,0]],"id":52671556}],"con":true,"img":false}]}
{"op":"mcm","clk":"11449533863","pt":1717310515777,"mc":[{"id":"1.229554893","rc":[{"atb":[[8,34.84],[10,11.61]],"id":52671546},{"atb":[[2.28,81.66],[2.08,225.83]],"id":52671548},{"atb":[[5.6,53.02],[7.2,16.86]],"id":52671542},{"atb":[[350,0.29],[250,1.19]],"id":52671545},{"atb":[[8,34.84],[10,11.61]],"id":52671544}],"con":true,"img":false}]}
{"op":"mcm","clk":"11449533871","pt":1717310515879,"mc":[{"id":"1.229554893","rc":[{"atb":[[2.28,81.66],[2.08,225.83]],"id":52671550},{"atb":[[9.2,29.74],[13,8.71]],"id":52671549},{"atb":[[2.8,135.5],[3,52.26]],"id":52671555},{"atb":[[17.5,6.33],[12.5,21.2]],"id":52671554},{"atb":[[17.5,6.33],[12.5,21.2]],"id":52671556}],"con":true,"img":false}]}
{"op":"mcm","clk":"11449546209","pt":1717310727222,"mc":[{"id":"1.229554893","rc":[{"atb":[[16,0],[18.5,0],[22,0],[27,0]],"id":52671549}],"con":true,"img":false}]}
{"op":"mcm","clk":"11449546214","pt":1717310727319,"mc":[{"id":"1.229554893","rc":[{"atb":[[2.36,0],[2.06,0],[2.26,0],[2.16,0]],"id":52671550},{"atb":[[16.5,0],[19,0],[23,0],[14,0]],"id":52671546},{"atb":[[17.5,0],[20,0],[25,0],[15,0]],"id":52671544},{"atb":[[4.3,0],[3.4,0],[3.9,0],[3.65,0]],"id":52671555}],"con":true,"img":false}]}
{"op":"mcm","clk":"11449546277","pt":1717310728400,"mc":[{"id":"1.229554893","rc":[{"atb":[[2.4,18.68],[2.3,40.24],[2.2,65.4],[2.1,95.12]],"id":52671550},{"atb":[[17,4.9],[19.5,2.83],[24,1.14],[14.5,7.75]],"id":52671546},{"atb":[[18,4.61],[21,2.62],[26,1.05],[15.5,7.21]],"id":52671549},{"atb":[[18,4.61],[21,2.62],[26,1.05],[15.5,7.21]],"id":52671544},{"atb":[[4.6,7.27],[4.1,16.88],[3.8,28.03],[3.55,41.03]],"id":52671555}],"con":true,"img":false}]}
{"op":"mcm","clk":"11449550478","pt":1717310796927,"mc":[{"id":"1.229554893","rc":[{"atb":[[2.28,0],[2.08,0]],"id":52671550},{"atb":[[8,0],[10,0]],"id":52671546},{"atb":[[9.2,0],[13,0]],"id":52671549},{"atb":[[2.28,0],[2.08,0]],"id":52671548},{"atb":[[5.6,0],[7.2,0]],"id":52671542},{"atb":[[350,0],[250,0.21]],"id":52671545},{"atb":[[8,0],[10,0]],"id":52671544},{"atb":[[2.8,0],[3,0]],"id":52671555},{"atb":[[17.5,0],[12.5,0]],"id":52671554},{"atb":[[17.5,0],[12.5,0]],"id":52671556}],"con":true,"img":false}]}
{"op":"mcm","clk":"11449553110","pt":1717310844499,"mc":[{"id":"1.229554893","rc":[{"atb":[[2.28,81.66],[2.08,225.83]],"id":52671550},{"atb":[[8,34.84],[10,11.61]],"id":52671546},{"atb":[[9.2,29.74],[13,8.71]],"id":52671549},{"atb":[[2.28,81.66],[2.08,225.83]],"id":52671548},{"atb":[[5.6,53.02],[7.2,16.86]],"id":52671542},{"atb":[[350,0.29],[250,1.19]],"id":52671545},{"atb":[[8,34.84],[10,11.61]],"id":52671544},{"atb":[[2.8,135.5],[3,52.26]],"id":52671555},{"atb":[[17.5,6.33],[12.5,21.2]],"id":52671554},{"atb":[[17.5,6.33],[12.5,21.2]],"id":52671556}],"con":true,"img":false}]}
{"op":"mcm","clk":"11449566096","pt":1717311084093,"mc":[{"id":"1.229554893","rc":[{"atb":[[2.4,0],[2.3,0],[2.2,0],[2.1,0]],"id":52671550},{"atb":[[17,0],[19.5,0],[24,0],[14.5,0]],"id":52671546},{"atb":[[18,0],[21,0],[26,0],[15.5,0]],"id":52671544},{"atb":[[4.6,0],[4.1,0],[3.8,0],[3.55,0]],"id":52671555}],"con":true,"img":false}]}
{"op":"mcm","clk":"11449566102","pt":1717311084190,"mc":[{"id":"1.229554893","rc":[{"atb":[[2.4,0],[2.5,0],[2.3,0],[2.2,0]],"id":52671548}],"con":true,"img":false}]}
{"op":"mcm","clk":"11449566136","pt":1717311084760,"mc":[{"id":"1.229554893","rc":[{"atb":[[2.36,19.23],[2.06,98.71],[2.26,41.52],[2.16,67.65]],"id":52671550},{"atb":[[16.5,5.06],[19,2.91],[23,1.19],[14,8.05]],"id":52671546},{"atb":[[17.5,4.76],[20,2.75],[25,1.09],[15,7.48]],"id":52671544},{"atb":[[4.3,7.93],[3.4,43.6],[3.9,18.04],[3.65,29.61]],"id":52671555}],"con":true,"img":false}]}
{"op":"mcm","clk":"11449566141","pt":1717311084908,"mc":[{"id":"1.229554893","rc":[{"atb":[[2.32,59.45],[2.42,36.84],[2.22,85.76],[2.52,17.21]],"id":52671548}],"con":true,"img":false}]}
{"op":"mcm","clk":"11449566885","pt":1717311098706,"mc":[{"id":"1.229554893","rc":[{"atb":[[2.32,0],[2.42,0],[2.22,0],[2.52,0]],"id":52671548}],"con":true,"img":false}]}
{"op":"mcm","clk":"11449566927","pt":1717311099374,"mc":[{"id":"1.229554893","rc":[{"atb":[[2.4,37.37],[2.5,17.44],[2.3,60.36],[2.2,87.2]],"id":52671548}],"con":true,"img":false}]}
{"op":"mcm","clk":"11449578753","pt":1717311307305,"mc":[{"id":"1.229554893","rc":[{"atb":[[21,0]],"id":52671549}],"con":true,"img":false}]}
{"op":"mcm","clk":"11449578761","pt":1717311307407,"mc":[{"id":"1.229554893","rc":[{"atb":[[18,0],[26,0],[15.5,0]],"id":52671549}],"con":true,"img":false}]}
{"op":"mcm","clk":"11449578791","pt":1717311308025,"mc":[{"id":"1.229554893","rc":[{"atb":[[22,2.49]],"id":52671549}],"con":true,"img":false}]}
{"op":"mcm","clk":"11449578794","pt":1717311308128,"mc":[{"id":"1.229554893","rc":[{"atb":[[16,6.97],[18.5,4.48],[27,1]],"id":52671549}],"con":true,"img":false}]}
{"op":"mcm","clk":"11449589833","pt":1717311499605,"mc":[{"id":"1.229554893","rc":[{"atb":[[16,0],[18.5,0],[22,0],[27,0]],"id":52671549}],"con":true,"img":false}]}
{"op":"mcm","clk":"11449589872","pt":1717311500276,"mc":[{"id":"1.229554893","rc":[{"atb":[[18,4.61],[21,2.62],[26,1.05],[15.5,7.21]],"id":52671549}],"con":true,"img":false}]}
{"op":"mcm","clk":"11449590355","pt":1717311508474,"mc":[{"id":"1.229554893","rc":[{"atb":[[18,0],[21,0],[26,0],[15.5,0]],"id":52671549}],"con":true,"img":false}]}
{"op":"mcm","clk":"11449590406","pt":1717311509298,"mc":[{"id":"1.229554893","rc":[{"atb":[[16,6.97],[18.5,4.48],[22,2.49],[27,1]],"id":52671549}],"con":true,"img":false}]}
{"op":"mcm","clk":"11449591411","pt":1717311529910,"mc":[{"id":"1.229554893","rc":[{"atb":[[16,0],[18.5,0],[22,0],[27,0]],"id":52671549}],"con":true,"img":false}]}
{"op":"mcm","clk":"11449591440","pt":1717311530583,"mc":[{"id":"1.229554893","rc":[{"atb":[[18,4.61],[21,2.62],[26,1.05],[15.5,7.21]],"id":52671549}],"con":true,"img":false}]}
{"op":"mcm","clk":"11449601385","pt":1717311718440,"mc":[{"id":"1.229554893","rc":[{"atb":[[2.28,0],[2.08,0]],"id":52671550},{"atb":[[8,0],[10,0]],"id":52671546},{"atb":[[9.2,0],[13,0]],"id":52671549},{"atb":[[2.28,0],[2.08,0]],"id":52671548},{"atb":[[5.6,0],[7.2,0]],"id":52671542},{"atb":[[350,0],[250,0.21]],"id":52671545},{"atb":[[8,0],[10,0]],"id":52671544},{"atb":[[2.8,0],[3,0]],"id":52671555},{"atb":[[17.5,0],[12.5,0]],"id":52671554},{"atb":[[17.5,0],[12.5,0]],"id":52671556}],"con":true,"img":false}]}
{"op":"mcm","clk":"11449603720","pt":1717311762398,"mc":[{"id":"1.229554893","rc":[{"atb":[[2.28,81.66],[2.08,225.83]],"id":52671550},{"atb":[[8,34.84],[10,11.61]],"id":52671546},{"atb":[[9.2,29.74],[13,8.71]],"id":52671549},{"atb":[[2.28,81.66],[2.08,225.83]],"id":52671548},{"atb":[[5.6,53.02],[7.2,16.86]],"id":52671542},{"atb":[[350,0.29],[250,1.19]],"id":52671545},{"atb":[[8,34.84],[10,11.61]],"id":52671544},{"atb":[[2.8,135.5],[3,52.26]],"id":52671555},{"atb":[[17.5,6.33],[12.5,21.2]],"id":52671554},{"atb":[[17.5,6.33],[12.5,21.2]],"id":52671556}],"con":true,"img":false}]}
{"op":"mcm","clk":"11449639293","pt":1717312554877,"mc":[{"id":"1.229554893","rc":[{"atb":[[2.28,0],[2.08,0]],"id":52671550},{"atb":[[8,0],[10,0]],"id":52671546},{"atb":[[9.2,0],[13,0]],"id":52671549},{"atb":[[2.28,0],[2.08,0]],"id":52671548},{"atb":[[5.6,0],[7.2,0]],"id":52671542},{"atb":[[350,0],[250,0.21]],"id":52671545},{"atb":[[8,0],[10,0]],"id":52671544},{"atb":[[2.8,0],[3,0]],"id":52671555},{"atb":[[17.5,0],[12.5,0]],"id":52671554},{"atb":[[17.5,0],[12.5,0]],"id":52671556}],"con":true,"img":false}]}
{"op":"mcm","clk":"11449639756","pt":1717312566697,"mc":[{"id":"1.229554893","rc":[{"atb":[[2.28,81.66],[2.08,225.83]],"id":52671550},{"atb":[[8,34.84],[10,11.61]],"id":52671546},{"atb":[[9.2,29.74],[13,8.71]],"id":52671549},{"atb":[[2.28,81.66],[2.08,225.83]],"id":52671548},{"atb":[[5.6,53.02],[7.2,16.86]],"id":52671542},{"atb":[[350,0.29],[250,1.19]],"id":52671545},{"atb":[[8,34.84],[10,11.61]],"id":52671544},{"atb":[[2.8,135.5],[3,52.26]],"id":52671555},{"atb":[[17.5,6.33],[12.5,21.2]],"id":52671554},{"atb":[[17.5,6.33],[12.5,21.2]],"id":52671556}],"con":true,"img":false}]}
{"op":"mcm","clk":"11449652029","pt":1717312860236,"mc":[{"id":"1.229554893","rc":[{"atb":[[1.19,149.32]],"id":52671550},{"atl":[[36,2]],"id":52671550},{"atb":[[11.5,9.52]],"id":52671546},{"atb":[[2.16,11.84]],"id":52671549},{"atb":[[1.26,142.03]],"id":52671548},{"atl":[[44,2]],"id":52671548},{"atb":[[6.4,18.52]],"id":52671542},{"atl":[[410,2]],"id":52671542},{"atb":[[140,2]],"id":52671545},{"atb":[[2.16,12.24]],"id":52671544},{"atb":[[2.24,73.22]],"id":52671555},{"atl":[[160,2]],"id":52671555},{"atb":[[25,4.17]],"id":52671554},{"atb":[[23,4.55]],"id":52671556}],"con":true,"img":false}]}
{"op":"mcm","clk":"11449655964","pt":1717312955983,"mc":[{"id":"1.229554893","rc":[{"atb":[[2.28,0],[2.08,0]],"id":52671550},{"atb":[[8,0],[10,0]],"id":52671546},{"atb":[[9.2,0],[13,0]],"id":52671549},{"atb":[[2.28,0],[2.08,0]],"id":52671548},{"atb":[[5.6,0],[7.2,0]],"id":52671542},{"atb":[[350,0],[250,0.21]],"id":52671545},{"atb":[[8,0],[10,0]],"id":52671544},{"atb":[[2.8,0],[3,0]],"id":52671555},{"atb":[[17.5,0],[12.5,0]],"id":52671554},{"atb":[[17.5,0],[12.5,0]],"id":52671556}],"con":true,"img":false}]}
{"op":"mcm","clk":"11449656393","pt":1717312966043,"mc":[{"id":"1.229554893","rc":[{"atb":[[2.28,81.66],[2.08,225.83]],"id":52671550},{"atb":[[8,34.84],[10,11.61]],"id":52671546},{"atb":[[9.2,29.74],[13,8.71]],"id":52671549},{"atb":[[2.28,81.66],[2.08,225.83]],"id":52671548},{"atb":[[5.6,53.02],[7.2,16.86]],"id":52671542},{"atb":[[350,0.29],[250,1.19]],"id":52671545},{"atb":[[8,34.84],[10,11.61]],"id":52671544},{"atb":[[2.8,135.5],[3,52.26]],"id":52671555},{"atb":[[17.5,6.33],[12.5,21.2]],"id":52671554},{"atb":[[17.5,6.33],[12.5,21.2]],"id":52671556}],"con":true,"img":false}]}
{"op":"mcm","clk":"11449658601","pt":1717313021596,"mc":[{"id":"1.229554893","rc":[{"atl":[[410,0],[400,2]],"id":52671542}],"con":true,"img":false}]}
{"op":"mcm","clk":"11449658622","pt":1717313021907,"mc":[{"id":"1.229554893","rc":[{"atb":[[300,0],[150,0],[200,0],[250,0.97]],"id":52671545}],"con":true,"img":false}]}
{"op":"mcm","clk":"11449658627","pt":1717313022006,"mc":[{"id":"1.229554893","rc":[{"atb":[[9.2,0],[10.5,0],[8.2,0],[13,0]],"id":52671542}],"con":true,"img":false}]}
{"op":"mcm","clk":"11449658632","pt":1717313022109,"mc":[{"id":"1.229554893","rc":[{"atb":[[6.2,19.23]],"id":52671542}],"con":true,"img":false}]}
{"op":"mcm","clk":"11449658638","pt":1717313022211,"mc":[{"id":"1.229554893","rc":[{"atb":[[6.4,0]],"id":52671542}],"con":true,"img":false}]}
{"op":"mcm","clk":"11449658655","pt":1717313022622,"mc":[{"id":"1.229554893","rc":[{"atb":[[140,2.75],[290,0.09],[190,0.41],[240,0.22]],"id":52671545}],"con":true,"img":false}]}
{"op":"mcm","clk":"11449658659","pt":1717313022679,"mc":[{"id":"1.229554893","rc":[{"atb":[[8,14.95],[9,9.81],[10,5.81],[12.5,2.28]],"id":52671542}],"con":true,"img":false}]}
{"op":"mcm","clk":"11449658745","pt":1717313025086,"mc":[{"id":"1.229554893","rc":[{"atb":[[8,0],[9,0],[10,0],[12.5,0]],"id":52671542}],"con":true,"img":false}]}
{"op":"mcm","clk":"11449658754","pt":1717313025294,"mc":[{"id":"1.229554893","rc":[{"atb":[[2.36,0],[2.06,0],[2.26,0],[2.16,0]],"id":52671550}],"con":true,"img":false}]}
{"op":"mcm","clk":"11449658793","pt":1717313026018,"mc":[{"id":"1.229554893","rc":[{"atb":[[2.4,18.68],[2.3,40.24],[2.2,65.4],[2.1,95.12]],"id":52671550},{"atb":[[8,14.95],[9,9.81],[10,5.81],[12.5,2.28]],"id":52671542}],"con":true,"img":false}]}
{"op":"mcm","clk":"11449658938","pt":1717313028792,"mc":[{"id":"1.229554893","rc":[{"atb":[[8,0],[9,0],[10,0],[12.5,0]],"id":52671542}],"con":true,"img":false}]}
{"op":"mcm","clk":"11449658968","pt":1717313029509,"mc":[{"id":"1.229554893","rc":[{"atb":[[9.2,9.57],[10.5,5.51],[8.2,14.53],[13,2.18]],"id":52671542}],"con":true,"img":false}]}
{"op":"mcm","clk":"11449659077","pt":1717313032026,"mc":[{"id":"1.229554893","rc":[{"atb":[[2.4,0],[2.3,0],[2.2,0],[2.1,0]],"id":52671550}],"con":true,"img":false}]}
{"op":"mcm","clk":"11449659105","pt":1717313032699,"mc":[{"id":"1.229554893","rc":[{"atb":[[2.36,19.23],[2.06,98.71],[2.26,41.52],[2.16,67.65]],"id":52671550}],"con":true,"img":false}]}
{"op":"mcm","clk":"11449660245","pt":1717313059930,"mc":[{"id":"1.229554893","rc":[{"atb":[[9.2,0],[10.5,0],[8.2,0],[13,0]],"id":52671542}],"con":true,"img":false}]}
{"op":"mcm","clk":"11449660250","pt":1717313060029,"mc":[{"id":"1.229554893","rc":[{"atb":[[6.2,0],[6,20]],"id":52671542}],"con":true,"img":false}]}
{"op":"mcm","clk":"11449660289","pt":1717313060643,"mc":[{"id":"1.229554893","rc":[{"atb":[[8,14.95],[9,9.81],[10,5.81],[12.5,2.28]],"id":52671542}],"con":true,"img":false}]}
{"op":"mcm","clk":"11449663865","pt":1717313137620,"mc":[{"id":"1.229554893","rc":[{"atb":[[1.12,163.32]],"id":52671550},{"atb":[[2.36,73.22]],"id":52671555}],"con":true,"img":false}]}
{"op":"mcm","clk":"11449663868","pt":1717313137725,"mc":[{"id":"1.229554893","rc":[{"atb":[[1.19,0]],"id":52671550},{"atb":[[2.24,0]],"id":52671555}],"con":true,"img":false}]}
{"op":"mcm","clk":"11449663881","pt":1717313138033,"mc":[{"id":"1.229554893","rc":[{"atb":[[2.36,0],[1.12,0],[1.18,163.32],[2.06,0],[2.26,0],[2.16,0]],"id":52671550},{"atb":[[8,0],[9,0],[10,0],[12.5,0]],"id":52671542}],"con":true,"img":false}]}
{"op":"mcm","clk":"11449663887","pt":1717313138137,"mc":[{"id":"1.229554893","rc":[{"atb":[[1.18,0],[1.12,163.32]],"id":52671550}],"con":true,"img":false}]}
{"op":"mcm","clk":"11449663913","pt":1717313138751,"mc":[{"id":"1.229554893","rc":[{"atb":[[2.38,18.95],[2.28,122.54],[2.18,66.51],[2.08,322.73]],"id":52671550},{"atb":[[8,14.95],[9,9.81],[10,5.81],[12.5,2.28]],"id":52671542}],"con":true,"img":false}]}
{"op":"mcm","clk":"11449664094","pt":1717313143261,"mc":[{"id":"1.229554893","rc":[{"atb":[[2.28,40.88],[2.08,96.89]],"id":52671550},{"atb":[[8,0],[10,0]],"id":52671546},{"atb":[[9.2,0],[13,0]],"id":52671549},{"atb":[[2.28,0],[2.08,0]],"id":52671548},{"atb":[[5.6,0],[7.2,0]],"id":52671542},{"atb":[[350,0],[250,0]],"id":52671545},{"atb":[[8,0],[10,0]],"id":52671544},{"atb":[[2.8,0],[3,0]],"id":52671555},{"atb":[[17.5,0],[12.5,0]],"id":52671554},{"atb":[[17.5,0],[12.5,0]],"id":52671556}],"con":true,"img":false}]}
{"op":"mcm","clk":"11449664401","pt":1717313151163,"mc":[{"id":"1.229554893","rc":[{"atb":[[2.38,0],[2.28,0],[2.18,0],[2.08,0]],"id":52671550},{"atb":[[8,0],[9,0],[10,0],[12.5,0]],"id":52671542}],"con":true,"img":false}]}
{"op":"mcm","clk":"11449664409","pt":1717313151370,"mc":[{"id":"1.229554893","rc":[{"atb":[[6,0],[5.9,20.41]],"id":52671542}],"con":true,"img":false}]}
{"op":"mcm","clk":"11449664437","pt":1717313151831,"mc":[{"id":"1.229554893","rc":[{"atb":[[2.06,74.03],[1.98,106.77],[2.26,20.76],[2.16,45.1]],"id":52671550},{"atb":[[12,2.38],[9.8,5.94],[8.8,10.06],[7.8,15.39]],"id":52671542}],"con":true,"img":false}]}
{"op":"mcm","clk":"11449664542","pt":1717313153851,"mc":[{"id":"1.229554893","rc":[{"atb":[[18,0],[21,0],[26,0],[15.5,0]],"id":52671549},{"atb":[[2.4,0],[2.5,0],[2.3,0],[2.2,0]],"id":52671548}],"con":true,"img":false}]}
{"op":"mcm","clk":"11449664548","pt":1717313153955,"mc":[{"id":"1.229554893","rc":[{"atb":[[1.26,0],[1.24,284.06]],"id":52671548}],"con":true,"img":false}]}
{"op":"mcm","clk":"11449664575","pt":1717313154572,"mc":[{"id":"1.229554893","rc":[{"atb":[[17.5,4.76],[20,2.75],[25,1.09],[15,7.48]],"id":52671549},{"atb":[[2.4,37.37],[2.5,17.44],[2.3,60.36],[2.2,87.2]],"id":52671548}],"con":true,"img":false}]}
{"op":"mcm","clk":"11449665511","pt":1717313176513,"mc":[{"id":"1.229554893","rc":[{"atb":[[2.24,84.29],[2.04,234.52]],"id":52671550},{"atb":[[9.8,11.87],[7.8,35.86]],"id":52671546},{"atb":[[9.6,28.36],[14,8.04]],"id":52671549},{"atb":[[2.24,84.29],[2.04,234.52]],"id":52671548},{"atb":[[6.8,18.02],[5.4,55.43]],"id":52671542},{"atb":[[360,0.68],[460,0.23]],"id":52671545},{"atb":[[9.8,11.87],[7.8,35.86]],"id":52671544},{"atb":[[3.1,49.77],[2.84,132.55]],"id":52671555},{"atb":[[18.5,5.97],[13.5,19.51]],"id":52671554},{"atb":[[18.5,5.97],[13.5,19.51]],"id":52671556}],"con":true,"img":false}]}
{"op":"mcm","clk":"11449666142","pt":1717313191808,"mc":[{"id":"1.229554893","rc":[{"atl":[[34,2],[36,0]],"id":52671550},{"atb":[[32,5.76],[25,0]],"id":52671554},{"atb":[[23,0],[29,3.57]],"id":52671556}],"con":true,"img":false}]}
{"op":"mcm","clk":"11449666169","pt":1717313192217,"mc":[{"id":"1.229554893","rc":[{"atb":[[2.4,0],[2.5,0],[2.3,0],[2.2,0]],"id":52671548},{"atb":[[32,3.23],[42,0],[26,0],[55,0]],"id":52671554},{"atb":[[40,0],[50,0],[25,0],[30,0]],"id":52671556}],"con":true,"img":false}]}
{"op":"mcm","clk":"11449666177","pt":1717313192317,"mc":[{"id":"1.229554893","rc":[{"atb":[[32,0],[19,5.56]],"id":52671554},{"atb":[[19,5.56],[29,0]],"id":52671556}],"con":true,"img":false}]}
{"op":"mcm","clk":"11449666225","pt":1717313192894,"mc":[{"id":"1.229554893","rc":[{"atb":[[2.38,37.91],[2.28,61.31],[2.18,88.67],[2.48,17.67]],"id":52671548},{"atb":[[70,0.38],[38,2.12],[48,1.11],[29,3.74]],"id":52671554},{"atb":[[34,2.38],[44,1.22],[27,4.02],[60,0.44]],"id":52671556}],"con":true,"img":false}]}
{"op":"mcm","clk":"11449667339","pt":1717313215510,"mc":[{"id":"1.229554893","rc":[{"atb":[[2.24,0],[2.04,0]],"id":52671550},{"atb":[[9.8,0],[7.8,0]],"id":52671546},{"atb":[[9.6,0],[14,0]],"id":52671549},{"atb":[[2.24,0],[2.04,0]],"id":52671548},{"atb":[[6.8,0],[5.4,0]],"id":52671542},{"atb":[[360,0],[460,0]],"id":52671545},{"atb":[[9.8,0],[7.8,0]],"id":52671544},{"atb":[[3.1,0],[2.84,0]],"id":52671555},{"atb":[[18.5,0],[13.5,0]],"id":52671554},{"atb":[[18.5,0],[13.5,0]],"id":52671556}],"con":true,"img":false}]}
{"op":"mcm","clk":"11449667351","pt":1717313215726,"mc":[{"id":"1.229554893","rc":[{"atb":[[140,0.75],[180,2]],"id":52671545}],"con":true,"img":false}]}
{"op":"mcm","clk":"11449667853","pt":1717313226156,"mc":[{"id":"1.229554893","rc":[{"atb":[[32,3.23],[19,0]],"id":52671554},{"atb":[[19,0],[29,3.57]],"id":52671556}],"con":true,"img":false}]}
{"op":"mcm","clk":"11449668616","pt":1717313241058,"mc":[{"id":"1.229554893","rc":[{"atb":[[2.02,239.12],[2.22,85.68]],"id":52671550},{"atb":[[10.5,11],[8.2,33.87]],"id":52671546},{"atb":[[9,30.48],[12.5,9.08]],"id":52671549},{"atb":[[2.02,239.12],[2.22,85.68]],"id":52671548},{"atb":[[6.8,18.02],[5.4,55.43]],"id":52671542},{"atb":[[260,0.94],[360,0.29]],"id":52671545},{"atb":[[10.5,11],[8.2,33.87]],"id":52671544},{"atb":[[2.9,128.37],[3.25,46.45]],"id":52671555},{"atb":[[18,6.14],[13,20.32]],"id":52671554},{"atb":[[18,6.14],[13,20.32]],"id":52671556}],"con":true,"img":false}]}
{"op":"mcm","clk":"11449670111","pt":1717313273218,"mc":[{"id":"1.229554893","rc":[{"atb":[[2.02,0],[2.22,0]],"id":52671550},{"atb":[[10.5,0],[8.2,0]],"id":52671546},{"atb":[[9,0],[12.5,0]],"id":52671549},{"atb":[[2.02,0],[2.22,0]],"id":52671548},{"atb":[[6.8,0],[5.4,0]],"id":52671542},{"atb":[[260,0],[360,0]],"id":52671545},{"atb":[[10.5,0],[8.2,0]],"id":52671544},{"atb":[[2.9,0],[3.25,0]],"id":52671555},{"atb":[[18,0],[13,0]],"id":52671554},{"atb":[[18,0],[13,0]],"id":52671556}],"con":true,"img":false}]}
{"op":"mcm","clk":"11449671575","pt":1717313301842,"mc":[{"id":"1.229554893","rc":[{"atb":[[2,243.9],[2.2,87.1]],"id":52671550},{"atb":[[8,34.84],[10,11.61]],"id":52671546},{"atb":[[13.5,8.36],[9.4,29.03]],"id":52671549},{"atb":[[2,243.9],[2.2,87.1]],"id":52671548},{"atb":[[6.8,18.02],[5.4,55.43]],"id":52671542},{"atb":[[400,0.61],[500,0.2]],"id":52671545},{"atb":[[8,34.84],[10,11.61]],"id":52671544},{"atb":[[2.9,128.37],[3.25,46.45]],"id":52671555},{"atb":[[19,5.8],[14,18.76]],"id":52671554},{"atb":[[19,5.8],[14,18.76]],"id":52671556}],"con":true,"img":false}]}
{"op":"mcm","clk":"11449673061","pt":1717313329596,"mc":[{"id":"1.229554893","rc":[{"atb":[[2,0],[2.2,0]],"id":52671550},{"atb":[[8,0],[10,0]],"id":52671546},{"atb":[[13.5,0],[9.4,0]],"id":52671549},{"atb":[[2,0],[2.2,0]],"id":52671548},{"atb":[[6.8,0],[5.4,0]],"id":52671542},{"atb":[[400,0],[500,0]],"id":52671545},{"atb":[[8,0],[10,0]],"id":52671544},{"atb":[[2.9,0],[3.25,0]],"id":52671555},{"atb":[[19,0],[14,0]],"id":52671554},{"atb":[[19,0],[14,0]],"id":52671556}],"con":true,"img":false}]}
{"op":"mcm","clk":"11449674320","pt":1717313351272,"mc":[{"id":"1.229554893","rc":[{"atb":[[2,243.9],[2.2,87.1]],"id":52671550},{"atb":[[13.5,8.36],[9.4,29.03]],"id":52671549},{"atb":[[2.9,128.37],[3.25,46.45]],"id":52671555},{"atb":[[19,5.8],[14,18.76]],"id":52671554},{"atb":[[19,5.8],[14,18.76]],"id":52671556}],"con":true,"img":false}]}
{"op":"mcm","clk":"11449674328","pt":1717313351382,"mc":[{"id":"1.229554893","rc":[{"atb":[[8,34.84],[10,11.61]],"id":52671546},{"atb":[[2,243.9],[2.2,87.1]],"id":52671548},{"atb":[[6.8,18.02],[5.4,55.43]],"id":52671542},{"atb":[[400,0.61],[500,0.2]],"id":52671545},{"atb":[[8,34.84],[10,11.61]],"id":52671544}],"con":true,"img":false}]}
{"op":"mcm","clk":"11449675510","pt":1717313372098,"mc":[{"id":"1.229554893","rc":[{"atb":[[140,0],[290,0],[190,0],[240,0]],"id":52671545}],"con":true,"img":false}]}
{"op":"mcm","clk":"11449675565","pt":1717313372821,"mc":[{"id":"1.229554893","rc":[{"atb":[[270,0.29],[320,0.16],[370,0.07],[220,0.48]],"id":52671545}],"con":true,"img":false}]}
{"op":"mcm","clk":"11449678831","pt":1717313421855,"mc":[{"id":"1.229554893","rc":[{"atl":[[32,2],[34,0]],"id":52671550}],"con":true,"img":false}]}
{"op":"mcm","clk":"11449678877","pt":1717313422158,"mc":[{"id":"1.229554893","rc":[{"atb":[[2.06,0],[1.98,0],[2.26,0],[2.16,0]],"id":52671550},{"atb":[[2.38,0],[2.28,0],[2.18,0],[2.48,0]],"id":52671548},{"atb":[[270,0],[320,0],[370,0],[220,0]],"id":52671545},{"atb":[[34,0],[44,0],[27,0],[60,0]],"id":52671556}],"con":true,"img":false}]}
{"op":"mcm","clk":"11449678883","pt":1717313422262,"mc":[{"id":"1.229554893","rc":[{"atb":[[19.5,5.41],[29,0]],"id":52671556}],"con":true,"img":false}]}
{"op":"mcm","clk":"11449678918","pt":1717313422881,"mc":[{"id":"1.229554893","rc":[{"atb":[[2.02,76.94],[2.22,21.44],[2.12,46.71],[1.96,108.99]],"id":52671550},{"atb":[[2.4,18.68],[2.3,40.24],[2.2,152.51],[2.1,95.12]],"id":52671548},{"atb":[[280,0.28],[330,0.16],[380,0.07],[230,0.46]],"id":52671545},{"atb":[[65,0.41],[36,2.24],[46,1.16],[28,3.88]],"id":52671556}],"con":true,"img":false}]}
{"op":"mcm","clk":"11449678924","pt":1717313422985,"mc":[{"id":"1.229554893","rc":[{"atb":[[19.5,0],[30,3.45]],"id":52671556}],"con":true,"img":false}]}
{"op":"mcm","clk":"11449683724","pt":1717313487276,"mc":[{"id":"1.229554893","rc":[{"atb":[[280,0],[330,0],[380,0],[230,0]],"id":52671545}],"con":true,"img":false}]}
{"op":"mcm","clk":"11449683790","pt":1717313488007,"mc":[{"id":"1.229554893","rc":[{"atb":[[300,0.26],[350,0.15],[400,0.68],[250,0.42]],"id":52671545}],"con":true,"img":false}]}
{"op":"mcm","clk":"11449684087","pt":1717313490893,"mc":[{"id":"1.229554893","rc":[{"atb":[[17.5,0],[20,0],[15,0]],"id":52671549}],"con":true,"img":false}]}
{"op":"mcm","clk":"11449684098","pt":1717313490997,"mc":[{"id":"1.229554893","rc":[{"atb":[[25,0]],"id":52671549}],"con":true,"img":false}]}
{"op":"mcm","clk":"11449684145","pt":1717313491564,"mc":[{"id":"1.229554893","rc":[{"atb":[[17.5,6.34],[20,4.13],[30,0.9]],"id":52671549}],"con":true,"img":false}]}
{"op":"mcm","clk":"11449684153","pt":1717313491666,"mc":[{"id":"1.229554893","rc":[{"atb":[[25,2.18]],"id":52671549}],"con":true,"img":false}]}
{"op":"mcm","clk":"11449685337","pt":1717313506489,"mc":[{"id":"1.229554893","rc":[{"atb":[[300,0],[350,0],[400,0.61],[250,0]],"id":52671545}],"con":true,"img":false}]}
{"op":"mcm","clk":"11449685390","pt":1717313507211,"mc":[{"id":"1.229554893","rc":[{"atb":[[300,0.26],[350,0.15],[400,0.68],[250,0.42]],"id":52671545}],"con":true,"img":false}]}
{"op":"mcm","clk":"11449687848","pt":1717313536746,"mc":[{"id":"1.229554893","rc":[{"atb":[[300,0],[350,0],[400,0.61],[250,0]],"id":52671545}],"con":true,"img":false}]}
{"op":"mcm","clk":"11449687925","pt":1717313537677,"mc":[{"id":"1.229554893","rc":[{"atb":[[300,0.26],[350,0.15],[400,0.68],[250,0.42]],"id":52671545}],"con":true,"img":false}]}
{"op":"mcm","clk":"11449689479","pt":1717313555988,"mc":[{"id":"1.229554893","rc":[{"atb":[[300,0],[350,0],[400,0.61],[250,0]],"id":52671545}],"con":true,"img":false}]}
{"op":"mcm","clk":"11449689535","pt":1717313556654,"mc":[{"id":"1.229554893","rc":[{"atb":[[300,0.26],[350,0.15],[400,0.68],[250,0.42]],"id":52671545}],"con":true,"img":false}]}
{"op":"mcm","clk":"11449690433","pt":1717313567262,"mc":[{"id":"1.229554893","rc":[{"atb":[[300,0],[350,0],[400,0.61],[250,0]],"id":52671545}],"con":true,"img":false}]}
{"op":"mcm","clk":"11449690489","pt":1717313567983,"mc":[{"id":"1.229554893","rc":[{"atb":[[300,0.26],[350,0.15],[400,0.68],[250,0.42]],"id":52671545}],"con":true,"img":false}]}
{"op":"mcm","clk":"11449691793","pt":1717313584078,"mc":[{"id":"1.229554893","rc":[{"atb":[[300,0],[350,0],[400,0.61],[250,0]],"id":52671545}],"con":true,"img":false}]}
{"op":"mcm","clk":"11449691860","pt":1717313584912,"mc":[{"id":"1.229554893","rc":[{"atb":[[280,0.28],[330,0.16],[380,0.07],[230,0.46]],"id":52671545}],"con":true,"img":false}]}
{"op":"mcm","clk":"11449703761","pt":1717313733840,"mc":[{"id":"1.229554893","rc":[{"atb":[[2,0],[2.2,0]],"id":52671550},{"atb":[[8,0],[10,0]],"id":52671546},{"atb":[[13.5,0],[9.4,0]],"id":52671549},{"atb":[[2,0],[2.2,65.4]],"id":52671548},{"atb":[[6.8,0],[5.4,0]],"id":52671542},{"atb":[[400,0],[500,0]],"id":52671545},{"atb":[[8,0],[10,0]],"id":52671544},{"atb":[[2.9,0],[3.25,0]],"id":52671555},{"atb":[[19,0],[14,0]],"id":52671554},{"atb":[[19,0],[14,0]],"id":52671556}],"con":true,"img":false}]}
{"op":"mcm","clk":"11449706169","pt":1717313763344,"mc":[{"id":"1.229554893","rc":[{"atb":[[8,34.84],[10,11.61]],"id":52671546},{"atb":[[2,243.9],[2.2,152.51]],"id":52671548},{"atb":[[6.8,18.02],[5.4,55.43]],"id":52671542},{"atb":[[400,0.61],[500,0.2]],"id":52671545},{"atb":[[8,34.84],[10,11.61]],"id":52671544}],"con":true,"img":false}]}
{"op":"mcm","clk":"11449706177","pt":1717313763450,"mc":[{"id":"1.229554893","rc":[{"atb":[[2,243.9],[2.2,87.1]],"id":52671550},{"atb":[[13.5,8.36],[9.4,29.03]],"id":52671549},{"atb":[[2.9,128.37],[3.25,46.45]],"id":52671555},{"atb":[[19,5.8],[14,18.76]],"id":52671554},{"atb":[[19,5.8],[14,18.76]],"id":52671556}],"con":true,"img":false}]}
{"op":"mcm","clk":"11449706455","pt":1717313766754,"mc":[{"id":"1.229554893","rc":[{"atl":[[42,2],[44,0]],"id":52671548}],"con":true,"img":false}]}
{"op":"mcm","clk":"11449706488","pt":1717313767164,"mc":[{"id":"1.229554893","rc":[{"atb":[[2.02,0],[2.22,0],[2.12,0],[1.96,0]],"id":52671550},{"atb":[[17.5,0],[20,0],[25,0],[30,0]],"id":52671549}],"con":true,"img":false}]}
{"op":"mcm","clk":"11449706551","pt":1717313767837,"mc":[{"id":"1.229554893","rc":[{"atb":[[17,6.54],[19.5,4.24],[24,2.28],[29,0.94]],"id":52671549}],"con":true,"img":false}]}
{"op":"mcm","clk":"11449706561","pt":1717313767939,"mc":[{"id":"1.229554893","rc":[{"atb":[[2,322.38],[2.2,108.91],[1.95,110.14],[2.1,47.56]],"id":52671550}],"con":true,"img":false}]}
{"op":"mcm","clk":"11449709517","pt":1717313801816,"mc":[{"id":"1.229554893","rc":[{"atb":[[1.18,247.64],[1.24,0]],"id":52671548}],"con":true,"img":false}]}
{"op":"mcm","clk":"11449709547","pt":1717313802125,"mc":[{"id":"1.229554893","rc":[{"atb":[[2.4,0],[2.3,0],[2.2,87.1],[2.1,0]],"id":52671548}],"con":true,"img":false}]}
{"op":"mcm","clk":"11449709615","pt":1717313802798,"mc":[{"id":"1.229554893","rc":[{"atb":[[2.38,18.95],[2.28,40.88],[2.18,66.51],[2.08,96.89]],"id":52671548}],"con":true,"img":false}]}
{"op":"mcm","clk":"11449716245","pt":1717313878111,"mc":[{"id":"1.229554893","rc":[{"atb":[[280,0]],"id":52671545}],"con":true,"img":false}]}
{"op":"mcm","clk":"11449716255","pt":1717313878219,"mc":[{"id":"1.229554893","rc":[{"atb":[[330,0],[380,0],[230,0]],"id":52671545}],"con":true,"img":false}]}
{"op":"mcm","clk":"11449716300","pt":1717313878784,"mc":[{"id":"1.229554893","rc":[{"atb":[[290,0.27]],"id":52671545}],"con":true,"img":false}]}
{"op":"mcm","clk":"11449716312","pt":1717313878887,"mc":[{"id":"1.229554893","rc":[{"atb":[[340,0.15],[390,0.07],[240,0.44]],"id":52671545}],"con":true,"img":false}]}
{"op":"mcm","clk":"11449721874","pt":1717313941437,"mc":[{"id":"1.229554893","rc":[{"atb":[[290,0],[340,0],[390,0],[240,0]],"id":52671545}],"con":true,"img":false}]}
{"op":"mcm","clk":"11449721955","pt":1717313942162,"mc":[{"id":"1.229554893","rc":[{"atb":[[280,0.28],[330,0.16],[380,0.07],[230,0.46]],"id":52671545}],"con":true,"img":false}]}
{"op":"mcm","clk":"11449734725","pt":1717314074262,"mc":[{"id":"1.229554893","rc":[{"atb":[[2.38,0],[2.28,0],[2.18,0],[2.08,0]],"id":52671548}],"con":true,"img":false}]}
{"op":"mcm","clk":"11449734791","pt":1717314074981,"mc":[{"id":"1.229554893","rc":[{"atb":[[2.32,39.64],[2.42,18.42],[2.22,64.32],[2.12,93.42]],"id":52671548}],"con":true,"img":false}]}
{"op":"mcm","clk":"11449736707","pt":1717314096394,"mc":[{"id":"1.229554893","rc":[{"atb":[[2,78.48],[2.2,21.8]],"id":52671550},{"atb":[[8,0],[10,0]],"id":52671546},{"atb":[[13.5,0],[9.4,0]],"id":52671549},{"atb":[[2,0],[2.2,0]],"id":52671548},{"atb":[[6.8,0],[5.4,0]],"id":52671542},{"atb":[[400,0],[500,0]],"id":52671545},{"atb":[[8,0],[10,0]],"id":52671544},{"atb":[[2.9,0],[3.25,0]],"id":52671555},{"atb":[[19,0],[14,0]],"id":52671554},{"atb":[[19,0],[14,0]],"id":52671556}],"con":true,"img":false}]}
{"op":"mcm","clk":"11449739271","pt":1717314124229,"mc":[{"id":"1.229554893","rc":[{"atb":[[2,322.38],[2.2,108.91]],"id":52671550},{"atb":[[8,34.84],[10,11.61]],"id":52671546},{"atb":[[13.5,8.36],[9.4,29.03]],"id":52671549},{"atb":[[2,243.9],[2.2,87.1]],"id":52671548},{"atb":[[6.8,18.02],[5.4,55.43]],"id":52671542},{"atb":[[400,0.61],[500,0.2]],"id":52671545},{"atb":[[8,34.84],[10,11.61]],"id":52671544},{"atb":[[2.9,128.37],[3.25,46.45]],"id":52671555},{"atb":[[19,5.8],[14,18.76]],"id":52671554},{"atb":[[19,5.8],[14,18.76]],"id":52671556}],"con":true,"img":false}]}
{"op":"mcm","clk":"11449747543","pt":1717314217867,"mc":[{"id":"1.229554893","rc":[{"atb":[[2,243.9],[2.2,87.1],[1.95,0],[2.1,0]],"id":52671550},{"atb":[[2.32,0],[2.42,0],[2.22,0],[2.12,0]],"id":52671548},{"atb":[[280,0],[330,0],[380,0],[230,0]],"id":52671545}],"con":true,"img":false}]}
{"op":"mcm","clk":"11449747612","pt":1717314218543,"mc":[{"id":"1.229554893","rc":[{"atb":[[2.24,21.09],[1.97,107.87],[2.04,75.46],[2.14,45.89]],"id":52671550},{"atb":[[2.38,18.95],[2.28,40.88],[2.18,66.51],[2.08,96.89]],"id":52671548},{"atb":[[290,0.27],[340,0.15],[390,0.07],[240,0.44]],"id":52671545}],"con":true,"img":false}]}
{"op":"mcm","clk":"11449747683","pt":1717314219366,"mc":[{"id":"1.229554893","rc":[{"atb":[[2.24,0],[1.97,0],[2.04,0],[2.14,0]],"id":52671550},{"atb":[[290,0],[340,0],[390,0],[240,0]],"id":52671545}],"con":true,"img":false}]}
{"op":"mcm","clk":"11449747742","pt":1717314220082,"mc":[{"id":"1.229554893","rc":[{"atb":[[2,322.38],[2.2,108.91],[1.95,110.14],[2.1,47.56]],"id":52671550},{"atb":[[280,0.28],[330,0.16],[380,0.07],[230,0.46]],"id":52671545}],"con":true,"img":false}]}
{"op":"mcm","clk":"11449766650","pt":1717314431784,"mc":[{"id":"1.229554893","rc":[{"atb":[[2,78.48],[2.2,21.8]],"id":52671550},{"atb":[[8,0],[10,0]],"id":52671546},{"atb":[[13.5,0],[9.4,0]],"id":52671549},{"atb":[[2,0],[2.2,0]],"id":52671548},{"atb":[[6.8,0],[5.4,0]],"id":52671542},{"atb":[[400,0],[500,0]],"id":52671545},{"atb":[[8,0],[10,0]],"id":52671544},{"atb":[[2.9,0],[3.25,0]],"id":52671555},{"atb":[[19,0],[14,0]],"id":52671554},{"atb":[[19,0],[14,0]],"id":52671556}],"con":true,"img":false}]}
{"op":"mcm","clk":"11449768260","pt":1717314449785,"mc":[{"id":"1.229554893","rc":[{"atb":[[280,0],[330,0],[380,0],[230,0]],"id":52671545}],"con":true,"img":false}]}
{"op":"mcm","clk":"11449768322","pt":1717314450460,"mc":[{"id":"1.229554893","rc":[{"atb":[[300,0.26],[350,0.15],[400,0.07],[250,0.42]],"id":52671545}],"con":true,"img":false}]}
{"op":"mcm","clk":"11449768900","pt":1717314457618,"mc":[{"id":"1.229554893","rc":[{"atb":[[2,322.38],[2.2,108.91]],"id":52671550},{"atb":[[8,34.84],[10,11.61]],"id":52671546},{"atb":[[13.5,8.36],[9.4,29.03]],"id":52671549},{"atb":[[2,243.9],[2.2,87.1]],"id":52671548},{"atb":[[6.8,18.02],[5.4,55.43]],"id":52671542},{"atb":[[400,0.68],[500,0.2]],"id":52671545},{"atb":[[8,34.84],[10,11.61]],"id":52671544},{"atb":[[2.9,128.37],[3.25,46.45]],"id":52671555},{"atb":[[19,5.8],[14,18.76]],"id":52671554},{"atb":[[19,5.8],[14,18.76]],"id":52671556}],"con":true,"img":false}]}
{"op":"mcm","clk":"11449782204","pt":1717314606623,"mc":[{"id":"1.229554893","rc":[{"atb":[[2,243.9],[2.2,87.1],[1.95,0],[2.1,0]],"id":52671550},{"atb":[[12,0],[9.8,0],[8.8,0],[7.8,0]],"id":52671542},{"atb":[[300,0],[350,0],[400,0.61],[250,0]],"id":52671545}],"con":true,"img":false}]}
{"op":"mcm","clk":"11449782214","pt":1717314606674,"mc":[{"id":"1.229554893","rc":[{"atb":[[5.6,21.74],[5.9,0]],"id":52671542}],"con":true,"img":false}]}
{"op":"mcm","clk":"11449782255","pt":1717314607298,"mc":[{"id":"1.229554893","rc":[{"atb":[[2.24,21.09],[1.97,107.87],[2.04,75.46],[2.14,45.89]],"id":52671550},{"atb":[[9.6,6.08],[8.6,10.33],[11.5,2.49],[7.6,15.85]],"id":52671542},{"atb":[[270,0.29],[320,0.16],[370,0.07],[220,0.48]],"id":52671545}],"con":true,"img":false}]}
{"op":"mcm","clk":"11449782706","pt":1717314613117,"mc":[{"id":"1.229554893","rc":[{"atb":[[2.24,0],[2.04,0]],"id":52671550}],"con":true,"img":false}]}
{"op":"mcm","clk":"11449782716","pt":1717314613219,"mc":[{"id":"1.229554893","rc":[{"atb":[[1.97,0],[2.14,0]],"id":52671550}],"con":true,"img":false}]}
{"op":"mcm","clk":"11449782763","pt":1717314613792,"mc":[{"id":"1.229554893","rc":[{"atb":[[2,322.38],[2.2,108.91]],"id":52671550}],"con":true,"img":false}]}
{"op":"mcm","clk":"11449782773","pt":1717314613892,"mc":[{"id":"1.229554893","rc":[{"atb":[[1.95,110.14],[2.1,47.56]],"id":52671550}],"con":true,"img":false}]}
{"op":"mcm","clk":"11449784910","pt":1717314640975,"mc":[{"id":"1.229554893","rc":[{"atb":[[270,0],[320,0],[370,0],[220,0]],"id":52671545}],"con":true,"img":false}]}
{"op":"mcm","clk":"11449784966","pt":1717314641652,"mc":[{"id":"1.229554893","rc":[{"atb":[[260,0.3],[310,0.17],[360,0.07],[210,0.5]],"id":52671545}],"con":true,"img":false}]}
{"op":"mcm","clk":"11449785011","pt":1717314642271,"mc":[{"id":"1.229554893","rc":[{"atb":[[1.23,247.64]],"id":52671548}],"con":true,"img":false}]}
{"op":"mcm","clk":"11449785018","pt":1717314642370,"mc":[{"id":"1.229554893","rc":[{"atb":[[1.18,0]],"id":52671548}],"con":true,"img":false}]}
{"op":"mcm","clk":"11449785044","pt":1717314642659,"mc":[{"id":"1.229554893","rc":[{"atb":[[17,0],[19.5,0],[24,0],[29,0]],"id":52671549}],"con":true,"img":false}]}
{"op":"mcm","clk":"11449785099","pt":1717314643276,"mc":[{"id":"1.229554893","rc":[{"atb":[[70,0],[38,0],[48,0],[29,0]],"id":52671554}],"con":true,"img":false}]}
{"op":"mcm","clk":"11449785104","pt":1717314643373,"mc":[{"id":"1.229554893","rc":[{"atb":[[17,6.54],[19.5,4.24],[24,2.28],[29,0.94]],"id":52671549},{"atb":[[32,0],[19.5,5.41]],"id":52671554},{"atb":[[65,0],[36,0],[46,0],[28,0]],"id":52671556}],"con":true,"img":false}]}
{"op":"mcm","clk":"11449785114","pt":1717314643478,"mc":[{"id":"1.229554893","rc":[{"atb":[[19.5,5.41],[30,0]],"id":52671556}],"con":true,"img":false}]}
{"op":"mcm","clk":"11449785159","pt":1717314643990,"mc":[{"id":"1.229554893","rc":[{"atb":[[65,0.41],[36,2.24],[46,1.16],[28,3.88]],"id":52671554}],"con":true,"img":false}]}
{"op":"mcm","clk":"11449785169","pt":1717314644093,"mc":[{"id":"1.229554893","rc":[{"atb":[[34,2.38],[44,1.22],[27,4.02],[60,0.44]],"id":52671556}],"con":true,"img":false}]}
{"op":"mcm","clk":"11449786595","pt":1717314661618,"mc":[{"id":"1.229554893","rc":[{"atb":[[2.12,14.01],[2.08,14.53]],"id":52671550},{"atl":[[3.8,5.6],[3.9,5.4]],"id":52671550},{"atb":[[14.5,2.94],[15.5,3.87]],"id":52671546},{"atl":[[65,3.53],[55,4.1]],"id":52671546},{"atb":[[2.88,11.84],[2.16,0]],"id":52671549},{"atl":[[70,4.03],[60,3.1]],"id":52671549},{"atb":[[2.24,12.65],[2.28,53.14],[2.2,100.18]],"id":52671548},{"atl":[[4.4,3.03],[4.2,4.9]],"id":52671548},{"atb":[[5.6,0],[2.88,31.72],[8.8,2.86],[8.4,3.03]],"id":52671542},{"atl":[[22,3.24],[24,2.96]],"id":52671542},{"atb":[[2.88,12.24],[2.16,0]],"id":52671544},{"atl":[[70,3.2],[60,2.76]],"id":52671544},{"atb":[[4,5.23],[4.2,4.9]],"id":52671555},{"atl":[[9.6,3.94],[9.2,2.89]],"id":52671555},{"atb":[[34,3.2],[30,4.59]],"id":52671554},{"atl":[[160,3.19],[180,3.63]],"id":52671554},{"atb":[[32,3.44],[29,3.55]],"id":52671556},{"atl":[[140,3.82],[160,3.39]],"id":52671556}],"con":true,"img":false}]}
{"op":"mcm","clk":"11449786616","pt":1717314661818,"mc":[{"id":"1.229554893","rc":[{"atl":[[32,0],[8.4,11.01]],"id":52671550},{"atl":[[9.2,7.95],[42,0]],"id":52671548},{"atl":[[400,0],[50,2.04]],"id":52671542},{"atl":[[160,0],[20,5.26]],"id":52671555}],"con":true,"img":false}]}
{"op":"mcm","clk":"11449786687","pt":1717314662708,"mc":[{"id":"1.229554893","rc":[{"atb":[[19.5,0],[30,8.04]],"id":52671554}],"con":true,"img":false}]}
{"op":"mcm","clk":"11449786696","pt":1717314662800,"mc":[{"id":"1.229554893","rc":[{"atb":[[19.5,0],[30,3.45]],"id":52671556}],"con":true,"img":false}]}
{"op":"mcm","clk":"11449786931","pt":1717314665285,"mc":[{"id":"1.229554893","rc":[{"atb":[[2.28,40.88]],"id":52671548},{"atb":[[8.8,0],[8.4,0]],"id":52671542}],"con":true,"img":false}]}
{"op":"mcm","clk":"11449787006","pt":1717314666112,"mc":[{"id":"1.229554893","rc":[{"atl":[[50,4.66]],"id":52671546}],"con":true,"img":false}]}
{"op":"mcm","clk":"11449787016","pt":1717314666218,"mc":[{"id":"1.229554893","rc":[{"atb":[[2.12,0],[2.16,13.52]],"id":52671550},{"atb":[[16,3.93],[15.5,0]],"id":52671546},{"atl":[[55,0]],"id":52671546},{"atb":[[2.24,0],[2.28,53.14]],"id":52671548},{"atb":[[4.1,5.06],[4.2,0]],"id":52671555}],"con":true,"img":false}]}
{"op":"mcm","clk":"11449787047","pt":1717314666632,"mc":[{"id":"1.229554893","rc":[{"atb":[[2,78.48],[2.2,21.8]],"id":52671550},{"atb":[[8,0],[10,0]],"id":52671546},{"atb":[[13.5,0],[9.4,0]],"id":52671549},{"atb":[[2,0],[2.2,13.07]],"id":52671548},{"atb":[[6.8,0],[5.4,0]],"id":52671542},{"atb":[[400,0],[500,0]],"id":52671545},{"atb":[[8,0],[10,0]],"id":52671544},{"atb":[[2.9,0],[3.25,0]],"id":52671555},{"atb":[[19,0],[14,0]],"id":52671554},{"atb":[[19,0],[14,0]],"id":52671556}],"con":true,"img":false}]}
{"op":"mcm","clk":"11449787246","pt":1717314668909,"mc":[{"id":"1.229554893","rc":[{"atl":[[3.7,5.81],[3.8,0]],"id":52671550},{"atb":[[2.98,7.92],[3.05,7.65]],"id":52671549},{"atl":[[4.1,5.06],[4.2,0]],"id":52671548}],"con":true,"img":false}]}
{"op":"mcm","clk":"11449787412","pt":1717314671041,"mc":[{"id":"1.229554893","rc":[{"atb":[[16,0],[15.5,4.39]],"id":52671546},{"atl":[[50,0],[55,3.52]],"id":52671546},{"atb":[[2.98,7.92],[3.05,7.65]],"id":52671542},{"atb":[[140,4.03],[160,3.28]],"id":52671545},{"atb":[[2.98,7.92],[3.05,7.65]],"id":52671544}],"con":true,"img":false}]}
{"op":"mcm","clk":"11449787475","pt":1717314671611,"mc":[{"id":"1.229554893","rc":[{"atl":[[3.7,0],[3.8,5.6]],"id":52671550},{"atl":[[4.1,0],[4.2,4.9]],"id":52671548}],"con":true,"img":false}]}
{"op":"mcm","clk":"11449787889","pt":1717314676207,"mc":[{"id":"1.229554893","rc":[{"atl":[[55,0]],"id":52671546},{"atl":[[9.2,0],[9.4,3.6]],"id":52671555}],"con":true,"img":false}]}
{"op":"mcm","clk":"11449787897","pt":1717314676308,"mc":[{"id":"1.229554893","rc":[{"atl":[[50,3.24]],"id":52671546}],"con":true,"img":false}]}
{"op":"mcm","clk":"11449788440","pt":1717314681635,"mc":[{"id":"1.229554893","rc":[{"atb":[[2.12,14.01]],"id":52671550},{"atb":[[2.24,12.65]],"id":52671548}],"con":true,"img":false}]}
{"op":"mcm","clk":"11449788907","pt":1717314686228,"mc":[{"id":"1.229554893","rc":[{"atl":[[50,0]],"id":52671546}],"con":true,"img":false}]}
{"op":"mcm","clk":"11449788916","pt":1717314686337,"mc":[{"id":"1.229554893","rc":[{"atl":[[55,3.09]],"id":52671546}],"con":true,"img":false}]}
{"op":"mcm","clk":"11449788983","pt":1717314687103,"mc":[{"id":"1.229554893","rc":[{"atb":[[2.08,0]],"id":52671550},{"atb":[[2.2,0]],"id":52671548},{"atl":[[4.1,5.06],[4.2,0]],"id":52671548}],"con":true,"img":false}]}
{"op":"mcm","clk":"11449789981","pt":1717314698352,"mc":[{"id":"1.229554893","rc":[{"atb":[[2,322.38],[2.2,108.91]],"id":52671550},{"atb":[[8,34.84],[10,11.61]],"id":52671546},{"atb":[[13.5,8.36],[9.4,29.03]],"id":52671549},{"atb":[[2,243.9],[2.2,87.1]],"id":52671548},{"atb":[[6.8,18.02],[5.4,55.43]],"id":52671542},{"atb":[[400,0.61],[500,0.2]],"id":52671545},{"atb":[[8,34.84],[10,11.61]],"id":52671544},{"atb":[[2.9,128.37],[3.25,46.45]],"id":52671555},{"atb":[[19,5.8],[14,18.76]],"id":52671554},{"atb":[[19,5.8],[14,18.76]],"id":52671556}],"con":true,"img":false}]}
{"op":"mcm","clk":"11449790941","pt":1717314708955,"mc":[{"id":"1.229554893","rc":[{"atl":[[9.4,0]],"id":52671555}],"con":true,"img":false}]}
{"op":"mcm","clk":"11449791099","pt":1717314710653,"mc":[{"id":"1.229554893","rc":[{"atl":[[9.6,0],[9.8,3.81]],"id":52671555}],"con":true,"img":false}]}
{"op":"mcm","clk":"11449791810","pt":1717314719460,"mc":[{"id":"1.229554893","rc":[{"atl":[[10,4.42],[9.8,0]],"id":52671555}],"con":true,"img":false}]}
{"op":"mcm","clk":"11449791933","pt":1717314720803,"mc":[{"id":"1.229554893","rc":[{"atb":[[1.16,153.62],[1.23,0]],"id":52671548},{"atb":[[38,2.7],[30,4.59]],"id":52671554},{"atb":[[36,2.86],[30,0]],"id":52671556}],"con":true,"img":false}]}
{"op":"mcm","clk":"11449791960","pt":1717314721109,"mc":[{"id":"1.229554893","rc":[{"atb":[[2.04,15.09],[2.16,0]],"id":52671550},{"atb":[[16.5,8.74],[15.5,0]],"id":52671546},{"atl":[[50,4.45],[55,0]],"id":52671546},{"atb":[[2.38,0],[2.28,0],[2.18,0],[2.16,13.52],[2.08,0]],"id":52671548},{"atl":[[55,4.63],[60,0]],"id":52671544},{"atb":[[4.1,0],[4.2,4.9]],"id":52671555},{"atb":[[65,0],[34,0],[36,0],[42,4.64],[46,0],[28,0]],"id":52671554},{"atl":[[150,3.81],[160,0]],"id":52671554},{"atb":[[32,0],[38,3.91]],"id":52671556}],"con":true,"img":false}]}
{"op":"mcm","clk":"11449792017","pt":1717314721814,"mc":[{"id":"1.229554893","rc":[{"atb":[[32,3.37],[80,0.33],[42,6.56],[55,0.97]],"id":52671554}],"con":true,"img":false}]}
{"op":"mcm","clk":"11449792026","pt":1717314721867,"mc":[{"id":"1.229554893","rc":[{"atb":[[2.24,54.85],[2.04,100.61],[2.14,68.84],[2.34,19.52]],"id":52671548}],"con":true,"img":false}]}
{"op":"mcm","clk":"11449792154","pt":1717314723307,"mc":[{"id":"1.229554893","rc":[{"atl":[[55,4.38]],"id":52671546},{"atl":[[21,3.63],[22,0]],"id":52671542},{"atl":[[55,0],[60,4.03]],"id":52671544},{"atl":[[150,0],[160,2.93]],"id":52671554}],"con":true,"img":false}]}
{"op":"mcm","clk":"11449792163","pt":1717314723367,"mc":[{"id":"1.229554893","rc":[{"atl":[[50,0]],"id":52671546}],"con":true,"img":false}]}
{"op":"mcm","clk":"11449792641","pt":1717314728880,"mc":[{"id":"1.229554893","rc":[{"atb":[[2.12,0]],"id":52671550},{"atl":[[3.7,5.81],[3.8,0]],"id":52671550},{"atb":[[2.24,42.19]],"id":52671548}],"con":true,"img":false}]}
{"op":"mcm","clk":"11449792816","pt":1717314731012,"mc":[{"id":"1.229554893","rc":[{"atb":[[2.12,14.01]],"id":52671548}],"con":true,"img":false}]}
{"op":"mcm","clk":"11449792824","pt":1717314731112,"mc":[{"id":"1.229554893","rc":[{"atl":[[11,4.34]],"id":52671555},{"atb":[[34,6.32]],"id":52671556}],"con":true,"img":false}]}
{"op":"mcm","clk":"11449792879","pt":1717314731732,"mc":[{"id":"1.229554893","rc":[{"atb":[[2,78.48],[2.2,21.8]],"id":52671550},{"atb":[[8,0],[10,0]],"id":52671546},{"atb":[[13.5,0],[9.4,0]],"id":52671549},{"atb":[[2,0],[2.2,0]],"id":52671548},{"atb":[[6.8,0],[5.4,0]],"id":52671542},{"atb":[[400,0],[500,0]],"id":52671545},{"atb":[[8,0],[10,0]],"id":52671544},{"atb":[[2.9,0],[3.25,0]],"id":52671555},{"atb":[[19,0],[14,0]],"id":52671554},{"atb":[[19,0],[14,0]],"id":52671556}],"con":true,"img":false}]}
{"op":"mcm","clk":"11449792895","pt":1717314731892,"mc":[{"id":"1.229554893","rc":[{"atb":[[220,2]],"id":52671545}],"con":true,"img":false}]}
{"op":"mcm","clk":"11449792904","pt":1717314732005,"mc":[{"id":"1.229554893","rc":[{"atb":[[180,0]],"id":52671545}],"con":true,"img":false}]}
{"op":"mcm","clk":"11449792952","pt":1717314732506,"mc":[{"id":"1.229554893","rc":[{"atb":[[160,0],[180,4.2]],"id":52671545},{"atl":[[10,0],[9.8,3.89]],"id":52671555},{"atb":[[29,0]],"id":52671556}],"con":true,"img":false}]}
{"op":"mcm","clk":"11449793035","pt":1717314733381,"mc":[{"id":"1.229554893","rc":[{"atb":[[15.5,4.21]],"id":52671546},{"atb":[[38,6.82]],"id":52671554}],"con":true,"img":false}]}
{"op":"mcm","clk":"11449793044","pt":1717314733482,"mc":[{"id":"1.229554893","rc":[{"atl":[[10,2.75],[9.8,0]],"id":52671555}],"con":true,"img":false}]}
{"op":"mcm","clk":"11449793335","pt":1717314737238,"mc":[{"id":"1.229554893","rc":[{"atb":[[2,322.38],[2.2,108.91]],"id":52671550},{"atb":[[8,34.84],[10,11.61]],"id":52671546},{"atb":[[13.5,8.36],[9.4,29.03]],"id":52671549},{"atb":[[2,243.9],[2.2,87.1]],"id":52671548},{"atb":[[6.8,18.02],[5.4,55.43]],"id":52671542},{"atb":[[400,0.61],[500,0.2]],"id":52671545},{"atb":[[8,34.84],[10,11.61]],"id":52671544},{"atb":[[2.9,128.37],[3.25,46.45]],"id":52671555},{"atb":[[19,5.8],[14,18.76]],"id":52671554},{"atb":[[19,5.8],[14,18.76]],"id":52671556}],"con":true,"img":false}]}
{"op":"mcm","clk":"11449793371","pt":1717314737604,"mc":[{"id":"1.229554893","rc":[{"atb":[[14.5,0]],"id":52671546},{"atb":[[30,0]],"id":52671554}],"con":true,"img":false}]}
{"op":"mcm","clk":"11449793480","pt":1717314738792,"mc":[{"id":"1.229554893","rc":[{"atb":[[2,338.08]],"id":52671550},{"atl":[[3.8,5.6]],"id":52671550}],"con":true,"img":false}]}
{"op":"mcm","clk":"11449793877","pt":1717314743321,"mc":[{"id":"1.229554893","rc":[{"atl":[[3.9,0]],"id":52671550}],"con":true,"img":false}]}
{"op":"mcm","clk":"11449796703","pt":1717314777055,"mc":[{"id":"1.229554893","rc":[{"atb":[[2,94.17],[2.2,21.8]],"id":52671550},{"atb":[[8,0],[10,0]],"id":52671546},{"atb":[[13.5,0],[9.4,0]],"id":52671549},{"atb":[[2,0],[2.2,0]],"id":52671548},{"atb":[[6.8,0],[5.4,0]],"id":52671542},{"atb":[[400,0],[500,0]],"id":52671545},{"atb":[[8,0],[10,0]],"id":52671544},{"atb":[[2.9,0],[3.25,0]],"id":52671555},{"atb":[[19,0],[14,0]],"id":52671554},{"atb":[[19,0],[14,0]],"id":52671556}],"con":true,"img":false}]}
{"op":"mcm","clk":"11449797469","pt":1717314786209,"mc":[{"id":"1.229554893","rc":[{"atb":[[1.21,153.62]],"id":52671548}],"con":true,"img":false}]}
{"op":"mcm","clk":"11449797478","pt":1717314786314,"mc":[{"id":"1.229554893","rc":[{"atb":[[1.16,0]],"id":52671548}],"con":true,"img":false}]}
{"op":"mcm","clk":"11449799612","pt":1717314812715,"mc":[{"id":"1.229554893","rc":[{"atb":[[2,15.69],[2.2,0],[1.95,0],[2.1,0]],"id":52671550},{"atb":[[9.6,0],[8.6,0],[11.5,0],[7.6,0]],"id":52671542}],"con":true,"img":false}]}
{"op":"mcm","clk":"11449799682","pt":1717314813442,"mc":[{"id":"1.229554893","rc":[{"atb":[[2.02,102.58],[2.32,19.82],[2.22,42.89],[2.12,70.07]],"id":52671550},{"atb":[[8,14.95],[9,9.81],[10,5.81],[12.5,2.28]],"id":52671542}],"con":true,"img":false}]}
{"op":"mcm","clk":"11449799694","pt":1717314813547,"mc":[{"id":"1.229554893","rc":[{"atb":[[2.04,0],[2.14,13.77]],"id":52671550},{"atl":[[3.7,0],[3.75,5.7]],"id":52671550},{"atb":[[2.26,12.45],[2.16,0]],"id":52671548},{"atl":[[3.95,5.32],[4.1,0]],"id":52671548},{"atb":[[3.05,0]],"id":52671542},{"atl":[[21,0],[22,3.34]],"id":52671542},{"atb":[[4.1,5.06],[4.2,0]],"id":52671555},{"atb":[[42,1.92]],"id":52671554},{"atb":[[38,0]],"id":52671556},{"atl":[[140,0]],"id":52671556}],"con":true,"img":false}]}
{"op":"mcm","clk":"11449799707","pt":1717314813650,"mc":[{"id":"1.229554893","rc":[{"atb":[[16.5,5.06],[16,3.9]],"id":52671546},{"atb":[[180,0]],"id":52671545},{"atb":[[36,7.02]],"id":52671556},{"atl":[[150,3.7]],"id":52671556}],"con":true,"img":false}]}
{"op":"mcm","clk":"11449800603","pt":1717314823547,"mc":[{"id":"1.229554893","rc":[{"atb":[[2.1,14.26]],"id":52671550},{"atb":[[2.22,12.86]],"id":52671548},{"atl":[[4.1,5.06]],"id":52671548},{"atb":[[3.05,7.65]],"id":52671542},{"atb":[[34,2.65]],"id":52671554}],"con":true,"img":false}]}
{"op":"mcm","clk":"11449800977","pt":1717314827474,"mc":[{"id":"1.229554893","rc":[{"atb":[[2,0]],"id":52671550},{"atb":[[2.12,0]],"id":52671548},{"atl":[[4.4,0]],"id":52671548}],"con":true,"img":false}]}
{"op":"mcm","clk":"11449801128","pt":1717314829133,"mc":[{"id":"1.229554893","rc":[{"atb":[[260,0]],"id":52671545}],"con":true,"img":false}]}
{"op":"mcm","clk":"11449801138","pt":1717314829239,"mc":[{"id":"1.229554893","rc":[{"atb":[[310,0],[360,0],[210,0]],"id":52671545}],"con":true,"img":false}]}
{"op":"mcm","clk":"11449801148","pt":1717314829342,"mc":[{"id":"1.229554893","rc":[{"atb":[[150,2]],"id":52671545}],"con":true,"img":false}]}
{"op":"mcm","clk":"11449801155","pt":1717314829447,"mc":[{"id":"1.229554893","rc":[{"atb":[[220,0]],"id":52671545}],"con":true,"img":false}]}
{"op":"mcm","clk":"11449801201","pt":1717314830066,"mc":[{"id":"1.229554893","rc":[{"atb":[[280,0.38],[330,0.24],[380,0.14],[430,0.06]],"id":52671545}],"con":true,"img":false}]}
{"op":"mcm","clk":"11449801220","pt":1717314830274,"mc":[{"id":"1.229554893","rc":[{"atb":[[150,0],[210,2]],"id":52671545}],"con":true,"img":false}]}
{"op":"mcm","clk":"11449801277","pt":1717314830782,"mc":[{"id":"1.229554893","rc":[{"atb":[[17,0],[19.5,0],[24,0],[29,0]],"id":52671549}],"con":true,"img":false}]}
{"op":"mcm","clk":"11449801330","pt":1717314831354,"mc":[{"id":"1.229554893","rc":[{"atb":[[34,3.93],[44,0],[27,0],[60,0]],"id":52671556}],"con":true,"img":false}]}
{"op":"mcm","clk":"11449801340","pt":1717314831457,"mc":[{"id":"1.229554893","rc":[{"atb":[[32,0.84],[18,6.15],[21,3.92],[26,2.09]],"id":52671549},{"atb":[[34,6.96],[36,4.16]],"id":52671556}],"con":true,"img":false}]}
{"op":"mcm","clk":"11449801386","pt":1717314832074,"mc":[{"id":"1.229554893","rc":[{"atb":[[70,0.38],[38,2.12],[48,1.11],[29,3.74]],"id":52671556}],"con":true,"img":false}]}
{"op":"mcm","clk":"11449801823","pt":1717314837383,"mc":[{"id":"1.229554893","rc":[{"atb":[[170,4.27]],"id":52671545}],"con":true,"img":false}]}
{"op":"mcm","clk":"11449801863","pt":1717314837896,"mc":[{"id":"1.229554893","rc":[{"atb":[[2,243.9],[2.2,87.1]],"id":52671550},{"atb":[[8,34.84],[10,11.61]],"id":52671546},{"atb":[[13.5,8.36],[9.4,29.03]],"id":52671549},{"atb":[[2,243.9],[2.2,87.1]],"id":52671548},{"atb":[[6.8,18.02],[5.4,55.43]],"id":52671542},{"atb":[[400,0.61],[500,0.2]],"id":52671545},{"atb":[[8,34.84],[10,11.61]],"id":52671544},{"atb":[[2.9,128.37],[3.25,46.45]],"id":52671555},{"atb":[[19,5.8],[14,18.76]],"id":52671554},{"atb":[[19,5.8],[14,18.76]],"id":52671556}],"con":true,"img":false}]}
{"op":"mcm","clk":"11449822867","pt":1717315070111,"mc":[{"id":"1.229554893","rc":[{"atb":[[2.02,0],[2.32,0],[2.22,0],[2.12,0]],"id":52671550},{"atb":[[16.5,9.1],[16,0]],"id":52671546},{"atb":[[2.26,0],[2.16,13.52]],"id":52671548},{"atb":[[8,0],[9,0],[10,0],[12.5,0]],"id":52671542},{"atb":[[280,0],[330,0],[380,0],[430,0]],"id":52671545},{"atb":[[4.1,0],[4.2,4.9]],"id":52671555},{"atb":[[38,2.7],[42,5.77]],"id":52671554},{"atb":[[70,0],[36,0],[38,2.85],[48,0],[29,0]],"id":52671556}],"con":true,"img":false}]}
{"op":"mcm","clk":"11449822874","pt":1717315070250,"mc":[{"id":"1.229554893","rc":[{"atb":[[2.14,0],[2.1,0]],"id":52671550},{"atb":[[34,3.93],[36,2.86]],"id":52671556}],"con":true,"img":false}]}
{"op":"mcm","clk":"11449822929","pt":1717315070785,"mc":[{"id":"1.229554893","rc":[{"atb":[[2.24,21.09],[1.97,107.87],[2.04,75.46],[2.14,45.89]],"id":52671550},{"atb":[[12,2.38],[9.8,5.94],[8.8,10.06],[7.8,15.39]],"id":52671542},{"atb":[[310,0.34],[360,0.22],[410,0.13],[460,0.06]],"id":52671545},{"atb":[[75,0.36],[40,2.01],[50,1.07],[30,3.61]],"id":52671556}],"con":true,"img":false}]}
{"op":"mcm","clk":"11449823756","pt":1717315080111,"mc":[{"id":"1.229554893","rc":[{"atb":[[2,259.6],[2.04,90.55]],"id":52671550},{"atb":[[2.22,0],[2.12,14.01]],"id":52671548},{"atl":[[4.3,4.75],[3.95,0]],"id":52671548},{"atl":[[21,2.71],[22,0]],"id":52671542},{"atb":[[38,7.36]],"id":52671554},{"atl":[[140,2.77],[150,0]],"id":52671556}],"con":true,"img":false}]}
{"op":"mcm","clk":"11449824474","pt":1717315088405,"mc":[{"id":"1.229554893","rc":[{"atb":[[34,0]],"id":52671554}],"con":true,"img":false}]}
{"op":"mcm","clk":"11449837779","pt":1717315159417,"mc":[{"id":"1.229554893","rc":[{"atb":[[210,0]],"id":52671545},{"atb":[[38,4.66]],"id":52671554},{"atb":[[36,0]],"id":52671556}],"con":true,"img":false}]}
{"op":"mcm","clk":"11449837792","pt":1717315159522,"mc":[{"id":"1.229554893","rc":[{"atb":[[170,6.27]],"id":52671545},{"atb":[[30,3.45]],"id":52671554},{"atb":[[29,3.57]],"id":52671556}],"con":true,"img":false}]}
{"op":"mcm","clk":"11449837808","pt":1717315159720,"mc":[{"id":"1.229554893","rc":[{"atb":[[2.24,0],[1.97,0],[2.04,0],[2.14,0],[2.16,13.52]],"id":52671550},{"atb":[[16.5,5.06]],"id":52671546},{"atb":[[32,0],[18,0],[21,0],[26,0]],"id":52671549},{"atb":[[2.26,12.45],[2.16,0]],"id":52671548},{"atb":[[310,0],[170,2],[360,0],[410,0],[460,0]],"id":52671545},{"atb":[[4.1,5.06],[4.2,0]],"id":52671555},{"atb":[[34,4.3]],"id":52671554},{"atb":[[34,0],[38,0]],"id":52671556}],"con":true,"img":false}]}
{"op":"mcm","clk":"11449837815","pt":1717315159824,"mc":[{"id":"1.229554893","rc":[{"atl":[[3.7,5.81],[3.75,0]],"id":52671550},{"atl":[[3.95,5.32],[4.1,0]],"id":52671548},{"atl":[[21,0],[22,3.17]],"id":52671542},{"atl":[[55,3.66],[60,0]],"id":52671544},{"atb":[[42,1.92]],"id":52671554}],"con":true,"img":false}]}
{"op":"mcm","clk":"11449837836","pt":1717315160135,"mc":[{"id":"1.229554893","rc":[{"atl":[[50,3.69]],"id":52671546},{"atl":[[160,0]],"id":52671554},{"atb":[[32,3.6]],"id":52671556},{"atl":[[140,0],[150,2.71]],"id":52671556}],"con":true,"img":false}]}
{"op":"mcm","clk":"11449837847","pt":1717315160197,"mc":[{"id":"1.229554893","rc":[{"atl":[[55,0]],"id":52671546},{"atl":[[4,5.23]],"id":52671548},{"atl":[[150,2.61]],"id":52671554}],"con":true,"img":false}]}
{"op":"mcm","clk":"11449837863","pt":1717315160402,"mc":[{"id":"1.229554893","rc":[{"atb":[[2.24,42.19],[2.04,100.61],[2.14,68.84],[2.34,19.52]],"id":52671550},{"atb":[[17,6.54],[19.5,4.24],[24,2.28],[29,0.94]],"id":52671549},{"atb":[[260,0.3],[310,0.17],[360,0.07],[210,0.5]],"id":52671545}],"con":true,"img":false}]}
{"op":"mcm","clk":"11449837894","pt":1717315160729,"mc":[{"id":"1.229554893","rc":[{"atb":[[2,15.69],[2.2,0]],"id":52671550},{"atb":[[8,0],[10,0]],"id":52671546},{"atb":[[13.5,0],[9.4,0]],"id":52671549},{"atb":[[2,0],[2.2,0]],"id":52671548},{"atb":[[6.8,0],[5.4,0]],"id":52671542},{"atb":[[170,0],[400,0],[220,2],[500,0]],"id":52671545},{"atb":[[8,0],[10,0]],"id":52671544},{"atb":[[2.9,0],[3.25,0]],"id":52671555},{"atb":[[38,7.36],[19,0],[14,0],[30,0]],"id":52671554},{"atb":[[36,2.86],[19,0],[14,0],[29,0]],"id":52671556}],"con":true,"img":false}]}
{"op":"mcm","clk":"11449837907","pt":1717315160824,"mc":[{"id":"1.229554893","rc":[{"atb":[[36,0]],"id":52671556}],"con":true,"img":false}]}
{"op":"mcm","clk":"11449837917","pt":1717315160931,"mc":[{"id":"1.229554893","rc":[{"atb":[[220,0]],"id":52671545},{"atb":[[38,4.66]],"id":52671554}],"con":true,"img":false}]}
{"op":"mcm","clk":"11449837926","pt":1717315161024,"mc":[{"id":"1.229554893","rc":[{"atb":[[2.16,0]],"id":52671550},{"atl":[[3.7,0],[3.75,5.7]],"id":52671550},{"atl":[[50,0],[55,3.63]],"id":52671546},{"atl":[[55,4.42],[60,0]],"id":52671549},{"atb":[[2.26,0]],"id":52671548},{"atl":[[4,0],[4.3,0]],"id":52671548},{"atl":[[21,4.22],[22,0]],"id":52671542},{"atb":[[170,2]],"id":52671545},{"atl":[[55,0],[60,3.5]],"id":52671544},{"atb":[[4.1,0],[4.2,4.9]],"id":52671555},{"atb":[[38,0],[42,5.89],[30,3.45]],"id":52671554},{"atl":[[150,0],[160,2.98]],"id":52671554},{"atb":[[38,4.68],[29,3.57]],"id":52671556},{"atl":[[140,3.7],[150,0]],"id":52671556}],"con":true,"img":false}]}
{"op":"mcm","clk":"11449837934","pt":1717315161128,"mc":[{"id":"1.229554893","rc":[{"atb":[[16.5,8.29]],"id":52671546},{"atb":[[2.16,13.52]],"id":52671548}],"con":true,"img":false}]}
{"op":"mcm","clk":"11449837942","pt":1717315161234,"mc":[{"id":"1.229554893","rc":[{"atl":[[3.95,0]],"id":52671548}],"con":true,"img":false}]}
{"op":"mcm","clk":"11449837978","pt":1717315161602,"mc":[{"id":"1.229554893","rc":[{"atb":[[160,3]],"id":52671545},{"atl":[[9.8,3.66]],"id":52671555}],"con":true,"img":false}]}
{"op":"mcm","clk":"11449837989","pt":1717315161711,"mc":[{"id":"1.229554893","rc":[{"atl":[[10,0]],"id":52671555}],"con":true,"img":false}]}
{"op":"mcm","clk":"11449838163","pt":1717315163415,"mc":[{"id":"1.229554893","rc":[{"atb":[[38,2.7],[30,0]],"id":52671554}],"con":true,"img":false}]}
{"op":"mcm","clk":"11449838192","pt":1717315163731,"mc":[{"id":"1.229554893","rc":[{"atb":[[2.24,0],[2.04,15.09],[2.14,0],[2.16,13.52],[2.34,0]],"id":52671550},{"atb":[[16.5,5.06]],"id":52671546},{"atb":[[17,0],[19.5,0],[24,0],[29,0]],"id":52671549},{"atl":[[55,0],[60,3.78]],"id":52671549},{"atb":[[2.26,12.45],[2.16,0]],"id":52671548},{"atl":[[3.95,5.32],[4.1,5.06]],"id":52671548},{"atl":[[21,0],[22,3.71]],"id":52671542},{"atb":[[160,0],[180,3.03]],"id":52671545},{"atb":[[4.1,5.06],[4.2,0]],"id":52671555},{"atl":[[10,4.63],[9.8,0]],"id":52671555},{"atb":[[42,1.92]],"id":52671554},{"atb":[[38,0]],"id":52671556},{"atl":[[140,0],[150,3.28]],"id":52671556}],"con":true,"img":false}]}
{"op":"mcm","clk":"11449838276","pt":1717315164504,"mc":[{"id":"1.229554893","rc":[{"atb":[[2.24,21.09],[1.97,107.87],[2.04,90.55],[2.14,45.89]],"id":52671550},{"atb":[[32,0.84],[18,6.15],[21,3.92],[26,2.09]],"id":52671549}],"con":true,"img":false}]}
{"op":"mcm","clk":"11449838858","pt":1717315171031,"mc":[{"id":"1.229554893","rc":[{"atb":[[16.5,8.34]],"id":52671546},{"atb":[[42,4.68]],"id":52671554}],"con":true,"img":false}]}
{"op":"mcm","clk":"11449838883","pt":1717315171235,"mc":[{"id":"1.229554893","rc":[{"atb":[[2.16,0]],"id":52671550},{"atb":[[2.26,0],[2.16,13.52]],"id":52671548},{"atl":[[3.95,0]],"id":52671548},{"atl":[[21,2.93],[22,0]],"id":52671542},{"atb":[[4.1,0],[4.2,4.9]],"id":52671555},{"atb":[[38,3.86]],"id":52671556},{"atl":[[140,2.83],[150,0]],"id":52671556}],"con":true,"img":false}]}
{"op":"mcm","clk":"11449838926","pt":1717315171646,"mc":[{"id":"1.229554893","rc":[{"atb":[[38,0]],"id":52671554}],"con":true,"img":false}]}
{"op":"mcm","clk":"11449838939","pt":1717315171750,"mc":[{"id":"1.229554893","rc":[{"atb":[[30,3.45]],"id":52671554}],"con":true,"img":false}]}
{"op":"mcm","clk":"11449838957","pt":1717315171954,"mc":[{"id":"1.229554893","rc":[{"atl":[[3.7,5.81]],"id":52671550},{"atl":[[50,4.6],[55,0]],"id":52671546},{"atl":[[55,4.38]],"id":52671549},{"atb":[[2.26,12.45]],"id":52671548},{"atb":[[180,0]],"id":52671545},{"atb":[[4.1,5.06]],"id":52671555},{"atb":[[38,0]],"id":52671556}],"con":true,"img":false}]}
{"op":"mcm","clk":"11449838969","pt":1717315172061,"mc":[{"id":"1.229554893","rc":[{"atb":[[2.24,0],[1.97,0],[2.04,0],[2.14,0],[2.16,13.52]],"id":52671550},{"atl":[[3.75,0]],"id":52671550},{"atb":[[16.5,5.06]],"id":52671546},{"atb":[[32,0],[18,0],[21,0],[26,0]],"id":52671549},{"atl":[[60,0]],"id":52671549},{"atb":[[2.16,0]],"id":52671548},{"atl":[[4,5.23]],"id":52671548},{"atb":[[4.2,0]],"id":52671555},{"atb":[[42,1.92]],"id":52671554}],"con":true,"img":false}]}
{"op":"mcm","clk":"11449839014","pt":1717315172428,"mc":[{"id":"1.229554893","rc":[{"atl":[[3.95,5.32]],"id":52671548},{"atl":[[21,0],[22,2.93]],"id":52671542},{"atl":[[140,0],[150,4.43]],"id":52671556}],"con":true,"img":false}]}
{"op":"mcm","clk":"11449839058","pt":1717315172837,"mc":[{"id":"1.229554893","rc":[{"atb":[[2.24,21.09],[1.97,107.87],[2.04,75.46],[2.14,45.89]],"id":52671550}],"con":true,"img":false}]}
{"op":"mcm","clk":"11449839069","pt":1717315172942,"mc":[{"id":"1.229554893","rc":[{"atb":[[32,0.84],[18,6.15],[21,3.92],[26,2.09]],"id":52671549}],"con":true,"img":false}]}
{"op":"mcm","clk":"11449839148","pt":1717315173767,"mc":[{"id":"1.229554893","rc":[{"atb":[[180,3.21]],"id":52671545}],"con":true,"img":false}]}
{"op":"mcm","clk":"11449839260","pt":1717315174757,"mc":[{"id":"1.229554893","rc":[{"atl":[[3.7,0],[3.75,5.7]],"id":52671550},{"atl":[[50,0],[55,3.6]],"id":52671546},{"atl":[[55,0],[60,2.95]],"id":52671549},{"atl":[[4,0],[3.95,0]],"id":52671548},{"atl":[[21,3.81],[22,0]],"id":52671542},{"atb":[[180,0]],"id":52671545},{"atl":[[140,3.55],[150,0]],"id":52671556}],"con":true,"img":false}]}
{"op":"mcm","clk":"11449839296","pt":1717315175062,"mc":[{"id":"1.229554893","rc":[{"atl":[[4.1,0]],"id":52671548},{"atl":[[55,2.91],[60,0]],"id":52671544},{"atl":[[150,3.2],[160,0]],"id":52671554}],"con":true,"img":false}]}
{"op":"mcm","clk":"11449839424","pt":1717315176359,"mc":[{"id":"1.229554893","rc":[{"atl":[[3.95,5.32],[4.1,5.06]],"id":52671548},{"atl":[[21,0],[22,3.87]],"id":52671542},{"atl":[[55,0],[60,3.75]],"id":52671544},{"atl":[[160,3.15]],"id":52671554},{"atl":[[140,0],[150,2.85]],"id":52671556}],"con":true,"img":false}]}
{"op":"mcm","clk":"11449839431","pt":1717315176459,"mc":[{"id":"1.229554893","rc":[{"atl":[[150,0]],"id":52671554}],"con":true,"img":false}]}
{"op":"mcm","clk":"11449839664","pt":1717315178766,"mc":[{"id":"1.229554893","rc":[{"atb":[[32,0],[18,0],[21,0],[26,0]],"id":52671549}],"con":true,"img":false}]}
{"op":"mcm","clk":"11449839738","pt":1717315179437,"mc":[{"id":"1.229554893","rc":[{"atl":[[3.75,0]],"id":52671550},{"atb":[[17,6.54],[19.5,4.24],[24,2.28],[29,0.94]],"id":52671549},{"atl":[[3.95,0]],"id":52671548},{"atl":[[55,3.06],[60,0]],"id":52671544},{"atl":[[150,3.67],[160,0]],"id":52671554},{"atl":[[140,3.8],[150,0]],"id":52671556}],"con":true,"img":false}]}
{"op":"mcm","clk":"11449839957","pt":1717315181849,"mc":[{"id":"1.229554893","rc":[{"atb":[[2.06,14.8],[2.16,0]],"id":52671550},{"atb":[[16,3.72]],"id":52671546},{"atb":[[2.26,0],[2.2,13.07]],"id":52671548},{"atb":[[12,0],[9.8,0],[8.8,0],[7.8,0]],"id":52671542},{"atb":[[4.3,12.68],[4.1,0]],"id":52671555},{"atb":[[36,4.09]],"id":52671554},{"atb":[[34,3.03]],"id":52671556}],"con":true,"img":false}]}
{"op":"mcm","clk":"11449840028","pt":1717315182533,"mc":[{"id":"1.229554893","rc":[{"atb":[[9.6,6.08],[8.6,10.33],[11.5,2.49],[7.6,15.85]],"id":52671542}],"con":true,"img":false}]}
{"op":"mcm","clk":"11449840239","pt":1717315184746,"mc":[{"id":"1.229554893","rc":[{"atl":[[55,4.43]],"id":52671549}],"con":true,"img":false}]}
{"op":"mcm","clk":"11449840249","pt":1717315184849,"mc":[{"id":"1.229554893","rc":[{"atl":[[60,0]],"id":52671549}],"con":true,"img":false}]}
{"op":"mcm","clk":"11449840370","pt":1717315186138,"mc":[{"id":"1.229554893","rc":[{"atl":[[3.8,0],[3.9,5.4]],"id":52671550},{"atl":[[21,3.94],[22,0]],"id":52671542}],"con":true,"img":false}]}
{"op":"mcm","clk":"11449840398","pt":1717315186450,"mc":[{"id":"1.229554893","rc":[{"atl":[[3.95,5.32]],"id":52671548},{"atl":[[140,0]],"id":52671556}],"con":true,"img":false}]}
{"op":"mcm","clk":"11449840412","pt":1717315186550,"mc":[{"id":"1.229554893","rc":[{"atl":[[3.85,5.5]],"id":52671550},{"atb":[[32,0],[80,0],[42,0],[55,0]],"id":52671554},{"atb":[[75,0],[40,0],[50,0],[30,0]],"id":52671556},{"atl":[[150,4.69]],"id":52671556}],"con":true,"img":false}]}
{"op":"mcm","clk":"11449840421","pt":1717315186658,"mc":[{"id":"1.229554893","rc":[{"atb":[[32,3.23],[30,0]],"id":52671554},{"atb":[[29,0],[30,3.45]],"id":52671556}],"con":true,"img":false}]}
{"op":"mcm","clk":"11449840471","pt":1717315187274,"mc":[{"id":"1.229554893","rc":[{"atb":[[70,0.38],[38,2.12],[48,1.11],[29,3.74]],"id":52671554},{"atb":[[65,0.41],[36,2.24],[46,1.16],[28,3.88]],"id":52671556}],"con":true,"img":false}]}
{"op":"mcm","clk":"11449840981","pt":1717315192651,"mc":[{"id":"1.229554893","rc":[{"atb":[[2.06,0],[2.08,14.53]],"id":52671550},{"atb":[[260,0],[310,0],[360,0],[210,0]],"id":52671545},{"atb":[[4.3,7.93],[4.2,4.9]],"id":52671555},{"atb":[[34,0],[36,0]],"id":52671554},{"atb":[[34,0],[30,7.82]],"id":52671556}],"con":true,"img":false}]}
{"op":"mcm","clk":"11449840993","pt":1717315192755,"mc":[{"id":"1.229554893","rc":[{"atb":[[17,0],[19.5,0],[24,0],[29,0]],"id":52671549},{"atb":[[150,2]],"id":52671545}],"con":true,"img":false}]}
{"op":"mcm","clk":"11449841001","pt":1717315192861,"mc":[{"id":"1.229554893","rc":[{"atb":[[170,0]],"id":52671545}],"con":true,"img":false}]}
{"op":"mcm","clk":"11449841018","pt":1717315193067,"mc":[{"id":"1.229554893","rc":[{"atb":[[70,0],[38,0],[48,0],[29,0]],"id":52671554},{"atb":[[65,0],[36,0],[46,0],[28,0]],"id":52671556}],"con":true,"img":false}]}
{"op":"mcm","clk":"11449841027","pt":1717315193164,"mc":[{"id":"1.229554893","rc":[{"atb":[[32,0],[27,3.85]],"id":52671554},{"atb":[[26,4]],"id":52671556}],"con":true,"img":false}]}
{"op":"mcm","clk":"11449841039","pt":1717315193270,"mc":[{"id":"1.229554893","rc":[{"atb":[[30,4.37]],"id":52671556}],"con":true,"img":false}]}
{"op":"mcm","clk":"11449841086","pt":1717315193786,"mc":[{"id":"1.229554893","rc":[{"atb":[[17,4.9],[19.5,2.83],[24,1.14],[14.5,7.75]],"id":52671549},{"atb":[[260,0.2],[310,0.08],[160,0.66],[210,0.38]],"id":52671545},{"atb":[[34,2.38],[44,1.22],[27,7.87],[60,0.44]],"id":52671554},{"atb":[[32,6.14],[42,1.28],[26,8.19],[55,0.49]],"id":52671556}],"con":true,"img":false}]}
{"op":"mcm","clk":"11449841178","pt":1717315194770,"mc":[{"id":"1.229554893","rc":[{"atb":[[150,4.89]],"id":52671545},{"atb":[[28,2.91],[30,3.86]],"id":52671554},{"atb":[[32,2.53]],"id":52671556}],"con":true,"img":false}]}
{"op":"mcm","clk":"11449841351","pt":1717315196584,"mc":[{"id":"1.229554893","rc":[{"atb":[[2.16,13.52]],"id":52671548}],"con":true,"img":false}]}
{"op":"mcm","clk":"11449841761","pt":1717315200495,"mc":[{"id":"1.229554893","rc":[{"atb":[[2.12,0]],"id":52671548}],"con":true,"img":false}]}
{"op":"mcm","clk":"11449842030","pt":1717315202695,"mc":[{"id":"1.229554893","rc":[{"atb":[[2.04,90.55]],"id":52671550},{"atb":[[28,3.4]],"id":52671556}],"con":true,"img":false}]}
{"op":"mcm","clk":"11449842711","pt":1717315208886,"mc":[{"id":"1.229554893","rc":[{"atb":[[2,0]],"id":52671550}],"con":true,"img":false}]}
{"op":"mcm","clk":"11449842903","pt":1717315210692,"mc":[{"id":"1.229554893","rc":[{"atb":[[2.36,0],[2.48,67.57]],"id":52671555}],"con":true,"img":false}]}
{"op":"mcm","clk":"11449842940","pt":1717315211003,"mc":[{"id":"1.229554893","rc":[{"atb":[[2.14,59.66],[2.08,0]],"id":52671550},{"atb":[[16.5,9.17],[16,0]],"id":52671546},{"atb":[[2.18,13.29],[2.2,0]],"id":52671548},{"atb":[[4.3,12.68],[4.2,0]],"id":52671555}],"con":true,"img":false}]}
{"op":"mcm","clk":"11449843010","pt":1717315211575,"mc":[{"id":"1.229554893","rc":[{"atb":[[2,243.9],[2.2,87.1]],"id":52671550},{"atb":[[8,34.84],[10,11.61]],"id":52671546},{"atb":[[13.5,8.36],[9.4,29.03]],"id":52671549},{"atb":[[2,243.9],[2.2,87.1]],"id":52671548},{"atb":[[6.8,18.02],[5.4,55.43]],"id":52671542},{"atb":[[400,0.61],[500,0.2]],"id":52671545},{"atb":[[8,34.84],[10,11.61]],"id":52671544},{"atb":[[2.9,128.37],[3.25,46.45]],"id":52671555},{"atb":[[19,5.8],[14,18.76]],"id":52671554},{"atb":[[19,5.8],[14,18.76]],"id":52671556}],"con":true,"img":false}]}
{"op":"mcm","clk":"11449843101","pt":1717315212366,"mc":[{"id":"1.229554893","rc":[{"atb":[[1.12,0],[1.2,177.67]],"id":52671550}],"con":true,"img":false}]}
{"op":"mcm","clk":"11449843122","pt":1717315212579,"mc":[{"id":"1.229554893","rc":[{"atl":[[10,0],[9.4,3.92]],"id":52671555}],"con":true,"img":false}]}
{"op":"mcm","clk":"11449843133","pt":1717315212678,"mc":[{"id":"1.229554893","rc":[{"atb":[[2.22,12.86]],"id":52671550},{"atb":[[2.18,0],[2.26,12.45]],"id":52671548},{"atb":[[140,0],[150,2]],"id":52671545},{"atb":[[4.2,4.9]],"id":52671555},{"atb":[[29,3.9],[30,0]],"id":52671554},{"atb":[[29,2.96],[30,0]],"id":52671556}],"con":true,"img":false}]}
{"op":"mcm","clk":"11449843144","pt":1717315212783,"mc":[{"id":"1.229554893","rc":[{"atb":[[2.14,45.89]],"id":52671550},{"atb":[[260,0],[310,0],[160,0],[210,0]],"id":52671545},{"atb":[[4.3,7.93]],"id":52671555}],"con":true,"img":false}]}
{"op":"mcm","clk":"11449843209","pt":1717315213504,"mc":[{"id":"1.229554893","rc":[{"atb":[[150,2.7],[300,0.09],[200,0.39],[250,0.21]],"id":52671545}],"con":true,"img":false}]}
{"op":"mcm","clk":"11449843263","pt":1717315213980,"mc":[{"id":"1.229554893","rc":[{"atl":[[3.85,0],[3.75,5.7]],"id":52671550},{"atl":[[8.8,3.55],[9.4,0]],"id":52671555},{"atl":[[150,0],[160,2.71]],"id":52671554},{"atl":[[140,3.32],[150,0]],"id":52671556}],"con":true,"img":false}]}
{"op":"mcm","clk":"11449844173","pt":1717315222689,"mc":[{"id":"1.229554893","rc":[{"atb":[[2.22,12.86]],"id":52671548}],"con":true,"img":false}]}
{"op":"mcm","clk":"11449844278","pt":1717315223715,"mc":[{"id":"1.229554893","rc":[{"atb":[[2.16,0]],"id":52671548}],"con":true,"img":false}]}
{"op":"mcm","clk":"11449844312","pt":1717315223979,"mc":[{"id":"1.229554893","rc":[{"atb":[[2.18,13.29]],"id":52671550},{"atl":[[9.2,4.42]],"id":52671555}],"con":true,"img":false}]}
{"op":"mcm","clk":"11449845148","pt":1717315232707,"mc":[{"id":"1.229554893","rc":[{"atl":[[50,2.84],[55,0]],"id":52671549},{"atl":[[4,5.23]],"id":52671548}],"con":true,"img":false}]}
{"op":"mcm","clk":"11449845157","pt":1717315232808,"mc":[{"id":"1.229554893","rc":[{"atl":[[3.95,0]],"id":52671548}],"con":true,"img":false}]}
{"op":"mcm","clk":"11449845269","pt":1717315234002,"mc":[{"id":"1.229554893","rc":[{"atb":[[2.04,75.46]],"id":52671550}],"con":true,"img":false}]}
{"op":"mcm","clk":"11449845275","pt":1717315234106,"mc":[{"id":"1.229554893","rc":[{"atl":[[11,0]],"id":52671555}],"con":true,"img":false}]}
{"op":"mcm","clk":"11449845700","pt":1717315239010,"mc":[{"id":"1.229554893","rc":[{"atl":[[140,3.15],[160,0]],"id":52671554},{"atl":[[130,4.45],[140,0]],"id":52671556}],"con":true,"img":false}]}
{"op":"mcm","clk":"11449846020","pt":1717315242706,"mc":[{"id":"1.229554893","rc":[{"atl":[[60,3.86]],"id":52671549}],"con":true,"img":false}]}
{"op":"mcm","clk":"11449846061","pt":1717315243121,"mc":[{"id":"1.229554893","rc":[{"atb":[[30,3.45]],"id":52671554},{"atb":[[26,4.19],[29,6.37]],"id":52671556}],"con":true,"img":false}]}
{"op":"mcm","clk":"11449846070","pt":1717315243224,"mc":[{"id":"1.229554893","rc":[{"atb":[[27,4.02]],"id":52671554}],"con":true,"img":false}]}
{"op":"mcm","clk":"11449846084","pt":1717315243328,"mc":[{"id":"1.229554893","rc":[{"atb":[[30,0]],"id":52671554}],"con":true,"img":false}]}
{"op":"mcm","clk":"11449846095","pt":1717315243432,"mc":[{"id":"1.229554893","rc":[{"atb":[[2.22,0],[2.2,100.18]],"id":52671550},{"atb":[[16.5,5.06]],"id":52671546},{"atl":[[70,0]],"id":52671549},{"atb":[[130,3.33],[150,5.87]],"id":52671545},{"atb":[[4.3,12.68],[4.2,0]],"id":52671555},{"atb":[[34,5.39],[25,4.17],[29,0]],"id":52671554},{"atb":[[32,6.6],[29,3.41]],"id":52671556}],"con":true,"img":false}]}
{"op":"mcm","clk":"11449846213","pt":1717315244623,"mc":[{"id":"1.229554893","rc":[{"atb":[[25,0],[30,3.45]],"id":52671554}],"con":true,"img":false}]}
{"op":"mcm","clk":"11449846241","pt":1717315245033,"mc":[{"id":"1.229554893","rc":[{"atb":[[30,0]],"id":52671554}],"con":true,"img":false}]}
{"op":"mcm","clk":"11449846250","pt":1717315245136,"mc":[{"id":"1.229554893","rc":[{"atb":[[25,4.17]],"id":52671554}],"con":true,"img":false}]}
{"op":"mcm","clk":"11449846265","pt":1717315245344,"mc":[{"id":"1.229554893","rc":[{"atb":[[2.22,12.86],[2.2,87.1]],"id":52671550},{"atb":[[16.5,9.32]],"id":52671546},{"atb":[[150,2.7]],"id":52671545},{"atb":[[4.3,7.93],[4.2,4.9]],"id":52671555},{"atb":[[34,2.38],[29,4.49]],"id":52671554},{"atb":[[32,2.53],[29,6.89]],"id":52671556}],"con":true,"img":false}]}
{"op":"mcm","clk":"11449846422","pt":1717315246902,"mc":[{"id":"1.229554893","rc":[{"atb":[[25,0],[30,3.45]],"id":52671554}],"con":true,"img":false}]}
{"op":"mcm","clk":"11449846456","pt":1717315247219,"mc":[{"id":"1.229554893","rc":[{"atb":[[2.22,0],[2.2,100.18]],"id":52671550},{"atb":[[16.5,5.06]],"id":52671546},{"atb":[[150,6.86]],"id":52671545},{"atb":[[4.3,12.68],[4.2,0]],"id":52671555},{"atb":[[34,6.48],[29,0]],"id":52671554},{"atb":[[32,6.38],[29,3.41]],"id":52671556}],"con":true,"img":false}]}
{"op":"mcm","clk":"11449846516","pt":1717315247732,"mc":[{"id":"1.229554893","rc":[{"atb":[[2,0],[2.2,13.07]],"id":52671550},{"atb":[[8,0],[10,0]],"id":52671546},{"atb":[[13.5,0],[9.4,0]],"id":52671549},{"atb":[[2,0],[2.2,0]],"id":52671548},{"atb":[[6.8,0],[5.4,0]],"id":52671542},{"atb":[[400,0],[500,0]],"id":52671545},{"atb":[[8,0],[10,0]],"id":52671544},{"atb":[[2.9,0],[3.25,0]],"id":52671555},{"atb":[[19,0],[14,0]],"id":52671554},{"atb":[[19,0],[14,0]],"id":52671556}],"con":true,"img":false}]}
{"op":"mcm","clk":"11449846804","pt":1717315249917,"mc":[{"id":"1.229554893","rc":[{"atb":[[30,0]],"id":52671554}],"con":true,"img":false}]}
{"op":"mcm","clk":"11449846832","pt":1717315250235,"mc":[{"id":"1.229554893","rc":[{"atb":[[2.22,12.86],[2.2,0]],"id":52671550},{"atb":[[16.5,9.24]],"id":52671546},{"atb":[[140,3.64],[150,2.7]],"id":52671545},{"atb":[[4.3,7.93],[4.2,4.9]],"id":52671555},{"atb":[[34,2.38],[29,4.12]],"id":52671554},{"atb":[[32,2.53],[29,7.15]],"id":52671556}],"con":true,"img":false}]}
{"op":"mcm","clk":"11449846853","pt":1717315250440,"mc":[{"id":"1.229554893","rc":[{"atb":[[25,4.17]],"id":52671554}],"con":true,"img":false}]}
{"op":"mcm","clk":"11449846952","pt":1717315251653,"mc":[{"id":"1.229554893","rc":[{"atl":[[50,0],[55,4.68]],"id":52671549},{"atb":[[140,0],[160,3.77]],"id":52671545},{"atl":[[55,0],[60,2.62]],"id":52671544},{"atl":[[9,3.61],[8.8,0]],"id":52671555},{"atb":[[32,3.44],[29,0]],"id":52671554},{"atl":[[140,0],[150,4.51]],"id":52671554},{"atb":[[32,6.12],[29,3.41]],"id":52671556}],"con":true,"img":false}]}
{"op":"mcm","clk":"11449846961","pt":1717315251713,"mc":[{"id":"1.229554893","rc":[{"atb":[[16.5,5.06]],"id":52671546},{"atl":[[160,3.82]],"id":52671554},{"atl":[[130,0],[140,3.44]],"id":52671556}],"con":true,"img":false}]}
{"op":"mcm","clk":"11449847009","pt":1717315252336,"mc":[{"id":"1.229554893","rc":[{"atl":[[9,0],[8.8,2.7]],"id":52671555}],"con":true,"img":false}]}
{"op":"mcm","clk":"11449847021","pt":1717315252429,"mc":[{"id":"1.229554893","rc":[{"atl":[[150,0]],"id":52671554}],"con":true,"img":false}]}
{"op":"mcm","clk":"11449847563","pt":1717315258253,"mc":[{"id":"1.229554893","rc":[{"atb":[[2.06,230.09],[2.26,82.96]],"id":52671550},{"atb":[[10.5,11],[8.2,33.87]],"id":52671546},{"atb":[[9,30.48],[12.5,9.08]],"id":52671549},{"atb":[[1.98,248.88],[2.16,90.11]],"id":52671548},{"atb":[[5.3,56.72],[6.6,18.66]],"id":52671542},{"atb":[[350,0.29],[250,1.19]],"id":52671545},{"atb":[[8,34.84],[10,11.61]],"id":52671544},{"atb":[[2.92,127.03],[3.3,45.44]],"id":52671555},{"atb":[[18,6.14],[13,20.32]],"id":52671554},{"atb":[[18,6.14],[13,20.32]],"id":52671556}],"con":true,"img":false}]}
{"op":"mcm","clk":"11449847737","pt":1717315260117,"mc":[{"id":"1.229554893","rc":[{"atb":[[30,3.45]],"id":52671554}],"con":true,"img":false}]}
{"op":"mcm","clk":"11449847745","pt":1717315260219,"mc":[{"id":"1.229554893","rc":[{"atb":[[14.5,4.46]],"id":52671546},{"atb":[[25,0]],"id":52671554}],"con":true,"img":false}]}
{"op":"mcm","clk":"11449848403","pt":1717315266759,"mc":[{"id":"1.229554893","rc":[{"atl":[[55,3.43]],"id":52671544}],"con":true,"img":false}]}
{"op":"mcm","clk":"11449848410","pt":1717315266864,"mc":[{"id":"1.229554893","rc":[{"atl":[[60,0]],"id":52671544}],"con":true,"img":false}]}
{"op":"mcm","clk":"11449848551","pt":1717315268272,"mc":[{"id":"1.229554893","rc":[{"atl":[[3.7,5.81]],"id":52671550},{"atl":[[50,3.14],[55,0]],"id":52671546},{"atl":[[9,4.03],[8.8,0]],"id":52671555}],"con":true,"img":false}]}
{"op":"mcm","clk":"11449848563","pt":1717315268367,"mc":[{"id":"1.229554893","rc":[{"atl":[[3.75,0]],"id":52671550},{"atl":[[55,0],[60,3.1]],"id":52671544}],"con":true,"img":false}]}
{"op":"mcm","clk":"11449849501","pt":1717315278384,"mc":[{"id":"1.229554893","rc":[{"atl":[[3.8,5.6]],"id":52671550}],"con":true,"img":false}]}
{"op":"mcm","clk":"11449849661","pt":1717315279886,"mc":[{"id":"1.229554893","rc":[{"atl":[[3.9,0]],"id":52671550},{"atl":[[9,0],[9.8,4.15]],"id":52671555}],"con":true,"img":false}]}
{"op":"mcm","clk":"11449849784","pt":1717315280862,"mc":[{"id":"1.229554893","rc":[{"atl":[[9.2,0]],"id":52671555}],"con":true,"img":false}]}
{"op":"mcm","clk":"11449850640","pt":1717315289921,"mc":[{"id":"1.229554893","rc":[{"atl":[[10.5,3.53]],"id":52671555}],"con":true,"img":false}]}
{"op":"mcm","clk":"11449851183","pt":1717315295523,"mc":[{"id":"1.229554893","rc":[{"atb":[[2.06,0],[2.26,0]],"id":52671550},{"atb":[[10.5,0],[8.2,0]],"id":52671546},{"atb":[[9,0],[12.5,0]],"id":52671549},{"atb":[[1.98,0],[2.16,0]],"id":52671548},{"atb":[[5.3,0],[6.6,0]],"id":52671542},{"atb":[[350,0],[250,0.21]],"id":52671545},{"atb":[[8,0],[10,0]],"id":52671544},{"atb":[[2.92,0],[3.3,0]],"id":52671555},{"atb":[[18,0],[13,0]],"id":52671554},{"atb":[[18,0],[13,0]],"id":52671556}],"con":true,"img":false}]}
{"op":"mcm","clk":"11449852327","pt":1717315307325,"mc":[{"id":"1.229554893","rc":[{"atb":[[2.24,0],[1.97,0],[2.04,0],[2.14,0]],"id":52671550}],"con":true,"img":false}]}
{"op":"mcm","clk":"11449852379","pt":1717315307987,"mc":[{"id":"1.229554893","rc":[{"atb":[[2.4,18.68],[2.3,40.24],[2.2,65.4]],"id":52671550}],"con":true,"img":false}]}
{"op":"mcm","clk":"11449852392","pt":1717315308091,"mc":[{"id":"1.229554893","rc":[{"atb":[[2.1,95.12]],"id":52671550}],"con":true,"img":false}]}
{"op":"mcm","clk":"11449854188","pt":1717315326144,"mc":[{"id":"1.229554893","rc":[{"atb":[[17,0],[19.5,0],[24,0],[14.5,0]],"id":52671549},{"atb":[[34,0],[44,0],[27,0],[60,0]],"id":52671554},{"atb":[[32,3.58],[42,0],[26,0],[55,0]],"id":52671556}],"con":true,"img":false}]}
{"op":"mcm","clk":"11449854214","pt":1717315326350,"mc":[{"id":"1.229554893","rc":[{"atb":[[29,0],[30,3.45]],"id":52671556}],"con":true,"img":false}]}
{"op":"mcm","clk":"11449854260","pt":1717315326814,"mc":[{"id":"1.229554893","rc":[{"atb":[[17,6.54],[19.5,4.24],[24,2.28],[29,0.94]],"id":52671549},{"atb":[[65,0.41],[36,2.24],[46,1.16],[28,6.8]],"id":52671554},{"atb":[[65,0.41],[36,2.24],[46,1.16],[28,7.28]],"id":52671556}],"con":true,"img":false}]}
{"op":"mcm","clk":"11449854732","pt":1717315331455,"mc":[{"id":"1.229554893","rc":[{"atb":[[2.32,79.18],[2.12,217.77]],"id":52671550},{"atb":[[11,10.45],[8.4,32.96]],"id":52671546},{"atb":[[12,9.5],[8.8,31.27]],"id":52671549},{"atb":[[2.06,98.61],[1.93,262.26]],"id":52671548},{"atb":[[6.4,19.35],[5.2,58.07]],"id":52671542},{"atb":[[340,0.3],[240,1.02]],"id":52671545},{"atb":[[8,34.84],[10,11.61]],"id":52671544},{"atb":[[3.35,44.48],[2.94,125.72]],"id":52671555},{"atb":[[17.5,6.33],[12.5,21.2]],"id":52671554},{"atb":[[18,6.14],[13,20.32]],"id":52671556}],"con":true,"img":false}]}
{"op":"mcm","clk":"11449857108","pt":1717315353753,"mc":[{"id":"1.229554893","rc":[{"atb":[[200,2.39]],"id":52671545}],"con":true,"img":false}]}
{"op":"mcm","clk":"11449857119","pt":1717315353858,"mc":[{"id":"1.229554893","rc":[{"atb":[[150,0.7]],"id":52671545}],"con":true,"img":false}]}
{"op":"mcm","clk":"11449857142","pt":1717315354069,"mc":[{"id":"1.229554893","rc":[{"atb":[[2.4,0],[2.3,0],[2.22,0],[2.2,13.07],[2.1,0]],"id":52671550},{"atb":[[16.5,9.42],[15.5,0]],"id":52671546},{"atb":[[2.24,54.85],[2.26,0]],"id":52671548},{"atb":[[160,0],[170,2.81]],"id":52671545},{"atb":[[32,0],[38,3.67]],"id":52671554},{"atb":[[32,0],[36,6.84]],"id":52671556}],"con":true,"img":false}]}
{"op":"mcm","clk":"11449857223","pt":1717315354788,"mc":[{"id":"1.229554893","rc":[{"atb":[[2.38,18.95],[2.28,40.88],[2.18,79.81],[2.08,96.89]],"id":52671550}],"con":true,"img":false}]}
{"op":"mcm","clk":"11449857232","pt":1717315354894,"mc":[{"id":"1.229554893","rc":[{"atb":[[2.22,12.86],[2.2,0]],"id":52671550},{"atb":[[16.5,5.06],[15.5,4.15]],"id":52671546},{"atb":[[2.24,42.19],[2.26,12.45]],"id":52671548},{"atb":[[170,0]],"id":52671545},{"atb":[[32,2.96],[38,0]],"id":52671554},{"atb":[[32,4.14],[36,2.24]],"id":52671556}],"con":true,"img":false}]}
{"op":"mcm","clk":"11449858490","pt":1717315367587,"mc":[{"id":"1.229554893","rc":[{"atb":[[2.32,0],[2.12,0]],"id":52671550},{"atb":[[11,0],[8.4,0]],"id":52671546},{"atb":[[12,0],[8.8,0]],"id":52671549},{"atb":[[2.06,0],[1.93,0]],"id":52671548},{"atb":[[6.4,0],[5.2,0]],"id":52671542},{"atb":[[340,0],[240,0]],"id":52671545},{"atb":[[8,0],[10,0]],"id":52671544},{"atb":[[3.35,0],[2.94,0]],"id":52671555},{"atb":[[17.5,0],[12.5,0]],"id":52671554},{"atb":[[18,0],[13,0]],"id":52671556}],"con":true,"img":false}]}
{"op":"mcm","clk":"11449858890","pt":1717315371464,"mc":[{"id":"1.229554893","rc":[{"atb":[[1.2,0],[1.14,120.69]],"id":52671550}],"con":true,"img":false}]}
{"op":"mcm","clk":"11449858915","pt":1717315371778,"mc":[{"id":"1.229554893","rc":[{"atb":[[2.22,0],[2.38,0],[2.28,0],[2.12,14.01],[2.18,13.29],[2.08,0]],"id":52671550},{"atb":[[17,4.49],[15.5,0]],"id":52671546},{"atb":[[17,0],[19.5,0],[24,0],[29,0]],"id":52671549},{"atb":[[2.26,0],[2.14,82.61]],"id":52671548},{"atb":[[160,2.76]],"id":52671545},{"atb":[[4.3,12.68],[4.2,0]],"id":52671555},{"atb":[[32,0],[34,4.44]],"id":52671554},{"atb":[[32,0],[34,4.33]],"id":52671556}],"con":true,"img":false}]}
{"op":"mcm","clk":"11449858998","pt":1717315372495,"mc":[{"id":"1.229554893","rc":[{"atb":[[2,104.64],[2.3,20.12],[2.2,43.6],[2.1,71.34]],"id":52671550},{"atb":[[16.5,6.75],[19,4.36],[23,2.38],[28,0.97]],"id":52671549}],"con":true,"img":false}]}
{"op":"mcm","clk":"11449859539","pt":1717315378477,"mc":[{"id":"1.229554893","rc":[{"atb":[[2.32,79.18],[2.12,231.78]],"id":52671550},{"atb":[[13.5,8.36],[9.4,29.03]],"id":52671549},{"atb":[[3.35,44.48],[2.94,125.72]],"id":52671555},{"atb":[[18.5,5.97],[13.5,19.51]],"id":52671554},{"atb":[[19,5.8],[14,18.76]],"id":52671556}],"con":true,"img":false}]}
{"op":"mcm","clk":"11449859549","pt":1717315378584,"mc":[{"id":"1.229554893","rc":[{"atb":[[10.5,11],[8.2,33.87]],"id":52671546},{"atb":[[1.92,265.11],[2.04,201.13]],"id":52671548},{"atb":[[6.4,19.35],[5.2,58.07]],"id":52671542},{"atb":[[370,0.65],[470,0.22]],"id":52671545},{"atb":[[8,34.84],[10,11.61]],"id":52671544}],"con":true,"img":false}]}
{"op":"mcm","clk":"11449859840","pt":1717315381580,"mc":[{"id":"1.229554893","rc":[{"atl":[[50,0],[55,4.46]],"id":52671546},{"atl":[[55,3.29],[60,0]],"id":52671544},{"atl":[[150,3.74],[160,0]],"id":52671554},{"atl":[[140,0],[150,2.65]],"id":52671556}],"con":true,"img":false}]}
{"op":"mcm","clk":"11449859856","pt":1717315381784,"mc":[{"id":"1.229554893","rc":[{"atb":[[2.12,217.77],[2.18,0]],"id":52671550},{"atl":[[3.85,5.5],[3.7,0]],"id":52671550},{"atb":[[2.22,0],[2.1,14.26]],"id":52671548},{"atl":[[4,0],[3.95,5.32]],"id":52671548}],"con":true,"img":false}]}
{"op":"mcm","clk":"11449859906","pt":1717315382303,"mc":[{"id":"1.229554893","rc":[{"atb":[[2,0],[2.3,0],[2.2,0],[2.1,0]],"id":52671550},{"atb":[[16.5,8.31],[17,0]],"id":52671546},{"atb":[[16.5,0],[19,0],[23,0],[28,0]],"id":52671549},{"atb":[[2.24,54.85]],"id":52671548},{"atb":[[4.3,7.93],[4.4,2.91]],"id":52671555},{"atb":[[32,3.76],[34,0]],"id":52671556}],"con":true,"img":false}]}
{"op":"mcm","clk":"11449859971","pt":1717315383032,"mc":[{"id":"1.229554893","rc":[{"atb":[[1.99,105.69],[2.28,20.44],[2.18,44.34],[2.08,72.66]],"id":52671550},{"atb":[[16,6.97],[18.5,4.48],[22,2.49],[27,1]],"id":52671549}],"con":true,"img":false}]}
{"op":"mcm","clk":"11449860767","pt":1717315391506,"mc":[{"id":"1.229554893","rc":[{"atl":[[3.8,0]],"id":52671550},{"atb":[[16.5,5.06],[16,4.69]],"id":52671546},{"atb":[[2.1,0]],"id":52671548},{"atb":[[32,0],[34,3.74]],"id":52671556}],"con":true,"img":false}]}
{"op":"mcm","clk":"11449860777","pt":1717315391608,"mc":[{"id":"1.229554893","rc":[{"atb":[[30,7.52]],"id":52671554}],"con":true,"img":false}]}
{"op":"mcm","clk":"11449860788","pt":1717315391707,"mc":[{"id":"1.229554893","rc":[{"atl":[[3.95,5.32]],"id":52671550}],"con":true,"img":false}]}
{"op":"mcm","clk":"11449860845","pt":1717315392324,"mc":[{"id":"1.229554893","rc":[{"atb":[[2.2,13.07]],"id":52671548},{"atb":[[4.2,4.9]],"id":52671555}],"con":true,"img":false}]}
{"op":"mcm","clk":"11449860980","pt":1717315393724,"mc":[{"id":"1.229554893","rc":[{"atb":[[2.14,68.84]],"id":52671548},{"atb":[[4,0]],"id":52671555},{"atb":[[28,3.88]],"id":52671554}],"con":true,"img":false}]}
{"op":"mcm","clk":"11449861647","pt":1717315400415,"mc":[{"id":"1.229554893","rc":[{"atb":[[16.5,8.2],[16,0]],"id":52671546},{"atb":[[32,4.32],[34,0]],"id":52671556}],"con":true,"img":false}]}
{"op":"mcm","clk":"11449862098","pt":1717315405059,"mc":[{"id":"1.229554893","rc":[{"atb":[[16.5,5.06],[16,3.56]],"id":52671546},{"atb":[[32,0],[34,4.45]],"id":52671556}],"con":true,"img":false}]}
{"op":"mcm","clk":"11449862791","pt":1717315411871,"mc":[{"id":"1.229554893","rc":[{"atb":[[16.5,8.63],[16,0]],"id":52671546},{"atb":[[32,4.36],[34,0]],"id":52671556}],"con":true,"img":false}]}
{"op":"mcm","clk":"11449863294","pt":1717315416450,"mc":[{"id":"1.229554893","rc":[{"atb":[[16.5,5.06],[16,4.63]],"id":52671546},{"atb":[[32,0],[34,3.93]],"id":52671556}],"con":true,"img":false}]}
{"op":"mcm","clk":"11449864014","pt":1717315423307,"mc":[{"id":"1.229554893","rc":[{"atb":[[16.5,8.76],[16,0]],"id":52671546},{"atb":[[32,3.31],[34,0]],"id":52671556}],"con":true,"img":false}]}
{"op":"mcm","clk":"11449864468","pt":1717315427869,"mc":[{"id":"1.229554893","rc":[{"atb":[[16.5,5.06]],"id":52671546},{"atb":[[32,0],[34,3.62]],"id":52671556}],"con":true,"img":false}]}
{"op":"mcm","clk":"11449864475","pt":1717315427973,"mc":[{"id":"1.229554893","rc":[{"atb":[[16,2.68]],"id":52671546}],"con":true,"img":false}]}
{"op":"mcm","clk":"11449864501","pt":1717315428278,"mc":[{"id":"1.229554893","rc":[{"atb":[[1.19,151.86]],"id":52671550}],"con":true,"img":false}]}
{"op":"mcm","clk":"11449864512","pt":1717315428384,"mc":[{"id":"1.229554893","rc":[{"atb":[[1.14,0]],"id":52671550}],"con":true,"img":false}]}
{"op":"mcm","clk":"11449864529","pt":1717315428591,"mc":[{"id":"1.229554893","rc":[{"atb":[[2.22,12.86],[2.18,57.64]],"id":52671550},{"atb":[[15.5,3.47]],"id":52671546},{"atb":[[2.24,42.19],[2.26,12.45]],"id":52671548},{"atb":[[4.4,0]],"id":52671555},{"atb":[[32,3.91],[34,0]],"id":52671554},{"atb":[[32,3.98],[34,0]],"id":52671556}],"con":true,"img":false}]}
{"op":"mcm","clk":"11449864767","pt":1717315431073,"mc":[{"id":"1.229554893","rc":[{"atl":[[3.85,0],[3.7,5.81]],"id":52671550},{"atb":[[16,0]],"id":52671546},{"atl":[[50,2.69],[55,0]],"id":52671546},{"atl":[[4,5.23],[3.95,0]],"id":52671548},{"atl":[[55,0],[60,3.55]],"id":52671544},{"atl":[[9.8,0],[8.8,3.91]],"id":52671555},{"atl":[[150,0],[160,4.33]],"id":52671554},{"atl":[[140,3.75],[150,0]],"id":52671556}],"con":true,"img":false}]}
{"op":"mcm","clk":"11449865152","pt":1717315434688,"mc":[{"id":"1.229554893","rc":[{"atb":[[2.22,0],[2.18,44.34]],"id":52671550},{"atb":[[17,4.13],[15.5,0]],"id":52671546},{"atb":[[2.26,0],[2.14,82.61]],"id":52671548},{"atb":[[4.3,12.68]],"id":52671555},{"atb":[[32,0],[34,3.03]],"id":52671554},{"atb":[[32,0],[34,4.46]],"id":52671556}],"con":true,"img":false}]}
{"op":"mcm","clk":"11449865235","pt":1717315435517,"mc":[{"id":"1.229554893","rc":[{"atl":[[3.85,5.5]],"id":52671550},{"atl":[[50,0]],"id":52671546},{"atl":[[3.95,5.32]],"id":52671548},{"atl":[[9,3.21]],"id":52671555},{"atl":[[150,2.64]],"id":52671556}],"con":true,"img":false}]}
{"op":"mcm","clk":"11449865245","pt":1717315435575,"mc":[{"id":"1.229554893","rc":[{"atl":[[3.7,0]],"id":52671550},{"atl":[[55,4.61]],"id":52671546},{"atb":[[2.2,0]],"id":52671548},{"atl":[[4,0]],"id":52671548},{"atl":[[55,3.68],[60,0]],"id":52671544},{"atl":[[8.8,0]],"id":52671555},{"atl":[[150,4.04],[160,0]],"id":52671554},{"atl":[[140,0]],"id":52671556}],"con":true,"img":false}]}
{"op":"mcm","clk":"11449865631","pt":1717315439299,"mc":[{"id":"1.229554893","rc":[{"atb":[[2.22,12.86],[2.18,57.64]],"id":52671550},{"atb":[[2.26,12.45]],"id":52671548},{"atb":[[4.3,7.93]],"id":52671555},{"atb":[[32,4.51],[34,0]],"id":52671554},{"atb":[[32,2.68],[34,0]],"id":52671556}],"con":true,"img":false}]}
{"op":"mcm","clk":"11449865645","pt":1717315439403,"mc":[{"id":"1.229554893","rc":[{"atb":[[17,0],[15.5,2.87]],"id":52671546}],"con":true,"img":false}]}
{"op":"mcm","clk":"11449865777","pt":1717315440493,"mc":[{"id":"1.229554893","rc":[{"atl":[[50,4.33],[55,0]],"id":52671546},{"atl":[[55,0]],"id":52671544},{"atl":[[150,0]],"id":52671554},{"atl":[[140,4.5]],"id":52671556}],"con":true,"img":false}]}
{"op":"mcm","clk":"11449865787","pt":1717315440595,"mc":[{"id":"1.229554893","rc":[{"atl":[[60,3.89]],"id":52671544},{"atl":[[9,0],[8.6,3.31]],"id":52671555},{"atl":[[160,3.57]],"id":52671554},{"atl":[[150,0]],"id":52671556}],"con":true,"img":false}]}
{"op":"mcm","clk":"11449865831","pt":1717315441003,"mc":[{"id":"1.229554893","rc":[{"atl":[[3.85,0],[3.7,5.81]],"id":52671550},{"atl":[[4,5.23],[3.95,0]],"id":52671548}],"con":true,"img":false}]}
{"op":"mcm","clk":"11449866385","pt":1717315446043,"mc":[{"id":"1.229554893","rc":[{"atb":[[2.22,0],[2.18,44.34]],"id":52671550},{"atb":[[17,2.87],[15.5,0]],"id":52671546},{"atb":[[2.26,0]],"id":52671548},{"atb":[[4.3,12.68]],"id":52671555},{"atb":[[32,0],[34,4.02]],"id":52671554},{"atb":[[32,0],[34,3.27]],"id":52671556}],"con":true,"img":false}]}
{"op":"mcm","clk":"11449866717","pt":1717315449149,"mc":[{"id":"1.229554893","rc":[{"atl":[[3.85,5.5],[3.7,0]],"id":52671550},{"atl":[[50,0],[55,3.93]],"id":52671546},{"atl":[[4,0],[3.95,5.32]],"id":52671548},{"atl":[[55,3.76],[60,0]],"id":52671544},{"atl":[[9,3.69]],"id":52671555},{"atl":[[150,4.03],[160,0]],"id":52671554},{"atl":[[140,0],[150,3.86]],"id":52671556}],"con":true,"img":false}]}
{"op":"mcm","clk":"11449866731","pt":1717315449252,"mc":[{"id":"1.229554893","rc":[{"atl":[[8.6,0]],"id":52671555}],"con":true,"img":false}]}
{"op":"mcm","clk":"11449866920","pt":1717315451154,"mc":[{"id":"1.229554893","rc":[{"atb":[[2.2,13.07],[2.16,13.52]],"id":52671550},{"atb":[[16.5,8.43],[17,0]],"id":52671546},{"atb":[[2.24,54.85]],"id":52671548},{"atb":[[160,0],[170,2.64]],"id":52671545},{"atb":[[4.3,7.93]],"id":52671555},{"atb":[[65,0],[34,0],[36,0],[38,4.11],[46,0],[28,0]],"id":52671554},{"atb":[[65,0],[34,0],[36,2.62],[46,0],[28,3.4]],"id":52671556}],"con":true,"img":false}]}
{"op":"mcm","clk":"11449866944","pt":1717315451378,"mc":[{"id":"1.229554893","rc":[{"atb":[[34,3.03],[30,4.07]],"id":52671554},{"atb":[[34,3.03],[30,0]],"id":52671556}],"con":true,"img":false}]}
{"op":"mcm","clk":"11449867025","pt":1717315451978,"mc":[{"id":"1.229554893","rc":[{"atb":[[75,0.36],[40,2.01],[50,1.07],[30,7.69]],"id":52671554},{"atb":[[70,0.38],[38,2.12],[48,1.11],[29,3.74]],"id":52671556}],"con":true,"img":false}]}
{"op":"mcm","clk":"11449867592","pt":1717315457459,"mc":[{"id":"1.229554893","rc":[{"atb":[[2.2,0],[2.16,0]],"id":52671550},{"atl":[[3.85,0],[3.7,5.81]],"id":52671550},{"atb":[[16.5,5.06],[17,4]],"id":52671546},{"atl":[[50,2.89],[55,0]],"id":52671546},{"atb":[[2.24,42.19]],"id":52671548},{"atl":[[4,5.23],[3.95,0]],"id":52671548},{"atb":[[170,0]],"id":52671545},{"atl":[[55,0],[60,4.62]],"id":52671544},{"atb":[[4.3,12.68]],"id":52671555},{"atl":[[9,0],[8.6,3.25]],"id":52671555},{"atb":[[34,6.73],[38,0]],"id":52671554},{"atl":[[150,0],[160,4.07]],"id":52671554},{"atb":[[34,7.08],[36,0]],"id":52671556},{"atl":[[140,3.67],[150,0]],"id":52671556}],"con":true,"img":false}]}
{"op":"mcm","clk":"11449867638","pt":1717315457973,"mc":[{"id":"1.229554893","rc":[{"atb":[[75,0],[40,0],[50,0],[30,4.07]],"id":52671554},{"atb":[[70,0],[38,0],[48,0],[29,0]],"id":52671556}],"con":true,"img":false}]}
{"op":"mcm","clk":"11449867646","pt":1717315458075,"mc":[{"id":"1.229554893","rc":[{"atb":[[32,3.23],[34,3.7]],"id":52671554},{"atb":[[34,4.05],[30,3.45]],"id":52671556}],"con":true,"img":false}]}
{"op":"mcm","clk":"11449867693","pt":1717315458492,"mc":[{"id":"1.229554893","rc":[{"atb":[[2.18,57.64],[2.14,13.77]],"id":52671550},{"atl":[[3.85,5.5],[3.7,0]],"id":52671550},{"atb":[[16.5,8.48],[17,0]],"id":52671546},{"atl":[[50,0],[55,2.83]],"id":52671546},{"atb":[[2.22,12.86]],"id":52671548},{"atl":[[4,0],[3.95,5.32]],"id":52671548},{"atl":[[55,4.19],[60,0]],"id":52671544},{"atb":[[4.3,7.93]],"id":52671555},{"atl":[[8.6,0],[9,3.71]],"id":52671555},{"atl":[[150,3.25],[160,0]],"id":52671554},{"atb":[[32,4.47],[34,0]],"id":52671556},{"atl":[[140,0],[150,3.38]],"id":52671556}],"con":true,"img":false}]}
{"op":"mcm","clk":"11449867719","pt":1717315458650,"mc":[{"id":"1.229554893","rc":[{"atb":[[65,0.41],[36,2.24],[46,1.16],[28,3.88]],"id":52671554},{"atb":[[65,0.41],[36,2.24],[46,1.16],[28,7.28]],"id":52671556}],"con":true,"img":false}]}
{"op":"mcm","clk":"11449868129","pt":1717315462680,"mc":[{"id":"1.229554893","rc":[{"atl":[[50,3.43],[55,0]],"id":52671546},{"atl":[[55,0],[60,2.98]],"id":52671544},{"atl":[[9,0],[8.6,2.9]],"id":52671555},{"atl":[[150,0],[160,3.44]],"id":52671554},{"atl":[[140,4.21],[150,0]],"id":52671556}],"con":true,"img":false}]}
{"op":"mcm","clk":"11449868301","pt":1717315464383,"mc":[{"id":"1.229554893","rc":[{"atl":[[3.85,0],[3.7,5.81]],"id":52671550},{"atl":[[4,5.23]],"id":52671548}],"con":true,"img":false}]}
{"op":"mcm","clk":"11449868314","pt":1717315464489,"mc":[{"id":"1.229554893","rc":[{"atl":[[3.95,0]],"id":52671548}],"con":true,"img":false}]}
{"op":"mcm","clk":"11449869204","pt":1717315472700,"mc":[{"id":"1.229554893","rc":[{"atb":[[15.5,3.2]],"id":52671546},{"atb":[[4,5.23]],"id":52671555},{"atl":[[9,4.7]],"id":52671555}],"con":true,"img":false}]}
{"op":"mcm","clk":"11449869426","pt":1717315474406,"mc":[{"id":"1.229554893","rc":[{"atl":[[3.8,5.6]],"id":52671550},{"atb":[[2.18,13.29]],"id":52671548}],"con":true,"img":false}]}
{"op":"mcm","clk":"11449869973","pt":1717315479220,"mc":[{"id":"1.229554893","rc":[{"atl":[[3.95,0]],"id":52671550},{"atb":[[2.14,68.84]],"id":52671548},{"atl":[[10.5,0]],"id":52671555}],"con":true,"img":false}]}
{"op":"mcm","clk":"11449870307","pt":1717315482275,"mc":[{"id":"1.229554893","rc":[{"atb":[[14.5,0]],"id":52671546}],"con":true,"img":false}]}
{"op":"mcm","clk":"11449876912","pt":1717315546967,"mc":[{"id":"1.229554893","rc":[{"atl":[[55,3.57]],"id":52671546}],"con":true,"img":false}]}
{"op":"mcm","clk":"11449876924","pt":1717315547069,"mc":[{"id":"1.229554893","rc":[{"atl":[[50,0]],"id":52671546},{"atl":[[8.6,0],[8.8,3.41]],"id":52671555}],"con":true,"img":false}]}
{"op":"mcm","clk":"11449876970","pt":1717315547590,"mc":[{"id":"1.229554893","rc":[{"atb":[[2.18,44.34],[2.2,13.07]],"id":52671550},{"atb":[[2.24,54.85],[2.22,0]],"id":52671548},{"atb":[[170,3.99]],"id":52671545},{"atb":[[34,0],[38,3.78]],"id":52671554},{"atb":[[32,0],[36,6.13]],"id":52671556}],"con":true,"img":false}]}
{"op":"mcm","clk":"11449876986","pt":1717315547803,"mc":[{"id":"1.229554893","rc":[{"atb":[[2.22,12.86]],"id":52671550},{"atb":[[16.5,5.06]],"id":52671546},{"atb":[[2.26,12.45]],"id":52671548},{"atb":[[32,6.47]],"id":52671554}],"con":true,"img":false}]}
{"op":"mcm","clk":"11449877053","pt":1717315548375,"mc":[{"id":"1.229554893","rc":[{"atb":[[2.18,57.64]],"id":52671550},{"atb":[[2.24,42.19]],"id":52671548},{"atb":[[170,0]],"id":52671545},{"atb":[[34,3.54]],"id":52671554},{"atb":[[32,4.55]],"id":52671556}],"con":true,"img":false}]}
{"op":"mcm","clk":"11449877064","pt":1717315548475,"mc":[{"id":"1.229554893","rc":[{"atb":[[2.2,0]],"id":52671550},{"atb":[[2.22,12.86]],"id":52671548},{"atb":[[38,0]],"id":52671554},{"atb":[[36,2.24]],"id":52671556}],"con":true,"img":false}]}
{"op":"mcm","clk":"11449877313","pt":1717315551373,"mc":[{"id":"1.229554893","rc":[{"atb":[[2.14,0]],"id":52671550},{"atb":[[2.18,0]],"id":52671548},{"atb":[[34,0]],"id":52671554}],"con":true,"img":false}]}
{"op":"mcm","clk":"11449877828","pt":1717315557104,"mc":[{"id":"1.229554893","rc":[{"atb":[[14.5,3.54]],"id":52671546}],"con":true,"img":false}]}
{"op":"mcm","clk":"11449878842","pt":1717315567800,"mc":[{"id":"1.229554893","rc":[{"atb":[[2.32,0],[2.12,0]],"id":52671550},{"atb":[[10.5,0],[8.2,0]],"id":52671546},{"atb":[[13.5,0],[9.4,0]],"id":52671549},{"atb":[[1.92,0],[2.04,100.61]],"id":52671548},{"atb":[[6.4,0],[5.2,0]],"id":52671542},{"atb":[[370,0],[470,0]],"id":52671545},{"atb":[[8,0],[10,0]],"id":52671544},{"atb":[[3.35,0],[2.94,0]],"id":52671555},{"atb":[[18.5,0],[13.5,0]],"id":52671554},{"atb":[[19,0],[14,0]],"id":52671556}],"con":true,"img":false}]}
{"op":"mcm","clk":"11449878880","pt":1717315568216,"mc":[{"id":"1.229554893","rc":[{"atb":[[2.22,0]],"id":52671550},{"atl":[[3.7,0],[3.75,5.7]],"id":52671550},{"atb":[[16,4.01],[15.5,0]],"id":52671546},{"atb":[[2.26,0]],"id":52671548},{"atl":[[55,4.53],[60,0]],"id":52671544},{"atl":[[8.8,0]],"id":52671555},{"atb":[[32,3.23],[34,3.49]],"id":52671554},{"atl":[[140,0],[150,3.04]],"id":52671556}],"con":true,"img":false}]}
{"op":"mcm","clk":"11449879146","pt":1717315570920,"mc":[{"id":"1.229554893","rc":[{"atl":[[55,0]],"id":52671549},{"atb":[[160,3.68]],"id":52671545},{"atl":[[55,0],[60,3.74]],"id":52671544},{"atl":[[160,0],[170,3.87]],"id":52671554}],"con":true,"img":false}]}
{"op":"mcm","clk":"11449879262","pt":1717315572117,"mc":[{"id":"1.229554893","rc":[{"atl":[[70,4.12]],"id":52671549},{"atb":[[2.18,13.29]],"id":52671548},{"atl":[[9.4,3.5]],"id":52671555}],"con":true,"img":false}]}
{"op":"mcm","clk":"11449879553","pt":1717315574710,"mc":[{"id":"1.229554893","rc":[{"atb":[[2.12,14.01],[2.18,44.34]],"id":52671550},{"atl":[[3.75,0]],"id":52671550},{"atb":[[16.5,8.1],[16,0]],"id":52671546},{"atb":[[2.22,0],[2.16,13.52]],"id":52671548},{"atb":[[4.3,12.68],[4.2,0]],"id":52671555},{"atb":[[32,0],[34,3.74]],"id":52671556},{"atl":[[150,0]],"id":52671556}],"con":true,"img":false}]}
{"op":"mcm","clk":"11449879825","pt":1717315577617,"mc":[{"id":"1.229554893","rc":[{"atb":[[16.5,5.06]],"id":52671546},{"atb":[[2.18,0]],"id":52671548},{"atb":[[4.3,7.93]],"id":52671555},{"atb":[[34,0]],"id":52671556}],"con":true,"img":false}]}
{"op":"mcm","clk":"11449879963","pt":1717315578818,"mc":[{"id":"1.229554893","rc":[{"atb":[[2.18,57.64]],"id":52671550},{"atb":[[16.5,7.98],[16,3.84]],"id":52671546},{"atb":[[2.22,12.86]],"id":52671548},{"atb":[[4.3,12.68],[4.2,4.9]],"id":52671555},{"atb":[[32,3.44],[34,3.09]],"id":52671556}],"con":true,"img":false}]}
{"op":"mcm","clk":"11449879984","pt":1717315579023,"mc":[{"id":"1.229554893","rc":[{"atl":[[3.75,5.7]],"id":52671550},{"atl":[[150,4.3]],"id":52671556}],"con":true,"img":false}]}
{"op":"mcm","clk":"11449880198","pt":1717315581346,"mc":[{"id":"1.229554893","rc":[{"atb":[[16.5,5.06]],"id":52671546},{"atb":[[4.3,7.93]],"id":52671555},{"atb":[[34,0]],"id":52671556}],"con":true,"img":false}]}
{"op":"mcm","clk":"11449880508","pt":1717315583909,"mc":[{"id":"1.229554893","rc":[{"atb":[[2.18,44.34]],"id":52671550},{"atl":[[3.75,0]],"id":52671550},{"atb":[[16.5,8.63],[16,0]],"id":52671546},{"atb":[[2.22,0]],"id":52671548},{"atb":[[4.3,12.68],[4.2,0]],"id":52671555},{"atb":[[32,0],[34,2.93]],"id":52671556},{"atl":[[150,0]],"id":52671556}],"con":true,"img":false}]}
{"op":"mcm","clk":"11449880677","pt":1717315585660,"mc":[{"id":"1.229554893","rc":[{"atb":[[2.18,57.64]],"id":52671550},{"atl":[[3.75,5.7]],"id":52671550},{"atb":[[16.5,5.06],[16,3.17]],"id":52671546},{"atb":[[2.22,12.86]],"id":52671548},{"atb":[[4.3,7.93],[4.2,4.9]],"id":52671555},{"atb":[[32,4.36],[34,0]],"id":52671556},{"atl":[[150,3.27]],"id":52671556}],"con":true,"img":false}]}
{"op":"mcm","clk":"11449880827","pt":1717315587011,"mc":[{"id":"1.229554893","rc":[{"atb":[[2.18,44.34]],"id":52671550},{"atb":[[16.5,8.85],[16,0]],"id":52671546},{"atb":[[2.22,0]],"id":52671548},{"atb":[[4.3,12.68],[4.2,0]],"id":52671555},{"atb":[[32,0],[34,4.37]],"id":52671556}],"con":true,"img":false}]}
{"op":"mcm","clk":"11449880945","pt":1717315588312,"mc":[{"id":"1.229554893","rc":[{"atb":[[1.19,0],[1.05,117.01]],"id":52671550},{"atb":[[1.21,0],[1.07,111.04]],"id":52671548},{"atb":[[2.6,62.5],[2.48,0]],"id":52671555},{"atb":[[32,0],[36,5.1]],"id":52671554}],"con":true,"img":false}]}
{"op":"mcm","clk":"11449880979","pt":1717315588621,"mc":[{"id":"1.229554893","rc":[{"atb":[[1.99,0],[2.28,0],[2.12,0],[2.18,0],[1.94,16.69],[2.08,0]],"id":52671550},{"atb":[[16.5,5.06],[18,2.74]],"id":52671546},{"atb":[[2.24,0],[2.04,0],[2.16,0],[2.14,0],[2.34,0]],"id":52671548},{"atb":[[9.6,0],[8.6,0],[11.5,0],[7.6,0]],"id":52671542},{"atb":[[160,0],[170,3.5]],"id":52671545},{"atl":[[55,4.13],[60,0]],"id":52671544},{"atb":[[4.3,7.93],[4.5,3.05]],"id":52671555},{"atb":[[65,0],[34,0],[36,2.86],[40,3.28],[46,0],[28,0]],"id":52671554},{"atb":[[65,0],[36,0],[38,3.24],[46,0],[28,3.4]],"id":52671556}],"con":true,"img":false}]}
{"op":"mcm","clk":"11449880987","pt":1717315588725,"mc":[{"id":"1.229554893","rc":[{"atb":[[34,0]],"id":52671556}],"con":true,"img":false}]}
{"op":"mcm","clk":"11449881000","pt":1717315588832,"mc":[{"id":"1.229554893","rc":[{"atb":[[34,3.03],[30,0]],"id":52671556}],"con":true,"img":false}]}
{"op":"mcm","clk":"11449881065","pt":1717315589347,"mc":[{"id":"1.229554893","rc":[{"atb":[[2.02,51.29],[2.12,23.35],[1.91,114.98],[1.96,81.75]],"id":52671550},{"atb":[[2.06,49.36],[1.98,80.08],[1.93,112.51],[2.16,22.55]],"id":52671548},{"atb":[[11,2.62],[7.4,16.35],[8.4,10.61],[9.4,6.23]],"id":52671542},{"atb":[[75,0.36],[40,5.29],[50,1.07],[30,7.69]],"id":52671554},{"atb":[[75,0.36],[40,2.01],[50,1.07],[30,3.61]],"id":52671556}],"con":true,"img":false}]}
{"op":"mcm","clk":"11449881220","pt":1717315590865,"mc":[{"id":"1.229554893","rc":[{"atb":[[1.97,16.18],[1.95,16.52]],"id":52671548}],"con":true,"img":false}]}
{"op":"mcm","clk":"11449881383","pt":1717315592435,"mc":[{"id":"1.229554893","rc":[{"atl":[[60,2.89]],"id":52671544},{"atl":[[150,0]],"id":52671556}],"con":true,"img":false}]}
{"op":"mcm","clk":"11449881393","pt":1717315592538,"mc":[{"id":"1.229554893","rc":[{"atl":[[3.75,0]],"id":52671550},{"atl":[[4,0]],"id":52671548},{"atl":[[55,0]],"id":52671544}],"con":true,"img":false}]}
{"op":"mcm","clk":"11449881429","pt":1717315592949,"mc":[{"id":"1.229554893","rc":[{"atl":[[9,0],[9.2,4.54]],"id":52671555}],"con":true,"img":false}]}
{"op":"mcm","clk":"11449881578","pt":1717315594348,"mc":[{"id":"1.229554893","rc":[{"atl":[[3.75,5.7]],"id":52671550},{"atl":[[4,5.23]],"id":52671548}],"con":true,"img":false}]}
{"op":"mcm","clk":"11449881723","pt":1717315595857,"mc":[{"id":"1.229554893","rc":[{"atl":[[3.75,0]],"id":52671550},{"atl":[[4,0]],"id":52671548},{"atl":[[9,4.63],[9.2,0]],"id":52671555}],"con":true,"img":false}]}
{"op":"mcm","clk":"11449881959","pt":1717315598551,"mc":[{"id":"1.229554893","rc":[{"atb":[[17,2.67]],"id":52671546},{"atb":[[150,4.44]],"id":52671545},{"atb":[[36,6.94]],"id":52671554},{"atb":[[34,5.71]],"id":52671556},{"atl":[[180,3.31]],"id":52671556}],"con":true,"img":false}]}
{"op":"mcm","clk":"11449882012","pt":1717315599171,"mc":[{"id":"1.229554893","rc":[{"atl":[[3.75,5.7]],"id":52671550},{"atl":[[4,5.23]],"id":52671548},{"atl":[[9,0],[9.2,4.29]],"id":52671555}],"con":true,"img":false}]}
{"op":"mcm","clk":"11449882031","pt":1717315599329,"mc":[{"id":"1.229554893","rc":[{"atb":[[30,3.61]],"id":52671554},{"atb":[[28,0]],"id":52671556}],"con":true,"img":false}]}
{"op":"mcm","clk":"11449882342","pt":1717315602459,"mc":[{"id":"1.229554893","rc":[{"atb":[[14.5,0]],"id":52671546},{"atb":[[130,0]],"id":52671545}],"con":true,"img":false}]}
{"op":"mcm","clk":"11449882787","pt":1717315606665,"mc":[{"id":"1.229554893","rc":[{"atl":[[3.75,0]],"id":52671550},{"atl":[[55,0],[60,4.31]],"id":52671546},{"atl":[[4,0]],"id":52671548},{"atl":[[9.2,0]],"id":52671555},{"atl":[[170,0]],"id":52671554},{"atl":[[160,0],[170,3.33]],"id":52671556}],"con":true,"img":false}]}
{"op":"mcm","clk":"11449882928","pt":1717315608060,"mc":[{"id":"1.229554893","rc":[{"atl":[[55,3.38]],"id":52671549}],"con":true,"img":false}]}
{"op":"mcm","clk":"11449882939","pt":1717315608163,"mc":[{"id":"1.229554893","rc":[{"atl":[[3.75,5.7]],"id":52671550},{"atl":[[60,0]],"id":52671549},{"atl":[[3.95,5.32]],"id":52671548},{"atl":[[65,3.04],[60,0]],"id":52671544},{"atl":[[170,2.88]],"id":52671554},{"atl":[[160,3.51],[170,0]],"id":52671556}],"con":true,"img":false}]}
{"op":"mcm","clk":"11449883008","pt":1717315608841,"mc":[{"id":"1.229554893","rc":[{"atl":[[70,0]],"id":52671549}],"con":true,"img":false}]}
{"op":"mcm","clk":"11449883045","pt":1717315609147,"mc":[{"id":"1.229554893","rc":[{"atb":[[4.3,12.68]],"id":52671555},{"atl":[[9.8,4.35]],"id":52671555}],"con":true,"img":false}]}
{"op":"mcm","clk":"11449883157","pt":1717315610080,"mc":[{"id":"1.229554893","rc":[{"atl":[[3.7,5.81],[3.75,0]],"id":52671550},{"atb":[[4,0]],"id":52671555}],"con":true,"img":false}]}
{"op":"mcm","clk":"11449883318","pt":1717315611336,"mc":[{"id":"1.229554893","rc":[{"atl":[[3.95,0]],"id":52671548},{"atl":[[9.6,4.42],[9.4,0]],"id":52671555}],"con":true,"img":false}]}
{"op":"mcm","clk":"11449883474","pt":1717315612880,"mc":[{"id":"1.229554893","rc":[{"atb":[[2.32,79.18],[2.12,241.13]],"id":52671550},{"atb":[[10.5,11],[8.2,33.87]],"id":52671546},{"atb":[[13.5,8.36],[9.4,29.03]],"id":52671549},{"atb":[[1.92,265.11],[2.04,100.51]],"id":52671548},{"atb":[[6.4,19.35],[5.2,58.07]],"id":52671542},{"atb":[[370,0.65],[470,0.22]],"id":52671545},{"atb":[[8,34.84],[10,11.61]],"id":52671544},{"atb":[[3.35,44.48],[2.94,125.72]],"id":52671555},{"atb":[[18.5,5.97],[13.5,19.51]],"id":52671554},{"atb":[[19,5.8],[14,18.76]],"id":52671556}],"con":true,"img":false}]}
{"op":"mcm","clk":"11449883991","pt":1717315618151,"mc":[{"id":"1.229554893","rc":[{"atl":[[65,2.88]],"id":52671549},{"atl":[[4.3,4.75]],"id":52671548}],"con":true,"img":false}]}
{"op":"mcm","clk":"11449885280","pt":1717315630378,"mc":[{"id":"1.229554893","rc":[{"atl":[[3.7,0],[3.75,5.7]],"id":52671550},{"atl":[[65,0]],"id":52671544},{"atl":[[9.6,0]],"id":52671555},{"atl":[[170,0]],"id":52671554},{"atl":[[160,0],[170,3.37]],"id":52671556}],"con":true,"img":false}]}
{"op":"mcm","clk":"11449885287","pt":1717315630477,"mc":[{"id":"1.229554893","rc":[{"atl":[[60,0]],"id":52671546}],"con":true,"img":false}]}
{"op":"mcm","clk":"11449885431","pt":1717315631882,"mc":[{"id":"1.229554893","rc":[{"atl":[[3.6,6.03],[3.75,0]],"id":52671550},{"atl":[[55,0],[60,4.68]],"id":52671549},{"atb":[[2.06,0],[1.98,0],[1.97,0],[1.96,16.34],[1.93,0],[2.16,0]],"id":52671548},{"atl":[[3.95,5.32],[4.1,0],[3.9,5.4]],"id":52671548},{"atl":[[21,0],[22,3.34]],"id":52671542},{"atb":[[4.5,0],[4.6,4.29]],"id":52671555},{"atb":[[38,3.17],[40,2.01]],"id":52671554},{"atl":[[180,0],[190,4.46]],"id":52671554}],"con":true,"img":false}]}
{"op":"mcm","clk":"11449885449","pt":1717315632084,"mc":[{"id":"1.229554893","rc":[{"atl":[[3.7,5.81],[3.65,5.92]],"id":52671550},{"atl":[[10,3.15],[9.8,0]],"id":52671555},{"atl":[[170,0]],"id":52671556}],"con":true,"img":false}]}
{"op":"mcm","clk":"11449885571","pt":1717315633275,"mc":[{"id":"1.229554893","rc":[{"atb":[[1.92,378.85],[1.97,80.9],[2.04,150.82],[2.14,22.95]],"id":52671548}],"con":true,"img":false}]}
{"op":"mcm","clk":"11449885858","pt":1717315635873,"mc":[{"id":"1.229554893","rc":[{"atb":[[2.6,0],[2.76,56.82]],"id":52671555}],"con":true,"img":false}]}
{"op":"mcm","clk":"11449885902","pt":1717315636288,"mc":[{"id":"1.229554893","rc":[{"atb":[[4.6,0],[4.7,3.2]],"id":52671555},{"atl":[[170,3.67]],"id":52671556}],"con":true,"img":false}]}
{"op":"mcm","clk":"11449885925","pt":1717315636498,"mc":[{"id":"1.229554893","rc":[{"atl":[[3.6,0],[3.7,0],[3.8,0]],"id":52671550},{"atl":[[55,2.84],[60,0]],"id":52671549},{"atb":[[2.02,15.38],[1.96,0]],"id":52671548},{"atl":[[4.3,0],[3.95,0]],"id":52671548},{"atb":[[11,0],[7.4,0],[8.4,0],[9.4,0]],"id":52671542},{"atb":[[38,0],[40,5.99]],"id":52671554}],"con":true,"img":false}]}
{"op":"mcm","clk":"11449885947","pt":1717315636707,"mc":[{"id":"1.229554893","rc":[{"atb":[[17.5,2.76],[18,0]],"id":52671546},{"atb":[[2,15.69]],"id":52671548},{"atb":[[4.5,4.56]],"id":52671555}],"con":true,"img":false}]}
{"op":"mcm","clk":"11449885997","pt":1717315637173,"mc":[{"id":"1.229554893","rc":[{"atb":[[11.5,0],[15.5,6.9]],"id":52671546},{"atb":[[11,2.62],[7.4,16.35],[8.4,10.61],[9.4,6.23]],"id":52671542}],"con":true,"img":false}]}
{"op":"mcm","clk":"11449886028","pt":1717315637484,"mc":[{"id":"1.229554893","rc":[{"atl":[[3.7,5.81]],"id":52671550},{"atb":[[17.5,0],[20,3.97]],"id":52671546},{"atl":[[55,0],[60,4.59]],"id":52671549},{"atb":[[1.92,265.11],[2.02,0],[1.97,0],[2.04,100.51],[2.14,0]],"id":52671548},{"atl":[[21,3.84],[22,0]],"id":52671542},{"atb":[[170,0],[180,4.58]],"id":52671545},{"atl":[[65,3.21]],"id":52671544},{"atb":[[4.7,0]],"id":52671555},{"atl":[[10,0],[10.5,4]],"id":52671555},{"atb":[[38,4.54],[40,2.01]],"id":52671554},{"atl":[[170,0]],"id":52671556}],"con":true,"img":false}]}
{"op":"mcm","clk":"11449886040","pt":1717315637592,"mc":[{"id":"1.229554893","rc":[{"atl":[[3.6,6.03],[3.65,0]],"id":52671550},{"atl":[[65,0],[70,3.89]],"id":52671546},{"atb":[[2,0],[1.95,0]],"id":52671548},{"atl":[[3.8,5.6]],"id":52671548},{"atl":[[70,0],[75,3.36]],"id":52671544},{"atl":[[190,0],[200,3.31]],"id":52671554}],"con":true,"img":false}]}
{"op":"mcm","clk":"11449886100","pt":1717315638167,"mc":[{"id":"1.229554893","rc":[{"atb":[[2.02,51.29],[2.12,23.35],[1.91,114.98],[1.96,81.75]],"id":52671548}],"con":true,"img":false}]}
{"op":"mcm","clk":"11449886151","pt":1717315638689,"mc":[{"id":"1.229554893","rc":[{"atl":[[65,3.17]],"id":52671546},{"atl":[[55,4.22],[60,0]],"id":52671549},{"atl":[[65,0],[70,3.7]],"id":52671544}],"con":true,"img":false}]}
{"op":"mcm","clk":"11449886361","pt":1717315641012,"mc":[{"id":"1.229554893","rc":[{"atb":[[2.62,61.73],[2.76,0]],"id":52671555}],"con":true,"img":false}]}
{"op":"mcm","clk":"11449886565","pt":1717315642919,"mc":[{"id":"1.229554893","rc":[{"atb":[[2.32,0],[2.12,23.35]],"id":52671550},{"atb":[[10.5,0],[8.2,0]],"id":52671546},{"atb":[[13.5,0],[9.4,0]],"id":52671549},{"atb":[[1.92,0],[2.04,0]],"id":52671548},{"atb":[[6.4,0],[5.2,0]],"id":52671542},{"atb":[[370,0],[470,0]],"id":52671545},{"atb":[[8,0],[10,0]],"id":52671544},{"atb":[[3.35,0],[2.94,0]],"id":52671555},{"atb":[[18.5,0],[13.5,0]],"id":52671554},{"atb":[[19,0],[14,0]],"id":52671556}],"con":true,"img":false}]}
{"op":"mcm","clk":"11449886576","pt":1717315643026,"mc":[{"id":"1.229554893","rc":[{"atb":[[18,3.92],[20,0]],"id":52671546},{"atb":[[1.97,16.18],[1.95,16.52]],"id":52671548},{"atb":[[180,0]],"id":52671545},{"atb":[[38,0],[40,5.07]],"id":52671554}],"con":true,"img":false}]}
{"op":"mcm","clk":"11449886909","pt":1717315646220,"mc":[{"id":"1.229554893","rc":[{"atl":[[3.6,0]],"id":52671550},{"atb":[[18,0],[20,3.91]],"id":52671546},{"atb":[[1.94,16.69]],"id":52671548},{"atl":[[21,0],[22,2.82]],"id":52671542},{"atb":[[180,2.89]],"id":52671545},{"atl":[[10,3.13]],"id":52671555},{"atb":[[38,3.68],[40,2.01]],"id":52671554},{"atl":[[190,3.35]],"id":52671554},{"atl":[[200,3.79]],"id":52671556}],"con":true,"img":false}]}
{"op":"mcm","clk":"11449886917","pt":1717315646281,"mc":[{"id":"1.229554893","rc":[{"atb":[[1.97,0]],"id":52671548},{"atl":[[3.8,0]],"id":52671548}],"con":true,"img":false}]}
{"op":"mcm","clk":"11449887060","pt":1717315647581,"mc":[{"id":"1.229554893","rc":[{"atb":[[1.92,17.06]],"id":52671550},{"atl":[[3.6,6.03]],"id":52671550}],"con":true,"img":false}]}
{"op":"mcm","clk":"11449887193","pt":1717315648709,"mc":[{"id":"1.229554893","rc":[{"atl":[[70,0],[85,3.84]],"id":52671544}],"con":true,"img":false}]}
{"op":"mcm","clk":"11449887322","pt":1717315650011,"mc":[{"id":"1.229554893","rc":[{"atb":[[18,4.06],[20,0]],"id":52671546},{"atl":[[65,0]],"id":52671546},{"atb":[[1.97,16.18],[1.95,0]],"id":52671548},{"atl":[[3.8,5.6]],"id":52671548},{"atl":[[21,4.37],[22,0]],"id":52671542},{"atb":[[170,4.27],[180,0]],"id":52671545},{"atl":[[10,0]],"id":52671555},{"atb":[[38,0],[40,6.49]],"id":52671554},{"atl":[[190,0]],"id":52671554}],"con":true,"img":false}]}
{"op":"mcm","clk":"11449887344","pt":1717315650218,"mc":[{"id":"1.229554893","rc":[{"atl":[[3.6,0]],"id":52671550},{"atl":[[70,4.33],[75,0]],"id":52671544}],"con":true,"img":false}]}
{"op":"mcm","clk":"11449887414","pt":1717315651001,"mc":[{"id":"1.229554893","rc":[{"atl":[[65,3.11]],"id":52671546},{"atl":[[3.8,0]],"id":52671548},{"atl":[[21,0],[22,4.26]],"id":52671542},{"atl":[[10,4.7]],"id":52671555},{"atl":[[190,3.87]],"id":52671554}],"con":true,"img":false}]}
{"op":"mcm","clk":"11449887510","pt":1717315652132,"mc":[{"id":"1.229554893","rc":[{"atb":[[2.02,0],[2.12,0],[1.91,17.24],[1.96,0],[1.94,0]],"id":52671550},{"atb":[[17.5,4.35],[18,0]],"id":52671546},{"atb":[[1.97,0],[2.04,15.09]],"id":52671548},{"atb":[[4.5,0],[4.6,3.46]],"id":52671555},{"atb":[[75,0],[40,0],[50,0],[30,0]],"id":52671556}],"con":true,"img":false}]}
{"op":"mcm","clk":"11449887525","pt":1717315652292,"mc":[{"id":"1.229554893","rc":[{"atl":[[3.6,6.03]],"id":52671550},{"atl":[[55,0]],"id":52671549},{"atl":[[10,0],[9.8,4.26]],"id":52671555},{"atl":[[190,0],[210,3.76]],"id":52671554},{"atl":[[180,0],[190,2.67]],"id":52671556}],"con":true,"img":false}]}
{"op":"mcm","clk":"11449887574","pt":1717315652807,"mc":[{"id":"1.229554893","rc":[{"atb":[[2.02,51.29],[1.91,132.23],[2.12,23.35],[1.96,81.75]],"id":52671550},{"atb":[[75,0.36],[40,2.01],[50,1.07],[30,3.61]],"id":52671556}],"con":true,"img":false}]}
{"op":"mcm","clk":"11449887658","pt":1717315653583,"mc":[{"id":"1.229554893","rc":[{"atb":[[1.92,0]],"id":52671550},{"atl":[[3.6,0]],"id":52671550},{"atl":[[10,2.79],[9.8,0]],"id":52671555},{"atl":[[200,0]],"id":52671554}],"con":true,"img":false}]}
{"op":"mcm","clk":"11449887920","pt":1717315656016,"mc":[{"id":"1.229554893","rc":[{"atl":[[3.6,6.03]],"id":52671550},{"atl":[[9.8,2.95]],"id":52671555}],"con":true,"img":false}]}
{"op":"mcm","clk":"11449887931","pt":1717315656120,"mc":[{"id":"1.229554893","rc":[{"atl":[[10,0]],"id":52671555}],"con":true,"img":false}]}
{"op":"mcm","clk":"11449888014","pt":1717315657106,"mc":[{"id":"1.229554893","rc":[{"atb":[[2.62,0],[2.76,56.82]],"id":52671555}],"con":true,"img":false}]}
{"op":"mcm","clk":"11449888044","pt":1717315657413,"mc":[{"id":"1.229554893","rc":[{"atb":[[1.96,98.1]],"id":52671550},{"atl":[[3.6,0],[3.55,6.15]],"id":52671550},{"atb":[[17.5,0],[18,3.72]],"id":52671546},{"atb":[[2.02,66.68],[2.04,0]],"id":52671548},{"atb":[[11,0],[7.4,0],[8.4,0],[9.4,0]],"id":52671542},{"atb":[[4.6,0],[4.7,4.52]],"id":52671555}],"con":true,"img":false}]}
{"op":"mcm","clk":"11449888056","pt":1717315657516,"mc":[{"id":"1.229554893","rc":[{"atl":[[3.65,5.92]],"id":52671550},{"atl":[[60,3.77]],"id":52671549},{"atl":[[3.85,5.5]],"id":52671548},{"atl":[[10,3.71],[9.8,0]],"id":52671555}],"con":true,"img":false}]}
{"op":"mcm","clk":"11449888108","pt":1717315658084,"mc":[{"id":"1.229554893","rc":[{"atb":[[7.2,16.88],[9.2,6.38],[10.5,2.75],[8.2,10.9]],"id":52671542}],"con":true,"img":false}]}
{"op":"mcm","clk":"11449888277","pt":1717315659736,"mc":[{"id":"1.229554893","rc":[{"atb":[[1.96,81.75]],"id":52671550},{"atl":[[3.55,0],[3.65,0]],"id":52671550},{"atb":[[17.5,3.05],[18,0]],"id":52671546},{"atb":[[2.02,51.29],[2.04,15.09]],"id":52671548},{"atl":[[3.85,0]],"id":52671548},{"atb":[[4.6,4.59],[4.7,0]],"id":52671555},{"atl":[[200,3.36]],"id":52671554},{"atb":[[75,0],[40,0],[50,0],[30,0]],"id":52671556}],"con":true,"img":false}]}
{"op":"mcm","clk":"11449888310","pt":1717315659991,"mc":[{"id":"1.229554893","rc":[{"atl":[[3.6,6.03]],"id":52671550},{"atl":[[3.95,5.32]],"id":52671548},{"atl":[[10,0],[9.8,3.58]],"id":52671555}],"con":true,"img":false}]}
{"op":"mcm","clk":"11449888328","pt":1717315660199,"mc":[{"id":"1.229554893","rc":[{"atl":[[180,3.7]],"id":52671556}],"con":true,"img":false}]}
{"op":"mcm","clk":"11449888351","pt":1717315660411,"mc":[{"id":"1.229554893","rc":[{"atb":[[75,0.36],[40,2.01],[50,1.07],[30,3.61]],"id":52671556},{"atl":[[190,0]],"id":52671556}],"con":true,"img":false}]}
{"op":"mcm","clk":"11449888914","pt":1717315666425,"mc":[{"id":"1.229554893","rc":[{"atb":[[15.5,0]],"id":52671546}],"con":true,"img":false}]}
{"op":"mcm","clk":"11449888925","pt":1717315666526,"mc":[{"id":"1.229554893","rc":[{"atb":[[13,6.1]],"id":52671546}],"con":true,"img":false}]}
{"op":"mcm","clk":"11449888932","pt":1717315666626,"mc":[{"id":"1.229554893","rc":[{"atl":[[200,0]],"id":52671554}],"con":true,"img":false}]}
{"op":"mcm","clk":"11449888942","pt":1717315666737,"mc":[{"id":"1.229554893","rc":[{"atb":[[1.94,16.69]],"id":52671550},{"atl":[[3.6,0],[3.65,5.92]],"id":52671550},{"atb":[[17.5,0]],"id":52671546},{"atl":[[3.85,5.5],[3.9,0]],"id":52671548},{"atb":[[7.2,0],[9.2,0],[10.5,0],[8.2,0]],"id":52671542},{"atl":[[21,3.52],[22,0]],"id":52671542},{"atb":[[160,3.86],[170,0]],"id":52671545},{"atb":[[4.6,0],[4.7,2.67]],"id":52671555},{"atl":[[10,4.12],[9.8,0]],"id":52671555},{"atl":[[180,0],[190,2.63]],"id":52671556}],"con":true,"img":false}]}
{"op":"mcm","clk":"11449889019","pt":1717315667538,"mc":[{"id":"1.229554893","rc":[{"atb":[[8,11.21],[9,6.54],[10,2.91],[7,17.44]],"id":52671542}],"con":true,"img":false}]}
{"op":"mcm","clk":"11449889240","pt":1717315669727,"mc":[{"id":"1.229554893","rc":[{"atb":[[16,3.63]],"id":52671546},{"atl":[[230,3.78]],"id":52671554}],"con":true,"img":false}]}
{"op":"mcm","clk":"11449889542","pt":1717315673046,"mc":[{"id":"1.229554893","rc":[{"atb":[[2,243.9],[2.2,87.1]],"id":52671550},{"atb":[[12,9.5],[8.8,31.27]],"id":52671546},{"atb":[[9.2,29.74],[13,8.71]],"id":52671549},{"atb":[[1.98,106.66],[1.88,277.16]],"id":52671548},{"atb":[[5,60.97],[6,20.9]],"id":52671542},{"atb":[[570,0.18],[470,0.51]],"id":52671545},{"atb":[[11,10.45],[8.4,32.96]],"id":52671544},{"atb":[[3.55,40.99],[3.05,118.97]],"id":52671555},{"atb":[[19.5,5.65],[14.5,18.06]],"id":52671554},{"atb":[[20,5.5],[15,17.42]],"id":52671556}],"con":true,"img":false}]}
{"op":"mcm","clk":"11449889590","pt":1717315673518,"mc":[{"id":"1.229554893","rc":[{"atl":[[200,2.97]],"id":52671554}],"con":true,"img":false}]}
{"op":"mcm","clk":"11449889598","pt":1717315673616,"mc":[{"id":"1.229554893","rc":[{"atl":[[210,0]],"id":52671554}],"con":true,"img":false}]}
{"op":"mcm","clk":"11449889765","pt":1717315675219,"mc":[{"id":"1.229554893","rc":[{"atl":[[55,4.27],[60,0]],"id":52671549},{"atl":[[3.85,0],[3.9,5.4]],"id":52671548},{"atl":[[19.5,2.86],[21,0]],"id":52671542},{"atl":[[65,3.24],[70,0]],"id":52671544},{"atl":[[190,4.55],[200,0]],"id":52671554},{"atl":[[180,3.47],[190,0]],"id":52671556}],"con":true,"img":false}]}
{"op":"mcm","clk":"11449889903","pt":1717315676721,"mc":[{"id":"1.229554893","rc":[{"atb":[[4.5,4.66]],"id":52671555}],"con":true,"img":false}]}
{"op":"mcm","clk":"11449890397","pt":1717315681430,"mc":[{"id":"1.229554893","rc":[{"atb":[[4.3,7.93]],"id":52671555}],"con":true,"img":false}]}
{"op":"mcm","clk":"11449890806","pt":1717315685269,"mc":[{"id":"1.229554893","rc":[{"atb":[[2,15.69]],"id":52671548},{"atl":[[21,4.24]],"id":52671542},{"atl":[[75,3.3]],"id":52671544},{"atl":[[210,3.75]],"id":52671554}],"con":true,"img":false}]}
{"op":"mcm","clk":"11449891155","pt":1717315688434,"mc":[{"id":"1.229554893","rc":[{"atb":[[1.94,0]],"id":52671548},{"atl":[[24,0]],"id":52671542},{"atl":[[85,0]],"id":52671544},{"atl":[[230,0]],"id":52671554}],"con":true,"img":false}]}
{"op":"mcm","clk":"11449891185","pt":1717315688747,"mc":[{"id":"1.229554893","rc":[{"atb":[[1.12,133.05],[1.07,0]],"id":52671548},{"atb":[[36,4.08],[50,3.11]],"id":52671554},{"atb":[[34,2.68],[46,2.22]],"id":52671556}],"con":true,"img":false}]}
{"op":"mcm","clk":"11449891215","pt":1717315689056,"mc":[{"id":"1.229554893","rc":[{"atb":[[1.91,114.98],[1.94,0]],"id":52671550},{"atl":[[3.65,0]],"id":52671550},{"atb":[[16.5,8.98],[17,0]],"id":52671546},{"atb":[[2.06,14.8],[2.04,0]],"id":52671548},{"atb":[[8,0],[9,0],[10,0],[7,0]],"id":52671542},{"atl":[[19.5,0],[20,3.67],[21,0]],"id":52671542},{"atb":[[160,0],[180,4.26]],"id":52671545},{"atl":[[65,0],[70,4.26],[75,0]],"id":52671544},{"atb":[[4.8,4.68],[4.7,0]],"id":52671555},{"atl":[[10,0],[11,3.79]],"id":52671555},{"atb":[[75,0],[40,0],[50,4.57],[30,0]],"id":52671554},{"atl":[[190,0]],"id":52671554},{"atb":[[38,0],[46,4.51]],"id":52671556},{"atl":[[180,0]],"id":52671556}],"con":true,"img":false}]}
{"op":"mcm","clk":"11449891238","pt":1717315689262,"mc":[{"id":"1.229554893","rc":[{"atb":[[36,6.94]],"id":52671554},{"atb":[[34,5.71]],"id":52671556}],"con":true,"img":false}]}
{"op":"mcm","clk":"11449891249","pt":1717315689360,"mc":[{"id":"1.229554893","rc":[{"atb":[[2.08,14.53]],"id":52671548},{"atl":[[3.8,5.6],[3.9,0]],"id":52671548},{"atb":[[75,0],[40,0],[50,0],[30,0]],"id":52671556}],"con":true,"img":false}]}
{"op":"mcm","clk":"11449891260","pt":1717315689469,"mc":[{"id":"1.229554893","rc":[{"atl":[[3.6,6.03]],"id":52671550}],"con":true,"img":false}]}
{"op":"mcm","clk":"11449891288","pt":1717315689731,"mc":[{"id":"1.229554893","rc":[{"atb":[[8,11.21],[9,6.54],[10,2.91],[7,17.44]],"id":52671542},{"atb":[[32,3.37],[80,0.33],[42,1.92],[55,0.97]],"id":52671554}],"con":true,"img":false}]}
{"op":"mcm","clk":"11449891303","pt":1717315689983,"mc":[{"id":"1.229554893","rc":[{"atl":[[10.5,0]],"id":52671555}],"con":true,"img":false}]}
{"op":"mcm","clk":"11449891316","pt":1717315690042,"mc":[{"id":"1.229554893","rc":[{"atb":[[34,8.88],[85,0.31],[44,1.83],[60,0.88]],"id":52671556}],"con":true,"img":false}]}
{"op":"mcm","clk":"11449891644","pt":1717315693454,"mc":[{"id":"1.229554893","rc":[{"atb":[[2.08,0]],"id":52671548},{"atl":[[19.5,2.79]],"id":52671542}],"con":true,"img":false}]}
{"op":"mcm","clk":"11449891886","pt":1717315695570,"mc":[{"id":"1.229554893","rc":[{"atb":[[8,0],[9,0],[10,0],[7,0]],"id":52671542}],"con":true,"img":false}]}
{"op":"mcm","clk":"11449891961","pt":1717315696257,"mc":[{"id":"1.229554893","rc":[{"atb":[[6.8,18.04],[9.8,2.97],[8.8,6.71],[7.8,11.54]],"id":52671542}],"con":true,"img":false}]}
{"op":"mcm","clk":"11449892020","pt":1717315696778,"mc":[{"id":"1.229554893","rc":[{"atb":[[2.06,0],[2.08,14.53]],"id":52671548},{"atb":[[180,0]],"id":52671545},{"atb":[[40,3.63],[50,0]],"id":52671554},{"atb":[[34,5.71],[38,4.64],[85,0],[44,0],[46,0],[60,0]],"id":52671556}],"con":true,"img":false}]}
{"op":"mcm","clk":"11449892044","pt":1717315696979,"mc":[{"id":"1.229554893","rc":[{"atl":[[3.6,0]],"id":52671550},{"atl":[[3.8,0],[3.9,5.4]],"id":52671548},{"atl":[[19.5,0]],"id":52671542}],"con":true,"img":false}]}
{"op":"mcm","clk":"11449892095","pt":1717315697450,"mc":[{"id":"1.229554893","rc":[{"atb":[[34,8.88],[85,0.31],[44,1.83],[60,0.88]],"id":52671556}],"con":true,"img":false}]}
{"op":"mcm","clk":"11449892103","pt":1717315697562,"mc":[{"id":"1.229554893","rc":[{"atb":[[36,4.08],[44,2.33]],"id":52671554},{"atb":[[46,2.22]],"id":52671556}],"con":true,"img":false}]}
{"op":"mcm","clk":"11449892114","pt":1717315697663,"mc":[{"id":"1.229554893","rc":[{"atb":[[34,5.85]],"id":52671556}],"con":true,"img":false}]}
{"op":"mcm","clk":"11449892164","pt":1717315698172,"mc":[{"id":"1.229554893","rc":[{"atl":[[3.6,6.03]],"id":52671550},{"atb":[[2.06,14.8],[2.08,0]],"id":52671548},{"atl":[[3.8,5.6],[3.9,0]],"id":52671548},{"atl":[[19.5,4.18]],"id":52671542},{"atb":[[180,4.09]],"id":52671545},{"atb":[[40,0],[50,3.46]],"id":52671554},{"atb":[[38,0],[46,6.49]],"id":52671556}],"con":true,"img":false}]}
{"op":"mcm","clk":"11449892177","pt":1717315698280,"mc":[{"id":"1.229554893","rc":[{"atb":[[50,5.5]],"id":52671554}],"con":true,"img":false}]}
{"op":"mcm","clk":"11449892191","pt":1717315698380,"mc":[{"id":"1.229554893","rc":[{"atb":[[44,0]],"id":52671554}],"con":true,"img":false}]}
{"op":"mcm","clk":"11449892261","pt":1717315699064,"mc":[{"id":"1.229554893","rc":[{"atl":[[80,3.69]],"id":52671544},{"atl":[[12,2.93]],"id":52671555}],"con":true,"img":false}]}
{"op":"mcm","clk":"11449892801","pt":1717315703989,"mc":[{"id":"1.229554893","rc":[{"atb":[[36,6.94],[50,3.46]],"id":52671554},{"atb":[[34,8.88],[46,4.27]],"id":52671556}],"con":true,"img":false}]}
{"op":"mcm","clk":"11449892839","pt":1717315704353,"mc":[{"id":"1.229554893","rc":[{"atb":[[2.06,0],[2.08,14.53]],"id":52671548},{"atb":[[180,0]],"id":52671545},{"atb":[[40,4.16],[50,0]],"id":52671554},{"atb":[[34,2.68],[38,3.09],[85,0],[44,0],[46,2.22],[60,0]],"id":52671556}],"con":true,"img":false}]}
{"op":"mcm","clk":"11449892847","pt":1717315704461,"mc":[{"id":"1.229554893","rc":[{"atb":[[40,2.56],[46,0]],"id":52671556}],"con":true,"img":false}]}
{"op":"mcm","clk":"11449892866","pt":1717315704674,"mc":[{"id":"1.229554893","rc":[{"atl":[[3.6,0]],"id":52671550},{"atl":[[3.8,0],[3.9,5.4]],"id":52671548},{"atl":[[19.5,0]],"id":52671542}],"con":true,"img":false}]}
{"op":"mcm","clk":"11449892909","pt":1717315705081,"mc":[{"id":"1.229554893","rc":[{"atb":[[34,5.85],[85,0.31],[44,1.83],[60,0.88]],"id":52671556}],"con":true,"img":false}]}
{"op":"mcm","clk":"11449892922","pt":1717315705184,"mc":[{"id":"1.229554893","rc":[{"atb":[[40,0],[46,2.22]],"id":52671556}],"con":true,"img":false}]}
{"op":"mcm","clk":"11449893004","pt":1717315705968,"mc":[{"id":"1.229554893","rc":[{"atl":[[3.6,6.03]],"id":52671550},{"atb":[[2.06,14.8]],"id":52671548},{"atl":[[3.8,5.6]],"id":52671548},{"atl":[[19.5,2.65]],"id":52671542},{"atb":[[180,3.46]],"id":52671545},{"atb":[[50,3.77]],"id":52671554},{"atb":[[38,0]],"id":52671556}],"con":true,"img":false}]}
{"op":"mcm","clk":"11449893014","pt":1717315706067,"mc":[{"id":"1.229554893","rc":[{"atb":[[2.08,0]],"id":52671548},{"atl":[[3.9,0]],"id":52671548},{"atb":[[40,0]],"id":52671554},{"atb":[[46,5.93]],"id":52671556}],"con":true,"img":false}]}
{"op":"mcm","clk":"11449893101","pt":1717315706986,"mc":[{"id":"1.229554893","rc":[{"atb":[[36,4.08],[50,5.81]],"id":52671554}],"con":true,"img":false}]}
{"op":"mcm","clk":"11449893498","pt":1717315711307,"mc":[{"id":"1.229554893","rc":[{"atb":[[36,6.94],[50,3.77]],"id":52671554},{"atb":[[34,8.88],[46,3.71]],"id":52671556}],"con":true,"img":false}]}
{"op":"mcm","clk":"11449893530","pt":1717315711572,"mc":[{"id":"1.229554893","rc":[{"atb":[[2.06,0],[2.08,14.53]],"id":52671548},{"atb":[[180,0]],"id":52671545},{"atb":[[40,3.02],[50,0]],"id":52671554},{"atb":[[34,5.71],[38,3.46],[85,0],[44,0],[46,0],[60,0]],"id":52671556}],"con":true,"img":false}]}
{"op":"mcm","clk":"11449893549","pt":1717315711780,"mc":[{"id":"1.229554893","rc":[{"atb":[[36,4.08],[44,2.33]],"id":52671554}],"con":true,"img":false}]}
{"op":"mcm","clk":"11449893588","pt":1717315712098,"mc":[{"id":"1.229554893","rc":[{"atb":[[2,0],[2.2,0]],"id":52671550},{"atl":[[3.6,0],[3.65,5.92]],"id":52671550},{"atb":[[12,0],[8.8,0]],"id":52671546},{"atb":[[9.2,0],[13,0]],"id":52671549},{"atb":[[1.98,0],[1.88,0]],"id":52671548},{"atl":[[3.8,0]],"id":52671548},{"atb":[[5,0],[6,0]],"id":52671542},{"atl":[[19.5,0],[21,3.15]],"id":52671542},{"atb":[[570,0],[470,0]],"id":52671545},{"atb":[[11,0],[8.4,0]],"id":52671544},{"atb":[[3.55,0],[3.05,0]],"id":52671555},{"atb":[[19.5,0],[14.5,0]],"id":52671554},{"atb":[[20,0],[15,0]],"id":52671556}],"con":true,"img":false}]}
{"op":"mcm","clk":"11449893610","pt":1717315712303,"mc":[{"id":"1.229554893","rc":[{"atb":[[34,8.88],[85,0.31],[44,1.83],[60,0.88]],"id":52671556}],"con":true,"img":false}]}
{"op":"mcm","clk":"11449893785","pt":1717315713879,"mc":[{"id":"1.229554893","rc":[{"atb":[[34,5.85],[46,2.22]],"id":52671556}],"con":true,"img":false}]}
{"op":"mcm","clk":"11449894003","pt":1717315716057,"mc":[{"id":"1.229554893","rc":[{"atb":[[180,3.74]],"id":52671545}],"con":true,"img":false}]}
{"op":"mcm","clk":"11449894221","pt":1717315717936,"mc":[{"id":"1.229554893","rc":[{"atb":[[1.92,17.06],[1.89,17.63],[1.91,132.23],[1.9,17.43]],"id":52671550},{"atl":[[3.6,6.03],[3.65,0]],"id":52671550},{"atb":[[2.06,14.8],[2.08,0]],"id":52671548},{"atl":[[3.85,5.5]],"id":52671548},{"atl":[[20,0]],"id":52671542},{"atb":[[170,4.41],[180,0]],"id":52671545},{"atl":[[10.5,3.71],[11,0]],"id":52671555},{"atb":[[40,0],[50,4.44]],"id":52671554},{"atl":[[190,3.99]],"id":52671554},{"atb":[[38,0],[44,4.7],[46,5.39]],"id":52671556},{"atl":[[180,4.39]],"id":52671556}],"con":true,"img":false}]}
{"op":"mcm","clk":"11449894299","pt":1717315718671,"mc":[{"id":"1.229554893","rc":[{"atb":[[36,6.94],[44,0]],"id":52671554},{"atb":[[34,8.88],[46,3.17]],"id":52671556}],"con":true,"img":false}]}
{"op":"mcm","clk":"11449894341","pt":1717315718936,"mc":[{"id":"1.229554893","rc":[{"atb":[[1.93,16.87]],"id":52671550},{"atb":[[2.08,14.53]],"id":52671548},{"atb":[[160,3.09],[170,0]],"id":52671545},{"atb":[[40,3.51],[50,0]],"id":52671554},{"atb":[[34,5.71],[38,4.55],[85,0],[44,0],[46,0],[60,0]],"id":52671556}],"con":true,"img":false}]}
{"op":"mcm","clk":"11449894355","pt":1717315719045,"mc":[{"id":"1.229554893","rc":[{"atb":[[1.92,0],[1.89,0],[1.9,0]],"id":52671550},{"atb":[[2.06,0]],"id":52671548}],"con":true,"img":false}]}
{"op":"mcm","clk":"11449894367","pt":1717315719147,"mc":[{"id":"1.229554893","rc":[{"atb":[[36,4.08],[42,4.36]],"id":52671554},{"atb":[[34,2.68],[40,2.56]],"id":52671556}],"con":true,"img":false}]}
{"op":"mcm","clk":"11449894406","pt":1717315719460,"mc":[{"id":"1.229554893","rc":[{"atl":[[3.6,0],[3.65,5.92]],"id":52671550},{"atl":[[3.85,0]],"id":52671548},{"atl":[[170,3.85],[180,0]],"id":52671556}],"con":true,"img":false}]}
{"op":"mcm","clk":"11449894436","pt":1717315719669,"mc":[{"id":"1.229554893","rc":[{"atb":[[34,5.85],[85,0.31],[44,1.83],[60,0.88]],"id":52671556}],"con":true,"img":false}]}
{"op":"mcm","clk":"11449894450","pt":1717315719772,"mc":[{"id":"1.229554893","rc":[{"atb":[[1.91,114.98],[1.93,0]],"id":52671550}],"con":true,"img":false}]}
{"op":"mcm","clk":"11449894633","pt":1717315721280,"mc":[{"id":"1.229554893","rc":[{"atb":[[1.92,17.06],[1.9,17.43]],"id":52671550},{"atl":[[3.6,6.03],[3.65,0]],"id":52671550},{"atl":[[3.85,5.5]],"id":52671548},{"atb":[[160,0],[170,4.47]],"id":52671545},{"atb":[[40,0],[50,2.97]],"id":52671554},{"atb":[[38,0],[44,5.1]],"id":52671556},{"atl":[[170,0],[180,4.43]],"id":52671556}],"con":true,"img":false}]}
{"op":"mcm","clk":"11449894735","pt":1717315722038,"mc":[{"id":"1.229554893","rc":[{"atl":[[23,2.94]],"id":52671542}],"con":true,"img":false}]}
{"op":"mcm","clk":"11449894902","pt":1717315723429,"mc":[{"id":"1.229554893","rc":[{"atb":[[1.92,0],[1.93,16.87]],"id":52671550},{"atb":[[160,4.31],[170,0]],"id":52671545},{"atb":[[40,4.54],[50,0]],"id":52671554},{"atb":[[38,4.09],[44,1.83]],"id":52671556}],"con":true,"img":false}]}
{"op":"mcm","clk":"11449894925","pt":1717315723636,"mc":[{"id":"1.229554893","rc":[{"atl":[[3.6,0],[3.65,5.92]],"id":52671550},{"atl":[[3.85,0]],"id":52671548},{"atl":[[170,4.43],[180,0]],"id":52671556}],"con":true,"img":false}]}
{"op":"mcm","clk":"11449895157","pt":1717315725867,"mc":[{"id":"1.229554893","rc":[{"atb":[[1.92,17.06],[1.93,0]],"id":52671550},{"atl":[[3.6,6.03],[3.65,0]],"id":52671550},{"atl":[[3.85,5.5]],"id":52671548},{"atb":[[160,0],[170,2.72]],"id":52671545},{"atb":[[40,0],[50,4.05]],"id":52671554},{"atb":[[38,0],[44,5.17]],"id":52671556},{"atl":[[170,0],[180,4.27]],"id":52671556}],"con":true,"img":false}]}
{"op":"mcm","clk":"11449895207","pt":1717315726335,"mc":[{"id":"1.229554893","rc":[{"atb":[[2.86,53.76],[2.76,0]],"id":52671555}],"con":true,"img":false}]}
{"op":"mcm","clk":"11449895219","pt":1717315726439,"mc":[{"id":"1.229554893","rc":[{"atb":[[34,2.68],[85,0],[44,3.34],[60,0]],"id":52671556}],"con":true,"img":false}]}
{"op":"mcm","clk":"11449895239","pt":1717315726650,"mc":[{"id":"1.229554893","rc":[{"atb":[[1.92,0],[1.98,16.01]],"id":52671550},{"atl":[[3.6,0],[3.65,5.92]],"id":52671550},{"atb":[[16.5,5.06],[18.5,3.06]],"id":52671546},{"atb":[[2.04,15.09],[2.08,0]],"id":52671548},{"atl":[[3.85,0]],"id":52671548},{"atb":[[170,0],[180,4.17]],"id":52671545},{"atb":[[4.8,0],[4.9,3.41]],"id":52671555},{"atb":[[46,3.79],[50,0]],"id":52671554},{"atl":[[170,3.58],[180,0]],"id":52671556}],"con":true,"img":false}]}
{"op":"mcm","clk":"11449895298","pt":1717315727163,"mc":[{"id":"1.229554893","rc":[{"atb":[[34,5.85],[85,0.31],[44,5.17],[60,0.88]],"id":52671556}],"con":true,"img":false}]}
{"op":"mcm","clk":"11449895547","pt":1717315729668,"mc":[{"id":"1.229554893","rc":[{"atl":[[3.6,6.03],[3.65,0]],"id":52671550},{"atl":[[3.8,5.6]],"id":52671548},{"atl":[[170,0],[180,4.34]],"id":52671556}],"con":true,"img":false}]}
{"op":"mcm","clk":"11449895611","pt":1717315730341,"mc":[{"id":"1.229554893","rc":[{"atb":[[1.99,15.85],[1.98,0]],"id":52671550},{"atb":[[18.5,0],[18,3.21]],"id":52671546},{"atb":[[16,0],[18.5,0],[22,0],[27,0]],"id":52671549},{"atb":[[2.06,14.8],[2.04,0]],"id":52671548},{"atb":[[160,2.98],[180,0]],"id":52671545},{"atb":[[32,0],[80,0],[40,3.15],[42,2.44],[46,0],[55,0]],"id":52671554},{"atb":[[34,2.68],[38,3.11],[85,0],[44,0],[60,0]],"id":52671556}],"con":true,"img":false}]}
{"op":"mcm","clk":"11449895626","pt":1717315730547,"mc":[{"id":"1.229554893","rc":[{"atb":[[36,6.94],[42,0]],"id":52671554},{"atb":[[34,5.71],[40,0]],"id":52671556}],"con":true,"img":false}]}
{"op":"mcm","clk":"11449895670","pt":1717315731061,"mc":[{"id":"1.229554893","rc":[{"atb":[[18,4.61],[21,2.62],[26,1.05],[15.5,7.21]],"id":52671549},{"atb":[[75,0.36],[40,5.17],[50,1.07],[30,3.61]],"id":52671554},{"atb":[[75,0.36],[40,2.01],[50,1.07],[30,3.61]],"id":52671556}],"con":true,"img":false}]}
{"op":"mcm","clk":"11449895859","pt":1717315732874,"mc":[{"id":"1.229554893","rc":[{"atb":[[36,4.08],[42,2.44]],"id":52671554},{"atb":[[40,4.57]],"id":52671556}],"con":true,"img":false}]}
{"op":"mcm","clk":"11449895870","pt":1717315732976,"mc":[{"id":"1.229554893","rc":[{"atb":[[34,2.68]],"id":52671556}],"con":true,"img":false}]}
{"op":"mcm","clk":"11449895895","pt":1717315733138,"mc":[{"id":"1.229554893","rc":[{"atb":[[1.99,0]],"id":52671550},{"atl":[[3.6,0]],"id":52671550},{"atb":[[18,0],[18.5,4.38]],"id":52671546},{"atb":[[2.06,0],[2.04,15.09]],"id":52671548},{"atl":[[3.8,0],[3.9,5.4]],"id":52671548},{"atb":[[160,0],[180,2.92]],"id":52671545},{"atb":[[40,2.01],[46,4.47]],"id":52671554},{"atl":[[180,2.62],[190,0]],"id":52671554},{"atb":[[38,0]],"id":52671556},{"atl":[[180,0]],"id":52671556}],"con":true,"img":false}]}
{"op":"mcm","clk":"11449895909","pt":1717315733241,"mc":[{"id":"1.229554893","rc":[{"atb":[[1.98,16.01]],"id":52671550},{"atb":[[44,4.47]],"id":52671556},{"atl":[[170,2.81]],"id":52671556}],"con":true,"img":false}]}
{"op":"mcm","clk":"11449896260","pt":1717315736671,"mc":[{"id":"1.229554893","rc":[{"atb":[[4.7,4.25]],"id":52671555}],"con":true,"img":false}]}
{"op":"mcm","clk":"11449896489","pt":1717315739184,"mc":[{"id":"1.229554893","rc":[{"atb":[[2.02,0],[2.12,0],[1.91,0],[1.96,0]],"id":52671550}],"con":true,"img":false}]}
{"op":"mcm","clk":"11449896566","pt":1717315739860,"mc":[{"id":"1.229554893","rc":[{"atb":[[1.98,96.09],[2.06,49.36],[1.93,112.51],[2.16,22.55]],"id":52671550}],"con":true,"img":false}]}
{"op":"mcm","clk":"11449896659","pt":1717315740952,"mc":[{"id":"1.229554893","rc":[{"atl":[[3.6,6.03]],"id":52671550},{"atl":[[3.8,5.6],[3.9,0]],"id":52671548},{"atb":[[4.5,0]],"id":52671555},{"atl":[[180,0],[190,4.65]],"id":52671554},{"atl":[[170,0],[180,3.33]],"id":52671556}],"con":true,"img":false}]}
{"op":"mcm","clk":"11449896679","pt":1717315741163,"mc":[{"id":"1.229554893","rc":[{"atb":[[1.99,15.85],[2.06,0],[1.98,0],[1.93,0],[2.16,0]],"id":52671550},{"atl":[[3.65,5.92]],"id":52671550},{"atb":[[18.5,0],[18,2.71]],"id":52671546},{"atb":[[2.06,14.8],[2.04,0]],"id":52671548},{"atl":[[3.75,5.7]],"id":52671548},{"atl":[[19.5,4.04],[21,0]],"id":52671542},{"atb":[[160,4.68],[180,0]],"id":52671545},{"atl":[[65,4.07],[70,0]],"id":52671544},{"atb":[[40,6.44],[46,0]],"id":52671554},{"atb":[[38,2.93],[44,0]],"id":52671556}],"con":true,"img":false}]}
{"op":"mcm","clk":"11449896725","pt":1717315741578,"mc":[{"id":"1.229554893","rc":[{"atl":[[3.7,0],[3.75,5.7]],"id":52671550},{"atl":[[65,0],[60,3.81]],"id":52671546},{"atl":[[3.85,5.5]],"id":52671548},{"atl":[[170,3.96]],"id":52671554}],"con":true,"img":false}]}
{"op":"mcm","clk":"11449896760","pt":1717315741885,"mc":[{"id":"1.229554893","rc":[{"atb":[[1.99,95.12],[2.18,22.17],[1.94,111.32],[2.08,48.44]],"id":52671550}],"con":true,"img":false}]}
{"op":"mcm","clk":"11449896822","pt":1717315742409,"mc":[{"id":"1.229554893","rc":[{"atl":[[3.6,0],[3.65,0]],"id":52671550},{"atl":[[3.8,0],[3.75,0]],"id":52671548},{"atl":[[210,0]],"id":52671554},{"atl":[[170,4.67],[180,0]],"id":52671556}],"con":true,"img":false}]}
{"op":"mcm","clk":"11449896846","pt":1717315742566,"mc":[{"id":"1.229554893","rc":[{"atb":[[1.99,0],[1.98,16.01],[2.18,0],[1.94,0],[2.08,0]],"id":52671550},{"atb":[[18,0]],"id":52671546},{"atb":[[2.06,0],[2.04,15.09]],"id":52671548},{"atb":[[180,3.6]],"id":52671545},{"atb":[[46,4.05]],"id":52671554},{"atb":[[38,0],[44,4.64]],"id":52671556}],"con":true,"img":false}]}
{"op":"mcm","clk":"11449896862","pt":1717315742668,"mc":[{"id":"1.229554893","rc":[{"atb":[[18.5,3.12]],"id":52671546},{"atb":[[160,0]],"id":52671545},{"atb":[[40,2.01]],"id":52671554}],"con":true,"img":false}]}
{"op":"mcm","clk":"11449896976","pt":1717315743561,"mc":[{"id":"1.229554893","rc":[{"atb":[[1.98,96.09],[2.06,49.36],[1.93,112.51],[2.16,22.55]],"id":52671550}],"con":true,"img":false}]}
{"op":"mcm","clk":"11449897041","pt":1717315744078,"mc":[{"id":"1.229554893","rc":[{"atl":[[3.65,5.92]],"id":52671550},{"atl":[[65,4.24],[60,0]],"id":52671546},{"atl":[[3.75,5.7]],"id":52671548},{"atl":[[170,0],[180,3.2]],"id":52671554},{"atl":[[170,0],[180,3.62]],"id":52671556}],"con":true,"img":false}]}
{"op":"mcm","clk":"11449897057","pt":1717315744185,"mc":[{"id":"1.229554893","rc":[{"atl":[[3.85,0]],"id":52671548}],"con":true,"img":false}]}
{"op":"mcm","clk":"11449897217","pt":1717315745591,"mc":[{"id":"1.229554893","rc":[{"atb":[[1.99,15.85],[1.98,80.08]],"id":52671550},{"atb":[[18.5,0],[18,3.44]],"id":52671546},{"atb":[[2.06,14.8],[2.04,0]],"id":52671548},{"atb":[[160,4.37],[180,0]],"id":52671545},{"atb":[[40,6.66],[46,0]],"id":52671554},{"atb":[[38,3.22],[44,0]],"id":52671556}],"con":true,"img":false}]}
{"op":"mcm","clk":"11449897265","pt":1717315745954,"mc":[{"id":"1.229554893","rc":[{"atl":[[3.65,0]],"id":52671550},{"atl":[[65,0],[60,3.36]],"id":52671546},{"atl":[[3.85,5.5],[3.75,0]],"id":52671548},{"atl":[[170,3.84],[180,0]],"id":52671554},{"atl":[[170,2.81],[180,0]],"id":52671556}],"con":true,"img":false}]}
{"op":"mcm","clk":"11449897468","pt":1717315747869,"mc":[{"id":"1.229554893","rc":[{"atb":[[1.99,0]],"id":52671550},{"atb":[[18,0]],"id":52671546},{"atl":[[60,0]],"id":52671546},{"atb":[[2.06,0],[2.04,15.09]],"id":52671548},{"atl":[[3.85,0],[3.75,5.7]],"id":52671548},{"atb":[[160,0],[180,3.04]],"id":52671545}],"con":true,"img":false}]}
{"op":"mcm","clk":"11449897476","pt":1717315747969,"mc":[{"id":"1.229554893","rc":[{"atb":[[1.98,96.09]],"id":52671550},{"atl":[[3.65,5.92]],"id":52671550},{"atb":[[18.5,4.58]],"id":52671546},{"atl":[[65,4.53]],"id":52671546},{"atb":[[40,2.01],[46,4]],"id":52671554},{"atl":[[170,0],[180,3.15]],"id":52671554},{"atb":[[38,0],[44,4.45]],"id":52671556},{"atl":[[170,0],[180,3.23]],"id":52671556}],"con":true,"img":false}]}
{"op":"mcm","clk":"11449897570","pt":1717315748901,"mc":[{"id":"1.229554893","rc":[{"atb":[[1.99,15.85],[1.98,80.08]],"id":52671550},{"atb":[[18.5,0],[18,4.29]],"id":52671546},{"atb":[[2.06,14.8],[2.04,0]],"id":52671548},{"atb":[[160,3.84],[180,0]],"id":52671545},{"atb":[[40,6],[46,0]],"id":52671554},{"atb":[[38,2.85],[44,0]],"id":52671556}],"con":true,"img":false}]}
{"op":"mcm","clk":"11449897644","pt":1717315749690,"mc":[{"id":"1.229554893","rc":[{"atl":[[3.65,0]],"id":52671550},{"atl":[[60,4.02]],"id":52671546},{"atl":[[170,4.05]],"id":52671556}],"con":true,"img":false}]}
{"op":"mcm","clk":"11449897654","pt":1717315749792,"mc":[{"id":"1.229554893","rc":[{"atl":[[65,0]],"id":52671546},{"atl":[[3.85,5.5],[3.75,0]],"id":52671548},{"atl":[[170,4.16],[180,0]],"id":52671554},{"atl":[[180,0]],"id":52671556}],"con":true,"img":false}]}
{"op":"mcm","clk":"11449897799","pt":1717315751203,"mc":[{"id":"1.229554893","rc":[{"atl":[[21,2.98]],"id":52671542}],"con":true,"img":false}]}
{"op":"mcm","clk":"11449898108","pt":1717315753868,"mc":[{"id":"1.229554893","rc":[{"atb":[[1.99,121.43],[1.89,274.05]],"id":52671550},{"atb":[[8.6,32.09],[11.5,9.95]],"id":52671546},{"atb":[[9,30.48],[12.5,9.08]],"id":52671549},{"atb":[[2.12,116.68],[1.96,335.81]],"id":52671548},{"atb":[[5.7,22.24],[4.7,65.92]],"id":52671542},{"atb":[[410,0.59],[510,0.2]],"id":52671545},{"atb":[[12,9.5],[8.8,31.27]],"id":52671544},{"atb":[[3.25,108.4],[3.75,38]],"id":52671555},{"atb":[[20,5.5],[15,17.42]],"id":52671554},{"atb":[[19.5,5.65],[14.5,18.06]],"id":52671556}],"con":true,"img":false}]}
{"op":"mcm","clk":"11449898265","pt":1717315755378,"mc":[{"id":"1.229554893","rc":[{"atl":[[23,0]],"id":52671542}],"con":true,"img":false}]}
{"op":"mcm","clk":"11449898641","pt":1717315758867,"mc":[{"id":"1.229554893","rc":[{"atb":[[1.97,16.18]],"id":52671550},{"atl":[[3.85,5.5]],"id":52671550}],"con":true,"img":false}]}
{"op":"mcm","clk":"11449898720","pt":1717315759700,"mc":[{"id":"1.229554893","rc":[{"atb":[[17,4.36]],"id":52671546}],"con":true,"img":false}]}
{"op":"mcm","clk":"11449898777","pt":1717315760306,"mc":[{"id":"1.229554893","rc":[{"atb":[[1.9,0]],"id":52671550}],"con":true,"img":false}]}
{"op":"mcm","clk":"11449898818","pt":1717315760672,"mc":[{"id":"1.229554893","rc":[{"atb":[[16,0]],"id":52671546}],"con":true,"img":false}]}
{"op":"mcm","clk":"11449899142","pt":1717315763782,"mc":[{"id":"1.229554893","rc":[{"atl":[[170,0],[180,3.85]],"id":52671554},{"atl":[[170,0],[180,3.66]],"id":52671556}],"con":true,"img":false}]}
{"op":"mcm","clk":"11449903249","pt":1717315803868,"mc":[{"id":"1.229554893","rc":[{"atb":[[1.99,15.85],[1.89,0]],"id":52671550},{"atb":[[8.6,0],[11.5,0]],"id":52671546},{"atb":[[9,0],[12.5,0]],"id":52671549},{"atb":[[2.12,23.35],[1.96,81.75]],"id":52671548},{"atb":[[5.7,0],[4.7,0]],"id":52671542},{"atb":[[410,0],[510,0]],"id":52671545},{"atb":[[12,0],[8.8,0]],"id":52671544},{"atb":[[3.25,0],[3.75,0]],"id":52671555},{"atb":[[20,0],[15,0]],"id":52671554},{"atb":[[19.5,0],[14.5,0]],"id":52671556}],"con":true,"img":false}]}
{"op":"mcm","clk":"11449904975","pt":1717315820979,"mc":[{"id":"1.229554893","rc":[{"atb":[[2.06,0],[1.98,0],[1.93,0],[2.16,0]],"id":52671550}],"con":true,"img":false}]}
{"op":"mcm","clk":"11449905058","pt":1717315821868,"mc":[{"id":"1.229554893","rc":[{"atb":[[1.99,95.12],[2.18,22.17],[1.94,111.32],[2.08,48.44]],"id":52671550}],"con":true,"img":false}]}
{"op":"mcm","clk":"11449905461","pt":1717315825697,"mc":[{"id":"1.229554893","rc":[{"atb":[[18,0],[18.5,4.41]],"id":52671546},{"atb":[[2.06,0],[2.04,15.09]],"id":52671548},{"atb":[[160,0],[170,4.48]],"id":52671545},{"atb":[[38,4.19],[40,2.01]],"id":52671554}],"con":true,"img":false}]}
{"op":"mcm","clk":"11449905838","pt":1717315829475,"mc":[{"id":"1.229554893","rc":[{"atl":[[3.75,0],[3.65,5.92]],"id":52671550},{"atl":[[65,3.84],[60,0]],"id":52671546},{"atl":[[3.85,0],[3.75,5.7]],"id":52671548},{"atl":[[19.5,0],[19,4.64]],"id":52671542},{"atl":[[180,0]],"id":52671554}],"con":true,"img":false}]}
{"op":"mcm","clk":"11449906152","pt":1717315832481,"mc":[{"id":"1.229554893","rc":[{"atb":[[1.92,265.11],[2.04,100.51]],"id":52671550},{"atb":[[12,9.5],[8.8,31.27]],"id":52671546},{"atb":[[12,9.5],[8.8,31.27]],"id":52671549},{"atb":[[1.92,265.11],[2.04,115.6]],"id":52671548},{"atb":[[5.6,22.72],[4.6,67.75]],"id":52671542},{"atb":[[390,0.62],[490,0.21]],"id":52671545},{"atb":[[12,9.5],[8.8,31.27]],"id":52671544},{"atb":[[3.8,37.33],[3.3,106.04]],"id":52671555},{"atb":[[20,5.5],[15,17.42]],"id":52671554},{"atb":[[20,5.5],[15,17.42]],"id":52671556}],"con":true,"img":false}]}
{"op":"mcm","clk":"11449906489","pt":1717315835705,"mc":[{"id":"1.229554893","rc":[{"atl":[[210,4.52]],"id":52671554}],"con":true,"img":false}]}
{"op":"mcm","clk":"11449906868","pt":1717315839480,"mc":[{"id":"1.229554893","rc":[{"atl":[[3.75,5.7]],"id":52671550},{"atl":[[3.85,5.5]],"id":52671548}],"con":true,"img":false}]}
{"op":"mcm","clk":"11449907398","pt":1717315844817,"mc":[{"id":"1.229554893","rc":[{"atl":[[3.85,0]],"id":52671550},{"atl":[[3.95,0]],"id":52671548}],"con":true,"img":false}]}
{"op":"mcm","clk":"11449909212","pt":1717315861933,"mc":[{"id":"1.229554893","rc":[{"atb":[[18.5,5.01]],"id":52671549},{"atl":[[36,5.01],[50,3.27]],"id":52671549},{"atb":[[2.24,5.01],[2.12,67.12]],"id":52671548},{"atl":[[3.2,5.01],[3.7,43.76]],"id":52671548},{"atb":[[5.6,5.01],[4.9,15.41]],"id":52671555},{"atl":[[10,11.99],[8.4,5.01]],"id":52671555},{"atb":[[50,6.08]],"id":52671554},{"atl":[[180,0.89],[110,5.01]],"id":52671554},{"atb":[[44,5.01]],"id":52671556},{"atl":[[170,0.95],[110,5.01]],"id":52671556}],"con":true,"img":false}]}
{"op":"mcm","clk":"11449909227","pt":1717315862032,"mc":[{"id":"1.229554893","rc":[{"atb":[[2.18,64.46],[2.44,5.01]],"id":52671550},{"atl":[[3.1,5.01],[3.65,48.21]],"id":52671550}],"con":true,"img":false}]}
{"op":"mcm","clk":"11449910107","pt":1717315870234,"mc":[{"id":"1.229554893","rc":[{"atb":[[1.92,0],[2.04,0]],"id":52671550},{"atb":[[12,0],[8.8,0]],"id":52671546},{"atb":[[12,0],[8.8,0]],"id":52671549},{"atb":[[1.92,0],[2.04,15.09]],"id":52671548},{"atb":[[5.6,0],[4.6,0]],"id":52671542},{"atb":[[390,0],[490,0]],"id":52671545},{"atb":[[12,0],[8.8,0]],"id":52671544},{"atb":[[3.8,0],[3.3,0]],"id":52671555},{"atb":[[20,0],[15,0]],"id":52671554},{"atb":[[20,0],[15,0]],"id":52671556}],"con":true,"img":false}]}
{"op":"mcm","clk":"11449910795","pt":1717315876339,"mc":[{"id":"1.229554893","rc":[{"atb":[[13,0],[14.5,7.41]],"id":52671546},{"atb":[[40,2.01]],"id":52671556}],"con":true,"img":false}]}
{"op":"mcm","clk":"11449910806","pt":1717315876440,"mc":[{"id":"1.229554893","rc":[{"atb":[[34,5.71]],"id":52671556}],"con":true,"img":false}]}
{"op":"mcm","clk":"11449910829","pt":1717315876652,"mc":[{"id":"1.229554893","rc":[{"atb":[[1.99,0],[1.97,0],[2.18,42.28],[1.94,0],[2.08,0]],"id":52671550},{"atb":[[18.5,0],[19,7.06]],"id":52671546},{"atb":[[2.06,14.8],[2.04,0]],"id":52671548},{"atl":[[19,0],[20,3.77]],"id":52671542},{"atb":[[4.8,3.8],[4.9,11.99]],"id":52671555},{"atb":[[38,0],[40,5.37]],"id":52671554},{"atb":[[75,0],[36,4.17],[38,0],[40,0],[50,0],[30,0]],"id":52671556}],"con":true,"img":false}]}
{"op":"mcm","clk":"11449910883","pt":1717315877160,"mc":[{"id":"1.229554893","rc":[{"atb":[[46,3.56]],"id":52671556}],"con":true,"img":false}]}
{"op":"mcm","clk":"11449910921","pt":1717315877427,"mc":[{"id":"1.229554893","rc":[{"atb":[[2,52.32],[1.9,116.26],[1.95,82.6],[2.1,23.78]],"id":52671550},{"atb":[[70,0.38],[38,2.12],[48,1.11],[29,3.74]],"id":52671556}],"con":true,"img":false}]}
{"op":"mcm","clk":"11449910940","pt":1717315877636,"mc":[{"id":"1.229554893","rc":[{"atb":[[2.24,35.91]],"id":52671548},{"atl":[[3.2,35.91]],"id":52671548},{"atb":[[5.6,20.13]],"id":52671555},{"atl":[[8.4,20.13]],"id":52671555},{"atl":[[110,6.49]],"id":52671556}],"con":true,"img":false}]}
{"op":"mcm","clk":"11449910952","pt":1717315877766,"mc":[{"id":"1.229554893","rc":[{"atb":[[2.44,21.17]],"id":52671550},{"atl":[[3.1,21.17]],"id":52671550}],"con":true,"img":false}]}
{"op":"mcm","clk":"11449911023","pt":1717315878460,"mc":[{"id":"1.229554893","rc":[{"atb":[[2.12,23.35]],"id":52671548},{"atl":[[3.7,0]],"id":52671548},{"atb":[[4.9,0]],"id":52671555},{"atl":[[10,0]],"id":52671555},{"atl":[[170,0],[110,5.01]],"id":52671556}],"con":true,"img":false}]}
{"op":"mcm","clk":"11449911036","pt":1717315878566,"mc":[{"id":"1.229554893","rc":[{"atb":[[2.18,0]],"id":52671550},{"atl":[[3.65,5.92]],"id":52671550}],"con":true,"img":false}]}
{"op":"mcm","clk":"11449911193","pt":1717315880068,"mc":[{"id":"1.229554893","rc":[{"atb":[[1.89,17.63],[1.91,17.24]],"id":52671550}],"con":true,"img":false}]}
{"op":"mcm","clk":"11449911302","pt":1717315881158,"mc":[{"id":"1.229554893","rc":[{"atb":[[14.5,0]],"id":52671546}],"con":true,"img":false}]}
{"op":"mcm","clk":"11449911315","pt":1717315881258,"mc":[{"id":"1.229554893","rc":[{"atb":[[12,9.09]],"id":52671546}],"con":true,"img":false}]}
{"op":"mcm","clk":"11449911337","pt":1717315881458,"mc":[{"id":"1.229554893","rc":[{"atb":[[1.91,0],[1.94,16.69]],"id":52671550},{"atb":[[16,3.22],[19,2.91]],"id":52671546},{"atb":[[2.06,0],[2.1,14.26]],"id":52671548},{"atb":[[6.8,0],[9.8,0],[8.8,0],[7.8,0]],"id":52671542},{"atb":[[160,4.58],[170,0]],"id":52671545},{"atb":[[40,2.01],[42,5.28]],"id":52671554},{"atb":[[36,0],[38,6.05]],"id":52671556}],"con":true,"img":false}]}
{"op":"mcm","clk":"11449911347","pt":1717315881562,"mc":[{"id":"1.229554893","rc":[{"atl":[[3.7,5.81],[3.65,0]],"id":52671550},{"atl":[[65,0],[60,3.07]],"id":52671546},{"atl":[[3.75,0]],"id":52671548},{"atl":[[19.5,4.67],[20,0]],"id":52671542},{"atl":[[180,5.57],[190,0]],"id":52671554},{"atl":[[170,4.15],[180,0]],"id":52671556}],"con":true,"img":false}]}
{"op":"mcm","clk":"11449911374","pt":1717315881829,"mc":[{"id":"1.229554893","rc":[{"atb":[[1.92,17.06]],"id":52671550},{"atb":[[17.5,3.87]],"id":52671546},{"atb":[[2.08,14.53]],"id":52671548}],"con":true,"img":false}]}
{"op":"mcm","clk":"11449911394","pt":1717315882083,"mc":[{"id":"1.229554893","rc":[{"atb":[[3.05,0]],"id":52671542}],"con":true,"img":false}]}
{"op":"mcm","clk":"11449911405","pt":1717315882139,"mc":[{"id":"1.229554893","rc":[{"atb":[[9.6,3.04],[8.6,6.89],[7.6,11.89],[6.6,18.68]],"id":52671542}],"con":true,"img":false}]}
{"op":"mcm","clk":"11449911422","pt":1717315882245,"mc":[{"id":"1.229554893","rc":[{"atl":[[19.5,0],[20,3.21]],"id":52671542},{"atb":[[160,0]],"id":52671545},{"atb":[[40,6.2],[42,2.44]],"id":52671554},{"atb":[[36,3.66]],"id":52671556},{"atl":[[170,0]],"id":52671556}],"con":true,"img":false}]}
{"op":"mcm","clk":"11449911436","pt":1717315882358,"mc":[{"id":"1.229554893","rc":[{"atb":[[1.94,0]],"id":52671550},{"atl":[[3.7,0]],"id":52671550},{"atb":[[17,0]],"id":52671546},{"atl":[[65,4.57],[60,0]],"id":52671546},{"atb":[[2.1,0]],"id":52671548},{"atb":[[170,3.9]],"id":52671545},{"atb":[[38,2.12]],"id":52671556},{"atl":[[180,3.21]],"id":52671556}],"con":true,"img":false}]}
{"op":"mcm","clk":"11449911497","pt":1717315882966,"mc":[{"id":"1.229554893","rc":[{"atb":[[1.92,0]],"id":52671550},{"atb":[[16,0],[17.5,0],[19,6.12]],"id":52671546},{"atb":[[2.06,14.8],[2.08,0]],"id":52671548}],"con":true,"img":false}]}
{"op":"mcm","clk":"11449911527","pt":1717315883172,"mc":[{"id":"1.229554893","rc":[{"atl":[[3.65,5.92]],"id":52671550},{"atl":[[3.75,5.7]],"id":52671548},{"atb":[[3.05,7.65]],"id":52671542},{"atl":[[180,0.89],[190,3.63]],"id":52671554}],"con":true,"img":false}]}
{"op":"mcm","clk":"11449911580","pt":1717315883565,"mc":[{"id":"1.229554893","rc":[{"atb":[[1.91,17.24]],"id":52671550}],"con":true,"img":false}]}
{"op":"mcm","clk":"11449911992","pt":1717315887465,"mc":[{"id":"1.229554893","rc":[{"atb":[[1.92,17.06],[1.91,0]],"id":52671550},{"atb":[[17.5,3.71],[19,2.91]],"id":52671546},{"atb":[[2.06,0],[2.08,14.53]],"id":52671548}],"con":true,"img":false}]}
{"op":"mcm","clk":"11449912052","pt":1717315888154,"mc":[{"id":"1.229554893","rc":[{"atb":[[12,0],[14.5,7.41]],"id":52671546},{"atl":[[180,3.92]],"id":52671554}],"con":true,"img":false}]}
{"op":"mcm","clk":"11449912064","pt":1717315888250,"mc":[{"id":"1.229554893","rc":[{"atb":[[1.92,0],[1.91,17.24]],"id":52671550},{"atl":[[3.65,0]],"id":52671550},{"atb":[[19,6.57]],"id":52671546},{"atb":[[2.06,14.8],[2.08,0]],"id":52671548},{"atl":[[3.75,0]],"id":52671548},{"atl":[[190,0]],"id":52671554}],"con":true,"img":false}]}
{"op":"mcm","clk":"11449912253","pt":1717315889953,"mc":[{"id":"1.229554893","rc":[{"atb":[[1.92,17.06],[1.91,0]],"id":52671550},{"atb":[[19,2.91]],"id":52671546},{"atb":[[2.06,0],[2.08,14.53]],"id":52671548}],"con":true,"img":false}]}
{"op":"mcm","clk":"11449912400","pt":1717315891353,"mc":[{"id":"1.229554893","rc":[{"atb":[[14.5,0]],"id":52671546}],"con":true,"img":false}]}
{"op":"mcm","clk":"11449912412","pt":1717315891457,"mc":[{"id":"1.229554893","rc":[{"atb":[[12,8.78]],"id":52671546}],"con":true,"img":false}]}
{"op":"mcm","clk":"11449912430","pt":1717315891662,"mc":[{"id":"1.229554893","rc":[{"atb":[[1.92,0],[1.94,16.69]],"id":52671550},{"atb":[[16,3.79],[17.5,0]],"id":52671546},{"atb":[[2.1,14.26],[2.08,0]],"id":52671548},{"atb":[[160,3.82],[170,0]],"id":52671545},{"atb":[[40,2.01],[42,5.19]],"id":52671554},{"atb":[[36,0],[38,6.62]],"id":52671556}],"con":true,"img":false}]}
{"op":"mcm","clk":"11449912440","pt":1717315891767,"mc":[{"id":"1.229554893","rc":[{"atl":[[3.7,5.81]],"id":52671550},{"atl":[[65,0],[60,4.56]],"id":52671546},{"atl":[[19.5,4.09],[20,0]],"id":52671542},{"atl":[[170,3.05],[180,0]],"id":52671556}],"con":true,"img":false}]}
{"op":"mcm","clk":"11449912721","pt":1717315894353,"mc":[{"id":"1.229554893","rc":[{"atb":[[1.92,17.06],[1.94,0]],"id":52671550},{"atl":[[3.7,0]],"id":52671550},{"atb":[[17.5,3.63]],"id":52671546},{"atl":[[65,2.74],[60,0]],"id":52671546},{"atb":[[2.1,0],[2.08,14.53]],"id":52671548},{"atl":[[19.5,0],[20,3.14]],"id":52671542},{"atb":[[160,0],[170,4.48]],"id":52671545},{"atb":[[40,6.13],[42,2.44]],"id":52671554},{"atl":[[170,0],[180,4.11]],"id":52671556}],"con":true,"img":false}]}
{"op":"mcm","clk":"11449912734","pt":1717315894459,"mc":[{"id":"1.229554893","rc":[{"atb":[[36,4.36],[38,2.12]],"id":52671556}],"con":true,"img":false}]}
{"op":"mcm","clk":"11449912997","pt":1717315896760,"mc":[{"id":"1.229554893","rc":[{"atb":[[2.88,0],[3.95,9.24]],"id":52671549},{"atl":[[9.2,0],[13,8.33]],"id":52671548},{"atb":[[2.88,0],[3.95,18.79]],"id":52671542},{"atb":[[10,4.8],[200,0.39]],"id":52671545},{"atb":[[2.88,0],[3.95,7.93]],"id":52671544},{"atb":[[10,7.71],[42,0]],"id":52671554},{"atb":[[34,2.68],[10,7.31]],"id":52671556}],"con":true,"img":false}]}
{"op":"mcm","clk":"11449913020","pt":1717315896973,"mc":[{"id":"1.229554893","rc":[{"atb":[[1.92,0],[1.94,16.69]],"id":52671550},{"atl":[[3.7,5.81]],"id":52671550},{"atb":[[17.5,0]],"id":52671546},{"atl":[[65,0],[60,3.34]],"id":52671546},{"atb":[[2.1,14.26],[2.08,0]],"id":52671548},{"atl":[[19.5,4.66],[20,0]],"id":52671542},{"atb":[[160,3.94],[170,0]],"id":52671545},{"atb":[[40,2.01],[42,2.99]],"id":52671554},{"atb":[[36,0],[38,5.43]],"id":52671556},{"atl":[[170,4.02],[180,0]],"id":52671556}],"con":true,"img":false}]}
{"op":"mcm","clk":"11449913028","pt":1717315897077,"mc":[{"id":"1.229554893","rc":[{"atl":[[4.9,4.46],[3.75,0]],"id":52671550},{"atb":[[16,0]],"id":52671546},{"atb":[[4.1,5.06],[3.05,0]],"id":52671549},{"atl":[[3.85,0],[13,11.24]],"id":52671548},{"atb":[[4.1,5.06],[3.05,0]],"id":52671542},{"atb":[[150,0.7]],"id":52671545},{"atb":[[4.1,5.06],[3.05,0]],"id":52671544},{"atl":[[10.5,0],[12,0],[13,4.49]],"id":52671555},{"atb":[[36,0]],"id":52671554},{"atb":[[34,0]],"id":52671556}],"con":true,"img":false}]}
{"op":"mcm","clk":"11449913120","pt":1717315897902,"mc":[{"id":"1.229554893","rc":[{"atb":[[1.92,17.06],[1.94,0]],"id":52671550},{"atl":[[3.7,0]],"id":52671550},{"atb":[[2.1,0],[2.08,14.53]],"id":52671548},{"atb":[[160,0]],"id":52671545},{"atb":[[42,0]],"id":52671554},{"atb":[[38,2.12]],"id":52671556}],"con":true,"img":false}]}
{"op":"mcm","clk":"11449913292","pt":1717315899464,"mc":[{"id":"1.229554893","rc":[{"atb":[[1.92,0],[1.94,16.69]],"id":52671550},{"atb":[[2.1,14.26],[2.08,0]],"id":52671548}],"con":true,"img":false}]}
{"op":"mcm","clk":"11449913806","pt":1717315904194,"mc":[{"id":"1.229554893","rc":[{"atl":[[180,0.89],[190,3.49]],"id":52671554},{"atl":[[170,0],[180,2.85]],"id":52671556}],"con":true,"img":false}]}
{"op":"mcm","clk":"11449914014","pt":1717315906258,"mc":[{"id":"1.229554893","rc":[{"atb":[[1.12,117.01],[1.05,0]],"id":52671550}],"con":true,"img":false}]}
{"op":"mcm","clk":"11449914044","pt":1717315906562,"mc":[{"id":"1.229554893","rc":[{"atl":[[42,4.34],[55,0]],"id":52671549},{"atb":[[9.6,0],[8.6,0],[7.6,0],[6.6,0]],"id":52671542},{"atl":[[19.5,0],[19,2.97]],"id":52671542},{"atb":[[4.8,0],[4.9,3.44]],"id":52671555},{"atb":[[9.8,4.56],[9.4,4.44]],"id":52671554},{"atl":[[180,4.54],[190,0]],"id":52671554},{"atl":[[170,3.36],[180,0]],"id":52671556}],"con":true,"img":false}]}
{"op":"mcm","clk":"11449914054","pt":1717315906670,"mc":[{"id":"1.229554893","rc":[{"atb":[[1.94,0],[2.08,14.53]],"id":52671550},{"atb":[[2.1,0],[2.14,13.77]],"id":52671548}],"con":true,"img":false}]}
{"op":"mcm","clk":"11449914073","pt":1717315906883,"mc":[{"id":"1.229554893","rc":[{"atb":[[1.92,265.11],[2.04,100.51]],"id":52671550},{"atb":[[12,18.28],[8.8,31.27]],"id":52671546},{"atb":[[12,9.5],[8.8,31.27]],"id":52671549},{"atb":[[1.92,265.11],[2.04,100.51]],"id":52671548},{"atb":[[5.6,22.72],[4.6,67.75]],"id":52671542},{"atb":[[390,0.62],[490,0.21]],"id":52671545},{"atb":[[12,9.5],[8.8,31.27]],"id":52671544},{"atb":[[3.8,37.33],[3.3,106.04]],"id":52671555},{"atb":[[20,5.5],[15,17.42]],"id":52671554},{"atb":[[20,5.5],[15,17.42]],"id":52671556}],"con":true,"img":false}]}
{"op":"mcm","clk":"11449914114","pt":1717315907285,"mc":[{"id":"1.229554893","rc":[{"atb":[[6.4,19.38],[7.4,12.26],[8.4,7.07],[9.4,3.11]],"id":52671542}],"con":true,"img":false}]}
{"op":"mcm","clk":"11449914125","pt":1717315907386,"mc":[{"id":"1.229554893","rc":[{"atb":[[9.8,4.41],[9.4,3.07]],"id":52671546}],"con":true,"img":false}]}
{"op":"mcm","clk":"11449915052","pt":1717315916879,"mc":[{"id":"1.229554893","rc":[{"atb":[[2.04,115.6]],"id":52671550},{"atl":[[5.1,4.13]],"id":52671550},{"atl":[[42,0],[55,3.25]],"id":52671549},{"atb":[[2.1,14.26]],"id":52671548},{"atl":[[14,4.46]],"id":52671548},{"atl":[[18.5,2.79],[19,0]],"id":52671542},{"atl":[[14,4.39]],"id":52671555}],"con":true,"img":false}]}
{"op":"mcm","clk":"11449915583","pt":1717315921870,"mc":[{"id":"1.229554893","rc":[{"atl":[[3.2,30.89],[3,5.01]],"id":52671548},{"atb":[[5.6,15.11],[5.7,5.01]],"id":52671555},{"atb":[[44,0],[46,8.58]],"id":52671556}],"con":true,"img":false}]}
{"op":"mcm","clk":"11449915637","pt":1717315922386,"mc":[{"id":"1.229554893","rc":[{"atl":[[3,60.91]],"id":52671548},{"atb":[[5.8,14.32]],"id":52671555}],"con":true,"img":false}]}
{"op":"mcm","clk":"11449915660","pt":1717315922595,"mc":[{"id":"1.229554893","rc":[{"atl":[[8,5.01],[8.4,15.11]],"id":52671555}],"con":true,"img":false}]}
{"op":"mcm","clk":"11449915716","pt":1717315923110,"mc":[{"id":"1.229554893","rc":[{"atl":[[3.2,0]],"id":52671548},{"atb":[[5.6,0]],"id":52671555},{"atl":[[7.8,23.61]],"id":52671555}],"con":true,"img":false}]}
{"op":"mcm","clk":"11449915803","pt":1717315923799,"mc":[{"id":"1.229554893","rc":[{"atl":[[8.4,0]],"id":52671555}],"con":true,"img":false}]}
{"op":"mcm","clk":"11449916127","pt":1717315926907,"mc":[{"id":"1.229554893","rc":[{"atb":[[1.89,0]],"id":52671550},{"atb":[[2,0]],"id":52671548},{"atl":[[19.5,3.65]],"id":52671542}],"con":true,"img":false}]}
{"op":"mcm","clk":"11449916985","pt":1717315934828,"mc":[{"id":"1.229554893","rc":[{"atb":[[1.12,0],[1.17,133.05]],"id":52671548},{"atl":[[40,2.56],[50,0]],"id":52671542}],"con":true,"img":false}]}
{"op":"mcm","clk":"11449917004","pt":1717315935031,"mc":[{"id":"1.229554893","rc":[{"atl":[[21,0]],"id":52671542}],"con":true,"img":false}]}
{"op":"mcm","clk":"11449917017","pt":1717315935133,"mc":[{"id":"1.229554893","rc":[{"atb":[[2.1,38.05],[2.08,0]],"id":52671550},{"atb":[[2.18,13.29],[2.14,0]],"id":52671548},{"atl":[[65,0],[60,3.51]],"id":52671544},{"atb":[[75,0],[40,0],[50,5.01],[30,0]],"id":52671554}],"con":true,"img":false}]}
{"op":"mcm","clk":"11449917056","pt":1717315935502,"mc":[{"id":"1.229554893","rc":[{"atb":[[50,8.29]],"id":52671554}],"con":true,"img":false}]}
{"op":"mcm","clk":"11449917085","pt":1717315935816,"mc":[{"id":"1.229554893","rc":[{"atb":[[70,0.38],[38,2.12],[48,1.11],[29,3.74]],"id":52671554}],"con":true,"img":false}]}
{"op":"mcm","clk":"11449917094","pt":1717315935920,"mc":[{"id":"1.229554893","rc":[{"atl":[[55,3.85],[60,0]],"id":52671546},{"atl":[[48,3.12],[55,0]],"id":52671549},{"atl":[[17,3.8],[18.5,0]],"id":52671542},{"atl":[[160,3.14],[180,0.89]],"id":52671554},{"atl":[[160,4.61],[170,0]],"id":52671556}],"con":true,"img":false}]}
{"op":"mcm","clk":"11449917103","pt":1717315936023,"mc":[{"id":"1.229554893","rc":[{"atl":[[110,6.49]],"id":52671554}],"con":true,"img":false}]}
{"op":"mcm","clk":"11449917169","pt":1717315936746,"mc":[{"id":"1.229554893","rc":[{"atl":[[180,0],[110,5.01]],"id":52671554}],"con":true,"img":false}]}
{"op":"mcm","clk":"11449917487","pt":1717315939547,"mc":[{"id":"1.229554893","rc":[{"atb":[[2.18,0],[2.16,13.52]],"id":52671548},{"atb":[[4.8,3.25],[4.9,0]],"id":52671555}],"con":true,"img":false}]}
{"op":"mcm","clk":"11449917580","pt":1717315940427,"mc":[{"id":"1.229554893","rc":[{"atl":[[46,2.7],[48,0]],"id":52671549},{"atl":[[17,0],[17.5,3.03]],"id":52671542},{"atl":[[7.8,0]],"id":52671555}],"con":true,"img":false}]}
{"op":"mcm","clk":"11449917645","pt":1717315941152,"mc":[{"id":"1.229554893","rc":[{"atl":[[12.5,13.96]],"id":52671555}],"con":true,"img":false}]}
{"op":"mcm","clk":"11449917997","pt":1717315944814,"mc":[{"id":"1.229554893","rc":[{"atl":[[70,2.97]],"id":52671544}],"con":true,"img":false}]}
{"op":"mcm","clk":"11449918090","pt":1717315945644,"mc":[{"id":"1.229554893","rc":[{"atl":[[180,4.38]],"id":52671554},{"atl":[[180,3.78]],"id":52671556}],"con":true,"img":false}]}
{"op":"mcm","clk":"11449918419","pt":1717315948641,"mc":[{"id":"1.229554893","rc":[{"atb":[[1.92,0],[2.04,15.09]],"id":52671550},{"atb":[[12,8.78],[8.8,0]],"id":52671546},{"atb":[[12,0],[8.8,0]],"id":52671549},{"atb":[[1.92,0],[2.04,0]],"id":52671548},{"atb":[[5.6,0],[4.6,0]],"id":52671542},{"atb":[[390,0],[490,0]],"id":52671545},{"atb":[[12,0],[8.8,0]],"id":52671544},{"atb":[[3.8,0],[3.3,0]],"id":52671555},{"atb":[[20,0],[15,0]],"id":52671554},{"atb":[[20,0],[15,0]],"id":52671556}],"con":true,"img":false}]}
{"op":"mcm","clk":"11449918581","pt":1717315950040,"mc":[{"id":"1.229554893","rc":[{"atb":[[3.95,14.56]],"id":52671549},{"atl":[[36,9.6],[50,7.81]],"id":52671549},{"atb":[[3.95,24.11]],"id":52671542},{"atl":[[18.5,4.22]],"id":52671542}],"con":true,"img":false}]}
{"op":"mcm","clk":"11449918643","pt":1717315950568,"mc":[{"id":"1.229554893","rc":[{"atb":[[9.8,4.17],[9.4,3.18]],"id":52671545},{"atl":[[80,0]],"id":52671544},{"atl":[[210,0]],"id":52671554},{"atl":[[200,0]],"id":52671556}],"con":true,"img":false}]}
{"op":"mcm","clk":"11449918661","pt":1717315950773,"mc":[{"id":"1.229554893","rc":[{"atl":[[50,4.54]],"id":52671549}],"con":true,"img":false}]}
{"op":"mcm","clk":"11449919043","pt":1717315954443,"mc":[{"id":"1.229554893","rc":[{"atb":[[3.95,13.25]],"id":52671544}],"con":true,"img":false}]}
{"op":"mcm","clk":"11449919110","pt":1717315955272,"mc":[{"id":"1.229554893","rc":[{"atl":[[8,20.13]],"id":52671555}],"con":true,"img":false}]}
{"op":"mcm","clk":"11449919184","pt":1717315955924,"mc":[{"id":"1.229554893","rc":[{"atl":[[12.5,0]],"id":52671555}],"con":true,"img":false}]}
{"op":"mcm","clk":"11449919212","pt":1717315956234,"mc":[{"id":"1.229554893","rc":[{"atb":[[2,0],[2.04,0],[1.9,17.43],[2.44,0],[1.95,0],[2.1,0]],"id":52671550},{"atl":[[2.82,5.01],[3.1,16.15]],"id":52671550},{"atb":[[18.5,0],[18,0],[21,0],[26,0],[2.98,0],[15.5,0]],"id":52671549},{"atl":[[65,0],[36,4.58],[27,5.01]],"id":52671549},{"atb":[[2.24,30.89],[2.96,5.01]],"id":52671548},{"atl":[[3,0],[4.2,5.01]],"id":52671548},{"atl":[[8,15.11],[9,5.01]],"id":52671555},{"atl":[[100,5.01],[110,1.47]],"id":52671554},{"atb":[[70,0],[38,0],[46,0],[48,0],[29,0]],"id":52671556},{"atl":[[80,5.01],[100,1.62],[110,0]],"id":52671556}],"con":true,"img":false}]}
{"op":"mcm","clk":"11449919265","pt":1717315956757,"mc":[{"id":"1.229554893","rc":[{"atl":[[2.82,11.72]],"id":52671550},{"atb":[[4.2,4.06]],"id":52671549},{"atb":[[2.96,29.49]],"id":52671548}],"con":true,"img":false}]}
{"op":"mcm","clk":"11449919296","pt":1717315956961,"mc":[{"id":"1.229554893","rc":[{"atb":[[1.12,123.72],[2.06,24.68],[1.98,53.39],[1.88,123.92],[1.93,84.38]],"id":52671550},{"atb":[[17,1.64],[11.5,5.01],[12,7.14],[9.8,11.89],[14.5,3.88]],"id":52671549},{"atl":[[12.5,13.96]],"id":52671548},{"atb":[[36,0.75],[19,5.81],[1.01,2.61],[21,5.01],[23,3.57],[28,1.94]],"id":52671556}],"con":true,"img":false}]}
{"op":"mcm","clk":"11449919346","pt":1717315957425,"mc":[{"id":"1.229554893","rc":[{"atl":[[3.1,0]],"id":52671550},{"atb":[[2.24,0]],"id":52671548}],"con":true,"img":false}]}
{"op":"mcm","clk":"11449919556","pt":1717315959548,"mc":[{"id":"1.229554893","rc":[{"atb":[[2.98,0]],"id":52671542},{"atl":[[19.5,0]],"id":52671542}],"con":true,"img":false}]}
{"op":"mcm","clk":"11449920025","pt":1717315963938,"mc":[{"id":"1.229554893","rc":[{"atl":[[26,6.42]],"id":52671549},{"atb":[[2.98,0]],"id":52671544}],"con":true,"img":false}]}
{"op":"mcm","clk":"11449920106","pt":1717315964669,"mc":[{"id":"1.229554893","rc":[{"atl":[[36,0]],"id":52671549}],"con":true,"img":false}]}
{"op":"mcm","clk":"11449920210","pt":1717315965656,"mc":[{"id":"1.229554893","rc":[{"atb":[[1.88,141.75]],"id":52671550}],"con":true,"img":false}]}
{"op":"mcm","clk":"11449920251","pt":1717315966068,"mc":[{"id":"1.229554893","rc":[{"atb":[[2.96,0],[2.94,5.01]],"id":52671548}],"con":true,"img":false}]}
{"op":"mcm","clk":"11449920261","pt":1717315966177,"mc":[{"id":"1.229554893","rc":[{"atl":[[2.82,6.71]],"id":52671550},{"atl":[[55,3.55],[60,0]],"id":52671544},{"atl":[[150,3.57],[160,0]],"id":52671556}],"con":true,"img":false}]}
{"op":"mcm","clk":"11449920271","pt":1717315966274,"mc":[{"id":"1.229554893","rc":[{"atl":[[2.82,0],[2.84,5.01]],"id":52671550}],"con":true,"img":false}]}
{"op":"mcm","clk":"11449920325","pt":1717315966750,"mc":[{"id":"1.229554893","rc":[{"atb":[[2.16,38]],"id":52671548}],"con":true,"img":false}]}
{"op":"mcm","clk":"11449920349","pt":1717315966950,"mc":[{"id":"1.229554893","rc":[{"atl":[[4.8,42.25]],"id":52671550}],"con":true,"img":false}]}
{"op":"mcm","clk":"11449920397","pt":1717315967364,"mc":[{"id":"1.229554893","rc":[{"atb":[[1.9,0],[1.91,17.24]],"id":52671550},{"atb":[[17,0],[12,0],[9.8,0],[14.5,0]],"id":52671549}],"con":true,"img":false}]}
{"op":"mcm","clk":"11449920478","pt":1717315968082,"mc":[{"id":"1.229554893","rc":[{"atb":[[16.5,1.69],[9.6,12.17],[11.5,12.49],[14,4.02]],"id":52671549}],"con":true,"img":false}]}
{"op":"mcm","clk":"11449920498","pt":1717315968252,"mc":[{"id":"1.229554893","rc":[{"atb":[[6.4,0],[7.4,0],[8.4,0],[9.4,0]],"id":52671542}],"con":true,"img":false}]}
