{"op":"mcm","clk":"11449075387","pt":1717303241523,"mc":[{"id":"1.229554898","marketDefinition":{"bspMarket":false,"turnInPlayEnabled":false,"persistenceEnabled":false,"marketBaseRate":7.0,"eventId":"33318908","eventTypeId":"4339","numberOfWinners":1,"bettingType":"ODDS","marketType":"QUINELLA","marketTime":"2024-06-02T08:41:00.000Z","suspendTime":"2024-06-02T08:41:00.000Z","bspReconciled":false,"complete":true,"inPlay":false,"crossMatching":false,"runnersVoidable":false,"numberOfActiveRunners":10,"betDelay":0,"status":"OPEN","runners":[{"status":"ACTIVE","sortPriority":1,"id":52671542,"name":"1 - 2 / 2 - 1"},{"status":"ACTIVE","sortPriority":2,"id":52671544,"name":"1 - 4 / 4 - 1"},{"status":"ACTIVE","sortPriority":3,"id":52671545,"name":"1 - 6 / 6 - 1"},{"status":"ACTIVE","sortPriority":4,"id":52671546,"name":"1 - 8 / 8 - 1"},{"status":"ACTIVE","sortPriority":5,"id":52671548,"name":"2 - 4 / 4 - 2"},{"status":"ACTIVE","sortPriority":6,"id":52671549,"name":"2 - 6 / 6 - 2"},{"status":"ACTIVE","sortPriority":7,"id":52671550,"name":"2 - 8 / 8 - 2"},{"status":"ACTIVE","sortPriority":8,"id":52671554,"name":"4 - 6 / 6 - 4"},{"status":"ACTIVE","sortPriority":9,"id":52671555,"name":"4 - 8 / 8 - 4"},{"status":"ACTIVE","sortPriority":10,"id":52671556,"name":"6 - 8 / 8 - 6"}],"regulators":["MR_INT"],"venue":"Murray Bridge","countryCode":"AU","discountAllowed":true,"timezone":"Australia/Adelaide","openDate":"2024-06-02T08:21:00.000Z","version":5962801926,"name":"Quinella","eventName":"Murray Bridge (AUS) 2nd Jun"},"rc":[],"con":true,"img":false}]}
{"op":"mcm","clk":"11449094250","pt":1717303691304,"mc":[{"id":"1.229554898","rc":[{"atb":[[34,0.8],[18.5,5.98],[22,3.74],[27,2.01]],"id":52671550},{"atb":[[300,0.09],[150,0.7],[200,0.39],[250,0.21]],"id":52671546},{"atb":[[9.6,3.04],[8.6,6.89],[7.6,11.89],[6.6,18.68]],"id":52671549},{"atb":[[1.36,72.66],[1.21,498.26],[1.26,301.83],[1.31,168.77]],"id":52671548},{"atb":[[17,1.64],[12,7.14],[9.8,11.89],[14.5,3.88]],"id":52671542},{"atb":[[34,3.17],[85,0.31],[44,1.83],[60,0.88]],"id":52671545},{"atb":[[6.8,18.04],[9.8,2.97],[8.8,6.71],[7.8,11.54]],"id":52671544},{"atb":[[17,3.27],[19.5,1.41],[12,9.51],[14.5,5.81]],"id":52671555},{"atb":[[5.6,5.69],[5.1,12.76],[4.6,21.8],[4.1,33.76]],"id":52671554},{"atb":[[170,0.16],[85,0.94],[120,0.44],[60,1.77]],"id":52671556}],"con":true,"img":false}]}
{"op":"mcm","clk":"11449095056","pt":1717303714149,"mc":[{"id":"1.229554898","rc":[{"atb":[[34,1.6],[18.5,11.97],[22,7.48],[27,4.03]],"id":52671550},{"atb":[[300,0.18],[150,1.41],[200,0.79],[250,0.42]],"id":52671546},{"atb":[[9.6,6.08],[8.6,13.78],[7.6,23.79],[6.6,37.37]],"id":52671549},{"atb":[[1.36,145.33],[1.21,996.53],[1.26,603.67],[1.31,337.54]],"id":52671548},{"atb":[[17,3.28],[12,14.28],[9.8,23.79],[14.5,7.76]],"id":52671542},{"atb":[[34,6.35],[85,0.63],[44,3.66],[60,1.77]],"id":52671545},{"atb":[[6.8,36.08],[9.8,5.95],[8.8,13.42],[7.8,23.09]],"id":52671544},{"atb":[[170,0.32],[85,1.88],[120,0.88],[60,3.55]],"id":52671556}],"con":true,"img":false}]}
{"op":"mcm","clk":"11449095079","pt":1717303714930,"mc":[{"id":"1.229554898","rc":[{"atb":[[34,0.8],[18.5,5.98],[22,3.74],[27,2.01]],"id":52671550},{"atb":[[300,0.09],[150,0.7],[200,0.39],[250,0.21]],"id":52671546},{"atb":[[9.6,3.04],[8.6,6.89],[7.6,11.89],[6.6,18.68]],"id":52671549},{"atb":[[1.36,72.66],[1.21,498.26],[1.26,301.83],[1.31,168.77]],"id":52671548},{"atb":[[17,1.64],[12,7.14],[9.8,11.89],[14.5,3.88]],"id":52671542},{"atb":[[34,3.17],[85,0.31],[44,1.83],[60,0.88]],"id":52671545},{"atb":[[6.8,18.04],[9.8,2.97],[8.8,6.71],[7.8,11.54]],"id":52671544},{"atb":[[170,0.16],[85,0.94],[120,0.44],[60,1.77]],"id":52671556}],"con":true,"img":false}]}
{"op":"mcm","clk":"11449099376","pt":1717303849458,"mc":[{"id":"1.229554898","rc":[{"atb":[[9.6,28.36],[14,8.04]],"id":52671550},{"atb":[[320,0.32],[220,1.11]],"id":52671546},{"atb":[[4.4,71.73],[5.4,23.75]],"id":52671549},{"atb":[[1.21,996.03],[1.11,2217.31]],"id":52671548},{"atb":[[9,13.06],[7,40.65]],"id":52671542},{"atb":[[21,5.22],[15.5,16.82]],"id":52671545},{"atb":[[5.7,22.24],[4.7,65.92]],"id":52671544},{"atb":[[7.4,38.1],[9.4,12.44]],"id":52671555},{"atb":[[3.2,110.86],[3.7,38.71]],"id":52671554},{"atb":[[46,2.32],[28,9.03]],"id":52671556}],"con":true,"img":false}]}
{"op":"mcm","clk":"11449115773","pt":1717304301299,"mc":[{"id":"1.229554898","rc":[{"atb":[[300,0],[150,0],[200,0],[250,0]],"id":52671546},{"atb":[[1.36,0],[1.21,497.76],[1.26,0],[1.31,0]],"id":52671548},{"atb":[[17,0],[12,0],[9.8,0],[14.5,0]],"id":52671542},{"atb":[[6.8,0],[9.8,0],[8.8,0],[7.8,0]],"id":52671544},{"atb":[[17,0],[19.5,0],[12,0],[14.5,0]],"id":52671555},{"atb":[[5.6,0],[5.1,0],[4.6,0],[4.1,0]],"id":52671554},{"atb":[[170,0],[85,0],[120,0],[60,0]],"id":52671556}],"con":true,"img":false}]}
{"op":"mcm","clk":"11449115798","pt":1717304302021,"mc":[{"id":"1.229554898","rc":[{"atb":[[260,0.2],[310,0.08],[160,0.66],[210,0.38]],"id":52671546},{"atb":[[1.28,280.27],[1.23,454.94],[1.33,158.54],[1.38,68.84]],"id":52671548},{"atb":[[7.2,16.88],[9.2,6.38],[10.5,2.75],[8.2,10.9]],"id":52671544}],"con":true,"img":false}]}
{"op":"mcm","clk":"11449115803","pt":1717304302074,"mc":[{"id":"1.229554898","rc":[{"atb":[[18,1.54],[10.5,11.01],[13,6.54],[15.5,3.61]],"id":52671542},{"atb":[[160,0.16],[80,0.99],[110,0.48],[55,1.94]],"id":52671556}],"con":true,"img":false}]}
{"op":"mcm","clk":"11449128742","pt":1717304417739,"mc":[{"id":"1.229554898","rc":[{"atb":[[1.28,0],[1.23,0],[1.33,0],[1.38,0]],"id":52671548},{"atb":[[18,0],[10.5,0],[13,0],[15.5,0]],"id":52671542}],"con":true,"img":false}]}
{"op":"mcm","clk":"11449128749","pt":1717304417843,"mc":[{"id":"1.229554898","rc":[{"atb":[[260,0],[310,0],[160,0],[210,0]],"id":52671546},{"atb":[[7.2,0],[9.2,0],[10.5,0],[8.2,0]],"id":52671544}],"con":true,"img":false}]}
{"op":"mcm","clk":"11449128781","pt":1717304418458,"mc":[{"id":"1.229554898","rc":[{"atb":[[1.36,72.66],[1.21,996.03],[1.26,301.83],[1.31,168.77]],"id":52671548},{"atb":[[17,1.64],[12,7.14],[9.8,11.89],[14.5,3.88]],"id":52671542}],"con":true,"img":false}]}
{"op":"mcm","clk":"11449128786","pt":1717304418561,"mc":[{"id":"1.229554898","rc":[{"atb":[[300,0.09],[150,0.7],[200,0.39],[250,0.21]],"id":52671546},{"atb":[[6.8,18.04],[9.8,2.97],[8.8,6.71],[7.8,11.54]],"id":52671544}],"con":true,"img":false}]}
{"op":"mcm","clk":"11449219107","pt":1717305748353,"mc":[{"id":"1.229554898","rc":[{"atb":[[1.36,0],[1.21,497.76],[1.26,0],[1.31,0]],"id":52671548},{"atb":[[17,0],[12,0],[9.8,0],[14.5,0]],"id":52671542}],"con":true,"img":false}]}
{"op":"mcm","clk":"11449219116","pt":1717305748455,"mc":[{"id":"1.229554898","rc":[{"atb":[[300,0],[150,0],[200,0],[250,0]],"id":52671546},{"atb":[[6.8,0],[9.8,0],[8.8,0],[7.8,0]],"id":52671544}],"con":true,"img":false}]}
{"op":"mcm","clk":"11449219160","pt":1717305749067,"mc":[{"id":"1.229554898","rc":[{"atb":[[1.28,280.27],[1.23,454.94],[1.33,158.54],[1.38,68.84]],"id":52671548},{"atb":[[18,1.54],[10.5,11.01],[13,6.54],[15.5,3.61]],"id":52671542}],"con":true,"img":false}]}
{"op":"mcm","clk":"11449219169","pt":1717305749173,"mc":[{"id":"1.229554898","rc":[{"atb":[[260,0.2],[310,0.08],[160,0.66],[210,0.38]],"id":52671546},{"atb":[[7.2,16.88],[10.5,2.75],[8.2,10.9]],"id":52671544}],"con":true,"img":false}]}
{"op":"mcm","clk":"11449219177","pt":1717305749274,"mc":[{"id":"1.229554898","rc":[{"atb":[[9.2,6.38]],"id":52671544}],"con":true,"img":false}]}
{"op":"mcm","clk":"11449232501","pt":1717305940320,"mc":[{"id":"1.229554898","rc":[{"atb":[[260,0],[310,0],[160,0],[210,0]],"id":52671546},{"atb":[[1.28,0],[1.23,0],[1.33,0],[1.38,0]],"id":52671548},{"atb":[[7.2,0],[9.2,0],[10.5,0],[8.2,0]],"id":52671544},{"atb":[[160,0],[80,0],[110,0],[55,0]],"id":52671556}],"con":true,"img":false}]}
{"op":"mcm","clk":"11449232544","pt":1717305940989,"mc":[{"id":"1.229554898","rc":[{"atb":[[300,0.09],[150,0.7],[200,0.39],[250,0.21]],"id":52671546},{"atb":[[1.36,72.66],[1.21,996.03],[1.26,301.83],[1.31,168.77]],"id":52671548},{"atb":[[6.8,18.04],[9.8,2.97],[8.8,6.71],[7.8,11.54]],"id":52671544},{"atb":[[170,0.16],[85,0.94],[120,0.44],[60,1.77]],"id":52671556}],"con":true,"img":false}]}
{"op":"mcm","clk":"11449238879","pt":1717306033922,"mc":[{"id":"1.229554898","rc":[{"atb":[[170,0],[85,0],[120,0],[60,0]],"id":52671556}],"con":true,"img":false}]}
{"op":"mcm","clk":"11449238917","pt":1717306034644,"mc":[{"id":"1.229554898","rc":[{"atb":[[160,0.16],[80,0.99],[110,0.48],[55,1.94]],"id":52671556}],"con":true,"img":false}]}
{"op":"mcm","clk":"11449308160","pt":1717306957906,"mc":[{"id":"1.229554898","rc":[{"atb":[[9.6,0],[14,0]],"id":52671550},{"atb":[[320,0],[220,0]],"id":52671546},{"atb":[[4.4,0],[5.4,0]],"id":52671549},{"atb":[[1.21,498.26],[1.11,0]],"id":52671548},{"atb":[[9,0],[7,0]],"id":52671542},{"atb":[[21,0],[15.5,0]],"id":52671545},{"atb":[[5.7,0],[4.7,0]],"id":52671544},{"atb":[[7.4,0],[9.4,0]],"id":52671555},{"atb":[[3.2,0],[3.7,0]],"id":52671554},{"atb":[[46,0],[28,0]],"id":52671556}],"con":true,"img":false}]}
{"op":"mcm","clk":"11449308947","pt":1717306969076,"mc":[{"id":"1.229554898","rc":[{"atb":[[9.6,28.36],[14,8.04]],"id":52671550},{"atb":[[310,0.34],[210,1.16]],"id":52671546},{"atb":[[5.7,22.24],[4.7,65.92]],"id":52671549},{"atb":[[1.18,580.72],[1.08,3048.81]],"id":52671548},{"atb":[[6.8,42.05],[8.8,13.4]],"id":52671542},{"atb":[[16,16.26],[22,4.97]],"id":52671545},{"atb":[[5.6,22.72],[4.6,67.75]],"id":52671544},{"atb":[[7.4,38.1],[9.4,12.44]],"id":52671555},{"atb":[[3.85,36.67],[3.35,103.78]],"id":52671554},{"atb":[[32,7.86],[55,3.87]],"id":52671556}],"con":true,"img":false}]}
{"op":"mcm","clk":"11449311194","pt":1717307001936,"mc":[{"id":"1.229554898","rc":[{"atb":[[9.6,0],[14,0]],"id":52671550},{"atb":[[310,0],[210,0]],"id":52671546},{"atb":[[5.7,0],[4.7,0]],"id":52671549},{"atb":[[1.18,0],[1.08,0]],"id":52671548},{"atb":[[6.8,0],[8.8,0]],"id":52671542},{"atb":[[16,0],[22,0]],"id":52671545},{"atb":[[5.6,0],[4.6,0]],"id":52671544},{"atb":[[7.4,0],[9.4,0]],"id":52671555},{"atb":[[3.85,0],[3.35,0]],"id":52671554},{"atb":[[32,0],[55,1.94]],"id":52671556}],"con":true,"img":false}]}
{"op":"mcm","clk":"11449313172","pt":1717307031265,"mc":[{"id":"1.229554898","rc":[{"atb":[[9.6,28.36],[14,8.04]],"id":52671550},{"atb":[[5.7,22.24],[4.7,65.92]],"id":52671549},{"atb":[[7.4,38.1],[9.4,12.44]],"id":52671555},{"atb":[[3.85,36.67],[3.35,103.78]],"id":52671554},{"atb":[[32,7.86],[55,3.87]],"id":52671556}],"con":true,"img":false}]}
{"op":"mcm","clk":"11449313193","pt":1717307031577,"mc":[{"id":"1.229554898","rc":[{"atb":[[310,0.34],[210,1.16]],"id":52671546},{"atb":[[1.18,580.72],[1.08,3048.81]],"id":52671548},{"atb":[[6.8,42.05],[8.8,13.4]],"id":52671542},{"atb":[[16,16.26],[22,4.97]],"id":52671545},{"atb":[[5.6,22.72],[4.6,67.75]],"id":52671544}],"con":true,"img":false}]}
{"op":"mcm","clk":"11449319014","pt":1717307115947,"mc":[{"id":"1.229554898","rc":[{"atb":[[9.6,0],[14,0]],"id":52671550},{"atb":[[310,0],[210,0]],"id":52671546},{"atb":[[5.7,0],[4.7,0]],"id":52671549},{"atb":[[1.18,0],[1.08,0]],"id":52671548},{"atb":[[6.8,0],[8.8,0]],"id":52671542},{"atb":[[16,0],[22,0]],"id":52671545},{"atb":[[5.6,0],[4.6,0]],"id":52671544},{"atb":[[7.4,0],[9.4,0]],"id":52671555},{"atb":[[3.85,0],[3.35,0]],"id":52671554},{"atb":[[32,0],[55,1.94]],"id":52671556}],"con":true,"img":false}]}
{"op":"mcm","clk":"11449319896","pt":1717307127145,"mc":[{"id":"1.229554898","rc":[{"atb":[[9.6,28.36],[14,8.04]],"id":52671550},{"atb":[[320,0.32],[220,1.11]],"id":52671546},{"atb":[[5.6,22.72],[4.6,67.75]],"id":52671549},{"atb":[[1.07,3484.35],[1.17,614.88]],"id":52671548},{"atb":[[6.8,42.05],[8.8,13.4]],"id":52671542},{"atb":[[16,16.26],[22,4.97]],"id":52671545},{"atb":[[5.7,22.24],[4.7,65.92]],"id":52671544},{"atb":[[7.4,38.1],[9.4,12.44]],"id":52671555},{"atb":[[3.4,101.62],[3.9,36.04]],"id":52671554},{"atb":[[32,7.86],[55,3.87]],"id":52671556}],"con":true,"img":false}]}
{"op":"mcm","clk":"11449321804","pt":1717307154576,"mc":[{"id":"1.229554898","rc":[{"atb":[[9.6,0],[14,0]],"id":52671550},{"atb":[[320,0],[220,0]],"id":52671546},{"atb":[[5.6,0],[4.6,0]],"id":52671549},{"atb":[[1.07,0],[1.17,0]],"id":52671548},{"atb":[[6.8,0],[8.8,0]],"id":52671542},{"atb":[[16,0],[22,0]],"id":52671545},{"atb":[[5.7,0],[4.7,0]],"id":52671544},{"atb":[[7.4,0],[9.4,0]],"id":52671555},{"atb":[[3.4,0],[3.9,0]],"id":52671554},{"atb":[[32,0],[55,1.94]],"id":52671556}],"con":true,"img":false}]}
{"op":"mcm","clk":"11449323273","pt":1717307173917,"mc":[{"id":"1.229554898","rc":[{"atb":[[280,0.87],[380,0.27]],"id":52671546},{"atb":[[1.16,653.31],[1.06,4065.08]],"id":52671548},{"atb":[[6.8,42.05],[8.8,13.4]],"id":52671542},{"atb":[[16,16.26],[22,4.97]],"id":52671545},{"atb":[[5.6,22.72],[4.6,67.75]],"id":52671544}],"con":true,"img":false}]}
{"op":"mcm","clk":"11449323283","pt":1717307174018,"mc":[{"id":"1.229554898","rc":[{"atb":[[9.8,27.71],[14.5,7.74]],"id":52671550},{"atb":[[5.6,22.72],[4.6,67.75]],"id":52671549},{"atb":[[9.6,12.15],[7.6,36.95]],"id":52671555},{"atb":[[3.85,36.67],[3.35,103.78]],"id":52671554},{"atb":[[75,1.41],[40,6.25]],"id":52671556}],"con":true,"img":false}]}
{"op":"mcm","clk":"11449325495","pt":1717307202836,"mc":[{"id":"1.229554898","rc":[{"atb":[[9.6,0],[8.6,0],[7.6,0],[6.6,0]],"id":52671549},{"atb":[[34,0],[85,0],[44,0],[60,0]],"id":52671545}],"con":true,"img":false}]}
{"op":"mcm","clk":"11449325501","pt":1717307202861,"mc":[{"id":"1.229554898","rc":[{"atb":[[1.36,0],[1.21,0],[1.26,0],[1.31,0]],"id":52671548}],"con":true,"img":false}]}
{"op":"mcm","clk":"11449325504","pt":1717307202966,"mc":[{"id":"1.229554898","rc":[{"atb":[[160,0],[80,0],[110,0],[55,0]],"id":52671556}],"con":true,"img":false}]}
{"op":"mcm","clk":"11449325552","pt":1717307203538,"mc":[{"id":"1.229554898","rc":[{"atb":[[11,2.62],[7.4,16.35],[8.4,10.61],[9.4,6.23]],"id":52671549},{"atb":[[1.19,550.71],[1.29,180.41],[1.34,76.94],[1.24,326.99]],"id":52671548},{"atb":[[70,0.76],[38,2.83],[95,0.28],[48,1.67]],"id":52671545}],"con":true,"img":false}]}
{"op":"mcm","clk":"11449325561","pt":1717307203650,"mc":[{"id":"1.229554898","rc":[{"atb":[[140,0.38],[70,1.52],[190,0.14],[95,0.84]],"id":52671556}],"con":true,"img":false}]}
{"op":"mcm","clk":"11449351053","pt":1717307662922,"mc":[{"id":"1.229554898","rc":[{"atb":[[300,0],[150,0],[200,0],[250,0]],"id":52671546},{"atb":[[1.19,0],[1.29,0],[1.34,0],[1.24,0]],"id":52671548},{"atb":[[6.8,0],[9.8,0],[8.8,0],[7.8,0]],"id":52671544}],"con":true,"img":false}]}
{"op":"mcm","clk":"11449351085","pt":1717307663591,"mc":[{"id":"1.229554898","rc":[{"atb":[[260,0.2],[310,0.08],[160,0.66],[210,0.38]],"id":52671546},{"atb":[[1.2,523.18],[1.25,313.91],[1.3,174.39],[1.35,74.74]],"id":52671548},{"atb":[[7.2,16.88],[9.2,6.38],[10.5,2.75],[8.2,10.9]],"id":52671544}],"con":true,"img":false}]}
{"op":"mcm","clk":"11449368319","pt":1717308059112,"mc":[{"id":"1.229554898","rc":[{"atb":[[9.8,0],[14.5,0]],"id":52671550},{"atb":[[280,0],[380,0]],"id":52671546},{"atb":[[5.6,0],[4.6,0]],"id":52671549},{"atb":[[1.16,0],[1.06,0]],"id":52671548},{"atb":[[6.8,0],[8.8,0]],"id":52671542},{"atb":[[16,0],[22,0]],"id":52671545},{"atb":[[5.6,0],[4.6,0]],"id":52671544},{"atb":[[9.6,0],[7.6,0]],"id":52671555},{"atb":[[3.85,0],[3.35,0]],"id":52671554},{"atb":[[75,0],[40,0]],"id":52671556}],"con":true,"img":false}]}
{"op":"mcm","clk":"11449369781","pt":1717308089125,"mc":[{"id":"1.229554898","rc":[{"atb":[[9.8,27.71],[14.5,7.74]],"id":52671550},{"atb":[[280,0.87],[380,0.27]],"id":52671546},{"atb":[[5.6,22.72],[4.6,67.75]],"id":52671549},{"atb":[[1.16,653.31],[1.06,4065.08]],"id":52671548},{"atb":[[6.8,42.05],[8.8,13.4]],"id":52671542},{"atb":[[16,16.26],[22,4.97]],"id":52671545},{"atb":[[5.6,22.72],[4.6,67.75]],"id":52671544},{"atb":[[9.6,12.15],[7.6,36.95]],"id":52671555},{"atb":[[3.85,36.67],[3.35,103.78]],"id":52671554},{"atb":[[75,1.41],[40,6.25]],"id":52671556}],"con":true,"img":false}]}
{"op":"mcm","clk":"11449374378","pt":1717308195176,"mc":[{"id":"1.229554898","rc":[{"atb":[[1.2,0],[1.25,0],[1.3,0],[1.35,0]],"id":52671548}],"con":true,"img":false}]}
{"op":"mcm","clk":"11449374407","pt":1717308196000,"mc":[{"id":"1.229554898","rc":[{"atb":[[1.19,550.71],[1.29,180.41],[1.34,76.94],[1.24,326.99]],"id":52671548}],"con":true,"img":false}]}
{"op":"mcm","clk":"11449404193","pt":1717308664187,"mc":[{"id":"1.229554898","rc":[{"atb":[[34,0],[18.5,0],[22,0],[27,0]],"id":52671550},{"atb":[[140,0],[70,0],[190,0],[95,0]],"id":52671556}],"con":true,"img":false}]}
{"op":"mcm","clk":"11449404241","pt":1717308664964,"mc":[{"id":"1.229554898","rc":[{"atb":[[40,0.67],[20,5.51],[25,3.27],[30,1.81]],"id":52671550},{"atb":[[160,0.33],[80,1.32],[210,0.13],[110,0.72]],"id":52671556}],"con":true,"img":false}]}
{"op":"mcm","clk":"11449426987","pt":1717308975529,"mc":[{"id":"1.229554898","rc":[{"atb":[[34,0.8],[18.5,5.98],[40,0],[20,0],[22,3.74],[25,0],[27,2.01],[30,0]],"id":52671550},{"atb":[[130,0.41],[65,1.64],[160,0],[80,0],[180,0.15],[90,0.88],[210,0],[110,0]],"id":52671556}],"con":true,"img":false}]}
{"op":"mcm","clk":"11449440323","pt":1717309173971,"mc":[{"id":"1.229554898","rc":[{"atb":[[9.8,0],[14.5,0]],"id":52671550},{"atb":[[280,0],[380,0]],"id":52671546},{"atb":[[5.6,0],[4.6,0]],"id":52671549},{"atb":[[1.16,0],[1.06,0]],"id":52671548},{"atb":[[6.8,0],[8.8,0]],"id":52671542},{"atb":[[16,0],[22,0]],"id":52671545},{"atb":[[5.6,0],[4.6,0]],"id":52671544},{"atb":[[9.6,0],[7.6,0]],"id":52671555},{"atb":[[3.85,0],[3.35,0]],"id":52671554},{"atb":[[75,0],[40,0]],"id":52671556}],"con":true,"img":false}]}
{"op":"mcm","clk":"11449440896","pt":1717309182713,"mc":[{"id":"1.229554898","rc":[{"atb":[[9.8,27.71],[14.5,7.74]],"id":52671550},{"atb":[[280,0.87],[380,0.27]],"id":52671546},{"atb":[[5.6,22.72],[4.6,67.75]],"id":52671549},{"atb":[[1.16,653.31],[1.06,4065.08]],"id":52671548},{"atb":[[6.8,42.05],[8.8,13.4]],"id":52671542},{"atb":[[16,16.26],[22,4.97]],"id":52671545},{"atb":[[5.6,22.72],[4.6,67.75]],"id":52671544},{"atb":[[9.6,12.15],[7.6,36.95]],"id":52671555},{"atb":[[3.85,36.67],[3.35,103.78]],"id":52671554},{"atb":[[75,1.41],[40,6.25]],"id":52671556}],"con":true,"img":false}]}
{"op":"mcm","clk":"11449459031","pt":1717309460000,"mc":[{"id":"1.229554898","rc":[{"atb":[[9.8,0],[14.5,0]],"id":52671550},{"atb":[[280,0],[380,0]],"id":52671546},{"atb":[[5.6,0],[4.6,0]],"id":52671549},{"atb":[[1.16,0],[1.06,0]],"id":52671548},{"atb":[[6.8,0],[8.8,0]],"id":52671542},{"atb":[[16,0],[22,0]],"id":52671545},{"atb":[[5.6,0],[4.6,0]],"id":52671544},{"atb":[[9.6,0],[7.6,0]],"id":52671555},{"atb":[[3.85,0],[3.35,0]],"id":52671554},{"atb":[[75,0],[40,0]],"id":52671556}],"con":true,"img":false}]}
{"op":"mcm","clk":"11449460685","pt":1717309485524,"mc":[{"id":"1.229554898","rc":[{"atb":[[550,0.18],[450,0.54]],"id":52671546},{"atb":[[1.12,871.08],[1.02,12195.24]],"id":52671548},{"atb":[[9,13.06],[7,40.65]],"id":52671542},{"atb":[[17,15.24],[24,4.54]],"id":52671545},{"atb":[[5.7,22.24],[4.7,65.92]],"id":52671544}],"con":true,"img":false}]}
{"op":"mcm","clk":"11449461424","pt":1717309496544,"mc":[{"id":"1.229554898","rc":[{"atb":[[10.5,25.67],[15.5,7.2]],"id":52671550},{"atb":[[4.8,64.18],[5.8,21.77]],"id":52671549},{"atb":[[10.5,11],[8.2,33.87]],"id":52671555},{"atb":[[4,34.84],[3.5,97.56]],"id":52671554},{"atb":[[160,0.65],[80,3.08]],"id":52671556}],"con":true,"img":false}]}
{"op":"mcm","clk":"11449493624","pt":1717309849789,"mc":[{"id":"1.229554898","rc":[{"atb":[[130,0],[65,0],[180,0],[90,0]],"id":52671556}],"con":true,"img":false}]}
{"op":"mcm","clk":"11449493662","pt":1717309850463,"mc":[{"id":"1.229554898","rc":[{"atb":[[140,0.38],[70,1.52],[190,0.14],[95,0.84]],"id":52671556}],"con":true,"img":false}]}
{"op":"mcm","clk":"11449497950","pt":1717309919042,"mc":[{"id":"1.229554898","rc":[{"atb":[[260,0],[310,0],[160,0],[210,0]],"id":52671546},{"atb":[[1.19,0],[1.29,0],[1.34,0],[1.24,0]],"id":52671548},{"atb":[[70,0],[38,0],[95,0],[48,0]],"id":52671545}],"con":true,"img":false}]}
{"op":"mcm","clk":"11449497993","pt":1717309919718,"mc":[{"id":"1.229554898","rc":[{"atb":[[270,0.19],[320,0.08],[170,0.62],[220,0.36]],"id":52671546},{"atb":[[1.28,186.85],[1.18,581.31],[1.23,341.2],[1.33,79.27]],"id":52671548},{"atb":[[80,0.66],[42,2.55],[110,0.24],[55,1.45]],"id":52671545}],"con":true,"img":false}]}
{"op":"mcm","clk":"11449520993","pt":1717310304249,"mc":[{"id":"1.229554898","rc":[{"atb":[[10.5,0],[15.5,0]],"id":52671550},{"atb":[[550,0],[450,0]],"id":52671546},{"atb":[[4.8,0],[5.8,0]],"id":52671549},{"atb":[[1.12,0],[1.02,0]],"id":52671548},{"atb":[[9,0],[7,0]],"id":52671542},{"atb":[[17,0],[24,0]],"id":52671545},{"atb":[[5.7,0],[4.7,0]],"id":52671544},{"atb":[[10.5,0],[8.2,0]],"id":52671555},{"atb":[[4,0],[3.5,0]],"id":52671554},{"atb":[[160,0],[80,0]],"id":52671556}],"con":true,"img":false}]}
{"op":"mcm","clk":"11449522629","pt":1717310330822,"mc":[{"id":"1.229554898","rc":[{"atb":[[10.5,25.67],[15.5,7.2]],"id":52671550},{"atb":[[550,0.18],[450,0.54]],"id":52671546},{"atb":[[4.8,64.18],[5.8,21.77]],"id":52671549},{"atb":[[1.12,871.08],[1.02,12195.24]],"id":52671548},{"atb":[[9,13.06],[7,40.65]],"id":52671542},{"atb":[[17,15.24],[24,4.54]],"id":52671545},{"atb":[[5.7,22.24],[4.7,65.92]],"id":52671544},{"atb":[[10.5,11],[8.2,33.87]],"id":52671555},{"atb":[[4,34.84],[3.5,97.56]],"id":52671554},{"atb":[[160,0.65],[80,3.08]],"id":52671556}],"con":true,"img":false}]}
{"op":"mcm","clk":"11449544572","pt":1717310699456,"mc":[{"id":"1.229554898","rc":[{"atb":[[1.28,0]],"id":52671548}],"con":true,"img":false}]}
{"op":"mcm","clk":"11449544579","pt":1717310699557,"mc":[{"id":"1.229554898","rc":[{"atb":[[1.18,0],[1.23,0],[1.33,0]],"id":52671548}],"con":true,"img":false}]}
{"op":"mcm","clk":"11449544615","pt":1717310700178,"mc":[{"id":"1.229554898","rc":[{"atb":[[1.29,180.41]],"id":52671548}],"con":true,"img":false}]}
{"op":"mcm","clk":"11449544624","pt":1717310700280,"mc":[{"id":"1.229554898","rc":[{"atb":[[1.19,550.71],[1.34,76.94],[1.24,326.99]],"id":52671548}],"con":true,"img":false}]}
{"op":"mcm","clk":"11449553993","pt":1717310860906,"mc":[{"id":"1.229554898","rc":[{"atb":[[1.19,0],[1.29,0],[1.34,0],[1.24,0]],"id":52671548}],"con":true,"img":false}]}
{"op":"mcm","clk":"11449554046","pt":1717310861680,"mc":[{"id":"1.229554898","rc":[{"atb":[[1.28,186.85],[1.18,581.31],[1.23,341.2],[1.33,79.27]],"id":52671548}],"con":true,"img":false}]}
{"op":"mcm","clk":"11449569998","pt":1717311155456,"mc":[{"id":"1.229554898","rc":[{"atb":[[10.5,0],[15.5,0]],"id":52671550},{"atb":[[550,0],[450,0]],"id":52671546},{"atb":[[4.8,0],[5.8,0]],"id":52671549},{"atb":[[1.12,0],[1.02,0]],"id":52671548},{"atb":[[9,0],[7,0]],"id":52671542},{"atb":[[17,0],[24,0]],"id":52671545},{"atb":[[5.7,0],[4.7,0]],"id":52671544},{"atb":[[10.5,0],[8.2,0]],"id":52671555},{"atb":[[4,0],[3.5,0]],"id":52671554},{"atb":[[160,0],[80,0]],"id":52671556}],"con":true,"img":false}]}
{"op":"mcm","clk":"11449571351","pt":1717311180683,"mc":[{"id":"1.229554898","rc":[{"atb":[[10.5,25.67],[15.5,7.2]],"id":52671550},{"atb":[[550,0.18],[450,0.54]],"id":52671546},{"atb":[[4.8,64.18],[5.8,21.77]],"id":52671549},{"atb":[[1.12,871.08],[1.02,12195.24]],"id":52671548},{"atb":[[9,13.06],[7,40.65]],"id":52671542},{"atb":[[17,15.24],[24,4.54]],"id":52671545},{"atb":[[5.7,22.24],[4.7,65.92]],"id":52671544},{"atb":[[10.5,11],[8.2,33.87]],"id":52671555},{"atb":[[4,34.84],[3.5,97.56]],"id":52671554},{"atb":[[160,0.65],[80,3.08]],"id":52671556}],"con":true,"img":false}]}
{"op":"mcm","clk":"11449617492","pt":1717312016032,"mc":[{"id":"1.229554898","rc":[{"atb":[[10.5,0],[15.5,0]],"id":52671550},{"atb":[[550,0],[450,0]],"id":52671546},{"atb":[[4.8,0],[5.8,0]],"id":52671549},{"atb":[[1.12,0],[1.02,0]],"id":52671548},{"atb":[[9,0],[7,0]],"id":52671542},{"atb":[[17,0],[24,0]],"id":52671545},{"atb":[[5.7,0],[4.7,0]],"id":52671544},{"atb":[[10.5,0],[8.2,0]],"id":52671555},{"atb":[[4,0],[3.5,0]],"id":52671554},{"atb":[[160,0],[80,0]],"id":52671556}],"con":true,"img":false}]}
{"op":"mcm","clk":"11449619094","pt":1717312045863,"mc":[{"id":"1.229554898","rc":[{"atb":[[10.5,25.67],[15.5,7.2]],"id":52671550},{"atb":[[550,0.18],[450,0.54]],"id":52671546},{"atb":[[4.8,64.18],[5.8,21.77]],"id":52671549},{"atb":[[1.12,871.08],[1.02,12195.24]],"id":52671548},{"atb":[[9,13.06],[7,40.65]],"id":52671542},{"atb":[[17,15.24],[24,4.54]],"id":52671545},{"atb":[[5.7,22.24],[4.7,65.92]],"id":52671544},{"atb":[[10.5,11],[8.2,33.87]],"id":52671555},{"atb":[[4,34.84],[3.5,97.56]],"id":52671554},{"atb":[[160,0.65],[80,3.08]],"id":52671556}],"con":true,"img":false}]}
{"op":"mcm","clk":"11449649771","pt":1717312812786,"mc":[{"id":"1.229554898","rc":[{"atb":[[1.28,0],[1.18,0],[1.23,0],[1.33,0]],"id":52671548}],"con":true,"img":false}]}
{"op":"mcm","clk":"11449649818","pt":1717312813470,"mc":[{"id":"1.229554898","rc":[{"atb":[[1.19,550.71],[1.29,180.41],[1.34,76.94],[1.24,326.99]],"id":52671548}],"con":true,"img":false}]}
{"op":"mcm","clk":"11449652151","pt":1717312862930,"mc":[{"id":"1.229554898","rc":[{"atb":[[10.5,0],[15.5,0]],"id":52671550},{"atb":[[550,0],[450,0]],"id":52671546},{"atb":[[4.8,0],[5.8,0]],"id":52671549},{"atb":[[1.12,0],[1.02,0]],"id":52671548},{"atb":[[9,0],[7,0]],"id":52671542},{"atb":[[17,0],[24,0]],"id":52671545},{"atb":[[5.7,0],[4.7,0]],"id":52671544},{"atb":[[10.5,0],[8.2,0]],"id":52671555},{"atb":[[4,0],[3.5,0]],"id":52671554},{"atb":[[160,0],[80,0]],"id":52671556}],"con":true,"img":false}]}
{"op":"mcm","clk":"11449653366","pt":1717312890700,"mc":[{"id":"1.229554898","rc":[{"atb":[[10.5,25.67],[15.5,7.2]],"id":52671550},{"atb":[[550,0.18],[450,0.54]],"id":52671546},{"atb":[[4.8,64.18],[5.8,21.77]],"id":52671549},{"atb":[[1.12,871.08],[1.02,12195.24]],"id":52671548},{"atb":[[9,13.06],[7,40.65]],"id":52671542},{"atb":[[17,15.24],[24,4.54]],"id":52671545},{"atb":[[5.7,22.24],[4.7,65.92]],"id":52671544},{"atb":[[10.5,11],[8.2,33.87]],"id":52671555},{"atb":[[4,34.84],[3.5,97.56]],"id":52671554},{"atb":[[160,0.65],[80,3.08]],"id":52671556}],"con":true,"img":false}]}
{"op":"mcm","clk":"11449662296","pt":1717313106827,"mc":[{"id":"1.229554898","rc":[{"atb":[[34,0],[18.5,0],[22,0],[27,0]],"id":52671550},{"atb":[[270,0],[320,0],[170,0],[220,0]],"id":52671546},{"atb":[[1.19,0],[1.29,0],[1.34,0],[1.24,0]],"id":52671548},{"atb":[[140,0],[70,0],[190,0],[95,0]],"id":52671556}],"con":true,"img":false}]}
{"op":"mcm","clk":"11449662336","pt":1717313107504,"mc":[{"id":"1.229554898","rc":[{"atb":[[38,0.71],[19.5,5.66],[24,3.41],[29,1.87]],"id":52671550},{"atb":[[280,0.28],[330,0.16],[380,0.07],[230,0.46]],"id":52671546},{"atb":[[1.27,193.77],[1.32,81.75],[1.22,356.71],[1.17,615.5]],"id":52671548},{"atb":[[170,0.31],[85,1.25],[220,0.12],[120,0.66]],"id":52671556}],"con":true,"img":false}]}
{"op":"mcm","clk":"11449687827","pt":1717313536538,"mc":[{"id":"1.229554898","rc":[{"atb":[[38,0],[19.5,0],[24,0],[29,0]],"id":52671550},{"atb":[[280,0],[330,0],[380,0],[230,0]],"id":52671546}],"con":true,"img":false}]}
{"op":"mcm","clk":"11449687908","pt":1717313537473,"mc":[{"id":"1.229554898","rc":[{"atb":[[80,0],[42,0],[110,0],[55,0]],"id":52671545}],"con":true,"img":false}]}
{"op":"mcm","clk":"11449687925","pt":1717313537677,"mc":[{"id":"1.229554898","rc":[{"atb":[[32,0.84],[18,6.15],[21,3.92],[26,2.09]],"id":52671550},{"atb":[[270,0.19],[320,0.08],[170,0.62],[220,0.36]],"id":52671546}],"con":true,"img":false}]}
{"op":"mcm","clk":"11449687969","pt":1717313538144,"mc":[{"id":"1.229554898","rc":[{"atb":[[70,0.76],[38,2.83],[95,0.28],[48,1.67]],"id":52671545}],"con":true,"img":false}]}
{"op":"mcm","clk":"11449688720","pt":1717313547173,"mc":[{"id":"1.229554898","rc":[{"atb":[[70,0],[38,0],[95,0],[48,0]],"id":52671545}],"con":true,"img":false}]}
{"op":"mcm","clk":"11449688777","pt":1717313547847,"mc":[{"id":"1.229554898","rc":[{"atb":[[80,0.66],[42,2.55],[110,0.24],[55,1.45]],"id":52671545}],"con":true,"img":false}]}
{"op":"mcm","clk":"11449690539","pt":1717313568551,"mc":[{"id":"1.229554898","rc":[{"atb":[[1.27,0],[1.32,0],[1.22,0],[1.17,0]],"id":52671548}],"con":true,"img":false}]}
{"op":"mcm","clk":"11449690591","pt":1717313569273,"mc":[{"id":"1.229554898","rc":[{"atb":[[1.28,186.85],[1.18,581.31],[1.23,341.2],[1.33,79.27]],"id":52671548}],"con":true,"img":false}]}
{"op":"mcm","clk":"11449703767","pt":1717313733941,"mc":[{"id":"1.229554898","rc":[{"atb":[[10.5,0],[15.5,0]],"id":52671550},{"atb":[[550,0],[450,0]],"id":52671546},{"atb":[[4.8,0],[5.8,0]],"id":52671549},{"atb":[[1.12,0],[1.02,0]],"id":52671548},{"atb":[[9,0],[7,0]],"id":52671542},{"atb":[[17,0],[24,0]],"id":52671545},{"atb":[[5.7,0],[4.7,0]],"id":52671544},{"atb":[[10.5,0],[8.2,0]],"id":52671555},{"atb":[[4,0],[3.5,0]],"id":52671554},{"atb":[[160,0],[80,0]],"id":52671556}],"con":true,"img":false}]}
{"op":"mcm","clk":"11449706169","pt":1717313763344,"mc":[{"id":"1.229554898","rc":[{"atb":[[10.5,25.67],[15.5,7.2]],"id":52671550},{"atb":[[4.8,64.18],[5.8,21.77]],"id":52671549},{"atb":[[10.5,11],[8.2,33.87]],"id":52671555},{"atb":[[4,34.84],[3.5,97.56]],"id":52671554},{"atb":[[160,0.65],[80,3.08]],"id":52671556}],"con":true,"img":false}]}
{"op":"mcm","clk":"11449706177","pt":1717313763450,"mc":[{"id":"1.229554898","rc":[{"atb":[[550,0.18],[450,0.54]],"id":52671546},{"atb":[[1.12,871.08],[1.02,12195.24]],"id":52671548},{"atb":[[9,13.06],[7,40.65]],"id":52671542},{"atb":[[17,15.24],[24,4.54]],"id":52671545},{"atb":[[5.7,22.24],[4.7,65.92]],"id":52671544}],"con":true,"img":false}]}
{"op":"mcm","clk":"11449732635","pt":1717314051925,"mc":[{"id":"1.229554898","rc":[{"atb":[[1.28,0],[1.18,0],[1.23,0],[1.33,0]],"id":52671548},{"atb":[[80,0],[42,0],[110,0],[55,0]],"id":52671545}],"con":true,"img":false}]}
{"op":"mcm","clk":"11449732703","pt":1717314052568,"mc":[{"id":"1.229554898","rc":[{"atb":[[1.28,186.85],[1.18,581.31],[1.23,341.2],[1.33,79.27]],"id":52671548}],"con":true,"img":false}]}
{"op":"mcm","clk":"11449732715","pt":1717314052673,"mc":[{"id":"1.229554898","rc":[{"atb":[[80,0.66],[42,2.55],[110,0.24],[55,1.45]],"id":52671545}],"con":true,"img":false}]}
{"op":"mcm","clk":"11449732841","pt":1717314053963,"mc":[{"id":"1.229554898","rc":[{"atb":[[1.28,0],[1.18,0],[1.23,0],[1.33,0]],"id":52671548}],"con":true,"img":false}]}
{"op":"mcm","clk":"11449732905","pt":1717314054641,"mc":[{"id":"1.229554898","rc":[{"atb":[[1.28,186.85],[1.18,581.31],[1.23,341.2],[1.33,79.27]],"id":52671548}],"con":true,"img":false}]}
{"op":"mcm","clk":"11449733432","pt":1717314060268,"mc":[{"id":"1.229554898","rc":[{"atb":[[1.44,10.09]],"id":52671550},{"atb":[[24,2]],"id":52671546},{"atb":[[3.7,26.96]],"id":52671549},{"atl":[[530,2]],"id":52671549},{"atb":[[1.14,714.29]],"id":52671548},{"atl":[[4,2]],"id":52671548},{"atb":[[5.9,17.56]],"id":52671542},{"atl":[[800,2]],"id":52671542},{"atb":[[22,4.76]],"id":52671545},{"atb":[[3.2,27.78]],"id":52671544},{"atl":[[450,2]],"id":52671544},{"atb":[[1.44,44.88]],"id":52671555},{"atl":[[710,2]],"id":52671555},{"atb":[[2.34,74.63]],"id":52671554},{"atl":[[140,2]],"id":52671554},{"atb":[[23,2]],"id":52671556}],"con":true,"img":false}]}
{"op":"mcm","clk":"11449733654","pt":1717314062244,"mc":[{"id":"1.229554898","rc":[{"atb":[[1.28,0],[1.18,0],[1.23,0],[1.33,0]],"id":52671548}],"con":true,"img":false}]}
{"op":"mcm","clk":"11449733724","pt":1717314062971,"mc":[{"id":"1.229554898","rc":[{"atb":[[1.19,550.71],[1.29,180.41],[1.34,76.94],[1.24,326.99]],"id":52671548}],"con":true,"img":false}]}
{"op":"mcm","clk":"11449736796","pt":1717314097384,"mc":[{"id":"1.229554898","rc":[{"atb":[[4.1,26.96],[3.7,0]],"id":52671549},{"atb":[[6.8,17.24]],"id":52671542},{"atb":[[3.2,0],[3.5,27.78]],"id":52671544},{"atb":[[2.5,66.67],[2.34,0]],"id":52671554}],"con":true,"img":false}]}
{"op":"mcm","clk":"11449736805","pt":1717314097490,"mc":[{"id":"1.229554898","rc":[{"atb":[[5.9,0]],"id":52671542}],"con":true,"img":false}]}
{"op":"mcm","clk":"11449737413","pt":1717314104427,"mc":[{"id":"1.229554898","rc":[{"atb":[[24,0],[30,2]],"id":52671546},{"atl":[[4,0],[3.35,2]],"id":52671548},{"atb":[[22,0],[28,3.7]],"id":52671545},{"atb":[[23,0],[30,2]],"id":52671556}],"con":true,"img":false}]}
{"op":"mcm","clk":"11449739666","pt":1717314128524,"mc":[{"id":"1.229554898","rc":[{"atl":[[530,0],[520,2]],"id":52671549},{"atl":[[770,2],[800,0]],"id":52671542},{"atl":[[440,2],[450,0]],"id":52671544},{"atl":[[690,2],[710,0]],"id":52671555},{"atl":[[140,0],[120,2]],"id":52671554}],"con":true,"img":false}]}
{"op":"mcm","clk":"11449740193","pt":1717314134161,"mc":[{"id":"1.229554898","rc":[{"atb":[[3.5,0],[3.75,27.78]],"id":52671544},{"atb":[[2.5,0],[2.62,61.73]],"id":52671554}],"con":true,"img":false}]}
{"op":"mcm","clk":"11449741821","pt":1717314153491,"mc":[{"id":"1.229554898","rc":[{"atb":[[10.5,0],[15.5,0]],"id":52671550},{"atb":[[550,0],[450,0]],"id":52671546},{"atb":[[4.8,0],[5.8,0]],"id":52671549},{"atb":[[1.12,0],[1.02,0]],"id":52671548},{"atb":[[9,0],[7,0]],"id":52671542},{"atb":[[17,0],[24,0]],"id":52671545},{"atb":[[5.7,0],[4.7,0]],"id":52671544},{"atb":[[10.5,0],[8.2,0]],"id":52671555},{"atb":[[4,0],[3.5,0]],"id":52671554},{"atb":[[160,0],[80,0]],"id":52671556}],"con":true,"img":false}]}
{"op":"mcm","clk":"11449743681","pt":1717314174823,"mc":[{"id":"1.229554898","rc":[{"atb":[[10.5,25.67],[15.5,7.2]],"id":52671550},{"atb":[[550,0.18],[450,0.54]],"id":52671546},{"atb":[[4.8,64.18],[5.8,21.77]],"id":52671549},{"atb":[[1.12,871.08],[1.02,12195.24]],"id":52671548},{"atb":[[9,13.06],[7,40.65]],"id":52671542},{"atb":[[17,15.24],[24,4.54]],"id":52671545},{"atb":[[5.7,22.24],[4.7,65.92]],"id":52671544},{"atb":[[10.5,11],[8.2,33.87]],"id":52671555},{"atb":[[4,34.84],[3.5,97.56]],"id":52671554},{"atb":[[160,0.65],[80,3.08]],"id":52671556}],"con":true,"img":false}]}
{"op":"mcm","clk":"11449750509","pt":1717314248539,"mc":[{"id":"1.229554898","rc":[{"atb":[[2.5,66.67],[2.62,0]],"id":52671554}],"con":true,"img":false}]}
{"op":"mcm","clk":"11449760629","pt":1717314366200,"mc":[{"id":"1.229554898","rc":[{"atb":[[1.19,0],[1.29,0],[1.34,0],[1.24,0]],"id":52671548},{"atb":[[18,0],[10.5,0],[13,0],[15.5,0]],"id":52671542},{"atb":[[7.2,0],[9.2,0],[10.5,0],[8.2,0]],"id":52671544}],"con":true,"img":false}]}
{"op":"mcm","clk":"11449760637","pt":1717314366253,"mc":[{"id":"1.229554898","rc":[{"atb":[[1.13,769.23]],"id":52671548}],"con":true,"img":false}]}
{"op":"mcm","clk":"11449760646","pt":1717314366357,"mc":[{"id":"1.229554898","rc":[{"atb":[[1.14,0]],"id":52671548}],"con":true,"img":false}]}
{"op":"mcm","clk":"11449760688","pt":1717314366883,"mc":[{"id":"1.229554898","rc":[{"atb":[[1.28,186.85],[1.18,581.31],[1.23,341.2],[1.33,79.27]],"id":52671548},{"atb":[[16.5,3.37],[19,1.45],[11.5,9.97],[14,6.04]],"id":52671542},{"atb":[[11,2.62],[7.4,16.35],[8.4,10.61],[9.4,6.23]],"id":52671544}],"con":true,"img":false}]}
{"op":"mcm","clk":"11449777991","pt":1717314555822,"mc":[{"id":"1.229554898","rc":[{"atb":[[10.5,0],[15.5,0]],"id":52671550},{"atb":[[550,0],[450,0]],"id":52671546},{"atb":[[4.8,0],[5.8,0]],"id":52671549},{"atb":[[1.12,0],[1.02,0]],"id":52671548},{"atb":[[9,0],[7,0]],"id":52671542},{"atb":[[17,0],[24,0]],"id":52671545},{"atb":[[5.7,0],[4.7,0]],"id":52671544},{"atb":[[10.5,0],[8.2,0]],"id":52671555},{"atb":[[4,0],[3.5,0]],"id":52671554},{"atb":[[160,0],[80,0]],"id":52671556}],"con":true,"img":false}]}
{"op":"mcm","clk":"11449780665","pt":1717314586827,"mc":[{"id":"1.229554898","rc":[{"atb":[[10.5,25.67],[15.5,7.2]],"id":52671550},{"atb":[[550,0.18],[450,0.54]],"id":52671546},{"atb":[[4.8,64.18],[5.8,21.77]],"id":52671549},{"atb":[[1.12,871.08],[1.02,12195.24]],"id":52671548},{"atb":[[9,13.06],[7,40.65]],"id":52671542},{"atb":[[17,15.24],[24,4.54]],"id":52671545},{"atb":[[5.7,22.24],[4.7,65.92]],"id":52671544},{"atb":[[10.5,11],[8.2,33.87]],"id":52671555},{"atb":[[4,34.84],[3.5,97.56]],"id":52671554},{"atb":[[160,0.65],[80,3.08]],"id":52671556}],"con":true,"img":false}]}
{"op":"mcm","clk":"11449808495","pt":1717314915068,"mc":[{"id":"1.229554898","rc":[{"atb":[[10.5,0],[15.5,0]],"id":52671550},{"atb":[[550,0],[450,0]],"id":52671546},{"atb":[[4.8,0],[5.8,0]],"id":52671549},{"atb":[[1.12,0],[1.02,0]],"id":52671548},{"atb":[[9,0],[7,0]],"id":52671542},{"atb":[[17,0],[24,0]],"id":52671545},{"atb":[[5.7,0],[4.7,0]],"id":52671544},{"atb":[[10.5,0],[8.2,0]],"id":52671555},{"atb":[[4,0],[3.5,0]],"id":52671554},{"atb":[[160,0],[80,0]],"id":52671556}],"con":true,"img":false}]}
{"op":"mcm","clk":"11449812789","pt":1717314962632,"mc":[{"id":"1.229554898","rc":[{"atb":[[10.5,25.67],[15.5,7.2]],"id":52671550},{"atb":[[550,0.18],[450,0.54]],"id":52671546},{"atb":[[4.8,64.18],[5.8,21.77]],"id":52671549},{"atb":[[1.12,871.08],[1.02,12195.24]],"id":52671548},{"atb":[[9,13.06],[7,40.65]],"id":52671542},{"atb":[[17,15.24],[24,4.54]],"id":52671545},{"atb":[[5.7,22.24],[4.7,65.92]],"id":52671544},{"atb":[[10.5,11],[8.2,33.87]],"id":52671555},{"atb":[[4,34.84],[3.5,97.56]],"id":52671554},{"atb":[[160,0.65],[80,3.08]],"id":52671556}],"con":true,"img":false}]}
{"op":"mcm","clk":"11449815546","pt":1717314993792,"mc":[{"id":"1.229554898","rc":[{"atb":[[1.02,101.4]],"id":52671550},{"atl":[[990,1.86]],"id":52671550},{"atb":[[1.04,148.27]],"id":52671546},{"atb":[[1.04,144.86]],"id":52671549},{"atl":[[960,0.96]],"id":52671549},{"atb":[[1.02,12305.17]],"id":52671548},{"atl":[[990,1.49]],"id":52671548},{"atb":[[1.03,76.69]],"id":52671542},{"atl":[[980,1.7]],"id":52671542},{"atb":[[1.03,150.83]],"id":52671545},{"atl":[[960,1.99]],"id":52671545},{"atb":[[1.02,157.64]],"id":52671544},{"atl":[[960,1.07]],"id":52671544},{"atb":[[1.03,154.23]],"id":52671555},{"atl":[[970,1.95]],"id":52671555},{"atb":[[1.04,139.75]],"id":52671554},{"atl":[[990,1.49]],"id":52671554},{"atb":[[1.03,85.21]],"id":52671556}],"con":true,"img":false}]}
{"op":"mcm","clk":"11449815568","pt":1717314993989,"mc":[{"id":"1.229554898","rc":[{"atl":[[520,0],[530,2]],"id":52671549},{"atl":[[4,4],[3.35,0]],"id":52671548},{"atl":[[770,0],[800,2]],"id":52671542},{"atl":[[440,0],[450,2]],"id":52671544},{"atl":[[690,0],[710,2]],"id":52671555},{"atl":[[140,2],[120,0]],"id":52671554}],"con":true,"img":false}]}
{"op":"mcm","clk":"11449851204","pt":1717315295685,"mc":[{"id":"1.229554898","rc":[{"atb":[[10.5,0],[15.5,0]],"id":52671550},{"atb":[[550,0],[450,0]],"id":52671546},{"atb":[[4.8,0],[5.8,0]],"id":52671549},{"atb":[[1.12,0],[1.02,109.92]],"id":52671548},{"atb":[[9,0],[7,0]],"id":52671542},{"atb":[[17,0],[24,0]],"id":52671545},{"atb":[[5.7,0],[4.7,0]],"id":52671544},{"atb":[[10.5,0],[8.2,0]],"id":52671555},{"atb":[[4,0],[3.5,0]],"id":52671554},{"atb":[[160,0],[80,0]],"id":52671556}],"con":true,"img":false}]}
{"op":"mcm","clk":"11449851225","pt":1717315295887,"mc":[{"id":"1.229554898","rc":[{"atb":[[1.44,0],[1.04,154.24]],"id":52671555},{"atb":[[2.5,0],[1.85,117.65]],"id":52671554}],"con":true,"img":false}]}
{"op":"mcm","clk":"11449854732","pt":1717315331455,"mc":[{"id":"1.229554898","rc":[{"atb":[[10.5,25.67],[15.5,7.2]],"id":52671550},{"atb":[[550,0.18],[450,0.54]],"id":52671546},{"atb":[[4.8,64.18],[5.8,21.77]],"id":52671549},{"atb":[[1.12,871.08],[1.02,12305.17]],"id":52671548},{"atb":[[9,13.06],[7,40.65]],"id":52671542},{"atb":[[17,15.24],[24,4.54]],"id":52671545},{"atb":[[5.7,22.24],[4.7,65.92]],"id":52671544},{"atb":[[10.5,11],[8.2,33.87]],"id":52671555},{"atb":[[4,34.84],[3.5,97.56]],"id":52671554},{"atb":[[160,0.65],[80,3.08]],"id":52671556}],"con":true,"img":false}]}
{"op":"mcm","clk":"11449854743","pt":1717315331558,"mc":[{"id":"1.229554898","rc":[{"atb":[[1.44,154.24]],"id":52671555},{"atb":[[2.5,66.67]],"id":52671554}],"con":true,"img":false}]}
{"op":"mcm","clk":"11449854752","pt":1717315331659,"mc":[{"id":"1.229554898","rc":[{"atb":[[1.04,0]],"id":52671555},{"atb":[[1.85,0]],"id":52671554}],"con":true,"img":false}]}
{"op":"mcm","clk":"11449866498","pt":1717315447076,"mc":[{"id":"1.229554898","rc":[{"atb":[[4.6,27.78],[4.1,0]],"id":52671549},{"atl":[[530,0],[540,2]],"id":52671549},{"atl":[[4,0],[3.35,2.75]],"id":52671548},{"atl":[[800,0],[820,2]],"id":52671542},{"atl":[[450,0],[460,2]],"id":52671544},{"atl":[[710,0],[720,2]],"id":52671555},{"atb":[[2.5,0],[2.7,58.82]],"id":52671554},{"atl":[[140,0],[150,2]],"id":52671554}],"con":true,"img":false}]}
{"op":"mcm","clk":"11449866641","pt":1717315448473,"mc":[{"id":"1.229554898","rc":[{"atl":[[540,0],[520,2]],"id":52671549},{"atl":[[690,2],[720,0]],"id":52671555}],"con":true,"img":false}]}
{"op":"mcm","clk":"11449867051","pt":1717315452186,"mc":[{"id":"1.229554898","rc":[{"atl":[[3.75,5.5]],"id":52671548}],"con":true,"img":false}]}
{"op":"mcm","clk":"11449867058","pt":1717315452236,"mc":[{"id":"1.229554898","rc":[{"atl":[[3.35,0]],"id":52671548}],"con":true,"img":false}]}
{"op":"mcm","clk":"11449868928","pt":1717315470271,"mc":[{"id":"1.229554898","rc":[{"atl":[[770,2]],"id":52671542},{"atl":[[440,2]],"id":52671544}],"con":true,"img":false}]}
{"op":"mcm","clk":"11449868942","pt":1717315470376,"mc":[{"id":"1.229554898","rc":[{"atl":[[820,0]],"id":52671542},{"atl":[[460,0]],"id":52671544},{"atl":[[150,0],[120,2]],"id":52671554}],"con":true,"img":false}]}
{"op":"mcm","clk":"11449878899","pt":1717315568422,"mc":[{"id":"1.229554898","rc":[{"atl":[[530,2]],"id":52671549},{"atl":[[4,11],[3.75,0]],"id":52671548},{"atl":[[770,0],[800,2]],"id":52671542},{"atl":[[440,0],[450,2]],"id":52671544},{"atl":[[690,0],[710,2]],"id":52671555},{"atb":[[2.5,66.67],[2.7,0]],"id":52671554},{"atl":[[140,2],[120,0]],"id":52671554}],"con":true,"img":false}]}
{"op":"mcm","clk":"11449878912","pt":1717315568522,"mc":[{"id":"1.229554898","rc":[{"atl":[[520,0]],"id":52671549}],"con":true,"img":false}]}
{"op":"mcm","clk":"11449893610","pt":1717315712303,"mc":[{"id":"1.229554898","rc":[{"atb":[[10.5,0],[15.5,0]],"id":52671550},{"atb":[[550,0],[450,0]],"id":52671546},{"atb":[[4.8,0],[5.8,0]],"id":52671549},{"atb":[[1.12,0],[1.02,109.92]],"id":52671548},{"atb":[[9,0],[7,0]],"id":52671542},{"atb":[[17,0],[24,0]],"id":52671545},{"atb":[[5.7,0],[4.7,0]],"id":52671544},{"atb":[[10.5,0],[8.2,0]],"id":52671555},{"atb":[[4,0],[3.5,0]],"id":52671554},{"atb":[[160,0],[80,0]],"id":52671556}],"con":true,"img":false}]}
{"op":"mcm","clk":"11449893637","pt":1717315712464,"mc":[{"id":"1.229554898","rc":[{"atb":[[1.44,0],[1.04,308.48]],"id":52671555},{"atb":[[2.5,0],[1.85,117.65]],"id":52671554}],"con":true,"img":false}]}
{"op":"mcm","clk":"11449899234","pt":1717315764715,"mc":[{"id":"1.229554898","rc":[{"atb":[[10.5,25.67],[15.5,7.2]],"id":52671550},{"atb":[[550,0.18],[450,0.54]],"id":52671546},{"atb":[[4.8,64.18],[5.8,21.77]],"id":52671549},{"atb":[[1.12,871.08],[1.02,12305.17]],"id":52671548},{"atb":[[9,13.06],[7,40.65]],"id":52671542},{"atb":[[17,15.24],[24,4.54]],"id":52671545},{"atb":[[5.7,22.24],[4.7,65.92]],"id":52671544},{"atb":[[10.5,11],[8.2,33.87]],"id":52671555},{"atb":[[4,34.84],[3.5,97.56]],"id":52671554},{"atb":[[160,0.65],[80,3.08]],"id":52671556}],"con":true,"img":false}]}
{"op":"mcm","clk":"11449899256","pt":1717315764876,"mc":[{"id":"1.229554898","rc":[{"atb":[[1.44,227.27],[1.04,0]],"id":52671555},{"atb":[[2.5,66.67],[1.85,0]],"id":52671554}],"con":true,"img":false}]}
{"op":"mcm","clk":"11449900856","pt":1717315780538,"mc":[{"id":"1.229554898","rc":[{"atb":[[80,0],[42,0],[110,0],[55,0]],"id":52671545}],"con":true,"img":false}]}
{"op":"mcm","clk":"11449900865","pt":1717315780641,"mc":[{"id":"1.229554898","rc":[{"atb":[[25,4.17],[28,0]],"id":52671545}],"con":true,"img":false}]}
{"op":"mcm","clk":"11449900924","pt":1717315781226,"mc":[{"id":"1.229554898","rc":[{"atb":[[75,0.71],[40,2.68],[100,0.27],[50,1.6]],"id":52671545}],"con":true,"img":false}]}
{"op":"mcm","clk":"11449906655","pt":1717315837426,"mc":[{"id":"1.229554898","rc":[{"atb":[[16.5,0],[19,0],[11.5,0],[14,0]],"id":52671542},{"atb":[[11,0],[7.4,0],[8.4,0],[9.4,0]],"id":52671544}],"con":true,"img":false}]}
{"op":"mcm","clk":"11449906729","pt":1717315838147,"mc":[{"id":"1.229554898","rc":[{"atb":[[18,1.54],[10.5,11.01],[13,6.54],[15.5,3.61]],"id":52671542},{"atb":[[7.2,16.88],[9.2,6.38],[10.5,2.75],[8.2,10.9]],"id":52671544}],"con":true,"img":false}]}
{"op":"mcm","clk":"11449909200","pt":1717315861822,"mc":[{"id":"1.229554898","rc":[{"atl":[[230,4.1],[250,3.2]],"id":52671550},{"atb":[[7.4,20.96],[7.8,2.65]],"id":52671549},{"atl":[[27,3.8],[29,2.91]],"id":52671549},{"atb":[[1.27,58.13],[1.25,62.78]],"id":52671548},{"atl":[[2.1,14.26],[2.14,13.77]],"id":52671548},{"atb":[[11,3.54],[12,4.61]],"id":52671542},{"atl":[[70,3.71],[80,3.58]],"id":52671542},{"atb":[[46,3.64],[50,5.6]],"id":52671545},{"atl":[[320,4.63],[340,3.55]],"id":52671545},{"atb":[[8,2.88],[7.6,3.41]],"id":52671544},{"atl":[[19.5,3.81],[21,3.66]],"id":52671544},{"atl":[[70,2.86],[60,3.13]],"id":52671555},{"atb":[[4.8,4.03],[5,3.64]],"id":52671554},{"atl":[[11,4],[12,3.29]],"id":52671554},{"atb":[[100,4.64],[120,4.71]],"id":52671556},{"atl":[[780,2.66],[800,4.15]],"id":52671556}],"con":true,"img":false}]}
{"op":"mcm","clk":"11449909227","pt":1717315862032,"mc":[{"id":"1.229554898","rc":[{"atl":[[530,0],[130,2]],"id":52671549},{"atl":[[4,0],[2.6,28.04]],"id":52671548},{"atl":[[800,0],[400,2]],"id":52671542},{"atl":[[75,2],[450,0]],"id":52671544},{"atl":[[310,2],[710,0]],"id":52671555},{"atl":[[140,0],[17,6.25]],"id":52671554}],"con":true,"img":false}]}
{"op":"mcm","clk":"11449909943","pt":1717315868557,"mc":[{"id":"1.229554898","rc":[{"atb":[[8.2,3.76],[7.8,0]],"id":52671549},{"atb":[[1.28,0],[1.18,0],[1.27,0],[1.26,60.36],[1.23,0],[1.33,0]],"id":52671548},{"atl":[[2.12,14.01],[2.1,0]],"id":52671548},{"atb":[[50,1.6],[55,3.59]],"id":52671545},{"atl":[[310,3.45],[320,0]],"id":52671545},{"atb":[[8,0],[7.8,4.24]],"id":52671544},{"atl":[[18,2.77],[19.5,0]],"id":52671544}],"con":true,"img":false}]}
{"op":"mcm","clk":"11449909962","pt":1717315868715,"mc":[{"id":"1.229554898","rc":[{"atb":[[1.13,0],[1.17,588.24]],"id":52671548}],"con":true,"img":false}]}
{"op":"mcm","clk":"11449910014","pt":1717315869249,"mc":[{"id":"1.229554898","rc":[{"atb":[[1.28,186.85],[1.18,581.31],[1.23,341.2],[1.33,79.27]],"id":52671548}],"con":true,"img":false}]}
{"op":"mcm","clk":"11449910146","pt":1717315870547,"mc":[{"id":"1.229554898","rc":[{"atb":[[1.28,0],[1.18,0],[1.23,0],[1.33,0]],"id":52671548}],"con":true,"img":false}]}
{"op":"mcm","clk":"11449910233","pt":1717315871227,"mc":[{"id":"1.229554898","rc":[{"atb":[[1.27,193.77],[1.32,81.75],[1.22,356.71],[1.17,1203.74]],"id":52671548}],"con":true,"img":false}]}
{"op":"mcm","clk":"11449911036","pt":1717315878566,"mc":[{"id":"1.229554898","rc":[{"atb":[[7.8,4.14]],"id":52671549},{"atl":[[2.12,0],[2.1,14.26]],"id":52671548},{"atl":[[310,0],[320,2.73]],"id":52671545},{"atl":[[18,0],[19.5,3.77]],"id":52671544}],"con":true,"img":false}]}
{"op":"mcm","clk":"11449911302","pt":1717315881158,"mc":[{"id":"1.229554898","rc":[{"atl":[[2.42,28.04],[2.6,0]],"id":52671548},{"atl":[[340,2],[400,0]],"id":52671542},{"atl":[[17,0],[15,7.14]],"id":52671554}],"con":true,"img":false}]}
{"op":"mcm","clk":"11449912099","pt":1717315888682,"mc":[{"id":"1.229554898","rc":[{"atb":[[7.4,16.35]],"id":52671549}],"con":true,"img":false}]}
{"op":"mcm","clk":"11449917169","pt":1717315936746,"mc":[{"id":"1.229554898","rc":[{"atl":[[950,2]],"id":52671550},{"atl":[[2.32,28.04],[2.42,0]],"id":52671548},{"atl":[[310,0],[250,2]],"id":52671555},{"atb":[[2.5,0],[2.68,59.52]],"id":52671554}],"con":true,"img":false}]}
{"op":"mcm","clk":"11449917204","pt":1717315937006,"mc":[{"id":"1.229554898","rc":[{"atl":[[28,4.41]],"id":52671549},{"atl":[[2.12,14.01],[2.1,0]],"id":52671548},{"atl":[[310,4.47],[320,0]],"id":52671545},{"atl":[[18,3.77],[19.5,0]],"id":52671544}],"con":true,"img":false}]}
{"op":"mcm","clk":"11449917214","pt":1717315937111,"mc":[{"id":"1.229554898","rc":[{"atl":[[27,0]],"id":52671549}],"con":true,"img":false}]}
{"op":"mcm","clk":"11449918246","pt":1717315947052,"mc":[{"id":"1.229554898","rc":[{"atl":[[19,4.43]],"id":52671544}],"con":true,"img":false}]}
{"op":"mcm","clk":"11449919316","pt":1717315957165,"mc":[{"id":"1.229554898","rc":[{"atl":[[21,0]],"id":52671544}],"con":true,"img":false}]}
{"op":"mcm","clk":"11449925363","pt":1717316016052,"mc":[{"id":"1.229554898","rc":[{"atl":[[2.12,0],[2.1,14.26]],"id":52671548},{"atl":[[310,0],[320,4.05]],"id":52671545},{"atl":[[18,0],[19.5,3.55]],"id":52671544}],"con":true,"img":false}]}
{"op":"mcm","clk":"11449926156","pt":1717316024056,"mc":[{"id":"1.229554898","rc":[{"atl":[[2.12,14.01],[2.1,0]],"id":52671548},{"atl":[[310,3.13],[320,0]],"id":52671545},{"atl":[[18,4.21],[19,0]],"id":52671544}],"con":true,"img":false}]}
{"op":"mcm","clk":"11449929421","pt":1717316056772,"mc":[{"id":"1.229554898","rc":[{"atl":[[950,0]],"id":52671550},{"atl":[[2.4,28.04],[2.32,0]],"id":52671548},{"atb":[[2.56,64.1],[2.68,0]],"id":52671554}],"con":true,"img":false}]}
{"op":"mcm","clk":"11449931925","pt":1717316084442,"mc":[{"id":"1.229554898","rc":[{"atb":[[10.5,0],[15.5,0]],"id":52671550},{"atb":[[550,0],[450,0]],"id":52671546},{"atb":[[4.8,0],[5.8,0]],"id":52671549},{"atb":[[1.12,0],[1.02,109.92]],"id":52671548},{"atb":[[9,0],[7,0]],"id":52671542},{"atb":[[17,0],[24,0]],"id":52671545},{"atb":[[5.7,0],[4.7,0]],"id":52671544},{"atb":[[10.5,0],[8.2,0]],"id":52671555},{"atb":[[4,0],[3.5,0]],"id":52671554},{"atb":[[160,0],[80,0]],"id":52671556}],"con":true,"img":false}]}
{"op":"mcm","clk":"11449931943","pt":1717316084654,"mc":[{"id":"1.229554898","rc":[{"atb":[[1.44,0],[1.04,454.54]],"id":52671555}],"con":true,"img":false}]}
{"op":"mcm","clk":"11449932860","pt":1717316094343,"mc":[{"id":"1.229554898","rc":[{"atl":[[2.4,0],[2.58,28.04]],"id":52671548},{"atl":[[340,0],[400,2]],"id":52671542},{"atl":[[320,2],[250,0]],"id":52671555},{"atl":[[17,6.25],[15,0]],"id":52671554}],"con":true,"img":false}]}
{"op":"mcm","clk":"11449932905","pt":1717316094863,"mc":[{"id":"1.229554898","rc":[{"atb":[[1.54,29.06],[1.52,30.18]],"id":52671550},{"atl":[[2.12,0],[2.1,14.26]],"id":52671548},{"atl":[[310,0],[320,4.24]],"id":52671545},{"atl":[[18,0],[21,4.42]],"id":52671544},{"atb":[[1.54,29.06],[1.52,30.18]],"id":52671555}],"con":true,"img":false}]}
{"op":"mcm","clk":"11449932915","pt":1717316094912,"mc":[{"id":"1.229554898","rc":[{"atb":[[1.44,227.27]],"id":52671555}],"con":true,"img":false}]}
{"op":"mcm","clk":"11449932923","pt":1717316095016,"mc":[{"id":"1.229554898","rc":[{"atb":[[1.04,0]],"id":52671555}],"con":true,"img":false}]}
{"op":"mcm","clk":"11449933207","pt":1717316098751,"mc":[{"id":"1.229554898","rc":[{"atb":[[140,3.28],[160,3.7]],"id":52671546},{"atl":[[2.12,14.01],[2.1,0]],"id":52671548},{"atl":[[310,3.48],[320,0]],"id":52671545},{"atl":[[18,4.66],[19.5,0]],"id":52671544}],"con":true,"img":false}]}
{"op":"mcm","clk":"11449934164","pt":1717316108747,"mc":[{"id":"1.229554898","rc":[{"atl":[[19,3.34]],"id":52671544}],"con":true,"img":false}]}
{"op":"mcm","clk":"11449934186","pt":1717316109059,"mc":[{"id":"1.229554898","rc":[{"atb":[[10.5,25.67],[15.5,7.2]],"id":52671550},{"atb":[[550,0.18],[450,0.54]],"id":52671546},{"atb":[[4.8,64.18],[5.8,21.77]],"id":52671549},{"atb":[[1.12,871.08],[1.02,12305.17]],"id":52671548},{"atb":[[9,13.06],[7,40.65]],"id":52671542},{"atb":[[17,15.24],[24,4.54]],"id":52671545},{"atb":[[5.7,22.24],[4.7,65.92]],"id":52671544},{"atb":[[10.5,11],[8.2,33.87]],"id":52671555},{"atb":[[4,34.84],[3.5,97.56]],"id":52671554},{"atb":[[160,0.65],[80,3.08]],"id":52671556}],"con":true,"img":false}]}
{"op":"mcm","clk":"11449934464","pt":1717316112382,"mc":[{"id":"1.229554898","rc":[{"atl":[[2.4,27.79],[2.58,0]],"id":52671548},{"atl":[[350,2],[400,0]],"id":52671542},{"atl":[[270,2],[320,0]],"id":52671555},{"atl":[[17,0],[15.5,6.9]],"id":52671554}],"con":true,"img":false}]}
{"op":"mcm","clk":"11449934701","pt":1717316114971,"mc":[{"id":"1.229554898","rc":[{"atl":[[21,0]],"id":52671544}],"con":true,"img":false}]}
{"op":"mcm","clk":"11449934867","pt":1717316116788,"mc":[{"id":"1.229554898","rc":[{"atl":[[980,2]],"id":52671550},{"atl":[[2.4,0],[2.32,27.79]],"id":52671548},{"atb":[[2.56,0],[2.68,59.52]],"id":52671554},{"atl":[[14.5,7.31],[15.5,0]],"id":52671554}],"con":true,"img":false}]}
{"op":"mcm","clk":"11449935049","pt":1717316118755,"mc":[{"id":"1.229554898","rc":[{"atl":[[18,0],[19.5,3.37]],"id":52671544}],"con":true,"img":false}]}
{"op":"mcm","clk":"11449935973","pt":1717316128791,"mc":[{"id":"1.229554898","rc":[{"atl":[[19,0],[21,4.38]],"id":52671544}],"con":true,"img":false}]}
{"op":"mcm","clk":"11449936903","pt":1717316138819,"mc":[{"id":"1.229554898","rc":[{"atl":[[18,2.62],[19.5,0]],"id":52671544}],"con":true,"img":false}]}
{"op":"mcm","clk":"11449937810","pt":1717316148817,"mc":[{"id":"1.229554898","rc":[{"atl":[[19,4.61]],"id":52671544}],"con":true,"img":false}]}
{"op":"mcm","clk":"11449938757","pt":1717316158834,"mc":[{"id":"1.229554898","rc":[{"atl":[[21,0]],"id":52671544}],"con":true,"img":false}]}
{"op":"mcm","clk":"11449940102","pt":1717316173039,"mc":[{"id":"1.229554898","rc":[{"atb":[[8.2,0]],"id":52671549},{"atb":[[1.27,58.13],[1.26,0],[1.32,0],[1.22,0],[1.17,588.24]],"id":52671548},{"atb":[[50,5.93],[55,0]],"id":52671545},{"atb":[[8,3.12],[7.8,0]],"id":52671544}],"con":true,"img":false}]}
{"op":"mcm","clk":"11449940177","pt":1717316173766,"mc":[{"id":"1.229554898","rc":[{"atb":[[1.28,186.85],[1.18,581.31],[1.23,341.2],[1.33,79.27]],"id":52671548}],"con":true,"img":false}]}
{"op":"mcm","clk":"11449941105","pt":1717316183056,"mc":[{"id":"1.229554898","rc":[{"atb":[[7.4,20.59]],"id":52671549}],"con":true,"img":false}]}
{"op":"mcm","clk":"11449945975","pt":1717316236818,"mc":[{"id":"1.229554898","rc":[{"atl":[[980,0]],"id":52671550},{"atl":[[2.4,28.04],[2.32,0]],"id":52671548},{"atb":[[2.56,64.1],[2.68,0]],"id":52671554}],"con":true,"img":false}]}
{"op":"mcm","clk":"11449952403","pt":1717316311128,"mc":[{"id":"1.229554898","rc":[{"atl":[[310,2]],"id":52671550},{"atb":[[13.5,8],[30,0]],"id":52671546},{"atl":[[960,2]],"id":52671546},{"atb":[[5.6,21.74],[4.6,0]],"id":52671549},{"atb":[[1.34,79.28],[1.17,0]],"id":52671548},{"atl":[[2.4,0],[4,28.04]],"id":52671548},{"atb":[[6.8,0],[3.9,34.48]],"id":52671542},{"atl":[[65,2],[350,0]],"id":52671542},{"atb":[[7.6,15.15],[25,0]],"id":52671545},{"atl":[[340,5.55]],"id":52671545},{"atb":[[2.4,71.43],[3.75,0]],"id":52671544},{"atl":[[18,5.24],[75,0]],"id":52671544},{"atl":[[270,0],[60,5.13]],"id":52671555},{"atb":[[2.56,0],[3.1,47.62]],"id":52671554},{"atl":[[23,4.55],[14.5,0]],"id":52671554},{"atl":[[780,4.66]],"id":52671556}],"con":true,"img":false}]}
{"op":"mcm","clk":"11449952435","pt":1717316311442,"mc":[{"id":"1.229554898","rc":[{"atl":[[80,3.85],[230,0]],"id":52671550},{"atb":[[270,0],[140,0],[320,0],[160,0],[170,0],[220,0]],"id":52671546},{"atl":[[36,4.32],[28,0],[29,0]],"id":52671549},{"atl":[[2.12,0],[2.14,0],[2.68,9.34]],"id":52671548},{"atb":[[18,0],[10.5,0],[12,0],[13,0],[15.5,0]],"id":52671542},{"atl":[[70,0],[36,2.63]],"id":52671542},{"atb":[[32,3.46],[75,0],[40,0],[100,0],[50,0]],"id":52671545},{"atb":[[8,0],[7.2,0],[9.2,0],[10.5,0],[8.2,0],[7.6,0]],"id":52671544},{"atl":[[40,3.01],[60,2]],"id":52671555},{"atb":[[170,0],[85,0],[220,0],[120,0]],"id":52671556}],"con":true,"img":false}]}
{"op":"mcm","clk":"11449952494","pt":1717316312158,"mc":[{"id":"1.229554898","rc":[{"atb":[[70,0.76],[38,2.83],[95,0.28],[48,1.67]],"id":52671546},{"atb":[[9.2,12.76],[10.5,8.26],[13,4.36],[15.5,1.81]],"id":52671542},{"atb":[[32,6],[42,1.28],[26,4.19],[55,0.49]],"id":52671545},{"atb":[[3.6,40.24],[3.85,27.54],[4.2,16.35],[4.7,72.99]],"id":52671544},{"atb":[[150,0.18],[75,1.06],[100,5.17],[50,2.13]],"id":52671556}],"con":true,"img":false}]}
{"op":"mcm","clk":"11449952582","pt":1717316313138,"mc":[{"id":"1.229554898","rc":[{"atb":[[48,5.97],[55,3.07]],"id":52671546},{"atb":[[46,0]],"id":52671545}],"con":true,"img":false}]}
{"op":"mcm","clk":"11449952840","pt":1717316316254,"mc":[{"id":"1.229554898","rc":[{"atl":[[400,2]],"id":52671545},{"atl":[[780,2.66],[850,2]],"id":52671556}],"con":true,"img":false}]}
{"op":"mcm","clk":"11449952848","pt":1717316316367,"mc":[{"id":"1.229554898","rc":[{"atl":[[340,3.55]],"id":52671545}],"con":true,"img":false}]}
{"op":"mcm","clk":"11449953296","pt":1717316321449,"mc":[{"id":"1.229554898","rc":[{"atl":[[90,2.99]],"id":52671550},{"atl":[[40,3.29]],"id":52671549},{"atl":[[2.72,9.12]],"id":52671548},{"atb":[[10,3.04]],"id":52671542},{"atl":[[40,3.62]],"id":52671542},{"atb":[[29,3.81]],"id":52671545},{"atl":[[44,4.69]],"id":52671555},{"atb":[[90,3.29]],"id":52671556}],"con":true,"img":false}]}
{"op":"mcm","clk":"11449953669","pt":1717316325551,"mc":[{"id":"1.229554898","rc":[{"atl":[[250,0]],"id":52671550},{"atl":[[80,0]],"id":52671542},{"atl":[[70,0]],"id":52671555}],"con":true,"img":false}]}
{"op":"mcm","clk":"11449956835","pt":1717316367028,"mc":[{"id":"1.229554898","rc":[{"atl":[[310,0]],"id":52671545}],"con":true,"img":false}]}
{"op":"mcm","clk":"11449956926","pt":1717316368257,"mc":[{"id":"1.229554898","rc":[{"atb":[[8.2,4.13]],"id":52671549},{"atb":[[1.27,0],[1.26,60.36]],"id":52671548},{"atb":[[5,0],[5.3,3.65]],"id":52671554}],"con":true,"img":false}]}
{"op":"mcm","clk":"11449956932","pt":1717316368361,"mc":[{"id":"1.229554898","rc":[{"atb":[[7.8,0]],"id":52671549}],"con":true,"img":false}]}
{"op":"mcm","clk":"11449957022","pt":1717316369345,"mc":[{"id":"1.229554898","rc":[{"atl":[[310,3.3]],"id":52671545}],"con":true,"img":false}]}
{"op":"mcm","clk":"11449957297","pt":1717316372848,"mc":[{"id":"1.229554898","rc":[{"atl":[[850,0],[880,2]],"id":52671556}],"con":true,"img":false}]}
{"op":"mcm","clk":"11449959578","pt":1717316402809,"mc":[{"id":"1.229554898","rc":[{"atb":[[8.2,0],[7.8,4.51]],"id":52671549},{"atl":[[36,0],[38,4.42]],"id":52671549},{"atb":[[5,4.39],[5.3,0]],"id":52671554}],"con":true,"img":false}]}
{"op":"mcm","clk":"11449959701","pt":1717316404114,"mc":[{"id":"1.229554898","rc":[{"atb":[[1.27,58.13],[1.26,0]],"id":52671548},{"atl":[[36,0],[38,2.63]],"id":52671542},{"atl":[[310,0],[330,3.43]],"id":52671545},{"atl":[[18,2.62],[19.5,3.52]],"id":52671544}],"con":true,"img":false}]}
{"op":"mcm","clk":"11449959713","pt":1717316404216,"mc":[{"id":"1.229554898","rc":[{"atl":[[18.5,5.24]],"id":52671544}],"con":true,"img":false}]}
{"op":"mcm","clk":"11449959721","pt":1717316404314,"mc":[{"id":"1.229554898","rc":[{"atl":[[18,0]],"id":52671544}],"con":true,"img":false}]}
{"op":"mcm","clk":"11449960530","pt":1717316413912,"mc":[{"id":"1.229554898","rc":[{"atb":[[8.2,3.36],[7.8,0]],"id":52671549},{"atb":[[1.27,0],[1.26,60.36]],"id":52671548},{"atl":[[36,3.09],[38,0]],"id":52671542},{"atl":[[310,4.32],[330,0]],"id":52671545},{"atl":[[18,2.99],[19,0]],"id":52671544},{"atb":[[5,0],[5.3,2.89]],"id":52671554}],"con":true,"img":false}]}
{"op":"mcm","clk":"11449960727","pt":1717316416449,"mc":[{"id":"1.229554898","rc":[{"atb":[[8.2,0],[7.8,3.08]],"id":52671549},{"atb":[[1.27,58.13],[1.26,0]],"id":52671548},{"atl":[[36,0],[38,3.34]],"id":52671542},{"atl":[[310,0],[320,4.34]],"id":52671545},{"atl":[[18,0]],"id":52671544},{"atb":[[5,2.9],[5.3,0]],"id":52671554}],"con":true,"img":false}]}
{"op":"mcm","clk":"11449960733","pt":1717316416502,"mc":[{"id":"1.229554898","rc":[{"atl":[[19,5.56]],"id":52671544}],"con":true,"img":false}]}
{"op":"mcm","clk":"11449960741","pt":1717316416604,"mc":[{"id":"1.229554898","rc":[{"atl":[[18.5,0]],"id":52671544}],"con":true,"img":false}]}
{"op":"mcm","clk":"11449960802","pt":1717316417329,"mc":[{"id":"1.229554898","rc":[{"atl":[[310,0],[370,2]],"id":52671550},{"atl":[[36,4.11],[38,0]],"id":52671542},{"atl":[[310,4.34],[320,0],[400,0],[440,2]],"id":52671545},{"atl":[[18,3.77]],"id":52671544},{"atl":[[880,0],[950,2]],"id":52671556}],"con":true,"img":false}]}
{"op":"mcm","clk":"11449960824","pt":1717316417636,"mc":[{"id":"1.229554898","rc":[{"atb":[[55,0],[60,2.82]],"id":52671546},{"atb":[[32,2.53],[34,3.43]],"id":52671545}],"con":true,"img":false}]}
{"op":"mcm","clk":"11449960831","pt":1717316417740,"mc":[{"id":"1.229554898","rc":[{"atl":[[2.62,9.68],[2.68,0]],"id":52671548}],"con":true,"img":false}]}
{"op":"mcm","clk":"11449961489","pt":1717316425319,"mc":[{"id":"1.229554898","rc":[{"atb":[[8.2,3.02],[7.8,0]],"id":52671549},{"atb":[[1.27,0],[1.26,60.36]],"id":52671548},{"atb":[[5,0],[5.3,2.85]],"id":52671554}],"con":true,"img":false}]}
{"op":"mcm","clk":"11449961625","pt":1717316426931,"mc":[{"id":"1.229554898","rc":[{"atb":[[8.2,0],[7.8,3.75]],"id":52671549},{"atb":[[1.27,58.13],[1.26,0]],"id":52671548},{"atl":[[36,0],[38,4.23]],"id":52671542},{"atl":[[310,0],[320,2.75]],"id":52671545},{"atl":[[18,0]],"id":52671544},{"atb":[[5,3.01],[5.3,0]],"id":52671554}],"con":true,"img":false}]}
{"op":"mcm","clk":"11449962061","pt":1717316432460,"mc":[{"id":"1.229554898","rc":[{"atb":[[16.5,6.45],[13.5,0]],"id":52671546},{"atl":[[130,0],[190,2]],"id":52671549},{"atl":[[65,0],[85,2]],"id":52671542},{"atl":[[950,0]],"id":52671556}],"con":true,"img":false}]}
{"op":"mcm","clk":"11449962080","pt":1717316432769,"mc":[{"id":"1.229554898","rc":[{"atb":[[70,5.16],[60,0]],"id":52671546},{"atl":[[38,0]],"id":52671549},{"atl":[[2.56,10.06],[2.62,0]],"id":52671548},{"atb":[[12,3.74]],"id":52671542},{"atl":[[36,2.94]],"id":52671542},{"atb":[[34,0],[36,3.63]],"id":52671545},{"atl":[[310,3.18],[320,0]],"id":52671545},{"atl":[[18,4.27]],"id":52671544},{"atb":[[100,0.53]],"id":52671556}],"con":true,"img":false}]}
{"op":"mcm","clk":"11449962086","pt":1717316432823,"mc":[{"id":"1.229554898","rc":[{"atb":[[11,0]],"id":52671542},{"atl":[[38,0]],"id":52671542},{"atb":[[110,2.9]],"id":52671556}],"con":true,"img":false}]}
{"op":"mcm","clk":"11449962092","pt":1717316432929,"mc":[{"id":"1.229554898","rc":[{"atl":[[17.5,4.27],[19,0]],"id":52671544}],"con":true,"img":false}]}
{"op":"mcm","clk":"11449962423","pt":1717316436971,"mc":[{"id":"1.229554898","rc":[{"atl":[[44,3.81]],"id":52671549}],"con":true,"img":false}]}
{"op":"mcm","clk":"11449962434","pt":1717316437076,"mc":[{"id":"1.229554898","rc":[{"atb":[[1.27,0],[1.26,60.36]],"id":52671548},{"atb":[[5,0],[5.3,3.29]],"id":52671554}],"con":true,"img":false}]}
{"op":"mcm","clk":"11449962442","pt":1717316437176,"mc":[{"id":"1.229554898","rc":[{"atb":[[8.2,4.31],[7.8,0]],"id":52671549}],"con":true,"img":false}]}
{"op":"mcm","clk":"11449962535","pt":1717316438365,"mc":[{"id":"1.229554898","rc":[{"atb":[[8.2,0],[7.8,3.29]],"id":52671549},{"atb":[[1.27,58.13],[1.26,0]],"id":52671548},{"atl":[[36,0],[38,3.92]],"id":52671542},{"atl":[[310,0],[320,3.94]],"id":52671545},{"atl":[[18,0]],"id":52671544},{"atb":[[5,4.27],[5.3,0]],"id":52671554}],"con":true,"img":false}]}
{"op":"mcm","clk":"11449962540","pt":1717316438465,"mc":[{"id":"1.229554898","rc":[{"atl":[[19,5.56]],"id":52671544}],"con":true,"img":false}]}
{"op":"mcm","clk":"11449962547","pt":1717316438570,"mc":[{"id":"1.229554898","rc":[{"atl":[[17.5,0]],"id":52671544}],"con":true,"img":false}]}
{"op":"mcm","clk":"11449962900","pt":1717316442750,"mc":[{"id":"1.229554898","rc":[{"atl":[[18,2.72]],"id":52671544}],"con":true,"img":false}]}
{"op":"mcm","clk":"11449962908","pt":1717316442854,"mc":[{"id":"1.229554898","rc":[{"atb":[[60,3.56]],"id":52671546}],"con":true,"img":false}]}
{"op":"mcm","clk":"11449962989","pt":1717316443941,"mc":[{"id":"1.229554898","rc":[{"atb":[[1.44,0],[2.88,29.07]],"id":52671550},{"atl":[[4,0],[5.4,20.12]],"id":52671548},{"atb":[[1.44,0],[2.88,44.88]],"id":52671555}],"con":true,"img":false}]}
{"op":"mcm","clk":"11449963022","pt":1717316444251,"mc":[{"id":"1.229554898","rc":[{"atl":[[2.56,0],[2.72,0],[5.4,24.02]],"id":52671548},{"atb":[[10,0],[12,0]],"id":52671542},{"atl":[[36,4.56],[38,0]],"id":52671542}],"con":true,"img":false}]}
{"op":"mcm","clk":"11449963026","pt":1717316444354,"mc":[{"id":"1.229554898","rc":[{"atb":[[48,1.67]],"id":52671546},{"atl":[[310,3.32],[320,0]],"id":52671545}],"con":true,"img":false}]}
{"op":"mcm","clk":"11449963134","pt":1717316445954,"mc":[{"id":"1.229554898","rc":[{"atb":[[8.2,4.47],[7.8,0]],"id":52671549},{"atb":[[1.27,0],[1.26,60.36]],"id":52671548},{"atb":[[5,0],[5.3,3.53]],"id":52671554}],"con":true,"img":false}]}
{"op":"mcm","clk":"11449963161","pt":1717316446371,"mc":[{"id":"1.229554898","rc":[{"atl":[[36,0],[38,3.03]],"id":52671542},{"atl":[[310,0],[320,3.98]],"id":52671545},{"atl":[[18,3.53],[19,0]],"id":52671544}],"con":true,"img":false}]}
{"op":"mcm","clk":"11449963291","pt":1717316448075,"mc":[{"id":"1.229554898","rc":[{"atl":[[36,3.33],[38,0]],"id":52671542},{"atl":[[310,2.89],[320,0]],"id":52671545},{"atl":[[18,8.12]],"id":52671544}],"con":true,"img":false}]}
{"op":"mcm","clk":"11449963342","pt":1717316449005,"mc":[{"id":"1.229554898","rc":[{"atb":[[8.2,0],[7.8,4]],"id":52671549},{"atb":[[1.27,58.13],[1.26,0]],"id":52671548},{"atl":[[36,0],[38,4.24]],"id":52671542},{"atl":[[310,0],[320,4.49]],"id":52671545},{"atl":[[18,3.53]],"id":52671544},{"atb":[[5,4.69],[5.3,0]],"id":52671554}],"con":true,"img":false}]}
{"op":"mcm","clk":"11449963477","pt":1717316450874,"mc":[{"id":"1.229554898","rc":[{"atb":[[8.2,3.91],[7.8,0]],"id":52671549},{"atb":[[1.27,0],[1.26,60.36]],"id":52671548},{"atl":[[36,3.51],[38,0]],"id":52671542},{"atl":[[310,4.24],[320,0]],"id":52671545},{"atl":[[18,6.34]],"id":52671544},{"atb":[[5,0],[5.3,4.12]],"id":52671554}],"con":true,"img":false}]}
{"op":"mcm","clk":"11449963606","pt":1717316452572,"mc":[{"id":"1.229554898","rc":[{"atb":[[10.5,0],[13,0],[15.5,0]],"id":52671542},{"atb":[[32,0],[55,0]],"id":52671545},{"atb":[[150,0],[75,0],[100,0],[50,0]],"id":52671556}],"con":true,"img":false}]}
{"op":"mcm","clk":"11449963614","pt":1717316452674,"mc":[{"id":"1.229554898","rc":[{"atb":[[70,4.4],[38,0],[95,0],[48,0]],"id":52671546},{"atb":[[9.2,0]],"id":52671542},{"atb":[[42,0],[26,0]],"id":52671545}],"con":true,"img":false}]}
{"op":"mcm","clk":"11449963639","pt":1717316453086,"mc":[{"id":"1.229554898","rc":[{"atl":[[38,3.39]],"id":52671542},{"atb":[[36,0],[38,3.71]],"id":52671545},{"atl":[[310,0],[320,3.84]],"id":52671545},{"atb":[[3.6,0],[3.85,0],[4.2,0],[4.7,65.92]],"id":52671544},{"atl":[[18,3.53]],"id":52671544}],"con":true,"img":false}]}
{"op":"mcm","clk":"11449963643","pt":1717316453188,"mc":[{"id":"1.229554898","rc":[{"atl":[[36,0]],"id":52671542},{"atl":[[19,5.56]],"id":52671544}],"con":true,"img":false}]}
{"op":"mcm","clk":"11449963649","pt":1717316453293,"mc":[{"id":"1.229554898","rc":[{"atb":[[17,1.64],[12,7.14],[14.5,3.88]],"id":52671542},{"atb":[[65,0.41],[36,2.24]],"id":52671545},{"atl":[[18,0]],"id":52671544},{"atb":[[130,0.41],[65,1.64],[90,4.18],[180,0.15]],"id":52671556}],"con":true,"img":false}]}
{"op":"mcm","clk":"11449963652","pt":1717316453395,"mc":[{"id":"1.229554898","rc":[{"atb":[[80,0.66],[42,2.55],[110,0.24],[55,1.45]],"id":52671546},{"atb":[[9.8,11.89]],"id":52671542},{"atb":[[46,1.16],[28,3.88]],"id":52671545}],"con":true,"img":false}]}
{"op":"mcm","clk":"11449963673","pt":1717316453762,"mc":[{"id":"1.229554898","rc":[{"atb":[[4.8,6.89],[4.3,15.85],[3.9,27.06],[3.65,39.48]],"id":52671544}],"con":true,"img":false}]}
{"op":"mcm","clk":"11449964189","pt":1717316460895,"mc":[{"id":"1.229554898","rc":[{"atb":[[7.8,3.09]],"id":52671549},{"atl":[[5.6,3.74]],"id":52671548},{"atl":[[21,3.69]],"id":52671544},{"atb":[[5.1,3.47]],"id":52671554}],"con":true,"img":false}]}
{"op":"mcm","clk":"11449964343","pt":1717316463104,"mc":[{"id":"1.229554898","rc":[{"atb":[[34,2.79]],"id":52671545}],"con":true,"img":false}]}
{"op":"mcm","clk":"11449964714","pt":1717316467981,"mc":[{"id":"1.229554898","rc":[{"atb":[[8.6,13.16],[7.6,0]],"id":52671545},{"atl":[[440,0],[500,2]],"id":52671545}],"con":true,"img":false}]}
{"op":"mcm","clk":"11449964746","pt":1717316468292,"mc":[{"id":"1.229554898","rc":[{"atb":[[80,0],[42,0],[110,0],[55,0]],"id":52671546},{"atb":[[7.4,16.35]],"id":52671549},{"atb":[[17,0],[12,0],[9.8,0],[14.5,0]],"id":52671542},{"atb":[[65,0],[36,0],[46,0],[28,0],[29,0]],"id":52671545},{"atb":[[4.8,0]],"id":52671554},{"atb":[[130,0],[65,0],[180,0],[90,3.29]],"id":52671556}],"con":true,"img":false}]}
{"op":"mcm","clk":"11449964802","pt":1717316469014,"mc":[{"id":"1.229554898","rc":[{"atb":[[85,0.62],[44,2.43],[60,4.89],[120,0.22]],"id":52671546},{"atb":[[17.5,1.59],[10,11.63],[12.5,6.82],[15,3.74]],"id":52671542},{"atb":[[70,0.38],[38,5.84],[48,1.11],[29,3.74]],"id":52671545},{"atb":[[140,0.38],[70,1.52],[190,0.14],[95,0.84]],"id":52671556}],"con":true,"img":false}]}
{"op":"mcm","clk":"11449966463","pt":1717316492135,"mc":[{"id":"1.229554898","rc":[{"atb":[[10.5,0],[15.5,0]],"id":52671550},{"atb":[[550,0],[450,0]],"id":52671546},{"atb":[[4.8,0],[5.8,0]],"id":52671549},{"atb":[[1.12,0],[1.02,109.92]],"id":52671548},{"atb":[[9,0],[7,0]],"id":52671542},{"atb":[[17,0],[24,0]],"id":52671545},{"atb":[[5.7,0],[4.7,0]],"id":52671544},{"atb":[[10.5,0],[8.2,0]],"id":52671555},{"atb":[[4,0],[3.5,0]],"id":52671554},{"atb":[[160,0],[80,0]],"id":52671556}],"con":true,"img":false}]}
{"op":"mcm","clk":"11449966477","pt":1717316492337,"mc":[{"id":"1.229554898","rc":[{"atb":[[2.88,0],[2.08,89.76]],"id":52671555}],"con":true,"img":false}]}
{"op":"mcm","clk":"11449967207","pt":1717316502504,"mc":[{"id":"1.229554898","rc":[{"atb":[[1.54,0],[3.05,7.65]],"id":52671550},{"atb":[[4.5,2.84],[4.3,4.75]],"id":52671542},{"atb":[[4,5.23],[4.2,4.9]],"id":52671544},{"atb":[[1.54,0],[3.05,7.65]],"id":52671555}],"con":true,"img":false}]}
{"op":"mcm","clk":"11449967406","pt":1717316505134,"mc":[{"id":"1.229554898","rc":[{"atb":[[2.88,53.19]],"id":52671555}],"con":true,"img":false}]}
{"op":"mcm","clk":"11449967411","pt":1717316505236,"mc":[{"id":"1.229554898","rc":[{"atb":[[2.08,0]],"id":52671555}],"con":true,"img":false}]}
{"op":"mcm","clk":"11449967805","pt":1717316511433,"mc":[{"id":"1.229554898","rc":[{"atl":[[600,2],[370,0]],"id":52671550},{"atb":[[16.5,0]],"id":52671546},{"atl":[[960,0]],"id":52671546},{"atb":[[5.6,0],[3.55,39.22]],"id":52671549},{"atl":[[190,0],[55,2]],"id":52671549},{"atb":[[1.21,345.62],[1.34,0]],"id":52671548},{"atb":[[4.4,29.41],[3.9,0]],"id":52671542},{"atl":[[85,0],[240,2]],"id":52671542},{"atb":[[17,6.25],[8.6,0]],"id":52671545},{"atl":[[710,2],[500,0]],"id":52671545},{"atb":[[2.4,0]],"id":52671544},{"atl":[[19,0]],"id":52671544},{"atl":[[220,2],[60,0]],"id":52671555},{"atb":[[2.56,64.1],[3.1,0]],"id":52671554},{"atl":[[23,0],[15,7.14]],"id":52671554}],"con":true,"img":false}]}
{"op":"mcm","clk":"11449967809","pt":1717316511537,"mc":[{"id":"1.229554898","rc":[{"atl":[[530,2],[600,0]],"id":52671550},{"atb":[[30,3.45]],"id":52671546},{"atb":[[3.55,0],[3.9,34.48]],"id":52671549},{"atl":[[48,2.13],[55,0]],"id":52671549},{"atb":[[1.21,0],[1.24,341.21]],"id":52671548},{"atb":[[17,0],[19.5,5.41]],"id":52671545},{"atl":[[640,2],[710,0]],"id":52671545},{"atb":[[4,32.29]],"id":52671544},{"atl":[[100,2]],"id":52671544},{"atb":[[2.56,0],[2.74,57.47]],"id":52671554},{"atl":[[14,7.31],[15,0]],"id":52671554}],"con":true,"img":false}]}
{"op":"mcm","clk":"11449967821","pt":1717316511747,"mc":[{"id":"1.229554898","rc":[{"atl":[[110,3.89]],"id":52671550},{"atb":[[70,0],[160,4.23]],"id":52671546},{"atl":[[21,2.84]],"id":52671549},{"atb":[[1.28,0],[1.18,0],[1.23,0],[1.33,0]],"id":52671548},{"atb":[[55,2.69]],"id":52671545},{"atb":[[4.8,0],[4,5.23],[4.3,0],[4.5,3.98],[4.4,15.86],[3.9,0],[4.2,0],[3.65,0]],"id":52671544},{"atl":[[19.5,0],[23,4.16]],"id":52671544},{"atb":[[5.3,0]],"id":52671554},{"atb":[[120,2.86]],"id":52671556}],"con":true,"img":false}]}
{"op":"mcm","clk":"11449967831","pt":1717316511847,"mc":[{"id":"1.229554898","rc":[{"atl":[[80,0],[90,0]],"id":52671550},{"atl":[[38,0],[40,0],[48,4.22]],"id":52671542},{"atl":[[46,2.71]],"id":52671555},{"atb":[[4.8,4.38]],"id":52671554},{"atb":[[110,0]],"id":52671556}],"con":true,"img":false}]}
{"op":"mcm","clk":"11449967837","pt":1717316511954,"mc":[{"id":"1.229554898","rc":[{"atl":[[40,0]],"id":52671549},{"atb":[[70,0],[38,0],[48,0],[29,0]],"id":52671545},{"atl":[[40,0]],"id":52671555}],"con":true,"img":false}]}
{"op":"mcm","clk":"11449967884","pt":1717316512522,"mc":[{"id":"1.229554898","rc":[{"atb":[[1.27,193.77],[1.32,81.75],[1.22,356.71],[1.17,615.5]],"id":52671548},{"atb":[[7.2,16.88],[9.2,6.38],[10.5,2.75],[8.2,10.9]],"id":52671544}],"con":true,"img":false}]}
{"op":"mcm","clk":"11449967890","pt":1717316512628,"mc":[{"id":"1.229554898","rc":[{"atb":[[75,0.71],[40,2.68],[100,0.27],[50,1.6]],"id":52671545}],"con":true,"img":false}]}
{"op":"mcm","clk":"11449968432","pt":1717316521513,"mc":[{"id":"1.229554898","rc":[{"atb":[[10.5,25.67],[15.5,7.2]],"id":52671550},{"atb":[[550,0.18],[450,0.54]],"id":52671546},{"atb":[[4.8,64.18],[5.8,21.77]],"id":52671549},{"atb":[[1.12,871.08],[1.02,12305.17]],"id":52671548},{"atb":[[9,13.06],[7,40.65]],"id":52671542},{"atb":[[17,15.24],[24,4.54]],"id":52671545},{"atb":[[5.7,22.24],[4.7,65.92]],"id":52671544},{"atb":[[10.5,11],[8.2,33.87]],"id":52671555},{"atb":[[4,34.84],[3.5,97.56]],"id":52671554},{"atb":[[160,0.65],[80,3.08]],"id":52671556}],"con":true,"img":false}]}
{"op":"mcm","clk":"11449968441","pt":1717316521726,"mc":[{"id":"1.229554898","rc":[{"atb":[[140,4.68]],"id":52671546},{"atb":[[48,4.7]],"id":52671545},{"atl":[[21,0]],"id":52671544},{"atb":[[2.98,7.92]],"id":52671555},{"atl":[[44,0],[50,3.78]],"id":52671555},{"atb":[[5.1,0]],"id":52671554}],"con":true,"img":false}]}
{"op":"mcm","clk":"11449968444","pt":1717316521828,"mc":[{"id":"1.229554898","rc":[{"atb":[[2.98,7.92]],"id":52671550},{"atl":[[130,2.82]],"id":52671550},{"atl":[[23,4.64]],"id":52671549},{"atl":[[55,4.24]],"id":52671542},{"atb":[[4.3,4.75]],"id":52671544},{"atl":[[25,4.49]],"id":52671544},{"atb":[[4.6,2.82]],"id":52671554},{"atb":[[100,3.34]],"id":52671556}],"con":true,"img":false}]}
{"op":"mcm","clk":"11449969123","pt":1717316531829,"mc":[{"id":"1.229554898","rc":[{"atb":[[60,1.33]],"id":52671546},{"atl":[[44,0]],"id":52671549},{"atb":[[34,0]],"id":52671545},{"atb":[[90,0]],"id":52671556}],"con":true,"img":false}]}
{"op":"mcm","clk":"11449969542","pt":1717316538337,"mc":[{"id":"1.229554898","rc":[{"atb":[[160,0],[170,4.3]],"id":52671546},{"atb":[[8.6,3.97],[11,0],[8.2,0],[7.4,0],[8.4,0],[9.4,0]],"id":52671549},{"atl":[[21,0],[22,3.18]],"id":52671549},{"atb":[[1.27,0],[1.25,0],[1.26,0],[1.32,0],[1.22,0],[1.17,0]],"id":52671548},{"atb":[[75,0],[40,0],[100,0],[50,0],[60,3.51]],"id":52671545},{"atl":[[11,0],[11.5,3.84]],"id":52671554},{"atl":[[780,0],[860,4.29]],"id":52671556}],"con":true,"img":false}]}
{"op":"mcm","clk":"11449969548","pt":1717316538444,"mc":[{"id":"1.229554898","rc":[{"atb":[[1.13,769.23]],"id":52671548},{"atb":[[17.5,0],[10,0],[12.5,0],[15,0]],"id":52671542},{"atb":[[55,0]],"id":52671545},{"atl":[[320,0]],"id":52671545}],"con":true,"img":false}]}
{"op":"mcm","clk":"11449969556","pt":1717316538547,"mc":[{"id":"1.229554898","rc":[{"atb":[[1.24,0]],"id":52671548}],"con":true,"img":false}]}
{"op":"mcm","clk":"11449969590","pt":1717316539061,"mc":[{"id":"1.229554898","rc":[{"atb":[[9.6,6.08],[8.6,14.3],[11.5,2.49],[7.6,15.85]],"id":52671549},{"atb":[[1.19,275.36],[1.14,560.55],[1.09,1162.61],[1.24,108.99]],"id":52671548},{"atb":[[80,0.66],[42,2.55],[110,0.24],[55,1.45]],"id":52671545}],"con":true,"img":false}]}
{"op":"mcm","clk":"11449969595","pt":1717316539160,"mc":[{"id":"1.229554898","rc":[{"atb":[[1.24,384.35]],"id":52671548},{"atb":[[16.5,3.37],[19,1.45],[11.5,9.97],[14,6.04]],"id":52671542}],"con":true,"img":false}]}
{"op":"mcm","clk":"11449969601","pt":1717316539264,"mc":[{"id":"1.229554898","rc":[{"atb":[[1.2,500],[1.13,0],[1.24,108.99]],"id":52671548}],"con":true,"img":false}]}
{"op":"mcm","clk":"11449969644","pt":1717316540043,"mc":[{"id":"1.229554898","rc":[{"atb":[[160,3.93],[170,0]],"id":52671546},{"atb":[[8.6,10.33],[8.2,4.53]],"id":52671549},{"atb":[[1.26,60.36],[1.24,174.39]],"id":52671548},{"atb":[[55,4.21],[60,0]],"id":52671545},{"atl":[[800,0]],"id":52671556}],"con":true,"img":false}]}
{"op":"mcm","clk":"11449969651","pt":1717316540143,"mc":[{"id":"1.229554898","rc":[{"atb":[[1.24,449.75]],"id":52671548}],"con":true,"img":false}]}
{"op":"mcm","clk":"11449969660","pt":1717316540248,"mc":[{"id":"1.229554898","rc":[{"atb":[[1.2,0]],"id":52671548}],"con":true,"img":false}]}
{"op":"mcm","clk":"11449969857","pt":1717316543033,"mc":[{"id":"1.229554898","rc":[{"atb":[[160,0],[170,3.93]],"id":52671546},{"atb":[[8.6,14.1]],"id":52671549},{"atl":[[21,4.33]],"id":52671549},{"atb":[[1.26,0],[1.19,357.96],[1.24,384.35]],"id":52671548},{"atb":[[55,1.45],[60,3.26]],"id":52671545},{"atl":[[320,4.02]],"id":52671545},{"atl":[[11,4.45],[11.5,0]],"id":52671554},{"atl":[[780,4.14]],"id":52671556}],"con":true,"img":false}]}
{"op":"mcm","clk":"11449969867","pt":1717316543147,"mc":[{"id":"1.229554898","rc":[{"atb":[[8.2,0]],"id":52671549},{"atl":[[22,0]],"id":52671549}],"con":true,"img":false}]}
{"op":"mcm","clk":"11449969988","pt":1717316544835,"mc":[{"id":"1.229554898","rc":[{"atb":[[9.6,0],[8.6,3.77],[11.5,0],[7.6,0]],"id":52671549},{"atb":[[80,0],[42,0],[110,0],[55,0]],"id":52671545}],"con":true,"img":false}]}
{"op":"mcm","clk":"11449970026","pt":1717316545561,"mc":[{"id":"1.229554898","rc":[{"atb":[[11,2.62],[7.4,16.35],[8.4,10.61],[9.4,6.23]],"id":52671549},{"atb":[[75,0.71],[40,2.68],[100,0.27],[50,1.6]],"id":52671545}],"con":true,"img":false}]}
{"op":"mcm","clk":"11449970534","pt":1717316553077,"mc":[{"id":"1.229554898","rc":[{"atb":[[160,3.83],[170,0]],"id":52671546},{"atb":[[8.6,0],[8.2,4.01]],"id":52671549},{"atb":[[1.26,60.36]],"id":52671548},{"atb":[[55,3.62],[60,0]],"id":52671545},{"atl":[[800,3.42]],"id":52671556}],"con":true,"img":false}]}
{"op":"mcm","clk":"11449970670","pt":1717316555062,"mc":[{"id":"1.229554898","rc":[{"atb":[[160,0],[170,4.02]],"id":52671546},{"atb":[[8.6,2.97],[8.2,0]],"id":52671549},{"atb":[[1.26,0]],"id":52671548},{"atb":[[55,0],[60,3.94]],"id":52671545},{"atl":[[860,0]],"id":52671556}],"con":true,"img":false}]}
{"op":"mcm","clk":"11449970676","pt":1717316555169,"mc":[{"id":"1.229554898","rc":[{"atl":[[21,0],[22,4.31]],"id":52671549},{"atl":[[320,0]],"id":52671545},{"atl":[[11,0],[11.5,3.77]],"id":52671554},{"atl":[[780,0],[800,0]],"id":52671556}],"con":true,"img":false}]}
{"op":"mcm","clk":"11449970808","pt":1717316557400,"mc":[{"id":"1.229554898","rc":[{"atl":[[21,3.03],[22,0]],"id":52671549},{"atl":[[320,3.74]],"id":52671545},{"atl":[[11,3.74],[11.5,0]],"id":52671554},{"atl":[[780,3.43],[800,4.11]],"id":52671556}],"con":true,"img":false}]}
{"op":"mcm","clk":"11449970883","pt":1717316558497,"mc":[{"id":"1.229554898","rc":[{"atb":[[160,4.05],[170,0]],"id":52671546},{"atb":[[8.6,0],[8.2,3.83]],"id":52671549},{"atl":[[21,0],[22,3.52]],"id":52671549},{"atb":[[1.26,60.36]],"id":52671548},{"atb":[[55,2.94],[60,0]],"id":52671545},{"atl":[[320,0]],"id":52671545},{"atl":[[11,0],[11.5,2.75]],"id":52671554},{"atl":[[780,0],[860,4.11]],"id":52671556}],"con":true,"img":false}]}
{"op":"mcm","clk":"11449970993","pt":1717316560468,"mc":[{"id":"1.229554898","rc":[{"atb":[[160,0],[170,4.02]],"id":52671546},{"atb":[[8.6,4.37],[8.2,0]],"id":52671549},{"atl":[[21,3.63],[22,0]],"id":52671549},{"atb":[[1.26,0]],"id":52671548},{"atb":[[55,0],[60,4.15]],"id":52671545},{"atl":[[320,4.35]],"id":52671545},{"atl":[[11,4.38],[11.5,0]],"id":52671554},{"atl":[[780,4.48],[800,0]],"id":52671556}],"con":true,"img":false}]}
{"op":"mcm","clk":"11449971152","pt":1717316562900,"mc":[{"id":"1.229554898","rc":[{"atb":[[170,0]],"id":52671546},{"atb":[[8.6,0]],"id":52671549},{"atl":[[21,0]],"id":52671549},{"atb":[[1.26,60.36]],"id":52671548},{"atb":[[60,0]],"id":52671545},{"atl":[[320,0]],"id":52671545},{"atl":[[11,0]],"id":52671554}],"con":true,"img":false}]}
{"op":"mcm","clk":"11449971162","pt":1717316563004,"mc":[{"id":"1.229554898","rc":[{"atb":[[160,4.5]],"id":52671546},{"atb":[[8.2,3.06]],"id":52671549},{"atl":[[22,3.45]],"id":52671549},{"atb":[[55,2.99]],"id":52671545},{"atl":[[11.5,2.68]],"id":52671554},{"atl":[[780,0]],"id":52671556}],"con":true,"img":false}]}
{"op":"mcm","clk":"11449971195","pt":1717316563369,"mc":[{"id":"1.229554898","rc":[{"atl":[[530,0],[600,2]],"id":52671550},{"atb":[[1.19,884.28],[1.24,108.99]],"id":52671548},{"atb":[[19.5,0],[30,3.45]],"id":52671545},{"atl":[[640,0],[930,2]],"id":52671545},{"atb":[[2.74,0],[2.94,51.55]],"id":52671554},{"atl":[[17,6.25],[14,0]],"id":52671554}],"con":true,"img":false}]}
{"op":"mcm","clk":"11449971203","pt":1717316563575,"mc":[{"id":"1.229554898","rc":[{"atb":[[180,3.76]],"id":52671546},{"atb":[[1.18,87.19],[1.19,801.68]],"id":52671548}],"con":true,"img":false}]}
{"op":"mcm","clk":"11449971209","pt":1717316563679,"mc":[{"id":"1.229554898","rc":[{"atl":[[110,0]],"id":52671550},{"atb":[[160,0]],"id":52671546},{"atb":[[8.6,3.91],[8.2,0]],"id":52671549},{"atb":[[1.26,0],[1.19,526.32],[1.14,0],[1.09,0],[1.24,0]],"id":52671548},{"atb":[[60,4.63]],"id":52671545},{"atb":[[4.8,0],[5.1,3.68]],"id":52671554},{"atb":[[120,0]],"id":52671556},{"atl":[[860,0]],"id":52671556}],"con":true,"img":false}]}
{"op":"mcm","clk":"11449971216","pt":1717316563783,"mc":[{"id":"1.229554898","rc":[{"atl":[[48,0]],"id":52671542},{"atb":[[55,0]],"id":52671545},{"atl":[[23,0]],"id":52671544},{"atl":[[46,0],[55,3.62]],"id":52671555},{"atb":[[140,4.4]],"id":52671556},{"atl":[[870,3.65]],"id":52671556}],"con":true,"img":false}]}
{"op":"mcm","clk":"11449971222","pt":1717316563887,"mc":[{"id":"1.229554898","rc":[{"atl":[[130,0],[140,2.63]],"id":52671550}],"con":true,"img":false}]}
{"op":"mcm","clk":"11449971259","pt":1717316564408,"mc":[{"id":"1.229554898","rc":[{"atb":[[1.18,377.85],[1.23,113.73],[1.13,603.67],[1.08,1307.94]],"id":52671548}],"con":true,"img":false}]}
{"op":"mcm","clk":"11449971279","pt":1717316564669,"mc":[{"id":"1.229554898","rc":[{"atb":[[8.6,0],[8.4,13.96]],"id":52671549},{"atb":[[1.22,71.34]],"id":52671548},{"atl":[[50,0]],"id":52671555}],"con":true,"img":false}]}
{"op":"mcm","clk":"11449971292","pt":1717316564872,"mc":[{"id":"1.229554898","rc":[{"atl":[[21,3.04],[22,0]],"id":52671549},{"atl":[[320,3.06]],"id":52671545},{"atl":[[11,3.24],[11.5,0]],"id":52671554},{"atl":[[780,3.8]],"id":52671556}],"con":true,"img":false}]}
{"op":"mcm","clk":"11449971306","pt":1717316565077,"mc":[{"id":"1.229554898","rc":[{"atl":[[65,2.76]],"id":52671542},{"atl":[[27,2.8]],"id":52671544}],"con":true,"img":false}]}
{"op":"mcm","clk":"11449971569","pt":1717316569784,"mc":[{"id":"1.229554898","rc":[{"atb":[[170,3.88],[180,0]],"id":52671546},{"atb":[[8.6,4.24],[8.4,10.61]],"id":52671549},{"atl":[[21,0],[22,4.35]],"id":52671549},{"atb":[[1.19,608.92],[1.22,0]],"id":52671548},{"atl":[[320,0]],"id":52671545},{"atl":[[11,0],[11.5,3.41]],"id":52671554},{"atb":[[130,2.84],[140,0.38]],"id":52671556},{"atl":[[780,0]],"id":52671556}],"con":true,"img":false}]}
{"op":"mcm","clk":"11449971837","pt":1717316573708,"mc":[{"id":"1.229554898","rc":[{"atl":[[65,3.24]],"id":52671555}],"con":true,"img":false}]}
{"op":"mcm","clk":"11449971855","pt":1717316573911,"mc":[{"id":"1.229554898","rc":[{"atl":[[160,4.33]],"id":52671550}],"con":true,"img":false}]}
{"op":"mcm","clk":"11449971936","pt":1717316574893,"mc":[{"id":"1.229554898","rc":[{"atl":[[360,3.03]],"id":52671545}],"con":true,"img":false}]}
{"op":"mcm","clk":"11449971983","pt":1717316575513,"mc":[{"id":"1.229554898","rc":[{"atl":[[860,2],[930,0]],"id":52671545},{"atl":[[16,6.67],[17,0]],"id":52671554}],"con":true,"img":false}]}
{"op":"mcm","clk":"11449972271","pt":1717316579796,"mc":[{"id":"1.229554898","rc":[{"atb":[[8.2,4.45]],"id":52671549},{"atb":[[4.9,2.74]],"id":52671554},{"atl":[[890,4.02]],"id":52671556}],"con":true,"img":false}]}
{"op":"mcm","clk":"11449972646","pt":1717316585200,"mc":[{"id":"1.229554898","rc":[{"atb":[[8.6,0],[8.4,14.71]],"id":52671549},{"atb":[[1.19,526.32],[1.22,71.34]],"id":52671548},{"atb":[[5.1,0],[4.6,0],[5.2,2.7]],"id":52671554}],"con":true,"img":false}]}
{"op":"mcm","clk":"11449972720","pt":1717316586236,"mc":[{"id":"1.229554898","rc":[{"atb":[[170,0],[180,3.77]],"id":52671546},{"atb":[[9,4.37],[7.8,0],[8.4,10.61]],"id":52671549},{"atl":[[21,3.93],[22,0]],"id":52671549},{"atb":[[1.18,0],[1.23,0],[1.22,0],[1.13,0],[1.08,0],[1.17,92.32]],"id":52671548},{"atb":[[65,4.05],[60,0]],"id":52671545},{"atl":[[310,4.39],[340,0]],"id":52671545},{"atl":[[11,4.18],[11.5,0]],"id":52671554},{"atb":[[130,0],[150,4.22]],"id":52671556},{"atl":[[780,3.19],[870,0]],"id":52671556}],"con":true,"img":false}]}
{"op":"mcm","clk":"11449972729","pt":1717316586391,"mc":[{"id":"1.229554898","rc":[{"atb":[[1.18,555.56],[1.19,0]],"id":52671548}],"con":true,"img":false}]}
{"op":"mcm","clk":"11449972762","pt":1717316586907,"mc":[{"id":"1.229554898","rc":[{"atb":[[1.12,1525.06],[1.22,118.9],[1.07,1494.79],[1.17,400.08]],"id":52671548}],"con":true,"img":false}]}
{"op":"mcm","clk":"11449972786","pt":1717316587216,"mc":[{"id":"1.229554898","rc":[{"atb":[[8.8,4.33]],"id":52671549},{"atl":[[22,3.52]],"id":52671549},{"atb":[[1.21,74.74]],"id":52671548},{"atl":[[310,0],[350,3.86]],"id":52671545},{"atl":[[11,0],[11.5,3.56]],"id":52671554},{"atb":[[140,4.91],[150,0]],"id":52671556},{"atl":[[780,0],[900,4.02]],"id":52671556}],"con":true,"img":false}]}
{"op":"mcm","clk":"11449972793","pt":1717316587317,"mc":[{"id":"1.229554898","rc":[{"atb":[[9,0]],"id":52671549},{"atl":[[21,0]],"id":52671549}],"con":true,"img":false}]}
{"op":"mcm","clk":"11449972816","pt":1717316587626,"mc":[{"id":"1.229554898","rc":[{"atb":[[170,3.67],[180,0]],"id":52671546},{"atb":[[8.4,14.56]],"id":52671549},{"atb":[[1.22,190.24]],"id":52671548},{"atb":[[65,0],[60,3.24]],"id":52671545},{"atb":[[130,3.67]],"id":52671556}],"con":true,"img":false}]}
{"op":"mcm","clk":"11449972881","pt":1717316588410,"mc":[{"id":"1.229554898","rc":[{"atb":[[22,4.76]],"id":52671545},{"atl":[[670,2]],"id":52671545},{"atb":[[2.78,56.18],[2.94,0]],"id":52671554},{"atl":[[16,0],[14.5,6.86]],"id":52671554}],"con":true,"img":false}]}
{"op":"mcm","clk":"11449972888","pt":1717316588512,"mc":[{"id":"1.229554898","rc":[{"atb":[[30,0]],"id":52671545},{"atl":[[860,0]],"id":52671545}],"con":true,"img":false}]}
{"op":"mcm","clk":"11449972911","pt":1717316588718,"mc":[{"id":"1.229554898","rc":[{"atl":[[130,3.17]],"id":52671550},{"atb":[[8.8,0]],"id":52671549},{"atl":[[22,0]],"id":52671549},{"atb":[[1.17,307.75]],"id":52671548},{"atl":[[310,2.63]],"id":52671545},{"atl":[[25,0]],"id":52671544}],"con":true,"img":false}]}
{"op":"mcm","clk":"11449972921","pt":1717316588827,"mc":[{"id":"1.229554898","rc":[{"atl":[[140,0]],"id":52671550},{"atl":[[21,4.37]],"id":52671549},{"atl":[[48,4.35],[55,0]],"id":52671542},{"atl":[[350,0]],"id":52671545},{"atl":[[22,3.26]],"id":52671544},{"atb":[[5.2,0]],"id":52671554},{"atl":[[11,3.1],[11.5,0]],"id":52671554},{"atb":[[140,0.38]],"id":52671556},{"atl":[[780,3.7],[890,0]],"id":52671556}],"con":true,"img":false}]}
{"op":"mcm","clk":"11449973298","pt":1717316593851,"mc":[{"id":"1.229554898","rc":[{"atb":[[85,0],[44,0],[120,0],[60,0]],"id":52671546},{"atb":[[140,0],[70,0],[190,0],[95,0]],"id":52671556}],"con":true,"img":false}]}
{"op":"mcm","clk":"11449973345","pt":1717316594526,"mc":[{"id":"1.229554898","rc":[{"atb":[[300,0.26],[350,0.15],[400,0.07],[250,0.42]],"id":52671546},{"atb":[[140,0.57],[190,0.28],[95,1.11],[240,0.11]],"id":52671556}],"con":true,"img":false}]}
{"op":"mcm","clk":"11449973487","pt":1717316596446,"mc":[{"id":"1.229554898","rc":[{"atl":[[21,0]],"id":52671549},{"atl":[[310,0],[330,3.84]],"id":52671545},{"atl":[[780,0],[840,4.7]],"id":52671556}],"con":true,"img":false}]}
{"op":"mcm","clk":"11449973532","pt":1717316597070,"mc":[{"id":"1.229554898","rc":[{"atb":[[300,0],[350,0],[400,0],[250,0]],"id":52671546},{"atb":[[9,4.59],[8.4,10.61]],"id":52671549},{"atb":[[1.21,0],[1.22,118.9],[1.17,400.08]],"id":52671548},{"atb":[[65,4.32]],"id":52671545},{"atl":[[11.5,2.67]],"id":52671554},{"atb":[[130,0],[140,3.62],[190,0],[95,0],[240,0]],"id":52671556},{"atl":[[920,2.9]],"id":52671556}],"con":true,"img":false}]}
{"op":"mcm","clk":"11449973540","pt":1717316597127,"mc":[{"id":"1.229554898","rc":[{"atb":[[60,0]],"id":52671545},{"atl":[[11,0]],"id":52671554}],"con":true,"img":false}]}
{"op":"mcm","clk":"11449973579","pt":1717316597743,"mc":[{"id":"1.229554898","rc":[{"atb":[[270,0.1],[170,0.47],[220,0.24],[120,0.88]],"id":52671556}],"con":true,"img":false}]}
{"op":"mcm","clk":"11449973584","pt":1717316597846,"mc":[{"id":"1.229554898","rc":[{"atb":[[330,0.32],[380,0.21],[430,0.12],[480,0.05]],"id":52671546}],"con":true,"img":false}]}
{"op":"mcm","clk":"11449973609","pt":1717316598308,"mc":[{"id":"1.229554898","rc":[{"atb":[[1.22,518.98]],"id":52671548}],"con":true,"img":false}]}
{"op":"mcm","clk":"11449973619","pt":1717316598409,"mc":[{"id":"1.229554898","rc":[{"atb":[[1.18,0]],"id":52671548}],"con":true,"img":false}]}
{"op":"mcm","clk":"11449973634","pt":1717316598624,"mc":[{"id":"1.229554898","rc":[{"atb":[[9,0],[8.8,4.1]],"id":52671549},{"atb":[[1.23,68.23]],"id":52671548},{"atb":[[65,0],[60,2.67]],"id":52671545},{"atl":[[330,0],[370,4.14]],"id":52671545},{"atl":[[840,0],[900,0],[920,0],[950,3.51]],"id":52671556}],"con":true,"img":false}]}
{"op":"mcm","clk":"11449973655","pt":1717316598826,"mc":[{"id":"1.229554898","rc":[{"atl":[[55,4.42]],"id":52671542},{"atl":[[24,3.32]],"id":52671544}],"con":true,"img":false}]}
{"op":"mcm","clk":"11449973670","pt":1717316599034,"mc":[{"id":"1.229554898","rc":[{"atb":[[8.4,13.55]],"id":52671549},{"atb":[[1.22,590.32]],"id":52671548},{"atb":[[130,2.63],[140,0]],"id":52671556}],"con":true,"img":false}]}
{"op":"mcm","clk":"11449973989","pt":1717316603534,"mc":[{"id":"1.229554898","rc":[{"atb":[[270,0],[170,0],[220,0],[120,0]],"id":52671556}],"con":true,"img":false}]}
{"op":"mcm","clk":"11449974034","pt":1717316604255,"mc":[{"id":"1.229554898","rc":[{"atb":[[140,0.57],[190,0.28],[95,1.11],[240,0.11]],"id":52671556}],"con":true,"img":false}]}
{"op":"mcm","clk":"11449974228","pt":1717316607052,"mc":[{"id":"1.229554898","rc":[{"atb":[[4.7,4.3]],"id":52671554}],"con":true,"img":false}]}
{"op":"mcm","clk":"11449974353","pt":1717316608453,"mc":[{"id":"1.229554898","rc":[{"atb":[[9,3.74],[8.2,0],[8.8,0]],"id":52671549},{"atb":[[1.23,0],[1.22,518.98]],"id":52671548},{"atl":[[65,0]],"id":52671542},{"atb":[[65,3.62],[60,0]],"id":52671545},{"atl":[[27,0]],"id":52671544},{"atb":[[130,0],[140,3.58]],"id":52671556},{"atl":[[920,3.07]],"id":52671556}],"con":true,"img":false}]}
{"op":"mcm","clk":"11449974396","pt":1717316609022,"mc":[{"id":"1.229554898","rc":[{"atb":[[1.15,104.63]],"id":52671548}],"con":true,"img":false}]}
{"op":"mcm","clk":"11449974439","pt":1717316609950,"mc":[{"id":"1.229554898","rc":[{"atb":[[60,3.41]],"id":52671545}],"con":true,"img":false}]}
{"op":"mcm","clk":"11449974446","pt":1717316610053,"mc":[{"id":"1.229554898","rc":[{"atb":[[9,0],[8.8,3.76]],"id":52671549},{"atb":[[1.23,68.23],[1.17,307.75]],"id":52671548},{"atb":[[65,0]],"id":52671545},{"atl":[[360,0]],"id":52671545},{"atl":[[920,0]],"id":52671556}],"con":true,"img":false}]}
{"op":"mcm","clk":"11449974469","pt":1717316610467,"mc":[{"id":"1.229554898","rc":[{"atb":[[1.22,590.32]],"id":52671548},{"atb":[[130,3.08],[140,0.57]],"id":52671556}],"con":true,"img":false}]}
{"op":"mcm","clk":"11449974602","pt":1717316612646,"mc":[{"id":"1.229554898","rc":[{"atb":[[8.8,0]],"id":52671549},{"atb":[[1.23,0]],"id":52671548},{"atl":[[920,3.82]],"id":52671556}],"con":true,"img":false}]}
{"op":"mcm","clk":"11449974609","pt":1717316612749,"mc":[{"id":"1.229554898","rc":[{"atl":[[360,2.73]],"id":52671545}],"con":true,"img":false}]}
{"op":"mcm","clk":"11449974969","pt":1717316618064,"mc":[{"id":"1.229554898","rc":[{"atb":[[8,3.78],[11,0],[7.4,0],[8.4,0],[9.4,0]],"id":52671549},{"atl":[[21,3.88]],"id":52671549},{"atb":[[1.25,62.78],[1.22,518.98]],"id":52671548},{"atb":[[55,4.65],[60,0]],"id":52671545},{"atl":[[330,2.92],[360,0]],"id":52671545},{"atb":[[4.8,3.4],[4.9,0]],"id":52671554},{"atb":[[130,0],[140,0],[190,0],[95,0],[240,0],[120,4.65]],"id":52671556},{"atl":[[850,2.77],[920,0]],"id":52671556}],"con":true,"img":false}]}
{"op":"mcm","clk":"11449975002","pt":1717316618538,"mc":[{"id":"1.229554898","rc":[{"atl":[[530,2],[600,0]],"id":52671550},{"atb":[[1.24,307.76]],"id":52671548},{"atl":[[14,5.97],[14.5,0]],"id":52671554}],"con":true,"img":false}]}
{"op":"mcm","clk":"11449975008","pt":1717316618639,"mc":[{"id":"1.229554898","rc":[{"atb":[[1.22,118.9]],"id":52671548}],"con":true,"img":false}]}
{"op":"mcm","clk":"11449975017","pt":1717316618743,"mc":[{"id":"1.229554898","rc":[{"atb":[[7.2,16.88],[9.2,6.38],[10.5,2.75],[8.2,10.9]],"id":52671549},{"atb":[[170,0.31],[85,1.25],[220,0.12],[120,5.32]],"id":52671556}],"con":true,"img":false}]}
{"op":"mcm","clk":"11449975024","pt":1717316618846,"mc":[{"id":"1.229554898","rc":[{"atl":[[110,4.54]],"id":52671550}],"con":true,"img":false}]}
{"op":"mcm","clk":"11449975030","pt":1717316619002,"mc":[{"id":"1.229554898","rc":[{"atl":[[130,0]],"id":52671550},{"atl":[[21,0],[22,4.64]],"id":52671549},{"atb":[[75,0],[40,0],[100,0],[50,0]],"id":52671545},{"atl":[[330,0],[340,2.74]],"id":52671545},{"atl":[[22,0],[23,2.69]],"id":52671544},{"atl":[[46,4.44],[55,0]],"id":52671555},{"atl":[[11,4.04],[11.5,0]],"id":52671554},{"atl":[[850,0],[870,3.59]],"id":52671556}],"con":true,"img":false}]}
{"op":"mcm","clk":"11449975079","pt":1717316619783,"mc":[{"id":"1.229554898","rc":[{"atb":[[70,0.76],[38,2.83],[95,0.28],[48,6.38]],"id":52671545}],"con":true,"img":false}]}
{"op":"mcm","clk":"11449975087","pt":1717316619887,"mc":[{"id":"1.229554898","rc":[{"atb":[[8.2,14.05]],"id":52671549},{"atb":[[1.25,0],[1.19,82.6]],"id":52671548},{"atb":[[16.5,0],[19,0],[11.5,0],[14,0]],"id":52671542},{"atb":[[55,0]],"id":52671545}],"con":true,"img":false}]}
{"op":"mcm","clk":"11449975092","pt":1717316619941,"mc":[{"id":"1.229554898","rc":[{"atb":[[65,3.45]],"id":52671545}],"con":true,"img":false}]}
{"op":"mcm","clk":"11449975118","pt":1717316620256,"mc":[{"id":"1.229554898","rc":[{"atb":[[10.5,0],[15.5,0]],"id":52671550},{"atb":[[550,0],[450,0]],"id":52671546},{"atb":[[4.8,0],[5.8,0]],"id":52671549},{"atb":[[1.12,653.97],[1.02,109.92]],"id":52671548},{"atb":[[9,0],[7,0]],"id":52671542},{"atb":[[17,0],[24,0]],"id":52671545},{"atb":[[5.7,0],[4.7,0]],"id":52671544},{"atb":[[10.5,0],[8.2,0]],"id":52671555},{"atb":[[4,0],[3.5,0]],"id":52671554},{"atb":[[160,0],[80,0]],"id":52671556}],"con":true,"img":false}]}
{"op":"mcm","clk":"11449975142","pt":1717316620562,"mc":[{"id":"1.229554898","rc":[{"atb":[[18,3.08],[21,1.31],[13,8.72],[15.5,5.41]],"id":52671542}],"con":true,"img":false}]}
{"op":"mcm","clk":"11449975226","pt":1717316621669,"mc":[{"id":"1.229554898","rc":[{"atb":[[8.2,10.9]],"id":52671549},{"atb":[[1.25,62.78]],"id":52671548},{"atb":[[65,0],[55,4.08]],"id":52671545},{"atb":[[4,0]],"id":52671544},{"atb":[[1.52,0]],"id":52671555}],"con":true,"img":false}]}
{"op":"mcm","clk":"11449975234","pt":1717316621778,"mc":[{"id":"1.229554898","rc":[{"atb":[[1.52,0]],"id":52671550},{"atb":[[1.19,0]],"id":52671548}],"con":true,"img":false}]}
{"op":"mcm","clk":"11449975423","pt":1717316624151,"mc":[{"id":"1.229554898","rc":[{"atl":[[860,2.94],[870,0]],"id":52671556}],"con":true,"img":false}]}
{"op":"mcm","clk":"11449975452","pt":1717316624565,"mc":[{"id":"1.229554898","rc":[{"atb":[[170,0],[85,0],[220,0],[120,4.65]],"id":52671556}],"con":true,"img":false}]}
{"op":"mcm","clk":"11449975517","pt":1717316625244,"mc":[{"id":"1.229554898","rc":[{"atb":[[160,0.33],[80,1.32],[210,0.13],[110,0.72]],"id":52671556}],"con":true,"img":false}]}
{"op":"mcm","clk":"11449975790","pt":1717316628794,"mc":[{"id":"1.229554898","rc":[{"atl":[[22,0]],"id":52671549},{"atb":[[1.25,0],[1.23,68.23]],"id":52671548},{"atl":[[340,0],[360,4.32]],"id":52671545},{"atl":[[11,0],[11.5,4.11]],"id":52671554},{"atl":[[860,0],[930,4.26]],"id":52671556}],"con":true,"img":false}]}
{"op":"mcm","clk":"11449975803","pt":1717316628946,"mc":[{"id":"1.229554898","rc":[{"atl":[[130,3.76]],"id":52671550},{"atl":[[50,4.68]],"id":52671555}],"con":true,"img":false}]}
{"op":"mcm","clk":"11449975861","pt":1717316629976,"mc":[{"id":"1.229554898","rc":[{"atb":[[7.6,3.66]],"id":52671549},{"atl":[[25,3.02]],"id":52671549}],"con":true,"img":false}]}
{"op":"mcm","clk":"11449976002","pt":1717316632059,"mc":[{"id":"1.229554898","rc":[{"atl":[[160,0]],"id":52671550},{"atb":[[8,0],[8.4,3.77]],"id":52671549},{"atb":[[1.21,74.74],[1.23,0]],"id":52671548},{"atb":[[60,3.27]],"id":52671545},{"atl":[[65,0]],"id":52671555}],"con":true,"img":false}]}
{"op":"mcm","clk":"11449976009","pt":1717316632162,"mc":[{"id":"1.229554898","rc":[{"atb":[[170,0],[180,4.47]],"id":52671546},{"atb":[[1.23,434.78]],"id":52671548},{"atb":[[55,0]],"id":52671545},{"atl":[[930,0]],"id":52671556}],"con":true,"img":false}]}
{"op":"mcm","clk":"11449976013","pt":1717316632265,"mc":[{"id":"1.229554898","rc":[{"atb":[[1.24,0]],"id":52671548}],"con":true,"img":false}]}
{"op":"mcm","clk":"11449976085","pt":1717316633353,"mc":[{"id":"1.229554898","rc":[{"atl":[[23,0],[24,3.43]],"id":52671549},{"atl":[[360,0]],"id":52671545},{"atl":[[11.5,0]],"id":52671554},{"atl":[[950,0]],"id":52671556}],"con":true,"img":false}]}
{"op":"mcm","clk":"11449976089","pt":1717316633454,"mc":[{"id":"1.229554898","rc":[{"atl":[[380,3.47]],"id":52671545},{"atl":[[11,4.02]],"id":52671554}],"con":true,"img":false}]}
{"op":"mcm","clk":"11449976138","pt":1717316634080,"mc":[{"id":"1.229554898","rc":[{"atb":[[8.6,3.02],[8.4,0]],"id":52671549},{"atb":[[1.18,87.19],[1.21,0]],"id":52671548},{"atl":[[370,0]],"id":52671545}],"con":true,"img":false}]}
{"op":"mcm","clk":"11449976700","pt":1717316642074,"mc":[{"id":"1.229554898","rc":[{"atb":[[160,4.57]],"id":52671546}],"con":true,"img":false}]}
{"op":"mcm","clk":"11449976765","pt":1717316643022,"mc":[{"id":"1.229554898","rc":[{"atb":[[140,0]],"id":52671546},{"atb":[[8.6,0],[8.4,2.67]],"id":52671549},{"atl":[[24,0]],"id":52671549},{"atb":[[1.18,0],[1.21,74.74]],"id":52671548},{"atl":[[380,0],[410,2.98]],"id":52671545},{"atl":[[46,0],[48,3.4]],"id":52671555},{"atl":[[11,0],[11.5,3.36]],"id":52671554}],"con":true,"img":false}]}
{"op":"mcm","clk":"11449977037","pt":1717316646319,"mc":[{"id":"1.229554898","rc":[{"atb":[[8.4,0]],"id":52671549},{"atb":[[1.21,0]],"id":52671548}],"con":true,"img":false}]}
{"op":"mcm","clk":"11449977042","pt":1717316646421,"mc":[{"id":"1.229554898","rc":[{"atb":[[8.6,3.31]],"id":52671549},{"atb":[[1.18,87.19]],"id":52671548}],"con":true,"img":false}]}
{"op":"mcm","clk":"11449977067","pt":1717316646579,"mc":[{"id":"1.229554898","rc":[{"atl":[[24,4.29]],"id":52671549}],"con":true,"img":false}]}
{"op":"mcm","clk":"11449977153","pt":1717316647613,"mc":[{"id":"1.229554898","rc":[{"atl":[[530,0],[600,2]],"id":52671550},{"atb":[[1.19,526.32],[1.23,0]],"id":52671548},{"atb":[[22,0],[30,3.45]],"id":52671545},{"atl":[[670,0],[930,2]],"id":52671545},{"atb":[[2.78,0],[2.94,51.55]],"id":52671554},{"atl":[[17,6.25],[14,0]],"id":52671554}],"con":true,"img":false}]}
{"op":"mcm","clk":"11449977175","pt":1717316647926,"mc":[{"id":"1.229554898","rc":[{"atl":[[110,0]],"id":52671550},{"atl":[[48,0]],"id":52671542},{"atl":[[23,0],[25,3.89]],"id":52671544},{"atl":[[48,0],[55,3.36]],"id":52671555},{"atb":[[4.8,0],[5.1,2.76]],"id":52671554},{"atb":[[140,4.17],[120,0]],"id":52671556}],"con":true,"img":false}]}
{"op":"mcm","clk":"11449977195","pt":1717316648084,"mc":[{"id":"1.229554898","rc":[{"atl":[[130,0],[140,2.79]],"id":52671550}],"con":true,"img":false}]}
{"op":"mcm","clk":"11449977257","pt":1717316648908,"mc":[{"id":"1.229554898","rc":[{"atl":[[24,0]],"id":52671544},{"atl":[[50,0]],"id":52671555}],"con":true,"img":false}]}
{"op":"mcm","clk":"11449977287","pt":1717316649320,"mc":[{"id":"1.229554898","rc":[{"atb":[[30,0]],"id":52671545}],"con":true,"img":false}]}
{"op":"mcm","clk":"11449977293","pt":1717316649424,"mc":[{"id":"1.229554898","rc":[{"atb":[[22,4.76]],"id":52671545}],"con":true,"img":false}]}
{"op":"mcm","clk":"11449977306","pt":1717316649631,"mc":[{"id":"1.229554898","rc":[{"atl":[[130,3.81]],"id":52671550},{"atl":[[48,2.69]],"id":52671542},{"atl":[[22,2.99]],"id":52671544},{"atb":[[5.1,0],[4.9,3.47]],"id":52671554}],"con":true,"img":false}]}
{"op":"mcm","clk":"11449977555","pt":1717316652695,"mc":[{"id":"1.229554898","rc":[{"atb":[[2.78,56.18]],"id":52671554}],"con":true,"img":false}]}
{"op":"mcm","clk":"11449977564","pt":1717316652797,"mc":[{"id":"1.229554898","rc":[{"atb":[[2.94,0]],"id":52671554}],"con":true,"img":false}]}
{"op":"mcm","clk":"11449977572","pt":1717316652900,"mc":[{"id":"1.229554898","rc":[{"atl":[[410,0],[480,3.91]],"id":52671545}],"con":true,"img":false}]}
{"op":"mcm","clk":"11449977682","pt":1717316654296,"mc":[{"id":"1.229554898","rc":[{"atb":[[1.18,642.75],[1.19,0]],"id":52671548},{"atl":[[930,0]],"id":52671545}],"con":true,"img":false}]}
{"op":"mcm","clk":"11449977704","pt":1717316654712,"mc":[{"id":"1.229554898","rc":[{"atl":[[27,4.26]],"id":52671544},{"atb":[[5.1,2.78],[4.9,0]],"id":52671554},{"atl":[[11.5,0]],"id":52671554}],"con":true,"img":false}]}
{"op":"mcm","clk":"11449977710","pt":1717316654714,"mc":[{"id":"1.229554898","rc":[{"atl":[[150,3.09]],"id":52671550},{"atl":[[24,0]],"id":52671549},{"atl":[[48,0],[55,0],[60,2.86]],"id":52671542},{"atl":[[22,0],[25,0]],"id":52671544},{"atl":[[55,0],[60,3.28]],"id":52671555}],"con":true,"img":false}]}
{"op":"mcm","clk":"11449977716","pt":1717316654812,"mc":[{"id":"1.229554898","rc":[{"atl":[[130,0]],"id":52671550}],"con":true,"img":false}]}
{"op":"mcm","clk":"11449977847","pt":1717316656626,"mc":[{"id":"1.229554898","rc":[{"atb":[[8.2,15.12]],"id":52671549},{"atl":[[24,2.71]],"id":52671549}],"con":true,"img":false}]}
{"op":"mcm","clk":"11449977945","pt":1717316657624,"mc":[{"id":"1.229554898","rc":[{"atb":[[16,6.96],[11,24.39]],"id":52671550},{"atb":[[610,0.17],[510,0.48]],"id":52671546},{"atb":[[5.1,59.49],[6.2,20.1]],"id":52671549},{"atb":[[1.01,24390.49],[1.11,950.27]],"id":52671548},{"atb":[[7.2,39.33],[9.2,12.74]],"id":52671542},{"atb":[[18,14.34],[26,4.18]],"id":52671545},{"atb":[[5.6,22.72],[4.6,67.75]],"id":52671544},{"atb":[[10.5,11],[8.2,33.87]],"id":52671555},{"atb":[[3.45,99.55],[3.95,35.43]],"id":52671554},{"atb":[[100,5.81],[200,0.52]],"id":52671556}],"con":true,"img":false}]}
{"op":"mcm","clk":"11449977969","pt":1717316657928,"mc":[{"id":"1.229554898","rc":[{"atb":[[120,4.67]],"id":52671556}],"con":true,"img":false}]}
{"op":"mcm","clk":"11449978047","pt":1717316658827,"mc":[{"id":"1.229554898","rc":[{"atb":[[2.78,0]],"id":52671554}],"con":true,"img":false}]}
{"op":"mcm","clk":"11449978057","pt":1717316658923,"mc":[{"id":"1.229554898","rc":[{"atb":[[2.98,50.51]],"id":52671554}],"con":true,"img":false}]}
{"op":"mcm","clk":"11449978124","pt":1717316659605,"mc":[{"id":"1.229554898","rc":[{"atl":[[140,0]],"id":52671550},{"atb":[[7.6,0]],"id":52671549},{"atl":[[24,0]],"id":52671549},{"atb":[[100,2.46]],"id":52671556}],"con":true,"img":false}]}
{"op":"mcm","clk":"11449978197","pt":1717316660626,"mc":[{"id":"1.229554898","rc":[{"atb":[[22,0],[30,3.45]],"id":52671545}],"con":true,"img":false}]}
{"op":"mcm","clk":"11449978363","pt":1717316662906,"mc":[{"id":"1.229554898","rc":[{"atl":[[500,3.98]],"id":52671545}],"con":true,"img":false}]}
{"op":"mcm","clk":"11449978493","pt":1717316664621,"mc":[{"id":"1.229554898","rc":[{"atl":[[170,3.46]],"id":52671550},{"atl":[[70,3.53]],"id":52671542},{"atl":[[29,3.3]],"id":52671544}],"con":true,"img":false}]}
{"op":"mcm","clk":"11449978503","pt":1717316664734,"mc":[{"id":"1.229554898","rc":[{"atl":[[70,3.26]],"id":52671555},{"atb":[[4.9,3.34]],"id":52671554},{"atl":[[13,4.53]],"id":52671554}],"con":true,"img":false}]}
{"op":"mcm","clk":"11449978656","pt":1717316666637,"mc":[{"id":"1.229554898","rc":[{"atl":[[25,0],[26,4.42]],"id":52671549}],"con":true,"img":false}]}
{"op":"mcm","clk":"11449979137","pt":1717316672949,"mc":[{"id":"1.229554898","rc":[{"atl":[[470,2.63],[480,0]],"id":52671545}],"con":true,"img":false}]}
{"op":"mcm","clk":"11449979274","pt":1717316674817,"mc":[{"id":"1.229554898","rc":[{"atb":[[4.7,0]],"id":52671554}],"con":true,"img":false}]}
{"op":"mcm","clk":"11449979354","pt":1717316676317,"mc":[{"id":"1.229554898","rc":[{"atl":[[25,3.4]],"id":52671549},{"atb":[[1.18,555.56],[1.17,400.08]],"id":52671548},{"atb":[[80,2.88],[60,0]],"id":52671545},{"atl":[[470,0],[480,3.75]],"id":52671545},{"atb":[[7.2,0],[9.2,0],[10.5,0],[8.2,0]],"id":52671544},{"atb":[[5.1,0],[5,3.98]],"id":52671554}],"con":true,"img":false}]}
{"op":"mcm","clk":"11449979401","pt":1717316677150,"mc":[{"id":"1.229554898","rc":[{"atb":[[9.6,6.08],[8.6,10.33],[11.5,2.49],[7.6,15.85]],"id":52671544}],"con":true,"img":false}]}
{"op":"mcm","clk":"11449979457","pt":1717316677925,"mc":[{"id":"1.229554898","rc":[{"atb":[[8.6,0],[8.8,3.38],[8.4,4.07]],"id":52671549},{"atb":[[1.12,0],[1.16,98.09],[1.22,0],[1.07,0],[1.17,0]],"id":52671548},{"atb":[[75,2.98],[80,0],[85,3.73]],"id":52671545},{"atb":[[5.2,2.98]],"id":52671554},{"atb":[[140,0],[150,4.26]],"id":52671556}],"con":true,"img":false}]}
{"op":"mcm","clk":"11449979469","pt":1717316678039,"mc":[{"id":"1.229554898","rc":[{"atb":[[1.18,0],[1.17,588.24]],"id":52671548},{"atb":[[5,0]],"id":52671554}],"con":true,"img":false}]}
{"op":"mcm","clk":"11449979512","pt":1717316678542,"mc":[{"id":"1.229554898","rc":[{"atb":[[9,4.38]],"id":52671549},{"atb":[[65,3.13]],"id":52671545},{"atl":[[770,2]],"id":52671545},{"atb":[[2.82,54.95],[5.3,4.03],[2.98,0]],"id":52671554},{"atl":[[17,0],[15.5,6.9]],"id":52671554},{"atb":[[160,4.02]],"id":52671556}],"con":true,"img":false}]}
{"op":"mcm","clk":"11449979519","pt":1717316678643,"mc":[{"id":"1.229554898","rc":[{"atb":[[1.12,653.97],[1.22,118.9],[1.07,1494.79],[1.17,895.99]],"id":52671548}],"con":true,"img":false}]}
{"op":"mcm","clk":"11449979526","pt":1717316678747,"mc":[{"id":"1.229554898","rc":[{"atb":[[1.2,237.82],[1.17,307.75]],"id":52671548}],"con":true,"img":false}]}
{"op":"mcm","clk":"11449979530","pt":1717316678850,"mc":[{"id":"1.229554898","rc":[{"atl":[[130,3.97],[150,0]],"id":52671550},{"atb":[[8.2,10.9],[8.8,0]],"id":52671549},{"atb":[[1.16,0],[1.17,400.08]],"id":52671548},{"atl":[[55,4.66],[60,0]],"id":52671542},{"atb":[[75,0],[85,0]],"id":52671545},{"atl":[[25,4.68],[27,0]],"id":52671544},{"atl":[[55,4.54],[60,0]],"id":52671555},{"atb":[[5.1,4.53],[5.2,0]],"id":52671554}],"con":true,"img":false}]}
{"op":"mcm","clk":"11449979536","pt":1717316678955,"mc":[{"id":"1.229554898","rc":[{"atb":[[48,1.67]],"id":52671545}],"con":true,"img":false}]}
{"op":"mcm","clk":"11449980148","pt":1717316687766,"mc":[{"id":"1.229554898","rc":[{"atb":[[9,0],[8.8,3.03]],"id":52671549},{"atb":[[1.2,316.29],[1.17,307.75]],"id":52671548},{"atb":[[85,3.25]],"id":52671545},{"atb":[[5.3,0]],"id":52671554},{"atb":[[160,0.33]],"id":52671556}],"con":true,"img":false}]}
{"op":"mcm","clk":"11449980180","pt":1717316688090,"mc":[{"id":"1.229554898","rc":[{"atb":[[1.16,98.09]],"id":52671548}],"con":true,"img":false}]}
{"op":"mcm","clk":"11449980201","pt":1717316688338,"mc":[{"id":"1.229554898","rc":[{"atb":[[70,4.92]],"id":52671545}],"con":true,"img":false}]}
{"op":"mcm","clk":"11449980238","pt":1717316688856,"mc":[{"id":"1.229554898","rc":[{"atl":[[150,4.27]],"id":52671550},{"atl":[[27,3.97]],"id":52671544}],"con":true,"img":false}]}
{"op":"mcm","clk":"11449980816","pt":1717316697729,"mc":[{"id":"1.229554898","rc":[{"atb":[[1.18,87.19],[1.15,0]],"id":52671548},{"atb":[[85,0],[60,3.79]],"id":52671545}],"con":true,"img":false}]}
{"op":"mcm","clk":"11449980897","pt":1717316698970,"mc":[{"id":"1.229554898","rc":[{"atl":[[170,0]],"id":52671550},{"atl":[[29,0]],"id":52671544}],"con":true,"img":false}]}
{"op":"mcm","clk":"11449981226","pt":1717316703570,"mc":[{"id":"1.229554898","rc":[{"atb":[[1.16,0]],"id":52671548},{"atb":[[60,0]],"id":52671545}],"con":true,"img":false}]}
{"op":"mcm","clk":"11449981606","pt":1717316708857,"mc":[{"id":"1.229554898","rc":[{"atb":[[16,0],[11,0]],"id":52671550},{"atb":[[610,0],[510,0]],"id":52671546},{"atb":[[5.1,0],[6.2,0]],"id":52671549},{"atb":[[1.01,0],[1.11,0]],"id":52671548},{"atb":[[7.2,0],[9.2,0]],"id":52671542},{"atb":[[18,0],[26,0]],"id":52671545},{"atb":[[5.6,0],[4.6,0]],"id":52671544},{"atb":[[10.5,0],[8.2,0]],"id":52671555},{"atb":[[3.45,0],[3.95,0]],"id":52671554},{"atb":[[200,0],[100,0]],"id":52671556}],"con":true,"img":false}]}
{"op":"mcm","clk":"11449981668","pt":1717316709885,"mc":[{"id":"1.229554898","rc":[{"atb":[[330,0],[380,0],[430,0],[480,0]],"id":52671546}],"con":true,"img":false}]}
{"op":"mcm","clk":"11449981713","pt":1717316710574,"mc":[{"id":"1.229554898","rc":[{"atb":[[530,0.05],[380,0.28],[430,0.18],[480,0.11]],"id":52671546}],"con":true,"img":false}]}
{"op":"mcm","clk":"11449981863","pt":1717316712486,"mc":[{"id":"1.229554898","rc":[{"atb":[[180,0],[190,3.69]],"id":52671546}],"con":true,"img":false}]}
{"op":"mcm","clk":"11449981965","pt":1717316713566,"mc":[{"id":"1.229554898","rc":[{"atb":[[180,3.35],[190,0]],"id":52671546},{"atb":[[9.6,3.47],[8.8,0]],"id":52671549},{"atb":[[1.2,237.82]],"id":52671548},{"atb":[[70,0.76],[80,4.52]],"id":52671545}],"con":true,"img":false}]}
{"op":"mcm","clk":"11449982349","pt":1717316719089,"mc":[{"id":"1.229554898","rc":[{"atb":[[1.16,98.09]],"id":52671548}],"con":true,"img":false}]}
{"op":"mcm","clk":"11449982538","pt":1717316721696,"mc":[{"id":"1.229554898","rc":[{"atb":[[18,12.3],[13,20.32]],"id":52671550},{"atb":[[550,0.44],[650,0.16]],"id":52671546},{"atb":[[5.6,53.02],[7.2,33.74]],"id":52671549},{"atb":[[1.01,24390.49],[1.04,2613.26]],"id":52671548},{"atb":[[7.4,38.1],[9.4,12.44]],"id":52671542},{"atb":[[32,3.37],[21,12.19]],"id":52671545},{"atb":[[4.8,64.18],[5.8,21.77]],"id":52671544},{"atb":[[9,30.48],[12.5,9.08]],"id":52671555},{"atb":[[3.7,90.33],[4.4,30.74]],"id":52671554},{"atb":[[340,0.72],[440,0.24]],"id":52671556}],"con":true,"img":false}]}
{"op":"mcm","clk":"11449982665","pt":1717316723596,"mc":[{"id":"1.229554898","rc":[{"atb":[[9.2,9.63]],"id":52671549}],"con":true,"img":false}]}
{"op":"mcm","clk":"11449982706","pt":1717316724274,"mc":[{"id":"1.229554898","rc":[{"atb":[[9.6,0],[8.8,4.47]],"id":52671549},{"atb":[[1.2,316.29],[1.18,0]],"id":52671548},{"atb":[[70,4.95],[80,0]],"id":52671545}],"con":true,"img":false}]}
{"op":"mcm","clk":"11449982722","pt":1717316724579,"mc":[{"id":"1.229554898","rc":[{"atb":[[8.4,0]],"id":52671549}],"con":true,"img":false}]}
{"op":"mcm","clk":"11449983001","pt":1717316728707,"mc":[{"id":"1.229554898","rc":[{"atb":[[7.2,16.86],[9.2,3.24],[10.5,0],[8.2,0]],"id":52671549}],"con":true,"img":false}]}
{"op":"mcm","clk":"11449983039","pt":1717316729382,"mc":[{"id":"1.229554898","rc":[{"atb":[[9.2,12.81],[10.5,5.51],[8.2,14.53],[13,2.18]],"id":52671549}],"con":true,"img":false}]}
{"op":"mcm","clk":"11449983056","pt":1717316729587,"mc":[{"id":"1.229554898","rc":[{"atb":[[70,4.19],[38,0],[95,0],[48,0]],"id":52671545}],"con":true,"img":false}]}
{"op":"mcm","clk":"11449983102","pt":1717316730302,"mc":[{"id":"1.229554898","rc":[{"atb":[[70,5.33],[140,0.19],[95,0.55],[48,2.23]],"id":52671545}],"con":true,"img":false}]}
{"op":"mcm","clk":"11449983399","pt":1717316734281,"mc":[{"id":"1.229554898","rc":[{"atb":[[9.6,4.59],[9.2,9.57]],"id":52671549},{"atb":[[1.2,237.82],[1.18,87.19]],"id":52671548},{"atb":[[80,3.01]],"id":52671545}],"con":true,"img":false}]}
{"op":"mcm","clk":"11449983405","pt":1717316734385,"mc":[{"id":"1.229554898","rc":[{"atb":[[70,1.14]],"id":52671545}],"con":true,"img":false}]}
{"op":"mcm","clk":"11449983462","pt":1717316735374,"mc":[{"id":"1.229554898","rc":[{"atl":[[600,0],[500,2]],"id":52671550},{"atl":[[650,2],[770,0]],"id":52671545},{"atl":[[13.5,7.83],[15.5,0]],"id":52671554}],"con":true,"img":false}]}
{"op":"mcm","clk":"11449983478","pt":1717316735687,"mc":[{"id":"1.229554898","rc":[{"atb":[[9.6,0],[9.2,0],[10.5,0],[8.2,0],[13,0]],"id":52671549},{"atb":[[1.2,316.29]],"id":52671548},{"atb":[[70,4.46],[80,0]],"id":52671545}],"con":true,"img":false}]}
{"op":"mcm","clk":"11449983487","pt":1717316735787,"mc":[{"id":"1.229554898","rc":[{"atb":[[1.18,0]],"id":52671548}],"con":true,"img":false}]}
{"op":"mcm","clk":"11449983517","pt":1717316736413,"mc":[{"id":"1.229554898","rc":[{"atb":[[9.2,9.57],[10.5,5.51],[8.2,14.53],[13,2.18]],"id":52671549}],"con":true,"img":false}]}
{"op":"mcm","clk":"11449983620","pt":1717316737704,"mc":[{"id":"1.229554898","rc":[{"atb":[[140,0],[70,3.32],[95,0],[48,0]],"id":52671545}],"con":true,"img":false}]}
{"op":"mcm","clk":"11449983655","pt":1717316738426,"mc":[{"id":"1.229554898","rc":[{"atb":[[85,0.62],[44,2.43],[120,0.22],[60,1.33]],"id":52671545}],"con":true,"img":false}]}
{"op":"mcm","clk":"11449983822","pt":1717316741200,"mc":[{"id":"1.229554898","rc":[{"atl":[[600,2],[500,0]],"id":52671550},{"atl":[[650,0],[770,2]],"id":52671545},{"atl":[[13.5,0],[15.5,6.9]],"id":52671554}],"con":true,"img":false}]}
{"op":"mcm","clk":"11449983897","pt":1717316742126,"mc":[{"id":"1.229554898","rc":[{"atb":[[9.2,0],[10.5,0],[8.2,0],[13,0]],"id":52671549}],"con":true,"img":false}]}
{"op":"mcm","clk":"11449983917","pt":1717316742487,"mc":[{"id":"1.229554898","rc":[{"atb":[[9.6,2.98]],"id":52671549},{"atb":[[1.2,237.82],[1.18,87.19]],"id":52671548},{"atb":[[80,3.96]],"id":52671545}],"con":true,"img":false}]}
{"op":"mcm","clk":"11449983922","pt":1717316742588,"mc":[{"id":"1.229554898","rc":[{"atb":[[70,0]],"id":52671545}],"con":true,"img":false}]}
{"op":"mcm","clk":"11449983944","pt":1717316742801,"mc":[{"id":"1.229554898","rc":[{"atb":[[9.2,9.57],[10.5,5.51],[8.2,14.53],[13,2.18]],"id":52671549}],"con":true,"img":false}]}
{"op":"mcm","clk":"11449984056","pt":1717316744300,"mc":[{"id":"1.229554898","rc":[{"atb":[[9.6,0]],"id":52671549},{"atb":[[1.2,316.29],[1.18,0]],"id":52671548},{"atb":[[70,2.8],[80,0]],"id":52671545}],"con":true,"img":false}]}
{"op":"mcm","clk":"11449984240","pt":1717316746827,"mc":[{"id":"1.229554898","rc":[{"atb":[[1.2,237.82],[1.18,87.19]],"id":52671548}],"con":true,"img":false}]}
{"op":"mcm","clk":"11449984386","pt":1717316748835,"mc":[{"id":"1.229554898","rc":[{"atb":[[9.6,3.88]],"id":52671549}],"con":true,"img":false}]}
{"op":"mcm","clk":"11449984396","pt":1717316748936,"mc":[{"id":"1.229554898","rc":[{"atb":[[1.18,0],[1.15,104.63]],"id":52671548},{"atb":[[18,0],[21,0],[13,0],[15.5,0]],"id":52671542},{"atb":[[70,0],[100,3.27]],"id":52671545}],"con":true,"img":false}]}
{"op":"mcm","clk":"11449984453","pt":1717316749717,"mc":[{"id":"1.229554898","rc":[{"atb":[[16,5.23],[18.5,2.99],[22,1.25],[13.5,8.37]],"id":52671542}],"con":true,"img":false}]}
{"op":"mcm","clk":"11449984566","pt":1717316751518,"mc":[{"id":"1.229554898","rc":[{"atl":[[600,0],[500,2]],"id":52671550},{"atl":[[650,2],[770,0]],"id":52671545},{"atl":[[13.5,7.83],[15.5,0]],"id":52671554}],"con":true,"img":false}]}
{"op":"mcm","clk":"11449984614","pt":1717316752242,"mc":[{"id":"1.229554898","rc":[{"atb":[[1.18,87.19],[1.16,0]],"id":52671548},{"atb":[[80,4.34],[100,0]],"id":52671545}],"con":true,"img":false}]}
{"op":"mcm","clk":"11449984669","pt":1717316753022,"mc":[{"id":"1.229554898","rc":[{"atb":[[1.18,0]],"id":52671548},{"atb":[[80,0],[100,3.81]],"id":52671545}],"con":true,"img":false}]}
{"op":"mcm","clk":"11449984935","pt":1717316756848,"mc":[{"id":"1.229554898","rc":[{"atb":[[1.18,87.19]],"id":52671548}],"con":true,"img":false}]}
{"op":"mcm","clk":"11449984945","pt":1717316756950,"mc":[{"id":"1.229554898","rc":[{"atb":[[80,3.52],[100,0]],"id":52671545}],"con":true,"img":false}]}
{"op":"mcm","clk":"11449985088","pt":1717316758920,"mc":[{"id":"1.229554898","rc":[{"atb":[[9.2,12.82]],"id":52671549}],"con":true,"img":false}]}
{"op":"mcm","clk":"11449985437","pt":1717316763555,"mc":[{"id":"1.229554898","rc":[{"atb":[[1.18,0]],"id":52671548},{"atb":[[100,3.98]],"id":52671545}],"con":true,"img":false}]}
{"op":"mcm","clk":"11449985447","pt":1717316763660,"mc":[{"id":"1.229554898","rc":[{"atb":[[8.8,0]],"id":52671549},{"atb":[[80,0]],"id":52671545}],"con":true,"img":false}]}
{"op":"mcm","clk":"11449985704","pt":1717316766621,"mc":[{"id":"1.229554898","rc":[{"atb":[[1.13,120.73]],"id":52671548}],"con":true,"img":false}]}
{"op":"mcm","clk":"11449986264","pt":1717316773620,"mc":[{"id":"1.229554898","rc":[{"atb":[[90,3.1]],"id":52671545}],"con":true,"img":false}]}
{"op":"mcm","clk":"11449986342","pt":1717316774545,"mc":[{"id":"1.229554898","rc":[{"atb":[[65,0]],"id":52671545}],"con":true,"img":false}]}
{"op":"mcm","clk":"11449986501","pt":1717316776867,"mc":[{"id":"1.229554898","rc":[{"atb":[[9.6,0],[9.8,4.52]],"id":52671549},{"atb":[[85,4.76],[100,0]],"id":52671545}],"con":true,"img":false}]}
{"op":"mcm","clk":"11449987215","pt":1717316786058,"mc":[{"id":"1.229554898","rc":[{"atb":[[90,0]],"id":52671545}],"con":true,"img":false}]}
{"op":"mcm","clk":"11449987269","pt":1717316786887,"mc":[{"id":"1.229554898","rc":[{"atb":[[75,3.26]],"id":52671545}],"con":true,"img":false}]}
{"op":"mcm","clk":"11449988108","pt":1717316798500,"mc":[{"id":"1.229554898","rc":[{"atb":[[1.19,356.73]],"id":52671548},{"atl":[[650,0],[710,2]],"id":52671545},{"atb":[[2.82,0],[2.7,58.82]],"id":52671554},{"atl":[[13.5,0],[14.5,7.41]],"id":52671554}],"con":true,"img":false}]}
{"op":"mcm","clk":"11449988114","pt":1717316798599,"mc":[{"id":"1.229554898","rc":[{"atb":[[1.2,0]],"id":52671548}],"con":true,"img":false}]}
{"op":"mcm","clk":"11449988981","pt":1717316811308,"mc":[{"id":"1.229554898","rc":[{"atb":[[530,0],[380,0],[430,0],[480,0]],"id":52671546}],"con":true,"img":false}]}
{"op":"mcm","clk":"11449989036","pt":1717316811995,"mc":[{"id":"1.229554898","rc":[{"atb":[[540,0.05],[390,0.27],[440,0.18],[490,0.1]],"id":52671546}],"con":true,"img":false}]}
{"op":"mcm","clk":"11449990916","pt":1717316836338,"mc":[{"id":"1.229554898","rc":[{"atb":[[85,4.13],[44,0],[120,0],[60,0]],"id":52671545}],"con":true,"img":false}]}
{"op":"mcm","clk":"11449990975","pt":1717316837024,"mc":[{"id":"1.229554898","rc":[{"atb":[[140,0.19],[70,1.14],[95,0.55],[48,2.23]],"id":52671545}],"con":true,"img":false}]}
{"op":"mcm","clk":"11449991242","pt":1717316840344,"mc":[{"id":"1.229554898","rc":[{"atb":[[9.2,3.24],[10.5,0],[8.2,0],[13,0]],"id":52671549}],"con":true,"img":false}]}
{"op":"mcm","clk":"11449991287","pt":1717316841062,"mc":[{"id":"1.229554898","rc":[{"atb":[[11,5.23],[13.5,2.09],[8.4,14.14],[9.4,9.34]],"id":52671549}],"con":true,"img":false}]}
{"op":"mcm","clk":"11449993588","pt":1717316870054,"mc":[{"id":"1.229554898","rc":[{"atb":[[18,6.15],[13,0]],"id":52671550},{"atb":[[550,0],[650,0]],"id":52671546},{"atb":[[5.6,0],[7.2,0]],"id":52671549},{"atb":[[1.01,0],[1.04,0]],"id":52671548},{"atb":[[7.4,0],[9.4,0]],"id":52671542},{"atb":[[32,0],[21,0]],"id":52671545},{"atb":[[4.8,0],[5.8,0]],"id":52671544},{"atb":[[9,0],[12.5,0]],"id":52671555},{"atb":[[3.7,0],[4.4,0]],"id":52671554},{"atb":[[340,0],[440,0]],"id":52671556}],"con":true,"img":false}]}
{"op":"mcm","clk":"11449993649","pt":1717316870676,"mc":[{"id":"1.229554898","rc":[{"atl":[[650,2],[500,0]],"id":52671550},{"atl":[[710,0],[830,2]],"id":52671545},{"atl":[[16,6.67],[14.5,0]],"id":52671554}],"con":true,"img":false}]}
{"op":"mcm","clk":"11449993957","pt":1717316873971,"mc":[{"id":"1.229554898","rc":[{"atb":[[180,0],[190,4.61]],"id":52671546}],"con":true,"img":false}]}
{"op":"mcm","clk":"11449994599","pt":1717316881767,"mc":[{"id":"1.229554898","rc":[{"atb":[[1.12,0],[1.22,0],[1.07,0],[1.17,0]],"id":52671548},{"atb":[[16,0],[18.5,0],[22,0],[13.5,0]],"id":52671542},{"atb":[[9.6,0],[8.6,0],[11.5,0],[7.6,0]],"id":52671544}],"con":true,"img":false}]}
{"op":"mcm","clk":"11449994615","pt":1717316881973,"mc":[{"id":"1.229554898","rc":[{"atb":[[1.16,625],[1.19,0]],"id":52671548},{"atb":[[4.3,35.05],[4.4,0]],"id":52671544}],"con":true,"img":false}]}
{"op":"mcm","clk":"11449994684","pt":1717316882763,"mc":[{"id":"1.229554898","rc":[{"atb":[[1.2,130.79],[1.15,453.42],[1.1,784.77],[1.05,2092.71]],"id":52671548},{"atb":[[17,3.27],[19.5,1.41],[12,9.51],[14.5,5.81]],"id":52671542},{"atb":[[8,11.21],[9,6.54],[10,2.91],[7,17.44]],"id":52671544}],"con":true,"img":false}]}
{"op":"mcm","clk":"11449995414","pt":1717316890885,"mc":[{"id":"1.229554898","rc":[{"atb":[[1.16,0],[1.19,453.43]],"id":52671548}],"con":true,"img":false}]}
{"op":"mcm","clk":"11449995977","pt":1717316896880,"mc":[{"id":"1.229554898","rc":[{"atb":[[540,0],[180,2.94],[190,0],[390,0],[440,0],[490,0]],"id":52671546},{"atb":[[9.6,3.26],[9.8,0]],"id":52671549},{"atb":[[1.18,87.19],[1.15,348.79]],"id":52671548},{"atb":[[17,0],[19.5,0],[12,0],[14.5,0]],"id":52671542},{"atb":[[80,4.58],[85,0]],"id":52671545}],"con":true,"img":false}]}
{"op":"mcm","clk":"11449996040","pt":1717316897606,"mc":[{"id":"1.229554898","rc":[{"atb":[[520,0.05],[370,0.28],[420,0.19],[470,0.11]],"id":52671546},{"atb":[[16.5,3.37],[19,1.45],[11.5,9.97],[14,6.04]],"id":52671542}],"con":true,"img":false}]}
{"op":"mcm","clk":"11449996399","pt":1717316901889,"mc":[{"id":"1.229554898","rc":[{"atb":[[18,12.3],[13,20.32]],"id":52671550},{"atb":[[550,0.44],[650,0.16]],"id":52671546},{"atb":[[5.6,53.02],[7.2,16.86]],"id":52671549},{"atb":[[1.01,24390.49],[1.04,2613.26]],"id":52671548},{"atb":[[7.4,38.1],[9.4,12.44]],"id":52671542},{"atb":[[32,3.37],[21,12.19]],"id":52671545},{"atb":[[4.8,64.18],[5.8,21.77]],"id":52671544},{"atb":[[9,30.48],[12.5,9.08]],"id":52671555},{"atb":[[3.7,90.33],[4.4,30.74]],"id":52671554},{"atb":[[340,0.72],[440,0.24]],"id":52671556}],"con":true,"img":false}]}
{"op":"mcm","clk":"11449996820","pt":1717316906881,"mc":[{"id":"1.229554898","rc":[{"atb":[[1.16,98.09]],"id":52671548}],"con":true,"img":false}]}
{"op":"mcm","clk":"11449997227","pt":1717316912267,"mc":[{"id":"1.229554898","rc":[{"atb":[[1.13,0]],"id":52671548}],"con":true,"img":false}]}
{"op":"mcm","clk":"11449998015","pt":1717316922017,"mc":[{"id":"1.229554898","rc":[{"atb":[[11,0],[13.5,0],[8.4,0],[9.4,0]],"id":52671549}],"con":true,"img":false}]}
{"op":"mcm","clk":"11449998073","pt":1717316922738,"mc":[{"id":"1.229554898","rc":[{"atb":[[9.2,12.82],[10.5,5.51],[8.2,14.53],[13,2.18]],"id":52671549}],"con":true,"img":false}]}
{"op":"mcm","clk":"11449998234","pt":1717316924824,"mc":[{"id":"1.229554898","rc":[{"atb":[[9.6,0],[9.8,3.64]],"id":52671549},{"atb":[[1.18,0],[1.15,453.42]],"id":52671548},{"atb":[[80,0],[85,3.39]],"id":52671545}],"con":true,"img":false}]}
{"op":"mcm","clk":"11449998338","pt":1717316926222,"mc":[{"id":"1.229554898","rc":[{"atb":[[9.6,4.61],[9.8,0]],"id":52671549},{"atb":[[1.18,87.19],[1.16,0]],"id":52671548},{"atb":[[80,3.61],[85,0]],"id":52671545}],"con":true,"img":false}]}
{"op":"mcm","clk":"11449998400","pt":1717316927148,"mc":[{"id":"1.229554898","rc":[{"atb":[[9.6,0],[9.8,4.46]],"id":52671549},{"atb":[[1.18,0]],"id":52671548},{"atb":[[80,0],[85,3.5]],"id":52671545}],"con":true,"img":false}]}
{"op":"mcm","clk":"11449999123","pt":1717316936253,"mc":[{"id":"1.229554898","rc":[{"atb":[[1.13,120.73]],"id":52671548}],"con":true,"img":false}]}
{"op":"mcm","clk":"11450002909","pt":1717316979531,"mc":[{"id":"1.229554898","rc":[{"atb":[[520,0],[370,0],[420,0],[470,0]],"id":52671546},{"atb":[[16.5,0],[19,0],[11.5,0],[14,0]],"id":52671542}],"con":true,"img":false}]}
{"op":"mcm","clk":"11450002964","pt":1717316980206,"mc":[{"id":"1.229554898","rc":[{"atb":[[540,0.05],[390,0.27],[440,0.18],[490,0.1]],"id":52671546},{"atb":[[17,3.27],[19.5,1.41],[12,9.51],[14.5,5.81]],"id":52671542}],"con":true,"img":false}]}
{"op":"mcm","clk":"11450003944","pt":1717316992037,"mc":[{"id":"1.229554898","rc":[{"atb":[[18,6.15],[13,0]],"id":52671550},{"atb":[[550,0],[650,0]],"id":52671546},{"atb":[[5.6,0],[7.2,0]],"id":52671549},{"atb":[[1.01,0],[1.04,0]],"id":52671548},{"atb":[[7.4,0],[9.4,0]],"id":52671542},{"atb":[[32,0],[21,0]],"id":52671545},{"atb":[[4.8,0],[5.8,0]],"id":52671544},{"atb":[[9,0],[12.5,0]],"id":52671555},{"atb":[[3.7,0],[4.4,0]],"id":52671554},{"atb":[[340,0],[440,0]],"id":52671556}],"con":true,"img":false}]}
{"op":"mcm","clk":"11450004202","pt":1717316995011,"mc":[{"id":"1.229554898","rc":[{"atb":[[180,0],[190,2.94]],"id":52671546}],"con":true,"img":false}]}
{"op":"mcm","clk":"11450006471","pt":1717317018552,"mc":[{"id":"1.229554898","rc":[{"atl":[[150,6.27],[650,0]],"id":52671550},{"atl":[[1000,2]],"id":52671546},{"atb":[[4.4,29.41],[3.9,0]],"id":52671549},{"atl":[[38,2.7],[48,0]],"id":52671549},{"atb":[[1.21,453.43],[1.19,0]],"id":52671548},{"atl":[[110,2],[240,0]],"id":52671542},{"atb":[[8,14.29],[30,0]],"id":52671545},{"atl":[[830,0],[470,2]],"id":52671545},{"atb":[[4.3,4.75],[3.75,36.36]],"id":52671544},{"atl":[[40,2.56],[100,0]],"id":52671544},{"atl":[[50,2.04],[220,0]],"id":52671555},{"atb":[[2.8,55.56],[2.7,0]],"id":52671554},{"atl":[[16,0],[14.5,7.41]],"id":52671554},{"atb":[[8.4,13.51],[30,0]],"id":52671556},{"atl":[[800,2]],"id":52671556}],"con":true,"img":false}]}
{"op":"mcm","clk":"11450006495","pt":1717317018859,"mc":[{"id":"1.229554898","rc":[{"atb":[[32,0],[18,0],[21,0],[26,0]],"id":52671550},{"atl":[[130,0],[100,3.46]],"id":52671550},{"atb":[[540,0],[160,0],[190,0],[390,0],[440,0],[490,0]],"id":52671546},{"atb":[[9,2.99],[9.2,3.24],[10.5,0],[8.2,0],[9.8,0],[13,0]],"id":52671549},{"atl":[[44,4.57],[55,0]],"id":52671542},{"atb":[[140,0],[70,0],[75,0],[85,0],[95,0],[48,0]],"id":52671545},{"atl":[[21,2.97],[25,0]],"id":52671544},{"atl":[[46,3.75],[55,0]],"id":52671555},{"atb":[[5.1,0]],"id":52671554},{"atb":[[160,0],[80,0],[210,0],[110,0]],"id":52671556}],"con":true,"img":false}]}
{"op":"mcm","clk":"11450006502","pt":1717317018962,"mc":[{"id":"1.229554898","rc":[{"atb":[[150,0],[120,0]],"id":52671556}],"con":true,"img":false}]}
{"op":"mcm","clk":"11450006512","pt":1717317019066,"mc":[{"id":"1.229554898","rc":[{"atb":[[8.6,13.16],[30,0]],"id":52671546},{"atl":[[44,2.33],[50,0]],"id":52671555}],"con":true,"img":false}]}
{"op":"mcm","clk":"11450006574","pt":1717317019583,"mc":[{"id":"1.229554898","rc":[{"atb":[[17.5,6.34],[20,4.13],[25,2.18],[30,0.9]],"id":52671550},{"atb":[[160,0.16],[80,0.99],[110,0.48],[55,1.94]],"id":52671546},{"atb":[[9.6,6.08],[8.6,10.33],[11.5,2.49],[7.6,15.85]],"id":52671549},{"atb":[[40,1.34],[50,0.53],[25,4.36],[30,2.71]],"id":52671545},{"atb":[[32,2.53],[42,1.28],[26,4.19],[55,0.49]],"id":52671556}],"con":true,"img":false}]}
{"op":"mcm","clk":"11450006585","pt":1717317019686,"mc":[{"id":"1.229554898","rc":[{"atb":[[8.6,0],[36,2.86]],"id":52671546}],"con":true,"img":false}]}
{"op":"mcm","clk":"11450006707","pt":1717317020878,"mc":[{"id":"1.229554898","rc":[{"atb":[[90,3.84],[100,3.03]],"id":52671546},{"atb":[[32,5.76],[29,4.37]],"id":52671556}],"con":true,"img":false}]}
{"op":"mcm","clk":"11450006716","pt":1717317020976,"mc":[{"id":"1.229554898","rc":[{"atb":[[9.2,0]],"id":52671549},{"atb":[[28,3.45],[30,6.07]],"id":52671545}],"con":true,"img":false}]}
{"op":"mcm","clk":"11450007021","pt":1717317023981,"mc":[{"id":"1.229554898","rc":[{"atb":[[17.5,0],[20,0],[25,0],[30,0]],"id":52671550}],"con":true,"img":false}]}
{"op":"mcm","clk":"11450007091","pt":1717317024655,"mc":[{"id":"1.229554898","rc":[{"atb":[[17,6.54],[19.5,4.24],[24,2.28],[29,0.94]],"id":52671550}],"con":true,"img":false}]}
{"op":"mcm","clk":"11450007244","pt":1717317026202,"mc":[{"id":"1.229554898","rc":[{"atl":[[130,2],[150,4.27]],"id":52671550},{"atl":[[90,2],[110,0]],"id":52671542},{"atb":[[8,0],[10,11.11]],"id":52671545},{"atb":[[4.3,35.05],[3.75,0]],"id":52671544},{"atb":[[2.8,0],[3.1,47.62]],"id":52671554},{"atl":[[13,11.13],[14.5,0]],"id":52671554},{"atb":[[10,11.11],[8.4,0]],"id":52671556}],"con":true,"img":false}]}
{"op":"mcm","clk":"11450007437","pt":1717317028280,"mc":[{"id":"1.229554898","rc":[{"atb":[[4.7,4.57]],"id":52671554}],"con":true,"img":false}]}
{"op":"mcm","clk":"11450007500","pt":1717317028895,"mc":[{"id":"1.229554898","rc":[{"atl":[[120,4.61]],"id":52671550},{"atb":[[8.6,13.48]],"id":52671549},{"atl":[[48,3.77]],"id":52671542},{"atl":[[23,2.81]],"id":52671544},{"atl":[[50,4.25]],"id":52671555}],"con":true,"img":false}]}
{"op":"mcm","clk":"11450007767","pt":1717317031597,"mc":[{"id":"1.229554898","rc":[{"atb":[[18,6.14],[13,20.32]],"id":52671550},{"atb":[[550,0.44],[650,0.16]],"id":52671546},{"atb":[[5.6,53.02],[7.2,16.86]],"id":52671549},{"atb":[[1.01,24390.49],[1.04,2613.26]],"id":52671548},{"atb":[[7.4,38.1],[9.4,12.44]],"id":52671542},{"atb":[[32,3.37],[21,12.19]],"id":52671545},{"atb":[[4.8,64.18],[5.8,21.77]],"id":52671544},{"atb":[[9,30.48],[12.5,9.08]],"id":52671555},{"atb":[[3.7,90.33],[4.4,30.74]],"id":52671554},{"atb":[[340,0.72],[440,0.24]],"id":52671556}],"con":true,"img":false}]}
{"op":"mcm","clk":"11450007777","pt":1717317031700,"mc":[{"id":"1.229554898","rc":[{"atl":[[150,0]],"id":52671550},{"atl":[[70,0]],"id":52671542},{"atl":[[27,0]],"id":52671544},{"atl":[[70,0]],"id":52671555}],"con":true,"img":false}]}
{"op":"mcm","clk":"11450012279","pt":1717317077033,"mc":[{"id":"1.229554898","rc":[{"atb":[[17,0],[19.5,0],[12,0],[14.5,0]],"id":52671542},{"atb":[[8,0],[9,0],[10,0],[7,0]],"id":52671544}],"con":true,"img":false}]}
{"op":"mcm","clk":"11450012344","pt":1717317077549,"mc":[{"id":"1.229554898","rc":[{"atb":[[1.68,5.01]],"id":52671548},{"atl":[[2.64,5.01]],"id":52671548},{"atb":[[9.6,3.01],[15,5.01]],"id":52671542},{"atl":[[27,5.01]],"id":52671542},{"atb":[[5.8,25.63],[8.2,5.01]],"id":52671544},{"atl":[[14.5,5.01]],"id":52671544}],"con":true,"img":false}]}
{"op":"mcm","clk":"11450012353","pt":1717317077601,"mc":[{"id":"1.229554898","rc":[{"atb":[[1.21,0],[1.33,303.03]],"id":52671548}],"con":true,"img":false}]}
{"op":"mcm","clk":"11450012370","pt":1717317077709,"mc":[{"id":"1.229554898","rc":[{"atl":[[130,0],[100,5.46]],"id":52671550},{"atl":[[38,0],[30,3.45]],"id":52671549},{"atb":[[18,3.08],[21,1.31],[13,8.72],[15.5,5.41]],"id":52671542},{"atb":[[11,2.62],[7.4,16.35],[8.4,10.61],[9.4,6.23]],"id":52671544},{"atl":[[40,0],[28,3.7]],"id":52671544},{"atl":[[11.5,3.3],[13,4.53]],"id":52671554}],"con":true,"img":false}]}
{"op":"mcm","clk":"11450012390","pt":1717317077919,"mc":[{"id":"1.229554898","rc":[{"atb":[[18.5,5.01]],"id":52671550},{"atl":[[50,5.01]],"id":52671550},{"atb":[[110,5.5]],"id":52671546},{"atb":[[9,8.01]],"id":52671549},{"atl":[[17,5.01]],"id":52671549},{"atb":[[32,8.39]],"id":52671545},{"atl":[[170,5.01]],"id":52671545},{"atb":[[5.1,5.01]],"id":52671554},{"atl":[[8.2,5.01]],"id":52671554}],"con":true,"img":false}]}
{"op":"mcm","clk":"11450012400","pt":1717317078021,"mc":[{"id":"1.229554898","rc":[{"atl":[[200,2],[470,0]],"id":52671545},{"atb":[[10,5.01]],"id":52671555},{"atl":[[22,5.01]],"id":52671555}],"con":true,"img":false}]}
{"op":"mcm","clk":"11450012418","pt":1717317078228,"mc":[{"id":"1.229554898","rc":[{"atl":[[34,3.03],[44,0]],"id":52671555}],"con":true,"img":false}]}
{"op":"mcm","clk":"11450012779","pt":1717317081837,"mc":[{"id":"1.229554898","rc":[{"atl":[[90,0],[60,2]],"id":52671542}],"con":true,"img":false}]}
{"op":"mcm","clk":"11450013042","pt":1717317084518,"mc":[{"id":"1.229554898","rc":[{"atl":[[50,8.29]],"id":52671550},{"atl":[[990,0.16]],"id":52671546},{"atl":[[17,15.05]],"id":52671549},{"atb":[[1.68,20.13]],"id":52671548},{"atl":[[2.64,20.13]],"id":52671548},{"atl":[[170,5.96]],"id":52671545},{"atl":[[14.5,16.91]],"id":52671544},{"atl":[[22,12.66]],"id":52671555},{"atb":[[5.1,16.92]],"id":52671554},{"atl":[[8.2,16.92]],"id":52671554},{"atl":[[790,0.2]],"id":52671556}],"con":true,"img":false}]}
{"op":"mcm","clk":"11450013068","pt":1717317084724,"mc":[{"id":"1.229554898","rc":[{"atl":[[80,2],[100,3.46]],"id":52671550},{"atl":[[25,7.57],[30,0]],"id":52671549},{"atl":[[24,4.35],[28,0]],"id":52671544},{"atl":[[11.5,0],[9.4,11.9]],"id":52671554}],"con":true,"img":false}]}
{"op":"mcm","clk":"11450013088","pt":1717317084927,"mc":[{"id":"1.229554898","rc":[{"atl":[[180,2]],"id":52671545}],"con":true,"img":false}]}
{"op":"mcm","clk":"11450013098","pt":1717317085032,"mc":[{"id":"1.229554898","rc":[{"atl":[[200,0]],"id":52671545}],"con":true,"img":false}]}
{"op":"mcm","clk":"11450013107","pt":1717317085137,"mc":[{"id":"1.229554898","rc":[{"atl":[[34,0],[28,3.7]],"id":52671555}],"con":true,"img":false}]}
{"op":"mcm","clk":"11450013612","pt":1717317090646,"mc":[{"id":"1.229554898","rc":[{"atl":[[17,10.03],[17.5,5.01]],"id":52671549}],"con":true,"img":false}]}
{"op":"mcm","clk":"11450013619","pt":1717317090749,"mc":[{"id":"1.229554898","rc":[{"atl":[[17,0]],"id":52671549}],"con":true,"img":false}]}
{"op":"mcm","clk":"11450013688","pt":1717317091420,"mc":[{"id":"1.229554898","rc":[{"atl":[[24,6.98]],"id":52671549}],"con":true,"img":false}]}
{"op":"mcm","clk":"11450014250","pt":1717317097653,"mc":[{"id":"1.229554898","rc":[{"atb":[[1.2,0],[1.18,87.19],[1.15,104.63],[1.1,0],[1.05,0]],"id":52671548}],"con":true,"img":false}]}
{"op":"mcm","clk":"11450014265","pt":1717317097756,"mc":[{"id":"1.229554898","rc":[{"atb":[[1.15,0]],"id":52671548}],"con":true,"img":false}]}
{"op":"mcm","clk":"11450014329","pt":1717317098374,"mc":[{"id":"1.229554898","rc":[{"atb":[[1.19,137.68],[1.14,373.7],[1.09,871.96],[1.04,5229.15]],"id":52671548}],"con":true,"img":false}]}
{"op":"mcm","clk":"11450014373","pt":1717317098842,"mc":[{"id":"1.229554898","rc":[{"atb":[[4.5,10.04],[2.88,0]],"id":52671550},{"atb":[[36,0],[11.5,9.52]],"id":52671546},{"atb":[[5.1,24.39],[4.4,0]],"id":52671549},{"atl":[[22,4.76],[25,3.4]],"id":52671549},{"atl":[[7.6,15.15],[5.4,3.9]],"id":52671548},{"atb":[[4.5,18.18],[2.88,0]],"id":52671555},{"atb":[[3.1,0],[3.4,41.67]],"id":52671554},{"atl":[[8.6,13.16],[9.4,0]],"id":52671554}],"con":true,"img":false}]}
{"op":"mcm","clk":"11450014389","pt":1717317099052,"mc":[{"id":"1.229554898","rc":[{"atl":[[80,0],[60,2]],"id":52671550},{"atl":[[22,0]],"id":52671549},{"atb":[[4.4,0],[6,10.43]],"id":52671542},{"atl":[[180,0],[250,2]],"id":52671545},{"atb":[[4.8,90.5],[4.3,4.75]],"id":52671544},{"atl":[[27,3.85],[28,0]],"id":52671555},{"atl":[[8.6,0]],"id":52671554}],"con":true,"img":false}]}
{"op":"mcm","clk":"11450014394","pt":1717317099149,"mc":[{"id":"1.229554898","rc":[{"atb":[[90,0],[100,0]],"id":52671546},{"atl":[[30,3.45]],"id":52671549},{"atl":[[5.6,0],[7.6,19.03],[5.4,0]],"id":52671548},{"atb":[[28,0],[30,2.71]],"id":52671545},{"atb":[[4.5,0],[6.2,3.15]],"id":52671544},{"atb":[[4.6,2.96],[4.9,0]],"id":52671554},{"atl":[[10,11.11]],"id":52671554},{"atb":[[32,2.53],[29,0]],"id":52671556}],"con":true,"img":false}]}
{"op":"mcm","clk":"11450014403","pt":1717317099255,"mc":[{"id":"1.229554898","rc":[{"atl":[[32,3.23]],"id":52671544}],"con":true,"img":false}]}
{"op":"mcm","clk":"11450014413","pt":1717317099363,"mc":[{"id":"1.229554898","rc":[{"atb":[[17,0],[18.5,0],[19.5,0],[24,0],[29,0]],"id":52671550},{"atb":[[160,0],[80,0],[110,5.01],[55,0]],"id":52671546},{"atb":[[9,5.01],[11.5,17.78],[9.4,4.44]],"id":52671549},{"atl":[[34,5.01],[27,0]],"id":52671542},{"atb":[[40,0],[50,3.27],[25,0],[30,0]],"id":52671545},{"atl":[[16.5,5.01],[24,0],[14.5,0]],"id":52671544},{"atb":[[10,0],[7.8,5.01]],"id":52671555},{"atb":[[32,0],[42,0],[26,0],[55,0]],"id":52671556}],"con":true,"img":false}]}
{"op":"mcm","clk":"11450014422","pt":1717317099461,"mc":[{"id":"1.229554898","rc":[{"atl":[[80,2],[60,0]],"id":52671542}],"con":true,"img":false}]}
{"op":"mcm","clk":"11450014440","pt":1717317099668,"mc":[{"id":"1.229554898","rc":[{"atb":[[110,0]],"id":52671546},{"atb":[[9.2,3.98]],"id":52671549},{"atb":[[1.18,0],[1.15,104.63]],"id":52671548},{"atb":[[21,9.34]],"id":52671542},{"atl":[[27,0.6]],"id":52671542},{"atb":[[5.1,0],[4.7,9.58]],"id":52671554}],"con":true,"img":false}]}
{"op":"mcm","clk":"11450014445","pt":1717317099770,"mc":[{"id":"1.229554898","rc":[{"atb":[[16,5.01],[18,9.16]],"id":52671550},{"atb":[[85,5.01]],"id":52671546},{"atl":[[17.5,14.74]],"id":52671549},{"atb":[[28,5.01]],"id":52671556}],"con":true,"img":false}]}
{"op":"mcm","clk":"11450014473","pt":1717317100083,"mc":[{"id":"1.229554898","rc":[{"atb":[[17.5,4.76],[20,2.75],[25,1.09],[15,7.48]],"id":52671550},{"atl":[[34,0],[36,5.01]],"id":52671542},{"atb":[[50,0]],"id":52671545},{"atl":[[20,8.44]],"id":52671544},{"atb":[[7.8,0],[8.4,5.01]],"id":52671555},{"atb":[[32,1.69],[42,0.64],[21,5.23],[26,3.14]],"id":52671556}],"con":true,"img":false}]}
{"op":"mcm","clk":"11450014481","pt":1717317100138,"mc":[{"id":"1.229554898","rc":[{"atb":[[10,3.77],[85,5.64],[44,2.43],[11,4.67],[120,0.22],[60,1.33]],"id":52671546},{"atb":[[11.5,2.49],[9.4,0]],"id":52671549},{"atb":[[34,2.38],[44,1.22],[27,4.02],[60,0.44]],"id":52671545},{"atb":[[4.7,5.01]],"id":52671554}],"con":true,"img":false}]}
{"op":"mcm","clk":"11450014501","pt":1717317100345,"mc":[{"id":"1.229554898","rc":[{"atb":[[9.6,0]],"id":52671542}],"con":true,"img":false}]}
{"op":"mcm","clk":"11450014510","pt":1717317100443,"mc":[{"id":"1.229554898","rc":[{"atl":[[24,0]],"id":52671549},{"atb":[[4.6,22.36]],"id":52671554}],"con":true,"img":false}]}
{"op":"mcm","clk":"11450014536","pt":1717317100859,"mc":[{"id":"1.229554898","rc":[{"atb":[[9.6,20.39]],"id":52671549}],"con":true,"img":false}]}
{"op":"mcm","clk":"11450014625","pt":1717317101972,"mc":[{"id":"1.229554898","rc":[{"atb":[[1.18,87.19],[1.15,0]],"id":52671548}],"con":true,"img":false}]}
{"op":"mcm","clk":"11450014829","pt":1717317104179,"mc":[{"id":"1.229554898","rc":[{"atl":[[70,2]],"id":52671550}],"con":true,"img":false}]}
{"op":"mcm","clk":"11450014839","pt":1717317104285,"mc":[{"id":"1.229554898","rc":[{"atl":[[60,0]],"id":52671550},{"atb":[[1.18,0],[1.15,104.63]],"id":52671548}],"con":true,"img":false}]}
{"op":"mcm","clk":"11450014962","pt":1717317105538,"mc":[{"id":"1.229554898","rc":[{"atl":[[23,4.55],[30,0]],"id":52671549}],"con":true,"img":false}]}
{"op":"mcm","clk":"11450014979","pt":1717317105740,"mc":[{"id":"1.229554898","rc":[{"atl":[[210,2],[250,0]],"id":52671545}],"con":true,"img":false}]}
{"op":"mcm","clk":"11450014989","pt":1717317105843,"mc":[{"id":"1.229554898","rc":[{"atl":[[8,11.11],[10,0]],"id":52671554}],"con":true,"img":false}]}
{"op":"mcm","clk":"11450015288","pt":1717317109453,"mc":[{"id":"1.229554898","rc":[{"atb":[[5.9,4.56]],"id":52671544},{"atl":[[20,11.14]],"id":52671544},{"atb":[[4.4,33.53]],"id":52671554}],"con":true,"img":false}]}
{"op":"mcm","clk":"11450015295","pt":1717317109558,"mc":[{"id":"1.229554898","rc":[{"atl":[[21,0]],"id":52671544}],"con":true,"img":false}]}
{"op":"mcm","clk":"11450015541","pt":1717317112293,"mc":[{"id":"1.229554898","rc":[{"atl":[[470,3.17],[480,0]],"id":52671545},{"atl":[[44,3.09]],"id":52671555}],"con":true,"img":false}]}
{"op":"mcm","clk":"11450015548","pt":1717317112348,"mc":[{"id":"1.229554898","rc":[{"atl":[[46,0]],"id":52671555}],"con":true,"img":false}]}
{"op":"mcm","clk":"11450015735","pt":1717317114461,"mc":[{"id":"1.229554898","rc":[{"atl":[[8,3.09]],"id":52671548}],"con":true,"img":false}]}
{"op":"mcm","clk":"11450015778","pt":1717317114977,"mc":[{"id":"1.229554898","rc":[{"atl":[[16.5,15.37]],"id":52671544}],"con":true,"img":false}]}
{"op":"mcm","clk":"11450015810","pt":1717317115386,"mc":[{"id":"1.229554898","rc":[{"atb":[[4.7,40.08]],"id":52671554}],"con":true,"img":false}]}
{"op":"mcm","clk":"11450015841","pt":1717317115696,"mc":[{"id":"1.229554898","rc":[{"atl":[[20,2.69]],"id":52671544}],"con":true,"img":false}]}
{"op":"mcm","clk":"11450015888","pt":1717317116161,"mc":[{"id":"1.229554898","rc":[{"atb":[[4.6,2.96]],"id":52671554}],"con":true,"img":false}]}
{"op":"mcm","clk":"11450016259","pt":1717317119662,"mc":[{"id":"1.229554898","rc":[{"atb":[[4.3,0]],"id":52671544}],"con":true,"img":false}]}
{"op":"mcm","clk":"11450016574","pt":1717317122832,"mc":[{"id":"1.229554898","rc":[{"atb":[[18,3.01],[13,0]],"id":52671550},{"atb":[[550,0],[650,0]],"id":52671546},{"atb":[[5.6,0],[7.2,0]],"id":52671549},{"atb":[[1.01,0],[1.04,2615.88]],"id":52671548},{"atb":[[7.4,0],[9.4,0]],"id":52671542},{"atb":[[32,5.01],[21,0]],"id":52671545},{"atb":[[4.8,26.32],[5.8,3.85]],"id":52671544},{"atb":[[9,0],[12.5,0]],"id":52671555},{"atb":[[3.7,0],[4.4,2.79]],"id":52671554},{"atb":[[340,0],[440,0]],"id":52671556}],"con":true,"img":false}]}
{"op":"mcm","clk":"11450016590","pt":1717317123035,"mc":[{"id":"1.229554898","rc":[{"atl":[[790,2.2],[800,0]],"id":52671556}],"con":true,"img":false}]}
{"op":"mcm","clk":"11450016621","pt":1717317123296,"mc":[{"id":"1.229554898","rc":[{"atb":[[8.4,24.09]],"id":52671555}],"con":true,"img":false}]}
{"op":"mcm","clk":"11450016941","pt":1717317126210,"mc":[{"id":"1.229554898","rc":[{"atl":[[70,0],[85,2]],"id":52671550},{"atl":[[23,0],[28,3.7]],"id":52671549},{"atl":[[260,2],[210,0]],"id":52671545},{"atl":[[8,0],[8.8,12.82]],"id":52671554}],"con":true,"img":false}]}
{"op":"mcm","clk":"11450017122","pt":1717317128029,"mc":[{"id":"1.229554898","rc":[{"atb":[[4.5,0],[6.2,4.66]],"id":52671542},{"atb":[[10,15.57],[11,4.25]],"id":52671545},{"atb":[[4.6,3.23],[3.05,0]],"id":52671555},{"atb":[[10,15.18],[11,2.62]],"id":52671556}],"con":true,"img":false}]}
{"op":"mcm","clk":"11450017182","pt":1717317128658,"mc":[{"id":"1.229554898","rc":[{"atb":[[9,0],[9.2,8.99]],"id":52671549},{"atb":[[20,5.01],[15,0]],"id":52671542},{"atb":[[32,0],[38,5.01]],"id":52671545},{"atb":[[9.6,5.01],[8.2,0]],"id":52671544}],"con":true,"img":false}]}
{"op":"mcm","clk":"11450018104","pt":1717317137942,"mc":[{"id":"1.229554898","rc":[{"atb":[[4.4,3.2]],"id":52671555}],"con":true,"img":false}]}
{"op":"mcm","clk":"11450018258","pt":1717317139445,"mc":[{"id":"1.229554898","rc":[{"atb":[[1.67,5.01],[1.68,0]],"id":52671548},{"atb":[[2.98,0]],"id":52671555},{"atl":[[8.2,0],[8.4,5.01]],"id":52671554}],"con":true,"img":false}]}
{"op":"mcm","clk":"11450018332","pt":1717317140136,"mc":[{"id":"1.229554898","rc":[{"atl":[[8.6,12.01]],"id":52671554}],"con":true,"img":false}]}
{"op":"mcm","clk":"11450018348","pt":1717317140227,"mc":[{"id":"1.229554898","rc":[{"atb":[[1.33,339.23]],"id":52671548}],"con":true,"img":false}]}
{"op":"mcm","clk":"11450018505","pt":1717317141727,"mc":[{"id":"1.229554898","rc":[{"atb":[[18,0],[21,8.03],[13,0],[15.5,0]],"id":52671542}],"con":true,"img":false}]}
{"op":"mcm","clk":"11450018577","pt":1717317142448,"mc":[{"id":"1.229554898","rc":[{"atb":[[16,5.23],[18.5,2.99],[22,1.25]],"id":52671542}],"con":true,"img":false}]}
{"op":"mcm","clk":"11450018591","pt":1717317142550,"mc":[{"id":"1.229554898","rc":[{"atb":[[13.5,8.37]],"id":52671542}],"con":true,"img":false}]}
{"op":"mcm","clk":"11450018627","pt":1717317142915,"mc":[{"id":"1.229554898","rc":[{"atl":[[27,0]],"id":52671542}],"con":true,"img":false}]}
{"op":"mcm","clk":"11450019065","pt":1717317147832,"mc":[{"id":"1.229554898","rc":[{"atb":[[1.67,0],[1.68,5.01]],"id":52671548},{"atl":[[21,5.01],[22,7.64]],"id":52671555}],"con":true,"img":false}]}
{"op":"mcm","clk":"11450019076","pt":1717317147944,"mc":[{"id":"1.229554898","rc":[{"atl":[[8.2,5.01],[8.4,0]],"id":52671554}],"con":true,"img":false}]}
{"op":"mcm","clk":"11450019104","pt":1717317148243,"mc":[{"id":"1.229554898","rc":[{"atl":[[21,13.04]],"id":52671555}],"con":true,"img":false}]}
{"op":"mcm","clk":"11450019181","pt":1717317149016,"mc":[{"id":"1.229554898","rc":[{"atl":[[22,0]],"id":52671555}],"con":true,"img":false}]}
{"op":"mcm","clk":"11450019650","pt":1717317153865,"mc":[{"id":"1.229554898","rc":[{"atb":[[1.18,87.19],[1.15,0]],"id":52671548},{"atb":[[11,0],[7.4,0],[8.4,0],[9.4,0]],"id":52671544}],"con":true,"img":false}]}
{"op":"mcm","clk":"11450019694","pt":1717317154230,"mc":[{"id":"1.229554898","rc":[{"atb":[[9.6,13.31]],"id":52671544},{"atl":[[8.2,17.02]],"id":52671554}],"con":true,"img":false}]}
{"op":"mcm","clk":"11450019702","pt":1717317154332,"mc":[{"id":"1.229554898","rc":[{"atb":[[1.68,63.96]],"id":52671548}],"con":true,"img":false}]}
{"op":"mcm","clk":"11450019722","pt":1717317154538,"mc":[{"id":"1.229554898","rc":[{"atb":[[11,2.62],[7.4,16.35],[8.4,10.61],[9.4,6.23]],"id":52671544}],"con":true,"img":false}]}
{"op":"mcm","clk":"11450019772","pt":1717317155055,"mc":[{"id":"1.229554898","rc":[{"atb":[[5.8,0]],"id":52671544},{"atl":[[8.6,0]],"id":52671554}],"con":true,"img":false}]}
{"op":"mcm","clk":"11450019785","pt":1717317155157,"mc":[{"id":"1.229554898","rc":[{"atb":[[1.33,303.03]],"id":52671548}],"con":true,"img":false}]}
{"op":"mcm","clk":"11450019810","pt":1717317155364,"mc":[{"id":"1.229554898","rc":[{"atb":[[11,0],[7.4,0],[8.4,0],[9.4,0]],"id":52671544}],"con":true,"img":false}]}
{"op":"mcm","clk":"11450019833","pt":1717317155522,"mc":[{"id":"1.229554898","rc":[{"atl":[[9.2,12.2],[8.8,0]],"id":52671554}],"con":true,"img":false}]}
{"op":"mcm","clk":"11450019857","pt":1717317155833,"mc":[{"id":"1.229554898","rc":[{"atb":[[1.18,0],[1.15,104.63]],"id":52671548}],"con":true,"img":false}]}
{"op":"mcm","clk":"11450019881","pt":1717317156042,"mc":[{"id":"1.229554898","rc":[{"atb":[[11,2.62],[7.4,16.35],[8.4,10.61],[9.4,6.23]],"id":52671544}],"con":true,"img":false}]}
{"op":"mcm","clk":"11450020035","pt":1717317157587,"mc":[{"id":"1.229554898","rc":[{"atb":[[18,9.16],[13,20.32]],"id":52671550},{"atb":[[550,0.44],[650,0.16]],"id":52671546},{"atb":[[5.6,53.02],[7.2,16.86]],"id":52671549},{"atb":[[1.01,24390.49],[1.04,5229.15]],"id":52671548},{"atb":[[7.4,38.1],[9.4,12.44]],"id":52671542},{"atb":[[32,3.37],[21,12.19]],"id":52671545},{"atb":[[4.8,90.5],[5.8,21.77]],"id":52671544},{"atb":[[9,30.48],[12.5,9.08]],"id":52671555},{"atb":[[3.7,90.33],[4.4,33.53]],"id":52671554},{"atb":[[340,0.72],[440,0.24]],"id":52671556}],"con":true,"img":false}]}
{"op":"mcm","clk":"11450020067","pt":1717317157849,"mc":[{"id":"1.229554898","rc":[{"atl":[[70,2],[85,0]],"id":52671550},{"atl":[[23,4.55],[28,0]],"id":52671549},{"atl":[[260,0],[210,2]],"id":52671545}],"con":true,"img":false}]}
{"op":"mcm","clk":"11450020103","pt":1717317158158,"mc":[{"id":"1.229554898","rc":[{"atl":[[8.2,5.01]],"id":52671554}],"con":true,"img":false}]}
{"op":"mcm","clk":"11450020113","pt":1717317158260,"mc":[{"id":"1.229554898","rc":[{"atl":[[17.5,0],[18,5.01]],"id":52671549},{"atb":[[1.18,87.19],[1.15,0]],"id":52671548},{"atl":[[8.2,0],[8.4,5.01]],"id":52671554}],"con":true,"img":false}]}
{"op":"mcm","clk":"11450020179","pt":1717317158828,"mc":[{"id":"1.229554898","rc":[{"atl":[[9,20.07]],"id":52671554}],"con":true,"img":false}]}
{"op":"mcm","clk":"11450020192","pt":1717317158982,"mc":[{"id":"1.229554898","rc":[{"atl":[[22,7.64]],"id":52671549}],"con":true,"img":false}]}
{"op":"mcm","clk":"11450020246","pt":1717317159552,"mc":[{"id":"1.229554898","rc":[{"atb":[[9.2,5.01],[9.4,2.91]],"id":52671549},{"atb":[[1.18,0],[1.15,104.63]],"id":52671548}],"con":true,"img":false}]}
{"op":"mcm","clk":"11450020453","pt":1717317161775,"mc":[{"id":"1.229554898","rc":[{"atl":[[9.2,0],[8.2,12.2]],"id":52671554}],"con":true,"img":false}]}
{"op":"mcm","clk":"11450021200","pt":1717317168864,"mc":[{"id":"1.229554898","rc":[{"atb":[[9,4.1]],"id":52671549}],"con":true,"img":false}]}
{"op":"mcm","clk":"11450021297","pt":1717317169845,"mc":[{"id":"1.229554898","rc":[{"atb":[[9.2,8.18],[9.4,0]],"id":52671549}],"con":true,"img":false}]}
{"op":"mcm","clk":"11450021537","pt":1717317172701,"mc":[{"id":"1.229554898","rc":[{"atl":[[18,14.46]],"id":52671549}],"con":true,"img":false}]}
{"op":"mcm","clk":"11450021606","pt":1717317173372,"mc":[{"id":"1.229554898","rc":[{"atl":[[22,0]],"id":52671549}],"con":true,"img":false}]}
{"op":"mcm","clk":"11450022145","pt":1717317178995,"mc":[{"id":"1.229554898","rc":[{"atb":[[8.8,4.33]],"id":52671549}],"con":true,"img":false}]}
{"op":"mcm","clk":"11450022156","pt":1717317179104,"mc":[{"id":"1.229554898","rc":[{"atb":[[8.6,10.33]],"id":52671549}],"con":true,"img":false}]}
{"op":"mcm","clk":"11450022883","pt":1717317186204,"mc":[{"id":"1.229554898","rc":[{"atb":[[8.8,0]],"id":52671549},{"atb":[[1.15,0],[1.19,82.6],[1.14,0],[1.09,0],[1.04,2613.26]],"id":52671548}],"con":true,"img":false}]}
{"op":"mcm","clk":"11450022892","pt":1717317186307,"mc":[{"id":"1.229554898","rc":[{"atb":[[9,0],[8.6,12.97],[9.2,5.01]],"id":52671549}],"con":true,"img":false}]}
{"op":"mcm","clk":"11450022951","pt":1717317186879,"mc":[{"id":"1.229554898","rc":[{"atb":[[1.19,357.96],[1.14,560.55],[1.09,1162.61],[1.24,108.99]],"id":52671548}],"con":true,"img":false}]}
{"op":"mcm","clk":"11450023073","pt":1717317188173,"mc":[{"id":"1.229554898","rc":[{"atb":[[8.8,3.73]],"id":52671549},{"atb":[[1.15,104.63],[1.19,275.36]],"id":52671548},{"atb":[[16,0],[18.5,0],[22,0],[13.5,0]],"id":52671542}],"con":true,"img":false}]}
{"op":"mcm","clk":"11450023153","pt":1717317188899,"mc":[{"id":"1.229554898","rc":[{"atb":[[17,4.9],[19.5,2.83],[24,1.14],[14.5,7.75]],"id":52671542}],"con":true,"img":false}]}
{"op":"mcm","clk":"11450023337","pt":1717317190787,"mc":[{"id":"1.229554898","rc":[{"atb":[[8.8,0]],"id":52671549},{"atb":[[1.15,0],[1.19,357.96]],"id":52671548},{"atl":[[470,0],[480,2.73]],"id":52671545},{"atl":[[20,0],[21,4.09]],"id":52671544},{"atl":[[44,0],[46,4.33]],"id":52671555}],"con":true,"img":false}]}
{"op":"mcm","clk":"11450023651","pt":1717317193692,"mc":[{"id":"1.229554898","rc":[{"atb":[[8.8,3.42]],"id":52671549},{"atb":[[1.15,104.63],[1.19,275.36]],"id":52671548},{"atl":[[470,3.65],[480,0]],"id":52671545},{"atl":[[20,4.35],[21,0]],"id":52671544},{"atl":[[44,4.48],[46,0]],"id":52671555}],"con":true,"img":false}]}
{"op":"mcm","clk":"11450023877","pt":1717317196012,"mc":[{"id":"1.229554898","rc":[{"atb":[[8.8,0]],"id":52671549},{"atb":[[1.15,0],[1.19,357.96]],"id":52671548},{"atb":[[17,0],[19.5,0],[24,0],[14.5,0]],"id":52671542},{"atl":[[470,0],[480,3.87]],"id":52671545},{"atl":[[20,0],[21,4.48]],"id":52671544},{"atl":[[44,0],[46,3.43]],"id":52671555}],"con":true,"img":false}]}
{"op":"mcm","clk":"11450023953","pt":1717317196690,"mc":[{"id":"1.229554898","rc":[{"atb":[[18,3.08],[21,9.34],[13,8.72],[15.5,5.41]],"id":52671542}],"con":true,"img":false}]}
{"op":"mcm","clk":"11450023991","pt":1717317197102,"mc":[{"id":"1.229554898","rc":[{"atl":[[36,9.6]],"id":52671542}],"con":true,"img":false}]}
{"op":"mcm","clk":"11450024176","pt":1717317199014,"mc":[{"id":"1.229554898","rc":[{"atb":[[9.2,8.95]],"id":52671549},{"atb":[[1.18,87.19],[1.19,275.36]],"id":52671548},{"atl":[[470,2.69],[480,0]],"id":52671545},{"atl":[[20,2.96],[21,0]],"id":52671544},{"atl":[[44,3.51],[46,0]],"id":52671555}],"con":true,"img":false}]}
{"op":"mcm","clk":"11450024205","pt":1717317199221,"mc":[{"id":"1.229554898","rc":[{"atb":[[1.15,104.63]],"id":52671548}],"con":true,"img":false}]}
{"op":"mcm","clk":"11450024380","pt":1717317201288,"mc":[{"id":"1.229554898","rc":[{"atb":[[1.13,0]],"id":52671548}],"con":true,"img":false}]}
{"op":"mcm","clk":"11450024389","pt":1717317201394,"mc":[{"id":"1.229554898","rc":[{"atb":[[9.2,5.01]],"id":52671549},{"atb":[[1.18,0],[1.19,357.96]],"id":52671548}],"con":true,"img":false}]}
{"op":"mcm","clk":"11450024401","pt":1717317201500,"mc":[{"id":"1.229554898","rc":[{"atl":[[32,3.23],[27,0]],"id":52671555}],"con":true,"img":false}]}
{"op":"mcm","clk":"11450024416","pt":1717317201607,"mc":[{"id":"1.229554898","rc":[{"atl":[[1000,0]],"id":52671546}],"con":true,"img":false}]}
{"op":"mcm","clk":"11450024424","pt":1717317201709,"mc":[{"id":"1.229554898","rc":[{"atl":[[260,2],[210,0]],"id":52671545},{"atl":[[32,0],[29,3.57]],"id":52671555}],"con":true,"img":false}]}
{"op":"mcm","clk":"11450024447","pt":1717317201913,"mc":[{"id":"1.229554898","rc":[{"atl":[[1000,2]],"id":52671546}],"con":true,"img":false}]}
{"op":"mcm","clk":"11450024456","pt":1717317202014,"mc":[{"id":"1.229554898","rc":[{"atl":[[1000,0]],"id":52671546}],"con":true,"img":false}]}
{"op":"mcm","clk":"11450024466","pt":1717317202117,"mc":[{"id":"1.229554898","rc":[{"atl":[[1000,2]],"id":52671546}],"con":true,"img":false}]}
{"op":"mcm","clk":"11450024475","pt":1717317202221,"mc":[{"id":"1.229554898","rc":[{"atl":[[1000,0]],"id":52671546}],"con":true,"img":false}]}
{"op":"mcm","clk":"11450024521","pt":1717317202741,"mc":[{"id":"1.229554898","rc":[{"atl":[[1000,2]],"id":52671546}],"con":true,"img":false}]}
{"op":"mcm","clk":"11450024969","pt":1717317206731,"mc":[{"id":"1.229554898","rc":[{"atb":[[9.2,8.18]],"id":52671549},{"atb":[[1.18,87.19],[1.19,275.36]],"id":52671548}],"con":true,"img":false}]}
{"op":"mcm","clk":"11450025044","pt":1717317207412,"mc":[{"id":"1.229554898","rc":[{"atl":[[27,3.85],[29,0]],"id":52671555}],"con":true,"img":false}]}
{"op":"mcm","clk":"11450025808","pt":1717317215297,"mc":[{"id":"1.229554898","rc":[{"atb":[[1.18,0],[1.13,120.73]],"id":52671548}],"con":true,"img":false}]}
{"op":"mcm","clk":"11450026091","pt":1717317217830,"mc":[{"id":"1.229554898","rc":[{"atl":[[1000,0]],"id":52671546}],"con":true,"img":false}]}
{"op":"mcm","clk":"11450026104","pt":1717317217940,"mc":[{"id":"1.229554898","rc":[{"atl":[[1000,2]],"id":52671546}],"con":true,"img":false}]}
{"op":"mcm","clk":"11450026372","pt":1717317220327,"mc":[{"id":"1.229554898","rc":[{"atl":[[70,0],[55,2]],"id":52671550},{"atl":[[1000,0]],"id":52671546},{"atb":[[5.6,74.76],[5.1,0]],"id":52671549},{"atl":[[23,0],[29,3.57]],"id":52671549},{"atb":[[4.5,0],[3.75,36.36]],"id":52671555},{"atl":[[9.2,12.2],[8.2,0]],"id":52671554},{"atb":[[10,4.07],[7.8,14.71]],"id":52671556}],"con":true,"img":false}]}
{"op":"mcm","clk":"11450026379","pt":1717317220433,"mc":[{"id":"1.229554898","rc":[{"atl":[[1000,2]],"id":52671546}],"con":true,"img":false}]}
{"op":"mcm","clk":"11450026403","pt":1717317220643,"mc":[{"id":"1.229554898","rc":[{"atb":[[16,0],[17.5,0],[18,6.14],[20,0],[25,0],[15,0]],"id":52671550},{"atl":[[100,0],[110,4.36]],"id":52671550},{"atb":[[85,0],[44,0],[120,0],[60,0]],"id":52671546},{"atb":[[9.6,23.87],[9.2,0],[10.5,5.01],[11.5,17.78]],"id":52671549},{"atl":[[25,0],[30,3.87]],"id":52671549},{"atl":[[2.64,15.11],[2.94,5.01]],"id":52671548},{"atb":[[20,0],[21,14.36]],"id":52671542},{"atl":[[36,4.58],[42,5.01],[44,0],[55,2.83]],"id":52671542},{"atb":[[34,0],[38,0],[44,0],[50,5.01],[27,0],[60,0]],"id":52671545},{"atl":[[710,2.99],[470,0],[500,0]],"id":52671545},{"atb":[[9.6,8.29],[10,5.01]],"id":52671544},{"atl":[[16.5,10.35],[20,5.01]],"id":52671544},{"atb":[[8.4,0],[5.9,5.01]],"id":52671555},{"atl":[[44,0],[48,4.18]],"id":52671555},{"atb":[[5.3,5.01],[4.7,35.06]],"id":52671554},{"atl":[[12,0],[13.5,4]],"id":52671554},{"atb":[[32,0],[42,0],[21,0],[26,0],[28,0]],"id":52671556}],"con":true,"img":false}]}
{"op":"mcm","clk":"11450026421","pt":1717317220845,"mc":[{"id":"1.229554898","rc":[{"atl":[[1000,0]],"id":52671546},{"atl":[[8.4,26.71]],"id":52671554}],"con":true,"img":false}]}
{"op":"mcm","clk":"11450026452","pt":1717317221108,"mc":[{"id":"1.229554898","rc":[{"atb":[[11,5.01]],"id":52671550},{"atb":[[50,5.01]],"id":52671546},{"atb":[[55,2.97]],"id":52671545},{"atb":[[5.4,25.92]],"id":52671554},{"atb":[[20,5.01]],"id":52671556}],"con":true,"img":false}]}
{"op":"mcm","clk":"11450026500","pt":1717317221531,"mc":[{"id":"1.229554898","rc":[{"atb":[[16.5,1.69],[9.6,12.17],[4.6,3.01],[11.5,7.48],[14,4.02]],"id":52671550},{"atb":[[32,3.37],[80,0.33],[42,1.92],[55,0.97]],"id":52671546},{"atl":[[1000,2]],"id":52671546},{"atb":[[9.6,9.56]],"id":52671549},{"atl":[[2.94,0]],"id":52671548},{"atl":[[48,0]],"id":52671542},{"atb":[[32,6.75],[80,0.33],[42,1.92],[55,3.94]],"id":52671545},{"atl":[[9,0],[13,0],[13.5,0]],"id":52671554},{"atb":[[17.5,6.34],[20,9.15],[25,2.18],[30,0.9]],"id":52671556}],"con":true,"img":false}]}
{"op":"mcm","clk":"11450026505","pt":1717317221626,"mc":[{"id":"1.229554898","rc":[{"atl":[[26,0]],"id":52671549},{"atl":[[2.88,5.01]],"id":52671548},{"atl":[[27,0],[30,3.45]],"id":52671555}],"con":true,"img":false}]}
{"op":"mcm","clk":"11450026515","pt":1717317221731,"mc":[{"id":"1.229554898","rc":[{"atl":[[1000,0]],"id":52671546}],"con":true,"img":false}]}
{"op":"mcm","clk":"11450026524","pt":1717317221833,"mc":[{"id":"1.229554898","rc":[{"atb":[[50,0],[55,5.99]],"id":52671546},{"atb":[[4.7,0]],"id":52671554},{"atb":[[22,5.01]],"id":52671556}],"con":true,"img":false}]}
{"op":"mcm","clk":"11450026532","pt":1717317221937,"mc":[{"id":"1.229554898","rc":[{"atl":[[100,4.13],[110,0]],"id":52671550},{"atb":[[9.6,6.08],[9.8,3.09]],"id":52671549},{"atl":[[25,2.98]],"id":52671549},{"atb":[[1.15,0],[1.16,98.09]],"id":52671548},{"atl":[[44,4.23]],"id":52671542},{"atl":[[470,3.71]],"id":52671545},{"atl":[[20,8.18]],"id":52671544},{"atl":[[44,3.38],[48,0]],"id":52671555},{"atl":[[12,3.13]],"id":52671554},{"atb":[[20,4.13]],"id":52671556}],"con":true,"img":false}]}
{"op":"mcm","clk":"11450026545","pt":1717317222038,"mc":[{"id":"1.229554898","rc":[{"atl":[[1000,2]],"id":52671546},{"atl":[[27,3.85],[30,0]],"id":52671555}],"con":true,"img":false}]}
{"op":"mcm","clk":"11450026576","pt":1717317222348,"mc":[{"id":"1.229554898","rc":[{"atl":[[1000,0]],"id":52671546},{"atl":[[29,7.31]],"id":52671549},{"atl":[[710,0],[730,4.54]],"id":52671545},{"atl":[[23,0],[24,4.14]],"id":52671544},{"atl":[[27,0],[30,3.45]],"id":52671555},{"atl":[[14,2.63],[15,4.58]],"id":52671554}],"con":true,"img":false}]}
{"op":"mcm","clk":"11450026588","pt":1717317222402,"mc":[{"id":"1.229554898","rc":[{"atl":[[1000,2]],"id":52671546},{"atl":[[27,3.85],[30,0]],"id":52671555}],"con":true,"img":false}]}
{"op":"mcm","clk":"11450026610","pt":1717317222610,"mc":[{"id":"1.229554898","rc":[{"atl":[[13,3.17]],"id":52671554}],"con":true,"img":false}]}
{"op":"mcm","clk":"11450026773","pt":1717317224111,"mc":[{"id":"1.229554898","rc":[{"atl":[[30,3.45]],"id":52671555}],"con":true,"img":false}]}
{"op":"mcm","clk":"11450026785","pt":1717317224212,"mc":[{"id":"1.229554898","rc":[{"atl":[[1000,0]],"id":52671546},{"atl":[[27,0]],"id":52671555}],"con":true,"img":false}]}
{"op":"mcm","clk":"11450026805","pt":1717317224423,"mc":[{"id":"1.229554898","rc":[{"atl":[[30,0]],"id":52671549},{"atl":[[14,0],[15,0]],"id":52671554}],"con":true,"img":false}]}
{"op":"mcm","clk":"11450026902","pt":1717317225405,"mc":[{"id":"1.229554898","rc":[{"atl":[[55,0],[60,2]],"id":52671550}],"con":true,"img":false}]}
{"op":"mcm","clk":"11450026912","pt":1717317225505,"mc":[{"id":"1.229554898","rc":[{"atl":[[9.2,0],[9.4,11.9]],"id":52671554}],"con":true,"img":false}]}
{"op":"mcm","clk":"11450027041","pt":1717317226848,"mc":[{"id":"1.229554898","rc":[{"atl":[[100,0],[110,4.02]],"id":52671550},{"atb":[[10,2.81],[9.8,0]],"id":52671549},{"atl":[[25,0]],"id":52671549},{"atb":[[1.16,0],[1.13,0]],"id":52671548},{"atl":[[44,0]],"id":52671542},{"atl":[[470,0]],"id":52671545},{"atb":[[11,0],[7.4,0],[8.4,0],[9.4,0]],"id":52671544},{"atl":[[20,5.01]],"id":52671544},{"atl":[[44,0],[48,3.34]],"id":52671555},{"atl":[[12,0],[14,2.62]],"id":52671554}],"con":true,"img":false}]}
{"op":"mcm","clk":"11450027080","pt":1717317227214,"mc":[{"id":"1.229554898","rc":[{"atb":[[10,20.13]],"id":52671544}],"con":true,"img":false}]}
{"op":"mcm","clk":"11450027108","pt":1717317227522,"mc":[{"id":"1.229554898","rc":[{"atb":[[12,2.38],[9.8,5.94],[8.8,10.06],[7.8,15.39]],"id":52671544}],"con":true,"img":false}]}
{"op":"mcm","clk":"11450027152","pt":1717317228036,"mc":[{"id":"1.229554898","rc":[{"atl":[[720,4.15]],"id":52671545},{"atb":[[9.6,0]],"id":52671544}],"con":true,"img":false}]}
{"op":"mcm","clk":"11450027164","pt":1717317228139,"mc":[{"id":"1.229554898","rc":[{"atl":[[55,2],[60,0]],"id":52671550},{"atl":[[1000,2]],"id":52671546},{"atl":[[26,4],[30,0]],"id":52671555}],"con":true,"img":false}]}
{"op":"mcm","clk":"11450027176","pt":1717317228242,"mc":[{"id":"1.229554898","rc":[{"atl":[[13,0],[13.5,4.3]],"id":52671554}],"con":true,"img":false}]}
{"op":"mcm","clk":"11450027190","pt":1717317228443,"mc":[{"id":"1.229554898","rc":[{"atl":[[710,3.15]],"id":52671545},{"atl":[[23,3.47]],"id":52671544}],"con":true,"img":false}]}
{"op":"mcm","clk":"11450027377","pt":1717317230210,"mc":[{"id":"1.229554898","rc":[{"atl":[[44,3.69]],"id":52671542}],"con":true,"img":false}]}
{"op":"mcm","clk":"11450027478","pt":1717317231141,"mc":[{"id":"1.229554898","rc":[{"atl":[[1000,0]],"id":52671546}],"con":true,"img":false}]}
{"op":"mcm","clk":"11450027512","pt":1717317231445,"mc":[{"id":"1.229554898","rc":[{"atl":[[100,2.86],[110,0]],"id":52671550},{"atl":[[26,3.33]],"id":52671549},{"atl":[[710,0],[720,0],[730,0],[490,2.96]],"id":52671545},{"atl":[[20,9.54],[23,0]],"id":52671544},{"atl":[[44,3.63],[48,0]],"id":52671555},{"atl":[[12,3.26],[13.5,0]],"id":52671554}],"con":true,"img":false}]}
{"op":"mcm","clk":"11450027689","pt":1717317233256,"mc":[{"id":"1.229554898","rc":[{"atl":[[55,0],[60,2]],"id":52671550},{"atl":[[26,0],[29,3.57]],"id":52671555}],"con":true,"img":false}]}
{"op":"mcm","clk":"11450027891","pt":1717317235027,"mc":[{"id":"1.229554898","rc":[{"atb":[[18,0],[13,0]],"id":52671550},{"atb":[[550,0],[650,0]],"id":52671546},{"atb":[[5.6,21.74],[7.2,0]],"id":52671549},{"atb":[[1.01,0],[1.04,0]],"id":52671548},{"atb":[[7.4,0],[9.4,0]],"id":52671542},{"atb":[[32,3.37],[21,0]],"id":52671545},{"atb":[[4.8,26.32],[5.8,0]],"id":52671544},{"atb":[[9,0],[12.5,0]],"id":52671555},{"atb":[[3.7,0],[4.4,2.79]],"id":52671554},{"atb":[[340,0],[440,0]],"id":52671556}],"con":true,"img":false}]}
{"op":"mcm","clk":"11450027926","pt":1717317235438,"mc":[{"id":"1.229554898","rc":[{"atl":[[100,0],[110,2.93]],"id":52671550},{"atl":[[26,0]],"id":52671549},{"atl":[[44,0]],"id":52671542},{"atl":[[710,2.83],[490,0]],"id":52671545},{"atl":[[20,5.01],[23,2.86]],"id":52671544},{"atl":[[44,0],[48,4.49]],"id":52671555},{"atl":[[12,0],[13.5,4.04]],"id":52671554}],"con":true,"img":false}]}
{"op":"mcm","clk":"11450027940","pt":1717317235547,"mc":[{"id":"1.229554898","rc":[{"atb":[[5.9,15.85]],"id":52671555}],"con":true,"img":false}]}
{"op":"mcm","clk":"11450028199","pt":1717317238462,"mc":[{"id":"1.229554898","rc":[{"atb":[[5.9,2.81]],"id":52671542},{"atl":[[65,3.32]],"id":52671542}],"con":true,"img":false}]}
{"op":"mcm","clk":"11450028290","pt":1717317239655,"mc":[{"id":"1.229554898","rc":[{"atb":[[9.6,10.57]],"id":52671549},{"atl":[[32,4.34]],"id":52671549},{"atb":[[1.11,130.79],[1.13,120.73]],"id":52671548}],"con":true,"img":false}]}
{"op":"mcm","clk":"11450028456","pt":1717317241172,"mc":[{"id":"1.229554898","rc":[{"atl":[[130,2],[80,0]],"id":52671542},{"atl":[[260,0],[360,2]],"id":52671545},{"atl":[[32,0],[48,2.13]],"id":52671544},{"atl":[[11.5,9.52],[9.4,0]],"id":52671554}],"con":true,"img":false}]}
{"op":"mcm","clk":"11450028498","pt":1717317241438,"mc":[{"id":"1.229554898","rc":[{"atb":[[4.6,5.92],[3.05,0]],"id":52671550},{"atb":[[8.6,10.33]],"id":52671549},{"atb":[[4.3,0]],"id":52671542}],"con":true,"img":false}]}
{"op":"mcm","clk":"11450028713","pt":1717317243566,"mc":[{"id":"1.229554898","rc":[{"atl":[[730,3.37]],"id":52671545}],"con":true,"img":false}]}
{"op":"mcm","clk":"11450028918","pt":1717317245734,"mc":[{"id":"1.229554898","rc":[{"atb":[[10,0]],"id":52671549},{"atl":[[29,3.57],[30,3.57]],"id":52671549},{"atb":[[1.15,104.63],[1.13,0]],"id":52671548},{"atl":[[710,0],[720,3.09]],"id":52671545}],"con":true,"img":false}]}
{"op":"mcm","clk":"11450029205","pt":1717317248783,"mc":[{"id":"1.229554898","rc":[{"atb":[[18,0],[21,13.04],[13,0],[15.5,0]],"id":52671542}],"con":true,"img":false}]}
{"op":"mcm","clk":"11450029277","pt":1717317249462,"mc":[{"id":"1.229554898","rc":[{"atb":[[4.4,4.69]],"id":52671550},{"atb":[[17.5,4.76],[20,2.75],[25,1.09],[15,7.48]],"id":52671542}],"con":true,"img":false}]}
{"op":"mcm","clk":"11450029687","pt":1717317253659,"mc":[{"id":"1.229554898","rc":[{"atb":[[9.2,3.37]],"id":52671549},{"atl":[[29,6.59],[30,0]],"id":52671549},{"atb":[[1.13,120.73]],"id":52671548},{"atl":[[720,0],[750,4.5]],"id":52671545},{"atl":[[23,0],[26,4.03]],"id":52671544},{"atl":[[13.5,0],[15,3.3]],"id":52671554}],"con":true,"img":false}]}
{"op":"mcm","clk":"11450029733","pt":1717317254182,"mc":[{"id":"1.229554898","rc":[{"atl":[[65,2],[60,0]],"id":52671550},{"atb":[[1.27,367],[1.33,0]],"id":52671548}],"con":true,"img":false}]}
{"op":"mcm","clk":"11450029761","pt":1717317254485,"mc":[{"id":"1.229554898","rc":[{"atb":[[2.98,0]],"id":52671550},{"atl":[[110,0]],"id":52671550},{"atl":[[29,3.57],[30,3.03]],"id":52671549},{"atb":[[1.11,0]],"id":52671548},{"atl":[[730,0],[790,3.33]],"id":52671545},{"atl":[[48,0]],"id":52671555}],"con":true,"img":false}]}
{"op":"mcm","clk":"11450029956","pt":1717317256462,"mc":[{"id":"1.229554898","rc":[{"atl":[[65,0],[60,2]],"id":52671550}],"con":true,"img":false}]}
{"op":"mcm","clk":"11450029988","pt":1717317256768,"mc":[{"id":"1.229554898","rc":[{"atl":[[30,0]],"id":52671549},{"atb":[[1.15,0],[1.14,672.66]],"id":52671548},{"atl":[[55,0],[60,3.76]],"id":52671542},{"atl":[[750,0],[830,4.12]],"id":52671545}],"con":true,"img":false}]}
{"op":"mcm","clk":"11450030041","pt":1717317257289,"mc":[{"id":"1.229554898","rc":[{"atl":[[140,4.58]],"id":52671550}],"con":true,"img":false}]}
{"op":"mcm","clk":"11450030228","pt":1717317259249,"mc":[{"id":"1.229554898","rc":[{"atl":[[110,4.38],[120,0]],"id":52671550},{"atl":[[29,6.43]],"id":52671549},{"atl":[[55,2.8],[60,0]],"id":52671542},{"atl":[[730,3.97],[790,0]],"id":52671545},{"atl":[[48,4.65]],"id":52671555},{"atl":[[13.5,3.43],[14,0]],"id":52671554}],"con":true,"img":false}]}
{"op":"mcm","clk":"11450030302","pt":1717317259880,"mc":[{"id":"1.229554898","rc":[{"atb":[[10,3.71]],"id":52671549}],"con":true,"img":false}]}
{"op":"mcm","clk":"11450030314","pt":1717317259982,"mc":[{"id":"1.229554898","rc":[{"atb":[[9.6,6.08]],"id":52671549},{"atb":[[1.14,560.55],[1.13,0]],"id":52671548}],"con":true,"img":false}]}
{"op":"mcm","clk":"11450030330","pt":1717317260106,"mc":[{"id":"1.229554898","rc":[{"atl":[[29,3.57],[30,3.14]],"id":52671549},{"atl":[[730,0],[720,3]],"id":52671545},{"atl":[[23,3.48],[24,0]],"id":52671544}],"con":true,"img":false}]}
{"op":"mcm","clk":"11450030358","pt":1717317260345,"mc":[{"id":"1.229554898","rc":[{"atl":[[48,5.01],[50,3.27]],"id":52671550}],"con":true,"img":false}]}
{"op":"mcm","clk":"11450030370","pt":1717317260448,"mc":[{"id":"1.229554898","rc":[{"atl":[[55,2],[60,0]],"id":52671550},{"atl":[[1000,2]],"id":52671546},{"atl":[[26,4],[29,0]],"id":52671555}],"con":true,"img":false}]}
{"op":"mcm","clk":"11450030380","pt":1717317260555,"mc":[{"id":"1.229554898","rc":[{"atl":[[1000,0]],"id":52671546}],"con":true,"img":false}]}
{"op":"mcm","clk":"11450030408","pt":1717317260814,"mc":[{"id":"1.229554898","rc":[{"atl":[[48,8.43]],"id":52671550},{"atb":[[9.6,9.9],[10,0]],"id":52671549},{"atb":[[1.16,98.09],[1.14,672.66]],"id":52671548}],"con":true,"img":false}]}
{"op":"mcm","clk":"11450030419","pt":1717317260871,"mc":[{"id":"1.229554898","rc":[{"atl":[[27,4.59],[30,0]],"id":52671549},{"atb":[[1.11,130.79],[1.13,120.73]],"id":52671548},{"atl":[[46,3.84],[55,0]],"id":52671542},{"atl":[[550,3.81],[720,0]],"id":52671545},{"atl":[[21,3.47],[23,0]],"id":52671544},{"atl":[[44,4.14],[48,0]],"id":52671555},{"atl":[[12.5,4.63],[13.5,0]],"id":52671554}],"con":true,"img":false}]}
{"op":"mcm","clk":"11450030509","pt":1717317261594,"mc":[{"id":"1.229554898","rc":[{"atl":[[50,0]],"id":52671550}],"con":true,"img":false}]}
{"op":"mcm","clk":"11450030707","pt":1717317263450,"mc":[{"id":"1.229554898","rc":[{"atl":[[1000,2]],"id":52671546}],"con":true,"img":false}]}
{"op":"mcm","clk":"11450030714","pt":1717317263557,"mc":[{"id":"1.229554898","rc":[{"atl":[[48,0],[55,7.01]],"id":52671550},{"atb":[[9.6,6.08],[10,3.39]],"id":52671549},{"atl":[[27,0],[30,3.34]],"id":52671549},{"atb":[[1.16,0],[1.67,5.01],[1.68,0],[1.14,560.55],[1.13,0]],"id":52671548},{"atl":[[46,0],[55,4.07]],"id":52671542},{"atl":[[550,0],[720,3.39]],"id":52671545},{"atb":[[10,0],[9.8,10.96]],"id":52671544},{"atl":[[21,0],[23,3.03]],"id":52671544},{"atl":[[21,0],[44,0],[22,5.01],[48,3.96]],"id":52671555},{"atl":[[12.5,0],[13.5,3.28]],"id":52671554}],"con":true,"img":false}]}
{"op":"mcm","clk":"11450030730","pt":1717317263759,"mc":[{"id":"1.229554898","rc":[{"atl":[[29,7.3]],"id":52671549},{"atl":[[710,2.91]],"id":52671545}],"con":true,"img":false}]}
{"op":"mcm","clk":"11450030750","pt":1717317263976,"mc":[{"id":"1.229554898","rc":[{"atb":[[17.5,0],[20,0],[25,0],[15,0]],"id":52671542},{"atl":[[50,4.7]],"id":52671542},{"atl":[[640,2.62]],"id":52671545},{"atl":[[22,2.85]],"id":52671544}],"con":true,"img":false}]}
{"op":"mcm","clk":"11450030759","pt":1717317264072,"mc":[{"id":"1.229554898","rc":[{"atb":[[1.15,104.63]],"id":52671548}],"con":true,"img":false}]}
{"op":"mcm","clk":"11450030775","pt":1717317264286,"mc":[{"id":"1.229554898","rc":[{"atl":[[100,1.62]],"id":52671550},{"atb":[[1.27,397.3]],"id":52671548},{"atl":[[25,6.69]],"id":52671555}],"con":true,"img":false}]}
{"op":"mcm","clk":"11450030785","pt":1717317264387,"mc":[{"id":"1.229554898","rc":[{"atl":[[30,0]],"id":52671549},{"atl":[[55,0]],"id":52671542},{"atl":[[720,0]],"id":52671545},{"atl":[[23,0]],"id":52671544},{"atl":[[22,0],[23,5.01],[46,3.6],[48,0]],"id":52671555},{"atl":[[8.2,5.01],[13,3.61],[13.5,0],[8.4,21.7]],"id":52671554}],"con":true,"img":false}]}
{"op":"mcm","clk":"11450030806","pt":1717317264694,"mc":[{"id":"1.229554898","rc":[{"atb":[[18,4.61],[21,15.66],[26,1.05],[15.5,7.21]],"id":52671542}],"con":true,"img":false}]}
{"op":"mcm","clk":"11450030821","pt":1717317264853,"mc":[{"id":"1.229554898","rc":[{"atl":[[1000,0]],"id":52671546},{"atl":[[8.2,26.9]],"id":52671554}],"con":true,"img":false}]}
{"op":"mcm","clk":"11450030859","pt":1717317265174,"mc":[{"id":"1.229554898","rc":[{"atl":[[110,0],[120,3.35]],"id":52671550},{"atl":[[29,3.57]],"id":52671549},{"atl":[[50,0],[60,3.29]],"id":52671542},{"atl":[[640,0],[710,0]],"id":52671545},{"atl":[[22,0],[24,4.46]],"id":52671544},{"atl":[[46,0],[50,0]],"id":52671555},{"atl":[[13,0],[14,3.89]],"id":52671554}],"con":true,"img":false}]}
{"op":"mcm","clk":"11450030872","pt":1717317265265,"mc":[{"id":"1.229554898","rc":[{"atl":[[36,3.25]],"id":52671549},{"atl":[[830,0]],"id":52671545},{"atl":[[27,2.94]],"id":52671544},{"atl":[[48,4.2]],"id":52671555},{"atl":[[15,0]],"id":52671554}],"con":true,"img":false}]}
{"op":"mcm","clk":"11450030900","pt":1717317265574,"mc":[{"id":"1.229554898","rc":[{"atl":[[60,2]],"id":52671550},{"atl":[[28,3.7]],"id":52671555}],"con":true,"img":false}]}
{"op":"mcm","clk":"11450030911","pt":1717317265682,"mc":[{"id":"1.229554898","rc":[{"atl":[[55,5.01]],"id":52671550},{"atl":[[26,0]],"id":52671555},{"atl":[[8.4,0]],"id":52671554}],"con":true,"img":false}]}
{"op":"mcm","clk":"11450030932","pt":1717317265883,"mc":[{"id":"1.229554898","rc":[{"atl":[[55,7.01],[60,0]],"id":52671550},{"atl":[[1000,2]],"id":52671546}],"con":true,"img":false}]}
{"op":"mcm","clk":"11450030943","pt":1717317265987,"mc":[{"id":"1.229554898","rc":[{"atl":[[55,5.01],[60,2]],"id":52671550},{"atl":[[1000,0]],"id":52671546},{"atl":[[28,0],[29,3.57]],"id":52671555}],"con":true,"img":false}]}
{"op":"mcm","clk":"11450030956","pt":1717317266085,"mc":[{"id":"1.229554898","rc":[{"atl":[[28,3.7]],"id":52671555}],"con":true,"img":false}]}
{"op":"mcm","clk":"11450030966","pt":1717317266194,"mc":[{"id":"1.229554898","rc":[{"atl":[[32,0]],"id":52671549},{"atl":[[60,0]],"id":52671542},{"atl":[[29,0]],"id":52671555},{"atl":[[14,0],[15.5,3.28]],"id":52671554}],"con":true,"img":false}]}
{"op":"mcm","clk":"11450030978","pt":1717317266292,"mc":[{"id":"1.229554898","rc":[{"atl":[[110,3.2],[120,0]],"id":52671550},{"atl":[[29,6.27]],"id":52671549},{"atb":[[1.15,0],[1.14,672.66]],"id":52671548},{"atl":[[50,3.7]],"id":52671542},{"atl":[[640,2.97],[660,3.11]],"id":52671545},{"atl":[[22,4.04],[24,0],[26,0],[27,0]],"id":52671544},{"atl":[[46,3.33],[28,0],[29,3.57]],"id":52671555},{"atl":[[13,3.62]],"id":52671554}],"con":true,"img":false}]}
{"op":"mcm","clk":"11450030989","pt":1717317266397,"mc":[{"id":"1.229554898","rc":[{"atl":[[38,3.13]],"id":52671549},{"atl":[[55,3.7]],"id":52671542},{"atl":[[23,4.41]],"id":52671544},{"atl":[[28,3.7],[29,0]],"id":52671555},{"atl":[[16,4.17]],"id":52671554}],"con":true,"img":false}]}
{"op":"mcm","clk":"11450031056","pt":1717317267075,"mc":[{"id":"1.229554898","rc":[{"atl":[[65,2],[60,0]],"id":52671550}],"con":true,"img":false}]}
{"op":"mcm","clk":"11450031091","pt":1717317267384,"mc":[{"id":"1.229554898","rc":[{"atl":[[110,0],[120,4.37]],"id":52671550},{"atl":[[38,0],[29,3.57]],"id":52671549},{"atl":[[50,0],[55,0]],"id":52671542},{"atl":[[640,0],[660,0]],"id":52671545},{"atl":[[22,0],[23,0]],"id":52671544},{"atl":[[46,0]],"id":52671555},{"atl":[[16,0],[13,0]],"id":52671554}],"con":true,"img":false}]}
{"op":"mcm","clk":"11450031244","pt":1717317268883,"mc":[{"id":"1.229554898","rc":[{"atl":[[1000,2]],"id":52671546}],"con":true,"img":false}]}
{"op":"mcm","clk":"11450031394","pt":1717317270490,"mc":[{"id":"1.229554898","rc":[{"atb":[[18,6.14],[13,20.32]],"id":52671550},{"atb":[[550,0.44],[650,0.16]],"id":52671546},{"atb":[[5.6,74.76],[7.2,16.86]],"id":52671549},{"atb":[[1.01,24390.49],[1.04,2613.26]],"id":52671548},{"atb":[[7.4,38.1],[9.4,12.44]],"id":52671542},{"atb":[[32,6.75],[21,12.19]],"id":52671545},{"atb":[[4.8,90.5],[5.8,21.77]],"id":52671544},{"atb":[[9,30.48],[12.5,9.08]],"id":52671555},{"atb":[[3.7,90.33],[4.4,33.53]],"id":52671554},{"atb":[[340,0.72],[440,0.24]],"id":52671556}],"con":true,"img":false}]}
{"op":"mcm","clk":"11450031464","pt":1717317271169,"mc":[{"id":"1.229554898","rc":[{"atb":[[32,0],[80,0],[42,0],[55,5.01]],"id":52671546},{"atb":[[32,3.37],[80,0],[42,0],[55,2.97]],"id":52671545}],"con":true,"img":false}]}
{"op":"mcm","clk":"11450031474","pt":1717317271272,"mc":[{"id":"1.229554898","rc":[{"atl":[[1000,0]],"id":52671546},{"atl":[[280,2],[360,0]],"id":52671545},{"atl":[[38,2.7],[48,0]],"id":52671544},{"atl":[[11.5,0],[9.4,11.9]],"id":52671554}],"con":true,"img":false}]}
{"op":"mcm","clk":"11450031490","pt":1717317271377,"mc":[{"id":"1.229554898","rc":[{"atl":[[1000,2]],"id":52671546}],"con":true,"img":false}]}
{"op":"mcm","clk":"11450031544","pt":1717317271892,"mc":[{"id":"1.229554898","rc":[{"atb":[[34,3.17],[85,0.31],[44,1.83],[60,0.88]],"id":52671546},{"atb":[[34,3.17],[85,0.31],[44,1.83],[60,0.88]],"id":52671545}],"con":true,"img":false}]}
{"op":"mcm","clk":"11450031576","pt":1717317272147,"mc":[{"id":"1.229554898","rc":[{"atl":[[65,0],[55,7.01]],"id":52671550}],"con":true,"img":false}]}
{"op":"mcm","clk":"11450031615","pt":1717317272561,"mc":[{"id":"1.229554898","rc":[{"atl":[[55,9.98]],"id":52671550},{"atb":[[5.3,0],[5.4,30.94]],"id":52671554}],"con":true,"img":false}]}
{"op":"mcm","clk":"11450031665","pt":1717317273077,"mc":[{"id":"1.229554898","rc":[{"atl":[[1000,0]],"id":52671546}],"con":true,"img":false}]}
{"op":"mcm","clk":"11450031689","pt":1717317273281,"mc":[{"id":"1.229554898","rc":[{"atl":[[100,0]],"id":52671550}],"con":true,"img":false}]}
{"op":"mcm","clk":"11450031748","pt":1717317273901,"mc":[{"id":"1.229554898","rc":[{"atl":[[830,3.64],[850,2.87]],"id":52671545},{"atl":[[48,0],[50,3.85]],"id":52671555}],"con":true,"img":false}]}
{"op":"mcm","clk":"11450031759","pt":1717317274003,"mc":[{"id":"1.229554898","rc":[{"atb":[[9.6,10.71]],"id":52671549},{"atl":[[32,4.65]],"id":52671549},{"atl":[[60,3.01]],"id":52671542},{"atl":[[24,2.82],[26,3.59]],"id":52671544},{"atl":[[14,2.68]],"id":52671554}],"con":true,"img":false}]}
{"op":"mcm","clk":"11450031978","pt":1717317275970,"mc":[{"id":"1.229554898","rc":[{"atb":[[1.67,56.41]],"id":52671548},{"atl":[[23,12.31]],"id":52671555}],"con":true,"img":false}]}
{"op":"mcm","clk":"11450032033","pt":1717317276492,"mc":[{"id":"1.229554898","rc":[{"atb":[[12,0],[9.8,5.01],[8.8,0],[7.8,0]],"id":52671544}],"con":true,"img":false}]}
{"op":"mcm","clk":"11450032056","pt":1717317276691,"mc":[{"id":"1.229554898","rc":[{"atb":[[1.27,367]],"id":52671548},{"atl":[[25,0]],"id":52671555}],"con":true,"img":false}]}
{"op":"mcm","clk":"11450032081","pt":1717317276899,"mc":[{"id":"1.229554898","rc":[{"atb":[[9.8,16.83]],"id":52671544}],"con":true,"img":false}]}
{"op":"mcm","clk":"11450032116","pt":1717317277161,"mc":[{"id":"1.229554898","rc":[{"atl":[[65,2],[55,7.98]],"id":52671550},{"atb":[[9.2,9.57],[10.5,5.51],[8.2,14.53],[13,2.18]],"id":52671544}],"con":true,"img":false}]}
{"op":"mcm","clk":"11450032168","pt":1717317277572,"mc":[{"id":"1.229554898","rc":[{"atl":[[16.5,0]],"id":52671544}],"con":true,"img":false}]}
{"op":"mcm","clk":"11450032203","pt":1717317277884,"mc":[{"id":"1.229554898","rc":[{"atb":[[1.67,0],[1.66,5.01]],"id":52671548},{"atl":[[23,7.29],[24,5.01]],"id":52671555}],"con":true,"img":false}]}
{"op":"mcm","clk":"11450032216","pt":1717317277985,"mc":[{"id":"1.229554898","rc":[{"atb":[[9.2,0]],"id":52671549},{"atl":[[23,0]],"id":52671555}],"con":true,"img":false}]}
{"op":"mcm","clk":"11450032233","pt":1717317278090,"mc":[{"id":"1.229554898","rc":[{"atl":[[28,0],[30,3.45]],"id":52671555}],"con":true,"img":false}]}
{"op":"mcm","clk":"11450032252","pt":1717317278295,"mc":[{"id":"1.229554898","rc":[{"atl":[[23,7.29]],"id":52671544}],"con":true,"img":false}]}
{"op":"mcm","clk":"11450032268","pt":1717317278401,"mc":[{"id":"1.229554898","rc":[{"atl":[[9.2,12.2],[9.4,0]],"id":52671554}],"con":true,"img":false}]}
{"op":"mcm","clk":"11450032290","pt":1717317278607,"mc":[{"id":"1.229554898","rc":[{"atb":[[1.27,397.3]],"id":52671548}],"con":true,"img":false}]}
{"op":"mcm","clk":"11450032300","pt":1717317278659,"mc":[{"id":"1.229554898","rc":[{"atl":[[48,3.41]],"id":52671555}],"con":true,"img":false}]}
{"op":"mcm","clk":"11450032322","pt":1717317278870,"mc":[{"id":"1.229554898","rc":[{"atl":[[280,0]],"id":52671545}],"con":true,"img":false}]}
{"op":"mcm","clk":"11450032333","pt":1717317278971,"mc":[{"id":"1.229554898","rc":[{"atl":[[400,2]],"id":52671545}],"con":true,"img":false}]}
{"op":"mcm","clk":"11450032352","pt":1717317279179,"mc":[{"id":"1.229554898","rc":[{"atb":[[16.5,0],[9.6,0],[11,0],[11.5,0],[14,0]],"id":52671550},{"atb":[[34,0],[85,0],[44,0],[60,0]],"id":52671546},{"atl":[[2.88,0],[2.86,5.01]],"id":52671548},{"atb":[[6,5.01],[5.9,10.84]],"id":52671555},{"atb":[[17.5,0],[20,0],[25,0],[30,0]],"id":52671556}],"con":true,"img":false}]}
{"op":"mcm","clk":"11450032372","pt":1717317279385,"mc":[{"id":"1.229554898","rc":[{"atl":[[830,0],[850,0]],"id":52671545},{"atl":[[27,3.34]],"id":52671544},{"atl":[[8.2,5.01],[8.4,5.01]],"id":52671554}],"con":true,"img":false}]}
{"op":"mcm","clk":"11450032381","pt":1717317279487,"mc":[{"id":"1.229554898","rc":[{"atl":[[32,0]],"id":52671549},{"atb":[[1.15,104.63],[1.14,560.55]],"id":52671548},{"atl":[[60,0]],"id":52671542},{"atl":[[24,0]],"id":52671544},{"atl":[[48,6.61]],"id":52671555},{"atl":[[8.2,0],[14,0]],"id":52671554}],"con":true,"img":false}]}
{"op":"mcm","clk":"11450032399","pt":1717317279696,"mc":[{"id":"1.229554898","rc":[{"atb":[[11.5,5.01]],"id":52671550}],"con":true,"img":false}]}
{"op":"mcm","clk":"11450032426","pt":1717317279907,"mc":[{"id":"1.229554898","rc":[{"atb":[[17,1.64],[12,7.14],[9.8,11.89],[14.5,3.88]],"id":52671550},{"atb":[[65,0.82],[36,2.99],[90,0.29],[46,1.74]],"id":52671546},{"atb":[[32,0.84],[18,6.15],[21,3.92],[26,2.09]],"id":52671556}],"con":true,"img":false}]}
{"op":"mcm","clk":"11450032445","pt":1717317280111,"mc":[{"id":"1.229554898","rc":[{"atl":[[9.2,31.78]],"id":52671554}],"con":true,"img":false}]}
{"op":"mcm","clk":"11450032482","pt":1717317280422,"mc":[{"id":"1.229554898","rc":[{"atl":[[26,0]],"id":52671544}],"con":true,"img":false}]}
{"op":"mcm","clk":"11450032585","pt":1717317281304,"mc":[{"id":"1.229554898","rc":[{"atl":[[830,2.93],[850,4.43]],"id":52671545}],"con":true,"img":false}]}
{"op":"mcm","clk":"11450032598","pt":1717317281409,"mc":[{"id":"1.229554898","rc":[{"atl":[[32,4.47]],"id":52671549},{"atl":[[60,3.09]],"id":52671542},{"atl":[[14,3.54]],"id":52671554}],"con":true,"img":false}]}
{"op":"mcm","clk":"11450032657","pt":1717317281981,"mc":[{"id":"1.229554898","rc":[{"atl":[[24,2.91]],"id":52671544},{"atl":[[48,3.41]],"id":52671555}],"con":true,"img":false}]}
{"op":"mcm","clk":"11450032665","pt":1717317282085,"mc":[{"id":"1.229554898","rc":[{"atb":[[4.5,0],[5.3,12.3]],"id":52671550},{"atb":[[16,4.68]],"id":52671546},{"atb":[[5.4,22.73]],"id":52671542}],"con":true,"img":false}]}
{"op":"mcm","clk":"11450032672","pt":1717317282189,"mc":[{"id":"1.229554898","rc":[{"atb":[[11.5,0]],"id":52671546},{"atb":[[6,0]],"id":52671542}],"con":true,"img":false}]}
{"op":"mcm","clk":"11450032683","pt":1717317282293,"mc":[{"id":"1.229554898","rc":[{"atl":[[65,0],[60,2]],"id":52671550}],"con":true,"img":false}]}
{"op":"mcm","clk":"11450032701","pt":1717317282499,"mc":[{"id":"1.229554898","rc":[{"atb":[[10,0]],"id":52671549},{"atl":[[32,0]],"id":52671549},{"atl":[[7.6,15.15],[6.8,4.65]],"id":52671548},{"atb":[[6.2,0],[5.9,0]],"id":52671542},{"atl":[[60,0]],"id":52671542},{"atb":[[10,11.11],[11,0]],"id":52671545},{"atl":[[830,0],[850,0]],"id":52671545},{"atb":[[6.2,0],[5.9,0]],"id":52671544},{"atl":[[14,0]],"id":52671554}],"con":true,"img":false}]}
{"op":"mcm","clk":"11450032717","pt":1717317282704,"mc":[{"id":"1.229554898","rc":[{"atl":[[65,2],[60,0]],"id":52671550}],"con":true,"img":false}]}
{"op":"mcm","clk":"11450032740","pt":1717317282908,"mc":[{"id":"1.229554898","rc":[{"atb":[[9.2,0],[10.5,0],[8.2,0],[13,0]],"id":52671544}],"con":true,"img":false}]}
{"op":"mcm","clk":"11450032753","pt":1717317283009,"mc":[{"id":"1.229554898","rc":[{"atb":[[1.15,0],[1.14,672.66]],"id":52671548},{"atl":[[24,0]],"id":52671544},{"atl":[[48,7.04]],"id":52671555}],"con":true,"img":false}]}
{"op":"mcm","clk":"11450032805","pt":1717317283380,"mc":[{"id":"1.229554898","rc":[{"atl":[[9.2,19.58],[9.4,11.9]],"id":52671554}],"con":true,"img":false}]}
{"op":"mcm","clk":"11450032829","pt":1717317283586,"mc":[{"id":"1.229554898","rc":[{"atb":[[9.2,9.57],[10.5,5.51],[8.2,14.53],[13,2.18]],"id":52671544}],"con":true,"img":false}]}
{"op":"mcm","clk":"11450032854","pt":1717317283790,"mc":[{"id":"1.229554898","rc":[{"atl":[[32,4.47]],"id":52671549},{"atl":[[60,4.56]],"id":52671542},{"atl":[[830,3.7],[850,3.86]],"id":52671545},{"atl":[[24,3.51]],"id":52671544},{"atl":[[48,3.41]],"id":52671555},{"atl":[[14,4.27]],"id":52671554}],"con":true,"img":false}]}
{"op":"mcm","clk":"11450032889","pt":1717317284102,"mc":[{"id":"1.229554898","rc":[{"atl":[[280,2],[400,0]],"id":52671545}],"con":true,"img":false}]}
{"op":"mcm","clk":"11450032906","pt":1717317284306,"mc":[{"id":"1.229554898","rc":[{"atl":[[23,5.01],[24,0]],"id":52671555}],"con":true,"img":false}]}
{"op":"mcm","clk":"11450033033","pt":1717317285735,"mc":[{"id":"1.229554898","rc":[{"atb":[[17,0],[12,0],[9.8,0],[14.5,0]],"id":52671550}],"con":true,"img":false}]}
{"op":"mcm","clk":"11450033096","pt":1717317286375,"mc":[{"id":"1.229554898","rc":[{"atb":[[16.5,1.69],[9.6,12.17],[11.5,12.49],[14,4.02]],"id":52671550}],"con":true,"img":false}]}
{"op":"mcm","clk":"11450033107","pt":1717317286483,"mc":[{"id":"1.229554898","rc":[{"atl":[[65,0],[60,2]],"id":52671550}],"con":true,"img":false}]}
{"op":"mcm","clk":"11450033138","pt":1717317286791,"mc":[{"id":"1.229554898","rc":[{"atb":[[1.14,560.55]],"id":52671548}],"con":true,"img":false}]}
{"op":"mcm","clk":"11450033204","pt":1717317287405,"mc":[{"id":"1.229554898","rc":[{"atb":[[1.66,35.31]],"id":52671548},{"atl":[[23,12.31]],"id":52671555}],"con":true,"img":false}]}
{"op":"mcm","clk":"11450033286","pt":1717317288186,"mc":[{"id":"1.229554898","rc":[{"atb":[[1.27,367]],"id":52671548},{"atl":[[48,0]],"id":52671555}],"con":true,"img":false}]}
{"op":"mcm","clk":"11450033310","pt":1717317288388,"mc":[{"id":"1.229554898","rc":[{"atb":[[1.12,130.79],[1.66,30.3]],"id":52671548},{"atl":[[790,3.74],[830,0]],"id":52671545}],"con":true,"img":false}]}
{"op":"mcm","clk":"11450033324","pt":1717317288495,"mc":[{"id":"1.229554898","rc":[{"atl":[[32,0],[30,4.01]],"id":52671549},{"atb":[[1.67,5.01]],"id":52671548},{"atl":[[55,3.45],[60,0]],"id":52671542}],"con":true,"img":false}]}
{"op":"mcm","clk":"11450033418","pt":1717317289420,"mc":[{"id":"1.229554898","rc":[{"atb":[[9.2,0],[10.5,0],[8.2,0],[13,0]],"id":52671544}],"con":true,"img":false}]}
{"op":"mcm","clk":"11450033431","pt":1717317289522,"mc":[{"id":"1.229554898","rc":[{"atb":[[1.67,0],[1.66,35.31]],"id":52671548}],"con":true,"img":false}]}
{"op":"mcm","clk":"11450033447","pt":1717317289686,"mc":[{"id":"1.229554898","rc":[{"atl":[[20,13.46]],"id":52671544},{"atl":[[29,3.57],[30,0]],"id":52671555}],"con":true,"img":false}]}
{"op":"mcm","clk":"11450033498","pt":1717317290198,"mc":[{"id":"1.229554898","rc":[{"atb":[[8,14.95],[9,9.81],[10,5.81],[12.5,2.28]],"id":52671544}],"con":true,"img":false}]}
{"op":"mcm","clk":"11450033509","pt":1717317290302,"mc":[{"id":"1.229554898","rc":[{"atl":[[32,4.67],[30,0]],"id":52671549},{"atl":[[770,3.87]],"id":52671545},{"atl":[[48,4.43]],"id":52671555}],"con":true,"img":false}]}
{"op":"mcm","clk":"11450033520","pt":1717317290409,"mc":[{"id":"1.229554898","rc":[{"atl":[[790,0]],"id":52671545},{"atl":[[23,0]],"id":52671544},{"atl":[[13.5,2.96],[14,0]],"id":52671554}],"con":true,"img":false}]}
{"op":"mcm","clk":"11450033617","pt":1717317291387,"mc":[{"id":"1.229554898","rc":[{"atl":[[8.4,26.71]],"id":52671554}],"con":true,"img":false}]}
{"op":"mcm","clk":"11450033693","pt":1717317292211,"mc":[{"id":"1.229554898","rc":[{"atl":[[9.2,0]],"id":52671554}],"con":true,"img":false}]}
{"op":"mcm","clk":"11450033856","pt":1717317293920,"mc":[{"id":"1.229554898","rc":[{"atl":[[55,9.98],[60,0]],"id":52671550},{"atl":[[280,0],[370,2]],"id":52671545}],"con":true,"img":false}]}
{"op":"mcm","clk":"11450033943","pt":1717317294804,"mc":[{"id":"1.229554898","rc":[{"atl":[[27,3.85],[29,0]],"id":52671555}],"con":true,"img":false}]}
{"op":"mcm","clk":"11450033995","pt":1717317295416,"mc":[{"id":"1.229554898","rc":[{"atl":[[110,4.01],[120,0]],"id":52671550},{"atl":[[32,0]],"id":52671549},{"atl":[[55,0]],"id":52671542},{"atb":[[50,0],[55,7.98]],"id":52671545},{"atl":[[770,0],[850,0]],"id":52671545},{"atb":[[6,0],[5.9,15.85]],"id":52671555},{"atl":[[46,2.87],[48,0]],"id":52671555},{"atl":[[13.5,0]],"id":52671554}],"con":true,"img":false}]}
{"op":"mcm","clk":"11450034003","pt":1717317295520,"mc":[{"id":"1.229554898","rc":[{"atl":[[24,0]],"id":52671544}],"con":true,"img":false}]}
{"op":"mcm","clk":"11450034022","pt":1717317295725,"mc":[{"id":"1.229554898","rc":[{"atl":[[7.2,3.14]],"id":52671548},{"atl":[[75,2.62]],"id":52671542}],"con":true,"img":false}]}
{"op":"mcm","clk":"11450034213","pt":1717317297487,"mc":[{"id":"1.229554898","rc":[{"atb":[[9.2,3.36]],"id":52671549},{"atl":[[40,4.51]],"id":52671549}],"con":true,"img":false}]}
{"op":"mcm","clk":"11450034227","pt":1717317297597,"mc":[{"id":"1.229554898","rc":[{"atl":[[16.5,2.65]],"id":52671554}],"con":true,"img":false}]}
{"op":"mcm","clk":"11450034352","pt":1717317298726,"mc":[{"id":"1.229554898","rc":[{"atl":[[55,7.98],[60,2]],"id":52671550},{"atl":[[27,0],[29,3.57]],"id":52671555}],"con":true,"img":false}]}
{"op":"mcm","clk":"11450034384","pt":1717317298989,"mc":[{"id":"1.229554898","rc":[{"atl":[[8,0]],"id":52671548}],"con":true,"img":false}]}
{"op":"mcm","clk":"11450034421","pt":1717317299302,"mc":[{"id":"1.229554898","rc":[{"atl":[[110,0],[120,4.46]],"id":52671550},{"atl":[[32,3.19],[36,0]],"id":52671549},{"atb":[[1.12,0],[1.13,120.73]],"id":52671548},{"atl":[[65,0],[55,4.15]],"id":52671542},{"atl":[[770,4.13],[790,2.94]],"id":52671545},{"atl":[[24,3.97]],"id":52671544},{"atl":[[46,0],[48,3.21]],"id":52671555},{"atl":[[13.5,4.08],[15.5,0]],"id":52671554}],"con":true,"img":false}]}
{"op":"mcm","clk":"11450034647","pt":1717317301324,"mc":[{"id":"1.229554898","rc":[{"atl":[[110,3.34],[120,0]],"id":52671550},{"atl":[[32,0],[36,3.32]],"id":52671549},{"atb":[[1.14,672.66],[1.13,0]],"id":52671548},{"atl":[[65,3.62],[55,0]],"id":52671542},{"atl":[[770,0],[790,0]],"id":52671545},{"atl":[[24,0]],"id":52671544},{"atl":[[46,4.05],[48,0]],"id":52671555},{"atl":[[13.5,0],[15.5,3.06]],"id":52671554}],"con":true,"img":false}]}
{"op":"mcm","clk":"11450034930","pt":1717317303729,"mc":[{"id":"1.229554898","rc":[{"atl":[[110,0],[120,4.35]],"id":52671550},{"atb":[[1.64,5.01],[1.66,0]],"id":52671548},{"atb":[[21,10.65],[23,5.01]],"id":52671542},{"atl":[[170,0],[190,5.01]],"id":52671545},{"atb":[[10.5,5.01],[9.8,11.81]],"id":52671544},{"atl":[[46,0],[48,2.99]],"id":52671555}],"con":true,"img":false}]}
{"op":"mcm","clk":"11450034939","pt":1717317303834,"mc":[{"id":"1.229554898","rc":[{"atl":[[28,3.7]],"id":52671555}],"con":true,"img":false}]}
{"op":"mcm","clk":"11450034950","pt":1717317303934,"mc":[{"id":"1.229554898","rc":[{"atl":[[29,0]],"id":52671555}],"con":true,"img":false}]}
{"op":"mcm","clk":"11450034974","pt":1717317304099,"mc":[{"id":"1.229554898","rc":[{"atl":[[55,9.98],[60,0]],"id":52671550}],"con":true,"img":false}]}
{"op":"mcm","clk":"11450035007","pt":1717317304410,"mc":[{"id":"1.229554898","rc":[{"atb":[[1.64,0],[1.27,382.11],[1.63,5.01],[1.14,560.55]],"id":52671548},{"atl":[[360,0.44]],"id":52671545}],"con":true,"img":false}]}
{"op":"mcm","clk":"11450035152","pt":1717317305719,"mc":[{"id":"1.229554898","rc":[{"atb":[[18,0],[13,0]],"id":52671550},{"atl":[[100,3.5],[120,0]],"id":52671550},{"atb":[[550,0],[650,0]],"id":52671546},{"atb":[[5.6,21.74],[7.2,0]],"id":52671549},{"atl":[[34,4.63],[36,0]],"id":52671549},{"atb":[[1.01,0],[1.04,0]],"id":52671548},{"atb":[[7.4,0],[9.4,0]],"id":52671542},{"atl":[[65,0],[60,3.69]],"id":52671542},{"atb":[[32,0],[21,0]],"id":52671545},{"atl":[[190,0],[200,5.01]],"id":52671545},{"atb":[[4.8,26.32],[5.8,0]],"id":52671544},{"atb":[[9,0],[12.5,0]],"id":52671555},{"atl":[[46,4.12],[48,0]],"id":52671555},{"atb":[[3.7,0],[4.4,2.79]],"id":52671554},{"atb":[[340,0],[440,0]],"id":52671556}],"con":true,"img":false}]}
{"op":"mcm","clk":"11450035175","pt":1717317305929,"mc":[{"id":"1.229554898","rc":[{"atl":[[38,0],[50,2.04]],"id":52671544},{"atl":[[11.5,9.52],[9.4,0]],"id":52671554}],"con":true,"img":false}]}
{"op":"mcm","clk":"11450035215","pt":1717317306242,"mc":[{"id":"1.229554898","rc":[{"atb":[[4.6,3.01],[6.2,3.53]],"id":52671550},{"atb":[[1.13,120.73]],"id":52671548},{"atb":[[5.6,2.76],[5.4,25.35]],"id":52671542},{"atb":[[34,0],[85,0],[44,0],[60,0]],"id":52671545},{"atb":[[4.6,0],[5.7,2.91]],"id":52671555},{"atb":[[11,0],[14.5,3.59]],"id":52671556}],"con":true,"img":false}]}
{"op":"mcm","clk":"11450035226","pt":1717317306298,"mc":[{"id":"1.229554898","rc":[{"atl":[[29,2.73]],"id":52671544}],"con":true,"img":false}]}
{"op":"mcm","clk":"11450035300","pt":1717317306924,"mc":[{"id":"1.229554898","rc":[{"atb":[[65,0.82],[36,2.99],[90,0.29],[46,1.74]],"id":52671545}],"con":true,"img":false}]}
{"op":"mcm","clk":"11450035424","pt":1717317308114,"mc":[{"id":"1.229554898","rc":[{"atl":[[190,5.01],[200,0]],"id":52671545}],"con":true,"img":false}]}
{"op":"mcm","clk":"11450035789","pt":1717317311537,"mc":[{"id":"1.229554898","rc":[{"atb":[[4.8,0],[5.3,23.26]],"id":52671544}],"con":true,"img":false}]}
{"op":"mcm","clk":"11450035811","pt":1717317311699,"mc":[{"id":"1.229554898","rc":[{"atb":[[1.63,0],[1.62,5.01]],"id":52671548},{"atl":[[190,0],[210,5.01]],"id":52671545}],"con":true,"img":false}]}
{"op":"mcm","clk":"11450035823","pt":1717317311799,"mc":[{"id":"1.229554898","rc":[{"atb":[[55,0],[60,5.01]],"id":52671546}],"con":true,"img":false}]}
{"op":"mcm","clk":"11450035979","pt":1717317313166,"mc":[{"id":"1.229554898","rc":[{"atb":[[5.9,2.73]],"id":52671550},{"atl":[[120,3.39]],"id":52671550},{"atb":[[5.5,2.73]],"id":52671555},{"atb":[[13.5,3.85]],"id":52671556}],"con":true,"img":false}]}
{"op":"mcm","clk":"11450036090","pt":1717317314104,"mc":[{"id":"1.229554898","rc":[{"atl":[[8.2,5.01],[8.4,21.7]],"id":52671554}],"con":true,"img":false}]}
{"op":"mcm","clk":"11450036126","pt":1717317314512,"mc":[{"id":"1.229554898","rc":[{"atl":[[8.2,26.9]],"id":52671554}],"con":true,"img":false}]}
{"op":"mcm","clk":"11450036204","pt":1717317315235,"mc":[{"id":"1.229554898","rc":[{"atl":[[350,0.46]],"id":52671545}],"con":true,"img":false}]}
{"op":"mcm","clk":"11450036221","pt":1717317315338,"mc":[{"id":"1.229554898","rc":[{"atl":[[8.4,0]],"id":52671554}],"con":true,"img":false}]}
{"op":"mcm","clk":"11450036280","pt":1717317315912,"mc":[{"id":"1.229554898","rc":[{"atl":[[360,0]],"id":52671545}],"con":true,"img":false}]}
{"op":"mcm","clk":"11450036335","pt":1717317316425,"mc":[{"id":"1.229554898","rc":[{"atl":[[55,7.98],[60,2]],"id":52671550}],"con":true,"img":false}]}
{"op":"mcm","clk":"11450036368","pt":1717317316735,"mc":[{"id":"1.229554898","rc":[{"atb":[[4.4,0]],"id":52671550},{"atl":[[140,0],[100,0],[110,3.87],[120,0]],"id":52671550},{"atb":[[1.11,0],[1.13,0]],"id":52671548},{"atb":[[18,0],[21,8.03],[26,0],[15.5,0]],"id":52671542},{"atb":[[4.4,0]],"id":52671555},{"atl":[[16,3.15],[15.5,0]],"id":52671554},{"atb":[[10,0]],"id":52671556}],"con":true,"img":false}]}
{"op":"mcm","clk":"11450036415","pt":1717317317147,"mc":[{"id":"1.229554898","rc":[{"atb":[[1.62,35.31]],"id":52671548}],"con":true,"img":false}]}
{"op":"mcm","clk":"11450036432","pt":1717317317251,"mc":[{"id":"1.229554898","rc":[{"atb":[[23,12.31]],"id":52671542}],"con":true,"img":false}]}
{"op":"mcm","clk":"11450036453","pt":1717317317409,"mc":[{"id":"1.229554898","rc":[{"atb":[[17,6.54],[19.5,4.24],[24,2.28],[29,0.94]],"id":52671542}],"con":true,"img":false}]}
{"op":"mcm","clk":"11450036482","pt":1717317317624,"mc":[{"id":"1.229554898","rc":[{"atb":[[18.5,5.97],[13.5,19.51]],"id":52671550},{"atb":[[550,0.44],[650,0.16]],"id":52671546},{"atb":[[8,14.93],[6,48.78]],"id":52671549},{"atl":[[32,3.03],[34,0]],"id":52671549},{"atb":[[1.01,34843.57]],"id":52671548},{"atb":[[8.6,32.09],[11.5,9.95]],"id":52671542},{"atl":[[55,2.83],[60,0]],"id":52671542},{"atb":[[95,1.11],[48,5.18]],"id":52671545},{"atl":[[840,3.89],[860,4.66]],"id":52671545},{"atb":[[5.6,53.02],[7.2,16.86]],"id":52671544},{"atl":[[24,2.92],[27,0]],"id":52671544},{"atb":[[13.5,8.36],[9.4,29.03]],"id":52671555},{"atl":[[46,0],[48,2.71]],"id":52671555},{"atb":[[3.95,82.67],[4.9,26.8]],"id":52671554},{"atl":[[16,0],[14,3.45]],"id":52671554},{"atb":[[550,0.44],[650,0.16]],"id":52671556}],"con":true,"img":false}]}
{"op":"mcm","clk":"11450036503","pt":1717317317831,"mc":[{"id":"1.229554898","rc":[{"atb":[[1.27,367]],"id":52671548}],"con":true,"img":false}]}
{"op":"mcm","clk":"11450036516","pt":1717317317931,"mc":[{"id":"1.229554898","rc":[{"atb":[[21,0]],"id":52671542},{"atl":[[36,0]],"id":52671542}],"con":true,"img":false}]}
{"op":"mcm","clk":"11450036596","pt":1717317318608,"mc":[{"id":"1.229554898","rc":[{"atl":[[50,3.27]],"id":52671542}],"con":true,"img":false}]}
{"op":"mcm","clk":"11450036770","pt":1717317320215,"mc":[{"id":"1.229554898","rc":[{"atl":[[130,0],[100,2]],"id":52671542},{"atl":[[290,2],[370,0]],"id":52671545},{"atl":[[40,2.56],[50,0]],"id":52671544},{"atl":[[11.5,0],[9.4,11.9]],"id":52671554}],"con":true,"img":false}]}
{"op":"mcm","clk":"11450036825","pt":1717317320732,"mc":[{"id":"1.229554898","rc":[{"atl":[[28,0],[29,3.57]],"id":52671555}],"con":true,"img":false}]}
{"op":"mcm","clk":"11450036857","pt":1717317321042,"mc":[{"id":"1.229554898","rc":[{"atb":[[1.11,130.79],[1.09,1293.41]],"id":52671548}],"con":true,"img":false}]}
{"op":"mcm","clk":"11450037098","pt":1717317323120,"mc":[{"id":"1.229554898","rc":[{"atb":[[17,0]],"id":52671542}],"con":true,"img":false}]}
{"op":"mcm","clk":"11450037110","pt":1717317323224,"mc":[{"id":"1.229554898","rc":[{"atb":[[19.5,0],[24,0],[29,0]],"id":52671542}],"con":true,"img":false}]}
{"op":"mcm","clk":"11450037147","pt":1717317323530,"mc":[{"id":"1.229554898","rc":[{"atl":[[130,3.21]],"id":52671550}],"con":true,"img":false}]}
{"op":"mcm","clk":"11450037165","pt":1717317323738,"mc":[{"id":"1.229554898","rc":[{"atb":[[65,0],[36,0],[90,0],[46,0]],"id":52671546}],"con":true,"img":false}]}
{"op":"mcm","clk":"11450037176","pt":1717317323839,"mc":[{"id":"1.229554898","rc":[{"atb":[[15,7.48]],"id":52671542}],"con":true,"img":false}]}
{"op":"mcm","clk":"11450037187","pt":1717317323944,"mc":[{"id":"1.229554898","rc":[{"atb":[[17.5,4.76],[20,2.75],[25,1.09]],"id":52671542}],"con":true,"img":false}]}
{"op":"mcm","clk":"11450037230","pt":1717317324358,"mc":[{"id":"1.229554898","rc":[{"atl":[[36,3.37]],"id":52671549},{"atl":[[65,4.68]],"id":52671542},{"atl":[[26,4.28]],"id":52671544},{"atl":[[15,3.37]],"id":52671554}],"con":true,"img":false}]}
{"op":"mcm","clk":"11450037237","pt":1717317324413,"mc":[{"id":"1.229554898","rc":[{"atb":[[70,0.76],[95,0.28]],"id":52671546}],"con":true,"img":false}]}
{"op":"mcm","clk":"11450037248","pt":1717317324512,"mc":[{"id":"1.229554898","rc":[{"atb":[[38,2.83],[48,1.67]],"id":52671546}],"con":true,"img":false}]}
{"op":"mcm","clk":"11450037385","pt":1717317325852,"mc":[{"id":"1.229554898","rc":[{"atl":[[210,5.78]],"id":52671545}],"con":true,"img":false}]}
{"op":"mcm","clk":"11450037466","pt":1717317326529,"mc":[{"id":"1.229554898","rc":[{"atl":[[350,0]],"id":52671545}],"con":true,"img":false}]}
{"op":"mcm","clk":"11450037641","pt":1717317328235,"mc":[{"id":"1.229554898","rc":[{"atl":[[2.86,0],[2.84,5.01]],"id":52671548}],"con":true,"img":false}]}
{"op":"mcm","clk":"11450037652","pt":1717317328341,"mc":[{"id":"1.229554898","rc":[{"atl":[[40,0]],"id":52671549},{"atl":[[75,0]],"id":52671542},{"atl":[[29,0]],"id":52671544},{"atl":[[16.5,0]],"id":52671554}],"con":true,"img":false}]}
{"op":"mcm","clk":"11450037763","pt":1717317329526,"mc":[{"id":"1.229554898","rc":[{"atl":[[42,8.93]],"id":52671542}],"con":true,"img":false}]}
{"op":"mcm","clk":"11450037849","pt":1717317330254,"mc":[{"id":"1.229554898","rc":[{"atl":[[50,0]],"id":52671542}],"con":true,"img":false}]}
{"op":"mcm","clk":"11450038194","pt":1717317333059,"mc":[{"id":"1.229554898","rc":[{"atl":[[22,5.01],[23,7.29]],"id":52671555}],"con":true,"img":false}]}
{"op":"mcm","clk":"11450038238","pt":1717317333419,"mc":[{"id":"1.229554898","rc":[{"atl":[[22,12.66]],"id":52671555}],"con":true,"img":false}]}
{"op":"mcm","clk":"11450038360","pt":1717317334562,"mc":[{"id":"1.229554898","rc":[{"atl":[[23,0]],"id":52671555}],"con":true,"img":false}]}
{"op":"mcm","clk":"11450038459","pt":1717317335544,"mc":[{"id":"1.229554898","rc":[{"atl":[[9,12.5],[9.4,0]],"id":52671554}],"con":true,"img":false}]}
{"op":"mcm","clk":"11450038492","pt":1717317335865,"mc":[{"id":"1.229554898","rc":[{"atb":[[70,0],[38,0],[95,0],[48,0],[60,0]],"id":52671546},{"atl":[[42,3.91],[46,5.01]],"id":52671542},{"atb":[[5.5,0],[5.7,5.01],[5.9,10.84]],"id":52671555},{"atb":[[5.2,5.01],[5.4,25.92]],"id":52671554},{"atb":[[32,0],[18,0],[21,0],[26,0]],"id":52671556}],"con":true,"img":false}]}
{"op":"mcm","clk":"11450038527","pt":1717317336155,"mc":[{"id":"1.229554898","rc":[{"atb":[[25,7.78]],"id":52671542}],"con":true,"img":false}]}
{"op":"mcm","clk":"11450038536","pt":1717317336253,"mc":[{"id":"1.229554898","rc":[{"atl":[[55,0],[60,7.01]],"id":52671550},{"atl":[[18,0],[19.5,5.01]],"id":52671549},{"atb":[[10,10.83],[10.5,0]],"id":52671544}],"con":true,"img":false}]}
{"op":"mcm","clk":"11450038544","pt":1717317336356,"mc":[{"id":"1.229554898","rc":[{"atb":[[55,5.01]],"id":52671546}],"con":true,"img":false}]}
{"op":"mcm","clk":"11450038560","pt":1717317336535,"mc":[{"id":"1.229554898","rc":[{"atb":[[65,0.82],[36,2.99],[90,0.29],[46,1.74]],"id":52671546}],"con":true,"img":false}]}
{"op":"mcm","clk":"11450038572","pt":1717317336627,"mc":[{"id":"1.229554898","rc":[{"atb":[[17.5,6.34],[20,4.13],[25,2.18],[30,0.9]],"id":52671556}],"con":true,"img":false}]}
{"op":"mcm","clk":"11450038597","pt":1717317336826,"mc":[{"id":"1.229554898","rc":[{"atb":[[23,5.01]],"id":52671542}],"con":true,"img":false}]}
{"op":"mcm","clk":"11450038611","pt":1717317336933,"mc":[{"id":"1.229554898","rc":[{"atl":[[28,5.94]],"id":52671549}],"con":true,"img":false}]}
{"op":"mcm","clk":"11450038622","pt":1717317337036,"mc":[{"id":"1.229554898","rc":[{"atl":[[100,1.62]],"id":52671550},{"atb":[[1.72,5.01],[1.62,30.3]],"id":52671548},{"atb":[[65,0],[36,0],[90,0],[46,0]],"id":52671545},{"atb":[[5.3,5.01],[5.2,0]],"id":52671554}],"con":true,"img":false}]}
{"op":"mcm","clk":"11450038660","pt":1717317337446,"mc":[{"id":"1.229554898","rc":[{"atb":[[1.72,35.31]],"id":52671548}],"con":true,"img":false}]}
{"op":"mcm","clk":"11450038696","pt":1717317337763,"mc":[{"id":"1.229554898","rc":[{"atb":[[34,3.17],[85,0.31],[44,1.83],[60,0.88]],"id":52671545}],"con":true,"img":false}]}
{"op":"mcm","clk":"11450038760","pt":1717317338232,"mc":[{"id":"1.229554898","rc":[{"atb":[[1.62,0]],"id":52671548}],"con":true,"img":false}]}
{"op":"mcm","clk":"11450039059","pt":1717317341122,"mc":[{"id":"1.229554898","rc":[{"atl":[[290,0],[370,2]],"id":52671545},{"atl":[[27,3.85],[29,0]],"id":52671555},{"atl":[[9.4,11.9]],"id":52671554}],"con":true,"img":false}]}
{"op":"mcm","clk":"11450039070","pt":1717317341225,"mc":[{"id":"1.229554898","rc":[{"atl":[[280,2],[370,0]],"id":52671545},{"atl":[[9,0]],"id":52671554}],"con":true,"img":false}]}
{"op":"mcm","clk":"11450039100","pt":1717317341537,"mc":[{"id":"1.229554898","rc":[{"atl":[[32,0]],"id":52671549},{"atl":[[55,0],[60,4.26]],"id":52671542},{"atl":[[840,0],[860,0]],"id":52671545},{"atl":[[24,0],[27,4.67]],"id":52671544},{"atl":[[46,4.44],[48,0]],"id":52671555},{"atl":[[14,0],[15.5,3.28]],"id":52671554}],"con":true,"img":false}]}
{"op":"mcm","clk":"11450039138","pt":1717317341846,"mc":[{"id":"1.229554898","rc":[{"atl":[[280,0],[370,2]],"id":52671545}],"con":true,"img":false}]}
