{"op":"mcm","clk":"10115380948","pt":1700861781567,"mc":[{"id":"1.221675352","marketDefinition":{"bspMarket":true,"turnInPlayEnabled":false,"persistenceEnabled":false,"marketBaseRate":7.0,"eventId":"32826103","eventTypeId":"4339","numberOfWinners":1,"bettingType":"ODDS","marketType":"WIN","marketTime":"2023-11-25T09:20:00.000Z","suspendTime":"2023-11-25T09:20:00.000Z","bspReconciled":false,"complete":true,"inPlay":false,"crossMatching":true,"runnersVoidable":false,"numberOfActiveRunners":8,"betDelay":0,"status":"OPEN","runners":[{"status":"ACTIVE","sortPriority":1,"id":54974498,"name":"1. Make No Promise"},{"status":"ACTIVE","sortPriority":2,"id":41132607,"name":"2. Wow Shes Fast"},{"status":"ACTIVE","sortPriority":3,"id":49487602,"name":"3. Andre Bale"},{"status":"ACTIVE","sortPriority":4,"id":51178794,"name":"4. Crackerjack Bull"},{"status":"ACTIVE","sortPriority":5,"id":51229677,"name":"5. Navarino"},{"status":"ACTIVE","sortPriority":6,"id":52386044,"name":"6. Saige Tenniele"},{"status":"ACTIVE","sortPriority":7,"id":61861979,"name":"7. Peaky Joe"},{"status":"ACTIVE","sortPriority":8,"id":50758683,"name":"8. Boomburst"}],"regulators":["MR_INT"],"venue":"Sandown Park","countryCode":"AU","discountAllowed":true,"timezone":"Australia/Sydney","openDate":"2023-11-25T07:34:00.000Z","version":5600960401,"name":"R6 515m Heat","eventName":"Sandown Park (AUS) 25th Nov"},"rc":[],"con":true,"img":false}]}
{"op":"mcm","clk":"10115423936","pt":1700862168294,"mc":[{"id":"1.221675352","rc":[{"atb":[[2,104.31],[1.9,231.8],[1.95,219.6]],"id":41132607},{"atl":[[6.2,26.77],[8.2,29]],"id":41132607},{"spn":4.1,"spf":"NaN","id":41132607},{"atb":[[4,69.54],[4.5,59.6],[5,26.07]],"id":51178794},{"atl":[[38,5.64],[24,6.05]],"id":51178794},{"spn":14.5,"spf":"NaN","id":51178794},{"atb":[[9.2,25.44],[10.5,10.97],[8.2,28.97]],"id":61861979},{"atl":[[260,0.8],[160,0.87]],"id":61861979},{"spn":85.25,"spf":"NaN","id":61861979},{"atb":[[3.1,99.34],[3.35,44.38],[2.94,107.53]],"id":54974498},{"atl":[[17,13.04],[12,12.65]],"id":54974498},{"spn":7.67,"spf":"NaN","id":54974498},{"atb":[[16.5,6.73],[11.5,19.86],[14,16.04]],"id":50758683},{"atl":[[340,0.61],[240,0.58]],"id":50758683},{"spn":128.25,"spf":"NaN","id":50758683},{"atb":[[8,14.89],[6,41.72],[7,34.76]],"id":51229677},{"atl":[[75,1.88],[150,1.4]],"id":51229677},{"spn":41.5,"spf":"NaN","id":51229677},{"atb":[[9,26.07],[10,23.18],[12.5,9.07]],"id":52386044},{"atl":[[300,0.7],[200,0.7]],"id":52386044},{"spn":106.25,"spf":"NaN","id":52386044},{"atb":[[8,14.89],[6,41.72],[7,34.76]],"id":49487602},{"atl":[[75,1.88],[150,1.4]],"id":49487602},{"spn":41.5,"spf":"NaN","id":49487602}],"con":true,"img":false}]}
{"op":"mcm","clk":"10115427129","pt":1700862203017,"mc":[{"id":"1.221675352","rc":[{"atb":[[2,0],[1.9,0],[1.95,0]],"id":41132607},{"atl":[[6.2,0],[8.2,0]],"id":41132607},{"atb":[[4,0],[4.5,0],[5,0]],"id":51178794},{"atl":[[38,0],[24,0]],"id":51178794},{"atb":[[9.2,0],[10.5,0],[8.2,0]],"id":61861979},{"atl":[[260,0],[160,0]],"id":61861979},{"atb":[[3.1,0],[3.35,0],[2.94,0]],"id":54974498},{"atl":[[17,0],[12,0]],"id":54974498},{"atb":[[16.5,0],[11.5,0],[14,0]],"id":50758683},{"atl":[[340,0],[240,0]],"id":50758683},{"atb":[[8,0],[6,0],[7,0]],"id":51229677},{"atl":[[75,0],[150,0]],"id":51229677},{"atb":[[9,0],[10,0],[12.5,0]],"id":52386044},{"atl":[[300,0],[200,0]],"id":52386044},{"atb":[[8,0],[6,0],[7,0]],"id":49487602},{"atl":[[75,0],[150,0]],"id":49487602}],"con":true,"img":false}]}
{"op":"mcm","clk":"10115427769","pt":1700862209858,"mc":[{"id":"1.221675352","rc":[{"atb":[[2,104.31],[1.9,231.8],[1.95,219.6]],"id":41132607},{"atl":[[6.2,26.77],[8.2,29]],"id":41132607},{"atb":[[4,69.54],[4.5,59.6],[5,26.07]],"id":51178794},{"atl":[[38,5.64],[24,6.05]],"id":51178794},{"atb":[[9.2,25.44],[10.5,10.97],[8.2,28.97]],"id":61861979},{"atl":[[260,0.8],[160,0.87]],"id":61861979},{"atb":[[3.1,99.34],[3.35,44.38],[2.94,107.53]],"id":54974498},{"atl":[[17,13.04],[12,12.65]],"id":54974498},{"atb":[[16.5,6.73],[11.5,19.86],[14,16.04]],"id":50758683},{"atl":[[340,0.61],[240,0.58]],"id":50758683},{"atb":[[8,14.89],[6,41.72],[7,34.76]],"id":51229677},{"atl":[[75,1.88],[150,1.4]],"id":51229677},{"atb":[[9,26.07],[10,23.18],[12.5,9.07]],"id":52386044},{"atl":[[300,0.7],[200,0.7]],"id":52386044},{"atb":[[8,14.89],[6,41.72],[7,34.76]],"id":49487602},{"atl":[[75,1.88],[150,1.4]],"id":49487602}],"con":true,"img":false}]}
{"op":"mcm","clk":"10115438181","pt":1700862325349,"mc":[{"id":"1.221675352","rc":[{"atb":[[4,0],[4.5,0],[5,0]],"id":51178794},{"atl":[[38,0],[24,0]],"id":51178794},{"spn":"NaN","spf":"NaN","id":51178794},{"atb":[[16.5,0],[11.5,0],[14,0]],"id":50758683},{"atl":[[340,0],[240,0]],"id":50758683},{"spn":"NaN","spf":"NaN","id":50758683},{"atb":[[8,0],[6,0],[7,0]],"id":51229677},{"atl":[[75,0],[150,0]],"id":51229677},{"spn":"NaN","spf":"NaN","id":51229677},{"atb":[[9,0],[10,0],[12.5,0]],"id":52386044},{"atl":[[300,0],[200,0]],"id":52386044},{"spn":"NaN","spf":"NaN","id":52386044}],"con":true,"img":false}]}
{"op":"mcm","clk":"10115438494","pt":1700862328973,"mc":[{"id":"1.221675352","rc":[{"atb":[[4,69.54],[4.5,59.6],[5,26.07]],"id":51178794},{"atl":[[38,5.64],[24,6.05]],"id":51178794},{"atb":[[16.5,6.73],[11.5,19.86],[14,16.04]],"id":50758683},{"atl":[[340,0.61],[240,0.58]],"id":50758683},{"atb":[[8,14.89],[6,41.72],[7,34.76]],"id":51229677},{"atl":[[75,1.88],[150,1.4]],"id":51229677},{"atb":[[9,26.07],[10,23.18],[12.5,9.07]],"id":52386044},{"atl":[[300,0.7],[200,0.7]],"id":52386044}],"con":true,"img":false}]}
{"op":"mcm","clk":"10115455487","pt":1700862422898,"mc":[{"id":"1.221675352","marketDefinition":{"bspMarket":true,"turnInPlayEnabled":false,"persistenceEnabled":false,"marketBaseRate":7.0,"eventId":"32826103","eventTypeId":"4339","numberOfWinners":1,"bettingType":"ODDS","marketType":"WIN","marketTime":"2023-11-25T09:20:00.000Z","suspendTime":"2023-11-25T09:20:00.000Z","bspReconciled":false,"complete":true,"inPlay":false,"crossMatching":true,"runnersVoidable":false,"numberOfActiveRunners":8,"betDelay":0,"status":"OPEN","runners":[{"status":"ACTIVE","sortPriority":1,"id":54974498,"name":"1. Make No Promise"},{"status":"ACTIVE","sortPriority":2,"id":41132607,"name":"2. Wow Shes Fast"},{"status":"ACTIVE","sortPriority":3,"id":49487602,"name":"3. Andre Bale"},{"status":"ACTIVE","sortPriority":4,"id":51178794,"name":"4. Crackerjack Bull"},{"status":"ACTIVE","sortPriority":5,"id":51229677,"name":"5. Navarino"},{"status":"ACTIVE","sortPriority":6,"id":52386044,"name":"6. Saige Tenniele"},{"status":"ACTIVE","sortPriority":7,"id":61861979,"name":"7. Peaky Joe"},{"status":"ACTIVE","sortPriority":8,"id":50758683,"name":"8. Boomburst"}],"regulators":["MR_INT"],"venue":"Sandown Park","countryCode":"AU","discountAllowed":true,"timezone":"Australia/Sydney","openDate":"2023-11-25T07:34:00.000Z","version":5600960401,"name":"R6 515m Heat","eventName":"Sandown Park (AUS) 25th Nov"},"rc":[{"atb":[[2,104.31],[1.9,231.8],[1.95,219.6]],"id":41132607},{"atl":[[6.2,26.77],[8.2,29]],"id":41132607},{"spn":4.1,"spf":"NaN","id":41132607},{"atb":[[4,69.54],[4.5,59.6],[5,26.07]],"id":51178794},{"atl":[[38,5.64],[24,6.05]],"id":51178794},{"spn":14.5,"spf":"NaN","id":51178794},{"atb":[[9.2,25.44],[10.5,10.97],[8.2,28.97]],"id":61861979},{"atl":[[260,0.8],[160,0.87]],"id":61861979},{"spn":85.25,"spf":"NaN","id":61861979},{"atb":[[3.1,99.34],[3.35,44.38],[2.94,107.53]],"id":54974498},{"atl":[[17,13.04],[12,12.65]],"id":54974498},{"spn":7.67,"spf":"NaN","id":54974498},{"atb":[[16.5,6.73],[11.5,19.86],[14,16.04]],"id":50758683},{"atl":[[340,0.61],[240,0.58]],"id":50758683},{"spn":128.25,"spf":"NaN","id":50758683},{"atb":[[8,14.89],[6,41.72],[7,34.76]],"id":51229677},{"atl":[[75,1.88],[150,1.4]],"id":51229677},{"spn":41.5,"spf":"NaN","id":51229677},{"atb":[[9,26.07],[10,23.18],[12.5,9.07]],"id":52386044},{"atl":[[300,0.7],[200,0.7]],"id":52386044},{"spn":106.25,"spf":"NaN","id":52386044},{"atb":[[8,14.89],[6,41.72],[7,34.76]],"id":49487602},{"atl":[[75,1.88],[150,1.4]],"id":49487602},{"spn":41.5,"spf":"NaN","id":49487602}],"con":true,"img":true}]}
{"op":"mcm","clk":"10115962308","pt":1700867822930,"mc":[{"id":"1.221675352","marketDefinition":{"bspMarket":true,"turnInPlayEnabled":false,"persistenceEnabled":false,"marketBaseRate":7.0,"eventId":"32826103","eventTypeId":"4339","numberOfWinners":1,"bettingType":"ODDS","marketType":"WIN","marketTime":"2023-11-25T09:20:00.000Z","suspendTime":"2023-11-25T09:20:00.000Z","bspReconciled":false,"complete":true,"inPlay":false,"crossMatching":true,"runnersVoidable":false,"numberOfActiveRunners":8,"betDelay":0,"status":"OPEN","runners":[{"status":"ACTIVE","sortPriority":1,"id":54974498,"name":"1. Make No Promise"},{"status":"ACTIVE","sortPriority":2,"id":41132607,"name":"2. Wow Shes Fast"},{"status":"ACTIVE","sortPriority":3,"id":49487602,"name":"3. Andre Bale"},{"status":"ACTIVE","sortPriority":4,"id":51178794,"name":"4. Crackerjack Bull"},{"status":"ACTIVE","sortPriority":5,"id":51229677,"name":"5. Navarino"},{"status":"ACTIVE","sortPriority":6,"id":52386044,"name":"6. Saige Tenniele"},{"status":"ACTIVE","sortPriority":7,"id":61861979,"name":"7. Peaky Joe"},{"status":"ACTIVE","sortPriority":8,"id":50758683,"name":"8. Boomburst"}],"regulators":["MR_INT"],"venue":"Sandown Park","countryCode":"AU","discountAllowed":true,"timezone":"Australia/Sydney","openDate":"2023-11-25T07:34:00.000Z","version":5600960401,"name":"R6 515m Heat","eventName":"Sandown Park (AUS) 25th Nov"},"rc":[{"atb":[[2,104.24],[1.9,231.66],[1.95,219.46]],"id":41132607},{"atl":[[6.2,26.75],[8.2,28.98]],"id":41132607},{"spn":4.1,"spf":"NaN","id":41132607},{"atb":[[4,69.49],[4.5,59.57],[5,26.06]],"id":51178794},{"atl":[[38,5.64],[24,6.04]],"id":51178794},{"spn":14.5,"spf":"NaN","id":51178794},{"atb":[[9.2,25.42],[10.5,10.97],[8.2,28.95]],"id":61861979},{"atl":[[260,0.8],[160,0.87]],"id":61861979},{"spn":85.25,"spf":"NaN","id":61861979},{"atb":[[3.1,99.28],[3.35,44.36],[2.94,107.46]],"id":54974498},{"atl":[[17,13.04],[12,12.64]],"id":54974498},{"spn":7.67,"spf":"NaN","id":54974498},{"atb":[[16.5,6.72],[11.5,19.85],[14,16.03]],"id":50758683},{"atl":[[340,0.61],[240,0.57]],"id":50758683},{"spn":128.25,"spf":"NaN","id":50758683},{"atb":[[8,14.89],[6,41.69],[7,34.74]],"id":51229677},{"atl":[[75,1.88],[150,1.39]],"id":51229677},{"spn":41.5,"spf":"NaN","id":51229677},{"atb":[[9,26.06],[10,23.16],[12.5,9.06]],"id":52386044},{"atl":[[300,0.69],[200,0.69]],"id":52386044},{"spn":106.25,"spf":"NaN","id":52386044},{"atb":[[8,14.89],[6,41.69],[7,34.74]],"id":49487602},{"atl":[[75,1.88],[150,1.39]],"id":49487602},{"spn":41.5,"spf":"NaN","id":49487602}],"con":true,"img":true}]}
{"op":"mcm","clk":"10116051547","pt":1700868749610,"mc":[{"id":"1.221675352","rc":[{"atb":[[2,0],[1.9,0],[1.95,0]],"id":41132607},{"atl":[[6.2,0],[8.2,0]],"id":41132607},{"spn":"NaN","spf":"NaN","id":41132607},{"atb":[[4,69.49],[4.5,59.57],[5,26.06]],"id":51178794},{"atl":[[38,5.64],[24,6.04]],"id":51178794},{"spn":14.5,"spf":"NaN","id":51178794},{"atb":[[9.2,0],[10.5,0],[8.2,0]],"id":61861979},{"atl":[[260,0],[160,0]],"id":61861979},{"spn":"NaN","spf":"NaN","id":61861979},{"atb":[[3.1,99.28],[3.35,44.36],[2.94,107.46]],"id":54974498},{"atl":[[17,13.04],[12,12.64]],"id":54974498},{"atb":[[16.5,0],[11.5,0],[14,0]],"id":50758683},{"atl":[[340,0],[240,0]],"id":50758683},{"atb":[[8,14.89],[6,41.69],[7,34.74]],"id":51229677},{"atl":[[75,1.88],[150,1.39]],"id":51229677},{"spn":41.5,"spf":"NaN","id":51229677},{"atb":[[9,26.06],[10,23.16],[12.5,9.06]],"id":52386044},{"atl":[[300,0.69],[200,0.69]],"id":52386044},{"spn":106.25,"spf":"NaN","id":52386044},{"atb":[[8,0],[6,0],[7,0]],"id":49487602},{"atl":[[75,0],[150,0]],"id":49487602},{"spn":"NaN","spf":"NaN","id":49487602}],"con":true,"img":false}]}
{"op":"mcm","clk":"10116054387","pt":1700868779042,"mc":[{"id":"1.221675352","rc":[{"atb":[[2,104.24],[1.9,231.66],[1.95,219.46]],"id":41132607},{"atl":[[6.2,26.75],[8.2,28.98]],"id":41132607},{"atb":[[9.2,25.42],[10.5,10.97],[8.2,28.95]],"id":61861979},{"atl":[[260,0.8],[160,0.87]],"id":61861979},{"atb":[[16.5,6.72],[11.5,19.85],[14,16.03]],"id":50758683},{"atl":[[340,0.61],[240,0.57]],"id":50758683},{"atb":[[8,14.89],[6,41.69],[7,34.74]],"id":49487602},{"atl":[[75,1.88],[150,1.39]],"id":49487602}],"con":true,"img":false}]}
{"op":"mcm","clk":"10116061532","pt":1700868856606,"mc":[{"id":"1.221675352","rc":[{"spn":4.1,"spf":"NaN","id":41132607},{"atb":[[9.2,0],[10.5,0],[8.2,0]],"id":61861979},{"atl":[[260,0],[160,0]],"id":61861979},{"spn":128.25,"spf":"NaN","id":50758683},{"atb":[[8,0],[6,0],[7,0]],"id":51229677},{"atl":[[75,0],[150,0]],"id":51229677},{"spn":"NaN","spf":"NaN","id":51229677},{"atb":[[8,0],[6,0],[7,0]],"id":49487602},{"atl":[[75,0],[150,0]],"id":49487602}],"con":true,"img":false}]}
{"op":"mcm","clk":"10116062646","pt":1700868868827,"mc":[{"id":"1.221675352","rc":[{"atb":[[9.2,25.42],[10.5,10.97],[8.2,28.95]],"id":61861979},{"atl":[[260,0.8],[160,0.87]],"id":61861979},{"atb":[[8,14.89],[6,41.69],[7,34.74]],"id":51229677},{"atl":[[75,1.88],[150,1.39]],"id":51229677},{"atb":[[9.2,25.42],[10.5,10.97],[8.2,28.95]],"id":49487602},{"atl":[[260,0.8],[160,0.87]],"id":49487602}],"con":true,"img":false}]}
{"op":"mcm","clk":"10116065187","pt":1700868895314,"mc":[{"id":"1.221675352","rc":[{"atb":[[4,0],[4.5,0],[5,0]],"id":51178794},{"atl":[[38,0],[24,0]],"id":51178794},{"atb":[[9.2,0],[10.5,0],[8.2,0]],"id":61861979},{"atl":[[260,0],[160,0]],"id":61861979},{"atb":[[9.2,0],[10.5,0],[8.2,0]],"id":49487602},{"atl":[[260,0],[160,0]],"id":49487602}],"con":true,"img":false}]}
{"op":"mcm","clk":"10116087979","pt":1700869150376,"mc":[{"id":"1.221675352","rc":[{"atb":[[4,69.49],[4.5,59.57],[5,26.06]],"id":51178794},{"atl":[[38,5.64],[24,6.04]],"id":51178794},{"atb":[[9.2,25.42],[10.5,10.97],[8.2,28.95]],"id":61861979},{"atl":[[260,0.8],[160,0.87]],"id":61861979},{"spn":85.25,"spf":"NaN","id":61861979},{"spn":41.5,"spf":"NaN","id":51229677},{"atb":[[9,26.06],[10,23.16],[12.5,9.06]],"id":49487602},{"atl":[[300,0.69],[200,0.69]],"id":49487602},{"spn":106.25,"spf":"NaN","id":49487602}],"con":true,"img":false}]}
{"op":"mcm","clk":"10116092421","pt":1700869201262,"mc":[{"id":"1.221675352","rc":[{"atb":[[2,0],[1.9,0],[1.95,0]],"id":41132607},{"atl":[[6.2,0],[8.2,0]],"id":41132607},{"atb":[[4,0],[4.5,0],[5,0]],"id":51178794},{"atl":[[38,0],[24,0]],"id":51178794},{"atb":[[9.2,0],[10.5,0],[8.2,0]],"id":61861979},{"atl":[[260,0],[160,0]],"id":61861979},{"atb":[[16.5,0],[11.5,0],[14,0]],"id":50758683},{"atl":[[340,0],[240,0]],"id":50758683},{"atb":[[9,0],[10,0],[12.5,0]],"id":52386044},{"atl":[[300,0],[200,0]],"id":52386044},{"atb":[[9,0],[10,0],[12.5,0]],"id":49487602},{"atl":[[300,0],[200,0]],"id":49487602}],"con":true,"img":false}]}
{"op":"mcm","clk":"10116098190","pt":1700869259738,"mc":[{"id":"1.221675352","rc":[{"atb":[[2.06,98.34],[1.98,212.74],[1.93,224.18]],"id":41132607},{"atl":[[6.4,25.76],[8.4,28.2]],"id":41132607},{"spn":4.23,"spf":"NaN","id":41132607},{"atb":[[4,69.49],[4.5,59.57],[5,26.06]],"id":51178794},{"atl":[[38,5.64],[24,6.04]],"id":51178794},{"atb":[[9.2,25.42],[10.5,10.97],[8.2,28.95]],"id":61861979},{"atl":[[260,0.8],[160,0.87]],"id":61861979},{"atb":[[16.5,6.72],[11.5,19.85],[14,16.03]],"id":50758683},{"atl":[[340,0.61],[240,0.57]],"id":50758683},{"atb":[[9,26.06],[10,23.16],[12.5,9.06]],"id":52386044},{"atl":[[300,0.69],[200,0.69]],"id":52386044},{"atb":[[9,26.06],[10,23.16],[12.5,9.06]],"id":49487602},{"atl":[[300,0.69],[200,0.69]],"id":49487602}],"con":true,"img":false}]}
{"op":"mcm","clk":"10116103287","pt":1700869316304,"mc":[{"id":"1.221675352","rc":[{"atb":[[4,0],[4.5,0],[5,0]],"id":51178794},{"atl":[[38,0],[24,0]],"id":51178794},{"atb":[[16.5,0],[11.5,0],[14,0]],"id":50758683},{"atl":[[340,0],[240,0]],"id":50758683},{"atb":[[8,0],[6,0],[7,0]],"id":51229677},{"atl":[[75,0],[150,0]],"id":51229677},{"atb":[[9,0],[10,0],[12.5,0]],"id":52386044},{"atl":[[300,0],[200,0]],"id":52386044}],"con":true,"img":false}]}
{"op":"mcm","clk":"10116107533","pt":1700869361689,"mc":[{"id":"1.221675352","rc":[{"atb":[[4,69.49],[4.5,59.57],[5,26.06]],"id":51178794},{"atl":[[38,5.64],[24,6.04]],"id":51178794},{"atb":[[16.5,6.72],[11.5,19.85],[14,16.03]],"id":50758683},{"atl":[[340,0.61],[240,0.57]],"id":50758683},{"atb":[[8,14.89],[6,41.69],[7,34.74]],"id":51229677},{"atl":[[75,1.88],[150,1.39]],"id":51229677},{"atb":[[9,26.06],[10,23.16],[12.5,9.06]],"id":52386044},{"atl":[[300,0.69],[200,0.69]],"id":52386044}],"con":true,"img":false}]}
{"op":"mcm","clk":"10116139765","pt":1700869708914,"mc":[{"id":"1.221675352","rc":[{"atb":[[8,0],[6,0],[7,0]],"id":51229677},{"atl":[[75,0],[150,0]],"id":51229677},{"spn":"NaN","spf":"NaN","id":51229677},{"atb":[[9,0],[10,0],[12.5,0]],"id":52386044},{"atl":[[300,0],[200,0]],"id":52386044},{"spn":"NaN","spf":"NaN","id":52386044}],"con":true,"img":false}]}
{"op":"mcm","clk":"10116142358","pt":1700869735014,"mc":[{"id":"1.221675352","rc":[{"atb":[[8,14.89],[6,41.69],[7,34.74]],"id":51229677},{"atl":[[75,1.88],[150,1.39]],"id":51229677},{"atb":[[9,26.06],[10,23.16],[12.5,9.06]],"id":52386044},{"atl":[[300,0.69],[200,0.69]],"id":52386044}],"con":true,"img":false}]}
{"op":"mcm","clk":"10116480025","pt":1700873222914,"mc":[{"id":"1.221675352","marketDefinition":{"bspMarket":true,"turnInPlayEnabled":false,"persistenceEnabled":false,"marketBaseRate":7.0,"eventId":"32826103","eventTypeId":"4339","numberOfWinners":1,"bettingType":"ODDS","marketType":"WIN","marketTime":"2023-11-25T09:20:00.000Z","suspendTime":"2023-11-25T09:20:00.000Z","bspReconciled":false,"complete":true,"inPlay":false,"crossMatching":true,"runnersVoidable":false,"numberOfActiveRunners":8,"betDelay":0,"status":"OPEN","runners":[{"status":"ACTIVE","sortPriority":1,"id":54974498,"name":"1. Make No Promise"},{"status":"ACTIVE","sortPriority":2,"id":41132607,"name":"2. Wow Shes Fast"},{"status":"ACTIVE","sortPriority":3,"id":49487602,"name":"3. Andre Bale"},{"status":"ACTIVE","sortPriority":4,"id":51178794,"name":"4. Crackerjack Bull"},{"status":"ACTIVE","sortPriority":5,"id":51229677,"name":"5. Navarino"},{"status":"ACTIVE","sortPriority":6,"id":52386044,"name":"6. Saige Tenniele"},{"status":"ACTIVE","sortPriority":7,"id":61861979,"name":"7. Peaky Joe"},{"status":"ACTIVE","sortPriority":8,"id":50758683,"name":"8. Boomburst"}],"regulators":["MR_INT"],"venue":"Sandown Park","countryCode":"AU","discountAllowed":true,"timezone":"Australia/Sydney","openDate":"2023-11-25T07:34:00.000Z","version":5600960401,"name":"R6 515m Heat","eventName":"Sandown Park (AUS) 25th Nov"},"rc":[{"atb":[[2.06,98.34],[1.98,212.74],[1.93,224.18]],"id":41132607},{"atl":[[6.4,25.76],[8.4,28.2]],"id":41132607},{"spn":4.23,"spf":"NaN","id":41132607},{"atb":[[4,69.49],[4.5,59.57],[5,26.06]],"id":51178794},{"atl":[[38,5.64],[24,6.04]],"id":51178794},{"spn":14.5,"spf":"NaN","id":51178794},{"atb":[[9.2,25.42],[10.5,10.97],[8.2,28.95]],"id":61861979},{"atl":[[260,0.8],[160,0.87]],"id":61861979},{"spn":85.25,"spf":"NaN","id":61861979},{"atb":[[3.1,99.28],[3.35,44.36],[2.94,107.46]],"id":54974498},{"atl":[[17,13.04],[12,12.64]],"id":54974498},{"spn":7.67,"spf":"NaN","id":54974498},{"atb":[[16.5,6.72],[11.5,19.85],[14,16.03]],"id":50758683},{"atl":[[340,0.61],[240,0.57]],"id":50758683},{"spn":128.25,"spf":"NaN","id":50758683},{"atb":[[8,14.89],[6,41.69],[7,34.74]],"id":51229677},{"atl":[[75,1.88],[150,1.39]],"id":51229677},{"spn":41.5,"spf":"NaN","id":51229677},{"atb":[[9,26.06],[10,23.16],[12.5,9.06]],"id":52386044},{"atl":[[300,0.69],[200,0.69]],"id":52386044},{"spn":106.25,"spf":"NaN","id":52386044},{"atb":[[9,26.06],[10,23.16],[12.5,9.06]],"id":49487602},{"atl":[[300,0.69],[200,0.69]],"id":49487602},{"spn":106.25,"spf":"NaN","id":49487602}],"con":true,"img":true}]}
{"op":"mcm","clk":"10116543961","pt":1700873836197,"mc":[{"id":"1.221675352","rc":[{"spl":[[1.01,0.52]],"id":51178794},{"spn":5.0,"spf":1.0,"id":51178794},{"spn":41.5,"spf":"NaN","id":51229677},{"spn":106.25,"spf":"NaN","id":52386044}],"con":true,"img":false}]}
{"op":"mcm","clk":"10116985126","pt":1700878622958,"mc":[{"id":"1.221675352","marketDefinition":{"bspMarket":true,"turnInPlayEnabled":false,"persistenceEnabled":false,"marketBaseRate":7.0,"eventId":"32826103","eventTypeId":"4339","numberOfWinners":1,"bettingType":"ODDS","marketType":"WIN","marketTime":"2023-11-25T09:20:00.000Z","suspendTime":"2023-11-25T09:20:00.000Z","bspReconciled":false,"complete":true,"inPlay":false,"crossMatching":true,"runnersVoidable":false,"numberOfActiveRunners":8,"betDelay":0,"status":"OPEN","runners":[{"status":"ACTIVE","sortPriority":1,"id":54974498,"name":"1. Make No Promise"},{"status":"ACTIVE","sortPriority":2,"id":41132607,"name":"2. Wow Shes Fast"},{"status":"ACTIVE","sortPriority":3,"id":49487602,"name":"3. Andre Bale"},{"status":"ACTIVE","sortPriority":4,"id":51178794,"name":"4. Crackerjack Bull"},{"status":"ACTIVE","sortPriority":5,"id":51229677,"name":"5. Navarino"},{"status":"ACTIVE","sortPriority":6,"id":52386044,"name":"6. Saige Tenniele"},{"status":"ACTIVE","sortPriority":7,"id":61861979,"name":"7. Peaky Joe"},{"status":"ACTIVE","sortPriority":8,"id":50758683,"name":"8. Boomburst"}],"regulators":["MR_INT"],"venue":"Sandown Park","countryCode":"AU","discountAllowed":true,"timezone":"Australia/Sydney","openDate":"2023-11-25T07:34:00.000Z","version":5600960401,"name":"R6 515m Heat","eventName":"Sandown Park (AUS) 25th Nov"},"rc":[{"atb":[[2.06,98.38],[1.98,212.82],[1.93,224.26]],"id":41132607},{"atl":[[6.4,25.77],[8.4,28.21]],"id":41132607},{"spn":4.23,"spf":"NaN","id":41132607},{"spl":[[1.01,0.52]],"id":51178794},{"atb":[[4,69.52],[4.5,59.59],[5,26.07]],"id":51178794},{"atl":[[38,5.64],[24,6.05]],"id":51178794},{"spn":5.0,"spf":1.0,"id":51178794},{"atb":[[9.2,25.43],[10.5,10.97],[8.2,28.96]],"id":61861979},{"atl":[[260,0.8],[160,0.87]],"id":61861979},{"spn":85.25,"spf":"NaN","id":61861979},{"atb":[[3.1,99.32],[3.35,44.37],[2.94,107.5]],"id":54974498},{"atl":[[17,13.04],[12,12.65]],"id":54974498},{"spn":7.67,"spf":"NaN","id":54974498},{"atb":[[16.5,6.72],[11.5,19.86],[14,16.04]],"id":50758683},{"atl":[[340,0.61],[240,0.57]],"id":50758683},{"spn":128.25,"spf":"NaN","id":50758683},{"atb":[[8,14.89],[6,41.71],[7,34.75]],"id":51229677},{"atl":[[75,1.88],[150,1.4]],"id":51229677},{"spn":41.5,"spf":"NaN","id":51229677},{"atb":[[9,26.07],[10,23.17],[12.5,9.07]],"id":52386044},{"atl":[[300,0.7],[200,0.7]],"id":52386044},{"spn":106.25,"spf":"NaN","id":52386044},{"atb":[[9,26.07],[10,23.17],[12.5,9.07]],"id":49487602},{"atl":[[300,0.7],[200,0.7]],"id":49487602},{"spn":106.25,"spf":"NaN","id":49487602}],"con":true,"img":true}]}
{"op":"mcm","clk":"10117113308","pt":1700880085678,"mc":[{"id":"1.221675352","rc":[{"atb":[[2.06,98.38],[1.98,212.82],[1.93,224.26]],"id":41132607},{"atl":[[3.6,7.83],[6.4,25.77],[8.4,28.21]],"id":41132607},{"spn":2.83,"spf":"NaN","id":41132607},{"spl":[[1.01,0.52]],"id":51178794},{"atb":[[4,69.52],[4.5,59.59],[5,26.07]],"id":51178794},{"atl":[[38,5.64],[24,6.05]],"id":51178794},{"atb":[[9.2,25.43],[10.5,10.97],[8.2,28.96]],"id":61861979},{"atl":[[260,0.8],[160,0.87]],"id":61861979},{"atb":[[3.1,99.32],[3.35,44.37],[2.94,107.5]],"id":54974498},{"atl":[[17,13.04],[12,12.65]],"id":54974498},{"atb":[[16.5,6.72],[11.5,19.86],[14,16.04]],"id":50758683},{"atl":[[340,0.61],[240,0.57]],"id":50758683},{"atb":[[8,14.89],[6,41.71],[7,34.75]],"id":51229677},{"atl":[[75,1.88],[150,1.4]],"id":51229677},{"atb":[[9,26.07],[10,23.17],[12.5,9.07]],"id":52386044},{"atl":[[300,0.7],[200,0.7]],"id":52386044},{"atb":[[9,26.07],[10,23.17],[12.5,9.07]],"id":49487602},{"atl":[[300,0.7],[200,0.7]],"id":49487602}],"con":true,"img":false}]}
{"op":"mcm","clk":"10117174764","pt":1700880783252,"mc":[{"id":"1.221675352","rc":[{"atb":[[2.06,0],[1.98,0],[1.93,0]],"id":41132607},{"atl":[[6.4,0],[8.4,0]],"id":41132607},{"spn":1.0,"spf":"NaN","id":41132607},{"atb":[[4,0],[4.5,0],[5,0]],"id":51178794},{"atl":[[38,0],[24,0]],"id":51178794},{"spn":1.0,"spf":1.0,"id":51178794},{"atb":[[9.2,0],[10.5,0],[8.2,0]],"id":61861979},{"atl":[[260,0],[160,0]],"id":61861979},{"spn":"NaN","spf":"NaN","id":61861979},{"atb":[[3.1,0],[3.35,0],[2.94,0]],"id":54974498},{"atl":[[17,0],[12,0]],"id":54974498},{"spn":"NaN","spf":"NaN","id":54974498},{"atb":[[16.5,0],[11.5,0],[14,0]],"id":50758683},{"atl":[[340,0],[240,0]],"id":50758683},{"spn":"NaN","spf":"NaN","id":50758683},{"atb":[[8,0],[6,0],[7,0]],"id":51229677},{"atl":[[75,0],[150,0]],"id":51229677},{"spn":"NaN","spf":"NaN","id":51229677},{"atb":[[9,0],[10,0],[12.5,0]],"id":52386044},{"atl":[[300,0],[200,0]],"id":52386044},{"spn":"NaN","spf":"NaN","id":52386044},{"atb":[[9,0],[10,0],[12.5,0]],"id":49487602},{"atl":[[300,0],[200,0]],"id":49487602},{"spn":"NaN","spf":"NaN","id":49487602}],"con":true,"img":false}]}
{"op":"mcm","clk":"10117177670","pt":1700880810976,"mc":[{"id":"1.221675352","rc":[{"atb":[[2.06,98.38],[1.98,212.82],[1.93,224.26]],"id":41132607},{"atl":[[6.4,25.77],[8.4,28.21]],"id":41132607},{"atb":[[4,69.52],[4.5,59.59],[5,26.07]],"id":51178794},{"atl":[[38,5.64],[24,6.05]],"id":51178794},{"atb":[[9.2,25.43],[10.5,10.97],[8.2,28.96]],"id":61861979},{"atl":[[260,0.8],[160,0.87]],"id":61861979},{"atb":[[2.9,109.77],[3,104.28],[3.25,46.34]],"id":54974498},{"atl":[[16,13.91],[11,13.91]],"id":54974498},{"atb":[[16.5,6.72],[11.5,19.86],[14,16.04]],"id":50758683},{"atl":[[340,0.61],[240,0.57]],"id":50758683},{"atb":[[8,14.89],[6,41.71],[7,34.75]],"id":51229677},{"atl":[[75,1.88],[150,1.4]],"id":51229677},{"atb":[[9,26.07],[10,23.17],[12.5,9.07]],"id":52386044},{"atl":[[300,0.7],[200,0.7]],"id":52386044},{"atb":[[9,26.07],[10,23.17],[12.5,9.07]],"id":49487602},{"atl":[[300,0.7],[200,0.7]],"id":49487602}],"con":true,"img":false}]}
{"op":"mcm","clk":"10117183868","pt":1700880869557,"mc":[{"id":"1.221675352","rc":[{"atb":[[2.06,0],[1.98,0],[1.93,0]],"id":41132607},{"atl":[[6.4,0],[8.4,0]],"id":41132607},{"spn":5.0,"spf":1.0,"id":51178794},{"atb":[[9.2,0],[10.5,0],[8.2,0]],"id":61861979},{"atl":[[260,0],[160,0]],"id":61861979},{"atb":[[2.9,0],[3,0],[3.25,0]],"id":54974498},{"atl":[[16,0],[11,0]],"id":54974498},{"atb":[[16.5,0],[11.5,0],[14,0]],"id":50758683},{"atl":[[340,0],[240,0]],"id":50758683},{"atb":[[8,0],[6,0],[7,0]],"id":51229677},{"atl":[[75,0],[150,0]],"id":51229677},{"atb":[[9,0],[10,0],[12.5,0]],"id":52386044},{"atl":[[300,0],[200,0]],"id":52386044},{"atb":[[9,0],[10,0],[12.5,0]],"id":49487602},{"atl":[[300,0],[200,0]],"id":49487602}],"con":true,"img":false}]}
{"op":"mcm","clk":"10117186454","pt":1700880895145,"mc":[{"id":"1.221675352","rc":[{"atb":[[2.06,98.38],[1.98,212.82],[1.93,224.26]],"id":41132607},{"atl":[[6.4,25.77],[8.4,28.21]],"id":41132607},{"atb":[[9.6,24.25],[8.6,27.44],[11.5,9.93]],"id":61861979},{"atl":[[280,0.74],[180,0.77]],"id":61861979},{"atb":[[2.9,109.77],[3,104.28],[3.25,46.34]],"id":54974498},{"atl":[[16,13.91],[11,13.91]],"id":54974498},{"atb":[[16.5,6.72],[11.5,19.86],[14,16.04]],"id":50758683},{"atl":[[340,0.61],[240,0.57]],"id":50758683},{"atb":[[8,14.89],[6,41.71],[7,34.75]],"id":51229677},{"atl":[[75,1.88],[150,1.4]],"id":51229677},{"atb":[[9,26.07],[10,23.17],[12.5,9.07]],"id":52386044},{"atl":[[300,0.7],[200,0.7]],"id":52386044},{"atb":[[9,26.07],[10,23.17],[12.5,9.07]],"id":49487602},{"atl":[[300,0.7],[200,0.7]],"id":49487602}],"con":true,"img":false}]}
{"op":"mcm","clk":"10117374110","pt":1700882985233,"mc":[{"id":"1.221675352","rc":[{"spl":[[3.25,16.19]],"id":41132607},{"spn":2.65,"spf":1.0,"id":41132607},{"spn":95.75,"spf":"NaN","id":61861979},{"spn":7.12,"spf":"NaN","id":54974498},{"spn":128.25,"spf":"NaN","id":50758683},{"spn":41.5,"spf":"NaN","id":51229677},{"spn":106.25,"spf":"NaN","id":52386044},{"spn":106.25,"spf":"NaN","id":49487602}],"con":true,"img":false}]}
{"op":"mcm","clk":"10117523828","pt":1700884537346,"mc":[{"id":"1.221675352","rc":[{"atb":[[1.01,2.61]],"id":41132607},{"atb":[[1.01,2.61]],"id":54974498}],"con":true,"img":false}]}
{"op":"mcm","clk":"10117523840","pt":1700884537449,"mc":[{"id":"1.221675352","rc":[{"atb":[[1.01,2.61]],"id":49487602}],"con":true,"img":false}]}
{"op":"mcm","clk":"10117523854","pt":1700884537553,"mc":[{"id":"1.221675352","rc":[{"atb":[[1.01,2.61]],"id":51178794}],"con":true,"img":false}]}
{"op":"mcm","clk":"10117523862","pt":1700884537657,"mc":[{"id":"1.221675352","rc":[{"atb":[[1.01,2.61]],"id":61861979},{"atb":[[1.01,2.61]],"id":50758683},{"atb":[[1.01,2.61]],"id":51229677},{"atb":[[1.01,2.61]],"id":52386044}],"con":true,"img":false}]}
{"op":"mcm","clk":"10117749067","pt":1700886944981,"mc":[{"id":"1.221675352","rc":[{"atl":[[3.1,5.22]],"id":41132607},{"spn":2.58,"spf":1.0,"id":41132607}],"con":true,"img":false}]}
{"op":"mcm","clk":"10117750354","pt":1700886959692,"mc":[{"id":"1.221675352","rc":[{"atl":[[90,107.1]],"id":41132607}],"con":true,"img":false}]}
{"op":"mcm","clk":"10117998866","pt":1700889361842,"mc":[{"id":"1.221675352","rc":[{"spl":[[8.2,9.01]],"id":41132607},{"spl":[[5.8,12.71]],"id":51178794},{"spl":[[10,7.21]],"id":61861979},{"spn":11.5,"spf":1.0,"id":61861979},{"spl":[[36,2.08]],"id":54974498},{"spn":7.12,"spf":1.0,"id":54974498},{"spl":[[13,5.63]],"id":50758683},{"spn":16.5,"spf":1.0,"id":50758683},{"spl":[[14.5,5.1]],"id":51229677},{"spn":11.25,"spf":1.0,"id":51229677},{"spl":[[12.5,5.78]],"id":52386044},{"spn":12.5,"spf":1.0,"id":52386044},{"spl":[[15,4.83]],"id":49487602},{"spn":13.75,"spf":1.0,"id":49487602}],"con":true,"img":false}]}
{"op":"mcm","clk":"10118039122","pt":1700889600948,"mc":[{"id":"1.221675352","rc":[{"atb":[[1.51,98.04]],"id":51178794},{"atb":[[1.51,98.04]],"id":54974498},{"atb":[[1.51,98.04]],"id":49487602}],"con":true,"img":false}]}
{"op":"mcm","clk":"10118039134","pt":1700889601052,"mc":[{"id":"1.221675352","rc":[{"atb":[[1.51,98.04]],"id":61861979},{"atb":[[1.51,98.04]],"id":50758683},{"atb":[[1.51,98.04]],"id":51229677},{"atb":[[1.51,98.04]],"id":52386044}],"con":true,"img":false}]}
{"op":"mcm","clk":"10118328591","pt":1700892180229,"mc":[{"id":"1.221675352","rc":[{"atb":[[2.06,0],[1.98,0],[1.93,0]],"id":41132607},{"atl":[[6.4,0],[8.4,0]],"id":41132607},{"spn":1.0,"spf":1.0,"id":41132607},{"atb":[[4,0],[4.5,0],[5,0]],"id":51178794},{"atl":[[38,0],[24,0]],"id":51178794},{"spn":1.51,"spf":1.0,"id":51178794},{"atb":[[9.6,0],[8.6,0],[11.5,0]],"id":61861979},{"atl":[[280,0],[180,0]],"id":61861979},{"spn":5.75,"spf":1.0,"id":61861979},{"atb":[[16.5,0],[11.5,0],[14,0]],"id":50758683},{"atl":[[340,0],[240,0]],"id":50758683},{"spn":7.25,"spf":1.0,"id":50758683},{"atb":[[8,0],[6,0],[7,0]],"id":51229677},{"atl":[[75,0],[150,0]],"id":51229677},{"spn":8.0,"spf":1.0,"id":51229677},{"atb":[[9,0],[10,0],[12.5,0]],"id":52386044},{"atl":[[300,0],[200,0]],"id":52386044},{"spn":7.0,"spf":1.0,"id":52386044},{"atb":[[9,0],[10,0],[12.5,0]],"id":49487602},{"atl":[[300,0],[200,0]],"id":49487602},{"spn":8.25,"spf":1.0,"id":49487602}],"con":true,"img":false}]}
{"op":"mcm","clk":"10118332366","pt":1700892216174,"mc":[{"id":"1.221675352","rc":[{"atb":[[2.06,98.38],[1.98,212.82],[1.93,224.26]],"id":41132607},{"atl":[[6.4,25.77],[8.4,28.21]],"id":41132607},{"atb":[[4,69.52],[4.5,59.59],[5,26.07]],"id":51178794},{"atl":[[38,5.64],[24,6.05]],"id":51178794},{"atb":[[9.6,24.25],[8.6,27.44],[11.5,9.93]],"id":61861979},{"atl":[[280,0.74],[180,0.77]],"id":61861979},{"atb":[[16.5,6.72],[11.5,19.86],[14,16.04]],"id":50758683},{"atl":[[340,0.61],[240,0.57]],"id":50758683},{"atb":[[5.8,43.45],[7.6,15.79],[6.6,37.24]],"id":51229677},{"atl":[[65,2.17],[130,1.61]],"id":51229677},{"atb":[[11,20.85],[13.5,8.34],[9.4,24.82]],"id":52386044},{"atl":[[310,0.67],[210,0.66]],"id":52386044},{"atb":[[12,18.96],[9.8,23.69],[14.5,7.72]],"id":49487602},{"atl":[[320,0.65],[220,0.63]],"id":49487602}],"con":true,"img":false}]}
{"op":"mcm","clk":"10118445474","pt":1700893210786,"mc":[{"id":"1.221675352","rc":[{"spn":2.58,"spf":1.0,"id":41132607},{"spn":5.0,"spf":1.0,"id":51178794},{"spn":11.5,"spf":1.0,"id":61861979},{"spn":16.5,"spf":1.0,"id":50758683},{"spn":11.05,"spf":1.0,"id":51229677},{"atb":[[4.1,16.13]],"id":52386044},{"spn":13.5,"spf":1.0,"id":52386044},{"atb":[[4.1,16.13]],"id":49487602},{"spn":14.75,"spf":1.0,"id":49487602}],"con":true,"img":false}]}
{"op":"mcm","clk":"10118445495","pt":1700893210855,"mc":[{"id":"1.221675352","rc":[{"atl":[[34,10]],"id":41132607},{"atb":[[2.12,44.64]],"id":51178794},{"atb":[[4.1,16.13],[2.12,44.64],[3.05,24.39]],"id":61861979},{"atl":[[34,10]],"id":54974498},{"atb":[[4.1,16.13],[2.12,44.64],[3.05,24.39]],"id":50758683},{"atb":[[2.12,44.64]],"id":51229677},{"atb":[[2.12,44.64],[3.05,24.39]],"id":52386044},{"atb":[[2.12,44.64],[3.05,24.39]],"id":49487602}],"con":true,"img":false}]}
{"op":"mcm","clk":"10118451579","pt":1700893259619,"mc":[{"id":"1.221675352","rc":[{"atb":[[2.06,0],[1.98,0],[1.93,0]],"id":41132607},{"atl":[[6.4,0],[8.4,0]],"id":41132607},{"atb":[[9.6,0],[8.6,0],[11.5,0]],"id":61861979},{"atl":[[280,0],[180,0]],"id":61861979},{"atb":[[2.9,0],[3,0],[3.25,0]],"id":54974498},{"atl":[[16,0],[11,0]],"id":54974498},{"atb":[[16.5,0],[11.5,0],[14,0]],"id":50758683},{"atl":[[340,0],[240,0]],"id":50758683},{"atb":[[5.8,0],[7.6,0],[6.6,0]],"id":51229677},{"atl":[[65,0],[130,0]],"id":51229677},{"atb":[[11,0],[13.5,0],[9.4,0]],"id":52386044},{"atl":[[310,0],[210,0]],"id":52386044},{"atb":[[12,0],[9.8,0],[14.5,0]],"id":49487602},{"atl":[[320,0],[220,0]],"id":49487602}],"con":true,"img":false}]}
{"op":"mcm","clk":"10118455524","pt":1700893292538,"mc":[{"id":"1.221675352","rc":[{"atb":[[2,104.28],[1.9,231.74],[1.95,219.54]],"id":41132607},{"atl":[[6.2,26.76],[8.2,28.99]],"id":41132607},{"spn":2.55,"spf":1.0,"id":41132607},{"atb":[[9.6,24.25],[8.6,27.44],[11.5,9.93]],"id":61861979},{"atl":[[280,0.74],[180,0.77]],"id":61861979},{"atb":[[2.5,139.04],[2.6,130.35],[2.7,61.34]],"id":54974498},{"atl":[[8.6,18.31],[11.5,19.88]],"id":54974498},{"spn":5.65,"spf":1.0,"id":54974498},{"atb":[[16.5,6.72],[11.5,19.86],[14,16.04]],"id":50758683},{"atl":[[340,0.61],[240,0.57]],"id":50758683},{"atb":[[5.5,46.34],[6,41.71],[7,17.38]],"id":51229677},{"atl":[[95,2.22],[48,2.96]],"id":51229677},{"spn":10.75,"spf":1.0,"id":51229677},{"atb":[[11,20.85],[13.5,8.34],[9.4,24.82]],"id":52386044},{"atl":[[310,0.67],[210,0.66]],"id":52386044},{"atb":[[12,18.96],[9.8,23.69],[14.5,7.72]],"id":49487602},{"atl":[[320,0.65],[220,0.63]],"id":49487602}],"con":true,"img":false}]}
{"op":"mcm","clk":"10118460880","pt":1700893341823,"mc":[{"id":"1.221675352","rc":[{"atb":[[2,0],[1.9,0],[1.95,0]],"id":41132607},{"atl":[[6.2,0],[8.2,0]],"id":41132607},{"atb":[[4,0],[4.5,0],[5,0]],"id":51178794},{"atl":[[38,0],[24,0]],"id":51178794},{"atb":[[9.6,0],[8.6,0],[11.5,0]],"id":61861979},{"atl":[[280,0],[180,0]],"id":61861979},{"atb":[[2.5,0],[2.6,0],[2.7,0]],"id":54974498},{"atl":[[8.6,0],[11.5,0]],"id":54974498},{"atb":[[16.5,0],[11.5,0],[14,0]],"id":50758683},{"atl":[[340,0],[240,0]],"id":50758683},{"atb":[[5.5,0],[6,0],[7,0]],"id":51229677},{"atl":[[95,0],[48,0]],"id":51229677},{"atb":[[11,0],[13.5,0],[9.4,0]],"id":52386044},{"atl":[[310,0],[210,0]],"id":52386044},{"atb":[[12,0],[9.8,0],[14.5,0]],"id":49487602},{"atl":[[320,0],[220,0]],"id":49487602}],"con":true,"img":false}]}
{"op":"mcm","clk":"10118465061","pt":1700893380467,"mc":[{"id":"1.221675352","rc":[{"atb":[[2,104.28],[1.9,231.74],[1.95,219.54]],"id":41132607},{"atl":[[6.2,26.76],[8.2,28.99]],"id":41132607},{"atb":[[4,69.52],[4.5,59.59],[5,26.07]],"id":51178794},{"atl":[[38,5.64],[24,6.05]],"id":51178794},{"atb":[[9.6,24.25],[8.6,27.44],[11.5,9.93]],"id":61861979},{"atl":[[280,0.74],[180,0.77]],"id":61861979},{"atb":[[2.5,139.04],[2.6,130.35],[2.7,61.34]],"id":54974498},{"atl":[[8.6,18.31],[11.5,19.88]],"id":54974498},{"atb":[[16.5,6.72],[11.5,19.86],[14,16.04]],"id":50758683},{"atl":[[340,0.61],[240,0.57]],"id":50758683},{"atb":[[5.5,46.34],[6,41.71],[7,17.38]],"id":51229677},{"atl":[[95,2.22],[48,2.96]],"id":51229677},{"atb":[[11,20.85],[13.5,8.34],[9.4,24.82]],"id":52386044},{"atl":[[310,0.67],[210,0.66]],"id":52386044},{"atb":[[12,18.96],[9.8,23.69],[14.5,7.72]],"id":49487602},{"atl":[[320,0.65],[220,0.63]],"id":49487602}],"con":true,"img":false}]}
{"op":"mcm","clk":"10118575334","pt":1700894458445,"mc":[{"id":"1.221675352","rc":[{"atb":[[2,0],[1.9,0],[1.95,0]],"id":41132607},{"atl":[[6.2,0],[8.2,0]],"id":41132607},{"spn":1.0,"spf":1.0,"id":41132607},{"atb":[[4,0],[4.5,0],[5,0]],"id":51178794},{"atl":[[38,0],[24,0]],"id":51178794},{"spn":2.12,"spf":1.0,"id":51178794},{"atb":[[9.6,0],[8.6,0],[11.5,0]],"id":61861979},{"atl":[[280,0],[180,0]],"id":61861979},{"spn":7.05,"spf":1.0,"id":61861979},{"atb":[[2.5,0],[2.6,0],[2.7,0]],"id":54974498},{"atl":[[8.6,0],[11.5,0]],"id":54974498},{"spn":17.75,"spf":1.0,"id":54974498},{"atb":[[16.5,0],[11.5,0],[14,0]],"id":50758683},{"atl":[[340,0],[240,0]],"id":50758683},{"spn":8.55,"spf":1.0,"id":50758683},{"atb":[[5.5,0],[6,0],[7,0]],"id":51229677},{"atl":[[95,0],[48,0]],"id":51229677},{"spn":8.31,"spf":1.0,"id":51229677},{"atb":[[11,0],[13.5,0],[9.4,0]],"id":52386044},{"atl":[[310,0],[210,0]],"id":52386044},{"spn":8.3,"spf":1.0,"id":52386044},{"atb":[[12,0],[9.8,0],[14.5,0]],"id":49487602},{"atl":[[320,0],[220,0]],"id":49487602},{"spn":9.55,"spf":1.0,"id":49487602}],"con":true,"img":false}]}
{"op":"mcm","clk":"10118578837","pt":1700894491954,"mc":[{"id":"1.221675352","rc":[{"atb":[[2,104.28],[1.9,231.74],[1.95,219.54]],"id":41132607},{"atl":[[6.2,26.76],[8.2,28.99]],"id":41132607},{"atb":[[4,69.52],[4.5,59.59],[5,26.07]],"id":51178794},{"atl":[[38,5.64],[24,6.05]],"id":51178794},{"atb":[[9.6,24.25],[8.6,27.44],[11.5,9.93]],"id":61861979},{"atl":[[280,0.74],[180,0.77]],"id":61861979},{"atb":[[2.5,139.04],[2.6,130.35],[2.7,61.34]],"id":54974498},{"atl":[[8.6,18.31],[11.5,19.88]],"id":54974498},{"atb":[[16.5,6.72],[11.5,19.86],[14,16.04]],"id":50758683},{"atl":[[340,0.61],[240,0.57]],"id":50758683},{"atb":[[5.5,46.34],[6,41.71],[7,17.38]],"id":51229677},{"atl":[[95,2.22],[48,2.96]],"id":51229677},{"atb":[[11,20.85],[13.5,8.34],[9.4,24.82]],"id":52386044},{"atl":[[310,0.67],[210,0.66]],"id":52386044},{"atb":[[12,18.96],[9.8,23.69],[14.5,7.72]],"id":49487602},{"atl":[[320,0.65],[220,0.63]],"id":49487602}],"con":true,"img":false}]}
{"op":"mcm","clk":"10118610657","pt":1700894785920,"mc":[{"id":"1.221675352","rc":[{"atl":[[3.6,0]],"id":41132607},{"spn":2.55,"spf":1.0,"id":41132607},{"spn":5.0,"spf":1.0,"id":51178794},{"spn":11.5,"spf":1.0,"id":61861979},{"spn":5.65,"spf":1.0,"id":54974498},{"spn":16.5,"spf":1.0,"id":50758683},{"spn":10.75,"spf":1.0,"id":51229677},{"spn":13.5,"spf":1.0,"id":52386044},{"spn":14.75,"spf":1.0,"id":49487602}],"con":true,"img":false}]}
{"op":"mcm","clk":"10118610668","pt":1700894786023,"mc":[{"id":"1.221675352","rc":[{"atl":[[3.5,7.83]],"id":41132607}],"con":true,"img":false}]}
{"op":"mcm","clk":"10118712613","pt":1700895647615,"mc":[{"id":"1.221675352","rc":[{"atb":[[2,0],[1.9,0],[1.95,0]],"id":41132607},{"atl":[[6.2,0],[8.2,0]],"id":41132607},{"spn":1.0,"spf":1.0,"id":41132607},{"atb":[[4,0],[4.5,0],[5,0]],"id":51178794},{"atl":[[38,0],[24,0]],"id":51178794},{"spn":2.12,"spf":1.0,"id":51178794},{"atb":[[9.6,0],[8.6,0],[11.5,0]],"id":61861979},{"atl":[[280,0],[180,0]],"id":61861979},{"spn":7.05,"spf":1.0,"id":61861979},{"atb":[[2.5,0],[2.6,0],[2.7,0]],"id":54974498},{"atl":[[8.6,0],[11.5,0]],"id":54974498},{"spn":17.75,"spf":1.0,"id":54974498},{"atb":[[16.5,0],[11.5,0],[14,0]],"id":50758683},{"atl":[[340,0],[240,0]],"id":50758683},{"spn":8.55,"spf":1.0,"id":50758683},{"atb":[[5.5,0],[6,0],[7,0]],"id":51229677},{"atl":[[95,0],[48,0]],"id":51229677},{"spn":8.31,"spf":1.0,"id":51229677},{"atb":[[11,0],[13.5,0],[9.4,0]],"id":52386044},{"atl":[[310,0],[210,0]],"id":52386044},{"spn":8.3,"spf":1.0,"id":52386044},{"atb":[[12,0],[9.8,0],[14.5,0]],"id":49487602},{"atl":[[320,0],[220,0]],"id":49487602},{"spn":9.55,"spf":1.0,"id":49487602}],"con":true,"img":false}]}
{"op":"mcm","clk":"10118716957","pt":1700895686586,"mc":[{"id":"1.221675352","rc":[{"atb":[[2,104.28],[1.9,231.74],[1.95,219.54]],"id":41132607},{"atl":[[6.2,26.76],[8.2,28.99]],"id":41132607},{"atb":[[4,69.52],[4.5,59.59],[5,26.07]],"id":51178794},{"atl":[[38,5.64],[24,6.05]],"id":51178794},{"atb":[[9.6,24.25],[8.6,27.44],[11.5,9.93]],"id":61861979},{"atl":[[280,0.74],[180,0.77]],"id":61861979},{"atb":[[2.5,139.04],[2.6,130.35],[2.7,61.34]],"id":54974498},{"atl":[[8.6,18.31],[11.5,19.88]],"id":54974498},{"atb":[[16.5,6.72],[11.5,19.86],[14,16.04]],"id":50758683},{"atl":[[340,0.61],[240,0.57]],"id":50758683},{"atb":[[5.5,46.34],[6,41.71],[7,17.38]],"id":51229677},{"atl":[[95,2.22],[48,2.96]],"id":51229677},{"atb":[[11,20.85],[13.5,8.34],[9.4,24.82]],"id":52386044},{"atl":[[310,0.67],[210,0.66]],"id":52386044},{"atb":[[12,18.96],[9.8,23.69],[14.5,7.72]],"id":49487602},{"atl":[[320,0.65],[220,0.63]],"id":49487602}],"con":true,"img":false}]}
{"op":"mcm","clk":"10118829596","pt":1700896757830,"mc":[{"id":"1.221675352","rc":[{"atb":[[2,0],[1.9,0],[1.95,0]],"id":41132607},{"atl":[[6.2,0],[8.2,0]],"id":41132607},{"atb":[[4,0],[4.5,0],[5,0]],"id":51178794},{"atl":[[38,0],[24,0]],"id":51178794},{"atb":[[9.6,0],[8.6,0],[11.5,0]],"id":61861979},{"atl":[[280,0],[180,0]],"id":61861979},{"atb":[[2.5,0],[2.6,0],[2.7,0]],"id":54974498},{"atl":[[8.6,0],[11.5,0]],"id":54974498},{"atb":[[16.5,0],[11.5,0],[14,0]],"id":50758683},{"atl":[[340,0],[240,0]],"id":50758683},{"atb":[[5.5,0],[6,0],[7,0]],"id":51229677},{"atl":[[95,0],[48,0]],"id":51229677},{"atb":[[11,0],[13.5,0],[9.4,0]],"id":52386044},{"atl":[[310,0],[210,0]],"id":52386044},{"atb":[[12,0],[9.8,0],[14.5,0]],"id":49487602},{"atl":[[320,0],[220,0]],"id":49487602}],"con":true,"img":false}]}
{"op":"mcm","clk":"10118829994","pt":1700896761855,"mc":[{"id":"1.221675352","rc":[{"atb":[[2,104.28],[1.9,231.74],[1.95,219.54]],"id":41132607},{"atl":[[6.2,26.76],[8.2,28.99]],"id":41132607},{"atb":[[4,69.52],[4.5,59.59],[5,26.07]],"id":51178794},{"atl":[[38,5.64],[24,6.05]],"id":51178794},{"atb":[[9.6,24.25],[8.6,27.44],[11.5,9.93]],"id":61861979},{"atl":[[280,0.74],[180,0.77]],"id":61861979},{"atb":[[2.5,139.04],[2.6,130.35],[2.7,61.34]],"id":54974498},{"atl":[[8.6,18.31],[11.5,19.88]],"id":54974498},{"atb":[[16.5,6.72],[11.5,19.86],[14,16.04]],"id":50758683},{"atl":[[340,0.61],[240,0.57]],"id":50758683},{"atb":[[5.5,46.34],[6,41.71],[7,17.38]],"id":51229677},{"atl":[[95,2.22],[48,2.96]],"id":51229677},{"atb":[[11,20.85],[13.5,8.34],[9.4,24.82]],"id":52386044},{"atl":[[310,0.67],[210,0.66]],"id":52386044},{"atb":[[12,18.96],[9.8,23.69],[14.5,7.72]],"id":49487602},{"atl":[[320,0.65],[220,0.63]],"id":49487602}],"con":true,"img":false}]}
{"op":"mcm","clk":"10118833746","pt":1700896800940,"mc":[{"id":"1.221675352","rc":[{"atl":[[16,10]],"id":41132607}],"con":true,"img":false}]}
{"op":"mcm","clk":"10118839287","pt":1700896857941,"mc":[{"id":"1.221675352","rc":[{"atb":[[2.14,2.61]],"id":41132607},{"spn":2.62,"spf":1.0,"id":41132607},{"spn":5.0,"spf":1.0,"id":51178794},{"spn":11.5,"spf":1.0,"id":61861979},{"spn":5.65,"spf":1.0,"id":54974498},{"spn":16.5,"spf":1.0,"id":50758683},{"spn":10.75,"spf":1.0,"id":51229677},{"spn":13.5,"spf":1.0,"id":52386044},{"spn":14.75,"spf":1.0,"id":49487602}],"con":true,"img":false}]}
{"op":"mcm","clk":"10118925948","pt":1700897654363,"mc":[{"id":"1.221675352","rc":[{"atb":[[4,0],[4.5,0],[5,0]],"id":51178794},{"atl":[[38,0],[24,0]],"id":51178794},{"spn":2.12,"spf":1.0,"id":51178794},{"atb":[[9.6,0],[8.6,0],[11.5,0]],"id":61861979},{"atl":[[280,0],[180,0]],"id":61861979},{"spn":7.05,"spf":1.0,"id":61861979},{"atb":[[2.5,0],[2.6,0],[2.7,0]],"id":54974498},{"atl":[[8.6,0],[11.5,0]],"id":54974498},{"spn":17.75,"spf":1.0,"id":54974498},{"atb":[[11,0],[13.5,0],[9.4,0]],"id":52386044},{"atl":[[310,0],[210,0]],"id":52386044},{"spn":8.3,"spf":1.0,"id":52386044},{"atb":[[12,0],[9.8,0],[14.5,0]],"id":49487602},{"atl":[[320,0],[220,0]],"id":49487602},{"spn":9.55,"spf":1.0,"id":49487602}],"con":true,"img":false}]}
{"op":"mcm","clk":"10118930599","pt":1700897694829,"mc":[{"id":"1.221675352","rc":[{"atb":[[4,69.52],[4.5,59.59],[5,26.07]],"id":51178794},{"atl":[[38,5.64],[24,6.05]],"id":51178794},{"atb":[[9.6,24.25],[8.6,27.44],[11.5,9.93]],"id":61861979},{"atl":[[280,0.74],[180,0.77]],"id":61861979},{"atb":[[3.2,47.4],[2.88,110.94],[2.98,105.33]],"id":54974498},{"atl":[[16,13.91],[11,13.91]],"id":54974498},{"atb":[[11,20.85],[13.5,8.34],[9.4,24.82]],"id":52386044},{"atl":[[310,0.67],[210,0.66]],"id":52386044},{"atb":[[12,18.96],[9.8,23.69],[14.5,7.72]],"id":49487602},{"atl":[[320,0.65],[220,0.63]],"id":49487602}],"con":true,"img":false}]}
{"op":"mcm","clk":"10118933636","pt":1700897720961,"mc":[{"id":"1.221675352","rc":[{"atb":[[2.14,0]],"id":41132607},{"spn":2.55,"spf":1.0,"id":41132607},{"spn":5.0,"spf":1.0,"id":51178794},{"spn":11.5,"spf":1.0,"id":61861979},{"spn":7.1,"spf":1.0,"id":54974498},{"spn":13.5,"spf":1.0,"id":52386044},{"spn":14.75,"spf":1.0,"id":49487602}],"con":true,"img":false}]}
{"op":"mcm","clk":"10118936891","pt":1700897752087,"mc":[{"id":"1.221675352","rc":[{"atb":[[2,0],[1.9,0],[1.95,0]],"id":41132607},{"atl":[[6.2,0],[8.2,0]],"id":41132607},{"atb":[[4,0],[4.5,0],[5,0]],"id":51178794},{"atl":[[38,0],[24,0]],"id":51178794},{"atb":[[9.6,0],[8.6,0],[11.5,0]],"id":61861979},{"atl":[[280,0],[180,0]],"id":61861979},{"atb":[[3.2,0],[2.88,0],[2.98,0]],"id":54974498},{"atl":[[16,0],[11,0]],"id":54974498},{"atb":[[16.5,0],[11.5,0],[14,0]],"id":50758683},{"atl":[[340,0],[240,0]],"id":50758683},{"atb":[[5.5,0],[6,0],[7,0]],"id":51229677},{"atl":[[95,0],[48,0]],"id":51229677},{"atb":[[11,0],[13.5,0],[9.4,0]],"id":52386044},{"atl":[[310,0],[210,0]],"id":52386044},{"atb":[[12,0],[9.8,0],[14.5,0]],"id":49487602},{"atl":[[320,0],[220,0]],"id":49487602}],"con":true,"img":false}]}
{"op":"mcm","clk":"10118940605","pt":1700897786023,"mc":[{"id":"1.221675352","rc":[{"atl":[[3.5,0]],"id":41132607},{"spn":1.0,"spf":1.0,"id":41132607},{"spn":2.12,"spf":1.0,"id":51178794},{"spn":7.05,"spf":1.0,"id":61861979},{"spn":17.75,"spf":1.0,"id":54974498},{"spn":8.55,"spf":1.0,"id":50758683},{"spn":8.31,"spf":1.0,"id":51229677},{"spn":8.3,"spf":1.0,"id":52386044},{"spn":9.55,"spf":1.0,"id":49487602}],"con":true,"img":false}]}
{"op":"mcm","clk":"10118940621","pt":1700897786130,"mc":[{"id":"1.221675352","rc":[{"atl":[[3.55,7.83]],"id":41132607}],"con":true,"img":false}]}
{"op":"mcm","clk":"10118941423","pt":1700897793469,"mc":[{"id":"1.221675352","rc":[{"atb":[[2,104.28],[1.9,231.74],[1.95,219.54]],"id":41132607},{"atl":[[6.2,26.76],[8.2,28.99]],"id":41132607},{"atb":[[4,69.52],[4.5,59.59],[5,26.07]],"id":51178794},{"atl":[[38,5.64],[24,6.05]],"id":51178794},{"atb":[[9.6,24.25],[8.6,27.44],[11.5,9.93]],"id":61861979},{"atl":[[280,0.74],[180,0.77]],"id":61861979},{"atb":[[3.2,47.4],[2.88,110.94],[2.98,105.33]],"id":54974498},{"atl":[[16,13.91],[11,13.91]],"id":54974498},{"atb":[[16.5,6.72],[11.5,19.86],[14,16.04]],"id":50758683},{"atl":[[340,0.61],[240,0.57]],"id":50758683},{"atb":[[5.5,46.34],[6,41.71],[7,17.38]],"id":51229677},{"atl":[[95,2.22],[48,2.96]],"id":51229677},{"atb":[[12,18.96],[9.8,23.69],[14.5,7.72]],"id":52386044},{"atl":[[320,0.65],[220,0.63]],"id":52386044},{"atb":[[12,18.96],[9.8,23.69],[14.5,7.72]],"id":49487602},{"atl":[[320,0.65],[220,0.63]],"id":49487602}],"con":true,"img":false}]}
{"op":"mcm","clk":"10119011019","pt":1700898394115,"mc":[{"id":"1.221675352","rc":[{"spn":2.55,"spf":1.0,"id":41132607},{"spn":5.0,"spf":1.0,"id":51178794},{"atl":[[17,20.89]],"id":61861979},{"spn":11.5,"spf":1.0,"id":61861979},{"spn":7.1,"spf":1.0,"id":54974498},{"spn":16.5,"spf":1.0,"id":50758683},{"spn":10.75,"spf":1.0,"id":51229677},{"spn":14.5,"spf":1.0,"id":52386044},{"spn":14.75,"spf":1.0,"id":49487602}],"con":true,"img":false}]}
{"op":"mcm","clk":"10119015890","pt":1700898429096,"mc":[{"id":"1.221675352","rc":[{"atl":[[23,10.44]],"id":49487602}],"con":true,"img":false}]}
{"op":"mcm","clk":"10119019269","pt":1700898454404,"mc":[{"id":"1.221675352","rc":[{"atl":[[23,0]],"id":49487602}],"con":true,"img":false}]}
{"op":"mcm","clk":"10119027341","pt":1700898512189,"mc":[{"id":"1.221675352","rc":[{"atl":[[18.5,10.44]],"id":61861979}],"con":true,"img":false}]}
{"op":"mcm","clk":"10119042814","pt":1700898632312,"mc":[{"id":"1.221675352","rc":[{"atb":[[2,0],[1.9,0],[1.95,0]],"id":41132607},{"atl":[[6.2,0],[8.2,0]],"id":41132607},{"spn":1.0,"spf":1.0,"id":41132607},{"atb":[[4,0],[4.5,0],[5,0]],"id":51178794},{"atl":[[38,0],[24,0]],"id":51178794},{"spn":2.12,"spf":1.0,"id":51178794},{"atb":[[9.6,0],[8.6,0],[11.5,0]],"id":61861979},{"atl":[[280,0],[180,0]],"id":61861979},{"spn":7.05,"spf":1.0,"id":61861979},{"atb":[[3.2,0],[2.88,0],[2.98,0]],"id":54974498},{"atl":[[16,0],[11,0]],"id":54974498},{"spn":17.75,"spf":1.0,"id":54974498},{"atb":[[16.5,0],[11.5,0],[14,0]],"id":50758683},{"atl":[[340,0],[240,0]],"id":50758683},{"spn":8.55,"spf":1.0,"id":50758683},{"atb":[[5.5,0],[6,0],[7,0]],"id":51229677},{"atl":[[95,0],[48,0]],"id":51229677},{"spn":8.31,"spf":1.0,"id":51229677},{"atb":[[12,0],[9.8,0],[14.5,0]],"id":49487602},{"atl":[[320,0],[220,0]],"id":49487602},{"spn":9.55,"spf":1.0,"id":49487602}],"con":true,"img":false}]}
{"op":"mcm","clk":"10119044549","pt":1700898645543,"mc":[{"id":"1.221675352","rc":[{"atb":[[2,104.28],[1.9,231.74],[1.95,219.54]],"id":41132607},{"atl":[[6.2,26.76],[8.2,28.99]],"id":41132607},{"atb":[[4,69.52],[4.5,59.59],[5,26.07]],"id":51178794},{"atl":[[38,5.64],[24,6.05]],"id":51178794},{"atb":[[9.6,24.25],[8.6,27.44],[11.5,9.93]],"id":61861979},{"atl":[[280,0.74],[180,0.77]],"id":61861979},{"atb":[[3.2,47.4],[2.88,110.94],[2.98,105.33]],"id":54974498},{"atl":[[16,13.91],[11,13.91]],"id":54974498},{"atb":[[16.5,13.45],[19,5.79],[14,16.04]],"id":50758683},{"atl":[[260,0.53],[360,0.57]],"id":50758683},{"atb":[[5.5,46.34],[6,41.71],[7,17.38]],"id":51229677},{"atl":[[95,2.22],[48,2.96]],"id":51229677},{"atb":[[11,20.85],[13.5,8.34],[9.4,24.82]],"id":49487602},{"atl":[[310,0.67],[210,0.66]],"id":49487602}],"con":true,"img":false}]}
{"op":"mcm","clk":"10119050039","pt":1700898687792,"mc":[{"id":"1.221675352","rc":[{"atb":[[2,0],[1.9,0],[1.95,0]],"id":41132607},{"atl":[[6.2,0],[8.2,0]],"id":41132607},{"atb":[[4,0],[4.5,0],[5,0]],"id":51178794},{"atl":[[38,0],[24,0]],"id":51178794},{"atb":[[9.6,0],[8.6,0],[11.5,0]],"id":61861979},{"atl":[[280,0],[180,0]],"id":61861979},{"atb":[[3.2,0],[2.88,0],[2.98,0]],"id":54974498},{"atl":[[16,0],[11,0]],"id":54974498},{"atb":[[16.5,0],[19,0],[14,0]],"id":50758683},{"atl":[[260,0],[360,0]],"id":50758683},{"atb":[[5.5,0],[6,0],[7,0]],"id":51229677},{"atl":[[95,0],[48,0]],"id":51229677},{"atb":[[12,0],[9.8,0],[14.5,0]],"id":52386044},{"atl":[[320,0],[220,0]],"id":52386044},{"atb":[[11,0],[13.5,0],[9.4,0]],"id":49487602},{"atl":[[310,0],[210,0]],"id":49487602}],"con":true,"img":false}]}
{"op":"mcm","clk":"10119054741","pt":1700898725225,"mc":[{"id":"1.221675352","rc":[{"atb":[[1.82,124.87],[2.02,54.93]],"id":41132607},{"atl":[[7.2,16.51],[5.2,13.34]],"id":41132607},{"spn":2.56,"spf":1.0,"id":41132607},{"atb":[[4.5,16],[3.75,42.84]],"id":51178794},{"atl":[[19.5,6.36],[14,4.31]],"id":51178794},{"spn":4.5,"spf":1.0,"id":51178794},{"atb":[[11,5.6],[8.8,16.19]],"id":61861979},{"atl":[[65,2.61],[48,2.61]],"id":61861979},{"spn":10.5,"spf":1.0,"id":61861979},{"atb":[[3,28.01],[2.62,68.85]],"id":54974498},{"atl":[[8.6,7.37],[12,10.14]],"id":54974498},{"spn":5.8,"spf":1.0,"id":54974498},{"atb":[[12,9.69],[15,4]],"id":50758683},{"atl":[[90,2.61],[120,2.61]],"id":50758683},{"spn":14.12,"spf":1.0,"id":50758683},{"atb":[[7.2,9.03],[6,21.73]],"id":51229677},{"atl":[[38,2.93],[27,2.61]],"id":51229677},{"spn":10.85,"spf":1.0,"id":51229677},{"atb":[[11,10.5],[14,4.31]],"id":52386044},{"atl":[[80,2.61],[110,2.61]],"id":52386044},{"spn":13.23,"spf":1.0,"id":52386044},{"atb":[[10,13.23],[12.5,4.87]],"id":49487602},{"atl":[[65,2.61],[85,2.61]],"id":49487602},{"spn":13.75,"spf":1.0,"id":49487602}],"con":true,"img":false}]}
{"op":"mcm","clk":"10119055650","pt":1700898732565,"mc":[{"id":"1.221675352","rc":[{"atb":[[2,104.28],[1.9,231.74],[1.95,219.54]],"id":41132607},{"atl":[[6.2,26.76],[8.2,28.99]],"id":41132607},{"atb":[[4,69.52],[4.5,75.6],[5,26.07]],"id":51178794},{"atl":[[38,5.64],[24,6.05]],"id":51178794},{"atb":[[9.6,24.25],[8.6,27.44],[11.5,9.93]],"id":61861979},{"atl":[[280,0.74],[180,0.77]],"id":61861979},{"atb":[[3.2,47.4],[2.88,110.94],[2.98,105.33]],"id":54974498},{"atl":[[16,13.91],[11,13.91]],"id":54974498},{"atb":[[16.5,13.45],[19,5.79],[14,16.04]],"id":50758683},{"atl":[[260,0.53],[360,0.57]],"id":50758683},{"atb":[[5.5,46.34],[6,63.44],[7,17.38]],"id":51229677},{"atl":[[95,2.22],[48,2.96]],"id":51229677},{"atb":[[12,18.96],[9.8,23.69],[14.5,7.72]],"id":52386044},{"atl":[[320,0.65],[220,0.63]],"id":52386044},{"atb":[[11,20.85],[13.5,8.34],[9.4,24.82]],"id":49487602},{"atl":[[310,0.67],[210,0.66]],"id":49487602}],"con":true,"img":false}]}
{"op":"mcm","clk":"10119059392","pt":1700898763339,"mc":[{"id":"1.221675352","rc":[{"atl":[[90,0]],"id":50758683}],"con":true,"img":false}]}
{"op":"mcm","clk":"10119059404","pt":1700898763447,"mc":[{"id":"1.221675352","rc":[{"atl":[[95,2.61]],"id":50758683}],"con":true,"img":false}]}
{"op":"mcm","clk":"10119062724","pt":1700898791589,"mc":[{"id":"1.221675352","rc":[{"atb":[[2,0],[1.9,0],[1.95,0]],"id":41132607},{"atl":[[6.2,0],[8.2,0]],"id":41132607},{"atb":[[4,0],[4.5,16],[5,0]],"id":51178794},{"atl":[[38,0],[24,0]],"id":51178794},{"atb":[[9.6,0],[8.6,0],[11.5,0]],"id":61861979},{"atl":[[280,0],[180,0]],"id":61861979},{"atb":[[3.2,0],[2.88,0],[2.98,0]],"id":54974498},{"atl":[[16,0],[11,0]],"id":54974498},{"atb":[[16.5,0],[19,0],[14,0]],"id":50758683},{"atl":[[260,0],[360,0]],"id":50758683},{"atb":[[5.5,0],[6,21.73],[7,0]],"id":51229677},{"atl":[[95,0],[48,0]],"id":51229677},{"spn":14.5,"spf":1.0,"id":52386044},{"atb":[[11,0],[13.5,0],[9.4,0]],"id":49487602},{"atl":[[310,0],[210,0]],"id":49487602}],"con":true,"img":false}]}
{"op":"mcm","clk":"10119064415","pt":1700898806039,"mc":[{"id":"1.221675352","rc":[{"atb":[[2,104.28],[1.9,231.74],[1.95,219.54]],"id":41132607},{"atl":[[6.2,26.76],[8.2,28.99]],"id":41132607},{"atb":[[4,69.52],[4.5,75.6],[5,26.07]],"id":51178794},{"atl":[[38,5.64],[24,6.05]],"id":51178794},{"atb":[[9.6,24.25],[8.6,27.44],[11.5,9.93]],"id":61861979},{"atl":[[280,0.74],[180,0.77]],"id":61861979},{"atb":[[3.2,47.4],[2.88,110.94],[2.98,105.33]],"id":54974498},{"atl":[[16,13.91],[11,13.91]],"id":54974498},{"atb":[[16.5,13.45],[19,5.79],[14,16.04]],"id":50758683},{"atl":[[260,0.53],[360,0.57]],"id":50758683},{"atb":[[5.5,46.34],[6,63.44],[7,17.38]],"id":51229677},{"atl":[[95,2.22],[48,2.96]],"id":51229677},{"atb":[[11,20.85],[13.5,8.34],[9.4,24.82]],"id":49487602},{"atl":[[310,0.67],[210,0.66]],"id":49487602}],"con":true,"img":false}]}
{"op":"mcm","clk":"10119070851","pt":1700898864279,"mc":[{"id":"1.221675352","rc":[{"spn":5.0,"spf":1.0,"id":51178794},{"spn":11.5,"spf":1.0,"id":61861979},{"atl":[[12,0]],"id":54974498},{"spn":5.9,"spf":1.0,"id":54974498},{"spn":19.0,"spf":1.0,"id":50758683},{"atb":[[11,0]],"id":52386044},{"spn":14.25,"spf":1.0,"id":49487602}],"con":true,"img":false}]}
{"op":"mcm","clk":"10119070865","pt":1700898864381,"mc":[{"id":"1.221675352","rc":[{"atl":[[10.5,10.14]],"id":54974498},{"atb":[[12.5,10.5]],"id":52386044}],"con":true,"img":false}]}
{"op":"mcm","clk":"10119071735","pt":1700898871873,"mc":[{"id":"1.221675352","rc":[{"atb":[[1.82,0],[2.02,155.33]],"id":41132607},{"atl":[[7.2,0],[6,20.48]],"id":41132607},{"atb":[[3.75,0]],"id":51178794},{"atb":[[8.8,0]],"id":61861979},{"atb":[[3,55.77],[2.62,0]],"id":54974498},{"atb":[[12,0],[14.5,7.89],[15,0]],"id":50758683},{"atb":[[10,0]],"id":49487602}],"con":true,"img":false}]}
{"op":"mcm","clk":"10119071744","pt":1700898871977,"mc":[{"id":"1.221675352","rc":[{"atb":[[4.1,42.84]],"id":51178794},{"atb":[[9.8,16.19]],"id":61861979},{"atb":[[3.25,28.01]],"id":54974498},{"atb":[[17,4]],"id":50758683},{"atb":[[11.5,13.23]],"id":49487602}],"con":true,"img":false}]}
{"op":"mcm","clk":"10119076542","pt":1700898917717,"mc":[{"id":"1.221675352","rc":[{"atb":[[2,0],[1.9,0],[1.95,0]],"id":41132607},{"atl":[[6.2,0],[8.2,0]],"id":41132607},{"atb":[[9.6,0],[8.6,0],[11.5,0]],"id":61861979},{"atl":[[280,0],[180,0]],"id":61861979},{"atb":[[3.2,0],[2.88,0],[2.98,0]],"id":54974498},{"atl":[[16,0],[11,0]],"id":54974498},{"atb":[[11,0],[13.5,0],[9.4,0]],"id":49487602},{"atl":[[310,0],[210,0]],"id":49487602}],"con":true,"img":false}]}
{"op":"mcm","clk":"10119078219","pt":1700898933648,"mc":[{"id":"1.221675352","rc":[{"atb":[[2,104.28],[1.9,231.74],[1.95,219.54]],"id":41132607},{"atl":[[6.2,26.76],[8.2,28.99]],"id":41132607},{"atb":[[9.2,25.43],[10.5,10.97],[8.2,28.96]],"id":61861979},{"atl":[[260,0.8],[160,0.87]],"id":61861979},{"spn":10.88,"spf":1.0,"id":61861979},{"atb":[[3.2,47.4],[2.88,110.94],[2.98,105.33]],"id":54974498},{"atl":[[16,13.91],[11,13.91]],"id":54974498},{"spn":5.92,"spf":1.0,"id":54974498},{"atb":[[11,20.85],[13.5,8.34],[9.4,24.82]],"id":49487602},{"atl":[[310,0.67],[210,0.66]],"id":49487602}],"con":true,"img":false}]}
{"op":"mcm","clk":"10119079414","pt":1700898945447,"mc":[{"id":"1.221675352","rc":[{"atb":[[17,0]],"id":50758683},{"atb":[[14,0]],"id":52386044},{"atb":[[12.5,0]],"id":49487602}],"con":true,"img":false}]}
{"op":"mcm","clk":"10119079429","pt":1700898945551,"mc":[{"id":"1.221675352","rc":[{"atb":[[19.5,4]],"id":50758683},{"atb":[[15,4.31]],"id":52386044},{"atb":[[14,4.87]],"id":49487602}],"con":true,"img":false}]}
{"op":"mcm","clk":"10119148649","pt":1700899585873,"mc":[{"id":"1.221675352","rc":[{"atb":[[2,0],[1.9,0],[1.95,0]],"id":41132607},{"atl":[[6.2,0],[8.2,0]],"id":41132607},{"atb":[[4,0],[4.5,16],[5,0]],"id":51178794},{"atl":[[38,0],[24,0]],"id":51178794},{"spn":4.5,"spf":1.0,"id":51178794},{"atb":[[9.2,0],[10.5,0],[8.2,0]],"id":61861979},{"atl":[[260,0],[160,0]],"id":61861979},{"spn":10.73,"spf":1.0,"id":61861979},{"atb":[[3.2,0],[2.88,0],[2.98,0]],"id":54974498},{"atl":[[16,0],[11,0]],"id":54974498},{"atb":[[16.5,0],[19,0],[14,0]],"id":50758683},{"atl":[[260,0],[360,0]],"id":50758683},{"spn":18.04,"spf":1.0,"id":50758683},{"atb":[[5.5,0],[6,21.73],[7,0]],"id":51229677},{"atl":[[95,0],[48,0]],"id":51229677},{"atb":[[12,0],[9.8,0],[14.5,0]],"id":52386044},{"atl":[[320,0],[220,0]],"id":52386044},{"spn":14.36,"spf":1.0,"id":52386044},{"atb":[[11,0],[13.5,0],[9.4,0]],"id":49487602},{"atl":[[310,0],[210,0]],"id":49487602},{"spn":14.5,"spf":1.0,"id":49487602}],"con":true,"img":false}]}
{"op":"mcm","clk":"10119150744","pt":1700899604083,"mc":[{"id":"1.221675352","rc":[{"atb":[[2,104.28],[1.9,231.74],[1.95,219.54]],"id":41132607},{"atl":[[6.2,26.76],[8.2,28.99]],"id":41132607},{"atb":[[4,69.52],[4.5,75.6],[5,26.07]],"id":51178794},{"atl":[[38,5.64],[24,6.05]],"id":51178794},{"atb":[[9.2,25.43],[10.5,10.97],[8.2,28.96]],"id":61861979},{"atl":[[260,0.8],[160,0.87]],"id":61861979},{"atb":[[3.2,47.4],[2.88,110.94],[2.98,105.33]],"id":54974498},{"atl":[[16,13.91],[11,13.91]],"id":54974498},{"atb":[[16.5,13.45],[19,5.79],[14,16.04]],"id":50758683},{"atl":[[260,0.53],[360,0.57]],"id":50758683},{"atb":[[5.5,46.34],[6,63.44],[7,17.38]],"id":51229677},{"atl":[[95,2.22],[48,2.96]],"id":51229677},{"atb":[[12,18.96],[9.8,23.69],[14.5,7.72]],"id":52386044},{"atl":[[320,0.65],[220,0.63]],"id":52386044},{"atb":[[11,20.85],[13.5,8.34],[9.4,24.82]],"id":49487602},{"atl":[[310,0.67],[210,0.66]],"id":49487602}],"con":true,"img":false}]}
{"op":"mcm","clk":"10119156629","pt":1700899654176,"mc":[{"id":"1.221675352","rc":[{"atb":[[2,0],[1.9,0],[1.95,0]],"id":41132607},{"atl":[[6.2,0],[8.2,0]],"id":41132607},{"atb":[[4,0],[4.5,16],[5,0]],"id":51178794},{"atl":[[38,0],[24,0]],"id":51178794},{"atb":[[9.2,0],[10.5,0],[8.2,0]],"id":61861979},{"atl":[[260,0],[160,0]],"id":61861979},{"atb":[[3.2,0],[2.88,0],[2.98,0]],"id":54974498},{"atl":[[16,0],[11,0]],"id":54974498},{"atb":[[16.5,0],[19,0],[14,0]],"id":50758683},{"atl":[[260,0],[360,0]],"id":50758683},{"atb":[[5.5,0],[6,21.73],[7,0]],"id":51229677},{"atl":[[95,0],[48,0]],"id":51229677},{"spn":14.87,"spf":1.0,"id":52386044},{"atb":[[11,0],[13.5,0],[9.4,0]],"id":49487602},{"atl":[[310,0],[210,0]],"id":49487602}],"con":true,"img":false}]}
{"op":"mcm","clk":"10119156904","pt":1700899656780,"mc":[{"id":"1.221675352","rc":[{"atb":[[1.82,124.87]],"id":41132607},{"atl":[[7.2,16.51]],"id":41132607},{"atb":[[2.6,69.71]],"id":54974498}],"con":true,"img":false}]}
{"op":"mcm","clk":"10119156913","pt":1700899656883,"mc":[{"id":"1.221675352","rc":[{"atb":[[2.02,54.93]],"id":41132607},{"atl":[[6,0]],"id":41132607},{"atb":[[3,0],[3.25,0]],"id":54974498},{"atb":[[19.5,0],[14.5,0]],"id":50758683},{"atb":[[14,0]],"id":49487602}],"con":true,"img":false}]}
{"op":"mcm","clk":"10119156926","pt":1700899656984,"mc":[{"id":"1.221675352","rc":[{"atb":[[3,28.01]],"id":54974498},{"atb":[[12.5,7.89],[15.5,4]],"id":50758683},{"atb":[[12.5,4.87]],"id":49487602}],"con":true,"img":false}]}
{"op":"mcm","clk":"10119157266","pt":1700899659959,"mc":[{"id":"1.221675352","rc":[{"atb":[[6.2,9.62]],"id":50758683}],"con":true,"img":false}]}
{"op":"mcm","clk":"10119161128","pt":1700899693552,"mc":[{"id":"1.221675352","rc":[{"atb":[[2,104.28],[1.9,231.74],[1.95,219.54]],"id":41132607},{"atl":[[6.2,26.76],[8.2,28.99]],"id":41132607},{"atb":[[4,69.52],[4.5,75.6],[5,26.07]],"id":51178794},{"atl":[[38,5.64],[24,6.05]],"id":51178794},{"atb":[[9.2,25.43],[10.5,10.97],[8.2,28.96]],"id":61861979},{"atl":[[260,0.8],[160,0.87]],"id":61861979},{"atb":[[3.2,47.4],[2.88,110.94],[2.98,105.33]],"id":54974498},{"atl":[[16,13.91],[11,13.91]],"id":54974498},{"atb":[[16.5,13.45],[19,5.79],[14,16.04]],"id":50758683},{"atl":[[260,0.53],[360,0.57]],"id":50758683},{"atb":[[5.5,46.34],[6,63.44],[7,17.38]],"id":51229677},{"atl":[[95,2.22],[48,2.96]],"id":51229677},{"atb":[[11,20.85],[13.5,8.34],[9.4,24.82]],"id":49487602},{"atl":[[310,0.67],[210,0.66]],"id":49487602}],"con":true,"img":false}]}
{"op":"mcm","clk":"10119165227","pt":1700899730072,"mc":[{"id":"1.221675352","rc":[{"spn":5.0,"spf":1.0,"id":51178794},{"spn":10.88,"spf":1.0,"id":61861979},{"spn":5.9,"spf":1.0,"id":54974498},{"atb":[[15.5,0]],"id":50758683},{"spn":19.0,"spf":1.0,"id":50758683},{"spn":14.25,"spf":1.0,"id":49487602}],"con":true,"img":false}]}
{"op":"mcm","clk":"10119165241","pt":1700899730130,"mc":[{"id":"1.221675352","rc":[{"atb":[[19.5,4]],"id":50758683}],"con":true,"img":false}]}
{"op":"mcm","clk":"10119167779","pt":1700899752211,"mc":[{"id":"1.221675352","rc":[{"atb":[[1.82,0],[2.02,155.33]],"id":41132607},{"atl":[[7.2,0],[6,20.48]],"id":41132607},{"atb":[[3,55.77],[2.6,0]],"id":54974498},{"atb":[[12.5,0]],"id":50758683},{"atb":[[12.5,0]],"id":49487602}],"con":true,"img":false}]}
{"op":"mcm","clk":"10119167787","pt":1700899752313,"mc":[{"id":"1.221675352","rc":[{"atb":[[3.25,28.01]],"id":54974498},{"atb":[[14.5,7.89]],"id":50758683},{"atb":[[14,4.87]],"id":49487602}],"con":true,"img":false}]}
{"op":"mcm","clk":"10119223859","pt":1700900215648,"mc":[{"id":"1.221675352","rc":[{"spl":[[1.01,2.61]],"id":41132607},{"spn":2.02,"spf":1.0,"id":41132607},{"spn":5.92,"spf":1.0,"id":54974498},{"spn":19.35,"spf":1.0,"id":50758683},{"spn":14.5,"spf":1.0,"id":49487602}],"con":true,"img":false}]}
{"op":"mcm","clk":"10119246044","pt":1700900292457,"mc":[{"id":"1.221675352","rc":[{"atl":[[3.1,0]],"id":41132607},{"trd":[[3.1,10.44]],"ltp":3.1,"tv":10.44,"id":41132607}],"con":true,"img":false}]}
{"op":"mcm","clk":"10119251271","pt":1700900332979,"mc":[{"id":"1.221675352","rc":[{"atb":[[2.04,16.71]],"id":41132607}],"con":true,"img":false}]}
{"op":"mcm","clk":"10119255752","pt":1700900367689,"mc":[{"id":"1.221675352","rc":[{"atb":[[2.06,7.48]],"id":41132607},{"spn":2.06,"spf":1.0,"id":41132607}],"con":true,"img":false}]}
{"op":"mcm","clk":"10119259964","pt":1700900400202,"mc":[{"id":"1.221675352","rc":[{"atb":[[2.08,16.72]],"id":41132607},{"atl":[[8.4,13.51]],"id":41132607},{"atb":[[2.52,65.79]],"id":51178794},{"atl":[[17,6.25]],"id":51178794},{"atb":[[5.8,20.83]],"id":61861979},{"atl":[[150,2]],"id":61861979},{"atb":[[2.12,89.29]],"id":54974498},{"atl":[[8.4,10.14]],"id":54974498},{"atb":[[6.6,16.13]],"id":50758683},{"atl":[[170,2]],"id":50758683},{"atb":[[3.2,45.45]],"id":51229677},{"atl":[[32,3.23]],"id":51229677},{"atb":[[1.62,50.32]],"id":52386044},{"atl":[[170,2]],"id":52386044},{"atb":[[4.4,26.46]],"id":49487602},{"atl":[[85,4.61]],"id":49487602}],"con":true,"img":false}]}
{"op":"mcm","clk":"10119262844","pt":1700900422212,"mc":[{"id":"1.221675352","rc":[{"atb":[[7.2,26.56],[6,41.71]],"id":51229677}],"con":true,"img":false}]}
{"op":"mcm","clk":"10119262857","pt":1700900422316,"mc":[{"id":"1.221675352","rc":[{"atb":[[7.2,9.03]],"id":51229677}],"con":true,"img":false}]}
{"op":"mcm","clk":"10119262873","pt":1700900422422,"mc":[{"id":"1.221675352","rc":[{"atb":[[6.2,17.52]],"id":51229677}],"con":true,"img":false}]}
{"op":"mcm","clk":"10119265165","pt":1700900439743,"mc":[{"id":"1.221675352","rc":[{"spn":2.08,"spf":1.0,"id":41132607},{"atb":[[2.52,0],[2.7,58.82]],"id":51178794},{"atl":[[17,0],[13.5,6.25]],"id":51178794},{"atb":[[5.8,0],[3.35,42.55]],"id":61861979},{"spn":5.82,"spf":1.0,"id":54974498},{"atl":[[80,2],[85,2.61]],"id":49487602}],"con":true,"img":false}]}
{"op":"mcm","clk":"10119265199","pt":1700900439948,"mc":[{"id":"1.221675352","rc":[{"atb":[[3.35,0],[6,20]],"id":61861979}],"con":true,"img":false}]}
{"op":"mcm","clk":"10119265356","pt":1700900441144,"mc":[{"id":"1.221675352","rc":[{"atl":[[30,3.74]],"id":51229677}],"con":true,"img":false}]}
{"op":"mcm","clk":"10119265364","pt":1700900441247,"mc":[{"id":"1.221675352","rc":[{"atl":[[38,0]],"id":51229677}],"con":true,"img":false}]}
{"op":"mcm","clk":"10119268104","pt":1700900463769,"mc":[{"id":"1.221675352","rc":[{"atb":[[2,0],[1.9,0],[1.95,0]],"id":41132607},{"atl":[[6.2,0],[8.2,0]],"id":41132607},{"atb":[[4,0],[4.5,16],[5,0]],"id":51178794},{"atl":[[38,0],[24,0]],"id":51178794},{"atb":[[9.2,0],[10.5,0],[8.2,0]],"id":61861979},{"atl":[[260,0],[160,0]],"id":61861979},{"atb":[[3.2,0],[2.88,0],[2.98,0]],"id":54974498},{"atl":[[16,0],[11,0]],"id":54974498},{"atb":[[16.5,0],[19,0],[14,0]],"id":50758683},{"atl":[[260,0],[360,0]],"id":50758683},{"atb":[[5.5,0],[6,0],[7,0]],"id":51229677},{"atl":[[95,0],[48,0]],"id":51229677},{"atb":[[12,0],[9.8,0],[14.5,0]],"id":52386044},{"atl":[[320,0],[220,0]],"id":52386044},{"atb":[[11,0],[13.5,0],[9.4,0]],"id":49487602},{"atl":[[310,0],[210,0]],"id":49487602}],"con":true,"img":false}]}
{"op":"mcm","clk":"10119269859","pt":1700900478867,"mc":[{"id":"1.221675352","rc":[{"atb":[[2,104.28],[1.9,231.74],[1.95,219.54]],"id":41132607},{"atl":[[6.2,26.76],[8.2,28.99]],"id":41132607},{"atb":[[4,69.52],[4.5,75.6],[5,26.07]],"id":51178794},{"atl":[[38,5.64],[24,6.05]],"id":51178794},{"atb":[[9.2,25.43],[10.5,10.97],[8.2,28.96]],"id":61861979},{"atl":[[260,0.8],[160,0.87]],"id":61861979},{"atb":[[3.2,47.4],[2.88,110.94],[2.98,105.33]],"id":54974498},{"atl":[[16,13.91],[11,13.91]],"id":54974498},{"atb":[[16.5,13.45],[19,5.79],[14,16.04]],"id":50758683},{"atl":[[260,0.53],[360,0.57]],"id":50758683},{"atb":[[5.5,46.34],[6,41.71],[7,17.38]],"id":51229677},{"atl":[[95,2.22],[48,2.96]],"id":51229677},{"atb":[[12,18.96],[9.8,23.69],[14.5,7.72]],"id":52386044},{"atl":[[320,0.65],[220,0.63]],"id":52386044},{"atb":[[11,20.85],[13.5,8.34],[9.4,24.82]],"id":49487602},{"atl":[[310,0.67],[210,0.66]],"id":49487602}],"con":true,"img":false}]}
{"op":"mcm","clk":"10119271972","pt":1700900496302,"mc":[{"id":"1.221675352","rc":[{"atb":[[2.02,100.39]],"id":41132607},{"atl":[[48,0]],"id":61861979},{"atb":[[6.2,0]],"id":51229677},{"atl":[[85,0]],"id":49487602}],"con":true,"img":false}]}
{"op":"mcm","clk":"10119271984","pt":1700900496405,"mc":[{"id":"1.221675352","rc":[{"atb":[[2.06,62.42]],"id":41132607},{"atl":[[46,2.61]],"id":61861979},{"atb":[[7.2,26.56]],"id":51229677},{"atl":[[75,2.61]],"id":49487602}],"con":true,"img":false}]}
{"op":"mcm","clk":"10119274866","pt":1700900519321,"mc":[{"id":"1.221675352","rc":[{"atb":[[2.04,0]],"id":41132607}],"con":true,"img":false}]}
{"op":"mcm","clk":"10119277677","pt":1700900541532,"mc":[{"id":"1.221675352","rc":[{"atb":[[2.08,32.81]],"id":41132607}],"con":true,"img":false}]}
{"op":"mcm","clk":"10119278064","pt":1700900544735,"mc":[{"id":"1.221675352","rc":[{"atb":[[2,0],[1.9,0],[1.95,0]],"id":41132607},{"atl":[[6.2,0],[8.2,0]],"id":41132607},{"atb":[[4,0],[4.5,16],[5,0]],"id":51178794},{"atl":[[38,0],[24,0]],"id":51178794},{"atb":[[9.2,0],[10.5,0],[8.2,0]],"id":61861979},{"atl":[[260,0],[160,0]],"id":61861979},{"atb":[[3.2,0],[2.88,0],[2.98,0]],"id":54974498},{"atl":[[16,0],[11,0]],"id":54974498},{"atb":[[16.5,0],[19,0],[14,0]],"id":50758683},{"atl":[[260,0],[360,0]],"id":50758683},{"atb":[[5.5,0],[6,0],[7,0]],"id":51229677},{"atl":[[95,0],[48,0]],"id":51229677},{"atb":[[11,0],[13.5,0],[9.4,0]],"id":49487602},{"atl":[[310,0],[210,0]],"id":49487602}],"con":true,"img":false}]}
{"op":"mcm","clk":"10119279193","pt":1700900553376,"mc":[{"id":"1.221675352","rc":[{"atb":[[1.82,124.87],[2.02,0]],"id":41132607},{"atl":[[6,0],[7,14.22]],"id":41132607},{"atb":[[3,0],[2.6,69.71],[3.25,0]],"id":54974498},{"atb":[[19.5,0],[14.5,0]],"id":50758683},{"atb":[[7.2,9.03],[6,21.73]],"id":51229677},{"atb":[[14,0]],"id":49487602}],"con":true,"img":false}]}
{"op":"mcm","clk":"10119279205","pt":1700900553445,"mc":[{"id":"1.221675352","rc":[{"atb":[[3,28.01]],"id":54974498},{"atb":[[12.5,7.89],[15.5,4]],"id":50758683},{"atb":[[12.5,4.87]],"id":49487602}],"con":true,"img":false}]}
{"op":"mcm","clk":"10119279219","pt":1700900553550,"mc":[{"id":"1.221675352","rc":[{"atb":[[6.4,18.52],[6.6,0]],"id":50758683}],"con":true,"img":false}]}
{"op":"mcm","clk":"10119279479","pt":1700900555644,"mc":[{"id":"1.221675352","rc":[{"atb":[[2,104.28],[1.9,231.74],[1.95,219.54]],"id":41132607},{"atl":[[6.2,26.76],[8.2,28.99]],"id":41132607},{"atb":[[4,69.52],[4.5,75.6],[5,26.07]],"id":51178794},{"atl":[[38,5.64],[24,6.05]],"id":51178794},{"atb":[[9.2,25.43],[10.5,10.97],[8.2,28.96]],"id":61861979},{"atl":[[260,0.8],[160,0.87]],"id":61861979},{"atb":[[3.2,47.4],[2.88,110.94],[2.98,105.33]],"id":54974498},{"atl":[[16,13.91],[11,13.91]],"id":54974498},{"atb":[[16.5,13.45],[19,5.79],[14,16.04]],"id":50758683},{"atl":[[260,0.53],[360,0.57]],"id":50758683},{"atb":[[5.5,46.34],[6,63.44],[7,17.38]],"id":51229677},{"atl":[[95,2.22],[48,2.96]],"id":51229677},{"atb":[[11,20.85],[13.5,8.34],[9.4,24.82]],"id":49487602},{"atl":[[310,0.67],[210,0.66]],"id":49487602}],"con":true,"img":false}]}
{"op":"mcm","clk":"10119279994","pt":1700900559648,"mc":[{"id":"1.221675352","rc":[{"atb":[[2.58,63.29],[2.7,0]],"id":51178794},{"atl":[[13.5,0],[14,12]],"id":51178794},{"atl":[[80,0],[85,2]],"id":49487602}],"con":true,"img":false}]}
{"op":"mcm","clk":"10119281596","pt":1700900571620,"mc":[{"id":"1.221675352","rc":[{"atl":[[75,0]],"id":49487602}],"con":true,"img":false}]}
{"op":"mcm","clk":"10119281608","pt":1700900571719,"mc":[{"id":"1.221675352","rc":[{"atl":[[80,2.61]],"id":49487602}],"con":true,"img":false}]}
{"op":"mcm","clk":"10119281635","pt":1700900571926,"mc":[{"id":"1.221675352","rc":[{"atl":[[1000,0.86]],"id":50758683},{"atl":[[1000,0.86]],"id":51229677},{"atl":[[1000,0.86]],"id":52386044},{"atl":[[1000,0.86]],"id":49487602}],"con":true,"img":false}]}
{"op":"mcm","clk":"10119281667","pt":1700900572134,"mc":[{"id":"1.221675352","rc":[{"atl":[[1000,0.09]],"id":50758683},{"atl":[[1000,0.33]],"id":51229677},{"atl":[[1000,0.11]],"id":52386044}],"con":true,"img":false}]}
{"op":"mcm","clk":"10119281708","pt":1700900572408,"mc":[{"id":"1.221675352","rc":[{"atl":[[1000,0.14]],"id":49487602}],"con":true,"img":false}]}
{"op":"mcm","clk":"10119281732","pt":1700900572618,"mc":[{"id":"1.221675352","rc":[{"atl":[[1000,0]],"id":50758683}],"con":true,"img":false}]}
{"op":"mcm","clk":"10119281746","pt":1700900572711,"mc":[{"id":"1.221675352","rc":[{"atl":[[90,0.09]],"id":50758683}],"con":true,"img":false}]}
{"op":"mcm","clk":"10119281791","pt":1700900573012,"mc":[{"id":"1.221675352","rc":[{"atl":[[1000,0]],"id":52386044}],"con":true,"img":false}]}
{"op":"mcm","clk":"10119281808","pt":1700900573117,"mc":[{"id":"1.221675352","rc":[{"atl":[[75,0.11]],"id":52386044}],"con":true,"img":false}]}
{"op":"mcm","clk":"10119281851","pt":1700900573421,"mc":[{"id":"1.221675352","rc":[{"atl":[[1000,0]],"id":51229677}],"con":true,"img":false}]}
{"op":"mcm","clk":"10119281867","pt":1700900573523,"mc":[{"id":"1.221675352","rc":[{"atl":[[26,0.33]],"id":51229677}],"con":true,"img":false}]}
{"op":"mcm","clk":"10119281947","pt":1700900574146,"mc":[{"id":"1.221675352","rc":[{"atl":[[1000,0]],"id":49487602}],"con":true,"img":false}]}
{"op":"mcm","clk":"10119281966","pt":1700900574252,"mc":[{"id":"1.221675352","rc":[{"atl":[[60,0.14]],"id":49487602}],"con":true,"img":false}]}
{"op":"mcm","clk":"10119282499","pt":1700900578630,"mc":[{"id":"1.221675352","rc":[{"atb":[[2.06,54.93]],"id":41132607}],"con":true,"img":false}]}
{"op":"mcm","clk":"10119284376","pt":1700900592638,"mc":[{"id":"1.221675352","rc":[{"atb":[[3,0]],"id":54974498},{"spn":5.8,"spf":1.0,"id":54974498},{"spn":19.0,"spf":1.0,"id":50758683},{"spn":14.25,"spf":1.0,"id":49487602}],"con":true,"img":false}]}
{"op":"mcm","clk":"10119284390","pt":1700900592752,"mc":[{"id":"1.221675352","rc":[{"atb":[[3.25,28.01]],"id":54974498}],"con":true,"img":false}]}
{"op":"mcm","clk":"10119285619","pt":1700900602467,"mc":[{"id":"1.221675352","rc":[{"atb":[[2.04,7.63]],"id":41132607}],"con":true,"img":false}]}
{"op":"mcm","clk":"10119287774","pt":1700900618181,"mc":[{"id":"1.221675352","rc":[{"atb":[[1.82,0],[2.02,100.39]],"id":41132607},{"atl":[[6,20.48],[7,0]],"id":41132607},{"atl":[[14,7.69]],"id":51178794},{"atb":[[3,55.77],[2.6,0]],"id":54974498},{"atb":[[12.5,0],[15.5,0]],"id":50758683},{"atb":[[6,41.71]],"id":51229677},{"atb":[[12.5,0]],"id":49487602}],"con":true,"img":false}]}
{"op":"mcm","clk":"10119287809","pt":1700900618284,"mc":[{"id":"1.221675352","rc":[{"atl":[[19,5.56],[13.5,4.31],[14,0]],"id":51178794},{"atb":[[19.5,4],[14.5,7.89]],"id":50758683},{"atb":[[6.2,21.73]],"id":51229677},{"atb":[[14,4.87]],"id":49487602}],"con":true,"img":false}]}
{"op":"mcm","clk":"10119287821","pt":1700900618388,"mc":[{"id":"1.221675352","rc":[{"atl":[[14,7.69]],"id":51178794}],"con":true,"img":false}]}
{"op":"mcm","clk":"10119287834","pt":1700900618492,"mc":[{"id":"1.221675352","rc":[{"atl":[[19,0]],"id":51178794}],"con":true,"img":false}]}
{"op":"mcm","clk":"10119290057","pt":1700900635224,"mc":[{"id":"1.221675352","rc":[{"atl":[[13,6.37],[14,0]],"id":51178794},{"atb":[[6,0],[3.65,37.74]],"id":61861979},{"atb":[[2.22,81.97],[2.12,0]],"id":54974498},{"atl":[[80,4.61],[85,0]],"id":49487602}],"con":true,"img":false}]}
{"op":"mcm","clk":"10119290081","pt":1700900635384,"mc":[{"id":"1.221675352","rc":[{"atl":[[60,0],[1000,0.86]],"id":49487602}],"con":true,"img":false}]}
{"op":"mcm","clk":"10119290112","pt":1700900635690,"mc":[{"id":"1.221675352","rc":[{"atl":[[1000,0.14]],"id":49487602}],"con":true,"img":false}]}
{"op":"mcm","clk":"10119290140","pt":1700900635895,"mc":[{"id":"1.221675352","rc":[{"atl":[[1000,0]],"id":49487602}],"con":true,"img":false}]}
{"op":"mcm","clk":"10119290153","pt":1700900635998,"mc":[{"id":"1.221675352","rc":[{"atl":[[75,0.14]],"id":49487602}],"con":true,"img":false}]}
{"op":"mcm","clk":"10119292167","pt":1700900652000,"mc":[{"id":"1.221675352","rc":[{"atb":[[2.04,0]],"id":41132607}],"con":true,"img":false}]}
{"op":"mcm","clk":"10119292193","pt":1700900652206,"mc":[{"id":"1.221675352","rc":[{"atl":[[1000,0.86]],"id":49487602}],"con":true,"img":false}]}
{"op":"mcm","clk":"10119292208","pt":1700900652312,"mc":[{"id":"1.221675352","rc":[{"atl":[[75,0]],"id":49487602}],"con":true,"img":false}]}
{"op":"mcm","clk":"10119292229","pt":1700900652524,"mc":[{"id":"1.221675352","rc":[{"atl":[[1000,0.15]],"id":49487602}],"con":true,"img":false}]}
{"op":"mcm","clk":"10119292262","pt":1700900652829,"mc":[{"id":"1.221675352","rc":[{"spn":5.82,"spf":1.0,"id":54974498},{"spn":19.35,"spf":1.0,"id":50758683},{"atl":[[1000,0]],"id":49487602},{"spn":14.5,"spf":1.0,"id":49487602}],"con":true,"img":false}]}
{"op":"mcm","clk":"10119292276","pt":1700900652930,"mc":[{"id":"1.221675352","rc":[{"atl":[[55,0.15]],"id":49487602}],"con":true,"img":false}]}
{"op":"mcm","clk":"10119293438","pt":1700900662049,"mc":[{"id":"1.221675352","rc":[{"atl":[[55,0],[1000,0.86]],"id":49487602}],"con":true,"img":false}]}
{"op":"mcm","clk":"10119293468","pt":1700900662319,"mc":[{"id":"1.221675352","rc":[{"atl":[[1000,0.15]],"id":49487602}],"con":true,"img":false}]}
{"op":"mcm","clk":"10119293571","pt":1700900663143,"mc":[{"id":"1.221675352","rc":[{"atl":[[1000,0]],"id":49487602}],"con":true,"img":false}]}
{"op":"mcm","clk":"10119293586","pt":1700900663246,"mc":[{"id":"1.221675352","rc":[{"atl":[[60,0.15]],"id":49487602}],"con":true,"img":false}]}
{"op":"mcm","clk":"10119294438","pt":1700900670027,"mc":[{"id":"1.221675352","rc":[{"atb":[[6.4,18.52],[3.65,0]],"id":61861979}],"con":true,"img":false}]}
{"op":"mcm","clk":"10119295886","pt":1700900679737,"mc":[{"id":"1.221675352","rc":[{"atb":[[2.58,0],[2.7,58.82]],"id":51178794},{"atl":[[13,0],[13.5,12.31]],"id":51178794},{"atb":[[6.4,0],[3.65,37.74]],"id":61861979}],"con":true,"img":false}]}
{"op":"mcm","clk":"10119296252","pt":1700900682665,"mc":[{"id":"1.221675352","rc":[{"atb":[[7.2,26.56]],"id":51229677}],"con":true,"img":false}]}
{"op":"mcm","clk":"10119296259","pt":1700900682759,"mc":[{"id":"1.221675352","rc":[{"atb":[[6.2,0]],"id":51229677}],"con":true,"img":false}]}
{"op":"mcm","clk":"10119296282","pt":1700900682963,"mc":[{"id":"1.221675352","rc":[{"atb":[[7.2,9.03]],"id":51229677}],"con":true,"img":false}]}
{"op":"mcm","clk":"10119296295","pt":1700900683067,"mc":[{"id":"1.221675352","rc":[{"atb":[[6.4,17.52]],"id":51229677}],"con":true,"img":false}]}
{"op":"mcm","clk":"10119300261","pt":1700900714095,"mc":[{"id":"1.221675352","rc":[{"atb":[[6,20],[3.65,0]],"id":61861979}],"con":true,"img":false}]}
{"op":"mcm","clk":"10119304067","pt":1700900743034,"mc":[{"id":"1.221675352","rc":[{"atb":[[6.4,0]],"id":51229677}],"con":true,"img":false}]}
{"op":"mcm","clk":"10119304079","pt":1700900743130,"mc":[{"id":"1.221675352","rc":[{"atb":[[7.2,26.56]],"id":51229677}],"con":true,"img":false}]}
{"op":"mcm","clk":"10119306644","pt":1700900762246,"mc":[{"id":"1.221675352","rc":[{"atb":[[7.2,9.03]],"id":51229677}],"con":true,"img":false}]}
{"op":"mcm","clk":"10119306658","pt":1700900762340,"mc":[{"id":"1.221675352","rc":[{"atb":[[6.2,17.52]],"id":51229677}],"con":true,"img":false}]}
{"op":"mcm","clk":"10119311625","pt":1700900799756,"mc":[{"id":"1.221675352","rc":[{"atb":[[2.58,63.29],[2.7,0]],"id":51178794},{"atl":[[13.5,4.31],[14,7.69]],"id":51178794},{"atl":[[80,2.61],[85,2]],"id":49487602}],"con":true,"img":false}]}
{"op":"mcm","clk":"10119316594","pt":1700900837244,"mc":[{"id":"1.221675352","rc":[{"atb":[[6.2,0]],"id":51229677}],"con":true,"img":false}]}
{"op":"mcm","clk":"10119316604","pt":1700900837348,"mc":[{"id":"1.221675352","rc":[{"atb":[[7.2,26.56]],"id":51229677}],"con":true,"img":false}]}
{"op":"mcm","clk":"10119317107","pt":1700900841262,"mc":[{"id":"1.221675352","rc":[{"atb":[[2,0],[1.9,0],[1.95,0]],"id":41132607},{"atl":[[6.2,0],[8.2,0]],"id":41132607},{"atb":[[4,0],[4.5,16],[5,0]],"id":51178794},{"atl":[[38,0],[24,0]],"id":51178794},{"atb":[[9.2,0],[10.5,0],[8.2,0]],"id":61861979},{"atl":[[260,0],[160,0]],"id":61861979},{"atb":[[3.2,0],[2.88,0],[2.98,0]],"id":54974498},{"atl":[[16,0],[11,0]],"id":54974498},{"atb":[[16.5,0],[19,0],[14,0]],"id":50758683},{"atl":[[260,0],[360,0]],"id":50758683},{"atb":[[5.5,0],[6,0],[7,0]],"id":51229677},{"atl":[[95,0],[48,0]],"id":51229677},{"atb":[[12,0],[9.8,0],[14.5,0]],"id":52386044},{"atl":[[320,0],[220,0]],"id":52386044},{"atb":[[11,0],[13.5,0],[9.4,0]],"id":49487602},{"atl":[[310,0],[210,0]],"id":49487602}],"con":true,"img":false}]}
{"op":"mcm","clk":"10119318383","pt":1700900850700,"mc":[{"id":"1.221675352","rc":[{"spl":[[1.01,36.57]],"id":54974498}],"con":true,"img":false}]}
{"op":"mcm","clk":"10119319138","pt":1700900856524,"mc":[{"id":"1.221675352","rc":[{"atb":[[2,104.28],[1.9,231.74],[1.95,219.54]],"id":41132607},{"atl":[[6.2,26.76],[8.2,28.99]],"id":41132607},{"atb":[[4,69.52],[4.5,75.6],[5,26.07]],"id":51178794},{"atl":[[38,5.64],[24,6.05]],"id":51178794},{"atb":[[9.2,25.43],[10.5,10.97],[8.2,28.96]],"id":61861979},{"atl":[[260,0.8],[160,0.87]],"id":61861979},{"atb":[[3.2,47.4],[2.88,110.94],[2.98,105.33]],"id":54974498},{"atl":[[16,13.91],[11,13.91]],"id":54974498},{"atb":[[16.5,13.45],[19,5.79],[14,16.04]],"id":50758683},{"atl":[[260,0.53],[360,0.57]],"id":50758683},{"atb":[[5.5,46.34],[6,41.71],[7,17.38]],"id":51229677},{"atl":[[95,2.22],[48,2.96]],"id":51229677},{"atb":[[12,18.96],[9.8,23.69],[14.5,7.72]],"id":52386044},{"atl":[[320,0.65],[220,0.63]],"id":52386044},{"atb":[[11,20.85],[13.5,8.34],[9.4,24.82]],"id":49487602},{"atl":[[310,0.67],[210,0.66]],"id":49487602}],"con":true,"img":false}]}
{"op":"mcm","clk":"10119319148","pt":1700900856585,"mc":[{"id":"1.221675352","rc":[{"atb":[[1.82,124.87],[2.02,0]],"id":41132607},{"atl":[[6,0],[7,14.22]],"id":41132607},{"atb":[[3,0],[2.6,69.71],[3.25,0]],"id":54974498},{"atb":[[19.5,0],[14.5,0]],"id":50758683},{"atb":[[7.2,9.03],[6,63.44]],"id":51229677},{"atb":[[14,0]],"id":49487602}],"con":true,"img":false}]}
{"op":"mcm","clk":"10119319154","pt":1700900856679,"mc":[{"id":"1.221675352","rc":[{"atb":[[3,28.01]],"id":54974498},{"atb":[[12.5,7.89],[15.5,4]],"id":50758683},{"atb":[[12.5,4.87]],"id":49487602}],"con":true,"img":false}]}
{"op":"mcm","clk":"10119319241","pt":1700900857304,"mc":[{"id":"1.221675352","rc":[{"spl":[[1.01,10.44]],"id":61861979}],"con":true,"img":false}]}
{"op":"mcm","clk":"10119320131","pt":1700900863911,"mc":[{"id":"1.221675352","rc":[{"spn":10.61,"spf":1.0,"id":61861979},{"spn":3.2,"spf":1.0,"id":54974498},{"spn":19.0,"spf":1.0,"id":50758683},{"spl":[[1.01,5.22]],"id":49487602},{"spn":13.5,"spf":1.0,"id":49487602}],"con":true,"img":false}]}
{"op":"mcm","clk":"10119324653","pt":1700900897850,"mc":[{"id":"1.221675352","rc":[{"atb":[[3,0]],"id":54974498}],"con":true,"img":false}]}
{"op":"mcm","clk":"10119324671","pt":1700900897955,"mc":[{"id":"1.221675352","rc":[{"atb":[[3.25,28.01]],"id":54974498}],"con":true,"img":false}]}
{"op":"mcm","clk":"10119327133","pt":1700900916877,"mc":[{"id":"1.221675352","rc":[{"atb":[[1.82,0],[2.02,100.39]],"id":41132607},{"atl":[[6,20.48],[7,0]],"id":41132607},{"atb":[[3,55.77],[2.6,0]],"id":54974498},{"atb":[[12.5,0],[15.5,0]],"id":50758683},{"atb":[[6,41.71]],"id":51229677},{"atb":[[12.5,0]],"id":49487602}],"con":true,"img":false}]}
{"op":"mcm","clk":"10119327147","pt":1700900916981,"mc":[{"id":"1.221675352","rc":[{"atb":[[19.5,4],[14.5,7.89]],"id":50758683},{"atb":[[6.2,21.73]],"id":51229677},{"atb":[[14,4.87]],"id":49487602}],"con":true,"img":false}]}
{"op":"mcm","clk":"10119331316","pt":1700900949091,"mc":[{"id":"1.221675352","rc":[{"atb":[[2,0],[1.9,0],[1.95,0]],"id":41132607},{"atl":[[6.2,0],[8.2,0]],"id":41132607},{"atb":[[4,0],[4.5,16],[5,0]],"id":51178794},{"atl":[[38,0],[24,0]],"id":51178794},{"spn":4.5,"spf":1.0,"id":51178794},{"atb":[[9.2,0],[10.5,0],[8.2,0]],"id":61861979},{"atl":[[260,0],[160,0]],"id":61861979},{"spn":10.18,"spf":1.0,"id":61861979},{"atb":[[3.2,0],[2.88,0],[2.98,0]],"id":54974498},{"atl":[[16,0],[11,0]],"id":54974498},{"spn":3.19,"spf":1.0,"id":54974498},{"atb":[[16.5,0],[19,0],[14,0]],"id":50758683},{"atl":[[260,0],[360,0]],"id":50758683},{"spn":18.04,"spf":1.0,"id":50758683},{"atb":[[5.5,0],[6,0],[7,0]],"id":51229677},{"atl":[[95,0],[48,0]],"id":51229677},{"atb":[[11,0],[13.5,0],[9.4,0]],"id":49487602},{"atl":[[310,0],[210,0]],"id":49487602},{"spn":13.83,"spf":1.0,"id":49487602}],"con":true,"img":false}]}
{"op":"mcm","clk":"10119332361","pt":1700900956890,"mc":[{"id":"1.221675352","rc":[{"atb":[[1.82,124.87],[2.02,0]],"id":41132607},{"atl":[[6,0],[7,14.22]],"id":41132607},{"atb":[[3,0],[2.6,69.71],[3.25,0]],"id":54974498},{"atb":[[19.5,0],[14.5,0]],"id":50758683},{"atb":[[14,0]],"id":49487602}],"con":true,"img":false}]}
{"op":"mcm","clk":"10119332384","pt":1700900957043,"mc":[{"id":"1.221675352","rc":[{"atb":[[3,28.01]],"id":54974498},{"atb":[[12.5,7.89],[15.5,4]],"id":50758683},{"atb":[[12.5,4.87]],"id":49487602}],"con":true,"img":false}]}
{"op":"mcm","clk":"10119333261","pt":1700900963510,"mc":[{"id":"1.221675352","rc":[{"atb":[[2,104.28],[1.9,231.74],[1.95,219.54]],"id":41132607},{"atl":[[6.2,26.76],[8.2,28.99]],"id":41132607},{"atb":[[4,69.52],[4.5,75.6],[5,26.07]],"id":51178794},{"atl":[[38,5.64],[24,6.05]],"id":51178794},{"atb":[[9.2,25.43],[10.5,10.97],[8.2,28.96]],"id":61861979},{"atl":[[260,0.8],[160,0.87]],"id":61861979},{"atb":[[3.2,47.4],[2.88,110.94],[2.98,105.33]],"id":54974498},{"atl":[[16,13.91],[11,13.91]],"id":54974498},{"atb":[[16.5,13.45],[19,5.79],[14,16.04]],"id":50758683},{"atl":[[260,0.53],[360,0.57]],"id":50758683},{"atb":[[5.5,46.34],[6,41.71],[7,17.38]],"id":51229677},{"atl":[[95,2.22],[48,2.96]],"id":51229677},{"atb":[[11,20.85],[13.5,8.34],[9.4,24.82]],"id":49487602},{"atl":[[310,0.67],[210,0.66]],"id":49487602}],"con":true,"img":false}]}
{"op":"mcm","clk":"10119337723","pt":1700900998973,"mc":[{"id":"1.221675352","rc":[{"atb":[[3,0]],"id":54974498}],"con":true,"img":false}]}
{"op":"mcm","clk":"10119337748","pt":1700900999080,"mc":[{"id":"1.221675352","rc":[{"atb":[[3.25,28.01]],"id":54974498}],"con":true,"img":false}]}
{"op":"mcm","clk":"10119337990","pt":1700901000883,"mc":[{"id":"1.221675352","rc":[{"atb":[[2.04,7.63]],"id":41132607}],"con":true,"img":false}]}
{"op":"mcm","clk":"10119340839","pt":1700901019405,"mc":[{"id":"1.221675352","rc":[{"atb":[[1.82,0],[2.02,100.39]],"id":41132607},{"atl":[[6,20.48],[7,0]],"id":41132607},{"spn":5.0,"spf":1.0,"id":51178794},{"spn":10.61,"spf":1.0,"id":61861979},{"atb":[[3,55.77],[2.6,0]],"id":54974498},{"spn":3.23,"spf":1.0,"id":54974498},{"atb":[[12.5,0],[15.5,0]],"id":50758683},{"spn":19.0,"spf":1.0,"id":50758683},{"atb":[[12.5,0]],"id":49487602},{"spn":13.5,"spf":1.0,"id":49487602}],"con":true,"img":false}]}
{"op":"mcm","clk":"10119340848","pt":1700901019457,"mc":[{"id":"1.221675352","rc":[{"atb":[[19.5,4],[14.5,7.89]],"id":50758683},{"atb":[[14,4.87]],"id":49487602}],"con":true,"img":false}]}
{"op":"mcm","clk":"10119348269","pt":1700901074247,"mc":[{"id":"1.221675352","rc":[{"atb":[[2.04,0]],"id":41132607}],"con":true,"img":false}]}
{"op":"mcm","clk":"10119349533","pt":1700901083593,"mc":[{"id":"1.221675352","rc":[{"spn":19.35,"spf":1.0,"id":50758683},{"atb":[[7.2,26.56],[6.2,0]],"id":51229677},{"spn":13.96,"spf":1.0,"id":49487602}],"con":true,"img":false}]}
{"op":"mcm","clk":"10119350517","pt":1700901091480,"mc":[{"id":"1.221675352","rc":[{"atl":[[13,6.37],[14,0]],"id":51178794},{"atb":[[3.85,35.09],[6,0]],"id":61861979},{"atb":[[7.2,9.03]],"id":51229677},{"atl":[[80,4.61]],"id":49487602}],"con":true,"img":false}]}
{"op":"mcm","clk":"10119350537","pt":1700901091585,"mc":[{"id":"1.221675352","rc":[{"atb":[[3.85,0],[6.4,18.52]],"id":61861979},{"atb":[[6.2,17.52]],"id":51229677},{"atl":[[85,0]],"id":49487602}],"con":true,"img":false}]}
{"op":"mcm","clk":"10119350545","pt":1700901091641,"mc":[{"id":"1.221675352","rc":[{"atl":[[60,0],[1000,0.86]],"id":49487602}],"con":true,"img":false}]}
{"op":"mcm","clk":"10119350578","pt":1700901091857,"mc":[{"id":"1.221675352","rc":[{"atl":[[1000,0.15]],"id":49487602}],"con":true,"img":false}]}
{"op":"mcm","clk":"10119350633","pt":1700901092263,"mc":[{"id":"1.221675352","rc":[{"atb":[[3,0]],"id":54974498}],"con":true,"img":false}]}
{"op":"mcm","clk":"10119350653","pt":1700901092376,"mc":[{"id":"1.221675352","rc":[{"atb":[[2.9,55.77]],"id":54974498}],"con":true,"img":false}]}
{"op":"mcm","clk":"10119350697","pt":1700901092878,"mc":[{"id":"1.221675352","rc":[{"atl":[[1000,0]],"id":49487602}],"con":true,"img":false}]}
{"op":"mcm","clk":"10119350712","pt":1700901092936,"mc":[{"id":"1.221675352","rc":[{"atl":[[75,0.15]],"id":49487602}],"con":true,"img":false}]}
{"op":"mcm","clk":"10119351466","pt":1700901099703,"mc":[{"id":"1.221675352","rc":[{"atb":[[2.58,0],[2.7,58.82]],"id":51178794},{"atl":[[13,0],[13.5,12.31]],"id":51178794},{"atb":[[6.4,0],[3.85,35.09]],"id":61861979}],"con":true,"img":false}]}
{"op":"mcm","clk":"10119351514","pt":1700901100006,"mc":[{"id":"1.221675352","rc":[{"atl":[[75,0],[1000,0.86]],"id":49487602}],"con":true,"img":false}]}
{"op":"mcm","clk":"10119351543","pt":1700901100173,"mc":[{"id":"1.221675352","rc":[{"atl":[[1000,0.15]],"id":49487602}],"con":true,"img":false}]}
{"op":"mcm","clk":"10119351566","pt":1700901100375,"mc":[{"id":"1.221675352","rc":[{"atl":[[1000,0]],"id":49487602}],"con":true,"img":false}]}
{"op":"mcm","clk":"10119351578","pt":1700901100476,"mc":[{"id":"1.221675352","rc":[{"atl":[[55,0.15]],"id":49487602}],"con":true,"img":false}]}
{"op":"mcm","clk":"10119351762","pt":1700901101875,"mc":[{"id":"1.221675352","rc":[{"atb":[[2.06,62.42]],"id":41132607}],"con":true,"img":false}]}
{"op":"mcm","clk":"10119351921","pt":1700901103181,"mc":[{"id":"1.221675352","rc":[{"atb":[[3.25,0]],"id":54974498}],"con":true,"img":false}]}
{"op":"mcm","clk":"10119351937","pt":1700901103288,"mc":[{"id":"1.221675352","rc":[{"atb":[[3.05,28.01]],"id":54974498}],"con":true,"img":false}]}
{"op":"mcm","clk":"10119352883","pt":1700901111093,"mc":[{"id":"1.221675352","rc":[{"atb":[[3.55,0.18]],"id":41132607},{"atl":[[3.55,0]],"id":41132607},{"trd":[[3.55,15.67]],"ltp":3.55,"tv":15.67,"id":41132607}],"con":true,"img":false}]}
{"op":"mcm","clk":"10119352896","pt":1700901111196,"mc":[{"id":"1.221675352","rc":[{"atb":[[2.42,11.49]],"id":41132607}],"con":true,"img":false}]}
{"op":"mcm","clk":"10119352914","pt":1700901111402,"mc":[{"id":"1.221675352","rc":[{"atl":[[3.75,7.83]],"id":41132607}],"con":true,"img":false}]}
{"op":"mcm","clk":"10119353014","pt":1700901112123,"mc":[{"id":"1.221675352","rc":[{"atl":[[7.4,15.62],[8.4,0]],"id":41132607},{"atl":[[150,0],[95,2]],"id":61861979},{"atl":[[130,2],[170,0]],"id":50758683},{"atl":[[130,2],[170,0]],"id":52386044},{"atl":[[65,4.61],[80,2.61]],"id":49487602}],"con":true,"img":false}]}
{"op":"mcm","clk":"10119353042","pt":1700901112336,"mc":[{"id":"1.221675352","rc":[{"atl":[[65,2.61],[75,2]],"id":49487602}],"con":true,"img":false}]}
{"op":"mcm","clk":"10119353066","pt":1700901112498,"mc":[{"id":"1.221675352","rc":[{"atl":[[65,4.61],[75,0]],"id":49487602}],"con":true,"img":false}]}
{"op":"mcm","clk":"10119353089","pt":1700901112702,"mc":[{"id":"1.221675352","rc":[{"atl":[[1000,0.86]],"id":49487602}],"con":true,"img":false}]}
{"op":"mcm","clk":"10119353106","pt":1700901112807,"mc":[{"id":"1.221675352","rc":[{"atl":[[55,0]],"id":49487602}],"con":true,"img":false}]}
{"op":"mcm","clk":"10119353129","pt":1700901113007,"mc":[{"id":"1.221675352","rc":[{"atl":[[1000,0.15]],"id":49487602}],"con":true,"img":false}]}
{"op":"mcm","clk":"10119353159","pt":1700901113318,"mc":[{"id":"1.221675352","rc":[{"atl":[[1000,0]],"id":49487602}],"con":true,"img":false}]}
{"op":"mcm","clk":"10119353169","pt":1700901113421,"mc":[{"id":"1.221675352","rc":[{"atl":[[60,0.15]],"id":49487602}],"con":true,"img":false}]}
{"op":"mcm","clk":"10119354201","pt":1700901121673,"mc":[{"id":"1.221675352","rc":[{"atl":[[1000,2.38]],"id":54974498}],"con":true,"img":false}]}
{"op":"mcm","clk":"10119354217","pt":1700901121724,"mc":[{"id":"1.221675352","rc":[{"atl":[[1000,2.38]],"id":51178794}],"con":true,"img":false}]}
{"op":"mcm","clk":"10119354246","pt":1700901121936,"mc":[{"id":"1.221675352","rc":[{"atl":[[1000,1.4]],"id":54974498}],"con":true,"img":false}]}
{"op":"mcm","clk":"10119354261","pt":1700901122039,"mc":[{"id":"1.221675352","rc":[{"atl":[[1000,1.07]],"id":51178794}],"con":true,"img":false}]}
{"op":"mcm","clk":"10119354288","pt":1700901122250,"mc":[{"id":"1.221675352","rc":[{"atl":[[1000,0]],"id":54974498}],"con":true,"img":false}]}
{"op":"mcm","clk":"10119354319","pt":1700901122512,"mc":[{"id":"1.221675352","rc":[{"atl":[[9.6,1.4]],"id":54974498}],"con":true,"img":false}]}
{"op":"mcm","clk":"10119354354","pt":1700901122826,"mc":[{"id":"1.221675352","rc":[{"atl":[[1000,0]],"id":51178794}],"con":true,"img":false}]}
{"op":"mcm","clk":"10119354360","pt":1700901122934,"mc":[{"id":"1.221675352","rc":[{"atl":[[12.5,1.07]],"id":51178794}],"con":true,"img":false}]}
{"op":"mcm","clk":"10119354936","pt":1700901127233,"mc":[{"id":"1.221675352","rc":[{"atb":[[4.5,59.59]],"id":51178794},{"atl":[[8.6,0]],"id":54974498}],"con":true,"img":false}]}
{"op":"mcm","clk":"10119354953","pt":1700901127327,"mc":[{"id":"1.221675352","rc":[{"atb":[[5.1,16]],"id":51178794},{"atl":[[9.6,13.03],[8.2,7.37]],"id":54974498}],"con":true,"img":false}]}
{"op":"mcm","clk":"10119354966","pt":1700901127479,"mc":[{"id":"1.221675352","rc":[{"atl":[[8.4,0]],"id":54974498}],"con":true,"img":false}]}
{"op":"mcm","clk":"10119354986","pt":1700901127635,"mc":[{"id":"1.221675352","rc":[{"atb":[[12,0],[9.8,0],[14.5,0]],"id":52386044},{"atl":[[320,0],[220,0]],"id":52386044}],"con":true,"img":false}]}
{"op":"mcm","clk":"10119355300","pt":1700901129846,"mc":[{"id":"1.221675352","rc":[{"atl":[[12.5,7.44],[13.5,4.31]],"id":51178794},{"atb":[[3.85,0],[6,20]],"id":61861979}],"con":true,"img":false}]}
{"op":"mcm","clk":"10119356096","pt":1700901136728,"mc":[{"id":"1.221675352","rc":[{"atl":[[13.5,0]],"id":51178794}],"con":true,"img":false}]}
{"op":"mcm","clk":"10119356111","pt":1700901136836,"mc":[{"id":"1.221675352","rc":[{"atl":[[14.5,4.31]],"id":51178794}],"con":true,"img":false}]}
{"op":"mcm","clk":"10119356907","pt":1700901142957,"mc":[{"id":"1.221675352","rc":[{"atb":[[3.55,0]],"id":41132607},{"trd":[[3.55,16.05]],"ltp":3.55,"tv":16.05,"id":41132607},{"atl":[[65,2]],"id":49487602}],"con":true,"img":false}]}
{"op":"mcm","clk":"10119356924","pt":1700901143065,"mc":[{"id":"1.221675352","rc":[{"atl":[[60,2.76]],"id":49487602}],"con":true,"img":false}]}
{"op":"mcm","clk":"10119356933","pt":1700901143126,"mc":[{"id":"1.221675352","rc":[{"atl":[[65,0],[75,2]],"id":49487602}],"con":true,"img":false}]}
{"op":"mcm","clk":"10119356955","pt":1700901143323,"mc":[{"id":"1.221675352","rc":[{"atb":[[12,18.96],[9.8,23.69],[14.5,7.72]],"id":52386044},{"atl":[[320,0.65],[220,0.63]],"id":52386044}],"con":true,"img":false}]}
{"op":"mcm","clk":"10119357333","pt":1700901146346,"mc":[{"id":"1.221675352","rc":[{"spn":2.42,"spf":1.0,"id":41132607},{"atb":[[4.1,0]],"id":51178794},{"spn":5.1,"spf":1.0,"id":51178794},{"atb":[[9.8,0]],"id":61861979},{"spn":10.57,"spf":1.0,"id":61861979},{"atb":[[2.9,0],[2.3,89.95]],"id":54974498},{"atl":[[10.5,0],[9.4,13.28]],"id":54974498},{"spn":3.2,"spf":1.0,"id":54974498},{"atb":[[10.5,11.21],[14.5,0]],"id":50758683},{"atb":[[15,0]],"id":52386044},{"spn":14.5,"spf":1.0,"id":52386044},{"atb":[[11.5,0]],"id":49487602}],"con":true,"img":false}]}
{"op":"mcm","clk":"10119357346","pt":1700901146449,"mc":[{"id":"1.221675352","rc":[{"atb":[[3.4,42.84]],"id":51178794},{"atb":[[8.4,16.19]],"id":61861979},{"atb":[[12.5,14.81]],"id":52386044},{"atb":[[9.6,13.23]],"id":49487602}],"con":true,"img":false}]}
{"op":"mcm","clk":"10119357371","pt":1700901146689,"mc":[{"id":"1.221675352","rc":[{"atl":[[5.6,2.41]],"id":41132607}],"con":true,"img":false}]}
{"op":"mcm","clk":"10119358345","pt":1700901154132,"mc":[{"id":"1.221675352","rc":[{"atb":[[2.06,7.48]],"id":41132607},{"atl":[[5.2,0]],"id":41132607},{"atb":[[5.1,0]],"id":51178794},{"atb":[[11,0]],"id":61861979},{"atb":[[3.05,0]],"id":54974498},{"atb":[[19.5,0]],"id":50758683},{"atb":[[7.2,0]],"id":51229677},{"atb":[[14,0]],"id":49487602}],"con":true,"img":false}]}
{"op":"mcm","clk":"10119358355","pt":1700901154237,"mc":[{"id":"1.221675352","rc":[{"atb":[[2.1,54.93]],"id":41132607},{"atl":[[6,33.82]],"id":41132607},{"atb":[[4.2,16]],"id":51178794},{"atb":[[10,5.6]],"id":61861979},{"atb":[[2.68,28.01]],"id":54974498},{"atb":[[17,4]],"id":50758683},{"atb":[[6.4,9.03]],"id":51229677},{"atb":[[12,4.87]],"id":49487602}],"con":true,"img":false}]}
{"op":"mcm","clk":"10119358774","pt":1700901157145,"mc":[{"id":"1.221675352","rc":[{"atl":[[8,13.03]],"id":54974498}],"con":true,"img":false}]}
{"op":"mcm","clk":"10119358786","pt":1700901157249,"mc":[{"id":"1.221675352","rc":[{"atl":[[9.6,1.4]],"id":54974498}],"con":true,"img":false}]}
{"op":"mcm","clk":"10119359211","pt":1700901160956,"mc":[{"id":"1.221675352","rc":[{"atl":[[12.5,1.07],[13.5,8]],"id":51178794},{"atl":[[130,0],[160,2]],"id":50758683},{"atl":[[75,0],[80,4.61]],"id":49487602}],"con":true,"img":false}]}
{"op":"mcm","clk":"10119359911","pt":1700901166272,"mc":[{"id":"1.221675352","rc":[{"atb":[[10,0]],"id":61861979},{"atb":[[12,0]],"id":49487602}],"con":true,"img":false}]}
{"op":"mcm","clk":"10119359921","pt":1700901166375,"mc":[{"id":"1.221675352","rc":[{"atb":[[9.4,5.6]],"id":61861979},{"atb":[[11.5,4.87]],"id":49487602}],"con":true,"img":false}]}
{"op":"mcm","clk":"10119359973","pt":1700901166846,"mc":[{"id":"1.221675352","rc":[{"atb":[[2.08,16.72]],"id":41132607}],"con":true,"img":false}]}
{"op":"mcm","clk":"10119361210","pt":1700901177062,"mc":[{"id":"1.221675352","rc":[{"atl":[[14.5,0]],"id":51178794},{"atl":[[46,0]],"id":61861979},{"atl":[[8.2,0]],"id":54974498},{"atl":[[95,0]],"id":50758683},{"atl":[[27,0]],"id":51229677},{"atl":[[80,0]],"id":52386044},{"atl":[[60,0.15]],"id":49487602}],"con":true,"img":false}]}
{"op":"mcm","clk":"10119361223","pt":1700901177166,"mc":[{"id":"1.221675352","rc":[{"atl":[[12.5,5.38]],"id":51178794},{"atl":[[38,2.61]],"id":61861979},{"atl":[[8,0],[7.2,7.37],[9.2,12.2]],"id":54974498},{"atl":[[80,2.61]],"id":50758683},{"atl":[[23,2.61]],"id":51229677},{"atl":[[70,2.61]],"id":52386044},{"atl":[[55,2.61]],"id":49487602}],"con":true,"img":false}]}
{"op":"mcm","clk":"10119361237","pt":1700901177275,"mc":[{"id":"1.221675352","rc":[{"atl":[[7,12.2]],"id":54974498}],"con":true,"img":false}]}
{"op":"mcm","clk":"10119361251","pt":1700901177372,"mc":[{"id":"1.221675352","rc":[{"atl":[[9.2,0]],"id":54974498}],"con":true,"img":false}]}
{"op":"mcm","clk":"10119361430","pt":1700901178674,"mc":[{"id":"1.221675352","rc":[{"atb":[[2.12,15.51]],"id":41132607}],"con":true,"img":false}]}
{"op":"mcm","clk":"10119362209","pt":1700901185089,"mc":[{"id":"1.221675352","rc":[{"atb":[[2,0],[1.9,0],[1.95,0]],"id":41132607},{"atl":[[6.2,0],[8.2,0]],"id":41132607},{"atb":[[9.2,0],[10.5,0],[8.2,0]],"id":61861979},{"atl":[[260,0],[160,0]],"id":61861979},{"atb":[[3.2,0],[2.88,0],[2.98,0]],"id":54974498},{"atl":[[16,0],[11,0]],"id":54974498},{"atb":[[16.5,0],[19,0],[14,0]],"id":50758683},{"atl":[[260,0],[360,0]],"id":50758683},{"atb":[[5.5,0],[6,0],[7,0]],"id":51229677},{"atl":[[95,0],[48,0]],"id":51229677},{"atb":[[11,0],[13.5,0],[9.4,0]],"id":49487602},{"atl":[[310,0],[210,0]],"id":49487602}],"con":true,"img":false}]}
{"op":"mcm","clk":"10119362564","pt":1700901188075,"mc":[{"id":"1.221675352","rc":[{"atl":[[7.2,16.51],[6,13.34]],"id":41132607},{"atb":[[6.2,0],[5.2,25.87]],"id":51229677}],"con":true,"img":false}]}
{"op":"mcm","clk":"10119362579","pt":1700901188180,"mc":[{"id":"1.221675352","rc":[{"atb":[[2.02,0]],"id":41132607},{"atb":[[17,0]],"id":50758683},{"atb":[[12.5,10.5]],"id":52386044}],"con":true,"img":false}]}
{"op":"mcm","clk":"10119362588","pt":1700901188283,"mc":[{"id":"1.221675352","rc":[{"atb":[[1.89,100.39]],"id":41132607},{"atb":[[7.2,16.13],[6.4,0],[13.5,4]],"id":50758683},{"atb":[[15,4.31]],"id":52386044}],"con":true,"img":false}]}
{"op":"mcm","clk":"10119363394","pt":1700901195099,"mc":[{"id":"1.221675352","rc":[{"atb":[[2.06,0]],"id":41132607}],"con":true,"img":false}]}
{"op":"mcm","clk":"10119364827","pt":1700901205357,"mc":[{"id":"1.221675352","rc":[{"atb":[[2,104.28],[1.9,231.74],[1.95,219.54]],"id":41132607},{"atl":[[6.2,26.76],[8.2,28.99]],"id":41132607},{"atb":[[9.2,25.43],[10.5,10.97],[8.2,28.96]],"id":61861979},{"atl":[[260,0.8],[160,0.87]],"id":61861979},{"atb":[[3.2,47.4],[2.88,110.94],[2.98,105.33]],"id":54974498},{"atl":[[16,13.91],[11,13.91]],"id":54974498},{"atb":[[16.5,13.45],[19,5.79],[14,16.04]],"id":50758683},{"atl":[[260,0.53],[360,0.57]],"id":50758683},{"atb":[[5.8,43.45],[7.6,15.79],[6.6,37.24]],"id":51229677},{"atl":[[65,2.17],[130,1.61]],"id":51229677},{"atb":[[12,18.96],[9.8,23.69],[14.5,7.72]],"id":49487602},{"atl":[[320,0.65],[220,0.63]],"id":49487602}],"con":true,"img":false}]}
{"op":"mcm","clk":"10119366651","pt":1700901219630,"mc":[{"id":"1.221675352","rc":[{"atb":[[2.58,63.29],[2.7,0]],"id":51178794},{"atl":[[12.5,11.75],[13.5,0]],"id":51178794},{"spn":5.0,"spf":1.0,"id":51178794},{"spn":10.07,"spf":1.0,"id":61861979},{"spn":19.0,"spf":1.0,"id":50758683},{"spn":11.05,"spf":1.0,"id":51229677},{"spn":14.87,"spf":1.0,"id":52386044},{"atl":[[75,2],[80,2.61]],"id":49487602},{"spn":14.5,"spf":1.0,"id":49487602}],"con":true,"img":false}]}
{"op":"mcm","clk":"10119368563","pt":1700901234649,"mc":[{"id":"1.221675352","rc":[{"atb":[[13.5,0]],"id":50758683}],"con":true,"img":false}]}
{"op":"mcm","clk":"10119368578","pt":1700901234752,"mc":[{"id":"1.221675352","rc":[{"atb":[[17,4]],"id":50758683}],"con":true,"img":false}]}
{"op":"mcm","clk":"10119370038","pt":1700901246360,"mc":[{"id":"1.221675352","rc":[{"atb":[[6.4,0]],"id":51229677},{"atb":[[11.5,0]],"id":49487602}],"con":true,"img":false}]}
{"op":"mcm","clk":"10119370050","pt":1700901246515,"mc":[{"id":"1.221675352","rc":[{"atb":[[6.8,9.03]],"id":51229677},{"atb":[[12.5,4.87]],"id":49487602}],"con":true,"img":false}]}
{"op":"mcm","clk":"10119371105","pt":1700901254590,"mc":[{"id":"1.221675352","rc":[{"atb":[[2.04,7.63]],"id":41132607}],"con":true,"img":false}]}
{"op":"mcm","clk":"10119371125","pt":1700901254796,"mc":[{"id":"1.221675352","rc":[{"atl":[[9.6,0]],"id":54974498}],"con":true,"img":false}]}
{"op":"mcm","clk":"10119371379","pt":1700901256691,"mc":[{"id":"1.221675352","rc":[{"atb":[[2,0],[1.9,0],[1.95,0]],"id":41132607},{"atl":[[6.2,0],[8.2,0]],"id":41132607},{"atb":[[4,0],[4.5,0],[5,0]],"id":51178794},{"atl":[[38,0],[24,0]],"id":51178794},{"atb":[[9.2,0],[10.5,0],[8.2,0]],"id":61861979},{"atl":[[260,0],[160,0]],"id":61861979},{"atb":[[3.2,0],[2.88,0],[2.98,0]],"id":54974498},{"atl":[[16,0],[11,0]],"id":54974498},{"atb":[[16.5,0],[19,0],[14,0]],"id":50758683},{"atl":[[260,0],[360,0]],"id":50758683},{"atb":[[5.8,0],[7.6,0],[6.6,0]],"id":51229677},{"atl":[[65,0],[130,0]],"id":51229677},{"atb":[[12,0],[9.8,0],[14.5,0]],"id":52386044},{"atl":[[320,0],[220,0]],"id":52386044},{"atb":[[12,0],[9.8,0],[14.5,0]],"id":49487602},{"atl":[[320,0],[220,0]],"id":49487602}],"con":true,"img":false}]}
{"op":"mcm","clk":"10119371553","pt":1700901257739,"mc":[{"id":"1.221675352","rc":[{"atl":[[7.2,0],[6,33.82]],"id":41132607}],"con":true,"img":false}]}
{"op":"mcm","clk":"10119371570","pt":1700901257842,"mc":[{"id":"1.221675352","rc":[{"atb":[[1.89,0]],"id":41132607},{"atl":[[6,13.34]],"id":41132607},{"atb":[[4.2,0]],"id":51178794},{"atl":[[38,0]],"id":61861979},{"atb":[[17,0]],"id":50758683},{"atb":[[6.8,0]],"id":51229677},{"atb":[[12.5,0],[15,0]],"id":52386044},{"atb":[[9.6,0],[12.5,0]],"id":49487602}],"con":true,"img":false}]}
{"op":"mcm","clk":"10119371585","pt":1700901257902,"mc":[{"id":"1.221675352","rc":[{"atb":[[2.02,100.39]],"id":41132607},{"atl":[[7,20.48]],"id":41132607},{"atb":[[4,16]],"id":51178794},{"atl":[[40,2.61]],"id":61861979},{"atb":[[13.5,4]],"id":50758683},{"atb":[[6.2,9.03]],"id":51229677},{"atb":[[10,10.5],[12.5,4.31]],"id":52386044},{"atb":[[10,13.23],[11,4.87]],"id":49487602}],"con":true,"img":false}]}
{"op":"mcm","clk":"10119371601","pt":1700901258004,"mc":[{"id":"1.221675352","rc":[{"atb":[[4.4,0],[4.2,31.25]],"id":49487602}],"con":true,"img":false}]}
{"op":"mcm","clk":"10119372286","pt":1700901262803,"mc":[{"id":"1.221675352","rc":[{"atl":[[1000,0.86]],"id":51178794},{"atl":[[26,0],[1000,0.86]],"id":51229677},{"atl":[[60,0],[1000,0.86]],"id":49487602}],"con":true,"img":false}]}
{"op":"mcm","clk":"10119372297","pt":1700901262961,"mc":[{"id":"1.221675352","rc":[{"atl":[[75,0],[1000,0.86]],"id":52386044}],"con":true,"img":false}]}
{"op":"mcm","clk":"10119372333","pt":1700901263220,"mc":[{"id":"1.221675352","rc":[{"atl":[[1000,0.72]],"id":51178794},{"atl":[[1000,0.39]],"id":51229677}],"con":true,"img":false}]}
{"op":"mcm","clk":"10119372350","pt":1700901263324,"mc":[{"id":"1.221675352","rc":[{"atl":[[1000,0.13]],"id":52386044},{"atl":[[1000,0.17]],"id":49487602}],"con":true,"img":false}]}
{"op":"mcm","clk":"10119372561","pt":1700901264724,"mc":[{"id":"1.221675352","rc":[{"atl":[[1000,0]],"id":51178794}],"con":true,"img":false}]}
{"op":"mcm","clk":"10119372573","pt":1700901264826,"mc":[{"id":"1.221675352","rc":[{"atl":[[12,0.72]],"id":51178794}],"con":true,"img":false}]}
{"op":"mcm","clk":"10119372664","pt":1700901265451,"mc":[{"id":"1.221675352","rc":[{"atl":[[1000,0]],"id":51229677}],"con":true,"img":false}]}
{"op":"mcm","clk":"10119372672","pt":1700901265504,"mc":[{"id":"1.221675352","rc":[{"atl":[[22,0.39]],"id":51229677}],"con":true,"img":false}]}
{"op":"mcm","clk":"10119372727","pt":1700901265812,"mc":[{"id":"1.221675352","rc":[{"atl":[[1000,0]],"id":52386044}],"con":true,"img":false}]}
{"op":"mcm","clk":"10119372747","pt":1700901265921,"mc":[{"id":"1.221675352","rc":[{"atl":[[65,0.13]],"id":52386044}],"con":true,"img":false}]}
{"op":"mcm","clk":"10119372787","pt":1700901266228,"mc":[{"id":"1.221675352","rc":[{"atl":[[1000,0]],"id":49487602}],"con":true,"img":false}]}
{"op":"mcm","clk":"10119372797","pt":1700901266331,"mc":[{"id":"1.221675352","rc":[{"atl":[[50,0.17]],"id":49487602}],"con":true,"img":false}]}
{"op":"mcm","clk":"10119372890","pt":1700901267110,"mc":[{"id":"1.221675352","rc":[{"atl":[[7.2,16.51]],"id":41132607}],"con":true,"img":false}]}
{"op":"mcm","clk":"10119372901","pt":1700901267209,"mc":[{"id":"1.221675352","rc":[{"atl":[[7,0]],"id":41132607},{"atb":[[10,0]],"id":49487602},{"atl":[[80,0]],"id":49487602}],"con":true,"img":false}]}
{"op":"mcm","clk":"10119372910","pt":1700901267314,"mc":[{"id":"1.221675352","rc":[{"atb":[[8.8,13.23]],"id":49487602},{"atl":[[70,2.61]],"id":49487602}],"con":true,"img":false}]}
{"op":"mcm","clk":"10119373762","pt":1700901274227,"mc":[{"id":"1.221675352","rc":[{"atl":[[12.5,5.38],[14,7.69]],"id":51178794},{"atl":[[130,0],[170,2]],"id":52386044}],"con":true,"img":false}]}
{"op":"mcm","clk":"10119373921","pt":1700901275615,"mc":[{"id":"1.221675352","rc":[{"atl":[[7.2,0]],"id":54974498}],"con":true,"img":false}]}
{"op":"mcm","clk":"10119373935","pt":1700901275716,"mc":[{"id":"1.221675352","rc":[{"atl":[[9.2,12.2],[7,7.37]],"id":54974498}],"con":true,"img":false}]}
{"op":"mcm","clk":"10119374021","pt":1700901276344,"mc":[{"id":"1.221675352","rc":[{"atb":[[2,104.28],[1.9,231.74],[1.95,219.54]],"id":41132607},{"atl":[[6.2,26.76],[8.2,28.99]],"id":41132607},{"atb":[[4,85.53],[4.5,59.59],[5,26.07]],"id":51178794},{"atl":[[38,5.64],[24,6.05]],"id":51178794},{"atb":[[9.2,25.43],[10.5,10.97],[8.2,28.96]],"id":61861979},{"atl":[[260,0.8],[160,0.87]],"id":61861979},{"atb":[[3.2,47.4],[2.88,110.94],[2.98,105.33]],"id":54974498},{"atl":[[16,13.91],[11,13.91]],"id":54974498},{"atb":[[16.5,13.45],[19,5.79],[14,16.04]],"id":50758683},{"atl":[[260,0.53],[360,0.57]],"id":50758683},{"atb":[[5.8,43.45],[7.6,15.79],[6.6,37.24]],"id":51229677},{"atl":[[65,2.17],[130,1.61]],"id":51229677},{"atb":[[12,18.96],[9.8,23.69],[14.5,7.72]],"id":52386044},{"atl":[[320,0.65],[220,0.63]],"id":52386044},{"atb":[[12,18.96],[9.8,23.69],[14.5,7.72]],"id":49487602},{"atl":[[320,0.65],[220,0.63]],"id":49487602}],"con":true,"img":false}]}
{"op":"mcm","clk":"10119374125","pt":1700901277021,"mc":[{"id":"1.221675352","rc":[{"atb":[[2.58,0],[2.7,58.82]],"id":51178794},{"atl":[[130,2],[160,0]],"id":50758683},{"atb":[[4.8,26.32],[4.2,0]],"id":49487602},{"atl":[[70,4.61],[75,0]],"id":49487602}],"con":true,"img":false}]}
{"op":"mcm","clk":"10119374518","pt":1700901280131,"mc":[{"id":"1.221675352","rc":[{"atl":[[5.6,0]],"id":41132607},{"spn":14.5,"spf":1.0,"id":52386044}],"con":true,"img":false}]}
{"op":"mcm","clk":"10119375829","pt":1700901290249,"mc":[{"id":"1.221675352","rc":[{"atb":[[2.04,0]],"id":41132607}],"con":true,"img":false}]}
{"op":"mcm","clk":"10119375837","pt":1700901290350,"mc":[{"id":"1.221675352","rc":[{"atl":[[12.5,4.31]],"id":51178794}],"con":true,"img":false}]}
{"op":"mcm","clk":"10119377388","pt":1700901302661,"mc":[{"id":"1.221675352","rc":[{"atl":[[12.5,10.68],[14,0]],"id":51178794},{"atl":[[140,2],[170,0]],"id":52386044}],"con":true,"img":false}]}
{"op":"mcm","clk":"10119377405","pt":1700901302763,"mc":[{"id":"1.221675352","rc":[{"atl":[[12.5,4.31],[14,6.37]],"id":51178794}],"con":true,"img":false}]}
{"op":"mcm","clk":"10119377600","pt":1700901304168,"mc":[{"id":"1.221675352","rc":[{"atl":[[9.2,0],[6.8,12.2]],"id":54974498}],"con":true,"img":false}]}
{"op":"mcm","clk":"10119379435","pt":1700901317412,"mc":[{"id":"1.221675352","rc":[{"atb":[[4,69.52]],"id":51178794},{"atb":[[13.5,0]],"id":50758683},{"atb":[[6.2,0]],"id":51229677},{"atb":[[11,0]],"id":49487602}],"con":true,"img":false}]}
{"op":"mcm","clk":"10119379447","pt":1700901317515,"mc":[{"id":"1.221675352","rc":[{"atb":[[4.1,16]],"id":51178794},{"atb":[[17,4]],"id":50758683},{"atb":[[6.8,9.03]],"id":51229677},{"atb":[[12.5,4.87]],"id":49487602}],"con":true,"img":false}]}
{"op":"mcm","clk":"10119379940","pt":1700901321232,"mc":[{"id":"1.221675352","rc":[{"atb":[[2,0],[1.9,0],[1.95,0]],"id":41132607},{"atl":[[6.2,0],[8.2,0]],"id":41132607},{"atb":[[4,0],[4.5,0],[5,0]],"id":51178794},{"atl":[[38,0],[24,0]],"id":51178794},{"atb":[[9.2,0],[10.5,0],[8.2,0]],"id":61861979},{"atl":[[260,0],[160,0]],"id":61861979},{"atb":[[3.2,0],[2.88,0],[2.98,0]],"id":54974498},{"atl":[[16,0],[11,0]],"id":54974498},{"atb":[[16.5,0],[19,0],[14,0]],"id":50758683},{"atl":[[260,0],[360,0]],"id":50758683},{"atb":[[5.8,0],[7.6,0],[6.6,0]],"id":51229677},{"atl":[[65,0],[130,0]],"id":51229677},{"atb":[[12,0],[9.8,0],[14.5,0]],"id":49487602},{"atl":[[320,0],[220,0]],"id":49487602}],"con":true,"img":false}]}
{"op":"mcm","clk":"10119381102","pt":1700901329715,"mc":[{"id":"1.221675352","rc":[{"atl":[[13.5,9.42]],"id":51178794}],"con":true,"img":false}]}
{"op":"mcm","clk":"10119381112","pt":1700901329827,"mc":[{"id":"1.221675352","rc":[{"atb":[[2.02,0]],"id":41132607},{"atl":[[19.5,0]],"id":51178794},{"atb":[[17,0]],"id":50758683},{"atb":[[6.8,0]],"id":51229677},{"atb":[[12.5,0]],"id":49487602}],"con":true,"img":false}]}
{"op":"mcm","clk":"10119381124","pt":1700901329919,"mc":[{"id":"1.221675352","rc":[{"atb":[[1.88,100.39]],"id":41132607},{"atb":[[13.5,4]],"id":50758683},{"atb":[[6.2,9.03]],"id":51229677},{"atb":[[11,4.87]],"id":49487602}],"con":true,"img":false}]}
{"op":"mcm","clk":"10119381244","pt":1700901330909,"mc":[{"id":"1.221675352","rc":[{"atl":[[12.5,10.68],[14,0]],"id":51178794}],"con":true,"img":false}]}
{"op":"mcm","clk":"10119382991","pt":1700901344144,"mc":[{"id":"1.221675352","rc":[{"atl":[[17,7.36],[13.5,0]],"id":51178794},{"spn":4.1,"spf":1.0,"id":51178794},{"spn":8.93,"spf":1.0,"id":61861979},{"spn":2.59,"spf":1.0,"id":54974498},{"spn":13.0,"spf":1.0,"id":50758683},{"spn":10.35,"spf":1.0,"id":51229677},{"atb":[[10,0]],"id":52386044},{"spn":10.85,"spf":1.0,"id":49487602}],"con":true,"img":false}]}
{"op":"mcm","clk":"10119383005","pt":1700901344212,"mc":[{"id":"1.221675352","rc":[{"atb":[[12.5,14.81]],"id":52386044}],"con":true,"img":false}]}
{"op":"mcm","clk":"10119383187","pt":1700901345703,"mc":[{"id":"1.221675352","rc":[{"atl":[[12.5,4.31],[13.5,8]],"id":51178794},{"atl":[[130,0],[160,2]],"id":50758683},{"atl":[[70,2.61],[80,2]],"id":49487602}],"con":true,"img":false}]}
{"op":"mcm","clk":"10119383249","pt":1700901346128,"mc":[{"id":"1.221675352","rc":[{"atb":[[2,104.28],[1.9,231.74],[1.95,219.54]],"id":41132607},{"atl":[[6.2,26.76],[8.2,28.99]],"id":41132607},{"atb":[[4,69.52],[4.5,59.59],[5,26.07]],"id":51178794},{"atl":[[38,5.64],[24,6.05]],"id":51178794},{"atb":[[9.2,25.43],[10.5,10.97],[8.2,28.96]],"id":61861979},{"atl":[[260,0.8],[160,0.87]],"id":61861979},{"atb":[[3.2,47.4],[2.88,110.94],[2.98,105.33]],"id":54974498},{"atl":[[16,13.91],[11,13.91]],"id":54974498},{"atb":[[16.5,13.45],[19,5.79],[14,16.04]],"id":50758683},{"atl":[[260,0.53],[360,0.57]],"id":50758683},{"atb":[[5.8,43.45],[7.6,15.79],[6.6,37.24]],"id":51229677},{"atl":[[65,2.17],[130,1.61]],"id":51229677},{"atb":[[12,18.96],[9.8,23.69],[14.5,7.72]],"id":49487602},{"atl":[[320,0.65],[220,0.63]],"id":49487602}],"con":true,"img":false}]}
{"op":"mcm","clk":"10119383857","pt":1700901350745,"mc":[{"id":"1.221675352","rc":[{"atb":[[2.04,7.63]],"id":41132607}],"con":true,"img":false}]}
{"op":"mcm","clk":"10119383882","pt":1700901350949,"mc":[{"id":"1.221675352","rc":[{"atl":[[1000,2.38]],"id":41132607}],"con":true,"img":false}]}
{"op":"mcm","clk":"10119383896","pt":1700901351011,"mc":[{"id":"1.221675352","rc":[{"atl":[[1000,2.38]],"id":54974498}],"con":true,"img":false}]}
{"op":"mcm","clk":"10119383924","pt":1700901351216,"mc":[{"id":"1.221675352","rc":[{"atl":[[1000,2.36]],"id":41132607}],"con":true,"img":false}]}
{"op":"mcm","clk":"10119383955","pt":1700901351426,"mc":[{"id":"1.221675352","rc":[{"atl":[[1000,0]],"id":41132607},{"atl":[[1000,1.57]],"id":54974498}],"con":true,"img":false}]}
{"op":"mcm","clk":"10119383967","pt":1700901351526,"mc":[{"id":"1.221675352","rc":[{"atl":[[5.7,2.36]],"id":41132607}],"con":true,"img":false}]}
{"op":"mcm","clk":"10119383989","pt":1700901351733,"mc":[{"id":"1.221675352","rc":[{"atl":[[1000,0]],"id":54974498}],"con":true,"img":false}]}
{"op":"mcm","clk":"10119383999","pt":1700901351836,"mc":[{"id":"1.221675352","rc":[{"atl":[[8.6,1.57]],"id":54974498}],"con":true,"img":false}]}
{"op":"mcm","clk":"10119389761","pt":1700901396676,"mc":[{"id":"1.221675352","rc":[{"atb":[[13.5,0]],"id":50758683},{"atb":[[6.2,0]],"id":51229677},{"atb":[[11,0]],"id":49487602}],"con":true,"img":false}]}
{"op":"mcm","clk":"10119389770","pt":1700901396780,"mc":[{"id":"1.221675352","rc":[{"atb":[[17,4]],"id":50758683},{"atb":[[6.8,9.03]],"id":51229677},{"atb":[[12.5,4.87]],"id":49487602}],"con":true,"img":false}]}
{"op":"mcm","clk":"10119389795","pt":1700901397001,"mc":[{"id":"1.221675352","rc":[{"atb":[[2.58,63.29],[2.7,0]],"id":51178794},{"atl":[[12.5,11.67],[13.5,0]],"id":51178794},{"atl":[[75,2],[80,0]],"id":49487602}],"con":true,"img":false}]}
{"op":"mcm","clk":"10119390754","pt":1700901404185,"mc":[{"id":"1.221675352","rc":[{"atb":[[1.88,0]],"id":41132607},{"atl":[[7.2,0],[6,33.82]],"id":41132607},{"spn":5.0,"spf":1.0,"id":51178794},{"atb":[[8.4,0]],"id":61861979},{"spn":10.07,"spf":1.0,"id":61861979},{"spn":3.2,"spf":1.0,"id":54974498},{"spn":19.0,"spf":1.0,"id":50758683},{"atb":[[5.2,0]],"id":51229677},{"spn":11.05,"spf":1.0,"id":51229677},{"atb":[[8.8,0]],"id":49487602},{"spn":14.5,"spf":1.0,"id":49487602}],"con":true,"img":false}]}
{"op":"mcm","clk":"10119390771","pt":1700901404284,"mc":[{"id":"1.221675352","rc":[{"atb":[[2.02,100.39]],"id":41132607},{"atb":[[9.4,21.79]],"id":61861979},{"atb":[[5.9,25.87]],"id":51229677},{"atb":[[10,13.23]],"id":49487602}],"con":true,"img":false}]}
{"op":"mcm","clk":"10119394680","pt":1700901434609,"mc":[{"id":"1.221675352","rc":[{"atl":[[12.5,7.36]],"id":51178794},{"atb":[[9.4,16.19]],"id":61861979},{"atb":[[12.5,10.5]],"id":52386044}],"con":true,"img":false}]}
{"op":"mcm","clk":"10119394689","pt":1700901434713,"mc":[{"id":"1.221675352","rc":[{"atl":[[16.5,6.45],[12,5.03]],"id":51178794},{"atb":[[11,5.6]],"id":61861979},{"atb":[[15,4.31]],"id":52386044}],"con":true,"img":false}]}
{"op":"mcm","clk":"10119394705","pt":1700901434815,"mc":[{"id":"1.221675352","rc":[{"atl":[[12.5,0]],"id":51178794}],"con":true,"img":false}]}
{"op":"mcm","clk":"10119394718","pt":1700901434921,"mc":[{"id":"1.221675352","rc":[{"atl":[[16.5,0],[12.5,8.7]],"id":51178794}],"con":true,"img":false}]}
{"op":"mcm","clk":"10119395123","pt":1700901438211,"mc":[{"id":"1.221675352","rc":[{"atl":[[3.75,0]],"id":41132607}],"con":true,"img":false}]}
{"op":"mcm","clk":"10119396126","pt":1700901445240,"mc":[{"id":"1.221675352","rc":[{"atb":[[2.04,0]],"id":41132607}],"con":true,"img":false}]}
{"op":"mcm","clk":"10119398941","pt":1700901466131,"mc":[{"id":"1.221675352","rc":[{"atb":[[2.06,7.48]],"id":41132607},{"spn":10.59,"spf":1.0,"id":61861979},{"spn":14.87,"spf":1.0,"id":52386044}],"con":true,"img":false}]}
{"op":"mcm","clk":"10119402055","pt":1700901489457,"mc":[{"id":"1.221675352","rc":[{"atl":[[8.6,0]],"id":54974498}],"con":true,"img":false}]}
{"op":"mcm","clk":"10119402373","pt":1700901491854,"mc":[{"id":"1.221675352","rc":[{"atb":[[1.71,50.32]],"id":52386044}],"con":true,"img":false}]}
{"op":"mcm","clk":"10119402383","pt":1700901491955,"mc":[{"id":"1.221675352","rc":[{"atb":[[1.62,0]],"id":52386044}],"con":true,"img":false}]}
{"op":"mcm","clk":"10119404105","pt":1700901504570,"mc":[{"id":"1.221675352","rc":[{"atl":[[5.7,0]],"id":41132607}],"con":true,"img":false}]}
{"op":"mcm","clk":"10119404118","pt":1700901504683,"mc":[{"id":"1.221675352","rc":[{"atl":[[7.2,16.13],[7.4,0]],"id":41132607}],"con":true,"img":false}]}
{"op":"mcm","clk":"10119418614","pt":1700901613525,"mc":[{"id":"1.221675352","rc":[{"atb":[[1.8,50.32],[1.71,0]],"id":52386044}],"con":true,"img":false}]}
{"op":"mcm","clk":"10119418644","pt":1700901613779,"mc":[{"id":"1.221675352","rc":[{"atl":[[90,0],[1000,0.86]],"id":50758683},{"atb":[[7.8,1.11]],"id":51229677}],"con":true,"img":false}]}
{"op":"mcm","clk":"10119418671","pt":1700901613940,"mc":[{"id":"1.221675352","rc":[{"atl":[[1000,0.11]],"id":50758683}],"con":true,"img":false}]}
{"op":"mcm","clk":"10119418708","pt":1700901614151,"mc":[{"id":"1.221675352","rc":[{"atl":[[1000,0]],"id":50758683}],"con":true,"img":false}]}
{"op":"mcm","clk":"10119418725","pt":1700901614251,"mc":[{"id":"1.221675352","rc":[{"atl":[[75,0.11]],"id":50758683}],"con":true,"img":false}]}
{"op":"mcm","clk":"10119424594","pt":1700901657052,"mc":[{"id":"1.221675352","rc":[{"atb":[[2,0],[1.9,0],[1.95,0]],"id":41132607},{"atl":[[6.2,0],[8.2,0]],"id":41132607},{"atb":[[4,0],[4.5,0],[5,0]],"id":51178794},{"atl":[[38,0],[24,0]],"id":51178794},{"atb":[[9.2,0],[10.5,0],[8.2,0]],"id":61861979},{"atl":[[260,0],[160,0]],"id":61861979},{"atb":[[3.2,0],[2.88,0],[2.98,0]],"id":54974498},{"atl":[[16,0],[11,0]],"id":54974498},{"atb":[[16.5,0],[19,0],[14,0]],"id":50758683},{"atl":[[260,0],[360,0]],"id":50758683},{"atb":[[5.8,0],[7.6,0],[6.6,0]],"id":51229677},{"atl":[[65,0],[130,0]],"id":51229677},{"atb":[[12,0],[9.8,0],[14.5,0]],"id":52386044},{"atl":[[320,0],[220,0]],"id":52386044},{"atb":[[12,0],[9.8,0],[14.5,0]],"id":49487602},{"atl":[[320,0],[220,0]],"id":49487602}],"con":true,"img":false}]}
{"op":"mcm","clk":"10119424623","pt":1700901657260,"mc":[{"id":"1.221675352","rc":[{"atb":[[7.8,0],[7,1.11]],"id":51229677}],"con":true,"img":false}]}
{"op":"mcm","clk":"10119425223","pt":1700901661755,"mc":[{"id":"1.221675352","rc":[{"atl":[[6,13.34]],"id":41132607},{"atb":[[11,0],[9.4,0]],"id":61861979},{"atb":[[17,0]],"id":50758683},{"atb":[[6.8,0],[5.9,0]],"id":51229677},{"atb":[[12.5,0],[15,0]],"id":52386044},{"atb":[[10,0],[12.5,0]],"id":49487602}],"con":true,"img":false}]}
{"op":"mcm","clk":"10119425238","pt":1700901661859,"mc":[{"id":"1.221675352","rc":[{"atl":[[7,20.48]],"id":41132607},{"atb":[[7.6,16.19],[4.2,31.25],[9.4,5.6]],"id":61861979},{"atb":[[13.5,4]],"id":50758683},{"atb":[[6.2,9.03],[5.2,25.87]],"id":51229677},{"atb":[[10,10.5],[12.5,4.31]],"id":52386044},{"atb":[[11,4.87],[8.8,13.23],[4.2,31.25]],"id":49487602}],"con":true,"img":false}]}
{"op":"mcm","clk":"10119425253","pt":1700901661963,"mc":[{"id":"1.221675352","rc":[{"atb":[[6,0]],"id":61861979},{"atb":[[4.8,0]],"id":49487602}],"con":true,"img":false}]}
{"op":"mcm","clk":"10119426607","pt":1700901671977,"mc":[{"id":"1.221675352","rc":[{"atb":[[2,104.28],[1.9,231.74],[1.95,219.54]],"id":41132607},{"atl":[[6.2,26.76],[8.2,28.99]],"id":41132607},{"atb":[[4,69.52],[4.5,59.59],[5,26.07]],"id":51178794},{"atl":[[38,5.64],[24,6.05]],"id":51178794},{"atb":[[9.2,25.43],[10.5,10.97],[8.2,28.96]],"id":61861979},{"atl":[[260,0.8],[160,0.87]],"id":61861979},{"atb":[[3.2,47.4],[2.88,110.94],[2.98,105.33]],"id":54974498},{"atl":[[16,13.91],[11,13.91]],"id":54974498},{"atb":[[16.5,13.45],[19,5.79],[14,16.04]],"id":50758683},{"atl":[[260,0.53],[360,0.57]],"id":50758683},{"atb":[[5.8,43.45],[7.6,15.79],[6.6,37.24]],"id":51229677},{"atl":[[65,2.17],[130,1.61]],"id":51229677},{"atb":[[12,18.96],[9.8,23.69],[14.5,7.72]],"id":52386044},{"atl":[[320,0.65],[220,0.63]],"id":52386044},{"atb":[[12,18.96],[9.8,23.69],[14.5,7.72]],"id":49487602},{"atl":[[320,0.65],[220,0.63]],"id":49487602}],"con":true,"img":false}]}
{"op":"mcm","clk":"10119428167","pt":1700901683468,"mc":[{"id":"1.221675352","rc":[{"spn":10.07,"spf":1.0,"id":61861979},{"atb":[[7,0],[7.8,1.11]],"id":51229677},{"spn":11.15,"spf":1.0,"id":51229677},{"spn":14.5,"spf":1.0,"id":52386044}],"con":true,"img":false}]}
{"op":"mcm","clk":"10119428573","pt":1700901686387,"mc":[{"id":"1.221675352","rc":[{"atb":[[5.5,22.22],[4.2,0]],"id":61861979}],"con":true,"img":false}]}
{"op":"mcm","clk":"10119431548","pt":1700901708627,"mc":[{"id":"1.221675352","rc":[{"atb":[[9.4,0]],"id":61861979},{"atb":[[13.5,0]],"id":50758683},{"atb":[[6.2,0]],"id":51229677},{"atb":[[11,0]],"id":49487602}],"con":true,"img":false}]}
{"op":"mcm","clk":"10119431567","pt":1700901708728,"mc":[{"id":"1.221675352","rc":[{"atb":[[11,5.6]],"id":61861979},{"atb":[[17,4]],"id":50758683},{"atb":[[6.8,9.03]],"id":51229677},{"atb":[[12.5,4.87]],"id":49487602}],"con":true,"img":false}]}
{"op":"mcm","clk":"10119432393","pt":1700901715044,"mc":[{"id":"1.221675352","rc":[{"atb":[[2,0],[1.9,0],[1.95,0]],"id":41132607},{"atl":[[6.2,0],[8.2,0]],"id":41132607},{"atb":[[4,0],[4.5,0],[5,0]],"id":51178794},{"atl":[[38,0],[24,0]],"id":51178794},{"atb":[[9.2,0],[10.5,0],[8.2,0]],"id":61861979},{"atl":[[260,0],[160,0]],"id":61861979},{"atb":[[3.2,0],[2.88,0],[2.98,0]],"id":54974498},{"atl":[[16,0],[11,0]],"id":54974498},{"atb":[[16.5,0],[19,0],[14,0]],"id":50758683},{"atl":[[260,0],[360,0]],"id":50758683},{"atb":[[5.8,0],[7.6,0],[6.6,0]],"id":51229677},{"atl":[[65,0],[130,0]],"id":51229677},{"atb":[[12,0],[9.8,0],[14.5,0]],"id":49487602},{"atl":[[320,0],[220,0]],"id":49487602}],"con":true,"img":false}]}
{"op":"mcm","clk":"10119432411","pt":1700901715205,"mc":[{"id":"1.221675352","rc":[{"atb":[[7,1.11]],"id":51229677}],"con":true,"img":false}]}
{"op":"mcm","clk":"10119432424","pt":1700901715306,"mc":[{"id":"1.221675352","rc":[{"atb":[[7.8,0]],"id":51229677}],"con":true,"img":false}]}
{"op":"mcm","clk":"10119434249","pt":1700901728551,"mc":[{"id":"1.221675352","rc":[{"atb":[[11,0]],"id":61861979},{"atb":[[17,0]],"id":50758683},{"atb":[[6.8,0]],"id":51229677},{"atb":[[10,0]],"id":52386044},{"atb":[[12.5,0]],"id":49487602}],"con":true,"img":false}]}
{"op":"mcm","clk":"10119434265","pt":1700901728649,"mc":[{"id":"1.221675352","rc":[{"atb":[[9.4,5.6]],"id":61861979},{"atb":[[13.5,4]],"id":50758683},{"atb":[[6.2,9.03]],"id":51229677},{"atb":[[12.5,14.81]],"id":52386044},{"atb":[[11,4.87]],"id":49487602}],"con":true,"img":false}]}
{"op":"mcm","clk":"10119434275","pt":1700901728703,"mc":[{"id":"1.221675352","rc":[{"atb":[[5.3,1.11],[7,0]],"id":51229677}],"con":true,"img":false}]}
{"op":"mcm","clk":"10119435125","pt":1700901735056,"mc":[{"id":"1.221675352","rc":[{"atb":[[2,104.28],[1.9,231.74],[1.95,219.54]],"id":41132607},{"atl":[[6.2,26.76],[8.2,28.99]],"id":41132607},{"atb":[[4,69.52],[4.5,59.59],[5,26.07]],"id":51178794},{"atl":[[38,5.64],[24,6.05]],"id":51178794},{"atb":[[9.2,25.43],[10.5,10.97],[8.2,28.96]],"id":61861979},{"atl":[[260,0.8],[160,0.87]],"id":61861979},{"atb":[[3.2,47.4],[2.88,110.94],[2.98,105.33]],"id":54974498},{"atl":[[16,13.91],[11,13.91]],"id":54974498},{"atb":[[16.5,13.45],[19,5.79],[14,16.04]],"id":50758683},{"atl":[[260,0.53],[360,0.57]],"id":50758683},{"atb":[[5.8,43.45],[7.6,15.79],[6.6,37.24]],"id":51229677},{"atl":[[65,2.17],[130,1.61]],"id":51229677},{"atb":[[12,18.96],[9.8,23.69],[14.5,7.72]],"id":49487602},{"atl":[[320,0.65],[220,0.63]],"id":49487602}],"con":true,"img":false}]}
{"op":"mcm","clk":"10119444307","pt":1700901803737,"mc":[{"id":"1.221675352","rc":[{"atb":[[7.8,1.11]],"id":51229677}],"con":true,"img":false}]}
{"op":"mcm","clk":"10119444320","pt":1700901803840,"mc":[{"id":"1.221675352","rc":[{"atb":[[5.3,0]],"id":51229677}],"con":true,"img":false}]}
{"op":"mcm","clk":"10119450223","pt":1700901849088,"mc":[{"id":"1.221675352","rc":[{"atl":[[7,0]],"id":41132607},{"atb":[[7.6,0]],"id":61861979},{"atb":[[13.5,0]],"id":50758683},{"atb":[[6.2,0],[5.2,0]],"id":51229677},{"atb":[[11,0],[8.8,0]],"id":49487602}],"con":true,"img":false}]}
{"op":"mcm","clk":"10119450234","pt":1700901849143,"mc":[{"id":"1.221675352","rc":[{"atl":[[6,33.82]],"id":41132607},{"atb":[[9.4,21.79]],"id":61861979},{"atb":[[17,4]],"id":50758683},{"atb":[[6.8,9.03],[5.9,25.87]],"id":51229677},{"atb":[[10,13.23],[12.5,4.87]],"id":49487602}],"con":true,"img":false}]}
{"op":"mcm","clk":"10119455729","pt":1700901893013,"mc":[{"id":"1.221675352","rc":[{"atb":[[9.4,16.19]],"id":61861979},{"spn":10.08,"spf":1.0,"id":61861979},{"atb":[[12.5,10.5]],"id":52386044}],"con":true,"img":false}]}
{"op":"mcm","clk":"10119455737","pt":1700901893112,"mc":[{"id":"1.221675352","rc":[{"atb":[[11,5.6]],"id":61861979},{"atb":[[15,4.31]],"id":52386044}],"con":true,"img":false}]}
{"op":"mcm","clk":"10119457892","pt":1700901910324,"mc":[{"id":"1.221675352","rc":[{"atl":[[1000,2.38]],"id":54974498}],"con":true,"img":false}]}
{"op":"mcm","clk":"10119457930","pt":1700901910629,"mc":[{"id":"1.221675352","rc":[{"atl":[[5.6,2.41]],"id":41132607}],"con":true,"img":false}]}
{"op":"mcm","clk":"10119457978","pt":1700901911006,"mc":[{"id":"1.221675352","rc":[{"atl":[[1000,1.57]],"id":54974498}],"con":true,"img":false}]}
{"op":"mcm","clk":"10119458052","pt":1700901911634,"mc":[{"id":"1.221675352","rc":[{"atl":[[1000,0]],"id":54974498}],"con":true,"img":false}]}
{"op":"mcm","clk":"10119458064","pt":1700901911692,"mc":[{"id":"1.221675352","rc":[{"atl":[[8.6,1.57]],"id":54974498}],"con":true,"img":false}]}
{"op":"mcm","clk":"10119458213","pt":1700901912835,"mc":[{"id":"1.221675352","rc":[{"atl":[[7.2,0],[6.6,17.86]],"id":41132607},{"atb":[[2.36,73.53],[2.58,0]],"id":51178794},{"atl":[[11.5,7.36],[12.5,0]],"id":51178794},{"atb":[[6.4,18.52],[5.5,0]],"id":61861979},{"atl":[[140,2],[160,0]],"id":50758683},{"atb":[[4.8,26.32],[4.2,0]],"id":49487602},{"atl":[[70,4.61],[75,0]],"id":49487602}],"con":true,"img":false}]}
{"op":"mcm","clk":"10119458252","pt":1700901913107,"mc":[{"id":"1.221675352","rc":[{"atl":[[50,0]],"id":49487602}],"con":true,"img":false}]}
{"op":"mcm","clk":"10119461081","pt":1700901934840,"mc":[{"id":"1.221675352","rc":[{"atb":[[2.36,0],[2.64,60.98]],"id":51178794}],"con":true,"img":false}]}
{"op":"mcm","clk":"10119461692","pt":1700901939744,"mc":[{"id":"1.221675352","rc":[{"atl":[[11.5,0],[12,14.12]],"id":51178794},{"atb":[[6.4,0],[3.85,35.09]],"id":61861979}],"con":true,"img":false}]}
{"op":"mcm","clk":"10119464404","pt":1700901961462,"mc":[{"id":"1.221675352","rc":[{"atb":[[3.85,0],[6,20]],"id":61861979},{"spn":10.59,"spf":1.0,"id":61861979},{"spn":14.87,"spf":1.0,"id":52386044}],"con":true,"img":false}]}
{"op":"mcm","clk":"10119475007","pt":1700902042364,"mc":[{"id":"1.221675352","rc":[{"atb":[[2,0],[1.9,0],[1.95,0]],"id":41132607},{"atl":[[6.2,0],[8.2,0]],"id":41132607},{"atb":[[4,0],[4.5,0],[5,0]],"id":51178794},{"atl":[[38,0],[24,0]],"id":51178794},{"spn":4.1,"spf":1.0,"id":51178794},{"atb":[[9.2,0],[10.5,0],[8.2,0]],"id":61861979},{"atl":[[260,0],[160,0]],"id":61861979},{"spn":10.0,"spf":1.0,"id":61861979},{"atb":[[3.2,0],[2.88,0],[2.98,0]],"id":54974498},{"atl":[[16,0],[11,0]],"id":54974498},{"spn":2.59,"spf":1.0,"id":54974498},{"atb":[[16.5,0],[19,0],[14,0]],"id":50758683},{"atl":[[260,0],[360,0]],"id":50758683},{"spn":15.11,"spf":1.0,"id":50758683},{"atb":[[5.8,0],[7.6,0],[6.6,0]],"id":51229677},{"atl":[[65,0],[130,0]],"id":51229677},{"atb":[[12,0],[9.8,0],[14.5,0]],"id":52386044},{"atl":[[320,0],[220,0]],"id":52386044},{"spn":14.36,"spf":1.0,"id":52386044},{"atb":[[12,0],[9.8,0],[14.5,0]],"id":49487602},{"atl":[[320,0],[220,0]],"id":49487602},{"spn":12.33,"spf":1.0,"id":49487602}],"con":true,"img":false}]}
{"op":"mcm","clk":"10119475052","pt":1700902042631,"mc":[{"id":"1.221675352","rc":[{"atb":[[7.8,0]],"id":51229677}],"con":true,"img":false}]}
{"op":"mcm","clk":"10119475200","pt":1700902043828,"mc":[{"id":"1.221675352","rc":[{"atl":[[8.6,0]],"id":54974498}],"con":true,"img":false}]}
{"op":"mcm","clk":"10119475972","pt":1700902049348,"mc":[{"id":"1.221675352","rc":[{"atl":[[7.4,15.62],[6.6,0]],"id":41132607},{"atl":[[12,5.03],[13.5,8]],"id":51178794},{"atl":[[70,2.61],[80,2]],"id":49487602}],"con":true,"img":false}]}
{"op":"mcm","clk":"10119476176","pt":1700902051057,"mc":[{"id":"1.221675352","rc":[{"atl":[[7.2,16.51],[6,13.34]],"id":41132607},{"atb":[[11,0],[9.4,0]],"id":61861979},{"atb":[[17,0]],"id":50758683},{"atb":[[6.8,0],[5.9,0]],"id":51229677},{"atb":[[12.5,0],[15,0]],"id":52386044},{"atb":[[10,0],[12.5,0]],"id":49487602}],"con":true,"img":false}]}
{"op":"mcm","clk":"10119476187","pt":1700902051155,"mc":[{"id":"1.221675352","rc":[{"atb":[[6,0],[7.6,16.19],[4.2,31.25],[9.4,5.6]],"id":61861979},{"atb":[[13.5,4]],"id":50758683},{"atb":[[2.36,73.53],[3.2,0],[6.2,9.03],[5.2,25.87]],"id":51229677},{"atb":[[10,10.5],[12.5,4.31]],"id":52386044},{"atb":[[4.8,0],[11,4.87],[8.8,13.23],[4.2,31.25]],"id":49487602}],"con":true,"img":false}]}
{"op":"mcm","clk":"10119476215","pt":1700902051364,"mc":[{"id":"1.221675352","rc":[{"atb":[[3.5,19.13]],"id":52386044}],"con":true,"img":false}]}
{"op":"mcm","clk":"10119476600","pt":1700902054428,"mc":[{"id":"1.221675352","rc":[{"atl":[[16.5,6.45]],"id":51178794}],"con":true,"img":false}]}
{"op":"mcm","clk":"10119476607","pt":1700902054537,"mc":[{"id":"1.221675352","rc":[{"atl":[[13.5,0]],"id":51178794}],"con":true,"img":false}]}
{"op":"mcm","clk":"10119476691","pt":1700902055369,"mc":[{"id":"1.221675352","rc":[{"atb":[[2,104.28],[1.9,231.74],[1.95,219.54]],"id":41132607},{"atl":[[5.6,0],[6.2,26.76],[8.2,28.99]],"id":41132607},{"atb":[[4,69.52],[4.5,59.59],[5,26.07]],"id":51178794},{"atl":[[38,5.64],[24,6.05]],"id":51178794},{"atb":[[9.2,25.43],[10.5,10.97],[8.2,28.96]],"id":61861979},{"atl":[[260,0.8],[160,0.87]],"id":61861979},{"atb":[[3.2,47.4],[2.88,110.94],[2.98,105.33]],"id":54974498},{"atl":[[16,13.91],[11,13.91]],"id":54974498},{"atb":[[16.5,13.45],[19,5.79],[14,16.04]],"id":50758683},{"atl":[[260,0.53],[360,0.57]],"id":50758683},{"atb":[[5.8,43.45],[7.6,15.79],[6.6,37.24]],"id":51229677},{"atl":[[65,2.17],[130,1.61]],"id":51229677},{"atb":[[12,18.96],[9.8,23.69],[14.5,7.72]],"id":52386044},{"atl":[[320,0.65],[220,0.63]],"id":52386044},{"atb":[[12,18.96],[9.8,23.69],[14.5,7.72]],"id":49487602},{"atl":[[320,0.65],[220,0.63]],"id":49487602}],"con":true,"img":false}]}
{"op":"mcm","clk":"10119476731","pt":1700902055645,"mc":[{"id":"1.221675352","rc":[{"atb":[[3.5,0]],"id":52386044}],"con":true,"img":false}]}
{"op":"mcm","clk":"10119478451","pt":1700902069956,"mc":[{"id":"1.221675352","rc":[{"atl":[[7.2,32.64]],"id":41132607},{"atl":[[75,2]],"id":49487602}],"con":true,"img":false}]}
{"op":"mcm","clk":"10119478465","pt":1700902070058,"mc":[{"id":"1.221675352","rc":[{"atl":[[7.4,0]],"id":41132607},{"atl":[[80,0]],"id":49487602}],"con":true,"img":false}]}
{"op":"mcm","clk":"10119478664","pt":1700902071776,"mc":[{"id":"1.221675352","rc":[{"atb":[[5.5,22.22],[4.2,0]],"id":61861979},{"atb":[[2.36,0],[3.2,45.45]],"id":51229677}],"con":true,"img":false}]}
{"op":"mcm","clk":"10119479056","pt":1700902075056,"mc":[{"id":"1.221675352","rc":[{"atl":[[16.5,0],[12.5,8.7]],"id":51178794}],"con":true,"img":false}]}
{"op":"mcm","clk":"10119480820","pt":1700902089207,"mc":[{"id":"1.221675352","rc":[{"atl":[[1000,2.38]],"id":54974498}],"con":true,"img":false}]}
{"op":"mcm","clk":"10119480831","pt":1700902089304,"mc":[{"id":"1.221675352","rc":[{"atb":[[2,0],[1.9,0],[1.95,0]],"id":41132607},{"atl":[[6.2,0],[8.2,0]],"id":41132607},{"atb":[[4,0],[4.5,0],[5,0]],"id":51178794},{"atl":[[38,0],[24,0]],"id":51178794},{"atb":[[9.2,0],[10.5,0],[8.2,0]],"id":61861979},{"atl":[[260,0],[160,0]],"id":61861979},{"atb":[[3.2,0],[2.88,0],[2.98,0]],"id":54974498},{"atl":[[16,0],[11,0]],"id":54974498},{"atb":[[16.5,0],[19,0],[14,0]],"id":50758683},{"atl":[[260,0],[360,0]],"id":50758683},{"atb":[[5.8,0],[7.6,0],[6.6,0]],"id":51229677},{"atl":[[65,0],[130,0]],"id":51229677},{"atb":[[12,0],[9.8,0],[14.5,0]],"id":49487602},{"atl":[[320,0],[220,0]],"id":49487602}],"con":true,"img":false}]}
{"op":"mcm","clk":"10119480867","pt":1700902089578,"mc":[{"id":"1.221675352","rc":[{"atl":[[1000,2.38]],"id":41132607}],"con":true,"img":false}]}
{"op":"mcm","clk":"10119480889","pt":1700902089783,"mc":[{"id":"1.221675352","rc":[{"atl":[[1000,1.57]],"id":54974498}],"con":true,"img":false}]}
{"op":"mcm","clk":"10119480914","pt":1700902089985,"mc":[{"id":"1.221675352","rc":[{"atl":[[1000,2.36]],"id":41132607}],"con":true,"img":false}]}
{"op":"mcm","clk":"10119480939","pt":1700902090195,"mc":[{"id":"1.221675352","rc":[{"atl":[[1000,0]],"id":54974498}],"con":true,"img":false}]}
{"op":"mcm","clk":"10119480952","pt":1700902090300,"mc":[{"id":"1.221675352","rc":[{"atl":[[8.6,1.57]],"id":54974498}],"con":true,"img":false}]}
{"op":"mcm","clk":"10119481003","pt":1700902090673,"mc":[{"id":"1.221675352","rc":[{"atl":[[1000,0]],"id":41132607}],"con":true,"img":false}]}
{"op":"mcm","clk":"10119481015","pt":1700902090777,"mc":[{"id":"1.221675352","rc":[{"atl":[[5.7,2.36]],"id":41132607}],"con":true,"img":false}]}
{"op":"mcm","clk":"10119481536","pt":1700902095299,"mc":[{"id":"1.221675352","rc":[{"atl":[[12.5,0],[14,7.69]],"id":51178794},{"atl":[[75,0],[85,2]],"id":49487602}],"con":true,"img":false}]}
{"op":"mcm","clk":"10119484303","pt":1700902117786,"mc":[{"id":"1.221675352","rc":[{"spn":8.56,"spf":1.0,"id":61861979},{"spn":13.0,"spf":1.0,"id":50758683},{"spn":10.35,"spf":1.0,"id":51229677},{"atb":[[10,0]],"id":52386044},{"spn":14.5,"spf":1.0,"id":52386044},{"spn":10.85,"spf":1.0,"id":49487602}],"con":true,"img":false}]}
{"op":"mcm","clk":"10119484315","pt":1700902117884,"mc":[{"id":"1.221675352","rc":[{"atb":[[12.5,14.81]],"id":52386044}],"con":true,"img":false}]}
{"op":"mcm","clk":"10119484951","pt":1700902123201,"mc":[{"id":"1.221675352","rc":[{"atb":[[2,104.28],[1.9,231.74],[1.95,219.54]],"id":41132607},{"atl":[[6.2,26.76],[8.2,28.99]],"id":41132607},{"atb":[[4,69.52],[4.5,59.59],[5,26.07]],"id":51178794},{"atl":[[38,5.64],[24,6.05]],"id":51178794},{"atb":[[9.2,25.43],[10.5,10.97],[8.2,28.96]],"id":61861979},{"atl":[[260,0.8],[160,0.87]],"id":61861979},{"atb":[[3.2,47.4],[2.88,110.94],[2.98,105.33]],"id":54974498},{"atl":[[16,13.91],[11,13.91]],"id":54974498},{"atb":[[16.5,13.45],[19,5.79],[14,16.04]],"id":50758683},{"atl":[[260,0.53],[360,0.57]],"id":50758683},{"atb":[[5.8,43.45],[7.6,15.79],[6.6,37.24]],"id":51229677},{"atl":[[65,2.17],[130,1.61]],"id":51229677},{"atb":[[12,18.96],[9.8,23.69],[14.5,7.72]],"id":49487602},{"atl":[[320,0.65],[220,0.63]],"id":49487602}],"con":true,"img":false}]}
{"op":"mcm","clk":"10119485948","pt":1700902132220,"mc":[{"id":"1.221675352","rc":[{"atl":[[12.5,8.7],[14,0]],"id":51178794},{"atl":[[75,2],[85,0]],"id":49487602}],"con":true,"img":false}]}
{"op":"mcm","clk":"10119489265","pt":1700902159924,"mc":[{"id":"1.221675352","rc":[{"atb":[[6.2,0]],"id":51229677},{"atb":[[11,0]],"id":49487602}],"con":true,"img":false}]}
{"op":"mcm","clk":"10119489275","pt":1700902160022,"mc":[{"id":"1.221675352","rc":[{"atb":[[6.8,9.03]],"id":51229677},{"atb":[[12.5,4.87]],"id":49487602}],"con":true,"img":false}]}
{"op":"mcm","clk":"10119490325","pt":1700902169032,"mc":[{"id":"1.221675352","rc":[{"atb":[[13.5,0]],"id":50758683}],"con":true,"img":false}]}
{"op":"mcm","clk":"10119490334","pt":1700902169140,"mc":[{"id":"1.221675352","rc":[{"atb":[[17,4]],"id":50758683}],"con":true,"img":false}]}
{"op":"mcm","clk":"10119491083","pt":1700902175338,"mc":[{"id":"1.221675352","rc":[{"atl":[[7.2,16.13],[6,33.82]],"id":41132607},{"atb":[[5.2,0]],"id":51229677},{"atb":[[8.8,0]],"id":49487602}],"con":true,"img":false}]}
{"op":"mcm","clk":"10119491092","pt":1700902175439,"mc":[{"id":"1.221675352","rc":[{"atb":[[5.9,25.87]],"id":51229677},{"atb":[[10,13.23]],"id":49487602}],"con":true,"img":false}]}
{"op":"mcm","clk":"10119491099","pt":1700902175544,"mc":[{"id":"1.221675352","rc":[{"atb":[[7.6,0]],"id":61861979}],"con":true,"img":false}]}
{"op":"mcm","clk":"10119491116","pt":1700902175654,"mc":[{"id":"1.221675352","rc":[{"atb":[[9.4,21.79]],"id":61861979}],"con":true,"img":false}]}
{"op":"mcm","clk":"10119494337","pt":1700902202469,"mc":[{"id":"1.221675352","rc":[{"spn":5.0,"spf":1.0,"id":51178794},{"atb":[[9.4,16.19]],"id":61861979},{"spn":10.08,"spf":1.0,"id":61861979},{"spn":3.2,"spf":1.0,"id":54974498},{"spn":19.0,"spf":1.0,"id":50758683},{"spn":11.05,"spf":1.0,"id":51229677},{"atb":[[12.5,10.5]],"id":52386044},{"spn":14.5,"spf":1.0,"id":49487602}],"con":true,"img":false}]}
{"op":"mcm","clk":"10119494352","pt":1700902202575,"mc":[{"id":"1.221675352","rc":[{"atb":[[11,5.6]],"id":61861979},{"atb":[[15,4.31]],"id":52386044}],"con":true,"img":false}]}
{"op":"mcm","clk":"10119494396","pt":1700902202866,"mc":[{"id":"1.221675352","rc":[{"atb":[[7.8,1.11]],"id":51229677},{"atl":[[1000,0.86]],"id":49487602}],"con":true,"img":false}]}
{"op":"mcm","clk":"10119494425","pt":1700902203081,"mc":[{"id":"1.221675352","rc":[{"atl":[[1000,0.17]],"id":49487602}],"con":true,"img":false}]}
{"op":"mcm","clk":"10119494460","pt":1700902203343,"mc":[{"id":"1.221675352","rc":[{"atl":[[1000,0]],"id":49487602}],"con":true,"img":false}]}
{"op":"mcm","clk":"10119494474","pt":1700902203451,"mc":[{"id":"1.221675352","rc":[{"atl":[[50,0.17]],"id":49487602}],"con":true,"img":false}]}
{"op":"mcm","clk":"10119495273","pt":1700902209678,"mc":[{"id":"1.221675352","rc":[{"atl":[[5.6,2.61]],"id":41132607}],"con":true,"img":false}]}
{"op":"mcm","clk":"10119495311","pt":1700902209985,"mc":[{"id":"1.221675352","rc":[{"atb":[[1.01,5.22]],"id":41132607}],"con":true,"img":false}]}
{"op":"mcm","clk":"10119495323","pt":1700902210043,"mc":[{"id":"1.221675352","rc":[{"atb":[[1.01,4.79]],"id":41132607}],"con":true,"img":false}]}
{"op":"mcm","clk":"10119495348","pt":1700902210255,"mc":[{"id":"1.221675352","rc":[{"atb":[[1.01,2.61]],"id":41132607}],"con":true,"img":false}]}
{"op":"mcm","clk":"10119495360","pt":1700902210358,"mc":[{"id":"1.221675352","rc":[{"atb":[[2.44,2.17]],"id":41132607}],"con":true,"img":false}]}
{"op":"mcm","clk":"10119495784","pt":1700902213656,"mc":[{"id":"1.221675352","rc":[{"atl":[[8.6,0]],"id":54974498}],"con":true,"img":false}]}
{"op":"mcm","clk":"10119497221","pt":1700902225273,"mc":[{"id":"1.221675352","rc":[{"atl":[[5.6,0]],"id":41132607}],"con":true,"img":false}]}
{"op":"mcm","clk":"10119497284","pt":1700902225693,"mc":[{"id":"1.221675352","rc":[{"atb":[[2.44,0]],"id":41132607}],"con":true,"img":false}]}
{"op":"mcm","clk":"10119497445","pt":1700902226781,"mc":[{"id":"1.221675352","rc":[{"atl":[[5.6,2.61]],"id":41132607}],"con":true,"img":false}]}
{"op":"mcm","clk":"10119497511","pt":1700902227300,"mc":[{"id":"1.221675352","rc":[{"atb":[[1.01,5.22]],"id":41132607}],"con":true,"img":false}]}
{"op":"mcm","clk":"10119497536","pt":1700902227500,"mc":[{"id":"1.221675352","rc":[{"atb":[[1.01,4.75]],"id":41132607}],"con":true,"img":false}]}
{"op":"mcm","clk":"10119497566","pt":1700902227707,"mc":[{"id":"1.221675352","rc":[{"atb":[[1.01,2.61]],"id":41132607}],"con":true,"img":false}]}
{"op":"mcm","clk":"10119497578","pt":1700902227763,"mc":[{"id":"1.221675352","rc":[{"atb":[[2.46,2.14]],"id":41132607}],"con":true,"img":false}]}
{"op":"mcm","clk":"10119498546","pt":1700902235404,"mc":[{"id":"1.221675352","rc":[{"atl":[[5.7,0]],"id":41132607}],"con":true,"img":false}]}
{"op":"mcm","clk":"10119499472","pt":1700902242481,"mc":[{"id":"1.221675352","rc":[{"atl":[[5.6,0]],"id":41132607}],"con":true,"img":false}]}
{"op":"mcm","clk":"10119499573","pt":1700902243211,"mc":[{"id":"1.221675352","rc":[{"atb":[[2.46,0]],"id":41132607}],"con":true,"img":false}]}
{"op":"mcm","clk":"10119499636","pt":1700902243671,"mc":[{"id":"1.221675352","rc":[{"atl":[[5.9,2.61]],"id":41132607}],"con":true,"img":false}]}
{"op":"mcm","clk":"10119499661","pt":1700902243877,"mc":[{"id":"1.221675352","rc":[{"atb":[[1.01,5.22]],"id":41132607}],"con":true,"img":false}]}
{"op":"mcm","clk":"10119499701","pt":1700902244191,"mc":[{"id":"1.221675352","rc":[{"atb":[[1.01,4.72]],"id":41132607}],"con":true,"img":false}]}
{"op":"mcm","clk":"10119499712","pt":1700902244296,"mc":[{"id":"1.221675352","rc":[{"atb":[[1.01,2.61]],"id":41132607}],"con":true,"img":false}]}
{"op":"mcm","clk":"10119499728","pt":1700902244397,"mc":[{"id":"1.221675352","rc":[{"atb":[[2.48,2.11]],"id":41132607}],"con":true,"img":false}]}
{"op":"mcm","clk":"10119501668","pt":1700902259007,"mc":[{"id":"1.221675352","rc":[{"atl":[[5.9,0]],"id":41132607}],"con":true,"img":false}]}
{"op":"mcm","clk":"10119501750","pt":1700902259730,"mc":[{"id":"1.221675352","rc":[{"atb":[[2.48,0]],"id":41132607}],"con":true,"img":false}]}
{"op":"mcm","clk":"10119501959","pt":1700902261519,"mc":[{"id":"1.221675352","rc":[{"atl":[[5.9,2.61]],"id":41132607}],"con":true,"img":false}]}
{"op":"mcm","clk":"10119502001","pt":1700902261932,"mc":[{"id":"1.221675352","rc":[{"atb":[[1.01,5.22]],"id":41132607}],"con":true,"img":false}]}
{"op":"mcm","clk":"10119502038","pt":1700902262099,"mc":[{"id":"1.221675352","rc":[{"atb":[[1.01,4.79]],"id":41132607}],"con":true,"img":false}]}
{"op":"mcm","clk":"10119502067","pt":1700902262307,"mc":[{"id":"1.221675352","rc":[{"atb":[[1.01,2.61]],"id":41132607}],"con":true,"img":false}]}
{"op":"mcm","clk":"10119502086","pt":1700902262409,"mc":[{"id":"1.221675352","rc":[{"atb":[[2.44,2.17]],"id":41132607}],"con":true,"img":false}]}
{"op":"mcm","clk":"10119502887","pt":1700902267824,"mc":[{"id":"1.221675352","rc":[{"atl":[[5.6,2.41]],"id":41132607},{"spn":2.43,"spf":1.0,"id":41132607},{"spn":10.59,"spf":1.0,"id":61861979},{"spn":11.15,"spf":1.0,"id":51229677},{"spn":14.87,"spf":1.0,"id":52386044}],"con":true,"img":false}]}
{"op":"mcm","clk":"10119502917","pt":1700902268031,"mc":[{"id":"1.221675352","rc":[{"atl":[[1000,2.38]],"id":54974498}],"con":true,"img":false}]}
{"op":"mcm","clk":"10119502938","pt":1700902268233,"mc":[{"id":"1.221675352","rc":[{"atl":[[1000,1.57]],"id":54974498}],"con":true,"img":false}]}
{"op":"mcm","clk":"10119502963","pt":1700902268396,"mc":[{"id":"1.221675352","rc":[{"atl":[[1000,0]],"id":54974498}],"con":true,"img":false}]}
{"op":"mcm","clk":"10119502973","pt":1700902268534,"mc":[{"id":"1.221675352","rc":[{"atl":[[8.6,1.57]],"id":54974498}],"con":true,"img":false}]}
{"op":"mcm","clk":"10119503911","pt":1700902275431,"mc":[{"id":"1.221675352","rc":[{"atl":[[7.2,0],[6.8,17.24]],"id":41132607},{"atl":[[12,12.39],[12.5,0]],"id":51178794},{"atb":[[4.8,26.32],[4.2,0]],"id":49487602},{"atl":[[70,4.61],[75,0]],"id":49487602}],"con":true,"img":false}]}
{"op":"mcm","clk":"10119504185","pt":1700902277249,"mc":[{"id":"1.221675352","rc":[{"atl":[[5.9,0]],"id":41132607}],"con":true,"img":false}]}
{"op":"mcm","clk":"10119504242","pt":1700902277615,"mc":[{"id":"1.221675352","rc":[{"atb":[[2.44,0]],"id":41132607}],"con":true,"img":false}]}
{"op":"mcm","clk":"10119504380","pt":1700902278443,"mc":[{"id":"1.221675352","rc":[{"atl":[[5.5,2.61]],"id":41132607}],"con":true,"img":false}]}
{"op":"mcm","clk":"10119504478","pt":1700902279017,"mc":[{"id":"1.221675352","rc":[{"atb":[[1.01,5.22]],"id":41132607}],"con":true,"img":false}]}
{"op":"mcm","clk":"10119504511","pt":1700902279223,"mc":[{"id":"1.221675352","rc":[{"atb":[[1.01,4.79]],"id":41132607}],"con":true,"img":false}]}
{"op":"mcm","clk":"10119504527","pt":1700902279429,"mc":[{"id":"1.221675352","rc":[{"atb":[[1.01,2.61]],"id":41132607}],"con":true,"img":false}]}
{"op":"mcm","clk":"10119504542","pt":1700902279530,"mc":[{"id":"1.221675352","rc":[{"atb":[[2.44,2.17]],"id":41132607}],"con":true,"img":false}]}
{"op":"mcm","clk":"10119506429","pt":1700902292751,"mc":[{"id":"1.221675352","rc":[{"spl":[[1.01,15.67]],"id":52386044}],"con":true,"img":false}]}
{"op":"mcm","clk":"10119506641","pt":1700902294232,"mc":[{"id":"1.221675352","rc":[{"atl":[[5.5,0]],"id":41132607}],"con":true,"img":false}]}
{"op":"mcm","clk":"10119506716","pt":1700902294942,"mc":[{"id":"1.221675352","rc":[{"atb":[[2.44,0]],"id":41132607}],"con":true,"img":false}]}
{"op":"mcm","clk":"10119506824","pt":1700902295723,"mc":[{"id":"1.221675352","rc":[{"atl":[[5.5,2.61]],"id":41132607}],"con":true,"img":false}]}
{"op":"mcm","clk":"10119506872","pt":1700902296130,"mc":[{"id":"1.221675352","rc":[{"atb":[[1.01,5.22]],"id":41132607}],"con":true,"img":false}]}
{"op":"mcm","clk":"10119506895","pt":1700902296343,"mc":[{"id":"1.221675352","rc":[{"atb":[[1.01,4.75]],"id":41132607}],"con":true,"img":false}]}
{"op":"mcm","clk":"10119506923","pt":1700902296546,"mc":[{"id":"1.221675352","rc":[{"atb":[[1.01,2.61]],"id":41132607}],"con":true,"img":false}]}
{"op":"mcm","clk":"10119506939","pt":1700902296652,"mc":[{"id":"1.221675352","rc":[{"atb":[[2.46,2.14]],"id":41132607}],"con":true,"img":false}]}
{"op":"mcm","clk":"10119508682","pt":1700902311272,"mc":[{"id":"1.221675352","rc":[{"atl":[[5.5,0]],"id":41132607}],"con":true,"img":false}]}
{"op":"mcm","clk":"10119508770","pt":1700902312055,"mc":[{"id":"1.221675352","rc":[{"atb":[[2.46,0]],"id":41132607}],"con":true,"img":false}]}
{"op":"mcm","clk":"10119508878","pt":1700902313042,"mc":[{"id":"1.221675352","rc":[{"atl":[[5.5,2.61]],"id":41132607}],"con":true,"img":false}]}
{"op":"mcm","clk":"10119508902","pt":1700902313145,"mc":[{"id":"1.221675352","rc":[{"atb":[[1.01,5.22]],"id":41132607}],"con":true,"img":false}]}
{"op":"mcm","clk":"10119508924","pt":1700902313348,"mc":[{"id":"1.221675352","rc":[{"atb":[[1.01,4.72]],"id":41132607}],"con":true,"img":false}]}
{"op":"mcm","clk":"10119508935","pt":1700902313451,"mc":[{"id":"1.221675352","rc":[{"atb":[[1.01,2.61]],"id":41132607}],"con":true,"img":false}]}
{"op":"mcm","clk":"10119508949","pt":1700902313564,"mc":[{"id":"1.221675352","rc":[{"atb":[[2.48,2.11]],"id":41132607}],"con":true,"img":false}]}
{"op":"mcm","clk":"10119509987","pt":1700902322454,"mc":[{"id":"1.221675352","rc":[{"atb":[[3.4,1.98]],"id":54974498}],"con":true,"img":false}]}
{"op":"mcm","clk":"10119510887","pt":1700902328573,"mc":[{"id":"1.221675352","rc":[{"atl":[[5.5,0]],"id":41132607},{"spn":2.46,"spf":1.0,"id":41132607},{"spn":3.21,"spf":1.0,"id":54974498},{"spn":13.72,"spf":1.0,"id":52386044}],"con":true,"img":false}]}
{"op":"mcm","clk":"10119510938","pt":1700902328984,"mc":[{"id":"1.221675352","rc":[{"atb":[[2.48,0]],"id":41132607}],"con":true,"img":false}]}
{"op":"mcm","clk":"10119510981","pt":1700902329298,"mc":[{"id":"1.221675352","rc":[{"spl":[[1.01,3.13]],"id":51178794}],"con":true,"img":false}]}
{"op":"mcm","clk":"10119511022","pt":1700902329666,"mc":[{"id":"1.221675352","rc":[{"atl":[[5.4,2.61]],"id":41132607}],"con":true,"img":false}]}
{"op":"mcm","clk":"10119511055","pt":1700902329978,"mc":[{"id":"1.221675352","rc":[{"atb":[[1.01,5.22]],"id":41132607}],"con":true,"img":false}]}
{"op":"mcm","clk":"10119511066","pt":1700902330078,"mc":[{"id":"1.221675352","rc":[{"atb":[[1.01,4.7]],"id":41132607}],"con":true,"img":false}]}
{"op":"mcm","clk":"10119511091","pt":1700902330288,"mc":[{"id":"1.221675352","rc":[{"atb":[[1.01,2.61]],"id":41132607}],"con":true,"img":false}]}
{"op":"mcm","clk":"10119511108","pt":1700902330396,"mc":[{"id":"1.221675352","rc":[{"atb":[[2.5,2.08]],"id":41132607}],"con":true,"img":false}]}
{"op":"mcm","clk":"10119513054","pt":1700902345395,"mc":[{"id":"1.221675352","rc":[{"atl":[[5.4,0]],"id":41132607}],"con":true,"img":false}]}
{"op":"mcm","clk":"10119513100","pt":1700902345707,"mc":[{"id":"1.221675352","rc":[{"atb":[[2.5,0]],"id":41132607}],"con":true,"img":false}]}
{"op":"mcm","clk":"10119515098","pt":1700902360528,"mc":[{"id":"1.221675352","rc":[{"atl":[[5.5,2.61]],"id":41132607}],"con":true,"img":false}]}
{"op":"mcm","clk":"10119515139","pt":1700902360838,"mc":[{"id":"1.221675352","rc":[{"atb":[[1.01,5.22]],"id":41132607}],"con":true,"img":false}]}
{"op":"mcm","clk":"10119515161","pt":1700902361047,"mc":[{"id":"1.221675352","rc":[{"atb":[[1.01,4.79]],"id":41132607}],"con":true,"img":false}]}
{"op":"mcm","clk":"10119515188","pt":1700902361211,"mc":[{"id":"1.221675352","rc":[{"atb":[[1.01,2.61]],"id":41132607}],"con":true,"img":false}]}
{"op":"mcm","clk":"10119515198","pt":1700902361305,"mc":[{"id":"1.221675352","rc":[{"atb":[[2.44,2.17]],"id":41132607}],"con":true,"img":false}]}
{"op":"mcm","clk":"10119515675","pt":1700902364897,"mc":[{"id":"1.221675352","rc":[{"atb":[[17.5,3.03]],"id":50758683}],"con":true,"img":false}]}
{"op":"mcm","clk":"10119515692","pt":1700902365065,"mc":[{"id":"1.221675352","rc":[{"atb":[[10,5.3]],"id":61861979}],"con":true,"img":false}]}
{"op":"mcm","clk":"10119515708","pt":1700902365173,"mc":[{"id":"1.221675352","rc":[{"atb":[[13.5,3.92]],"id":52386044}],"con":true,"img":false}]}
{"op":"mcm","clk":"10119515739","pt":1700902365339,"mc":[{"id":"1.221675352","rc":[{"atb":[[7,7.58]],"id":51229677}],"con":true,"img":false}]}
{"op":"mcm","clk":"10119515763","pt":1700902365542,"mc":[{"id":"1.221675352","rc":[{"atb":[[4.5,71.38]],"id":51178794}],"con":true,"img":false}]}
{"op":"mcm","clk":"10119515788","pt":1700902365755,"mc":[{"id":"1.221675352","rc":[{"atb":[[13,4.08]],"id":49487602}],"con":true,"img":false}]}
{"op":"mcm","clk":"10119515801","pt":1700902365856,"mc":[{"id":"1.221675352","rc":[{"atb":[[2.22,23.89]],"id":41132607}],"con":true,"img":false}]}
{"op":"mcm","clk":"10119515813","pt":1700902365901,"mc":[{"id":"1.221675352","rc":[{"atb":[[3.1,17.11]],"id":54974498}],"con":true,"img":false}]}
{"op":"mcm","clk":"10119517035","pt":1700902375842,"mc":[{"id":"1.221675352","rc":[{"atl":[[5.5,0]],"id":41132607}],"con":true,"img":false}]}
{"op":"mcm","clk":"10119517135","pt":1700902376681,"mc":[{"id":"1.221675352","rc":[{"atb":[[2.44,0]],"id":41132607}],"con":true,"img":false}]}
{"op":"mcm","clk":"10119517223","pt":1700902377350,"mc":[{"id":"1.221675352","rc":[{"atl":[[5.5,2.61]],"id":41132607}],"con":true,"img":false}]}
{"op":"mcm","clk":"10119517250","pt":1700902377556,"mc":[{"id":"1.221675352","rc":[{"atb":[[1.01,5.22]],"id":41132607}],"con":true,"img":false}]}
{"op":"mcm","clk":"10119517292","pt":1700902377819,"mc":[{"id":"1.221675352","rc":[{"atb":[[1.01,4.75]],"id":41132607}],"con":true,"img":false}]}
{"op":"mcm","clk":"10119517331","pt":1700902378027,"mc":[{"id":"1.221675352","rc":[{"atb":[[1.01,2.61]],"id":41132607}],"con":true,"img":false}]}
{"op":"mcm","clk":"10119517351","pt":1700902378133,"mc":[{"id":"1.221675352","rc":[{"atb":[[2.46,2.14]],"id":41132607}],"con":true,"img":false}]}
{"op":"mcm","clk":"10119519124","pt":1700902391338,"mc":[{"id":"1.221675352","rc":[{"spn":2.45,"spf":1.0,"id":41132607},{"spn":10.62,"spf":1.0,"id":61861979},{"atl":[[8.6,0]],"id":54974498},{"spn":13.9,"spf":1.0,"id":52386044}],"con":true,"img":false}]}
{"op":"mcm","clk":"10119519291","pt":1700902392535,"mc":[{"id":"1.221675352","rc":[{"atb":[[2.1,0]],"id":41132607}],"con":true,"img":false}]}
{"op":"mcm","clk":"10119519304","pt":1700902392641,"mc":[{"id":"1.221675352","rc":[{"atb":[[2.24,54.93]],"id":41132607}],"con":true,"img":false}]}
{"op":"mcm","clk":"10119519316","pt":1700902392749,"mc":[{"id":"1.221675352","rc":[{"atl":[[5.5,0]],"id":41132607}],"con":true,"img":false}]}
{"op":"mcm","clk":"10119519378","pt":1700902393294,"mc":[{"id":"1.221675352","rc":[{"atb":[[2.5,1.98]],"id":41132607}],"con":true,"img":false}]}
{"op":"mcm","clk":"10119519401","pt":1700902393452,"mc":[{"id":"1.221675352","rc":[{"atb":[[2.46,0]],"id":41132607}],"con":true,"img":false}]}
{"op":"mcm","clk":"10119519488","pt":1700902394175,"mc":[{"id":"1.221675352","rc":[{"atl":[[5.5,2.61]],"id":41132607}],"con":true,"img":false}]}
{"op":"mcm","clk":"10119519511","pt":1700902394335,"mc":[{"id":"1.221675352","rc":[{"atb":[[1.01,5.22]],"id":41132607}],"con":true,"img":false}]}
{"op":"mcm","clk":"10119519523","pt":1700902394439,"mc":[{"id":"1.221675352","rc":[{"atb":[[1.01,4.72]],"id":41132607}],"con":true,"img":false}]}
{"op":"mcm","clk":"10119519536","pt":1700902394540,"mc":[{"id":"1.221675352","rc":[{"atb":[[1.01,2.61]],"id":41132607}],"con":true,"img":false}]}
{"op":"mcm","clk":"10119519547","pt":1700902394646,"mc":[{"id":"1.221675352","rc":[{"atb":[[2.48,2.11]],"id":41132607}],"con":true,"img":false}]}
{"op":"mcm","clk":"10119519656","pt":1700902395488,"mc":[{"id":"1.221675352","rc":[{"atl":[[12,5.03],[12.5,8.7]],"id":51178794},{"atl":[[70,2.61],[75,2]],"id":49487602}],"con":true,"img":false}]}
{"op":"mcm","clk":"10119520395","pt":1700902400672,"mc":[{"id":"1.221675352","rc":[{"atl":[[16.5,6.45],[12.5,0]],"id":51178794}],"con":true,"img":false}]}
{"op":"mcm","clk":"10119521459","pt":1700902408588,"mc":[{"id":"1.221675352","rc":[{"atb":[[2,0],[1.95,0],[1.9,0]],"id":41132607},{"atl":[[6.2,0],[8.2,0]],"id":41132607},{"atb":[[4,0],[4.5,11.79],[5,0]],"id":51178794},{"atl":[[38,0],[24,0]],"id":51178794},{"atb":[[9.2,0],[10.5,0],[8.2,0]],"id":61861979},{"atl":[[260,0],[160,0]],"id":61861979},{"atb":[[3.2,0],[2.88,0],[2.98,0]],"id":54974498},{"atl":[[16,0],[11,0]],"id":54974498},{"atb":[[14,0],[16.5,0],[19,0]],"id":50758683},{"atl":[[260,0],[360,0]],"id":50758683},{"atb":[[5.8,0],[7.6,0],[6.6,0]],"id":51229677},{"atl":[[65,0],[130,0]],"id":51229677},{"atb":[[12,0],[9.8,0],[14.5,0]],"id":52386044},{"atl":[[320,0],[220,0]],"id":52386044},{"atb":[[12,0],[9.8,0],[14.5,0]],"id":49487602},{"atl":[[320,0],[220,0]],"id":49487602}],"con":true,"img":false}]}
{"op":"mcm","clk":"10119521502","pt":1700902408947,"mc":[{"id":"1.221675352","rc":[{"atb":[[7.2,1.11]],"id":51229677}],"con":true,"img":false}]}
{"op":"mcm","clk":"10119521514","pt":1700902409050,"mc":[{"id":"1.221675352","rc":[{"atb":[[7.8,0]],"id":51229677}],"con":true,"img":false}]}
{"op":"mcm","clk":"10119521554","pt":1700902409363,"mc":[{"id":"1.221675352","rc":[{"atl":[[5.5,0]],"id":41132607}],"con":true,"img":false}]}
{"op":"mcm","clk":"10119521653","pt":1700902410037,"mc":[{"id":"1.221675352","rc":[{"atb":[[2.48,0]],"id":41132607}],"con":true,"img":false}]}
{"op":"mcm","clk":"10119521734","pt":1700902410663,"mc":[{"id":"1.221675352","rc":[{"atl":[[5.4,2.61]],"id":41132607}],"con":true,"img":false}]}
{"op":"mcm","clk":"10119521749","pt":1700902410829,"mc":[{"id":"1.221675352","rc":[{"atb":[[1.01,5.22]],"id":41132607}],"con":true,"img":false}]}
{"op":"mcm","clk":"10119521791","pt":1700902411084,"mc":[{"id":"1.221675352","rc":[{"atb":[[1.01,4.67]],"id":41132607}],"con":true,"img":false}]}
{"op":"mcm","clk":"10119521820","pt":1700902411296,"mc":[{"id":"1.221675352","rc":[{"atb":[[1.01,2.61]],"id":41132607}],"con":true,"img":false}]}
{"op":"mcm","clk":"10119521852","pt":1700902411451,"mc":[{"id":"1.221675352","rc":[{"atb":[[2.52,2.06]],"id":41132607},{"atl":[[5.6,0]],"id":41132607}],"con":true,"img":false}]}
{"op":"mcm","clk":"10119522000","pt":1700902412551,"mc":[{"id":"1.221675352","rc":[{"atl":[[6,13.34]],"id":41132607},{"atb":[[9.4,0]],"id":61861979},{"atb":[[5.9,0]],"id":51229677},{"atb":[[12.5,0]],"id":52386044},{"atb":[[10,0]],"id":49487602}],"con":true,"img":false}]}
{"op":"mcm","clk":"10119522017","pt":1700902412714,"mc":[{"id":"1.221675352","rc":[{"atl":[[6.6,20.48]],"id":41132607},{"atl":[[16.5,0],[12.5,8.7]],"id":51178794},{"atb":[[7.6,16.19]],"id":61861979},{"atb":[[5.2,25.87]],"id":51229677},{"atb":[[10,10.5]],"id":52386044},{"atb":[[8.8,13.23]],"id":49487602}],"con":true,"img":false}]}
{"op":"mcm","clk":"10119522609","pt":1700902417526,"mc":[{"id":"1.221675352","rc":[{"atb":[[11,0]],"id":61861979},{"atb":[[17,0]],"id":50758683},{"atb":[[6.8,0]],"id":51229677},{"atb":[[15,0]],"id":52386044},{"atb":[[12.5,0]],"id":49487602}],"con":true,"img":false}]}
{"op":"mcm","clk":"10119522638","pt":1700902417678,"mc":[{"id":"1.221675352","rc":[{"atb":[[10.5,5.6]],"id":61861979},{"atb":[[14,4]],"id":50758683},{"atb":[[6.4,9.03]],"id":51229677},{"atb":[[14,4.31]],"id":52386044},{"atb":[[11,4.87]],"id":49487602}],"con":true,"img":false}]}
{"op":"mcm","clk":"10119523366","pt":1700902423276,"mc":[{"id":"1.221675352","rc":[{"atb":[[2,104.28],[1.95,219.54],[1.9,231.74]],"id":41132607},{"atl":[[6.2,26.76],[8.2,28.99]],"id":41132607},{"atb":[[4,69.52],[4.5,71.38],[5,26.07]],"id":51178794},{"atl":[[38,5.64],[24,6.05]],"id":51178794},{"atb":[[9.2,25.43],[10.5,16.57],[8.2,28.96]],"id":61861979},{"atl":[[260,0.8],[160,0.87]],"id":61861979},{"atb":[[3.2,47.4],[2.88,110.94],[2.98,105.33]],"id":54974498},{"atl":[[16,13.91],[11,13.91]],"id":54974498},{"atb":[[16.5,13.45],[19,5.79],[14,20.04]],"id":50758683},{"atl":[[260,0.53],[360,0.57]],"id":50758683},{"atb":[[5.8,43.45],[7.6,15.79],[6.6,37.24]],"id":51229677},{"atl":[[65,2.17],[130,1.61]],"id":51229677},{"atb":[[12,18.96],[9.8,23.69],[14.5,7.72]],"id":52386044},{"atl":[[320,0.65],[220,0.63]],"id":52386044},{"atb":[[12,18.96],[9.8,23.69],[14.5,7.72]],"id":49487602},{"atl":[[320,0.65],[220,0.63]],"id":49487602}],"con":true,"img":false}]}
{"op":"mcm","clk":"10119523605","pt":1700902425182,"mc":[{"id":"1.221675352","rc":[{"atb":[[14,15.8]],"id":52386044}],"con":true,"img":false}]}
{"op":"mcm","clk":"10119523752","pt":1700902426170,"mc":[{"id":"1.221675352","rc":[{"atl":[[5.4,0]],"id":41132607}],"con":true,"img":false}]}
{"op":"mcm","clk":"10119523764","pt":1700902426274,"mc":[{"id":"1.221675352","rc":[{"atl":[[7.2,16.13],[6.8,0]],"id":41132607}],"con":true,"img":false}]}
{"op":"mcm","clk":"10119523848","pt":1700902426997,"mc":[{"id":"1.221675352","rc":[{"atb":[[2.52,0]],"id":41132607}],"con":true,"img":false}]}
{"op":"mcm","clk":"10119524583","pt":1700902432796,"mc":[{"id":"1.221675352","rc":[{"atb":[[2.12,0]],"id":41132607}],"con":true,"img":false}]}
{"op":"mcm","clk":"10119524604","pt":1700902433001,"mc":[{"id":"1.221675352","rc":[{"atl":[[1000,2.65]],"id":41132607}],"con":true,"img":false}]}
{"op":"mcm","clk":"10119524615","pt":1700902433106,"mc":[{"id":"1.221675352","rc":[{"atb":[[1.03,5.55],[1.21,5.26]],"id":41132607},{"atl":[[1000,15.98]],"id":41132607}],"con":true,"img":false}]}
{"op":"mcm","clk":"10119524627","pt":1700902433165,"mc":[{"id":"1.221675352","rc":[{"atb":[[1.03,8.34]],"id":41132607}],"con":true,"img":false}]}
{"op":"mcm","clk":"10119524702","pt":1700902433885,"mc":[{"id":"1.221675352","rc":[{"atl":[[1000,13.36]],"id":41132607}],"con":true,"img":false}]}
{"op":"mcm","clk":"10119524784","pt":1700902434510,"mc":[{"id":"1.221675352","rc":[{"atb":[[1.03,3.11],[1.21,0.04]],"id":41132607},{"atl":[[1000,0.3]],"id":41132607}],"con":true,"img":false}]}
{"op":"mcm","clk":"10119524846","pt":1700902434978,"mc":[{"id":"1.221675352","rc":[{"atb":[[1.03,0.5]],"id":41132607},{"atl":[[1000,0.26]],"id":41132607}],"con":true,"img":false}]}
{"op":"mcm","clk":"10119524859","pt":1700902435081,"mc":[{"id":"1.221675352","rc":[{"atl":[[6,13.39]],"id":41132607}],"con":true,"img":false}]}
{"op":"mcm","clk":"10119524918","pt":1700902435597,"mc":[{"id":"1.221675352","rc":[{"atb":[[1.03,0.17],[1.21,0]],"id":41132607},{"atl":[[1000,0]],"id":41132607}],"con":true,"img":false}]}
{"op":"mcm","clk":"10119524929","pt":1700902435701,"mc":[{"id":"1.221675352","rc":[{"atb":[[2.5,2.35]],"id":41132607},{"atl":[[6,13.65]],"id":41132607}],"con":true,"img":false}]}
{"op":"mcm","clk":"10119524950","pt":1700902435908,"mc":[{"id":"1.221675352","rc":[{"atb":[[1.03,0]],"id":41132607}],"con":true,"img":false}]}
{"op":"mcm","clk":"10119524963","pt":1700902436013,"mc":[{"id":"1.221675352","rc":[{"atb":[[2.5,2.52]],"id":41132607}],"con":true,"img":false}]}
{"op":"mcm","clk":"10119525705","pt":1700902441877,"mc":[{"id":"1.221675352","rc":[{"atl":[[5.9,2.61]],"id":41132607}],"con":true,"img":false}]}
{"op":"mcm","clk":"10119525717","pt":1700902441983,"mc":[{"id":"1.221675352","rc":[{"atb":[[1.01,5.22]],"id":41132607}],"con":true,"img":false}]}
{"op":"mcm","clk":"10119525742","pt":1700902442190,"mc":[{"id":"1.221675352","rc":[{"atb":[[1.01,4.67]],"id":41132607}],"con":true,"img":false}]}
{"op":"mcm","clk":"10119525768","pt":1700902442399,"mc":[{"id":"1.221675352","rc":[{"atb":[[1.01,2.61]],"id":41132607}],"con":true,"img":false}]}
{"op":"mcm","clk":"10119525780","pt":1700902442499,"mc":[{"id":"1.221675352","rc":[{"atb":[[2.52,2.06]],"id":41132607}],"con":true,"img":false}]}
{"op":"mcm","clk":"10119526387","pt":1700902447482,"mc":[{"id":"1.221675352","rc":[{"atb":[[14,16.04]],"id":50758683},{"atb":[[6.4,0]],"id":51229677},{"atb":[[11,0]],"id":49487602}],"con":true,"img":false}]}
{"op":"mcm","clk":"10119526399","pt":1700902447584,"mc":[{"id":"1.221675352","rc":[{"atb":[[17,4]],"id":50758683},{"atb":[[6.8,9.03]],"id":51229677},{"atb":[[12.5,4.87]],"id":49487602}],"con":true,"img":false}]}
{"op":"mcm","clk":"10119527011","pt":1700902452631,"mc":[{"id":"1.221675352","rc":[{"spn":2.51,"spf":1.0,"id":41132607},{"spn":10.46,"spf":1.0,"id":61861979},{"spn":11.05,"spf":1.0,"id":51229677},{"atb":[[14,11.49]],"id":52386044},{"spn":14.12,"spf":1.0,"id":52386044}],"con":true,"img":false}]}
{"op":"mcm","clk":"10119527026","pt":1700902452731,"mc":[{"id":"1.221675352","rc":[{"atb":[[15,4.31]],"id":52386044}],"con":true,"img":false}]}
{"op":"mcm","clk":"10119527339","pt":1700902455225,"mc":[{"id":"1.221675352","rc":[{"atb":[[2.26,13.79]],"id":41132607}],"con":true,"img":false}]}
{"op":"mcm","clk":"10119527374","pt":1700902455436,"mc":[{"id":"1.221675352","rc":[{"atl":[[7.2,0],[6.8,17.24]],"id":41132607},{"atl":[[11.5,7.36],[12.5,0]],"id":51178794},{"atl":[[70,4.61],[75,0]],"id":49487602}],"con":true,"img":false}]}
{"op":"mcm","clk":"10119527421","pt":1700902455702,"mc":[{"id":"1.221675352","rc":[{"atl":[[50,0]],"id":49487602}],"con":true,"img":false}]}
{"op":"mcm","clk":"10119527630","pt":1700902457405,"mc":[{"id":"1.221675352","rc":[{"atl":[[5.9,0]],"id":41132607}],"con":true,"img":false}]}
{"op":"mcm","clk":"10119527695","pt":1700902457921,"mc":[{"id":"1.221675352","rc":[{"atb":[[2.52,0]],"id":41132607}],"con":true,"img":false}]}
{"op":"mcm","clk":"10119527804","pt":1700902458808,"mc":[{"id":"1.221675352","rc":[{"atl":[[5.9,2.61]],"id":41132607}],"con":true,"img":false}]}
{"op":"mcm","clk":"10119527842","pt":1700902459169,"mc":[{"id":"1.221675352","rc":[{"atb":[[1.01,5.22]],"id":41132607}],"con":true,"img":false}]}
{"op":"mcm","clk":"10119527871","pt":1700902459324,"mc":[{"id":"1.221675352","rc":[{"atb":[[1.01,4.64]],"id":41132607}],"con":true,"img":false}]}
{"op":"mcm","clk":"10119527893","pt":1700902459532,"mc":[{"id":"1.221675352","rc":[{"atb":[[1.01,2.61]],"id":41132607}],"con":true,"img":false}]}
{"op":"mcm","clk":"10119527902","pt":1700902459635,"mc":[{"id":"1.221675352","rc":[{"atb":[[2.54,2.03]],"id":41132607}],"con":true,"img":false}]}
{"op":"mcm","clk":"10119528811","pt":1700902467521,"mc":[{"id":"1.221675352","rc":[{"atl":[[6.6,0]],"id":41132607},{"atb":[[7.6,0]],"id":61861979},{"atb":[[5.2,0]],"id":51229677},{"atb":[[8.8,0]],"id":49487602}],"con":true,"img":false}]}
{"op":"mcm","clk":"10119528823","pt":1700902467628,"mc":[{"id":"1.221675352","rc":[{"atl":[[6,34.13]],"id":41132607},{"atb":[[9.4,16.19]],"id":61861979},{"atb":[[5.9,25.87]],"id":51229677},{"atb":[[10,13.23]],"id":49487602}],"con":true,"img":false}]}
{"op":"mcm","clk":"10119529386","pt":1700902472507,"mc":[{"id":"1.221675352","rc":[{"atb":[[10,0]],"id":52386044}],"con":true,"img":false}]}
{"op":"mcm","clk":"10119529400","pt":1700902472612,"mc":[{"id":"1.221675352","rc":[{"atb":[[12.5,10.5]],"id":52386044}],"con":true,"img":false}]}
{"op":"mcm","clk":"10119529609","pt":1700902474433,"mc":[{"id":"1.221675352","rc":[{"atl":[[5.9,0]],"id":41132607}],"con":true,"img":false}]}
{"op":"mcm","clk":"10119529665","pt":1700902474953,"mc":[{"id":"1.221675352","rc":[{"atb":[[2.54,0]],"id":41132607}],"con":true,"img":false}]}
{"op":"mcm","clk":"10119529816","pt":1700902476154,"mc":[{"id":"1.221675352","rc":[{"atl":[[5.8,2.61]],"id":41132607}],"con":true,"img":false}]}
{"op":"mcm","clk":"10119529846","pt":1700902476413,"mc":[{"id":"1.221675352","rc":[{"atb":[[1.01,5.22]],"id":41132607}],"con":true,"img":false}]}
{"op":"mcm","clk":"10119529863","pt":1700902476517,"mc":[{"id":"1.221675352","rc":[{"atb":[[1.01,4.62]],"id":41132607}],"con":true,"img":false}]}
{"op":"mcm","clk":"10119529876","pt":1700902476620,"mc":[{"id":"1.221675352","rc":[{"atb":[[1.01,2.61]],"id":41132607}],"con":true,"img":false}]}
{"op":"mcm","clk":"10119529894","pt":1700902476725,"mc":[{"id":"1.221675352","rc":[{"atb":[[2.56,2.01]],"id":41132607}],"con":true,"img":false}]}
{"op":"mcm","clk":"10119531432","pt":1700902490456,"mc":[{"id":"1.221675352","rc":[{"atb":[[2,0],[1.95,0],[1.9,0]],"id":41132607},{"atl":[[6.2,0],[8.2,0]],"id":41132607},{"atb":[[4,0],[4.5,11.79],[5,0]],"id":51178794},{"atl":[[38,0],[24,0]],"id":51178794},{"atb":[[9.2,0],[10.5,5.6],[8.2,0]],"id":61861979},{"atl":[[260,0],[160,0]],"id":61861979},{"atb":[[3.2,0],[2.88,0],[2.98,0]],"id":54974498},{"atl":[[16,0],[11,0]],"id":54974498},{"atb":[[14,0],[16.5,0],[19,0]],"id":50758683},{"atl":[[260,0],[360,0]],"id":50758683},{"atb":[[5.8,0],[7.6,0],[6.6,0]],"id":51229677},{"atl":[[65,0],[130,0]],"id":51229677},{"atb":[[12,0],[9.8,0],[14.5,0]],"id":49487602},{"atl":[[320,0],[220,0]],"id":49487602}],"con":true,"img":false}]}
{"op":"mcm","clk":"10119531526","pt":1700902491450,"mc":[{"id":"1.221675352","rc":[{"atl":[[5.8,0]],"id":41132607}],"con":true,"img":false}]}
{"op":"mcm","clk":"10119531600","pt":1700902492025,"mc":[{"id":"1.221675352","rc":[{"atb":[[2.56,0]],"id":41132607}],"con":true,"img":false}]}
{"op":"mcm","clk":"10119531654","pt":1700902492549,"mc":[{"id":"1.221675352","rc":[{"atl":[[6,13.65]],"id":41132607},{"atb":[[9.4,0]],"id":61861979},{"atb":[[5.9,0]],"id":51229677},{"atb":[[10,0]],"id":49487602}],"con":true,"img":false}]}
{"op":"mcm","clk":"10119531666","pt":1700902492654,"mc":[{"id":"1.221675352","rc":[{"atl":[[6.6,20.48]],"id":41132607},{"atb":[[7.6,16.19]],"id":61861979},{"atb":[[5.2,25.87]],"id":51229677},{"atb":[[8.8,13.23]],"id":49487602}],"con":true,"img":false}]}
{"op":"mcm","clk":"10119532213","pt":1700902497215,"mc":[{"id":"1.221675352","rc":[{"atl":[[6.8,0],[7.6,15.15]],"id":41132607},{"atl":[[11.5,0],[13,8.33]],"id":51178794},{"atl":[[70,2.61],[80,2]],"id":49487602}],"con":true,"img":false}]}
{"op":"mcm","clk":"10119532259","pt":1700902497548,"mc":[{"id":"1.221675352","rc":[{"atl":[[7.4,15.99],[6.6,0]],"id":41132607},{"atb":[[17,0]],"id":50758683},{"atb":[[6.8,0]],"id":51229677},{"atb":[[12.5,0]],"id":49487602}],"con":true,"img":false}]}
{"op":"mcm","clk":"10119532268","pt":1700902497651,"mc":[{"id":"1.221675352","rc":[{"atb":[[14,4]],"id":50758683},{"atb":[[6.4,9.03]],"id":51229677},{"atb":[[11,4.87]],"id":49487602}],"con":true,"img":false}]}
{"op":"mcm","clk":"10119533439","pt":1700902507572,"mc":[{"id":"1.221675352","rc":[{"atl":[[5.9,2.61]],"id":41132607}],"con":true,"img":false}]}
{"op":"mcm","clk":"10119533462","pt":1700902507878,"mc":[{"id":"1.221675352","rc":[{"atb":[[1.01,5.22]],"id":41132607}],"con":true,"img":false}]}
{"op":"mcm","clk":"10119533488","pt":1700902508087,"mc":[{"id":"1.221675352","rc":[{"atb":[[1.01,4.67]],"id":41132607}],"con":true,"img":false}]}
{"op":"mcm","clk":"10119533511","pt":1700902508242,"mc":[{"id":"1.221675352","rc":[{"atb":[[1.01,2.61]],"id":41132607}],"con":true,"img":false}]}
{"op":"mcm","clk":"10119533520","pt":1700902508348,"mc":[{"id":"1.221675352","rc":[{"atb":[[2.52,2.06]],"id":41132607}],"con":true,"img":false}]}
{"op":"mcm","clk":"10119534132","pt":1700902513343,"mc":[{"id":"1.221675352","rc":[{"atl":[[7.6,0],[6.8,16.26]],"id":41132607},{"atl":[[11.5,7.36],[13,0]],"id":51178794},{"spn":4.5,"spf":1.0,"id":51178794},{"spn":10.0,"spf":1.0,"id":61861979},{"spn":2.91,"spf":1.0,"id":54974498},{"spn":15.88,"spf":1.0,"id":50758683},{"spn":10.85,"spf":1.0,"id":51229677},{"spn":14.38,"spf":1.0,"id":52386044},{"atl":[[70,4.61],[80,0]],"id":49487602},{"spn":12.56,"spf":1.0,"id":49487602}],"con":true,"img":false}]}
{"op":"mcm","clk":"10119535446","pt":1700902523066,"mc":[{"id":"1.221675352","rc":[{"atl":[[5.9,0]],"id":41132607}],"con":true,"img":false}]}
{"op":"mcm","clk":"10119535523","pt":1700902523687,"mc":[{"id":"1.221675352","rc":[{"atb":[[2.52,0]],"id":41132607}],"con":true,"img":false}]}
{"op":"mcm","clk":"10119535619","pt":1700902524470,"mc":[{"id":"1.221675352","rc":[{"atl":[[5.9,2.61]],"id":41132607}],"con":true,"img":false}]}
{"op":"mcm","clk":"10119535647","pt":1700902524678,"mc":[{"id":"1.221675352","rc":[{"atb":[[1.01,5.22]],"id":41132607}],"con":true,"img":false}]}
{"op":"mcm","clk":"10119535671","pt":1700902524886,"mc":[{"id":"1.221675352","rc":[{"atb":[[1.01,4.64]],"id":41132607}],"con":true,"img":false}]}
{"op":"mcm","clk":"10119535697","pt":1700902525093,"mc":[{"id":"1.221675352","rc":[{"atb":[[1.01,2.61]],"id":41132607}],"con":true,"img":false}]}
{"op":"mcm","clk":"10119535710","pt":1700902525196,"mc":[{"id":"1.221675352","rc":[{"atb":[[2.54,2.03]],"id":41132607}],"con":true,"img":false}]}
{"op":"mcm","clk":"10119535956","pt":1700902526968,"mc":[{"id":"1.221675352","rc":[{"atb":[[2,104.28],[1.95,219.54],[1.9,231.74]],"id":41132607},{"atl":[[6.2,26.76],[8.2,28.99]],"id":41132607},{"atb":[[4,69.52],[4.5,71.38],[5,26.07]],"id":51178794},{"atl":[[38,5.64],[24,6.05]],"id":51178794},{"atb":[[9.2,25.43],[10.5,16.57],[8.2,28.96]],"id":61861979},{"atl":[[260,0.8],[160,0.87]],"id":61861979},{"atb":[[3.2,47.4],[2.88,110.94],[2.98,105.33]],"id":54974498},{"atl":[[16,13.91],[11,13.91]],"id":54974498},{"atb":[[16.5,13.45],[19,5.79],[14,20.04]],"id":50758683},{"atl":[[260,0.53],[360,0.57]],"id":50758683},{"atb":[[5.8,43.45],[7.6,15.79],[6.6,37.24]],"id":51229677},{"atl":[[65,2.17],[130,1.61]],"id":51229677},{"atb":[[12,18.96],[9.8,23.69],[14.5,7.72]],"id":49487602},{"atl":[[320,0.65],[220,0.63]],"id":49487602}],"con":true,"img":false}]}
{"op":"mcm","clk":"10119537471","pt":1700902539671,"mc":[{"id":"1.221675352","rc":[{"atl":[[5.9,0]],"id":41132607}],"con":true,"img":false}]}
{"op":"mcm","clk":"10119537558","pt":1700902540501,"mc":[{"id":"1.221675352","rc":[{"atb":[[2.54,0]],"id":41132607}],"con":true,"img":false}]}
{"op":"mcm","clk":"10119537642","pt":1700902541175,"mc":[{"id":"1.221675352","rc":[{"atl":[[5.8,2.61]],"id":41132607}],"con":true,"img":false}]}
{"op":"mcm","clk":"10119537676","pt":1700902541486,"mc":[{"id":"1.221675352","rc":[{"atb":[[1.01,5.22]],"id":41132607}],"con":true,"img":false}]}
{"op":"mcm","clk":"10119537698","pt":1700902541694,"mc":[{"id":"1.221675352","rc":[{"atb":[[1.01,4.62]],"id":41132607}],"con":true,"img":false}]}
{"op":"mcm","clk":"10119537718","pt":1700902541904,"mc":[{"id":"1.221675352","rc":[{"atb":[[1.01,2.61]],"id":41132607}],"con":true,"img":false}]}
{"op":"mcm","clk":"10119537727","pt":1700902542008,"mc":[{"id":"1.221675352","rc":[{"atb":[[2.56,2.01]],"id":41132607}],"con":true,"img":false}]}
{"op":"mcm","clk":"10119538298","pt":1700902547496,"mc":[{"id":"1.221675352","rc":[{"atb":[[14,16.04]],"id":50758683},{"atb":[[6.4,0]],"id":51229677},{"atb":[[11,0]],"id":49487602}],"con":true,"img":false}]}
{"op":"mcm","clk":"10119538308","pt":1700902547600,"mc":[{"id":"1.221675352","rc":[{"atb":[[17,4]],"id":50758683},{"atb":[[6.8,9.03]],"id":51229677},{"atb":[[12.5,4.87]],"id":49487602}],"con":true,"img":false}]}
{"op":"mcm","clk":"10119539227","pt":1700902556525,"mc":[{"id":"1.221675352","rc":[{"atl":[[5.8,0]],"id":41132607}],"con":true,"img":false}]}
{"op":"mcm","clk":"10119539346","pt":1700902557512,"mc":[{"id":"1.221675352","rc":[{"atb":[[2.56,0]],"id":41132607},{"atl":[[7.4,0],[6,34.13]],"id":41132607}],"con":true,"img":false}]}
{"op":"mcm","clk":"10119539384","pt":1700902557925,"mc":[{"id":"1.221675352","rc":[{"atl":[[5.9,4.41]],"id":41132607}],"con":true,"img":false}]}
{"op":"mcm","clk":"10119540539","pt":1700902567597,"mc":[{"id":"1.221675352","rc":[{"atb":[[7.6,0]],"id":61861979},{"atb":[[5.2,0]],"id":51229677},{"atb":[[8.8,0]],"id":49487602}],"con":true,"img":false}]}
{"op":"mcm","clk":"10119540549","pt":1700902567700,"mc":[{"id":"1.221675352","rc":[{"atb":[[9.4,16.19]],"id":61861979},{"atb":[[5.9,25.87]],"id":51229677},{"atb":[[10,13.23]],"id":49487602}],"con":true,"img":false}]}
{"op":"mcm","clk":"10119541201","pt":1700902573306,"mc":[{"id":"1.221675352","rc":[{"atl":[[5.8,2.61]],"id":41132607}],"con":true,"img":false}]}
{"op":"mcm","clk":"10119541238","pt":1700902573615,"mc":[{"id":"1.221675352","rc":[{"atb":[[1.01,5.22]],"id":41132607},{"spn":2.49,"spf":1.0,"id":41132607},{"spn":5.0,"spf":1.0,"id":51178794},{"spn":10.46,"spf":1.0,"id":61861979},{"spn":3.21,"spf":1.0,"id":54974498},{"spn":19.0,"spf":1.0,"id":50758683},{"spn":11.05,"spf":1.0,"id":51229677},{"spn":14.5,"spf":1.0,"id":49487602}],"con":true,"img":false}]}
{"op":"mcm","clk":"10119541266","pt":1700902573822,"mc":[{"id":"1.221675352","rc":[{"atb":[[1.01,4.67]],"id":41132607}],"con":true,"img":false}]}
{"op":"mcm","clk":"10119541295","pt":1700902574030,"mc":[{"id":"1.221675352","rc":[{"atb":[[1.01,2.61]],"id":41132607}],"con":true,"img":false}]}
{"op":"mcm","clk":"10119541308","pt":1700902574134,"mc":[{"id":"1.221675352","rc":[{"atb":[[2.52,2.06]],"id":41132607}],"con":true,"img":false}]}
{"op":"mcm","clk":"10119541473","pt":1700902575439,"mc":[{"id":"1.221675352","rc":[{"atl":[[11.5,0],[12.5,8.7]],"id":51178794},{"atl":[[70,2.61],[75,2]],"id":49487602}],"con":true,"img":false}]}
{"op":"mcm","clk":"10119541536","pt":1700902576005,"mc":[{"id":"1.221675352","rc":[{"atl":[[5.9,0]],"id":41132607}],"con":true,"img":false}]}
{"op":"mcm","clk":"10119542963","pt":1700902588852,"mc":[{"id":"1.221675352","rc":[{"atl":[[5.8,0]],"id":41132607}],"con":true,"img":false}]}
{"op":"mcm","clk":"10119542992","pt":1700902589008,"mc":[{"id":"1.221675352","rc":[{"atl":[[7.2,16.13],[6.8,0]],"id":41132607}],"con":true,"img":false}]}
{"op":"mcm","clk":"10119543043","pt":1700902589421,"mc":[{"id":"1.221675352","rc":[{"atb":[[2.52,0]],"id":41132607}],"con":true,"img":false}]}
{"op":"mcm","clk":"10119543128","pt":1700902590316,"mc":[{"id":"1.221675352","rc":[{"atl":[[5.7,2.61]],"id":41132607}],"con":true,"img":false}]}
{"op":"mcm","clk":"10119543155","pt":1700902590624,"mc":[{"id":"1.221675352","rc":[{"atb":[[1.01,5.22]],"id":41132607}],"con":true,"img":false}]}
{"op":"mcm","clk":"10119543177","pt":1700902590835,"mc":[{"id":"1.221675352","rc":[{"atb":[[1.01,4.64]],"id":41132607}],"con":true,"img":false}]}
{"op":"mcm","clk":"10119543198","pt":1700902591041,"mc":[{"id":"1.221675352","rc":[{"atb":[[1.01,2.61]],"id":41132607}],"con":true,"img":false}]}
{"op":"mcm","clk":"10119543211","pt":1700902591145,"mc":[{"id":"1.221675352","rc":[{"atb":[[2.54,2.03]],"id":41132607}],"con":true,"img":false}]}
{"op":"mcm","clk":"10119544943","pt":1700902605650,"mc":[{"id":"1.221675352","rc":[{"atl":[[5.7,0]],"id":41132607}],"con":true,"img":false}]}
{"op":"mcm","clk":"10119544993","pt":1700902606063,"mc":[{"id":"1.221675352","rc":[{"atl":[[5.9,4.4]],"id":41132607}],"con":true,"img":false}]}
{"op":"mcm","clk":"10119545025","pt":1700902606324,"mc":[{"id":"1.221675352","rc":[{"atb":[[2.54,0]],"id":41132607}],"con":true,"img":false}]}
{"op":"mcm","clk":"10119545088","pt":1700902607055,"mc":[{"id":"1.221675352","rc":[{"atl":[[5.6,2.61]],"id":41132607}],"con":true,"img":false}]}
{"op":"mcm","clk":"10119545110","pt":1700902607262,"mc":[{"id":"1.221675352","rc":[{"atb":[[1.01,5.22]],"id":41132607}],"con":true,"img":false}]}
{"op":"mcm","clk":"10119545124","pt":1700902607369,"mc":[{"id":"1.221675352","rc":[{"atb":[[1.01,4.62]],"id":41132607}],"con":true,"img":false}]}
{"op":"mcm","clk":"10119545155","pt":1700902607581,"mc":[{"id":"1.221675352","rc":[{"atb":[[1.01,2.61]],"id":41132607}],"con":true,"img":false}]}
{"op":"mcm","clk":"10119545161","pt":1700902607632,"mc":[{"id":"1.221675352","rc":[{"atb":[[2.56,2.01]],"id":41132607}],"con":true,"img":false}]}
{"op":"mcm","clk":"10119545317","pt":1700902609130,"mc":[{"id":"1.221675352","rc":[{"atl":[[5.9,0]],"id":41132607}],"con":true,"img":false}]}
{"op":"mcm","clk":"10119545582","pt":1700902611670,"mc":[{"id":"1.221675352","rc":[{"atl":[[6,34.08]],"id":41132607}],"con":true,"img":false}]}
{"op":"mcm","clk":"10119545597","pt":1700902611773,"mc":[{"id":"1.221675352","rc":[{"atl":[[4.9,0.04]],"id":41132607}],"con":true,"img":false}]}
{"op":"mcm","clk":"10119546941","pt":1700902622565,"mc":[{"id":"1.221675352","rc":[{"atl":[[5.6,0]],"id":41132607}],"con":true,"img":false}]}
{"op":"mcm","clk":"10119546983","pt":1700902622881,"mc":[{"id":"1.221675352","rc":[{"atb":[[2.56,0]],"id":41132607}],"con":true,"img":false}]}
{"op":"mcm","clk":"10119547111","pt":1700902624084,"mc":[{"id":"1.221675352","rc":[{"atl":[[5.9,4.43]],"id":41132607}],"con":true,"img":false}]}
{"op":"mcm","clk":"10119547136","pt":1700902624292,"mc":[{"id":"1.221675352","rc":[{"atl":[[5.5,2.61]],"id":41132607}],"con":true,"img":false}]}
{"op":"mcm","clk":"10119547161","pt":1700902624452,"mc":[{"id":"1.221675352","rc":[{"atb":[[1.01,5.22]],"id":41132607}],"con":true,"img":false}]}
{"op":"mcm","clk":"10119547190","pt":1700902624662,"mc":[{"id":"1.221675352","rc":[{"atb":[[1.01,4.59]],"id":41132607}],"con":true,"img":false}]}
{"op":"mcm","clk":"10119547213","pt":1700902624870,"mc":[{"id":"1.221675352","rc":[{"atb":[[1.01,2.61]],"id":41132607}],"con":true,"img":false}]}
{"op":"mcm","clk":"10119547220","pt":1700902624972,"mc":[{"id":"1.221675352","rc":[{"atb":[[2.58,1.98]],"id":41132607}],"con":true,"img":false}]}
{"op":"mcm","clk":"10119547546","pt":1700902627476,"mc":[{"id":"1.221675352","rc":[{"atl":[[5.9,0]],"id":41132607}],"con":true,"img":false}]}
{"op":"mcm","clk":"10119548340","pt":1700902634303,"mc":[{"id":"1.221675352","rc":[{"spn":2.56,"spf":1.0,"id":41132607},{"atl":[[12,12.39],[12.5,0]],"id":51178794},{"atl":[[70,4.61],[75,0]],"id":49487602}],"con":true,"img":false}]}
{"op":"mcm","clk":"10119548347","pt":1700902634403,"mc":[{"id":"1.221675352","rc":[{"atl":[[16.5,6.45],[12,5.03]],"id":51178794}],"con":true,"img":false}]}
{"op":"mcm","clk":"10119548936","pt":1700902639682,"mc":[{"id":"1.221675352","rc":[{"atl":[[5.5,0]],"id":41132607}],"con":true,"img":false}]}
{"op":"mcm","clk":"10119549022","pt":1700902640619,"mc":[{"id":"1.221675352","rc":[{"atb":[[2.58,0]],"id":41132607}],"con":true,"img":false}]}
{"op":"mcm","clk":"10119550073","pt":1700902649205,"mc":[{"id":"1.221675352","rc":[{"atl":[[16.5,0],[12,11.48]],"id":51178794}],"con":true,"img":false}]}
{"op":"mcm","clk":"10119550088","pt":1700902649308,"mc":[{"id":"1.221675352","rc":[{"atl":[[65,2],[70,2.61]],"id":49487602}],"con":true,"img":false}]}
{"op":"mcm","clk":"10119550421","pt":1700902651911,"mc":[{"id":"1.221675352","rc":[{"atl":[[5.9,2.61]],"id":41132607}],"con":true,"img":false}]}
{"op":"mcm","clk":"10119550457","pt":1700902652174,"mc":[{"id":"1.221675352","rc":[{"atb":[[1.01,5.22]],"id":41132607}],"con":true,"img":false}]}
{"op":"mcm","clk":"10119550478","pt":1700902652277,"mc":[{"id":"1.221675352","rc":[{"atb":[[1.01,4.67]],"id":41132607}],"con":true,"img":false}]}
{"op":"mcm","clk":"10119550519","pt":1700902652592,"mc":[{"id":"1.221675352","rc":[{"atb":[[1.01,2.61]],"id":41132607}],"con":true,"img":false}]}
{"op":"mcm","clk":"10119550530","pt":1700902652693,"mc":[{"id":"1.221675352","rc":[{"atb":[[2.52,2.06]],"id":41132607}],"con":true,"img":false}]}
{"op":"mcm","clk":"10119550551","pt":1700902652905,"mc":[{"id":"1.221675352","rc":[{"atl":[[5.9,7.1]],"id":41132607}],"con":true,"img":false}]}
{"op":"mcm","clk":"10119552237","pt":1700902667109,"mc":[{"id":"1.221675352","rc":[{"atl":[[5.9,4.49]],"id":41132607}],"con":true,"img":false}]}
{"op":"mcm","clk":"10119552344","pt":1700902668101,"mc":[{"id":"1.221675352","rc":[{"atb":[[2.52,0]],"id":41132607}],"con":true,"img":false}]}
{"op":"mcm","clk":"10119552443","pt":1700902668915,"mc":[{"id":"1.221675352","rc":[{"atl":[[5.8,2.61]],"id":41132607}],"con":true,"img":false}]}
{"op":"mcm","clk":"10119552487","pt":1700902669228,"mc":[{"id":"1.221675352","rc":[{"atb":[[1.01,5.22]],"id":41132607}],"con":true,"img":false}]}
{"op":"mcm","clk":"10119552498","pt":1700902669330,"mc":[{"id":"1.221675352","rc":[{"atb":[[1.01,4.64]],"id":41132607}],"con":true,"img":false}]}
{"op":"mcm","clk":"10119552537","pt":1700902669639,"mc":[{"id":"1.221675352","rc":[{"atb":[[1.01,2.61]],"id":41132607}],"con":true,"img":false}]}
{"op":"mcm","clk":"10119552552","pt":1700902669694,"mc":[{"id":"1.221675352","rc":[{"atb":[[2.54,2.03]],"id":41132607}],"con":true,"img":false}]}
{"op":"mcm","clk":"10119552871","pt":1700902672143,"mc":[{"id":"1.221675352","rc":[{"atl":[[5.9,0]],"id":41132607}],"con":true,"img":false}]}
{"op":"mcm","clk":"10119554539","pt":1700902684523,"mc":[{"id":"1.221675352","rc":[{"atl":[[5.8,0]],"id":41132607}],"con":true,"img":false}]}
{"op":"mcm","clk":"10119554601","pt":1700902685037,"mc":[{"id":"1.221675352","rc":[{"atb":[[2.54,0]],"id":41132607}],"con":true,"img":false}]}
{"op":"mcm","clk":"10119554698","pt":1700902685717,"mc":[{"id":"1.221675352","rc":[{"atl":[[5.7,2.61]],"id":41132607}],"con":true,"img":false}]}
{"op":"mcm","clk":"10119554748","pt":1700902686130,"mc":[{"id":"1.221675352","rc":[{"atb":[[1.01,5.22]],"id":41132607}],"con":true,"img":false}]}
{"op":"mcm","clk":"10119554779","pt":1700902686351,"mc":[{"id":"1.221675352","rc":[{"atb":[[1.01,4.62]],"id":41132607}],"con":true,"img":false}]}
{"op":"mcm","clk":"10119554800","pt":1700902686548,"mc":[{"id":"1.221675352","rc":[{"atb":[[1.01,2.61]],"id":41132607}],"con":true,"img":false}]}
{"op":"mcm","clk":"10119554811","pt":1700902686650,"mc":[{"id":"1.221675352","rc":[{"atb":[[2.56,2.01]],"id":41132607}],"con":true,"img":false}]}
{"op":"mcm","clk":"10119554947","pt":1700902687540,"mc":[{"id":"1.221675352","rc":[{"atl":[[70,0]],"id":49487602}],"con":true,"img":false}]}
{"op":"mcm","clk":"10119554962","pt":1700902687641,"mc":[{"id":"1.221675352","rc":[{"atl":[[60,2.61]],"id":49487602}],"con":true,"img":false}]}
{"op":"mcm","clk":"10119556617","pt":1700902701167,"mc":[{"id":"1.221675352","rc":[{"atl":[[5.7,0]],"id":41132607},{"spn":2.54,"spf":1.0,"id":41132607}],"con":true,"img":false}]}
{"op":"mcm","clk":"10119556726","pt":1700902701949,"mc":[{"id":"1.221675352","rc":[{"atb":[[2.56,0]],"id":41132607}],"con":true,"img":false}]}
{"op":"mcm","clk":"10119556744","pt":1700902702157,"mc":[{"id":"1.221675352","rc":[{"atl":[[5.9,4.38]],"id":41132607}],"con":true,"img":false}]}
{"op":"mcm","clk":"10119558305","pt":1700902714560,"mc":[{"id":"1.221675352","rc":[{"atl":[[5.8,2.61]],"id":41132607}],"con":true,"img":false}]}
{"op":"mcm","clk":"10119558339","pt":1700902714872,"mc":[{"id":"1.221675352","rc":[{"atb":[[1.01,5.22]],"id":41132607}],"con":true,"img":false}]}
{"op":"mcm","clk":"10119558369","pt":1700902715086,"mc":[{"id":"1.221675352","rc":[{"atb":[[1.01,4.67]],"id":41132607}],"con":true,"img":false}]}
{"op":"mcm","clk":"10119558398","pt":1700902715245,"mc":[{"id":"1.221675352","rc":[{"atb":[[1.01,2.61]],"id":41132607}],"con":true,"img":false}]}
{"op":"mcm","clk":"10119558415","pt":1700902715347,"mc":[{"id":"1.221675352","rc":[{"atb":[[2.52,2.06]],"id":41132607}],"con":true,"img":false}]}
{"op":"mcm","clk":"10119558653","pt":1700902717288,"mc":[{"id":"1.221675352","rc":[{"atl":[[5.9,0]],"id":41132607}],"con":true,"img":false}]}
{"op":"mcm","clk":"10119558918","pt":1700902719579,"mc":[{"id":"1.221675352","rc":[{"atl":[[6,34.06]],"id":41132607}],"con":true,"img":false}]}
{"op":"mcm","clk":"10119558927","pt":1700902719679,"mc":[{"id":"1.221675352","rc":[{"atl":[[4.6,0.02]],"id":41132607}],"con":true,"img":false}]}
{"op":"mcm","clk":"10119559703","pt":1700902726314,"mc":[{"id":"1.221675352","rc":[{"atb":[[2.5,0],[2.52,0]],"id":41132607},{"atl":[[2.5,99.9]],"id":41132607},{"trd":[[2.5,5.05],[2.52,4.12]],"ltp":2.5,"tv":9.17,"id":41132607}],"con":true,"img":false}]}
{"op":"mcm","clk":"10119559730","pt":1700902726574,"mc":[{"id":"1.221675352","rc":[{"atb":[[5.1,1.02]],"id":51178794},{"atb":[[11,0.98]],"id":61861979},{"atb":[[3.25,0.95]],"id":54974498},{"atb":[[7.8,0.97]],"id":51229677},{"atb":[[15.5,0.98]],"id":52386044}],"con":true,"img":false}]}
{"op":"mcm","clk":"10119559744","pt":1700902726679,"mc":[{"id":"1.221675352","rc":[{"atl":[[2.5,0]],"id":41132607}],"con":true,"img":false}]}
{"op":"mcm","clk":"10119559773","pt":1700902726989,"mc":[{"id":"1.221675352","rc":[{"atl":[[5.7,0.95]],"id":41132607},{"atl":[[16.5,0.96]],"id":61861979},{"atl":[[6.6,0.93]],"id":54974498},{"atl":[[50,0.99]],"id":49487602}],"con":true,"img":false}]}
{"op":"mcm","clk":"10119559824","pt":1700902727507,"mc":[{"id":"1.221675352","rc":[{"atb":[[11,3.15]],"id":61861979},{"atb":[[19.5,2.17]],"id":50758683},{"atb":[[7.8,3.57]],"id":51229677},{"atb":[[15.5,3.15]],"id":52386044},{"atb":[[15,2.17]],"id":49487602}],"con":true,"img":false}]}
{"op":"mcm","clk":"10119559833","pt":1700902727612,"mc":[{"id":"1.221675352","rc":[{"atl":[[1000,0.86]],"id":41132607}],"con":true,"img":false}]}
{"op":"mcm","clk":"10119559845","pt":1700902727718,"mc":[{"id":"1.221675352","rc":[{"atb":[[2.32,23.89]],"id":41132607}],"con":true,"img":false}]}
{"op":"mcm","clk":"10119559858","pt":1700902727826,"mc":[{"id":"1.221675352","rc":[{"atb":[[2.08,0]],"id":41132607},{"atl":[[1000,0.85]],"id":41132607}],"con":true,"img":false}]}
{"op":"mcm","clk":"10119559880","pt":1700902727981,"mc":[{"id":"1.221675352","rc":[{"atl":[[1000,0]],"id":41132607}],"con":true,"img":false}]}
{"op":"mcm","clk":"10119559888","pt":1700902728084,"mc":[{"id":"1.221675352","rc":[{"atl":[[5.8,3.46],[1000,0.86]],"id":41132607}],"con":true,"img":false}]}
{"op":"mcm","clk":"10119559909","pt":1700902728291,"mc":[{"id":"1.221675352","rc":[{"atb":[[2.44,0.97]],"id":41132607},{"atl":[[1000,0.85]],"id":41132607}],"con":true,"img":false}]}
{"op":"mcm","clk":"10119559934","pt":1700902728494,"mc":[{"id":"1.221675352","rc":[{"atl":[[1000,0]],"id":41132607}],"con":true,"img":false}]}
{"op":"mcm","clk":"10119559950","pt":1700902728596,"mc":[{"id":"1.221675352","rc":[{"atl":[[5.8,4.31]],"id":41132607}],"con":true,"img":false}]}
{"op":"mcm","clk":"10119560153","pt":1700902730314,"mc":[{"id":"1.221675352","rc":[{"atl":[[5.8,1.7]],"id":41132607}],"con":true,"img":false}]}
{"op":"mcm","clk":"10119561349","pt":1700902740340,"mc":[{"id":"1.221675352","rc":[{"atb":[[2.32,0],[2.1,90.91]],"id":41132607}],"con":true,"img":false}]}
{"op":"mcm","clk":"10119561446","pt":1700902741017,"mc":[{"id":"1.221675352","rc":[{"atb":[[2.44,0]],"id":41132607}],"con":true,"img":false}]}
{"op":"mcm","clk":"10119562093","pt":1700902746223,"mc":[{"id":"1.221675352","rc":[{"atl":[[1000,2.06]],"id":41132607}],"con":true,"img":false}]}
{"op":"mcm","clk":"10119562111","pt":1700902746328,"mc":[{"id":"1.221675352","rc":[{"atl":[[1000,0]],"id":41132607}],"con":true,"img":false}]}
{"op":"mcm","clk":"10119562119","pt":1700902746432,"mc":[{"id":"1.221675352","rc":[{"atl":[[5.6,2.06]],"id":41132607}],"con":true,"img":false}]}
{"op":"mcm","clk":"10119562167","pt":1700902746794,"mc":[{"id":"1.221675352","rc":[{"atl":[[5.7,0]],"id":41132607}],"con":true,"img":false}]}
{"op":"mcm","clk":"10119562177","pt":1700902746898,"mc":[{"id":"1.221675352","rc":[{"atl":[[5.5,0.95]],"id":41132607}],"con":true,"img":false}]}
{"op":"mcm","clk":"10119562243","pt":1700902747518,"mc":[{"id":"1.221675352","rc":[{"atl":[[7,0]],"id":54974498}],"con":true,"img":false}]}
{"op":"mcm","clk":"10119562255","pt":1700902747624,"mc":[{"id":"1.221675352","rc":[{"atl":[[9.2,12.2],[6.8,0],[6.6,8.3]],"id":54974498}],"con":true,"img":false}]}
{"op":"mcm","clk":"10119562305","pt":1700902747991,"mc":[{"id":"1.221675352","rc":[{"atl":[[6.6,7.37]],"id":54974498}],"con":true,"img":false}]}
{"op":"mcm","clk":"10119562810","pt":1700902752504,"mc":[{"id":"1.221675352","rc":[{"atl":[[6.6,0]],"id":54974498}],"con":true,"img":false}]}
{"op":"mcm","clk":"10119562820","pt":1700902752608,"mc":[{"id":"1.221675352","rc":[{"atl":[[7,7.37]],"id":54974498}],"con":true,"img":false}]}
{"op":"mcm","clk":"10119563145","pt":1700902755626,"mc":[{"id":"1.221675352","rc":[{"atl":[[3.65,26.12]],"id":41132607}],"con":true,"img":false}]}
{"op":"mcm","clk":"10119563230","pt":1700902756408,"mc":[{"id":"1.221675352","rc":[{"atl":[[3.6,5.06]],"id":41132607}],"con":true,"img":false}]}
{"op":"mcm","clk":"10119563244","pt":1700902756560,"mc":[{"id":"1.221675352","rc":[{"atl":[[5.8,0],[3.55,1.39]],"id":41132607}],"con":true,"img":false}]}
{"op":"mcm","clk":"10119563279","pt":1700902757026,"mc":[{"id":"1.221675352","rc":[{"atl":[[5.5,0]],"id":41132607}],"con":true,"img":false}]}
{"op":"mcm","clk":"10119563289","pt":1700902757134,"mc":[{"id":"1.221675352","rc":[{"atl":[[3.55,2.35]],"id":41132607}],"con":true,"img":false}]}
{"op":"mcm","clk":"10119563384","pt":1700902758064,"mc":[{"id":"1.221675352","rc":[{"atb":[[2.64,0],[2.76,56.82]],"id":51178794},{"atb":[[5.5,0],[6,20]],"id":61861979},{"atb":[[3.5,40],[3.2,0]],"id":51229677}],"con":true,"img":false}]}
{"op":"mcm","clk":"10119563520","pt":1700902759318,"mc":[{"id":"1.221675352","rc":[{"atl":[[3.6,0]],"id":41132607}],"con":true,"img":false}]}
{"op":"mcm","clk":"10119563735","pt":1700902761246,"mc":[{"id":"1.221675352","rc":[{"spn":2.42,"spf":1.0,"id":41132607},{"spn":5.03,"spf":1.0,"id":51178794},{"spn":10.58,"spf":1.0,"id":61861979},{"atl":[[9.2,0],[6.8,12.2]],"id":54974498},{"spn":3.21,"spf":1.0,"id":54974498},{"spn":19.19,"spf":1.0,"id":50758683},{"spn":11.15,"spf":1.0,"id":51229677},{"spn":14.6,"spf":1.0,"id":52386044},{"spn":14.7,"spf":1.0,"id":49487602}],"con":true,"img":false}]}
{"op":"mcm","clk":"10119563785","pt":1700902761710,"mc":[{"id":"1.221675352","rc":[{"atl":[[5.6,0]],"id":41132607},{"atl":[[6.6,0.93]],"id":54974498}],"con":true,"img":false}]}
{"op":"mcm","clk":"10119563871","pt":1700902762747,"mc":[{"id":"1.221675352","rc":[{"atl":[[1000,2.06]],"id":41132607}],"con":true,"img":false}]}
{"op":"mcm","clk":"10119563899","pt":1700902762903,"mc":[{"id":"1.221675352","rc":[{"atl":[[1000,0]],"id":41132607}],"con":true,"img":false}]}
{"op":"mcm","clk":"10119563909","pt":1700902763015,"mc":[{"id":"1.221675352","rc":[{"atl":[[3.5,2.06]],"id":41132607}],"con":true,"img":false}]}
{"op":"mcm","clk":"10119563969","pt":1700902763529,"mc":[{"id":"1.221675352","rc":[{"atl":[[3.55,1.39]],"id":41132607}],"con":true,"img":false}]}
{"op":"mcm","clk":"10119563982","pt":1700902763640,"mc":[{"id":"1.221675352","rc":[{"atl":[[3.45,0.95]],"id":41132607}],"con":true,"img":false}]}
{"op":"mcm","clk":"10119564044","pt":1700902764150,"mc":[{"id":"1.221675352","rc":[{"atl":[[3.4,8.68]],"id":41132607}],"con":true,"img":false}]}
{"op":"mcm","clk":"10119564099","pt":1700902764730,"mc":[{"id":"1.221675352","rc":[{"atl":[[3.55,0],[3.45,0],[3.4,10.14]],"id":41132607}],"con":true,"img":false}]}
{"op":"mcm","clk":"10119564104","pt":1700902764828,"mc":[{"id":"1.221675352","rc":[{"atl":[[3.35,0.95]],"id":41132607}],"con":true,"img":false}]}
{"op":"mcm","clk":"10119564754","pt":1700902770146,"mc":[{"id":"1.221675352","rc":[{"atl":[[3.65,0]],"id":41132607}],"con":true,"img":false}]}
{"op":"mcm","clk":"10119564767","pt":1700902770248,"mc":[{"id":"1.221675352","rc":[{"atl":[[3.15,26.12]],"id":41132607}],"con":true,"img":false}]}
{"op":"mcm","clk":"10119564855","pt":1700902770834,"mc":[{"id":"1.221675352","rc":[{"atl":[[3.35,0]],"id":41132607}],"con":true,"img":false}]}
{"op":"mcm","clk":"10119564955","pt":1700902771565,"mc":[{"id":"1.221675352","rc":[{"atl":[[3.15,11.54]],"id":41132607},{"trd":[[3.15,29.16]],"ltp":3.15,"tv":29.16,"id":41132607}],"con":true,"img":false}]}
{"op":"mcm","clk":"10119565028","pt":1700902772036,"mc":[{"id":"1.221675352","rc":[{"atl":[[3.1,5.01]],"id":41132607}],"con":true,"img":false}]}
{"op":"mcm","clk":"10119565052","pt":1700902772242,"mc":[{"id":"1.221675352","rc":[{"atb":[[5.1,2.12]],"id":51178794},{"atb":[[3.25,2.07]],"id":54974498},{"atb":[[7.8,4.7]],"id":51229677},{"atb":[[15,5.47]],"id":52386044}],"con":true,"img":false}]}
{"op":"mcm","clk":"10119565142","pt":1700902772874,"mc":[{"id":"1.221675352","rc":[{"atb":[[2.06,0]],"id":41132607}],"con":true,"img":false}]}
{"op":"mcm","clk":"10119565223","pt":1700902773549,"mc":[{"id":"1.221675352","rc":[{"atl":[[3.05,1.62],[3.4,8.68]],"id":41132607}],"con":true,"img":false}]}
{"op":"mcm","clk":"10119565232","pt":1700902773651,"mc":[{"id":"1.221675352","rc":[{"atb":[[2.38,23.89],[2.1,0]],"id":41132607}],"con":true,"img":false}]}
{"op":"mcm","clk":"10119565473","pt":1700902775662,"mc":[{"id":"1.221675352","rc":[{"atl":[[3.1,0]],"id":41132607}],"con":true,"img":false}]}
{"op":"mcm","clk":"10119565635","pt":1700902777180,"mc":[{"id":"1.221675352","rc":[{"atl":[[6,20.72]],"id":41132607}],"con":true,"img":false}]}
{"op":"mcm","clk":"10119565645","pt":1700902777275,"mc":[{"id":"1.221675352","rc":[{"atl":[[5.8,13.34]],"id":41132607}],"con":true,"img":false}]}
{"op":"mcm","clk":"10119565767","pt":1700902778425,"mc":[{"id":"1.221675352","rc":[{"atl":[[3.5,0]],"id":41132607}],"con":true,"img":false}]}
{"op":"mcm","clk":"10119566313","pt":1700902782755,"mc":[{"id":"1.221675352","rc":[{"atb":[[2.38,0],[2.1,90.91]],"id":41132607}],"con":true,"img":false}]}
{"op":"mcm","clk":"10119566354","pt":1700902783072,"mc":[{"id":"1.221675352","rc":[{"atl":[[7,0]],"id":54974498}],"con":true,"img":false}]}
{"op":"mcm","clk":"10119566369","pt":1700902783177,"mc":[{"id":"1.221675352","rc":[{"atl":[[6.6,8.3]],"id":54974498}],"con":true,"img":false}]}
{"op":"mcm","clk":"10119566381","pt":1700902783281,"mc":[{"id":"1.221675352","rc":[{"atl":[[9.2,12.2],[6.8,0]],"id":54974498}],"con":true,"img":false}]}
{"op":"mcm","clk":"10119566416","pt":1700902783505,"mc":[{"id":"1.221675352","rc":[{"atl":[[6.6,7.37]],"id":54974498}],"con":true,"img":false}]}
{"op":"mcm","clk":"10119566611","pt":1700902785152,"mc":[{"id":"1.221675352","rc":[{"atl":[[6.6,0]],"id":54974498}],"con":true,"img":false}]}
{"op":"mcm","clk":"10119566619","pt":1700902785259,"mc":[{"id":"1.221675352","rc":[{"atl":[[7,7.37]],"id":54974498}],"con":true,"img":false}]}
{"op":"mcm","clk":"10119567265","pt":1700902791348,"mc":[{"id":"1.221675352","rc":[{"atb":[[1.89,50.32],[1.8,0]],"id":52386044}],"con":true,"img":false}]}
{"op":"mcm","clk":"10119567461","pt":1700902793174,"mc":[{"id":"1.221675352","rc":[{"atb":[[2.46,13.06]],"id":41132607}],"con":true,"img":false}]}
{"op":"mcm","clk":"10119567557","pt":1700902793959,"mc":[{"id":"1.221675352","rc":[{"atl":[[1000,2.06]],"id":41132607}],"con":true,"img":false}]}
{"op":"mcm","clk":"10119567582","pt":1700902794164,"mc":[{"id":"1.221675352","rc":[{"atl":[[1000,0]],"id":41132607}],"con":true,"img":false}]}
{"op":"mcm","clk":"10119567601","pt":1700902794309,"mc":[{"id":"1.221675352","rc":[{"atl":[[3,2.06]],"id":41132607}],"con":true,"img":false}]}
{"op":"mcm","clk":"10119567859","pt":1700902796562,"mc":[{"id":"1.221675352","rc":[{"atl":[[9.2,0],[6.8,12.2]],"id":54974498}],"con":true,"img":false}]}
{"op":"mcm","clk":"10119567911","pt":1700902797087,"mc":[{"id":"1.221675352","rc":[{"atl":[[5.8,0]],"id":41132607}],"con":true,"img":false}]}
{"op":"mcm","clk":"10119567921","pt":1700902797190,"mc":[{"id":"1.221675352","rc":[{"atl":[[5.7,13.34]],"id":41132607}],"con":true,"img":false}]}
{"op":"mcm","clk":"10119568253","pt":1700902800185,"mc":[{"id":"1.221675352","rc":[{"atl":[[1000,1.01]],"id":51178794},{"atl":[[1000,1.01]],"id":50758683},{"atl":[[1000,1.01]],"id":52386044},{"atl":[[1000,1.01]],"id":49487602}],"con":true,"img":false}]}
{"op":"mcm","clk":"10119568295","pt":1700902800462,"mc":[{"id":"1.221675352","rc":[{"atl":[[1000,0.01]],"id":51178794},{"atb":[[19.5,4.17]],"id":50758683},{"atl":[[80,4.61],[1000,0.01]],"id":50758683},{"atb":[[17,2]],"id":52386044},{"atl":[[70,4.61],[1000,0.01]],"id":52386044},{"atb":[[15,4.17]],"id":49487602},{"atl":[[55,4.61],[1000,0.01]],"id":49487602}],"con":true,"img":false}]}
{"op":"mcm","clk":"10119568321","pt":1700902800580,"mc":[{"id":"1.221675352","rc":[{"atl":[[1000,0]],"id":51178794},{"atb":[[11.5,2]],"id":61861979},{"atl":[[23,4.61]],"id":51229677},{"atl":[[1000,0]],"id":52386044},{"atl":[[1000,0]],"id":49487602}],"con":true,"img":false}]}
{"op":"mcm","clk":"10119568344","pt":1700902800688,"mc":[{"id":"1.221675352","rc":[{"atb":[[5.1,2.12]],"id":51178794},{"trd":[[5.1,0.01]],"ltp":5.1,"tv":0.01,"id":51178794},{"atl":[[1000,0]],"id":50758683},{"atb":[[8,1.08],[7.2,0]],"id":51229677},{"atb":[[17,1.99]],"id":52386044},{"trd":[[17,0.02]],"ltp":17.0,"tv":0.02,"id":52386044},{"atb":[[15,4.16]],"id":49487602},{"atl":[[1000,0.86]],"id":49487602},{"trd":[[15,0.01]],"ltp":15.0,"tv":0.01,"id":49487602}],"con":true,"img":false}]}
{"op":"mcm","clk":"10119568368","pt":1700902800790,"mc":[{"id":"1.221675352","rc":[{"atb":[[19.5,4.16]],"id":50758683},{"trd":[[19.5,0.01]],"ltp":19.5,"tv":0.01,"id":50758683}],"con":true,"img":false}]}
{"op":"mcm","clk":"10119568425","pt":1700902801013,"mc":[{"id":"1.221675352","rc":[{"atl":[[1000,0.18]],"id":49487602}],"con":true,"img":false}]}
{"op":"mcm","clk":"10119568478","pt":1700902801177,"mc":[{"id":"1.221675352","rc":[{"atl":[[1000,0]],"id":49487602}],"con":true,"img":false}]}
{"op":"mcm","clk":"10119568503","pt":1700902801286,"mc":[{"id":"1.221675352","rc":[{"atl":[[48,0.18]],"id":49487602}],"con":true,"img":false}]}
{"op":"mcm","clk":"10119568788","pt":1700902802107,"mc":[{"id":"1.221675352","rc":[{"atb":[[11,0.98]],"id":61861979},{"atb":[[15.5,0.98]],"id":52386044}],"con":true,"img":false}]}
{"op":"mcm","clk":"10119568885","pt":1700902802689,"mc":[{"id":"1.221675352","rc":[{"atl":[[6.6,0.86]],"id":54974498},{"atl":[[48,1.05]],"id":49487602}],"con":true,"img":false}]}
{"op":"mcm","clk":"10119568895","pt":1700902802793,"mc":[{"id":"1.221675352","rc":[{"atl":[[11.5,0.86]],"id":51178794},{"atl":[[75,0.98]],"id":50758683},{"atl":[[22,1.25]],"id":51229677},{"atl":[[65,0.99]],"id":52386044}],"con":true,"img":false}]}
{"op":"mcm","clk":"10119569017","pt":1700902803328,"mc":[{"id":"1.221675352","rc":[{"atl":[[1000,1.01]],"id":54974498},{"atl":[[1000,1.01]],"id":51229677}],"con":true,"img":false}]}
{"op":"mcm","clk":"10119569060","pt":1700902803590,"mc":[{"id":"1.221675352","rc":[{"atl":[[1000,0.01]],"id":54974498},{"atl":[[1000,0.01]],"id":51229677}],"con":true,"img":false}]}
{"op":"mcm","clk":"10119569089","pt":1700902803700,"mc":[{"id":"1.221675352","rc":[{"atl":[[1000,0]],"id":54974498},{"atl":[[1000,0]],"id":51229677}],"con":true,"img":false}]}
{"op":"mcm","clk":"10119569122","pt":1700902803807,"mc":[{"id":"1.221675352","rc":[{"atb":[[3.4,1.97]],"id":54974498},{"trd":[[3.4,0.01]],"ltp":3.4,"tv":0.01,"id":54974498},{"atb":[[8,1.07]],"id":51229677},{"trd":[[8,0.01]],"ltp":8.0,"tv":0.01,"id":51229677}],"con":true,"img":false}]}
{"op":"mcm","clk":"10119569282","pt":1700902804908,"mc":[{"id":"1.221675352","rc":[{"atb":[[2.14,6.95]],"id":41132607}],"con":true,"img":false}]}
{"op":"mcm","clk":"10119569315","pt":1700902805067,"mc":[{"id":"1.221675352","rc":[{"atb":[[2.44,2.75]],"id":41132607}],"con":true,"img":false}]}
{"op":"mcm","clk":"10119569397","pt":1700902805593,"mc":[{"id":"1.221675352","rc":[{"atl":[[48,3.05],[55,2.61]],"id":49487602}],"con":true,"img":false}]}
{"op":"mcm","clk":"10119569414","pt":1700902805700,"mc":[{"id":"1.221675352","rc":[{"atl":[[48,1.05]],"id":49487602}],"con":true,"img":false}]}
{"op":"mcm","clk":"10119569421","pt":1700902805804,"mc":[{"id":"1.221675352","rc":[{"atb":[[11,2.98],[11.5,0]],"id":61861979},{"atl":[[48,3.05]],"id":49487602}],"con":true,"img":false}]}
{"op":"mcm","clk":"10119569481","pt":1700902806171,"mc":[{"id":"1.221675352","rc":[{"atl":[[1000,1.01]],"id":61861979}],"con":true,"img":false}]}
{"op":"mcm","clk":"10119569509","pt":1700902806384,"mc":[{"id":"1.221675352","rc":[{"atl":[[1000,0.01]],"id":61861979}],"con":true,"img":false}]}
{"op":"mcm","clk":"10119569545","pt":1700902806594,"mc":[{"id":"1.221675352","rc":[{"atl":[[1000,0]],"id":61861979},{"atl":[[50,0]],"id":49487602}],"con":true,"img":false}]}
{"op":"mcm","clk":"10119569560","pt":1700902806701,"mc":[{"id":"1.221675352","rc":[{"atb":[[11,2.97]],"id":61861979},{"trd":[[11,0.01]],"ltp":11.0,"tv":0.01,"id":61861979},{"atl":[[46,0.99]],"id":49487602}],"con":true,"img":false}]}
{"op":"mcm","clk":"10119569619","pt":1700902807133,"mc":[{"id":"1.221675352","rc":[{"atl":[[5.7,0]],"id":41132607}],"con":true,"img":false}]}
{"op":"mcm","clk":"10119569637","pt":1700902807182,"mc":[{"id":"1.221675352","rc":[{"atl":[[5.9,13.34]],"id":41132607}],"con":true,"img":false}]}
