{"op":"mcm","clk":"11448351870","pt":1717289088271,"mc":[{"id":"1.229554924","marketDefinition":{"bspMarket":false,"turnInPlayEnabled":false,"persistenceEnabled":false,"marketBaseRate":7.0,"eventId":"33318908","eventTypeId":"4339","numberOfWinners":1,"bettingType":"ODDS","marketType":"MATCH_BET","marketTime":"2024-06-02T10:24:00.000Z","suspendTime":"2024-06-02T10:24:00.000Z","bspReconciled":false,"complete":true,"inPlay":false,"crossMatching":true,"runnersVoidable":false,"numberOfActiveRunners":2,"betDelay":0,"status":"OPEN","runners":[{"status":"ACTIVE","sortPriority":1,"id":65460404,"name":"1. Give Me Room"},{"status":"ACTIVE","sortPriority":2,"id":52671121,"name":"2. Elegant Ritzy"}],"regulators":["MR_INT"],"venue":"Murray Bridge","countryCode":"AU","discountAllowed":true,"timezone":"Australia/Adelaide","openDate":"2024-06-02T08:21:00.000Z","version":5962433789,"name":"Give Me Room v Elegant Ritzy","eventName":"Murray Bridge (AUS) 2nd Jun"},"rc":[],"con":true,"img":false}]}
{"op":"mcm","clk":"11448366403","pt":1717289278043,"mc":[{"id":"1.229554924","rc":[{"atb":[[1.56,14.01],[1.66,11.89]],"id":52671121},{"atb":[[2.06,7.4],[1.93,8.43]],"id":65460404}],"con":true,"img":false}]}
{"op":"mcm","clk":"11448367939","pt":1717289300806,"mc":[{"id":"1.229554924","rc":[{"atb":[[1.56,0],[1.66,0]],"id":52671121},{"atb":[[2.06,0],[1.93,0]],"id":65460404}],"con":true,"img":false}]}
{"op":"mcm","clk":"11448368462","pt":1717289309031,"mc":[{"id":"1.229554924","rc":[{"atb":[[1.56,14.01],[1.66,11.89]],"id":52671121},{"atb":[[2.06,7.4],[1.93,8.43]],"id":65460404}],"con":true,"img":false}]}
{"op":"mcm","clk":"11448370211","pt":1717289334655,"mc":[{"id":"1.229554924","rc":[{"atb":[[1.56,0],[1.66,0]],"id":52671121},{"atb":[[2.06,0],[1.93,0]],"id":65460404}],"con":true,"img":false}]}
{"op":"mcm","clk":"11448371801","pt":1717289358064,"mc":[{"id":"1.229554924","rc":[{"atb":[[1.56,14.01],[1.66,11.89]],"id":52671121},{"atb":[[2.06,7.4],[1.93,8.43]],"id":65460404}],"con":true,"img":false}]}
{"op":"mcm","clk":"11448375272","pt":1717289407462,"mc":[{"id":"1.229554924","rc":[{"atb":[[1.56,0],[1.66,0]],"id":52671121},{"atb":[[2.06,0],[1.93,0]],"id":65460404}],"con":true,"img":false}]}
{"op":"mcm","clk":"11448375736","pt":1717289413686,"mc":[{"id":"1.229554924","rc":[{"atb":[[1.56,14.01],[1.66,11.89]],"id":52671121},{"atb":[[2.06,7.4],[1.93,8.43]],"id":65460404}],"con":true,"img":false}]}
{"op":"mcm","clk":"11448378852","pt":1717289456920,"mc":[{"id":"1.229554924","rc":[{"atb":[[1.56,0],[1.66,0]],"id":52671121},{"atb":[[2.06,0],[1.93,0]],"id":65460404}],"con":true,"img":false}]}
{"op":"mcm","clk":"11448379529","pt":1717289465530,"mc":[{"id":"1.229554924","rc":[{"atb":[[1.56,14.01],[1.66,11.89]],"id":52671121},{"atb":[[2.06,7.4],[1.93,8.43]],"id":65460404}],"con":true,"img":false}]}
{"op":"mcm","clk":"11448381082","pt":1717289487636,"mc":[{"id":"1.229554924","rc":[{"atb":[[1.56,0],[1.66,0]],"id":52671121},{"atb":[[2.06,0],[1.93,0]],"id":65460404}],"con":true,"img":false}]}
{"op":"mcm","clk":"11448381758","pt":1717289496483,"mc":[{"id":"1.229554924","rc":[{"atb":[[1.62,12.65],[1.52,15.09]],"id":52671121},{"atb":[[2.12,7],[1.96,8.17]],"id":65460404}],"con":true,"img":false}]}
{"op":"mcm","clk":"11448383596","pt":1717289521000,"mc":[{"id":"1.229554924","rc":[{"atb":[[1.62,0],[1.52,0]],"id":52671121},{"atb":[[2.12,0],[1.96,0]],"id":65460404}],"con":true,"img":false}]}
{"op":"mcm","clk":"11448384385","pt":1717289531252,"mc":[{"id":"1.229554924","rc":[{"atb":[[1.62,12.65],[1.52,15.09]],"id":52671121},{"atb":[[2.12,7],[1.96,8.17]],"id":65460404}],"con":true,"img":false}]}
{"op":"mcm","clk":"11448452965","pt":1717290537252,"mc":[{"id":"1.229554924","rc":[{"atb":[[1.62,0],[1.52,0]],"id":52671121},{"atb":[[2.12,0],[1.96,0]],"id":65460404}],"con":true,"img":false}]}
{"op":"mcm","clk":"11448453486","pt":1717290545869,"mc":[{"id":"1.229554924","rc":[{"atb":[[1.82,9.56],[1.72,10.89]],"id":52671121},{"atb":[[1.82,9.56],[1.92,8.52]],"id":65460404}],"con":true,"img":false}]}
{"op":"mcm","clk":"11448454336","pt":1717290557091,"mc":[{"id":"1.229554924","rc":[{"atb":[[1.82,0],[1.72,0]],"id":52671121},{"atb":[[1.82,0],[1.92,0]],"id":65460404}],"con":true,"img":false}]}
{"op":"mcm","clk":"11448454922","pt":1717290565164,"mc":[{"id":"1.229554924","rc":[{"atb":[[1.82,9.56],[1.72,10.89]],"id":52671121},{"atb":[[1.82,9.56],[1.92,8.52]],"id":65460404}],"con":true,"img":false}]}
{"op":"mcm","clk":"11448455687","pt":1717290577115,"mc":[{"id":"1.229554924","rc":[{"atb":[[1.82,0],[1.72,0]],"id":52671121},{"atb":[[1.82,0],[1.92,0]],"id":65460404}],"con":true,"img":false}]}
{"op":"mcm","clk":"11448456059","pt":1717290583604,"mc":[{"id":"1.229554924","rc":[{"atb":[[1.82,9.56],[1.72,10.89]],"id":52671121},{"atb":[[1.82,9.56],[1.92,8.52]],"id":65460404}],"con":true,"img":false}]}
{"op":"mcm","clk":"11448459594","pt":1717290647490,"mc":[{"id":"1.229554924","rc":[{"atb":[[1.82,0],[1.72,0]],"id":52671121},{"atb":[[1.82,0],[1.92,0]],"id":65460404}],"con":true,"img":false}]}
{"op":"mcm","clk":"11448459972","pt":1717290655707,"mc":[{"id":"1.229554924","rc":[{"atb":[[1.82,9.56],[1.72,10.89]],"id":52671121},{"atb":[[1.82,9.56],[1.92,8.52]],"id":65460404}],"con":true,"img":false}]}
{"op":"mcm","clk":"11448463739","pt":1717290717742,"mc":[{"id":"1.229554924","rc":[{"atb":[[1.82,0],[1.72,0]],"id":52671121},{"atb":[[1.82,0],[1.92,0]],"id":65460404}],"con":true,"img":false}]}
{"op":"mcm","clk":"11448465282","pt":1717290743288,"mc":[{"id":"1.229554924","rc":[{"atb":[[1.82,9.56],[1.72,10.89]],"id":52671121},{"atb":[[1.82,9.56],[1.92,8.52]],"id":65460404}],"con":true,"img":false}]}
{"op":"mcm","clk":"11448465960","pt":1717290755917,"mc":[{"id":"1.229554924","rc":[{"atb":[[1.82,0],[1.72,0]],"id":52671121},{"atb":[[1.82,0],[1.92,0]],"id":65460404}],"con":true,"img":false}]}
{"op":"mcm","clk":"11448466602","pt":1717290765785,"mc":[{"id":"1.229554924","rc":[{"atb":[[1.77,10.19],[1.87,9.01]],"id":52671121},{"atb":[[1.79,9.93],[1.89,8.81]],"id":65460404}],"con":true,"img":false}]}
{"op":"mcm","clk":"11448467888","pt":1717290786624,"mc":[{"id":"1.229554924","rc":[{"atb":[[1.77,0],[1.87,0]],"id":52671121},{"atb":[[1.79,0],[1.89,0]],"id":65460404}],"con":true,"img":false}]}
{"op":"mcm","clk":"11448468363","pt":1717290794432,"mc":[{"id":"1.229554924","rc":[{"atb":[[1.77,10.19],[1.87,9.01]],"id":52671121},{"atb":[[1.79,9.93],[1.89,8.81]],"id":65460404}],"con":true,"img":false}]}
{"op":"mcm","clk":"11448951034","pt":1717300631169,"mc":[{"id":"1.229554924","rc":[{"atb":[[1.02,8.59]],"id":52671121},{"atl":[[990,0.85]],"id":52671121},{"atb":[[1.01,17.19]],"id":65460404},{"atl":[[990,0.85]],"id":65460404}],"con":true,"img":false}]}
{"op":"mcm","clk":"11449585886","pt":1717311429387,"mc":[{"id":"1.229554924","rc":[{"atl":[[990,0.17]],"id":52671121},{"atl":[[990,0.17]],"id":65460404}],"con":true,"img":false}]}
{"op":"mcm","clk":"11449667363","pt":1717313215933,"mc":[{"id":"1.229554924","rc":[{"atb":[[1.77,0],[1.87,0]],"id":52671121},{"atb":[[1.79,0],[1.89,0]],"id":65460404}],"con":true,"img":false}]}
{"op":"mcm","clk":"11449668017","pt":1717313230061,"mc":[{"id":"1.229554924","rc":[{"atb":[[1.77,10.19],[1.87,9.01]],"id":52671121},{"atb":[[1.79,9.93],[1.89,8.81]],"id":65460404}],"con":true,"img":false}]}
{"op":"mcm","clk":"11449670132","pt":1717313273588,"mc":[{"id":"1.229554924","rc":[{"atb":[[1.77,0],[1.87,0]],"id":52671121},{"atb":[[1.79,0],[1.89,0]],"id":65460404}],"con":true,"img":false}]}
{"op":"mcm","clk":"11449671569","pt":1717313301739,"mc":[{"id":"1.229554924","rc":[{"atb":[[1.84,9.34],[1.74,10.6]],"id":52671121},{"atb":[[1.81,9.68],[1.91,8.62]],"id":65460404}],"con":true,"img":false}]}
{"op":"mcm","clk":"11449753638","pt":1717314283862,"mc":[{"id":"1.229554924","rc":[{"atb":[[1.84,0],[1.74,0]],"id":52671121},{"atb":[[1.81,0],[1.91,0]],"id":65460404}],"con":true,"img":false}]}
{"op":"mcm","clk":"11449754572","pt":1717314295496,"mc":[{"id":"1.229554924","rc":[{"atb":[[1.84,9.34],[1.74,10.6]],"id":52671121},{"atb":[[1.81,9.68],[1.91,8.62]],"id":65460404}],"con":true,"img":false}]}
{"op":"mcm","clk":"11449862835","pt":1717315412239,"mc":[{"id":"1.229554924","rc":[{"atb":[[1.84,0],[1.74,0]],"id":52671121},{"atb":[[1.81,0],[1.91,0]],"id":65460404}],"con":true,"img":false}]}
{"op":"mcm","clk":"11449866531","pt":1717315447341,"mc":[{"id":"1.229554924","rc":[{"atb":[[1.84,9.34],[1.74,10.6]],"id":52671121},{"atb":[[1.81,9.68],[1.91,8.62]],"id":65460404}],"con":true,"img":false}]}
{"op":"mcm","clk":"11449893712","pt":1717315713192,"mc":[{"id":"1.229554924","rc":[{"atb":[[1.84,0],[1.74,0]],"id":52671121},{"atb":[[1.81,0],[1.91,0]],"id":65460404}],"con":true,"img":false}]}
{"op":"mcm","clk":"11449898095","pt":1717315753812,"mc":[{"id":"1.229554924","rc":[{"atb":[[1.84,9.34],[1.74,10.6]],"id":52671121},{"atb":[[1.81,9.68],[1.91,8.62]],"id":65460404}],"con":true,"img":false}]}
{"op":"mcm","clk":"11449970518","pt":1717316552873,"mc":[{"id":"1.229554924","rc":[{"atb":[[1.84,0],[1.74,0]],"id":52671121},{"atb":[[1.81,0],[1.91,0]],"id":65460404}],"con":true,"img":false}]}
{"op":"mcm","clk":"11449971658","pt":1717316571125,"mc":[{"id":"1.229554924","rc":[{"atb":[[1.84,9.34],[1.74,10.6]],"id":52671121},{"atb":[[1.81,9.68],[1.91,8.62]],"id":65460404}],"con":true,"img":false}]}
{"op":"mcm","clk":"11450051687","pt":1717317460901,"mc":[{"id":"1.229554924","rc":[{"atb":[[1.84,0],[1.74,0]],"id":52671121},{"atb":[[1.81,0],[1.91,0]],"id":65460404}],"con":true,"img":false}]}
{"op":"mcm","clk":"11450053353","pt":1717317479872,"mc":[{"id":"1.229554924","rc":[{"atb":[[1.84,9.34],[1.74,10.6]],"id":52671121},{"atb":[[1.81,9.68],[1.91,8.62]],"id":65460404}],"con":true,"img":false}]}
{"op":"mcm","clk":"11450128174","pt":1717318324162,"mc":[{"id":"1.229554924","rc":[{"atb":[[1.84,0],[1.74,0]],"id":52671121},{"atb":[[1.81,0],[1.91,0]],"id":65460404}],"con":true,"img":false}]}
{"op":"mcm","clk":"11450129268","pt":1717318336095,"mc":[{"id":"1.229554924","rc":[{"atb":[[1.84,9.34],[1.74,10.6]],"id":52671121},{"atb":[[1.81,9.68],[1.91,8.62]],"id":65460404}],"con":true,"img":false}]}
{"op":"mcm","clk":"11450208408","pt":1717319183232,"mc":[{"id":"1.229554924","rc":[{"atb":[[1.84,0],[1.74,0]],"id":52671121},{"atb":[[1.81,0],[1.91,0]],"id":65460404}],"con":true,"img":false}]}
{"op":"mcm","clk":"11450210488","pt":1717319203422,"mc":[{"id":"1.229554924","rc":[{"atb":[[1.84,9.34],[1.74,10.6]],"id":52671121},{"atb":[[1.81,9.68],[1.91,8.62]],"id":65460404}],"con":true,"img":false}]}
{"op":"mcm","clk":"11450279077","pt":1717319965151,"mc":[{"id":"1.229554924","rc":[{"atb":[[1.84,0],[1.74,0]],"id":52671121},{"atb":[[1.81,0],[1.91,0]],"id":65460404}],"con":true,"img":false}]}
{"op":"mcm","clk":"11450280028","pt":1717319977177,"mc":[{"id":"1.229554924","rc":[{"atb":[[1.78,10.06],[1.68,11.54]],"id":52671121},{"atb":[[1.84,9.34],[1.94,8.34]],"id":65460404}],"con":true,"img":false}]}
{"op":"mcm","clk":"11450282306","pt":1717320005210,"mc":[{"id":"1.229554924","rc":[{"atb":[[1.78,0],[1.68,0]],"id":52671121},{"atb":[[1.84,0],[1.94,0]],"id":65460404}],"con":true,"img":false}]}
{"op":"mcm","clk":"11450283138","pt":1717320015425,"mc":[{"id":"1.229554924","rc":[{"atb":[[1.71,11.05],[1.61,12.86]],"id":52671121},{"atb":[[1.99,7.92],[1.89,8.81]],"id":65460404}],"con":true,"img":false}]}
{"op":"mcm","clk":"11450284728","pt":1717320037531,"mc":[{"id":"1.229554924","rc":[{"atb":[[1.71,0],[1.61,0]],"id":52671121},{"atb":[[1.99,0],[1.89,0]],"id":65460404}],"con":true,"img":false}]}
{"op":"mcm","clk":"11450285290","pt":1717320045849,"mc":[{"id":"1.229554924","rc":[{"atb":[[1.71,11.05],[1.61,12.86]],"id":52671121},{"atb":[[1.99,7.92],[1.89,8.81]],"id":65460404}],"con":true,"img":false}]}
{"op":"mcm","clk":"11450286930","pt":1717320072780,"mc":[{"id":"1.229554924","rc":[{"atb":[[1.71,0],[1.61,0]],"id":52671121},{"atb":[[1.99,0],[1.89,0]],"id":65460404}],"con":true,"img":false}]}
{"op":"mcm","clk":"11450287949","pt":1717320087390,"mc":[{"id":"1.229554924","rc":[{"atb":[[1.71,11.05],[1.61,12.86]],"id":52671121},{"atb":[[1.99,7.92],[1.89,8.81]],"id":65460404}],"con":true,"img":false}]}
{"op":"mcm","clk":"11450289710","pt":1717320114841,"mc":[{"id":"1.229554924","rc":[{"atb":[[1.71,0],[1.61,0]],"id":52671121},{"atb":[[1.99,0],[1.89,0]],"id":65460404}],"con":true,"img":false}]}
{"op":"mcm","clk":"11450290825","pt":1717320129869,"mc":[{"id":"1.229554924","rc":[{"atb":[[1.71,11.05],[1.61,12.86]],"id":52671121},{"atb":[[1.99,7.92],[1.89,8.81]],"id":65460404}],"con":true,"img":false}]}
{"op":"mcm","clk":"11450298222","pt":1717320240412,"mc":[{"id":"1.229554924","rc":[{"atb":[[1.25,23.91]],"id":52671121},{"atl":[[7.8,2]],"id":52671121},{"atb":[[1.28,17.2]],"id":65460404},{"atl":[[7.2,2]],"id":65460404}],"con":true,"img":false}]}
{"op":"mcm","clk":"11450298235","pt":1717320240625,"mc":[{"id":"1.229554924","rc":[{"atl":[[2.56,16.03],[2.52,13.16],[2.6,18.75],[2.48,10.14]],"id":52671121},{"atl":[[2.54,9.74],[2.66,18.07],[2.58,12.66],[2.62,15.43]],"id":65460404}],"con":true,"img":false}]}
{"op":"mcm","clk":"11450298412","pt":1717320243217,"mc":[{"id":"1.229554924","rc":[{"atl":[[2.5,10],[2.48,0]],"id":52671121},{"atl":[[2.54,0],[2.74,8.62],[2.62,9.26]],"id":65460404}],"con":true,"img":false}]}
{"op":"mcm","clk":"11450298507","pt":1717320244415,"mc":[{"id":"1.229554924","rc":[{"atl":[[2.48,10.14]],"id":52671121}],"con":true,"img":false}]}
{"op":"mcm","clk":"11450298510","pt":1717320244513,"mc":[{"id":"1.229554924","rc":[{"atl":[[2.5,0]],"id":52671121},{"atl":[[2.58,0]],"id":65460404}],"con":true,"img":false}]}
{"op":"mcm","clk":"11450298561","pt":1717320245393,"mc":[{"id":"1.229554924","rc":[{"atl":[[2.72,8.72],[2.62,0],[2.7,8.82]],"id":65460404}],"con":true,"img":false}]}
{"op":"mcm","clk":"11450298583","pt":1717320245707,"mc":[{"id":"1.229554924","rc":[{"atl":[[2.66,0]],"id":65460404}],"con":true,"img":false}]}
{"op":"mcm","clk":"11450298889","pt":1717320249698,"mc":[{"id":"1.229554924","rc":[{"atl":[[2.4,10.71]],"id":52671121}],"con":true,"img":false}]}
{"op":"mcm","clk":"11450298894","pt":1717320249802,"mc":[{"id":"1.229554924","rc":[{"atl":[[2.48,0]],"id":52671121}],"con":true,"img":false}]}
{"op":"mcm","clk":"11450299274","pt":1717320255413,"mc":[{"id":"1.229554924","rc":[{"atl":[[2.74,11.49]],"id":65460404}],"con":true,"img":false}]}
{"op":"mcm","clk":"11450299548","pt":1717320259739,"mc":[{"id":"1.229554924","rc":[{"atl":[[2.44,13.89]],"id":52671121}],"con":true,"img":false}]}
{"op":"mcm","clk":"11450299816","pt":1717320263735,"mc":[{"id":"1.229554924","rc":[{"atl":[[2.6,0]],"id":52671121}],"con":true,"img":false}]}
{"op":"mcm","clk":"11450299967","pt":1717320265447,"mc":[{"id":"1.229554924","rc":[{"atl":[[2.78,14.04]],"id":65460404}],"con":true,"img":false}]}
{"op":"mcm","clk":"11450300268","pt":1717320269721,"mc":[{"id":"1.229554924","rc":[{"atl":[[2.48,16.89]],"id":52671121}],"con":true,"img":false}]}
{"op":"mcm","clk":"11450300443","pt":1717320272735,"mc":[{"id":"1.229554924","rc":[{"atl":[[2.56,0]],"id":52671121}],"con":true,"img":false}]}
{"op":"mcm","clk":"11450300807","pt":1717320277574,"mc":[{"id":"1.229554924","rc":[{"atl":[[3.15,27.05],[7.8,0]],"id":52671121},{"atb":[[1.28,0],[1.38,17.2]],"id":65460404},{"atl":[[7.2,0],[3.3,20.31]],"id":65460404}],"con":true,"img":false}]}
{"op":"mcm","clk":"11450302638","pt":1717320306610,"mc":[{"id":"1.229554924","rc":[{"atb":[[1.71,0],[1.61,0]],"id":52671121},{"atb":[[1.99,0],[1.89,0]],"id":65460404}],"con":true,"img":false}]}
{"op":"mcm","clk":"11450302648","pt":1717320306664,"mc":[{"id":"1.229554924","rc":[{"atb":[[1.03,47.82]],"id":52671121},{"atb":[[1.02,34.4],[1.38,0]],"id":65460404}],"con":true,"img":false}]}
{"op":"mcm","clk":"11450302655","pt":1717320306765,"mc":[{"id":"1.229554924","rc":[{"atb":[[1.25,0]],"id":52671121}],"con":true,"img":false}]}
{"op":"mcm","clk":"11450302686","pt":1717320307400,"mc":[{"id":"1.229554924","rc":[{"atl":[[3.85,27.78],[3.15,0]],"id":52671121},{"atl":[[4,22.98],[3.3,0]],"id":65460404}],"con":true,"img":false}]}
{"op":"mcm","clk":"11450302890","pt":1717320310477,"mc":[{"id":"1.229554924","rc":[{"atb":[[1.27,92.59],[1.25,120],[1.29,68.97],[1.31,48.39]],"id":52671121},{"atb":[[1.45,66.67],[1.49,40.82],[1.51,29.41],[1.47,53.19]],"id":65460404}],"con":true,"img":false}]}
{"op":"mcm","clk":"11450302900","pt":1717320310584,"mc":[{"id":"1.229554924","rc":[{"atb":[[1.03,0],[1.29,165.75]],"id":52671121}],"con":true,"img":false}]}
{"op":"mcm","clk":"11450302906","pt":1717320310685,"mc":[{"id":"1.229554924","rc":[{"atb":[[1.27,306.73],[1.29,68.97]],"id":52671121}],"con":true,"img":false}]}
{"op":"mcm","clk":"11450303167","pt":1717320314267,"mc":[{"id":"1.229554924","rc":[{"atb":[[1.02,0],[1.38,94.01]],"id":65460404}],"con":true,"img":false}]}
{"op":"mcm","clk":"11450303925","pt":1717320326716,"mc":[{"id":"1.229554924","rc":[{"atb":[[1.71,11.05],[1.61,12.86]],"id":52671121},{"atb":[[1.99,7.92],[1.89,8.81]],"id":65460404}],"con":true,"img":false}]}
{"op":"mcm","clk":"11450304333","pt":1717320333506,"mc":[{"id":"1.229554924","rc":[{"atl":[[3.85,0],[3.15,27.05]],"id":52671121},{"atl":[[4,0],[3.3,20.31]],"id":65460404}],"con":true,"img":false}]}
{"op":"mcm","clk":"11450308136","pt":1717320400500,"mc":[{"id":"1.229554924","rc":[{"atb":[[1.71,0],[1.61,0]],"id":52671121},{"atb":[[1.99,0],[1.89,0]],"id":65460404}],"con":true,"img":false}]}
{"op":"mcm","clk":"11450308154","pt":1717320400704,"mc":[{"id":"1.229554924","rc":[{"atb":[[1.27,92.59],[1.26,137.94]],"id":52671121}],"con":true,"img":false}]}
{"op":"mcm","clk":"11450308291","pt":1717320402736,"mc":[{"id":"1.229554924","rc":[{"atl":[[4,27.78],[3.15,0]],"id":52671121},{"atl":[[3.3,0],[4.2,22.98]],"id":65460404}],"con":true,"img":false}]}
{"op":"mcm","clk":"11450308808","pt":1717320410992,"mc":[{"id":"1.229554924","rc":[{"atb":[[1.71,11.05],[1.61,12.86]],"id":52671121},{"atb":[[1.99,7.92],[1.89,8.81]],"id":65460404}],"con":true,"img":false}]}
{"op":"mcm","clk":"11450310593","pt":1717320438203,"mc":[{"id":"1.229554924","rc":[{"atl":[[4,0],[3.35,27.05]],"id":52671121},{"atl":[[3.5,20.31],[4.2,0]],"id":65460404}],"con":true,"img":false}]}
{"op":"mcm","clk":"11450325260","pt":1717320555161,"mc":[{"id":"1.229554924","rc":[{"atl":[[2.76,11.36]],"id":65460404}],"con":true,"img":false}]}
{"op":"mcm","clk":"11450325269","pt":1717320555264,"mc":[{"id":"1.229554924","rc":[{"atl":[[2.7,0]],"id":65460404}],"con":true,"img":false}]}
{"op":"mcm","clk":"11450325371","pt":1717320556670,"mc":[{"id":"1.229554924","rc":[{"atl":[[2.4,0],[2.38,10.87]],"id":52671121}],"con":true,"img":false}]}
{"op":"mcm","clk":"11450344125","pt":1717320794361,"mc":[{"id":"1.229554924","rc":[{"atb":[[1.71,0],[1.61,0]],"id":52671121},{"atb":[[1.99,0],[1.89,0]],"id":65460404}],"con":true,"img":false}]}
{"op":"mcm","clk":"11450344213","pt":1717320795458,"mc":[{"id":"1.229554924","rc":[{"atl":[[4,27.78],[3.35,0]],"id":52671121},{"atl":[[3.5,0],[4.2,22.98]],"id":65460404}],"con":true,"img":false}]}
{"op":"mcm","clk":"11450345295","pt":1717320809084,"mc":[{"id":"1.229554924","rc":[{"atb":[[1.71,11.05],[1.61,12.86]],"id":52671121},{"atb":[[1.99,7.92],[1.89,8.81]],"id":65460404}],"con":true,"img":false}]}
{"op":"mcm","clk":"11450346723","pt":1717320826996,"mc":[{"id":"1.229554924","rc":[{"atl":[[4,0],[3.3,27.05]],"id":52671121},{"atl":[[3.5,22.85],[4.2,0]],"id":65460404}],"con":true,"img":false}]}
{"op":"mcm","clk":"11450352314","pt":1717320890346,"mc":[{"id":"1.229554924","rc":[{"atb":[[1.51,0]],"id":65460404}],"con":true,"img":false}]}
{"op":"mcm","clk":"11450369432","pt":1717321112415,"mc":[{"id":"1.229554924","rc":[{"atl":[[2.4,10.71],[2.38,0]],"id":52671121}],"con":true,"img":false}]}
{"op":"mcm","clk":"11450370514","pt":1717321128728,"mc":[{"id":"1.229554924","rc":[{"atl":[[2.4,0],[2.38,10.87]],"id":52671121}],"con":true,"img":false}]}
{"op":"mcm","clk":"11450372150","pt":1717321151965,"mc":[{"id":"1.229554924","rc":[{"atb":[[1.26,0],[1.31,117.36]],"id":52671121},{"atl":[[2.9,27.05],[2.38,0],[2.28,11.72],[3.3,0]],"id":52671121},{"atb":[[1.46,66.67],[1.38,0]],"id":65460404},{"atl":[[3.15,22.85],[3.5,0]],"id":65460404}],"con":true,"img":false}]}
{"op":"mcm","clk":"11450372595","pt":1717321158297,"mc":[{"id":"1.229554924","rc":[{"atb":[[1.71,0],[1.61,0]],"id":52671121},{"atb":[[1.99,0],[1.89,0]],"id":65460404}],"con":true,"img":false}]}
{"op":"mcm","clk":"11450372604","pt":1717321158403,"mc":[{"id":"1.229554924","rc":[{"atb":[[1.27,278.92]],"id":52671121}],"con":true,"img":false}]}
{"op":"mcm","clk":"11450372615","pt":1717321158570,"mc":[{"id":"1.229554924","rc":[{"atb":[[1.31,48.39]],"id":52671121}],"con":true,"img":false}]}
{"op":"mcm","clk":"11450372651","pt":1717321159078,"mc":[{"id":"1.229554924","rc":[{"atl":[[2.9,0],[3.25,27.78]],"id":52671121},{"atb":[[1.51,29.41]],"id":65460404},{"atl":[[3.85,22.98],[3.15,0]],"id":65460404}],"con":true,"img":false}]}
{"op":"mcm","clk":"11450372871","pt":1717321161895,"mc":[{"id":"1.229554924","rc":[{"atl":[[2.32,15.15]],"id":52671121}],"con":true,"img":false}]}
{"op":"mcm","clk":"11450372983","pt":1717321163302,"mc":[{"id":"1.229554924","rc":[{"atl":[[2.52,0]],"id":52671121}],"con":true,"img":false}]}
{"op":"mcm","clk":"11450373543","pt":1717321171905,"mc":[{"id":"1.229554924","rc":[{"atl":[[2.36,18.38]],"id":52671121}],"con":true,"img":false}]}
{"op":"mcm","clk":"11450373732","pt":1717321174803,"mc":[{"id":"1.229554924","rc":[{"atb":[[1.71,11.05],[1.61,12.86]],"id":52671121},{"atb":[[1.99,7.92],[1.89,8.81]],"id":65460404}],"con":true,"img":false}]}
{"op":"mcm","clk":"11450373743","pt":1717321174907,"mc":[{"id":"1.229554924","rc":[{"atl":[[2.48,0]],"id":52671121}],"con":true,"img":false}]}
{"op":"mcm","clk":"11450374075","pt":1717321179986,"mc":[{"id":"1.229554924","rc":[{"atb":[[1.4,68.97],[1.27,92.59]],"id":52671121},{"atl":[[3.25,0],[2.68,29.04]],"id":52671121},{"atb":[[1.46,0],[1.54,40.82]],"id":65460404},{"atl":[[3.85,0],[3.15,22.85]],"id":65460404}],"con":true,"img":false}]}
{"op":"mcm","clk":"11450374190","pt":1717321181951,"mc":[{"id":"1.229554924","rc":[{"atl":[[2.4,21.43]],"id":52671121}],"con":true,"img":false}]}
{"op":"mcm","clk":"11450374392","pt":1717321185061,"mc":[{"id":"1.229554924","rc":[{"atl":[[2.44,0]],"id":52671121}],"con":true,"img":false}]}
{"op":"mcm","clk":"11450375794","pt":1717321209177,"mc":[{"id":"1.229554924","rc":[{"atl":[[2.26,11.9]],"id":52671121},{"atl":[[2.7,8.82]],"id":65460404}],"con":true,"img":false}]}
{"op":"mcm","clk":"11450375801","pt":1717321209278,"mc":[{"id":"1.229554924","rc":[{"atl":[[2.28,0]],"id":52671121},{"atl":[[2.72,0]],"id":65460404}],"con":true,"img":false}]}
{"op":"mcm","clk":"11450376133","pt":1717321215482,"mc":[{"id":"1.229554924","rc":[{"atl":[[2.28,11.72],[2.26,0]],"id":52671121},{"atl":[[2.72,8.72],[2.7,0]],"id":65460404}],"con":true,"img":false}]}
{"op":"mcm","clk":"11450376583","pt":1717321223499,"mc":[{"id":"1.229554924","rc":[{"atl":[[2.26,11.9]],"id":52671121}],"con":true,"img":false}]}
{"op":"mcm","clk":"11450376589","pt":1717321223602,"mc":[{"id":"1.229554924","rc":[{"atl":[[2.28,0]],"id":52671121},{"atl":[[2.72,0],[2.7,8.82]],"id":65460404}],"con":true,"img":false}]}
{"op":"mcm","clk":"11450376998","pt":1717321229824,"mc":[{"id":"1.229554924","rc":[{"atl":[[2.28,11.72],[2.26,0]],"id":52671121},{"atl":[[2.72,8.72],[2.7,0]],"id":65460404}],"con":true,"img":false}]}
{"op":"mcm","clk":"11450378584","pt":1717321256146,"mc":[{"id":"1.229554924","rc":[{"atl":[[2.28,0],[2.26,11.9]],"id":52671121},{"atl":[[2.72,0],[2.7,8.82]],"id":65460404}],"con":true,"img":false}]}
{"op":"mcm","clk":"11450379602","pt":1717321271933,"mc":[{"id":"1.229554924","rc":[{"atl":[[2.82,36.76],[2.68,0]],"id":52671121}],"con":true,"img":false}]}
{"op":"mcm","clk":"11450380783","pt":1717321288961,"mc":[{"id":"1.229554924","rc":[{"atl":[[2.72,8.72],[2.7,0]],"id":65460404}],"con":true,"img":false}]}
{"op":"mcm","clk":"11450381281","pt":1717321296782,"mc":[{"id":"1.229554924","rc":[{"atl":[[2.28,11.72],[2.26,0]],"id":52671121}],"con":true,"img":false}]}
{"op":"mcm","clk":"11450382295","pt":1717321314219,"mc":[{"id":"1.229554924","rc":[{"atb":[[1.51,0]],"id":65460404}],"con":true,"img":false}]}
{"op":"mcm","clk":"11450394607","pt":1717321511757,"mc":[{"id":"1.229554924","rc":[{"atb":[[1.71,0],[1.61,0]],"id":52671121},{"atb":[[1.99,0],[1.89,0]],"id":65460404}],"con":true,"img":false}]}
{"op":"mcm","clk":"11450394615","pt":1717321511862,"mc":[{"id":"1.229554924","rc":[{"atb":[[1.4,0],[1.29,186.33]],"id":52671121},{"atb":[[1.54,0],[1.47,134.83]],"id":65460404}],"con":true,"img":false}]}
{"op":"mcm","clk":"11450395228","pt":1717321520252,"mc":[{"id":"1.229554924","rc":[{"atl":[[3.4,36.76]],"id":52671121},{"atb":[[1.51,29.41]],"id":65460404},{"atl":[[4.1,22.98]],"id":65460404}],"con":true,"img":false}]}
{"op":"mcm","clk":"11450395237","pt":1717321520356,"mc":[{"id":"1.229554924","rc":[{"atb":[[1.27,327.31]],"id":52671121},{"atl":[[2.82,0]],"id":52671121},{"atb":[[1.49,107.49],[1.47,53.19]],"id":65460404},{"atl":[[3.15,0]],"id":65460404}],"con":true,"img":false}]}
{"op":"mcm","clk":"11450395241","pt":1717321520456,"mc":[{"id":"1.229554924","rc":[{"atb":[[1.29,68.97]],"id":52671121},{"atb":[[1.47,123.42]],"id":65460404}],"con":true,"img":false}]}
{"op":"mcm","clk":"11450395246","pt":1717321520562,"mc":[{"id":"1.229554924","rc":[{"atb":[[1.49,40.82]],"id":65460404}],"con":true,"img":false}]}
{"op":"mcm","clk":"11450396064","pt":1717321532382,"mc":[{"id":"1.229554924","rc":[{"atb":[[1.71,11.05],[1.61,12.86]],"id":52671121},{"atb":[[1.99,7.92],[1.89,8.81]],"id":65460404}],"con":true,"img":false}]}
{"op":"mcm","clk":"11450396072","pt":1717321532484,"mc":[{"id":"1.229554924","rc":[{"atb":[[1.27,92.59],[1.37,68.97]],"id":52671121}],"con":true,"img":false}]}
{"op":"mcm","clk":"11450396133","pt":1717321533056,"mc":[{"id":"1.229554924","rc":[{"atl":[[2.82,33.53],[3.4,0]],"id":52671121},{"atl":[[4.1,0],[3.35,22.85]],"id":65460404}],"con":true,"img":false}]}
{"op":"mcm","clk":"11450400674","pt":1717321597312,"mc":[{"id":"1.229554924","rc":[{"atb":[[1.51,0]],"id":65460404}],"con":true,"img":false}]}
{"op":"mcm","clk":"11450421294","pt":1717321850610,"mc":[{"id":"1.229554924","rc":[{"atb":[[1.71,0],[1.61,0]],"id":52671121},{"atb":[[1.99,0],[1.89,0]],"id":65460404}],"con":true,"img":false}]}
{"op":"mcm","clk":"11450421302","pt":1717321850718,"mc":[{"id":"1.229554924","rc":[{"atb":[[1.37,0],[1.29,186.33]],"id":52671121},{"atb":[[1.45,230.91],[1.47,53.19]],"id":65460404}],"con":true,"img":false}]}
{"op":"mcm","clk":"11450421486","pt":1717321852906,"mc":[{"id":"1.229554924","rc":[{"atl":[[2.82,0],[2.28,0],[3.4,36.76],[2.26,11.9]],"id":52671121},{"atb":[[1.51,29.41]],"id":65460404},{"atl":[[4.1,22.98],[3.35,0]],"id":65460404}],"con":true,"img":false}]}
{"op":"mcm","clk":"11450421737","pt":1717321855925,"mc":[{"id":"1.229554924","rc":[{"atb":[[1.27,327.31],[1.29,68.97]],"id":52671121}],"con":true,"img":false}]}
{"op":"mcm","clk":"11450422893","pt":1717321869440,"mc":[{"id":"1.229554924","rc":[{"atb":[[1.71,11.05],[1.61,12.86]],"id":52671121},{"atb":[[1.99,7.92],[1.89,8.81]],"id":65460404}],"con":true,"img":false}]}
{"op":"mcm","clk":"11450423494","pt":1717321876859,"mc":[{"id":"1.229554924","rc":[{"atb":[[1.27,92.59],[1.37,68.97]],"id":52671121}],"con":true,"img":false}]}
{"op":"mcm","clk":"11450424626","pt":1717321890744,"mc":[{"id":"1.229554924","rc":[{"atl":[[2.82,33.53],[3.4,0]],"id":52671121},{"atl":[[4.1,0],[3.35,22.85]],"id":65460404}],"con":true,"img":false}]}
{"op":"mcm","clk":"11450425690","pt":1717321903656,"mc":[{"id":"1.229554924","rc":[{"atb":[[1.71,0],[1.61,0]],"id":52671121},{"atb":[[1.99,0],[1.89,0]],"id":65460404}],"con":true,"img":false}]}
{"op":"mcm","clk":"11450425709","pt":1717321903861,"mc":[{"id":"1.229554924","rc":[{"atb":[[1.37,0],[1.29,186.33]],"id":52671121},{"atb":[[1.45,66.67],[1.47,123.42]],"id":65460404}],"con":true,"img":false}]}
{"op":"mcm","clk":"11450425841","pt":1717321905279,"mc":[{"id":"1.229554924","rc":[{"atl":[[2.82,0],[3.4,36.76]],"id":52671121},{"atl":[[4.1,22.98],[3.35,0]],"id":65460404}],"con":true,"img":false}]}
{"op":"mcm","clk":"11450425849","pt":1717321905383,"mc":[{"id":"1.229554924","rc":[{"atb":[[1.27,327.31]],"id":52671121}],"con":true,"img":false}]}
{"op":"mcm","clk":"11450425860","pt":1717321905497,"mc":[{"id":"1.229554924","rc":[{"atb":[[1.29,68.97]],"id":52671121}],"con":true,"img":false}]}
{"op":"mcm","clk":"11450426413","pt":1717321912760,"mc":[{"id":"1.229554924","rc":[{"atl":[[2.28,11.72],[2.26,0]],"id":52671121}],"con":true,"img":false}]}
{"op":"mcm","clk":"11450426490","pt":1717321913706,"mc":[{"id":"1.229554924","rc":[{"atb":[[1.71,11.05],[1.61,12.86]],"id":52671121},{"atb":[[1.99,7.92],[1.89,8.81]],"id":65460404}],"con":true,"img":false}]}
{"op":"mcm","clk":"11450426508","pt":1717321913868,"mc":[{"id":"1.229554924","rc":[{"atb":[[1.27,92.59],[1.37,68.97]],"id":52671121}],"con":true,"img":false}]}
{"op":"mcm","clk":"11450426643","pt":1717321915376,"mc":[{"id":"1.229554924","rc":[{"atl":[[2.82,33.53],[2.28,0],[3.4,0],[2.26,11.9]],"id":52671121},{"atl":[[2.72,0],[4.1,0],[3.35,22.85],[2.7,8.82]],"id":65460404}],"con":true,"img":false}]}
{"op":"mcm","clk":"11450439792","pt":1717322064408,"mc":[{"id":"1.229554924","rc":[{"atl":[[2.82,0],[2.68,33.53]],"id":52671121},{"atb":[[1.54,40.82],[1.47,53.19]],"id":65460404}],"con":true,"img":false}]}
{"op":"mcm","clk":"11450451530","pt":1717322198430,"mc":[{"id":"1.229554924","rc":[{"atl":[[2.82,36.76],[2.68,0]],"id":52671121}],"con":true,"img":false}]}
{"op":"mcm","clk":"11450452400","pt":1717322207548,"mc":[{"id":"1.229554924","rc":[{"atb":[[1.71,0],[1.61,0]],"id":52671121},{"atb":[[1.99,0],[1.89,0]],"id":65460404}],"con":true,"img":false}]}
{"op":"mcm","clk":"11450452406","pt":1717322207603,"mc":[{"id":"1.229554924","rc":[{"atb":[[1.37,0],[1.29,186.33]],"id":52671121},{"atb":[[1.54,0],[1.49,111.05]],"id":65460404}],"con":true,"img":false}]}
{"op":"mcm","clk":"11450452414","pt":1717322207707,"mc":[{"id":"1.229554924","rc":[{"atb":[[1.27,327.31],[1.29,68.97]],"id":52671121},{"atb":[[1.49,40.82],[1.47,193.65]],"id":65460404}],"con":true,"img":false}]}
{"op":"mcm","clk":"11450453169","pt":1717322215636,"mc":[{"id":"1.229554924","rc":[{"atl":[[2.82,0],[3.4,36.76]],"id":52671121},{"atb":[[1.51,0],[1.52,28.85]],"id":65460404},{"atl":[[4.1,22.98],[3.35,0]],"id":65460404}],"con":true,"img":false}]}
{"op":"mcm","clk":"11450453174","pt":1717322215741,"mc":[{"id":"1.229554924","rc":[{"atb":[[1.49,107.49],[1.47,53.19]],"id":65460404}],"con":true,"img":false}]}
{"op":"mcm","clk":"11450453665","pt":1717322220846,"mc":[{"id":"1.229554924","rc":[{"atb":[[1.49,40.82],[1.47,189.53]],"id":65460404}],"con":true,"img":false}]}
{"op":"mcm","clk":"11450453988","pt":1717322224465,"mc":[{"id":"1.229554924","rc":[{"atb":[[1.02,144.94]],"id":52671121},{"atl":[[980,0.85]],"id":52671121},{"atb":[[1.01,185.07]],"id":65460404},{"atl":[[970,0.85]],"id":65460404}],"con":true,"img":false}]}
{"op":"mcm","clk":"11450454069","pt":1717322225361,"mc":[{"id":"1.229554924","rc":[{"atb":[[1.71,11.05],[1.61,12.86]],"id":52671121},{"atb":[[1.99,7.92],[1.89,8.81]],"id":65460404}],"con":true,"img":false}]}
{"op":"mcm","clk":"11450454094","pt":1717322225573,"mc":[{"id":"1.229554924","rc":[{"atb":[[1.27,92.59],[1.37,68.97]],"id":52671121}],"con":true,"img":false}]}
{"op":"mcm","clk":"11450454830","pt":1717322233079,"mc":[{"id":"1.229554924","rc":[{"atl":[[2.82,33.53],[3.4,0]],"id":52671121},{"atl":[[4.1,0],[3.35,22.85]],"id":65460404}],"con":true,"img":false}]}
{"op":"mcm","clk":"11450485439","pt":1717322584430,"mc":[{"id":"1.229554924","rc":[{"atb":[[1.71,0],[1.61,0]],"id":52671121},{"atb":[[1.99,0],[1.89,0]],"id":65460404}],"con":true,"img":false}]}
{"op":"mcm","clk":"11450485457","pt":1717322584634,"mc":[{"id":"1.229554924","rc":[{"atb":[[1.37,0],[1.29,186.33]],"id":52671121}],"con":true,"img":false}]}
{"op":"mcm","clk":"11450485474","pt":1717322584805,"mc":[{"id":"1.229554924","rc":[{"atb":[[1.27,327.31],[1.29,68.97]],"id":52671121}],"con":true,"img":false}]}
{"op":"mcm","clk":"11450485537","pt":1717322585686,"mc":[{"id":"1.229554924","rc":[{"atl":[[2.82,0],[3.4,36.76]],"id":52671121},{"atl":[[4.1,22.98],[3.35,0]],"id":65460404}],"con":true,"img":false}]}
{"op":"mcm","clk":"11450486967","pt":1717322601652,"mc":[{"id":"1.229554924","rc":[{"atb":[[1.71,11.05],[1.61,12.86]],"id":52671121},{"atb":[[1.99,7.92],[1.89,8.81]],"id":65460404}],"con":true,"img":false}]}
{"op":"mcm","clk":"11450486988","pt":1717322601864,"mc":[{"id":"1.229554924","rc":[{"atb":[[1.27,92.59],[1.37,68.97]],"id":52671121}],"con":true,"img":false}]}
{"op":"mcm","clk":"11450487244","pt":1717322604626,"mc":[{"id":"1.229554924","rc":[{"atl":[[2.82,33.53],[3.4,0]],"id":52671121},{"atl":[[4.1,0],[3.35,22.85]],"id":65460404}],"con":true,"img":false}]}
{"op":"mcm","clk":"11450490567","pt":1717322642215,"mc":[{"id":"1.229554924","rc":[{"atl":[[2.24,12.1]],"id":52671121}],"con":true,"img":false}]}
{"op":"mcm","clk":"11450490578","pt":1717322642299,"mc":[{"id":"1.229554924","rc":[{"atl":[[2.4,0],[2.26,0]],"id":52671121},{"atb":[[1.49,0],[1.52,0]],"id":65460404},{"atl":[[2.68,8.93]],"id":65460404}],"con":true,"img":false}]}
{"op":"mcm","clk":"11450490592","pt":1717322642405,"mc":[{"id":"1.229554924","rc":[{"atl":[[2.24,0],[2.36,0],[2.32,0]],"id":52671121},{"atl":[[2.7,0]],"id":65460404}],"con":true,"img":false}]}
{"op":"mcm","clk":"11450490604","pt":1717322642501,"mc":[{"id":"1.229554924","rc":[{"atl":[[5.1,24.39]],"id":52671121},{"atl":[[2.74,0],[2.78,0]],"id":65460404}],"con":true,"img":false}]}
{"op":"mcm","clk":"11450490623","pt":1717322642614,"mc":[{"id":"1.229554924","rc":[{"atl":[[2.82,0],[2.24,12.1],[2.36,22.06],[2.32,18.94],[2.28,15.63]],"id":52671121}],"con":true,"img":false}]}
{"op":"mcm","clk":"11450490638","pt":1717322642774,"mc":[{"id":"1.229554924","rc":[{"atl":[[2.82,34.57],[5.1,0]],"id":52671121}],"con":true,"img":false}]}
{"op":"mcm","clk":"11450490657","pt":1717322642880,"mc":[{"id":"1.229554924","rc":[{"atl":[[2.26,11.9]],"id":52671121},{"atl":[[2.7,8.82]],"id":65460404}],"con":true,"img":false}]}
{"op":"mcm","clk":"11450490664","pt":1717322642979,"mc":[{"id":"1.229554924","rc":[{"atl":[[2.24,0]],"id":52671121},{"atl":[[2.68,0]],"id":65460404}],"con":true,"img":false}]}
{"op":"mcm","clk":"11450490737","pt":1717322643665,"mc":[{"id":"1.229554924","rc":[{"atl":[[2.24,12.1],[2.26,0]],"id":52671121}],"con":true,"img":false}]}
{"op":"mcm","clk":"11450490745","pt":1717322643767,"mc":[{"id":"1.229554924","rc":[{"atl":[[2.68,8.93]],"id":65460404}],"con":true,"img":false}]}
{"op":"mcm","clk":"11450490986","pt":1717322645766,"mc":[{"id":"1.229554924","rc":[{"atl":[[2.24,0],[2.26,11.9]],"id":52671121},{"atl":[[2.68,0]],"id":65460404}],"con":true,"img":false}]}
{"op":"mcm","clk":"11450492639","pt":1717322665330,"mc":[{"id":"1.229554924","rc":[{"atb":[[1.72,2]],"id":52671121},{"atl":[[2.82,0],[2.18,2],[2.68,34.57]],"id":52671121},{"atb":[[1.97,2],[1.54,185.07],[1.47,53.19]],"id":65460404},{"atl":[[2.48,2]],"id":65460404}],"con":true,"img":false}]}
{"op":"mcm","clk":"11450492651","pt":1717322665384,"mc":[{"id":"1.229554924","rc":[{"atb":[[1.97,0],[1.96,2]],"id":65460404}],"con":true,"img":false}]}
{"op":"mcm","clk":"11450492662","pt":1717322665491,"mc":[{"id":"1.229554924","rc":[{"atl":[[2.24,12.1],[2.26,0]],"id":52671121},{"atl":[[2.68,8.93]],"id":65460404}],"con":true,"img":false}]}
{"op":"mcm","clk":"11450492681","pt":1717322665695,"mc":[{"id":"1.229554924","rc":[{"atl":[[2.24,0],[2.26,11.9]],"id":52671121},{"atl":[[2.68,0]],"id":65460404}],"con":true,"img":false}]}
{"op":"mcm","clk":"11450492911","pt":1717322668610,"mc":[{"id":"1.229554924","rc":[{"atl":[[2.24,12.1],[2.26,0]],"id":52671121},{"atl":[[2.68,8.93]],"id":65460404}],"con":true,"img":false}]}
{"op":"mcm","clk":"11450492967","pt":1717322669230,"mc":[{"id":"1.229554924","rc":[{"atl":[[2.24,0],[2.26,11.9]],"id":52671121}],"con":true,"img":false}]}
{"op":"mcm","clk":"11450493068","pt":1717322670320,"mc":[{"id":"1.229554924","rc":[{"atl":[[2.24,12.1],[2.26,0]],"id":52671121}],"con":true,"img":false}]}
{"op":"mcm","clk":"11450493126","pt":1717322671005,"mc":[{"id":"1.229554924","rc":[{"atl":[[2.26,11.9]],"id":52671121}],"con":true,"img":false}]}
{"op":"mcm","clk":"11450493132","pt":1717322671111,"mc":[{"id":"1.229554924","rc":[{"atl":[[2.24,0]],"id":52671121}],"con":true,"img":false}]}
{"op":"mcm","clk":"11450493821","pt":1717322678530,"mc":[{"id":"1.229554924","rc":[{"atb":[[1.37,0],[1.42,68.97]],"id":52671121},{"atl":[[2.72,11.63],[3.1,17.75],[3.35,0]],"id":65460404}],"con":true,"img":false}]}
{"op":"mcm","clk":"11450493835","pt":1717322678632,"mc":[{"id":"1.229554924","rc":[{"atb":[[1.96,0],[1.93,2]],"id":65460404}],"con":true,"img":false}]}
{"op":"mcm","clk":"11450494385","pt":1717322684752,"mc":[{"id":"1.229554924","rc":[{"atl":[[2.5,2],[2.68,0],[2.48,0]],"id":65460404}],"con":true,"img":false}]}
{"op":"mcm","clk":"11450494696","pt":1717322688564,"mc":[{"id":"1.229554924","rc":[{"atl":[[2.74,11.49]],"id":65460404}],"con":true,"img":false}]}
{"op":"mcm","clk":"11450496591","pt":1717322710323,"mc":[{"id":"1.229554924","rc":[{"atl":[[2.22,2]],"id":52671121}],"con":true,"img":false}]}
{"op":"mcm","clk":"11450496601","pt":1717322710428,"mc":[{"id":"1.229554924","rc":[{"atb":[[1.71,0],[1.61,0]],"id":52671121},{"atl":[[2.18,0]],"id":52671121},{"atb":[[1.99,0],[1.89,0]],"id":65460404}],"con":true,"img":false}]}
{"op":"mcm","clk":"11450496611","pt":1717322710492,"mc":[{"id":"1.229554924","rc":[{"atb":[[1.72,0],[1.63,2],[1.42,0],[1.31,119.36]],"id":52671121},{"atb":[[1.8,2],[1.54,0],[1.47,240.26]],"id":65460404}],"con":true,"img":false}]}
{"op":"mcm","clk":"11450496622","pt":1717322710594,"mc":[{"id":"1.229554924","rc":[{"atb":[[1.93,0],[1.47,53.19],[1.52,185.07]],"id":65460404}],"con":true,"img":false}]}
{"op":"mcm","clk":"11450496704","pt":1717322711490,"mc":[{"id":"1.229554924","rc":[{"atb":[[1.36,41.67],[1.32,46.87],[1.31,70.97]],"id":52671121},{"atb":[[1.49,30.61],[1.53,28.3]],"id":65460404},{"atl":[[2.68,8.93],[2.7,0]],"id":65460404}],"con":true,"img":false}]}
{"op":"mcm","clk":"11450496710","pt":1717322711591,"mc":[{"id":"1.229554924","rc":[{"atb":[[1.36,134.26]],"id":52671121}],"con":true,"img":false}]}
{"op":"mcm","clk":"11450496718","pt":1717322711696,"mc":[{"id":"1.229554924","rc":[{"atb":[[1.31,0]],"id":52671121}],"con":true,"img":false}]}
{"op":"mcm","clk":"11450496744","pt":1717322712115,"mc":[{"id":"1.229554924","rc":[{"atb":[[1.25,0]],"id":52671121}],"con":true,"img":false}]}
{"op":"mcm","clk":"11450497296","pt":1717322717715,"mc":[{"id":"1.229554924","rc":[{"atb":[[1.36,92.59]],"id":52671121},{"atb":[[1.53,0]],"id":65460404}],"con":true,"img":false}]}
{"op":"mcm","clk":"11450497347","pt":1717322718238,"mc":[{"id":"1.229554924","rc":[{"atb":[[1.72,10.89],[1.62,12.65]],"id":52671121},{"atb":[[1.98,8],[1.88,8.92]],"id":65460404}],"con":true,"img":false}]}
{"op":"mcm","clk":"11450497357","pt":1717322718342,"mc":[{"id":"1.229554924","rc":[{"atb":[[1.73,2],[1.42,68.97]],"id":52671121},{"atl":[[2.22,0],[2.16,2]],"id":52671121},{"atb":[[1.8,0],[1.85,2]],"id":65460404}],"con":true,"img":false}]}
{"op":"mcm","clk":"11450497368","pt":1717322718446,"mc":[{"id":"1.229554924","rc":[{"atb":[[1.36,0],[1.63,0]],"id":52671121}],"con":true,"img":false}]}
{"op":"mcm","clk":"11450497853","pt":1717322723439,"mc":[{"id":"1.229554924","rc":[{"atb":[[1.93,2]],"id":65460404}],"con":true,"img":false}]}
{"op":"mcm","clk":"11450497858","pt":1717322723544,"mc":[{"id":"1.229554924","rc":[{"atb":[[1.85,0]],"id":65460404}],"con":true,"img":false}]}
{"op":"mcm","clk":"11450499369","pt":1717322738636,"mc":[{"id":"1.229554924","rc":[{"atl":[[2.7,8.82]],"id":65460404}],"con":true,"img":false}]}
{"op":"mcm","clk":"11450499383","pt":1717322738739,"mc":[{"id":"1.229554924","rc":[{"atl":[[2.68,0]],"id":65460404}],"con":true,"img":false}]}
{"op":"mcm","clk":"11450499557","pt":1717322740665,"mc":[{"id":"1.229554924","rc":[{"atb":[[1.72,0],[1.62,0]],"id":52671121},{"atl":[[2.22,2]],"id":52671121},{"atb":[[1.98,0],[1.88,0]],"id":65460404}],"con":true,"img":false}]}
{"op":"mcm","clk":"11450499566","pt":1717322740768,"mc":[{"id":"1.229554924","rc":[{"atb":[[1.63,2],[1.32,117.84]],"id":52671121},{"atl":[[2.16,0]],"id":52671121},{"atb":[[1.8,2]],"id":65460404}],"con":true,"img":false}]}
{"op":"mcm","clk":"11450499573","pt":1717322740871,"mc":[{"id":"1.229554924","rc":[{"atb":[[1.73,0],[1.42,0]],"id":52671121},{"atb":[[1.93,0]],"id":65460404}],"con":true,"img":false}]}
{"op":"mcm","clk":"11450499725","pt":1717322742567,"mc":[{"id":"1.229554924","rc":[{"atb":[[1.34,44.12]],"id":52671121},{"atb":[[1.54,27.78]],"id":65460404}],"con":true,"img":false}]}
{"op":"mcm","clk":"11450500358","pt":1717322749256,"mc":[{"id":"1.229554924","rc":[{"atb":[[1.34,0],[1.35,42.86]],"id":52671121},{"atb":[[1.54,0],[1.5,30]],"id":65460404}],"con":true,"img":false}]}
{"op":"mcm","clk":"11450500413","pt":1717322749880,"mc":[{"id":"1.229554924","rc":[{"atb":[[1.72,10.89],[1.62,12.65]],"id":52671121},{"atb":[[1.98,8],[1.88,8.92]],"id":65460404}],"con":true,"img":false}]}
{"op":"mcm","clk":"11450500422","pt":1717322749992,"mc":[{"id":"1.229554924","rc":[{"atl":[[2.22,0],[2.16,2]],"id":52671121},{"atb":[[1.8,0],[1.86,2]],"id":65460404}],"con":true,"img":false}]}
{"op":"mcm","clk":"11450500449","pt":1717322750303,"mc":[{"id":"1.229554924","rc":[{"atb":[[1.73,2],[1.63,0]],"id":52671121},{"atb":[[1.86,0],[1.93,2]],"id":65460404}],"con":true,"img":false}]}
{"op":"mcm","clk":"11450500675","pt":1717322752852,"mc":[{"id":"1.229554924","rc":[{"atb":[[1.32,46.87],[1.42,68.97]],"id":52671121}],"con":true,"img":false}]}
{"op":"mcm","clk":"11450501276","pt":1717322759598,"mc":[{"id":"1.229554924","rc":[{"atb":[[1.32,0],[1.35,0]],"id":52671121}],"con":true,"img":false}]}
{"op":"mcm","clk":"11450501296","pt":1717322759805,"mc":[{"id":"1.229554924","rc":[{"atl":[[2.64,9.15],[2.7,0]],"id":65460404}],"con":true,"img":false}]}
{"op":"mcm","clk":"11450501751","pt":1717322764106,"mc":[{"id":"1.229554924","rc":[{"atl":[[2.64,0],[2.7,8.82]],"id":65460404}],"con":true,"img":false}]}
{"op":"mcm","clk":"11450501898","pt":1717322765469,"mc":[{"id":"1.229554924","rc":[{"atb":[[1.5,0],[1.49,0]],"id":65460404}],"con":true,"img":false}]}
{"op":"mcm","clk":"11450502728","pt":1717322774011,"mc":[{"id":"1.229554924","rc":[{"atl":[[2.2,2],[2.16,0]],"id":52671121}],"con":true,"img":false}]}
{"op":"mcm","clk":"11450504695","pt":1717322794946,"mc":[{"id":"1.229554924","rc":[{"atl":[[2.18,2],[2.2,0]],"id":52671121}],"con":true,"img":false}]}
{"op":"mcm","clk":"11450505048","pt":1717322798551,"mc":[{"id":"1.229554924","rc":[{"atl":[[2.88,34.57],[2.68,0]],"id":52671121}],"con":true,"img":false}]}
{"op":"mcm","clk":"11450510003","pt":1717322852883,"mc":[{"id":"1.229554924","rc":[{"atb":[[1.73,0]],"id":52671121},{"atl":[[2.18,0]],"id":52671121},{"atb":[[1.93,0]],"id":65460404},{"atl":[[2.5,0]],"id":65460404}],"con":true,"img":false}]}
{"op":"mcm","clk":"11450518072","pt":1717322928564,"mc":[{"id":"1.229554924","rc":[{"atb":[[1.72,0],[1.62,0]],"id":52671121},{"atb":[[1.98,0],[1.88,0]],"id":65460404}],"con":true,"img":false}]}
{"op":"mcm","clk":"11450518091","pt":1717322928777,"mc":[{"id":"1.229554924","rc":[{"atb":[[1.27,230.53],[1.42,0]],"id":52671121},{"atb":[[1.45,288.89],[1.52,0]],"id":65460404}],"con":true,"img":false}]}
{"op":"mcm","clk":"11450518150","pt":1717322929459,"mc":[{"id":"1.229554924","rc":[{"atb":[[1.35,42.86]],"id":52671121},{"atb":[[1.5,30]],"id":65460404}],"con":true,"img":false}]}
{"op":"mcm","clk":"11450518313","pt":1717322931280,"mc":[{"id":"1.229554924","rc":[{"atb":[[1.32,46.87],[1.35,0]],"id":52671121},{"atl":[[2.88,0],[3.5,37.88]],"id":52671121},{"atb":[[1.49,30.61]],"id":65460404},{"atl":[[4,22.98]],"id":65460404}],"con":true,"img":false}]}
{"op":"mcm","clk":"11450518325","pt":1717322931386,"mc":[{"id":"1.229554924","rc":[{"atb":[[1.5,0]],"id":65460404},{"atl":[[3.1,0]],"id":65460404}],"con":true,"img":false}]}
{"op":"mcm","clk":"11450518839","pt":1717322936468,"mc":[{"id":"1.229554924","rc":[{"atb":[[1.35,42.86]],"id":52671121},{"atb":[[1.5,30]],"id":65460404}],"con":true,"img":false}]}
{"op":"mcm","clk":"11450518878","pt":1717322936778,"mc":[{"id":"1.229554924","rc":[{"atb":[[1.35,0]],"id":52671121},{"atb":[[1.5,0]],"id":65460404}],"con":true,"img":false}]}
{"op":"mcm","clk":"11450519507","pt":1717322942496,"mc":[{"id":"1.229554924","rc":[{"atb":[[1.72,10.89],[1.62,12.65]],"id":52671121},{"atb":[[1.98,8],[1.88,8.92]],"id":65460404}],"con":true,"img":false}]}
{"op":"mcm","clk":"11450519521","pt":1717322942702,"mc":[{"id":"1.229554924","rc":[{"atb":[[1.27,92.59],[1.38,68.97]],"id":52671121},{"atl":[[2.88,34.57],[3.5,0]],"id":52671121},{"atl":[[4,0],[3.3,22.85]],"id":65460404}],"con":true,"img":false}]}
{"op":"mcm","clk":"11450522855","pt":1717322976694,"mc":[{"id":"1.229554924","rc":[{"atl":[[2.66,9.04],[2.7,0]],"id":65460404}],"con":true,"img":false}]}
{"op":"mcm","clk":"11450529782","pt":1717323047056,"mc":[{"id":"1.229554924","rc":[{"atb":[[1.72,0],[1.62,0]],"id":52671121},{"atb":[[1.98,0],[1.88,0]],"id":65460404}],"con":true,"img":false}]}
{"op":"mcm","clk":"11450529793","pt":1717323047162,"mc":[{"id":"1.229554924","rc":[{"atb":[[1.29,184.81],[1.38,0]],"id":52671121}],"con":true,"img":false}]}
{"op":"mcm","clk":"11450530290","pt":1717323052279,"mc":[{"id":"1.229554924","rc":[{"atb":[[1.27,324.27],[1.29,68.97]],"id":52671121}],"con":true,"img":false}]}
{"op":"mcm","clk":"11450530371","pt":1717323053065,"mc":[{"id":"1.229554924","rc":[{"atb":[[1.34,44.12]],"id":52671121},{"atl":[[2.88,0],[3.5,37.88]],"id":52671121},{"atl":[[4,22.98],[3.3,0]],"id":65460404}],"con":true,"img":false}]}
{"op":"mcm","clk":"11450530423","pt":1717323053493,"mc":[{"id":"1.229554924","rc":[{"atb":[[1.72,10.89],[1.62,12.65]],"id":52671121},{"atb":[[1.98,8],[1.88,8.92]],"id":65460404}],"con":true,"img":false}]}
{"op":"mcm","clk":"11450531134","pt":1717323061308,"mc":[{"id":"1.229554924","rc":[{"atb":[[1.27,92.59],[1.38,46.87]],"id":52671121}],"con":true,"img":false}]}
{"op":"mcm","clk":"11450531229","pt":1717323062102,"mc":[{"id":"1.229554924","rc":[{"atl":[[2.88,34.57],[3.5,0]],"id":52671121},{"atl":[[4,0],[3.3,22.85]],"id":65460404}],"con":true,"img":false}]}
{"op":"mcm","clk":"11450535985","pt":1717323108737,"mc":[{"id":"1.229554924","rc":[{"atb":[[1.32,0],[1.34,0]],"id":52671121}],"con":true,"img":false}]}
{"op":"mcm","clk":"11450539313","pt":1717323141456,"mc":[{"id":"1.229554924","rc":[{"atb":[[1.72,0],[1.62,0]],"id":52671121},{"atb":[[1.98,0],[1.88,0]],"id":65460404}],"con":true,"img":false}]}
{"op":"mcm","clk":"11450539363","pt":1717323141882,"mc":[{"id":"1.229554924","rc":[{"atb":[[1.27,211.35],[1.38,0]],"id":52671121}],"con":true,"img":false}]}
{"op":"mcm","clk":"11450539403","pt":1717323142156,"mc":[{"id":"1.229554924","rc":[{"atb":[[1.32,46.87]],"id":52671121},{"atl":[[2.88,0],[3.5,37.88]],"id":52671121},{"atl":[[4,22.98],[3.3,0]],"id":65460404}],"con":true,"img":false}]}
{"op":"mcm","clk":"11450540549","pt":1717323152183,"mc":[{"id":"1.229554924","rc":[{"atb":[[1.47,42.55]],"id":65460404}],"con":true,"img":false}]}
{"op":"mcm","clk":"11450540628","pt":1717323152918,"mc":[{"id":"1.229554924","rc":[{"atb":[[1.72,10.89],[1.62,12.65]],"id":52671121},{"atb":[[1.98,8],[1.88,8.92]],"id":65460404}],"con":true,"img":false}]}
{"op":"mcm","clk":"11450540660","pt":1717323153080,"mc":[{"id":"1.229554924","rc":[{"atb":[[1.27,92.59],[1.38,68.97]],"id":52671121}],"con":true,"img":false}]}
{"op":"mcm","clk":"11450541126","pt":1717323157103,"mc":[{"id":"1.229554924","rc":[{"atl":[[2.88,34.57],[3.5,0]],"id":52671121},{"atl":[[4,0],[3.3,22.85]],"id":65460404}],"con":true,"img":false}]}
{"op":"mcm","clk":"11450548262","pt":1717323222151,"mc":[{"id":"1.229554924","rc":[{"atb":[[1.72,0],[1.62,0]],"id":52671121},{"atb":[[1.98,0],[1.88,0]],"id":65460404}],"con":true,"img":false}]}
{"op":"mcm","clk":"11450548286","pt":1717323222307,"mc":[{"id":"1.229554924","rc":[{"atb":[[1.29,184.81],[1.38,0]],"id":52671121}],"con":true,"img":false}]}
{"op":"mcm","clk":"11450548300","pt":1717323222414,"mc":[{"id":"1.229554924","rc":[{"atl":[[2.88,0],[3.5,37.88]],"id":52671121},{"atl":[[4,22.98]],"id":65460404}],"con":true,"img":false}]}
{"op":"mcm","clk":"11450548314","pt":1717323222520,"mc":[{"id":"1.229554924","rc":[{"atl":[[3.3,0]],"id":65460404}],"con":true,"img":false}]}
{"op":"mcm","clk":"11450548871","pt":1717323227512,"mc":[{"id":"1.229554924","rc":[{"atb":[[1.27,324.27],[1.29,68.97]],"id":52671121}],"con":true,"img":false}]}
{"op":"mcm","clk":"11450549629","pt":1717323234137,"mc":[{"id":"1.229554924","rc":[{"atb":[[1.72,10.89],[1.62,12.65]],"id":52671121},{"atb":[[1.98,8],[1.88,8.92]],"id":65460404}],"con":true,"img":false}]}
{"op":"mcm","clk":"11450549642","pt":1717323234244,"mc":[{"id":"1.229554924","rc":[{"atb":[[1.27,92.59],[1.38,68.97]],"id":52671121}],"con":true,"img":false}]}
{"op":"mcm","clk":"11450549656","pt":1717323234354,"mc":[{"id":"1.229554924","rc":[{"atl":[[2.88,34.57],[3.5,0]],"id":52671121},{"atl":[[4,0],[3.3,22.85]],"id":65460404}],"con":true,"img":false}]}
{"op":"mcm","clk":"11450555692","pt":1717323289444,"mc":[{"id":"1.229554924","rc":[{"atb":[[1.73,2]],"id":52671121},{"atl":[[2.88,0],[2.2,2],[2.7,34.57]],"id":52671121},{"atb":[[1.45,66.67],[1.51,42.55],[1.93,2]],"id":65460404},{"atl":[[2.5,2]],"id":65460404}],"con":true,"img":false}]}
{"op":"mcm","clk":"11450555715","pt":1717323289606,"mc":[{"id":"1.229554924","rc":[{"atl":[[2.18,2],[2.2,0]],"id":52671121},{"atb":[[1.96,2],[1.93,0]],"id":65460404}],"con":true,"img":false}]}
{"op":"mcm","clk":"11450556477","pt":1717323296822,"mc":[{"id":"1.229554924","rc":[{"atl":[[2.52,2]],"id":65460404}],"con":true,"img":false}]}
{"op":"mcm","clk":"11450556487","pt":1717323296926,"mc":[{"id":"1.229554924","rc":[{"atl":[[2.5,0]],"id":65460404}],"con":true,"img":false}]}
{"op":"mcm","clk":"11450558168","pt":1717323312118,"mc":[{"id":"1.229554924","rc":[{"atl":[[2.5,2],[2.52,0]],"id":65460404}],"con":true,"img":false}]}
{"op":"mcm","clk":"11450559098","pt":1717323320765,"mc":[{"id":"1.229554924","rc":[{"atl":[[2.5,0],[2.52,2]],"id":65460404}],"con":true,"img":false}]}
{"op":"mcm","clk":"11450561728","pt":1717323343674,"mc":[{"id":"1.229554924","rc":[{"atb":[[1.72,0],[1.62,0]],"id":52671121},{"atb":[[1.98,0],[1.88,0]],"id":65460404}],"con":true,"img":false}]}
{"op":"mcm","clk":"11450561742","pt":1717323343776,"mc":[{"id":"1.229554924","rc":[{"atb":[[1.73,0],[1.62,2],[1.38,0]],"id":52671121},{"atb":[[1.85,2],[1.96,0]],"id":65460404}],"con":true,"img":false}]}
{"op":"mcm","clk":"11450561754","pt":1717323343875,"mc":[{"id":"1.229554924","rc":[{"atb":[[1.32,117.84]],"id":52671121}],"con":true,"img":false}]}
{"op":"mcm","clk":"11450561831","pt":1717323344501,"mc":[{"id":"1.229554924","rc":[{"atb":[[1.34,44.12]],"id":52671121}],"con":true,"img":false}]}
{"op":"mcm","clk":"11450561884","pt":1717323344874,"mc":[{"id":"1.229554924","rc":[{"atb":[[1.34,0]],"id":52671121}],"con":true,"img":false}]}
{"op":"mcm","clk":"11450561962","pt":1717323345497,"mc":[{"id":"1.229554924","rc":[{"atb":[[1.84,2],[1.85,0]],"id":65460404}],"con":true,"img":false}]}
{"op":"mcm","clk":"11450562113","pt":1717323346863,"mc":[{"id":"1.229554924","rc":[{"atb":[[1.34,44.12]],"id":52671121}],"con":true,"img":false}]}
{"op":"mcm","clk":"11450562249","pt":1717323348185,"mc":[{"id":"1.229554924","rc":[{"atb":[[1.34,0]],"id":52671121}],"con":true,"img":false}]}
{"op":"mcm","clk":"11450562841","pt":1717323353809,"mc":[{"id":"1.229554924","rc":[{"atb":[[1.45,55.56]],"id":65460404}],"con":true,"img":false}]}
{"op":"mcm","clk":"11450563440","pt":1717323359137,"mc":[{"id":"1.229554924","rc":[{"atb":[[1.72,10.89],[1.62,14.65]],"id":52671121},{"atb":[[1.98,8],[1.88,8.92]],"id":65460404}],"con":true,"img":false}]}
{"op":"mcm","clk":"11450563464","pt":1717323359340,"mc":[{"id":"1.229554924","rc":[{"atb":[[1.73,2],[1.41,92.59],[1.62,12.65],[1.32,46.87]],"id":52671121},{"atb":[[1.84,0],[1.96,2]],"id":65460404}],"con":true,"img":false}]}
{"op":"mcm","clk":"11450564954","pt":1717323372116,"mc":[{"id":"1.229554924","rc":[{"atb":[[1.73,0]],"id":52671121},{"atl":[[2.18,0]],"id":52671121},{"atb":[[1.96,0]],"id":65460404},{"atl":[[2.52,0]],"id":65460404}],"con":true,"img":false}]}
{"op":"mcm","clk":"11450565187","pt":1717323373841,"mc":[{"id":"1.229554924","rc":[{"atl":[[2.66,0],[2.64,9.15]],"id":65460404}],"con":true,"img":false}]}
{"op":"mcm","clk":"11450565201","pt":1717323373947,"mc":[{"id":"1.229554924","rc":[{"atl":[[2.28,11.72],[2.26,0]],"id":52671121}],"con":true,"img":false}]}
{"op":"mcm","clk":"11450565213","pt":1717323374014,"mc":[{"id":"1.229554924","rc":[{"atl":[[2.3,11.54]],"id":52671121},{"atl":[[2.64,0],[2.68,8.93]],"id":65460404}],"con":true,"img":false}]}
{"op":"mcm","clk":"11450565222","pt":1717323374116,"mc":[{"id":"1.229554924","rc":[{"atl":[[2.28,0]],"id":52671121}],"con":true,"img":false}]}
{"op":"mcm","clk":"11450565233","pt":1717323374213,"mc":[{"id":"1.229554924","rc":[{"atl":[[2.32,11.36]],"id":52671121},{"atl":[[2.68,0],[2.7,8.82]],"id":65460404}],"con":true,"img":false}]}
{"op":"mcm","clk":"11450565250","pt":1717323374373,"mc":[{"id":"1.229554924","rc":[{"atl":[[2.28,11.72]],"id":52671121},{"atl":[[2.66,9.04],[2.7,0]],"id":65460404}],"con":true,"img":false}]}
{"op":"mcm","clk":"11450565294","pt":1717323374742,"mc":[{"id":"1.229554924","rc":[{"atl":[[2.28,0]],"id":52671121},{"atl":[[2.66,0],[2.68,8.93]],"id":65460404}],"con":true,"img":false}]}
{"op":"mcm","clk":"11450565311","pt":1717323374943,"mc":[{"id":"1.229554924","rc":[{"atl":[[2.3,0]],"id":52671121},{"atl":[[2.68,0],[2.7,8.82]],"id":65460404}],"con":true,"img":false}]}
{"op":"mcm","clk":"11450565335","pt":1717323375099,"mc":[{"id":"1.229554924","rc":[{"atl":[[2.26,11.9]],"id":52671121},{"atl":[[2.66,9.04]],"id":65460404}],"con":true,"img":false}]}
{"op":"mcm","clk":"11450565350","pt":1717323375210,"mc":[{"id":"1.229554924","rc":[{"atl":[[2.7,0]],"id":65460404}],"con":true,"img":false}]}
{"op":"mcm","clk":"11450565454","pt":1717323376038,"mc":[{"id":"1.229554924","rc":[{"atl":[[2.66,0],[2.64,9.15]],"id":65460404}],"con":true,"img":false}]}
{"op":"mcm","clk":"11450565486","pt":1717323376256,"mc":[{"id":"1.229554924","rc":[{"atl":[[2.28,11.72],[2.26,0]],"id":52671121},{"atl":[[2.64,0],[2.66,9.04]],"id":65460404}],"con":true,"img":false}]}
{"op":"mcm","clk":"11450565495","pt":1717323376357,"mc":[{"id":"1.229554924","rc":[{"atl":[[2.3,11.54]],"id":52671121},{"atl":[[2.68,8.93]],"id":65460404}],"con":true,"img":false}]}
{"op":"mcm","clk":"11450565523","pt":1717323376520,"mc":[{"id":"1.229554924","rc":[{"atl":[[2.28,0]],"id":52671121},{"atl":[[2.74,0],[2.66,0]],"id":65460404}],"con":true,"img":false}]}
{"op":"mcm","clk":"11450565536","pt":1717323376623,"mc":[{"id":"1.229554924","rc":[{"atl":[[2.72,8.72],[2.68,0]],"id":65460404}],"con":true,"img":false}]}
{"op":"mcm","clk":"11450565548","pt":1717323376727,"mc":[{"id":"1.229554924","rc":[{"atl":[[3.15,22.72],[3.3,0]],"id":65460404}],"con":true,"img":false}]}
{"op":"mcm","clk":"11450565621","pt":1717323377249,"mc":[{"id":"1.229554924","rc":[{"atl":[[2.3,0]],"id":52671121},{"atl":[[2.72,0]],"id":65460404}],"con":true,"img":false}]}
{"op":"mcm","clk":"11450565628","pt":1717323377352,"mc":[{"id":"1.229554924","rc":[{"atl":[[2.74,8.62]],"id":65460404}],"con":true,"img":false}]}
{"op":"mcm","clk":"11450565641","pt":1717323377417,"mc":[{"id":"1.229554924","rc":[{"atb":[[1.41,0],[1.35,68.97]],"id":52671121},{"atl":[[2.28,11.72]],"id":52671121},{"atl":[[2.68,8.93]],"id":65460404}],"con":true,"img":false}]}
{"op":"mcm","clk":"11450565914","pt":1717323379760,"mc":[{"id":"1.229554924","rc":[{"atb":[[1.41,68.97],[1.35,0]],"id":52671121}],"con":true,"img":false}]}
{"op":"mcm","clk":"11450566729","pt":1717323386153,"mc":[{"id":"1.229554924","rc":[{"atl":[[2.32,15.15]],"id":52671121}],"con":true,"img":false}]}
{"op":"mcm","clk":"11450566786","pt":1717323386673,"mc":[{"id":"1.229554924","rc":[{"atl":[[2.26,11.9]],"id":52671121},{"atl":[[2.66,9.04]],"id":65460404}],"con":true,"img":false}]}
{"op":"mcm","clk":"11450566810","pt":1717323386836,"mc":[{"id":"1.229554924","rc":[{"atl":[[2.3,11.54],[2.26,0]],"id":52671121},{"atl":[[2.72,8.72],[2.66,0]],"id":65460404}],"con":true,"img":false}]}
{"op":"mcm","clk":"11450567162","pt":1717323389962,"mc":[{"id":"1.229554924","rc":[{"atl":[[2.32,11.36],[2.28,0]],"id":52671121},{"atl":[[2.68,0]],"id":65460404}],"con":true,"img":false}]}
{"op":"mcm","clk":"11450567292","pt":1717323391175,"mc":[{"id":"1.229554924","rc":[{"atl":[[2.3,0],[2.34,11.19]],"id":52671121},{"atl":[[2.72,0],[2.76,8.52]],"id":65460404}],"con":true,"img":false}]}
{"op":"mcm","clk":"11450567311","pt":1717323391385,"mc":[{"id":"1.229554924","rc":[{"atb":[[1.41,0],[1.35,68.97]],"id":52671121},{"atl":[[2.3,11.54]],"id":52671121},{"atl":[[2.7,8.82]],"id":65460404}],"con":true,"img":false}]}
{"op":"mcm","clk":"11450567338","pt":1717323391557,"mc":[{"id":"1.229554924","rc":[{"atl":[[2.3,0],[2.28,11.72]],"id":52671121},{"atl":[[2.68,8.93]],"id":65460404}],"con":true,"img":false}]}
{"op":"mcm","clk":"11450567362","pt":1717323391859,"mc":[{"id":"1.229554924","rc":[{"atl":[[2.28,0]],"id":52671121},{"atl":[[2.68,0]],"id":65460404}],"con":true,"img":false}]}
{"op":"mcm","clk":"11450567418","pt":1717323392385,"mc":[{"id":"1.229554924","rc":[{"atl":[[2.7,0]],"id":65460404}],"con":true,"img":false}]}
{"op":"mcm","clk":"11450567443","pt":1717323392600,"mc":[{"id":"1.229554924","rc":[{"atb":[[1.72,12.89]],"id":52671121},{"atl":[[2.18,2]],"id":52671121},{"atb":[[1.96,2]],"id":65460404},{"atl":[[2.54,2]],"id":65460404}],"con":true,"img":false}]}
{"op":"mcm","clk":"11450567667","pt":1717323394383,"mc":[{"id":"1.229554924","rc":[{"atl":[[2.32,0],[2.3,11.54]],"id":52671121},{"atl":[[2.74,0]],"id":65460404}],"con":true,"img":false}]}
{"op":"mcm","clk":"11450567679","pt":1717323394488,"mc":[{"id":"1.229554924","rc":[{"atl":[[2.28,11.72]],"id":52671121}],"con":true,"img":false}]}
{"op":"mcm","clk":"11450567691","pt":1717323394543,"mc":[{"id":"1.229554924","rc":[{"atl":[[2.74,8.62]],"id":65460404}],"con":true,"img":false}]}
{"op":"mcm","clk":"11450567967","pt":1717323396944,"mc":[{"id":"1.229554924","rc":[{"atb":[[1.4,68.97],[1.35,0]],"id":52671121}],"con":true,"img":false}]}
{"op":"mcm","clk":"11450568057","pt":1717323397673,"mc":[{"id":"1.229554924","rc":[{"atb":[[1.97,2],[1.96,0]],"id":65460404}],"con":true,"img":false}]}
{"op":"mcm","clk":"11450568308","pt":1717323399572,"mc":[{"id":"1.229554924","rc":[{"atl":[[2.24,12.1],[2.28,0],[2.26,11.9]],"id":52671121},{"atl":[[2.7,8.82]],"id":65460404}],"con":true,"img":false}]}
{"op":"mcm","clk":"11450568331","pt":1717323399776,"mc":[{"id":"1.229554924","rc":[{"atl":[[2.24,0],[2.36,0],[2.26,0]],"id":52671121},{"atl":[[2.7,0]],"id":65460404}],"con":true,"img":false}]}
{"op":"mcm","clk":"11450568437","pt":1717323400565,"mc":[{"id":"1.229554924","rc":[{"atl":[[2.74,0]],"id":65460404}],"con":true,"img":false}]}
{"op":"mcm","clk":"11450568457","pt":1717323400778,"mc":[{"id":"1.229554924","rc":[{"atl":[[2.26,11.9]],"id":52671121},{"atl":[[2.7,8.82]],"id":65460404}],"con":true,"img":false}]}
{"op":"mcm","clk":"11450568579","pt":1717323401608,"mc":[{"id":"1.229554924","rc":[{"atl":[[2.26,0]],"id":52671121},{"atl":[[2.7,0]],"id":65460404}],"con":true,"img":false}]}
{"op":"mcm","clk":"11450568598","pt":1717323401817,"mc":[{"id":"1.229554924","rc":[{"atl":[[2.26,11.9]],"id":52671121},{"atl":[[2.7,8.82]],"id":65460404}],"con":true,"img":false}]}
{"op":"mcm","clk":"11450568645","pt":1717323402287,"mc":[{"id":"1.229554924","rc":[{"atl":[[2.26,0]],"id":52671121},{"atl":[[2.7,0]],"id":65460404}],"con":true,"img":false}]}
{"op":"mcm","clk":"11450569006","pt":1717323404777,"mc":[{"id":"1.229554924","rc":[{"atl":[[2.28,11.72]],"id":52671121},{"atl":[[2.74,8.62]],"id":65460404}],"con":true,"img":false}]}
{"op":"mcm","clk":"11450569031","pt":1717323404977,"mc":[{"id":"1.229554924","rc":[{"atl":[[2.68,8.93]],"id":65460404}],"con":true,"img":false}]}
{"op":"mcm","clk":"11450569194","pt":1717323406283,"mc":[{"id":"1.229554924","rc":[{"atl":[[2.26,11.9]],"id":52671121},{"atl":[[2.66,9.04]],"id":65460404}],"con":true,"img":false}]}
{"op":"mcm","clk":"11450569260","pt":1717323406876,"mc":[{"id":"1.229554924","rc":[{"atl":[[2.18,0],[2.16,2]],"id":52671121}],"con":true,"img":false}]}
{"op":"mcm","clk":"11450569368","pt":1717323407763,"mc":[{"id":"1.229554924","rc":[{"atl":[[2.64,9.15]],"id":65460404}],"con":true,"img":false}]}
{"op":"mcm","clk":"11450569379","pt":1717323407861,"mc":[{"id":"1.229554924","rc":[{"atl":[[2.66,0]],"id":65460404}],"con":true,"img":false}]}
{"op":"mcm","clk":"11450569394","pt":1717323407969,"mc":[{"id":"1.229554924","rc":[{"atl":[[2.26,0]],"id":52671121},{"atl":[[2.74,0],[2.64,0]],"id":65460404}],"con":true,"img":false}]}
{"op":"mcm","clk":"11450569902","pt":1717323412043,"mc":[{"id":"1.229554924","rc":[{"atl":[[2.18,2],[2.16,0]],"id":52671121}],"con":true,"img":false}]}
{"op":"mcm","clk":"11450569915","pt":1717323412149,"mc":[{"id":"1.229554924","rc":[{"atl":[[2.28,0]],"id":52671121}],"con":true,"img":false}]}
{"op":"mcm","clk":"11450570204","pt":1717323414345,"mc":[{"id":"1.229554924","rc":[{"atl":[[2.3,0],[2.32,11.36]],"id":52671121},{"atl":[[2.68,0],[2.7,8.82]],"id":65460404}],"con":true,"img":false}]}
{"op":"mcm","clk":"11450570436","pt":1717323416222,"mc":[{"id":"1.229554924","rc":[{"atl":[[2.72,8.72],[2.7,0]],"id":65460404}],"con":true,"img":false}]}
{"op":"mcm","clk":"11450570791","pt":1717323419551,"mc":[{"id":"1.229554924","rc":[{"atb":[[1.72,2],[1.62,0]],"id":52671121},{"atb":[[1.98,0],[1.88,0]],"id":65460404}],"con":true,"img":false}]}
{"op":"mcm","clk":"11450570800","pt":1717323419654,"mc":[{"id":"1.229554924","rc":[{"atl":[[2.7,8.82]],"id":65460404}],"con":true,"img":false}]}
{"op":"mcm","clk":"11450570837","pt":1717323419968,"mc":[{"id":"1.229554924","rc":[{"atb":[[1.4,0],[1.72,0],[1.32,117.84],[1.61,2]],"id":52671121},{"atb":[[1.97,0],[1.85,2]],"id":65460404}],"con":true,"img":false}]}
{"op":"mcm","clk":"11450570853","pt":1717323420128,"mc":[{"id":"1.229554924","rc":[{"atb":[[1.4,92.59]],"id":52671121}],"con":true,"img":false}]}
{"op":"mcm","clk":"11450570862","pt":1717323420283,"mc":[{"id":"1.229554924","rc":[{"atb":[[1.32,46.87]],"id":52671121}],"con":true,"img":false}]}
{"op":"mcm","clk":"11450571124","pt":1717323422433,"mc":[{"id":"1.229554924","rc":[{"atb":[[1.34,44.12]],"id":52671121},{"atl":[[2.3,11.54]],"id":52671121}],"con":true,"img":false}]}
{"op":"mcm","clk":"11450571382","pt":1717323424679,"mc":[{"id":"1.229554924","rc":[{"atb":[[1.72,10.89],[1.62,12.65]],"id":52671121},{"atb":[[1.98,8],[1.88,8.92]],"id":65460404}],"con":true,"img":false}]}
{"op":"mcm","clk":"11450571395","pt":1717323424739,"mc":[{"id":"1.229554924","rc":[{"atb":[[1.72,12.89]],"id":52671121},{"atb":[[1.97,2]],"id":65460404}],"con":true,"img":false}]}
{"op":"mcm","clk":"11450571408","pt":1717323424838,"mc":[{"id":"1.229554924","rc":[{"atb":[[1.61,0]],"id":52671121},{"atb":[[1.85,0]],"id":65460404}],"con":true,"img":false}]}
{"op":"mcm","clk":"11450571485","pt":1717323425472,"mc":[{"id":"1.229554924","rc":[{"atl":[[2.18,0],[2.16,2]],"id":52671121},{"atl":[[2.68,8.93]],"id":65460404}],"con":true,"img":false}]}
{"op":"mcm","clk":"11450571536","pt":1717323425843,"mc":[{"id":"1.229554924","rc":[{"atl":[[2.18,2],[2.16,0]],"id":52671121}],"con":true,"img":false}]}
{"op":"mcm","clk":"11450572090","pt":1717323430479,"mc":[{"id":"1.229554924","rc":[{"atl":[[2.34,14.93]],"id":52671121}],"con":true,"img":false}]}
{"op":"mcm","clk":"11450572564","pt":1717323434358,"mc":[{"id":"1.229554924","rc":[{"atl":[[2.56,2],[2.54,0]],"id":65460404}],"con":true,"img":false}]}
{"op":"mcm","clk":"11450572579","pt":1717323434473,"mc":[{"id":"1.229554924","rc":[{"atb":[[1.72,2],[1.62,0]],"id":52671121},{"atb":[[1.98,0],[1.88,0]],"id":65460404}],"con":true,"img":false}]}
{"op":"mcm","clk":"11450572609","pt":1717323434677,"mc":[{"id":"1.229554924","rc":[{"atb":[[1.4,0],[1.72,0],[1.6,2],[1.34,138.71]],"id":52671121},{"atb":[[1.97,0],[1.84,2]],"id":65460404}],"con":true,"img":false}]}
{"op":"mcm","clk":"11450572624","pt":1717323434782,"mc":[{"id":"1.229554924","rc":[{"atb":[[1.4,46.87],[1.34,44.12]],"id":52671121}],"con":true,"img":false}]}
{"op":"mcm","clk":"11450572636","pt":1717323434877,"mc":[{"id":"1.229554924","rc":[{"atb":[[1.4,0],[1.32,187.58]],"id":52671121}],"con":true,"img":false}]}
{"op":"mcm","clk":"11450572829","pt":1717323436302,"mc":[{"id":"1.229554924","rc":[{"atb":[[1.34,0],[1.35,42.86]],"id":52671121},{"atb":[[1.51,71.96],[1.52,28.85]],"id":65460404}],"con":true,"img":false}]}
{"op":"mcm","clk":"11450572865","pt":1717323436557,"mc":[{"id":"1.229554924","rc":[{"atl":[[2.24,12.1]],"id":52671121},{"atb":[[1.45,0]],"id":65460404},{"atl":[[2.64,9.15],[2.68,0]],"id":65460404}],"con":true,"img":false}]}
{"op":"mcm","clk":"11450572879","pt":1717323436661,"mc":[{"id":"1.229554924","rc":[{"atb":[[1.37,40.54],[1.35,0]],"id":52671121}],"con":true,"img":false}]}
{"op":"mcm","clk":"11450572891","pt":1717323436765,"mc":[{"id":"1.229554924","rc":[{"atb":[[1.52,0]],"id":65460404}],"con":true,"img":false}]}
{"op":"mcm","clk":"11450572904","pt":1717323436865,"mc":[{"id":"1.229554924","rc":[{"atb":[[1.32,46.87],[1.38,68.97]],"id":52671121}],"con":true,"img":false}]}
{"op":"mcm","clk":"11450573143","pt":1717323438794,"mc":[{"id":"1.229554924","rc":[{"atb":[[1.37,0],[1.38,108.44]],"id":52671121},{"atl":[[2.24,0],[2.28,11.72]],"id":52671121},{"atb":[[1.52,28.85]],"id":65460404},{"atl":[[2.64,0],[2.66,9.04]],"id":65460404}],"con":true,"img":false}]}
{"op":"mcm","clk":"11450573195","pt":1717323439166,"mc":[{"id":"1.229554924","rc":[{"atl":[[2.18,0],[2.2,2]],"id":52671121},{"atb":[[1.83,2],[1.84,0]],"id":65460404}],"con":true,"img":false}]}
{"op":"mcm","clk":"11450573250","pt":1717323439685,"mc":[{"id":"1.229554924","rc":[{"atb":[[1.72,10.89],[1.62,12.65]],"id":52671121},{"atb":[[1.98,8],[1.88,8.92]],"id":65460404}],"con":true,"img":false}]}
{"op":"mcm","clk":"11450573263","pt":1717323439791,"mc":[{"id":"1.229554924","rc":[{"atb":[[1.72,12.89],[1.6,0]],"id":52671121},{"atb":[[1.83,0],[1.97,2]],"id":65460404}],"con":true,"img":false}]}
{"op":"mcm","clk":"11450575259","pt":1717323455676,"mc":[{"id":"1.229554924","rc":[{"atb":[[1.72,2],[1.62,0]],"id":52671121},{"atb":[[1.98,0],[1.88,0]],"id":65460404}],"con":true,"img":false}]}
{"op":"mcm","clk":"11450575269","pt":1717323455776,"mc":[{"id":"1.229554924","rc":[{"atb":[[1.72,0],[1.6,2],[1.32,157.31],[1.38,39.47]],"id":52671121},{"atb":[[1.83,2],[1.97,0]],"id":65460404}],"con":true,"img":false}]}
{"op":"mcm","clk":"11450575633","pt":1717323458781,"mc":[{"id":"1.229554924","rc":[{"atl":[[2.18,2]],"id":52671121}],"con":true,"img":false}]}
{"op":"mcm","clk":"11450575640","pt":1717323458886,"mc":[{"id":"1.229554924","rc":[{"atl":[[2.2,0]],"id":52671121}],"con":true,"img":false}]}
{"op":"mcm","clk":"11450575672","pt":1717323459203,"mc":[{"id":"1.229554924","rc":[{"atl":[[2.56,0],[2.54,2]],"id":65460404}],"con":true,"img":false}]}
{"op":"mcm","clk":"11450575734","pt":1717323459778,"mc":[{"id":"1.229554924","rc":[{"atb":[[1.6,0]],"id":52671121},{"atl":[[2.18,0]],"id":52671121},{"atb":[[1.83,0]],"id":65460404},{"atl":[[2.54,0]],"id":65460404}],"con":true,"img":false}]}
{"op":"mcm","clk":"11450575748","pt":1717323459887,"mc":[{"id":"1.229554924","rc":[{"atb":[[1.38,0],[1.35,42.86]],"id":52671121},{"atb":[[1.49,131.42],[1.51,29.41],[1.53,28.3],[1.52,0]],"id":65460404}],"con":true,"img":false}]}
{"op":"mcm","clk":"11450575783","pt":1717323460201,"mc":[{"id":"1.229554924","rc":[{"atb":[[1.38,39.47]],"id":52671121},{"atl":[[3.25,23.44],[2.7,0]],"id":52671121},{"atl":[[3.85,17.64],[3.15,0]],"id":65460404}],"con":true,"img":false}]}
{"op":"mcm","clk":"11450575798","pt":1717323460306,"mc":[{"id":"1.229554924","rc":[{"atb":[[1.35,0]],"id":52671121},{"atb":[[1.53,0],[1.52,28.85]],"id":65460404}],"con":true,"img":false}]}
{"op":"mcm","clk":"11450576208","pt":1717323463719,"mc":[{"id":"1.229554924","rc":[{"atb":[[1.38,0],[1.35,42.86]],"id":52671121},{"atb":[[1.53,28.3],[1.52,0]],"id":65460404}],"con":true,"img":false}]}
{"op":"mcm","clk":"11450576234","pt":1717323463920,"mc":[{"id":"1.229554924","rc":[{"atb":[[1.32,46.87],[1.29,269.14]],"id":52671121}],"con":true,"img":false}]}
{"op":"mcm","clk":"11450576286","pt":1717323464337,"mc":[{"id":"1.229554924","rc":[{"atb":[[1.72,10.89],[1.62,12.65]],"id":52671121},{"atb":[[1.98,8],[1.88,8.92]],"id":65460404}],"con":true,"img":false}]}
{"op":"mcm","clk":"11450576299","pt":1717323464404,"mc":[{"id":"1.229554924","rc":[{"atb":[[1.4,46.87],[1.29,68.97]],"id":52671121}],"con":true,"img":false}]}
{"op":"mcm","clk":"11450576366","pt":1717323465020,"mc":[{"id":"1.229554924","rc":[{"atb":[[1.54,29.41],[1.49,30.61]],"id":65460404}],"con":true,"img":false}]}
{"op":"mcm","clk":"11450576476","pt":1717323465914,"mc":[{"id":"1.229554924","rc":[{"atl":[[3.25,0],[2.68,23.26]],"id":52671121},{"atl":[[3.85,0],[3.15,17.54]],"id":65460404}],"con":true,"img":false}]}
{"op":"mcm","clk":"11450578440","pt":1717323484022,"mc":[{"id":"1.229554924","rc":[{"atl":[[2.66,0],[2.68,8.93]],"id":65460404}],"con":true,"img":false}]}
{"op":"mcm","clk":"11450578461","pt":1717323484122,"mc":[{"id":"1.229554924","rc":[{"atb":[[1.73,5.05]],"id":52671121},{"atl":[[2.28,0],[2.26,4.35]],"id":52671121},{"atb":[[1.89,4.42]],"id":65460404},{"atl":[[2.66,3.86]],"id":65460404}],"con":true,"img":false}]}
{"op":"mcm","clk":"11450579216","pt":1717323491022,"mc":[{"id":"1.229554924","rc":[{"atl":[[2.38,18.12]],"id":52671121}],"con":true,"img":false}]}
{"op":"mcm","clk":"11450579795","pt":1717323496467,"mc":[{"id":"1.229554924","rc":[{"atb":[[1.53,0]],"id":65460404}],"con":true,"img":false}]}
{"op":"mcm","clk":"11450580281","pt":1717323500855,"mc":[{"id":"1.229554924","rc":[{"atl":[[2.3,0],[2.28,11.72]],"id":52671121},{"atl":[[2.66,12.9],[2.68,0]],"id":65460404}],"con":true,"img":false}]}
{"op":"mcm","clk":"11450581485","pt":1717323512660,"mc":[{"id":"1.229554924","rc":[{"atl":[[2.82,26.65],[2.68,0]],"id":52671121}],"con":true,"img":false}]}
{"op":"mcm","clk":"11450581708","pt":1717323514957,"mc":[{"id":"1.229554924","rc":[{"atl":[[2.3,11.54],[2.28,0]],"id":52671121},{"atl":[[2.66,3.86],[2.68,8.93]],"id":65460404}],"con":true,"img":false}]}
{"op":"mcm","clk":"11450581744","pt":1717323515272,"mc":[{"id":"1.229554924","rc":[{"atl":[[2.3,0],[2.28,11.72]],"id":52671121},{"atl":[[2.66,12.9],[2.68,0]],"id":65460404}],"con":true,"img":false}]}
{"op":"mcm","clk":"11450581772","pt":1717323515484,"mc":[{"id":"1.229554924","rc":[{"atl":[[2.3,11.54],[2.28,0]],"id":52671121},{"atl":[[2.66,3.86],[2.68,8.93]],"id":65460404}],"con":true,"img":false}]}
{"op":"mcm","clk":"11450581816","pt":1717323515850,"mc":[{"id":"1.229554924","rc":[{"atl":[[2.3,0],[2.28,11.72]],"id":52671121},{"atl":[[2.66,12.9],[2.68,0]],"id":65460404}],"con":true,"img":false}]}
{"op":"mcm","clk":"11450581973","pt":1717323517568,"mc":[{"id":"1.229554924","rc":[{"atb":[[1.72,0],[1.62,0]],"id":52671121},{"atb":[[1.98,0],[1.88,0]],"id":65460404}],"con":true,"img":false}]}
{"op":"mcm","clk":"11450581981","pt":1717323517672,"mc":[{"id":"1.229554924","rc":[{"atl":[[2.3,11.54]],"id":52671121},{"atl":[[2.68,8.93]],"id":65460404}],"con":true,"img":false}]}
{"op":"mcm","clk":"11450581993","pt":1717323517781,"mc":[{"id":"1.229554924","rc":[{"atl":[[2.28,0]],"id":52671121},{"atl":[[2.66,3.86]],"id":65460404}],"con":true,"img":false}]}
{"op":"mcm","clk":"11450582026","pt":1717323518099,"mc":[{"id":"1.229554924","rc":[{"atl":[[2.3,0],[2.28,11.72]],"id":52671121},{"atl":[[2.66,12.9],[2.68,0]],"id":65460404}],"con":true,"img":false}]}
{"op":"mcm","clk":"11450582167","pt":1717323519454,"mc":[{"id":"1.229554924","rc":[{"atl":[[2.3,11.54],[2.28,0]],"id":52671121},{"atl":[[2.66,3.86],[2.68,8.93]],"id":65460404}],"con":true,"img":false}]}
{"op":"mcm","clk":"11450582209","pt":1717323519875,"mc":[{"id":"1.229554924","rc":[{"atl":[[2.3,0],[2.28,11.72]],"id":52671121},{"atl":[[2.66,12.9],[2.68,0]],"id":65460404}],"con":true,"img":false}]}
{"op":"mcm","clk":"11450582281","pt":1717323520599,"mc":[{"id":"1.229554924","rc":[{"atl":[[2.3,11.54],[2.28,0]],"id":52671121},{"atl":[[2.66,3.86],[2.68,8.93]],"id":65460404}],"con":true,"img":false}]}
{"op":"mcm","clk":"11450582445","pt":1717323522278,"mc":[{"id":"1.229554924","rc":[{"atl":[[2.3,0],[2.28,11.72]],"id":52671121},{"atl":[[2.66,12.9],[2.68,0]],"id":65460404}],"con":true,"img":false}]}
{"op":"mcm","clk":"11450582672","pt":1717323524397,"mc":[{"id":"1.229554924","rc":[{"atl":[[2.3,11.54],[2.28,0]],"id":52671121},{"atl":[[2.66,3.86],[2.68,8.93]],"id":65460404}],"con":true,"img":false}]}
{"op":"mcm","clk":"11450582683","pt":1717323524503,"mc":[{"id":"1.229554924","rc":[{"atl":[[2.3,0],[2.28,11.72]],"id":52671121},{"atl":[[2.66,12.9],[2.68,0]],"id":65460404}],"con":true,"img":false}]}
{"op":"mcm","clk":"11450582693","pt":1717323524670,"mc":[{"id":"1.229554924","rc":[{"atb":[[1.72,10.89],[1.62,12.65]],"id":52671121},{"atb":[[1.98,8],[1.88,8.92]],"id":65460404}],"con":true,"img":false}]}
{"op":"mcm","clk":"11450582920","pt":1717323526410,"mc":[{"id":"1.229554924","rc":[{"atl":[[2.24,12.1],[2.3,11.54],[2.28,0]],"id":52671121},{"atl":[[2.66,3.86],[2.64,9.15],[2.68,8.93]],"id":65460404}],"con":true,"img":false}]}
{"op":"mcm","clk":"11450582948","pt":1717323526678,"mc":[{"id":"1.229554924","rc":[{"atl":[[2.24,0],[2.32,0]],"id":52671121},{"atl":[[2.64,0],[2.7,0]],"id":65460404}],"con":true,"img":false}]}
{"op":"mcm","clk":"11450582958","pt":1717323526788,"mc":[{"id":"1.229554924","rc":[{"atl":[[2.72,0],[2.68,0],[2.76,0]],"id":65460404}],"con":true,"img":false}]}
{"op":"mcm","clk":"11450582992","pt":1717323527095,"mc":[{"id":"1.229554924","rc":[{"atl":[[2.24,12.1]],"id":52671121},{"atl":[[2.72,14.53],[2.64,9.15],[2.68,11.9],[2.76,17.05]],"id":65460404}],"con":true,"img":false}]}
{"op":"mcm","clk":"11450583006","pt":1717323527194,"mc":[{"id":"1.229554924","rc":[{"atl":[[2.8,16.67]],"id":65460404}],"con":true,"img":false}]}
{"op":"mcm","clk":"11450583017","pt":1717323527304,"mc":[{"id":"1.229554924","rc":[{"atl":[[2.24,0]],"id":52671121},{"atl":[[2.64,0],[2.68,8.93]],"id":65460404}],"con":true,"img":false}]}
{"op":"mcm","clk":"11450583374","pt":1717323530690,"mc":[{"id":"1.229554924","rc":[{"atl":[[2.24,12.1]],"id":52671121},{"atl":[[2.64,9.15],[2.68,0]],"id":65460404}],"con":true,"img":false}]}
{"op":"mcm","clk":"11450583674","pt":1717323533503,"mc":[{"id":"1.229554924","rc":[{"atl":[[2.24,0]],"id":52671121},{"atl":[[2.64,0],[2.68,8.93]],"id":65460404}],"con":true,"img":false}]}
{"op":"mcm","clk":"11450583684","pt":1717323533608,"mc":[{"id":"1.229554924","rc":[{"atl":[[2.28,11.72]],"id":52671121},{"atl":[[2.66,12.9]],"id":65460404}],"con":true,"img":false}]}
{"op":"mcm","clk":"11450583703","pt":1717323533817,"mc":[{"id":"1.229554924","rc":[{"atl":[[2.8,0],[2.72,0],[2.68,0],[2.76,0]],"id":65460404}],"con":true,"img":false}]}
{"op":"mcm","clk":"11450583823","pt":1717323535091,"mc":[{"id":"1.229554924","rc":[{"atb":[[1.72,0],[1.62,0]],"id":52671121},{"atb":[[1.98,0],[1.88,0]],"id":65460404}],"con":true,"img":false}]}
{"op":"mcm","clk":"11450584230","pt":1717323539717,"mc":[{"id":"1.229554924","rc":[{"atl":[[2.7,11.76]],"id":65460404}],"con":true,"img":false}]}
{"op":"mcm","clk":"11450584564","pt":1717323542926,"mc":[{"id":"1.229554924","rc":[{"atb":[[1.72,10.89],[1.62,12.65]],"id":52671121},{"atb":[[1.98,8],[1.88,8.92]],"id":65460404}],"con":true,"img":false}]}
{"op":"mcm","clk":"11450584843","pt":1717323545709,"mc":[{"id":"1.229554924","rc":[{"atl":[[2.66,3.86],[2.68,8.93]],"id":65460404}],"con":true,"img":false}]}
{"op":"mcm","clk":"11450584937","pt":1717323546817,"mc":[{"id":"1.229554924","rc":[{"atl":[[2.42,21.13],[2.28,0]],"id":52671121}],"con":true,"img":false}]}
{"op":"mcm","clk":"11450585405","pt":1717323551635,"mc":[{"id":"1.229554924","rc":[{"atl":[[2.72,11.63]],"id":65460404}],"con":true,"img":false}]}
{"op":"mcm","clk":"11450585698","pt":1717323554721,"mc":[{"id":"1.229554924","rc":[{"atl":[[2.7,20.58]],"id":65460404}],"con":true,"img":false}]}
{"op":"mcm","clk":"11450585707","pt":1717323554829,"mc":[{"id":"1.229554924","rc":[{"atl":[[2.68,0],[2.7,8.82]],"id":65460404}],"con":true,"img":false}]}
{"op":"mcm","clk":"11450586231","pt":1717323560556,"mc":[{"id":"1.229554924","rc":[{"atl":[[2.74,11.49]],"id":65460404}],"con":true,"img":false}]}
{"op":"mcm","clk":"11450586503","pt":1717323563238,"mc":[{"id":"1.229554924","rc":[{"atl":[[2.68,8.93]],"id":65460404}],"con":true,"img":false}]}
{"op":"mcm","clk":"11450587646","pt":1717323574142,"mc":[{"id":"1.229554924","rc":[{"atl":[[2.68,0]],"id":65460404}],"con":true,"img":false}]}
{"op":"mcm","clk":"11450587739","pt":1717323575181,"mc":[{"id":"1.229554924","rc":[{"atl":[[2.78,14.04]],"id":65460404}],"con":true,"img":false}]}
{"op":"mcm","clk":"11450587773","pt":1717323575448,"mc":[{"id":"1.229554924","rc":[{"atl":[[2.68,8.93],[2.7,0]],"id":65460404}],"con":true,"img":false}]}
{"op":"mcm","clk":"11450587852","pt":1717323576272,"mc":[{"id":"1.229554924","rc":[{"atl":[[2.66,12.9]],"id":65460404}],"con":true,"img":false}]}
{"op":"mcm","clk":"11450587864","pt":1717323576429,"mc":[{"id":"1.229554924","rc":[{"atl":[[2.68,0]],"id":65460404}],"con":true,"img":false}]}
{"op":"mcm","clk":"11450588186","pt":1717323579666,"mc":[{"id":"1.229554924","rc":[{"atl":[[2.3,0],[2.28,11.72]],"id":52671121},{"atl":[[2.66,3.86],[2.64,9.15]],"id":65460404}],"con":true,"img":false}]}
{"op":"mcm","clk":"11450588679","pt":1717323584876,"mc":[{"id":"1.229554924","rc":[{"atl":[[2.3,11.54],[2.28,0]],"id":52671121},{"atl":[[2.66,12.9]],"id":65460404}],"con":true,"img":false}]}
{"op":"mcm","clk":"11450588688","pt":1717323584976,"mc":[{"id":"1.229554924","rc":[{"atl":[[2.64,0]],"id":65460404}],"con":true,"img":false}]}
{"op":"mcm","clk":"11450589050","pt":1717323589158,"mc":[{"id":"1.229554924","rc":[{"atl":[[2.3,0],[2.28,11.72]],"id":52671121},{"atl":[[2.66,3.86],[2.64,9.15]],"id":65460404}],"con":true,"img":false}]}
{"op":"mcm","clk":"11450589102","pt":1717323589673,"mc":[{"id":"1.229554924","rc":[{"atl":[[2.62,3.89]],"id":65460404}],"con":true,"img":false}]}
{"op":"mcm","clk":"11450589427","pt":1717323593255,"mc":[{"id":"1.229554924","rc":[{"atl":[[2.3,11.54]],"id":52671121},{"atl":[[2.66,12.9]],"id":65460404}],"con":true,"img":false}]}
{"op":"mcm","clk":"11450589437","pt":1717323593353,"mc":[{"id":"1.229554924","rc":[{"atl":[[2.28,0]],"id":52671121},{"atl":[[2.64,0]],"id":65460404}],"con":true,"img":false}]}
{"op":"mcm","clk":"11450589497","pt":1717323593976,"mc":[{"id":"1.229554924","rc":[{"atl":[[2.3,0],[2.28,11.72]],"id":52671121},{"atl":[[2.66,3.86],[2.64,9.15]],"id":65460404}],"con":true,"img":false}]}
{"op":"mcm","clk":"11450590471","pt":1717323604404,"mc":[{"id":"1.229554924","rc":[{"atb":[[1.4,0],[1.6,4.71],[1.34,68.97]],"id":52671121},{"atl":[[2.82,0],[2.5,29.86],[2.16,4.71]],"id":52671121},{"atb":[[1.59,29.41],[1.97,4.16],[1.54,0]],"id":65460404},{"atl":[[2.56,4.16],[2.72,0],[2.74,0],[2.64,0],[2.78,0]],"id":65460404}],"con":true,"img":false}]}
{"op":"mcm","clk":"11450590572","pt":1717323605295,"mc":[{"id":"1.229554924","rc":[{"atl":[[2.14,4.43]],"id":52671121},{"atl":[[2.54,3.92]],"id":65460404}],"con":true,"img":false}]}
{"op":"mcm","clk":"11450590583","pt":1717323605397,"mc":[{"id":"1.229554924","rc":[{"atb":[[1.97,8.5]],"id":65460404}],"con":true,"img":false}]}
{"op":"mcm","clk":"11450591034","pt":1717323609614,"mc":[{"id":"1.229554924","rc":[{"atb":[[1.42,46.87],[1.34,0]],"id":52671121},{"atl":[[2.5,0],[2.12,4.75],[2.26,16.07],[2.16,0]],"id":52671121},{"atb":[[1.59,0],[1.75,29.41]],"id":65460404}],"con":true,"img":false}]}
{"op":"mcm","clk":"11450591718","pt":1717323617005,"mc":[{"id":"1.229554924","rc":[{"atl":[[2.3,11.54],[2.28,0]],"id":52671121}],"con":true,"img":false}]}
{"op":"mcm","clk":"11450591727","pt":1717323617115,"mc":[{"id":"1.229554924","rc":[{"atb":[[1.27,0],[1.32,0],[1.29,0],[1.35,0]],"id":52671121},{"atb":[[1.49,0],[1.51,0],[1.47,0]],"id":65460404}],"con":true,"img":false}]}
{"op":"mcm","clk":"11450591751","pt":1717323617426,"mc":[{"id":"1.229554924","rc":[{"atb":[[1.72,0],[1.62,0]],"id":52671121},{"atb":[[1.98,0],[1.88,0]],"id":65460404}],"con":true,"img":false}]}
{"op":"mcm","clk":"11450591768","pt":1717323617592,"mc":[{"id":"1.229554924","rc":[{"atl":[[2.3,0],[2.32,11.36]],"id":52671121}],"con":true,"img":false}]}
{"op":"mcm","clk":"11450591783","pt":1717323617792,"mc":[{"id":"1.229554924","rc":[{"atl":[[2.32,0],[2.1,4.45],[2.34,0]],"id":52671121},{"atb":[[1.98,4.33]],"id":65460404}],"con":true,"img":false}]}
{"op":"mcm","clk":"11450591803","pt":1717323617906,"mc":[{"id":"1.229554924","rc":[{"atl":[[2.12,0],[2.08,2.22]],"id":52671121}],"con":true,"img":false}]}
{"op":"mcm","clk":"11450592633","pt":1717323625838,"mc":[{"id":"1.229554924","rc":[{"atl":[[2.56,0],[2.54,8.04],[3.15,0],[2.96,7.82]],"id":65460404}],"con":true,"img":false}]}
{"op":"mcm","clk":"11450592732","pt":1717323626820,"mc":[{"id":"1.229554924","rc":[{"atb":[[1.72,10.89],[1.62,12.65]],"id":52671121},{"atb":[[1.98,12.34],[1.88,8.92]],"id":65460404}],"con":true,"img":false}]}
{"op":"mcm","clk":"11450593697","pt":1717323636218,"mc":[{"id":"1.229554924","rc":[{"atl":[[2.54,3.92],[2.52,4.14]],"id":65460404}],"con":true,"img":false}]}
{"op":"mcm","clk":"11450593789","pt":1717323637226,"mc":[{"id":"1.229554924","rc":[{"atl":[[2.06,4.47]],"id":52671121},{"atb":[[1.99,4.3]],"id":65460404},{"atl":[[2.5,3.97]],"id":65460404}],"con":true,"img":false}]}
{"op":"mcm","clk":"11450593800","pt":1717323637333,"mc":[{"id":"1.229554924","rc":[{"atl":[[2.04,4.77],[2.08,0]],"id":52671121}],"con":true,"img":false}]}
{"op":"mcm","clk":"11450594024","pt":1717323639641,"mc":[{"id":"1.229554924","rc":[{"atb":[[1.6,0],[1.66,4.77]],"id":52671121},{"atb":[[1.99,0]],"id":65460404}],"con":true,"img":false}]}
{"op":"mcm","clk":"11450594034","pt":1717323639757,"mc":[{"id":"1.229554924","rc":[{"atb":[[1.67,4.47],[1.42,0],[1.66,0],[1.47,95.9]],"id":52671121},{"atl":[[2.86,7.84],[2.96,0]],"id":65460404}],"con":true,"img":false}]}
{"op":"mcm","clk":"11450594169","pt":1717323641114,"mc":[{"id":"1.229554924","rc":[{"atb":[[1.98,8],[1.97,4.16]],"id":65460404}],"con":true,"img":false}]}
{"op":"mcm","clk":"11450594191","pt":1717323641335,"mc":[{"id":"1.229554924","rc":[{"atl":[[2.44,3.95]],"id":65460404}],"con":true,"img":false}]}
{"op":"mcm","clk":"11450594202","pt":1717323641432,"mc":[{"id":"1.229554924","rc":[{"atl":[[2.52,0]],"id":65460404}],"con":true,"img":false}]}
{"op":"mcm","clk":"11450594291","pt":1717323642329,"mc":[{"id":"1.229554924","rc":[{"atl":[[2.42,4.08],[2.66,0]],"id":65460404}],"con":true,"img":false}]}
{"op":"mcm","clk":"11450594735","pt":1717323646452,"mc":[{"id":"1.229554924","rc":[{"atb":[[1.67,0],[1.68,4.47]],"id":52671121},{"atl":[[2.42,8.11],[2.44,0]],"id":65460404}],"con":true,"img":false}]}
{"op":"mcm","clk":"11450595090","pt":1717323649756,"mc":[{"id":"1.229554924","rc":[{"atb":[[1.72,0],[1.62,0]],"id":52671121},{"atb":[[1.98,0],[1.88,0]],"id":65460404}],"con":true,"img":false}]}
{"op":"mcm","clk":"11450595100","pt":1717323649860,"mc":[{"id":"1.229554924","rc":[{"atb":[[1.97,0],[1.9,3.95]],"id":65460404}],"con":true,"img":false}]}
{"op":"mcm","clk":"11450595148","pt":1717323650337,"mc":[{"id":"1.229554924","rc":[{"atl":[[2.06,0]],"id":52671121},{"atl":[[2.4,4.19],[2.62,0]],"id":65460404}],"con":true,"img":false}]}
{"op":"mcm","clk":"11450595159","pt":1717323650441,"mc":[{"id":"1.229554924","rc":[{"atl":[[2.04,0],[2.08,2.22]],"id":52671121}],"con":true,"img":false}]}
{"op":"mcm","clk":"11450595287","pt":1717323651853,"mc":[{"id":"1.229554924","rc":[{"atl":[[2.4,8.22],[2.42,4.08]],"id":65460404}],"con":true,"img":false}]}
{"op":"mcm","clk":"11450595461","pt":1717323653834,"mc":[{"id":"1.229554924","rc":[{"atl":[[2.1,0],[2.14,0]],"id":52671121}],"con":true,"img":false}]}
{"op":"mcm","clk":"11450595472","pt":1717323653987,"mc":[{"id":"1.229554924","rc":[{"atb":[[1.89,0]],"id":65460404}],"con":true,"img":false}]}
{"op":"mcm","clk":"11450595487","pt":1717323654146,"mc":[{"id":"1.229554924","rc":[{"atb":[[1.46,65.22],[1.63,4.03],[1.9,0],[1.5,40],[1.75,0],[1.48,52.08],[1.34,185.07],[1.52,28.85]],"id":65460404},{"atl":[[2.54,0],[2.38,4.61]],"id":65460404}],"con":true,"img":false}]}
{"op":"mcm","clk":"11450595497","pt":1717323654253,"mc":[{"id":"1.229554924","rc":[{"atl":[[2.42,0],[2.38,0]],"id":52671121},{"atb":[[1.63,158.73],[1.53,4.03],[1.34,0]],"id":65460404}],"con":true,"img":false}]}
{"op":"mcm","clk":"11450595506","pt":1717323654351,"mc":[{"id":"1.229554924","rc":[{"atb":[[1.5,92.08]],"id":65460404}],"con":true,"img":false}]}
{"op":"mcm","clk":"11450595514","pt":1717323654455,"mc":[{"id":"1.229554924","rc":[{"atb":[[1.63,0],[1.53,32.33],[1.52,0]],"id":65460404}],"con":true,"img":false}]}
{"op":"mcm","clk":"11450595527","pt":1717323654559,"mc":[{"id":"1.229554924","rc":[{"atb":[[1.5,40],[1.52,162.76]],"id":65460404}],"con":true,"img":false}]}
{"op":"mcm","clk":"11450595533","pt":1717323654661,"mc":[{"id":"1.229554924","rc":[{"atl":[[2.52,18.3],[2.26,4.35]],"id":52671121},{"atb":[[1.48,176.49],[1.52,0]],"id":65460404},{"atl":[[2.86,0],[3.15,9.24]],"id":65460404}],"con":true,"img":false}]}
{"op":"mcm","clk":"11450595544","pt":1717323654767,"mc":[{"id":"1.229554924","rc":[{"atb":[[1.5,105.22],[1.48,52.08]],"id":65460404}],"con":true,"img":false}]}
{"op":"mcm","clk":"11450595558","pt":1717323654974,"mc":[{"id":"1.229554924","rc":[{"atb":[[1.5,40],[1.48,189.63]],"id":65460404}],"con":true,"img":false}]}
{"op":"mcm","clk":"11450595620","pt":1717323655551,"mc":[{"id":"1.229554924","rc":[{"atl":[[2.52,20.3],[2.08,0]],"id":52671121}],"con":true,"img":false}]}
{"op":"mcm","clk":"11450595631","pt":1717323655650,"mc":[{"id":"1.229554924","rc":[{"atl":[[2.74,17.24],[2.66,12.05],[2.62,9.26],[2.7,14.71]],"id":52671121},{"atb":[[1.54,2.04],[1.53,28.3]],"id":65460404}],"con":true,"img":false}]}
{"op":"mcm","clk":"11450595645","pt":1717323655758,"mc":[{"id":"1.229554924","rc":[{"atl":[[2.24,2],[2.52,18.3]],"id":52671121}],"con":true,"img":false}]}
{"op":"mcm","clk":"11450595735","pt":1717323656863,"mc":[{"id":"1.229554924","rc":[{"atb":[[1.68,0],[1.69,2]],"id":52671121},{"atl":[[2.4,4.19],[2.38,6.65]],"id":65460404}],"con":true,"img":false}]}
{"op":"mcm","clk":"11450595834","pt":1717323657850,"mc":[{"id":"1.229554924","rc":[{"atb":[[1.72,10.89],[1.62,12.65]],"id":52671121},{"atb":[[1.98,8],[1.88,8.92]],"id":65460404}],"con":true,"img":false}]}
{"op":"mcm","clk":"11450595841","pt":1717323658009,"mc":[{"id":"1.229554924","rc":[{"atl":[[2.24,5.97]],"id":52671121},{"atb":[[1.97,4.41],[1.54,6.93]],"id":65460404}],"con":true,"img":false}]}
{"op":"mcm","clk":"11450595848","pt":1717323658060,"mc":[{"id":"1.229554924","rc":[{"atb":[[1.54,4.89]],"id":65460404}],"con":true,"img":false}]}
{"op":"mcm","clk":"11450595860","pt":1717323658163,"mc":[{"id":"1.229554924","rc":[{"atl":[[2.32,12.05],[2.52,0]],"id":52671121},{"atl":[[2.82,8.28],[3.15,0]],"id":65460404}],"con":true,"img":false}]}
{"op":"mcm","clk":"11450596023","pt":1717323660048,"mc":[{"id":"1.229554924","rc":[{"atb":[[1.73,28.3],[1.48,52.07]],"id":65460404}],"con":true,"img":false}]}
{"op":"mcm","clk":"11450596066","pt":1717323660465,"mc":[{"id":"1.229554924","rc":[{"atb":[[1.98,0.42]],"id":65460404},{"trd":[[1.98,15.17]],"ltp":1.98,"tv":15.17,"id":65460404}],"con":true,"img":false}]}
{"op":"mcm","clk":"11450596077","pt":1717323660565,"mc":[{"id":"1.229554924","rc":[{"atb":[[1.74,4.87]],"id":65460404}],"con":true,"img":false}]}
{"op":"mcm","clk":"11450596209","pt":1717323661877,"mc":[{"id":"1.229554924","rc":[{"atb":[[1.7,4.16],[1.69,0]],"id":52671121},{"atl":[[2.32,0],[2.34,12.05]],"id":52671121}],"con":true,"img":false}]}
{"op":"mcm","clk":"11450596297","pt":1717323662655,"mc":[{"id":"1.229554924","rc":[{"atb":[[1.46,0],[1.5,0],[1.53,0],[1.48,0]],"id":65460404}],"con":true,"img":false}]}
{"op":"mcm","clk":"11450596350","pt":1717323663185,"mc":[{"id":"1.229554924","rc":[{"atb":[[1.89,4.14],[1.97,0]],"id":65460404}],"con":true,"img":false}]}
{"op":"mcm","clk":"11450596424","pt":1717323663863,"mc":[{"id":"1.229554924","rc":[{"atb":[[1.98,0]],"id":65460404},{"trd":[[1.98,16.01]],"ltp":1.98,"tv":16.01,"id":65460404}],"con":true,"img":false}]}
{"op":"mcm","clk":"11450596773","pt":1717323667250,"mc":[{"id":"1.229554924","rc":[{"atb":[[1.7,0],[1.69,4.16]],"id":52671121},{"atl":[[2.32,12.05],[2.34,0]],"id":52671121}],"con":true,"img":false}]}
{"op":"mcm","clk":"11450596856","pt":1717323667987,"mc":[{"id":"1.229554924","rc":[{"atb":[[1.7,4.16],[1.69,0]],"id":52671121},{"atl":[[2.32,0],[2.34,12.05]],"id":52671121}],"con":true,"img":false}]}
{"op":"mcm","clk":"11450597929","pt":1717323678884,"mc":[{"id":"1.229554924","rc":[{"atb":[[1.72,15.05],[1.7,0]],"id":52671121}],"con":true,"img":false}]}
{"op":"mcm","clk":"11450598076","pt":1717323680182,"mc":[{"id":"1.229554924","rc":[{"atb":[[1.72,4.16],[1.62,0]],"id":52671121},{"atb":[[1.88,0]],"id":65460404}],"con":true,"img":false}]}
{"op":"mcm","clk":"11450598085","pt":1717323680285,"mc":[{"id":"1.229554924","rc":[{"atb":[[1.89,0],[1.75,4.14]],"id":65460404}],"con":true,"img":false}]}
{"op":"mcm","clk":"11450598154","pt":1717323680987,"mc":[{"id":"1.229554924","rc":[{"atl":[[1.89,17.27]],"id":65460404}],"con":true,"img":false}]}
{"op":"mcm","clk":"11450598167","pt":1717323681074,"mc":[{"id":"1.229554924","rc":[{"trd":[[1.89,34.54]],"ltp":1.89,"tv":34.54,"id":65460404},{"atl":[[1.89,0]],"id":65460404}],"con":true,"img":false}]}
{"op":"mcm","clk":"11450598175","pt":1717323681227,"mc":[{"id":"1.229554924","rc":[{"atb":[[1.76,4.88]],"id":65460404}],"con":true,"img":false}]}
{"op":"mcm","clk":"11450598185","pt":1717323681282,"mc":[{"id":"1.229554924","rc":[{"atb":[[1.77,4.41]],"id":65460404}],"con":true,"img":false}]}
{"op":"mcm","clk":"11450598195","pt":1717323681385,"mc":[{"id":"1.229554924","rc":[{"atb":[[1.75,0]],"id":65460404}],"con":true,"img":false}]}
{"op":"mcm","clk":"11450598213","pt":1717323681594,"mc":[{"id":"1.229554924","rc":[{"atb":[[1.77,6.02]],"id":65460404}],"con":true,"img":false}]}
{"op":"mcm","clk":"11450598221","pt":1717323681699,"mc":[{"id":"1.229554924","rc":[{"atl":[[2.22,0.78]],"id":52671121},{"atl":[[2.36,0.78]],"id":65460404}],"con":true,"img":false}]}
{"op":"mcm","clk":"11450598243","pt":1717323682013,"mc":[{"id":"1.229554924","rc":[{"atl":[[2.24,2],[2.74,0],[2.66,0],[2.26,0],[2.62,0],[2.7,0]],"id":52671121},{"atb":[[1.76,0]],"id":65460404},{"atl":[[2.36,5.69],[2.5,0]],"id":65460404}],"con":true,"img":false}]}
{"op":"mcm","clk":"11450598251","pt":1717323682067,"mc":[{"id":"1.229554924","rc":[{"atl":[[2.24,0],[2.54,9.74],[2.32,3.82],[2.66,18.07],[2.58,12.66],[2.62,15.43],[2.34,14.05]],"id":52671121},{"atb":[[1.76,5.1]],"id":65460404},{"atl":[[2.36,10.1],[2.38,4.61]],"id":65460404}],"con":true,"img":false}]}
{"op":"mcm","clk":"11450598263","pt":1717323682173,"mc":[{"id":"1.229554924","rc":[{"atl":[[2.72,17.44],[2.3,2],[2.6,9.38],[2.64,12.2],[2.68,14.88]],"id":52671121}],"con":true,"img":false}]}
{"op":"mcm","clk":"11450598271","pt":1717323682279,"mc":[{"id":"1.229554924","rc":[{"atl":[[2.72,0],[2.54,0],[2.22,0.62],[2.6,0],[2.64,0],[2.58,0],[2.62,0],[2.34,12.05],[2.66,0],[2.68,0]],"id":52671121},{"atl":[[2.36,9.94]],"id":65460404}],"con":true,"img":false}]}
{"op":"mcm","clk":"11450598321","pt":1717323682899,"mc":[{"id":"1.229554924","rc":[{"atl":[[2.22,0]],"id":52671121}],"con":true,"img":false}]}
{"op":"mcm","clk":"11450598335","pt":1717323683002,"mc":[{"id":"1.229554924","rc":[{"atl":[[2.28,0.62]],"id":52671121}],"con":true,"img":false}]}
{"op":"mcm","clk":"11450598396","pt":1717323683576,"mc":[{"id":"1.229554924","rc":[{"atb":[[1.78,0.85]],"id":65460404}],"con":true,"img":false}]}
{"op":"mcm","clk":"11450598417","pt":1717323684002,"mc":[{"id":"1.229554924","rc":[{"atl":[[2.28,4.53]],"id":52671121},{"atb":[[1.78,5.84]],"id":65460404}],"con":true,"img":false}]}
{"op":"mcm","clk":"11450598427","pt":1717323684104,"mc":[{"id":"1.229554924","rc":[{"atb":[[1.73,7.05],[1.72,0]],"id":52671121},{"atl":[[2.36,5.83],[2.34,0]],"id":52671121},{"atb":[[1.73,0],[1.72,94.98],[1.79,4.86]],"id":65460404}],"con":true,"img":false}]}
{"op":"mcm","clk":"11450598433","pt":1717323684163,"mc":[{"id":"1.229554924","rc":[{"atb":[[1.77,1.61]],"id":65460404}],"con":true,"img":false}]}
{"op":"mcm","clk":"11450598590","pt":1717323686082,"mc":[{"id":"1.229554924","rc":[{"atb":[[1.78,4.99]],"id":65460404}],"con":true,"img":false}]}
{"op":"mcm","clk":"11450598690","pt":1717323687286,"mc":[{"id":"1.229554924","rc":[{"atl":[[2.26,4.18]],"id":52671121}],"con":true,"img":false}]}
{"op":"mcm","clk":"11450598701","pt":1717323687384,"mc":[{"id":"1.229554924","rc":[{"atl":[[2.3,0]],"id":52671121}],"con":true,"img":false}]}
{"op":"mcm","clk":"11450598730","pt":1717323687804,"mc":[{"id":"1.229554924","rc":[{"atl":[[2.28,3.9]],"id":52671121}],"con":true,"img":false}]}
{"op":"mcm","clk":"11450598738","pt":1717323687908,"mc":[{"id":"1.229554924","rc":[{"atl":[[2.24,0.62]],"id":52671121}],"con":true,"img":false}]}
{"op":"mcm","clk":"11450598842","pt":1717323689318,"mc":[{"id":"1.229554924","rc":[{"atb":[[1.73,5.05],[1.7,2.26]],"id":52671121},{"atl":[[2.36,0],[2.34,7.73]],"id":52671121},{"atb":[[1.72,0],[1.74,14.73]],"id":65460404}],"con":true,"img":false}]}
{"op":"mcm","clk":"11450598906","pt":1717323689989,"mc":[{"id":"1.229554924","rc":[{"atl":[[2.42,0],[2.34,4.78]],"id":65460404}],"con":true,"img":false}]}
{"op":"mcm","clk":"11450598976","pt":1717323690709,"mc":[{"id":"1.229554924","rc":[{"atl":[[2.36,9.32]],"id":65460404}],"con":true,"img":false}]}
{"op":"mcm","clk":"11450598984","pt":1717323690813,"mc":[{"id":"1.229554924","rc":[{"atl":[[2.32,0.62]],"id":65460404}],"con":true,"img":false}]}
{"op":"mcm","clk":"11450599002","pt":1717323691020,"mc":[{"id":"1.229554924","rc":[{"atl":[[2.26,8.1]],"id":52671121},{"atb":[[1.79,9.82]],"id":65460404}],"con":true,"img":false}]}
{"op":"mcm","clk":"11450599013","pt":1717323691124,"mc":[{"id":"1.229554924","rc":[{"atb":[[1.54,0]],"id":65460404}],"con":true,"img":false}]}
{"op":"mcm","clk":"11450599033","pt":1717323691283,"mc":[{"id":"1.229554924","rc":[{"atb":[[1.77,0]],"id":65460404}],"con":true,"img":false}]}
{"op":"mcm","clk":"11450599042","pt":1717323691384,"mc":[{"id":"1.229554924","rc":[{"atb":[[1.8,1.61]],"id":65460404}],"con":true,"img":false}]}
{"op":"mcm","clk":"11450599076","pt":1717323691709,"mc":[{"id":"1.229554924","rc":[{"atb":[[1.79,15],[1.69,17.17]],"id":52671121},{"atb":[[1.56,7],[1.46,8.52]],"id":65460404}],"con":true,"img":false}]}
{"op":"mcm","clk":"11450599104","pt":1717323691918,"mc":[{"id":"1.229554924","rc":[{"atl":[[2.24,0]],"id":52671121}],"con":true,"img":false}]}
{"op":"mcm","clk":"11450599111","pt":1717323691975,"mc":[{"id":"1.229554924","rc":[{"atl":[[1000,0.62]],"id":52671121}],"con":true,"img":false}]}
{"op":"mcm","clk":"11450599121","pt":1717323692077,"mc":[{"id":"1.229554924","rc":[{"atb":[[1.8,4.04]],"id":52671121},{"atl":[[2.4,0],[2.32,5.4]],"id":65460404}],"con":true,"img":false}]}
{"op":"mcm","clk":"11450599163","pt":1717323692488,"mc":[{"id":"1.229554924","rc":[{"atl":[[2.32,4.78]],"id":65460404}],"con":true,"img":false}]}
{"op":"mcm","clk":"11450599179","pt":1717323692592,"mc":[{"id":"1.229554924","rc":[{"atb":[[1.8,0]],"id":65460404},{"atl":[[1000,0.62]],"id":65460404}],"con":true,"img":false}]}
{"op":"mcm","clk":"11450599227","pt":1717323693113,"mc":[{"id":"1.229554924","rc":[{"atl":[[1000,0]],"id":65460404}],"con":true,"img":false}]}
{"op":"mcm","clk":"11450599234","pt":1717323693216,"mc":[{"id":"1.229554924","rc":[{"atl":[[2.3,0.62]],"id":65460404}],"con":true,"img":false}]}
{"op":"mcm","clk":"11450599290","pt":1717323693791,"mc":[{"id":"1.229554924","rc":[{"atl":[[2.36,11.63],[2.34,0]],"id":52671121},{"atl":[[2.36,4.91],[2.32,9.66]],"id":65460404}],"con":true,"img":false}]}
{"op":"mcm","clk":"11450599303","pt":1717323693893,"mc":[{"id":"1.229554924","rc":[{"atl":[[2.32,4.78],[2.34,9.66]],"id":65460404}],"con":true,"img":false}]}
{"op":"mcm","clk":"11450599347","pt":1717323694317,"mc":[{"id":"1.229554924","rc":[{"atb":[[1.73,14.93],[1.74,4.87]],"id":65460404}],"con":true,"img":false}]}
{"op":"mcm","clk":"11450599360","pt":1717323694419,"mc":[{"id":"1.229554924","rc":[{"atb":[[1.72,3.98],[1.7,0]],"id":52671121}],"con":true,"img":false}]}
{"op":"mcm","clk":"11450599440","pt":1717323695000,"mc":[{"id":"1.229554924","rc":[{"atb":[[1.72,0],[1.75,3.98],[1.47,0],[1.52,120.42]],"id":52671121},{"atl":[[2.36,0],[2.38,12]],"id":52671121},{"atl":[[2.3,5.5],[2.34,4.78]],"id":65460404}],"con":true,"img":false}]}
{"op":"mcm","clk":"11450599491","pt":1717323695515,"mc":[{"id":"1.229554924","rc":[{"atl":[[2.3,4.88]],"id":65460404}],"con":true,"img":false}]}
{"op":"mcm","clk":"11450599499","pt":1717323695621,"mc":[{"id":"1.229554924","rc":[{"atl":[[1000,0.62]],"id":65460404}],"con":true,"img":false}]}
{"op":"mcm","clk":"11450599793","pt":1717323698784,"mc":[{"id":"1.229554924","rc":[{"atb":[[1.73,0],[1.7,10.22]],"id":65460404}],"con":true,"img":false}]}
{"op":"mcm","clk":"11450599863","pt":1717323699622,"mc":[{"id":"1.229554924","rc":[{"atl":[[2.38,0],[2.28,4.78]],"id":65460404}],"con":true,"img":false}]}
{"op":"mcm","clk":"11450599870","pt":1717323699725,"mc":[{"id":"1.229554924","rc":[{"atb":[[1.58,132.68],[1.77,3.91],[1.75,0],[1.52,0]],"id":52671121},{"atl":[[2.38,0],[2.64,12]],"id":52671121},{"atb":[[1.7,0]],"id":65460404},{"atl":[[2.82,0],[2.56,9.58],[2.26,4.88]],"id":65460404}],"con":true,"img":false}]}
{"op":"mcm","clk":"11450599876","pt":1717323699830,"mc":[{"id":"1.229554924","rc":[{"atb":[[1.57,10.22]],"id":65460404},{"atl":[[2.3,0]],"id":65460404}],"con":true,"img":false}]}
{"op":"mcm","clk":"11450599932","pt":1717323700400,"mc":[{"id":"1.229554924","rc":[{"atb":[[1.8,5.55]],"id":52671121}],"con":true,"img":false}]}
{"op":"mcm","clk":"11450600027","pt":1717323701538,"mc":[{"id":"1.229554924","rc":[{"atb":[[1.81,0.85]],"id":52671121}],"con":true,"img":false}]}
{"op":"mcm","clk":"11450600278","pt":1717323704145,"mc":[{"id":"1.229554924","rc":[{"atb":[[1.81,0.26]],"id":52671121}],"con":true,"img":false}]}
{"op":"mcm","clk":"11450600847","pt":1717323711140,"mc":[{"id":"1.229554924","rc":[{"atb":[[1.79,0],[1.69,0]],"id":52671121},{"atb":[[1.56,0],[1.46,0]],"id":65460404}],"con":true,"img":false}]}
{"op":"mcm","clk":"11450600874","pt":1717323711453,"mc":[{"id":"1.229554924","rc":[{"atb":[[1.8,4.04]],"id":52671121}],"con":true,"img":false}]}
{"op":"mcm","clk":"11450600883","pt":1717323711506,"mc":[{"id":"1.229554924","rc":[{"atb":[[1.81,0]],"id":52671121}],"con":true,"img":false}]}
{"op":"mcm","clk":"11450600887","pt":1717323711613,"mc":[{"id":"1.229554924","rc":[{"atb":[[1.13,0.26]],"id":52671121}],"con":true,"img":false}]}
{"op":"mcm","clk":"11450601359","pt":1717323716244,"mc":[{"id":"1.229554924","rc":[{"atb":[[1.79,15],[1.69,17.17]],"id":52671121},{"atb":[[1.56,7],[1.46,8.52]],"id":65460404}],"con":true,"img":false}]}
{"op":"mcm","clk":"11450601389","pt":1717323716654,"mc":[{"id":"1.229554924","rc":[{"atb":[[1.13,0]],"id":52671121}],"con":true,"img":false}]}
{"op":"mcm","clk":"11450601397","pt":1717323716763,"mc":[{"id":"1.229554924","rc":[{"atb":[[1.8,4.31]],"id":52671121}],"con":true,"img":false}]}
{"op":"mcm","clk":"11450601412","pt":1717323716969,"mc":[{"id":"1.229554924","rc":[{"atb":[[1.8,5.82],[1.81,3.91],[1.77,0]],"id":52671121}],"con":true,"img":false}]}
{"op":"mcm","clk":"11450601424","pt":1717323717128,"mc":[{"id":"1.229554924","rc":[{"atb":[[1.82,4.03]],"id":52671121},{"atb":[[1.8,4.93],[1.74,0]],"id":65460404},{"atl":[[2.36,0],[2.24,4.79]],"id":65460404}],"con":true,"img":false}]}
{"op":"mcm","clk":"11450601433","pt":1717323717225,"mc":[{"id":"1.229554924","rc":[{"atb":[[1.79,4.96],[1.81,4.86]],"id":65460404},{"atl":[[2.22,4.86],[2.26,0]],"id":65460404}],"con":true,"img":false}]}
{"op":"mcm","clk":"11450601461","pt":1717323717640,"mc":[{"id":"1.229554924","rc":[{"atb":[[1.8,4.31]],"id":52671121}],"con":true,"img":false}]}
{"op":"mcm","clk":"11450601589","pt":1717323719055,"mc":[{"id":"1.229554924","rc":[{"atb":[[1.8,4.04]],"id":52671121}],"con":true,"img":false}]}
{"op":"mcm","clk":"11450601598","pt":1717323719159,"mc":[{"id":"1.229554924","rc":[{"atb":[[1.13,0.26]],"id":52671121}],"con":true,"img":false}]}
{"op":"mcm","clk":"11450601885","pt":1717323722029,"mc":[{"id":"1.229554924","rc":[{"atb":[[1.83,3.91]],"id":52671121}],"con":true,"img":false}]}
{"op":"mcm","clk":"11450601893","pt":1717323722132,"mc":[{"id":"1.229554924","rc":[{"atb":[[1.81,0]],"id":52671121}],"con":true,"img":false}]}
{"op":"mcm","clk":"11450602278","pt":1717323725543,"mc":[{"id":"1.229554924","rc":[{"atl":[[2.22,12.73]],"id":52671121},{"atl":[[2.2,12.84]],"id":65460404}],"con":true,"img":false}]}
{"op":"mcm","clk":"11450602288","pt":1717323725653,"mc":[{"id":"1.229554924","rc":[{"atl":[[2.22,16.71],[2.26,3.92]],"id":52671121},{"atl":[[2.22,0],[2.18,4.86]],"id":65460404}],"con":true,"img":false}]}
{"op":"mcm","clk":"11450602329","pt":1717323726071,"mc":[{"id":"1.229554924","rc":[{"atl":[[2.2,4.2]],"id":52671121},{"atb":[[1.82,4.6],[1.76,0]],"id":65460404}],"con":true,"img":false}]}
{"op":"mcm","clk":"11450602336","pt":1717323726176,"mc":[{"id":"1.229554924","rc":[{"atb":[[1.84,4.29]],"id":52671121}],"con":true,"img":false}]}
{"op":"mcm","clk":"11450602345","pt":1717323726239,"mc":[{"id":"1.229554924","rc":[{"atl":[[2.16,4.49],[2.34,0]],"id":65460404}],"con":true,"img":false}]}
{"op":"mcm","clk":"11450602493","pt":1717323727652,"mc":[{"id":"1.229554924","rc":[{"atb":[[1.79,0],[1.69,0]],"id":52671121},{"atb":[[1.56,0],[1.46,0]],"id":65460404}],"con":true,"img":false}]}
{"op":"mcm","clk":"11450602782","pt":1717323730053,"mc":[{"id":"1.229554924","rc":[{"atl":[[2.18,12.95]],"id":52671121},{"atb":[[1.83,4.55],[1.81,0]],"id":65460404},{"atl":[[2.14,13.17]],"id":65460404}],"con":true,"img":false}]}
{"op":"mcm","clk":"11450602847","pt":1717323730574,"mc":[{"id":"1.229554924","rc":[{"atb":[[1.84,39.8]],"id":52671121},{"atb":[[1.82,40.97]],"id":65460404}],"con":true,"img":false}]}
{"op":"mcm","clk":"11450602880","pt":1717323730885,"mc":[{"id":"1.229554924","rc":[{"atl":[[2.22,12.73],[2.16,8.48]],"id":52671121}],"con":true,"img":false}]}
{"op":"mcm","clk":"11450602891","pt":1717323730942,"mc":[{"id":"1.229554924","rc":[{"atl":[[2.54,8.13],[2.64,0]],"id":52671121},{"atb":[[1.57,0],[1.62,97.64]],"id":65460404}],"con":true,"img":false}]}
{"op":"mcm","clk":"11450602902","pt":1717323731045,"mc":[{"id":"1.229554924","rc":[{"atb":[[1.73,0],[1.85,4.19]],"id":52671121},{"atl":[[2.32,0],[2.12,4.61]],"id":65460404}],"con":true,"img":false}]}
{"op":"mcm","clk":"11450602974","pt":1717323731671,"mc":[{"id":"1.229554924","rc":[{"atl":[[2.32,0]],"id":52671121},{"atb":[[1.78,0]],"id":65460404}],"con":true,"img":false}]}
{"op":"mcm","clk":"11450602983","pt":1717323731776,"mc":[{"id":"1.229554924","rc":[{"atl":[[2.16,12.59]],"id":52671121},{"atb":[[1.84,4.7]],"id":65460404}],"con":true,"img":false}]}
{"op":"mcm","clk":"11450603070","pt":1717323732667,"mc":[{"id":"1.229554924","rc":[{"atl":[[2.16,8.48]],"id":52671121}],"con":true,"img":false}]}
{"op":"mcm","clk":"11450603100","pt":1717323732973,"mc":[{"id":"1.229554924","rc":[{"atb":[[1.84,40.21]],"id":65460404}],"con":true,"img":false}]}
{"op":"mcm","clk":"11450603141","pt":1717323733379,"mc":[{"id":"1.229554924","rc":[{"atl":[[2.14,13.17]],"id":52671121},{"atl":[[2.2,0],[2.16,15.65]],"id":65460404}],"con":true,"img":false}]}
{"op":"mcm","clk":"11450603168","pt":1717323733584,"mc":[{"id":"1.229554924","rc":[{"atl":[[2.12,8.57],[2.14,0],[2.16,0]],"id":52671121},{"atl":[[2.14,0]],"id":65460404}],"con":true,"img":false}]}
{"op":"mcm","clk":"11450603182","pt":1717323733689,"mc":[{"id":"1.229554924","rc":[{"atl":[[2.12,0],[2.18,17.04],[2.16,4.2]],"id":52671121},{"atb":[[1.79,0],[1.85,4.73]],"id":65460404}],"con":true,"img":false}]}
{"op":"mcm","clk":"11450603292","pt":1717323734780,"mc":[{"id":"1.229554924","rc":[{"trd":[[2.16,4.18]],"ltp":2.16,"tv":4.18,"id":52671121},{"atl":[[2.16,2.11]],"id":52671121}],"con":true,"img":false}]}
{"op":"mcm","clk":"11450603299","pt":1717323734879,"mc":[{"id":"1.229554924","rc":[{"atl":[[2.16,0]],"id":52671121}],"con":true,"img":false}]}
{"op":"mcm","clk":"11450603333","pt":1717323735151,"mc":[{"id":"1.229554924","rc":[{"atb":[[1.83,0],[1.86,4.67]],"id":65460404}],"con":true,"img":false}]}
{"op":"mcm","clk":"11450603410","pt":1717323735875,"mc":[{"id":"1.229554924","rc":[{"atb":[[1.02,148.48],[1.88,13.46],[1.78,15.19],[1.05,2.7]],"id":52671121},{"atl":[[1000,7.68]],"id":52671121},{"atb":[[1.4,9.8],[1.02,3.56],[1.5,7.84],[1.05,2.7]],"id":65460404},{"atl":[[1000,7.72]],"id":65460404}],"con":true,"img":false}]}
{"op":"mcm","clk":"11450603438","pt":1717323736193,"mc":[{"id":"1.229554924","rc":[{"atb":[[1.8,0],[1.89,4.13]],"id":52671121},{"atb":[[1.85,0]],"id":65460404}],"con":true,"img":false}]}
{"op":"mcm","clk":"11450603470","pt":1717323736456,"mc":[{"id":"1.229554924","rc":[{"atb":[[1.87,34.28]],"id":52671121}],"con":true,"img":false}]}
{"op":"mcm","clk":"11450603482","pt":1717323736563,"mc":[{"id":"1.229554924","rc":[{"atb":[[1.84,4.7]],"id":65460404}],"con":true,"img":false}]}
{"op":"mcm","clk":"11450603491","pt":1717323736667,"mc":[{"id":"1.229554924","rc":[{"atl":[[2.1,6.85]],"id":65460404}],"con":true,"img":false}]}
{"op":"mcm","clk":"11450603506","pt":1717323736871,"mc":[{"id":"1.229554924","rc":[{"atb":[[1.02,145.86],[1.05,0.08]],"id":52671121},{"atl":[[1000,2.45]],"id":52671121},{"atb":[[1.02,0.94],[1.05,0.08]],"id":65460404},{"atl":[[1000,2.49]],"id":65460404}],"con":true,"img":false}]}
{"op":"mcm","clk":"11450603602","pt":1717323737867,"mc":[{"id":"1.229554924","rc":[{"atb":[[1.02,144.94],[1.05,0]],"id":52671121},{"atl":[[1000,0.62]],"id":52671121},{"atb":[[1.02,0],[1.05,0]],"id":65460404},{"atl":[[1000,0.62]],"id":65460404}],"con":true,"img":false}]}
{"op":"mcm","clk":"11450603612","pt":1717323737969,"mc":[{"id":"1.229554924","rc":[{"atb":[[1.98,1.01]],"id":52671121},{"trd":[[1.99,1.82]],"ltp":1.99,"tv":1.82,"id":52671121},{"atb":[[1.96,0.97]],"id":65460404},{"trd":[[2,1.81]],"ltp":2.0,"tv":1.81,"id":65460404}],"con":true,"img":false}]}
{"op":"mcm","clk":"11450603653","pt":1717323738491,"mc":[{"id":"1.229554924","rc":[{"atb":[[1.84,40.21]],"id":65460404}],"con":true,"img":false}]}
{"op":"mcm","clk":"11450603765","pt":1717323739683,"mc":[{"id":"1.229554924","rc":[{"atl":[[2.12,9.22]],"id":65460404}],"con":true,"img":false}]}
{"op":"mcm","clk":"11450603793","pt":1717323739974,"mc":[{"id":"1.229554924","rc":[{"atb":[[1.89,37.64],[1.84,4.29]],"id":52671121}],"con":true,"img":false}]}
{"op":"mcm","clk":"11450603826","pt":1717323740365,"mc":[{"id":"1.229554924","rc":[{"atb":[[1.98,5.14]],"id":52671121},{"atb":[[1.96,0]],"id":65460404},{"trd":[[1.96,1.95]],"ltp":1.96,"tv":1.95,"id":65460404},{"atl":[[2.28,0],[2.08,4.68]],"id":65460404}],"con":true,"img":false}]}
{"op":"mcm","clk":"11450603832","pt":1717323740466,"mc":[{"id":"1.229554924","rc":[{"atb":[[1.82,0]],"id":52671121},{"atb":[[1.84,4.7],[1.85,8.04],[1.86,0]],"id":65460404}],"con":true,"img":false}]}
{"op":"mcm","clk":"11450603868","pt":1717323740982,"mc":[{"id":"1.229554924","rc":[{"atb":[[1.84,40.21]],"id":65460404}],"con":true,"img":false}]}
{"op":"mcm","clk":"11450603949","pt":1717323741770,"mc":[{"id":"1.229554924","rc":[{"atl":[[2.06,7.11]],"id":65460404}],"con":true,"img":false}]}
{"op":"mcm","clk":"11450604350","pt":1717323745866,"mc":[{"id":"1.229554924","rc":[{"atl":[[2.18,12.95]],"id":52671121}],"con":true,"img":false}]}
{"op":"mcm","clk":"11450604407","pt":1717323746481,"mc":[{"id":"1.229554924","rc":[{"atb":[[1.84,4.7]],"id":65460404}],"con":true,"img":false}]}
{"op":"mcm","clk":"11450604424","pt":1717323746691,"mc":[{"id":"1.229554924","rc":[{"atl":[[2.06,18.78],[2.16,4.49]],"id":65460404}],"con":true,"img":false}]}
{"op":"mcm","clk":"11450604470","pt":1717323747206,"mc":[{"id":"1.229554924","rc":[{"atl":[[2.24,0],[2.04,4.73]],"id":65460404}],"con":true,"img":false}]}
{"op":"mcm","clk":"11450604495","pt":1717323747470,"mc":[{"id":"1.229554924","rc":[{"atb":[[1.93,32.06]],"id":52671121}],"con":true,"img":false}]}
{"op":"mcm","clk":"11450604520","pt":1717323747777,"mc":[{"id":"1.229554924","rc":[{"atb":[[1.84,0]],"id":65460404}],"con":true,"img":false}]}
{"op":"mcm","clk":"11450604529","pt":1717323747880,"mc":[{"id":"1.229554924","rc":[{"atb":[[1.83,4.84],[1.85,0]],"id":65460404}],"con":true,"img":false}]}
{"op":"mcm","clk":"11450604554","pt":1717323748091,"mc":[{"id":"1.229554924","rc":[{"atb":[[1.87,0]],"id":52671121}],"con":true,"img":false}]}
{"op":"mcm","clk":"11450604589","pt":1717323748402,"mc":[{"id":"1.229554924","rc":[{"atl":[[2.2,0]],"id":52671121}],"con":true,"img":false}]}
{"op":"mcm","clk":"11450604651","pt":1717323748982,"mc":[{"id":"1.229554924","rc":[{"atl":[[2.02,18.78]],"id":65460404}],"con":true,"img":false}]}
{"op":"mcm","clk":"11450604659","pt":1717323749084,"mc":[{"id":"1.229554924","rc":[{"atl":[[2.18,0]],"id":52671121}],"con":true,"img":false}]}
{"op":"mcm","clk":"11450604701","pt":1717323749497,"mc":[{"id":"1.229554924","rc":[{"atb":[[1.89,4.13]],"id":52671121}],"con":true,"img":false}]}
{"op":"mcm","clk":"11450604710","pt":1717323749601,"mc":[{"id":"1.229554924","rc":[{"atb":[[1.82,4.6]],"id":65460404}],"con":true,"img":false}]}
{"op":"mcm","clk":"11450604748","pt":1717323749994,"mc":[{"id":"1.229554924","rc":[{"atb":[[1.95,31.39]],"id":52671121},{"atb":[[1.79,37.75]],"id":65460404}],"con":true,"img":false}]}
{"op":"mcm","clk":"11450604802","pt":1717323750566,"mc":[{"id":"1.229554924","rc":[{"atl":[[2.12,4.61],[2.1,0]],"id":65460404}],"con":true,"img":false}]}
{"op":"mcm","clk":"11450604869","pt":1717323751405,"mc":[{"id":"1.229554924","rc":[{"atl":[[2.2,4.03]],"id":52671121},{"atb":[[1.83,9.65]],"id":65460404}],"con":true,"img":false}]}
{"op":"mcm","clk":"11450604883","pt":1717323751510,"mc":[{"id":"1.229554924","rc":[{"atl":[[2.2,0]],"id":52671121},{"atb":[[1.83,4.84]],"id":65460404},{"atl":[[2,4.78],[2.16,0]],"id":65460404}],"con":true,"img":false}]}
{"op":"mcm","clk":"11450604904","pt":1717323751717,"mc":[{"id":"1.229554924","rc":[{"atl":[[2.22,16.76]],"id":52671121},{"atb":[[1.83,9.65]],"id":65460404}],"con":true,"img":false}]}
{"op":"mcm","clk":"11450604931","pt":1717323751984,"mc":[{"id":"1.229554924","rc":[{"atb":[[1.97,30.74]],"id":52671121},{"atl":[[2.24,17.34]],"id":52671121},{"atb":[[1.81,36.82]],"id":65460404}],"con":true,"img":false}]}
{"op":"mcm","clk":"11450604946","pt":1717323752196,"mc":[{"id":"1.229554924","rc":[{"atb":[[1.83,4.84]],"id":65460404}],"con":true,"img":false}]}
{"op":"mcm","clk":"11450605011","pt":1717323752924,"mc":[{"id":"1.229554924","rc":[{"atb":[[1.98,5.05]],"id":52671121}],"con":true,"img":false}]}
{"op":"mcm","clk":"11450605018","pt":1717323752980,"mc":[{"id":"1.229554924","rc":[{"atb":[[2.02,0.08]],"id":52671121}],"con":true,"img":false}]}
{"op":"mcm","clk":"11450605088","pt":1717323753602,"mc":[{"id":"1.229554924","rc":[{"atb":[[1.84,0],[2.02,4.12]],"id":52671121}],"con":true,"img":false}]}
{"op":"mcm","clk":"11450605132","pt":1717323754017,"mc":[{"id":"1.229554924","rc":[{"atb":[[1.93,0]],"id":52671121}],"con":true,"img":false}]}
{"op":"mcm","clk":"11450605301","pt":1717323755999,"mc":[{"id":"1.229554924","rc":[{"atb":[[1.98,4.13]],"id":52671121}],"con":true,"img":false}]}
{"op":"mcm","clk":"11450605309","pt":1717323756106,"mc":[{"id":"1.229554924","rc":[{"atb":[[2.02,5.05]],"id":52671121}],"con":true,"img":false}]}
{"op":"mcm","clk":"11450605321","pt":1717323756310,"mc":[{"id":"1.229554924","rc":[{"atl":[[1.99,11.72]],"id":65460404}],"con":true,"img":false}]}
{"op":"mcm","clk":"11450605339","pt":1717323756519,"mc":[{"id":"1.229554924","rc":[{"atb":[[1.99,30.12]],"id":52671121}],"con":true,"img":false}]}
{"op":"mcm","clk":"11450605368","pt":1717323756901,"mc":[{"id":"1.229554924","rc":[{"atl":[[2.06,0]],"id":65460404}],"con":true,"img":false}]}
{"op":"mcm","clk":"11450605500","pt":1717323758311,"mc":[{"id":"1.229554924","rc":[{"atl":[[1.98,14.29]],"id":65460404}],"con":true,"img":false}]}
{"op":"mcm","clk":"11450605526","pt":1717323758617,"mc":[{"id":"1.229554924","rc":[{"atb":[[1.95,0]],"id":52671121}],"con":true,"img":false}]}
{"op":"mcm","clk":"11450605560","pt":1717323758994,"mc":[{"id":"1.229554924","rc":[{"atl":[[2.02,0]],"id":65460404}],"con":true,"img":false}]}
{"op":"mcm","clk":"11450605609","pt":1717323759612,"mc":[{"id":"1.229554924","rc":[{"atl":[[1.97,4.8],[2.12,0]],"id":65460404}],"con":true,"img":false}]}
{"op":"mcm","clk":"11450605647","pt":1717323760022,"mc":[{"id":"1.229554924","rc":[{"atb":[[2.02,34.29]],"id":52671121}],"con":true,"img":false}]}
{"op":"mcm","clk":"11450605809","pt":1717323761803,"mc":[{"id":"1.229554924","rc":[{"atl":[[2.22,4.02]],"id":52671121}],"con":true,"img":false}]}
{"op":"mcm","clk":"11450605826","pt":1717323762012,"mc":[{"id":"1.229554924","rc":[{"atl":[[1.96,14.44]],"id":65460404}],"con":true,"img":false}]}
{"op":"mcm","clk":"11450606270","pt":1717323766344,"mc":[{"id":"1.229554924","rc":[{"atb":[[1.83,0]],"id":65460404},{"trd":[[1.83,9.67]],"ltp":1.83,"tv":9.67,"id":65460404},{"atl":[[1.83,10.21]],"id":65460404}],"con":true,"img":false}]}
{"op":"mcm","clk":"11450606282","pt":1717323766401,"mc":[{"id":"1.229554924","rc":[{"atb":[[1.85,0],[2.04,4.02]],"id":52671121},{"atb":[[1.82,12.11]],"id":65460404},{"trd":[[1.83,30.11]],"ltp":1.83,"tv":30.11,"id":65460404},{"atl":[[1.83,0],[1.95,4.82],[2.08,0]],"id":65460404}],"con":true,"img":false}]}
{"op":"mcm","clk":"11450606291","pt":1717323766506,"mc":[{"id":"1.229554924","rc":[{"atb":[[1.82,7.51],[1.79,0],[1.81,0],[1.77,38.73]],"id":65460404},{"atl":[[1.84,1.2]],"id":65460404}],"con":true,"img":false}]}
{"op":"mcm","clk":"11450606300","pt":1717323766611,"mc":[{"id":"1.229554924","rc":[{"atl":[[2.22,0],[2.2,11.06]],"id":52671121},{"atl":[[1.84,0]],"id":65460404}],"con":true,"img":false}]}
{"op":"mcm","clk":"11450606308","pt":1717323766714,"mc":[{"id":"1.229554924","rc":[{"atl":[[1.95,5.96]],"id":65460404}],"con":true,"img":false}]}
{"op":"mcm","clk":"11450606321","pt":1717323766876,"mc":[{"id":"1.229554924","rc":[{"atl":[[2.2,0]],"id":52671121}],"con":true,"img":false}]}
{"op":"mcm","clk":"11450606376","pt":1717323767545,"mc":[{"id":"1.229554924","rc":[{"atb":[[1.8,42.21]],"id":65460404}],"con":true,"img":false}]}
{"op":"mcm","clk":"11450606390","pt":1717323767734,"mc":[{"id":"1.229554924","rc":[{"atb":[[1.64,132.68],[1.83,0],[1.58,0],[1.91,10.68]],"id":52671121},{"atl":[[2.08,9.63],[2.18,0]],"id":65460404}],"con":true,"img":false}]}
{"op":"mcm","clk":"11450606400","pt":1717323767810,"mc":[{"id":"1.229554924","rc":[{"atb":[[2.02,34.2]],"id":52671121}],"con":true,"img":false}]}
{"op":"mcm","clk":"11450606413","pt":1717323767919,"mc":[{"id":"1.229554924","rc":[{"atb":[[2,0.08]],"id":52671121}],"con":true,"img":false}]}
{"op":"mcm","clk":"11450606528","pt":1717323769123,"mc":[{"id":"1.229554924","rc":[{"atb":[[2,0]],"id":52671121}],"con":true,"img":false}]}
{"op":"mcm","clk":"11450606535","pt":1717323769217,"mc":[{"id":"1.229554924","rc":[{"atb":[[2.02,34.29]],"id":52671121}],"con":true,"img":false}]}
{"op":"mcm","clk":"11450606628","pt":1717323770315,"mc":[{"id":"1.229554924","rc":[{"atb":[[1.93,21.36],[1.91,0]],"id":52671121},{"atl":[[2.54,0],[2.66,12.05]],"id":52671121},{"atb":[[1.56,80.95],[1.62,0]],"id":65460404}],"con":true,"img":false}]}
{"op":"mcm","clk":"11450606814","pt":1717323772440,"mc":[{"id":"1.229554924","rc":[{"atl":[[2.56,0],[2.46,15.59]],"id":65460404}],"con":true,"img":false}]}
{"op":"mcm","clk":"11450607160","pt":1717323776151,"mc":[{"id":"1.229554924","rc":[{"atb":[[2.02,23.88],[2.04,0]],"id":52671121},{"trd":[[2.02,20.8],[2.04,27.62]],"ltp":2.02,"tv":48.42,"id":52671121},{"trd":[[1.96,16.4],[1.95,5.96]],"ltp":1.96,"tv":22.36,"id":65460404},{"atl":[[1.96,0],[1.95,0]],"id":65460404}],"con":true,"img":false}]}
{"op":"mcm","clk":"11450607166","pt":1717323776256,"mc":[{"id":"1.229554924","rc":[{"atl":[[2.22,14.8]],"id":52671121},{"atb":[[1.82,0],[1.83,4.69],[1.81,10.2]],"id":65460404}],"con":true,"img":false}]}
{"op":"mcm","clk":"11450607324","pt":1717323778131,"mc":[{"id":"1.229554924","rc":[{"atl":[[2.2,10.71]],"id":52671121}],"con":true,"img":false}]}
{"op":"mcm","clk":"11450607356","pt":1717323778542,"mc":[{"id":"1.229554924","rc":[{"atb":[[1.82,36.36]],"id":65460404}],"con":true,"img":false}]}
{"op":"mcm","clk":"11450607633","pt":1717323781328,"mc":[{"id":"1.229554924","rc":[{"atl":[[2.2,24.73]],"id":52671121}],"con":true,"img":false}]}
{"op":"mcm","clk":"11450607646","pt":1717323781427,"mc":[{"id":"1.229554924","rc":[{"atl":[[2.22,4.12]],"id":52671121}],"con":true,"img":false}]}
{"op":"mcm","clk":"11450607819","pt":1717323783255,"mc":[{"id":"1.229554924","rc":[{"atl":[[2.2,14.02]],"id":52671121}],"con":true,"img":false}]}
{"op":"mcm","clk":"11450608332","pt":1717323788872,"mc":[{"id":"1.229554924","rc":[{"atb":[[1.82,44.62],[1.81,0]],"id":65460404}],"con":true,"img":false}]}
{"op":"mcm","clk":"11450608343","pt":1717323788977,"mc":[{"id":"1.229554924","rc":[{"atb":[[1.82,36.36],[1.81,8.26]],"id":65460404}],"con":true,"img":false}]}
{"op":"mcm","clk":"11450608356","pt":1717323789082,"mc":[{"id":"1.229554924","rc":[{"atb":[[1.82,0]],"id":65460404}],"con":true,"img":false}]}
{"op":"mcm","clk":"11450608505","pt":1717323790690,"mc":[{"id":"1.229554924","rc":[{"atl":[[2.22,25.59],[2.2,0]],"id":52671121},{"atb":[[1.8,58.74],[1.81,0]],"id":65460404},{"atl":[[2.06,16.53],[2.08,0]],"id":65460404}],"con":true,"img":false}]}
{"op":"mcm","clk":"11450608517","pt":1717323790791,"mc":[{"id":"1.229554924","rc":[{"atl":[[2.12,13.07]],"id":52671121}],"con":true,"img":false}]}
{"op":"mcm","clk":"11450608525","pt":1717323790849,"mc":[{"id":"1.229554924","rc":[{"atl":[[2.24,18.52],[2.2,4.08]],"id":52671121}],"con":true,"img":false}]}
{"op":"mcm","clk":"11450608546","pt":1717323791063,"mc":[{"id":"1.229554924","rc":[{"atb":[[1.82,36.36]],"id":65460404}],"con":true,"img":false}]}
{"op":"mcm","clk":"11450608996","pt":1717323795475,"mc":[{"id":"1.229554924","rc":[{"atb":[[2,3.46]],"id":52671121}],"con":true,"img":false}]}
{"op":"mcm","clk":"11450609028","pt":1717323795791,"mc":[{"id":"1.229554924","rc":[{"atl":[[2.22,4.12],[2.2,21.28]],"id":52671121},{"atb":[[1.8,42.21],[1.81,26.02]],"id":65460404}],"con":true,"img":false}]}
{"op":"mcm","clk":"11450609050","pt":1717323796002,"mc":[{"id":"1.229554924","rc":[{"atl":[[1.98,0]],"id":65460404}],"con":true,"img":false}]}
{"op":"mcm","clk":"11450609122","pt":1717323796580,"mc":[{"id":"1.229554924","rc":[{"atb":[[1.99,0],[2.02,0.08]],"id":52671121},{"atb":[[1.77,0]],"id":65460404}],"con":true,"img":false}]}
{"op":"mcm","clk":"11450609140","pt":1717323796779,"mc":[{"id":"1.229554924","rc":[{"atb":[[2,18.84]],"id":52671121},{"atl":[[1.99,0]],"id":65460404}],"con":true,"img":false}]}
{"op":"mcm","clk":"11450609166","pt":1717323797093,"mc":[{"id":"1.229554924","rc":[{"atb":[[1.99,30.12]],"id":52671121},{"atl":[[2.22,14.12],[2.2,4.08]],"id":52671121},{"atb":[[1.84,35.5]],"id":65460404}],"con":true,"img":false}]}
{"op":"mcm","clk":"11450609216","pt":1717323797562,"mc":[{"id":"1.229554924","rc":[{"atb":[[1.84,0]],"id":65460404}],"con":true,"img":false}]}
{"op":"mcm","clk":"11450609276","pt":1717323798080,"mc":[{"id":"1.229554924","rc":[{"atb":[[2,15.38]],"id":52671121}],"con":true,"img":false}]}
{"op":"mcm","clk":"11450609292","pt":1717323798286,"mc":[{"id":"1.229554924","rc":[{"atb":[[2,18.84]],"id":52671121}],"con":true,"img":false}]}
{"op":"mcm","clk":"11450609323","pt":1717323798556,"mc":[{"id":"1.229554924","rc":[{"atl":[[2.12,0]],"id":52671121}],"con":true,"img":false}]}
{"op":"mcm","clk":"11450609335","pt":1717323798656,"mc":[{"id":"1.229554924","rc":[{"atl":[[2.14,13.07]],"id":52671121}],"con":true,"img":false}]}
{"op":"mcm","clk":"11450609560","pt":1717323800889,"mc":[{"id":"1.229554924","rc":[{"atb":[[2.02,18.72]],"id":52671121}],"con":true,"img":false}]}
{"op":"mcm","clk":"11450609580","pt":1717323801096,"mc":[{"id":"1.229554924","rc":[{"atb":[[1.97,0]],"id":52671121}],"con":true,"img":false}]}
{"op":"mcm","clk":"11450609597","pt":1717323801302,"mc":[{"id":"1.229554924","rc":[{"atb":[[2,0]],"id":52671121}],"con":true,"img":false}]}
{"op":"mcm","clk":"11450609637","pt":1717323801670,"mc":[{"id":"1.229554924","rc":[{"atb":[[2.02,0.08]],"id":52671121}],"con":true,"img":false}]}
{"op":"mcm","clk":"11450609681","pt":1717323802083,"mc":[{"id":"1.229554924","rc":[{"atb":[[1.99,0],[1.95,31.39]],"id":52671121}],"con":true,"img":false}]}
{"op":"mcm","clk":"11450609691","pt":1717323802187,"mc":[{"id":"1.229554924","rc":[{"atl":[[2.22,4.12],[2.2,8.2]],"id":52671121}],"con":true,"img":false}]}
{"op":"mcm","clk":"11450609702","pt":1717323802289,"mc":[{"id":"1.229554924","rc":[{"atb":[[2,18.84]],"id":52671121}],"con":true,"img":false}]}
{"op":"mcm","clk":"11450609895","pt":1717323804057,"mc":[{"id":"1.229554924","rc":[{"atl":[[2.14,0]],"id":52671121}],"con":true,"img":false}]}
{"op":"mcm","clk":"11450609907","pt":1717323804161,"mc":[{"id":"1.229554924","rc":[{"atl":[[2.16,13.07]],"id":52671121}],"con":true,"img":false}]}
{"op":"mcm","clk":"11450609925","pt":1717323804376,"mc":[{"id":"1.229554924","rc":[{"atb":[[1.99,13.61]],"id":52671121}],"con":true,"img":false}]}
{"op":"mcm","clk":"11450609946","pt":1717323804574,"mc":[{"id":"1.229554924","rc":[{"atb":[[2,48.67]],"id":52671121}],"con":true,"img":false}]}
{"op":"mcm","clk":"11450610175","pt":1717323807285,"mc":[{"id":"1.229554924","rc":[{"atl":[[2.22,21.32],[2.2,4.08]],"id":52671121}],"con":true,"img":false}]}
{"op":"mcm","clk":"11450610206","pt":1717323807588,"mc":[{"id":"1.229554924","rc":[{"atb":[[2.04,3.46]],"id":52671121}],"con":true,"img":false}]}
{"op":"mcm","clk":"11450610226","pt":1717323807793,"mc":[{"id":"1.229554924","rc":[{"atb":[[1.99,0]],"id":52671121}],"con":true,"img":false}]}
{"op":"mcm","clk":"11450610305","pt":1717323808783,"mc":[{"id":"1.229554924","rc":[{"atb":[[2.02,0]],"id":52671121}],"con":true,"img":false}]}
{"op":"mcm","clk":"11450610313","pt":1717323808887,"mc":[{"id":"1.229554924","rc":[{"atb":[[1.98,4.22]],"id":52671121}],"con":true,"img":false}]}
{"op":"mcm","clk":"11450610377","pt":1717323809568,"mc":[{"id":"1.229554924","rc":[{"atb":[[2.04,13.48]],"id":52671121}],"con":true,"img":false}]}
{"op":"mcm","clk":"11450610513","pt":1717323811123,"mc":[{"id":"1.229554924","rc":[{"atl":[[2.24,35.82],[2.22,4.12]],"id":52671121},{"atb":[[1.79,10],[1.81,0]],"id":65460404}],"con":true,"img":false}]}
{"op":"mcm","clk":"11450610536","pt":1717323811288,"mc":[{"id":"1.229554924","rc":[{"atl":[[1000,1.51]],"id":65460404}],"con":true,"img":false}]}
{"op":"mcm","clk":"11450610549","pt":1717323811437,"mc":[{"id":"1.229554924","rc":[{"atl":[[1000,2.61]],"id":65460404}],"con":true,"img":false}]}
{"op":"mcm","clk":"11450610568","pt":1717323811595,"mc":[{"id":"1.229554924","rc":[{"atb":[[1.82,0]],"id":65460404},{"atl":[[1000,1.61]],"id":65460404}],"con":true,"img":false}]}
{"op":"mcm","clk":"11450610579","pt":1717323811698,"mc":[{"id":"1.229554924","rc":[{"atb":[[1.88,0],[1.78,0]],"id":52671121},{"atb":[[1.4,0],[1.5,0]],"id":65460404},{"atl":[[1000,0.86]],"id":65460404}],"con":true,"img":false}]}
{"op":"mcm","clk":"11450610588","pt":1717323811802,"mc":[{"id":"1.229554924","rc":[{"atl":[[1000,0.76]],"id":65460404}],"con":true,"img":false}]}
{"op":"mcm","clk":"11450610597","pt":1717323811911,"mc":[{"id":"1.229554924","rc":[{"trd":[[2.16,4.26]],"ltp":2.16,"tv":4.26,"id":52671121},{"atl":[[2.16,12.99]],"id":52671121},{"trd":[[1.86,0.1]],"ltp":1.86,"tv":0.1,"id":65460404}],"con":true,"img":false}]}
{"op":"mcm","clk":"11450610620","pt":1717323812118,"mc":[{"id":"1.229554924","rc":[{"atl":[[1000,0.62]],"id":65460404}],"con":true,"img":false}]}
{"op":"mcm","clk":"11450610630","pt":1717323812176,"mc":[{"id":"1.229554924","rc":[{"trd":[[2.16,4.39]],"ltp":2.16,"tv":4.39,"id":52671121},{"atl":[[2.16,12.86]],"id":52671121},{"trd":[[1.86,0.24]],"ltp":1.86,"tv":0.24,"id":65460404}],"con":true,"img":false}]}
{"op":"mcm","clk":"11450610704","pt":1717323812904,"mc":[{"id":"1.229554924","rc":[{"atb":[[2.04,0]],"id":52671121}],"con":true,"img":false}]}
{"op":"mcm","clk":"11450610712","pt":1717323813008,"mc":[{"id":"1.229554924","rc":[{"atb":[[1.99,13.48]],"id":52671121}],"con":true,"img":false}]}
{"op":"mcm","clk":"11450610722","pt":1717323813111,"mc":[{"id":"1.229554924","rc":[{"atb":[[2,18.84]],"id":52671121}],"con":true,"img":false}]}
{"op":"mcm","clk":"11450610770","pt":1717323813635,"mc":[{"id":"1.229554924","rc":[{"atb":[[2,48.67]],"id":52671121}],"con":true,"img":false}]}
{"op":"mcm","clk":"11450610851","pt":1717323814085,"mc":[{"id":"1.229554924","rc":[{"atb":[[2.04,13.61]],"id":52671121}],"con":true,"img":false}]}
{"op":"mcm","clk":"11450610871","pt":1717323814296,"mc":[{"id":"1.229554924","rc":[{"atb":[[2.04,0]],"id":52671121}],"con":true,"img":false}]}
{"op":"mcm","clk":"11450611020","pt":1717323815801,"mc":[{"id":"1.229554924","rc":[{"atl":[[2.24,18.52],[2.22,21.2]],"id":52671121},{"atb":[[1.8,52.21],[1.79,0]],"id":65460404}],"con":true,"img":false}]}
{"op":"mcm","clk":"11450611035","pt":1717323816009,"mc":[{"id":"1.229554924","rc":[{"atl":[[2.2,0]],"id":52671121},{"atb":[[1.83,0]],"id":65460404}],"con":true,"img":false}]}
{"op":"mcm","clk":"11450611046","pt":1717323816116,"mc":[{"id":"1.229554924","rc":[{"atb":[[1.82,36.36]],"id":65460404}],"con":true,"img":false}]}
{"op":"mcm","clk":"11450611059","pt":1717323816175,"mc":[{"id":"1.229554924","rc":[{"atb":[[2.04,15.61]],"id":52671121}],"con":true,"img":false}]}
{"op":"mcm","clk":"11450611069","pt":1717323816280,"mc":[{"id":"1.229554924","rc":[{"atl":[[2.24,0]],"id":52671121}],"con":true,"img":false}]}
{"op":"mcm","clk":"11450611088","pt":1717323816486,"mc":[{"id":"1.229554924","rc":[{"atl":[[2.2,4.03]],"id":52671121},{"atb":[[1.83,4.8]],"id":65460404}],"con":true,"img":false}]}
{"op":"mcm","clk":"11450611098","pt":1717323816593,"mc":[{"id":"1.229554924","rc":[{"atb":[[2,29.82],[1.99,0]],"id":52671121}],"con":true,"img":false}]}
{"op":"mcm","clk":"11450611153","pt":1717323817109,"mc":[{"id":"1.229554924","rc":[{"atb":[[2,0],[1.99,30.12]],"id":52671121},{"atl":[[2.2,0]],"id":52671121}],"con":true,"img":false}]}
{"op":"mcm","clk":"11450611208","pt":1717323817589,"mc":[{"id":"1.229554924","rc":[{"atb":[[1.83,0]],"id":65460404}],"con":true,"img":false}]}
{"op":"mcm","clk":"11450611288","pt":1717323818211,"mc":[{"id":"1.229554924","rc":[{"atb":[[1.81,4.83]],"id":65460404}],"con":true,"img":false}]}
{"op":"mcm","clk":"11450611297","pt":1717323818315,"mc":[{"id":"1.229554924","rc":[{"atb":[[2.02,13.12]],"id":52671121}],"con":true,"img":false}]}
{"op":"mcm","clk":"11450611319","pt":1717323818582,"mc":[{"id":"1.229554924","rc":[{"atb":[[1.95,0]],"id":52671121}],"con":true,"img":false}]}
{"op":"mcm","clk":"11450611424","pt":1717323819788,"mc":[{"id":"1.229554924","rc":[{"atl":[[2.16,0]],"id":52671121}],"con":true,"img":false}]}
{"op":"mcm","clk":"11450611437","pt":1717323819893,"mc":[{"id":"1.229554924","rc":[{"atl":[[2.12,12.86]],"id":52671121}],"con":true,"img":false}]}
{"op":"mcm","clk":"11450611449","pt":1717323819999,"mc":[{"id":"1.229554924","rc":[{"atb":[[1.83,4.82]],"id":65460404}],"con":true,"img":false}]}
{"op":"mcm","clk":"11450611459","pt":1717323820106,"mc":[{"id":"1.229554924","rc":[{"atb":[[2.04,44.28]],"id":52671121}],"con":true,"img":false}]}
{"op":"mcm","clk":"11450611567","pt":1717323820999,"mc":[{"id":"1.229554924","rc":[{"atb":[[1.98,4.13]],"id":52671121},{"atl":[[2.2,4.03]],"id":52671121}],"con":true,"img":false}]}
{"op":"mcm","clk":"11450611579","pt":1717323821105,"mc":[{"id":"1.229554924","rc":[{"atb":[[1.96,0.08]],"id":52671121}],"con":true,"img":false}]}
{"op":"mcm","clk":"11450611622","pt":1717323821516,"mc":[{"id":"1.229554924","rc":[{"atb":[[1.64,0],[1.69,132.68]],"id":52671121},{"atb":[[1.8,42.21],[1.78,10]],"id":65460404}],"con":true,"img":false}]}
{"op":"mcm","clk":"11450611662","pt":1717323821833,"mc":[{"id":"1.229554924","rc":[{"atb":[[1.97,12.22],[1.87,13.62]],"id":52671121},{"atb":[[1.27,14.53],[1.37,10.6]],"id":65460404}],"con":true,"img":false}]}
{"op":"mcm","clk":"11450611871","pt":1717323823411,"mc":[{"id":"1.229554924","rc":[{"atl":[[2.12,0]],"id":52671121}],"con":true,"img":false}]}
{"op":"mcm","clk":"11450611877","pt":1717323823513,"mc":[{"id":"1.229554924","rc":[{"atb":[[2.04,31.41]],"id":52671121},{"trd":[[2.04,53.36]],"ltp":2.04,"tv":53.36,"id":52671121},{"atl":[[2.26,21.16]],"id":52671121}],"con":true,"img":false}]}
{"op":"mcm","clk":"11450611883","pt":1717323823615,"mc":[{"id":"1.229554924","rc":[{"atl":[[2.22,4.12]],"id":52671121}],"con":true,"img":false}]}
{"op":"mcm","clk":"11450611923","pt":1717323824092,"mc":[{"id":"1.229554924","rc":[{"atb":[[2.04,2.74]],"id":52671121},{"atb":[[1.82,0]],"id":65460404}],"con":true,"img":false}]}
{"op":"mcm","clk":"11450611978","pt":1717323824715,"mc":[{"id":"1.229554924","rc":[{"atb":[[1.96,0]],"id":52671121}],"con":true,"img":false}]}
{"op":"mcm","clk":"11450611989","pt":1717323824829,"mc":[{"id":"1.229554924","rc":[{"atb":[[2,0.08]],"id":52671121},{"trd":[[2.22,4.12],[2.2,4.03]],"ltp":2.22,"tv":8.15,"id":52671121},{"atl":[[2.22,0],[2.2,0]],"id":52671121},{"atb":[[1.83,0],[1.81,0]],"id":65460404},{"trd":[[1.81,14.72],[1.83,44.61]],"ltp":1.81,"tv":59.33,"id":65460404},{"atl":[[1.81,10.87]],"id":65460404}],"con":true,"img":false}]}
{"op":"mcm","clk":"11450611998","pt":1717323824923,"mc":[{"id":"1.229554924","rc":[{"atb":[[2.06,4.09]],"id":52671121},{"trd":[[1.81,36.46]],"ltp":1.81,"tv":36.46,"id":65460404},{"atl":[[1.81,0]],"id":65460404}],"con":true,"img":false}]}
{"op":"mcm","clk":"11450612015","pt":1717323825086,"mc":[{"id":"1.229554924","rc":[{"atb":[[1.8,4.93]],"id":65460404}],"con":true,"img":false}]}
{"op":"mcm","clk":"11450612074","pt":1717323825613,"mc":[{"id":"1.229554924","rc":[{"atb":[[2.02,42.36]],"id":52671121},{"atb":[[1.79,37.75]],"id":65460404}],"con":true,"img":false}]}
{"op":"mcm","clk":"11450612116","pt":1717323825928,"mc":[{"id":"1.229554924","rc":[{"atb":[[2,0]],"id":52671121}],"con":true,"img":false}]}
{"op":"mcm","clk":"11450612132","pt":1717323826029,"mc":[{"id":"1.229554924","rc":[{"atb":[[2.06,4.18]],"id":52671121}],"con":true,"img":false}]}
{"op":"mcm","clk":"11450612141","pt":1717323826133,"mc":[{"id":"1.229554924","rc":[{"atb":[[2.08,9.65]],"id":52671121}],"con":true,"img":false}]}
{"op":"mcm","clk":"11450612158","pt":1717323826302,"mc":[{"id":"1.229554924","rc":[{"atb":[[2.02,29.23]],"id":52671121}],"con":true,"img":false}]}
{"op":"mcm","clk":"11450612188","pt":1717323826609,"mc":[{"id":"1.229554924","rc":[{"atb":[[2.02,0]],"id":52671121},{"atb":[[1.79,42.54],[1.78,0]],"id":65460404}],"con":true,"img":false}]}
{"op":"mcm","clk":"11450612223","pt":1717323826920,"mc":[{"id":"1.229554924","rc":[{"atb":[[2.1,4.03]],"id":52671121}],"con":true,"img":false}]}
{"op":"mcm","clk":"11450612244","pt":1717323827128,"mc":[{"id":"1.229554924","rc":[{"atl":[[2.24,4.01]],"id":52671121}],"con":true,"img":false}]}
{"op":"mcm","clk":"11450612299","pt":1717323827607,"mc":[{"id":"1.229554924","rc":[{"atb":[[2.02,29.23]],"id":52671121}],"con":true,"img":false}]}
{"op":"mcm","clk":"11450612308","pt":1717323827711,"mc":[{"id":"1.229554924","rc":[{"atb":[[2.1,0]],"id":52671121}],"con":true,"img":false}]}
{"op":"mcm","clk":"11450612346","pt":1717323828118,"mc":[{"id":"1.229554924","rc":[{"atb":[[2.02,0]],"id":52671121}],"con":true,"img":false}]}
{"op":"mcm","clk":"11450612355","pt":1717323828225,"mc":[{"id":"1.229554924","rc":[{"atb":[[2.08,13.7]],"id":52671121}],"con":true,"img":false}]}
{"op":"mcm","clk":"11450612362","pt":1717323828326,"mc":[{"id":"1.229554924","rc":[{"atb":[[2.02,7.21]],"id":52671121}],"con":true,"img":false}]}
{"op":"mcm","clk":"11450612389","pt":1717323828589,"mc":[{"id":"1.229554924","rc":[{"atb":[[2.04,31.41],[2.06,4.09]],"id":52671121},{"atl":[[2.24,7.98],[2.26,3.92]],"id":52671121}],"con":true,"img":false}]}
{"op":"mcm","clk":"11450612399","pt":1717323828697,"mc":[{"id":"1.229554924","rc":[{"atb":[[2.04,31.5]],"id":52671121}],"con":true,"img":false}]}
{"op":"mcm","clk":"11450612440","pt":1717323829112,"mc":[{"id":"1.229554924","rc":[{"atb":[[1.79,4.79]],"id":65460404}],"con":true,"img":false}]}
{"op":"mcm","clk":"11450612451","pt":1717323829216,"mc":[{"id":"1.229554924","rc":[{"atb":[[1.89,0],[2.1,4.04]],"id":52671121}],"con":true,"img":false}]}
{"op":"mcm","clk":"11450612467","pt":1717323829418,"mc":[{"id":"1.229554924","rc":[{"atb":[[2.12,9.47]],"id":52671121},{"atl":[[2.22,4.01]],"id":52671121}],"con":true,"img":false}]}
{"op":"mcm","clk":"11450612479","pt":1717323829624,"mc":[{"id":"1.229554924","rc":[{"atb":[[2.02,0]],"id":52671121},{"atb":[[1.61,48.89]],"id":65460404}],"con":true,"img":false}]}
{"op":"mcm","clk":"11450612581","pt":1717323830822,"mc":[{"id":"1.229554924","rc":[{"atb":[[2.04,31.41],[2.1,0]],"id":52671121}],"con":true,"img":false}]}
{"op":"mcm","clk":"11450612588","pt":1717323830928,"mc":[{"id":"1.229554924","rc":[{"atb":[[2.02,0.08]],"id":52671121}],"con":true,"img":false}]}
{"op":"mcm","clk":"11450612600","pt":1717323831032,"mc":[{"id":"1.229554924","rc":[{"atb":[[2.12,0]],"id":52671121}],"con":true,"img":false}]}
{"op":"mcm","clk":"11450612606","pt":1717323831137,"mc":[{"id":"1.229554924","rc":[{"atb":[[1.61,0]],"id":65460404}],"con":true,"img":false}]}
{"op":"mcm","clk":"11450612620","pt":1717323831240,"mc":[{"id":"1.229554924","rc":[{"atb":[[2.1,4.03]],"id":52671121}],"con":true,"img":false}]}
{"op":"mcm","clk":"11450612642","pt":1717323831403,"mc":[{"id":"1.229554924","rc":[{"atb":[[2.12,9.47]],"id":52671121}],"con":true,"img":false}]}
{"op":"mcm","clk":"11450612659","pt":1717323831614,"mc":[{"id":"1.229554924","rc":[{"atb":[[2.12,0]],"id":52671121}],"con":true,"img":false}]}
{"op":"mcm","clk":"11450612860","pt":1717323833337,"mc":[{"id":"1.229554924","rc":[{"atb":[[2.12,9.47]],"id":52671121}],"con":true,"img":false}]}
{"op":"mcm","clk":"11450612881","pt":1717323833611,"mc":[{"id":"1.229554924","rc":[{"atb":[[1.61,48.89]],"id":65460404}],"con":true,"img":false}]}
{"op":"mcm","clk":"11450612957","pt":1717323834533,"mc":[{"id":"1.229554924","rc":[{"atb":[[2.1,0]],"id":52671121}],"con":true,"img":false}]}
{"op":"mcm","clk":"11450612969","pt":1717323834742,"mc":[{"id":"1.229554924","rc":[{"atb":[[2.12,0]],"id":52671121}],"con":true,"img":false}]}
{"op":"mcm","clk":"11450613007","pt":1717323835121,"mc":[{"id":"1.229554924","rc":[{"atb":[[2.02,29.32],[2.04,2.74]],"id":52671121},{"atb":[[1.61,0]],"id":65460404}],"con":true,"img":false}]}
{"op":"mcm","clk":"11450613017","pt":1717323835225,"mc":[{"id":"1.229554924","rc":[{"atb":[[1.79,0]],"id":65460404}],"con":true,"img":false}]}
{"op":"mcm","clk":"11450613025","pt":1717323835324,"mc":[{"id":"1.229554924","rc":[{"atb":[[1.78,10]],"id":65460404}],"con":true,"img":false}]}
{"op":"mcm","clk":"11450613037","pt":1717323835428,"mc":[{"id":"1.229554924","rc":[{"atb":[[2.1,4.04]],"id":52671121}],"con":true,"img":false}]}
{"op":"mcm","clk":"11450613055","pt":1717323835637,"mc":[{"id":"1.229554924","rc":[{"atb":[[2.12,9.52],[2.1,0]],"id":52671121}],"con":true,"img":false}]}
{"op":"mcm","clk":"11450613072","pt":1717323835844,"mc":[{"id":"1.229554924","rc":[{"atb":[[2.12,0],[2.08,9.65]],"id":52671121}],"con":true,"img":false}]}
{"op":"mcm","clk":"11450613093","pt":1717323836122,"mc":[{"id":"1.229554924","rc":[{"atb":[[2.02,0.08]],"id":52671121},{"atb":[[1.79,37.75]],"id":65460404}],"con":true,"img":false}]}
{"op":"mcm","clk":"11450613238","pt":1717323837519,"mc":[{"id":"1.229554924","rc":[{"atb":[[2.02,7.32]],"id":52671121},{"atl":[[2.2,12.35]],"id":52671121}],"con":true,"img":false}]}
{"op":"mcm","clk":"11450613292","pt":1717323838136,"mc":[{"id":"1.229554924","rc":[{"atb":[[2.04,31.41]],"id":52671121}],"con":true,"img":false}]}
{"op":"mcm","clk":"11450613310","pt":1717323838342,"mc":[{"id":"1.229554924","rc":[{"atl":[[2.2,0]],"id":52671121}],"con":true,"img":false}]}
{"op":"mcm","clk":"11450613360","pt":1717323838823,"mc":[{"id":"1.229554924","rc":[{"atb":[[2.02,7.23]],"id":52671121}],"con":true,"img":false}]}
{"op":"mcm","clk":"11450613370","pt":1717323838922,"mc":[{"id":"1.229554924","rc":[{"atb":[[2,0.08]],"id":52671121}],"con":true,"img":false}]}
{"op":"mcm","clk":"11450613390","pt":1717323839124,"mc":[{"id":"1.229554924","rc":[{"atb":[[2.04,2.74],[2.02,36.47]],"id":52671121}],"con":true,"img":false}]}
{"op":"mcm","clk":"11450613439","pt":1717323839488,"mc":[{"id":"1.229554924","rc":[{"atl":[[2.22,14.36]],"id":52671121}],"con":true,"img":false}]}
{"op":"mcm","clk":"11450613499","pt":1717323840058,"mc":[{"id":"1.229554924","rc":[{"atb":[[2,0]],"id":52671121}],"con":true,"img":false}]}
{"op":"mcm","clk":"11450613504","pt":1717323840163,"mc":[{"id":"1.229554924","rc":[{"atb":[[2.02,36.56]],"id":52671121}],"con":true,"img":false}]}
{"op":"mcm","clk":"11450613517","pt":1717323840272,"mc":[{"id":"1.229554924","rc":[{"atl":[[2.28,0],[2.2,4.07]],"id":52671121}],"con":true,"img":false}]}
{"op":"mcm","clk":"11450613525","pt":1717323840379,"mc":[{"id":"1.229554924","rc":[{"atb":[[2.08,0]],"id":52671121},{"trd":[[2.08,19.3]],"ltp":2.08,"tv":19.3,"id":52671121},{"atl":[[2.08,21.21]],"id":52671121}],"con":true,"img":false}]}
{"op":"mcm","clk":"11450613536","pt":1717323840483,"mc":[{"id":"1.229554924","rc":[{"trd":[[2.08,27.48]],"ltp":2.08,"tv":27.48,"id":52671121},{"atl":[[2.22,4.01],[2.08,17.12]],"id":52671121},{"atb":[[1.79,47.75],[1.78,0]],"id":65460404}],"con":true,"img":false}]}
{"op":"mcm","clk":"11450613546","pt":1717323840588,"mc":[{"id":"1.229554924","rc":[{"atb":[[1.99,0],[2.02,7.32]],"id":52671121},{"trd":[[2.08,40.34]],"ltp":2.08,"tv":40.34,"id":52671121},{"atl":[[2.08,4.26]],"id":52671121},{"trd":[[1.92,13.92]],"ltp":1.92,"tv":13.92,"id":65460404}],"con":true,"img":false}]}
{"op":"mcm","clk":"11450613582","pt":1717323840849,"mc":[{"id":"1.229554924","rc":[{"atb":[[2.02,0.08],[2.04,0]],"id":52671121}],"con":true,"img":false}]}
{"op":"mcm","clk":"11450613590","pt":1717323840954,"mc":[{"id":"1.229554924","rc":[{"atb":[[1.8,14.93],[1.79,37.75]],"id":65460404}],"con":true,"img":false}]}
{"op":"mcm","clk":"11450613599","pt":1717323841060,"mc":[{"id":"1.229554924","rc":[{"atb":[[1.98,34.56]],"id":52671121}],"con":true,"img":false}]}
{"op":"mcm","clk":"11450613695","pt":1717323841875,"mc":[{"id":"1.229554924","rc":[{"atb":[[2.02,0],[2.06,0]],"id":52671121},{"atb":[[1.81,4.52]],"id":65460404},{"atl":[[1.97,0]],"id":65460404}],"con":true,"img":false}]}
{"op":"mcm","clk":"11450613706","pt":1717323841978,"mc":[{"id":"1.229554924","rc":[{"atb":[[1.94,0.08]],"id":52671121}],"con":true,"img":false}]}
{"op":"mcm","clk":"11450613719","pt":1717323842082,"mc":[{"id":"1.229554924","rc":[{"atb":[[1.98,4.13],[1.95,31.39]],"id":52671121},{"atl":[[2.26,0],[2.08,8.56]],"id":52671121},{"atb":[[1.81,41.34]],"id":65460404},{"atl":[[2,0]],"id":65460404}],"con":true,"img":false}]}
{"op":"mcm","clk":"11450613738","pt":1717323842291,"mc":[{"id":"1.229554924","rc":[{"atb":[[1.82,4.48]],"id":65460404}],"con":true,"img":false}]}
{"op":"mcm","clk":"11450613773","pt":1717323842604,"mc":[{"id":"1.229554924","rc":[{"atb":[[1.98,0]],"id":52671121}],"con":true,"img":false}]}
{"op":"mcm","clk":"11450613999","pt":1717323844799,"mc":[{"id":"1.229554924","rc":[{"atl":[[2.08,4.29]],"id":52671121}],"con":true,"img":false}]}
{"op":"mcm","clk":"11450614009","pt":1717323844856,"mc":[{"id":"1.229554924","rc":[{"atl":[[2.04,0]],"id":65460404}],"con":true,"img":false}]}
{"op":"mcm","clk":"11450614027","pt":1717323845065,"mc":[{"id":"1.229554924","rc":[{"atb":[[1.94,31.81],[1.95,0]],"id":52671121},{"atl":[[2.36,14.71],[2.4,17.86],[2.06,0],[2.32,11.36],[2.22,2.66],[2.46,0],[2.44,20.83],[3.65,32.12]],"id":65460404}],"con":true,"img":false}]}
{"op":"mcm","clk":"11450614044","pt":1717323845280,"mc":[{"id":"1.229554924","rc":[{"atl":[[2.24,2.24],[2.32,12.21],[2.22,0],[2.46,29.42],[3.65,0]],"id":65460404}],"con":true,"img":false}]}
{"op":"mcm","clk":"11450614068","pt":1717323845482,"mc":[{"id":"1.229554924","rc":[{"atl":[[2.24,0],[2.26,2.67]],"id":65460404}],"con":true,"img":false}]}
{"op":"mcm","clk":"11450614096","pt":1717323845793,"mc":[{"id":"1.229554924","rc":[{"atl":[[2.08,8.56]],"id":52671121},{"atb":[[1.8,4.93],[1.79,40.42]],"id":65460404}],"con":true,"img":false}]}
{"op":"mcm","clk":"11450614124","pt":1717323846000,"mc":[{"id":"1.229554924","rc":[{"atb":[[1.83,6.32],[1.58,72.6],[1.93,0],[1.69,0]],"id":52671121},{"atl":[[2.24,4.01],[2.52,12.06],[2.66,0],[2.2,10.39]],"id":52671121},{"atb":[[1.56,0],[1.63,45.35]],"id":65460404},{"atl":[[2.32,0.85],[2.46,10.27],[2.62,32.57]],"id":65460404}],"con":true,"img":false}]}
{"op":"mcm","clk":"11450614190","pt":1717323846577,"mc":[{"id":"1.229554924","rc":[{"atb":[[1.94,0.08]],"id":52671121},{"atb":[[1.79,2.67]],"id":65460404}],"con":true,"img":false}]}
{"op":"mcm","clk":"11450614200","pt":1717323846681,"mc":[{"id":"1.229554924","rc":[{"atl":[[2.36,0],[2.24,4.35],[2.32,0]],"id":65460404}],"con":true,"img":false}]}
{"op":"mcm","clk":"11450614209","pt":1717323846784,"mc":[{"id":"1.229554924","rc":[{"atb":[[1.88,4.44],[1.94,4.51]],"id":52671121},{"atl":[[2.34,0.85]],"id":65460404}],"con":true,"img":false}]}
{"op":"mcm","clk":"11450614218","pt":1717323846897,"mc":[{"id":"1.229554924","rc":[{"atl":[[2.4,0],[2.46,0],[2.44,0]],"id":65460404}],"con":true,"img":false}]}
{"op":"mcm","clk":"11450614254","pt":1717323847307,"mc":[{"id":"1.229554924","rc":[{"atl":[[2.24,0],[2.06,4.39]],"id":52671121}],"con":true,"img":false}]}
{"op":"mcm","clk":"11450614287","pt":1717323847575,"mc":[{"id":"1.229554924","rc":[{"atb":[[1.97,0],[1.88,38.33],[1.87,0]],"id":52671121},{"atb":[[1.27,0],[1.37,0]],"id":65460404}],"con":true,"img":false}]}
{"op":"mcm","clk":"11450614355","pt":1717323848099,"mc":[{"id":"1.229554924","rc":[{"atb":[[1.88,4.44]],"id":52671121},{"atb":[[1.81,4.52]],"id":65460404}],"con":true,"img":false}]}
{"op":"mcm","clk":"11450614366","pt":1717323848206,"mc":[{"id":"1.229554924","rc":[{"atb":[[1.82,5.33]],"id":65460404}],"con":true,"img":false}]}
{"op":"mcm","clk":"11450614416","pt":1717323848580,"mc":[{"id":"1.229554924","rc":[{"atb":[[1.82,41.7]],"id":65460404}],"con":true,"img":false}]}
{"op":"mcm","clk":"11450614565","pt":1717323850002,"mc":[{"id":"1.229554924","rc":[{"atl":[[2.08,4.29]],"id":52671121}],"con":true,"img":false}]}
{"op":"mcm","clk":"11450614623","pt":1717323850580,"mc":[{"id":"1.229554924","rc":[{"atb":[[1.82,41.45]],"id":65460404},{"atl":[[2.26,0],[2.2,4.44]],"id":65460404}],"con":true,"img":false}]}
{"op":"mcm","clk":"11450614661","pt":1717323850896,"mc":[{"id":"1.229554924","rc":[{"atb":[[1.8,9.37],[1.79,0]],"id":65460404}],"con":true,"img":false}]}
{"op":"mcm","clk":"11450614684","pt":1717323851105,"mc":[{"id":"1.229554924","rc":[{"atl":[[2.08,8.56]],"id":52671121}],"con":true,"img":false}]}
{"op":"mcm","clk":"11450614694","pt":1717323851209,"mc":[{"id":"1.229554924","rc":[{"atl":[[2.18,4.39]],"id":65460404}],"con":true,"img":false}]}
{"op":"mcm","clk":"11450614716","pt":1717323851368,"mc":[{"id":"1.229554924","rc":[{"atl":[[2.2,0],[2.16,4.46]],"id":65460404}],"con":true,"img":false}]}
{"op":"mcm","clk":"11450614740","pt":1717323851579,"mc":[{"id":"1.229554924","rc":[{"atb":[[1.82,5.08]],"id":65460404}],"con":true,"img":false}]}
{"op":"mcm","clk":"11450614790","pt":1717323852092,"mc":[{"id":"1.229554924","rc":[{"atl":[[2.14,4.39]],"id":65460404}],"con":true,"img":false}]}
{"op":"mcm","clk":"11450615306","pt":1717323856220,"mc":[{"id":"1.229554924","rc":[{"atl":[[2.18,8.85],[2.16,0]],"id":65460404}],"con":true,"img":false}]}
{"op":"mcm","clk":"11450615357","pt":1717323856588,"mc":[{"id":"1.229554924","rc":[{"atb":[[1.82,4.48]],"id":65460404}],"con":true,"img":false}]}
{"op":"mcm","clk":"11450615368","pt":1717323856693,"mc":[{"id":"1.229554924","rc":[{"atb":[[1.64,0.6]],"id":65460404}],"con":true,"img":false}]}
{"op":"mcm","clk":"11450615799","pt":1717323860389,"mc":[{"id":"1.229554924","rc":[{"atb":[[1.8,4.93],[1.79,4.44]],"id":65460404}],"con":true,"img":false}]}
{"op":"mcm","clk":"11450615925","pt":1717323861320,"mc":[{"id":"1.229554924","rc":[{"atl":[[2.18,4.39],[2.2,4.44]],"id":65460404}],"con":true,"img":false}]}
{"op":"mcm","clk":"11450615941","pt":1717323861526,"mc":[{"id":"1.229554924","rc":[{"atb":[[1.94,0.08]],"id":52671121}],"con":true,"img":false}]}
{"op":"mcm","clk":"11450616149","pt":1717323863247,"mc":[{"id":"1.229554924","rc":[{"atb":[[1.99,11.97],[1.89,13.32]],"id":52671121},{"atb":[[1.23,17.06],[1.33,11.89]],"id":65460404}],"con":true,"img":false}]}
{"op":"mcm","clk":"11450616178","pt":1717323863409,"mc":[{"id":"1.229554924","rc":[{"atb":[[1.9,4.49]],"id":52671121}],"con":true,"img":false}]}
{"op":"mcm","clk":"11450616205","pt":1717323863618,"mc":[{"id":"1.229554924","rc":[{"atb":[[1.89,46.83]],"id":52671121},{"atb":[[1.82,40.85]],"id":65460404}],"con":true,"img":false}]}
{"op":"mcm","clk":"11450616247","pt":1717323864030,"mc":[{"id":"1.229554924","rc":[{"atb":[[1.83,4.32]],"id":65460404}],"con":true,"img":false}]}
{"op":"mcm","clk":"11450616614","pt":1717323867113,"mc":[{"id":"1.229554924","rc":[{"atb":[[1.99,0],[1.94,0]],"id":52671121},{"trd":[[1.94,0.17],[1.99,25.76]],"ltp":1.94,"tv":25.93,"id":52671121},{"atl":[[1.94,2.9]],"id":52671121}],"con":true,"img":false}]}
{"op":"mcm","clk":"11450616625","pt":1717323867218,"mc":[{"id":"1.229554924","rc":[{"trd":[[1.94,5.99]],"ltp":1.94,"tv":5.99,"id":52671121},{"atl":[[1.94,0]],"id":52671121}],"con":true,"img":false}]}
{"op":"mcm","clk":"11450616657","pt":1717323867638,"mc":[{"id":"1.229554924","rc":[{"atb":[[1.89,13.32],[1.84,35.5]],"id":52671121},{"atb":[[1.64,0]],"id":65460404}],"con":true,"img":false}]}
{"op":"mcm","clk":"11450616668","pt":1717323867693,"mc":[{"id":"1.229554924","rc":[{"atb":[[1.83,4.92]],"id":65460404}],"con":true,"img":false}]}
{"op":"mcm","clk":"11450616911","pt":1717323869923,"mc":[{"id":"1.229554924","rc":[{"atb":[[1.83,0],[1.84,39.96]],"id":52671121},{"atl":[[2.2,0],[2.16,4.46]],"id":65460404}],"con":true,"img":false}]}
{"op":"mcm","clk":"11450617068","pt":1717323871336,"mc":[{"id":"1.229554924","rc":[{"atb":[[1.9,1.58]],"id":52671121},{"trd":[[1.9,5.81]],"ltp":1.9,"tv":5.81,"id":52671121}],"con":true,"img":false}]}
{"op":"mcm","clk":"11450617605","pt":1717323875742,"mc":[{"id":"1.229554924","rc":[{"atl":[[2.06,0]],"id":52671121}],"con":true,"img":false}]}
{"op":"mcm","clk":"11450617627","pt":1717323876053,"mc":[{"id":"1.229554924","rc":[{"atb":[[1.89,14.17]],"id":52671121}],"con":true,"img":false}]}
{"op":"mcm","clk":"11450617653","pt":1717323876327,"mc":[{"id":"1.229554924","rc":[{"atb":[[1.84,35.5],[1.86,4.26]],"id":52671121},{"atl":[[2.14,8.85],[2.16,0]],"id":65460404}],"con":true,"img":false}]}
{"op":"mcm","clk":"11450617677","pt":1717323876532,"mc":[{"id":"1.229554924","rc":[{"atl":[[2.08,4.26]],"id":52671121},{"atl":[[2.12,4.35]],"id":65460404}],"con":true,"img":false}]}
{"op":"mcm","clk":"11450617685","pt":1717323876631,"mc":[{"id":"1.229554924","rc":[{"atb":[[1.84,0]],"id":52671121}],"con":true,"img":false}]}
{"op":"mcm","clk":"11450617735","pt":1717323877102,"mc":[{"id":"1.229554924","rc":[{"atb":[[1.88,38.33]],"id":52671121}],"con":true,"img":false}]}
{"op":"mcm","clk":"11450617803","pt":1717323877842,"mc":[{"id":"1.229554924","rc":[{"atb":[[1.89,13.94]],"id":52671121}],"con":true,"img":false}]}
{"op":"mcm","clk":"11450617812","pt":1717323877935,"mc":[{"id":"1.229554924","rc":[{"atb":[[1.64,72.6],[1.58,0]],"id":52671121},{"atl":[[2.08,8.57]],"id":52671121},{"atb":[[1.8,9.39],[1.79,0],[1.57,17.06]],"id":65460404},{"atl":[[2.5,8.72]],"id":65460404}],"con":true,"img":false}]}
{"op":"mcm","clk":"11450617825","pt":1717323878037,"mc":[{"id":"1.229554924","rc":[{"atb":[[1.63,0]],"id":65460404},{"atl":[[2.62,0]],"id":65460404}],"con":true,"img":false}]}
{"op":"mcm","clk":"11450617900","pt":1717323878829,"mc":[{"id":"1.229554924","rc":[{"atl":[[2.08,4.26]],"id":52671121}],"con":true,"img":false}]}
{"op":"mcm","clk":"11450618183","pt":1717323881541,"mc":[{"id":"1.229554924","rc":[{"atb":[[1.86,0],[1.87,4.18]],"id":52671121}],"con":true,"img":false}]}
{"op":"mcm","clk":"11450618339","pt":1717323883046,"mc":[{"id":"1.229554924","rc":[{"atb":[[1.82,45.31],[1.8,4.93]],"id":65460404}],"con":true,"img":false}]}
{"op":"mcm","clk":"11450619193","pt":1717323891380,"mc":[{"id":"1.229554924","marketDefinition":{"bspMarket":false,"turnInPlayEnabled":false,"persistenceEnabled":false,"marketBaseRate":7.0,"eventId":"33318908","eventTypeId":"4339","numberOfWinners":1,"bettingType":"ODDS","marketType":"MATCH_BET","marketTime":"2024-06-02T10:24:00.000Z","suspendTime":"2024-06-02T10:24:00.000Z","bspReconciled":false,"complete":true,"inPlay":false,"crossMatching":true,"runnersVoidable":false,"numberOfActiveRunners":2,"betDelay":0,"status":"SUSPENDED","runners":[{"status":"ACTIVE","sortPriority":1,"id":65460404,"name":"1. Give Me Room"},{"status":"ACTIVE","sortPriority":2,"id":52671121,"name":"2. Elegant Ritzy"}],"regulators":["MR_INT"],"venue":"Murray Bridge","countryCode":"AU","discountAllowed":true,"timezone":"Australia/Adelaide","openDate":"2024-06-02T08:21:00.000Z","version":5963127097,"name":"Give Me Room v Elegant Ritzy","eventName":"Murray Bridge (AUS) 2nd Jun"},"rc":[],"con":true,"img":false}]}
{"op":"mcm","clk":"11450619193","pt":1717323891380,"mc":[{"id":"1.229554924","rc":[{"atb":[[1.64,0],[1.89,0],[1.88,0],[1.02,0],[1.9,0],[1.13,0],[1.87,0]],"id":52671121},{"atl":[[2.22,0],[2.52,0],[2.2,0],[2.08,0],[980,0],[990,0],[1000,0]],"id":52671121},{"atb":[[1.83,0],[1.82,0],[1.8,0],[1.01,0],[1.81,0],[1.57,0],[1.23,0],[1.33,0]],"id":65460404},{"atl":[[2.24,0],[2.5,0],[2.12,0],[2.18,0],[2.14,0],[2.34,0],[970,0],[990,0],[1000,0]],"id":65460404}],"con":true,"img":false}]}
{"op":"mcm","clk":"11450631634","pt":1717324026246,"mc":[{"id":"1.229554924","rc":[{"trd":[[1.99,0],[2.02,0],[2.22,0],[2.04,0],[1.9,0],[1.94,0],[2.2,0],[2.16,0],[2.08,0]],"ltp":1.99,"tv":0.0,"id":52671121},{"trd":[[2,0],[1.83,0],[1.92,0],[1.81,0],[1.89,0],[1.98,0],[1.86,0],[1.96,0],[1.95,0]],"ltp":2.0,"tv":0.0,"id":65460404}],"con":true,"img":false}]}
{"op":"mcm","clk":"11450631716","pt":1717324027135,"mc":[{"id":"1.229554924","marketDefinition":{"bspMarket":false,"turnInPlayEnabled":false,"persistenceEnabled":false,"marketBaseRate":7.0,"eventId":"33318908","eventTypeId":"4339","numberOfWinners":1,"bettingType":"ODDS","marketType":"MATCH_BET","marketTime":"2024-06-02T10:24:00.000Z","suspendTime":"2024-06-02T10:24:00.000Z","bspReconciled":false,"complete":true,"inPlay":false,"crossMatching":false,"runnersVoidable":false,"numberOfActiveRunners":0,"betDelay":0,"status":"CLOSED","settledTime":"2024-06-02T10:27:04.000Z","runners":[{"status":"LOSER","sortPriority":1,"id":65460404,"name":"1. Give Me Room"},{"status":"WINNER","sortPriority":2,"id":52671121,"name":"2. Elegant Ritzy"}],"regulators":["MR_INT"],"venue":"Murray Bridge","countryCode":"AU","discountAllowed":true,"timezone":"Australia/Adelaide","openDate":"2024-06-02T08:21:00.000Z","version":5963127863,"name":"Give Me Room v Elegant Ritzy","eventName":"Murray Bridge (AUS) 2nd Jun"},"rc":[],"con":true,"img":false}]}
