{"op":"mcm","clk":"11449075381","pt":1717303241522,"mc":[{"id":"1.229554933","marketDefinition":{"bspMarket":false,"turnInPlayEnabled":false,"persistenceEnabled":false,"marketBaseRate":7.0,"eventId":"33318908","eventTypeId":"4339","numberOfWinners":1,"bettingType":"ODDS","marketType":"QUINELLA","marketTime":"2024-06-02T11:02:00.000Z","suspendTime":"2024-06-02T11:02:00.000Z","bspReconciled":false,"complete":true,"inPlay":false,"crossMatching":true,"runnersVoidable":false,"numberOfActiveRunners":6,"betDelay":0,"status":"OPEN","runners":[{"status":"ACTIVE","sortPriority":1,"id":52671544,"name":"1 - 4 / 4 - 1"},{"status":"ACTIVE","sortPriority":2,"id":52671545,"name":"1 - 6 / 6 - 1"},{"status":"ACTIVE","sortPriority":3,"id":52671546,"name":"1 - 8 / 8 - 1"},{"status":"ACTIVE","sortPriority":4,"id":52671554,"name":"4 - 6 / 6 - 4"},{"status":"ACTIVE","sortPriority":5,"id":52671555,"name":"4 - 8 / 8 - 4"},{"status":"ACTIVE","sortPriority":6,"id":52671556,"name":"6 - 8 / 8 - 6"}],"regulators":["MR_INT"],"venue":"Murray Bridge","countryCode":"AU","discountAllowed":true,"timezone":"Australia/Adelaide","openDate":"2024-06-02T08:21:00.000Z","version":5962801928,"name":"Quinella","eventName":"Murray Bridge (AUS) 2nd Jun"},"rc":[],"con":true,"img":false}]}
{"op":"mcm","clk":"11449099382","pt":1717303849562,"mc":[{"id":"1.229554933","rc":[{"atb":[[2.9,55.01],[2.7,143.47]],"id":52671546},{"atb":[[9.6,12.15],[7.6,36.95]],"id":52671545},{"atb":[[1.45,232.29],[1.35,696.87]],"id":52671544},{"atb":[[3.1,49.77],[2.84,132.55]],"id":52671555},{"atb":[[10.5,11],[8.2,33.87]],"id":52671554},{"atb":[[18.5,5.97],[13.5,19.51]],"id":52671556}],"con":true,"img":false}]}
{"op":"mcm","clk":"11449371144","pt":1717308120469,"mc":[{"id":"1.229554933","rc":[{"atb":[[3,52.32],[3.25,34.88],[3.5,20.93],[3.75,9.51]],"id":52671546},{"atb":[[16.5,3.37],[19,1.45],[11.5,9.97],[14,6.04]],"id":52671545},{"atb":[[1.4,261.59],[1.45,406.68],[1.55,47.56],[1.5,104.64]],"id":52671544},{"atb":[[3.6,30.18],[3.85,18.36],[3.35,44.53],[4.2,8.18]],"id":52671555},{"atb":[[16,5.23],[18.5,2.99],[22,1.25],[13.5,8.37]],"id":52671554},{"atb":[[34,2.38],[44,1.22],[27,4.02],[60,0.44]],"id":52671556}],"con":true,"img":false}]}
{"op":"mcm","clk":"11449371597","pt":1717308131121,"mc":[{"id":"1.229554933","rc":[{"atb":[[3,0],[3.25,0],[3.5,0],[3.75,0]],"id":52671546}],"con":true,"img":false}]}
{"op":"mcm","clk":"11449371635","pt":1717308131806,"mc":[{"id":"1.229554933","rc":[{"atb":[[4,8.72],[3.25,46.51],[3.5,31.39],[3.75,19.02]],"id":52671546}],"con":true,"img":false}]}
{"op":"mcm","clk":"11449497945","pt":1717309918992,"mc":[{"id":"1.229554933","rc":[{"atb":[[16.5,0],[19,0],[11.5,0],[14,0]],"id":52671545}],"con":true,"img":false}]}
{"op":"mcm","clk":"11449497993","pt":1717309919718,"mc":[{"id":"1.229554933","rc":[{"atb":[[18,3.08],[21,1.31],[13,8.72],[15.5,5.41]],"id":52671545}],"con":true,"img":false}]}
{"op":"mcm","clk":"11449586508","pt":1717311439794,"mc":[{"id":"1.229554933","rc":[{"atb":[[1.03,5.96]],"id":52671546},{"atl":[[1000,0.85]],"id":52671546},{"atb":[[1.01,17.89]],"id":52671545},{"atl":[[1000,0.85]],"id":52671545},{"atb":[[1.01,17.89]],"id":52671544},{"atl":[[990,0.85]],"id":52671544},{"atb":[[1.02,8.94]],"id":52671555},{"atl":[[990,0.85]],"id":52671555},{"atb":[[1.01,17.89]],"id":52671554},{"atl":[[990,0.85]],"id":52671554},{"atb":[[1.01,17.89]],"id":52671556},{"atl":[[990,0.85]],"id":52671556}],"con":true,"img":false}]}
{"op":"mcm","clk":"11449624324","pt":1717312169412,"mc":[{"id":"1.229554933","rc":[{"atb":[[2.9,0],[2.7,0]],"id":52671546},{"atb":[[9.6,0],[7.6,0]],"id":52671545},{"atb":[[1.45,174.39],[1.35,0]],"id":52671544},{"atb":[[3.1,0],[2.84,0]],"id":52671555},{"atb":[[10.5,0],[8.2,0]],"id":52671554},{"atb":[[18.5,0],[13.5,0]],"id":52671556}],"con":true,"img":false}]}
{"op":"mcm","clk":"11449625465","pt":1717312196239,"mc":[{"id":"1.229554933","rc":[{"atb":[[3.1,49.77],[2.84,132.55]],"id":52671555},{"atb":[[10.5,11],[8.2,33.87]],"id":52671554},{"atb":[[18.5,5.97],[13.5,19.51]],"id":52671556}],"con":true,"img":false}]}
{"op":"mcm","clk":"11449625470","pt":1717312196390,"mc":[{"id":"1.229554933","rc":[{"atb":[[2.9,55.01],[2.7,143.47]],"id":52671546},{"atb":[[9.6,12.15],[7.6,36.95]],"id":52671545},{"atb":[[1.45,406.68],[1.35,696.87]],"id":52671544}],"con":true,"img":false}]}
{"op":"mcm","clk":"11449626456","pt":1717312220693,"mc":[{"id":"1.229554933","rc":[{"atb":[[2.9,0],[2.7,0]],"id":52671546},{"atb":[[9.6,0],[7.6,0]],"id":52671545},{"atb":[[1.45,174.39],[1.35,0]],"id":52671544},{"atb":[[3.1,0],[2.84,0]],"id":52671555},{"atb":[[10.5,0],[8.2,0]],"id":52671554},{"atb":[[18.5,0],[13.5,0]],"id":52671556}],"con":true,"img":false}]}
{"op":"mcm","clk":"11449626906","pt":1717312229610,"mc":[{"id":"1.229554933","rc":[{"atb":[[2.9,55.01],[2.7,143.47]],"id":52671546},{"atb":[[9.6,12.15],[7.6,36.95]],"id":52671545},{"atb":[[1.45,406.68],[1.35,696.87]],"id":52671544},{"atb":[[3.1,49.77],[2.84,132.55]],"id":52671555},{"atb":[[10.5,11],[8.2,33.87]],"id":52671554},{"atb":[[18.5,5.97],[13.5,19.51]],"id":52671556}],"con":true,"img":false}]}
{"op":"mcm","clk":"11449630237","pt":1717312316541,"mc":[{"id":"1.229554933","rc":[{"atb":[[3.6,0],[3.85,0],[3.35,0],[4.2,0]],"id":52671555}],"con":true,"img":false}]}
{"op":"mcm","clk":"11449630260","pt":1717312317212,"mc":[{"id":"1.229554933","rc":[{"atb":[[4.3,7.93],[3.4,43.6],[3.9,18.04],[3.65,29.61]],"id":52671555}],"con":true,"img":false}]}
{"op":"mcm","clk":"11449632431","pt":1717312371107,"mc":[{"id":"1.229554933","rc":[{"atb":[[1.4,0],[1.45,232.29],[1.55,0],[1.5,0]],"id":52671544}],"con":true,"img":false}]}
{"op":"mcm","clk":"11449632458","pt":1717312371775,"mc":[{"id":"1.229554933","rc":[{"atb":[[1.44,178.36],[1.54,48.44],[1.49,106.77],[1.39,268.3]],"id":52671544}],"con":true,"img":false}]}
{"op":"mcm","clk":"11449686772","pt":1717313524444,"mc":[{"id":"1.229554933","rc":[{"atb":[[16,0],[18.5,0],[22,0],[13.5,0]],"id":52671554},{"atb":[[34,0],[44,0],[27,0],[60,0]],"id":52671556}],"con":true,"img":false}]}
{"op":"mcm","clk":"11449686824","pt":1717313525160,"mc":[{"id":"1.229554933","rc":[{"atb":[[16.5,5.06],[19,2.91],[23,1.19],[14,8.05]],"id":52671554},{"atb":[[65,0.41],[36,2.24],[46,1.16],[28,3.88]],"id":52671556}],"con":true,"img":false}]}
{"op":"mcm","clk":"11449710373","pt":1717313811625,"mc":[{"id":"1.229554933","rc":[{"atb":[[4.3,0],[3.4,0],[3.9,0],[3.65,0]],"id":52671555}],"con":true,"img":false}]}
{"op":"mcm","clk":"11449710494","pt":1717313813015,"mc":[{"id":"1.229554933","rc":[{"atb":[[3.45,42.71],[3.95,17.74],[3.7,29.07],[4.4,7.7]],"id":52671555}],"con":true,"img":false}]}
{"op":"mcm","clk":"11449818832","pt":1717315029321,"mc":[{"id":"1.229554933","rc":[{"atl":[[1000,0.17]],"id":52671546},{"atl":[[1000,0.17]],"id":52671545},{"atl":[[990,0.17]],"id":52671544},{"atl":[[990,0.17]],"id":52671555},{"atl":[[990,0.17]],"id":52671554},{"atl":[[990,0.17]],"id":52671556}],"con":true,"img":false}]}
{"op":"mcm","clk":"11449862846","pt":1717315412340,"mc":[{"id":"1.229554933","rc":[{"atb":[[2.9,0],[2.7,0]],"id":52671546},{"atb":[[9.6,0],[7.6,0]],"id":52671545},{"atb":[[1.45,0],[1.35,0]],"id":52671544},{"atb":[[3.1,0],[2.84,0]],"id":52671555},{"atb":[[10.5,0],[8.2,0]],"id":52671554},{"atb":[[18.5,0],[13.5,0]],"id":52671556}],"con":true,"img":false}]}
{"op":"mcm","clk":"11449866542","pt":1717315447498,"mc":[{"id":"1.229554933","rc":[{"atb":[[2.9,55.01],[2.7,143.47]],"id":52671546},{"atb":[[9.6,12.15],[7.6,36.95]],"id":52671545},{"atb":[[1.45,232.29],[1.35,696.87]],"id":52671544},{"atb":[[3.1,49.77],[2.84,132.55]],"id":52671555},{"atb":[[10.5,11],[8.2,33.87]],"id":52671554},{"atb":[[18.5,5.97],[13.5,19.51]],"id":52671556}],"con":true,"img":false}]}
{"op":"mcm","clk":"11449874242","pt":1717315519850,"mc":[{"id":"1.229554933","rc":[{"atb":[[2.9,0],[2.7,0]],"id":52671546},{"atb":[[9.6,0],[7.6,0]],"id":52671545},{"atb":[[1.45,0],[1.35,0]],"id":52671544},{"atb":[[3.1,0],[2.84,0]],"id":52671555},{"atb":[[10.5,0],[8.2,0]],"id":52671554},{"atb":[[18.5,0],[13.5,0]],"id":52671556}],"con":true,"img":false}]}
{"op":"mcm","clk":"11449876417","pt":1717315542090,"mc":[{"id":"1.229554933","rc":[{"atb":[[2.86,56.19],[2.66,146.92]],"id":52671546},{"atb":[[9.6,12.15],[7.6,36.95]],"id":52671545},{"atb":[[1.45,232.29],[1.35,696.87]],"id":52671544},{"atb":[[3.2,47.51],[2.88,129.73]],"id":52671555},{"atb":[[11,10.45],[8.4,32.96]],"id":52671554},{"atb":[[18.5,5.97],[13.5,19.51]],"id":52671556}],"con":true,"img":false}]}
{"op":"mcm","clk":"11449938382","pt":1717316154630,"mc":[{"id":"1.229554933","rc":[{"atb":[[18,0],[21,0],[13,0],[15.5,0]],"id":52671545},{"atb":[[3.45,0],[3.95,0],[3.7,0],[4.4,0]],"id":52671555}],"con":true,"img":false}]}
{"op":"mcm","clk":"11449938393","pt":1717316154732,"mc":[{"id":"1.229554933","rc":[{"atb":[[4,0],[3.25,0],[3.5,0],[3.75,0]],"id":52671546}],"con":true,"img":false}]}
{"op":"mcm","clk":"11449938448","pt":1717316155302,"mc":[{"id":"1.229554933","rc":[{"atb":[[4.3,7.93],[3.4,43.6],[3.9,18.04],[3.65,29.61]],"id":52671555}],"con":true,"img":false}]}
{"op":"mcm","clk":"11449938461","pt":1717316155404,"mc":[{"id":"1.229554933","rc":[{"atb":[[3.8,9.34],[3.55,20.52],[3.3,34.12],[3.05,51.04]],"id":52671546},{"atb":[[17.5,3.17],[20,1.38],[12.5,9.1],[15,5.6]],"id":52671545}],"con":true,"img":false}]}
{"op":"mcm","clk":"11449939800","pt":1717316169827,"mc":[{"id":"1.229554933","rc":[{"atb":[[3.8,0],[3.55,0],[3.3,0],[3.05,0]],"id":52671546},{"atb":[[17.5,0],[20,0],[12.5,0],[15,0]],"id":52671545},{"atb":[[16.5,0],[19,0],[23,0],[14,0]],"id":52671554},{"atb":[[65,0],[36,0],[46,0],[28,0]],"id":52671556}],"con":true,"img":false}]}
{"op":"mcm","clk":"11449939870","pt":1717316170547,"mc":[{"id":"1.229554933","rc":[{"atb":[[3,52.32],[3.25,34.88],[3.5,20.93],[3.75,9.51]],"id":52671546},{"atb":[[17,3.27],[19.5,1.41],[12,9.51],[14.5,5.81]],"id":52671545},{"atb":[[17,4.9],[19.5,2.83],[24,1.14],[14.5,7.75]],"id":52671554},{"atb":[[34,2.38],[44,1.22],[27,4.02],[60,0.44]],"id":52671556}],"con":true,"img":false}]}
{"op":"mcm","clk":"11449970527","pt":1717316552974,"mc":[{"id":"1.229554933","rc":[{"atb":[[2.86,0],[2.66,0]],"id":52671546},{"atb":[[9.6,0],[7.6,0]],"id":52671545},{"atb":[[1.45,0],[1.35,0]],"id":52671544},{"atb":[[3.2,0],[2.88,0]],"id":52671555},{"atb":[[11,0],[8.4,0]],"id":52671554},{"atb":[[18.5,0],[13.5,0]],"id":52671556}],"con":true,"img":false}]}
{"op":"mcm","clk":"11449972397","pt":1717316581815,"mc":[{"id":"1.229554933","rc":[{"atb":[[2.86,56.19],[2.66,146.92]],"id":52671546},{"atb":[[9.6,12.15],[7.6,36.95]],"id":52671545},{"atb":[[1.45,232.29],[1.35,696.87]],"id":52671544},{"atb":[[3.2,47.51],[2.88,129.73]],"id":52671555},{"atb":[[11,10.45],[8.4,32.96]],"id":52671554},{"atb":[[18.5,5.97],[13.5,19.51]],"id":52671556}],"con":true,"img":false}]}
{"op":"mcm","clk":"11450020035","pt":1717317157587,"mc":[{"id":"1.229554933","rc":[{"atb":[[4.3,0],[3.4,0],[3.9,0],[3.65,0]],"id":52671555}],"con":true,"img":false}]}
{"op":"mcm","clk":"11450020113","pt":1717317158260,"mc":[{"id":"1.229554933","rc":[{"atb":[[4,17.44],[4.5,7.48],[3.5,41.85],[3.75,28.54]],"id":52671555}],"con":true,"img":false}]}
{"op":"mcm","clk":"11450068130","pt":1717317644469,"mc":[{"id":"1.229554933","rc":[{"atb":[[2.86,0],[2.66,0]],"id":52671546},{"atb":[[9.6,0],[7.6,0]],"id":52671545},{"atb":[[1.45,0],[1.35,0]],"id":52671544},{"atb":[[3.2,0],[2.88,0]],"id":52671555},{"atb":[[11,0],[8.4,0]],"id":52671554},{"atb":[[18.5,0],[13.5,0]],"id":52671556}],"con":true,"img":false}]}
{"op":"mcm","clk":"11450071080","pt":1717317676095,"mc":[{"id":"1.229554933","rc":[{"atb":[[2.86,56.19],[2.66,146.92]],"id":52671546},{"atb":[[9.6,12.15],[7.6,36.95]],"id":52671545},{"atb":[[1.45,232.29],[1.35,696.87]],"id":52671544},{"atb":[[3.2,47.51],[2.88,129.73]],"id":52671555},{"atb":[[11,10.45],[8.4,32.96]],"id":52671554},{"atb":[[18.5,5.97],[13.5,19.51]],"id":52671556}],"con":true,"img":false}]}
{"op":"mcm","clk":"11450083402","pt":1717317813744,"mc":[{"id":"1.229554933","rc":[{"atb":[[17,0],[19.5,0],[12,0],[14.5,0]],"id":52671545},{"atb":[[4,0],[4.5,0],[3.5,0],[3.75,0]],"id":52671555},{"atb":[[34,0],[44,0],[27,0],[60,0]],"id":52671556}],"con":true,"img":false}]}
{"op":"mcm","clk":"11450083449","pt":1717317814418,"mc":[{"id":"1.229554933","rc":[{"atb":[[17.5,3.17],[20,1.38],[12.5,9.1],[15,5.6]],"id":52671545},{"atb":[[3.45,42.71],[3.95,17.74],[3.7,29.07],[4.4,7.7]],"id":52671555},{"atb":[[65,0.41],[36,2.24],[46,1.16],[28,3.88]],"id":52671556}],"con":true,"img":false}]}
{"op":"mcm","clk":"11450128184","pt":1717318324261,"mc":[{"id":"1.229554933","rc":[{"atb":[[2.86,0],[2.66,0]],"id":52671546},{"atb":[[9.6,0],[7.6,0]],"id":52671545},{"atb":[[1.45,0],[1.35,0]],"id":52671544},{"atb":[[3.2,0],[2.88,0]],"id":52671555},{"atb":[[11,0],[8.4,0]],"id":52671554},{"atb":[[18.5,0],[13.5,0]],"id":52671556}],"con":true,"img":false}]}
{"op":"mcm","clk":"11450129281","pt":1717318336161,"mc":[{"id":"1.229554933","rc":[{"atb":[[2.82,57.43],[2.62,150.55]],"id":52671546},{"atb":[[10.5,11],[8.2,33.87]],"id":52671545},{"atb":[[1.44,415.93],[1.34,717.36]],"id":52671544},{"atb":[[3.2,47.51],[2.88,129.73]],"id":52671555},{"atb":[[9.2,29.74],[13,8.71]],"id":52671554},{"atb":[[19.5,5.65],[14.5,18.06]],"id":52671556}],"con":true,"img":false}]}
{"op":"mcm","clk":"11450133842","pt":1717318390322,"mc":[{"id":"1.229554933","rc":[{"atb":[[2.82,0],[2.62,0]],"id":52671546},{"atb":[[10.5,0],[8.2,0]],"id":52671545},{"atb":[[1.44,178.36],[1.34,0]],"id":52671544},{"atb":[[3.2,0],[2.88,0]],"id":52671555},{"atb":[[9.2,0],[13,0]],"id":52671554},{"atb":[[19.5,0],[14.5,0]],"id":52671556}],"con":true,"img":false}]}
{"op":"mcm","clk":"11450134730","pt":1717318401243,"mc":[{"id":"1.229554933","rc":[{"atb":[[2.82,57.43],[2.62,150.55]],"id":52671546},{"atb":[[10.5,11],[8.2,33.87]],"id":52671545},{"atb":[[1.46,227.24],[1.36,677.51]],"id":52671544},{"atb":[[2.86,131.13],[3.15,48.61]],"id":52671555},{"atb":[[9.2,29.74],[13,8.71]],"id":52671554},{"atb":[[19.5,5.65],[14.5,18.06]],"id":52671556}],"con":true,"img":false}]}
{"op":"mcm","clk":"11450157581","pt":1717318650717,"mc":[{"id":"1.229554933","rc":[{"atb":[[3.45,0],[3.95,0],[3.7,0],[4.4,0]],"id":52671555}],"con":true,"img":false}]}
{"op":"mcm","clk":"11450157649","pt":1717318651388,"mc":[{"id":"1.229554933","rc":[{"atb":[[4.5,7.48],[3.5,41.85],[3.75,28.54]],"id":52671555}],"con":true,"img":false}]}
{"op":"mcm","clk":"11450157660","pt":1717318651494,"mc":[{"id":"1.229554933","rc":[{"atb":[[4,17.44]],"id":52671555}],"con":true,"img":false}]}
{"op":"mcm","clk":"11450164697","pt":1717318724600,"mc":[{"id":"1.229554933","rc":[{"atb":[[2.82,0],[2.62,0]],"id":52671546},{"atb":[[10.5,0],[8.2,0]],"id":52671545},{"atb":[[1.46,0],[1.36,0]],"id":52671544},{"atb":[[2.86,0],[3.15,0]],"id":52671555},{"atb":[[9.2,0],[13,0]],"id":52671554},{"atb":[[19.5,0],[14.5,0]],"id":52671556}],"con":true,"img":false}]}
{"op":"mcm","clk":"11450167438","pt":1717318753411,"mc":[{"id":"1.229554933","rc":[{"atb":[[2.82,57.43],[2.62,150.55]],"id":52671546},{"atb":[[10.5,11],[8.2,33.87]],"id":52671545},{"atb":[[1.46,227.24],[1.36,677.51]],"id":52671544},{"atb":[[2.86,131.13],[3.15,48.61]],"id":52671555},{"atb":[[9.2,29.74],[13,8.71]],"id":52671554},{"atb":[[19.5,5.65],[14.5,18.06]],"id":52671556}],"con":true,"img":false}]}
{"op":"mcm","clk":"11450181001","pt":1717318898845,"mc":[{"id":"1.229554933","rc":[{"atb":[[1.44,0],[1.54,0],[1.49,0],[1.39,0]],"id":52671544}],"con":true,"img":false}]}
{"op":"mcm","clk":"11450181067","pt":1717318899577,"mc":[{"id":"1.229554933","rc":[{"atb":[[1.37,282.8],[1.42,186.85],[1.47,111.32],[1.52,50.3]],"id":52671544}],"con":true,"img":false}]}
{"op":"mcm","clk":"11450246467","pt":1717319582903,"mc":[{"id":"1.229554933","rc":[{"atb":[[2.82,0],[2.62,0]],"id":52671546},{"atb":[[10.5,0],[8.2,0]],"id":52671545},{"atb":[[1.46,0],[1.36,0]],"id":52671544},{"atb":[[2.86,0],[3.15,0]],"id":52671555},{"atb":[[9.2,0],[13,0]],"id":52671554},{"atb":[[19.5,0],[14.5,0]],"id":52671556}],"con":true,"img":false}]}
{"op":"mcm","clk":"11450247605","pt":1717319595636,"mc":[{"id":"1.229554933","rc":[{"atb":[[2.82,57.43],[2.62,150.55]],"id":52671546},{"atb":[[10.5,11],[8.2,33.87]],"id":52671545},{"atb":[[1.46,227.24],[1.36,677.51]],"id":52671544}],"con":true,"img":false}]}
{"op":"mcm","clk":"11450247617","pt":1717319595742,"mc":[{"id":"1.229554933","rc":[{"atb":[[2.86,131.13],[3.15,48.61]],"id":52671555},{"atb":[[9.2,29.74],[13,8.71]],"id":52671554},{"atb":[[19.5,5.65],[14.5,18.06]],"id":52671556}],"con":true,"img":false}]}
{"op":"mcm","clk":"11450275363","pt":1717319918892,"mc":[{"id":"1.229554933","rc":[{"atb":[[17,0],[19.5,0],[24,0],[14.5,0]],"id":52671554}],"con":true,"img":false}]}
{"op":"mcm","clk":"11450275400","pt":1717319919564,"mc":[{"id":"1.229554933","rc":[{"atb":[[17.5,4.76],[20,2.75],[25,1.09],[15,7.48]],"id":52671554}],"con":true,"img":false}]}
{"op":"mcm","clk":"11450277826","pt":1717319949110,"mc":[{"id":"1.229554933","rc":[{"atb":[[1.37,0],[1.42,0],[1.47,0],[1.52,0]],"id":52671544}],"con":true,"img":false}]}
{"op":"mcm","clk":"11450277886","pt":1717319949834,"mc":[{"id":"1.229554933","rc":[{"atb":[[1.44,178.36],[1.54,48.44],[1.49,106.77],[1.39,268.3]],"id":52671544}],"con":true,"img":false}]}
{"op":"mcm","clk":"11450308144","pt":1717320400600,"mc":[{"id":"1.229554933","rc":[{"atb":[[2.82,0],[2.62,0]],"id":52671546},{"atb":[[10.5,0],[8.2,0]],"id":52671545},{"atb":[[1.46,0],[1.36,0]],"id":52671544},{"atb":[[2.86,0],[3.15,0]],"id":52671555},{"atb":[[9.2,0],[13,0]],"id":52671554},{"atb":[[19.5,0],[14.5,0]],"id":52671556}],"con":true,"img":false}]}
{"op":"mcm","clk":"11450308813","pt":1717320411094,"mc":[{"id":"1.229554933","rc":[{"atb":[[2.82,57.43],[2.62,150.55]],"id":52671546},{"atb":[[10.5,11],[8.2,33.87]],"id":52671545},{"atb":[[1.46,227.24],[1.36,677.51]],"id":52671544},{"atb":[[2.86,131.13],[3.15,48.61]],"id":52671555},{"atb":[[9.2,29.74],[13,8.71]],"id":52671554},{"atb":[[19.5,5.65],[14.5,18.06]],"id":52671556}],"con":true,"img":false}]}
{"op":"mcm","clk":"11450312275","pt":1717320464242,"mc":[{"id":"1.229554933","rc":[{"atb":[[1.44,0],[1.54,0],[1.49,0],[1.39,0]],"id":52671544},{"atb":[[4,0],[4.5,0],[3.5,0],[3.75,0]],"id":52671555},{"atb":[[17.5,0],[20,0],[25,0],[15,0]],"id":52671554},{"atb":[[65,0],[36,0],[46,0],[28,0]],"id":52671556}],"con":true,"img":false}]}
{"op":"mcm","clk":"11450312323","pt":1717320465052,"mc":[{"id":"1.229554933","rc":[{"atb":[[1.41,127.6],[1.46,284.11],[1.36,895.51],[1.31,337.53]],"id":52671544},{"atb":[[4.8,6.89],[4.3,15.85],[3.9,27.06],[3.65,39.48]],"id":52671555},{"atb":[[17,6.54],[19.5,4.24],[24,2.28],[29,0.94]],"id":52671554},{"atb":[[70,0.38],[38,2.12],[48,1.11],[29,3.74]],"id":52671556}],"con":true,"img":false}]}
{"op":"mcm","clk":"11450312418","pt":1717320465944,"mc":[{"id":"1.229554933","rc":[{"atb":[[4.8,0],[4.3,0],[3.9,0],[3.65,0]],"id":52671555}],"con":true,"img":false}]}
{"op":"mcm","clk":"11450312472","pt":1717320466619,"mc":[{"id":"1.229554933","rc":[{"atb":[[4,17.44],[4.5,7.48],[3.5,41.85],[3.75,28.54]],"id":52671555}],"con":true,"img":false}]}
{"op":"mcm","clk":"11450312841","pt":1717320473420,"mc":[{"id":"1.229554933","rc":[{"atb":[[4,0],[4.5,0],[3.5,0],[3.75,0]],"id":52671555}],"con":true,"img":false}]}
{"op":"mcm","clk":"11450312883","pt":1717320474146,"mc":[{"id":"1.229554933","rc":[{"atb":[[4.8,6.89],[4.3,15.85],[3.9,27.06],[3.65,39.48]],"id":52671555}],"con":true,"img":false}]}
{"op":"mcm","clk":"11450313190","pt":1717320480065,"mc":[{"id":"1.229554933","rc":[{"atb":[[4.8,0],[4.3,0],[3.9,0],[3.65,0]],"id":52671555}],"con":true,"img":false}]}
{"op":"mcm","clk":"11450313225","pt":1717320480749,"mc":[{"id":"1.229554933","rc":[{"atb":[[4,17.44],[4.5,7.48],[3.5,41.85],[3.75,28.54]],"id":52671555}],"con":true,"img":false}]}
{"op":"mcm","clk":"11450313557","pt":1717320486366,"mc":[{"id":"1.229554933","rc":[{"atb":[[1.41,0],[1.46,227.24],[1.36,677.51],[1.31,0]],"id":52671544}],"con":true,"img":false}]}
{"op":"mcm","clk":"11450313586","pt":1717320487051,"mc":[{"id":"1.229554933","rc":[{"atb":[[1.27,387.54],[1.37,141.4],[1.32,245.24],[1.42,62.28]],"id":52671544}],"con":true,"img":false}]}
{"op":"mcm","clk":"11450324819","pt":1717320550071,"mc":[{"id":"1.229554933","rc":[{"atb":[[2.82,0],[2.62,0]],"id":52671546},{"atb":[[10.5,0],[8.2,0]],"id":52671545},{"atb":[[1.46,0],[1.36,0]],"id":52671544},{"atb":[[2.86,0],[3.15,0]],"id":52671555},{"atb":[[9.2,0],[13,0]],"id":52671554},{"atb":[[19.5,0],[14.5,0]],"id":52671556}],"con":true,"img":false}]}
{"op":"mcm","clk":"11450326242","pt":1717320567768,"mc":[{"id":"1.229554933","rc":[{"atb":[[2.56,156.35],[2.76,59.39]],"id":52671546},{"atb":[[9.8,11.87],[7.8,35.86]],"id":52671545},{"atb":[[1.4,261.32],[1.3,813.01]],"id":52671544},{"atb":[[3,121.95],[3.5,83.67]],"id":52671555},{"atb":[[9.6,28.36],[14,8.04]],"id":52671554},{"atb":[[21,5.22],[15.5,16.82]],"id":52671556}],"con":true,"img":false}]}
{"op":"mcm","clk":"11450328982","pt":1717320605069,"mc":[{"id":"1.229554933","rc":[{"atb":[[2.56,0],[2.76,0]],"id":52671546},{"atb":[[9.8,0],[7.8,0]],"id":52671545},{"atb":[[1.4,0],[1.3,0]],"id":52671544},{"atb":[[3,0],[3.5,41.85]],"id":52671555},{"atb":[[9.6,0],[14,0]],"id":52671554},{"atb":[[21,0],[15.5,0]],"id":52671556}],"con":true,"img":false}]}
{"op":"mcm","clk":"11450331344","pt":1717320634448,"mc":[{"id":"1.229554933","rc":[{"atb":[[2.54,158.38],[2.74,60.07]],"id":52671546},{"atb":[[9,30.48],[12.5,18.19]],"id":52671545},{"atb":[[1.29,841.05],[1.39,268.02]],"id":52671544},{"atb":[[3,121.95],[3.5,83.67]],"id":52671555},{"atb":[[16,6.96],[11,24.39]],"id":52671554},{"atb":[[18,14.34],[26,4.18]],"id":52671556}],"con":true,"img":false}]}
{"op":"mcm","clk":"11450333315","pt":1717320660844,"mc":[{"id":"1.229554933","rc":[{"atb":[[2.54,0],[2.74,0]],"id":52671546},{"atb":[[9,0],[12.5,9.1]],"id":52671545},{"atb":[[1.29,0],[1.39,0]],"id":52671544},{"atb":[[3,0],[3.5,41.85]],"id":52671555},{"atb":[[16,0],[11,0]],"id":52671554},{"atb":[[18,0],[26,0]],"id":52671556}],"con":true,"img":false}]}
{"op":"mcm","clk":"11450334365","pt":1717320674090,"mc":[{"id":"1.229554933","rc":[{"atb":[[2.54,158.38],[2.74,60.07]],"id":52671546},{"atb":[[9,30.48],[12.5,18.19]],"id":52671545},{"atb":[[1.29,841.05],[1.39,268.02]],"id":52671544},{"atb":[[3,121.95],[3.5,83.67]],"id":52671555},{"atb":[[16,6.96],[11,24.39]],"id":52671554},{"atb":[[18,14.34],[26,4.18]],"id":52671556}],"con":true,"img":false}]}
{"op":"mcm","clk":"11450338740","pt":1717320727902,"mc":[{"id":"1.229554933","rc":[{"atb":[[17.5,0],[20,0],[12.5,9.08],[15,0]],"id":52671545},{"atb":[[17,0],[19.5,0],[24,0],[29,0]],"id":52671554},{"atb":[[70,0],[38,0],[48,0],[29,0]],"id":52671556}],"con":true,"img":false}]}
{"op":"mcm","clk":"11450338792","pt":1717320728619,"mc":[{"id":"1.229554933","rc":[{"atb":[[18,3.08],[21,1.31],[13,8.72],[15.5,5.41]],"id":52671545},{"atb":[[38,0.71],[19.5,5.66],[24,3.41],[29,1.87]],"id":52671554},{"atb":[[75,0.71],[40,2.68],[100,0.27],[50,1.6]],"id":52671556}],"con":true,"img":false}]}
{"op":"mcm","clk":"11450365145","pt":1717321050365,"mc":[{"id":"1.229554933","rc":[{"atb":[[4,0],[4.5,0],[3.5,41.81],[3.75,0]],"id":52671555}],"con":true,"img":false}]}
{"op":"mcm","clk":"11450365190","pt":1717321051043,"mc":[{"id":"1.229554933","rc":[{"atb":[[4.6,21.8],[4.1,33.76]],"id":52671555}],"con":true,"img":false}]}
{"op":"mcm","clk":"11450365200","pt":1717321051150,"mc":[{"id":"1.229554933","rc":[{"atb":[[5.6,5.69],[5.1,12.76]],"id":52671555}],"con":true,"img":false}]}
{"op":"mcm","clk":"11450379303","pt":1717321268136,"mc":[{"id":"1.229554933","rc":[{"atb":[[2.54,0],[2.74,0]],"id":52671546},{"atb":[[9,0],[12.5,0]],"id":52671545},{"atb":[[1.29,0],[1.39,0]],"id":52671544},{"atb":[[3,0],[3.5,0]],"id":52671555},{"atb":[[16,0],[11,0]],"id":52671554},{"atb":[[18,0],[26,0]],"id":52671556}],"con":true,"img":false}]}
{"op":"mcm","clk":"11450380297","pt":1717321282051,"mc":[{"id":"1.229554933","rc":[{"atb":[[2.54,158.38],[2.74,60.07]],"id":52671546},{"atb":[[9,30.48],[12.5,9.08]],"id":52671545},{"atb":[[1.29,841.05],[1.39,268.02]],"id":52671544},{"atb":[[3,121.95],[3.5,41.81]],"id":52671555},{"atb":[[16,6.96],[11,24.39]],"id":52671554},{"atb":[[18,14.34],[26,4.18]],"id":52671556}],"con":true,"img":false}]}
{"op":"mcm","clk":"11450390445","pt":1717321448096,"mc":[{"id":"1.229554933","rc":[{"atb":[[4.6,0],[4.1,0]],"id":52671555}],"con":true,"img":false}]}
{"op":"mcm","clk":"11450390485","pt":1717321448786,"mc":[{"id":"1.229554933","rc":[{"atb":[[4.5,29.89],[5,19.62]],"id":52671555}],"con":true,"img":false}]}
{"op":"mcm","clk":"11450390565","pt":1717321450089,"mc":[{"id":"1.229554933","rc":[{"atb":[[4.5,0],[5,0]],"id":52671555}],"con":true,"img":false}]}
{"op":"mcm","clk":"11450390612","pt":1717321450763,"mc":[{"id":"1.229554933","rc":[{"atb":[[4.6,21.8],[4.1,33.76]],"id":52671555}],"con":true,"img":false}]}
{"op":"mcm","clk":"11450409723","pt":1717321719309,"mc":[{"id":"1.229554933","rc":[{"atb":[[18,0],[21,0],[13,0],[15.5,0]],"id":52671545},{"atb":[[75,0],[40,0],[100,0],[50,0]],"id":52671556}],"con":true,"img":false}]}
{"op":"mcm","clk":"11450409780","pt":1717321720000,"mc":[{"id":"1.229554933","rc":[{"atb":[[16,5.23],[18.5,2.99],[22,1.25],[13.5,8.37]],"id":52671545},{"atb":[[80,0.66],[42,2.55],[110,0.24],[55,1.45]],"id":52671556}],"con":true,"img":false}]}
{"op":"mcm","clk":"11450412326","pt":1717321749515,"mc":[{"id":"1.229554933","rc":[{"atb":[[5.6,0],[5.1,0],[4.6,0],[4.1,0]],"id":52671555}],"con":true,"img":false}]}
{"op":"mcm","clk":"11450412378","pt":1717321750241,"mc":[{"id":"1.229554933","rc":[{"atb":[[4.8,20.65],[4.3,31.71],[5.8,5.45],[5.3,12.17]],"id":52671555}],"con":true,"img":false}]}
{"op":"mcm","clk":"11450445397","pt":1717322128282,"mc":[{"id":"1.229554933","rc":[{"atb":[[2.54,316.76],[2.74,120.15]],"id":52671546},{"atb":[[9,60.97],[12.5,18.17]],"id":52671545},{"atb":[[1.29,1682.1],[1.39,536.05]],"id":52671544},{"atb":[[3,243.9],[3.5,83.62]],"id":52671555},{"atb":[[16,13.93],[11,48.78]],"id":52671554},{"atb":[[18,28.69],[26,8.36]],"id":52671556}],"con":true,"img":false}]}
{"op":"mcm","clk":"11450470122","pt":1717322405327,"mc":[{"id":"1.229554933","rc":[{"atb":[[3,0],[3.25,0],[3.5,0],[3.75,0]],"id":52671546}],"con":true,"img":false}]}
{"op":"mcm","clk":"11450470199","pt":1717322406004,"mc":[{"id":"1.229554933","rc":[{"atb":[[2.9,55.07],[3,39.24],[3.25,23.25],[3.5,10.46]],"id":52671546}],"con":true,"img":false}]}
{"op":"mcm","clk":"11450480554","pt":1717322520284,"mc":[{"id":"1.229554933","rc":[{"atb":[[2.78,56.18]],"id":52671546},{"atl":[[210,2]],"id":52671546},{"atb":[[6.8,17.24]],"id":52671545},{"atl":[[740,2]],"id":52671545},{"atb":[[1.14,632.78]],"id":52671544},{"atl":[[2.76,2]],"id":52671544},{"atb":[[1.44,52.37]],"id":52671555},{"atl":[[170,2]],"id":52671555},{"atb":[[6.8,17.24]],"id":52671554},{"atl":[[760,2]],"id":52671554},{"atb":[[25,4.17]],"id":52671556}],"con":true,"img":false}]}
{"op":"mcm","clk":"11450483402","pt":1717322557467,"mc":[{"id":"1.229554933","rc":[{"atb":[[2.78,0],[3.05,48.78]],"id":52671546},{"atb":[[6.8,0],[7.8,14.71]],"id":52671545},{"atb":[[8,14.29],[6.8,0]],"id":52671554},{"atb":[[25,0],[30,3.45]],"id":52671556}],"con":true,"img":false}]}
{"op":"mcm","clk":"11450490356","pt":1717322639593,"mc":[{"id":"1.229554933","rc":[{"atb":[[2.54,158.38],[2.74,60.07]],"id":52671546},{"atb":[[9,30.48],[12.5,9.08]],"id":52671545},{"atb":[[1.29,841.05],[1.39,268.02]],"id":52671544},{"atb":[[3,121.95],[3.5,41.81]],"id":52671555},{"atb":[[16,6.96],[11,24.39]],"id":52671554},{"atb":[[18,14.34],[26,4.18]],"id":52671556}],"con":true,"img":false}]}
{"op":"mcm","clk":"11450491173","pt":1717322647806,"mc":[{"id":"1.229554933","rc":[{"atb":[[3.15,46.51],[3.05,0]],"id":52671546},{"atl":[[160,2],[210,0]],"id":52671546},{"atb":[[9.2,12.2],[7.8,0]],"id":52671545},{"atl":[[2.62,2],[2.76,0]],"id":52671544},{"atl":[[150,2]],"id":52671555},{"atb":[[8,0],[10,11.11]],"id":52671554},{"atl":[[760,0],[770,2]],"id":52671554}],"con":true,"img":false}]}
{"op":"mcm","clk":"11450491183","pt":1717322647914,"mc":[{"id":"1.229554933","rc":[{"atl":[[170,0]],"id":52671555}],"con":true,"img":false}]}
{"op":"mcm","clk":"11450491414","pt":1717322650804,"mc":[{"id":"1.229554933","rc":[{"atl":[[710,2],[740,0]],"id":52671545},{"atb":[[10,0],[8.8,12.82]],"id":52671554},{"atl":[[730,2],[770,0]],"id":52671554}],"con":true,"img":false}]}
{"op":"mcm","clk":"11450491515","pt":1717322652008,"mc":[{"id":"1.229554933","rc":[{"atb":[[2.54,316.76],[2.74,120.15]],"id":52671546},{"atb":[[9,60.97],[12.5,18.17]],"id":52671545},{"atb":[[1.29,1682.1],[1.39,536.05]],"id":52671544},{"atb":[[3,243.9],[3.5,83.62]],"id":52671555},{"atb":[[16,13.93],[11,48.78]],"id":52671554},{"atb":[[18,28.69],[26,8.36]],"id":52671556}],"con":true,"img":false}]}
{"op":"mcm","clk":"11450491607","pt":1717322652904,"mc":[{"id":"1.229554933","rc":[{"atl":[[160,0],[180,2]],"id":52671546}],"con":true,"img":false}]}
{"op":"mcm","clk":"11450494285","pt":1717322683654,"mc":[{"id":"1.229554933","rc":[{"atb":[[3.2,45.45],[3.15,0]],"id":52671546}],"con":true,"img":false}]}
{"op":"mcm","clk":"11450502419","pt":1717322770794,"mc":[{"id":"1.229554933","rc":[{"atb":[[3.2,0],[3.05,48.78]],"id":52671546},{"atl":[[180,0],[210,2]],"id":52671546},{"atb":[[9.2,0],[7.8,14.71]],"id":52671545},{"atl":[[710,0],[740,2]],"id":52671545},{"atl":[[2.62,0],[2.76,4]],"id":52671544},{"atl":[[150,0],[170,2]],"id":52671555},{"atl":[[730,0],[760,2]],"id":52671554}],"con":true,"img":false}]}
{"op":"mcm","clk":"11450504411","pt":1717322791832,"mc":[{"id":"1.229554933","rc":[{"atb":[[16,0],[18.5,0],[22,0],[13.5,0]],"id":52671545},{"atb":[[4.8,0],[4.3,0],[5.8,0],[5.3,0]],"id":52671555},{"atb":[[38,0],[19.5,0],[24,0],[29,0]],"id":52671554},{"atb":[[80,0],[42,0],[110,0],[55,0]],"id":52671556}],"con":true,"img":false}]}
{"op":"mcm","clk":"11450504426","pt":1717322792039,"mc":[{"id":"1.229554933","rc":[{"atb":[[27,3.85]],"id":52671556}],"con":true,"img":false}]}
{"op":"mcm","clk":"11450504433","pt":1717322792140,"mc":[{"id":"1.229554933","rc":[{"atb":[[30,0]],"id":52671556}],"con":true,"img":false}]}
{"op":"mcm","clk":"11450504503","pt":1717322792829,"mc":[{"id":"1.229554933","rc":[{"atb":[[17,4.9],[19.5,2.83],[24,1.14],[14.5,7.75]],"id":52671545},{"atb":[[4.9,20.12],[4.4,30.77],[5.9,5.34],[5.4,11.89]],"id":52671555},{"atb":[[85,0.62],[44,2.43],[120,0.22],[60,1.33]],"id":52671556}],"con":true,"img":false}]}
{"op":"mcm","clk":"11450504509","pt":1717322792931,"mc":[{"id":"1.229554933","rc":[{"atb":[[34,1.59],[44,0.61],[22,4.98],[27,3.02]],"id":52671554}],"con":true,"img":false}]}
{"op":"mcm","clk":"11450507276","pt":1717322823672,"mc":[{"id":"1.229554933","rc":[{"atb":[[4.9,0],[4.4,0],[5.9,0],[5.4,0]],"id":52671555}],"con":true,"img":false}]}
{"op":"mcm","clk":"11450507352","pt":1717322824388,"mc":[{"id":"1.229554933","rc":[{"atb":[[4.8,20.65],[4.3,31.71],[5.8,5.45],[5.3,12.17]],"id":52671555}],"con":true,"img":false}]}
{"op":"mcm","clk":"11450526067","pt":1717323010311,"mc":[{"id":"1.229554933","rc":[{"atb":[[2.54,158.38],[2.74,60.07]],"id":52671546},{"atb":[[9,30.48],[12.5,9.08]],"id":52671545},{"atb":[[1.29,841.05],[1.39,268.02]],"id":52671544},{"atb":[[3,121.95],[3.5,41.81]],"id":52671555},{"atb":[[16,6.96],[11,24.39]],"id":52671554},{"atb":[[18,14.34],[26,4.18]],"id":52671556}],"con":true,"img":false}]}
{"op":"mcm","clk":"11450527434","pt":1717323023937,"mc":[{"id":"1.229554933","rc":[{"atb":[[2.54,316.76],[2.74,120.15]],"id":52671546},{"atb":[[9,60.97],[12.5,18.17]],"id":52671545},{"atb":[[1.29,1682.1],[1.39,536.05]],"id":52671544},{"atb":[[3,243.9],[3.5,83.62]],"id":52671555},{"atb":[[16,13.93],[11,48.78]],"id":52671554},{"atb":[[18,28.69],[26,8.36]],"id":52671556}],"con":true,"img":false}]}
{"op":"mcm","clk":"11450542687","pt":1717323171499,"mc":[{"id":"1.229554933","rc":[{"atb":[[17,0],[19.5,0],[24,0],[14.5,0]],"id":52671545},{"atb":[[34,0],[44,0],[22,0],[27,0]],"id":52671554},{"atb":[[85,0],[44,0],[120,0],[60,0]],"id":52671556}],"con":true,"img":false}]}
{"op":"mcm","clk":"11450542759","pt":1717323172225,"mc":[{"id":"1.229554933","rc":[{"atb":[[16,5.23],[18.5,2.99],[22,1.25],[13.5,8.37]],"id":52671545},{"atb":[[38,0.71],[19.5,5.66],[24,3.41],[29,1.87]],"id":52671554},{"atb":[[80,0.66],[42,2.55],[110,0.24],[55,1.45]],"id":52671556}],"con":true,"img":false}]}
{"op":"mcm","clk":"11450561742","pt":1717323343776,"mc":[{"id":"1.229554933","rc":[{"atb":[[2.54,158.38],[2.74,60.07]],"id":52671546},{"atb":[[9,30.48],[12.5,9.08]],"id":52671545},{"atb":[[1.29,841.05],[1.39,268.02]],"id":52671544},{"atb":[[3,121.95],[3.5,41.81]],"id":52671555},{"atb":[[16,6.96],[11,24.39]],"id":52671554},{"atb":[[18,14.34],[26,4.18]],"id":52671556}],"con":true,"img":false}]}
{"op":"mcm","clk":"11450563440","pt":1717323359137,"mc":[{"id":"1.229554933","rc":[{"atb":[[2.54,316.76],[2.74,120.15]],"id":52671546},{"atb":[[9,60.97],[12.5,18.17]],"id":52671545},{"atb":[[1.29,1682.1],[1.39,536.05]],"id":52671544}],"con":true,"img":false}]}
{"op":"mcm","clk":"11450563452","pt":1717323359233,"mc":[{"id":"1.229554933","rc":[{"atb":[[3,243.9],[3.5,83.62]],"id":52671555},{"atb":[[16,13.93],[11,48.78]],"id":52671554},{"atb":[[18,28.69],[26,8.36]],"id":52671556}],"con":true,"img":false}]}
{"op":"mcm","clk":"11450592001","pt":1717323620105,"mc":[{"id":"1.229554933","rc":[{"atb":[[16,0],[18.5,0],[22,0],[13.5,0]],"id":52671545},{"atb":[[38,0],[19.5,0],[24,0],[29,0]],"id":52671554},{"atb":[[80,0],[42,0],[110,0],[55,0]],"id":52671556}],"con":true,"img":false}]}
{"op":"mcm","clk":"11450592068","pt":1717323620826,"mc":[{"id":"1.229554933","rc":[{"atb":[[17,4.9],[19.5,2.83],[24,1.14],[14.5,7.75]],"id":52671545},{"atb":[[34,1.59],[44,0.61],[22,4.98],[27,3.02]],"id":52671554},{"atb":[[85,0.62],[44,2.43],[120,0.22],[60,1.33]],"id":52671556}],"con":true,"img":false}]}
{"op":"mcm","clk":"11450598085","pt":1717323680285,"mc":[{"id":"1.229554933","rc":[{"atb":[[2.54,158.38],[2.74,60.07]],"id":52671546},{"atb":[[9,30.48],[12.5,9.08]],"id":52671545},{"atb":[[1.29,841.05],[1.39,268.02]],"id":52671544},{"atb":[[3,121.95],[3.5,41.81]],"id":52671555},{"atb":[[16,6.96],[11,24.39]],"id":52671554},{"atb":[[18,14.34],[26,4.18]],"id":52671556}],"con":true,"img":false}]}
{"op":"mcm","clk":"11450599088","pt":1717323691811,"mc":[{"id":"1.229554933","rc":[{"atb":[[2.54,316.76],[2.74,120.15]],"id":52671546},{"atb":[[9,60.97],[12.5,18.17]],"id":52671545},{"atb":[[1.29,1682.1],[1.39,536.05]],"id":52671544},{"atb":[[3,243.9],[3.5,83.62]],"id":52671555},{"atb":[[16,13.93],[11,48.78]],"id":52671554},{"atb":[[18,28.69],[26,8.36]],"id":52671556}],"con":true,"img":false}]}
{"op":"mcm","clk":"11450601824","pt":1717323721457,"mc":[{"id":"1.229554933","rc":[{"atb":[[3.2,45.45],[3.05,0]],"id":52671546},{"atl":[[180,2],[210,0]],"id":52671546},{"atb":[[7.8,0],[5.9,17.9]],"id":52671545},{"atl":[[4.2,8],[2.76,0]],"id":52671544},{"atb":[[1.44,0],[2.16,52.37]],"id":52671555},{"atb":[[8.8,0],[5.9,17.9]],"id":52671554},{"atb":[[27,0],[5.9,17.9]],"id":52671556}],"con":true,"img":false}]}
{"op":"mcm","clk":"11450614276","pt":1717323847517,"mc":[{"id":"1.229554933","rc":[{"atb":[[3.2,0],[3.35,39.24]],"id":52671546},{"atl":[[140,2],[180,0]],"id":52671546},{"atl":[[150,2],[170,0]],"id":52671555},{"atl":[[760,0],[770,2]],"id":52671554}],"con":true,"img":false}]}
{"op":"mcm","clk":"11450614575","pt":1717323850101,"mc":[{"id":"1.229554933","rc":[{"atl":[[710,2],[740,0]],"id":52671545}],"con":true,"img":false}]}
{"op":"mcm","clk":"11450614873","pt":1717323852674,"mc":[{"id":"1.229554933","rc":[{"atl":[[140,0],[150,2]],"id":52671546}],"con":true,"img":false}]}
{"op":"mcm","clk":"11450617084","pt":1717323871451,"mc":[{"id":"1.229554933","rc":[{"atb":[[3.35,0],[3.4,39.24]],"id":52671546},{"atl":[[730,2],[770,0]],"id":52671554}],"con":true,"img":false}]}
{"op":"mcm","clk":"11450626477","pt":1717323970067,"mc":[{"id":"1.229554933","rc":[{"atb":[[3.2,45.45],[3.4,0]],"id":52671546},{"atl":[[150,0],[180,2]],"id":52671546},{"atl":[[710,0],[740,2]],"id":52671545},{"atl":[[150,0],[170,2]],"id":52671555},{"atl":[[730,0],[760,2]],"id":52671554}],"con":true,"img":false}]}
{"op":"mcm","clk":"11450632145","pt":1717324032453,"mc":[{"id":"1.229554933","rc":[{"atb":[[2.54,158.38],[2.74,60.07]],"id":52671546},{"atb":[[9,30.48],[12.5,9.08]],"id":52671545},{"atb":[[1.29,841.05],[1.39,268.02]],"id":52671544},{"atb":[[3,121.95],[3.5,41.81]],"id":52671555},{"atb":[[16,6.96],[11,24.39]],"id":52671554},{"atb":[[18,14.34],[26,4.18]],"id":52671556}],"con":true,"img":false}]}
{"op":"mcm","clk":"11450633156","pt":1717324044655,"mc":[{"id":"1.229554933","rc":[{"atb":[[2.54,316.76],[2.74,120.15]],"id":52671546},{"atb":[[9,60.97],[12.5,18.17]],"id":52671545},{"atb":[[1.29,1682.1],[1.39,536.05]],"id":52671544},{"atb":[[3,243.9],[3.5,83.62]],"id":52671555},{"atb":[[16,13.93],[11,48.78]],"id":52671554},{"atb":[[18,28.69],[26,8.36]],"id":52671556}],"con":true,"img":false}]}
{"op":"mcm","clk":"11450649496","pt":1717324218974,"mc":[{"id":"1.229554933","rc":[{"atb":[[2.9,0],[3,0],[3.25,0],[3.5,0]],"id":52671546}],"con":true,"img":false}]}
{"op":"mcm","clk":"11450649546","pt":1717324219459,"mc":[{"id":"1.229554933","rc":[{"atb":[[2.76,56.82]],"id":52671546}],"con":true,"img":false}]}
{"op":"mcm","clk":"11450649561","pt":1717324219562,"mc":[{"id":"1.229554933","rc":[{"atb":[[3.2,0]],"id":52671546}],"con":true,"img":false}]}
{"op":"mcm","clk":"11450649571","pt":1717324219669,"mc":[{"id":"1.229554933","rc":[{"atb":[[2.86,56.26],[3.4,10.9],[3.15,24.33],[2.96,40.04]],"id":52671546}],"con":true,"img":false}]}
{"op":"mcm","clk":"11450651775","pt":1717324239675,"mc":[{"id":"1.229554933","rc":[{"atb":[[3.2,40.04],[2.76,0]],"id":52671546}],"con":true,"img":false}]}
{"op":"mcm","clk":"11450658196","pt":1717324302240,"mc":[{"id":"1.229554933","rc":[{"atb":[[2.86,0],[3.4,0],[3.15,0],[2.96,0]],"id":52671546},{"atb":[[17,0],[19.5,0],[24,0],[14.5,0]],"id":52671545},{"atb":[[34,0],[44,0],[22,0],[27,0]],"id":52671554},{"atb":[[85,0],[44,0],[120,0],[60,0]],"id":52671556}],"con":true,"img":false}]}
{"op":"mcm","clk":"11450658207","pt":1717324302343,"mc":[{"id":"1.229554933","rc":[{"atb":[[3.2,0],[2.76,56.82]],"id":52671546}],"con":true,"img":false}]}
{"op":"mcm","clk":"11450658273","pt":1717324302921,"mc":[{"id":"1.229554933","rc":[{"atl":[[180,0],[230,2]],"id":52671546},{"atl":[[740,0],[820,2]],"id":52671545},{"atl":[[170,0],[220,2]],"id":52671555},{"atl":[[760,0],[850,2]],"id":52671554}],"con":true,"img":false}]}
{"op":"mcm","clk":"11450658458","pt":1717324304444,"mc":[{"id":"1.229554933","rc":[{"atb":[[2.9,55.07],[3,39.24],[3.25,23.25],[3.5,10.46]],"id":52671546},{"atb":[[16,5.23],[18.5,2.99],[22,1.25],[13.5,8.37]],"id":52671545},{"atb":[[38,0.71],[19.5,5.66],[24,3.41],[29,1.87]],"id":52671554},{"atb":[[80,0.66],[42,2.55],[110,0.24],[55,1.45]],"id":52671556}],"con":true,"img":false}]}
{"op":"mcm","clk":"11450658556","pt":1717324305134,"mc":[{"id":"1.229554933","rc":[{"atb":[[16,0],[18.5,0],[22,0],[13.5,0]],"id":52671545},{"atb":[[38,0],[19.5,0],[24,0],[29,0]],"id":52671554},{"atb":[[80,0],[42,0],[110,0],[55,0]],"id":52671556}],"con":true,"img":false}]}
{"op":"mcm","clk":"11450658629","pt":1717324305825,"mc":[{"id":"1.229554933","rc":[{"atb":[[17,4.9],[19.5,2.83],[24,1.14],[14.5,7.75]],"id":52671545}],"con":true,"img":false}]}
{"op":"mcm","clk":"11450658679","pt":1717324306333,"mc":[{"id":"1.229554933","rc":[{"atb":[[34,1.59],[44,0.61],[22,4.98],[27,3.02]],"id":52671554},{"atb":[[85,0.62],[44,2.43],[120,0.22],[60,1.33]],"id":52671556}],"con":true,"img":false}]}
{"op":"mcm","clk":"11450658986","pt":1717324309249,"mc":[{"id":"1.229554933","rc":[{"atl":[[180,2],[230,0]],"id":52671546},{"atl":[[740,2],[820,0]],"id":52671545},{"atl":[[170,2],[220,0]],"id":52671555},{"atl":[[760,2],[850,0]],"id":52671554}],"con":true,"img":false}]}
{"op":"mcm","clk":"11450660308","pt":1717324321649,"mc":[{"id":"1.229554933","rc":[{"atb":[[3.2,45.45],[2.76,0]],"id":52671546}],"con":true,"img":false}]}
{"op":"mcm","clk":"11450660884","pt":1717324326889,"mc":[{"id":"1.229554933","rc":[{"atb":[[2.98,7.92],[3.05,7.65]],"id":52671546},{"atl":[[9.8,4.27],[9.4,3.88]],"id":52671546},{"atl":[[75,3.24],[85,4.6]],"id":52671545},{"atb":[[1.36,43.59],[1.34,46.16]],"id":52671544},{"atl":[[2.64,9.56],[2.68,9.34]],"id":52671544},{"atl":[[9.6,4.05],[10,4.2]],"id":52671555},{"atl":[[80,2.75],[90,3.77]],"id":52671554},{"atl":[[380,2.71],[400,4.55]],"id":52671556}],"con":true,"img":false}]}
{"op":"mcm","clk":"11450660895","pt":1717324327049,"mc":[{"id":"1.229554933","rc":[{"atl":[[19,5.56],[180,0]],"id":52671546},{"atl":[[340,2],[740,0]],"id":52671545},{"atl":[[2.64,18.9],[4.2,0]],"id":52671544},{"atl":[[18.5,5.71],[170,0]],"id":52671555},{"atl":[[360,2],[760,0]],"id":52671554}],"con":true,"img":false}]}
{"op":"mcm","clk":"11450666060","pt":1717324370760,"mc":[{"id":"1.229554933","rc":[{"atb":[[2.54,158.38],[2.74,60.07]],"id":52671546},{"atb":[[9,30.48],[12.5,9.08]],"id":52671545},{"atb":[[1.29,841.05],[1.39,268.02]],"id":52671544},{"atb":[[3,121.95],[3.5,41.81]],"id":52671555},{"atb":[[16,6.96],[11,24.39]],"id":52671554},{"atb":[[18,14.34],[26,4.18]],"id":52671556}],"con":true,"img":false}]}
{"op":"mcm","clk":"11450667829","pt":1717324387198,"mc":[{"id":"1.229554933","rc":[{"atb":[[2.54,316.76],[2.74,120.15]],"id":52671546},{"atb":[[9,60.97],[12.5,18.17]],"id":52671545},{"atb":[[1.29,1682.1],[1.39,536.05]],"id":52671544},{"atb":[[3,243.9],[3.5,83.62]],"id":52671555},{"atb":[[16,13.93],[11,48.78]],"id":52671554},{"atb":[[18,28.69],[26,8.36]],"id":52671556}],"con":true,"img":false}]}
{"op":"mcm","clk":"11450690037","pt":1717324575856,"mc":[{"id":"1.229554933","rc":[{"atb":[[2.9,0],[3,0],[3.25,0],[3.5,0]],"id":52671546}],"con":true,"img":false}]}
{"op":"mcm","clk":"11450690050","pt":1717324575962,"mc":[{"id":"1.229554933","rc":[{"atb":[[3.1,47.62]],"id":52671546}],"con":true,"img":false}]}
{"op":"mcm","clk":"11450690060","pt":1717324576063,"mc":[{"id":"1.229554933","rc":[{"atb":[[3.2,0]],"id":52671546}],"con":true,"img":false}]}
{"op":"mcm","clk":"11450690142","pt":1717324576639,"mc":[{"id":"1.229554933","rc":[{"atb":[[2.86,56.26],[3.4,10.9],[3.15,24.33],[2.96,40.04]],"id":52671546}],"con":true,"img":false}]}
{"op":"mcm","clk":"11450691992","pt":1717324592562,"mc":[{"id":"1.229554933","rc":[{"atb":[[3.2,24.34],[3.1,0]],"id":52671546}],"con":true,"img":false}]}
{"op":"mcm","clk":"11450705818","pt":1717324712427,"mc":[{"id":"1.229554933","rc":[{"atb":[[2.54,158.38],[2.74,60.07]],"id":52671546},{"atb":[[9,30.48],[12.5,9.08]],"id":52671545},{"atb":[[1.29,841.05],[1.39,268.02]],"id":52671544},{"atb":[[3,121.95],[3.5,41.81]],"id":52671555},{"atb":[[16,6.96],[11,24.39]],"id":52671554},{"atb":[[18,14.34],[26,4.18]],"id":52671556}],"con":true,"img":false}]}
{"op":"mcm","clk":"11450707053","pt":1717324725487,"mc":[{"id":"1.229554933","rc":[{"atb":[[2.54,316.76],[2.74,120.15]],"id":52671546},{"atb":[[9,60.97],[12.5,18.17]],"id":52671545},{"atb":[[1.29,1682.1],[1.39,536.05]],"id":52671544},{"atb":[[3,243.9],[3.5,83.62]],"id":52671555},{"atb":[[16,13.93],[11,48.78]],"id":52671554},{"atb":[[18,28.69],[26,8.36]],"id":52671556}],"con":true,"img":false}]}
{"op":"mcm","clk":"11450724854","pt":1717324900427,"mc":[{"id":"1.229554933","rc":[{"atb":[[2.86,0],[3.4,0],[3.15,7.29],[2.96,0],[3.05,0]],"id":52671546},{"atb":[[17,0],[19.5,0],[24,0],[14.5,0]],"id":52671545},{"atb":[[34,0],[44,0],[22,0],[27,0]],"id":52671554},{"atb":[[85,0],[44,0],[120,0],[60,0]],"id":52671556}],"con":true,"img":false}]}
{"op":"mcm","clk":"11450724917","pt":1717324901112,"mc":[{"id":"1.229554933","rc":[{"atb":[[2.86,56.26],[3.4,10.9],[3.15,31.63],[2.96,40.04]],"id":52671546},{"atb":[[17,4.9],[19.5,2.83],[24,1.14],[14.5,7.75]],"id":52671545},{"atl":[[340,0],[420,2]],"id":52671545},{"atb":[[34,1.59],[44,0.61],[22,4.98],[27,3.02]],"id":52671554},{"atl":[[360,0],[450,2]],"id":52671554},{"atb":[[85,0.62],[44,2.43],[120,0.22],[60,1.33]],"id":52671556}],"con":true,"img":false}]}
{"op":"mcm","clk":"11450725127","pt":1717324903298,"mc":[{"id":"1.229554933","rc":[{"atb":[[3.15,24.33],[3.05,7.65]],"id":52671546}],"con":true,"img":false}]}
{"op":"mcm","clk":"11450725543","pt":1717324907905,"mc":[{"id":"1.229554933","rc":[{"atb":[[3.15,31.63],[3.05,0]],"id":52671546}],"con":true,"img":false}]}
{"op":"mcm","clk":"11450726158","pt":1717324914402,"mc":[{"id":"1.229554933","rc":[{"atl":[[340,2]],"id":52671545}],"con":true,"img":false}]}
{"op":"mcm","clk":"11450726167","pt":1717324914507,"mc":[{"id":"1.229554933","rc":[{"atl":[[420,0]],"id":52671545},{"atl":[[360,2],[450,0]],"id":52671554}],"con":true,"img":false}]}
{"op":"mcm","clk":"11450726470","pt":1717324917832,"mc":[{"id":"1.229554933","rc":[{"atb":[[3.05,7.65]],"id":52671546}],"con":true,"img":false}]}
{"op":"mcm","clk":"11450726824","pt":1717324920724,"mc":[{"id":"1.229554933","rc":[{"atl":[[9.6,0],[9.8,3.06]],"id":52671555}],"con":true,"img":false}]}
{"op":"mcm","clk":"11450726951","pt":1717324921926,"mc":[{"id":"1.229554933","rc":[{"atb":[[2.98,0]],"id":52671546}],"con":true,"img":false}]}
{"op":"mcm","clk":"11450727423","pt":1717324927146,"mc":[{"id":"1.229554933","rc":[{"atb":[[3.15,24.33]],"id":52671546}],"con":true,"img":false}]}
{"op":"mcm","clk":"11450727484","pt":1717324927818,"mc":[{"id":"1.229554933","rc":[{"atb":[[2.98,7.92]],"id":52671546}],"con":true,"img":false}]}
{"op":"mcm","clk":"11450727721","pt":1717324930725,"mc":[{"id":"1.229554933","rc":[{"atl":[[9.6,4.56]],"id":52671555}],"con":true,"img":false}]}
{"op":"mcm","clk":"11450727732","pt":1717324930828,"mc":[{"id":"1.229554933","rc":[{"atl":[[9.8,0]],"id":52671555}],"con":true,"img":false}]}
{"op":"mcm","clk":"11450732453","pt":1717324981835,"mc":[{"id":"1.229554933","rc":[{"atb":[[3.15,31.63],[3.05,0]],"id":52671546}],"con":true,"img":false}]}
{"op":"mcm","clk":"11450733322","pt":1717324991939,"mc":[{"id":"1.229554933","rc":[{"atb":[[3.05,7.65]],"id":52671546}],"con":true,"img":false}]}
{"op":"mcm","clk":"11450733693","pt":1717324995947,"mc":[{"id":"1.229554933","rc":[{"atb":[[3.15,24.33]],"id":52671546}],"con":true,"img":false}]}
{"op":"mcm","clk":"11450733941","pt":1717324998346,"mc":[{"id":"1.229554933","rc":[{"atb":[[3.15,31.63],[3.05,0]],"id":52671546}],"con":true,"img":false}]}
{"op":"mcm","clk":"11450734036","pt":1717324999128,"mc":[{"id":"1.229554933","rc":[{"atb":[[3.05,7.65]],"id":52671546}],"con":true,"img":false}]}
{"op":"mcm","clk":"11450734049","pt":1717324999236,"mc":[{"id":"1.229554933","rc":[{"atb":[[3.15,24.33]],"id":52671546}],"con":true,"img":false}]}
{"op":"mcm","clk":"11450734459","pt":1717325003441,"mc":[{"id":"1.229554933","rc":[{"atb":[[3.15,31.63],[3.05,0]],"id":52671546}],"con":true,"img":false}]}
{"op":"mcm","clk":"11450734616","pt":1717325005264,"mc":[{"id":"1.229554933","rc":[{"atb":[[3.15,24.33],[3.05,7.65]],"id":52671546}],"con":true,"img":false}]}
{"op":"mcm","clk":"11450735442","pt":1717325013863,"mc":[{"id":"1.229554933","rc":[{"atb":[[3.15,31.63],[3.05,0]],"id":52671546}],"con":true,"img":false}]}
{"op":"mcm","clk":"11450735544","pt":1717325014885,"mc":[{"id":"1.229554933","rc":[{"atb":[[3.15,24.33],[3.05,7.65]],"id":52671546}],"con":true,"img":false}]}
{"op":"mcm","clk":"11450737351","pt":1717325034410,"mc":[{"id":"1.229554933","rc":[{"atb":[[2.54,158.38],[2.74,60.07]],"id":52671546},{"atb":[[9,30.48],[12.5,9.08]],"id":52671545},{"atb":[[1.29,841.05],[1.39,268.02]],"id":52671544},{"atb":[[3,121.95],[3.5,41.81]],"id":52671555},{"atb":[[16,6.96],[11,24.39]],"id":52671554},{"atb":[[18,14.34],[26,4.18]],"id":52671556}],"con":true,"img":false}]}
{"op":"mcm","clk":"11450738360","pt":1717325045102,"mc":[{"id":"1.229554933","rc":[{"atb":[[2.54,316.76],[2.74,120.15]],"id":52671546},{"atb":[[9,60.97],[12.5,18.17]],"id":52671545},{"atb":[[1.29,1682.1],[1.39,536.05]],"id":52671544},{"atb":[[3,243.9],[3.5,83.62]],"id":52671555},{"atb":[[16,13.93],[11,48.78]],"id":52671554},{"atb":[[18,28.69],[26,8.36]],"id":52671556}],"con":true,"img":false}]}
{"op":"mcm","clk":"11450744826","pt":1717325113195,"mc":[{"id":"1.229554933","rc":[{"atb":[[2.86,0],[3.4,0],[3.15,0],[2.96,0]],"id":52671546}],"con":true,"img":false}]}
{"op":"mcm","clk":"11450744842","pt":1717325113304,"mc":[{"id":"1.229554933","rc":[{"atb":[[3.1,47.62]],"id":52671546}],"con":true,"img":false}]}
{"op":"mcm","clk":"11450744853","pt":1717325113401,"mc":[{"id":"1.229554933","rc":[{"atb":[[3.2,0]],"id":52671546}],"con":true,"img":false}]}
{"op":"mcm","clk":"11450744911","pt":1717325113949,"mc":[{"id":"1.229554933","rc":[{"atb":[[2.86,56.26],[3.4,10.9],[3.15,24.33],[2.96,40.04]],"id":52671546}],"con":true,"img":false}]}
{"op":"mcm","clk":"11450745284","pt":1717325117596,"mc":[{"id":"1.229554933","rc":[{"atb":[[2.86,0],[3.4,0],[3.15,7.29],[2.96,0],[3.05,0]],"id":52671546}],"con":true,"img":false}]}
{"op":"mcm","clk":"11450745352","pt":1717325118323,"mc":[{"id":"1.229554933","rc":[{"atb":[[2.9,55.07],[3,39.24],[3.25,23.25],[3.5,10.46]],"id":52671546}],"con":true,"img":false}]}
{"op":"mcm","clk":"11450745966","pt":1717325123909,"mc":[{"id":"1.229554933","rc":[{"atb":[[3.05,7.65]],"id":52671546}],"con":true,"img":false}]}
{"op":"mcm","clk":"11450745978","pt":1717325123998,"mc":[{"id":"1.229554933","rc":[{"atb":[[3.15,0]],"id":52671546}],"con":true,"img":false}]}
{"op":"mcm","clk":"11450746035","pt":1717325124516,"mc":[{"id":"1.229554933","rc":[{"atb":[[3.2,39.24],[3.1,0]],"id":52671546}],"con":true,"img":false}]}
{"op":"mcm","clk":"11450746518","pt":1717325129011,"mc":[{"id":"1.229554933","rc":[{"atb":[[3.15,7.29],[3.05,0]],"id":52671546}],"con":true,"img":false}]}
{"op":"mcm","clk":"11450748442","pt":1717325147354,"mc":[{"id":"1.229554933","rc":[{"atb":[[3.05,7.65]],"id":52671546}],"con":true,"img":false}]}
{"op":"mcm","clk":"11450748451","pt":1717325147456,"mc":[{"id":"1.229554933","rc":[{"atb":[[3.15,0]],"id":52671546}],"con":true,"img":false}]}
{"op":"mcm","clk":"11450752267","pt":1717325186024,"mc":[{"id":"1.229554933","rc":[{"atb":[[3.05,0]],"id":52671546}],"con":true,"img":false}]}
{"op":"mcm","clk":"11450754118","pt":1717325204754,"mc":[{"id":"1.229554933","rc":[{"atb":[[3.2,0],[3.35,39.24]],"id":52671546}],"con":true,"img":false}]}
{"op":"mcm","clk":"11450754148","pt":1717325205029,"mc":[{"id":"1.229554933","rc":[{"atl":[[9.4,0]],"id":52671546},{"atl":[[75,0]],"id":52671545},{"atl":[[80,0]],"id":52671554},{"atl":[[380,0]],"id":52671556}],"con":true,"img":false}]}
{"op":"mcm","clk":"11450754167","pt":1717325205235,"mc":[{"id":"1.229554933","rc":[{"atl":[[17,6.25],[19,0]],"id":52671546}],"con":true,"img":false}]}
{"op":"mcm","clk":"11450754276","pt":1717325206369,"mc":[{"id":"1.229554933","rc":[{"atl":[[400,0]],"id":52671556}],"con":true,"img":false}]}
{"op":"mcm","clk":"11450754286","pt":1717325206430,"mc":[{"id":"1.229554933","rc":[{"atb":[[7.2,16.13],[5.9,0]],"id":52671545},{"atl":[[2.64,9.56],[2.98,28.25]],"id":52671544},{"atb":[[2.42,52.37],[2.16,0]],"id":52671555},{"atb":[[7.2,16.13],[5.9,0]],"id":52671554},{"atb":[[7.2,16.13]],"id":52671556}],"con":true,"img":false}]}
{"op":"mcm","clk":"11450754296","pt":1717325206537,"mc":[{"id":"1.229554933","rc":[{"atb":[[5.9,0]],"id":52671556}],"con":true,"img":false}]}
{"op":"mcm","clk":"11450754329","pt":1717325206848,"mc":[{"id":"1.229554933","rc":[{"atl":[[2.64,0],[2.68,0]],"id":52671544}],"con":true,"img":false}]}
{"op":"mcm","clk":"11450754792","pt":1717325211543,"mc":[{"id":"1.229554933","rc":[{"atl":[[5.9,20.41]],"id":52671544}],"con":true,"img":false}]}
{"op":"mcm","clk":"11450754803","pt":1717325211646,"mc":[{"id":"1.229554933","rc":[{"atl":[[2.98,0]],"id":52671544}],"con":true,"img":false}]}
{"op":"mcm","clk":"11450758182","pt":1717325243206,"mc":[{"id":"1.229554933","rc":[{"atb":[[2.54,158.38],[2.74,60.07]],"id":52671546},{"atb":[[9,30.48],[12.5,9.08]],"id":52671545},{"atb":[[1.29,841.05],[1.39,268.02]],"id":52671544},{"atb":[[3,121.95],[3.5,41.81]],"id":52671555},{"atb":[[16,6.96],[11,24.39]],"id":52671554},{"atb":[[18,14.34],[26,4.18]],"id":52671556}],"con":true,"img":false}]}
{"op":"mcm","clk":"11450758847","pt":1717325249921,"mc":[{"id":"1.229554933","rc":[{"atb":[[2.54,316.76],[2.74,120.15]],"id":52671546},{"atb":[[9,60.97],[12.5,18.17]],"id":52671545},{"atb":[[1.29,1682.1],[1.39,536.05]],"id":52671544},{"atb":[[3,243.9],[3.5,83.62]],"id":52671555},{"atb":[[16,13.93],[11,48.78]],"id":52671554},{"atb":[[18,28.69],[26,8.36]],"id":52671556}],"con":true,"img":false}]}
{"op":"mcm","clk":"11450766939","pt":1717325324717,"mc":[{"id":"1.229554933","rc":[{"atb":[[3.35,0],[3.15,46.51]],"id":52671546}],"con":true,"img":false}]}
{"op":"mcm","clk":"11450768267","pt":1717325337734,"mc":[{"id":"1.229554933","rc":[{"atb":[[2.54,158.38],[2.74,60.07]],"id":52671546},{"atb":[[9,30.48],[12.5,9.08]],"id":52671545},{"atb":[[1.29,841.05],[1.39,268.02]],"id":52671544},{"atb":[[3,121.95],[3.5,41.81]],"id":52671555},{"atb":[[16,6.96],[11,24.39]],"id":52671554},{"atb":[[18,14.34],[26,4.18]],"id":52671556}],"con":true,"img":false}]}
{"op":"mcm","clk":"11450768810","pt":1717325342538,"mc":[{"id":"1.229554933","rc":[{"atb":[[2.54,316.76],[2.74,120.15]],"id":52671546},{"atb":[[9,60.97],[12.5,18.17]],"id":52671545},{"atb":[[1.29,1682.1],[1.39,536.05]],"id":52671544},{"atb":[[3,243.9],[3.5,83.62]],"id":52671555},{"atb":[[16,13.93],[11,48.78]],"id":52671554},{"atb":[[18,28.69],[26,8.36]],"id":52671556}],"con":true,"img":false}]}
{"op":"mcm","clk":"11450774756","pt":1717325396104,"mc":[{"id":"1.229554933","rc":[{"atb":[[2.54,158.38],[2.74,60.07]],"id":52671546},{"atb":[[9,30.48],[12.5,9.08]],"id":52671545},{"atb":[[1.29,841.05],[1.39,268.02]],"id":52671544},{"atb":[[3,121.95],[3.5,41.81]],"id":52671555},{"atb":[[16,6.96],[11,24.39]],"id":52671554},{"atb":[[18,14.34],[26,4.18]],"id":52671556}],"con":true,"img":false}]}
{"op":"mcm","clk":"11450775260","pt":1717325400870,"mc":[{"id":"1.229554933","rc":[{"atb":[[2.86,56.19],[2.66,146.92]],"id":52671546},{"atb":[[8.6,32.09],[11.5,9.95]],"id":52671545},{"atb":[[1.16,1524.4],[1.26,402.04]],"id":52671544},{"atb":[[3.25,108.4],[3.75,38]],"id":52671555},{"atb":[[10.5,25.67],[15.5,7.2]],"id":52671554},{"atb":[[19.5,13.18],[29,3.73]],"id":52671556}],"con":true,"img":false}]}
{"op":"mcm","clk":"11450776520","pt":1717325411428,"mc":[{"id":"1.229554933","rc":[{"atl":[[9.6,0]],"id":52671555}],"con":true,"img":false}]}
{"op":"mcm","clk":"11450777672","pt":1717325420795,"mc":[{"id":"1.229554933","rc":[{"atl":[[10,0]],"id":52671555}],"con":true,"img":false}]}
{"op":"mcm","clk":"11450777683","pt":1717325420904,"mc":[{"id":"1.229554933","rc":[{"atl":[[18.5,0],[170,2]],"id":52671555}],"con":true,"img":false}]}
{"op":"mcm","clk":"11450778798","pt":1717325430914,"mc":[{"id":"1.229554933","rc":[{"atb":[[2.86,0],[2.66,0]],"id":52671546},{"atb":[[8.6,0],[11.5,0]],"id":52671545},{"atb":[[1.16,0],[1.26,0]],"id":52671544},{"atb":[[3.25,0],[3.75,0]],"id":52671555},{"atb":[[10.5,0],[15.5,0]],"id":52671554},{"atb":[[19.5,0],[29,0]],"id":52671556}],"con":true,"img":false}]}
{"op":"mcm","clk":"11450779168","pt":1717325434437,"mc":[{"id":"1.229554933","rc":[{"atb":[[2.86,56.19],[2.66,146.92]],"id":52671546},{"atb":[[8.6,32.09],[11.5,9.95]],"id":52671545},{"atb":[[1.16,1524.4],[1.26,402.04]],"id":52671544},{"atb":[[3.25,108.4],[3.75,38]],"id":52671555},{"atb":[[10.5,25.67],[15.5,7.2]],"id":52671554},{"atb":[[19.5,13.18],[29,3.73]],"id":52671556}],"con":true,"img":false}]}
{"op":"mcm","clk":"11450779937","pt":1717325441867,"mc":[{"id":"1.229554933","rc":[{"atb":[[2.86,0],[2.66,0]],"id":52671546},{"atb":[[8.6,0],[11.5,0]],"id":52671545},{"atb":[[1.16,0],[1.26,0]],"id":52671544},{"atb":[[3.25,0],[3.75,0]],"id":52671555},{"atb":[[10.5,0],[15.5,0]],"id":52671554},{"atb":[[19.5,0],[29,0]],"id":52671556}],"con":true,"img":false}]}
{"op":"mcm","clk":"11450780637","pt":1717325448239,"mc":[{"id":"1.229554933","rc":[{"atb":[[2.86,56.19],[2.66,146.92]],"id":52671546},{"atb":[[8.6,32.09],[11.5,9.95]],"id":52671545},{"atb":[[1.16,1524.4],[1.26,402.04]],"id":52671544},{"atb":[[3.25,108.4],[3.75,38]],"id":52671555},{"atb":[[10.5,25.67],[15.5,7.2]],"id":52671554},{"atb":[[19.5,13.18],[29,3.73]],"id":52671556}],"con":true,"img":false}]}
{"op":"mcm","clk":"11450790304","pt":1717325536630,"mc":[{"id":"1.229554933","rc":[{"atb":[[2.86,0],[2.66,0]],"id":52671546},{"atb":[[8.6,0],[11.5,0]],"id":52671545},{"atb":[[1.16,0],[1.26,0]],"id":52671544},{"atb":[[3.25,0],[3.75,0]],"id":52671555},{"atb":[[10.5,0],[15.5,0]],"id":52671554},{"atb":[[19.5,0],[29,0]],"id":52671556}],"con":true,"img":false}]}
{"op":"mcm","clk":"11450791170","pt":1717325544431,"mc":[{"id":"1.229554933","rc":[{"atb":[[2.86,56.19],[2.66,146.92]],"id":52671546},{"atb":[[8.6,32.09],[11.5,9.95]],"id":52671545},{"atb":[[1.16,1524.4],[1.26,402.04]],"id":52671544},{"atb":[[3.25,108.4],[3.75,38]],"id":52671555},{"atb":[[10.5,25.67],[15.5,7.2]],"id":52671554},{"atb":[[19.5,13.18],[29,3.73]],"id":52671556}],"con":true,"img":false}]}
{"op":"mcm","clk":"11450792761","pt":1717325558455,"mc":[{"id":"1.229554933","rc":[{"atb":[[3,85.76],[3.15,0]],"id":52671546},{"atb":[[7.2,0],[1.35,18.18]],"id":52671545},{"atl":[[21,5],[5.9,0]],"id":52671544},{"atb":[[2.42,0],[3.1,47.62]],"id":52671555},{"atl":[[150,2],[170,0]],"id":52671555},{"atb":[[7.2,0],[14.5,7.41]],"id":52671556}],"con":true,"img":false}]}
{"op":"mcm","clk":"11450792794","pt":1717325558776,"mc":[{"id":"1.229554933","rc":[{"atl":[[9.8,0]],"id":52671546}],"con":true,"img":false}]}
{"op":"mcm","clk":"11450792817","pt":1717325558972,"mc":[{"id":"1.229554933","rc":[{"atl":[[17,0],[190,2]],"id":52671546}],"con":true,"img":false}]}
{"op":"mcm","clk":"11450793389","pt":1717325563550,"mc":[{"id":"1.229554933","rc":[{"atb":[[2.74,117.54],[3,39.24]],"id":52671546},{"atb":[[2.82,54.95],[3.1,0]],"id":52671555}],"con":true,"img":false}]}
{"op":"mcm","clk":"11450800420","pt":1717325627630,"mc":[{"id":"1.229554933","rc":[{"atb":[[2.86,0],[2.66,0]],"id":52671546},{"atb":[[8.6,0],[11.5,0]],"id":52671545},{"atb":[[1.16,0],[1.26,0]],"id":52671544},{"atb":[[3.25,0],[3.75,0]],"id":52671555},{"atb":[[10.5,0],[15.5,0]],"id":52671554},{"atb":[[19.5,0],[29,0]],"id":52671556}],"con":true,"img":false}]}
{"op":"mcm","clk":"11450801046","pt":1717325633458,"mc":[{"id":"1.229554933","rc":[{"atb":[[2.86,56.19],[2.66,146.92]],"id":52671546},{"atb":[[8.6,32.09],[11.5,9.95]],"id":52671545},{"atb":[[1.16,1524.4],[1.26,402.04]],"id":52671544},{"atb":[[3.25,108.4],[3.75,38]],"id":52671555},{"atb":[[10.5,25.67],[15.5,7.2]],"id":52671554},{"atb":[[19.5,13.18],[29,3.73]],"id":52671556}],"con":true,"img":false}]}
{"op":"mcm","clk":"11450804903","pt":1717325668204,"mc":[{"id":"1.229554933","rc":[{"atb":[[2.86,109.95],[2.74,60.07]],"id":52671546},{"atl":[[170,2],[190,0]],"id":52671546},{"atb":[[2.82,0],[3.05,48.78]],"id":52671555},{"atb":[[7.2,0],[11,34.39]],"id":52671554},{"atl":[[360,0],[430,2]],"id":52671554}],"con":true,"img":false}]}
{"op":"mcm","clk":"11450804934","pt":1717325668517,"mc":[{"id":"1.229554933","rc":[{"atl":[[85,0]],"id":52671545},{"atb":[[1.36,0]],"id":52671544},{"atl":[[90,0]],"id":52671554}],"con":true,"img":false}]}
{"op":"mcm","clk":"11450804945","pt":1717325668576,"mc":[{"id":"1.229554933","rc":[{"atl":[[340,0],[780,2]],"id":52671545}],"con":true,"img":false}]}
{"op":"mcm","clk":"11450805466","pt":1717325673308,"mc":[{"id":"1.229554933","rc":[{"atl":[[830,2],[430,0]],"id":52671554}],"con":true,"img":false}]}
{"op":"mcm","clk":"11450808216","pt":1717325699872,"mc":[{"id":"1.229554933","rc":[{"atb":[[2.86,53.76],[2.66,0]],"id":52671546},{"atb":[[8.6,0],[11.5,0]],"id":52671545},{"atb":[[1.16,0],[1.26,0]],"id":52671544},{"atb":[[3.25,0],[3.75,0]],"id":52671555},{"atb":[[10.5,0],[15.5,0]],"id":52671554},{"atb":[[19.5,0],[29,0]],"id":52671556}],"con":true,"img":false}]}
{"op":"mcm","clk":"11450808878","pt":1717325705677,"mc":[{"id":"1.229554933","rc":[{"atb":[[2.64,148.72],[2.84,56.81]],"id":52671546},{"atb":[[9.2,29.74],[13,8.71]],"id":52671545},{"atb":[[1.23,454.48],[1.13,1876.19]],"id":52671544}],"con":true,"img":false}]}
{"op":"mcm","clk":"11450808891","pt":1717325705784,"mc":[{"id":"1.229554933","rc":[{"atb":[[3.45,99.55],[3.95,35.43]],"id":52671555},{"atb":[[17.5,6.33],[12.5,21.2]],"id":52671554},{"atb":[[42,2.54],[26,13.93]],"id":52671556}],"con":true,"img":false}]}
{"op":"mcm","clk":"11450809979","pt":1717325715471,"mc":[{"id":"1.229554933","rc":[{"atb":[[2.64,0],[2.84,0]],"id":52671546},{"atb":[[9.2,0],[13,0]],"id":52671545},{"atb":[[1.23,0],[1.13,0]],"id":52671544},{"atb":[[3.45,0],[3.95,0]],"id":52671555},{"atb":[[17.5,0],[12.5,0]],"id":52671554},{"atb":[[42,0],[26,4.18]],"id":52671556}],"con":true,"img":false}]}
{"op":"mcm","clk":"11450810518","pt":1717325720670,"mc":[{"id":"1.229554933","rc":[{"atb":[[2.64,148.72],[2.84,56.81]],"id":52671546},{"atb":[[9.2,29.74],[13,8.71]],"id":52671545},{"atb":[[1.23,454.48],[1.13,1876.19]],"id":52671544},{"atb":[[3.45,99.55],[3.95,35.43]],"id":52671555},{"atb":[[17.5,6.33],[12.5,21.2]],"id":52671554},{"atb":[[42,2.54],[26,13.93]],"id":52671556}],"con":true,"img":false}]}
{"op":"mcm","clk":"11450811404","pt":1717325729316,"mc":[{"id":"1.229554933","rc":[{"atb":[[2.64,0],[2.84,0]],"id":52671546},{"atb":[[9.2,0],[13,0]],"id":52671545},{"atb":[[1.23,0],[1.13,0]],"id":52671544},{"atb":[[3.45,0],[3.95,0]],"id":52671555},{"atb":[[17.5,0],[12.5,0]],"id":52671554},{"atb":[[42,0],[26,4.18]],"id":52671556}],"con":true,"img":false}]}
{"op":"mcm","clk":"11450812025","pt":1717325734895,"mc":[{"id":"1.229554933","rc":[{"atb":[[2.8,58.07],[2.6,152.44]],"id":52671546},{"atb":[[9,60.97],[12.5,18.17]],"id":52671545},{"atb":[[1.14,2374.95],[1.24,435.54]],"id":52671544},{"atb":[[4,34.84],[3.5,139.37]],"id":52671555},{"atb":[[17.5,6.33],[12.5,21.2]],"id":52671554},{"atb":[[40,2.67],[25,10.16]],"id":52671556}],"con":true,"img":false}]}
{"op":"mcm","clk":"11450812753","pt":1717325741838,"mc":[{"id":"1.229554933","rc":[{"atb":[[2.8,0],[2.6,0]],"id":52671546},{"atb":[[9,30.48],[12.5,9.08]],"id":52671545},{"atb":[[1.14,632.78],[1.24,0]],"id":52671544},{"atb":[[4,0],[3.5,41.81]],"id":52671555},{"atb":[[17.5,0],[12.5,0]],"id":52671554},{"atb":[[40,0],[25,0]],"id":52671556}],"con":true,"img":false}]}
{"op":"mcm","clk":"11450813214","pt":1717325746041,"mc":[{"id":"1.229554933","rc":[{"atb":[[2.8,58.07],[2.6,152.44]],"id":52671546},{"atb":[[9.2,29.74],[13,8.71]],"id":52671545},{"atb":[[1.14,2374.95],[1.24,435.54]],"id":52671544},{"atb":[[4,34.84],[3.5,139.37]],"id":52671555},{"atb":[[18,6.14],[13,20.32]],"id":52671554},{"atb":[[44,4.87],[27,9.38]],"id":52671556}],"con":true,"img":false}]}
{"op":"mcm","clk":"11450814199","pt":1717325756854,"mc":[{"id":"1.229554933","rc":[{"atb":[[2.8,0],[2.6,0]],"id":52671546},{"atb":[[9.2,0],[13,0]],"id":52671545},{"atb":[[1.14,632.78],[1.24,0]],"id":52671544},{"atb":[[4,0],[3.5,41.81]],"id":52671555},{"atb":[[18,0],[13,0]],"id":52671554},{"atb":[[44,2.43],[27,0]],"id":52671556}],"con":true,"img":false}]}
{"op":"mcm","clk":"11450814559","pt":1717325760796,"mc":[{"id":"1.229554933","rc":[{"atb":[[2.8,58.07],[2.6,152.44]],"id":52671546},{"atb":[[13.5,8.36],[9.4,29.03]],"id":52671545},{"atb":[[1.23,454.48],[1.13,1876.19]],"id":52671544},{"atb":[[4,34.84],[3.5,139.37]],"id":52671555},{"atb":[[19,5.8],[14,18.76]],"id":52671554},{"atb":[[32,7.86],[55,1.93]],"id":52671556}],"con":true,"img":false}]}
{"op":"mcm","clk":"11450817270","pt":1717325788166,"mc":[{"id":"1.229554933","rc":[{"atb":[[2.86,0],[2.74,117.54]],"id":52671546},{"atl":[[170,0],[190,2]],"id":52671546},{"atl":[[780,0],[820,2]],"id":52671545},{"atb":[[2.9,52.63],[3.05,0]],"id":52671555},{"atl":[[150,0],[180,2]],"id":52671555},{"atl":[[830,0],[880,2]],"id":52671554}],"con":true,"img":false}]}
{"op":"mcm","clk":"11450818721","pt":1717325802973,"mc":[{"id":"1.229554933","rc":[{"atb":[[1.26,17.9],[1.35,0]],"id":52671545},{"atl":[[21,0],[22,4.76]],"id":52671544}],"con":true,"img":false}]}
{"op":"mcm","clk":"11450820000","pt":1717325814689,"mc":[{"id":"1.229554933","rc":[{"atb":[[2.8,0],[2.6,0]],"id":52671546},{"atb":[[13.5,0],[9.4,0]],"id":52671545},{"atb":[[1.23,0],[1.13,0]],"id":52671544},{"atb":[[4,0],[3.5,41.81]],"id":52671555},{"atb":[[19,0],[14,0]],"id":52671554},{"atb":[[32,0],[55,0]],"id":52671556}],"con":true,"img":false}]}
{"op":"mcm","clk":"11450820768","pt":1717325822417,"mc":[{"id":"1.229554933","rc":[{"atb":[[2.8,58.07],[2.6,152.44]],"id":52671546},{"atb":[[13.5,8.36],[9.4,29.03]],"id":52671545},{"atb":[[1.23,454.48],[1.13,1876.19]],"id":52671544},{"atb":[[4,34.84],[3.5,139.37]],"id":52671555},{"atb":[[19,5.8],[14,18.76]],"id":52671554},{"atb":[[32,7.86],[55,1.93]],"id":52671556}],"con":true,"img":false}]}
{"op":"mcm","clk":"11450822071","pt":1717325833131,"mc":[{"id":"1.229554933","rc":[{"atb":[[2.8,0],[2.6,0]],"id":52671546},{"atb":[[13.5,0],[9.4,0]],"id":52671545},{"atb":[[1.23,0],[1.13,0]],"id":52671544},{"atb":[[4,0],[3.5,41.81]],"id":52671555},{"atb":[[19,0],[14,0]],"id":52671554},{"atb":[[32,0],[55,0]],"id":52671556}],"con":true,"img":false}]}
{"op":"mcm","clk":"11450822100","pt":1717325833398,"mc":[{"id":"1.229554933","rc":[{"atb":[[2.74,60.07],[2.58,63.29]],"id":52671546},{"atl":[[260,2],[820,0]],"id":52671545},{"atb":[[1.27,757.91],[1.14,0]],"id":52671544},{"atb":[[3.45,40.82],[2.9,0]],"id":52671555},{"atl":[[350,2],[180,0]],"id":52671555},{"atb":[[11,24.39],[4.1,17.9]],"id":52671554},{"atl":[[880,0],[440,2]],"id":52671554},{"atb":[[6.8,17.24],[14.5,0]],"id":52671556},{"atl":[[650,2]],"id":52671556}],"con":true,"img":false}]}
{"op":"mcm","clk":"11450822108","pt":1717325833500,"mc":[{"id":"1.229554933","rc":[{"atb":[[2.84,54.35]],"id":52671546},{"atb":[[4.1,0]],"id":52671554},{"atl":[[440,0]],"id":52671554},{"atb":[[8.2,13.89]],"id":52671556},{"atl":[[600,2]],"id":52671556}],"con":true,"img":false}]}
{"op":"mcm","clk":"11450822119","pt":1717325833609,"mc":[{"id":"1.229554933","rc":[{"atb":[[2.58,0]],"id":52671546},{"atb":[[1.27,387.54],[1.31,322.58]],"id":52671544},{"atb":[[3.45,0],[3.9,34.48]],"id":52671555},{"atl":[[310,2],[350,0]],"id":52671555},{"atb":[[4.8,17.9]],"id":52671554},{"atl":[[410,2]],"id":52671554},{"atb":[[6.8,0]],"id":52671556},{"atl":[[650,0]],"id":52671556}],"con":true,"img":false}]}
{"op":"mcm","clk":"11450822913","pt":1717325841143,"mc":[{"id":"1.229554933","rc":[{"atb":[[2.8,58.07],[2.6,152.44]],"id":52671546},{"atb":[[13.5,8.36],[9.4,29.03]],"id":52671545},{"atb":[[1.23,454.48],[1.13,1876.19]],"id":52671544},{"atb":[[4,34.84],[3.5,139.37]],"id":52671555},{"atb":[[19,5.8],[14,18.76]],"id":52671554},{"atb":[[32,7.86],[55,1.93]],"id":52671556}],"con":true,"img":false}]}
{"op":"mcm","clk":"11450824211","pt":1717325853040,"mc":[{"id":"1.229554933","rc":[{"atl":[[270,2]],"id":52671545}],"con":true,"img":false}]}
{"op":"mcm","clk":"11450824225","pt":1717325853142,"mc":[{"id":"1.229554933","rc":[{"atl":[[260,0]],"id":52671545}],"con":true,"img":false}]}
{"op":"mcm","clk":"11450824292","pt":1717325853660,"mc":[{"id":"1.229554933","rc":[{"atb":[[3.1,39.24],[2.84,0]],"id":52671546},{"atl":[[260,2],[310,0]],"id":52671555},{"atl":[[410,0],[400,2]],"id":52671554},{"atb":[[8.2,0],[9.4,11.9]],"id":52671556},{"atl":[[600,0],[680,2]],"id":52671556}],"con":true,"img":false}]}
{"op":"mcm","clk":"11450824305","pt":1717325853758,"mc":[{"id":"1.229554933","rc":[{"atl":[[270,0],[260,2]],"id":52671545}],"con":true,"img":false}]}
{"op":"mcm","clk":"11450824364","pt":1717325854236,"mc":[{"id":"1.229554933","rc":[{"atl":[[270,2]],"id":52671545}],"con":true,"img":false}]}
{"op":"mcm","clk":"11450824374","pt":1717325854337,"mc":[{"id":"1.229554933","rc":[{"atl":[[260,0]],"id":52671545}],"con":true,"img":false}]}
{"op":"mcm","clk":"11450824876","pt":1717325858946,"mc":[{"id":"1.229554933","rc":[{"atb":[[1.25,400]],"id":52671544}],"con":true,"img":false}]}
{"op":"mcm","clk":"11450824891","pt":1717325859051,"mc":[{"id":"1.229554933","rc":[{"atb":[[1.31,0]],"id":52671544}],"con":true,"img":false}]}
{"op":"mcm","clk":"11450824953","pt":1717325859665,"mc":[{"id":"1.229554933","rc":[{"atl":[[270,0],[260,2]],"id":52671545}],"con":true,"img":false}]}
{"op":"mcm","clk":"11450824975","pt":1717325859873,"mc":[{"id":"1.229554933","rc":[{"atl":[[270,2]],"id":52671545}],"con":true,"img":false}]}
{"op":"mcm","clk":"11450824983","pt":1717325859976,"mc":[{"id":"1.229554933","rc":[{"atl":[[260,0]],"id":52671545}],"con":true,"img":false}]}
{"op":"mcm","clk":"11450825535","pt":1717325864974,"mc":[{"id":"1.229554933","rc":[{"atl":[[260,2]],"id":52671545}],"con":true,"img":false}]}
{"op":"mcm","clk":"11450825549","pt":1717325865073,"mc":[{"id":"1.229554933","rc":[{"atl":[[270,0]],"id":52671545}],"con":true,"img":false}]}
{"op":"mcm","clk":"11450826776","pt":1717325875490,"mc":[{"id":"1.229554933","rc":[{"atl":[[250,2]],"id":52671555}],"con":true,"img":false}]}
{"op":"mcm","clk":"11450826788","pt":1717325875551,"mc":[{"id":"1.229554933","rc":[{"atl":[[260,0]],"id":52671555}],"con":true,"img":false}]}
{"op":"mcm","clk":"11450827848","pt":1717325885974,"mc":[{"id":"1.229554933","rc":[{"atl":[[260,2]],"id":52671555}],"con":true,"img":false}]}
{"op":"mcm","clk":"11450827857","pt":1717325886079,"mc":[{"id":"1.229554933","rc":[{"atl":[[250,0]],"id":52671555}],"con":true,"img":false}]}
{"op":"mcm","clk":"11450828421","pt":1717325891004,"mc":[{"id":"1.229554933","rc":[{"atl":[[690,2]],"id":52671556}],"con":true,"img":false}]}
{"op":"mcm","clk":"11450828435","pt":1717325891105,"mc":[{"id":"1.229554933","rc":[{"atl":[[680,0]],"id":52671556}],"con":true,"img":false}]}
{"op":"mcm","clk":"11450829503","pt":1717325900303,"mc":[{"id":"1.229554933","rc":[{"atl":[[260,0],[270,2]],"id":52671545}],"con":true,"img":false}]}
{"op":"mcm","clk":"11450829642","pt":1717325901596,"mc":[{"id":"1.229554933","rc":[{"atl":[[270,0],[260,2]],"id":52671545}],"con":true,"img":false}]}
{"op":"mcm","clk":"11450829706","pt":1717325902218,"mc":[{"id":"1.229554933","rc":[{"atl":[[270,2]],"id":52671545}],"con":true,"img":false}]}
{"op":"mcm","clk":"11450829716","pt":1717325902324,"mc":[{"id":"1.229554933","rc":[{"atl":[[260,0]],"id":52671545}],"con":true,"img":false}]}
{"op":"mcm","clk":"11450829902","pt":1717325904335,"mc":[{"id":"1.229554933","rc":[{"atl":[[310,2]],"id":52671545},{"atl":[[420,2]],"id":52671554}],"con":true,"img":false}]}
{"op":"mcm","clk":"11450829916","pt":1717325904437,"mc":[{"id":"1.229554933","rc":[{"atl":[[270,0]],"id":52671545},{"atl":[[400,0]],"id":52671554}],"con":true,"img":false}]}
{"op":"mcm","clk":"11450829980","pt":1717325905009,"mc":[{"id":"1.229554933","rc":[{"atl":[[260,2]],"id":52671545},{"atl":[[400,2]],"id":52671554}],"con":true,"img":false}]}
{"op":"mcm","clk":"11450829992","pt":1717325905113,"mc":[{"id":"1.229554933","rc":[{"atl":[[310,0]],"id":52671545},{"atl":[[420,0]],"id":52671554}],"con":true,"img":false}]}
{"op":"mcm","clk":"11450830265","pt":1717325907809,"mc":[{"id":"1.229554933","rc":[{"atb":[[3.2,39.24]],"id":52671546}],"con":true,"img":false}]}
{"op":"mcm","clk":"11450830273","pt":1717325907911,"mc":[{"id":"1.229554933","rc":[{"atb":[[3.1,0]],"id":52671546}],"con":true,"img":false}]}
{"op":"mcm","clk":"11450830509","pt":1717325910337,"mc":[{"id":"1.229554933","rc":[{"atl":[[260,0],[300,2]],"id":52671545},{"atl":[[400,0],[420,2]],"id":52671554}],"con":true,"img":false}]}
{"op":"mcm","clk":"11450830772","pt":1717325912821,"mc":[{"id":"1.229554933","rc":[{"atl":[[260,0],[270,2]],"id":52671555},{"atl":[[690,0],[700,2]],"id":52671556}],"con":true,"img":false}]}
{"op":"mcm","clk":"11450830975","pt":1717325914643,"mc":[{"id":"1.229554933","rc":[{"atb":[[2.8,0],[2.6,0]],"id":52671546},{"atb":[[13.5,0],[9.4,0]],"id":52671545},{"atb":[[1.23,0],[1.13,0]],"id":52671544},{"atb":[[4,0],[3.5,41.81]],"id":52671555},{"atb":[[19,0],[14,0]],"id":52671554},{"atb":[[32,0],[55,0]],"id":52671556}],"con":true,"img":false}]}
{"op":"mcm","clk":"11450831055","pt":1717325915423,"mc":[{"id":"1.229554933","rc":[{"atl":[[260,2],[300,0]],"id":52671545},{"atl":[[400,2],[420,0]],"id":52671554}],"con":true,"img":false}]}
{"op":"mcm","clk":"11450831154","pt":1717325916421,"mc":[{"id":"1.229554933","rc":[{"atl":[[260,0],[250,2]],"id":52671545}],"con":true,"img":false}]}
{"op":"mcm","clk":"11450831219","pt":1717325917038,"mc":[{"id":"1.229554933","rc":[{"atl":[[290,2]],"id":52671545},{"atl":[[420,2]],"id":52671554}],"con":true,"img":false}]}
{"op":"mcm","clk":"11450831226","pt":1717325917138,"mc":[{"id":"1.229554933","rc":[{"atl":[[250,0]],"id":52671545},{"atl":[[400,0]],"id":52671554}],"con":true,"img":false}]}
{"op":"mcm","clk":"11450831245","pt":1717325917345,"mc":[{"id":"1.229554933","rc":[{"atl":[[290,0],[250,2]],"id":52671545}],"con":true,"img":false}]}
{"op":"mcm","clk":"11450831315","pt":1717325917914,"mc":[{"id":"1.229554933","rc":[{"atl":[[270,0],[260,2]],"id":52671555},{"atl":[[400,2],[420,0]],"id":52671554}],"con":true,"img":false}]}
{"op":"mcm","clk":"11450831414","pt":1717325918748,"mc":[{"id":"1.229554933","rc":[{"atl":[[290,2],[250,0]],"id":52671545},{"atl":[[400,0],[420,2]],"id":52671554}],"con":true,"img":false}]}
{"op":"mcm","clk":"11450831428","pt":1717325918847,"mc":[{"id":"1.229554933","rc":[{"atl":[[260,0],[270,2]],"id":52671555}],"con":true,"img":false}]}
{"op":"mcm","clk":"11450831823","pt":1717325922426,"mc":[{"id":"1.229554933","rc":[{"atb":[[2.64,148.72],[2.84,56.81]],"id":52671546},{"atb":[[9.6,28.36],[14,8.04]],"id":52671545},{"atb":[[1.21,497.76],[1.11,2217.31]],"id":52671544},{"atb":[[3.45,99.55],[3.95,35.43]],"id":52671555},{"atb":[[18.5,5.97],[13.5,19.51]],"id":52671554},{"atb":[[34,7.39],[60,3.1]],"id":52671556}],"con":true,"img":false}]}
{"op":"mcm","clk":"11450831904","pt":1717325923162,"mc":[{"id":"1.229554933","rc":[{"atl":[[400,2],[420,0]],"id":52671554}],"con":true,"img":false}]}
{"op":"mcm","clk":"11450831980","pt":1717325923874,"mc":[{"id":"1.229554933","rc":[{"atl":[[290,0],[250,2]],"id":52671545}],"con":true,"img":false}]}
{"op":"mcm","clk":"11450831989","pt":1717325923984,"mc":[{"id":"1.229554933","rc":[{"atl":[[270,0],[260,2]],"id":52671555}],"con":true,"img":false}]}
{"op":"mcm","clk":"11450832447","pt":1717325928063,"mc":[{"id":"1.229554933","rc":[{"atl":[[290,2],[250,0]],"id":52671545},{"atl":[[400,0],[420,2]],"id":52671554}],"con":true,"img":false}]}
{"op":"mcm","clk":"11450839241","pt":1717325929457,"mc":[{"id":"1.229554933","rc":[{"atl":[[290,0],[250,2]],"id":52671545}],"con":true,"img":false}]}
{"op":"mcm","clk":"11450839643","pt":1717325933156,"mc":[{"id":"1.229554933","rc":[{"atl":[[290,2]],"id":52671545}],"con":true,"img":false}]}
{"op":"mcm","clk":"11450839656","pt":1717325933263,"mc":[{"id":"1.229554933","rc":[{"atl":[[250,0]],"id":52671545}],"con":true,"img":false}]}
{"op":"mcm","clk":"11450840242","pt":1717325939063,"mc":[{"id":"1.229554933","rc":[{"atb":[[3.2,0],[3,85.76]],"id":52671546},{"atb":[[3.55,39.22],[3.9,0]],"id":52671555},{"atl":[[260,0],[230,2]],"id":52671555},{"atl":[[700,0],[680,2]],"id":52671556}],"con":true,"img":false}]}
{"op":"mcm","clk":"11450840522","pt":1717325942176,"mc":[{"id":"1.229554933","rc":[{"atb":[[2.64,0],[2.84,0]],"id":52671546},{"atb":[[9.6,0],[14,0]],"id":52671545},{"atb":[[1.21,0],[1.11,0]],"id":52671544},{"atb":[[3.45,0],[3.95,0]],"id":52671555},{"atb":[[18.5,0],[13.5,0]],"id":52671554},{"atb":[[34,0],[60,1.33]],"id":52671556}],"con":true,"img":false}]}
{"op":"mcm","clk":"11450840711","pt":1717325944100,"mc":[{"id":"1.229554933","rc":[{"atl":[[220,2],[230,0]],"id":52671555},{"atl":[[670,2],[680,0]],"id":52671556}],"con":true,"img":false}]}
{"op":"mcm","clk":"11450840801","pt":1717325944888,"mc":[{"id":"1.229554933","rc":[{"atl":[[290,0],[300,2]],"id":52671545}],"con":true,"img":false}]}
{"op":"mcm","clk":"11450840991","pt":1717325946901,"mc":[{"id":"1.229554933","rc":[{"atb":[[2.64,148.72],[2.84,56.81]],"id":52671546},{"atb":[[13.5,8.36],[9.4,29.03]],"id":52671545},{"atb":[[1.12,2032.54],[1.22,475.13]],"id":52671544},{"atb":[[3.45,99.55],[3.95,35.43]],"id":52671555},{"atb":[[18,6.14],[13,20.32]],"id":52671554},{"atb":[[46,2.32],[28,9.03]],"id":52671556}],"con":true,"img":false}]}
{"op":"mcm","clk":"11450841084","pt":1717325947784,"mc":[{"id":"1.229554933","rc":[{"atl":[[300,0],[310,2]],"id":52671545}],"con":true,"img":false}]}
{"op":"mcm","clk":"11450841309","pt":1717325950308,"mc":[{"id":"1.229554933","rc":[{"atl":[[300,2],[310,0]],"id":52671545}],"con":true,"img":false}]}
{"op":"mcm","clk":"11450841371","pt":1717325951096,"mc":[{"id":"1.229554933","rc":[{"atl":[[310,2]],"id":52671545}],"con":true,"img":false}]}
{"op":"mcm","clk":"11450841379","pt":1717325951196,"mc":[{"id":"1.229554933","rc":[{"atl":[[300,0]],"id":52671545}],"con":true,"img":false}]}
{"op":"mcm","clk":"11450841389","pt":1717325951300,"mc":[{"id":"1.229554933","rc":[{"atl":[[300,2]],"id":52671545}],"con":true,"img":false}]}
{"op":"mcm","clk":"11450841399","pt":1717325951400,"mc":[{"id":"1.229554933","rc":[{"atl":[[310,0]],"id":52671545}],"con":true,"img":false}]}
{"op":"mcm","clk":"11450841739","pt":1717325954221,"mc":[{"id":"1.229554933","rc":[{"atl":[[220,0],[240,2]],"id":52671555},{"atl":[[670,0],[690,2]],"id":52671556}],"con":true,"img":false}]}
{"op":"mcm","clk":"11450841814","pt":1717325954909,"mc":[{"id":"1.229554933","rc":[{"atl":[[300,0],[310,2]],"id":52671545}],"con":true,"img":false}]}
{"op":"mcm","clk":"11450842043","pt":1717325957432,"mc":[{"id":"1.229554933","rc":[{"atb":[[2.64,0],[2.84,0]],"id":52671546},{"atb":[[13.5,0],[9.4,0]],"id":52671545},{"atb":[[1.12,0],[1.22,0]],"id":52671544},{"atb":[[3.45,0],[3.95,0]],"id":52671555},{"atb":[[18,0],[13,0]],"id":52671554},{"atb":[[46,0],[28,0]],"id":52671556}],"con":true,"img":false}]}
{"op":"mcm","clk":"11450842402","pt":1717325961391,"mc":[{"id":"1.229554933","rc":[{"atl":[[290,2],[310,0]],"id":52671545}],"con":true,"img":false}]}
{"op":"mcm","clk":"11450842636","pt":1717325964324,"mc":[{"id":"1.229554933","rc":[{"atb":[[2.58,154.36],[2.78,58.72]],"id":52671546},{"atb":[[13.5,8.36],[9.4,29.03]],"id":52671545},{"atb":[[1.27,774.69],[1.17,1434.73]],"id":52671544},{"atb":[[3.8,37.33],[3.3,106.04]],"id":52671555},{"atb":[[18,6.14],[13,20.32]],"id":52671554},{"atb":[[42,2.54],[26,13.93]],"id":52671556}],"con":true,"img":false}]}
{"op":"mcm","clk":"11450842665","pt":1717325964697,"mc":[{"id":"1.229554933","rc":[{"atl":[[290,0],[300,2]],"id":52671545}],"con":true,"img":false}]}
{"op":"mcm","clk":"11450842830","pt":1717325966559,"mc":[{"id":"1.229554933","rc":[{"atl":[[300,0],[290,2]],"id":52671545}],"con":true,"img":false}]}
{"op":"mcm","clk":"11450842844","pt":1717325966759,"mc":[{"id":"1.229554933","rc":[{"atl":[[290,0],[310,2]],"id":52671545}],"con":true,"img":false}]}
{"op":"mcm","clk":"11450842853","pt":1717325966862,"mc":[{"id":"1.229554933","rc":[{"atl":[[290,2],[310,0]],"id":52671545}],"con":true,"img":false}]}
{"op":"mcm","clk":"11450842862","pt":1717325966966,"mc":[{"id":"1.229554933","rc":[{"atl":[[290,0],[310,2]],"id":52671545}],"con":true,"img":false}]}
{"op":"mcm","clk":"11450843187","pt":1717325970253,"mc":[{"id":"1.229554933","rc":[{"atl":[[240,0],[250,2]],"id":52671555}],"con":true,"img":false}]}
{"op":"mcm","clk":"11450843367","pt":1717325972065,"mc":[{"id":"1.229554933","rc":[{"atl":[[290,2],[310,0]],"id":52671545}],"con":true,"img":false}]}
{"op":"mcm","clk":"11450843403","pt":1717325972375,"mc":[{"id":"1.229554933","rc":[{"atb":[[2.58,0],[2.78,0]],"id":52671546},{"atb":[[13.5,0],[9.4,0]],"id":52671545},{"atb":[[1.27,387.54],[1.17,0]],"id":52671544},{"atb":[[3.8,0],[3.3,0]],"id":52671555},{"atb":[[18,0],[13,0]],"id":52671554},{"atb":[[42,0],[26,4.18]],"id":52671556}],"con":true,"img":false}]}
{"op":"mcm","clk":"11450843651","pt":1717325974669,"mc":[{"id":"1.229554933","rc":[{"atl":[[300,2]],"id":52671545}],"con":true,"img":false}]}
{"op":"mcm","clk":"11450843662","pt":1717325974774,"mc":[{"id":"1.229554933","rc":[{"atl":[[290,0]],"id":52671545},{"atl":[[410,2],[420,0]],"id":52671554}],"con":true,"img":false}]}
{"op":"mcm","clk":"11450843741","pt":1717325975349,"mc":[{"id":"1.229554933","rc":[{"atl":[[260,2],[250,0]],"id":52671555},{"atl":[[690,0],[680,2]],"id":52671556}],"con":true,"img":false}]}
{"op":"mcm","clk":"11450843800","pt":1717325975868,"mc":[{"id":"1.229554933","rc":[{"atb":[[3.8,35.71],[3.55,0]],"id":52671555},{"atl":[[260,0],[290,2]],"id":52671555},{"atb":[[4.8,0],[5.3,17.9]],"id":52671554},{"atl":[[680,0],[700,2]],"id":52671556}],"con":true,"img":false}]}
{"op":"mcm","clk":"11450843942","pt":1717325977272,"mc":[{"id":"1.229554933","rc":[{"atb":[[2.58,154.36],[2.78,58.72]],"id":52671546},{"atb":[[9.6,28.36],[14,8.04]],"id":52671545},{"atb":[[1.27,774.69],[1.17,1434.73]],"id":52671544},{"atb":[[3.8,73.04],[3.3,106.04]],"id":52671555},{"atb":[[19,5.8],[14,18.76]],"id":52671554},{"atb":[[50,2.13],[30,8.41]],"id":52671556}],"con":true,"img":false}]}
{"op":"mcm","clk":"11450843952","pt":1717325977378,"mc":[{"id":"1.229554933","rc":[{"atl":[[410,0],[430,2]],"id":52671554}],"con":true,"img":false}]}
{"op":"mcm","clk":"11450844198","pt":1717325979871,"mc":[{"id":"1.229554933","rc":[{"atl":[[430,0],[420,2]],"id":52671554}],"con":true,"img":false}]}
{"op":"mcm","clk":"11450844267","pt":1717325980599,"mc":[{"id":"1.229554933","rc":[{"atb":[[3,39.24],[2.84,54.35]],"id":52671546},{"atl":[[530,2],[300,0]],"id":52671545},{"atb":[[1.25,0],[1.16,536.06]],"id":52671544},{"atb":[[9.4,0],[15.5,6.9]],"id":52671556},{"atl":[[700,0]],"id":52671556}],"con":true,"img":false}]}
{"op":"mcm","clk":"11450844309","pt":1717325980967,"mc":[{"id":"1.229554933","rc":[{"atl":[[270,2],[290,0]],"id":52671555},{"atb":[[5.3,0],[14,26.45]],"id":52671554}],"con":true,"img":false}]}
{"op":"mcm","clk":"11450844452","pt":1717325982365,"mc":[{"id":"1.229554933","rc":[{"atl":[[760,2],[420,0]],"id":52671554}],"con":true,"img":false}]}
{"op":"mcm","clk":"11450844850","pt":1717325986180,"mc":[{"id":"1.229554933","rc":[{"atl":[[530,0],[540,2]],"id":52671545},{"atl":[[270,0],[260,2]],"id":52671555},{"atl":[[760,0],[770,2]],"id":52671554}],"con":true,"img":false}]}
{"op":"mcm","clk":"11450844874","pt":1717325986378,"mc":[{"id":"1.229554933","rc":[{"atb":[[2.58,0],[2.78,0]],"id":52671546},{"atb":[[9.6,0],[14,0]],"id":52671545},{"atb":[[1.27,387.54],[1.17,0]],"id":52671544},{"atb":[[3.8,35.71],[3.3,0]],"id":52671555},{"atb":[[19,0],[14,7.69]],"id":52671554},{"atb":[[50,0],[30,0]],"id":52671556}],"con":true,"img":false}]}
{"op":"mcm","clk":"11450845403","pt":1717325991181,"mc":[{"id":"1.229554933","rc":[{"atl":[[770,0],[780,2]],"id":52671554}],"con":true,"img":false}]}
{"op":"mcm","clk":"11450845446","pt":1717325991591,"mc":[{"id":"1.229554933","rc":[{"atl":[[540,0],[550,2]],"id":52671545},{"atl":[[780,0],[790,2]],"id":52671554}],"con":true,"img":false}]}
{"op":"mcm","clk":"11450845577","pt":1717325992997,"mc":[{"id":"1.229554933","rc":[{"atb":[[2.8,58.07],[2.6,152.44]],"id":52671546},{"atb":[[11,10.45],[8.4,32.96]],"id":52671545},{"atb":[[1.19,1283.7],[1.29,1201.5]],"id":52671544},{"atb":[[3.8,73.04],[3.3,106.04]],"id":52671555},{"atb":[[10.5,25.67],[15.5,7.2]],"id":52671554},{"atb":[[19,13.55],[28,3.87]],"id":52671556}],"con":true,"img":false}]}
{"op":"mcm","clk":"11450845648","pt":1717325993783,"mc":[{"id":"1.229554933","rc":[{"atl":[[85,2],[190,0]],"id":52671546},{"atb":[[1.26,0],[1.17,18.18]],"id":52671545},{"atl":[[22,0],[26,4]],"id":52671544}],"con":true,"img":false}]}
{"op":"mcm","clk":"11450845948","pt":1717325996629,"mc":[{"id":"1.229554933","rc":[{"atl":[[550,0],[560,2]],"id":52671545},{"atl":[[260,0],[250,2]],"id":52671555},{"atb":[[17,6.25],[14,0]],"id":52671554},{"atl":[[790,0],[800,2]],"id":52671554}],"con":true,"img":false}]}
{"op":"mcm","clk":"11450846136","pt":1717325998399,"mc":[{"id":"1.229554933","rc":[{"atl":[[560,0],[550,2]],"id":52671545},{"atl":[[260,2],[250,0]],"id":52671555}],"con":true,"img":false}]}
{"op":"mcm","clk":"11450846216","pt":1717325999322,"mc":[{"id":"1.229554933","rc":[{"atb":[[2.8,0],[2.6,0]],"id":52671546},{"atb":[[11,0],[8.4,0]],"id":52671545},{"atb":[[1.19,0],[1.29,841.05]],"id":52671544},{"atb":[[3.8,35.71],[3.3,0]],"id":52671555},{"atb":[[10.5,0],[15.5,0]],"id":52671554},{"atb":[[19,0],[28,0]],"id":52671556}],"con":true,"img":false}]}
{"op":"mcm","clk":"11450846497","pt":1717326001625,"mc":[{"id":"1.229554933","rc":[{"atb":[[2.8,58.07],[2.6,152.44]],"id":52671546},{"atb":[[11,10.45],[8.4,32.96]],"id":52671545},{"atb":[[1.19,1283.7],[1.29,1201.5]],"id":52671544},{"atb":[[3.8,73.04],[3.3,106.04]],"id":52671555},{"atb":[[10.5,25.67],[15.5,7.2]],"id":52671554},{"atb":[[19,13.55],[28,3.87]],"id":52671556}],"con":true,"img":false}]}
{"op":"mcm","clk":"11450846510","pt":1717326001731,"mc":[{"id":"1.229554933","rc":[{"atl":[[550,0],[570,2]],"id":52671545},{"atl":[[230,2]],"id":52671555},{"atl":[[800,0],[810,2]],"id":52671554}],"con":true,"img":false}]}
{"op":"mcm","clk":"11450846524","pt":1717326001839,"mc":[{"id":"1.229554933","rc":[{"atl":[[260,0]],"id":52671555}],"con":true,"img":false}]}
{"op":"mcm","clk":"11450847087","pt":1717326006648,"mc":[{"id":"1.229554933","rc":[{"atl":[[820,2]],"id":52671554}],"con":true,"img":false}]}
{"op":"mcm","clk":"11450847099","pt":1717326006751,"mc":[{"id":"1.229554933","rc":[{"atl":[[810,0]],"id":52671554}],"con":true,"img":false}]}
{"op":"mcm","clk":"11450847483","pt":1717326010239,"mc":[{"id":"1.229554933","rc":[{"atb":[[2.8,0],[2.6,0]],"id":52671546},{"atb":[[11,0],[8.4,0]],"id":52671545},{"atb":[[1.19,0],[1.29,841.05]],"id":52671544},{"atb":[[3.8,35.71],[3.3,0]],"id":52671555},{"atb":[[10.5,0],[15.5,0]],"id":52671554},{"atb":[[19,0],[28,0]],"id":52671556}],"con":true,"img":false}]}
{"op":"mcm","clk":"11450847622","pt":1717326011948,"mc":[{"id":"1.229554933","rc":[{"atb":[[2.66,60.24],[2.84,0]],"id":52671546},{"atl":[[210,2],[230,0]],"id":52671555}],"con":true,"img":false}]}
{"op":"mcm","clk":"11450847690","pt":1717326012530,"mc":[{"id":"1.229554933","rc":[{"atb":[[2.88,55.6],[2.68,145.18]],"id":52671546},{"atb":[[8,14.93],[6,48.78]],"id":52671545},{"atb":[[1.2,1219.52],[1.3,348.43]],"id":52671544},{"atb":[[3.45,99.55],[3.95,35.43]],"id":52671555},{"atb":[[8.6,32.09],[11.5,9.95]],"id":52671554},{"atb":[[19.5,5.65],[14.5,18.06]],"id":52671556}],"con":true,"img":false}]}
{"op":"mcm","clk":"11450848153","pt":1717326016652,"mc":[{"id":"1.229554933","rc":[{"atb":[[24,0.28]],"id":52671545},{"trd":[[24,1.7]],"ltp":24.0,"tv":1.7,"id":52671545},{"atb":[[34,1.34],[44,0]],"id":52671554},{"trd":[[34,0.47],[44,1.22]],"ltp":34.0,"tv":1.69,"id":52671554},{"atb":[[85,0],[120,0]],"id":52671556},{"trd":[[85,1.25],[120,0.44]],"ltp":85.0,"tv":1.69,"id":52671556}],"con":true,"img":false}]}
{"op":"mcm","clk":"11450848204","pt":1717326017125,"mc":[{"id":"1.229554933","rc":[{"atl":[[190,2],[210,0]],"id":52671555},{"atl":[[820,0],[840,2]],"id":52671554}],"con":true,"img":false}]}
{"op":"mcm","clk":"11450848216","pt":1717326017230,"mc":[{"id":"1.229554933","rc":[{"atl":[[570,0],[580,2]],"id":52671545}],"con":true,"img":false}]}
{"op":"mcm","clk":"11450848435","pt":1717326019311,"mc":[{"id":"1.229554933","rc":[{"atl":[[200,2]],"id":52671555},{"atb":[[19.5,5.41]],"id":52671554}],"con":true,"img":false}]}
{"op":"mcm","clk":"11450848447","pt":1717326019416,"mc":[{"id":"1.229554933","rc":[{"atb":[[7.6,15.15],[1.17,0]],"id":52671545},{"atl":[[190,0]],"id":52671555},{"atb":[[17,0]],"id":52671554}],"con":true,"img":false}]}
{"op":"mcm","clk":"11450848459","pt":1717326019476,"mc":[{"id":"1.229554933","rc":[{"atb":[[2.88,0],[2.68,0]],"id":52671546},{"atb":[[8,0],[6,0]],"id":52671545},{"atb":[[1.2,0],[1.3,0]],"id":52671544},{"atb":[[3.45,0],[3.95,0]],"id":52671555},{"atb":[[8.6,0],[11.5,0]],"id":52671554},{"atb":[[32,3.23],[19.5,0],[14.5,0]],"id":52671556}],"con":true,"img":false}]}
{"op":"mcm","clk":"11450848468","pt":1717326019573,"mc":[{"id":"1.229554933","rc":[{"atb":[[15.5,0]],"id":52671556}],"con":true,"img":false}]}
{"op":"mcm","clk":"11450848680","pt":1717326021812,"mc":[{"id":"1.229554933","rc":[{"atb":[[4.1,33.71],[3.55,95.64]],"id":52671555},{"atb":[[8.6,32.09],[11.5,9.95]],"id":52671554},{"atb":[[20,5.5],[15,17.42]],"id":52671556}],"con":true,"img":false}]}
{"op":"mcm","clk":"11450848686","pt":1717326021865,"mc":[{"id":"1.229554933","rc":[{"atb":[[2.86,56.19],[2.66,207.16]],"id":52671546},{"atb":[[8,14.93],[6,48.78]],"id":52671545},{"atb":[[1.19,1283.7],[1.29,1201.5]],"id":52671544}],"con":true,"img":false}]}
{"op":"mcm","clk":"11450848714","pt":1717326022179,"mc":[{"id":"1.229554933","rc":[{"atb":[[2.54,223.32],[2.66,146.92]],"id":52671546}],"con":true,"img":false}]}
{"op":"mcm","clk":"11450848723","pt":1717326022286,"mc":[{"id":"1.229554933","rc":[{"atl":[[190,2],[200,0]],"id":52671555}],"con":true,"img":false}]}
{"op":"mcm","clk":"11450848898","pt":1717326024047,"mc":[{"id":"1.229554933","rc":[{"atl":[[580,0],[600,2]],"id":52671545},{"atl":[[840,0],[850,2]],"id":52671554}],"con":true,"img":false}]}
{"op":"mcm","clk":"11450848955","pt":1717326024415,"mc":[{"id":"1.229554933","rc":[{"atl":[[190,0],[200,2]],"id":52671555}],"con":true,"img":false}]}
{"op":"mcm","clk":"11450849263","pt":1717326027215,"mc":[{"id":"1.229554933","rc":[{"atl":[[200,0],[210,2]],"id":52671555},{"atl":[[850,0],[860,2]],"id":52671554}],"con":true,"img":false}]}
{"op":"mcm","clk":"11450849343","pt":1717326027783,"mc":[{"id":"1.229554933","rc":[{"atb":[[7.6,0],[1.17,18.18]],"id":52671545},{"atb":[[32,0],[17,6.25]],"id":52671556}],"con":true,"img":false}]}
{"op":"mcm","clk":"11450849498","pt":1717326029081,"mc":[{"id":"1.229554933","rc":[{"atl":[[580,2]],"id":52671545}],"con":true,"img":false}]}
{"op":"mcm","clk":"11450849510","pt":1717326029180,"mc":[{"id":"1.229554933","rc":[{"atl":[[600,0]],"id":52671545}],"con":true,"img":false}]}
{"op":"mcm","clk":"11450849817","pt":1717326032305,"mc":[{"id":"1.229554933","rc":[{"atl":[[860,0],[850,2]],"id":52671554}],"con":true,"img":false}]}
{"op":"mcm","clk":"11450850273","pt":1717326036338,"mc":[{"id":"1.229554933","rc":[{"atb":[[2.86,0],[2.66,0]],"id":52671546},{"atb":[[8,0],[6,0]],"id":52671545},{"atb":[[1.19,0],[1.29,841.05]],"id":52671544},{"atb":[[4.1,0],[3.55,0]],"id":52671555},{"atb":[[8.6,0],[11.5,0]],"id":52671554},{"atb":[[20,0],[15,0]],"id":52671556}],"con":true,"img":false}]}
{"op":"mcm","clk":"11450850365","pt":1717326037429,"mc":[{"id":"1.229554933","rc":[{"atl":[[540,2],[580,0]],"id":52671545},{"atb":[[19.5,0],[15.5,6.9]],"id":52671554},{"atl":[[800,2],[850,0]],"id":52671554}],"con":true,"img":false}]}
{"op":"mcm","clk":"11450850895","pt":1717326042520,"mc":[{"id":"1.229554933","rc":[{"atb":[[2.8,58.07],[2.54,158.38],[2.6,152.44],[2.68,59.52]],"id":52671546},{"atb":[[8,14.93],[6,48.78]],"id":52671545},{"atb":[[1.25,975.61],[1.35,298.66]],"id":52671544},{"atb":[[3.4,101.62],[3.9,36.04]],"id":52671555},{"atl":[[210,0],[220,2]],"id":52671555},{"atb":[[12,9.5],[8.8,31.27]],"id":52671554},{"atl":[[780,2]],"id":52671554},{"atb":[[19.5,5.65],[14.5,18.06]],"id":52671556}],"con":true,"img":false}]}
{"op":"mcm","clk":"11450850906","pt":1717326042625,"mc":[{"id":"1.229554933","rc":[{"atl":[[800,0]],"id":52671554}],"con":true,"img":false}]}
{"op":"mcm","clk":"11450851396","pt":1717326047624,"mc":[{"id":"1.229554933","rc":[{"atl":[[540,0],[560,2]],"id":52671545},{"atl":[[210,2],[220,0]],"id":52671555},{"atl":[[780,0],[810,2]],"id":52671554}],"con":true,"img":false}]}
{"op":"mcm","clk":"11450851580","pt":1717326049646,"mc":[{"id":"1.229554933","rc":[{"atb":[[2.8,0],[2.6,0]],"id":52671546},{"atb":[[8,0],[6,0]],"id":52671545},{"atb":[[1.25,0],[1.35,0]],"id":52671544},{"atb":[[3.4,0],[3.9,0]],"id":52671555},{"atb":[[12,0],[8.8,0]],"id":52671554},{"atb":[[19.5,0],[14.5,0]],"id":52671556}],"con":true,"img":false}]}
{"op":"mcm","clk":"11450851901","pt":1717326052927,"mc":[{"id":"1.229554933","rc":[{"atl":[[810,0],[800,2]],"id":52671554}],"con":true,"img":false}]}
{"op":"mcm","clk":"11450851936","pt":1717326053349,"mc":[{"id":"1.229554933","rc":[{"atb":[[2.58,154.36],[2.78,58.72]],"id":52671546},{"atb":[[8,14.93],[6,48.78]],"id":52671545},{"atb":[[1.27,1290.89],[1.37,423.91]],"id":52671544},{"atb":[[3.4,101.62],[3.9,36.04]],"id":52671555},{"atb":[[9,30.48],[12.5,9.08]],"id":52671554},{"atb":[[19,5.8],[14,18.76]],"id":52671556}],"con":true,"img":false}]}
{"op":"mcm","clk":"11450852412","pt":1717326058052,"mc":[{"id":"1.229554933","rc":[{"atl":[[560,0],[550,2]],"id":52671545}],"con":true,"img":false}]}
{"op":"mcm","clk":"11450852423","pt":1717326058103,"mc":[{"id":"1.229554933","rc":[{"atl":[[780,2],[800,0]],"id":52671554}],"con":true,"img":false}]}
{"op":"mcm","clk":"11450852660","pt":1717326060310,"mc":[{"id":"1.229554933","rc":[{"atb":[[1.02,5000]],"id":52671546},{"atb":[[1.02,5000]],"id":52671545},{"atb":[[1.02,5000]],"id":52671544},{"atb":[[1.02,5008.94]],"id":52671555},{"atb":[[1.02,5000]],"id":52671554},{"atb":[[1.02,5000]],"id":52671556}],"con":true,"img":false}]}
{"op":"mcm","clk":"11450852680","pt":1717326060571,"mc":[{"id":"1.229554933","rc":[{"atb":[[2.58,0],[2.78,0]],"id":52671546},{"atb":[[8,0],[6,0]],"id":52671545},{"atb":[[1.27,387.54],[1.37,141.4]],"id":52671544},{"atb":[[3.4,0],[3.9,0]],"id":52671555},{"atb":[[9,0],[12.5,0]],"id":52671554},{"atb":[[19,0],[14,0]],"id":52671556}],"con":true,"img":false}]}
{"op":"mcm","clk":"11450852783","pt":1717326061618,"mc":[{"id":"1.229554933","rc":[{"atb":[[2.8,55.56]],"id":52671546},{"atl":[[230,2]],"id":52671555}],"con":true,"img":false}]}
{"op":"mcm","clk":"11450852789","pt":1717326061724,"mc":[{"id":"1.229554933","rc":[{"atb":[[2.68,0]],"id":52671546},{"atl":[[550,0],[580,2]],"id":52671545},{"atl":[[210,0]],"id":52671555},{"atl":[[780,0],[800,2]],"id":52671554}],"con":true,"img":false}]}
{"op":"mcm","clk":"11450852943","pt":1717326063240,"mc":[{"id":"1.229554933","rc":[{"atl":[[570,2],[580,0]],"id":52671545}],"con":true,"img":false}]}
{"op":"mcm","clk":"11450853037","pt":1717326064226,"mc":[{"id":"1.229554933","rc":[{"atb":[[2.64,148.72],[2.84,56.81]],"id":52671546},{"atb":[[7.8,15.37],[5.9,49.77]],"id":52671545},{"atb":[[1.21,1161.45],[1.31,337.19]],"id":52671544},{"atb":[[3.6,93.81],[4.2,32.66]],"id":52671555},{"atb":[[12,9.5],[8.8,31.27]],"id":52671554},{"atb":[[19.5,5.65],[14.5,18.06]],"id":52671556}],"con":true,"img":false}]}
{"op":"mcm","clk":"11450853463","pt":1717326068336,"mc":[{"id":"1.229554933","rc":[{"atl":[[570,0],[550,2]],"id":52671545},{"atl":[[230,0],[240,2]],"id":52671555},{"atl":[[760,2],[800,0]],"id":52671554}],"con":true,"img":false}]}
{"op":"mcm","clk":"11450853472","pt":1717326068440,"mc":[{"id":"1.229554933","rc":[{"atl":[[85,0],[120,2]],"id":52671546},{"atb":[[1.44,18.18],[1.17,0]],"id":52671545},{"atl":[[34,3.03],[26,0]],"id":52671544},{"atb":[[6.6,17.86]],"id":52671554},{"atb":[[17,0],[20,5.26]],"id":52671556}],"con":true,"img":false}]}
{"op":"mcm","clk":"11450853481","pt":1717326068544,"mc":[{"id":"1.229554933","rc":[{"atb":[[15.5,0]],"id":52671554}],"con":true,"img":false}]}
{"op":"mcm","clk":"11450853715","pt":1717326070421,"mc":[{"id":"1.229554933","rc":[{"atl":[[260,2],[240,0]],"id":52671555}],"con":true,"img":false}]}
{"op":"mcm","clk":"11450853888","pt":1717326072035,"mc":[{"id":"1.229554933","rc":[{"atb":[[2.64,0],[2.84,0]],"id":52671546},{"atb":[[7.8,0],[5.9,0]],"id":52671545},{"atb":[[1.21,0],[1.31,0]],"id":52671544},{"atb":[[3.6,0],[4.2,0]],"id":52671555},{"atb":[[12,0],[8.8,0]],"id":52671554},{"atb":[[19.5,0],[14.5,0]],"id":52671556}],"con":true,"img":false}]}
{"op":"mcm","clk":"11450854038","pt":1717326073347,"mc":[{"id":"1.229554933","rc":[{"atb":[[2.9,107.7]],"id":52671546},{"atl":[[260,0],[290,2]],"id":52671555},{"atl":[[770,2]],"id":52671554}],"con":true,"img":false}]}
{"op":"mcm","clk":"11450854046","pt":1717326073451,"mc":[{"id":"1.229554933","rc":[{"atb":[[2.8,0]],"id":52671546},{"atl":[[760,0]],"id":52671554}],"con":true,"img":false}]}
{"op":"mcm","clk":"11450854074","pt":1717326073709,"mc":[{"id":"1.229554933","rc":[{"atb":[[1.34,0]],"id":52671544}],"con":true,"img":false}]}
{"op":"mcm","clk":"11450854314","pt":1717326075801,"mc":[{"id":"1.229554933","rc":[{"atb":[[2.64,148.72],[2.84,56.81],[3.5,2.96]],"id":52671546},{"trd":[[3.5,15]],"ltp":3.5,"tv":15.0,"id":52671546},{"atb":[[7.8,15.37],[5.9,49.77]],"id":52671545},{"atb":[[1.21,1161.45],[1.31,337.19]],"id":52671544},{"atb":[[3.6,93.81],[4.2,32.66]],"id":52671555},{"atb":[[12,9.5],[8.8,31.27]],"id":52671554},{"atb":[[19.5,5.65],[14.5,18.06]],"id":52671556}],"con":true,"img":false}]}
{"op":"mcm","clk":"11450854437","pt":1717326076881,"mc":[{"id":"1.229554933","rc":[{"atl":[[280,2]],"id":52671555}],"con":true,"img":false}]}
{"op":"mcm","clk":"11450854449","pt":1717326076989,"mc":[{"id":"1.229554933","rc":[{"atl":[[290,0]],"id":52671555}],"con":true,"img":false}]}
{"op":"mcm","clk":"11450854599","pt":1717326078398,"mc":[{"id":"1.229554933","rc":[{"atl":[[280,0],[290,2]],"id":52671555},{"atl":[[770,0],[780,2]],"id":52671554}],"con":true,"img":false}]}
{"op":"mcm","clk":"11450854920","pt":1717326081806,"mc":[{"id":"1.229554933","rc":[{"atb":[[3.25,20.98],[3.5,0]],"id":52671546},{"trd":[[3.25,4.53],[3.5,20.93]],"ltp":3.25,"tv":25.46,"id":52671546}],"con":true,"img":false}]}
{"op":"mcm","clk":"11450854930","pt":1717326081908,"mc":[{"id":"1.229554933","rc":[{"atb":[[2.82,54.95],[2.9,55.07]],"id":52671546}],"con":true,"img":false}]}
{"op":"mcm","clk":"11450855017","pt":1717326082790,"mc":[{"id":"1.229554933","rc":[{"atb":[[2.64,0],[2.84,0]],"id":52671546},{"atb":[[7.8,0],[5.9,0]],"id":52671545},{"atb":[[1.21,0],[1.31,0]],"id":52671544},{"atb":[[3.6,0],[4.2,0]],"id":52671555},{"atb":[[12,0],[8.8,0]],"id":52671554},{"atb":[[19.5,0],[14.5,0]],"id":52671556}],"con":true,"img":false}]}
{"op":"mcm","clk":"11450855075","pt":1717326083314,"mc":[{"id":"1.229554933","rc":[{"atl":[[1000,0.96]],"id":52671546},{"atl":[[1000,0.96]],"id":52671545},{"atl":[[1000,0.78]],"id":52671555},{"atl":[[1000,0.78]],"id":52671554},{"atl":[[1000,0.78]],"id":52671556}],"con":true,"img":false}]}
{"op":"mcm","clk":"11450855089","pt":1717326083425,"mc":[{"id":"1.229554933","rc":[{"atb":[[3.3,1.55]],"id":52671546},{"atb":[[1.43,1.62]],"id":52671544}],"con":true,"img":false}]}
{"op":"mcm","clk":"11450855112","pt":1717326083625,"mc":[{"id":"1.229554933","rc":[{"atl":[[290,0],[300,2]],"id":52671555},{"atl":[[780,0],[790,2]],"id":52671554}],"con":true,"img":false}]}
{"op":"mcm","clk":"11450855132","pt":1717326083778,"mc":[{"id":"1.229554933","rc":[{"atb":[[1.49,15]],"id":52671544}],"con":true,"img":false}]}
{"op":"mcm","clk":"11450855145","pt":1717326083936,"mc":[{"id":"1.229554933","rc":[{"atl":[[1000,0.45]],"id":52671546},{"atl":[[1000,0.44]],"id":52671545},{"atl":[[1000,0.28]],"id":52671555},{"atl":[[1000,0.27]],"id":52671554},{"atl":[[1000,0.25]],"id":52671556}],"con":true,"img":false}]}
{"op":"mcm","clk":"11450855154","pt":1717326084033,"mc":[{"id":"1.229554933","rc":[{"atl":[[540,2],[550,0]],"id":52671545}],"con":true,"img":false}]}
{"op":"mcm","clk":"11450855237","pt":1717326084924,"mc":[{"id":"1.229554933","rc":[{"atl":[[48,2],[120,0]],"id":52671546},{"atb":[[1.44,0],[1.53,18.18]],"id":52671545},{"atl":[[34,0],[40,2.56]],"id":52671544}],"con":true,"img":false}]}
{"op":"mcm","clk":"11450855457","pt":1717326086995,"mc":[{"id":"1.229554933","rc":[{"atb":[[2.82,0],[2.94,51.55]],"id":52671546}],"con":true,"img":false}]}
{"op":"mcm","clk":"11450855484","pt":1717326087309,"mc":[{"id":"1.229554933","rc":[{"atb":[[2.58,154.36],[2.78,58.72]],"id":52671546},{"atb":[[8,14.93],[6,48.78]],"id":52671545},{"atb":[[1.27,1290.89],[1.37,423.91]],"id":52671544},{"atb":[[3.4,101.62],[3.9,36.04]],"id":52671555},{"atb":[[9,30.48],[12.5,9.08]],"id":52671554},{"atb":[[19,5.8],[14,18.76]],"id":52671556}],"con":true,"img":false}]}
{"op":"mcm","clk":"11450855610","pt":1717326088500,"mc":[{"id":"1.229554933","rc":[{"atb":[[5.8,0.22]],"id":52671555},{"trd":[[5.8,10.46]],"ltp":5.8,"tv":10.46,"id":52671555}],"con":true,"img":false}]}
{"op":"mcm","clk":"11450855619","pt":1717326088606,"mc":[{"id":"1.229554933","rc":[{"atl":[[50,2.04]],"id":52671546},{"atl":[[530,2]],"id":52671545},{"atl":[[300,0],[310,2]],"id":52671555}],"con":true,"img":false}]}
{"op":"mcm","clk":"11450855633","pt":1717326088711,"mc":[{"id":"1.229554933","rc":[{"atl":[[48,0]],"id":52671546},{"atl":[[540,0]],"id":52671545}],"con":true,"img":false}]}
{"op":"mcm","clk":"11450855641","pt":1717326088816,"mc":[{"id":"1.229554933","rc":[{"atl":[[750,2],[790,0]],"id":52671554}],"con":true,"img":false}]}
{"op":"mcm","clk":"11450855785","pt":1717326090330,"mc":[{"id":"1.229554933","rc":[{"atb":[[2.68,93]],"id":52671546},{"atb":[[8.6,29]],"id":52671545},{"atb":[[1.3,192]],"id":52671544},{"atl":[[2.84,44]],"id":52671544},{"atb":[[3.35,75]],"id":52671555},{"atb":[[11,47.39]],"id":52671554},{"atb":[[13,19]],"id":52671556}],"con":true,"img":false}]}
{"op":"mcm","clk":"11450855798","pt":1717326090430,"mc":[{"id":"1.229554933","rc":[{"atl":[[9,12.5],[40,0]],"id":52671544}],"con":true,"img":false}]}
{"op":"mcm","clk":"11450855820","pt":1717326090537,"mc":[{"id":"1.229554933","rc":[{"atl":[[2.82,0.78]],"id":52671544}],"con":true,"img":false}]}
{"op":"mcm","clk":"11450855843","pt":1717326090739,"mc":[{"id":"1.229554933","rc":[{"atb":[[4.5,28.57],[3.8,0]],"id":52671555}],"con":true,"img":false}]}
{"op":"mcm","clk":"11450855903","pt":1717326091217,"mc":[{"id":"1.229554933","rc":[{"atl":[[2.82,0.25]],"id":52671544}],"con":true,"img":false}]}
{"op":"mcm","clk":"11450855990","pt":1717326092139,"mc":[{"id":"1.229554933","rc":[{"atb":[[3.25,41.97],[2.94,0]],"id":52671546}],"con":true,"img":false}]}
{"op":"mcm","clk":"11450856148","pt":1717326093706,"mc":[{"id":"1.229554933","rc":[{"atl":[[48,2],[50,0]],"id":52671546},{"atl":[[290,2],[310,0]],"id":52671555},{"atl":[[750,0],[760,2]],"id":52671554}],"con":true,"img":false}]}
{"op":"mcm","clk":"11450856663","pt":1717326098838,"mc":[{"id":"1.229554933","rc":[{"atl":[[48,0],[55,2]],"id":52671546},{"atl":[[760,0],[750,2]],"id":52671554}],"con":true,"img":false}]}
{"op":"mcm","clk":"11450856670","pt":1717326098938,"mc":[{"id":"1.229554933","rc":[{"atb":[[34,0.56]],"id":52671554},{"trd":[[34,2.04]],"ltp":34.0,"tv":2.04,"id":52671554}],"con":true,"img":false}]}
{"op":"mcm","clk":"11450856699","pt":1717326099247,"mc":[{"id":"1.229554933","rc":[{"atb":[[3.3,3.17]],"id":52671546}],"con":true,"img":false}]}
{"op":"mcm","clk":"11450856713","pt":1717326099348,"mc":[{"id":"1.229554933","rc":[{"atb":[[3.35,39.24],[3.25,20.98]],"id":52671546}],"con":true,"img":false}]}
{"op":"mcm","clk":"11450856750","pt":1717326099714,"mc":[{"id":"1.229554933","rc":[{"atb":[[3.3,1.61]],"id":52671546}],"con":true,"img":false}]}
{"op":"mcm","clk":"11450856758","pt":1717326099812,"mc":[{"id":"1.229554933","rc":[{"atb":[[3.3,43.48],[3.4,1.55]],"id":52671546}],"con":true,"img":false}]}
{"op":"mcm","clk":"11450856767","pt":1717326099928,"mc":[{"id":"1.229554933","rc":[{"atb":[[3.35,0],[3.4,3.17]],"id":52671546}],"con":true,"img":false}]}
{"op":"mcm","clk":"11450856803","pt":1717326100333,"mc":[{"id":"1.229554933","rc":[{"atb":[[3.4,1.61]],"id":52671546}],"con":true,"img":false}]}
{"op":"mcm","clk":"11450856818","pt":1717326100444,"mc":[{"id":"1.229554933","rc":[{"atb":[[3.35,1.55],[3.4,0]],"id":52671546}],"con":true,"img":false}]}
{"op":"mcm","clk":"11450856829","pt":1717326100539,"mc":[{"id":"1.229554933","rc":[{"atb":[[3.35,3.17]],"id":52671546}],"con":true,"img":false}]}
{"op":"mcm","clk":"11450856917","pt":1717326101326,"mc":[{"id":"1.229554933","rc":[{"atl":[[65,2],[55,0]],"id":52671546},{"atb":[[1.98,18.18],[1.53,0]],"id":52671545},{"atl":[[9,0],[3.1,44.26]],"id":52671544},{"atb":[[9.2,12.2],[6.6,0]],"id":52671554},{"atb":[[20,0],[27,3.85]],"id":52671556}],"con":true,"img":false}]}
{"op":"mcm","clk":"11450856984","pt":1717326101948,"mc":[{"id":"1.229554933","rc":[{"atb":[[3.3,0],[3.15,41.98]],"id":52671546}],"con":true,"img":false}]}
{"op":"mcm","clk":"11450857023","pt":1717326102254,"mc":[{"id":"1.229554933","rc":[{"atb":[[3.35,0]],"id":52671546}],"con":true,"img":false}]}
{"op":"mcm","clk":"11450857036","pt":1717326102351,"mc":[{"id":"1.229554933","rc":[{"atb":[[3.3,3.17]],"id":52671546}],"con":true,"img":false}]}
{"op":"mcm","clk":"11450857061","pt":1717326102615,"mc":[{"id":"1.229554933","rc":[{"atb":[[2.58,0],[2.78,0]],"id":52671546},{"atb":[[8,0],[6,0]],"id":52671545},{"atb":[[1.27,387.54],[1.37,141.4]],"id":52671544},{"atb":[[3.4,0],[3.9,0]],"id":52671555},{"atb":[[9,0],[12.5,0]],"id":52671554},{"atb":[[19,0],[14,0]],"id":52671556}],"con":true,"img":false}]}
{"op":"mcm","clk":"11450857072","pt":1717326102721,"mc":[{"id":"1.229554933","rc":[{"atb":[[60,0.54]],"id":52671556},{"trd":[[60,1.56]],"ltp":60.0,"tv":1.56,"id":52671556}],"con":true,"img":false}]}
{"op":"mcm","clk":"11450857184","pt":1717326103857,"mc":[{"id":"1.229554933","rc":[{"atl":[[530,0],[520,2]],"id":52671545},{"atl":[[730,2],[750,0]],"id":52671554}],"con":true,"img":false}]}
{"op":"mcm","clk":"11450857290","pt":1717326104953,"mc":[{"id":"1.229554933","rc":[{"atl":[[310,2]],"id":52671555}],"con":true,"img":false}]}
{"op":"mcm","clk":"11450857297","pt":1717326105064,"mc":[{"id":"1.229554933","rc":[{"atl":[[290,0]],"id":52671555}],"con":true,"img":false}]}
{"op":"mcm","clk":"11450857322","pt":1717326105365,"mc":[{"id":"1.229554933","rc":[{"atb":[[2.74,151.07],[2.68,0]],"id":52671546},{"atl":[[2.8,45],[2.84,0]],"id":52671544},{"atb":[[3.45,72],[3.35,0]],"id":52671555},{"atb":[[9.2,39.2],[11,24.39]],"id":52671554}],"con":true,"img":false}]}
{"op":"mcm","clk":"11450857347","pt":1717326105568,"mc":[{"id":"1.229554933","rc":[{"atl":[[2.82,0]],"id":52671544}],"con":true,"img":false}]}
{"op":"mcm","clk":"11450857353","pt":1717326105628,"mc":[{"id":"1.229554933","rc":[{"atl":[[2.78,0.25]],"id":52671544}],"con":true,"img":false}]}
{"op":"mcm","clk":"11450857386","pt":1717326105936,"mc":[{"id":"1.229554933","rc":[{"atl":[[520,0],[530,2]],"id":52671545}],"con":true,"img":false}]}
{"op":"mcm","clk":"11450857408","pt":1717326106144,"mc":[{"id":"1.229554933","rc":[{"atl":[[740,2]],"id":52671554}],"con":true,"img":false}]}
{"op":"mcm","clk":"11450857424","pt":1717326106251,"mc":[{"id":"1.229554933","rc":[{"atl":[[730,0]],"id":52671554}],"con":true,"img":false}]}
{"op":"mcm","clk":"11450857436","pt":1717326106351,"mc":[{"id":"1.229554933","rc":[{"atb":[[3.4,101.62],[3.9,36.04]],"id":52671555},{"atb":[[9,30.48],[12.5,9.08]],"id":52671554},{"atb":[[19,5.8],[14,18.76]],"id":52671556}],"con":true,"img":false}]}
{"op":"mcm","clk":"11450857445","pt":1717326106451,"mc":[{"id":"1.229554933","rc":[{"atb":[[2.58,154.36],[2.78,58.72]],"id":52671546},{"atb":[[8,14.93],[6,48.78]],"id":52671545},{"atb":[[1.27,1290.89],[1.37,423.91]],"id":52671544},{"atb":[[42,2.44]],"id":52671556}],"con":true,"img":false}]}
{"op":"mcm","clk":"11450857460","pt":1717326106553,"mc":[{"id":"1.229554933","rc":[{"atb":[[27,0]],"id":52671556}],"con":true,"img":false}]}
{"op":"mcm","clk":"11450857508","pt":1717326107134,"mc":[{"id":"1.229554933","rc":[{"atb":[[3.35,20.99],[3.15,0]],"id":52671546}],"con":true,"img":false}]}
{"op":"mcm","clk":"11450857543","pt":1717326107544,"mc":[{"id":"1.229554933","rc":[{"atb":[[3.3,1.61]],"id":52671546}],"con":true,"img":false}]}
{"op":"mcm","clk":"11450857549","pt":1717326107650,"mc":[{"id":"1.229554933","rc":[{"atb":[[3.3,43.59],[3.4,1.55]],"id":52671546}],"con":true,"img":false}]}
{"op":"mcm","clk":"11450857554","pt":1717326107749,"mc":[{"id":"1.229554933","rc":[{"atb":[[3.35,0],[3.3,41.98]],"id":52671546}],"con":true,"img":false}]}
{"op":"mcm","clk":"11450857562","pt":1717326107861,"mc":[{"id":"1.229554933","rc":[{"atb":[[3.4,3.17]],"id":52671546}],"con":true,"img":false}]}
{"op":"mcm","clk":"11450857596","pt":1717326108265,"mc":[{"id":"1.229554933","rc":[{"atb":[[3.4,1.61]],"id":52671546}],"con":true,"img":false}]}
{"op":"mcm","clk":"11450857603","pt":1717326108326,"mc":[{"id":"1.229554933","rc":[{"atb":[[3.35,1.55],[3.4,0]],"id":52671546}],"con":true,"img":false}]}
{"op":"mcm","clk":"11450857610","pt":1717326108464,"mc":[{"id":"1.229554933","rc":[{"atb":[[3.35,3.17]],"id":52671546},{"atb":[[19.5,2.33],[24,0]],"id":52671545},{"trd":[[19.5,0.99],[24,2.28]],"ltp":19.5,"tv":3.27,"id":52671545}],"con":true,"img":false}]}
{"op":"mcm","clk":"11450857643","pt":1717326108851,"mc":[{"id":"1.229554933","rc":[{"atl":[[65,0],[70,2]],"id":52671546}],"con":true,"img":false}]}
{"op":"mcm","clk":"11450857652","pt":1717326108952,"mc":[{"id":"1.229554933","rc":[{"atl":[[720,2],[740,0]],"id":52671554}],"con":true,"img":false}]}
{"op":"mcm","clk":"11450857924","pt":1717326111536,"mc":[{"id":"1.229554933","rc":[{"atb":[[1.98,0],[8.4,13.51]],"id":52671545}],"con":true,"img":false}]}
{"op":"mcm","clk":"11450858047","pt":1717326112767,"mc":[{"id":"1.229554933","rc":[{"atb":[[3.4,20.99]],"id":52671546}],"con":true,"img":false}]}
{"op":"mcm","clk":"11450858059","pt":1717326112870,"mc":[{"id":"1.229554933","rc":[{"atb":[[3.3,0]],"id":52671546}],"con":true,"img":false}]}
{"op":"mcm","clk":"11450858098","pt":1717326113142,"mc":[{"id":"1.229554933","rc":[{"atb":[[3.35,1.55]],"id":52671546}],"con":true,"img":false}]}
{"op":"mcm","clk":"11450858112","pt":1717326113240,"mc":[{"id":"1.229554933","rc":[{"atb":[[3.4,22.6]],"id":52671546}],"con":true,"img":false}]}
{"op":"mcm","clk":"11450858132","pt":1717326113452,"mc":[{"id":"1.229554933","rc":[{"atb":[[2.58,0],[2.78,0]],"id":52671546},{"atb":[[8,0],[6,0]],"id":52671545},{"atb":[[1.27,387.54],[1.37,141.4]],"id":52671544},{"atb":[[3.4,0],[3.9,0]],"id":52671555},{"atb":[[9,0],[12.5,0]],"id":52671554},{"atb":[[19,0],[14,0]],"id":52671556}],"con":true,"img":false}]}
{"op":"mcm","clk":"11450858188","pt":1717326113976,"mc":[{"id":"1.229554933","rc":[{"atl":[[70,0],[75,2]],"id":52671546},{"atl":[[300,2],[310,0]],"id":52671555}],"con":true,"img":false}]}
{"op":"mcm","clk":"11450858201","pt":1717326114069,"mc":[{"id":"1.229554933","rc":[{"atb":[[42,0],[27,3.85]],"id":52671556}],"con":true,"img":false}]}
{"op":"mcm","clk":"11450858374","pt":1717326115783,"mc":[{"id":"1.229554933","rc":[{"atb":[[2.58,154.36],[2.78,58.72]],"id":52671546},{"atb":[[8,14.93],[6,48.78]],"id":52671545},{"atb":[[1.28,871.08],[1.38,275.08]],"id":52671544},{"atb":[[3.85,36.67],[3.35,103.78]],"id":52671555},{"atb":[[12,9.5],[8.8,31.27]],"id":52671554},{"atb":[[19,5.8],[14,18.76]],"id":52671556}],"con":true,"img":false}]}
{"op":"mcm","clk":"11450858409","pt":1717326116043,"mc":[{"id":"1.229554933","rc":[{"atl":[[300,0],[310,2]],"id":52671555}],"con":true,"img":false}]}
{"op":"mcm","clk":"11450858711","pt":1717326118944,"mc":[{"id":"1.229554933","rc":[{"atl":[[75,0],[80,2]],"id":52671546},{"atl":[[310,0],[320,2]],"id":52671555}],"con":true,"img":false}]}
{"op":"mcm","clk":"11450858750","pt":1717326119356,"mc":[{"id":"1.229554933","rc":[{"atb":[[1.98,102.04],[8.4,0]],"id":52671545},{"atl":[[720,0],[730,2]],"id":52671554}],"con":true,"img":false}]}
{"op":"mcm","clk":"11450858847","pt":1717326120393,"mc":[{"id":"1.229554933","rc":[{"atb":[[2.74,60.07],[2.78,148.72]],"id":52671546}],"con":true,"img":false}]}
{"op":"mcm","clk":"11450858974","pt":1717326121698,"mc":[{"id":"1.229554933","rc":[{"atb":[[50,1.04]],"id":52671556}],"con":true,"img":false}]}
{"op":"mcm","clk":"11450858993","pt":1717326121853,"mc":[{"id":"1.229554933","rc":[{"atb":[[46,1.68]],"id":52671556}],"con":true,"img":false}]}
{"op":"mcm","clk":"11450859004","pt":1717326121957,"mc":[{"id":"1.229554933","rc":[{"atb":[[3.35,0]],"id":52671546}],"con":true,"img":false}]}
{"op":"mcm","clk":"11450859013","pt":1717326122065,"mc":[{"id":"1.229554933","rc":[{"atb":[[3.45,1.55]],"id":52671546},{"atb":[[4.8,31.52]],"id":52671555}],"con":true,"img":false}]}
{"op":"mcm","clk":"11450859037","pt":1717326122266,"mc":[{"id":"1.229554933","rc":[{"atb":[[4.5,45.78]],"id":52671555}],"con":true,"img":false}]}
{"op":"mcm","clk":"11450859053","pt":1717326122469,"mc":[{"id":"1.229554933","rc":[{"atb":[[28,1.86]],"id":52671554}],"con":true,"img":false}]}
{"op":"mcm","clk":"11450859065","pt":1717326122571,"mc":[{"id":"1.229554933","rc":[{"atb":[[26,2.98]],"id":52671554}],"con":true,"img":false}]}
{"op":"mcm","clk":"11450859085","pt":1717326122779,"mc":[{"id":"1.229554933","rc":[{"atb":[[2.84,18.37]],"id":52671546}],"con":true,"img":false}]}
{"op":"mcm","clk":"11450859096","pt":1717326122886,"mc":[{"id":"1.229554933","rc":[{"atb":[[2.62,29.55]],"id":52671546}],"con":true,"img":false}]}
{"op":"mcm","clk":"11450859127","pt":1717326123145,"mc":[{"id":"1.229554933","rc":[{"atb":[[16,3.26]],"id":52671545}],"con":true,"img":false}]}
{"op":"mcm","clk":"11450859140","pt":1717326123249,"mc":[{"id":"1.229554933","rc":[{"atb":[[15,5.16]],"id":52671545}],"con":true,"img":false}]}
{"op":"mcm","clk":"11450859159","pt":1717326123455,"mc":[{"id":"1.229554933","rc":[{"atb":[[1.24,42.08]],"id":52671544}],"con":true,"img":false}]}
{"op":"mcm","clk":"11450859169","pt":1717326123507,"mc":[{"id":"1.229554933","rc":[{"atb":[[1.15,67.33]],"id":52671544}],"con":true,"img":false}]}
{"op":"mcm","clk":"11450859218","pt":1717326124024,"mc":[{"id":"1.229554933","rc":[{"atl":[[80,0],[85,2]],"id":52671546}],"con":true,"img":false}]}
{"op":"mcm","clk":"11450859254","pt":1717326124342,"mc":[{"id":"1.229554933","rc":[{"atb":[[2.58,0],[2.78,90]],"id":52671546},{"atb":[[8,0],[6,0]],"id":52671545},{"atb":[[1.28,0],[1.38,0]],"id":52671544},{"atb":[[3.85,0],[3.35,0]],"id":52671555},{"atb":[[12,0],[8.8,0]],"id":52671554},{"atb":[[19,0],[14,0]],"id":52671556}],"con":true,"img":false}]}
{"op":"mcm","clk":"11450859493","pt":1717326126630,"mc":[{"id":"1.229554933","rc":[{"atl":[[530,0],[540,2]],"id":52671545}],"con":true,"img":false}]}
{"op":"mcm","clk":"11450859695","pt":1717326128753,"mc":[{"id":"1.229554933","rc":[{"atb":[[1.98,0],[2.34,74.63]],"id":52671545},{"atl":[[3.1,0],[2.78,44.51]],"id":52671544},{"atb":[[9.2,27],[10.5,10.53]],"id":52671554},{"atb":[[32,3.23],[27,0]],"id":52671556}],"con":true,"img":false}]}
{"op":"mcm","clk":"11450859724","pt":1717326129063,"mc":[{"id":"1.229554933","rc":[{"atl":[[85,0],[95,2]],"id":52671546},{"atl":[[540,0],[530,2]],"id":52671545},{"atl":[[320,0],[340,2]],"id":52671555},{"atl":[[730,0],[710,2]],"id":52671554}],"con":true,"img":false}]}
{"op":"mcm","clk":"11450859766","pt":1717326129431,"mc":[{"id":"1.229554933","rc":[{"atl":[[320,2]],"id":52671555},{"atl":[[700,2],[710,0]],"id":52671554}],"con":true,"img":false}]}
{"op":"mcm","clk":"11450859780","pt":1717326129530,"mc":[{"id":"1.229554933","rc":[{"atl":[[340,0]],"id":52671555}],"con":true,"img":false}]}
{"op":"mcm","clk":"11450859924","pt":1717326130930,"mc":[{"id":"1.229554933","rc":[{"atb":[[2.58,154.36],[2.78,148.72]],"id":52671546},{"atb":[[8,14.93],[6,48.78]],"id":52671545},{"atb":[[1.28,871.08],[1.38,275.08]],"id":52671544},{"atb":[[3.85,36.67],[3.35,103.78]],"id":52671555},{"atb":[[12,9.5],[8.8,31.27]],"id":52671554},{"atb":[[19,5.8],[14,18.76]],"id":52671556}],"con":true,"img":false}]}
{"op":"mcm","clk":"11450860277","pt":1717326134053,"mc":[{"id":"1.229554933","rc":[{"atl":[[85,2],[95,0]],"id":52671546},{"atl":[[530,0],[550,2]],"id":52671545},{"atl":[[310,2],[320,0]],"id":52671555},{"atl":[[700,0],[720,2]],"id":52671554}],"con":true,"img":false}]}
{"op":"mcm","clk":"11450860330","pt":1717326134521,"mc":[{"id":"1.229554933","rc":[{"atl":[[550,0],[560,2]],"id":52671545},{"atl":[[720,0],[730,2]],"id":52671554}],"con":true,"img":false}]}
{"op":"mcm","clk":"11450860418","pt":1717326135453,"mc":[{"id":"1.229554933","rc":[{"atb":[[9.2,27]],"id":52671545},{"atl":[[2.74,46]],"id":52671544},{"atb":[[13,19]],"id":52671554},{"atb":[[18.5,14]],"id":52671556}],"con":true,"img":false}]}
{"op":"mcm","clk":"11450860432","pt":1717326135555,"mc":[{"id":"1.229554933","rc":[{"atb":[[8.6,0]],"id":52671545},{"atl":[[2.8,0],[2.72,45],[2.78,0.25]],"id":52671544},{"atb":[[9.2,0]],"id":52671554},{"atb":[[13,0]],"id":52671556}],"con":true,"img":false}]}
{"op":"mcm","clk":"11450860823","pt":1717326139135,"mc":[{"id":"1.229554933","rc":[{"atl":[[85,0],[90,2]],"id":52671546},{"atl":[[310,0],[320,2]],"id":52671555}],"con":true,"img":false}]}
{"op":"mcm","clk":"11450860871","pt":1717326139654,"mc":[{"id":"1.229554933","rc":[{"atl":[[560,0],[550,2]],"id":52671545}],"con":true,"img":false}]}
{"op":"mcm","clk":"11450860962","pt":1717326140487,"mc":[{"id":"1.229554933","rc":[{"atb":[[2.58,0],[2.78,90]],"id":52671546},{"atb":[[8,0],[6,0]],"id":52671545},{"atb":[[1.28,0],[1.38,0]],"id":52671544},{"atb":[[3.85,0],[3.35,0]],"id":52671555},{"atb":[[12,0],[8.8,0]],"id":52671554},{"atb":[[19,0],[14,0]],"id":52671556}],"con":true,"img":false}]}
{"op":"mcm","clk":"11450861413","pt":1717326144288,"mc":[{"id":"1.229554933","rc":[{"atl":[[730,0],[740,2]],"id":52671554}],"con":true,"img":false}]}
{"op":"mcm","clk":"11450861489","pt":1717326144963,"mc":[{"id":"1.229554933","rc":[{"atl":[[2.78,0]],"id":52671544},{"atl":[[720,2],[740,0]],"id":52671554}],"con":true,"img":false}]}
{"op":"mcm","clk":"11450861497","pt":1717326145066,"mc":[{"id":"1.229554933","rc":[{"atl":[[2.7,0.25]],"id":52671544}],"con":true,"img":false}]}
{"op":"mcm","clk":"11450861504","pt":1717326145169,"mc":[{"id":"1.229554933","rc":[{"atb":[[2.7,58.82]],"id":52671545},{"atb":[[38,2.7]],"id":52671556}],"con":true,"img":false}]}
{"op":"mcm","clk":"11450861516","pt":1717326145272,"mc":[{"id":"1.229554933","rc":[{"atb":[[2.34,0]],"id":52671545},{"atb":[[32,0]],"id":52671556}],"con":true,"img":false}]}
{"op":"mcm","clk":"11450861529","pt":1717326145379,"mc":[{"id":"1.229554933","rc":[{"atb":[[2.82,57.43],[2.62,180.1]],"id":52671546},{"atb":[[8.2,14.51],[6.2,46.9]],"id":52671545},{"atb":[[1.26,938.09],[1.36,290.36]],"id":52671544},{"atb":[[3.8,37.33],[3.3,106.04]],"id":52671555},{"atb":[[11.5,9.95],[8.6,32.09]],"id":52671554},{"atb":[[19,5.8],[14,18.76]],"id":52671556}],"con":true,"img":false}]}
{"op":"mcm","clk":"11450861992","pt":1717326149285,"mc":[{"id":"1.229554933","rc":[{"atl":[[85,2],[90,0]],"id":52671546},{"atl":[[310,2],[320,0]],"id":52671555}],"con":true,"img":false}]}
{"op":"mcm","clk":"11450862725","pt":1717326156300,"mc":[{"id":"1.229554933","rc":[{"atb":[[2.82,0],[2.62,29.55]],"id":52671546},{"atb":[[8.2,0],[6.2,0]],"id":52671545},{"atb":[[1.26,0],[1.36,0]],"id":52671544},{"atb":[[3.8,0],[3.3,0]],"id":52671555},{"atb":[[11.5,0],[8.6,0]],"id":52671554},{"atb":[[19,0],[14,0]],"id":52671556}],"con":true,"img":false}]}
{"op":"mcm","clk":"11450863003","pt":1717326159619,"mc":[{"id":"1.229554933","rc":[{"atl":[[80,2],[85,0]],"id":52671546}],"con":true,"img":false}]}
{"op":"mcm","clk":"11450863076","pt":1717326160594,"mc":[{"id":"1.229554933","rc":[{"atb":[[3.2,45.45],[2.7,0]],"id":52671545},{"atb":[[4.5,17.21],[4.9,25.64]],"id":52671555},{"atl":[[280,2],[310,0]],"id":52671555},{"atb":[[10.5,0],[13.5,8]],"id":52671554}],"con":true,"img":false}]}
{"op":"mcm","clk":"11450863136","pt":1717326161221,"mc":[{"id":"1.229554933","rc":[{"atb":[[5.4,1.58]],"id":52671555}],"con":true,"img":false}]}
{"op":"mcm","clk":"11450863332","pt":1717326163087,"mc":[{"id":"1.229554933","rc":[{"atb":[[3.8,37.33],[3.3,106.04]],"id":52671555},{"atb":[[11.5,9.95],[8.6,32.09]],"id":52671554},{"atb":[[19,5.8],[14,18.76]],"id":52671556}],"con":true,"img":false}]}
{"op":"mcm","clk":"11450863343","pt":1717326163193,"mc":[{"id":"1.229554933","rc":[{"atb":[[2.82,57.43],[2.62,180.1]],"id":52671546},{"atb":[[8.2,14.51],[6.2,46.9]],"id":52671545},{"atb":[[1.26,938.09],[1.36,290.36]],"id":52671544}],"con":true,"img":false}]}
{"op":"mcm","clk":"11450863381","pt":1717326163609,"mc":[{"id":"1.229554933","rc":[{"atb":[[38,0],[42,2.44]],"id":52671556}],"con":true,"img":false}]}
{"op":"mcm","clk":"11450863482","pt":1717326164703,"mc":[{"id":"1.229554933","rc":[{"atl":[[280,0],[290,2]],"id":52671555},{"atl":[[720,0],[730,2]],"id":52671554}],"con":true,"img":false}]}
{"op":"mcm","clk":"11450863545","pt":1717326165591,"mc":[{"id":"1.229554933","rc":[{"atl":[[550,0],[560,2]],"id":52671545},{"atl":[[730,0],[740,2]],"id":52671554}],"con":true,"img":false}]}
{"op":"mcm","clk":"11450863552","pt":1717326165687,"mc":[{"id":"1.229554933","rc":[{"atl":[[2.72,91],[2.74,0]],"id":52671544},{"atb":[[3.45,0],[3.65,68]],"id":52671555}],"con":true,"img":false}]}
{"op":"mcm","clk":"11450863594","pt":1717326166206,"mc":[{"id":"1.229554933","rc":[{"atl":[[85,2]],"id":52671546},{"atl":[[340,2]],"id":52671555}],"con":true,"img":false}]}
{"op":"mcm","clk":"11450863602","pt":1717326166311,"mc":[{"id":"1.229554933","rc":[{"atl":[[80,0]],"id":52671546},{"atl":[[290,0]],"id":52671555}],"con":true,"img":false}]}
{"op":"mcm","clk":"11450863653","pt":1717326166884,"mc":[{"id":"1.229554933","rc":[{"atl":[[330,2]],"id":52671555}],"con":true,"img":false}]}
{"op":"mcm","clk":"11450863664","pt":1717326166988,"mc":[{"id":"1.229554933","rc":[{"atl":[[340,0]],"id":52671555}],"con":true,"img":false}]}
{"op":"mcm","clk":"11450863752","pt":1717326167716,"mc":[{"id":"1.229554933","rc":[{"atl":[[760,2]],"id":52671554}],"con":true,"img":false}]}
{"op":"mcm","clk":"11450863759","pt":1717326167819,"mc":[{"id":"1.229554933","rc":[{"atl":[[740,0]],"id":52671554}],"con":true,"img":false}]}
{"op":"mcm","clk":"11450863847","pt":1717326168812,"mc":[{"id":"1.229554933","rc":[{"atb":[[42,0],[44,4.76]],"id":52671556}],"con":true,"img":false}]}
{"op":"mcm","clk":"11450863902","pt":1717326169240,"mc":[{"id":"1.229554933","marketDefinition":{"bspMarket":false,"turnInPlayEnabled":false,"persistenceEnabled":false,"marketBaseRate":7.0,"eventId":"33318908","eventTypeId":"4339","numberOfWinners":1,"bettingType":"ODDS","marketType":"QUINELLA","marketTime":"2024-06-02T11:02:00.000Z","suspendTime":"2024-06-02T11:02:00.000Z","bspReconciled":false,"complete":true,"inPlay":false,"crossMatching":true,"runnersVoidable":false,"numberOfActiveRunners":6,"betDelay":0,"status":"SUSPENDED","runners":[{"status":"ACTIVE","sortPriority":1,"id":52671544,"name":"1 - 4 / 4 - 1"},{"status":"ACTIVE","sortPriority":2,"id":52671545,"name":"1 - 6 / 6 - 1"},{"status":"ACTIVE","sortPriority":3,"id":52671546,"name":"1 - 8 / 8 - 1"},{"status":"ACTIVE","sortPriority":4,"id":52671554,"name":"4 - 6 / 6 - 4"},{"status":"ACTIVE","sortPriority":5,"id":52671555,"name":"4 - 8 / 8 - 4"},{"status":"ACTIVE","sortPriority":6,"id":52671556,"name":"6 - 8 / 8 - 6"}],"regulators":["MR_INT"],"venue":"Murray Bridge","countryCode":"AU","discountAllowed":true,"timezone":"Australia/Adelaide","openDate":"2024-06-02T08:21:00.000Z","version":5963171712,"name":"Quinella","eventName":"Murray Bridge (AUS) 2nd Jun"},"rc":[],"con":true,"img":false}]}
{"op":"mcm","clk":"11450863902","pt":1717326169240,"mc":[{"id":"1.229554933","rc":[{"atb":[[2.82,0],[2.54,0],[1.03,0],[3,0],[3.25,0],[2.98,0],[2.84,0],[2.62,0],[3.45,0],[2.9,0],[2.74,0],[1.02,0],[3.4,0],[2.78,0]],"id":52671546},{"atl":[[85,0],[1000,0]],"id":52671546},{"atb":[[9,0],[1.01,0],[9.2,0],[8.2,0],[12.5,0],[14.5,0],[15,0],[16,0],[17,0],[19.5,0],[3.2,0],[6.2,0],[1.02,0]],"id":52671545},{"atl":[[560,0],[1000,0]],"id":52671545},{"atb":[[1.01,0],[1.43,0],[1.37,0],[1.26,0],[1.39,0],[1.36,0],[1.27,0],[1.16,0],[1.15,0],[1.02,0],[1.32,0],[1.3,0],[1.49,0],[1.42,0],[1.29,0],[1.24,0]],"id":52671544},{"atl":[[2.72,0],[990,0],[2.7,0]],"id":52671544},{"atb":[[4.8,0],[4.3,0],[5.8,0],[5.3,0],[3.8,0],[3,0],[4.9,0],[3.5,0],[3.3,0],[5.4,0],[4.5,0],[1.02,0],[3.65,0]],"id":52671555},{"atl":[[330,0],[990,0],[1000,0]],"id":52671555},{"atb":[[34,0],[1.01,0],[11,0],[11.5,0],[13,0],[13.5,0],[16,0],[8.6,0],[22,0],[1.02,0],[26,0],[27,0],[28,0]],"id":52671554},{"atl":[[760,0],[990,0],[1000,0]],"id":52671554},{"atb":[[18.5,0],[18,0],[19,0],[1.01,0],[44,0],[46,0],[1.02,0],[50,0],[26,0],[14,0],[60,0]],"id":52671556},{"atl":[[990,0],[1000,0]],"id":52671556}],"con":true,"img":false}]}
{"op":"mcm","clk":"11450868602","pt":1717326219500,"mc":[{"id":"1.229554933","rc":[{"trd":[[3.25,0],[3.5,0]],"ltp":3.25,"tv":0.0,"id":52671546},{"trd":[[19.5,0],[24,0]],"ltp":19.5,"tv":0.0,"id":52671545},{"trd":[[5.8,0]],"ltp":5.8,"tv":0.0,"id":52671555},{"trd":[[34,0],[44,0]],"ltp":34.0,"tv":0.0,"id":52671554},{"trd":[[85,0],[60,0],[120,0]],"ltp":85.0,"tv":0.0,"id":52671556}],"con":true,"img":false}]}
{"op":"mcm","clk":"11450868707","pt":1717326220728,"mc":[{"id":"1.229554933","marketDefinition":{"bspMarket":false,"turnInPlayEnabled":false,"persistenceEnabled":false,"marketBaseRate":7.0,"eventId":"33318908","eventTypeId":"4339","numberOfWinners":1,"bettingType":"ODDS","marketType":"QUINELLA","marketTime":"2024-06-02T11:02:00.000Z","suspendTime":"2024-06-02T11:02:00.000Z","bspReconciled":false,"complete":true,"inPlay":false,"crossMatching":false,"runnersVoidable":false,"numberOfActiveRunners":0,"betDelay":0,"status":"CLOSED","settledTime":"2024-06-02T11:03:38.000Z","runners":[{"status":"LOSER","sortPriority":1,"id":52671544,"name":"1 - 4 / 4 - 1"},{"status":"LOSER","sortPriority":2,"id":52671545,"name":"1 - 6 / 6 - 1"},{"status":"WINNER","sortPriority":3,"id":52671546,"name":"1 - 8 / 8 - 1"},{"status":"LOSER","sortPriority":4,"id":52671554,"name":"4 - 6 / 6 - 4"},{"status":"LOSER","sortPriority":5,"id":52671555,"name":"4 - 8 / 8 - 4"},{"status":"LOSER","sortPriority":6,"id":52671556,"name":"6 - 8 / 8 - 6"}],"regulators":["MR_INT"],"venue":"Murray Bridge","countryCode":"AU","discountAllowed":true,"timezone":"Australia/Adelaide","openDate":"2024-06-02T08:21:00.000Z","version":5963173512,"name":"Quinella","eventName":"Murray Bridge (AUS) 2nd Jun"},"rc":[],"con":true,"img":false}]}
