{"op":"mcm","clk":"11448127646","pt":1717286034980,"mc":[{"id":"1.229554900","marketDefinition":{"bspMarket":true,"turnInPlayEnabled":false,"persistenceEnabled":false,"marketBaseRate":7.0,"eventId":"33318908","eventTypeId":"4339","numberOfWinners":1,"bettingType":"ODDS","marketType":"WIN","marketTime":"2024-06-02T08:59:00.000Z","suspendTime":"2024-06-02T08:59:00.000Z","bspReconciled":false,"complete":true,"inPlay":false,"crossMatching":true,"runnersVoidable":false,"numberOfActiveRunners":6,"betDelay":0,"status":"OPEN","runners":[{"status":"ACTIVE","sortPriority":1,"id":63161681,"name":"1. Razzle Berries"},{"status":"ACTIVE","sortPriority":2,"id":63027102,"name":"2. Christoff"},{"status":"ACTIVE","sortPriority":3,"id":47208569,"name":"4. Enticement"},{"status":"ACTIVE","sortPriority":4,"id":67532289,"name":"5. Super Breeze"},{"status":"ACTIVE","sortPriority":5,"id":49183855,"name":"7. Bruces Angel"},{"status":"ACTIVE","sortPriority":6,"id":70003368,"name":"8. Dark Queen"}],"regulators":["MR_INT"],"venue":"Murray Bridge","countryCode":"AU","discountAllowed":true,"timezone":"Australia/Adelaide","openDate":"2024-06-02T08:21:00.000Z","version":5962317631,"name":"R3 395m Rest","eventName":"Murray Bridge (AUS) 2nd Jun"},"rc":[],"con":true,"img":false}]}
{"op":"mcm","clk":"11448260604","pt":1717287908538,"mc":[{"id":"1.229554900","rc":[{"atb":[[3.25,92.91],[3.5,83.62],[3.75,38]],"id":70003368},{"atl":[[17.5,8.44],[25,8.71]],"id":70003368},{"spn":10.62,"spf":"NaN","id":70003368},{"atb":[[3.4,43.55],[3.15,97.23],[2.96,106.66]],"id":47208569},{"atl":[[19,11.61],[14,10.71]],"id":47208569},{"spn":8.7,"spf":"NaN","id":47208569},{"atb":[[17.5,12.67],[20,11],[25,4.35]],"id":49183855},{"atl":[[350,0.39],[450,0.46]],"id":49183855},{"spn":187.5,"spf":"NaN","id":49183855},{"atb":[[3.1,49.77],[2.84,113.61],[2.94,107.76]],"id":63161681},{"atl":[[16,13.93],[11,13.93]],"id":63161681},{"spn":7.05,"spf":"NaN","id":63161681},{"atb":[[19.5,11.3],[24,9.08],[29,3.73]],"id":63027102},{"atl":[[400,0.35],[500,0.41]],"id":63027102},{"spn":214.5,"spf":"NaN","id":63027102},{"atb":[[1.83,251.88],[1.88,237.56],[1.93,112.39]],"id":67532289},{"atl":[[5.6,30.29],[7.2,33.71]],"id":67532289},{"spn":3.76,"spf":"NaN","id":67532289}],"con":true,"img":false}]}
{"op":"mcm","clk":"11448264303","pt":1717287962255,"mc":[{"id":"1.229554900","rc":[{"atb":[[3.25,0],[3.5,0],[3.75,0]],"id":70003368},{"atl":[[17.5,0],[25,0]],"id":70003368},{"atb":[[3.4,0],[3.15,0],[2.96,0]],"id":47208569},{"atl":[[19,0],[14,0]],"id":47208569},{"atb":[[17.5,0],[20,0],[25,0]],"id":49183855},{"atl":[[350,0],[450,0]],"id":49183855},{"atb":[[3.1,0],[2.84,0],[2.94,0]],"id":63161681},{"atl":[[16,0],[11,0]],"id":63161681},{"atb":[[19.5,0],[24,0],[29,0]],"id":63027102},{"atl":[[400,0],[500,0]],"id":63027102},{"atb":[[1.83,0],[1.88,0],[1.93,0]],"id":67532289},{"atl":[[5.6,0],[7.2,0]],"id":67532289}],"con":true,"img":false}]}
{"op":"mcm","clk":"11448265018","pt":1717287972318,"mc":[{"id":"1.229554900","rc":[{"atb":[[3.25,92.91],[3.5,83.62],[3.75,38]],"id":70003368},{"atl":[[17.5,8.44],[25,8.71]],"id":70003368},{"atb":[[3.4,43.55],[3.15,97.23],[2.96,106.66]],"id":47208569},{"atl":[[19,11.61],[14,10.71]],"id":47208569},{"atb":[[17.5,12.67],[20,11],[25,4.35]],"id":49183855},{"atl":[[350,0.39],[450,0.46]],"id":49183855},{"atb":[[3.1,49.77],[2.84,113.61],[2.94,107.76]],"id":63161681},{"atl":[[16,13.93],[11,13.93]],"id":63161681},{"atb":[[19.5,11.3],[24,9.08],[29,3.73]],"id":63027102},{"atl":[[400,0.35],[500,0.41]],"id":63027102},{"atb":[[1.83,251.88],[1.88,237.56],[1.93,112.39]],"id":67532289},{"atl":[[5.6,30.29],[7.2,33.71]],"id":67532289}],"con":true,"img":false}]}
{"op":"mcm","clk":"11448272355","pt":1717288089584,"mc":[{"id":"1.229554900","rc":[{"atb":[[17.5,0],[20,0],[25,0]],"id":49183855},{"atl":[[350,0],[450,0]],"id":49183855},{"spn":"NaN","spf":"NaN","id":49183855},{"atb":[[19.5,0],[24,0],[29,0]],"id":63027102},{"atl":[[400,0],[500,0]],"id":63027102},{"spn":"NaN","spf":"NaN","id":63027102},{"atb":[[1.83,0],[1.88,0],[1.93,0]],"id":67532289},{"atl":[[5.6,0],[7.2,0]],"id":67532289},{"spn":"NaN","spf":"NaN","id":67532289}],"con":true,"img":false}]}
{"op":"mcm","clk":"11448273012","pt":1717288099886,"mc":[{"id":"1.229554900","rc":[{"atb":[[17.5,12.67],[20,11],[25,4.35]],"id":49183855},{"atl":[[350,0.39],[450,0.46]],"id":49183855},{"atb":[[19.5,11.3],[24,9.08],[29,3.73]],"id":63027102},{"atl":[[400,0.35],[500,0.41]],"id":63027102},{"atb":[[1.83,251.88],[1.88,237.56],[1.93,112.39]],"id":67532289},{"atl":[[5.6,30.29],[7.2,33.71]],"id":67532289}],"con":true,"img":false}]}
{"op":"mcm","clk":"11448277237","pt":1717288128428,"mc":[{"id":"1.229554900","marketDefinition":{"bspMarket":true,"turnInPlayEnabled":false,"persistenceEnabled":false,"marketBaseRate":7.0,"eventId":"33318908","eventTypeId":"4339","numberOfWinners":1,"bettingType":"ODDS","marketType":"WIN","marketTime":"2024-06-02T08:59:00.000Z","suspendTime":"2024-06-02T08:59:00.000Z","bspReconciled":false,"complete":true,"inPlay":false,"crossMatching":true,"runnersVoidable":false,"numberOfActiveRunners":6,"betDelay":0,"status":"OPEN","runners":[{"status":"ACTIVE","sortPriority":1,"id":63161681,"name":"1. Razzle Berries"},{"status":"ACTIVE","sortPriority":2,"id":63027102,"name":"2. Christoff"},{"status":"ACTIVE","sortPriority":3,"id":47208569,"name":"4. Enticement"},{"status":"ACTIVE","sortPriority":4,"id":67532289,"name":"5. Super Breeze"},{"status":"ACTIVE","sortPriority":5,"id":49183855,"name":"7. Bruces Angel"},{"status":"ACTIVE","sortPriority":6,"id":70003368,"name":"8. Dark Queen"}],"regulators":["MR_INT"],"venue":"Murray Bridge","countryCode":"AU","discountAllowed":true,"timezone":"Australia/Adelaide","openDate":"2024-06-02T08:21:00.000Z","version":5962317631,"name":"R3 395m Rest","eventName":"Murray Bridge (AUS) 2nd Jun"},"rc":[{"atb":[[3.25,92.91],[3.5,83.62],[3.75,38]],"id":70003368},{"atl":[[17.5,8.44],[25,8.71]],"id":70003368},{"spn":10.62,"spf":"NaN","id":70003368},{"atb":[[3.4,43.55],[3.15,97.23],[2.96,106.66]],"id":47208569},{"atl":[[19,11.61],[14,10.71]],"id":47208569},{"spn":8.7,"spf":"NaN","id":47208569},{"atb":[[17.5,12.67],[20,11],[25,4.35]],"id":49183855},{"atl":[[350,0.39],[450,0.46]],"id":49183855},{"spn":"NaN","spf":"NaN","id":49183855},{"atb":[[3.1,49.77],[2.84,113.61],[2.94,107.76]],"id":63161681},{"atl":[[16,13.93],[11,13.93]],"id":63161681},{"spn":7.05,"spf":"NaN","id":63161681},{"atb":[[19.5,11.3],[24,9.08],[29,3.73]],"id":63027102},{"atl":[[400,0.35],[500,0.41]],"id":63027102},{"spn":"NaN","spf":"NaN","id":63027102},{"atb":[[1.83,251.88],[1.88,237.56],[1.93,112.39]],"id":67532289},{"atl":[[5.6,30.29],[7.2,33.71]],"id":67532289},{"spn":"NaN","spf":"NaN","id":67532289}],"con":true,"img":true}]}
{"op":"mcm","clk":"11448284287","pt":1717288159833,"mc":[{"id":"1.229554900","rc":[{"atb":[[3.25,0],[3.5,0],[3.75,0]],"id":70003368},{"atl":[[17.5,0],[25,0]],"id":70003368},{"spn":"NaN","spf":"NaN","id":70003368},{"spn":187.5,"spf":"NaN","id":49183855},{"atb":[[19.5,0],[24,0],[29,0]],"id":63027102},{"atl":[[400,0],[500,0]],"id":63027102},{"spn":3.76,"spf":"NaN","id":67532289}],"con":true,"img":false}]}
{"op":"mcm","clk":"11448285284","pt":1717288174030,"mc":[{"id":"1.229554900","rc":[{"atb":[[3.4,87.1],[3.15,97.23],[3.65,39.44]],"id":70003368},{"atl":[[16.5,8.99],[23,9.5]],"id":70003368},{"atb":[[19.5,11.3],[24,9.08],[29,3.73]],"id":63027102},{"atl":[[400,0.35],[500,0.41]],"id":63027102}],"con":true,"img":false}]}
{"op":"mcm","clk":"11448292458","pt":1717288273850,"mc":[{"id":"1.229554900","rc":[{"atb":[[3.4,0],[3.15,0],[3.65,0]],"id":70003368},{"atl":[[16.5,0],[23,0]],"id":70003368},{"atb":[[3.4,0],[3.15,0],[2.96,0]],"id":47208569},{"atl":[[19,0],[14,0]],"id":47208569},{"spn":"NaN","spf":"NaN","id":47208569},{"atb":[[17.5,0],[20,0],[25,0]],"id":49183855},{"atl":[[350,0],[450,0]],"id":49183855},{"spn":"NaN","spf":"NaN","id":49183855},{"atb":[[3.1,0],[2.84,0],[2.94,0]],"id":63161681},{"atl":[[16,0],[11,0]],"id":63161681},{"spn":"NaN","spf":"NaN","id":63161681},{"atb":[[19.5,0],[24,0],[29,0]],"id":63027102},{"atl":[[400,0],[500,0]],"id":63027102},{"atb":[[1.83,0],[1.88,0],[1.93,0]],"id":67532289},{"atl":[[5.6,0],[7.2,0]],"id":67532289},{"spn":"NaN","spf":"NaN","id":67532289}],"con":true,"img":false}]}
{"op":"mcm","clk":"11448293804","pt":1717288291623,"mc":[{"id":"1.229554900","rc":[{"atb":[[3.25,92.91],[3.5,83.62],[3.75,38]],"id":70003368},{"atl":[[17.5,8.44],[25,8.71]],"id":70003368},{"atb":[[3.6,40.2],[3.1,99.55],[3.35,88.96]],"id":47208569},{"atl":[[18.5,11.94],[13.5,11.14]],"id":47208569},{"atb":[[17.5,12.67],[20,11],[25,4.35]],"id":49183855},{"atl":[[350,0.39],[450,0.46]],"id":49183855},{"atb":[[2.88,111.2],[2.98,52.79],[2.78,117.44]],"id":63161681},{"atl":[[10.5,14.66],[15.5,14.41]],"id":63161681},{"atb":[[19.5,11.3],[24,9.08],[29,3.73]],"id":63027102},{"atl":[[400,0.35],[500,0.41]],"id":63027102},{"atb":[[1.91,229.73],[1.96,108.88],[1.86,243.09]],"id":67532289},{"atl":[[7.8,30.74],[5.9,28.44]],"id":67532289}],"con":true,"img":false}]}
{"op":"mcm","clk":"11448298261","pt":1717288351278,"mc":[{"id":"1.229554900","rc":[{"atb":[[3.25,0],[3.5,0],[3.75,0]],"id":70003368},{"atl":[[17.5,0],[25,0]],"id":70003368},{"atb":[[3.6,0],[3.1,0],[3.35,0]],"id":47208569},{"atl":[[18.5,0],[13.5,0]],"id":47208569},{"atb":[[17.5,0],[20,0],[25,0]],"id":49183855},{"atl":[[350,0],[450,0]],"id":49183855},{"atb":[[2.88,0],[2.98,0],[2.78,0]],"id":63161681},{"atl":[[10.5,0],[15.5,0]],"id":63161681},{"atb":[[19.5,0],[24,0],[29,0]],"id":63027102},{"atl":[[400,0],[500,0]],"id":63027102},{"atb":[[1.91,0],[1.96,0],[1.86,0]],"id":67532289},{"atl":[[7.8,0],[5.9,0]],"id":67532289}],"con":true,"img":false}]}
{"op":"mcm","clk":"11448300795","pt":1717288383947,"mc":[{"id":"1.229554900","rc":[{"atb":[[3.25,92.91],[3.5,83.62],[3.75,38]],"id":70003368},{"atl":[[17.5,8.44],[25,8.71]],"id":70003368},{"atb":[[3.6,40.2],[3.1,99.55],[3.35,88.96]],"id":47208569},{"atl":[[18.5,11.94],[13.5,11.14]],"id":47208569},{"atb":[[17.5,12.67],[20,11],[25,4.35]],"id":49183855},{"atl":[[350,0.39],[450,0.46]],"id":49183855},{"atb":[[2.88,111.2],[2.98,52.79],[2.78,117.44]],"id":63161681},{"atl":[[10.5,14.66],[15.5,14.41]],"id":63161681},{"atb":[[32,3.37],[21,10.45],[26,8.36]],"id":63027102},{"atl":[[520,0.4],[420,0.33]],"id":63027102},{"atb":[[2.02,102.47],[1.91,229.73],[1.96,217.77]],"id":67532289},{"atl":[[6.4,25.8],[8.4,28.25]],"id":67532289}],"con":true,"img":false}]}
{"op":"mcm","clk":"11448305316","pt":1717288449206,"mc":[{"id":"1.229554900","rc":[{"spn":10.62,"spf":"NaN","id":70003368},{"atb":[[3.6,0],[3.1,0],[3.35,0]],"id":47208569},{"atl":[[18.5,0],[13.5,0]],"id":47208569},{"atb":[[17.5,0],[20,0],[25,0]],"id":49183855},{"atl":[[350,0],[450,0]],"id":49183855},{"atb":[[2.88,0],[2.98,0],[2.78,0]],"id":63161681},{"atl":[[10.5,0],[15.5,0]],"id":63161681},{"atb":[[32,0],[21,0],[26,0]],"id":63027102},{"atl":[[520,0],[420,0]],"id":63027102},{"atb":[[2.02,0],[1.91,0],[1.96,0]],"id":67532289},{"atl":[[6.4,0],[8.4,0]],"id":67532289}],"con":true,"img":false}]}
{"op":"mcm","clk":"11448307458","pt":1717288481177,"mc":[{"id":"1.229554900","rc":[{"atb":[[3.4,87.1],[3.15,97.23],[3.65,39.44]],"id":47208569},{"atl":[[16.5,8.99],[23,9.5]],"id":47208569},{"atb":[[19.5,11.3],[24,9.08],[29,3.73]],"id":49183855},{"atl":[[400,0.35],[500,0.41]],"id":49183855},{"atb":[[2.88,111.2],[2.98,52.79],[2.78,117.44]],"id":63161681},{"atl":[[10.5,14.66],[15.5,14.41]],"id":63161681},{"atb":[[38,2.82],[24,9.08],[29,7.46]],"id":63027102},{"atl":[[550,0.38],[450,0.3]],"id":63027102},{"atb":[[2.02,102.47],[1.91,229.73],[1.96,217.77]],"id":67532289},{"atl":[[6.4,25.8],[8.4,28.25]],"id":67532289}],"con":true,"img":false}]}
{"op":"mcm","clk":"11448310805","pt":1717288529482,"mc":[{"id":"1.229554900","rc":[{"spn":10.07,"spf":"NaN","id":47208569},{"spn":214.5,"spf":"NaN","id":49183855},{"spn":6.74,"spf":"NaN","id":63161681},{"atb":[[38,0],[24,0],[29,0]],"id":63027102},{"atl":[[550,0],[450,0]],"id":63027102},{"spn":4.21,"spf":"NaN","id":67532289}],"con":true,"img":false}]}
{"op":"mcm","clk":"11448312152","pt":1717288548667,"mc":[{"id":"1.229554900","rc":[{"atb":[[32,3.37],[21,10.45],[26,8.36]],"id":63027102},{"atl":[[520,0.4],[420,0.33]],"id":63027102}],"con":true,"img":false}]}
{"op":"mcm","clk":"11448321955","pt":1717288687519,"mc":[{"id":"1.229554900","rc":[{"atb":[[32,0],[21,0],[26,0]],"id":63027102},{"atl":[[520,0],[420,0]],"id":63027102},{"atb":[[2.02,0],[1.91,0],[1.96,0]],"id":67532289},{"atl":[[6.4,0],[8.4,0]],"id":67532289},{"spn":"NaN","spf":"NaN","id":67532289}],"con":true,"img":false}]}
{"op":"mcm","clk":"11448323044","pt":1717288701244,"mc":[{"id":"1.229554900","rc":[{"atb":[[38,2.82],[24,9.08],[29,7.46]],"id":63027102},{"atl":[[550,0.38],[450,0.3]],"id":63027102},{"atb":[[1.99,211.17],[1.94,222.4],[2.08,96.78]],"id":67532289},{"atl":[[8.6,27.5],[6.6,24.88]],"id":67532289}],"con":true,"img":false}]}
{"op":"mcm","clk":"11448325043","pt":1717288727655,"mc":[{"id":"1.229554900","rc":[{"atb":[[38,0],[24,0],[29,0]],"id":63027102},{"atl":[[550,0],[450,0]],"id":63027102}],"con":true,"img":false}]}
{"op":"mcm","clk":"11448326201","pt":1717288744502,"mc":[{"id":"1.229554900","rc":[{"atb":[[32,3.37],[21,10.45],[26,8.36]],"id":63027102},{"atl":[[520,0.4],[420,0.33]],"id":63027102}],"con":true,"img":false}]}
{"op":"mcm","clk":"11448629966","pt":1717293528419,"mc":[{"id":"1.229554900","marketDefinition":{"bspMarket":true,"turnInPlayEnabled":false,"persistenceEnabled":false,"marketBaseRate":7.0,"eventId":"33318908","eventTypeId":"4339","numberOfWinners":1,"bettingType":"ODDS","marketType":"WIN","marketTime":"2024-06-02T08:59:00.000Z","suspendTime":"2024-06-02T08:59:00.000Z","bspReconciled":false,"complete":true,"inPlay":false,"crossMatching":true,"runnersVoidable":false,"numberOfActiveRunners":6,"betDelay":0,"status":"OPEN","runners":[{"status":"ACTIVE","sortPriority":1,"id":63161681,"name":"1. Razzle Berries"},{"status":"ACTIVE","sortPriority":2,"id":63027102,"name":"2. Christoff"},{"status":"ACTIVE","sortPriority":3,"id":47208569,"name":"4. Enticement"},{"status":"ACTIVE","sortPriority":4,"id":67532289,"name":"5. Super Breeze"},{"status":"ACTIVE","sortPriority":5,"id":49183855,"name":"7. Bruces Angel"},{"status":"ACTIVE","sortPriority":6,"id":70003368,"name":"8. Dark Queen"}],"regulators":["MR_INT"],"venue":"Murray Bridge","countryCode":"AU","discountAllowed":true,"timezone":"Australia/Adelaide","openDate":"2024-06-02T08:21:00.000Z","version":5962317631,"name":"R3 395m Rest","eventName":"Murray Bridge (AUS) 2nd Jun"},"rc":[{"atb":[[3.25,92.91],[3.5,83.62],[3.75,38]],"id":70003368},{"atl":[[17.5,8.44],[25,8.71]],"id":70003368},{"spn":10.62,"spf":"NaN","id":70003368},{"atb":[[3.4,87.1],[3.15,97.23],[3.65,39.44]],"id":47208569},{"atl":[[16.5,8.99],[23,9.5]],"id":47208569},{"spn":10.07,"spf":"NaN","id":47208569},{"atb":[[19.5,11.3],[24,9.08],[29,3.73]],"id":49183855},{"atl":[[400,0.35],[500,0.41]],"id":49183855},{"spn":214.5,"spf":"NaN","id":49183855},{"atb":[[2.88,111.2],[2.98,52.79],[2.78,117.44]],"id":63161681},{"atl":[[10.5,14.66],[15.5,14.41]],"id":63161681},{"spn":6.74,"spf":"NaN","id":63161681},{"atb":[[32,3.37],[21,10.45],[26,8.36]],"id":63027102},{"atl":[[520,0.4],[420,0.33]],"id":63027102},{"spn":226.0,"spf":"NaN","id":63027102},{"atb":[[1.99,211.17],[1.94,222.4],[2.08,96.78]],"id":67532289},{"atl":[[8.6,27.5],[6.6,24.88]],"id":67532289},{"spn":4.34,"spf":"NaN","id":67532289}],"con":true,"img":true}]}
{"op":"mcm","clk":"11449031908","pt":1717302242803,"mc":[{"id":"1.229554900","rc":[{"spl":[[1.01,10.46]],"id":63161681},{"spn":2.98,"spf":1.0,"id":63161681},{"spn":226.0,"spf":"NaN","id":63027102},{"spn":4.34,"spf":"NaN","id":67532289}],"con":true,"img":false}]}
{"op":"mcm","clk":"11449367030","pt":1717308032356,"mc":[{"id":"1.229554900","rc":[{"atb":[[3.25,0],[3.5,0],[3.75,0]],"id":70003368},{"atl":[[17.5,0],[25,0]],"id":70003368},{"spn":"NaN","spf":"NaN","id":70003368},{"atb":[[3.4,0],[3.15,0],[3.65,0]],"id":47208569},{"atl":[[16.5,0],[23,0]],"id":47208569},{"spn":"NaN","spf":"NaN","id":47208569},{"atb":[[19.5,0],[24,0],[29,0]],"id":49183855},{"atl":[[400,0],[500,0]],"id":49183855},{"spn":"NaN","spf":"NaN","id":49183855},{"atb":[[2.88,0],[2.98,0],[2.78,0]],"id":63161681},{"atl":[[10.5,0],[15.5,0]],"id":63161681},{"spn":1.0,"spf":1.0,"id":63161681},{"atb":[[32,0],[21,0],[26,0]],"id":63027102},{"atl":[[520,0],[420,0]],"id":63027102},{"spn":"NaN","spf":"NaN","id":63027102},{"atb":[[1.99,0],[1.94,0],[2.08,0]],"id":67532289},{"atl":[[8.6,0],[6.6,0]],"id":67532289},{"spn":"NaN","spf":"NaN","id":67532289}],"con":true,"img":false}]}
{"op":"mcm","clk":"11449367310","pt":1717308038566,"mc":[{"id":"1.229554900","rc":[{"atb":[[3.25,92.91],[3.5,83.62],[3.75,38]],"id":70003368},{"atl":[[17.5,8.44],[25,8.71]],"id":70003368},{"atb":[[3.4,87.1],[3.15,97.23],[3.65,39.44]],"id":47208569},{"atl":[[16.5,8.99],[23,9.5]],"id":47208569},{"atb":[[19.5,11.3],[24,9.08],[29,3.73]],"id":49183855},{"atl":[[400,0.35],[500,0.41]],"id":49183855},{"atb":[[2.88,111.2],[2.98,52.79],[2.78,117.44]],"id":63161681},{"atl":[[10.5,14.66],[15.5,14.41]],"id":63161681},{"atb":[[32,3.37],[21,10.45],[26,8.36]],"id":63027102},{"atl":[[520,0.4],[420,0.33]],"id":63027102},{"atb":[[1.99,211.17],[1.94,222.4],[2.08,96.78]],"id":67532289},{"atl":[[8.6,27.5],[6.6,24.88]],"id":67532289}],"con":true,"img":false}]}
{"op":"mcm","clk":"11449437342","pt":1717309126625,"mc":[{"id":"1.229554900","rc":[{"atb":[[3.25,0],[3.5,0],[3.75,0]],"id":70003368},{"atl":[[17.5,0],[25,0]],"id":70003368},{"atb":[[3.4,0],[3.15,0],[3.65,0]],"id":47208569},{"atl":[[16.5,0],[23,0]],"id":47208569},{"atb":[[19.5,0],[24,0],[29,0]],"id":49183855},{"atl":[[400,0],[500,0]],"id":49183855},{"atb":[[2.88,0],[2.98,0],[2.78,0]],"id":63161681},{"atl":[[10.5,0],[15.5,0]],"id":63161681},{"atb":[[32,0],[21,0],[26,0]],"id":63027102},{"atl":[[520,0],[420,0]],"id":63027102},{"atb":[[1.99,0],[1.94,0],[2.08,0]],"id":67532289},{"atl":[[8.6,0],[6.6,0]],"id":67532289}],"con":true,"img":false}]}
{"op":"mcm","clk":"11449438877","pt":1717309151673,"mc":[{"id":"1.229554900","rc":[{"atb":[[3.25,92.91],[3.5,83.62],[3.75,38]],"id":70003368},{"atl":[[17.5,8.44],[25,8.71]],"id":70003368},{"atb":[[3.4,87.1],[3.15,97.23],[3.65,39.44]],"id":47208569},{"atl":[[16.5,8.99],[23,9.5]],"id":47208569},{"atb":[[19.5,11.3],[24,9.08],[29,3.73]],"id":49183855},{"atl":[[400,0.35],[500,0.41]],"id":49183855},{"atb":[[2.88,111.2],[2.98,52.79],[2.78,117.44]],"id":63161681},{"atl":[[10.5,14.66],[15.5,14.41]],"id":63161681},{"atb":[[32,3.37],[21,10.45],[26,8.36]],"id":63027102},{"atl":[[520,0.4],[420,0.33]],"id":63027102},{"atb":[[1.99,211.17],[1.94,222.4],[2.08,96.78]],"id":67532289},{"atl":[[8.6,27.5],[6.6,24.88]],"id":67532289}],"con":true,"img":false}]}
{"op":"mcm","clk":"11449442383","pt":1717309206590,"mc":[{"id":"1.229554900","rc":[{"atb":[[3.25,0],[3.5,0],[3.75,0]],"id":70003368},{"atl":[[17.5,0],[25,0]],"id":70003368},{"atb":[[3.4,0],[3.15,0],[3.65,0]],"id":47208569},{"atl":[[16.5,0],[23,0]],"id":47208569},{"atb":[[19.5,0],[24,0],[29,0]],"id":49183855},{"atl":[[400,0],[500,0]],"id":49183855},{"spn":2.98,"spf":1.0,"id":63161681},{"atb":[[32,0],[21,0],[26,0]],"id":63027102},{"atl":[[520,0],[420,0]],"id":63027102},{"atb":[[1.99,0],[1.94,0],[2.08,0]],"id":67532289},{"atl":[[8.6,0],[6.6,0]],"id":67532289}],"con":true,"img":false}]}
{"op":"mcm","clk":"11449442982","pt":1717309215121,"mc":[{"id":"1.229554900","rc":[{"atb":[[2.88,0],[2.98,0],[2.78,0]],"id":63161681},{"atl":[[10.5,0],[15.5,0]],"id":63161681}],"con":true,"img":false}]}
{"op":"mcm","clk":"11449447235","pt":1717309280771,"mc":[{"id":"1.229554900","marketDefinition":{"bspMarket":true,"turnInPlayEnabled":false,"persistenceEnabled":false,"marketBaseRate":7.0,"eventId":"33318908","eventTypeId":"4339","numberOfWinners":1,"bettingType":"ODDS","marketType":"WIN","marketTime":"2024-06-02T08:59:00.000Z","suspendTime":"2024-06-02T08:59:00.000Z","bspReconciled":false,"complete":true,"inPlay":false,"crossMatching":true,"runnersVoidable":false,"numberOfActiveRunners":6,"betDelay":0,"status":"SUSPENDED","runners":[{"status":"ACTIVE","sortPriority":1,"id":63161681,"name":"1. Razzle Berries"},{"status":"ACTIVE","sortPriority":2,"id":63027102,"name":"2. Christoff"},{"status":"ACTIVE","sortPriority":3,"id":47208569,"name":"4. Enticement"},{"status":"ACTIVE","sortPriority":4,"id":67532289,"name":"5. Super Breeze"},{"status":"ACTIVE","sortPriority":5,"id":49183855,"name":"7. Bruces Angel"},{"status":"ACTIVE","sortPriority":6,"id":70003368,"name":"8. Dark Queen"}],"regulators":["MR_INT"],"venue":"Murray Bridge","countryCode":"AU","discountAllowed":true,"timezone":"Australia/Adelaide","openDate":"2024-06-02T08:21:00.000Z","version":5962889462,"name":"R3 395m Rest","eventName":"Murray Bridge (AUS) 2nd Jun"},"rc":[],"con":true,"img":false}]}
{"op":"mcm","clk":"11449448326","pt":1717309298219,"mc":[{"id":"1.229554900","marketDefinition":{"bspMarket":true,"turnInPlayEnabled":false,"persistenceEnabled":false,"marketBaseRate":7.0,"eventId":"33318908","eventTypeId":"4339","numberOfWinners":1,"bettingType":"ODDS","marketType":"WIN","marketTime":"2024-06-02T08:59:00.000Z","suspendTime":"2024-06-02T08:59:00.000Z","bspReconciled":false,"complete":true,"inPlay":false,"crossMatching":true,"runnersVoidable":false,"numberOfActiveRunners":5,"betDelay":0,"status":"SUSPENDED","runners":[{"status":"ACTIVE","sortPriority":1,"id":63027102,"name":"2. Christoff"},{"status":"ACTIVE","sortPriority":2,"id":47208569,"name":"4. Enticement"},{"status":"ACTIVE","sortPriority":3,"id":67532289,"name":"5. Super Breeze"},{"status":"ACTIVE","sortPriority":4,"id":49183855,"name":"7. Bruces Angel"},{"status":"ACTIVE","sortPriority":5,"id":70003368,"name":"8. Dark Queen"},{"status":"REMOVED","sortPriority":6,"removalDate":"2024-06-02T06:21:38.000Z","id":63161681,"name":"1. Razzle Berries"}],"regulators":["MR_INT"],"venue":"Murray Bridge","countryCode":"AU","discountAllowed":true,"timezone":"Australia/Adelaide","openDate":"2024-06-02T08:21:00.000Z","version":5962889952,"name":"R3 395m Rest","eventName":"Murray Bridge (AUS) 2nd Jun"},"rc":[],"con":true,"img":false}]}
{"op":"mcm","clk":"11449448326","pt":1717309298219,"mc":[{"id":"1.229554900","rc":[{"spl":[[1.01,0]],"id":63161681}],"con":true,"img":false}]}
{"op":"mcm","clk":"11449452431","pt":1717309356905,"mc":[{"id":"1.229554900","marketDefinition":{"bspMarket":true,"turnInPlayEnabled":false,"persistenceEnabled":false,"marketBaseRate":7.0,"eventId":"33318908","eventTypeId":"4339","numberOfWinners":1,"bettingType":"ODDS","marketType":"WIN","marketTime":"2024-06-02T08:59:00.000Z","suspendTime":"2024-06-02T08:59:00.000Z","bspReconciled":false,"complete":true,"inPlay":false,"crossMatching":true,"runnersVoidable":false,"numberOfActiveRunners":5,"betDelay":0,"status":"OPEN","runners":[{"status":"ACTIVE","sortPriority":1,"id":63027102,"name":"2. Christoff"},{"status":"ACTIVE","sortPriority":2,"id":47208569,"name":"4. Enticement"},{"status":"ACTIVE","sortPriority":3,"id":67532289,"name":"5. Super Breeze"},{"status":"ACTIVE","sortPriority":4,"id":49183855,"name":"7. Bruces Angel"},{"status":"ACTIVE","sortPriority":5,"id":70003368,"name":"8. Dark Queen"},{"status":"REMOVED","sortPriority":6,"removalDate":"2024-06-02T06:21:38.000Z","id":63161681,"name":"1. Razzle Berries"}],"regulators":["MR_INT"],"venue":"Murray Bridge","countryCode":"AU","discountAllowed":true,"timezone":"Australia/Adelaide","openDate":"2024-06-02T08:21:00.000Z","version":5962891348,"name":"R3 395m Rest","eventName":"Murray Bridge (AUS) 2nd Jun"},"rc":[],"con":true,"img":false}]}
{"op":"mcm","clk":"11449454762","pt":1717309392781,"mc":[{"id":"1.229554900","rc":[{"atb":[[1.64,163.33],[1.59,354.34],[1.54,387.15]],"id":67532289},{"atl":[[4,69.68],[3.5,55.74]],"id":67532289},{"spn":2.57,"spf":"NaN","id":67532289}],"con":true,"img":false}]}
{"op":"mcm","clk":"11449460685","pt":1717309485524,"mc":[{"id":"1.229554900","rc":[{"atb":[[2.86,112.39],[2.96,53.33],[2.76,118.78]],"id":70003368},{"atl":[[10.5,14.66],[15.5,14.41]],"id":70003368},{"spn":6.73,"spf":"NaN","id":70003368},{"atb":[[2.8,116.14],[2.9,55.01],[2.7,122.97]],"id":47208569},{"atl":[[10,15.48],[15,14.93]],"id":47208569},{"spn":6.45,"spf":"NaN","id":47208569},{"atb":[[16,13.93],[18.5,11.94],[22,4.97]],"id":63027102},{"atl":[[320,0.43],[420,0.49]],"id":63027102},{"spn":171.0,"spf":"NaN","id":63027102}],"con":true,"img":false}]}
{"op":"mcm","clk":"11449462408","pt":1717309511436,"mc":[{"id":"1.229554900","rc":[{"atb":[[2.86,0],[2.96,0],[2.76,0]],"id":70003368},{"atl":[[10.5,0],[15.5,0]],"id":70003368},{"atb":[[2.8,0],[2.9,0],[2.7,0]],"id":47208569},{"atl":[[10,0],[15,0]],"id":47208569},{"atb":[[1.64,0],[1.59,0],[1.54,0]],"id":67532289},{"atl":[[4,0],[3.5,0]],"id":67532289}],"con":true,"img":false}]}
{"op":"mcm","clk":"11449463292","pt":1717309524777,"mc":[{"id":"1.229554900","rc":[{"atb":[[2.86,112.39],[2.96,53.33],[2.76,118.78]],"id":70003368},{"atl":[[10.5,14.66],[15.5,14.41]],"id":70003368},{"atb":[[2.8,116.14],[2.9,55.01],[2.7,122.97]],"id":47208569},{"atl":[[10,15.48],[15,14.93]],"id":47208569},{"atb":[[1.63,331.84],[1.58,360.45],[1.68,153.71]],"id":67532289},{"atl":[[3.7,51.62],[4.4,61.48]],"id":67532289}],"con":true,"img":false}]}
{"op":"mcm","clk":"11449480351","pt":1717309728419,"mc":[{"id":"1.229554900","marketDefinition":{"bspMarket":true,"turnInPlayEnabled":false,"persistenceEnabled":false,"marketBaseRate":7.0,"eventId":"33318908","eventTypeId":"4339","numberOfWinners":1,"bettingType":"ODDS","marketType":"WIN","marketTime":"2024-06-02T08:59:00.000Z","suspendTime":"2024-06-02T08:59:00.000Z","bspReconciled":false,"complete":true,"inPlay":false,"crossMatching":true,"runnersVoidable":false,"numberOfActiveRunners":5,"betDelay":0,"status":"OPEN","runners":[{"status":"ACTIVE","sortPriority":1,"id":63027102,"name":"2. Christoff"},{"status":"ACTIVE","sortPriority":2,"id":47208569,"name":"4. Enticement"},{"status":"ACTIVE","sortPriority":3,"id":67532289,"name":"5. Super Breeze"},{"status":"ACTIVE","sortPriority":4,"id":49183855,"name":"7. Bruces Angel"},{"status":"ACTIVE","sortPriority":5,"id":70003368,"name":"8. Dark Queen"},{"status":"REMOVED","sortPriority":6,"removalDate":"2024-06-02T06:21:38.000Z","id":63161681,"name":"1. Razzle Berries"}],"regulators":["MR_INT"],"venue":"Murray Bridge","countryCode":"AU","discountAllowed":true,"timezone":"Australia/Adelaide","openDate":"2024-06-02T08:21:00.000Z","version":5962891348,"name":"R3 395m Rest","eventName":"Murray Bridge (AUS) 2nd Jun"},"rc":[{"atb":[[2.86,112.39],[2.96,53.33],[2.76,118.78]],"id":70003368},{"atl":[[10.5,14.66],[15.5,14.41]],"id":70003368},{"spn":6.73,"spf":"NaN","id":70003368},{"atb":[[2.8,116.14],[2.9,55.01],[2.7,122.97]],"id":47208569},{"atl":[[10,15.48],[15,14.93]],"id":47208569},{"spn":6.45,"spf":"NaN","id":47208569},{"atb":[[16,13.93],[18.5,11.94],[22,4.97]],"id":63027102},{"atl":[[320,0.43],[420,0.49]],"id":63027102},{"spn":171.0,"spf":"NaN","id":63027102},{"atb":[[1.63,331.84],[1.58,360.45],[1.68,153.71]],"id":67532289},{"atl":[[3.7,51.62],[4.4,61.48]],"id":67532289},{"spn":2.69,"spf":"NaN","id":67532289}],"con":true,"img":true}]}
{"op":"mcm","clk":"11449491210","pt":1717309814047,"mc":[{"id":"1.229554900","rc":[{"atb":[[16,0],[18.5,0],[22,0]],"id":63027102},{"atl":[[320,0],[420,0]],"id":63027102},{"spn":"NaN","spf":"NaN","id":63027102},{"spn":2.69,"spf":"NaN","id":67532289}],"con":true,"img":false}]}
{"op":"mcm","clk":"11449492615","pt":1717309833772,"mc":[{"id":"1.229554900","rc":[{"atb":[[16,13.93],[18.5,11.94],[22,4.97]],"id":63027102},{"atl":[[320,0.43],[420,0.49]],"id":63027102}],"con":true,"img":false}]}
{"op":"mcm","clk":"11449516572","pt":1717310230694,"mc":[{"id":"1.229554900","rc":[{"atb":[[2.86,0],[2.96,0],[2.76,0]],"id":70003368},{"atl":[[10.5,0],[15.5,0]],"id":70003368},{"spn":"NaN","spf":"NaN","id":70003368},{"atb":[[2.8,0],[2.9,0],[2.7,0]],"id":47208569},{"atl":[[10,0],[15,0]],"id":47208569},{"spn":"NaN","spf":"NaN","id":47208569},{"atb":[[16,0],[18.5,0],[22,0]],"id":63027102},{"atl":[[320,0],[420,0]],"id":63027102},{"atb":[[1.63,0],[1.58,0],[1.68,0]],"id":67532289},{"atl":[[3.7,0],[4.4,0]],"id":67532289},{"spn":"NaN","spf":"NaN","id":67532289}],"con":true,"img":false}]}
{"op":"mcm","clk":"11449517962","pt":1717310252321,"mc":[{"id":"1.229554900","rc":[{"atb":[[2.86,112.39],[2.96,53.33],[2.76,118.78]],"id":70003368},{"atl":[[10.5,14.66],[15.5,14.41]],"id":70003368},{"atb":[[2.8,116.14],[2.9,55.01],[2.7,122.97]],"id":47208569},{"atl":[[10,15.48],[15,14.93]],"id":47208569},{"atb":[[16,13.93],[18.5,11.94],[22,4.97]],"id":63027102},{"atl":[[320,0.43],[420,0.49]],"id":63027102},{"atb":[[1.63,331.84],[1.58,360.45],[1.68,153.71]],"id":67532289},{"atl":[[3.7,51.62],[4.4,61.48]],"id":67532289}],"con":true,"img":false}]}
{"op":"mcm","clk":"11449578265","pt":1717311300125,"mc":[{"id":"1.229554900","rc":[{"atb":[[2.86,0],[2.96,0],[2.76,0]],"id":70003368},{"atl":[[10.5,0],[15.5,0]],"id":70003368},{"atb":[[2.8,0],[2.9,0],[2.7,0]],"id":47208569},{"atl":[[10,0],[15,0]],"id":47208569},{"atb":[[16,0],[18.5,0],[22,0]],"id":63027102},{"atl":[[320,0],[420,0]],"id":63027102},{"atb":[[1.63,0],[1.58,0],[1.68,0]],"id":67532289},{"atl":[[3.7,0],[4.4,0]],"id":67532289}],"con":true,"img":false}]}
{"op":"mcm","clk":"11449579181","pt":1717311315022,"mc":[{"id":"1.229554900","rc":[{"atb":[[2.86,112.39],[2.96,53.33],[2.76,118.78]],"id":70003368},{"atl":[[10.5,14.66],[15.5,14.41]],"id":70003368},{"atb":[[2.8,116.14],[2.9,55.01],[2.7,122.97]],"id":47208569},{"atl":[[10,15.48],[15,14.93]],"id":47208569},{"atb":[[16,13.93],[18.5,11.94],[22,4.97]],"id":63027102},{"atl":[[320,0.43],[420,0.49]],"id":63027102},{"atb":[[1.63,331.84],[1.58,360.45],[1.68,153.71]],"id":67532289},{"atl":[[3.7,51.62],[4.4,61.48]],"id":67532289}],"con":true,"img":false}]}
{"op":"mcm","clk":"11449586632","pt":1717311442023,"mc":[{"id":"1.229554900","rc":[{"atb":[[1.03,5.78]],"id":70003368},{"atl":[[1000,0.85]],"id":70003368},{"spn":6.73,"spf":"NaN","id":70003368},{"atb":[[1.03,5.78]],"id":47208569},{"atl":[[990,0.85]],"id":47208569},{"spn":6.45,"spf":"NaN","id":47208569},{"atb":[[1.03,5.78]],"id":49183855},{"atl":[[1000,0.85]],"id":49183855},{"spn":500.51,"spf":"NaN","id":49183855},{"atb":[[1.03,5.78]],"id":63027102},{"atl":[[990,0.85]],"id":63027102},{"spn":171.0,"spf":"NaN","id":63027102},{"atb":[[1.03,5.78]],"id":67532289},{"atl":[[1000,0.85]],"id":67532289},{"spn":2.69,"spf":"NaN","id":67532289}],"con":true,"img":false}]}
{"op":"mcm","clk":"11449588496","pt":1717311474766,"mc":[{"id":"1.229554900","rc":[{"atb":[[17,13.06],[19.5,5.65],[14.5,15.48]],"id":49183855},{"atl":[[300,0.46],[400,0.52]],"id":49183855}],"con":true,"img":false}]}
{"op":"mcm","clk":"11449589091","pt":1717311486741,"mc":[{"id":"1.229554900","rc":[{"atl":[[1000,3.2]],"id":70003368},{"atl":[[1000,2.35]],"id":47208569},{"atl":[[3.45,3.87]],"id":67532289}],"con":true,"img":false}]}
{"op":"mcm","clk":"11449589105","pt":1717311487045,"mc":[{"id":"1.229554900","rc":[{"atl":[[1000,2.24]],"id":70003368},{"atl":[[1000,1.45]],"id":47208569}],"con":true,"img":false}]}
{"op":"mcm","clk":"11449589119","pt":1717311487351,"mc":[{"id":"1.229554900","rc":[{"atl":[[1000,0.85]],"id":70003368}],"con":true,"img":false}]}
{"op":"mcm","clk":"11449589126","pt":1717311487452,"mc":[{"id":"1.229554900","rc":[{"atl":[[9.6,1.38]],"id":70003368}],"con":true,"img":false}]}
{"op":"mcm","clk":"11449589136","pt":1717311487657,"mc":[{"id":"1.229554900","rc":[{"atl":[[1000,0]],"id":47208569}],"con":true,"img":false}]}
{"op":"mcm","clk":"11449589144","pt":1717311487761,"mc":[{"id":"1.229554900","rc":[{"atl":[[9.2,1.45]],"id":47208569}],"con":true,"img":false}]}
{"op":"mcm","clk":"11449589250","pt":1717311490163,"mc":[{"id":"1.229554900","rc":[{"atl":[[9.2,3.54]],"id":47208569}],"con":true,"img":false}]}
{"op":"mcm","clk":"11449589260","pt":1717311490372,"mc":[{"id":"1.229554900","rc":[{"atl":[[3.45,9.46]],"id":67532289}],"con":true,"img":false}]}
{"op":"mcm","clk":"11449589266","pt":1717311490476,"mc":[{"id":"1.229554900","rc":[{"atl":[[9.6,3.4]],"id":70003368}],"con":true,"img":false}]}
{"op":"mcm","clk":"11449599447","pt":1717311679575,"mc":[{"id":"1.229554900","rc":[{"spn":6.28,"spf":"NaN","id":70003368},{"atl":[[9.2,2.09]],"id":47208569},{"spn":6.05,"spf":"NaN","id":47208569},{"spn":159.75,"spf":"NaN","id":49183855},{"spn":2.56,"spf":"NaN","id":67532289}],"con":true,"img":false}]}
{"op":"mcm","clk":"11449600213","pt":1717311694605,"mc":[{"id":"1.229554900","rc":[{"atl":[[3.45,5.59]],"id":67532289}],"con":true,"img":false}]}
{"op":"mcm","clk":"11449600730","pt":1717311705017,"mc":[{"id":"1.229554900","rc":[{"atl":[[9.2,0]],"id":47208569}],"con":true,"img":false}]}
{"op":"mcm","clk":"11449600936","pt":1717311709792,"mc":[{"id":"1.229554900","rc":[{"atl":[[9.6,2.01]],"id":70003368}],"con":true,"img":false}]}
{"op":"mcm","clk":"11449601747","pt":1717311725368,"mc":[{"id":"1.229554900","rc":[{"atl":[[1000,3.2]],"id":70003368},{"atl":[[1000,2.35]],"id":47208569},{"atl":[[3.45,9.46]],"id":67532289}],"con":true,"img":false}]}
{"op":"mcm","clk":"11449601763","pt":1717311725574,"mc":[{"id":"1.229554900","rc":[{"atl":[[1000,2.24]],"id":70003368},{"atl":[[1000,1.45]],"id":47208569}],"con":true,"img":false}]}
{"op":"mcm","clk":"11449601787","pt":1717311725835,"mc":[{"id":"1.229554900","rc":[{"atl":[[1000,0.85]],"id":70003368}],"con":true,"img":false}]}
{"op":"mcm","clk":"11449601795","pt":1717311725937,"mc":[{"id":"1.229554900","rc":[{"atl":[[9.6,3.4]],"id":70003368}],"con":true,"img":false}]}
{"op":"mcm","clk":"11449601806","pt":1717311726145,"mc":[{"id":"1.229554900","rc":[{"atl":[[1000,0]],"id":47208569}],"con":true,"img":false}]}
{"op":"mcm","clk":"11449601814","pt":1717311726244,"mc":[{"id":"1.229554900","rc":[{"atl":[[9.2,1.45]],"id":47208569}],"con":true,"img":false}]}
{"op":"mcm","clk":"11449602576","pt":1717311740775,"mc":[{"id":"1.229554900","rc":[{"atl":[[3.45,3.87]],"id":67532289}],"con":true,"img":false}]}
{"op":"mcm","clk":"11449603961","pt":1717311766469,"mc":[{"id":"1.229554900","rc":[{"atl":[[9.6,1.38]],"id":70003368}],"con":true,"img":false}]}
{"op":"mcm","clk":"11449606556","pt":1717311815781,"mc":[{"id":"1.229554900","rc":[{"atl":[[9.2,3.54]],"id":47208569}],"con":true,"img":false}]}
{"op":"mcm","clk":"11449606562","pt":1717311815883,"mc":[{"id":"1.229554900","rc":[{"atl":[[3.45,9.46]],"id":67532289}],"con":true,"img":false}]}
{"op":"mcm","clk":"11449606569","pt":1717311815984,"mc":[{"id":"1.229554900","rc":[{"atl":[[9.6,3.4]],"id":70003368}],"con":true,"img":false}]}
{"op":"mcm","clk":"11449612114","pt":1717311914020,"mc":[{"id":"1.229554900","rc":[{"atl":[[9.2,2.09]],"id":47208569}],"con":true,"img":false}]}
{"op":"mcm","clk":"11449612969","pt":1717311928826,"mc":[{"id":"1.229554900","rc":[{"atl":[[3.45,5.59]],"id":67532289}],"con":true,"img":false}]}
{"op":"mcm","clk":"11449613889","pt":1717311943862,"mc":[{"id":"1.229554900","rc":[{"atl":[[9.6,2.01]],"id":70003368}],"con":true,"img":false}]}
{"op":"mcm","clk":"11449614656","pt":1717311959034,"mc":[{"id":"1.229554900","rc":[{"atl":[[1000,2.35]],"id":47208569},{"atl":[[3.45,9.46]],"id":67532289}],"con":true,"img":false}]}
{"op":"mcm","clk":"11449614665","pt":1717311959236,"mc":[{"id":"1.229554900","rc":[{"atl":[[1000,3.2]],"id":70003368},{"atl":[[1000,1.45]],"id":47208569}],"con":true,"img":false}]}
{"op":"mcm","clk":"11449614677","pt":1717311959443,"mc":[{"id":"1.229554900","rc":[{"atl":[[1000,0]],"id":47208569}],"con":true,"img":false}]}
{"op":"mcm","clk":"11449614684","pt":1717311959545,"mc":[{"id":"1.229554900","rc":[{"atl":[[9.2,3.54]],"id":47208569}],"con":true,"img":false}]}
{"op":"mcm","clk":"11449614705","pt":1717311959860,"mc":[{"id":"1.229554900","rc":[{"atl":[[1000,2.24]],"id":70003368}],"con":true,"img":false}]}
{"op":"mcm","clk":"11449614722","pt":1717311960162,"mc":[{"id":"1.229554900","rc":[{"atl":[[1000,0.85]],"id":70003368}],"con":true,"img":false}]}
{"op":"mcm","clk":"11449614729","pt":1717311960266,"mc":[{"id":"1.229554900","rc":[{"atl":[[9.6,3.4]],"id":70003368}],"con":true,"img":false}]}
{"op":"mcm","clk":"11449617634","pt":1717312019033,"mc":[{"id":"1.229554900","rc":[{"atl":[[9.2,1.45]],"id":47208569}],"con":true,"img":false}]}
{"op":"mcm","clk":"11449618874","pt":1717312041759,"mc":[{"id":"1.229554900","rc":[{"atl":[[3.45,3.87]],"id":67532289}],"con":true,"img":false}]}
{"op":"mcm","clk":"11449621285","pt":1717312090685,"mc":[{"id":"1.229554900","rc":[{"atl":[[9.6,1.38]],"id":70003368}],"con":true,"img":false}]}
{"op":"mcm","clk":"11449622755","pt":1717312126151,"mc":[{"id":"1.229554900","rc":[{"atl":[[3.45,9.46]],"id":67532289}],"con":true,"img":false}]}
{"op":"mcm","clk":"11449622757","pt":1717312126254,"mc":[{"id":"1.229554900","rc":[{"atl":[[9.2,3.54]],"id":47208569}],"con":true,"img":false}]}
{"op":"mcm","clk":"11449622766","pt":1717312126565,"mc":[{"id":"1.229554900","rc":[{"atl":[[9.6,3.4]],"id":70003368}],"con":true,"img":false}]}
{"op":"mcm","clk":"11449623745","pt":1717312152896,"mc":[{"id":"1.229554900","rc":[{"atl":[[9.2,2.09]],"id":47208569}],"con":true,"img":false}]}
{"op":"mcm","clk":"11449624041","pt":1717312161624,"mc":[{"id":"1.229554900","rc":[{"atl":[[3.45,5.59]],"id":67532289}],"con":true,"img":false}]}
{"op":"mcm","clk":"11449624317","pt":1717312169307,"mc":[{"id":"1.229554900","rc":[{"atb":[[2.86,0],[2.96,0],[2.76,0]],"id":70003368},{"atl":[[10.5,0],[15.5,0]],"id":70003368},{"atb":[[2.8,0],[2.9,0],[2.7,0]],"id":47208569},{"atl":[[10,0],[15,0]],"id":47208569},{"atb":[[16,0],[18.5,0],[22,0]],"id":63027102},{"atl":[[320,0],[420,0]],"id":63027102},{"atb":[[1.63,0],[1.58,0],[1.68,0]],"id":67532289},{"atl":[[3.7,0],[4.4,0]],"id":67532289}],"con":true,"img":false}]}
{"op":"mcm","clk":"11449624611","pt":1717312176719,"mc":[{"id":"1.229554900","rc":[{"atl":[[9.6,2.01]],"id":70003368}],"con":true,"img":false}]}
{"op":"mcm","clk":"11449624998","pt":1717312185760,"mc":[{"id":"1.229554900","rc":[{"atb":[[2.86,112.39],[2.96,53.33],[2.76,118.78]],"id":70003368},{"atl":[[10.5,14.66],[15.5,14.41]],"id":70003368},{"atb":[[2.8,116.14],[2.9,55.01],[2.7,122.97]],"id":47208569},{"atl":[[10,15.48],[15,14.93]],"id":47208569},{"atb":[[16,13.93],[18.5,11.94],[22,4.97]],"id":63027102},{"atl":[[320,0.43],[420,0.49]],"id":63027102},{"atb":[[1.63,331.84],[1.58,360.45],[1.68,153.71]],"id":67532289},{"atl":[[3.7,51.62],[4.4,61.48]],"id":67532289}],"con":true,"img":false}]}
{"op":"mcm","clk":"11449625432","pt":1717312195462,"mc":[{"id":"1.229554900","rc":[{"atl":[[1000,3.2]],"id":70003368},{"atl":[[1000,2.35]],"id":47208569},{"atl":[[3.45,9.46]],"id":67532289}],"con":true,"img":false}]}
{"op":"mcm","clk":"11449625443","pt":1717312195619,"mc":[{"id":"1.229554900","rc":[{"atl":[[1000,2.24]],"id":70003368},{"atl":[[1000,1.45]],"id":47208569}],"con":true,"img":false}]}
{"op":"mcm","clk":"11449625456","pt":1717312195927,"mc":[{"id":"1.229554900","rc":[{"atl":[[1000,0]],"id":47208569}],"con":true,"img":false}]}
{"op":"mcm","clk":"11449625459","pt":1717312196033,"mc":[{"id":"1.229554900","rc":[{"atl":[[9.2,3.54]],"id":47208569}],"con":true,"img":false}]}
{"op":"mcm","clk":"11449625465","pt":1717312196239,"mc":[{"id":"1.229554900","rc":[{"atl":[[1000,0.85]],"id":70003368}],"con":true,"img":false}]}
{"op":"mcm","clk":"11449625470","pt":1717312196390,"mc":[{"id":"1.229554900","rc":[{"atl":[[9.6,3.4]],"id":70003368}],"con":true,"img":false}]}
{"op":"mcm","clk":"11449629874","pt":1717312307929,"mc":[{"id":"1.229554900","rc":[{"atb":[[17,0],[19.5,0],[14.5,0]],"id":49183855},{"atl":[[300,0],[400,0]],"id":49183855},{"spn":500.51,"spf":"NaN","id":49183855}],"con":true,"img":false}]}
{"op":"mcm","clk":"11449630255","pt":1717312317109,"mc":[{"id":"1.229554900","rc":[{"atl":[[9.2,1.45]],"id":47208569}],"con":true,"img":false}]}
{"op":"mcm","clk":"11449630303","pt":1717312317937,"mc":[{"id":"1.229554900","rc":[{"atb":[[17,13.06],[19.5,5.65],[14.5,15.48]],"id":49183855},{"atl":[[300,0.46],[400,0.52]],"id":49183855}],"con":true,"img":false}]}
{"op":"mcm","clk":"11449631901","pt":1717312355777,"mc":[{"id":"1.229554900","rc":[{"atl":[[3.45,3.87]],"id":67532289}],"con":true,"img":false}]}
{"op":"mcm","clk":"11449632767","pt":1717312380807,"mc":[{"id":"1.229554900","rc":[{"atl":[[9.2,0]],"id":47208569},{"spn":6.45,"spf":"NaN","id":47208569},{"spn":159.75,"spf":"NaN","id":49183855}],"con":true,"img":false}]}
{"op":"mcm","clk":"11449633101","pt":1717312388532,"mc":[{"id":"1.229554900","rc":[{"atl":[[9.6,1.38]],"id":70003368}],"con":true,"img":false}]}
{"op":"mcm","clk":"11449633282","pt":1717312393907,"mc":[{"id":"1.229554900","rc":[{"atl":[[3.45,0]],"id":67532289}],"con":true,"img":false}]}
{"op":"mcm","clk":"11449633853","pt":1717312409026,"mc":[{"id":"1.229554900","rc":[{"atl":[[9.6,0]],"id":70003368}],"con":true,"img":false}]}
{"op":"mcm","clk":"11449634354","pt":1717312424160,"mc":[{"id":"1.229554900","rc":[{"atl":[[1000,3.2]],"id":70003368},{"atl":[[1000,2.35]],"id":47208569},{"atl":[[3.45,3.87]],"id":67532289}],"con":true,"img":false}]}
{"op":"mcm","clk":"11449634363","pt":1717312424363,"mc":[{"id":"1.229554900","rc":[{"atl":[[1000,2.24]],"id":70003368},{"atl":[[1000,1.45]],"id":47208569}],"con":true,"img":false}]}
{"op":"mcm","clk":"11449634378","pt":1717312424568,"mc":[{"id":"1.229554900","rc":[{"atl":[[1000,0.85]],"id":70003368}],"con":true,"img":false}]}
{"op":"mcm","clk":"11449634382","pt":1717312424670,"mc":[{"id":"1.229554900","rc":[{"atl":[[9.6,1.38]],"id":70003368}],"con":true,"img":false}]}
{"op":"mcm","clk":"11449634389","pt":1717312424977,"mc":[{"id":"1.229554900","rc":[{"atl":[[1000,0]],"id":47208569}],"con":true,"img":false}]}
{"op":"mcm","clk":"11449634393","pt":1717312425082,"mc":[{"id":"1.229554900","rc":[{"atl":[[9.2,1.45]],"id":47208569}],"con":true,"img":false}]}
{"op":"mcm","clk":"11449635102","pt":1717312442970,"mc":[{"id":"1.229554900","rc":[{"spn":6.05,"spf":"NaN","id":47208569},{"atb":[[1.52,100]],"id":67532289}],"con":true,"img":false}]}
{"op":"mcm","clk":"11449637801","pt":1717312515077,"mc":[{"id":"1.229554900","rc":[{"atl":[[9.2,3.54]],"id":47208569}],"con":true,"img":false}]}
{"op":"mcm","clk":"11449637823","pt":1717312515390,"mc":[{"id":"1.229554900","rc":[{"atl":[[3.45,9.46]],"id":67532289}],"con":true,"img":false}]}
{"op":"mcm","clk":"11449637839","pt":1717312515647,"mc":[{"id":"1.229554900","rc":[{"atl":[[9.6,3.4]],"id":70003368}],"con":true,"img":false}]}
{"op":"mcm","clk":"11449641354","pt":1717312605862,"mc":[{"id":"1.229554900","rc":[{"atl":[[9.2,2.09]],"id":47208569}],"con":true,"img":false}]}
{"op":"mcm","clk":"11449641979","pt":1717312620994,"mc":[{"id":"1.229554900","rc":[{"atl":[[3.45,5.59]],"id":67532289}],"con":true,"img":false}]}
{"op":"mcm","clk":"11449642254","pt":1717312628028,"mc":[{"id":"1.229554900","rc":[{"atl":[[9.6,2.01]],"id":70003368}],"con":true,"img":false}]}
{"op":"mcm","clk":"11449643182","pt":1717312650961,"mc":[{"id":"1.229554900","rc":[{"atl":[[1000,3.2]],"id":70003368},{"atl":[[1000,2.35]],"id":47208569},{"atl":[[3.45,9.46]],"id":67532289}],"con":true,"img":false}]}
{"op":"mcm","clk":"11449643194","pt":1717312651115,"mc":[{"id":"1.229554900","rc":[{"atl":[[1000,2.24]],"id":70003368},{"atl":[[1000,1.45]],"id":47208569}],"con":true,"img":false}]}
{"op":"mcm","clk":"11449643204","pt":1717312651325,"mc":[{"id":"1.229554900","rc":[{"atl":[[1000,0.85]],"id":70003368}],"con":true,"img":false}]}
{"op":"mcm","clk":"11449643207","pt":1717312651429,"mc":[{"id":"1.229554900","rc":[{"atl":[[9.6,3.4]],"id":70003368}],"con":true,"img":false}]}
{"op":"mcm","clk":"11449643215","pt":1717312651634,"mc":[{"id":"1.229554900","rc":[{"atl":[[1000,0]],"id":47208569}],"con":true,"img":false}]}
{"op":"mcm","clk":"11449643223","pt":1717312651742,"mc":[{"id":"1.229554900","rc":[{"atl":[[9.2,3.54]],"id":47208569}],"con":true,"img":false}]}
{"op":"mcm","clk":"11449646486","pt":1717312732241,"mc":[{"id":"1.229554900","rc":[{"atl":[[9.2,1.45]],"id":47208569}],"con":true,"img":false}]}
{"op":"mcm","clk":"11449647870","pt":1717312767181,"mc":[{"id":"1.229554900","rc":[{"atl":[[3.45,3.87]],"id":67532289}],"con":true,"img":false}]}
{"op":"mcm","clk":"11449649883","pt":1717312814763,"mc":[{"id":"1.229554900","rc":[{"atl":[[9.6,1.38]],"id":70003368}],"con":true,"img":false}]}
{"op":"mcm","clk":"11449651292","pt":1717312843290,"mc":[{"id":"1.229554900","rc":[{"atl":[[9.2,0]],"id":47208569}],"con":true,"img":false}]}
{"op":"mcm","clk":"11449651603","pt":1717312849915,"mc":[{"id":"1.229554900","rc":[{"atl":[[9.2,2.09]],"id":47208569}],"con":true,"img":false}]}
{"op":"mcm","clk":"11449651607","pt":1717312850019,"mc":[{"id":"1.229554900","rc":[{"atl":[[3.45,9.46]],"id":67532289}],"con":true,"img":false}]}
{"op":"mcm","clk":"11449651615","pt":1717312850222,"mc":[{"id":"1.229554900","rc":[{"atl":[[9.6,3.4]],"id":70003368}],"con":true,"img":false}]}
{"op":"mcm","clk":"11449651900","pt":1717312857405,"mc":[{"id":"1.229554900","rc":[{"atl":[[3.45,5.59]],"id":67532289}],"con":true,"img":false}]}
{"op":"mcm","clk":"11449652588","pt":1717312872747,"mc":[{"id":"1.229554900","rc":[{"atl":[[9.6,2.01]],"id":70003368}],"con":true,"img":false}]}
{"op":"mcm","clk":"11449653224","pt":1717312887366,"mc":[{"id":"1.229554900","rc":[{"atl":[[1000,3.2]],"id":70003368},{"atl":[[1000,2.35]],"id":47208569},{"atl":[[3.45,9.46]],"id":67532289}],"con":true,"img":false}]}
{"op":"mcm","clk":"11449653240","pt":1717312887671,"mc":[{"id":"1.229554900","rc":[{"atl":[[1000,2.24]],"id":70003368},{"atl":[[1000,1.45]],"id":47208569}],"con":true,"img":false}]}
{"op":"mcm","clk":"11449653253","pt":1717312887876,"mc":[{"id":"1.229554900","rc":[{"atl":[[1000,0]],"id":47208569}],"con":true,"img":false}]}
{"op":"mcm","clk":"11449653259","pt":1717312887978,"mc":[{"id":"1.229554900","rc":[{"atl":[[9.2,3.54]],"id":47208569}],"con":true,"img":false}]}
{"op":"mcm","clk":"11449653272","pt":1717312888239,"mc":[{"id":"1.229554900","rc":[{"atl":[[1000,0.85]],"id":70003368}],"con":true,"img":false}]}
{"op":"mcm","clk":"11449653275","pt":1717312888340,"mc":[{"id":"1.229554900","rc":[{"atl":[[9.6,3.4]],"id":70003368}],"con":true,"img":false}]}
{"op":"mcm","clk":"11449657618","pt":1717312995577,"mc":[{"id":"1.229554900","rc":[{"atb":[[2.86,0],[2.96,0],[2.76,0]],"id":70003368},{"atl":[[10.5,0],[15.5,0]],"id":70003368},{"spn":5.31,"spf":"NaN","id":70003368},{"atb":[[2.8,0],[2.9,0],[2.7,0]],"id":47208569},{"atl":[[10,0],[15,0]],"id":47208569},{"spn":5.11,"spf":"NaN","id":47208569},{"atb":[[16,0],[18.5,0],[22,0]],"id":63027102},{"atl":[[320,0],[420,0]],"id":63027102},{"spn":495.51,"spf":"NaN","id":63027102},{"atb":[[1.63,0],[1.58,0],[1.68,0]],"id":67532289},{"atl":[[3.7,0],[4.4,0]],"id":67532289},{"spn":2.48,"spf":"NaN","id":67532289}],"con":true,"img":false}]}
{"op":"mcm","clk":"11449658107","pt":1717313008190,"mc":[{"id":"1.229554900","rc":[{"atb":[[2.86,112.39],[2.96,53.33],[2.76,118.78]],"id":70003368},{"atl":[[10.5,14.66],[15.5,14.41]],"id":70003368},{"atb":[[2.8,116.14],[2.9,55.01],[2.7,122.97]],"id":47208569},{"atl":[[10,15.48],[15,14.93]],"id":47208569},{"atb":[[16,13.93],[18.5,11.94],[22,4.97]],"id":63027102},{"atl":[[320,0.43],[420,0.49]],"id":63027102},{"atb":[[1.63,331.84],[1.58,360.45],[1.68,153.71]],"id":67532289},{"atl":[[3.7,51.62],[4.4,61.48]],"id":67532289}],"con":true,"img":false}]}
{"op":"mcm","clk":"11449659025","pt":1717313030795,"mc":[{"id":"1.229554900","rc":[{"atl":[[9.2,1.45]],"id":47208569}],"con":true,"img":false}]}
{"op":"mcm","clk":"11449660558","pt":1717313068971,"mc":[{"id":"1.229554900","rc":[{"spn":6.28,"spf":"NaN","id":70003368},{"spn":6.05,"spf":"NaN","id":47208569},{"spn":171.0,"spf":"NaN","id":63027102},{"atl":[[3.45,3.87]],"id":67532289},{"spn":2.56,"spf":"NaN","id":67532289}],"con":true,"img":false}]}
{"op":"mcm","clk":"11449660978","pt":1717313080056,"mc":[{"id":"1.229554900","rc":[{"atl":[[9.2,0]],"id":47208569}],"con":true,"img":false}]}
{"op":"mcm","clk":"11449661409","pt":1717313090614,"mc":[{"id":"1.229554900","rc":[{"atl":[[9.6,1.38]],"id":70003368}],"con":true,"img":false}]}
{"op":"mcm","clk":"11449661609","pt":1717313095103,"mc":[{"id":"1.229554900","rc":[{"atl":[[3.45,0]],"id":67532289}],"con":true,"img":false}]}
{"op":"mcm","clk":"11449662553","pt":1717313110311,"mc":[{"id":"1.229554900","rc":[{"atl":[[9.6,0]],"id":70003368}],"con":true,"img":false}]}
{"op":"mcm","clk":"11449663197","pt":1717313122341,"mc":[{"id":"1.229554900","rc":[{"atl":[[9.2,2.09]],"id":47208569}],"con":true,"img":false}]}
{"op":"mcm","clk":"11449663203","pt":1717313122496,"mc":[{"id":"1.229554900","rc":[{"atl":[[3.45,5.59]],"id":67532289}],"con":true,"img":false}]}
{"op":"mcm","clk":"11449663209","pt":1717313122601,"mc":[{"id":"1.229554900","rc":[{"atl":[[9.6,2.01]],"id":70003368}],"con":true,"img":false}]}
{"op":"mcm","clk":"11449663679","pt":1717313133144,"mc":[{"id":"1.229554900","rc":[{"atl":[[1000,3.2]],"id":70003368},{"atl":[[1000,2.35]],"id":47208569},{"atl":[[3.45,9.46]],"id":67532289}],"con":true,"img":false}]}
{"op":"mcm","clk":"11449663690","pt":1717313133352,"mc":[{"id":"1.229554900","rc":[{"atl":[[1000,2.24]],"id":70003368},{"atl":[[1000,1.45]],"id":47208569}],"con":true,"img":false}]}
{"op":"mcm","clk":"11449663698","pt":1717313133654,"mc":[{"id":"1.229554900","rc":[{"atl":[[1000,0]],"id":47208569}],"con":true,"img":false}]}
{"op":"mcm","clk":"11449663703","pt":1717313133713,"mc":[{"id":"1.229554900","rc":[{"atl":[[9.2,3.54]],"id":47208569}],"con":true,"img":false}]}
{"op":"mcm","clk":"11449663710","pt":1717313134020,"mc":[{"id":"1.229554900","rc":[{"atl":[[1000,0.85]],"id":70003368}],"con":true,"img":false}]}
{"op":"mcm","clk":"11449663713","pt":1717313134121,"mc":[{"id":"1.229554900","rc":[{"atl":[[9.6,3.4]],"id":70003368}],"con":true,"img":false}]}
{"op":"mcm","clk":"11449667339","pt":1717313215510,"mc":[{"id":"1.229554900","rc":[{"atb":[[17,0],[19.5,0],[14.5,0]],"id":49183855},{"atl":[[300,0],[400,0]],"id":49183855},{"spn":500.51,"spf":"NaN","id":49183855}],"con":true,"img":false}]}
{"op":"mcm","clk":"11449668017","pt":1717313230061,"mc":[{"id":"1.229554900","rc":[{"atb":[[17,13.06],[19.5,5.65],[14.5,15.48]],"id":49183855},{"atl":[[300,0.46],[400,0.52]],"id":49183855}],"con":true,"img":false}]}
{"op":"mcm","clk":"11449672727","pt":1717313324035,"mc":[{"id":"1.229554900","rc":[{"atl":[[9.2,1.45]],"id":47208569},{"spn":159.75,"spf":"NaN","id":49183855}],"con":true,"img":false}]}
{"op":"mcm","clk":"11449672788","pt":1717313325374,"mc":[{"id":"1.229554900","rc":[{"atl":[[9.2,0]],"id":47208569}],"con":true,"img":false}]}
{"op":"mcm","clk":"11449673635","pt":1717313340395,"mc":[{"id":"1.229554900","rc":[{"atl":[[3.45,5.59]],"id":67532289}],"con":true,"img":false}]}
{"op":"mcm","clk":"11449673849","pt":1717313343596,"mc":[{"id":"1.229554900","rc":[{"atl":[[3.45,0]],"id":67532289}],"con":true,"img":false}]}
{"op":"mcm","clk":"11449674568","pt":1717313355706,"mc":[{"id":"1.229554900","rc":[{"atl":[[9.6,2.01]],"id":70003368}],"con":true,"img":false}]}
{"op":"mcm","clk":"11449675615","pt":1717313373811,"mc":[{"id":"1.229554900","rc":[{"atl":[[1000,3.2]],"id":70003368},{"atl":[[1000,2.35]],"id":47208569},{"atl":[[3.45,3.87]],"id":67532289}],"con":true,"img":false}]}
{"op":"mcm","clk":"11449675628","pt":1717313374019,"mc":[{"id":"1.229554900","rc":[{"atl":[[1000,2.24]],"id":70003368},{"atl":[[1000,1.45]],"id":47208569}],"con":true,"img":false}]}
{"op":"mcm","clk":"11449675646","pt":1717313374224,"mc":[{"id":"1.229554900","rc":[{"atl":[[1000,0]],"id":47208569}],"con":true,"img":false}]}
{"op":"mcm","clk":"11449675663","pt":1717313374429,"mc":[{"id":"1.229554900","rc":[{"atl":[[9.2,1.45]],"id":47208569}],"con":true,"img":false}]}
{"op":"mcm","clk":"11449675682","pt":1717313374594,"mc":[{"id":"1.229554900","rc":[{"atl":[[1000,0.85]],"id":70003368}],"con":true,"img":false}]}
{"op":"mcm","clk":"11449675693","pt":1717313374694,"mc":[{"id":"1.229554900","rc":[{"atl":[[9.6,3.4]],"id":70003368}],"con":true,"img":false}]}
{"op":"mcm","clk":"11449677323","pt":1717313401549,"mc":[{"id":"1.229554900","rc":[{"atl":[[9.6,1.38]],"id":70003368}],"con":true,"img":false}]}
{"op":"mcm","clk":"11449678936","pt":1717313423188,"mc":[{"id":"1.229554900","rc":[{"atl":[[9.2,3.54]],"id":47208569}],"con":true,"img":false}]}
{"op":"mcm","clk":"11449678954","pt":1717313423395,"mc":[{"id":"1.229554900","rc":[{"atl":[[9.6,3.4]],"id":70003368},{"atl":[[3.45,9.46]],"id":67532289}],"con":true,"img":false}]}
{"op":"mcm","clk":"11449690359","pt":1717313566287,"mc":[{"id":"1.229554900","rc":[{"atl":[[9.2,2.09]],"id":47208569}],"con":true,"img":false}]}
{"op":"mcm","clk":"11449691868","pt":1717313585010,"mc":[{"id":"1.229554900","rc":[{"atl":[[3.45,5.59]],"id":67532289}],"con":true,"img":false}]}
{"op":"mcm","clk":"11449692397","pt":1717313591903,"mc":[{"id":"1.229554900","rc":[{"atl":[[9.6,2.01]],"id":70003368}],"con":true,"img":false}]}
{"op":"mcm","clk":"11449693604","pt":1717313606848,"mc":[{"id":"1.229554900","rc":[{"atl":[[1000,2.35]],"id":47208569},{"atl":[[3.45,9.46]],"id":67532289}],"con":true,"img":false}]}
{"op":"mcm","clk":"11449693617","pt":1717313607005,"mc":[{"id":"1.229554900","rc":[{"atl":[[1000,3.2]],"id":70003368}],"con":true,"img":false}]}
{"op":"mcm","clk":"11449693625","pt":1717313607107,"mc":[{"id":"1.229554900","rc":[{"atl":[[1000,1.45]],"id":47208569}],"con":true,"img":false}]}
{"op":"mcm","clk":"11449693646","pt":1717313607317,"mc":[{"id":"1.229554900","rc":[{"atl":[[1000,0]],"id":47208569}],"con":true,"img":false}]}
{"op":"mcm","clk":"11449693655","pt":1717313607418,"mc":[{"id":"1.229554900","rc":[{"atl":[[1000,2.24]],"id":70003368},{"atl":[[9.2,3.54]],"id":47208569}],"con":true,"img":false}]}
{"op":"mcm","clk":"11449693683","pt":1717313607728,"mc":[{"id":"1.229554900","rc":[{"atl":[[1000,0.85]],"id":70003368}],"con":true,"img":false}]}
{"op":"mcm","clk":"11449693693","pt":1717313607835,"mc":[{"id":"1.229554900","rc":[{"atl":[[9.6,3.4]],"id":70003368}],"con":true,"img":false}]}
{"op":"mcm","clk":"11449693705","pt":1717313607942,"mc":[{"id":"1.229554900","rc":[{"atl":[[9.2,1.45]],"id":47208569}],"con":true,"img":false}]}
{"op":"mcm","clk":"11449697120","pt":1717313648801,"mc":[{"id":"1.229554900","rc":[{"atl":[[3.45,3.87]],"id":67532289}],"con":true,"img":false}]}
{"op":"mcm","clk":"11449700235","pt":1717313686877,"mc":[{"id":"1.229554900","rc":[{"atl":[[9.6,1.38]],"id":70003368}],"con":true,"img":false}]}
{"op":"mcm","clk":"11449703509","pt":1717313730628,"mc":[{"id":"1.229554900","rc":[{"atl":[[9.2,3.54]],"id":47208569}],"con":true,"img":false}]}
{"op":"mcm","clk":"11449703524","pt":1717313730833,"mc":[{"id":"1.229554900","rc":[{"atl":[[9.6,3.4]],"id":70003368}],"con":true,"img":false}]}
{"op":"mcm","clk":"11449703529","pt":1717313730936,"mc":[{"id":"1.229554900","rc":[{"atl":[[3.45,9.46]],"id":67532289}],"con":true,"img":false}]}
{"op":"mcm","clk":"11449705328","pt":1717313753033,"mc":[{"id":"1.229554900","rc":[{"atb":[[2.88,62.61],[2.9,29.84]],"id":70003368},{"atl":[[9.2,6.84],[10,13.07]],"id":70003368},{"atb":[[2.82,96.51]],"id":47208569},{"atl":[[9.8,13.58],[8.8,7.19]],"id":47208569},{"atb":[[17.5,3.4],[15,7.82]],"id":49183855},{"atl":[[180,0.31],[250,2.61]],"id":49183855},{"atb":[[17,7.84],[22,7.64]],"id":63027102},{"atl":[[260,0.21],[310,2.61]],"id":63027102},{"atb":[[1.59,95.1],[1.42,267.81]],"id":67532289},{"atl":[[3.35,23.87],[3.65,42.44]],"id":67532289}],"con":true,"img":false}]}
{"op":"mcm","clk":"11449708875","pt":1717313794388,"mc":[{"id":"1.229554900","rc":[{"spn":6.08,"spf":"NaN","id":70003368},{"atl":[[9.2,2.09]],"id":47208569},{"spn":5.85,"spf":"NaN","id":47208569},{"spn":99.75,"spf":"NaN","id":49183855},{"spn":141.0,"spf":"NaN","id":63027102},{"spn":2.51,"spf":"NaN","id":67532289}],"con":true,"img":false}]}
{"op":"mcm","clk":"11449710098","pt":1717313808325,"mc":[{"id":"1.229554900","rc":[{"atl":[[3.45,5.59]],"id":67532289}],"con":true,"img":false}]}
{"op":"mcm","clk":"11449710439","pt":1717313812448,"mc":[{"id":"1.229554900","rc":[{"atb":[[2.9,0]],"id":70003368},{"atb":[[2.82,65.68]],"id":47208569}],"con":true,"img":false}]}
{"op":"mcm","clk":"11449710450","pt":1717313812551,"mc":[{"id":"1.229554900","rc":[{"atb":[[2.98,29.84]],"id":70003368},{"atb":[[2.92,30.83]],"id":47208569}],"con":true,"img":false}]}
{"op":"mcm","clk":"11449711544","pt":1717313824536,"mc":[{"id":"1.229554900","rc":[{"atl":[[9.6,2.01]],"id":70003368}],"con":true,"img":false}]}
{"op":"mcm","clk":"11449712746","pt":1717313838041,"mc":[{"id":"1.229554900","rc":[{"atb":[[2.86,0],[2.96,0],[2.76,0]],"id":70003368},{"atl":[[10.5,0],[15.5,0]],"id":70003368},{"atb":[[2.8,0],[2.9,0],[2.7,0]],"id":47208569},{"atl":[[10,0],[15,0]],"id":47208569},{"atb":[[16,0],[18.5,0],[22,2.67]],"id":63027102},{"atl":[[320,0],[420,0]],"id":63027102},{"atb":[[1.63,0],[1.58,0],[1.68,0]],"id":67532289},{"atl":[[3.7,0],[4.4,0]],"id":67532289}],"con":true,"img":false}]}
{"op":"mcm","clk":"11449712765","pt":1717313838251,"mc":[{"id":"1.229554900","rc":[{"atl":[[1000,2.35]],"id":47208569},{"atl":[[3.15,4.23]],"id":67532289}],"con":true,"img":false}]}
{"op":"mcm","clk":"11449712776","pt":1717313838355,"mc":[{"id":"1.229554900","rc":[{"atl":[[1000,3.2]],"id":70003368}],"con":true,"img":false}]}
{"op":"mcm","clk":"11449712793","pt":1717313838562,"mc":[{"id":"1.229554900","rc":[{"atl":[[1000,2.43]],"id":70003368},{"atl":[[1000,1.66]],"id":47208569}],"con":true,"img":false}]}
{"op":"mcm","clk":"11449712825","pt":1717313838876,"mc":[{"id":"1.229554900","rc":[{"atl":[[1000,0.85]],"id":70003368}],"con":true,"img":false}]}
{"op":"mcm","clk":"11449712838","pt":1717313838979,"mc":[{"id":"1.229554900","rc":[{"atl":[[8.4,1.58]],"id":70003368}],"con":true,"img":false}]}
{"op":"mcm","clk":"11449712860","pt":1717313839134,"mc":[{"id":"1.229554900","rc":[{"atl":[[1000,0]],"id":47208569}],"con":true,"img":false}]}
{"op":"mcm","clk":"11449712872","pt":1717313839240,"mc":[{"id":"1.229554900","rc":[{"atl":[[8,1.66]],"id":47208569}],"con":true,"img":false}]}
{"op":"mcm","clk":"11449713035","pt":1717313841063,"mc":[{"id":"1.229554900","rc":[{"atb":[[2.88,0],[2.5,78.47],[2.98,0]],"id":70003368},{"atl":[[10,0],[12.5,10.23]],"id":70003368},{"atb":[[2.82,0],[2.92,0],[2.44,83.01]],"id":47208569},{"atl":[[12,10.86],[9.8,0]],"id":47208569},{"atl":[[310,0]],"id":63027102},{"atb":[[1.59,0]],"id":67532289},{"atl":[[4.4,33.08],[3.65,0]],"id":67532289}],"con":true,"img":false}]}
{"op":"mcm","clk":"11449713044","pt":1717313841168,"mc":[{"id":"1.229554900","rc":[{"atb":[[2.9,29.84]],"id":70003368},{"atb":[[2.82,30.83]],"id":47208569},{"atl":[[370,2.61]],"id":63027102},{"atb":[[1.53,95.1]],"id":67532289}],"con":true,"img":false}]}
{"op":"mcm","clk":"11449714402","pt":1717313856485,"mc":[{"id":"1.229554900","rc":[{"atb":[[2.86,112.39],[2.96,53.33],[2.76,118.78]],"id":70003368},{"atl":[[10.5,14.66],[15.5,14.41]],"id":70003368},{"spn":5.68,"spf":"NaN","id":70003368},{"atb":[[2.8,116.14],[2.9,55.01],[2.7,122.97]],"id":47208569},{"atl":[[10,15.48],[15,14.93]],"id":47208569},{"spn":5.45,"spf":"NaN","id":47208569},{"atb":[[16,13.93],[18.5,11.94],[22,7.64]],"id":63027102},{"atl":[[320,0.43],[420,0.49]],"id":63027102},{"atb":[[1.63,331.84],[1.58,360.45],[1.68,153.71]],"id":67532289},{"atl":[[3.7,51.62],[4.4,94.57]],"id":67532289},{"spn":2.41,"spf":"NaN","id":67532289}],"con":true,"img":false}]}
{"op":"mcm","clk":"11449720418","pt":1717313925954,"mc":[{"id":"1.229554900","rc":[{"atb":[[2.88,62.61],[2.9,0],[2.5,0]],"id":70003368},{"atl":[[10,13.07],[12.5,0]],"id":70003368},{"atb":[[2.82,65.68],[2.44,0]],"id":47208569},{"atl":[[12,0],[9.8,13.58]],"id":47208569},{"atb":[[17,0]],"id":63027102},{"atl":[[370,0]],"id":63027102},{"atb":[[1.53,0]],"id":67532289},{"atl":[[4.4,61.48],[3.65,42.44]],"id":67532289}],"con":true,"img":false}]}
{"op":"mcm","clk":"11449720429","pt":1717313926003,"mc":[{"id":"1.229554900","rc":[{"atb":[[2.98,29.84]],"id":70003368},{"atb":[[2.92,30.83]],"id":47208569},{"atb":[[19,7.84]],"id":63027102},{"atl":[[310,2.61]],"id":63027102},{"atb":[[1.59,95.1]],"id":67532289}],"con":true,"img":false}]}
{"op":"mcm","clk":"11449722717","pt":1717313950016,"mc":[{"id":"1.229554900","rc":[{"atl":[[9.2,0]],"id":47208569}],"con":true,"img":false}]}
{"op":"mcm","clk":"11449725890","pt":1717313983878,"mc":[{"id":"1.229554900","rc":[{"atl":[[3.45,0]],"id":67532289}],"con":true,"img":false}]}
{"op":"mcm","clk":"11449729369","pt":1717314019812,"mc":[{"id":"1.229554900","rc":[{"atl":[[9.6,0]],"id":70003368},{"spn":5.69,"spf":"NaN","id":70003368},{"spn":5.46,"spf":"NaN","id":47208569}],"con":true,"img":false}]}
{"op":"mcm","clk":"11449730391","pt":1717314029607,"mc":[{"id":"1.229554900","rc":[{"atl":[[8,0]],"id":47208569}],"con":true,"img":false}]}
{"op":"mcm","clk":"11449731917","pt":1717314044637,"mc":[{"id":"1.229554900","rc":[{"atl":[[3.15,0]],"id":67532289}],"con":true,"img":false}]}
{"op":"mcm","clk":"11449732743","pt":1717314052933,"mc":[{"id":"1.229554900","rc":[{"atl":[[8,2.4]],"id":47208569}],"con":true,"img":false}]}
{"op":"mcm","clk":"11449732765","pt":1717314053137,"mc":[{"id":"1.229554900","rc":[{"atl":[[3.15,6.12]],"id":67532289}],"con":true,"img":false}]}
{"op":"mcm","clk":"11449732774","pt":1717314053237,"mc":[{"id":"1.229554900","rc":[{"atl":[[8.4,3.87]],"id":70003368}],"con":true,"img":false}]}
{"op":"mcm","clk":"11449733385","pt":1717314059751,"mc":[{"id":"1.229554900","rc":[{"atl":[[8.4,2.29]],"id":70003368}],"con":true,"img":false}]}
{"op":"mcm","clk":"11449734757","pt":1717314074668,"mc":[{"id":"1.229554900","rc":[{"atl":[[1000,3.2]],"id":70003368},{"atl":[[1000,2.35]],"id":47208569},{"atl":[[3.15,10.36]],"id":67532289}],"con":true,"img":false}]}
{"op":"mcm","clk":"11449734791","pt":1717314074981,"mc":[{"id":"1.229554900","rc":[{"atl":[[1000,2.43]],"id":70003368},{"atl":[[1000,1.66]],"id":47208569}],"con":true,"img":false}]}
{"op":"mcm","clk":"11449734818","pt":1717314075189,"mc":[{"id":"1.229554900","rc":[{"atl":[[1000,0.85]],"id":70003368}],"con":true,"img":false}]}
{"op":"mcm","clk":"11449734830","pt":1717314075285,"mc":[{"id":"1.229554900","rc":[{"atl":[[8.4,3.87]],"id":70003368}],"con":true,"img":false}]}
{"op":"mcm","clk":"11449734851","pt":1717314075491,"mc":[{"id":"1.229554900","rc":[{"atl":[[1000,0]],"id":47208569}],"con":true,"img":false}]}
{"op":"mcm","clk":"11449734861","pt":1717314075595,"mc":[{"id":"1.229554900","rc":[{"atl":[[8,4.06]],"id":47208569}],"con":true,"img":false}]}
{"op":"mcm","clk":"11449736707","pt":1717314096394,"mc":[{"id":"1.229554900","rc":[{"atb":[[17,0],[19.5,0],[14.5,0]],"id":49183855},{"atl":[[300,0],[400,0]],"id":49183855},{"spn":98.75,"spf":"NaN","id":49183855}],"con":true,"img":false}]}
{"op":"mcm","clk":"11449738237","pt":1717314113455,"mc":[{"id":"1.229554900","rc":[{"atb":[[17,13.06],[19.5,5.65],[14.5,15.48]],"id":49183855},{"atl":[[300,0.46],[400,0.52]],"id":49183855}],"con":true,"img":false}]}
{"op":"mcm","clk":"11449740327","pt":1717314135559,"mc":[{"id":"1.229554900","rc":[{"atl":[[1000,1.85]],"id":70003368},{"atl":[[1000,1]],"id":47208569},{"atl":[[1000,1.85]],"id":49183855},{"atl":[[1000,1]],"id":63027102},{"atl":[[1000,1.85]],"id":67532289}],"con":true,"img":false}]}
{"op":"mcm","clk":"11449752084","pt":1717314264845,"mc":[{"id":"1.229554900","rc":[{"atl":[[8,2.4]],"id":47208569},{"spn":99.75,"spf":"NaN","id":49183855}],"con":true,"img":false}]}
{"op":"mcm","clk":"11449752825","pt":1717314273537,"mc":[{"id":"1.229554900","rc":[{"atl":[[8,0]],"id":47208569}],"con":true,"img":false}]}
{"op":"mcm","clk":"11449753322","pt":1717314280035,"mc":[{"id":"1.229554900","rc":[{"atl":[[3.15,6.12]],"id":67532289}],"con":true,"img":false}]}
{"op":"mcm","clk":"11449754515","pt":1717314294775,"mc":[{"id":"1.229554900","rc":[{"atl":[[8.4,2.29]],"id":70003368}],"con":true,"img":false}]}
{"op":"mcm","clk":"11449755850","pt":1717314309966,"mc":[{"id":"1.229554900","rc":[{"atl":[[1000,3.35]],"id":47208569},{"atl":[[3.15,10.36]],"id":67532289}],"con":true,"img":false}]}
{"op":"mcm","clk":"11449755867","pt":1717314310178,"mc":[{"id":"1.229554900","rc":[{"atl":[[1000,4.2]],"id":70003368},{"atl":[[1000,2.66]],"id":47208569}],"con":true,"img":false}]}
{"op":"mcm","clk":"11449755886","pt":1717314310391,"mc":[{"id":"1.229554900","rc":[{"atl":[[1000,1]],"id":47208569}],"con":true,"img":false}]}
{"op":"mcm","clk":"11449755895","pt":1717314310487,"mc":[{"id":"1.229554900","rc":[{"atl":[[8,1.66]],"id":47208569}],"con":true,"img":false}]}
{"op":"mcm","clk":"11449755908","pt":1717314310695,"mc":[{"id":"1.229554900","rc":[{"atl":[[1000,3.43]],"id":70003368}],"con":true,"img":false}]}
{"op":"mcm","clk":"11449755933","pt":1717314310904,"mc":[{"id":"1.229554900","rc":[{"atl":[[1000,1.85]],"id":70003368}],"con":true,"img":false}]}
{"op":"mcm","clk":"11449755941","pt":1717314311001,"mc":[{"id":"1.229554900","rc":[{"atl":[[8.4,3.87]],"id":70003368}],"con":true,"img":false}]}
{"op":"mcm","clk":"11449756038","pt":1717314312198,"mc":[{"id":"1.229554900","rc":[{"atl":[[3.15,4.23]],"id":67532289}],"con":true,"img":false}]}
{"op":"mcm","clk":"11449759228","pt":1717314349761,"mc":[{"id":"1.229554900","rc":[{"atl":[[8.4,1.58]],"id":70003368}],"con":true,"img":false}]}
{"op":"mcm","clk":"11449762695","pt":1717314386802,"mc":[{"id":"1.229554900","rc":[{"atl":[[8,4.06]],"id":47208569}],"con":true,"img":false}]}
{"op":"mcm","clk":"11449762724","pt":1717314387105,"mc":[{"id":"1.229554900","rc":[{"atl":[[8.4,3.87]],"id":70003368}],"con":true,"img":false}]}
{"op":"mcm","clk":"11449762751","pt":1717314387420,"mc":[{"id":"1.229554900","rc":[{"atl":[[3.15,10.36]],"id":67532289}],"con":true,"img":false}]}
{"op":"mcm","clk":"11449772385","pt":1717314496037,"mc":[{"id":"1.229554900","rc":[{"atl":[[8,2.4]],"id":47208569}],"con":true,"img":false}]}
{"op":"mcm","clk":"11449773793","pt":1717314511043,"mc":[{"id":"1.229554900","rc":[{"atl":[[3.15,6.12]],"id":67532289}],"con":true,"img":false}]}
{"op":"mcm","clk":"11449775239","pt":1717314526254,"mc":[{"id":"1.229554900","rc":[{"atl":[[8.4,2.29]],"id":70003368}],"con":true,"img":false}]}
{"op":"mcm","clk":"11449776617","pt":1717314541194,"mc":[{"id":"1.229554900","rc":[{"atl":[[1000,3.35]],"id":47208569},{"atl":[[3.15,10.36]],"id":67532289}],"con":true,"img":false}]}
{"op":"mcm","clk":"11449776639","pt":1717314541397,"mc":[{"id":"1.229554900","rc":[{"atl":[[1000,4.2]],"id":70003368}],"con":true,"img":false}]}
{"op":"mcm","clk":"11449776653","pt":1717314541503,"mc":[{"id":"1.229554900","rc":[{"atl":[[1000,2.66]],"id":47208569}],"con":true,"img":false}]}
{"op":"mcm","clk":"11449776660","pt":1717314541606,"mc":[{"id":"1.229554900","rc":[{"atl":[[1000,3.43]],"id":70003368}],"con":true,"img":false}]}
{"op":"mcm","clk":"11449776669","pt":1717314541666,"mc":[{"id":"1.229554900","rc":[{"atl":[[1000,1]],"id":47208569}],"con":true,"img":false}]}
{"op":"mcm","clk":"11449776683","pt":1717314541768,"mc":[{"id":"1.229554900","rc":[{"atl":[[8,4.06]],"id":47208569}],"con":true,"img":false}]}
{"op":"mcm","clk":"11449776705","pt":1717314542072,"mc":[{"id":"1.229554900","rc":[{"atl":[[1000,1.85]],"id":70003368}],"con":true,"img":false}]}
{"op":"mcm","clk":"11449776715","pt":1717314542177,"mc":[{"id":"1.229554900","rc":[{"atl":[[8.4,3.87]],"id":70003368}],"con":true,"img":false}]}
{"op":"mcm","clk":"11449782137","pt":1717314605595,"mc":[{"id":"1.229554900","rc":[{"atl":[[8,1.66]],"id":47208569}],"con":true,"img":false}]}
{"op":"mcm","clk":"11449784596","pt":1717314637061,"mc":[{"id":"1.229554900","rc":[{"atl":[[3.15,4.23]],"id":67532289}],"con":true,"img":false}]}
{"op":"mcm","clk":"11449787047","pt":1717314666632,"mc":[{"id":"1.229554900","rc":[{"atb":[[2.86,0],[2.96,0],[2.76,0]],"id":70003368},{"atl":[[10.5,0],[15.5,0]],"id":70003368},{"atb":[[2.8,0],[2.9,0],[2.7,0]],"id":47208569},{"atl":[[10,0],[15,0]],"id":47208569},{"atb":[[16,0],[18.5,0],[22,2.67]],"id":63027102},{"atl":[[320,0],[420,0]],"id":63027102},{"atb":[[1.63,0],[1.58,0],[1.68,0]],"id":67532289},{"atl":[[3.7,0],[4.4,0]],"id":67532289},{"spn":2.37,"spf":"NaN","id":67532289}],"con":true,"img":false}]}
{"op":"mcm","clk":"11449787713","pt":1717314674198,"mc":[{"id":"1.229554900","rc":[{"atl":[[8.4,1.58]],"id":70003368}],"con":true,"img":false}]}
{"op":"mcm","clk":"11449787848","pt":1717314675693,"mc":[{"id":"1.229554900","rc":[{"atb":[[2.88,0],[2.5,78.47],[2.98,0]],"id":70003368},{"atl":[[10,0],[12.5,10.23]],"id":70003368},{"atb":[[2.82,0],[2.92,0],[2.44,83.01]],"id":47208569},{"atl":[[12,10.86],[9.8,0]],"id":47208569},{"atl":[[310,0]],"id":63027102},{"atb":[[1.59,0]],"id":67532289},{"atl":[[4.4,33.08],[3.65,0]],"id":67532289}],"con":true,"img":false}]}
{"op":"mcm","clk":"11449787854","pt":1717314675792,"mc":[{"id":"1.229554900","rc":[{"atb":[[2.9,29.84]],"id":70003368},{"atb":[[2.82,30.83]],"id":47208569},{"atl":[[370,2.61]],"id":63027102},{"atb":[[1.53,95.1]],"id":67532289}],"con":true,"img":false}]}
{"op":"mcm","clk":"11449789019","pt":1717314687421,"mc":[{"id":"1.229554900","rc":[{"atb":[[2.86,112.39],[2.96,53.33],[2.76,118.78]],"id":70003368},{"atl":[[10.5,14.66],[15.5,14.41]],"id":70003368},{"atb":[[2.8,116.14],[2.9,55.01],[2.7,122.97]],"id":47208569},{"atl":[[10,15.48],[15,14.93]],"id":47208569},{"atb":[[16,13.93],[18.5,11.94],[22,7.64]],"id":63027102},{"atl":[[320,0.43],[420,0.49]],"id":63027102},{"atb":[[1.63,331.84],[1.58,360.45],[1.68,153.71]],"id":67532289},{"atl":[[3.7,51.62],[4.4,94.57]],"id":67532289}],"con":true,"img":false}]}
{"op":"mcm","clk":"11449790675","pt":1717314705753,"mc":[{"id":"1.229554900","rc":[{"atl":[[8,4.06]],"id":47208569}],"con":true,"img":false}]}
{"op":"mcm","clk":"11449790695","pt":1717314705958,"mc":[{"id":"1.229554900","rc":[{"atl":[[3.15,10.36]],"id":67532289}],"con":true,"img":false}]}
{"op":"mcm","clk":"11449790705","pt":1717314706057,"mc":[{"id":"1.229554900","rc":[{"atl":[[8.4,3.87]],"id":70003368}],"con":true,"img":false}]}
{"op":"mcm","clk":"11449792859","pt":1717314731524,"mc":[{"id":"1.229554900","rc":[{"spn":5.68,"spf":"NaN","id":70003368},{"atl":[[8,2.4]],"id":47208569},{"spn":5.45,"spf":"NaN","id":47208569},{"spn":2.41,"spf":"NaN","id":67532289}],"con":true,"img":false}]}
{"op":"mcm","clk":"11449793828","pt":1717314742803,"mc":[{"id":"1.229554900","rc":[{"atb":[[2.88,62.61],[2.9,0],[2.5,0]],"id":70003368},{"atl":[[10,13.07],[12.5,0]],"id":70003368},{"atb":[[2.82,65.68],[2.44,0]],"id":47208569},{"atl":[[12,0],[9.8,13.58]],"id":47208569},{"atl":[[370,0]],"id":63027102},{"atb":[[1.53,0]],"id":67532289},{"atl":[[4.4,61.48],[3.65,42.44]],"id":67532289}],"con":true,"img":false}]}
{"op":"mcm","clk":"11449793838","pt":1717314742910,"mc":[{"id":"1.229554900","rc":[{"atb":[[2.98,29.84]],"id":70003368},{"atb":[[2.92,30.83]],"id":47208569},{"atl":[[310,2.61]],"id":63027102},{"atb":[[1.59,95.1]],"id":67532289}],"con":true,"img":false}]}
{"op":"mcm","clk":"11449794145","pt":1717314746618,"mc":[{"id":"1.229554900","rc":[{"atl":[[3.15,6.12]],"id":67532289}],"con":true,"img":false}]}
{"op":"mcm","clk":"11449795332","pt":1717314761729,"mc":[{"id":"1.229554900","rc":[{"atl":[[8.4,2.29]],"id":70003368}],"con":true,"img":false}]}
{"op":"mcm","clk":"11449796671","pt":1717314776690,"mc":[{"id":"1.229554900","rc":[{"atl":[[1000,3.35]],"id":47208569}],"con":true,"img":false}]}
{"op":"mcm","clk":"11449796685","pt":1717314776851,"mc":[{"id":"1.229554900","rc":[{"atl":[[3.15,10.36]],"id":67532289}],"con":true,"img":false}]}
{"op":"mcm","clk":"11449796694","pt":1717314776952,"mc":[{"id":"1.229554900","rc":[{"atl":[[1000,4.2]],"id":70003368}],"con":true,"img":false}]}
{"op":"mcm","clk":"11449796703","pt":1717314777055,"mc":[{"id":"1.229554900","rc":[{"atl":[[1000,2.66]],"id":47208569}],"con":true,"img":false}]}
{"op":"mcm","clk":"11449796714","pt":1717314777183,"mc":[{"id":"1.229554900","rc":[{"atl":[[1000,3.43]],"id":70003368}],"con":true,"img":false}]}
{"op":"mcm","clk":"11449796726","pt":1717314777264,"mc":[{"id":"1.229554900","rc":[{"atl":[[1000,1]],"id":47208569}],"con":true,"img":false}]}
{"op":"mcm","clk":"11449796736","pt":1717314777367,"mc":[{"id":"1.229554900","rc":[{"atl":[[8,4.06]],"id":47208569}],"con":true,"img":false}]}
{"op":"mcm","clk":"11449796762","pt":1717314777675,"mc":[{"id":"1.229554900","rc":[{"atl":[[1000,1.85]],"id":70003368}],"con":true,"img":false}]}
{"op":"mcm","clk":"11449796770","pt":1717314777776,"mc":[{"id":"1.229554900","rc":[{"atl":[[8.4,3.87]],"id":70003368}],"con":true,"img":false}]}
{"op":"mcm","clk":"11449806194","pt":1717314889657,"mc":[{"id":"1.229554900","rc":[{"spn":5.69,"spf":"NaN","id":70003368},{"atl":[[8,1.66]],"id":47208569},{"spn":5.46,"spf":"NaN","id":47208569}],"con":true,"img":false}]}
{"op":"mcm","clk":"11449809541","pt":1717314926497,"mc":[{"id":"1.229554900","rc":[{"atl":[[3.15,4.23]],"id":67532289}],"con":true,"img":false}]}
{"op":"mcm","clk":"11449812724","pt":1717314961951,"mc":[{"id":"1.229554900","rc":[{"atl":[[8.4,1.58]],"id":70003368}],"con":true,"img":false}]}
{"op":"mcm","clk":"11449812859","pt":1717314963553,"mc":[{"id":"1.229554900","rc":[{"atl":[[8,0]],"id":47208569}],"con":true,"img":false}]}
{"op":"mcm","clk":"11449814180","pt":1717314978952,"mc":[{"id":"1.229554900","rc":[{"atl":[[3.15,0]],"id":67532289}],"con":true,"img":false}]}
{"op":"mcm","clk":"11449815408","pt":1717314992372,"mc":[{"id":"1.229554900","rc":[{"atb":[[17,0],[19.5,0],[14.5,0]],"id":49183855},{"atl":[[300,0],[400,0]],"id":49183855}],"con":true,"img":false}]}
{"op":"mcm","clk":"11449815557","pt":1717314993887,"mc":[{"id":"1.229554900","rc":[{"atl":[[8.4,0]],"id":70003368}],"con":true,"img":false}]}
{"op":"mcm","clk":"11449815816","pt":1717314996682,"mc":[{"id":"1.229554900","rc":[{"atb":[[17,13.06],[19.5,5.65],[14.5,15.48]],"id":49183855},{"atl":[[300,0.46],[400,0.52]],"id":49183855}],"con":true,"img":false}]}
{"op":"mcm","clk":"11449815979","pt":1717314998476,"mc":[{"id":"1.229554900","rc":[{"atl":[[8,2.4]],"id":47208569}],"con":true,"img":false}]}
{"op":"mcm","clk":"11449816008","pt":1717314998785,"mc":[{"id":"1.229554900","rc":[{"atl":[[8.4,2.29]],"id":70003368}],"con":true,"img":false}]}
{"op":"mcm","clk":"11449816032","pt":1717314999095,"mc":[{"id":"1.229554900","rc":[{"atl":[[3.15,6.12]],"id":67532289}],"con":true,"img":false}]}
{"op":"mcm","clk":"11449816997","pt":1717315009090,"mc":[{"id":"1.229554900","rc":[{"atl":[[1000,4.2]],"id":70003368},{"atl":[[1000,3.35]],"id":47208569},{"atl":[[3.15,10.36]],"id":67532289}],"con":true,"img":false}]}
{"op":"mcm","clk":"11449817016","pt":1717315009292,"mc":[{"id":"1.229554900","rc":[{"atl":[[1000,3.43]],"id":70003368},{"atl":[[1000,2.66]],"id":47208569}],"con":true,"img":false}]}
{"op":"mcm","clk":"11449817037","pt":1717315009504,"mc":[{"id":"1.229554900","rc":[{"atl":[[1000,1.85]],"id":70003368}],"con":true,"img":false}]}
{"op":"mcm","clk":"11449817046","pt":1717315009604,"mc":[{"id":"1.229554900","rc":[{"atl":[[8.4,3.87]],"id":70003368}],"con":true,"img":false}]}
{"op":"mcm","clk":"11449817061","pt":1717315009810,"mc":[{"id":"1.229554900","rc":[{"atl":[[1000,1]],"id":47208569}],"con":true,"img":false}]}
{"op":"mcm","clk":"11449817069","pt":1717315009911,"mc":[{"id":"1.229554900","rc":[{"atl":[[8,4.06]],"id":47208569}],"con":true,"img":false}]}
{"op":"mcm","clk":"11449826235","pt":1717315107750,"mc":[{"id":"1.229554900","rc":[{"atb":[[1.01,123.56]],"id":70003368},{"atl":[[960,0.93]],"id":70003368},{"atb":[[1.01,151.68]],"id":47208569},{"atl":[[990,2.05]],"id":47208569},{"atb":[[1.01,109.92]],"id":49183855},{"atl":[[970,1.63]],"id":49183855},{"atb":[[1.02,105.66]],"id":63027102},{"atl":[[960,0.86]],"id":63027102},{"atb":[[1.03,118.27]],"id":67532289},{"atl":[[960,0.9]],"id":67532289}],"con":true,"img":false}]}
{"op":"mcm","clk":"11449836016","pt":1717315140186,"mc":[{"id":"1.229554900","rc":[{"atb":[[1.97,103.09]],"id":70003368},{"atl":[[11.5,9.52]],"id":70003368},{"atb":[[2.4,71.43]],"id":47208569},{"atl":[[12.5,8.7]],"id":47208569},{"atb":[[1.62,57.86]],"id":49183855},{"atl":[[350,2]],"id":49183855},{"atb":[[3.6,38.46]],"id":63027102},{"atl":[[700,2]],"id":63027102},{"atb":[[1.36,277.78]],"id":67532289},{"atl":[[11.5,9.52]],"id":67532289}],"con":true,"img":false}]}
{"op":"mcm","clk":"11449839014","pt":1717315172428,"mc":[{"id":"1.229554900","rc":[{"atb":[[6.2,9.62]],"id":49183855},{"atb":[[6.2,9.62],[4.1,16.13]],"id":63027102}],"con":true,"img":false}]}
{"op":"mcm","clk":"11449839024","pt":1717315172529,"mc":[{"id":"1.229554900","rc":[{"atb":[[4.1,16.13],[3.05,24.39]],"id":49183855},{"atb":[[3.05,24.39]],"id":63027102}],"con":true,"img":false}]}
{"op":"mcm","clk":"11449839039","pt":1717315172635,"mc":[{"id":"1.229554900","rc":[{"atl":[[34,10]],"id":70003368},{"atl":[[34,10]],"id":47208569},{"atb":[[2.12,44.64],[1.51,98.04]],"id":49183855},{"atb":[[2.12,44.64],[1.51,98.04]],"id":63027102},{"atl":[[16,10],[34,10]],"id":67532289}],"con":true,"img":false}]}
{"op":"mcm","clk":"11449841520","pt":1717315198286,"mc":[{"id":"1.229554900","rc":[{"atl":[[8,2.4]],"id":47208569}],"con":true,"img":false}]}
{"op":"mcm","clk":"11449843220","pt":1717315213564,"mc":[{"id":"1.229554900","rc":[{"atl":[[3.15,6.12]],"id":67532289}],"con":true,"img":false}]}
{"op":"mcm","clk":"11449843552","pt":1717315216661,"mc":[{"id":"1.229554900","rc":[{"atb":[[15,0]],"id":49183855}],"con":true,"img":false}]}
{"op":"mcm","clk":"11449843563","pt":1717315216764,"mc":[{"id":"1.229554900","rc":[{"atb":[[17.5,11.22]],"id":49183855}],"con":true,"img":false}]}
{"op":"mcm","clk":"11449844092","pt":1717315221998,"mc":[{"id":"1.229554900","rc":[{"atl":[[8,0]],"id":47208569}],"con":true,"img":false}]}
{"op":"mcm","clk":"11449844915","pt":1717315230076,"mc":[{"id":"1.229554900","rc":[{"atl":[[8.4,2.29]],"id":70003368}],"con":true,"img":false}]}
{"op":"mcm","clk":"11449846363","pt":1717315246431,"mc":[{"id":"1.229554900","rc":[{"atl":[[1000,4.2]],"id":70003368},{"atl":[[1000,3.35]],"id":47208569},{"spn":5.86,"spf":"NaN","id":47208569},{"atl":[[3.15,10.36]],"id":67532289}],"con":true,"img":false}]}
{"op":"mcm","clk":"11449846385","pt":1717315246635,"mc":[{"id":"1.229554900","rc":[{"atl":[[1000,2.66]],"id":47208569}],"con":true,"img":false}]}
{"op":"mcm","clk":"11449846422","pt":1717315246902,"mc":[{"id":"1.229554900","rc":[{"atl":[[1000,3.43]],"id":70003368},{"atl":[[1000,1]],"id":47208569}],"con":true,"img":false}]}
{"op":"mcm","clk":"11449846431","pt":1717315247004,"mc":[{"id":"1.229554900","rc":[{"atl":[[8,1.66]],"id":47208569}],"con":true,"img":false}]}
{"op":"mcm","clk":"11449846456","pt":1717315247219,"mc":[{"id":"1.229554900","rc":[{"atl":[[1000,1.85]],"id":70003368}],"con":true,"img":false}]}
{"op":"mcm","clk":"11449846468","pt":1717315247321,"mc":[{"id":"1.229554900","rc":[{"atl":[[8.4,3.87]],"id":70003368}],"con":true,"img":false}]}
{"op":"mcm","clk":"11449849400","pt":1717315277355,"mc":[{"id":"1.229554900","rc":[{"atl":[[3.15,4.23]],"id":67532289}],"con":true,"img":false}]}
{"op":"mcm","clk":"11449851204","pt":1717315295685,"mc":[{"id":"1.229554900","rc":[{"atb":[[2.86,0],[2.96,0],[2.76,0]],"id":70003368},{"atl":[[10.5,0],[15.5,0]],"id":70003368},{"atb":[[2.8,0],[2.9,0],[2.7,0]],"id":47208569},{"atl":[[10,0],[15,0]],"id":47208569},{"atb":[[16,0],[18.5,0],[22,2.67]],"id":63027102},{"atl":[[320,0],[420,0]],"id":63027102},{"atb":[[1.63,0],[1.58,0],[1.68,0]],"id":67532289},{"atl":[[3.7,0],[4.4,0]],"id":67532289}],"con":true,"img":false}]}
{"op":"mcm","clk":"11449852969","pt":1717315314199,"mc":[{"id":"1.229554900","rc":[{"atb":[[2.88,0],[2.5,78.47],[2.98,0]],"id":70003368},{"atl":[[10,0]],"id":70003368},{"spn":5.45,"spf":"NaN","id":70003368},{"atb":[[2.82,0],[2.92,0],[2.44,84.18]],"id":47208569},{"atl":[[12,10.86],[9.8,0]],"id":47208569},{"spn":5.22,"spf":"NaN","id":47208569},{"atl":[[310,0]],"id":63027102},{"atb":[[1.59,0]],"id":67532289},{"atl":[[4.4,33.08],[3.65,0]],"id":67532289},{"spn":2.33,"spf":"NaN","id":67532289}],"con":true,"img":false}]}
{"op":"mcm","clk":"11449852980","pt":1717315314301,"mc":[{"id":"1.229554900","rc":[{"atb":[[2.9,29.84]],"id":70003368},{"atl":[[11,13.07]],"id":70003368},{"atb":[[2.82,30.83]],"id":47208569},{"atl":[[380,2.61],[960,2.86]],"id":63027102},{"atb":[[1.53,95.1]],"id":67532289}],"con":true,"img":false}]}
{"op":"mcm","clk":"11449852993","pt":1717315314403,"mc":[{"id":"1.229554900","rc":[{"atl":[[700,0]],"id":63027102}],"con":true,"img":false}]}
{"op":"mcm","clk":"11449853036","pt":1717315314924,"mc":[{"id":"1.229554900","rc":[{"atl":[[8.4,1.58]],"id":70003368}],"con":true,"img":false}]}
{"op":"mcm","clk":"11449853607","pt":1717315320659,"mc":[{"id":"1.229554900","rc":[{"atb":[[2.86,112.39],[2.96,53.33],[2.76,118.78]],"id":70003368},{"atl":[[10.5,14.66],[15.5,14.41]],"id":70003368},{"atb":[[2.8,116.14],[2.9,55.01],[2.7,122.97]],"id":47208569},{"atl":[[10,15.48],[15,14.93]],"id":47208569},{"atb":[[16,13.93],[18.5,11.94],[22,7.64]],"id":63027102},{"atl":[[320,0.43],[420,0.49]],"id":63027102},{"atb":[[1.63,331.84],[1.58,360.45],[1.68,153.71]],"id":67532289},{"atl":[[3.7,51.62],[4.4,94.57]],"id":67532289}],"con":true,"img":false}]}
{"op":"mcm","clk":"11449854631","pt":1717315330541,"mc":[{"id":"1.229554900","rc":[{"atl":[[8,4.06]],"id":47208569}],"con":true,"img":false}]}
{"op":"mcm","clk":"11449854642","pt":1717315330633,"mc":[{"id":"1.229554900","rc":[{"atl":[[3.15,10.36]],"id":67532289}],"con":true,"img":false}]}
{"op":"mcm","clk":"11449854666","pt":1717315330838,"mc":[{"id":"1.229554900","rc":[{"atl":[[8.4,3.87]],"id":70003368}],"con":true,"img":false}]}
{"op":"mcm","clk":"11449856684","pt":1717315349783,"mc":[{"id":"1.229554900","rc":[{"atl":[[700,2],[960,0.86]],"id":63027102}],"con":true,"img":false}]}
{"op":"mcm","clk":"11449859453","pt":1717315377594,"mc":[{"id":"1.229554900","rc":[{"atb":[[2.88,62.61],[2.9,0],[2.5,0]],"id":70003368},{"atl":[[11,0]],"id":70003368},{"spn":5.68,"spf":"NaN","id":70003368},{"atb":[[2.82,65.68],[2.44,0]],"id":47208569},{"atl":[[12,0],[9.8,13.58]],"id":47208569},{"spn":5.45,"spf":"NaN","id":47208569},{"atl":[[380,0]],"id":63027102},{"atb":[[1.53,0]],"id":67532289},{"atl":[[4.4,61.48],[3.65,42.44]],"id":67532289},{"spn":2.41,"spf":"NaN","id":67532289}],"con":true,"img":false}]}
{"op":"mcm","clk":"11449859463","pt":1717315377700,"mc":[{"id":"1.229554900","rc":[{"atb":[[2.98,29.84]],"id":70003368},{"atl":[[10,13.07]],"id":70003368},{"atb":[[2.92,30.83]],"id":47208569},{"atl":[[310,2.61]],"id":63027102},{"atb":[[1.59,95.1]],"id":67532289}],"con":true,"img":false}]}
{"op":"mcm","clk":"11449862781","pt":1717315411767,"mc":[{"id":"1.229554900","rc":[{"atb":[[17,0],[19.5,0],[14.5,0]],"id":49183855},{"atl":[[300,0],[400,0]],"id":49183855}],"con":true,"img":false}]}
{"op":"mcm","clk":"11449863357","pt":1717315417173,"mc":[{"id":"1.229554900","rc":[{"atb":[[17.5,3.4]],"id":49183855}],"con":true,"img":false}]}
{"op":"mcm","clk":"11449863365","pt":1717315417227,"mc":[{"id":"1.229554900","rc":[{"atb":[[14,7.82]],"id":49183855}],"con":true,"img":false}]}
{"op":"mcm","clk":"11449865319","pt":1717315436398,"mc":[{"id":"1.229554900","rc":[{"atb":[[14.5,15.48],[17,13.06],[19.5,5.65]],"id":49183855},{"atl":[[300,0.46],[400,0.52]],"id":49183855}],"con":true,"img":false}]}
{"op":"mcm","clk":"11449865372","pt":1717315436887,"mc":[{"id":"1.229554900","rc":[{"atl":[[8,2.4]],"id":47208569}],"con":true,"img":false}]}
{"op":"mcm","clk":"11449867034","pt":1717315452081,"mc":[{"id":"1.229554900","rc":[{"spn":5.69,"spf":"NaN","id":70003368},{"spn":5.46,"spf":"NaN","id":47208569},{"atl":[[3.15,6.12]],"id":67532289}],"con":true,"img":false}]}
{"op":"mcm","clk":"11449869100","pt":1717315471773,"mc":[{"id":"1.229554900","rc":[{"atl":[[8.4,2.29]],"id":70003368}],"con":true,"img":false}]}
{"op":"mcm","clk":"11449869815","pt":1717315477917,"mc":[{"id":"1.229554900","rc":[{"atl":[[1000,4.2]],"id":70003368},{"atl":[[1000,3.35]],"id":47208569},{"atl":[[3.15,10.36]],"id":67532289}],"con":true,"img":false}]}
{"op":"mcm","clk":"11449869840","pt":1717315478073,"mc":[{"id":"1.229554900","rc":[{"atl":[[1000,3.43]],"id":70003368},{"atl":[[1000,2.66]],"id":47208569}],"con":true,"img":false}]}
{"op":"mcm","clk":"11449869866","pt":1717315478283,"mc":[{"id":"1.229554900","rc":[{"atl":[[1000,1.85]],"id":70003368}],"con":true,"img":false}]}
{"op":"mcm","clk":"11449869876","pt":1717315478385,"mc":[{"id":"1.229554900","rc":[{"atl":[[8.4,3.87]],"id":70003368}],"con":true,"img":false}]}
{"op":"mcm","clk":"11449869901","pt":1717315478589,"mc":[{"id":"1.229554900","rc":[{"atl":[[1000,1]],"id":47208569}],"con":true,"img":false}]}
{"op":"mcm","clk":"11449869912","pt":1717315478695,"mc":[{"id":"1.229554900","rc":[{"atl":[[8,4.06]],"id":47208569}],"con":true,"img":false}]}
{"op":"mcm","clk":"11449873332","pt":1717315511928,"mc":[{"id":"1.229554900","rc":[{"atb":[[14,0]],"id":49183855}],"con":true,"img":false}]}
{"op":"mcm","clk":"11449873344","pt":1717315512031,"mc":[{"id":"1.229554900","rc":[{"atb":[[17.5,11.22]],"id":49183855}],"con":true,"img":false}]}
{"op":"mcm","clk":"11449876751","pt":1717315545362,"mc":[{"id":"1.229554900","rc":[{"atl":[[8,1.66]],"id":47208569}],"con":true,"img":false}]}
{"op":"mcm","clk":"11449880257","pt":1717315581822,"mc":[{"id":"1.229554900","rc":[{"atl":[[3.15,4.23]],"id":67532289}],"con":true,"img":false}]}
{"op":"mcm","clk":"11449882507","pt":1717315603964,"mc":[{"id":"1.229554900","rc":[{"atl":[[8.4,1.58]],"id":70003368}],"con":true,"img":false}]}
{"op":"mcm","clk":"11449882679","pt":1717315605569,"mc":[{"id":"1.229554900","rc":[{"atb":[[2.88,0]],"id":70003368},{"atb":[[2.82,0]],"id":47208569},{"atb":[[17.5,3.4]],"id":49183855}],"con":true,"img":false}]}
{"op":"mcm","clk":"11449882691","pt":1717315605634,"mc":[{"id":"1.229554900","rc":[{"atb":[[2.78,62.61]],"id":70003368},{"atb":[[2.72,65.68]],"id":47208569},{"atb":[[15,7.82]],"id":49183855}],"con":true,"img":false}]}
{"op":"mcm","clk":"11449884317","pt":1717315621370,"mc":[{"id":"1.229554900","rc":[{"atb":[[1.64,66]],"id":67532289}],"con":true,"img":false}]}
{"op":"mcm","clk":"11449884325","pt":1717315621470,"mc":[{"id":"1.229554900","rc":[{"atl":[[9.2,0]],"id":70003368},{"atl":[[8.8,0]],"id":47208569},{"atb":[[1.59,0]],"id":67532289}],"con":true,"img":false}]}
{"op":"mcm","clk":"11449884335","pt":1717315621581,"mc":[{"id":"1.229554900","rc":[{"atl":[[8.8,6.84]],"id":70003368},{"atl":[[8.6,7.19]],"id":47208569}],"con":true,"img":false}]}
{"op":"mcm","clk":"11449885827","pt":1717315635569,"mc":[{"id":"1.229554900","rc":[{"atl":[[3.35,0]],"id":67532289}],"con":true,"img":false}]}
{"op":"mcm","clk":"11449885840","pt":1717315635666,"mc":[{"id":"1.229554900","rc":[{"atl":[[3.5,23.87]],"id":67532289}],"con":true,"img":false}]}
{"op":"mcm","clk":"11449886576","pt":1717315643026,"mc":[{"id":"1.229554900","rc":[{"atb":[[2.86,0],[2.96,0],[2.76,0]],"id":70003368},{"atl":[[10.5,0],[15.5,0]],"id":70003368},{"atb":[[2.8,0],[2.9,0],[2.7,0]],"id":47208569},{"atl":[[10,0],[15,0]],"id":47208569},{"atb":[[14.5,0],[17,0],[19.5,0]],"id":49183855},{"atl":[[300,0],[400,0]],"id":49183855},{"atb":[[16,0],[18.5,0],[22,2.67]],"id":63027102},{"atl":[[320,0],[420,0]],"id":63027102},{"atb":[[1.63,0],[1.58,0],[1.68,0]],"id":67532289},{"atl":[[3.7,0],[4.4,0]],"id":67532289}],"con":true,"img":false}]}
{"op":"mcm","clk":"11449886873","pt":1717315645811,"mc":[{"id":"1.229554900","rc":[{"atb":[[2.44,81.74],[2.98,0],[2.78,0]],"id":70003368},{"atl":[[10,0]],"id":70003368},{"atb":[[2.92,0],[2.72,0],[2.42,84.18]],"id":47208569},{"atl":[[11,10.86],[9.8,0]],"id":47208569},{"atb":[[1.64,0]],"id":67532289},{"atl":[[4.6,31.24],[3.65,0]],"id":67532289}],"con":true,"img":false}]}
{"op":"mcm","clk":"11449886884","pt":1717315645915,"mc":[{"id":"1.229554900","rc":[{"atb":[[2.82,29.84]],"id":70003368},{"atl":[[11,13.07]],"id":70003368},{"atb":[[2.74,30.83]],"id":47208569},{"atb":[[1.57,66]],"id":67532289}],"con":true,"img":false}]}
{"op":"mcm","clk":"11449888159","pt":1717315658601,"mc":[{"id":"1.229554900","rc":[{"atl":[[8,0]],"id":47208569}],"con":true,"img":false}]}
{"op":"mcm","clk":"11449888516","pt":1717315662234,"mc":[{"id":"1.229554900","rc":[{"atb":[[2.86,112.39],[2.96,53.33],[2.76,118.78]],"id":70003368},{"atl":[[10.5,14.66],[15.5,14.41]],"id":70003368},{"atb":[[2.8,116.14],[2.9,55.01],[2.7,122.97]],"id":47208569},{"atl":[[10,15.48],[15,14.93]],"id":47208569},{"atb":[[14.5,15.48],[17,13.06],[19.5,5.65]],"id":49183855},{"atl":[[300,0.46],[400,0.52]],"id":49183855},{"atb":[[16,13.93],[18.5,11.94],[22,7.64]],"id":63027102},{"atl":[[320,0.43],[420,0.49]],"id":63027102},{"atb":[[1.63,331.84],[1.58,360.45],[1.68,153.71]],"id":67532289},{"atl":[[3.7,51.62],[4.4,61.48]],"id":67532289}],"con":true,"img":false}]}
{"op":"mcm","clk":"11449888809","pt":1717315665133,"mc":[{"id":"1.229554900","rc":[{"atl":[[8.6,0]],"id":47208569},{"atl":[[180,0]],"id":49183855}],"con":true,"img":false}]}
{"op":"mcm","clk":"11449888819","pt":1717315665231,"mc":[{"id":"1.229554900","rc":[{"atl":[[8.2,7.19]],"id":47208569},{"atl":[[170,0.31]],"id":49183855}],"con":true,"img":false}]}
{"op":"mcm","clk":"11449889598","pt":1717315673616,"mc":[{"id":"1.229554900","rc":[{"spn":5.68,"spf":"NaN","id":70003368},{"spn":5.55,"spf":"NaN","id":47208569},{"spn":94.75,"spf":"NaN","id":49183855},{"atl":[[3.15,0]],"id":67532289},{"spn":2.59,"spf":"NaN","id":67532289}],"con":true,"img":false}]}
{"op":"mcm","clk":"11449891207","pt":1717315688954,"mc":[{"id":"1.229554900","rc":[{"atl":[[8.4,0]],"id":70003368}],"con":true,"img":false}]}
{"op":"mcm","clk":"11449892005","pt":1717315696669,"mc":[{"id":"1.229554900","rc":[{"atl":[[7.6,2.53]],"id":47208569}],"con":true,"img":false}]}
{"op":"mcm","clk":"11449892033","pt":1717315696875,"mc":[{"id":"1.229554900","rc":[{"atl":[[3.3,5.83]],"id":67532289}],"con":true,"img":false}]}
{"op":"mcm","clk":"11449892053","pt":1717315697083,"mc":[{"id":"1.229554900","rc":[{"atl":[[8,2.4]],"id":70003368}],"con":true,"img":false}]}
{"op":"mcm","clk":"11449892741","pt":1717315703380,"mc":[{"id":"1.229554900","rc":[{"atb":[[2.82,0],[2.78,66.12]],"id":70003368},{"atl":[[11,0]],"id":70003368},{"atb":[[2.72,69.5],[2.74,0]],"id":47208569},{"atl":[[9.8,13.58]],"id":47208569},{"atb":[[1.57,0]],"id":67532289},{"atl":[[3.65,42.44]],"id":67532289}],"con":true,"img":false}]}
{"op":"mcm","clk":"11449892754","pt":1717315703492,"mc":[{"id":"1.229554900","rc":[{"atb":[[2.44,0],[2.98,29.84]],"id":70003368},{"atl":[[10,13.07]],"id":70003368},{"atb":[[2.92,30.83],[2.42,0]],"id":47208569},{"atl":[[11,0]],"id":47208569},{"atb":[[1.64,66]],"id":67532289},{"atl":[[4.6,0]],"id":67532289}],"con":true,"img":false}]}
{"op":"mcm","clk":"11449892821","pt":1717315704155,"mc":[{"id":"1.229554900","rc":[{"atl":[[1000,3.35]],"id":47208569},{"atl":[[3.3,9.88]],"id":67532289}],"con":true,"img":false}]}
{"op":"mcm","clk":"11449892839","pt":1717315704353,"mc":[{"id":"1.229554900","rc":[{"atl":[[1000,4.2]],"id":70003368}],"con":true,"img":false}]}
{"op":"mcm","clk":"11449892847","pt":1717315704461,"mc":[{"id":"1.229554900","rc":[{"atl":[[1000,2.75]],"id":47208569}],"con":true,"img":false}]}
{"op":"mcm","clk":"11449892866","pt":1717315704674,"mc":[{"id":"1.229554900","rc":[{"atl":[[1000,3.51]],"id":70003368}],"con":true,"img":false}]}
{"op":"mcm","clk":"11449892877","pt":1717315704774,"mc":[{"id":"1.229554900","rc":[{"atl":[[1000,1]],"id":47208569}],"con":true,"img":false}]}
{"op":"mcm","clk":"11449892888","pt":1717315704897,"mc":[{"id":"1.229554900","rc":[{"atl":[[7.6,4.29]],"id":47208569}],"con":true,"img":false}]}
{"op":"mcm","clk":"11449892909","pt":1717315705081,"mc":[{"id":"1.229554900","rc":[{"atl":[[1000,1.85]],"id":70003368}],"con":true,"img":false}]}
{"op":"mcm","clk":"11449892922","pt":1717315705184,"mc":[{"id":"1.229554900","rc":[{"atl":[[8,4.06]],"id":70003368}],"con":true,"img":false}]}
{"op":"mcm","clk":"11449893610","pt":1717315712303,"mc":[{"id":"1.229554900","rc":[{"atb":[[2.86,0],[2.96,0],[2.76,0]],"id":70003368},{"atl":[[10.5,0],[15.5,0]],"id":70003368},{"atb":[[2.8,0],[2.9,0],[2.7,0]],"id":47208569},{"atl":[[10,0],[15,0]],"id":47208569},{"atb":[[16,0],[18.5,0],[22,2.67]],"id":63027102},{"atl":[[320,0],[420,0]],"id":63027102},{"atb":[[1.63,0],[1.58,0],[1.68,0]],"id":67532289},{"atl":[[3.7,0],[4.4,0]],"id":67532289}],"con":true,"img":false}]}
{"op":"mcm","clk":"11449894776","pt":1717315722441,"mc":[{"id":"1.229554900","rc":[{"atb":[[2.44,81.74]],"id":70003368},{"atb":[[2.42,84.18]],"id":47208569},{"atl":[[11,10.86]],"id":47208569},{"atl":[[4.6,31.24]],"id":67532289}],"con":true,"img":false}]}
{"op":"mcm","clk":"11449894789","pt":1717315722546,"mc":[{"id":"1.229554900","rc":[{"atb":[[2.98,0],[2.78,0]],"id":70003368},{"atl":[[10,0]],"id":70003368},{"atb":[[2.92,0],[2.72,0]],"id":47208569},{"atl":[[9.8,0]],"id":47208569},{"atb":[[1.64,0]],"id":67532289},{"atl":[[3.65,0]],"id":67532289}],"con":true,"img":false}]}
{"op":"mcm","clk":"11449894800","pt":1717315722648,"mc":[{"id":"1.229554900","rc":[{"atb":[[2.82,29.84]],"id":70003368},{"atl":[[11,13.07]],"id":70003368},{"atb":[[2.74,30.83]],"id":47208569},{"atb":[[1.57,66]],"id":67532289}],"con":true,"img":false}]}
{"op":"mcm","clk":"11449896887","pt":1717315742884,"mc":[{"id":"1.229554900","rc":[{"atb":[[2.86,112.39],[2.96,53.33],[2.76,118.78]],"id":70003368},{"atl":[[10.5,14.66],[15.5,14.41]],"id":70003368},{"spn":5.48,"spf":"NaN","id":70003368},{"atb":[[2.8,116.14],[2.9,55.01],[2.7,122.97]],"id":47208569},{"atl":[[10,15.48],[15,14.93]],"id":47208569},{"spn":5.25,"spf":"NaN","id":47208569},{"atb":[[16,13.93],[18.5,11.94],[22,7.64]],"id":63027102},{"atl":[[320,0.43],[420,0.49]],"id":63027102},{"atb":[[1.63,331.84],[1.58,360.45],[1.68,153.71]],"id":67532289},{"atl":[[3.7,51.62],[4.4,61.48]],"id":67532289},{"spn":2.49,"spf":"NaN","id":67532289}],"con":true,"img":false}]}
{"op":"mcm","clk":"11449898171","pt":1717315754493,"mc":[{"id":"1.229554900","rc":[{"atl":[[320,2],[350,0]],"id":49183855},{"atl":[[650,2],[700,0]],"id":63027102}],"con":true,"img":false}]}
{"op":"mcm","clk":"11449898298","pt":1717315755689,"mc":[{"id":"1.229554900","rc":[{"atb":[[2.4,0],[2.5,66.67]],"id":47208569}],"con":true,"img":false}]}
{"op":"mcm","clk":"11449902419","pt":1717315795645,"mc":[{"id":"1.229554900","rc":[{"atb":[[2.82,0]],"id":70003368},{"atl":[[11,0]],"id":70003368},{"atb":[[2.74,0]],"id":47208569},{"atb":[[1.57,0]],"id":67532289}],"con":true,"img":false}]}
{"op":"mcm","clk":"11449902431","pt":1717315795746,"mc":[{"id":"1.229554900","rc":[{"atb":[[2.98,29.84]],"id":70003368},{"atl":[[10,13.07]],"id":70003368},{"atb":[[2.92,30.83]],"id":47208569},{"atb":[[1.64,66]],"id":67532289}],"con":true,"img":false}]}
{"op":"mcm","clk":"11449904118","pt":1717315812050,"mc":[{"id":"1.229554900","rc":[{"atb":[[2.44,0],[2.78,66.12]],"id":70003368},{"spn":5.49,"spf":"NaN","id":70003368},{"atb":[[2.72,69.5],[2.42,0]],"id":47208569},{"atl":[[11,0],[9.8,13.58]],"id":47208569},{"spn":5.26,"spf":"NaN","id":47208569},{"atl":[[4.6,0],[3.65,42.44]],"id":67532289}],"con":true,"img":false}]}
{"op":"mcm","clk":"11449906577","pt":1717315836688,"mc":[{"id":"1.229554900","rc":[{"atl":[[9.2,12.2],[12.5,0]],"id":47208569},{"atl":[[320,0],[250,4.61]],"id":49183855},{"atl":[[650,0],[470,2]],"id":63027102}],"con":true,"img":false}]}
{"op":"mcm","clk":"11449906588","pt":1717315836791,"mc":[{"id":"1.229554900","rc":[{"atl":[[300,2.46],[250,2.61]],"id":49183855}],"con":true,"img":false}]}
{"op":"mcm","clk":"11449910107","pt":1717315870234,"mc":[{"id":"1.229554900","rc":[{"atb":[[14.5,0],[17,0],[19.5,0]],"id":49183855},{"atl":[[300,2],[400,0]],"id":49183855}],"con":true,"img":false}]}
{"op":"mcm","clk":"11449910133","pt":1717315870441,"mc":[{"id":"1.229554900","rc":[{"atl":[[300,0],[250,4.61]],"id":49183855}],"con":true,"img":false}]}
{"op":"mcm","clk":"11449912124","pt":1717315888861,"mc":[{"id":"1.229554900","rc":[{"atl":[[7.6,2.53]],"id":47208569},{"spn":93.75,"spf":"NaN","id":49183855}],"con":true,"img":false}]}
{"op":"mcm","clk":"11449912796","pt":1717315894975,"mc":[{"id":"1.229554900","rc":[{"atb":[[14.5,15.48],[17,13.06],[19.5,5.65]],"id":49183855},{"atl":[[300,0.46],[400,0.52]],"id":49183855}],"con":true,"img":false}]}
{"op":"mcm","clk":"11449913245","pt":1717315899047,"mc":[{"id":"1.229554900","rc":[{"atl":[[9.8,0]],"id":47208569}],"con":true,"img":false}]}
{"op":"mcm","clk":"11449913259","pt":1717315899153,"mc":[{"id":"1.229554900","rc":[{"atl":[[9,13.58]],"id":47208569}],"con":true,"img":false}]}
{"op":"mcm","clk":"11449913861","pt":1717315904656,"mc":[{"id":"1.229554900","rc":[{"atl":[[3.3,5.83]],"id":67532289}],"con":true,"img":false}]}
{"op":"mcm","clk":"11449915372","pt":1717315919791,"mc":[{"id":"1.229554900","rc":[{"atl":[[8,2.4]],"id":70003368}],"con":true,"img":false}]}
{"op":"mcm","clk":"11449917192","pt":1717315936919,"mc":[{"id":"1.229554900","rc":[{"atl":[[9.2,0],[12.5,8.7]],"id":47208569},{"atl":[[350,2],[250,2.61]],"id":49183855},{"atl":[[700,2],[470,0]],"id":63027102}],"con":true,"img":false}]}
{"op":"mcm","clk":"11449917673","pt":1717315941416,"mc":[{"id":"1.229554900","rc":[{"atl":[[7.6,0]],"id":47208569}],"con":true,"img":false}]}
{"op":"mcm","clk":"11449918806","pt":1717315952163,"mc":[{"id":"1.229554900","rc":[{"atl":[[9,0]],"id":47208569},{"spn":5.56,"spf":"NaN","id":47208569},{"spn":94.75,"spf":"NaN","id":49183855}],"con":true,"img":false}]}
{"op":"mcm","clk":"11449918815","pt":1717315952214,"mc":[{"id":"1.229554900","rc":[{"atl":[[9.8,13.58]],"id":47208569}],"con":true,"img":false}]}
{"op":"mcm","clk":"11449920966","pt":1717315972664,"mc":[{"id":"1.229554900","rc":[{"atl":[[3.3,0]],"id":67532289}],"con":true,"img":false}]}
{"op":"mcm","clk":"11449925024","pt":1717316012214,"mc":[{"id":"1.229554900","rc":[{"atl":[[8,0]],"id":70003368},{"spn":5.89,"spf":"NaN","id":70003368},{"spn":2.59,"spf":"NaN","id":67532289}],"con":true,"img":false}]}
{"op":"mcm","clk":"11449931932","pt":1717316084548,"mc":[{"id":"1.229554900","rc":[{"atb":[[2.86,0],[2.96,0],[2.76,0]],"id":70003368},{"atl":[[10.5,0],[15.5,0]],"id":70003368},{"atb":[[2.8,0],[2.9,0],[2.7,0]],"id":47208569},{"atl":[[10,0],[15,0]],"id":47208569},{"atb":[[16,0],[18.5,0],[22,2.67]],"id":63027102},{"atl":[[320,0],[420,0]],"id":63027102},{"atb":[[1.63,0],[1.58,0],[1.68,0]],"id":67532289},{"atl":[[3.7,0],[4.4,0]],"id":67532289},{"spn":2.57,"spf":"NaN","id":67532289}],"con":true,"img":false}]}
{"op":"mcm","clk":"11449933171","pt":1717316098384,"mc":[{"id":"1.229554900","rc":[{"atb":[[2.86,112.39],[2.96,53.33],[2.76,118.78]],"id":70003368},{"atl":[[10.5,14.66],[15.5,14.41]],"id":70003368},{"atb":[[2.8,116.14],[2.9,55.01],[2.7,122.97]],"id":47208569},{"atl":[[10,15.48],[15,14.93]],"id":47208569},{"atb":[[16,13.93],[18.5,11.94],[22,7.64]],"id":63027102},{"atl":[[320,0.43],[420,0.49]],"id":63027102},{"atb":[[1.63,331.84],[1.58,360.45],[1.68,153.71]],"id":67532289},{"atl":[[3.7,51.62],[4.4,61.48]],"id":67532289}],"con":true,"img":false}]}
{"op":"mcm","clk":"11449934540","pt":1717316113055,"mc":[{"id":"1.229554900","rc":[{"atl":[[3.3,5.83]],"id":67532289}],"con":true,"img":false}]}
{"op":"mcm","clk":"11449934559","pt":1717316113261,"mc":[{"id":"1.229554900","rc":[{"atl":[[7.6,2.53]],"id":47208569}],"con":true,"img":false}]}
{"op":"mcm","clk":"11449934570","pt":1717316113366,"mc":[{"id":"1.229554900","rc":[{"atl":[[8,2.4]],"id":70003368}],"con":true,"img":false}]}
{"op":"mcm","clk":"11449934729","pt":1717316115280,"mc":[{"id":"1.229554900","rc":[{"atl":[[1000,4.2]],"id":70003368},{"atl":[[1000,3.35]],"id":47208569},{"atl":[[3.3,9.88]],"id":67532289}],"con":true,"img":false}]}
{"op":"mcm","clk":"11449934771","pt":1717316115643,"mc":[{"id":"1.229554900","rc":[{"atl":[[1000,3.51]],"id":70003368},{"atl":[[1000,2.75]],"id":47208569}],"con":true,"img":false}]}
{"op":"mcm","clk":"11449934790","pt":1717316115872,"mc":[{"id":"1.229554900","rc":[{"atl":[[1000,1]],"id":47208569}],"con":true,"img":false}]}
{"op":"mcm","clk":"11449934799","pt":1717316115955,"mc":[{"id":"1.229554900","rc":[{"atl":[[7.6,4.29]],"id":47208569}],"con":true,"img":false}]}
{"op":"mcm","clk":"11449934817","pt":1717316116165,"mc":[{"id":"1.229554900","rc":[{"atl":[[1000,1.85]],"id":70003368}],"con":true,"img":false}]}
{"op":"mcm","clk":"11449934827","pt":1717316116266,"mc":[{"id":"1.229554900","rc":[{"atl":[[8,4.06]],"id":70003368}],"con":true,"img":false}]}
{"op":"mcm","clk":"11449934876","pt":1717316116893,"mc":[{"id":"1.229554900","rc":[{"atb":[[1.97,0],[2.04,96.15]],"id":70003368}],"con":true,"img":false}]}
{"op":"mcm","clk":"11449944482","pt":1717316220723,"mc":[{"id":"1.229554900","rc":[{"spn":5.49,"spf":"NaN","id":70003368},{"spn":5.26,"spf":"NaN","id":47208569},{"atb":[[1.89,57.86],[1.62,0]],"id":49183855},{"atb":[[3.6,0],[4.2,24.39]],"id":63027102},{"atl":[[4.3,30.3],[11.5,0]],"id":67532289},{"spn":2.49,"spf":"NaN","id":67532289}],"con":true,"img":false}]}
{"op":"mcm","clk":"11449945965","pt":1717316236761,"mc":[{"id":"1.229554900","rc":[{"atb":[[14.5,0],[17,0],[19.5,0]],"id":49183855},{"atl":[[300,0],[400,0]],"id":49183855}],"con":true,"img":false}]}
{"op":"mcm","clk":"11449948111","pt":1717316259617,"mc":[{"id":"1.229554900","rc":[{"atb":[[14.5,15.48],[17,13.06],[19.5,5.65]],"id":49183855},{"atl":[[300,0.46],[400,0.52]],"id":49183855}],"con":true,"img":false}]}
{"op":"mcm","clk":"11449952245","pt":1717316309209,"mc":[{"id":"1.229554900","rc":[{"atl":[[7.6,2.53]],"id":47208569}],"con":true,"img":false}]}
{"op":"mcm","clk":"11449952414","pt":1717316311249,"mc":[{"id":"1.229554900","rc":[{"atb":[[2.9,52.63],[2.04,0]],"id":70003368},{"atl":[[11.5,0],[23,4.55]],"id":70003368},{"atb":[[1.4,136.17],[2.5,0]],"id":47208569},{"atl":[[8.6,13.16],[12.5,0]],"id":47208569},{"atb":[[1.89,0]],"id":49183855},{"atl":[[270,2],[350,0]],"id":49183855},{"atb":[[4.2,0]],"id":63027102},{"atl":[[590,2],[700,0]],"id":63027102},{"atb":[[1.36,0],[1.06,535.62]],"id":67532289}],"con":true,"img":false}]}
{"op":"mcm","clk":"11449952422","pt":1717316311347,"mc":[{"id":"1.229554900","rc":[{"atb":[[1.89,98.04]],"id":49183855},{"atb":[[4.2,24.39]],"id":63027102}],"con":true,"img":false}]}
{"op":"mcm","clk":"11449952435","pt":1717316311442,"mc":[{"id":"1.229554900","rc":[{"atl":[[7.6,0]],"id":47208569}],"con":true,"img":false}]}
{"op":"mcm","clk":"11449953588","pt":1717316324680,"mc":[{"id":"1.229554900","rc":[{"atl":[[3.3,5.83]],"id":67532289}],"con":true,"img":false}]}
{"op":"mcm","clk":"11449954517","pt":1717316336678,"mc":[{"id":"1.229554900","rc":[{"atb":[[1.4,0],[2.12,89.29]],"id":47208569},{"atb":[[1.25,400],[1.06,0]],"id":67532289}],"con":true,"img":false}]}
{"op":"mcm","clk":"11449954755","pt":1717316339562,"mc":[{"id":"1.229554900","rc":[{"atl":[[8,2.4]],"id":70003368}],"con":true,"img":false}]}
{"op":"mcm","clk":"11449955502","pt":1717316349108,"mc":[{"id":"1.229554900","rc":[{"atl":[[9.8,0]],"id":47208569}],"con":true,"img":false}]}
{"op":"mcm","clk":"11449955510","pt":1717316349209,"mc":[{"id":"1.229554900","rc":[{"atl":[[8.4,13.58]],"id":47208569}],"con":true,"img":false}]}
{"op":"mcm","clk":"11449955679","pt":1717316351602,"mc":[{"id":"1.229554900","rc":[{"atl":[[3.3,0]],"id":67532289}],"con":true,"img":false}]}
{"op":"mcm","clk":"11449956520","pt":1717316363153,"mc":[{"id":"1.229554900","rc":[{"atl":[[1000,3.35]],"id":47208569}],"con":true,"img":false}]}
{"op":"mcm","clk":"11449956541","pt":1717316363360,"mc":[{"id":"1.229554900","rc":[{"atl":[[1000,4.2]],"id":70003368},{"atl":[[3.3,4.04]],"id":67532289}],"con":true,"img":false}]}
{"op":"mcm","clk":"11449956583","pt":1717316363725,"mc":[{"id":"1.229554900","rc":[{"atl":[[1000,2.75]],"id":47208569}],"con":true,"img":false}]}
{"op":"mcm","clk":"11449956596","pt":1717316363931,"mc":[{"id":"1.229554900","rc":[{"atl":[[1000,3.51]],"id":70003368},{"atl":[[1000,1]],"id":47208569}],"con":true,"img":false}]}
{"op":"mcm","clk":"11449956608","pt":1717316364032,"mc":[{"id":"1.229554900","rc":[{"atl":[[7.6,1.75]],"id":47208569}],"con":true,"img":false}]}
{"op":"mcm","clk":"11449956646","pt":1717316364445,"mc":[{"id":"1.229554900","rc":[{"atl":[[1000,1.85]],"id":70003368}],"con":true,"img":false}]}
{"op":"mcm","clk":"11449956653","pt":1717316364548,"mc":[{"id":"1.229554900","rc":[{"atl":[[8,4.06]],"id":70003368}],"con":true,"img":false}]}
{"op":"mcm","clk":"11449957189","pt":1717316371556,"mc":[{"id":"1.229554900","rc":[{"atl":[[8,1.66]],"id":70003368}],"con":true,"img":false}]}
{"op":"mcm","clk":"11449960816","pt":1717316417533,"mc":[{"id":"1.229554900","rc":[{"atb":[[2.9,0],[2.94,51.55]],"id":70003368},{"atl":[[8.6,0],[8.8,12.82]],"id":47208569}],"con":true,"img":false}]}
{"op":"mcm","clk":"11449961268","pt":1717316422713,"mc":[{"id":"1.229554900","rc":[{"atl":[[8.4,0]],"id":47208569}],"con":true,"img":false}]}
{"op":"mcm","clk":"11449961278","pt":1717316422815,"mc":[{"id":"1.229554900","rc":[{"atl":[[8.6,13.58]],"id":47208569}],"con":true,"img":false}]}
{"op":"mcm","clk":"11449962024","pt":1717316431947,"mc":[{"id":"1.229554900","rc":[{"atl":[[7.6,4.29]],"id":47208569}],"con":true,"img":false}]}
{"op":"mcm","clk":"11449962038","pt":1717316432152,"mc":[{"id":"1.229554900","rc":[{"atl":[[8,4.06]],"id":70003368}],"con":true,"img":false}]}
{"op":"mcm","clk":"11449962072","pt":1717316432666,"mc":[{"id":"1.229554900","rc":[{"atl":[[3.3,9.88]],"id":67532289}],"con":true,"img":false}]}
{"op":"mcm","clk":"11449963627","pt":1717316452879,"mc":[{"id":"1.229554900","rc":[{"atb":[[2.92,52.08]],"id":70003368}],"con":true,"img":false}]}
{"op":"mcm","clk":"11449963636","pt":1717316452985,"mc":[{"id":"1.229554900","rc":[{"atb":[[2.94,0]],"id":70003368}],"con":true,"img":false}]}
{"op":"mcm","clk":"11449964723","pt":1717316468086,"mc":[{"id":"1.229554900","rc":[{"atb":[[2.92,0],[2.76,175.6]],"id":70003368},{"atl":[[19,5.56],[23,0]],"id":70003368},{"atl":[[8.6,26.74],[8.8,0]],"id":47208569},{"atb":[[1.89,0]],"id":49183855},{"atl":[[270,0],[700,2]],"id":49183855},{"atb":[[4.2,0]],"id":63027102},{"atl":[[590,0]],"id":63027102}],"con":true,"img":false}]}
{"op":"mcm","clk":"11449964735","pt":1717316468188,"mc":[{"id":"1.229554900","rc":[{"atb":[[1.89,98.04]],"id":49183855},{"atb":[[4.2,24.39]],"id":63027102}],"con":true,"img":false}]}
{"op":"mcm","clk":"11449966463","pt":1717316492135,"mc":[{"id":"1.229554900","rc":[{"atb":[[2.86,0],[2.96,0],[2.76,56.82]],"id":70003368},{"atl":[[10.5,0],[15.5,0]],"id":70003368},{"atb":[[2.8,0],[2.9,0],[2.7,0]],"id":47208569},{"atl":[[10,0],[15,0]],"id":47208569},{"atb":[[16,0],[18.5,0],[22,2.67]],"id":63027102},{"atl":[[320,0],[420,0]],"id":63027102},{"atb":[[1.63,0],[1.58,0],[1.68,0]],"id":67532289},{"atl":[[3.7,0],[4.4,0]],"id":67532289},{"spn":2.47,"spf":"NaN","id":67532289}],"con":true,"img":false}]}
{"op":"mcm","clk":"11449966485","pt":1717316492389,"mc":[{"id":"1.229554900","rc":[{"atl":[[10,0],[12,10.69]],"id":70003368},{"atb":[[2.72,0],[2.38,86.62]],"id":47208569},{"atl":[[4.2,35.15],[3.65,0]],"id":67532289}],"con":true,"img":false}]}
{"op":"mcm","clk":"11449966496","pt":1717316492494,"mc":[{"id":"1.229554900","rc":[{"atb":[[2.98,0]],"id":70003368},{"atb":[[2.92,0]],"id":47208569},{"atb":[[1.64,0]],"id":67532289}],"con":true,"img":false}]}
{"op":"mcm","clk":"11449966504","pt":1717316492597,"mc":[{"id":"1.229554900","rc":[{"atb":[[2.82,29.84]],"id":70003368},{"atb":[[2.74,30.83]],"id":47208569},{"atb":[[1.57,66]],"id":67532289}],"con":true,"img":false}]}
{"op":"mcm","clk":"11449967769","pt":1717316510916,"mc":[{"id":"1.229554900","rc":[{"atb":[[2.86,112.39],[2.96,53.33],[2.76,175.6]],"id":70003368},{"atl":[[10.5,14.66],[15.5,14.41]],"id":70003368},{"atb":[[2.8,116.14],[2.9,55.01],[2.7,122.97]],"id":47208569},{"atl":[[10,15.48],[15,14.93]],"id":47208569},{"atb":[[16,13.93],[18.5,11.94],[22,7.64]],"id":63027102},{"atl":[[320,0.43],[420,0.49]],"id":63027102},{"atb":[[1.63,331.84],[1.58,360.45],[1.68,153.71]],"id":67532289},{"atl":[[3.7,51.62],[4.4,61.48]],"id":67532289}],"con":true,"img":false}]}
{"op":"mcm","clk":"11449967809","pt":1717316511537,"mc":[{"id":"1.229554900","rc":[{"atb":[[2.3,76.92],[2.76,118.78]],"id":70003368},{"atl":[[19,0],[13.5,8]],"id":70003368},{"atb":[[2.12,0],[1.06,175.92]],"id":47208569},{"atl":[[8.6,13.58],[13.5,8]],"id":47208569},{"atl":[[600,2],[700,0]],"id":49183855}],"con":true,"img":false}]}
{"op":"mcm","clk":"11449967821","pt":1717316511747,"mc":[{"id":"1.229554900","rc":[{"atb":[[2.3,0],[2.44,69.44]],"id":70003368}],"con":true,"img":false}]}
{"op":"mcm","clk":"11449968486","pt":1717316522353,"mc":[{"id":"1.229554900","rc":[{"atl":[[8.6,0]],"id":47208569}],"con":true,"img":false}]}
{"op":"mcm","clk":"11449968498","pt":1717316522450,"mc":[{"id":"1.229554900","rc":[{"atl":[[9.8,13.58]],"id":47208569}],"con":true,"img":false}]}
{"op":"mcm","clk":"11449969350","pt":1717316535036,"mc":[{"id":"1.229554900","rc":[{"atb":[[1.26,173.26],[1.06,0]],"id":47208569}],"con":true,"img":false}]}
{"op":"mcm","clk":"11449969945","pt":1717316544077,"mc":[{"id":"1.229554900","rc":[{"atl":[[7.6,2.53]],"id":47208569}],"con":true,"img":false}]}
{"op":"mcm","clk":"11449970527","pt":1717316552974,"mc":[{"id":"1.229554900","rc":[{"atb":[[2.82,0]],"id":70003368},{"spn":5.48,"spf":"NaN","id":70003368},{"atb":[[2.74,0]],"id":47208569},{"spn":5.25,"spf":"NaN","id":47208569},{"atb":[[1.57,0]],"id":67532289},{"spn":2.49,"spf":"NaN","id":67532289}],"con":true,"img":false}]}
{"op":"mcm","clk":"11449970534","pt":1717316553077,"mc":[{"id":"1.229554900","rc":[{"atb":[[2.98,29.84]],"id":70003368},{"atb":[[2.92,30.83]],"id":47208569},{"atb":[[1.64,66]],"id":67532289}],"con":true,"img":false}]}
{"op":"mcm","clk":"11449970932","pt":1717316559379,"mc":[{"id":"1.229554900","rc":[{"atl":[[3.3,5.83]],"id":67532289}],"con":true,"img":false}]}
{"op":"mcm","clk":"11449971424","pt":1717316567294,"mc":[{"id":"1.229554900","rc":[{"atl":[[10,13.07]],"id":70003368},{"atb":[[2.72,69.5]],"id":47208569},{"atl":[[3.65,42.44]],"id":67532289}],"con":true,"img":false}]}
{"op":"mcm","clk":"11449971430","pt":1717316567398,"mc":[{"id":"1.229554900","rc":[{"atl":[[12,0]],"id":70003368},{"atb":[[2.38,0]],"id":47208569},{"atl":[[4.2,0]],"id":67532289}],"con":true,"img":false}]}
{"op":"mcm","clk":"11449971586","pt":1717316569983,"mc":[{"id":"1.229554900","rc":[{"atl":[[8,2.4]],"id":70003368}],"con":true,"img":false}]}
{"op":"mcm","clk":"11449972626","pt":1717316584993,"mc":[{"id":"1.229554900","rc":[{"atl":[[1000,3.35]],"id":47208569},{"atl":[[3.3,9.88]],"id":67532289}],"con":true,"img":false}]}
{"op":"mcm","clk":"11449972646","pt":1717316585200,"mc":[{"id":"1.229554900","rc":[{"atl":[[1000,4.2]],"id":70003368}],"con":true,"img":false}]}
{"op":"mcm","clk":"11449972675","pt":1717316585613,"mc":[{"id":"1.229554900","rc":[{"atl":[[1000,2.75]],"id":47208569}],"con":true,"img":false}]}
{"op":"mcm","clk":"11449972685","pt":1717316585821,"mc":[{"id":"1.229554900","rc":[{"atl":[[1000,3.51]],"id":70003368},{"atl":[[1000,1]],"id":47208569}],"con":true,"img":false}]}
{"op":"mcm","clk":"11449972696","pt":1717316585932,"mc":[{"id":"1.229554900","rc":[{"atl":[[7.6,4.29]],"id":47208569}],"con":true,"img":false}]}
{"op":"mcm","clk":"11449972725","pt":1717316586287,"mc":[{"id":"1.229554900","rc":[{"atl":[[1000,1.85]],"id":70003368}],"con":true,"img":false}]}
{"op":"mcm","clk":"11449972729","pt":1717316586391,"mc":[{"id":"1.229554900","rc":[{"atl":[[8,4.06]],"id":70003368}],"con":true,"img":false}]}
{"op":"mcm","clk":"11449974713","pt":1717316614039,"mc":[{"id":"1.229554900","rc":[{"spn":5.49,"spf":"NaN","id":70003368},{"atl":[[7.6,1.75]],"id":47208569},{"spn":5.26,"spf":"NaN","id":47208569}],"con":true,"img":false}]}
{"op":"mcm","clk":"11449975118","pt":1717316620256,"mc":[{"id":"1.229554900","rc":[{"atb":[[14.5,0],[17,0],[19.5,0]],"id":49183855},{"atl":[[300,0],[400,0]],"id":49183855}],"con":true,"img":false}]}
{"op":"mcm","clk":"11449975973","pt":1717316631590,"mc":[{"id":"1.229554900","rc":[{"atb":[[1.12,185.65],[1.26,0]],"id":47208569}],"con":true,"img":false}]}
{"op":"mcm","clk":"11449977005","pt":1717316646006,"mc":[{"id":"1.229554900","rc":[{"atb":[[14.5,15.48],[17,13.06],[19.5,5.65]],"id":49183855},{"atl":[[300,0.46],[400,0.52]],"id":49183855}],"con":true,"img":false}]}
{"op":"mcm","clk":"11449977602","pt":1717316653313,"mc":[{"id":"1.229554900","rc":[{"atl":[[3.3,4.04]],"id":67532289}],"con":true,"img":false}]}
{"op":"mcm","clk":"11449979974","pt":1717316685420,"mc":[{"id":"1.229554900","rc":[{"atl":[[8,1.66]],"id":70003368}],"con":true,"img":false}]}
{"op":"mcm","clk":"11449982484","pt":1717316720866,"mc":[{"id":"1.229554900","rc":[{"atl":[[7.6,4.29]],"id":47208569}],"con":true,"img":false}]}
{"op":"mcm","clk":"11449982493","pt":1717316721071,"mc":[{"id":"1.229554900","rc":[{"atl":[[3.3,9.88]],"id":67532289}],"con":true,"img":false}]}
{"op":"mcm","clk":"11449982501","pt":1717316721174,"mc":[{"id":"1.229554900","rc":[{"atl":[[8,4.06]],"id":70003368}],"con":true,"img":false}]}
{"op":"mcm","clk":"11449985671","pt":1717316766266,"mc":[{"id":"1.229554900","rc":[{"atl":[[7.6,2.53]],"id":47208569}],"con":true,"img":false}]}
{"op":"mcm","clk":"11449986793","pt":1717316781056,"mc":[{"id":"1.229554900","rc":[{"atl":[[3.3,5.83]],"id":67532289}],"con":true,"img":false}]}
{"op":"mcm","clk":"11449987599","pt":1717316791775,"mc":[{"id":"1.229554900","rc":[{"atl":[[8,2.4]],"id":70003368}],"con":true,"img":false}]}
{"op":"mcm","clk":"11449993588","pt":1717316870054,"mc":[{"id":"1.229554900","rc":[{"atb":[[2.86,0],[2.96,0],[2.76,0]],"id":70003368},{"atl":[[10.5,0],[15.5,0]],"id":70003368},{"atb":[[2.8,0],[2.9,0],[2.7,0]],"id":47208569},{"atl":[[10,0],[15,0]],"id":47208569},{"atb":[[16,0],[18.5,0],[22,2.67]],"id":63027102},{"atl":[[320,0],[420,0]],"id":63027102},{"atb":[[1.63,0],[1.58,0],[1.68,0]],"id":67532289},{"atl":[[3.7,0],[4.4,0]],"id":67532289},{"spn":2.47,"spf":"NaN","id":67532289}],"con":true,"img":false}]}
{"op":"mcm","clk":"11449994901","pt":1717316885094,"mc":[{"id":"1.229554900","rc":[{"atb":[[2.46,80.62],[2.98,0],[2.78,0]],"id":70003368},{"atl":[[10,0],[12,9.8]],"id":70003368},{"atb":[[2.92,0],[2.72,0],[2.38,86.62]],"id":47208569},{"atl":[[11,9.96],[9.8,0]],"id":47208569},{"atb":[[1.64,0]],"id":67532289},{"atl":[[4.2,35.15],[3.65,0]],"id":67532289}],"con":true,"img":false}]}
{"op":"mcm","clk":"11449994911","pt":1717316885195,"mc":[{"id":"1.229554900","rc":[{"atb":[[2.82,29.84]],"id":70003368},{"atb":[[2.74,30.83]],"id":47208569},{"atb":[[1.57,66]],"id":67532289}],"con":true,"img":false}]}
{"op":"mcm","clk":"11449994923","pt":1717316885299,"mc":[{"id":"1.229554900","rc":[{"atb":[[2.44,0],[2.34,74.63]],"id":70003368}],"con":true,"img":false}]}
{"op":"mcm","clk":"11449995437","pt":1717316891092,"mc":[{"id":"1.229554900","rc":[{"atb":[[2.86,112.39],[2.96,53.33],[2.76,118.78]],"id":70003368},{"atl":[[10.5,14.66],[15.5,14.41]],"id":70003368},{"atb":[[2.8,116.14],[2.9,55.01],[2.7,122.97]],"id":47208569},{"atl":[[10,15.48],[15,14.93]],"id":47208569},{"atb":[[16,13.93],[18.5,11.94],[22,7.64]],"id":63027102},{"atl":[[320,0.43],[420,0.49]],"id":63027102},{"atb":[[1.63,331.84],[1.58,360.45],[1.68,153.71]],"id":67532289},{"atl":[[3.7,51.62],[4.4,61.48]],"id":67532289}],"con":true,"img":false}]}
{"op":"mcm","clk":"11449996527","pt":1717316903294,"mc":[{"id":"1.229554900","rc":[{"atl":[[7.6,0]],"id":47208569}],"con":true,"img":false}]}
{"op":"mcm","clk":"11449999457","pt":1717316939547,"mc":[{"id":"1.229554900","rc":[{"atb":[[2.82,0]],"id":70003368},{"spn":5.48,"spf":"NaN","id":70003368},{"atb":[[2.74,0]],"id":47208569},{"atl":[[11,0],[9.8,13.58]],"id":47208569},{"spn":5.55,"spf":"NaN","id":47208569},{"atb":[[1.57,0]],"id":67532289},{"spn":2.49,"spf":"NaN","id":67532289}],"con":true,"img":false}]}
{"op":"mcm","clk":"11449999465","pt":1717316939651,"mc":[{"id":"1.229554900","rc":[{"atb":[[2.98,29.84]],"id":70003368},{"atb":[[2.92,30.83]],"id":47208569},{"atb":[[1.64,66]],"id":67532289}],"con":true,"img":false}]}
{"op":"mcm","clk":"11450000195","pt":1717316947865,"mc":[{"id":"1.229554900","rc":[{"atb":[[2.46,0],[2.78,66.12]],"id":70003368},{"atl":[[10,13.07],[12,0]],"id":70003368},{"atb":[[2.72,69.5],[2.38,0]],"id":47208569},{"atl":[[4.2,0],[3.65,42.44]],"id":67532289}],"con":true,"img":false}]}
{"op":"mcm","clk":"11450000516","pt":1717316951188,"mc":[{"id":"1.229554900","rc":[{"atl":[[3.3,0]],"id":67532289}],"con":true,"img":false}]}
{"op":"mcm","clk":"11450000709","pt":1717316953572,"mc":[{"id":"1.229554900","rc":[{"atl":[[3.45,5.01]],"id":67532289}],"con":true,"img":false}]}
{"op":"mcm","clk":"11450001564","pt":1717316963575,"mc":[{"id":"1.229554900","rc":[{"atb":[[1.12,0],[1.06,185.65]],"id":47208569},{"atl":[[12,9.09],[13.5,0]],"id":47208569}],"con":true,"img":false}]}
{"op":"mcm","clk":"11450001573","pt":1717316963677,"mc":[{"id":"1.229554900","rc":[{"atb":[[2.44,69.44],[2.34,0]],"id":70003368},{"atb":[[1.06,0],[1.3,151.68]],"id":47208569}],"con":true,"img":false}]}
{"op":"mcm","clk":"11450002856","pt":1717316978815,"mc":[{"id":"1.229554900","rc":[{"atb":[[1.37,151.68],[1.3,0]],"id":47208569}],"con":true,"img":false}]}
{"op":"mcm","clk":"11450002865","pt":1717316978917,"mc":[{"id":"1.229554900","rc":[{"atb":[[1.37,0],[1.26,185.65]],"id":47208569}],"con":true,"img":false}]}
{"op":"mcm","clk":"11450003255","pt":1717316983720,"mc":[{"id":"1.229554900","rc":[{"atl":[[8,0]],"id":70003368}],"con":true,"img":false}]}
{"op":"mcm","clk":"11450003947","pt":1717316992140,"mc":[{"id":"1.229554900","rc":[{"atb":[[14.5,0],[17,0],[19.5,0]],"id":49183855},{"atl":[[300,0],[400,0]],"id":49183855}],"con":true,"img":false}]}
{"op":"mcm","clk":"11450005493","pt":1717317008264,"mc":[{"id":"1.229554900","rc":[{"spn":5.89,"spf":"NaN","id":70003368},{"atl":[[1000,3.35]],"id":47208569},{"spn":5.56,"spf":"NaN","id":47208569},{"spn":93.75,"spf":"NaN","id":49183855},{"atl":[[3.3,4.04]],"id":67532289}],"con":true,"img":false}]}
{"op":"mcm","clk":"11450005512","pt":1717317008425,"mc":[{"id":"1.229554900","rc":[{"atl":[[1000,4.2]],"id":70003368}],"con":true,"img":false}]}
{"op":"mcm","clk":"11450005605","pt":1717317009355,"mc":[{"id":"1.229554900","rc":[{"atl":[[1000,2.75]],"id":47208569}],"con":true,"img":false}]}
{"op":"mcm","clk":"11450005613","pt":1717317009459,"mc":[{"id":"1.229554900","rc":[{"atl":[[1000,3.51]],"id":70003368},{"atl":[[7.6,2.53]],"id":47208569}],"con":true,"img":false}]}
{"op":"mcm","clk":"11450005622","pt":1717317009561,"mc":[{"id":"1.229554900","rc":[{"atl":[[1000,1]],"id":47208569},{"atl":[[3.3,9.88]],"id":67532289}],"con":true,"img":false}]}
{"op":"mcm","clk":"11450005629","pt":1717317009663,"mc":[{"id":"1.229554900","rc":[{"atl":[[7.6,4.29]],"id":47208569}],"con":true,"img":false}]}
{"op":"mcm","clk":"11450005638","pt":1717317009768,"mc":[{"id":"1.229554900","rc":[{"atl":[[8,2.4]],"id":70003368}],"con":true,"img":false}]}
{"op":"mcm","clk":"11450005647","pt":1717317009868,"mc":[{"id":"1.229554900","rc":[{"atl":[[1000,1.85]],"id":70003368}],"con":true,"img":false}]}
{"op":"mcm","clk":"11450005654","pt":1717317009970,"mc":[{"id":"1.229554900","rc":[{"atl":[[8,4.06]],"id":70003368}],"con":true,"img":false}]}
{"op":"mcm","clk":"11450005717","pt":1717317010747,"mc":[{"id":"1.229554900","rc":[{"atl":[[3.45,0]],"id":67532289}],"con":true,"img":false}]}
{"op":"mcm","clk":"11450006447","pt":1717317018340,"mc":[{"id":"1.229554900","rc":[{"atb":[[14.5,15.48],[17,13.06],[19.5,5.65]],"id":49183855},{"atl":[[300,0.46],[400,0.52]],"id":49183855}],"con":true,"img":false}]}
{"op":"mcm","clk":"11450014362","pt":1717317098737,"mc":[{"id":"1.229554900","rc":[{"spn":5.49,"spf":"NaN","id":70003368},{"atb":[[1.12,185.65]],"id":47208569},{"spn":5.26,"spf":"NaN","id":47208569},{"spn":94.75,"spf":"NaN","id":49183855}],"con":true,"img":false}]}
{"op":"mcm","clk":"11450014373","pt":1717317098842,"mc":[{"id":"1.229554900","rc":[{"atb":[[1.26,0]],"id":47208569}],"con":true,"img":false}]}
{"op":"mcm","clk":"11450018885","pt":1717317145816,"mc":[{"id":"1.229554900","rc":[{"atb":[[2.92,4.09]],"id":70003368},{"atb":[[2.86,4.22]],"id":47208569},{"atb":[[1.65,12.07]],"id":67532289}],"con":true,"img":false}]}
{"op":"mcm","clk":"11450023036","pt":1717317187810,"mc":[{"id":"1.229554900","rc":[{"atb":[[1.42,0],[1.53,212.23]],"id":67532289}],"con":true,"img":false}]}
{"op":"mcm","clk":"11450023359","pt":1717317190991,"mc":[{"id":"1.229554900","rc":[{"atl":[[7.6,2.53]],"id":47208569}],"con":true,"img":false}]}
{"op":"mcm","clk":"11450024889","pt":1717317205913,"mc":[{"id":"1.229554900","rc":[{"atl":[[3.3,5.83]],"id":67532289}],"con":true,"img":false}]}
{"op":"mcm","clk":"11450025599","pt":1717317213016,"mc":[{"id":"1.229554900","rc":[{"atl":[[7.6,0]],"id":47208569}],"con":true,"img":false}]}
{"op":"mcm","clk":"11450026452","pt":1717317221108,"mc":[{"id":"1.229554900","rc":[{"atl":[[8,2.4]],"id":70003368}],"con":true,"img":false}]}
{"op":"mcm","clk":"11450027897","pt":1717317235132,"mc":[{"id":"1.229554900","rc":[{"atb":[[2.86,0],[2.96,0],[2.76,0]],"id":70003368},{"atl":[[10.5,0],[15.5,0]],"id":70003368},{"atb":[[2.8,0],[2.9,0],[2.7,0]],"id":47208569},{"atl":[[10,0],[15,0]],"id":47208569},{"atb":[[16,0],[18.5,0],[22,2.67]],"id":63027102},{"atl":[[320,0],[420,0]],"id":63027102},{"atb":[[1.63,0],[1.58,0],[1.68,0]],"id":67532289},{"atl":[[3.7,0],[4.4,0]],"id":67532289}],"con":true,"img":false}]}
{"op":"mcm","clk":"11450028011","pt":1717317236272,"mc":[{"id":"1.229554900","rc":[{"atl":[[1000,3.35]],"id":47208569}],"con":true,"img":false}]}
{"op":"mcm","clk":"11450028030","pt":1717317236434,"mc":[{"id":"1.229554900","rc":[{"atl":[[1000,4.2]],"id":70003368},{"atl":[[3.3,9.88]],"id":67532289}],"con":true,"img":false}]}
{"op":"mcm","clk":"11450028069","pt":1717317236845,"mc":[{"id":"1.229554900","rc":[{"atl":[[1000,2.75]],"id":47208569}],"con":true,"img":false}]}
{"op":"mcm","clk":"11450028106","pt":1717317237260,"mc":[{"id":"1.229554900","rc":[{"atl":[[1000,3.51]],"id":70003368}],"con":true,"img":false}]}
{"op":"mcm","clk":"11450028117","pt":1717317237362,"mc":[{"id":"1.229554900","rc":[{"atl":[[1000,1]],"id":47208569}],"con":true,"img":false}]}
{"op":"mcm","clk":"11450028123","pt":1717317237468,"mc":[{"id":"1.229554900","rc":[{"atl":[[7.6,1.75]],"id":47208569}],"con":true,"img":false}]}
{"op":"mcm","clk":"11450028138","pt":1717317237676,"mc":[{"id":"1.229554900","rc":[{"atl":[[1000,1.85]],"id":70003368}],"con":true,"img":false}]}
{"op":"mcm","clk":"11450028147","pt":1717317237781,"mc":[{"id":"1.229554900","rc":[{"atl":[[8,4.06]],"id":70003368}],"con":true,"img":false}]}
{"op":"mcm","clk":"11450028153","pt":1717317237835,"mc":[{"id":"1.229554900","rc":[{"atb":[[2.46,80.62],[2.78,0]],"id":70003368},{"atl":[[10,0],[12,9.8]],"id":70003368},{"atb":[[2.72,0],[2.38,86.62]],"id":47208569},{"atl":[[4.2,35.15],[3.65,0]],"id":67532289}],"con":true,"img":false}]}
{"op":"mcm","clk":"11450028162","pt":1717317237944,"mc":[{"id":"1.229554900","rc":[{"atb":[[2.98,0]],"id":70003368},{"atb":[[2.92,0]],"id":47208569},{"atl":[[9.8,0]],"id":47208569},{"atb":[[1.64,0]],"id":67532289}],"con":true,"img":false}]}
{"op":"mcm","clk":"11450028170","pt":1717317238052,"mc":[{"id":"1.229554900","rc":[{"atb":[[2.82,29.84]],"id":70003368},{"atb":[[2.74,30.83]],"id":47208569},{"atl":[[11,13.58]],"id":47208569},{"atb":[[1.57,66]],"id":67532289}],"con":true,"img":false}]}
{"op":"mcm","clk":"11450029387","pt":1717317250652,"mc":[{"id":"1.229554900","rc":[{"spn":5.46,"spf":"NaN","id":70003368},{"spn":5.23,"spf":"NaN","id":47208569},{"atl":[[3.3,4.04]],"id":67532289},{"spn":2.47,"spf":"NaN","id":67532289}],"con":true,"img":false}]}
{"op":"mcm","clk":"11450030267","pt":1717317259572,"mc":[{"id":"1.229554900","rc":[{"atb":[[2.86,112.39],[2.96,53.33],[2.76,118.78]],"id":70003368},{"atl":[[10.5,14.66],[15.5,14.41]],"id":70003368},{"atb":[[2.8,116.14],[2.9,55.01],[2.7,122.97]],"id":47208569},{"atl":[[10,15.48],[15,14.93]],"id":47208569},{"atb":[[16,13.93],[18.5,11.94],[22,7.64]],"id":63027102},{"atl":[[320,0.43],[420,0.49]],"id":63027102},{"atb":[[1.63,331.84],[1.58,360.45],[1.68,153.71]],"id":67532289},{"atl":[[3.7,51.62],[4.4,61.48]],"id":67532289}],"con":true,"img":false}]}
{"op":"mcm","clk":"11450031140","pt":1717317267898,"mc":[{"id":"1.229554900","rc":[{"atb":[[1.53,0]],"id":67532289}],"con":true,"img":false}]}
{"op":"mcm","clk":"11450031151","pt":1717317267954,"mc":[{"id":"1.229554900","rc":[{"atb":[[1.45,212.23]],"id":67532289}],"con":true,"img":false}]}
{"op":"mcm","clk":"11450033693","pt":1717317292211,"mc":[{"id":"1.229554900","rc":[{"atl":[[8,1.66]],"id":70003368}],"con":true,"img":false}]}
{"op":"mcm","clk":"11450034265","pt":1717317297903,"mc":[{"id":"1.229554900","rc":[{"atb":[[2.82,0]],"id":70003368},{"atb":[[2.74,0]],"id":47208569},{"atl":[[11,0]],"id":47208569},{"atb":[[1.57,0]],"id":67532289}],"con":true,"img":false}]}
{"op":"mcm","clk":"11450034278","pt":1717317298005,"mc":[{"id":"1.229554900","rc":[{"atb":[[2.98,29.84]],"id":70003368},{"atb":[[2.92,30.83]],"id":47208569},{"atl":[[9.8,13.58]],"id":47208569},{"atb":[[1.64,66]],"id":67532289}],"con":true,"img":false}]}
{"op":"mcm","clk":"11450035393","pt":1717317307804,"mc":[{"id":"1.229554900","rc":[{"atb":[[2.46,0],[2.78,66.12]],"id":70003368},{"atl":[[10,13.07],[12,0]],"id":70003368},{"atb":[[2.72,69.5],[2.38,0]],"id":47208569},{"atl":[[4.2,0],[3.65,42.44]],"id":67532289}],"con":true,"img":false}]}
{"op":"mcm","clk":"11450036516","pt":1717317317931,"mc":[{"id":"1.229554900","rc":[{"spn":5.49,"spf":"NaN","id":70003368},{"atl":[[7.6,4.29]],"id":47208569},{"spn":5.26,"spf":"NaN","id":47208569},{"spn":2.49,"spf":"NaN","id":67532289}],"con":true,"img":false}]}
{"op":"mcm","clk":"11450036538","pt":1717317318137,"mc":[{"id":"1.229554900","rc":[{"atl":[[3.3,9.88]],"id":67532289}],"con":true,"img":false}]}
{"op":"mcm","clk":"11450036551","pt":1717317318242,"mc":[{"id":"1.229554900","rc":[{"atl":[[8,4.06]],"id":70003368}],"con":true,"img":false}]}
{"op":"mcm","clk":"11450040232","pt":1717317351851,"mc":[{"id":"1.229554900","rc":[{"atb":[[14.5,0],[17,0],[19.5,0]],"id":49183855},{"atl":[[300,0],[400,0]],"id":49183855}],"con":true,"img":false}]}
{"op":"mcm","clk":"11450040823","pt":1717317357876,"mc":[{"id":"1.229554900","rc":[{"atb":[[1.45,0]],"id":67532289}],"con":true,"img":false}]}
{"op":"mcm","clk":"11450040835","pt":1717317357980,"mc":[{"id":"1.229554900","rc":[{"atb":[[1.53,212.23]],"id":67532289}],"con":true,"img":false}]}
{"op":"mcm","clk":"11450042982","pt":1717317378075,"mc":[{"id":"1.229554900","rc":[{"atb":[[14.5,15.48],[17,13.06],[19.5,5.65]],"id":49183855},{"atl":[[300,0.46],[400,0.52]],"id":49183855}],"con":true,"img":false}]}
{"op":"mcm","clk":"11450047164","pt":1717317418031,"mc":[{"id":"1.229554900","rc":[{"atl":[[7.6,2.53]],"id":47208569}],"con":true,"img":false}]}
{"op":"mcm","clk":"11450048225","pt":1717317427559,"mc":[{"id":"1.229554900","rc":[{"atb":[[3.3,2.61]],"id":70003368},{"atb":[[3.2,2.61]],"id":47208569},{"atb":[[1.8,2.61]],"id":67532289}],"con":true,"img":false}]}
{"op":"mcm","clk":"11450048807","pt":1717317432848,"mc":[{"id":"1.229554900","rc":[{"atb":[[2.92,0]],"id":70003368},{"atb":[[2.86,0]],"id":47208569},{"atb":[[1.65,0]],"id":67532289},{"atl":[[3.3,5.83]],"id":67532289}],"con":true,"img":false}]}
{"op":"mcm","clk":"11450050457","pt":1717317447965,"mc":[{"id":"1.229554900","rc":[{"atl":[[8,2.4]],"id":70003368},{"spn":5.65,"spf":"NaN","id":70003368},{"spn":5.4,"spf":"NaN","id":47208569},{"spn":2.55,"spf":"NaN","id":67532289}],"con":true,"img":false}]}
{"op":"mcm","clk":"11450050791","pt":1717317451070,"mc":[{"id":"1.229554900","rc":[{"atl":[[550,2],[600,0]],"id":49183855}],"con":true,"img":false}]}
{"op":"mcm","clk":"11450051435","pt":1717317457855,"mc":[{"id":"1.229554900","rc":[{"atb":[[17.5,0]],"id":49183855}],"con":true,"img":false}]}
{"op":"mcm","clk":"11450051441","pt":1717317457956,"mc":[{"id":"1.229554900","rc":[{"atb":[[20,3.4]],"id":49183855}],"con":true,"img":false}]}
{"op":"mcm","clk":"11450051871","pt":1717317462948,"mc":[{"id":"1.229554900","rc":[{"atl":[[1000,4.2]],"id":70003368},{"atl":[[1000,3.35]],"id":47208569},{"atl":[[3.3,9.88]],"id":67532289}],"con":true,"img":false}]}
{"op":"mcm","clk":"11450051982","pt":1717317464084,"mc":[{"id":"1.229554900","rc":[{"atl":[[1000,2.75]],"id":47208569}],"con":true,"img":false}]}
{"op":"mcm","clk":"11450052000","pt":1717317464240,"mc":[{"id":"1.229554900","rc":[{"atl":[[1000,3.51]],"id":70003368}],"con":true,"img":false}]}
{"op":"mcm","clk":"11450052041","pt":1717317464755,"mc":[{"id":"1.229554900","rc":[{"atl":[[1000,1]],"id":47208569}],"con":true,"img":false}]}
{"op":"mcm","clk":"11450052055","pt":1717317464858,"mc":[{"id":"1.229554900","rc":[{"atl":[[7.6,4.29]],"id":47208569}],"con":true,"img":false}]}
{"op":"mcm","clk":"11450052095","pt":1717317465266,"mc":[{"id":"1.229554900","rc":[{"atl":[[1000,1.85]],"id":70003368}],"con":true,"img":false}]}
{"op":"mcm","clk":"11450052106","pt":1717317465369,"mc":[{"id":"1.229554900","rc":[{"atl":[[8,4.06]],"id":70003368}],"con":true,"img":false}]}
{"op":"mcm","clk":"11450056001","pt":1717317509408,"mc":[{"id":"1.229554900","rc":[{"atl":[[7.6,1.75]],"id":47208569},{"spn":95.0,"spf":"NaN","id":49183855}],"con":true,"img":false}]}
{"op":"mcm","clk":"11450060675","pt":1717317562348,"mc":[{"id":"1.229554900","rc":[{"atl":[[3.3,4.04]],"id":67532289}],"con":true,"img":false}]}
{"op":"mcm","clk":"11450064247","pt":1717317601985,"mc":[{"id":"1.229554900","rc":[{"atl":[[8,1.66]],"id":70003368}],"con":true,"img":false}]}
{"op":"mcm","clk":"11450067099","pt":1717317633350,"mc":[{"id":"1.229554900","rc":[{"atb":[[22,2]],"id":49183855},{"atl":[[250,4.61]],"id":49183855},{"atb":[[27,2]],"id":63027102},{"atl":[[310,4.61]],"id":63027102}],"con":true,"img":false}]}
{"op":"mcm","clk":"11450068040","pt":1717317643587,"mc":[{"id":"1.229554900","rc":[{"atl":[[7.6,4.29]],"id":47208569}],"con":true,"img":false}]}
{"op":"mcm","clk":"11450068057","pt":1717317643791,"mc":[{"id":"1.229554900","rc":[{"atl":[[3.3,9.88]],"id":67532289}],"con":true,"img":false}]}
{"op":"mcm","clk":"11450068070","pt":1717317643900,"mc":[{"id":"1.229554900","rc":[{"atl":[[8,4.06]],"id":70003368}],"con":true,"img":false}]}
{"op":"mcm","clk":"11450068114","pt":1717317644262,"mc":[{"id":"1.229554900","rc":[{"atb":[[2.86,0],[2.96,0],[2.76,0]],"id":70003368},{"atl":[[10.5,0],[15.5,0]],"id":70003368},{"atb":[[2.8,0],[2.9,0],[2.7,0]],"id":47208569},{"atl":[[10,0],[15,0]],"id":47208569},{"atb":[[16,0],[18.5,0],[22,2.67]],"id":63027102},{"atl":[[320,0],[420,0]],"id":63027102},{"atb":[[1.63,0],[1.58,0],[1.68,0]],"id":67532289},{"atl":[[3.7,0],[4.4,0]],"id":67532289}],"con":true,"img":false}]}
{"op":"mcm","clk":"11450068465","pt":1717317647767,"mc":[{"id":"1.229554900","rc":[{"atb":[[2.78,0]],"id":70003368},{"atl":[[10,0]],"id":70003368},{"atb":[[2.72,0]],"id":47208569},{"atl":[[3.65,0]],"id":67532289}],"con":true,"img":false}]}
{"op":"mcm","clk":"11450068472","pt":1717317647859,"mc":[{"id":"1.229554900","rc":[{"atb":[[2.46,80.62],[2.98,0]],"id":70003368},{"atl":[[12,9.8]],"id":70003368},{"atb":[[2.92,0],[2.38,86.62]],"id":47208569},{"atl":[[9.8,0]],"id":47208569},{"atb":[[1.64,0]],"id":67532289},{"atl":[[4.2,35.15]],"id":67532289}],"con":true,"img":false}]}
{"op":"mcm","clk":"11450068479","pt":1717317647966,"mc":[{"id":"1.229554900","rc":[{"atb":[[2.82,29.84]],"id":70003368},{"atb":[[2.74,30.83]],"id":47208569},{"atl":[[11,13.58]],"id":47208569},{"atb":[[1.57,66]],"id":67532289}],"con":true,"img":false}]}
{"op":"mcm","clk":"11450069155","pt":1717317655815,"mc":[{"id":"1.229554900","rc":[{"atl":[[7.6,2.53]],"id":47208569}],"con":true,"img":false}]}
{"op":"mcm","clk":"11450069753","pt":1717317662513,"mc":[{"id":"1.229554900","rc":[{"spn":96.0,"spf":"NaN","id":49183855},{"spn":143.5,"spf":"NaN","id":63027102},{"atl":[[3.25,3]],"id":67532289},{"spn":2.52,"spf":"NaN","id":67532289}],"con":true,"img":false}]}
{"op":"mcm","clk":"11450070037","pt":1717317665303,"mc":[{"id":"1.229554900","rc":[{"atb":[[2.86,112.39],[2.96,53.33],[2.76,118.78]],"id":70003368},{"atl":[[10.5,14.66],[15.5,14.41]],"id":70003368},{"atb":[[2.8,116.14],[2.9,55.01],[2.7,122.97]],"id":47208569},{"atl":[[10,15.48],[15,14.93]],"id":47208569},{"atb":[[16,13.93],[18.5,11.94],[22,7.64]],"id":63027102},{"atl":[[320,0.43],[420,0.49]],"id":63027102},{"atb":[[1.63,331.84],[1.58,360.45],[1.68,153.71]],"id":67532289},{"atl":[[3.7,51.62],[4.4,61.48]],"id":67532289}],"con":true,"img":false}]}
{"op":"mcm","clk":"11450070598","pt":1717317671164,"mc":[{"id":"1.229554900","rc":[{"atl":[[3.3,5.83]],"id":67532289}],"con":true,"img":false}]}
{"op":"mcm","clk":"11450072394","pt":1717317690229,"mc":[{"id":"1.229554900","rc":[{"atl":[[8,2.4]],"id":70003368}],"con":true,"img":false}]}
{"op":"mcm","clk":"11450073145","pt":1717317697845,"mc":[{"id":"1.229554900","rc":[{"atb":[[2.82,0]],"id":70003368},{"atb":[[2.74,0]],"id":47208569},{"atl":[[11,0]],"id":47208569},{"atb":[[1.57,0]],"id":67532289}],"con":true,"img":false}]}
{"op":"mcm","clk":"11450073155","pt":1717317697948,"mc":[{"id":"1.229554900","rc":[{"atb":[[2.98,29.84]],"id":70003368},{"atb":[[2.92,30.83]],"id":47208569},{"atl":[[9.8,13.58]],"id":47208569},{"atb":[[1.64,66]],"id":67532289}],"con":true,"img":false}]}
{"op":"mcm","clk":"11450074057","pt":1717317707854,"mc":[{"id":"1.229554900","rc":[{"atb":[[2.46,0],[2.78,66.12]],"id":70003368},{"atl":[[10,13.07],[12,0]],"id":70003368},{"atb":[[2.72,69.5],[2.38,0]],"id":47208569},{"atl":[[4.2,0],[3.65,42.44]],"id":67532289}],"con":true,"img":false}]}
{"op":"mcm","clk":"11450076046","pt":1717317730170,"mc":[{"id":"1.229554900","rc":[{"atb":[[14.5,0],[17,0],[19.5,0]],"id":49183855},{"atl":[[300,0],[400,0]],"id":49183855}],"con":true,"img":false}]}
{"op":"mcm","clk":"11450076759","pt":1717317737758,"mc":[{"id":"1.229554900","rc":[{"atb":[[20,0]],"id":49183855}],"con":true,"img":false}]}
{"op":"mcm","clk":"11450076769","pt":1717317737859,"mc":[{"id":"1.229554900","rc":[{"atb":[[17.5,3.4]],"id":49183855}],"con":true,"img":false}]}
{"op":"mcm","clk":"11450078202","pt":1717317753860,"mc":[{"id":"1.229554900","rc":[{"atb":[[14.5,15.48],[17,13.06],[19.5,5.65]],"id":49183855},{"atl":[[300,0.46],[400,0.52]],"id":49183855}],"con":true,"img":false}]}
{"op":"mcm","clk":"11450082089","pt":1717317797879,"mc":[{"id":"1.229554900","rc":[{"atb":[[17.5,0]],"id":49183855}],"con":true,"img":false}]}
{"op":"mcm","clk":"11450082096","pt":1717317797982,"mc":[{"id":"1.229554900","rc":[{"atb":[[20,3.4]],"id":49183855}],"con":true,"img":false}]}
{"op":"mcm","clk":"11450082605","pt":1717317804352,"mc":[{"id":"1.229554900","rc":[{"atb":[[22,0]],"id":49183855},{"atl":[[250,2.61]],"id":49183855},{"atb":[[27,0]],"id":63027102},{"atl":[[310,2.61]],"id":63027102}],"con":true,"img":false}]}
{"op":"mcm","clk":"11450083959","pt":1717317819747,"mc":[{"id":"1.229554900","rc":[{"atb":[[22,2]],"id":49183855},{"atl":[[250,4.61]],"id":49183855},{"atb":[[27,2]],"id":63027102},{"atl":[[310,4.61]],"id":63027102}],"con":true,"img":false}]}
{"op":"mcm","clk":"11450084426","pt":1717317825620,"mc":[{"id":"1.229554900","rc":[{"atb":[[1.89,0],[2.34,74.63]],"id":49183855},{"atb":[[2.34,44.64],[4.2,0]],"id":63027102},{"atl":[[4.3,0],[5.3,23.26]],"id":67532289}],"con":true,"img":false}]}
{"op":"mcm","clk":"11450084724","pt":1717317829450,"mc":[{"id":"1.229554900","rc":[{"atl":[[7.6,0]],"id":47208569}],"con":true,"img":false}]}
{"op":"mcm","clk":"11450086436","pt":1717317849743,"mc":[{"id":"1.229554900","rc":[{"atl":[[1000,2.7]],"id":47208569},{"atl":[[1000,3.55]],"id":67532289}],"con":true,"img":false}]}
{"op":"mcm","clk":"11450086456","pt":1717317849950,"mc":[{"id":"1.229554900","rc":[{"atb":[[1.03,7.49]],"id":47208569}],"con":true,"img":false}]}
{"op":"mcm","clk":"11450086475","pt":1717317850157,"mc":[{"id":"1.229554900","rc":[{"atb":[[1.2,1.7]],"id":63027102}],"con":true,"img":false}]}
{"op":"mcm","clk":"11450086484","pt":1717317850260,"mc":[{"id":"1.229554900","rc":[{"atb":[[1.02,1.7]],"id":67532289}],"con":true,"img":false}]}
{"op":"mcm","clk":"11450086499","pt":1717317850467,"mc":[{"id":"1.229554900","rc":[{"atl":[[1000,3.55]],"id":70003368}],"con":true,"img":false}]}
{"op":"mcm","clk":"11450086506","pt":1717317850569,"mc":[{"id":"1.229554900","rc":[{"atb":[[1.2,1.7]],"id":49183855}],"con":true,"img":false}]}
{"op":"mcm","clk":"11450086537","pt":1717317850933,"mc":[{"id":"1.229554900","rc":[{"atl":[[1000,2.11]],"id":67532289}],"con":true,"img":false}]}
{"op":"mcm","clk":"11450086568","pt":1717317851344,"mc":[{"id":"1.229554900","rc":[{"atb":[[1.03,7.49]],"id":70003368}],"con":true,"img":false}]}
{"op":"mcm","clk":"11450086603","pt":1717317851760,"mc":[{"id":"1.229554900","rc":[{"atb":[[1.03,6.05]],"id":47208569},{"atb":[[1.2,0.03]],"id":63027102}],"con":true,"img":false}]}
{"op":"mcm","clk":"11450086628","pt":1717317852071,"mc":[{"id":"1.229554900","rc":[{"atb":[[1.02,0.46]],"id":67532289},{"atl":[[1000,1.85]],"id":67532289}],"con":true,"img":false}]}
{"op":"mcm","clk":"11450086638","pt":1717317852175,"mc":[{"id":"1.229554900","rc":[{"atl":[[3.2,0.26]],"id":67532289}],"con":true,"img":false}]}
{"op":"mcm","clk":"11450086653","pt":1717317852334,"mc":[{"id":"1.229554900","rc":[{"atl":[[1000,1.1]],"id":47208569}],"con":true,"img":false}]}
{"op":"mcm","clk":"11450086662","pt":1717317852492,"mc":[{"id":"1.229554900","rc":[{"atb":[[1.2,0.03]],"id":49183855}],"con":true,"img":false}]}
{"op":"mcm","clk":"11450086675","pt":1717317852646,"mc":[{"id":"1.229554900","rc":[{"atl":[[1000,1.96]],"id":70003368}],"con":true,"img":false}]}
{"op":"mcm","clk":"11450086702","pt":1717317852956,"mc":[{"id":"1.229554900","rc":[{"atb":[[1.03,6.04]],"id":70003368}],"con":true,"img":false}]}
{"op":"mcm","clk":"11450086723","pt":1717317853164,"mc":[{"id":"1.229554900","rc":[{"atb":[[1.2,0]],"id":63027102}],"con":true,"img":false}]}
{"op":"mcm","clk":"11450086732","pt":1717317853266,"mc":[{"id":"1.229554900","rc":[{"atb":[[28,0.03]],"id":63027102}],"con":true,"img":false}]}
{"op":"mcm","clk":"11450086801","pt":1717317854144,"mc":[{"id":"1.229554900","rc":[{"atb":[[1.03,5.78]],"id":47208569}],"con":true,"img":false}]}
{"op":"mcm","clk":"11450086809","pt":1717317854247,"mc":[{"id":"1.229554900","rc":[{"atb":[[3.25,0.26]],"id":47208569}],"con":true,"img":false}]}
{"op":"mcm","clk":"11450086843","pt":1717317854662,"mc":[{"id":"1.229554900","rc":[{"atb":[[1.02,0]],"id":67532289}],"con":true,"img":false}]}
{"op":"mcm","clk":"11450086852","pt":1717317854765,"mc":[{"id":"1.229554900","rc":[{"atb":[[1.81,0.46]],"id":67532289}],"con":true,"img":false}]}
{"op":"mcm","clk":"11450086924","pt":1717317855541,"mc":[{"id":"1.229554900","rc":[{"atl":[[1000,1]],"id":47208569}],"con":true,"img":false}]}
{"op":"mcm","clk":"11450086933","pt":1717317855645,"mc":[{"id":"1.229554900","rc":[{"atl":[[8,0.1]],"id":47208569}],"con":true,"img":false}]}
{"op":"mcm","clk":"11450086966","pt":1717317856162,"mc":[{"id":"1.229554900","rc":[{"atb":[[1.2,0]],"id":49183855}],"con":true,"img":false}]}
{"op":"mcm","clk":"11450086977","pt":1717317856265,"mc":[{"id":"1.229554900","rc":[{"atb":[[23,0.03]],"id":49183855}],"con":true,"img":false}]}
{"op":"mcm","clk":"11450087010","pt":1717317856681,"mc":[{"id":"1.229554900","rc":[{"atl":[[1000,1.85]],"id":70003368}],"con":true,"img":false}]}
{"op":"mcm","clk":"11450087019","pt":1717317856785,"mc":[{"id":"1.229554900","rc":[{"atl":[[7.8,0.11]],"id":70003368}],"con":true,"img":false}]}
{"op":"mcm","clk":"11450087048","pt":1717317857046,"mc":[{"id":"1.229554900","rc":[{"atb":[[1.03,5.78]],"id":70003368}],"con":true,"img":false}]}
{"op":"mcm","clk":"11450087056","pt":1717317857148,"mc":[{"id":"1.229554900","rc":[{"atb":[[3.35,0.25]],"id":70003368}],"con":true,"img":false}]}
{"op":"mcm","clk":"11450087066","pt":1717317857254,"mc":[{"id":"1.229554900","rc":[{"atb":[[1.02,2]],"id":47208569}],"con":true,"img":false}]}
{"op":"mcm","clk":"11450087193","pt":1717317858548,"mc":[{"id":"1.229554900","rc":[{"spn":5.57,"spf":"NaN","id":70003368},{"spn":5.62,"spf":"NaN","id":47208569},{"spn":96.5,"spf":"NaN","id":49183855},{"spn":144.0,"spf":"NaN","id":63027102},{"atb":[[1.02,2]],"id":67532289},{"spn":2.5,"spf":"NaN","id":67532289}],"con":true,"img":false}]}
{"op":"mcm","clk":"11450087461","pt":1717317861954,"mc":[{"id":"1.229554900","rc":[{"atb":[[1.02,2]],"id":70003368}],"con":true,"img":false}]}
{"op":"mcm","clk":"11450087684","pt":1717317864656,"mc":[{"id":"1.229554900","rc":[{"atb":[[19,0]],"id":63027102}],"con":true,"img":false}]}
{"op":"mcm","clk":"11450087696","pt":1717317864758,"mc":[{"id":"1.229554900","rc":[{"atb":[[16.5,7.84]],"id":63027102}],"con":true,"img":false}]}
{"op":"mcm","clk":"11450088064","pt":1717317869151,"mc":[{"id":"1.229554900","rc":[{"atb":[[1.02,0]],"id":47208569}],"con":true,"img":false}]}
{"op":"mcm","clk":"11450088073","pt":1717317869255,"mc":[{"id":"1.229554900","rc":[{"atb":[[3.25,2.26]],"id":47208569}],"con":true,"img":false}]}
{"op":"mcm","clk":"11450088113","pt":1717317869673,"mc":[{"id":"1.229554900","rc":[{"atb":[[1.02,0]],"id":67532289}],"con":true,"img":false}]}
{"op":"mcm","clk":"11450088120","pt":1717317869776,"mc":[{"id":"1.229554900","rc":[{"atb":[[1.81,2.46]],"id":67532289}],"con":true,"img":false}]}
{"op":"mcm","clk":"11450088161","pt":1717317870193,"mc":[{"id":"1.229554900","rc":[{"atb":[[1.02,0]],"id":70003368}],"con":true,"img":false}]}
{"op":"mcm","clk":"11450088174","pt":1717317870296,"mc":[{"id":"1.229554900","rc":[{"atb":[[3.35,2.25]],"id":70003368}],"con":true,"img":false}]}
{"op":"mcm","clk":"11450088281","pt":1717317871447,"mc":[{"id":"1.229554900","rc":[{"atl":[[3.3,0]],"id":67532289}],"con":true,"img":false}]}
{"op":"mcm","clk":"11450088860","pt":1717317877903,"mc":[{"id":"1.229554900","rc":[{"atl":[[260,0]],"id":63027102}],"con":true,"img":false}]}
{"op":"mcm","clk":"11450088868","pt":1717317877964,"mc":[{"id":"1.229554900","rc":[{"atl":[[220,0.21]],"id":63027102}],"con":true,"img":false}]}
{"op":"mcm","clk":"11450092230","pt":1717317915336,"mc":[{"id":"1.229554900","rc":[{"atl":[[1000,4.2]],"id":70003368},{"atb":[[2.98,3.96]],"id":47208569},{"atl":[[1000,3.35]],"id":47208569},{"atb":[[1.7,11.21]],"id":67532289},{"atl":[[3.3,4.04]],"id":67532289}],"con":true,"img":false}]}
{"op":"mcm","clk":"11450092449","pt":1717317917614,"mc":[{"id":"1.229554900","rc":[{"atl":[[1000,3.51]],"id":70003368},{"atl":[[1000,2.75]],"id":47208569}],"con":true,"img":false}]}
{"op":"mcm","clk":"11450092474","pt":1717317917917,"mc":[{"id":"1.229554900","rc":[{"atb":[[22,4.97]],"id":63027102}],"con":true,"img":false}]}
{"op":"mcm","clk":"11450092481","pt":1717317918020,"mc":[{"id":"1.229554900","rc":[{"atb":[[28,2.7]],"id":63027102}],"con":true,"img":false}]}
{"op":"mcm","clk":"11450092754","pt":1717317921229,"mc":[{"id":"1.229554900","rc":[{"atl":[[1000,1]],"id":47208569},{"spn":124.0,"spf":"NaN","id":63027102}],"con":true,"img":false}]}
{"op":"mcm","clk":"11450092762","pt":1717317921329,"mc":[{"id":"1.229554900","rc":[{"atl":[[7.6,1.75]],"id":47208569}],"con":true,"img":false}]}
{"op":"mcm","clk":"11450092782","pt":1717317921540,"mc":[{"id":"1.229554900","rc":[{"atl":[[8,0]],"id":70003368}],"con":true,"img":false}]}
{"op":"mcm","clk":"11450092816","pt":1717317921948,"mc":[{"id":"1.229554900","rc":[{"atl":[[1000,1.85]],"id":70003368}],"con":true,"img":false}]}
{"op":"mcm","clk":"11450092823","pt":1717317922055,"mc":[{"id":"1.229554900","rc":[{"atl":[[8,1.66]],"id":70003368}],"con":true,"img":false}]}
{"op":"mcm","clk":"11450093231","pt":1717317926430,"mc":[{"id":"1.229554900","rc":[{"atl":[[3.25,0]],"id":67532289}],"con":true,"img":false}]}
{"op":"mcm","clk":"11450093346","pt":1717317927825,"mc":[{"id":"1.229554900","rc":[{"atb":[[16.5,0]],"id":63027102}],"con":true,"img":false}]}
{"op":"mcm","clk":"11450093358","pt":1717317927929,"mc":[{"id":"1.229554900","rc":[{"atb":[[19,7.84]],"id":63027102}],"con":true,"img":false}]}
{"op":"mcm","clk":"11450093481","pt":1717317929331,"mc":[{"id":"1.229554900","rc":[{"atb":[[2.86,0],[2.96,0],[2.76,0]],"id":70003368},{"atl":[[10.5,0],[15.5,0]],"id":70003368},{"atb":[[2.8,0],[2.9,0],[2.7,0]],"id":47208569},{"atl":[[10,0],[15,0]],"id":47208569},{"atb":[[14.5,0],[17,0],[19.5,0]],"id":49183855},{"atl":[[300,0],[400,0]],"id":49183855},{"atb":[[16,0],[18.5,0],[22,0]],"id":63027102},{"atl":[[320,0],[420,0]],"id":63027102},{"atb":[[1.63,0],[1.58,0],[1.68,0]],"id":67532289},{"atl":[[3.7,0],[4.4,0]],"id":67532289}],"con":true,"img":false}]}
{"op":"mcm","clk":"11450093848","pt":1717317933145,"mc":[{"id":"1.229554900","rc":[{"atl":[[3.15,3]],"id":67532289}],"con":true,"img":false}]}
{"op":"mcm","clk":"11450094281","pt":1717317937869,"mc":[{"id":"1.229554900","rc":[{"atb":[[2.46,80.62],[2.98,0]],"id":70003368},{"atl":[[12,9.8]],"id":70003368},{"atb":[[2.92,0],[2.38,86.62]],"id":47208569},{"atl":[[9.8,0]],"id":47208569},{"atb":[[20,0]],"id":49183855},{"atb":[[19,0]],"id":63027102},{"atb":[[1.64,0]],"id":67532289},{"atl":[[4.6,26.78]],"id":67532289}],"con":true,"img":false}]}
{"op":"mcm","clk":"11450094289","pt":1717317937972,"mc":[{"id":"1.229554900","rc":[{"atb":[[2.82,29.84],[2.78,0]],"id":70003368},{"atl":[[10,0]],"id":70003368},{"atb":[[2.72,0],[2.74,30.83]],"id":47208569},{"atl":[[11,13.58]],"id":47208569},{"atb":[[17.5,3.4]],"id":49183855},{"atb":[[15.5,7.84]],"id":63027102},{"atb":[[1.57,66]],"id":67532289},{"atl":[[3.65,0]],"id":67532289}],"con":true,"img":false}]}
{"op":"mcm","clk":"11450094986","pt":1717317946036,"mc":[{"id":"1.229554900","rc":[{"atb":[[2.88,4.17]],"id":70003368}],"con":true,"img":false}]}
{"op":"mcm","clk":"11450095079","pt":1717317946968,"mc":[{"id":"1.229554900","rc":[{"atb":[[2.86,112.39],[2.96,53.33],[2.76,118.78]],"id":70003368},{"atl":[[10.5,14.66],[15.5,14.41]],"id":70003368},{"atb":[[2.8,116.14],[2.9,55.01],[2.7,122.97]],"id":47208569},{"atl":[[10,15.48],[15,14.93]],"id":47208569},{"atb":[[14.5,15.48],[17,13.06],[19.5,5.65]],"id":49183855},{"atl":[[300,0.46],[400,0.52]],"id":49183855},{"atb":[[16,13.93],[18.5,11.94],[22,4.97]],"id":63027102},{"atl":[[320,0.43],[420,0.49]],"id":63027102},{"atb":[[1.63,331.84],[1.58,360.45],[1.68,153.71]],"id":67532289},{"atl":[[3.7,51.62],[4.4,61.48]],"id":67532289}],"con":true,"img":false}]}
{"op":"mcm","clk":"11450096071","pt":1717317959184,"mc":[{"id":"1.229554900","rc":[{"atb":[[22,0]],"id":49183855},{"atl":[[250,2.61]],"id":49183855},{"atb":[[27,0]],"id":63027102},{"atl":[[310,2.61]],"id":63027102}],"con":true,"img":false}]}
{"op":"mcm","clk":"11450096209","pt":1717317960988,"mc":[{"id":"1.229554900","rc":[{"atl":[[7.6,4.29]],"id":47208569},{"atl":[[3.15,0]],"id":67532289}],"con":true,"img":false}]}
{"op":"mcm","clk":"11450096222","pt":1717317961195,"mc":[{"id":"1.229554900","rc":[{"atl":[[8,4.06]],"id":70003368},{"atl":[[3.3,9.88]],"id":67532289}],"con":true,"img":false}]}
{"op":"mcm","clk":"11450096243","pt":1717317961401,"mc":[{"id":"1.229554900","rc":[{"atl":[[3.1,3]],"id":67532289}],"con":true,"img":false}]}
{"op":"mcm","clk":"11450096809","pt":1717317967898,"mc":[{"id":"1.229554900","rc":[{"atb":[[28,0.03]],"id":63027102}],"con":true,"img":false}]}
{"op":"mcm","clk":"11450096818","pt":1717317968005,"mc":[{"id":"1.229554900","rc":[{"atb":[[23,2.67]],"id":63027102}],"con":true,"img":false}]}
{"op":"mcm","clk":"11450096871","pt":1717317968674,"mc":[{"id":"1.229554900","rc":[{"atl":[[3.1,0]],"id":67532289}],"con":true,"img":false}]}
{"op":"mcm","clk":"11450096898","pt":1717317968983,"mc":[{"id":"1.229554900","rc":[{"atl":[[3.05,3]],"id":67532289}],"con":true,"img":false}]}
{"op":"mcm","clk":"11450097051","pt":1717317970891,"mc":[{"id":"1.229554900","rc":[{"atb":[[28,0]],"id":63027102}],"con":true,"img":false}]}
{"op":"mcm","clk":"11450097075","pt":1717317971198,"mc":[{"id":"1.229554900","rc":[{"atl":[[8,0]],"id":47208569}],"con":true,"img":false}]}
{"op":"mcm","clk":"11450097084","pt":1717317971298,"mc":[{"id":"1.229554900","rc":[{"atl":[[3.2,0]],"id":67532289}],"con":true,"img":false}]}
{"op":"mcm","clk":"11450097104","pt":1717317971508,"mc":[{"id":"1.229554900","rc":[{"atb":[[3.25,2]],"id":47208569}],"con":true,"img":false}]}
{"op":"mcm","clk":"11450097111","pt":1717317971611,"mc":[{"id":"1.229554900","rc":[{"atb":[[1.81,2]],"id":67532289}],"con":true,"img":false}]}
{"op":"mcm","clk":"11450097134","pt":1717317971868,"mc":[{"id":"1.229554900","rc":[{"atl":[[7.8,0]],"id":70003368}],"con":true,"img":false}]}
{"op":"mcm","clk":"11450097142","pt":1717317971972,"mc":[{"id":"1.229554900","rc":[{"atl":[[1000,3.55]],"id":67532289}],"con":true,"img":false}]}
{"op":"mcm","clk":"11450097156","pt":1717317972178,"mc":[{"id":"1.229554900","rc":[{"atb":[[1.03,7.49]],"id":47208569},{"atb":[[23,0]],"id":49183855}],"con":true,"img":false}]}
{"op":"mcm","clk":"11450097166","pt":1717317972382,"mc":[{"id":"1.229554900","rc":[{"atl":[[1000,2.7]],"id":47208569},{"atb":[[1.02,1.7]],"id":67532289}],"con":true,"img":false}]}
{"op":"mcm","clk":"11450097184","pt":1717317972589,"mc":[{"id":"1.229554900","rc":[{"atl":[[1000,3.55]],"id":70003368}],"con":true,"img":false}]}
{"op":"mcm","clk":"11450097190","pt":1717317972691,"mc":[{"id":"1.229554900","rc":[{"atb":[[1.2,1.7]],"id":63027102}],"con":true,"img":false}]}
{"op":"mcm","clk":"11450097202","pt":1717317972901,"mc":[{"id":"1.229554900","rc":[{"atl":[[1000,2.13]],"id":67532289}],"con":true,"img":false}]}
{"op":"mcm","clk":"11450097211","pt":1717317973002,"mc":[{"id":"1.229554900","rc":[{"atb":[[1.03,6.04]],"id":47208569}],"con":true,"img":false}]}
{"op":"mcm","clk":"11450097228","pt":1717317973208,"mc":[{"id":"1.229554900","rc":[{"atb":[[1.02,0.46]],"id":67532289}],"con":true,"img":false}]}
{"op":"mcm","clk":"11450097237","pt":1717317973311,"mc":[{"id":"1.229554900","rc":[{"atl":[[1000,1.11]],"id":47208569}],"con":true,"img":false}]}
{"op":"mcm","clk":"11450097250","pt":1717317973514,"mc":[{"id":"1.229554900","rc":[{"atb":[[3.35,2]],"id":70003368}],"con":true,"img":false}]}
{"op":"mcm","clk":"11450097258","pt":1717317973619,"mc":[{"id":"1.229554900","rc":[{"atb":[[1.2,0.03]],"id":63027102}],"con":true,"img":false}]}
{"op":"mcm","clk":"11450097288","pt":1717317973982,"mc":[{"id":"1.229554900","rc":[{"atl":[[1000,1.85]],"id":67532289}],"con":true,"img":false}]}
{"op":"mcm","clk":"11450097295","pt":1717317974086,"mc":[{"id":"1.229554900","rc":[{"atb":[[1.16,1.7]],"id":49183855},{"atl":[[3,0.28]],"id":67532289}],"con":true,"img":false}]}
{"op":"mcm","clk":"11450097335","pt":1717317974501,"mc":[{"id":"1.229554900","rc":[{"atl":[[1000,1.96]],"id":70003368},{"atb":[[1.03,5.78]],"id":47208569}],"con":true,"img":false}]}
{"op":"mcm","clk":"11450097344","pt":1717317974603,"mc":[{"id":"1.229554900","rc":[{"atb":[[3.3,0.25]],"id":47208569}],"con":true,"img":false}]}
{"op":"mcm","clk":"11450097366","pt":1717317974908,"mc":[{"id":"1.229554900","rc":[{"atb":[[1.02,0]],"id":67532289}],"con":true,"img":false}]}
{"op":"mcm","clk":"11450097380","pt":1717317975011,"mc":[{"id":"1.229554900","rc":[{"atb":[[1.82,0.46]],"id":67532289}],"con":true,"img":false}]}
{"op":"mcm","clk":"11450097405","pt":1717317975275,"mc":[{"id":"1.229554900","rc":[{"atl":[[1000,1]],"id":47208569}],"con":true,"img":false}]}
{"op":"mcm","clk":"11450097413","pt":1717317975376,"mc":[{"id":"1.229554900","rc":[{"atl":[[7.4,0.11]],"id":47208569}],"con":true,"img":false}]}
{"op":"mcm","clk":"11450097439","pt":1717317975693,"mc":[{"id":"1.229554900","rc":[{"atb":[[1.03,7.49]],"id":70003368}],"con":true,"img":false}]}
{"op":"mcm","clk":"11450097457","pt":1717317975994,"mc":[{"id":"1.229554900","rc":[{"atb":[[1.2,0]],"id":63027102}],"con":true,"img":false}]}
{"op":"mcm","clk":"11450097468","pt":1717317976098,"mc":[{"id":"1.229554900","rc":[{"atb":[[24,0.03]],"id":63027102}],"con":true,"img":false}]}
{"op":"mcm","clk":"11450097495","pt":1717317976402,"mc":[{"id":"1.229554900","rc":[{"atb":[[1.16,0.04]],"id":49183855}],"con":true,"img":false}]}
{"op":"mcm","clk":"11450097514","pt":1717317976609,"mc":[{"id":"1.229554900","rc":[{"atl":[[1000,1.85]],"id":70003368},{"atl":[[3.05,0]],"id":67532289}],"con":true,"img":false}]}
{"op":"mcm","clk":"11450097528","pt":1717317976712,"mc":[{"id":"1.229554900","rc":[{"atl":[[7.8,0.11]],"id":70003368}],"con":true,"img":false}]}
{"op":"mcm","clk":"11450097535","pt":1717317976815,"mc":[{"id":"1.229554900","rc":[{"atl":[[3,3.28]],"id":67532289}],"con":true,"img":false}]}
{"op":"mcm","clk":"11450097555","pt":1717317977077,"mc":[{"id":"1.229554900","rc":[{"atb":[[1.16,0]],"id":49183855}],"con":true,"img":false}]}
{"op":"mcm","clk":"11450097562","pt":1717317977182,"mc":[{"id":"1.229554900","rc":[{"atb":[[1.03,6.03]],"id":70003368},{"atb":[[20,0.04]],"id":49183855}],"con":true,"img":false}]}
{"op":"mcm","clk":"11450097621","pt":1717317977801,"mc":[{"id":"1.229554900","rc":[{"atb":[[2.82,0],[1.03,5.78]],"id":70003368},{"atb":[[2.74,0]],"id":47208569},{"atl":[[11,0]],"id":47208569},{"atb":[[1.57,0]],"id":67532289}],"con":true,"img":false}]}
{"op":"mcm","clk":"11450097630","pt":1717317977900,"mc":[{"id":"1.229554900","rc":[{"atb":[[3.4,0.24],[2.98,29.84]],"id":70003368},{"atb":[[2.92,30.83]],"id":47208569},{"atl":[[9.8,13.58]],"id":47208569},{"atb":[[1.64,66]],"id":67532289}],"con":true,"img":false}]}
{"op":"mcm","clk":"11450098176","pt":1717317984518,"mc":[{"id":"1.229554900","rc":[{"spn":5.6,"spf":"NaN","id":70003368},{"spn":5.35,"spf":"NaN","id":47208569},{"spn":95.0,"spf":"NaN","id":49183855},{"spn":122.0,"spf":"NaN","id":63027102},{"atl":[[3,0.28]],"id":67532289},{"spn":2.41,"spf":"NaN","id":67532289}],"con":true,"img":false}]}
{"op":"mcm","clk":"11450098202","pt":1717317984823,"mc":[{"id":"1.229554900","rc":[{"atl":[[2.98,3]],"id":67532289}],"con":true,"img":false}]}
{"op":"mcm","clk":"11450098438","pt":1717317987822,"mc":[{"id":"1.229554900","rc":[{"atb":[[2.78,66.12]],"id":70003368},{"atl":[[10,13.07]],"id":70003368},{"atb":[[2.72,69.5]],"id":47208569},{"atb":[[17.5,0]],"id":49183855},{"atb":[[15.5,0]],"id":63027102},{"atl":[[3.65,42.44]],"id":67532289}],"con":true,"img":false}]}
{"op":"mcm","clk":"11450098444","pt":1717317987923,"mc":[{"id":"1.229554900","rc":[{"atb":[[2.46,0]],"id":70003368},{"atl":[[12,0]],"id":70003368},{"atb":[[2.38,0]],"id":47208569},{"atb":[[20,3.44]],"id":49183855},{"atb":[[19,7.84]],"id":63027102},{"atl":[[4.6,0]],"id":67532289}],"con":true,"img":false}]}
{"op":"mcm","clk":"11450098489","pt":1717317988390,"mc":[{"id":"1.229554900","rc":[{"atb":[[21,1.21]],"id":49183855}],"con":true,"img":false}]}
{"op":"mcm","clk":"11450098765","pt":1717317992209,"mc":[{"id":"1.229554900","rc":[{"atl":[[2.98,0]],"id":67532289}],"con":true,"img":false}]}
{"op":"mcm","clk":"11450098780","pt":1717317992416,"mc":[{"id":"1.229554900","rc":[{"atl":[[2.96,3]],"id":67532289}],"con":true,"img":false}]}
{"op":"mcm","clk":"11450099409","pt":1717317999432,"mc":[{"id":"1.229554900","rc":[{"atb":[[22,2]],"id":49183855},{"atl":[[250,4.61]],"id":49183855},{"atb":[[27,2]],"id":63027102},{"atl":[[310,4.61]],"id":63027102}],"con":true,"img":false}]}
{"op":"mcm","clk":"11450099423","pt":1717317999533,"mc":[{"id":"1.229554900","rc":[{"atl":[[300,2.46]],"id":49183855},{"atl":[[320,2.43]],"id":63027102}],"con":true,"img":false}]}
{"op":"mcm","clk":"11450099428","pt":1717317999636,"mc":[{"id":"1.229554900","rc":[{"atl":[[250,2.61]],"id":49183855},{"atl":[[310,2.61]],"id":63027102}],"con":true,"img":false}]}
{"op":"mcm","clk":"11450099443","pt":1717317999754,"mc":[{"id":"1.229554900","rc":[{"atl":[[250,4.61]],"id":49183855}],"con":true,"img":false}]}
{"op":"mcm","clk":"11450099448","pt":1717317999798,"mc":[{"id":"1.229554900","rc":[{"atl":[[300,0.46]],"id":49183855}],"con":true,"img":false}]}
{"op":"mcm","clk":"11450099462","pt":1717317999917,"mc":[{"id":"1.229554900","rc":[{"atl":[[2.96,0]],"id":67532289}],"con":true,"img":false}]}
{"op":"mcm","clk":"11450099480","pt":1717318000112,"mc":[{"id":"1.229554900","rc":[{"atb":[[21,0]],"id":49183855}],"con":true,"img":false}]}
{"op":"mcm","clk":"11450099500","pt":1717318000227,"mc":[{"id":"1.229554900","rc":[{"atl":[[2.94,3]],"id":67532289}],"con":true,"img":false}]}
{"op":"mcm","clk":"11450100103","pt":1717318007725,"mc":[{"id":"1.229554900","rc":[{"atl":[[2.94,0]],"id":67532289}],"con":true,"img":false}]}
{"op":"mcm","clk":"11450100120","pt":1717318007930,"mc":[{"id":"1.229554900","rc":[{"atl":[[2.92,3]],"id":67532289}],"con":true,"img":false}]}
{"op":"mcm","clk":"11450100708","pt":1717318015521,"mc":[{"id":"1.229554900","rc":[{"atl":[[2.92,0]],"id":67532289}],"con":true,"img":false}]}
{"op":"mcm","clk":"11450100725","pt":1717318015736,"mc":[{"id":"1.229554900","rc":[{"atl":[[2.9,3]],"id":67532289}],"con":true,"img":false}]}
{"op":"mcm","clk":"11450101422","pt":1717318023374,"mc":[{"id":"1.229554900","rc":[{"atl":[[2.9,0]],"id":67532289}],"con":true,"img":false}]}
{"op":"mcm","clk":"11450101441","pt":1717318023581,"mc":[{"id":"1.229554900","rc":[{"atl":[[2.88,3]],"id":67532289}],"con":true,"img":false}]}
{"op":"mcm","clk":"11450101651","pt":1717318025769,"mc":[{"id":"1.229554900","rc":[{"atb":[[2.88,0]],"id":70003368}],"con":true,"img":false}]}
{"op":"mcm","clk":"11450102133","pt":1717318031077,"mc":[{"id":"1.229554900","rc":[{"atl":[[2.88,0]],"id":67532289}],"con":true,"img":false}]}
{"op":"mcm","clk":"11450102159","pt":1717318031290,"mc":[{"id":"1.229554900","rc":[{"atl":[[2.86,3]],"id":67532289}],"con":true,"img":false}]}
{"op":"mcm","clk":"11450102780","pt":1717318037879,"mc":[{"id":"1.229554900","rc":[{"atb":[[23,0]],"id":63027102}],"con":true,"img":false}]}
{"op":"mcm","clk":"11450102791","pt":1717318037981,"mc":[{"id":"1.229554900","rc":[{"atb":[[28,2.67]],"id":63027102}],"con":true,"img":false}]}
{"op":"mcm","clk":"11450102883","pt":1717318038867,"mc":[{"id":"1.229554900","rc":[{"atl":[[2.86,0]],"id":67532289}],"con":true,"img":false}]}
{"op":"mcm","clk":"11450102916","pt":1717318039188,"mc":[{"id":"1.229554900","rc":[{"atl":[[2.84,3]],"id":67532289}],"con":true,"img":false}]}
{"op":"mcm","clk":"11450103611","pt":1717318046658,"mc":[{"id":"1.229554900","rc":[{"spn":96.0,"spf":"NaN","id":49183855},{"spn":124.0,"spf":"NaN","id":63027102},{"atl":[[2.84,0]],"id":67532289}],"con":true,"img":false}]}
{"op":"mcm","clk":"11450103628","pt":1717318046864,"mc":[{"id":"1.229554900","rc":[{"atl":[[2.82,3]],"id":67532289}],"con":true,"img":false}]}
{"op":"mcm","clk":"11450104324","pt":1717318054392,"mc":[{"id":"1.229554900","rc":[{"atl":[[2.82,0]],"id":67532289}],"con":true,"img":false}]}
{"op":"mcm","clk":"11450104349","pt":1717318054601,"mc":[{"id":"1.229554900","rc":[{"atl":[[2.8,3]],"id":67532289}],"con":true,"img":false}]}
{"op":"mcm","clk":"11450105054","pt":1717318062189,"mc":[{"id":"1.229554900","rc":[{"atl":[[2.8,0]],"id":67532289}],"con":true,"img":false}]}
{"op":"mcm","clk":"11450105072","pt":1717318062399,"mc":[{"id":"1.229554900","rc":[{"atl":[[2.78,3]],"id":67532289}],"con":true,"img":false}]}
{"op":"mcm","clk":"11450105795","pt":1717318069908,"mc":[{"id":"1.229554900","rc":[{"atl":[[2.78,0]],"id":67532289}],"con":true,"img":false}]}
{"op":"mcm","clk":"11450105819","pt":1717318070216,"mc":[{"id":"1.229554900","rc":[{"atl":[[2.76,3]],"id":67532289}],"con":true,"img":false}]}
{"op":"mcm","clk":"11450106543","pt":1717318077719,"mc":[{"id":"1.229554900","rc":[{"atl":[[2.76,0]],"id":67532289}],"con":true,"img":false}]}
{"op":"mcm","clk":"11450106560","pt":1717318077923,"mc":[{"id":"1.229554900","rc":[{"atl":[[2.74,3]],"id":67532289}],"con":true,"img":false}]}
{"op":"mcm","clk":"11450107223","pt":1717318085457,"mc":[{"id":"1.229554900","rc":[{"atl":[[2.74,0]],"id":67532289}],"con":true,"img":false}]}
{"op":"mcm","clk":"11450107246","pt":1717318085617,"mc":[{"id":"1.229554900","rc":[{"atl":[[2.72,3]],"id":67532289}],"con":true,"img":false}]}
{"op":"mcm","clk":"11450107916","pt":1717318093233,"mc":[{"id":"1.229554900","rc":[{"atl":[[2.72,0]],"id":67532289}],"con":true,"img":false}]}
{"op":"mcm","clk":"11450107937","pt":1717318093439,"mc":[{"id":"1.229554900","rc":[{"atl":[[2.7,3]],"id":67532289}],"con":true,"img":false}]}
{"op":"mcm","clk":"11450107944","pt":1717318093535,"mc":[{"id":"1.229554900","rc":[{"atl":[[7.4,0]],"id":47208569}],"con":true,"img":false}]}
{"op":"mcm","clk":"11450107963","pt":1717318093850,"mc":[{"id":"1.229554900","rc":[{"atb":[[3.3,0]],"id":47208569},{"atl":[[3,0]],"id":67532289}],"con":true,"img":false}]}
{"op":"mcm","clk":"11450107988","pt":1717318094160,"mc":[{"id":"1.229554900","rc":[{"atb":[[24,0]],"id":63027102},{"atb":[[1.82,0]],"id":67532289}],"con":true,"img":false}]}
{"op":"mcm","clk":"11450108004","pt":1717318094323,"mc":[{"id":"1.229554900","rc":[{"atl":[[1000,2.7]],"id":47208569}],"con":true,"img":false}]}
{"op":"mcm","clk":"11450108021","pt":1717318094531,"mc":[{"id":"1.229554900","rc":[{"atl":[[1000,3.55]],"id":67532289}],"con":true,"img":false}]}
{"op":"mcm","clk":"11450108051","pt":1717318094836,"mc":[{"id":"1.229554900","rc":[{"atl":[[7.8,0]],"id":70003368},{"atb":[[1.27,1.7]],"id":63027102}],"con":true,"img":false}]}
{"op":"mcm","clk":"11450108074","pt":1717318095143,"mc":[{"id":"1.229554900","rc":[{"atb":[[1.03,7.49]],"id":47208569}],"con":true,"img":false}]}
{"op":"mcm","clk":"11450108101","pt":1717318095352,"mc":[{"id":"1.229554900","rc":[{"atb":[[1.02,1.7]],"id":67532289}],"con":true,"img":false}]}
{"op":"mcm","clk":"11450108110","pt":1717318095453,"mc":[{"id":"1.229554900","rc":[{"atl":[[1000,1.11]],"id":47208569}],"con":true,"img":false}]}
{"op":"mcm","clk":"11450108142","pt":1717318095868,"mc":[{"id":"1.229554900","rc":[{"atl":[[1000,2.16]],"id":67532289}],"con":true,"img":false}]}
{"op":"mcm","clk":"11450108162","pt":1717318096028,"mc":[{"id":"1.229554900","rc":[{"atb":[[1.27,0.02]],"id":63027102}],"con":true,"img":false}]}
{"op":"mcm","clk":"11450108174","pt":1717318096133,"mc":[{"id":"1.229554900","rc":[{"atl":[[1000,1]],"id":47208569}],"con":true,"img":false}]}
{"op":"mcm","clk":"11450108189","pt":1717318096239,"mc":[{"id":"1.229554900","rc":[{"atl":[[7.4,0.11]],"id":47208569}],"con":true,"img":false}]}
{"op":"mcm","clk":"11450108218","pt":1717318096545,"mc":[{"id":"1.229554900","rc":[{"atb":[[1.03,6.04]],"id":47208569}],"con":true,"img":false}]}
{"op":"mcm","clk":"11450108226","pt":1717318096648,"mc":[{"id":"1.229554900","rc":[{"atb":[[1.02,0.46]],"id":67532289}],"con":true,"img":false}]}
{"op":"mcm","clk":"11450108246","pt":1717318096854,"mc":[{"id":"1.229554900","rc":[{"atb":[[20,3.4]],"id":49183855}],"con":true,"img":false}]}
{"op":"mcm","clk":"11450108254","pt":1717318096966,"mc":[{"id":"1.229554900","rc":[{"atl":[[1000,3.55]],"id":70003368}],"con":true,"img":false}]}
{"op":"mcm","clk":"11450108294","pt":1717318097468,"mc":[{"id":"1.229554900","rc":[{"atl":[[1000,1.85]],"id":67532289}],"con":true,"img":false}]}
{"op":"mcm","clk":"11450108302","pt":1717318097524,"mc":[{"id":"1.229554900","rc":[{"atl":[[2.68,0.31]],"id":67532289}],"con":true,"img":false}]}
{"op":"mcm","clk":"11450108332","pt":1717318097945,"mc":[{"id":"1.229554900","rc":[{"atb":[[3.4,0]],"id":70003368}],"con":true,"img":false}]}
{"op":"mcm","clk":"11450108351","pt":1717318098247,"mc":[{"id":"1.229554900","rc":[{"atb":[[1.27,0]],"id":63027102}],"con":true,"img":false}]}
{"op":"mcm","clk":"11450108361","pt":1717318098352,"mc":[{"id":"1.229554900","rc":[{"atb":[[29,0.02]],"id":63027102}],"con":true,"img":false}]}
{"op":"mcm","clk":"11450108387","pt":1717318098653,"mc":[{"id":"1.229554900","rc":[{"atb":[[1.03,5.78]],"id":47208569}],"con":true,"img":false}]}
{"op":"mcm","clk":"11450108396","pt":1717318098762,"mc":[{"id":"1.229554900","rc":[{"atb":[[3.3,0.25]],"id":47208569}],"con":true,"img":false}]}
{"op":"mcm","clk":"11450108421","pt":1717318099068,"mc":[{"id":"1.229554900","rc":[{"atb":[[1.02,0]],"id":67532289}],"con":true,"img":false}]}
{"op":"mcm","clk":"11450108430","pt":1717318099170,"mc":[{"id":"1.229554900","rc":[{"atb":[[1.82,0.46]],"id":67532289}],"con":true,"img":false}]}
{"op":"mcm","clk":"11450108461","pt":1717318099437,"mc":[{"id":"1.229554900","rc":[{"atb":[[1.2,1.7]],"id":49183855}],"con":true,"img":false}]}
{"op":"mcm","clk":"11450108484","pt":1717318099742,"mc":[{"id":"1.229554900","rc":[{"atl":[[1000,1.96]],"id":70003368}],"con":true,"img":false}]}
{"op":"mcm","clk":"11450108531","pt":1717318100467,"mc":[{"id":"1.229554900","rc":[{"atb":[[1.03,7.49]],"id":70003368}],"con":true,"img":false}]}
{"op":"mcm","clk":"11450108554","pt":1717318100781,"mc":[{"id":"1.229554900","rc":[{"atl":[[1000,1.85]],"id":70003368},{"atb":[[1.2,0.03]],"id":49183855}],"con":true,"img":false}]}
{"op":"mcm","clk":"11450108577","pt":1717318100940,"mc":[{"id":"1.229554900","rc":[{"atl":[[7.8,0.11]],"id":70003368}],"con":true,"img":false}]}
{"op":"mcm","clk":"11450108591","pt":1717318101150,"mc":[{"id":"1.229554900","rc":[{"atl":[[2.7,0]],"id":67532289}],"con":true,"img":false}]}
{"op":"mcm","clk":"11450108608","pt":1717318101350,"mc":[{"id":"1.229554900","rc":[{"atl":[[7.6,2.53]],"id":47208569},{"atl":[[2.68,3.31]],"id":67532289}],"con":true,"img":false}]}
{"op":"mcm","clk":"11450108614","pt":1717318101453,"mc":[{"id":"1.229554900","rc":[{"atb":[[1.03,6.03]],"id":70003368},{"atb":[[1.2,0]],"id":49183855}],"con":true,"img":false}]}
{"op":"mcm","clk":"11450108620","pt":1717318101560,"mc":[{"id":"1.229554900","rc":[{"atb":[[23,0.03]],"id":49183855}],"con":true,"img":false}]}
{"op":"mcm","clk":"11450108676","pt":1717318102236,"mc":[{"id":"1.229554900","rc":[{"atb":[[1.03,5.78]],"id":70003368}],"con":true,"img":false}]}
{"op":"mcm","clk":"11450108688","pt":1717318102343,"mc":[{"id":"1.229554900","rc":[{"atb":[[3.4,0.24]],"id":70003368}],"con":true,"img":false}]}
{"op":"mcm","clk":"11450109294","pt":1717318108862,"mc":[{"id":"1.229554900","rc":[{"spn":96.5,"spf":"NaN","id":49183855},{"spn":124.5,"spf":"NaN","id":63027102},{"atl":[[2.68,0.31]],"id":67532289},{"spn":2.25,"spf":"NaN","id":67532289}],"con":true,"img":false}]}
{"op":"mcm","clk":"11450109314","pt":1717318109073,"mc":[{"id":"1.229554900","rc":[{"atl":[[2.66,3]],"id":67532289}],"con":true,"img":false}]}
{"op":"mcm","clk":"11450109590","pt":1717318112450,"mc":[{"id":"1.229554900","rc":[{"atb":[[22,0]],"id":49183855},{"atl":[[250,2.61]],"id":49183855},{"atb":[[27,0]],"id":63027102},{"atl":[[320,0.43]],"id":63027102}],"con":true,"img":false}]}
{"op":"mcm","clk":"11450109964","pt":1717318116551,"mc":[{"id":"1.229554900","rc":[{"atl":[[3.3,5.83]],"id":67532289}],"con":true,"img":false}]}
{"op":"mcm","clk":"11450109977","pt":1717318116660,"mc":[{"id":"1.229554900","rc":[{"atl":[[2.66,0]],"id":67532289}],"con":true,"img":false}]}
{"op":"mcm","clk":"11450109995","pt":1717318116864,"mc":[{"id":"1.229554900","rc":[{"atl":[[2.64,3]],"id":67532289}],"con":true,"img":false}]}
{"op":"mcm","clk":"11450110073","pt":1717318117787,"mc":[{"id":"1.229554900","rc":[{"atb":[[28,0]],"id":63027102}],"con":true,"img":false}]}
{"op":"mcm","clk":"11450110081","pt":1717318117889,"mc":[{"id":"1.229554900","rc":[{"atb":[[23,2.67]],"id":63027102}],"con":true,"img":false}]}
{"op":"mcm","clk":"11450110623","pt":1717318124571,"mc":[{"id":"1.229554900","rc":[{"atl":[[2.64,0]],"id":67532289}],"con":true,"img":false}]}
{"op":"mcm","clk":"11450110637","pt":1717318124773,"mc":[{"id":"1.229554900","rc":[{"atl":[[2.62,3]],"id":67532289}],"con":true,"img":false}]}
{"op":"mcm","clk":"11450110948","pt":1717318128199,"mc":[{"id":"1.229554900","rc":[{"atb":[[21,1.21]],"id":49183855}],"con":true,"img":false}]}
{"op":"mcm","clk":"11450111163","pt":1717318130681,"mc":[{"id":"1.229554900","rc":[{"atb":[[2.86,0],[2.96,0],[2.76,0]],"id":70003368},{"atl":[[10.5,0],[15.5,0]],"id":70003368},{"atb":[[2.8,0],[2.9,0],[2.7,0]],"id":47208569},{"atl":[[10,0],[15,0]],"id":47208569},{"atb":[[14.5,0],[17,0],[19.5,0]],"id":49183855},{"atl":[[300,0],[400,0]],"id":49183855},{"atb":[[16,0],[18.5,0],[22,0]],"id":63027102},{"atl":[[320,0],[420,0]],"id":63027102},{"atb":[[1.63,0],[1.58,0],[1.68,0]],"id":67532289},{"atl":[[3.7,0],[4.4,0]],"id":67532289}],"con":true,"img":false}]}
{"op":"mcm","clk":"11450111249","pt":1717318131872,"mc":[{"id":"1.229554900","rc":[{"atl":[[8,2.4]],"id":70003368}],"con":true,"img":false}]}
{"op":"mcm","clk":"11450111274","pt":1717318132292,"mc":[{"id":"1.229554900","rc":[{"atl":[[2.62,0]],"id":67532289}],"con":true,"img":false}]}
{"op":"mcm","clk":"11450111288","pt":1717318132497,"mc":[{"id":"1.229554900","rc":[{"atl":[[2.6,3]],"id":67532289}],"con":true,"img":false}]}
{"op":"mcm","clk":"11450111778","pt":1717318137800,"mc":[{"id":"1.229554900","rc":[{"atb":[[2.46,80.62]],"id":70003368},{"atl":[[12,9.8]],"id":70003368},{"atb":[[2.38,86.62]],"id":47208569},{"atl":[[4.6,26.78]],"id":67532289}],"con":true,"img":false}]}
{"op":"mcm","clk":"11450111789","pt":1717318137905,"mc":[{"id":"1.229554900","rc":[{"atb":[[2.98,0],[2.78,0]],"id":70003368},{"atl":[[10,0]],"id":70003368},{"atb":[[2.92,0],[2.72,0]],"id":47208569},{"atl":[[9.8,0]],"id":47208569},{"atb":[[20,0]],"id":49183855},{"atb":[[19,0],[23,0]],"id":63027102},{"atb":[[1.64,0]],"id":67532289},{"atl":[[3.65,0]],"id":67532289}],"con":true,"img":false}]}
{"op":"mcm","clk":"11450111803","pt":1717318138007,"mc":[{"id":"1.229554900","rc":[{"atb":[[2.82,29.84]],"id":70003368},{"atb":[[2.74,30.83]],"id":47208569},{"atl":[[11,13.58]],"id":47208569},{"atb":[[17.5,3.4]],"id":49183855},{"atb":[[20,2.67],[15.5,7.84]],"id":63027102},{"atb":[[1.57,66]],"id":67532289}],"con":true,"img":false}]}
{"op":"mcm","clk":"11450111840","pt":1717318138418,"mc":[{"id":"1.229554900","rc":[{"atb":[[21,0]],"id":49183855}],"con":true,"img":false}]}
{"op":"mcm","clk":"11450111973","pt":1717318140123,"mc":[{"id":"1.229554900","rc":[{"atl":[[2.6,0]],"id":67532289}],"con":true,"img":false}]}
{"op":"mcm","clk":"11450111995","pt":1717318140395,"mc":[{"id":"1.229554900","rc":[{"atl":[[2.58,3]],"id":67532289}],"con":true,"img":false}]}
{"op":"mcm","clk":"11450112417","pt":1717318144488,"mc":[{"id":"1.229554900","rc":[{"atb":[[1.17,100]],"id":70003368},{"atb":[[1.17,100]],"id":47208569},{"atb":[[1.17,100]],"id":49183855},{"atb":[[1.17,100]],"id":63027102}],"con":true,"img":false}]}
{"op":"mcm","clk":"11450112603","pt":1717318146511,"mc":[{"id":"1.229554900","rc":[{"atb":[[2.98,0]],"id":47208569},{"atb":[[1.7,0]],"id":67532289}],"con":true,"img":false}]}
{"op":"mcm","clk":"11450112621","pt":1717318146622,"mc":[{"id":"1.229554900","rc":[{"atb":[[2.88,4.17]],"id":70003368}],"con":true,"img":false}]}
{"op":"mcm","clk":"11450112757","pt":1717318147921,"mc":[{"id":"1.229554900","rc":[{"atl":[[2.58,0]],"id":67532289}],"con":true,"img":false}]}
{"op":"mcm","clk":"11450112781","pt":1717318148137,"mc":[{"id":"1.229554900","rc":[{"atl":[[2.56,3]],"id":67532289}],"con":true,"img":false}]}
{"op":"mcm","clk":"11450113443","pt":1717318155039,"mc":[{"id":"1.229554900","rc":[{"atl":[[7.6,0]],"id":47208569}],"con":true,"img":false}]}
{"op":"mcm","clk":"11450113490","pt":1717318155613,"mc":[{"id":"1.229554900","rc":[{"atl":[[2.56,0]],"id":67532289}],"con":true,"img":false}]}
{"op":"mcm","clk":"11450113508","pt":1717318155822,"mc":[{"id":"1.229554900","rc":[{"atl":[[2.54,3]],"id":67532289}],"con":true,"img":false}]}
{"op":"mcm","clk":"11450113649","pt":1717318157531,"mc":[{"id":"1.229554900","rc":[{"atb":[[20,2.17],[29,0]],"id":63027102},{"trd":[[20,0.99],[29,0.05]],"ltp":20.0,"tv":1.04,"id":63027102}],"con":true,"img":false}]}
{"op":"mcm","clk":"11450113678","pt":1717318157843,"mc":[{"id":"1.229554900","rc":[{"atl":[[12,0],[8.8,0]],"id":70003368},{"atl":[[8.2,0],[11,0]],"id":47208569},{"atl":[[170,0]],"id":49183855},{"atb":[[20,0],[13,9.94],[15.5,0]],"id":63027102},{"atl":[[300,0.08]],"id":63027102},{"atl":[[4.6,0],[3.5,0]],"id":67532289}],"con":true,"img":false}]}
{"op":"mcm","clk":"11450113689","pt":1717318157946,"mc":[{"id":"1.229554900","rc":[{"atl":[[10.5,6.84],[13,9.8]],"id":70003368},{"atl":[[9.6,7.19],[32,3.23],[11.5,13.58]],"id":47208569},{"atl":[[200,0.31]],"id":49183855},{"atb":[[17,2.17]],"id":63027102},{"atl":[[3.95,23.87],[5.2,26.78]],"id":67532289}],"con":true,"img":false}]}
{"op":"mcm","clk":"11450113696","pt":1717318158051,"mc":[{"id":"1.229554900","rc":[{"atl":[[12,0]],"id":47208569}],"con":true,"img":false}]}
{"op":"mcm","clk":"11450113706","pt":1717318158095,"mc":[{"id":"1.229554900","rc":[{"atl":[[32,0],[11.5,22.67]],"id":47208569}],"con":true,"img":false}]}
{"op":"mcm","clk":"11450113969","pt":1717318161047,"mc":[{"id":"1.229554900","rc":[{"atl":[[1000,4.2]],"id":70003368},{"atb":[[2.8,4.36]],"id":47208569},{"atl":[[1000,3.35]],"id":47208569},{"atb":[[1.59,13.3]],"id":67532289}],"con":true,"img":false}]}
{"op":"mcm","clk":"11450113988","pt":1717318161209,"mc":[{"id":"1.229554900","rc":[{"atl":[[1000,3.24]],"id":70003368},{"atl":[[1000,2.51]],"id":47208569}],"con":true,"img":false}]}
{"op":"mcm","clk":"11450114006","pt":1717318161413,"mc":[{"id":"1.229554900","rc":[{"atl":[[1000,1.85]],"id":70003368},{"atb":[[1.12,0],[1.19,100]],"id":47208569}],"con":true,"img":false}]}
{"op":"mcm","clk":"11450114016","pt":1717318161511,"mc":[{"id":"1.229554900","rc":[{"atl":[[9.6,1.38]],"id":70003368}],"con":true,"img":false}]}
{"op":"mcm","clk":"11450114034","pt":1717318161724,"mc":[{"id":"1.229554900","rc":[{"atl":[[1000,1]],"id":47208569}],"con":true,"img":false}]}
{"op":"mcm","clk":"11450114044","pt":1717318161826,"mc":[{"id":"1.229554900","rc":[{"atl":[[8.8,1.51]],"id":47208569}],"con":true,"img":false}]}
{"op":"mcm","clk":"11450114193","pt":1717318163442,"mc":[{"id":"1.229554900","rc":[{"atl":[[2.54,0]],"id":67532289}],"con":true,"img":false}]}
{"op":"mcm","clk":"11450114229","pt":1717318163851,"mc":[{"id":"1.229554900","rc":[{"atl":[[2.52,3]],"id":67532289}],"con":true,"img":false}]}
{"op":"mcm","clk":"11450114506","pt":1717318166854,"mc":[{"id":"1.229554900","rc":[{"atb":[[2.76,118.78],[2.86,112.39],[2.96,53.33]],"id":70003368},{"atl":[[10.5,21.51],[15.5,14.41]],"id":70003368},{"atb":[[2.8,120.51],[2.9,55.01],[2.7,122.97]],"id":47208569},{"atl":[[10,15.48],[15,14.93]],"id":47208569},{"atb":[[14.5,15.48],[17,13.06],[19.5,5.65]],"id":49183855},{"atl":[[300,0.46],[400,0.52]],"id":49183855},{"atb":[[16,13.93],[18.5,11.94],[22,4.97]],"id":63027102},{"atl":[[320,0.43],[420,0.49]],"id":63027102},{"atb":[[1.63,331.84],[1.58,360.45],[1.68,153.71]],"id":67532289},{"atl":[[3.7,51.62],[4.4,61.48]],"id":67532289}],"con":true,"img":false}]}
{"op":"mcm","clk":"11450114602","pt":1717318167841,"mc":[{"id":"1.229554900","rc":[{"atb":[[17,2.76]],"id":63027102},{"atl":[[190,0.3],[220,0]],"id":63027102},{"atb":[[1.57,0]],"id":67532289}],"con":true,"img":false}]}
{"op":"mcm","clk":"11450114613","pt":1717318167945,"mc":[{"id":"1.229554900","rc":[{"atb":[[1.61,66]],"id":67532289}],"con":true,"img":false}]}
{"op":"mcm","clk":"11450115155","pt":1717318174140,"mc":[{"id":"1.229554900","rc":[{"atb":[[3.1,16.94]],"id":70003368},{"spn":111.5,"spf":"NaN","id":49183855},{"spn":106.0,"spf":"NaN","id":63027102},{"spn":2.17,"spf":"NaN","id":67532289}],"con":true,"img":false}]}
{"op":"mcm","clk":"11450115165","pt":1717318174236,"mc":[{"id":"1.229554900","rc":[{"atb":[[21,2.5]],"id":49183855}],"con":true,"img":false}]}
{"op":"mcm","clk":"11450115175","pt":1717318174345,"mc":[{"id":"1.229554900","rc":[{"atb":[[1.65,31.81]],"id":67532289}],"con":true,"img":false}]}
{"op":"mcm","clk":"11450115186","pt":1717318174443,"mc":[{"id":"1.229554900","rc":[{"atb":[[3,17.5]],"id":47208569}],"con":true,"img":false}]}
{"op":"mcm","clk":"11450115195","pt":1717318174544,"mc":[{"id":"1.229554900","rc":[{"atb":[[20,2.62]],"id":63027102}],"con":true,"img":false}]}
{"op":"mcm","clk":"11450115452","pt":1717318177858,"mc":[{"id":"1.229554900","rc":[{"atb":[[2.82,0]],"id":70003368},{"atb":[[2.74,0]],"id":47208569},{"atb":[[17.5,0]],"id":49183855}],"con":true,"img":false}]}
{"op":"mcm","clk":"11450115458","pt":1717318177952,"mc":[{"id":"1.229554900","rc":[{"atb":[[3.15,29.84]],"id":70003368},{"atb":[[3.05,30.83]],"id":47208569},{"atb":[[20,3.4]],"id":49183855}],"con":true,"img":false}]}
{"op":"mcm","clk":"11450115721","pt":1717318181237,"mc":[{"id":"1.229554900","rc":[{"atb":[[22,1.15]],"id":49183855}],"con":true,"img":false}]}
{"op":"mcm","clk":"11450115731","pt":1717318181335,"mc":[{"id":"1.229554900","rc":[{"atl":[[6.4,23.15],[5.8,10.42],[11,9.81],[13.5,0],[5.6,4.35],[6,15]],"id":70003368},{"atl":[[8,10.71],[8.4,16.89],[7.2,3.23],[7.6,7.58]],"id":47208569},{"atb":[[2.34,0],[3.15,44.64]],"id":49183855},{"atl":[[5.3,0],[7.2,16.13]],"id":67532289}],"con":true,"img":false}]}
{"op":"mcm","clk":"11450115748","pt":1717318181548,"mc":[{"id":"1.229554900","rc":[{"atb":[[22,3.15]],"id":49183855},{"atl":[[250,4.61]],"id":49183855},{"atb":[[27,2]],"id":63027102}],"con":true,"img":false}]}
{"op":"mcm","clk":"11450115755","pt":1717318181646,"mc":[{"id":"1.229554900","rc":[{"atl":[[300,2.46],[250,2.61]],"id":49183855}],"con":true,"img":false}]}
{"op":"mcm","clk":"11450115767","pt":1717318181751,"mc":[{"id":"1.229554900","rc":[{"atl":[[300,0.46],[250,4.61]],"id":49183855}],"con":true,"img":false}]}
{"op":"mcm","clk":"11450115923","pt":1717318183474,"mc":[{"id":"1.229554900","rc":[{"atb":[[2.44,0],[2.58,63.29]],"id":70003368},{"atb":[[1.19,0],[1.13,110.04]],"id":47208569},{"atl":[[550,0],[470,2]],"id":49183855},{"atl":[[300,2.08]],"id":63027102}],"con":true,"img":false}]}
{"op":"mcm","clk":"11450115931","pt":1717318183573,"mc":[{"id":"1.229554900","rc":[{"atl":[[10,26.59],[11.5,13.58]],"id":47208569}],"con":true,"img":false}]}
{"op":"mcm","clk":"11450115941","pt":1717318183635,"mc":[{"id":"1.229554900","rc":[{"atb":[[1.37,100],[1.13,0]],"id":47208569}],"con":true,"img":false}]}
{"op":"mcm","clk":"11450116371","pt":1717318187833,"mc":[{"id":"1.229554900","rc":[{"atl":[[10.5,14.66]],"id":70003368}],"con":true,"img":false}]}
{"op":"mcm","clk":"11450116383","pt":1717318187935,"mc":[{"id":"1.229554900","rc":[{"atl":[[10,6.84]],"id":70003368}],"con":true,"img":false}]}
{"op":"mcm","clk":"11450116842","pt":1717318193164,"mc":[{"id":"1.229554900","rc":[{"atl":[[3.3,0]],"id":67532289}],"con":true,"img":false}]}
{"op":"mcm","clk":"11450116863","pt":1717318193370,"mc":[{"id":"1.229554900","rc":[{"atb":[[2.94,5.83]],"id":47208569},{"atb":[[1.69,16.43]],"id":67532289}],"con":true,"img":false}]}
{"op":"mcm","clk":"11450116893","pt":1717318193780,"mc":[{"id":"1.229554900","rc":[{"atb":[[3,5.67]],"id":70003368}],"con":true,"img":false}]}
{"op":"mcm","clk":"11450117281","pt":1717318197882,"mc":[{"id":"1.229554900","rc":[{"atb":[[1.61,0]],"id":67532289},{"atl":[[3.95,0]],"id":67532289}],"con":true,"img":false}]}
{"op":"mcm","clk":"11450117286","pt":1717318197989,"mc":[{"id":"1.229554900","rc":[{"atb":[[22,3.87]],"id":49183855},{"atb":[[1.03,8.14]],"id":63027102},{"atb":[[1.69,82.44]],"id":67532289},{"atl":[[3.65,23.87]],"id":67532289}],"con":true,"img":false}]}
{"op":"mcm","clk":"11450117310","pt":1717318198299,"mc":[{"id":"1.229554900","rc":[{"atb":[[3.3,6.18]],"id":70003368},{"atb":[[3.2,6.29]],"id":47208569}],"con":true,"img":false}]}
{"op":"mcm","clk":"11450117336","pt":1717318198555,"mc":[{"id":"1.229554900","rc":[{"atb":[[1.03,6.36]],"id":63027102}],"con":true,"img":false}]}
{"op":"mcm","clk":"11450117356","pt":1717318198870,"mc":[{"id":"1.229554900","rc":[{"atb":[[1.03,5.78]],"id":63027102}],"con":true,"img":false}]}
{"op":"mcm","clk":"11450117368","pt":1717318198971,"mc":[{"id":"1.229554900","rc":[{"atb":[[27,2.58]],"id":63027102}],"con":true,"img":false}]}
{"op":"mcm","clk":"11450117878","pt":1717318204679,"mc":[{"id":"1.229554900","rc":[{"atb":[[1.02,108.02]],"id":63027102}],"con":true,"img":false}]}
{"op":"mcm","clk":"11450117888","pt":1717318204782,"mc":[{"id":"1.229554900","rc":[{"atb":[[1.02,2.35]],"id":49183855}],"con":true,"img":false}]}
{"op":"mcm","clk":"11450117929","pt":1717318205197,"mc":[{"id":"1.229554900","rc":[{"atl":[[60,5]],"id":67532289}],"con":true,"img":false}]}
{"op":"mcm","clk":"11450118049","pt":1717318206761,"mc":[{"id":"1.229554900","rc":[{"atb":[[1.02,106.05]],"id":63027102}],"con":true,"img":false}]}
{"op":"mcm","clk":"11450118121","pt":1717318207485,"mc":[{"id":"1.229554900","rc":[{"atb":[[1.02,0.39]],"id":49183855}],"con":true,"img":false}]}
{"op":"mcm","clk":"11450118158","pt":1717318207896,"mc":[{"id":"1.229554900","rc":[{"atb":[[2.98,59.45],[2.46,0]],"id":70003368},{"atb":[[2.92,62.26],[2.38,0]],"id":47208569},{"atl":[[11.5,0],[9.6,0]],"id":47208569},{"atb":[[15,0],[20,5.77]],"id":49183855},{"atb":[[13,0],[16.5,7.32],[17,0],[23,2.77]],"id":63027102},{"atb":[[1.53,0]],"id":67532289},{"atl":[[4.3,34.08],[5.2,0]],"id":67532289}],"con":true,"img":false}]}
{"op":"mcm","clk":"11450118168","pt":1717318208006,"mc":[{"id":"1.229554900","rc":[{"atl":[[9.4,7.19],[9.8,13.58]],"id":47208569},{"atb":[[23,3.43]],"id":49183855},{"atb":[[1.59,225.53]],"id":67532289}],"con":true,"img":false}]}
{"op":"mcm","clk":"11450118189","pt":1717318208211,"mc":[{"id":"1.229554900","rc":[{"atb":[[22,0.71],[24,2]],"id":49183855}],"con":true,"img":false}]}
{"op":"mcm","clk":"11450118436","pt":1717318211271,"mc":[{"id":"1.229554900","rc":[{"atb":[[1.02,105.66]],"id":63027102}],"con":true,"img":false}]}
{"op":"mcm","clk":"11450118445","pt":1717318211373,"mc":[{"id":"1.229554900","rc":[{"atb":[[28,0.39]],"id":63027102}],"con":true,"img":false}]}
{"op":"mcm","clk":"11450118478","pt":1717318211787,"mc":[{"id":"1.229554900","rc":[{"atb":[[1.02,0]],"id":49183855}],"con":true,"img":false}]}
{"op":"mcm","clk":"11450118488","pt":1717318211891,"mc":[{"id":"1.229554900","rc":[{"atb":[[23,3.82]],"id":49183855}],"con":true,"img":false}]}
{"op":"mcm","clk":"11450118584","pt":1717318213078,"mc":[{"id":"1.229554900","rc":[{"atb":[[1.02,2.35]],"id":70003368}],"con":true,"img":false}]}
{"op":"mcm","clk":"11450118609","pt":1717318213391,"mc":[{"id":"1.229554900","rc":[{"atb":[[1.02,2.35]],"id":47208569}],"con":true,"img":false}]}
{"op":"mcm","clk":"11450118732","pt":1717318214847,"mc":[{"id":"1.229554900","rc":[{"atl":[[7.4,0]],"id":47208569}],"con":true,"img":false}]}
{"op":"mcm","clk":"11450118795","pt":1717318215479,"mc":[{"id":"1.229554900","rc":[{"atb":[[1.02,0.39]],"id":47208569}],"con":true,"img":false}]}
{"op":"mcm","clk":"11450118813","pt":1717318215680,"mc":[{"id":"1.229554900","rc":[{"atb":[[1.02,0.39]],"id":70003368}],"con":true,"img":false}]}
{"op":"mcm","clk":"11450118831","pt":1717318215889,"mc":[{"id":"1.229554900","rc":[{"atb":[[3.3,0]],"id":47208569},{"atb":[[23,3.43]],"id":49183855},{"atl":[[2.68,0]],"id":67532289}],"con":true,"img":false}]}
{"op":"mcm","clk":"11450118892","pt":1717318216613,"mc":[{"id":"1.229554900","rc":[{"atb":[[1.02,2.35]],"id":49183855}],"con":true,"img":false}]}
{"op":"mcm","clk":"11450119012","pt":1717318217807,"mc":[{"id":"1.229554900","rc":[{"atl":[[310,0]],"id":63027102}],"con":true,"img":false}]}
{"op":"mcm","clk":"11450119023","pt":1717318217910,"mc":[{"id":"1.229554900","rc":[{"atl":[[260,2.61],[300,0.08],[320,2.43]],"id":63027102}],"con":true,"img":false}]}
{"op":"mcm","clk":"11450119043","pt":1717318218072,"mc":[{"id":"1.229554900","rc":[{"atl":[[300,0]],"id":63027102}],"con":true,"img":false}]}
{"op":"mcm","clk":"11450119172","pt":1717318219568,"mc":[{"id":"1.229554900","rc":[{"atb":[[1.02,0]],"id":47208569}],"con":true,"img":false}]}
{"op":"mcm","clk":"11450119181","pt":1717318219677,"mc":[{"id":"1.229554900","rc":[{"atb":[[3.1,0.39]],"id":47208569}],"con":true,"img":false}]}
{"op":"mcm","clk":"11450119220","pt":1717318220197,"mc":[{"id":"1.229554900","rc":[{"atb":[[1.02,0]],"id":70003368}],"con":true,"img":false}]}
{"op":"mcm","clk":"11450119231","pt":1717318220296,"mc":[{"id":"1.229554900","rc":[{"atb":[[3,6.06]],"id":70003368}],"con":true,"img":false}]}
{"op":"mcm","clk":"11450119257","pt":1717318220606,"mc":[{"id":"1.229554900","rc":[{"atl":[[7.8,0]],"id":70003368}],"con":true,"img":false}]}
{"op":"mcm","clk":"11450119268","pt":1717318220705,"mc":[{"id":"1.229554900","rc":[{"atb":[[1.82,0]],"id":67532289}],"con":true,"img":false}]}
{"op":"mcm","clk":"11450119329","pt":1717318221380,"mc":[{"id":"1.229554900","rc":[{"atl":[[1000,3.55]],"id":67532289}],"con":true,"img":false}]}
{"op":"mcm","clk":"11450119345","pt":1717318221585,"mc":[{"id":"1.229554900","rc":[{"atb":[[23,3.4],[1.02,0.39]],"id":49183855}],"con":true,"img":false}]}
{"op":"mcm","clk":"11450119353","pt":1717318221686,"mc":[{"id":"1.229554900","rc":[{"atl":[[1000,2.7]],"id":47208569}],"con":true,"img":false}]}
{"op":"mcm","clk":"11450119375","pt":1717318221996,"mc":[{"id":"1.229554900","rc":[{"atb":[[1.03,7.49]],"id":47208569}],"con":true,"img":false}]}
{"op":"mcm","clk":"11450119405","pt":1717318222415,"mc":[{"id":"1.229554900","rc":[{"atl":[[1000,3.55]],"id":70003368}],"con":true,"img":false}]}
{"op":"mcm","clk":"11450119414","pt":1717318222464,"mc":[{"id":"1.229554900","rc":[{"atl":[[1000,2.19]],"id":67532289}],"con":true,"img":false}]}
{"op":"mcm","clk":"11450119434","pt":1717318222672,"mc":[{"id":"1.229554900","rc":[{"atb":[[1.02,1.7]],"id":67532289}],"con":true,"img":false}]}
{"op":"mcm","clk":"11450119444","pt":1717318222782,"mc":[{"id":"1.229554900","rc":[{"atl":[[1000,1.11]],"id":47208569}],"con":true,"img":false}]}
{"op":"mcm","clk":"11450119473","pt":1717318222982,"mc":[{"id":"1.229554900","rc":[{"atb":[[3.4,0]],"id":70003368}],"con":true,"img":false}]}
{"op":"mcm","clk":"11450119507","pt":1717318223290,"mc":[{"id":"1.229554900","rc":[{"atl":[[1000,1.85]],"id":67532289}],"con":true,"img":false}]}
{"op":"mcm","clk":"11450119516","pt":1717318223396,"mc":[{"id":"1.229554900","rc":[{"atl":[[2.5,0.34]],"id":67532289}],"con":true,"img":false}]}
{"op":"mcm","clk":"11450119540","pt":1717318223601,"mc":[{"id":"1.229554900","rc":[{"atb":[[1.03,6.04]],"id":47208569}],"con":true,"img":false}]}
{"op":"mcm","clk":"11450119569","pt":1717318223862,"mc":[{"id":"1.229554900","rc":[{"atb":[[1.02,0]],"id":49183855}],"con":true,"img":false}]}
{"op":"mcm","clk":"11450119577","pt":1717318223965,"mc":[{"id":"1.229554900","rc":[{"atl":[[1000,1]],"id":47208569},{"atb":[[25,0.39]],"id":49183855}],"con":true,"img":false}]}
{"op":"mcm","clk":"11450119589","pt":1717318224067,"mc":[{"id":"1.229554900","rc":[{"atl":[[7,0.11]],"id":47208569}],"con":true,"img":false}]}
{"op":"mcm","clk":"11450119607","pt":1717318224273,"mc":[{"id":"1.229554900","rc":[{"atl":[[1000,2]],"id":70003368}],"con":true,"img":false}]}
{"op":"mcm","clk":"11450119614","pt":1717318224378,"mc":[{"id":"1.229554900","rc":[{"atb":[[1.2,1.7]],"id":49183855}],"con":true,"img":false}]}
{"op":"mcm","clk":"11450119654","pt":1717318224797,"mc":[{"id":"1.229554900","rc":[{"atb":[[1.03,5.78]],"id":47208569}],"con":true,"img":false}]}
{"op":"mcm","clk":"11450119661","pt":1717318224895,"mc":[{"id":"1.229554900","rc":[{"atb":[[3.3,0.25]],"id":47208569}],"con":true,"img":false}]}
{"op":"mcm","clk":"11450119670","pt":1717318224998,"mc":[{"id":"1.229554900","rc":[{"atb":[[1.02,0.46]],"id":67532289}],"con":true,"img":false}]}
{"op":"mcm","clk":"11450119700","pt":1717318225259,"mc":[{"id":"1.229554900","rc":[{"atl":[[1000,1.85]],"id":70003368}],"con":true,"img":false}]}
{"op":"mcm","clk":"11450119707","pt":1717318225364,"mc":[{"id":"1.229554900","rc":[{"atl":[[5.5,0.15]],"id":70003368}],"con":true,"img":false}]}
{"op":"mcm","clk":"11450119738","pt":1717318225680,"mc":[{"id":"1.229554900","rc":[{"atb":[[1.03,7.49]],"id":70003368}],"con":true,"img":false}]}
{"op":"mcm","clk":"11450119754","pt":1717318225925,"mc":[{"id":"1.229554900","rc":[{"atb":[[1.02,0]],"id":67532289}],"con":true,"img":false}]}
{"op":"mcm","clk":"11450119763","pt":1717318226018,"mc":[{"id":"1.229554900","rc":[{"atb":[[1.2,0.03]],"id":49183855}],"con":true,"img":false}]}
{"op":"mcm","clk":"11450119773","pt":1717318226124,"mc":[{"id":"1.229554900","rc":[{"atb":[[3,5.67]],"id":70003368},{"atb":[[1.82,0.46]],"id":67532289}],"con":true,"img":false}]}
{"op":"mcm","clk":"11450119779","pt":1717318226197,"mc":[{"id":"1.229554900","rc":[{"atb":[[1.02,2.35]],"id":70003368}],"con":true,"img":false}]}
{"op":"mcm","clk":"11450119817","pt":1717318226667,"mc":[{"id":"1.229554900","rc":[{"atb":[[1.2,0]],"id":49183855}],"con":true,"img":false}]}
{"op":"mcm","clk":"11450119826","pt":1717318226773,"mc":[{"id":"1.229554900","rc":[{"atb":[[1.03,6.03]],"id":70003368},{"atb":[[25,0.42]],"id":49183855}],"con":true,"img":false}]}
{"op":"mcm","clk":"11450119837","pt":1717318226875,"mc":[{"id":"1.229554900","rc":[{"atb":[[1.02,0.39]],"id":70003368}],"con":true,"img":false}]}
{"op":"mcm","clk":"11450119888","pt":1717318227390,"mc":[{"id":"1.229554900","rc":[{"atb":[[1.03,5.78]],"id":70003368}],"con":true,"img":false}]}
{"op":"mcm","clk":"11450119900","pt":1717318227496,"mc":[{"id":"1.229554900","rc":[{"atb":[[3.4,0.24]],"id":70003368}],"con":true,"img":false}]}
{"op":"mcm","clk":"11450119925","pt":1717318227803,"mc":[{"id":"1.229554900","rc":[{"atl":[[10.5,27.05]],"id":70003368}],"con":true,"img":false}]}
{"op":"mcm","clk":"11450119935","pt":1717318227861,"mc":[{"id":"1.229554900","rc":[{"atl":[[13,0]],"id":70003368}],"con":true,"img":false}]}
{"op":"mcm","clk":"11450119953","pt":1717318228066,"mc":[{"id":"1.229554900","rc":[{"atb":[[1.02,0]],"id":70003368}],"con":true,"img":false}]}
{"op":"mcm","clk":"11450119958","pt":1717318228220,"mc":[{"id":"1.229554900","rc":[{"atb":[[3.2,0.39]],"id":70003368}],"con":true,"img":false}]}
{"op":"mcm","clk":"11450120524","pt":1717318234588,"mc":[{"id":"1.229554900","rc":[{"atl":[[8,0]],"id":70003368},{"spn":4.45,"spf":"NaN","id":70003368},{"spn":5.15,"spf":"NaN","id":47208569},{"spn":112.5,"spf":"NaN","id":49183855},{"spn":109.0,"spf":"NaN","id":63027102},{"spn":2.16,"spf":"NaN","id":67532289}],"con":true,"img":false}]}
{"op":"mcm","clk":"11450120542","pt":1717318234793,"mc":[{"id":"1.229554900","rc":[{"atb":[[2.94,0]],"id":47208569}],"con":true,"img":false}]}
{"op":"mcm","clk":"11450120680","pt":1717318236398,"mc":[{"id":"1.229554900","rc":[{"atb":[[2.88,0]],"id":70003368},{"atb":[[2.8,116.14]],"id":47208569},{"atb":[[1.59,212.23]],"id":67532289}],"con":true,"img":false}]}
{"op":"mcm","clk":"11450121619","pt":1717318247798,"mc":[{"id":"1.229554900","rc":[{"atb":[[23,0]],"id":49183855}],"con":true,"img":false}]}
{"op":"mcm","clk":"11450121632","pt":1717318247898,"mc":[{"id":"1.229554900","rc":[{"atb":[[22,2.71],[24,0],[25,3.82]],"id":49183855}],"con":true,"img":false}]}
{"op":"mcm","clk":"11450121952","pt":1717318251712,"mc":[{"id":"1.229554900","rc":[{"atb":[[1.71,11.05]],"id":67532289}],"con":true,"img":false}]}
{"op":"mcm","clk":"11450122073","pt":1717318253010,"mc":[{"id":"1.229554900","rc":[{"atb":[[22,0.71],[26,2]],"id":49183855}],"con":true,"img":false}]}
{"op":"mcm","clk":"11450122193","pt":1717318254304,"mc":[{"id":"1.229554900","rc":[{"atb":[[25,3.43]],"id":49183855}],"con":true,"img":false}]}
{"op":"mcm","clk":"11450122310","pt":1717318255710,"mc":[{"id":"1.229554900","rc":[{"atb":[[1.02,2.35]],"id":49183855}],"con":true,"img":false}]}
{"op":"mcm","clk":"11450122385","pt":1717318256629,"mc":[{"id":"1.229554900","rc":[{"atb":[[1.02,0.39]],"id":49183855}],"con":true,"img":false}]}
{"op":"mcm","clk":"11450122472","pt":1717318257607,"mc":[{"id":"1.229554900","rc":[{"atb":[[1.02,0]],"id":49183855}],"con":true,"img":false}]}
{"op":"mcm","clk":"11450122483","pt":1717318257710,"mc":[{"id":"1.229554900","rc":[{"atb":[[27,0.39]],"id":49183855}],"con":true,"img":false}]}
{"op":"mcm","clk":"11450122697","pt":1717318260405,"mc":[{"id":"1.229554900","rc":[{"atl":[[22,3.49]],"id":70003368},{"atl":[[44,3.59],[22,3.49]],"id":47208569},{"atl":[[44,3.59],[22,3.49]],"id":67532289}],"con":true,"img":false}]}
{"op":"mcm","clk":"11450122703","pt":1717318260509,"mc":[{"id":"1.229554900","rc":[{"atl":[[44,3.59]],"id":70003368}],"con":true,"img":false}]}
{"op":"mcm","clk":"11450122721","pt":1717318260716,"mc":[{"id":"1.229554900","rc":[{"atb":[[3.2,2.61]],"id":47208569}],"con":true,"img":false}]}
{"op":"mcm","clk":"11450122747","pt":1717318261024,"mc":[{"id":"1.229554900","rc":[{"atb":[[3.3,2.61]],"id":70003368}],"con":true,"img":false}]}
{"op":"mcm","clk":"11450122765","pt":1717318261230,"mc":[{"id":"1.229554900","rc":[{"atb":[[3.2,6.29]],"id":47208569}],"con":true,"img":false}]}
{"op":"mcm","clk":"11450122789","pt":1717318261437,"mc":[{"id":"1.229554900","rc":[{"atb":[[3.3,6.18]],"id":70003368}],"con":true,"img":false}]}
{"op":"mcm","clk":"11450123381","pt":1717318268734,"mc":[{"id":"1.229554900","rc":[{"atb":[[2.76,0],[2.86,0],[2.96,0]],"id":70003368},{"atl":[[10.5,12.38],[15.5,0]],"id":70003368},{"atb":[[2.8,0],[2.9,0],[2.7,0]],"id":47208569},{"atl":[[10,11.11],[15,0]],"id":47208569},{"atb":[[14.5,0],[17,0],[19.5,0]],"id":49183855},{"atl":[[300,0],[400,0]],"id":49183855},{"atb":[[16,0],[18.5,0],[22,0]],"id":63027102},{"atl":[[320,2],[420,0]],"id":63027102},{"atb":[[1.58,0],[1.68,0],[1.63,0]],"id":67532289},{"atl":[[4.4,0],[3.7,0]],"id":67532289}],"con":true,"img":false}]}
{"op":"mcm","clk":"11450123621","pt":1717318271422,"mc":[{"id":"1.229554900","rc":[{"atb":[[1.69,66]],"id":67532289}],"con":true,"img":false}]}
{"op":"mcm","clk":"11450123640","pt":1717318271629,"mc":[{"id":"1.229554900","rc":[{"atb":[[2.96,5.78]],"id":47208569}],"con":true,"img":false}]}
{"op":"mcm","clk":"11450124198","pt":1717318277831,"mc":[{"id":"1.229554900","rc":[{"atb":[[2.6,73.56],[2.98,0]],"id":70003368},{"atb":[[2.54,77.62],[2.92,0]],"id":47208569},{"atb":[[16,7.3],[20,0]],"id":49183855},{"atb":[[13,9.94],[16.5,0],[23,0]],"id":63027102},{"atb":[[1.59,0],[1.69,0]],"id":67532289},{"atl":[[4.3,0],[5.2,26.78],[3.65,0]],"id":67532289}],"con":true,"img":false}]}
{"op":"mcm","clk":"11450124211","pt":1717318277936,"mc":[{"id":"1.229554900","rc":[{"atb":[[21,2.77]],"id":63027102},{"atb":[[1.66,66],[1.53,212.23]],"id":67532289},{"atl":[[3.7,23.87]],"id":67532289}],"con":true,"img":false}]}
{"op":"mcm","clk":"11450124228","pt":1717318278138,"mc":[{"id":"1.229554900","rc":[{"atb":[[22,0]],"id":49183855},{"atb":[[27,2]],"id":63027102}],"con":true,"img":false}]}
{"op":"mcm","clk":"11450124238","pt":1717318278251,"mc":[{"id":"1.229554900","rc":[{"atb":[[1.02,108.02],[28,0]],"id":63027102}],"con":true,"img":false}]}
{"op":"mcm","clk":"11450124257","pt":1717318278448,"mc":[{"id":"1.229554900","rc":[{"atb":[[1.03,8.14]],"id":49183855},{"atb":[[1.03,8.14]],"id":63027102}],"con":true,"img":false}]}
{"op":"mcm","clk":"11450124280","pt":1717318278655,"mc":[{"id":"1.229554900","rc":[{"atb":[[1.02,106.05]],"id":63027102}],"con":true,"img":false}]}
{"op":"mcm","clk":"11450124291","pt":1717318278758,"mc":[{"id":"1.229554900","rc":[{"atb":[[1.03,6.36]],"id":49183855}],"con":true,"img":false}]}
{"op":"mcm","clk":"11450124303","pt":1717318278964,"mc":[{"id":"1.229554900","rc":[{"atb":[[1.03,6.34]],"id":63027102}],"con":true,"img":false}]}
{"op":"mcm","clk":"11450124314","pt":1717318279068,"mc":[{"id":"1.229554900","rc":[{"atb":[[1.03,5.78]],"id":49183855},{"atb":[[1.02,105.66]],"id":63027102}],"con":true,"img":false}]}
{"op":"mcm","clk":"11450124320","pt":1717318279173,"mc":[{"id":"1.229554900","rc":[{"atb":[[27,0.97]],"id":49183855},{"atb":[[28,0.39]],"id":63027102}],"con":true,"img":false}]}
{"op":"mcm","clk":"11450124372","pt":1717318279744,"mc":[{"id":"1.229554900","rc":[{"atb":[[1.03,5.78]],"id":63027102}],"con":true,"img":false}]}
{"op":"mcm","clk":"11450124383","pt":1717318279847,"mc":[{"id":"1.229554900","rc":[{"atb":[[28,0.94]],"id":63027102}],"con":true,"img":false}]}
{"op":"mcm","clk":"11450125057","pt":1717318287854,"mc":[{"id":"1.229554900","rc":[{"atb":[[25,0.03]],"id":49183855}],"con":true,"img":false}]}
{"op":"mcm","clk":"11450125068","pt":1717318287956,"mc":[{"id":"1.229554900","rc":[{"atb":[[22,2],[26,0],[27,4.37]],"id":49183855}],"con":true,"img":false}]}
{"op":"mcm","clk":"11450125080","pt":1717318288062,"mc":[{"id":"1.229554900","rc":[{"atb":[[2.76,118.78],[2.86,112.39],[2.96,53.33]],"id":70003368},{"atl":[[10.5,27.05],[15.5,14.41]],"id":70003368},{"atb":[[2.8,116.14],[2.9,55.01],[2.7,122.97]],"id":47208569},{"atl":[[10,26.59],[15,14.93]],"id":47208569},{"atb":[[14.5,15.48],[17,13.06],[19.5,5.65],[22,0],[28,2]],"id":49183855},{"atl":[[300,0.46],[400,0.52]],"id":49183855},{"atb":[[16,13.93],[18.5,11.94],[22,4.97]],"id":63027102},{"atl":[[320,2.43],[420,0.49]],"id":63027102},{"atb":[[1.58,360.45],[1.68,153.71],[1.63,331.84]],"id":67532289},{"atl":[[4.4,61.48],[3.7,75.49]],"id":67532289}],"con":true,"img":false}]}
{"op":"mcm","clk":"11450125104","pt":1717318288273,"mc":[{"id":"1.229554900","rc":[{"atb":[[27,3.98]],"id":49183855}],"con":true,"img":false}]}
{"op":"mcm","clk":"11450125157","pt":1717318288745,"mc":[{"id":"1.229554900","rc":[{"atb":[[1.02,2.35]],"id":49183855}],"con":true,"img":false}]}
{"op":"mcm","clk":"11450125214","pt":1717318289567,"mc":[{"id":"1.229554900","rc":[{"atb":[[1.02,0.39]],"id":49183855}],"con":true,"img":false}]}
{"op":"mcm","clk":"11450125251","pt":1717318289980,"mc":[{"id":"1.229554900","rc":[{"atb":[[1.02,0]],"id":49183855}],"con":true,"img":false}]}
{"op":"mcm","clk":"11450125260","pt":1717318290039,"mc":[{"id":"1.229554900","rc":[{"atb":[[28,2.39]],"id":49183855}],"con":true,"img":false}]}
{"op":"mcm","clk":"11450126188","pt":1717318301257,"mc":[{"id":"1.229554900","rc":[{"spn":114.0,"spf":"NaN","id":49183855},{"atl":[[320,0.43]],"id":63027102}],"con":true,"img":false}]}
{"op":"mcm","clk":"11450126196","pt":1717318301320,"mc":[{"id":"1.229554900","rc":[{"atb":[[2.34,0]],"id":63027102}],"con":true,"img":false}]}
{"op":"mcm","clk":"11450126652","pt":1717318306540,"mc":[{"id":"1.229554900","rc":[{"atb":[[27,0],[28,2.94]],"id":63027102}],"con":true,"img":false}]}
{"op":"mcm","clk":"11450126748","pt":1717318307524,"mc":[{"id":"1.229554900","rc":[{"atb":[[1.69,16.43]],"id":67532289}],"con":true,"img":false}]}
{"op":"mcm","clk":"11450126757","pt":1717318307625,"mc":[{"id":"1.229554900","rc":[{"atb":[[2.96,0]],"id":47208569}],"con":true,"img":false}]}
{"op":"mcm","clk":"11450127327","pt":1717318314748,"mc":[{"id":"1.229554900","rc":[{"atl":[[7,1.38]],"id":47208569},{"atl":[[250,1.26]],"id":63027102}],"con":true,"img":false}]}
{"op":"mcm","clk":"11450127334","pt":1717318314855,"mc":[{"id":"1.229554900","rc":[{"atl":[[2.5,1.61]],"id":67532289}],"con":true,"img":false}]}
{"op":"mcm","clk":"11450127340","pt":1717318314955,"mc":[{"id":"1.229554900","rc":[{"atl":[[240,1.26]],"id":49183855}],"con":true,"img":false}]}
{"op":"mcm","clk":"11450127351","pt":1717318315062,"mc":[{"id":"1.229554900","rc":[{"atl":[[5.5,1.42]],"id":70003368}],"con":true,"img":false}]}
{"op":"mcm","clk":"11450127584","pt":1717318317862,"mc":[{"id":"1.229554900","rc":[{"atb":[[21,0]],"id":63027102}],"con":true,"img":false}]}
{"op":"mcm","clk":"11450127596","pt":1717318317960,"mc":[{"id":"1.229554900","rc":[{"atb":[[23,2.77]],"id":63027102}],"con":true,"img":false}]}
{"op":"mcm","clk":"11450127791","pt":1717318320249,"mc":[{"id":"1.229554900","rc":[{"atb":[[2.02,12.2]],"id":70003368},{"atb":[[3,12.2],[4,6.2],[2.02,12.2],[6,6.2],[27,0.58]],"id":49183855},{"atb":[[3,12.2],[4,6.2],[2.02,12.2],[6,6.2]],"id":63027102},{"atb":[[1.66,0]],"id":67532289}],"con":true,"img":false}]}
{"op":"mcm","clk":"11450127800","pt":1717318320353,"mc":[{"id":"1.229554900","rc":[{"atb":[[10,6.2],[29,3.4]],"id":49183855},{"atb":[[10,6.2]],"id":63027102},{"atb":[[1.69,82.44]],"id":67532289}],"con":true,"img":false}]}
{"op":"mcm","clk":"11450127807","pt":1717318320456,"mc":[{"id":"1.229554900","rc":[{"atb":[[25,2.03],[28,0.39]],"id":49183855}],"con":true,"img":false}]}
{"op":"mcm","clk":"11450127871","pt":1717318321137,"mc":[{"id":"1.229554900","rc":[{"atb":[[1.02,2.35]],"id":49183855}],"con":true,"img":false}]}
{"op":"mcm","clk":"11450127881","pt":1717318321249,"mc":[{"id":"1.229554900","rc":[{"atb":[[28,0]],"id":49183855}],"con":true,"img":false}]}
{"op":"mcm","clk":"11450127917","pt":1717318321554,"mc":[{"id":"1.229554900","rc":[{"atb":[[3.2,2.61]],"id":47208569}],"con":true,"img":false}]}
{"op":"mcm","clk":"11450127944","pt":1717318321864,"mc":[{"id":"1.229554900","rc":[{"atb":[[3.3,2.61]],"id":70003368},{"atb":[[3.2,6.29]],"id":47208569}],"con":true,"img":false}]}
{"op":"mcm","clk":"11450127970","pt":1717318322187,"mc":[{"id":"1.229554900","rc":[{"atb":[[3.3,6.18]],"id":70003368}],"con":true,"img":false}]}
{"op":"mcm","clk":"11450128008","pt":1717318322554,"mc":[{"id":"1.229554900","rc":[{"atb":[[1.02,0.39]],"id":49183855}],"con":true,"img":false}]}
{"op":"mcm","clk":"11450128101","pt":1717318323439,"mc":[{"id":"1.229554900","rc":[{"atb":[[1.02,0]],"id":49183855}],"con":true,"img":false}]}
{"op":"mcm","clk":"11450128112","pt":1717318323544,"mc":[{"id":"1.229554900","rc":[{"atb":[[30,0.39]],"id":49183855}],"con":true,"img":false}]}
{"op":"mcm","clk":"11450128131","pt":1717318323760,"mc":[{"id":"1.229554900","rc":[{"atb":[[2.76,0],[2.86,0],[2.96,0]],"id":70003368},{"atl":[[10.5,12.38],[15.5,0]],"id":70003368},{"atb":[[2.8,0],[2.9,0],[2.7,0]],"id":47208569},{"atl":[[10,11.11],[15,0]],"id":47208569},{"atb":[[16,0],[18.5,0],[22,0]],"id":63027102},{"atl":[[320,0],[420,0]],"id":63027102}],"con":true,"img":false}]}
{"op":"mcm","clk":"11450128245","pt":1717318324952,"mc":[{"id":"1.229554900","rc":[{"atl":[[2.52,0]],"id":67532289}],"con":true,"img":false}]}
