{"op":"mcm","clk":"11449075388","pt":1717303241532,"mc":[{"id":"1.229554923","marketDefinition":{"bspMarket":false,"turnInPlayEnabled":false,"persistenceEnabled":false,"marketBaseRate":7.0,"eventId":"33318908","eventTypeId":"4339","numberOfWinners":1,"bettingType":"ODDS","marketType":"QUINELLA","marketTime":"2024-06-02T10:24:00.000Z","suspendTime":"2024-06-02T10:24:00.000Z","bspReconciled":false,"complete":true,"inPlay":false,"crossMatching":true,"runnersVoidable":false,"numberOfActiveRunners":21,"betDelay":0,"status":"OPEN","runners":[{"status":"ACTIVE","sortPriority":1,"id":52671542,"name":"1 - 2 / 2 - 1"},{"status":"ACTIVE","sortPriority":2,"id":52671543,"name":"1 - 3 / 3 - 1"},{"status":"ACTIVE","sortPriority":3,"id":52671544,"name":"1 - 4 / 4 - 1"},{"status":"ACTIVE","sortPriority":4,"id":52671545,"name":"1 - 6 / 6 - 1"},{"status":"ACTIVE","sortPriority":5,"id":52671560,"name":"1 - 7 / 7 - 1"},{"status":"ACTIVE","sortPriority":6,"id":52671546,"name":"1 - 8 / 8 - 1"},{"status":"ACTIVE","sortPriority":7,"id":52671547,"name":"2 - 3 / 3 - 2"},{"status":"ACTIVE","sortPriority":8,"id":52671548,"name":"2 - 4 / 4 - 2"},{"status":"ACTIVE","sortPriority":9,"id":52671549,"name":"2 - 6 / 6 - 2"},{"status":"ACTIVE","sortPriority":10,"id":52671561,"name":"2 - 7 / 7 - 2"},{"status":"ACTIVE","sortPriority":11,"id":52671550,"name":"2 - 8 / 8 - 2"},{"status":"ACTIVE","sortPriority":12,"id":52671551,"name":"3 - 4 / 4 - 3"},{"status":"ACTIVE","sortPriority":13,"id":52671552,"name":"3 - 6 / 6 - 3"},{"status":"ACTIVE","sortPriority":14,"id":52671562,"name":"3 - 7 / 7 - 3"},{"status":"ACTIVE","sortPriority":15,"id":52671553,"name":"3 - 8 / 8 - 3"},{"status":"ACTIVE","sortPriority":16,"id":52671554,"name":"4 - 6 / 6 - 4"},{"status":"ACTIVE","sortPriority":17,"id":52671563,"name":"4 - 7 / 7 - 4"},{"status":"ACTIVE","sortPriority":18,"id":52671555,"name":"4 - 8 / 8 - 4"},{"status":"ACTIVE","sortPriority":19,"id":52671564,"name":"6 - 7 / 7 - 6"},{"status":"ACTIVE","sortPriority":20,"id":52671556,"name":"6 - 8 / 8 - 6"},{"status":"ACTIVE","sortPriority":21,"id":52671565,"name":"7 - 8 / 8 - 7"}],"regulators":["MR_INT"],"venue":"Murray Bridge","countryCode":"AU","discountAllowed":true,"timezone":"Australia/Adelaide","openDate":"2024-06-02T08:21:00.000Z","version":5962801947,"name":"Quinella","eventName":"Murray Bridge (AUS) 2nd Jun"},"rc":[],"con":true,"img":false}]}
{"op":"mcm","clk":"11449099388","pt":1717303849619,"mc":[{"id":"1.229554923","rc":[{"atb":[[21,5.22],[15.5,16.82]],"id":52671563},{"atb":[[9,30.48],[12.5,9.08]],"id":52671562},{"atb":[[9.8,11.87],[7.8,35.86]],"id":52671565},{"atb":[[95,1.11],[48,5.18]],"id":52671564},{"atb":[[8,34.84],[10,11.61]],"id":52671561},{"atb":[[8,34.84],[10,11.61]],"id":52671560},{"atb":[[9,13.06],[7,40.65]],"id":52671555},{"atb":[[50,2.13],[30,8.41]],"id":52671554},{"atb":[[10.5,25.67],[15.5,7.2]],"id":52671556},{"atb":[[8,34.84],[10,11.61]],"id":52671551},{"atb":[[3.6,40.2],[3.1,116.14]],"id":52671550},{"atb":[[4.1,33.71],[3.55,95.64]],"id":52671553},{"atb":[[18,6.14],[13,20.32]],"id":52671552},{"atb":[[4.3,31.67],[3.65,92.03]],"id":52671547},{"atb":[[3.6,40.2],[3.1,116.14]],"id":52671546},{"atb":[[16,6.96],[11,24.39]],"id":52671549},{"atb":[[7.2,39.33],[9.2,12.74]],"id":52671548},{"atb":[[3.7,90.33],[4.4,30.74]],"id":52671543},{"atb":[[3.2,110.86],[3.7,38.71]],"id":52671542},{"atb":[[16.5,6.74],[11.5,23.22]],"id":52671545},{"atb":[[7.2,39.33],[9.2,12.74]],"id":52671544}],"con":true,"img":false}]}
{"op":"mcm","clk":"11449225677","pt":1717305840462,"mc":[{"id":"1.229554923","rc":[{"atb":[[38,1.41],[48,0.55],[24,4.55],[29,2.8]],"id":52671563},{"atb":[[17.5,1.59],[10,11.63],[12.5,15.91],[15,3.74]],"id":52671562},{"atb":[[12,2.38],[9.8,17.82],[8.8,10.06],[7.8,51.26]],"id":52671565},{"atb":[[85,0.62],[44,2.43],[120,0.22],[60,1.33]],"id":52671564},{"atb":[[16,6.97],[18.5,4.48],[22,2.49],[27,1]],"id":52671561},{"atb":[[16,1.74],[11,7.85],[13.5,4.19],[9.4,12.46]],"id":52671560},{"atb":[[9.6,9.12],[8.6,13.77],[11.5,4.98],[14,2.01]],"id":52671555},{"atb":[[140,0.19],[70,1.14],[95,0.55],[48,2.23]],"id":52671554},{"atb":[[36,0.75],[19,5.81],[23,3.57],[28,1.94]],"id":52671556},{"atb":[[18,1.54],[10.5,11.01],[13,6.54],[15.5,3.61]],"id":52671551},{"atb":[[3.95,35.47],[4.9,13.41],[4.4,23.08],[5.4,5.94]],"id":52671550},{"atb":[[5.6,11.37],[5.1,19.14],[4.6,29.07],[6.2,5.03]],"id":52671553},{"atb":[[40,1.34],[50,0.53],[25,4.36],[30,2.71]],"id":52671552},{"atb":[[5,26.16],[5.5,17.44],[6,10.46],[7,4.36]],"id":52671547},{"atb":[[3.95,26.6],[3.7,38.75],[4.9,6.71],[4.4,15.39]],"id":52671546},{"atb":[[32,2.53],[42,1.28],[26,4.19],[55,0.49]],"id":52671549},{"atb":[[17,4.9],[19.5,2.83],[24,1.14],[14.5,7.75]],"id":52671548},{"atb":[[6.4,4.84],[5.2,18.68],[5.7,11.13],[4.7,28.28]],"id":52671543},{"atb":[[4.9,20.12],[4.4,30.77],[5.9,5.34],[5.4,11.89]],"id":52671542},{"atb":[[38,1.41],[48,0.55],[24,4.55],[29,2.8]],"id":52671545},{"atb":[[16.5,1.69],[9.6,12.17],[11.5,7.48],[14,4.02]],"id":52671544}],"con":true,"img":false}]}
{"op":"mcm","clk":"11449227019","pt":1717305859051,"mc":[{"id":"1.229554923","rc":[{"atb":[[32,0],[42,0],[26,0],[55,0]],"id":52671549},{"atb":[[17,0],[19.5,0],[24,0],[14.5,0]],"id":52671548},{"atb":[[4.9,0],[4.4,0],[5.9,0],[5.4,0]],"id":52671542}],"con":true,"img":false}]}
{"op":"mcm","clk":"11449227081","pt":1717305859772,"mc":[{"id":"1.229554923","rc":[{"atb":[[40,1.34],[50,0.53],[25,4.36],[30,2.71]],"id":52671549},{"atb":[[16.5,5.06],[19,2.91],[23,1.19],[14,8.05]],"id":52671548},{"atb":[[4.8,20.65],[4.3,31.71],[5.8,5.45],[5.3,12.17]],"id":52671542}],"con":true,"img":false}]}
{"op":"mcm","clk":"11449249280","pt":1717306178326,"mc":[{"id":"1.229554923","rc":[{"atb":[[5,0],[5.5,0],[6,0],[7,0]],"id":52671547}],"con":true,"img":false}]}
{"op":"mcm","clk":"11449249336","pt":1717306178993,"mc":[{"id":"1.229554923","rc":[{"atb":[[6.8,4.51],[4.9,26.83],[5.9,10.68],[5.4,17.84]],"id":52671547}],"con":true,"img":false}]}
{"op":"mcm","clk":"11449289064","pt":1717306703015,"mc":[{"id":"1.229554923","rc":[{"atb":[[17.5,0],[10,0],[12.5,9.08],[15,0]],"id":52671562},{"atb":[[85,0],[44,0],[120,0],[60,0]],"id":52671564},{"atb":[[16,0],[11,0],[13.5,0],[9.4,0]],"id":52671560},{"atb":[[18,0],[10.5,0],[13,0],[15.5,0]],"id":52671551},{"atb":[[40,0],[50,0],[25,0],[30,0]],"id":52671552},{"atb":[[6.4,0],[5.2,0],[5.7,0],[4.7,0]],"id":52671543},{"atb":[[38,0],[48,0],[24,0],[29,0]],"id":52671545},{"atb":[[16.5,0],[9.6,0],[11.5,0],[14,0]],"id":52671544}],"con":true,"img":false}]}
{"op":"mcm","clk":"11449289130","pt":1717306703797,"mc":[{"id":"1.229554923","rc":[{"atb":[[12,4.76],[9.8,8.92],[8.8,13.41],[14.5,1.94]],"id":52671560},{"atb":[[16,1.74],[11,7.85],[13.5,4.19],[9.4,12.46]],"id":52671551},{"atb":[[4.8,6.89],[4.3,15.85],[3.9,27.06],[3.65,39.48]],"id":52671543},{"atb":[[38,0.71],[19.5,5.66],[24,3.41],[29,1.87]],"id":52671545},{"atb":[[9.2,25.51],[10.5,8.26],[13,4.36],[15.5,1.81]],"id":52671544}],"con":true,"img":false}]}
{"op":"mcm","clk":"11449289161","pt":1717306704263,"mc":[{"id":"1.229554923","rc":[{"atb":[[9,43.57],[10,8.72],[12.5,13.64],[15,1.87]],"id":52671562},{"atb":[[80,0.66],[42,2.55],[110,0.24],[55,1.45]],"id":52671564},{"atb":[[38,0.71],[19.5,5.66],[24,3.41],[29,1.87]],"id":52671552}],"con":true,"img":false}]}
{"op":"mcm","clk":"11449350277","pt":1717307646176,"mc":[{"id":"1.229554923","rc":[{"atb":[[38,0],[48,0],[24,0],[29,0]],"id":52671563},{"atb":[[12,0],[9.8,11.87],[8.8,0],[7.8,35.86]],"id":52671565},{"atb":[[9.6,0],[8.6,0],[11.5,0],[14,0]],"id":52671555},{"atb":[[36,0],[19,0],[23,0],[28,0]],"id":52671556},{"atb":[[5.6,0],[5.1,0],[4.6,0],[6.2,0]],"id":52671553},{"atb":[[3.95,0],[3.7,0],[4.9,0],[4.4,0]],"id":52671546}],"con":true,"img":false}]}
{"op":"mcm","clk":"11449350297","pt":1717307646894,"mc":[{"id":"1.229554923","rc":[{"atb":[[40,1.34],[50,0.53],[25,4.36],[30,2.71]],"id":52671563},{"atb":[[16,1.74],[11,7.85],[13.5,4.19],[9.4,12.46]],"id":52671565},{"atb":[[17,3.27],[19.5,1.41],[12,9.51],[14.5,5.81]],"id":52671555},{"atb":[[34,1.59],[44,0.61],[22,4.98],[27,3.02]],"id":52671556},{"atb":[[6.4,4.84],[5.2,18.68],[5.7,11.13],[4.7,28.28]],"id":52671553},{"atb":[[4,34.88],[4.5,22.42],[5,13.08],[5.5,5.81]],"id":52671546}],"con":true,"img":false}]}
{"op":"mcm","clk":"11449350968","pt":1717307661284,"mc":[{"id":"1.229554923","rc":[{"atb":[[3.95,0],[4.9,0],[4.4,0],[5.4,0]],"id":52671550},{"atb":[[6.4,0],[5.2,0],[5.7,0],[4.7,0]],"id":52671553},{"atb":[[4,0],[4.5,0],[5,0],[5.5,0]],"id":52671546}],"con":true,"img":false}]}
{"op":"mcm","clk":"11449350973","pt":1717307661383,"mc":[{"id":"1.229554923","rc":[{"atb":[[16,0],[11,0],[13.5,0],[9.4,0]],"id":52671565},{"atb":[[17,0],[19.5,0],[12,0],[14.5,0]],"id":52671555}],"con":true,"img":false}]}
{"op":"mcm","clk":"11449350979","pt":1717307661485,"mc":[{"id":"1.229554923","rc":[{"atb":[[40,0],[50,0],[25,0],[30,0]],"id":52671563},{"atb":[[140,0],[70,0],[95,0],[48,0]],"id":52671554},{"atb":[[34,0],[44,0],[22,0],[27,0]],"id":52671556}],"con":true,"img":false}]}
{"op":"mcm","clk":"11449351015","pt":1717307662206,"mc":[{"id":"1.229554923","rc":[{"atb":[[4.8,20.65],[4.3,31.71],[5.8,5.45],[5.3,12.17]],"id":52671546}],"con":true,"img":false}]}
{"op":"mcm","clk":"11449351023","pt":1717307662307,"mc":[{"id":"1.229554923","rc":[{"atb":[[34,3.17],[85,0.31],[44,1.83],[60,0.88]],"id":52671563},{"atb":[[16,6.97],[18.5,4.48],[22,2.49],[27,1]],"id":52671565},{"atb":[[16.5,5.06],[19,2.91],[23,1.19],[14,8.05]],"id":52671555},{"atb":[[160,0.33],[80,1.32],[210,0.13],[110,0.72]],"id":52671554},{"atb":[[40,1.34],[50,0.53],[25,4.36],[30,2.71]],"id":52671556},{"atb":[[5.2,12.46],[5.7,5.57],[4.2,32.7],[4.7,21.21]],"id":52671550},{"atb":[[5,26.16],[5.5,17.44],[6,10.46],[7,4.36]],"id":52671553}],"con":true,"img":false}]}
{"op":"mcm","clk":"11449363063","pt":1717307950880,"mc":[{"id":"1.229554923","rc":[{"atb":[[6.8,0],[4.9,0],[5.9,0],[5.4,0]],"id":52671547}],"con":true,"img":false}]}
{"op":"mcm","clk":"11449363085","pt":1717307951594,"mc":[{"id":"1.229554923","rc":[{"atb":[[5,26.16],[5.5,17.44],[6,10.46],[7,4.36]],"id":52671547}],"con":true,"img":false}]}
{"op":"mcm","clk":"11449387496","pt":1717308423708,"mc":[{"id":"1.229554923","rc":[{"atb":[[9,30.48],[10,0],[12.5,9.08],[15,0]],"id":52671562}],"con":true,"img":false}]}
{"op":"mcm","clk":"11449387548","pt":1717308424427,"mc":[{"id":"1.229554923","rc":[{"atb":[[17.5,4.76],[20,2.75],[25,1.09],[15,7.48]],"id":52671562}],"con":true,"img":false}]}
{"op":"mcm","clk":"11449456197","pt":1717309416756,"mc":[{"id":"1.229554923","rc":[{"atb":[[160,0],[80,0],[210,0],[110,0]],"id":52671554}],"con":true,"img":false}]}
{"op":"mcm","clk":"11449456205","pt":1717309416811,"mc":[{"id":"1.229554923","rc":[{"atb":[[16,0],[18.5,0],[22,0],[27,0]],"id":52671565}],"con":true,"img":false}]}
{"op":"mcm","clk":"11449456238","pt":1717309417432,"mc":[{"id":"1.229554923","rc":[{"atb":[[170,0.31],[85,1.25],[220,0.12],[120,0.66]],"id":52671554}],"con":true,"img":false}]}
{"op":"mcm","clk":"11449456245","pt":1717309417535,"mc":[{"id":"1.229554923","rc":[{"atb":[[17.5,4.76],[20,2.75],[25,1.09],[15,7.48]],"id":52671565}],"con":true,"img":false}]}
{"op":"mcm","clk":"11449456834","pt":1717309426543,"mc":[{"id":"1.229554923","rc":[{"atb":[[170,0],[85,0],[220,0],[120,0]],"id":52671554}],"con":true,"img":false}]}
{"op":"mcm","clk":"11449456880","pt":1717309427261,"mc":[{"id":"1.229554923","rc":[{"atb":[[160,0.33],[80,1.32],[210,0.13],[110,0.72]],"id":52671554}],"con":true,"img":false}]}
{"op":"mcm","clk":"11449523808","pt":1717310348948,"mc":[{"id":"1.229554923","rc":[{"atb":[[17.5,0],[20,0],[25,0],[15,0]],"id":52671562}],"con":true,"img":false}]}
{"op":"mcm","clk":"11449523863","pt":1717310349622,"mc":[{"id":"1.229554923","rc":[{"atb":[[17.5,4.76],[20,2.75],[25,1.09],[15,7.48]],"id":52671562}],"con":true,"img":false}]}
{"op":"mcm","clk":"11449554319","pt":1717310865489,"mc":[{"id":"1.229554923","rc":[{"atb":[[17.5,0],[20,0],[25,0],[15,0]],"id":52671565}],"con":true,"img":false}]}
{"op":"mcm","clk":"11449554358","pt":1717310866204,"mc":[{"id":"1.229554923","rc":[{"atb":[[16,6.97],[18.5,4.48],[22,2.49],[27,1]],"id":52671565}],"con":true,"img":false}]}
{"op":"mcm","clk":"11449589230","pt":1717311489650,"mc":[{"id":"1.229554923","rc":[{"atb":[[16,0],[18.5,0],[22,0],[27,0]],"id":52671565},{"atb":[[160,0],[80,0],[210,0],[110,0]],"id":52671554}],"con":true,"img":false}]}
{"op":"mcm","clk":"11449589260","pt":1717311490372,"mc":[{"id":"1.229554923","rc":[{"atb":[[17.5,4.76],[20,2.75],[25,1.09],[15,7.48]],"id":52671565},{"atb":[[170,0.31],[85,1.25],[220,0.12],[120,0.66]],"id":52671554}],"con":true,"img":false}]}
{"op":"mcm","clk":"11449593430","pt":1717311568793,"mc":[{"id":"1.229554923","rc":[{"atb":[[17.5,0],[20,0],[25,0],[15,0]],"id":52671562}],"con":true,"img":false}]}
{"op":"mcm","clk":"11449593472","pt":1717311569464,"mc":[{"id":"1.229554923","rc":[{"atb":[[17.5,4.76],[20,2.75],[25,1.09],[15,7.48]],"id":52671562}],"con":true,"img":false}]}
{"op":"mcm","clk":"11449620341","pt":1717312070889,"mc":[{"id":"1.229554923","rc":[{"atb":[[170,0],[85,0],[220,0],[120,0]],"id":52671554}],"con":true,"img":false}]}
{"op":"mcm","clk":"11449620379","pt":1717312071596,"mc":[{"id":"1.229554923","rc":[{"atb":[[160,0.33],[80,1.32],[210,0.13],[110,0.72]],"id":52671554}],"con":true,"img":false}]}
{"op":"mcm","clk":"11449620531","pt":1717312074595,"mc":[{"id":"1.229554923","rc":[{"atb":[[34,0],[85,0],[44,0],[60,0]],"id":52671563},{"atb":[[17.5,0],[20,0],[25,0],[15,0]],"id":52671562},{"atb":[[17.5,0],[20,0],[25,0],[15,0]],"id":52671565},{"atb":[[80,0],[42,0],[110,0],[55,0]],"id":52671564},{"atb":[[16,0],[18.5,0],[22,0],[27,0]],"id":52671561},{"atb":[[12,0],[9.8,0],[8.8,0],[14.5,0]],"id":52671560},{"atb":[[16.5,0],[19,0],[23,0],[14,0]],"id":52671555},{"atb":[[40,0],[50,0],[25,0],[30,0]],"id":52671556},{"atb":[[40,0],[50,0],[25,0],[30,0]],"id":52671549},{"atb":[[16.5,0],[19,0],[23,0],[14,0]],"id":52671548},{"atb":[[38,0],[19.5,0],[24,0],[29,0]],"id":52671545},{"atb":[[9.2,12.74],[10.5,0],[13,0],[15.5,0]],"id":52671544}],"con":true,"img":false}]}
{"op":"mcm","clk":"11449620560","pt":1717312075312,"mc":[{"id":"1.229554923","rc":[{"atb":[[7.2,16.88],[9.2,6.38],[10.5,2.75],[8.2,10.9]],"id":52671563},{"atb":[[16.5,1.69],[9.6,12.17],[11.5,7.48],[14,4.02]],"id":52671562},{"atb":[[16.5,1.69],[9.6,12.17],[11.5,7.48],[14,4.02]],"id":52671565},{"atb":[[16,5.23],[18.5,2.99],[22,1.25],[13.5,8.37]],"id":52671564},{"atb":[[17.5,1.59],[10,23.24],[12.5,6.82],[15,3.74]],"id":52671561},{"atb":[[11,5.23],[13.5,2.09],[8.4,14.14],[9.4,9.34]],"id":52671560},{"atb":[[16.5,3.37],[19,1.45],[11.5,9.97],[14,6.04]],"id":52671555},{"atb":[[36,1.5],[46,0.58],[23,4.76],[28,2.91]],"id":52671556},{"atb":[[36,1.5],[46,0.58],[23,4.76],[28,2.91]],"id":52671549},{"atb":[[17,1.64],[12,7.14],[9.8,11.89],[14.5,3.88]],"id":52671548},{"atb":[[36,0.75],[19,5.81],[23,3.57],[28,1.94]],"id":52671545},{"atb":[[11,5.23],[13.5,2.09],[8.4,14.14],[9.4,9.34]],"id":52671544}],"con":true,"img":false}]}
{"op":"mcm","clk":"11449620661","pt":1717312077419,"mc":[{"id":"1.229554923","rc":[{"atb":[[160,0],[80,0],[210,0],[110,0]],"id":52671554}],"con":true,"img":false}]}
{"op":"mcm","clk":"11449620703","pt":1717312078193,"mc":[{"id":"1.229554923","rc":[{"atb":[[18.5,4.48],[22,2.49]],"id":52671554}],"con":true,"img":false}]}
{"op":"mcm","clk":"11449620709","pt":1717312078293,"mc":[{"id":"1.229554923","rc":[{"atb":[[16,6.97],[27,1]],"id":52671554}],"con":true,"img":false}]}
{"op":"mcm","clk":"11449659736","pt":1717313047834,"mc":[{"id":"1.229554923","rc":[{"atb":[[36,0],[46,0],[23,0],[28,0]],"id":52671556}],"con":true,"img":false}]}
{"op":"mcm","clk":"11449659740","pt":1717313047938,"mc":[{"id":"1.229554923","rc":[{"atb":[[16.5,0],[9.6,0],[11.5,0],[14,0]],"id":52671565}],"con":true,"img":false}]}
{"op":"mcm","clk":"11449659767","pt":1717313048505,"mc":[{"id":"1.229554923","rc":[{"atb":[[36,1.5],[46,0.58],[23,4.76],[28,2.91]],"id":52671556}],"con":true,"img":false}]}
{"op":"mcm","clk":"11449659770","pt":1717313048608,"mc":[{"id":"1.229554923","rc":[{"atb":[[16.5,1.69],[9.6,12.17],[11.5,7.48],[14,4.02]],"id":52671565}],"con":true,"img":false}]}
{"op":"mcm","clk":"11449667363","pt":1717313215933,"mc":[{"id":"1.229554923","rc":[{"atb":[[21,0],[15.5,0]],"id":52671563},{"atb":[[9,0],[12.5,0]],"id":52671562},{"atb":[[9.8,0],[7.8,0]],"id":52671565},{"atb":[[95,0],[48,0]],"id":52671564},{"atb":[[8,0],[10,11.63]],"id":52671561},{"atb":[[8,0],[10,0]],"id":52671560},{"atb":[[9,0],[7,0]],"id":52671555},{"atb":[[50,0],[30,0]],"id":52671554},{"atb":[[10.5,0],[15.5,0]],"id":52671556},{"atb":[[8,0],[10,0]],"id":52671551},{"atb":[[3.6,0],[3.1,0]],"id":52671550},{"atb":[[4.1,0],[3.55,0]],"id":52671553},{"atb":[[18,0],[13,0]],"id":52671552},{"atb":[[4.3,0],[3.65,0]],"id":52671547},{"atb":[[3.6,0],[3.1,0]],"id":52671546},{"atb":[[16,0],[11,0]],"id":52671549},{"atb":[[7.2,0],[9.2,0]],"id":52671548},{"atb":[[3.7,0],[4.4,0]],"id":52671543},{"atb":[[3.2,0],[3.7,0]],"id":52671542},{"atb":[[16.5,0],[11.5,0]],"id":52671545},{"atb":[[7.2,0],[9.2,0]],"id":52671544}],"con":true,"img":false}]}
{"op":"mcm","clk":"11449667890","pt":1717313226923,"mc":[{"id":"1.229554923","rc":[{"atb":[[16.5,0],[9.6,0],[11.5,0],[14,0]],"id":52671565},{"atb":[[17.5,0],[10,0],[12.5,0],[15,0]],"id":52671561},{"atb":[[11,0],[13.5,0],[8.4,0],[9.4,0]],"id":52671560}],"con":true,"img":false}]}
{"op":"mcm","clk":"11449667899","pt":1717313227132,"mc":[{"id":"1.229554923","rc":[{"atb":[[16.5,0],[19,0],[11.5,0],[14,0]],"id":52671555},{"atb":[[17,0],[12,0],[9.8,0],[14.5,0]],"id":52671548},{"atb":[[11,0],[13.5,0],[8.4,0],[9.4,0]],"id":52671544}],"con":true,"img":false}]}
{"op":"mcm","clk":"11449667918","pt":1717313227643,"mc":[{"id":"1.229554923","rc":[{"atb":[[16.5,1.69],[9.6,12.17],[11.5,7.48],[14,4.02]],"id":52671565},{"atb":[[17.5,1.59],[10,11.63],[12.5,6.82],[15,3.74]],"id":52671561},{"atb":[[11,5.23],[13.5,2.09],[8.4,14.14],[9.4,9.34]],"id":52671560}],"con":true,"img":false}]}
{"op":"mcm","clk":"11449667926","pt":1717313227849,"mc":[{"id":"1.229554923","rc":[{"atb":[[16,3.49],[18.5,1.5],[11,10.46],[13.5,6.28]],"id":52671555},{"atb":[[16.5,1.69],[9.6,12.17],[11.5,7.48],[14,4.02]],"id":52671548},{"atb":[[9.2,9.57],[10.5,5.51],[8.2,14.53],[13,2.18]],"id":52671544}],"con":true,"img":false}]}
{"op":"mcm","clk":"11449668616","pt":1717313241058,"mc":[{"id":"1.229554923","rc":[{"atb":[[16,16.26],[22,4.97]],"id":52671563},{"atb":[[9.2,29.74],[13,8.71]],"id":52671562},{"atb":[[10.5,11],[8.2,33.87]],"id":52671565},{"atb":[[100,1.05],[50,4.97]],"id":52671564},{"atb":[[10.5,11],[8.2,33.87]],"id":52671561},{"atb":[[10.5,11],[8.2,33.87]],"id":52671560},{"atb":[[7.2,39.33],[9.2,12.74]],"id":52671555},{"atb":[[48,2.22],[29,8.71]],"id":52671554},{"atb":[[16,6.96],[11,24.39]],"id":52671556},{"atb":[[9.8,11.87],[7.8,35.86]],"id":52671551},{"atb":[[3.15,113.44],[3.65,39.44]],"id":52671550},{"atb":[[3.6,93.81],[4.2,32.66]],"id":52671553},{"atb":[[18,6.14],[13,20.32]],"id":52671552},{"atb":[[3.6,93.81],[4.2,32.66]],"id":52671547},{"atb":[[3.15,113.44],[3.65,39.44]],"id":52671546},{"atb":[[16,6.96],[11,24.39]],"id":52671549},{"atb":[[7.2,39.33],[9.2,12.74]],"id":52671548},{"atb":[[4.3,47.53],[3.65,131.52]],"id":52671543},{"atb":[[3.15,113.44],[3.65,39.44]],"id":52671542},{"atb":[[16,6.96],[11,24.39]],"id":52671545},{"atb":[[7.2,39.33],[9.2,22.32]],"id":52671544}],"con":true,"img":false}]}
{"op":"mcm","clk":"11449669366","pt":1717313257591,"mc":[{"id":"1.229554923","rc":[{"atb":[[7.2,0],[9.2,0],[10.5,0],[8.2,0]],"id":52671563},{"atb":[[16.5,0],[9.6,0],[11.5,0],[14,0]],"id":52671562},{"atb":[[16,0],[18.5,0],[22,0],[13.5,0]],"id":52671564}],"con":true,"img":false}]}
{"op":"mcm","clk":"11449669401","pt":1717313258264,"mc":[{"id":"1.229554923","rc":[{"atb":[[11,2.62],[7.4,16.35],[8.4,10.61],[9.4,6.23]],"id":52671563},{"atb":[[17,1.64],[12,7.14],[9.8,11.89],[14.5,3.88]],"id":52671562},{"atb":[[17.5,4.76],[20,2.75],[25,1.09],[15,7.48]],"id":52671564}],"con":true,"img":false}]}
{"op":"mcm","clk":"11449669495","pt":1717313260177,"mc":[{"id":"1.229554923","rc":[{"atb":[[18.5,0],[22,0]],"id":52671554}],"con":true,"img":false}]}
{"op":"mcm","clk":"11449669525","pt":1717313260899,"mc":[{"id":"1.229554923","rc":[{"atb":[[19.5,4.24],[24,2.28]],"id":52671554}],"con":true,"img":false}]}
{"op":"mcm","clk":"11449670132","pt":1717313273588,"mc":[{"id":"1.229554923","rc":[{"atb":[[16,0],[22,0]],"id":52671563},{"atb":[[9.2,0],[13,0]],"id":52671562},{"atb":[[10.5,0],[8.2,0]],"id":52671565},{"atb":[[100,0],[50,0]],"id":52671564},{"atb":[[10.5,0],[8.2,0]],"id":52671561},{"atb":[[10.5,0],[8.2,0]],"id":52671560},{"atb":[[7.2,0],[9.2,0]],"id":52671555},{"atb":[[48,0],[29,0]],"id":52671554},{"atb":[[16,0],[11,0]],"id":52671556},{"atb":[[9.8,0],[7.8,0]],"id":52671551},{"atb":[[3.15,0],[3.65,0]],"id":52671550},{"atb":[[3.6,0],[4.2,0]],"id":52671553},{"atb":[[18,0],[13,0]],"id":52671552},{"atb":[[3.6,0],[4.2,0]],"id":52671547},{"atb":[[3.15,0],[3.65,0]],"id":52671546},{"atb":[[16,0],[11,0]],"id":52671549},{"atb":[[7.2,0],[9.2,0]],"id":52671548},{"atb":[[4.3,15.85],[3.65,39.48]],"id":52671543},{"atb":[[3.15,0],[3.65,0]],"id":52671542},{"atb":[[16,0],[11,0]],"id":52671545},{"atb":[[7.2,0],[9.2,9.57]],"id":52671544}],"con":true,"img":false}]}
{"op":"mcm","clk":"11449671575","pt":1717313301842,"mc":[{"id":"1.229554923","rc":[{"atb":[[17,15.24],[24,4.54]],"id":52671563},{"atb":[[9.2,29.74],[13,8.71]],"id":52671562},{"atb":[[10.5,11],[8.2,33.87]],"id":52671565},{"atb":[[140,0.75],[70,3.53]],"id":52671564},{"atb":[[8,34.84],[10,23.24]],"id":52671561},{"atb":[[10.5,11],[8.2,33.87]],"id":52671560},{"atb":[[7.4,38.1],[9.4,12.44]],"id":52671555},{"atb":[[75,1.41],[40,6.25]],"id":52671554},{"atb":[[16.5,6.74],[11.5,23.22]],"id":52671556},{"atb":[[10.5,11],[8.2,33.87]],"id":52671551},{"atb":[[3.55,40.99],[3.05,118.97]],"id":52671550},{"atb":[[4.3,31.67],[3.65,92.03]],"id":52671553},{"atb":[[18.5,5.97],[13.5,19.51]],"id":52671552},{"atb":[[4,34.84],[3.5,97.56]],"id":52671547},{"atb":[[3.15,113.44],[3.65,39.44]],"id":52671546},{"atb":[[16,6.96],[11,24.39]],"id":52671549},{"atb":[[7.2,39.33],[9.2,12.74]],"id":52671548},{"atb":[[4.3,47.53],[3.65,131.52]],"id":52671543},{"atb":[[3.55,40.99],[3.05,118.97]],"id":52671542},{"atb":[[16.5,6.74],[11.5,23.22]],"id":52671545},{"atb":[[7.4,38.1],[9.4,12.44]],"id":52671544}],"con":true,"img":false}]}
{"op":"mcm","clk":"11449673083","pt":1717313329956,"mc":[{"id":"1.229554923","rc":[{"atb":[[17,0],[24,0]],"id":52671563},{"atb":[[9.2,0],[13,0]],"id":52671562},{"atb":[[10.5,0],[8.2,0]],"id":52671565},{"atb":[[140,0],[70,0]],"id":52671564},{"atb":[[8,0],[10,11.63]],"id":52671561},{"atb":[[10.5,0],[8.2,0]],"id":52671560},{"atb":[[7.4,0],[9.4,0]],"id":52671555},{"atb":[[75,0],[40,0]],"id":52671554},{"atb":[[16.5,0],[11.5,0]],"id":52671556},{"atb":[[10.5,0],[8.2,0]],"id":52671551},{"atb":[[3.55,0],[3.05,0]],"id":52671550},{"atb":[[4.3,0],[3.65,0]],"id":52671553},{"atb":[[18.5,0],[13.5,0]],"id":52671552},{"atb":[[4,0],[3.5,0]],"id":52671547},{"atb":[[3.15,0],[3.65,0]],"id":52671546},{"atb":[[16,0],[11,0]],"id":52671549},{"atb":[[7.2,0],[9.2,0]],"id":52671548},{"atb":[[4.3,15.85],[3.65,39.48]],"id":52671543},{"atb":[[3.55,0],[3.05,0]],"id":52671542},{"atb":[[16.5,0],[11.5,0]],"id":52671545},{"atb":[[7.4,0],[9.4,0]],"id":52671544}],"con":true,"img":false}]}
{"op":"mcm","clk":"11449674328","pt":1717313351382,"mc":[{"id":"1.229554923","rc":[{"atb":[[17.5,14.77],[25,4.35]],"id":52671563},{"atb":[[9.2,29.74],[13,8.71]],"id":52671562},{"atb":[[11,10.45],[8.4,32.96]],"id":52671565},{"atb":[[170,0.61],[85,2.9]],"id":52671564},{"atb":[[10.5,11],[8.2,33.87]],"id":52671561},{"atb":[[11,15.69],[8.4,47.1]],"id":52671560},{"atb":[[7.4,38.1],[9.4,12.44]],"id":52671555},{"atb":[[70,1.51],[38,6.59]],"id":52671554},{"atb":[[16.5,6.74],[11.5,23.22]],"id":52671556},{"atb":[[10.5,11],[8.2,33.87]],"id":52671551},{"atb":[[3.55,40.99],[3.05,118.97]],"id":52671550},{"atb":[[4.3,31.67],[3.65,92.03]],"id":52671553},{"atb":[[18.5,5.97],[13.5,19.51]],"id":52671552},{"atb":[[4,34.84],[3.5,97.56]],"id":52671547},{"atb":[[3.15,113.44],[3.65,39.44]],"id":52671546},{"atb":[[16,6.96],[11,24.39]],"id":52671549},{"atb":[[7.2,39.33],[9.2,12.74]],"id":52671548},{"atb":[[4.3,47.53],[3.65,131.52]],"id":52671543},{"atb":[[3.55,40.99],[3.05,118.97]],"id":52671542},{"atb":[[16.5,6.74],[11.5,23.22]],"id":52671545},{"atb":[[7.4,38.1],[9.4,12.44]],"id":52671544}],"con":true,"img":false}]}
{"op":"mcm","clk":"11449680101","pt":1717313441382,"mc":[{"id":"1.229554923","rc":[{"atb":[[17.5,0],[25,0]],"id":52671563},{"atb":[[9.2,0],[13,0]],"id":52671562},{"atb":[[11,0],[8.4,0]],"id":52671565},{"atb":[[170,0],[85,0]],"id":52671564},{"atb":[[10.5,0],[8.2,0]],"id":52671561},{"atb":[[11,5.23],[8.4,14.14]],"id":52671560},{"atb":[[7.4,0],[9.4,0]],"id":52671555},{"atb":[[70,0],[38,0]],"id":52671554},{"atb":[[16.5,0],[11.5,0]],"id":52671556},{"atb":[[10.5,0],[8.2,0]],"id":52671551},{"atb":[[3.55,0],[3.05,0]],"id":52671550},{"atb":[[4.3,0],[3.65,0]],"id":52671553},{"atb":[[18.5,0],[13.5,0]],"id":52671552},{"atb":[[4,0],[3.5,0]],"id":52671547},{"atb":[[3.15,0],[3.65,0]],"id":52671546},{"atb":[[16,0],[11,0]],"id":52671549},{"atb":[[7.2,0],[9.2,0]],"id":52671548},{"atb":[[4.3,15.85],[3.65,39.48]],"id":52671543},{"atb":[[3.55,0],[3.05,0]],"id":52671542},{"atb":[[16.5,0],[11.5,0]],"id":52671545},{"atb":[[7.4,0],[9.4,0]],"id":52671544}],"con":true,"img":false}]}
{"op":"mcm","clk":"11449680671","pt":1717313449233,"mc":[{"id":"1.229554923","rc":[{"atb":[[11,10.45],[8.4,32.96]],"id":52671561},{"atb":[[8.6,32.09],[11.5,9.95]],"id":52671560},{"atb":[[4,34.84],[3.5,97.56]],"id":52671547},{"atb":[[3.15,113.44],[3.65,39.44]],"id":52671546},{"atb":[[16,6.96],[11,24.39]],"id":52671549},{"atb":[[7.2,39.33],[9.2,12.74]],"id":52671548},{"atb":[[3.6,93.81],[4.2,32.66]],"id":52671543},{"atb":[[3.55,40.99],[3.05,118.97]],"id":52671542},{"atb":[[16.5,6.74],[11.5,23.22]],"id":52671545},{"atb":[[7.4,38.1],[9.4,12.44]],"id":52671544}],"con":true,"img":false}]}
{"op":"mcm","clk":"11449680679","pt":1717313449330,"mc":[{"id":"1.229554923","rc":[{"atb":[[18,14.34],[26,4.18]],"id":52671563},{"atb":[[13.5,8.36],[9.4,29.03]],"id":52671562},{"atb":[[8.6,32.09],[11.5,17.43]],"id":52671565},{"atb":[[190,0.55],[95,2.59]],"id":52671564},{"atb":[[7.4,38.1],[9.4,12.44]],"id":52671555},{"atb":[[70,1.51],[38,6.59]],"id":52671554},{"atb":[[16.5,6.74],[11.5,23.22]],"id":52671556},{"atb":[[10.5,11],[8.2,33.87]],"id":52671551},{"atb":[[3.55,40.99],[3.05,118.97]],"id":52671550},{"atb":[[3.6,93.81],[4.2,32.66]],"id":52671553},{"atb":[[18.5,5.97],[13.5,19.51]],"id":52671552}],"con":true,"img":false}]}
{"op":"mcm","clk":"11449693458","pt":1717313605037,"mc":[{"id":"1.229554923","rc":[{"atb":[[18,0],[26,0]],"id":52671563},{"atb":[[13.5,0],[9.4,0]],"id":52671562},{"atb":[[8.6,0],[11.5,7.48]],"id":52671565},{"atb":[[190,0],[95,0]],"id":52671564},{"atb":[[11,0],[8.4,0]],"id":52671561},{"atb":[[8.6,0],[11.5,0]],"id":52671560},{"atb":[[7.4,0],[9.4,0]],"id":52671555},{"atb":[[70,0],[38,0]],"id":52671554},{"atb":[[16.5,0],[11.5,0]],"id":52671556},{"atb":[[10.5,0],[8.2,0]],"id":52671551},{"atb":[[3.55,0],[3.05,0]],"id":52671550},{"atb":[[3.6,0],[4.2,0]],"id":52671553},{"atb":[[18.5,0],[13.5,0]],"id":52671552},{"atb":[[4,0],[3.5,0]],"id":52671547},{"atb":[[3.15,0],[3.65,0]],"id":52671546},{"atb":[[16,0],[11,0]],"id":52671549},{"atb":[[7.2,0],[9.2,0]],"id":52671548},{"atb":[[3.6,0],[4.2,0]],"id":52671543},{"atb":[[3.55,0],[3.05,0]],"id":52671542},{"atb":[[16.5,0],[11.5,0]],"id":52671545},{"atb":[[7.4,0],[9.4,0]],"id":52671544}],"con":true,"img":false}]}
{"op":"mcm","clk":"11449696057","pt":1717313635100,"mc":[{"id":"1.229554923","rc":[{"atb":[[17.5,14.77],[25,4.35]],"id":52671563},{"atb":[[13.5,8.36],[9.4,29.03]],"id":52671562},{"atb":[[8.6,32.09],[11.5,17.43]],"id":52671565},{"atb":[[190,0.55],[95,2.59]],"id":52671564},{"atb":[[11,10.45],[8.4,32.96]],"id":52671561},{"atb":[[8.6,32.09],[11.5,9.95]],"id":52671560},{"atb":[[7.4,38.1],[9.4,12.44]],"id":52671555},{"atb":[[65,1.63],[36,6.96]],"id":52671554},{"atb":[[16.5,6.74],[11.5,23.22]],"id":52671556},{"atb":[[11,18.3],[8.4,32.96]],"id":52671551},{"atb":[[3,121.95],[3.5,41.81]],"id":52671550},{"atb":[[3.7,90.33],[4.4,30.74]],"id":52671553},{"atb":[[18.5,5.97],[13.5,19.51]],"id":52671552},{"atb":[[4.1,33.71],[3.55,95.64]],"id":52671547},{"atb":[[3.6,40.2],[3.1,116.14]],"id":52671546},{"atb":[[16,6.96],[11,24.39]],"id":52671549},{"atb":[[7.2,39.33],[9.2,12.74]],"id":52671548},{"atb":[[3.7,90.33],[4.4,30.74]],"id":52671543},{"atb":[[3,121.95],[3.5,41.81]],"id":52671542},{"atb":[[16.5,6.74],[11.5,23.22]],"id":52671545},{"atb":[[7.4,38.1],[9.4,12.44]],"id":52671544}],"con":true,"img":false}]}
{"op":"mcm","clk":"11449730180","pt":1717314027587,"mc":[{"id":"1.229554923","rc":[{"atb":[[5,0],[5.5,0],[6,0],[7,0]],"id":52671553},{"atb":[[5,0],[5.5,0],[6,0],[7,0]],"id":52671547}],"con":true,"img":false}]}
{"op":"mcm","clk":"11449730256","pt":1717314028318,"mc":[{"id":"1.229554923","rc":[{"atb":[[6.4,9.69],[7.4,4.09],[5.2,24.91],[5.7,16.69]],"id":52671553},{"atb":[[5.6,17.06],[7.2,4.22],[5.1,25.52],[6.2,10.06]],"id":52671547}],"con":true,"img":false}]}
{"op":"mcm","clk":"11449740117","pt":1717314133336,"mc":[{"id":"1.229554923","rc":[{"atb":[[28,0]],"id":52671556}],"con":true,"img":false}]}
{"op":"mcm","clk":"11449740126","pt":1717314133439,"mc":[{"id":"1.229554923","rc":[{"atb":[[36,0],[46,0]],"id":52671556}],"con":true,"img":false}]}
{"op":"mcm","clk":"11449740135","pt":1717314133542,"mc":[{"id":"1.229554923","rc":[{"atb":[[23,0]],"id":52671556}],"con":true,"img":false}]}
{"op":"mcm","clk":"11449740185","pt":1717314134060,"mc":[{"id":"1.229554923","rc":[{"atb":[[29,2.8]],"id":52671556}],"con":true,"img":false}]}
{"op":"mcm","clk":"11449740193","pt":1717314134161,"mc":[{"id":"1.229554923","rc":[{"atb":[[38,1.41],[48,0.55]],"id":52671556}],"con":true,"img":false}]}
{"op":"mcm","clk":"11449740208","pt":1717314134264,"mc":[{"id":"1.229554923","rc":[{"atb":[[24,4.55]],"id":52671556}],"con":true,"img":false}]}
{"op":"mcm","clk":"11449750501","pt":1717314248437,"mc":[{"id":"1.229554923","rc":[{"atb":[[17,0],[12,0],[9.8,0],[14.5,0]],"id":52671562},{"atb":[[16.5,0],[9.6,0],[11.5,9.95],[14,0]],"id":52671565},{"atb":[[17.5,0],[20,0],[25,0],[15,0]],"id":52671564},{"atb":[[17.5,0],[10,0],[12.5,0],[15,0]],"id":52671561},{"atb":[[11,0],[13.5,0],[8.4,0],[9.4,0]],"id":52671560},{"atb":[[38,0],[48,0],[24,0],[29,0]],"id":52671556},{"atb":[[36,0],[46,0],[23,0],[28,0]],"id":52671549}],"con":true,"img":false}]}
{"op":"mcm","clk":"11449750576","pt":1717314249213,"mc":[{"id":"1.229554923","rc":[{"atb":[[17,1.64],[12,7.14],[9.8,11.89],[14.5,3.88]],"id":52671562},{"atb":[[16.5,1.69],[9.6,12.17],[11.5,17.43],[14,4.02]],"id":52671565},{"atb":[[17.5,4.76],[20,2.75],[25,1.09],[15,7.48]],"id":52671564},{"atb":[[17.5,1.59],[10,11.63],[12.5,6.82],[15,3.74]],"id":52671561},{"atb":[[11,5.23],[13.5,2.09],[8.4,14.14],[9.4,9.34]],"id":52671560},{"atb":[[38,1.41],[48,0.55],[24,4.55],[29,2.8]],"id":52671556},{"atb":[[36,1.5],[46,0.58],[23,4.76],[28,2.91]],"id":52671549}],"con":true,"img":false}]}
{"op":"mcm","clk":"11449753638","pt":1717314283862,"mc":[{"id":"1.229554923","rc":[{"atb":[[17.5,0],[25,0]],"id":52671563},{"atb":[[13.5,0],[9.4,0]],"id":52671562},{"atb":[[8.6,0],[11.5,7.48]],"id":52671565},{"atb":[[190,0],[95,0]],"id":52671564},{"atb":[[11,0],[8.4,0]],"id":52671561},{"atb":[[8.6,0],[11.5,0]],"id":52671560},{"atb":[[7.4,0],[9.4,0]],"id":52671555},{"atb":[[65,0],[36,0]],"id":52671554},{"atb":[[16.5,0],[11.5,0]],"id":52671556},{"atb":[[11,7.85],[8.4,0]],"id":52671551},{"atb":[[3,0],[3.5,0]],"id":52671550},{"atb":[[3.7,0],[4.4,0]],"id":52671553},{"atb":[[18.5,0],[13.5,0]],"id":52671552},{"atb":[[4.1,0],[3.55,0]],"id":52671547},{"atb":[[3.6,0],[3.1,0]],"id":52671546},{"atb":[[16,0],[11,0]],"id":52671549},{"atb":[[7.2,0],[9.2,0]],"id":52671548},{"atb":[[3.7,0],[4.4,0]],"id":52671543},{"atb":[[3,0],[3.5,0]],"id":52671542},{"atb":[[16.5,0],[11.5,0]],"id":52671545},{"atb":[[7.4,0],[9.4,0]],"id":52671544}],"con":true,"img":false}]}
{"op":"mcm","clk":"11449755528","pt":1717314306096,"mc":[{"id":"1.229554923","rc":[{"atb":[[11,10.45],[8.4,32.96]],"id":52671561},{"atb":[[8.6,32.09],[11.5,9.95]],"id":52671560},{"atb":[[4.1,33.71],[3.55,95.64]],"id":52671547},{"atb":[[3.6,40.2],[3.1,116.14]],"id":52671546},{"atb":[[16,6.96],[11,24.39]],"id":52671549},{"atb":[[7.2,39.33],[9.2,12.74]],"id":52671548},{"atb":[[3.7,90.33],[4.4,30.74]],"id":52671543},{"atb":[[3,121.95],[3.5,41.81]],"id":52671542},{"atb":[[16.5,6.74],[11.5,23.22]],"id":52671545},{"atb":[[7.4,38.1],[9.4,12.44]],"id":52671544}],"con":true,"img":false}]}
{"op":"mcm","clk":"11449755540","pt":1717314306202,"mc":[{"id":"1.229554923","rc":[{"atb":[[17.5,14.77],[25,4.35]],"id":52671563},{"atb":[[13.5,8.36],[9.4,29.03]],"id":52671562},{"atb":[[8.6,32.09],[11.5,17.43]],"id":52671565},{"atb":[[190,0.55],[95,2.59]],"id":52671564},{"atb":[[7.4,38.1],[9.4,12.44]],"id":52671555},{"atb":[[65,1.63],[36,6.96]],"id":52671554},{"atb":[[16.5,6.74],[11.5,23.22]],"id":52671556},{"atb":[[11,18.3],[8.4,32.96]],"id":52671551},{"atb":[[3,121.95],[3.5,41.81]],"id":52671550},{"atb":[[3.7,90.33],[4.4,30.74]],"id":52671553},{"atb":[[18.5,5.97],[13.5,19.51]],"id":52671552}],"con":true,"img":false}]}
{"op":"mcm","clk":"11449823477","pt":1717315076909,"mc":[{"id":"1.229554923","rc":[{"atb":[[19.5,0],[24,0]],"id":52671554},{"atb":[[38,0],[48,0],[24,0],[29,0]],"id":52671556},{"atb":[[38,0],[19.5,0],[24,0],[29,0]],"id":52671552}],"con":true,"img":false}]}
{"op":"mcm","clk":"11449823489","pt":1717315077010,"mc":[{"id":"1.229554923","rc":[{"atb":[[11,0],[7.4,0],[8.4,0],[9.4,0]],"id":52671563},{"atb":[[36,0],[46,0],[23,0],[28,0]],"id":52671549},{"atb":[[36,0],[19,0],[23,0],[28,0]],"id":52671545}],"con":true,"img":false}]}
{"op":"mcm","clk":"11449823546","pt":1717315077637,"mc":[{"id":"1.229554923","rc":[{"atb":[[75,0.71],[50,1.6]],"id":52671554},{"atb":[[17.5,3.17],[20,1.38],[12.5,9.1],[15,5.6]],"id":52671556},{"atb":[[17,6.54],[19.5,4.24],[24,2.28],[29,0.94]],"id":52671552}],"con":true,"img":false}]}
{"op":"mcm","clk":"11449823553","pt":1717315077693,"mc":[{"id":"1.229554923","rc":[{"atb":[[130,0.2],[65,1.22],[90,0.59],[46,2.32]],"id":52671563},{"atb":[[16,13.94],[18.5,4.48],[22,2.49],[27,1]],"id":52671549},{"atb":[[17,4.9],[19.5,2.83],[24,1.14],[14.5,7.75]],"id":52671545}],"con":true,"img":false}]}
{"op":"mcm","clk":"11449843263","pt":1717315213980,"mc":[{"id":"1.229554923","rc":[{"atb":[[17,0],[12,0],[9.8,0],[14.5,0]],"id":52671562},{"atb":[[16.5,0],[9.6,0],[11.5,9.95],[14,0]],"id":52671565},{"atb":[[17.5,0],[20,0],[25,0],[15,0]],"id":52671564},{"atb":[[17.5,0],[10,0],[12.5,0],[15,0]],"id":52671561},{"atb":[[11,0],[13.5,0],[9.4,0]],"id":52671560}],"con":true,"img":false}]}
{"op":"mcm","clk":"11449843275","pt":1717315214080,"mc":[{"id":"1.229554923","rc":[{"atb":[[8.4,0]],"id":52671560}],"con":true,"img":false}]}
{"op":"mcm","clk":"11449843343","pt":1717315214699,"mc":[{"id":"1.229554923","rc":[{"atb":[[32,0.84],[18,6.15],[21,3.92],[26,2.09]],"id":52671562},{"atb":[[16,5.23],[18.5,2.99],[22,1.25],[13.5,8.37]],"id":52671565},{"atb":[[34,2.38],[44,1.22],[27,4.02],[60,0.44]],"id":52671564},{"atb":[[17,6.54],[19.5,4.24],[24,2.28],[29,0.94]],"id":52671561},{"atb":[[20,4.13],[25,2.18],[30,0.9]],"id":52671560}],"con":true,"img":false}]}
{"op":"mcm","clk":"11449843353","pt":1717315214800,"mc":[{"id":"1.229554923","rc":[{"atb":[[17.5,6.34]],"id":52671560}],"con":true,"img":false}]}
{"op":"mcm","clk":"11449862835","pt":1717315412239,"mc":[{"id":"1.229554923","rc":[{"atb":[[17.5,0],[25,0]],"id":52671563},{"atb":[[13.5,0],[9.4,0]],"id":52671562},{"atb":[[8.6,0],[11.5,0]],"id":52671565},{"atb":[[190,0],[95,0]],"id":52671564},{"atb":[[11,0],[8.4,0]],"id":52671561},{"atb":[[8.6,0],[11.5,0]],"id":52671560},{"atb":[[7.4,0],[9.4,0]],"id":52671555},{"atb":[[65,0],[36,0]],"id":52671554},{"atb":[[16.5,0],[11.5,0]],"id":52671556},{"atb":[[11,7.85],[8.4,0]],"id":52671551},{"atb":[[3,0],[3.5,0]],"id":52671550},{"atb":[[3.7,0],[4.4,0]],"id":52671553},{"atb":[[18.5,0],[13.5,0]],"id":52671552},{"atb":[[4.1,0],[3.55,0]],"id":52671547},{"atb":[[3.6,0],[3.1,0]],"id":52671546},{"atb":[[16,6.97],[11,0]],"id":52671549},{"atb":[[7.2,0],[9.2,0]],"id":52671548},{"atb":[[3.7,0],[4.4,0]],"id":52671543},{"atb":[[3,0],[3.5,0]],"id":52671542},{"atb":[[16.5,0],[11.5,0]],"id":52671545},{"atb":[[7.4,0],[9.4,0]],"id":52671544}],"con":true,"img":false}]}
{"op":"mcm","clk":"11449866542","pt":1717315447498,"mc":[{"id":"1.229554923","rc":[{"atb":[[17.5,14.77],[25,4.35]],"id":52671563},{"atb":[[13.5,8.36],[9.4,29.03]],"id":52671562},{"atb":[[8.6,32.09],[11.5,9.95]],"id":52671565},{"atb":[[190,0.55],[95,2.59]],"id":52671564},{"atb":[[11,10.45],[8.4,32.96]],"id":52671561},{"atb":[[8.6,32.09],[11.5,9.95]],"id":52671560},{"atb":[[7.4,38.1],[9.4,12.44]],"id":52671555},{"atb":[[65,1.63],[36,6.96]],"id":52671554},{"atb":[[16.5,6.74],[11.5,23.22]],"id":52671556},{"atb":[[11,18.3],[8.4,32.96]],"id":52671551},{"atb":[[3,121.95],[3.5,41.81]],"id":52671550},{"atb":[[3.7,90.33],[4.4,30.74]],"id":52671553},{"atb":[[18.5,5.97],[13.5,19.51]],"id":52671552},{"atb":[[4.1,33.71],[3.55,95.64]],"id":52671547},{"atb":[[3.6,40.2],[3.1,116.14]],"id":52671546},{"atb":[[16,13.94],[11,24.39]],"id":52671549},{"atb":[[7.2,39.33],[9.2,12.74]],"id":52671548},{"atb":[[3.7,90.33],[4.4,30.74]],"id":52671543},{"atb":[[3,121.95],[3.5,41.81]],"id":52671542},{"atb":[[16.5,6.74],[11.5,23.22]],"id":52671545},{"atb":[[7.4,38.1],[9.4,12.44]],"id":52671544}],"con":true,"img":false}]}
{"op":"mcm","clk":"11449875824","pt":1717315535557,"mc":[{"id":"1.229554923","rc":[{"atb":[[5.6,0],[7.2,0],[5.1,0],[6.2,0]],"id":52671547}],"con":true,"img":false}]}
{"op":"mcm","clk":"11449875903","pt":1717315536380,"mc":[{"id":"1.229554923","rc":[{"atb":[[6.4,9.69],[7.4,4.09],[5.2,24.91],[5.7,16.69]],"id":52671547}],"con":true,"img":false}]}
{"op":"mcm","clk":"11449879484","pt":1717315574029,"mc":[{"id":"1.229554923","rc":[{"atb":[[16,0],[18.5,0],[22,0],[13.5,0]],"id":52671565},{"atb":[[17.5,0],[20,0],[25,0],[30,0]],"id":52671560},{"atb":[[75,0],[50,0]],"id":52671554}],"con":true,"img":false}]}
{"op":"mcm","clk":"11449879553","pt":1717315574710,"mc":[{"id":"1.229554923","rc":[{"atb":[[16,5.23],[18.5,2.99],[22,1.25],[13.5,8.37]],"id":52671565},{"atb":[[17.5,6.34],[20,4.13],[25,2.18],[30,0.9]],"id":52671560},{"atb":[[75,0.71],[50,1.6]],"id":52671554}],"con":true,"img":false}]}
{"op":"mcm","clk":"11449893722","pt":1717315713296,"mc":[{"id":"1.229554923","rc":[{"atb":[[17.5,0],[25,0]],"id":52671563},{"atb":[[13.5,0],[9.4,0]],"id":52671562},{"atb":[[8.6,0],[11.5,0]],"id":52671565},{"atb":[[190,0],[95,0]],"id":52671564},{"atb":[[11,0],[8.4,0]],"id":52671561},{"atb":[[8.6,0],[11.5,0]],"id":52671560},{"atb":[[7.4,0],[9.4,0]],"id":52671555},{"atb":[[65,0],[36,0]],"id":52671554},{"atb":[[16.5,0],[11.5,0]],"id":52671556},{"atb":[[11,7.85],[8.4,0]],"id":52671551},{"atb":[[3,0],[3.5,0]],"id":52671550},{"atb":[[3.7,0],[4.4,0]],"id":52671553},{"atb":[[18.5,0],[13.5,0]],"id":52671552},{"atb":[[4.1,0],[3.55,0]],"id":52671547},{"atb":[[3.6,0],[3.1,0]],"id":52671546},{"atb":[[16,6.97],[11,0]],"id":52671549},{"atb":[[7.2,0],[9.2,0]],"id":52671548},{"atb":[[3.7,0],[4.4,0]],"id":52671543},{"atb":[[3,0],[3.5,0]],"id":52671542},{"atb":[[16.5,0],[11.5,0]],"id":52671545},{"atb":[[7.4,0],[9.4,0]],"id":52671544}],"con":true,"img":false}]}
{"op":"mcm","clk":"11449899234","pt":1717315764715,"mc":[{"id":"1.229554923","rc":[{"atb":[[17.5,14.77],[25,4.35]],"id":52671563},{"atb":[[13.5,8.36],[9.4,29.03]],"id":52671562},{"atb":[[8.6,32.09],[11.5,9.95]],"id":52671565},{"atb":[[310,0.34],[210,1.16]],"id":52671564},{"atb":[[7.2,39.33],[9.2,12.74]],"id":52671555},{"atb":[[120,0.87],[60,4.13]],"id":52671554},{"atb":[[18,6.14],[13,20.32]],"id":52671556},{"atb":[[11,18.3],[8.4,32.96]],"id":52671551},{"atb":[[3,121.95],[3.5,41.81]],"id":52671550},{"atb":[[3.7,90.33],[4.4,30.74]],"id":52671553},{"atb":[[20,5.5],[15,17.42]],"id":52671552}],"con":true,"img":false}]}
{"op":"mcm","clk":"11449899246","pt":1717315764822,"mc":[{"id":"1.229554923","rc":[{"atb":[[10.5,11],[8.2,33.87]],"id":52671561},{"atb":[[8.6,32.09],[11.5,9.95]],"id":52671560},{"atb":[[4.1,33.71],[3.55,95.64]],"id":52671547},{"atb":[[3.6,40.2],[3.1,116.14]],"id":52671546},{"atb":[[17.5,6.33],[12.5,21.2]],"id":52671549},{"atb":[[7.2,39.33],[9.2,12.74]],"id":52671548},{"atb":[[3.7,90.33],[4.4,30.74]],"id":52671543},{"atb":[[3,121.95],[3.5,41.81]],"id":52671542},{"atb":[[18,6.14],[13,20.32]],"id":52671545},{"atb":[[7.2,39.33],[9.2,22.32]],"id":52671544}],"con":true,"img":false}]}
{"op":"mcm","clk":"11449970518","pt":1717316552873,"mc":[{"id":"1.229554923","rc":[{"atb":[[17.5,0],[25,0]],"id":52671563},{"atb":[[13.5,0],[9.4,0]],"id":52671562},{"atb":[[8.6,0],[11.5,0]],"id":52671565},{"atb":[[310,0],[210,0]],"id":52671564},{"atb":[[10.5,0],[8.2,0]],"id":52671561},{"atb":[[8.6,0],[11.5,0]],"id":52671560},{"atb":[[7.2,0],[9.2,0]],"id":52671555},{"atb":[[120,0],[60,0]],"id":52671554},{"atb":[[18,0],[13,0]],"id":52671556},{"atb":[[11,7.85],[8.4,0]],"id":52671551},{"atb":[[3,0],[3.5,0]],"id":52671550},{"atb":[[3.7,0],[4.4,0]],"id":52671553},{"atb":[[20,0],[15,0]],"id":52671552},{"atb":[[4.1,0],[3.55,0]],"id":52671547},{"atb":[[3.6,0],[3.1,0]],"id":52671546},{"atb":[[17.5,0],[12.5,0]],"id":52671549},{"atb":[[7.2,0],[9.2,0]],"id":52671548},{"atb":[[3.7,0],[4.4,0]],"id":52671543},{"atb":[[3,0],[3.5,0]],"id":52671542},{"atb":[[18,0],[13,0]],"id":52671545},{"atb":[[7.2,0],[9.2,9.57]],"id":52671544}],"con":true,"img":false}]}
{"op":"mcm","clk":"11449972397","pt":1717316581815,"mc":[{"id":"1.229554923","rc":[{"atb":[[17.5,14.77],[25,4.35]],"id":52671563},{"atb":[[13.5,8.36],[9.4,29.03]],"id":52671562},{"atb":[[8.6,32.09],[11.5,9.95]],"id":52671565},{"atb":[[310,0.34],[210,1.16]],"id":52671564},{"atb":[[10.5,11],[8.2,33.87]],"id":52671561},{"atb":[[8.6,32.09],[11.5,9.95]],"id":52671560},{"atb":[[7.2,39.33],[9.2,12.74]],"id":52671555},{"atb":[[120,0.87],[60,4.13]],"id":52671554},{"atb":[[18,6.14],[13,20.32]],"id":52671556},{"atb":[[11,18.3],[8.4,32.96]],"id":52671551},{"atb":[[3,121.95],[3.5,41.81]],"id":52671550},{"atb":[[3.7,90.33],[4.4,30.74]],"id":52671553},{"atb":[[20,5.5],[15,17.42]],"id":52671552},{"atb":[[4.1,33.71],[3.55,95.64]],"id":52671547},{"atb":[[3.6,40.2],[3.1,116.14]],"id":52671546},{"atb":[[17.5,6.33],[12.5,21.2]],"id":52671549},{"atb":[[7.2,39.33],[9.2,12.74]],"id":52671548},{"atb":[[3.7,90.33],[4.4,30.74]],"id":52671543},{"atb":[[3,121.95],[3.5,41.81]],"id":52671542},{"atb":[[18,6.14],[13,20.32]],"id":52671545},{"atb":[[7.2,39.33],[9.2,22.32]],"id":52671544}],"con":true,"img":false}]}
{"op":"mcm","clk":"11449975030","pt":1717316619002,"mc":[{"id":"1.229554923","rc":[{"atb":[[16,0],[18.5,0],[22,0],[27,0]],"id":52671549}],"con":true,"img":false}]}
{"op":"mcm","clk":"11449975039","pt":1717316619059,"mc":[{"id":"1.229554923","rc":[{"atb":[[130,0],[65,0],[90,0],[46,0]],"id":52671563},{"atb":[[32,0],[18,0],[21,0],[26,0]],"id":52671562},{"atb":[[16,0],[18.5,0],[22,0],[13.5,0]],"id":52671565},{"atb":[[34,0],[44,0],[27,0],[60,0]],"id":52671564},{"atb":[[75,0],[50,0]],"id":52671554},{"atb":[[17.5,0],[20,0],[12.5,0],[15,0]],"id":52671556},{"atb":[[17,0],[19.5,0],[24,0],[29,0]],"id":52671552},{"atb":[[17,0],[19.5,0],[24,0],[14.5,0]],"id":52671545}],"con":true,"img":false}]}
{"op":"mcm","clk":"11449975079","pt":1717316619783,"mc":[{"id":"1.229554923","rc":[{"atb":[[17.5,6.34],[20,4.13],[25,2.18],[30,0.9]],"id":52671562},{"atb":[[16,3.49],[18.5,1.5],[11,10.46],[13.5,6.28]],"id":52671556},{"atb":[[18,4.61],[21,2.62],[26,1.05],[15.5,7.21]],"id":52671552},{"atb":[[17.5,11.09],[20,2.75],[25,1.09],[15,7.48]],"id":52671549},{"atb":[[16.5,5.06],[19,2.91],[23,1.19],[14,8.05]],"id":52671545}],"con":true,"img":false}]}
{"op":"mcm","clk":"11449975087","pt":1717316619887,"mc":[{"id":"1.229554923","rc":[{"atb":[[85,0.62],[44,2.43],[120,0.22],[60,1.33]],"id":52671563},{"atb":[[18,3.08],[21,1.31],[13,8.72],[15.5,5.41]],"id":52671565},{"atb":[[32,2.53],[42,1.28],[26,4.19],[55,0.49]],"id":52671564},{"atb":[[70,0.76],[48,1.67]],"id":52671554}],"con":true,"img":false}]}
{"op":"mcm","clk":"11450000357","pt":1717316949476,"mc":[{"id":"1.229554923","rc":[{"atb":[[17.5,0],[20,0],[25,0],[30,0]],"id":52671560}],"con":true,"img":false}]}
{"op":"mcm","clk":"11450000425","pt":1717316950155,"mc":[{"id":"1.229554923","rc":[{"atb":[[17.5,6.34],[20,4.13],[25,2.18],[30,0.9]],"id":52671560}],"con":true,"img":false}]}
{"op":"mcm","clk":"11450051687","pt":1717317460901,"mc":[{"id":"1.229554923","rc":[{"atb":[[17.5,0],[25,0]],"id":52671563},{"atb":[[13.5,0],[9.4,0]],"id":52671562},{"atb":[[8.6,0],[11.5,0]],"id":52671565},{"atb":[[310,0],[210,0]],"id":52671564},{"atb":[[10.5,0],[8.2,0]],"id":52671561},{"atb":[[8.6,0],[11.5,0]],"id":52671560},{"atb":[[7.2,0],[9.2,0]],"id":52671555},{"atb":[[120,0],[60,0]],"id":52671554},{"atb":[[18,0],[13,0]],"id":52671556},{"atb":[[11,7.85],[8.4,0]],"id":52671551},{"atb":[[3,0],[3.5,0]],"id":52671550},{"atb":[[3.7,0],[4.4,0]],"id":52671553},{"atb":[[20,0],[15,0]],"id":52671552},{"atb":[[4.1,0],[3.55,0]],"id":52671547},{"atb":[[3.6,0],[3.1,0]],"id":52671546},{"atb":[[17.5,4.76],[12.5,0]],"id":52671549},{"atb":[[7.2,0],[9.2,0]],"id":52671548},{"atb":[[3.7,0],[4.4,0]],"id":52671543},{"atb":[[3,0],[3.5,0]],"id":52671542},{"atb":[[18,0],[13,0]],"id":52671545},{"atb":[[7.2,0],[9.2,9.57]],"id":52671544}],"con":true,"img":false}]}
{"op":"mcm","clk":"11450054325","pt":1717317490793,"mc":[{"id":"1.229554923","rc":[{"atb":[[17.5,14.77],[25,4.35]],"id":52671563},{"atb":[[13.5,8.36],[9.4,29.03]],"id":52671562},{"atb":[[8.6,32.09],[11.5,9.95]],"id":52671565},{"atb":[[310,0.34],[210,1.16]],"id":52671564},{"atb":[[10.5,11],[8.2,33.87]],"id":52671561},{"atb":[[8.6,32.09],[11.5,9.95]],"id":52671560},{"atb":[[7.2,39.33],[9.2,12.74]],"id":52671555},{"atb":[[120,0.87],[60,4.13]],"id":52671554},{"atb":[[18,6.14],[13,20.32]],"id":52671556},{"atb":[[11,18.3],[8.4,32.96]],"id":52671551},{"atb":[[3,121.95],[3.5,41.81]],"id":52671550},{"atb":[[3.7,90.33],[4.4,30.74]],"id":52671553},{"atb":[[20,5.5],[15,17.42]],"id":52671552},{"atb":[[4.1,33.71],[3.55,95.64]],"id":52671547},{"atb":[[3.6,40.2],[3.1,116.14]],"id":52671546},{"atb":[[17.5,11.09],[12.5,21.2]],"id":52671549},{"atb":[[7.2,39.33],[9.2,12.74]],"id":52671548},{"atb":[[3.7,90.33],[4.4,30.74]],"id":52671543},{"atb":[[3,121.95],[3.5,41.81]],"id":52671542},{"atb":[[18,6.14],[13,20.32]],"id":52671545},{"atb":[[7.2,39.33],[9.2,22.32]],"id":52671544}],"con":true,"img":false}]}
{"op":"mcm","clk":"11450099793","pt":1717318004002,"mc":[{"id":"1.229554923","rc":[{"atb":[[4.8,0],[4.3,0],[5.8,0],[5.3,0]],"id":52671542}],"con":true,"img":false}]}
{"op":"mcm","clk":"11450100500","pt":1717318012824,"mc":[{"id":"1.229554923","rc":[{"atb":[[3.95,35.47],[4.9,13.41],[4.4,23.08],[5.4,5.94]],"id":52671542}],"con":true,"img":false}]}
{"op":"mcm","clk":"11450100572","pt":1717318013861,"mc":[{"id":"1.229554923","rc":[{"atb":[[5.2,0],[5.7,0],[4.2,0],[4.7,0]],"id":52671550},{"atb":[[4.8,0],[4.3,0],[5.8,0],[5.3,0]],"id":52671546}],"con":true,"img":false}]}
{"op":"mcm","clk":"11450100635","pt":1717318014546,"mc":[{"id":"1.229554923","rc":[{"atb":[[3.95,35.47],[4.9,13.41],[4.4,23.08],[5.4,5.94]],"id":52671550}],"con":true,"img":false}]}
{"op":"mcm","clk":"11450100646","pt":1717318014646,"mc":[{"id":"1.229554923","rc":[{"atb":[[5.6,5.69],[5.1,12.76],[4.6,21.8],[4.1,33.76]],"id":52671546}],"con":true,"img":false}]}
{"op":"mcm","clk":"11450105868","pt":1717318070743,"mc":[{"id":"1.229554923","rc":[{"atb":[[16,0],[18.5,0],[11,0],[13.5,0]],"id":52671556},{"atb":[[16.5,0],[19,0],[23,0],[14,0]],"id":52671545}],"con":true,"img":false}]}
{"op":"mcm","clk":"11450105934","pt":1717318071424,"mc":[{"id":"1.229554923","rc":[{"atb":[[16.5,3.37],[19,1.45],[11.5,9.97],[14,6.04]],"id":52671556}],"con":true,"img":false}]}
{"op":"mcm","clk":"11450105945","pt":1717318071518,"mc":[{"id":"1.229554923","rc":[{"atb":[[17,4.9],[19.5,2.83],[24,1.14],[14.5,7.75]],"id":52671545}],"con":true,"img":false}]}
{"op":"mcm","clk":"11450118696","pt":1717318214487,"mc":[{"id":"1.229554923","rc":[{"atb":[[85,0],[44,0],[120,0],[60,0]],"id":52671563},{"atb":[[17.5,0],[20,0],[25,0],[30,0]],"id":52671562},{"atb":[[18,0],[21,0],[13,0],[15.5,0]],"id":52671565},{"atb":[[17.5,0],[20,0],[25,0],[30,0]],"id":52671560},{"atb":[[70,0],[48,0]],"id":52671554},{"atb":[[16.5,0],[19,0],[11.5,0],[14,0]],"id":52671556},{"atb":[[18,0],[21,0],[26,0],[15.5,0]],"id":52671552},{"atb":[[17.5,6.33],[20,0],[25,0],[15,0]],"id":52671549}],"con":true,"img":false}]}
{"op":"mcm","clk":"11450118706","pt":1717318214591,"mc":[{"id":"1.229554923","rc":[{"atb":[[32,0],[42,0],[26,0],[55,0]],"id":52671564}],"con":true,"img":false}]}
{"op":"mcm","clk":"11450118763","pt":1717318215162,"mc":[{"id":"1.229554923","rc":[{"atb":[[130,0.2],[65,1.22],[90,0.59],[46,2.32]],"id":52671563},{"atb":[[32,0.84],[18,6.15],[21,3.92],[26,2.09]],"id":52671562},{"atb":[[16,5.23],[18.5,2.99],[22,1.25],[13.5,8.37]],"id":52671565},{"atb":[[17.5,6.34],[20,4.13],[25,2.18],[30,0.9]],"id":52671560},{"atb":[[75,0.71],[50,1.6]],"id":52671554},{"atb":[[17.5,3.17],[20,1.38],[12.5,9.1],[15,5.6]],"id":52671556},{"atb":[[17,6.54],[19.5,4.24],[24,2.28],[29,0.94]],"id":52671552},{"atb":[[16,6.97],[18.5,4.48],[22,2.49],[27,1]],"id":52671549}],"con":true,"img":false}]}
{"op":"mcm","clk":"11450118769","pt":1717318215263,"mc":[{"id":"1.229554923","rc":[{"atb":[[65,0.41],[36,2.24],[46,1.16],[28,3.88]],"id":52671564}],"con":true,"img":false}]}
{"op":"mcm","clk":"11450120884","pt":1717318238993,"mc":[{"id":"1.229554923","rc":[{"atb":[[130,0],[65,0],[90,0],[46,0]],"id":52671563},{"atb":[[32,0],[18,0],[21,0],[26,0]],"id":52671562},{"atb":[[16,0],[18.5,0],[22,0],[13.5,0]],"id":52671565},{"atb":[[65,0],[36,0],[46,0],[28,0]],"id":52671564},{"atb":[[75,0],[50,0]],"id":52671554},{"atb":[[17.5,0],[20,0],[12.5,0],[15,0]],"id":52671556},{"atb":[[17,0],[19.5,0],[24,0],[29,0]],"id":52671552},{"atb":[[16,0],[18.5,0],[22,0],[27,0]],"id":52671549}],"con":true,"img":false}]}
{"op":"mcm","clk":"11450120948","pt":1717318239720,"mc":[{"id":"1.229554923","rc":[{"atb":[[85,0.62],[44,2.43],[120,0.22],[60,1.33]],"id":52671563},{"atb":[[17.5,6.34],[20,4.13],[25,2.18],[30,0.9]],"id":52671562},{"atb":[[18,3.08],[21,1.31],[13,8.72],[15.5,5.41]],"id":52671565},{"atb":[[32,2.53],[42,1.28],[26,4.19],[55,0.49]],"id":52671564},{"atb":[[70,0.76],[48,1.67]],"id":52671554},{"atb":[[16.5,3.37],[19,1.45],[11.5,9.97],[14,6.04]],"id":52671556},{"atb":[[18,4.61],[21,2.62],[26,1.05],[15.5,7.21]],"id":52671552},{"atb":[[17.5,11.09],[20,2.75],[25,1.09],[15,7.48]],"id":52671549}],"con":true,"img":false}]}
{"op":"mcm","clk":"11450128174","pt":1717318324162,"mc":[{"id":"1.229554923","rc":[{"atb":[[17.5,0],[25,0]],"id":52671563},{"atb":[[13.5,0],[9.4,0]],"id":52671562},{"atb":[[8.6,0],[11.5,0]],"id":52671565},{"atb":[[310,0],[210,0]],"id":52671564},{"atb":[[10.5,0],[8.2,0]],"id":52671561},{"atb":[[8.6,0],[11.5,0]],"id":52671560},{"atb":[[7.2,0],[9.2,0]],"id":52671555},{"atb":[[120,0],[60,0]],"id":52671554},{"atb":[[18,0],[13,0]],"id":52671556},{"atb":[[11,7.85],[8.4,0]],"id":52671551},{"atb":[[3,0],[3.5,0]],"id":52671550},{"atb":[[3.7,0],[4.4,0]],"id":52671553},{"atb":[[20,0],[15,0]],"id":52671552},{"atb":[[4.1,0],[3.55,0]],"id":52671547},{"atb":[[3.6,0],[3.1,0]],"id":52671546},{"atb":[[17.5,4.76],[12.5,0]],"id":52671549},{"atb":[[7.2,0],[9.2,0]],"id":52671548},{"atb":[[3.7,0],[4.4,0]],"id":52671543},{"atb":[[3,0],[3.5,0]],"id":52671542},{"atb":[[18,0],[13,0]],"id":52671545},{"atb":[[7.2,0],[9.2,9.57]],"id":52671544}],"con":true,"img":false}]}
{"op":"mcm","clk":"11450129268","pt":1717318336095,"mc":[{"id":"1.229554923","rc":[{"atb":[[10.5,11],[8.2,33.87]],"id":52671561},{"atb":[[8.6,32.09],[11.5,9.95]],"id":52671560},{"atb":[[4.1,33.71],[3.55,95.64]],"id":52671547},{"atb":[[3.6,40.2],[3.1,116.14]],"id":52671546},{"atb":[[17.5,11.09],[12.5,21.2]],"id":52671549},{"atb":[[7.2,39.33],[9.2,12.74]],"id":52671548},{"atb":[[3.7,90.33],[4.4,30.74]],"id":52671543},{"atb":[[3,121.95],[3.5,41.81]],"id":52671542},{"atb":[[18,6.14],[13,20.32]],"id":52671545},{"atb":[[7.2,39.33],[9.2,22.32]],"id":52671544}],"con":true,"img":false}]}
{"op":"mcm","clk":"11450129281","pt":1717318336161,"mc":[{"id":"1.229554923","rc":[{"atb":[[17.5,14.77],[25,4.35]],"id":52671563},{"atb":[[13.5,8.36],[9.4,29.03]],"id":52671562},{"atb":[[8.6,32.09],[11.5,9.95]],"id":52671565},{"atb":[[310,0.34],[210,1.16]],"id":52671564},{"atb":[[7.2,39.33],[9.2,12.74]],"id":52671555},{"atb":[[120,0.87],[60,4.13]],"id":52671554},{"atb":[[18,6.14],[13,20.32]],"id":52671556},{"atb":[[11,18.3],[8.4,32.96]],"id":52671551},{"atb":[[3,121.95],[3.5,41.81]],"id":52671550},{"atb":[[3.7,90.33],[4.4,30.74]],"id":52671553},{"atb":[[20,5.5],[15,17.42]],"id":52671552}],"con":true,"img":false}]}
{"op":"mcm","clk":"11450137816","pt":1717318436672,"mc":[{"id":"1.229554923","rc":[{"atb":[[3.95,0],[4.9,0],[4.4,0],[5.4,0]],"id":52671550},{"atb":[[5.6,0],[5.1,0],[4.6,0],[4.1,0]],"id":52671546}],"con":true,"img":false}]}
{"op":"mcm","clk":"11450137901","pt":1717318437558,"mc":[{"id":"1.229554923","rc":[{"atb":[[5.6,5.69],[5.1,12.76],[4.6,21.8],[4.1,33.76]],"id":52671550},{"atb":[[5.2,12.46],[5.7,5.57],[4.2,32.7],[4.7,21.21]],"id":52671546}],"con":true,"img":false}]}
{"op":"mcm","clk":"11450208408","pt":1717319183232,"mc":[{"id":"1.229554923","rc":[{"atb":[[17.5,0],[25,0]],"id":52671563},{"atb":[[13.5,0],[9.4,0]],"id":52671562},{"atb":[[8.6,0],[11.5,0]],"id":52671565},{"atb":[[310,0],[210,0]],"id":52671564},{"atb":[[10.5,0],[8.2,0]],"id":52671561},{"atb":[[8.6,0],[11.5,0]],"id":52671560},{"atb":[[7.2,0],[9.2,0]],"id":52671555},{"atb":[[120,0],[60,0]],"id":52671554},{"atb":[[18,0],[13,0]],"id":52671556},{"atb":[[11,7.85],[8.4,0]],"id":52671551},{"atb":[[3,0],[3.5,0]],"id":52671550},{"atb":[[3.7,0],[4.4,0]],"id":52671553},{"atb":[[20,0],[15,0]],"id":52671552},{"atb":[[4.1,0],[3.55,0]],"id":52671547},{"atb":[[3.6,0],[3.1,0]],"id":52671546},{"atb":[[17.5,4.76],[12.5,0]],"id":52671549},{"atb":[[7.2,0],[9.2,0]],"id":52671548},{"atb":[[3.7,0],[4.4,0]],"id":52671543},{"atb":[[3,0],[3.5,0]],"id":52671542},{"atb":[[18,0],[13,0]],"id":52671545},{"atb":[[7.2,0],[9.2,9.57]],"id":52671544}],"con":true,"img":false}]}
{"op":"mcm","clk":"11450211546","pt":1717319214150,"mc":[{"id":"1.229554923","rc":[{"atb":[[17.5,14.77],[25,4.35]],"id":52671563},{"atb":[[13.5,8.36],[9.4,29.03]],"id":52671562},{"atb":[[8.6,32.09],[11.5,9.95]],"id":52671565},{"atb":[[310,0.34],[210,1.16]],"id":52671564},{"atb":[[10.5,11],[8.2,33.87]],"id":52671561},{"atb":[[8.6,32.09],[11.5,9.95]],"id":52671560},{"atb":[[7.2,39.33],[9.2,12.74]],"id":52671555},{"atb":[[120,0.87],[60,4.13]],"id":52671554},{"atb":[[18,6.14],[13,20.32]],"id":52671556},{"atb":[[11,18.3],[8.4,32.96]],"id":52671551},{"atb":[[3,121.95],[3.5,41.81]],"id":52671550},{"atb":[[3.7,90.33],[4.4,30.74]],"id":52671553},{"atb":[[20,5.5],[15,17.42]],"id":52671552},{"atb":[[4.1,33.71],[3.55,95.64]],"id":52671547},{"atb":[[3.6,40.2],[3.1,116.14]],"id":52671546},{"atb":[[17.5,11.09],[12.5,21.2]],"id":52671549},{"atb":[[7.2,39.33],[9.2,12.74]],"id":52671548},{"atb":[[3.7,90.33],[4.4,30.74]],"id":52671543},{"atb":[[3,121.95],[3.5,41.81]],"id":52671542},{"atb":[[18,6.14],[13,20.32]],"id":52671545},{"atb":[[7.2,39.33],[9.2,22.32]],"id":52671544}],"con":true,"img":false}]}
{"op":"mcm","clk":"11450252185","pt":1717319648493,"mc":[{"id":"1.229554923","rc":[{"atb":[[17,0],[19.5,0],[24,0],[14.5,0]],"id":52671545}],"con":true,"img":false}]}
{"op":"mcm","clk":"11450252255","pt":1717319649208,"mc":[{"id":"1.229554923","rc":[{"atb":[[17,4.9],[19.5,2.83],[24,1.14],[14.5,7.75]],"id":52671545}],"con":true,"img":false}]}
{"op":"mcm","clk":"11450271304","pt":1717319866495,"mc":[{"id":"1.229554923","rc":[{"atb":[[17,0],[19.5,0],[24,0],[29,0]],"id":52671561},{"atb":[[17.5,0],[20,0],[25,0],[30,0]],"id":52671560},{"atb":[[5.6,0],[5.1,0],[4.6,0],[4.1,0]],"id":52671550},{"atb":[[6.4,0],[7.4,0],[5.2,0],[5.7,0]],"id":52671553},{"atb":[[5.2,0],[5.7,0],[4.2,0],[4.7,0]],"id":52671546}],"con":true,"img":false}]}
{"op":"mcm","clk":"11450271387","pt":1717319867274,"mc":[{"id":"1.229554923","rc":[{"atb":[[16.5,6.75],[19,4.36],[23,2.38],[28,0.97]],"id":52671561},{"atb":[[16.5,6.75],[19,4.36],[23,2.38],[28,0.97]],"id":52671560},{"atb":[[4.8,20.65],[4.3,31.71],[5.8,5.45],[5.3,12.17]],"id":52671550},{"atb":[[5.8,16.35],[5.3,24.33],[7.6,3.97],[6.6,9.34]],"id":52671553},{"atb":[[4.9,20.12],[4.4,30.77],[5.9,5.34],[5.4,11.89]],"id":52671546}],"con":true,"img":false}]}
{"op":"mcm","clk":"11450274566","pt":1717319908087,"mc":[{"id":"1.229554923","rc":[{"atb":[[16.5,0],[19,0],[23,0],[28,0]],"id":52671561}],"con":true,"img":false}]}
{"op":"mcm","clk":"11450274615","pt":1717319908792,"mc":[{"id":"1.229554923","rc":[{"atb":[[16,6.97],[18.5,4.48],[22,2.49],[27,1]],"id":52671561}],"con":true,"img":false}]}
{"op":"mcm","clk":"11450275817","pt":1717319924278,"mc":[{"id":"1.229554923","rc":[{"atb":[[16,0],[18.5,0],[22,0],[27,0]],"id":52671561}],"con":true,"img":false}]}
{"op":"mcm","clk":"11450275875","pt":1717319924996,"mc":[{"id":"1.229554923","rc":[{"atb":[[18,4.61],[21,2.62],[26,1.05],[15.5,7.21]],"id":52671561}],"con":true,"img":false}]}
{"op":"mcm","clk":"11450279080","pt":1717319965251,"mc":[{"id":"1.229554923","rc":[{"atb":[[17.5,0],[25,0]],"id":52671563},{"atb":[[13.5,0],[9.4,0]],"id":52671562},{"atb":[[8.6,0],[11.5,0]],"id":52671565},{"atb":[[310,0],[210,0]],"id":52671564},{"atb":[[10.5,0],[8.2,0]],"id":52671561},{"atb":[[8.6,0],[11.5,0]],"id":52671560},{"atb":[[7.2,0],[9.2,0]],"id":52671555},{"atb":[[120,0],[60,0]],"id":52671554},{"atb":[[18,0],[13,0]],"id":52671556},{"atb":[[11,7.85],[8.4,0]],"id":52671551},{"atb":[[3,0],[3.5,0]],"id":52671550},{"atb":[[3.7,0],[4.4,0]],"id":52671553},{"atb":[[20,0],[15,0]],"id":52671552},{"atb":[[4.1,0],[3.55,0]],"id":52671547},{"atb":[[3.6,0],[3.1,0]],"id":52671546},{"atb":[[17.5,4.76],[12.5,0]],"id":52671549},{"atb":[[7.2,0],[9.2,0]],"id":52671548},{"atb":[[3.7,0],[4.4,0]],"id":52671543},{"atb":[[3,0],[3.5,0]],"id":52671542},{"atb":[[18,0],[13,0]],"id":52671545},{"atb":[[7.2,0],[9.2,9.57]],"id":52671544}],"con":true,"img":false}]}
{"op":"mcm","clk":"11450280028","pt":1717319977177,"mc":[{"id":"1.229554923","rc":[{"atb":[[11,10.45],[8.4,32.96]],"id":52671561},{"atb":[[12,9.5],[8.8,31.27]],"id":52671560},{"atb":[[3.45,99.55],[3.95,35.43]],"id":52671547},{"atb":[[3.6,40.2],[3.1,116.14]],"id":52671546},{"atb":[[17,6.53],[12,22.17]],"id":52671549},{"atb":[[7.2,39.33],[9.2,12.74]],"id":52671548},{"atb":[[4.5,29.86],[3.75,88.69]],"id":52671543},{"atb":[[3.4,43.55],[2.96,124.44]],"id":52671542},{"atb":[[18,6.14],[13,20.32]],"id":52671545},{"atb":[[9.6,12.15],[7.6,36.95]],"id":52671544}],"con":true,"img":false}]}
{"op":"mcm","clk":"11450280036","pt":1717319977282,"mc":[{"id":"1.229554923","rc":[{"atb":[[19,13.55],[28,3.87]],"id":52671563},{"atb":[[9.6,28.36],[14,8.04]],"id":52671562},{"atb":[[12,9.5],[8.8,31.27]],"id":52671565},{"atb":[[350,0.29],[250,0.97]],"id":52671564},{"atb":[[9.6,12.15],[7.6,36.95]],"id":52671555},{"atb":[[170,0.61],[85,2.9]],"id":52671554},{"atb":[[18,6.14],[13,20.32]],"id":52671556},{"atb":[[12,9.5],[8.8,31.27]],"id":52671551},{"atb":[[3.4,43.55],[2.96,124.44]],"id":52671550},{"atb":[[4.5,29.86],[3.75,88.69]],"id":52671553},{"atb":[[20,5.5],[15,17.42]],"id":52671552}],"con":true,"img":false}]}
{"op":"mcm","clk":"11450282317","pt":1717320005288,"mc":[{"id":"1.229554923","rc":[{"atb":[[19,0],[28,0]],"id":52671563},{"atb":[[9.6,0],[14,0]],"id":52671562},{"atb":[[12,0],[8.8,0]],"id":52671565},{"atb":[[350,0],[250,0]],"id":52671564},{"atb":[[11,0],[8.4,0]],"id":52671561},{"atb":[[12,0],[8.8,0]],"id":52671560},{"atb":[[9.6,0],[7.6,0]],"id":52671555},{"atb":[[170,0],[85,0]],"id":52671554},{"atb":[[18,0],[13,0]],"id":52671556},{"atb":[[12,0],[8.8,0]],"id":52671551},{"atb":[[3.4,0],[2.96,0]],"id":52671550},{"atb":[[4.5,0],[3.75,0]],"id":52671553},{"atb":[[20,0],[15,0]],"id":52671552},{"atb":[[3.45,0],[3.95,0]],"id":52671547},{"atb":[[3.6,0],[3.1,0]],"id":52671546},{"atb":[[17,0],[12,0]],"id":52671549},{"atb":[[7.2,0],[9.2,0]],"id":52671548},{"atb":[[4.5,0],[3.75,0]],"id":52671543},{"atb":[[3.4,0],[2.96,0]],"id":52671542},{"atb":[[18,0],[13,0]],"id":52671545},{"atb":[[9.6,0],[7.6,0]],"id":52671544}],"con":true,"img":false}]}
{"op":"mcm","clk":"11450283145","pt":1717320015532,"mc":[{"id":"1.229554923","rc":[{"atb":[[34,3.16],[22,11.61]],"id":52671563},{"atb":[[9.8,27.71],[14.5,7.74]],"id":52671562},{"atb":[[9.2,29.74],[13,17.43]],"id":52671565},{"atb":[[310,0.78],[410,0.25]],"id":52671564},{"atb":[[10.5,11],[8.2,33.87]],"id":52671561},{"atb":[[9.2,29.74],[13,8.71]],"id":52671560},{"atb":[[8,34.84],[10,11.61]],"id":52671555},{"atb":[[220,0.47],[120,2.05]],"id":52671554},{"atb":[[18,6.14],[13,20.32]],"id":52671556},{"atb":[[9.2,29.74],[13,8.71]],"id":52671551},{"atb":[[2.92,127.03],[3.3,45.44]],"id":52671550},{"atb":[[4.6,29.03],[3.8,87.1]],"id":52671553},{"atb":[[20,5.5],[15,17.42]],"id":52671552},{"atb":[[3.8,37.33],[3.3,106.04]],"id":52671547},{"atb":[[3.2,110.86],[3.7,38.71]],"id":52671546},{"atb":[[16.5,6.74],[11.5,23.22]],"id":52671549},{"atb":[[7.2,39.33],[9.2,12.74]],"id":52671548},{"atb":[[4.6,29.03],[3.8,87.1]],"id":52671543},{"atb":[[3.35,44.48],[2.94,125.72]],"id":52671542},{"atb":[[18.5,5.97],[13.5,19.51]],"id":52671545},{"atb":[[8,34.84],[10,11.61]],"id":52671544}],"con":true,"img":false}]}
{"op":"mcm","clk":"11450284728","pt":1717320037531,"mc":[{"id":"1.229554923","rc":[{"atb":[[34,0],[22,0]],"id":52671563},{"atb":[[9.8,0],[14.5,0]],"id":52671562},{"atb":[[9.2,0],[13,8.72]],"id":52671565},{"atb":[[310,0],[410,0]],"id":52671564},{"atb":[[10.5,0],[8.2,0]],"id":52671561},{"atb":[[9.2,0],[13,0]],"id":52671560},{"atb":[[8,0],[10,0]],"id":52671555},{"atb":[[220,0],[120,0]],"id":52671554},{"atb":[[18,0],[13,0]],"id":52671556},{"atb":[[9.2,0],[13,0]],"id":52671551},{"atb":[[2.92,0],[3.3,0]],"id":52671550},{"atb":[[4.6,0],[3.8,0]],"id":52671553},{"atb":[[20,0],[15,0]],"id":52671552},{"atb":[[3.8,0],[3.3,0]],"id":52671547},{"atb":[[3.2,0],[3.7,0]],"id":52671546},{"atb":[[16.5,0],[11.5,0]],"id":52671549},{"atb":[[7.2,0],[9.2,0]],"id":52671548},{"atb":[[4.6,0],[3.8,0]],"id":52671543},{"atb":[[3.35,0],[2.94,0]],"id":52671542},{"atb":[[18.5,0],[13.5,0]],"id":52671545},{"atb":[[8,0],[10,0]],"id":52671544}],"con":true,"img":false}]}
{"op":"mcm","clk":"11450285290","pt":1717320045849,"mc":[{"id":"1.229554923","rc":[{"atb":[[10.5,11],[8.2,33.87]],"id":52671561},{"atb":[[9.2,29.74],[13,8.71]],"id":52671560},{"atb":[[3.8,37.33],[3.3,106.04]],"id":52671547},{"atb":[[3.2,110.86],[3.7,38.71]],"id":52671546},{"atb":[[16.5,6.74],[11.5,23.22]],"id":52671549},{"atb":[[7.2,39.33],[9.2,12.74]],"id":52671548},{"atb":[[4.6,29.03],[3.8,87.1]],"id":52671543},{"atb":[[3.35,44.48],[2.94,125.72]],"id":52671542},{"atb":[[18.5,5.97],[13.5,19.51]],"id":52671545},{"atb":[[8,34.84],[10,11.61]],"id":52671544}],"con":true,"img":false}]}
{"op":"mcm","clk":"11450285295","pt":1717320045956,"mc":[{"id":"1.229554923","rc":[{"atb":[[34,3.16],[22,11.61]],"id":52671563},{"atb":[[9.8,27.71],[14.5,7.74]],"id":52671562},{"atb":[[9.2,29.74],[13,17.43]],"id":52671565},{"atb":[[310,0.78],[410,0.25]],"id":52671564},{"atb":[[8,34.84],[10,11.61]],"id":52671555},{"atb":[[220,0.47],[120,2.05]],"id":52671554},{"atb":[[18,6.14],[13,20.32]],"id":52671556},{"atb":[[9.2,29.74],[13,8.71]],"id":52671551},{"atb":[[2.92,127.03],[3.3,45.44]],"id":52671550},{"atb":[[4.6,29.03],[3.8,87.1]],"id":52671553},{"atb":[[20,5.5],[15,17.42]],"id":52671552}],"con":true,"img":false}]}
{"op":"mcm","clk":"11450286930","pt":1717320072780,"mc":[{"id":"1.229554923","rc":[{"atb":[[34,0],[22,0]],"id":52671563},{"atb":[[9.8,0],[14.5,0]],"id":52671562},{"atb":[[9.2,0],[13,8.72]],"id":52671565},{"atb":[[310,0],[410,0]],"id":52671564},{"atb":[[10.5,0],[8.2,0]],"id":52671561},{"atb":[[9.2,0],[13,0]],"id":52671560},{"atb":[[8,0],[10,0]],"id":52671555},{"atb":[[220,0],[120,0]],"id":52671554},{"atb":[[18,0],[13,0]],"id":52671556},{"atb":[[9.2,0],[13,0]],"id":52671551},{"atb":[[2.92,0],[3.3,0]],"id":52671550},{"atb":[[4.6,0],[3.8,0]],"id":52671553},{"atb":[[20,0],[15,0]],"id":52671552},{"atb":[[3.8,0],[3.3,0]],"id":52671547},{"atb":[[3.2,0],[3.7,0]],"id":52671546},{"atb":[[16.5,0],[11.5,0]],"id":52671549},{"atb":[[7.2,0],[9.2,0]],"id":52671548},{"atb":[[4.6,0],[3.8,0]],"id":52671543},{"atb":[[3.35,0],[2.94,0]],"id":52671542},{"atb":[[18.5,0],[13.5,0]],"id":52671545},{"atb":[[8,0],[10,0]],"id":52671544}],"con":true,"img":false}]}
{"op":"mcm","clk":"11450287024","pt":1717320074071,"mc":[{"id":"1.229554923","rc":[{"atb":[[17,0],[19.5,0],[24,0],[14.5,0]],"id":52671545}],"con":true,"img":false}]}
{"op":"mcm","clk":"11450287075","pt":1717320074838,"mc":[{"id":"1.229554923","rc":[{"atb":[[18,4.61],[21,2.62],[26,1.05],[15.5,7.21]],"id":52671545}],"con":true,"img":false}]}
{"op":"mcm","clk":"11450287958","pt":1717320087503,"mc":[{"id":"1.229554923","rc":[{"atb":[[32,3.37],[21,12.19]],"id":52671563},{"atb":[[10,27.1],[15,7.46]],"id":52671562},{"atb":[[9.2,29.74],[13,17.43]],"id":52671565},{"atb":[[290,0.84],[390,0.26]],"id":52671564},{"atb":[[10.5,11],[8.2,33.87]],"id":52671561},{"atb":[[9.2,29.74],[13,8.71]],"id":52671560},{"atb":[[9.8,11.87],[7.8,35.86]],"id":52671555},{"atb":[[200,0.52],[100,2.46]],"id":52671554},{"atb":[[18,6.14],[13,20.32]],"id":52671556},{"atb":[[9.2,29.74],[13,8.71]],"id":52671551},{"atb":[[2.9,128.37],[3.25,46.45]],"id":52671550},{"atb":[[3.85,85.58],[4.7,28.25]],"id":52671553},{"atb":[[21,7.84],[15.5,24.03]],"id":52671552},{"atb":[[3.4,101.62],[3.9,36.04]],"id":52671547},{"atb":[[3.15,113.44],[3.65,39.44]],"id":52671546},{"atb":[[16.5,6.74],[11.5,23.22]],"id":52671549},{"atb":[[7.2,39.33],[9.2,12.74]],"id":52671548},{"atb":[[3.85,85.58],[4.7,28.25]],"id":52671543},{"atb":[[2.92,127.03],[3.3,45.44]],"id":52671542},{"atb":[[18,10.76],[13,20.32]],"id":52671545},{"atb":[[9.8,11.87],[7.8,35.86]],"id":52671544}],"con":true,"img":false}]}
{"op":"mcm","clk":"11450289710","pt":1717320114841,"mc":[{"id":"1.229554923","rc":[{"atb":[[32,0],[21,0]],"id":52671563},{"atb":[[10,0],[15,0]],"id":52671562},{"atb":[[9.2,0],[13,8.72]],"id":52671565},{"atb":[[290,0],[390,0]],"id":52671564},{"atb":[[10.5,0],[8.2,0]],"id":52671561},{"atb":[[9.2,0],[13,0]],"id":52671560},{"atb":[[9.8,0],[7.8,0]],"id":52671555},{"atb":[[200,0],[100,0]],"id":52671554},{"atb":[[18,0],[13,0]],"id":52671556},{"atb":[[9.2,0],[13,0]],"id":52671551},{"atb":[[2.9,0],[3.25,0]],"id":52671550},{"atb":[[3.85,0],[4.7,0]],"id":52671553},{"atb":[[21,2.62],[15.5,7.21]],"id":52671552},{"atb":[[3.4,0],[3.9,0]],"id":52671547},{"atb":[[3.15,0],[3.65,0]],"id":52671546},{"atb":[[16.5,0],[11.5,0]],"id":52671549},{"atb":[[7.2,0],[9.2,0]],"id":52671548},{"atb":[[3.85,0],[4.7,0]],"id":52671543},{"atb":[[2.92,0],[3.3,0]],"id":52671542},{"atb":[[18,4.61],[13,0]],"id":52671545},{"atb":[[9.8,0],[7.8,0]],"id":52671544}],"con":true,"img":false}]}
{"op":"mcm","clk":"11450291592","pt":1717320140894,"mc":[{"id":"1.229554923","rc":[{"atb":[[36,2.98],[23,11.08]],"id":52671563},{"atb":[[10.5,25.67],[15.5,7.2]],"id":52671562},{"atb":[[9.2,29.74],[13,17.43]],"id":52671565},{"atb":[[320,0.76],[420,0.25]],"id":52671564},{"atb":[[11,10.45],[8.4,32.96]],"id":52671561},{"atb":[[9.2,29.74],[13,8.71]],"id":52671560},{"atb":[[9.8,11.87],[7.8,35.86]],"id":52671555},{"atb":[[200,0.52],[100,2.46]],"id":52671554},{"atb":[[18,6.14],[13,20.32]],"id":52671556},{"atb":[[9.2,29.74],[13,8.71]],"id":52671551},{"atb":[[2.9,128.37],[3.25,46.45]],"id":52671550},{"atb":[[4.6,29.03],[3.8,87.1]],"id":52671553},{"atb":[[21,7.84],[15.5,24.03]],"id":52671552},{"atb":[[3.4,101.62],[3.9,36.04]],"id":52671547},{"atb":[[3.15,113.44],[3.65,39.44]],"id":52671546},{"atb":[[16.5,6.74],[11.5,23.22]],"id":52671549},{"atb":[[7.2,39.33],[9.2,12.74]],"id":52671548},{"atb":[[3.85,85.58],[4.7,28.25]],"id":52671543},{"atb":[[2.92,127.03],[3.3,45.44]],"id":52671542},{"atb":[[18,10.76],[13,20.32]],"id":52671545},{"atb":[[9.8,11.87],[7.8,35.86]],"id":52671544}],"con":true,"img":false}]}
{"op":"mcm","clk":"11450298216","pt":1717320240320,"mc":[{"id":"1.229554923","rc":[{"atb":[[2.52,3.77]],"id":52671563},{"atl":[[1000,2]],"id":52671563},{"atb":[[4.8,10.48]],"id":52671562},{"atl":[[610,2]],"id":52671562},{"atb":[[3.7,10.82]],"id":52671565},{"atl":[[530,2]],"id":52671565},{"atb":[[6.6,2.04]],"id":52671564},{"atl":[[920,2]],"id":52671564},{"atb":[[4.8,11.84]],"id":52671561},{"atl":[[600,2]],"id":52671561},{"atb":[[4.5,11.11]],"id":52671560},{"atl":[[590,2]],"id":52671560},{"atb":[[5.1,16.75]],"id":52671555},{"atl":[[630,2]],"id":52671555},{"atb":[[13,2.68]],"id":52671554},{"atl":[[1000,2]],"id":52671554},{"atb":[[3.55,12.19]],"id":52671556},{"atl":[[530,2]],"id":52671556},{"atb":[[5.6,16.56]],"id":52671551},{"atl":[[720,2]],"id":52671551},{"atb":[[2.52,52.37]],"id":52671550},{"atl":[[330,2]],"id":52671550},{"atb":[[2.96,40.69]],"id":52671553},{"atl":[[380,2]],"id":52671553},{"atb":[[4.5,12.47]],"id":52671552},{"atl":[[580,2]],"id":52671552},{"atb":[[3.05,41.62]],"id":52671547},{"atl":[[410,2]],"id":52671547},{"atb":[[2.72,50.91]],"id":52671546},{"atl":[[310,2]],"id":52671546},{"atb":[[4.3,11.5]],"id":52671549},{"atl":[[570,2]],"id":52671549},{"atb":[[5.6,19.65]],"id":52671548},{"atl":[[710,2]],"id":52671548},{"atb":[[2.52,55.31]],"id":52671543},{"atl":[[380,2]],"id":52671543},{"atb":[[2.84,54.35]],"id":52671542},{"atl":[[340,2]],"id":52671542},{"atb":[[4.1,14.44]],"id":52671545},{"atl":[[560,2]],"id":52671545},{"atb":[[5.4,21.45]],"id":52671544},{"atl":[[690,2]],"id":52671544}],"con":true,"img":false}]}
{"op":"mcm","clk":"11450298507","pt":1717320244415,"mc":[{"id":"1.229554923","rc":[{"atl":[[360,2],[380,0]],"id":52671543}],"con":true,"img":false}]}
{"op":"mcm","clk":"11450300295","pt":1717320270244,"mc":[{"id":"1.229554923","rc":[{"atb":[[16.5,0],[19,0],[23,0],[28,0]],"id":52671560},{"atb":[[5.8,0],[5.3,0],[7.6,0],[6.6,0]],"id":52671553},{"atb":[[4.9,0],[4.4,0],[5.9,0],[5.4,0]],"id":52671546}],"con":true,"img":false}]}
{"op":"mcm","clk":"11450300336","pt":1717320270958,"mc":[{"id":"1.229554923","rc":[{"atb":[[17.5,6.34],[20,4.13],[25,2.18],[30,0.9]],"id":52671560},{"atb":[[8,3.74],[5.5,23.25],[6,15.7],[7,8.72]],"id":52671553},{"atb":[[5,19.62],[5.5,11.63],[6,5.23]],"id":52671546}],"con":true,"img":false}]}
{"op":"mcm","clk":"11450300345","pt":1717320271013,"mc":[{"id":"1.229554923","rc":[{"atb":[[4.5,29.89]],"id":52671546}],"con":true,"img":false}]}
{"op":"mcm","clk":"11450300799","pt":1717320277465,"mc":[{"id":"1.229554923","rc":[{"atl":[[590,2],[610,0]],"id":52671562},{"atl":[[530,0],[520,2]],"id":52671565},{"atl":[[880,2],[920,0]],"id":52671564},{"atl":[[600,0],[580,2]],"id":52671561},{"atl":[[590,0],[580,2]],"id":52671560},{"atb":[[5.6,16.75],[5.1,0]],"id":52671555},{"atb":[[16.5,4.83],[13,0]],"id":52671554},{"atl":[[530,0],[520,2]],"id":52671556},{"atb":[[5.6,0],[6.2,16.56]],"id":52671551},{"atl":[[300,2],[330,0]],"id":52671550},{"atl":[[380,0],[370,2]],"id":52671553},{"atl":[[570,2],[580,0]],"id":52671552},{"atl":[[380,2],[410,0]],"id":52671547},{"atb":[[2.72,0],[2.86,50.91]],"id":52671546},{"atl":[[570,0],[550,2]],"id":52671549},{"atl":[[320,2],[340,0]],"id":52671542},{"atl":[[560,0],[550,2]],"id":52671545},{"atb":[[6,20],[5.4,0]],"id":52671544}],"con":true,"img":false}]}
{"op":"mcm","clk":"11450302638","pt":1717320306610,"mc":[{"id":"1.229554923","rc":[{"atb":[[36,0],[23,0]],"id":52671563},{"atb":[[10.5,0],[15.5,0]],"id":52671562},{"atb":[[9.2,0],[13,8.72]],"id":52671565},{"atb":[[320,0],[420,0]],"id":52671564},{"atb":[[11,0],[8.4,0]],"id":52671561},{"atb":[[9.2,0],[13,0]],"id":52671560},{"atb":[[9.8,0],[7.8,0]],"id":52671555},{"atb":[[200,0],[100,0]],"id":52671554},{"atb":[[18,0],[13,0]],"id":52671556},{"atb":[[9.2,0],[13,0]],"id":52671551},{"atb":[[2.9,0],[3.25,0]],"id":52671550},{"atb":[[4.6,0],[3.8,0]],"id":52671553},{"atb":[[21,2.62],[15.5,7.21]],"id":52671552},{"atb":[[3.4,0],[3.9,0]],"id":52671547},{"atb":[[3.15,0],[3.65,0]],"id":52671546},{"atb":[[16.5,0],[11.5,0]],"id":52671549},{"atb":[[7.2,0],[9.2,0]],"id":52671548},{"atb":[[3.85,0],[4.7,0]],"id":52671543},{"atb":[[2.92,0],[3.3,0]],"id":52671542},{"atb":[[18,4.61],[13,0]],"id":52671545},{"atb":[[9.8,0],[7.8,0]],"id":52671544}],"con":true,"img":false}]}
{"op":"mcm","clk":"11450303925","pt":1717320326716,"mc":[{"id":"1.229554923","rc":[{"atb":[[36,2.98],[23,11.08]],"id":52671563},{"atb":[[10.5,25.67],[15.5,7.2]],"id":52671562},{"atb":[[9.2,29.74],[13,17.43]],"id":52671565},{"atb":[[320,0.76],[420,0.25]],"id":52671564},{"atb":[[11,10.45],[8.4,32.96]],"id":52671561},{"atb":[[9.2,29.74],[13,8.71]],"id":52671560},{"atb":[[9.8,11.87],[7.8,35.86]],"id":52671555},{"atb":[[200,0.52],[100,2.46]],"id":52671554},{"atb":[[18,6.14],[13,20.32]],"id":52671556},{"atb":[[9.2,29.74],[13,8.71]],"id":52671551},{"atb":[[2.9,128.37],[3.25,46.45]],"id":52671550},{"atb":[[4.6,29.03],[3.8,87.1]],"id":52671553},{"atb":[[21,7.84],[15.5,24.03]],"id":52671552},{"atb":[[3.4,101.62],[3.9,36.04]],"id":52671547},{"atb":[[3.15,113.44],[3.65,39.44]],"id":52671546},{"atb":[[16.5,6.74],[11.5,23.22]],"id":52671549},{"atb":[[7.2,39.33],[9.2,12.74]],"id":52671548},{"atb":[[3.85,85.58],[4.7,28.25]],"id":52671543},{"atb":[[2.92,127.03],[3.3,45.44]],"id":52671542},{"atb":[[18,10.76],[13,20.32]],"id":52671545},{"atb":[[9.8,11.87],[7.8,35.86]],"id":52671544}],"con":true,"img":false}]}
{"op":"mcm","clk":"11450306331","pt":1717320369677,"mc":[{"id":"1.229554923","rc":[{"atb":[[2.86,0],[2.74,57.47]],"id":52671546}],"con":true,"img":false}]}
{"op":"mcm","clk":"11450308136","pt":1717320400500,"mc":[{"id":"1.229554923","rc":[{"atb":[[36,0],[23,0]],"id":52671563},{"atb":[[10.5,0],[15.5,0]],"id":52671562},{"atb":[[9.2,0],[13,8.72]],"id":52671565},{"atb":[[320,0],[420,0]],"id":52671564},{"atb":[[11,0],[8.4,0]],"id":52671561},{"atb":[[9.2,0],[13,0]],"id":52671560},{"atb":[[9.8,0],[7.8,0]],"id":52671555},{"atb":[[200,0],[100,0]],"id":52671554},{"atb":[[18,0],[13,0]],"id":52671556},{"atb":[[9.2,0],[13,0]],"id":52671551},{"atb":[[2.9,0],[3.25,0]],"id":52671550},{"atb":[[4.6,0],[3.8,0]],"id":52671553},{"atb":[[21,2.62],[15.5,7.21]],"id":52671552},{"atb":[[3.4,0],[3.9,0]],"id":52671547},{"atb":[[3.15,0],[3.65,0]],"id":52671546},{"atb":[[16.5,0],[11.5,0]],"id":52671549},{"atb":[[7.2,0],[9.2,0]],"id":52671548},{"atb":[[3.85,0],[4.7,0]],"id":52671543},{"atb":[[2.92,0],[3.3,0]],"id":52671542},{"atb":[[18,4.61],[13,0]],"id":52671545},{"atb":[[9.8,0],[7.8,0]],"id":52671544}],"con":true,"img":false}]}
{"op":"mcm","clk":"11450308808","pt":1717320410992,"mc":[{"id":"1.229554923","rc":[{"atb":[[36,2.98],[23,11.08]],"id":52671563},{"atb":[[10.5,25.67],[15.5,7.2]],"id":52671562},{"atb":[[9.2,29.74],[13,17.43]],"id":52671565},{"atb":[[320,0.76],[420,0.25]],"id":52671564},{"atb":[[11,10.45],[8.4,32.96]],"id":52671561},{"atb":[[9.2,29.74],[13,8.71]],"id":52671560},{"atb":[[9.8,11.87],[7.8,35.86]],"id":52671555},{"atb":[[200,0.52],[100,2.46]],"id":52671554},{"atb":[[18,6.14],[13,20.32]],"id":52671556},{"atb":[[9.2,29.74],[13,8.71]],"id":52671551},{"atb":[[2.9,128.37],[3.25,46.45]],"id":52671550},{"atb":[[4.6,29.03],[3.8,87.1]],"id":52671553},{"atb":[[21,7.84],[15.5,24.03]],"id":52671552},{"atb":[[3.4,101.62],[3.9,36.04]],"id":52671547},{"atb":[[3.15,113.44],[3.65,39.44]],"id":52671546},{"atb":[[16.5,6.74],[11.5,23.22]],"id":52671549},{"atb":[[7.2,39.33],[9.2,12.74]],"id":52671548},{"atb":[[3.85,85.58],[4.7,28.25]],"id":52671543},{"atb":[[2.92,127.03],[3.3,45.44]],"id":52671542},{"atb":[[18,10.76],[13,20.32]],"id":52671545},{"atb":[[9.8,11.87],[7.8,35.86]],"id":52671544}],"con":true,"img":false}]}
{"op":"mcm","clk":"11450325371","pt":1717320556670,"mc":[{"id":"1.229554923","rc":[{"atb":[[4.8,0],[5.3,10.48]],"id":52671562},{"atb":[[4.5,0],[5,11.11]],"id":52671560},{"atl":[[300,0],[290,2]],"id":52671550},{"atl":[[360,2],[370,0]],"id":52671553},{"atb":[[2.74,0],[2.84,54.35]],"id":52671546},{"atl":[[300,2],[310,0]],"id":52671546},{"atb":[[2.84,0],[2.94,51.55]],"id":52671542}],"con":true,"img":false}]}
{"op":"mcm","clk":"11450325412","pt":1717320557046,"mc":[{"id":"1.229554923","rc":[{"atb":[[18,6.14],[21,0],[26,0],[15.5,0]],"id":52671545}],"con":true,"img":false}]}
{"op":"mcm","clk":"11450325477","pt":1717320557772,"mc":[{"id":"1.229554923","rc":[{"atb":[[16,6.97],[18.5,4.48],[22,2.49],[27,1]],"id":52671545}],"con":true,"img":false}]}
{"op":"mcm","clk":"11450331271","pt":1717320633604,"mc":[{"id":"1.229554923","rc":[{"atb":[[17.5,0],[20,0],[25,0],[30,0]],"id":52671560}],"con":true,"img":false}]}
{"op":"mcm","clk":"11450331330","pt":1717320634287,"mc":[{"id":"1.229554923","rc":[{"atb":[[32,0.84],[18,6.15],[21,3.92],[26,2.09]],"id":52671560}],"con":true,"img":false}]}
{"op":"mcm","clk":"11450334592","pt":1717320676667,"mc":[{"id":"1.229554923","rc":[{"atl":[[290,0],[300,2]],"id":52671550},{"atl":[[360,0],[370,2]],"id":52671553},{"atb":[[2.72,58.14],[2.84,0]],"id":52671546},{"atl":[[300,0],[310,2]],"id":52671546},{"atb":[[2.82,54.95],[2.94,0]],"id":52671542}],"con":true,"img":false}]}
{"op":"mcm","clk":"11450344125","pt":1717320794361,"mc":[{"id":"1.229554923","rc":[{"atb":[[36,0],[23,0]],"id":52671563},{"atb":[[10.5,0],[15.5,0]],"id":52671562},{"atb":[[9.2,0],[13,8.72]],"id":52671565},{"atb":[[320,0],[420,0]],"id":52671564},{"atb":[[11,0],[8.4,0]],"id":52671561},{"atb":[[9.2,0],[13,0]],"id":52671560},{"atb":[[9.8,0],[7.8,0]],"id":52671555},{"atb":[[200,0],[100,0]],"id":52671554},{"atb":[[18,0],[13,0]],"id":52671556},{"atb":[[9.2,0],[13,0]],"id":52671551},{"atb":[[2.9,0],[3.25,0]],"id":52671550},{"atb":[[4.6,0],[3.8,0]],"id":52671553},{"atb":[[21,2.62],[15.5,7.21]],"id":52671552},{"atb":[[3.4,0],[3.9,0]],"id":52671547},{"atb":[[3.15,0],[3.65,0]],"id":52671546},{"atb":[[16.5,0],[11.5,0]],"id":52671549},{"atb":[[7.2,0],[9.2,0]],"id":52671548},{"atb":[[3.85,0],[4.7,0]],"id":52671543},{"atb":[[2.92,0],[3.3,0]],"id":52671542},{"atb":[[18,0],[13,0]],"id":52671545},{"atb":[[9.8,0],[7.8,0]],"id":52671544}],"con":true,"img":false}]}
{"op":"mcm","clk":"11450345301","pt":1717320809190,"mc":[{"id":"1.229554923","rc":[{"atb":[[36,2.98],[23,11.08]],"id":52671563},{"atb":[[10.5,25.67],[15.5,7.2]],"id":52671562},{"atb":[[9.2,29.74],[13,17.43]],"id":52671565},{"atb":[[320,0.76],[420,0.25]],"id":52671564},{"atb":[[11,10.45],[8.4,32.96]],"id":52671561},{"atb":[[9.2,29.74],[13,8.71]],"id":52671560},{"atb":[[9.8,11.87],[7.8,35.86]],"id":52671555},{"atb":[[200,0.52],[100,2.46]],"id":52671554},{"atb":[[18,6.14],[13,20.32]],"id":52671556},{"atb":[[9.2,29.74],[13,8.71]],"id":52671551},{"atb":[[2.9,128.37],[3.25,46.45]],"id":52671550},{"atb":[[4.6,29.03],[3.8,87.1]],"id":52671553},{"atb":[[21,7.84],[15.5,24.03]],"id":52671552},{"atb":[[3.4,101.62],[3.9,36.04]],"id":52671547},{"atb":[[3.15,113.44],[3.65,39.44]],"id":52671546},{"atb":[[16.5,6.74],[11.5,23.22]],"id":52671549},{"atb":[[7.2,39.33],[9.2,12.74]],"id":52671548},{"atb":[[3.85,85.58],[4.7,28.25]],"id":52671543},{"atb":[[2.92,127.03],[3.3,45.44]],"id":52671542},{"atb":[[18,6.14],[13,20.32]],"id":52671545},{"atb":[[9.8,11.87],[7.8,35.86]],"id":52671544}],"con":true,"img":false}]}
{"op":"mcm","clk":"11450349908","pt":1717320862831,"mc":[{"id":"1.229554923","rc":[{"atl":[[1000,0]],"id":52671563},{"atb":[[4.1,10.82],[3.7,0]],"id":52671565},{"atb":[[6.6,0],[8.4,2.04]],"id":52671564},{"atl":[[280,2],[300,0]],"id":52671550},{"atb":[[4.5,0],[5,12.47]],"id":52671552},{"atl":[[280,2],[310,0]],"id":52671546},{"atl":[[700,2],[710,0]],"id":52671548},{"atl":[[310,2],[320,0]],"id":52671542}],"con":true,"img":false}]}
{"op":"mcm","clk":"11450349918","pt":1717320862932,"mc":[{"id":"1.229554923","rc":[{"atb":[[2.82,54.95],[2.72,0]],"id":52671546}],"con":true,"img":false}]}
{"op":"mcm","clk":"11450349948","pt":1717320863245,"mc":[{"id":"1.229554923","rc":[{"atb":[[16,0],[18.5,0],[22,0],[27,0]],"id":52671545}],"con":true,"img":false}]}
{"op":"mcm","clk":"11450350008","pt":1717320863918,"mc":[{"id":"1.229554923","rc":[{"atb":[[18,10.76],[21,2.62],[26,1.05],[15.5,7.21]],"id":52671545}],"con":true,"img":false}]}
{"op":"mcm","clk":"11450351262","pt":1717320878441,"mc":[{"id":"1.229554923","rc":[{"atl":[[1000,2]],"id":52671563},{"atl":[[360,2],[370,0]],"id":52671553},{"atb":[[2.82,0],[2.94,51.55]],"id":52671542}],"con":true,"img":false}]}
{"op":"mcm","clk":"11450354252","pt":1717320913873,"mc":[{"id":"1.229554923","rc":[{"atb":[[18,0],[21,0],[26,0],[15.5,0]],"id":52671561}],"con":true,"img":false}]}
{"op":"mcm","clk":"11450354413","pt":1717320915858,"mc":[{"id":"1.229554923","rc":[{"atl":[[520,0],[510,2]],"id":52671556}],"con":true,"img":false}]}
{"op":"mcm","clk":"11450355808","pt":1717320933016,"mc":[{"id":"1.229554923","rc":[{"atb":[[16,6.97],[18.5,4.48],[22,2.49],[27,1]],"id":52671561}],"con":true,"img":false}]}
{"op":"mcm","clk":"11450356283","pt":1717320938780,"mc":[{"id":"1.229554923","rc":[{"atb":[[16,0],[18.5,0],[22,0],[27,0]],"id":52671561}],"con":true,"img":false}]}
{"op":"mcm","clk":"11450356338","pt":1717320939605,"mc":[{"id":"1.229554923","rc":[{"atb":[[18,4.61],[21,2.62],[26,1.05],[15.5,7.21]],"id":52671561}],"con":true,"img":false}]}
{"op":"mcm","clk":"11450356865","pt":1717320946002,"mc":[{"id":"1.229554923","rc":[{"atb":[[18,0],[21,0],[26,0],[15.5,0]],"id":52671561}],"con":true,"img":false}]}
{"op":"mcm","clk":"11450356924","pt":1717320946689,"mc":[{"id":"1.229554923","rc":[{"atb":[[16,6.97],[18.5,4.48],[22,2.49],[27,1]],"id":52671561}],"con":true,"img":false}]}
{"op":"mcm","clk":"11450357217","pt":1717320950529,"mc":[{"id":"1.229554923","rc":[{"atb":[[16,0],[18.5,0],[22,0],[27,0]],"id":52671561}],"con":true,"img":false}]}
{"op":"mcm","clk":"11450357279","pt":1717320951203,"mc":[{"id":"1.229554923","rc":[{"atb":[[18,4.61],[21,2.62],[26,1.05],[15.5,7.21]],"id":52671561}],"con":true,"img":false}]}
{"op":"mcm","clk":"11450367331","pt":1717321082012,"mc":[{"id":"1.229554923","rc":[{"atl":[[520,2],[510,0]],"id":52671556}],"con":true,"img":false}]}
{"op":"mcm","clk":"11450370514","pt":1717321128728,"mc":[{"id":"1.229554923","rc":[{"atb":[[16.5,0],[19.5,5.41]],"id":52671554},{"atb":[[3.8,12.19],[3.55,0]],"id":52671556}],"con":true,"img":false}]}
{"op":"mcm","clk":"11450372143","pt":1717321151905,"mc":[{"id":"1.229554923","rc":[{"atb":[[5.3,0],[6,10.48]],"id":52671562},{"atb":[[4.9,10.82]],"id":52671565},{"atb":[[24,2.04],[8.4,0]],"id":52671564},{"atl":[[880,0]],"id":52671564},{"atl":[[560,2],[580,0]],"id":52671561},{"atb":[[5,0],[5.5,11.11]],"id":52671560},{"atl":[[600,2],[630,0]],"id":52671555},{"atb":[[19.5,0],[24,4.35]],"id":52671554},{"atl":[[1000,0]],"id":52671554},{"atl":[[520,0]],"id":52671556},{"atl":[[720,0],[710,2]],"id":52671551},{"atl":[[280,0],[170,2]],"id":52671550},{"atb":[[3.2,40.69],[2.96,0]],"id":52671553},{"atb":[[5,0],[22,4.76]],"id":52671552},{"atl":[[570,0],[820,2]],"id":52671552},{"atl":[[280,2],[380,0]],"id":52671547},{"atb":[[9,11.5]],"id":52671549},{"atl":[[570,2]],"id":52671549},{"atb":[[5.6,0],[4.3,24.34]],"id":52671548},{"atl":[[550,2],[700,0]],"id":52671548},{"atb":[[2.44,69.44],[2.94,0]],"id":52671542},{"atl":[[130,2],[310,0]],"id":52671542},{"atb":[[14,7.69]],"id":52671545},{"atl":[[700,2]],"id":52671545},{"atb":[[5.3,23.26],[6,0]],"id":52671544},{"atl":[[610,2],[690,0]],"id":52671544}],"con":true,"img":false}]}
{"op":"mcm","clk":"11450372150","pt":1717321151965,"mc":[{"id":"1.229554923","rc":[{"atb":[[4.1,0]],"id":52671565},{"atl":[[650,2]],"id":52671556},{"atb":[[2.82,0],[3,50]],"id":52671546},{"atl":[[260,2],[280,0]],"id":52671546},{"atb":[[4.3,0]],"id":52671549},{"atl":[[550,0]],"id":52671549},{"atl":[[350,2],[360,0]],"id":52671543},{"atb":[[4.1,0]],"id":52671545},{"atl":[[550,0]],"id":52671545}],"con":true,"img":false}]}
{"op":"mcm","clk":"11450372173","pt":1717321152276,"mc":[{"id":"1.229554923","rc":[{"atb":[[4.8,0],[4.3,0],[5.8,0],[5.3,0]],"id":52671550},{"atb":[[6.4,0],[7.4,0],[5.2,0],[5.7,0]],"id":52671547},{"atb":[[3.95,0],[4.9,0],[4.4,0],[5.4,0]],"id":52671542}],"con":true,"img":false}]}
{"op":"mcm","clk":"11450372188","pt":1717321152483,"mc":[{"id":"1.229554923","rc":[{"atb":[[3.2,45.45],[3.05,0]],"id":52671547}],"con":true,"img":false}]}
{"op":"mcm","clk":"11450372248","pt":1717321153260,"mc":[{"id":"1.229554923","rc":[{"atb":[[3.85,36.72],[5.2,6.23],[4.2,24.52],[4.7,14.14]],"id":52671550},{"atb":[[5,26.16],[5.5,17.44],[6,10.46],[7,4.36]],"id":52671547},{"atb":[[3.85,36.72],[5.2,6.23],[4.2,24.52],[4.7,14.14]],"id":52671542}],"con":true,"img":false}]}
{"op":"mcm","clk":"11450372505","pt":1717321156953,"mc":[{"id":"1.229554923","rc":[{"atb":[[3.8,0],[12.5,8.7]],"id":52671556}],"con":true,"img":false}]}
{"op":"mcm","clk":"11450372595","pt":1717321158297,"mc":[{"id":"1.229554923","rc":[{"atb":[[36,0],[23,0]],"id":52671563},{"atb":[[10.5,0],[15.5,0]],"id":52671562},{"atb":[[9.2,0],[13,8.72]],"id":52671565},{"atb":[[320,0],[420,0]],"id":52671564},{"atb":[[11,0],[8.4,0]],"id":52671561},{"atb":[[9.2,0],[13,0]],"id":52671560},{"atb":[[9.8,0],[7.8,0]],"id":52671555},{"atb":[[200,0],[100,0]],"id":52671554},{"atb":[[18,0],[13,0]],"id":52671556},{"atb":[[9.2,0],[13,0]],"id":52671551},{"atb":[[2.9,0],[3.25,0]],"id":52671550},{"atb":[[4.6,0],[3.8,0]],"id":52671553},{"atb":[[21,2.62],[15.5,7.21]],"id":52671552},{"atb":[[3.4,0],[3.9,0]],"id":52671547},{"atb":[[3.15,0],[3.65,0]],"id":52671546},{"atb":[[16.5,0],[11.5,0]],"id":52671549},{"atb":[[7.2,0],[9.2,0]],"id":52671548},{"atb":[[3.85,0],[4.7,0]],"id":52671543},{"atb":[[2.92,0],[3.3,0]],"id":52671542},{"atb":[[18,4.61],[13,0]],"id":52671545},{"atb":[[9.8,0],[7.8,0]],"id":52671544}],"con":true,"img":false}]}
{"op":"mcm","clk":"11450372645","pt":1717321158980,"mc":[{"id":"1.229554923","rc":[{"atb":[[3.85,0],[5.2,0],[4.7,0]],"id":52671550},{"atb":[[3.85,0],[4.7,0]],"id":52671542}],"con":true,"img":false}]}
{"op":"mcm","clk":"11450372651","pt":1717321159078,"mc":[{"id":"1.229554923","rc":[{"atb":[[4.2,0]],"id":52671550},{"atb":[[5.2,0],[4.2,0]],"id":52671542}],"con":true,"img":false}]}
{"op":"mcm","clk":"11450372702","pt":1717321159656,"mc":[{"id":"1.229554923","rc":[{"atb":[[4.8,6.89],[4.3,15.85],[3.65,39.48]],"id":52671550},{"atb":[[4.3,15.85],[3.65,39.48]],"id":52671542}],"con":true,"img":false}]}
{"op":"mcm","clk":"11450372707","pt":1717321159759,"mc":[{"id":"1.229554923","rc":[{"atb":[[3.9,27.06]],"id":52671550},{"atb":[[4.8,6.89],[3.9,27.06]],"id":52671542}],"con":true,"img":false}]}
{"op":"mcm","clk":"11450373232","pt":1717321167195,"mc":[{"id":"1.229554923","rc":[{"atb":[[15.5,0]],"id":52671545}],"con":true,"img":false}]}
{"op":"mcm","clk":"11450373236","pt":1717321167289,"mc":[{"id":"1.229554923","rc":[{"atb":[[18,0],[21,0],[26,0]],"id":52671545}],"con":true,"img":false}]}
{"op":"mcm","clk":"11450373277","pt":1717321167916,"mc":[{"id":"1.229554923","rc":[{"atb":[[28,3.88]],"id":52671545}],"con":true,"img":false}]}
{"op":"mcm","clk":"11450373282","pt":1717321167968,"mc":[{"id":"1.229554923","rc":[{"atb":[[65,0.41],[36,2.24],[46,1.16]],"id":52671545}],"con":true,"img":false}]}
{"op":"mcm","clk":"11450373752","pt":1717321175010,"mc":[{"id":"1.229554923","rc":[{"atb":[[36,2.98],[23,11.08]],"id":52671563},{"atb":[[10.5,25.67],[15.5,7.2]],"id":52671562},{"atb":[[9.2,29.74],[13,17.43]],"id":52671565},{"atb":[[320,0.76],[420,0.25]],"id":52671564},{"atb":[[11,10.45],[8.4,32.96]],"id":52671561},{"atb":[[9.2,29.74],[13,8.71]],"id":52671560},{"atb":[[9.8,11.87],[7.8,35.86]],"id":52671555},{"atb":[[200,0.52],[100,2.46]],"id":52671554},{"atb":[[18,6.14],[13,20.32]],"id":52671556},{"atb":[[9.2,29.74],[13,8.71]],"id":52671551},{"atb":[[2.9,128.37],[3.25,46.45]],"id":52671550},{"atb":[[4.6,29.03],[3.8,87.1]],"id":52671553},{"atb":[[21,7.84],[15.5,24.03]],"id":52671552},{"atb":[[3.4,101.62],[3.9,36.04]],"id":52671547},{"atb":[[3.15,113.44],[3.65,39.44]],"id":52671546},{"atb":[[16.5,6.74],[11.5,23.22]],"id":52671549},{"atb":[[7.2,39.33],[9.2,12.74]],"id":52671548},{"atb":[[3.85,85.58],[4.7,28.25]],"id":52671543},{"atb":[[2.92,127.03],[3.3,45.44]],"id":52671542},{"atb":[[18,6.14],[13,20.32]],"id":52671545},{"atb":[[9.8,11.87],[7.8,35.86]],"id":52671544}],"con":true,"img":false}]}
{"op":"mcm","clk":"11450374070","pt":1717321179887,"mc":[{"id":"1.229554923","rc":[{"atl":[[540,2],[560,0]],"id":52671561},{"atb":[[5.5,0],[6,11.11]],"id":52671560},{"atl":[[600,0],[580,2]],"id":52671555},{"atl":[[680,2],[710,0]],"id":52671551},{"atl":[[140,2],[170,0]],"id":52671550},{"atb":[[3.45,40.69],[3.2,0]],"id":52671553},{"atb":[[22,0],[25,4.17]],"id":52671552},{"atl":[[260,2],[280,0]],"id":52671547},{"atb":[[9,0],[10,11.11]],"id":52671549},{"atb":[[4.8,24.34],[4.3,0]],"id":52671548},{"atl":[[530,2],[550,0]],"id":52671548},{"atb":[[2.44,0],[2.6,62.5]],"id":52671542},{"atl":[[130,0],[110,2]],"id":52671542},{"atb":[[5.3,0],[5.9,20.41]],"id":52671544},{"atl":[[590,2],[610,0]],"id":52671544}],"con":true,"img":false}]}
{"op":"mcm","clk":"11450375388","pt":1717321202182,"mc":[{"id":"1.229554923","rc":[{"atb":[[32,0],[18,0],[21,0],[26,0]],"id":52671560}],"con":true,"img":false}]}
{"op":"mcm","clk":"11450375434","pt":1717321202858,"mc":[{"id":"1.229554923","rc":[{"atb":[[36,0.75],[19,5.81],[23,3.57],[28,1.94]],"id":52671560}],"con":true,"img":false}]}
{"op":"mcm","clk":"11450375914","pt":1717321211958,"mc":[{"id":"1.229554923","rc":[{"atb":[[36,0],[19,0],[23,0],[28,0]],"id":52671560}],"con":true,"img":false}]}
{"op":"mcm","clk":"11450375945","pt":1717321212680,"mc":[{"id":"1.229554923","rc":[{"atb":[[32,0.84],[18,6.15],[21,3.92],[26,2.09]],"id":52671560}],"con":true,"img":false}]}
{"op":"mcm","clk":"11450378020","pt":1717321247140,"mc":[{"id":"1.229554923","rc":[{"atb":[[18,0],[21,0],[26,0],[15.5,0]],"id":52671561}],"con":true,"img":false}]}
{"op":"mcm","clk":"11450378071","pt":1717321247918,"mc":[{"id":"1.229554923","rc":[{"atb":[[16.5,6.75],[19,4.36],[23,2.38],[28,0.97]],"id":52671561}],"con":true,"img":false}]}
{"op":"mcm","clk":"11450379602","pt":1717321271933,"mc":[{"id":"1.229554923","rc":[{"atb":[[23,4.55],[25,0]],"id":52671552},{"atb":[[2.86,53.76],[3,0]],"id":52671546}],"con":true,"img":false}]}
{"op":"mcm","clk":"11450380115","pt":1717321279352,"mc":[{"id":"1.229554923","rc":[{"atb":[[16.5,0],[19,0],[23,0],[28,0]],"id":52671561}],"con":true,"img":false}]}
{"op":"mcm","clk":"11450380157","pt":1717321280030,"mc":[{"id":"1.229554923","rc":[{"atb":[[18,4.61],[21,2.62],[26,1.05],[15.5,7.21]],"id":52671561}],"con":true,"img":false}]}
{"op":"mcm","clk":"11450389887","pt":1717321438857,"mc":[{"id":"1.229554923","rc":[{"atb":[[4.8,0],[4.3,0],[3.9,0],[3.65,0]],"id":52671550},{"atb":[[4.8,0],[4.3,0],[3.9,0],[3.65,0]],"id":52671542}],"con":true,"img":false}]}
{"op":"mcm","clk":"11450389931","pt":1717321439574,"mc":[{"id":"1.229554923","rc":[{"atb":[[3.85,36.72],[5.2,6.23],[4.2,24.52],[4.7,14.14]],"id":52671550},{"atb":[[3.85,36.72],[5.2,6.23],[4.2,24.52],[4.7,14.14]],"id":52671542}],"con":true,"img":false}]}
{"op":"mcm","clk":"11450390289","pt":1717321445365,"mc":[{"id":"1.229554923","rc":[{"atb":[[3.85,0],[5.2,0],[4.2,0],[4.7,0]],"id":52671550},{"atb":[[3.85,0],[5.2,0],[4.2,0],[4.7,0]],"id":52671542}],"con":true,"img":false}]}
{"op":"mcm","clk":"11450390362","pt":1717321446417,"mc":[{"id":"1.229554923","rc":[{"atb":[[4.8,6.89]],"id":52671550}],"con":true,"img":false}]}
{"op":"mcm","clk":"11450390370","pt":1717321446491,"mc":[{"id":"1.229554923","rc":[{"atb":[[4.3,15.85],[3.9,27.06],[3.65,39.48]],"id":52671550},{"atb":[[4.8,6.89],[4.3,15.85],[3.9,27.06],[3.65,39.48]],"id":52671542}],"con":true,"img":false}]}
{"op":"mcm","clk":"11450394599","pt":1717321511655,"mc":[{"id":"1.229554923","rc":[{"atb":[[36,0],[23,0]],"id":52671563},{"atb":[[10.5,0],[15.5,0]],"id":52671562},{"atb":[[9.2,0],[13,8.72]],"id":52671565},{"atb":[[320,0],[420,0]],"id":52671564},{"atb":[[11,0],[8.4,0]],"id":52671561},{"atb":[[9.2,0],[13,0]],"id":52671560},{"atb":[[9.8,0],[7.8,0]],"id":52671555},{"atb":[[200,0],[100,0]],"id":52671554},{"atb":[[18,0],[13,0]],"id":52671556},{"atb":[[9.2,0],[13,0]],"id":52671551},{"atb":[[2.9,0],[3.25,0]],"id":52671550},{"atb":[[4.6,0],[3.8,0]],"id":52671553},{"atb":[[21,2.62],[15.5,7.21]],"id":52671552},{"atb":[[3.4,0],[3.9,0]],"id":52671547},{"atb":[[3.15,0],[3.65,0]],"id":52671546},{"atb":[[16.5,0],[11.5,0]],"id":52671549},{"atb":[[7.2,0],[9.2,0]],"id":52671548},{"atb":[[3.85,0],[4.7,0]],"id":52671543},{"atb":[[2.92,0],[3.3,0]],"id":52671542},{"atb":[[18,0],[13,0]],"id":52671545},{"atb":[[9.8,0],[7.8,0]],"id":52671544}],"con":true,"img":false}]}
{"op":"mcm","clk":"11450396064","pt":1717321532382,"mc":[{"id":"1.229554923","rc":[{"atb":[[11,10.45],[8.4,32.96]],"id":52671561},{"atb":[[9.2,29.74],[13,8.71]],"id":52671560},{"atb":[[3.4,101.62],[3.9,36.04]],"id":52671547},{"atb":[[3.15,113.44],[3.65,39.44]],"id":52671546},{"atb":[[16.5,6.74],[11.5,23.22]],"id":52671549},{"atb":[[7.2,39.33],[9.2,12.74]],"id":52671548},{"atb":[[3.85,85.58],[4.7,28.25]],"id":52671543},{"atb":[[2.92,127.03],[3.3,45.44]],"id":52671542},{"atb":[[18,6.14],[13,20.32]],"id":52671545},{"atb":[[9.8,11.87],[7.8,35.86]],"id":52671544}],"con":true,"img":false}]}
{"op":"mcm","clk":"11450396781","pt":1717321543073,"mc":[{"id":"1.229554923","rc":[{"atb":[[36,2.98],[23,11.08]],"id":52671563},{"atb":[[10.5,25.67],[15.5,7.2]],"id":52671562},{"atb":[[9.2,29.74],[13,17.43]],"id":52671565},{"atb":[[320,0.76],[420,0.25]],"id":52671564},{"atb":[[9.8,11.87],[7.8,35.86]],"id":52671555},{"atb":[[200,0.52],[100,2.46]],"id":52671554},{"atb":[[18,6.14],[13,20.32]],"id":52671556},{"atb":[[9.2,29.74],[13,8.71]],"id":52671551},{"atb":[[2.9,128.37],[3.25,46.45]],"id":52671550},{"atb":[[4.6,29.03],[3.8,87.1]],"id":52671553},{"atb":[[21,7.84],[15.5,24.03]],"id":52671552}],"con":true,"img":false}]}
{"op":"mcm","clk":"11450400692","pt":1717321597580,"mc":[{"id":"1.229554923","rc":[{"atb":[[18,0],[21,0],[26,0],[15.5,0]],"id":52671561}],"con":true,"img":false}]}
{"op":"mcm","clk":"11450400748","pt":1717321598300,"mc":[{"id":"1.229554923","rc":[{"atb":[[16,6.97],[18.5,4.48],[22,2.49],[27,1]],"id":52671561}],"con":true,"img":false}]}
{"op":"mcm","clk":"11450400830","pt":1717321599394,"mc":[{"id":"1.229554923","rc":[{"atb":[[16,0],[18.5,0],[22,0],[27,0]],"id":52671561}],"con":true,"img":false}]}
{"op":"mcm","clk":"11450400882","pt":1717321600113,"mc":[{"id":"1.229554923","rc":[{"atb":[[16,6.97],[18.5,4.48],[22,2.49],[27,1]],"id":52671561}],"con":true,"img":false}]}
{"op":"mcm","clk":"11450401317","pt":1717321605786,"mc":[{"id":"1.229554923","rc":[{"atb":[[16,0],[18.5,0],[22,0],[27,0]],"id":52671561}],"con":true,"img":false}]}
{"op":"mcm","clk":"11450401379","pt":1717321606817,"mc":[{"id":"1.229554923","rc":[{"atb":[[18,4.61],[21,2.62],[26,1.05],[15.5,7.21]],"id":52671561}],"con":true,"img":false}]}
{"op":"mcm","clk":"11450421294","pt":1717321850610,"mc":[{"id":"1.229554923","rc":[{"atb":[[36,0],[23,0]],"id":52671563},{"atb":[[10.5,0],[15.5,0]],"id":52671562},{"atb":[[9.2,0],[13,8.72]],"id":52671565},{"atb":[[320,0],[420,0]],"id":52671564},{"atb":[[11,0],[8.4,0]],"id":52671561},{"atb":[[9.2,0],[13,0]],"id":52671560},{"atb":[[9.8,0],[7.8,0]],"id":52671555},{"atb":[[200,0],[100,0]],"id":52671554},{"atb":[[18,0],[13,0]],"id":52671556},{"atb":[[9.2,0],[13,0]],"id":52671551},{"atb":[[2.9,0],[3.25,0]],"id":52671550},{"atb":[[4.6,0],[3.8,0]],"id":52671553},{"atb":[[21,2.62],[15.5,7.21]],"id":52671552},{"atb":[[3.4,0],[3.9,0]],"id":52671547},{"atb":[[3.15,0],[3.65,0]],"id":52671546},{"atb":[[16.5,0],[11.5,0]],"id":52671549},{"atb":[[7.2,0],[9.2,0]],"id":52671548},{"atb":[[3.85,0],[4.7,0]],"id":52671543},{"atb":[[2.92,0],[3.3,0]],"id":52671542},{"atb":[[18,0],[13,0]],"id":52671545},{"atb":[[9.8,0],[7.8,0]],"id":52671544}],"con":true,"img":false}]}
{"op":"mcm","clk":"11450422893","pt":1717321869440,"mc":[{"id":"1.229554923","rc":[{"atb":[[36,2.98],[23,11.08]],"id":52671563},{"atb":[[10.5,25.67],[15.5,7.2]],"id":52671562},{"atb":[[9.2,29.74],[13,17.43]],"id":52671565},{"atb":[[320,0.76],[420,0.25]],"id":52671564},{"atb":[[11,10.45],[8.4,32.96]],"id":52671561},{"atb":[[9.2,29.74],[13,8.71]],"id":52671560},{"atb":[[9.8,11.87],[7.8,35.86]],"id":52671555},{"atb":[[200,0.52],[100,2.46]],"id":52671554},{"atb":[[18,6.14],[13,20.32]],"id":52671556},{"atb":[[9.2,29.74],[13,8.71]],"id":52671551},{"atb":[[2.9,128.37],[3.25,46.45]],"id":52671550},{"atb":[[4.6,29.03],[3.8,87.1]],"id":52671553},{"atb":[[21,7.84],[15.5,24.03]],"id":52671552},{"atb":[[3.4,101.62],[3.9,36.04]],"id":52671547},{"atb":[[3.15,113.44],[3.65,39.44]],"id":52671546},{"atb":[[16.5,6.74],[11.5,23.22]],"id":52671549},{"atb":[[7.2,39.33],[9.2,12.74]],"id":52671548},{"atb":[[3.85,85.58],[4.7,28.25]],"id":52671543},{"atb":[[2.92,127.03],[3.3,45.44]],"id":52671542},{"atb":[[18,6.14],[13,20.32]],"id":52671545},{"atb":[[9.8,11.87],[7.8,35.86]],"id":52671544}],"con":true,"img":false}]}
{"op":"mcm","clk":"11450425690","pt":1717321903656,"mc":[{"id":"1.229554923","rc":[{"atb":[[36,0],[23,0]],"id":52671563},{"atb":[[10.5,0],[15.5,0]],"id":52671562},{"atb":[[9.2,0],[13,8.72]],"id":52671565},{"atb":[[320,0],[420,0]],"id":52671564},{"atb":[[11,0],[8.4,0]],"id":52671561},{"atb":[[9.2,0],[13,0]],"id":52671560},{"atb":[[9.8,0],[7.8,0]],"id":52671555},{"atb":[[200,0],[100,0]],"id":52671554},{"atb":[[18,0],[13,0]],"id":52671556},{"atb":[[9.2,0],[13,0]],"id":52671551},{"atb":[[2.9,0],[3.25,0]],"id":52671550},{"atb":[[4.6,0],[3.8,0]],"id":52671553},{"atb":[[21,2.62],[15.5,7.21]],"id":52671552},{"atb":[[3.4,0],[3.9,0]],"id":52671547},{"atb":[[3.15,0],[3.65,0]],"id":52671546},{"atb":[[16.5,0],[11.5,0]],"id":52671549},{"atb":[[7.2,0],[9.2,0]],"id":52671548},{"atb":[[3.85,0],[4.7,0]],"id":52671543},{"atb":[[2.92,0],[3.3,0]],"id":52671542},{"atb":[[18,0],[13,0]],"id":52671545},{"atb":[[9.8,0],[7.8,0]],"id":52671544}],"con":true,"img":false}]}
{"op":"mcm","clk":"11450426499","pt":1717321913810,"mc":[{"id":"1.229554923","rc":[{"atb":[[34,3.16],[22,11.61]],"id":52671563},{"atb":[[10.5,25.67],[15.5,7.2]],"id":52671562},{"atb":[[9.2,29.74],[13,17.43]],"id":52671565},{"atb":[[320,0.76],[420,0.25]],"id":52671564},{"atb":[[11,10.45],[8.4,32.96]],"id":52671561},{"atb":[[9.2,29.74],[13,8.71]],"id":52671560},{"atb":[[9.8,11.87],[7.8,35.86]],"id":52671555},{"atb":[[200,0.52],[100,2.46]],"id":52671554},{"atb":[[18,6.14],[13,20.32]],"id":52671556},{"atb":[[9.2,29.74],[13,8.71]],"id":52671551},{"atb":[[2.9,128.37],[3.25,46.45]],"id":52671550},{"atb":[[3.85,85.58],[4.7,28.25]],"id":52671553},{"atb":[[21,7.84],[15.5,24.03]],"id":52671552},{"atb":[[3.4,101.62],[3.9,36.04]],"id":52671547},{"atb":[[3.15,113.44],[3.65,39.44]],"id":52671546},{"atb":[[16,6.96],[11,24.39]],"id":52671549},{"atb":[[9,13.06],[7,40.65]],"id":52671548},{"atb":[[3.85,85.58],[4.7,28.25]],"id":52671543},{"atb":[[2.9,128.37],[3.25,46.45]],"id":52671542},{"atb":[[18,6.14],[13,20.32]],"id":52671545},{"atb":[[9.8,11.87],[7.8,35.86]],"id":52671544}],"con":true,"img":false}]}
{"op":"mcm","clk":"11450426676","pt":1717321915793,"mc":[{"id":"1.229554923","rc":[{"atb":[[18,0],[21,0],[26,0],[15.5,0]],"id":52671561},{"atb":[[4.8,0],[4.3,0],[3.65,0]],"id":52671550},{"atb":[[4.8,0],[3.65,0]],"id":52671542}],"con":true,"img":false}]}
{"op":"mcm","clk":"11450426737","pt":1717321916485,"mc":[{"id":"1.229554923","rc":[{"atb":[[16.5,6.75],[19,4.36],[23,2.38],[28,0.97]],"id":52671561},{"atb":[[4.8,6.89],[4.3,15.85],[3.65,39.48]],"id":52671550},{"atb":[[4.8,6.89],[3.65,39.48]],"id":52671542}],"con":true,"img":false}]}
{"op":"mcm","clk":"11450428781","pt":1717321936379,"mc":[{"id":"1.229554923","rc":[{"atb":[[8,0],[5.5,0],[6,0],[7,0]],"id":52671553},{"atb":[[5,0],[5.5,0],[6,0],[7,0]],"id":52671547}],"con":true,"img":false}]}
{"op":"mcm","clk":"11450428864","pt":1717321937118,"mc":[{"id":"1.229554923","rc":[{"atb":[[6.8,9.02],[7.8,3.85],[5.9,16.01],[5.4,23.78]],"id":52671553},{"atb":[[6.8,4.51],[4.9,26.83],[5.9,10.68],[5.4,17.84]],"id":52671547}],"con":true,"img":false}]}
{"op":"mcm","clk":"11450429777","pt":1717321946631,"mc":[{"id":"1.229554923","rc":[{"atb":[[6.8,0],[4.9,0],[5.9,0],[5.4,0]],"id":52671547}],"con":true,"img":false}]}
{"op":"mcm","clk":"11450429842","pt":1717321947312,"mc":[{"id":"1.229554923","rc":[{"atb":[[6.4,4.84],[5.2,18.68],[5.7,11.13],[4.7,28.28]],"id":52671547}],"con":true,"img":false}]}
{"op":"mcm","clk":"11450435934","pt":1717322021708,"mc":[{"id":"1.229554923","rc":[{"atb":[[16.5,0],[19,0],[23,0],[28,0]],"id":52671561}],"con":true,"img":false}]}
{"op":"mcm","clk":"11450436008","pt":1717322022432,"mc":[{"id":"1.229554923","rc":[{"atb":[[16,6.97],[18.5,4.48],[22,2.49],[27,1]],"id":52671561}],"con":true,"img":false}]}
{"op":"mcm","clk":"11450437628","pt":1717322040647,"mc":[{"id":"1.229554923","rc":[{"atb":[[25,5],[27,3.08]],"id":52671562},{"atl":[[100,3.33],[120,2.8]],"id":52671562},{"atb":[[19,4.46],[20,4.16]],"id":52671565},{"atl":[[70,3.18],[80,4.04]],"id":52671565},{"atb":[[17.5,3.85],[18.5,8.9]],"id":52671561},{"atl":[[65,3.8],[55,3.76]],"id":52671561},{"atb":[[20,4.31],[22,3.78]],"id":52671560},{"atl":[[70,4.6],[80,3.25]],"id":52671560},{"atb":[[16.5,3.33],[17.5,3.52]],"id":52671555},{"atl":[[65,3.12],[55,3.73]],"id":52671555},{"atb":[[130,2.69],[150,4.5]],"id":52671554},{"atl":[[920,3.69],[940,3.86]],"id":52671554},{"atb":[[32,4.05],[29,2.72]],"id":52671556},{"atl":[[130,2.8],[150,4.2]],"id":52671556},{"atb":[[21,4.45],[23,2.94]],"id":52671551},{"atl":[[75,4.32],[85,4.25]],"id":52671551},{"atl":[[8,3.91],[8.4,4.56]],"id":52671550},{"atb":[[6.2,3.97],[5.9,19.93]],"id":52671553},{"atl":[[16.5,4.31],[15.5,4.41]],"id":52671553},{"atb":[[42,2.74],[46,3.64]],"id":52671552},{"atl":[[190,4.52],[210,3.21]],"id":52671552},{"atb":[[5.1,3.36],[4.9,3.78]],"id":52671547},{"atl":[[11.5,3.73],[12.5,3.85]],"id":52671547},{"atb":[[4.8,4.42],[5,23.65]],"id":52671546},{"atl":[[10.5,3.76],[11.5,2.84]],"id":52671546},{"atb":[[28,4.35],[30,3.51]],"id":52671549},{"atl":[[130,4.48],[110,4.22]],"id":52671549},{"atb":[[14.5,3.92],[15.5,3.42]],"id":52671548},{"atl":[[44,3.59],[48,3.63]],"id":52671548},{"atl":[[14,3.8],[15,3.18]],"id":52671543},{"atb":[[4.3,20.61],[4.5,4.27]],"id":52671542},{"atl":[[8.6,3.53],[9,3.35]],"id":52671542},{"atb":[[34,3.56],[30,4.56]],"id":52671545},{"atl":[[140,3.68],[160,3.06]],"id":52671545},{"atb":[[17,4.53],[18,2.9]],"id":52671544},{"atl":[[65,3.14],[55,3.85]],"id":52671544}],"con":true,"img":false}]}
{"op":"mcm","clk":"11450437635","pt":1717322040750,"mc":[{"id":"1.229554923","rc":[{"atl":[[460,2.88],[480,2.92]],"id":52671563}],"con":true,"img":false}]}
{"op":"mcm","clk":"11450437643","pt":1717322040852,"mc":[{"id":"1.229554923","rc":[{"atl":[[590,0],[320,2]],"id":52671562},{"atl":[[520,0],[170,2]],"id":52671565},{"atl":[[540,0],[160,2]],"id":52671561},{"atl":[[580,0],[220,2]],"id":52671560},{"atl":[[580,0],[190,2]],"id":52671555},{"atl":[[300,2],[680,0]],"id":52671551},{"atl":[[140,0],[18,5.88]],"id":52671550},{"atl":[[360,0],[50,2.04]],"id":52671553},{"atl":[[260,0],[27,3.85]],"id":52671547},{"atl":[[260,0],[27,3.85]],"id":52671546},{"atl":[[530,0],[140,2]],"id":52671548},{"atl":[[350,0],[44,2.33]],"id":52671543},{"atl":[[16.5,6.45],[110,0]],"id":52671542},{"atl":[[590,0],[200,2]],"id":52671544}],"con":true,"img":false}]}
{"op":"mcm","clk":"11450437654","pt":1717322040961,"mc":[{"id":"1.229554923","rc":[{"atl":[[800,2],[1000,0]],"id":52671563}],"con":true,"img":false}]}
{"op":"mcm","clk":"11450437669","pt":1717322041070,"mc":[{"id":"1.229554923","rc":[{"atb":[[26,3.89],[28,3.89]],"id":52671562},{"atb":[[17,4.09],[18,2.7]],"id":52671561},{"atb":[[16,7.21],[17,3.87]],"id":52671555},{"atb":[[34,4.43],[30,2.88]],"id":52671556},{"atb":[[6.4,3.2],[6,3.7]],"id":52671553},{"atb":[[44,4.12],[48,4.62]],"id":52671552},{"atb":[[27,4.16],[29,4.6]],"id":52671549},{"atb":[[13,3.6],[14,7.45]],"id":52671548},{"atb":[[4,5.23],[4.2,4.9]],"id":52671542},{"atb":[[16.5,4.45],[17.5,3.7]],"id":52671544}],"con":true,"img":false}]}
{"op":"mcm","clk":"11450437702","pt":1717322041385,"mc":[{"id":"1.229554923","rc":[{"atb":[[6,0],[7.6,10.48]],"id":52671562},{"atb":[[6,10.82],[4.9,0]],"id":52671565},{"atb":[[32,5.07],[24,0]],"id":52671564},{"atb":[[4.8,0],[5.6,11.84]],"id":52671561},{"atb":[[5.6,0],[6.4,16.75]],"id":52671555},{"atb":[[32,3.23],[24,0]],"id":52671554},{"atb":[[6.2,0],[7.4,15.62]],"id":52671551},{"atb":[[3.45,0],[3.75,36.36]],"id":52671553},{"atb":[[23,0],[28,3.7]],"id":52671552},{"atb":[[3.2,0],[3.5,40]],"id":52671547},{"atb":[[3.2,45.45],[2.86,0]],"id":52671546},{"atb":[[4.8,0],[5.3,23.26]],"id":52671548},{"atb":[[2.6,0],[2.76,56.82]],"id":52671542},{"atb":[[17.5,6.06],[14,0]],"id":52671545}],"con":true,"img":false}]}
{"op":"mcm","clk":"11450437804","pt":1717322042369,"mc":[{"id":"1.229554923","rc":[{"atb":[[28,0]],"id":52671562},{"atb":[[17.5,0],[17,0]],"id":52671561},{"atb":[[16.5,0],[16,3.49]],"id":52671555},{"atb":[[34,0]],"id":52671556},{"atb":[[6.4,0]],"id":52671553},{"atb":[[48,0]],"id":52671552},{"atb":[[27,0],[28,0]],"id":52671549},{"atb":[[13,0],[14,4.02]],"id":52671548},{"atb":[[4,0],[4.2,0]],"id":52671542},{"atb":[[16.5,0],[17,0]],"id":52671544}],"con":true,"img":false}]}
{"op":"mcm","clk":"11450437813","pt":1717322042474,"mc":[{"id":"1.229554923","rc":[{"atb":[[25,2.18],[26,0]],"id":52671562},{"atb":[[18.5,4.48]],"id":52671561},{"atb":[[17.5,0]],"id":52671555},{"atb":[[29,0],[30,0]],"id":52671556},{"atb":[[6,0],[5.9,16.01]],"id":52671553},{"atb":[[42,0],[44,0]],"id":52671552},{"atb":[[30,0]],"id":52671549},{"atb":[[14.5,0],[15.5,0]],"id":52671548},{"atb":[[4.5,0],[4.3,15.85]],"id":52671542},{"atb":[[18,0]],"id":52671544}],"con":true,"img":false}]}
{"op":"mcm","clk":"11450438114","pt":1717322045945,"mc":[{"id":"1.229554923","rc":[{"atb":[[28,2.76]],"id":52671562},{"atb":[[34,2.94]],"id":52671556},{"atb":[[6.4,3.17]],"id":52671553},{"atb":[[48,3.63]],"id":52671552},{"atb":[[13,3.35],[14,7.95]],"id":52671548},{"atb":[[4,5.23],[4.2,4.9]],"id":52671542}],"con":true,"img":false}]}
{"op":"mcm","clk":"11450438554","pt":1717322051039,"mc":[{"id":"1.229554923","rc":[{"atb":[[17,4.48]],"id":52671561},{"atb":[[16,7.25]],"id":52671555},{"atb":[[27,2.72]],"id":52671549},{"atb":[[16.5,2.84]],"id":52671544}],"con":true,"img":false}]}
{"op":"mcm","clk":"11450439792","pt":1717322064408,"mc":[{"id":"1.229554923","rc":[{"atl":[[800,0]],"id":52671563},{"atb":[[9.2,10.48],[7.6,0]],"id":52671562},{"atl":[[320,0],[410,2]],"id":52671562},{"atb":[[7.4,10.82],[6,0]],"id":52671565},{"atb":[[5.6,0],[6.8,11.84]],"id":52671561},{"atb":[[6,0],[7.8,11.11]],"id":52671560},{"atb":[[16.5,9.82],[12.5,0]],"id":52671556},{"atl":[[590,2],[650,0]],"id":52671556},{"atb":[[7.4,0],[8.4,13.51]],"id":52671551},{"atb":[[4.1,32.26],[3.75,0]],"id":52671553},{"atb":[[32,3.23],[28,0]],"id":52671552},{"atb":[[3.5,0],[3.75,36.36]],"id":52671547},{"atl":[[570,0],[500,2]],"id":52671549},{"atl":[[16.5,0],[13.5,6.89]],"id":52671542},{"atl":[[610,2],[700,0]],"id":52671545},{"atb":[[7,16.67],[5.9,0]],"id":52671544}],"con":true,"img":false}]}
{"op":"mcm","clk":"11450439821","pt":1717322064664,"mc":[{"id":"1.229554923","rc":[{"atb":[[20,0],[21,5.88]],"id":52671565},{"atl":[[16,2.78],[15.5,0]],"id":52671553},{"atl":[[190,0],[200,4.24]],"id":52671552},{"atl":[[10,4.32],[10.5,0]],"id":52671546},{"atl":[[100,3.12],[110,0]],"id":52671549}],"con":true,"img":false}]}
{"op":"mcm","clk":"11450441299","pt":1717322078378,"mc":[{"id":"1.229554923","rc":[{"atl":[[750,2]],"id":52671563},{"atl":[[290,2],[410,0]],"id":52671562},{"atl":[[740,2],[820,0]],"id":52671552},{"atb":[[10,0],[12.5,8.7]],"id":52671549},{"atb":[[5.8,20.83],[5.3,0]],"id":52671548},{"atb":[[2.92,52.08],[2.76,0]],"id":52671542}],"con":true,"img":false}]}
{"op":"mcm","clk":"11450441328","pt":1717322078692,"mc":[{"id":"1.229554923","rc":[{"atb":[[20,4.64],[21,1.31]],"id":52671565},{"atl":[[16,0],[15.5,4.39]],"id":52671553},{"atl":[[190,4.3],[200,0]],"id":52671552},{"atl":[[10,0],[10.5,3.18]],"id":52671546},{"atl":[[100,0],[110,3.78]],"id":52671549}],"con":true,"img":false}]}
{"op":"mcm","clk":"11450451530","pt":1717322198430,"mc":[{"id":"1.229554923","rc":[{"atb":[[9.2,0],[7.6,8.26]],"id":52671562},{"atb":[[7.4,0],[6,10.05]],"id":52671565},{"atb":[[5.6,8.98],[6.8,0]],"id":52671561},{"atb":[[4.1,0],[3.75,32.04]],"id":52671553},{"atb":[[2.92,0],[2.76,54.12]],"id":52671542},{"atl":[[16.5,6.45],[13.5,0]],"id":52671542},{"atl":[[610,0],[680,2]],"id":52671545}],"con":true,"img":false}]}
{"op":"mcm","clk":"11450452400","pt":1717322207548,"mc":[{"id":"1.229554923","rc":[{"atb":[[34,0],[22,0]],"id":52671563},{"atb":[[10.5,0],[15.5,0]],"id":52671562},{"atb":[[9.2,0],[13,8.72]],"id":52671565},{"atb":[[320,0],[420,0]],"id":52671564},{"atb":[[11,0],[8.4,0]],"id":52671561},{"atb":[[9.2,0],[13,0]],"id":52671560},{"atb":[[9.8,0],[7.8,0]],"id":52671555},{"atb":[[200,0],[100,0]],"id":52671554},{"atb":[[18,0],[13,0]],"id":52671556},{"atb":[[9.2,0],[13,0]],"id":52671551},{"atb":[[2.9,0],[3.25,0]],"id":52671550},{"atb":[[3.85,0],[4.7,0]],"id":52671553},{"atb":[[21,2.62],[15.5,7.21]],"id":52671552},{"atb":[[3.4,0],[3.9,0]],"id":52671547},{"atb":[[3.15,0],[3.65,0]],"id":52671546},{"atb":[[16,0],[11,0]],"id":52671549},{"atb":[[9,0],[7,0]],"id":52671548},{"atb":[[3.85,0],[4.7,0]],"id":52671543},{"atb":[[2.9,0],[3.25,0]],"id":52671542},{"atb":[[18,0],[13,0]],"id":52671545},{"atb":[[9.8,0],[7.8,0]],"id":52671544}],"con":true,"img":false}]}
{"op":"mcm","clk":"11450453191","pt":1717322215948,"mc":[{"id":"1.229554923","rc":[{"atb":[[2.64,9.56],[2.68,9.34]],"id":52671563},{"atb":[[150,3.35],[170,4.04]],"id":52671564},{"atb":[[2.64,9.56],[2.68,9.34]],"id":52671550},{"atb":[[2.64,9.56],[2.68,9.34]],"id":52671543}],"con":true,"img":false}]}
{"op":"mcm","clk":"11450453231","pt":1717322216374,"mc":[{"id":"1.229554923","rc":[{"atb":[[16,0],[18.5,0],[22,0],[27,0]],"id":52671561}],"con":true,"img":false}]}
{"op":"mcm","clk":"11450453302","pt":1717322217040,"mc":[{"id":"1.229554923","rc":[{"atb":[[16.5,6.75],[19,4.36],[23,2.38],[28,0.97]],"id":52671561}],"con":true,"img":false}]}
{"op":"mcm","clk":"11450453893","pt":1717322223468,"mc":[{"id":"1.229554923","rc":[{"atb":[[1.03,97.14]],"id":52671563},{"atb":[[1.03,180.65]],"id":52671562},{"atb":[[1.04,109.07]],"id":52671565},{"atb":[[1.03,137.19]],"id":52671564},{"atb":[[1.03,86.91]],"id":52671561},{"atb":[[1.02,219.85]],"id":52671560},{"atb":[[1.03,172.98]],"id":52671555},{"atb":[[1.03,159.35]],"id":52671554},{"atb":[[1.04,164.46]],"id":52671556},{"atb":[[1.04,90.32]],"id":52671551},{"atb":[[1.04,111.63]],"id":52671550},{"atb":[[1.03,121]],"id":52671553},{"atb":[[1.02,81.8]],"id":52671552},{"atb":[[1.02,91.18]],"id":52671547},{"atb":[[1.04,177.24]],"id":52671546},{"atb":[[1.03,162.76]],"id":52671549},{"atb":[[1.02,78.39]],"id":52671548},{"atb":[[1.02,97.14]],"id":52671543},{"atb":[[1.02,124.41]],"id":52671542},{"atb":[[1.03,153.38]],"id":52671545},{"atb":[[1.03,103.96]],"id":52671544}],"con":true,"img":false}]}
{"op":"mcm","clk":"11450455186","pt":1717322236055,"mc":[{"id":"1.229554923","rc":[{"atb":[[11,10.45],[8.4,32.96]],"id":52671561},{"atb":[[9.2,29.74],[13,8.71]],"id":52671560},{"atb":[[3.4,101.62],[3.9,36.04]],"id":52671547},{"atb":[[3.15,113.44],[3.65,39.44]],"id":52671546},{"atb":[[16,6.96],[11,24.39]],"id":52671549},{"atb":[[9,13.06],[7,40.65]],"id":52671548},{"atb":[[3.85,85.58],[4.7,28.25]],"id":52671543},{"atb":[[2.9,128.37],[3.25,46.45]],"id":52671542},{"atb":[[18,6.14],[13,20.32]],"id":52671545},{"atb":[[9.8,11.87],[7.8,35.86]],"id":52671544}],"con":true,"img":false}]}
{"op":"mcm","clk":"11450455196","pt":1717322236155,"mc":[{"id":"1.229554923","rc":[{"atb":[[34,3.16],[22,11.61]],"id":52671563},{"atb":[[10.5,25.67],[15.5,7.2]],"id":52671562},{"atb":[[9.2,29.74],[13,17.43]],"id":52671565},{"atb":[[320,0.76],[420,0.25]],"id":52671564},{"atb":[[9.8,11.87],[7.8,35.86]],"id":52671555},{"atb":[[200,0.52],[100,2.46]],"id":52671554},{"atb":[[18,6.14],[13,20.32]],"id":52671556},{"atb":[[9.2,29.74],[13,8.71]],"id":52671551},{"atb":[[2.9,128.37],[3.25,46.45]],"id":52671550},{"atb":[[3.85,85.58],[4.7,28.25]],"id":52671553},{"atb":[[21,7.84],[15.5,24.03]],"id":52671552}],"con":true,"img":false}]}
{"op":"mcm","clk":"11450485439","pt":1717322584430,"mc":[{"id":"1.229554923","rc":[{"atb":[[34,0],[22,0]],"id":52671563},{"atb":[[10.5,0],[15.5,0]],"id":52671562},{"atb":[[9.2,0],[13,8.72]],"id":52671565},{"atb":[[320,0],[420,0]],"id":52671564},{"atb":[[11,0],[8.4,0]],"id":52671561},{"atb":[[9.2,0],[13,0]],"id":52671560},{"atb":[[9.8,0],[7.8,0]],"id":52671555},{"atb":[[200,0],[100,0]],"id":52671554},{"atb":[[18,0],[13,0]],"id":52671556},{"atb":[[9.2,0],[13,0]],"id":52671551},{"atb":[[2.9,0],[3.25,0]],"id":52671550},{"atb":[[3.85,0],[4.7,0]],"id":52671553},{"atb":[[21,2.62],[15.5,7.21]],"id":52671552},{"atb":[[3.4,0],[3.9,0]],"id":52671547},{"atb":[[3.15,0],[3.65,0]],"id":52671546},{"atb":[[16,0],[11,0]],"id":52671549},{"atb":[[9,0],[7,0]],"id":52671548},{"atb":[[3.85,0],[4.7,0]],"id":52671543},{"atb":[[2.9,0],[3.25,0]],"id":52671542},{"atb":[[18,0],[13,0]],"id":52671545},{"atb":[[9.8,0],[7.8,0]],"id":52671544}],"con":true,"img":false}]}
{"op":"mcm","clk":"11450486978","pt":1717322601760,"mc":[{"id":"1.229554923","rc":[{"atb":[[34,3.16],[22,11.61]],"id":52671563},{"atb":[[10.5,25.67],[15.5,7.2]],"id":52671562},{"atb":[[9.2,29.74],[13,17.43]],"id":52671565},{"atb":[[320,0.76],[420,0.25]],"id":52671564},{"atb":[[9.8,11.87],[7.8,35.86]],"id":52671555},{"atb":[[200,0.52],[100,2.46]],"id":52671554},{"atb":[[18,6.14],[13,20.32]],"id":52671556},{"atb":[[9.2,29.74],[13,8.71]],"id":52671551},{"atb":[[2.9,128.37],[3.25,46.45]],"id":52671550},{"atb":[[3.85,85.58],[4.7,28.25]],"id":52671553},{"atb":[[21,7.84],[15.5,24.03]],"id":52671552}],"con":true,"img":false}]}
{"op":"mcm","clk":"11450486988","pt":1717322601864,"mc":[{"id":"1.229554923","rc":[{"atb":[[11,10.45],[8.4,32.96]],"id":52671561},{"atb":[[9.2,29.74],[13,8.71]],"id":52671560},{"atb":[[3.4,101.62],[3.9,36.04]],"id":52671547},{"atb":[[3.15,113.44],[3.65,39.44]],"id":52671546},{"atb":[[16,6.96],[11,24.39]],"id":52671549},{"atb":[[9,13.06],[7,40.65]],"id":52671548},{"atb":[[3.85,85.58],[4.7,28.25]],"id":52671543},{"atb":[[2.9,128.37],[3.25,46.45]],"id":52671542},{"atb":[[18,6.14],[13,20.32]],"id":52671545},{"atb":[[9.8,11.87],[7.8,35.86]],"id":52671544}],"con":true,"img":false}]}
{"op":"mcm","clk":"11450489786","pt":1717322632484,"mc":[{"id":"1.229554923","rc":[{"atb":[[25,4.84],[28,0]],"id":52671562},{"atb":[[19.5,3.69]],"id":52671565},{"atb":[[170,0]],"id":52671564},{"atb":[[16.5,0],[19,0],[23,0],[28,0]],"id":52671561},{"atb":[[22,0]],"id":52671560},{"atb":[[22,3.19],[23,0]],"id":52671551},{"atb":[[4.8,0],[4.3,0],[3.65,0]],"id":52671550},{"atb":[[48,0]],"id":52671552},{"atb":[[6.4,0],[5.2,0],[5.7,0],[4.7,0]],"id":52671547},{"atb":[[29,0],[30,2.77]],"id":52671549},{"atb":[[14,4.02],[15,3.74]],"id":52671548},{"atb":[[4.8,0],[4.5,4.37],[4.2,0],[3.65,0]],"id":52671542}],"con":true,"img":false}]}
{"op":"mcm","clk":"11450489796","pt":1717322632587,"mc":[{"id":"1.229554923","rc":[{"atb":[[20,0]],"id":52671565},{"atb":[[18,0]],"id":52671561},{"atb":[[16.5,2.96],[17,0]],"id":52671555},{"atb":[[34,0]],"id":52671556},{"atb":[[6.4,0]],"id":52671553},{"atb":[[28,3.7]],"id":52671552}],"con":true,"img":false}]}
{"op":"mcm","clk":"11450489802","pt":1717322632690,"mc":[{"id":"1.229554923","rc":[{"atb":[[32,0]],"id":52671552}],"con":true,"img":false}]}
{"op":"mcm","clk":"11450489843","pt":1717322633160,"mc":[{"id":"1.229554923","rc":[{"atb":[[16.5,6.75],[19,4.36],[23,2.38],[28,0.97]],"id":52671561},{"atb":[[4.8,6.89],[3.65,39.48]],"id":52671542}],"con":true,"img":false}]}
{"op":"mcm","clk":"11450489856","pt":1717322633268,"mc":[{"id":"1.229554923","rc":[{"atb":[[4.8,6.89],[4.3,15.85],[3.65,39.48]],"id":52671550},{"atb":[[6.4,4.84],[5.2,18.68],[5.7,11.13],[4.7,28.28]],"id":52671547}],"con":true,"img":false}]}
{"op":"mcm","clk":"11450489990","pt":1717322634979,"mc":[{"id":"1.229554923","rc":[{"atb":[[22,4.09]],"id":52671560}],"con":true,"img":false}]}
{"op":"mcm","clk":"11450489994","pt":1717322635086,"mc":[{"id":"1.229554923","rc":[{"atb":[[18,4.05]],"id":52671561},{"atb":[[34,2.94]],"id":52671556},{"atb":[[6.4,4.7]],"id":52671553},{"atb":[[48,2.67]],"id":52671552}],"con":true,"img":false}]}
{"op":"mcm","clk":"11450490044","pt":1717322635665,"mc":[{"id":"1.229554923","rc":[{"atb":[[27,0],[28,3.34]],"id":52671562},{"atb":[[19.5,0],[20,4.63]],"id":52671565},{"atb":[[16.5,0],[17,3.52]],"id":52671555},{"atb":[[22,0],[23,3.91]],"id":52671551},{"atb":[[29,3.98]],"id":52671549},{"atb":[[14,8.41],[15,0]],"id":52671548},{"atb":[[4.5,0],[4.2,4.9]],"id":52671542}],"con":true,"img":false}]}
{"op":"mcm","clk":"11450490049","pt":1717322635761,"mc":[{"id":"1.229554923","rc":[{"atb":[[30,0]],"id":52671549}],"con":true,"img":false}]}
{"op":"mcm","clk":"11450490176","pt":1717322637176,"mc":[{"id":"1.229554923","rc":[{"atb":[[28,0]],"id":52671562},{"atb":[[19.5,4.26],[20,0]],"id":52671565},{"atb":[[18,0]],"id":52671561},{"atb":[[22,0]],"id":52671560},{"atb":[[16.5,3.1],[17,0]],"id":52671555},{"atb":[[34,0]],"id":52671556},{"atb":[[22,3.62],[23,0]],"id":52671551},{"atb":[[6.4,0]],"id":52671553},{"atb":[[48,0]],"id":52671552},{"atb":[[29,0],[30,3.03]],"id":52671549},{"atb":[[14,4.02],[15,2.95]],"id":52671548},{"atb":[[4.5,3.55],[4.2,0]],"id":52671542}],"con":true,"img":false}]}
{"op":"mcm","clk":"11450490230","pt":1717322637861,"mc":[{"id":"1.229554923","rc":[{"atb":[[3.95,9.34],[2.52,0]],"id":52671563},{"atb":[[16.5,3.37],[8,14.29]],"id":52671556},{"atb":[[8,14.29],[12.5,0]],"id":52671549},{"atb":[[5.8,0],[3.95,33.9]],"id":52671548}],"con":true,"img":false}]}
{"op":"mcm","clk":"11450490244","pt":1717322638071,"mc":[{"id":"1.229554923","rc":[{"atb":[[3.1,7.47]],"id":52671550}],"con":true,"img":false}]}
{"op":"mcm","clk":"11450490254","pt":1717322638175,"mc":[{"id":"1.229554923","rc":[{"atb":[[32,0]],"id":52671556},{"atb":[[2.68,0]],"id":52671550},{"atb":[[5.1,0],[5.4,4.57]],"id":52671547},{"atb":[[27,0],[30,0]],"id":52671549},{"atb":[[13,0],[15,0]],"id":52671548},{"atb":[[4.1,5.06],[2.68,0]],"id":52671543}],"con":true,"img":false}]}
{"op":"mcm","clk":"11450490623","pt":1717322642614,"mc":[{"id":"1.229554923","rc":[{"atl":[[460,0],[470,3.08]],"id":52671563},{"atb":[[28,3.25]],"id":52671562},{"atb":[[19.5,0],[20,3.63]],"id":52671565},{"atb":[[18,4.01]],"id":52671561},{"atl":[[55,0],[60,4.69]],"id":52671561},{"atb":[[21,7.12],[22,4.39]],"id":52671560},{"atl":[[70,0],[75,3.05]],"id":52671560},{"atb":[[16.5,0],[17,3.63],[18,4.56]],"id":52671555},{"atl":[[50,3.9],[55,0]],"id":52671555},{"atl":[[920,0],[910,3.35]],"id":52671554},{"atb":[[22,0],[23,4.67],[24,3.9]],"id":52671551},{"atb":[[6.4,3.96]],"id":52671553},{"atb":[[48,3.62]],"id":52671552},{"atb":[[5,19.62],[4.9,4.36]],"id":52671546},{"atl":[[42,4.29],[44,0]],"id":52671548},{"atb":[[4.8,0],[4.5,0],[4.3,0],[4.1,5.06],[3.9,0],[4.2,4.9],[3.65,0]],"id":52671542},{"atl":[[8.6,0],[8.4,4.36]],"id":52671542},{"atb":[[17.5,0],[18.5,2.81],[18,3.33]],"id":52671544}],"con":true,"img":false}]}
{"op":"mcm","clk":"11450490631","pt":1717322642676,"mc":[{"id":"1.229554923","rc":[{"atl":[[450,4.45]],"id":52671563},{"atl":[[880,3.2],[890,3.38]],"id":52671554},{"atl":[[8,0],[8.2,4.6]],"id":52671550},{"atb":[[6.8,0],[7.8,0],[5.9,0],[5.4,0]],"id":52671553},{"atl":[[11,4.08],[11.5,0]],"id":52671547}],"con":true,"img":false}]}
{"op":"mcm","clk":"11450490709","pt":1717322643400,"mc":[{"id":"1.229554923","rc":[{"atb":[[6.8,9.02],[7.8,3.85],[5.9,16.01],[5.4,23.78]],"id":52671553},{"atb":[[4.8,6.89],[4.3,15.85],[3.9,27.06],[3.65,39.48]],"id":52671542}],"con":true,"img":false}]}
{"op":"mcm","clk":"11450490773","pt":1717322643983,"mc":[{"id":"1.229554923","rc":[{"atl":[[450,0],[480,0]],"id":52671563},{"atb":[[20,0]],"id":52671560},{"atb":[[18,0]],"id":52671555},{"atl":[[880,0],[890,0],[940,0]],"id":52671554},{"atb":[[24,0]],"id":52671551},{"atl":[[8,3.68]],"id":52671550},{"atl":[[11,0],[11.5,4.04]],"id":52671547},{"atb":[[5,22.4],[4.9,0]],"id":52671546},{"atb":[[4,0]],"id":52671542},{"atb":[[17.5,3.46],[18.5,0],[18,0]],"id":52671544}],"con":true,"img":false}]}
{"op":"mcm","clk":"11450490787","pt":1717322644087,"mc":[{"id":"1.229554923","rc":[{"atl":[[460,2.73],[470,0]],"id":52671563},{"atl":[[55,3.17],[60,0]],"id":52671561},{"atb":[[22,0]],"id":52671560},{"atl":[[70,4.28],[75,0]],"id":52671560},{"atb":[[16,3.49]],"id":52671555},{"atl":[[55,3.71]],"id":52671555},{"atl":[[910,0]],"id":52671554},{"atb":[[21,0]],"id":52671551},{"atl":[[8.2,0]],"id":52671550},{"atb":[[6.8,0],[7.8,0],[5.9,0],[5.4,0]],"id":52671553},{"atb":[[4.8,0],[4.3,0],[4.1,0],[3.9,0],[4.2,0],[3.65,0]],"id":52671542},{"atb":[[16.5,0]],"id":52671544}],"con":true,"img":false}]}
{"op":"mcm","clk":"11450490795","pt":1717322644190,"mc":[{"id":"1.229554923","rc":[{"atl":[[50,0]],"id":52671555}],"con":true,"img":false}]}
{"op":"mcm","clk":"11450490861","pt":1717322644767,"mc":[{"id":"1.229554923","rc":[{"atb":[[8,3.74],[5.5,23.25],[6,15.7],[7,8.72]],"id":52671553}],"con":true,"img":false}]}
{"op":"mcm","clk":"11450490873","pt":1717322644873,"mc":[{"id":"1.229554923","rc":[{"atb":[[3.6,40.24],[3.85,27.54],[4.2,16.35],[4.7,7.07]],"id":52671542}],"con":true,"img":false}]}
{"op":"mcm","clk":"11450491023","pt":1717322646093,"mc":[{"id":"1.229554923","rc":[{"atb":[[22,3.17]],"id":52671560},{"atb":[[18,3.47]],"id":52671555},{"atl":[[920,3.4],[940,3.51]],"id":52671554},{"atb":[[24,3.57]],"id":52671551},{"atb":[[5,19.62]],"id":52671546},{"atl":[[42,0],[44,3.65]],"id":52671548},{"atb":[[4,5.23],[3.9,5.4],[4.2,21.26]],"id":52671542},{"atl":[[8.6,4.14],[8.4,0]],"id":52671542},{"atb":[[18,2.89]],"id":52671544}],"con":true,"img":false}]}
{"op":"mcm","clk":"11450491201","pt":1717322648074,"mc":[{"id":"1.229554923","rc":[{"atb":[[3.95,5.32]],"id":52671543}],"con":true,"img":false}]}
{"op":"mcm","clk":"11450491703","pt":1717322653893,"mc":[{"id":"1.229554923","rc":[{"atb":[[18,0]],"id":52671555},{"atb":[[24,0]],"id":52671551},{"atb":[[5,22.75]],"id":52671546},{"atb":[[18,0]],"id":52671544}],"con":true,"img":false}]}
{"op":"mcm","clk":"11450491715","pt":1717322653994,"mc":[{"id":"1.229554923","rc":[{"atb":[[3,7.84]],"id":52671550},{"atb":[[5.2,21.42]],"id":52671547},{"atb":[[2.64,0]],"id":52671543},{"atb":[[3.9,0]],"id":52671542}],"con":true,"img":false}]}
{"op":"mcm","clk":"11450491723","pt":1717322654098,"mc":[{"id":"1.229554923","rc":[{"atl":[[480,4.14]],"id":52671563}],"con":true,"img":false}]}
{"op":"mcm","clk":"11450491883","pt":1717322656101,"mc":[{"id":"1.229554923","rc":[{"atb":[[16,7.24]],"id":52671555},{"atb":[[21,3.64]],"id":52671551},{"atb":[[16.5,3.74]],"id":52671544}],"con":true,"img":false}]}
{"op":"mcm","clk":"11450492545","pt":1717322664129,"mc":[{"id":"1.229554923","rc":[{"atb":[[2.64,0]],"id":52671550},{"atb":[[4.9,0]],"id":52671547}],"con":true,"img":false}]}
{"op":"mcm","clk":"11450492639","pt":1717322665330,"mc":[{"id":"1.229554923","rc":[{"atl":[[750,0]],"id":52671563},{"atb":[[9,12.5],[7.6,0]],"id":52671562},{"atl":[[290,0],[400,2]],"id":52671562},{"atb":[[7.4,15.62],[6,0]],"id":52671565},{"atb":[[5.6,0],[6.6,17.86]],"id":52671561},{"atb":[[6.4,0],[7.4,15.62]],"id":52671555},{"atb":[[2.52,0],[2.96,51.02]],"id":52671550},{"atb":[[4.1,32.26],[3.75,0]],"id":52671553},{"atb":[[28,0],[30,3.45]],"id":52671552},{"atb":[[3.85,120.67],[2.52,0]],"id":52671543},{"atl":[[16.5,0],[13,7.51]],"id":52671542},{"atl":[[590,2],[680,0]],"id":52671545}],"con":true,"img":false}]}
{"op":"mcm","clk":"11450492651","pt":1717322665384,"mc":[{"id":"1.229554923","rc":[{"atl":[[170,0],[230,2]],"id":52671565}],"con":true,"img":false}]}
{"op":"mcm","clk":"11450492669","pt":1717322665591,"mc":[{"id":"1.229554923","rc":[{"atb":[[21,4.11]],"id":52671565},{"atl":[[17,2.78],[15.5,0]],"id":52671553},{"atl":[[190,0],[200,3.67]],"id":52671552},{"atl":[[10,3.34]],"id":52671546},{"atl":[[100,3.32],[110,0]],"id":52671549},{"atl":[[130,3.34],[140,0]],"id":52671545}],"con":true,"img":false}]}
{"op":"mcm","clk":"11450492681","pt":1717322665695,"mc":[{"id":"1.229554923","rc":[{"atb":[[20,0]],"id":52671565},{"atl":[[16,4.56]],"id":52671553},{"atl":[[10.5,0]],"id":52671546}],"con":true,"img":false}]}
{"op":"mcm","clk":"11450492695","pt":1717322665800,"mc":[{"id":"1.229554923","rc":[{"atb":[[22,2.87]],"id":52671565},{"atb":[[22,0]],"id":52671560},{"atb":[[17,0],[18,3.21]],"id":52671555},{"atl":[[880,3.18],[920,0]],"id":52671554},{"atb":[[23,0],[24,3.88]],"id":52671551},{"atl":[[11,3.56],[11.5,0]],"id":52671547},{"atb":[[5,19.62]],"id":52671546},{"atl":[[42,2.88],[44,0]],"id":52671548},{"atb":[[4.2,16.35]],"id":52671542},{"atl":[[8.6,0],[8.4,2.69]],"id":52671542},{"atb":[[17.5,0],[18,4.27]],"id":52671544}],"con":true,"img":false}]}
{"op":"mcm","clk":"11450492930","pt":1717322668820,"mc":[{"id":"1.229554923","rc":[{"atb":[[17.5,3.25]],"id":52671544}],"con":true,"img":false}]}
{"op":"mcm","clk":"11450492938","pt":1717322668920,"mc":[{"id":"1.229554923","rc":[{"atb":[[19,0],[22,0]],"id":52671565},{"atb":[[22,2.75]],"id":52671560},{"atb":[[17,4.23],[18,0]],"id":52671555},{"atb":[[23,4.22],[24,0]],"id":52671551},{"atl":[[16.5,0],[17,0]],"id":52671553},{"atb":[[5,23.85]],"id":52671546},{"atb":[[4.2,21.26]],"id":52671542},{"atb":[[18,0]],"id":52671544}],"con":true,"img":false}]}
{"op":"mcm","clk":"11450493003","pt":1717322669540,"mc":[{"id":"1.229554923","rc":[{"atl":[[460,0],[470,3.73]],"id":52671563},{"atl":[[55,0],[60,3.77]],"id":52671561},{"atb":[[17.5,2.65]],"id":52671555},{"atl":[[880,0],[910,3.1]],"id":52671554},{"atl":[[8,0],[8.2,2.93]],"id":52671550},{"atl":[[11,0],[11.5,4.53]],"id":52671547},{"atb":[[4.9,3.96]],"id":52671546},{"atb":[[17,3.77]],"id":52671544}],"con":true,"img":false}]}
{"op":"mcm","clk":"11450493097","pt":1717322670635,"mc":[{"id":"1.229554923","rc":[{"atl":[[460,3.61],[470,0]],"id":52671563},{"atb":[[26,2.74],[28,0]],"id":52671562},{"atb":[[20,3.5],[21,1.31],[22,3.47]],"id":52671565},{"atb":[[16.5,3.09],[18,0],[19,0],[23,0],[28,0]],"id":52671561},{"atl":[[55,4.58],[60,0]],"id":52671561},{"atb":[[20,3.51],[22,0]],"id":52671560},{"atb":[[16,3.49]],"id":52671555},{"atl":[[880,3.09],[910,0]],"id":52671554},{"atl":[[8,4.24],[8.2,0]],"id":52671550},{"atb":[[48,0],[50,3.2]],"id":52671552},{"atl":[[11,4.31],[11.5,0]],"id":52671547},{"atb":[[5,19.62]],"id":52671546},{"atb":[[4.1,5.06],[4.2,16.35]],"id":52671542},{"atb":[[17.5,0]],"id":52671544}],"con":true,"img":false}]}
{"op":"mcm","clk":"11450493150","pt":1717322671320,"mc":[{"id":"1.229554923","rc":[{"atb":[[16.5,9.84],[19,4.36],[23,2.38],[28,0.97]],"id":52671561}],"con":true,"img":false}]}
{"op":"mcm","clk":"11450493560","pt":1717322675745,"mc":[{"id":"1.229554923","rc":[{"atl":[[17,3.45]],"id":52671553}],"con":true,"img":false}]}
{"op":"mcm","clk":"11450493602","pt":1717322676119,"mc":[{"id":"1.229554923","rc":[{"atl":[[460,0],[470,2.98]],"id":52671563},{"atb":[[26,0],[28,3.91]],"id":52671562},{"atb":[[17,0],[18,3.91]],"id":52671561},{"atl":[[55,0],[60,3.06]],"id":52671561},{"atl":[[880,0],[910,4.24]],"id":52671554},{"atl":[[8,0],[8.2,3.88]],"id":52671550},{"atb":[[48,2.91],[50,0]],"id":52671552},{"atl":[[11,0],[11.5,4.55]],"id":52671547},{"atb":[[4.1,0]],"id":52671542}],"con":true,"img":false}]}
{"op":"mcm","clk":"11450493664","pt":1717322676845,"mc":[{"id":"1.229554923","rc":[{"atb":[[34,0],[22,0]],"id":52671563},{"atb":[[10.5,0],[15.5,0]],"id":52671562},{"atb":[[9.2,0],[13,8.72]],"id":52671565},{"atb":[[320,0],[420,0]],"id":52671564},{"atb":[[11,0],[8.4,0]],"id":52671561},{"atb":[[9.2,0],[13,0]],"id":52671560},{"atb":[[9.8,0],[7.8,0]],"id":52671555},{"atb":[[200,0],[100,0]],"id":52671554},{"atb":[[18,0],[13,0]],"id":52671556},{"atb":[[9.2,0],[13,0]],"id":52671551},{"atb":[[2.9,0],[3.25,0]],"id":52671550},{"atb":[[3.85,0],[4.7,0]],"id":52671553},{"atb":[[21,2.62],[15.5,7.21]],"id":52671552},{"atb":[[3.4,0],[3.9,0]],"id":52671547},{"atb":[[3.15,0],[3.65,0]],"id":52671546},{"atb":[[16,0],[11,0]],"id":52671549},{"atb":[[9,0],[7,0]],"id":52671548},{"atb":[[3.85,35.09],[4.7,0]],"id":52671543},{"atb":[[2.9,0],[3.25,0]],"id":52671542},{"atb":[[18,0],[13,0]],"id":52671545},{"atb":[[9.8,0],[7.8,0]],"id":52671544}],"con":true,"img":false}]}
{"op":"mcm","clk":"11450493856","pt":1717322678841,"mc":[{"id":"1.229554923","rc":[{"atb":[[4.1,5.06],[2.68,0]],"id":52671563},{"atb":[[170,3.46]],"id":52671564},{"atb":[[8,18.5],[7.6,3.55]],"id":52671556},{"atl":[[16,0],[15.5,4.04]],"id":52671553},{"atl":[[190,3.83],[200,0]],"id":52671552},{"atb":[[8,17.61],[7.6,2.9]],"id":52671549},{"atl":[[100,0],[110,2.85]],"id":52671549},{"atb":[[3.95,39.22],[4.1,5.06]],"id":52671548}],"con":true,"img":false}]}
{"op":"mcm","clk":"11450494011","pt":1717322680628,"mc":[{"id":"1.229554923","rc":[{"atb":[[3.9,5.4]],"id":52671542}],"con":true,"img":false}]}
{"op":"mcm","clk":"11450494416","pt":1717322685063,"mc":[{"id":"1.229554923","rc":[{"atl":[[470,0]],"id":52671563},{"atl":[[910,0],[950,4.67]],"id":52671554},{"atl":[[75,0],[80,3.94]],"id":52671551},{"atl":[[44,2.63]],"id":52671548},{"atl":[[8.2,3.44],[8.4,0]],"id":52671542}],"con":true,"img":false}]}
{"op":"mcm","clk":"11450494424","pt":1717322685164,"mc":[{"id":"1.229554923","rc":[{"atl":[[42,0]],"id":52671548}],"con":true,"img":false}]}
{"op":"mcm","clk":"11450494713","pt":1717322688875,"mc":[{"id":"1.229554923","rc":[{"atb":[[3.95,14.66]],"id":52671563},{"atl":[[500,4.6]],"id":52671563}],"con":true,"img":false}]}
{"op":"mcm","clk":"11450494738","pt":1717322689042,"mc":[{"id":"1.229554923","rc":[{"atb":[[38,2.82],[24,10.6]],"id":52671563},{"atb":[[10,27.1],[15,7.46]],"id":52671562},{"atb":[[9.2,29.74],[13,17.43]],"id":52671565},{"atb":[[310,0.78],[410,0.25]],"id":52671564},{"atb":[[10.5,11],[8.2,33.87]],"id":52671561},{"atb":[[9.2,29.74],[13,8.71]],"id":52671560},{"atb":[[8,34.84],[10,11.61]],"id":52671555},{"atb":[[130,4.58],[230,0.45]],"id":52671554},{"atb":[[18,6.14],[13,20.32]],"id":52671556},{"atb":[[13.5,12.55],[9.4,41.49]],"id":52671551},{"atb":[[2.9,128.37],[3.25,46.45]],"id":52671550},{"atb":[[3.85,85.58],[4.7,28.25]],"id":52671553},{"atb":[[21,7.84],[15.5,24.03]],"id":52671552},{"atb":[[3.85,36.67],[3.35,103.78]],"id":52671547},{"atb":[[3.15,113.44],[3.65,39.44]],"id":52671546},{"atb":[[16,6.96],[11,24.39]],"id":52671549},{"atb":[[7.2,39.33],[9.2,12.74]],"id":52671548},{"atb":[[3.85,120.67],[4.7,28.25]],"id":52671543},{"atb":[[2.9,128.37],[3.25,46.45]],"id":52671542},{"atb":[[18,6.14],[13,20.32]],"id":52671545},{"atb":[[8,34.84],[10,11.61]],"id":52671544}],"con":true,"img":false}]}
{"op":"mcm","clk":"11450494863","pt":1717322690684,"mc":[{"id":"1.229554923","rc":[{"atl":[[940,0]],"id":52671554},{"atb":[[48,0],[50,2.95]],"id":52671552},{"atb":[[4.9,0]],"id":52671546},{"atb":[[4,0],[4.1,5.06]],"id":52671542}],"con":true,"img":false}]}
{"op":"mcm","clk":"11450495223","pt":1717322695077,"mc":[{"id":"1.229554923","rc":[{"atl":[[970,3.6]],"id":52671554},{"atb":[[4.6,3.66]],"id":52671546}],"con":true,"img":false}]}
{"op":"mcm","clk":"11450495720","pt":1717322700680,"mc":[{"id":"1.229554923","rc":[{"atl":[[8.6,3]],"id":52671542}],"con":true,"img":false}]}
{"op":"mcm","clk":"11450496601","pt":1717322710428,"mc":[{"id":"1.229554923","rc":[{"atb":[[38,0],[24,0]],"id":52671563},{"atb":[[10,0],[15,0]],"id":52671562},{"atb":[[9.2,0],[13,8.72]],"id":52671565},{"atb":[[310,0],[410,0]],"id":52671564},{"atb":[[10.5,0],[8.2,0]],"id":52671561},{"atb":[[9.2,0],[13,0]],"id":52671560},{"atb":[[8,0],[10,0]],"id":52671555},{"atb":[[130,2.69],[230,0]],"id":52671554},{"atb":[[18,0],[13,0]],"id":52671556},{"atb":[[13.5,4.19],[9.4,12.46]],"id":52671551},{"atb":[[2.9,0],[3.25,0]],"id":52671550},{"atb":[[3.85,0],[4.7,0]],"id":52671553},{"atb":[[21,2.62],[15.5,7.21]],"id":52671552},{"atb":[[3.85,0],[3.35,0]],"id":52671547},{"atb":[[3.15,0],[3.65,0]],"id":52671546},{"atb":[[16,0],[11,0]],"id":52671549},{"atb":[[7.2,0],[9.2,0]],"id":52671548},{"atb":[[3.85,35.09],[4.7,0]],"id":52671543},{"atb":[[2.9,0],[3.25,0]],"id":52671542},{"atb":[[18,0],[13,0]],"id":52671545},{"atb":[[8,0],[10,0]],"id":52671544}],"con":true,"img":false}]}
{"op":"mcm","clk":"11450496622","pt":1717322710594,"mc":[{"id":"1.229554923","rc":[{"atl":[[9,0]],"id":52671542}],"con":true,"img":false}]}
{"op":"mcm","clk":"11450496723","pt":1717322711802,"mc":[{"id":"1.229554923","rc":[{"atb":[[2.64,0]],"id":52671563},{"atl":[[470,3.3],[480,0]],"id":52671563},{"atb":[[27,3.6],[28,0]],"id":52671562},{"atb":[[22,0]],"id":52671565},{"atb":[[160,4.54]],"id":52671564},{"atb":[[18,0],[18.5,4.24]],"id":52671561},{"atl":[[55,2.7],[60,0]],"id":52671561},{"atl":[[950,0],[930,4.42]],"id":52671554},{"atb":[[50,0]],"id":52671552},{"atb":[[5.7,14.43],[5.4,0]],"id":52671547},{"atb":[[4.8,0],[5,23.55]],"id":52671546},{"atb":[[4.5,4.61]],"id":52671542},{"atb":[[17,0],[18,3.67]],"id":52671544}],"con":true,"img":false}]}
{"op":"mcm","clk":"11450496729","pt":1717322711904,"mc":[{"id":"1.229554923","rc":[{"atb":[[170,0]],"id":52671564},{"atb":[[4.1,0]],"id":52671542}],"con":true,"img":false}]}
{"op":"mcm","clk":"11450497315","pt":1717322717923,"mc":[{"id":"1.229554923","rc":[{"atb":[[17.5,0],[18,4.69]],"id":52671555},{"atb":[[48,4.42]],"id":52671552},{"atb":[[5.4,4.6]],"id":52671547}],"con":true,"img":false}]}
{"op":"mcm","clk":"11450497325","pt":1717322718029,"mc":[{"id":"1.229554923","rc":[{"atb":[[27,0],[28,3.31]],"id":52671562},{"atb":[[22,3.75]],"id":52671565},{"atb":[[160,0],[170,4.14]],"id":52671564},{"atb":[[18.5,0],[18,3.29]],"id":52671561},{"atb":[[23,0],[24,4.41]],"id":52671551},{"atb":[[5.7,11.13]],"id":52671547},{"atb":[[4.8,2.97],[5,19.62]],"id":52671546},{"atb":[[4,5.23],[4.5,0]],"id":52671542}],"con":true,"img":false}]}
{"op":"mcm","clk":"11450497347","pt":1717322718238,"mc":[{"id":"1.229554923","rc":[{"atb":[[48,2.22],[29,8.71]],"id":52671563},{"atb":[[16,6.96],[11,24.39]],"id":52671562},{"atb":[[13.5,8.36],[9.4,29.03]],"id":52671565},{"atb":[[380,0.64],[480,0.21]],"id":52671564},{"atb":[[8.6,32.09],[11.5,9.95]],"id":52671561},{"atb":[[13.5,8.36],[9.4,29.03]],"id":52671560},{"atb":[[11,20.92],[8.4,32.96]],"id":52671555},{"atb":[[260,0.4],[160,1.53]],"id":52671554},{"atb":[[18,6.14],[13,20.32]],"id":52671556},{"atb":[[13.5,12.55],[9.4,41.49]],"id":52671551},{"atb":[[3.2,47.51],[2.88,129.73]],"id":52671550},{"atb":[[4.6,29.03],[3.8,87.1]],"id":52671553},{"atb":[[20,5.5],[15,17.42]],"id":52671552},{"atb":[[3.85,36.67],[3.35,103.78]],"id":52671547},{"atb":[[3.6,40.2],[3.1,116.14]],"id":52671546},{"atb":[[16,6.96],[11,24.39]],"id":52671549},{"atb":[[7.4,38.1],[9.4,12.44]],"id":52671548},{"atb":[[4.6,29.03],[3.8,87.1]],"id":52671543},{"atb":[[2.86,131.13],[3.15,48.61]],"id":52671542},{"atb":[[18,6.14],[13,20.32]],"id":52671545},{"atb":[[10.5,16.51],[8.2,48.41]],"id":52671544}],"con":true,"img":false}]}
{"op":"mcm","clk":"11450497532","pt":1717322720129,"mc":[{"id":"1.229554923","rc":[{"atb":[[27,3.97],[28,0]],"id":52671562},{"atb":[[22,0]],"id":52671565},{"atb":[[160,4.38],[170,0]],"id":52671564},{"atb":[[18,0],[18.5,2.72]],"id":52671561},{"atb":[[17.5,3.25],[18,0]],"id":52671555},{"atb":[[23,2.78],[24,0]],"id":52671551},{"atb":[[48,0]],"id":52671552},{"atb":[[5.7,15.45],[5.4,0]],"id":52671547},{"atb":[[4.8,0],[5,23.65]],"id":52671546},{"atb":[[4,0],[4.5,3.93]],"id":52671542}],"con":true,"img":false}]}
{"op":"mcm","clk":"11450497687","pt":1717322721808,"mc":[{"id":"1.229554923","rc":[{"atl":[[950,4.6]],"id":52671554}],"con":true,"img":false}]}
{"op":"mcm","clk":"11450498321","pt":1717322727953,"mc":[{"id":"1.229554923","rc":[{"atb":[[19,2.81]],"id":52671565},{"atb":[[42,3.69]],"id":52671552}],"con":true,"img":false}]}
{"op":"mcm","clk":"11450498469","pt":1717322729361,"mc":[{"id":"1.229554923","rc":[{"atb":[[27,0],[28,3.05]],"id":52671562},{"atb":[[20,0],[22,3.57]],"id":52671565},{"atb":[[170,2.88]],"id":52671564},{"atb":[[17.5,0],[18,3.87]],"id":52671555},{"atb":[[23,0],[24,4.16]],"id":52671551},{"atb":[[48,4.34]],"id":52671552},{"atb":[[5.7,11.13],[5.4,4.44]],"id":52671547},{"atb":[[4.8,4.55],[5,19.62]],"id":52671546},{"atb":[[4,5.23],[4.5,0]],"id":52671542}],"con":true,"img":false}]}
{"op":"mcm","clk":"11450498480","pt":1717322729466,"mc":[{"id":"1.229554923","rc":[{"atb":[[160,0]],"id":52671564},{"atb":[[18.5,0],[18,3.84]],"id":52671561},{"atl":[[970,0]],"id":52671554},{"atb":[[46,0]],"id":52671552}],"con":true,"img":false}]}
{"op":"mcm","clk":"11450498692","pt":1717322731454,"mc":[{"id":"1.229554923","rc":[{"atb":[[27,2.97],[28,0]],"id":52671562},{"atb":[[20,3.72],[22,0]],"id":52671565},{"atb":[[160,3.7],[170,0]],"id":52671564},{"atb":[[18,0],[18.5,2.94]],"id":52671561},{"atb":[[17.5,4.37],[18,0]],"id":52671555},{"atb":[[23,3.97],[24,0]],"id":52671551},{"atb":[[46,3.8],[48,0]],"id":52671552},{"atb":[[5.7,13.91],[5.4,0]],"id":52671547},{"atb":[[4.8,0],[5,24.05]],"id":52671546},{"atb":[[4,0],[4.5,3.46]],"id":52671542}],"con":true,"img":false}]}
{"op":"mcm","clk":"11450499091","pt":1717322735652,"mc":[{"id":"1.229554923","rc":[{"atb":[[27,0],[28,4.01]],"id":52671562},{"atb":[[20,0],[22,4.48]],"id":52671565},{"atb":[[160,0],[170,3]],"id":52671564},{"atb":[[18.5,0],[18,2.84]],"id":52671561},{"atb":[[17.5,0],[18,3.1]],"id":52671555},{"atb":[[23,0],[24,4.48]],"id":52671551},{"atb":[[46,0],[48,2.69]],"id":52671552},{"atb":[[5.7,11.13],[5.4,3.14]],"id":52671547},{"atb":[[4.8,2.68],[5,19.62]],"id":52671546},{"atb":[[4,5.23],[4.5,0]],"id":52671542}],"con":true,"img":false}]}
{"op":"mcm","clk":"11450499243","pt":1717322737375,"mc":[{"id":"1.229554923","rc":[{"atb":[[27,2.64],[28,0]],"id":52671562},{"atb":[[22,0]],"id":52671565},{"atb":[[160,3.16],[170,0]],"id":52671564},{"atb":[[18,0],[18.5,3.68]],"id":52671561},{"atb":[[17.5,4.14]],"id":52671555},{"atb":[[23,4.19],[24,0]],"id":52671551},{"atb":[[46,4.2],[48,0]],"id":52671552},{"atb":[[5.7,14.8],[5.4,0]],"id":52671547},{"atb":[[4.8,0],[5,22.89]],"id":52671546},{"atb":[[4,0],[4.5,4.49]],"id":52671542}],"con":true,"img":false}]}
{"op":"mcm","clk":"11450499258","pt":1717322737432,"mc":[{"id":"1.229554923","rc":[{"atb":[[20,2.67]],"id":52671565}],"con":true,"img":false}]}
{"op":"mcm","clk":"11450499270","pt":1717322737537,"mc":[{"id":"1.229554923","rc":[{"atb":[[18,0]],"id":52671555}],"con":true,"img":false}]}
{"op":"mcm","clk":"11450499411","pt":1717322739057,"mc":[{"id":"1.229554923","rc":[{"atl":[[470,0],[480,2.83]],"id":52671563},{"atb":[[20,0],[21,4.18]],"id":52671565},{"atb":[[18.5,0],[18,3.95]],"id":52671561},{"atb":[[21,3.92],[22,4.11]],"id":52671560},{"atl":[[930,0],[940,4.15]],"id":52671554},{"atb":[[23,0],[24,3.36]],"id":52671551},{"atl":[[8,4.49],[8.2,0]],"id":52671550},{"atb":[[5.6,3.58],[5.7,11.13]],"id":52671547},{"atb":[[4.5,0],[4.4,3.31]],"id":52671542},{"atb":[[18,0],[18.5,3.06]],"id":52671544}],"con":true,"img":false}]}
{"op":"mcm","clk":"11450499495","pt":1717322740046,"mc":[{"id":"1.229554923","rc":[{"atb":[[27,0],[28,4.22]],"id":52671562},{"atb":[[21,1.31],[22,3]],"id":52671565},{"atb":[[160,0],[170,3.92]],"id":52671564},{"atb":[[21,7],[22,0]],"id":52671560},{"atb":[[17.5,0],[18,3.06]],"id":52671555},{"atb":[[46,0],[48,2.81]],"id":52671552},{"atb":[[5.6,0],[5.4,3.77]],"id":52671547},{"atb":[[4.8,3.08],[5,19.62]],"id":52671546},{"atb":[[4,5.23],[4.4,0]],"id":52671542},{"atb":[[18.5,0],[18,4.34]],"id":52671544}],"con":true,"img":false}]}
{"op":"mcm","clk":"11450499548","pt":1717322740564,"mc":[{"id":"1.229554923","rc":[{"atb":[[48,0],[29,0]],"id":52671563},{"atb":[[16,0],[11,0]],"id":52671562},{"atb":[[13.5,0],[9.4,0]],"id":52671565},{"atb":[[380,0],[480,0]],"id":52671564},{"atb":[[8.6,0],[11.5,0]],"id":52671561},{"atb":[[13.5,0],[9.4,0]],"id":52671560},{"atb":[[11,10.46],[8.4,0]],"id":52671555},{"atb":[[260,0],[160,0]],"id":52671554},{"atb":[[18,0],[13,0]],"id":52671556},{"atb":[[13.5,4.19],[9.4,12.46]],"id":52671551},{"atb":[[3.2,0],[2.88,0]],"id":52671550},{"atb":[[4.6,0],[3.8,0]],"id":52671553},{"atb":[[20,0],[15,0]],"id":52671552},{"atb":[[3.85,0],[3.35,0]],"id":52671547},{"atb":[[3.6,0],[3.1,0]],"id":52671546},{"atb":[[16,0],[11,0]],"id":52671549},{"atb":[[7.4,0],[9.4,0]],"id":52671548},{"atb":[[4.6,0],[3.8,0]],"id":52671543},{"atb":[[2.86,0],[3.15,0]],"id":52671542},{"atb":[[18,0],[13,0]],"id":52671545},{"atb":[[10.5,5.51],[8.2,14.53]],"id":52671544}],"con":true,"img":false}]}
{"op":"mcm","clk":"11450499761","pt":1717322742881,"mc":[{"id":"1.229554923","rc":[{"atb":[[27,3.81],[28,0]],"id":52671562},{"atb":[[21,5.72],[22,0]],"id":52671565},{"atb":[[160,3.5],[170,0]],"id":52671564},{"atb":[[21,3.92],[22,3.91]],"id":52671560},{"atb":[[17.5,3.55],[18,0]],"id":52671555},{"atb":[[46,3.15],[48,0]],"id":52671552},{"atb":[[5.6,2.94],[5.4,0]],"id":52671547},{"atb":[[4.8,0],[5,24.24]],"id":52671546},{"atb":[[4,0],[4.4,3.31]],"id":52671542},{"atb":[[18,0],[18.5,4.31]],"id":52671544}],"con":true,"img":false}]}
{"op":"mcm","clk":"11450500071","pt":1717322745952,"mc":[{"id":"1.229554923","rc":[{"atb":[[150,0],[160,0],[80,4.22]],"id":52671564},{"atb":[[130,0],[150,0],[60,4.67]],"id":52671554},{"atb":[[42,0],[21,6.47],[46,0]],"id":52671552},{"atl":[[10,0],[11,4.59]],"id":52671546},{"atl":[[8.6,0],[9.2,4.35],[8.2,0]],"id":52671542},{"atb":[[34,0],[30,0]],"id":52671545}],"con":true,"img":false}]}
{"op":"mcm","clk":"11450500080","pt":1717322746055,"mc":[{"id":"1.229554923","rc":[{"atb":[[26,5.05]],"id":52671552}],"con":true,"img":false}]}
{"op":"mcm","clk":"11450500092","pt":1717322746155,"mc":[{"id":"1.229554923","rc":[{"atb":[[30,0]],"id":52671552}],"con":true,"img":false}]}
{"op":"mcm","clk":"11450500384","pt":1717322749564,"mc":[{"id":"1.229554923","rc":[{"atb":[[27,0],[28,3.23]],"id":52671562},{"atb":[[170,3.48]],"id":52671564},{"atb":[[18,0],[18.5,2.64]],"id":52671561},{"atb":[[21,7.26],[22,0]],"id":52671560},{"atb":[[17.5,0],[18,2.71]],"id":52671555},{"atb":[[150,2.73]],"id":52671554},{"atb":[[48,2.9]],"id":52671552},{"atb":[[4.8,4.27],[5,19.62]],"id":52671546},{"atl":[[10,2.81],[11,0]],"id":52671546},{"atb":[[4.4,0],[4.2,21.26]],"id":52671542},{"atl":[[8.2,4.19]],"id":52671542},{"atb":[[32,2.67],[29,3.32]],"id":52671545},{"atb":[[18.5,0],[18,3.5]],"id":52671544}],"con":true,"img":false}]}
{"op":"mcm","clk":"11450500392","pt":1717322749671,"mc":[{"id":"1.229554923","rc":[{"atb":[[30,3.45]],"id":52671552}],"con":true,"img":false}]}
{"op":"mcm","clk":"11450500402","pt":1717322749776,"mc":[{"id":"1.229554923","rc":[{"atb":[[26,1.05]],"id":52671552}],"con":true,"img":false}]}
{"op":"mcm","clk":"11450500422","pt":1717322749992,"mc":[{"id":"1.229554923","rc":[{"atb":[[48,2.22],[29,8.71]],"id":52671563},{"atb":[[16,6.96],[11,24.39]],"id":52671562},{"atb":[[13.5,8.36],[9.4,29.03]],"id":52671565},{"atb":[[380,0.64],[480,0.21]],"id":52671564},{"atb":[[8.6,32.09],[11.5,9.95]],"id":52671561},{"atb":[[13.5,8.36],[9.4,29.03]],"id":52671560},{"atb":[[11,20.92],[8.4,32.96]],"id":52671555},{"atb":[[260,0.4],[160,1.53]],"id":52671554},{"atb":[[18,6.14],[13,20.32]],"id":52671556},{"atb":[[13.5,12.55],[9.4,41.49]],"id":52671551},{"atb":[[3.2,47.51],[2.88,129.73]],"id":52671550},{"atb":[[4.6,29.03],[3.8,87.1]],"id":52671553},{"atb":[[20,5.5],[15,17.42]],"id":52671552},{"atb":[[3.85,36.67],[3.35,103.78]],"id":52671547},{"atb":[[3.6,40.2],[3.1,116.14]],"id":52671546},{"atb":[[16,6.96],[11,24.39]],"id":52671549},{"atb":[[7.4,38.1],[9.4,12.44]],"id":52671548},{"atb":[[4.6,29.03],[3.8,87.1]],"id":52671543},{"atb":[[2.86,131.13],[3.15,48.61]],"id":52671542},{"atb":[[18,6.14],[13,20.32]],"id":52671545},{"atb":[[10.5,16.51],[8.2,48.41]],"id":52671544}],"con":true,"img":false}]}
{"op":"mcm","clk":"11450500675","pt":1717322752852,"mc":[{"id":"1.229554923","rc":[{"atb":[[5.4,4.16]],"id":52671547}],"con":true,"img":false}]}
{"op":"mcm","clk":"11450501276","pt":1717322759598,"mc":[{"id":"1.229554923","rc":[{"atb":[[150,4.01]],"id":52671564},{"atb":[[17.5,3.34]],"id":52671561},{"atb":[[130,3.77]],"id":52671554},{"atb":[[44,3.65]],"id":52671552},{"atb":[[4,5.23]],"id":52671542},{"atl":[[8.6,3.08]],"id":52671542}],"con":true,"img":false}]}
{"op":"mcm","clk":"11450501287","pt":1717322759700,"mc":[{"id":"1.229554923","rc":[{"atb":[[3.65,0]],"id":52671550},{"atb":[[6.4,0]],"id":52671547}],"con":true,"img":false}]}
{"op":"mcm","clk":"11450501296","pt":1717322759805,"mc":[{"id":"1.229554923","rc":[{"atb":[[4.8,0],[4.3,0]],"id":52671550},{"atb":[[5.2,2.73],[5.7,0],[4.7,0]],"id":52671547}],"con":true,"img":false}]}
{"op":"mcm","clk":"11450501309","pt":1717322759909,"mc":[{"id":"1.229554923","rc":[{"atb":[[28,0],[29,3.07]],"id":52671562},{"atb":[[21,1.31],[23,4.29]],"id":52671565},{"atb":[[18.5,0],[19.5,3.46]],"id":52671561},{"atb":[[21,3.92],[23,4.38]],"id":52671560},{"atb":[[5.6,0]],"id":52671547},{"atb":[[4.2,16.35]],"id":52671542},{"atb":[[32,0]],"id":52671545}],"con":true,"img":false}]}
{"op":"mcm","clk":"11450501318","pt":1717322759992,"mc":[{"id":"1.229554923","rc":[{"atb":[[34,3.46]],"id":52671545}],"con":true,"img":false}]}
{"op":"mcm","clk":"11450501330","pt":1717322760069,"mc":[{"id":"1.229554923","rc":[{"atl":[[940,0],[960,4.19]],"id":52671554},{"atl":[[10,0],[9.8,3.52]],"id":52671546},{"atl":[[13.5,3.21],[14,0]],"id":52671543},{"atl":[[8,4.44],[8.2,0]],"id":52671542}],"con":true,"img":false}]}
{"op":"mcm","clk":"11450501352","pt":1717322760381,"mc":[{"id":"1.229554923","rc":[{"atb":[[3.6,40.24]],"id":52671550},{"atb":[[6.4,4.84]],"id":52671547}],"con":true,"img":false}]}
{"op":"mcm","clk":"11450501366","pt":1717322760500,"mc":[{"id":"1.229554923","rc":[{"atb":[[4.2,16.35],[4.7,7.07]],"id":52671550},{"atb":[[5.2,21.42],[5.7,11.13],[4.7,28.28]],"id":52671547}],"con":true,"img":false}]}
{"op":"mcm","clk":"11450501382","pt":1717322760705,"mc":[{"id":"1.229554923","rc":[{"atb":[[80,0]],"id":52671564},{"atb":[[16.5,6.75]],"id":52671561},{"atb":[[60,0]],"id":52671554},{"atb":[[21,2.62]],"id":52671552},{"atl":[[8.6,0],[9.2,0]],"id":52671542}],"con":true,"img":false}]}
{"op":"mcm","clk":"11450501699","pt":1717322763588,"mc":[{"id":"1.229554923","rc":[{"atb":[[28,2.88],[29,0]],"id":52671562},{"atb":[[21,4.4],[23,0]],"id":52671565},{"atb":[[18.5,4.39],[19.5,0]],"id":52671561},{"atb":[[21,6.68],[23,0]],"id":52671560},{"atb":[[5.6,4.24],[5.4,0]],"id":52671547},{"atb":[[4,0],[4.2,21.26]],"id":52671542},{"atb":[[32,4.12],[34,0]],"id":52671545}],"con":true,"img":false}]}
{"op":"mcm","clk":"11450501708","pt":1717322763692,"mc":[{"id":"1.229554923","rc":[{"atl":[[950,0]],"id":52671554}],"con":true,"img":false}]}
{"op":"mcm","clk":"11450501785","pt":1717322764375,"mc":[{"id":"1.229554923","rc":[{"atb":[[27,3.54],[28,0]],"id":52671562},{"atl":[[8,0],[8.2,3.9]],"id":52671550},{"atb":[[6.4,0]],"id":52671553},{"atb":[[5.6,0],[5.5,2.75]],"id":52671547},{"atb":[[4.8,0],[4.9,3.93]],"id":52671546},{"atl":[[10,4.34],[9.8,0]],"id":52671546},{"atl":[[13.5,0],[14,2.96]],"id":52671543},{"atl":[[8,0],[8.4,3.97]],"id":52671542}],"con":true,"img":false}]}
{"op":"mcm","clk":"11450501925","pt":1717322765678,"mc":[{"id":"1.229554923","rc":[{"atb":[[27,0],[28,2.87]],"id":52671562},{"atb":[[21,1.31],[22,4.17]],"id":52671565},{"atb":[[18.5,0],[18,2.84]],"id":52671561},{"atb":[[6.4,4.03]],"id":52671553},{"atb":[[5.5,0],[5.4,4.26]],"id":52671547},{"atb":[[4.8,2.91],[4.9,0]],"id":52671546},{"atb":[[4,5.23],[4.2,16.35]],"id":52671542},{"atb":[[32,0],[34,3.18]],"id":52671545}],"con":true,"img":false}]}
{"op":"mcm","clk":"11450502196","pt":1717322768711,"mc":[{"id":"1.229554923","rc":[{"atb":[[27,4.33]],"id":52671562},{"atb":[[21,4.89],[22,0]],"id":52671565},{"atb":[[18,0],[18.5,4.41]],"id":52671561},{"atb":[[6.4,0]],"id":52671553},{"atb":[[5.5,3.89],[5.4,0]],"id":52671547},{"atb":[[4.8,0],[4.9,2.99]],"id":52671546},{"atb":[[4,0],[4.2,21.26]],"id":52671542},{"atb":[[32,4.52],[34,0]],"id":52671545}],"con":true,"img":false}]}
{"op":"mcm","clk":"11450502205","pt":1717322768813,"mc":[{"id":"1.229554923","rc":[{"atb":[[28,0]],"id":52671562}],"con":true,"img":false}]}
{"op":"mcm","clk":"11450502896","pt":1717322775713,"mc":[{"id":"1.229554923","rc":[{"atb":[[5.9,3.97]],"id":52671553}],"con":true,"img":false}]}
{"op":"mcm","clk":"11450503026","pt":1717322777028,"mc":[{"id":"1.229554923","rc":[{"atb":[[28,4.07]],"id":52671562},{"atb":[[22,4.65]],"id":52671565},{"atb":[[6.2,0]],"id":52671553},{"atb":[[5.5,0],[5.4,3.47]],"id":52671547},{"atb":[[4.8,3.05],[4.9,0]],"id":52671546},{"atb":[[34,4.25]],"id":52671545}],"con":true,"img":false}]}
{"op":"mcm","clk":"11450503033","pt":1717322777123,"mc":[{"id":"1.229554923","rc":[{"atb":[[27,0]],"id":52671562},{"atb":[[21,1.31]],"id":52671565},{"atb":[[18.5,0],[18,4.43]],"id":52671561},{"atb":[[6.4,3.22]],"id":52671553},{"atb":[[4,5.23],[4.2,16.35]],"id":52671542},{"atb":[[32,0]],"id":52671545}],"con":true,"img":false}]}
{"op":"mcm","clk":"11450503271","pt":1717322779920,"mc":[{"id":"1.229554923","rc":[{"atb":[[27,2.74],[28,0]],"id":52671562},{"atb":[[21,5.68],[22,0]],"id":52671565},{"atb":[[18,0],[18.5,3.96]],"id":52671561},{"atb":[[6.4,0],[6.2,4.6]],"id":52671553},{"atb":[[5.5,3.65],[5.4,0]],"id":52671547},{"atb":[[4.8,0],[4.9,4.47]],"id":52671546},{"atb":[[4,0],[4.2,21.26]],"id":52671542},{"atb":[[32,4.27]],"id":52671545}],"con":true,"img":false}]}
{"op":"mcm","clk":"11450503284","pt":1717322780018,"mc":[{"id":"1.229554923","rc":[{"atb":[[34,0]],"id":52671545}],"con":true,"img":false}]}
{"op":"mcm","clk":"11450504090","pt":1717322788429,"mc":[{"id":"1.229554923","rc":[{"atb":[[27,0],[28,2.87]],"id":52671562},{"atb":[[22,3.6]],"id":52671565},{"atb":[[18.5,0],[18,3.92]],"id":52671561},{"atb":[[6.4,3.31],[6.2,0]],"id":52671553},{"atb":[[5.5,0],[5.4,4.57]],"id":52671547},{"atb":[[4.8,3.98],[4.9,0]],"id":52671546},{"atb":[[4,5.23],[4.2,16.35]],"id":52671542},{"atb":[[32,0],[34,4.55]],"id":52671545}],"con":true,"img":false}]}
{"op":"mcm","clk":"11450504102","pt":1717322788526,"mc":[{"id":"1.229554923","rc":[{"atb":[[21,1.31]],"id":52671565}],"con":true,"img":false}]}
{"op":"mcm","clk":"11450504364","pt":1717322791355,"mc":[{"id":"1.229554923","rc":[{"atb":[[27,4.28],[28,0]],"id":52671562},{"atb":[[21,4.35]],"id":52671565},{"atb":[[18,0],[18.5,3.23]],"id":52671561},{"atb":[[6.4,0]],"id":52671553},{"atb":[[5.5,2.72],[5.4,0]],"id":52671547},{"atb":[[4.8,0],[4.9,3.81]],"id":52671546},{"atb":[[4.2,21.26]],"id":52671542},{"atb":[[32,4.67]],"id":52671545}],"con":true,"img":false}]}
{"op":"mcm","clk":"11450504374","pt":1717322791419,"mc":[{"id":"1.229554923","rc":[{"atb":[[22,0]],"id":52671565},{"atb":[[6.2,3.7]],"id":52671553},{"atb":[[4,0]],"id":52671542},{"atb":[[34,0]],"id":52671545}],"con":true,"img":false}]}
{"op":"mcm","clk":"11450505048","pt":1717322798551,"mc":[{"id":"1.229554923","rc":[{"atb":[[4.1,0],[3.75,36.36]],"id":52671553},{"atl":[[740,0],[800,2]],"id":52671552},{"atl":[[560,2],[500,0]],"id":52671549},{"atb":[[3.85,0],[3.55,39.22]],"id":52671543},{"atl":[[590,0],[650,2]],"id":52671545}],"con":true,"img":false}]}
{"op":"mcm","clk":"11450505157","pt":1717322799745,"mc":[{"id":"1.229554923","rc":[{"atb":[[4.8,4.39]],"id":52671546}],"con":true,"img":false}]}
{"op":"mcm","clk":"11450505166","pt":1717322799859,"mc":[{"id":"1.229554923","rc":[{"atb":[[28,3.68]],"id":52671562},{"atb":[[22,4.47]],"id":52671565},{"atb":[[18.5,0],[18,3.52]],"id":52671561},{"atb":[[6.4,4.7]],"id":52671553},{"atb":[[5.5,0],[5.4,3.63]],"id":52671547},{"atb":[[4.9,0]],"id":52671546},{"atb":[[4,5.23],[4.2,16.35]],"id":52671542},{"atb":[[32,0],[34,4.01]],"id":52671545}],"con":true,"img":false}]}
{"op":"mcm","clk":"11450505174","pt":1717322799953,"mc":[{"id":"1.229554923","rc":[{"atb":[[27,0]],"id":52671562},{"atb":[[21,1.31]],"id":52671565},{"atb":[[6.2,0]],"id":52671553}],"con":true,"img":false}]}
{"op":"mcm","clk":"11450505440","pt":1717322802853,"mc":[{"id":"1.229554923","rc":[{"atb":[[27,3.9],[28,0]],"id":52671562},{"atb":[[21,5.37],[22,0]],"id":52671565},{"atb":[[18,0],[18.5,2.98]],"id":52671561},{"atb":[[6.4,0],[6.2,3.19]],"id":52671553},{"atb":[[5.5,3.77],[5.4,0]],"id":52671547},{"atb":[[4.8,0],[4.9,4.68]],"id":52671546},{"atb":[[4,0],[4.2,21.26]],"id":52671542},{"atb":[[32,4.54],[34,0]],"id":52671545}],"con":true,"img":false}]}
{"op":"mcm","clk":"11450506191","pt":1717322811253,"mc":[{"id":"1.229554923","rc":[{"atb":[[28,4.26]],"id":52671562},{"atb":[[21,1.31],[22,2.69]],"id":52671565},{"atb":[[18.5,0],[18,3.57]],"id":52671561},{"atb":[[6.4,2.8],[6.2,0]],"id":52671553},{"atb":[[5.5,0],[5.4,3.78]],"id":52671547},{"atb":[[4.8,4.16],[4.9,0]],"id":52671546},{"atb":[[4,5.23],[4.2,16.35]],"id":52671542},{"atb":[[32,0],[34,3.76]],"id":52671545}],"con":true,"img":false}]}
{"op":"mcm","clk":"11450506207","pt":1717322811356,"mc":[{"id":"1.229554923","rc":[{"atb":[[27,0]],"id":52671562}],"con":true,"img":false}]}
{"op":"mcm","clk":"11450506432","pt":1717322814065,"mc":[{"id":"1.229554923","rc":[{"atb":[[27,4.54],[28,0]],"id":52671562},{"atb":[[21,4.97]],"id":52671565},{"atb":[[6.4,0]],"id":52671553},{"atb":[[5.5,2.84],[5.4,0]],"id":52671547},{"atb":[[4.9,4.08]],"id":52671546}],"con":true,"img":false}]}
{"op":"mcm","clk":"11450506439","pt":1717322814174,"mc":[{"id":"1.229554923","rc":[{"atb":[[22,0]],"id":52671565},{"atb":[[18.5,2.88]],"id":52671561},{"atb":[[6.2,3.18]],"id":52671553},{"atb":[[4.8,0]],"id":52671546},{"atb":[[4,0],[4.2,21.26]],"id":52671542},{"atb":[[32,4.68]],"id":52671545}],"con":true,"img":false}]}
{"op":"mcm","clk":"11450506449","pt":1717322814300,"mc":[{"id":"1.229554923","rc":[{"atb":[[18,0]],"id":52671561},{"atb":[[34,0]],"id":52671545}],"con":true,"img":false}]}
{"op":"mcm","clk":"11450507182","pt":1717322822786,"mc":[{"id":"1.229554923","rc":[{"atb":[[27,0],[28,3.52]],"id":52671562},{"atb":[[21,1.31],[22,2.94]],"id":52671565},{"atb":[[18.5,0],[18,3.85]],"id":52671561},{"atb":[[6.4,2.95],[6.2,0]],"id":52671553},{"atb":[[5.5,0],[5.4,3.92]],"id":52671547},{"atb":[[4.8,3.1],[4.9,0]],"id":52671546},{"atb":[[4,5.23],[4.2,16.35]],"id":52671542},{"atb":[[32,0],[34,3.6]],"id":52671545}],"con":true,"img":false}]}
{"op":"mcm","clk":"11450507472","pt":1717322825587,"mc":[{"id":"1.229554923","rc":[{"atb":[[27,3.58],[28,0]],"id":52671562},{"atb":[[21,4.55],[22,0]],"id":52671565},{"atb":[[18,0],[18.5,2.79]],"id":52671561},{"atb":[[6.4,0],[6.2,3.77]],"id":52671553},{"atb":[[5.5,2.63],[5.4,0]],"id":52671547},{"atb":[[4.8,0],[4.9,4.02]],"id":52671546},{"atb":[[4,0],[4.2,21.26]],"id":52671542},{"atb":[[32,3.62],[34,0]],"id":52671545}],"con":true,"img":false}]}
{"op":"mcm","clk":"11450508250","pt":1717322834105,"mc":[{"id":"1.229554923","rc":[{"atb":[[27,0],[28,3.63]],"id":52671562},{"atb":[[21,1.31],[22,3.88]],"id":52671565},{"atb":[[18.5,0],[18,4.41]],"id":52671561},{"atb":[[6.4,2.8],[6.2,0]],"id":52671553},{"atb":[[5.5,0],[5.4,2.94]],"id":52671547},{"atb":[[4.8,2.96],[4.9,0]],"id":52671546},{"atb":[[4,5.23],[4.2,16.35]],"id":52671542},{"atb":[[32,0],[34,4.65]],"id":52671545}],"con":true,"img":false}]}
{"op":"mcm","clk":"11450508590","pt":1717322837080,"mc":[{"id":"1.229554923","rc":[{"atb":[[27,2.95],[28,0]],"id":52671562},{"atb":[[21,5.34],[22,0]],"id":52671565},{"atb":[[18,0],[18.5,4.2]],"id":52671561},{"atb":[[6.4,0],[6.2,3.3]],"id":52671553},{"atb":[[5.5,3.45],[5.4,0]],"id":52671547},{"atb":[[4.8,0],[4.9,3]],"id":52671546},{"atb":[[4,0],[4.2,21.26]],"id":52671542},{"atb":[[32,2.68],[34,0]],"id":52671545}],"con":true,"img":false}]}
{"op":"mcm","clk":"11450509357","pt":1717322845517,"mc":[{"id":"1.229554923","rc":[{"atb":[[27,0],[28,3.33]],"id":52671562},{"atb":[[21,1.31],[22,3.93]],"id":52671565},{"atb":[[18.5,0],[18,3.54]],"id":52671561},{"atb":[[6.4,4.54],[6.2,0]],"id":52671553},{"atb":[[5.5,0],[5.4,4.1]],"id":52671547},{"atb":[[4.8,4],[4.9,0]],"id":52671546},{"atb":[[4,5.23],[4.2,16.35]],"id":52671542},{"atb":[[32,0],[34,3.13]],"id":52671545}],"con":true,"img":false}]}
{"op":"mcm","clk":"11450509581","pt":1717322848295,"mc":[{"id":"1.229554923","rc":[{"atb":[[27,4.38],[28,0]],"id":52671562},{"atb":[[21,4.03],[22,0]],"id":52671565},{"atb":[[18,0],[18.5,3.1]],"id":52671561},{"atb":[[6.4,0],[6.2,4.19]],"id":52671553},{"atb":[[5.5,3.04],[5.4,0]],"id":52671547},{"atb":[[4.8,0],[4.9,3.79]],"id":52671546},{"atb":[[4,0],[4.2,21.26]],"id":52671542},{"atb":[[34,0]],"id":52671545}],"con":true,"img":false}]}
{"op":"mcm","clk":"11450509591","pt":1717322848388,"mc":[{"id":"1.229554923","rc":[{"atb":[[32,3.12]],"id":52671545}],"con":true,"img":false}]}
{"op":"mcm","clk":"11450510395","pt":1717322857003,"mc":[{"id":"1.229554923","rc":[{"atb":[[27,0],[28,4.55]],"id":52671562},{"atb":[[21,1.31],[22,4.54]],"id":52671565},{"atb":[[18.5,0],[18,3.68]],"id":52671561},{"atb":[[6.4,3.23],[6.2,0]],"id":52671553},{"atb":[[5.5,0],[5.4,3.9]],"id":52671547},{"atb":[[4.8,3.21],[4.9,0]],"id":52671546},{"atb":[[4,5.23],[4.2,16.35]],"id":52671542},{"atb":[[32,0],[34,3.58]],"id":52671545}],"con":true,"img":false}]}
{"op":"mcm","clk":"11450510659","pt":1717322859792,"mc":[{"id":"1.229554923","rc":[{"atb":[[27,3.71],[28,0]],"id":52671562},{"atb":[[21,4.07],[22,0]],"id":52671565},{"atb":[[18,0],[18.5,2.88]],"id":52671561},{"atb":[[6.4,0],[6.2,4.23]],"id":52671553},{"atb":[[5.5,4.12],[5.4,0]],"id":52671547},{"atb":[[4.8,0],[4.9,4.48]],"id":52671546},{"atb":[[4,0],[4.2,21.26]],"id":52671542},{"atb":[[32,3.69],[34,0]],"id":52671545}],"con":true,"img":false}]}
{"op":"mcm","clk":"11450511697","pt":1717322869888,"mc":[{"id":"1.229554923","rc":[{"atb":[[4,5.23]],"id":52671542},{"atl":[[8.8,4.52]],"id":52671542}],"con":true,"img":false}]}
{"op":"mcm","clk":"11450512166","pt":1717322874182,"mc":[{"id":"1.229554923","rc":[{"atb":[[3.6,0],[4.2,0],[4.7,0]],"id":52671550},{"atb":[[6.4,0],[5.2,2.73],[5.7,0],[4.7,0]],"id":52671547}],"con":true,"img":false}]}
{"op":"mcm","clk":"11450512244","pt":1717322874904,"mc":[{"id":"1.229554923","rc":[{"atb":[[3.7,38.75],[4.9,6.71],[4.4,15.39]],"id":52671550},{"atb":[[4.8,27.54],[5.8,10.9],[5.3,18.25],[6.6,4.67]],"id":52671547}],"con":true,"img":false}]}
{"op":"mcm","clk":"11450512379","pt":1717322876096,"mc":[{"id":"1.229554923","rc":[{"atb":[[3.9,0]],"id":52671542}],"con":true,"img":false}]}
{"op":"mcm","clk":"11450516023","pt":1717322910065,"mc":[{"id":"1.229554923","rc":[{"atb":[[27,0],[28,3]],"id":52671562},{"atb":[[21,1.31],[22,4.15]],"id":52671565},{"atb":[[18.5,0],[18,3.47]],"id":52671561},{"atb":[[6.4,4.6],[6.2,0]],"id":52671553},{"atb":[[5.5,0],[5.4,3.86]],"id":52671547},{"atb":[[4.8,2.87],[4.9,0]],"id":52671546},{"atb":[[4.2,16.35]],"id":52671542},{"atb":[[32,0],[34,4.57]],"id":52671545}],"con":true,"img":false}]}
{"op":"mcm","clk":"11450516239","pt":1717322911848,"mc":[{"id":"1.229554923","rc":[{"atb":[[18.5,4.16]],"id":52671561}],"con":true,"img":false}]}
{"op":"mcm","clk":"11450516249","pt":1717322911952,"mc":[{"id":"1.229554923","rc":[{"atb":[[27,3.64],[28,0]],"id":52671562},{"atb":[[21,5.54],[22,0]],"id":52671565},{"atb":[[18,0]],"id":52671561},{"atb":[[6.4,0],[6.2,4.49]],"id":52671553},{"atb":[[5.5,3.4],[5.4,0]],"id":52671547},{"atb":[[4.8,0],[4.9,3.76]],"id":52671546},{"atb":[[4.2,21.26]],"id":52671542},{"atb":[[32,2.64],[34,0]],"id":52671545}],"con":true,"img":false}]}
{"op":"mcm","clk":"11450516777","pt":1717322916647,"mc":[{"id":"1.229554923","rc":[{"atb":[[5.4,2.92]],"id":52671547},{"atb":[[4.8,3.1]],"id":52671546}],"con":true,"img":false}]}
{"op":"mcm","clk":"11450516785","pt":1717322916748,"mc":[{"id":"1.229554923","rc":[{"atb":[[27,0],[28,3.85]],"id":52671562},{"atb":[[21,1.31],[22,3.49]],"id":52671565},{"atb":[[18.5,0],[18,4.13]],"id":52671561},{"atb":[[6.4,4.41],[6.2,0]],"id":52671553},{"atb":[[5.5,0]],"id":52671547},{"atb":[[4.9,0]],"id":52671546},{"atb":[[4.2,16.35]],"id":52671542},{"atb":[[32,0],[34,3.75]],"id":52671545}],"con":true,"img":false}]}
{"op":"mcm","clk":"11450517078","pt":1717322919774,"mc":[{"id":"1.229554923","rc":[{"atb":[[28,0]],"id":52671562},{"atb":[[21,5.46],[22,0]],"id":52671565},{"atb":[[18,0],[18.5,3.31]],"id":52671561},{"atb":[[6.4,0],[6.2,3.6]],"id":52671553},{"atb":[[5.5,3.55],[5.4,0]],"id":52671547},{"atb":[[4.8,0]],"id":52671546},{"atb":[[4.2,21.26]],"id":52671542},{"atb":[[34,0]],"id":52671545}],"con":true,"img":false}]}
{"op":"mcm","clk":"11450517088","pt":1717322919841,"mc":[{"id":"1.229554923","rc":[{"atb":[[27,4.5]],"id":52671562},{"atb":[[4.9,3.56]],"id":52671546},{"atb":[[32,4.42]],"id":52671545}],"con":true,"img":false}]}
{"op":"mcm","clk":"11450517252","pt":1717322921345,"mc":[{"id":"1.229554923","rc":[{"atb":[[27,0],[28,3.39]],"id":52671562},{"atb":[[21,1.31],[22,3.96]],"id":52671565},{"atb":[[18,3.97]],"id":52671561},{"atb":[[6.4,4.64],[6.2,0]],"id":52671553},{"atb":[[5.5,0],[5.4,3.15]],"id":52671547},{"atb":[[4.8,3.76],[4.9,0]],"id":52671546},{"atb":[[4.2,16.35]],"id":52671542},{"atb":[[32,0],[34,4.09]],"id":52671545}],"con":true,"img":false}]}
{"op":"mcm","clk":"11450517265","pt":1717322921459,"mc":[{"id":"1.229554923","rc":[{"atb":[[18.5,0]],"id":52671561}],"con":true,"img":false}]}
{"op":"mcm","clk":"11450517474","pt":1717322923284,"mc":[{"id":"1.229554923","rc":[{"atb":[[27,3.96],[28,0]],"id":52671562},{"atb":[[21,5.37],[22,0]],"id":52671565},{"atb":[[18,0],[18.5,4.4]],"id":52671561},{"atb":[[6.2,4.07]],"id":52671553},{"atb":[[5.5,3.84],[5.4,0]],"id":52671547},{"atb":[[4.9,3.42]],"id":52671546},{"atb":[[4.2,21.26]],"id":52671542},{"atb":[[32,4.21]],"id":52671545}],"con":true,"img":false}]}
{"op":"mcm","clk":"11450517485","pt":1717322923345,"mc":[{"id":"1.229554923","rc":[{"atb":[[6.4,0]],"id":52671553},{"atb":[[4.8,0]],"id":52671546}],"con":true,"img":false}]}
{"op":"mcm","clk":"11450517498","pt":1717322923450,"mc":[{"id":"1.229554923","rc":[{"atb":[[34,0]],"id":52671545}],"con":true,"img":false}]}
{"op":"mcm","clk":"11450518023","pt":1717322928070,"mc":[{"id":"1.229554923","rc":[{"atb":[[27,0],[28,3.32]],"id":52671562},{"atb":[[21,1.31],[22,3.35]],"id":52671565},{"atb":[[18.5,0],[18,3.25]],"id":52671561},{"atb":[[6.4,3],[6.2,0]],"id":52671553},{"atb":[[5.5,0],[5.4,2.8]],"id":52671547},{"atb":[[4.8,4.21],[4.9,0]],"id":52671546},{"atb":[[4.2,16.35]],"id":52671542},{"atb":[[32,0],[34,2.68]],"id":52671545}],"con":true,"img":false}]}
{"op":"mcm","clk":"11450518082","pt":1717322928665,"mc":[{"id":"1.229554923","rc":[{"atb":[[48,0],[29,0]],"id":52671563},{"atb":[[16,0],[11,0]],"id":52671562},{"atb":[[13.5,0],[9.4,0]],"id":52671565},{"atb":[[380,0],[480,0]],"id":52671564},{"atb":[[8.6,0],[11.5,0]],"id":52671561},{"atb":[[13.5,0],[9.4,0]],"id":52671560},{"atb":[[11,10.46],[8.4,0]],"id":52671555},{"atb":[[260,0],[160,0]],"id":52671554},{"atb":[[18,0],[13,0]],"id":52671556},{"atb":[[13.5,4.19],[9.4,12.46]],"id":52671551},{"atb":[[3.2,0],[2.88,0]],"id":52671550},{"atb":[[4.6,0],[3.8,0]],"id":52671553},{"atb":[[20,0],[15,0]],"id":52671552},{"atb":[[3.85,0],[3.35,0]],"id":52671547},{"atb":[[3.6,0],[3.1,0]],"id":52671546},{"atb":[[16,0],[11,0]],"id":52671549},{"atb":[[7.4,0],[9.4,0]],"id":52671548},{"atb":[[4.6,0],[3.8,0]],"id":52671543},{"atb":[[2.86,0],[3.15,0]],"id":52671542},{"atb":[[18,0],[13,0]],"id":52671545},{"atb":[[10.5,5.51],[8.2,14.53]],"id":52671544}],"con":true,"img":false}]}
{"op":"mcm","clk":"11450518107","pt":1717322928983,"mc":[{"id":"1.229554923","rc":[{"atb":[[27,3.26],[28,0]],"id":52671562},{"atb":[[21,5.6],[22,0]],"id":52671565},{"atb":[[18,0],[18.5,4]],"id":52671561},{"atb":[[6.4,0],[6.2,4.08]],"id":52671553},{"atb":[[5.5,4.03],[5.4,0]],"id":52671547},{"atb":[[4.8,0],[4.9,2.9]],"id":52671546},{"atb":[[4.2,21.26]],"id":52671542},{"atb":[[32,3.01]],"id":52671545}],"con":true,"img":false}]}
{"op":"mcm","clk":"11450518115","pt":1717322929082,"mc":[{"id":"1.229554923","rc":[{"atb":[[34,0]],"id":52671545}],"con":true,"img":false}]}
{"op":"mcm","clk":"11450518348","pt":1717322931597,"mc":[{"id":"1.229554923","rc":[{"atb":[[27,0]],"id":52671562},{"atb":[[21,1.31]],"id":52671565},{"atb":[[18.5,0]],"id":52671561},{"atb":[[6.4,3.47]],"id":52671553},{"atb":[[5.5,0]],"id":52671547},{"atb":[[4.8,4.62],[4.9,0]],"id":52671546},{"atb":[[4.2,16.35]],"id":52671542},{"atb":[[32,0],[34,3.24]],"id":52671545}],"con":true,"img":false}]}
{"op":"mcm","clk":"11450518359","pt":1717322931656,"mc":[{"id":"1.229554923","rc":[{"atb":[[28,4.19]],"id":52671562},{"atb":[[22,3.64]],"id":52671565},{"atb":[[18,3]],"id":52671561},{"atb":[[6.2,0]],"id":52671553},{"atb":[[5.4,4.33]],"id":52671547}],"con":true,"img":false}]}
{"op":"mcm","clk":"11450518795","pt":1717322935987,"mc":[{"id":"1.229554923","rc":[{"atb":[[150,0],[170,0]],"id":52671564},{"atb":[[21,5.45]],"id":52671552},{"atl":[[10,0],[11,3.53]],"id":52671546},{"atl":[[9.2,3.2],[8.4,0]],"id":52671542}],"con":true,"img":false}]}
{"op":"mcm","clk":"11450518804","pt":1717322936091,"mc":[{"id":"1.229554923","rc":[{"atb":[[80,2.9]],"id":52671564},{"atb":[[130,0],[150,0],[60,2.77]],"id":52671554},{"atb":[[44,0],[48,0]],"id":52671552},{"atb":[[34,0],[29,0]],"id":52671545}],"con":true,"img":false}]}
{"op":"mcm","clk":"11450518811","pt":1717322936154,"mc":[{"id":"1.229554923","rc":[{"atb":[[26,5.05]],"id":52671552}],"con":true,"img":false}]}
{"op":"mcm","clk":"11450518819","pt":1717322936255,"mc":[{"id":"1.229554923","rc":[{"atb":[[30,0]],"id":52671552}],"con":true,"img":false}]}
{"op":"mcm","clk":"11450518878","pt":1717322936778,"mc":[{"id":"1.229554923","rc":[{"atb":[[27,2.73],[28,0]],"id":52671562},{"atb":[[21,4.48],[22,0]],"id":52671565},{"atb":[[170,3.52]],"id":52671564},{"atb":[[18,0],[18.5,3.27]],"id":52671561},{"atb":[[150,3.99]],"id":52671554},{"atb":[[6.4,0],[6.2,3.8]],"id":52671553},{"atb":[[48,3.75]],"id":52671552},{"atb":[[5.5,3.05],[5.4,0]],"id":52671547},{"atb":[[4.8,0],[4.9,3.4]],"id":52671546},{"atl":[[10,4.65],[11,0]],"id":52671546},{"atb":[[4.2,21.26]],"id":52671542},{"atl":[[8.8,0],[8.4,3.6]],"id":52671542},{"atb":[[32,3.68],[29,2.94]],"id":52671545}],"con":true,"img":false}]}
{"op":"mcm","clk":"11450518914","pt":1717322937087,"mc":[{"id":"1.229554923","rc":[{"atb":[[34,4.07],[30,3.85]],"id":52671545}],"con":true,"img":false}]}
{"op":"mcm","clk":"11450519507","pt":1717322942496,"mc":[{"id":"1.229554923","rc":[{"atb":[[8.6,32.09],[11.5,9.95]],"id":52671561},{"atb":[[13.5,8.36],[9.4,29.03]],"id":52671560},{"atb":[[3.85,36.67],[3.35,103.78]],"id":52671547},{"atb":[[3.6,40.2],[3.1,116.14]],"id":52671546},{"atb":[[16,6.96],[11,24.39]],"id":52671549},{"atb":[[7.4,38.1],[9.4,12.44]],"id":52671548},{"atb":[[4.6,29.03],[3.8,87.1]],"id":52671543},{"atb":[[2.86,131.13],[3.15,48.61]],"id":52671542},{"atb":[[18,6.14],[13,20.32]],"id":52671545},{"atb":[[10.5,16.51],[8.2,48.41]],"id":52671544}],"con":true,"img":false}]}
{"op":"mcm","clk":"11450519521","pt":1717322942702,"mc":[{"id":"1.229554923","rc":[{"atb":[[48,2.22],[29,8.71]],"id":52671563},{"atb":[[16,6.96],[11,24.39]],"id":52671562},{"atb":[[13.5,8.36],[9.4,29.03]],"id":52671565},{"atb":[[380,0.64],[480,0.21]],"id":52671564},{"atb":[[11,20.92],[8.4,32.96]],"id":52671555},{"atb":[[260,0.4],[160,1.53]],"id":52671554},{"atb":[[18,6.14],[13,20.32]],"id":52671556},{"atb":[[13.5,12.55],[9.4,41.49]],"id":52671551},{"atb":[[3.2,47.51],[2.88,129.73]],"id":52671550},{"atb":[[4.6,29.03],[3.8,87.1]],"id":52671553},{"atb":[[20,5.5],[15,17.42]],"id":52671552}],"con":true,"img":false}]}
{"op":"mcm","clk":"11450519556","pt":1717322942983,"mc":[{"id":"1.229554923","rc":[{"atb":[[28,2.99]],"id":52671562},{"atb":[[21,1.31],[22,3.27]],"id":52671565},{"atb":[[18.5,0],[18,2.65]],"id":52671561},{"atb":[[6.4,2.63],[6.2,0]],"id":52671553},{"atb":[[5.5,0],[5.4,3.7]],"id":52671547},{"atb":[[4.8,4.62],[4.9,0]],"id":52671546},{"atb":[[29,0],[30,0]],"id":52671545}],"con":true,"img":false}]}
{"op":"mcm","clk":"11450519565","pt":1717322943084,"mc":[{"id":"1.229554923","rc":[{"atb":[[27,0]],"id":52671562},{"atb":[[4.2,16.35]],"id":52671542}],"con":true,"img":false}]}
{"op":"mcm","clk":"11450519998","pt":1717322946802,"mc":[{"id":"1.229554923","rc":[{"atb":[[150,2.92]],"id":52671564},{"atb":[[130,3.66]],"id":52671554},{"atb":[[44,3.52]],"id":52671552},{"atb":[[3.9,5.4]],"id":52671542},{"atl":[[8.8,3.04]],"id":52671542}],"con":true,"img":false}]}
{"op":"mcm","clk":"11450520199","pt":1717322948896,"mc":[{"id":"1.229554923","rc":[{"atb":[[80,0]],"id":52671564},{"atb":[[60,0]],"id":52671554},{"atb":[[21,2.62]],"id":52671552},{"atl":[[9.2,0]],"id":52671542}],"con":true,"img":false}]}
{"op":"mcm","clk":"11450520618","pt":1717322953121,"mc":[{"id":"1.229554923","rc":[{"atb":[[20,2.95]],"id":52671565}],"con":true,"img":false}]}
{"op":"mcm","clk":"11450520737","pt":1717322954280,"mc":[{"id":"1.229554923","rc":[{"atb":[[19,0]],"id":52671565}],"con":true,"img":false}]}
{"op":"mcm","clk":"11450522882","pt":1717322977003,"mc":[{"id":"1.229554923","rc":[{"atl":[[480,0],[490,3.28]],"id":52671563},{"atl":[[960,0],[970,4.39]],"id":52671554},{"atl":[[10,0],[9.8,4.13]],"id":52671546},{"atl":[[13.5,4.13],[14,0]],"id":52671543},{"atl":[[8.2,4.38],[8.4,0]],"id":52671542}],"con":true,"img":false}]}
{"op":"mcm","clk":"11450523879","pt":1717322986992,"mc":[{"id":"1.229554923","rc":[{"atl":[[10.5,3.73]],"id":52671546}],"con":true,"img":false}]}
{"op":"mcm","clk":"11450524371","pt":1717322992310,"mc":[{"id":"1.229554923","rc":[{"atl":[[11.5,0]],"id":52671546}],"con":true,"img":false}]}
{"op":"mcm","clk":"11450528098","pt":1717323030460,"mc":[{"id":"1.229554923","rc":[{"atb":[[27,4.64],[28,0]],"id":52671562},{"atb":[[160,2.75],[170,0]],"id":52671564},{"atb":[[17.5,4.6],[18,0]],"id":52671555},{"atb":[[22,3.76],[24,0]],"id":52671551},{"atb":[[3.7,0],[4.9,0],[4.4,0]],"id":52671550},{"atb":[[8,0],[6.4,0],[5.5,0],[6,0],[7,0],[6.6,3.17]],"id":52671553},{"atb":[[46,4.52],[48,0]],"id":52671552},{"atb":[[5.5,3.73],[5.4,0]],"id":52671547},{"atb":[[4.8,0],[5,23.71]],"id":52671546},{"atb":[[4,0],[4.2,21.26]],"id":52671542},{"atb":[[34,0]],"id":52671545},{"atb":[[17,4.64],[18,0]],"id":52671544}],"con":true,"img":false}]}
{"op":"mcm","clk":"11450528113","pt":1717323030667,"mc":[{"id":"1.229554923","rc":[{"atb":[[26,1.05],[28,3.7]],"id":52671552}],"con":true,"img":false}]}
{"op":"mcm","clk":"11450528155","pt":1717323031149,"mc":[{"id":"1.229554923","rc":[{"atb":[[5.1,6.38],[4.6,14.53],[3.8,37.37]],"id":52671550}],"con":true,"img":false}]}
{"op":"mcm","clk":"11450528166","pt":1717323031247,"mc":[{"id":"1.229554923","rc":[{"atb":[[5.6,22.75],[7.2,8.44],[6.2,15.09],[8.2,3.63]],"id":52671553}],"con":true,"img":false}]}
{"op":"mcm","clk":"11450528377","pt":1717323033482,"mc":[{"id":"1.229554923","rc":[{"atb":[[21,4.15],[22,0]],"id":52671565},{"atb":[[160,0],[170,3.77]],"id":52671564},{"atb":[[18,0],[18.5,3.05]],"id":52671561},{"atb":[[17.5,0]],"id":52671555},{"atb":[[22,0],[23,3.42]],"id":52671551},{"atb":[[6.4,4.01],[6.6,0]],"id":52671553},{"atb":[[46,0],[48,4.03]],"id":52671552},{"atb":[[4.8,0],[5.8,0],[5.3,0],[6.6,0]],"id":52671547},{"atb":[[5,19.62],[4.9,2.68]],"id":52671546},{"atb":[[34,4.45]],"id":52671545}],"con":true,"img":false}]}
{"op":"mcm","clk":"11450528450","pt":1717323034158,"mc":[{"id":"1.229554923","rc":[{"atb":[[6.8,4.51],[4.9,26.83],[5.9,10.68],[5.4,17.84]],"id":52671547}],"con":true,"img":false}]}
{"op":"mcm","clk":"11450528667","pt":1717323035956,"mc":[{"id":"1.229554923","rc":[{"atb":[[21,1.31],[22,4.12]],"id":52671565},{"atb":[[160,2.86],[170,0]],"id":52671564},{"atb":[[18.5,0],[18,3.23]],"id":52671561},{"atb":[[17.5,4.67]],"id":52671555},{"atb":[[22,3.31],[23,0]],"id":52671551},{"atb":[[6.4,0],[6.6,2.97]],"id":52671553},{"atb":[[46,2.84],[48,0]],"id":52671552},{"atb":[[5,22.37],[4.9,0]],"id":52671546},{"atb":[[34,0]],"id":52671545}],"con":true,"img":false}]}
{"op":"mcm","clk":"11450529099","pt":1717323040472,"mc":[{"id":"1.229554923","rc":[{"atb":[[4,5.23]],"id":52671542}],"con":true,"img":false}]}
{"op":"mcm","clk":"11450529405","pt":1717323043490,"mc":[{"id":"1.229554923","rc":[{"atb":[[29,2.79]],"id":52671545}],"con":true,"img":false}]}
{"op":"mcm","clk":"11450529672","pt":1717323045962,"mc":[{"id":"1.229554923","rc":[{"atb":[[6.2,19.21]],"id":52671553},{"atb":[[4.8,2.92]],"id":52671546}],"con":true,"img":false}]}
{"op":"mcm","clk":"11450529734","pt":1717323046684,"mc":[{"id":"1.229554923","rc":[{"atb":[[21,5.4],[22,0]],"id":52671565},{"atb":[[160,0],[170,2.89]],"id":52671564},{"atb":[[18,0],[18.5,3.05]],"id":52671561},{"atb":[[17.5,0]],"id":52671555},{"atb":[[22,0],[23,4.01]],"id":52671551},{"atb":[[6.4,3.79],[6.6,0]],"id":52671553},{"atb":[[46,0],[48,3.02]],"id":52671552},{"atb":[[5,19.62],[4.9,3.66]],"id":52671546},{"atb":[[3.9,0]],"id":52671542},{"atb":[[32,0],[34,3.4]],"id":52671545}],"con":true,"img":false}]}
{"op":"mcm","clk":"11450529782","pt":1717323047056,"mc":[{"id":"1.229554923","rc":[{"atb":[[48,0],[29,0]],"id":52671563},{"atb":[[16,0],[11,0]],"id":52671562},{"atb":[[13.5,0],[9.4,0]],"id":52671565},{"atb":[[380,0],[480,0]],"id":52671564},{"atb":[[8.6,0],[11.5,0]],"id":52671561},{"atb":[[13.5,0],[9.4,0]],"id":52671560},{"atb":[[11,10.46],[8.4,0]],"id":52671555},{"atb":[[260,0],[160,0]],"id":52671554},{"atb":[[18,0],[13,0]],"id":52671556},{"atb":[[13.5,4.19],[9.4,12.46]],"id":52671551},{"atb":[[3.2,0],[2.88,0]],"id":52671550},{"atb":[[4.6,0],[3.8,0]],"id":52671553},{"atb":[[20,0],[15,0]],"id":52671552},{"atb":[[3.85,0],[3.35,0]],"id":52671547},{"atb":[[3.6,0],[3.1,0]],"id":52671546},{"atb":[[16,0],[11,0]],"id":52671549},{"atb":[[7.4,0],[9.4,0]],"id":52671548},{"atb":[[4.6,0],[3.8,0]],"id":52671543},{"atb":[[2.86,0],[3.15,0]],"id":52671542},{"atb":[[18,0],[13,0]],"id":52671545},{"atb":[[10.5,5.51],[8.2,14.53]],"id":52671544}],"con":true,"img":false}]}
{"op":"mcm","clk":"11450530423","pt":1717323053493,"mc":[{"id":"1.229554923","rc":[{"atb":[[48,2.22],[29,8.71]],"id":52671563},{"atb":[[16,6.96],[11,24.39]],"id":52671562},{"atb":[[13.5,8.36],[9.4,29.03]],"id":52671565},{"atb":[[380,0.64],[480,0.21]],"id":52671564},{"atb":[[11,20.92],[8.4,32.96]],"id":52671555},{"atb":[[260,0.4],[160,1.53]],"id":52671554},{"atb":[[18,6.14],[13,20.32]],"id":52671556},{"atb":[[13.5,12.55],[9.4,41.49]],"id":52671551},{"atb":[[3.2,47.51],[2.88,129.73]],"id":52671550},{"atb":[[4.6,29.03],[3.8,87.1]],"id":52671553},{"atb":[[20,5.5],[15,17.42]],"id":52671552}],"con":true,"img":false}]}
{"op":"mcm","clk":"11450530432","pt":1717323053590,"mc":[{"id":"1.229554923","rc":[{"atb":[[8.6,32.09],[11.5,9.95]],"id":52671561},{"atb":[[13.5,8.36],[9.4,29.03]],"id":52671560},{"atb":[[3.85,36.67],[3.35,103.78]],"id":52671547},{"atb":[[3.6,40.2],[3.1,116.14]],"id":52671546},{"atb":[[16,6.96],[11,24.39]],"id":52671549},{"atb":[[7.4,38.1],[9.4,12.44]],"id":52671548},{"atb":[[4.6,29.03],[3.8,87.1]],"id":52671543},{"atb":[[2.86,131.13],[3.15,48.61]],"id":52671542},{"atb":[[18,6.14],[13,20.32]],"id":52671545},{"atb":[[10.5,16.51],[8.2,48.41]],"id":52671544}],"con":true,"img":false}]}
{"op":"mcm","clk":"11450530740","pt":1717323056676,"mc":[{"id":"1.229554923","rc":[{"atb":[[16,8.08]],"id":52671555},{"atb":[[6,4.65],[5.9,0]],"id":52671553},{"atb":[[4.6,0],[4.7,4.26]],"id":52671546}],"con":true,"img":false}]}
{"op":"mcm","clk":"11450531707","pt":1717323066720,"mc":[{"id":"1.229554923","rc":[{"atb":[[6,0]],"id":52671553},{"atb":[[4.7,0]],"id":52671546}],"con":true,"img":false}]}
{"op":"mcm","clk":"11450531751","pt":1717323067143,"mc":[{"id":"1.229554923","rc":[{"atb":[[5.1,0],[4.6,0],[3.8,0]],"id":52671550},{"atb":[[5.6,0],[7.2,0],[6.2,4.11],[8.2,0]],"id":52671553}],"con":true,"img":false}]}
{"op":"mcm","clk":"11450531825","pt":1717323067820,"mc":[{"id":"1.229554923","rc":[{"atb":[[3.7,38.75],[4.9,6.71],[4.4,15.39]],"id":52671550},{"atb":[[6.8,9.02],[7.8,3.85],[5.9,16.01],[5.4,23.78]],"id":52671553}],"con":true,"img":false}]}
{"op":"mcm","clk":"11450535221","pt":1717323100806,"mc":[{"id":"1.229554923","rc":[{"atb":[[4.5,14.66],[3.95,5.32]],"id":52671563},{"atb":[[8,4.21],[14,13.73]],"id":52671556},{"atb":[[3.3,43.48],[3.75,0]],"id":52671547},{"atb":[[4.5,28.57],[3.95,5.32]],"id":52671548},{"atb":[[3.8,122.81],[3.55,0]],"id":52671543},{"atl":[[17,6.25],[13,0]],"id":52671542},{"atb":[[4.5,28.57],[7,0]],"id":52671544}],"con":true,"img":false}]}
{"op":"mcm","clk":"11450535254","pt":1717323101203,"mc":[{"id":"1.229554923","rc":[{"atb":[[8,14.29]],"id":52671549}],"con":true,"img":false}]}
{"op":"mcm","clk":"11450536023","pt":1717323109005,"mc":[{"id":"1.229554923","rc":[{"atb":[[27,0],[28,3.01]],"id":52671562},{"atb":[[21,1.31],[22,2.87]],"id":52671565},{"atb":[[17.5,0],[18.5,0]],"id":52671561},{"atb":[[20,0],[21,3.92]],"id":52671560},{"atb":[[17,0],[18,2.84]],"id":52671555},{"atb":[[23,0],[24,3.27]],"id":52671551},{"atb":[[3.1,0],[4.1,5.06],[4.2,4.9]],"id":52671550},{"atb":[[5.5,0],[5.4,22.33]],"id":52671547},{"atl":[[17,4.13],[11.5,0],[12.5,0]],"id":52671547},{"atb":[[4.9,0]],"id":52671546},{"atb":[[13,3.08]],"id":52671549},{"atb":[[6.4,3.13],[6.2,3.7],[4.1,0]],"id":52671543},{"atb":[[4.2,16.35]],"id":52671542},{"atl":[[17,9.17],[8.2,0],[8.8,0]],"id":52671542},{"atb":[[16.5,0],[17,0]],"id":52671544}],"con":true,"img":false}]}
{"op":"mcm","clk":"11450536211","pt":1717323110716,"mc":[{"id":"1.229554923","rc":[{"atb":[[9,0],[7.8,14.71]],"id":52671562},{"atb":[[6.2,19.23],[7.4,0]],"id":52671555},{"atb":[[7.2,16.13],[8.4,0]],"id":52671551},{"atb":[[8,0],[11,34.39]],"id":52671549},{"atb":[[2.64,60.98],[2.76,0]],"id":52671542}],"con":true,"img":false}]}
{"op":"mcm","clk":"11450536234","pt":1717323111031,"mc":[{"id":"1.229554923","rc":[{"atb":[[4.2,0]],"id":52671550}],"con":true,"img":false}]}
{"op":"mcm","clk":"11450536243","pt":1717323111090,"mc":[{"id":"1.229554923","rc":[{"atb":[[6.4,0]],"id":52671543}],"con":true,"img":false}]}
{"op":"mcm","clk":"11450537023","pt":1717323118950,"mc":[{"id":"1.229554923","rc":[{"atl":[[18,4.27]],"id":52671547},{"atb":[[12,2.76]],"id":52671549},{"atb":[[3.9,5.4]],"id":52671542},{"atl":[[18,4.19]],"id":52671542}],"con":true,"img":false}]}
{"op":"mcm","clk":"11450537037","pt":1717323119008,"mc":[{"id":"1.229554923","rc":[{"atb":[[17,4.39]],"id":52671555},{"atb":[[3.95,5.32]],"id":52671550},{"atb":[[4.6,3.32]],"id":52671546},{"atb":[[5.9,4.47]],"id":52671543}],"con":true,"img":false}]}
{"op":"mcm","clk":"11450538043","pt":1717323129043,"mc":[{"id":"1.229554923","rc":[{"atb":[[16,3.49]],"id":52671555},{"atb":[[3,0]],"id":52671550},{"atb":[[7.6,0]],"id":52671549},{"atb":[[3.95,0]],"id":52671543}],"con":true,"img":false}]}
{"op":"mcm","clk":"11450539313","pt":1717323141456,"mc":[{"id":"1.229554923","rc":[{"atb":[[48,0],[29,0]],"id":52671563},{"atb":[[16,0],[11,0]],"id":52671562},{"atb":[[13.5,0],[9.4,0]],"id":52671565},{"atb":[[380,0],[480,0]],"id":52671564},{"atb":[[8.6,0],[11.5,0]],"id":52671561},{"atb":[[13.5,0],[9.4,0]],"id":52671560},{"atb":[[11,10.46],[8.4,0]],"id":52671555},{"atb":[[260,0],[160,0]],"id":52671554},{"atb":[[18,0],[13,0]],"id":52671556},{"atb":[[13.5,4.19],[9.4,12.46]],"id":52671551},{"atb":[[3.2,0],[2.88,0]],"id":52671550},{"atb":[[4.6,0],[3.8,0]],"id":52671553},{"atb":[[20,0],[15,0]],"id":52671552},{"atb":[[3.85,0],[3.35,0]],"id":52671547},{"atb":[[3.6,0],[3.1,0]],"id":52671546},{"atb":[[16,0],[11,10]],"id":52671549},{"atb":[[7.4,0],[9.4,0]],"id":52671548},{"atb":[[4.6,0],[3.8,35.71]],"id":52671543},{"atb":[[2.86,0],[3.15,0]],"id":52671542},{"atb":[[18,0],[13,0]],"id":52671545},{"atb":[[10.5,5.51],[8.2,14.53]],"id":52671544}],"con":true,"img":false}]}
{"op":"mcm","clk":"11450539795","pt":1717323145384,"mc":[{"id":"1.229554923","rc":[{"atb":[[4.7,2.83]],"id":52671563},{"atb":[[11.5,2.86],[12.5,2.71]],"id":52671560}],"con":true,"img":false}]}
{"op":"mcm","clk":"11450539805","pt":1717323145485,"mc":[{"id":"1.229554923","rc":[{"atb":[[4.1,0]],"id":52671563},{"atb":[[11.5,4.04],[12.5,3.41]],"id":52671561},{"atb":[[8,0],[13,4.7]],"id":52671556},{"atb":[[4.1,0],[4.7,4.47]],"id":52671548},{"atb":[[4.5,31.67],[4.7,3.51]],"id":52671544}],"con":true,"img":false}]}
{"op":"mcm","clk":"11450540396","pt":1717323150778,"mc":[{"id":"1.229554923","rc":[{"atb":[[6.8,0],[7.8,0],[5.9,0],[5.4,0]],"id":52671553}],"con":true,"img":false}]}
{"op":"mcm","clk":"11450540472","pt":1717323151507,"mc":[{"id":"1.229554923","rc":[{"atb":[[8,3.74],[5.5,23.25],[6,15.7],[7,8.72]],"id":52671553}],"con":true,"img":false}]}
{"op":"mcm","clk":"11450540628","pt":1717323152918,"mc":[{"id":"1.229554923","rc":[{"atb":[[48,2.22],[29,8.71]],"id":52671563},{"atb":[[16,6.96],[11,24.39]],"id":52671562},{"atb":[[13.5,8.36],[9.4,29.03]],"id":52671565},{"atb":[[380,0.64],[480,0.21]],"id":52671564},{"atb":[[11,20.92],[8.4,32.96]],"id":52671555},{"atb":[[260,0.4],[160,1.53]],"id":52671554},{"atb":[[18,6.14],[13,25.02]],"id":52671556},{"atb":[[13.5,12.55],[9.4,41.49]],"id":52671551},{"atb":[[3.2,47.51],[2.88,129.73]],"id":52671550},{"atb":[[4.6,29.03],[3.8,87.1]],"id":52671553},{"atb":[[20,5.5],[15,17.42]],"id":52671552}],"con":true,"img":false}]}
{"op":"mcm","clk":"11450540642","pt":1717323152974,"mc":[{"id":"1.229554923","rc":[{"atb":[[8.6,32.09],[11.5,14]],"id":52671561},{"atb":[[13.5,8.36],[9.4,29.03]],"id":52671560},{"atb":[[3.85,36.67],[3.35,103.78]],"id":52671547},{"atb":[[3.6,40.2],[3.1,116.14]],"id":52671546},{"atb":[[16,6.96],[11,34.39]],"id":52671549},{"atb":[[7.4,38.1],[9.4,12.44]],"id":52671548},{"atb":[[4.6,29.03],[3.8,122.81]],"id":52671543},{"atb":[[2.86,131.13],[3.15,48.61]],"id":52671542},{"atb":[[18,6.14],[13,20.32]],"id":52671545},{"atb":[[10.5,16.51],[8.2,48.41]],"id":52671544}],"con":true,"img":false}]}
{"op":"mcm","clk":"11450547236","pt":1717323212318,"mc":[{"id":"1.229554923","rc":[{"atb":[[6.8,0],[4.9,0],[5.9,0],[5.4,4.49]],"id":52671547}],"con":true,"img":false}]}
{"op":"mcm","clk":"11450547326","pt":1717323213085,"mc":[{"id":"1.229554923","rc":[{"atb":[[4.8,27.54],[5.8,10.9],[5.3,18.25],[6.6,4.67]],"id":52671547}],"con":true,"img":false}]}
{"op":"mcm","clk":"11450548262","pt":1717323222151,"mc":[{"id":"1.229554923","rc":[{"atb":[[48,0],[29,0]],"id":52671563},{"atb":[[16,0],[11,0]],"id":52671562},{"atb":[[13.5,0],[9.4,0]],"id":52671565},{"atb":[[380,0],[480,0]],"id":52671564},{"atb":[[8.6,0],[11.5,4.04]],"id":52671561},{"atb":[[13.5,0],[9.4,0]],"id":52671560},{"atb":[[11,10.46],[8.4,0]],"id":52671555},{"atb":[[260,0],[160,0]],"id":52671554},{"atb":[[18,0],[13,4.7]],"id":52671556},{"atb":[[13.5,4.19],[9.4,12.46]],"id":52671551},{"atb":[[3.2,0],[2.88,0]],"id":52671550},{"atb":[[4.6,0],[3.8,0]],"id":52671553},{"atb":[[20,0],[15,0]],"id":52671552},{"atb":[[3.85,0],[3.35,0]],"id":52671547},{"atb":[[3.6,0],[3.1,0]],"id":52671546},{"atb":[[16,0],[11,10]],"id":52671549},{"atb":[[7.4,0],[9.4,0]],"id":52671548},{"atb":[[4.6,0],[3.8,35.71]],"id":52671543},{"atb":[[2.86,0],[3.15,0]],"id":52671542},{"atb":[[18,0],[13,0]],"id":52671545},{"atb":[[10.5,5.51],[8.2,14.53]],"id":52671544}],"con":true,"img":false}]}
{"op":"mcm","clk":"11450548759","pt":1717323226615,"mc":[{"id":"1.229554923","rc":[{"atb":[[4.5,17.36]],"id":52671563},{"atb":[[12,3.3]],"id":52671556},{"atb":[[4.5,31.98]],"id":52671548}],"con":true,"img":false}]}
{"op":"mcm","clk":"11450549629","pt":1717323234137,"mc":[{"id":"1.229554923","rc":[{"atb":[[48,2.22],[29,8.71]],"id":52671563},{"atb":[[16,6.96],[11,24.39]],"id":52671562},{"atb":[[13.5,8.36],[9.4,29.03]],"id":52671565},{"atb":[[380,0.64],[480,0.21]],"id":52671564},{"atb":[[11,20.92],[8.4,32.96]],"id":52671555},{"atb":[[260,0.4],[160,1.53]],"id":52671554},{"atb":[[18,6.14],[13,25.02]],"id":52671556},{"atb":[[13.5,12.55],[9.4,41.49]],"id":52671551},{"atb":[[3.2,47.51],[2.88,129.73]],"id":52671550},{"atb":[[4.6,29.03],[3.8,87.1]],"id":52671553},{"atb":[[20,5.5],[15,17.42]],"id":52671552}],"con":true,"img":false}]}
{"op":"mcm","clk":"11450549642","pt":1717323234244,"mc":[{"id":"1.229554923","rc":[{"atb":[[8.6,32.09],[11.5,14]],"id":52671561},{"atb":[[13.5,8.36],[9.4,29.03]],"id":52671560},{"atb":[[3.85,36.67],[3.35,103.78]],"id":52671547},{"atb":[[3.6,40.2],[3.1,116.14]],"id":52671546},{"atb":[[16,6.96],[11,34.39]],"id":52671549},{"atb":[[7.4,38.1],[9.4,12.44]],"id":52671548},{"atb":[[4.6,29.03],[3.8,122.81]],"id":52671543},{"atb":[[2.86,131.13],[3.15,48.61]],"id":52671542},{"atb":[[18,6.14],[13,20.32]],"id":52671545},{"atb":[[10.5,16.51],[8.2,48.41]],"id":52671544}],"con":true,"img":false}]}
{"op":"mcm","clk":"11450551496","pt":1717323250896,"mc":[{"id":"1.229554923","rc":[{"atb":[[4.1,0]],"id":52671550},{"atb":[[4.8,0],[4.9,4.26]],"id":52671546}],"con":true,"img":false}]}
{"op":"mcm","clk":"11450551505","pt":1717323250985,"mc":[{"id":"1.229554923","rc":[{"atb":[[27,2.66],[28,0]],"id":52671562},{"atb":[[21,4.23],[22,0]],"id":52671565},{"atb":[[4.2,4.9]],"id":52671550},{"atb":[[6.4,0]],"id":52671553},{"atb":[[5.5,3.91],[5.4,0]],"id":52671547},{"atb":[[4,0],[4.2,21.26]],"id":52671542},{"atb":[[32,3.43],[34,0]],"id":52671545}],"con":true,"img":false}]}
{"op":"mcm","clk":"11450551649","pt":1717323252282,"mc":[{"id":"1.229554923","rc":[{"atb":[[6.4,2.76]],"id":52671553}],"con":true,"img":false}]}
{"op":"mcm","clk":"11450551770","pt":1717323253372,"mc":[{"id":"1.229554923","rc":[{"atb":[[6.4,0]],"id":52671553}],"con":true,"img":false}]}
{"op":"mcm","clk":"11450552580","pt":1717323261781,"mc":[{"id":"1.229554923","rc":[{"atb":[[4,5.23]],"id":52671542}],"con":true,"img":false}]}
{"op":"mcm","clk":"11450552728","pt":1717323263096,"mc":[{"id":"1.229554923","rc":[{"atb":[[5.9,3.44]],"id":52671553}],"con":true,"img":false}]}
{"op":"mcm","clk":"11450552945","pt":1717323265079,"mc":[{"id":"1.229554923","rc":[{"atb":[[3.9,0]],"id":52671542}],"con":true,"img":false}]}
{"op":"mcm","clk":"11450554448","pt":1717323278628,"mc":[{"id":"1.229554923","rc":[{"atb":[[18,0]],"id":52671555},{"atb":[[23,3.71],[24,0]],"id":52671551},{"atb":[[6.4,3.27],[6.2,0]],"id":52671553},{"atb":[[6.4,3.02],[6.2,0]],"id":52671543},{"atb":[[32,0],[34,3.18]],"id":52671545}],"con":true,"img":false}]}
{"op":"mcm","clk":"11450554546","pt":1717323279428,"mc":[{"id":"1.229554923","rc":[{"atb":[[160,6.53]],"id":52671554}],"con":true,"img":false}]}
{"op":"mcm","clk":"11450554556","pt":1717323279528,"mc":[{"id":"1.229554923","rc":[{"atb":[[110,5]],"id":52671563},{"atl":[[240,5]],"id":52671563},{"atb":[[34,5]],"id":52671562},{"atl":[[75,5]],"id":52671562},{"atb":[[25,5]],"id":52671565},{"atl":[[46,5]],"id":52671565},{"atb":[[160,5]],"id":52671564},{"atb":[[27,5]],"id":52671560},{"atl":[[55,5]],"id":52671560},{"atb":[[30,5]],"id":52671551},{"atl":[[65,5]],"id":52671551},{"atb":[[5.5,5]],"id":52671550},{"atl":[[7.8,5]],"id":52671550},{"atb":[[9.4,5]],"id":52671553},{"atl":[[15.5,9.05]],"id":52671553},{"atb":[[70,5]],"id":52671552},{"atl":[[200,5]],"id":52671552},{"atb":[[7.4,5]],"id":52671547},{"atl":[[10.5,5]],"id":52671547},{"atb":[[6.2,5]],"id":52671546},{"atl":[[9.8,9.13]],"id":52671546},{"atb":[[44,5]],"id":52671549},{"atl":[[110,7.85]],"id":52671549},{"atb":[[16,5]],"id":52671548},{"atl":[[34,5]],"id":52671548},{"atb":[[8.2,5]],"id":52671543},{"atl":[[13.5,9.14]],"id":52671543},{"atb":[[50,5]],"id":52671545},{"atl":[[130,8.35]],"id":52671545},{"atb":[[21,5]],"id":52671544},{"atl":[[42,5]],"id":52671544}],"con":true,"img":false}]}
{"op":"mcm","clk":"11450554601","pt":1717323279903,"mc":[{"id":"1.229554923","rc":[{"atb":[[5,5]],"id":52671542},{"atl":[[7.2,5]],"id":52671542}],"con":true,"img":false}]}
{"op":"mcm","clk":"11450554612","pt":1717323280009,"mc":[{"id":"1.229554923","rc":[{"atb":[[23,7.39]],"id":52671561},{"atl":[[44,5]],"id":52671561},{"atb":[[23,5]],"id":52671555},{"atl":[[42,5]],"id":52671555},{"atb":[[50,5]],"id":52671556},{"atl":[[120,5]],"id":52671556}],"con":true,"img":false}]}
{"op":"mcm","clk":"11450554645","pt":1717323280312,"mc":[{"id":"1.229554923","rc":[{"atl":[[180,2]],"id":52671565},{"atb":[[3.45,40.82]],"id":52671546},{"atl":[[22,4.76]],"id":52671546}],"con":true,"img":false}]}
{"op":"mcm","clk":"11450554661","pt":1717323280418,"mc":[{"id":"1.229554923","rc":[{"atl":[[930,2]],"id":52671563},{"atb":[[7.8,0],[9.4,11.9]],"id":52671562},{"atl":[[350,2],[400,0]],"id":52671562},{"atl":[[230,0]],"id":52671565},{"atb":[[6.2,0],[7.4,15.62]],"id":52671555},{"atl":[[540,2],[590,0]],"id":52671556},{"atb":[[7.2,0],[8.6,13.16]],"id":52671551},{"atb":[[2.96,0],[3.3,43.48]],"id":52671550},{"atl":[[18,0],[15,7.14]],"id":52671550},{"atb":[[4.2,31.25],[3.75,0]],"id":52671553},{"atb":[[32,3.23],[28,0]],"id":52671552},{"atl":[[690,2],[800,0]],"id":52671552},{"atb":[[3.6,38.46],[3.3,0]],"id":52671547},{"atb":[[3.2,0]],"id":52671546},{"atl":[[27,0]],"id":52671546},{"atb":[[11,24.39],[13.5,8]],"id":52671549},{"atl":[[560,0],[470,2]],"id":52671549},{"atb":[[3.8,87.1],[4.2,31.25]],"id":52671543},{"atl":[[32,3.23],[44,0]],"id":52671543},{"atb":[[2.9,52.63],[2.64,0]],"id":52671542},{"atl":[[560,2],[650,0]],"id":52671545}],"con":true,"img":false}]}
{"op":"mcm","clk":"11450554700","pt":1717323280760,"mc":[{"id":"1.229554923","rc":[{"atb":[[18,4.12]],"id":52671555},{"atb":[[23,0],[24,4.03]],"id":52671551},{"atb":[[6.4,0],[6.2,4.36]],"id":52671553},{"atb":[[6.4,0],[6.2,3.33]],"id":52671543},{"atb":[[32,4.32],[34,0]],"id":52671545}],"con":true,"img":false}]}
{"op":"mcm","clk":"11450554788","pt":1717323281497,"mc":[{"id":"1.229554923","rc":[{"atb":[[4.8,0],[5.8,0],[5.3,0],[6.6,0]],"id":52671547}],"con":true,"img":false}]}
{"op":"mcm","clk":"11450554878","pt":1717323282335,"mc":[{"id":"1.229554923","rc":[{"atb":[[4.8,27.54],[5.8,10.9],[5.3,18.25],[6.6,4.67]],"id":52671547}],"con":true,"img":false}]}
{"op":"mcm","clk":"11450554886","pt":1717323282392,"mc":[{"id":"1.229554923","rc":[{"atb":[[27,0],[28,3.89]],"id":52671562},{"atb":[[21,1.31],[22,3.39]],"id":52671565},{"atb":[[4.1,5.06],[4.2,0]],"id":52671550},{"atb":[[6.4,4.31],[6.2,0]],"id":52671553},{"atb":[[5.5,0],[5.4,3.2]],"id":52671547},{"atb":[[4.8,3.58],[4.9,0]],"id":52671546},{"atb":[[4.2,16.35]],"id":52671542},{"atb":[[32,0],[34,4.39]],"id":52671545}],"con":true,"img":false}]}
{"op":"mcm","clk":"11450555050","pt":1717323283918,"mc":[{"id":"1.229554923","rc":[{"atb":[[4.2,21.26]],"id":52671542}],"con":true,"img":false}]}
{"op":"mcm","clk":"11450555063","pt":1717323284014,"mc":[{"id":"1.229554923","rc":[{"atb":[[28,0]],"id":52671562},{"atb":[[21,4.34],[22,0]],"id":52671565},{"atb":[[4.1,0],[4.2,4.9]],"id":52671550},{"atb":[[5.5,3.53],[5.4,0]],"id":52671547},{"atb":[[4.8,0],[4.9,4.03]],"id":52671546},{"atl":[[7.2,0],[7.6,5]],"id":52671542}],"con":true,"img":false}]}
{"op":"mcm","clk":"11450555085","pt":1717323284210,"mc":[{"id":"1.229554923","rc":[{"atb":[[3.45,0],[3.15,46.51]],"id":52671546}],"con":true,"img":false}]}
{"op":"mcm","clk":"11450555272","pt":1717323285632,"mc":[{"id":"1.229554923","rc":[{"atb":[[8.2,13.89],[9.4,0]],"id":52671562},{"atb":[[3,50],[3.3,0]],"id":52671550},{"atb":[[4.2,0],[3.75,36.36]],"id":52671553},{"atb":[[3.6,0],[3.3,43.48]],"id":52671547},{"atb":[[3.8,122.81],[4.2,0]],"id":52671543},{"atb":[[2.9,0],[2.7,58.82]],"id":52671542}],"con":true,"img":false}]}
{"op":"mcm","clk":"11450555626","pt":1717323288712,"mc":[{"id":"1.229554923","rc":[{"atb":[[28,2.95]],"id":52671562},{"atb":[[21,1.31],[22,3.97]],"id":52671565},{"atb":[[4.1,5.06],[4.2,0]],"id":52671550},{"atb":[[5.5,0],[5.4,2.72]],"id":52671547},{"atb":[[4.8,4.7],[4.9,0]],"id":52671546},{"atb":[[4.2,16.35]],"id":52671542},{"atl":[[7.6,0],[7.8,5]],"id":52671542}],"con":true,"img":false}]}
{"op":"mcm","clk":"11450555635","pt":1717323288816,"mc":[{"id":"1.229554923","rc":[{"atb":[[27,3.44]],"id":52671562},{"atb":[[6.4,0],[6.2,3.73]],"id":52671553},{"atb":[[32,2.87],[34,0]],"id":52671545}],"con":true,"img":false}]}
{"op":"mcm","clk":"11450555692","pt":1717323289444,"mc":[{"id":"1.229554923","rc":[{"atb":[[3.4,41.67],[3.15,0]],"id":52671546},{"atl":[[410,2],[470,0]],"id":52671549},{"atl":[[560,0],[500,2]],"id":52671545},{"atl":[[150,2],[200,0]],"id":52671544}],"con":true,"img":false}]}
{"op":"mcm","clk":"11450555704","pt":1717323289542,"mc":[{"id":"1.229554923","rc":[{"atl":[[930,0]],"id":52671563}],"con":true,"img":false}]}
{"op":"mcm","clk":"11450555728","pt":1717323289710,"mc":[{"id":"1.229554923","rc":[{"atb":[[25,2.18]],"id":52671562},{"atb":[[22,5],[23,2.38]],"id":52671561},{"atl":[[42,0],[46,5]],"id":52671555},{"atl":[[130,7.81],[120,0]],"id":52671556},{"atb":[[6.4,2.76],[6.2,0]],"id":52671553},{"atl":[[17,8.46],[15.5,0]],"id":52671553},{"atl":[[190,0],[200,8.66]],"id":52671552},{"atl":[[10,2.88],[9.8,5]],"id":52671546},{"atb":[[5,0],[4.7,12.08]],"id":52671542},{"atb":[[32,0],[34,3.39]],"id":52671545}],"con":true,"img":false}]}
{"op":"mcm","clk":"11450555736","pt":1717323289841,"mc":[{"id":"1.229554923","rc":[{"atl":[[270,5],[240,0]],"id":52671563},{"atl":[[75,0],[85,5]],"id":52671562},{"atl":[[46,0],[55,5]],"id":52671565},{"atl":[[16,4.55]],"id":52671553},{"atb":[[7.2,5],[7.4,0]],"id":52671547}],"con":true,"img":false}]}
{"op":"mcm","clk":"11450556022","pt":1717323292338,"mc":[{"id":"1.229554923","rc":[{"atb":[[8.2,0],[9.4,11.9]],"id":52671562},{"atb":[[4.1,32.26],[3.75,0]],"id":52671553},{"atb":[[4.1,32.26],[3.8,87.1]],"id":52671543}],"con":true,"img":false}]}
{"op":"mcm","clk":"11450556214","pt":1717323294224,"mc":[{"id":"1.229554923","rc":[{"atb":[[3.9,5.4]],"id":52671542}],"con":true,"img":false}]}
{"op":"mcm","clk":"11450556505","pt":1717323297182,"mc":[{"id":"1.229554923","rc":[{"atl":[[9.8,8.92]],"id":52671546}],"con":true,"img":false}]}
{"op":"mcm","clk":"11450556514","pt":1717323297236,"mc":[{"id":"1.229554923","rc":[{"atl":[[10,0]],"id":52671546}],"con":true,"img":false}]}
{"op":"mcm","clk":"11450556730","pt":1717323299435,"mc":[{"id":"1.229554923","rc":[{"atb":[[120,1.56]],"id":52671563},{"atl":[[480,0.33]],"id":52671563},{"atb":[[34,9.86]],"id":52671562},{"atl":[[85,6.91]],"id":52671562},{"atb":[[25,11.68]],"id":52671565},{"atl":[[65,2.5]],"id":52671565},{"atl":[[1000,0.16]],"id":52671564},{"atb":[[23,12.28]],"id":52671555},{"atl":[[55,6.68]],"id":52671555},{"atl":[[960,0.16]],"id":52671554},{"atb":[[50,8.27]],"id":52671556},{"atl":[[150,5.27]],"id":52671556},{"atb":[[30,10.53]],"id":52671551},{"atl":[[65,7.5]],"id":52671551},{"atb":[[5.5,20.05]],"id":52671550},{"atl":[[7.8,20.05]],"id":52671550},{"atb":[[9.4,19.37]],"id":52671553},{"atl":[[16,15.24]],"id":52671553},{"atb":[[70,7.32]],"id":52671552},{"atl":[[200,9.47]],"id":52671552},{"atb":[[6.6,18.13]],"id":52671547},{"atl":[[10.5,18.46]],"id":52671547},{"atb":[[6.2,20.4]],"id":52671546},{"atl":[[9.8,24.32]],"id":52671546},{"atb":[[44,8.73]],"id":52671549},{"atl":[[110,9.32]],"id":52671549},{"atb":[[16.5,12.03]],"id":52671548},{"atl":[[34,9.86]],"id":52671548},{"atb":[[8.2,16.73]],"id":52671543},{"atl":[[13.5,20.87]],"id":52671543},{"atb":[[4.7,33.72]],"id":52671542},{"atl":[[7.8,26.65]],"id":52671542},{"atl":[[130,9.59]],"id":52671545},{"atb":[[21,13.01]],"id":52671544},{"atl":[[42,8.91]],"id":52671544}],"con":true,"img":false}]}
{"op":"mcm","clk":"11450556814","pt":1717323300247,"mc":[{"id":"1.229554923","rc":[{"atb":[[30,5]],"id":52671551}],"con":true,"img":false}]}
{"op":"mcm","clk":"11450556892","pt":1717323300932,"mc":[{"id":"1.229554923","rc":[{"atb":[[25,6.67]],"id":52671551}],"con":true,"img":false}]}
{"op":"mcm","clk":"11450558388","pt":1717323314017,"mc":[{"id":"1.229554923","rc":[{"atl":[[270,5.6]],"id":52671563},{"atl":[[55,7.97]],"id":52671565},{"atl":[[46,8.56]],"id":52671555},{"atl":[[130,9.05]],"id":52671556},{"atb":[[30,10.53]],"id":52671551},{"atb":[[7.2,28.9]],"id":52671547}],"con":true,"img":false}]}
{"op":"mcm","clk":"11450558472","pt":1717323314854,"mc":[{"id":"1.229554923","rc":[{"atl":[[480,0]],"id":52671563},{"atl":[[65,0]],"id":52671565},{"atl":[[55,3.71]],"id":52671555},{"atl":[[150,4.2]],"id":52671556},{"atb":[[25,0],[30,5]],"id":52671551},{"atb":[[6.6,4.67]],"id":52671547}],"con":true,"img":false}]}
{"op":"mcm","clk":"11450558562","pt":1717323315641,"mc":[{"id":"1.229554923","rc":[{"atb":[[22,7.62]],"id":52671551}],"con":true,"img":false}]}
{"op":"mcm","clk":"11450558975","pt":1717323319360,"mc":[{"id":"1.229554923","rc":[{"atl":[[44,8.73]],"id":52671561}],"con":true,"img":false}]}
{"op":"mcm","clk":"11450559955","pt":1717323328266,"mc":[{"id":"1.229554923","rc":[{"atb":[[30,10.53]],"id":52671551}],"con":true,"img":false}]}
{"op":"mcm","clk":"11450560036","pt":1717323328947,"mc":[{"id":"1.229554923","rc":[{"atb":[[22,0],[30,5]],"id":52671551}],"con":true,"img":false}]}
{"op":"mcm","clk":"11450560125","pt":1717323329673,"mc":[{"id":"1.229554923","rc":[{"atb":[[25,6.67]],"id":52671551}],"con":true,"img":false}]}
{"op":"mcm","clk":"11450560648","pt":1717323333979,"mc":[{"id":"1.229554923","rc":[{"atb":[[28,0]],"id":52671562},{"atb":[[21,5.08],[22,0]],"id":52671565},{"atb":[[18,0]],"id":52671555},{"atb":[[23,4.37],[24,0]],"id":52671551},{"atb":[[4.1,0],[4.2,4.9]],"id":52671550},{"atb":[[5.5,3.1],[5.4,0]],"id":52671547},{"atb":[[4.8,0],[4.9,2.73]],"id":52671546},{"atb":[[6.2,0]],"id":52671543},{"atb":[[4,0],[4.2,21.26]],"id":52671542}],"con":true,"img":false}]}
{"op":"mcm","clk":"11450560662","pt":1717323334083,"mc":[{"id":"1.229554923","rc":[{"atb":[[6.4,4.07]],"id":52671543}],"con":true,"img":false}]}
{"op":"mcm","clk":"11450561050","pt":1717323337491,"mc":[{"id":"1.229554923","rc":[{"atb":[[110,0]],"id":52671563},{"atb":[[34,4.85],[36,5]],"id":52671562},{"atl":[[7.6,5],[7.8,15.05]],"id":52671550},{"atb":[[6.4,5],[6.2,15.39]],"id":52671546},{"atl":[[7.8,21.64]],"id":52671542}],"con":true,"img":false}]}
{"op":"mcm","clk":"11450561063","pt":1717323337567,"mc":[{"id":"1.229554923","rc":[{"atb":[[120,6.57]],"id":52671563},{"atb":[[25,6.67],[27,5]],"id":52671565},{"atb":[[22,0],[24,5]],"id":52671561},{"atb":[[27,0],[28,5]],"id":52671560},{"atb":[[23,7.28],[25,5]],"id":52671555},{"atb":[[32,5],[30,0]],"id":52671551},{"atb":[[9.6,5],[9.4,14.37]],"id":52671553},{"atl":[[100,5],[110,4.32]],"id":52671549},{"atl":[[7.6,5]],"id":52671542},{"atb":[[50,0],[55,5]],"id":52671545}],"con":true,"img":false}]}
{"op":"mcm","clk":"11450561093","pt":1717323337873,"mc":[{"id":"1.229554923","rc":[{"atl":[[7.4,25.03]],"id":52671550}],"con":true,"img":false}]}
{"op":"mcm","clk":"11450561106","pt":1717323337977,"mc":[{"id":"1.229554923","rc":[{"atb":[[38,4.33]],"id":52671562},{"atb":[[6.6,15.39]],"id":52671546}],"con":true,"img":false}]}
{"op":"mcm","clk":"11450561113","pt":1717323338078,"mc":[{"id":"1.229554923","rc":[{"atb":[[28,5.93]],"id":52671565},{"atb":[[26,6.4]],"id":52671555},{"atb":[[9.6,23.63]],"id":52671553},{"atl":[[95,1.7]],"id":52671549},{"atl":[[7.6,29.28]],"id":52671542}],"con":true,"img":false}]}
{"op":"mcm","clk":"11450561167","pt":1717323338608,"mc":[{"id":"1.229554923","rc":[{"atb":[[28,3.65]],"id":52671562},{"atb":[[18,3.42]],"id":52671555},{"atl":[[16.5,5],[17,3.45]],"id":52671553}],"con":true,"img":false}]}
{"op":"mcm","clk":"11450561178","pt":1717323338662,"mc":[{"id":"1.229554923","rc":[{"atb":[[34,0]],"id":52671562},{"atl":[[7.8,0]],"id":52671550},{"atb":[[6.2,0]],"id":52671546}],"con":true,"img":false}]}
{"op":"mcm","clk":"11450561191","pt":1717323338761,"mc":[{"id":"1.229554923","rc":[{"atb":[[25,0]],"id":52671565},{"atb":[[23,0]],"id":52671555},{"atb":[[9.4,0]],"id":52671553},{"atl":[[110,2.85]],"id":52671549},{"atl":[[7.8,0]],"id":52671542}],"con":true,"img":false}]}
{"op":"mcm","clk":"11450561570","pt":1717323342297,"mc":[{"id":"1.229554923","rc":[{"atb":[[32,10.17]],"id":52671551}],"con":true,"img":false}]}
{"op":"mcm","clk":"11450561650","pt":1717323342988,"mc":[{"id":"1.229554923","rc":[{"atb":[[25,0]],"id":52671551}],"con":true,"img":false}]}
{"op":"mcm","clk":"11450561706","pt":1717323343464,"mc":[{"id":"1.229554923","rc":[{"atb":[[21,1.31],[22,2.87]],"id":52671565},{"atb":[[23,0],[24,3.45]],"id":52671551},{"atb":[[4.1,5.06],[4.2,0]],"id":52671550},{"atb":[[5.5,0],[5.4,3.57]],"id":52671547},{"atb":[[4.9,0]],"id":52671546},{"atb":[[6.4,0],[6.2,3.26]],"id":52671543},{"atb":[[4,5.23],[4.2,16.35]],"id":52671542}],"con":true,"img":false}]}
{"op":"mcm","clk":"11450561728","pt":1717323343674,"mc":[{"id":"1.229554923","rc":[{"atb":[[48,0],[29,0]],"id":52671563},{"atb":[[16,0],[11,0]],"id":52671562},{"atb":[[13.5,0],[9.4,0]],"id":52671565},{"atb":[[380,0],[480,0]],"id":52671564},{"atb":[[8.6,0],[11.5,4.04]],"id":52671561},{"atb":[[13.5,0],[9.4,0]],"id":52671560},{"atb":[[11,10.46],[8.4,0]],"id":52671555},{"atb":[[260,0],[160,5]],"id":52671554},{"atb":[[18,0],[13,4.7]],"id":52671556},{"atb":[[13.5,4.19],[9.4,12.46]],"id":52671551},{"atb":[[3.2,0],[2.88,0]],"id":52671550},{"atb":[[4.6,0],[3.8,0]],"id":52671553},{"atb":[[20,0],[15,0]],"id":52671552},{"atb":[[3.85,0],[3.35,0]],"id":52671547},{"atb":[[3.6,0],[3.1,0]],"id":52671546},{"atb":[[16,0],[11,0]],"id":52671549},{"atb":[[7.4,0],[9.4,0]],"id":52671548},{"atb":[[4.6,0],[3.8,0]],"id":52671543},{"atb":[[2.86,0],[3.15,0]],"id":52671542},{"atb":[[18,0],[13,0]],"id":52671545},{"atb":[[10.5,5.51],[8.2,14.53]],"id":52671544}],"con":true,"img":false}]}
{"op":"mcm","clk":"11450561783","pt":1717323344086,"mc":[{"id":"1.229554923","rc":[{"atb":[[180,0.89]],"id":52671564},{"atb":[[170,0.94]],"id":52671554}],"con":true,"img":false}]}
{"op":"mcm","clk":"11450561868","pt":1717323344771,"mc":[{"id":"1.229554923","rc":[{"atb":[[4.1,0],[4.2,4.9]],"id":52671550},{"atb":[[5.4,0]],"id":52671547},{"atb":[[4.9,4.54]],"id":52671546}],"con":true,"img":false}]}
