{"op":"mcm","clk":"11448127652","pt":1717286034988,"mc":[{"id":"1.229554895","marketDefinition":{"bspMarket":true,"turnInPlayEnabled":false,"persistenceEnabled":false,"marketBaseRate":7.0,"eventId":"33318908","eventTypeId":"4339","numberOfWinners":1,"bettingType":"ODDS","marketType":"WIN","marketTime":"2024-06-02T08:41:00.000Z","suspendTime":"2024-06-02T08:41:00.000Z","bspReconciled":false,"complete":true,"inPlay":false,"crossMatching":true,"runnersVoidable":false,"numberOfActiveRunners":5,"betDelay":0,"status":"OPEN","runners":[{"status":"ACTIVE","sortPriority":1,"id":58069703,"name":"1. Dookie"},{"status":"ACTIVE","sortPriority":2,"id":65732558,"name":"2. All The Sass"},{"status":"ACTIVE","sortPriority":3,"id":63161712,"name":"4. Dirty Dash"},{"status":"ACTIVE","sortPriority":4,"id":61028210,"name":"6. Banjo Bob"},{"status":"ACTIVE","sortPriority":5,"id":50605162,"name":"8. Boy From Hill"}],"regulators":["MR_INT"],"venue":"Murray Bridge","countryCode":"AU","discountAllowed":true,"timezone":"Australia/Adelaide","openDate":"2024-06-02T08:21:00.000Z","version":5962317638,"name":"R2 395m Rest","eventName":"Murray Bridge (AUS) 2nd Jun"},"rc":[],"con":true,"img":false}]}
{"op":"mcm","clk":"11448232696","pt":1717287558861,"mc":[{"id":"1.229554895","rc":[{"atl":[[2.66,2.61]],"id":63161712},{"spn":1.0,"spf":"NaN","id":63161712}],"con":true,"img":false}]}
{"op":"mcm","clk":"11448254110","pt":1717287816975,"mc":[{"id":"1.229554895","rc":[{"atb":[[1.73,143.19],[1.63,331.84],[1.68,307.44]],"id":63161712},{"atl":[[4,46.45],[5,52.26]],"id":63161712},{"spn":2.19,"spf":"NaN","id":63161712},{"atb":[[7.4,32.66],[8.4,28.25],[9.4,12.44]],"id":58069703},{"atl":[[140,1],[240,0.87]],"id":58069703},{"spn":74.7,"spf":"NaN","id":58069703},{"atb":[[17,13.06],[19.5,5.65],[14.5,15.48]],"id":50605162},{"atl":[[300,0.46],[400,0.52]],"id":50605162},{"spn":159.75,"spf":"NaN","id":50605162},{"atb":[[2.02,204.95],[2.12,93.32],[1.96,217.77]],"id":65732558},{"atl":[[6.8,24.02],[8.8,26.8]],"id":65732558},{"spn":4.46,"spf":"NaN","id":65732558},{"atb":[[4.8,55.01],[4.3,63.35],[5.3,24.31]],"id":61028210},{"atl":[[44,4.86],[27,5.36]],"id":61028210},{"spn":16.15,"spf":"NaN","id":61028210}],"con":true,"img":false}]}
{"op":"mcm","clk":"11448254823","pt":1717287826180,"mc":[{"id":"1.229554895","rc":[{"atb":[[1.73,0],[1.63,0],[1.68,0]],"id":63161712},{"atl":[[4,0],[5,0]],"id":63161712},{"atb":[[7.4,0],[8.4,0],[9.4,0]],"id":58069703},{"atl":[[140,0],[240,0]],"id":58069703},{"atb":[[2.02,0],[2.12,0],[1.96,0]],"id":65732558},{"atl":[[6.8,0],[8.8,0]],"id":65732558},{"atb":[[4.8,0],[4.3,0],[5.3,0]],"id":61028210},{"atl":[[44,0],[27,0]],"id":61028210}],"con":true,"img":false}]}
{"op":"mcm","clk":"11448255283","pt":1717287833098,"mc":[{"id":"1.229554895","rc":[{"atb":[[1.73,143.19],[1.63,331.84],[1.68,307.44]],"id":63161712},{"atl":[[4,46.45],[5,52.26]],"id":63161712},{"atb":[[7.4,32.66],[8.4,28.25],[9.4,12.44]],"id":58069703},{"atl":[[140,1],[240,0.87]],"id":58069703},{"atb":[[1.99,211.17],[1.94,222.4],[2.08,96.78]],"id":65732558},{"atl":[[8.6,27.5],[6.6,24.88]],"id":65732558},{"atb":[[4.8,55.01],[4.3,63.35],[5.3,24.31]],"id":61028210},{"atl":[[44,4.86],[27,5.36]],"id":61028210}],"con":true,"img":false}]}
{"op":"mcm","clk":"11448255868","pt":1717287841600,"mc":[{"id":"1.229554895","rc":[{"atb":[[17,0],[19.5,0],[14.5,0]],"id":50605162},{"atl":[[300,0],[400,0]],"id":50605162}],"con":true,"img":false}]}
{"op":"mcm","clk":"11448256290","pt":1717287847599,"mc":[{"id":"1.229554895","rc":[{"atb":[[17,13.06],[19.5,5.65],[14.5,15.48]],"id":50605162},{"atl":[[300,0.46],[400,0.52]],"id":50605162}],"con":true,"img":false}]}
{"op":"mcm","clk":"11448257231","pt":1717287860833,"mc":[{"id":"1.229554895","rc":[{"atb":[[1.73,0],[1.63,0],[1.68,0]],"id":63161712},{"atl":[[4,0],[5,0]],"id":63161712},{"atb":[[7.4,0],[8.4,0],[9.4,0]],"id":58069703},{"atl":[[140,0],[240,0]],"id":58069703},{"atb":[[17,0],[19.5,0],[14.5,0]],"id":50605162},{"atl":[[300,0],[400,0]],"id":50605162},{"atb":[[1.99,0],[1.94,0],[2.08,0]],"id":65732558},{"atl":[[8.6,0],[6.6,0]],"id":65732558},{"atb":[[4.8,0],[4.3,0],[5.3,0]],"id":61028210},{"atl":[[44,0],[27,0]],"id":61028210}],"con":true,"img":false}]}
{"op":"mcm","clk":"11448258036","pt":1717287872067,"mc":[{"id":"1.229554895","rc":[{"atb":[[1.43,486.18],[1.48,217.77],[1.38,550.16]],"id":63161712},{"atl":[[3.45,85.33],[2.98,70.39]],"id":63161712},{"atb":[[9.2,25.49],[10.5,11],[8.2,29.03]],"id":58069703},{"atl":[[280,0.74],[180,0.77]],"id":58069703},{"atb":[[17,13.06],[19.5,11.3],[24,4.54]],"id":50605162},{"atl":[[340,0.41],[440,0.47]],"id":50605162},{"atb":[[1.99,211.17],[1.94,222.4],[2.08,96.78]],"id":65732558},{"atl":[[8.6,27.5],[6.6,24.88]],"id":65732558},{"atb":[[5.6,22.72],[5.1,50.98],[4.6,58.07]],"id":61028210},{"atl":[[46,4.64],[28,5.16]],"id":61028210}],"con":true,"img":false}]}
{"op":"mcm","clk":"11448259639","pt":1717287895189,"mc":[{"id":"1.229554895","rc":[{"atb":[[1.43,0],[1.48,0],[1.38,0]],"id":63161712},{"atl":[[3.45,0],[2.98,0]],"id":63161712},{"spn":1.0,"spf":"NaN","id":63161712},{"atb":[[9.2,0],[10.5,0],[8.2,0]],"id":58069703},{"atl":[[280,0],[180,0]],"id":58069703},{"spn":"NaN","spf":"NaN","id":58069703},{"atb":[[17,0],[19.5,0],[24,0]],"id":50605162},{"atl":[[340,0],[440,0]],"id":50605162},{"spn":"NaN","spf":"NaN","id":50605162},{"atb":[[1.99,0],[1.94,0],[2.08,0]],"id":65732558},{"atl":[[8.6,0],[6.6,0]],"id":65732558},{"spn":"NaN","spf":"NaN","id":65732558},{"atb":[[5.6,0],[5.1,0],[4.6,0]],"id":61028210},{"atl":[[46,0],[28,0]],"id":61028210},{"spn":"NaN","spf":"NaN","id":61028210}],"con":true,"img":false}]}
{"op":"mcm","clk":"11448260594","pt":1717287908430,"mc":[{"id":"1.229554895","rc":[{"atb":[[1.43,486.18],[1.48,217.77],[1.38,550.16]],"id":63161712},{"atl":[[3.45,85.33],[2.98,70.39]],"id":63161712},{"atb":[[9.2,25.49],[10.5,11],[8.2,29.03]],"id":58069703},{"atl":[[280,0.74],[180,0.77]],"id":58069703},{"atb":[[16,13.93],[18.5,11.94],[22,4.97]],"id":50605162},{"atl":[[320,0.43],[420,0.49]],"id":50605162},{"atb":[[1.99,211.17],[1.94,222.4],[2.08,96.78]],"id":65732558},{"atl":[[8.6,27.5],[6.6,24.88]],"id":65732558},{"atb":[[5.6,22.72],[5.1,50.98],[4.6,58.07]],"id":61028210},{"atl":[[46,4.64],[28,5.16]],"id":61028210}],"con":true,"img":false}]}
{"op":"mcm","clk":"11448262185","pt":1717287930028,"mc":[{"id":"1.229554895","rc":[{"atb":[[1.99,0],[1.94,0],[2.08,0]],"id":65732558},{"atl":[[8.6,0],[6.6,0]],"id":65732558}],"con":true,"img":false}]}
{"op":"mcm","clk":"11448262804","pt":1717287939632,"mc":[{"id":"1.229554895","rc":[{"atb":[[2.02,204.95],[2.12,93.32],[1.96,217.77]],"id":65732558},{"atl":[[6.8,24.02],[8.8,26.8]],"id":65732558}],"con":true,"img":false}]}
{"op":"mcm","clk":"11448264303","pt":1717287962255,"mc":[{"id":"1.229554895","rc":[{"spn":2.07,"spf":"NaN","id":63161712},{"atb":[[9.2,0],[10.5,0],[8.2,0]],"id":58069703},{"atl":[[280,0],[180,0]],"id":58069703},{"spn":171.0,"spf":"NaN","id":50605162},{"atb":[[2.02,0],[2.12,0],[1.96,0]],"id":65732558},{"atl":[[6.8,0],[8.8,0]],"id":65732558},{"atb":[[5.6,0],[5.1,0],[4.6,0]],"id":61028210},{"atl":[[46,0],[28,0]],"id":61028210}],"con":true,"img":false}]}
{"op":"mcm","clk":"11448265018","pt":1717287972318,"mc":[{"id":"1.229554895","rc":[{"atb":[[9.2,25.49],[10.5,11],[8.2,29.03]],"id":58069703},{"atl":[[280,0.74],[180,0.77]],"id":58069703},{"atb":[[2.06,197.22],[1.98,213.33],[2.16,90.11]],"id":65732558},{"atl":[[9,26.13],[7,23.22]],"id":65732558},{"atb":[[5.6,22.72],[5.1,50.98],[4.6,58.07]],"id":61028210},{"atl":[[46,4.64],[28,5.16]],"id":61028210}],"con":true,"img":false}]}
{"op":"mcm","clk":"11448270133","pt":1717288057118,"mc":[{"id":"1.229554895","rc":[{"atb":[[1.43,0],[1.48,0],[1.38,0]],"id":63161712},{"atl":[[3.45,0],[2.98,0]],"id":63161712},{"spn":1.0,"spf":"NaN","id":63161712},{"atb":[[9.2,0],[10.5,0],[8.2,0]],"id":58069703},{"atl":[[280,0],[180,0]],"id":58069703},{"atb":[[16,0],[18.5,0],[22,0]],"id":50605162},{"atl":[[320,0],[420,0]],"id":50605162},{"spn":"NaN","spf":"NaN","id":50605162},{"atb":[[2.06,0],[1.98,0],[2.16,0]],"id":65732558},{"atl":[[9,0],[7,0]],"id":65732558},{"atb":[[5.6,0],[5.1,0],[4.6,0]],"id":61028210},{"atl":[[46,0],[28,0]],"id":61028210}],"con":true,"img":false}]}
{"op":"mcm","clk":"11448270978","pt":1717288067734,"mc":[{"id":"1.229554895","rc":[{"atb":[[1.43,486.18],[1.48,217.77],[1.38,550.16]],"id":63161712},{"atl":[[3.45,85.33],[2.98,70.39]],"id":63161712},{"atb":[[9.6,24.31],[8.6,27.5],[11.5,9.95]],"id":58069703},{"atl":[[300,0.7],[200,0.7]],"id":58069703},{"atb":[[16,13.93],[18.5,11.94],[22,4.97]],"id":50605162},{"atl":[[320,0.43],[420,0.49]],"id":50605162},{"atb":[[2.06,197.22],[1.98,213.33],[2.16,90.11]],"id":65732558},{"atl":[[9,26.13],[7,23.22]],"id":65732558},{"atb":[[4.8,55.01],[5.8,21.77],[5.3,48.61]],"id":61028210},{"atl":[[48,4.44],[29,4.97]],"id":61028210}],"con":true,"img":false}]}
{"op":"mcm","clk":"11448277214","pt":1717288128427,"mc":[{"id":"1.229554895","marketDefinition":{"bspMarket":true,"turnInPlayEnabled":false,"persistenceEnabled":false,"marketBaseRate":7.0,"eventId":"33318908","eventTypeId":"4339","numberOfWinners":1,"bettingType":"ODDS","marketType":"WIN","marketTime":"2024-06-02T08:41:00.000Z","suspendTime":"2024-06-02T08:41:00.000Z","bspReconciled":false,"complete":true,"inPlay":false,"crossMatching":true,"runnersVoidable":false,"numberOfActiveRunners":5,"betDelay":0,"status":"OPEN","runners":[{"status":"ACTIVE","sortPriority":1,"id":58069703,"name":"1. Dookie"},{"status":"ACTIVE","sortPriority":2,"id":65732558,"name":"2. All The Sass"},{"status":"ACTIVE","sortPriority":3,"id":63161712,"name":"4. Dirty Dash"},{"status":"ACTIVE","sortPriority":4,"id":61028210,"name":"6. Banjo Bob"},{"status":"ACTIVE","sortPriority":5,"id":50605162,"name":"8. Boy From Hill"}],"regulators":["MR_INT"],"venue":"Murray Bridge","countryCode":"AU","discountAllowed":true,"timezone":"Australia/Adelaide","openDate":"2024-06-02T08:21:00.000Z","version":5962317638,"name":"R2 395m Rest","eventName":"Murray Bridge (AUS) 2nd Jun"},"rc":[{"atb":[[1.43,486.18],[1.48,217.77],[1.38,550.16]],"id":63161712},{"atl":[[3.45,85.33],[2.66,2.61],[2.98,70.39]],"id":63161712},{"spn":2.07,"spf":"NaN","id":63161712},{"atb":[[9.6,24.31],[8.6,27.5],[11.5,9.95]],"id":58069703},{"atl":[[300,0.7],[200,0.7]],"id":58069703},{"spn":105.75,"spf":"NaN","id":58069703},{"atb":[[16,13.93],[18.5,11.94],[22,4.97]],"id":50605162},{"atl":[[320,0.43],[420,0.49]],"id":50605162},{"spn":171.0,"spf":"NaN","id":50605162},{"atb":[[2.06,197.22],[1.98,213.33],[2.16,90.11]],"id":65732558},{"atl":[[9,26.13],[7,23.22]],"id":65732558},{"spn":4.58,"spf":"NaN","id":65732558},{"atb":[[4.8,55.01],[5.8,21.77],[5.3,48.61]],"id":61028210},{"atl":[[48,4.44],[29,4.97]],"id":61028210},{"spn":17.4,"spf":"NaN","id":61028210}],"con":true,"img":true}]}
{"op":"mcm","clk":"11448289491","pt":1717288232485,"mc":[{"id":"1.229554895","rc":[{"atb":[[1.43,0],[1.48,0],[1.38,0]],"id":63161712},{"atl":[[3.45,0],[2.98,0]],"id":63161712},{"atb":[[9.6,0],[8.6,0],[11.5,0]],"id":58069703},{"atl":[[300,0],[200,0]],"id":58069703},{"spn":171.0,"spf":"NaN","id":50605162},{"atb":[[2.06,0],[1.98,0],[2.16,0]],"id":65732558},{"atl":[[9,0],[7,0]],"id":65732558},{"atb":[[4.8,0],[5.8,0],[5.3,0]],"id":61028210},{"atl":[[48,0],[29,0]],"id":61028210}],"con":true,"img":false}]}
{"op":"mcm","clk":"11448290414","pt":1717288245743,"mc":[{"id":"1.229554895","rc":[{"atb":[[1.43,486.18],[1.48,217.77],[1.38,550.16]],"id":63161712},{"atl":[[3.45,85.33],[2.98,70.39]],"id":63161712},{"atb":[[9.6,24.31],[8.6,27.5],[11.5,9.95]],"id":58069703},{"atl":[[300,0.7],[200,0.7]],"id":58069703},{"atb":[[1.99,211.17],[1.94,222.4],[2.08,96.78]],"id":65732558},{"atl":[[8.6,27.5],[6.6,24.88]],"id":65732558},{"atb":[[4.8,55.01],[5.8,21.77],[5.3,48.61]],"id":61028210},{"atl":[[48,4.44],[29,4.97]],"id":61028210}],"con":true,"img":false}]}
{"op":"mcm","clk":"11448292450","pt":1717288273746,"mc":[{"id":"1.229554895","rc":[{"atb":[[1.43,0],[1.48,0],[1.38,0]],"id":63161712},{"atl":[[3.45,0],[2.98,0]],"id":63161712},{"atb":[[9.6,0],[8.6,0],[11.5,0]],"id":58069703},{"atl":[[300,0],[200,0]],"id":58069703},{"atb":[[16,0],[18.5,0],[22,0]],"id":50605162},{"atl":[[320,0],[420,0]],"id":50605162},{"atb":[[1.99,0],[1.94,0],[2.08,0]],"id":65732558},{"atl":[[8.6,0],[6.6,0]],"id":65732558},{"atb":[[4.8,0],[5.8,0],[5.3,0]],"id":61028210},{"atl":[[48,0],[29,0]],"id":61028210}],"con":true,"img":false}]}
{"op":"mcm","clk":"11448293804","pt":1717288291623,"mc":[{"id":"1.229554895","rc":[{"atb":[[1.43,486.18],[1.48,217.77],[1.38,550.16]],"id":63161712},{"atl":[[3.45,85.33],[2.98,70.39]],"id":63161712},{"atb":[[9,26.13],[10,23.22],[12.5,9.08]],"id":58069703},{"atl":[[310,0.67],[210,0.66]],"id":58069703},{"atb":[[16,13.93],[18.5,11.94],[22,4.97]],"id":50605162},{"atl":[[320,0.43],[420,0.49]],"id":50605162},{"atb":[[1.99,211.17],[1.94,222.4],[2.08,96.78]],"id":65732558},{"atl":[[8.6,27.5],[6.6,24.88]],"id":65732558},{"atb":[[5.6,45.44],[5.1,50.98],[6.2,20.1]],"id":61028210},{"atl":[[70,3.02],[38,3.76]],"id":61028210}],"con":true,"img":false}]}
{"op":"mcm","clk":"11448298252","pt":1717288351176,"mc":[{"id":"1.229554895","rc":[{"spn":2.07,"spf":"NaN","id":63161712},{"atb":[[9,0],[10,0],[12.5,0]],"id":58069703},{"atl":[[310,0],[210,0]],"id":58069703},{"atb":[[1.99,0],[1.94,0],[2.08,0]],"id":65732558},{"atl":[[8.6,0],[6.6,0]],"id":65732558},{"atb":[[5.6,0],[5.1,0],[6.2,0]],"id":61028210},{"atl":[[70,0],[38,0]],"id":61028210}],"con":true,"img":false}]}
{"op":"mcm","clk":"11448300795","pt":1717288383947,"mc":[{"id":"1.229554895","rc":[{"atb":[[12,19],[9.8,23.75],[14.5,7.74]],"id":58069703},{"atl":[[330,0.63],[230,0.6]],"id":58069703},{"atb":[[1.99,211.17],[1.94,222.4],[2.08,96.78]],"id":65732558},{"atl":[[8.6,27.5],[6.6,24.88]],"id":65732558},{"atb":[[5.6,45.44],[5.1,50.98],[6.2,20.1]],"id":61028210},{"atl":[[70,3.02],[38,3.76]],"id":61028210}],"con":true,"img":false}]}
{"op":"mcm","clk":"11448470639","pt":1717290837881,"mc":[{"id":"1.229554895","rc":[{"atb":[[1.43,0],[1.48,0],[1.38,0]],"id":63161712},{"atl":[[3.45,0],[2.98,0]],"id":63161712},{"spn":1.0,"spf":"NaN","id":63161712},{"atb":[[12,0],[9.8,0],[14.5,0]],"id":58069703},{"atl":[[330,0],[230,0]],"id":58069703},{"atb":[[16,0],[18.5,0],[22,0]],"id":50605162},{"atl":[[320,0],[420,0]],"id":50605162},{"spn":"NaN","spf":"NaN","id":50605162},{"atb":[[1.99,0],[1.94,0],[2.08,0]],"id":65732558},{"atl":[[8.6,0],[6.6,0]],"id":65732558},{"atb":[[5.6,0],[5.1,0],[6.2,0]],"id":61028210},{"atl":[[70,0],[38,0]],"id":61028210}],"con":true,"img":false}]}
{"op":"mcm","clk":"11448471003","pt":1717290844005,"mc":[{"id":"1.229554895","rc":[{"atb":[[1.43,486.18],[1.48,217.77],[1.38,550.16]],"id":63161712},{"atl":[[3.45,85.33],[2.98,70.39]],"id":63161712},{"atb":[[12,19],[9.8,23.75],[14.5,7.74]],"id":58069703},{"atl":[[330,0.63],[230,0.6]],"id":58069703},{"atb":[[17.5,12.67],[20,11],[25,4.35]],"id":50605162},{"atl":[[350,0.39],[450,0.46]],"id":50605162},{"atb":[[1.99,211.17],[1.94,222.4],[2.08,96.78]],"id":65732558},{"atl":[[8.6,27.5],[6.6,24.88]],"id":65732558},{"atb":[[5.8,43.55],[5.3,48.61],[6.6,18.66]],"id":61028210},{"atl":[[95,2.22],[48,2.96]],"id":61028210}],"con":true,"img":false}]}
{"op":"mcm","clk":"11448472535","pt":1717290873858,"mc":[{"id":"1.229554895","rc":[{"atb":[[1.43,0],[1.48,0],[1.38,0]],"id":63161712},{"atl":[[3.45,0],[2.98,0]],"id":63161712},{"atb":[[12,0],[9.8,0],[14.5,0]],"id":58069703},{"atl":[[330,0],[230,0]],"id":58069703},{"atb":[[1.99,0],[1.94,0],[2.08,0]],"id":65732558},{"atl":[[8.6,0],[6.6,0]],"id":65732558},{"atb":[[5.8,0],[5.3,0],[6.6,0]],"id":61028210},{"atl":[[95,0],[48,0]],"id":61028210}],"con":true,"img":false}]}
{"op":"mcm","clk":"11448472839","pt":1717290879454,"mc":[{"id":"1.229554895","rc":[{"atb":[[1.43,486.18],[1.48,217.77],[1.38,550.16]],"id":63161712},{"atl":[[3.45,85.33],[2.98,70.39]],"id":63161712},{"atb":[[12,19],[9.8,23.75],[14.5,7.74]],"id":58069703},{"atl":[[330,0.63],[230,0.6]],"id":58069703},{"atb":[[1.99,211.17],[1.94,222.4],[2.08,96.78]],"id":65732558},{"atl":[[8.6,27.5],[6.6,24.88]],"id":65732558},{"atb":[[5.8,43.55],[5.3,48.61],[6.6,18.66]],"id":61028210},{"atl":[[95,2.22],[48,2.96]],"id":61028210}],"con":true,"img":false}]}
{"op":"mcm","clk":"11448473355","pt":1717290888050,"mc":[{"id":"1.229554895","rc":[{"atb":[[1.43,0],[1.48,0],[1.38,0]],"id":63161712},{"atl":[[3.45,0],[2.98,0]],"id":63161712},{"atb":[[12,0],[9.8,0],[14.5,0]],"id":58069703},{"atl":[[330,0],[230,0]],"id":58069703},{"atb":[[17.5,0],[20,0],[25,0]],"id":50605162},{"atl":[[350,0],[450,0]],"id":50605162},{"atb":[[1.99,0],[1.94,0],[2.08,0]],"id":65732558},{"atl":[[8.6,0],[6.6,0]],"id":65732558},{"atb":[[5.8,0],[5.3,0],[6.6,0]],"id":61028210},{"atl":[[95,0],[48,0]],"id":61028210}],"con":true,"img":false}]}
{"op":"mcm","clk":"11448473596","pt":1717290892695,"mc":[{"id":"1.229554895","rc":[{"atb":[[1.43,486.18],[1.48,217.77],[1.38,550.16]],"id":63161712},{"atl":[[3.45,85.33],[2.98,70.39]],"id":63161712},{"atb":[[12,19],[9.8,23.75],[14.5,7.74]],"id":58069703},{"atl":[[330,0.63],[230,0.6]],"id":58069703},{"atb":[[17.5,12.67],[20,11],[25,4.35]],"id":50605162},{"atl":[[350,0.39],[450,0.46]],"id":50605162},{"atb":[[1.99,211.17],[1.94,222.4],[2.08,96.78]],"id":65732558},{"atl":[[8.6,27.5],[6.6,24.88]],"id":65732558},{"atb":[[5.8,43.55],[5.3,48.61],[6.6,18.66]],"id":61028210},{"atl":[[95,2.22],[48,2.96]],"id":61028210}],"con":true,"img":false}]}
{"op":"mcm","clk":"11448474826","pt":1717290912477,"mc":[{"id":"1.229554895","rc":[{"spn":2.07,"spf":"NaN","id":63161712},{"atb":[[12,0],[9.8,0],[14.5,0]],"id":58069703},{"atl":[[330,0],[230,0]],"id":58069703},{"atb":[[17.5,0],[20,0],[25,0]],"id":50605162},{"atl":[[350,0],[450,0]],"id":50605162},{"spn":4.34,"spf":"NaN","id":65732558},{"atb":[[5.8,0],[5.3,0],[6.6,0]],"id":61028210},{"atl":[[95,0],[48,0]],"id":61028210}],"con":true,"img":false}]}
{"op":"mcm","clk":"11448475142","pt":1717290917393,"mc":[{"id":"1.229554895","rc":[{"atb":[[12,19],[9.8,23.75],[14.5,7.74]],"id":58069703},{"atl":[[330,0.63],[230,0.6]],"id":58069703},{"atb":[[17.5,12.67],[20,11],[25,4.35]],"id":50605162},{"atl":[[350,0.39],[450,0.46]],"id":50605162},{"atb":[[5.8,43.55],[5.3,48.61],[6.6,18.66]],"id":61028210},{"atl":[[95,2.22],[48,2.96]],"id":61028210}],"con":true,"img":false}]}
{"op":"mcm","clk":"11448476918","pt":1717290945627,"mc":[{"id":"1.229554895","rc":[{"atb":[[1.43,0],[1.48,0],[1.38,0]],"id":63161712},{"atl":[[3.45,0],[2.98,0]],"id":63161712},{"atb":[[12,0],[9.8,0],[14.5,0]],"id":58069703},{"atl":[[330,0],[230,0]],"id":58069703},{"atb":[[17.5,0],[20,0],[25,0]],"id":50605162},{"atl":[[350,0],[450,0]],"id":50605162},{"atb":[[1.99,0],[1.94,0],[2.08,0]],"id":65732558},{"atl":[[8.6,0],[6.6,0]],"id":65732558},{"atb":[[5.8,0],[5.3,0],[6.6,0]],"id":61028210},{"atl":[[95,0],[48,0]],"id":61028210}],"con":true,"img":false}]}
{"op":"mcm","clk":"11448477472","pt":1717290954640,"mc":[{"id":"1.229554895","rc":[{"atb":[[1.43,486.18],[1.48,217.77],[1.38,550.16]],"id":63161712},{"atl":[[3.45,85.33],[2.98,70.39]],"id":63161712},{"atb":[[16.5,6.74],[11.5,19.91],[14,16.08]],"id":58069703},{"atl":[[350,0.59],[250,0.55]],"id":58069703},{"atb":[[17.5,12.67],[20,11],[25,4.35]],"id":50605162},{"atl":[[350,0.39],[450,0.46]],"id":50605162},{"atb":[[1.99,211.17],[1.94,222.4],[2.08,96.78]],"id":65732558},{"atl":[[8.6,27.5],[6.6,24.88]],"id":65732558},{"atb":[[5.6,45.44],[7.2,16.86],[6.2,40.2]],"id":61028210},{"atl":[[65,2.17],[130,1.62]],"id":61028210}],"con":true,"img":false}]}
{"op":"mcm","clk":"11448629942","pt":1717293528418,"mc":[{"id":"1.229554895","marketDefinition":{"bspMarket":true,"turnInPlayEnabled":false,"persistenceEnabled":false,"marketBaseRate":7.0,"eventId":"33318908","eventTypeId":"4339","numberOfWinners":1,"bettingType":"ODDS","marketType":"WIN","marketTime":"2024-06-02T08:41:00.000Z","suspendTime":"2024-06-02T08:41:00.000Z","bspReconciled":false,"complete":true,"inPlay":false,"crossMatching":true,"runnersVoidable":false,"numberOfActiveRunners":5,"betDelay":0,"status":"OPEN","runners":[{"status":"ACTIVE","sortPriority":1,"id":58069703,"name":"1. Dookie"},{"status":"ACTIVE","sortPriority":2,"id":65732558,"name":"2. All The Sass"},{"status":"ACTIVE","sortPriority":3,"id":63161712,"name":"4. Dirty Dash"},{"status":"ACTIVE","sortPriority":4,"id":61028210,"name":"6. Banjo Bob"},{"status":"ACTIVE","sortPriority":5,"id":50605162,"name":"8. Boy From Hill"}],"regulators":["MR_INT"],"venue":"Murray Bridge","countryCode":"AU","discountAllowed":true,"timezone":"Australia/Adelaide","openDate":"2024-06-02T08:21:00.000Z","version":5962317638,"name":"R2 395m Rest","eventName":"Murray Bridge (AUS) 2nd Jun"},"rc":[{"atb":[[1.43,486.18],[1.48,217.77],[1.38,550.16]],"id":63161712},{"atl":[[3.45,85.33],[2.66,2.61],[2.98,70.39]],"id":63161712},{"spn":2.07,"spf":"NaN","id":63161712},{"atb":[[16.5,6.74],[11.5,19.91],[14,16.08]],"id":58069703},{"atl":[[350,0.59],[250,0.55]],"id":58069703},{"spn":133.25,"spf":"NaN","id":58069703},{"atb":[[17.5,12.67],[20,11],[25,4.35]],"id":50605162},{"atl":[[350,0.39],[450,0.46]],"id":50605162},{"spn":187.5,"spf":"NaN","id":50605162},{"atb":[[1.99,211.17],[1.94,222.4],[2.08,96.78]],"id":65732558},{"atl":[[8.6,27.5],[6.6,24.88]],"id":65732558},{"spn":4.34,"spf":"NaN","id":65732558},{"atb":[[5.6,45.44],[7.2,16.86],[6.2,40.2]],"id":61028210},{"atl":[[65,2.17],[130,1.62]],"id":61028210},{"spn":36.1,"spf":"NaN","id":61028210}],"con":true,"img":true}]}
{"op":"mcm","clk":"11448953481","pt":1717300705899,"mc":[{"id":"1.229554895","rc":[{"atb":[[1.43,0],[1.48,0],[1.38,0]],"id":63161712},{"atl":[[3.45,0],[2.98,0]],"id":63161712},{"spn":1.0,"spf":"NaN","id":63161712},{"atb":[[16.5,0],[11.5,0],[14,0]],"id":58069703},{"atl":[[350,0],[250,0]],"id":58069703},{"atb":[[17.5,0],[20,0],[25,0]],"id":50605162},{"atl":[[350,0],[450,0]],"id":50605162},{"atb":[[1.99,0],[1.94,0],[2.08,0]],"id":65732558},{"atl":[[8.6,0],[6.6,0]],"id":65732558},{"spn":"NaN","spf":"NaN","id":65732558},{"atb":[[5.6,0],[7.2,0],[6.2,0]],"id":61028210},{"atl":[[65,0],[130,0]],"id":61028210}],"con":true,"img":false}]}
{"op":"mcm","clk":"11448954095","pt":1717300723513,"mc":[{"id":"1.229554895","rc":[{"atb":[[1.43,243.09],[1.33,633.51],[1.38,550.16]],"id":63161712},{"atl":[[2.9,73.35],[3.25,92.91]],"id":63161712},{"atb":[[16.5,6.74],[11.5,19.91],[14,16.08]],"id":58069703},{"atl":[[350,0.59],[250,0.55]],"id":58069703},{"atb":[[17.5,12.67],[20,11],[25,4.35]],"id":50605162},{"atl":[[350,0.39],[450,0.46]],"id":50605162},{"atb":[[1.99,211.17],[1.94,222.4],[2.08,96.78]],"id":65732558},{"atl":[[8.6,27.5],[6.6,24.88]],"id":65732558},{"atb":[[5.6,45.44],[7.2,16.86],[6.2,40.2]],"id":61028210},{"atl":[[65,2.17],[130,1.62]],"id":61028210}],"con":true,"img":false}]}
{"op":"mcm","clk":"11448957695","pt":1717300804910,"mc":[{"id":"1.229554895","rc":[{"atb":[[1.43,0],[1.33,0],[1.38,0]],"id":63161712},{"atl":[[2.9,0],[3.25,0]],"id":63161712},{"atb":[[16.5,0],[11.5,0],[14,0]],"id":58069703},{"atl":[[350,0],[250,0]],"id":58069703},{"atb":[[17.5,0],[20,0],[25,0]],"id":50605162},{"atl":[[350,0],[450,0]],"id":50605162},{"atb":[[1.99,0],[1.94,0],[2.08,0]],"id":65732558},{"atl":[[8.6,0],[6.6,0]],"id":65732558},{"atb":[[5.6,0],[7.2,0],[6.2,0]],"id":61028210},{"atl":[[65,0],[130,0]],"id":61028210}],"con":true,"img":false}]}
{"op":"mcm","clk":"11448958449","pt":1717300819077,"mc":[{"id":"1.229554895","rc":[{"atb":[[1.43,243.09],[1.33,633.51],[1.38,550.16]],"id":63161712},{"atl":[[2.9,73.35],[3.25,92.91]],"id":63161712},{"atb":[[16.5,6.74],[11.5,19.91],[14,16.08]],"id":58069703},{"atl":[[350,0.59],[250,0.55]],"id":58069703},{"atb":[[19.5,11.3],[24,9.08],[29,3.73]],"id":50605162},{"atl":[[400,0.35],[500,0.41]],"id":50605162},{"atb":[[2.02,204.95],[2.12,93.32],[1.96,217.77]],"id":65732558},{"atl":[[6.8,24.02],[8.8,26.8]],"id":65732558},{"atb":[[8.6,13.75],[7.6,31.67],[6.6,37.33]],"id":61028210},{"atl":[[100,1.4],[200,1.05]],"id":61028210}],"con":true,"img":false}]}
{"op":"mcm","clk":"11448963900","pt":1717300914219,"mc":[{"id":"1.229554895","rc":[{"atb":[[1.43,0],[1.33,0],[1.38,0]],"id":63161712},{"atl":[[2.9,0],[3.25,0]],"id":63161712},{"atb":[[16.5,0],[11.5,0],[14,0]],"id":58069703},{"atl":[[350,0],[250,0]],"id":58069703},{"atb":[[19.5,0],[24,0],[29,0]],"id":50605162},{"atl":[[400,0],[500,0]],"id":50605162},{"atb":[[2.02,0],[2.12,0],[1.96,0]],"id":65732558},{"atl":[[6.8,0],[8.8,0]],"id":65732558},{"atb":[[8.6,0],[7.6,0],[6.6,0]],"id":61028210},{"atl":[[100,0],[200,0]],"id":61028210}],"con":true,"img":false}]}
{"op":"mcm","clk":"11448965590","pt":1717300946049,"mc":[{"id":"1.229554895","rc":[{"atb":[[1.43,243.09],[1.33,633.51],[1.38,550.16]],"id":63161712},{"atl":[[2.9,73.35],[3.25,92.91]],"id":63161712},{"atb":[[16.5,6.74],[11.5,19.91],[14,16.08]],"id":58069703},{"atl":[[350,0.59],[250,0.55]],"id":58069703},{"atb":[[19.5,11.3],[24,9.08],[29,3.73]],"id":50605162},{"atl":[[400,0.35],[500,0.41]],"id":50605162},{"atb":[[2.06,197.22],[1.98,213.33],[2.16,90.11]],"id":65732558},{"atl":[[9,26.13],[7,23.22]],"id":65732558},{"atb":[[8.6,13.75],[7.6,31.67],[6.6,37.33]],"id":61028210},{"atl":[[100,1.4],[200,1.05]],"id":61028210}],"con":true,"img":false}]}
{"op":"mcm","clk":"11449119128","pt":1717304328430,"mc":[{"id":"1.229554895","marketDefinition":{"bspMarket":true,"turnInPlayEnabled":false,"persistenceEnabled":false,"marketBaseRate":7.0,"eventId":"33318908","eventTypeId":"4339","numberOfWinners":1,"bettingType":"ODDS","marketType":"WIN","marketTime":"2024-06-02T08:41:00.000Z","suspendTime":"2024-06-02T08:41:00.000Z","bspReconciled":false,"complete":true,"inPlay":false,"crossMatching":true,"runnersVoidable":false,"numberOfActiveRunners":5,"betDelay":0,"status":"OPEN","runners":[{"status":"ACTIVE","sortPriority":1,"id":58069703,"name":"1. Dookie"},{"status":"ACTIVE","sortPriority":2,"id":65732558,"name":"2. All The Sass"},{"status":"ACTIVE","sortPriority":3,"id":63161712,"name":"4. Dirty Dash"},{"status":"ACTIVE","sortPriority":4,"id":61028210,"name":"6. Banjo Bob"},{"status":"ACTIVE","sortPriority":5,"id":50605162,"name":"8. Boy From Hill"}],"regulators":["MR_INT"],"venue":"Murray Bridge","countryCode":"AU","discountAllowed":true,"timezone":"Australia/Adelaide","openDate":"2024-06-02T08:21:00.000Z","version":5962317638,"name":"R2 395m Rest","eventName":"Murray Bridge (AUS) 2nd Jun"},"rc":[{"atb":[[1.43,243.09],[1.33,633.51],[1.38,550.16]],"id":63161712},{"atl":[[2.9,73.35],[2.66,2.61],[3.25,92.91]],"id":63161712},{"spn":2.04,"spf":"NaN","id":63161712},{"atb":[[16.5,6.74],[11.5,19.91],[14,16.08]],"id":58069703},{"atl":[[350,0.59],[250,0.55]],"id":58069703},{"spn":133.25,"spf":"NaN","id":58069703},{"atb":[[19.5,11.3],[24,9.08],[29,3.73]],"id":50605162},{"atl":[[400,0.35],[500,0.41]],"id":50605162},{"spn":214.5,"spf":"NaN","id":50605162},{"atb":[[2.06,197.22],[1.98,213.33],[2.16,90.11]],"id":65732558},{"atl":[[9,26.13],[7,23.22]],"id":65732558},{"spn":4.58,"spf":"NaN","id":65732558},{"atb":[[8.6,13.75],[7.6,31.67],[6.6,37.33]],"id":61028210},{"atl":[[100,1.4],[200,1.05]],"id":61028210},{"spn":54.3,"spf":"NaN","id":61028210}],"con":true,"img":true}]}
{"op":"mcm","clk":"11449166920","pt":1717305021756,"mc":[{"id":"1.229554895","rc":[{"atl":[[2,4.73]],"id":63161712},{"spn":1.71,"spf":"NaN","id":63161712},{"spn":133.25,"spf":"NaN","id":58069703},{"spn":214.5,"spf":"NaN","id":50605162},{"spn":4.58,"spf":"NaN","id":65732558},{"spn":54.3,"spf":"NaN","id":61028210}],"con":true,"img":false}]}
{"op":"mcm","clk":"11449308154","pt":1717306957803,"mc":[{"id":"1.229554895","rc":[{"atb":[[1.43,0],[1.33,0],[1.38,0]],"id":63161712},{"atl":[[2.9,0],[3.25,0]],"id":63161712},{"spn":1.0,"spf":"NaN","id":63161712},{"atb":[[2.06,0],[1.98,0],[2.16,0]],"id":65732558},{"atl":[[9,0],[7,0]],"id":65732558},{"spn":"NaN","spf":"NaN","id":65732558},{"atb":[[8.6,0],[7.6,0],[6.6,0]],"id":61028210},{"atl":[[100,0],[200,0]],"id":61028210},{"spn":"NaN","spf":"NaN","id":61028210}],"con":true,"img":false}]}
{"op":"mcm","clk":"11449308938","pt":1717306969019,"mc":[{"id":"1.229554895","rc":[{"atb":[[1.43,243.09],[1.33,633.51],[1.38,550.16]],"id":63161712},{"atl":[[2.9,73.35],[3.25,92.91]],"id":63161712},{"atb":[[2.06,197.22],[1.98,213.33],[2.16,90.11]],"id":65732558},{"atl":[[9,26.13],[7,23.22]],"id":65732558},{"atb":[[8,29.86],[9,13.06],[7,34.84]],"id":61028210},{"atl":[[210,0.99],[110,1.27]],"id":61028210}],"con":true,"img":false}]}
{"op":"mcm","clk":"11449311178","pt":1717307001724,"mc":[{"id":"1.229554895","rc":[{"atb":[[19.5,0],[24,0],[29,0]],"id":50605162},{"atl":[[400,0],[500,0]],"id":50605162}],"con":true,"img":false}]}
{"op":"mcm","clk":"11449313154","pt":1717307031054,"mc":[{"id":"1.229554895","rc":[{"spn":1.71,"spf":"NaN","id":63161712},{"atb":[[19.5,11.3],[24,9.08],[29,3.73]],"id":50605162},{"atl":[[400,0.35],[500,0.41]],"id":50605162},{"spn":4.58,"spf":"NaN","id":65732558},{"spn":59.5,"spf":"NaN","id":61028210}],"con":true,"img":false}]}
{"op":"mcm","clk":"11449319003","pt":1717307115740,"mc":[{"id":"1.229554895","rc":[{"atb":[[1.43,0],[1.33,0],[1.38,0]],"id":63161712},{"atl":[[2.9,0],[3.25,0]],"id":63161712},{"spn":1.0,"spf":"NaN","id":63161712},{"atb":[[2.06,0],[1.98,0],[2.16,0]],"id":65732558},{"atl":[[9,0],[7,0]],"id":65732558},{"spn":"NaN","spf":"NaN","id":65732558},{"atb":[[8,0],[9,0],[7,0]],"id":61028210},{"atl":[[210,0],[110,0]],"id":61028210},{"spn":"NaN","spf":"NaN","id":61028210}],"con":true,"img":false}]}
{"op":"mcm","clk":"11449319872","pt":1717307127037,"mc":[{"id":"1.229554895","rc":[{"atb":[[1.43,243.09],[1.33,633.51],[1.38,550.16]],"id":63161712},{"atl":[[2.9,73.35],[3.25,92.91]],"id":63161712},{"atb":[[2.02,204.95],[2.12,93.32],[1.96,217.77]],"id":65732558},{"atl":[[6.8,24.02],[8.8,26.8]],"id":65732558},{"atb":[[8,29.86],[9,13.06],[7,34.84]],"id":61028210},{"atl":[[210,0.99],[110,1.27]],"id":61028210}],"con":true,"img":false}]}
{"op":"mcm","clk":"11449321811","pt":1717307154679,"mc":[{"id":"1.229554895","rc":[{"atb":[[1.43,0],[1.33,0],[1.38,0]],"id":63161712},{"atl":[[2.9,0],[3.25,0]],"id":63161712},{"atb":[[16.5,0],[11.5,0],[14,0]],"id":58069703},{"atl":[[350,0],[250,0]],"id":58069703},{"atb":[[19.5,0],[24,0],[29,0]],"id":50605162},{"atl":[[400,0],[500,0]],"id":50605162},{"atb":[[2.02,0],[2.12,0],[1.96,0]],"id":65732558},{"atl":[[6.8,0],[8.8,0]],"id":65732558},{"atb":[[8,0],[9,0],[7,0]],"id":61028210},{"atl":[[210,0],[110,0]],"id":61028210}],"con":true,"img":false}]}
{"op":"mcm","clk":"11449322426","pt":1717307163106,"mc":[{"id":"1.229554895","rc":[{"atb":[[1.43,243.09],[1.33,633.51],[1.38,550.16]],"id":63161712},{"atl":[[2.9,73.35],[3.25,92.91]],"id":63161712},{"atb":[[16.5,6.74],[11.5,19.91],[14,16.08]],"id":58069703},{"atl":[[350,0.59],[250,0.55]],"id":58069703},{"atb":[[32,3.37],[21,10.45],[26,8.36]],"id":50605162},{"atl":[[520,0.4],[420,0.33]],"id":50605162},{"atb":[[2.02,204.95],[2.12,93.32],[1.96,217.77]],"id":65732558},{"atl":[[6.8,24.02],[8.8,26.8]],"id":65732558},{"atb":[[8,29.86],[9,13.06],[7,34.84]],"id":61028210},{"atl":[[210,0.99],[110,1.27]],"id":61028210}],"con":true,"img":false}]}
{"op":"mcm","clk":"11449368314","pt":1717308059014,"mc":[{"id":"1.229554895","rc":[{"spn":1.71,"spf":"NaN","id":63161712},{"atb":[[32,0],[21,0],[26,0]],"id":50605162},{"atl":[[520,0],[420,0]],"id":50605162},{"spn":"NaN","spf":"NaN","id":50605162},{"spn":4.46,"spf":"NaN","id":65732558},{"spn":59.5,"spf":"NaN","id":61028210}],"con":true,"img":false}]}
{"op":"mcm","clk":"11449369772","pt":1717308089019,"mc":[{"id":"1.229554895","rc":[{"atb":[[32,3.37],[21,10.45],[26,8.36]],"id":50605162},{"atl":[[520,0.4],[420,0.33]],"id":50605162}],"con":true,"img":false}]}
{"op":"mcm","clk":"11449373085","pt":1717308165440,"mc":[{"id":"1.229554895","rc":[{"spn":226.0,"spf":"NaN","id":50605162},{"atl":[[1000,2.35]],"id":65732558}],"con":true,"img":false}]}
{"op":"mcm","clk":"11449373096","pt":1717308165748,"mc":[{"id":"1.229554895","rc":[{"atl":[[1000,2.15]],"id":65732558}],"con":true,"img":false}]}
{"op":"mcm","clk":"11449373110","pt":1717308166056,"mc":[{"id":"1.229554895","rc":[{"atl":[[1000,0]],"id":65732558}],"con":true,"img":false}]}
{"op":"mcm","clk":"11449373114","pt":1717308166157,"mc":[{"id":"1.229554895","rc":[{"atl":[[6.2,2.15]],"id":65732558}],"con":true,"img":false}]}
{"op":"mcm","clk":"11449381036","pt":1717308321532,"mc":[{"id":"1.229554895","rc":[{"atl":[[6.2,5.26]],"id":65732558},{"spn":4.16,"spf":"NaN","id":65732558}],"con":true,"img":false}]}
{"op":"mcm","clk":"11449382960","pt":1717308350289,"mc":[{"id":"1.229554895","rc":[{"atl":[[6.2,3.11]],"id":65732558}],"con":true,"img":false}]}
{"op":"mcm","clk":"11449383836","pt":1717308365181,"mc":[{"id":"1.229554895","rc":[{"atl":[[1000,2.35]],"id":65732558}],"con":true,"img":false}]}
{"op":"mcm","clk":"11449383849","pt":1717308365487,"mc":[{"id":"1.229554895","rc":[{"atl":[[1000,2.15]],"id":65732558}],"con":true,"img":false}]}
{"op":"mcm","clk":"11449383865","pt":1717308365695,"mc":[{"id":"1.229554895","rc":[{"atl":[[1000,0]],"id":65732558}],"con":true,"img":false}]}
{"op":"mcm","clk":"11449383870","pt":1717308365802,"mc":[{"id":"1.229554895","rc":[{"atl":[[6.2,5.26]],"id":65732558}],"con":true,"img":false}]}
{"op":"mcm","clk":"11449394353","pt":1717308521107,"mc":[{"id":"1.229554895","rc":[{"atl":[[6.2,2.15]],"id":65732558}],"con":true,"img":false}]}
{"op":"mcm","clk":"11449396575","pt":1717308553786,"mc":[{"id":"1.229554895","rc":[{"atl":[[6.2,0]],"id":65732558}],"con":true,"img":false}]}
{"op":"mcm","clk":"11449397570","pt":1717308568769,"mc":[{"id":"1.229554895","rc":[{"atl":[[1000,2.35]],"id":65732558}],"con":true,"img":false}]}
{"op":"mcm","clk":"11449397584","pt":1717308569031,"mc":[{"id":"1.229554895","rc":[{"atl":[[1000,2.15]],"id":65732558}],"con":true,"img":false}]}
{"op":"mcm","clk":"11449397600","pt":1717308569264,"mc":[{"id":"1.229554895","rc":[{"atl":[[1000,0]],"id":65732558}],"con":true,"img":false}]}
{"op":"mcm","clk":"11449397609","pt":1717308569341,"mc":[{"id":"1.229554895","rc":[{"atl":[[6.2,2.15]],"id":65732558}],"con":true,"img":false}]}
{"op":"mcm","clk":"11449410523","pt":1717308754154,"mc":[{"id":"1.229554895","rc":[{"atl":[[6.2,0]],"id":65732558},{"spn":4.46,"spf":"NaN","id":65732558}],"con":true,"img":false}]}
{"op":"mcm","clk":"11449411380","pt":1717308766591,"mc":[{"id":"1.229554895","rc":[{"atl":[[1000,2.35]],"id":65732558}],"con":true,"img":false}]}
{"op":"mcm","clk":"11449411407","pt":1717308766901,"mc":[{"id":"1.229554895","rc":[{"atl":[[1000,2.15]],"id":65732558}],"con":true,"img":false}]}
{"op":"mcm","clk":"11449411429","pt":1717308767210,"mc":[{"id":"1.229554895","rc":[{"atl":[[1000,0]],"id":65732558}],"con":true,"img":false}]}
{"op":"mcm","clk":"11449411437","pt":1717308767312,"mc":[{"id":"1.229554895","rc":[{"atl":[[6.2,2.15]],"id":65732558}],"con":true,"img":false}]}
{"op":"mcm","clk":"11449421597","pt":1717308904943,"mc":[{"id":"1.229554895","rc":[{"atl":[[6.2,5.26]],"id":65732558},{"spn":4.16,"spf":"NaN","id":65732558}],"con":true,"img":false}]}
{"op":"mcm","clk":"11449425047","pt":1717308949701,"mc":[{"id":"1.229554895","rc":[{"atl":[[6.2,3.11]],"id":65732558}],"con":true,"img":false}]}
{"op":"mcm","clk":"11449425947","pt":1717308961975,"mc":[{"id":"1.229554895","rc":[{"atl":[[1000,2.35]],"id":65732558}],"con":true,"img":false}]}
{"op":"mcm","clk":"11449425965","pt":1717308962128,"mc":[{"id":"1.229554895","rc":[{"atl":[[1000,2.15]],"id":65732558}],"con":true,"img":false}]}
{"op":"mcm","clk":"11449425988","pt":1717308962327,"mc":[{"id":"1.229554895","rc":[{"atl":[[1000,0]],"id":65732558}],"con":true,"img":false}]}
{"op":"mcm","clk":"11449425997","pt":1717308962441,"mc":[{"id":"1.229554895","rc":[{"atl":[[6.2,5.26]],"id":65732558}],"con":true,"img":false}]}
{"op":"mcm","clk":"11449436088","pt":1717309107786,"mc":[{"id":"1.229554895","rc":[{"atl":[[6.2,2.15]],"id":65732558}],"con":true,"img":false}]}
{"op":"mcm","clk":"11449438341","pt":1717309142534,"mc":[{"id":"1.229554895","rc":[{"atl":[[6.2,5.26]],"id":65732558}],"con":true,"img":false}]}
{"op":"mcm","clk":"11449438675","pt":1717309148153,"mc":[{"id":"1.229554895","rc":[{"atl":[[6.2,3.11]],"id":65732558}],"con":true,"img":false}]}
{"op":"mcm","clk":"11449439099","pt":1717309154739,"mc":[{"id":"1.229554895","rc":[{"atl":[[1000,2.35]],"id":65732558}],"con":true,"img":false}]}
{"op":"mcm","clk":"11449439110","pt":1717309154946,"mc":[{"id":"1.229554895","rc":[{"atl":[[1000,2.15]],"id":65732558}],"con":true,"img":false}]}
{"op":"mcm","clk":"11449439130","pt":1717309155254,"mc":[{"id":"1.229554895","rc":[{"atl":[[1000,0]],"id":65732558}],"con":true,"img":false}]}
{"op":"mcm","clk":"11449439138","pt":1717309155357,"mc":[{"id":"1.229554895","rc":[{"atl":[[6.2,5.26]],"id":65732558}],"con":true,"img":false}]}
{"op":"mcm","clk":"11449440317","pt":1717309173868,"mc":[{"id":"1.229554895","rc":[{"atb":[[32,0],[21,0],[26,0]],"id":50605162},{"atl":[[520,0],[420,0]],"id":50605162},{"spn":"NaN","spf":"NaN","id":50605162}],"con":true,"img":false}]}
{"op":"mcm","clk":"11449440885","pt":1717309182656,"mc":[{"id":"1.229554895","rc":[{"atb":[[32,3.37],[21,10.45],[26,8.36]],"id":50605162},{"atl":[[520,0.4],[420,0.33]],"id":50605162}],"con":true,"img":false}]}
{"op":"mcm","clk":"11449451008","pt":1717309336112,"mc":[{"id":"1.229554895","rc":[{"spn":226.0,"spf":"NaN","id":50605162},{"atl":[[6.2,3.11]],"id":65732558}],"con":true,"img":false}]}
{"op":"mcm","clk":"11449451756","pt":1717309347532,"mc":[{"id":"1.229554895","rc":[{"atl":[[6.2,0]],"id":65732558}],"con":true,"img":false}]}
{"op":"mcm","clk":"11449451774","pt":1717309347735,"mc":[{"id":"1.229554895","rc":[{"atl":[[1000,2.35]],"id":65732558}],"con":true,"img":false}]}
{"op":"mcm","clk":"11449451794","pt":1717309347948,"mc":[{"id":"1.229554895","rc":[{"atl":[[1000,2.15]],"id":65732558}],"con":true,"img":false}]}
{"op":"mcm","clk":"11449451814","pt":1717309348253,"mc":[{"id":"1.229554895","rc":[{"atl":[[1000,0]],"id":65732558}],"con":true,"img":false}]}
{"op":"mcm","clk":"11449451826","pt":1717309348359,"mc":[{"id":"1.229554895","rc":[{"atl":[[6.2,2.15]],"id":65732558}],"con":true,"img":false}]}
{"op":"mcm","clk":"11449454090","pt":1717309381872,"mc":[{"id":"1.229554895","rc":[{"atl":[[6.2,5.26]],"id":65732558}],"con":true,"img":false}]}
{"op":"mcm","clk":"11449459024","pt":1717309459898,"mc":[{"id":"1.229554895","rc":[{"atb":[[1.43,0],[1.33,0],[1.38,0]],"id":63161712},{"atl":[[2.9,0],[3.25,0]],"id":63161712},{"spn":1.0,"spf":"NaN","id":63161712},{"atb":[[16.5,0],[11.5,0],[14,0]],"id":58069703},{"atl":[[350,0],[250,0]],"id":58069703},{"spn":"NaN","spf":"NaN","id":58069703},{"atb":[[32,0],[21,0],[26,0]],"id":50605162},{"atl":[[520,0],[420,0]],"id":50605162},{"spn":"NaN","spf":"NaN","id":50605162},{"atb":[[2.02,0],[2.12,0],[1.96,0]],"id":65732558},{"atl":[[6.8,0],[8.8,0]],"id":65732558},{"spn":1.0,"spf":"NaN","id":65732558},{"atb":[[8,0],[9,0],[7,0]],"id":61028210},{"atl":[[210,0],[110,0]],"id":61028210},{"spn":"NaN","spf":"NaN","id":61028210}],"con":true,"img":false}]}
{"op":"mcm","clk":"11449460680","pt":1717309485424,"mc":[{"id":"1.229554895","rc":[{"atb":[[1.43,243.09],[1.33,633.51],[1.38,550.16]],"id":63161712},{"atl":[[2.9,73.35],[3.25,92.91]],"id":63161712},{"atb":[[17,6.53],[12,19],[14.5,15.48]],"id":58069703},{"atl":[[350,0.59],[250,0.55]],"id":58069703},{"atb":[[38,2.82],[24,9.08],[29,7.46]],"id":50605162},{"atl":[[550,0.38],[450,0.3]],"id":50605162},{"atb":[[2.02,204.95],[2.12,93.32],[1.96,217.77]],"id":65732558},{"atl":[[6.8,24.02],[8.8,26.8]],"id":65732558},{"atb":[[7.4,32.66],[8.4,28.25],[9.4,12.44]],"id":61028210},{"atl":[[140,1],[240,0.87]],"id":61028210}],"con":true,"img":false}]}
{"op":"mcm","clk":"11449464551","pt":1717309542786,"mc":[{"id":"1.229554895","rc":[{"spn":1.71,"spf":"NaN","id":63161712},{"spn":133.5,"spf":"NaN","id":58069703},{"spn":244.0,"spf":"NaN","id":50605162},{"atl":[[6.2,3.11]],"id":65732558},{"spn":4.16,"spf":"NaN","id":65732558},{"spn":74.7,"spf":"NaN","id":61028210}],"con":true,"img":false}]}
{"op":"mcm","clk":"11449465549","pt":1717309557733,"mc":[{"id":"1.229554895","rc":[{"atl":[[1000,2.35]],"id":65732558}],"con":true,"img":false}]}
{"op":"mcm","clk":"11449465571","pt":1717309557995,"mc":[{"id":"1.229554895","rc":[{"atl":[[1000,2.15]],"id":65732558}],"con":true,"img":false}]}
{"op":"mcm","clk":"11449465589","pt":1717309558303,"mc":[{"id":"1.229554895","rc":[{"atl":[[1000,0]],"id":65732558}],"con":true,"img":false}]}
{"op":"mcm","clk":"11449465593","pt":1717309558405,"mc":[{"id":"1.229554895","rc":[{"atl":[[6.2,5.26]],"id":65732558}],"con":true,"img":false}]}
{"op":"mcm","clk":"11449466033","pt":1717309564671,"mc":[{"id":"1.229554895","rc":[{"atl":[[6.2,2.15]],"id":65732558}],"con":true,"img":false}]}
{"op":"mcm","clk":"11449468451","pt":1717309598677,"mc":[{"id":"1.229554895","rc":[{"atl":[[6.2,5.26]],"id":65732558}],"con":true,"img":false}]}
{"op":"mcm","clk":"11449486142","pt":1717309742057,"mc":[{"id":"1.229554895","rc":[{"atl":[[6.2,3.11]],"id":65732558}],"con":true,"img":false}]}
{"op":"mcm","clk":"11449487209","pt":1717309756990,"mc":[{"id":"1.229554895","rc":[{"atl":[[1000,2.35]],"id":65732558}],"con":true,"img":false}]}
{"op":"mcm","clk":"11449487225","pt":1717309757209,"mc":[{"id":"1.229554895","rc":[{"atl":[[1000,2.15]],"id":65732558}],"con":true,"img":false}]}
{"op":"mcm","clk":"11449487240","pt":1717309757398,"mc":[{"id":"1.229554895","rc":[{"atl":[[1000,0]],"id":65732558}],"con":true,"img":false}]}
{"op":"mcm","clk":"11449487248","pt":1717309757506,"mc":[{"id":"1.229554895","rc":[{"atl":[[6.2,5.26]],"id":65732558}],"con":true,"img":false}]}
{"op":"mcm","clk":"11449490616","pt":1717309805622,"mc":[{"id":"1.229554895","rc":[{"atl":[[6.2,2.15]],"id":65732558}],"con":true,"img":false}]}
{"op":"mcm","clk":"11449493769","pt":1717309852269,"mc":[{"id":"1.229554895","rc":[{"atl":[[6.2,5.26]],"id":65732558}],"con":true,"img":false}]}
{"op":"mcm","clk":"11449499152","pt":1717309939625,"mc":[{"id":"1.229554895","rc":[{"atl":[[6.2,3.11]],"id":65732558}],"con":true,"img":false}]}
{"op":"mcm","clk":"11449499871","pt":1717309952352,"mc":[{"id":"1.229554895","rc":[{"atl":[[1000,2.35]],"id":65732558}],"con":true,"img":false}]}
{"op":"mcm","clk":"11449499888","pt":1717309952659,"mc":[{"id":"1.229554895","rc":[{"atl":[[1000,2.15]],"id":65732558}],"con":true,"img":false}]}
{"op":"mcm","clk":"11449499908","pt":1717309952966,"mc":[{"id":"1.229554895","rc":[{"atl":[[1000,0]],"id":65732558}],"con":true,"img":false}]}
{"op":"mcm","clk":"11449499913","pt":1717309953069,"mc":[{"id":"1.229554895","rc":[{"atl":[[6.2,5.26]],"id":65732558}],"con":true,"img":false}]}
{"op":"mcm","clk":"11449505075","pt":1717310038333,"mc":[{"id":"1.229554895","rc":[{"atl":[[6.2,2.15]],"id":65732558}],"con":true,"img":false}]}
{"op":"mcm","clk":"11449506956","pt":1717310069161,"mc":[{"id":"1.229554895","rc":[{"atl":[[6.2,5.26]],"id":65732558}],"con":true,"img":false}]}
{"op":"mcm","clk":"11449511541","pt":1717310144648,"mc":[{"id":"1.229554895","rc":[{"atl":[[6.2,3.11]],"id":65732558}],"con":true,"img":false}]}
{"op":"mcm","clk":"11449512361","pt":1717310159539,"mc":[{"id":"1.229554895","rc":[{"atl":[[1000,2.35]],"id":65732558}],"con":true,"img":false}]}
{"op":"mcm","clk":"11449512382","pt":1717310159850,"mc":[{"id":"1.229554895","rc":[{"atl":[[1000,2.15]],"id":65732558}],"con":true,"img":false}]}
{"op":"mcm","clk":"11449512404","pt":1717310160158,"mc":[{"id":"1.229554895","rc":[{"atl":[[1000,0]],"id":65732558}],"con":true,"img":false}]}
{"op":"mcm","clk":"11449512411","pt":1717310160264,"mc":[{"id":"1.229554895","rc":[{"atl":[[6.2,5.26]],"id":65732558}],"con":true,"img":false}]}
{"op":"mcm","clk":"11449518169","pt":1717310255624,"mc":[{"id":"1.229554895","rc":[{"atl":[[6.2,2.15]],"id":65732558}],"con":true,"img":false}]}
{"op":"mcm","clk":"11449519433","pt":1717310277318,"mc":[{"id":"1.229554895","rc":[{"atl":[[6.2,5.26]],"id":65732558}],"con":true,"img":false}]}
{"op":"mcm","clk":"11449520989","pt":1717310304147,"mc":[{"id":"1.229554895","rc":[{"atb":[[38,0],[24,0],[29,0]],"id":50605162},{"atl":[[550,0],[450,0]],"id":50605162}],"con":true,"img":false}]}
{"op":"mcm","clk":"11449521986","pt":1717310319875,"mc":[{"id":"1.229554895","rc":[{"atb":[[38,2.82],[24,9.08],[29,7.46]],"id":50605162},{"atl":[[550,0.38],[450,0.3]],"id":50605162}],"con":true,"img":false}]}
{"op":"mcm","clk":"11449523354","pt":1717310341937,"mc":[{"id":"1.229554895","rc":[{"atl":[[6.2,3.11]],"id":65732558}],"con":true,"img":false}]}
{"op":"mcm","clk":"11449524315","pt":1717310357031,"mc":[{"id":"1.229554895","rc":[{"atl":[[1000,2.35]],"id":65732558}],"con":true,"img":false}]}
{"op":"mcm","clk":"11449524330","pt":1717310357339,"mc":[{"id":"1.229554895","rc":[{"atl":[[1000,2.15]],"id":65732558}],"con":true,"img":false}]}
{"op":"mcm","clk":"11449524347","pt":1717310357646,"mc":[{"id":"1.229554895","rc":[{"atl":[[1000,0]],"id":65732558}],"con":true,"img":false}]}
{"op":"mcm","clk":"11449524355","pt":1717310357747,"mc":[{"id":"1.229554895","rc":[{"atl":[[6.2,5.26]],"id":65732558}],"con":true,"img":false}]}
{"op":"mcm","clk":"11449530682","pt":1717310460464,"mc":[{"id":"1.229554895","rc":[{"atl":[[6.2,2.15]],"id":65732558}],"con":true,"img":false}]}
{"op":"mcm","clk":"11449532539","pt":1717310493588,"mc":[{"id":"1.229554895","rc":[{"atl":[[6.2,5.26]],"id":65732558}],"con":true,"img":false}]}
{"op":"mcm","clk":"11449535939","pt":1717310551198,"mc":[{"id":"1.229554895","rc":[{"atl":[[6.2,3.11]],"id":65732558}],"con":true,"img":false}]}
{"op":"mcm","clk":"11449537538","pt":1717310576620,"mc":[{"id":"1.229554895","rc":[{"atl":[[1000,2.35]],"id":65732558}],"con":true,"img":false}]}
{"op":"mcm","clk":"11449537548","pt":1717310576830,"mc":[{"id":"1.229554895","rc":[{"atl":[[1000,2.15]],"id":65732558}],"con":true,"img":false}]}
{"op":"mcm","clk":"11449537559","pt":1717310577035,"mc":[{"id":"1.229554895","rc":[{"atl":[[1000,0]],"id":65732558}],"con":true,"img":false}]}
{"op":"mcm","clk":"11449537568","pt":1717310577134,"mc":[{"id":"1.229554895","rc":[{"atl":[[6.2,5.26]],"id":65732558}],"con":true,"img":false}]}
{"op":"mcm","clk":"11449545092","pt":1717310708301,"mc":[{"id":"1.229554895","rc":[{"atl":[[6.2,2.15]],"id":65732558}],"con":true,"img":false}]}
{"op":"mcm","clk":"11449547255","pt":1717310744041,"mc":[{"id":"1.229554895","rc":[{"atl":[[6.2,5.26]],"id":65732558}],"con":true,"img":false}]}
{"op":"mcm","clk":"11449548420","pt":1717310763567,"mc":[{"id":"1.229554895","rc":[{"atl":[[6.2,3.11]],"id":65732558}],"con":true,"img":false}]}
{"op":"mcm","clk":"11449549326","pt":1717310778567,"mc":[{"id":"1.229554895","rc":[{"atl":[[1000,2.35]],"id":65732558}],"con":true,"img":false}]}
{"op":"mcm","clk":"11449549346","pt":1717310778879,"mc":[{"id":"1.229554895","rc":[{"atl":[[1000,2.15]],"id":65732558}],"con":true,"img":false}]}
{"op":"mcm","clk":"11449549361","pt":1717310779084,"mc":[{"id":"1.229554895","rc":[{"atl":[[1000,0]],"id":65732558}],"con":true,"img":false}]}
{"op":"mcm","clk":"11449549368","pt":1717310779188,"mc":[{"id":"1.229554895","rc":[{"atl":[[6.2,5.26]],"id":65732558}],"con":true,"img":false}]}
{"op":"mcm","clk":"11449557834","pt":1717310927887,"mc":[{"id":"1.229554895","rc":[{"atl":[[6.2,2.15]],"id":65732558}],"con":true,"img":false}]}
{"op":"mcm","clk":"11449560011","pt":1717310967441,"mc":[{"id":"1.229554895","rc":[{"atl":[[6.2,0]],"id":65732558}],"con":true,"img":false}]}
{"op":"mcm","clk":"11449560207","pt":1717310970526,"mc":[{"id":"1.229554895","rc":[{"atl":[[6.2,3.11]],"id":65732558}],"con":true,"img":false}]}
{"op":"mcm","clk":"11449560824","pt":1717310982850,"mc":[{"id":"1.229554895","rc":[{"atl":[[1000,2.35]],"id":65732558}],"con":true,"img":false}]}
{"op":"mcm","clk":"11449560837","pt":1717310983157,"mc":[{"id":"1.229554895","rc":[{"atl":[[1000,2.15]],"id":65732558}],"con":true,"img":false}]}
{"op":"mcm","clk":"11449560848","pt":1717310983468,"mc":[{"id":"1.229554895","rc":[{"atl":[[1000,0]],"id":65732558}],"con":true,"img":false}]}
{"op":"mcm","clk":"11449560858","pt":1717310983523,"mc":[{"id":"1.229554895","rc":[{"atl":[[6.2,5.26]],"id":65732558}],"con":true,"img":false}]}
{"op":"mcm","clk":"11449569991","pt":1717311155355,"mc":[{"id":"1.229554895","rc":[{"atb":[[38,0],[24,0],[29,0]],"id":50605162},{"atl":[[550,0],[450,0]],"id":50605162},{"spn":"NaN","spf":"NaN","id":50605162}],"con":true,"img":false}]}
{"op":"mcm","clk":"11449570789","pt":1717311169967,"mc":[{"id":"1.229554895","rc":[{"atb":[[38,2.82],[24,9.08],[29,7.46]],"id":50605162},{"atl":[[550,0.38],[450,0.3]],"id":50605162}],"con":true,"img":false}]}
{"op":"mcm","clk":"11449571088","pt":1717311175952,"mc":[{"id":"1.229554895","rc":[{"atl":[[6.2,3.11]],"id":65732558}],"con":true,"img":false}]}
{"op":"mcm","clk":"11449571529","pt":1717311183577,"mc":[{"id":"1.229554895","rc":[{"atl":[[6.2,0]],"id":65732558}],"con":true,"img":false}]}
{"op":"mcm","clk":"11449571833","pt":1717311189391,"mc":[{"id":"1.229554895","rc":[{"atl":[[1000,2.35]],"id":65732558}],"con":true,"img":false}]}
{"op":"mcm","clk":"11449571845","pt":1717311189696,"mc":[{"id":"1.229554895","rc":[{"atl":[[1000,2.15]],"id":65732558}],"con":true,"img":false}]}
{"op":"mcm","clk":"11449571858","pt":1717311190004,"mc":[{"id":"1.229554895","rc":[{"atl":[[1000,0]],"id":65732558}],"con":true,"img":false}]}
{"op":"mcm","clk":"11449571864","pt":1717311190106,"mc":[{"id":"1.229554895","rc":[{"atl":[[6.2,2.15]],"id":65732558}],"con":true,"img":false}]}
{"op":"mcm","clk":"11449573522","pt":1717311221550,"mc":[{"id":"1.229554895","rc":[{"spn":244.0,"spf":"NaN","id":50605162},{"atl":[[6.2,5.26]],"id":65732558}],"con":true,"img":false}]}
{"op":"mcm","clk":"11449583342","pt":1717311382822,"mc":[{"id":"1.229554895","rc":[{"atl":[[6.2,3.11]],"id":65732558}],"con":true,"img":false}]}
{"op":"mcm","clk":"11449584171","pt":1717311397854,"mc":[{"id":"1.229554895","rc":[{"atl":[[1000,2.35]],"id":65732558}],"con":true,"img":false}]}
{"op":"mcm","clk":"11449584187","pt":1717311398169,"mc":[{"id":"1.229554895","rc":[{"atl":[[1000,2.15]],"id":65732558}],"con":true,"img":false}]}
{"op":"mcm","clk":"11449584208","pt":1717311398426,"mc":[{"id":"1.229554895","rc":[{"atl":[[1000,0]],"id":65732558}],"con":true,"img":false}]}
{"op":"mcm","clk":"11449584213","pt":1717311398530,"mc":[{"id":"1.229554895","rc":[{"atl":[[6.2,5.26]],"id":65732558}],"con":true,"img":false}]}
{"op":"mcm","clk":"11449585434","pt":1717311421385,"mc":[{"id":"1.229554895","rc":[{"atl":[[6.2,2.15]],"id":65732558}],"con":true,"img":false}]}
{"op":"mcm","clk":"11449586460","pt":1717311438873,"mc":[{"id":"1.229554895","rc":[{"atb":[[1.03,5.96]],"id":63161712},{"atl":[[990,0.85]],"id":63161712},{"atb":[[1.02,8.94]],"id":58069703},{"atl":[[990,0.85]],"id":58069703},{"atb":[[1.02,8.94]],"id":50605162},{"atl":[[990,0.85]],"id":50605162},{"atb":[[1.01,17.89]],"id":65732558},{"atl":[[990,0.85]],"id":65732558},{"atb":[[1.01,17.89]],"id":61028210},{"atl":[[1000,0.85]],"id":61028210}],"con":true,"img":false}]}
{"op":"mcm","clk":"11449587509","pt":1717311457624,"mc":[{"id":"1.229554895","rc":[{"atl":[[6.2,5.26]],"id":65732558}],"con":true,"img":false}]}
{"op":"mcm","clk":"11449593948","pt":1717311578766,"mc":[{"id":"1.229554895","rc":[{"atl":[[6.2,3.11]],"id":65732558}],"con":true,"img":false}]}
{"op":"mcm","clk":"11449594622","pt":1717311593777,"mc":[{"id":"1.229554895","rc":[{"atl":[[1000,2.35]],"id":65732558}],"con":true,"img":false}]}
{"op":"mcm","clk":"11449594631","pt":1717311593982,"mc":[{"id":"1.229554895","rc":[{"atl":[[1000,2.15]],"id":65732558}],"con":true,"img":false}]}
{"op":"mcm","clk":"11449594647","pt":1717311594391,"mc":[{"id":"1.229554895","rc":[{"atl":[[1000,0]],"id":65732558}],"con":true,"img":false}]}
{"op":"mcm","clk":"11449594651","pt":1717311594494,"mc":[{"id":"1.229554895","rc":[{"atl":[[6.2,5.26]],"id":65732558}],"con":true,"img":false}]}
{"op":"mcm","clk":"11449598138","pt":1717311656045,"mc":[{"id":"1.229554895","rc":[{"atl":[[6.2,2.15]],"id":65732558}],"con":true,"img":false}]}
{"op":"mcm","clk":"11449600768","pt":1717311705788,"mc":[{"id":"1.229554895","rc":[{"atl":[[6.2,5.26]],"id":65732558}],"con":true,"img":false}]}
{"op":"mcm","clk":"11449604584","pt":1717311779408,"mc":[{"id":"1.229554895","rc":[{"atl":[[6.2,3.11]],"id":65732558}],"con":true,"img":false}]}
{"op":"mcm","clk":"11449605277","pt":1717311794132,"mc":[{"id":"1.229554895","rc":[{"atl":[[1000,2.35]],"id":65732558}],"con":true,"img":false}]}
{"op":"mcm","clk":"11449605289","pt":1717311794370,"mc":[{"id":"1.229554895","rc":[{"atl":[[1000,2.15]],"id":65732558}],"con":true,"img":false}]}
{"op":"mcm","clk":"11449605298","pt":1717311794531,"mc":[{"id":"1.229554895","rc":[{"atl":[[1000,0]],"id":65732558}],"con":true,"img":false}]}
{"op":"mcm","clk":"11449605305","pt":1717311794622,"mc":[{"id":"1.229554895","rc":[{"atl":[[6.2,5.26]],"id":65732558}],"con":true,"img":false}]}
{"op":"mcm","clk":"11449610603","pt":1717311886941,"mc":[{"id":"1.229554895","rc":[{"atl":[[6.2,2.15]],"id":65732558}],"con":true,"img":false}]}
{"op":"mcm","clk":"11449612502","pt":1717311920154,"mc":[{"id":"1.229554895","rc":[{"atl":[[6.2,5.26]],"id":65732558}],"con":true,"img":false}]}
{"op":"mcm","clk":"11449615491","pt":1717311974867,"mc":[{"id":"1.229554895","rc":[{"atl":[[6.2,3.11]],"id":65732558}],"con":true,"img":false}]}
{"op":"mcm","clk":"11449616235","pt":1717311990275,"mc":[{"id":"1.229554895","rc":[{"atl":[[1000,2.35]],"id":65732558}],"con":true,"img":false}]}
{"op":"mcm","clk":"11449616245","pt":1717311990483,"mc":[{"id":"1.229554895","rc":[{"atl":[[1000,2.15]],"id":65732558}],"con":true,"img":false}]}
{"op":"mcm","clk":"11449616263","pt":1717311990790,"mc":[{"id":"1.229554895","rc":[{"atl":[[1000,0]],"id":65732558}],"con":true,"img":false}]}
{"op":"mcm","clk":"11449616266","pt":1717311990891,"mc":[{"id":"1.229554895","rc":[{"atl":[[6.2,5.26]],"id":65732558}],"con":true,"img":false}]}
{"op":"mcm","clk":"11449617486","pt":1717312015934,"mc":[{"id":"1.229554895","rc":[{"atb":[[38,0],[24,0],[29,0]],"id":50605162},{"atl":[[550,0],[450,0]],"id":50605162}],"con":true,"img":false}]}
{"op":"mcm","clk":"11449618490","pt":1717312035122,"mc":[{"id":"1.229554895","rc":[{"atb":[[38,2.82],[24,9.08],[29,7.46]],"id":50605162},{"atl":[[550,0.38],[450,0.3]],"id":50605162}],"con":true,"img":false}]}
{"op":"mcm","clk":"11449622819","pt":1717312127658,"mc":[{"id":"1.229554895","rc":[{"atl":[[6.2,2.15]],"id":65732558}],"con":true,"img":false}]}
{"op":"mcm","clk":"11449624485","pt":1717312173427,"mc":[{"id":"1.229554895","rc":[{"atl":[[6.2,5.26]],"id":65732558}],"con":true,"img":false}]}
{"op":"mcm","clk":"11449624630","pt":1717312177131,"mc":[{"id":"1.229554895","rc":[{"atl":[[6.2,3.11]],"id":65732558}],"con":true,"img":false}]}
{"op":"mcm","clk":"11449625448","pt":1717312195724,"mc":[{"id":"1.229554895","rc":[{"atl":[[1000,2.35]],"id":65732558}],"con":true,"img":false}]}
{"op":"mcm","clk":"11449625480","pt":1717312196548,"mc":[{"id":"1.229554895","rc":[{"atl":[[1000,2.15]],"id":65732558}],"con":true,"img":false}]}
{"op":"mcm","clk":"11449625494","pt":1717312196856,"mc":[{"id":"1.229554895","rc":[{"atl":[[1000,0]],"id":65732558}],"con":true,"img":false}]}
{"op":"mcm","clk":"11449625499","pt":1717312196958,"mc":[{"id":"1.229554895","rc":[{"atl":[[6.2,5.26]],"id":65732558}],"con":true,"img":false}]}
{"op":"mcm","clk":"11449631570","pt":1717312346894,"mc":[{"id":"1.229554895","rc":[{"atb":[[1.44,75.17],[1.39,327.5]],"id":63161712},{"atl":[[2.88,68.01],[2.7,33]],"id":63161712},{"spn":1.72,"spf":"NaN","id":63161712},{"atb":[[17.5,3.4],[15,7.68]],"id":58069703},{"atl":[[160,0.35],[200,2.61]],"id":58069703},{"spn":88.75,"spf":"NaN","id":58069703},{"atb":[[34,3.11],[42,2.61]],"id":50605162},{"atl":[[760,0.07],[980,2.61]],"id":50605162},{"spn":246.0,"spf":"NaN","id":50605162},{"atb":[[1.97,120],[2.04,53.94]],"id":65732558},{"atl":[[6.2,26.04],[4.9,14.38]],"id":65732558},{"spn":3.51,"spf":"NaN","id":65732558},{"atb":[[9.2,14.64],[10.5,5.9]],"id":61028210},{"atl":[[75,2.61],[60,2.61]],"id":61028210},{"spn":35.25,"spf":"NaN","id":61028210}],"con":true,"img":false}]}
{"op":"mcm","clk":"11449631912","pt":1717312356288,"mc":[{"id":"1.229554895","rc":[{"atl":[[6.2,22.93]],"id":65732558}],"con":true,"img":false}]}
{"op":"mcm","clk":"11449632797","pt":1717312381536,"mc":[{"id":"1.229554895","rc":[{"atl":[[6.2,20.78]],"id":65732558}],"con":true,"img":false}]}
{"op":"mcm","clk":"11449633311","pt":1717312394520,"mc":[{"id":"1.229554895","rc":[{"atl":[[4.5,2.96]],"id":65732558}],"con":true,"img":false}]}
{"op":"mcm","clk":"11449634023","pt":1717312414143,"mc":[{"id":"1.229554895","rc":[{"atb":[[1.32,100]],"id":63161712},{"spn":3.31,"spf":"NaN","id":65732558}],"con":true,"img":false}]}
{"op":"mcm","clk":"11449637848","pt":1717312515853,"mc":[{"id":"1.229554895","rc":[{"atl":[[4.5,7.25]],"id":65732558}],"con":true,"img":false}]}
{"op":"mcm","clk":"11449640086","pt":1717312576230,"mc":[{"id":"1.229554895","rc":[{"atl":[[4.5,4.28]],"id":65732558}],"con":true,"img":false}]}
{"op":"mcm","clk":"11449640704","pt":1717312591062,"mc":[{"id":"1.229554895","rc":[{"atl":[[4.5,7.25]],"id":65732558}],"con":true,"img":false}]}
{"op":"mcm","clk":"11449646517","pt":1717312732859,"mc":[{"id":"1.229554895","rc":[{"atl":[[4.5,2.96]],"id":65732558}],"con":true,"img":false}]}
{"op":"mcm","clk":"11449647900","pt":1717312768200,"mc":[{"id":"1.229554895","rc":[{"atl":[[4.5,7.25]],"id":65732558}],"con":true,"img":false}]}
{"op":"mcm","clk":"11449648505","pt":1717312782428,"mc":[{"id":"1.229554895","rc":[{"atl":[[4.5,4.28]],"id":65732558}],"con":true,"img":false}]}
{"op":"mcm","clk":"11449649092","pt":1717312797545,"mc":[{"id":"1.229554895","rc":[{"atl":[[4.5,7.25]],"id":65732558}],"con":true,"img":false}]}
{"op":"mcm","clk":"11449652142","pt":1717312862827,"mc":[{"id":"1.229554895","rc":[{"atb":[[38,0],[24,0],[29,0]],"id":50605162},{"atl":[[550,0],[450,0]],"id":50605162},{"spn":401.0,"spf":"NaN","id":50605162}],"con":true,"img":false}]}
{"op":"mcm","clk":"11449652655","pt":1717312874746,"mc":[{"id":"1.229554895","rc":[{"atl":[[70,5.23]],"id":58069703}],"con":true,"img":false}]}
{"op":"mcm","clk":"11449652928","pt":1717312879778,"mc":[{"id":"1.229554895","rc":[{"atb":[[38,2.82],[24,9.08],[29,7.46]],"id":50605162},{"atl":[[550,0.38],[450,0.3]],"id":50605162}],"con":true,"img":false}]}
{"op":"mcm","clk":"11449653717","pt":1717312898661,"mc":[{"id":"1.229554895","rc":[{"atl":[[1000,20.92]],"id":58069703}],"con":true,"img":false}]}
{"op":"mcm","clk":"11449654404","pt":1717312915080,"mc":[{"id":"1.229554895","rc":[{"atl":[[700,5.23]],"id":58069703}],"con":true,"img":false}]}
{"op":"mcm","clk":"11449655561","pt":1717312945404,"mc":[{"id":"1.229554895","rc":[{"atl":[[160,0]],"id":58069703},{"spn":43.75,"spf":"NaN","id":58069703},{"spn":246.0,"spf":"NaN","id":50605162}],"con":true,"img":false}]}
{"op":"mcm","clk":"11449655562","pt":1717312945455,"mc":[{"id":"1.229554895","rc":[{"atl":[[150,0.35]],"id":58069703}],"con":true,"img":false}]}
{"op":"mcm","clk":"11449656967","pt":1717312978235,"mc":[{"id":"1.229554895","rc":[{"atl":[[4.5,4.28]],"id":65732558}],"con":true,"img":false}]}
{"op":"mcm","clk":"11449657495","pt":1717312993458,"mc":[{"id":"1.229554895","rc":[{"atl":[[4.5,7.25]],"id":65732558}],"con":true,"img":false}]}
{"op":"mcm","clk":"11449657537","pt":1717312994132,"mc":[{"id":"1.229554895","rc":[{"atl":[[4.5,2.96]],"id":65732558}],"con":true,"img":false}]}
{"op":"mcm","clk":"11449659062","pt":1717313031621,"mc":[{"id":"1.229554895","rc":[{"atl":[[4.5,7.25]],"id":65732558}],"con":true,"img":false}]}
{"op":"mcm","clk":"11449665963","pt":1717313187206,"mc":[{"id":"1.229554895","rc":[{"atl":[[4.5,4.28]],"id":65732558}],"con":true,"img":false}]}
{"op":"mcm","clk":"11449666626","pt":1717313202006,"mc":[{"id":"1.229554895","rc":[{"atl":[[4.5,7.25]],"id":65732558}],"con":true,"img":false}]}
{"op":"mcm","clk":"11449667193","pt":1717313212613,"mc":[{"id":"1.229554895","rc":[{"atl":[[4.5,2.96]],"id":65732558}],"con":true,"img":false}]}
{"op":"mcm","clk":"11449668950","pt":1717313248361,"mc":[{"id":"1.229554895","rc":[{"atl":[[4.5,7.25]],"id":65732558}],"con":true,"img":false}]}
{"op":"mcm","clk":"11449676598","pt":1717313389607,"mc":[{"id":"1.229554895","rc":[{"atl":[[4.5,4.28]],"id":65732558}],"con":true,"img":false}]}
{"op":"mcm","clk":"11449677630","pt":1717313404538,"mc":[{"id":"1.229554895","rc":[{"atl":[[4.5,7.25]],"id":65732558}],"con":true,"img":false}]}
{"op":"mcm","clk":"11449682620","pt":1717313473747,"mc":[{"id":"1.229554895","rc":[{"atl":[[4.5,2.96]],"id":65732558}],"con":true,"img":false}]}
{"op":"mcm","clk":"11449685584","pt":1717313509425,"mc":[{"id":"1.229554895","rc":[{"atl":[[4.5,7.25]],"id":65732558}],"con":true,"img":false}]}
{"op":"mcm","clk":"11449691919","pt":1717313585584,"mc":[{"id":"1.229554895","rc":[{"atl":[[4.5,4.28]],"id":65732558}],"con":true,"img":false}]}
{"op":"mcm","clk":"11449692413","pt":1717313592113,"mc":[{"id":"1.229554895","rc":[{"atl":[[4.5,7.25]],"id":65732558}],"con":true,"img":false}]}
{"op":"mcm","clk":"11449703585","pt":1717313731607,"mc":[{"id":"1.229554895","rc":[{"atl":[[4.5,2.96]],"id":65732558}],"con":true,"img":false}]}
{"op":"mcm","clk":"11449703761","pt":1717313733840,"mc":[{"id":"1.229554895","rc":[{"atb":[[38,0],[24,0],[29,0]],"id":50605162},{"atl":[[550,0],[450,0]],"id":50605162}],"con":true,"img":false}]}
{"op":"mcm","clk":"11449705292","pt":1717313752611,"mc":[{"id":"1.229554895","rc":[{"atb":[[38,2.82],[24,9.08],[29,7.46]],"id":50605162},{"atl":[[550,0.38],[450,0.3]],"id":50605162}],"con":true,"img":false}]}
{"op":"mcm","clk":"11449706667","pt":1717313769171,"mc":[{"id":"1.229554895","rc":[{"atl":[[4.5,7.25]],"id":65732558}],"con":true,"img":false}]}
{"op":"mcm","clk":"11449707640","pt":1717313780115,"mc":[{"id":"1.229554895","rc":[{"atl":[[4.5,4.28]],"id":65732558}],"con":true,"img":false}]}
{"op":"mcm","clk":"11449708922","pt":1717313795005,"mc":[{"id":"1.229554895","rc":[{"atl":[[4.5,7.25]],"id":65732558}],"con":true,"img":false}]}
{"op":"mcm","clk":"11449722769","pt":1717313950541,"mc":[{"id":"1.229554895","rc":[{"atl":[[4.5,2.96]],"id":65732558}],"con":true,"img":false}]}
{"op":"mcm","clk":"11449725926","pt":1717313984289,"mc":[{"id":"1.229554895","rc":[{"atl":[[4.5,7.25]],"id":65732558}],"con":true,"img":false}]}
{"op":"mcm","clk":"11449725976","pt":1717313984663,"mc":[{"id":"1.229554895","rc":[{"atl":[[4.5,4.28]],"id":65732558}],"con":true,"img":false}]}
{"op":"mcm","clk":"11449727369","pt":1717313999672,"mc":[{"id":"1.229554895","rc":[{"atl":[[4.5,7.25]],"id":65732558}],"con":true,"img":false}]}
{"op":"mcm","clk":"11449733263","pt":1717314058349,"mc":[{"id":"1.229554895","rc":[{"atl":[[1000,1]],"id":63161712},{"atl":[[1000,21.92]],"id":58069703},{"atl":[[1000,1]],"id":50605162},{"atl":[[1000,1]],"id":65732558},{"atl":[[1000,1.85]],"id":61028210}],"con":true,"img":false}]}
{"op":"mcm","clk":"11449733443","pt":1717314060376,"mc":[{"id":"1.229554895","rc":[{"atb":[[1.17,570.6]],"id":63161712},{"atl":[[8,14.29]],"id":63161712},{"atb":[[3.2,15.36]],"id":58069703},{"atl":[[430,2]],"id":58069703},{"atb":[[3.2,8.95]],"id":50605162},{"atl":[[760,2.07]],"id":50605162},{"atb":[[2.1,90.91]],"id":65732558},{"atl":[[16,6.67]],"id":65732558},{"atb":[[2.16,29.3]],"id":61028210},{"atl":[[70,2]],"id":61028210}],"con":true,"img":false}]}
{"op":"mcm","clk":"11449735569","pt":1717314083473,"mc":[{"id":"1.229554895","rc":[{"atb":[[1.97,0]],"id":65732558}],"con":true,"img":false}]}
{"op":"mcm","clk":"11449735579","pt":1717314083576,"mc":[{"id":"1.229554895","rc":[{"atb":[[1.82,120]],"id":65732558}],"con":true,"img":false}]}
{"op":"mcm","clk":"11449737413","pt":1717314104427,"mc":[{"id":"1.229554895","rc":[{"atb":[[2.06,94.34],[2.1,0]],"id":65732558},{"atl":[[70,0],[75,4.61]],"id":61028210}],"con":true,"img":false}]}
{"op":"mcm","clk":"11449737425","pt":1717314104530,"mc":[{"id":"1.229554895","rc":[{"atb":[[2.06,0],[2.14,87.72]],"id":65732558}],"con":true,"img":false}]}
{"op":"mcm","clk":"11449738536","pt":1717314116704,"mc":[{"id":"1.229554895","rc":[{"atl":[[75,2]],"id":61028210}],"con":true,"img":false}]}
{"op":"mcm","clk":"11449738549","pt":1717314116810,"mc":[{"id":"1.229554895","rc":[{"atl":[[65,2.61]],"id":61028210}],"con":true,"img":false}]}
{"op":"mcm","clk":"11449738866","pt":1717314120027,"mc":[{"id":"1.229554895","rc":[{"spn":3.32,"spf":"NaN","id":65732558},{"atl":[[65,0]],"id":61028210}],"con":true,"img":false}]}
{"op":"mcm","clk":"11449738876","pt":1717314120128,"mc":[{"id":"1.229554895","rc":[{"atl":[[70,2.61]],"id":61028210}],"con":true,"img":false}]}
{"op":"mcm","clk":"11449739676","pt":1717314128624,"mc":[{"id":"1.229554895","rc":[{"atb":[[3.2,0]],"id":58069703},{"atl":[[65,2],[75,0]],"id":61028210}],"con":true,"img":false}]}
{"op":"mcm","clk":"11449739688","pt":1717314128729,"mc":[{"id":"1.229554895","rc":[{"atb":[[3.2,15.36]],"id":58069703}],"con":true,"img":false}]}
{"op":"mcm","clk":"11449741809","pt":1717314153384,"mc":[{"id":"1.229554895","rc":[{"atb":[[38,0],[24,0],[29,0]],"id":50605162},{"atl":[[550,0],[450,0]],"id":50605162}],"con":true,"img":false}]}
{"op":"mcm","clk":"11449741821","pt":1717314153491,"mc":[{"id":"1.229554895","rc":[{"atl":[[760,0.07],[980,4.61]],"id":50605162}],"con":true,"img":false}]}
{"op":"mcm","clk":"11449742651","pt":1717314163984,"mc":[{"id":"1.229554895","rc":[{"atb":[[38,2.82],[24,9.08],[29,7.46]],"id":50605162},{"atl":[[550,0.38],[450,0.3]],"id":50605162}],"con":true,"img":false}]}
{"op":"mcm","clk":"11449742806","pt":1717314165586,"mc":[{"id":"1.229554895","rc":[{"atl":[[760,0]],"id":50605162}],"con":true,"img":false}]}
{"op":"mcm","clk":"11449742814","pt":1717314165696,"mc":[{"id":"1.229554895","rc":[{"atl":[[800,0.07]],"id":50605162}],"con":true,"img":false}]}
{"op":"mcm","clk":"11449743217","pt":1717314169974,"mc":[{"id":"1.229554895","rc":[{"atl":[[4.5,2.96]],"id":65732558}],"con":true,"img":false}]}
{"op":"mcm","clk":"11449744585","pt":1717314184818,"mc":[{"id":"1.229554895","rc":[{"atl":[[70,0]],"id":61028210}],"con":true,"img":false}]}
{"op":"mcm","clk":"11449744595","pt":1717314184946,"mc":[{"id":"1.229554895","rc":[{"atl":[[60,5.23]],"id":61028210}],"con":true,"img":false}]}
{"op":"mcm","clk":"11449744994","pt":1717314189723,"mc":[{"id":"1.229554895","rc":[{"atl":[[800,2.07],[980,2.61]],"id":50605162}],"con":true,"img":false}]}
{"op":"mcm","clk":"11449745033","pt":1717314190234,"mc":[{"id":"1.229554895","rc":[{"atl":[[4.5,0]],"id":65732558}],"con":true,"img":false}]}
{"op":"mcm","clk":"11449745649","pt":1717314197232,"mc":[{"id":"1.229554895","rc":[{"atl":[[4.5,2.96]],"id":65732558}],"con":true,"img":false}]}
{"op":"mcm","clk":"11449746418","pt":1717314205547,"mc":[{"id":"1.229554895","rc":[{"atl":[[4.5,7.25]],"id":65732558}],"con":true,"img":false}]}
{"op":"mcm","clk":"11449750516","pt":1717314248600,"mc":[{"id":"1.229554895","rc":[{"atb":[[2.14,0],[2.1,90.91]],"id":65732558},{"spn":3.31,"spf":"NaN","id":65732558},{"atl":[[65,0],[70,2]],"id":61028210}],"con":true,"img":false}]}
{"op":"mcm","clk":"11449751826","pt":1717314261809,"mc":[{"id":"1.229554895","rc":[{"atl":[[60,2.61]],"id":61028210}],"con":true,"img":false}]}
{"op":"mcm","clk":"11449751836","pt":1717314261915,"mc":[{"id":"1.229554895","rc":[{"atl":[[65,2.61]],"id":61028210}],"con":true,"img":false}]}
{"op":"mcm","clk":"11449752770","pt":1717314272860,"mc":[{"id":"1.229554895","rc":[{"atl":[[1000,22.77]],"id":58069703}],"con":true,"img":false}]}
{"op":"mcm","clk":"11449752806","pt":1717314273235,"mc":[{"id":"1.229554895","rc":[{"atl":[[1000,2.7]],"id":61028210}],"con":true,"img":false}]}
{"op":"mcm","clk":"11449752825","pt":1717314273537,"mc":[{"id":"1.229554895","rc":[{"atl":[[1000,22.05]],"id":58069703}],"con":true,"img":false}]}
{"op":"mcm","clk":"11449752848","pt":1717314273857,"mc":[{"id":"1.229554895","rc":[{"atl":[[1000,2]],"id":61028210}],"con":true,"img":false}]}
{"op":"mcm","clk":"11449752868","pt":1717314274048,"mc":[{"id":"1.229554895","rc":[{"atl":[[1000,21.92]],"id":58069703}],"con":true,"img":false}]}
{"op":"mcm","clk":"11449752877","pt":1717314274152,"mc":[{"id":"1.229554895","rc":[{"atl":[[65,0.12]],"id":58069703}],"con":true,"img":false}]}
{"op":"mcm","clk":"11449752939","pt":1717314274877,"mc":[{"id":"1.229554895","rc":[{"atl":[[1000,1.85]],"id":61028210}],"con":true,"img":false}]}
{"op":"mcm","clk":"11449752944","pt":1717314274929,"mc":[{"id":"1.229554895","rc":[{"atl":[[55,0.15]],"id":61028210}],"con":true,"img":false}]}
{"op":"mcm","clk":"11449762544","pt":1717314385196,"mc":[{"id":"1.229554895","rc":[{"spn":41.25,"spf":"NaN","id":58069703},{"atl":[[4.5,4.28]],"id":65732558},{"spn":32.75,"spf":"NaN","id":61028210}],"con":true,"img":false}]}
{"op":"mcm","clk":"11449762774","pt":1717314387684,"mc":[{"id":"1.229554895","rc":[{"atl":[[4.5,0]],"id":65732558}],"con":true,"img":false}]}
{"op":"mcm","clk":"11449763870","pt":1717314400407,"mc":[{"id":"1.229554895","rc":[{"atl":[[4.5,2.96]],"id":65732558}],"con":true,"img":false}]}
{"op":"mcm","clk":"11449766265","pt":1717314427129,"mc":[{"id":"1.229554895","rc":[{"atl":[[4.5,7.25]],"id":65732558}],"con":true,"img":false}]}
{"op":"mcm","clk":"11449777970","pt":1717314555619,"mc":[{"id":"1.229554895","rc":[{"atb":[[38,0],[24,0],[29,0]],"id":50605162},{"atl":[[550,0],[450,0]],"id":50605162},{"spn":421.0,"spf":"NaN","id":50605162}],"con":true,"img":false}]}
{"op":"mcm","clk":"11449777979","pt":1717314555718,"mc":[{"id":"1.229554895","rc":[{"atl":[[980,4.61]],"id":50605162}],"con":true,"img":false}]}
{"op":"mcm","clk":"11449777991","pt":1717314555822,"mc":[{"id":"1.229554895","rc":[{"atl":[[800,0.07]],"id":50605162}],"con":true,"img":false}]}
{"op":"mcm","clk":"11449779210","pt":1717314569520,"mc":[{"id":"1.229554895","rc":[{"atl":[[65,0]],"id":61028210}],"con":true,"img":false}]}
{"op":"mcm","clk":"11449779219","pt":1717314569626,"mc":[{"id":"1.229554895","rc":[{"atl":[[75,2.61]],"id":61028210}],"con":true,"img":false}]}
{"op":"mcm","clk":"11449779231","pt":1717314569827,"mc":[{"id":"1.229554895","rc":[{"atl":[[55,0]],"id":61028210}],"con":true,"img":false}]}
{"op":"mcm","clk":"11449779736","pt":1717314575423,"mc":[{"id":"1.229554895","rc":[{"atb":[[38,2.82],[24,9.08],[29,7.46]],"id":50605162},{"atl":[[550,0.38],[450,0.3]],"id":50605162}],"con":true,"img":false}]}
{"op":"mcm","clk":"11449780665","pt":1717314586827,"mc":[{"id":"1.229554895","rc":[{"atl":[[4.5,4.28]],"id":65732558}],"con":true,"img":false}]}
{"op":"mcm","clk":"11449780742","pt":1717314587951,"mc":[{"id":"1.229554895","rc":[{"atl":[[800,2.07],[980,2.61]],"id":50605162}],"con":true,"img":false}]}
{"op":"mcm","clk":"11449781836","pt":1717314602087,"mc":[{"id":"1.229554895","rc":[{"atl":[[4.5,7.25]],"id":65732558}],"con":true,"img":false}]}
{"op":"mcm","clk":"11449781871","pt":1717314602399,"mc":[{"id":"1.229554895","rc":[{"atl":[[1000,2.7]],"id":61028210}],"con":true,"img":false}]}
{"op":"mcm","clk":"11449781898","pt":1717314602706,"mc":[{"id":"1.229554895","rc":[{"atl":[[1000,2]],"id":61028210}],"con":true,"img":false}]}
{"op":"mcm","clk":"11449781927","pt":1717314602967,"mc":[{"id":"1.229554895","rc":[{"atl":[[1000,1.85]],"id":61028210}],"con":true,"img":false}]}
{"op":"mcm","clk":"11449781936","pt":1717314603069,"mc":[{"id":"1.229554895","rc":[{"atl":[[55,0.15]],"id":61028210}],"con":true,"img":false}]}
{"op":"mcm","clk":"11449783825","pt":1717314627052,"mc":[{"id":"1.229554895","rc":[{"spn":246.0,"spf":"NaN","id":50605162},{"atl":[[75,0]],"id":61028210}],"con":true,"img":false}]}
{"op":"mcm","clk":"11449783835","pt":1717314627162,"mc":[{"id":"1.229554895","rc":[{"atl":[[65,2.61]],"id":61028210}],"con":true,"img":false}]}
{"op":"mcm","clk":"11449784689","pt":1717314638044,"mc":[{"id":"1.229554895","rc":[{"atl":[[4.5,2.96]],"id":65732558}],"con":true,"img":false}]}
{"op":"mcm","clk":"11449787800","pt":1717314675122,"mc":[{"id":"1.229554895","rc":[{"atl":[[4.5,7.25]],"id":65732558}],"con":true,"img":false}]}
{"op":"mcm","clk":"11449797586","pt":1717314787884,"mc":[{"id":"1.229554895","rc":[{"atl":[[4.5,4.28]],"id":65732558}],"con":true,"img":false}]}
{"op":"mcm","clk":"11449798830","pt":1717314803005,"mc":[{"id":"1.229554895","rc":[{"atl":[[4.5,7.25]],"id":65732558}],"con":true,"img":false}]}
{"op":"mcm","clk":"11449806225","pt":1717314890020,"mc":[{"id":"1.229554895","rc":[{"atl":[[4.5,2.96]],"id":65732558}],"con":true,"img":false}]}
{"op":"mcm","clk":"11449808484","pt":1717314914969,"mc":[{"id":"1.229554895","rc":[{"atb":[[38,0],[24,0],[29,0]],"id":50605162},{"atl":[[550,0],[450,0]],"id":50605162}],"con":true,"img":false}]}
{"op":"mcm","clk":"11449808495","pt":1717314915068,"mc":[{"id":"1.229554895","rc":[{"atl":[[800,0.07],[980,4.61]],"id":50605162}],"con":true,"img":false}]}
{"op":"mcm","clk":"11449809601","pt":1717314927162,"mc":[{"id":"1.229554895","rc":[{"atl":[[4.5,7.25]],"id":65732558}],"con":true,"img":false}]}
{"op":"mcm","clk":"11449810091","pt":1717314932928,"mc":[{"id":"1.229554895","rc":[{"atl":[[65,0]],"id":61028210}],"con":true,"img":false}]}
{"op":"mcm","clk":"11449810100","pt":1717314932996,"mc":[{"id":"1.229554895","rc":[{"atl":[[75,2.61]],"id":61028210}],"con":true,"img":false}]}
{"op":"mcm","clk":"11449810120","pt":1717314933189,"mc":[{"id":"1.229554895","rc":[{"atl":[[55,0],[1000,2.7]],"id":61028210}],"con":true,"img":false}]}
{"op":"mcm","clk":"11449810158","pt":1717314933502,"mc":[{"id":"1.229554895","rc":[{"atl":[[1000,2]],"id":61028210}],"con":true,"img":false}]}
{"op":"mcm","clk":"11449810185","pt":1717314933806,"mc":[{"id":"1.229554895","rc":[{"atl":[[1000,1.85]],"id":61028210}],"con":true,"img":false}]}
{"op":"mcm","clk":"11449810194","pt":1717314933910,"mc":[{"id":"1.229554895","rc":[{"atl":[[65,0.15]],"id":61028210}],"con":true,"img":false}]}
{"op":"mcm","clk":"11449810835","pt":1717314940922,"mc":[{"id":"1.229554895","rc":[{"atb":[[38,2.82],[24,9.08],[29,7.46]],"id":50605162},{"atl":[[550,0.38],[450,0.3]],"id":50605162}],"con":true,"img":false}]}
{"op":"mcm","clk":"11449810846","pt":1717314941029,"mc":[{"id":"1.229554895","rc":[{"atl":[[800,2.07],[980,2.61]],"id":50605162}],"con":true,"img":false}]}
{"op":"mcm","clk":"11449814880","pt":1717314986945,"mc":[{"id":"1.229554895","rc":[{"atl":[[75,0]],"id":61028210},{"spn":35.25,"spf":"NaN","id":61028210}],"con":true,"img":false}]}
{"op":"mcm","clk":"11449814887","pt":1717314987056,"mc":[{"id":"1.229554895","rc":[{"atl":[[65,2.76]],"id":61028210}],"con":true,"img":false}]}
{"op":"mcm","clk":"11449815587","pt":1717314994195,"mc":[{"id":"1.229554895","rc":[{"atl":[[4.5,4.28]],"id":65732558}],"con":true,"img":false}]}
{"op":"mcm","clk":"11449817025","pt":1717315009397,"mc":[{"id":"1.229554895","rc":[{"atl":[[4.5,7.25]],"id":65732558}],"con":true,"img":false}]}
{"op":"mcm","clk":"11449818680","pt":1717315027822,"mc":[{"id":"1.229554895","rc":[{"atl":[[990,0.17]],"id":63161712},{"atl":[[990,0.17]],"id":58069703},{"atl":[[990,0.17]],"id":50605162},{"atl":[[990,0.17]],"id":65732558},{"atl":[[1000,1.17]],"id":61028210}],"con":true,"img":false}]}
{"op":"mcm","clk":"11449836973","pt":1717315150832,"mc":[{"id":"1.229554895","rc":[{"atl":[[4.5,2.96]],"id":65732558}],"con":true,"img":false}]}
{"op":"mcm","clk":"11449838858","pt":1717315171031,"mc":[{"id":"1.229554895","rc":[{"atb":[[4.1,16.13],[3.05,24.39]],"id":58069703},{"atb":[[6.2,9.62],[4.1,16.13],[3.05,24.39]],"id":50605162},{"atb":[[4.1,16.13],[1.51,98.04],[3.05,24.39]],"id":61028210}],"con":true,"img":false}]}
{"op":"mcm","clk":"11449838871","pt":1717315171131,"mc":[{"id":"1.229554895","rc":[{"atl":[[16,10],[34,10]],"id":63161712},{"atb":[[2.12,44.64]],"id":58069703},{"atb":[[1.51,98.04]],"id":50605162},{"atl":[[34,10]],"id":65732558}],"con":true,"img":false}]}
{"op":"mcm","clk":"11449838883","pt":1717315171235,"mc":[{"id":"1.229554895","rc":[{"atb":[[1.51,98.04]],"id":58069703},{"atb":[[2.12,44.64]],"id":50605162},{"atl":[[16,16.67]],"id":65732558},{"atb":[[2.12,44.64]],"id":61028210}],"con":true,"img":false}]}
{"op":"mcm","clk":"11449839697","pt":1717315179024,"mc":[{"id":"1.229554895","rc":[{"atl":[[4.5,7.25]],"id":65732558}],"con":true,"img":false}]}
{"op":"mcm","clk":"11449841570","pt":1717315198759,"mc":[{"id":"1.229554895","rc":[{"atl":[[4.5,4.28]],"id":65732558}],"con":true,"img":false}]}
{"op":"mcm","clk":"11449842617","pt":1717315208092,"mc":[{"id":"1.229554895","rc":[{"atl":[[1000,2.03]],"id":61028210}],"con":true,"img":false}]}
{"op":"mcm","clk":"11449842656","pt":1717315208407,"mc":[{"id":"1.229554895","rc":[{"atl":[[65,2.61]],"id":61028210}],"con":true,"img":false}]}
{"op":"mcm","clk":"11449842811","pt":1717315209761,"mc":[{"id":"1.229554895","rc":[{"atl":[[1000,1.33]],"id":61028210}],"con":true,"img":false}]}
{"op":"mcm","clk":"11449843001","pt":1717315211470,"mc":[{"id":"1.229554895","rc":[{"atl":[[1000,1.17]],"id":61028210}],"con":true,"img":false}]}
{"op":"mcm","clk":"11449843010","pt":1717315211575,"mc":[{"id":"1.229554895","rc":[{"atl":[[55,0.15]],"id":61028210}],"con":true,"img":false}]}
{"op":"mcm","clk":"11449843305","pt":1717315214392,"mc":[{"id":"1.229554895","rc":[{"atl":[[4.5,7.25]],"id":65732558}],"con":true,"img":false}]}
{"op":"mcm","clk":"11449846431","pt":1717315247004,"mc":[{"id":"1.229554895","rc":[{"atl":[[2.88,73.97]],"id":63161712}],"con":true,"img":false}]}
{"op":"mcm","clk":"11449846456","pt":1717315247219,"mc":[{"id":"1.229554895","rc":[{"atl":[[4.7,5.96]],"id":65732558}],"con":true,"img":false}]}
{"op":"mcm","clk":"11449846483","pt":1717315247424,"mc":[{"id":"1.229554895","rc":[{"atl":[[80,5.96]],"id":61028210}],"con":true,"img":false}]}
{"op":"mcm","clk":"11449846516","pt":1717315247732,"mc":[{"id":"1.229554895","rc":[{"atb":[[1.25,7.66]],"id":63161712}],"con":true,"img":false}]}
{"op":"mcm","clk":"11449846551","pt":1717315248043,"mc":[{"id":"1.229554895","rc":[{"atb":[[1.86,7.66]],"id":65732558}],"con":true,"img":false}]}
{"op":"mcm","clk":"11449846627","pt":1717315248306,"mc":[{"id":"1.229554895","rc":[{"atb":[[9.8,7.66]],"id":61028210}],"con":true,"img":false}]}
{"op":"mcm","clk":"11449846659","pt":1717315248621,"mc":[{"id":"1.229554895","rc":[{"atb":[[18,7.66]],"id":58069703}],"con":true,"img":false}]}
{"op":"mcm","clk":"11449846693","pt":1717315248941,"mc":[{"id":"1.229554895","rc":[{"atb":[[42,10.28]],"id":50605162}],"con":true,"img":false}]}
{"op":"mcm","clk":"11449850269","pt":1717315286186,"mc":[{"id":"1.229554895","rc":[{"atb":[[17.5,0]],"id":58069703},{"spn":41.5,"spf":"NaN","id":58069703},{"spn":32.75,"spf":"NaN","id":61028210}],"con":true,"img":false}]}
{"op":"mcm","clk":"11449850279","pt":1717315286285,"mc":[{"id":"1.229554895","rc":[{"atb":[[18.5,3.4]],"id":58069703}],"con":true,"img":false}]}
{"op":"mcm","clk":"11449851196","pt":1717315295583,"mc":[{"id":"1.229554895","rc":[{"atb":[[38,0],[24,0],[29,0]],"id":50605162},{"atl":[[550,0],[450,0]],"id":50605162}],"con":true,"img":false}]}
{"op":"mcm","clk":"11449851204","pt":1717315295685,"mc":[{"id":"1.229554895","rc":[{"atl":[[800,0.07],[980,4.61]],"id":50605162}],"con":true,"img":false}]}
{"op":"mcm","clk":"11449852314","pt":1717315307210,"mc":[{"id":"1.229554895","rc":[{"atb":[[9.2,0]],"id":61028210},{"atl":[[65,0]],"id":61028210}],"con":true,"img":false}]}
{"op":"mcm","clk":"11449852327","pt":1717315307325,"mc":[{"id":"1.229554895","rc":[{"atb":[[9.6,14.64]],"id":61028210},{"atl":[[75,2.61]],"id":61028210}],"con":true,"img":false}]}
{"op":"mcm","clk":"11449852337","pt":1717315307419,"mc":[{"id":"1.229554895","rc":[{"atl":[[55,0],[1000,2.03]],"id":61028210}],"con":true,"img":false}]}
{"op":"mcm","clk":"11449852357","pt":1717315307683,"mc":[{"id":"1.229554895","rc":[{"atl":[[1000,1.33]],"id":61028210}],"con":true,"img":false}]}
{"op":"mcm","clk":"11449852379","pt":1717315307987,"mc":[{"id":"1.229554895","rc":[{"atl":[[1000,1.17]],"id":61028210}],"con":true,"img":false}]}
{"op":"mcm","clk":"11449852392","pt":1717315308091,"mc":[{"id":"1.229554895","rc":[{"atl":[[65,0.15]],"id":61028210}],"con":true,"img":false}]}
{"op":"mcm","clk":"11449852423","pt":1717315308401,"mc":[{"id":"1.229554895","rc":[{"atl":[[65,0],[1000,2.03]],"id":61028210}],"con":true,"img":false}]}
{"op":"mcm","clk":"11449852457","pt":1717315308814,"mc":[{"id":"1.229554895","rc":[{"atl":[[1000,1.34]],"id":61028210}],"con":true,"img":false}]}
{"op":"mcm","clk":"11449852488","pt":1717315309125,"mc":[{"id":"1.229554895","rc":[{"atl":[[1000,1.17]],"id":61028210}],"con":true,"img":false}]}
{"op":"mcm","clk":"11449852496","pt":1717315309242,"mc":[{"id":"1.229554895","rc":[{"atl":[[50,0.17]],"id":61028210}],"con":true,"img":false}]}
{"op":"mcm","clk":"11449853607","pt":1717315320659,"mc":[{"id":"1.229554895","rc":[{"atb":[[38,2.82],[24,9.08],[29,7.46]],"id":50605162},{"atl":[[550,0.38],[450,0.3]],"id":50605162}],"con":true,"img":false}]}
{"op":"mcm","clk":"11449853624","pt":1717315320716,"mc":[{"id":"1.229554895","rc":[{"atl":[[800,2.07],[980,2.61]],"id":50605162}],"con":true,"img":false}]}
{"op":"mcm","clk":"11449854084","pt":1717315325107,"mc":[{"id":"1.229554895","rc":[{"atl":[[50,0]],"id":61028210}],"con":true,"img":false}]}
{"op":"mcm","clk":"11449854095","pt":1717315325210,"mc":[{"id":"1.229554895","rc":[{"atl":[[1000,2.03]],"id":61028210}],"con":true,"img":false}]}
{"op":"mcm","clk":"11449854155","pt":1717315325834,"mc":[{"id":"1.229554895","rc":[{"atl":[[1000,1.34]],"id":61028210}],"con":true,"img":false}]}
{"op":"mcm","clk":"11449854188","pt":1717315326144,"mc":[{"id":"1.229554895","rc":[{"atl":[[1000,1.17]],"id":61028210}],"con":true,"img":false}]}
{"op":"mcm","clk":"11449854200","pt":1717315326249,"mc":[{"id":"1.229554895","rc":[{"atl":[[55,0.17]],"id":61028210}],"con":true,"img":false}]}
{"op":"mcm","clk":"11449858774","pt":1717315370379,"mc":[{"id":"1.229554895","rc":[{"spn":41.75,"spf":"NaN","id":58069703},{"atl":[[75,0]],"id":61028210}],"con":true,"img":false}]}
{"op":"mcm","clk":"11449858784","pt":1717315370483,"mc":[{"id":"1.229554895","rc":[{"atl":[[65,2.61]],"id":61028210}],"con":true,"img":false}]}
{"op":"mcm","clk":"11449858819","pt":1717315370797,"mc":[{"id":"1.229554895","rc":[{"atl":[[55,0],[1000,2.03]],"id":61028210}],"con":true,"img":false}]}
{"op":"mcm","clk":"11449858848","pt":1717315371104,"mc":[{"id":"1.229554895","rc":[{"atl":[[1000,1.34]],"id":61028210}],"con":true,"img":false}]}
{"op":"mcm","clk":"11449858880","pt":1717315371416,"mc":[{"id":"1.229554895","rc":[{"atl":[[1000,1.17]],"id":61028210}],"con":true,"img":false}]}
{"op":"mcm","clk":"11449858890","pt":1717315371464,"mc":[{"id":"1.229554895","rc":[{"atl":[[60,2.78]],"id":61028210}],"con":true,"img":false}]}
{"op":"mcm","clk":"11449859033","pt":1717315372905,"mc":[{"id":"1.229554895","rc":[{"atl":[[4.5,2.96]],"id":65732558}],"con":true,"img":false}]}
{"op":"mcm","clk":"11449861940","pt":1717315403312,"mc":[{"id":"1.229554895","rc":[{"atl":[[4.5,0]],"id":65732558}],"con":true,"img":false}]}
{"op":"mcm","clk":"11449861980","pt":1717315403725,"mc":[{"id":"1.229554895","rc":[{"atl":[[4.7,0]],"id":65732558}],"con":true,"img":false}]}
{"op":"mcm","clk":"11449861990","pt":1717315403829,"mc":[{"id":"1.229554895","rc":[{"atl":[[4.8,5.96]],"id":65732558}],"con":true,"img":false}]}
{"op":"mcm","clk":"11449862835","pt":1717315412239,"mc":[{"id":"1.229554895","rc":[{"atl":[[4.5,4.28]],"id":65732558}],"con":true,"img":false}]}
{"op":"mcm","clk":"11449862928","pt":1717315412965,"mc":[{"id":"1.229554895","rc":[{"atl":[[4.8,0]],"id":65732558}],"con":true,"img":false}]}
{"op":"mcm","clk":"11449862939","pt":1717315413071,"mc":[{"id":"1.229554895","rc":[{"atl":[[4.7,5.96]],"id":65732558}],"con":true,"img":false}]}
{"op":"mcm","clk":"11449863857","pt":1717315421788,"mc":[{"id":"1.229554895","rc":[{"atl":[[4.5,7.25]],"id":65732558}],"con":true,"img":false}]}
{"op":"mcm","clk":"11449866506","pt":1717315447130,"mc":[{"id":"1.229554895","rc":[{"atb":[[3.2,0]],"id":58069703},{"atb":[[2.1,0],[2.14,87.72]],"id":65732558},{"spn":3.32,"spf":"NaN","id":65732558},{"atl":[[70,0],[75,2]],"id":61028210},{"spn":35.25,"spf":"NaN","id":61028210}],"con":true,"img":false}]}
{"op":"mcm","clk":"11449866531","pt":1717315447341,"mc":[{"id":"1.229554895","rc":[{"atb":[[3.2,44.64]],"id":58069703}],"con":true,"img":false}]}
{"op":"mcm","clk":"11449866641","pt":1717315448473,"mc":[{"id":"1.229554895","rc":[{"atl":[[65,4.61]],"id":61028210}],"con":true,"img":false}]}
{"op":"mcm","clk":"11449866654","pt":1717315448526,"mc":[{"id":"1.229554895","rc":[{"atl":[[75,0]],"id":61028210}],"con":true,"img":false}]}
{"op":"mcm","clk":"11449878912","pt":1717315568522,"mc":[{"id":"1.229554895","rc":[{"atb":[[2.14,0],[2.1,90.91]],"id":65732558},{"spn":3.31,"spf":"NaN","id":65732558},{"atl":[[65,2.61],[70,2]],"id":61028210}],"con":true,"img":false}]}
{"op":"mcm","clk":"11449880775","pt":1717315586543,"mc":[{"id":"1.229554895","rc":[{"atl":[[2.7,0]],"id":63161712}],"con":true,"img":false}]}
{"op":"mcm","clk":"11449880788","pt":1717315586647,"mc":[{"id":"1.229554895","rc":[{"atl":[[2.8,33]],"id":63161712}],"con":true,"img":false}]}
{"op":"mcm","clk":"11449882206","pt":1717315601150,"mc":[{"id":"1.229554895","rc":[{"atb":[[34,0]],"id":50605162}],"con":true,"img":false}]}
{"op":"mcm","clk":"11449882217","pt":1717315601254,"mc":[{"id":"1.229554895","rc":[{"atb":[[30,3.11]],"id":50605162}],"con":true,"img":false}]}
{"op":"mcm","clk":"11449882589","pt":1717315604647,"mc":[{"id":"1.229554895","rc":[{"atl":[[4.5,2.96]],"id":65732558}],"con":true,"img":false}]}
{"op":"mcm","clk":"11449882987","pt":1717315608633,"mc":[{"id":"1.229554895","rc":[{"atl":[[4.5,0]],"id":65732558}],"con":true,"img":false}]}
{"op":"mcm","clk":"11449883033","pt":1717315609051,"mc":[{"id":"1.229554895","rc":[{"atl":[[4.7,0]],"id":65732558}],"con":true,"img":false}]}
{"op":"mcm","clk":"11449883045","pt":1717315609147,"mc":[{"id":"1.229554895","rc":[{"atl":[[4.8,5.96]],"id":65732558}],"con":true,"img":false}]}
{"op":"mcm","clk":"11449884612","pt":1717315623991,"mc":[{"id":"1.229554895","rc":[{"atl":[[4.5,2.96]],"id":65732558}],"con":true,"img":false}]}
{"op":"mcm","clk":"11449884674","pt":1717315624453,"mc":[{"id":"1.229554895","rc":[{"atl":[[4.8,0]],"id":65732558}],"con":true,"img":false}]}
{"op":"mcm","clk":"11449884688","pt":1717315624563,"mc":[{"id":"1.229554895","rc":[{"atl":[[4.7,5.96]],"id":65732558}],"con":true,"img":false}]}
{"op":"mcm","clk":"11449886151","pt":1717315638689,"mc":[{"id":"1.229554895","rc":[{"atl":[[800,2]],"id":50605162}],"con":true,"img":false}]}
{"op":"mcm","clk":"11449886159","pt":1717315638789,"mc":[{"id":"1.229554895","rc":[{"atl":[[670,0.07]],"id":50605162}],"con":true,"img":false}]}
{"op":"mcm","clk":"11449886180","pt":1717315638997,"mc":[{"id":"1.229554895","rc":[{"atl":[[720,2],[800,0]],"id":50605162}],"con":true,"img":false}]}
{"op":"mcm","clk":"11449887779","pt":1717315654720,"mc":[{"id":"1.229554895","rc":[{"atl":[[4.5,7.25]],"id":65732558}],"con":true,"img":false}]}
{"op":"mcm","clk":"11449888891","pt":1717315666116,"mc":[{"id":"1.229554895","rc":[{"atl":[[980,0]],"id":50605162}],"con":true,"img":false}]}
{"op":"mcm","clk":"11449888900","pt":1717315666215,"mc":[{"id":"1.229554895","rc":[{"atl":[[710,2.61]],"id":50605162}],"con":true,"img":false}]}
{"op":"mcm","clk":"11449891787","pt":1717315694541,"mc":[{"id":"1.229554895","rc":[{"atb":[[30,0]],"id":50605162}],"con":true,"img":false}]}
{"op":"mcm","clk":"11449891799","pt":1717315694646,"mc":[{"id":"1.229554895","rc":[{"atb":[[32,3.11]],"id":50605162}],"con":true,"img":false}]}
{"op":"mcm","clk":"11449893588","pt":1717315712098,"mc":[{"id":"1.229554895","rc":[{"atb":[[38,0],[24,0],[29,0]],"id":50605162},{"atl":[[550,0],[450,0]],"id":50605162},{"spn":356.0,"spf":"NaN","id":50605162}],"con":true,"img":false}]}
{"op":"mcm","clk":"11449896536","pt":1717315739649,"mc":[{"id":"1.229554895","rc":[{"atl":[[65,0]],"id":61028210}],"con":true,"img":false}]}
{"op":"mcm","clk":"11449896554","pt":1717315739759,"mc":[{"id":"1.229554895","rc":[{"atl":[[75,2.61]],"id":61028210}],"con":true,"img":false}]}
{"op":"mcm","clk":"11449896899","pt":1717315742980,"mc":[{"id":"1.229554895","rc":[{"atb":[[38,2.82],[24,9.08],[29,7.46]],"id":50605162},{"atl":[[550,0.38],[450,0.3]],"id":50605162}],"con":true,"img":false}]}
{"op":"mcm","clk":"11449902419","pt":1717315795645,"mc":[{"id":"1.229554895","rc":[{"spn":246.0,"spf":"NaN","id":50605162},{"atl":[[75,0]],"id":61028210}],"con":true,"img":false}]}
{"op":"mcm","clk":"11449902431","pt":1717315795746,"mc":[{"id":"1.229554895","rc":[{"atl":[[65,2.61]],"id":61028210}],"con":true,"img":false}]}
{"op":"mcm","clk":"11449904327","pt":1717315814383,"mc":[{"id":"1.229554895","rc":[{"atl":[[4.5,4.28]],"id":65732558}],"con":true,"img":false}]}
{"op":"mcm","clk":"11449905402","pt":1717315825078,"mc":[{"id":"1.229554895","rc":[{"atl":[[4.5,7.25]],"id":65732558}],"con":true,"img":false}]}
{"op":"mcm","clk":"11449908431","pt":1717315854439,"mc":[{"id":"1.229554895","rc":[{"atb":[[1.25,0]],"id":63161712}],"con":true,"img":false}]}
{"op":"mcm","clk":"11449908440","pt":1717315854504,"mc":[{"id":"1.229554895","rc":[{"atb":[[1.18,7.66]],"id":63161712}],"con":true,"img":false}]}
{"op":"mcm","clk":"11449908472","pt":1717315854800,"mc":[{"id":"1.229554895","rc":[{"atb":[[1.86,0]],"id":65732558}],"con":true,"img":false}]}
{"op":"mcm","clk":"11449908482","pt":1717315854907,"mc":[{"id":"1.229554895","rc":[{"atb":[[1.76,7.66]],"id":65732558}],"con":true,"img":false}]}
{"op":"mcm","clk":"11449908518","pt":1717315855225,"mc":[{"id":"1.229554895","rc":[{"atb":[[9.8,0]],"id":61028210}],"con":true,"img":false}]}
{"op":"mcm","clk":"11449908531","pt":1717315855318,"mc":[{"id":"1.229554895","rc":[{"atb":[[9.4,20.11]],"id":61028210}],"con":true,"img":false}]}
{"op":"mcm","clk":"11449908560","pt":1717315855631,"mc":[{"id":"1.229554895","rc":[{"atb":[[18,0]],"id":58069703}],"con":true,"img":false}]}
{"op":"mcm","clk":"11449908572","pt":1717315855726,"mc":[{"id":"1.229554895","rc":[{"atb":[[17.5,7.66]],"id":58069703}],"con":true,"img":false}]}
{"op":"mcm","clk":"11449908598","pt":1717315856040,"mc":[{"id":"1.229554895","rc":[{"atb":[[42,2.61]],"id":50605162}],"con":true,"img":false}]}
{"op":"mcm","clk":"11449908610","pt":1717315856096,"mc":[{"id":"1.229554895","rc":[{"atb":[[40,7.66]],"id":50605162}],"con":true,"img":false}]}
{"op":"mcm","clk":"11449912953","pt":1717315896350,"mc":[{"id":"1.229554895","rc":[{"atl":[[4.5,2.96]],"id":65732558}],"con":true,"img":false}]}
{"op":"mcm","clk":"11449917169","pt":1717315936746,"mc":[{"id":"1.229554895","rc":[{"atl":[[670,2.07],[720,0]],"id":50605162},{"atb":[[2.1,0],[2.14,87.72]],"id":65732558},{"spn":3.32,"spf":"NaN","id":65732558},{"atl":[[65,4.61],[70,0]],"id":61028210}],"con":true,"img":false}]}
{"op":"mcm","clk":"11449917828","pt":1717315943029,"mc":[{"id":"1.229554895","rc":[{"atl":[[710,0]],"id":50605162}],"con":true,"img":false}]}
{"op":"mcm","clk":"11449917839","pt":1717315943121,"mc":[{"id":"1.229554895","rc":[{"atl":[[970,2.61]],"id":50605162}],"con":true,"img":false}]}
{"op":"mcm","clk":"11449918556","pt":1717315949835,"mc":[{"id":"1.229554895","rc":[{"atl":[[2.88,68.01]],"id":63161712}],"con":true,"img":false}]}
{"op":"mcm","clk":"11449918581","pt":1717315950040,"mc":[{"id":"1.229554895","rc":[{"atl":[[80,0]],"id":61028210}],"con":true,"img":false}]}
{"op":"mcm","clk":"11449918603","pt":1717315950244,"mc":[{"id":"1.229554895","rc":[{"atl":[[4.7,0]],"id":65732558}],"con":true,"img":false}]}
{"op":"mcm","clk":"11449918633","pt":1717315950454,"mc":[{"id":"1.229554895","rc":[{"atb":[[1.18,0]],"id":63161712}],"con":true,"img":false}]}
{"op":"mcm","clk":"11449918651","pt":1717315950669,"mc":[{"id":"1.229554895","rc":[{"atb":[[1.76,0]],"id":65732558}],"con":true,"img":false}]}
{"op":"mcm","clk":"11449918670","pt":1717315950865,"mc":[{"id":"1.229554895","rc":[{"atb":[[9.4,12.44]],"id":61028210}],"con":true,"img":false}]}
{"op":"mcm","clk":"11449918689","pt":1717315951072,"mc":[{"id":"1.229554895","rc":[{"atb":[[17.5,0]],"id":58069703}],"con":true,"img":false}]}
{"op":"mcm","clk":"11449918749","pt":1717315951442,"mc":[{"id":"1.229554895","rc":[{"atb":[[40,0]],"id":50605162}],"con":true,"img":false}]}
{"op":"mcm","clk":"11449925326","pt":1717316015584,"mc":[{"id":"1.229554895","rc":[{"atl":[[4.5,0]],"id":65732558},{"spn":3.52,"spf":"NaN","id":65732558}],"con":true,"img":false}]}
{"op":"mcm","clk":"11449926081","pt":1717316023328,"mc":[{"id":"1.229554895","rc":[{"atl":[[2.88,73.97]],"id":63161712}],"con":true,"img":false}]}
{"op":"mcm","clk":"11449926100","pt":1717316023534,"mc":[{"id":"1.229554895","rc":[{"atl":[[4.8,5.96]],"id":65732558}],"con":true,"img":false}]}
{"op":"mcm","clk":"11449926136","pt":1717316023853,"mc":[{"id":"1.229554895","rc":[{"atl":[[80,5.96]],"id":61028210}],"con":true,"img":false}]}
{"op":"mcm","clk":"11449926168","pt":1717316024159,"mc":[{"id":"1.229554895","rc":[{"atb":[[1.22,7.66]],"id":63161712}],"con":true,"img":false}]}
{"op":"mcm","clk":"11449926197","pt":1717316024463,"mc":[{"id":"1.229554895","rc":[{"atb":[[1.82,127.67]],"id":65732558}],"con":true,"img":false}]}
{"op":"mcm","clk":"11449926216","pt":1717316024619,"mc":[{"id":"1.229554895","rc":[{"atb":[[9.6,22.31]],"id":61028210}],"con":true,"img":false}]}
{"op":"mcm","clk":"11449926244","pt":1717316024942,"mc":[{"id":"1.229554895","rc":[{"atb":[[18,7.66]],"id":58069703}],"con":true,"img":false}]}
{"op":"mcm","clk":"11449926266","pt":1717316025244,"mc":[{"id":"1.229554895","rc":[{"atb":[[40,7.66]],"id":50605162}],"con":true,"img":false}]}
{"op":"mcm","clk":"11449927226","pt":1717316034684,"mc":[{"id":"1.229554895","rc":[{"atb":[[1.22,0]],"id":63161712}],"con":true,"img":false}]}
{"op":"mcm","clk":"11449927237","pt":1717316034782,"mc":[{"id":"1.229554895","rc":[{"atb":[[1.25,7.66]],"id":63161712}],"con":true,"img":false}]}
{"op":"mcm","clk":"11449927276","pt":1717316035096,"mc":[{"id":"1.229554895","rc":[{"atb":[[1.82,120]],"id":65732558}],"con":true,"img":false}]}
{"op":"mcm","clk":"11449927286","pt":1717316035148,"mc":[{"id":"1.229554895","rc":[{"atb":[[1.86,7.66]],"id":65732558}],"con":true,"img":false}]}
{"op":"mcm","clk":"11449927321","pt":1717316035457,"mc":[{"id":"1.229554895","rc":[{"atb":[[9.6,14.64]],"id":61028210}],"con":true,"img":false}]}
{"op":"mcm","clk":"11449927333","pt":1717316035565,"mc":[{"id":"1.229554895","rc":[{"atb":[[9.8,7.66]],"id":61028210}],"con":true,"img":false}]}
{"op":"mcm","clk":"11449927362","pt":1717316035873,"mc":[{"id":"1.229554895","rc":[{"atb":[[40,0]],"id":50605162}],"con":true,"img":false}]}
{"op":"mcm","clk":"11449927370","pt":1717316035972,"mc":[{"id":"1.229554895","rc":[{"atb":[[42,10.28]],"id":50605162}],"con":true,"img":false}]}
{"op":"mcm","clk":"11449929421","pt":1717316056772,"mc":[{"id":"1.229554895","rc":[{"atb":[[2.14,0],[2.1,90.91]],"id":65732558},{"atl":[[65,2.61],[70,2]],"id":61028210}],"con":true,"img":false}]}
{"op":"mcm","clk":"11449931915","pt":1717316084342,"mc":[{"id":"1.229554895","rc":[{"atb":[[38,0],[24,0],[29,0]],"id":50605162},{"atl":[[550,0],[450,0]],"id":50605162},{"spn":356.0,"spf":"NaN","id":50605162},{"spn":3.46,"spf":"NaN","id":65732558}],"con":true,"img":false}]}
{"op":"mcm","clk":"11449931932","pt":1717316084548,"mc":[{"id":"1.229554895","rc":[{"atl":[[670,0.07],[970,4.61]],"id":50605162}],"con":true,"img":false}]}
{"op":"mcm","clk":"11449933162","pt":1717316098221,"mc":[{"id":"1.229554895","rc":[{"atb":[[38,2.82],[24,9.08],[29,7.46]],"id":50605162},{"atl":[[550,0.38],[450,0.3]],"id":50605162}],"con":true,"img":false}]}
{"op":"mcm","clk":"11449933171","pt":1717316098384,"mc":[{"id":"1.229554895","rc":[{"atl":[[720,2],[970,2.61]],"id":50605162}],"con":true,"img":false}]}
{"op":"mcm","clk":"11449934656","pt":1717316114453,"mc":[{"id":"1.229554895","rc":[{"atl":[[4.5,4.28]],"id":65732558}],"con":true,"img":false}]}
{"op":"mcm","clk":"11449934678","pt":1717316114763,"mc":[{"id":"1.229554895","rc":[{"atl":[[4.8,0]],"id":65732558}],"con":true,"img":false}]}
{"op":"mcm","clk":"11449934689","pt":1717316114865,"mc":[{"id":"1.229554895","rc":[{"atl":[[4.7,5.96]],"id":65732558}],"con":true,"img":false}]}
{"op":"mcm","clk":"11449934817","pt":1717316116165,"mc":[{"id":"1.229554895","rc":[{"atb":[[1.4,19.62]],"id":63161712},{"atb":[[2.08,7.26]],"id":65732558},{"atl":[[4.5,7.25]],"id":65732558}],"con":true,"img":false}]}
{"op":"mcm","clk":"11449934867","pt":1717316116788,"mc":[{"id":"1.229554895","rc":[{"atl":[[670,2.07],[720,0]],"id":50605162},{"atb":[[2.1,0],[2.14,87.72]],"id":65732558},{"atl":[[65,4.61],[70,0]],"id":61028210}],"con":true,"img":false}]}
{"op":"mcm","clk":"11449945326","pt":1717316229641,"mc":[{"id":"1.229554895","rc":[{"atb":[[1.5,2.61]],"id":63161712},{"spn":1.75,"spf":"NaN","id":63161712},{"spn":246.0,"spf":"NaN","id":50605162},{"atb":[[2.24,2.61]],"id":65732558},{"spn":3.37,"spf":"NaN","id":65732558}],"con":true,"img":false}]}
{"op":"mcm","clk":"11449945338","pt":1717316229744,"mc":[{"id":"1.229554895","rc":[{"atb":[[2.18,84.75]],"id":65732558}],"con":true,"img":false}]}
{"op":"mcm","clk":"11449945346","pt":1717316229799,"mc":[{"id":"1.229554895","rc":[{"atb":[[2.14,0]],"id":65732558}],"con":true,"img":false}]}
{"op":"mcm","clk":"11449945975","pt":1717316236818,"mc":[{"id":"1.229554895","rc":[{"atb":[[2.18,0],[2.1,90.91]],"id":65732558},{"atl":[[65,2.61],[70,2]],"id":61028210}],"con":true,"img":false}]}
{"op":"mcm","clk":"11449950898","pt":1717316294605,"mc":[{"id":"1.229554895","rc":[{"atb":[[1.4,0]],"id":63161712},{"atb":[[2.08,0]],"id":65732558}],"con":true,"img":false}]}
{"op":"mcm","clk":"11449952298","pt":1717316309937,"mc":[{"id":"1.229554895","rc":[{"atl":[[4.5,4.28]],"id":65732558}],"con":true,"img":false}]}
{"op":"mcm","clk":"11449952403","pt":1717316311128,"mc":[{"id":"1.229554895","rc":[{"atb":[[3.2,0]],"id":58069703},{"atl":[[140,2],[430,0]],"id":58069703},{"atb":[[3.2,0]],"id":50605162},{"atb":[[2.22,81.97],[2.1,0]],"id":65732558},{"atl":[[70,0],[75,2]],"id":61028210}],"con":true,"img":false}]}
{"op":"mcm","clk":"11449952414","pt":1717316311249,"mc":[{"id":"1.229554895","rc":[{"atb":[[3.2,44.64]],"id":58069703},{"atb":[[3.2,24.39]],"id":50605162}],"con":true,"img":false}]}
{"op":"mcm","clk":"11449952435","pt":1717316311442,"mc":[{"id":"1.229554895","rc":[{"atl":[[65,0]],"id":58069703}],"con":true,"img":false}]}
{"op":"mcm","clk":"11449952523","pt":1717316312520,"mc":[{"id":"1.229554895","rc":[{"atl":[[4.5,0]],"id":65732558}],"con":true,"img":false}]}
{"op":"mcm","clk":"11449952571","pt":1717316313042,"mc":[{"id":"1.229554895","rc":[{"atl":[[65,0]],"id":61028210}],"con":true,"img":false}]}
{"op":"mcm","clk":"11449952582","pt":1717316313138,"mc":[{"id":"1.229554895","rc":[{"atl":[[4.7,0]],"id":65732558},{"atl":[[70,2.61]],"id":61028210}],"con":true,"img":false}]}
{"op":"mcm","clk":"11449952591","pt":1717316313246,"mc":[{"id":"1.229554895","rc":[{"atl":[[4.8,5.96]],"id":65732558}],"con":true,"img":false}]}
{"op":"mcm","clk":"11449952840","pt":1717316316254,"mc":[{"id":"1.229554895","rc":[{"atl":[[75,0],[85,2]],"id":61028210}],"con":true,"img":false}]}
{"op":"mcm","clk":"11449953626","pt":1717316325089,"mc":[{"id":"1.229554895","rc":[{"atl":[[4.5,2.96]],"id":65732558}],"con":true,"img":false}]}
{"op":"mcm","clk":"11449953643","pt":1717316325287,"mc":[{"id":"1.229554895","rc":[{"atb":[[2.16,6.76]],"id":65732558}],"con":true,"img":false}]}
{"op":"mcm","clk":"11449953691","pt":1717316325853,"mc":[{"id":"1.229554895","rc":[{"atl":[[4.8,0]],"id":65732558}],"con":true,"img":false}]}
{"op":"mcm","clk":"11449953698","pt":1717316325955,"mc":[{"id":"1.229554895","rc":[{"atl":[[4.7,5.96]],"id":65732558}],"con":true,"img":false}]}
{"op":"mcm","clk":"11449954247","pt":1717316332976,"mc":[{"id":"1.229554895","rc":[{"atl":[[2.8,0]],"id":63161712}],"con":true,"img":false}]}
{"op":"mcm","clk":"11449954256","pt":1717316333078,"mc":[{"id":"1.229554895","rc":[{"atl":[[2.74,33]],"id":63161712}],"con":true,"img":false}]}
{"op":"mcm","clk":"11449955723","pt":1717316352376,"mc":[{"id":"1.229554895","rc":[{"atl":[[4.5,7.25]],"id":65732558}],"con":true,"img":false}]}
{"op":"mcm","clk":"11449960021","pt":1717316407987,"mc":[{"id":"1.229554895","rc":[{"atl":[[1000,22.77]],"id":58069703},{"spn":44.25,"spf":"NaN","id":58069703}],"con":true,"img":false}]}
{"op":"mcm","clk":"11449960380","pt":1717316412312,"mc":[{"id":"1.229554895","rc":[{"atl":[[1000,22.05]],"id":58069703}],"con":true,"img":false}]}
{"op":"mcm","clk":"11449960746","pt":1717316416707,"mc":[{"id":"1.229554895","rc":[{"atl":[[1000,21.92]],"id":58069703}],"con":true,"img":false}]}
{"op":"mcm","clk":"11449960756","pt":1717316416814,"mc":[{"id":"1.229554895","rc":[{"atl":[[65,0.12]],"id":58069703}],"con":true,"img":false}]}
{"op":"mcm","clk":"11449960810","pt":1717316417429,"mc":[{"id":"1.229554895","rc":[{"atb":[[2.22,0],[2.2,83.33]],"id":65732558}],"con":true,"img":false}]}
{"op":"mcm","clk":"11449960816","pt":1717316417533,"mc":[{"id":"1.229554895","rc":[{"atb":[[2.22,81.97],[2.2,0]],"id":65732558}],"con":true,"img":false}]}
{"op":"mcm","clk":"11449962067","pt":1717316432563,"mc":[{"id":"1.229554895","rc":[{"atb":[[2.22,0],[2.14,87.72]],"id":65732558},{"atl":[[85,0],[90,2]],"id":61028210}],"con":true,"img":false}]}
{"op":"mcm","clk":"11449962072","pt":1717316432666,"mc":[{"id":"1.229554895","rc":[{"atb":[[2.24,9.38],[2.14,0]],"id":65732558}],"con":true,"img":false}]}
{"op":"mcm","clk":"11449962092","pt":1717316432929,"mc":[{"id":"1.229554895","rc":[{"atl":[[2.74,0]],"id":63161712}],"con":true,"img":false}]}
{"op":"mcm","clk":"11449962101","pt":1717316433031,"mc":[{"id":"1.229554895","rc":[{"atl":[[2.82,33]],"id":63161712}],"con":true,"img":false}]}
{"op":"mcm","clk":"11449963165","pt":1717316446474,"mc":[{"id":"1.229554895","rc":[{"atl":[[8,0],[3.1,47.62]],"id":63161712},{"atb":[[3.2,0],[6.2,25.75]],"id":50605162},{"atl":[[16,10],[8.4,13.51]],"id":65732558},{"atb":[[4.1,43.23],[2.16,0]],"id":61028210}],"con":true,"img":false}]}
{"op":"mcm","clk":"11449963621","pt":1717316452777,"mc":[{"id":"1.229554895","rc":[{"atb":[[3.2,0],[5.5,22.22]],"id":58069703}],"con":true,"img":false}]}
{"op":"mcm","clk":"11449963749","pt":1717316454793,"mc":[{"id":"1.229554895","rc":[{"atl":[[2.88,68.01]],"id":63161712}],"con":true,"img":false}]}
{"op":"mcm","clk":"11449963759","pt":1717316454898,"mc":[{"id":"1.229554895","rc":[{"atl":[[4.3,5.96]],"id":63161712}],"con":true,"img":false}]}
{"op":"mcm","clk":"11449963785","pt":1717316455161,"mc":[{"id":"1.229554895","rc":[{"atl":[[4.7,0]],"id":65732558}],"con":true,"img":false}]}
{"op":"mcm","clk":"11449963792","pt":1717316455265,"mc":[{"id":"1.229554895","rc":[{"atl":[[7,5.96]],"id":65732558}],"con":true,"img":false}]}
{"op":"mcm","clk":"11449964172","pt":1717316460684,"mc":[{"id":"1.229554895","rc":[{"atb":[[19.5,2]],"id":58069703},{"atl":[[65,2.12]],"id":58069703},{"atb":[[46,2]],"id":50605162},{"atl":[[670,4.07]],"id":50605162},{"atb":[[11,2]],"id":61028210},{"atl":[[60,4.78]],"id":61028210}],"con":true,"img":false}]}
{"op":"mcm","clk":"11449964414","pt":1717316463886,"mc":[{"id":"1.229554895","rc":[{"atl":[[80,0]],"id":61028210}],"con":true,"img":false}]}
{"op":"mcm","clk":"11449964426","pt":1717316464090,"mc":[{"id":"1.229554895","rc":[{"atb":[[18,0]],"id":58069703}],"con":true,"img":false}]}
{"op":"mcm","clk":"11449964438","pt":1717316464296,"mc":[{"id":"1.229554895","rc":[{"atb":[[1.25,0]],"id":63161712}],"con":true,"img":false}]}
{"op":"mcm","clk":"11449964461","pt":1717316464605,"mc":[{"id":"1.229554895","rc":[{"atb":[[1.86,0]],"id":65732558}],"con":true,"img":false}]}
{"op":"mcm","clk":"11449964469","pt":1717316464762,"mc":[{"id":"1.229554895","rc":[{"atb":[[9.8,0]],"id":61028210}],"con":true,"img":false}]}
{"op":"mcm","clk":"11449964484","pt":1717316464968,"mc":[{"id":"1.229554895","rc":[{"atb":[[42,2.61]],"id":50605162}],"con":true,"img":false}]}
{"op":"mcm","clk":"11449964502","pt":1717316465177,"mc":[{"id":"1.229554895","rc":[{"atl":[[4.3,0]],"id":63161712}],"con":true,"img":false}]}
{"op":"mcm","clk":"11449964519","pt":1717316465382,"mc":[{"id":"1.229554895","rc":[{"atl":[[7,0]],"id":65732558}],"con":true,"img":false}]}
{"op":"mcm","clk":"11449966455","pt":1717316492028,"mc":[{"id":"1.229554895","rc":[{"spn":42.25,"spf":"NaN","id":58069703},{"atb":[[38,0],[24,0],[29,0]],"id":50605162},{"atl":[[550,0],[450,0]],"id":50605162},{"spn":358.0,"spf":"NaN","id":50605162},{"spn":35.5,"spf":"NaN","id":61028210}],"con":true,"img":false}]}
{"op":"mcm","clk":"11449966463","pt":1717316492135,"mc":[{"id":"1.229554895","rc":[{"atl":[[670,0.07],[790,2],[970,4.61]],"id":50605162}],"con":true,"img":false}]}
{"op":"mcm","clk":"11449966477","pt":1717316492337,"mc":[{"id":"1.229554895","rc":[{"atl":[[970,2.61]],"id":50605162}],"con":true,"img":false}]}
{"op":"mcm","clk":"11449966485","pt":1717316492389,"mc":[{"id":"1.229554895","rc":[{"atl":[[970,4.61]],"id":50605162}],"con":true,"img":false}]}
{"op":"mcm","clk":"11449967741","pt":1717316510500,"mc":[{"id":"1.229554895","rc":[{"atl":[[4.5,4.28]],"id":65732558}],"con":true,"img":false}]}
{"op":"mcm","clk":"11449967759","pt":1717316510810,"mc":[{"id":"1.229554895","rc":[{"atb":[[38,2.82],[24,9.08],[29,7.46]],"id":50605162},{"atl":[[550,0.38],[450,0.3]],"id":50605162}],"con":true,"img":false}]}
{"op":"mcm","clk":"11449967777","pt":1717316511023,"mc":[{"id":"1.229554895","rc":[{"atl":[[670,4.07],[790,0],[970,2.61]],"id":50605162}],"con":true,"img":false}]}
{"op":"mcm","clk":"11449967805","pt":1717316511433,"mc":[{"id":"1.229554895","rc":[{"atb":[[5.5,0]],"id":58069703},{"atl":[[140,0],[470,2]],"id":58069703},{"atb":[[46,0]],"id":50605162},{"atb":[[2.24,2.61]],"id":65732558},{"atl":[[8.4,0],[15,7.14]],"id":65732558},{"atl":[[85,2]],"id":61028210}],"con":true,"img":false}]}
{"op":"mcm","clk":"11449967809","pt":1717316511537,"mc":[{"id":"1.229554895","rc":[{"atb":[[1.1,570.6],[1.17,0]],"id":63161712},{"atb":[[19.5,0]],"id":58069703},{"atl":[[65,0.12],[410,2],[470,0]],"id":58069703},{"atb":[[6.2,9.62]],"id":50605162},{"atl":[[670,2.07]],"id":50605162},{"atb":[[1.09,186.66]],"id":65732558},{"atl":[[75,2],[85,0],[90,0]],"id":61028210}],"con":true,"img":false}]}
{"op":"mcm","clk":"11449967821","pt":1717316511747,"mc":[{"id":"1.229554895","rc":[{"atl":[[940,2]],"id":50605162}],"con":true,"img":false}]}
{"op":"mcm","clk":"11449968533","pt":1717316522921,"mc":[{"id":"1.229554895","rc":[{"atl":[[970,0]],"id":50605162}],"con":true,"img":false}]}
{"op":"mcm","clk":"11449968544","pt":1717316523024,"mc":[{"id":"1.229554895","rc":[{"atl":[[930,2.61]],"id":50605162}],"con":true,"img":false}]}
{"op":"mcm","clk":"11449968690","pt":1717316525240,"mc":[{"id":"1.229554895","rc":[{"atl":[[4.5,7.25]],"id":65732558}],"con":true,"img":false}]}
{"op":"mcm","clk":"11449969284","pt":1717316534161,"mc":[{"id":"1.229554895","rc":[{"atb":[[1.37,27.7]],"id":63161712},{"atl":[[2.9,78.95]],"id":63161712},{"atb":[[1.9,11.57]],"id":65732558}],"con":true,"img":false}]}
{"op":"mcm","clk":"11449971195","pt":1717316563369,"mc":[{"id":"1.229554895","rc":[{"atl":[[520,2],[410,0]],"id":58069703},{"spn":41.75,"spf":"NaN","id":58069703},{"atl":[[940,0]],"id":50605162},{"spn":246.0,"spf":"NaN","id":50605162},{"atb":[[1.09,0]],"id":65732558},{"atb":[[4.1,16.13],[2.58,44.64]],"id":61028210},{"atl":[[75,0],[120,2]],"id":61028210}],"con":true,"img":false}]}
{"op":"mcm","clk":"11449971964","pt":1717316575310,"mc":[{"id":"1.229554895","rc":[{"atl":[[4.5,2.96]],"id":65732558}],"con":true,"img":false}]}
{"op":"mcm","clk":"11449971983","pt":1717316575513,"mc":[{"id":"1.229554895","rc":[{"atb":[[3.1,44.64]],"id":61028210}],"con":true,"img":false}]}
{"op":"mcm","clk":"11449971992","pt":1717316575614,"mc":[{"id":"1.229554895","rc":[{"atb":[[2.58,0]],"id":61028210}],"con":true,"img":false}]}
{"op":"mcm","clk":"11449972018","pt":1717316575871,"mc":[{"id":"1.229554895","rc":[{"atl":[[930,0]],"id":50605162},{"atl":[[70,0]],"id":61028210}],"con":true,"img":false}]}
{"op":"mcm","clk":"11449972025","pt":1717316575985,"mc":[{"id":"1.229554895","rc":[{"atl":[[980,2.61]],"id":50605162},{"atl":[[80,2.61]],"id":61028210}],"con":true,"img":false}]}
{"op":"mcm","clk":"11449972259","pt":1717316579589,"mc":[{"id":"1.229554895","rc":[{"atl":[[1.99,3]],"id":63161712}],"con":true,"img":false}]}
{"op":"mcm","clk":"11449972602","pt":1717316584733,"mc":[{"id":"1.229554895","rc":[{"atl":[[2.9,73.35]],"id":63161712}],"con":true,"img":false}]}
{"op":"mcm","clk":"11449972881","pt":1717316588410,"mc":[{"id":"1.229554895","rc":[{"atb":[[19.5,2]],"id":58069703},{"atb":[[1.02,147.28]],"id":65732558}],"con":true,"img":false}]}
{"op":"mcm","clk":"11449972888","pt":1717316588512,"mc":[{"id":"1.229554895","rc":[{"atb":[[19.5,0]],"id":58069703},{"atl":[[520,0],[420,2]],"id":58069703},{"atb":[[1.02,0]],"id":65732558},{"atb":[[3.1,0],[4.1,43.23]],"id":61028210},{"atl":[[90,2],[120,0]],"id":61028210}],"con":true,"img":false}]}
{"op":"mcm","clk":"11449973089","pt":1717316591146,"mc":[{"id":"1.229554895","rc":[{"atb":[[1.39,0]],"id":63161712},{"atl":[[670,2]],"id":50605162}],"con":true,"img":false}]}
{"op":"mcm","clk":"11449973094","pt":1717316591249,"mc":[{"id":"1.229554895","rc":[{"atb":[[1.34,327.5]],"id":63161712},{"atl":[[670,0],[850,0.07],[970,2]],"id":50605162}],"con":true,"img":false}]}
{"op":"mcm","clk":"11449973105","pt":1717316591309,"mc":[{"id":"1.229554895","rc":[{"atb":[[1.37,24.88]],"id":63161712},{"atl":[[850,2.07]],"id":50605162}],"con":true,"img":false}]}
{"op":"mcm","clk":"11449973116","pt":1717316591411,"mc":[{"id":"1.229554895","rc":[{"atl":[[2.78,5.76]],"id":63161712},{"atl":[[970,0]],"id":50605162}],"con":true,"img":false}]}
{"op":"mcm","clk":"11449973953","pt":1717316603020,"mc":[{"id":"1.229554895","rc":[{"atl":[[2.82,0]],"id":63161712},{"atb":[[10.5,0]],"id":61028210}],"con":true,"img":false}]}
{"op":"mcm","clk":"11449973960","pt":1717316603122,"mc":[{"id":"1.229554895","rc":[{"atl":[[2.66,35.62]],"id":63161712},{"atb":[[11,7.9]],"id":61028210}],"con":true,"img":false}]}
{"op":"mcm","clk":"11449973968","pt":1717316603223,"mc":[{"id":"1.229554895","rc":[{"atb":[[1.37,27.7]],"id":63161712}],"con":true,"img":false}]}
{"op":"mcm","clk":"11449974222","pt":1717316606950,"mc":[{"id":"1.229554895","rc":[{"atb":[[1.37,24.43]],"id":63161712}],"con":true,"img":false}]}
{"op":"mcm","clk":"11449974574","pt":1717316612228,"mc":[{"id":"1.229554895","rc":[{"atb":[[1.5,0]],"id":63161712}],"con":true,"img":false}]}
{"op":"mcm","clk":"11449974580","pt":1717316612333,"mc":[{"id":"1.229554895","rc":[{"atb":[[1.4,2.61]],"id":63161712}],"con":true,"img":false}]}
{"op":"mcm","clk":"11449974625","pt":1717316612954,"mc":[{"id":"1.229554895","rc":[{"atl":[[850,2]],"id":50605162}],"con":true,"img":false}]}
{"op":"mcm","clk":"11449974632","pt":1717316613057,"mc":[{"id":"1.229554895","rc":[{"atl":[[850,0],[840,0.07],[970,2]],"id":50605162}],"con":true,"img":false}]}
{"op":"mcm","clk":"11449974644","pt":1717316613163,"mc":[{"id":"1.229554895","rc":[{"atl":[[840,2.07]],"id":50605162}],"con":true,"img":false}]}
{"op":"mcm","clk":"11449974652","pt":1717316613262,"mc":[{"id":"1.229554895","rc":[{"atl":[[970,0]],"id":50605162}],"con":true,"img":false}]}
{"op":"mcm","clk":"11449974758","pt":1717316614862,"mc":[{"id":"1.229554895","rc":[{"atl":[[4.5,7.25]],"id":65732558}],"con":true,"img":false}]}
{"op":"mcm","clk":"11449974922","pt":1717316617343,"mc":[{"id":"1.229554895","rc":[{"atl":[[2.78,0]],"id":63161712}],"con":true,"img":false}]}
{"op":"mcm","clk":"11449975008","pt":1717316618639,"mc":[{"id":"1.229554895","rc":[{"atb":[[32,0]],"id":50605162},{"atl":[[940,2]],"id":50605162},{"atb":[[1.14,147.28]],"id":65732558},{"atl":[[75,2],[90,0]],"id":61028210}],"con":true,"img":false}]}
{"op":"mcm","clk":"11449975017","pt":1717316618743,"mc":[{"id":"1.229554895","rc":[{"atb":[[36,3.11]],"id":50605162}],"con":true,"img":false}]}
{"op":"mcm","clk":"11449975092","pt":1717316619941,"mc":[{"id":"1.229554895","rc":[{"atb":[[1.43,0],[1.33,0],[1.38,0]],"id":63161712},{"atl":[[2.9,0],[3.25,0]],"id":63161712},{"atb":[[17,0],[12,0],[14.5,0]],"id":58069703},{"atl":[[350,0],[250,0]],"id":58069703},{"atb":[[38,0],[24,0],[29,0]],"id":50605162},{"atl":[[550,0],[450,0]],"id":50605162},{"atb":[[2.02,0],[2.12,0],[1.96,0]],"id":65732558},{"atl":[[6.8,0],[8.8,0]],"id":65732558},{"atb":[[7.4,0],[8.4,0],[9.4,0]],"id":61028210},{"atl":[[140,0],[240,0]],"id":61028210}],"con":true,"img":false}]}
{"op":"mcm","clk":"11449975099","pt":1717316620045,"mc":[{"id":"1.229554895","rc":[{"atl":[[840,0.07],[980,4.61]],"id":50605162}],"con":true,"img":false}]}
{"op":"mcm","clk":"11449975118","pt":1717316620256,"mc":[{"id":"1.229554895","rc":[{"atl":[[980,2.61],[990,2.17]],"id":50605162}],"con":true,"img":false}]}
{"op":"mcm","clk":"11449975150","pt":1717316620667,"mc":[{"id":"1.229554895","rc":[{"atb":[[1.35,22.42]],"id":63161712}],"con":true,"img":false}]}
{"op":"mcm","clk":"11449975320","pt":1717316622948,"mc":[{"id":"1.229554895","rc":[{"atl":[[3.25,56.5]],"id":63161712}],"con":true,"img":false}]}
{"op":"mcm","clk":"11449975325","pt":1717316623052,"mc":[{"id":"1.229554895","rc":[{"atb":[[1.44,0]],"id":63161712},{"atl":[[2.88,0]],"id":63161712},{"atb":[[2.04,0]],"id":65732558}],"con":true,"img":false}]}
{"op":"mcm","clk":"11449975336","pt":1717316623157,"mc":[{"id":"1.229554895","rc":[{"atb":[[1.38,75.17]],"id":63161712},{"atb":[[1.96,53.94]],"id":65732558}],"con":true,"img":false}]}
{"op":"mcm","clk":"11449975392","pt":1717316623787,"mc":[{"id":"1.229554895","rc":[{"spn":1.69,"spf":"NaN","id":63161712},{"atl":[[940,0],[980,4.61]],"id":50605162},{"spn":441.0,"spf":"NaN","id":50605162}],"con":true,"img":false}]}
{"op":"mcm","clk":"11449976055","pt":1717316632987,"mc":[{"id":"1.229554895","rc":[{"atl":[[840,0]],"id":50605162}],"con":true,"img":false}]}
{"op":"mcm","clk":"11449976065","pt":1717316633089,"mc":[{"id":"1.229554895","rc":[{"atl":[[920,0.07]],"id":50605162}],"con":true,"img":false}]}
{"op":"mcm","clk":"11449976268","pt":1717316635992,"mc":[{"id":"1.229554895","rc":[{"atl":[[60,2.17]],"id":61028210}],"con":true,"img":false}]}
{"op":"mcm","clk":"11449976277","pt":1717316636096,"mc":[{"id":"1.229554895","rc":[{"atl":[[70,2.61],[80,4.61],[60,0.17]],"id":61028210}],"con":true,"img":false}]}
{"op":"mcm","clk":"11449976284","pt":1717316636200,"mc":[{"id":"1.229554895","rc":[{"atl":[[80,6.61],[990,2]],"id":61028210}],"con":true,"img":false}]}
{"op":"mcm","clk":"11449976294","pt":1717316636310,"mc":[{"id":"1.229554895","rc":[{"atl":[[70,4.61],[75,0],[80,4.61],[990,0]],"id":61028210}],"con":true,"img":false}]}
{"op":"mcm","clk":"11449976301","pt":1717316636361,"mc":[{"id":"1.229554895","rc":[{"atl":[[70,2.61],[75,2],[80,2.61]],"id":61028210}],"con":true,"img":false}]}
{"op":"mcm","clk":"11449976304","pt":1717316636460,"mc":[{"id":"1.229554895","rc":[{"atl":[[70,4.61]],"id":61028210}],"con":true,"img":false}]}
{"op":"mcm","clk":"11449976765","pt":1717316643022,"mc":[{"id":"1.229554895","rc":[{"atl":[[920,0],[980,2]],"id":50605162}],"con":true,"img":false}]}
{"op":"mcm","clk":"11449976772","pt":1717316643072,"mc":[{"id":"1.229554895","rc":[{"atb":[[1.37,0]],"id":63161712},{"atl":[[980,0],[970,0.07],[1000,3]],"id":50605162}],"con":true,"img":false}]}
{"op":"mcm","clk":"11449976782","pt":1717316643178,"mc":[{"id":"1.229554895","rc":[{"atl":[[990,0.17],[1000,5]],"id":50605162}],"con":true,"img":false}]}
{"op":"mcm","clk":"11449976997","pt":1717316645898,"mc":[{"id":"1.229554895","rc":[{"atl":[[2.78,5.6]],"id":63161712}],"con":true,"img":false}]}
{"op":"mcm","clk":"11449977005","pt":1717316646006,"mc":[{"id":"1.229554895","rc":[{"atl":[[60,0],[1000,2.03]],"id":61028210}],"con":true,"img":false}]}
{"op":"mcm","clk":"11449977013","pt":1717316646108,"mc":[{"id":"1.229554895","rc":[{"atb":[[1.28,746.64],[1.23,908.96],[1.33,316.75]],"id":63161712},{"atl":[[2.8,77.43],[3,104.53]],"id":63161712},{"atb":[[17,6.53],[12,19],[14.5,15.48]],"id":58069703},{"atl":[[350,0.59],[250,0.55]],"id":58069703},{"atb":[[38,2.82],[24,9.08],[29,7.46]],"id":50605162},{"atl":[[550,0.38],[450,0.3]],"id":50605162},{"atb":[[2.02,204.95],[2.12,93.32],[1.96,271.72]],"id":65732558},{"atl":[[6.8,24.02],[8.8,26.8]],"id":65732558},{"atb":[[7.4,32.66],[8.4,28.25],[9.4,12.44]],"id":61028210},{"atl":[[140,1],[240,0.87]],"id":61028210}],"con":true,"img":false}]}
{"op":"mcm","clk":"11449977026","pt":1717316646214,"mc":[{"id":"1.229554895","rc":[{"atl":[[970,2.07],[1000,3]],"id":50605162}],"con":true,"img":false}]}
{"op":"mcm","clk":"11449977087","pt":1717316646839,"mc":[{"id":"1.229554895","rc":[{"atl":[[1000,1.34]],"id":61028210}],"con":true,"img":false}]}
{"op":"mcm","clk":"11449977153","pt":1717316647613,"mc":[{"id":"1.229554895","rc":[{"atb":[[19.5,2]],"id":58069703},{"atl":[[520,2],[420,0]],"id":58069703},{"atl":[[1000,1]],"id":50605162},{"atb":[[1.14,0]],"id":65732558},{"atb":[[4.1,16.13],[2.58,48.78]],"id":61028210},{"atl":[[75,0],[80,4.61]],"id":61028210}],"con":true,"img":false}]}
{"op":"mcm","clk":"11449977161","pt":1717316647716,"mc":[{"id":"1.229554895","rc":[{"atb":[[19.5,0]],"id":58069703}],"con":true,"img":false}]}
{"op":"mcm","clk":"11449977175","pt":1717316647926,"mc":[{"id":"1.229554895","rc":[{"atb":[[2.58,0]],"id":61028210}],"con":true,"img":false}]}
{"op":"mcm","clk":"11449977186","pt":1717316647979,"mc":[{"id":"1.229554895","rc":[{"atb":[[3.1,44.64]],"id":61028210}],"con":true,"img":false}]}
{"op":"mcm","clk":"11449977209","pt":1717316648288,"mc":[{"id":"1.229554895","rc":[{"atl":[[1000,1.17]],"id":61028210}],"con":true,"img":false}]}
{"op":"mcm","clk":"11449977217","pt":1717316648390,"mc":[{"id":"1.229554895","rc":[{"atl":[[65,0.17]],"id":61028210}],"con":true,"img":false}]}
{"op":"mcm","clk":"11449977287","pt":1717316649320,"mc":[{"id":"1.229554895","rc":[{"atb":[[19.5,2]],"id":58069703},{"atb":[[1.02,186.66]],"id":65732558}],"con":true,"img":false}]}
{"op":"mcm","clk":"11449977293","pt":1717316649424,"mc":[{"id":"1.229554895","rc":[{"atb":[[19.5,0]],"id":58069703},{"atb":[[1.02,0]],"id":65732558}],"con":true,"img":false}]}
{"op":"mcm","clk":"11449977555","pt":1717316652695,"mc":[{"id":"1.229554895","rc":[{"atl":[[80,2.61],[90,2]],"id":61028210}],"con":true,"img":false}]}
{"op":"mcm","clk":"11449977588","pt":1717316653107,"mc":[{"id":"1.229554895","rc":[{"atl":[[2.78,0]],"id":63161712}],"con":true,"img":false}]}
{"op":"mcm","clk":"11449977682","pt":1717316654296,"mc":[{"id":"1.229554895","rc":[{"atl":[[520,0],[580,2]],"id":58069703},{"atb":[[3.1,0],[1.04,52.64]],"id":61028210},{"atl":[[140,3],[90,0]],"id":61028210}],"con":true,"img":false}]}
{"op":"mcm","clk":"11449978065","pt":1717316659028,"mc":[{"id":"1.229554895","rc":[{"atb":[[42,0]],"id":50605162},{"atb":[[11,2]],"id":61028210}],"con":true,"img":false}]}
{"op":"mcm","clk":"11449978074","pt":1717316659131,"mc":[{"id":"1.229554895","rc":[{"atb":[[50,2.61]],"id":50605162},{"atb":[[12,5.9]],"id":61028210}],"con":true,"img":false}]}
{"op":"mcm","clk":"11449978089","pt":1717316659233,"mc":[{"id":"1.229554895","rc":[{"atb":[[11,0],[12,7.9]],"id":61028210}],"con":true,"img":false}]}
{"op":"mcm","clk":"11449978205","pt":1717316660729,"mc":[{"id":"1.229554895","rc":[{"atb":[[1.35,50.12]],"id":63161712}],"con":true,"img":false}]}
{"op":"mcm","clk":"11449979145","pt":1717316673048,"mc":[{"id":"1.229554895","rc":[{"atl":[[970,2]],"id":50605162},{"atl":[[70,2]],"id":61028210}],"con":true,"img":false}]}
{"op":"mcm","clk":"11449979153","pt":1717316673107,"mc":[{"id":"1.229554895","rc":[{"atl":[[970,0],[990,2.17],[960,0.07]],"id":50605162},{"atl":[[65,2.78],[80,4.61]],"id":61028210}],"con":true,"img":false}]}
{"op":"mcm","clk":"11449979159","pt":1717316673213,"mc":[{"id":"1.229554895","rc":[{"atl":[[70,0]],"id":61028210}],"con":true,"img":false}]}
{"op":"mcm","clk":"11449979222","pt":1717316674136,"mc":[{"id":"1.229554895","rc":[{"atb":[[1.9,0]],"id":65732558}],"con":true,"img":false}]}
{"op":"mcm","clk":"11449979485","pt":1717316678237,"mc":[{"id":"1.229554895","rc":[{"atl":[[960,2.07]],"id":50605162},{"atl":[[65,4.78],[80,2.61]],"id":61028210}],"con":true,"img":false}]}
{"op":"mcm","clk":"11449979493","pt":1717316678339,"mc":[{"id":"1.229554895","rc":[{"atl":[[990,0.17]],"id":50605162},{"atl":[[80,4.61]],"id":61028210}],"con":true,"img":false}]}
{"op":"mcm","clk":"11449979503","pt":1717316678452,"mc":[{"id":"1.229554895","rc":[{"atb":[[36,0]],"id":50605162},{"atb":[[9.6,0]],"id":61028210},{"atl":[[65,2.78]],"id":61028210}],"con":true,"img":false}]}
{"op":"mcm","clk":"11449979512","pt":1717316678542,"mc":[{"id":"1.229554895","rc":[{"atb":[[22,2]],"id":58069703},{"atl":[[580,0],[500,2]],"id":58069703},{"atb":[[40,3.11]],"id":50605162},{"atb":[[10,14.64],[4.1,45.43],[1.04,0]],"id":61028210},{"atl":[[65,4.78],[140,1],[80,2.61],[100,2]],"id":61028210}],"con":true,"img":false}]}
{"op":"mcm","clk":"11449979519","pt":1717316678643,"mc":[{"id":"1.229554895","rc":[{"atb":[[22,0]],"id":58069703},{"atl":[[65,2.78],[80,4.61]],"id":61028210}],"con":true,"img":false}]}
{"op":"mcm","clk":"11449979526","pt":1717316678747,"mc":[{"id":"1.229554895","rc":[{"atl":[[65,4.78],[80,2.61]],"id":61028210}],"con":true,"img":false}]}
{"op":"mcm","clk":"11449979571","pt":1717316679426,"mc":[{"id":"1.229554895","rc":[{"atb":[[1.96,217.77]],"id":65732558}],"con":true,"img":false}]}
{"op":"mcm","clk":"11449979579","pt":1717316679529,"mc":[{"id":"1.229554895","rc":[{"atb":[[2.04,53.94]],"id":65732558}],"con":true,"img":false}]}
{"op":"mcm","clk":"11449979681","pt":1717316681028,"mc":[{"id":"1.229554895","rc":[{"atl":[[80,0]],"id":61028210}],"con":true,"img":false}]}
{"op":"mcm","clk":"11449979688","pt":1717316681132,"mc":[{"id":"1.229554895","rc":[{"atl":[[95,2.61]],"id":61028210}],"con":true,"img":false}]}
{"op":"mcm","clk":"11449979720","pt":1717316681646,"mc":[{"id":"1.229554895","rc":[{"atb":[[1.9,11.57]],"id":65732558}],"con":true,"img":false}]}
{"op":"mcm","clk":"11449979817","pt":1717316683046,"mc":[{"id":"1.229554895","rc":[{"atl":[[65,2.17]],"id":61028210}],"con":true,"img":false}]}
{"op":"mcm","clk":"11449979825","pt":1717316683151,"mc":[{"id":"1.229554895","rc":[{"atl":[[75,2.61]],"id":61028210}],"con":true,"img":false}]}
{"op":"mcm","clk":"11449979839","pt":1717316683353,"mc":[{"id":"1.229554895","rc":[{"atl":[[65,0.17],[75,4.61]],"id":61028210}],"con":true,"img":false}]}
{"op":"mcm","clk":"11449979846","pt":1717316683451,"mc":[{"id":"1.229554895","rc":[{"atl":[[75,2.61],[90,2]],"id":61028210}],"con":true,"img":false}]}
{"op":"mcm","clk":"11449980219","pt":1717316688600,"mc":[{"id":"1.229554895","rc":[{"spn":250.0,"spf":"NaN","id":50605162},{"atl":[[75,4.61],[90,0]],"id":61028210},{"spn":38.5,"spf":"NaN","id":61028210}],"con":true,"img":false}]}
{"op":"mcm","clk":"11449980223","pt":1717316688652,"mc":[{"id":"1.229554895","rc":[{"atl":[[90,2]],"id":61028210}],"con":true,"img":false}]}
{"op":"mcm","clk":"11449980231","pt":1717316688758,"mc":[{"id":"1.229554895","rc":[{"atl":[[75,2.61]],"id":61028210}],"con":true,"img":false}]}
{"op":"mcm","clk":"11449980702","pt":1717316695934,"mc":[{"id":"1.229554895","rc":[{"atl":[[3.25,0],[2.78,71.67]],"id":63161712},{"atl":[[200,0]],"id":58069703}],"con":true,"img":false}]}
{"op":"mcm","clk":"11449980708","pt":1717316696034,"mc":[{"id":"1.229554895","rc":[{"atl":[[240,2.61]],"id":58069703}],"con":true,"img":false}]}
{"op":"mcm","clk":"11449980810","pt":1717316697673,"mc":[{"id":"1.229554895","rc":[{"atl":[[2.72,5.6]],"id":63161712}],"con":true,"img":false}]}
{"op":"mcm","clk":"11449981170","pt":1717316702951,"mc":[{"id":"1.229554895","rc":[{"atl":[[150,0]],"id":58069703},{"atl":[[960,2]],"id":50605162},{"atb":[[12,2]],"id":61028210}],"con":true,"img":false}]}
{"op":"mcm","clk":"11449981181","pt":1717316703053,"mc":[{"id":"1.229554895","rc":[{"atl":[[170,0.35]],"id":58069703},{"atl":[[950,0.07],[960,0],[990,2.17]],"id":50605162},{"atb":[[12,0],[12.5,5.9],[13,2]],"id":61028210},{"atl":[[75,4.61],[90,0]],"id":61028210}],"con":true,"img":false}]}
{"op":"mcm","clk":"11449981376","pt":1717316705441,"mc":[{"id":"1.229554895","rc":[{"atl":[[65,0]],"id":61028210}],"con":true,"img":false}]}
{"op":"mcm","clk":"11449981552","pt":1717316708185,"mc":[{"id":"1.229554895","rc":[{"atl":[[950,2.07]],"id":50605162}],"con":true,"img":false}]}
{"op":"mcm","clk":"11449981560","pt":1717316708281,"mc":[{"id":"1.229554895","rc":[{"atl":[[990,0.17]],"id":50605162}],"con":true,"img":false}]}
{"op":"mcm","clk":"11449981568","pt":1717316708381,"mc":[{"id":"1.229554895","rc":[{"atl":[[950,0.07]],"id":50605162}],"con":true,"img":false}]}
{"op":"mcm","clk":"11449981573","pt":1717316708489,"mc":[{"id":"1.229554895","rc":[{"atl":[[950,2.07]],"id":50605162}],"con":true,"img":false}]}
{"op":"mcm","clk":"11449981591","pt":1717316708652,"mc":[{"id":"1.229554895","rc":[{"atb":[[1.28,0],[1.23,0],[1.33,0]],"id":63161712},{"atl":[[2.8,0],[3,0]],"id":63161712},{"atb":[[17,0],[12,0],[14.5,0]],"id":58069703},{"atl":[[350,0],[250,0]],"id":58069703},{"atb":[[38,0],[24,0],[29,0]],"id":50605162},{"atl":[[550,0],[450,0]],"id":50605162},{"atb":[[2.02,0],[2.12,0],[1.96,0]],"id":65732558},{"atl":[[6.8,0],[8.8,0]],"id":65732558},{"atb":[[7.4,0],[8.4,0],[9.4,0]],"id":61028210},{"atl":[[140,0],[240,0]],"id":61028210}],"con":true,"img":false}]}
{"op":"mcm","clk":"11449981813","pt":1717316711870,"mc":[{"id":"1.229554895","rc":[{"atb":[[1.38,0]],"id":63161712},{"atl":[[75,2]],"id":61028210}],"con":true,"img":false}]}
{"op":"mcm","clk":"11449981819","pt":1717316711974,"mc":[{"id":"1.229554895","rc":[{"atb":[[1.36,75.17]],"id":63161712},{"atl":[[75,0],[80,2.61],[95,4.61]],"id":61028210}],"con":true,"img":false}]}
{"op":"mcm","clk":"11449981829","pt":1717316712072,"mc":[{"id":"1.229554895","rc":[{"atl":[[1000,3.17]],"id":61028210}],"con":true,"img":false}]}
{"op":"mcm","clk":"11449981837","pt":1717316712181,"mc":[{"id":"1.229554895","rc":[{"atl":[[80,4.61],[95,2.61],[1000,1.17]],"id":61028210}],"con":true,"img":false}]}
{"op":"mcm","clk":"11449981912","pt":1717316712993,"mc":[{"id":"1.229554895","rc":[{"atb":[[1.34,0]],"id":63161712},{"atl":[[2.66,2.61],[3.15,59.11],[2.78,0]],"id":63161712},{"atb":[[2.04,0]],"id":65732558}],"con":true,"img":false}]}
{"op":"mcm","clk":"11449981920","pt":1717316713052,"mc":[{"id":"1.229554895","rc":[{"atb":[[1.33,327.5]],"id":63161712},{"atl":[[2.58,33]],"id":63161712},{"atb":[[1.96,53.94]],"id":65732558}],"con":true,"img":false}]}
{"op":"mcm","clk":"11449981931","pt":1717316713156,"mc":[{"id":"1.229554895","rc":[{"atb":[[1.35,22.42]],"id":63161712}],"con":true,"img":false}]}
{"op":"mcm","clk":"11449981965","pt":1717316713566,"mc":[{"id":"1.229554895","rc":[{"atl":[[950,0.07],[990,2.17]],"id":50605162}],"con":true,"img":false}]}
{"op":"mcm","clk":"11449981972","pt":1717316713668,"mc":[{"id":"1.229554895","rc":[{"atl":[[990,0.17],[1000,3]],"id":50605162}],"con":true,"img":false}]}
{"op":"mcm","clk":"11449982017","pt":1717316714387,"mc":[{"id":"1.229554895","rc":[{"atb":[[1.33,355.2]],"id":63161712}],"con":true,"img":false}]}
{"op":"mcm","clk":"11449982205","pt":1717316716974,"mc":[{"id":"1.229554895","rc":[{"atb":[[1.33,327.5]],"id":63161712}],"con":true,"img":false}]}
{"op":"mcm","clk":"11449982469","pt":1717316720656,"mc":[{"id":"1.229554895","rc":[{"atb":[[2.16,0]],"id":65732558},{"atl":[[4.5,4.28]],"id":65732558}],"con":true,"img":false}]}
{"op":"mcm","clk":"11449982528","pt":1717316721588,"mc":[{"id":"1.229554895","rc":[{"atb":[[1.28,746.64],[1.23,908.96],[1.33,644.26]],"id":63161712},{"atl":[[2.8,77.43],[3,104.53]],"id":63161712},{"atb":[[18,6.14],[13,17.42],[15.5,14.41]],"id":58069703},{"atl":[[260,0.53],[360,0.58]],"id":58069703},{"atb":[[34,6.33],[44,2.43],[27,8.04]],"id":50605162},{"atl":[[580,0.36],[480,0.29]],"id":50605162},{"atb":[[2.02,204.95],[2.12,93.32],[1.96,271.72]],"id":65732558},{"atl":[[6.8,24.02],[8.8,26.8]],"id":65732558},{"atb":[[9.2,25.49],[10.5,11],[8.2,29.03]],"id":61028210},{"atl":[[280,0.74],[180,0.77]],"id":61028210}],"con":true,"img":false}]}
{"op":"mcm","clk":"11449982546","pt":1717316721801,"mc":[{"id":"1.229554895","rc":[{"atl":[[950,2.07],[1000,1]],"id":50605162}],"con":true,"img":false}]}
{"op":"mcm","clk":"11449982595","pt":1717316722568,"mc":[{"id":"1.229554895","rc":[{"atl":[[2.44,7.9]],"id":63161712}],"con":true,"img":false}]}
{"op":"mcm","clk":"11449982619","pt":1717316722982,"mc":[{"id":"1.229554895","rc":[{"atb":[[10,0],[11,12.03]],"id":61028210}],"con":true,"img":false}]}
{"op":"mcm","clk":"11449982629","pt":1717316723087,"mc":[{"id":"1.229554895","rc":[{"atl":[[2.72,0]],"id":63161712}],"con":true,"img":false}]}
{"op":"mcm","clk":"11449982722","pt":1717316724579,"mc":[{"id":"1.229554895","rc":[{"atb":[[12.5,0]],"id":61028210}],"con":true,"img":false}]}
{"op":"mcm","clk":"11449982728","pt":1717316724686,"mc":[{"id":"1.229554895","rc":[{"atb":[[13,7.9]],"id":61028210}],"con":true,"img":false}]}
{"op":"mcm","clk":"11449983304","pt":1717316733094,"mc":[{"id":"1.229554895","rc":[{"atl":[[950,2]],"id":50605162}],"con":true,"img":false}]}
{"op":"mcm","clk":"11449983310","pt":1717316733202,"mc":[{"id":"1.229554895","rc":[{"atl":[[940,0.07],[990,2.17]],"id":50605162}],"con":true,"img":false}]}
{"op":"mcm","clk":"11449983321","pt":1717316733350,"mc":[{"id":"1.229554895","rc":[{"atl":[[950,0]],"id":50605162}],"con":true,"img":false}]}
{"op":"mcm","clk":"11449983648","pt":1717316738317,"mc":[{"id":"1.229554895","rc":[{"atl":[[940,2.07],[990,0.17]],"id":50605162}],"con":true,"img":false}]}
{"op":"mcm","clk":"11449983655","pt":1717316738426,"mc":[{"id":"1.229554895","rc":[{"atl":[[940,0.07]],"id":50605162}],"con":true,"img":false}]}
{"op":"mcm","clk":"11449983660","pt":1717316738486,"mc":[{"id":"1.229554895","rc":[{"atl":[[940,2.07]],"id":50605162}],"con":true,"img":false}]}
{"op":"mcm","clk":"11449984184","pt":1717316746107,"mc":[{"id":"1.229554895","rc":[{"atb":[[1.9,0]],"id":65732558}],"con":true,"img":false}]}
{"op":"mcm","clk":"11449984240","pt":1717316746827,"mc":[{"id":"1.229554895","rc":[{"atl":[[2.66,8.21]],"id":63161712}],"con":true,"img":false}]}
{"op":"mcm","clk":"11449984669","pt":1717316753022,"mc":[{"id":"1.229554895","rc":[{"atb":[[1.33,316.75]],"id":63161712},{"spn":265.0,"spf":"NaN","id":50605162},{"atb":[[1.96,217.77]],"id":65732558},{"atl":[[80,2]],"id":61028210},{"spn":46.5,"spf":"NaN","id":61028210}],"con":true,"img":false}]}
{"op":"mcm","clk":"11449984677","pt":1717316753131,"mc":[{"id":"1.229554895","rc":[{"atb":[[1.34,327.5]],"id":63161712},{"atb":[[2.04,53.94]],"id":65732558},{"atl":[[75,2.61],[95,4.61]],"id":61028210}],"con":true,"img":false}]}
{"op":"mcm","clk":"11449984685","pt":1717316753231,"mc":[{"id":"1.229554895","rc":[{"atl":[[80,0],[95,2.61]],"id":61028210}],"con":true,"img":false}]}
{"op":"mcm","clk":"11449984693","pt":1717316753335,"mc":[{"id":"1.229554895","rc":[{"atl":[[75,4.61]],"id":61028210}],"con":true,"img":false}]}
{"op":"mcm","clk":"11449984762","pt":1717316754321,"mc":[{"id":"1.229554895","rc":[{"atb":[[1.9,11.57]],"id":65732558}],"con":true,"img":false}]}
{"op":"mcm","clk":"11449985271","pt":1717316761629,"mc":[{"id":"1.229554895","rc":[{"atb":[[1.33,332.55]],"id":63161712}],"con":true,"img":false}]}
{"op":"mcm","clk":"11449985374","pt":1717316762929,"mc":[{"id":"1.229554895","rc":[{"atl":[[2.78,71.67]],"id":63161712},{"atb":[[18.5,9.54]],"id":58069703}],"con":true,"img":false}]}
{"op":"mcm","clk":"11449985384","pt":1717316763031,"mc":[{"id":"1.229554895","rc":[{"atl":[[3.15,0]],"id":63161712},{"atb":[[15,0]],"id":58069703},{"atl":[[940,2]],"id":50605162},{"atl":[[75,2]],"id":61028210}],"con":true,"img":false}]}
{"op":"mcm","clk":"11449985394","pt":1717316763143,"mc":[{"id":"1.229554895","rc":[{"atl":[[940,0],[930,0.07],[990,2.17]],"id":50605162},{"atl":[[75,0],[80,2.61],[95,4.61]],"id":61028210}],"con":true,"img":false}]}
{"op":"mcm","clk":"11449985403","pt":1717316763239,"mc":[{"id":"1.229554895","rc":[{"atl":[[930,2.07],[990,0.17]],"id":50605162},{"atl":[[280,2.74],[95,2.61]],"id":61028210}],"con":true,"img":false}]}
{"op":"mcm","clk":"11449985418","pt":1717316763351,"mc":[{"id":"1.229554895","rc":[{"atl":[[80,4.61]],"id":61028210}],"con":true,"img":false}]}
{"op":"mcm","clk":"11449985424","pt":1717316763444,"mc":[{"id":"1.229554895","rc":[{"atl":[[280,0.74]],"id":61028210}],"con":true,"img":false}]}
{"op":"mcm","clk":"11449985490","pt":1717316764017,"mc":[{"id":"1.229554895","rc":[{"atb":[[1.9,0]],"id":65732558}],"con":true,"img":false}]}
{"op":"mcm","clk":"11449986115","pt":1717316771758,"mc":[{"id":"1.229554895","rc":[{"atb":[[1.27,1.7]],"id":58069703},{"atb":[[1.04,1.7]],"id":65732558}],"con":true,"img":false}]}
{"op":"mcm","clk":"11449986134","pt":1717316772061,"mc":[{"id":"1.229554895","rc":[{"atb":[[1.8,1.7]],"id":50605162}],"con":true,"img":false}]}
{"op":"mcm","clk":"11449986144","pt":1717316772126,"mc":[{"id":"1.229554895","rc":[{"atb":[[1.2,1.7]],"id":61028210}],"con":true,"img":false}]}
{"op":"mcm","clk":"11449986163","pt":1717316772334,"mc":[{"id":"1.229554895","rc":[{"atb":[[1.03,7.66]],"id":63161712},{"atb":[[1.04,0.18]],"id":65732558}],"con":true,"img":false}]}
{"op":"mcm","clk":"11449986194","pt":1717316772743,"mc":[{"id":"1.229554895","rc":[{"atb":[[1.27,0.02]],"id":58069703}],"con":true,"img":false}]}
{"op":"mcm","clk":"11449986204","pt":1717316772843,"mc":[{"id":"1.229554895","rc":[{"atb":[[1.04,0]],"id":65732558}],"con":true,"img":false}]}
{"op":"mcm","clk":"11449986210","pt":1717316772946,"mc":[{"id":"1.229554895","rc":[{"atb":[[2.26,0.18]],"id":65732558}],"con":true,"img":false}]}
{"op":"mcm","clk":"11449986219","pt":1717316773049,"mc":[{"id":"1.229554895","rc":[{"atb":[[1.8,0]],"id":50605162}],"con":true,"img":false}]}
{"op":"mcm","clk":"11449986241","pt":1717316773363,"mc":[{"id":"1.229554895","rc":[{"atb":[[1.2,0.03]],"id":61028210}],"con":true,"img":false}]}
{"op":"mcm","clk":"11449986264","pt":1717316773620,"mc":[{"id":"1.229554895","rc":[{"atb":[[1.03,6.26]],"id":63161712}],"con":true,"img":false}]}
{"op":"mcm","clk":"11449986292","pt":1717316773928,"mc":[{"id":"1.229554895","rc":[{"atb":[[1.27,0]],"id":58069703}],"con":true,"img":false}]}
{"op":"mcm","clk":"11449986305","pt":1717316774031,"mc":[{"id":"1.229554895","rc":[{"atb":[[19,0.02]],"id":58069703}],"con":true,"img":false}]}
{"op":"mcm","clk":"11449986327","pt":1717316774340,"mc":[{"id":"1.229554895","rc":[{"atb":[[1.8,0]],"id":50605162}],"con":true,"img":false}]}
{"op":"mcm","clk":"11449986335","pt":1717316774445,"mc":[{"id":"1.229554895","rc":[{"atb":[[55,0]],"id":50605162}],"con":true,"img":false}]}
{"op":"mcm","clk":"11449986364","pt":1717316774855,"mc":[{"id":"1.229554895","rc":[{"atb":[[1.2,0]],"id":61028210}],"con":true,"img":false}]}
{"op":"mcm","clk":"11449986376","pt":1717316774957,"mc":[{"id":"1.229554895","rc":[{"atb":[[13.5,0.03]],"id":61028210}],"con":true,"img":false}]}
{"op":"mcm","clk":"11449986400","pt":1717316775366,"mc":[{"id":"1.229554895","rc":[{"atb":[[1.03,5.96]],"id":63161712}],"con":true,"img":false}]}
{"op":"mcm","clk":"11449986408","pt":1717316775425,"mc":[{"id":"1.229554895","rc":[{"atb":[[1.41,0.29]],"id":63161712}],"con":true,"img":false}]}
{"op":"mcm","clk":"11449986447","pt":1717316776040,"mc":[{"id":"1.229554895","rc":[{"atb":[[1.16,1.7]],"id":58069703}],"con":true,"img":false}]}
{"op":"mcm","clk":"11449986457","pt":1717316776144,"mc":[{"id":"1.229554895","rc":[{"atb":[[1.02,1.7]],"id":65732558}],"con":true,"img":false}]}
{"op":"mcm","clk":"11449986472","pt":1717316776355,"mc":[{"id":"1.229554895","rc":[{"atb":[[1.12,1.7]],"id":61028210}],"con":true,"img":false}]}
{"op":"mcm","clk":"11449986478","pt":1717316776457,"mc":[{"id":"1.229554895","rc":[{"atb":[[1.03,7.66]],"id":63161712}],"con":true,"img":false}]}
{"op":"mcm","clk":"11449986489","pt":1717316776666,"mc":[{"id":"1.229554895","rc":[{"atl":[[1000,23.63]],"id":58069703}],"con":true,"img":false}]}
{"op":"mcm","clk":"11449986501","pt":1717316776867,"mc":[{"id":"1.229554895","rc":[{"atb":[[1.4,1.7]],"id":50605162},{"atl":[[1000,2.88]],"id":61028210}],"con":true,"img":false}]}
{"op":"mcm","clk":"11449986508","pt":1717316777023,"mc":[{"id":"1.229554895","rc":[{"atl":[[1000,2.7]],"id":63161712}],"con":true,"img":false}]}
{"op":"mcm","clk":"11449986551","pt":1717316777746,"mc":[{"id":"1.229554895","rc":[{"atl":[[1000,2.7]],"id":65732558}],"con":true,"img":false}]}
{"op":"mcm","clk":"11449986700","pt":1717316779767,"mc":[{"id":"1.229554895","rc":[{"atb":[[1.03,6.57]],"id":63161712}],"con":true,"img":false}]}
{"op":"mcm","clk":"11449986745","pt":1717316780336,"mc":[{"id":"1.229554895","rc":[{"atb":[[1.4,0.01]],"id":50605162}],"con":true,"img":false}]}
{"op":"mcm","clk":"11449986766","pt":1717316780641,"mc":[{"id":"1.229554895","rc":[{"atl":[[1000,1.18]],"id":61028210}],"con":true,"img":false}]}
{"op":"mcm","clk":"11449986781","pt":1717316780856,"mc":[{"id":"1.229554895","rc":[{"atb":[[1.12,0.05]],"id":61028210}],"con":true,"img":false}]}
{"op":"mcm","clk":"11449986822","pt":1717316781470,"mc":[{"id":"1.229554895","rc":[{"atb":[[1.35,0]],"id":63161712}],"con":true,"img":false}]}
{"op":"mcm","clk":"11449986857","pt":1717316781947,"mc":[{"id":"1.229554895","rc":[{"atb":[[1.02,0.37]],"id":65732558}],"con":true,"img":false}]}
{"op":"mcm","clk":"11449986862","pt":1717316782050,"mc":[{"id":"1.229554895","rc":[{"atb":[[1.16,0.04]],"id":58069703}],"con":true,"img":false}]}
{"op":"mcm","clk":"11449986903","pt":1717316782564,"mc":[{"id":"1.229554895","rc":[{"atl":[[1000,1.43]],"id":63161712}],"con":true,"img":false}]}
{"op":"mcm","clk":"11449986943","pt":1717316782983,"mc":[{"id":"1.229554895","rc":[{"atl":[[930,2]],"id":50605162}],"con":true,"img":false}]}
{"op":"mcm","clk":"11449986951","pt":1717316783085,"mc":[{"id":"1.229554895","rc":[{"atl":[[920,0.07],[990,2.17]],"id":50605162},{"atl":[[1000,1.19]],"id":65732558}],"con":true,"img":false}]}
{"op":"mcm","clk":"11449986961","pt":1717316783144,"mc":[{"id":"1.229554895","rc":[{"atl":[[1000,3.13]],"id":63161712},{"atl":[[930,0]],"id":50605162}],"con":true,"img":false}]}
{"op":"mcm","clk":"11449986995","pt":1717316783566,"mc":[{"id":"1.229554895","rc":[{"atl":[[1000,21.94]],"id":58069703}],"con":true,"img":false}]}
{"op":"mcm","clk":"11449987004","pt":1717316783664,"mc":[{"id":"1.229554895","rc":[{"atb":[[1.03,5.96]],"id":63161712}],"con":true,"img":false}]}
{"op":"mcm","clk":"11449987010","pt":1717316783767,"mc":[{"id":"1.229554895","rc":[{"atb":[[1.41,0.9]],"id":63161712}],"con":true,"img":false}]}
{"op":"mcm","clk":"11449987112","pt":1717316785071,"mc":[{"id":"1.229554895","rc":[{"atb":[[1.4,0]],"id":50605162}],"con":true,"img":false}]}
{"op":"mcm","clk":"11449987118","pt":1717316785177,"mc":[{"id":"1.229554895","rc":[{"atb":[[55,0.02]],"id":50605162}],"con":true,"img":false}]}
{"op":"mcm","clk":"11449987136","pt":1717316785484,"mc":[{"id":"1.229554895","rc":[{"atl":[[1000,1.17]],"id":61028210}],"con":true,"img":false}]}
{"op":"mcm","clk":"11449987142","pt":1717316785586,"mc":[{"id":"1.229554895","rc":[{"atl":[[75,0]],"id":61028210}],"con":true,"img":false}]}
{"op":"mcm","clk":"11449987210","pt":1717316785956,"mc":[{"id":"1.229554895","rc":[{"atb":[[1.12,0]],"id":61028210}],"con":true,"img":false}]}
{"op":"mcm","clk":"11449987215","pt":1717316786058,"mc":[{"id":"1.229554895","rc":[{"atb":[[13.5,0.09]],"id":61028210}],"con":true,"img":false}]}
{"op":"mcm","clk":"11449987244","pt":1717316786469,"mc":[{"id":"1.229554895","rc":[{"atb":[[1.02,0]],"id":65732558}],"con":true,"img":false}]}
{"op":"mcm","clk":"11449987251","pt":1717316786570,"mc":[{"id":"1.229554895","rc":[{"atb":[[2.26,0.56]],"id":65732558}],"con":true,"img":false}]}
{"op":"mcm","clk":"11449987284","pt":1717316787142,"mc":[{"id":"1.229554895","rc":[{"atb":[[1.16,0]],"id":58069703}],"con":true,"img":false}]}
{"op":"mcm","clk":"11449987292","pt":1717316787245,"mc":[{"id":"1.229554895","rc":[{"atb":[[19,0.06]],"id":58069703}],"con":true,"img":false}]}
{"op":"mcm","clk":"11449987325","pt":1717316787862,"mc":[{"id":"1.229554895","rc":[{"atl":[[1000,2.7]],"id":63161712}],"con":true,"img":false}]}
{"op":"mcm","clk":"11449987336","pt":1717316787966,"mc":[{"id":"1.229554895","rc":[{"atl":[[1.98,0.43]],"id":63161712}],"con":true,"img":false}]}
{"op":"mcm","clk":"11449987354","pt":1717316788178,"mc":[{"id":"1.229554895","rc":[{"atl":[[920,2.07],[990,0.17]],"id":50605162}],"con":true,"img":false}]}
{"op":"mcm","clk":"11449987366","pt":1717316788383,"mc":[{"id":"1.229554895","rc":[{"atl":[[920,0.07],[990,2.17]],"id":50605162}],"con":true,"img":false}]}
{"op":"mcm","clk":"11449987372","pt":1717316788483,"mc":[{"id":"1.229554895","rc":[{"atl":[[920,2.07],[990,0.17]],"id":50605162}],"con":true,"img":false}]}
{"op":"mcm","clk":"11449987383","pt":1717316788640,"mc":[{"id":"1.229554895","rc":[{"atl":[[1000,1]],"id":65732558}],"con":true,"img":false}]}
{"op":"mcm","clk":"11449987391","pt":1717316788744,"mc":[{"id":"1.229554895","rc":[{"atl":[[4.4,0.19]],"id":65732558}],"con":true,"img":false}]}
{"op":"mcm","clk":"11449987398","pt":1717316788850,"mc":[{"id":"1.229554895","rc":[{"atb":[[19,1.41]],"id":58069703}],"con":true,"img":false}]}
{"op":"mcm","clk":"11449987478","pt":1717316790047,"mc":[{"id":"1.229554895","rc":[{"atl":[[1000,1.43]],"id":63161712}],"con":true,"img":false}]}
{"op":"mcm","clk":"11449987502","pt":1717316790381,"mc":[{"id":"1.229554895","rc":[{"atl":[[1000,21.92]],"id":58069703}],"con":true,"img":false}]}
{"op":"mcm","clk":"11449987510","pt":1717316790482,"mc":[{"id":"1.229554895","rc":[{"atl":[[65,0.14]],"id":58069703}],"con":true,"img":false}]}
{"op":"mcm","clk":"11449987704","pt":1717316793082,"mc":[{"id":"1.229554895","rc":[{"atl":[[80,2]],"id":61028210}],"con":true,"img":false}]}
{"op":"mcm","clk":"11449987711","pt":1717316793188,"mc":[{"id":"1.229554895","rc":[{"atl":[[75,2.62],[80,0],[95,4.61]],"id":61028210}],"con":true,"img":false}]}
{"op":"mcm","clk":"11449987720","pt":1717316793243,"mc":[{"id":"1.229554895","rc":[{"atl":[[180,2.77]],"id":61028210}],"con":true,"img":false}]}
{"op":"mcm","clk":"11449987728","pt":1717316793357,"mc":[{"id":"1.229554895","rc":[{"atl":[[180,0.77],[95,2.61]],"id":61028210}],"con":true,"img":false}]}
{"op":"mcm","clk":"11449987747","pt":1717316793563,"mc":[{"id":"1.229554895","rc":[{"atl":[[75,4.62]],"id":61028210}],"con":true,"img":false}]}
{"op":"mcm","clk":"11449987932","pt":1717316796196,"mc":[{"id":"1.229554895","rc":[{"atl":[[1000,1]],"id":63161712}],"con":true,"img":false}]}
{"op":"mcm","clk":"11449987941","pt":1717316796274,"mc":[{"id":"1.229554895","rc":[{"atl":[[1.98,0.86]],"id":63161712}],"con":true,"img":false}]}
{"op":"mcm","clk":"11449988114","pt":1717316798599,"mc":[{"id":"1.229554895","rc":[{"atb":[[4.1,16.13],[3.55,39.22]],"id":61028210},{"atl":[[100,0],[110,2]],"id":61028210}],"con":true,"img":false}]}
{"op":"mcm","clk":"11449988246","pt":1717316800582,"mc":[{"id":"1.229554895","rc":[{"atb":[[1.9,8.64]],"id":65732558}],"con":true,"img":false}]}
{"op":"mcm","clk":"11449988297","pt":1717316801258,"mc":[{"id":"1.229554895","rc":[{"atb":[[40,0]],"id":50605162},{"atl":[[920,2]],"id":50605162}],"con":true,"img":false}]}
{"op":"mcm","clk":"11449988302","pt":1717316801364,"mc":[{"id":"1.229554895","rc":[{"atb":[[46,3.11]],"id":50605162},{"atl":[[920,0],[990,2.17]],"id":50605162}],"con":true,"img":false}]}
{"op":"mcm","clk":"11449988957","pt":1717316810793,"mc":[{"id":"1.229554895","rc":[{"atb":[[1.02,2]],"id":65732558}],"con":true,"img":false}]}
{"op":"mcm","clk":"11449988997","pt":1717316811466,"mc":[{"id":"1.229554895","rc":[{"atb":[[1.02,2]],"id":63161712}],"con":true,"img":false}]}
{"op":"mcm","clk":"11449989109","pt":1717316812975,"mc":[{"id":"1.229554895","rc":[{"atl":[[75,2]],"id":61028210}],"con":true,"img":false}]}
{"op":"mcm","clk":"11449989118","pt":1717316813078,"mc":[{"id":"1.229554895","rc":[{"spn":42.0,"spf":"NaN","id":58069703},{"spn":267.5,"spf":"NaN","id":50605162},{"spn":3.33,"spf":"NaN","id":65732558},{"atl":[[75,0],[80,2.61],[95,4.61]],"id":61028210},{"spn":44.25,"spf":"NaN","id":61028210}],"con":true,"img":false}]}
{"op":"mcm","clk":"11449989312","pt":1717316815393,"mc":[{"id":"1.229554895","rc":[{"atb":[[1.02,0]],"id":65732558}],"con":true,"img":false}]}
{"op":"mcm","clk":"11449989323","pt":1717316815506,"mc":[{"id":"1.229554895","rc":[{"atb":[[2.26,2.56]],"id":65732558}],"con":true,"img":false}]}
{"op":"mcm","clk":"11449989350","pt":1717316815908,"mc":[{"id":"1.229554895","rc":[{"atb":[[1.02,0]],"id":63161712}],"con":true,"img":false}]}
{"op":"mcm","clk":"11449989358","pt":1717316816013,"mc":[{"id":"1.229554895","rc":[{"atb":[[1.41,2.9]],"id":63161712}],"con":true,"img":false}]}
{"op":"mcm","clk":"11449989524","pt":1717316818193,"mc":[{"id":"1.229554895","rc":[{"atl":[[80,4.61],[95,2.61]],"id":61028210}],"con":true,"img":false}]}
{"op":"mcm","clk":"11449989788","pt":1717316822597,"mc":[{"id":"1.229554895","rc":[{"atl":[[4.5,0]],"id":65732558}],"con":true,"img":false}]}
{"op":"mcm","clk":"11449990648","pt":1717316833034,"mc":[{"id":"1.229554895","rc":[{"atl":[[80,2]],"id":61028210}],"con":true,"img":false}]}
{"op":"mcm","clk":"11449990659","pt":1717316833138,"mc":[{"id":"1.229554895","rc":[{"atl":[[75,2.62],[80,0],[95,4.61]],"id":61028210}],"con":true,"img":false}]}
{"op":"mcm","clk":"11449991065","pt":1717316838203,"mc":[{"id":"1.229554895","rc":[{"atl":[[75,4.62]],"id":61028210}],"con":true,"img":false}]}
{"op":"mcm","clk":"11449991076","pt":1717316838305,"mc":[{"id":"1.229554895","rc":[{"atl":[[95,2.61]],"id":61028210}],"con":true,"img":false}]}
{"op":"mcm","clk":"11449991514","pt":1717316843637,"mc":[{"id":"1.229554895","rc":[{"atb":[[1.9,11.57]],"id":65732558}],"con":true,"img":false}]}
{"op":"mcm","clk":"11449991725","pt":1717316846323,"mc":[{"id":"1.229554895","rc":[{"atb":[[1.43,104.63]],"id":63161712}],"con":true,"img":false}]}
{"op":"mcm","clk":"11449991932","pt":1717316849418,"mc":[{"id":"1.229554895","rc":[{"atb":[[1.41,0.9]],"id":63161712}],"con":true,"img":false}]}
{"op":"mcm","clk":"11449991945","pt":1717316849519,"mc":[{"id":"1.229554895","rc":[{"atb":[[1.44,2]],"id":63161712}],"con":true,"img":false}]}
{"op":"mcm","clk":"11449992004","pt":1717316850342,"mc":[{"id":"1.229554895","rc":[{"atb":[[1.45,6.39]],"id":63161712}],"con":true,"img":false}]}
{"op":"mcm","clk":"11449992230","pt":1717316852956,"mc":[{"id":"1.229554895","rc":[{"atl":[[75,2]],"id":61028210}],"con":true,"img":false}]}
{"op":"mcm","clk":"11449992241","pt":1717316853049,"mc":[{"id":"1.229554895","rc":[{"atb":[[1.44,0]],"id":63161712},{"atl":[[80,2.61],[95,4.61]],"id":61028210}],"con":true,"img":false}]}
{"op":"mcm","clk":"11449992253","pt":1717316853154,"mc":[{"id":"1.229554895","rc":[{"atb":[[1.46,2]],"id":63161712},{"atl":[[75,0]],"id":61028210}],"con":true,"img":false}]}
{"op":"mcm","clk":"11449992261","pt":1717316853257,"mc":[{"id":"1.229554895","rc":[{"atl":[[95,2.61]],"id":61028210}],"con":true,"img":false}]}
{"op":"mcm","clk":"11449992285","pt":1717316853466,"mc":[{"id":"1.229554895","rc":[{"atl":[[80,4.61]],"id":61028210}],"con":true,"img":false}]}
{"op":"mcm","clk":"11449992303","pt":1717316853616,"mc":[{"id":"1.229554895","rc":[{"atb":[[1.45,0]],"id":63161712}],"con":true,"img":false}]}
{"op":"mcm","clk":"11449992426","pt":1717316855124,"mc":[{"id":"1.229554895","rc":[{"atb":[[1.46,0]],"id":63161712}],"con":true,"img":false}]}
{"op":"mcm","clk":"11449992435","pt":1717316855224,"mc":[{"id":"1.229554895","rc":[{"atb":[[1.44,2]],"id":63161712}],"con":true,"img":false}]}
{"op":"mcm","clk":"11449992471","pt":1717316855638,"mc":[{"id":"1.229554895","rc":[{"atb":[[1.45,6.39]],"id":63161712}],"con":true,"img":false}]}
{"op":"mcm","clk":"11449992632","pt":1717316857996,"mc":[{"id":"1.229554895","rc":[{"atb":[[1.44,0]],"id":63161712}],"con":true,"img":false}]}
{"op":"mcm","clk":"11449992639","pt":1717316858072,"mc":[{"id":"1.229554895","rc":[{"atb":[[1.46,2]],"id":63161712}],"con":true,"img":false}]}
{"op":"mcm","clk":"11449992659","pt":1717316858334,"mc":[{"id":"1.229554895","rc":[{"atb":[[1.45,0]],"id":63161712}],"con":true,"img":false}]}
{"op":"mcm","clk":"11449992855","pt":1717316861074,"mc":[{"id":"1.229554895","rc":[{"atb":[[1.46,0]],"id":63161712}],"con":true,"img":false}]}
{"op":"mcm","clk":"11449992865","pt":1717316861175,"mc":[{"id":"1.229554895","rc":[{"atb":[[1.44,2]],"id":63161712}],"con":true,"img":false}]}
{"op":"mcm","clk":"11449992907","pt":1717316861753,"mc":[{"id":"1.229554895","rc":[{"atb":[[1.45,6.39]],"id":63161712}],"con":true,"img":false}]}
{"op":"mcm","clk":"11449993243","pt":1717316865788,"mc":[{"id":"1.229554895","rc":[{"atb":[[1.44,0]],"id":63161712}],"con":true,"img":false}]}
{"op":"mcm","clk":"11449993252","pt":1717316865847,"mc":[{"id":"1.229554895","rc":[{"atb":[[1.46,2]],"id":63161712}],"con":true,"img":false}]}
{"op":"mcm","clk":"11449993284","pt":1717316866256,"mc":[{"id":"1.229554895","rc":[{"atb":[[1.45,0]],"id":63161712}],"con":true,"img":false}]}
{"op":"mcm","clk":"11449993519","pt":1717316869164,"mc":[{"id":"1.229554895","rc":[{"atb":[[1.46,0]],"id":63161712}],"con":true,"img":false}]}
{"op":"mcm","clk":"11449993524","pt":1717316869269,"mc":[{"id":"1.229554895","rc":[{"atb":[[1.44,2]],"id":63161712}],"con":true,"img":false}]}
{"op":"mcm","clk":"11449993561","pt":1717316869740,"mc":[{"id":"1.229554895","rc":[{"atb":[[1.45,6.39]],"id":63161712}],"con":true,"img":false}]}
{"op":"mcm","clk":"11449993580","pt":1717316869952,"mc":[{"id":"1.229554895","rc":[{"atb":[[34,0],[44,0],[27,0]],"id":50605162},{"atl":[[580,0],[480,0]],"id":50605162}],"con":true,"img":false}]}
{"op":"mcm","clk":"11449993596","pt":1717316870156,"mc":[{"id":"1.229554895","rc":[{"atl":[[990,0.17],[1000,3]],"id":50605162}],"con":true,"img":false}]}
{"op":"mcm","clk":"11449993793","pt":1717316872142,"mc":[{"id":"1.229554895","rc":[{"atl":[[4.5,4.28]],"id":65732558}],"con":true,"img":false}]}
{"op":"mcm","clk":"11449993915","pt":1717316873500,"mc":[{"id":"1.229554895","rc":[{"atb":[[1.44,0]],"id":63161712},{"spn":1.71,"spf":"NaN","id":63161712},{"spn":522.5,"spf":"NaN","id":50605162}],"con":true,"img":false}]}
{"op":"mcm","clk":"11449993922","pt":1717316873554,"mc":[{"id":"1.229554895","rc":[{"atb":[[1.46,2]],"id":63161712}],"con":true,"img":false}]}
{"op":"mcm","clk":"11449993957","pt":1717316873971,"mc":[{"id":"1.229554895","rc":[{"atb":[[1.45,0]],"id":63161712}],"con":true,"img":false}]}
{"op":"mcm","clk":"11449994188","pt":1717316876875,"mc":[{"id":"1.229554895","rc":[{"atb":[[1.46,0]],"id":63161712}],"con":true,"img":false}]}
{"op":"mcm","clk":"11449994202","pt":1717316876983,"mc":[{"id":"1.229554895","rc":[{"atb":[[1.44,2]],"id":63161712}],"con":true,"img":false}]}
{"op":"mcm","clk":"11449994219","pt":1717316877185,"mc":[{"id":"1.229554895","rc":[{"atb":[[1.45,6.39]],"id":63161712}],"con":true,"img":false}]}
{"op":"mcm","clk":"11449994444","pt":1717316879879,"mc":[{"id":"1.229554895","rc":[{"atb":[[1.44,0]],"id":63161712}],"con":true,"img":false}]}
{"op":"mcm","clk":"11449994452","pt":1717316879985,"mc":[{"id":"1.229554895","rc":[{"atb":[[1.46,2]],"id":63161712}],"con":true,"img":false}]}
{"op":"mcm","clk":"11449994473","pt":1717316880294,"mc":[{"id":"1.229554895","rc":[{"atb":[[1.45,0]],"id":63161712}],"con":true,"img":false}]}
{"op":"mcm","clk":"11449994570","pt":1717316881496,"mc":[{"id":"1.229554895","rc":[{"atl":[[1000,1]],"id":50605162},{"atb":[[13,5.9]],"id":61028210},{"atl":[[80,2.61]],"id":61028210}],"con":true,"img":false}]}
{"op":"mcm","clk":"11449994714","pt":1717316883074,"mc":[{"id":"1.229554895","rc":[{"atb":[[1.33,316.75]],"id":63161712}],"con":true,"img":false}]}
{"op":"mcm","clk":"11449994824","pt":1717316884222,"mc":[{"id":"1.229554895","rc":[{"atb":[[1.46,0],[1.36,81.42]],"id":63161712}],"con":true,"img":false}]}
{"op":"mcm","clk":"11449994843","pt":1717316884373,"mc":[{"id":"1.229554895","rc":[{"atb":[[1.44,2]],"id":63161712}],"con":true,"img":false}]}
{"op":"mcm","clk":"11449994851","pt":1717316884494,"mc":[{"id":"1.229554895","rc":[{"atb":[[1.45,6.39]],"id":63161712}],"con":true,"img":false}]}
{"op":"mcm","clk":"11449995037","pt":1717316886492,"mc":[{"id":"1.229554895","rc":[{"atb":[[1.44,0]],"id":63161712}],"con":true,"img":false}]}
{"op":"mcm","clk":"11449995047","pt":1717316886595,"mc":[{"id":"1.229554895","rc":[{"atb":[[1.46,2]],"id":63161712}],"con":true,"img":false}]}
{"op":"mcm","clk":"11449995103","pt":1717316887067,"mc":[{"id":"1.229554895","rc":[{"atb":[[1.45,0]],"id":63161712}],"con":true,"img":false}]}
{"op":"mcm","clk":"11449995259","pt":1717316889177,"mc":[{"id":"1.229554895","rc":[{"atb":[[1.46,0]],"id":63161712}],"con":true,"img":false}]}
{"op":"mcm","clk":"11449995272","pt":1717316889281,"mc":[{"id":"1.229554895","rc":[{"atb":[[1.44,2]],"id":63161712}],"con":true,"img":false}]}
{"op":"mcm","clk":"11449995328","pt":1717316889798,"mc":[{"id":"1.229554895","rc":[{"atb":[[1.45,6.39]],"id":63161712}],"con":true,"img":false}]}
{"op":"mcm","clk":"11449995437","pt":1717316891092,"mc":[{"id":"1.229554895","rc":[{"atb":[[34,6.33],[44,2.43],[27,8.04]],"id":50605162},{"atl":[[580,0.36],[480,0.29]],"id":50605162}],"con":true,"img":false}]}
{"op":"mcm","clk":"11449995518","pt":1717316891976,"mc":[{"id":"1.229554895","rc":[{"atb":[[1.44,0]],"id":63161712}],"con":true,"img":false}]}
{"op":"mcm","clk":"11449995527","pt":1717316892077,"mc":[{"id":"1.229554895","rc":[{"atb":[[1.46,2]],"id":63161712}],"con":true,"img":false}]}
{"op":"mcm","clk":"11449995549","pt":1717316892286,"mc":[{"id":"1.229554895","rc":[{"atb":[[19,1.38]],"id":58069703},{"atb":[[2.26,2.37]],"id":65732558}],"con":true,"img":false}]}
{"op":"mcm","clk":"11449995567","pt":1717316892501,"mc":[{"id":"1.229554895","rc":[{"atb":[[1.45,0]],"id":63161712}],"con":true,"img":false}]}
{"op":"mcm","clk":"11449995579","pt":1717316892604,"mc":[{"id":"1.229554895","rc":[{"atb":[[13.5,0.05]],"id":61028210}],"con":true,"img":false}]}
{"op":"mcm","clk":"11449995601","pt":1717316892802,"mc":[{"id":"1.229554895","rc":[{"atb":[[55,0.01]],"id":50605162}],"con":true,"img":false}]}
{"op":"mcm","clk":"11449995622","pt":1717316893004,"mc":[{"id":"1.229554895","rc":[{"atb":[[1.27,1.7]],"id":58069703}],"con":true,"img":false}]}
{"op":"mcm","clk":"11449995640","pt":1717316893162,"mc":[{"id":"1.229554895","rc":[{"atb":[[1.04,1.7]],"id":65732558},{"atb":[[1.2,1.7]],"id":61028210}],"con":true,"img":false}]}
{"op":"mcm","clk":"11449995656","pt":1717316893369,"mc":[{"id":"1.229554895","rc":[{"atb":[[1.8,1.7]],"id":50605162}],"con":true,"img":false}]}
{"op":"mcm","clk":"11449995671","pt":1717316893572,"mc":[{"id":"1.229554895","rc":[{"atb":[[1.27,0.02]],"id":58069703}],"con":true,"img":false}]}
{"op":"mcm","clk":"11449995682","pt":1717316893677,"mc":[{"id":"1.229554895","rc":[{"atb":[[1.2,0.03]],"id":61028210}],"con":true,"img":false}]}
{"op":"mcm","clk":"11449995698","pt":1717316893885,"mc":[{"id":"1.229554895","rc":[{"atb":[[1.04,0.18]],"id":65732558}],"con":true,"img":false}]}
{"op":"mcm","clk":"11449995703","pt":1717316893985,"mc":[{"id":"1.229554895","rc":[{"atb":[[1.41,0.6]],"id":63161712}],"con":true,"img":false}]}
{"op":"mcm","clk":"11449995733","pt":1717316894296,"mc":[{"id":"1.229554895","rc":[{"atb":[[1.27,0]],"id":58069703},{"atb":[[1.8,0]],"id":50605162}],"con":true,"img":false}]}
{"op":"mcm","clk":"11449995744","pt":1717316894398,"mc":[{"id":"1.229554895","rc":[{"atb":[[19.5,0.02]],"id":58069703}],"con":true,"img":false}]}
{"op":"mcm","clk":"11449995781","pt":1717316894814,"mc":[{"id":"1.229554895","rc":[{"atb":[[1.46,0]],"id":63161712}],"con":true,"img":false}]}
{"op":"mcm","clk":"11449995793","pt":1717316894916,"mc":[{"id":"1.229554895","rc":[{"atb":[[1.44,2]],"id":63161712},{"atb":[[1.2,0]],"id":61028210}],"con":true,"img":false}]}
{"op":"mcm","clk":"11449995807","pt":1717316894967,"mc":[{"id":"1.229554895","rc":[{"atb":[[13.5,0.09]],"id":61028210}],"con":true,"img":false}]}
{"op":"mcm","clk":"11449995828","pt":1717316895171,"mc":[{"id":"1.229554895","rc":[{"atb":[[1.45,6.39]],"id":63161712}],"con":true,"img":false}]}
{"op":"mcm","clk":"11449995836","pt":1717316895273,"mc":[{"id":"1.229554895","rc":[{"atb":[[1.04,0]],"id":65732558}],"con":true,"img":false}]}
{"op":"mcm","clk":"11449995846","pt":1717316895376,"mc":[{"id":"1.229554895","rc":[{"atb":[[2.28,0.18]],"id":65732558}],"con":true,"img":false}]}
{"op":"mcm","clk":"11449995868","pt":1717316895687,"mc":[{"id":"1.229554895","rc":[{"atb":[[1.03,7.66]],"id":63161712},{"atb":[[1.8,0]],"id":50605162}],"con":true,"img":false}]}
{"op":"mcm","clk":"11449995877","pt":1717316895791,"mc":[{"id":"1.229554895","rc":[{"atb":[[55,0.02]],"id":50605162}],"con":true,"img":false}]}
{"op":"mcm","clk":"11449995912","pt":1717316896105,"mc":[{"id":"1.229554895","rc":[{"atb":[[1.03,6.25]],"id":63161712}],"con":true,"img":false}]}
{"op":"mcm","clk":"11449995937","pt":1717316896410,"mc":[{"id":"1.229554895","rc":[{"atb":[[1.03,5.96]],"id":63161712}],"con":true,"img":false}]}
{"op":"mcm","clk":"11449995946","pt":1717316896516,"mc":[{"id":"1.229554895","rc":[{"atb":[[1.47,0.28]],"id":63161712}],"con":true,"img":false}]}
{"op":"mcm","clk":"11449995994","pt":1717316897093,"mc":[{"id":"1.229554895","rc":[{"atb":[[1.44,0]],"id":63161712}],"con":true,"img":false}]}
{"op":"mcm","clk":"11449996001","pt":1717316897190,"mc":[{"id":"1.229554895","rc":[{"atb":[[1.46,2]],"id":63161712}],"con":true,"img":false}]}
{"op":"mcm","clk":"11449996068","pt":1717316897911,"mc":[{"id":"1.229554895","rc":[{"atb":[[1.45,0]],"id":63161712}],"con":true,"img":false}]}
{"op":"mcm","clk":"11449996111","pt":1717316898476,"mc":[{"id":"1.229554895","rc":[{"atb":[[19,1.34]],"id":58069703},{"atl":[[65,0.12]],"id":58069703}],"con":true,"img":false}]}
{"op":"mcm","clk":"11449996190","pt":1717316899410,"mc":[{"id":"1.229554895","rc":[{"atb":[[2.26,2]],"id":65732558}],"con":true,"img":false}]}
{"op":"mcm","clk":"11449996215","pt":1717316899616,"mc":[{"id":"1.229554895","rc":[{"atb":[[1.41,0]],"id":63161712}],"con":true,"img":false}]}
{"op":"mcm","clk":"11449996226","pt":1717316899719,"mc":[{"id":"1.229554895","rc":[{"atl":[[4.4,0]],"id":65732558}],"con":true,"img":false}]}
{"op":"mcm","clk":"11449996261","pt":1717316899978,"mc":[{"id":"1.229554895","rc":[{"atl":[[1.98,0.43]],"id":63161712}],"con":true,"img":false}]}
{"op":"mcm","clk":"11449996317","pt":1717316900805,"mc":[{"id":"1.229554895","rc":[{"atb":[[13.5,0.03]],"id":61028210},{"atl":[[75,0]],"id":61028210}],"con":true,"img":false}]}
{"op":"mcm","clk":"11449996332","pt":1717316901114,"mc":[{"id":"1.229554895","rc":[{"atb":[[55,0]],"id":50605162}],"con":true,"img":false}]}
{"op":"mcm","clk":"11449996622","pt":1717316904337,"mc":[{"id":"1.229554895","rc":[{"atl":[[2.44,0]],"id":63161712}],"con":true,"img":false}]}
{"op":"mcm","clk":"11449996793","pt":1717316906617,"mc":[{"id":"1.229554895","rc":[{"atl":[[1000,23.63]],"id":58069703},{"atb":[[1.02,1.7]],"id":65732558}],"con":true,"img":false}]}
{"op":"mcm","clk":"11449996811","pt":1717316906826,"mc":[{"id":"1.229554895","rc":[{"atb":[[1.03,7.66]],"id":63161712},{"atb":[[1.16,1.7]],"id":58069703}],"con":true,"img":false}]}
{"op":"mcm","clk":"11449996895","pt":1717316907912,"mc":[{"id":"1.229554895","rc":[{"atb":[[1.12,1.7]],"id":61028210}],"con":true,"img":false}]}
{"op":"mcm","clk":"11449996968","pt":1717316908798,"mc":[{"id":"1.229554895","rc":[{"atb":[[1.4,1.7]],"id":50605162}],"con":true,"img":false}]}
{"op":"mcm","clk":"11449997173","pt":1717316911640,"mc":[{"id":"1.229554895","rc":[{"atl":[[1.98,0]],"id":63161712}],"con":true,"img":false}]}
{"op":"mcm","clk":"11449997227","pt":1717316912267,"mc":[{"id":"1.229554895","rc":[{"atl":[[1000,21.94]],"id":58069703}],"con":true,"img":false}]}
{"op":"mcm","clk":"11449997243","pt":1717316912422,"mc":[{"id":"1.229554895","rc":[{"atb":[[1.02,0.37]],"id":65732558}],"con":true,"img":false}]}
{"op":"mcm","clk":"11449997252","pt":1717316912526,"mc":[{"id":"1.229554895","rc":[{"atb":[[1.12,0.05]],"id":61028210}],"con":true,"img":false}]}
{"op":"mcm","clk":"11449997282","pt":1717316912841,"mc":[{"id":"1.229554895","rc":[{"atb":[[1.03,6.54]],"id":63161712}],"con":true,"img":false}]}
{"op":"mcm","clk":"11449997297","pt":1717316913051,"mc":[{"id":"1.229554895","rc":[{"atb":[[1.16,0.04]],"id":58069703}],"con":true,"img":false}]}
{"op":"mcm","clk":"11449997309","pt":1717316913206,"mc":[{"id":"1.229554895","rc":[{"atb":[[1.4,0.01]],"id":50605162}],"con":true,"img":false}]}
{"op":"mcm","clk":"11449997447","pt":1717316914806,"mc":[{"id":"1.229554895","rc":[{"atl":[[1000,2.7]],"id":65732558}],"con":true,"img":false}]}
{"op":"mcm","clk":"11449997457","pt":1717316914909,"mc":[{"id":"1.229554895","rc":[{"atl":[[1000,2.88]],"id":61028210}],"con":true,"img":false}]}
{"op":"mcm","clk":"11449997512","pt":1717316915639,"mc":[{"id":"1.229554895","rc":[{"atl":[[1000,21.92]],"id":58069703}],"con":true,"img":false}]}
{"op":"mcm","clk":"11449997526","pt":1717316915743,"mc":[{"id":"1.229554895","rc":[{"atl":[[65,0.14]],"id":58069703}],"con":true,"img":false}]}
{"op":"mcm","clk":"11449997561","pt":1717316916303,"mc":[{"id":"1.229554895","rc":[{"atb":[[1.02,0]],"id":65732558}],"con":true,"img":false}]}
{"op":"mcm","clk":"11449997572","pt":1717316916406,"mc":[{"id":"1.229554895","rc":[{"atb":[[2.28,0.56]],"id":65732558}],"con":true,"img":false}]}
{"op":"mcm","clk":"11449997599","pt":1717316916817,"mc":[{"id":"1.229554895","rc":[{"atb":[[1.12,0]],"id":61028210}],"con":true,"img":false}]}
{"op":"mcm","clk":"11449997607","pt":1717316916921,"mc":[{"id":"1.229554895","rc":[{"atb":[[13.5,0.09]],"id":61028210}],"con":true,"img":false}]}
{"op":"mcm","clk":"11449997634","pt":1717316917346,"mc":[{"id":"1.229554895","rc":[{"atb":[[1.03,5.96]],"id":63161712}],"con":true,"img":false}]}
{"op":"mcm","clk":"11449997640","pt":1717316917397,"mc":[{"id":"1.229554895","rc":[{"atb":[[1.46,2.57]],"id":63161712}],"con":true,"img":false}]}
{"op":"mcm","clk":"11449997731","pt":1717316918503,"mc":[{"id":"1.229554895","rc":[{"atb":[[1.16,0]],"id":58069703}],"con":true,"img":false}]}
{"op":"mcm","clk":"11449997738","pt":1717316918607,"mc":[{"id":"1.229554895","rc":[{"atb":[[19.5,0.06]],"id":58069703}],"con":true,"img":false}]}
{"op":"mcm","clk":"11449997758","pt":1717316918915,"mc":[{"id":"1.229554895","rc":[{"atb":[[1.4,0]],"id":50605162}],"con":true,"img":false}]}
{"op":"mcm","clk":"11449997766","pt":1717316919019,"mc":[{"id":"1.229554895","rc":[{"atb":[[55,0.02]],"id":50605162}],"con":true,"img":false}]}
{"op":"mcm","clk":"11449997828","pt":1717316919638,"mc":[{"id":"1.229554895","rc":[{"atl":[[3.1,0],[3.45,40.82]],"id":63161712},{"atl":[[1000,1.19]],"id":65732558}],"con":true,"img":false}]}
{"op":"mcm","clk":"11449997883","pt":1717316920411,"mc":[{"id":"1.229554895","rc":[{"atl":[[1000,1.18]],"id":61028210}],"con":true,"img":false}]}
{"op":"mcm","clk":"11449997934","pt":1717316921136,"mc":[{"id":"1.229554895","rc":[{"atl":[[1000,2.7]],"id":63161712}],"con":true,"img":false}]}
{"op":"mcm","clk":"11449997989","pt":1717316921709,"mc":[{"id":"1.229554895","rc":[{"atl":[[1000,3]],"id":50605162},{"atb":[[13,7.9]],"id":61028210},{"atl":[[80,4.61]],"id":61028210}],"con":true,"img":false}]}
{"op":"mcm","clk":"11449998035","pt":1717316922223,"mc":[{"id":"1.229554895","rc":[{"atl":[[1000,1]],"id":65732558}],"con":true,"img":false}]}
{"op":"mcm","clk":"11449998045","pt":1717316922326,"mc":[{"id":"1.229554895","rc":[{"atl":[[4.4,0.19]],"id":65732558}],"con":true,"img":false}]}
{"op":"mcm","clk":"11449998062","pt":1717316922635,"mc":[{"id":"1.229554895","rc":[{"atl":[[1000,1.17]],"id":61028210}],"con":true,"img":false}]}
{"op":"mcm","clk":"11449998073","pt":1717316922738,"mc":[{"id":"1.229554895","rc":[{"atl":[[75,0]],"id":61028210}],"con":true,"img":false}]}
{"op":"mcm","clk":"11449998097","pt":1717316923045,"mc":[{"id":"1.229554895","rc":[{"atb":[[1.36,84.83]],"id":63161712}],"con":true,"img":false}]}
{"op":"mcm","clk":"11449998163","pt":1717316923817,"mc":[{"id":"1.229554895","rc":[{"atl":[[1000,1.43]],"id":63161712}],"con":true,"img":false}]}
{"op":"mcm","clk":"11449998188","pt":1717316924230,"mc":[{"id":"1.229554895","rc":[{"atl":[[1000,1]],"id":63161712}],"con":true,"img":false}]}
{"op":"mcm","clk":"11449998195","pt":1717316924359,"mc":[{"id":"1.229554895","rc":[{"atl":[[1.98,0.43]],"id":63161712}],"con":true,"img":false}]}
{"op":"mcm","clk":"11450000251","pt":1717316948490,"mc":[{"id":"1.229554895","rc":[{"atb":[[1.36,75.17]],"id":63161712},{"spn":1.72,"spf":"NaN","id":63161712},{"spn":42.25,"spf":"NaN","id":58069703},{"spn":267.5,"spf":"NaN","id":50605162},{"spn":3.34,"spf":"NaN","id":65732558}],"con":true,"img":false}]}
{"op":"mcm","clk":"11450000579","pt":1717316951972,"mc":[{"id":"1.229554895","rc":[{"atl":[[2.44,7.9]],"id":63161712}],"con":true,"img":false}]}
{"op":"mcm","clk":"11450003229","pt":1717316983411,"mc":[{"id":"1.229554895","rc":[{"atb":[[1.01,1]],"id":58069703}],"con":true,"img":false}]}
{"op":"mcm","clk":"11450003392","pt":1717316985217,"mc":[{"id":"1.229554895","rc":[{"atb":[[1.37,6.98]],"id":63161712}],"con":true,"img":false}]}
{"op":"mcm","clk":"11450003807","pt":1717316990429,"mc":[{"id":"1.229554895","rc":[{"trd":[[1.99,1.14],[1.98,0.86]],"ltp":1.99,"tv":2.0,"id":63161712},{"atl":[[1.98,0],[1.99,2.43]],"id":63161712}],"con":true,"img":false}]}
{"op":"mcm","clk":"11450003916","pt":1717316991623,"mc":[{"id":"1.229554895","rc":[{"atl":[[3.45,0],[1.99,7.16],[2.66,2.61]],"id":63161712}],"con":true,"img":false}]}
{"op":"mcm","clk":"11450003937","pt":1717316991935,"mc":[{"id":"1.229554895","rc":[{"atb":[[34,0],[44,0],[27,0]],"id":50605162},{"atl":[[580,0],[480,0]],"id":50605162}],"con":true,"img":false}]}
{"op":"mcm","clk":"11450003961","pt":1717316992343,"mc":[{"id":"1.229554895","rc":[{"atb":[[1.47,2.84]],"id":63161712},{"atb":[[19,3.47]],"id":58069703},{"atb":[[2.28,3.11]],"id":65732558}],"con":true,"img":false}]}
{"op":"mcm","clk":"11450004026","pt":1717316993027,"mc":[{"id":"1.229554895","rc":[{"atl":[[2.78,0]],"id":63161712}],"con":true,"img":false}]}
{"op":"mcm","clk":"11450004038","pt":1717316993128,"mc":[{"id":"1.229554895","rc":[{"atl":[[2.98,71.67]],"id":63161712}],"con":true,"img":false}]}
{"op":"mcm","clk":"11450004149","pt":1717316994440,"mc":[{"id":"1.229554895","rc":[{"atb":[[2.26,0]],"id":65732558}],"con":true,"img":false}]}
{"op":"mcm","clk":"11450004158","pt":1717316994539,"mc":[{"id":"1.229554895","rc":[{"atb":[[2.3,2]],"id":65732558}],"con":true,"img":false}]}
{"op":"mcm","clk":"11450004193","pt":1717316994956,"mc":[{"id":"1.229554895","rc":[{"atb":[[1.46,0.57]],"id":63161712}],"con":true,"img":false}]}
{"op":"mcm","clk":"11450004202","pt":1717316995011,"mc":[{"id":"1.229554895","rc":[{"atb":[[1.48,2]],"id":63161712}],"con":true,"img":false}]}
{"op":"mcm","clk":"11450004344","pt":1717316996729,"mc":[{"id":"1.229554895","rc":[{"atb":[[1.47,0.28]],"id":63161712},{"atb":[[2.28,0.56]],"id":65732558}],"con":true,"img":false}]}
{"op":"mcm","clk":"11450004548","pt":1717316999314,"mc":[{"id":"1.229554895","rc":[{"atb":[[2.32,2.55]],"id":65732558}],"con":true,"img":false}]}
{"op":"mcm","clk":"11450004733","pt":1717317001046,"mc":[{"id":"1.229554895","rc":[{"atb":[[2.3,0]],"id":65732558}],"con":true,"img":false}]}
{"op":"mcm","clk":"11450004748","pt":1717317001151,"mc":[{"id":"1.229554895","rc":[{"atb":[[2.34,2]],"id":65732558}],"con":true,"img":false}]}
{"op":"mcm","clk":"11450004767","pt":1717317001258,"mc":[{"id":"1.229554895","rc":[{"atl":[[3.45,40.82],[1.99,2.42]],"id":63161712}],"con":true,"img":false}]}
{"op":"mcm","clk":"11450004803","pt":1717317001564,"mc":[{"id":"1.229554895","rc":[{"atb":[[1.48,0]],"id":63161712}],"con":true,"img":false}]}
{"op":"mcm","clk":"11450004815","pt":1717317001670,"mc":[{"id":"1.229554895","rc":[{"atb":[[1.44,2]],"id":63161712}],"con":true,"img":false}]}
{"op":"mcm","clk":"11450004871","pt":1717317002140,"mc":[{"id":"1.229554895","rc":[{"atl":[[65,0.01]],"id":58069703}],"con":true,"img":false}]}
{"op":"mcm","clk":"11450005012","pt":1717317003547,"mc":[{"id":"1.229554895","rc":[{"atb":[[1.45,2.55]],"id":63161712},{"atb":[[55,0.41]],"id":50605162},{"atb":[[2.32,0]],"id":65732558}],"con":true,"img":false}]}
{"op":"mcm","clk":"11450005158","pt":1717317004958,"mc":[{"id":"1.229554895","rc":[{"atb":[[1.02,11.3]],"id":58069703},{"atb":[[1.02,2.35]],"id":61028210}],"con":true,"img":false}]}
{"op":"mcm","clk":"11450005220","pt":1717317005528,"mc":[{"id":"1.229554895","rc":[{"atl":[[1000,2.7]],"id":63161712}],"con":true,"img":false}]}
{"op":"mcm","clk":"11450005431","pt":1717317007646,"mc":[{"id":"1.229554895","rc":[{"atb":[[2.34,0]],"id":65732558}],"con":true,"img":false}]}
{"op":"mcm","clk":"11450005441","pt":1717317007751,"mc":[{"id":"1.229554895","rc":[{"atb":[[2.26,2]],"id":65732558}],"con":true,"img":false}]}
{"op":"mcm","clk":"11450005452","pt":1717317007857,"mc":[{"id":"1.229554895","rc":[{"atl":[[1000,1.21]],"id":63161712}],"con":true,"img":false}]}
{"op":"mcm","clk":"11450005482","pt":1717317008164,"mc":[{"id":"1.229554895","rc":[{"atb":[[1.44,0]],"id":63161712}],"con":true,"img":false}]}
{"op":"mcm","clk":"11450005493","pt":1717317008264,"mc":[{"id":"1.229554895","rc":[{"atb":[[1.46,2.57]],"id":63161712},{"atb":[[1.02,0.39]],"id":61028210}],"con":true,"img":false}]}
{"op":"mcm","clk":"11450005520","pt":1717317008576,"mc":[{"id":"1.229554895","rc":[{"atl":[[1000,1]],"id":63161712},{"spn":1.73,"spf":"NaN","id":63161712},{"atb":[[1.02,9.34]],"id":58069703},{"spn":522.5,"spf":"NaN","id":50605162}],"con":true,"img":false}]}
{"op":"mcm","clk":"11450005533","pt":1717317008706,"mc":[{"id":"1.229554895","rc":[{"atl":[[1.98,0.21]],"id":63161712}],"con":true,"img":false}]}
{"op":"mcm","clk":"11450005587","pt":1717317009146,"mc":[{"id":"1.229554895","rc":[{"atb":[[50,3.63]],"id":50605162}],"con":true,"img":false}]}
{"op":"mcm","clk":"11450005595","pt":1717317009251,"mc":[{"id":"1.229554895","rc":[{"atb":[[12.5,4.08]],"id":61028210}],"con":true,"img":false}]}
{"op":"mcm","clk":"11450005605","pt":1717317009355,"mc":[{"id":"1.229554895","rc":[{"atb":[[1.34,365.58]],"id":63161712},{"atl":[[4.5,7.25]],"id":65732558}],"con":true,"img":false}]}
{"op":"mcm","clk":"11450005613","pt":1717317009459,"mc":[{"id":"1.229554895","rc":[{"atb":[[2.16,6.76]],"id":65732558}],"con":true,"img":false}]}
{"op":"mcm","clk":"11450005622","pt":1717317009561,"mc":[{"id":"1.229554895","rc":[{"atb":[[1.37,28.19]],"id":63161712}],"con":true,"img":false}]}
{"op":"mcm","clk":"11450005638","pt":1717317009768,"mc":[{"id":"1.229554895","rc":[{"atb":[[13.5,1.98]],"id":61028210}],"con":true,"img":false}]}
{"op":"mcm","clk":"11450005647","pt":1717317009868,"mc":[{"id":"1.229554895","rc":[{"atl":[[2.66,8.21]],"id":63161712}],"con":true,"img":false}]}
{"op":"mcm","clk":"11450005660","pt":1717317010025,"mc":[{"id":"1.229554895","rc":[{"atb":[[1.45,0]],"id":63161712},{"atb":[[2.28,3.11]],"id":65732558}],"con":true,"img":false}]}
{"op":"mcm","clk":"11450005669","pt":1717317010126,"mc":[{"id":"1.229554895","rc":[{"atb":[[2.08,24.53]],"id":65732558}],"con":true,"img":false}]}
{"op":"mcm","clk":"11450005674","pt":1717317010230,"mc":[{"id":"1.229554895","rc":[{"atb":[[17.5,2.91]],"id":58069703}],"con":true,"img":false}]}
{"op":"mcm","clk":"11450005690","pt":1717317010438,"mc":[{"id":"1.229554895","rc":[{"atb":[[1.02,0]],"id":61028210}],"con":true,"img":false}]}
{"op":"mcm","clk":"11450005700","pt":1717317010539,"mc":[{"id":"1.229554895","rc":[{"atb":[[13.5,2.37]],"id":61028210}],"con":true,"img":false}]}
{"op":"mcm","clk":"11450005746","pt":1717317011169,"mc":[{"id":"1.229554895","rc":[{"atb":[[2.14,9.94]],"id":65732558}],"con":true,"img":false}]}
{"op":"mcm","clk":"11450005761","pt":1717317011336,"mc":[{"id":"1.229554895","rc":[{"atb":[[1.44,25.77]],"id":63161712},{"atb":[[2.26,0]],"id":65732558}],"con":true,"img":false}]}
{"op":"mcm","clk":"11450005768","pt":1717317011441,"mc":[{"id":"1.229554895","rc":[{"atb":[[2.3,2]],"id":65732558}],"con":true,"img":false}]}
{"op":"mcm","clk":"11450005788","pt":1717317011647,"mc":[{"id":"1.229554895","rc":[{"atb":[[1.02,8.94]],"id":58069703}],"con":true,"img":false}]}
{"op":"mcm","clk":"11450005800","pt":1717317011748,"mc":[{"id":"1.229554895","rc":[{"atb":[[19.5,0.46]],"id":58069703}],"con":true,"img":false}]}
{"op":"mcm","clk":"11450005829","pt":1717317012066,"mc":[{"id":"1.229554895","rc":[{"atb":[[1.02,2.35]],"id":65732558}],"con":true,"img":false}]}
{"op":"mcm","clk":"11450005878","pt":1717317012476,"mc":[{"id":"1.229554895","rc":[{"atb":[[1.47,2.84]],"id":63161712},{"atb":[[14,2.13]],"id":61028210}],"con":true,"img":false}]}
{"op":"mcm","clk":"11450005900","pt":1717317012633,"mc":[{"id":"1.229554895","rc":[{"atb":[[13,5.9],[14,4.13]],"id":61028210}],"con":true,"img":false}]}
{"op":"mcm","clk":"11450005933","pt":1717317012943,"mc":[{"id":"1.229554895","rc":[{"atb":[[13.5,0.48]],"id":61028210}],"con":true,"img":false}]}
{"op":"mcm","clk":"11450006008","pt":1717317013664,"mc":[{"id":"1.229554895","rc":[{"atb":[[2.28,0.56]],"id":65732558}],"con":true,"img":false}]}
{"op":"mcm","clk":"11450006034","pt":1717317013976,"mc":[{"id":"1.229554895","rc":[{"atb":[[13.5,0.09]],"id":61028210}],"con":true,"img":false}]}
{"op":"mcm","clk":"11450006073","pt":1717317014342,"mc":[{"id":"1.229554895","rc":[{"atb":[[1.02,2.35]],"id":61028210}],"con":true,"img":false}]}
{"op":"mcm","clk":"11450006097","pt":1717317014651,"mc":[{"id":"1.229554895","rc":[{"atb":[[2.3,0]],"id":65732558}],"con":true,"img":false}]}
{"op":"mcm","clk":"11450006110","pt":1717317014770,"mc":[{"id":"1.229554895","rc":[{"atb":[[2.26,2]],"id":65732558}],"con":true,"img":false}]}
{"op":"mcm","clk":"11450006138","pt":1717317015067,"mc":[{"id":"1.229554895","rc":[{"atb":[[1.02,0.39]],"id":65732558}],"con":true,"img":false}]}
{"op":"mcm","clk":"11450006147","pt":1717317015166,"mc":[{"id":"1.229554895","rc":[{"atb":[[2.32,2.55]],"id":65732558}],"con":true,"img":false}]}
{"op":"mcm","clk":"11450006160","pt":1717317015270,"mc":[{"id":"1.229554895","rc":[{"atb":[[1.46,0.57]],"id":63161712}],"con":true,"img":false}]}
{"op":"mcm","clk":"11450006168","pt":1717317015379,"mc":[{"id":"1.229554895","rc":[{"atb":[[1.48,2]],"id":63161712},{"atb":[[19.5,0.43]],"id":58069703}],"con":true,"img":false}]}
{"op":"mcm","clk":"11450006178","pt":1717317015480,"mc":[{"id":"1.229554895","rc":[{"atb":[[1.02,0.39]],"id":61028210}],"con":true,"img":false}]}
{"op":"mcm","clk":"11450006250","pt":1717317016266,"mc":[{"id":"1.229554895","rc":[{"atb":[[2.28,0.37]],"id":65732558}],"con":true,"img":false}]}
{"op":"mcm","clk":"11450006280","pt":1717317016676,"mc":[{"id":"1.229554895","rc":[{"atb":[[55,0.4]],"id":50605162}],"con":true,"img":false}]}
{"op":"mcm","clk":"11450006337","pt":1717317017246,"mc":[{"id":"1.229554895","rc":[{"atb":[[1.02,0]],"id":65732558}],"con":true,"img":false}]}
{"op":"mcm","clk":"11450006347","pt":1717317017355,"mc":[{"id":"1.229554895","rc":[{"atb":[[2.26,0],[2.14,10.33]],"id":65732558},{"atb":[[13.5,0.05]],"id":61028210}],"con":true,"img":false}]}
{"op":"mcm","clk":"11450006356","pt":1717317017453,"mc":[{"id":"1.229554895","rc":[{"atb":[[2.34,2]],"id":65732558}],"con":true,"img":false}]}
{"op":"mcm","clk":"11450006374","pt":1717317017661,"mc":[{"id":"1.229554895","rc":[{"atb":[[1.02,0]],"id":61028210}],"con":true,"img":false}]}
{"op":"mcm","clk":"11450006386","pt":1717317017768,"mc":[{"id":"1.229554895","rc":[{"atb":[[14.5,0.39]],"id":61028210}],"con":true,"img":false}]}
{"op":"mcm","clk":"11450006403","pt":1717317017979,"mc":[{"id":"1.229554895","rc":[{"atb":[[1.47,0]],"id":63161712}],"con":true,"img":false}]}
{"op":"mcm","clk":"11450006436","pt":1717317018236,"mc":[{"id":"1.229554895","rc":[{"atb":[[1.27,1.7]],"id":58069703}],"con":true,"img":false}]}
{"op":"mcm","clk":"11450006456","pt":1717317018448,"mc":[{"id":"1.229554895","rc":[{"atb":[[34,6.33],[44,2.43],[27,8.04]],"id":50605162},{"atl":[[580,0.36],[480,0.29]],"id":50605162}],"con":true,"img":false}]}
{"op":"mcm","clk":"11450006471","pt":1717317018552,"mc":[{"id":"1.229554895","rc":[{"atb":[[1.1,0]],"id":63161712},{"atb":[[5.6,21.74],[22,2]],"id":58069703},{"atl":[[65,2.01],[110,2]],"id":58069703},{"atb":[[6.6,16.13]],"id":50605162},{"atl":[[580,2.36]],"id":50605162},{"atb":[[2.26,6.77]],"id":65732558},{"atl":[[6.6,17.86],[15,0]],"id":65732558},{"atb":[[14,2.13]],"id":61028210},{"atl":[[80,6.61],[110,0]],"id":61028210}],"con":true,"img":false}]}
{"op":"mcm","clk":"11450006479","pt":1717317018653,"mc":[{"id":"1.229554895","rc":[{"atl":[[500,0]],"id":58069703},{"atl":[[90,2]],"id":61028210}],"con":true,"img":false}]}
{"op":"mcm","clk":"11450006487","pt":1717317018756,"mc":[{"id":"1.229554895","rc":[{"atl":[[80,4.61]],"id":61028210}],"con":true,"img":false}]}
{"op":"mcm","clk":"11450006495","pt":1717317018859,"mc":[{"id":"1.229554895","rc":[{"atb":[[19,2.13]],"id":58069703}],"con":true,"img":false}]}
{"op":"mcm","clk":"11450006502","pt":1717317018962,"mc":[{"id":"1.229554895","rc":[{"atb":[[1.04,1.7]],"id":65732558}],"con":true,"img":false}]}
{"op":"mcm","clk":"11450006534","pt":1717317019275,"mc":[{"id":"1.229554895","rc":[{"atb":[[1.8,1.7]],"id":50605162}],"con":true,"img":false}]}
{"op":"mcm","clk":"11450006548","pt":1717317019376,"mc":[{"id":"1.229554895","rc":[{"atl":[[1.98,2.76]],"id":63161712}],"con":true,"img":false}]}
{"op":"mcm","clk":"11450006563","pt":1717317019480,"mc":[{"id":"1.229554895","rc":[{"atb":[[2.32,0]],"id":65732558}],"con":true,"img":false}]}
{"op":"mcm","clk":"11450006596","pt":1717317019788,"mc":[{"id":"1.229554895","rc":[{"atb":[[1.27,1.7]],"id":61028210}],"con":true,"img":false}]}
{"op":"mcm","clk":"11450006644","pt":1717317020256,"mc":[{"id":"1.229554895","rc":[{"atb":[[1.03,7.66]],"id":63161712}],"con":true,"img":false}]}
{"op":"mcm","clk":"11450006665","pt":1717317020463,"mc":[{"id":"1.229554895","rc":[{"atb":[[1.02,11.3]],"id":58069703},{"atb":[[2.34,0]],"id":65732558}],"con":true,"img":false}]}
{"op":"mcm","clk":"11450006674","pt":1717317020564,"mc":[{"id":"1.229554895","rc":[{"atb":[[2.28,2.37]],"id":65732558}],"con":true,"img":false}]}
{"op":"mcm","clk":"11450006695","pt":1717317020772,"mc":[{"id":"1.229554895","rc":[{"atb":[[19,0]],"id":58069703}],"con":true,"img":false}]}
{"op":"mcm","clk":"11450006707","pt":1717317020878,"mc":[{"id":"1.229554895","rc":[{"atb":[[1.48,0]],"id":63161712},{"atb":[[1.27,0.02]],"id":58069703},{"atl":[[1000,23.63]],"id":58069703}],"con":true,"img":false}]}
{"op":"mcm","clk":"11450006716","pt":1717317020976,"mc":[{"id":"1.229554895","rc":[{"atb":[[1.37,30.58],[1.45,2]],"id":63161712}],"con":true,"img":false}]}
{"op":"mcm","clk":"11450006747","pt":1717317021286,"mc":[{"id":"1.229554895","rc":[{"atb":[[1.46,6.97]],"id":63161712},{"atb":[[1.04,0.17]],"id":65732558}],"con":true,"img":false}]}
{"op":"mcm","clk":"11450006782","pt":1717317021649,"mc":[{"id":"1.229554895","rc":[{"atb":[[19.5,0.04]],"id":58069703}],"con":true,"img":false}]}
{"op":"mcm","clk":"11450006825","pt":1717317022065,"mc":[{"id":"1.229554895","rc":[{"atb":[[1.02,9.34]],"id":58069703}],"con":true,"img":false}]}
{"op":"mcm","clk":"11450006837","pt":1717317022170,"mc":[{"id":"1.229554895","rc":[{"atb":[[1.27,0]],"id":58069703},{"atb":[[1.8,0]],"id":50605162}],"con":true,"img":false}]}
{"op":"mcm","clk":"11450006849","pt":1717317022277,"mc":[{"id":"1.229554895","rc":[{"atb":[[19.5,0.06]],"id":58069703}],"con":true,"img":false}]}
{"op":"mcm","clk":"11450006892","pt":1717317022746,"mc":[{"id":"1.229554895","rc":[{"atb":[[1.04,0]],"id":65732558}],"con":true,"img":false}]}
{"op":"mcm","clk":"11450006901","pt":1717317022851,"mc":[{"id":"1.229554895","rc":[{"atb":[[2.34,0.17]],"id":65732558}],"con":true,"img":false}]}
{"op":"mcm","clk":"11450006910","pt":1717317022952,"mc":[{"id":"1.229554895","rc":[{"atb":[[1.36,0]],"id":63161712},{"atb":[[1.27,0.02]],"id":61028210}],"con":true,"img":false}]}
{"op":"mcm","clk":"11450006923","pt":1717317023054,"mc":[{"id":"1.229554895","rc":[{"atb":[[1.38,75.17]],"id":63161712}],"con":true,"img":false}]}
{"op":"mcm","clk":"11450006936","pt":1717317023157,"mc":[{"id":"1.229554895","rc":[{"atb":[[1.47,2.55]],"id":63161712},{"atb":[[2.3,2.55]],"id":65732558}],"con":true,"img":false}]}
{"op":"mcm","clk":"11450006958","pt":1717317023360,"mc":[{"id":"1.229554895","rc":[{"atb":[[1.02,8.94]],"id":58069703},{"atb":[[1.8,0]],"id":50605162}],"con":true,"img":false}]}
{"op":"mcm","clk":"11450006969","pt":1717317023464,"mc":[{"id":"1.229554895","rc":[{"atb":[[1.46,0.57]],"id":63161712},{"atb":[[23,0.39]],"id":58069703},{"atb":[[55,0.41]],"id":50605162}],"con":true,"img":false}]}
{"op":"mcm","clk":"11450007005","pt":1717317023776,"mc":[{"id":"1.229554895","rc":[{"atb":[[2.28,0.37]],"id":65732558},{"atl":[[80,6.61]],"id":61028210}],"con":true,"img":false}]}
{"op":"mcm","clk":"11450007015","pt":1717317023875,"mc":[{"id":"1.229554895","rc":[{"atb":[[1.03,6.25]],"id":63161712},{"atb":[[2.32,2]],"id":65732558},{"atl":[[80,4.61]],"id":61028210}],"con":true,"img":false}]}
{"op":"mcm","clk":"11450007029","pt":1717317024080,"mc":[{"id":"1.229554895","rc":[{"atb":[[1.45,0]],"id":63161712},{"atb":[[1.27,0]],"id":61028210}],"con":true,"img":false}]}
{"op":"mcm","clk":"11450007036","pt":1717317024185,"mc":[{"id":"1.229554895","rc":[{"atb":[[1.48,2]],"id":63161712},{"atb":[[14.5,0.41]],"id":61028210}],"con":true,"img":false}]}
{"op":"mcm","clk":"11450007066","pt":1717317024456,"mc":[{"id":"1.229554895","rc":[{"atl":[[1000,21.93]],"id":58069703}],"con":true,"img":false}]}
{"op":"mcm","clk":"11450007135","pt":1717317025067,"mc":[{"id":"1.229554895","rc":[{"atb":[[1.03,5.96]],"id":63161712}],"con":true,"img":false}]}
{"op":"mcm","clk":"11450007147","pt":1717317025166,"mc":[{"id":"1.229554895","rc":[{"atb":[[1.49,0.28]],"id":63161712}],"con":true,"img":false}]}
{"op":"mcm","clk":"11450007203","pt":1717317025785,"mc":[{"id":"1.229554895","rc":[{"atb":[[1.47,0]],"id":63161712},{"atb":[[2.3,0]],"id":65732558}],"con":true,"img":false}]}
{"op":"mcm","clk":"11450007234","pt":1717317026097,"mc":[{"id":"1.229554895","rc":[{"atb":[[6.8,17.24],[5.6,0]],"id":58069703},{"atl":[[95,2],[110,0],[1000,21.92]],"id":58069703},{"atl":[[550,2],[580,0.36]],"id":50605162},{"atb":[[1.9,0]],"id":65732558}],"con":true,"img":false}]}
{"op":"mcm","clk":"11450007244","pt":1717317026202,"mc":[{"id":"1.229554895","rc":[{"atl":[[65,2.02]],"id":58069703},{"atb":[[2.32,4],[2.26,0]],"id":65732558},{"atl":[[5.8,20.79],[6.6,0]],"id":65732558},{"atl":[[80,6.61],[90,0]],"id":61028210}],"con":true,"img":false}]}
{"op":"mcm","clk":"11450007254","pt":1717317026256,"mc":[{"id":"1.229554895","rc":[{"atb":[[2.32,2],[2.28,2.99]],"id":65732558},{"atl":[[80,2.61],[90,4]],"id":61028210}],"con":true,"img":false}]}
{"op":"mcm","clk":"11450007452","pt":1717317028387,"mc":[{"id":"1.229554895","rc":[{"atb":[[2.34,2.73]],"id":65732558}],"con":true,"img":false}]}
{"op":"mcm","clk":"11450007574","pt":1717317029672,"mc":[{"id":"1.229554895","rc":[{"atl":[[1.99,0]],"id":63161712}],"con":true,"img":false}]}
{"op":"mcm","clk":"11450007685","pt":1717317030867,"mc":[{"id":"1.229554895","rc":[{"atl":[[2.66,2.61]],"id":63161712}],"con":true,"img":false}]}
{"op":"mcm","clk":"11450007706","pt":1717317031072,"mc":[{"id":"1.229554895","rc":[{"atb":[[2.32,0]],"id":65732558}],"con":true,"img":false}]}
{"op":"mcm","clk":"11450007718","pt":1717317031179,"mc":[{"id":"1.229554895","rc":[{"atb":[[2.36,2]],"id":65732558}],"con":true,"img":false}]}
{"op":"mcm","clk":"11450007744","pt":1717317031383,"mc":[{"id":"1.229554895","rc":[{"atl":[[80,4.61],[90,2]],"id":61028210}],"con":true,"img":false}]}
{"op":"mcm","clk":"11450007756","pt":1717317031487,"mc":[{"id":"1.229554895","rc":[{"atl":[[80,2.61],[90,4]],"id":61028210}],"con":true,"img":false}]}
{"op":"mcm","clk":"11450007767","pt":1717317031597,"mc":[{"id":"1.229554895","rc":[{"atl":[[80,4.61],[90,2]],"id":61028210}],"con":true,"img":false}]}
{"op":"mcm","clk":"11450007777","pt":1717317031700,"mc":[{"id":"1.229554895","rc":[{"atb":[[19.5,0.02]],"id":58069703}],"con":true,"img":false}]}
{"op":"mcm","clk":"11450007787","pt":1717317031803,"mc":[{"id":"1.229554895","rc":[{"atb":[[1.46,0]],"id":63161712}],"con":true,"img":false}]}
{"op":"mcm","clk":"11450007807","pt":1717317031965,"mc":[{"id":"1.229554895","rc":[{"atb":[[2.28,2.62]],"id":65732558}],"con":true,"img":false}]}
{"op":"mcm","clk":"11450007816","pt":1717317032075,"mc":[{"id":"1.229554895","rc":[{"atb":[[55,0.4]],"id":50605162}],"con":true,"img":false}]}
{"op":"mcm","clk":"11450007834","pt":1717317032271,"mc":[{"id":"1.229554895","rc":[{"atb":[[1.03,7.66]],"id":63161712},{"atb":[[23,0]],"id":58069703}],"con":true,"img":false}]}
{"op":"mcm","clk":"11450007844","pt":1717317032375,"mc":[{"id":"1.229554895","rc":[{"atb":[[1.02,1.7]],"id":65732558}],"con":true,"img":false}]}
{"op":"mcm","clk":"11450007867","pt":1717317032585,"mc":[{"id":"1.229554895","rc":[{"atb":[[1.4,1.7]],"id":50605162}],"con":true,"img":false}]}
{"op":"mcm","clk":"11450007876","pt":1717317032686,"mc":[{"id":"1.229554895","rc":[{"atb":[[13.5,0]],"id":61028210}],"con":true,"img":false}]}
{"op":"mcm","clk":"11450007889","pt":1717317032789,"mc":[{"id":"1.229554895","rc":[{"atb":[[1.02,11.3]],"id":58069703}],"con":true,"img":false}]}
{"op":"mcm","clk":"11450007898","pt":1717317032890,"mc":[{"id":"1.229554895","rc":[{"atl":[[65,2]],"id":58069703}],"con":true,"img":false}]}
{"op":"mcm","clk":"11450007926","pt":1717317033202,"mc":[{"id":"1.229554895","rc":[{"atb":[[1.03,6.55]],"id":63161712},{"atb":[[1.02,0.35]],"id":65732558}],"con":true,"img":false}]}
{"op":"mcm","clk":"11450007942","pt":1717317033361,"mc":[{"id":"1.229554895","rc":[{"atb":[[1.4,0.01]],"id":50605162}],"con":true,"img":false}]}
{"op":"mcm","clk":"11450007950","pt":1717317033465,"mc":[{"id":"1.229554895","rc":[{"atb":[[1.12,1.7]],"id":61028210}],"con":true,"img":false}]}
{"op":"mcm","clk":"11450007960","pt":1717317033566,"mc":[{"id":"1.229554895","rc":[{"atb":[[1.02,9.34]],"id":58069703},{"atb":[[2.34,0.17]],"id":65732558}],"con":true,"img":false}]}
{"op":"mcm","clk":"11450007968","pt":1717317033667,"mc":[{"id":"1.229554895","rc":[{"atl":[[80,6.61]],"id":61028210}],"con":true,"img":false}]}
{"op":"mcm","clk":"11450007976","pt":1717317033778,"mc":[{"id":"1.229554895","rc":[{"atb":[[1.03,5.96]],"id":63161712},{"atb":[[2.36,4],[2.28,0]],"id":65732558},{"atl":[[90,0]],"id":61028210}],"con":true,"img":false}]}
{"op":"mcm","clk":"11450007985","pt":1717317033874,"mc":[{"id":"1.229554895","rc":[{"atb":[[1.45,0.58]],"id":63161712},{"atb":[[2.36,2],[2.28,2.62]],"id":65732558}],"con":true,"img":false}]}
{"op":"mcm","clk":"11450007991","pt":1717317033981,"mc":[{"id":"1.229554895","rc":[{"atb":[[2.36,4.62],[2.28,0]],"id":65732558}],"con":true,"img":false}]}
{"op":"mcm","clk":"11450008000","pt":1717317034081,"mc":[{"id":"1.229554895","rc":[{"atb":[[1.1,1]],"id":63161712},{"atb":[[1.02,8.94]],"id":58069703},{"atb":[[2.36,2],[2.28,2.62]],"id":65732558}],"con":true,"img":false}]}
{"op":"mcm","clk":"11450008008","pt":1717317034185,"mc":[{"id":"1.229554895","rc":[{"atb":[[23,0.39]],"id":58069703},{"atb":[[2.36,2.62],[1.02,0],[2.28,0]],"id":65732558}],"con":true,"img":false}]}
{"op":"mcm","clk":"11450008017","pt":1717317034285,"mc":[{"id":"1.229554895","rc":[{"atb":[[1.1,0.2]],"id":63161712},{"atb":[[2.3,2],[2.36,0],[2.38,0.35],[2.28,2.62]],"id":65732558}],"con":true,"img":false}]}
{"op":"mcm","clk":"11450008028","pt":1717317034389,"mc":[{"id":"1.229554895","rc":[{"atb":[[2.26,6.77],[2.28,0]],"id":65732558}],"con":true,"img":false}]}
{"op":"mcm","clk":"11450008034","pt":1717317034490,"mc":[{"id":"1.229554895","rc":[{"atb":[[1.1,0]],"id":63161712},{"atb":[[2.32,2.62],[2.26,0]],"id":65732558}],"con":true,"img":false}]}
{"op":"mcm","clk":"11450008043","pt":1717317034595,"mc":[{"id":"1.229554895","rc":[{"atb":[[1.48,2.2]],"id":63161712},{"atb":[[1.4,0]],"id":50605162}],"con":true,"img":false}]}
{"op":"mcm","clk":"11450008053","pt":1717317034698,"mc":[{"id":"1.229554895","rc":[{"atb":[[55,0.41]],"id":50605162}],"con":true,"img":false}]}
{"op":"mcm","clk":"11450008071","pt":1717317034857,"mc":[{"id":"1.229554895","rc":[{"atb":[[1.12,0.05]],"id":61028210}],"con":true,"img":false}]}
{"op":"mcm","clk":"11450008079","pt":1717317035006,"mc":[{"id":"1.229554895","rc":[{"atb":[[1.48,2]],"id":63161712}],"con":true,"img":false}]}
{"op":"mcm","clk":"11450008088","pt":1717317035059,"mc":[{"id":"1.229554895","rc":[{"atl":[[1000,2.7]],"id":65732558}],"con":true,"img":false}]}
{"op":"mcm","clk":"11450008122","pt":1717317035473,"mc":[{"id":"1.229554895","rc":[{"atb":[[1.12,0]],"id":61028210}],"con":true,"img":false}]}
{"op":"mcm","clk":"11450008131","pt":1717317035576,"mc":[{"id":"1.229554895","rc":[{"atb":[[13.5,0.05]],"id":61028210}],"con":true,"img":false}]}
{"op":"mcm","clk":"11450008179","pt":1717317035992,"mc":[{"id":"1.229554895","rc":[{"atl":[[1000,1.09]],"id":65732558}],"con":true,"img":false}]}
{"op":"mcm","clk":"11450008205","pt":1717317036300,"mc":[{"id":"1.229554895","rc":[{"atb":[[2.34,2.73]],"id":65732558},{"atl":[[1000,1]],"id":65732558}],"con":true,"img":false}]}
{"op":"mcm","clk":"11450008213","pt":1717317036352,"mc":[{"id":"1.229554895","rc":[{"atl":[[4.4,0.28]],"id":65732558}],"con":true,"img":false}]}
{"op":"mcm","clk":"11450008229","pt":1717317036560,"mc":[{"id":"1.229554895","rc":[{"atl":[[1000,2.88]],"id":61028210}],"con":true,"img":false}]}
{"op":"mcm","clk":"11450008240","pt":1717317036662,"mc":[{"id":"1.229554895","rc":[{"atb":[[2.3,0]],"id":65732558}],"con":true,"img":false}]}
{"op":"mcm","clk":"11450008251","pt":1717317036766,"mc":[{"id":"1.229554895","rc":[{"atb":[[2.34,4.73]],"id":65732558}],"con":true,"img":false}]}
{"op":"mcm","clk":"11450008266","pt":1717317036870,"mc":[{"id":"1.229554895","rc":[{"atb":[[2.32,0],[2.36,2.62]],"id":65732558}],"con":true,"img":false}]}
{"op":"mcm","clk":"11450008287","pt":1717317037078,"mc":[{"id":"1.229554895","rc":[{"atl":[[1000,1.18]],"id":61028210}],"con":true,"img":false}]}
{"op":"mcm","clk":"11450008329","pt":1717317037490,"mc":[{"id":"1.229554895","rc":[{"atl":[[1000,1.17]],"id":61028210}],"con":true,"img":false}]}
{"op":"mcm","clk":"11450008337","pt":1717317037593,"mc":[{"id":"1.229554895","rc":[{"atl":[[75,0.01]],"id":61028210}],"con":true,"img":false}]}
{"op":"mcm","clk":"11450008477","pt":1717317038989,"mc":[{"id":"1.229554895","rc":[{"atb":[[2.34,2.17]],"id":65732558}],"con":true,"img":false}]}
{"op":"mcm","clk":"11450008503","pt":1717317039296,"mc":[{"id":"1.229554895","rc":[{"atb":[[1.2,0.78]],"id":63161712},{"atb":[[2.34,0.17]],"id":65732558}],"con":true,"img":false}]}
{"op":"mcm","clk":"11450008513","pt":1717317039397,"mc":[{"id":"1.229554895","rc":[{"atb":[[2.38,2.35]],"id":65732558}],"con":true,"img":false}]}
{"op":"mcm","clk":"11450008520","pt":1717317039499,"mc":[{"id":"1.229554895","rc":[{"atb":[[2.34,3.15],[2.36,0]],"id":65732558}],"con":true,"img":false}]}
{"op":"mcm","clk":"11450008525","pt":1717317039603,"mc":[{"id":"1.229554895","rc":[{"atb":[[2.38,4.97],[2.34,0.17]],"id":65732558},{"atl":[[4.4,0.09]],"id":65732558}],"con":true,"img":false}]}
{"op":"mcm","clk":"11450008538","pt":1717317039760,"mc":[{"id":"1.229554895","rc":[{"atb":[[1.2,0.25]],"id":63161712}],"con":true,"img":false}]}
{"op":"mcm","clk":"11450008547","pt":1717317039866,"mc":[{"id":"1.229554895","rc":[{"atl":[[75,0]],"id":61028210}],"con":true,"img":false}]}
{"op":"mcm","clk":"11450008573","pt":1717317040174,"mc":[{"id":"1.229554895","rc":[{"atb":[[1.2,0]],"id":63161712}],"con":true,"img":false}]}
{"op":"mcm","clk":"11450008582","pt":1717317040278,"mc":[{"id":"1.229554895","rc":[{"atb":[[1.49,0.54]],"id":63161712}],"con":true,"img":false}]}
{"op":"mcm","clk":"11450008601","pt":1717317040588,"mc":[{"id":"1.229554895","rc":[{"atl":[[1000,2.7]],"id":65732558}],"con":true,"img":false}]}
{"op":"mcm","clk":"11450008609","pt":1717317040693,"mc":[{"id":"1.229554895","rc":[{"atb":[[2.36,1.8]],"id":65732558},{"atl":[[1000,2.88]],"id":61028210}],"con":true,"img":false}]}
{"op":"mcm","clk":"11450008698","pt":1717317041674,"mc":[{"id":"1.229554895","rc":[{"atl":[[1000,1.18]],"id":61028210}],"con":true,"img":false}]}
{"op":"mcm","clk":"11450008758","pt":1717317042409,"mc":[{"id":"1.229554895","rc":[{"atl":[[1000,1.19]],"id":65732558}],"con":true,"img":false}]}
{"op":"mcm","clk":"11450008768","pt":1717317042506,"mc":[{"id":"1.229554895","rc":[{"atb":[[1.1,1]],"id":63161712}],"con":true,"img":false}]}
{"op":"mcm","clk":"11450008785","pt":1717317042716,"mc":[{"id":"1.229554895","rc":[{"atb":[[1.1,0.2]],"id":63161712}],"con":true,"img":false}]}
{"op":"mcm","clk":"11450008795","pt":1717317042773,"mc":[{"id":"1.229554895","rc":[{"atl":[[1000,1.17]],"id":61028210}],"con":true,"img":false}]}
{"op":"mcm","clk":"11450008805","pt":1717317042876,"mc":[{"id":"1.229554895","rc":[{"atb":[[1.1,0]],"id":63161712},{"atl":[[75,0.01]],"id":61028210}],"con":true,"img":false}]}
{"op":"mcm","clk":"11450008816","pt":1717317042979,"mc":[{"id":"1.229554895","rc":[{"atb":[[1.48,2.2]],"id":63161712},{"atl":[[2.98,0]],"id":63161712}],"con":true,"img":false}]}
{"op":"mcm","clk":"11450008828","pt":1717317043081,"mc":[{"id":"1.229554895","rc":[{"atl":[[2.78,71.67]],"id":63161712}],"con":true,"img":false}]}
{"op":"mcm","clk":"11450008837","pt":1717317043185,"mc":[{"id":"1.229554895","rc":[{"atl":[[1000,1]],"id":65732558}],"con":true,"img":false}]}
{"op":"mcm","clk":"11450008851","pt":1717317043288,"mc":[{"id":"1.229554895","rc":[{"atl":[[4.4,0.28]],"id":65732558}],"con":true,"img":false}]}
{"op":"mcm","clk":"11450008865","pt":1717317043392,"mc":[{"id":"1.229554895","rc":[{"atl":[[2.66,8.21]],"id":63161712}],"con":true,"img":false}]}
{"op":"mcm","clk":"11450009440","pt":1717317048890,"mc":[{"id":"1.229554895","rc":[{"atb":[[2.36,0]],"id":65732558}],"con":true,"img":false}]}
{"op":"mcm","clk":"11450009669","pt":1717317050812,"mc":[{"id":"1.229554895","rc":[{"atb":[[1.48,2]],"id":63161712}],"con":true,"img":false}]}
{"op":"mcm","clk":"11450009690","pt":1717317051017,"mc":[{"id":"1.229554895","rc":[{"atb":[[1.1,1]],"id":63161712}],"con":true,"img":false}]}
{"op":"mcm","clk":"11450009710","pt":1717317051225,"mc":[{"id":"1.229554895","rc":[{"atb":[[1.1,0.2]],"id":63161712}],"con":true,"img":false}]}
{"op":"mcm","clk":"11450009736","pt":1717317051435,"mc":[{"id":"1.229554895","rc":[{"atb":[[1.1,0]],"id":63161712}],"con":true,"img":false}]}
{"op":"mcm","clk":"11450009748","pt":1717317051490,"mc":[{"id":"1.229554895","rc":[{"atb":[[1.48,2.2]],"id":63161712}],"con":true,"img":false}]}
{"op":"mcm","clk":"11450009893","pt":1717317053000,"mc":[{"id":"1.229554895","rc":[{"atb":[[11,0],[13,15.84]],"id":61028210}],"con":true,"img":false}]}
{"op":"mcm","clk":"11450010102","pt":1717317055325,"mc":[{"id":"1.229554895","rc":[{"atb":[[2.38,9.46]],"id":65732558}],"con":true,"img":false}]}
{"op":"mcm","clk":"11450010319","pt":1717317057912,"mc":[{"id":"1.229554895","rc":[{"atb":[[1.9,11.57]],"id":65732558}],"con":true,"img":false}]}
{"op":"mcm","clk":"11450010436","pt":1717317059208,"mc":[{"id":"1.229554895","rc":[{"atb":[[1.48,2]],"id":63161712}],"con":true,"img":false}]}
{"op":"mcm","clk":"11450010459","pt":1717317059414,"mc":[{"id":"1.229554895","rc":[{"atb":[[1.1,1]],"id":63161712}],"con":true,"img":false}]}
{"op":"mcm","clk":"11450010476","pt":1717317059627,"mc":[{"id":"1.229554895","rc":[{"atb":[[1.1,0.2]],"id":63161712}],"con":true,"img":false}]}
{"op":"mcm","clk":"11450010486","pt":1717317059730,"mc":[{"id":"1.229554895","rc":[{"atb":[[1.1,0]],"id":63161712}],"con":true,"img":false}]}
{"op":"mcm","clk":"11450010494","pt":1717317059824,"mc":[{"id":"1.229554895","rc":[{"atb":[[1.48,2.2]],"id":63161712}],"con":true,"img":false}]}
{"op":"mcm","clk":"11450010555","pt":1717317060410,"mc":[{"id":"1.229554895","rc":[{"atb":[[23,1.25]],"id":58069703},{"atl":[[80,0.26]],"id":58069703},{"atb":[[13.5,1.68]],"id":61028210},{"atl":[[75,0.26]],"id":61028210}],"con":true,"img":false}]}
{"op":"mcm","clk":"11450010589","pt":1717317060728,"mc":[{"id":"1.229554895","rc":[{"atl":[[4.5,2.96]],"id":65732558}],"con":true,"img":false}]}
{"op":"mcm","clk":"11450010860","pt":1717317063340,"mc":[{"id":"1.229554895","rc":[{"atl":[[2.66,2.61]],"id":63161712}],"con":true,"img":false}]}
{"op":"mcm","clk":"11450011381","pt":1717317068429,"mc":[{"id":"1.229554895","rc":[{"atb":[[1.37,21.21]],"id":63161712}],"con":true,"img":false}]}
{"op":"mcm","clk":"11450012020","pt":1717317075010,"mc":[{"id":"1.229554895","rc":[{"spn":1.73,"spf":"NaN","id":63161712},{"spn":44.0,"spf":"NaN","id":58069703},{"spn":267.5,"spf":"NaN","id":50605162},{"spn":3.39,"spf":"NaN","id":65732558},{"atb":[[14.5,2.18]],"id":61028210},{"spn":44.75,"spf":"NaN","id":61028210}],"con":true,"img":false}]}
{"op":"mcm","clk":"11450012304","pt":1717317077236,"mc":[{"id":"1.229554895","rc":[{"atb":[[14,0]],"id":61028210}],"con":true,"img":false}]}
{"op":"mcm","clk":"11450012344","pt":1717317077549,"mc":[{"id":"1.229554895","rc":[{"atb":[[1.17,100]],"id":58069703},{"atb":[[1.17,100]],"id":50605162},{"atb":[[1.17,100]],"id":61028210}],"con":true,"img":false}]}
{"op":"mcm","clk":"11450012751","pt":1717317081531,"mc":[{"id":"1.229554895","rc":[{"atb":[[1.48,2]],"id":63161712}],"con":true,"img":false}]}
{"op":"mcm","clk":"11450012917","pt":1717317083024,"mc":[{"id":"1.229554895","rc":[{"atb":[[1.38,0]],"id":63161712}],"con":true,"img":false}]}
{"op":"mcm","clk":"11450012923","pt":1717317083125,"mc":[{"id":"1.229554895","rc":[{"atb":[[1.36,75.17]],"id":63161712}],"con":true,"img":false}]}
{"op":"mcm","clk":"11450013405","pt":1717317088527,"mc":[{"id":"1.229554895","rc":[{"atb":[[1.1,1]],"id":63161712}],"con":true,"img":false}]}
{"op":"mcm","clk":"11450013424","pt":1717317088730,"mc":[{"id":"1.229554895","rc":[{"atb":[[1.1,0.2]],"id":63161712}],"con":true,"img":false}]}
{"op":"mcm","clk":"11450013441","pt":1717317088937,"mc":[{"id":"1.229554895","rc":[{"atb":[[1.1,0]],"id":63161712}],"con":true,"img":false}]}
{"op":"mcm","clk":"11450013450","pt":1717317089040,"mc":[{"id":"1.229554895","rc":[{"atb":[[1.48,2.2]],"id":63161712}],"con":true,"img":false}]}
{"op":"mcm","clk":"11450013539","pt":1717317089927,"mc":[{"id":"1.229554895","rc":[{"atl":[[60,1.26]],"id":58069703}],"con":true,"img":false}]}
{"op":"mcm","clk":"11450013550","pt":1717317090027,"mc":[{"id":"1.229554895","rc":[{"atl":[[4.4,1.55]],"id":65732558}],"con":true,"img":false}]}
{"op":"mcm","clk":"11450013561","pt":1717317090131,"mc":[{"id":"1.229554895","rc":[{"atl":[[1.97,1.26]],"id":63161712}],"con":true,"img":false}]}
{"op":"mcm","clk":"11450013566","pt":1717317090232,"mc":[{"id":"1.229554895","rc":[{"atl":[[75,1.53]],"id":61028210}],"con":true,"img":false}]}
{"op":"mcm","clk":"11450013576","pt":1717317090335,"mc":[{"id":"1.229554895","rc":[{"atl":[[540,1.26]],"id":50605162}],"con":true,"img":false}]}
{"op":"mcm","clk":"11450013590","pt":1717317090443,"mc":[{"id":"1.229554895","rc":[{"atl":[[540,3.26]],"id":50605162}],"con":true,"img":false}]}
{"op":"mcm","clk":"11450013600","pt":1717317090541,"mc":[{"id":"1.229554895","rc":[{"atl":[[990,2.17],[1000,1]],"id":50605162}],"con":true,"img":false}]}
{"op":"mcm","clk":"11450013612","pt":1717317090646,"mc":[{"id":"1.229554895","rc":[{"atl":[[540,1.26]],"id":50605162}],"con":true,"img":false}]}
{"op":"mcm","clk":"11450013619","pt":1717317090749,"mc":[{"id":"1.229554895","rc":[{"atl":[[540,3.26]],"id":50605162}],"con":true,"img":false}]}
{"op":"mcm","clk":"11450013632","pt":1717317090850,"mc":[{"id":"1.229554895","rc":[{"atl":[[990,0.17]],"id":50605162}],"con":true,"img":false}]}
{"op":"mcm","clk":"11450013673","pt":1717317091267,"mc":[{"id":"1.229554895","rc":[{"atl":[[2.66,6.95]],"id":63161712}],"con":true,"img":false}]}
{"op":"mcm","clk":"11450013990","pt":1717317094720,"mc":[{"id":"1.229554895","rc":[{"atb":[[1.37,0]],"id":63161712}],"con":true,"img":false}]}
{"op":"mcm","clk":"11450014389","pt":1717317099052,"mc":[{"id":"1.229554895","rc":[{"atb":[[1.07,175.17]],"id":63161712},{"atl":[[95,0],[120,2]],"id":58069703},{"atl":[[530,2],[550,0]],"id":50605162},{"atb":[[1.9,0]],"id":65732558},{"atl":[[5.3,29.07],[4.9,27.2],[5.1,18.29],[4.7,5.41]],"id":65732558}],"con":true,"img":false}]}
{"op":"mcm","clk":"11450014394","pt":1717317099149,"mc":[{"id":"1.229554895","rc":[{"atb":[[1.38,4.34]],"id":63161712}],"con":true,"img":false}]}
{"op":"mcm","clk":"11450014413","pt":1717317099363,"mc":[{"id":"1.229554895","rc":[{"atl":[[2.54,33.01],[3.45,0],[2.66,2.61]],"id":63161712},{"atb":[[5.2,23.81],[6.6,0]],"id":50605162}],"con":true,"img":false}]}
{"op":"mcm","clk":"11450014422","pt":1717317099461,"mc":[{"id":"1.229554895","rc":[{"atb":[[6.8,0],[8.4,13.51]],"id":58069703},{"atb":[[3.55,0],[4.4,24.39]],"id":61028210}],"con":true,"img":false}]}
{"op":"mcm","clk":"11450016048","pt":1717317117595,"mc":[{"id":"1.229554895","rc":[{"atb":[[23,1.93]],"id":58069703},{"atb":[[1.03,2.35]],"id":50605162}],"con":true,"img":false}]}
{"op":"mcm","clk":"11450016071","pt":1717317117754,"mc":[{"id":"1.229554895","rc":[{"atb":[[1.01,20.25]],"id":61028210}],"con":true,"img":false}]}
{"op":"mcm","clk":"11450016080","pt":1717317117856,"mc":[{"id":"1.229554895","rc":[{"atb":[[2.38,14.4]],"id":65732558}],"con":true,"img":false}]}
