{"op":"mcm","clk":"11449075380","pt":1717303241522,"mc":[{"id":"1.229554892","marketDefinition":{"bspMarket":false,"turnInPlayEnabled":false,"persistenceEnabled":false,"marketBaseRate":7.0,"eventId":"33318908","eventTypeId":"4339","numberOfWinners":1,"bettingType":"ODDS","marketType":"EXACTA","marketTime":"2024-06-02T08:21:00.000Z","suspendTime":"2024-06-02T08:21:00.000Z","bspReconciled":false,"complete":true,"inPlay":false,"crossMatching":true,"runnersVoidable":false,"numberOfActiveRunners":20,"betDelay":0,"status":"OPEN","runners":[{"status":"ACTIVE","sortPriority":1,"id":52385882,"name":"1 - 2"},{"status":"ACTIVE","sortPriority":2,"id":52385884,"name":"1 - 4"},{"status":"ACTIVE","sortPriority":3,"id":52385886,"name":"1 - 6"},{"status":"ACTIVE","sortPriority":4,"id":52385888,"name":"1 - 8"},{"status":"ACTIVE","sortPriority":5,"id":52385889,"name":"2 - 1"},{"status":"ACTIVE","sortPriority":6,"id":52385891,"name":"2 - 4"},{"status":"ACTIVE","sortPriority":7,"id":52385893,"name":"2 - 6"},{"status":"ACTIVE","sortPriority":8,"id":52385895,"name":"2 - 8"},{"status":"ACTIVE","sortPriority":9,"id":52385903,"name":"4 - 1"},{"status":"ACTIVE","sortPriority":10,"id":52385904,"name":"4 - 2"},{"status":"ACTIVE","sortPriority":11,"id":52385907,"name":"4 - 6"},{"status":"ACTIVE","sortPriority":12,"id":52385909,"name":"4 - 8"},{"status":"ACTIVE","sortPriority":13,"id":52385917,"name":"6 - 1"},{"status":"ACTIVE","sortPriority":14,"id":52385918,"name":"6 - 2"},{"status":"ACTIVE","sortPriority":15,"id":52385920,"name":"6 - 4"},{"status":"ACTIVE","sortPriority":16,"id":52385923,"name":"6 - 8"},{"status":"ACTIVE","sortPriority":17,"id":52385931,"name":"8 - 1"},{"status":"ACTIVE","sortPriority":18,"id":52385932,"name":"8 - 2"},{"status":"ACTIVE","sortPriority":19,"id":52385934,"name":"8 - 4"},{"status":"ACTIVE","sortPriority":20,"id":52385936,"name":"8 - 6"}],"regulators":["MR_INT"],"venue":"Murray Bridge","countryCode":"AU","discountAllowed":true,"timezone":"Australia/Adelaide","openDate":"2024-06-02T08:21:00.000Z","version":5962801922,"name":"Exacta","eventName":"Murray Bridge (AUS) 2nd Jun"},"rc":[],"con":true,"img":false}]}
{"op":"mcm","clk":"11449094250","pt":1717303691304,"mc":[{"id":"1.229554892","rc":[{"atb":[[70,0.38],[38,2.12],[48,1.11],[29,3.74]],"id":52385907},{"atb":[[6.4,4.84],[5.2,18.68],[5.7,11.13],[4.7,28.28]],"id":52385909},{"atb":[[560,0.14],[610,0.08],[660,0.04],[510,0.2]],"id":52385886},{"atb":[[85,0.62],[44,2.43],[120,0.22],[60,1.33]],"id":52385918},{"atb":[[34,2.38],[44,1.22],[27,4.02],[60,0.44]],"id":52385888},{"atb":[[150,0.18],[75,1.06],[100,0.53],[50,2.13]],"id":52385920},{"atb":[[16,6.97],[18.5,4.48],[22,2.49],[27,1]],"id":52385889},{"atb":[[32,2.53],[42,1.28],[26,4.19],[55,0.49]],"id":52385882},{"atb":[[65,0.41],[36,2.24],[46,1.16],[28,3.88]],"id":52385884},{"atb":[[610,0.17],[660,0.12],[710,0.07],[760,0.04]],"id":52385917},{"atb":[[3.6,40.24],[3.85,27.54],[4.2,16.35],[4.7,7.07]],"id":52385895},{"atb":[[140,0.19],[70,1.14],[95,0.55],[48,2.23]],"id":52385923},{"atb":[[4,26.16],[4.5,14.95],[5,6.54],[3.75,38.05]],"id":52385891},{"atb":[[32,2.53],[42,1.28],[26,4.19],[55,0.49]],"id":52385893},{"atb":[[4.5,29.89],[5,19.62],[5.5,11.63],[6,5.23]],"id":52385934},{"atb":[[36,0.75],[19,5.81],[23,3.57],[28,1.94]],"id":52385903},{"atb":[[65,0.41],[36,2.24],[46,1.16],[28,3.88]],"id":52385936},{"atb":[[5.6,5.69],[5.1,12.76],[4.6,21.8],[4.1,33.76]],"id":52385904},{"atb":[[32,0.84],[18,6.15],[21,3.92],[26,2.09]],"id":52385931},{"atb":[[4,26.16],[4.5,14.95],[5,6.54],[3.75,38.05]],"id":52385932}],"con":true,"img":false}]}
{"op":"mcm","clk":"11449095056","pt":1717303714149,"mc":[{"id":"1.229554892","rc":[{"atb":[[70,0.76],[38,4.24],[48,2.23],[29,7.48]],"id":52385907},{"atb":[[6.4,9.69],[5.2,37.37],[5.7,22.27],[4.7,56.56]],"id":52385909},{"atb":[[560,0.29],[610,0.17],[660,0.09],[510,0.41]],"id":52385886},{"atb":[[85,1.25],[44,4.87],[120,0.44],[60,2.66]],"id":52385918},{"atb":[[34,4.77],[44,2.44],[27,8.05],[60,0.89]],"id":52385888},{"atb":[[150,0.36],[75,2.13],[100,1.06],[50,4.27]],"id":52385920},{"atb":[[16,13.95],[18.5,8.97],[22,4.99],[27,2.01]],"id":52385889},{"atb":[[32,5.07],[42,2.56],[26,8.38],[55,0.98]],"id":52385882},{"atb":[[610,0.35],[660,0.25],[710,0.15],[760,0.08]],"id":52385917},{"atb":[[3.6,80.49],[3.85,55.08],[4.2,32.7],[4.7,14.14]],"id":52385895},{"atb":[[140,0.38],[70,2.28],[95,1.11],[48,4.46]],"id":52385923},{"atb":[[4,52.32],[4.5,29.9],[5,13.08],[3.75,76.11]],"id":52385891},{"atb":[[32,5.07],[42,2.56],[26,8.38],[55,0.98]],"id":52385893},{"atb":[[36,1.5],[19,11.63],[23,7.14],[28,3.88]],"id":52385903},{"atb":[[65,0.82],[36,4.49],[46,2.33],[28,7.76]],"id":52385936},{"atb":[[5.6,11.38],[5.1,25.53],[4.6,43.61],[4.1,67.52]],"id":52385904},{"atb":[[4,52.32],[4.5,29.9],[5,13.08],[3.75,76.11]],"id":52385932}],"con":true,"img":false}]}
{"op":"mcm","clk":"11449095079","pt":1717303714930,"mc":[{"id":"1.229554892","rc":[{"atb":[[70,0.38],[38,2.12],[48,1.11],[29,3.74]],"id":52385907},{"atb":[[6.4,4.84],[5.2,18.68],[5.7,11.13],[4.7,28.28]],"id":52385909},{"atb":[[560,0.14],[610,0.08],[660,0.04],[510,0.2]],"id":52385886},{"atb":[[85,0.62],[44,2.43],[120,0.22],[60,1.33]],"id":52385918},{"atb":[[150,0.18],[75,1.06],[100,0.53],[50,2.13]],"id":52385920},{"atb":[[34,2.38],[44,1.22],[27,4.02],[60,0.44]],"id":52385888},{"atb":[[16,6.97],[18.5,4.48],[22,2.49],[27,1]],"id":52385889},{"atb":[[32,2.53],[42,1.28],[26,4.19],[55,0.49]],"id":52385882},{"atb":[[610,0.17],[660,0.12],[710,0.07],[760,0.04]],"id":52385917},{"atb":[[3.6,40.24],[3.85,27.54],[4.2,16.35],[4.7,7.07]],"id":52385895},{"atb":[[140,0.19],[70,1.14],[95,0.55],[48,2.23]],"id":52385923},{"atb":[[4,26.16],[4.5,14.95],[5,6.54],[3.75,38.05]],"id":52385891},{"atb":[[32,2.53],[42,1.28],[26,4.19],[55,0.49]],"id":52385893},{"atb":[[36,0.75],[19,5.81],[23,3.57],[28,1.94]],"id":52385903},{"atb":[[65,0.41],[36,2.24],[46,1.16],[28,3.88]],"id":52385936},{"atb":[[5.6,5.69],[5.1,12.76],[4.6,21.8],[4.1,33.76]],"id":52385904},{"atb":[[4,26.16],[4.5,14.95],[5,6.54],[3.75,38.05]],"id":52385932}],"con":true,"img":false}]}
{"op":"mcm","clk":"11449099376","pt":1717303849458,"mc":[{"id":"1.229554892","rc":[{"atb":[[550,0.44],[650,0.16]],"id":52385886},{"atb":[[10.5,25.67],[15.5,7.2]],"id":52385888},{"atb":[[12,9.5],[8.8,31.27]],"id":52385889},{"atb":[[10,27.1],[15,7.46]],"id":52385882},{"atb":[[16,6.96],[11,24.39]],"id":52385884},{"atb":[[2.92,127.03],[3.3,45.44]],"id":52385895},{"atb":[[3.4,43.55],[2.96,124.44]],"id":52385891},{"atb":[[18.5,5.97],[13.5,19.51]],"id":52385893},{"atb":[[9.6,28.36],[14,8.04]],"id":52385903},{"atb":[[3.55,40.99],[3.05,118.97]],"id":52385904}],"con":true,"img":false}]}
{"op":"mcm","clk":"11449099382","pt":1717303849562,"mc":[{"id":"1.229554892","rc":[{"atb":[[21,5.22],[15.5,16.82]],"id":52385907},{"atb":[[3.25,108.4],[3.75,38]],"id":52385909},{"atb":[[16.5,15.73],[23,4.75]],"id":52385918},{"atb":[[18,14.34],[26,4.18]],"id":52385920},{"atb":[[550,0.44],[650,0.16]],"id":52385917},{"atb":[[17.5,14.77],[25,4.35]],"id":52385923},{"atb":[[3.2,110.86],[3.7,38.71]],"id":52385934},{"atb":[[19.5,5.65],[14.5,18.06]],"id":52385936},{"atb":[[13.5,8.36],[9.4,29.03]],"id":52385931},{"atb":[[3.4,43.55],[2.96,124.44]],"id":52385932}],"con":true,"img":false}]}
{"op":"mcm","clk":"11449105852","pt":1717304053712,"mc":[{"id":"1.229554892","rc":[{"atb":[[3.6,0],[3.85,0],[4.2,0],[4.7,0]],"id":52385895}],"con":true,"img":false}]}
{"op":"mcm","clk":"11449105879","pt":1717304054382,"mc":[{"id":"1.229554892","rc":[{"atb":[[4,17.44],[4.5,7.48],[3.5,41.85],[3.75,28.54]],"id":52385895}],"con":true,"img":false}]}
{"op":"mcm","clk":"11449111956","pt":1717304219910,"mc":[{"id":"1.229554892","rc":[{"atb":[[4,0],[4.5,0],[5,0],[3.75,0]],"id":52385891},{"atb":[[5.6,0],[5.1,0],[4.6,0],[4.1,0]],"id":52385904}],"con":true,"img":false}]}
{"op":"mcm","clk":"11449113936","pt":1717304262370,"mc":[{"id":"1.229554892","rc":[{"atb":[[560,0],[610,0],[660,0],[510,0]],"id":52385886},{"atb":[[610,0],[660,0],[710,0],[760,0]],"id":52385917},{"atb":[[5.1,6.38],[4.6,14.53],[4.1,25.32],[3.8,37.37]],"id":52385891},{"atb":[[4.5,0],[5,0],[5.5,0],[6,0]],"id":52385934},{"atb":[[4.9,20.12],[4.4,30.77],[5.9,5.34],[5.4,11.89]],"id":52385904}],"con":true,"img":false}]}
{"op":"mcm","clk":"11449113987","pt":1717304263036,"mc":[{"id":"1.229554892","rc":[{"atb":[[530,0.15],[580,0.09],[630,0.04],[480,0.22]],"id":52385886},{"atb":[[580,0.18],[630,0.13],[680,0.08],[730,0.04]],"id":52385917}],"con":true,"img":false}]}
{"op":"mcm","clk":"11449131921","pt":1717304481642,"mc":[{"id":"1.229554892","rc":[{"atb":[[530,0],[580,0],[630,0],[480,0]],"id":52385886},{"atb":[[580,0],[630,0],[680,0],[730,0]],"id":52385917},{"atb":[[5.1,0],[4.6,0],[4.1,0],[3.8,0]],"id":52385891}],"con":true,"img":false}]}
{"op":"mcm","clk":"11449131952","pt":1717304482361,"mc":[{"id":"1.229554892","rc":[{"atb":[[560,0.14],[610,0.08],[660,0.04],[510,0.2]],"id":52385886},{"atb":[[610,0.17],[660,0.12],[710,0.07],[760,0.04]],"id":52385917},{"atb":[[4,26.16],[4.5,14.95],[5,6.54],[3.75,38.05]],"id":52385891}],"con":true,"img":false}]}
{"op":"mcm","clk":"11449170601","pt":1717305074617,"mc":[{"id":"1.229554892","rc":[{"atb":[[560,0],[610,0],[660,0],[510,0]],"id":52385886},{"atb":[[610,0],[660,0],[710,0],[760,0]],"id":52385917}],"con":true,"img":false}]}
{"op":"mcm","clk":"11449170651","pt":1717305075331,"mc":[{"id":"1.229554892","rc":[{"atb":[[530,0.15],[580,0.09],[630,0.04],[480,0.22]],"id":52385886},{"atb":[[580,0.18],[630,0.13],[680,0.08],[730,0.04]],"id":52385917}],"con":true,"img":false}]}
{"op":"mcm","clk":"11449212048","pt":1717305658056,"mc":[{"id":"1.229554892","rc":[{"atb":[[70,0],[38,0],[48,0],[29,0]],"id":52385907},{"atb":[[6.4,0],[5.2,0],[5.7,0],[4.7,0]],"id":52385909},{"atb":[[34,0],[44,0],[27,0],[60,0]],"id":52385888},{"atb":[[16,0],[18.5,0],[22,0],[27,0]],"id":52385889},{"atb":[[65,0],[36,0],[46,0],[28,0]],"id":52385884},{"atb":[[4,0],[4.5,0],[3.5,0],[3.75,0]],"id":52385895},{"atb":[[4,0],[4.5,0],[5,0],[3.75,0]],"id":52385891},{"atb":[[36,0],[19,0],[23,0],[28,0]],"id":52385903},{"atb":[[32,0],[18,0],[21,0],[26,0]],"id":52385931},{"atb":[[4,0],[4.5,0],[5,0],[3.75,0]],"id":52385932}],"con":true,"img":false}]}
{"op":"mcm","clk":"11449212108","pt":1717305658734,"mc":[{"id":"1.229554892","rc":[{"atb":[[75,0.36],[40,2.01],[50,1.07],[30,3.61]],"id":52385907},{"atb":[[4.8,27.54],[5.8,10.9],[5.3,18.25],[6.6,4.67]],"id":52385909},{"atb":[[65,0.41],[36,2.24],[46,1.16],[28,3.88]],"id":52385888},{"atb":[[18,4.61],[21,2.62],[26,1.05],[15.5,7.21]],"id":52385889},{"atb":[[3.45,42.71],[3.95,17.74],[3.7,29.07],[4.4,7.7]],"id":52385895},{"atb":[[4.8,6.89],[4.3,15.85],[3.9,27.06],[3.65,39.48]],"id":52385891},{"atb":[[40,0.67],[20,5.51],[25,3.27],[30,1.81]],"id":52385903},{"atb":[[4.8,6.89],[4.3,15.85],[3.9,27.06],[3.65,39.48]],"id":52385932}],"con":true,"img":false}]}
{"op":"mcm","clk":"11449212363","pt":1717305661635,"mc":[{"id":"1.229554892","rc":[{"atb":[[40,0],[20,0],[25,0],[30,0]],"id":52385903},{"atb":[[4.8,0],[4.3,0],[3.9,0],[3.65,0]],"id":52385932}],"con":true,"img":false}]}
{"op":"mcm","clk":"11449212425","pt":1717305662320,"mc":[{"id":"1.229554892","rc":[{"atb":[[38,0.71],[19.5,5.66],[24,3.41],[29,1.87]],"id":52385903},{"atb":[[3.95,26.6],[3.7,38.75],[4.9,6.71],[4.4,15.39]],"id":52385932}],"con":true,"img":false}]}
{"op":"mcm","clk":"11449222807","pt":1717305799206,"mc":[{"id":"1.229554892","rc":[{"atb":[[21,0],[15.5,0]],"id":52385907},{"atb":[[3.25,0],[3.75,0]],"id":52385909},{"atb":[[550,0],[650,0]],"id":52385886},{"atb":[[16.5,0],[23,0]],"id":52385918},{"atb":[[10.5,0],[15.5,0]],"id":52385888},{"atb":[[18,0],[26,0]],"id":52385920},{"atb":[[12,0],[8.8,0]],"id":52385889},{"atb":[[10,0],[15,0]],"id":52385882},{"atb":[[16,0],[11,0]],"id":52385884},{"atb":[[550,0],[650,0]],"id":52385917},{"atb":[[2.92,0],[3.3,0]],"id":52385895},{"atb":[[3.4,0],[2.96,0]],"id":52385891},{"atb":[[17.5,0],[25,0]],"id":52385923},{"atb":[[18.5,0],[13.5,0]],"id":52385893},{"atb":[[3.2,0],[3.7,0]],"id":52385934},{"atb":[[9.6,0],[14,0]],"id":52385903},{"atb":[[3.55,0],[3.05,0]],"id":52385904},{"atb":[[19.5,0],[14.5,0]],"id":52385936},{"atb":[[13.5,0],[9.4,0]],"id":52385931},{"atb":[[3.4,0],[2.96,0]],"id":52385932}],"con":true,"img":false}]}
{"op":"mcm","clk":"11449222984","pt":1717305801742,"mc":[{"id":"1.229554892","rc":[{"atb":[[65,0],[36,0],[46,0],[28,0]],"id":52385888},{"atb":[[18,0],[21,0],[26,0],[15.5,0]],"id":52385889},{"atb":[[3.45,0],[3.95,0],[3.7,0],[4.4,0]],"id":52385895},{"atb":[[38,0],[19.5,0],[24,0],[29,0]],"id":52385903},{"atb":[[3.95,0],[3.7,0],[4.9,0],[4.4,0]],"id":52385932}],"con":true,"img":false}]}
{"op":"mcm","clk":"11449223062","pt":1717305802720,"mc":[{"id":"1.229554892","rc":[{"atb":[[34,2.38],[44,1.22],[27,4.02],[60,0.44]],"id":52385888},{"atb":[[16,6.97],[18.5,4.48],[22,2.49],[27,1]],"id":52385889},{"atb":[[4,17.44],[4.5,7.48],[3.5,41.85],[3.75,28.54]],"id":52385895},{"atb":[[36,0.75],[19,5.81],[23,3.57],[28,1.94]],"id":52385903},{"atb":[[4,26.16],[4.5,14.95],[5,6.54],[3.75,38.05]],"id":52385932}],"con":true,"img":false}]}
{"op":"mcm","clk":"11449224642","pt":1717305826166,"mc":[{"id":"1.229554892","rc":[{"atb":[[16,0],[18.5,0],[22,0],[27,0]],"id":52385889},{"atb":[[4,0],[4.5,0],[3.5,0],[3.75,0]],"id":52385895},{"atb":[[4,0],[4.5,0],[5,0],[3.75,0]],"id":52385932}],"con":true,"img":false}]}
{"op":"mcm","clk":"11449224679","pt":1717305826834,"mc":[{"id":"1.229554892","rc":[{"atb":[[18,4.61],[21,2.62],[26,1.05],[15.5,7.21]],"id":52385889},{"atb":[[4.3,7.93],[3.4,43.6],[3.9,18.04],[3.65,29.61]],"id":52385895},{"atb":[[3.95,26.6],[3.7,38.75],[4.9,6.71],[4.4,15.39]],"id":52385932}],"con":true,"img":false}]}
{"op":"mcm","clk":"11449225303","pt":1717305835090,"mc":[{"id":"1.229554892","rc":[{"atb":[[550,0.44],[650,0.16]],"id":52385886},{"atb":[[17,6.53],[12,22.17]],"id":52385888},{"atb":[[9.2,29.74],[13,8.71]],"id":52385889},{"atb":[[10.5,25.67],[15.5,7.2]],"id":52385882},{"atb":[[17.5,6.33],[12.5,21.2]],"id":52385884},{"atb":[[3.2,47.51],[2.88,129.73]],"id":52385895},{"atb":[[2.92,127.03],[3.3,45.44]],"id":52385891},{"atb":[[18.5,5.97],[13.5,19.51]],"id":52385893},{"atb":[[10,27.1],[15,7.46]],"id":52385903},{"atb":[[3,121.95],[3.5,41.81]],"id":52385904}],"con":true,"img":false}]}
{"op":"mcm","clk":"11449225315","pt":1717305835195,"mc":[{"id":"1.229554892","rc":[{"atb":[[21,5.22],[15.5,16.82]],"id":52385907},{"atb":[[3.85,36.67],[3.35,103.78]],"id":52385909},{"atb":[[16.5,15.73],[23,4.75]],"id":52385918},{"atb":[[18.5,13.93],[27,4.01]],"id":52385920},{"atb":[[550,0.44],[650,0.16]],"id":52385917},{"atb":[[18,14.34],[26,4.18]],"id":52385923},{"atb":[[3.8,37.33],[3.3,106.04]],"id":52385934},{"atb":[[20,5.5],[15,17.42]],"id":52385936},{"atb":[[9.8,27.71],[14.5,7.74]],"id":52385931},{"atb":[[3.35,44.48],[2.94,125.72]],"id":52385932}],"con":true,"img":false}]}
{"op":"mcm","clk":"11449228452","pt":1717305880590,"mc":[{"id":"1.229554892","rc":[{"atb":[[18,0],[21,0],[26,0],[15.5,0]],"id":52385889},{"atb":[[32,0],[42,0],[26,0],[55,0]],"id":52385882},{"atb":[[65,0],[36,0],[46,0],[28,0]],"id":52385936}],"con":true,"img":false}]}
{"op":"mcm","clk":"11449228501","pt":1717305881325,"mc":[{"id":"1.229554892","rc":[{"atb":[[17.5,4.76],[20,2.75],[25,1.09],[15,7.48]],"id":52385889},{"atb":[[40,1.34],[50,0.53],[25,4.36],[30,2.71]],"id":52385882},{"atb":[[70,0.38],[38,2.12],[48,1.11],[29,3.74]],"id":52385936}],"con":true,"img":false}]}
{"op":"mcm","clk":"11449228509","pt":1717305881380,"mc":[{"id":"1.229554892","rc":[{"atb":[[21,0],[15.5,0]],"id":52385907},{"atb":[[3.85,0],[3.35,0]],"id":52385909},{"atb":[[16.5,0],[23,0]],"id":52385918},{"atb":[[550,0],[650,0]],"id":52385886},{"atb":[[18.5,0],[27,0]],"id":52385920},{"atb":[[17,0],[12,0]],"id":52385888},{"atb":[[9.2,0],[13,0]],"id":52385889},{"atb":[[10.5,0],[15.5,0]],"id":52385882},{"atb":[[17.5,0],[12.5,0]],"id":52385884},{"atb":[[550,0],[650,0]],"id":52385917},{"atb":[[3.2,0],[2.88,0]],"id":52385895},{"atb":[[18,0],[26,0]],"id":52385923},{"atb":[[2.92,0],[3.3,0]],"id":52385891},{"atb":[[18.5,0],[13.5,0]],"id":52385893},{"atb":[[3.8,0],[3.3,0]],"id":52385934},{"atb":[[10,0],[15,0]],"id":52385903},{"atb":[[20,0],[15,0]],"id":52385936},{"atb":[[3,0],[3.5,0]],"id":52385904},{"atb":[[9.8,0],[14.5,0]],"id":52385931},{"atb":[[3.35,0],[2.94,0]],"id":52385932}],"con":true,"img":false}]}
{"op":"mcm","clk":"11449228569","pt":1717305882321,"mc":[{"id":"1.229554892","rc":[{"atb":[[40,0],[50,0],[25,0],[30,0]],"id":52385882}],"con":true,"img":false}]}
{"op":"mcm","clk":"11449228613","pt":1717305883004,"mc":[{"id":"1.229554892","rc":[{"atb":[[40,1.34],[50,0.53],[25,4.36],[30,2.71]],"id":52385882}],"con":true,"img":false}]}
{"op":"mcm","clk":"11449228646","pt":1717305883528,"mc":[{"id":"1.229554892","rc":[{"atb":[[75,0],[40,0],[50,0],[30,0]],"id":52385907},{"atb":[[4.8,0],[5.8,0],[5.3,0],[6.6,0]],"id":52385909},{"atb":[[150,0],[75,0],[100,0],[50,0]],"id":52385920},{"atb":[[17.5,0],[20,0],[25,0],[15,0]],"id":52385889},{"atb":[[4.3,0],[3.4,0],[3.9,0],[3.65,0]],"id":52385895},{"atb":[[4.8,0],[4.3,0],[3.9,0],[3.65,0]],"id":52385891},{"atb":[[32,0],[42,0],[26,0],[55,0]],"id":52385893},{"atb":[[70,0],[38,0],[48,0],[29,0]],"id":52385936},{"atb":[[3.95,0],[3.7,0],[4.9,0],[4.4,0]],"id":52385932}],"con":true,"img":false}]}
{"op":"mcm","clk":"11449228693","pt":1717305884230,"mc":[{"id":"1.229554892","rc":[{"atb":[[34,3.17],[85,0.31],[44,1.83],[60,0.88]],"id":52385907},{"atb":[[6.8,4.51],[4.9,26.83],[5.9,10.68],[5.4,17.84]],"id":52385909},{"atb":[[160,0.16],[80,0.99],[110,0.48],[55,1.94]],"id":52385920},{"atb":[[17,4.9],[19.5,2.83],[24,1.14],[14.5,7.75]],"id":52385889},{"atb":[[3.4,32.7],[3.15,48.67],[3.9,9.02],[3.65,19.74]],"id":52385895},{"atb":[[4.3,7.93],[3.4,43.6],[3.9,18.04],[3.65,29.61]],"id":52385891},{"atb":[[40,1.34],[50,0.53],[25,4.36],[30,2.71]],"id":52385893},{"atb":[[32,3.37],[80,0.33],[42,1.92],[55,0.97]],"id":52385936},{"atb":[[4.6,7.27],[4.1,16.88],[3.8,28.03],[3.55,41.03]],"id":52385932}],"con":true,"img":false}]}
{"op":"mcm","clk":"11449230092","pt":1717305903643,"mc":[{"id":"1.229554892","rc":[{"atb":[[40,0],[50,0],[25,0],[30,0]],"id":52385882}],"con":true,"img":false}]}
{"op":"mcm","clk":"11449230161","pt":1717305904375,"mc":[{"id":"1.229554892","rc":[{"atb":[[36,1.5],[46,0.58],[23,4.76],[28,2.91]],"id":52385882}],"con":true,"img":false}]}
{"op":"mcm","clk":"11449231089","pt":1717305917271,"mc":[{"id":"1.229554892","rc":[{"atb":[[4.3,0],[3.4,0],[3.9,0],[3.65,0]],"id":52385891}],"con":true,"img":false}]}
{"op":"mcm","clk":"11449231141","pt":1717305917990,"mc":[{"id":"1.229554892","rc":[{"atb":[[4.1,8.44],[3.8,18.68],[3.55,30.77],[3.3,45.5]],"id":52385891}],"con":true,"img":false}]}
{"op":"mcm","clk":"11449231488","pt":1717305923383,"mc":[{"id":"1.229554892","rc":[{"atb":[[21,5.22],[15.5,16.82]],"id":52385907},{"atb":[[3.85,36.67],[3.35,103.78]],"id":52385909},{"atb":[[16.5,15.73],[23,4.75]],"id":52385918},{"atb":[[550,0.44],[650,0.16]],"id":52385886},{"atb":[[18.5,13.93],[27,4.01]],"id":52385920},{"atb":[[17,6.53],[12,22.17]],"id":52385888},{"atb":[[9.2,29.74],[13,8.71]],"id":52385889},{"atb":[[10.5,25.67],[15.5,7.2]],"id":52385882},{"atb":[[17.5,6.33],[12.5,21.2]],"id":52385884},{"atb":[[550,0.44],[650,0.16]],"id":52385917},{"atb":[[3.2,47.51],[2.88,129.73]],"id":52385895},{"atb":[[2.92,127.03],[3.3,90.94]],"id":52385891},{"atb":[[18,14.34],[26,4.18]],"id":52385923},{"atb":[[18.5,5.97],[13.5,19.51]],"id":52385893},{"atb":[[3.8,37.33],[3.3,106.04]],"id":52385934},{"atb":[[10,27.1],[15,7.46]],"id":52385903},{"atb":[[20,5.5],[15,17.42]],"id":52385936},{"atb":[[3,121.95],[3.5,41.81]],"id":52385904},{"atb":[[9.8,27.71],[14.5,7.74]],"id":52385931},{"atb":[[3.35,44.48],[2.94,125.72]],"id":52385932}],"con":true,"img":false}]}
{"op":"mcm","clk":"11449233027","pt":1717305947607,"mc":[{"id":"1.229554892","rc":[{"atb":[[40,0],[50,0],[25,0],[30,0]],"id":52385893}],"con":true,"img":false}]}
{"op":"mcm","clk":"11449233076","pt":1717305948337,"mc":[{"id":"1.229554892","rc":[{"atb":[[32,1.69],[42,0.64],[21,5.23],[26,3.14]],"id":52385893}],"con":true,"img":false}]}
{"op":"mcm","clk":"11449233584","pt":1717305955949,"mc":[{"id":"1.229554892","rc":[{"atb":[[21,0],[15.5,0]],"id":52385907},{"atb":[[3.85,0],[3.35,0]],"id":52385909},{"atb":[[550,0],[650,0]],"id":52385886},{"atb":[[16.5,0],[23,0]],"id":52385918},{"atb":[[18.5,0],[27,0]],"id":52385920},{"atb":[[17,0],[12,0]],"id":52385888},{"atb":[[9.2,0],[13,0]],"id":52385889},{"atb":[[10.5,0],[15.5,0]],"id":52385882},{"atb":[[17.5,0],[12.5,0]],"id":52385884},{"atb":[[550,0],[650,0]],"id":52385917},{"atb":[[3.2,0],[2.88,0]],"id":52385895},{"atb":[[2.92,0],[3.3,45.5]],"id":52385891},{"atb":[[18,0],[26,0]],"id":52385923},{"atb":[[18.5,0],[13.5,0]],"id":52385893},{"atb":[[3.8,0],[3.3,0]],"id":52385934},{"atb":[[10,0],[15,0]],"id":52385903},{"atb":[[20,0],[15,0]],"id":52385936},{"atb":[[3,0],[3.5,0]],"id":52385904},{"atb":[[9.8,0],[14.5,0]],"id":52385931},{"atb":[[3.35,0],[2.94,0]],"id":52385932}],"con":true,"img":false}]}
{"op":"mcm","clk":"11449235530","pt":1717305983747,"mc":[{"id":"1.229554892","rc":[{"atb":[[550,0.44],[650,0.16]],"id":52385886},{"atb":[[16.5,6.74],[11.5,23.22]],"id":52385888},{"atb":[[8,34.84],[10,11.61]],"id":52385889},{"atb":[[9.6,28.36],[14,8.04]],"id":52385882},{"atb":[[17,6.53],[12,22.17]],"id":52385884},{"atb":[[2.8,135.5],[3,52.26]],"id":52385895},{"atb":[[2.86,131.13],[3.15,48.61]],"id":52385891},{"atb":[[19,5.8],[14,18.76]],"id":52385893},{"atb":[[9.8,27.71],[14.5,7.74]],"id":52385903},{"atb":[[3,121.95],[3.5,41.81]],"id":52385904}],"con":true,"img":false}]}
{"op":"mcm","clk":"11449236230","pt":1717305994362,"mc":[{"id":"1.229554892","rc":[{"atb":[[18.5,13.93],[27,4.01]],"id":52385907},{"atb":[[4.3,31.67],[3.65,92.03]],"id":52385909},{"atb":[[17.5,14.77],[25,4.35]],"id":52385918},{"atb":[[38,2.82],[24,10.6]],"id":52385920},{"atb":[[550,0.44],[650,0.16]],"id":52385917},{"atb":[[34,3.16],[22,11.61]],"id":52385923},{"atb":[[3.6,93.81],[4.2,32.66]],"id":52385934},{"atb":[[17.5,14.77],[25,4.35]],"id":52385936},{"atb":[[9.6,28.36],[14,8.04]],"id":52385931},{"atb":[[3.35,44.48],[2.94,125.72]],"id":52385932}],"con":true,"img":false}]}
{"op":"mcm","clk":"11449237634","pt":1717306014418,"mc":[{"id":"1.229554892","rc":[{"atb":[[18.5,0],[27,0]],"id":52385907},{"atb":[[4.3,0],[3.65,0]],"id":52385909},{"atb":[[17.5,0],[25,0]],"id":52385918},{"atb":[[550,0],[650,0]],"id":52385886},{"atb":[[38,0],[24,0]],"id":52385920},{"atb":[[16.5,0],[11.5,0]],"id":52385888},{"atb":[[8,0],[10,0]],"id":52385889},{"atb":[[9.6,0],[14,0]],"id":52385882},{"atb":[[17,0],[12,0]],"id":52385884},{"atb":[[550,0],[650,0]],"id":52385917},{"atb":[[2.8,0],[3,0]],"id":52385895},{"atb":[[34,0],[22,0]],"id":52385923},{"atb":[[2.86,0],[3.15,0]],"id":52385891},{"atb":[[19,0],[14,0]],"id":52385893},{"atb":[[3.6,0],[4.2,0]],"id":52385934},{"atb":[[9.8,0],[14.5,0]],"id":52385903},{"atb":[[17.5,0],[25,0]],"id":52385936},{"atb":[[3,0],[3.5,0]],"id":52385904},{"atb":[[9.6,0],[14,0]],"id":52385931},{"atb":[[3.35,0],[2.94,0]],"id":52385932}],"con":true,"img":false}]}
{"op":"mcm","clk":"11449239508","pt":1717306042729,"mc":[{"id":"1.229554892","rc":[{"atb":[[18.5,13.93],[27,4.01]],"id":52385907},{"atb":[[4.3,31.67],[3.65,92.03]],"id":52385909},{"atb":[[17.5,14.77],[25,4.35]],"id":52385918},{"atb":[[38,2.82],[24,10.6]],"id":52385920},{"atb":[[550,0.44],[650,0.16]],"id":52385917},{"atb":[[34,3.16],[22,11.61]],"id":52385923},{"atb":[[3.6,93.81],[4.2,32.66]],"id":52385934},{"atb":[[17.5,14.77],[25,4.35]],"id":52385936},{"atb":[[9.6,28.36],[14,8.04]],"id":52385931},{"atb":[[3.35,44.48],[2.94,125.72]],"id":52385932}],"con":true,"img":false}]}
{"op":"mcm","clk":"11449239519","pt":1717306042833,"mc":[{"id":"1.229554892","rc":[{"atb":[[550,0.44],[650,0.16]],"id":52385886},{"atb":[[16.5,6.74],[11.5,23.22]],"id":52385888},{"atb":[[8,34.84],[10,11.61]],"id":52385889},{"atb":[[9.6,28.36],[14,8.04]],"id":52385882},{"atb":[[17,6.53],[12,22.17]],"id":52385884},{"atb":[[2.8,135.5],[3,52.26]],"id":52385895},{"atb":[[2.86,131.13],[3.15,48.61]],"id":52385891},{"atb":[[19,5.8],[14,18.76]],"id":52385893},{"atb":[[9.8,27.71],[14.5,7.74]],"id":52385903},{"atb":[[3,121.95],[3.5,41.81]],"id":52385904}],"con":true,"img":false}]}
{"op":"mcm","clk":"11449241221","pt":1717306068555,"mc":[{"id":"1.229554892","rc":[{"atb":[[18.5,0],[27,0]],"id":52385907},{"atb":[[4.3,0],[3.65,0]],"id":52385909},{"atb":[[550,0],[650,0]],"id":52385886},{"atb":[[17.5,0],[25,0]],"id":52385918},{"atb":[[16.5,0],[11.5,0]],"id":52385888},{"atb":[[38,0],[24,0]],"id":52385920},{"atb":[[8,0],[10,0]],"id":52385889},{"atb":[[9.6,0],[14,0]],"id":52385882},{"atb":[[17,0],[12,0]],"id":52385884},{"atb":[[550,0],[650,0]],"id":52385917},{"atb":[[2.8,0],[3,0]],"id":52385895},{"atb":[[2.86,0],[3.15,0]],"id":52385891},{"atb":[[34,0],[22,0]],"id":52385923},{"atb":[[19,0],[14,0]],"id":52385893},{"atb":[[3.6,0],[4.2,0]],"id":52385934},{"atb":[[9.8,0],[14.5,0]],"id":52385903},{"atb":[[3,0],[3.5,0]],"id":52385904},{"atb":[[17.5,0],[25,0]],"id":52385936},{"atb":[[9.6,0],[14,0]],"id":52385931},{"atb":[[3.35,0],[2.94,0]],"id":52385932}],"con":true,"img":false}]}
{"op":"mcm","clk":"11449242774","pt":1717306089400,"mc":[{"id":"1.229554892","rc":[{"atb":[[18.5,13.93],[27,4.01]],"id":52385907},{"atb":[[4.3,31.67],[3.65,92.03]],"id":52385909},{"atb":[[17.5,14.77],[25,4.35]],"id":52385918},{"atb":[[550,0.44],[650,0.16]],"id":52385886},{"atb":[[38,2.82],[24,10.6]],"id":52385920},{"atb":[[16.5,6.74],[11.5,23.22]],"id":52385888},{"atb":[[8,34.84],[10,11.61]],"id":52385889},{"atb":[[9.6,28.36],[14,8.04]],"id":52385882},{"atb":[[17,6.53],[12,22.17]],"id":52385884},{"atb":[[550,0.44],[650,0.16]],"id":52385917},{"atb":[[2.8,135.5],[3,52.26]],"id":52385895},{"atb":[[34,3.16],[22,11.61]],"id":52385923},{"atb":[[2.86,131.13],[3.15,48.61]],"id":52385891},{"atb":[[19,5.8],[14,18.76]],"id":52385893},{"atb":[[3.6,93.81],[4.2,32.66]],"id":52385934},{"atb":[[9.8,27.71],[14.5,7.74]],"id":52385903},{"atb":[[3,121.95],[3.5,41.81]],"id":52385904},{"atb":[[17.5,14.77],[25,4.35]],"id":52385936},{"atb":[[9.6,28.36],[14,8.04]],"id":52385931},{"atb":[[3.35,44.48],[2.94,125.72]],"id":52385932}],"con":true,"img":false}]}
{"op":"mcm","clk":"11449252531","pt":1717306219462,"mc":[{"id":"1.229554892","rc":[{"atb":[[530,0]],"id":52385886},{"atb":[[580,0],[630,0]],"id":52385917}],"con":true,"img":false}]}
{"op":"mcm","clk":"11449252538","pt":1717306219558,"mc":[{"id":"1.229554892","rc":[{"atb":[[580,0],[630,0],[480,0]],"id":52385886},{"atb":[[680,0],[730,0]],"id":52385917}],"con":true,"img":false}]}
{"op":"mcm","clk":"11449252590","pt":1717306220186,"mc":[{"id":"1.229554892","rc":[{"atb":[[660,0.12]],"id":52385886},{"atb":[[700,0.15],[750,0.1]],"id":52385917}],"con":true,"img":false}]}
{"op":"mcm","clk":"11449252597","pt":1717306220290,"mc":[{"id":"1.229554892","rc":[{"atb":[[610,0.17],[710,0.07],[760,0.04]],"id":52385886},{"atb":[[800,0.07],[850,0.03]],"id":52385917}],"con":true,"img":false}]}
{"op":"mcm","clk":"11449255019","pt":1717306251602,"mc":[{"id":"1.229554892","rc":[{"atb":[[3.4,0],[3.15,0],[3.9,0],[3.65,0]],"id":52385895},{"atb":[[32,0],[42,0],[21,0],[26,0]],"id":52385893}],"con":true,"img":false}]}
{"op":"mcm","clk":"11449255037","pt":1717306251814,"mc":[{"id":"1.229554892","rc":[{"atb":[[4.1,0],[3.8,0],[3.55,0],[3.3,0]],"id":52385891}],"con":true,"img":false}]}
{"op":"mcm","clk":"11449255077","pt":1717306252321,"mc":[{"id":"1.229554892","rc":[{"atb":[[3.6,20.12],[3.85,9.18],[3.1,49.83],[3.35,33.39]],"id":52385895},{"atb":[[38,0.71],[19.5,5.66],[24,3.41],[29,1.87]],"id":52385893}],"con":true,"img":false}]}
{"op":"mcm","clk":"11449255095","pt":1717306252482,"mc":[{"id":"1.229554892","rc":[{"atb":[[4,8.72],[3.25,46.51],[3.5,31.39],[3.75,19.02]],"id":52385891}],"con":true,"img":false}]}
{"op":"mcm","clk":"11449258053","pt":1717306290281,"mc":[{"id":"1.229554892","rc":[{"atb":[[18.5,0],[27,0]],"id":52385907},{"atb":[[4.3,0],[3.65,0]],"id":52385909},{"atb":[[550,0],[650,0]],"id":52385886},{"atb":[[17.5,0],[25,0]],"id":52385918},{"atb":[[38,0],[24,0]],"id":52385920},{"atb":[[16.5,0],[11.5,0]],"id":52385888},{"atb":[[8,0],[10,0]],"id":52385889},{"atb":[[9.6,0],[14,0]],"id":52385882},{"atb":[[17,0],[12,0]],"id":52385884},{"atb":[[550,0],[650,0]],"id":52385917},{"atb":[[2.8,0],[3,0]],"id":52385895},{"atb":[[2.86,0],[3.15,0]],"id":52385891},{"atb":[[34,0],[22,0]],"id":52385923},{"atb":[[19,0],[14,0]],"id":52385893},{"atb":[[3.6,0],[4.2,0]],"id":52385934},{"atb":[[9.8,0],[14.5,0]],"id":52385903},{"atb":[[17.5,0],[25,0]],"id":52385936},{"atb":[[3,0],[3.5,0]],"id":52385904},{"atb":[[9.6,0],[14,0]],"id":52385931},{"atb":[[3.35,0],[2.94,0]],"id":52385932}],"con":true,"img":false}]}
{"op":"mcm","clk":"11449259933","pt":1717306314682,"mc":[{"id":"1.229554892","rc":[{"atb":[[18,14.34],[26,4.18]],"id":52385907},{"atb":[[4.6,29.03],[3.8,87.1]],"id":52385909},{"atb":[[550,0.44],[650,0.16]],"id":52385886},{"atb":[[17,15.24],[24,4.54]],"id":52385918},{"atb":[[16.5,6.74],[11.5,23.22]],"id":52385888},{"atb":[[36,2.98],[23,11.08]],"id":52385920},{"atb":[[9.6,12.15],[7.6,36.95]],"id":52385889},{"atb":[[13.5,8.36],[9.4,29.03]],"id":52385882},{"atb":[[16.5,6.74],[11.5,23.22]],"id":52385884},{"atb":[[550,0.44],[650,0.16]],"id":52385917},{"atb":[[2.98,52.79],[2.78,137.02]],"id":52385895},{"atb":[[2.8,135.5],[3,52.26]],"id":52385891},{"atb":[[36,2.98],[23,11.08]],"id":52385923},{"atb":[[18,6.14],[13,20.32]],"id":52385893},{"atb":[[4.6,29.03],[3.8,87.1]],"id":52385934},{"atb":[[9.8,27.71],[14.5,7.74]],"id":52385903},{"atb":[[3.45,42.66],[2.98,123.18]],"id":52385904},{"atb":[[18,14.34],[26,4.18]],"id":52385936},{"atb":[[9.8,27.71],[14.5,7.74]],"id":52385931},{"atb":[[3.4,43.55],[2.96,124.44]],"id":52385932}],"con":true,"img":false}]}
{"op":"mcm","clk":"11449262361","pt":1717306345526,"mc":[{"id":"1.229554892","rc":[{"atb":[[18,0],[26,0]],"id":52385907},{"atb":[[4.6,0],[3.8,0]],"id":52385909},{"atb":[[550,0],[650,0]],"id":52385886},{"atb":[[17,0],[24,0]],"id":52385918},{"atb":[[16.5,0],[11.5,0]],"id":52385888},{"atb":[[36,0],[23,0]],"id":52385920},{"atb":[[9.6,0],[7.6,0]],"id":52385889},{"atb":[[13.5,0],[9.4,0]],"id":52385882},{"atb":[[16.5,0],[11.5,0]],"id":52385884},{"atb":[[550,0],[650,0]],"id":52385917},{"atb":[[2.98,0],[2.78,0]],"id":52385895},{"atb":[[2.8,0],[3,0]],"id":52385891},{"atb":[[36,0],[23,0]],"id":52385923},{"atb":[[18,0],[13,0]],"id":52385893},{"atb":[[4.6,0],[3.8,0]],"id":52385934},{"atb":[[9.8,0],[14.5,0]],"id":52385903},{"atb":[[3.45,0],[2.98,0]],"id":52385904},{"atb":[[18,0],[26,0]],"id":52385936},{"atb":[[9.8,0],[14.5,0]],"id":52385931},{"atb":[[3.4,0],[2.96,0]],"id":52385932}],"con":true,"img":false}]}
{"op":"mcm","clk":"11449264600","pt":1717306375342,"mc":[{"id":"1.229554892","rc":[{"atb":[[18,14.34],[26,4.18]],"id":52385907},{"atb":[[3.85,85.58],[4.7,28.25]],"id":52385909},{"atb":[[16.5,15.73],[23,4.75]],"id":52385918},{"atb":[[36,2.98],[23,11.08]],"id":52385920},{"atb":[[550,0.44],[650,0.16]],"id":52385917},{"atb":[[36,2.98],[23,11.08]],"id":52385923},{"atb":[[3.85,85.58],[4.7,28.25]],"id":52385934},{"atb":[[18,14.34],[26,4.18]],"id":52385936},{"atb":[[9.8,27.71],[14.5,7.74]],"id":52385931},{"atb":[[3.45,42.66],[2.98,123.18]],"id":52385932}],"con":true,"img":false}]}
{"op":"mcm","clk":"11449264609","pt":1717306375445,"mc":[{"id":"1.229554892","rc":[{"atb":[[550,0.44],[650,0.16]],"id":52385886},{"atb":[[16.5,6.74],[11.5,23.22]],"id":52385888},{"atb":[[7.4,38.1],[9.4,12.44]],"id":52385889},{"atb":[[9.2,29.74],[13,8.71]],"id":52385882},{"atb":[[16.5,6.74],[11.5,23.22]],"id":52385884},{"atb":[[2.98,52.79],[2.78,137.02]],"id":52385895},{"atb":[[2.96,53.33],[2.76,138.58]],"id":52385891},{"atb":[[18,6.14],[13,20.32]],"id":52385893},{"atb":[[9.8,27.71],[14.5,7.74]],"id":52385903},{"atb":[[3.45,42.66],[2.98,123.18]],"id":52385904}],"con":true,"img":false}]}
{"op":"mcm","clk":"11449283678","pt":1717306631828,"mc":[{"id":"1.229554892","rc":[{"atb":[[34,0],[85,0],[44,0],[60,0]],"id":52385907},{"atb":[[610,0],[660,0],[710,0],[760,0]],"id":52385886},{"atb":[[17,0],[19.5,0],[24,0],[14.5,0]],"id":52385889},{"atb":[[36,0],[46,0],[23,0],[28,0]],"id":52385882},{"atb":[[700,0],[750,0],[800,0],[850,0]],"id":52385917},{"atb":[[140,0],[70,0],[95,0],[48,0]],"id":52385923},{"atb":[[38,0],[19.5,0],[24,0],[29,0]],"id":52385893},{"atb":[[4.9,0],[4.4,0],[5.9,0],[5.4,0]],"id":52385904},{"atb":[[32,0],[80,0],[42,0],[55,0]],"id":52385936}],"con":true,"img":false}]}
{"op":"mcm","clk":"11449283744","pt":1717306632611,"mc":[{"id":"1.229554892","rc":[{"atb":[[32,3.37],[80,0.33],[42,1.92],[55,0.97]],"id":52385907},{"atb":[[560,0.05],[410,0.26],[460,0.17],[510,0.1]],"id":52385886},{"atb":[[16,3.49],[18.5,1.5],[11,10.46],[13.5,6.28]],"id":52385889},{"atb":[[34,1.59],[44,0.61],[22,4.98],[27,3.02]],"id":52385882},{"atb":[[520,0.2],[570,0.14],[620,0.08],[670,0.04]],"id":52385917},{"atb":[[150,0.18],[75,1.06],[100,0.53],[50,2.13]],"id":52385923},{"atb":[[36,0.75],[19,5.81],[23,3.57],[28,1.94]],"id":52385893},{"atb":[[4.5,29.89],[5,19.62],[5.5,11.63],[6,5.23]],"id":52385904},{"atb":[[70,0.38],[38,2.12],[48,1.11],[29,3.74]],"id":52385936}],"con":true,"img":false}]}
{"op":"mcm","clk":"11449291977","pt":1717306738804,"mc":[{"id":"1.229554892","rc":[{"atb":[[560,0],[410,0],[460,0],[510,0]],"id":52385886},{"atb":[[36,0],[19,0],[23,0],[28,0]],"id":52385893}],"con":true,"img":false}]}
{"op":"mcm","clk":"11449292027","pt":1717306739524,"mc":[{"id":"1.229554892","rc":[{"atb":[[550,0.49],[400,0.26],[450,0.17],[500,0.1]],"id":52385886},{"atb":[[34,0.8],[18.5,5.98],[22,3.74],[27,2.01]],"id":52385893}],"con":true,"img":false}]}
{"op":"mcm","clk":"11449301937","pt":1717306870185,"mc":[{"id":"1.229554892","rc":[{"atb":[[18,0],[26,0]],"id":52385907},{"atb":[[3.85,0],[4.7,0]],"id":52385909},{"atb":[[550,0.05],[650,0]],"id":52385886},{"atb":[[16.5,0],[23,0]],"id":52385918},{"atb":[[16.5,0],[11.5,0]],"id":52385888},{"atb":[[36,0],[23,0]],"id":52385920},{"atb":[[7.4,0],[9.4,0]],"id":52385889},{"atb":[[9.2,0],[13,0]],"id":52385882},{"atb":[[16.5,0],[11.5,0]],"id":52385884},{"atb":[[550,0],[650,0]],"id":52385917},{"atb":[[2.98,0],[2.78,0]],"id":52385895},{"atb":[[36,0],[23,0]],"id":52385923},{"atb":[[2.96,0],[2.76,0]],"id":52385891},{"atb":[[18,0],[13,0]],"id":52385893},{"atb":[[3.85,0],[4.7,0]],"id":52385934},{"atb":[[9.8,0],[14.5,0]],"id":52385903},{"atb":[[18,0],[26,0]],"id":52385936},{"atb":[[3.45,0],[2.98,0]],"id":52385904},{"atb":[[9.8,0],[14.5,0]],"id":52385931},{"atb":[[3.45,0],[2.98,0]],"id":52385932}],"con":true,"img":false}]}
{"op":"mcm","clk":"11449302239","pt":1717306874172,"mc":[{"id":"1.229554892","rc":[{"atb":[[34,0],[44,0],[27,0],[60,0]],"id":52385888},{"atb":[[36,0],[19,0],[23,0],[28,0]],"id":52385903}],"con":true,"img":false}]}
{"op":"mcm","clk":"11449302296","pt":1717306874893,"mc":[{"id":"1.229554892","rc":[{"atb":[[70,0.38],[38,2.12],[48,1.11],[29,3.74]],"id":52385888},{"atb":[[40,0.67],[20,5.51],[25,3.27],[30,1.81]],"id":52385903}],"con":true,"img":false}]}
{"op":"mcm","clk":"11449306428","pt":1717306931781,"mc":[{"id":"1.229554892","rc":[{"atb":[[18,14.34],[26,4.18]],"id":52385907},{"atb":[[3.85,85.58],[4.7,28.25]],"id":52385909},{"atb":[[16.5,15.73],[23,4.75]],"id":52385918},{"atb":[[36,2.98],[23,11.08]],"id":52385920},{"atb":[[550,0.44],[650,0.16]],"id":52385917},{"atb":[[36,2.98],[23,11.08]],"id":52385923},{"atb":[[3.85,85.58],[4.7,28.25]],"id":52385934},{"atb":[[18,14.34],[26,4.18]],"id":52385936},{"atb":[[9.8,27.71],[14.5,7.74]],"id":52385931},{"atb":[[3.45,42.66],[2.98,123.18]],"id":52385932}],"con":true,"img":false}]}
{"op":"mcm","clk":"11449306439","pt":1717306931838,"mc":[{"id":"1.229554892","rc":[{"atb":[[550,0.49],[650,0.16]],"id":52385886},{"atb":[[16.5,6.74],[11.5,23.22]],"id":52385888},{"atb":[[7.4,38.1],[9.4,12.44]],"id":52385889},{"atb":[[9.2,29.74],[13,8.71]],"id":52385882},{"atb":[[16.5,6.74],[11.5,23.22]],"id":52385884},{"atb":[[2.98,52.79],[2.78,137.02]],"id":52385895},{"atb":[[2.96,53.33],[2.76,138.58]],"id":52385891},{"atb":[[18,6.14],[13,20.32]],"id":52385893},{"atb":[[9.8,27.71],[14.5,7.74]],"id":52385903},{"atb":[[3.45,42.66],[2.98,123.18]],"id":52385904}],"con":true,"img":false}]}
{"op":"mcm","clk":"11449307459","pt":1717306947557,"mc":[{"id":"1.229554892","rc":[{"atb":[[6.8,0],[4.9,0],[5.9,0],[5.4,0]],"id":52385909}],"con":true,"img":false}]}
{"op":"mcm","clk":"11449307467","pt":1717306947663,"mc":[{"id":"1.229554892","rc":[{"atb":[[4.6,0],[4.1,0],[3.8,0],[3.55,0]],"id":52385932}],"con":true,"img":false}]}
{"op":"mcm","clk":"11449307506","pt":1717306948278,"mc":[{"id":"1.229554892","rc":[{"atb":[[7.2,12.66],[9.2,3.19],[6.2,20.12],[8.2,7.27]],"id":52385909}],"con":true,"img":false}]}
{"op":"mcm","clk":"11449307513","pt":1717306948381,"mc":[{"id":"1.229554892","rc":[{"atb":[[5.6,5.69],[5.1,12.76],[4.6,21.8],[4.1,33.76]],"id":52385932}],"con":true,"img":false}]}
{"op":"mcm","clk":"11449314392","pt":1717307049065,"mc":[{"id":"1.229554892","rc":[{"atb":[[3.6,0],[3.85,0],[3.1,0],[3.35,0]],"id":52385895}],"con":true,"img":false}]}
{"op":"mcm","clk":"11449314446","pt":1717307049787,"mc":[{"id":"1.229554892","rc":[{"atb":[[3.6,20.12],[3.85,9.18],[3.1,49.83],[3.35,33.39]],"id":52385895}],"con":true,"img":false}]}
{"op":"mcm","clk":"11449334061","pt":1717307327842,"mc":[{"id":"1.229554892","rc":[{"atb":[[18,0],[26,0]],"id":52385907},{"atb":[[3.85,0],[4.7,0]],"id":52385909},{"atb":[[550,0.05],[650,0]],"id":52385886},{"atb":[[16.5,0],[23,0]],"id":52385918},{"atb":[[16.5,0],[11.5,0]],"id":52385888},{"atb":[[36,0],[23,0]],"id":52385920},{"atb":[[7.4,0],[9.4,0]],"id":52385889},{"atb":[[9.2,0],[13,0]],"id":52385882},{"atb":[[16.5,0],[11.5,0]],"id":52385884},{"atb":[[550,0],[650,0]],"id":52385917},{"atb":[[2.98,0],[2.78,0]],"id":52385895},{"atb":[[2.96,0],[2.76,0]],"id":52385891},{"atb":[[36,0],[23,0]],"id":52385923},{"atb":[[18,0],[13,0]],"id":52385893},{"atb":[[3.85,0],[4.7,0]],"id":52385934},{"atb":[[9.8,0],[14.5,0]],"id":52385903},{"atb":[[3.45,0],[2.98,0]],"id":52385904},{"atb":[[18,0],[26,0]],"id":52385936},{"atb":[[9.8,0],[14.5,0]],"id":52385931},{"atb":[[3.45,0],[2.98,0]],"id":52385932}],"con":true,"img":false}]}
{"op":"mcm","clk":"11449335833","pt":1717307354781,"mc":[{"id":"1.229554892","rc":[{"atb":[[18,14.34],[26,4.18]],"id":52385907},{"atb":[[3.85,85.58],[4.7,28.25]],"id":52385909},{"atb":[[16.5,15.73],[23,4.75]],"id":52385918},{"atb":[[550,0.49],[650,0.16]],"id":52385886},{"atb":[[36,2.98],[23,11.08]],"id":52385920},{"atb":[[16.5,6.74],[11.5,23.22]],"id":52385888},{"atb":[[7.4,38.1],[9.4,12.44]],"id":52385889},{"atb":[[9.2,29.74],[13,8.71]],"id":52385882},{"atb":[[16.5,6.74],[11.5,23.22]],"id":52385884},{"atb":[[550,0.44],[650,0.16]],"id":52385917},{"atb":[[2.98,52.79],[2.78,137.02]],"id":52385895},{"atb":[[36,2.98],[23,11.08]],"id":52385923},{"atb":[[2.96,53.33],[2.76,138.58]],"id":52385891},{"atb":[[18,6.14],[13,20.32]],"id":52385893},{"atb":[[3.85,85.58],[4.7,28.25]],"id":52385934},{"atb":[[9.8,27.71],[14.5,7.74]],"id":52385903},{"atb":[[18,14.34],[26,4.18]],"id":52385936},{"atb":[[3.45,42.66],[2.98,123.18]],"id":52385904},{"atb":[[9.8,27.71],[14.5,7.74]],"id":52385931},{"atb":[[3.45,42.66],[2.98,123.18]],"id":52385932}],"con":true,"img":false}]}
{"op":"mcm","clk":"11449341388","pt":1717307438850,"mc":[{"id":"1.229554892","rc":[{"atb":[[18,0],[26,0]],"id":52385907},{"atb":[[3.85,0],[4.7,0]],"id":52385909},{"atb":[[16.5,0],[23,0]],"id":52385918},{"atb":[[550,0.05],[650,0]],"id":52385886},{"atb":[[16.5,0],[11.5,0]],"id":52385888},{"atb":[[36,0],[23,0]],"id":52385920},{"atb":[[7.4,0],[9.4,0]],"id":52385889},{"atb":[[9.2,0],[13,0]],"id":52385882},{"atb":[[16.5,0],[11.5,0]],"id":52385884},{"atb":[[550,0],[650,0]],"id":52385917},{"atb":[[2.98,0],[2.78,0]],"id":52385895},{"atb":[[2.96,0],[2.76,0]],"id":52385891},{"atb":[[36,0],[23,0]],"id":52385923},{"atb":[[18,0],[13,0]],"id":52385893},{"atb":[[3.85,0],[4.7,0]],"id":52385934},{"atb":[[9.8,0],[14.5,0]],"id":52385903},{"atb":[[3.45,0],[2.98,0]],"id":52385904},{"atb":[[18,0],[26,0]],"id":52385936},{"atb":[[9.8,0],[14.5,0]],"id":52385931},{"atb":[[3.45,0],[2.98,0]],"id":52385932}],"con":true,"img":false}]}
{"op":"mcm","clk":"11449342055","pt":1717307452116,"mc":[{"id":"1.229554892","rc":[{"atb":[[18,14.34],[26,4.18]],"id":52385907},{"atb":[[3.85,85.58],[4.7,28.25]],"id":52385909},{"atb":[[550,0.49],[650,0.16]],"id":52385886},{"atb":[[16,16.26],[22,4.97]],"id":52385918},{"atb":[[36,2.98],[23,11.08]],"id":52385920},{"atb":[[16.5,6.74],[11.5,23.22]],"id":52385888},{"atb":[[7.4,38.1],[9.4,12.44]],"id":52385889},{"atb":[[9.2,29.74],[13,8.71]],"id":52385882},{"atb":[[16.5,6.74],[11.5,23.22]],"id":52385884},{"atb":[[550,0.44],[650,0.16]],"id":52385917},{"atb":[[2.96,53.33],[2.76,138.58]],"id":52385895},{"atb":[[36,2.98],[23,11.08]],"id":52385923},{"atb":[[2.96,53.33],[2.76,138.58]],"id":52385891},{"atb":[[17.5,6.33],[12.5,21.2]],"id":52385893},{"atb":[[3.85,85.58],[4.7,28.25]],"id":52385934},{"atb":[[9.8,27.71],[14.5,7.74]],"id":52385903},{"atb":[[3.45,42.66],[2.98,123.18]],"id":52385904},{"atb":[[18,14.34],[26,4.18]],"id":52385936},{"atb":[[9.8,27.71],[14.5,7.74]],"id":52385931},{"atb":[[3.45,42.66],[2.98,123.18]],"id":52385932}],"con":true,"img":false}]}
{"op":"mcm","clk":"11449342827","pt":1717307467273,"mc":[{"id":"1.229554892","rc":[{"atb":[[7.2,0],[9.2,0],[6.2,0],[8.2,0]],"id":52385909},{"atb":[[70,0],[38,0],[48,0],[29,0]],"id":52385888}],"con":true,"img":false}]}
{"op":"mcm","clk":"11449342860","pt":1717307467940,"mc":[{"id":"1.229554892","rc":[{"atb":[[6.8,13.53],[8.8,3.35],[7.8,7.7],[5.9,21.36]],"id":52385909},{"atb":[[65,0.41],[36,2.24],[46,1.16],[28,3.88]],"id":52385888}],"con":true,"img":false}]}
{"op":"mcm","clk":"11449363588","pt":1717307963207,"mc":[{"id":"1.229554892","rc":[{"atb":[[18,0],[26,0]],"id":52385907},{"atb":[[3.85,0],[4.7,0]],"id":52385909},{"atb":[[550,0.05],[650,0]],"id":52385886},{"atb":[[16,0],[22,0]],"id":52385918},{"atb":[[16.5,0],[11.5,0]],"id":52385888},{"atb":[[36,0],[23,0]],"id":52385920},{"atb":[[7.4,0],[9.4,0]],"id":52385889},{"atb":[[9.2,0],[13,0]],"id":52385882},{"atb":[[16.5,0],[11.5,0]],"id":52385884},{"atb":[[550,0],[650,0]],"id":52385917},{"atb":[[2.96,0],[2.76,0]],"id":52385895},{"atb":[[36,0],[23,0]],"id":52385923},{"atb":[[2.96,0],[2.76,0]],"id":52385891},{"atb":[[17.5,0],[12.5,0]],"id":52385893},{"atb":[[3.85,0],[4.7,0]],"id":52385934},{"atb":[[9.8,0],[14.5,0]],"id":52385903},{"atb":[[18,0],[26,0]],"id":52385936},{"atb":[[3.45,0],[2.98,0]],"id":52385904},{"atb":[[9.8,0],[14.5,0]],"id":52385931},{"atb":[[3.45,0],[2.98,0]],"id":52385932}],"con":true,"img":false}]}
{"op":"mcm","clk":"11449365911","pt":1717308010405,"mc":[{"id":"1.229554892","rc":[{"atb":[[18,14.34],[26,4.18]],"id":52385907},{"atb":[[3.85,85.58],[4.7,28.25]],"id":52385909},{"atb":[[550,0.49],[650,0.16]],"id":52385886},{"atb":[[16,16.26],[22,4.97]],"id":52385918},{"atb":[[16.5,6.74],[11.5,23.22]],"id":52385888},{"atb":[[36,2.98],[23,11.08]],"id":52385920},{"atb":[[7.4,38.1],[9.4,12.44]],"id":52385889},{"atb":[[9.2,29.74],[13,8.71]],"id":52385882},{"atb":[[16.5,6.74],[11.5,23.22]],"id":52385884},{"atb":[[550,0.44],[650,0.16]],"id":52385917},{"atb":[[2.96,53.33],[2.76,138.58]],"id":52385895},{"atb":[[2.96,53.33],[2.76,138.58]],"id":52385891},{"atb":[[36,2.98],[23,11.08]],"id":52385923},{"atb":[[17.5,6.33],[12.5,21.2]],"id":52385893},{"atb":[[3.85,85.58],[4.7,28.25]],"id":52385934},{"atb":[[9.8,27.71],[14.5,7.74]],"id":52385903},{"atb":[[3.45,42.66],[2.98,123.18]],"id":52385904},{"atb":[[18,14.34],[26,4.18]],"id":52385936},{"atb":[[9.8,27.71],[14.5,7.74]],"id":52385931},{"atb":[[3.45,42.66],[2.98,123.18]],"id":52385932}],"con":true,"img":false}]}
{"op":"mcm","clk":"11449372622","pt":1717308154150,"mc":[{"id":"1.229554892","rc":[{"atb":[[34,0],[44,0],[22,0],[27,0]],"id":52385882},{"atb":[[150,0],[75,0],[100,0],[50,0]],"id":52385923},{"atb":[[4.5,0],[5,0],[5.5,0],[6,0]],"id":52385904}],"con":true,"img":false}]}
{"op":"mcm","clk":"11449372646","pt":1717308154871,"mc":[{"id":"1.229554892","rc":[{"atb":[[36,1.5],[46,0.58],[23,4.76],[28,2.91]],"id":52385882},{"atb":[[160,0.16],[80,0.99],[110,0.48],[55,1.94]],"id":52385923},{"atb":[[5.6,11.37],[5.1,19.14],[4.6,29.07],[6.2,5.03]],"id":52385904}],"con":true,"img":false}]}
{"op":"mcm","clk":"11449372883","pt":1717308160726,"mc":[{"id":"1.229554892","rc":[{"atb":[[36,0],[46,0],[23,0],[28,0]],"id":52385882},{"atb":[[5.6,0],[4.6,0],[6.2,0]],"id":52385904}],"con":true,"img":false}]}
{"op":"mcm","clk":"11449372887","pt":1717308160835,"mc":[{"id":"1.229554892","rc":[{"atb":[[5.1,0]],"id":52385904}],"con":true,"img":false}]}
{"op":"mcm","clk":"11449372905","pt":1717308161442,"mc":[{"id":"1.229554892","rc":[{"atb":[[34,1.59],[44,0.61],[22,4.98],[27,3.02]],"id":52385882},{"atb":[[4.5,29.89],[5.5,11.63],[6,5.23]],"id":52385904}],"con":true,"img":false}]}
{"op":"mcm","clk":"11449372909","pt":1717308161549,"mc":[{"id":"1.229554892","rc":[{"atb":[[5,19.62]],"id":52385904}],"con":true,"img":false}]}
{"op":"mcm","clk":"11449376968","pt":1717308252245,"mc":[{"id":"1.229554892","rc":[{"atb":[[3.6,0],[3.85,0],[3.1,0],[3.35,0]],"id":52385895},{"atb":[[4,0],[3.25,0],[3.5,0],[3.75,0]],"id":52385891}],"con":true,"img":false}]}
{"op":"mcm","clk":"11449377005","pt":1717308252968,"mc":[{"id":"1.229554892","rc":[{"atb":[[3.4,32.7],[3.15,48.67],[3.9,9.02],[3.65,19.74]],"id":52385895},{"atb":[[4,8.72],[3.25,46.51],[3.5,31.39],[3.75,19.02]],"id":52385891}],"con":true,"img":false}]}
{"op":"mcm","clk":"11449398387","pt":1717308580982,"mc":[{"id":"1.229554892","rc":[{"atb":[[6.8,0],[8.8,0],[7.8,0],[5.9,0]],"id":52385909},{"atb":[[65,0],[36,0],[46,0],[28,0]],"id":52385888}],"con":true,"img":false}]}
{"op":"mcm","clk":"11449398434","pt":1717308581658,"mc":[{"id":"1.229554892","rc":[{"atb":[[7.2,12.66],[9.2,3.19],[6.2,20.12],[8.2,7.27]],"id":52385909},{"atb":[[70,0.38],[38,2.12],[48,1.11],[29,3.74]],"id":52385888}],"con":true,"img":false}]}
{"op":"mcm","clk":"11449398984","pt":1717308589556,"mc":[{"id":"1.229554892","rc":[{"atb":[[7.2,0],[9.2,0],[6.2,0],[8.2,0]],"id":52385909},{"atb":[[70,0],[38,0],[48,0],[29,0]],"id":52385888}],"con":true,"img":false}]}
{"op":"mcm","clk":"11449399037","pt":1717308590274,"mc":[{"id":"1.229554892","rc":[{"atb":[[6.8,13.53],[8.8,3.35],[7.8,7.7],[5.9,21.36]],"id":52385909},{"atb":[[65,0.41],[36,2.24],[46,1.16],[28,3.88]],"id":52385888}],"con":true,"img":false}]}
{"op":"mcm","clk":"11449428596","pt":1717308997546,"mc":[{"id":"1.229554892","rc":[{"atb":[[22,0]],"id":52385882},{"atb":[[4.5,0],[5,0]],"id":52385904}],"con":true,"img":false}]}
{"op":"mcm","clk":"11449428658","pt":1717308998266,"mc":[{"id":"1.229554892","rc":[{"atb":[[23,4.76]],"id":52385882},{"atb":[[5.1,19.14],[4.6,29.07]],"id":52385904}],"con":true,"img":false}]}
{"op":"mcm","clk":"11449429076","pt":1717309004053,"mc":[{"id":"1.229554892","rc":[{"atb":[[23,0]],"id":52385882},{"atb":[[5.1,0],[4.6,0]],"id":52385904}],"con":true,"img":false}]}
{"op":"mcm","clk":"11449429131","pt":1717309004778,"mc":[{"id":"1.229554892","rc":[{"atb":[[22,4.98]],"id":52385882},{"atb":[[4.5,29.89],[5,19.62]],"id":52385904}],"con":true,"img":false}]}
{"op":"mcm","clk":"11449433535","pt":1717309070258,"mc":[{"id":"1.229554892","rc":[{"atb":[[18,0],[26,0]],"id":52385907},{"atb":[[3.85,0],[4.7,0]],"id":52385909},{"atb":[[16,0],[22,0]],"id":52385918},{"atb":[[550,0.05],[650,0]],"id":52385886},{"atb":[[16.5,0],[11.5,0]],"id":52385888},{"atb":[[36,0],[23,0]],"id":52385920},{"atb":[[7.4,0],[9.4,0]],"id":52385889},{"atb":[[9.2,0],[13,0]],"id":52385882},{"atb":[[16.5,0],[11.5,0]],"id":52385884},{"atb":[[550,0],[650,0]],"id":52385917},{"atb":[[2.96,0],[2.76,0]],"id":52385895},{"atb":[[2.96,0],[2.76,0]],"id":52385891},{"atb":[[36,0],[23,0]],"id":52385923},{"atb":[[17.5,0],[12.5,0]],"id":52385893},{"atb":[[3.85,0],[4.7,0]],"id":52385934},{"atb":[[9.8,0],[14.5,0]],"id":52385903},{"atb":[[3.45,0],[2.98,0]],"id":52385904},{"atb":[[18,0],[26,0]],"id":52385936},{"atb":[[9.8,0],[14.5,0]],"id":52385931},{"atb":[[3.45,0],[2.98,0]],"id":52385932}],"con":true,"img":false}]}
{"op":"mcm","clk":"11449436214","pt":1717309109609,"mc":[{"id":"1.229554892","rc":[{"atb":[[18,14.34],[26,4.18]],"id":52385907},{"atb":[[3.85,85.58],[4.7,28.25]],"id":52385909},{"atb":[[16,16.26],[22,4.97]],"id":52385918},{"atb":[[36,2.98],[23,11.08]],"id":52385920},{"atb":[[550,0.44],[650,0.16]],"id":52385917},{"atb":[[36,2.98],[23,11.08]],"id":52385923},{"atb":[[3.85,85.58],[4.7,28.25]],"id":52385934},{"atb":[[18,14.34],[26,4.18]],"id":52385936},{"atb":[[9.8,27.71],[14.5,7.74]],"id":52385931},{"atb":[[3.45,42.66],[2.98,123.18]],"id":52385932}],"con":true,"img":false}]}
{"op":"mcm","clk":"11449436224","pt":1717309109717,"mc":[{"id":"1.229554892","rc":[{"atb":[[550,0.49],[650,0.16]],"id":52385886},{"atb":[[16.5,6.74],[11.5,23.22]],"id":52385888},{"atb":[[7.4,38.1],[9.4,12.44]],"id":52385889},{"atb":[[9.2,29.74],[13,8.71]],"id":52385882},{"atb":[[16.5,6.74],[11.5,23.22]],"id":52385884},{"atb":[[2.96,53.33],[2.76,138.58]],"id":52385895},{"atb":[[2.96,53.33],[2.76,138.58]],"id":52385891},{"atb":[[17.5,6.33],[12.5,21.2]],"id":52385893},{"atb":[[9.8,27.71],[14.5,7.74]],"id":52385903},{"atb":[[3.45,42.66],[2.98,123.18]],"id":52385904}],"con":true,"img":false}]}
{"op":"mcm","clk":"11449444482","pt":1717309238761,"mc":[{"id":"1.229554892","rc":[{"atb":[[3.4,0],[3.15,0],[3.9,0],[3.65,0]],"id":52385895}],"con":true,"img":false}]}
{"op":"mcm","clk":"11449444525","pt":1717309239435,"mc":[{"id":"1.229554892","rc":[{"atb":[[3.8,9.34],[3.55,20.52],[3.3,34.12],[3.05,51.04]],"id":52385895}],"con":true,"img":false}]}
{"op":"mcm","clk":"11449486653","pt":1717309749298,"mc":[{"id":"1.229554892","rc":[{"atb":[[4,0],[3.25,0],[3.5,0],[3.75,0]],"id":52385891}],"con":true,"img":false}]}
{"op":"mcm","clk":"11449486698","pt":1717309749976,"mc":[{"id":"1.229554892","rc":[{"atb":[[4,8.72],[3.25,46.51],[3.5,31.39],[3.75,19.02]],"id":52385891}],"con":true,"img":false}]}
{"op":"mcm","clk":"11449497935","pt":1717309918839,"mc":[{"id":"1.229554892","rc":[{"atb":[[18,0],[26,0]],"id":52385907},{"atb":[[3.85,0],[4.7,0]],"id":52385909},{"atb":[[550,0.05],[650,0]],"id":52385886},{"atb":[[16,0],[22,0]],"id":52385918},{"atb":[[16.5,0],[11.5,0]],"id":52385888},{"atb":[[36,0],[23,0]],"id":52385920},{"atb":[[7.4,0],[9.4,0]],"id":52385889},{"atb":[[9.2,0],[13,0]],"id":52385882},{"atb":[[16.5,0],[11.5,0]],"id":52385884},{"atb":[[550,0],[650,0]],"id":52385917},{"atb":[[2.96,0],[2.76,0]],"id":52385895},{"atb":[[2.96,0],[2.76,0]],"id":52385891},{"atb":[[36,0],[23,0]],"id":52385923},{"atb":[[17.5,0],[12.5,0]],"id":52385893},{"atb":[[3.85,0],[4.7,0]],"id":52385934},{"atb":[[9.8,0],[14.5,0]],"id":52385903},{"atb":[[3.45,0],[2.98,0]],"id":52385904},{"atb":[[18,0],[26,0]],"id":52385936},{"atb":[[9.8,0],[14.5,0]],"id":52385931},{"atb":[[3.45,0],[2.98,0]],"id":52385932}],"con":true,"img":false}]}
{"op":"mcm","clk":"11449500037","pt":1717309954985,"mc":[{"id":"1.229554892","rc":[{"atb":[[18,14.34],[26,4.18]],"id":52385907},{"atb":[[3.85,85.58],[4.7,28.25]],"id":52385909},{"atb":[[16,16.26],[22,4.97]],"id":52385918},{"atb":[[36,2.98],[23,11.08]],"id":52385920},{"atb":[[550,0.44],[650,0.16]],"id":52385917},{"atb":[[36,2.98],[23,11.08]],"id":52385923},{"atb":[[3.85,85.58],[4.7,28.25]],"id":52385934},{"atb":[[18,14.34],[26,4.18]],"id":52385936},{"atb":[[9.8,27.71],[14.5,7.74]],"id":52385931},{"atb":[[3.45,42.66],[2.98,123.18]],"id":52385932}],"con":true,"img":false}]}
{"op":"mcm","clk":"11449500042","pt":1717309955045,"mc":[{"id":"1.229554892","rc":[{"atb":[[550,0.49],[650,0.16]],"id":52385886},{"atb":[[16.5,6.74],[11.5,23.22]],"id":52385888},{"atb":[[7.4,38.1],[9.4,12.44]],"id":52385889},{"atb":[[9.2,29.74],[13,8.71]],"id":52385882},{"atb":[[16.5,6.74],[11.5,23.22]],"id":52385884},{"atb":[[2.96,53.33],[2.76,138.58]],"id":52385895},{"atb":[[2.96,53.33],[2.76,138.58]],"id":52385891},{"atb":[[17.5,6.33],[12.5,21.2]],"id":52385893},{"atb":[[9.8,27.71],[14.5,7.74]],"id":52385903},{"atb":[[3.45,42.66],[2.98,123.18]],"id":52385904}],"con":true,"img":false}]}
{"op":"mcm","clk":"11449532194","pt":1717310488017,"mc":[{"id":"1.229554892","rc":[{"atb":[[18,0],[26,0]],"id":52385907},{"atb":[[3.85,0],[4.7,0]],"id":52385909},{"atb":[[550,0.05],[650,0]],"id":52385886},{"atb":[[16,0],[22,0]],"id":52385918},{"atb":[[16.5,0],[11.5,0]],"id":52385888},{"atb":[[36,0],[23,0]],"id":52385920},{"atb":[[7.4,0],[9.4,0]],"id":52385889},{"atb":[[9.2,0],[13,0]],"id":52385882},{"atb":[[16.5,0],[11.5,0]],"id":52385884},{"atb":[[550,0],[650,0]],"id":52385917},{"atb":[[2.96,0],[2.76,0]],"id":52385895},{"atb":[[2.96,0],[2.76,0]],"id":52385891},{"atb":[[36,0],[23,0]],"id":52385923},{"atb":[[17.5,0],[12.5,0]],"id":52385893},{"atb":[[3.85,0],[4.7,0]],"id":52385934},{"atb":[[9.8,0],[14.5,0]],"id":52385903},{"atb":[[3.45,0],[2.98,0]],"id":52385904},{"atb":[[18,0],[26,0]],"id":52385936},{"atb":[[9.8,0],[14.5,0]],"id":52385931},{"atb":[[3.45,0],[2.98,0]],"id":52385932}],"con":true,"img":false}]}
{"op":"mcm","clk":"11449533863","pt":1717310515777,"mc":[{"id":"1.229554892","rc":[{"atb":[[550,0.49],[650,0.16]],"id":52385886},{"atb":[[16.5,6.74],[11.5,23.22]],"id":52385888},{"atb":[[7.4,38.1],[9.4,12.44]],"id":52385889},{"atb":[[9.2,29.74],[13,8.71]],"id":52385882},{"atb":[[16.5,6.74],[11.5,23.22]],"id":52385884},{"atb":[[2.96,53.33],[2.76,138.58]],"id":52385895},{"atb":[[2.96,53.33],[2.76,138.58]],"id":52385891},{"atb":[[16,6.96],[11,24.39]],"id":52385893},{"atb":[[9.8,27.71],[14.5,7.74]],"id":52385903},{"atb":[[3.45,42.66],[2.98,123.18]],"id":52385904}],"con":true,"img":false}]}
{"op":"mcm","clk":"11449533871","pt":1717310515879,"mc":[{"id":"1.229554892","rc":[{"atb":[[16.5,15.73],[23,4.75]],"id":52385907},{"atb":[[3.85,85.58],[4.7,28.25]],"id":52385909},{"atb":[[20,5.5],[15,17.42]],"id":52385918},{"atb":[[19,13.55],[28,3.87]],"id":52385920},{"atb":[[550,0.44],[650,0.16]],"id":52385917},{"atb":[[19,13.55],[28,3.87]],"id":52385923},{"atb":[[3.85,85.58],[4.7,28.25]],"id":52385934},{"atb":[[16.5,15.73],[23,4.75]],"id":52385936},{"atb":[[9.8,27.71],[14.5,7.74]],"id":52385931},{"atb":[[3.45,42.66],[2.98,123.18]],"id":52385932}],"con":true,"img":false}]}
{"op":"mcm","clk":"11449546209","pt":1717310727222,"mc":[{"id":"1.229554892","rc":[{"atb":[[4.5,0],[5,0]],"id":52385904}],"con":true,"img":false}]}
{"op":"mcm","clk":"11449546214","pt":1717310727319,"mc":[{"id":"1.229554892","rc":[{"atb":[[6.8,0],[8.8,0],[7.8,0],[5.9,0]],"id":52385909},{"atb":[[65,0],[36,0],[46,0],[28,0]],"id":52385888},{"atb":[[22,0]],"id":52385882}],"con":true,"img":false}]}
{"op":"mcm","clk":"11449546277","pt":1717310728400,"mc":[{"id":"1.229554892","rc":[{"atb":[[7.2,12.66],[9.2,3.19],[6.2,20.12],[8.2,7.27]],"id":52385909},{"atb":[[70,0.38],[38,2.12],[48,1.11],[29,3.74]],"id":52385888},{"atb":[[23,4.76]],"id":52385882},{"atb":[[5.1,19.14],[4.6,29.07]],"id":52385904}],"con":true,"img":false}]}
{"op":"mcm","clk":"11449550478","pt":1717310796927,"mc":[{"id":"1.229554892","rc":[{"atb":[[16.5,0],[23,0]],"id":52385907},{"atb":[[3.85,0],[4.7,0]],"id":52385909},{"atb":[[20,0],[15,0]],"id":52385918},{"atb":[[550,0.05],[650,0]],"id":52385886},{"atb":[[16.5,0],[11.5,0]],"id":52385888},{"atb":[[19,0],[28,0]],"id":52385920},{"atb":[[7.4,0],[9.4,0]],"id":52385889},{"atb":[[9.2,0],[13,0]],"id":52385882},{"atb":[[16.5,0],[11.5,0]],"id":52385884},{"atb":[[550,0],[650,0]],"id":52385917},{"atb":[[2.96,0],[2.76,0]],"id":52385895},{"atb":[[19,0],[28,0]],"id":52385923},{"atb":[[2.96,0],[2.76,0]],"id":52385891},{"atb":[[16,0],[11,0]],"id":52385893},{"atb":[[3.85,0],[4.7,0]],"id":52385934},{"atb":[[9.8,0],[14.5,0]],"id":52385903},{"atb":[[3.45,0],[2.98,0]],"id":52385904},{"atb":[[16.5,0],[23,0]],"id":52385936},{"atb":[[9.8,0],[14.5,0]],"id":52385931},{"atb":[[3.45,0],[2.98,0]],"id":52385932}],"con":true,"img":false}]}
{"op":"mcm","clk":"11449553110","pt":1717310844499,"mc":[{"id":"1.229554892","rc":[{"atb":[[16.5,15.73],[23,4.75]],"id":52385907},{"atb":[[3.85,85.58],[4.7,28.25]],"id":52385909},{"atb":[[20,5.5],[15,17.42]],"id":52385918},{"atb":[[550,0.49],[650,0.16]],"id":52385886},{"atb":[[19,13.55],[28,3.87]],"id":52385920},{"atb":[[16.5,6.74],[11.5,23.22]],"id":52385888},{"atb":[[7.4,38.1],[9.4,12.44]],"id":52385889},{"atb":[[9.2,29.74],[13,8.71]],"id":52385882},{"atb":[[16.5,6.74],[11.5,23.22]],"id":52385884},{"atb":[[550,0.44],[650,0.16]],"id":52385917},{"atb":[[2.96,53.33],[2.76,138.58]],"id":52385895},{"atb":[[2.96,53.33],[2.76,138.58]],"id":52385891},{"atb":[[19,13.55],[28,3.87]],"id":52385923},{"atb":[[16,6.96],[11,24.39]],"id":52385893},{"atb":[[3.85,85.58],[4.7,28.25]],"id":52385934},{"atb":[[9.8,27.71],[14.5,7.74]],"id":52385903},{"atb":[[3.45,42.66],[2.98,123.18]],"id":52385904},{"atb":[[16.5,15.73],[23,4.75]],"id":52385936},{"atb":[[9.8,27.71],[14.5,7.74]],"id":52385931},{"atb":[[3.45,42.66],[2.98,123.18]],"id":52385932}],"con":true,"img":false}]}
{"op":"mcm","clk":"11449566096","pt":1717311084093,"mc":[{"id":"1.229554892","rc":[{"atb":[[70,0],[38,0],[48,0],[29,0]],"id":52385888},{"atb":[[23,0]],"id":52385882}],"con":true,"img":false}]}
{"op":"mcm","clk":"11449566102","pt":1717311084190,"mc":[{"id":"1.229554892","rc":[{"atb":[[4,0],[3.25,0],[3.5,0],[3.75,0]],"id":52385891}],"con":true,"img":false}]}
{"op":"mcm","clk":"11449566109","pt":1717311084293,"mc":[{"id":"1.229554892","rc":[{"atb":[[7.2,0],[9.2,0],[6.2,0],[8.2,0]],"id":52385909},{"atb":[[3.8,0],[3.55,0],[3.3,0],[3.05,0]],"id":52385895},{"atb":[[5.1,0],[4.6,0]],"id":52385904}],"con":true,"img":false}]}
{"op":"mcm","clk":"11449566136","pt":1717311084760,"mc":[{"id":"1.229554892","rc":[{"atb":[[65,0.41],[36,2.24],[46,1.16],[28,3.88]],"id":52385888},{"atb":[[22,4.98]],"id":52385882}],"con":true,"img":false}]}
{"op":"mcm","clk":"11449566141","pt":1717311084908,"mc":[{"id":"1.229554892","rc":[{"atb":[[4,8.72],[3.25,46.51],[3.5,31.39],[3.75,19.02]],"id":52385891}],"con":true,"img":false}]}
{"op":"mcm","clk":"11449566144","pt":1717311084958,"mc":[{"id":"1.229554892","rc":[{"atb":[[4.5,29.89],[5,19.62]],"id":52385904}],"con":true,"img":false}]}
{"op":"mcm","clk":"11449566149","pt":1717311085065,"mc":[{"id":"1.229554892","rc":[{"atb":[[6.8,13.53],[8.8,3.35],[7.8,7.7],[5.9,21.36]],"id":52385909},{"atb":[[3.4,32.7],[3.15,48.67],[3.9,9.02],[3.65,19.74]],"id":52385895}],"con":true,"img":false}]}
{"op":"mcm","clk":"11449566877","pt":1717311098603,"mc":[{"id":"1.229554892","rc":[{"atb":[[3.4,0],[3.15,0],[3.9,0],[3.65,0]],"id":52385895}],"con":true,"img":false}]}
{"op":"mcm","clk":"11449566922","pt":1717311099321,"mc":[{"id":"1.229554892","rc":[{"atb":[[3.8,9.34],[3.55,20.52],[3.3,34.12],[3.05,51.04]],"id":52385895}],"con":true,"img":false}]}
{"op":"mcm","clk":"11449590968","pt":1717311521095,"mc":[{"id":"1.229554892","rc":[{"atb":[[1.02,107.37]],"id":52385907},{"atb":[[1.04,82.65]],"id":52385909},{"atb":[[1.02,150.83]],"id":52385886},{"atb":[[1.04,103.96]],"id":52385918},{"atb":[[1.02,143.16]],"id":52385888},{"atb":[[1.04,115.89]],"id":52385920},{"atb":[[1.02,155.94]],"id":52385889},{"atb":[[1.03,158.5]],"id":52385882},{"atb":[[1.04,69.87]],"id":52385884},{"atb":[[1.04,79.25]],"id":52385917},{"atb":[[1.04,109.92]],"id":52385895},{"atb":[[1.03,165.31]],"id":52385891},{"atb":[[1.03,70.72]],"id":52385923},{"atb":[[1.02,155.94]],"id":52385893},{"atb":[[1.02,127.82]],"id":52385934},{"atb":[[1.03,125.26]],"id":52385903},{"atb":[[1.03,80.1]],"id":52385904},{"atb":[[1.03,115.89]],"id":52385936},{"atb":[[1.03,86.91]],"id":52385931},{"atb":[[1.04,71.58]],"id":52385932}],"con":true,"img":false}]}
{"op":"mcm","clk":"11449601391","pt":1717311718543,"mc":[{"id":"1.229554892","rc":[{"atb":[[16.5,0],[23,0]],"id":52385907},{"atb":[[3.85,0],[4.7,0]],"id":52385909},{"atb":[[550,0.05],[650,0]],"id":52385886},{"atb":[[20,0],[15,0]],"id":52385918},{"atb":[[19,0],[28,0]],"id":52385920},{"atb":[[16.5,0],[11.5,0]],"id":52385888},{"atb":[[7.4,0],[9.4,0]],"id":52385889},{"atb":[[9.2,0],[13,0]],"id":52385882},{"atb":[[16.5,0],[11.5,0]],"id":52385884},{"atb":[[550,0],[650,0]],"id":52385917},{"atb":[[2.96,0],[2.76,0]],"id":52385895},{"atb":[[2.96,0],[2.76,0]],"id":52385891},{"atb":[[19,0],[28,0]],"id":52385923},{"atb":[[16,0],[11,0]],"id":52385893},{"atb":[[3.85,0],[4.7,0]],"id":52385934},{"atb":[[9.8,0],[14.5,0]],"id":52385903},{"atb":[[3.45,0],[2.98,0]],"id":52385904},{"atb":[[16.5,0],[23,0]],"id":52385936},{"atb":[[9.8,0],[14.5,0]],"id":52385931},{"atb":[[3.45,0],[2.98,0]],"id":52385932}],"con":true,"img":false}]}
{"op":"mcm","clk":"11449603720","pt":1717311762398,"mc":[{"id":"1.229554892","rc":[{"atb":[[16.5,15.73],[23,4.75]],"id":52385907},{"atb":[[3.85,85.58],[4.7,28.25]],"id":52385909},{"atb":[[550,0.49],[650,0.16]],"id":52385886},{"atb":[[20,5.5],[15,17.42]],"id":52385918},{"atb":[[16.5,6.74],[11.5,23.22]],"id":52385888},{"atb":[[19,13.55],[28,3.87]],"id":52385920},{"atb":[[7.4,38.1],[9.4,12.44]],"id":52385889},{"atb":[[9.2,29.74],[13,8.71]],"id":52385882},{"atb":[[16.5,6.74],[11.5,23.22]],"id":52385884},{"atb":[[550,0.44],[650,0.16]],"id":52385917},{"atb":[[2.96,53.33],[2.76,138.58]],"id":52385895},{"atb":[[2.96,53.33],[2.76,138.58]],"id":52385891},{"atb":[[19,13.55],[28,3.87]],"id":52385923},{"atb":[[16,6.96],[11,24.39]],"id":52385893},{"atb":[[3.85,85.58],[4.7,28.25]],"id":52385934},{"atb":[[9.8,27.71],[14.5,7.74]],"id":52385903},{"atb":[[3.45,42.66],[2.98,123.18]],"id":52385904},{"atb":[[16.5,15.73],[23,4.75]],"id":52385936},{"atb":[[9.8,27.71],[14.5,7.74]],"id":52385931},{"atb":[[3.45,42.66],[2.98,123.18]],"id":52385932}],"con":true,"img":false}]}
{"op":"mcm","clk":"11449635263","pt":1717312448506,"mc":[{"id":"1.229554892","rc":[{"atb":[[4,0],[3.25,0],[3.5,0],[3.75,0]],"id":52385891}],"con":true,"img":false}]}
{"op":"mcm","clk":"11449635287","pt":1717312449175,"mc":[{"id":"1.229554892","rc":[{"atb":[[4,8.72],[3.25,46.51],[3.5,31.39],[3.75,19.02]],"id":52385891}],"con":true,"img":false}]}
{"op":"mcm","clk":"11449638300","pt":1717312527089,"mc":[{"id":"1.229554892","rc":[{"atb":[[6.8,0],[8.8,0],[7.8,0],[5.9,0]],"id":52385909}],"con":true,"img":false}]}
{"op":"mcm","clk":"11449638302","pt":1717312527189,"mc":[{"id":"1.229554892","rc":[{"atb":[[4.5,0],[5,0]],"id":52385904}],"con":true,"img":false}]}
{"op":"mcm","clk":"11449638327","pt":1717312527808,"mc":[{"id":"1.229554892","rc":[{"atb":[[7.2,12.66],[9.2,3.19],[6.2,20.12],[8.2,7.27]],"id":52385909}],"con":true,"img":false}]}
{"op":"mcm","clk":"11449638329","pt":1717312527909,"mc":[{"id":"1.229554892","rc":[{"atb":[[5.1,19.14],[4.6,29.07]],"id":52385904}],"con":true,"img":false}]}
{"op":"mcm","clk":"11449639286","pt":1717312554827,"mc":[{"id":"1.229554892","rc":[{"atb":[[16.5,0],[23,0]],"id":52385907},{"atb":[[3.85,0],[4.7,0]],"id":52385909},{"atb":[[20,0],[15,0]],"id":52385918},{"atb":[[550,0.05],[650,0]],"id":52385886},{"atb":[[16.5,0],[11.5,0]],"id":52385888},{"atb":[[19,0],[28,0]],"id":52385920},{"atb":[[7.4,0],[9.4,0]],"id":52385889},{"atb":[[9.2,0],[13,0]],"id":52385882},{"atb":[[16.5,0],[11.5,0]],"id":52385884},{"atb":[[550,0],[650,0]],"id":52385917},{"atb":[[2.96,0],[2.76,0]],"id":52385895},{"atb":[[2.96,0],[2.76,0]],"id":52385891},{"atb":[[19,0],[28,0]],"id":52385923},{"atb":[[16,0],[11,0]],"id":52385893},{"atb":[[3.85,0],[4.7,0]],"id":52385934},{"atb":[[9.8,0],[14.5,0]],"id":52385903},{"atb":[[3.45,0],[2.98,0]],"id":52385904},{"atb":[[16.5,0],[23,0]],"id":52385936},{"atb":[[9.8,0],[14.5,0]],"id":52385931},{"atb":[[3.45,0],[2.98,0]],"id":52385932}],"con":true,"img":false}]}
{"op":"mcm","clk":"11449639756","pt":1717312566697,"mc":[{"id":"1.229554892","rc":[{"atb":[[550,0.49],[650,0.16]],"id":52385886},{"atb":[[16.5,6.74],[11.5,23.22]],"id":52385888},{"atb":[[7.4,38.1],[9.4,12.44]],"id":52385889},{"atb":[[9.2,29.74],[13,8.71]],"id":52385882},{"atb":[[16.5,6.74],[11.5,23.22]],"id":52385884},{"atb":[[2.96,53.33],[2.76,138.58]],"id":52385895},{"atb":[[2.96,53.33],[2.76,138.58]],"id":52385891},{"atb":[[16,6.96],[11,24.39]],"id":52385893},{"atb":[[9.8,27.71],[14.5,7.74]],"id":52385903},{"atb":[[3.45,42.66],[2.98,123.18]],"id":52385904}],"con":true,"img":false}]}
{"op":"mcm","clk":"11449639761","pt":1717312566802,"mc":[{"id":"1.229554892","rc":[{"atb":[[16.5,15.73],[23,4.75]],"id":52385907},{"atb":[[3.85,85.58],[4.7,28.25]],"id":52385909},{"atb":[[20,5.5],[15,17.42]],"id":52385918},{"atb":[[19,13.55],[28,3.87]],"id":52385920},{"atb":[[550,0.44],[650,0.16]],"id":52385917},{"atb":[[19,13.55],[28,3.87]],"id":52385923},{"atb":[[3.85,85.58],[4.7,28.25]],"id":52385934},{"atb":[[16.5,15.73],[23,4.75]],"id":52385936},{"atb":[[9.8,27.71],[14.5,7.74]],"id":52385931},{"atb":[[3.45,42.66],[2.98,123.18]],"id":52385932}],"con":true,"img":false}]}
{"op":"mcm","clk":"11449652040","pt":1717312860343,"mc":[{"id":"1.229554892","rc":[{"atb":[[36,2.86]],"id":52385907},{"atb":[[4.5,28.57]],"id":52385909},{"atl":[[340,2]],"id":52385909},{"atb":[[50,2.04]],"id":52385918},{"atb":[[270,2]],"id":52385886},{"atb":[[75,2]],"id":52385920},{"atb":[[32,3.23]],"id":52385888},{"atb":[[9,12.5]],"id":52385889},{"atl":[[430,2]],"id":52385889},{"atb":[[22,9.74]],"id":52385882},{"atb":[[17,6.25]],"id":52385884},{"atb":[[330,2]],"id":52385917},{"atb":[[1.35,109.93]],"id":52385895},{"atl":[[95,2]],"id":52385895},{"atb":[[75,2]],"id":52385923},{"atb":[[2.18,84.75]],"id":52385891},{"atl":[[100,2]],"id":52385891},{"atb":[[16.5,6.45]],"id":52385893},{"atb":[[4.4,29.41]],"id":52385934},{"atl":[[330,2]],"id":52385934},{"atb":[[19.5,5.41]],"id":52385903},{"atb":[[34,3.03]],"id":52385936},{"atb":[[3,50]],"id":52385904},{"atl":[[250,2]],"id":52385904},{"atb":[[15,7.14]],"id":52385931},{"atb":[[1.35,71.58]],"id":52385932},{"atl":[[220,2]],"id":52385932}],"con":true,"img":false}]}
{"op":"mcm","clk":"11449652785","pt":1717312877257,"mc":[{"id":"1.229554892","rc":[{"atb":[[4.4,0],[4.2,31.25]],"id":52385934}],"con":true,"img":false}]}
{"op":"mcm","clk":"11449654404","pt":1717312915080,"mc":[{"id":"1.229554892","rc":[{"atb":[[4.4,29.41],[4.2,0]],"id":52385934}],"con":true,"img":false}]}
{"op":"mcm","clk":"11449654588","pt":1717312920193,"mc":[{"id":"1.229554892","rc":[{"atb":[[4.2,31.25]],"id":52385934}],"con":true,"img":false}]}
{"op":"mcm","clk":"11449654591","pt":1717312920294,"mc":[{"id":"1.229554892","rc":[{"atb":[[4.4,0]],"id":52385934}],"con":true,"img":false}]}
{"op":"mcm","clk":"11449655960","pt":1717312955878,"mc":[{"id":"1.229554892","rc":[{"atb":[[16.5,0],[23,0]],"id":52385907},{"atb":[[3.85,0],[4.7,0]],"id":52385909},{"atb":[[550,0.05],[650,0]],"id":52385886},{"atb":[[20,0],[15,0]],"id":52385918},{"atb":[[16.5,0],[11.5,0]],"id":52385888},{"atb":[[19,0],[28,0]],"id":52385920},{"atb":[[7.4,0],[9.4,0]],"id":52385889},{"atb":[[9.2,0],[13,0]],"id":52385882},{"atb":[[16.5,0],[11.5,0]],"id":52385884},{"atb":[[550,0],[650,0]],"id":52385917},{"atb":[[2.96,0],[2.76,0]],"id":52385895},{"atb":[[2.96,0],[2.76,0]],"id":52385891},{"atb":[[19,0],[28,0]],"id":52385923},{"atb":[[16,0],[11,0]],"id":52385893},{"atb":[[3.85,0],[4.7,0]],"id":52385934},{"atb":[[9.8,0],[14.5,0]],"id":52385903},{"atb":[[16.5,0],[23,0]],"id":52385936},{"atb":[[3.45,0],[2.98,0]],"id":52385904},{"atb":[[9.8,0],[14.5,0]],"id":52385931},{"atb":[[3.45,0],[2.98,0]],"id":52385932}],"con":true,"img":false}]}
{"op":"mcm","clk":"11449655964","pt":1717312955983,"mc":[{"id":"1.229554892","rc":[{"atb":[[17,0],[8.2,13.89]],"id":52385884},{"atb":[[2.64,60.98],[4.2,0]],"id":52385934},{"atb":[[5.5,22.22],[15,0]],"id":52385931}],"con":true,"img":false}]}
{"op":"mcm","clk":"11449656393","pt":1717312966043,"mc":[{"id":"1.229554892","rc":[{"atb":[[16.5,15.73],[23,4.75]],"id":52385907},{"atb":[[3.85,85.58],[4.7,28.25]],"id":52385909},{"atb":[[20,5.5],[15,17.42]],"id":52385918},{"atb":[[19,13.55],[28,3.87]],"id":52385920},{"atb":[[550,0.44],[650,0.16]],"id":52385917},{"atb":[[19,13.55],[28,3.87]],"id":52385923},{"atb":[[3.85,85.58],[4.7,28.25]],"id":52385934},{"atb":[[16.5,15.73],[23,4.75]],"id":52385936},{"atb":[[9.8,27.71],[14.5,7.74]],"id":52385931},{"atb":[[3.45,42.66],[2.98,123.18]],"id":52385932}],"con":true,"img":false}]}
{"op":"mcm","clk":"11449656399","pt":1717312966144,"mc":[{"id":"1.229554892","rc":[{"atb":[[550,0.49],[650,0.16]],"id":52385886},{"atb":[[16.5,6.74],[11.5,23.22]],"id":52385888},{"atb":[[7.4,38.1],[9.4,12.44]],"id":52385889},{"atb":[[9.2,29.74],[13,8.71]],"id":52385882},{"atb":[[16.5,6.74],[11.5,23.22]],"id":52385884},{"atb":[[2.96,53.33],[2.76,138.58]],"id":52385895},{"atb":[[2.96,53.33],[2.76,138.58]],"id":52385891},{"atb":[[16,6.96],[11,24.39]],"id":52385893},{"atb":[[9.8,27.71],[14.5,7.74]],"id":52385903},{"atb":[[3.45,42.66],[2.98,123.18]],"id":52385904}],"con":true,"img":false}]}
{"op":"mcm","clk":"11449656405","pt":1717312966246,"mc":[{"id":"1.229554892","rc":[{"atb":[[2.64,0],[4.2,31.25]],"id":52385934},{"atb":[[5.5,0],[15,7.14]],"id":52385931}],"con":true,"img":false}]}
{"op":"mcm","clk":"11449656412","pt":1717312966301,"mc":[{"id":"1.229554892","rc":[{"atb":[[17,6.25]],"id":52385884}],"con":true,"img":false}]}
{"op":"mcm","clk":"11449656417","pt":1717312966401,"mc":[{"id":"1.229554892","rc":[{"atb":[[8.2,0]],"id":52385884}],"con":true,"img":false}]}
{"op":"mcm","clk":"11449658591","pt":1717313021391,"mc":[{"id":"1.229554892","rc":[{"atb":[[4.3,30.3],[4.2,0]],"id":52385934}],"con":true,"img":false}]}
{"op":"mcm","clk":"11449658601","pt":1717313021596,"mc":[{"id":"1.229554892","rc":[{"atl":[[90,2],[95,0]],"id":52385895}],"con":true,"img":false}]}
{"op":"mcm","clk":"11449658607","pt":1717313021704,"mc":[{"id":"1.229554892","rc":[{"atb":[[16,0],[18.5,0],[11,0],[13.5,0]],"id":52385889},{"atb":[[520,0],[570,0],[620,0],[670,0]],"id":52385917},{"atb":[[40,0],[20,0],[25,0],[30,0]],"id":52385903},{"atb":[[70,0],[38,0],[48,0],[29,0]],"id":52385936}],"con":true,"img":false}]}
{"op":"mcm","clk":"11449658614","pt":1717313021803,"mc":[{"id":"1.229554892","rc":[{"atb":[[550,0.44],[400,0],[450,0],[500,0]],"id":52385886},{"atb":[[8.6,13.16]],"id":52385889},{"atb":[[19.5,0],[15,7.14]],"id":52385903},{"atb":[[34,0],[24,4.35]],"id":52385936},{"atb":[[5.6,0],[5.1,0],[4.6,0],[4.1,0]],"id":52385932}],"con":true,"img":false}]}
{"op":"mcm","clk":"11449658622","pt":1717313021907,"mc":[{"id":"1.229554892","rc":[{"atb":[[9,0]],"id":52385889}],"con":true,"img":false}]}
{"op":"mcm","clk":"11449658648","pt":1717313022418,"mc":[{"id":"1.229554892","rc":[{"atb":[[17.5,1.59],[10,11.63],[12.5,6.82],[15,3.74]],"id":52385889},{"atb":[[540,0.15],[590,0.09],[640,0.04],[490,0.21]],"id":52385917},{"atb":[[40,0.67],[20,5.51],[25,3.27],[30,1.81]],"id":52385903},{"atb":[[70,0.38],[38,2.12],[48,1.11],[29,3.74]],"id":52385936}],"con":true,"img":false}]}
{"op":"mcm","clk":"11449658651","pt":1717313022518,"mc":[{"id":"1.229554892","rc":[{"atb":[[530,0.05],[380,0.28],[430,0.18],[480,0.11]],"id":52385886},{"atb":[[19,5.56],[15,0]],"id":52385903},{"atb":[[34,3.03]],"id":52385936},{"atb":[[5.2,12.46],[5.7,5.57],[4.2,32.7],[4.7,21.21]],"id":52385932}],"con":true,"img":false}]}
{"op":"mcm","clk":"11449658655","pt":1717313022622,"mc":[{"id":"1.229554892","rc":[{"atb":[[24,0]],"id":52385936}],"con":true,"img":false}]}
{"op":"mcm","clk":"11449658754","pt":1717313025294,"mc":[{"id":"1.229554892","rc":[{"atb":[[160,0],[80,0],[110,0],[55,0]],"id":52385920}],"con":true,"img":false}]}
{"op":"mcm","clk":"11449658759","pt":1717313025405,"mc":[{"id":"1.229554892","rc":[{"atb":[[75,0],[29,3.57]],"id":52385920}],"con":true,"img":false}]}
{"op":"mcm","clk":"11449658793","pt":1717313026018,"mc":[{"id":"1.229554892","rc":[{"atb":[[160,0.16],[80,0.99],[110,0.48],[55,1.94]],"id":52385920}],"con":true,"img":false}]}
{"op":"mcm","clk":"11449658803","pt":1717313026120,"mc":[{"id":"1.229554892","rc":[{"atb":[[75,2],[29,0]],"id":52385920}],"con":true,"img":false}]}
{"op":"mcm","clk":"11449658914","pt":1717313028426,"mc":[{"id":"1.229554892","rc":[{"atb":[[4.3,0],[4.2,31.25]],"id":52385934}],"con":true,"img":false}]}
{"op":"mcm","clk":"11449660245","pt":1717313059930,"mc":[{"id":"1.229554892","rc":[{"atb":[[7.2,0],[9.2,0],[6.2,0],[8.2,0]],"id":52385909},{"atb":[[530,0],[380,0],[430,0],[480,0]],"id":52385886},{"atb":[[540,0],[590,0],[640,0],[490,0]],"id":52385917},{"atb":[[5.1,0],[4.6,0]],"id":52385904}],"con":true,"img":false}]}
{"op":"mcm","clk":"11449660250","pt":1717313060029,"mc":[{"id":"1.229554892","rc":[{"atb":[[4.5,0],[4.7,55.28]],"id":52385909}],"con":true,"img":false}]}
{"op":"mcm","clk":"11449660289","pt":1717313060643,"mc":[{"id":"1.229554892","rc":[{"atb":[[9.6,3.04],[8.6,6.89],[7.6,11.89],[6.6,18.68]],"id":52385909},{"atb":[[520,0.05],[370,0.28],[420,0.19],[470,0.11]],"id":52385886},{"atb":[[530,0.15],[580,0.09],[630,0.04],[480,0.22]],"id":52385917},{"atb":[[5.2,18.68],[4.7,28.28]],"id":52385904}],"con":true,"img":false}]}
{"op":"mcm","clk":"11449660417","pt":1717313063837,"mc":[{"id":"1.229554892","rc":[{"atb":[[4.5,28.57],[4.2,0]],"id":52385934}],"con":true,"img":false}]}
{"op":"mcm","clk":"11449663865","pt":1717313137620,"mc":[{"id":"1.229554892","rc":[{"atb":[[4.6,27.78]],"id":52385934}],"con":true,"img":false}]}
{"op":"mcm","clk":"11449663868","pt":1717313137725,"mc":[{"id":"1.229554892","rc":[{"atb":[[4.5,0]],"id":52385934}],"con":true,"img":false}]}
{"op":"mcm","clk":"11449663881","pt":1717313138033,"mc":[{"id":"1.229554892","rc":[{"atb":[[32,0],[80,0],[42,0],[55,0]],"id":52385907},{"atb":[[17.5,0],[10,0],[12.5,0],[15,0]],"id":52385889},{"atb":[[34,0],[44,0],[22,4.76],[27,0]],"id":52385882},{"atb":[[4.5,28.57],[4.6,0]],"id":52385934},{"atb":[[5.2,0],[4.7,0]],"id":52385904}],"con":true,"img":false}]}
{"op":"mcm","clk":"11449663887","pt":1717313138137,"mc":[{"id":"1.229554892","rc":[{"atb":[[36,0],[24,4.35]],"id":52385907},{"atb":[[8.2,13.89]],"id":52385889},{"atb":[[13.5,8]],"id":52385882},{"atb":[[4.5,0],[4.6,27.78]],"id":52385934}],"con":true,"img":false}]}
{"op":"mcm","clk":"11449663893","pt":1717313138236,"mc":[{"id":"1.229554892","rc":[{"atb":[[8.6,0]],"id":52385889},{"atb":[[22,0]],"id":52385882}],"con":true,"img":false}]}
{"op":"mcm","clk":"11449663913","pt":1717313138751,"mc":[{"id":"1.229554892","rc":[{"atb":[[32,3.37],[80,0.33],[42,1.92],[55,0.97]],"id":52385907},{"atb":[[17.5,1.59],[10,11.63],[12.5,6.82],[15,3.74]],"id":52385889},{"atb":[[34,1.59],[44,0.61],[22,4.98],[27,3.02]],"id":52385882},{"atb":[[5.2,18.68],[4.7,28.28]],"id":52385904}],"con":true,"img":false}]}
{"op":"mcm","clk":"11449664094","pt":1717313143261,"mc":[{"id":"1.229554892","rc":[{"atb":[[16.5,0],[23,0]],"id":52385907},{"atb":[[3.85,0],[4.7,27.03]],"id":52385909},{"atb":[[550,0],[650,0]],"id":52385886},{"atb":[[20,0],[15,0]],"id":52385918},{"atb":[[19,0],[28,0]],"id":52385920},{"atb":[[16.5,0],[11.5,0]],"id":52385888},{"atb":[[7.4,0],[9.4,0]],"id":52385889},{"atb":[[9.2,0],[13,0]],"id":52385882},{"atb":[[16.5,0],[11.5,0]],"id":52385884},{"atb":[[550,0],[650,0]],"id":52385917},{"atb":[[2.96,0],[2.76,0]],"id":52385895},{"atb":[[2.96,0],[2.76,0]],"id":52385891},{"atb":[[19,0],[28,0]],"id":52385923},{"atb":[[16,0],[11,0]],"id":52385893},{"atb":[[4.5,28.57],[3.85,0],[4.6,0],[4.7,0]],"id":52385934},{"atb":[[9.8,0],[14.5,0]],"id":52385903},{"atb":[[3.45,0],[2.98,0]],"id":52385904},{"atb":[[16.5,0],[23,0]],"id":52385936},{"atb":[[9.8,0],[14.5,0]],"id":52385931},{"atb":[[3.45,0],[2.98,0]],"id":52385932}],"con":true,"img":false}]}
{"op":"mcm","clk":"11449664102","pt":1717313143365,"mc":[{"id":"1.229554892","rc":[{"atb":[[17,0],[8.4,13.51]],"id":52385884},{"atb":[[2.7,58.82]],"id":52385934},{"atb":[[15,0],[5.4,22.73]],"id":52385931}],"con":true,"img":false}]}
{"op":"mcm","clk":"11449664110","pt":1717313143466,"mc":[{"id":"1.229554892","rc":[{"atb":[[4.5,0]],"id":52385934}],"con":true,"img":false}]}
{"op":"mcm","clk":"11449664401","pt":1717313151163,"mc":[{"id":"1.229554892","rc":[{"atb":[[17.5,0],[10,0],[12.5,0],[15,0]],"id":52385889},{"atb":[[34,0],[44,0],[22,0],[27,0]],"id":52385882},{"atb":[[5.2,0],[4.7,0]],"id":52385904}],"con":true,"img":false}]}
{"op":"mcm","clk":"11449664406","pt":1717313151271,"mc":[{"id":"1.229554892","rc":[{"atb":[[3.55,39.22]],"id":52385889}],"con":true,"img":false}]}
{"op":"mcm","clk":"11449664409","pt":1717313151370,"mc":[{"id":"1.229554892","rc":[{"atb":[[8.2,0]],"id":52385889},{"atb":[[6,20]],"id":52385882}],"con":true,"img":false}]}
{"op":"mcm","clk":"11449664416","pt":1717313151476,"mc":[{"id":"1.229554892","rc":[{"atb":[[13.5,0]],"id":52385882}],"con":true,"img":false}]}
{"op":"mcm","clk":"11449664437","pt":1717313151831,"mc":[{"id":"1.229554892","rc":[{"atb":[[17,1.64],[12,7.14],[9.8,11.89],[14.5,3.88]],"id":52385889},{"atb":[[32,1.69],[42,0.64],[21,5.23],[26,3.14]],"id":52385882},{"atb":[[5.1,19.14],[4.6,29.07]],"id":52385904}],"con":true,"img":false}]}
{"op":"mcm","clk":"11449664536","pt":1717313153749,"mc":[{"id":"1.229554892","rc":[{"atb":[[3.8,0],[3.55,0],[3.3,0],[3.05,0]],"id":52385895},{"atb":[[4,0],[3.25,0],[3.5,0],[3.75,0]],"id":52385891}],"con":true,"img":false}]}
{"op":"mcm","clk":"11449664542","pt":1717313153851,"mc":[{"id":"1.229554892","rc":[{"atb":[[1.05,219.86]],"id":52385895},{"atb":[[1.64,156.25]],"id":52385891}],"con":true,"img":false}]}
{"op":"mcm","clk":"11449664548","pt":1717313153955,"mc":[{"id":"1.229554892","rc":[{"atb":[[1.35,0]],"id":52385895},{"atb":[[2.18,0]],"id":52385891}],"con":true,"img":false}]}
{"op":"mcm","clk":"11449664573","pt":1717313154470,"mc":[{"id":"1.229554892","rc":[{"atb":[[3.6,10.06],[3.1,37.37],[3.35,22.26],[2.94,53.93]],"id":52385895},{"atb":[[3.6,20.12],[3.85,9.18],[3.1,49.83],[3.35,33.39]],"id":52385891}],"con":true,"img":false}]}
{"op":"mcm","clk":"11449664581","pt":1717313154676,"mc":[{"id":"1.229554892","rc":[{"atb":[[1.05,0],[1.35,164.9]],"id":52385895},{"atb":[[1.64,0],[2.08,92.59]],"id":52385891}],"con":true,"img":false}]}
{"op":"mcm","clk":"11449665175","pt":1717313168775,"mc":[{"id":"1.229554892","rc":[{"atb":[[3.6,0],[3.85,0],[3.1,0],[3.35,0]],"id":52385891}],"con":true,"img":false}]}
{"op":"mcm","clk":"11449665189","pt":1717313168983,"mc":[{"id":"1.229554892","rc":[{"atb":[[1.64,156.25],[2.08,0]],"id":52385891}],"con":true,"img":false}]}
{"op":"mcm","clk":"11449665221","pt":1717313169494,"mc":[{"id":"1.229554892","rc":[{"atb":[[4,8.72],[3.25,46.51],[3.5,31.39],[3.75,19.02]],"id":52385891}],"con":true,"img":false}]}
{"op":"mcm","clk":"11449665228","pt":1717313169598,"mc":[{"id":"1.229554892","rc":[{"atb":[[2.08,92.59]],"id":52385891}],"con":true,"img":false}]}
{"op":"mcm","clk":"11449665240","pt":1717313169708,"mc":[{"id":"1.229554892","rc":[{"atb":[[1.64,0]],"id":52385891}],"con":true,"img":false}]}
{"op":"mcm","clk":"11449665349","pt":1717313172492,"mc":[{"id":"1.229554892","rc":[{"atb":[[40,2.56],[24,0]],"id":52385907},{"atb":[[8.2,13.89],[3.55,0]],"id":52385889}],"con":true,"img":false}]}
{"op":"mcm","clk":"11449665511","pt":1717313176513,"mc":[{"id":"1.229554892","rc":[{"atb":[[18,14.34],[26,4.18]],"id":52385907},{"atb":[[4.8,27.5],[3.9,84.1]],"id":52385909},{"atb":[[16,16.26],[22,4.97]],"id":52385918},{"atb":[[550,0.44],[650,0.16]],"id":52385886},{"atb":[[36,2.98],[23,11.08]],"id":52385920},{"atb":[[16.5,6.74],[11.5,23.22]],"id":52385888},{"atb":[[7.2,39.33],[9.2,12.74]],"id":52385889},{"atb":[[9.2,29.74],[13,8.71]],"id":52385882},{"atb":[[16.5,6.74],[11.5,23.22]],"id":52385884},{"atb":[[550,0.44],[650,0.16]],"id":52385917},{"atb":[[2.74,140.17],[2.94,107.82]],"id":52385895},{"atb":[[2.74,140.17],[2.94,53.88]],"id":52385891},{"atb":[[36,2.98],[23,11.08]],"id":52385923},{"atb":[[17,6.53],[12,22.17]],"id":52385893},{"atb":[[4.8,27.5],[3.9,84.1]],"id":52385934},{"atb":[[9.8,27.71],[14.5,7.74]],"id":52385903},{"atb":[[3.45,42.66],[2.98,123.18]],"id":52385904},{"atb":[[18,14.34],[26,4.18]],"id":52385936},{"atb":[[9.8,27.71],[14.5,7.74]],"id":52385931},{"atb":[[3.45,42.66],[2.98,123.18]],"id":52385932}],"con":true,"img":false}]}
{"op":"mcm","clk":"11449665552","pt":1717313177588,"mc":[{"id":"1.229554892","rc":[{"atb":[[17,6.25],[8.4,0]],"id":52385884},{"atb":[[4.6,27.78]],"id":52385934},{"atb":[[15,7.14],[5.4,0]],"id":52385931}],"con":true,"img":false}]}
{"op":"mcm","clk":"11449665557","pt":1717313177692,"mc":[{"id":"1.229554892","rc":[{"atb":[[2.7,0]],"id":52385934}],"con":true,"img":false}]}
{"op":"mcm","clk":"11449665913","pt":1717313185567,"mc":[{"id":"1.229554892","rc":[{"atb":[[20,5.26]],"id":52385882}],"con":true,"img":false}]}
{"op":"mcm","clk":"11449665916","pt":1717313185670,"mc":[{"id":"1.229554892","rc":[{"atb":[[6,0]],"id":52385882}],"con":true,"img":false}]}
{"op":"mcm","clk":"11449666142","pt":1717313191808,"mc":[{"id":"1.229554892","rc":[{"atb":[[40,0],[44,2.33]],"id":52385907},{"atb":[[270,0],[320,2]],"id":52385886},{"atb":[[50,0],[60,3.33]],"id":52385918},{"atb":[[75,0],[85,2]],"id":52385920},{"atl":[[430,0],[420,2]],"id":52385889},{"atb":[[330,0],[400,2]],"id":52385917},{"atb":[[75,0],[85,2]],"id":52385923},{"atb":[[16.5,0],[19,5.56]],"id":52385893},{"atb":[[34,0],[42,2.44]],"id":52385936}],"con":true,"img":false}]}
{"op":"mcm","clk":"11449666169","pt":1717313192217,"mc":[{"id":"1.229554892","rc":[{"atb":[[85,0],[44,0],[120,0],[60,2]],"id":52385918},{"atb":[[17,0],[12,0],[9.8,0],[14.5,0]],"id":52385889},{"atb":[[160,0],[80,0],[110,0],[55,0]],"id":52385923}],"con":true,"img":false}]}
{"op":"mcm","clk":"11449666177","pt":1717313192317,"mc":[{"id":"1.229554892","rc":[{"atb":[[23,4.55],[60,0]],"id":52385918},{"atb":[[36,5.84],[85,0]],"id":52385923}],"con":true,"img":false}]}
{"op":"mcm","clk":"11449666225","pt":1717313192894,"mc":[{"id":"1.229554892","rc":[{"atb":[[130,0.2],[65,1.22],[90,0.59],[46,2.32]],"id":52385918},{"atb":[[16.5,1.69],[9.6,12.17],[11.5,7.48],[14,4.02]],"id":52385889},{"atb":[[150,0.35],[75,1.41],[200,0.13],[100,0.8]],"id":52385923}],"con":true,"img":false}]}
{"op":"mcm","clk":"11449666574","pt":1717313200926,"mc":[{"id":"1.229554892","rc":[{"atl":[[85,2]],"id":52385895}],"con":true,"img":false}]}
{"op":"mcm","clk":"11449666578","pt":1717313201029,"mc":[{"id":"1.229554892","rc":[{"atl":[[90,0]],"id":52385895}],"con":true,"img":false}]}
{"op":"mcm","clk":"11449667339","pt":1717313215510,"mc":[{"id":"1.229554892","rc":[{"atb":[[18,0],[26,0]],"id":52385907},{"atb":[[4.8,0],[3.9,0]],"id":52385909},{"atb":[[16,0],[22,0]],"id":52385918},{"atb":[[550,0],[650,0]],"id":52385886},{"atb":[[36,0],[23,0]],"id":52385920},{"atb":[[16.5,0],[11.5,0]],"id":52385888},{"atb":[[7.2,0],[9.2,0]],"id":52385889},{"atb":[[9.2,0],[13,0]],"id":52385882},{"atb":[[16.5,0],[11.5,0]],"id":52385884},{"atb":[[550,0],[650,0]],"id":52385917},{"atb":[[2.74,0],[2.94,53.93]],"id":52385895},{"atb":[[36,2.86],[23,0]],"id":52385923},{"atb":[[2.74,0],[2.94,0]],"id":52385891},{"atb":[[17,0],[12,0]],"id":52385893},{"atb":[[4.8,0],[3.9,0]],"id":52385934},{"atb":[[9.8,0],[14.5,0]],"id":52385903},{"atb":[[18,0],[26,0]],"id":52385936},{"atb":[[3.45,0],[2.98,0]],"id":52385904},{"atb":[[9.8,0],[14.5,0]],"id":52385931},{"atb":[[3.45,0],[2.98,0]],"id":52385932}],"con":true,"img":false}]}
{"op":"mcm","clk":"11449667351","pt":1717313215726,"mc":[{"id":"1.229554892","rc":[{"atb":[[17,0],[8.4,13.51]],"id":52385884},{"atb":[[2.72,58.14],[4.6,0]],"id":52385934},{"atb":[[5.6,21.74],[15,0]],"id":52385931}],"con":true,"img":false}]}
{"op":"mcm","clk":"11449667853","pt":1717313226156,"mc":[{"id":"1.229554892","rc":[{"atb":[[23,0],[60,2]],"id":52385918},{"atb":[[36,0],[95,2]],"id":52385923}],"con":true,"img":false}]}
{"op":"mcm","clk":"11449668616","pt":1717313241058,"mc":[{"id":"1.229554892","rc":[{"atb":[[17,15.24],[24,4.54]],"id":52385907},{"atb":[[3.95,82.67],[4.9,26.8]],"id":52385909},{"atb":[[19.5,5.65],[14.5,18.06]],"id":52385918},{"atb":[[550,0.44],[650,0.16]],"id":52385886},{"atb":[[19.5,13.18],[29,3.73]],"id":52385920},{"atb":[[17,6.53],[12,22.17]],"id":52385888},{"atb":[[7.2,39.33],[9.2,12.74]],"id":52385889},{"atb":[[9.2,29.74],[13,8.71]],"id":52385882},{"atb":[[17,6.53],[12,22.17]],"id":52385884},{"atb":[[550,0.44],[650,0.16]],"id":52385917},{"atb":[[2.92,54.44],[2.72,141.8]],"id":52385895},{"atb":[[19.5,13.18],[29,3.73]],"id":52385923},{"atb":[[2.92,54.44],[2.72,141.8]],"id":52385891},{"atb":[[10.5,25.67],[15.5,7.2]],"id":52385893},{"atb":[[3.95,82.67],[4.9,26.8]],"id":52385934},{"atb":[[10,27.1],[15,7.46]],"id":52385903},{"atb":[[17,15.24],[24,4.54]],"id":52385936},{"atb":[[3.45,42.66],[2.98,123.18]],"id":52385904},{"atb":[[10,27.1],[15,7.46]],"id":52385931},{"atb":[[3.45,42.66],[2.98,123.18]],"id":52385932}],"con":true,"img":false}]}
{"op":"mcm","clk":"11449668636","pt":1717313241266,"mc":[{"id":"1.229554892","rc":[{"atb":[[17.5,6.06],[8.4,0]],"id":52385884},{"atb":[[2.72,0],[4.6,27.78]],"id":52385934},{"atb":[[5.6,0],[15.5,6.9]],"id":52385931}],"con":true,"img":false}]}
{"op":"mcm","clk":"11449670108","pt":1717313273114,"mc":[{"id":"1.229554892","rc":[{"atb":[[17,0],[24,0]],"id":52385907},{"atb":[[3.95,0],[4.9,0]],"id":52385909},{"atb":[[19.5,0],[14.5,0]],"id":52385918},{"atb":[[550,0],[650,0]],"id":52385886},{"atb":[[17,0],[12,0]],"id":52385888},{"atb":[[19.5,0],[29,0]],"id":52385920},{"atb":[[7.2,0],[9.2,0]],"id":52385889},{"atb":[[9.2,0],[13,0]],"id":52385882},{"atb":[[17,0],[12,0]],"id":52385884},{"atb":[[550,0],[650,0]],"id":52385917},{"atb":[[2.92,0],[2.72,0]],"id":52385895},{"atb":[[2.92,0],[2.72,0]],"id":52385891},{"atb":[[19.5,0],[29,0]],"id":52385923},{"atb":[[10.5,0],[15.5,0]],"id":52385893},{"atb":[[3.95,0],[4.9,0]],"id":52385934},{"atb":[[10,0],[15,0]],"id":52385903},{"atb":[[3.45,0],[2.98,0]],"id":52385904},{"atb":[[17,0],[24,0]],"id":52385936},{"atb":[[10,0],[15,0]],"id":52385931},{"atb":[[3.45,0],[2.98,0]],"id":52385932}],"con":true,"img":false}]}
{"op":"mcm","clk":"11449670111","pt":1717313273218,"mc":[{"id":"1.229554892","rc":[{"atb":[[17.5,0],[8.4,13.51]],"id":52385884},{"atb":[[2.72,58.14]],"id":52385934},{"atb":[[5.6,21.74],[15.5,0]],"id":52385931}],"con":true,"img":false}]}
{"op":"mcm","clk":"11449670116","pt":1717313273274,"mc":[{"id":"1.229554892","rc":[{"atb":[[4.6,0]],"id":52385934}],"con":true,"img":false}]}
{"op":"mcm","clk":"11449671575","pt":1717313301842,"mc":[{"id":"1.229554892","rc":[{"atb":[[18.5,13.93],[27,4.01]],"id":52385907},{"atb":[[3.95,82.67],[4.9,26.8]],"id":52385909},{"atb":[[550,0.44],[650,0.16]],"id":52385886},{"atb":[[16,16.26],[22,4.97]],"id":52385918},{"atb":[[17,6.53],[12,22.17]],"id":52385888},{"atb":[[38,2.82],[24,10.6]],"id":52385920},{"atb":[[7.2,39.33],[9.2,12.74]],"id":52385889},{"atb":[[9.2,29.74],[13,8.71]],"id":52385882},{"atb":[[17,6.53],[12,22.17]],"id":52385884},{"atb":[[550,0.44],[650,0.16]],"id":52385917},{"atb":[[2.92,54.44],[2.72,141.8]],"id":52385895},{"atb":[[38,2.82],[24,10.6]],"id":52385923},{"atb":[[2.92,54.44],[2.72,141.8]],"id":52385891},{"atb":[[17,6.53],[12,22.17]],"id":52385893},{"atb":[[3.95,82.67],[4.9,26.8]],"id":52385934},{"atb":[[10,27.1],[15,7.46]],"id":52385903},{"atb":[[3.45,42.66],[2.98,123.18]],"id":52385904},{"atb":[[18.5,13.93],[27,4.01]],"id":52385936},{"atb":[[10,27.1],[15,7.46]],"id":52385931},{"atb":[[3.45,42.66],[2.98,123.18]],"id":52385932}],"con":true,"img":false}]}
{"op":"mcm","clk":"11449671581","pt":1717313301949,"mc":[{"id":"1.229554892","rc":[{"atb":[[17.5,6.06],[8.4,0]],"id":52385884},{"atb":[[4.6,27.78]],"id":52385934},{"atb":[[5.6,0],[15.5,6.9]],"id":52385931}],"con":true,"img":false}]}
{"op":"mcm","clk":"11449671587","pt":1717313302053,"mc":[{"id":"1.229554892","rc":[{"atb":[[2.72,0]],"id":52385934}],"con":true,"img":false}]}
{"op":"mcm","clk":"11449673061","pt":1717313329596,"mc":[{"id":"1.229554892","rc":[{"atb":[[18.5,0],[27,0]],"id":52385907},{"atb":[[3.95,0],[4.9,0]],"id":52385909},{"atb":[[16,0],[22,0]],"id":52385918},{"atb":[[550,0],[650,0]],"id":52385886},{"atb":[[17,0],[12,0]],"id":52385888},{"atb":[[38,0],[24,0]],"id":52385920},{"atb":[[7.2,0],[9.2,0]],"id":52385889},{"atb":[[9.2,0],[13,0]],"id":52385882},{"atb":[[17,0],[12,0]],"id":52385884},{"atb":[[550,0],[650,0]],"id":52385917},{"atb":[[2.92,0],[2.72,0]],"id":52385895},{"atb":[[2.92,0],[2.72,0]],"id":52385891},{"atb":[[38,0],[24,0]],"id":52385923},{"atb":[[17,0],[12,0]],"id":52385893},{"atb":[[3.95,0],[4.9,0]],"id":52385934},{"atb":[[10,0],[15,0]],"id":52385903},{"atb":[[18.5,0],[27,0]],"id":52385936},{"atb":[[3.45,0],[2.98,0]],"id":52385904},{"atb":[[10,0],[15,0]],"id":52385931},{"atb":[[3.45,0],[2.98,0]],"id":52385932}],"con":true,"img":false}]}
{"op":"mcm","clk":"11449673069","pt":1717313329752,"mc":[{"id":"1.229554892","rc":[{"atb":[[17.5,0],[8.4,13.51]],"id":52385884},{"atb":[[2.72,58.14],[4.6,0]],"id":52385934},{"atb":[[5.6,21.74],[15.5,0]],"id":52385931}],"con":true,"img":false}]}
{"op":"mcm","clk":"11449673650","pt":1717313340557,"mc":[{"id":"1.229554892","rc":[{"atb":[[550,0.44],[650,0.16]],"id":52385886},{"atb":[[17,6.53],[12,22.17]],"id":52385888},{"atb":[[7.2,39.33],[9.2,12.74]],"id":52385889},{"atb":[[9.2,29.74],[13,8.71]],"id":52385882},{"atb":[[17,6.53],[12,22.17]],"id":52385884},{"atb":[[2.92,54.44],[2.72,141.8]],"id":52385895},{"atb":[[2.92,54.44],[2.72,141.8]],"id":52385891},{"atb":[[17,6.53],[12,22.17]],"id":52385893},{"atb":[[10,27.1],[15,7.46]],"id":52385903},{"atb":[[3.45,42.66],[2.98,123.18]],"id":52385904}],"con":true,"img":false}]}
{"op":"mcm","clk":"11449674328","pt":1717313351382,"mc":[{"id":"1.229554892","rc":[{"atb":[[18.5,13.93],[27,4.01]],"id":52385907},{"atb":[[3.95,82.67],[4.9,26.8]],"id":52385909},{"atb":[[16,16.26],[22,4.97]],"id":52385918},{"atb":[[38,2.82],[24,10.6]],"id":52385920},{"atb":[[550,0.44],[650,0.16]],"id":52385917},{"atb":[[38,2.82],[24,10.6]],"id":52385923},{"atb":[[3.95,82.67],[4.9,26.8]],"id":52385934},{"atb":[[18.5,13.93],[27,4.01]],"id":52385936},{"atb":[[10,27.1],[15,7.46]],"id":52385931},{"atb":[[3.45,42.66],[2.98,123.18]],"id":52385932}],"con":true,"img":false}]}
{"op":"mcm","clk":"11449674935","pt":1717313362244,"mc":[{"id":"1.229554892","rc":[{"atb":[[17.5,6.06],[8.4,0]],"id":52385884},{"atb":[[2.72,0],[4.6,27.78]],"id":52385934},{"atb":[[5.6,0],[15.5,6.9]],"id":52385931}],"con":true,"img":false}]}
{"op":"mcm","clk":"11449675497","pt":1717313371894,"mc":[{"id":"1.229554892","rc":[{"atb":[[40,0],[20,0],[25,0],[30,0]],"id":52385903},{"atb":[[70,0],[38,0],[48,0],[29,0]],"id":52385936}],"con":true,"img":false}]}
{"op":"mcm","clk":"11449675510","pt":1717313372098,"mc":[{"id":"1.229554892","rc":[{"atb":[[19,0],[15.5,6.9]],"id":52385903},{"atb":[[42,0],[28,3.7]],"id":52385936}],"con":true,"img":false}]}
{"op":"mcm","clk":"11449675549","pt":1717313372615,"mc":[{"id":"1.229554892","rc":[{"atb":[[32,1.69],[42,0.64],[21,5.23],[26,3.14]],"id":52385903}],"con":true,"img":false}]}
{"op":"mcm","clk":"11449675558","pt":1717313372717,"mc":[{"id":"1.229554892","rc":[{"atb":[[65,0.82],[36,2.99],[90,0.29],[46,1.74]],"id":52385936}],"con":true,"img":false}]}
{"op":"mcm","clk":"11449675729","pt":1717313375207,"mc":[{"id":"1.229554892","rc":[{"atb":[[160,0],[80,0],[110,0],[55,0]],"id":52385920}],"con":true,"img":false}]}
{"op":"mcm","clk":"11449675734","pt":1717313375310,"mc":[{"id":"1.229554892","rc":[{"atb":[[38,5.52]],"id":52385920}],"con":true,"img":false}]}
{"op":"mcm","clk":"11449675739","pt":1717313375410,"mc":[{"id":"1.229554892","rc":[{"atb":[[38,2.82],[85,0],[25,4.17]],"id":52385920}],"con":true,"img":false}]}
{"op":"mcm","clk":"11449675747","pt":1717313375515,"mc":[{"id":"1.229554892","rc":[{"atb":[[38,5.52],[25,0]],"id":52385920}],"con":true,"img":false}]}
{"op":"mcm","clk":"11449675754","pt":1717313375618,"mc":[{"id":"1.229554892","rc":[{"atb":[[38,2.82],[25,4.17]],"id":52385920}],"con":true,"img":false}]}
{"op":"mcm","clk":"11449675771","pt":1717313375923,"mc":[{"id":"1.229554892","rc":[{"atb":[[160,0.33],[80,1.32],[210,0.13],[110,0.72]],"id":52385920}],"con":true,"img":false}]}
{"op":"mcm","clk":"11449677601","pt":1717313404124,"mc":[{"id":"1.229554892","rc":[{"atb":[[20,5.26],[15.5,0]],"id":52385903},{"atb":[[42,2.44],[28,0]],"id":52385936}],"con":true,"img":false}]}
{"op":"mcm","clk":"11449677751","pt":1717313406252,"mc":[{"id":"1.229554892","rc":[{"atb":[[9.6,0],[8.6,0],[7.6,0],[6.6,0]],"id":52385909},{"atb":[[520,0],[370,0],[420,0],[470,0]],"id":52385886}],"con":true,"img":false}]}
{"op":"mcm","clk":"11449677756","pt":1717313406355,"mc":[{"id":"1.229554892","rc":[{"atb":[[4.8,26.32]],"id":52385909}],"con":true,"img":false}]}
{"op":"mcm","clk":"11449677762","pt":1717313406457,"mc":[{"id":"1.229554892","rc":[{"atb":[[4.7,0]],"id":52385909}],"con":true,"img":false}]}
{"op":"mcm","clk":"11449677792","pt":1717313406931,"mc":[{"id":"1.229554892","rc":[{"atb":[[6.8,18.04],[9.8,2.97],[8.8,6.71],[7.8,11.54]],"id":52385909},{"atb":[[550,0.59],[600,0.09],[650,0.2],[500,0.21]],"id":52385886}],"con":true,"img":false}]}
{"op":"mcm","clk":"11449677841","pt":1717313407547,"mc":[{"id":"1.229554892","rc":[{"atb":[[25,0],[100,2]],"id":52385920}],"con":true,"img":false}]}
{"op":"mcm","clk":"11449678831","pt":1717313421855,"mc":[{"id":"1.229554892","rc":[{"atl":[[95,2],[100,0]],"id":52385891}],"con":true,"img":false}]}
{"op":"mcm","clk":"11449678877","pt":1717313422158,"mc":[{"id":"1.229554892","rc":[{"atb":[[6.8,0],[9.8,0],[8.8,0],[7.8,0]],"id":52385909}],"con":true,"img":false}]}
{"op":"mcm","clk":"11449678883","pt":1717313422262,"mc":[{"id":"1.229554892","rc":[{"atb":[[4.8,0],[4.7,27.03]],"id":52385909}],"con":true,"img":false}]}
{"op":"mcm","clk":"11449678918","pt":1717313422881,"mc":[{"id":"1.229554892","rc":[{"atb":[[9.6,3.04],[8.6,6.89],[7.6,11.89],[6.6,18.68]],"id":52385909}],"con":true,"img":false}]}
{"op":"mcm","clk":"11449682883","pt":1717313476656,"mc":[{"id":"1.229554892","rc":[{"atb":[[32,0],[80,0],[42,0],[55,0]],"id":52385907}],"con":true,"img":false}]}
{"op":"mcm","clk":"11449682898","pt":1717313476861,"mc":[{"id":"1.229554892","rc":[{"atb":[[28,3.7]],"id":52385907}],"con":true,"img":false}]}
{"op":"mcm","clk":"11449682907","pt":1717313476967,"mc":[{"id":"1.229554892","rc":[{"atb":[[44,0]],"id":52385907}],"con":true,"img":false}]}
{"op":"mcm","clk":"11449682939","pt":1717313477388,"mc":[{"id":"1.229554892","rc":[{"atb":[[75,0.71],[40,2.68],[100,0.27],[50,1.6]],"id":52385907}],"con":true,"img":false}]}
{"op":"mcm","clk":"11449685438","pt":1717313507834,"mc":[{"id":"1.229554892","rc":[{"atb":[[48,2.13],[28,0]],"id":52385907}],"con":true,"img":false}]}
{"op":"mcm","clk":"11449697024","pt":1717313647925,"mc":[{"id":"1.229554892","rc":[{"atb":[[4,0],[3.25,0],[3.5,0],[3.75,0]],"id":52385891}],"con":true,"img":false}]}
{"op":"mcm","clk":"11449697103","pt":1717313648645,"mc":[{"id":"1.229554892","rc":[{"atb":[[3.6,20.12],[3.85,9.18],[3.1,49.83],[3.35,33.39]],"id":52385891}],"con":true,"img":false}]}
{"op":"mcm","clk":"11449697178","pt":1717313649528,"mc":[{"id":"1.229554892","rc":[{"atb":[[3.6,0],[3.85,0],[3.1,0],[3.35,0]],"id":52385891}],"con":true,"img":false}]}
{"op":"mcm","clk":"11449697225","pt":1717313650249,"mc":[{"id":"1.229554892","rc":[{"atb":[[4,8.72],[3.25,46.51],[3.5,31.39],[3.75,19.02]],"id":52385891}],"con":true,"img":false}]}
{"op":"mcm","clk":"11449702516","pt":1717313718031,"mc":[{"id":"1.229554892","rc":[{"atb":[[550,0.44],[600,0],[650,0.16],[500,0]],"id":52385886}],"con":true,"img":false}]}
{"op":"mcm","clk":"11449702569","pt":1717313718700,"mc":[{"id":"1.229554892","rc":[{"atb":[[630,0.08]],"id":52385886}],"con":true,"img":false}]}
{"op":"mcm","clk":"11449702574","pt":1717313718803,"mc":[{"id":"1.229554892","rc":[{"atb":[[530,0.2],[580,0.14],[680,0.04]],"id":52385886}],"con":true,"img":false}]}
{"op":"mcm","clk":"11449703761","pt":1717313733840,"mc":[{"id":"1.229554892","rc":[{"atb":[[18.5,0],[27,0]],"id":52385907},{"atb":[[3.95,0],[4.9,0]],"id":52385909},{"atb":[[550,0],[650,0]],"id":52385886},{"atb":[[16,0],[22,0]],"id":52385918},{"atb":[[38,0],[24,0]],"id":52385920},{"atb":[[17,0],[12,0]],"id":52385888},{"atb":[[7.2,0],[9.2,0]],"id":52385889},{"atb":[[9.2,0],[13,0]],"id":52385882},{"atb":[[17,0],[12,0]],"id":52385884},{"atb":[[550,0],[650,0]],"id":52385917},{"atb":[[2.92,0],[2.72,0]],"id":52385895},{"atb":[[2.92,0],[2.72,0]],"id":52385891},{"atb":[[38,0],[24,0]],"id":52385923},{"atb":[[17,0],[12,0]],"id":52385893},{"atb":[[3.95,0],[4.9,0]],"id":52385934},{"atb":[[10,0],[15,0]],"id":52385903},{"atb":[[18.5,0],[27,0]],"id":52385936},{"atb":[[3.45,0],[2.98,0]],"id":52385904},{"atb":[[10,0],[15,0]],"id":52385931},{"atb":[[3.45,0],[2.98,0]],"id":52385932}],"con":true,"img":false}]}
{"op":"mcm","clk":"11449703767","pt":1717313733941,"mc":[{"id":"1.229554892","rc":[{"atb":[[8.4,13.51]],"id":52385884},{"atb":[[2.72,58.14]],"id":52385934},{"atb":[[5.7,21.28],[15.5,0]],"id":52385931}],"con":true,"img":false}]}
{"op":"mcm","clk":"11449703776","pt":1717313733995,"mc":[{"id":"1.229554892","rc":[{"atb":[[17.5,0]],"id":52385884},{"atb":[[4.6,0]],"id":52385934}],"con":true,"img":false}]}
{"op":"mcm","clk":"11449706169","pt":1717313763344,"mc":[{"id":"1.229554892","rc":[{"atb":[[18.5,13.93],[27,4.01]],"id":52385907},{"atb":[[3.95,82.67],[4.9,26.8]],"id":52385909},{"atb":[[16,16.26],[22,4.97]],"id":52385918},{"atb":[[38,2.82],[24,10.6]],"id":52385920},{"atb":[[550,0.44],[650,0.16]],"id":52385917},{"atb":[[38,2.82],[24,10.6]],"id":52385923},{"atb":[[3.95,82.67],[4.9,26.8]],"id":52385934},{"atb":[[18.5,13.93],[27,4.01]],"id":52385936},{"atb":[[10,27.1],[15,7.46]],"id":52385931},{"atb":[[3.45,42.66],[2.98,123.18]],"id":52385932}],"con":true,"img":false}]}
{"op":"mcm","clk":"11449706177","pt":1717313763450,"mc":[{"id":"1.229554892","rc":[{"atb":[[550,0.44],[650,0.16]],"id":52385886},{"atb":[[17,6.53],[12,22.17]],"id":52385888},{"atb":[[7.2,39.33],[9.2,12.74]],"id":52385889},{"atb":[[9.2,29.74],[13,8.71]],"id":52385882},{"atb":[[17,6.53],[12,22.17]],"id":52385884},{"atb":[[2.92,54.44],[2.72,141.8]],"id":52385895},{"atb":[[2.92,54.44],[2.72,141.8]],"id":52385891},{"atb":[[17,6.53],[12,22.17]],"id":52385893},{"atb":[[10,27.1],[15,7.46]],"id":52385903},{"atb":[[3.45,42.66],[2.98,123.18]],"id":52385904}],"con":true,"img":false}]}
{"op":"mcm","clk":"11449706184","pt":1717313763553,"mc":[{"id":"1.229554892","rc":[{"atb":[[2.72,0],[4.6,27.78]],"id":52385934},{"atb":[[5.7,0],[15.5,6.9]],"id":52385931}],"con":true,"img":false}]}
{"op":"mcm","clk":"11449706194","pt":1717313763664,"mc":[{"id":"1.229554892","rc":[{"atb":[[17.5,6.06],[8.4,0]],"id":52385884}],"con":true,"img":false}]}
{"op":"mcm","clk":"11449706479","pt":1717313767062,"mc":[{"id":"1.229554892","rc":[{"atb":[[32,0],[42,0],[21,0],[26,0]],"id":52385903}],"con":true,"img":false}]}
{"op":"mcm","clk":"11449706488","pt":1717313767164,"mc":[{"id":"1.229554892","rc":[{"atb":[[20,0],[15.5,6.9]],"id":52385903}],"con":true,"img":false}]}
{"op":"mcm","clk":"11449706542","pt":1717313767732,"mc":[{"id":"1.229554892","rc":[{"atb":[[34,1.59],[44,0.61],[22,4.98],[27,3.02]],"id":52385903}],"con":true,"img":false}]}
{"op":"mcm","clk":"11449706630","pt":1717313768762,"mc":[{"id":"1.229554892","rc":[{"atb":[[3.6,0],[3.1,0],[3.35,0],[2.94,0]],"id":52385895},{"atb":[[4,0],[3.25,0],[3.5,0],[3.75,0]],"id":52385891}],"con":true,"img":false}]}
{"op":"mcm","clk":"11449706692","pt":1717313769429,"mc":[{"id":"1.229554892","rc":[{"atb":[[3.1,24.91],[3.35,11.13],[2.84,56.87],[2.94,40.45]],"id":52385895},{"atb":[[3.6,10.06],[3.1,37.37],[3.35,22.26],[2.94,53.93]],"id":52385891}],"con":true,"img":false}]}
{"op":"mcm","clk":"11449707757","pt":1717313781512,"mc":[{"id":"1.229554892","rc":[{"atb":[[75,0],[40,0],[100,0],[50,0]],"id":52385907}],"con":true,"img":false}]}
{"op":"mcm","clk":"11449707777","pt":1717313781666,"mc":[{"id":"1.229554892","rc":[{"atb":[[48,0],[28,3.7]],"id":52385907}],"con":true,"img":false}]}
{"op":"mcm","clk":"11449707817","pt":1717313782177,"mc":[{"id":"1.229554892","rc":[{"atb":[[42,2.55]],"id":52385907}],"con":true,"img":false}]}
{"op":"mcm","clk":"11449707824","pt":1717313782280,"mc":[{"id":"1.229554892","rc":[{"atb":[[80,0.66],[42,4.99],[110,0.24],[55,1.45]],"id":52385907}],"con":true,"img":false}]}
{"op":"mcm","clk":"11449707830","pt":1717313782382,"mc":[{"id":"1.229554892","rc":[{"atb":[[42,2.55],[50,2.04],[28,0]],"id":52385907}],"con":true,"img":false}]}
{"op":"mcm","clk":"11449708940","pt":1717313795219,"mc":[{"id":"1.229554892","rc":[{"atb":[[21,5],[15.5,0]],"id":52385903}],"con":true,"img":false}]}
{"op":"mcm","clk":"11449709517","pt":1717313801816,"mc":[{"id":"1.229554892","rc":[{"atb":[[1.97,103.09],[2.08,0]],"id":52385891},{"atb":[[4.8,26.32],[4.6,0]],"id":52385934}],"con":true,"img":false}]}
{"op":"mcm","clk":"11449709547","pt":1717313802125,"mc":[{"id":"1.229554892","rc":[{"atb":[[80,0],[42,0],[110,0],[55,0]],"id":52385907},{"atb":[[530,0],[580,0],[630,0],[680,0]],"id":52385886}],"con":true,"img":false}]}
{"op":"mcm","clk":"11449709557","pt":1717313802228,"mc":[{"id":"1.229554892","rc":[{"atb":[[50,0],[28,3.7]],"id":52385907}],"con":true,"img":false}]}
{"op":"mcm","clk":"11449709615","pt":1717313802798,"mc":[{"id":"1.229554892","rc":[{"atb":[[75,0.71],[40,2.68],[100,0.27],[50,1.6]],"id":52385907},{"atb":[[550,0.63],[600,0.13],[650,0.24],[700,0.04]],"id":52385886}],"con":true,"img":false}]}
{"op":"mcm","clk":"11449709627","pt":1717313802907,"mc":[{"id":"1.229554892","rc":[{"atb":[[48,2.13],[28,0]],"id":52385907}],"con":true,"img":false}]}
{"op":"mcm","clk":"11449721844","pt":1717313941132,"mc":[{"id":"1.229554892","rc":[{"atb":[[4.8,0],[4.6,27.78]],"id":52385934}],"con":true,"img":false}]}
{"op":"mcm","clk":"11449721874","pt":1717313941437,"mc":[{"id":"1.229554892","rc":[{"atb":[[550,0.44],[600,0],[650,0.16],[700,0]],"id":52385886}],"con":true,"img":false}]}
{"op":"mcm","clk":"11449721955","pt":1717313942162,"mc":[{"id":"1.229554892","rc":[{"atb":[[530,0.2],[580,0.14],[630,0.08],[680,0.04]],"id":52385886}],"con":true,"img":false}]}
{"op":"mcm","clk":"11449731113","pt":1717314036731,"mc":[{"id":"1.229554892","rc":[{"atb":[[4.8,26.32],[4.6,0]],"id":52385934}],"con":true,"img":false}]}
{"op":"mcm","clk":"11449731577","pt":1717314041211,"mc":[{"id":"1.229554892","rc":[{"atb":[[4.8,0],[4.6,27.78]],"id":52385934}],"con":true,"img":false}]}
{"op":"mcm","clk":"11449734725","pt":1717314074262,"mc":[{"id":"1.229554892","rc":[{"atb":[[75,0],[40,0],[100,0],[50,0]],"id":52385907}],"con":true,"img":false}]}
{"op":"mcm","clk":"11449734733","pt":1717314074361,"mc":[{"id":"1.229554892","rc":[{"atb":[[48,0],[28,3.7]],"id":52385907}],"con":true,"img":false}]}
{"op":"mcm","clk":"11449734791","pt":1717314074981,"mc":[{"id":"1.229554892","rc":[{"atb":[[42,2.55],[110,0.24]],"id":52385907}],"con":true,"img":false}]}
{"op":"mcm","clk":"11449734808","pt":1717314075081,"mc":[{"id":"1.229554892","rc":[{"atb":[[80,0.66],[42,4.99],[55,1.45],[28,0]],"id":52385907}],"con":true,"img":false}]}
{"op":"mcm","clk":"11449736699","pt":1717314096292,"mc":[{"id":"1.229554892","rc":[{"atb":[[18.5,0],[27,0]],"id":52385907},{"atb":[[3.95,0],[4.9,0]],"id":52385909},{"atb":[[550,0],[650,0]],"id":52385886},{"atb":[[16,0],[22,0]],"id":52385918},{"atb":[[17,0],[12,0]],"id":52385888},{"atb":[[38,0],[24,0]],"id":52385920},{"atb":[[7.2,0],[9.2,0]],"id":52385889},{"atb":[[9.2,0],[13,0]],"id":52385882},{"atb":[[17,0],[12,0]],"id":52385884},{"atb":[[550,0],[650,0]],"id":52385917},{"atb":[[2.92,0],[2.72,0]],"id":52385895},{"atb":[[2.92,0],[2.72,0]],"id":52385891},{"atb":[[38,0],[24,0]],"id":52385923},{"atb":[[17,0],[12,0]],"id":52385893},{"atb":[[3.95,0],[4.9,0]],"id":52385934},{"atb":[[10,0],[15,0]],"id":52385903},{"atb":[[3.45,0],[2.98,0]],"id":52385904},{"atb":[[18.5,0],[27,0]],"id":52385936},{"atb":[[10,0],[15,0]],"id":52385931},{"atb":[[3.45,0],[2.98,0]],"id":52385932}],"con":true,"img":false}]}
{"op":"mcm","clk":"11449736707","pt":1717314096394,"mc":[{"id":"1.229554892","rc":[{"atb":[[2.72,58.14]],"id":52385934}],"con":true,"img":false}]}
{"op":"mcm","clk":"11449736718","pt":1717314096493,"mc":[{"id":"1.229554892","rc":[{"atb":[[17.5,0],[8.4,13.51]],"id":52385884},{"atb":[[4.6,0]],"id":52385934},{"atb":[[5.7,21.28],[15.5,0]],"id":52385931}],"con":true,"img":false}]}
{"op":"mcm","clk":"11449737027","pt":1717314100105,"mc":[{"id":"1.229554892","rc":[{"atb":[[42,2.55],[50,2.04]],"id":52385907}],"con":true,"img":false}]}
{"op":"mcm","clk":"11449739271","pt":1717314124229,"mc":[{"id":"1.229554892","rc":[{"atb":[[18.5,13.93],[27,4.01]],"id":52385907},{"atb":[[3.95,82.67],[4.9,26.8]],"id":52385909},{"atb":[[16,16.26],[22,4.97]],"id":52385918},{"atb":[[550,0.44],[650,0.16]],"id":52385886},{"atb":[[17,6.53],[12,22.17]],"id":52385888},{"atb":[[38,2.82],[24,10.6]],"id":52385920},{"atb":[[7.2,39.33],[9.2,12.74]],"id":52385889},{"atb":[[9.2,29.74],[13,8.71]],"id":52385882},{"atb":[[17,6.53],[12,22.17]],"id":52385884},{"atb":[[550,0.44],[650,0.16]],"id":52385917},{"atb":[[2.92,54.44],[2.72,141.8]],"id":52385895},{"atb":[[38,2.82],[24,10.6]],"id":52385923},{"atb":[[2.92,54.44],[2.72,141.8]],"id":52385891},{"atb":[[17,6.53],[12,22.17]],"id":52385893},{"atb":[[3.95,82.67],[4.9,26.8]],"id":52385934},{"atb":[[10,27.1],[15,7.46]],"id":52385903},{"atb":[[18.5,13.93],[27,4.01]],"id":52385936},{"atb":[[3.45,42.66],[2.98,123.18]],"id":52385904},{"atb":[[10,27.1],[15,7.46]],"id":52385931},{"atb":[[3.45,42.66],[2.98,123.18]],"id":52385932}],"con":true,"img":false}]}
{"op":"mcm","clk":"11449739281","pt":1717314124338,"mc":[{"id":"1.229554892","rc":[{"atb":[[17.5,6.06]],"id":52385884},{"atb":[[4.6,27.78]],"id":52385934},{"atb":[[15.5,6.9]],"id":52385931}],"con":true,"img":false}]}
{"op":"mcm","clk":"11449739292","pt":1717314124436,"mc":[{"id":"1.229554892","rc":[{"atb":[[8.4,0]],"id":52385884},{"atb":[[2.72,0]],"id":52385934},{"atb":[[5.7,0]],"id":52385931}],"con":true,"img":false}]}
{"op":"mcm","clk":"11449747501","pt":1717314217449,"mc":[{"id":"1.229554892","rc":[{"atb":[[4.8,26.32]],"id":52385934}],"con":true,"img":false}]}
{"op":"mcm","clk":"11449747511","pt":1717314217555,"mc":[{"id":"1.229554892","rc":[{"atb":[[4.6,0]],"id":52385934}],"con":true,"img":false}]}
{"op":"mcm","clk":"11449747543","pt":1717314217867,"mc":[{"id":"1.229554892","rc":[{"atb":[[80,0],[42,0],[110,0],[55,0]],"id":52385907},{"atb":[[530,0],[580,0],[630,0],[680,0]],"id":52385886}],"con":true,"img":false}]}
{"op":"mcm","clk":"11449747553","pt":1717314217972,"mc":[{"id":"1.229554892","rc":[{"atb":[[28,3.7]],"id":52385907}],"con":true,"img":false}]}
{"op":"mcm","clk":"11449747564","pt":1717314218071,"mc":[{"id":"1.229554892","rc":[{"atb":[[50,0]],"id":52385907}],"con":true,"img":false}]}
{"op":"mcm","clk":"11449747612","pt":1717314218543,"mc":[{"id":"1.229554892","rc":[{"atb":[[75,0.71],[40,2.68],[100,0.27],[50,1.6]],"id":52385907},{"atb":[[550,0.63],[600,0.13],[650,0.24],[700,0.04]],"id":52385886}],"con":true,"img":false}]}
{"op":"mcm","clk":"11449747633","pt":1717314218755,"mc":[{"id":"1.229554892","rc":[{"atb":[[4.6,27.78]],"id":52385934}],"con":true,"img":false}]}
{"op":"mcm","clk":"11449747641","pt":1717314218850,"mc":[{"id":"1.229554892","rc":[{"atb":[[4.8,0]],"id":52385934}],"con":true,"img":false}]}
{"op":"mcm","clk":"11449747683","pt":1717314219366,"mc":[{"id":"1.229554892","rc":[{"atb":[[550,0.44],[600,0],[650,0.16],[700,0]],"id":52385886}],"con":true,"img":false}]}
{"op":"mcm","clk":"11449747742","pt":1717314220082,"mc":[{"id":"1.229554892","rc":[{"atb":[[530,0.2],[580,0.14],[630,0.08],[680,0.04]],"id":52385886}],"con":true,"img":false}]}
{"op":"mcm","clk":"11449748206","pt":1717314224576,"mc":[{"id":"1.229554892","rc":[{"atb":[[4.8,26.32],[4.6,0]],"id":52385934}],"con":true,"img":false}]}
{"op":"mcm","clk":"11449749293","pt":1717314235814,"mc":[{"id":"1.229554892","rc":[{"atb":[[4.8,0],[4.6,27.78]],"id":52385934}],"con":true,"img":false}]}
{"op":"mcm","clk":"11449749861","pt":1717314241498,"mc":[{"id":"1.229554892","rc":[{"atb":[[50,3.64]],"id":52385907}],"con":true,"img":false}]}
{"op":"mcm","clk":"11449749873","pt":1717314241597,"mc":[{"id":"1.229554892","rc":[{"atb":[[28,0]],"id":52385907}],"con":true,"img":false}]}
{"op":"mcm","clk":"11449763105","pt":1717314391707,"mc":[{"id":"1.229554892","rc":[{"atb":[[34,0],[44,0],[22,0],[27,0]],"id":52385903}],"con":true,"img":false}]}
{"op":"mcm","clk":"11449763117","pt":1717314391821,"mc":[{"id":"1.229554892","rc":[{"atb":[[21,0],[15.5,6.9]],"id":52385903}],"con":true,"img":false}]}
{"op":"mcm","clk":"11449763168","pt":1717314392380,"mc":[{"id":"1.229554892","rc":[{"atb":[[32,1.69],[42,0.64],[21,5.23],[26,3.14]],"id":52385903}],"con":true,"img":false}]}
{"op":"mcm","clk":"11449765011","pt":1717314413612,"mc":[{"id":"1.229554892","rc":[{"atb":[[21,10.23],[15.5,0]],"id":52385903}],"con":true,"img":false}]}
{"op":"mcm","clk":"11449766639","pt":1717314431677,"mc":[{"id":"1.229554892","rc":[{"atb":[[18.5,0],[27,0]],"id":52385907},{"atb":[[3.95,0],[4.9,0]],"id":52385909},{"atb":[[550,0],[650,0]],"id":52385886},{"atb":[[16,0],[22,0]],"id":52385918},{"atb":[[38,0],[24,0]],"id":52385920},{"atb":[[17,0],[12,0]],"id":52385888},{"atb":[[7.2,0],[9.2,0]],"id":52385889},{"atb":[[9.2,0],[13,0]],"id":52385882},{"atb":[[17,0],[12,0]],"id":52385884},{"atb":[[550,0],[650,0]],"id":52385917},{"atb":[[2.92,0],[2.72,0]],"id":52385895},{"atb":[[38,0],[24,0]],"id":52385923},{"atb":[[2.92,0],[2.72,0]],"id":52385891},{"atb":[[17,0],[12,0]],"id":52385893},{"atb":[[3.95,0],[4.9,0]],"id":52385934},{"atb":[[10,0],[15,0]],"id":52385903},{"atb":[[3.45,0],[2.98,0]],"id":52385904},{"atb":[[18.5,0],[27,0]],"id":52385936},{"atb":[[10,0],[15,0]],"id":52385931},{"atb":[[3.45,0],[2.98,0]],"id":52385932}],"con":true,"img":false}]}
{"op":"mcm","clk":"11449766650","pt":1717314431784,"mc":[{"id":"1.229554892","rc":[{"atb":[[17.5,0],[8.6,13.16]],"id":52385884},{"atb":[[2.72,58.14],[4.6,0]],"id":52385934},{"atb":[[5.9,20.41],[15.5,0]],"id":52385931}],"con":true,"img":false}]}
{"op":"mcm","clk":"11449768260","pt":1717314449785,"mc":[{"id":"1.229554892","rc":[{"atb":[[530,0],[580,0],[630,0],[680,0]],"id":52385886}],"con":true,"img":false}]}
{"op":"mcm","clk":"11449768268","pt":1717314449890,"mc":[{"id":"1.229554892","rc":[{"atb":[[42,2.44]],"id":52385886}],"con":true,"img":false}]}
{"op":"mcm","clk":"11449768277","pt":1717314449992,"mc":[{"id":"1.229554892","rc":[{"atb":[[320,0]],"id":52385886}],"con":true,"img":false}]}
{"op":"mcm","clk":"11449768322","pt":1717314450460,"mc":[{"id":"1.229554892","rc":[{"atb":[[580,0.18],[630,0.13],[680,0.08],[730,0.04]],"id":52385886}],"con":true,"img":false}]}
{"op":"mcm","clk":"11449768343","pt":1717314450662,"mc":[{"id":"1.229554892","rc":[{"atb":[[42,0],[360,2]],"id":52385886}],"con":true,"img":false}]}
{"op":"mcm","clk":"11449768892","pt":1717314457509,"mc":[{"id":"1.229554892","rc":[{"atb":[[550,0.44],[650,0.16]],"id":52385886},{"atb":[[17,6.53],[12,22.17]],"id":52385888},{"atb":[[7.2,39.33],[9.2,12.74]],"id":52385889},{"atb":[[9.2,29.74],[13,8.71]],"id":52385882},{"atb":[[17,6.53],[12,22.17]],"id":52385884},{"atb":[[2.92,54.44],[2.72,141.8]],"id":52385895},{"atb":[[2.92,54.44],[2.72,141.8]],"id":52385891},{"atb":[[17,6.53],[12,22.17]],"id":52385893},{"atb":[[10,27.1],[15,7.46]],"id":52385903},{"atb":[[3.45,42.66],[2.98,123.18]],"id":52385904}],"con":true,"img":false}]}
{"op":"mcm","clk":"11449768900","pt":1717314457618,"mc":[{"id":"1.229554892","rc":[{"atb":[[18.5,13.93],[27,4.01]],"id":52385907},{"atb":[[3.95,82.67],[4.9,26.8]],"id":52385909},{"atb":[[16,16.26],[22,4.97]],"id":52385918},{"atb":[[38,2.82],[24,10.6]],"id":52385920},{"atb":[[550,0.44],[650,0.16]],"id":52385917},{"atb":[[38,2.82],[24,10.6]],"id":52385923},{"atb":[[3.95,82.67],[4.9,26.8]],"id":52385934},{"atb":[[18.5,13.93],[27,4.01]],"id":52385936},{"atb":[[10,27.1],[15,7.46]],"id":52385931},{"atb":[[3.45,42.66],[2.98,123.18]],"id":52385932}],"con":true,"img":false}]}
{"op":"mcm","clk":"11449768907","pt":1717314457668,"mc":[{"id":"1.229554892","rc":[{"atb":[[17.5,6.06],[8.6,0]],"id":52385884}],"con":true,"img":false}]}
{"op":"mcm","clk":"11449768913","pt":1717314457772,"mc":[{"id":"1.229554892","rc":[{"atb":[[2.72,0],[4.6,27.78]],"id":52385934},{"atb":[[5.9,0],[15.5,6.9]],"id":52385931}],"con":true,"img":false}]}
{"op":"mcm","clk":"11449768991","pt":1717314458802,"mc":[{"id":"1.229554892","rc":[{"atb":[[3.6,0],[3.1,0],[3.35,0],[2.94,0]],"id":52385891}],"con":true,"img":false}]}
{"op":"mcm","clk":"11449769052","pt":1717314459491,"mc":[{"id":"1.229554892","rc":[{"atb":[[2.92,108.94],[3.55,10.26],[3.3,22.75],[3.05,38.28]],"id":52385891}],"con":true,"img":false}]}
{"op":"mcm","clk":"11449782082","pt":1717314604923,"mc":[{"id":"1.229554892","rc":[{"atb":[[32,0],[42,0],[26,0]],"id":52385903}],"con":true,"img":false}]}
{"op":"mcm","clk":"11449782092","pt":1717314604980,"mc":[{"id":"1.229554892","rc":[{"atb":[[21,5]],"id":52385903}],"con":true,"img":false}]}
{"op":"mcm","clk":"11449782108","pt":1717314605185,"mc":[{"id":"1.229554892","rc":[{"atb":[[15.5,6.9]],"id":52385903}],"con":true,"img":false}]}
{"op":"mcm","clk":"11449782113","pt":1717314605283,"mc":[{"id":"1.229554892","rc":[{"atb":[[21,0]],"id":52385903}],"con":true,"img":false}]}
{"op":"mcm","clk":"11449782137","pt":1717314605595,"mc":[{"id":"1.229554892","rc":[{"atb":[[34,1.59],[44,0.61],[27,3.02]],"id":52385903}],"con":true,"img":false}]}
{"op":"mcm","clk":"11449782147","pt":1717314605696,"mc":[{"id":"1.229554892","rc":[{"atb":[[22,4.98]],"id":52385903}],"con":true,"img":false}]}
{"op":"mcm","clk":"11449782186","pt":1717314606314,"mc":[{"id":"1.229554892","rc":[{"atb":[[4.8,26.32],[4.6,0]],"id":52385934}],"con":true,"img":false}]}
{"op":"mcm","clk":"11449782204","pt":1717314606623,"mc":[{"id":"1.229554892","rc":[{"atb":[[580,0],[630,0],[680,0],[730,0]],"id":52385886},{"atb":[[16.5,0],[9.6,0],[11.5,0],[14,0]],"id":52385889},{"atb":[[34,0],[44,0],[22,0],[27,0]],"id":52385903},{"atb":[[65,0],[36,0],[90,0],[46,0]],"id":52385936}],"con":true,"img":false}]}
{"op":"mcm","clk":"11449782214","pt":1717314606674,"mc":[{"id":"1.229554892","rc":[{"atb":[[28,3.7]],"id":52385936}],"con":true,"img":false}]}
{"op":"mcm","clk":"11449782220","pt":1717314606782,"mc":[{"id":"1.229554892","rc":[{"atb":[[42,0]],"id":52385936}],"con":true,"img":false}]}
{"op":"mcm","clk":"11449782255","pt":1717314607298,"mc":[{"id":"1.229554892","rc":[{"atb":[[520,0.2],[570,0.14],[620,0.08],[670,0.04]],"id":52385886},{"atb":[[16,1.74],[11,7.85],[13.5,4.19],[9.4,12.46]],"id":52385889},{"atb":[[32,1.69],[42,0.64],[21,5.23],[26,3.14]],"id":52385903},{"atb":[[70,0.76],[38,2.83],[95,0.28],[48,1.67]],"id":52385936}],"con":true,"img":false}]}
{"op":"mcm","clk":"11449782570","pt":1717314611415,"mc":[{"id":"1.229554892","rc":[{"atb":[[4.8,0],[4.6,27.78]],"id":52385934}],"con":true,"img":false}]}
{"op":"mcm","clk":"11449783642","pt":1717314624869,"mc":[{"id":"1.229554892","rc":[{"atb":[[21,10.23],[15.5,0]],"id":52385903}],"con":true,"img":false}]}
{"op":"mcm","clk":"11449783758","pt":1717314626377,"mc":[{"id":"1.229554892","rc":[{"atb":[[44,2.33],[28,0]],"id":52385936}],"con":true,"img":false}]}
{"op":"mcm","clk":"11449784855","pt":1717314640260,"mc":[{"id":"1.229554892","rc":[{"atb":[[4.8,26.32],[4.6,0]],"id":52385934}],"con":true,"img":false}]}
{"op":"mcm","clk":"11449784879","pt":1717314640567,"mc":[{"id":"1.229554892","rc":[{"atb":[[1.97,0],[2.04,96.15]],"id":52385891}],"con":true,"img":false}]}
{"op":"mcm","clk":"11449784910","pt":1717314640975,"mc":[{"id":"1.229554892","rc":[{"atb":[[520,0],[570,0],[620,0],[670,0]],"id":52385886}],"con":true,"img":false}]}
{"op":"mcm","clk":"11449784966","pt":1717314641652,"mc":[{"id":"1.229554892","rc":[{"atb":[[540,0.15],[590,0.09],[640,0.04],[490,0.21]],"id":52385886}],"con":true,"img":false}]}
{"op":"mcm","clk":"11449785099","pt":1717314643276,"mc":[{"id":"1.229554892","rc":[{"atb":[[75,0],[40,0],[100,0],[50,2.04]],"id":52385907},{"atb":[[3.1,0],[3.35,0],[2.84,0],[2.94,0]],"id":52385895},{"atb":[[70,0],[38,0],[95,0],[48,0]],"id":52385936}],"con":true,"img":false}]}
{"op":"mcm","clk":"11449785104","pt":1717314643373,"mc":[{"id":"1.229554892","rc":[{"atb":[[50,0],[28,3.7]],"id":52385907},{"atb":[[44,0],[28,3.7]],"id":52385936}],"con":true,"img":false}]}
{"op":"mcm","clk":"11449785159","pt":1717314643990,"mc":[{"id":"1.229554892","rc":[{"atb":[[70,0.76],[38,2.83],[95,0.28],[48,1.67]],"id":52385907},{"atb":[[3,52.32],[3.25,34.88],[3.5,20.93],[3.75,9.51]],"id":52385895},{"atb":[[65,0.82],[36,2.99],[90,0.29],[46,1.74]],"id":52385936}],"con":true,"img":false}]}
{"op":"mcm","clk":"11449785278","pt":1717314645390,"mc":[{"id":"1.229554892","rc":[{"atb":[[4.7,27.03]],"id":52385934}],"con":true,"img":false}]}
{"op":"mcm","clk":"11449785287","pt":1717314645493,"mc":[{"id":"1.229554892","rc":[{"atb":[[4.8,0]],"id":52385934}],"con":true,"img":false}]}
{"op":"mcm","clk":"11449786595","pt":1717314661618,"mc":[{"id":"1.229554892","rc":[{"atb":[[46,3.92],[50,3.9]],"id":52385907},{"atl":[[190,2.78],[210,4]],"id":52385907},{"atb":[[7.2,4.13],[7.6,16.04]],"id":52385909},{"atl":[[19,3.19],[20,3.39]],"id":52385909},{"atb":[[70,3.56],[60,6.34]],"id":52385918},{"atl":[[590,3.89],[610,4.3]],"id":52385918},{"atb":[[100,5.05],[120,2.98]],"id":52385920},{"atl":[[970,3.95]],"id":52385920},{"atb":[[32,7.47],[36,6.1]],"id":52385888},{"atl":[[220,4.45],[240,4.3]],"id":52385888},{"atb":[[10,4.08],[10.5,3.67],[11,11.37],[11.5,3.84]],"id":52385889},{"atl":[[26,3.16],[28,3.89]],"id":52385889},{"atb":[[23,2.83],[25,4.3]],"id":52385882},{"atl":[[140,3.34],[160,3.73]],"id":52385882},{"atb":[[16.5,2.89],[15.5,3.26]],"id":52385884},{"atl":[[230,4.16],[250,3.2]],"id":52385884},{"atl":[[6.2,3.13],[6.6,4.15]],"id":52385895},{"atb":[[3.4,6.53],[3.5,6.27]],"id":52385891},{"atl":[[6.6,2.98],[7,4.55]],"id":52385891},{"atb":[[95,4.97],[110,2.83]],"id":52385923},{"atl":[[910,3.37],[930,3.14]],"id":52385923},{"atb":[[21,4.62],[23,4.08]],"id":52385893},{"atl":[[65,2.85],[55,3.4]],"id":52385893},{"atb":[[7.2,3.36],[7.4,4.34],[7.6,3.2],[7,3.85]],"id":52385934},{"atl":[[18,4.34],[19,3.57]],"id":52385934},{"atb":[[22,4.48],[23,3.51],[24,3.6],[25,3.9]],"id":52385903},{"atl":[[80,4.03],[90,4.25]],"id":52385903},{"atb":[[4.8,3.74],[5.1,23.23],[5,3.08],[4.9,4.37]],"id":52385904},{"atl":[[12,3.79],[13,3.86]],"id":52385904},{"atb":[[13.5,2.92],[14.5,3.87]],"id":52385931},{"atl":[[70,3.59],[80,3.81]],"id":52385931},{"atl":[[10.5,4.3],[11.5,4.52]],"id":52385932}],"con":true,"img":false}]}
{"op":"mcm","clk":"11449786606","pt":1717314661716,"mc":[{"id":"1.229554892","rc":[{"atb":[[44,2.62],[48,4.49]],"id":52385936},{"atl":[[160,3.09],[180,4.58]],"id":52385936}],"con":true,"img":false}]}
{"op":"mcm","clk":"11449786616","pt":1717314661818,"mc":[{"id":"1.229554892","rc":[{"atl":[[340,0],[42,2.44]],"id":52385909},{"atl":[[420,0],[60,2]],"id":52385889},{"atl":[[85,0],[13.5,7.29]],"id":52385895},{"atl":[[95,0],[14.5,7.41]],"id":52385891},{"atl":[[38,2.7],[330,0]],"id":52385934},{"atl":[[26,4],[250,0]],"id":52385904},{"atl":[[23,4.55],[220,0]],"id":52385932}],"con":true,"img":false}]}
{"op":"mcm","clk":"11449786687","pt":1717314662708,"mc":[{"id":"1.229554892","rc":[{"atb":[[46,6.14],[28,0]],"id":52385907},{"atb":[[42,2.44],[28,0]],"id":52385936}],"con":true,"img":false}]}
{"op":"mcm","clk":"11449786915","pt":1717314665229,"mc":[{"id":"1.229554892","rc":[{"atb":[[2.92,54.44]],"id":52385891}],"con":true,"img":false}]}
{"op":"mcm","clk":"11449786931","pt":1717314665285,"mc":[{"id":"1.229554892","rc":[{"atb":[[10,0],[10.5,0]],"id":52385889},{"atb":[[3.55,0],[3.3,0],[3.05,0]],"id":52385891},{"atb":[[7.6,0]],"id":52385934},{"atb":[[25,0]],"id":52385903},{"atb":[[5.1,19.14]],"id":52385904}],"con":true,"img":false}]}
{"op":"mcm","clk":"11449786987","pt":1717314665911,"mc":[{"id":"1.229554892","rc":[{"atb":[[3.15,48.67]],"id":52385891}],"con":true,"img":false}]}
{"op":"mcm","clk":"11449786996","pt":1717314666012,"mc":[{"id":"1.229554892","rc":[{"atb":[[3.4,39.24],[3.9,9.02],[3.65,19.74]],"id":52385891}],"con":true,"img":false}]}
{"op":"mcm","clk":"11449787006","pt":1717314666112,"mc":[{"id":"1.229554892","rc":[{"atl":[[180,2.67]],"id":52385907},{"atl":[[210,4.11]],"id":52385888},{"atb":[[26,7.69]],"id":52385882},{"atb":[[25,4.12]],"id":52385903},{"atl":[[10.5,0]],"id":52385932}],"con":true,"img":false}]}
{"op":"mcm","clk":"11449787016","pt":1717314666218,"mc":[{"id":"1.229554892","rc":[{"atl":[[190,0]],"id":52385907},{"atl":[[570,4.34],[590,0]],"id":52385918},{"atb":[[36,2.24],[38,3.64]],"id":52385888},{"atl":[[220,0]],"id":52385888},{"atl":[[940,2.69]],"id":52385920},{"atb":[[25,0]],"id":52385882},{"atl":[[880,3.24],[910,0]],"id":52385923},{"atb":[[7,0]],"id":52385934},{"atb":[[22,0],[24,0]],"id":52385903},{"atl":[[75,2.94],[80,0]],"id":52385903},{"atb":[[4.8,0],[5.1,22.96],[5,0]],"id":52385904},{"atl":[[11.5,4.61],[12,0]],"id":52385904},{"atb":[[65,0],[36,0],[90,0],[46,0]],"id":52385936},{"atl":[[10,3.76]],"id":52385932}],"con":true,"img":false}]}
{"op":"mcm","clk":"11449787047","pt":1717314666632,"mc":[{"id":"1.229554892","rc":[{"atb":[[18.5,0],[27,0]],"id":52385907},{"atb":[[3.95,0],[4.9,0]],"id":52385909},{"atb":[[16,0],[22,0]],"id":52385918},{"atb":[[550,0],[650,0]],"id":52385886},{"atb":[[17,0],[12,0]],"id":52385888},{"atb":[[38,0],[24,0]],"id":52385920},{"atb":[[7.2,0],[9.2,0]],"id":52385889},{"atb":[[9.2,0],[13,0]],"id":52385882},{"atb":[[17,0],[12,0]],"id":52385884},{"atb":[[550,0],[650,0]],"id":52385917},{"atb":[[2.92,0],[2.72,0]],"id":52385895},{"atb":[[38,0],[24,0]],"id":52385923},{"atb":[[2.92,0],[2.72,0]],"id":52385891},{"atb":[[17,0],[12,0]],"id":52385893},{"atb":[[3.95,0],[4.9,0]],"id":52385934},{"atb":[[10,0],[15,0]],"id":52385903},{"atb":[[3.45,0],[2.98,0]],"id":52385904},{"atb":[[18.5,0],[27,0]],"id":52385936},{"atb":[[10,0],[15,0]],"id":52385931},{"atb":[[3.45,0],[2.98,0]],"id":52385932}],"con":true,"img":false}]}
{"op":"mcm","clk":"11449787058","pt":1717314666687,"mc":[{"id":"1.229554892","rc":[{"atb":[[16.5,9.34]],"id":52385884},{"atb":[[15,7.14],[15.5,0]],"id":52385931}],"con":true,"img":false}]}
{"op":"mcm","clk":"11449787067","pt":1717314666790,"mc":[{"id":"1.229554892","rc":[{"atb":[[16,6.67],[17.5,0]],"id":52385884}],"con":true,"img":false}]}
{"op":"mcm","clk":"11449787076","pt":1717314666898,"mc":[{"id":"1.229554892","rc":[{"atb":[[16.5,2.89]],"id":52385884},{"atb":[[34,3.17],[85,0.31],[44,4.45],[60,0.88]],"id":52385936}],"con":true,"img":false}]}
{"op":"mcm","clk":"11449787246","pt":1717314668909,"mc":[{"id":"1.229554892","rc":[{"atl":[[180,0],[190,2.65]],"id":52385907},{"atl":[[570,0],[560,4.38]],"id":52385918},{"atl":[[940,0],[950,2.99]],"id":52385920},{"atb":[[1.45,34.88],[1.43,36.5],[3,0],[3.25,0],[3.5,0],[3.75,0]],"id":52385895},{"atl":[[6.2,0],[5.9,4.4]],"id":52385895},{"atb":[[3.5,0],[3.3,6.82]],"id":52385891},{"atl":[[6.4,3.46],[6.6,0]],"id":52385891},{"atl":[[880,0],[890,3.72]],"id":52385923},{"atb":[[22,7.81],[23,0]],"id":52385893},{"atl":[[160,0],[170,3.1]],"id":52385936},{"atb":[[1.45,34.88],[1.43,36.5]],"id":52385932},{"atl":[[10,0],[9.8,4.42]],"id":52385932}],"con":true,"img":false}]}
{"op":"mcm","clk":"11449787309","pt":1717314669695,"mc":[{"id":"1.229554892","rc":[{"atb":[[3.45,10.68],[3.2,23.78],[2.88,55.66],[2.98,39.64]],"id":52385895}],"con":true,"img":false}]}
{"op":"mcm","clk":"11449787412","pt":1717314671041,"mc":[{"id":"1.229554892","rc":[{"atb":[[70,0],[75,4.22]],"id":52385918},{"atb":[[540,0],[590,0],[640,0],[180,3.88],[200,3.95],[490,0]],"id":52385886},{"atb":[[34,2.84],[38,0]],"id":52385888},{"atb":[[25,3.31],[26,3.14]],"id":52385882},{"atb":[[16.5,0]],"id":52385884},{"atb":[[190,4.38],[210,2.73]],"id":52385917},{"atb":[[3.4,32.7]],"id":52385891},{"atb":[[32,0],[42,0],[21,5],[24,2.87],[25,0],[26,0]],"id":52385903},{"atl":[[75,0],[80,3.4]],"id":52385903},{"atb":[[14,2.66],[14.5,0]],"id":52385931}],"con":true,"img":false}]}
{"op":"mcm","clk":"11449787422","pt":1717314671099,"mc":[{"id":"1.229554892","rc":[{"atb":[[210,2]],"id":52385886},{"atb":[[19.5,5.41],[21,0]],"id":52385903},{"atb":[[14,10.35],[15,0]],"id":52385931}],"con":true,"img":false}]}
{"op":"mcm","clk":"11449787434","pt":1717314671200,"mc":[{"id":"1.229554892","rc":[{"atb":[[360,0]],"id":52385886}],"con":true,"img":false}]}
{"op":"mcm","clk":"11449787475","pt":1717314671611,"mc":[{"id":"1.229554892","rc":[{"atl":[[180,4.2],[190,0]],"id":52385907},{"atl":[[560,0],[570,3.48]],"id":52385918},{"atl":[[950,0],[940,3.06]],"id":52385920},{"atb":[[15,4.23]],"id":52385884},{"atl":[[6.2,4.52],[5.9,0]],"id":52385895},{"atb":[[3.15,0]],"id":52385891},{"atl":[[6.4,0],[6.6,3.55]],"id":52385891},{"atl":[[890,0],[880,3.44]],"id":52385923},{"atb":[[23,0]],"id":52385903},{"atl":[[160,4.34],[170,0]],"id":52385936},{"atb":[[13,4.01]],"id":52385931},{"atl":[[10,3.78],[9.8,0]],"id":52385932}],"con":true,"img":false}]}
{"op":"mcm","clk":"11449787483","pt":1717314671715,"mc":[{"id":"1.229554892","rc":[{"atb":[[530,0.15],[580,0.09],[630,0.04],[480,0.22]],"id":52385886},{"atb":[[3.4,0],[3.9,0],[3.65,0]],"id":52385891},{"atb":[[40,0.67],[20,5.51],[25,3.27],[30,1.81]],"id":52385903}],"con":true,"img":false}]}
{"op":"mcm","clk":"11449787544","pt":1717314672392,"mc":[{"id":"1.229554892","rc":[{"atb":[[3.4,21.8],[3.15,36.5],[2.96,53.39],[3.65,9.87]],"id":52385891}],"con":true,"img":false}]}
{"op":"mcm","clk":"11449787889","pt":1717314676207,"mc":[{"id":"1.229554892","rc":[{"atl":[[19,0],[19.5,3.76]],"id":52385909},{"atl":[[18,0],[18.5,4.31]],"id":52385934},{"atl":[[75,3.66]],"id":52385903},{"atb":[[13.5,0],[14,7.69]],"id":52385931}],"con":true,"img":false}]}
{"op":"mcm","clk":"11449787897","pt":1717314676308,"mc":[{"id":"1.229554892","rc":[{"atb":[[15.5,0]],"id":52385884},{"atl":[[80,0]],"id":52385903},{"atb":[[13.5,8]],"id":52385931}],"con":true,"img":false}]}
{"op":"mcm","clk":"11449787908","pt":1717314676411,"mc":[{"id":"1.229554892","rc":[{"atb":[[15.5,6.9]],"id":52385884},{"atb":[[14,0]],"id":52385931}],"con":true,"img":false}]}
{"op":"mcm","clk":"11449787915","pt":1717314676515,"mc":[{"id":"1.229554892","rc":[{"atb":[[16,0]],"id":52385884}],"con":true,"img":false}]}
{"op":"mcm","clk":"11449788430","pt":1717314681532,"mc":[{"id":"1.229554892","rc":[{"atl":[[590,2.89]],"id":52385918}],"con":true,"img":false}]}
{"op":"mcm","clk":"11449788440","pt":1717314681635,"mc":[{"id":"1.229554892","rc":[{"atb":[[14.5,3.73],[15,0]],"id":52385884},{"atb":[[3.2,7.13]],"id":52385891},{"atl":[[900,4.09]],"id":52385923},{"atb":[[12.5,2.7],[13,0]],"id":52385931}],"con":true,"img":false}]}
{"op":"mcm","clk":"11449788448","pt":1717314681738,"mc":[{"id":"1.229554892","rc":[{"atb":[[15,7.14]],"id":52385884},{"atb":[[12.5,11.4]],"id":52385931}],"con":true,"img":false}]}
{"op":"mcm","clk":"11449788456","pt":1717314681797,"mc":[{"id":"1.229554892","rc":[{"atb":[[15.5,0]],"id":52385884},{"atb":[[12.5,2.7],[13.5,0],[5.7,21.28]],"id":52385931}],"con":true,"img":false}]}
{"op":"mcm","clk":"11449788916","pt":1717314686337,"mc":[{"id":"1.229554892","rc":[{"atb":[[22,4.57]],"id":52385903}],"con":true,"img":false}]}
{"op":"mcm","clk":"11449788983","pt":1717314687103,"mc":[{"id":"1.229554892","rc":[{"atl":[[610,0]],"id":52385918},{"atl":[[940,0],[930,3.87]],"id":52385920},{"atb":[[14,2.69],[14.5,0]],"id":52385884},{"atl":[[220,3.47],[230,0]],"id":52385884},{"atl":[[880,0],[890,4.43],[900,0]],"id":52385923},{"atl":[[6.4,4.25],[6.6,0]],"id":52385891},{"atb":[[11.5,3.47],[12.5,0]],"id":52385931}],"con":true,"img":false}]}
{"op":"mcm","clk":"11449789010","pt":1717314687369,"mc":[{"id":"1.229554892","rc":[{"atb":[[14,10.38],[15,0]],"id":52385884}],"con":true,"img":false}]}
{"op":"mcm","clk":"11449789239","pt":1717314689838,"mc":[{"id":"1.229554892","rc":[{"atb":[[13,4.15],[14,7.69]],"id":52385884},{"atb":[[10.5,3.76],[11.5,0]],"id":52385931}],"con":true,"img":false}]}
{"op":"mcm","clk":"11449789262","pt":1717314690150,"mc":[{"id":"1.229554892","rc":[{"atb":[[310,2],[210,0]],"id":52385886}],"con":true,"img":false}]}
{"op":"mcm","clk":"11449789313","pt":1717314690624,"mc":[{"id":"1.229554892","rc":[{"atb":[[10.5,0],[9.8,4.37]],"id":52385931}],"con":true,"img":false}]}
{"op":"mcm","clk":"11449789472","pt":1717314692425,"mc":[{"id":"1.229554892","rc":[{"atb":[[13.5,8],[14,0]],"id":52385884}],"con":true,"img":false}]}
{"op":"mcm","clk":"11449789726","pt":1717314695347,"mc":[{"id":"1.229554892","rc":[{"atb":[[12.5,4.2],[13,0]],"id":52385884},{"atb":[[10,11.11],[9.8,0],[5.7,0],[9.4,4.3]],"id":52385931}],"con":true,"img":false}]}
{"op":"mcm","clk":"11449789734","pt":1717314695450,"mc":[{"id":"1.229554892","rc":[{"atb":[[9.6,11.63],[10,0]],"id":52385931}],"con":true,"img":false}]}
{"op":"mcm","clk":"11449789873","pt":1717314697150,"mc":[{"id":"1.229554892","rc":[{"atl":[[950,4.1]],"id":52385920},{"atl":[[910,3.02]],"id":52385923}],"con":true,"img":false}]}
{"op":"mcm","clk":"11449789903","pt":1717314697522,"mc":[{"id":"1.229554892","rc":[{"atb":[[13,8.33],[13.5,0]],"id":52385884}],"con":true,"img":false}]}
{"op":"mcm","clk":"11449789945","pt":1717314698038,"mc":[{"id":"1.229554892","rc":[{"atl":[[970,0]],"id":52385920},{"atb":[[12,4.05],[12.5,0]],"id":52385884},{"atl":[[930,0]],"id":52385923},{"atb":[[9.2,3.36],[9.4,0]],"id":52385931}],"con":true,"img":false}]}
{"op":"mcm","clk":"11449789956","pt":1717314698136,"mc":[{"id":"1.229554892","rc":[{"atb":[[9.6,0],[9.4,11.9]],"id":52385931}],"con":true,"img":false}]}
{"op":"mcm","clk":"11449789981","pt":1717314698352,"mc":[{"id":"1.229554892","rc":[{"atb":[[550,0.44],[650,0.16]],"id":52385886},{"atb":[[17,6.53],[12,22.17]],"id":52385888},{"atb":[[7.2,39.33],[9.2,12.74]],"id":52385889},{"atb":[[9.2,29.74],[13,8.71]],"id":52385882},{"atb":[[17,6.53],[12,26.23]],"id":52385884},{"atb":[[2.92,54.44],[2.72,141.8]],"id":52385895},{"atb":[[2.92,54.44],[2.72,141.8]],"id":52385891},{"atb":[[17,6.53],[12,22.17]],"id":52385893},{"atb":[[10,27.1],[15,7.46]],"id":52385903},{"atb":[[3.45,42.66],[2.98,123.18]],"id":52385904}],"con":true,"img":false}]}
{"op":"mcm","clk":"11449789991","pt":1717314698449,"mc":[{"id":"1.229554892","rc":[{"atb":[[18.5,13.93],[27,4.01]],"id":52385907},{"atb":[[3.95,82.67],[4.9,26.8]],"id":52385909},{"atb":[[16,16.26],[22,4.97]],"id":52385918},{"atb":[[38,2.82],[24,10.6]],"id":52385920},{"atb":[[550,0.44],[650,0.16]],"id":52385917},{"atb":[[38,2.82],[24,10.6]],"id":52385923},{"atb":[[3.95,82.67],[4.9,26.8]],"id":52385934},{"atb":[[18.5,13.93],[27,4.01]],"id":52385936},{"atb":[[10,27.1],[15,7.46]],"id":52385931},{"atb":[[3.45,42.66],[2.98,123.18]],"id":52385932}],"con":true,"img":false}]}
{"op":"mcm","clk":"11449790265","pt":1717314701447,"mc":[{"id":"1.229554892","rc":[{"atb":[[16,3.63]],"id":52385884},{"atb":[[14,4.07]],"id":52385931}],"con":true,"img":false}]}
{"op":"mcm","clk":"11449790931","pt":1717314708853,"mc":[{"id":"1.229554892","rc":[{"atl":[[19.5,0]],"id":52385909},{"atl":[[80,4.47]],"id":52385903}],"con":true,"img":false}]}
{"op":"mcm","clk":"11449790941","pt":1717314708955,"mc":[{"id":"1.229554892","rc":[{"atl":[[18.5,0]],"id":52385934},{"atl":[[75,0]],"id":52385903}],"con":true,"img":false}]}
{"op":"mcm","clk":"11449791170","pt":1717314711435,"mc":[{"id":"1.229554892","rc":[{"atb":[[15,4.11]],"id":52385884},{"atb":[[13,4.5]],"id":52385931}],"con":true,"img":false}]}
{"op":"mcm","clk":"11449791304","pt":1717314713083,"mc":[{"id":"1.229554892","rc":[{"atb":[[12,22.17]],"id":52385884},{"atb":[[9.2,0]],"id":52385931}],"con":true,"img":false}]}
{"op":"mcm","clk":"11449791553","pt":1717314716274,"mc":[{"id":"1.229554892","rc":[{"atb":[[17.5,4.12]],"id":52385884}],"con":true,"img":false}]}
{"op":"mcm","clk":"11449791560","pt":1717314716377,"mc":[{"id":"1.229554892","rc":[{"atb":[[13,0]],"id":52385884}],"con":true,"img":false}]}
{"op":"mcm","clk":"11449791597","pt":1717314716891,"mc":[{"id":"1.229554892","rc":[{"atb":[[9.4,0],[15.5,4.51]],"id":52385931}],"con":true,"img":false}]}
{"op":"mcm","clk":"11449791680","pt":1717314717971,"mc":[{"id":"1.229554892","rc":[{"atb":[[16,0],[16.5,4.52]],"id":52385884},{"atb":[[14,0],[14.5,3.87]],"id":52385931}],"con":true,"img":false}]}
{"op":"mcm","clk":"11449791749","pt":1717314718787,"mc":[{"id":"1.229554892","rc":[{"atl":[[21,2.8]],"id":52385909}],"con":true,"img":false}]}
{"op":"mcm","clk":"11449791761","pt":1717314718891,"mc":[{"id":"1.229554892","rc":[{"atl":[[20,0]],"id":52385909},{"atl":[[20,3.77]],"id":52385934}],"con":true,"img":false}]}
{"op":"mcm","clk":"11449791810","pt":1717314719460,"mc":[{"id":"1.229554892","rc":[{"atl":[[19,0],[19.5,3.49]],"id":52385934}],"con":true,"img":false}]}
{"op":"mcm","clk":"11449791920","pt":1717314720695,"mc":[{"id":"1.229554892","rc":[{"atb":[[21,9.62]],"id":52385893}],"con":true,"img":false}]}
{"op":"mcm","clk":"11449791933","pt":1717314720803,"mc":[{"id":"1.229554892","rc":[{"atb":[[46,3.92],[55,2]],"id":52385907},{"atb":[[70,2],[60,4.34]],"id":52385918},{"atb":[[310,0],[400,2]],"id":52385886},{"atb":[[100,3.05],[120,4.98]],"id":52385920},{"atb":[[400,0],[510,2]],"id":52385917},{"atb":[[95,2.97],[110,4.83]],"id":52385923},{"atb":[[2.04,0],[1.95,105.26]],"id":52385891},{"atb":[[19,0]],"id":52385893},{"atb":[[42,0],[50,2.04]],"id":52385936}],"con":true,"img":false}]}
{"op":"mcm","clk":"11449791960","pt":1717314721109,"mc":[{"id":"1.229554892","rc":[{"atb":[[65,2.7],[50,0]],"id":52385907},{"atb":[[130,0],[65,0],[75,0],[90,3.83],[46,0]],"id":52385918},{"atl":[[570,0]],"id":52385918},{"atb":[[130,4.57],[160,0],[80,0],[210,0],[110,0],[120,2]],"id":52385920},{"atl":[[930,0],[960,3.24]],"id":52385920},{"atb":[[34,0],[38,4.03]],"id":52385888},{"atb":[[130,2.78],[150,0],[75,0],[200,0],[100,0],[110,2]],"id":52385923},{"atl":[[890,0],[920,4.48]],"id":52385923},{"atl":[[55,0]],"id":52385893},{"atb":[[7.4,0],[7.6,2.79]],"id":52385934},{"atb":[[24,0],[26,2.85]],"id":52385903},{"atb":[[48,0],[60,4.83]],"id":52385936},{"atb":[[5.1,19.14]],"id":52385904}],"con":true,"img":false}]}
{"op":"mcm","clk":"11449792017","pt":1717314721814,"mc":[{"id":"1.229554892","rc":[{"atb":[[150,0.18],[75,1.06],[100,0.53],[50,2.13]],"id":52385918},{"atb":[[150,0.53],[100,4.11],[200,0.26],[250,0.1]],"id":52385920},{"atb":[[140,0.57],[95,4.09],[190,0.28],[240,0.11]],"id":52385923}],"con":true,"img":false}]}
{"op":"mcm","clk":"11449792154","pt":1717314723307,"mc":[{"id":"1.229554892","rc":[{"atl":[[180,0],[190,3.45]],"id":52385907},{"atl":[[580,4.56]],"id":52385918},{"atl":[[950,0],[960,0]],"id":52385920},{"atl":[[220,0],[230,4.1]],"id":52385884},{"atl":[[910,0]],"id":52385923},{"atl":[[160,0],[170,3.53]],"id":52385936},{"atl":[[10,0],[9.8,4.7]],"id":52385932}],"con":true,"img":false}]}
{"op":"mcm","clk":"11449792623","pt":1717314728717,"mc":[{"id":"1.229554892","rc":[{"atl":[[23,4.49]],"id":52385909}],"con":true,"img":false}]}
{"op":"mcm","clk":"11449792633","pt":1717314728773,"mc":[{"id":"1.229554892","rc":[{"atb":[[3.45,0],[3.2,0],[2.88,0],[2.98,0]],"id":52385895},{"atl":[[5.9,4.13]],"id":52385895},{"atb":[[3.4,0],[3.15,0],[3.3,0],[2.96,0],[3.65,0]],"id":52385891},{"atb":[[22,3.74],[23,4.33]],"id":52385893}],"con":true,"img":false}]}
{"op":"mcm","clk":"11449792641","pt":1717314728880,"mc":[{"id":"1.229554892","rc":[{"atl":[[6.2,0]],"id":52385895}],"con":true,"img":false}]}
{"op":"mcm","clk":"11449792680","pt":1717314729390,"mc":[{"id":"1.229554892","rc":[{"atb":[[4.7,4.61]],"id":52385904}],"con":true,"img":false}]}
{"op":"mcm","clk":"11449792691","pt":1717314729493,"mc":[{"id":"1.229554892","rc":[{"atb":[[3.1,24.91],[3.35,11.13],[2.84,56.87],[2.94,40.45]],"id":52385895},{"atb":[[2.92,108.94],[3.1,7.47],[3.55,10.26],[3.3,22.75],[3.05,38.28]],"id":52385891}],"con":true,"img":false}]}
{"op":"mcm","clk":"11449792824","pt":1717314731112,"mc":[{"id":"1.229554892","rc":[{"atb":[[110,5.57]],"id":52385923},{"atl":[[940,3.84]],"id":52385923},{"atb":[[24,3.42]],"id":52385903}],"con":true,"img":false}]}
{"op":"mcm","clk":"11449792868","pt":1717314731625,"mc":[{"id":"1.229554892","rc":[{"atb":[[18.5,0],[27,0]],"id":52385907},{"atb":[[3.95,0],[4.9,0]],"id":52385909},{"atb":[[16,0],[22,0]],"id":52385918},{"atb":[[550,0],[650,0]],"id":52385886},{"atb":[[38,0],[24,0]],"id":52385920},{"atb":[[17,0],[12,0]],"id":52385888},{"atb":[[7.2,0],[9.2,0]],"id":52385889},{"atb":[[9.2,0],[13,0]],"id":52385882},{"atb":[[17,0],[12,0]],"id":52385884},{"atb":[[550,0],[650,0]],"id":52385917},{"atb":[[2.92,0],[2.72,0]],"id":52385895},{"atb":[[38,0],[24,0]],"id":52385923},{"atb":[[2.92,54.5],[2.72,0]],"id":52385891},{"atb":[[17,0],[12,0]],"id":52385893},{"atb":[[3.95,0],[4.9,0]],"id":52385934},{"atb":[[10,0],[15,0]],"id":52385903},{"atb":[[3.45,0],[2.98,0]],"id":52385904},{"atb":[[18.5,0],[27,0]],"id":52385936},{"atb":[[10,0],[15,0]],"id":52385931},{"atb":[[3.45,0],[2.98,0]],"id":52385932}],"con":true,"img":false}]}
{"op":"mcm","clk":"11449792879","pt":1717314731732,"mc":[{"id":"1.229554892","rc":[{"atb":[[17,6.25]],"id":52385884}],"con":true,"img":false}]}
{"op":"mcm","clk":"11449792885","pt":1717314731785,"mc":[{"id":"1.229554892","rc":[{"atb":[[15,7.14],[15.5,0]],"id":52385931}],"con":true,"img":false}]}
{"op":"mcm","clk":"11449792895","pt":1717314731892,"mc":[{"id":"1.229554892","rc":[{"atb":[[17.5,0]],"id":52385884}],"con":true,"img":false}]}
{"op":"mcm","clk":"11449792952","pt":1717314732506,"mc":[{"id":"1.229554892","rc":[{"atb":[[23,0]],"id":52385893}],"con":true,"img":false}]}
{"op":"mcm","clk":"11449792962","pt":1717314732606,"mc":[{"id":"1.229554892","rc":[{"atb":[[200,0],[210,2.94]],"id":52385886},{"atb":[[16.5,0],[16,4.6]],"id":52385884},{"atb":[[210,0],[230,3.12]],"id":52385917},{"atb":[[95,1.11]],"id":52385923},{"atb":[[24,2.62]],"id":52385893},{"atl":[[19.5,0],[19,3.62]],"id":52385934},{"atb":[[22,0]],"id":52385903},{"atb":[[14,3.18],[14.5,0]],"id":52385931}],"con":true,"img":false}]}
{"op":"mcm","clk":"11449792972","pt":1717314732709,"mc":[{"id":"1.229554892","rc":[{"atb":[[16.5,6.45]],"id":52385884}],"con":true,"img":false}]}
{"op":"mcm","clk":"11449792982","pt":1717314732812,"mc":[{"id":"1.229554892","rc":[{"atb":[[17,0]],"id":52385884}],"con":true,"img":false}]}
{"op":"mcm","clk":"11449793025","pt":1717314733323,"mc":[{"id":"1.229554892","rc":[{"atb":[[55,5.93]],"id":52385907}],"con":true,"img":false}]}
{"op":"mcm","clk":"11449793035","pt":1717314733381,"mc":[{"id":"1.229554892","rc":[{"atb":[[80,4.61]],"id":52385918},{"atb":[[15.5,3.51]],"id":52385884},{"atb":[[50,6.14]],"id":52385936},{"atl":[[10.5,3.43]],"id":52385932}],"con":true,"img":false}]}
{"op":"mcm","clk":"11449793044","pt":1717314733482,"mc":[{"id":"1.229554892","rc":[{"atb":[[16,0]],"id":52385884},{"atb":[[23,3.39],[24,0]],"id":52385893},{"atl":[[19,0],[19.5,2.67]],"id":52385934}],"con":true,"img":false}]}
{"op":"mcm","clk":"11449793305","pt":1717314736925,"mc":[{"id":"1.229554892","rc":[{"atb":[[14.5,7.41],[15,0]],"id":52385931}],"con":true,"img":false}]}
{"op":"mcm","clk":"11449793335","pt":1717314737238,"mc":[{"id":"1.229554892","rc":[{"atb":[[18.5,13.93],[27,4.01]],"id":52385907},{"atb":[[3.95,82.67],[4.9,26.8]],"id":52385909},{"atb":[[16,16.26],[22,4.97]],"id":52385918},{"atb":[[550,0.44],[650,0.16]],"id":52385886},{"atb":[[17,6.53],[12,22.17]],"id":52385888},{"atb":[[38,2.82],[24,10.6]],"id":52385920},{"atb":[[7.2,39.33],[9.2,12.74]],"id":52385889},{"atb":[[9.2,29.74],[13,8.71]],"id":52385882},{"atb":[[17,6.53],[12,22.17]],"id":52385884},{"atb":[[550,0.44],[650,0.16]],"id":52385917},{"atb":[[2.92,54.44],[2.72,141.8]],"id":52385895},{"atb":[[38,2.82],[24,10.6]],"id":52385923},{"atb":[[2.92,108.94],[2.72,141.8]],"id":52385891},{"atb":[[17,6.53],[12,22.17]],"id":52385893},{"atb":[[3.95,82.67],[4.9,26.8]],"id":52385934},{"atb":[[10,27.1],[15,7.46]],"id":52385903},{"atb":[[18.5,13.93],[27,4.01]],"id":52385936},{"atb":[[3.45,42.66],[2.98,123.18]],"id":52385904},{"atb":[[10,27.1],[15,7.46]],"id":52385931},{"atb":[[3.45,42.66],[2.98,123.18]],"id":52385932}],"con":true,"img":false}]}
{"op":"mcm","clk":"11449793371","pt":1717314737604,"mc":[{"id":"1.229554892","rc":[{"atb":[[46,0]],"id":52385907},{"atb":[[60,0]],"id":52385918},{"atb":[[44,1.83]],"id":52385936},{"atb":[[13.5,2.73],[14,0]],"id":52385931},{"atl":[[11.5,0]],"id":52385932}],"con":true,"img":false}]}
{"op":"mcm","clk":"11449793480","pt":1717314738792,"mc":[{"id":"1.229554892","rc":[{"atl":[[6.2,3.76]],"id":52385895}],"con":true,"img":false}]}
{"op":"mcm","clk":"11449793877","pt":1717314743321,"mc":[{"id":"1.229554892","rc":[{"atb":[[16,3.83],[15.5,0]],"id":52385884},{"atl":[[6.6,0]],"id":52385895},{"atb":[[13.5,0],[14,4.43]],"id":52385931}],"con":true,"img":false}]}
{"op":"mcm","clk":"11449793888","pt":1717314743426,"mc":[{"id":"1.229554892","rc":[{"atl":[[75,2.96]],"id":52385893}],"con":true,"img":false}]}
{"op":"mcm","clk":"11449794418","pt":1717314750218,"mc":[{"id":"1.229554892","rc":[{"atb":[[15.5,6.9]],"id":52385931}],"con":true,"img":false}]}
{"op":"mcm","clk":"11449794428","pt":1717314750326,"mc":[{"id":"1.229554892","rc":[{"atb":[[14.5,0]],"id":52385931}],"con":true,"img":false}]}
{"op":"mcm","clk":"11449794500","pt":1717314751148,"mc":[{"id":"1.229554892","rc":[{"atb":[[17.5,6.06]],"id":52385884}],"con":true,"img":false}]}
{"op":"mcm","clk":"11449794509","pt":1717314751250,"mc":[{"id":"1.229554892","rc":[{"atb":[[16.5,0]],"id":52385884}],"con":true,"img":false}]}
{"op":"mcm","clk":"11449794679","pt":1717314753309,"mc":[{"id":"1.229554892","rc":[{"atb":[[16.5,3.6]],"id":52385884},{"atb":[[14,0],[14.5,3.28]],"id":52385931}],"con":true,"img":false}]}
{"op":"mcm","clk":"11449795092","pt":1717314758544,"mc":[{"id":"1.229554892","rc":[{"atb":[[15,0]],"id":52385884}],"con":true,"img":false}]}
{"op":"mcm","clk":"11449796406","pt":1717314773879,"mc":[{"id":"1.229554892","rc":[{"atb":[[16,0]],"id":52385884}],"con":true,"img":false}]}
{"op":"mcm","clk":"11449796609","pt":1717314776219,"mc":[{"id":"1.229554892","rc":[{"atb":[[15.5,3.02]],"id":52385884}],"con":true,"img":false}]}
{"op":"mcm","clk":"11449796703","pt":1717314777055,"mc":[{"id":"1.229554892","rc":[{"atb":[[18.5,0],[27,0]],"id":52385907},{"atb":[[3.95,0],[4.9,0]],"id":52385909},{"atb":[[16,0],[22,0]],"id":52385918},{"atb":[[550,0],[650,0]],"id":52385886},{"atb":[[17,0],[12,0]],"id":52385888},{"atb":[[38,0],[24,0]],"id":52385920},{"atb":[[7.2,0],[9.2,0]],"id":52385889},{"atb":[[9.2,0],[13,0]],"id":52385882},{"atb":[[17,0],[12,0]],"id":52385884},{"atb":[[550,0],[650,0]],"id":52385917},{"atb":[[2.92,0],[2.72,0]],"id":52385895},{"atb":[[38,0],[24,0]],"id":52385923},{"atb":[[2.92,54.5],[2.72,0]],"id":52385891},{"atb":[[17,0],[12,0]],"id":52385893},{"atb":[[3.95,0],[4.9,0]],"id":52385934},{"atb":[[10,0],[15,0]],"id":52385903},{"atb":[[18.5,0],[27,0]],"id":52385936},{"atb":[[3.45,0],[2.98,0]],"id":52385904},{"atb":[[10,0],[15,0]],"id":52385931},{"atb":[[3.45,0],[2.98,0]],"id":52385932}],"con":true,"img":false}]}
{"op":"mcm","clk":"11449796726","pt":1717314777264,"mc":[{"id":"1.229554892","rc":[{"atb":[[17.5,0],[17,6.25]],"id":52385884},{"atb":[[15,7.14],[15.5,0]],"id":52385931}],"con":true,"img":false}]}
{"op":"mcm","clk":"11449797469","pt":1717314786209,"mc":[{"id":"1.229554892","rc":[{"atb":[[2.04,96.15],[1.95,0]],"id":52385891}],"con":true,"img":false}]}
{"op":"mcm","clk":"11449799632","pt":1717314812974,"mc":[{"id":"1.229554892","rc":[{"atb":[[16,0],[11,3.52],[13.5,0],[9.4,0]],"id":52385889}],"con":true,"img":false}]}
{"op":"mcm","clk":"11449799694","pt":1717314813547,"mc":[{"id":"1.229554892","rc":[{"atb":[[65,0],[60,4.43]],"id":52385907},{"atb":[[7.4,2.83],[7.6,11.89]],"id":52385909},{"atb":[[90,0],[95,3.14]],"id":52385918},{"atb":[[10.5,3.29],[11.5,0]],"id":52385889},{"atb":[[25,0]],"id":52385882},{"atb":[[16.5,0],[16,4.66]],"id":52385884},{"atl":[[220,4.32],[230,0]],"id":52385884},{"atl":[[6,3.89],[5.9,0]],"id":52385895},{"atl":[[6.4,0],[6.2,4.64]],"id":52385891},{"atb":[[7.4,3.45]],"id":52385934},{"atb":[[25,7.74],[26,0]],"id":52385903},{"atb":[[55,4.04],[60,0.88]],"id":52385936},{"atb":[[5.1,22.96],[4.9,0]],"id":52385904},{"atl":[[11,2.66],[11.5,0]],"id":52385904},{"atb":[[14,3.55],[14.5,0]],"id":52385931},{"atl":[[10,3.99],[9.8,0]],"id":52385932}],"con":true,"img":false}]}
{"op":"mcm","clk":"11449799707","pt":1717314813650,"mc":[{"id":"1.229554892","rc":[{"atl":[[970,3.34]],"id":52385920},{"atb":[[26,7.18]],"id":52385882},{"atb":[[16.5,6.45],[17,0]],"id":52385884},{"atb":[[7.6,0]],"id":52385934},{"atb":[[14.5,7.41],[15,0]],"id":52385931}],"con":true,"img":false}]}
{"op":"mcm","clk":"11449799740","pt":1717314813957,"mc":[{"id":"1.229554892","rc":[{"atb":[[17,1.64],[12,7.14],[9.8,11.89],[14.5,3.88]],"id":52385889}],"con":true,"img":false}]}
{"op":"mcm","clk":"11449800603","pt":1717314823547,"mc":[{"id":"1.229554892","rc":[{"atb":[[11,0],[11.5,3]],"id":52385889},{"atb":[[16,0],[14.5,4.04]],"id":52385884},{"atb":[[210,2.73]],"id":52385917},{"atl":[[6.6,3.31]],"id":52385891},{"atb":[[4.9,3.22]],"id":52385904},{"atl":[[12,4.35]],"id":52385904},{"atb":[[13.5,2.85]],"id":52385931}],"con":true,"img":false}]}
{"op":"mcm","clk":"11449800613","pt":1717314823650,"mc":[{"id":"1.229554892","rc":[{"atb":[[14,0]],"id":52385931}],"con":true,"img":false}]}
{"op":"mcm","clk":"11449800624","pt":1717314823751,"mc":[{"id":"1.229554892","rc":[{"atb":[[16.5,0],[16,6.67]],"id":52385884},{"atb":[[13.5,10.85],[14.5,0]],"id":52385931}],"con":true,"img":false}]}
{"op":"mcm","clk":"11449800977","pt":1717314827474,"mc":[{"id":"1.229554892","rc":[{"atb":[[15,3.98],[15.5,0]],"id":52385884},{"atb":[[190,0]],"id":52385917},{"atl":[[7,0]],"id":52385891},{"atb":[[4.7,0]],"id":52385904},{"atl":[[13,0]],"id":52385904},{"atb":[[12.5,3.7],[13.5,8]],"id":52385931}],"con":true,"img":false}]}
{"op":"mcm","clk":"11449801103","pt":1717314828874,"mc":[{"id":"1.229554892","rc":[{"atb":[[16,0],[15.5,6.9]],"id":52385884}],"con":true,"img":false}]}
{"op":"mcm","clk":"11449801113","pt":1717314828975,"mc":[{"id":"1.229554892","rc":[{"atb":[[13,0]],"id":52385931}],"con":true,"img":false}]}
{"op":"mcm","clk":"11449801121","pt":1717314829082,"mc":[{"id":"1.229554892","rc":[{"atb":[[13,8.33],[13.5,0]],"id":52385931}],"con":true,"img":false}]}
{"op":"mcm","clk":"11449801823","pt":1717314837383,"mc":[{"id":"1.229554892","rc":[{"atb":[[15,0]],"id":52385884},{"atb":[[12,3.11],[12.5,0]],"id":52385931}],"con":true,"img":false}]}
{"op":"mcm","clk":"11449801830","pt":1717314837482,"mc":[{"id":"1.229554892","rc":[{"atb":[[13.5,2.87],[15,7.14]],"id":52385884},{"atb":[[12.5,8.7],[13,0]],"id":52385931}],"con":true,"img":false}]}
{"op":"mcm","clk":"11449801839","pt":1717314837586,"mc":[{"id":"1.229554892","rc":[{"atb":[[15.5,0]],"id":52385884}],"con":true,"img":false}]}
{"op":"mcm","clk":"11449801863","pt":1717314837896,"mc":[{"id":"1.229554892","rc":[{"atb":[[18.5,13.93],[27,4.01]],"id":52385907},{"atb":[[3.95,82.67],[4.9,26.8]],"id":52385909},{"atb":[[16,16.26],[22,4.97]],"id":52385918},{"atb":[[550,0.44],[650,0.16]],"id":52385886},{"atb":[[38,2.82],[24,10.6]],"id":52385920},{"atb":[[17,6.53],[12,22.17]],"id":52385888},{"atb":[[7.2,39.33],[9.2,12.74]],"id":52385889},{"atb":[[9.2,29.74],[13,8.71]],"id":52385882},{"atb":[[17,6.53],[12,22.17]],"id":52385884},{"atb":[[550,0.44],[650,0.16]],"id":52385917},{"atb":[[2.92,54.44],[2.72,141.8]],"id":52385895},{"atb":[[2.92,108.94],[2.72,141.8]],"id":52385891},{"atb":[[38,2.82],[24,10.6]],"id":52385923},{"atb":[[17,6.53],[12,22.17]],"id":52385893},{"atb":[[3.95,82.67],[4.9,26.8]],"id":52385934},{"atb":[[10,27.1],[15,7.46]],"id":52385903},{"atb":[[3.45,42.66],[2.98,123.18]],"id":52385904},{"atb":[[18.5,13.93],[27,4.01]],"id":52385936},{"atb":[[10,27.1],[15,7.46]],"id":52385931},{"atb":[[3.45,42.66],[2.98,123.18]],"id":52385932}],"con":true,"img":false}]}
{"op":"mcm","clk":"11449802661","pt":1717314847401,"mc":[{"id":"1.229554892","rc":[{"atb":[[14,4.23]],"id":52385931}],"con":true,"img":false}]}
{"op":"mcm","clk":"11449802669","pt":1717314847499,"mc":[{"id":"1.229554892","rc":[{"atb":[[16,3.75],[14.5,0]],"id":52385884}],"con":true,"img":false}]}
{"op":"mcm","clk":"11449803243","pt":1717314854820,"mc":[{"id":"1.229554892","rc":[{"atb":[[17.5,6.06],[15,0]],"id":52385884},{"atb":[[12.5,0],[15.5,6.9]],"id":52385931}],"con":true,"img":false}]}
{"op":"mcm","clk":"11449803481","pt":1717314857402,"mc":[{"id":"1.229554892","rc":[{"atb":[[14,0],[14.5,3.9]],"id":52385931}],"con":true,"img":false}]}
{"op":"mcm","clk":"11449803490","pt":1717314857502,"mc":[{"id":"1.229554892","rc":[{"atb":[[16,0],[16.5,2.76]],"id":52385884}],"con":true,"img":false}]}
{"op":"mcm","clk":"11449804255","pt":1717314867394,"mc":[{"id":"1.229554892","rc":[{"atb":[[13.5,4.23]],"id":52385931}],"con":true,"img":false}]}
{"op":"mcm","clk":"11449804265","pt":1717314867498,"mc":[{"id":"1.229554892","rc":[{"atb":[[15.5,3.25]],"id":52385884}],"con":true,"img":false}]}
{"op":"mcm","clk":"11449804933","pt":1717314875123,"mc":[{"id":"1.229554892","rc":[{"atb":[[13.5,0]],"id":52385884},{"atb":[[12,0]],"id":52385931}],"con":true,"img":false}]}
{"op":"mcm","clk":"11449822832","pt":1717315069804,"mc":[{"id":"1.229554892","rc":[{"atb":[[2.04,0],[1.95,105.26]],"id":52385891}],"con":true,"img":false}]}
{"op":"mcm","clk":"11449822867","pt":1717315070111,"mc":[{"id":"1.229554892","rc":[{"atb":[[65,3.25],[60,0]],"id":52385907},{"atb":[[7.4,0],[7.6,15.8]],"id":52385909},{"atb":[[90,4.55],[95,0]],"id":52385918},{"atb":[[25,3.37],[26,3.14]],"id":52385882},{"atb":[[7.4,0],[7.6,3.17]],"id":52385934},{"atb":[[25,3.27],[26,3.55]],"id":52385903},{"atb":[[55,0],[60,3.89]],"id":52385936},{"atb":[[5.1,19.14]],"id":52385904}],"con":true,"img":false}]}
{"op":"mcm","clk":"11449823756","pt":1717315080111,"mc":[{"id":"1.229554892","rc":[{"atl":[[970,0]],"id":52385920},{"atl":[[220,0],[230,3.4]],"id":52385884},{"atl":[[6.4,3.94],[6.2,0]],"id":52385891},{"atb":[[4.7,3.86]],"id":52385904},{"atl":[[11,0],[11.5,3.98]],"id":52385904}],"con":true,"img":false}]}
{"op":"mcm","clk":"11449836750","pt":1717315148223,"mc":[{"id":"1.229554892","rc":[{"atb":[[65,0]],"id":52385907},{"atb":[[2.92,54.44],[3.2,0],[3.4,6.53],[3.55,0],[3.3,0],[3.05,0]],"id":52385891},{"atb":[[60,0.88]],"id":52385936}],"con":true,"img":false}]}
{"op":"mcm","clk":"11449836762","pt":1717315148298,"mc":[{"id":"1.229554892","rc":[{"atb":[[3.1,0],[3.35,0],[2.84,0],[2.94,0]],"id":52385895},{"atb":[[3.5,6.27]],"id":52385891},{"atb":[[55,4.48]],"id":52385936},{"atb":[[5.1,0],[4.6,0]],"id":52385904}],"con":true,"img":false}]}
{"op":"mcm","clk":"11449836768","pt":1717315148399,"mc":[{"id":"1.229554892","rc":[{"atb":[[60,3.33]],"id":52385907}],"con":true,"img":false}]}
{"op":"mcm","clk":"11449836805","pt":1717315148912,"mc":[{"id":"1.229554892","rc":[{"atb":[[3.4,39.24],[3.15,48.67],[3.9,9.02],[3.65,19.74]],"id":52385891}],"con":true,"img":false}]}
{"op":"mcm","clk":"11449836813","pt":1717315149014,"mc":[{"id":"1.229554892","rc":[{"atb":[[3,52.32],[3.25,34.88],[3.5,20.93],[3.75,9.51]],"id":52385895},{"atb":[[4.9,23.35],[4.4,30.77]],"id":52385904}],"con":true,"img":false}]}
{"op":"mcm","clk":"11449836852","pt":1717315149481,"mc":[{"id":"1.229554892","rc":[{"atb":[[3.1,0]],"id":52385891}],"con":true,"img":false}]}
{"op":"mcm","clk":"11449837083","pt":1717315152124,"mc":[{"id":"1.229554892","rc":[{"atb":[[3.5,0]],"id":52385891}],"con":true,"img":false}]}
{"op":"mcm","clk":"11449837095","pt":1717315152183,"mc":[{"id":"1.229554892","rc":[{"atb":[[65,4.16],[60,0]],"id":52385907},{"atb":[[3.2,7.13]],"id":52385891},{"atb":[[55,0],[60,5.03]],"id":52385936}],"con":true,"img":false}]}
{"op":"mcm","clk":"11449837341","pt":1717315154722,"mc":[{"id":"1.229554892","rc":[{"atb":[[3,0],[3.25,0],[3.5,0],[3.75,0]],"id":52385895},{"atb":[[3.4,6.53],[3.15,0],[3.9,0],[3.65,0]],"id":52385891}],"con":true,"img":false}]}
{"op":"mcm","clk":"11449837414","pt":1717315155392,"mc":[{"id":"1.229554892","rc":[{"atb":[[3.1,24.91],[3.35,11.13],[2.84,56.87],[2.94,40.45]],"id":52385895},{"atb":[[2.92,108.94],[3.55,10.26],[3.3,22.75],[3.05,38.28]],"id":52385891}],"con":true,"img":false}]}
{"op":"mcm","clk":"11449837477","pt":1717315156089,"mc":[{"id":"1.229554892","rc":[{"atb":[[3.4,0]],"id":52385891}],"con":true,"img":false}]}
{"op":"mcm","clk":"11449837779","pt":1717315159417,"mc":[{"id":"1.229554892","rc":[{"atb":[[44,2.33],[55,3.93]],"id":52385907},{"atb":[[310,2],[400,0]],"id":52385886},{"atb":[[390,2],[510,0]],"id":52385917},{"atb":[[2.06,94.34],[1.95,0]],"id":52385891},{"atb":[[18.5,11.69],[21,4.62]],"id":52385893},{"atb":[[42,2.44],[50,4.1]],"id":52385936}],"con":true,"img":false}]}
{"op":"mcm","clk":"11449837808","pt":1717315159720,"mc":[{"id":"1.229554892","rc":[{"atb":[[65,0],[50,4.6]],"id":52385907},{"atb":[[210,0]],"id":52385886},{"atb":[[75,5.63],[90,0]],"id":52385918},{"atb":[[120,6.02]],"id":52385920},{"atb":[[34,4.5],[38,0]],"id":52385888},{"atb":[[17,0],[12,0],[9.8,0],[14.5,0]],"id":52385889},{"atb":[[210,0],[230,0]],"id":52385917},{"atb":[[130,0]],"id":52385923},{"atb":[[7.4,2.89],[7.6,0]],"id":52385934},{"atb":[[26,0]],"id":52385903},{"atb":[[48,4.3],[60,0.88]],"id":52385936},{"atb":[[5.1,4.11],[4.9,20.12]],"id":52385904}],"con":true,"img":false}]}
{"op":"mcm","clk":"11449837815","pt":1717315159824,"mc":[{"id":"1.229554892","rc":[{"atl":[[560,4.63],[580,0]],"id":52385918},{"atb":[[130,0]],"id":52385920},{"atl":[[130,4.59],[140,0]],"id":52385882},{"atl":[[220,2.93],[230,0]],"id":52385884},{"atl":[[6,0],[5.9,3]],"id":52385895},{"atl":[[890,3.02],[920,0]],"id":52385923},{"atl":[[6.4,0],[6.2,3.97]],"id":52385891},{"atl":[[11,3.92],[11.5,0]],"id":52385904}],"con":true,"img":false}]}
{"op":"mcm","clk":"11449837822","pt":1717315159927,"mc":[{"id":"1.229554892","rc":[{"atl":[[930,2.84],[950,3.68]],"id":52385920}],"con":true,"img":false}]}
{"op":"mcm","clk":"11449837836","pt":1717315160135,"mc":[{"id":"1.229554892","rc":[{"atl":[[180,2.86]],"id":52385907},{"atl":[[570,3.01]],"id":52385918},{"atl":[[920,3.2],[940,4.65],[970,4.07]],"id":52385920},{"atb":[[11.5,0]],"id":52385889},{"atl":[[160,3.16]],"id":52385936}],"con":true,"img":false}]}
{"op":"mcm","clk":"11449837847","pt":1717315160197,"mc":[{"id":"1.229554892","rc":[{"atl":[[190,0]],"id":52385907},{"atl":[[880,3.99]],"id":52385923},{"atl":[[170,0]],"id":52385936}],"con":true,"img":false}]}
{"op":"mcm","clk":"11449837863","pt":1717315160402,"mc":[{"id":"1.229554892","rc":[{"atb":[[16.5,1.69],[9.6,12.17],[11.5,7.48],[14,4.02]],"id":52385889}],"con":true,"img":false}]}
{"op":"mcm","clk":"11449837894","pt":1717315160729,"mc":[{"id":"1.229554892","rc":[{"atb":[[18.5,0],[44,0],[55,5.93],[27,0]],"id":52385907},{"atb":[[3.95,0],[4.9,0]],"id":52385909},{"atb":[[16,0],[22,0]],"id":52385918},{"atb":[[550,0],[310,0],[650,0],[400,2]],"id":52385886},{"atb":[[38,0],[24,0]],"id":52385920},{"atb":[[17,0],[12,0]],"id":52385888},{"atb":[[7.2,0],[9.2,0]],"id":52385889},{"atb":[[9.2,0],[13,0]],"id":52385882},{"atb":[[17,0],[12,0]],"id":52385884},{"atb":[[550,0],[650,0],[390,0],[510,2]],"id":52385917},{"atb":[[2.92,0],[2.72,0]],"id":52385895},{"atb":[[38,0],[24,0]],"id":52385923},{"atb":[[2.92,54.5],[2.72,0],[2.06,0],[1.95,105.26]],"id":52385891},{"atb":[[17,0],[18.5,5.98],[21,9.62],[12,0]],"id":52385893},{"atb":[[3.95,0],[4.9,0]],"id":52385934},{"atb":[[10,0],[15,0]],"id":52385903},{"atb":[[18.5,0],[42,0],[50,6.14],[27,0]],"id":52385936},{"atb":[[3.45,0],[2.98,0]],"id":52385904},{"atb":[[10,0],[15,0]],"id":52385931},{"atb":[[3.45,0],[2.98,0]],"id":52385932}],"con":true,"img":false}]}
{"op":"mcm","clk":"11449837907","pt":1717315160824,"mc":[{"id":"1.229554892","rc":[{"atl":[[920,0],[930,0],[940,0],[950,0],[970,0]],"id":52385920},{"atb":[[390,2]],"id":52385917}],"con":true,"img":false}]}
{"op":"mcm","clk":"11449837917","pt":1717315160931,"mc":[{"id":"1.229554892","rc":[{"atb":[[55,3.93]],"id":52385907},{"atb":[[400,0]],"id":52385886},{"atb":[[16.5,9.21],[17.5,0]],"id":52385884},{"atb":[[510,0]],"id":52385917},{"atb":[[50,4.1]],"id":52385936},{"atb":[[15,7.14],[15.5,0]],"id":52385931}],"con":true,"img":false}]}
{"op":"mcm","clk":"11449837926","pt":1717315161024,"mc":[{"id":"1.229554892","rc":[{"atb":[[65,2.94],[44,2.33],[55,0]],"id":52385907},{"atl":[[180,0],[190,3.47]],"id":52385907},{"atb":[[310,2]],"id":52385886},{"atb":[[80,0],[90,4.67]],"id":52385918},{"atl":[[560,0],[570,0],[590,0],[580,4.32]],"id":52385918},{"atb":[[130,3.07],[120,2]],"id":52385920},{"atb":[[34,0],[38,4.4]],"id":52385888},{"atl":[[130,0],[140,3.71]],"id":52385882},{"atb":[[16,6.67]],"id":52385884},{"atl":[[6,3.64],[5.9,0]],"id":52385895},{"atb":[[130,4.08]],"id":52385923},{"atl":[[880,0],[890,0],[920,3.42],[940,0]],"id":52385923},{"atl":[[6.4,4.47],[6.2,0]],"id":52385891},{"atb":[[7.4,0],[7.6,2.62]],"id":52385934},{"atb":[[26,4.16]],"id":52385903},{"atb":[[42,2.44],[50,0],[60,5.36]],"id":52385936},{"atl":[[160,0],[170,2.83]],"id":52385936},{"atb":[[5.1,0],[4.9,23.6]],"id":52385904},{"atl":[[11,0],[11.5,2.83]],"id":52385904}],"con":true,"img":false}]}
{"op":"mcm","clk":"11449837934","pt":1717315161128,"mc":[{"id":"1.229554892","rc":[{"atl":[[25,3.73]],"id":52385889},{"atb":[[16.5,2.76]],"id":52385884}],"con":true,"img":false}]}
{"op":"mcm","clk":"11449837942","pt":1717315161234,"mc":[{"id":"1.229554892","rc":[{"atl":[[26,0]],"id":52385889}],"con":true,"img":false}]}
{"op":"mcm","clk":"11449837978","pt":1717315161602,"mc":[{"id":"1.229554892","rc":[{"atb":[[200,4.26]],"id":52385886},{"atl":[[930,3.02],[950,3.88]],"id":52385920},{"atb":[[11.5,11.25]],"id":52385889},{"atb":[[16.5,0]],"id":52385884},{"atb":[[190,4.22],[210,3.13]],"id":52385917},{"atl":[[19.5,0],[19,4.34]],"id":52385934},{"atb":[[14,3.76],[14.5,0]],"id":52385931}],"con":true,"img":false}]}
{"op":"mcm","clk":"11449837989","pt":1717315161711,"mc":[{"id":"1.229554892","rc":[{"atb":[[14.5,7.41],[15,0]],"id":52385931}],"con":true,"img":false}]}
{"op":"mcm","clk":"11449838163","pt":1717315163415,"mc":[{"id":"1.229554892","rc":[{"atb":[[390,0],[510,2]],"id":52385917}],"con":true,"img":false}]}
{"op":"mcm","clk":"11449838192","pt":1717315163731,"mc":[{"id":"1.229554892","rc":[{"atb":[[65,0]],"id":52385907},{"atb":[[200,0],[210,3.22]],"id":52385886},{"atb":[[90,0]],"id":52385918},{"atb":[[130,0],[120,6.03]],"id":52385920},{"atl":[[930,0],[970,2.71]],"id":52385920},{"atb":[[34,4.68],[38,0]],"id":52385888},{"atb":[[16.5,0],[9.6,0],[11.5,3.77],[14,0]],"id":52385889},{"atl":[[25,0],[26,3.42]],"id":52385889},{"atb":[[15,3.96],[15.5,0]],"id":52385884},{"atb":[[210,0],[230,4.03]],"id":52385917},{"atb":[[130,0]],"id":52385923},{"atl":[[6.4,0],[6.2,3.92]],"id":52385891},{"atb":[[7.4,3.35],[7.6,0]],"id":52385934},{"atl":[[19,0],[19.5,3.74]],"id":52385934},{"atb":[[26,0]],"id":52385903},{"atb":[[60,0.88]],"id":52385936},{"atb":[[5.1,3.69],[4.9,20.12]],"id":52385904},{"atl":[[11,2.95],[11.5,0]],"id":52385904},{"atb":[[14,0]],"id":52385931}],"con":true,"img":false}]}
{"op":"mcm","clk":"11449838215","pt":1717315163934,"mc":[{"id":"1.229554892","rc":[{"atb":[[15.5,6.9]],"id":52385884},{"atb":[[14,7.69]],"id":52385931}],"con":true,"img":false}]}
{"op":"mcm","clk":"11449838225","pt":1717315164040,"mc":[{"id":"1.229554892","rc":[{"atb":[[16,0]],"id":52385884},{"atb":[[14.5,0]],"id":52385931}],"con":true,"img":false}]}
{"op":"mcm","clk":"11449838271","pt":1717315164401,"mc":[{"id":"1.229554892","rc":[{"atb":[[17,1.64],[12,7.14],[9.8,11.89],[14.5,3.88]],"id":52385889}],"con":true,"img":false}]}
{"op":"mcm","clk":"11449838858","pt":1717315171031,"mc":[{"id":"1.229554892","rc":[{"atb":[[65,3.98]],"id":52385907},{"atb":[[90,3.19]],"id":52385918},{"atl":[[600,4.31]],"id":52385918},{"atb":[[130,3.77]],"id":52385923},{"atl":[[940,3.19]],"id":52385923},{"atb":[[26,3.65]],"id":52385903},{"atb":[[60,4.79]],"id":52385936}],"con":true,"img":false}]}
{"op":"mcm","clk":"11449838883","pt":1717315171235,"mc":[{"id":"1.229554892","rc":[{"atb":[[34,0],[38,4.29]],"id":52385888},{"atb":[[130,3.35],[120,2]],"id":52385920},{"atl":[[950,0],[970,0]],"id":52385920},{"atb":[[14.5,2.84],[15,0]],"id":52385884},{"atl":[[220,0],[230,4.11]],"id":52385884},{"atl":[[6.4,4.05],[6.2,0]],"id":52385891},{"atb":[[7.4,0],[7.6,3.54]],"id":52385934},{"atb":[[4.9,23.03]],"id":52385904},{"atl":[[11.5,2.78]],"id":52385904},{"atb":[[13.5,0]],"id":52385931}],"con":true,"img":false}]}
{"op":"mcm","clk":"11449838892","pt":1717315171340,"mc":[{"id":"1.229554892","rc":[{"atb":[[14.5,10.25]],"id":52385884},{"atb":[[5.1,0]],"id":52385904},{"atl":[[11,0]],"id":52385904},{"atb":[[6,20],[13,2.83]],"id":52385931}],"con":true,"img":false}]}
{"op":"mcm","clk":"11449838904","pt":1717315171440,"mc":[{"id":"1.229554892","rc":[{"atb":[[15.5,0]],"id":52385884},{"atb":[[14,0]],"id":52385931}],"con":true,"img":false}]}
{"op":"mcm","clk":"11449838926","pt":1717315171646,"mc":[{"id":"1.229554892","rc":[{"atb":[[390,2],[510,0]],"id":52385917},{"atb":[[18.5,11.69],[21,4.62]],"id":52385893}],"con":true,"img":false}]}
{"op":"mcm","clk":"11449838957","pt":1717315171954,"mc":[{"id":"1.229554892","rc":[{"atb":[[65,0]],"id":52385907},{"atl":[[560,4.61],[580,0]],"id":52385918},{"atb":[[210,0]],"id":52385886},{"atb":[[120,5.73]],"id":52385920},{"atl":[[950,3.25],[970,3.77]],"id":52385920},{"atb":[[34,3.28]],"id":52385888},{"atb":[[17,0],[12,0],[9.8,0],[14.5,0]],"id":52385889},{"atl":[[25,2.94]],"id":52385889},{"atl":[[130,3.01],[140,0]],"id":52385882},{"atb":[[14.5,7.41]],"id":52385884},{"atl":[[230,0]],"id":52385884},{"atl":[[6,0],[5.9,4.65]],"id":52385895},{"atl":[[880,4.67],[920,0]],"id":52385923},{"atb":[[26,0]],"id":52385903},{"atl":[[12,0]],"id":52385904},{"atb":[[11,4.59],[12,2.69]],"id":52385931}],"con":true,"img":false}]}
{"op":"mcm","clk":"11449838969","pt":1717315172061,"mc":[{"id":"1.229554892","rc":[{"atb":[[90,0]],"id":52385918},{"atb":[[130,0]],"id":52385920},{"atb":[[38,0]],"id":52385888},{"atl":[[26,0]],"id":52385889},{"atb":[[13.5,4.4]],"id":52385884},{"atl":[[220,3.55]],"id":52385884},{"atb":[[230,0]],"id":52385917},{"atb":[[130,0]],"id":52385923},{"atb":[[7.4,3.7],[7.6,0]],"id":52385934},{"atb":[[4.7,0]],"id":52385904},{"atb":[[60,0.88]],"id":52385936}],"con":true,"img":false}]}
{"op":"mcm","clk":"11449839014","pt":1717315172428,"mc":[{"id":"1.229554892","rc":[{"atb":[[11.5,0]],"id":52385889},{"atl":[[6.4,0],[6.2,4.6]],"id":52385891},{"atb":[[5.1,4.21],[4.9,20.12]],"id":52385904},{"atl":[[11,3.43],[11.5,0]],"id":52385904},{"atb":[[13,0]],"id":52385931}],"con":true,"img":false}]}
{"op":"mcm","clk":"11449839069","pt":1717315172942,"mc":[{"id":"1.229554892","rc":[{"atb":[[17,1.64],[12,7.14],[9.8,11.89],[14.5,3.88]],"id":52385889}],"con":true,"img":false}]}
{"op":"mcm","clk":"11449839148","pt":1717315173767,"mc":[{"id":"1.229554892","rc":[{"atb":[[210,4.29]],"id":52385886},{"atb":[[230,4.24]],"id":52385917}],"con":true,"img":false}]}
{"op":"mcm","clk":"11449839260","pt":1717315174757,"mc":[{"id":"1.229554892","rc":[{"atb":[[210,0]],"id":52385886},{"atl":[[560,0],[580,2.81]],"id":52385918},{"atl":[[950,0],[970,0]],"id":52385920},{"atb":[[11.5,4.56]],"id":52385889},{"atl":[[25,0],[26,4.11]],"id":52385889},{"atl":[[130,0],[140,3.78]],"id":52385882},{"atl":[[220,0],[230,2.83]],"id":52385884},{"atb":[[230,0]],"id":52385917},{"atl":[[6,3.28],[5.9,0]],"id":52385895},{"atl":[[6.4,2.83],[6.2,0]],"id":52385891},{"atl":[[880,0],[920,4.22]],"id":52385923},{"atl":[[11,0],[11.5,3.89]],"id":52385904},{"atb":[[12,0]],"id":52385931}],"con":true,"img":false}]}
{"op":"mcm","clk":"11449839270","pt":1717315174855,"mc":[{"id":"1.229554892","rc":[{"atb":[[2.06,94.34],[1.95,0]],"id":52385891}],"con":true,"img":false}]}
{"op":"mcm","clk":"11449839296","pt":1717315175062,"mc":[{"id":"1.229554892","rc":[{"atl":[[180,3.3]],"id":52385907},{"atl":[[570,2.75]],"id":52385918},{"atl":[[920,2.68]],"id":52385920},{"atl":[[160,3.77],[170,0]],"id":52385936}],"con":true,"img":false}]}
{"op":"mcm","clk":"11449839309","pt":1717315175166,"mc":[{"id":"1.229554892","rc":[{"atl":[[190,0]],"id":52385907}],"con":true,"img":false}]}
{"op":"mcm","clk":"11449839424","pt":1717315176359,"mc":[{"id":"1.229554892","rc":[{"atl":[[180,0],[190,3.18]],"id":52385907},{"atl":[[570,0]],"id":52385918},{"atl":[[920,0],[970,2.62]],"id":52385920},{"atl":[[220,2.94],[230,0]],"id":52385884},{"atl":[[6.4,0],[6.2,4.21]],"id":52385891},{"atl":[[160,0],[170,3.73]],"id":52385936},{"atl":[[11,3.05]],"id":52385904},{"atb":[[10,4.35],[11,0]],"id":52385931}],"con":true,"img":false}]}
{"op":"mcm","clk":"11449839431","pt":1717315176459,"mc":[{"id":"1.229554892","rc":[{"atb":[[14,7.69],[14.5,0]],"id":52385884}],"con":true,"img":false}]}
{"op":"mcm","clk":"11449839664","pt":1717315178766,"mc":[{"id":"1.229554892","rc":[{"atb":[[17,0],[12,0],[9.8,0],[14.5,0]],"id":52385889}],"con":true,"img":false}]}
{"op":"mcm","clk":"11449839738","pt":1717315179437,"mc":[{"id":"1.229554892","rc":[{"atl":[[180,4.42],[190,0]],"id":52385907},{"atl":[[580,0],[590,3.91]],"id":52385918},{"atl":[[960,3.06]],"id":52385920},{"atb":[[16.5,1.69],[9.6,12.17],[11.5,7.48],[14,4.02]],"id":52385889},{"atb":[[13,4.32]],"id":52385884},{"atl":[[6,0]],"id":52385895},{"atl":[[6.4,2.66],[6.2,0]],"id":52385891},{"atl":[[920,0],[910,4.63]],"id":52385923},{"atl":[[10,0]],"id":52385932}],"con":true,"img":false}]}
{"op":"mcm","clk":"11449839749","pt":1717315179535,"mc":[{"id":"1.229554892","rc":[{"atb":[[13.5,0]],"id":52385884},{"atb":[[9.6,3.98],[10,0]],"id":52385931}],"con":true,"img":false}]}
{"op":"mcm","clk":"11449839890","pt":1717315181031,"mc":[{"id":"1.229554892","rc":[{"atb":[[22,3.85]],"id":52385903}],"con":true,"img":false}]}
{"op":"mcm","clk":"11449839918","pt":1717315181339,"mc":[{"id":"1.229554892","rc":[{"atl":[[11.5,4.69]],"id":52385932}],"con":true,"img":false}]}
{"op":"mcm","clk":"11449839933","pt":1717315181546,"mc":[{"id":"1.229554892","rc":[{"atb":[[44,0],[48,3.8]],"id":52385907},{"atb":[[13.5,8]],"id":52385884}],"con":true,"img":false}]}
{"op":"mcm","clk":"11449839942","pt":1717315181651,"mc":[{"id":"1.229554892","rc":[{"atb":[[14,0]],"id":52385884}],"con":true,"img":false}]}
{"op":"mcm","clk":"11449839957","pt":1717315181849,"mc":[{"id":"1.229554892","rc":[{"atb":[[55,3.29]],"id":52385907},{"atb":[[7.6,11.89],[7.8,3.58]],"id":52385909},{"atb":[[70,4.89],[75,1.06]],"id":52385918},{"atb":[[34,0],[36,5.84]],"id":52385888},{"atb":[[11,4.45]],"id":52385889},{"atb":[[24,4.04],[25,0]],"id":52385882},{"atb":[[7.4,0],[7.6,4.22]],"id":52385934},{"atb":[[24,0],[25,6.98]],"id":52385903},{"atb":[[50,4.48]],"id":52385936},{"atb":[[5.1,0],[5,3.25]],"id":52385904},{"atb":[[9.6,0],[9.2,3.86]],"id":52385931}],"con":true,"img":false}]}
{"op":"mcm","clk":"11449840239","pt":1717315184746,"mc":[{"id":"1.229554892","rc":[{"atl":[[6.6,4.43]],"id":52385895}],"con":true,"img":false}]}
{"op":"mcm","clk":"11449840289","pt":1717315185259,"mc":[{"id":"1.229554892","rc":[{"atb":[[16.5,0],[9.6,0],[11.5,0],[14,0]],"id":52385889}],"con":true,"img":false}]}
{"op":"mcm","clk":"11449840302","pt":1717315185361,"mc":[{"id":"1.229554892","rc":[{"atb":[[9.4,11.9]],"id":52385931}],"con":true,"img":false}]}
{"op":"mcm","clk":"11449840314","pt":1717315185462,"mc":[{"id":"1.229554892","rc":[{"atb":[[6,0]],"id":52385931}],"con":true,"img":false}]}
{"op":"mcm","clk":"11449840353","pt":1717315185933,"mc":[{"id":"1.229554892","rc":[{"atb":[[16,1.74],[11,12.3],[13.5,4.19],[9.4,12.46]],"id":52385889}],"con":true,"img":false}]}
{"op":"mcm","clk":"11449840370","pt":1717315186138,"mc":[{"id":"1.229554892","rc":[{"atl":[[560,3.77],[590,0]],"id":52385918},{"atl":[[920,3.47],[960,0]],"id":52385920},{"atb":[[10,3.06],[11,7.85]],"id":52385889},{"atl":[[25,3.89],[26,0]],"id":52385889},{"atl":[[130,2.74],[140,0]],"id":52385882},{"atb":[[12.5,3.93],[13,0]],"id":52385884},{"atl":[[910,0],[900,4.44]],"id":52385923},{"atl":[[65,0],[60,4.39]],"id":52385893},{"atl":[[11,0]],"id":52385904},{"atl":[[160,4.52],[170,0]],"id":52385936},{"atb":[[9,2.62],[9.2,0]],"id":52385931},{"atl":[[10.5,0],[11,3.54]],"id":52385932}],"con":true,"img":false}]}
{"op":"mcm","clk":"11449840385","pt":1717315186346,"mc":[{"id":"1.229554892","rc":[{"atb":[[13,8.33],[13.5,0]],"id":52385884}],"con":true,"img":false}]}
{"op":"mcm","clk":"11449840398","pt":1717315186450,"mc":[{"id":"1.229554892","rc":[{"atl":[[550,3.56]],"id":52385918},{"atl":[[930,2.63]],"id":52385920},{"atl":[[6,4.59]],"id":52385895},{"atl":[[6.4,0]],"id":52385891},{"atb":[[22,6.53],[23,0]],"id":52385893}],"con":true,"img":false}]}
{"op":"mcm","clk":"11449840412","pt":1717315186550,"mc":[{"id":"1.229554892","rc":[{"atl":[[6.2,0]],"id":52385895},{"atb":[[3.3,29.57]],"id":52385891},{"atl":[[6.2,3.34]],"id":52385891}],"con":true,"img":false}]}
{"op":"mcm","clk":"11449840421","pt":1717315186658,"mc":[{"id":"1.229554892","rc":[{"atb":[[3.4,6.53]],"id":52385891}],"con":true,"img":false}]}
{"op":"mcm","clk":"11449840773","pt":1717315190479,"mc":[{"id":"1.229554892","rc":[{"atb":[[9,15.12]],"id":52385931}],"con":true,"img":false}]}
{"op":"mcm","clk":"11449840785","pt":1717315190581,"mc":[{"id":"1.229554892","rc":[{"atb":[[9.4,0]],"id":52385931}],"con":true,"img":false}]}
{"op":"mcm","clk":"11449840903","pt":1717315191875,"mc":[{"id":"1.229554892","rc":[{"atb":[[4.8,4.53]],"id":52385904},{"atl":[[11,4.48]],"id":52385904}],"con":true,"img":false}]}
{"op":"mcm","clk":"11449840954","pt":1717315192342,"mc":[{"id":"1.229554892","rc":[{"atb":[[40,2.56]],"id":52385907},{"atb":[[70,2.89],[46,2.22]],"id":52385918},{"atb":[[80,2],[120,3.73]],"id":52385920},{"atb":[[330,2],[390,0]],"id":52385917},{"atb":[[75,2],[110,3.57]],"id":52385923}],"con":true,"img":false}]}
{"op":"mcm","clk":"11449840963","pt":1717315192445,"mc":[{"id":"1.229554892","rc":[{"atb":[[48,1.67]],"id":52385907},{"atb":[[18.5,5.98]],"id":52385893}],"con":true,"img":false}]}
{"op":"mcm","clk":"11449840971","pt":1717315192548,"mc":[{"id":"1.229554892","rc":[{"atb":[[16,6.67]],"id":52385893}],"con":true,"img":false}]}
{"op":"mcm","clk":"11449840981","pt":1717315192651,"mc":[{"id":"1.229554892","rc":[{"atb":[[46,3.58],[55,0]],"id":52385907},{"atb":[[70,0],[50,6.79]],"id":52385918},{"atl":[[540,4.14],[550,0],[600,0]],"id":52385918},{"atb":[[530,0],[580,0],[630,0],[480,0]],"id":52385886},{"atl":[[920,0],[900,4.02],[930,0],[970,0]],"id":52385920},{"atl":[[210,0],[220,4.54]],"id":52385888},{"atb":[[10.5,0],[11,11.16],[11.5,4.11]],"id":52385889},{"atb":[[24,0],[25,4.66]],"id":52385882},{"atb":[[12,3.86],[12.5,0]],"id":52385884},{"atb":[[100,3.45],[110,0]],"id":52385923},{"atl":[[880,4.45],[900,0]],"id":52385923},{"atb":[[3.2,0]],"id":52385891},{"atb":[[20,3.78],[22,3.74],[23,4.52]],"id":52385893},{"atb":[[34,0],[85,0],[42,5.42],[44,0],[50,0],[60,0]],"id":52385936},{"atl":[[160,0],[170,3.02]],"id":52385936},{"atb":[[9,12.5],[8.6,3.98]],"id":52385931},{"atl":[[10.5,3.62],[11,0]],"id":52385932}],"con":true,"img":false}]}
{"op":"mcm","clk":"11449840993","pt":1717315192755,"mc":[{"id":"1.229554892","rc":[{"atb":[[70,0],[38,0],[95,0],[48,0]],"id":52385907},{"atb":[[190,2]],"id":52385886},{"atb":[[120,0]],"id":52385920},{"atb":[[38,2.7]],"id":52385936}],"con":true,"img":false}]}
{"op":"mcm","clk":"11449841001","pt":1717315192861,"mc":[{"id":"1.229554892","rc":[{"atb":[[310,0]],"id":52385886},{"atb":[[12.5,8.7],[13,0]],"id":52385884},{"atb":[[42,2.98]],"id":52385936}],"con":true,"img":false}]}
{"op":"mcm","clk":"11449841086","pt":1717315193786,"mc":[{"id":"1.229554892","rc":[{"atb":[[34,3.17],[85,0.31],[44,1.83],[60,0.88]],"id":52385907},{"atb":[[520,0.1],[570,0.05],[420,0.25],[470,0.17]],"id":52385886},{"atb":[[32,3.37],[80,0.33],[42,4.9],[55,0.97]],"id":52385936}],"con":true,"img":false}]}
{"op":"mcm","clk":"11449841178","pt":1717315194770,"mc":[{"id":"1.229554892","rc":[{"atb":[[190,5.28]],"id":52385886},{"atb":[[10,0]],"id":52385889},{"atb":[[11.5,4.18]],"id":52385884},{"atb":[[200,3.58]],"id":52385917},{"atb":[[21,0],[23,0]],"id":52385893},{"atb":[[48,0]],"id":52385936}],"con":true,"img":false}]}
{"op":"mcm","clk":"11449841186","pt":1717315194874,"mc":[{"id":"1.229554892","rc":[{"atb":[[50,0]],"id":52385907},{"atb":[[12,0]],"id":52385884}],"con":true,"img":false}]}
{"op":"mcm","clk":"11449841195","pt":1717315194977,"mc":[{"id":"1.229554892","rc":[{"atb":[[12,9.09]],"id":52385884}],"con":true,"img":false}]}
{"op":"mcm","clk":"11449841205","pt":1717315195077,"mc":[{"id":"1.229554892","rc":[{"atb":[[12.5,0]],"id":52385884}],"con":true,"img":false}]}
{"op":"mcm","clk":"11449841253","pt":1717315195552,"mc":[{"id":"1.229554892","rc":[{"atb":[[9,0],[8.8,12.82]],"id":52385931}],"con":true,"img":false}]}
{"op":"mcm","clk":"11449841761","pt":1717315200495,"mc":[{"id":"1.229554892","rc":[{"atb":[[11,3.65],[11.5,0]],"id":52385884},{"atb":[[8.6,0],[8.4,3.07]],"id":52385931}],"con":true,"img":false}]}
{"op":"mcm","clk":"11449841794","pt":1717315200658,"mc":[{"id":"1.229554892","rc":[{"atb":[[11.5,9.52],[12,0]],"id":52385884},{"atb":[[8.6,13.16],[8.8,0]],"id":52385931}],"con":true,"img":false}]}
{"op":"mcm","clk":"11449842030","pt":1717315202695,"mc":[{"id":"1.229554892","rc":[{"atb":[[42,4.2]],"id":52385907},{"atb":[[46,6.49]],"id":52385918},{"atb":[[90,3.85]],"id":52385920},{"atl":[[920,3.47]],"id":52385920},{"atb":[[90,2.96]],"id":52385923},{"atl":[[900,4.55]],"id":52385923},{"atb":[[19,3.49]],"id":52385893},{"atb":[[38,6.21]],"id":52385936}],"con":true,"img":false}]}
{"op":"mcm","clk":"11449842469","pt":1717315206587,"mc":[{"id":"1.229554892","rc":[{"atb":[[280,2]],"id":52385886}],"con":true,"img":false}]}
{"op":"mcm","clk":"11449842479","pt":1717315206695,"mc":[{"id":"1.229554892","rc":[{"atb":[[190,3.28]],"id":52385886}],"con":true,"img":false}]}
{"op":"mcm","clk":"11449842700","pt":1717315208781,"mc":[{"id":"1.229554892","rc":[{"atl":[[940,0]],"id":52385923},{"atb":[[3.2,7.13],[3.4,0]],"id":52385891}],"con":true,"img":false}]}
{"op":"mcm","clk":"11449842711","pt":1717315208886,"mc":[{"id":"1.229554892","rc":[{"atb":[[34,0],[18.5,0],[22,0],[27,0]],"id":52385893}],"con":true,"img":false}]}
{"op":"mcm","clk":"11449842792","pt":1717315209605,"mc":[{"id":"1.229554892","rc":[{"atb":[[32,0.84],[18,6.15],[21,3.92],[26,2.09]],"id":52385893}],"con":true,"img":false}]}
{"op":"mcm","clk":"11449842879","pt":1717315210485,"mc":[{"id":"1.229554892","rc":[{"atb":[[10.5,3.34],[11,0]],"id":52385884},{"atb":[[8.2,4.27],[8.4,0]],"id":52385931}],"con":true,"img":false}]}
{"op":"mcm","clk":"11449842892","pt":1717315210589,"mc":[{"id":"1.229554892","rc":[{"atb":[[11,10],[11.5,0]],"id":52385884},{"atb":[[8.4,13.51]],"id":52385931}],"con":true,"img":false}]}
{"op":"mcm","clk":"11449842903","pt":1717315210692,"mc":[{"id":"1.229554892","rc":[{"atb":[[2.06,0],[1.96,104.17]],"id":52385891},{"atb":[[8.6,0]],"id":52385931}],"con":true,"img":false}]}
{"op":"mcm","clk":"11449842928","pt":1717315210901,"mc":[{"id":"1.229554892","rc":[{"atb":[[44,3.69]],"id":52385936}],"con":true,"img":false}]}
{"op":"mcm","clk":"11449842940","pt":1717315211003,"mc":[{"id":"1.229554892","rc":[{"atb":[[44,5.26],[46,0]],"id":52385907},{"atb":[[520,0],[570,0],[420,0],[470,0]],"id":52385886},{"atb":[[11.5,0]],"id":52385889},{"atb":[[24,3.23],[25,0]],"id":52385882},{"atb":[[3.3,22.75]],"id":52385891},{"atb":[[7.6,0],[7.8,3.93]],"id":52385934},{"atb":[[42,1.92]],"id":52385936},{"atb":[[5.2,0],[5.7,0],[4.2,0],[4.7,0]],"id":52385932}],"con":true,"img":false}]}
{"op":"mcm","clk":"11449842956","pt":1717315211061,"mc":[{"id":"1.229554892","rc":[{"atb":[[200,2]],"id":52385886}],"con":true,"img":false}]}
{"op":"mcm","clk":"11449842968","pt":1717315211160,"mc":[{"id":"1.229554892","rc":[{"atb":[[280,0]],"id":52385886}],"con":true,"img":false}]}
{"op":"mcm","clk":"11449843010","pt":1717315211575,"mc":[{"id":"1.229554892","rc":[{"atb":[[550,0.44],[650,0.16]],"id":52385886},{"atb":[[17,6.53],[12,22.17]],"id":52385888},{"atb":[[7.2,39.33],[9.2,12.74]],"id":52385889},{"atb":[[9.2,29.74],[13,8.71]],"id":52385882},{"atb":[[17,6.53],[12,22.17]],"id":52385884},{"atb":[[2.92,54.44],[2.72,141.8]],"id":52385895},{"atb":[[2.92,108.94],[2.72,141.8]],"id":52385891},{"atb":[[17,6.53],[12,22.17]],"id":52385893},{"atb":[[10,27.1],[15,7.46]],"id":52385903},{"atb":[[3.45,42.66],[2.98,123.18]],"id":52385904}],"con":true,"img":false}]}
{"op":"mcm","clk":"11449843022","pt":1717315211688,"mc":[{"id":"1.229554892","rc":[{"atb":[[18.5,13.93],[27,4.01]],"id":52385907},{"atb":[[3.95,82.67],[4.9,26.8]],"id":52385909},{"atb":[[560,0.05],[410,0.26],[460,0.17],[510,0.1]],"id":52385886},{"atb":[[16,16.26],[22,4.97]],"id":52385918},{"atb":[[38,2.82],[24,10.6]],"id":52385920},{"atb":[[550,0.44],[650,0.16]],"id":52385917},{"atb":[[38,2.82],[24,10.6]],"id":52385923},{"atb":[[3.95,82.67],[4.9,26.8]],"id":52385934},{"atb":[[18.5,13.93],[27,4.01]],"id":52385936},{"atb":[[10,27.1],[15,7.46]],"id":52385931},{"atb":[[4.8,20.65],[3.45,42.66],[4.3,31.71],[5.8,5.45],[5.3,12.17],[2.98,123.18]],"id":52385932}],"con":true,"img":false}]}
{"op":"mcm","clk":"11449843033","pt":1717315211792,"mc":[{"id":"1.229554892","rc":[{"atb":[[270,2]],"id":52385886}],"con":true,"img":false}]}
{"op":"mcm","clk":"11449843044","pt":1717315211890,"mc":[{"id":"1.229554892","rc":[{"atb":[[200,0]],"id":52385886}],"con":true,"img":false}]}
{"op":"mcm","clk":"11449843101","pt":1717315212366,"mc":[{"id":"1.229554892","rc":[{"atb":[[2.06,94.34],[1.96,0]],"id":52385891}],"con":true,"img":false}]}
{"op":"mcm","clk":"11449843122","pt":1717315212579,"mc":[{"id":"1.229554892","rc":[{"atl":[[19,3.36],[21,0]],"id":52385909},{"atb":[[16,4.64]],"id":52385884},{"atl":[[18,4.22]],"id":52385934},{"atl":[[75,2.83],[80,0]],"id":52385903},{"atb":[[14,3.37]],"id":52385931}],"con":true,"img":false}]}
{"op":"mcm","clk":"11449843133","pt":1717315212678,"mc":[{"id":"1.229554892","rc":[{"atb":[[40,7.18],[44,1.83]],"id":52385907},{"atb":[[7.6,16.22],[7.8,0]],"id":52385909},{"atb":[[560,0],[410,0],[460,0],[510,0]],"id":52385886},{"atb":[[50,2.13],[55,4.39]],"id":52385918},{"atl":[[540,0],[530,4.59]],"id":52385918},{"atl":[[890,4.69],[900,0]],"id":52385920},{"atb":[[36,2.24],[38,3.25]],"id":52385888},{"atl":[[210,3.26],[220,0]],"id":52385888},{"atb":[[11.5,3.17]],"id":52385889},{"atl":[[24,3.88],[25,0]],"id":52385889},{"atb":[[24,0],[26,6.53]],"id":52385882},{"atl":[[880,0],[870,2.62]],"id":52385923},{"atl":[[55,2.73],[60,0]],"id":52385893},{"atb":[[7.6,3.85],[7.8,0]],"id":52385934},{"atl":[[19.5,0]],"id":52385934},{"atb":[[40,4.58],[44,0]],"id":52385936},{"atb":[[5.1,3.31],[5,0]],"id":52385904},{"atb":[[4.8,0],[4.3,0],[5.8,0],[5.3,0]],"id":52385932}],"con":true,"img":false}]}
{"op":"mcm","clk":"11449843199","pt":1717315213401,"mc":[{"id":"1.229554892","rc":[{"atb":[[4.9,20.12],[4.4,30.77],[5.9,5.34],[5.4,11.89]],"id":52385932}],"con":true,"img":false}]}
{"op":"mcm","clk":"11449843209","pt":1717315213504,"mc":[{"id":"1.229554892","rc":[{"atb":[[550,0.49],[400,0.26],[450,0.17],[500,0.1]],"id":52385886}],"con":true,"img":false}]}
{"op":"mcm","clk":"11449843263","pt":1717315213980,"mc":[{"id":"1.229554892","rc":[{"atb":[[42,0]],"id":52385907},{"atl":[[18.5,4.39],[19,0]],"id":52385909},{"atl":[[890,0],[900,2.98]],"id":52385920},{"atl":[[24,0],[25,4.53]],"id":52385889},{"atl":[[860,4.3],[870,0]],"id":52385923}],"con":true,"img":false}]}
{"op":"mcm","clk":"11449843305","pt":1717315214392,"mc":[{"id":"1.229554892","rc":[{"atb":[[17.5,6.06],[11,0]],"id":52385884},{"atb":[[8.4,0],[15.5,6.9]],"id":52385931}],"con":true,"img":false}]}
{"op":"mcm","clk":"11449843769","pt":1717315218792,"mc":[{"id":"1.229554892","rc":[{"atb":[[3.1,7.47]],"id":52385891}],"con":true,"img":false}]}
{"op":"mcm","clk":"11449844159","pt":1717315222622,"mc":[{"id":"1.229554892","rc":[{"atb":[[16,0],[16.5,2.65]],"id":52385884},{"atb":[[14,0],[14.5,3.15]],"id":52385931}],"con":true,"img":false}]}
{"op":"mcm","clk":"11449844173","pt":1717315222689,"mc":[{"id":"1.229554892","rc":[{"atb":[[36,4.61]],"id":52385907},{"atl":[[65,4.7]],"id":52385893},{"atl":[[19,3.98]],"id":52385934}],"con":true,"img":false}]}
{"op":"mcm","clk":"11449844278","pt":1717315223715,"mc":[{"id":"1.229554892","rc":[{"atl":[[75,0]],"id":52385893},{"atl":[[20,0]],"id":52385934}],"con":true,"img":false}]}
{"op":"mcm","clk":"11449844312","pt":1717315223979,"mc":[{"id":"1.229554892","rc":[{"atl":[[19.5,4.32]],"id":52385909},{"atl":[[880,2.99]],"id":52385923}],"con":true,"img":false}]}
{"op":"mcm","clk":"11449845143","pt":1717315232607,"mc":[{"id":"1.229554892","rc":[{"atb":[[15.5,2.78]],"id":52385884},{"atb":[[13.5,3.38]],"id":52385931}],"con":true,"img":false}]}
{"op":"mcm","clk":"11449845148","pt":1717315232707,"mc":[{"id":"1.229554892","rc":[{"atl":[[170,2.67]],"id":52385907}],"con":true,"img":false}]}
{"op":"mcm","clk":"11449845157","pt":1717315232808,"mc":[{"id":"1.229554892","rc":[{"atl":[[180,0]],"id":52385907}],"con":true,"img":false}]}
{"op":"mcm","clk":"11449845236","pt":1717315233591,"mc":[{"id":"1.229554892","rc":[{"atl":[[530,0],[480,4.58]],"id":52385918},{"atl":[[11,0],[12.5,4.55]],"id":52385904}],"con":true,"img":false}]}
{"op":"mcm","clk":"11449845246","pt":1717315233690,"mc":[{"id":"1.229554892","rc":[{"atl":[[160,3.04],[170,0]],"id":52385936}],"con":true,"img":false}]}
{"op":"mcm","clk":"11449845269","pt":1717315234002,"mc":[{"id":"1.229554892","rc":[{"atl":[[780,2.99]],"id":52385923}],"con":true,"img":false}]}
{"op":"mcm","clk":"11449845275","pt":1717315234106,"mc":[{"id":"1.229554892","rc":[{"atl":[[23,0]],"id":52385909},{"atl":[[860,0],[900,0]],"id":52385923}],"con":true,"img":false}]}
{"op":"mcm","clk":"11449845700","pt":1717315239010,"mc":[{"id":"1.229554892","rc":[{"atl":[[820,3.69],[900,0]],"id":52385920},{"atb":[[10.5,0]],"id":52385884},{"atb":[[8.2,0]],"id":52385931}],"con":true,"img":false}]}
{"op":"mcm","clk":"11449846020","pt":1717315242706,"mc":[{"id":"1.229554892","rc":[{"atl":[[190,3.17]],"id":52385907}],"con":true,"img":false}]}
{"op":"mcm","clk":"11449846061","pt":1717315243121,"mc":[{"id":"1.229554892","rc":[{"atb":[[40,4.62],[44,4.16]],"id":52385907},{"atb":[[46,4.27],[60,2]],"id":52385918},{"atb":[[80,0],[100,6.11]],"id":52385920},{"atb":[[380,2]],"id":52385917},{"atb":[[95,3.11]],"id":52385923}],"con":true,"img":false}]}
{"op":"mcm","clk":"11449846070","pt":1717315243224,"mc":[{"id":"1.229554892","rc":[{"atb":[[330,0]],"id":52385917},{"atb":[[75,0]],"id":52385923}],"con":true,"img":false}]}
{"op":"mcm","clk":"11449846084","pt":1717315243328,"mc":[{"id":"1.229554892","rc":[{"atb":[[36,7.47],[44,1.83]],"id":52385907},{"atb":[[60,0]],"id":52385918},{"atb":[[100,4.11]],"id":52385920},{"atb":[[320,2],[380,0]],"id":52385917}],"con":true,"img":false}]}
{"op":"mcm","clk":"11449846095","pt":1717315243432,"mc":[{"id":"1.229554892","rc":[{"atb":[[50,4.2]],"id":52385907},{"atb":[[8,3.25],[7.6,11.89]],"id":52385909},{"atb":[[48,2.13],[55,0]],"id":52385918},{"atb":[[80,2],[100,1.06],[120,3.42]],"id":52385920},{"atb":[[36,5.75],[38,0]],"id":52385888},{"atb":[[11.5,0]],"id":52385889},{"atb":[[25,4.53],[26,3.14]],"id":52385882},{"atb":[[100,0],[110,4.68]],"id":52385923},{"atb":[[20,0],[21,8.15]],"id":52385893},{"atb":[[7.6,0],[7.8,3.27]],"id":52385934},{"atb":[[24,2.67],[25,3.27]],"id":52385903},{"atb":[[40,0],[46,3.92]],"id":52385936},{"atb":[[5.1,0],[5.3,3.1]],"id":52385904}],"con":true,"img":false}]}
{"op":"mcm","clk":"11449846101","pt":1717315243532,"mc":[{"id":"1.229554892","rc":[{"atb":[[40,0]],"id":52385907},{"atl":[[210,0]],"id":52385907},{"atb":[[70,3.25]],"id":52385918}],"con":true,"img":false}]}
{"op":"mcm","clk":"11449846213","pt":1717315244623,"mc":[{"id":"1.229554892","rc":[{"atb":[[36,4.61],[44,4.16]],"id":52385907},{"atb":[[48,0],[60,2]],"id":52385918},{"atb":[[80,0],[100,3.06]],"id":52385920},{"atb":[[320,0],[380,2]],"id":52385917}],"con":true,"img":false}]}
{"op":"mcm","clk":"11449846241","pt":1717315245033,"mc":[{"id":"1.229554892","rc":[{"atb":[[36,7.47],[44,1.83]],"id":52385907},{"atb":[[60,0]],"id":52385918},{"atb":[[100,1.06]],"id":52385920},{"atb":[[320,2],[380,0]],"id":52385917}],"con":true,"img":false}]}
{"op":"mcm","clk":"11449846250","pt":1717315245136,"mc":[{"id":"1.229554892","rc":[{"atb":[[48,2.13]],"id":52385918},{"atb":[[80,2]],"id":52385920}],"con":true,"img":false}]}
{"op":"mcm","clk":"11449846265","pt":1717315245344,"mc":[{"id":"1.229554892","rc":[{"atb":[[40,4.64],[50,0]],"id":52385907},{"atb":[[8,0],[7.6,15.99]],"id":52385909},{"atb":[[70,0],[55,3.43]],"id":52385918},{"atb":[[100,4.04],[120,0]],"id":52385920},{"atb":[[36,2.24],[38,3.57]],"id":52385888},{"atb":[[11.5,3.79]],"id":52385889},{"atb":[[25,0],[26,6.54]],"id":52385882},{"atb":[[100,3.52],[110,0]],"id":52385923},{"atb":[[20,3.54],[21,3.92]],"id":52385893},{"atb":[[7.6,3.04],[7.8,0]],"id":52385934},{"atb":[[24,0],[25,7.2]],"id":52385903},{"atb":[[5.1,4.2],[5.3,0]],"id":52385904},{"atb":[[40,4.54],[46,0]],"id":52385936}],"con":true,"img":false}]}
{"op":"mcm","clk":"11449846422","pt":1717315246902,"mc":[{"id":"1.229554892","rc":[{"atb":[[36,4.61],[44,4.16]],"id":52385907},{"atb":[[48,0],[60,2]],"id":52385918},{"atb":[[80,0],[100,6.04]],"id":52385920},{"atb":[[320,0],[380,2]],"id":52385917}],"con":true,"img":false}]}
{"op":"mcm","clk":"11449846456","pt":1717315247219,"mc":[{"id":"1.229554892","rc":[{"atb":[[40,0],[50,3.8]],"id":52385907},{"atb":[[8,4.32],[7.6,11.89]],"id":52385909},{"atb":[[70,3.2],[55,0]],"id":52385918},{"atb":[[100,3.06],[120,3.34]],"id":52385920},{"atb":[[36,6.49],[38,0]],"id":52385888},{"atb":[[11.5,0]],"id":52385889},{"atb":[[25,2.91],[26,3.14]],"id":52385882},{"atb":[[100,0],[110,3.01]],"id":52385923},{"atb":[[20,0],[21,8.31]],"id":52385893},{"atb":[[7.6,0],[7.8,4.59]],"id":52385934},{"atb":[[24,3.75],[25,3.27]],"id":52385903},{"atb":[[5.1,0],[5.3,3.94]],"id":52385904},{"atb":[[40,0],[46,2.9]],"id":52385936}],"con":true,"img":false}]}
{"op":"mcm","clk":"11449846516","pt":1717315247732,"mc":[{"id":"1.229554892","rc":[{"atb":[[18.5,0],[27,0]],"id":52385907},{"atb":[[3.95,0],[4.9,0]],"id":52385909},{"atb":[[16,0],[22,0]],"id":52385918},{"atb":[[550,0.05],[650,0]],"id":52385886},{"atb":[[17,0],[12,0]],"id":52385888},{"atb":[[38,0],[24,0]],"id":52385920},{"atb":[[7.2,0],[9.2,0]],"id":52385889},{"atb":[[9.2,0],[13,0]],"id":52385882},{"atb":[[17,0],[12,0]],"id":52385884},{"atb":[[550,0],[650,0]],"id":52385917},{"atb":[[2.92,0],[2.72,0]],"id":52385895},{"atb":[[38,0],[24,0]],"id":52385923},{"atb":[[2.92,54.5],[2.72,0]],"id":52385891},{"atb":[[17,0],[12,0]],"id":52385893},{"atb":[[3.95,0],[4.9,0]],"id":52385934},{"atb":[[10,0],[15,0]],"id":52385903},{"atb":[[18.5,0],[27,0]],"id":52385936},{"atb":[[3.45,0],[2.98,0]],"id":52385904},{"atb":[[10,0],[15,0]],"id":52385931},{"atb":[[3.45,0],[2.98,0]],"id":52385932}],"con":true,"img":false}]}
{"op":"mcm","clk":"11449846526","pt":1717315247837,"mc":[{"id":"1.229554892","rc":[{"atb":[[16.5,9.1],[17.5,0]],"id":52385884},{"atb":[[15,7.14]],"id":52385931}],"con":true,"img":false}]}
{"op":"mcm","clk":"11449846538","pt":1717315247942,"mc":[{"id":"1.229554892","rc":[{"atb":[[15.5,0]],"id":52385931}],"con":true,"img":false}]}
{"op":"mcm","clk":"11449846659","pt":1717315248621,"mc":[{"id":"1.229554892","rc":[{"atb":[[16.5,6.45]],"id":52385884},{"atb":[[200,0],[210,4.12]],"id":52385917},{"atb":[[14,4.52]],"id":52385931}],"con":true,"img":false}]}
{"op":"mcm","clk":"11449846670","pt":1717315248729,"mc":[{"id":"1.229554892","rc":[{"atb":[[16.5,0],[15.5,9.68]],"id":52385884},{"atb":[[14.5,0]],"id":52385931}],"con":true,"img":false}]}
{"op":"mcm","clk":"11449846682","pt":1717315248834,"mc":[{"id":"1.229554892","rc":[{"atb":[[14.5,7.41],[15,0]],"id":52385931}],"con":true,"img":false}]}
{"op":"mcm","clk":"11449846804","pt":1717315249917,"mc":[{"id":"1.229554892","rc":[{"atb":[[44,1.83]],"id":52385907},{"atb":[[60,0]],"id":52385918},{"atb":[[100,1.06]],"id":52385920}],"con":true,"img":false}]}
{"op":"mcm","clk":"11449846832","pt":1717315250235,"mc":[{"id":"1.229554892","rc":[{"atb":[[40,4.04],[50,0]],"id":52385907},{"atb":[[8,0],[7.6,15.37]],"id":52385909},{"atb":[[70,0],[55,2.62]],"id":52385918},{"atb":[[100,4.29],[120,0]],"id":52385920},{"atb":[[36,2.24],[38,2.92]],"id":52385888},{"atb":[[11.5,3.53]],"id":52385889},{"atb":[[25,0],[26,6.89]],"id":52385882},{"atb":[[14.5,4.48],[15.5,6.9]],"id":52385884},{"atb":[[210,0]],"id":52385917},{"atb":[[100,4.44],[110,0]],"id":52385923},{"atb":[[20,3.08],[21,3.92]],"id":52385893},{"atb":[[7.6,3.52],[7.8,0]],"id":52385934},{"atb":[[24,0],[25,7.07]],"id":52385903},{"atb":[[40,2.79],[46,0]],"id":52385936},{"atb":[[5.1,3.72],[5.3,0]],"id":52385904},{"atb":[[14,0]],"id":52385931}],"con":true,"img":false}]}
{"op":"mcm","clk":"11449846853","pt":1717315250440,"mc":[{"id":"1.229554892","rc":[{"atb":[[36,7.47]],"id":52385907},{"atb":[[48,2.13]],"id":52385918},{"atb":[[80,2]],"id":52385920},{"atb":[[15,7.14],[15.5,0]],"id":52385884},{"atb":[[14,7.69],[14.5,0]],"id":52385931}],"con":true,"img":false}]}
{"op":"mcm","clk":"11449846934","pt":1717315251344,"mc":[{"id":"1.229554892","rc":[{"atb":[[270,0],[320,2]],"id":52385886},{"atb":[[16,0],[18,12.03]],"id":52385893},{"atb":[[38,3.51],[42,4.36]],"id":52385936}],"con":true,"img":false}]}
{"op":"mcm","clk":"11449846952","pt":1717315251653,"mc":[{"id":"1.229554892","rc":[{"atb":[[40,0],[48,4.52]],"id":52385907},{"atb":[[190,0],[200,4.4]],"id":52385886},{"atb":[[70,3.29],[55,0]],"id":52385918},{"atl":[[480,0],[490,4.54]],"id":52385918},{"atb":[[100,1.06],[120,2.67]],"id":52385920},{"atl":[[820,0],[840,3.59]],"id":52385920},{"atb":[[14,4.5],[14.5,0]],"id":52385884},{"atb":[[210,4.63]],"id":52385917},{"atb":[[100,0],[110,3.66]],"id":52385923},{"atl":[[780,0],[800,4.29]],"id":52385923},{"atl":[[6.4,2.89],[6.2,0]],"id":52385891},{"atb":[[20,0],[21,7.31]],"id":52385893},{"atl":[[55,0],[60,4.67]],"id":52385893},{"atb":[[24,2.68],[25,3.27]],"id":52385903},{"atb":[[40,0],[48,3.92]],"id":52385936},{"atb":[[13,3.65],[13.5,0]],"id":52385931}],"con":true,"img":false}]}
{"op":"mcm","clk":"11449846961","pt":1717315251713,"mc":[{"id":"1.229554892","rc":[{"atb":[[50,4.21]],"id":52385907},{"atl":[[170,0],[180,3.18]],"id":52385907},{"atl":[[540,3.45]],"id":52385918},{"atb":[[36,6.22],[38,0]],"id":52385888},{"atb":[[11.5,0]],"id":52385889},{"atb":[[25,3.86],[26,3.14]],"id":52385882},{"atl":[[160,0],[170,3.8]],"id":52385936}],"con":true,"img":false}]}
{"op":"mcm","clk":"11449846970","pt":1717315251812,"mc":[{"id":"1.229554892","rc":[{"atb":[[14.5,7.41],[15,0]],"id":52385884},{"atb":[[13.5,8],[14,0]],"id":52385931}],"con":true,"img":false}]}
{"op":"mcm","clk":"11449847009","pt":1717315252336,"mc":[{"id":"1.229554892","rc":[{"atl":[[490,0]],"id":52385918},{"atb":[[13.5,3.06],[14,0]],"id":52385884},{"atl":[[800,0]],"id":52385923},{"atl":[[55,4.69],[60,0]],"id":52385893},{"atb":[[12.5,2.87]],"id":52385931}],"con":true,"img":false}]}
{"op":"mcm","clk":"11449847021","pt":1717315252429,"mc":[{"id":"1.229554892","rc":[{"atl":[[840,0]],"id":52385920},{"atb":[[14,7.69],[14.5,0]],"id":52385884},{"atb":[[13,0]],"id":52385931}],"con":true,"img":false}]}
{"op":"mcm","clk":"11449847030","pt":1717315252533,"mc":[{"id":"1.229554892","rc":[{"atb":[[12.5,11.57],[13.5,0]],"id":52385931}],"con":true,"img":false}]}
{"op":"mcm","clk":"11449847244","pt":1717315254504,"mc":[{"id":"1.229554892","rc":[{"atb":[[36,2.86]],"id":52385907},{"atb":[[13,3.84],[13.5,0]],"id":52385884},{"atb":[[12.5,8.7]],"id":52385931}],"con":true,"img":false}]}
{"op":"mcm","clk":"11449847253","pt":1717315254607,"mc":[{"id":"1.229554892","rc":[{"atb":[[13.5,8],[14,0]],"id":52385884},{"atb":[[11.5,3.97],[12.5,0],[5.7,21.28]],"id":52385931}],"con":true,"img":false}]}
{"op":"mcm","clk":"11449847260","pt":1717315254713,"mc":[{"id":"1.229554892","rc":[{"atb":[[12,9.09],[5.7,0]],"id":52385931}],"con":true,"img":false}]}
{"op":"mcm","clk":"11449847431","pt":1717315256732,"mc":[{"id":"1.229554892","rc":[{"atb":[[12.5,3.3]],"id":52385884},{"atb":[[11,4.07],[11.5,0]],"id":52385931}],"con":true,"img":false}]}
{"op":"mcm","clk":"11449847437","pt":1717315256824,"mc":[{"id":"1.229554892","rc":[{"atb":[[13,0]],"id":52385884},{"atb":[[11.5,9.52]],"id":52385931}],"con":true,"img":false}]}
{"op":"mcm","clk":"11449847444","pt":1717315256929,"mc":[{"id":"1.229554892","rc":[{"atb":[[13,8.33]],"id":52385884},{"atb":[[12,0]],"id":52385931}],"con":true,"img":false}]}
{"op":"mcm","clk":"11449847453","pt":1717315257034,"mc":[{"id":"1.229554892","rc":[{"atb":[[13.5,0]],"id":52385884}],"con":true,"img":false}]}
{"op":"mcm","clk":"11449847563","pt":1717315258253,"mc":[{"id":"1.229554892","rc":[{"atb":[[16.5,15.73],[23,4.75]],"id":52385907},{"atb":[[4,81.3],[5,26.13]],"id":52385909},{"atb":[[19.5,5.65],[14.5,18.06]],"id":52385918},{"atb":[[550,0.49],[650,0.16]],"id":52385886},{"atb":[[19.5,13.18],[29,3.73]],"id":52385920},{"atb":[[17,6.53],[12,22.17]],"id":52385888},{"atb":[[9,13.06],[7,40.65]],"id":52385889},{"atb":[[9.2,29.74],[13,8.71]],"id":52385882},{"atb":[[16.5,6.74],[11.5,23.22]],"id":52385884},{"atb":[[550,0.44],[650,0.16]],"id":52385917},{"atb":[[2.74,140.17],[2.94,94.33]],"id":52385895},{"atb":[[20,12.83],[30,3.6]],"id":52385923},{"atb":[[2.9,55.01],[2.7,143.47]],"id":52385891},{"atb":[[10.5,25.67],[15.5,7.2]],"id":52385893},{"atb":[[4,81.3],[5,26.13]],"id":52385934},{"atb":[[10,27.1],[15,7.46]],"id":52385903},{"atb":[[17,15.24],[24,4.54]],"id":52385936},{"atb":[[3.45,42.66],[2.98,123.18]],"id":52385904},{"atb":[[10,27.1],[15,7.46]],"id":52385931},{"atb":[[3,121.95],[3.5,41.81]],"id":52385932}],"con":true,"img":false}]}
{"op":"mcm","clk":"11449847572","pt":1717315258306,"mc":[{"id":"1.229554892","rc":[{"atb":[[17,6.25]],"id":52385884},{"atb":[[15.5,6.9]],"id":52385931}],"con":true,"img":false}]}
{"op":"mcm","clk":"11449847583","pt":1717315258409,"mc":[{"id":"1.229554892","rc":[{"atb":[[13,0]],"id":52385884},{"atb":[[11.5,0]],"id":52385931}],"con":true,"img":false}]}
{"op":"mcm","clk":"11449847601","pt":1717315258671,"mc":[{"id":"1.229554892","rc":[{"atb":[[12,4.35],[12.5,0]],"id":52385884},{"atb":[[10.5,3.23],[11,0]],"id":52385931}],"con":true,"img":false}]}
{"op":"mcm","clk":"11449847737","pt":1717315260117,"mc":[{"id":"1.229554892","rc":[{"atb":[[36,0],[44,4.16]],"id":52385907},{"atb":[[48,0],[60,2]],"id":52385918},{"atb":[[80,0],[100,3.06]],"id":52385920}],"con":true,"img":false}]}
{"op":"mcm","clk":"11449847745","pt":1717315260219,"mc":[{"id":"1.229554892","rc":[{"atb":[[10,4.59]],"id":52385889}],"con":true,"img":false}]}
{"op":"mcm","clk":"11449847859","pt":1717315261418,"mc":[{"id":"1.229554892","rc":[{"atb":[[16,3.79]],"id":52385884},{"atb":[[14.5,3.32]],"id":52385931}],"con":true,"img":false}]}
{"op":"mcm","clk":"11449847880","pt":1717315261674,"mc":[{"id":"1.229554892","rc":[{"atb":[[100,6.13]],"id":52385920},{"atl":[[940,2.79]],"id":52385920},{"atl":[[900,4.03]],"id":52385923}],"con":true,"img":false}]}
{"op":"mcm","clk":"11449847890","pt":1717315261736,"mc":[{"id":"1.229554892","rc":[{"atb":[[60,5.88]],"id":52385918},{"atb":[[44,3.55]],"id":52385936}],"con":true,"img":false}]}
{"op":"mcm","clk":"11449848023","pt":1717315262926,"mc":[{"id":"1.229554892","rc":[{"atb":[[90,0]],"id":52385920},{"atb":[[38,0]],"id":52385936}],"con":true,"img":false}]}
{"op":"mcm","clk":"11449848033","pt":1717315263030,"mc":[{"id":"1.229554892","rc":[{"atb":[[46,0]],"id":52385918}],"con":true,"img":false}]}
{"op":"mcm","clk":"11449848403","pt":1717315266759,"mc":[{"id":"1.229554892","rc":[{"atl":[[540,0],[550,3.66]],"id":52385918},{"atl":[[6,0],[5.9,4.13]],"id":52385895},{"atl":[[880,0]],"id":52385923},{"atl":[[6.4,0],[6.2,2.71]],"id":52385891},{"atl":[[55,0],[60,3.56]],"id":52385893}],"con":true,"img":false}]}
{"op":"mcm","clk":"11449848410","pt":1717315266864,"mc":[{"id":"1.229554892","rc":[{"atl":[[920,0]],"id":52385920}],"con":true,"img":false}]}
{"op":"mcm","clk":"11449848551","pt":1717315268272,"mc":[{"id":"1.229554892","rc":[{"atl":[[550,0]],"id":52385918},{"atl":[[6.4,3.67]],"id":52385891},{"atl":[[75,0],[80,4.68]],"id":52385903},{"atl":[[10,4.44]],"id":52385932}],"con":true,"img":false}]}
{"op":"mcm","clk":"11449848563","pt":1717315268367,"mc":[{"id":"1.229554892","rc":[{"atl":[[180,0]],"id":52385907},{"atl":[[940,0],[950,3.16]],"id":52385920},{"atl":[[6.2,0]],"id":52385891},{"atl":[[880,3.55]],"id":52385923},{"atl":[[60,0]],"id":52385893},{"atl":[[10.5,0]],"id":52385932}],"con":true,"img":false}]}
{"op":"mcm","clk":"11449848844","pt":1717315271483,"mc":[{"id":"1.229554892","rc":[{"atb":[[15,2.9]],"id":52385884},{"atb":[[13.5,2.94]],"id":52385931}],"con":true,"img":false}]}
{"op":"mcm","clk":"11449848996","pt":1717315273179,"mc":[{"id":"1.229554892","rc":[{"atl":[[210,2.65]],"id":52385907}],"con":true,"img":false}]}
{"op":"mcm","clk":"11449849339","pt":1717315276755,"mc":[{"id":"1.229554892","rc":[{"atl":[[580,2.99]],"id":52385918},{"atl":[[6.2,2.98]],"id":52385895},{"atl":[[75,2.89]],"id":52385893}],"con":true,"img":false}]}
{"op":"mcm","clk":"11449849488","pt":1717315278279,"mc":[{"id":"1.229554892","rc":[{"atl":[[970,4.35]],"id":52385920}],"con":true,"img":false}]}
{"op":"mcm","clk":"11449849661","pt":1717315279886,"mc":[{"id":"1.229554892","rc":[{"atl":[[18.5,0],[21,3.36]],"id":52385909},{"atl":[[18,0]],"id":52385934}],"con":true,"img":false}]}
{"op":"mcm","clk":"11449849674","pt":1717315279989,"mc":[{"id":"1.229554892","rc":[{"atb":[[12,0]],"id":52385884},{"atl":[[6.6,0]],"id":52385895},{"atb":[[10.5,0]],"id":52385931}],"con":true,"img":false}]}
{"op":"mcm","clk":"11449849784","pt":1717315280862,"mc":[{"id":"1.229554892","rc":[{"atl":[[19.5,0]],"id":52385909}],"con":true,"img":false}]}
{"op":"mcm","clk":"11449850243","pt":1717315285874,"mc":[{"id":"1.229554892","rc":[{"atb":[[4.9,0],[4.4,0]],"id":52385904}],"con":true,"img":false}]}
{"op":"mcm","clk":"11449850304","pt":1717315286596,"mc":[{"id":"1.229554892","rc":[{"atb":[[4.5,29.89],[5,19.62]],"id":52385904}],"con":true,"img":false}]}
{"op":"mcm","clk":"11449850640","pt":1717315289921,"mc":[{"id":"1.229554892","rc":[{"atl":[[23,4.05]],"id":52385909},{"atl":[[20,4.18]],"id":52385934}],"con":true,"img":false}]}
{"op":"mcm","clk":"11449851183","pt":1717315295523,"mc":[{"id":"1.229554892","rc":[{"atb":[[16.5,0],[23,0]],"id":52385907},{"atb":[[4,0],[5,0]],"id":52385909},{"atb":[[19.5,0],[14.5,0]],"id":52385918},{"atb":[[550,0.05],[650,0]],"id":52385886},{"atb":[[19.5,0],[29,0]],"id":52385920},{"atb":[[17,0],[12,0]],"id":52385888},{"atb":[[9,0],[7,0]],"id":52385889},{"atb":[[9.2,0],[13,0]],"id":52385882},{"atb":[[16.5,0],[11.5,0]],"id":52385884},{"atb":[[550,0],[650,0]],"id":52385917},{"atb":[[2.74,0],[2.94,40.45]],"id":52385895},{"atb":[[2.9,0],[2.7,0]],"id":52385891},{"atb":[[20,0],[30,0]],"id":52385923},{"atb":[[10.5,0],[15.5,0]],"id":52385893},{"atb":[[4,0],[5,0]],"id":52385934},{"atb":[[10,0],[15,0]],"id":52385903},{"atb":[[3.45,0],[2.98,0]],"id":52385904},{"atb":[[17,0],[24,0]],"id":52385936},{"atb":[[10,0],[15,0]],"id":52385931},{"atb":[[3,0],[3.5,0]],"id":52385932}],"con":true,"img":false}]}
{"op":"mcm","clk":"11449851196","pt":1717315295583,"mc":[{"id":"1.229554892","rc":[{"atb":[[16.5,6.45],[17,0]],"id":52385884},{"atb":[[15.5,0]],"id":52385931}],"con":true,"img":false}]}
{"op":"mcm","clk":"11449851204","pt":1717315295685,"mc":[{"id":"1.229554892","rc":[{"atb":[[15,7.14]],"id":52385931}],"con":true,"img":false}]}
{"op":"mcm","clk":"11449851287","pt":1717315296619,"mc":[{"id":"1.229554892","rc":[{"atb":[[15.5,2.81]],"id":52385884},{"atb":[[14,3.89]],"id":52385931}],"con":true,"img":false}]}
{"op":"mcm","clk":"11449851295","pt":1717315296672,"mc":[{"id":"1.229554892","rc":[{"atb":[[16,0]],"id":52385884},{"atb":[[14.5,0]],"id":52385931}],"con":true,"img":false}]}
{"op":"mcm","clk":"11449851690","pt":1717315300715,"mc":[{"id":"1.229554892","rc":[{"atb":[[16.5,0],[15.5,9.71]],"id":52385884}],"con":true,"img":false}]}
{"op":"mcm","clk":"11449851703","pt":1717315300823,"mc":[{"id":"1.229554892","rc":[{"atb":[[14.5,7.41],[15,0]],"id":52385931}],"con":true,"img":false}]}
{"op":"mcm","clk":"11449852262","pt":1717315306602,"mc":[{"id":"1.229554892","rc":[{"atb":[[14.5,4.26],[15.5,6.9]],"id":52385884},{"atb":[[12.5,3.24],[14,0]],"id":52385931}],"con":true,"img":false}]}
{"op":"mcm","clk":"11449852280","pt":1717315306805,"mc":[{"id":"1.229554892","rc":[{"atb":[[15,10.04],[15.5,0]],"id":52385884},{"atb":[[13.5,10.94]],"id":52385931}],"con":true,"img":false}]}
{"op":"mcm","clk":"11449852291","pt":1717315306901,"mc":[{"id":"1.229554892","rc":[{"atb":[[13,8.33],[14.5,0]],"id":52385931}],"con":true,"img":false}]}
{"op":"mcm","clk":"11449852297","pt":1717315307004,"mc":[{"id":"1.229554892","rc":[{"atb":[[13.5,2.94]],"id":52385931}],"con":true,"img":false}]}
{"op":"mcm","clk":"11449853195","pt":1717315316618,"mc":[{"id":"1.229554892","rc":[{"atb":[[14,4.03],[15,7.14]],"id":52385884},{"atb":[[11.5,3.28],[13.5,0]],"id":52385931}],"con":true,"img":false}]}
{"op":"mcm","clk":"11449853673","pt":1717315321133,"mc":[{"id":"1.229554892","rc":[{"atb":[[14.5,0]],"id":52385884},{"atb":[[12,2.98],[12.5,0]],"id":52385931}],"con":true,"img":false}]}
{"op":"mcm","clk":"11449853691","pt":1717315321334,"mc":[{"id":"1.229554892","rc":[{"atb":[[14.5,7.41],[15,0]],"id":52385884},{"atb":[[12,12.07],[13,0]],"id":52385931}],"con":true,"img":false}]}
{"op":"mcm","clk":"11449853741","pt":1717315321810,"mc":[{"id":"1.229554892","rc":[{"atb":[[13.5,2.64]],"id":52385884},{"atb":[[11,4.49]],"id":52385931}],"con":true,"img":false}]}
{"op":"mcm","clk":"11449854188","pt":1717315326144,"mc":[{"id":"1.229554892","rc":[{"atb":[[34,0],[85,0],[44,2.33],[60,0]],"id":52385907},{"atb":[[32,0],[80,0],[42,2.44],[55,0]],"id":52385936}],"con":true,"img":false}]}
{"op":"mcm","clk":"11449854260","pt":1717315326814,"mc":[{"id":"1.229554892","rc":[{"atb":[[65,0.82],[36,2.99],[90,0.29],[46,1.74]],"id":52385936}],"con":true,"img":false}]}
