{"op":"mcm","clk":"11448127654","pt":1717286034989,"mc":[{"id":"1.229554891","marketDefinition":{"bspMarket":true,"turnInPlayEnabled":false,"persistenceEnabled":false,"marketBaseRate":7.0,"eventId":"33318908","eventTypeId":"4339","numberOfWinners":2,"bettingType":"ODDS","marketType":"PLACE","marketTime":"2024-06-02T08:21:00.000Z","suspendTime":"2024-06-02T08:21:00.000Z","bspReconciled":false,"complete":true,"inPlay":false,"crossMatching":true,"runnersVoidable":false,"numberOfActiveRunners":5,"betDelay":0,"status":"OPEN","runners":[{"status":"ACTIVE","sortPriority":1,"id":70003363,"name":"1. Plodding Along"},{"status":"ACTIVE","sortPriority":2,"id":70003364,"name":"2. Parrakie"},{"status":"ACTIVE","sortPriority":3,"id":70003365,"name":"4. Bookaloo"},{"status":"ACTIVE","sortPriority":4,"id":70003366,"name":"6. Manner Of Strife"},{"status":"ACTIVE","sortPriority":5,"id":70003367,"name":"8. Apilla"}],"regulators":["MR_INT"],"venue":"Murray Bridge","countryCode":"AU","discountAllowed":true,"timezone":"Australia/Adelaide","openDate":"2024-06-02T08:21:00.000Z","version":5962317650,"name":"To Be Placed","eventName":"Murray Bridge (AUS) 2nd Jun"},"rc":[],"con":true,"img":false}]}
{"op":"mcm","clk":"11448260594","pt":1717287908430,"mc":[{"id":"1.229554891","rc":[{"atb":[[3.6,13.4],[4.2,7.26]],"id":70003366},{"spn":"Infinity","spf":"NaN","id":70003366},{"atb":[[1.45,51.62],[1.35,99.55]],"id":70003367},{"atl":[[4.2,0.16]],"id":70003367},{"spn":2.82,"spf":"NaN","id":70003367},{"atb":[[1.01,5807.26]],"id":70003364},{"atl":[[2.78,0.29]],"id":70003364},{"spn":1.89,"spf":"NaN","id":70003364},{"atb":[[1.45,51.62],[1.35,99.55]],"id":70003365},{"atl":[[4.2,0.16]],"id":70003365},{"spn":2.82,"spf":"NaN","id":70003365},{"atb":[[4.3,7.03],[3.65,13.14]],"id":70003363},{"spn":"Infinity","spf":"NaN","id":70003363}],"con":true,"img":false}]}
{"op":"mcm","clk":"11448264294","pt":1717287962153,"mc":[{"id":"1.229554891","rc":[{"atb":[[3.6,0],[4.2,0]],"id":70003366},{"atb":[[1.45,0],[1.35,0]],"id":70003367},{"atl":[[4.2,0]],"id":70003367},{"atb":[[1.01,0]],"id":70003364},{"atl":[[2.78,0]],"id":70003364},{"atb":[[1.45,0],[1.35,0]],"id":70003365},{"atl":[[4.2,0]],"id":70003365},{"atb":[[4.3,0],[3.65,0]],"id":70003363}],"con":true,"img":false}]}
{"op":"mcm","clk":"11448265018","pt":1717287972318,"mc":[{"id":"1.229554891","rc":[{"atb":[[4.5,6.63],[3.75,12.67]],"id":70003366},{"atb":[[1.27,86.03],[1.17,204.95]],"id":70003367},{"atl":[[3.3,0.22]],"id":70003367},{"spn":2.28,"spf":"NaN","id":70003367},{"atb":[[1.01,5807.26]],"id":70003364},{"atl":[[2.8,0.29]],"id":70003364},{"spn":1.9,"spf":"NaN","id":70003364},{"atb":[[1.57,40.75],[1.47,74.13]],"id":70003365},{"atl":[[5.2,0.12]],"id":70003365},{"spn":3.38,"spf":"NaN","id":70003365},{"atb":[[3.6,13.4],[4.2,7.26]],"id":70003363}],"con":true,"img":false}]}
{"op":"mcm","clk":"11448270133","pt":1717288057118,"mc":[{"id":"1.229554891","rc":[{"atb":[[4.5,0],[3.75,0]],"id":70003366},{"spn":"NaN","spf":"NaN","id":70003366},{"atb":[[1.27,0],[1.17,0]],"id":70003367},{"atl":[[3.3,0]],"id":70003367},{"spn":"NaN","spf":"NaN","id":70003367},{"atb":[[1.01,0]],"id":70003364},{"atl":[[2.8,0]],"id":70003364},{"spn":"NaN","spf":"NaN","id":70003364},{"atb":[[1.57,0],[1.47,0]],"id":70003365},{"atl":[[5.2,0]],"id":70003365},{"spn":"NaN","spf":"NaN","id":70003365},{"atb":[[3.6,0],[4.2,0]],"id":70003363},{"spn":"NaN","spf":"NaN","id":70003363}],"con":true,"img":false}]}
{"op":"mcm","clk":"11448270978","pt":1717288067734,"mc":[{"id":"1.229554891","rc":[{"atb":[[4.5,6.63],[3.75,12.67]],"id":70003366},{"atb":[[1.14,248.88],[1.24,96.78]],"id":70003367},{"atl":[[3.15,0.24]],"id":70003367},{"atb":[[1.01,5807.26]],"id":70003364},{"atl":[[2.82,0.28]],"id":70003364},{"atb":[[1.57,40.75],[1.47,74.13]],"id":70003365},{"atl":[[5.2,0.12]],"id":70003365},{"atb":[[3.7,12.9],[4.4,6.83]],"id":70003363}],"con":true,"img":false}]}
{"op":"mcm","clk":"11448272355","pt":1717288089584,"mc":[{"id":"1.229554891","rc":[{"atb":[[4.5,0],[3.75,0]],"id":70003366},{"atb":[[1.14,0],[1.24,0]],"id":70003367},{"atl":[[3.15,0]],"id":70003367},{"atb":[[1.01,0]],"id":70003364},{"atl":[[2.82,0]],"id":70003364},{"atb":[[1.57,0],[1.47,0]],"id":70003365},{"atl":[[5.2,0]],"id":70003365},{"atb":[[3.7,0],[4.4,0]],"id":70003363}],"con":true,"img":false}]}
{"op":"mcm","clk":"11448273012","pt":1717288099886,"mc":[{"id":"1.229554891","rc":[{"atb":[[3.95,11.81],[4.9,5.95]],"id":70003366},{"atb":[[1.21,110.61],[1.11,316.75]],"id":70003367},{"atl":[[3.1,0.25]],"id":70003367},{"atb":[[1.01,5807.26]],"id":70003364},{"atl":[[2.78,0.29]],"id":70003364},{"atb":[[1.58,40.04],[1.48,72.59]],"id":70003365},{"atl":[[5.4,0.12]],"id":70003365},{"atb":[[3.85,12.22],[4.7,6.27]],"id":70003363}],"con":true,"img":false}]}
{"op":"mcm","clk":"11448277213","pt":1717288128427,"mc":[{"id":"1.229554891","marketDefinition":{"bspMarket":true,"turnInPlayEnabled":false,"persistenceEnabled":false,"marketBaseRate":7.0,"eventId":"33318908","eventTypeId":"4339","numberOfWinners":2,"bettingType":"ODDS","marketType":"PLACE","marketTime":"2024-06-02T08:21:00.000Z","suspendTime":"2024-06-02T08:21:00.000Z","bspReconciled":false,"complete":true,"inPlay":false,"crossMatching":true,"runnersVoidable":false,"numberOfActiveRunners":5,"betDelay":0,"status":"OPEN","runners":[{"status":"ACTIVE","sortPriority":1,"id":70003363,"name":"1. Plodding Along"},{"status":"ACTIVE","sortPriority":2,"id":70003364,"name":"2. Parrakie"},{"status":"ACTIVE","sortPriority":3,"id":70003365,"name":"4. Bookaloo"},{"status":"ACTIVE","sortPriority":4,"id":70003366,"name":"6. Manner Of Strife"},{"status":"ACTIVE","sortPriority":5,"id":70003367,"name":"8. Apilla"}],"regulators":["MR_INT"],"venue":"Murray Bridge","countryCode":"AU","discountAllowed":true,"timezone":"Australia/Adelaide","openDate":"2024-06-02T08:21:00.000Z","version":5962317650,"name":"To Be Placed","eventName":"Murray Bridge (AUS) 2nd Jun"},"rc":[{"atb":[[3.95,11.81],[4.9,5.95]],"id":70003366},{"spn":"Infinity","spf":"NaN","id":70003366},{"atb":[[1.21,110.61],[1.11,316.75]],"id":70003367},{"atl":[[3.1,0.25]],"id":70003367},{"spn":2.15,"spf":"NaN","id":70003367},{"atb":[[1.01,5807.26]],"id":70003364},{"atl":[[2.78,0.29]],"id":70003364},{"spn":1.89,"spf":"NaN","id":70003364},{"atb":[[1.58,40.04],[1.48,72.59]],"id":70003365},{"atl":[[5.4,0.12]],"id":70003365},{"spn":3.49,"spf":"NaN","id":70003365},{"atb":[[3.85,12.22],[4.7,6.27]],"id":70003363},{"spn":"Infinity","spf":"NaN","id":70003363}],"con":true,"img":true}]}
{"op":"mcm","clk":"11448284287","pt":1717288159833,"mc":[{"id":"1.229554891","rc":[{"spn":"Infinity","spf":"NaN","id":70003366},{"spn":2.15,"spf":"NaN","id":70003367},{"spn":1.89,"spf":"NaN","id":70003364},{"atb":[[1.58,0],[1.48,0]],"id":70003365},{"atl":[[5.4,0]],"id":70003365},{"spn":3.49,"spf":"NaN","id":70003365},{"atb":[[3.85,0],[4.7,0]],"id":70003363},{"spn":"Infinity","spf":"NaN","id":70003363}],"con":true,"img":false}]}
{"op":"mcm","clk":"11448285284","pt":1717288174030,"mc":[{"id":"1.229554891","rc":[{"atb":[[1.58,40.04],[1.48,72.59]],"id":70003365},{"atl":[[5.4,0.12]],"id":70003365},{"atb":[[4.6,6.45],[3.8,12.44]],"id":70003363}],"con":true,"img":false}]}
{"op":"mcm","clk":"11448289491","pt":1717288232485,"mc":[{"id":"1.229554891","rc":[{"atb":[[1.21,0],[1.11,0]],"id":70003367},{"atl":[[3.1,0]],"id":70003367},{"spn":"NaN","spf":"NaN","id":70003367},{"atb":[[4.6,0],[3.8,0]],"id":70003363},{"spn":"NaN","spf":"NaN","id":70003363}],"con":true,"img":false}]}
{"op":"mcm","clk":"11448290414","pt":1717288245743,"mc":[{"id":"1.229554891","rc":[{"atb":[[1.23,100.99],[1.13,268.02]],"id":70003367},{"atl":[[3.15,0.24]],"id":70003367},{"atb":[[4.5,6.63],[3.75,12.67]],"id":70003363}],"con":true,"img":false}]}
{"op":"mcm","clk":"11448292443","pt":1717288273689,"mc":[{"id":"1.229554891","rc":[{"atb":[[3.95,0],[4.9,0]],"id":70003366},{"atb":[[1.23,0],[1.13,0]],"id":70003367},{"atl":[[3.15,0]],"id":70003367},{"atb":[[1.58,0],[1.48,0]],"id":70003365},{"atl":[[5.4,0]],"id":70003365},{"atb":[[4.5,0],[3.75,0]],"id":70003363}],"con":true,"img":false}]}
{"op":"mcm","clk":"11448293804","pt":1717288291623,"mc":[{"id":"1.229554891","rc":[{"atb":[[4,11.61],[5,5.8]],"id":70003366},{"atb":[[1.07,497.76],[1.17,136.64]],"id":70003367},{"atl":[[3,0.26]],"id":70003367},{"atb":[[1.64,36.29],[1.54,64.52]],"id":70003365},{"atl":[[6,0.1]],"id":70003365},{"atb":[[3.85,12.22],[4.7,6.27]],"id":70003363}],"con":true,"img":false}]}
{"op":"mcm","clk":"11448298252","pt":1717288351176,"mc":[{"id":"1.229554891","rc":[{"atb":[[1.07,0],[1.17,0]],"id":70003367},{"atl":[[3,0]],"id":70003367},{"atb":[[1.64,0],[1.54,0]],"id":70003365},{"atl":[[6,0]],"id":70003365},{"spn":"NaN","spf":"NaN","id":70003365},{"atb":[[3.85,0],[4.7,0]],"id":70003363}],"con":true,"img":false}]}
{"op":"mcm","clk":"11448300795","pt":1717288383947,"mc":[{"id":"1.229554891","rc":[{"atb":[[1.07,497.76],[1.17,136.64]],"id":70003367},{"atl":[[3,0.26]],"id":70003367},{"atb":[[1.62,37.46],[1.52,67]],"id":70003365},{"atl":[[5.8,0.1]],"id":70003365},{"atb":[[4,11.61],[5,5.8]],"id":70003363}],"con":true,"img":false}]}
{"op":"mcm","clk":"11448449904","pt":1717290485765,"mc":[{"id":"1.229554891","rc":[{"atb":[[4,0],[5,0]],"id":70003366},{"spn":"NaN","spf":"NaN","id":70003366},{"atb":[[1.07,0],[1.17,0]],"id":70003367},{"atl":[[3,0]],"id":70003367},{"atb":[[1.01,0]],"id":70003364},{"atl":[[2.78,0]],"id":70003364},{"spn":"NaN","spf":"NaN","id":70003364},{"atb":[[1.62,0],[1.52,0]],"id":70003365},{"atl":[[5.8,0]],"id":70003365},{"atb":[[4,0],[5,0]],"id":70003363}],"con":true,"img":false}]}
{"op":"mcm","clk":"11448450355","pt":1717290493608,"mc":[{"id":"1.229554891","rc":[{"atb":[[3.95,11.81],[4.9,5.95]],"id":70003366},{"atb":[[1.01,3484.35],[1.1,232.29]],"id":70003367},{"atl":[[2.9,0.27]],"id":70003367},{"atb":[[1.01,5807.26]],"id":70003364},{"atl":[[2.78,0.29]],"id":70003364},{"atb":[[1.57,61.12],[1.67,34.67]],"id":70003365},{"atl":[[6.4,0.09]],"id":70003365},{"atb":[[3.95,11.81],[4.9,5.95]],"id":70003363}],"con":true,"img":false}]}
{"op":"mcm","clk":"11448451088","pt":1717290505987,"mc":[{"id":"1.229554891","rc":[{"atb":[[1.01,0],[1.1,0]],"id":70003367},{"atl":[[2.9,0]],"id":70003367},{"atb":[[1.01,0]],"id":70003364},{"atl":[[2.78,0]],"id":70003364},{"atb":[[1.57,0],[1.67,0]],"id":70003365},{"atl":[[6.4,0]],"id":70003365}],"con":true,"img":false}]}
{"op":"mcm","clk":"11448451644","pt":1717290515494,"mc":[{"id":"1.229554891","rc":[{"atb":[[1.01,3484.35],[1.11,211.17]],"id":70003367},{"atl":[[2.92,0.27]],"id":70003367},{"atb":[[1.01,5807.26]],"id":70003364},{"atl":[[2.78,0.29]],"id":70003364},{"atb":[[1.59,59.05],[1.69,33.66]],"id":70003365},{"atl":[[6.6,0.09]],"id":70003365}],"con":true,"img":false}]}
{"op":"mcm","clk":"11448452959","pt":1717290537143,"mc":[{"id":"1.229554891","rc":[{"atb":[[1.01,0],[1.11,0]],"id":70003367},{"atl":[[2.92,0]],"id":70003367},{"atb":[[1.01,0]],"id":70003364},{"atl":[[2.78,0]],"id":70003364},{"atb":[[1.59,0],[1.69,0]],"id":70003365},{"atl":[[6.6,0]],"id":70003365}],"con":true,"img":false}]}
{"op":"mcm","clk":"11448453477","pt":1717290545756,"mc":[{"id":"1.229554891","rc":[{"atb":[[1.01,3484.35],[1.09,258.09]],"id":70003367},{"atl":[[2.9,0.27]],"id":70003367},{"atb":[[1.01,5807.26]],"id":70003364},{"atl":[[2.78,0.29]],"id":70003364},{"atb":[[1.59,59.05],[1.69,33.66]],"id":70003365},{"atl":[[6.6,0.09]],"id":70003365}],"con":true,"img":false}]}
{"op":"mcm","clk":"11448455672","pt":1717290576906,"mc":[{"id":"1.229554891","rc":[{"spn":"Infinity","spf":"NaN","id":70003366},{"atb":[[1.01,0],[1.09,0]],"id":70003367},{"atl":[[2.9,0]],"id":70003367},{"atb":[[1.01,0]],"id":70003364},{"atl":[[2.78,0]],"id":70003364},{"atb":[[1.59,0],[1.69,0]],"id":70003365},{"atl":[[6.6,0]],"id":70003365},{"spn":"Infinity","spf":"NaN","id":70003363}],"con":true,"img":false}]}
{"op":"mcm","clk":"11448456054","pt":1717290583503,"mc":[{"id":"1.229554891","rc":[{"atb":[[1.01,3484.35],[1.1,232.29]],"id":70003367},{"atl":[[2.9,0.27]],"id":70003367},{"atb":[[1.01,5807.26]],"id":70003364},{"atl":[[2.82,0.28]],"id":70003364},{"atb":[[1.57,61.12],[1.67,34.67]],"id":70003365},{"atl":[[6.4,0.09]],"id":70003365}],"con":true,"img":false}]}
{"op":"mcm","clk":"11448459584","pt":1717290647283,"mc":[{"id":"1.229554891","rc":[{"atb":[[1.01,0],[1.1,0]],"id":70003367},{"atl":[[2.9,0]],"id":70003367},{"atb":[[1.01,0]],"id":70003364},{"atl":[[2.82,0]],"id":70003364},{"atb":[[1.57,0],[1.67,0]],"id":70003365},{"atl":[[6.4,0]],"id":70003365}],"con":true,"img":false}]}
{"op":"mcm","clk":"11448459972","pt":1717290655707,"mc":[{"id":"1.229554891","rc":[{"atb":[[1.01,3484.35],[1.11,211.17]],"id":70003367},{"atl":[[2.92,0.27]],"id":70003367},{"atb":[[1.01,5807.26]],"id":70003364},{"atl":[[2.8,0.29]],"id":70003364},{"atb":[[1.57,61.12],[1.67,34.67]],"id":70003365},{"atl":[[6.4,0.09]],"id":70003365}],"con":true,"img":false}]}
{"op":"mcm","clk":"11448461417","pt":1717290680524,"mc":[{"id":"1.229554891","rc":[{"atb":[[1.01,0],[1.11,0]],"id":70003367},{"atl":[[2.92,0]],"id":70003367},{"atb":[[1.57,0],[1.67,0]],"id":70003365},{"atl":[[6.4,0]],"id":70003365}],"con":true,"img":false}]}
{"op":"mcm","clk":"11448462200","pt":1717290691801,"mc":[{"id":"1.229554891","rc":[{"atb":[[1.01,3484.35],[1.08,290.36]],"id":70003367},{"atl":[[2.88,0.27]],"id":70003367},{"atb":[[1.6,58.07],[1.7,33.18]],"id":70003365},{"atl":[[6.6,0.09]],"id":70003365}],"con":true,"img":false}]}
{"op":"mcm","clk":"11448463733","pt":1717290717628,"mc":[{"id":"1.229554891","rc":[{"atb":[[1.01,0],[1.08,0]],"id":70003367},{"atl":[[2.88,0]],"id":70003367},{"atb":[[1.01,0]],"id":70003364},{"atl":[[2.8,0]],"id":70003364},{"atb":[[1.6,0],[1.7,0]],"id":70003365},{"atl":[[6.6,0]],"id":70003365},{"atb":[[3.95,0],[4.9,0]],"id":70003363},{"spn":"NaN","spf":"NaN","id":70003363}],"con":true,"img":false}]}
{"op":"mcm","clk":"11448464647","pt":1717290732552,"mc":[{"id":"1.229554891","rc":[{"atb":[[1.01,3484.35],[1.06,387.15]],"id":70003367},{"atl":[[2.86,0.28]],"id":70003367},{"atb":[[1.01,5807.26]],"id":70003364},{"atl":[[2.82,0.28]],"id":70003364},{"atb":[[1.6,58.07],[1.7,33.18]],"id":70003365},{"atl":[[6.6,0.09]],"id":70003365},{"atb":[[4.8,6.11],[3.9,12.01]],"id":70003363}],"con":true,"img":false}]}
{"op":"mcm","clk":"11448474826","pt":1717290912477,"mc":[{"id":"1.229554891","rc":[{"atb":[[1.01,0],[1.06,0]],"id":70003367},{"atl":[[2.86,0]],"id":70003367},{"atb":[[1.01,0]],"id":70003364},{"atl":[[2.82,0]],"id":70003364},{"atb":[[1.6,0],[1.7,0]],"id":70003365},{"atl":[[6.6,0]],"id":70003365},{"spn":"Infinity","spf":"NaN","id":70003363}],"con":true,"img":false}]}
{"op":"mcm","clk":"11448475142","pt":1717290917393,"mc":[{"id":"1.229554891","rc":[{"atb":[[1.01,3484.35],[1.05,464.58]],"id":70003367},{"atl":[[2.86,0.28]],"id":70003367},{"atb":[[1.01,5807.26]],"id":70003364},{"atl":[[2.8,0.29]],"id":70003364},{"atb":[[1.75,30.97],[1.65,53.6]],"id":70003365},{"atl":[[7,0.08]],"id":70003365}],"con":true,"img":false}]}
{"op":"mcm","clk":"11448476910","pt":1717290945522,"mc":[{"id":"1.229554891","rc":[{"atb":[[1.01,0],[1.05,0]],"id":70003367},{"atl":[[2.86,0]],"id":70003367},{"atb":[[1.01,0]],"id":70003364},{"atl":[[2.8,0]],"id":70003364},{"atb":[[1.75,0],[1.65,0]],"id":70003365},{"atl":[[7,0]],"id":70003365}],"con":true,"img":false}]}
{"op":"mcm","clk":"11448477472","pt":1717290954640,"mc":[{"id":"1.229554891","rc":[{"atb":[[1.01,3484.35],[1.04,580.72]],"id":70003367},{"atl":[[2.84,0.28]],"id":70003367},{"atb":[[1.01,5807.26]],"id":70003364},{"atl":[[2.8,0.29]],"id":70003364},{"atb":[[1.64,54.44],[1.74,31.39]],"id":70003365},{"atl":[[6.8,0.08]],"id":70003365}],"con":true,"img":false}]}
{"op":"mcm","clk":"11448482360","pt":1717291031786,"mc":[{"id":"1.229554891","rc":[{"atb":[[1.01,0],[1.04,0]],"id":70003367},{"atl":[[2.84,0]],"id":70003367},{"atb":[[1.01,0]],"id":70003364},{"atl":[[2.8,0]],"id":70003364},{"atb":[[1.64,0],[1.74,0]],"id":70003365},{"atl":[[6.8,0]],"id":70003365}],"con":true,"img":false}]}
{"op":"mcm","clk":"11448483015","pt":1717291041104,"mc":[{"id":"1.229554891","rc":[{"atb":[[1.01,3484.35],[1.04,580.72]],"id":70003367},{"atl":[[2.84,0.28]],"id":70003367},{"atb":[[1.01,3484.35],[1.03,774.3]],"id":70003364},{"atl":[[2.84,0.28]],"id":70003364},{"atb":[[1.72,32.26],[1.62,56.19]],"id":70003365},{"atl":[[6.8,0.08]],"id":70003365}],"con":true,"img":false}]}
{"op":"mcm","clk":"11448487738","pt":1717291112533,"mc":[{"id":"1.229554891","rc":[{"atb":[[3.95,0],[4.9,0]],"id":70003366},{"spn":"NaN","spf":"NaN","id":70003366},{"spn":1.94,"spf":"NaN","id":70003367},{"spn":1.93,"spf":"NaN","id":70003364},{"spn":4.26,"spf":"NaN","id":70003365},{"atb":[[4.8,0],[3.9,0]],"id":70003363},{"spn":"NaN","spf":"NaN","id":70003363}],"con":true,"img":false}]}
{"op":"mcm","clk":"11448487972","pt":1717291116013,"mc":[{"id":"1.229554891","rc":[{"atb":[[3.95,11.81],[4.9,5.95]],"id":70003366},{"atb":[[4,11.61],[5,5.8]],"id":70003363}],"con":true,"img":false}]}
{"op":"mcm","clk":"11448491817","pt":1717291173850,"mc":[{"id":"1.229554891","rc":[{"atb":[[3.95,0],[4.9,0]],"id":70003366},{"atb":[[1.01,0],[1.04,0]],"id":70003367},{"atl":[[2.84,0]],"id":70003367},{"spn":"NaN","spf":"NaN","id":70003367},{"atb":[[1.01,0],[1.03,0]],"id":70003364},{"atl":[[2.84,0]],"id":70003364},{"spn":"NaN","spf":"NaN","id":70003364},{"atb":[[1.72,0],[1.62,0]],"id":70003365},{"atl":[[6.8,0]],"id":70003365},{"spn":"NaN","spf":"NaN","id":70003365},{"atb":[[4,0],[5,0]],"id":70003363}],"con":true,"img":false}]}
{"op":"mcm","clk":"11448492653","pt":1717291186676,"mc":[{"id":"1.229554891","rc":[{"atb":[[4.8,6.11],[3.9,12.01]],"id":70003366},{"atb":[[1.01,3484.35],[1.08,290.36]],"id":70003367},{"atl":[[2.88,0.27]],"id":70003367},{"atb":[[1.01,3484.35],[1.06,387.15]],"id":70003364},{"atl":[[2.86,0.28]],"id":70003364},{"atb":[[1.59,39.36],[1.49,71.11]],"id":70003365},{"atl":[[5.5,0.11]],"id":70003365},{"atb":[[4.4,10.24],[5.4,5.27]],"id":70003363}],"con":true,"img":false}]}
{"op":"mcm","clk":"11448494247","pt":1717291211930,"mc":[{"id":"1.229554891","rc":[{"atb":[[4.8,0],[3.9,0]],"id":70003366},{"atb":[[1.01,0],[1.08,0]],"id":70003367},{"atl":[[2.88,0]],"id":70003367},{"atb":[[1.01,0],[1.06,0]],"id":70003364},{"atl":[[2.86,0]],"id":70003364},{"atb":[[1.59,0],[1.49,0]],"id":70003365},{"atl":[[5.5,0]],"id":70003365},{"atb":[[4.4,0],[5.4,0]],"id":70003363}],"con":true,"img":false}]}
{"op":"mcm","clk":"11448494993","pt":1717291222496,"mc":[{"id":"1.229554891","rc":[{"atb":[[4.9,8.93],[5.9,4.73]],"id":70003366},{"atb":[[1.01,3484.35],[1.05,464.58]],"id":70003367},{"atl":[[2.86,0.28]],"id":70003367},{"atb":[[1.01,3484.35],[1.07,331.84]],"id":70003364},{"atl":[[2.88,0.27]],"id":70003364},{"atb":[[1.44,79.18],[1.54,43.01]],"id":70003365},{"atl":[[4.9,0.13]],"id":70003365},{"atb":[[4.4,10.24],[5.4,5.27]],"id":70003363}],"con":true,"img":false}]}
{"op":"mcm","clk":"11448496468","pt":1717291244133,"mc":[{"id":"1.229554891","rc":[{"spn":"Infinity","spf":"NaN","id":70003366},{"atb":[[1.01,0],[1.05,0]],"id":70003367},{"atl":[[2.86,0]],"id":70003367},{"atb":[[1.01,0],[1.07,0]],"id":70003364},{"atl":[[2.88,0]],"id":70003364},{"atb":[[1.44,0],[1.54,0]],"id":70003365},{"atl":[[4.9,0]],"id":70003365},{"spn":"Infinity","spf":"NaN","id":70003363}],"con":true,"img":false}]}
{"op":"mcm","clk":"11448497015","pt":1717291252057,"mc":[{"id":"1.229554891","rc":[{"atb":[[1.01,3484.35],[1.08,290.36]],"id":70003367},{"atl":[[2.88,0.27]],"id":70003367},{"atb":[[1.01,3484.35],[1.1,232.29]],"id":70003364},{"atl":[[2.9,0.27]],"id":70003364},{"atb":[[1.44,52.79],[1.34,102.47]],"id":70003365},{"atl":[[4.2,0.16]],"id":70003365}],"con":true,"img":false}]}
{"op":"mcm","clk":"11448497991","pt":1717291267478,"mc":[{"id":"1.229554891","rc":[{"atb":[[4.9,0],[5.9,0]],"id":70003366},{"atb":[[1.01,0],[1.08,0]],"id":70003367},{"atl":[[2.88,0]],"id":70003367},{"atb":[[1.01,0],[1.1,0]],"id":70003364},{"atl":[[2.9,0]],"id":70003364},{"atb":[[1.44,0],[1.34,0]],"id":70003365},{"atl":[[4.2,0]],"id":70003365},{"atb":[[4.4,0],[5.4,0]],"id":70003363}],"con":true,"img":false}]}
{"op":"mcm","clk":"11448498617","pt":1717291276972,"mc":[{"id":"1.229554891","rc":[{"atb":[[5.6,5.04],[4.6,9.67]],"id":70003366},{"atb":[[1.01,3484.35],[1.1,232.29]],"id":70003367},{"atl":[[2.9,0.27]],"id":70003367},{"atb":[[1.01,3484.35],[1.11,211.17]],"id":70003364},{"atl":[[2.92,0.27]],"id":70003364},{"atb":[[1.41,56.65],[1.31,112.39]],"id":70003365},{"atl":[[4.1,0.16]],"id":70003365},{"atb":[[4.5,9.95],[5.5,5.16]],"id":70003363}],"con":true,"img":false}]}
{"op":"mcm","clk":"11448500201","pt":1717291300007,"mc":[{"id":"1.229554891","rc":[{"atb":[[1.01,0],[1.1,0]],"id":70003367},{"atl":[[2.9,0]],"id":70003367},{"atb":[[1.01,0],[1.11,0]],"id":70003364},{"atl":[[2.92,0]],"id":70003364},{"atb":[[1.41,0],[1.31,0]],"id":70003365},{"atl":[[4.1,0]],"id":70003365}],"con":true,"img":false}]}
{"op":"mcm","clk":"11448500711","pt":1717291307822,"mc":[{"id":"1.229554891","rc":[{"atb":[[1.01,3484.35],[1.1,232.29]],"id":70003367},{"atl":[[2.9,0.27]],"id":70003367},{"spn":2.0,"spf":"NaN","id":70003367},{"atb":[[1.01,3484.35],[1.1,232.29]],"id":70003364},{"atl":[[2.9,0.27]],"id":70003364},{"spn":2.0,"spf":"NaN","id":70003364},{"atb":[[1.32,108.88],[1.42,55.3]],"id":70003365},{"atl":[[4.1,0.16]],"id":70003365},{"spn":2.76,"spf":"NaN","id":70003365}],"con":true,"img":false}]}
{"op":"mcm","clk":"11448505177","pt":1717291373191,"mc":[{"id":"1.229554891","rc":[{"atb":[[1.01,0],[1.1,0]],"id":70003367},{"atl":[[2.9,0]],"id":70003367},{"spn":"NaN","spf":"NaN","id":70003367},{"atb":[[1.01,0],[1.1,0]],"id":70003364},{"atl":[[2.9,0]],"id":70003364},{"spn":"NaN","spf":"NaN","id":70003364},{"atb":[[1.32,0],[1.42,0]],"id":70003365},{"atl":[[4.1,0]],"id":70003365},{"spn":"NaN","spf":"NaN","id":70003365}],"con":true,"img":false}]}
{"op":"mcm","clk":"11448506046","pt":1717291384677,"mc":[{"id":"1.229554891","rc":[{"atb":[[1.01,3484.35],[1.08,290.36]],"id":70003367},{"atl":[[2.88,0.27]],"id":70003367},{"atb":[[1.16,145.18],[1.06,580.72]],"id":70003364},{"atl":[[2.98,0.26]],"id":70003364},{"atb":[[1.4,58.07],[1.3,116.14]],"id":70003365},{"atl":[[4,0.17]],"id":70003365}],"con":true,"img":false}]}
{"op":"mcm","clk":"11448507525","pt":1717291405810,"mc":[{"id":"1.229554891","rc":[{"atb":[[1.01,0],[1.08,0]],"id":70003367},{"atl":[[2.88,0]],"id":70003367},{"atb":[[1.4,0],[1.3,0]],"id":70003365},{"atl":[[4,0]],"id":70003365}],"con":true,"img":false}]}
{"op":"mcm","clk":"11448507967","pt":1717291412383,"mc":[{"id":"1.229554891","rc":[{"atb":[[1.01,3484.35],[1.08,290.36]],"id":70003367},{"atl":[[2.88,0.27]],"id":70003367},{"atb":[[1.43,54.02],[1.33,105.58]],"id":70003365},{"atl":[[4.1,0.16]],"id":70003365}],"con":true,"img":false}]}
{"op":"mcm","clk":"11448516305","pt":1717291543772,"mc":[{"id":"1.229554891","rc":[{"atb":[[5.6,0],[4.6,0]],"id":70003366},{"spn":"NaN","spf":"NaN","id":70003366},{"atb":[[1.01,0],[1.08,0]],"id":70003367},{"atl":[[2.88,0]],"id":70003367},{"atb":[[1.16,0],[1.06,0]],"id":70003364},{"atl":[[2.98,0]],"id":70003364},{"atb":[[1.43,0],[1.33,0]],"id":70003365},{"atl":[[4.1,0]],"id":70003365}],"con":true,"img":false}]}
{"op":"mcm","clk":"11448516748","pt":1717291550972,"mc":[{"id":"1.229554891","rc":[{"atb":[[4.9,8.93],[5.9,4.73]],"id":70003366},{"atb":[[1.01,3484.35],[1.09,258.09]],"id":70003367},{"atl":[[2.9,0.27]],"id":70003367},{"atb":[[1.16,145.18],[1.06,580.72]],"id":70003364},{"atl":[[2.98,0.26]],"id":70003364},{"atb":[[1.23,151.49],[1.33,70.39]],"id":70003365},{"atl":[[3.6,0.19]],"id":70003365}],"con":true,"img":false}]}
{"op":"mcm","clk":"11448517440","pt":1717291562288,"mc":[{"id":"1.229554891","rc":[{"atb":[[4.9,0],[5.9,0]],"id":70003366},{"atb":[[1.01,0],[1.09,0]],"id":70003367},{"atl":[[2.9,0]],"id":70003367},{"atb":[[1.16,0],[1.06,0]],"id":70003364},{"atl":[[2.98,0]],"id":70003364},{"atb":[[1.23,0],[1.33,0]],"id":70003365},{"atl":[[3.6,0]],"id":70003365}],"con":true,"img":false}]}
{"op":"mcm","clk":"11448517838","pt":1717291568298,"mc":[{"id":"1.229554891","rc":[{"atb":[[6.4,4.3],[5.2,8.29]],"id":70003366},{"atb":[[1.01,3484.35],[1.09,258.09]],"id":70003367},{"atl":[[2.9,0.27]],"id":70003367},{"atb":[[1.16,145.18],[1.06,580.72]],"id":70003364},{"atl":[[2.98,0.26]],"id":70003364},{"atb":[[1.21,165.92],[1.31,74.93]],"id":70003365},{"atl":[[3.5,0.2]],"id":70003365}],"con":true,"img":false}]}
{"op":"mcm","clk":"11448520458","pt":1717291614238,"mc":[{"id":"1.229554891","rc":[{"spn":"Infinity","spf":"NaN","id":70003366},{"atb":[[1.01,0],[1.09,0]],"id":70003367},{"atl":[[2.9,0]],"id":70003367},{"atb":[[1.16,0],[1.06,0]],"id":70003364},{"atl":[[2.98,0]],"id":70003364},{"atb":[[1.21,0],[1.31,0]],"id":70003365},{"atl":[[3.5,0]],"id":70003365}],"con":true,"img":false}]}
{"op":"mcm","clk":"11448520760","pt":1717291619576,"mc":[{"id":"1.229554891","rc":[{"atb":[[1.01,3484.35],[1.09,258.09]],"id":70003367},{"atl":[[2.9,0.27]],"id":70003367},{"atb":[[1.12,290.36],[1.22,105.58]],"id":70003364},{"atl":[[3.1,0.25]],"id":70003364},{"atb":[[1.16,217.77],[1.26,89.34]],"id":70003365},{"atl":[[5.4,0.12]],"id":70003365}],"con":true,"img":false}]}
{"op":"mcm","clk":"11448521421","pt":1717291630105,"mc":[{"id":"1.229554891","rc":[{"atb":[[1.01,0],[1.09,0]],"id":70003367},{"atl":[[2.9,0]],"id":70003367},{"atb":[[1.16,0],[1.26,0]],"id":70003365},{"atl":[[5.4,0]],"id":70003365}],"con":true,"img":false}]}
{"op":"mcm","clk":"11448521774","pt":1717291635884,"mc":[{"id":"1.229554891","rc":[{"atb":[[1.01,3484.35],[1.08,290.36]],"id":70003367},{"atl":[[2.88,0.27]],"id":70003367},{"atb":[[1.19,183.38],[1.29,80.09]],"id":70003365},{"atl":[[3.4,0.21]],"id":70003365}],"con":true,"img":false}]}
{"op":"mcm","clk":"11448524030","pt":1717291678626,"mc":[{"id":"1.229554891","rc":[{"atb":[[6.4,0],[5.2,0]],"id":70003366},{"spn":"NaN","spf":"NaN","id":70003366},{"spn":1.98,"spf":"NaN","id":70003367},{"spn":2.16,"spf":"NaN","id":70003364},{"spn":2.34,"spf":"NaN","id":70003365}],"con":true,"img":false}]}
{"op":"mcm","clk":"11448524291","pt":1717291682657,"mc":[{"id":"1.229554891","rc":[{"atb":[[6.8,4],[5.4,7.92]],"id":70003366}],"con":true,"img":false}]}
{"op":"mcm","clk":"11448527332","pt":1717291733107,"mc":[{"id":"1.229554891","rc":[{"atb":[[1.01,0],[1.08,0]],"id":70003367},{"atl":[[2.88,0]],"id":70003367},{"atb":[[1.19,0],[1.29,0]],"id":70003365},{"atl":[[3.4,0]],"id":70003365}],"con":true,"img":false}]}
{"op":"mcm","clk":"11448527774","pt":1717291740829,"mc":[{"id":"1.229554891","rc":[{"spn":"Infinity","spf":"NaN","id":70003366},{"atb":[[1.01,3484.35],[1.1,232.29]],"id":70003367},{"atl":[[2.9,0.27]],"id":70003367},{"spn":2.0,"spf":"NaN","id":70003367},{"atb":[[1.25,92.91],[1.15,232.29]],"id":70003365},{"atl":[[3.2,0.23]],"id":70003365},{"spn":2.22,"spf":"NaN","id":70003365}],"con":true,"img":false}]}
{"op":"mcm","clk":"11448528399","pt":1717291751018,"mc":[{"id":"1.229554891","rc":[{"atb":[[6.8,0],[5.4,0]],"id":70003366},{"atb":[[1.01,0],[1.1,0]],"id":70003367},{"atl":[[2.9,0]],"id":70003367},{"atb":[[1.12,0],[1.22,0]],"id":70003364},{"atl":[[3.1,0]],"id":70003364},{"atb":[[1.25,0],[1.15,0]],"id":70003365},{"atl":[[3.2,0]],"id":70003365}],"con":true,"img":false}]}
{"op":"mcm","clk":"11448528848","pt":1717291758052,"mc":[{"id":"1.229554891","rc":[{"atb":[[4.9,8.93],[5.9,4.73]],"id":70003366},{"atb":[[1.01,3484.35],[1.07,331.84]],"id":70003367},{"atl":[[2.88,0.27]],"id":70003367},{"atb":[[1.19,122.25],[1.09,387.15]],"id":70003364},{"atl":[[3.05,0.25]],"id":70003364},{"atb":[[1.23,151.49],[1.33,70.39]],"id":70003365},{"atl":[[3.6,0.19]],"id":70003365}],"con":true,"img":false}]}
{"op":"mcm","clk":"11448629940","pt":1717293528418,"mc":[{"id":"1.229554891","marketDefinition":{"bspMarket":true,"turnInPlayEnabled":false,"persistenceEnabled":false,"marketBaseRate":7.0,"eventId":"33318908","eventTypeId":"4339","numberOfWinners":2,"bettingType":"ODDS","marketType":"PLACE","marketTime":"2024-06-02T08:21:00.000Z","suspendTime":"2024-06-02T08:21:00.000Z","bspReconciled":false,"complete":true,"inPlay":false,"crossMatching":true,"runnersVoidable":false,"numberOfActiveRunners":5,"betDelay":0,"status":"OPEN","runners":[{"status":"ACTIVE","sortPriority":1,"id":70003363,"name":"1. Plodding Along"},{"status":"ACTIVE","sortPriority":2,"id":70003364,"name":"2. Parrakie"},{"status":"ACTIVE","sortPriority":3,"id":70003365,"name":"4. Bookaloo"},{"status":"ACTIVE","sortPriority":4,"id":70003366,"name":"6. Manner Of Strife"},{"status":"ACTIVE","sortPriority":5,"id":70003367,"name":"8. Apilla"}],"regulators":["MR_INT"],"venue":"Murray Bridge","countryCode":"AU","discountAllowed":true,"timezone":"Australia/Adelaide","openDate":"2024-06-02T08:21:00.000Z","version":5962317650,"name":"To Be Placed","eventName":"Murray Bridge (AUS) 2nd Jun"},"rc":[{"atb":[[4.9,8.93],[5.9,4.73]],"id":70003366},{"spn":"Infinity","spf":"NaN","id":70003366},{"atb":[[1.01,3484.35],[1.07,331.84]],"id":70003367},{"atl":[[2.88,0.27]],"id":70003367},{"spn":1.97,"spf":"NaN","id":70003367},{"atb":[[1.19,122.25],[1.09,387.15]],"id":70003364},{"atl":[[3.05,0.25]],"id":70003364},{"spn":2.12,"spf":"NaN","id":70003364},{"atb":[[1.23,151.49],[1.33,70.39]],"id":70003365},{"atl":[[3.6,0.19]],"id":70003365},{"spn":2.46,"spf":"NaN","id":70003365},{"atb":[[4.5,9.95],[5.5,5.16]],"id":70003363},{"spn":"Infinity","spf":"NaN","id":70003363}],"con":true,"img":true}]}
{"op":"mcm","clk":"11448772464","pt":1717296122426,"mc":[{"id":"1.229554891","rc":[{"spn":1.97,"spf":"NaN","id":70003367},{"atb":[[1.19,0],[1.09,0]],"id":70003364},{"atl":[[3.05,0]],"id":70003364},{"spn":"NaN","spf":"NaN","id":70003364},{"spn":2.46,"spf":"NaN","id":70003365},{"atb":[[4.5,0],[5.5,0]],"id":70003363},{"spn":"NaN","spf":"NaN","id":70003363}],"con":true,"img":false}]}
{"op":"mcm","clk":"11448773249","pt":1717296140447,"mc":[{"id":"1.229554891","rc":[{"atb":[[1.16,145.18],[1.06,580.72]],"id":70003364},{"atl":[[2.98,0.26]],"id":70003364},{"atb":[[4.4,10.24],[5.4,5.27]],"id":70003363}],"con":true,"img":false}]}
{"op":"mcm","clk":"11448777241","pt":1717296235499,"mc":[{"id":"1.229554891","rc":[{"atb":[[4.9,0],[5.9,0]],"id":70003366},{"spn":"NaN","spf":"NaN","id":70003366},{"atb":[[1.01,0],[1.07,0]],"id":70003367},{"atl":[[2.88,0]],"id":70003367},{"spn":"NaN","spf":"NaN","id":70003367},{"atb":[[1.16,0],[1.06,0]],"id":70003364},{"atl":[[2.98,0]],"id":70003364},{"atb":[[1.23,0],[1.33,0]],"id":70003365},{"atl":[[3.6,0]],"id":70003365},{"spn":"NaN","spf":"NaN","id":70003365},{"spn":"Infinity","spf":"NaN","id":70003363}],"con":true,"img":false}]}
{"op":"mcm","clk":"11448777880","pt":1717296252867,"mc":[{"id":"1.229554891","rc":[{"atb":[[6.4,4.3],[5.2,8.29]],"id":70003366},{"atb":[[1.01,3484.35],[1.09,258.09]],"id":70003367},{"atl":[[2.9,0.27]],"id":70003367},{"atb":[[1.18,129.05],[1.08,435.54]],"id":70003364},{"atl":[[3,0.26]],"id":70003364},{"atb":[[1.2,174.21],[1.3,77.43]],"id":70003365},{"atl":[[3.45,0.21]],"id":70003365}],"con":true,"img":false}]}
{"op":"mcm","clk":"11448885213","pt":1717298928434,"mc":[{"id":"1.229554891","marketDefinition":{"bspMarket":true,"turnInPlayEnabled":false,"persistenceEnabled":false,"marketBaseRate":7.0,"eventId":"33318908","eventTypeId":"4339","numberOfWinners":2,"bettingType":"ODDS","marketType":"PLACE","marketTime":"2024-06-02T08:21:00.000Z","suspendTime":"2024-06-02T08:21:00.000Z","bspReconciled":false,"complete":true,"inPlay":false,"crossMatching":true,"runnersVoidable":false,"numberOfActiveRunners":5,"betDelay":0,"status":"OPEN","runners":[{"status":"ACTIVE","sortPriority":1,"id":70003363,"name":"1. Plodding Along"},{"status":"ACTIVE","sortPriority":2,"id":70003364,"name":"2. Parrakie"},{"status":"ACTIVE","sortPriority":3,"id":70003365,"name":"4. Bookaloo"},{"status":"ACTIVE","sortPriority":4,"id":70003366,"name":"6. Manner Of Strife"},{"status":"ACTIVE","sortPriority":5,"id":70003367,"name":"8. Apilla"}],"regulators":["MR_INT"],"venue":"Murray Bridge","countryCode":"AU","discountAllowed":true,"timezone":"Australia/Adelaide","openDate":"2024-06-02T08:21:00.000Z","version":5962317650,"name":"To Be Placed","eventName":"Murray Bridge (AUS) 2nd Jun"},"rc":[{"atb":[[6.4,4.3],[5.2,8.29]],"id":70003366},{"spn":"Infinity","spf":"NaN","id":70003366},{"atb":[[1.01,3484.35],[1.09,258.09]],"id":70003367},{"atl":[[2.9,0.27]],"id":70003367},{"spn":1.99,"spf":"NaN","id":70003367},{"atb":[[1.18,129.05],[1.08,435.54]],"id":70003364},{"atl":[[3,0.26]],"id":70003364},{"spn":2.09,"spf":"NaN","id":70003364},{"atb":[[1.2,174.21],[1.3,77.43]],"id":70003365},{"atl":[[3.45,0.21]],"id":70003365},{"spn":2.37,"spf":"NaN","id":70003365},{"atb":[[4.4,10.24],[5.4,5.27]],"id":70003363},{"spn":"Infinity","spf":"NaN","id":70003363}],"con":true,"img":true}]}
{"op":"mcm","clk":"11448990874","pt":1717301393980,"mc":[{"id":"1.229554891","rc":[{"atb":[[6.4,0],[5.2,0]],"id":70003366},{"atb":[[1.01,0],[1.09,0]],"id":70003367},{"atl":[[2.9,0]],"id":70003367},{"atb":[[1.18,0],[1.08,0]],"id":70003364},{"atl":[[3,0]],"id":70003364},{"atb":[[1.2,0],[1.3,0]],"id":70003365},{"atl":[[3.45,0]],"id":70003365},{"atb":[[4.4,0],[5.4,0]],"id":70003363},{"spn":"NaN","spf":"NaN","id":70003363}],"con":true,"img":false}]}
{"op":"mcm","clk":"11448991752","pt":1717301409627,"mc":[{"id":"1.229554891","rc":[{"atb":[[6.4,4.3],[5.2,8.29]],"id":70003366},{"atb":[[1.07,497.76],[1.17,136.64]],"id":70003367},{"atl":[[3,0.26]],"id":70003367},{"atb":[[1.15,154.86],[1.05,696.87]],"id":70003364},{"atl":[[2.98,0.26]],"id":70003364},{"atb":[[1.36,64.52],[1.26,134.01]],"id":70003365},{"atl":[[3.75,0.18]],"id":70003365},{"atb":[[4.1,7.49],[3.55,13.66]],"id":70003363}],"con":true,"img":false}]}
{"op":"mcm","clk":"11448993604","pt":1717301444870,"mc":[{"id":"1.229554891","rc":[{"atb":[[6.4,0],[5.2,0]],"id":70003366},{"atb":[[1.07,0],[1.17,0]],"id":70003367},{"atl":[[3,0]],"id":70003367},{"atb":[[1.15,0],[1.05,0]],"id":70003364},{"atl":[[2.98,0]],"id":70003364},{"atb":[[1.36,0],[1.26,0]],"id":70003365},{"atl":[[3.75,0]],"id":70003365},{"atb":[[4.1,0],[3.55,0]],"id":70003363}],"con":true,"img":false}]}
{"op":"mcm","clk":"11448994250","pt":1717301457065,"mc":[{"id":"1.229554891","rc":[{"atb":[[6.4,4.3],[5.2,8.29]],"id":70003366},{"spn":"Infinity","spf":"NaN","id":70003366},{"atb":[[1.19,122.25],[1.09,387.15]],"id":70003367},{"atl":[[3.05,0.25]],"id":70003367},{"spn":2.12,"spf":"NaN","id":70003367},{"atb":[[1.16,145.18],[1.06,580.72]],"id":70003364},{"atl":[[2.98,0.26]],"id":70003364},{"spn":2.07,"spf":"NaN","id":70003364},{"atb":[[1.21,165.92],[1.31,74.93]],"id":70003365},{"atl":[[3.5,0.2]],"id":70003365},{"spn":2.4,"spf":"NaN","id":70003365},{"atb":[[3.6,13.4],[4.2,7.26]],"id":70003363},{"spn":"Infinity","spf":"NaN","id":70003363}],"con":true,"img":false}]}
{"op":"mcm","clk":"11448995833","pt":1717301484409,"mc":[{"id":"1.229554891","rc":[{"atb":[[6.4,0],[5.2,0]],"id":70003366},{"atb":[[1.16,0],[1.06,0]],"id":70003364},{"atl":[[2.98,0]],"id":70003364},{"atb":[[3.6,0],[4.2,0]],"id":70003363}],"con":true,"img":false}]}
{"op":"mcm","clk":"11448996689","pt":1717301499641,"mc":[{"id":"1.229554891","rc":[{"atb":[[7.4,3.63],[5.7,7.41]],"id":70003366},{"atb":[[1.15,154.86],[1.05,696.87]],"id":70003364},{"atl":[[2.98,0.26]],"id":70003364},{"atb":[[4.1,7.49],[3.55,13.66]],"id":70003363}],"con":true,"img":false}]}
{"op":"mcm","clk":"11448998387","pt":1717301534009,"mc":[{"id":"1.229554891","rc":[{"atb":[[7.4,0],[5.7,0]],"id":70003366},{"spn":"NaN","spf":"NaN","id":70003366},{"atb":[[1.15,0],[1.05,0]],"id":70003364},{"atl":[[2.98,0]],"id":70003364},{"spn":"NaN","spf":"NaN","id":70003364},{"atb":[[4.1,0],[3.55,0]],"id":70003363},{"spn":"NaN","spf":"NaN","id":70003363}],"con":true,"img":false}]}
{"op":"mcm","clk":"11448999556","pt":1717301555299,"mc":[{"id":"1.229554891","rc":[{"atb":[[5.1,8.49],[6.2,4.46]],"id":70003366},{"atb":[[1.15,154.86],[1.05,696.87]],"id":70003364},{"atl":[[2.98,0.26]],"id":70003364},{"atb":[[3.6,13.4],[4.2,7.26]],"id":70003363}],"con":true,"img":false}]}
{"op":"mcm","clk":"11449002382","pt":1717301606922,"mc":[{"id":"1.229554891","rc":[{"atb":[[5.1,0],[6.2,0]],"id":70003366},{"atb":[[1.19,0],[1.09,0]],"id":70003367},{"atl":[[3.05,0]],"id":70003367},{"spn":"NaN","spf":"NaN","id":70003367},{"atb":[[1.15,0],[1.05,0]],"id":70003364},{"atl":[[2.98,0]],"id":70003364},{"atb":[[1.21,0],[1.31,0]],"id":70003365},{"atl":[[3.5,0]],"id":70003365},{"spn":"NaN","spf":"NaN","id":70003365},{"atb":[[3.6,0],[4.2,0]],"id":70003363}],"con":true,"img":false}]}
{"op":"mcm","clk":"11449003390","pt":1717301626865,"mc":[{"id":"1.229554891","rc":[{"atb":[[5,8.71],[6,4.64]],"id":70003366},{"atb":[[1.2,116.14],[1.1,348.43]],"id":70003367},{"atl":[[3.05,0.25]],"id":70003367},{"atb":[[1.07,497.76],[1.17,136.64]],"id":70003364},{"atl":[[3,0.26]],"id":70003364},{"atb":[[1.21,165.92],[1.31,74.93]],"id":70003365},{"atl":[[3.5,0.2]],"id":70003365},{"atb":[[4.1,7.49],[3.55,13.66]],"id":70003363}],"con":true,"img":false}]}
{"op":"mcm","clk":"11449012695","pt":1717301809743,"mc":[{"id":"1.229554891","rc":[{"atb":[[5,0],[6,0]],"id":70003366},{"atb":[[1.2,0],[1.1,0]],"id":70003367},{"atl":[[3.05,0]],"id":70003367},{"spn":2.08,"spf":"NaN","id":70003364},{"atb":[[1.21,0],[1.31,0]],"id":70003365},{"atl":[[3.5,0]],"id":70003365},{"spn":"Infinity","spf":"NaN","id":70003363}],"con":true,"img":false}]}
{"op":"mcm","clk":"11449014020","pt":1717301838486,"mc":[{"id":"1.229554891","rc":[{"atb":[[5,8.71],[6,4.64]],"id":70003366},{"atb":[[1.16,145.18],[1.06,580.72]],"id":70003367},{"atl":[[2.98,0.26]],"id":70003367},{"atb":[[1.27,129.05],[1.37,62.78]],"id":70003365},{"atl":[[3.85,0.18]],"id":70003365}],"con":true,"img":false}]}
{"op":"mcm","clk":"11449015142","pt":1717301864401,"mc":[{"id":"1.229554891","rc":[{"atb":[[1.16,0],[1.06,0]],"id":70003367},{"atl":[[2.98,0]],"id":70003367},{"atb":[[1.07,0],[1.17,0]],"id":70003364},{"atl":[[3,0]],"id":70003364},{"atb":[[1.27,0],[1.37,0]],"id":70003365},{"atl":[[3.85,0]],"id":70003365},{"atb":[[4.1,0],[3.55,0]],"id":70003363}],"con":true,"img":false}]}
{"op":"mcm","clk":"11449015689","pt":1717301876412,"mc":[{"id":"1.229554891","rc":[{"spn":"Infinity","spf":"NaN","id":70003366},{"atb":[[1.07,497.76],[1.17,136.64]],"id":70003367},{"atl":[[3,0.26]],"id":70003367},{"spn":2.08,"spf":"NaN","id":70003367},{"atb":[[1.14,165.92],[1.04,871.08]],"id":70003364},{"atl":[[2.94,0.27]],"id":70003364},{"spn":2.04,"spf":"NaN","id":70003364},{"atb":[[1.34,68.32],[1.24,145.18]],"id":70003365},{"atl":[[3.65,0.19]],"id":70003365},{"spn":2.49,"spf":"NaN","id":70003365},{"atb":[[3.7,12.9],[4.4,6.83]],"id":70003363}],"con":true,"img":false}]}
{"op":"mcm","clk":"11449020027","pt":1717301965559,"mc":[{"id":"1.229554891","rc":[{"atb":[[5,0],[6,0]],"id":70003366},{"spn":"NaN","spf":"NaN","id":70003366},{"atb":[[1.07,0],[1.17,0]],"id":70003367},{"atl":[[3,0]],"id":70003367},{"spn":"NaN","spf":"NaN","id":70003367},{"atb":[[1.14,0],[1.04,0]],"id":70003364},{"atl":[[2.94,0]],"id":70003364},{"spn":"NaN","spf":"NaN","id":70003364},{"atb":[[1.34,0],[1.24,0]],"id":70003365},{"atl":[[3.65,0]],"id":70003365},{"spn":"NaN","spf":"NaN","id":70003365}],"con":true,"img":false}]}
{"op":"mcm","clk":"11449020849","pt":1717301985069,"mc":[{"id":"1.229554891","rc":[{"atb":[[6.4,6.45],[8.4,3.13]],"id":70003366},{"atb":[[1.2,116.14],[1.1,348.43]],"id":70003367},{"atl":[[3.05,0.25]],"id":70003367},{"atb":[[1.03,1161.45],[1.13,178.68]],"id":70003364},{"atl":[[2.94,0.27]],"id":70003364},{"atb":[[1.21,165.92],[1.31,74.93]],"id":70003365},{"atl":[[3.5,0.2]],"id":70003365}],"con":true,"img":false}]}
{"op":"mcm","clk":"11449022551","pt":1717302023434,"mc":[{"id":"1.229554891","rc":[{"atb":[[1.2,0],[1.1,0]],"id":70003367},{"atl":[[3.05,0]],"id":70003367},{"atb":[[1.03,0],[1.13,0]],"id":70003364},{"atl":[[2.94,0]],"id":70003364},{"atb":[[1.21,0],[1.31,0]],"id":70003365},{"atl":[[3.5,0]],"id":70003365}],"con":true,"img":false}]}
{"op":"mcm","clk":"11449023117","pt":1717302036350,"mc":[{"id":"1.229554891","rc":[{"spn":"Infinity","spf":"NaN","id":70003366},{"atb":[[1.14,248.88],[1.24,96.78]],"id":70003367},{"atl":[[3.15,0.24]],"id":70003367},{"spn":2.19,"spf":"NaN","id":70003367},{"atb":[[1.03,1161.45],[1.13,178.68]],"id":70003364},{"atl":[[2.94,0.27]],"id":70003364},{"spn":2.03,"spf":"NaN","id":70003364},{"atb":[[1.27,86.03],[1.17,204.95]],"id":70003365},{"atl":[[3.3,0.22]],"id":70003365},{"spn":2.28,"spf":"NaN","id":70003365}],"con":true,"img":false}]}
{"op":"mcm","clk":"11449024254","pt":1717302063805,"mc":[{"id":"1.229554891","rc":[{"atb":[[6.4,0],[8.4,0]],"id":70003366},{"atb":[[1.14,0],[1.24,0]],"id":70003367},{"atl":[[3.15,0]],"id":70003367},{"atb":[[1.03,0],[1.13,0]],"id":70003364},{"atl":[[2.94,0]],"id":70003364},{"atb":[[1.27,0],[1.17,0]],"id":70003365},{"atl":[[3.3,0]],"id":70003365},{"atb":[[3.7,0],[4.4,0]],"id":70003363}],"con":true,"img":false}]}
{"op":"mcm","clk":"11449024937","pt":1717302080015,"mc":[{"id":"1.229554891","rc":[{"atb":[[6.4,6.45],[8.4,3.13]],"id":70003366},{"atb":[[1.21,110.61],[1.11,316.75]],"id":70003367},{"atl":[[3.1,0.25]],"id":70003367},{"atb":[[1.12,193.57],[1.02,1742.17]],"id":70003364},{"atl":[[2.92,0.27]],"id":70003364},{"atb":[[1.2,174.21],[1.3,77.43]],"id":70003365},{"atl":[[3.45,0.21]],"id":70003365},{"atb":[[4.1,7.49],[3.55,13.66]],"id":70003363}],"con":true,"img":false}]}
{"op":"mcm","clk":"11449025877","pt":1717302103368,"mc":[{"id":"1.229554891","rc":[{"atb":[[6.4,0],[8.4,0]],"id":70003366},{"spn":"NaN","spf":"NaN","id":70003366},{"atb":[[1.21,0],[1.11,0]],"id":70003367},{"atl":[[3.1,0]],"id":70003367},{"spn":"NaN","spf":"NaN","id":70003367},{"atb":[[1.12,0],[1.02,0]],"id":70003364},{"atl":[[2.92,0]],"id":70003364},{"spn":"NaN","spf":"NaN","id":70003364},{"atb":[[1.2,0],[1.3,0]],"id":70003365},{"atl":[[3.45,0]],"id":70003365},{"spn":"NaN","spf":"NaN","id":70003365},{"atb":[[4.1,0],[3.55,0]],"id":70003363},{"spn":"NaN","spf":"NaN","id":70003363}],"con":true,"img":false}]}
{"op":"mcm","clk":"11449026267","pt":1717302113379,"mc":[{"id":"1.229554891","rc":[{"atb":[[5.3,8.1],[6.6,4.14]],"id":70003366},{"atb":[[1.12,290.36],[1.22,105.58]],"id":70003367},{"atl":[[3.1,0.25]],"id":70003367},{"atb":[[1.12,193.57],[1.02,1742.17]],"id":70003364},{"atl":[[2.92,0.27]],"id":70003364},{"atb":[[1.21,165.92],[1.31,74.93]],"id":70003365},{"atl":[[3.5,0.2]],"id":70003365},{"atb":[[4.3,7.03],[3.65,13.14]],"id":70003363}],"con":true,"img":false}]}
{"op":"mcm","clk":"11449119124","pt":1717304328430,"mc":[{"id":"1.229554891","marketDefinition":{"bspMarket":true,"turnInPlayEnabled":false,"persistenceEnabled":false,"marketBaseRate":7.0,"eventId":"33318908","eventTypeId":"4339","numberOfWinners":2,"bettingType":"ODDS","marketType":"PLACE","marketTime":"2024-06-02T08:21:00.000Z","suspendTime":"2024-06-02T08:21:00.000Z","bspReconciled":false,"complete":true,"inPlay":false,"crossMatching":true,"runnersVoidable":false,"numberOfActiveRunners":5,"betDelay":0,"status":"OPEN","runners":[{"status":"ACTIVE","sortPriority":1,"id":70003363,"name":"1. Plodding Along"},{"status":"ACTIVE","sortPriority":2,"id":70003364,"name":"2. Parrakie"},{"status":"ACTIVE","sortPriority":3,"id":70003365,"name":"4. Bookaloo"},{"status":"ACTIVE","sortPriority":4,"id":70003366,"name":"6. Manner Of Strife"},{"status":"ACTIVE","sortPriority":5,"id":70003367,"name":"8. Apilla"}],"regulators":["MR_INT"],"venue":"Murray Bridge","countryCode":"AU","discountAllowed":true,"timezone":"Australia/Adelaide","openDate":"2024-06-02T08:21:00.000Z","version":5962317650,"name":"To Be Placed","eventName":"Murray Bridge (AUS) 2nd Jun"},"rc":[{"atb":[[5.3,8.1],[6.6,4.14]],"id":70003366},{"spn":"Infinity","spf":"NaN","id":70003366},{"atb":[[1.12,290.36],[1.22,105.58]],"id":70003367},{"atl":[[3.1,0.25]],"id":70003367},{"spn":2.16,"spf":"NaN","id":70003367},{"atb":[[1.12,193.57],[1.02,1742.17]],"id":70003364},{"atl":[[2.92,0.27]],"id":70003364},{"spn":2.02,"spf":"NaN","id":70003364},{"atb":[[1.21,165.92],[1.31,74.93]],"id":70003365},{"atl":[[3.5,0.2]],"id":70003365},{"spn":2.4,"spf":"NaN","id":70003365},{"atb":[[4.3,7.03],[3.65,13.14]],"id":70003363},{"spn":"Infinity","spf":"NaN","id":70003363}],"con":true,"img":true}]}
{"op":"mcm","clk":"11449222801","pt":1717305799102,"mc":[{"id":"1.229554891","rc":[{"atb":[[5.3,0],[6.6,0]],"id":70003366},{"atb":[[1.12,0],[1.22,0]],"id":70003367},{"atl":[[3.1,0]],"id":70003367},{"atb":[[1.12,0],[1.02,0]],"id":70003364},{"atl":[[2.92,0]],"id":70003364},{"atb":[[1.21,0],[1.31,0]],"id":70003365},{"atl":[[3.5,0]],"id":70003365},{"atb":[[4.3,0],[3.65,0]],"id":70003363}],"con":true,"img":false}]}
{"op":"mcm","clk":"11449223860","pt":1717305813531,"mc":[{"id":"1.229554891","rc":[{"atb":[[7.4,3.63],[5.7,7.41]],"id":70003366},{"atb":[[1.23,100.99],[1.13,268.02]],"id":70003367},{"atl":[[3.15,0.24]],"id":70003367},{"atb":[[1.01,3484.35],[1.07,331.84]],"id":70003364},{"atl":[[2.88,0.27]],"id":70003364},{"atb":[[1.34,68.32],[1.24,145.18]],"id":70003365},{"atl":[[3.65,0.19]],"id":70003365},{"atb":[[4.3,7.03],[3.65,13.14]],"id":70003363}],"con":true,"img":false}]}
{"op":"mcm","clk":"11449228501","pt":1717305881325,"mc":[{"id":"1.229554891","rc":[{"spn":"Infinity","spf":"NaN","id":70003366},{"atb":[[1.23,0],[1.13,0]],"id":70003367},{"atl":[[3.15,0]],"id":70003367},{"atb":[[1.01,0],[1.07,0]],"id":70003364},{"atl":[[2.88,0]],"id":70003364},{"atb":[[1.34,0],[1.24,0]],"id":70003365},{"atl":[[3.65,0]],"id":70003365},{"spn":"Infinity","spf":"NaN","id":70003363}],"con":true,"img":false}]}
{"op":"mcm","clk":"11449230789","pt":1717305912539,"mc":[{"id":"1.229554891","rc":[{"atb":[[1.25,92.91],[1.15,232.29]],"id":70003367},{"atl":[[3.2,0.23]],"id":70003367},{"atb":[[1.01,3484.35],[1.08,290.36]],"id":70003364},{"atl":[[2.88,0.27]],"id":70003364},{"atb":[[1.32,72.59],[1.22,158.38]],"id":70003365},{"atl":[[3.55,0.2]],"id":70003365}],"con":true,"img":false}]}
{"op":"mcm","clk":"11449233576","pt":1717305955844,"mc":[{"id":"1.229554891","rc":[{"atb":[[7.4,0],[5.7,0]],"id":70003366},{"spn":"NaN","spf":"NaN","id":70003366},{"atb":[[1.25,0],[1.15,0]],"id":70003367},{"atl":[[3.2,0]],"id":70003367},{"atb":[[1.01,0],[1.08,0]],"id":70003364},{"atl":[[2.88,0]],"id":70003364},{"atb":[[1.32,0],[1.22,0]],"id":70003365},{"atl":[[3.55,0]],"id":70003365},{"atb":[[4.3,0],[3.65,0]],"id":70003363},{"spn":"NaN","spf":"NaN","id":70003363}],"con":true,"img":false}]}
{"op":"mcm","clk":"11449235514","pt":1717305983593,"mc":[{"id":"1.229554891","rc":[{"atb":[[6.2,6.7],[8.2,3.22]],"id":70003366},{"atb":[[1.27,86.03],[1.17,204.95]],"id":70003367},{"atl":[[3.3,0.22]],"id":70003367},{"atb":[[1.01,3484.35],[1.02,1161.45]],"id":70003364},{"atl":[[2.82,0.28]],"id":70003364},{"atb":[[1.36,64.52],[1.26,134.01]],"id":70003365},{"atl":[[3.75,0.18]],"id":70003365},{"atb":[[4.3,7.03],[3.65,13.14]],"id":70003363}],"con":true,"img":false}]}
{"op":"mcm","clk":"11449237634","pt":1717306014418,"mc":[{"id":"1.229554891","rc":[{"atb":[[6.2,0],[8.2,0]],"id":70003366},{"atb":[[1.27,0],[1.17,0]],"id":70003367},{"atl":[[3.3,0]],"id":70003367},{"atb":[[1.01,0],[1.02,0]],"id":70003364},{"atl":[[2.82,0]],"id":70003364},{"atb":[[1.36,0],[1.26,0]],"id":70003365},{"atl":[[3.75,0]],"id":70003365},{"atb":[[4.3,0],[3.65,0]],"id":70003363}],"con":true,"img":false}]}
{"op":"mcm","clk":"11449238752","pt":1717306032017,"mc":[{"id":"1.229554891","rc":[{"atb":[[6.4,6.45],[8.4,3.13]],"id":70003366},{"spn":"Infinity","spf":"NaN","id":70003366},{"atb":[[1.21,165.92],[1.31,74.93]],"id":70003367},{"atl":[[3.5,0.2]],"id":70003367},{"spn":2.4,"spf":"NaN","id":70003367},{"atb":[[1.01,5807.26]],"id":70003364},{"atl":[[2.78,0.29]],"id":70003364},{"spn":1.89,"spf":"NaN","id":70003364},{"atb":[[1.27,129.05],[1.37,62.78]],"id":70003365},{"atl":[[3.85,0.18]],"id":70003365},{"spn":2.61,"spf":"NaN","id":70003365},{"atb":[[3.6,13.4],[4.2,7.26]],"id":70003363},{"spn":"Infinity","spf":"NaN","id":70003363}],"con":true,"img":false}]}
{"op":"mcm","clk":"11449241221","pt":1717306068555,"mc":[{"id":"1.229554891","rc":[{"atb":[[6.4,0],[8.4,0]],"id":70003366}],"con":true,"img":false}]}
{"op":"mcm","clk":"11449241953","pt":1717306078693,"mc":[{"id":"1.229554891","rc":[{"atb":[[6.4,6.45],[8.4,3.13]],"id":70003366}],"con":true,"img":false}]}
{"op":"mcm","clk":"11449258053","pt":1717306290281,"mc":[{"id":"1.229554891","rc":[{"atb":[[6.4,0],[8.4,0]],"id":70003366},{"spn":"NaN","spf":"NaN","id":70003366},{"atb":[[1.21,0],[1.31,0]],"id":70003367},{"atl":[[3.5,0]],"id":70003367},{"spn":"NaN","spf":"NaN","id":70003367},{"atb":[[1.01,0]],"id":70003364},{"atl":[[2.78,0]],"id":70003364},{"spn":"NaN","spf":"NaN","id":70003364},{"atb":[[1.27,0],[1.37,0]],"id":70003365},{"atl":[[3.85,0]],"id":70003365},{"spn":"NaN","spf":"NaN","id":70003365},{"atb":[[3.6,0],[4.2,0]],"id":70003363},{"spn":"NaN","spf":"NaN","id":70003363}],"con":true,"img":false}]}
{"op":"mcm","clk":"11449259122","pt":1717306303983,"mc":[{"id":"1.229554891","rc":[{"atb":[[7.8,3.41],[5.9,7.1]],"id":70003366},{"atb":[[1.27,129.05],[1.37,62.78]],"id":70003367},{"atl":[[3.85,0.18]],"id":70003367},{"atb":[[1.01,5807.26]],"id":70003364},{"atl":[[2.74,0.29]],"id":70003364},{"atb":[[1.41,56.65],[1.31,112.39]],"id":70003365},{"atl":[[4.1,0.16]],"id":70003365},{"atb":[[3.45,14.21],[3.95,7.87]],"id":70003363}],"con":true,"img":false}]}
{"op":"mcm","clk":"11449262361","pt":1717306345526,"mc":[{"id":"1.229554891","rc":[{"atb":[[7.8,0],[5.9,0]],"id":70003366},{"atb":[[1.27,0],[1.37,0]],"id":70003367},{"atl":[[3.85,0]],"id":70003367},{"atb":[[1.01,0]],"id":70003364},{"atl":[[2.74,0]],"id":70003364},{"atb":[[1.41,0],[1.31,0]],"id":70003365},{"atl":[[4.1,0]],"id":70003365},{"atb":[[3.45,0],[3.95,0]],"id":70003363}],"con":true,"img":false}]}
{"op":"mcm","clk":"11449263734","pt":1717306363673,"mc":[{"id":"1.229554891","rc":[{"atb":[[6.2,6.7],[8.2,3.22]],"id":70003366},{"spn":"Infinity","spf":"NaN","id":70003366},{"atb":[[1.32,108.88],[1.42,55.3]],"id":70003367},{"atl":[[4.1,0.16]],"id":70003367},{"spn":2.76,"spf":"NaN","id":70003367},{"atb":[[1.01,5807.26]],"id":70003364},{"atl":[[2.74,0.29]],"id":70003364},{"spn":1.87,"spf":"NaN","id":70003364},{"atb":[[1.25,139.37],[1.35,66.37]],"id":70003365},{"atl":[[3.7,0.19]],"id":70003365},{"spn":2.52,"spf":"NaN","id":70003365},{"atb":[[3.45,14.21],[3.95,7.87]],"id":70003363},{"spn":"Infinity","spf":"NaN","id":70003363}],"con":true,"img":false}]}
{"op":"mcm","clk":"11449301937","pt":1717306870185,"mc":[{"id":"1.229554891","rc":[{"atb":[[6.2,0],[8.2,0]],"id":70003366},{"spn":"NaN","spf":"NaN","id":70003366},{"atb":[[1.32,0],[1.42,0]],"id":70003367},{"atl":[[4.1,0]],"id":70003367},{"spn":"NaN","spf":"NaN","id":70003367},{"atb":[[1.01,0]],"id":70003364},{"atl":[[2.74,0]],"id":70003364},{"spn":"NaN","spf":"NaN","id":70003364},{"atb":[[1.25,0],[1.35,0]],"id":70003365},{"atl":[[3.7,0]],"id":70003365},{"spn":"NaN","spf":"NaN","id":70003365},{"atb":[[3.45,0],[3.95,0]],"id":70003363},{"spn":"NaN","spf":"NaN","id":70003363}],"con":true,"img":false}]}
{"op":"mcm","clk":"11449304928","pt":1717306910017,"mc":[{"id":"1.229554891","rc":[{"atb":[[5.8,7.26],[7.6,3.52]],"id":70003366},{"atb":[[1.29,120.15],[1.39,59.56]],"id":70003367},{"atl":[[3.95,0.17]],"id":70003367},{"atb":[[1.01,5807.26]],"id":70003364},{"atl":[[2.7,0.3]],"id":70003364},{"atb":[[1.41,56.65],[1.31,112.39]],"id":70003365},{"atl":[[4.1,0.16]],"id":70003365},{"atb":[[4.1,7.49],[3.55,13.66]],"id":70003363}],"con":true,"img":false}]}
{"op":"mcm","clk":"11449334055","pt":1717307327740,"mc":[{"id":"1.229554891","rc":[{"atb":[[5.8,0],[7.6,0]],"id":70003366},{"atb":[[1.29,0],[1.39,0]],"id":70003367},{"atl":[[3.95,0]],"id":70003367},{"spn":1.85,"spf":"NaN","id":70003364},{"atb":[[1.41,0],[1.31,0]],"id":70003365},{"atl":[[4.1,0]],"id":70003365},{"atb":[[4.1,0],[3.55,0]],"id":70003363}],"con":true,"img":false}]}
{"op":"mcm","clk":"11449335094","pt":1717307344108,"mc":[{"id":"1.229554891","rc":[{"atb":[[5.6,7.57],[7.2,3.74]],"id":70003366},{"atb":[[1.41,56.65],[1.31,112.39]],"id":70003367},{"atl":[[4.1,0.16]],"id":70003367},{"atb":[[1.32,108.88],[1.42,55.3]],"id":70003365},{"atl":[[4.1,0.16]],"id":70003365},{"atb":[[3.85,8.15],[3.35,14.82]],"id":70003363}],"con":true,"img":false}]}
{"op":"mcm","clk":"11449341381","pt":1717307438748,"mc":[{"id":"1.229554891","rc":[{"atb":[[5.6,0],[7.2,0]],"id":70003366},{"atb":[[1.41,0],[1.31,0]],"id":70003367},{"atl":[[4.1,0]],"id":70003367},{"atb":[[1.32,0],[1.42,0]],"id":70003365},{"atl":[[4.1,0]],"id":70003365},{"atb":[[3.85,0],[3.35,0]],"id":70003363}],"con":true,"img":false}]}
{"op":"mcm","clk":"11449342048","pt":1717307452010,"mc":[{"id":"1.229554891","rc":[{"atb":[[5.8,7.26],[7.6,3.52]],"id":70003366},{"atb":[[1.43,54.02],[1.33,105.58]],"id":70003367},{"atl":[[4.1,0.16]],"id":70003367},{"atb":[[1.27,129.05],[1.37,62.78]],"id":70003365},{"atl":[[3.85,0.18]],"id":70003365},{"atb":[[4.1,7.49],[3.55,13.66]],"id":70003363}],"con":true,"img":false}]}
{"op":"mcm","clk":"11449358394","pt":1717307834450,"mc":[{"id":"1.229554891","rc":[{"atb":[[1.02,8.87]],"id":70003366},{"atl":[[990,0.85]],"id":70003366},{"spn":498.8,"spf":"NaN","id":70003366},{"atb":[[1.01,17.76]],"id":70003367},{"atl":[[1000,0.85]],"id":70003367},{"spn":2.76,"spf":"NaN","id":70003367},{"atb":[[1.02,8.87]],"id":70003364},{"atl":[[1000,0.85]],"id":70003364},{"spn":1.86,"spf":"NaN","id":70003364},{"atb":[[1.03,5.92]],"id":70003365},{"atl":[[1000,0.85]],"id":70003365},{"spn":2.61,"spf":"NaN","id":70003365},{"atb":[[1.02,8.87]],"id":70003363},{"atl":[[990,0.85]],"id":70003363},{"spn":497.05,"spf":"NaN","id":70003363}],"con":true,"img":false}]}
{"op":"mcm","clk":"11449363583","pt":1717307963108,"mc":[{"id":"1.229554891","rc":[{"atb":[[5.8,0],[7.6,0]],"id":70003366},{"spn":495.51,"spf":"NaN","id":70003366},{"atb":[[1.43,0],[1.33,0]],"id":70003367},{"atl":[[4.1,0]],"id":70003367},{"spn":500.5,"spf":"NaN","id":70003367},{"atb":[[1.01,0]],"id":70003364},{"atl":[[2.7,0]],"id":70003364},{"spn":500.51,"spf":"NaN","id":70003364},{"atb":[[1.27,0],[1.37,0]],"id":70003365},{"atl":[[3.85,0]],"id":70003365},{"spn":500.51,"spf":"NaN","id":70003365},{"atb":[[4.1,0],[3.55,0]],"id":70003363},{"spn":495.51,"spf":"NaN","id":70003363}],"con":true,"img":false}]}
{"op":"mcm","clk":"11449364610","pt":1717307987909,"mc":[{"id":"1.229554891","rc":[{"atb":[[7.8,3.41],[5.9,7.1]],"id":70003366},{"atb":[[1.45,51.62],[1.35,99.55]],"id":70003367},{"atl":[[4.2,0.16]],"id":70003367},{"atb":[[1.01,5807.26]],"id":70003364},{"atl":[[2.74,0.29]],"id":70003364},{"atb":[[1.36,64.52],[1.26,134.01]],"id":70003365},{"atl":[[3.75,0.18]],"id":70003365},{"atb":[[3.8,8.29],[3.3,15.15]],"id":70003363}],"con":true,"img":false}]}
{"op":"mcm","clk":"11449433528","pt":1717309070158,"mc":[{"id":"1.229554891","rc":[{"atb":[[7.8,0],[5.9,0]],"id":70003366},{"atb":[[1.45,0],[1.35,0]],"id":70003367},{"atl":[[4.2,0]],"id":70003367},{"atb":[[1.01,0]],"id":70003364},{"atl":[[2.74,0]],"id":70003364},{"atb":[[1.36,0],[1.26,0]],"id":70003365},{"atl":[[3.75,0]],"id":70003365},{"atb":[[3.8,0],[3.3,0]],"id":70003363}],"con":true,"img":false}]}
{"op":"mcm","clk":"11449435536","pt":1717309098907,"mc":[{"id":"1.229554891","rc":[{"atb":[[7.4,3.63],[5.7,7.41]],"id":70003366},{"atb":[[1.41,56.65],[1.31,112.39]],"id":70003367},{"atl":[[4.1,0.16]],"id":70003367},{"atb":[[1.01,5807.26]],"id":70003364},{"atl":[[2.76,0.29]],"id":70003364},{"atb":[[1.4,58.07],[1.3,116.14]],"id":70003365},{"atl":[[4,0.17]],"id":70003365},{"atb":[[3.25,15.48],[3.75,8.44]],"id":70003363}],"con":true,"img":false}]}
{"op":"mcm","clk":"11449480328","pt":1717309728418,"mc":[{"id":"1.229554891","marketDefinition":{"bspMarket":true,"turnInPlayEnabled":false,"persistenceEnabled":false,"marketBaseRate":7.0,"eventId":"33318908","eventTypeId":"4339","numberOfWinners":2,"bettingType":"ODDS","marketType":"PLACE","marketTime":"2024-06-02T08:21:00.000Z","suspendTime":"2024-06-02T08:21:00.000Z","bspReconciled":false,"complete":true,"inPlay":false,"crossMatching":true,"runnersVoidable":false,"numberOfActiveRunners":5,"betDelay":0,"status":"OPEN","runners":[{"status":"ACTIVE","sortPriority":1,"id":70003363,"name":"1. Plodding Along"},{"status":"ACTIVE","sortPriority":2,"id":70003364,"name":"2. Parrakie"},{"status":"ACTIVE","sortPriority":3,"id":70003365,"name":"4. Bookaloo"},{"status":"ACTIVE","sortPriority":4,"id":70003366,"name":"6. Manner Of Strife"},{"status":"ACTIVE","sortPriority":5,"id":70003367,"name":"8. Apilla"}],"regulators":["MR_INT"],"venue":"Murray Bridge","countryCode":"AU","discountAllowed":true,"timezone":"Australia/Adelaide","openDate":"2024-06-02T08:21:00.000Z","version":5962317650,"name":"To Be Placed","eventName":"Murray Bridge (AUS) 2nd Jun"},"rc":[{"atb":[[7.4,3.63],[1.02,8.87],[5.7,7.41]],"id":70003366},{"atl":[[990,0.85]],"id":70003366},{"spn":498.7,"spf":"NaN","id":70003366},{"atb":[[1.41,56.65],[1.01,17.76],[1.31,112.39]],"id":70003367},{"atl":[[4.1,0.16],[1000,0.85]],"id":70003367},{"spn":2.75,"spf":"NaN","id":70003367},{"atb":[[1.01,5807.26],[1.02,8.87]],"id":70003364},{"atl":[[2.76,0.29],[1000,0.85]],"id":70003364},{"spn":1.89,"spf":"NaN","id":70003364},{"atb":[[1.4,58.07],[1.03,5.92],[1.3,116.14]],"id":70003365},{"atl":[[4,0.17],[1000,0.85]],"id":70003365},{"spn":2.7,"spf":"NaN","id":70003365},{"atb":[[1.02,8.87],[3.25,15.48],[3.75,8.44]],"id":70003363},{"atl":[[990,0.85]],"id":70003363},{"spn":496.87,"spf":"NaN","id":70003363}],"con":true,"img":true}]}
{"op":"mcm","clk":"11449497926","pt":1717309918729,"mc":[{"id":"1.229554891","rc":[{"atb":[[7.4,0],[5.7,0]],"id":70003366},{"atb":[[1.41,0],[1.31,0]],"id":70003367},{"atl":[[4.1,0]],"id":70003367},{"atb":[[1.01,0]],"id":70003364},{"atl":[[2.76,0]],"id":70003364},{"atb":[[1.4,0],[1.3,0]],"id":70003365},{"atl":[[4,0]],"id":70003365},{"atb":[[3.25,0],[3.75,0]],"id":70003363}],"con":true,"img":false}]}
{"op":"mcm","clk":"11449499421","pt":1717309943849,"mc":[{"id":"1.229554891","rc":[{"atb":[[5.8,7.26],[7.6,3.52]],"id":70003366},{"atb":[[1.32,108.88],[1.42,55.3]],"id":70003367},{"atl":[[4.1,0.16]],"id":70003367},{"atb":[[1.01,5807.26]],"id":70003364},{"atl":[[2.7,0.3]],"id":70003364},{"atb":[[1.32,108.88],[1.42,55.3]],"id":70003365},{"atl":[[4.1,0.16]],"id":70003365},{"atb":[[3.4,14.51],[3.9,8]],"id":70003363}],"con":true,"img":false}]}
{"op":"mcm","clk":"11449532192","pt":1717310487911,"mc":[{"id":"1.229554891","rc":[{"atb":[[5.8,0],[7.6,0]],"id":70003366},{"spn":2.76,"spf":"NaN","id":70003367},{"spn":1.86,"spf":"NaN","id":70003364},{"spn":2.76,"spf":"NaN","id":70003365},{"atb":[[3.4,0],[3.9,0]],"id":70003363}],"con":true,"img":false}]}
{"op":"mcm","clk":"11449533234","pt":1717310504889,"mc":[{"id":"1.229554891","rc":[{"atb":[[5.6,7.57],[7.2,3.74]],"id":70003366},{"atb":[[3.45,14.21],[3.95,7.87]],"id":70003363}],"con":true,"img":false}]}
{"op":"mcm","clk":"11449550471","pt":1717310796824,"mc":[{"id":"1.229554891","rc":[{"atb":[[5.6,0],[7.2,0]],"id":70003366},{"atb":[[1.32,0],[1.42,0]],"id":70003367},{"atl":[[4.1,0]],"id":70003367},{"spn":500.5,"spf":"NaN","id":70003367},{"atb":[[1.01,0]],"id":70003364},{"atl":[[2.7,0]],"id":70003364},{"spn":500.51,"spf":"NaN","id":70003364},{"atb":[[1.32,0],[1.42,0]],"id":70003365},{"atl":[[4.1,0]],"id":70003365},{"spn":500.51,"spf":"NaN","id":70003365},{"atb":[[3.45,0],[3.95,0]],"id":70003363}],"con":true,"img":false}]}
{"op":"mcm","clk":"11449552512","pt":1717310833578,"mc":[{"id":"1.229554891","rc":[{"atb":[[5.3,8.1],[6.6,4.14]],"id":70003366},{"atb":[[1.43,54.02],[1.33,105.58]],"id":70003367},{"atl":[[4.1,0.16]],"id":70003367},{"atb":[[1.01,5807.26]],"id":70003364},{"atl":[[2.74,0.29]],"id":70003364},{"atb":[[1.27,129.05],[1.37,62.78]],"id":70003365},{"atl":[[3.85,0.18]],"id":70003365},{"atb":[[4.1,7.49],[3.55,13.66]],"id":70003363}],"con":true,"img":false}]}
{"op":"mcm","clk":"11449573511","pt":1717311221244,"mc":[{"id":"1.229554891","rc":[{"atb":[[6.2,10.53],[7,6.97]],"id":70003366},{"atl":[[210,2.81]],"id":70003366},{"spn":108.5,"spf":"NaN","id":70003366},{"atb":[[1.23,253.06],[1.34,49.24]],"id":70003367},{"atl":[[7.4,9.09],[7,6.97]],"id":70003367},{"spn":2.76,"spf":"NaN","id":70003367},{"atb":[[1.12,119.36],[1.11,558.75]],"id":70003364},{"atl":[[4.8,16.21],[4.6,11.62]],"id":70003364},{"spn":1.93,"spf":"NaN","id":70003364},{"atb":[[1.28,184.04],[1.38,44.05]],"id":70003365},{"atl":[[7.4,6.53],[7.8,7.58]],"id":70003365},{"spn":2.61,"spf":"NaN","id":70003365},{"atb":[[3.6,16.09],[3,26.42]],"id":70003363},{"atl":[[55,5.23]],"id":70003363},{"spn":29.55,"spf":"NaN","id":70003363}],"con":true,"img":false}]}
{"op":"mcm","clk":"11449575966","pt":1717311263435,"mc":[{"id":"1.229554891","rc":[{"atb":[[7,0]],"id":70003366}],"con":true,"img":false}]}
{"op":"mcm","clk":"11449575973","pt":1717311263589,"mc":[{"id":"1.229554891","rc":[{"atb":[[7.2,6.97]],"id":70003366}],"con":true,"img":false}]}
{"op":"mcm","clk":"11449586694","pt":1717311442903,"mc":[{"id":"1.229554891","rc":[{"atl":[[990,0.17]],"id":70003366},{"spn":108.6,"spf":"NaN","id":70003366},{"atl":[[1000,0.17]],"id":70003367},{"atl":[[1000,0.17]],"id":70003364},{"atl":[[1000,0.17]],"id":70003365},{"atl":[[990,0.17]],"id":70003363}],"con":true,"img":false}]}
{"op":"mcm","clk":"11449601377","pt":1717311718333,"mc":[{"id":"1.229554891","rc":[{"atb":[[5.3,0],[6.6,0]],"id":70003366},{"atb":[[1.43,0],[1.33,0]],"id":70003367},{"atl":[[4.1,0]],"id":70003367},{"spn":4.17,"spf":"NaN","id":70003367},{"atb":[[1.01,0]],"id":70003364},{"atl":[[2.74,0]],"id":70003364},{"spn":2.86,"spf":"NaN","id":70003364},{"atb":[[1.27,0],[1.37,0]],"id":70003365},{"atl":[[3.85,0]],"id":70003365},{"spn":4.39,"spf":"NaN","id":70003365},{"atb":[[4.1,0],[3.55,0]],"id":70003363},{"spn":29.3,"spf":"NaN","id":70003363}],"con":true,"img":false}]}
{"op":"mcm","clk":"11449602283","pt":1717311734775,"mc":[{"id":"1.229554891","rc":[{"atb":[[1.34,0]],"id":70003367},{"atb":[[1.28,0],[1.38,0]],"id":70003365},{"atb":[[3.6,0]],"id":70003363}],"con":true,"img":false}]}
{"op":"mcm","clk":"11449602290","pt":1717311734877,"mc":[{"id":"1.229554891","rc":[{"atb":[[1.26,49.24]],"id":70003367},{"atb":[[1.28,44.05],[1.24,184.04]],"id":70003365},{"atb":[[3.3,16.09]],"id":70003363}],"con":true,"img":false}]}
{"op":"mcm","clk":"11449603138","pt":1717311751696,"mc":[{"id":"1.229554891","rc":[{"atb":[[7.4,3.63],[5.7,7.41]],"id":70003366},{"atb":[[1.44,52.79],[1.34,102.47]],"id":70003367},{"atl":[[4.2,0.16]],"id":70003367},{"atb":[[1.01,5807.26]],"id":70003364},{"atl":[[2.72,0.3]],"id":70003364},{"atb":[[1.29,120.15],[1.39,59.56]],"id":70003365},{"atl":[[3.95,0.17]],"id":70003365},{"atb":[[3.8,8.29],[3.3,31.24]],"id":70003363}],"con":true,"img":false}]}
{"op":"mcm","clk":"11449605979","pt":1717311806431,"mc":[{"id":"1.229554891","rc":[{"spn":108.7,"spf":"NaN","id":70003366},{"atb":[[1.26,0]],"id":70003367},{"spn":2.82,"spf":"NaN","id":70003367},{"spn":1.92,"spf":"NaN","id":70003364},{"atb":[[1.28,0]],"id":70003365},{"spn":2.67,"spf":"NaN","id":70003365},{"atb":[[3.3,15.15]],"id":70003363},{"spn":29.4,"spf":"NaN","id":70003363}],"con":true,"img":false}]}
{"op":"mcm","clk":"11449605986","pt":1717311806536,"mc":[{"id":"1.229554891","rc":[{"atb":[[1.35,49.24]],"id":70003367},{"atb":[[1.4,44.05]],"id":70003365},{"atb":[[3.35,16.09]],"id":70003363}],"con":true,"img":false}]}
{"op":"mcm","clk":"11449610104","pt":1717311877340,"mc":[{"id":"1.229554891","rc":[{"spn":2.67,"spf":"NaN","id":70003365},{"atb":[[3.35,0]],"id":70003363}],"con":true,"img":false}]}
{"op":"mcm","clk":"11449610109","pt":1717311877450,"mc":[{"id":"1.229554891","rc":[{"atb":[[3.85,16.09]],"id":70003363}],"con":true,"img":false}]}
{"op":"mcm","clk":"11449615244","pt":1717311970789,"mc":[{"id":"1.229554891","rc":[{"atl":[[210,2.61]],"id":70003366},{"atb":[[1.12,0]],"id":70003364},{"spn":1.91,"spf":"NaN","id":70003364},{"spn":29.42,"spf":"NaN","id":70003363}],"con":true,"img":false}]}
{"op":"mcm","clk":"11449615257","pt":1717311970897,"mc":[{"id":"1.229554891","rc":[{"atl":[[170,0.19]],"id":70003366},{"atb":[[1.14,119.36]],"id":70003364}],"con":true,"img":false}]}
{"op":"mcm","clk":"11449616603","pt":1717311998189,"mc":[{"id":"1.229554891","rc":[{"atl":[[210,0]],"id":70003366},{"atl":[[7,0]],"id":70003367},{"atb":[[1.11,0]],"id":70003364},{"atl":[[7.4,0]],"id":70003365},{"atb":[[3.85,0],[3,0]],"id":70003363}],"con":true,"img":false}]}
{"op":"mcm","clk":"11449616611","pt":1717311998287,"mc":[{"id":"1.229554891","rc":[{"atl":[[180,2.61]],"id":70003366},{"atl":[[6.2,6.97]],"id":70003367},{"atb":[[1.12,558.75]],"id":70003364},{"atl":[[6.6,6.53]],"id":70003365},{"atb":[[3.35,26.42],[3.55,16.09]],"id":70003363}],"con":true,"img":false}]}
{"op":"mcm","clk":"11449617923","pt":1717312024197,"mc":[{"id":"1.229554891","rc":[{"atl":[[7.4,0]],"id":70003367}],"con":true,"img":false}]}
{"op":"mcm","clk":"11449617925","pt":1717312024301,"mc":[{"id":"1.229554891","rc":[{"atl":[[6.6,9.09]],"id":70003367}],"con":true,"img":false}]}
{"op":"mcm","clk":"11449620254","pt":1717312069187,"mc":[{"id":"1.229554891","rc":[{"spn":88.7,"spf":"NaN","id":70003366},{"spn":1.93,"spf":"NaN","id":70003364},{"atb":[[3.55,0]],"id":70003363},{"spn":29.4,"spf":"NaN","id":70003363}],"con":true,"img":false}]}
{"op":"mcm","clk":"11449620263","pt":1717312069292,"mc":[{"id":"1.229554891","rc":[{"atb":[[3.85,16.09]],"id":70003363}],"con":true,"img":false}]}
{"op":"mcm","clk":"11449639286","pt":1717312554827,"mc":[{"id":"1.229554891","rc":[{"atb":[[7.4,0],[5.7,0]],"id":70003366},{"spn":88.6,"spf":"NaN","id":70003366},{"atb":[[1.44,0],[1.34,0]],"id":70003367},{"atl":[[4.2,0]],"id":70003367},{"spn":3.77,"spf":"NaN","id":70003367},{"atb":[[1.01,0]],"id":70003364},{"atl":[[2.72,0]],"id":70003364},{"spn":2.87,"spf":"NaN","id":70003364},{"atb":[[1.29,0],[1.39,0]],"id":70003365},{"atl":[[3.95,0]],"id":70003365},{"spn":4.0,"spf":"NaN","id":70003365},{"atb":[[3.8,0],[3.3,0]],"id":70003363},{"spn":29.42,"spf":"NaN","id":70003363}],"con":true,"img":false}]}
{"op":"mcm","clk":"11449639754","pt":1717312566647,"mc":[{"id":"1.229554891","rc":[{"atb":[[5.3,8.1],[6.6,4.14]],"id":70003366},{"atb":[[1.43,54.02],[1.33,105.58]],"id":70003367},{"atl":[[4.1,0.16]],"id":70003367},{"atb":[[1.01,5807.26]],"id":70003364},{"atl":[[2.78,0.29]],"id":70003364},{"atb":[[1.29,120.15],[1.39,59.56]],"id":70003365},{"atl":[[3.95,0.17]],"id":70003365},{"atb":[[3.25,15.48],[3.75,8.44]],"id":70003363}],"con":true,"img":false}]}
{"op":"mcm","clk":"11449639969","pt":1717312572948,"mc":[{"id":"1.229554891","rc":[{"atb":[[1.35,0]],"id":70003367},{"atb":[[3.85,0]],"id":70003363}],"con":true,"img":false}]}
{"op":"mcm","clk":"11449639978","pt":1717312573000,"mc":[{"id":"1.229554891","rc":[{"atb":[[1.34,49.24]],"id":70003367},{"atb":[[3.8,16.09]],"id":70003363}],"con":true,"img":false}]}
{"op":"mcm","clk":"11449652040","pt":1717312860343,"mc":[{"id":"1.229554891","rc":[{"atb":[[3.75,15.07]],"id":70003366},{"atl":[[180,4.61]],"id":70003366},{"atl":[[6,6.97]],"id":70003367},{"spn":2.76,"spf":"NaN","id":70003367},{"atl":[[4.5,11.62]],"id":70003364},{"spn":1.96,"spf":"NaN","id":70003364},{"atl":[[6.4,6.54]],"id":70003365},{"spn":2.67,"spf":"NaN","id":70003365},{"atb":[[2.2,31.59]],"id":70003363},{"atl":[[50,2.04]],"id":70003363},{"spn":26.9,"spf":"NaN","id":70003363}],"con":true,"img":false}]}
{"op":"mcm","clk":"11449653874","pt":1717312902778,"mc":[{"id":"1.229554891","rc":[{"atl":[[55,2.61]],"id":70003363}],"con":true,"img":false}]}
{"op":"mcm","clk":"11449653879","pt":1717312902883,"mc":[{"id":"1.229554891","rc":[{"atl":[[48,2.61],[50,0],[55,4.61]],"id":70003363}],"con":true,"img":false}]}
{"op":"mcm","clk":"11449653886","pt":1717312902983,"mc":[{"id":"1.229554891","rc":[{"atl":[[55,2.61],[230,2]],"id":70003363}],"con":true,"img":false}]}
{"op":"mcm","clk":"11449654161","pt":1717312909574,"mc":[{"id":"1.229554891","rc":[{"atb":[[1.42,9.34]],"id":70003365}],"con":true,"img":false}]}
{"op":"mcm","clk":"11449654167","pt":1717312909675,"mc":[{"id":"1.229554891","rc":[{"atb":[[1.45,8.72]],"id":70003367}],"con":true,"img":false}]}
{"op":"mcm","clk":"11449654717","pt":1717312922892,"mc":[{"id":"1.229554891","rc":[{"spn":2.77,"spf":"NaN","id":70003367},{"spn":2.68,"spf":"NaN","id":70003365},{"atl":[[48,0]],"id":70003363},{"spn":29.4,"spf":"NaN","id":70003363}],"con":true,"img":false}]}
{"op":"mcm","clk":"11449654722","pt":1717312922991,"mc":[{"id":"1.229554891","rc":[{"atl":[[50,2.61]],"id":70003363}],"con":true,"img":false}]}
{"op":"mcm","clk":"11449655363","pt":1717312939648,"mc":[{"id":"1.229554891","rc":[{"atl":[[50,4.65],[230,0]],"id":70003363}],"con":true,"img":false}]}
{"op":"mcm","clk":"11449655367","pt":1717312939750,"mc":[{"id":"1.229554891","rc":[{"atl":[[50,2.61],[55,4.61]],"id":70003363}],"con":true,"img":false}]}
{"op":"mcm","clk":"11449655497","pt":1717312943400,"mc":[{"id":"1.229554891","rc":[{"atb":[[7.2,0]],"id":70003366}],"con":true,"img":false}]}
{"op":"mcm","clk":"11449655501","pt":1717312943503,"mc":[{"id":"1.229554891","rc":[{"atb":[[7.4,6.97]],"id":70003366}],"con":true,"img":false}]}
{"op":"mcm","clk":"11449655960","pt":1717312955878,"mc":[{"id":"1.229554891","rc":[{"atb":[[5.3,0],[6.6,0]],"id":70003366},{"atb":[[1.43,0],[1.33,0]],"id":70003367},{"atl":[[4.1,0]],"id":70003367},{"atb":[[1.01,0]],"id":70003364},{"atl":[[2.78,0]],"id":70003364},{"atb":[[1.29,0],[1.39,0]],"id":70003365},{"atl":[[3.95,0]],"id":70003365},{"atb":[[3.25,0],[3.75,0]],"id":70003363}],"con":true,"img":false}]}
{"op":"mcm","clk":"11449656037","pt":1717312957994,"mc":[{"id":"1.229554891","rc":[{"atb":[[6.2,0]],"id":70003366},{"atb":[[1.34,0]],"id":70003367},{"atb":[[1.4,0]],"id":70003365},{"atb":[[3.8,0]],"id":70003363}],"con":true,"img":false}]}
{"op":"mcm","clk":"11449656043","pt":1717312958098,"mc":[{"id":"1.229554891","rc":[{"atb":[[6.6,10.53]],"id":70003366},{"atb":[[1.26,49.24]],"id":70003367},{"atb":[[1.28,44.05]],"id":70003365},{"atb":[[3.55,16.09]],"id":70003363}],"con":true,"img":false}]}
{"op":"mcm","clk":"11449656387","pt":1717312965929,"mc":[{"id":"1.229554891","rc":[{"atb":[[5.8,7.26],[7.6,3.52]],"id":70003366},{"atb":[[1.4,58.07],[1.3,116.14]],"id":70003367},{"atl":[[4,0.17]],"id":70003367},{"atb":[[1.01,5807.26]],"id":70003364},{"atl":[[2.72,0.3]],"id":70003364},{"atb":[[1.32,108.88],[1.42,64.64]],"id":70003365},{"atl":[[4.1,0.16]],"id":70003365},{"atb":[[3.85,8.15],[3.35,41.24]],"id":70003363}],"con":true,"img":false}]}
{"op":"mcm","clk":"11449656577","pt":1717312970329,"mc":[{"id":"1.229554891","rc":[{"atb":[[1.42,55.3]],"id":70003365}],"con":true,"img":false}]}
{"op":"mcm","clk":"11449656586","pt":1717312970534,"mc":[{"id":"1.229554891","rc":[{"atb":[[1.44,8.91]],"id":70003365}],"con":true,"img":false}]}
{"op":"mcm","clk":"11449657518","pt":1717312993874,"mc":[{"id":"1.229554891","rc":[{"spn":88.8,"spf":"NaN","id":70003366},{"spn":2.72,"spf":"NaN","id":70003367},{"spn":1.93,"spf":"NaN","id":70003364},{"spn":2.77,"spf":"NaN","id":70003365},{"atl":[[55,2]],"id":70003363},{"spn":26.92,"spf":"NaN","id":70003363}],"con":true,"img":false}]}
{"op":"mcm","clk":"11449657525","pt":1717312993932,"mc":[{"id":"1.229554891","rc":[{"atl":[[48,2.61]],"id":70003363}],"con":true,"img":false}]}
{"op":"mcm","clk":"11449657531","pt":1717312994035,"mc":[{"id":"1.229554891","rc":[{"atl":[[48,4.74],[55,0]],"id":70003363}],"con":true,"img":false}]}
{"op":"mcm","clk":"11449657537","pt":1717312994132,"mc":[{"id":"1.229554891","rc":[{"atl":[[48,2.61],[50,4.65]],"id":70003363}],"con":true,"img":false}]}
{"op":"mcm","clk":"11449657815","pt":1717313000752,"mc":[{"id":"1.229554891","rc":[{"atb":[[3.55,0]],"id":70003363}],"con":true,"img":false}]}
{"op":"mcm","clk":"11449657819","pt":1717313000855,"mc":[{"id":"1.229554891","rc":[{"atb":[[3.9,16.09]],"id":70003363}],"con":true,"img":false}]}
{"op":"mcm","clk":"11449657848","pt":1717313001880,"mc":[{"id":"1.229554891","rc":[{"atb":[[1.26,0]],"id":70003367},{"atb":[[1.28,0]],"id":70003365}],"con":true,"img":false}]}
{"op":"mcm","clk":"11449657852","pt":1717313001978,"mc":[{"id":"1.229554891","rc":[{"atb":[[1.31,49.24]],"id":70003367},{"atb":[[1.33,44.05]],"id":70003365}],"con":true,"img":false}]}
{"op":"mcm","clk":"11449657858","pt":1717313002185,"mc":[{"id":"1.229554891","rc":[{"atb":[[1.33,56.96]],"id":70003365}],"con":true,"img":false}]}
{"op":"mcm","clk":"11449657886","pt":1717313002857,"mc":[{"id":"1.229554891","rc":[{"atb":[[1.42,10.14]],"id":70003367}],"con":true,"img":false}]}
{"op":"mcm","clk":"11449658591","pt":1717313021391,"mc":[{"id":"1.229554891","rc":[{"atb":[[5.5,14.23],[3.75,0]],"id":70003366},{"atl":[[7.8,0]],"id":70003365}],"con":true,"img":false}]}
{"op":"mcm","clk":"11449658596","pt":1717313021495,"mc":[{"id":"1.229554891","rc":[{"atl":[[6.8,7.58]],"id":70003365},{"atb":[[2.3,32.2],[2.2,0]],"id":70003363}],"con":true,"img":false}]}
{"op":"mcm","clk":"11449658914","pt":1717313028426,"mc":[{"id":"1.229554891","rc":[{"atb":[[3.75,14.52]],"id":70003366}],"con":true,"img":false}]}
{"op":"mcm","clk":"11449658921","pt":1717313028526,"mc":[{"id":"1.229554891","rc":[{"atb":[[5.5,0]],"id":70003366}],"con":true,"img":false}]}
{"op":"mcm","clk":"11449659238","pt":1717313035611,"mc":[{"id":"1.229554891","rc":[{"atb":[[1.45,0]],"id":70003367}],"con":true,"img":false}]}
{"op":"mcm","clk":"11449659618","pt":1717313044795,"mc":[{"id":"1.229554891","rc":[{"atb":[[1.42,19.48]],"id":70003367}],"con":true,"img":false}]}
{"op":"mcm","clk":"11449660417","pt":1717313063837,"mc":[{"id":"1.229554891","rc":[{"atb":[[5.5,14.23],[3.75,0]],"id":70003366},{"spn":2.71,"spf":"NaN","id":70003367},{"spn":25.95,"spf":"NaN","id":70003363}],"con":true,"img":false}]}
{"op":"mcm","clk":"11449662658","pt":1717313112212,"mc":[{"id":"1.229554891","rc":[{"atb":[[7.4,0]],"id":70003366},{"atl":[[4.6,0]],"id":70003364}],"con":true,"img":false}]}
{"op":"mcm","clk":"11449662666","pt":1717313112318,"mc":[{"id":"1.229554891","rc":[{"atb":[[7.6,10.49]],"id":70003366},{"atl":[[4.2,11.62]],"id":70003364}],"con":true,"img":false}]}
{"op":"mcm","clk":"11449662726","pt":1717313113296,"mc":[{"id":"1.229554891","rc":[{"atb":[[1.33,12.91]],"id":70003365},{"atb":[[3.9,0]],"id":70003363}],"con":true,"img":false}]}
{"op":"mcm","clk":"11449662734","pt":1717313113397,"mc":[{"id":"1.229554891","rc":[{"atb":[[1.43,44.05]],"id":70003365},{"atb":[[3.65,16.09]],"id":70003363}],"con":true,"img":false}]}
{"op":"mcm","clk":"11449663071","pt":1717313119518,"mc":[{"id":"1.229554891","rc":[{"atb":[[1.24,0]],"id":70003365}],"con":true,"img":false}]}
{"op":"mcm","clk":"11449663077","pt":1717313119621,"mc":[{"id":"1.229554891","rc":[{"atb":[[1.26,184.04]],"id":70003365}],"con":true,"img":false}]}
{"op":"mcm","clk":"11449663115","pt":1717313120233,"mc":[{"id":"1.229554891","rc":[{"atb":[[1.44,0]],"id":70003365}],"con":true,"img":false}]}
{"op":"mcm","clk":"11449663126","pt":1717313120441,"mc":[{"id":"1.229554891","rc":[{"atb":[[1.45,8.72]],"id":70003365}],"con":true,"img":false}]}
{"op":"mcm","clk":"11449664088","pt":1717313143153,"mc":[{"id":"1.229554891","rc":[{"atb":[[5.8,0],[7.6,6.97]],"id":70003366},{"atb":[[1.4,0],[1.3,0]],"id":70003367},{"atl":[[4,0]],"id":70003367},{"spn":3.71,"spf":"NaN","id":70003367},{"atb":[[1.01,0]],"id":70003364},{"atl":[[2.72,0]],"id":70003364},{"spn":2.67,"spf":"NaN","id":70003364},{"atb":[[1.32,0],[1.42,0]],"id":70003365},{"atl":[[4.1,0]],"id":70003365},{"spn":3.92,"spf":"NaN","id":70003365},{"atb":[[3.85,0],[3.35,26.42]],"id":70003363},{"spn":25.82,"spf":"NaN","id":70003363}],"con":true,"img":false}]}
{"op":"mcm","clk":"11449664094","pt":1717313143261,"mc":[{"id":"1.229554891","rc":[{"atl":[[4.5,0],[4.3,23.24]],"id":70003364}],"con":true,"img":false}]}
{"op":"mcm","clk":"11449664121","pt":1717313143727,"mc":[{"id":"1.229554891","rc":[{"atb":[[1.31,0]],"id":70003367},{"atb":[[1.43,0]],"id":70003365},{"atb":[[3.65,0]],"id":70003363}],"con":true,"img":false}]}
{"op":"mcm","clk":"11449664127","pt":1717313143832,"mc":[{"id":"1.229554891","rc":[{"atb":[[1.26,49.24]],"id":70003367},{"atb":[[1.3,44.05]],"id":70003365},{"atb":[[3.55,16.09]],"id":70003363}],"con":true,"img":false}]}
{"op":"mcm","clk":"11449664152","pt":1717313144656,"mc":[{"id":"1.229554891","rc":[{"atb":[[1.42,9.34]],"id":70003367},{"atb":[[1.33,0]],"id":70003365}],"con":true,"img":false}]}
{"op":"mcm","clk":"11449664345","pt":1717313149462,"mc":[{"id":"1.229554891","rc":[{"atl":[[6.2,8.24]],"id":70003365}],"con":true,"img":false}]}
{"op":"mcm","clk":"11449664348","pt":1717313149562,"mc":[{"id":"1.229554891","rc":[{"atl":[[6,6.54]],"id":70003365}],"con":true,"img":false}]}
{"op":"mcm","clk":"11449664351","pt":1717313149664,"mc":[{"id":"1.229554891","rc":[{"atl":[[6.4,0]],"id":70003365}],"con":true,"img":false}]}
{"op":"mcm","clk":"11449664384","pt":1717313150855,"mc":[{"id":"1.229554891","rc":[{"atl":[[4.3,0],[4.2,27.84]],"id":70003364}],"con":true,"img":false}]}
{"op":"mcm","clk":"11449664387","pt":1717313150956,"mc":[{"id":"1.229554891","rc":[{"atl":[[4.5,28.57],[4.2,11.62]],"id":70003364}],"con":true,"img":false}]}
{"op":"mcm","clk":"11449664393","pt":1717313151059,"mc":[{"id":"1.229554891","rc":[{"atl":[[4.5,0],[4.2,27.84]],"id":70003364}],"con":true,"img":false}]}
{"op":"mcm","clk":"11449664981","pt":1717313164450,"mc":[{"id":"1.229554891","rc":[{"atl":[[6,15.21]],"id":70003367}],"con":true,"img":false}]}
{"op":"mcm","clk":"11449665020","pt":1717313165587,"mc":[{"id":"1.229554891","rc":[{"atb":[[5.8,7.26],[7.6,10.49]],"id":70003366},{"atb":[[1.41,56.65],[1.31,112.39]],"id":70003367},{"atl":[[4.1,0.16]],"id":70003367},{"atb":[[1.01,5807.26]],"id":70003364},{"atl":[[2.72,0.3]],"id":70003364},{"atb":[[1.4,58.07],[1.3,160.2]],"id":70003365},{"atl":[[4,0.17]],"id":70003365},{"atb":[[3.45,14.21],[3.95,7.87]],"id":70003363}],"con":true,"img":false}]}
{"op":"mcm","clk":"11449665631","pt":1717313179487,"mc":[{"id":"1.229554891","rc":[{"atb":[[1.32,13.31]],"id":70003367}],"con":true,"img":false}]}
{"op":"mcm","clk":"11449665637","pt":1717313179594,"mc":[{"id":"1.229554891","rc":[{"atb":[[1.42,10.14]],"id":70003365}],"con":true,"img":false}]}
{"op":"mcm","clk":"11449665654","pt":1717313179960,"mc":[{"id":"1.229554891","rc":[{"atb":[[1.42,0]],"id":70003367}],"con":true,"img":false}]}
{"op":"mcm","clk":"11449665667","pt":1717313180168,"mc":[{"id":"1.229554891","rc":[{"atb":[[1.43,9.12]],"id":70003367}],"con":true,"img":false}]}
{"op":"mcm","clk":"11449666142","pt":1717313191808,"mc":[{"id":"1.229554891","rc":[{"atb":[[4.5,21.03],[5.5,0]],"id":70003366},{"atb":[[2,32.2],[2.3,0]],"id":70003363}],"con":true,"img":false}]}
{"op":"mcm","clk":"11449666540","pt":1717313200202,"mc":[{"id":"1.229554891","rc":[{"atb":[[1.26,0]],"id":70003367}],"con":true,"img":false}]}
{"op":"mcm","clk":"11449666544","pt":1717313200306,"mc":[{"id":"1.229554891","rc":[{"atb":[[1.32,62.55]],"id":70003367}],"con":true,"img":false}]}
{"op":"mcm","clk":"11449666589","pt":1717313201237,"mc":[{"id":"1.229554891","rc":[{"atb":[[1.3,116.14]],"id":70003365}],"con":true,"img":false}]}
{"op":"mcm","clk":"11449666597","pt":1717313201334,"mc":[{"id":"1.229554891","rc":[{"atb":[[1.41,44.05]],"id":70003365}],"con":true,"img":false}]}
{"op":"mcm","clk":"11449666804","pt":1717313205516,"mc":[{"id":"1.229554891","rc":[{"spn":2.76,"spf":"NaN","id":70003367},{"spn":1.93,"spf":"NaN","id":70003364},{"atl":[[6.2,0]],"id":70003365},{"spn":2.72,"spf":"NaN","id":70003365},{"spn":25.97,"spf":"NaN","id":70003363}],"con":true,"img":false}]}
{"op":"mcm","clk":"11449666815","pt":1717313205720,"mc":[{"id":"1.229554891","rc":[{"atl":[[6.4,8.24]],"id":70003365}],"con":true,"img":false}]}
{"op":"mcm","clk":"11449667056","pt":1717313210240,"mc":[{"id":"1.229554891","rc":[{"atb":[[1.45,0]],"id":70003365}],"con":true,"img":false}]}
{"op":"mcm","clk":"11449667333","pt":1717313215404,"mc":[{"id":"1.229554891","rc":[{"atb":[[5.8,0],[7.6,6.97]],"id":70003366},{"atb":[[1.41,0],[1.31,0]],"id":70003367},{"atl":[[4.1,0]],"id":70003367},{"atb":[[1.01,0]],"id":70003364},{"atl":[[2.72,0]],"id":70003364},{"atb":[[1.4,0],[1.3,0]],"id":70003365},{"atl":[[4,0]],"id":70003365},{"atb":[[3.45,0],[3.95,0]],"id":70003363}],"con":true,"img":false}]}
{"op":"mcm","clk":"11449667339","pt":1717313215510,"mc":[{"id":"1.229554891","rc":[{"atl":[[6.2,13.08],[6,0]],"id":70003365}],"con":true,"img":false}]}
{"op":"mcm","clk":"11449667351","pt":1717313215726,"mc":[{"id":"1.229554891","rc":[{"atb":[[1.32,13.31]],"id":70003367},{"atb":[[1.41,0]],"id":70003365}],"con":true,"img":false}]}
{"op":"mcm","clk":"11449667357","pt":1717313215831,"mc":[{"id":"1.229554891","rc":[{"atb":[[1.27,49.24]],"id":70003367},{"atb":[[1.3,44.05]],"id":70003365}],"con":true,"img":false}]}
{"op":"mcm","clk":"11449667485","pt":1717313218309,"mc":[{"id":"1.229554891","rc":[{"atb":[[1.32,0]],"id":70003367},{"atb":[[1.42,0]],"id":70003365}],"con":true,"img":false}]}
{"op":"mcm","clk":"11449667501","pt":1717313218623,"mc":[{"id":"1.229554891","rc":[{"atl":[[6.6,0],[5.9,11.87]],"id":70003367}],"con":true,"img":false}]}
{"op":"mcm","clk":"11449667510","pt":1717313218724,"mc":[{"id":"1.229554891","rc":[{"atl":[[5.8,11.88],[6,8.24]],"id":70003367}],"con":true,"img":false}]}
{"op":"mcm","clk":"11449667534","pt":1717313219653,"mc":[{"id":"1.229554891","rc":[{"atl":[[6.8,0],[6,10.3]],"id":70003365}],"con":true,"img":false}]}
{"op":"mcm","clk":"11449667538","pt":1717313219704,"mc":[{"id":"1.229554891","rc":[{"atl":[[6.2,0],[5.9,10.31]],"id":70003365}],"con":true,"img":false}]}
{"op":"mcm","clk":"11449667645","pt":1717313221526,"mc":[{"id":"1.229554891","rc":[{"atl":[[4.8,0],[4.1,19.88]],"id":70003364}],"con":true,"img":false}]}
{"op":"mcm","clk":"11449667794","pt":1717313225126,"mc":[{"id":"1.229554891","rc":[{"atb":[[1.31,12.66]],"id":70003365}],"con":true,"img":false}]}
{"op":"mcm","clk":"11449667799","pt":1717313225226,"mc":[{"id":"1.229554891","rc":[{"atb":[[1.43,0]],"id":70003367}],"con":true,"img":false}]}
{"op":"mcm","clk":"11449668009","pt":1717313229956,"mc":[{"id":"1.229554891","rc":[{"atb":[[5.3,8.1],[6.6,14.68]],"id":70003366},{"atb":[[1.32,108.88],[1.42,55.3]],"id":70003367},{"atl":[[4.1,0.16]],"id":70003367},{"atb":[[1.01,5807.26]],"id":70003364},{"atl":[[2.68,0.31]],"id":70003364},{"atb":[[1.45,51.62],[1.35,99.55]],"id":70003365},{"atl":[[4.2,0.16]],"id":70003365},{"atb":[[3.45,14.21],[3.95,7.87]],"id":70003363}],"con":true,"img":false}]}
{"op":"mcm","clk":"11449668039","pt":1717313230327,"mc":[{"id":"1.229554891","rc":[{"atl":[[6,0]],"id":70003365}],"con":true,"img":false}]}
{"op":"mcm","clk":"11449668044","pt":1717313230430,"mc":[{"id":"1.229554891","rc":[{"atl":[[6.2,10.3]],"id":70003365}],"con":true,"img":false}]}
{"op":"mcm","clk":"11449668316","pt":1717313235752,"mc":[{"id":"1.229554891","rc":[{"atl":[[6.4,0]],"id":70003365}],"con":true,"img":false}]}
{"op":"mcm","clk":"11449668349","pt":1717313236164,"mc":[{"id":"1.229554891","rc":[{"atl":[[6.8,6.81]],"id":70003365}],"con":true,"img":false}]}
{"op":"mcm","clk":"11449668358","pt":1717313236272,"mc":[{"id":"1.229554891","rc":[{"atl":[[6.2,0]],"id":70003365}],"con":true,"img":false}]}
{"op":"mcm","clk":"11449668367","pt":1717313236367,"mc":[{"id":"1.229554891","rc":[{"atl":[[6.8,17.11]],"id":70003365}],"con":true,"img":false}]}
{"op":"mcm","clk":"11449668596","pt":1717313240738,"mc":[{"id":"1.229554891","rc":[{"atb":[[1.31,0]],"id":70003365}],"con":true,"img":false}]}
{"op":"mcm","clk":"11449668599","pt":1717313240843,"mc":[{"id":"1.229554891","rc":[{"atb":[[1.44,8.91]],"id":70003367}],"con":true,"img":false}]}
{"op":"mcm","clk":"11449668636","pt":1717313241266,"mc":[{"id":"1.229554891","rc":[{"atb":[[1.47,8.35]],"id":70003365}],"con":true,"img":false}]}
{"op":"mcm","clk":"11449669251","pt":1717313254569,"mc":[{"id":"1.229554891","rc":[{"atb":[[1.33,12.91]],"id":70003367}],"con":true,"img":false}]}
{"op":"mcm","clk":"11449669265","pt":1717313254980,"mc":[{"id":"1.229554891","rc":[{"atb":[[1.36,11.83]],"id":70003365}],"con":true,"img":false}]}
{"op":"mcm","clk":"11449669624","pt":1717313263076,"mc":[{"id":"1.229554891","rc":[{"atl":[[6.2,0]],"id":70003367}],"con":true,"img":false}]}
{"op":"mcm","clk":"11449669634","pt":1717313263179,"mc":[{"id":"1.229554891","rc":[{"atl":[[5.6,6.97]],"id":70003367}],"con":true,"img":false}]}
{"op":"mcm","clk":"11449669643","pt":1717313263277,"mc":[{"id":"1.229554891","rc":[{"atl":[[5.5,11.88]],"id":70003367}],"con":true,"img":false}]}
{"op":"mcm","clk":"11449669652","pt":1717313263384,"mc":[{"id":"1.229554891","rc":[{"atl":[[5.8,0]],"id":70003367}],"con":true,"img":false}]}
{"op":"mcm","clk":"11449669721","pt":1717313264413,"mc":[{"id":"1.229554891","rc":[{"atb":[[1.27,0]],"id":70003367},{"atb":[[1.3,0]],"id":70003365}],"con":true,"img":false}]}
{"op":"mcm","clk":"11449669727","pt":1717313264459,"mc":[{"id":"1.229554891","rc":[{"atb":[[1.33,62.15]],"id":70003367},{"atb":[[1.36,55.89]],"id":70003365}],"con":true,"img":false}]}
{"op":"mcm","clk":"11449670104","pt":1717313273012,"mc":[{"id":"1.229554891","rc":[{"atb":[[5.3,0],[6.6,10.53]],"id":70003366},{"atb":[[1.32,0],[1.42,0]],"id":70003367},{"atl":[[4.1,0]],"id":70003367},{"spn":3.47,"spf":"NaN","id":70003367},{"atb":[[1.01,0]],"id":70003364},{"atl":[[2.68,0]],"id":70003364},{"spn":2.62,"spf":"NaN","id":70003364},{"atb":[[1.45,0],[1.35,0]],"id":70003365},{"atl":[[4.2,0]],"id":70003365},{"spn":3.68,"spf":"NaN","id":70003365},{"atb":[[3.45,0],[3.95,0]],"id":70003363},{"spn":25.77,"spf":"NaN","id":70003363}],"con":true,"img":false}]}
{"op":"mcm","clk":"11449670111","pt":1717313273218,"mc":[{"id":"1.229554891","rc":[{"atb":[[1.33,12.91]],"id":70003367},{"atb":[[1.36,11.83]],"id":70003365},{"atl":[[6.4,18.52],[5.9,0]],"id":70003365}],"con":true,"img":false}]}
{"op":"mcm","clk":"11449670116","pt":1717313273274,"mc":[{"id":"1.229554891","rc":[{"atb":[[1.27,49.24]],"id":70003367},{"atb":[[1.3,44.05]],"id":70003365},{"atl":[[6.8,10.3]],"id":70003365}],"con":true,"img":false}]}
{"op":"mcm","clk":"11449670132","pt":1717313273588,"mc":[{"id":"1.229554891","rc":[{"atl":[[6.8,18.54]],"id":70003365}],"con":true,"img":false}]}
{"op":"mcm","clk":"11449670993","pt":1717313290214,"mc":[{"id":"1.229554891","rc":[{"atl":[[6.8,8.24]],"id":70003365}],"con":true,"img":false}]}
{"op":"mcm","clk":"11449670997","pt":1717313290317,"mc":[{"id":"1.229554891","rc":[{"atl":[[6.2,10.3]],"id":70003365}],"con":true,"img":false}]}
{"op":"mcm","clk":"11449671001","pt":1717313290420,"mc":[{"id":"1.229554891","rc":[{"atl":[[6,10.31]],"id":70003365}],"con":true,"img":false}]}
{"op":"mcm","clk":"11449671004","pt":1717313290523,"mc":[{"id":"1.229554891","rc":[{"atl":[[6.4,0]],"id":70003365}],"con":true,"img":false}]}
{"op":"mcm","clk":"11449671034","pt":1717313291048,"mc":[{"id":"1.229554891","rc":[{"atb":[[7.4,3.63],[5.7,7.41]],"id":70003366},{"atb":[[1.32,108.88],[1.42,55.3]],"id":70003367},{"atl":[[4.1,0.16]],"id":70003367},{"atb":[[1.01,5807.26]],"id":70003364},{"atl":[[2.68,0.31]],"id":70003364},{"atb":[[1.43,54.02],[1.33,105.58]],"id":70003365},{"atl":[[4.1,0.16]],"id":70003365},{"atb":[[4,7.74],[3.5,13.93]],"id":70003363}],"con":true,"img":false}]}
{"op":"mcm","clk":"11449671058","pt":1717313291304,"mc":[{"id":"1.229554891","rc":[{"atl":[[6.8,0]],"id":70003365}],"con":true,"img":false}]}
{"op":"mcm","clk":"11449671069","pt":1717313291509,"mc":[{"id":"1.229554891","rc":[{"atl":[[6.8,6.45]],"id":70003365}],"con":true,"img":false}]}
{"op":"mcm","clk":"11449671107","pt":1717313292127,"mc":[{"id":"1.229554891","rc":[{"atb":[[7.6,0]],"id":70003366},{"atl":[[4.2,16.22]],"id":70003364},{"atl":[[6.2,0]],"id":70003365}],"con":true,"img":false}]}
{"op":"mcm","clk":"11449671116","pt":1717313292232,"mc":[{"id":"1.229554891","rc":[{"atb":[[8,6.97]],"id":70003366},{"atl":[[3.85,11.62]],"id":70003364},{"atl":[[6.6,16.84]],"id":70003365}],"con":true,"img":false}]}
{"op":"mcm","clk":"11449671137","pt":1717313292539,"mc":[{"id":"1.229554891","rc":[{"atb":[[1.33,0]],"id":70003367},{"atb":[[1.36,0]],"id":70003365}],"con":true,"img":false}]}
{"op":"mcm","clk":"11449672413","pt":1717313318946,"mc":[{"id":"1.229554891","rc":[{"atb":[[6.6,0]],"id":70003366},{"atl":[[6.6,10.3]],"id":70003365},{"atl":[[48,0]],"id":70003363}],"con":true,"img":false}]}
{"op":"mcm","clk":"11449672421","pt":1717313319047,"mc":[{"id":"1.229554891","rc":[{"atb":[[7,10.53]],"id":70003366},{"atl":[[6,16.84]],"id":70003365},{"atl":[[44,2.61]],"id":70003363}],"con":true,"img":false}]}
{"op":"mcm","clk":"11449672428","pt":1717313319149,"mc":[{"id":"1.229554891","rc":[{"atl":[[44,4.94],[50,2.61]],"id":70003363}],"con":true,"img":false}]}
{"op":"mcm","clk":"11449672847","pt":1717313326247,"mc":[{"id":"1.229554891","rc":[{"atb":[[1.27,0]],"id":70003367},{"atb":[[1.3,0]],"id":70003365}],"con":true,"img":false}]}
{"op":"mcm","clk":"11449672855","pt":1717313326349,"mc":[{"id":"1.229554891","rc":[{"atb":[[1.33,49.24]],"id":70003367},{"atb":[[1.44,44.05]],"id":70003365}],"con":true,"img":false}]}
{"op":"mcm","clk":"11449673040","pt":1717313329237,"mc":[{"id":"1.229554891","rc":[{"atb":[[1.34,12.53]],"id":70003365}],"con":true,"img":false}]}
{"op":"mcm","clk":"11449673056","pt":1717313329441,"mc":[{"id":"1.229554891","rc":[{"atb":[[7.4,0],[5.7,0]],"id":70003366},{"atb":[[1.32,0],[1.42,0]],"id":70003367},{"atl":[[4.1,0]],"id":70003367},{"atb":[[1.01,0]],"id":70003364},{"atl":[[2.68,0]],"id":70003364},{"atb":[[1.43,0],[1.33,0]],"id":70003365},{"atl":[[4.1,0]],"id":70003365},{"atb":[[4,0],[3.5,0]],"id":70003363}],"con":true,"img":false}]}
{"op":"mcm","clk":"11449673061","pt":1717313329596,"mc":[{"id":"1.229554891","rc":[{"atl":[[6.8,0]],"id":70003365}],"con":true,"img":false}]}
{"op":"mcm","clk":"11449673069","pt":1717313329752,"mc":[{"id":"1.229554891","rc":[{"atl":[[6.8,8.81]],"id":70003365}],"con":true,"img":false}]}
{"op":"mcm","clk":"11449673077","pt":1717313329854,"mc":[{"id":"1.229554891","rc":[{"atb":[[1.33,62.15]],"id":70003367}],"con":true,"img":false}]}
{"op":"mcm","clk":"11449673083","pt":1717313329956,"mc":[{"id":"1.229554891","rc":[{"atb":[[1.33,12.91]],"id":70003367},{"atb":[[1.44,0]],"id":70003365}],"con":true,"img":false}]}
{"op":"mcm","clk":"11449673090","pt":1717313330059,"mc":[{"id":"1.229554891","rc":[{"atb":[[1.27,49.24]],"id":70003367},{"atb":[[1.3,44.05]],"id":70003365}],"con":true,"img":false}]}
{"op":"mcm","clk":"11449673642","pt":1717313340501,"mc":[{"id":"1.229554891","rc":[{"atb":[[6.2,6.7],[8.2,3.22]],"id":70003366},{"spn":89.1,"spf":"NaN","id":70003366},{"atb":[[1.43,54.02],[1.33,118.49]],"id":70003367},{"atl":[[4.1,0.16]],"id":70003367},{"spn":2.77,"spf":"NaN","id":70003367},{"atb":[[1.01,5807.26]],"id":70003364},{"atl":[[2.66,0.31]],"id":70003364},{"spn":1.9,"spf":"NaN","id":70003364},{"atb":[[1.32,108.88],[1.42,55.3]],"id":70003365},{"atl":[[4.1,0.16]],"id":70003365},{"spn":2.78,"spf":"NaN","id":70003365},{"atb":[[3.45,14.21],[3.95,7.87]],"id":70003363},{"spn":23.97,"spf":"NaN","id":70003363}],"con":true,"img":false}]}
{"op":"mcm","clk":"11449673675","pt":1717313340972,"mc":[{"id":"1.229554891","rc":[{"atl":[[6.8,0]],"id":70003365}],"con":true,"img":false}]}
{"op":"mcm","clk":"11449673688","pt":1717313341178,"mc":[{"id":"1.229554891","rc":[{"atl":[[6.8,6.45]],"id":70003365}],"con":true,"img":false}]}
{"op":"mcm","clk":"11449674052","pt":1717313346692,"mc":[{"id":"1.229554891","rc":[{"atb":[[1.44,0]],"id":70003367},{"atb":[[1.47,0]],"id":70003365}],"con":true,"img":false}]}
{"op":"mcm","clk":"11449674891","pt":1717313361417,"mc":[{"id":"1.229554891","rc":[{"atb":[[1.44,8.91]],"id":70003365}],"con":true,"img":false}]}
{"op":"mcm","clk":"11449674901","pt":1717313361520,"mc":[{"id":"1.229554891","rc":[{"atb":[[1.45,8.72]],"id":70003367}],"con":true,"img":false}]}
{"op":"mcm","clk":"11449675176","pt":1717313366418,"mc":[{"id":"1.229554891","rc":[{"atb":[[1.33,105.58]],"id":70003367},{"atb":[[1.34,0]],"id":70003365}],"con":true,"img":false}]}
{"op":"mcm","clk":"11449675535","pt":1717313372414,"mc":[{"id":"1.229554891","rc":[{"atl":[[50,0]],"id":70003363}],"con":true,"img":false}]}
{"op":"mcm","clk":"11449675541","pt":1717313372509,"mc":[{"id":"1.229554891","rc":[{"atl":[[42,2.61]],"id":70003363}],"con":true,"img":false}]}
{"op":"mcm","clk":"11449675747","pt":1717313375515,"mc":[{"id":"1.229554891","rc":[{"atb":[[1.27,0]],"id":70003367}],"con":true,"img":false}]}
{"op":"mcm","clk":"11449675754","pt":1717313375618,"mc":[{"id":"1.229554891","rc":[{"atb":[[1.34,49.24]],"id":70003367}],"con":true,"img":false}]}
{"op":"mcm","clk":"11449675808","pt":1717313376493,"mc":[{"id":"1.229554891","rc":[{"atb":[[1.3,0]],"id":70003365}],"con":true,"img":false}]}
{"op":"mcm","clk":"11449675817","pt":1717313376596,"mc":[{"id":"1.229554891","rc":[{"atb":[[1.43,44.05]],"id":70003365}],"con":true,"img":false}]}
{"op":"mcm","clk":"11449676729","pt":1717313392230,"mc":[{"id":"1.229554891","rc":[{"atb":[[1.44,0]],"id":70003365}],"con":true,"img":false}]}
{"op":"mcm","clk":"11449676745","pt":1717313392435,"mc":[{"id":"1.229554891","rc":[{"atb":[[1.45,8.72]],"id":70003365}],"con":true,"img":false}]}
{"op":"mcm","clk":"11449676858","pt":1717313394142,"mc":[{"id":"1.229554891","rc":[{"atb":[[3.55,0]],"id":70003363}],"con":true,"img":false}]}
{"op":"mcm","clk":"11449676865","pt":1717313394244,"mc":[{"id":"1.229554891","rc":[{"atb":[[3.6,16.09]],"id":70003363}],"con":true,"img":false}]}
{"op":"mcm","clk":"11449676924","pt":1717313395120,"mc":[{"id":"1.229554891","rc":[{"atb":[[3.35,0],[3.5,21.13]],"id":70003363}],"con":true,"img":false}]}
{"op":"mcm","clk":"11449676979","pt":1717313396450,"mc":[{"id":"1.229554891","rc":[{"atl":[[6.8,0]],"id":70003365}],"con":true,"img":false}]}
{"op":"mcm","clk":"11449676991","pt":1717313396608,"mc":[{"id":"1.229554891","rc":[{"atl":[[6.6,18.54]],"id":70003365}],"con":true,"img":false}]}
{"op":"mcm","clk":"11449677404","pt":1717313402346,"mc":[{"id":"1.229554891","rc":[{"spn":2.77,"spf":"NaN","id":70003367},{"atl":[[6.6,10.3]],"id":70003365},{"spn":2.77,"spf":"NaN","id":70003365},{"spn":22.97,"spf":"NaN","id":70003363}],"con":true,"img":false}]}
{"op":"mcm","clk":"11449677648","pt":1717313404745,"mc":[{"id":"1.229554891","rc":[{"atb":[[1.33,12.91]],"id":70003365}],"con":true,"img":false}]}
{"op":"mcm","clk":"11449677655","pt":1717313404845,"mc":[{"id":"1.229554891","rc":[{"atb":[[1.34,61.77]],"id":70003367}],"con":true,"img":false}]}
{"op":"mcm","clk":"11449681292","pt":1717313457552,"mc":[{"id":"1.229554891","rc":[{"atb":[[3.6,0]],"id":70003363}],"con":true,"img":false}]}
{"op":"mcm","clk":"11449681302","pt":1717313457658,"mc":[{"id":"1.229554891","rc":[{"atb":[[4,16.09]],"id":70003363}],"con":true,"img":false}]}
{"op":"mcm","clk":"11449683381","pt":1717313483313,"mc":[{"id":"1.229554891","rc":[{"atb":[[1.23,0]],"id":70003367},{"spn":23.0,"spf":"NaN","id":70003363}],"con":true,"img":false}]}
{"op":"mcm","clk":"11449683391","pt":1717313483358,"mc":[{"id":"1.229554891","rc":[{"atb":[[1.25,253.06]],"id":70003367}],"con":true,"img":false}]}
{"op":"mcm","clk":"11449683693","pt":1717313486868,"mc":[{"id":"1.229554891","rc":[{"atb":[[2,0],[2.1,30.32]],"id":70003363}],"con":true,"img":false}]}
{"op":"mcm","clk":"11449688532","pt":1717313544962,"mc":[{"id":"1.229554891","rc":[{"atl":[[6,0]],"id":70003367}],"con":true,"img":false}]}
{"op":"mcm","clk":"11449688548","pt":1717313545160,"mc":[{"id":"1.229554891","rc":[{"atl":[[6,4.83]],"id":70003367},{"atl":[[6.4,5.75]],"id":70003365}],"con":true,"img":false}]}
{"op":"mcm","clk":"11449688737","pt":1717313547380,"mc":[{"id":"1.229554891","rc":[{"atl":[[6.4,0]],"id":70003365}],"con":true,"img":false}]}
{"op":"mcm","clk":"11449703751","pt":1717313733733,"mc":[{"id":"1.229554891","rc":[{"atb":[[6.2,0],[8.2,0]],"id":70003366},{"spn":89.0,"spf":"NaN","id":70003366},{"atb":[[1.43,0],[1.33,0]],"id":70003367},{"atl":[[4.1,0]],"id":70003367},{"spn":3.47,"spf":"NaN","id":70003367},{"atb":[[1.01,0]],"id":70003364},{"atl":[[2.66,0]],"id":70003364},{"spn":2.49,"spf":"NaN","id":70003364},{"atb":[[1.32,0],[1.42,0]],"id":70003365},{"atl":[[4.1,0]],"id":70003365},{"spn":3.72,"spf":"NaN","id":70003365},{"atb":[[3.45,0],[3.95,0]],"id":70003363}],"con":true,"img":false}]}
{"op":"mcm","clk":"11449703767","pt":1717313733941,"mc":[{"id":"1.229554891","rc":[{"atb":[[1.34,12.53]],"id":70003367},{"atb":[[1.43,0]],"id":70003365},{"atb":[[4,0],[3.5,0]],"id":70003363}],"con":true,"img":false}]}
{"op":"mcm","clk":"11449703776","pt":1717313733995,"mc":[{"id":"1.229554891","rc":[{"atb":[[1.28,49.24]],"id":70003367},{"atb":[[1.31,44.05]],"id":70003365},{"atb":[[3.3,21.13],[1.65,60.64],[2.1,0],[3.65,16.09]],"id":70003363}],"con":true,"img":false}]}
{"op":"mcm","clk":"11449703851","pt":1717313734928,"mc":[{"id":"1.229554891","rc":[{"atl":[[6.8,4.82]],"id":70003365}],"con":true,"img":false}]}
{"op":"mcm","clk":"11449705303","pt":1717313752774,"mc":[{"id":"1.229554891","rc":[{"atb":[[5.8,7.26],[7.6,3.52]],"id":70003366},{"atb":[[1.45,60.34],[1.35,99.55]],"id":70003367},{"atl":[[4.2,0.16]],"id":70003367},{"atb":[[1.01,5807.26]],"id":70003364},{"atl":[[2.66,0.31]],"id":70003364},{"atb":[[1.41,56.65],[1.31,156.45]],"id":70003365},{"atl":[[4.1,0.16]],"id":70003365},{"atb":[[4,7.74],[3.5,13.93]],"id":70003363}],"con":true,"img":false}]}
{"op":"mcm","clk":"11449705381","pt":1717313753751,"mc":[{"id":"1.229554891","rc":[{"atl":[[6.8,0]],"id":70003365}],"con":true,"img":false}]}
{"op":"mcm","clk":"11449705404","pt":1717313754013,"mc":[{"id":"1.229554891","rc":[{"atl":[[6.6,15.12]],"id":70003365}],"con":true,"img":false}]}
{"op":"mcm","clk":"11449705480","pt":1717313754937,"mc":[{"id":"1.229554891","rc":[{"atb":[[1.45,51.62]],"id":70003367}],"con":true,"img":false}]}
{"op":"mcm","clk":"11449705495","pt":1717313755141,"mc":[{"id":"1.229554891","rc":[{"atb":[[1.47,8.35]],"id":70003367}],"con":true,"img":false}]}
{"op":"mcm","clk":"11449706091","pt":1717313762462,"mc":[{"id":"1.229554891","rc":[{"atb":[[1.65,0],[2.1,34.76]],"id":70003363}],"con":true,"img":false}]}
{"op":"mcm","clk":"11449706455","pt":1717313766754,"mc":[{"id":"1.229554891","rc":[{"atb":[[5.5,14.96]],"id":70003366}],"con":true,"img":false}]}
{"op":"mcm","clk":"11449706463","pt":1717313766856,"mc":[{"id":"1.229554891","rc":[{"atb":[[4.5,0]],"id":70003366}],"con":true,"img":false}]}
{"op":"mcm","clk":"11449706943","pt":1717313772259,"mc":[{"id":"1.229554891","rc":[{"atb":[[1.34,0]],"id":70003367},{"atb":[[1.33,0]],"id":70003365}],"con":true,"img":false}]}
{"op":"mcm","clk":"11449708292","pt":1717313787700,"mc":[{"id":"1.229554891","rc":[{"atb":[[1.28,0]],"id":70003367},{"atb":[[1.31,112.39]],"id":70003365}],"con":true,"img":false}]}
{"op":"mcm","clk":"11449708302","pt":1717313787804,"mc":[{"id":"1.229554891","rc":[{"atb":[[1.36,49.24]],"id":70003367},{"atb":[[1.42,44.05]],"id":70003365}],"con":true,"img":false}]}
{"op":"mcm","clk":"11449708483","pt":1717313790021,"mc":[{"id":"1.229554891","rc":[{"atb":[[3.65,0]],"id":70003363}],"con":true,"img":false}]}
{"op":"mcm","clk":"11449708493","pt":1717313790123,"mc":[{"id":"1.229554891","rc":[{"atb":[[3.7,16.09]],"id":70003363}],"con":true,"img":false}]}
{"op":"mcm","clk":"11449708641","pt":1717313791733,"mc":[{"id":"1.229554891","rc":[{"atb":[[4.5,14.52],[5.5,0]],"id":70003366}],"con":true,"img":false}]}
{"op":"mcm","clk":"11449710043","pt":1717313807607,"mc":[{"id":"1.229554891","rc":[{"spn":2.83,"spf":"NaN","id":70003367},{"spn":1.9,"spf":"NaN","id":70003364},{"spn":2.77,"spf":"NaN","id":70003365},{"atb":[[3.3,0]],"id":70003363}],"con":true,"img":false}]}
{"op":"mcm","clk":"11449710053","pt":1717313807712,"mc":[{"id":"1.229554891","rc":[{"atb":[[3.55,21.13]],"id":70003363}],"con":true,"img":false}]}
{"op":"mcm","clk":"11449710139","pt":1717313808941,"mc":[{"id":"1.229554891","rc":[{"atb":[[1.32,13.31]],"id":70003365}],"con":true,"img":false}]}
{"op":"mcm","clk":"11449710157","pt":1717313809099,"mc":[{"id":"1.229554891","rc":[{"atb":[[1.36,61.07]],"id":70003367}],"con":true,"img":false}]}
{"op":"mcm","clk":"11449710168","pt":1717313809201,"mc":[{"id":"1.229554891","rc":[{"atb":[[1.45,0]],"id":70003365}],"con":true,"img":false}]}
{"op":"mcm","clk":"11449710670","pt":1717313815038,"mc":[{"id":"1.229554891","rc":[{"atb":[[1.44,8.91]],"id":70003365}],"con":true,"img":false}]}
{"op":"mcm","clk":"11449721844","pt":1717313941132,"mc":[{"id":"1.229554891","rc":[{"atb":[[4.5,0],[5.5,14.23]],"id":70003366},{"spn":2.77,"spf":"NaN","id":70003365}],"con":true,"img":false}]}
{"op":"mcm","clk":"11449722092","pt":1717313943556,"mc":[{"id":"1.229554891","rc":[{"atb":[[5.5,0]],"id":70003366}],"con":true,"img":false}]}
{"op":"mcm","clk":"11449722100","pt":1717313943656,"mc":[{"id":"1.229554891","rc":[{"atb":[[4.5,14.23]],"id":70003366}],"con":true,"img":false}]}
{"op":"mcm","clk":"11449724630","pt":1717313969940,"mc":[{"id":"1.229554891","rc":[{"atb":[[4.5,0],[5.5,14.23]],"id":70003366}],"con":true,"img":false}]}
{"op":"mcm","clk":"11449731113","pt":1717314036731,"mc":[{"id":"1.229554891","rc":[{"atb":[[4.5,14.52],[5.5,0]],"id":70003366}],"con":true,"img":false}]}
{"op":"mcm","clk":"11449731577","pt":1717314041211,"mc":[{"id":"1.229554891","rc":[{"atb":[[4.5,0],[5.5,14.23]],"id":70003366}],"con":true,"img":false}]}
{"op":"mcm","clk":"11449735916","pt":1717314087299,"mc":[{"id":"1.229554891","rc":[{"atb":[[4.5,14.52],[5.5,0]],"id":70003366}],"con":true,"img":false}]}
{"op":"mcm","clk":"11449736699","pt":1717314096292,"mc":[{"id":"1.229554891","rc":[{"atb":[[5.8,0],[7.6,0]],"id":70003366},{"atb":[[1.45,0],[1.35,0]],"id":70003367},{"atl":[[4.2,0]],"id":70003367},{"atb":[[1.01,0]],"id":70003364},{"atl":[[2.66,0]],"id":70003364},{"atb":[[1.41,0],[1.31,0]],"id":70003365},{"atl":[[4.1,0]],"id":70003365},{"atb":[[4,0],[3.5,0]],"id":70003363}],"con":true,"img":false}]}
{"op":"mcm","clk":"11449736736","pt":1717314096708,"mc":[{"id":"1.229554891","rc":[{"atb":[[1.36,11.83]],"id":70003367},{"atb":[[1.42,0]],"id":70003365},{"atb":[[3.55,0]],"id":70003363}],"con":true,"img":false}]}
{"op":"mcm","clk":"11449736747","pt":1717314096812,"mc":[{"id":"1.229554891","rc":[{"atb":[[1.28,49.24]],"id":70003367},{"spn":3.48,"spf":"NaN","id":70003367},{"spn":2.49,"spf":"NaN","id":70003364},{"atb":[[1.31,44.05]],"id":70003365},{"spn":3.72,"spf":"NaN","id":70003365},{"atb":[[3.3,21.13]],"id":70003363},{"spn":22.85,"spf":"NaN","id":70003363}],"con":true,"img":false}]}
{"op":"mcm","clk":"11449736783","pt":1717314097175,"mc":[{"id":"1.229554891","rc":[{"atl":[[6.6,10.3]],"id":70003365}],"con":true,"img":false}]}
{"op":"mcm","clk":"11449736869","pt":1717314098225,"mc":[{"id":"1.229554891","rc":[{"atl":[[6.6,15.48]],"id":70003365}],"con":true,"img":false}]}
{"op":"mcm","clk":"11449736934","pt":1717314099007,"mc":[{"id":"1.229554891","rc":[{"atl":[[6.6,10.3]],"id":70003365}],"con":true,"img":false}]}
{"op":"mcm","clk":"11449737099","pt":1717314101019,"mc":[{"id":"1.229554891","rc":[{"atb":[[1.36,0]],"id":70003367},{"atb":[[1.32,0]],"id":70003365}],"con":true,"img":false}]}
{"op":"mcm","clk":"11449738100","pt":1717314112102,"mc":[{"id":"1.229554891","rc":[{"atb":[[5.5,17.51]],"id":70003366}],"con":true,"img":false}]}
{"op":"mcm","clk":"11449738112","pt":1717314112206,"mc":[{"id":"1.229554891","rc":[{"atb":[[4.5,0]],"id":70003366}],"con":true,"img":false}]}
{"op":"mcm","clk":"11449738237","pt":1717314113455,"mc":[{"id":"1.229554891","rc":[{"atb":[[7.8,3.41],[5.9,7.1]],"id":70003366},{"atb":[[1.41,56.65],[1.31,112.39]],"id":70003367},{"atl":[[4.1,0.16]],"id":70003367},{"atb":[[1.01,5807.26]],"id":70003364},{"atl":[[2.66,0.31]],"id":70003364},{"atb":[[1.37,94.17],[1.47,49.42]],"id":70003365},{"atl":[[4.3,0.15]],"id":70003365},{"atb":[[3.8,8.29],[3.3,36.28]],"id":70003363}],"con":true,"img":false}]}
{"op":"mcm","clk":"11449738300","pt":1717314114127,"mc":[{"id":"1.229554891","rc":[{"atb":[[5.5,0]],"id":70003366}],"con":true,"img":false}]}
{"op":"mcm","clk":"11449738308","pt":1717314114228,"mc":[{"id":"1.229554891","rc":[{"atb":[[4.5,14.22]],"id":70003366}],"con":true,"img":false}]}
{"op":"mcm","clk":"11449738325","pt":1717314114436,"mc":[{"id":"1.229554891","rc":[{"atl":[[6.6,16.05]],"id":70003365}],"con":true,"img":false}]}
{"op":"mcm","clk":"11449738549","pt":1717314116810,"mc":[{"id":"1.229554891","rc":[{"atb":[[1.44,0]],"id":70003365}],"con":true,"img":false}]}
{"op":"mcm","clk":"11449738567","pt":1717314117014,"mc":[{"id":"1.229554891","rc":[{"atb":[[1.49,8]],"id":70003365}],"con":true,"img":false}]}
{"op":"mcm","clk":"11449739303","pt":1717314124543,"mc":[{"id":"1.229554891","rc":[{"atl":[[6.6,10.3]],"id":70003365}],"con":true,"img":false}]}
{"op":"mcm","clk":"11449739331","pt":1717314124851,"mc":[{"id":"1.229554891","rc":[{"atl":[[6.4,5.75]],"id":70003365}],"con":true,"img":false}]}
{"op":"mcm","clk":"11449739420","pt":1717314125630,"mc":[{"id":"1.229554891","rc":[{"atl":[[6.4,0]],"id":70003365}],"con":true,"img":false}]}
{"op":"mcm","clk":"11449739460","pt":1717314126051,"mc":[{"id":"1.229554891","rc":[{"atl":[[6.6,16.07]],"id":70003365}],"con":true,"img":false}]}
{"op":"mcm","clk":"11449740432","pt":1717314136747,"mc":[{"id":"1.229554891","rc":[{"atb":[[5.5,14.08]],"id":70003366}],"con":true,"img":false}]}
{"op":"mcm","clk":"11449740439","pt":1717314136854,"mc":[{"id":"1.229554891","rc":[{"atb":[[4.5,0]],"id":70003366}],"con":true,"img":false}]}
{"op":"mcm","clk":"11449740869","pt":1717314141767,"mc":[{"id":"1.229554891","rc":[{"atb":[[3.4,1.77]],"id":70003363}],"con":true,"img":false}]}
{"op":"mcm","clk":"11449740886","pt":1717314141966,"mc":[{"id":"1.229554891","rc":[{"atb":[[1.32,13.31]],"id":70003367}],"con":true,"img":false}]}
{"op":"mcm","clk":"11449740898","pt":1717314142068,"mc":[{"id":"1.229554891","rc":[{"atb":[[1.38,11.21]],"id":70003365}],"con":true,"img":false}]}
{"op":"mcm","clk":"11449741124","pt":1717314144551,"mc":[{"id":"1.229554891","rc":[{"atb":[[4.5,14.22],[5.5,0]],"id":70003366}],"con":true,"img":false}]}
{"op":"mcm","clk":"11449741420","pt":1717314148466,"mc":[{"id":"1.229554891","rc":[{"atb":[[1.28,0]],"id":70003367}],"con":true,"img":false}]}
{"op":"mcm","clk":"11449741430","pt":1717314148570,"mc":[{"id":"1.229554891","rc":[{"atb":[[1.42,49.24]],"id":70003367}],"con":true,"img":false}]}
{"op":"mcm","clk":"11449741483","pt":1717314149340,"mc":[{"id":"1.229554891","rc":[{"atb":[[1.31,0]],"id":70003365}],"con":true,"img":false}]}
{"op":"mcm","clk":"11449741491","pt":1717314149445,"mc":[{"id":"1.229554891","rc":[{"atb":[[1.38,55.27]],"id":70003365}],"con":true,"img":false}]}
{"op":"mcm","clk":"11449741556","pt":1717314150273,"mc":[{"id":"1.229554891","rc":[{"atb":[[3.7,0]],"id":70003363}],"con":true,"img":false}]}
{"op":"mcm","clk":"11449741563","pt":1717314150374,"mc":[{"id":"1.229554891","rc":[{"atb":[[3.85,16.09]],"id":70003363}],"con":true,"img":false}]}
{"op":"mcm","clk":"11449741833","pt":1717314153599,"mc":[{"id":"1.229554891","rc":[{"atl":[[6.6,10.3]],"id":70003365}],"con":true,"img":false}]}
{"op":"mcm","clk":"11449741850","pt":1717314153752,"mc":[{"id":"1.229554891","rc":[{"atl":[[6.6,16.07]],"id":70003365}],"con":true,"img":false}]}
{"op":"mcm","clk":"11449743101","pt":1717314168785,"mc":[{"id":"1.229554891","rc":[{"atb":[[5.5,14.08]],"id":70003366},{"spn":2.78,"spf":"NaN","id":70003367},{"spn":1.9,"spf":"NaN","id":70003364},{"spn":2.89,"spf":"NaN","id":70003365},{"spn":22.92,"spf":"NaN","id":70003363}],"con":true,"img":false}]}
{"op":"mcm","clk":"11449743110","pt":1717314168887,"mc":[{"id":"1.229554891","rc":[{"atb":[[4.5,0]],"id":70003366}],"con":true,"img":false}]}
{"op":"mcm","clk":"11449743701","pt":1717314174979,"mc":[{"id":"1.229554891","rc":[{"atb":[[4.5,14.22],[5.5,0]],"id":70003366}],"con":true,"img":false}]}
{"op":"mcm","clk":"11449743724","pt":1717314175292,"mc":[{"id":"1.229554891","rc":[{"atb":[[1.47,0]],"id":70003367}],"con":true,"img":false}]}
{"op":"mcm","clk":"11449743855","pt":1717314176689,"mc":[{"id":"1.229554891","rc":[{"atb":[[1.44,8.91]],"id":70003367}],"con":true,"img":false}]}
{"op":"mcm","clk":"11449745808","pt":1717314198932,"mc":[{"id":"1.229554891","rc":[{"atb":[[4.5,0],[5.5,14.08]],"id":70003366}],"con":true,"img":false}]}
{"op":"mcm","clk":"11449746384","pt":1717314205241,"mc":[{"id":"1.229554891","rc":[{"atb":[[4.5,14.22],[5.5,0]],"id":70003366}],"con":true,"img":false}]}
{"op":"mcm","clk":"11449749384","pt":1717314236792,"mc":[{"id":"1.229554891","rc":[{"atb":[[4.5,0],[5.5,14.08]],"id":70003366},{"spn":2.77,"spf":"NaN","id":70003367}],"con":true,"img":false}]}
{"op":"mcm","clk":"11449752189","pt":1717314266148,"mc":[{"id":"1.229554891","rc":[{"atb":[[4.5,14.22],[5.5,0]],"id":70003366}],"con":true,"img":false}]}
{"op":"mcm","clk":"11449754101","pt":1717314289250,"mc":[{"id":"1.229554891","rc":[{"atb":[[4.5,0],[5.5,14.08]],"id":70003366}],"con":true,"img":false}]}
{"op":"mcm","clk":"11449754665","pt":1717314296572,"mc":[{"id":"1.229554891","rc":[{"atb":[[4.5,14.22],[5.5,0]],"id":70003366}],"con":true,"img":false}]}
{"op":"mcm","clk":"11449754778","pt":1717314297966,"mc":[{"id":"1.229554891","rc":[{"atb":[[4.5,0],[5.5,14.08]],"id":70003366}],"con":true,"img":false}]}
{"op":"mcm","clk":"11449757279","pt":1717314326920,"mc":[{"id":"1.229554891","rc":[{"atb":[[4.5,14.22],[5.5,0]],"id":70003366}],"con":true,"img":false}]}
{"op":"mcm","clk":"11449759192","pt":1717314349350,"mc":[{"id":"1.229554891","rc":[{"atb":[[5.5,14.08]],"id":70003366}],"con":true,"img":false}]}
{"op":"mcm","clk":"11449759203","pt":1717314349450,"mc":[{"id":"1.229554891","rc":[{"atb":[[4.5,0]],"id":70003366}],"con":true,"img":false}]}
{"op":"mcm","clk":"11449759888","pt":1717314357674,"mc":[{"id":"1.229554891","rc":[{"atb":[[4.5,14.22],[5.5,0]],"id":70003366}],"con":true,"img":false}]}
{"op":"mcm","clk":"11449761973","pt":1717314379910,"mc":[{"id":"1.229554891","rc":[{"atb":[[4.5,0],[5.5,14.08]],"id":70003366}],"con":true,"img":false}]}
{"op":"mcm","clk":"11449762785","pt":1717314387786,"mc":[{"id":"1.229554891","rc":[{"atb":[[4.5,14.22],[5.5,0]],"id":70003366}],"con":true,"img":false}]}
{"op":"mcm","clk":"11449766639","pt":1717314431677,"mc":[{"id":"1.229554891","rc":[{"atb":[[7.8,0],[5.9,0]],"id":70003366},{"atb":[[1.41,0],[1.31,0]],"id":70003367},{"atl":[[4.1,0]],"id":70003367},{"atb":[[1.01,0]],"id":70003364},{"atl":[[2.66,0]],"id":70003364},{"atb":[[1.37,0],[1.47,0]],"id":70003365},{"atl":[[4.3,0]],"id":70003365},{"atb":[[3.8,0],[3.3,21.13]],"id":70003363}],"con":true,"img":false}]}
{"op":"mcm","clk":"11449766697","pt":1717314432146,"mc":[{"id":"1.229554891","rc":[{"atb":[[1.42,0]],"id":70003367},{"atb":[[1.38,11.21]],"id":70003365},{"atb":[[3.85,0]],"id":70003363}],"con":true,"img":false}]}
{"op":"mcm","clk":"11449766710","pt":1717314432254,"mc":[{"id":"1.229554891","rc":[{"atb":[[1.28,49.24]],"id":70003367},{"atb":[[1.31,44.05]],"id":70003365},{"atb":[[3.65,16.09]],"id":70003363}],"con":true,"img":false}]}
{"op":"mcm","clk":"11449766734","pt":1717314432459,"mc":[{"id":"1.229554891","rc":[{"atl":[[6.6,10.3]],"id":70003365}],"con":true,"img":false}]}
{"op":"mcm","clk":"11449766750","pt":1717314432667,"mc":[{"id":"1.229554891","rc":[{"atl":[[6.6,12.31]],"id":70003365}],"con":true,"img":false}]}
{"op":"mcm","clk":"11449766823","pt":1717314433346,"mc":[{"id":"1.229554891","rc":[{"atl":[[6,0]],"id":70003367},{"atl":[[6.6,10.3]],"id":70003365}],"con":true,"img":false}]}
{"op":"mcm","clk":"11449766857","pt":1717314433658,"mc":[{"id":"1.229554891","rc":[{"atl":[[5.8,5.51]],"id":70003367},{"atl":[[6.6,12.38]],"id":70003365}],"con":true,"img":false}]}
{"op":"mcm","clk":"11449766869","pt":1717314433759,"mc":[{"id":"1.229554891","rc":[{"atl":[[6.6,10.3]],"id":70003365}],"con":true,"img":false}]}
{"op":"mcm","clk":"11449766890","pt":1717314434025,"mc":[{"id":"1.229554891","rc":[{"atl":[[5.8,0]],"id":70003367}],"con":true,"img":false}]}
{"op":"mcm","clk":"11449766937","pt":1717314434438,"mc":[{"id":"1.229554891","rc":[{"atl":[[5.7,1.86]],"id":70003367},{"atl":[[6.4,1.62]],"id":70003365}],"con":true,"img":false}]}
{"op":"mcm","clk":"11449766966","pt":1717314434747,"mc":[{"id":"1.229554891","rc":[{"atl":[[5.7,0]],"id":70003367},{"atl":[[6.4,0]],"id":70003365}],"con":true,"img":false}]}
{"op":"mcm","clk":"11449767016","pt":1717314435266,"mc":[{"id":"1.229554891","rc":[{"atl":[[5.6,11.87]],"id":70003367},{"atl":[[6.4,1.62]],"id":70003365}],"con":true,"img":false}]}
{"op":"mcm","clk":"11449767049","pt":1717314435573,"mc":[{"id":"1.229554891","rc":[{"atl":[[5.6,6.97]],"id":70003367}],"con":true,"img":false}]}
{"op":"mcm","clk":"11449767109","pt":1717314436246,"mc":[{"id":"1.229554891","rc":[{"atl":[[6.4,0]],"id":70003365}],"con":true,"img":false}]}
{"op":"mcm","clk":"11449767125","pt":1717314436450,"mc":[{"id":"1.229554891","rc":[{"atl":[[6.2,4.25]],"id":70003365}],"con":true,"img":false}]}
{"op":"mcm","clk":"11449767174","pt":1717314437065,"mc":[{"id":"1.229554891","rc":[{"atl":[[5.5,16.82]],"id":70003367}],"con":true,"img":false}]}
{"op":"mcm","clk":"11449767219","pt":1717314437529,"mc":[{"id":"1.229554891","rc":[{"atl":[[6.2,0]],"id":70003365}],"con":true,"img":false}]}
{"op":"mcm","clk":"11449767235","pt":1717314437735,"mc":[{"id":"1.229554891","rc":[{"atl":[[5.5,11.88]],"id":70003367}],"con":true,"img":false}]}
{"op":"mcm","clk":"11449767953","pt":1717314446185,"mc":[{"id":"1.229554891","rc":[{"atb":[[8,10.29],[6,6.96]],"id":70003366},{"atb":[[1.41,56.65],[1.31,112.39]],"id":70003367},{"atl":[[4.1,0.16]],"id":70003367},{"atb":[[1.01,5807.26]],"id":70003364},{"atl":[[2.68,0.31]],"id":70003364},{"spn":1.91,"spf":"NaN","id":70003364},{"atb":[[1.44,52.79],[1.34,102.47]],"id":70003365},{"atl":[[4.2,0.16]],"id":70003365},{"spn":2.84,"spf":"NaN","id":70003365},{"atb":[[3.85,8.15],[3.35,14.82]],"id":70003363}],"con":true,"img":false}]}
{"op":"mcm","clk":"11449768056","pt":1717314447369,"mc":[{"id":"1.229554891","rc":[{"atl":[[6.2,1.61]],"id":70003365}],"con":true,"img":false}]}
{"op":"mcm","clk":"11449769970","pt":1717314470498,"mc":[{"id":"1.229554891","rc":[{"atb":[[1.38,0]],"id":70003365},{"atb":[[3.4,0]],"id":70003363}],"con":true,"img":false}]}
{"op":"mcm","clk":"11449771095","pt":1717314482930,"mc":[{"id":"1.229554891","rc":[{"atb":[[1.28,0]],"id":70003367},{"atb":[[1.31,0]],"id":70003365},{"atb":[[3.65,0]],"id":70003363}],"con":true,"img":false}]}
{"op":"mcm","clk":"11449771106","pt":1717314483032,"mc":[{"id":"1.229554891","rc":[{"atb":[[1.42,49.24]],"id":70003367},{"atb":[[1.45,44.05]],"id":70003365},{"atb":[[3.9,16.09]],"id":70003363}],"con":true,"img":false}]}
{"op":"mcm","clk":"11449772094","pt":1717314493246,"mc":[{"id":"1.229554891","rc":[{"atb":[[1.49,0]],"id":70003365}],"con":true,"img":false}]}
{"op":"mcm","clk":"11449772792","pt":1717314500372,"mc":[{"id":"1.229554891","rc":[{"atb":[[3.3,0]],"id":70003363}],"con":true,"img":false}]}
{"op":"mcm","clk":"11449772805","pt":1717314500422,"mc":[{"id":"1.229554891","rc":[{"atb":[[3.4,21.13]],"id":70003363}],"con":true,"img":false}]}
{"op":"mcm","clk":"11449772875","pt":1717314501144,"mc":[{"id":"1.229554891","rc":[{"atl":[[6.6,0]],"id":70003365}],"con":true,"img":false}]}
{"op":"mcm","clk":"11449772885","pt":1717314501244,"mc":[{"id":"1.229554891","rc":[{"atl":[[6,27.15]],"id":70003365}],"con":true,"img":false}]}
{"op":"mcm","clk":"11449773000","pt":1717314502535,"mc":[{"id":"1.229554891","rc":[{"atb":[[1.35,12.17]],"id":70003365}],"con":true,"img":false}]}
{"op":"mcm","clk":"11449773526","pt":1717314508157,"mc":[{"id":"1.229554891","rc":[{"atb":[[1.44,0]],"id":70003367},{"spn":2.76,"spf":"NaN","id":70003367},{"spn":2.82,"spf":"NaN","id":70003365},{"spn":22.95,"spf":"NaN","id":70003363}],"con":true,"img":false}]}
{"op":"mcm","clk":"11449773544","pt":1717314508363,"mc":[{"id":"1.229554891","rc":[{"atb":[[1.47,8.35]],"id":70003365}],"con":true,"img":false}]}
{"op":"mcm","clk":"11449773587","pt":1717314508723,"mc":[{"id":"1.229554891","rc":[{"atb":[[1.14,0]],"id":70003364}],"con":true,"img":false}]}
{"op":"mcm","clk":"11449773602","pt":1717314508828,"mc":[{"id":"1.229554891","rc":[{"atb":[[1.13,119.36]],"id":70003364}],"con":true,"img":false}]}
{"op":"mcm","clk":"11449774950","pt":1717314523347,"mc":[{"id":"1.229554891","rc":[{"atb":[[1.44,8.91]],"id":70003367}],"con":true,"img":false}]}
{"op":"mcm","clk":"11449782180","pt":1717314606209,"mc":[{"id":"1.229554891","rc":[{"atb":[[4.5,0],[6,26.96]],"id":70003366},{"spn":2.77,"spf":"NaN","id":70003367},{"spn":1.9,"spf":"NaN","id":70003364},{"spn":2.83,"spf":"NaN","id":70003365}],"con":true,"img":false}]}
{"op":"mcm","clk":"11449782186","pt":1717314606314,"mc":[{"id":"1.229554891","rc":[{"atb":[[2.3,30.93]],"id":70003363}],"con":true,"img":false}]}
{"op":"mcm","clk":"11449782192","pt":1717314606417,"mc":[{"id":"1.229554891","rc":[{"atb":[[2.1,0]],"id":70003363}],"con":true,"img":false}]}
{"op":"mcm","clk":"11449782531","pt":1717314610804,"mc":[{"id":"1.229554891","rc":[{"atl":[[5.9,0]],"id":70003367}],"con":true,"img":false}]}
{"op":"mcm","clk":"11449782539","pt":1717314610915,"mc":[{"id":"1.229554891","rc":[{"atl":[[6.2,11.87]],"id":70003367}],"con":true,"img":false}]}
{"op":"mcm","clk":"11449782570","pt":1717314611415,"mc":[{"id":"1.229554891","rc":[{"atb":[[4.5,21.08],[6,6.96]],"id":70003366},{"atb":[[2.3,0],[2.1,32.2]],"id":70003363}],"con":true,"img":false}]}
{"op":"mcm","clk":"11449784133","pt":1717314630970,"mc":[{"id":"1.229554891","rc":[{"atb":[[4.5,0],[5.5,20.58]],"id":70003366}],"con":true,"img":false}]}
{"op":"mcm","clk":"11449784145","pt":1717314631073,"mc":[{"id":"1.229554891","rc":[{"atb":[[5.5,0]],"id":70003366}],"con":true,"img":false}]}
{"op":"mcm","clk":"11449784151","pt":1717314631175,"mc":[{"id":"1.229554891","rc":[{"atb":[[4.5,20.83]],"id":70003366}],"con":true,"img":false}]}
{"op":"mcm","clk":"11449784855","pt":1717314640260,"mc":[{"id":"1.229554891","rc":[{"atb":[[2.3,30.93],[2.1,0]],"id":70003363}],"con":true,"img":false}]}
{"op":"mcm","clk":"11449785699","pt":1717314650589,"mc":[{"id":"1.229554891","rc":[{"atb":[[4.5,0],[5,20.58]],"id":70003366}],"con":true,"img":false}]}
{"op":"mcm","clk":"11449786163","pt":1717314656669,"mc":[{"id":"1.229554891","rc":[{"atb":[[1.42,0]],"id":70003367}],"con":true,"img":false}]}
{"op":"mcm","clk":"11449786171","pt":1717314656774,"mc":[{"id":"1.229554891","rc":[{"atb":[[1.32,62.55]],"id":70003367}],"con":true,"img":false}]}
{"op":"mcm","clk":"11449786987","pt":1717314665911,"mc":[{"id":"1.229554891","rc":[{"atb":[[2.3,0],[2.1,32.2]],"id":70003363}],"con":true,"img":false}]}
{"op":"mcm","clk":"11449787039","pt":1717314666482,"mc":[{"id":"1.229554891","rc":[{"atb":[[1.41,0],[1.31,0]],"id":70003367},{"atl":[[4.1,0]],"id":70003367},{"spn":3.47,"spf":"NaN","id":70003367},{"atb":[[1.01,0]],"id":70003364},{"atl":[[2.68,0]],"id":70003364},{"spn":2.49,"spf":"NaN","id":70003364},{"atb":[[1.44,0],[1.34,0]],"id":70003365},{"atl":[[4.2,0]],"id":70003365},{"spn":3.73,"spf":"NaN","id":70003365},{"atb":[[3.85,0],[3.35,0]],"id":70003363}],"con":true,"img":false}]}
{"op":"mcm","clk":"11449787103","pt":1717314667206,"mc":[{"id":"1.229554891","rc":[{"atb":[[1.32,13.31]],"id":70003367},{"atb":[[1.45,0]],"id":70003365},{"atl":[[6,16.84]],"id":70003365},{"atb":[[3.9,0]],"id":70003363}],"con":true,"img":false}]}
{"op":"mcm","clk":"11449787113","pt":1717314667303,"mc":[{"id":"1.229554891","rc":[{"atb":[[1.27,49.24]],"id":70003367},{"atb":[[1.3,44.05]],"id":70003365},{"atl":[[7,10.3]],"id":70003365},{"atb":[[3.6,16.09]],"id":70003363}],"con":true,"img":false}]}
{"op":"mcm","clk":"11449788621","pt":1717314683708,"mc":[{"id":"1.229554891","rc":[{"atb":[[1.32,0]],"id":70003367},{"atb":[[1.35,0]],"id":70003365}],"con":true,"img":false}]}
{"op":"mcm","clk":"11449789010","pt":1717314687369,"mc":[{"id":"1.229554891","rc":[{"atb":[[1.43,54.02],[1.33,105.58]],"id":70003367},{"atl":[[4.1,0.16]],"id":70003367},{"atb":[[1.01,5807.26]],"id":70003364},{"atl":[[2.64,0.31]],"id":70003364},{"atb":[[1.32,108.88],[1.42,55.3]],"id":70003365},{"atl":[[4.1,0.16]],"id":70003365},{"atb":[[3.45,14.21],[3.95,7.87]],"id":70003363}],"con":true,"img":false}]}
{"op":"mcm","clk":"11449789090","pt":1717314688240,"mc":[{"id":"1.229554891","rc":[{"atb":[[1.44,0]],"id":70003367}],"con":true,"img":false}]}
{"op":"mcm","clk":"11449789148","pt":1717314688812,"mc":[{"id":"1.229554891","rc":[{"atb":[[1.45,8.72]],"id":70003367}],"con":true,"img":false}]}
{"op":"mcm","clk":"11449791546","pt":1717314716174,"mc":[{"id":"1.229554891","rc":[{"atb":[[1.27,0]],"id":70003367},{"atb":[[3.6,0]],"id":70003363}],"con":true,"img":false}]}
{"op":"mcm","clk":"11449791553","pt":1717314716274,"mc":[{"id":"1.229554891","rc":[{"atb":[[1.34,49.24]],"id":70003367},{"atb":[[4,16.09]],"id":70003363}],"con":true,"img":false}]}
{"op":"mcm","clk":"11449791582","pt":1717314716685,"mc":[{"id":"1.229554891","rc":[{"atb":[[1.3,0]],"id":70003365},{"atb":[[4,0]],"id":70003363}],"con":true,"img":false}]}
{"op":"mcm","clk":"11449791588","pt":1717314716789,"mc":[{"id":"1.229554891","rc":[{"atb":[[1.43,44.05]],"id":70003365},{"atb":[[3.65,16.09]],"id":70003363}],"con":true,"img":false}]}
{"op":"mcm","clk":"11449791920","pt":1717314720695,"mc":[{"id":"1.229554891","rc":[{"atb":[[6,26.96]],"id":70003366},{"atb":[[2.3,30.32]],"id":70003363}],"con":true,"img":false}]}
{"op":"mcm","clk":"11449791933","pt":1717314720803,"mc":[{"id":"1.229554891","rc":[{"atb":[[5,0]],"id":70003366},{"atb":[[2.1,0]],"id":70003363}],"con":true,"img":false}]}
{"op":"mcm","clk":"11449792334","pt":1717314725114,"mc":[{"id":"1.229554891","rc":[{"atb":[[1.33,12.91]],"id":70003365}],"con":true,"img":false}]}
{"op":"mcm","clk":"11449792372","pt":1717314725578,"mc":[{"id":"1.229554891","rc":[{"atb":[[1.34,61.77]],"id":70003367}],"con":true,"img":false}]}
{"op":"mcm","clk":"11449792491","pt":1717314727067,"mc":[{"id":"1.229554891","rc":[{"spn":2.77,"spf":"NaN","id":70003367},{"spn":1.88,"spf":"NaN","id":70003364},{"spn":2.78,"spf":"NaN","id":70003365},{"atb":[[3.4,0]],"id":70003363},{"spn":22.97,"spf":"NaN","id":70003363}],"con":true,"img":false}]}
{"op":"mcm","clk":"11449792501","pt":1717314727171,"mc":[{"id":"1.229554891","rc":[{"atb":[[3.5,21.13]],"id":70003363}],"con":true,"img":false}]}
{"op":"mcm","clk":"11449792586","pt":1717314728201,"mc":[{"id":"1.229554891","rc":[{"atl":[[7,0]],"id":70003365}],"con":true,"img":false}]}
{"op":"mcm","clk":"11449792594","pt":1717314728303,"mc":[{"id":"1.229554891","rc":[{"atl":[[6,27.15]],"id":70003365}],"con":true,"img":false}]}
{"op":"mcm","clk":"11449792617","pt":1717314728613,"mc":[{"id":"1.229554891","rc":[{"atb":[[5,21.08],[6,6.96]],"id":70003366},{"atb":[[2.3,0],[2.1,32.2]],"id":70003363}],"con":true,"img":false}]}
{"op":"mcm","clk":"11449792859","pt":1717314731524,"mc":[{"id":"1.229554891","rc":[{"atb":[[8,6.97],[6,0]],"id":70003366},{"atb":[[1.43,0],[1.33,0]],"id":70003367},{"atl":[[4.1,0]],"id":70003367},{"atb":[[1.01,0]],"id":70003364},{"atl":[[2.64,0]],"id":70003364},{"atb":[[1.32,0],[1.42,0]],"id":70003365},{"atl":[[4.1,0]],"id":70003365}],"con":true,"img":false}]}
{"op":"mcm","clk":"11449792879","pt":1717314731732,"mc":[{"id":"1.229554891","rc":[{"atl":[[4.1,43.12],[4.2,0]],"id":70003364}],"con":true,"img":false}]}
{"op":"mcm","clk":"11449792911","pt":1717314732097,"mc":[{"id":"1.229554891","rc":[{"atb":[[1.34,12.53]],"id":70003367},{"atb":[[1.43,0]],"id":70003365}],"con":true,"img":false}]}
{"op":"mcm","clk":"11449792921","pt":1717314732196,"mc":[{"id":"1.229554891","rc":[{"atb":[[1.27,49.24]],"id":70003367},{"atb":[[1.3,44.05]],"id":70003365}],"con":true,"img":false}]}
{"op":"mcm","clk":"11449793035","pt":1717314733381,"mc":[{"id":"1.229554891","rc":[{"atb":[[1.47,0]],"id":70003365}],"con":true,"img":false}]}
{"op":"mcm","clk":"11449793324","pt":1717314737132,"mc":[{"id":"1.229554891","rc":[{"atb":[[5.8,7.26],[7.6,3.52]],"id":70003366},{"atb":[[1.44,52.79],[1.34,115.01]],"id":70003367},{"atl":[[4.2,0.16]],"id":70003367},{"atb":[[1.01,5807.26]],"id":70003364},{"atl":[[2.66,0.31]],"id":70003364},{"atb":[[1.43,54.02],[1.33,118.49]],"id":70003365},{"atl":[[4.1,0.16]],"id":70003365}],"con":true,"img":false}]}
{"op":"mcm","clk":"11449793731","pt":1717314741620,"mc":[{"id":"1.229554891","rc":[{"atb":[[3.65,0]],"id":70003363}],"con":true,"img":false}]}
{"op":"mcm","clk":"11449793737","pt":1717314741722,"mc":[{"id":"1.229554891","rc":[{"atb":[[4,16.09]],"id":70003363}],"con":true,"img":false}]}
{"op":"mcm","clk":"11449794265","pt":1717314748316,"mc":[{"id":"1.229554891","rc":[{"atb":[[1.45,0]],"id":70003367},{"atb":[[1.45,8.72]],"id":70003365}],"con":true,"img":false}]}
{"op":"mcm","clk":"11449794284","pt":1717314748526,"mc":[{"id":"1.229554891","rc":[{"atb":[[1.46,8.53]],"id":70003367}],"con":true,"img":false}]}
{"op":"mcm","clk":"11449795367","pt":1717314762142,"mc":[{"id":"1.229554891","rc":[{"atb":[[1.34,102.47]],"id":70003367},{"atb":[[1.33,105.58]],"id":70003365}],"con":true,"img":false}]}
{"op":"mcm","clk":"11449795758","pt":1717314766728,"mc":[{"id":"1.229554891","rc":[{"atb":[[1.27,0]],"id":70003367}],"con":true,"img":false}]}
{"op":"mcm","clk":"11449795767","pt":1717314766829,"mc":[{"id":"1.229554891","rc":[{"atb":[[1.35,49.24]],"id":70003367}],"con":true,"img":false}]}
{"op":"mcm","clk":"11449795786","pt":1717314767139,"mc":[{"id":"1.229554891","rc":[{"atb":[[1.3,0]],"id":70003365}],"con":true,"img":false}]}
{"op":"mcm","clk":"11449795796","pt":1717314767238,"mc":[{"id":"1.229554891","rc":[{"atb":[[1.44,44.05]],"id":70003365}],"con":true,"img":false}]}
{"op":"mcm","clk":"11449796694","pt":1717314776952,"mc":[{"id":"1.229554891","rc":[{"atb":[[5.8,0],[7.6,0]],"id":70003366},{"atb":[[1.44,0],[1.34,0]],"id":70003367},{"atl":[[4.2,0]],"id":70003367},{"atb":[[1.01,0]],"id":70003364},{"atl":[[2.66,0]],"id":70003364},{"atb":[[1.43,0],[1.33,0]],"id":70003365},{"atl":[[4.1,0]],"id":70003365},{"atb":[[3.45,0],[3.95,0]],"id":70003363}],"con":true,"img":false}]}
{"op":"mcm","clk":"11449796762","pt":1717314777675,"mc":[{"id":"1.229554891","rc":[{"atb":[[1.35,0]],"id":70003367},{"atb":[[1.44,0]],"id":70003365},{"atb":[[4,0],[3.5,0]],"id":70003363}],"con":true,"img":false}]}
{"op":"mcm","clk":"11449796770","pt":1717314777776,"mc":[{"id":"1.229554891","rc":[{"atb":[[1.27,49.24]],"id":70003367},{"atb":[[1.3,44.05]],"id":70003365},{"atb":[[3.6,16.09],[3.3,21.13],[1.65,64.4],[2.1,0]],"id":70003363}],"con":true,"img":false}]}
{"op":"mcm","clk":"11449796779","pt":1717314777880,"mc":[{"id":"1.229554891","rc":[{"atb":[[2.1,37.24]],"id":70003363}],"con":true,"img":false}]}
{"op":"mcm","clk":"11449796784","pt":1717314777982,"mc":[{"id":"1.229554891","rc":[{"atb":[[1.65,0]],"id":70003363}],"con":true,"img":false}]}
{"op":"mcm","clk":"11449800913","pt":1717314826849,"mc":[{"id":"1.229554891","rc":[{"atb":[[6.2,6.7],[8.2,3.22]],"id":70003366},{"spn":89.1,"spf":"NaN","id":70003366},{"atb":[[1.41,56.65],[1.31,112.39]],"id":70003367},{"atl":[[4.1,0.16]],"id":70003367},{"spn":2.78,"spf":"NaN","id":70003367},{"atb":[[1.01,5807.26]],"id":70003364},{"atl":[[2.68,0.31]],"id":70003364},{"spn":1.9,"spf":"NaN","id":70003364},{"atb":[[1.43,54.02],[1.33,105.58]],"id":70003365},{"atl":[[4.1,0.16]],"id":70003365},{"spn":2.77,"spf":"NaN","id":70003365},{"atb":[[3.4,14.51],[3.9,8]],"id":70003363},{"spn":22.95,"spf":"NaN","id":70003363}],"con":true,"img":false}]}
{"op":"mcm","clk":"11449801528","pt":1717314833982,"mc":[{"id":"1.229554891","rc":[{"atb":[[1.34,12.53]],"id":70003365}],"con":true,"img":false}]}
{"op":"mcm","clk":"11449801544","pt":1717314834184,"mc":[{"id":"1.229554891","rc":[{"atb":[[1.32,13.31]],"id":70003367}],"con":true,"img":false}]}
{"op":"mcm","clk":"11449801962","pt":1717314839091,"mc":[{"id":"1.229554891","rc":[{"atb":[[1.46,0]],"id":70003367},{"atb":[[1.45,0]],"id":70003365}],"con":true,"img":false}]}
{"op":"mcm","clk":"11449803215","pt":1717314854413,"mc":[{"id":"1.229554891","rc":[{"atb":[[1.43,9.13]],"id":70003367},{"atb":[[1.45,8.72]],"id":70003365}],"con":true,"img":false}]}
{"op":"mcm","clk":"11449803319","pt":1717314855597,"mc":[{"id":"1.229554891","rc":[{"atb":[[1.27,0]],"id":70003367}],"con":true,"img":false}]}
{"op":"mcm","clk":"11449803330","pt":1717314855752,"mc":[{"id":"1.229554891","rc":[{"atb":[[1.32,62.55]],"id":70003367}],"con":true,"img":false}]}
{"op":"mcm","clk":"11449803408","pt":1717314856579,"mc":[{"id":"1.229554891","rc":[{"atb":[[1.3,0]],"id":70003365}],"con":true,"img":false}]}
{"op":"mcm","clk":"11449803419","pt":1717314856687,"mc":[{"id":"1.229554891","rc":[{"atb":[[1.44,44.05]],"id":70003365}],"con":true,"img":false}]}
{"op":"mcm","clk":"11449804235","pt":1717314867190,"mc":[{"id":"1.229554891","rc":[{"atb":[[3.3,0]],"id":70003363}],"con":true,"img":false}]}
{"op":"mcm","clk":"11449804245","pt":1717314867301,"mc":[{"id":"1.229554891","rc":[{"atb":[[3.45,21.13]],"id":70003363}],"con":true,"img":false}]}
{"op":"mcm","clk":"11449804444","pt":1717314869511,"mc":[{"id":"1.229554891","rc":[{"atb":[[1.45,0]],"id":70003365}],"con":true,"img":false}]}
{"op":"mcm","clk":"11449804482","pt":1717314869926,"mc":[{"id":"1.229554891","rc":[{"atb":[[1.46,8.53]],"id":70003365}],"con":true,"img":false}]}
{"op":"mcm","clk":"11449805261","pt":1717314879237,"mc":[{"id":"1.229554891","rc":[{"atb":[[3.6,0]],"id":70003363}],"con":true,"img":false}]}
{"op":"mcm","clk":"11449805268","pt":1717314879342,"mc":[{"id":"1.229554891","rc":[{"atb":[[3.95,16.09]],"id":70003363}],"con":true,"img":false}]}
{"op":"mcm","clk":"11449830274","pt":1717315128427,"mc":[{"id":"1.229554891","marketDefinition":{"bspMarket":true,"turnInPlayEnabled":false,"persistenceEnabled":false,"marketBaseRate":7.0,"eventId":"33318908","eventTypeId":"4339","numberOfWinners":2,"bettingType":"ODDS","marketType":"PLACE","marketTime":"2024-06-02T08:21:00.000Z","suspendTime":"2024-06-02T08:21:00.000Z","bspReconciled":false,"complete":true,"inPlay":false,"crossMatching":true,"runnersVoidable":false,"numberOfActiveRunners":5,"betDelay":0,"status":"OPEN","runners":[{"status":"ACTIVE","sortPriority":1,"id":70003363,"name":"1. Plodding Along"},{"status":"ACTIVE","sortPriority":2,"id":70003364,"name":"2. Parrakie"},{"status":"ACTIVE","sortPriority":3,"id":70003365,"name":"4. Bookaloo"},{"status":"ACTIVE","sortPriority":4,"id":70003366,"name":"6. Manner Of Strife"},{"status":"ACTIVE","sortPriority":5,"id":70003367,"name":"8. Apilla"}],"regulators":["MR_INT"],"venue":"Murray Bridge","countryCode":"AU","discountAllowed":true,"timezone":"Australia/Adelaide","openDate":"2024-06-02T08:21:00.000Z","version":5962317650,"name":"To Be Placed","eventName":"Murray Bridge (AUS) 2nd Jun"},"rc":[{"atb":[[8,6.97],[5,21.08],[6.2,6.7],[8.2,3.22],[1.02,8.87],[7,10.53]],"id":70003366},{"atl":[[170,0.19],[180,4.61],[990,0.17]],"id":70003366},{"spn":89.1,"spf":"NaN","id":70003366},{"atb":[[1.41,56.65],[1.01,17.76],[1.43,9.13],[1.25,253.06],[1.32,62.55],[1.31,112.39]],"id":70003367},{"atl":[[5.6,6.97],[6.2,11.87],[4.1,0.16],[5.5,11.88],[1000,0.17]],"id":70003367},{"spn":2.76,"spf":"NaN","id":70003367},{"atb":[[1.12,558.75],[1.01,5807.26],[1.02,8.87],[1.13,119.36]],"id":70003364},{"atl":[[3.85,11.62],[4.1,43.12],[2.68,0.31],[1000,0.17]],"id":70003364},{"spn":1.9,"spf":"NaN","id":70003364},{"atb":[[1.46,8.53],[1.44,44.05],[1.43,54.02],[1.03,5.92],[1.26,184.04],[1.33,105.58],[1.34,12.53]],"id":70003365},{"atl":[[6.2,1.61],[4.1,0.16],[6,27.15],[1000,0.17]],"id":70003365},{"spn":2.78,"spf":"NaN","id":70003365},{"atb":[[3.45,21.13],[3.95,16.09],[1.02,8.87],[3.4,14.51],[3.9,8],[2.1,37.24]],"id":70003363},{"atl":[[42,2.61],[44,4.94],[990,0.17]],"id":70003363},{"spn":22.97,"spf":"NaN","id":70003363}],"con":true,"img":true}]}
{"op":"mcm","clk":"11449837894","pt":1717315160729,"mc":[{"id":"1.229554891","rc":[{"atb":[[6.2,0],[8.2,0]],"id":70003366},{"atb":[[1.41,0],[1.31,0]],"id":70003367},{"atl":[[4.1,0]],"id":70003367},{"spn":2.76,"spf":"NaN","id":70003367},{"atb":[[1.01,0]],"id":70003364},{"atl":[[2.68,0]],"id":70003364},{"atb":[[1.43,0],[1.33,0]],"id":70003365},{"atl":[[4.1,0]],"id":70003365},{"spn":2.78,"spf":"NaN","id":70003365},{"atb":[[3.4,0],[3.9,0]],"id":70003363},{"spn":22.97,"spf":"NaN","id":70003363}],"con":true,"img":false}]}
{"op":"mcm","clk":"11449837942","pt":1717315161234,"mc":[{"id":"1.229554891","rc":[{"atb":[[1.32,13.31]],"id":70003367},{"atb":[[1.44,0]],"id":70003365},{"atb":[[3.45,0],[3.95,0]],"id":70003363}],"con":true,"img":false}]}
{"op":"mcm","clk":"11449837949","pt":1717315161337,"mc":[{"id":"1.229554891","rc":[{"atb":[[1.27,49.24]],"id":70003367},{"atb":[[1.3,44.05]],"id":70003365},{"atb":[[3.55,16.09],[3.25,21.13]],"id":70003363}],"con":true,"img":false}]}
{"op":"mcm","clk":"11449837957","pt":1717315161393,"mc":[{"id":"1.229554891","rc":[{"atb":[[1.65,74.48]],"id":70003363}],"con":true,"img":false}]}
{"op":"mcm","clk":"11449837969","pt":1717315161548,"mc":[{"id":"1.229554891","rc":[{"atb":[[2.1,0]],"id":70003363}],"con":true,"img":false}]}
{"op":"mcm","clk":"11449837989","pt":1717315161711,"mc":[{"id":"1.229554891","rc":[{"atb":[[1.65,0],[2.1,37.24]],"id":70003363}],"con":true,"img":false}]}
{"op":"mcm","clk":"11449838770","pt":1717315170145,"mc":[{"id":"1.229554891","rc":[{"atb":[[1.32,0]],"id":70003367},{"atb":[[1.34,0]],"id":70003365}],"con":true,"img":false}]}
{"op":"mcm","clk":"11449839908","pt":1717315181236,"mc":[{"id":"1.229554891","rc":[{"atb":[[6,17.51]],"id":70003366},{"atb":[[2.3,37.24]],"id":70003363}],"con":true,"img":false}]}
{"op":"mcm","clk":"11449839918","pt":1717315181339,"mc":[{"id":"1.229554891","rc":[{"atb":[[5,0]],"id":70003366},{"atb":[[2.1,0]],"id":70003363}],"con":true,"img":false}]}
{"op":"mcm","clk":"11449839933","pt":1717315181546,"mc":[{"id":"1.229554891","rc":[{"atb":[[6,0]],"id":70003366}],"con":true,"img":false}]}
{"op":"mcm","clk":"11449839942","pt":1717315181651,"mc":[{"id":"1.229554891","rc":[{"atb":[[5,21.08]],"id":70003366}],"con":true,"img":false}]}
{"op":"mcm","clk":"11449841686","pt":1717315199991,"mc":[{"id":"1.229554891","rc":[{"atb":[[5.6,7.57],[7.2,3.74]],"id":70003366},{"spn":89.0,"spf":"NaN","id":70003366},{"atb":[[1.29,120.15],[1.39,59.56]],"id":70003367},{"atl":[[3.95,0.17]],"id":70003367},{"spn":2.69,"spf":"NaN","id":70003367},{"atb":[[1.01,5807.26]],"id":70003364},{"atl":[[2.68,0.31]],"id":70003364},{"atb":[[1.49,47.4],[1.39,89.34]],"id":70003365},{"atl":[[4.4,0.15]],"id":70003365},{"spn":2.94,"spf":"NaN","id":70003365},{"atb":[[3.8,8.29],[3.3,15.15]],"id":70003363},{"spn":22.9,"spf":"NaN","id":70003363}],"con":true,"img":false}]}
{"op":"mcm","clk":"11449842206","pt":1717315204104,"mc":[{"id":"1.229554891","rc":[{"atb":[[1.41,10.39]],"id":70003367}],"con":true,"img":false}]}
{"op":"mcm","clk":"11449842220","pt":1717315204165,"mc":[{"id":"1.229554891","rc":[{"atb":[[1.41,10.39]],"id":70003365}],"con":true,"img":false}]}
{"op":"mcm","clk":"11449842375","pt":1717315205701,"mc":[{"id":"1.229554891","rc":[{"atb":[[8,0]],"id":70003366}],"con":true,"img":false}]}
{"op":"mcm","clk":"11449842382","pt":1717315205763,"mc":[{"id":"1.229554891","rc":[{"atb":[[8.2,6.97]],"id":70003366}],"con":true,"img":false}]}
{"op":"mcm","clk":"11449843101","pt":1717315212366,"mc":[{"id":"1.229554891","rc":[{"atb":[[2,32.2],[2.3,0]],"id":70003363}],"con":true,"img":false}]}
{"op":"mcm","clk":"11449843467","pt":1717315215886,"mc":[{"id":"1.229554891","rc":[{"atb":[[1.46,0]],"id":70003365}],"con":true,"img":false}]}
{"op":"mcm","clk":"11449843658","pt":1717315217701,"mc":[{"id":"1.229554891","rc":[{"atb":[[1.51,7.69]],"id":70003365}],"con":true,"img":false}]}
{"op":"mcm","clk":"11449844708","pt":1717315228107,"mc":[{"id":"1.229554891","rc":[{"atb":[[3.55,0]],"id":70003363}],"con":true,"img":false}]}
{"op":"mcm","clk":"11449844720","pt":1717315228207,"mc":[{"id":"1.229554891","rc":[{"atb":[[3.85,16.09]],"id":70003363}],"con":true,"img":false}]}
{"op":"mcm","clk":"11449844873","pt":1717315229614,"mc":[{"id":"1.229554891","rc":[{"atb":[[1.27,0]],"id":70003367}],"con":true,"img":false}]}
{"op":"mcm","clk":"11449844883","pt":1717315229711,"mc":[{"id":"1.229554891","rc":[{"atb":[[1.4,49.24]],"id":70003367}],"con":true,"img":false}]}
{"op":"mcm","clk":"11449844915","pt":1717315230076,"mc":[{"id":"1.229554891","rc":[{"atb":[[1.43,0]],"id":70003367}],"con":true,"img":false}]}
{"op":"mcm","clk":"11449844925","pt":1717315230177,"mc":[{"id":"1.229554891","rc":[{"atb":[[1.3,0]],"id":70003365}],"con":true,"img":false}]}
{"op":"mcm","clk":"11449844935","pt":1717315230280,"mc":[{"id":"1.229554891","rc":[{"atb":[[1.4,44.05]],"id":70003365}],"con":true,"img":false}]}
{"op":"mcm","clk":"11449845064","pt":1717315231619,"mc":[{"id":"1.229554891","rc":[{"atb":[[1.42,9.34]],"id":70003367}],"con":true,"img":false}]}
{"op":"mcm","clk":"11449845086","pt":1717315231930,"mc":[{"id":"1.229554891","rc":[{"atl":[[6,16.84]],"id":70003365}],"con":true,"img":false}]}
{"op":"mcm","clk":"11449845090","pt":1717315231988,"mc":[{"id":"1.229554891","rc":[{"atl":[[7,10.3]],"id":70003365}],"con":true,"img":false}]}
{"op":"mcm","clk":"11449845793","pt":1717315240203,"mc":[{"id":"1.229554891","rc":[{"atb":[[3.25,0]],"id":70003363}],"con":true,"img":false}]}
{"op":"mcm","clk":"11449845803","pt":1717315240306,"mc":[{"id":"1.229554891","rc":[{"atb":[[3.35,21.13]],"id":70003363}],"con":true,"img":false}]}
{"op":"mcm","clk":"11449846502","pt":1717315247637,"mc":[{"id":"1.229554891","rc":[{"atb":[[5.6,0],[7.2,0]],"id":70003366},{"atb":[[1.29,0],[1.39,0]],"id":70003367},{"atl":[[3.95,0]],"id":70003367},{"atb":[[1.49,0],[1.39,0]],"id":70003365},{"atl":[[4.4,0]],"id":70003365},{"atb":[[3.8,0],[3.3,0]],"id":70003363}],"con":true,"img":false}]}
{"op":"mcm","clk":"11449846560","pt":1717315248096,"mc":[{"id":"1.229554891","rc":[{"atb":[[1.4,0]],"id":70003367},{"atb":[[1.4,0]],"id":70003365},{"atb":[[3.85,0]],"id":70003363}],"con":true,"img":false}]}
{"op":"mcm","clk":"11449846616","pt":1717315248203,"mc":[{"id":"1.229554891","rc":[{"atb":[[1.27,49.24]],"id":70003367},{"atb":[[1.3,44.05]],"id":70003365},{"atb":[[3.55,16.09]],"id":70003363}],"con":true,"img":false}]}
{"op":"mcm","clk":"11449847371","pt":1717315256100,"mc":[{"id":"1.229554891","rc":[{"atl":[[6.2,0]],"id":70003365}],"con":true,"img":false}]}
{"op":"mcm","clk":"11449847414","pt":1717315256528,"mc":[{"id":"1.229554891","rc":[{"atl":[[6.6,9.75]],"id":70003365}],"con":true,"img":false}]}
{"op":"mcm","clk":"11449847437","pt":1717315256824,"mc":[{"id":"1.229554891","rc":[{"atl":[[6.6,0]],"id":70003365}],"con":true,"img":false}]}
{"op":"mcm","clk":"11449847547","pt":1717315258119,"mc":[{"id":"1.229554891","rc":[{"atb":[[5.5,7.74],[7,14.4]],"id":70003366},{"atb":[[1.46,50.49],[1.36,96.78]],"id":70003367},{"atl":[[4.3,0.15]],"id":70003367},{"atb":[[1.32,108.88],[1.42,55.3]],"id":70003365},{"atl":[[4.1,0.16]],"id":70003365},{"atb":[[3.25,15.48],[3.75,8.44]],"id":70003363}],"con":true,"img":false}]}
{"op":"mcm","clk":"11449848193","pt":1717315264538,"mc":[{"id":"1.229554891","rc":[{"spn":89.1,"spf":"NaN","id":70003366},{"atb":[[1.42,0]],"id":70003367},{"spn":2.88,"spf":"NaN","id":70003367},{"spn":2.8,"spf":"NaN","id":70003365},{"spn":22.87,"spf":"NaN","id":70003363}],"con":true,"img":false}]}
{"op":"mcm","clk":"11449848215","pt":1717315264746,"mc":[{"id":"1.229554891","rc":[{"atb":[[1.48,8.17]],"id":70003367}],"con":true,"img":false}]}
{"op":"mcm","clk":"11449848375","pt":1717315266497,"mc":[{"id":"1.229554891","rc":[{"atb":[[5,0],[5.5,29.12]],"id":70003366}],"con":true,"img":false}]}
{"op":"mcm","clk":"11449850316","pt":1717315286650,"mc":[{"id":"1.229554891","rc":[{"atb":[[1.41,0]],"id":70003367},{"atb":[[1.41,0]],"id":70003365}],"con":true,"img":false}]}
{"op":"mcm","clk":"11449850363","pt":1717315287174,"mc":[{"id":"1.229554891","rc":[{"atb":[[3.55,0]],"id":70003363}],"con":true,"img":false}]}
{"op":"mcm","clk":"11449850374","pt":1717315287324,"mc":[{"id":"1.229554891","rc":[{"atb":[[3.8,16.09]],"id":70003363}],"con":true,"img":false}]}
{"op":"mcm","clk":"11449850417","pt":1717315287687,"mc":[{"id":"1.229554891","rc":[{"atb":[[1.27,0]],"id":70003367},{"atb":[[1.3,0]],"id":70003365}],"con":true,"img":false}]}
{"op":"mcm","clk":"11449850430","pt":1717315287803,"mc":[{"id":"1.229554891","rc":[{"atb":[[1.37,49.24]],"id":70003367},{"atb":[[1.43,44.05]],"id":70003365}],"con":true,"img":false}]}
{"op":"mcm","clk":"11449851183","pt":1717315295523,"mc":[{"id":"1.229554891","rc":[{"atb":[[5.5,21.38],[7,10.53]],"id":70003366},{"atb":[[1.46,0],[1.36,0]],"id":70003367},{"atl":[[4.3,0]],"id":70003367},{"atb":[[1.32,0],[1.42,0]],"id":70003365},{"atl":[[4.1,0]],"id":70003365},{"atb":[[3.25,0],[3.75,0]],"id":70003363}],"con":true,"img":false}]}
{"op":"mcm","clk":"11449851251","pt":1717315296202,"mc":[{"id":"1.229554891","rc":[{"atb":[[1.37,0]],"id":70003367},{"atb":[[1.43,0]],"id":70003365},{"atb":[[3.8,0]],"id":70003363}],"con":true,"img":false}]}
{"op":"mcm","clk":"11449851262","pt":1717315296308,"mc":[{"id":"1.229554891","rc":[{"atb":[[1.27,49.24]],"id":70003367},{"atb":[[1.3,44.05]],"id":70003365},{"atb":[[3.55,16.09]],"id":70003363}],"con":true,"img":false}]}
{"op":"mcm","clk":"11449853607","pt":1717315320659,"mc":[{"id":"1.229554891","rc":[{"atb":[[5.3,8.1],[6.6,4.14]],"id":70003366},{"atb":[[1.42,82.96],[1.52,44.66]],"id":70003367},{"atl":[[4.7,0.14]],"id":70003367},{"atb":[[1.28,124.44],[1.38,61.12]],"id":70003365},{"atl":[[3.9,0.17]],"id":70003365},{"atb":[[4,7.74],[3.5,13.93]],"id":70003363}],"con":true,"img":false}]}
{"op":"mcm","clk":"11449853960","pt":1717315323824,"mc":[{"id":"1.229554891","rc":[{"atb":[[1.48,0]],"id":70003367}],"con":true,"img":false}]}
{"op":"mcm","clk":"11449854020","pt":1717315324442,"mc":[{"id":"1.229554891","rc":[{"atb":[[1.54,7.26]],"id":70003367}],"con":true,"img":false}]}
{"op":"mcm","clk":"11449854137","pt":1717315325628,"mc":[{"id":"1.229554891","rc":[{"spn":3.12,"spf":"NaN","id":70003367},{"atb":[[1.4,10.65]],"id":70003365},{"spn":2.7,"spf":"NaN","id":70003365},{"spn":23.0,"spf":"NaN","id":70003363}],"con":true,"img":false}]}
{"op":"mcm","clk":"11449854177","pt":1717315326040,"mc":[{"id":"1.229554891","rc":[{"atb":[[1.44,9.68]],"id":70003367}],"con":true,"img":false}]}
{"op":"mcm","clk":"11449854422","pt":1717315328461,"mc":[{"id":"1.229554891","rc":[{"atb":[[1.51,0]],"id":70003365}],"con":true,"img":false}]}
{"op":"mcm","clk":"11449855542","pt":1717315339046,"mc":[{"id":"1.229554891","rc":[{"atb":[[1.4,20.46]],"id":70003365}],"con":true,"img":false}]}
{"op":"mcm","clk":"11449856672","pt":1717315349666,"mc":[{"id":"1.229554891","rc":[{"atb":[[1.27,0]],"id":70003367},{"atb":[[1.3,0]],"id":70003365}],"con":true,"img":false}]}
{"op":"mcm","clk":"11449856684","pt":1717315349783,"mc":[{"id":"1.229554891","rc":[{"atb":[[1.3,49.24]],"id":70003367},{"atb":[[1.39,44.05]],"id":70003365}],"con":true,"img":false}]}
{"op":"mcm","clk":"11449857119","pt":1717315353858,"mc":[{"id":"1.229554891","rc":[{"atb":[[1.4,10.65]],"id":70003365}],"con":true,"img":false}]}
{"op":"mcm","clk":"11449857200","pt":1717315354582,"mc":[{"id":"1.229554891","rc":[{"atb":[[1.41,9.57]],"id":70003365}],"con":true,"img":false}]}
{"op":"mcm","clk":"11449857816","pt":1717315360672,"mc":[{"id":"1.229554891","rc":[{"atb":[[1.26,0]],"id":70003365}],"con":true,"img":false}]}
{"op":"mcm","clk":"11449857828","pt":1717315360777,"mc":[{"id":"1.229554891","rc":[{"atb":[[1.29,184.04]],"id":70003365}],"con":true,"img":false}]}
{"op":"mcm","clk":"11449858482","pt":1717315367483,"mc":[{"id":"1.229554891","rc":[{"atb":[[5.3,0],[6.6,0]],"id":70003366},{"atb":[[1.42,0],[1.52,0]],"id":70003367},{"atl":[[4.7,0]],"id":70003367},{"atb":[[1.28,0],[1.38,0]],"id":70003365},{"atl":[[3.9,0]],"id":70003365},{"atb":[[4,0],[3.5,0]],"id":70003363}],"con":true,"img":false}]}
{"op":"mcm","clk":"11449858546","pt":1717315368206,"mc":[{"id":"1.229554891","rc":[{"atb":[[1.29,0],[1.39,0]],"id":70003365}],"con":true,"img":false}]}
{"op":"mcm","clk":"11449858558","pt":1717315368263,"mc":[{"id":"1.229554891","rc":[{"atb":[[1.26,184.04],[1.3,44.05]],"id":70003365}],"con":true,"img":false}]}
{"op":"mcm","clk":"11449859539","pt":1717315378477,"mc":[{"id":"1.229554891","rc":[{"atb":[[5.6,7.57],[7.2,3.74]],"id":70003366},{"atb":[[1.4,87.1],[1.5,46.45]],"id":70003367},{"atl":[[4.5,0.15]],"id":70003367},{"atb":[[1.41,66.23],[1.31,112.39]],"id":70003365},{"atl":[[4.1,0.16]],"id":70003365},{"atb":[[4.1,7.49],[3.55,29.76]],"id":70003363}],"con":true,"img":false}]}
{"op":"mcm","clk":"11449860078","pt":1717315384114,"mc":[{"id":"1.229554891","rc":[{"atb":[[1.41,56.65]],"id":70003365}],"con":true,"img":false}]}
{"op":"mcm","clk":"11449860100","pt":1717315384321,"mc":[{"id":"1.229554891","rc":[{"atb":[[1.43,9.13]],"id":70003365}],"con":true,"img":false}]}
{"op":"mcm","clk":"11449861499","pt":1717315398819,"mc":[{"id":"1.229554891","rc":[{"atb":[[1.44,0]],"id":70003367},{"spn":3.02,"spf":"NaN","id":70003367},{"atb":[[1.4,0]],"id":70003365},{"spn":2.76,"spf":"NaN","id":70003365},{"spn":23.05,"spf":"NaN","id":70003363}],"con":true,"img":false}]}
{"op":"mcm","clk":"11449862430","pt":1717315408120,"mc":[{"id":"1.229554891","rc":[{"atb":[[1.3,0]],"id":70003365}],"con":true,"img":false}]}
{"op":"mcm","clk":"11449862438","pt":1717315408226,"mc":[{"id":"1.229554891","rc":[{"atb":[[1.42,44.05]],"id":70003365}],"con":true,"img":false}]}
{"op":"mcm","clk":"11449863082","pt":1717315414373,"mc":[{"id":"1.229554891","rc":[{"atb":[[1.43,0]],"id":70003365}],"con":true,"img":false}]}
{"op":"mcm","clk":"11449863106","pt":1717315414531,"mc":[{"id":"1.229554891","rc":[{"atb":[[1.44,8.92]],"id":70003365}],"con":true,"img":false}]}
{"op":"mcm","clk":"11449864578","pt":1717315429260,"mc":[{"id":"1.229554891","rc":[{"atb":[[1.54,0]],"id":70003367}],"con":true,"img":false}]}
{"op":"mcm","clk":"11449865490","pt":1717315437904,"mc":[{"id":"1.229554891","rc":[{"atb":[[1.32,13.31]],"id":70003365}],"con":true,"img":false}]}
{"op":"mcm","clk":"11449865515","pt":1717315438114,"mc":[{"id":"1.229554891","rc":[{"atb":[[1.42,10.14]],"id":70003367}],"con":true,"img":false}]}
{"op":"mcm","clk":"11449865724","pt":1717315440082,"mc":[{"id":"1.229554891","rc":[{"atl":[[5.6,47.54]],"id":70003367}],"con":true,"img":false}]}
{"op":"mcm","clk":"11449865796","pt":1717315440696,"mc":[{"id":"1.229554891","rc":[{"atl":[[5.6,6.97]],"id":70003367}],"con":true,"img":false}]}
{"op":"mcm","clk":"11449865821","pt":1717315440902,"mc":[{"id":"1.229554891","rc":[{"atl":[[5.2,3.41]],"id":70003367}],"con":true,"img":false}]}
{"op":"mcm","clk":"11449865989","pt":1717315442511,"mc":[{"id":"1.229554891","rc":[{"atl":[[5.2,0]],"id":70003367}],"con":true,"img":false}]}
{"op":"mcm","clk":"11449866017","pt":1717315442714,"mc":[{"id":"1.229554891","rc":[{"atl":[[5.1,3.13]],"id":70003367}],"con":true,"img":false}]}
{"op":"mcm","clk":"11449866093","pt":1717315443296,"mc":[{"id":"1.229554891","rc":[{"atl":[[5.1,0]],"id":70003367}],"con":true,"img":false}]}
{"op":"mcm","clk":"11449866137","pt":1717315443701,"mc":[{"id":"1.229554891","rc":[{"atl":[[4.9,4.27]],"id":70003367}],"con":true,"img":false}]}
{"op":"mcm","clk":"11449866238","pt":1717315444803,"mc":[{"id":"1.229554891","rc":[{"atb":[[1.52,7.55]],"id":70003367}],"con":true,"img":false}]}
{"op":"mcm","clk":"11449866573","pt":1717315447752,"mc":[{"id":"1.229554891","rc":[{"atl":[[4.9,0]],"id":70003367}],"con":true,"img":false}]}
{"op":"mcm","clk":"11449866593","pt":1717315447959,"mc":[{"id":"1.229554891","rc":[{"atl":[[4.8,3.13]],"id":70003367}],"con":true,"img":false}]}
{"op":"mcm","clk":"11449878829","pt":1717315567698,"mc":[{"id":"1.229554891","rc":[{"atb":[[5.6,0],[7.2,0]],"id":70003366},{"atb":[[1.4,0],[1.5,0]],"id":70003367},{"atl":[[4.5,0]],"id":70003367},{"spn":3.16,"spf":"NaN","id":70003367},{"atb":[[1.01,0]],"id":70003364},{"atl":[[2.68,0]],"id":70003364},{"spn":2.49,"spf":"NaN","id":70003364},{"atb":[[1.41,0],[1.31,0]],"id":70003365},{"atl":[[4.1,0]],"id":70003365},{"spn":3.72,"spf":"NaN","id":70003365},{"atb":[[4.1,0],[3.55,16.09]],"id":70003363},{"spn":22.77,"spf":"NaN","id":70003363}],"con":true,"img":false}]}
{"op":"mcm","clk":"11449878842","pt":1717315567800,"mc":[{"id":"1.229554891","rc":[{"atl":[[4.1,19.88],[4.2,31.25]],"id":70003364}],"con":true,"img":false}]}
{"op":"mcm","clk":"11449878880","pt":1717315568216,"mc":[{"id":"1.229554891","rc":[{"atb":[[1.42,0]],"id":70003365}],"con":true,"img":false}]}
{"op":"mcm","clk":"11449878890","pt":1717315568316,"mc":[{"id":"1.229554891","rc":[{"atb":[[1.3,44.05]],"id":70003365}],"con":true,"img":false}]}
{"op":"mcm","clk":"11449879932","pt":1717315578502,"mc":[{"id":"1.229554891","rc":[{"atl":[[4.1,43.12],[4.2,0]],"id":70003364}],"con":true,"img":false}]}
{"op":"mcm","clk":"11449880279","pt":1717315582027,"mc":[{"id":"1.229554891","rc":[{"atl":[[6.4,1.95]],"id":70003365}],"con":true,"img":false}]}
{"op":"mcm","clk":"11449880306","pt":1717315582237,"mc":[{"id":"1.229554891","rc":[{"atl":[[6.2,0]],"id":70003367}],"con":true,"img":false}]}
{"op":"mcm","clk":"11449880321","pt":1717315582336,"mc":[{"id":"1.229554891","rc":[{"atl":[[6.6,11.87]],"id":70003367}],"con":true,"img":false}]}
{"op":"mcm","clk":"11449880570","pt":1717315584522,"mc":[{"id":"1.229554891","rc":[{"atb":[[1.42,0]],"id":70003367},{"atb":[[1.32,0]],"id":70003365}],"con":true,"img":false}]}
{"op":"mcm","clk":"11449880648","pt":1717315585344,"mc":[{"id":"1.229554891","rc":[{"atl":[[4.1,19.88],[4.2,31.25]],"id":70003364}],"con":true,"img":false}]}
{"op":"mcm","clk":"11449881252","pt":1717315591127,"mc":[{"id":"1.229554891","rc":[{"atb":[[7.4,3.63],[5.7,7.41]],"id":70003366},{"atb":[[1.41,84.98],[1.51,45.54]],"id":70003367},{"atl":[[4.6,0.14]],"id":70003367},{"atb":[[1.01,5807.26]],"id":70003364},{"atl":[[2.64,0.31]],"id":70003364},{"atb":[[1.29,120.15],[1.39,59.56]],"id":70003365},{"atl":[[6.4,0],[3.95,0.17]],"id":70003365},{"atb":[[3.8,8.29],[3.3,15.15]],"id":70003363}],"con":true,"img":false}]}
{"op":"mcm","clk":"11449881276","pt":1717315591343,"mc":[{"id":"1.229554891","rc":[{"atl":[[6.4,3.56]],"id":70003365}],"con":true,"img":false}]}
{"op":"mcm","clk":"11449881493","pt":1717315593531,"mc":[{"id":"1.229554891","rc":[{"atl":[[5.6,0]],"id":70003367},{"atb":[[1.12,0]],"id":70003364}],"con":true,"img":false}]}
{"op":"mcm","clk":"11449881507","pt":1717315593631,"mc":[{"id":"1.229554891","rc":[{"atl":[[6.4,6.97]],"id":70003367},{"atb":[[1.1,558.75]],"id":70003364}],"con":true,"img":false}]}
{"op":"mcm","clk":"11449881713","pt":1717315595757,"mc":[{"id":"1.229554891","rc":[{"atb":[[1.52,0]],"id":70003367}],"con":true,"img":false}]}
{"op":"mcm","clk":"11449881739","pt":1717315596021,"mc":[{"id":"1.229554891","rc":[{"atb":[[1.53,7.41]],"id":70003367}],"con":true,"img":false}]}
{"op":"mcm","clk":"11449882679","pt":1717315605569,"mc":[{"id":"1.229554891","rc":[{"atl":[[42,0]],"id":70003363}],"con":true,"img":false}]}
{"op":"mcm","clk":"11449882691","pt":1717315605634,"mc":[{"id":"1.229554891","rc":[{"atl":[[50,2.61]],"id":70003363}],"con":true,"img":false}]}
{"op":"mcm","clk":"11449884190","pt":1717315620172,"mc":[{"id":"1.229554891","rc":[{"atb":[[1.3,0]],"id":70003365},{"atb":[[3.55,0]],"id":70003363}],"con":true,"img":false}]}
{"op":"mcm","clk":"11449884202","pt":1717315620275,"mc":[{"id":"1.229554891","rc":[{"atb":[[1.4,44.05]],"id":70003365},{"atb":[[3.85,16.09]],"id":70003363}],"con":true,"img":false}]}
{"op":"mcm","clk":"11449884359","pt":1717315621790,"mc":[{"id":"1.229554891","rc":[{"atl":[[6.4,0]],"id":70003365}],"con":true,"img":false}]}
{"op":"mcm","clk":"11449884569","pt":1717315623569,"mc":[{"id":"1.229554891","rc":[{"atl":[[6.4,1.85]],"id":70003365}],"con":true,"img":false}]}
{"op":"mcm","clk":"11449884747","pt":1717315625085,"mc":[{"id":"1.229554891","rc":[{"atb":[[1.43,9.91]],"id":70003367}],"con":true,"img":false}]}
{"op":"mcm","clk":"11449884773","pt":1717315625289,"mc":[{"id":"1.229554891","rc":[{"atb":[[1.41,10.39]],"id":70003365}],"con":true,"img":false}]}
{"op":"mcm","clk":"11449885402","pt":1717315631567,"mc":[{"id":"1.229554891","rc":[{"atl":[[5.5,0],[5.3,11.88]],"id":70003367},{"spn":3.06,"spf":"NaN","id":70003367},{"spn":1.88,"spf":"NaN","id":70003364},{"spn":2.69,"spf":"NaN","id":70003365},{"spn":23.92,"spf":"NaN","id":70003363}],"con":true,"img":false}]}
{"op":"mcm","clk":"11449885858","pt":1717315635873,"mc":[{"id":"1.229554891","rc":[{"atb":[[2,0],[2.3,31.25]],"id":70003363}],"con":true,"img":false}]}
{"op":"mcm","clk":"11449886080","pt":1717315638004,"mc":[{"id":"1.229554891","rc":[{"atl":[[6.4,0]],"id":70003365}],"con":true,"img":false}]}
{"op":"mcm","clk":"11449886361","pt":1717315641012,"mc":[{"id":"1.229554891","rc":[{"atb":[[2,32.2],[2.3,0]],"id":70003363}],"con":true,"img":false}]}
{"op":"mcm","clk":"11449886549","pt":1717315642812,"mc":[{"id":"1.229554891","rc":[{"atb":[[7.4,0],[5.7,0]],"id":70003366},{"atb":[[1.41,0],[1.51,0]],"id":70003367},{"atl":[[4.6,0]],"id":70003367},{"atb":[[1.01,0]],"id":70003364},{"atl":[[2.64,0]],"id":70003364},{"atb":[[1.29,0],[1.39,0]],"id":70003365},{"atl":[[3.95,0]],"id":70003365},{"atb":[[3.8,0],[3.3,0]],"id":70003363}],"con":true,"img":false}]}
{"op":"mcm","clk":"11449886576","pt":1717315643026,"mc":[{"id":"1.229554891","rc":[{"atl":[[5.3,0],[5.4,15.01]],"id":70003367},{"atl":[[4.1,43.12],[4.2,0]],"id":70003364}],"con":true,"img":false}]}
{"op":"mcm","clk":"11449886589","pt":1717315643084,"mc":[{"id":"1.229554891","rc":[{"atb":[[1.4,0]],"id":70003365},{"atl":[[6,10.31]],"id":70003365},{"atb":[[3.85,0]],"id":70003363}],"con":true,"img":false}]}
{"op":"mcm","clk":"11449886601","pt":1717315643188,"mc":[{"id":"1.229554891","rc":[{"atb":[[1.29,44.05]],"id":70003365},{"atl":[[6.8,6.53]],"id":70003365},{"atb":[[3.5,16.09]],"id":70003363}],"con":true,"img":false}]}
{"op":"mcm","clk":"11449886613","pt":1717315643299,"mc":[{"id":"1.229554891","rc":[{"atl":[[6,0],[6.8,23.77]],"id":70003365}],"con":true,"img":false}]}
{"op":"mcm","clk":"11449886702","pt":1717315644084,"mc":[{"id":"1.229554891","rc":[{"atl":[[6.6,2.17]],"id":70003365}],"con":true,"img":false}]}
{"op":"mcm","clk":"11449886771","pt":1717315644810,"mc":[{"id":"1.229554891","rc":[{"atb":[[1.44,0]],"id":70003365}],"con":true,"img":false}]}
{"op":"mcm","clk":"11449886826","pt":1717315645287,"mc":[{"id":"1.229554891","rc":[{"atb":[[2,0],[2.2,37.24]],"id":70003363}],"con":true,"img":false}]}
{"op":"mcm","clk":"11449886884","pt":1717315645915,"mc":[{"id":"1.229554891","rc":[{"atb":[[2,42.28],[2.2,0]],"id":70003363}],"con":true,"img":false}]}
{"op":"mcm","clk":"11449887294","pt":1717315649705,"mc":[{"id":"1.229554891","rc":[{"atb":[[2,0],[2.2,37.24]],"id":70003363}],"con":true,"img":false}]}
{"op":"mcm","clk":"11449887808","pt":1717315654979,"mc":[{"id":"1.229554891","rc":[{"atb":[[1.3,13.08]],"id":70003365}],"con":true,"img":false}]}
{"op":"mcm","clk":"11449887881","pt":1717315655703,"mc":[{"id":"1.229554891","rc":[{"atb":[[2,42.28],[2.2,0]],"id":70003363}],"con":true,"img":false}]}
{"op":"mcm","clk":"11449888516","pt":1717315662234,"mc":[{"id":"1.229554891","rc":[{"atb":[[8,3.31],[6,6.96]],"id":70003366},{"atb":[[1.57,40.75],[1.47,74.13]],"id":70003367},{"atl":[[5.2,0.12]],"id":70003367},{"atb":[[1.01,5807.26]],"id":70003364},{"atl":[[2.52,0.34]],"id":70003364},{"atb":[[1.44,52.79],[1.34,102.47]],"id":70003365},{"atl":[[4.2,0.16]],"id":70003365},{"atb":[[3.4,14.51],[3.9,8]],"id":70003363}],"con":true,"img":false}]}
{"op":"mcm","clk":"11449888667","pt":1717315663740,"mc":[{"id":"1.229554891","rc":[{"atl":[[6.4,0]],"id":70003367},{"atl":[[6.8,17.24]],"id":70003365}],"con":true,"img":false}]}
{"op":"mcm","clk":"11449888675","pt":1717315663792,"mc":[{"id":"1.229554891","rc":[{"atl":[[5.7,6.97]],"id":70003367},{"atl":[[6,6.53]],"id":70003365}],"con":true,"img":false}]}
{"op":"mcm","clk":"11449888701","pt":1717315664001,"mc":[{"id":"1.229554891","rc":[{"atl":[[6.8,0],[5.9,6.54]],"id":70003365}],"con":true,"img":false}]}
{"op":"mcm","clk":"11449889123","pt":1717315668547,"mc":[{"id":"1.229554891","rc":[{"atb":[[1.43,0]],"id":70003367},{"atb":[[1.41,0]],"id":70003365}],"con":true,"img":false}]}
{"op":"mcm","clk":"11449889293","pt":1717315670244,"mc":[{"id":"1.229554891","rc":[{"atb":[[1.53,0]],"id":70003367},{"atb":[[1.3,0]],"id":70003365}],"con":true,"img":false}]}
{"op":"mcm","clk":"11449889314","pt":1717315670450,"mc":[{"id":"1.229554891","rc":[{"atb":[[1.59,6.65]],"id":70003367},{"atb":[[1.46,8.53]],"id":70003365}],"con":true,"img":false}]}
{"op":"mcm","clk":"11449890432","pt":1717315681744,"mc":[{"id":"1.229554891","rc":[{"atl":[[6.6,0]],"id":70003365}],"con":true,"img":false}]}
{"op":"mcm","clk":"11449890484","pt":1717315682161,"mc":[{"id":"1.229554891","rc":[{"atl":[[6.4,1.95]],"id":70003365}],"con":true,"img":false}]}
{"op":"mcm","clk":"11449890544","pt":1717315682623,"mc":[{"id":"1.229554891","rc":[{"atb":[[1.1,0]],"id":70003364},{"atl":[[50,0]],"id":70003363}],"con":true,"img":false}]}
{"op":"mcm","clk":"11449890558","pt":1717315682728,"mc":[{"id":"1.229554891","rc":[{"atb":[[1.11,558.75]],"id":70003364},{"atl":[[42,2.61]],"id":70003363}],"con":true,"img":false}]}
{"op":"mcm","clk":"11449891072","pt":1717315687657,"mc":[{"id":"1.229554891","rc":[{"atl":[[6.4,0]],"id":70003365}],"con":true,"img":false}]}
{"op":"mcm","clk":"11449891102","pt":1717315687963,"mc":[{"id":"1.229554891","rc":[{"atl":[[6.4,3.56]],"id":70003365}],"con":true,"img":false}]}
{"op":"mcm","clk":"11449891278","pt":1717315689626,"mc":[{"id":"1.229554891","rc":[{"atl":[[5.7,0]],"id":70003367}],"con":true,"img":false}]}
{"op":"mcm","clk":"11449891288","pt":1717315689731,"mc":[{"id":"1.229554891","rc":[{"atl":[[5.3,6.97]],"id":70003367}],"con":true,"img":false}]}
{"op":"mcm","clk":"11449891504","pt":1717315692164,"mc":[{"id":"1.229554891","rc":[{"spn":3.19,"spf":"NaN","id":70003367},{"spn":1.82,"spf":"NaN","id":70003364},{"atb":[[1.29,0]],"id":70003365},{"spn":2.83,"spf":"NaN","id":70003365},{"atb":[[3.5,0]],"id":70003363},{"spn":22.95,"spf":"NaN","id":70003363}],"con":true,"img":false}]}
{"op":"mcm","clk":"11449891514","pt":1717315692267,"mc":[{"id":"1.229554891","rc":[{"atb":[[1.45,44.05]],"id":70003365},{"atb":[[3.55,16.09]],"id":70003363}],"con":true,"img":false}]}
{"op":"mcm","clk":"11449892400","pt":1717315700371,"mc":[{"id":"1.229554891","rc":[{"atb":[[1.46,0]],"id":70003365}],"con":true,"img":false}]}
{"op":"mcm","clk":"11449892422","pt":1717315700573,"mc":[{"id":"1.229554891","rc":[{"atb":[[1.47,8.35]],"id":70003365}],"con":true,"img":false}]}
{"op":"mcm","clk":"11449892541","pt":1717315701659,"mc":[{"id":"1.229554891","rc":[{"atb":[[8.2,0]],"id":70003366}],"con":true,"img":false}]}
{"op":"mcm","clk":"11449892552","pt":1717315701768,"mc":[{"id":"1.229554891","rc":[{"atb":[[8.6,6.97]],"id":70003366}],"con":true,"img":false}]}
{"op":"mcm","clk":"11449892603","pt":1717315702182,"mc":[{"id":"1.229554891","rc":[{"atb":[[3.35,0]],"id":70003363}],"con":true,"img":false}]}
{"op":"mcm","clk":"11449892615","pt":1717315702281,"mc":[{"id":"1.229554891","rc":[{"atb":[[3.45,21.13]],"id":70003363}],"con":true,"img":false}]}
{"op":"mcm","clk":"11449893186","pt":1717315707972,"mc":[{"id":"1.229554891","rc":[{"atb":[[1.35,12.17]],"id":70003365}],"con":true,"img":false}]}
{"op":"mcm","clk":"11449893194","pt":1717315708072,"mc":[{"id":"1.229554891","rc":[{"atb":[[1.49,8.69]],"id":70003367}],"con":true,"img":false}]}
{"op":"mcm","clk":"11449893575","pt":1717315711991,"mc":[{"id":"1.229554891","rc":[{"atb":[[8,0],[6,0]],"id":70003366},{"atb":[[1.57,0],[1.47,0]],"id":70003367},{"atl":[[5.2,0]],"id":70003367},{"atb":[[1.01,0]],"id":70003364},{"atl":[[2.52,0]],"id":70003364},{"atb":[[1.44,0],[1.34,0]],"id":70003365},{"atl":[[4.2,0]],"id":70003365},{"atb":[[3.4,0],[3.9,0]],"id":70003363}],"con":true,"img":false}]}
{"op":"mcm","clk":"11449893661","pt":1717315712681,"mc":[{"id":"1.229554891","rc":[{"atb":[[1.45,0]],"id":70003365},{"atb":[[3.45,0]],"id":70003363}],"con":true,"img":false}]}
{"op":"mcm","clk":"11449893671","pt":1717315712774,"mc":[{"id":"1.229554891","rc":[{"atb":[[1.3,44.05]],"id":70003365},{"atb":[[3.15,21.13]],"id":70003363}],"con":true,"img":false}]}
{"op":"mcm","clk":"11449894190","pt":1717315717676,"mc":[{"id":"1.229554891","rc":[{"atb":[[5.5,0],[4.7,21.08]],"id":70003366}],"con":true,"img":false}]}
{"op":"mcm","clk":"11449894211","pt":1717315717834,"mc":[{"id":"1.229554891","rc":[{"atl":[[6.4,0]],"id":70003365}],"con":true,"img":false}]}
{"op":"mcm","clk":"11449894231","pt":1717315718044,"mc":[{"id":"1.229554891","rc":[{"atl":[[4.8,0]],"id":70003367}],"con":true,"img":false}]}
{"op":"mcm","clk":"11449894243","pt":1717315718146,"mc":[{"id":"1.229554891","rc":[{"atl":[[5.5,21.98],[5.4,0]],"id":70003367}],"con":true,"img":false}]}
{"op":"mcm","clk":"11449894254","pt":1717315718248,"mc":[{"id":"1.229554891","rc":[{"atl":[[6.2,1.83]],"id":70003365}],"con":true,"img":false}]}
{"op":"mcm","clk":"11449894327","pt":1717315718880,"mc":[{"id":"1.229554891","rc":[{"atl":[[4.7,1.97]],"id":70003367}],"con":true,"img":false}]}
{"op":"mcm","clk":"11449894800","pt":1717315722648,"mc":[{"id":"1.229554891","rc":[{"atb":[[7.6,8.3],[7,0]],"id":70003366}],"con":true,"img":false}]}
{"op":"mcm","clk":"11449896633","pt":1717315740688,"mc":[{"id":"1.229554891","rc":[{"atb":[[7.2,2.5],[6.4,5],[5.8,10],[8.8,8.69]],"id":70003366},{"atl":[[34,5],[160,0.5],[28,2.5]],"id":70003366},{"atb":[[1.59,18.39],[1.46,10],[1.54,2.5],[1.5,5]],"id":70003367},{"atl":[[2.88,2.5],[4.6,11.74],[3.1,10],[2.96,5]],"id":70003367},{"atb":[[1.12,2.5],[1.13,160.41],[1.08,5],[1.04,10]],"id":70003364},{"atl":[[1.83,2.5],[1.91,10],[3.8,28.57],[1.87,5]],"id":70003364},{"atb":[[1.56,2.5],[1.48,10],[1.47,19.52],[1.52,5]],"id":70003365},{"atl":[[5.8,11.17],[3.1,2.5],[3.3,5],[3.5,10]],"id":70003365}],"con":true,"img":false}]}
{"op":"mcm","clk":"11449896641","pt":1717315740743,"mc":[{"id":"1.229554891","rc":[{"atl":[[65,2],[180,2.61]],"id":70003366}],"con":true,"img":false}]}
{"op":"mcm","clk":"11449896651","pt":1717315740850,"mc":[{"id":"1.229554891","rc":[{"atl":[[65,0],[160,2.5]],"id":70003366}],"con":true,"img":false}]}
{"op":"mcm","clk":"11449896659","pt":1717315740952,"mc":[{"id":"1.229554891","rc":[{"atl":[[65,2],[160,0.5]],"id":70003366}],"con":true,"img":false}]}
{"op":"mcm","clk":"11449896666","pt":1717315741056,"mc":[{"id":"1.229554891","rc":[{"atl":[[160,2.5]],"id":70003366}],"con":true,"img":false}]}
{"op":"mcm","clk":"11449896679","pt":1717315741163,"mc":[{"id":"1.229554891","rc":[{"atl":[[65,0]],"id":70003366}],"con":true,"img":false}]}
{"op":"mcm","clk":"11449896691","pt":1717315741272,"mc":[{"id":"1.229554891","rc":[{"atl":[[65,2],[160,0.5]],"id":70003366}],"con":true,"img":false}]}
{"op":"mcm","clk":"11449896797","pt":1717315742148,"mc":[{"id":"1.229554891","rc":[{"atl":[[4.7,0]],"id":70003367}],"con":true,"img":false}]}
{"op":"mcm","clk":"11449896887","pt":1717315742884,"mc":[{"id":"1.229554891","rc":[{"atb":[[8,3.31],[6,6.96]],"id":70003366},{"atb":[[1.48,48.39],[1.38,91.69]],"id":70003367},{"atl":[[4.4,0.15]],"id":70003367},{"atb":[[1.01,5807.26]],"id":70003364},{"atl":[[2.46,0.35]],"id":70003364},{"atb":[[1.56,43.98],[1.46,75.74]],"id":70003365},{"atl":[[5.1,0.12]],"id":70003365},{"atb":[[3.45,14.21],[3.95,7.87]],"id":70003363}],"con":true,"img":false}]}
{"op":"mcm","clk":"11449896911","pt":1717315743088,"mc":[{"id":"1.229554891","rc":[{"atb":[[6.6,15.09]],"id":70003366},{"atb":[[1.22,160.9]],"id":70003367},{"atl":[[8.2,40.61]],"id":70003367},{"atb":[[1.09,252.18]],"id":70003364},{"atl":[[8.8,37.85]],"id":70003365},{"atl":[[65,5.12]],"id":70003363}],"con":true,"img":false}]}
{"op":"mcm","clk":"11449896925","pt":1717315743190,"mc":[{"id":"1.229554891","rc":[{"atb":[[7.6,0]],"id":70003366},{"atl":[[180,0]],"id":70003366},{"atb":[[1.25,0]],"id":70003367},{"atl":[[6.6,0]],"id":70003367},{"atb":[[1.11,0]],"id":70003364},{"atb":[[1.26,0]],"id":70003365},{"atl":[[7,0]],"id":70003365},{"atl":[[42,0]],"id":70003363}],"con":true,"img":false}]}
{"op":"mcm","clk":"11449896937","pt":1717315743247,"mc":[{"id":"1.229554891","rc":[{"atl":[[250,2.61]],"id":70003366},{"atb":[[1.23,184.04]],"id":70003365}],"con":true,"img":false}]}
{"op":"mcm","clk":"11449897217","pt":1717315745591,"mc":[{"id":"1.229554891","rc":[{"atb":[[1.49,0]],"id":70003367},{"atb":[[1.35,0]],"id":70003365}],"con":true,"img":false}]}
{"op":"mcm","clk":"11449897252","pt":1717315745850,"mc":[{"id":"1.229554891","rc":[{"atb":[[1.59,11.74]],"id":70003367}],"con":true,"img":false}]}
{"op":"mcm","clk":"11449897265","pt":1717315745954,"mc":[{"id":"1.229554891","rc":[{"atb":[[1.59,0]],"id":70003367}],"con":true,"img":false}]}
{"op":"mcm","clk":"11449897275","pt":1717315746058,"mc":[{"id":"1.229554891","rc":[{"atb":[[1.51,5.62]],"id":70003367}],"con":true,"img":false}]}
{"op":"mcm","clk":"11449898072","pt":1717315753603,"mc":[{"id":"1.229554891","rc":[{"spn":18.4,"spf":"NaN","id":70003366},{"spn":2.21,"spf":"NaN","id":70003367},{"atl":[[4.1,99.02]],"id":70003364},{"spn":1.48,"spf":"NaN","id":70003364},{"spn":2.33,"spf":"NaN","id":70003365},{"spn":23.97,"spf":"NaN","id":70003363}],"con":true,"img":false}]}
{"op":"mcm","clk":"11449898288","pt":1717315755587,"mc":[{"id":"1.229554891","rc":[{"atb":[[3.15,36.16]],"id":70003363}],"con":true,"img":false}]}
{"op":"mcm","clk":"11449898343","pt":1717315756106,"mc":[{"id":"1.229554891","rc":[{"atl":[[3.85,0]],"id":70003364}],"con":true,"img":false}]}
{"op":"mcm","clk":"11449898352","pt":1717315756209,"mc":[{"id":"1.229554891","rc":[{"atl":[[3.5,11.62]],"id":70003364}],"con":true,"img":false}]}
{"op":"mcm","clk":"11449898449","pt":1717315757095,"mc":[{"id":"1.229554891","rc":[{"atl":[[42,0.95],[44,2.33]],"id":70003363}],"con":true,"img":false}]}
{"op":"mcm","clk":"11449898462","pt":1717315757199,"mc":[{"id":"1.229554891","rc":[{"atl":[[44,0],[60,2]],"id":70003363}],"con":true,"img":false}]}
{"op":"mcm","clk":"11449898570","pt":1717315758192,"mc":[{"id":"1.229554891","rc":[{"atl":[[27,3.08]],"id":70003366},{"atb":[[1.54,10]],"id":70003367},{"atl":[[2.84,7.5]],"id":70003367},{"atl":[[1.82,11.25]],"id":70003364},{"atb":[[1.56,55.23]],"id":70003365},{"atl":[[3.05,11.25]],"id":70003365}],"con":true,"img":false}]}
{"op":"mcm","clk":"11449898590","pt":1717315758400,"mc":[{"id":"1.229554891","rc":[{"atl":[[160,0]],"id":70003366},{"atb":[[1.51,0]],"id":70003367},{"atl":[[4.6,0]],"id":70003367},{"atl":[[3.8,0]],"id":70003364},{"atb":[[1.47,8.35]],"id":70003365},{"atl":[[5.8,0]],"id":70003365}],"con":true,"img":false}]}
{"op":"mcm","clk":"11449898613","pt":1717315758607,"mc":[{"id":"1.229554891","rc":[{"atl":[[140,0.28],[170,0]],"id":70003366}],"con":true,"img":false}]}
{"op":"mcm","clk":"11449898661","pt":1717315759078,"mc":[{"id":"1.229554891","rc":[{"atb":[[3.7,38.83]],"id":70003366},{"atl":[[9.6,27.58]],"id":70003367},{"atb":[[2.82,41.09]],"id":70003363}],"con":true,"img":false}]}
{"op":"mcm","clk":"11449898668","pt":1717315759180,"mc":[{"id":"1.229554891","rc":[{"atb":[[6.6,0]],"id":70003366},{"atl":[[8.2,0]],"id":70003367},{"atb":[[3.15,0]],"id":70003363}],"con":true,"img":false}]}
{"op":"mcm","clk":"11449898806","pt":1717315760615,"mc":[{"id":"1.229554891","rc":[{"atb":[[1.5,12.85]],"id":70003367}],"con":true,"img":false}]}
{"op":"mcm","clk":"11449898903","pt":1717315761600,"mc":[{"id":"1.229554891","rc":[{"atb":[[8.6,0]],"id":70003366}],"con":true,"img":false}]}
{"op":"mcm","clk":"11449898913","pt":1717315761703,"mc":[{"id":"1.229554891","rc":[{"atb":[[6.2,6.97]],"id":70003366}],"con":true,"img":false}]}
{"op":"mcm","clk":"11449898925","pt":1717315761806,"mc":[{"id":"1.229554891","rc":[{"atb":[[8.8,0]],"id":70003366}],"con":true,"img":false}]}
{"op":"mcm","clk":"11449898934","pt":1717315761907,"mc":[{"id":"1.229554891","rc":[{"atb":[[8.4,4.8]],"id":70003366}],"con":true,"img":false}]}
{"op":"mcm","clk":"11449898952","pt":1717315762117,"mc":[{"id":"1.229554891","rc":[{"atb":[[8.4,0]],"id":70003366}],"con":true,"img":false}]}
{"op":"mcm","clk":"11449898967","pt":1717315762223,"mc":[{"id":"1.229554891","rc":[{"atb":[[7.6,4.19]],"id":70003366}],"con":true,"img":false}]}
{"op":"mcm","clk":"11449899173","pt":1717315764100,"mc":[{"id":"1.229554891","rc":[{"atb":[[1.3,0]],"id":70003367},{"atl":[[5.3,0]],"id":70003367},{"atb":[[3.55,0]],"id":70003363}],"con":true,"img":false}]}
{"op":"mcm","clk":"11449899184","pt":1717315764195,"mc":[{"id":"1.229554891","rc":[{"atb":[[1.39,49.24]],"id":70003367},{"atl":[[5.4,6.97]],"id":70003367},{"atb":[[3.5,16.09]],"id":70003363}],"con":true,"img":false}]}
{"op":"mcm","clk":"11449899225","pt":1717315764607,"mc":[{"id":"1.229554891","rc":[{"atb":[[1.3,0]],"id":70003365}],"con":true,"img":false}]}
{"op":"mcm","clk":"11449899234","pt":1717315764715,"mc":[{"id":"1.229554891","rc":[{"atb":[[1.38,44.05]],"id":70003365}],"con":true,"img":false}]}
{"op":"mcm","clk":"11449900112","pt":1717315773113,"mc":[{"id":"1.229554891","rc":[{"atb":[[1.13,41.05]],"id":70003364}],"con":true,"img":false}]}
{"op":"mcm","clk":"11449900123","pt":1717315773214,"mc":[{"id":"1.229554891","rc":[{"atb":[[1.14,119.36]],"id":70003364}],"con":true,"img":false}]}
{"op":"mcm","clk":"11449900136","pt":1717315773319,"mc":[{"id":"1.229554891","rc":[{"atb":[[1.14,131.55]],"id":70003364}],"con":true,"img":false}]}
{"op":"mcm","clk":"11449900148","pt":1717315773424,"mc":[{"id":"1.229554891","rc":[{"atb":[[1.13,0]],"id":70003364}],"con":true,"img":false}]}
{"op":"mcm","clk":"11449900166","pt":1717315773631,"mc":[{"id":"1.229554891","rc":[{"atl":[[42,0]],"id":70003363}],"con":true,"img":false}]}
{"op":"mcm","clk":"11449900179","pt":1717315773735,"mc":[{"id":"1.229554891","rc":[{"atl":[[38,0.95]],"id":70003363}],"con":true,"img":false}]}
{"op":"mcm","clk":"11449900328","pt":1717315775134,"mc":[{"id":"1.229554891","rc":[{"atl":[[32,1.26],[140,0]],"id":70003366}],"con":true,"img":false}]}
{"op":"mcm","clk":"11449900417","pt":1717315775907,"mc":[{"id":"1.229554891","rc":[{"atb":[[1.5,5]],"id":70003367},{"atb":[[1.47,0]],"id":70003365}],"con":true,"img":false}]}
{"op":"mcm","clk":"11449900726","pt":1717315779029,"mc":[{"id":"1.229554891","rc":[{"atb":[[8.2,4.19]],"id":70003366}],"con":true,"img":false}]}
{"op":"mcm","clk":"11449900744","pt":1717315779238,"mc":[{"id":"1.229554891","rc":[{"atb":[[7.6,0]],"id":70003366}],"con":true,"img":false}]}
{"op":"mcm","clk":"11449900865","pt":1717315780641,"mc":[{"id":"1.229554891","rc":[{"atl":[[8.8,26.76]],"id":70003365}],"con":true,"img":false}]}
{"op":"mcm","clk":"11449901494","pt":1717315786646,"mc":[{"id":"1.229554891","rc":[{"atl":[[65,0]],"id":70003363}],"con":true,"img":false}]}
{"op":"mcm","clk":"11449901510","pt":1717315786747,"mc":[{"id":"1.229554891","rc":[{"atl":[[55,5.12],[240,2]],"id":70003363}],"con":true,"img":false}]}
{"op":"mcm","clk":"11449901522","pt":1717315786849,"mc":[{"id":"1.229554891","rc":[{"atl":[[60,0]],"id":70003363}],"con":true,"img":false}]}
{"op":"mcm","clk":"11449901656","pt":1717315788156,"mc":[{"id":"1.229554891","rc":[{"atb":[[1.09,0]],"id":70003364}],"con":true,"img":false}]}
{"op":"mcm","clk":"11449901666","pt":1717315788260,"mc":[{"id":"1.229554891","rc":[{"atb":[[1.1,252.18]],"id":70003364}],"con":true,"img":false}]}
{"op":"mcm","clk":"11449901705","pt":1717315788632,"mc":[{"id":"1.229554891","rc":[{"atl":[[250,0]],"id":70003366},{"atb":[[1.26,133.29],[1.23,0]],"id":70003365}],"con":true,"img":false}]}
{"op":"mcm","clk":"11449901715","pt":1717315788744,"mc":[{"id":"1.229554891","rc":[{"atl":[[110,2.61]],"id":70003366}],"con":true,"img":false}]}
{"op":"mcm","clk":"11449902324","pt":1717315794657,"mc":[{"id":"1.229554891","rc":[{"atl":[[6,0]],"id":70003365},{"atl":[[50,2],[240,0]],"id":70003363}],"con":true,"img":false}]}
{"op":"mcm","clk":"11449902334","pt":1717315794759,"mc":[{"id":"1.229554891","rc":[{"atl":[[5.8,6.53]],"id":70003365}],"con":true,"img":false}]}
{"op":"mcm","clk":"11449902388","pt":1717315795340,"mc":[{"id":"1.229554891","rc":[{"atb":[[1.4,10.65]],"id":70003367}],"con":true,"img":false}]}
{"op":"mcm","clk":"11449902399","pt":1717315795437,"mc":[{"id":"1.229554891","rc":[{"atb":[[2.9,2.24]],"id":70003363}],"con":true,"img":false}]}
{"op":"mcm","clk":"11449903233","pt":1717315803758,"mc":[{"id":"1.229554891","rc":[{"atb":[[8,0],[6,0]],"id":70003366},{"atb":[[1.48,0],[1.38,0]],"id":70003367},{"atl":[[4.4,0]],"id":70003367},{"atb":[[1.01,0]],"id":70003364},{"atl":[[2.46,0]],"id":70003364},{"atb":[[1.56,13.75],[1.46,0]],"id":70003365},{"atl":[[5.1,0]],"id":70003365},{"atb":[[3.45,0],[3.95,0]],"id":70003363}],"con":true,"img":false}]}
{"op":"mcm","clk":"11449903249","pt":1717315803868,"mc":[{"id":"1.229554891","rc":[{"atb":[[8.2,0]],"id":70003366}],"con":true,"img":false}]}
{"op":"mcm","clk":"11449903261","pt":1717315803968,"mc":[{"id":"1.229554891","rc":[{"atb":[[7.8,4.19]],"id":70003366}],"con":true,"img":false}]}
{"op":"mcm","clk":"11449903285","pt":1717315804126,"mc":[{"id":"1.229554891","rc":[{"atb":[[7.8,0]],"id":70003366},{"atl":[[110,0]],"id":70003366},{"atb":[[1.39,0]],"id":70003367},{"atb":[[1.14,12.19]],"id":70003364},{"atb":[[1.38,0]],"id":70003365}],"con":true,"img":false}]}
{"op":"mcm","clk":"11449903299","pt":1717315804232,"mc":[{"id":"1.229554891","rc":[{"atb":[[7.4,4.19]],"id":70003366},{"atl":[[180,2.61]],"id":70003366},{"atb":[[1.29,49.24]],"id":70003367},{"atb":[[1.12,121.86]],"id":70003364},{"atb":[[1.31,44.05]],"id":70003365}],"con":true,"img":false}]}
{"op":"mcm","clk":"11449903307","pt":1717315804337,"mc":[{"id":"1.229554891","rc":[{"atb":[[1.14,0]],"id":70003364}],"con":true,"img":false}]}
{"op":"mcm","clk":"11449903317","pt":1717315804442,"mc":[{"id":"1.229554891","rc":[{"atb":[[1.12,139.44]],"id":70003364}],"con":true,"img":false}]}
{"op":"mcm","clk":"11449903567","pt":1717315806640,"mc":[{"id":"1.229554891","rc":[{"atl":[[2.8,9.38],[2.82,2.5],[2.88,0],[2.9,5],[3.1,0],[2.98,10],[2.96,0]],"id":70003367}],"con":true,"img":false}]}
{"op":"mcm","clk":"11449903572","pt":1717315806745,"mc":[{"id":"1.229554891","rc":[{"atl":[[2.84,0]],"id":70003367}],"con":true,"img":false}]}
{"op":"mcm","clk":"11449903649","pt":1717315807369,"mc":[{"id":"1.229554891","rc":[{"atl":[[180,0]],"id":70003366}],"con":true,"img":false}]}
{"op":"mcm","clk":"11449903661","pt":1717315807475,"mc":[{"id":"1.229554891","rc":[{"atl":[[200,2.61]],"id":70003366}],"con":true,"img":false}]}
{"op":"mcm","clk":"11449904066","pt":1717315811681,"mc":[{"id":"1.229554891","rc":[{"atl":[[32,0],[160,0.26]],"id":70003366}],"con":true,"img":false}]}
{"op":"mcm","clk":"11449905035","pt":1717315821653,"mc":[{"id":"1.229554891","rc":[{"atb":[[8,3.31],[6,6.96]],"id":70003366},{"spn":17.5,"spf":"NaN","id":70003366},{"atb":[[1.45,77.43],[1.55,42.23]],"id":70003367},{"atl":[[5,0.13]],"id":70003367},{"spn":2.17,"spf":"NaN","id":70003367},{"atb":[[1.01,5807.26],[1.1,614.73]],"id":70003364},{"atl":[[2.46,0.35]],"id":70003364},{"spn":1.47,"spf":"NaN","id":70003364},{"atb":[[1.43,81.02],[1.26,190.86],[1.53,43.82]],"id":70003365},{"atl":[[4.8,0.13]],"id":70003365},{"spn":2.3,"spf":"NaN","id":70003365},{"atb":[[3.25,15.48],[3.75,8.44]],"id":70003363},{"atl":[[38,2.61]],"id":70003363},{"spn":20.87,"spf":"NaN","id":70003363}],"con":true,"img":false}]}
{"op":"mcm","clk":"11449905046","pt":1717315821809,"mc":[{"id":"1.229554891","rc":[{"atb":[[8.2,4.8]],"id":70003366},{"atb":[[1.55,53.01]],"id":70003367},{"atl":[[38,5.23],[50,0]],"id":70003363}],"con":true,"img":false}]}
{"op":"mcm","clk":"11449905070","pt":1717315821972,"mc":[{"id":"1.229554891","rc":[{"atb":[[7.4,0]],"id":70003366},{"atb":[[1.54,2.5]],"id":70003367}],"con":true,"img":false}]}
{"op":"mcm","clk":"11449905084","pt":1717315822175,"mc":[{"id":"1.229554891","rc":[{"atb":[[6.2,0]],"id":70003366},{"atl":[[200,0]],"id":70003366},{"atl":[[55,0]],"id":70003363}],"con":true,"img":false}]}
{"op":"mcm","clk":"11449905103","pt":1717315822382,"mc":[{"id":"1.229554891","rc":[{"atb":[[8.2,11.77]],"id":70003366},{"atl":[[290,2.61]],"id":70003366},{"atl":[[65,5.12]],"id":70003363}],"con":true,"img":false}]}
{"op":"mcm","clk":"11449905596","pt":1717315827093,"mc":[{"id":"1.229554891","rc":[{"atb":[[1.1,257.09]],"id":70003364},{"atl":[[38,3.68]],"id":70003363}],"con":true,"img":false}]}
{"op":"mcm","clk":"11449905668","pt":1717315827665,"mc":[{"id":"1.229554891","rc":[{"atb":[[8.2,4.8]],"id":70003366}],"con":true,"img":false}]}
{"op":"mcm","clk":"11449905678","pt":1717315827770,"mc":[{"id":"1.229554891","rc":[{"atb":[[6.2,6.97]],"id":70003366}],"con":true,"img":false}]}
{"op":"mcm","clk":"11449906622","pt":1717315837103,"mc":[{"id":"1.229554891","rc":[{"atb":[[1.12,20.08]],"id":70003364}],"con":true,"img":false}]}
{"op":"mcm","clk":"11449906631","pt":1717315837203,"mc":[{"id":"1.229554891","rc":[{"atb":[[1.13,119.36]],"id":70003364}],"con":true,"img":false}]}
{"op":"mcm","clk":"11449906641","pt":1717315837312,"mc":[{"id":"1.229554891","rc":[{"atb":[[1.13,142.86]],"id":70003364}],"con":true,"img":false}]}
{"op":"mcm","clk":"11449906655","pt":1717315837426,"mc":[{"id":"1.229554891","rc":[{"atb":[[1.12,2.5]],"id":70003364}],"con":true,"img":false}]}
{"op":"mcm","clk":"11449906729","pt":1717315838147,"mc":[{"id":"1.229554891","rc":[{"atl":[[160,0],[55,0.72]],"id":70003366},{"atb":[[1.29,0]],"id":70003367},{"atb":[[1.31,0]],"id":70003365},{"atb":[[2.82,0],[3.3,28.64]],"id":70003363}],"con":true,"img":false}]}
{"op":"mcm","clk":"11449906741","pt":1717315838192,"mc":[{"id":"1.229554891","rc":[{"atb":[[1.36,49.24]],"id":70003367},{"atb":[[1.44,44.05]],"id":70003365}],"con":true,"img":false}]}
{"op":"mcm","clk":"11449907420","pt":1717315845010,"mc":[{"id":"1.229554891","rc":[{"atb":[[1.4,0]],"id":70003367}],"con":true,"img":false}]}
{"op":"mcm","clk":"11449907442","pt":1717315845217,"mc":[{"id":"1.229554891","rc":[{"atb":[[1.45,9.46]],"id":70003365}],"con":true,"img":false}]}
{"op":"mcm","clk":"11449907814","pt":1717315848603,"mc":[{"id":"1.229554891","rc":[{"atl":[[3.15,18.24],[3.5,0]],"id":70003364}],"con":true,"img":false}]}
{"op":"mcm","clk":"11449907920","pt":1717315849628,"mc":[{"id":"1.229554891","rc":[{"atb":[[3.5,0]],"id":70003363}],"con":true,"img":false}]}
{"op":"mcm","clk":"11449907932","pt":1717315849733,"mc":[{"id":"1.229554891","rc":[{"atb":[[3.8,16.09]],"id":70003363}],"con":true,"img":false}]}
{"op":"mcm","clk":"11449908075","pt":1717315851229,"mc":[{"id":"1.229554891","rc":[{"atb":[[1.55,7.13]],"id":70003365}],"con":true,"img":false}]}
{"op":"mcm","clk":"11449908160","pt":1717315852123,"mc":[{"id":"1.229554891","rc":[{"atl":[[290,0]],"id":70003366}],"con":true,"img":false}]}
{"op":"mcm","clk":"11449908185","pt":1717315852314,"mc":[{"id":"1.229554891","rc":[{"atl":[[130,2.61]],"id":70003366}],"con":true,"img":false}]}
{"op":"mcm","clk":"11449908334","pt":1717315853619,"mc":[{"id":"1.229554891","rc":[{"atb":[[6.2,0]],"id":70003366}],"con":true,"img":false}]}
{"op":"mcm","clk":"11449908345","pt":1717315853713,"mc":[{"id":"1.229554891","rc":[{"atb":[[6.6,6.97]],"id":70003366}],"con":true,"img":false}]}
{"op":"mcm","clk":"11449909533","pt":1717315864621,"mc":[{"id":"1.229554891","rc":[{"atb":[[7.4,3.12],[6.2,24.04],[6.6,20.36],[7,8.33]],"id":70003366},{"atl":[[32,2.42],[36,3.57],[27,4.08],[29,1.79]],"id":70003366},{"atb":[[1.02,258.87],[1.06,250],[1.08,255],[1.04,260]],"id":70003364},{"atl":[[2.22,102.46],[2.18,63.56],[2.1,18.18],[2.14,43.86]],"id":70003364},{"atl":[[2.5,83.33],[2.4,13.79],[2.42,35.21],[2.38,14.49],[2.46,51.37]],"id":70003365},{"atb":[[3.2,34.09],[3.1,59.52],[3.4,8.33],[3.3,50.38]],"id":70003363},{"atl":[[11,2],[12,4.55],[13,6.25],[14,9.62]],"id":70003363}],"con":true,"img":false}]}
{"op":"mcm","clk":"11449909544","pt":1717315864730,"mc":[{"id":"1.229554891","rc":[{"atl":[[3.05,0]],"id":70003365},{"atl":[[38,1.06],[24,3.68]],"id":70003363}],"con":true,"img":false}]}
{"op":"mcm","clk":"11449909635","pt":1717315865654,"mc":[{"id":"1.229554891","rc":[{"atb":[[2.56,51.56],[3.3,21.74]],"id":70003363}],"con":true,"img":false}]}
{"op":"mcm","clk":"11449909765","pt":1717315866744,"mc":[{"id":"1.229554891","rc":[{"atb":[[1.17,100]],"id":70003366},{"atb":[[1.17,100]],"id":70003363}],"con":true,"img":false}]}
{"op":"mcm","clk":"11449910094","pt":1717315870127,"mc":[{"id":"1.229554891","rc":[{"atb":[[8,0],[6,0]],"id":70003366},{"atb":[[1.45,0],[1.55,10.78]],"id":70003367},{"atl":[[5,0]],"id":70003367},{"atb":[[1.01,0]],"id":70003364},{"atl":[[2.46,0]],"id":70003364},{"atb":[[1.43,0],[1.53,0]],"id":70003365},{"atl":[[4.8,0]],"id":70003365},{"atb":[[3.25,0],[3.75,0]],"id":70003363}],"con":true,"img":false}]}
{"op":"mcm","clk":"11449910119","pt":1717315870336,"mc":[{"id":"1.229554891","rc":[{"atb":[[8.2,0]],"id":70003366}],"con":true,"img":false}]}
{"op":"mcm","clk":"11449910133","pt":1717315870441,"mc":[{"id":"1.229554891","rc":[{"atb":[[7.8,3.75]],"id":70003366}],"con":true,"img":false}]}
{"op":"mcm","clk":"11449910160","pt":1717315870648,"mc":[{"id":"1.229554891","rc":[{"atb":[[7.8,0]],"id":70003366},{"atb":[[1.44,0]],"id":70003365}],"con":true,"img":false}]}
{"op":"mcm","clk":"11449910172","pt":1717315870746,"mc":[{"id":"1.229554891","rc":[{"atb":[[7.6,4.22]],"id":70003366},{"atb":[[1.29,44.05]],"id":70003365}],"con":true,"img":false}]}
{"op":"mcm","clk":"11449910816","pt":1717315876542,"mc":[{"id":"1.229554891","rc":[{"atb":[[7.2,0],[6.4,0],[5.8,0],[7.4,5.62]],"id":70003366},{"atb":[[1.36,104.8],[1.32,234.37],[1.3,250],[1.34,147.06]],"id":70003367},{"atl":[[4.8,32.89],[4.6,20.83],[4.4,14.71],[4.2,6.25]],"id":70003367},{"atl":[[3.1,0],[3.3,0],[3.5,0],[6.2,0]],"id":70003365}],"con":true,"img":false}]}
{"op":"mcm","clk":"11449910940","pt":1717315877636,"mc":[{"id":"1.229554891","rc":[{"atb":[[3.8,0]],"id":70003363}],"con":true,"img":false}]}
{"op":"mcm","clk":"11449910952","pt":1717315877766,"mc":[{"id":"1.229554891","rc":[{"atb":[[3.45,16.09]],"id":70003363}],"con":true,"img":false}]}
{"op":"mcm","clk":"11449911147","pt":1717315879657,"mc":[{"id":"1.229554891","rc":[{"atl":[[2.38,35.15]],"id":70003365}],"con":true,"img":false}]}
{"op":"mcm","clk":"11449911158","pt":1717315879756,"mc":[{"id":"1.229554891","rc":[{"atl":[[2.4,0]],"id":70003365}],"con":true,"img":false}]}
{"op":"mcm","clk":"11449911302","pt":1717315881158,"mc":[{"id":"1.229554891","rc":[{"atl":[[34,6],[27,3.08],[28,3.5]],"id":70003366},{"atl":[[9.6,2.33],[11,0]],"id":70003363}],"con":true,"img":false}]}
{"op":"mcm","clk":"11449911347","pt":1717315881562,"mc":[{"id":"1.229554891","rc":[{"atl":[[32,1],[34,5],[28,2.5],[29,0]],"id":70003366},{"atl":[[2.38,20.66],[2.44,13.89]],"id":70003365},{"atl":[[9.6,0],[9.8,2.27]],"id":70003363}],"con":true,"img":false}]}
{"op":"mcm","clk":"11449911364","pt":1717315881720,"mc":[{"id":"1.229554891","rc":[{"atl":[[34,6]],"id":70003366},{"spn":17.3,"spf":"NaN","id":70003366},{"spn":1.47,"spf":"NaN","id":70003364},{"atl":[[2.38,0],[2.46,65.07]],"id":70003365},{"spn":1.99,"spf":"NaN","id":70003365},{"spn":6.62,"spf":"NaN","id":70003363}],"con":true,"img":false}]}
{"op":"mcm","clk":"11449911374","pt":1717315881829,"mc":[{"id":"1.229554891","rc":[{"atl":[[32,0]],"id":70003366},{"atl":[[2.42,20.73],[2.46,13.7]],"id":70003365}],"con":true,"img":false}]}
{"op":"mcm","clk":"11449911387","pt":1717315881931,"mc":[{"id":"1.229554891","rc":[{"atl":[[10,2.22]],"id":70003363}],"con":true,"img":false}]}
{"op":"mcm","clk":"11449911394","pt":1717315882083,"mc":[{"id":"1.229554891","rc":[{"atl":[[32,1]],"id":70003366},{"atl":[[9.8,0]],"id":70003363}],"con":true,"img":false}]}
{"op":"mcm","clk":"11449911554","pt":1717315883335,"mc":[{"id":"1.229554891","rc":[{"atl":[[27,4.08]],"id":70003366},{"atl":[[2.38,14.49]],"id":70003365},{"atl":[[10,0],[11,2]],"id":70003363}],"con":true,"img":false}]}
{"op":"mcm","clk":"11449911809","pt":1717315885664,"mc":[{"id":"1.229554891","rc":[{"atb":[[3.45,0]],"id":70003363}],"con":true,"img":false}]}
{"op":"mcm","clk":"11449911816","pt":1717315885760,"mc":[{"id":"1.229554891","rc":[{"atb":[[3.35,16.09]],"id":70003363}],"con":true,"img":false}]}
{"op":"mcm","clk":"11449911852","pt":1717315886073,"mc":[{"id":"1.229554891","rc":[{"atl":[[23,2.61]],"id":70003363}],"con":true,"img":false}]}
{"op":"mcm","clk":"11449911864","pt":1717315886175,"mc":[{"id":"1.229554891","rc":[{"atl":[[38,0]],"id":70003363}],"con":true,"img":false}]}
{"op":"mcm","clk":"11449911921","pt":1717315886648,"mc":[{"id":"1.229554891","rc":[{"atb":[[6.6,13.39]],"id":70003366}],"con":true,"img":false}]}
{"op":"mcm","clk":"11449911930","pt":1717315886752,"mc":[{"id":"1.229554891","rc":[{"atb":[[7.6,11.19]],"id":70003366}],"con":true,"img":false}]}
{"op":"mcm","clk":"11449912041","pt":1717315888038,"mc":[{"id":"1.229554891","rc":[{"atl":[[55,2.61]],"id":70003366}],"con":true,"img":false}]}
{"op":"mcm","clk":"11449912223","pt":1717315889666,"mc":[{"id":"1.229554891","rc":[{"atl":[[27,3.08]],"id":70003366},{"atl":[[10,2.22],[11,0]],"id":70003363}],"con":true,"img":false}]}
{"op":"mcm","clk":"11449912326","pt":1717315890681,"mc":[{"id":"1.229554891","rc":[{"atl":[[5.8,0],[4.6,11.62]],"id":70003365}],"con":true,"img":false}]}
{"op":"mcm","clk":"11449912400","pt":1717315891353,"mc":[{"id":"1.229554891","rc":[{"atl":[[32,0]],"id":70003366},{"atl":[[10,0],[9.8,2.27]],"id":70003363}],"con":true,"img":false}]}
{"op":"mcm","clk":"11449912412","pt":1717315891457,"mc":[{"id":"1.229554891","rc":[{"atl":[[9.4,2.38]],"id":70003363}],"con":true,"img":false}]}
{"op":"mcm","clk":"11449912461","pt":1717315891974,"mc":[{"id":"1.229554891","rc":[{"atl":[[2.38,0]],"id":70003365},{"atl":[[9.2,2.44],[9.8,0],[14,0],[9.4,0]],"id":70003363}],"con":true,"img":false}]}
{"op":"mcm","clk":"11449912471","pt":1717315892076,"mc":[{"id":"1.229554891","rc":[{"atb":[[1.46,0],[1.48,10],[1.56,2.5],[1.54,0],[1.5,0],[1.52,5]],"id":70003367}],"con":true,"img":false}]}
{"op":"mcm","clk":"11449912480","pt":1717315892135,"mc":[{"id":"1.229554891","rc":[{"atl":[[32,5],[34,1],[27,5.58],[28,0]],"id":70003366}],"con":true,"img":false}]}
{"op":"mcm","clk":"11449912489","pt":1717315892241,"mc":[{"id":"1.229554891","rc":[{"atb":[[1.56,10]],"id":70003367},{"atb":[[1.56,11.25],[1.57,2.5],[1.49,10],[1.48,0],[1.53,5],[1.52,0]],"id":70003365},{"atl":[[2.44,0]],"id":70003365}],"con":true,"img":false}]}
{"op":"mcm","clk":"11449912515","pt":1717315892445,"mc":[{"id":"1.229554891","rc":[{"atb":[[1.55,0]],"id":70003367},{"atb":[[1.57,21.21]],"id":70003365},{"atl":[[2.92,2.5],[3.2,10],[2.42,0],[3,5]],"id":70003365}],"con":true,"img":false}]}
{"op":"mcm","clk":"11449912529","pt":1717315892547,"mc":[{"id":"1.229554891","rc":[{"atb":[[1.56,0]],"id":70003365},{"atl":[[2.46,32.41]],"id":70003365},{"atl":[[9.2,0],[9.4,2.38]],"id":70003363}],"con":true,"img":false}]}
{"op":"mcm","clk":"11449912574","pt":1717315892960,"mc":[{"id":"1.229554891","rc":[{"atl":[[9.2,2.44]],"id":70003363}],"con":true,"img":false}]}
{"op":"mcm","clk":"11449912680","pt":1717315893947,"mc":[{"id":"1.229554891","rc":[{"atl":[[38,1.35]],"id":70003366},{"atl":[[2.5,33.33]],"id":70003365}],"con":true,"img":false}]}
{"op":"mcm","clk":"11449912691","pt":1717315894047,"mc":[{"id":"1.229554891","rc":[{"atl":[[32,6]],"id":70003366},{"atl":[[2.44,13.89]],"id":70003365},{"atl":[[9.2,0],[10,2.22]],"id":70003363}],"con":true,"img":false}]}
{"op":"mcm","clk":"11449912721","pt":1717315894353,"mc":[{"id":"1.229554891","rc":[{"atl":[[2.44,40.22]],"id":70003365}],"con":true,"img":false}]}
{"op":"mcm","clk":"11449912747","pt":1717315894560,"mc":[{"id":"1.229554891","rc":[{"atl":[[2.46,13.7]],"id":70003365}],"con":true,"img":false}]}
{"op":"mcm","clk":"11449912796","pt":1717315894975,"mc":[{"id":"1.229554891","rc":[{"atl":[[9.4,0]],"id":70003363}],"con":true,"img":false}]}
{"op":"mcm","clk":"11449912808","pt":1717315895080,"mc":[{"id":"1.229554891","rc":[{"atb":[[7.8,3.41],[5.9,7.1]],"id":70003366},{"atb":[[1.41,84.98],[1.51,45.54]],"id":70003367},{"atl":[[4.6,20.97]],"id":70003367},{"atb":[[1.01,5807.26]],"id":70003364},{"atl":[[2.48,0.35]],"id":70003364},{"atb":[[1.44,79.18],[1.54,43.01]],"id":70003365},{"atl":[[4.9,0.13]],"id":70003365},{"atb":[[3.25,15.48],[3.75,8.44]],"id":70003363}],"con":true,"img":false}]}
{"op":"mcm","clk":"11449912829","pt":1717315895280,"mc":[{"id":"1.229554891","rc":[{"atb":[[8,8.4]],"id":70003366},{"atl":[[2.38,14.49]],"id":70003365},{"atl":[[10,0],[11,2]],"id":70003363}],"con":true,"img":false}]}
{"op":"mcm","clk":"11449912854","pt":1717315895447,"mc":[{"id":"1.229554891","rc":[{"atb":[[7.6,6.97]],"id":70003366}],"con":true,"img":false}]}
{"op":"mcm","clk":"11449912881","pt":1717315895655,"mc":[{"id":"1.229554891","rc":[{"atl":[[9.6,41.51]],"id":70003367},{"atl":[[3.15,0]],"id":70003364},{"atb":[[1.21,197],[1.26,0]],"id":70003365},{"atl":[[7.4,53.86],[8.8,0]],"id":70003365},{"atl":[[65,0],[46,8.66]],"id":70003363}],"con":true,"img":false}]}
{"op":"mcm","clk":"11449912894","pt":1717315895758,"mc":[{"id":"1.229554891","rc":[{"atl":[[2.96,18.24]],"id":70003364}],"con":true,"img":false}]}
{"op":"mcm","clk":"11449912924","pt":1717315896065,"mc":[{"id":"1.229554891","rc":[{"atl":[[4.3,12.68]],"id":70003367}],"con":true,"img":false}]}
{"op":"mcm","clk":"11449912934","pt":1717315896170,"mc":[{"id":"1.229554891","rc":[{"atl":[[5.4,0]],"id":70003367}],"con":true,"img":false}]}
{"op":"mcm","clk":"11449912942","pt":1717315896298,"mc":[{"id":"1.229554891","rc":[{"atb":[[1.55,0]],"id":70003365}],"con":true,"img":false}]}
{"op":"mcm","clk":"11449912974","pt":1717315896559,"mc":[{"id":"1.229554891","rc":[{"atl":[[2.38,41.27]],"id":70003365}],"con":true,"img":false}]}
{"op":"mcm","clk":"11449912990","pt":1717315896660,"mc":[{"id":"1.229554891","rc":[{"atl":[[32,5]],"id":70003366},{"atl":[[2.44,13.89]],"id":70003365}],"con":true,"img":false}]}
{"op":"mcm","clk":"11449912997","pt":1717315896760,"mc":[{"id":"1.229554891","rc":[{"atl":[[2.38,26.78]],"id":70003365}],"con":true,"img":false}]}
{"op":"mcm","clk":"11449913011","pt":1717315896871,"mc":[{"id":"1.229554891","rc":[{"atl":[[2.38,0]],"id":70003365}],"con":true,"img":false}]}
{"op":"mcm","clk":"11449913020","pt":1717315896973,"mc":[{"id":"1.229554891","rc":[{"atl":[[2.42,26.33]],"id":70003365}],"con":true,"img":false}]}
{"op":"mcm","clk":"11449913085","pt":1717315897590,"mc":[{"id":"1.229554891","rc":[{"atl":[[2.38,14.49]],"id":70003365}],"con":true,"img":false}]}
{"op":"mcm","clk":"11449913259","pt":1717315899153,"mc":[{"id":"1.229554891","rc":[{"atl":[[2.38,0]],"id":70003365},{"atl":[[10.5,2.11]],"id":70003363}],"con":true,"img":false}]}
{"op":"mcm","clk":"11449913351","pt":1717315900049,"mc":[{"id":"1.229554891","rc":[{"atl":[[2.44,0]],"id":70003365}],"con":true,"img":false}]}
{"op":"mcm","clk":"11449913368","pt":1717315900255,"mc":[{"id":"1.229554891","rc":[{"atl":[[2.42,0]],"id":70003365}],"con":true,"img":false}]}
{"op":"mcm","clk":"11449913385","pt":1717315900360,"mc":[{"id":"1.229554891","rc":[{"atl":[[2.46,49.36]],"id":70003365}],"con":true,"img":false}]}
{"op":"mcm","clk":"11449913409","pt":1717315900622,"mc":[{"id":"1.229554891","rc":[{"atl":[[55,0.71]],"id":70003366}],"con":true,"img":false}]}
{"op":"mcm","clk":"11449913647","pt":1717315902695,"mc":[{"id":"1.229554891","rc":[{"atb":[[4.8,26.34],[3.7,0]],"id":70003366},{"atb":[[1.22,0],[1.33,95.29]],"id":70003367}],"con":true,"img":false}]}
{"op":"mcm","clk":"11449913773","pt":1717315903896,"mc":[{"id":"1.229554891","rc":[{"atb":[[1.36,49.24],[1.32,0],[1.34,0]],"id":70003367},{"atb":[[2,0],[3.3,8.7],[3.4,0],[1.9,54.44]],"id":70003363}],"con":true,"img":false}]}
{"op":"mcm","clk":"11449913792","pt":1717315904090,"mc":[{"id":"1.229554891","rc":[{"atb":[[1.33,0]],"id":70003367}],"con":true,"img":false}]}
{"op":"mcm","clk":"11449913806","pt":1717315904194,"mc":[{"id":"1.229554891","rc":[{"atb":[[1.31,95.29]],"id":70003367}],"con":true,"img":false}]}
{"op":"mcm","clk":"11449913851","pt":1717315904601,"mc":[{"id":"1.229554891","rc":[{"atl":[[42,1.83]],"id":70003366}],"con":true,"img":false}]}
{"op":"mcm","clk":"11449914014","pt":1717315906258,"mc":[{"id":"1.229554891","rc":[{"atl":[[10,2.22],[10.5,0]],"id":70003363}],"con":true,"img":false}]}
{"op":"mcm","clk":"11449914171","pt":1717315907960,"mc":[{"id":"1.229554891","rc":[{"atl":[[2.54,48.7]],"id":70003365}],"con":true,"img":false}]}
{"op":"mcm","clk":"11449914279","pt":1717315909078,"mc":[{"id":"1.229554891","rc":[{"atb":[[1.36,0]],"id":70003367}],"con":true,"img":false}]}
{"op":"mcm","clk":"11449914290","pt":1717315909183,"mc":[{"id":"1.229554891","rc":[{"atb":[[1.42,49.24]],"id":70003367}],"con":true,"img":false}]}
{"op":"mcm","clk":"11449914550","pt":1717315912089,"mc":[{"id":"1.229554891","rc":[{"atl":[[2.2,34.88],[2.96,0]],"id":70003364}],"con":true,"img":false}]}
{"op":"mcm","clk":"11449914565","pt":1717315912197,"mc":[{"id":"1.229554891","rc":[{"atb":[[1.29,0]],"id":70003365}],"con":true,"img":false}]}
{"op":"mcm","clk":"11449914576","pt":1717315912297,"mc":[{"id":"1.229554891","rc":[{"atb":[[1.45,53.52]],"id":70003365}],"con":true,"img":false}]}
{"op":"mcm","clk":"11449914803","pt":1717315914474,"mc":[{"id":"1.229554891","rc":[{"atb":[[7.6,0]],"id":70003366}],"con":true,"img":false}]}
{"op":"mcm","clk":"11449914813","pt":1717315914575,"mc":[{"id":"1.229554891","rc":[{"atb":[[8.2,6.97]],"id":70003366}],"con":true,"img":false}]}
{"op":"mcm","clk":"11449914825","pt":1717315914683,"mc":[{"id":"1.229554891","rc":[{"atb":[[8.4,7.94]],"id":70003366}],"con":true,"img":false}]}
{"op":"mcm","clk":"11449914838","pt":1717315914806,"mc":[{"id":"1.229554891","rc":[{"atb":[[8,0]],"id":70003366},{"atb":[[1.45,44.05]],"id":70003365},{"atb":[[2.9,0]],"id":70003363}],"con":true,"img":false}]}
{"op":"mcm","clk":"11449914966","pt":1717315916098,"mc":[{"id":"1.229554891","rc":[{"atb":[[3.35,0]],"id":70003363}],"con":true,"img":false}]}
{"op":"mcm","clk":"11449914978","pt":1717315916200,"mc":[{"id":"1.229554891","rc":[{"atb":[[3.8,16.09]],"id":70003363}],"con":true,"img":false}]}
{"op":"mcm","clk":"11449915203","pt":1717315918186,"mc":[{"id":"1.229554891","rc":[{"atl":[[2.58,79.11]],"id":70003365}],"con":true,"img":false}]}
{"op":"mcm","clk":"11449915404","pt":1717315920103,"mc":[{"id":"1.229554891","rc":[{"atl":[[40,2.61],[55,0]],"id":70003366}],"con":true,"img":false}]}
{"op":"mcm","clk":"11449915716","pt":1717315923110,"mc":[{"id":"1.229554891","rc":[{"atb":[[8.2,0]],"id":70003366}],"con":true,"img":false}]}
{"op":"mcm","clk":"11449915728","pt":1717315923214,"mc":[{"id":"1.229554891","rc":[{"atb":[[7.6,6.97]],"id":70003366}],"con":true,"img":false}]}
{"op":"mcm","clk":"11449915738","pt":1717315923317,"mc":[{"id":"1.229554891","rc":[{"atb":[[8.4,0]],"id":70003366}],"con":true,"img":false}]}
{"op":"mcm","clk":"11449915752","pt":1717315923377,"mc":[{"id":"1.229554891","rc":[{"atb":[[8,7.94]],"id":70003366}],"con":true,"img":false}]}
{"op":"mcm","clk":"11449915775","pt":1717315923587,"mc":[{"id":"1.229554891","rc":[{"atl":[[4.3,0]],"id":70003367}],"con":true,"img":false}]}
{"op":"mcm","clk":"11449915788","pt":1717315923691,"mc":[{"id":"1.229554891","rc":[{"atl":[[4.5,12.68]],"id":70003367}],"con":true,"img":false}]}
{"op":"mcm","clk":"11449916053","pt":1717315926117,"mc":[{"id":"1.229554891","rc":[{"atb":[[1.25,153.97],[1.21,0]],"id":70003365}],"con":true,"img":false}]}
{"op":"mcm","clk":"11449916985","pt":1717315934828,"mc":[{"id":"1.229554891","rc":[{"atb":[[1.09,222.22],[1.08,5]],"id":70003364}],"con":true,"img":false}]}
{"op":"mcm","clk":"11449917065","pt":1717315935608,"mc":[{"id":"1.229554891","rc":[{"atl":[[60,5]],"id":70003367},{"atl":[[60,5]],"id":70003364},{"atl":[[60,5]],"id":70003365}],"con":true,"img":false}]}
{"op":"mcm","clk":"11449917077","pt":1717315935709,"mc":[{"id":"1.229554891","rc":[{"atl":[[10,0],[9.8,2.27]],"id":70003363}],"con":true,"img":false}]}
{"op":"mcm","clk":"11449917292","pt":1717315937837,"mc":[{"id":"1.229554891","rc":[{"atb":[[7.4,3.12],[7.6,9.47]],"id":70003366},{"atl":[[10.5,2.11],[9.8,0]],"id":70003363}],"con":true,"img":false}]}
{"op":"mcm","clk":"11449917435","pt":1717315939136,"mc":[{"id":"1.229554891","rc":[{"atb":[[7.6,2.5]],"id":70003366}],"con":true,"img":false}]}
{"op":"mcm","clk":"11449917450","pt":1717315939239,"mc":[{"id":"1.229554891","rc":[{"atb":[[8.2,6.97]],"id":70003366},{"atl":[[32,6],[34,0]],"id":70003366},{"atl":[[2.44,13.89],[2.46,35.66]],"id":70003365}],"con":true,"img":false}]}
{"op":"mcm","clk":"11449917474","pt":1717315939445,"mc":[{"id":"1.229554891","rc":[{"atb":[[8.4,8.68]],"id":70003366},{"atl":[[2.44,54.79]],"id":70003365}],"con":true,"img":false}]}
{"op":"mcm","clk":"11449917487","pt":1717315939547,"mc":[{"id":"1.229554891","rc":[{"atb":[[8,0]],"id":70003366},{"atl":[[2.46,0]],"id":70003365}],"con":true,"img":false}]}
{"op":"mcm","clk":"11449917552","pt":1717315940121,"mc":[{"id":"1.229554891","rc":[{"atl":[[32,5],[27,6.58]],"id":70003366},{"atl":[[2.44,40.9],[2.36,14.71]],"id":70003365}],"con":true,"img":false}]}
{"op":"mcm","clk":"11449918301","pt":1717315947639,"mc":[{"id":"1.229554891","rc":[{"atb":[[8.2,0]],"id":70003366},{"spn":17.7,"spf":"NaN","id":70003366},{"spn":2.18,"spf":"NaN","id":70003367},{"spn":1.96,"spf":"NaN","id":70003365},{"spn":7.15,"spf":"NaN","id":70003363}],"con":true,"img":false}]}
{"op":"mcm","clk":"11449918313","pt":1717315947732,"mc":[{"id":"1.229554891","rc":[{"atb":[[7.8,10.39]],"id":70003366}],"con":true,"img":false}]}
{"op":"mcm","clk":"11449918327","pt":1717315947840,"mc":[{"id":"1.229554891","rc":[{"atb":[[8.4,0]],"id":70003366}],"con":true,"img":false}]}
{"op":"mcm","clk":"11449918347","pt":1717315948052,"mc":[{"id":"1.229554891","rc":[{"atb":[[8,6.43]],"id":70003366}],"con":true,"img":false}]}
{"op":"mcm","clk":"11449918406","pt":1717315948527,"mc":[{"id":"1.229554891","rc":[{"atb":[[7.8,6.97],[5.9,0]],"id":70003366},{"atb":[[1.41,0],[1.51,0]],"id":70003367},{"atl":[[4.6,20.83]],"id":70003367},{"atb":[[1.01,0]],"id":70003364},{"atl":[[2.48,0]],"id":70003364},{"atb":[[1.44,0],[1.54,0]],"id":70003365},{"atl":[[4.9,0]],"id":70003365},{"atb":[[3.25,0],[3.75,0]],"id":70003363}],"con":true,"img":false}]}
{"op":"mcm","clk":"11449918481","pt":1717315949160,"mc":[{"id":"1.229554891","rc":[{"atb":[[1.42,0]],"id":70003367}],"con":true,"img":false}]}
{"op":"mcm","clk":"11449918492","pt":1717315949253,"mc":[{"id":"1.229554891","rc":[{"atb":[[1.38,49.24]],"id":70003367}],"con":true,"img":false}]}
{"op":"mcm","clk":"11449918546","pt":1717315949730,"mc":[{"id":"1.229554891","rc":[{"atl":[[29,1.79]],"id":70003366},{"atb":[[1.4,50],[1.36,208.33],[1.34,250],[1.38,131.58]],"id":70003365},{"atl":[[2.4,35.71]],"id":70003365}],"con":true,"img":false}]}
{"op":"mcm","clk":"11449918603","pt":1717315950244,"mc":[{"id":"1.229554891","rc":[{"atl":[[38,0],[42,0]],"id":70003366},{"atb":[[1.36,55.56]],"id":70003367},{"atl":[[1.83,0],[1.87,0],[1.82,13.75],[1.91,0],[1.9,10],[1.86,5]],"id":70003364},{"atl":[[2.54,0],[2.5,0],[2.58,0]],"id":70003365}],"con":true,"img":false}]}
{"op":"mcm","clk":"11449918866","pt":1717315952942,"mc":[{"id":"1.229554891","rc":[{"atl":[[2.36,41.65]],"id":70003365}],"con":true,"img":false}]}
{"op":"mcm","clk":"11449918877","pt":1717315953042,"mc":[{"id":"1.229554891","rc":[{"atl":[[2.44,0]],"id":70003365}],"con":true,"img":false}]}
{"op":"mcm","clk":"11449919184","pt":1717315955924,"mc":[{"id":"1.229554891","rc":[{"atl":[[32,0],[21,2.5],[23,3.64],[25,5],[27,4.08],[29,11.79]],"id":70003366},{"atb":[[1.56,0],[1.48,0],[1.52,0]],"id":70003367},{"atb":[[1.68,23.41],[1.53,0],[1.69,2.5],[1.57,18.71],[1.49,0],[1.65,5],[1.61,10]],"id":70003365},{"atl":[[2.36,26.94],[2.4,0],[2.92,0],[3.2,0],[3,0],[3.25,8.89]],"id":70003365}],"con":true,"img":false}]}
{"op":"mcm","clk":"11449919193","pt":1717315956027,"mc":[{"id":"1.229554891","rc":[{"atb":[[1.38,60.02]],"id":70003367}],"con":true,"img":false}]}
{"op":"mcm","clk":"11449919202","pt":1717315956134,"mc":[{"id":"1.229554891","rc":[{"atl":[[27,1]],"id":70003366},{"atb":[[1.3,252.5]],"id":70003367},{"atb":[[1.57,0]],"id":70003365},{"atl":[[2.36,0],[4,5],[3.8,2.5],[4.4,10]],"id":70003365}],"con":true,"img":false}]}
{"op":"mcm","clk":"11449919212","pt":1717315956234,"mc":[{"id":"1.229554891","rc":[{"atl":[[3.25,19.31]],"id":70003365}],"con":true,"img":false}]}
{"op":"mcm","clk":"11449919256","pt":1717315956653,"mc":[{"id":"1.229554891","rc":[{"atb":[[4.8,14.42]],"id":70003366},{"atl":[[2.2,0],[2.94,21.57]],"id":70003364},{"atb":[[1.45,0]],"id":70003365},{"atl":[[4.6,0]],"id":70003365},{"atb":[[3.8,0]],"id":70003363}],"con":true,"img":false}]}
{"op":"mcm","clk":"11449919265","pt":1717315956757,"mc":[{"id":"1.229554891","rc":[{"atb":[[1.41,44.05]],"id":70003365},{"atl":[[5.7,11.62]],"id":70003365},{"atb":[[3.35,16.09]],"id":70003363}],"con":true,"img":false}]}
{"op":"mcm","clk":"11449919526","pt":1717315959239,"mc":[{"id":"1.229554891","rc":[{"atl":[[32,2.42]],"id":70003366}],"con":true,"img":false}]}
{"op":"mcm","clk":"11449919576","pt":1717315959752,"mc":[{"id":"1.229554891","rc":[{"atb":[[1.34,147.06]],"id":70003367},{"atb":[[3.2,22.73]],"id":70003363}],"con":true,"img":false}]}
{"op":"mcm","clk":"11449919609","pt":1717315960161,"mc":[{"id":"1.229554891","rc":[{"atb":[[7.8,0]],"id":70003366}],"con":true,"img":false}]}
{"op":"mcm","clk":"11449919618","pt":1717315960262,"mc":[{"id":"1.229554891","rc":[{"atb":[[8,0],[6.8,6.97]],"id":70003366}],"con":true,"img":false}]}
{"op":"mcm","clk":"11449919637","pt":1717315960471,"mc":[{"id":"1.229554891","rc":[{"atb":[[7.4,7.34]],"id":70003366}],"con":true,"img":false}]}
{"op":"mcm","clk":"11449919748","pt":1717315961456,"mc":[{"id":"1.229554891","rc":[{"atb":[[7.6,8.98]],"id":70003366}],"con":true,"img":false}]}
