{"op":"mcm","clk":"11448351866","pt":1717289088271,"mc":[{"id":"1.229554904","marketDefinition":{"bspMarket":false,"turnInPlayEnabled":false,"persistenceEnabled":false,"marketBaseRate":7.0,"eventId":"33318908","eventTypeId":"4339","numberOfWinners":1,"bettingType":"ODDS","marketType":"MATCH_BET","marketTime":"2024-06-02T08:59:00.000Z","suspendTime":"2024-06-02T08:59:00.000Z","bspReconciled":false,"complete":true,"inPlay":false,"crossMatching":true,"runnersVoidable":false,"numberOfActiveRunners":2,"betDelay":0,"status":"OPEN","runners":[{"status":"ACTIVE","sortPriority":1,"id":47208569,"name":"4. Enticement"},{"status":"ACTIVE","sortPriority":2,"id":70003368,"name":"8. Dark Queen"}],"regulators":["MR_INT"],"venue":"Murray Bridge","countryCode":"AU","discountAllowed":true,"timezone":"Australia/Adelaide","openDate":"2024-06-02T08:21:00.000Z","version":5962433804,"name":"Enticement v Dark Queen","eventName":"Murray Bridge (AUS) 2nd Jun"},"rc":[],"con":true,"img":false}]}
{"op":"mcm","clk":"11448366403","pt":1717289278043,"mc":[{"id":"1.229554904","rc":[{"atb":[[1.81,9.68],[1.91,8.62]],"id":70003368},{"atb":[[1.84,9.34],[1.74,10.6]],"id":47208569}],"con":true,"img":false}]}
{"op":"mcm","clk":"11448951080","pt":1717300632762,"mc":[{"id":"1.229554904","rc":[{"atb":[[1.01,17.19]],"id":70003368},{"atl":[[990,0.85]],"id":70003368},{"atb":[[1.02,8.59]],"id":47208569},{"atl":[[1000,0.85]],"id":47208569}],"con":true,"img":false}]}
{"op":"mcm","clk":"11449367045","pt":1717308032562,"mc":[{"id":"1.229554904","rc":[{"atb":[[1.81,0],[1.91,0]],"id":70003368},{"atb":[[1.84,0],[1.74,0]],"id":47208569}],"con":true,"img":false}]}
{"op":"mcm","clk":"11449367310","pt":1717308038566,"mc":[{"id":"1.229554904","rc":[{"atb":[[1.81,9.68],[1.91,8.62]],"id":70003368},{"atb":[[1.84,9.34],[1.74,10.6]],"id":47208569}],"con":true,"img":false}]}
{"op":"mcm","clk":"11449437351","pt":1717309126726,"mc":[{"id":"1.229554904","rc":[{"atb":[[1.81,0],[1.91,0]],"id":70003368},{"atb":[[1.84,0],[1.74,0]],"id":47208569}],"con":true,"img":false}]}
{"op":"mcm","clk":"11449438870","pt":1717309151566,"mc":[{"id":"1.229554904","rc":[{"atb":[[1.81,9.68],[1.91,8.62]],"id":70003368},{"atb":[[1.84,9.34],[1.74,10.6]],"id":47208569}],"con":true,"img":false}]}
{"op":"mcm","clk":"11449442398","pt":1717309206895,"mc":[{"id":"1.229554904","rc":[{"atb":[[1.81,0],[1.91,0]],"id":70003368},{"atb":[[1.84,0],[1.74,0]],"id":47208569}],"con":true,"img":false}]}
{"op":"mcm","clk":"11449447234","pt":1717309280771,"mc":[{"id":"1.229554904","marketDefinition":{"bspMarket":false,"turnInPlayEnabled":false,"persistenceEnabled":false,"marketBaseRate":7.0,"eventId":"33318908","eventTypeId":"4339","numberOfWinners":1,"bettingType":"ODDS","marketType":"MATCH_BET","marketTime":"2024-06-02T08:59:00.000Z","suspendTime":"2024-06-02T08:59:00.000Z","bspReconciled":false,"complete":true,"inPlay":false,"crossMatching":true,"runnersVoidable":false,"numberOfActiveRunners":2,"betDelay":0,"status":"SUSPENDED","runners":[{"status":"ACTIVE","sortPriority":1,"id":47208569,"name":"4. Enticement"},{"status":"ACTIVE","sortPriority":2,"id":70003368,"name":"8. Dark Queen"}],"regulators":["MR_INT"],"venue":"Murray Bridge","countryCode":"AU","discountAllowed":true,"timezone":"Australia/Adelaide","openDate":"2024-06-02T08:21:00.000Z","version":5962889456,"name":"Enticement v Dark Queen","eventName":"Murray Bridge (AUS) 2nd Jun"},"rc":[],"con":true,"img":false}]}
{"op":"mcm","clk":"11449452430","pt":1717309356905,"mc":[{"id":"1.229554904","marketDefinition":{"bspMarket":false,"turnInPlayEnabled":false,"persistenceEnabled":false,"marketBaseRate":7.0,"eventId":"33318908","eventTypeId":"4339","numberOfWinners":1,"bettingType":"ODDS","marketType":"MATCH_BET","marketTime":"2024-06-02T08:59:00.000Z","suspendTime":"2024-06-02T08:59:00.000Z","bspReconciled":false,"complete":true,"inPlay":false,"crossMatching":true,"runnersVoidable":false,"numberOfActiveRunners":2,"betDelay":0,"status":"OPEN","runners":[{"status":"ACTIVE","sortPriority":1,"id":47208569,"name":"4. Enticement"},{"status":"ACTIVE","sortPriority":2,"id":70003368,"name":"8. Dark Queen"}],"regulators":["MR_INT"],"venue":"Murray Bridge","countryCode":"AU","discountAllowed":true,"timezone":"Australia/Adelaide","openDate":"2024-06-02T08:21:00.000Z","version":5962891346,"name":"Enticement v Dark Queen","eventName":"Murray Bridge (AUS) 2nd Jun"},"rc":[],"con":true,"img":false}]}
{"op":"mcm","clk":"11449460685","pt":1717309485524,"mc":[{"id":"1.229554904","rc":[{"atb":[[1.81,9.68],[1.91,8.62]],"id":70003368},{"atb":[[1.84,9.34],[1.74,10.6]],"id":47208569}],"con":true,"img":false}]}
{"op":"mcm","clk":"11449462408","pt":1717309511436,"mc":[{"id":"1.229554904","rc":[{"atb":[[1.81,0],[1.91,0]],"id":70003368},{"atb":[[1.84,0],[1.74,0]],"id":47208569}],"con":true,"img":false}]}
{"op":"mcm","clk":"11449463292","pt":1717309524777,"mc":[{"id":"1.229554904","rc":[{"atb":[[1.81,9.68],[1.91,8.62]],"id":70003368},{"atb":[[1.84,9.34],[1.74,10.6]],"id":47208569}],"con":true,"img":false}]}
{"op":"mcm","clk":"11449516572","pt":1717310230694,"mc":[{"id":"1.229554904","rc":[{"atb":[[1.81,0],[1.91,0]],"id":70003368},{"atb":[[1.84,0],[1.74,0]],"id":47208569}],"con":true,"img":false}]}
{"op":"mcm","clk":"11449518582","pt":1717310263114,"mc":[{"id":"1.229554904","rc":[{"atb":[[1.81,9.68],[1.91,8.62]],"id":70003368},{"atb":[[1.84,9.34],[1.74,10.6]],"id":47208569}],"con":true,"img":false}]}
{"op":"mcm","clk":"11449578273","pt":1717311300179,"mc":[{"id":"1.229554904","rc":[{"atb":[[1.81,0],[1.91,0]],"id":70003368},{"atb":[[1.84,0],[1.74,0]],"id":47208569}],"con":true,"img":false}]}
{"op":"mcm","clk":"11449579181","pt":1717311315022,"mc":[{"id":"1.229554904","rc":[{"atb":[[1.81,9.68],[1.91,8.62]],"id":70003368},{"atb":[[1.84,9.34],[1.74,10.6]],"id":47208569}],"con":true,"img":false}]}
{"op":"mcm","clk":"11449586143","pt":1717311433289,"mc":[{"id":"1.229554904","rc":[{"atl":[[990,0.17]],"id":70003368},{"atl":[[1000,0.17]],"id":47208569}],"con":true,"img":false}]}
{"op":"mcm","clk":"11449624324","pt":1717312169412,"mc":[{"id":"1.229554904","rc":[{"atb":[[1.81,0],[1.91,0]],"id":70003368},{"atb":[[1.84,0],[1.74,0]],"id":47208569}],"con":true,"img":false}]}
{"op":"mcm","clk":"11449624998","pt":1717312185760,"mc":[{"id":"1.229554904","rc":[{"atb":[[1.81,9.68],[1.91,8.62]],"id":70003368},{"atb":[[1.84,9.34],[1.74,10.6]],"id":47208569}],"con":true,"img":false}]}
{"op":"mcm","clk":"11449657588","pt":1717312995065,"mc":[{"id":"1.229554904","rc":[{"atb":[[1.81,0],[1.91,0]],"id":70003368},{"atb":[[1.84,0],[1.74,0]],"id":47208569}],"con":true,"img":false}]}
{"op":"mcm","clk":"11449658107","pt":1717313008190,"mc":[{"id":"1.229554904","rc":[{"atb":[[1.81,9.68],[1.91,8.62]],"id":70003368},{"atb":[[1.84,9.34],[1.74,10.6]],"id":47208569}],"con":true,"img":false}]}
{"op":"mcm","clk":"11449712757","pt":1717313838144,"mc":[{"id":"1.229554904","rc":[{"atb":[[1.81,0],[1.91,0]],"id":70003368},{"atb":[[1.84,0],[1.74,0]],"id":47208569}],"con":true,"img":false}]}
{"op":"mcm","clk":"11449715370","pt":1717313867171,"mc":[{"id":"1.229554904","rc":[{"atb":[[1.81,9.68],[1.91,8.62]],"id":70003368},{"atb":[[1.84,9.34],[1.74,10.6]],"id":47208569}],"con":true,"img":false}]}
{"op":"mcm","clk":"11449787058","pt":1717314666687,"mc":[{"id":"1.229554904","rc":[{"atb":[[1.81,0],[1.91,0]],"id":70003368},{"atb":[[1.84,0],[1.74,0]],"id":47208569}],"con":true,"img":false}]}
{"op":"mcm","clk":"11449789967","pt":1717314698243,"mc":[{"id":"1.229554904","rc":[{"atb":[[1.81,9.68],[1.91,8.62]],"id":70003368},{"atb":[[1.84,9.34],[1.74,10.6]],"id":47208569}],"con":true,"img":false}]}
{"op":"mcm","clk":"11449836016","pt":1717315140186,"mc":[{"id":"1.229554904","rc":[{"atb":[[1.09,18.31]],"id":70003368},{"atl":[[2.84,2]],"id":70003368},{"atl":[[30,2]],"id":47208569}],"con":true,"img":false}]}
{"op":"mcm","clk":"11449836039","pt":1717315140390,"mc":[{"id":"1.229554904","rc":[{"atl":[[2.56,16.03],[2.52,13.16],[2.6,18.75],[2.48,10.14]],"id":70003368},{"atl":[[5.1,3.66],[5.3,4.65],[5.5,5.56],[5.7,6.38]],"id":47208569}],"con":true,"img":false}]}
{"op":"mcm","clk":"11449836052","pt":1717315140493,"mc":[{"id":"1.229554904","rc":[{"atl":[[2.56,18.03],[2.84,0]],"id":70003368}],"con":true,"img":false}]}
{"op":"mcm","clk":"11449836149","pt":1717315141683,"mc":[{"id":"1.229554904","rc":[{"atl":[[2.46,10.27],[2.48,0]],"id":70003368}],"con":true,"img":false}]}
{"op":"mcm","clk":"11449837043","pt":1717315151608,"mc":[{"id":"1.229554904","rc":[{"atl":[[2.48,10.14]],"id":70003368}],"con":true,"img":false}]}
{"op":"mcm","clk":"11449837051","pt":1717315151713,"mc":[{"id":"1.229554904","rc":[{"atl":[[2.46,0]],"id":70003368}],"con":true,"img":false}]}
{"op":"mcm","clk":"11449839525","pt":1717315177348,"mc":[{"id":"1.229554904","rc":[{"atl":[[8,10.21],[30,0]],"id":47208569}],"con":true,"img":false}]}
{"op":"mcm","clk":"11449841380","pt":1717315196892,"mc":[{"id":"1.229554904","rc":[{"atl":[[2.46,10.27]],"id":70003368}],"con":true,"img":false}]}
{"op":"mcm","clk":"11449841390","pt":1717315196996,"mc":[{"id":"1.229554904","rc":[{"atl":[[2.56,16.03],[2.52,33.44],[2.48,0]],"id":70003368}],"con":true,"img":false}]}
{"op":"mcm","clk":"11449841454","pt":1717315197564,"mc":[{"id":"1.229554904","rc":[{"atl":[[2.48,10.14]],"id":70003368}],"con":true,"img":false}]}
{"op":"mcm","clk":"11449841463","pt":1717315197669,"mc":[{"id":"1.229554904","rc":[{"atl":[[2.46,0]],"id":70003368}],"con":true,"img":false}]}
{"op":"mcm","clk":"11449841533","pt":1717315198386,"mc":[{"id":"1.229554904","rc":[{"atl":[[2.46,10.27],[2.48,0]],"id":70003368}],"con":true,"img":false}]}
{"op":"mcm","clk":"11449841964","pt":1717315202074,"mc":[{"id":"1.229554904","rc":[{"atl":[[2.56,59.74],[2.52,13.16]],"id":70003368}],"con":true,"img":false}]}
{"op":"mcm","clk":"11449842656","pt":1717315208407,"mc":[{"id":"1.229554904","rc":[{"atl":[[2.46,0],[2.48,10.14]],"id":70003368}],"con":true,"img":false}]}
{"op":"mcm","clk":"11449851204","pt":1717315295685,"mc":[{"id":"1.229554904","rc":[{"atb":[[1.81,0],[1.91,0]],"id":70003368},{"atb":[[1.84,0],[1.74,0]],"id":47208569}],"con":true,"img":false}]}
{"op":"mcm","clk":"11449851225","pt":1717315295887,"mc":[{"id":"1.229554904","rc":[{"atb":[[1.25,60],[1.21,119.05],[1.19,157.89],[1.02,36.62],[1.23,86.96],[1.09,0]],"id":70003368},{"atb":[[1.46,43.48],[1.44,56.82],[1.42,71.43],[1.48,31.25]],"id":47208569},{"atl":[[10,11.11]],"id":47208569}],"con":true,"img":false}]}
{"op":"mcm","clk":"11449851235","pt":1717315295993,"mc":[{"id":"1.229554904","rc":[{"atb":[[1.1,17.76]],"id":70003368},{"atl":[[8,0]],"id":47208569}],"con":true,"img":false}]}
{"op":"mcm","clk":"11449851245","pt":1717315296108,"mc":[{"id":"1.229554904","rc":[{"atb":[[1.02,0]],"id":70003368}],"con":true,"img":false}]}
{"op":"mcm","clk":"11449854719","pt":1717315331356,"mc":[{"id":"1.229554904","rc":[{"atb":[[1.81,9.68],[1.91,8.62]],"id":70003368},{"atb":[[1.84,9.34],[1.74,10.6]],"id":47208569}],"con":true,"img":false}]}
{"op":"mcm","clk":"11449855542","pt":1717315339046,"mc":[{"id":"1.229554904","rc":[{"atl":[[8,10.21],[10,0]],"id":47208569}],"con":true,"img":false}]}
{"op":"mcm","clk":"11449886576","pt":1717315643026,"mc":[{"id":"1.229554904","rc":[{"atb":[[1.81,0],[1.91,0]],"id":70003368},{"atb":[[1.84,0],[1.74,0]],"id":47208569}],"con":true,"img":false}]}
{"op":"mcm","clk":"11449886601","pt":1717315643188,"mc":[{"id":"1.229554904","rc":[{"atl":[[8,0],[10,11.11]],"id":47208569}],"con":true,"img":false}]}
{"op":"mcm","clk":"11449888531","pt":1717315662342,"mc":[{"id":"1.229554904","rc":[{"atb":[[1.81,9.68],[1.91,8.62]],"id":70003368},{"atb":[[1.84,9.34],[1.74,10.6]],"id":47208569}],"con":true,"img":false}]}
{"op":"mcm","clk":"11449888830","pt":1717315665340,"mc":[{"id":"1.229554904","rc":[{"atl":[[8,10.21],[10,0]],"id":47208569}],"con":true,"img":false}]}
{"op":"mcm","clk":"11449893610","pt":1717315712303,"mc":[{"id":"1.229554904","rc":[{"atb":[[1.81,0],[1.91,0]],"id":70003368},{"atb":[[1.84,0],[1.74,0]],"id":47208569}],"con":true,"img":false}]}
{"op":"mcm","clk":"11449893637","pt":1717315712464,"mc":[{"id":"1.229554904","rc":[{"atl":[[8,0],[10,11.11]],"id":47208569}],"con":true,"img":false}]}
{"op":"mcm","clk":"11449897325","pt":1717315746571,"mc":[{"id":"1.229554904","rc":[{"atl":[[2.46,10.27],[2.48,0]],"id":70003368}],"con":true,"img":false}]}
{"op":"mcm","clk":"11449897336","pt":1717315746676,"mc":[{"id":"1.229554904","rc":[{"atl":[[2.56,16.03],[2.52,33.44]],"id":70003368}],"con":true,"img":false}]}
{"op":"mcm","clk":"11449897865","pt":1717315751782,"mc":[{"id":"1.229554904","rc":[{"atl":[[2.56,59.74],[2.52,13.16]],"id":70003368}],"con":true,"img":false}]}
{"op":"mcm","clk":"11449897999","pt":1717315752978,"mc":[{"id":"1.229554904","rc":[{"atl":[[2.46,0],[2.44,10.42]],"id":70003368}],"con":true,"img":false}]}
{"op":"mcm","clk":"11449898095","pt":1717315753812,"mc":[{"id":"1.229554904","rc":[{"atb":[[1.81,9.68],[1.91,8.62]],"id":70003368},{"atb":[[1.84,9.34],[1.74,10.6]],"id":47208569}],"con":true,"img":false}]}
{"op":"mcm","clk":"11449898171","pt":1717315754493,"mc":[{"id":"1.229554904","rc":[{"atl":[[10,0],[7.6,10.21]],"id":47208569}],"con":true,"img":false}]}
{"op":"mcm","clk":"11449899057","pt":1717315763002,"mc":[{"id":"1.229554904","rc":[{"atl":[[2.48,13.51]],"id":70003368}],"con":true,"img":false}]}
{"op":"mcm","clk":"11449899109","pt":1717315763523,"mc":[{"id":"1.229554904","rc":[{"atl":[[2.6,0]],"id":70003368}],"con":true,"img":false}]}
{"op":"mcm","clk":"11449900589","pt":1717315777719,"mc":[{"id":"1.229554904","rc":[{"atl":[[2.52,37.09]],"id":70003368}],"con":true,"img":false}]}
{"op":"mcm","clk":"11449900602","pt":1717315777830,"mc":[{"id":"1.229554904","rc":[{"atl":[[2.56,16.03]],"id":70003368}],"con":true,"img":false}]}
{"op":"mcm","clk":"11449906176","pt":1717315832700,"mc":[{"id":"1.229554904","rc":[{"atb":[[1.48,0]],"id":47208569}],"con":true,"img":false}]}
{"op":"mcm","clk":"11449906577","pt":1717315836688,"mc":[{"id":"1.229554904","rc":[{"atl":[[2.46,10.27],[2.44,0]],"id":70003368}],"con":true,"img":false}]}
{"op":"mcm","clk":"11449906588","pt":1717315836791,"mc":[{"id":"1.229554904","rc":[{"atl":[[2.52,13.16],[2.48,34.35]],"id":70003368}],"con":true,"img":false}]}
{"op":"mcm","clk":"11449906598","pt":1717315836895,"mc":[{"id":"1.229554904","rc":[{"atl":[[2.52,57.78],[2.48,13.51]],"id":70003368}],"con":true,"img":false}]}
{"op":"mcm","clk":"11449907411","pt":1717315844908,"mc":[{"id":"1.229554904","rc":[{"atl":[[2.46,0],[2.44,10.42]],"id":70003368}],"con":true,"img":false}]}
{"op":"mcm","clk":"11449907420","pt":1717315845010,"mc":[{"id":"1.229554904","rc":[{"atl":[[2.52,13.16],[2.48,34.05]],"id":70003368}],"con":true,"img":false}]}
{"op":"mcm","clk":"11449907431","pt":1717315845112,"mc":[{"id":"1.229554904","rc":[{"atl":[[2.52,37.09],[2.48,13.51]],"id":70003368}],"con":true,"img":false}]}
{"op":"mcm","clk":"11449931932","pt":1717316084548,"mc":[{"id":"1.229554904","rc":[{"atb":[[1.81,0],[1.91,0]],"id":70003368},{"atb":[[1.84,0],[1.74,0]],"id":47208569}],"con":true,"img":false}]}
{"op":"mcm","clk":"11449931951","pt":1717316084709,"mc":[{"id":"1.229554904","rc":[{"atb":[[1.47,31.91]],"id":47208569},{"atl":[[10,11.11],[7.6,0]],"id":47208569}],"con":true,"img":false}]}
{"op":"mcm","clk":"11449933171","pt":1717316098384,"mc":[{"id":"1.229554904","rc":[{"atb":[[1.81,9.68],[1.91,8.62]],"id":70003368},{"atb":[[1.84,9.34],[1.74,10.6]],"id":47208569}],"con":true,"img":false}]}
{"op":"mcm","clk":"11449934474","pt":1717316112429,"mc":[{"id":"1.229554904","rc":[{"atl":[[8,10.21],[10,0]],"id":47208569}],"con":true,"img":false}]}
{"op":"mcm","clk":"11449952414","pt":1717316311249,"mc":[{"id":"1.229554904","rc":[{"atb":[[1.72,86.96],[1.1,0]],"id":70003368},{"atl":[[3.6,29.54],[2.52,0],[2.44,0],[2.98,7.58],[2.48,0]],"id":70003368},{"atb":[[1.24,75.39]],"id":47208569},{"atl":[[8,0],[5.1,0],[5.5,13.87],[2.46,10.27]],"id":47208569}],"con":true,"img":false}]}
{"op":"mcm","clk":"11449952422","pt":1717316311347,"mc":[{"id":"1.229554904","rc":[{"atl":[[2.38,10.87]],"id":47208569}],"con":true,"img":false}]}
{"op":"mcm","clk":"11449952451","pt":1717316311642,"mc":[{"id":"1.229554904","rc":[{"atl":[[2.56,0]],"id":70003368},{"atl":[[5.7,0]],"id":47208569}],"con":true,"img":false}]}
{"op":"mcm","clk":"11449953194","pt":1717316320364,"mc":[{"id":"1.229554904","rc":[{"atb":[[1.24,0],[1.17,86.96]],"id":47208569}],"con":true,"img":false}]}
{"op":"mcm","clk":"11449953278","pt":1717316321245,"mc":[{"id":"1.229554904","rc":[{"atl":[[3.05,9.76]],"id":70003368}],"con":true,"img":false}]}
{"op":"mcm","clk":"11449953286","pt":1717316321346,"mc":[{"id":"1.229554904","rc":[{"atl":[[2.42,14.08]],"id":47208569}],"con":true,"img":false}]}
{"op":"mcm","clk":"11449953516","pt":1717316323861,"mc":[{"id":"1.229554904","rc":[{"atl":[[5.5,8.31]],"id":47208569}],"con":true,"img":false}]}
{"op":"mcm","clk":"11449954132","pt":1717316331284,"mc":[{"id":"1.229554904","rc":[{"atl":[[3.15,11.63]],"id":70003368}],"con":true,"img":false}]}
{"op":"mcm","clk":"11449954142","pt":1717316331378,"mc":[{"id":"1.229554904","rc":[{"atl":[[2.46,17.12]],"id":47208569}],"con":true,"img":false}]}
{"op":"mcm","clk":"11449954517","pt":1717316336678,"mc":[{"id":"1.229554904","rc":[{"atl":[[5.5,0],[2.48,28.16]],"id":47208569}],"con":true,"img":false}]}
{"op":"mcm","clk":"11449954910","pt":1717316341298,"mc":[{"id":"1.229554904","rc":[{"atl":[[3.25,13.33]],"id":70003368}],"con":true,"img":false}]}
{"op":"mcm","clk":"11449954920","pt":1717316341378,"mc":[{"id":"1.229554904","rc":[{"atl":[[2.5,20]],"id":47208569}],"con":true,"img":false}]}
{"op":"mcm","clk":"11449955328","pt":1717316346786,"mc":[{"id":"1.229554904","rc":[{"atl":[[5.3,0]],"id":47208569}],"con":true,"img":false}]}
{"op":"mcm","clk":"11449957305","pt":1717316372950,"mc":[{"id":"1.229554904","rc":[{"atl":[[3,7.5]],"id":70003368}],"con":true,"img":false}]}
{"op":"mcm","clk":"11449957314","pt":1717316373050,"mc":[{"id":"1.229554904","rc":[{"atl":[[2.98,0]],"id":70003368}],"con":true,"img":false}]}
{"op":"mcm","clk":"11449962072","pt":1717316432666,"mc":[{"id":"1.229554904","rc":[{"atl":[[3,0],[2.98,7.58]],"id":70003368}],"con":true,"img":false}]}
{"op":"mcm","clk":"11449963627","pt":1717316452879,"mc":[{"id":"1.229554904","rc":[{"atl":[[3,7.5],[2.98,0]],"id":70003368}],"con":true,"img":false}]}
{"op":"mcm","clk":"11449964723","pt":1717316468086,"mc":[{"id":"1.229554904","rc":[{"atl":[[3,0],[2.98,7.58]],"id":70003368}],"con":true,"img":false}]}
{"op":"mcm","clk":"11449966463","pt":1717316492135,"mc":[{"id":"1.229554904","rc":[{"atb":[[1.81,0],[1.91,0]],"id":70003368},{"atb":[[1.84,0],[1.74,0]],"id":47208569}],"con":true,"img":false}]}
{"op":"mcm","clk":"11449966477","pt":1717316492337,"mc":[{"id":"1.229554904","rc":[{"atb":[[1.72,0],[1.25,0],[1.33,173.92],[1.48,31.25]],"id":70003368},{"atl":[[3.6,0],[4.1,23.26]],"id":70003368},{"atb":[[1.48,31.25],[1.47,0]],"id":47208569},{"atl":[[2.72,34.24],[2.48,0]],"id":47208569}],"con":true,"img":false}]}
{"op":"mcm","clk":"11449966821","pt":1717316497235,"mc":[{"id":"1.229554904","rc":[{"atb":[[1.48,0],[1.47,31.91]],"id":70003368},{"atb":[[1.48,0],[1.47,31.91]],"id":47208569}],"con":true,"img":false}]}
{"op":"mcm","clk":"11449966841","pt":1717316497437,"mc":[{"id":"1.229554904","rc":[{"atl":[[2.72,0],[2.96,34.24]],"id":47208569}],"con":true,"img":false}]}
{"op":"mcm","clk":"11449967459","pt":1717316506012,"mc":[{"id":"1.229554904","rc":[{"atb":[[1.48,31.25]],"id":70003368},{"atb":[[1.48,31.25]],"id":47208569}],"con":true,"img":false}]}
{"op":"mcm","clk":"11449967466","pt":1717316506115,"mc":[{"id":"1.229554904","rc":[{"atb":[[1.47,0]],"id":70003368},{"atb":[[1.47,0]],"id":47208569}],"con":true,"img":false}]}
{"op":"mcm","clk":"11449967759","pt":1717316510810,"mc":[{"id":"1.229554904","rc":[{"atb":[[1.81,9.68],[1.91,8.62]],"id":70003368},{"atb":[[1.84,9.34],[1.74,10.6]],"id":47208569}],"con":true,"img":false}]}
{"op":"mcm","clk":"11449967809","pt":1717316511537,"mc":[{"id":"1.229554904","rc":[{"atl":[[2.56,9.62],[2.98,0]],"id":70003368},{"atb":[[1.06,86.96],[1.17,0]],"id":47208569}],"con":true,"img":false}]}
{"op":"mcm","clk":"11449967837","pt":1717316511954,"mc":[{"id":"1.229554904","rc":[{"atb":[[1.16,74.73],[1.06,0]],"id":47208569}],"con":true,"img":false}]}
{"op":"mcm","clk":"11449968084","pt":1717316515929,"mc":[{"id":"1.229554904","rc":[{"atb":[[1.57,86.96],[1.33,0]],"id":70003368},{"atl":[[4.1,0],[3.55,21.39]],"id":70003368},{"atl":[[2.72,31.2]],"id":47208569}],"con":true,"img":false}]}
{"op":"mcm","clk":"11449968090","pt":1717316516032,"mc":[{"id":"1.229554904","rc":[{"atl":[[2.96,0]],"id":47208569}],"con":true,"img":false}]}
{"op":"mcm","clk":"11449968432","pt":1717316521513,"mc":[{"id":"1.229554904","rc":[{"atl":[[2.6,12.5]],"id":70003368}],"con":true,"img":false}]}
{"op":"mcm","clk":"11449969094","pt":1717316531565,"mc":[{"id":"1.229554904","rc":[{"atl":[[2.64,15.24]],"id":70003368}],"con":true,"img":false}]}
{"op":"mcm","clk":"11449969105","pt":1717316531619,"mc":[{"id":"1.229554904","rc":[{"atl":[[3.15,0],[3.25,0],[3.05,0]],"id":70003368}],"con":true,"img":false}]}
{"op":"mcm","clk":"11449969753","pt":1717316541540,"mc":[{"id":"1.229554904","rc":[{"atl":[[2.68,17.86]],"id":70003368}],"con":true,"img":false}]}
{"op":"mcm","clk":"11449975973","pt":1717316631590,"mc":[{"id":"1.229554904","rc":[{"atl":[[2.72,0],[2.88,34.24]],"id":47208569}],"con":true,"img":false}]}
{"op":"mcm","clk":"11449993596","pt":1717316870156,"mc":[{"id":"1.229554904","rc":[{"atb":[[1.81,0],[1.91,0]],"id":70003368},{"atb":[[1.84,0],[1.74,0]],"id":47208569}],"con":true,"img":false}]}
{"op":"mcm","clk":"11449993608","pt":1717316870264,"mc":[{"id":"1.229554904","rc":[{"atb":[[1.57,0],[1.23,206.01]],"id":70003368},{"atl":[[3.2,34.24]],"id":47208569}],"con":true,"img":false}]}
{"op":"mcm","clk":"11449993618","pt":1717316870367,"mc":[{"id":"1.229554904","rc":[{"atl":[[4.1,30.48],[3.55,0]],"id":70003368},{"atl":[[2.88,0]],"id":47208569}],"con":true,"img":false}]}
{"op":"mcm","clk":"11449993964","pt":1717316874073,"mc":[{"id":"1.229554904","rc":[{"atb":[[1.46,43.48]],"id":70003368}],"con":true,"img":false}]}
{"op":"mcm","clk":"11449994066","pt":1717316875371,"mc":[{"id":"1.229554904","rc":[{"atl":[[3.5,34.24]],"id":47208569}],"con":true,"img":false}]}
{"op":"mcm","clk":"11449994070","pt":1717316875471,"mc":[{"id":"1.229554904","rc":[{"atl":[[3.2,0]],"id":47208569}],"con":true,"img":false}]}
{"op":"mcm","clk":"11449994395","pt":1717316879157,"mc":[{"id":"1.229554904","rc":[{"atb":[[1.19,0]],"id":70003368}],"con":true,"img":false}]}
{"op":"mcm","clk":"11449994808","pt":1717316884053,"mc":[{"id":"1.229554904","rc":[{"atb":[[1.44,56.82]],"id":70003368}],"con":true,"img":false}]}
{"op":"mcm","clk":"11449994923","pt":1717316885299,"mc":[{"id":"1.229554904","rc":[{"atb":[[1.21,0]],"id":70003368}],"con":true,"img":false}]}
{"op":"mcm","clk":"11449995350","pt":1717316890057,"mc":[{"id":"1.229554904","rc":[{"atb":[[1.44,131.55],[1.23,86.96]],"id":70003368}],"con":true,"img":false}]}
{"op":"mcm","clk":"11449995714","pt":1717316894088,"mc":[{"id":"1.229554904","rc":[{"atb":[[1.42,71.43]],"id":70003368}],"con":true,"img":false}]}
{"op":"mcm","clk":"11449996389","pt":1717316901784,"mc":[{"id":"1.229554904","rc":[{"atb":[[1.81,9.68],[1.91,8.62]],"id":70003368},{"atb":[[1.84,9.34],[1.74,10.6]],"id":47208569}],"con":true,"img":false}]}
{"op":"mcm","clk":"11449996547","pt":1717316903501,"mc":[{"id":"1.229554904","rc":[{"atl":[[4.1,0],[3.75,27.74]],"id":70003368},{"atl":[[2.88,31.2],[3.5,0]],"id":47208569}],"con":true,"img":false}]}
{"op":"mcm","clk":"11449997033","pt":1717316909724,"mc":[{"id":"1.229554904","rc":[{"atb":[[1.44,56.82],[1.52,43.48]],"id":70003368}],"con":true,"img":false}]}
{"op":"mcm","clk":"11449997914","pt":1717316920825,"mc":[{"id":"1.229554904","rc":[{"atb":[[1.48,0]],"id":70003368},{"atb":[[1.48,0]],"id":47208569}],"con":true,"img":false}]}
{"op":"mcm","clk":"11450001564","pt":1717316963575,"mc":[{"id":"1.229554904","rc":[{"atb":[[1.58,43.48],[1.52,0]],"id":70003368},{"atl":[[2.88,0],[2.7,31.2]],"id":47208569}],"con":true,"img":false}]}
{"op":"mcm","clk":"11450001573","pt":1717316963677,"mc":[{"id":"1.229554904","rc":[{"atl":[[2.56,0],[2.58,9.49]],"id":70003368}],"con":true,"img":false}]}
{"op":"mcm","clk":"11450002845","pt":1717316978708,"mc":[{"id":"1.229554904","rc":[{"atl":[[2.56,9.62],[2.58,0]],"id":70003368}],"con":true,"img":false}]}
{"op":"mcm","clk":"11450014362","pt":1717317098737,"mc":[{"id":"1.229554904","rc":[{"atb":[[1.58,0],[1.52,56.82]],"id":70003368},{"atl":[[2.88,34.24],[2.7,0]],"id":47208569}],"con":true,"img":false}]}
{"op":"mcm","clk":"11450027897","pt":1717317235132,"mc":[{"id":"1.229554904","rc":[{"atb":[[1.81,0],[1.91,0]],"id":70003368},{"atb":[[1.84,0],[1.74,0]],"id":47208569}],"con":true,"img":false}]}
{"op":"mcm","clk":"11450027905","pt":1717317235234,"mc":[{"id":"1.229554904","rc":[{"atb":[[1.44,157.12],[1.47,31.91],[1.52,0]],"id":70003368},{"atl":[[4.1,30.48],[3.75,0]],"id":70003368},{"atb":[[1.47,31.91]],"id":47208569},{"atl":[[2.88,0],[3.2,34.24]],"id":47208569}],"con":true,"img":false}]}
{"op":"mcm","clk":"11450027917","pt":1717317235339,"mc":[{"id":"1.229554904","rc":[{"atb":[[1.46,113.64],[1.44,56.82]],"id":70003368}],"con":true,"img":false}]}
{"op":"mcm","clk":"11450027926","pt":1717317235438,"mc":[{"id":"1.229554904","rc":[{"atb":[[1.44,143.78],[1.23,0]],"id":70003368},{"atl":[[3.2,0],[3.5,34.24]],"id":47208569}],"con":true,"img":false}]}
{"op":"mcm","clk":"11450027940","pt":1717317235547,"mc":[{"id":"1.229554904","rc":[{"atb":[[1.46,0]],"id":70003368}],"con":true,"img":false}]}
{"op":"mcm","clk":"11450028047","pt":1717317236635,"mc":[{"id":"1.229554904","rc":[{"atb":[[1.48,31.25]],"id":70003368}],"con":true,"img":false}]}
{"op":"mcm","clk":"11450028058","pt":1717317236741,"mc":[{"id":"1.229554904","rc":[{"atb":[[1.44,56.82],[1.49,31.91]],"id":70003368}],"con":true,"img":false}]}
{"op":"mcm","clk":"11450028069","pt":1717317236845,"mc":[{"id":"1.229554904","rc":[{"atb":[[1.49,0],[1.47,95.07]],"id":70003368}],"con":true,"img":false}]}
{"op":"mcm","clk":"11450028771","pt":1717317244179,"mc":[{"id":"1.229554904","rc":[{"atb":[[1.48,0]],"id":70003368}],"con":true,"img":false}]}
{"op":"mcm","clk":"11450028789","pt":1717317244338,"mc":[{"id":"1.229554904","rc":[{"atb":[[1.42,223.32],[1.47,31.91]],"id":70003368}],"con":true,"img":false}]}
{"op":"mcm","clk":"11450028817","pt":1717317244647,"mc":[{"id":"1.229554904","rc":[{"atb":[[1.48,31.25]],"id":70003368}],"con":true,"img":false}]}
{"op":"mcm","clk":"11450028825","pt":1717317244753,"mc":[{"id":"1.229554904","rc":[{"atb":[[1.44,120.64]],"id":70003368}],"con":true,"img":false}]}
{"op":"mcm","clk":"11450028832","pt":1717317244857,"mc":[{"id":"1.229554904","rc":[{"atb":[[1.42,71.43]],"id":70003368}],"con":true,"img":false}]}
{"op":"mcm","clk":"11450031377","pt":1717317270283,"mc":[{"id":"1.229554904","rc":[{"atb":[[1.81,9.68],[1.91,8.62]],"id":70003368},{"atb":[[1.84,9.34],[1.74,10.6]],"id":47208569}],"con":true,"img":false}]}
{"op":"mcm","clk":"11450031385","pt":1717317270383,"mc":[{"id":"1.229554904","rc":[{"atb":[[1.44,56.82],[1.52,31.91]],"id":70003368}],"con":true,"img":false}]}
{"op":"mcm","clk":"11450031604","pt":1717317272459,"mc":[{"id":"1.229554904","rc":[{"atl":[[3.75,27.74]],"id":70003368},{"atl":[[2.88,31.2]],"id":47208569}],"con":true,"img":false}]}
{"op":"mcm","clk":"11450031615","pt":1717317272561,"mc":[{"id":"1.229554904","rc":[{"atl":[[4.1,0]],"id":70003368},{"atl":[[3.5,0]],"id":47208569}],"con":true,"img":false}]}
{"op":"mcm","clk":"11450056851","pt":1717317519887,"mc":[{"id":"1.229554904","rc":[{"atb":[[1.48,0],[1.47,0]],"id":70003368}],"con":true,"img":false}]}
{"op":"mcm","clk":"11450068130","pt":1717317644469,"mc":[{"id":"1.229554904","rc":[{"atb":[[1.81,0],[1.91,0]],"id":70003368},{"atb":[[1.84,0],[1.74,0]],"id":47208569}],"con":true,"img":false}]}
{"op":"mcm","clk":"11450068141","pt":1717317644598,"mc":[{"id":"1.229554904","rc":[{"atb":[[1.42,160.16],[1.52,0]],"id":70003368}],"con":true,"img":false}]}
{"op":"mcm","clk":"11450068149","pt":1717317644675,"mc":[{"id":"1.229554904","rc":[{"atb":[[1.12,216.98],[1.42,71.43],[1.47,31.91]],"id":70003368},{"atl":[[4.1,30.48],[3.75,0]],"id":70003368},{"atl":[[2.88,0],[3.2,34.24]],"id":47208569}],"con":true,"img":false}]}
{"op":"mcm","clk":"11450068160","pt":1717317644782,"mc":[{"id":"1.229554904","rc":[{"atb":[[1.12,0],[1.42,185.07]],"id":70003368}],"con":true,"img":false}]}
{"op":"mcm","clk":"11450068191","pt":1717317645096,"mc":[{"id":"1.229554904","rc":[{"atb":[[1.48,31.25]],"id":70003368},{"atb":[[1.48,31.25],[1.47,0]],"id":47208569},{"atl":[[3.2,0],[3.5,34.24]],"id":47208569}],"con":true,"img":false}]}
{"op":"mcm","clk":"11450068204","pt":1717317645149,"mc":[{"id":"1.229554904","rc":[{"atb":[[1.44,120.64]],"id":70003368}],"con":true,"img":false}]}
{"op":"mcm","clk":"11450068220","pt":1717317645304,"mc":[{"id":"1.229554904","rc":[{"atb":[[1.42,71.43]],"id":70003368}],"con":true,"img":false}]}
{"op":"mcm","clk":"11450068600","pt":1717317649467,"mc":[{"id":"1.229554904","rc":[{"atb":[[1.48,0]],"id":70003368},{"atb":[[1.48,0],[1.47,31.91]],"id":47208569}],"con":true,"img":false}]}
{"op":"mcm","clk":"11450070061","pt":1717317665515,"mc":[{"id":"1.229554904","rc":[{"atb":[[1.48,31.25]],"id":70003368}],"con":true,"img":false}]}
{"op":"mcm","clk":"11450071059","pt":1717317675929,"mc":[{"id":"1.229554904","rc":[{"atb":[[1.81,9.68],[1.91,8.62]],"id":70003368},{"atb":[[1.84,9.34],[1.74,10.6]],"id":47208569}],"con":true,"img":false}]}
{"op":"mcm","clk":"11450071068","pt":1717317675988,"mc":[{"id":"1.229554904","rc":[{"atb":[[1.44,56.82],[1.52,31.91]],"id":70003368}],"con":true,"img":false}]}
{"op":"mcm","clk":"11450071222","pt":1717317677500,"mc":[{"id":"1.229554904","rc":[{"atl":[[4.1,0],[3.75,27.74]],"id":70003368},{"atl":[[2.88,31.2],[3.5,0]],"id":47208569}],"con":true,"img":false}]}
{"op":"mcm","clk":"11450083720","pt":1717317817007,"mc":[{"id":"1.229554904","rc":[{"atb":[[1.48,0],[1.47,0]],"id":70003368}],"con":true,"img":false}]}
{"op":"mcm","clk":"11450093481","pt":1717317929331,"mc":[{"id":"1.229554904","rc":[{"atb":[[1.81,0],[1.91,0]],"id":70003368},{"atb":[[1.84,0],[1.74,0]],"id":47208569}],"con":true,"img":false}]}
{"op":"mcm","clk":"11450093497","pt":1717317929434,"mc":[{"id":"1.229554904","rc":[{"atb":[[1.42,160.16]],"id":70003368}],"con":true,"img":false}]}
{"op":"mcm","clk":"11450093512","pt":1717317929539,"mc":[{"id":"1.229554904","rc":[{"atb":[[1.48,31.25],[1.52,0]],"id":70003368},{"atl":[[4.1,30.48],[3.75,0]],"id":70003368},{"atl":[[2.88,0],[3.2,34.24]],"id":47208569}],"con":true,"img":false}]}
{"op":"mcm","clk":"11450094002","pt":1717317934646,"mc":[{"id":"1.229554904","rc":[{"atl":[[3.5,34.24]],"id":47208569}],"con":true,"img":false}]}
{"op":"mcm","clk":"11450094011","pt":1717317934745,"mc":[{"id":"1.229554904","rc":[{"atl":[[3.2,0]],"id":47208569}],"con":true,"img":false}]}
{"op":"mcm","clk":"11450094349","pt":1717317938653,"mc":[{"id":"1.229554904","rc":[{"atb":[[1.44,119.32],[1.42,71.43]],"id":70003368}],"con":true,"img":false}]}
{"op":"mcm","clk":"11450094427","pt":1717317939537,"mc":[{"id":"1.229554904","rc":[{"atb":[[1.46,43.48]],"id":70003368}],"con":true,"img":false}]}
{"op":"mcm","clk":"11450095079","pt":1717317946968,"mc":[{"id":"1.229554904","rc":[{"atb":[[1.81,9.68],[1.91,8.62]],"id":70003368},{"atb":[[1.84,9.34],[1.74,10.6]],"id":47208569}],"con":true,"img":false}]}
{"op":"mcm","clk":"11450095150","pt":1717317947847,"mc":[{"id":"1.229554904","rc":[{"atb":[[1.52,43.48]],"id":70003368}],"con":true,"img":false}]}
{"op":"mcm","clk":"11450095189","pt":1717317947951,"mc":[{"id":"1.229554904","rc":[{"atb":[[1.44,56.82]],"id":70003368}],"con":true,"img":false}]}
{"op":"mcm","clk":"11450095381","pt":1717317950074,"mc":[{"id":"1.229554904","rc":[{"atl":[[3.75,27.74]],"id":70003368},{"atl":[[2.88,31.2]],"id":47208569}],"con":true,"img":false}]}
{"op":"mcm","clk":"11450095387","pt":1717317950181,"mc":[{"id":"1.229554904","rc":[{"atl":[[4.1,0]],"id":70003368},{"atl":[[3.5,0]],"id":47208569}],"con":true,"img":false}]}
{"op":"mcm","clk":"11450099409","pt":1717317999432,"mc":[{"id":"1.229554904","rc":[{"atb":[[1.48,0]],"id":70003368}],"con":true,"img":false}]}
{"op":"mcm","clk":"11450111170","pt":1717318130781,"mc":[{"id":"1.229554904","rc":[{"atb":[[1.81,0],[1.91,0]],"id":70003368},{"atb":[[1.84,0],[1.74,0]],"id":47208569}],"con":true,"img":false}]}
{"op":"mcm","clk":"11450111188","pt":1717318130993,"mc":[{"id":"1.229554904","rc":[{"atb":[[1.44,143.78],[1.52,0]],"id":70003368}],"con":true,"img":false}]}
{"op":"mcm","clk":"11450111204","pt":1717318131201,"mc":[{"id":"1.229554904","rc":[{"atb":[[1.48,31.25]],"id":70003368},{"atl":[[4.5,28.57],[3.75,0]],"id":70003368},{"atl":[[2.88,0],[3.5,34.24]],"id":47208569}],"con":true,"img":false}]}
{"op":"mcm","clk":"11450115435","pt":1717318177651,"mc":[{"id":"1.229554904","rc":[{"atb":[[1.81,9.68],[1.91,8.62]],"id":70003368},{"atb":[[1.84,9.34],[1.74,10.6]],"id":47208569}],"con":true,"img":false}]}
{"op":"mcm","clk":"11450115452","pt":1717318177858,"mc":[{"id":"1.229554904","rc":[{"atb":[[1.44,56.82],[1.52,43.48]],"id":70003368}],"con":true,"img":false}]}
{"op":"mcm","clk":"11450115478","pt":1717318178218,"mc":[{"id":"1.229554904","rc":[{"atb":[[1.48,0]],"id":70003368},{"atl":[[4.5,0],[3.75,27.74]],"id":70003368},{"atl":[[2.88,31.2],[3.5,0]],"id":47208569}],"con":true,"img":false}]}
{"op":"mcm","clk":"11450115923","pt":1717318183474,"mc":[{"id":"1.229554904","rc":[{"atb":[[1.92,2],[1.58,43.48],[1.52,0]],"id":70003368},{"atl":[[2.76,2]],"id":70003368},{"atb":[[1.5,2]],"id":47208569},{"atl":[[2.38,12.87]],"id":47208569}],"con":true,"img":false}]}
{"op":"mcm","clk":"11450115931","pt":1717318183573,"mc":[{"id":"1.229554904","rc":[{"atl":[[2.56,0],[2.58,9.49]],"id":70003368}],"con":true,"img":false}]}
{"op":"mcm","clk":"11450116063","pt":1717318184970,"mc":[{"id":"1.229554904","rc":[{"atl":[[2.88,0],[2.68,31.2]],"id":47208569}],"con":true,"img":false}]}
{"op":"mcm","clk":"11450118838","pt":1717318215991,"mc":[{"id":"1.229554904","rc":[{"atl":[[2.36,2],[2.38,10.87]],"id":47208569}],"con":true,"img":false}]}
{"op":"mcm","clk":"11450119496","pt":1717318223189,"mc":[{"id":"1.229554904","rc":[{"atl":[[2.36,0],[2.38,12.87]],"id":47208569}],"con":true,"img":false}]}
{"op":"mcm","clk":"11450119607","pt":1717318224273,"mc":[{"id":"1.229554904","rc":[{"atl":[[2.36,2],[2.38,10.87]],"id":47208569}],"con":true,"img":false}]}
{"op":"mcm","clk":"11450119670","pt":1717318224998,"mc":[{"id":"1.229554904","rc":[{"atl":[[2.38,12.87]],"id":47208569}],"con":true,"img":false}]}
{"op":"mcm","clk":"11450119677","pt":1717318225104,"mc":[{"id":"1.229554904","rc":[{"atl":[[2.36,0]],"id":47208569}],"con":true,"img":false}]}
{"op":"mcm","clk":"11450123257","pt":1717318267118,"mc":[{"id":"1.229554904","rc":[{"atb":[[1.92,0]],"id":70003368},{"atl":[[2.76,0]],"id":70003368},{"atb":[[1.5,0]],"id":47208569},{"atl":[[2.38,10.87]],"id":47208569}],"con":true,"img":false}]}
{"op":"mcm","clk":"11450123293","pt":1717318267533,"mc":[{"id":"1.229554904","rc":[{"atl":[[2.38,0],[2.44,10.42]],"id":47208569}],"con":true,"img":false}]}
{"op":"mcm","clk":"11450123381","pt":1717318268734,"mc":[{"id":"1.229554904","rc":[{"atb":[[1.81,0],[1.91,0]],"id":70003368},{"atb":[[1.84,0],[1.74,0]],"id":47208569}],"con":true,"img":false}]}
{"op":"mcm","clk":"11450123399","pt":1717318268941,"mc":[{"id":"1.229554904","rc":[{"atb":[[1.44,143.78],[1.58,0]],"id":70003368}],"con":true,"img":false}]}
{"op":"mcm","clk":"11450123410","pt":1717318269047,"mc":[{"id":"1.229554904","rc":[{"atb":[[1.44,56.82],[1.42,258.69]],"id":70003368}],"con":true,"img":false}]}
{"op":"mcm","clk":"11450123443","pt":1717318269444,"mc":[{"id":"1.229554904","rc":[{"atl":[[4.3,30.3],[3.75,0]],"id":70003368},{"atl":[[3.3,34.24],[2.68,0]],"id":47208569}],"con":true,"img":false}]}
{"op":"mcm","clk":"11450124063","pt":1717318276333,"mc":[{"id":"1.229554904","rc":[{"atb":[[1.48,31.25]],"id":70003368}],"con":true,"img":false}]}
{"op":"mcm","clk":"11450124075","pt":1717318276440,"mc":[{"id":"1.229554904","rc":[{"atb":[[1.44,143.78]],"id":70003368},{"atl":[[2.38,10.87]],"id":47208569}],"con":true,"img":false}]}
{"op":"mcm","clk":"11450124086","pt":1717318276538,"mc":[{"id":"1.229554904","rc":[{"atb":[[1.42,71.43]],"id":70003368},{"atl":[[2.42,0]],"id":47208569}],"con":true,"img":false}]}
{"op":"mcm","clk":"11450125647","pt":1717318294890,"mc":[{"id":"1.229554904","rc":[{"atl":[[2.38,0]],"id":47208569}],"con":true,"img":false}]}
{"op":"mcm","clk":"11450125755","pt":1717318296181,"mc":[{"id":"1.229554904","rc":[{"atl":[[2.38,10.87]],"id":47208569}],"con":true,"img":false}]}
{"op":"mcm","clk":"11450125858","pt":1717318297466,"mc":[{"id":"1.229554904","rc":[{"atl":[[2.38,0]],"id":47208569}],"con":true,"img":false}]}
{"op":"mcm","clk":"11450125992","pt":1717318298864,"mc":[{"id":"1.229554904","rc":[{"atb":[[1.81,9.68],[1.91,8.62]],"id":70003368},{"atb":[[1.84,9.34],[1.74,10.6]],"id":47208569}],"con":true,"img":false}]}
{"op":"mcm","clk":"11450126012","pt":1717318299074,"mc":[{"id":"1.229554904","rc":[{"atb":[[1.44,56.82],[1.52,43.48]],"id":70003368}],"con":true,"img":false}]}
{"op":"mcm","clk":"11450126131","pt":1717318300643,"mc":[{"id":"1.229554904","rc":[{"atl":[[3.6,27.74],[4.3,0]],"id":70003368},{"atl":[[3.3,0],[2.68,34.24]],"id":47208569}],"con":true,"img":false}]}
{"op":"mcm","clk":"11450126188","pt":1717318301257,"mc":[{"id":"1.229554904","rc":[{"atb":[[1.92,2]],"id":70003368},{"atl":[[2.54,9.74],[2.58,0],[2.78,2]],"id":70003368},{"atb":[[1.09,86.96],[1.49,2]],"id":47208569},{"atl":[[2.38,2]],"id":47208569}],"con":true,"img":false}]}
{"op":"mcm","clk":"11450126196","pt":1717318301320,"mc":[{"id":"1.229554904","rc":[{"atl":[[2.56,9.62],[2.54,0]],"id":70003368},{"atb":[[1.16,0]],"id":47208569}],"con":true,"img":false}]}
{"op":"mcm","clk":"11450126215","pt":1717318301518,"mc":[{"id":"1.229554904","rc":[{"atb":[[1.57,43.48],[1.52,0]],"id":70003368}],"con":true,"img":false}]}
{"op":"mcm","clk":"11450126505","pt":1717318304524,"mc":[{"id":"1.229554904","rc":[{"atl":[[2.48,13.51]],"id":47208569}],"con":true,"img":false}]}
{"op":"mcm","clk":"11450126652","pt":1717318306540,"mc":[{"id":"1.229554904","rc":[{"atl":[[2.42,10.56],[2.44,0]],"id":47208569}],"con":true,"img":false}]}
{"op":"mcm","clk":"11450126672","pt":1717318306738,"mc":[{"id":"1.229554904","rc":[{"atb":[[1.16,63.82],[1.09,0]],"id":47208569}],"con":true,"img":false}]}
{"op":"mcm","clk":"11450128141","pt":1717318323851,"mc":[{"id":"1.229554904","rc":[{"atb":[[1.81,0],[1.91,0]],"id":70003368},{"atb":[[1.84,0],[1.74,0]],"id":47208569}],"con":true,"img":false}]}
{"op":"mcm","clk":"11450128152","pt":1717318323973,"mc":[{"id":"1.229554904","rc":[{"atb":[[1.92,0],[1.48,76.73]],"id":70003368},{"atb":[[1.5,2]],"id":47208569}],"con":true,"img":false}]}
{"op":"mcm","clk":"11450128162","pt":1717318324073,"mc":[{"id":"1.229554904","rc":[{"atb":[[1.57,0],[1.7,2]],"id":70003368},{"atb":[[1.49,0]],"id":47208569}],"con":true,"img":false}]}
{"op":"mcm","clk":"11450128174","pt":1717318324162,"mc":[{"id":"1.229554904","rc":[{"atb":[[1.46,163.69],[1.48,31.25]],"id":70003368}],"con":true,"img":false}]}
{"op":"mcm","clk":"11450128236","pt":1717318324842,"mc":[{"id":"1.229554904","rc":[{"atl":[[3.9,27.74]],"id":70003368},{"atl":[[3.05,30.63]],"id":47208569}],"con":true,"img":false}]}
{"op":"mcm","clk":"11450128245","pt":1717318324952,"mc":[{"id":"1.229554904","rc":[{"atl":[[3.6,0]],"id":70003368},{"atl":[[2.68,0]],"id":47208569}],"con":true,"img":false}]}
{"op":"mcm","clk":"11450128747","pt":1717318330238,"mc":[{"id":"1.229554904","rc":[{"atb":[[1.48,31.25],[1.47,0]],"id":47208569}],"con":true,"img":false}]}
{"op":"mcm","clk":"11450129268","pt":1717318336095,"mc":[{"id":"1.229554904","rc":[{"atb":[[1.88,8.92],[1.78,10.06]],"id":70003368},{"atb":[[1.88,8.92],[1.78,10.06]],"id":47208569}],"con":true,"img":false}]}
{"op":"mcm","clk":"11450129281","pt":1717318336161,"mc":[{"id":"1.229554904","rc":[{"atb":[[1.89,2]],"id":70003368}],"con":true,"img":false}]}
{"op":"mcm","clk":"11450129288","pt":1717318336259,"mc":[{"id":"1.229554904","rc":[{"atb":[[1.46,43.48],[1.57,56.82],[1.7,0]],"id":70003368},{"atl":[[3.55,25],[3.9,0]],"id":70003368},{"atl":[[2.72,27.02],[3.05,0]],"id":47208569}],"con":true,"img":false}]}
{"op":"mcm","clk":"11450129315","pt":1717318336570,"mc":[{"id":"1.229554904","rc":[{"atb":[[1.48,0]],"id":70003368},{"atb":[[1.48,0]],"id":47208569}],"con":true,"img":false}]}
{"op":"mcm","clk":"11450129350","pt":1717318336979,"mc":[{"id":"1.229554904","rc":[{"atl":[[2.36,2]],"id":47208569}],"con":true,"img":false}]}
{"op":"mcm","clk":"11450129358","pt":1717318337083,"mc":[{"id":"1.229554904","rc":[{"atl":[[2.38,0]],"id":47208569}],"con":true,"img":false}]}
{"op":"mcm","clk":"11450131043","pt":1717318356587,"mc":[{"id":"1.229554904","rc":[{"atl":[[2.36,0],[2.38,2]],"id":47208569}],"con":true,"img":false}]}
{"op":"mcm","clk":"11450131918","pt":1717318367222,"mc":[{"id":"1.229554904","rc":[{"atb":[[1.89,0]],"id":70003368},{"atl":[[2.78,0]],"id":70003368},{"atb":[[1.5,0]],"id":47208569},{"atl":[[2.38,0]],"id":47208569}],"con":true,"img":false}]}
{"op":"mcm","clk":"11450133294","pt":1717318383592,"mc":[{"id":"1.229554904","rc":[{"atl":[[2.44,10.42]],"id":47208569}],"con":true,"img":false}]}
{"op":"mcm","clk":"11450133307","pt":1717318383693,"mc":[{"id":"1.229554904","rc":[{"atb":[[1.79,4.66]],"id":70003368},{"atl":[[2.54,4.04]],"id":70003368},{"atb":[[1.79,4.79]],"id":47208569},{"atl":[[2.42,0]],"id":47208569}],"con":true,"img":false}]}
{"op":"mcm","clk":"11450133315","pt":1717318383795,"mc":[{"id":"1.229554904","rc":[{"atl":[[2.4,4.14]],"id":47208569}],"con":true,"img":false}]}
{"op":"mcm","clk":"11450133799","pt":1717318389906,"mc":[{"id":"1.229554904","rc":[{"atb":[[1.88,0],[1.78,0]],"id":70003368},{"atb":[[1.88,0],[1.78,0]],"id":47208569}],"con":true,"img":false}]}
{"op":"mcm","clk":"11450134730","pt":1717318401243,"mc":[{"id":"1.229554904","rc":[{"atb":[[1.77,10.19],[1.87,9.01]],"id":70003368},{"atb":[[1.79,14.73],[1.89,8.81]],"id":47208569}],"con":true,"img":false}]}
{"op":"mcm","clk":"11450135331","pt":1717318408249,"mc":[{"id":"1.229554904","rc":[{"atb":[[1.57,0],[1.74,56.82],[1.88,4.35]],"id":70003368},{"atl":[[2.56,0],[3.2,25],[2.6,9.38],[3.55,0],[2.76,4.35]],"id":70003368},{"atb":[[1.28,86.96],[1.16,0],[1.5,2.08]],"id":47208569},{"atl":[[2.36,2.08],[2.72,0],[2.66,27.02]],"id":47208569}],"con":true,"img":false}]}
{"op":"mcm","clk":"11450135768","pt":1717318413364,"mc":[{"id":"1.229554904","rc":[{"atl":[[2.38,10.42],[2.66,0]],"id":47208569}],"con":true,"img":false}]}
{"op":"mcm","clk":"11450135893","pt":1717318414763,"mc":[{"id":"1.229554904","rc":[{"atl":[[2.64,12.2]],"id":70003368}],"con":true,"img":false}]}
{"op":"mcm","clk":"11450136372","pt":1717318420140,"mc":[{"id":"1.229554904","rc":[{"atl":[[2.36,0],[2.34,2.08]],"id":47208569}],"con":true,"img":false}]}
{"op":"mcm","clk":"11450136379","pt":1717318420243,"mc":[{"id":"1.229554904","rc":[{"atl":[[2.36,10.42]],"id":47208569}],"con":true,"img":false}]}
{"op":"mcm","clk":"11450136384","pt":1717318420348,"mc":[{"id":"1.229554904","rc":[{"atl":[[2.38,0]],"id":47208569}],"con":true,"img":false}]}
{"op":"mcm","clk":"11450136391","pt":1717318420451,"mc":[{"id":"1.229554904","rc":[{"atl":[[2.38,12.5]],"id":47208569}],"con":true,"img":false}]}
{"op":"mcm","clk":"11450136400","pt":1717318420553,"mc":[{"id":"1.229554904","rc":[{"atl":[[2.36,0]],"id":47208569}],"con":true,"img":false}]}
{"op":"mcm","clk":"11450136442","pt":1717318421168,"mc":[{"id":"1.229554904","rc":[{"atl":[[2.68,14.88]],"id":70003368}],"con":true,"img":false}]}
{"op":"mcm","clk":"11450136766","pt":1717318424784,"mc":[{"id":"1.229554904","rc":[{"atl":[[2.6,0],[2.62,9.26]],"id":70003368}],"con":true,"img":false}]}
{"op":"mcm","clk":"11450136921","pt":1717318426432,"mc":[{"id":"1.229554904","rc":[{"atl":[[2.42,10.56],[2.38,23.37],[2.44,0]],"id":47208569}],"con":true,"img":false}]}
{"op":"mcm","clk":"11450137021","pt":1717318427778,"mc":[{"id":"1.229554904","rc":[{"atb":[[1.77,0],[1.87,0]],"id":70003368},{"atb":[[1.79,4.79],[1.89,0]],"id":47208569},{"atl":[[2.5,0],[2.48,0]],"id":47208569}],"con":true,"img":false}]}
{"op":"mcm","clk":"11450137029","pt":1717318427878,"mc":[{"id":"1.229554904","rc":[{"atb":[[1.8,2],[1.88,0]],"id":70003368}],"con":true,"img":false}]}
{"op":"mcm","clk":"11450137324","pt":1717318430990,"mc":[{"id":"1.229554904","rc":[{"atl":[[2.66,12.05]],"id":70003368}],"con":true,"img":false}]}
{"op":"mcm","clk":"11450137481","pt":1717318432745,"mc":[{"id":"1.229554904","rc":[{"atl":[[2.38,12.5],[2.46,13.7]],"id":47208569}],"con":true,"img":false}]}
{"op":"mcm","clk":"11450137502","pt":1717318432948,"mc":[{"id":"1.229554904","rc":[{"atb":[[1.8,6.66],[1.74,0]],"id":70003368},{"atl":[[2.68,23.81]],"id":70003368}],"con":true,"img":false}]}
{"op":"mcm","clk":"11450137511","pt":1717318433051,"mc":[{"id":"1.229554904","rc":[{"atl":[[2.62,0],[2.68,8.93]],"id":70003368}],"con":true,"img":false}]}
{"op":"mcm","clk":"11450137571","pt":1717318433876,"mc":[{"id":"1.229554904","rc":[{"atl":[[2.64,0]],"id":70003368}],"con":true,"img":false}]}
{"op":"mcm","clk":"11450137659","pt":1717318434863,"mc":[{"id":"1.229554904","rc":[{"atl":[[2.66,0]],"id":70003368}],"con":true,"img":false}]}
{"op":"mcm","clk":"11450137711","pt":1717318435481,"mc":[{"id":"1.229554904","rc":[{"atl":[[2.32,10],[2.34,0]],"id":47208569}],"con":true,"img":false}]}
{"op":"mcm","clk":"11450137719","pt":1717318435583,"mc":[{"id":"1.229554904","rc":[{"atl":[[2.3,10],[2.38,0]],"id":47208569}],"con":true,"img":false}]}
{"op":"mcm","clk":"11450138026","pt":1717318438875,"mc":[{"id":"1.229554904","rc":[{"atl":[[2.5,16.67]],"id":47208569}],"con":true,"img":false}]}
{"op":"mcm","clk":"11450138054","pt":1717318439197,"mc":[{"id":"1.229554904","rc":[{"atl":[[2.72,11.63]],"id":70003368}],"con":true,"img":false}]}
{"op":"mcm","clk":"11450138105","pt":1717318439766,"mc":[{"id":"1.229554904","rc":[{"atl":[[2.3,0],[2.38,20]],"id":47208569}],"con":true,"img":false}]}
{"op":"mcm","clk":"11450138280","pt":1717318441579,"mc":[{"id":"1.229554904","rc":[{"atl":[[2.42,0],[2.44,10.42]],"id":47208569}],"con":true,"img":false}]}
{"op":"mcm","clk":"11450138302","pt":1717318441785,"mc":[{"id":"1.229554904","rc":[{"atl":[[2.32,0],[2.38,22]],"id":47208569}],"con":true,"img":false}]}
{"op":"mcm","clk":"11450138323","pt":1717318441990,"mc":[{"id":"1.229554904","rc":[{"atl":[[2.72,8.72],[2.68,0]],"id":70003368}],"con":true,"img":false}]}
{"op":"mcm","clk":"11450138335","pt":1717318442095,"mc":[{"id":"1.229554904","rc":[{"atl":[[2.32,2],[2.38,20]],"id":47208569}],"con":true,"img":false}]}
{"op":"mcm","clk":"11450138370","pt":1717318442408,"mc":[{"id":"1.229554904","rc":[{"atb":[[1.77,10.19],[1.87,9.01]],"id":70003368},{"atb":[[1.79,14.73],[1.89,8.81]],"id":47208569}],"con":true,"img":false}]}
{"op":"mcm","clk":"11450138379","pt":1717318442461,"mc":[{"id":"1.229554904","rc":[{"atb":[[1.8,4.66],[1.88,2.02]],"id":70003368}],"con":true,"img":false}]}
{"op":"mcm","clk":"11450138401","pt":1717318442668,"mc":[{"id":"1.229554904","rc":[{"atl":[[2.32,0],[2.34,10]],"id":47208569}],"con":true,"img":false}]}
{"op":"mcm","clk":"11450138437","pt":1717318443081,"mc":[{"id":"1.229554904","rc":[{"atb":[[1.64,2],[1.6,40],[1.58,2],[1.78,8],[1.68,2],[1.62,2],[1.53,60],[1.71,18],[1.76,2],[1.69,2],[1.8,9.66],[1.72,2],[1.55,2],[1.74,2],[1.77,12.19],[1.75,12],[1.66,27]],"id":70003368}],"con":true,"img":false}]}
{"op":"mcm","clk":"11450138456","pt":1717318443286,"mc":[{"id":"1.229554904","rc":[{"atb":[[1.8,5]],"id":70003368}],"con":true,"img":false}]}
{"op":"mcm","clk":"11450138467","pt":1717318443395,"mc":[{"id":"1.229554904","rc":[{"atb":[[1.77,28.19]],"id":70003368}],"con":true,"img":false}]}
{"op":"mcm","clk":"11450138591","pt":1717318444790,"mc":[{"id":"1.229554904","rc":[{"atl":[[3.6,2],[3.1,8],[3,5],[3.8,2],[3.25,12],[3.55,2],[3.3,2],[4,40],[3.45,18],[4.5,2],[3.2,27],[3.7,27],[3.4,2],[3.15,2],[3.9,2],[4.2,2],[4.7,60]],"id":70003368}],"con":true,"img":false}]}
{"op":"mcm","clk":"11450138710","pt":1717318446487,"mc":[{"id":"1.229554904","rc":[{"atl":[[2.42,10.56]],"id":47208569}],"con":true,"img":false}]}
{"op":"mcm","clk":"11450138811","pt":1717318447781,"mc":[{"id":"1.229554904","rc":[{"atl":[[2.36,10],[2.34,0]],"id":47208569}],"con":true,"img":false}]}
{"op":"mcm","clk":"11450138818","pt":1717318447883,"mc":[{"id":"1.229554904","rc":[{"atl":[[2.76,15.71]],"id":70003368}],"con":true,"img":false}]}
{"op":"mcm","clk":"11450139100","pt":1717318451287,"mc":[{"id":"1.229554904","rc":[{"atb":[[1.78,10],[1.96,5],[1.93,2],[1.71,20],[1.92,2],[1.74,4],[1.88,4.02],[1.91,12],[1.9,2],[1.84,2],[1.85,2],[1.94,8],[1.87,27.01],[1.76,42],[1.69,62],[1.8,7],[1.82,27]],"id":70003368}],"con":true,"img":false}]}
{"op":"mcm","clk":"11450139109","pt":1717318451393,"mc":[{"id":"1.229554904","rc":[{"atb":[[1.93,12],[1.88,2],[1.77,12.19],[1.82,38.04]],"id":70003368}],"con":true,"img":false}]}
{"op":"mcm","clk":"11450139317","pt":1717318453779,"mc":[{"id":"1.229554904","rc":[{"atl":[[2.8,13.89]],"id":70003368}],"con":true,"img":false}]}
{"op":"mcm","clk":"11450139439","pt":1717318455016,"mc":[{"id":"1.229554904","rc":[{"atl":[[2.7,8.82]],"id":70003368}],"con":true,"img":false}]}
{"op":"mcm","clk":"11450139461","pt":1717318455224,"mc":[{"id":"1.229554904","rc":[{"atb":[[1.8,4.77]],"id":47208569},{"atl":[[2.34,4.17]],"id":47208569}],"con":true,"img":false}]}
{"op":"mcm","clk":"11450139473","pt":1717318455278,"mc":[{"id":"1.229554904","rc":[{"atl":[[2.32,20],[2.38,0]],"id":47208569}],"con":true,"img":false}]}
{"op":"mcm","clk":"11450139487","pt":1717318455383,"mc":[{"id":"1.229554904","rc":[{"atl":[[2.36,0]],"id":47208569}],"con":true,"img":false}]}
{"op":"mcm","clk":"11450141582","pt":1717318479437,"mc":[{"id":"1.229554904","rc":[{"atb":[[1.46,0]],"id":47208569}],"con":true,"img":false}]}
{"op":"mcm","clk":"11450141625","pt":1717318479854,"mc":[{"id":"1.229554904","rc":[{"atb":[[1.28,0],[1.33,47.78]],"id":47208569}],"con":true,"img":false}]}
{"op":"mcm","clk":"11450141803","pt":1717318481812,"mc":[{"id":"1.229554904","rc":[{"atl":[[2.72,0],[2.76,4.35],[2.7,0]],"id":70003368}],"con":true,"img":false}]}
{"op":"mcm","clk":"11450141886","pt":1717318482742,"mc":[{"id":"1.229554904","rc":[{"atl":[[2.3,4.12]],"id":47208569}],"con":true,"img":false}]}
{"op":"mcm","clk":"11450141897","pt":1717318482843,"mc":[{"id":"1.229554904","rc":[{"atl":[[2.32,10],[2.28,4.17]],"id":47208569}],"con":true,"img":false}]}
{"op":"mcm","clk":"11450141910","pt":1717318482945,"mc":[{"id":"1.229554904","rc":[{"atl":[[2.32,0],[2.28,14.17]],"id":47208569}],"con":true,"img":false}]}
{"op":"mcm","clk":"11450142056","pt":1717318484757,"mc":[{"id":"1.229554904","rc":[{"atb":[[1.77,2],[1.87,18]],"id":70003368},{"atb":[[1.79,4.79],[1.89,0]],"id":47208569}],"con":true,"img":false}]}
{"op":"mcm","clk":"11450143581","pt":1717318502065,"mc":[{"id":"1.229554904","rc":[{"atb":[[1.85,15],[1.82,27]],"id":70003368},{"atl":[[2.4,14.85],[2.42,0]],"id":47208569}],"con":true,"img":false}]}
{"op":"mcm","clk":"11450143596","pt":1717318502272,"mc":[{"id":"1.229554904","rc":[{"atl":[[2.4,4.14],[2.42,10.56]],"id":47208569}],"con":true,"img":false}]}
{"op":"mcm","clk":"11450143609","pt":1717318502379,"mc":[{"id":"1.229554904","rc":[{"atl":[[2.4,14.85]],"id":47208569}],"con":true,"img":false}]}
{"op":"mcm","clk":"11450143623","pt":1717318502436,"mc":[{"id":"1.229554904","rc":[{"atl":[[2.42,0],[2.46,0],[2.44,0]],"id":47208569}],"con":true,"img":false}]}
{"op":"mcm","clk":"11450143673","pt":1717318503055,"mc":[{"id":"1.229554904","rc":[{"atl":[[2.4,4.14],[2.42,10.56]],"id":47208569}],"con":true,"img":false}]}
{"op":"mcm","clk":"11450143732","pt":1717318503635,"mc":[{"id":"1.229554904","rc":[{"atl":[[2.4,14.85]],"id":47208569}],"con":true,"img":false}]}
{"op":"mcm","clk":"11450143754","pt":1717318503841,"mc":[{"id":"1.229554904","rc":[{"atl":[[2.4,4.14],[2.46,10.27]],"id":47208569}],"con":true,"img":false}]}
{"op":"mcm","clk":"11450143795","pt":1717318504358,"mc":[{"id":"1.229554904","rc":[{"atl":[[2.42,0]],"id":47208569}],"con":true,"img":false}]}
{"op":"mcm","clk":"11450143823","pt":1717318504671,"mc":[{"id":"1.229554904","rc":[{"atl":[[2.44,10.42]],"id":47208569}],"con":true,"img":false}]}
{"op":"mcm","clk":"11450143832","pt":1717318504770,"mc":[{"id":"1.229554904","rc":[{"atl":[[2.42,10.56],[2.46,0],[2.48,10.14]],"id":47208569}],"con":true,"img":false}]}
{"op":"mcm","clk":"11450143842","pt":1717318504877,"mc":[{"id":"1.229554904","rc":[{"atl":[[2.44,0]],"id":47208569}],"con":true,"img":false}]}
{"op":"mcm","clk":"11450143967","pt":1717318506336,"mc":[{"id":"1.229554904","rc":[{"atl":[[2.42,0],[2.46,10.27]],"id":47208569}],"con":true,"img":false}]}
{"op":"mcm","clk":"11450143985","pt":1717318506642,"mc":[{"id":"1.229554904","rc":[{"atl":[[2.44,10.42]],"id":47208569}],"con":true,"img":false}]}
{"op":"mcm","clk":"11450144001","pt":1717318506857,"mc":[{"id":"1.229554904","rc":[{"atb":[[1.78,20.06],[1.88,10.92]],"id":70003368},{"atb":[[1.88,8.92],[1.78,10.06]],"id":47208569}],"con":true,"img":false}]}
{"op":"mcm","clk":"11450144961","pt":1717318517574,"mc":[{"id":"1.229554904","rc":[{"atl":[[2.4,14.85]],"id":47208569}],"con":true,"img":false}]}
{"op":"mcm","clk":"11450144976","pt":1717318517683,"mc":[{"id":"1.229554904","rc":[{"atl":[[2.44,0]],"id":47208569}],"con":true,"img":false}]}
{"op":"mcm","clk":"11450144982","pt":1717318517785,"mc":[{"id":"1.229554904","rc":[{"atl":[[2.5,0]],"id":47208569}],"con":true,"img":false}]}
{"op":"mcm","clk":"11450144994","pt":1717318517891,"mc":[{"id":"1.229554904","rc":[{"atl":[[2.4,4.14],[2.46,0],[2.48,0]],"id":47208569}],"con":true,"img":false}]}
{"op":"mcm","clk":"11450145006","pt":1717318518049,"mc":[{"id":"1.229554904","rc":[{"atl":[[2.56,19.23],[2.52,16.45],[2.44,10.42],[2.26,4.17],[2.48,13.51]],"id":47208569}],"con":true,"img":false}]}
{"op":"mcm","clk":"11450145017","pt":1717318518156,"mc":[{"id":"1.229554904","rc":[{"atl":[[2.24,14.17],[2.28,0]],"id":47208569}],"con":true,"img":false}]}
{"op":"mcm","clk":"11450145175","pt":1717318520066,"mc":[{"id":"1.229554904","rc":[{"atl":[[2.42,10.56],[2.44,0],[2.48,0]],"id":47208569}],"con":true,"img":false}]}
{"op":"mcm","clk":"11450145187","pt":1717318520270,"mc":[{"id":"1.229554904","rc":[{"atl":[[2.42,0]],"id":47208569}],"con":true,"img":false}]}
{"op":"mcm","clk":"11450145419","pt":1717318522979,"mc":[{"id":"1.229554904","rc":[{"atl":[[2.4,14.85]],"id":47208569}],"con":true,"img":false}]}
{"op":"mcm","clk":"11450145587","pt":1717318524893,"mc":[{"id":"1.229554904","rc":[{"atl":[[2.4,4.14]],"id":47208569}],"con":true,"img":false}]}
{"op":"mcm","clk":"11450145636","pt":1717318525468,"mc":[{"id":"1.229554904","rc":[{"atl":[[2.44,10.42]],"id":47208569}],"con":true,"img":false}]}
{"op":"mcm","clk":"11450145809","pt":1717318527889,"mc":[{"id":"1.229554904","rc":[{"atl":[[2.44,0]],"id":47208569}],"con":true,"img":false}]}
{"op":"mcm","clk":"11450145817","pt":1717318527994,"mc":[{"id":"1.229554904","rc":[{"atl":[[2.4,14.85]],"id":47208569}],"con":true,"img":false}]}
{"op":"mcm","clk":"11450145835","pt":1717318528200,"mc":[{"id":"1.229554904","rc":[{"atl":[[2.4,4.14],[2.44,10.42]],"id":47208569}],"con":true,"img":false}]}
{"op":"mcm","clk":"11450146194","pt":1717318532668,"mc":[{"id":"1.229554904","rc":[{"atl":[[2.48,13.51]],"id":47208569}],"con":true,"img":false}]}
{"op":"mcm","clk":"11450146204","pt":1717318532772,"mc":[{"id":"1.229554904","rc":[{"atb":[[1.44,0]],"id":47208569}],"con":true,"img":false}]}
{"op":"mcm","clk":"11450146219","pt":1717318532981,"mc":[{"id":"1.229554904","rc":[{"atl":[[2.4,0],[2.22,4.19]],"id":47208569}],"con":true,"img":false}]}
{"op":"mcm","clk":"11450146237","pt":1717318533185,"mc":[{"id":"1.229554904","rc":[{"atl":[[2.24,0],[2.2,8.67]],"id":47208569}],"con":true,"img":false}]}
{"op":"mcm","clk":"11450146254","pt":1717318533392,"mc":[{"id":"1.229554904","rc":[{"atl":[[2.18,4.19],[2.34,0]],"id":47208569}],"con":true,"img":false}]}
{"op":"mcm","clk":"11450146261","pt":1717318533495,"mc":[{"id":"1.229554904","rc":[{"atl":[[2.8,0]],"id":70003368}],"con":true,"img":false}]}
{"op":"mcm","clk":"11450146682","pt":1717318538298,"mc":[{"id":"1.229554904","rc":[{"atl":[[2.2,0],[2.16,14.19]],"id":47208569}],"con":true,"img":false}]}
{"op":"mcm","clk":"11450146702","pt":1717318538503,"mc":[{"id":"1.229554904","rc":[{"atl":[[2.3,0],[2.14,4.25]],"id":47208569}],"con":true,"img":false}]}
{"op":"mcm","clk":"11450146710","pt":1717318538606,"mc":[{"id":"1.229554904","rc":[{"atl":[[2.12,14.26],[2.16,0]],"id":47208569}],"con":true,"img":false}]}
{"op":"mcm","clk":"11450146740","pt":1717318538972,"mc":[{"id":"1.229554904","rc":[{"atl":[[2.26,0],[2.1,4.26]],"id":47208569}],"con":true,"img":false}]}
{"op":"mcm","clk":"11450146777","pt":1717318539483,"mc":[{"id":"1.229554904","rc":[{"atb":[[1.92,6.51]],"id":70003368}],"con":true,"img":false}]}
{"op":"mcm","clk":"11450146854","pt":1717318540420,"mc":[{"id":"1.229554904","rc":[{"atb":[[1.85,2],[1.79,23.58]],"id":70003368},{"atl":[[2.74,14.37],[2.66,9.04],[2.78,16.85],[2.7,11.76]],"id":70003368},{"atl":[[2.12,10]],"id":47208569}],"con":true,"img":false}]}
{"op":"mcm","clk":"11450146865","pt":1717318540475,"mc":[{"id":"1.229554904","rc":[{"atl":[[2.3,13.51]],"id":47208569}],"con":true,"img":false}]}
{"op":"mcm","clk":"11450146899","pt":1717318540988,"mc":[{"id":"1.229554904","rc":[{"atb":[[1.93,16.46]],"id":70003368}],"con":true,"img":false}]}
{"op":"mcm","clk":"11450146928","pt":1717318541299,"mc":[{"id":"1.229554904","rc":[{"atb":[[1.78,10],[1.88,2]],"id":70003368},{"atb":[[1.88,0],[1.78,0]],"id":47208569}],"con":true,"img":false}]}
{"op":"mcm","clk":"11450146947","pt":1717318541510,"mc":[{"id":"1.229554904","rc":[{"atb":[[1.94,12.45]],"id":70003368}],"con":true,"img":false}]}
{"op":"mcm","clk":"11450146956","pt":1717318541613,"mc":[{"id":"1.229554904","rc":[{"atb":[[1.93,6.46],[1.95,2.02]],"id":70003368}],"con":true,"img":false}]}
{"op":"mcm","clk":"11450147165","pt":1717318543606,"mc":[{"id":"1.229554904","rc":[{"atl":[[2.66,0],[2.68,8.93]],"id":70003368}],"con":true,"img":false}]}
{"op":"mcm","clk":"11450147177","pt":1717318543711,"mc":[{"id":"1.229554904","rc":[{"atl":[[2.12,0],[2.08,4.26]],"id":47208569}],"con":true,"img":false}]}
{"op":"mcm","clk":"11450147604","pt":1717318548686,"mc":[{"id":"1.229554904","rc":[{"atl":[[2.68,0],[2.7,8.82]],"id":70003368}],"con":true,"img":false}]}
{"op":"mcm","clk":"11450147702","pt":1717318549822,"mc":[{"id":"1.229554904","rc":[{"atb":[[1.89,8.81],[1.79,33.51]],"id":70003368},{"atb":[[1.77,10.19],[1.87,9.01]],"id":47208569}],"con":true,"img":false}]}
{"op":"mcm","clk":"11450147857","pt":1717318551490,"mc":[{"id":"1.229554904","rc":[{"atb":[[1.42,0]],"id":47208569}],"con":true,"img":false}]}
{"op":"mcm","clk":"11450147894","pt":1717318551901,"mc":[{"id":"1.229554904","rc":[{"atl":[[2.44,0],[2.48,0]],"id":47208569}],"con":true,"img":false}]}
{"op":"mcm","clk":"11450147902","pt":1717318552004,"mc":[{"id":"1.229554904","rc":[{"atl":[[2.06,4.36],[2.22,0]],"id":47208569}],"con":true,"img":false}]}
{"op":"mcm","clk":"11450147909","pt":1717318552107,"mc":[{"id":"1.229554904","rc":[{"atb":[[1.87,13.67]],"id":47208569},{"atl":[[2.04,4.56],[2.08,0]],"id":47208569}],"con":true,"img":false}]}
{"op":"mcm","clk":"11450147981","pt":1717318552939,"mc":[{"id":"1.229554904","rc":[{"atl":[[2.74,11.49]],"id":70003368}],"con":true,"img":false}]}
{"op":"mcm","clk":"11450148348","pt":1717318557025,"mc":[{"id":"1.229554904","rc":[{"atl":[[2.78,14.04]],"id":70003368}],"con":true,"img":false}]}
{"op":"mcm","clk":"11450148414","pt":1717318557907,"mc":[{"id":"1.229554904","rc":[{"atb":[[1.95,6.43]],"id":70003368}],"con":true,"img":false}]}
{"op":"mcm","clk":"11450148426","pt":1717318558014,"mc":[{"id":"1.229554904","rc":[{"atb":[[1.79,28.85]],"id":70003368}],"con":true,"img":false}]}
{"op":"mcm","clk":"11450148676","pt":1717318561022,"mc":[{"id":"1.229554904","rc":[{"atl":[[2.82,16.48]],"id":70003368}],"con":true,"img":false}]}
{"op":"mcm","clk":"11450148730","pt":1717318561600,"mc":[{"id":"1.229554904","rc":[{"atb":[[1.96,9.38]],"id":70003368}],"con":true,"img":false}]}
{"op":"mcm","clk":"11450148741","pt":1717318561710,"mc":[{"id":"1.229554904","rc":[{"atb":[[1.95,4.41],[1.92,2],[1.97,4.21]],"id":70003368},{"atb":[[1.38,28.19]],"id":47208569},{"atl":[[2.04,8.96],[2.18,0]],"id":47208569}],"con":true,"img":false}]}
{"op":"mcm","clk":"11450148754","pt":1717318561858,"mc":[{"id":"1.229554904","rc":[{"atb":[[1.33,0]],"id":47208569}],"con":true,"img":false}]}
{"op":"mcm","clk":"11450148991","pt":1717318564406,"mc":[{"id":"1.229554904","rc":[{"atb":[[1.72,22],[1.79,9.93]],"id":70003368},{"atl":[[2.58,9.49],[2.7,0]],"id":70003368}],"con":true,"img":false}]}
{"op":"mcm","clk":"11450149045","pt":1717318564923,"mc":[{"id":"1.229554904","rc":[{"atb":[[1.93,2],[1.98,4.34]],"id":70003368},{"atb":[[1.87,9.01]],"id":47208569}],"con":true,"img":false}]}
{"op":"mcm","clk":"11450149056","pt":1717318565056,"mc":[{"id":"1.229554904","rc":[{"atb":[[1.99,2.02],[1.97,0]],"id":70003368}],"con":true,"img":false}]}
{"op":"mcm","clk":"11450149109","pt":1717318565542,"mc":[{"id":"1.229554904","rc":[{"atl":[[2.02,4.46],[2.14,0]],"id":47208569}],"con":true,"img":false}]}
{"op":"mcm","clk":"11450149125","pt":1717318565707,"mc":[{"id":"1.229554904","rc":[{"atl":[[2,4.62],[2.04,4.4]],"id":47208569}],"con":true,"img":false}]}
{"op":"mcm","clk":"11450149200","pt":1717318566524,"mc":[{"id":"1.229554904","rc":[{"atb":[[1.99,6.28],[1.94,8]],"id":70003368},{"atl":[[2,9.14]],"id":47208569}],"con":true,"img":false}]}
{"op":"mcm","clk":"11450149205","pt":1717318566625,"mc":[{"id":"1.229554904","rc":[{"atl":[[2.1,0]],"id":47208569}],"con":true,"img":false}]}
{"op":"mcm","clk":"11450149250","pt":1717318567139,"mc":[{"id":"1.229554904","rc":[{"atl":[[2.06,0]],"id":47208569}],"con":true,"img":false}]}
{"op":"mcm","clk":"11450149261","pt":1717318567241,"mc":[{"id":"1.229554904","rc":[{"atl":[[1.99,4.55]],"id":47208569}],"con":true,"img":false}]}
{"op":"mcm","clk":"11450149269","pt":1717318567343,"mc":[{"id":"1.229554904","rc":[{"atl":[[2.6,9.38],[2.58,0]],"id":70003368}],"con":true,"img":false}]}
{"op":"mcm","clk":"11450149470","pt":1717318569410,"mc":[{"id":"1.229554904","rc":[{"atl":[[2,4.52],[1.98,4.66]],"id":47208569}],"con":true,"img":false}]}
{"op":"mcm","clk":"11450149548","pt":1717318570236,"mc":[{"id":"1.229554904","rc":[{"atl":[[2.6,0],[2.62,9.26]],"id":70003368}],"con":true,"img":false}]}
{"op":"mcm","clk":"11450149574","pt":1717318570441,"mc":[{"id":"1.229554904","rc":[{"atl":[[1.97,4.63]],"id":47208569}],"con":true,"img":false}]}
{"op":"mcm","clk":"11450149581","pt":1717318570550,"mc":[{"id":"1.229554904","rc":[{"atl":[[2.04,0]],"id":47208569}],"con":true,"img":false}]}
{"op":"mcm","clk":"11450149625","pt":1717318571017,"mc":[{"id":"1.229554904","rc":[{"atl":[[2.62,0],[2.74,0],[2.78,0]],"id":70003368}],"con":true,"img":false}]}
{"op":"mcm","clk":"11450149958","pt":1717318574574,"mc":[{"id":"1.229554904","rc":[{"atl":[[1.99,9.25],[1.98,0]],"id":47208569}],"con":true,"img":false}]}
{"op":"mcm","clk":"11450150011","pt":1717318575037,"mc":[{"id":"1.229554904","rc":[{"atl":[[2.72,8.72]],"id":70003368}],"con":true,"img":false}]}
{"op":"mcm","clk":"11450150037","pt":1717318575350,"mc":[{"id":"1.229554904","rc":[{"atl":[[2.72,0]],"id":70003368}],"con":true,"img":false}]}
{"op":"mcm","clk":"11450150218","pt":1717318577378,"mc":[{"id":"1.229554904","rc":[{"atb":[[1.89,0],[1.79,0]],"id":70003368},{"atb":[[1.77,0],[1.87,0]],"id":47208569}],"con":true,"img":false}]}
{"op":"mcm","clk":"11450150234","pt":1717318577536,"mc":[{"id":"1.229554904","rc":[{"atl":[[2.72,8.72]],"id":70003368}],"con":true,"img":false}]}
{"op":"mcm","clk":"11450150470","pt":1717318580297,"mc":[{"id":"1.229554904","rc":[{"atl":[[2.72,12.87],[2.76,0]],"id":70003368}],"con":true,"img":false}]}
{"op":"mcm","clk":"11450150523","pt":1717318580819,"mc":[{"id":"1.229554904","rc":[{"atl":[[2.72,4.15]],"id":70003368}],"con":true,"img":false}]}
{"op":"mcm","clk":"11450150779","pt":1717318583422,"mc":[{"id":"1.229554904","rc":[{"atb":[[1.02,80.95]],"id":70003368},{"atl":[[970,2.11]],"id":70003368},{"atb":[[1.01,103.11]],"id":47208569},{"atl":[[960,0.85]],"id":47208569}],"con":true,"img":false}]}
{"op":"mcm","clk":"11450150791","pt":1717318583521,"mc":[{"id":"1.229554904","rc":[{"atl":[[2.72,12.87]],"id":70003368}],"con":true,"img":false}]}
{"op":"mcm","clk":"11450150956","pt":1717318585225,"mc":[{"id":"1.229554904","rc":[{"atl":[[2.72,4.15]],"id":70003368}],"con":true,"img":false}]}
{"op":"mcm","clk":"11450150989","pt":1717318585534,"mc":[{"id":"1.229554904","rc":[{"atl":[[2.72,12.87]],"id":70003368}],"con":true,"img":false}]}
{"op":"mcm","clk":"11450151327","pt":1717318588997,"mc":[{"id":"1.229554904","rc":[{"atl":[[2.62,9.26]],"id":70003368}],"con":true,"img":false}]}
{"op":"mcm","clk":"11450151423","pt":1717318589831,"mc":[{"id":"1.229554904","rc":[{"atl":[[2,9.11],[1.99,4.55]],"id":47208569}],"con":true,"img":false}]}
{"op":"mcm","clk":"11450151501","pt":1717318590497,"mc":[{"id":"1.229554904","rc":[{"atl":[[2.6,9.38]],"id":70003368}],"con":true,"img":false}]}
{"op":"mcm","clk":"11450151650","pt":1717318592006,"mc":[{"id":"1.229554904","rc":[{"atb":[[1.99,36.41]],"id":70003368}],"con":true,"img":false}]}
{"op":"mcm","clk":"11450151751","pt":1717318593147,"mc":[{"id":"1.229554904","rc":[{"atb":[[1.92,10.52],[1.82,36.56]],"id":70003368},{"atb":[[1.73,10.75],[1.83,9.45]],"id":47208569}],"con":true,"img":false}]}
{"op":"mcm","clk":"11450151775","pt":1717318593314,"mc":[{"id":"1.229554904","rc":[{"atl":[[2.6,0]],"id":70003368}],"con":true,"img":false}]}
{"op":"mcm","clk":"11450151802","pt":1717318593519,"mc":[{"id":"1.229554904","rc":[{"atl":[[2.72,4.15],[2.62,0]],"id":70003368}],"con":true,"img":false}]}
{"op":"mcm","clk":"11450151840","pt":1717318593835,"mc":[{"id":"1.229554904","rc":[{"atl":[[2.72,12.87]],"id":70003368}],"con":true,"img":false}]}
{"op":"mcm","clk":"11450151859","pt":1717318594050,"mc":[{"id":"1.229554904","rc":[{"atl":[[2.72,4.15]],"id":70003368}],"con":true,"img":false}]}
{"op":"mcm","clk":"11450151886","pt":1717318594344,"mc":[{"id":"1.229554904","rc":[{"atl":[[2.72,12.87]],"id":70003368}],"con":true,"img":false}]}
{"op":"mcm","clk":"11450151956","pt":1717318594919,"mc":[{"id":"1.229554904","rc":[{"atl":[[2.72,4.15],[2.7,8.82]],"id":70003368}],"con":true,"img":false}]}
{"op":"mcm","clk":"11450151989","pt":1717318595219,"mc":[{"id":"1.229554904","rc":[{"atb":[[2,4.1],[1.95,0]],"id":70003368},{"atl":[[2.7,0]],"id":70003368}],"con":true,"img":false}]}
{"op":"mcm","clk":"11450152034","pt":1717318595639,"mc":[{"id":"1.229554904","rc":[{"atl":[[2.72,12.87],[2.7,8.82]],"id":70003368}],"con":true,"img":false}]}
{"op":"mcm","clk":"11450152044","pt":1717318595741,"mc":[{"id":"1.229554904","rc":[{"atb":[[2,8.18],[1.99,34.39]],"id":70003368},{"atl":[[2.94,21.69],[3.2,2]],"id":70003368},{"atl":[[2,4.52],[1.99,9.25]],"id":47208569}],"con":true,"img":false}]}
{"op":"mcm","clk":"11450152053","pt":1717318595839,"mc":[{"id":"1.229554904","rc":[{"atl":[[2.94,0]],"id":70003368}],"con":true,"img":false}]}
{"op":"mcm","clk":"11450152062","pt":1717318595943,"mc":[{"id":"1.229554904","rc":[{"atl":[[3.15,19.64]],"id":70003368}],"con":true,"img":false}]}
{"op":"mcm","clk":"11450152070","pt":1717318596001,"mc":[{"id":"1.229554904","rc":[{"atl":[[2.7,0]],"id":70003368}],"con":true,"img":false}]}
{"op":"mcm","clk":"11450152176","pt":1717318597030,"mc":[{"id":"1.229554904","rc":[{"atl":[[2.72,4.15]],"id":70003368}],"con":true,"img":false}]}
{"op":"mcm","clk":"11450152280","pt":1717318598125,"mc":[{"id":"1.229554904","rc":[{"atl":[[2.72,12.87],[2.7,8.82]],"id":70003368}],"con":true,"img":false}]}
{"op":"mcm","clk":"11450152331","pt":1717318598646,"mc":[{"id":"1.229554904","rc":[{"atl":[[2.7,0]],"id":70003368}],"con":true,"img":false}]}
{"op":"mcm","clk":"11450152340","pt":1717318598752,"mc":[{"id":"1.229554904","rc":[{"atl":[[2.72,4.15]],"id":70003368}],"con":true,"img":false}]}
{"op":"mcm","clk":"11450152394","pt":1717318599319,"mc":[{"id":"1.229554904","rc":[{"atl":[[2.6,9.38]],"id":70003368}],"con":true,"img":false}]}
{"op":"mcm","clk":"11450152455","pt":1717318600047,"mc":[{"id":"1.229554904","rc":[{"atl":[[2.6,0]],"id":70003368}],"con":true,"img":false}]}
{"op":"mcm","clk":"11450152476","pt":1717318600252,"mc":[{"id":"1.229554904","rc":[{"atb":[[2.02,4.1]],"id":70003368}],"con":true,"img":false}]}
{"op":"mcm","clk":"11450152489","pt":1717318600352,"mc":[{"id":"1.229554904","rc":[{"atb":[[1.96,5]],"id":70003368}],"con":true,"img":false}]}
{"op":"mcm","clk":"11450152498","pt":1717318600453,"mc":[{"id":"1.229554904","rc":[{"atl":[[2.8,4.07],[2.72,0],[2.6,9.38]],"id":70003368}],"con":true,"img":false}]}
{"op":"mcm","clk":"11450152546","pt":1717318600820,"mc":[{"id":"1.229554904","rc":[{"atb":[[2,4.1],[2.02,8.17]],"id":70003368},{"atl":[[1.99,4.55],[1.98,4.7]],"id":47208569}],"con":true,"img":false}]}
{"op":"mcm","clk":"11450152597","pt":1717318601236,"mc":[{"id":"1.229554904","rc":[{"atl":[[2.6,0]],"id":70003368}],"con":true,"img":false}]}
{"op":"mcm","clk":"11450152606","pt":1717318601335,"mc":[{"id":"1.229554904","rc":[{"atb":[[2.02,37.4]],"id":70003368}],"con":true,"img":false}]}
{"op":"mcm","clk":"11450152674","pt":1717318601963,"mc":[{"id":"1.229554904","rc":[{"atb":[[1.99,4.26],[2.02,8.17]],"id":70003368}],"con":true,"img":false}]}
{"op":"mcm","clk":"11450152711","pt":1717318602228,"mc":[{"id":"1.229554904","rc":[{"atl":[[2.6,9.38]],"id":70003368}],"con":true,"img":false}]}
{"op":"mcm","clk":"11450152726","pt":1717318602330,"mc":[{"id":"1.229554904","rc":[{"atb":[[1.97,30.74]],"id":70003368}],"con":true,"img":false}]}
{"op":"mcm","clk":"11450152987","pt":1717318605223,"mc":[{"id":"1.229554904","rc":[{"atb":[[1.87,27.34],[1.72,2]],"id":70003368},{"atl":[[2.82,0],[2.6,0]],"id":70003368},{"atl":[[2.3,0],[2.18,16.45]],"id":47208569}],"con":true,"img":false}]}
{"op":"mcm","clk":"11450153051","pt":1717318605952,"mc":[{"id":"1.229554904","rc":[{"atl":[[1.98,0],[1.96,4.7]],"id":47208569}],"con":true,"img":false}]}
{"op":"mcm","clk":"11450153921","pt":1717318615953,"mc":[{"id":"1.229554904","rc":[{"atl":[[2.04,16.45],[2.18,0]],"id":47208569}],"con":true,"img":false}]}
{"op":"mcm","clk":"11450153951","pt":1717318616368,"mc":[{"id":"1.229554904","rc":[{"atb":[[1.98,0],[2.04,4.09]],"id":70003368},{"atl":[[2.02,0],[1.95,4.72]],"id":47208569}],"con":true,"img":false}]}
{"op":"mcm","clk":"11450153960","pt":1717318616469,"mc":[{"id":"1.229554904","rc":[{"atb":[[2.02,4.1],[2.06,10]],"id":70003368},{"atl":[[1.96,0],[1.94,10]],"id":47208569}],"con":true,"img":false}]}
{"op":"mcm","clk":"11450153994","pt":1717318616833,"mc":[{"id":"1.229554904","rc":[{"atb":[[2,33.93]],"id":70003368}],"con":true,"img":false}]}
{"op":"mcm","clk":"11450155432","pt":1717318631401,"mc":[{"id":"1.229554904","rc":[{"atb":[[1.92,2],[1.82,27]],"id":70003368},{"atb":[[1.73,0],[1.83,0]],"id":47208569}],"con":true,"img":false}]}
{"op":"mcm","clk":"11450157193","pt":1717318646989,"mc":[{"id":"1.229554904","rc":[{"atl":[[2.8,0],[3,0],[3.5,9.07],[3.15,2],[2.96,2.02]],"id":70003368},{"atb":[[1.5,0],[1.38,0]],"id":47208569},{"atl":[[2.04,0],[1.94,14.73]],"id":47208569}],"con":true,"img":false}]}
{"op":"mcm","clk":"11450157202","pt":1717318647091,"mc":[{"id":"1.229554904","rc":[{"atb":[[1.48,4.68],[1.34,55.86]],"id":47208569}],"con":true,"img":false}]}
{"op":"mcm","clk":"11450157378","pt":1717318648798,"mc":[{"id":"1.229554904","rc":[{"atb":[[1.91,21.27],[1.87,18]],"id":70003368}],"con":true,"img":false}]}
{"op":"mcm","clk":"11450157404","pt":1717318649005,"mc":[{"id":"1.229554904","rc":[{"atb":[[1.92,10.52],[1.82,36.56]],"id":70003368},{"atb":[[1.81,9.68],[1.71,11.05]],"id":47208569}],"con":true,"img":false}]}
{"op":"mcm","clk":"11450159138","pt":1717318666130,"mc":[{"id":"1.229554904","rc":[{"atl":[[1.95,0]],"id":47208569}],"con":true,"img":false}]}
{"op":"mcm","clk":"11450159148","pt":1717318666233,"mc":[{"id":"1.229554904","rc":[{"atl":[[1.96,34.16],[1.94,0]],"id":47208569}],"con":true,"img":false}]}
{"op":"mcm","clk":"11450159158","pt":1717318666336,"mc":[{"id":"1.229554904","rc":[{"atb":[[2.04,0]],"id":70003368}],"con":true,"img":false}]}
{"op":"mcm","clk":"11450159167","pt":1717318666391,"mc":[{"id":"1.229554904","rc":[{"atb":[[2.04,2.02],[2.06,0]],"id":70003368}],"con":true,"img":false}]}
{"op":"mcm","clk":"11450159220","pt":1717318667015,"mc":[{"id":"1.229554904","rc":[{"atb":[[2,4.1],[1.46,0],[1.44,0]],"id":70003368},{"atb":[[1.82,4.67]],"id":47208569}],"con":true,"img":false}]}
{"op":"mcm","clk":"11450159239","pt":1717318667218,"mc":[{"id":"1.229554904","rc":[{"atl":[[2.84,2.02],[2.96,0]],"id":70003368}],"con":true,"img":false}]}
{"op":"mcm","clk":"11450159258","pt":1717318667432,"mc":[{"id":"1.229554904","rc":[{"atb":[[1.99,34.39]],"id":70003368},{"atb":[[1.65,45.88]],"id":47208569}],"con":true,"img":false}]}
{"op":"mcm","clk":"11450159726","pt":1717318672228,"mc":[{"id":"1.229554904","rc":[{"atl":[[2.84,0],[3.25,16.04],[3.5,0],[2.76,10]],"id":70003368},{"atb":[[1.42,55.86],[1.34,0]],"id":47208569},{"atl":[[1.96,4.7],[2.18,16.45]],"id":47208569}],"con":true,"img":false}]}
{"op":"mcm","clk":"11450159749","pt":1717318672437,"mc":[{"id":"1.229554904","rc":[{"atb":[[1.65,0]],"id":47208569}],"con":true,"img":false}]}
{"op":"mcm","clk":"11450160429","pt":1717318679522,"mc":[{"id":"1.229554904","rc":[{"atl":[[1.97,0]],"id":47208569}],"con":true,"img":false}]}
{"op":"mcm","clk":"11450160434","pt":1717318679621,"mc":[{"id":"1.229554904","rc":[{"atl":[[1.98,10],[1.96,0]],"id":47208569}],"con":true,"img":false}]}
{"op":"mcm","clk":"11450160489","pt":1717318680254,"mc":[{"id":"1.229554904","rc":[{"atb":[[1.04,1.25]],"id":70003368}],"con":true,"img":false}]}
{"op":"mcm","clk":"11450160498","pt":1717318680356,"mc":[{"id":"1.229554904","rc":[{"atb":[[1.04,0.25]],"id":70003368}],"con":true,"img":false}]}
{"op":"mcm","clk":"11450160508","pt":1717318680457,"mc":[{"id":"1.229554904","rc":[{"atb":[[1.78,0],[1.68,0],[1.96,0],[1.93,0],[1.53,0],[1.71,0],[1.92,8.52],[1.74,0],[1.88,0],[1.91,9.27],[1.9,0],[1.77,0],[1.66,0],[1.64,0],[1.6,0],[1.84,0],[1.58,0],[1.85,0],[1.62,0],[1.94,0],[1.87,0],[1.76,0],[1.69,0],[1.82,9.56],[1.8,0],[1.72,0],[1.55,0],[1.75,0],[1.04,0]],"id":70003368},{"atl":[[3.6,0],[3.1,0],[3.8,0],[3.25,4.04],[3.55,0],[3.3,0],[4,0],[3.45,0],[4.5,0],[3.2,0],[3.7,0],[3.4,0],[3.15,0],[3.9,0],[4.2,0],[4.7,0]],"id":70003368}],"con":true,"img":false}]}
{"op":"mcm","clk":"11450160518","pt":1717318680560,"mc":[{"id":"1.229554904","rc":[{"trd":[[2.22,0.25]],"ltp":2.22,"tv":0.25,"id":70003368},{"atl":[[1000,2]],"id":70003368},{"atb":[[1.82,4.36]],"id":47208569},{"trd":[[1.82,0.3]],"ltp":1.82,"tv":0.3,"id":47208569}],"con":true,"img":false}]}
{"op":"mcm","clk":"11450160528","pt":1717318680621,"mc":[{"id":"1.229554904","rc":[{"atl":[[3.25,0]],"id":70003368}],"con":true,"img":false}]}
{"op":"mcm","clk":"11450160980","pt":1717318684814,"mc":[{"id":"1.229554904","rc":[{"atb":[[1.82,0],[1.92,0]],"id":70003368},{"atb":[[1.81,0],[1.71,0]],"id":47208569}],"con":true,"img":false}]}
{"op":"mcm","clk":"11450161040","pt":1717318685438,"mc":[{"id":"1.229554904","rc":[{"atb":[[1.99,4.26],[1.97,0]],"id":70003368}],"con":true,"img":false}]}
{"op":"mcm","clk":"11450161442","pt":1717318689547,"mc":[{"id":"1.229554904","rc":[{"atb":[[1.91,0],[1.87,71.43]],"id":70003368}],"con":true,"img":false}]}
{"op":"mcm","clk":"11450161459","pt":1717318689753,"mc":[{"id":"1.229554904","rc":[{"atl":[[2.8,13.89],[2.72,8.72],[2.84,16.3],[2.76,21.36]],"id":70003368},{"atl":[[2.18,0],[2.26,16.45]],"id":47208569}],"con":true,"img":false}]}
{"op":"mcm","clk":"11450161473","pt":1717318689862,"mc":[{"id":"1.229554904","rc":[{"atl":[[2.82,16.48],[1000,0],[2.74,11.49],[2.9,27.78],[2.78,14.04],[2.7,8.82]],"id":70003368}],"con":true,"img":false}]}
{"op":"mcm","clk":"11450161483","pt":1717318689911,"mc":[{"id":"1.229554904","rc":[{"atb":[[1.99,34.39]],"id":70003368},{"atl":[[1000,2],[2.9,0]],"id":70003368}],"con":true,"img":false}]}
{"op":"mcm","clk":"11450161501","pt":1717318690118,"mc":[{"id":"1.229554904","rc":[{"atl":[[2.8,0],[2.82,0],[2.72,0],[2.74,0],[2.84,0],[2.78,0],[2.7,0],[2.76,10]],"id":70003368}],"con":true,"img":false}]}
{"op":"mcm","clk":"11450161522","pt":1717318690325,"mc":[{"id":"1.229554904","rc":[{"atl":[[2.82,16.48],[2.74,11.49],[2.78,14.04],[2.7,8.82]],"id":70003368}],"con":true,"img":false}]}
{"op":"mcm","clk":"11450161536","pt":1717318690431,"mc":[{"id":"1.229554904","rc":[{"atb":[[1.99,4.26]],"id":70003368}],"con":true,"img":false}]}
{"op":"mcm","clk":"11450161591","pt":1717318690943,"mc":[{"id":"1.229554904","rc":[{"atb":[[1.99,34.39]],"id":70003368},{"atl":[[2.72,8.72]],"id":70003368}],"con":true,"img":false}]}
{"op":"mcm","clk":"11450161603","pt":1717318691059,"mc":[{"id":"1.229554904","rc":[{"atl":[[2.7,0]],"id":70003368}],"con":true,"img":false}]}
{"op":"mcm","clk":"11450161613","pt":1717318691180,"mc":[{"id":"1.229554904","rc":[{"atl":[[2.82,0],[2.74,0],[2.78,0]],"id":70003368}],"con":true,"img":false}]}
{"op":"mcm","clk":"11450161738","pt":1717318692746,"mc":[{"id":"1.229554904","rc":[{"atl":[[2.76,21.36]],"id":70003368}],"con":true,"img":false}]}
{"op":"mcm","clk":"11450161767","pt":1717318693056,"mc":[{"id":"1.229554904","rc":[{"atb":[[2.02,0]],"id":70003368}],"con":true,"img":false}]}
{"op":"mcm","clk":"11450161783","pt":1717318693210,"mc":[{"id":"1.229554904","rc":[{"atb":[[1.01,123.01],[2.02,10],[2.04,0],[1.87,0]],"id":70003368}],"con":true,"img":false}]}
{"op":"mcm","clk":"11450161816","pt":1717318693523,"mc":[{"id":"1.229554904","rc":[{"atb":[[1.99,4.26]],"id":70003368}],"con":true,"img":false}]}
{"op":"mcm","clk":"11450161934","pt":1717318694553,"mc":[{"id":"1.229554904","rc":[{"atl":[[2.8,13.89]],"id":70003368}],"con":true,"img":false}]}
{"op":"mcm","clk":"11450162117","pt":1717318696336,"mc":[{"id":"1.229554904","rc":[{"atb":[[1.83,9.45],[1.93,8.43]],"id":70003368},{"atl":[[2.84,16.3]],"id":70003368},{"atb":[[1.8,14.58],[1.7,11.21]],"id":47208569}],"con":true,"img":false}]}
{"op":"mcm","clk":"11450162138","pt":1717318696540,"mc":[{"id":"1.229554904","rc":[{"atb":[[1.83,80.88],[1.01,17.19]],"id":70003368}],"con":true,"img":false}]}
{"op":"mcm","clk":"11450162172","pt":1717318696958,"mc":[{"id":"1.229554904","rc":[{"atb":[[1.97,30.74]],"id":70003368}],"con":true,"img":false}]}
{"op":"mcm","clk":"11450162649","pt":1717318702865,"mc":[{"id":"1.229554904","rc":[{"atl":[[2.72,0]],"id":70003368}],"con":true,"img":false}]}
{"op":"mcm","clk":"11450163108","pt":1717318707865,"mc":[{"id":"1.229554904","rc":[{"atb":[[1.83,9.45],[1.86,80.88]],"id":70003368},{"atl":[[2.76,10]],"id":70003368}],"con":true,"img":false}]}
{"op":"mcm","clk":"11450163347","pt":1717318710385,"mc":[{"id":"1.229554904","rc":[{"atl":[[1000,1.07]],"id":47208569}],"con":true,"img":false}]}
{"op":"mcm","clk":"11450163384","pt":1717318710647,"mc":[{"id":"1.229554904","rc":[{"atb":[[2.04,4.18]],"id":70003368},{"atl":[[1.97,4.62]],"id":47208569}],"con":true,"img":false}]}
{"op":"mcm","clk":"11450163393","pt":1717318710747,"mc":[{"id":"1.229554904","rc":[{"atb":[[2.02,0],[2.06,10]],"id":70003368},{"atl":[[1.96,10],[1000,0.32]],"id":47208569}],"con":true,"img":false}]}
{"op":"mcm","clk":"11450163401","pt":1717318710850,"mc":[{"id":"1.229554904","rc":[{"atl":[[1.98,0]],"id":47208569}],"con":true,"img":false}]}
{"op":"mcm","clk":"11450163415","pt":1717318710958,"mc":[{"id":"1.229554904","rc":[{"atb":[[2,33.93]],"id":70003368},{"atb":[[1.65,45.88]],"id":47208569}],"con":true,"img":false}]}
{"op":"mcm","clk":"11450163433","pt":1717318711164,"mc":[{"id":"1.229554904","rc":[{"atl":[[1000,0.17]],"id":47208569}],"con":true,"img":false}]}
{"op":"mcm","clk":"11450163445","pt":1717318711264,"mc":[{"id":"1.229554904","rc":[{"atb":[[1.82,4.21]],"id":47208569},{"trd":[[1.82,0.6]],"ltp":1.82,"tv":0.6,"id":47208569}],"con":true,"img":false}]}
{"op":"mcm","clk":"11450163467","pt":1717318711471,"mc":[{"id":"1.229554904","rc":[{"atb":[[1.65,0]],"id":47208569},{"atl":[[1.96,14.63]],"id":47208569}],"con":true,"img":false}]}
{"op":"mcm","clk":"11450163516","pt":1717318711986,"mc":[{"id":"1.229554904","rc":[{"atb":[[1.65,45.88]],"id":47208569}],"con":true,"img":false}]}
{"op":"mcm","clk":"11450163552","pt":1717318712345,"mc":[{"id":"1.229554904","rc":[{"atl":[[2.84,26.3],[2.76,0]],"id":70003368},{"atl":[[2.26,0],[2.2,16.45]],"id":47208569}],"con":true,"img":false}]}
{"op":"mcm","clk":"11450163613","pt":1717318712963,"mc":[{"id":"1.229554904","rc":[{"atb":[[1.89,71.43],[1.86,0]],"id":70003368}],"con":true,"img":false}]}
{"op":"mcm","clk":"11450163723","pt":1717318714146,"mc":[{"id":"1.229554904","rc":[{"atl":[[2.8,0]],"id":70003368}],"con":true,"img":false}]}
{"op":"mcm","clk":"11450164641","pt":1717318723980,"mc":[{"id":"1.229554904","rc":[{"atb":[[1.83,0],[1.93,0]],"id":70003368},{"atb":[[1.8,4.77],[1.7,0]],"id":47208569}],"con":true,"img":false}]}
{"op":"mcm","clk":"11450164687","pt":1717318724496,"mc":[{"id":"1.229554904","rc":[{"atb":[[1.65,0]],"id":47208569}],"con":true,"img":false}]}
{"op":"mcm","clk":"11450164722","pt":1717318724808,"mc":[{"id":"1.229554904","rc":[{"atb":[[1.82,0.29]],"id":47208569},{"trd":[[1.82,8.45]],"ltp":1.82,"tv":8.45,"id":47208569}],"con":true,"img":false}]}
{"op":"mcm","clk":"11450164730","pt":1717318724933,"mc":[{"id":"1.229554904","rc":[{"atb":[[2.06,14.12]],"id":70003368},{"atl":[[2,0],[1.95,4.68]],"id":47208569}],"con":true,"img":false}]}
{"op":"mcm","clk":"11450164739","pt":1717318724965,"mc":[{"id":"1.229554904","rc":[{"atb":[[2.08,13.15]],"id":70003368},{"atl":[[1.94,4.67]],"id":47208569}],"con":true,"img":false}]}
{"op":"mcm","clk":"11450164746","pt":1717318725071,"mc":[{"id":"1.229554904","rc":[{"atb":[[2.06,4.12],[2.1,4.09]],"id":70003368},{"atl":[[1.96,4.63]],"id":47208569}],"con":true,"img":false}]}
{"op":"mcm","clk":"11450164771","pt":1717318725380,"mc":[{"id":"1.229554904","rc":[{"atb":[[2.02,29.23]],"id":70003368}],"con":true,"img":false}]}
{"op":"mcm","clk":"11450164939","pt":1717318727196,"mc":[{"id":"1.229554904","rc":[{"atb":[[2.06,0]],"id":70003368}],"con":true,"img":false}]}
{"op":"mcm","clk":"11450165030","pt":1717318728077,"mc":[{"id":"1.229554904","rc":[{"atb":[[1.82,71.43],[1.89,0]],"id":70003368},{"atl":[[2.72,8.72]],"id":70003368},{"atb":[[1.42,0],[1.47,55.86]],"id":47208569}],"con":true,"img":false}]}
{"op":"mcm","clk":"11450165049","pt":1717318728517,"mc":[{"id":"1.229554904","rc":[{"atb":[[2.12,12.91]],"id":70003368},{"atl":[[2.72,0]],"id":70003368},{"atb":[[1.8,17.38]],"id":47208569},{"atl":[[1.9,15.38]],"id":47208569}],"con":true,"img":false}]}
{"op":"mcm","clk":"11450165060","pt":1717318728529,"mc":[{"id":"1.229554904","rc":[{"atb":[[2.14,10]],"id":70003368},{"atl":[[1.99,0],[1.89,4.74]],"id":47208569}],"con":true,"img":false}]}
{"op":"mcm","clk":"11450165071","pt":1717318728539,"mc":[{"id":"1.229554904","rc":[{"atb":[[2.1,0]],"id":70003368},{"atl":[[1.94,4.7]],"id":47208569}],"con":true,"img":false}]}
{"op":"mcm","clk":"11450165114","pt":1717318729004,"mc":[{"id":"1.229554904","rc":[{"atb":[[1.97,0]],"id":70003368}],"con":true,"img":false}]}
{"op":"mcm","clk":"11450165154","pt":1717318729519,"mc":[{"id":"1.229554904","rc":[{"atl":[[1.94,0],[1.95,0]],"id":47208569}],"con":true,"img":false}]}
{"op":"mcm","clk":"11450165163","pt":1717318729573,"mc":[{"id":"1.229554904","rc":[{"atb":[[2.12,0]],"id":70003368}],"con":true,"img":false}]}
{"op":"mcm","clk":"11450165171","pt":1717318729677,"mc":[{"id":"1.229554904","rc":[{"atb":[[2.14,0],[2.1,10]],"id":70003368}],"con":true,"img":false}]}
{"op":"mcm","clk":"11450165187","pt":1717318729882,"mc":[{"id":"1.229554904","rc":[{"atb":[[2.04,32.86]],"id":70003368}],"con":true,"img":false}]}
{"op":"mcm","clk":"11450165334","pt":1717318731588,"mc":[{"id":"1.229554904","rc":[{"atb":[[2.06,12.79]],"id":70003368},{"atb":[[1.79,17.54]],"id":47208569}],"con":true,"img":false}]}
{"op":"mcm","clk":"11450165355","pt":1717318731894,"mc":[{"id":"1.229554904","rc":[{"atb":[[2,4.1]],"id":70003368},{"atb":[[1.65,45.88]],"id":47208569}],"con":true,"img":false}]}
{"op":"mcm","clk":"11450165475","pt":1717318733185,"mc":[{"id":"1.229554904","rc":[{"atb":[[1.82,0],[1.88,71.43]],"id":70003368}],"con":true,"img":false}]}
{"op":"mcm","clk":"11450165567","pt":1717318734218,"mc":[{"id":"1.229554904","rc":[{"atl":[[1.96,0]],"id":47208569}],"con":true,"img":false}]}
{"op":"mcm","clk":"11450165607","pt":1717318734584,"mc":[{"id":"1.229554904","rc":[{"atb":[[2.04,28.67]],"id":70003368}],"con":true,"img":false}]}
{"op":"mcm","clk":"11450165616","pt":1717318734687,"mc":[{"id":"1.229554904","rc":[{"atl":[[1.97,0]],"id":47208569}],"con":true,"img":false}]}
{"op":"mcm","clk":"11450165636","pt":1717318734890,"mc":[{"id":"1.229554904","rc":[{"atb":[[2.12,16.21]],"id":70003368}],"con":true,"img":false}]}
{"op":"mcm","clk":"11450165647","pt":1717318734993,"mc":[{"id":"1.229554904","rc":[{"atb":[[2.1,0],[2.14,10]],"id":70003368},{"atl":[[2.18,4.6]],"id":47208569}],"con":true,"img":false}]}
{"op":"mcm","clk":"11450165654","pt":1717318735097,"mc":[{"id":"1.229554904","rc":[{"atb":[[2.06,0]],"id":70003368}],"con":true,"img":false}]}
{"op":"mcm","clk":"11450165673","pt":1717318735304,"mc":[{"id":"1.229554904","rc":[{"atb":[[2.12,0]],"id":70003368}],"con":true,"img":false}]}
{"op":"mcm","clk":"11450165682","pt":1717318735410,"mc":[{"id":"1.229554904","rc":[{"atb":[[2.14,36.16]],"id":70003368}],"con":true,"img":false}]}
{"op":"mcm","clk":"11450165725","pt":1717318735921,"mc":[{"id":"1.229554904","rc":[{"atb":[[2.14,10]],"id":70003368}],"con":true,"img":false}]}
{"op":"mcm","clk":"11450165764","pt":1717318736385,"mc":[{"id":"1.229554904","rc":[{"atb":[[2.12,26.62]],"id":70003368}],"con":true,"img":false}]}
{"op":"mcm","clk":"11450165926","pt":1717318738396,"mc":[{"id":"1.229554904","rc":[{"atb":[[2,0],[1.99,0]],"id":70003368}],"con":true,"img":false}]}
{"op":"mcm","clk":"11450165935","pt":1717318738502,"mc":[{"id":"1.229554904","rc":[{"atb":[[2.08,0]],"id":70003368}],"con":true,"img":false}]}
{"op":"mcm","clk":"11450166080","pt":1717318740408,"mc":[{"id":"1.229554904","rc":[{"atb":[[1.8,4.77],[1.79,4.79]],"id":47208569},{"atl":[[1.87,18.98]],"id":47208569}],"con":true,"img":false}]}
{"op":"mcm","clk":"11450166097","pt":1717318740615,"mc":[{"id":"1.229554904","rc":[{"atl":[[2.86,30.34],[1000,0]],"id":70003368}],"con":true,"img":false}]}
{"op":"mcm","clk":"11450166123","pt":1717318740928,"mc":[{"id":"1.229554904","rc":[{"atb":[[2.06,28.13],[2.12,0]],"id":70003368},{"atb":[[1.65,0]],"id":47208569}],"con":true,"img":false}]}
{"op":"mcm","clk":"11450166134","pt":1717318741032,"mc":[{"id":"1.229554904","rc":[{"atb":[[2.14,0],[2.08,10]],"id":70003368}],"con":true,"img":false}]}
{"op":"mcm","clk":"11450166172","pt":1717318741397,"mc":[{"id":"1.229554904","rc":[{"atb":[[1.89,4.39],[2.08,8.38]],"id":70003368},{"trd":[[2.08,3.23],[2.12,4.22]],"ltp":2.08,"tv":7.45,"id":70003368},{"trd":[[1.89,4.74]],"ltp":1.89,"tv":4.74,"id":47208569},{"atl":[[1.89,0],[1.9,0],[1.87,0]],"id":47208569}],"con":true,"img":false}]}
{"op":"mcm","clk":"11450166182","pt":1717318741500,"mc":[{"id":"1.229554904","rc":[{"atb":[[2.08,0]],"id":70003368},{"atb":[[1.8,6.01]],"id":47208569},{"atl":[[2.22,21.05],[2.2,0],[2.16,10]],"id":47208569}],"con":true,"img":false}]}
{"op":"mcm","clk":"11450166189","pt":1717318741605,"mc":[{"id":"1.229554904","rc":[{"atl":[[2.16,0]],"id":47208569}],"con":true,"img":false}]}
{"op":"mcm","clk":"11450166230","pt":1717318742022,"mc":[{"id":"1.229554904","rc":[{"atb":[[2.02,0],[2.06,0],[2.04,0]],"id":70003368}],"con":true,"img":false}]}
{"op":"mcm","clk":"11450166237","pt":1717318742119,"mc":[{"id":"1.229554904","rc":[{"atb":[[1.85,75.82]],"id":70003368}],"con":true,"img":false}]}
{"op":"mcm","clk":"11450166248","pt":1717318742223,"mc":[{"id":"1.229554904","rc":[{"atb":[[1.88,0]],"id":70003368}],"con":true,"img":false}]}
{"op":"mcm","clk":"11450166279","pt":1717318742537,"mc":[{"id":"1.229554904","rc":[{"atb":[[1.9,16.45]],"id":70003368},{"atl":[[2.24,18.31]],"id":70003368}],"con":true,"img":false}]}
{"op":"mcm","clk":"11450166303","pt":1717318742709,"mc":[{"id":"1.229554904","rc":[{"atb":[[1.81,9.68],[1.9,0],[1.91,8.62]],"id":70003368},{"atl":[[2.24,0]],"id":70003368},{"atb":[[1.73,10.75],[1.83,9.45]],"id":47208569}],"con":true,"img":false}]}
{"op":"mcm","clk":"11450166326","pt":1717318742907,"mc":[{"id":"1.229554904","rc":[{"atb":[[1.92,4.35]],"id":70003368}],"con":true,"img":false}]}
{"op":"mcm","clk":"11450166346","pt":1717318743114,"mc":[{"id":"1.229554904","rc":[{"atb":[[1.85,0],[1.78,71.43]],"id":70003368},{"atl":[[2.8,26.3],[2.86,0]],"id":70003368},{"atb":[[1.83,10.67],[1.8,4.77]],"id":47208569}],"con":true,"img":false}]}
{"op":"mcm","clk":"11450166399","pt":1717318743597,"mc":[{"id":"1.229554904","rc":[{"atb":[[1.83,5.44]],"id":47208569},{"trd":[[1.83,10.46]],"ltp":1.83,"tv":10.46,"id":47208569},{"atl":[[2.32,25.65],[2.22,0]],"id":47208569}],"con":true,"img":false}]}
{"op":"mcm","clk":"11450166409","pt":1717318743687,"mc":[{"id":"1.229554904","rc":[{"atb":[[1.84,4.48]],"id":47208569}],"con":true,"img":false}]}
{"op":"mcm","clk":"11450166554","pt":1717318745087,"mc":[{"id":"1.229554904","rc":[{"atb":[[1.93,16.08]],"id":70003368},{"atl":[[2.18,15.78]],"id":70003368},{"atb":[[1.84,19.08]],"id":47208569},{"atl":[[2.08,16.48]],"id":47208569}],"con":true,"img":false}]}
{"op":"mcm","clk":"11450166588","pt":1717318745396,"mc":[{"id":"1.229554904","rc":[{"atb":[[1.93,48.15]],"id":70003368},{"atb":[[1.85,35.09]],"id":47208569}],"con":true,"img":false}]}
{"op":"mcm","clk":"11450166618","pt":1717318745706,"mc":[{"id":"1.229554904","rc":[{"atb":[[1.94,4.3]],"id":70003368},{"atl":[[2.16,4.26]],"id":70003368},{"atb":[[1.79,0],[1.86,4.53]],"id":47208569},{"atl":[[2.06,4.49]],"id":47208569}],"con":true,"img":false}]}
{"op":"mcm","clk":"11450166850","pt":1717318747728,"mc":[{"id":"1.229554904","rc":[{"atb":[[1.95,15.91]],"id":70003368},{"atl":[[2.14,16.05]],"id":70003368},{"atl":[[2.04,16.79]],"id":47208569}],"con":true,"img":false}]}
{"op":"mcm","clk":"11450166869","pt":1717318747932,"mc":[{"id":"1.229554904","rc":[{"atb":[[1.96,31.06]],"id":70003368}],"con":true,"img":false}]}
{"op":"mcm","clk":"11450166994","pt":1717318749021,"mc":[{"id":"1.229554904","rc":[{"atb":[[1.83,4.22],[1.86,5.73]],"id":47208569}],"con":true,"img":false}]}
{"op":"mcm","clk":"11450167136","pt":1717318750315,"mc":[{"id":"1.229554904","rc":[{"atb":[[1.97,15.75]],"id":70003368},{"atb":[[1.86,16.94]],"id":47208569}],"con":true,"img":false}]}
{"op":"mcm","clk":"11450167161","pt":1717318750415,"mc":[{"id":"1.229554904","rc":[{"atb":[[1.87,34.28]],"id":47208569}],"con":true,"img":false}]}
{"op":"mcm","clk":"11450167172","pt":1717318750536,"mc":[{"id":"1.229554904","rc":[{"atl":[[2.12,4.3]],"id":70003368},{"atb":[[1.88,4.49]],"id":47208569}],"con":true,"img":false}]}
{"op":"mcm","clk":"11450167179","pt":1717318750634,"mc":[{"id":"1.229554904","rc":[{"atb":[[1.8,0]],"id":47208569}],"con":true,"img":false}]}
{"op":"mcm","clk":"11450167194","pt":1717318750727,"mc":[{"id":"1.229554904","rc":[{"atb":[[1.93,32.06]],"id":70003368}],"con":true,"img":false}]}
{"op":"mcm","clk":"11450167201","pt":1717318750832,"mc":[{"id":"1.229554904","rc":[{"atb":[[1.98,4.31]],"id":70003368},{"atl":[[2.02,4.48]],"id":47208569}],"con":true,"img":false}]}
{"op":"mcm","clk":"11450167247","pt":1717318751364,"mc":[{"id":"1.229554904","rc":[{"atb":[[1.88,5.68],[1.86,15.74]],"id":47208569}],"con":true,"img":false}]}
{"op":"mcm","clk":"11450167299","pt":1717318751916,"mc":[{"id":"1.229554904","rc":[{"atb":[[1.98,0],[1.96,29.55],[1.97,0]],"id":70003368},{"trd":[[1.96,3.03],[1.98,13.19],[1.97,31.51]],"ltp":1.96,"tv":47.73,"id":70003368},{"trd":[[2.02,4.48]],"ltp":2.02,"tv":4.48,"id":47208569},{"atl":[[2.02,0]],"id":47208569}],"con":true,"img":false}]}
{"op":"mcm","clk":"11450167329","pt":1717318752229,"mc":[{"id":"1.229554904","rc":[{"atb":[[1.95,0]],"id":70003368}],"con":true,"img":false}]}
{"op":"mcm","clk":"11450167348","pt":1717318752432,"mc":[{"id":"1.229554904","rc":[{"atb":[[1.97,4.78],[1.96,0]],"id":70003368},{"atb":[[1.9,16.36]],"id":47208569}],"con":true,"img":false}]}
{"op":"mcm","clk":"11450167355","pt":1717318752530,"mc":[{"id":"1.229554904","rc":[{"atl":[[2.08,0]],"id":47208569}],"con":true,"img":false}]}
{"op":"mcm","clk":"11450167366","pt":1717318752633,"mc":[{"id":"1.229554904","rc":[{"atb":[[1.97,0]],"id":70003368}],"con":true,"img":false}]}
{"op":"mcm","clk":"11450167396","pt":1717318752899,"mc":[{"id":"1.229554904","rc":[{"atb":[[1.93,0]],"id":70003368}],"con":true,"img":false}]}
{"op":"mcm","clk":"11450167414","pt":1717318753105,"mc":[{"id":"1.229554904","rc":[{"atl":[[2.04,0]],"id":47208569}],"con":true,"img":false}]}
{"op":"mcm","clk":"11450167429","pt":1717318753311,"mc":[{"id":"1.229554904","rc":[{"atb":[[1.47,0],[1.52,31.48]],"id":47208569}],"con":true,"img":false}]}
{"op":"mcm","clk":"11450167438","pt":1717318753411,"mc":[{"id":"1.229554904","rc":[{"atb":[[1.82,36.36]],"id":70003368}],"con":true,"img":false}]}
{"op":"mcm","clk":"11450167485","pt":1717318753926,"mc":[{"id":"1.229554904","rc":[{"atb":[[1.9,0]],"id":47208569}],"con":true,"img":false}]}
{"op":"mcm","clk":"11450167514","pt":1717318754347,"mc":[{"id":"1.229554904","rc":[{"atb":[[1.88,6.53]],"id":47208569}],"con":true,"img":false}]}
{"op":"mcm","clk":"11450167539","pt":1717318754502,"mc":[{"id":"1.229554904","rc":[{"atl":[[2.56,0],[2.52,0]],"id":47208569}],"con":true,"img":false}]}
{"op":"mcm","clk":"11450167550","pt":1717318754607,"mc":[{"id":"1.229554904","rc":[{"atl":[[2.1,16.33]],"id":70003368},{"atb":[[1.88,19.62]],"id":47208569}],"con":true,"img":false}]}
{"op":"mcm","clk":"11450167578","pt":1717318754916,"mc":[{"id":"1.229554904","rc":[{"atl":[[2.08,4.39]],"id":70003368},{"atb":[[1.82,0]],"id":47208569}],"con":true,"img":false}]}
{"op":"mcm","clk":"11450167589","pt":1717318755012,"mc":[{"id":"1.229554904","rc":[{"atb":[[1.89,4.39]],"id":47208569}],"con":true,"img":false}]}
{"op":"mcm","clk":"11450167623","pt":1717318755427,"mc":[{"id":"1.229554904","rc":[{"atb":[[1.89,37.91]],"id":47208569}],"con":true,"img":false}]}
{"op":"mcm","clk":"11450167649","pt":1717318755635,"mc":[{"id":"1.229554904","rc":[{"atb":[[1.94,0]],"id":70003368},{"atl":[[2.06,0]],"id":47208569}],"con":true,"img":false}]}
{"op":"mcm","clk":"11450167661","pt":1717318755736,"mc":[{"id":"1.229554904","rc":[{"atb":[[1.94,4.43]],"id":70003368},{"atl":[[2.08,0]],"id":70003368},{"atl":[[2.32,0],[2.06,4.36],[2.38,30.25]],"id":47208569}],"con":true,"img":false}]}
{"op":"mcm","clk":"11450167672","pt":1717318755795,"mc":[{"id":"1.229554904","rc":[{"atl":[[2.12,12.91]],"id":47208569}],"con":true,"img":false}]}
{"op":"mcm","clk":"11450167680","pt":1717318755899,"mc":[{"id":"1.229554904","rc":[{"atb":[[1.84,14.59]],"id":47208569}],"con":true,"img":false}]}
{"op":"mcm","clk":"11450167688","pt":1717318756031,"mc":[{"id":"1.229554904","rc":[{"atb":[[1.9,4.5]],"id":47208569}],"con":true,"img":false}]}
{"op":"mcm","clk":"11450167720","pt":1717318756410,"mc":[{"id":"1.229554904","rc":[{"atb":[[1.82,0],[1.9,33.14]],"id":70003368}],"con":true,"img":false}]}
{"op":"mcm","clk":"11450167728","pt":1717318756514,"mc":[{"id":"1.229554904","rc":[{"atl":[[2.32,9.2],[2.38,0]],"id":47208569}],"con":true,"img":false}]}
{"op":"mcm","clk":"11450167738","pt":1717318756622,"mc":[{"id":"1.229554904","rc":[{"atb":[[1.95,13.05]],"id":70003368}],"con":true,"img":false}]}
{"op":"mcm","clk":"11450167772","pt":1717318757033,"mc":[{"id":"1.229554904","rc":[{"atb":[[1.88,26.41]],"id":47208569},{"atl":[[2.08,11.09]],"id":47208569}],"con":true,"img":false}]}
{"op":"mcm","clk":"11450167814","pt":1717318757394,"mc":[{"id":"1.229554904","rc":[{"atb":[[1.93,32.06]],"id":70003368}],"con":true,"img":false}]}
{"op":"mcm","clk":"11450168332","pt":1717318763219,"mc":[{"id":"1.229554904","rc":[{"atb":[[1.92,0],[1.89,0],[1.94,0]],"id":70003368},{"atl":[[2.74,20.48],[2.84,16.3]],"id":70003368},{"atl":[[2.06,0]],"id":47208569}],"con":true,"img":false}]}
{"op":"mcm","clk":"11450168340","pt":1717318763325,"mc":[{"id":"1.229554904","rc":[{"atb":[[1.94,24.67]],"id":70003368},{"atb":[[1.91,23.15]],"id":47208569}],"con":true,"img":false}]}
{"op":"mcm","clk":"11450168348","pt":1717318763427,"mc":[{"id":"1.229554904","rc":[{"atb":[[1.92,32.41],[1.78,0],[1.95,0],[1.93,0],[1.66,71.43]],"id":70003368},{"atl":[[2.8,0],[2.08,4.5],[2.66,20.48]],"id":70003368},{"atl":[[2.32,0],[2.46,20.3]],"id":47208569}],"con":true,"img":false}]}
{"op":"mcm","clk":"11450168362","pt":1717318763634,"mc":[{"id":"1.229554904","rc":[{"atb":[[1.84,0]],"id":47208569}],"con":true,"img":false}]}
{"op":"mcm","clk":"11450168387","pt":1717318763938,"mc":[{"id":"1.229554904","rc":[{"atb":[[1.85,0]],"id":47208569}],"con":true,"img":false}]}
{"op":"mcm","clk":"11450168424","pt":1717318764359,"mc":[{"id":"1.229554904","rc":[{"atb":[[1.92,4.31],[1.86,11.2]],"id":47208569}],"con":true,"img":false}]}
{"op":"mcm","clk":"11450168474","pt":1717318764928,"mc":[{"id":"1.229554904","rc":[{"atb":[[1.91,55.92]],"id":47208569}],"con":true,"img":false}]}
{"op":"mcm","clk":"11450168527","pt":1717318765543,"mc":[{"id":"1.229554904","rc":[{"atb":[[1.93,23.12]],"id":47208569}],"con":true,"img":false}]}
{"op":"mcm","clk":"11450168564","pt":1717318765904,"mc":[{"id":"1.229554904","rc":[{"atb":[[1.87,0],[1.88,19.62],[1.86,0]],"id":47208569}],"con":true,"img":false}]}
{"op":"mcm","clk":"11450168715","pt":1717318767715,"mc":[{"id":"1.229554904","rc":[{"atb":[[1.88,6.53]],"id":47208569}],"con":true,"img":false}]}
{"op":"mcm","clk":"11450168773","pt":1717318768333,"mc":[{"id":"1.229554904","rc":[{"atb":[[1.94,23.67]],"id":70003368},{"trd":[[1.94,1.99]],"ltp":1.94,"tv":1.99,"id":70003368}],"con":true,"img":false}]}
{"op":"mcm","clk":"11450168782","pt":1717318768434,"mc":[{"id":"1.229554904","rc":[{"atb":[[1.94,0],[1.93,6.56]],"id":70003368}],"con":true,"img":false}]}
{"op":"mcm","clk":"11450168792","pt":1717318768533,"mc":[{"id":"1.229554904","rc":[{"atb":[[1.66,0],[1.75,71.43]],"id":70003368},{"atl":[[2.46,0],[2.34,22.2]],"id":47208569}],"con":true,"img":false}]}
{"op":"mcm","clk":"11450168804","pt":1717318768639,"mc":[{"id":"1.229554904","rc":[{"atb":[[1.91,13.15]],"id":70003368},{"atl":[[2.12,0],[2.1,4.26],[2.08,17.31]],"id":47208569}],"con":true,"img":false}]}
{"op":"mcm","clk":"11450168831","pt":1717318768946,"mc":[{"id":"1.229554904","rc":[{"atb":[[1.93,55.19]],"id":47208569}],"con":true,"img":false}]}
{"op":"mcm","clk":"11450168886","pt":1717318769572,"mc":[{"id":"1.229554904","rc":[{"atb":[[1.91,8.62]],"id":70003368},{"atb":[[1.94,4.33],[1.88,2.04]],"id":47208569},{"atl":[[2.1,0]],"id":47208569}],"con":true,"img":false}]}
{"op":"mcm","clk":"11450168894","pt":1717318769625,"mc":[{"id":"1.229554904","rc":[{"atb":[[1.82,4.61]],"id":70003368}],"con":true,"img":false}]}
{"op":"mcm","clk":"11450168959","pt":1717318770294,"mc":[{"id":"1.229554904","rc":[{"atb":[[1.95,23.15]],"id":47208569}],"con":true,"img":false}]}
{"op":"mcm","clk":"11450168993","pt":1717318770552,"mc":[{"id":"1.229554904","rc":[{"atb":[[1.91,32.77]],"id":47208569}],"con":true,"img":false}]}
{"op":"mcm","clk":"11450169001","pt":1717318770655,"mc":[{"id":"1.229554904","rc":[{"atb":[[1.89,33.51],[1.96,4.33]],"id":47208569}],"con":true,"img":false}]}
{"op":"mcm","clk":"11450169042","pt":1717318771026,"mc":[{"id":"1.229554904","rc":[{"atb":[[1.89,0]],"id":47208569}],"con":true,"img":false}]}
{"op":"mcm","clk":"11450169180","pt":1717318772457,"mc":[{"id":"1.229554904","rc":[{"atb":[[1.97,23.15]],"id":47208569}],"con":true,"img":false}]}
{"op":"mcm","clk":"11450169228","pt":1717318772924,"mc":[{"id":"1.229554904","rc":[{"atb":[[1.96,35.4],[1.93,32.06]],"id":47208569}],"con":true,"img":false}]}
{"op":"mcm","clk":"11450169249","pt":1717318773142,"mc":[{"id":"1.229554904","rc":[{"atl":[[2.08,0]],"id":47208569}],"con":true,"img":false}]}
{"op":"mcm","clk":"11450169281","pt":1717318773448,"mc":[{"id":"1.229554904","rc":[{"atb":[[1.92,0],[1.9,0]],"id":70003368}],"con":true,"img":false}]}
{"op":"mcm","clk":"11450169289","pt":1717318773550,"mc":[{"id":"1.229554904","rc":[{"atb":[[1.88,1.91]],"id":47208569}],"con":true,"img":false}]}
{"op":"mcm","clk":"11450169319","pt":1717318773917,"mc":[{"id":"1.229554904","rc":[{"atb":[[1.82,40.98]],"id":70003368}],"con":true,"img":false}]}
{"op":"mcm","clk":"11450169392","pt":1717318774648,"mc":[{"id":"1.229554904","rc":[{"atl":[[2.02,25.24]],"id":70003368}],"con":true,"img":false}]}
{"op":"mcm","clk":"11450169418","pt":1717318774952,"mc":[{"id":"1.229554904","rc":[{"atb":[[1.96,4.33]],"id":47208569}],"con":true,"img":false}]}
{"op":"mcm","clk":"11450169427","pt":1717318775066,"mc":[{"id":"1.229554904","rc":[{"atl":[[2.14,0],[2.18,0]],"id":70003368}],"con":true,"img":false}]}
{"op":"mcm","clk":"11450169553","pt":1717318776242,"mc":[{"id":"1.229554904","rc":[{"trd":[[2.02,25.24]],"ltp":2.02,"tv":25.24,"id":70003368},{"atl":[[2.02,0]],"id":70003368},{"atb":[[1.97,4.43]],"id":47208569},{"trd":[[1.97,37.44],[1.98,25.75]],"ltp":1.97,"tv":63.19,"id":47208569}],"con":true,"img":false}]}
{"op":"mcm","clk":"11450169558","pt":1717318776346,"mc":[{"id":"1.229554904","rc":[{"atb":[[1.83,4.55],[1.92,24.96]],"id":70003368},{"atl":[[2.16,10]],"id":47208569}],"con":true,"img":false}]}
{"op":"mcm","clk":"11450169565","pt":1717318776446,"mc":[{"id":"1.229554904","rc":[{"atb":[[1.93,0]],"id":70003368},{"atb":[[1.96,35.4]],"id":47208569}],"con":true,"img":false}]}
{"op":"mcm","clk":"11450169595","pt":1717318776854,"mc":[{"id":"1.229554904","rc":[{"atl":[[2.1,0]],"id":70003368},{"atb":[[1.95,0]],"id":47208569}],"con":true,"img":false}]}
{"op":"mcm","clk":"11450169610","pt":1717318777068,"mc":[{"id":"1.229554904","rc":[{"atl":[[2.16,10.97]],"id":47208569}],"con":true,"img":false}]}
{"op":"mcm","clk":"11450169643","pt":1717318777429,"mc":[{"id":"1.229554904","rc":[{"atb":[[1.92,57.37]],"id":70003368},{"atb":[[1.89,33.51],[1.96,4.33],[1.93,0],[1.91,0]],"id":47208569}],"con":true,"img":false}]}
{"op":"mcm","clk":"11450169684","pt":1717318778086,"mc":[{"id":"1.229554904","rc":[{"atb":[[1.82,4.61]],"id":70003368},{"atb":[[1.96,21.23],[1.97,0]],"id":47208569},{"atl":[[2.08,25.31]],"id":47208569}],"con":true,"img":false}]}
{"op":"mcm","clk":"11450169698","pt":1717318778277,"mc":[{"id":"1.229554904","rc":[{"atb":[[1.96,4.33]],"id":47208569},{"atl":[[2.06,10],[2.16,0.97]],"id":47208569}],"con":true,"img":false}]}
{"op":"mcm","clk":"11450169718","pt":1717318778460,"mc":[{"id":"1.229554904","rc":[{"atb":[[1.87,34.28]],"id":47208569}],"con":true,"img":false}]}
{"op":"mcm","clk":"11450169726","pt":1717318778564,"mc":[{"id":"1.229554904","rc":[{"atb":[[1.89,0]],"id":47208569}],"con":true,"img":false}]}
{"op":"mcm","clk":"11450169741","pt":1717318778772,"mc":[{"id":"1.229554904","rc":[{"atb":[[1.91,13.16]],"id":70003368},{"atl":[[2.16,5.22]],"id":47208569}],"con":true,"img":false}]}
{"op":"mcm","clk":"11450169775","pt":1717318779276,"mc":[{"id":"1.229554904","marketDefinition":{"bspMarket":false,"turnInPlayEnabled":false,"persistenceEnabled":false,"marketBaseRate":7.0,"eventId":"33318908","eventTypeId":"4339","numberOfWinners":1,"bettingType":"ODDS","marketType":"MATCH_BET","marketTime":"2024-06-02T08:59:00.000Z","suspendTime":"2024-06-02T08:59:00.000Z","bspReconciled":false,"complete":true,"inPlay":false,"crossMatching":true,"runnersVoidable":false,"numberOfActiveRunners":2,"betDelay":0,"status":"SUSPENDED","runners":[{"status":"ACTIVE","sortPriority":1,"id":47208569,"name":"4. Enticement"},{"status":"ACTIVE","sortPriority":2,"id":70003368,"name":"8. Dark Queen"}],"regulators":["MR_INT"],"venue":"Murray Bridge","countryCode":"AU","discountAllowed":true,"timezone":"Australia/Adelaide","openDate":"2024-06-02T08:21:00.000Z","version":5963007721,"name":"Enticement v Dark Queen","eventName":"Murray Bridge (AUS) 2nd Jun"},"rc":[],"con":true,"img":false}]}
{"op":"mcm","clk":"11450169775","pt":1717318779276,"mc":[{"id":"1.229554904","rc":[{"atb":[[1.83,0],[1.82,0],[1.92,0],[1.01,0],[1.81,0],[1.02,0],[1.91,0],[1.42,0],[1.75,0]],"id":70003368},{"atl":[[2.54,0],[2.74,0],[2.12,0],[2.66,0],[2.84,0],[2.16,0],[2.08,0],[970,0],[990,0]],"id":70003368},{"atb":[[1.73,0],[1.83,0],[1.92,0],[1.01,0],[1.88,0],[1.02,0],[1.9,0],[1.96,0],[1.94,0],[1.87,0],[1.48,0],[1.52,0]],"id":47208569},{"atl":[[2.06,0],[2.18,0],[2.16,0],[2.08,0],[2.34,0],[960,0],[1000,0]],"id":47208569}],"con":true,"img":false}]}
{"op":"mcm","clk":"11450173554","pt":1717318820273,"mc":[{"id":"1.229554904","rc":[{"trd":[[2.02,0],[1.98,0],[1.97,0],[2.22,0],[2.12,0],[1.96,0],[1.94,0],[2.08,0]],"ltp":2.02,"tv":0.0,"id":70003368},{"trd":[[1.82,0],[1.83,0],[2.02,0],[1.89,0],[1.98,0],[1.97,0]],"ltp":1.82,"tv":0.0,"id":47208569}],"con":true,"img":false}]}
{"op":"mcm","clk":"11450173665","pt":1717318821516,"mc":[{"id":"1.229554904","marketDefinition":{"bspMarket":false,"turnInPlayEnabled":false,"persistenceEnabled":false,"marketBaseRate":7.0,"eventId":"33318908","eventTypeId":"4339","numberOfWinners":1,"bettingType":"ODDS","marketType":"MATCH_BET","marketTime":"2024-06-02T08:59:00.000Z","suspendTime":"2024-06-02T08:59:00.000Z","bspReconciled":false,"complete":true,"inPlay":false,"crossMatching":false,"runnersVoidable":false,"numberOfActiveRunners":0,"betDelay":0,"status":"CLOSED","settledTime":"2024-06-02T09:00:18.000Z","runners":[{"status":"LOSER","sortPriority":1,"id":47208569,"name":"4. Enticement"},{"status":"WINNER","sortPriority":2,"id":70003368,"name":"8. Dark Queen"}],"regulators":["MR_INT"],"venue":"Murray Bridge","countryCode":"AU","discountAllowed":true,"timezone":"Australia/Adelaide","openDate":"2024-06-02T08:21:00.000Z","version":5963009301,"name":"Enticement v Dark Queen","eventName":"Murray Bridge (AUS) 2nd Jun"},"rc":[],"con":true,"img":false}]}
