{"op":"mcm","clk":"11448127650","pt":1717286034987,"mc":[{"id":"1.229554901","marketDefinition":{"bspMarket":true,"turnInPlayEnabled":false,"persistenceEnabled":false,"marketBaseRate":7.0,"eventId":"33318908","eventTypeId":"4339","numberOfWinners":2,"bettingType":"ODDS","marketType":"PLACE","marketTime":"2024-06-02T08:59:00.000Z","suspendTime":"2024-06-02T08:59:00.000Z","bspReconciled":false,"complete":true,"inPlay":false,"crossMatching":true,"runnersVoidable":false,"numberOfActiveRunners":6,"betDelay":0,"status":"OPEN","runners":[{"status":"ACTIVE","sortPriority":1,"id":63161681,"name":"1. Razzle Berries"},{"status":"ACTIVE","sortPriority":2,"id":63027102,"name":"2. Christoff"},{"status":"ACTIVE","sortPriority":3,"id":47208569,"name":"4. Enticement"},{"status":"ACTIVE","sortPriority":4,"id":67532289,"name":"5. Super Breeze"},{"status":"ACTIVE","sortPriority":5,"id":49183855,"name":"7. Bruces Angel"},{"status":"ACTIVE","sortPriority":6,"id":70003368,"name":"8. Dark Queen"}],"regulators":["MR_INT"],"venue":"Murray Bridge","countryCode":"AU","discountAllowed":true,"timezone":"Australia/Adelaide","openDate":"2024-06-02T08:21:00.000Z","version":5962317637,"name":"To Be Placed","eventName":"Murray Bridge (AUS) 2nd Jun"},"rc":[],"con":true,"img":false}]}
{"op":"mcm","clk":"11448260594","pt":1717287908430,"mc":[{"id":"1.229554901","rc":[{"atb":[[1.81,43.01],[1.91,25.52]],"id":70003368},{"atl":[[8,0.07]],"id":70003368},{"spn":4.95,"spf":"NaN","id":70003368},{"atb":[[1.78,29.77],[1.68,51.23]],"id":47208569},{"atl":[[7.2,0.08]],"id":47208569},{"spn":4.49,"spf":"NaN","id":47208569},{"atb":[[6.4,4.3],[5.2,8.29]],"id":49183855},{"spn":"Infinity","spf":"NaN","id":49183855},{"atb":[[1.72,32.26],[1.62,56.19]],"id":63161681},{"atl":[[6.8,0.08]],"id":63161681},{"spn":4.26,"spf":"NaN","id":63161681},{"atb":[[5.5,7.74],[7,3.87]],"id":63027102},{"spn":"Infinity","spf":"NaN","id":63027102},{"atb":[[1.14,165.92],[1.04,871.08]],"id":67532289},{"atl":[[2.94,0.27]],"id":67532289},{"spn":2.04,"spf":"NaN","id":67532289}],"con":true,"img":false}]}
{"op":"mcm","clk":"11448264312","pt":1717287962366,"mc":[{"id":"1.229554901","rc":[{"atb":[[1.81,0],[1.91,0]],"id":70003368},{"atl":[[8,0]],"id":70003368},{"atb":[[1.78,0],[1.68,0]],"id":47208569},{"atl":[[7.2,0]],"id":47208569},{"atb":[[6.4,0],[5.2,0]],"id":49183855},{"atb":[[1.72,0],[1.62,0]],"id":63161681},{"atl":[[6.8,0]],"id":63161681},{"atb":[[5.5,0],[7,0]],"id":63027102},{"atb":[[1.14,0],[1.04,0]],"id":67532289},{"atl":[[2.94,0]],"id":67532289}],"con":true,"img":false}]}
{"op":"mcm","clk":"11448265018","pt":1717287972318,"mc":[{"id":"1.229554901","rc":[{"atb":[[1.82,42.49],[1.92,25.24]],"id":70003368},{"atl":[[8,0.07]],"id":70003368},{"spn":4.96,"spf":"NaN","id":70003368},{"atb":[[1.67,52],[1.77,30.16]],"id":47208569},{"atl":[[7,0.08]],"id":47208569},{"spn":4.38,"spf":"NaN","id":47208569},{"atb":[[5.1,8.49],[6.2,4.46]],"id":49183855},{"atb":[[1.73,31.81],[1.63,55.3]],"id":63161681},{"atl":[[6.8,0.08]],"id":63161681},{"spn":4.26,"spf":"NaN","id":63161681},{"atb":[[5.5,7.74],[7,3.87]],"id":63027102},{"atb":[[1.12,193.57],[1.02,1742.17]],"id":67532289},{"atl":[[2.92,0.27]],"id":67532289},{"spn":2.02,"spf":"NaN","id":67532289}],"con":true,"img":false}]}
{"op":"mcm","clk":"11448272355","pt":1717288089584,"mc":[{"id":"1.229554901","rc":[{"atb":[[5.1,0],[6.2,0]],"id":49183855},{"spn":"NaN","spf":"NaN","id":49183855},{"atb":[[5.5,0],[7,0]],"id":63027102},{"spn":"NaN","spf":"NaN","id":63027102},{"atb":[[1.12,0],[1.02,0]],"id":67532289},{"atl":[[2.92,0]],"id":67532289},{"spn":"NaN","spf":"NaN","id":67532289}],"con":true,"img":false}]}
{"op":"mcm","clk":"11448273012","pt":1717288099886,"mc":[{"id":"1.229554901","rc":[{"atb":[[5.7,4.94],[4.7,9.41]],"id":49183855},{"atb":[[6.4,4.3],[5.2,8.29]],"id":63027102},{"atb":[[1.16,145.18],[1.06,580.72]],"id":67532289},{"atl":[[2.98,0.26]],"id":67532289}],"con":true,"img":false}]}
{"op":"mcm","clk":"11448284287","pt":1717288159833,"mc":[{"id":"1.229554901","rc":[{"atb":[[1.82,0],[1.92,0]],"id":70003368},{"atl":[[8,0]],"id":70003368},{"spn":"NaN","spf":"NaN","id":70003368},{"spn":"Infinity","spf":"NaN","id":49183855},{"atb":[[6.4,0],[5.2,0]],"id":63027102},{"spn":2.07,"spf":"NaN","id":67532289}],"con":true,"img":false}]}
{"op":"mcm","clk":"11448285284","pt":1717288174030,"mc":[{"id":"1.229554901","rc":[{"atb":[[1.85,27.33],[1.75,46.45]],"id":70003368},{"atl":[[7.6,0.07]],"id":70003368},{"atb":[[6.8,4],[5.4,7.92]],"id":63027102}],"con":true,"img":false}]}
{"op":"mcm","clk":"11448292458","pt":1717288273850,"mc":[{"id":"1.229554901","rc":[{"atb":[[1.85,0],[1.75,0]],"id":70003368},{"atl":[[7.6,0]],"id":70003368},{"atb":[[1.67,0],[1.77,0]],"id":47208569},{"atl":[[7,0]],"id":47208569},{"spn":"NaN","spf":"NaN","id":47208569},{"atb":[[5.7,0],[4.7,0]],"id":49183855},{"spn":"NaN","spf":"NaN","id":49183855},{"atb":[[1.73,0],[1.63,0]],"id":63161681},{"atl":[[6.8,0]],"id":63161681},{"spn":"NaN","spf":"NaN","id":63161681},{"atb":[[6.8,0],[5.4,0]],"id":63027102},{"atb":[[1.16,0],[1.06,0]],"id":67532289},{"atl":[[2.98,0]],"id":67532289},{"spn":"NaN","spf":"NaN","id":67532289}],"con":true,"img":false}]}
{"op":"mcm","clk":"11448293804","pt":1717288291623,"mc":[{"id":"1.229554901","rc":[{"atb":[[1.81,43.01],[1.91,25.52]],"id":70003368},{"atl":[[8,0.07]],"id":70003368},{"atb":[[1.85,27.33],[1.75,46.45]],"id":47208569},{"atl":[[7.6,0.07]],"id":47208569},{"atb":[[5.7,4.94],[4.7,9.41]],"id":49183855},{"atb":[[1.56,62.22],[1.66,35.19]],"id":63161681},{"atl":[[6.2,0.09]],"id":63161681},{"atb":[[5.5,7.74],[7,3.87]],"id":63027102},{"atb":[[1.15,154.86],[1.05,696.87]],"id":67532289},{"atl":[[2.98,0.26]],"id":67532289}],"con":true,"img":false}]}
{"op":"mcm","clk":"11448298269","pt":1717288351379,"mc":[{"id":"1.229554901","rc":[{"atb":[[1.81,0],[1.91,0]],"id":70003368},{"atl":[[8,0]],"id":70003368},{"atb":[[1.85,0],[1.75,0]],"id":47208569},{"atl":[[7.6,0]],"id":47208569},{"atb":[[5.7,0],[4.7,0]],"id":49183855},{"atb":[[1.56,0],[1.66,0]],"id":63161681},{"atl":[[6.2,0]],"id":63161681},{"atb":[[5.5,0],[7,0]],"id":63027102},{"atb":[[1.15,0],[1.05,0]],"id":67532289},{"atl":[[2.98,0]],"id":67532289}],"con":true,"img":false}]}
{"op":"mcm","clk":"11448300795","pt":1717288383947,"mc":[{"id":"1.229554901","rc":[{"atb":[[1.79,44.1],[1.89,26.1]],"id":70003368},{"atl":[[7.8,0.07]],"id":70003368},{"atb":[[1.8,29.03],[1.7,49.77]],"id":47208569},{"atl":[[7.2,0.08]],"id":47208569},{"atb":[[5.7,4.94],[4.7,9.41]],"id":49183855},{"atb":[[1.57,61.12],[1.67,34.67]],"id":63161681},{"atl":[[6.4,0.09]],"id":63161681},{"atb":[[7.8,3.41],[5.9,7.1]],"id":63027102},{"atb":[[1.19,122.25],[1.09,387.15]],"id":67532289},{"atl":[[3.05,0.25]],"id":67532289}],"con":true,"img":false}]}
{"op":"mcm","clk":"11448305316","pt":1717288449206,"mc":[{"id":"1.229554901","rc":[{"spn":4.84,"spf":"NaN","id":70003368},{"atb":[[1.8,0],[1.7,0]],"id":47208569},{"atl":[[7.2,0]],"id":47208569},{"atb":[[5.7,0],[4.7,0]],"id":49183855},{"atb":[[1.57,0],[1.67,0]],"id":63161681},{"atl":[[6.4,0]],"id":63161681},{"atb":[[7.8,0],[5.9,0]],"id":63027102},{"atb":[[1.19,0],[1.09,0]],"id":67532289},{"atl":[[3.05,0]],"id":67532289}],"con":true,"img":false}]}
{"op":"mcm","clk":"11448307458","pt":1717288481177,"mc":[{"id":"1.229554901","rc":[{"atb":[[1.73,47.72],[1.83,27.98]],"id":47208569},{"atl":[[7.4,0.08]],"id":47208569},{"atb":[[5.6,7.57],[7.2,3.74]],"id":49183855},{"atb":[[1.64,36.29],[1.54,64.52]],"id":63161681},{"atl":[[6,0.1]],"id":63161681},{"atb":[[7.8,3.41],[5.9,7.1]],"id":63027102},{"atb":[[1.14,165.92],[1.04,871.08]],"id":67532289},{"atl":[[2.94,0.27]],"id":67532289}],"con":true,"img":false}]}
{"op":"mcm","clk":"11448310805","pt":1717288529482,"mc":[{"id":"1.229554901","rc":[{"spn":4.61,"spf":"NaN","id":47208569},{"spn":"Infinity","spf":"NaN","id":49183855},{"spn":3.82,"spf":"NaN","id":63161681},{"atb":[[7.8,0],[5.9,0]],"id":63027102},{"spn":2.04,"spf":"NaN","id":67532289}],"con":true,"img":false}]}
{"op":"mcm","clk":"11448312152","pt":1717288548667,"mc":[{"id":"1.229554901","rc":[{"atb":[[7.4,3.63],[5.7,7.41]],"id":63027102}],"con":true,"img":false}]}
{"op":"mcm","clk":"11448321955","pt":1717288687519,"mc":[{"id":"1.229554901","rc":[{"atb":[[7.4,0],[5.7,0]],"id":63027102},{"atb":[[1.14,0],[1.04,0]],"id":67532289},{"atl":[[2.94,0]],"id":67532289},{"spn":"NaN","spf":"NaN","id":67532289}],"con":true,"img":false}]}
{"op":"mcm","clk":"11448323044","pt":1717288701244,"mc":[{"id":"1.229554901","rc":[{"atb":[[5.5,7.74],[7,3.87]],"id":63027102},{"atb":[[1.19,122.25],[1.09,387.15]],"id":67532289},{"atl":[[3.05,0.25]],"id":67532289}],"con":true,"img":false}]}
{"op":"mcm","clk":"11448325043","pt":1717288727655,"mc":[{"id":"1.229554901","rc":[{"atb":[[5.5,0],[7,0]],"id":63027102}],"con":true,"img":false}]}
{"op":"mcm","clk":"11448326201","pt":1717288744502,"mc":[{"id":"1.229554901","rc":[{"atb":[[6.8,4],[5.4,7.92]],"id":63027102}],"con":true,"img":false}]}
{"op":"mcm","clk":"11448629967","pt":1717293528419,"mc":[{"id":"1.229554901","marketDefinition":{"bspMarket":true,"turnInPlayEnabled":false,"persistenceEnabled":false,"marketBaseRate":7.0,"eventId":"33318908","eventTypeId":"4339","numberOfWinners":2,"bettingType":"ODDS","marketType":"PLACE","marketTime":"2024-06-02T08:59:00.000Z","suspendTime":"2024-06-02T08:59:00.000Z","bspReconciled":false,"complete":true,"inPlay":false,"crossMatching":true,"runnersVoidable":false,"numberOfActiveRunners":6,"betDelay":0,"status":"OPEN","runners":[{"status":"ACTIVE","sortPriority":1,"id":63161681,"name":"1. Razzle Berries"},{"status":"ACTIVE","sortPriority":2,"id":63027102,"name":"2. Christoff"},{"status":"ACTIVE","sortPriority":3,"id":47208569,"name":"4. Enticement"},{"status":"ACTIVE","sortPriority":4,"id":67532289,"name":"5. Super Breeze"},{"status":"ACTIVE","sortPriority":5,"id":49183855,"name":"7. Bruces Angel"},{"status":"ACTIVE","sortPriority":6,"id":70003368,"name":"8. Dark Queen"}],"regulators":["MR_INT"],"venue":"Murray Bridge","countryCode":"AU","discountAllowed":true,"timezone":"Australia/Adelaide","openDate":"2024-06-02T08:21:00.000Z","version":5962317637,"name":"To Be Placed","eventName":"Murray Bridge (AUS) 2nd Jun"},"rc":[{"atb":[[1.79,44.1],[1.89,26.1]],"id":70003368},{"atl":[[7.8,0.07]],"id":70003368},{"spn":4.84,"spf":"NaN","id":70003368},{"atb":[[1.73,47.72],[1.83,27.98]],"id":47208569},{"atl":[[7.4,0.08]],"id":47208569},{"spn":4.61,"spf":"NaN","id":47208569},{"atb":[[5.6,7.57],[7.2,3.74]],"id":49183855},{"spn":"Infinity","spf":"NaN","id":49183855},{"atb":[[1.64,36.29],[1.54,64.52]],"id":63161681},{"atl":[[6,0.1]],"id":63161681},{"spn":3.82,"spf":"NaN","id":63161681},{"atb":[[6.8,4],[5.4,7.92]],"id":63027102},{"spn":"Infinity","spf":"NaN","id":63027102},{"atb":[[1.19,122.25],[1.09,387.15]],"id":67532289},{"atl":[[3.05,0.25]],"id":67532289},{"spn":2.12,"spf":"NaN","id":67532289}],"con":true,"img":true}]}
{"op":"mcm","clk":"11449367030","pt":1717308032356,"mc":[{"id":"1.229554901","rc":[{"atb":[[1.79,0],[1.89,0]],"id":70003368},{"atl":[[7.8,0]],"id":70003368},{"spn":"NaN","spf":"NaN","id":70003368},{"atb":[[1.73,0],[1.83,0]],"id":47208569},{"atl":[[7.4,0]],"id":47208569},{"spn":"NaN","spf":"NaN","id":47208569},{"atb":[[5.6,0],[7.2,0]],"id":49183855},{"spn":"NaN","spf":"NaN","id":49183855},{"atb":[[1.64,0],[1.54,0]],"id":63161681},{"atl":[[6,0]],"id":63161681},{"spn":"NaN","spf":"NaN","id":63161681},{"atb":[[6.8,0],[5.4,0]],"id":63027102},{"atb":[[1.19,0],[1.09,0]],"id":67532289},{"atl":[[3.05,0]],"id":67532289}],"con":true,"img":false}]}
{"op":"mcm","clk":"11449367310","pt":1717308038566,"mc":[{"id":"1.229554901","rc":[{"atb":[[1.8,43.55],[1.9,25.8]],"id":70003368},{"atl":[[8,0.07]],"id":70003368},{"atb":[[1.79,29.4],[1.69,50.49]],"id":47208569},{"atl":[[7.2,0.08]],"id":47208569},{"atb":[[5.3,8.1],[6.6,4.14]],"id":49183855},{"atb":[[1.56,62.22],[1.66,35.19]],"id":63161681},{"atl":[[6.2,0.09]],"id":63161681},{"atb":[[7.4,3.63],[5.7,7.41]],"id":63027102},{"atb":[[1.18,129.05],[1.08,435.54]],"id":67532289},{"atl":[[3,0.26]],"id":67532289}],"con":true,"img":false}]}
{"op":"mcm","clk":"11449437342","pt":1717309126625,"mc":[{"id":"1.229554901","rc":[{"atb":[[1.8,0],[1.9,0]],"id":70003368},{"atl":[[8,0]],"id":70003368},{"atb":[[1.79,0],[1.69,0]],"id":47208569},{"atl":[[7.2,0]],"id":47208569},{"atb":[[5.3,0],[6.6,0]],"id":49183855},{"atb":[[1.56,0],[1.66,0]],"id":63161681},{"atl":[[6.2,0]],"id":63161681},{"atb":[[7.4,0],[5.7,0]],"id":63027102},{"atb":[[1.18,0],[1.08,0]],"id":67532289},{"atl":[[3,0]],"id":67532289}],"con":true,"img":false}]}
{"op":"mcm","clk":"11449438870","pt":1717309151566,"mc":[{"id":"1.229554901","rc":[{"atb":[[1.77,45.24],[1.87,26.69]],"id":70003368},{"atl":[[7.8,0.07]],"id":70003368},{"atb":[[1.82,28.33],[1.72,48.39]],"id":47208569},{"atl":[[7.4,0.08]],"id":47208569},{"atb":[[6.8,4],[5.4,7.92]],"id":49183855},{"atb":[[1.55,63.35],[1.65,35.73]],"id":63161681},{"atl":[[6.2,0.09]],"id":63161681},{"atb":[[7.4,3.63],[5.7,7.41]],"id":63027102},{"atb":[[1.18,129.05],[1.08,435.54]],"id":67532289},{"atl":[[3,0.26]],"id":67532289}],"con":true,"img":false}]}
{"op":"mcm","clk":"11449442383","pt":1717309206590,"mc":[{"id":"1.229554901","rc":[{"atb":[[1.77,0],[1.87,0]],"id":70003368},{"atl":[[7.8,0]],"id":70003368},{"atb":[[1.82,0],[1.72,0]],"id":47208569},{"atl":[[7.4,0]],"id":47208569},{"atb":[[6.8,0],[5.4,0]],"id":49183855},{"spn":3.92,"spf":"NaN","id":63161681},{"atb":[[7.4,0],[5.7,0]],"id":63027102},{"atb":[[1.18,0],[1.08,0]],"id":67532289},{"atl":[[3,0]],"id":67532289}],"con":true,"img":false}]}
{"op":"mcm","clk":"11449442982","pt":1717309215121,"mc":[{"id":"1.229554901","rc":[{"atb":[[1.55,0],[1.65,0]],"id":63161681},{"atl":[[6.2,0]],"id":63161681}],"con":true,"img":false}]}
{"op":"mcm","clk":"11449447233","pt":1717309280771,"mc":[{"id":"1.229554901","marketDefinition":{"bspMarket":true,"turnInPlayEnabled":false,"persistenceEnabled":false,"marketBaseRate":7.0,"eventId":"33318908","eventTypeId":"4339","numberOfWinners":2,"bettingType":"ODDS","marketType":"PLACE","marketTime":"2024-06-02T08:59:00.000Z","suspendTime":"2024-06-02T08:59:00.000Z","bspReconciled":false,"complete":true,"inPlay":false,"crossMatching":true,"runnersVoidable":false,"numberOfActiveRunners":6,"betDelay":0,"status":"SUSPENDED","runners":[{"status":"ACTIVE","sortPriority":1,"id":63161681,"name":"1. Razzle Berries"},{"status":"ACTIVE","sortPriority":2,"id":63027102,"name":"2. Christoff"},{"status":"ACTIVE","sortPriority":3,"id":47208569,"name":"4. Enticement"},{"status":"ACTIVE","sortPriority":4,"id":67532289,"name":"5. Super Breeze"},{"status":"ACTIVE","sortPriority":5,"id":49183855,"name":"7. Bruces Angel"},{"status":"ACTIVE","sortPriority":6,"id":70003368,"name":"8. Dark Queen"}],"regulators":["MR_INT"],"venue":"Murray Bridge","countryCode":"AU","discountAllowed":true,"timezone":"Australia/Adelaide","openDate":"2024-06-02T08:21:00.000Z","version":5962889464,"name":"To Be Placed","eventName":"Murray Bridge (AUS) 2nd Jun"},"rc":[],"con":true,"img":false}]}
{"op":"mcm","clk":"11449448335","pt":1717309298322,"mc":[{"id":"1.229554901","marketDefinition":{"bspMarket":true,"turnInPlayEnabled":false,"persistenceEnabled":false,"marketBaseRate":7.0,"eventId":"33318908","eventTypeId":"4339","numberOfWinners":2,"bettingType":"ODDS","marketType":"PLACE","marketTime":"2024-06-02T08:59:00.000Z","suspendTime":"2024-06-02T08:59:00.000Z","bspReconciled":false,"complete":true,"inPlay":false,"crossMatching":true,"runnersVoidable":false,"numberOfActiveRunners":5,"betDelay":0,"status":"SUSPENDED","runners":[{"status":"ACTIVE","sortPriority":1,"id":63027102,"name":"2. Christoff"},{"status":"ACTIVE","sortPriority":2,"id":47208569,"name":"4. Enticement"},{"status":"ACTIVE","sortPriority":3,"id":67532289,"name":"5. Super Breeze"},{"status":"ACTIVE","sortPriority":4,"id":49183855,"name":"7. Bruces Angel"},{"status":"ACTIVE","sortPriority":5,"id":70003368,"name":"8. Dark Queen"},{"status":"REMOVED","sortPriority":6,"removalDate":"2024-06-02T06:21:38.000Z","id":63161681,"name":"1. Razzle Berries"}],"regulators":["MR_INT"],"venue":"Murray Bridge","countryCode":"AU","discountAllowed":true,"timezone":"Australia/Adelaide","openDate":"2024-06-02T08:21:00.000Z","version":5962889950,"name":"To Be Placed","eventName":"Murray Bridge (AUS) 2nd Jun"},"rc":[],"con":true,"img":false}]}
{"op":"mcm","clk":"11449452432","pt":1717309356905,"mc":[{"id":"1.229554901","marketDefinition":{"bspMarket":true,"turnInPlayEnabled":false,"persistenceEnabled":false,"marketBaseRate":7.0,"eventId":"33318908","eventTypeId":"4339","numberOfWinners":2,"bettingType":"ODDS","marketType":"PLACE","marketTime":"2024-06-02T08:59:00.000Z","suspendTime":"2024-06-02T08:59:00.000Z","bspReconciled":false,"complete":true,"inPlay":false,"crossMatching":true,"runnersVoidable":false,"numberOfActiveRunners":5,"betDelay":0,"status":"OPEN","runners":[{"status":"ACTIVE","sortPriority":1,"id":63027102,"name":"2. Christoff"},{"status":"ACTIVE","sortPriority":2,"id":47208569,"name":"4. Enticement"},{"status":"ACTIVE","sortPriority":3,"id":67532289,"name":"5. Super Breeze"},{"status":"ACTIVE","sortPriority":4,"id":49183855,"name":"7. Bruces Angel"},{"status":"ACTIVE","sortPriority":5,"id":70003368,"name":"8. Dark Queen"},{"status":"REMOVED","sortPriority":6,"removalDate":"2024-06-02T06:21:38.000Z","id":63161681,"name":"1. Razzle Berries"}],"regulators":["MR_INT"],"venue":"Murray Bridge","countryCode":"AU","discountAllowed":true,"timezone":"Australia/Adelaide","openDate":"2024-06-02T08:21:00.000Z","version":5962891350,"name":"To Be Placed","eventName":"Murray Bridge (AUS) 2nd Jun"},"rc":[],"con":true,"img":false}]}
{"op":"mcm","clk":"11449454762","pt":1717309392781,"mc":[{"id":"1.229554901","rc":[{"atb":[[1.01,5807.26]],"id":67532289},{"atl":[[2.64,0.31]],"id":67532289},{"spn":1.82,"spf":"NaN","id":67532289}],"con":true,"img":false}]}
{"op":"mcm","clk":"11449460680","pt":1717309485424,"mc":[{"id":"1.229554901","rc":[{"atb":[[1.44,52.79],[1.34,102.47]],"id":70003368},{"atl":[[4.2,0.16]],"id":70003368},{"spn":2.82,"spf":"NaN","id":70003368},{"atb":[[1.43,54.02],[1.33,105.58]],"id":47208569},{"atl":[[4.1,0.16]],"id":47208569},{"spn":2.76,"spf":"NaN","id":47208569},{"atb":[[3.95,11.81],[4.9,5.95]],"id":63027102},{"spn":"Infinity","spf":"NaN","id":63027102}],"con":true,"img":false}]}
{"op":"mcm","clk":"11449462408","pt":1717309511436,"mc":[{"id":"1.229554901","rc":[{"atb":[[1.44,0],[1.34,0]],"id":70003368},{"atl":[[4.2,0]],"id":70003368},{"atb":[[1.43,0],[1.33,0]],"id":47208569},{"atl":[[4.1,0]],"id":47208569},{"atb":[[1.01,0]],"id":67532289},{"atl":[[2.64,0]],"id":67532289}],"con":true,"img":false}]}
{"op":"mcm","clk":"11449463292","pt":1717309524777,"mc":[{"id":"1.229554901","rc":[{"atb":[[1.48,48.39],[1.38,91.69]],"id":70003368},{"atl":[[4.4,0.15]],"id":70003368},{"atb":[[1.4,58.07],[1.3,116.14]],"id":47208569},{"atl":[[4,0.17]],"id":47208569},{"atb":[[1.01,5807.26]],"id":67532289},{"atl":[[2.64,0.31]],"id":67532289}],"con":true,"img":false}]}
{"op":"mcm","clk":"11449480352","pt":1717309728419,"mc":[{"id":"1.229554901","marketDefinition":{"bspMarket":true,"turnInPlayEnabled":false,"persistenceEnabled":false,"marketBaseRate":7.0,"eventId":"33318908","eventTypeId":"4339","numberOfWinners":2,"bettingType":"ODDS","marketType":"PLACE","marketTime":"2024-06-02T08:59:00.000Z","suspendTime":"2024-06-02T08:59:00.000Z","bspReconciled":false,"complete":true,"inPlay":false,"crossMatching":true,"runnersVoidable":false,"numberOfActiveRunners":5,"betDelay":0,"status":"OPEN","runners":[{"status":"ACTIVE","sortPriority":1,"id":63027102,"name":"2. Christoff"},{"status":"ACTIVE","sortPriority":2,"id":47208569,"name":"4. Enticement"},{"status":"ACTIVE","sortPriority":3,"id":67532289,"name":"5. Super Breeze"},{"status":"ACTIVE","sortPriority":4,"id":49183855,"name":"7. Bruces Angel"},{"status":"ACTIVE","sortPriority":5,"id":70003368,"name":"8. Dark Queen"},{"status":"REMOVED","sortPriority":6,"removalDate":"2024-06-02T06:21:38.000Z","id":63161681,"name":"1. Razzle Berries"}],"regulators":["MR_INT"],"venue":"Murray Bridge","countryCode":"AU","discountAllowed":true,"timezone":"Australia/Adelaide","openDate":"2024-06-02T08:21:00.000Z","version":5962891350,"name":"To Be Placed","eventName":"Murray Bridge (AUS) 2nd Jun"},"rc":[{"atb":[[1.48,48.39],[1.38,91.69]],"id":70003368},{"atl":[[4.4,0.15]],"id":70003368},{"spn":2.94,"spf":"NaN","id":70003368},{"atb":[[1.4,58.07],[1.3,116.14]],"id":47208569},{"atl":[[4,0.17]],"id":47208569},{"spn":2.7,"spf":"NaN","id":47208569},{"atb":[[3.95,11.81],[4.9,5.95]],"id":63027102},{"spn":"Infinity","spf":"NaN","id":63027102},{"atb":[[1.01,5807.26]],"id":67532289},{"atl":[[2.64,0.31]],"id":67532289},{"spn":1.82,"spf":"NaN","id":67532289}],"con":true,"img":true}]}
{"op":"mcm","clk":"11449491210","pt":1717309814047,"mc":[{"id":"1.229554901","rc":[{"spn":2.94,"spf":"NaN","id":70003368},{"spn":2.7,"spf":"NaN","id":47208569},{"atb":[[3.95,0],[4.9,0]],"id":63027102},{"spn":"NaN","spf":"NaN","id":63027102}],"con":true,"img":false}]}
{"op":"mcm","clk":"11449492615","pt":1717309833772,"mc":[{"id":"1.229554901","rc":[{"atb":[[4,11.61],[5,5.8]],"id":63027102}],"con":true,"img":false}]}
{"op":"mcm","clk":"11449516572","pt":1717310230694,"mc":[{"id":"1.229554901","rc":[{"atb":[[1.48,0],[1.38,0]],"id":70003368},{"atl":[[4.4,0]],"id":70003368},{"spn":"NaN","spf":"NaN","id":70003368},{"atb":[[1.4,0],[1.3,0]],"id":47208569},{"atl":[[4,0]],"id":47208569},{"spn":"NaN","spf":"NaN","id":47208569},{"atb":[[4,0],[5,0]],"id":63027102},{"atb":[[1.01,0]],"id":67532289},{"atl":[[2.64,0]],"id":67532289},{"spn":"NaN","spf":"NaN","id":67532289}],"con":true,"img":false}]}
{"op":"mcm","clk":"11449517962","pt":1717310252321,"mc":[{"id":"1.229554901","rc":[{"atb":[[1.42,82.96],[1.52,44.66]],"id":70003368},{"atl":[[4.7,0.14]],"id":70003368},{"atb":[[1.25,139.37],[1.35,66.37]],"id":47208569},{"atl":[[3.7,0.19]],"id":47208569},{"atb":[[4.8,6.11],[3.9,12.01]],"id":63027102},{"atb":[[1.01,5807.26]],"id":67532289},{"atl":[[2.68,0.31]],"id":67532289}],"con":true,"img":false}]}
{"op":"mcm","clk":"11449578273","pt":1717311300179,"mc":[{"id":"1.229554901","rc":[{"atb":[[1.42,0],[1.52,0]],"id":70003368},{"atl":[[4.7,0]],"id":70003368},{"atb":[[1.25,0],[1.35,0]],"id":47208569},{"atl":[[3.7,0]],"id":47208569},{"atb":[[4.8,0],[3.9,0]],"id":63027102},{"atb":[[1.01,0]],"id":67532289},{"atl":[[2.68,0]],"id":67532289}],"con":true,"img":false}]}
{"op":"mcm","clk":"11449579171","pt":1717311314926,"mc":[{"id":"1.229554901","rc":[{"atb":[[1.41,84.98],[1.51,45.54]],"id":70003368},{"atl":[[4.6,0.14]],"id":70003368},{"atb":[[1.28,124.44],[1.38,61.12]],"id":47208569},{"atl":[[3.9,0.17]],"id":47208569},{"atb":[[3.95,11.81],[4.9,5.95]],"id":63027102},{"atb":[[1.01,5807.26]],"id":67532289},{"atl":[[2.64,0.31]],"id":67532289}],"con":true,"img":false}]}
{"op":"mcm","clk":"11449586484","pt":1717311439386,"mc":[{"id":"1.229554901","rc":[{"atb":[[1.02,8.94]],"id":70003368},{"atl":[[990,0.85]],"id":70003368},{"spn":3.05,"spf":"NaN","id":70003368},{"atb":[[1.01,17.89]],"id":47208569},{"atl":[[1000,0.85]],"id":47208569},{"spn":2.64,"spf":"NaN","id":47208569},{"atb":[[1.03,5.96]],"id":49183855},{"atl":[[1000,0.85]],"id":49183855},{"spn":500.51,"spf":"NaN","id":49183855},{"atb":[[1.03,5.96]],"id":63027102},{"atl":[[1000,0.85]],"id":63027102},{"spn":502.45,"spf":"NaN","id":63027102},{"atb":[[1.01,5825.15]],"id":67532289},{"atl":[[1000,0.85]],"id":67532289},{"spn":1.82,"spf":"NaN","id":67532289}],"con":true,"img":false}]}
{"op":"mcm","clk":"11449588496","pt":1717311474766,"mc":[{"id":"1.229554901","rc":[{"atb":[[4.8,6.11],[3.9,12.01]],"id":49183855}],"con":true,"img":false}]}
{"op":"mcm","clk":"11449624317","pt":1717312169307,"mc":[{"id":"1.229554901","rc":[{"atb":[[1.41,0],[1.51,0]],"id":70003368},{"atl":[[4.6,0]],"id":70003368},{"spn":495.51,"spf":"NaN","id":70003368},{"atb":[[1.28,0],[1.38,0]],"id":47208569},{"atl":[[3.9,0]],"id":47208569},{"spn":500.5,"spf":"NaN","id":47208569},{"spn":502.4,"spf":"NaN","id":49183855},{"atb":[[3.95,0],[4.9,0]],"id":63027102},{"spn":500.51,"spf":"NaN","id":63027102},{"atb":[[1.01,17.89]],"id":67532289},{"atl":[[2.64,0]],"id":67532289},{"spn":500.5,"spf":"NaN","id":67532289}],"con":true,"img":false}]}
{"op":"mcm","clk":"11449624990","pt":1717312185655,"mc":[{"id":"1.229554901","rc":[{"atb":[[1.49,47.4],[1.39,89.34]],"id":70003368},{"atl":[[4.4,0.15]],"id":70003368},{"atb":[[1.41,56.65],[1.31,112.39]],"id":47208569},{"atl":[[4.1,0.16]],"id":47208569},{"atb":[[5.1,5.66],[4.1,11.23]],"id":63027102},{"atb":[[1.01,5825.15]],"id":67532289},{"atl":[[2.64,0.31]],"id":67532289}],"con":true,"img":false}]}
{"op":"mcm","clk":"11449629874","pt":1717312307929,"mc":[{"id":"1.229554901","rc":[{"spn":2.94,"spf":"NaN","id":70003368},{"spn":2.75,"spf":"NaN","id":47208569},{"atb":[[4.8,0],[3.9,0]],"id":49183855},{"spn":500.51,"spf":"NaN","id":49183855},{"spn":502.55,"spf":"NaN","id":63027102},{"spn":1.82,"spf":"NaN","id":67532289}],"con":true,"img":false}]}
{"op":"mcm","clk":"11449630303","pt":1717312317937,"mc":[{"id":"1.229554901","rc":[{"atb":[[3.85,12.22],[4.7,6.27]],"id":49183855}],"con":true,"img":false}]}
{"op":"mcm","clk":"11449657588","pt":1717312995065,"mc":[{"id":"1.229554901","rc":[{"atb":[[1.49,0],[1.39,0]],"id":70003368},{"atl":[[4.4,0]],"id":70003368},{"spn":495.51,"spf":"NaN","id":70003368},{"atb":[[1.41,0],[1.31,0]],"id":47208569},{"atl":[[4.1,0]],"id":47208569},{"spn":500.5,"spf":"NaN","id":47208569},{"spn":502.35,"spf":"NaN","id":49183855},{"atb":[[5.1,0],[4.1,0]],"id":63027102},{"spn":500.51,"spf":"NaN","id":63027102},{"atb":[[1.01,17.89]],"id":67532289},{"atl":[[2.64,0]],"id":67532289},{"spn":500.5,"spf":"NaN","id":67532289}],"con":true,"img":false}]}
{"op":"mcm","clk":"11449658098","pt":1717313008085,"mc":[{"id":"1.229554901","rc":[{"atb":[[1.4,87.1],[1.5,46.45]],"id":70003368},{"atl":[[4.5,0.15]],"id":70003368},{"atb":[[1.36,64.52],[1.26,134.01]],"id":47208569},{"atl":[[3.75,0.18]],"id":47208569},{"atb":[[3.95,11.81],[4.9,5.95]],"id":63027102},{"atb":[[1.01,5825.15]],"id":67532289},{"atl":[[2.68,0.31]],"id":67532289}],"con":true,"img":false}]}
{"op":"mcm","clk":"11449667339","pt":1717313215510,"mc":[{"id":"1.229554901","rc":[{"spn":3.0,"spf":"NaN","id":70003368},{"spn":2.55,"spf":"NaN","id":47208569},{"atb":[[3.85,0],[4.7,0]],"id":49183855},{"spn":500.51,"spf":"NaN","id":49183855},{"spn":502.45,"spf":"NaN","id":63027102},{"spn":1.84,"spf":"NaN","id":67532289}],"con":true,"img":false}]}
{"op":"mcm","clk":"11449668017","pt":1717313230061,"mc":[{"id":"1.229554901","rc":[{"atb":[[5.1,5.66],[4.1,11.23]],"id":49183855}],"con":true,"img":false}]}
{"op":"mcm","clk":"11449705328","pt":1717313753033,"mc":[{"id":"1.229554901","rc":[{"atb":[[1.28,224.44],[1.34,49.24]],"id":70003368},{"atl":[[6,8.37],[6.6,10.98]],"id":70003368},{"atb":[[1.3,55.8],[1.24,253.74]],"id":47208569},{"atl":[[6,12.03],[5.4,9.51]],"id":47208569},{"atb":[[5,10.46],[4.2,19.35]],"id":49183855},{"atl":[[60,5.23]],"id":49183855},{"spn":32.55,"spf":"NaN","id":49183855},{"atb":[[4.6,15],[5.4,9.51]],"id":63027102},{"atl":[[70,2.61],[75,2.61]],"id":63027102},{"spn":37.7,"spf":"NaN","id":63027102},{"atb":[[1.12,139.51],[1.1,514.02]],"id":67532289},{"atl":[[3.6,19.77],[3.2,19.02]],"id":67532289},{"spn":1.9,"spf":"NaN","id":67532289}],"con":true,"img":false}]}
{"op":"mcm","clk":"11449708704","pt":1717313792416,"mc":[{"id":"1.229554901","rc":[{"atb":[[5.4,0]],"id":63027102}],"con":true,"img":false}]}
{"op":"mcm","clk":"11449708713","pt":1717313792513,"mc":[{"id":"1.229554901","rc":[{"atb":[[5.6,9.51]],"id":63027102}],"con":true,"img":false}]}
{"op":"mcm","clk":"11449711229","pt":1717313821229,"mc":[{"id":"1.229554901","rc":[{"atb":[[1.34,0]],"id":70003368},{"atb":[[1.3,0],[1.24,0]],"id":47208569},{"spn":37.8,"spf":"NaN","id":63027102}],"con":true,"img":false}]}
{"op":"mcm","clk":"11449711241","pt":1717313821334,"mc":[{"id":"1.229554901","rc":[{"atb":[[1.41,49.24]],"id":70003368},{"atb":[[1.27,253.74],[1.37,55.8]],"id":47208569}],"con":true,"img":false}]}
{"op":"mcm","clk":"11449712757","pt":1717313838144,"mc":[{"id":"1.229554901","rc":[{"atb":[[1.4,0],[1.5,0]],"id":70003368},{"atl":[[4.5,0]],"id":70003368},{"atb":[[1.36,0],[1.26,0]],"id":47208569},{"atl":[[3.75,0]],"id":47208569},{"atb":[[3.95,0],[4.9,0]],"id":63027102},{"atb":[[1.01,17.89]],"id":67532289},{"atl":[[2.68,0]],"id":67532289}],"con":true,"img":false}]}
{"op":"mcm","clk":"11449713492","pt":1717313846082,"mc":[{"id":"1.229554901","rc":[{"atb":[[1.41,0]],"id":70003368},{"atb":[[1.37,0]],"id":47208569}],"con":true,"img":false}]}
{"op":"mcm","clk":"11449713501","pt":1717313846180,"mc":[{"id":"1.229554901","rc":[{"atb":[[1.34,49.24]],"id":70003368},{"atb":[[1.3,55.8]],"id":47208569}],"con":true,"img":false}]}
{"op":"mcm","clk":"11449714402","pt":1717313856485,"mc":[{"id":"1.229554901","rc":[{"atb":[[1.48,48.39],[1.38,91.69]],"id":70003368},{"atl":[[4.4,0.15]],"id":70003368},{"atb":[[1.4,58.07],[1.3,171.95]],"id":47208569},{"atl":[[4,0.17]],"id":47208569},{"atb":[[5.1,5.66],[4.1,11.23]],"id":63027102},{"atb":[[1.01,5825.15]],"id":67532289},{"atl":[[2.66,0.31]],"id":67532289}],"con":true,"img":false}]}
{"op":"mcm","clk":"11449720878","pt":1717313930919,"mc":[{"id":"1.229554901","rc":[{"atb":[[1.49,34.16],[1.34,0]],"id":70003368},{"spn":2.94,"spf":"NaN","id":70003368},{"atb":[[1.3,116.14]],"id":47208569},{"spn":2.7,"spf":"NaN","id":47208569},{"spn":1.89,"spf":"NaN","id":67532289}],"con":true,"img":false}]}
{"op":"mcm","clk":"11449720892","pt":1717313931018,"mc":[{"id":"1.229554901","rc":[{"atb":[[1.31,55.8]],"id":47208569}],"con":true,"img":false}]}
{"op":"mcm","clk":"11449736707","pt":1717314096394,"mc":[{"id":"1.229554901","rc":[{"atb":[[5.1,0],[4.1,0]],"id":49183855},{"spn":32.5,"spf":"NaN","id":49183855}],"con":true,"img":false}]}
{"op":"mcm","clk":"11449738237","pt":1717314113455,"mc":[{"id":"1.229554901","rc":[{"atb":[[3.85,12.22],[4.7,6.27]],"id":49183855}],"con":true,"img":false}]}
{"op":"mcm","clk":"11449787058","pt":1717314666687,"mc":[{"id":"1.229554901","rc":[{"atb":[[1.48,0],[1.38,0]],"id":70003368},{"atl":[[4.4,0]],"id":70003368},{"spn":3.74,"spf":"NaN","id":70003368},{"atb":[[1.4,0],[1.3,0]],"id":47208569},{"atl":[[4,0]],"id":47208569},{"spn":3.35,"spf":"NaN","id":47208569},{"atb":[[5.1,0],[4.1,0]],"id":63027102},{"atb":[[1.01,17.89]],"id":67532289},{"atl":[[2.66,0]],"id":67532289},{"spn":2.16,"spf":"NaN","id":67532289}],"con":true,"img":false}]}
{"op":"mcm","clk":"11449787826","pt":1717314675381,"mc":[{"id":"1.229554901","rc":[{"atb":[[1.49,0],[1.34,49.24]],"id":70003368}],"con":true,"img":false}]}
{"op":"mcm","clk":"11449789010","pt":1717314687369,"mc":[{"id":"1.229554901","rc":[{"atb":[[1.46,50.49],[1.36,96.78]],"id":70003368},{"atl":[[4.3,0.15]],"id":70003368},{"atb":[[1.29,120.15],[1.39,59.56]],"id":47208569},{"atl":[[3.95,0.17]],"id":47208569},{"atb":[[5.1,5.66],[4.1,11.23]],"id":63027102},{"atb":[[1.01,5825.15]],"id":67532289},{"atl":[[2.66,0.31]],"id":67532289}],"con":true,"img":false}]}
{"op":"mcm","clk":"11449794396","pt":1717314750012,"mc":[{"id":"1.229554901","rc":[{"atb":[[1.34,0]],"id":70003368},{"spn":2.88,"spf":"NaN","id":70003368},{"atb":[[1.3,202.99]],"id":47208569},{"spn":2.67,"spf":"NaN","id":47208569},{"spn":1.89,"spf":"NaN","id":67532289}],"con":true,"img":false}]}
{"op":"mcm","clk":"11449794405","pt":1717314750118,"mc":[{"id":"1.229554901","rc":[{"atb":[[1.47,49.24]],"id":70003368},{"atb":[[1.27,0]],"id":47208569}],"con":true,"img":false}]}
{"op":"mcm","clk":"11449815418","pt":1717314992479,"mc":[{"id":"1.229554901","rc":[{"spn":2.88,"spf":"NaN","id":70003368},{"atb":[[3.85,0],[4.7,0]],"id":49183855}],"con":true,"img":false}]}
{"op":"mcm","clk":"11449815816","pt":1717314996682,"mc":[{"id":"1.229554901","rc":[{"atb":[[4.6,6.45],[3.8,12.44]],"id":49183855}],"con":true,"img":false}]}
{"op":"mcm","clk":"11449818718","pt":1717315028238,"mc":[{"id":"1.229554901","rc":[{"atl":[[990,0.17]],"id":70003368},{"atl":[[1000,0.17]],"id":47208569},{"atl":[[1000,0.17]],"id":49183855},{"atl":[[1000,0.17]],"id":63027102},{"atl":[[1000,0.17]],"id":67532289}],"con":true,"img":false}]}
{"op":"mcm","clk":"11449826327","pt":1717315108751,"mc":[{"id":"1.229554901","rc":[{"atb":[[1.01,81.8]],"id":70003368},{"atl":[[990,1.13]],"id":70003368},{"atb":[[1.03,103.11]],"id":47208569},{"atl":[[960,1.49]],"id":47208569},{"atb":[[1.01,153.38]],"id":49183855},{"atl":[[990,1.44]],"id":49183855},{"atb":[[1.03,104.81]],"id":63027102},{"atl":[[960,1.03]],"id":63027102},{"atb":[[1.02,108.22]],"id":67532289},{"atl":[[980,1.6]],"id":67532289}],"con":true,"img":false}]}
{"op":"mcm","clk":"11449836016","pt":1717315140186,"mc":[{"id":"1.229554901","rc":[{"atb":[[1.09,147.29]],"id":70003368},{"atl":[[2.54,8.37]],"id":70003368},{"atb":[[1.4,59.56]],"id":47208569},{"atl":[[5.6,9.69]],"id":47208569},{"atb":[[3.1,47.62]],"id":49183855},{"atl":[[55,2]],"id":49183855},{"atb":[[3.85,35.09]],"id":63027102},{"atl":[[100,2]],"id":63027102},{"atb":[[1.1,1028.04]],"id":67532289},{"atl":[[2.72,19.02]],"id":67532289}],"con":true,"img":false}]}
{"op":"mcm","clk":"11449836027","pt":1717315140287,"mc":[{"id":"1.229554901","rc":[{"atl":[[5.8,3.87]],"id":70003368},{"atl":[[5.6,13.75]],"id":47208569}],"con":true,"img":false}]}
{"op":"mcm","clk":"11449838061","pt":1717315162528,"mc":[{"id":"1.229554901","rc":[{"atl":[[60,2.61]],"id":49183855}],"con":true,"img":false}]}
{"op":"mcm","clk":"11449838073","pt":1717315162635,"mc":[{"id":"1.229554901","rc":[{"atl":[[50,2.61],[60,4.61]],"id":49183855}],"con":true,"img":false}]}
{"op":"mcm","clk":"11449838086","pt":1717315162738,"mc":[{"id":"1.229554901","rc":[{"atl":[[330,2],[55,0],[60,2.61]],"id":49183855}],"con":true,"img":false}]}
{"op":"mcm","clk":"11449838098","pt":1717315162843,"mc":[{"id":"1.229554901","rc":[{"atl":[[2.56,10.36]],"id":67532289}],"con":true,"img":false}]}
{"op":"mcm","clk":"11449838892","pt":1717315171340,"mc":[{"id":"1.229554901","rc":[{"spn":2.0,"spf":"NaN","id":70003368},{"spn":2.67,"spf":"NaN","id":47208569},{"atl":[[50,0]],"id":49183855},{"spn":1.84,"spf":"NaN","id":67532289}],"con":true,"img":false}]}
{"op":"mcm","clk":"11449838904","pt":1717315171440,"mc":[{"id":"1.229554901","rc":[{"atl":[[60,5.23]],"id":49183855}],"con":true,"img":false}]}
{"op":"mcm","clk":"11449839525","pt":1717315177348,"mc":[{"id":"1.229554901","rc":[{"atl":[[330,0],[55,2]],"id":49183855},{"atl":[[2.72,0],[2.54,10.36]],"id":67532289}],"con":true,"img":false}]}
{"op":"mcm","clk":"11449840818","pt":1717315190947,"mc":[{"id":"1.229554901","rc":[{"atl":[[6,0]],"id":47208569}],"con":true,"img":false}]}
{"op":"mcm","clk":"11449840830","pt":1717315191048,"mc":[{"id":"1.229554901","rc":[{"atl":[[5.5,12.03]],"id":47208569}],"con":true,"img":false}]}
{"op":"mcm","clk":"11449841541","pt":1717315198492,"mc":[{"id":"1.229554901","rc":[{"atl":[[5.6,9.69]],"id":47208569}],"con":true,"img":false}]}
{"op":"mcm","clk":"11449841570","pt":1717315198759,"mc":[{"id":"1.229554901","rc":[{"atl":[[5.6,12.08]],"id":47208569}],"con":true,"img":false}]}
{"op":"mcm","clk":"11449843249","pt":1717315213880,"mc":[{"id":"1.229554901","rc":[{"atl":[[2.56,0]],"id":67532289}],"con":true,"img":false}]}
{"op":"mcm","clk":"11449843263","pt":1717315213980,"mc":[{"id":"1.229554901","rc":[{"atl":[[2.72,19.02],[2.54,0]],"id":67532289}],"con":true,"img":false}]}
{"op":"mcm","clk":"11449843286","pt":1717315214181,"mc":[{"id":"1.229554901","rc":[{"atl":[[2.56,6.12]],"id":67532289}],"con":true,"img":false}]}
{"op":"mcm","clk":"11449844112","pt":1717315222207,"mc":[{"id":"1.229554901","rc":[{"atl":[[5.6,9.69]],"id":47208569}],"con":true,"img":false}]}
{"op":"mcm","clk":"11449844159","pt":1717315222622,"mc":[{"id":"1.229554901","rc":[{"atl":[[6,7.18]],"id":47208569}],"con":true,"img":false}]}
{"op":"mcm","clk":"11449844819","pt":1717315229092,"mc":[{"id":"1.229554901","rc":[{"atl":[[60,2.61]],"id":49183855}],"con":true,"img":false}]}
{"op":"mcm","clk":"11449844831","pt":1717315229194,"mc":[{"id":"1.229554901","rc":[{"atl":[[50,2.61],[60,4.61]],"id":49183855}],"con":true,"img":false}]}
{"op":"mcm","clk":"11449844841","pt":1717315229297,"mc":[{"id":"1.229554901","rc":[{"atl":[[55,0]],"id":49183855}],"con":true,"img":false}]}
{"op":"mcm","clk":"11449844943","pt":1717315230384,"mc":[{"id":"1.229554901","rc":[{"atl":[[5.8,0]],"id":70003368}],"con":true,"img":false}]}
{"op":"mcm","clk":"11449846456","pt":1717315247219,"mc":[{"id":"1.229554901","rc":[{"atl":[[6,0]],"id":47208569},{"spn":27.5,"spf":"NaN","id":49183855}],"con":true,"img":false}]}
{"op":"mcm","clk":"11449846502","pt":1717315247637,"mc":[{"id":"1.229554901","rc":[{"atl":[[5.6,11.34]],"id":47208569}],"con":true,"img":false}]}
{"op":"mcm","clk":"11449846853","pt":1717315250440,"mc":[{"id":"1.229554901","rc":[{"atl":[[2.72,0],[2.54,6.12]],"id":67532289}],"con":true,"img":false}]}
{"op":"mcm","clk":"11449848272","pt":1717315265466,"mc":[{"id":"1.229554901","rc":[{"atl":[[50,4.65],[60,2.61]],"id":49183855}],"con":true,"img":false}]}
{"op":"mcm","clk":"11449848282","pt":1717315265568,"mc":[{"id":"1.229554901","rc":[{"atl":[[60,4.61]],"id":49183855}],"con":true,"img":false}]}
{"op":"mcm","clk":"11449848294","pt":1717315265628,"mc":[{"id":"1.229554901","rc":[{"atl":[[50,2.61]],"id":49183855}],"con":true,"img":false}]}
{"op":"mcm","clk":"11449848306","pt":1717315265729,"mc":[{"id":"1.229554901","rc":[{"atl":[[50,4.65],[60,2.61]],"id":49183855}],"con":true,"img":false}]}
{"op":"mcm","clk":"11449848315","pt":1717315265832,"mc":[{"id":"1.229554901","rc":[{"atl":[[50,2.61],[60,4.61]],"id":49183855}],"con":true,"img":false}]}
{"op":"mcm","clk":"11449849425","pt":1717315277662,"mc":[{"id":"1.229554901","rc":[{"atl":[[2.56,0]],"id":67532289}],"con":true,"img":false}]}
{"op":"mcm","clk":"11449849447","pt":1717315277869,"mc":[{"id":"1.229554901","rc":[{"atl":[[2.56,4.23],[2.72,19.02],[2.54,0]],"id":67532289}],"con":true,"img":false}]}
{"op":"mcm","clk":"11449851204","pt":1717315295685,"mc":[{"id":"1.229554901","rc":[{"atb":[[1.46,0],[1.36,0]],"id":70003368},{"atl":[[4.3,0]],"id":70003368},{"atb":[[1.29,0],[1.39,0]],"id":47208569},{"atl":[[3.95,0]],"id":47208569},{"atb":[[5.1,0],[4.1,0]],"id":63027102},{"atb":[[1.01,17.89]],"id":67532289},{"atl":[[2.66,0]],"id":67532289}],"con":true,"img":false}]}
{"op":"mcm","clk":"11449851225","pt":1717315295887,"mc":[{"id":"1.229554901","rc":[{"atb":[[1.4,0],[1.32,119.12]],"id":47208569}],"con":true,"img":false}]}
{"op":"mcm","clk":"11449851799","pt":1717315301803,"mc":[{"id":"1.229554901","rc":[{"atl":[[50,4.65],[60,2.61]],"id":49183855}],"con":true,"img":false}]}
{"op":"mcm","clk":"11449852466","pt":1717315308917,"mc":[{"id":"1.229554901","rc":[{"atb":[[1.49,8]],"id":70003368},{"spn":2.01,"spf":"NaN","id":70003368},{"atb":[[1.33,11.89]],"id":47208569},{"spn":3.36,"spf":"NaN","id":47208569}],"con":true,"img":false}]}
{"op":"mcm","clk":"11449852479","pt":1717315309021,"mc":[{"id":"1.229554901","rc":[{"atb":[[1.32,0],[1.34,55.81]],"id":47208569}],"con":true,"img":false}]}
{"op":"mcm","clk":"11449852902","pt":1717315313629,"mc":[{"id":"1.229554901","rc":[{"atl":[[2.54,19.02]],"id":67532289}],"con":true,"img":false}]}
{"op":"mcm","clk":"11449852910","pt":1717315313739,"mc":[{"id":"1.229554901","rc":[{"atl":[[2.72,0]],"id":67532289}],"con":true,"img":false}]}
{"op":"mcm","clk":"11449852969","pt":1717315314199,"mc":[{"id":"1.229554901","rc":[{"atb":[[1.47,0]],"id":70003368},{"atb":[[1.25,243.8],[1.31,0]],"id":47208569}],"con":true,"img":false}]}
{"op":"mcm","clk":"11449852980","pt":1717315314301,"mc":[{"id":"1.229554901","rc":[{"atb":[[1.34,49.24]],"id":70003368},{"atb":[[1.35,55.8]],"id":47208569}],"con":true,"img":false}]}
{"op":"mcm","clk":"11449853607","pt":1717315320659,"mc":[{"id":"1.229554901","rc":[{"atb":[[1.43,54.02],[1.33,105.58]],"id":70003368},{"atl":[[4.1,0.16]],"id":70003368},{"atb":[[1.32,108.88],[1.42,55.3]],"id":47208569},{"atl":[[4.1,0.16]],"id":47208569},{"atb":[[4.8,6.11],[3.9,12.01]],"id":63027102},{"atb":[[1.01,5825.15]],"id":67532289},{"atl":[[2.7,0.3]],"id":67532289}],"con":true,"img":false}]}
{"op":"mcm","clk":"11449853960","pt":1717315323824,"mc":[{"id":"1.229554901","rc":[{"atb":[[1.33,0]],"id":47208569}],"con":true,"img":false}]}
{"op":"mcm","clk":"11449854020","pt":1717315324442,"mc":[{"id":"1.229554901","rc":[{"atb":[[1.44,8.91]],"id":47208569}],"con":true,"img":false}]}
{"op":"mcm","clk":"11449854805","pt":1717315332132,"mc":[{"id":"1.229554901","rc":[{"atb":[[1.25,0],[1.3,0]],"id":47208569}],"con":true,"img":false}]}
{"op":"mcm","clk":"11449855516","pt":1717315338841,"mc":[{"id":"1.229554901","rc":[{"atb":[[1.49,0]],"id":70003368},{"atb":[[1.44,0]],"id":47208569}],"con":true,"img":false}]}
{"op":"mcm","clk":"11449856135","pt":1717315344469,"mc":[{"id":"1.229554901","rc":[{"atb":[[1.43,55.81],[1.34,0]],"id":47208569}],"con":true,"img":false}]}
{"op":"mcm","clk":"11449856755","pt":1717315350445,"mc":[{"id":"1.229554901","rc":[{"atb":[[1.35,0]],"id":47208569}],"con":true,"img":false}]}
{"op":"mcm","clk":"11449856766","pt":1717315350550,"mc":[{"id":"1.229554901","rc":[{"atb":[[1.33,55.8]],"id":47208569}],"con":true,"img":false}]}
{"op":"mcm","clk":"11449857089","pt":1717315353552,"mc":[{"id":"1.229554901","rc":[{"atb":[[1.45,8.72]],"id":70003368},{"atb":[[1.45,8.72]],"id":47208569}],"con":true,"img":false}]}
{"op":"mcm","clk":"11449858574","pt":1717315368367,"mc":[{"id":"1.229554901","rc":[{"atb":[[1.34,0]],"id":70003368},{"atb":[[1.25,243.8]],"id":47208569}],"con":true,"img":false}]}
{"op":"mcm","clk":"11449858585","pt":1717315368522,"mc":[{"id":"1.229554901","rc":[{"atb":[[1.44,49.24]],"id":70003368}],"con":true,"img":false}]}
{"op":"mcm","clk":"11449858631","pt":1717315368986,"mc":[{"id":"1.229554901","rc":[{"atb":[[1.45,0]],"id":70003368},{"spn":1.99,"spf":"NaN","id":70003368},{"spn":2.77,"spf":"NaN","id":47208569},{"spn":1.83,"spf":"NaN","id":67532289}],"con":true,"img":false}]}
{"op":"mcm","clk":"11449858653","pt":1717315369190,"mc":[{"id":"1.229554901","rc":[{"atb":[[1.46,8.53]],"id":70003368}],"con":true,"img":false}]}
{"op":"mcm","clk":"11449859640","pt":1717315379512,"mc":[{"id":"1.229554901","rc":[{"atb":[[1.46,55.31]],"id":47208569}],"con":true,"img":false}]}
{"op":"mcm","clk":"11449859653","pt":1717315379615,"mc":[{"id":"1.229554901","rc":[{"atb":[[1.43,0]],"id":47208569}],"con":true,"img":false}]}
{"op":"mcm","clk":"11449860078","pt":1717315384114,"mc":[{"id":"1.229554901","rc":[{"atb":[[1.45,0]],"id":47208569}],"con":true,"img":false}]}
{"op":"mcm","clk":"11449860100","pt":1717315384321,"mc":[{"id":"1.229554901","rc":[{"atb":[[1.48,8.18]],"id":47208569}],"con":true,"img":false}]}
{"op":"mcm","clk":"11449860306","pt":1717315386595,"mc":[{"id":"1.229554901","rc":[{"atb":[[1.28,0],[1.34,184.68]],"id":70003368}],"con":true,"img":false}]}
{"op":"mcm","clk":"11449861421","pt":1717315398144,"mc":[{"id":"1.229554901","rc":[{"atb":[[1.33,68.71]],"id":47208569}],"con":true,"img":false}]}
{"op":"mcm","clk":"11449861453","pt":1717315398448,"mc":[{"id":"1.229554901","rc":[{"atb":[[1.35,12.17]],"id":70003368}],"con":true,"img":false}]}
{"op":"mcm","clk":"11449862791","pt":1717315411871,"mc":[{"id":"1.229554901","rc":[{"atb":[[4.6,0],[3.8,0]],"id":49183855}],"con":true,"img":false}]}
{"op":"mcm","clk":"11449863082","pt":1717315414373,"mc":[{"id":"1.229554901","rc":[{"atb":[[1.46,0],[1.49,55.31]],"id":47208569}],"con":true,"img":false}]}
{"op":"mcm","clk":"11449864595","pt":1717315429472,"mc":[{"id":"1.229554901","rc":[{"spn":2.0,"spf":"NaN","id":70003368},{"atb":[[1.48,0]],"id":47208569},{"spn":2.79,"spf":"NaN","id":47208569}],"con":true,"img":false}]}
{"op":"mcm","clk":"11449864604","pt":1717315429573,"mc":[{"id":"1.229554901","rc":[{"atb":[[1.43,110.62]],"id":47208569}],"con":true,"img":false}]}
{"op":"mcm","clk":"11449864613","pt":1717315429674,"mc":[{"id":"1.229554901","rc":[{"atb":[[1.49,0]],"id":47208569}],"con":true,"img":false}]}
{"op":"mcm","clk":"11449864651","pt":1717315429981,"mc":[{"id":"1.229554901","rc":[{"atb":[[1.51,7.7]],"id":47208569}],"con":true,"img":false}]}
{"op":"mcm","clk":"11449864662","pt":1717315430088,"mc":[{"id":"1.229554901","rc":[{"atb":[[1.43,0],[1.52,55.31]],"id":47208569}],"con":true,"img":false}]}
{"op":"mcm","clk":"11449865331","pt":1717315436507,"mc":[{"id":"1.229554901","rc":[{"atb":[[4.5,6.63],[3.75,12.67]],"id":49183855}],"con":true,"img":false}]}
{"op":"mcm","clk":"11449865431","pt":1717315437388,"mc":[{"id":"1.229554901","rc":[{"atb":[[1.33,55.8]],"id":47208569}],"con":true,"img":false}]}
{"op":"mcm","clk":"11449866218","pt":1717315444596,"mc":[{"id":"1.229554901","rc":[{"atb":[[1.51,0]],"id":47208569}],"con":true,"img":false}]}
{"op":"mcm","clk":"11449866238","pt":1717315444803,"mc":[{"id":"1.229554901","rc":[{"atb":[[1.43,110.62],[1.52,0]],"id":47208569}],"con":true,"img":false}]}
{"op":"mcm","clk":"11449866296","pt":1717315445371,"mc":[{"id":"1.229554901","rc":[{"atb":[[1.54,7.26]],"id":47208569}],"con":true,"img":false}]}
{"op":"mcm","clk":"11449869226","pt":1717315472855,"mc":[{"id":"1.229554901","rc":[{"atb":[[1.45,9.46]],"id":47208569}],"con":true,"img":false}]}
{"op":"mcm","clk":"11449869937","pt":1717315478903,"mc":[{"id":"1.229554901","rc":[{"atb":[[1.43,0],[1.55,9.47]],"id":47208569}],"con":true,"img":false}]}
{"op":"mcm","clk":"11449873449","pt":1717315513061,"mc":[{"id":"1.229554901","rc":[{"atb":[[1.45,0]],"id":47208569},{"spn":2.82,"spf":"NaN","id":47208569}],"con":true,"img":false}]}
{"op":"mcm","clk":"11449874254","pt":1717315519955,"mc":[{"id":"1.229554901","rc":[{"atb":[[1.54,0]],"id":47208569}],"con":true,"img":false}]}
{"op":"mcm","clk":"11449874267","pt":1717315520059,"mc":[{"id":"1.229554901","rc":[{"atb":[[1.43,55.81]],"id":47208569}],"con":true,"img":false}]}
{"op":"mcm","clk":"11449874276","pt":1717315520157,"mc":[{"id":"1.229554901","rc":[{"atb":[[1.55,0]],"id":47208569}],"con":true,"img":false}]}
{"op":"mcm","clk":"11449875747","pt":1717315534879,"mc":[{"id":"1.229554901","rc":[{"atb":[[1.45,8.72]],"id":47208569}],"con":true,"img":false}]}
{"op":"mcm","clk":"11449875759","pt":1717315534984,"mc":[{"id":"1.229554901","rc":[{"atb":[[1.46,55.31]],"id":47208569}],"con":true,"img":false}]}
{"op":"mcm","clk":"11449875771","pt":1717315535084,"mc":[{"id":"1.229554901","rc":[{"atb":[[1.43,0]],"id":47208569}],"con":true,"img":false}]}
{"op":"mcm","clk":"11449877179","pt":1717315549775,"mc":[{"id":"1.229554901","rc":[{"atb":[[1.45,0]],"id":47208569}],"con":true,"img":false}]}
{"op":"mcm","clk":"11449877197","pt":1717315549983,"mc":[{"id":"1.229554901","rc":[{"atb":[[1.46,0],[1.43,110.62],[1.48,8.18]],"id":47208569}],"con":true,"img":false}]}
{"op":"mcm","clk":"11449877712","pt":1717315555913,"mc":[{"id":"1.229554901","rc":[{"atb":[[1.45,9.46]],"id":47208569}],"con":true,"img":false}]}
{"op":"mcm","clk":"11449878880","pt":1717315568216,"mc":[{"id":"1.229554901","rc":[{"atb":[[1.43,0],[1.49,9.47]],"id":47208569}],"con":true,"img":false}]}
{"op":"mcm","clk":"11449880521","pt":1717315584003,"mc":[{"id":"1.229554901","rc":[{"atb":[[1.45,0]],"id":47208569},{"spn":2.79,"spf":"NaN","id":47208569}],"con":true,"img":false}]}
{"op":"mcm","clk":"11449884635","pt":1717315624191,"mc":[{"id":"1.229554901","rc":[{"atb":[[1.33,68.71]],"id":47208569}],"con":true,"img":false}]}
{"op":"mcm","clk":"11449884836","pt":1717315625759,"mc":[{"id":"1.229554901","rc":[{"atb":[[1.48,0]],"id":47208569}],"con":true,"img":false}]}
{"op":"mcm","clk":"11449884846","pt":1717315625857,"mc":[{"id":"1.229554901","rc":[{"atb":[[1.43,68.72]],"id":47208569}],"con":true,"img":false}]}
{"op":"mcm","clk":"11449884859","pt":1717315625967,"mc":[{"id":"1.229554901","rc":[{"atb":[[1.49,0]],"id":47208569}],"con":true,"img":false}]}
{"op":"mcm","clk":"11449885827","pt":1717315635569,"mc":[{"id":"1.229554901","rc":[{"atb":[[5.6,0]],"id":63027102}],"con":true,"img":false}]}
{"op":"mcm","clk":"11449885840","pt":1717315635666,"mc":[{"id":"1.229554901","rc":[{"atb":[[5.3,9.51]],"id":63027102}],"con":true,"img":false}]}
{"op":"mcm","clk":"11449886260","pt":1717315639880,"mc":[{"id":"1.229554901","rc":[{"atb":[[1.45,8.72]],"id":47208569}],"con":true,"img":false}]}
{"op":"mcm","clk":"11449886576","pt":1717315643026,"mc":[{"id":"1.229554901","rc":[{"atb":[[1.43,0],[1.33,0]],"id":70003368},{"atl":[[4.1,0]],"id":70003368},{"atb":[[1.32,0],[1.42,0]],"id":47208569},{"atl":[[4.1,0]],"id":47208569},{"atb":[[4.5,0],[3.75,0]],"id":49183855},{"atb":[[4.8,0],[3.9,0]],"id":63027102},{"atb":[[1.01,17.89]],"id":67532289},{"atl":[[2.7,0]],"id":67532289}],"con":true,"img":false}]}
{"op":"mcm","clk":"11449888108","pt":1717315658084,"mc":[{"id":"1.229554901","rc":[{"atb":[[1.46,68.72],[1.43,0]],"id":47208569},{"spn":3.43,"spf":"NaN","id":47208569},{"spn":37.65,"spf":"NaN","id":63027102}],"con":true,"img":false}]}
{"op":"mcm","clk":"11449888180","pt":1717315658804,"mc":[{"id":"1.229554901","rc":[{"atl":[[5.6,9.69]],"id":47208569}],"con":true,"img":false}]}
{"op":"mcm","clk":"11449888203","pt":1717315659011,"mc":[{"id":"1.229554901","rc":[{"atl":[[6,7.18]],"id":47208569}],"con":true,"img":false}]}
{"op":"mcm","clk":"11449888516","pt":1717315662234,"mc":[{"id":"1.229554901","rc":[{"atb":[[1.49,47.4],[1.39,89.34]],"id":70003368},{"atl":[[4.4,0.15]],"id":70003368},{"atb":[[1.43,54.02],[1.33,174.3]],"id":47208569},{"atl":[[4.1,0.16]],"id":47208569},{"atb":[[4.8,6.11],[3.9,12.01]],"id":49183855},{"atb":[[5.1,5.66],[4.1,11.23]],"id":63027102},{"atb":[[1.01,5825.15]],"id":67532289},{"atl":[[2.6,0.32]],"id":67532289}],"con":true,"img":false}]}
{"op":"mcm","clk":"11449888783","pt":1717315664822,"mc":[{"id":"1.229554901","rc":[{"atb":[[1.28,224.44],[1.34,0]],"id":70003368}],"con":true,"img":false}]}
{"op":"mcm","clk":"11449888830","pt":1717315665340,"mc":[{"id":"1.229554901","rc":[{"atl":[[6,0]],"id":47208569}],"con":true,"img":false}]}
{"op":"mcm","clk":"11449888877","pt":1717315665907,"mc":[{"id":"1.229554901","rc":[{"atl":[[5.7,7.18]],"id":47208569}],"con":true,"img":false}]}
{"op":"mcm","clk":"11449889100","pt":1717315668336,"mc":[{"id":"1.229554901","rc":[{"atb":[[1.35,0]],"id":70003368},{"atb":[[1.33,161.39]],"id":47208569}],"con":true,"img":false}]}
{"op":"mcm","clk":"11449889293","pt":1717315670244,"mc":[{"id":"1.229554901","rc":[{"atb":[[1.46,0]],"id":70003368},{"atb":[[1.45,0]],"id":47208569}],"con":true,"img":false}]}
{"op":"mcm","clk":"11449889314","pt":1717315670450,"mc":[{"id":"1.229554901","rc":[{"atb":[[1.46,0],[1.44,161.39]],"id":47208569}],"con":true,"img":false}]}
{"op":"mcm","clk":"11449889616","pt":1717315673821,"mc":[{"id":"1.229554901","rc":[{"atl":[[2.56,0]],"id":67532289}],"con":true,"img":false}]}
{"op":"mcm","clk":"11449889626","pt":1717315673927,"mc":[{"id":"1.229554901","rc":[{"atl":[[2.72,19.35]],"id":67532289}],"con":true,"img":false}]}
{"op":"mcm","clk":"11449889634","pt":1717315674038,"mc":[{"id":"1.229554901","rc":[{"atl":[[2.54,0]],"id":67532289}],"con":true,"img":false}]}
{"op":"mcm","clk":"11449889664","pt":1717315674341,"mc":[{"id":"1.229554901","rc":[{"atl":[[2.78,23.87]],"id":67532289}],"con":true,"img":false}]}
{"op":"mcm","clk":"11449890470","pt":1717315682049,"mc":[{"id":"1.229554901","rc":[{"atb":[[1.44,0]],"id":70003368}],"con":true,"img":false}]}
{"op":"mcm","clk":"11449890484","pt":1717315682161,"mc":[{"id":"1.229554901","rc":[{"atb":[[1.4,49.24]],"id":70003368}],"con":true,"img":false}]}
{"op":"mcm","clk":"11449890835","pt":1717315685536,"mc":[{"id":"1.229554901","rc":[{"atb":[[1.51,7.69]],"id":70003368},{"atb":[[1.46,8.53]],"id":47208569}],"con":true,"img":false}]}
{"op":"mcm","clk":"11449891316","pt":1717315690042,"mc":[{"id":"1.229554901","rc":[{"atb":[[1.44,0],[1.47,54.02]],"id":47208569}],"con":true,"img":false}]}
{"op":"mcm","clk":"11449892033","pt":1717315696875,"mc":[{"id":"1.229554901","rc":[{"atl":[[5.7,0]],"id":47208569}],"con":true,"img":false}]}
{"op":"mcm","clk":"11449892053","pt":1717315697083,"mc":[{"id":"1.229554901","rc":[{"atl":[[5.3,2.53]],"id":47208569},{"atl":[[2.78,0]],"id":67532289}],"con":true,"img":false}]}
{"op":"mcm","clk":"11449892400","pt":1717315700371,"mc":[{"id":"1.229554901","rc":[{"atb":[[1.46,0]],"id":47208569}],"con":true,"img":false}]}
{"op":"mcm","clk":"11449892413","pt":1717315700473,"mc":[{"id":"1.229554901","rc":[{"atb":[[1.44,161.39],[1.47,0]],"id":47208569}],"con":true,"img":false}]}
{"op":"mcm","clk":"11449892422","pt":1717315700573,"mc":[{"id":"1.229554901","rc":[{"atb":[[1.49,8]],"id":47208569},{"atl":[[2.64,5.83]],"id":67532289}],"con":true,"img":false}]}
{"op":"mcm","clk":"11449892440","pt":1717315700779,"mc":[{"id":"1.229554901","rc":[{"atl":[[2.62,19.02]],"id":67532289}],"con":true,"img":false}]}
{"op":"mcm","clk":"11449892452","pt":1717315700878,"mc":[{"id":"1.229554901","rc":[{"atl":[[2.72,0]],"id":67532289}],"con":true,"img":false}]}
{"op":"mcm","clk":"11449893089","pt":1717315706884,"mc":[{"id":"1.229554901","rc":[{"atb":[[1.46,9.26]],"id":47208569}],"con":true,"img":false}]}
{"op":"mcm","clk":"11449893125","pt":1717315707296,"mc":[{"id":"1.229554901","rc":[{"atb":[[1.41,10.39]],"id":70003368}],"con":true,"img":false}]}
{"op":"mcm","clk":"11449893610","pt":1717315712303,"mc":[{"id":"1.229554901","rc":[{"atb":[[1.49,0],[1.39,0]],"id":70003368},{"atl":[[4.4,0]],"id":70003368},{"atb":[[1.43,0],[1.33,55.8]],"id":47208569},{"atl":[[4.1,0]],"id":47208569},{"atb":[[5.1,0],[4.1,0]],"id":63027102},{"atb":[[1.01,17.89]],"id":67532289},{"atl":[[2.6,0]],"id":67532289}],"con":true,"img":false}]}
{"op":"mcm","clk":"11449894156","pt":1717315717359,"mc":[{"id":"1.229554901","rc":[{"atb":[[1.4,0]],"id":70003368}],"con":true,"img":false}]}
{"op":"mcm","clk":"11449894166","pt":1717315717463,"mc":[{"id":"1.229554901","rc":[{"atb":[[1.34,49.24]],"id":70003368}],"con":true,"img":false}]}
{"op":"mcm","clk":"11449895760","pt":1717315731943,"mc":[{"id":"1.229554901","rc":[{"spn":2.02,"spf":"NaN","id":70003368},{"atb":[[1.44,0],[1.5,9.26]],"id":47208569},{"spn":3.4,"spf":"NaN","id":47208569},{"spn":1.87,"spf":"NaN","id":67532289}],"con":true,"img":false}]}
{"op":"mcm","clk":"11449896887","pt":1717315742884,"mc":[{"id":"1.229554901","rc":[{"atb":[[1.46,50.49],[1.36,96.78]],"id":70003368},{"atl":[[4.3,0.15]],"id":70003368},{"atb":[[1.32,108.88],[1.42,55.3]],"id":47208569},{"atl":[[4.1,0.16]],"id":47208569},{"atb":[[4,11.61],[5,5.8]],"id":63027102},{"atb":[[1.01,5825.15]],"id":67532289},{"atl":[[2.68,0.31]],"id":67532289}],"con":true,"img":false}]}
{"op":"mcm","clk":"11449897185","pt":1717315745173,"mc":[{"id":"1.229554901","rc":[{"atb":[[1.41,0]],"id":70003368},{"atb":[[1.46,0]],"id":47208569}],"con":true,"img":false}]}
{"op":"mcm","clk":"11449897226","pt":1717315745690,"mc":[{"id":"1.229554901","rc":[{"atb":[[1.51,0]],"id":70003368},{"atb":[[1.49,0]],"id":47208569}],"con":true,"img":false}]}
{"op":"mcm","clk":"11449897252","pt":1717315745850,"mc":[{"id":"1.229554901","rc":[{"atb":[[1.43,55.81],[1.5,0]],"id":47208569}],"con":true,"img":false}]}
{"op":"mcm","clk":"11449897970","pt":1717315752665,"mc":[{"id":"1.229554901","rc":[{"atl":[[3.2,0]],"id":67532289}],"con":true,"img":false}]}
{"op":"mcm","clk":"11449897980","pt":1717315752772,"mc":[{"id":"1.229554901","rc":[{"atl":[[2.6,19.02]],"id":67532289}],"con":true,"img":false}]}
{"op":"mcm","clk":"11449897988","pt":1717315752874,"mc":[{"id":"1.229554901","rc":[{"atl":[[2.58,19.02]],"id":67532289}],"con":true,"img":false}]}
{"op":"mcm","clk":"11449897999","pt":1717315752978,"mc":[{"id":"1.229554901","rc":[{"atl":[[2.62,0]],"id":67532289}],"con":true,"img":false}]}
{"op":"mcm","clk":"11449898171","pt":1717315754493,"mc":[{"id":"1.229554901","rc":[{"atl":[[2.54,0],[2.44,8.37]],"id":70003368},{"atl":[[5.6,0],[5.3,12.04]],"id":47208569},{"atb":[[4,44.94],[3.85,0]],"id":63027102},{"atl":[[95,2],[100,0]],"id":63027102},{"atb":[[1.11,909.09],[1.1,514.02]],"id":67532289}],"con":true,"img":false}]}
{"op":"mcm","clk":"11449898298","pt":1717315755689,"mc":[{"id":"1.229554901","rc":[{"atl":[[2.42,8.37],[2.44,0]],"id":70003368}],"con":true,"img":false}]}
{"op":"mcm","clk":"11449898777","pt":1717315760306,"mc":[{"id":"1.229554901","rc":[{"atb":[[1.45,8.72]],"id":47208569}],"con":true,"img":false}]}
{"op":"mcm","clk":"11449898785","pt":1717315760404,"mc":[{"id":"1.229554901","rc":[{"atb":[[1.48,8.18]],"id":70003368}],"con":true,"img":false}]}
{"op":"mcm","clk":"11449899078","pt":1717315763209,"mc":[{"id":"1.229554901","rc":[{"atb":[[1.46,55.31],[1.43,0]],"id":47208569}],"con":true,"img":false}]}
{"op":"mcm","clk":"11449900417","pt":1717315775907,"mc":[{"id":"1.229554901","rc":[{"atb":[[1.45,0]],"id":47208569}],"con":true,"img":false}]}
{"op":"mcm","clk":"11449900428","pt":1717315776003,"mc":[{"id":"1.229554901","rc":[{"atb":[[1.43,110.62]],"id":47208569}],"con":true,"img":false}]}
{"op":"mcm","clk":"11449900439","pt":1717315776108,"mc":[{"id":"1.229554901","rc":[{"atb":[[1.46,0]],"id":47208569}],"con":true,"img":false}]}
{"op":"mcm","clk":"11449900488","pt":1717315776628,"mc":[{"id":"1.229554901","rc":[{"atb":[[1.48,8.18]],"id":47208569}],"con":true,"img":false}]}
{"op":"mcm","clk":"11449901592","pt":1717315787533,"mc":[{"id":"1.229554901","rc":[{"atb":[[1.34,0]],"id":70003368}],"con":true,"img":false}]}
{"op":"mcm","clk":"11449901602","pt":1717315787643,"mc":[{"id":"1.229554901","rc":[{"atb":[[1.37,49.24]],"id":70003368}],"con":true,"img":false}]}
{"op":"mcm","clk":"11449902334","pt":1717315794759,"mc":[{"id":"1.229554901","rc":[{"spn":1.95,"spf":"NaN","id":70003368},{"atb":[[1.45,9.46]],"id":47208569},{"spn":2.79,"spf":"NaN","id":47208569},{"spn":1.85,"spf":"NaN","id":67532289}],"con":true,"img":false}]}
{"op":"mcm","clk":"11449902361","pt":1717315795022,"mc":[{"id":"1.229554901","rc":[{"atb":[[1.37,60.75]],"id":70003368}],"con":true,"img":false}]}
{"op":"mcm","clk":"11449903249","pt":1717315803868,"mc":[{"id":"1.229554901","rc":[{"atl":[[5.4,0]],"id":47208569},{"atl":[[2.56,26.82],[2.6,0]],"id":67532289}],"con":true,"img":false}]}
{"op":"mcm","clk":"11449903261","pt":1717315803968,"mc":[{"id":"1.229554901","rc":[{"atl":[[5.2,9.51]],"id":47208569},{"atl":[[2.54,19.02],[2.58,0]],"id":67532289}],"con":true,"img":false}]}
{"op":"mcm","clk":"11449903572","pt":1717315806745,"mc":[{"id":"1.229554901","rc":[{"atb":[[1.43,0],[1.49,9.47]],"id":47208569}],"con":true,"img":false}]}
{"op":"mcm","clk":"11449905364","pt":1717315824772,"mc":[{"id":"1.229554901","rc":[{"atl":[[5.5,0],[5.2,24.16]],"id":47208569},{"atb":[[1.1,0]],"id":67532289}],"con":true,"img":false}]}
{"op":"mcm","clk":"11449905378","pt":1717315824872,"mc":[{"id":"1.229554901","rc":[{"atb":[[1.12,653.53]],"id":67532289}],"con":true,"img":false}]}
{"op":"mcm","clk":"11449907015","pt":1717315841132,"mc":[{"id":"1.229554901","rc":[{"atb":[[1.37,11.51]],"id":70003368}],"con":true,"img":false}]}
{"op":"mcm","clk":"11449907024","pt":1717315841184,"mc":[{"id":"1.229554901","rc":[{"atb":[[1.47,49.24]],"id":70003368}],"con":true,"img":false}]}
{"op":"mcm","clk":"11449907249","pt":1717315843465,"mc":[{"id":"1.229554901","rc":[{"atb":[[1.45,0]],"id":47208569}],"con":true,"img":false}]}
{"op":"mcm","clk":"11449907390","pt":1717315844700,"mc":[{"id":"1.229554901","rc":[{"atl":[[2.42,0],[2.38,8.37]],"id":70003368},{"atl":[[90,2],[95,0]],"id":63027102}],"con":true,"img":false}]}
{"op":"mcm","clk":"11449908035","pt":1717315850814,"mc":[{"id":"1.229554901","rc":[{"atb":[[1.48,0]],"id":70003368}],"con":true,"img":false}]}
{"op":"mcm","clk":"11449908086","pt":1717315851334,"mc":[{"id":"1.229554901","rc":[{"atb":[[1.49,8.01]],"id":70003368}],"con":true,"img":false}]}
{"op":"mcm","clk":"11449908844","pt":1717315858413,"mc":[{"id":"1.229554901","rc":[{"spn":1.93,"spf":"NaN","id":70003368},{"atb":[[1.48,0]],"id":47208569},{"spn":2.79,"spf":"NaN","id":47208569},{"spn":1.83,"spf":"NaN","id":67532289}],"con":true,"img":false}]}
{"op":"mcm","clk":"11449908852","pt":1717315858512,"mc":[{"id":"1.229554901","rc":[{"atb":[[1.43,55.81],[1.49,0]],"id":47208569}],"con":true,"img":false}]}
{"op":"mcm","clk":"11449909187","pt":1717315861717,"mc":[{"id":"1.229554901","rc":[{"atb":[[1.47,0]],"id":70003368},{"atl":[[2.56,0]],"id":67532289}],"con":true,"img":false}]}
{"op":"mcm","clk":"11449909200","pt":1717315861822,"mc":[{"id":"1.229554901","rc":[{"atb":[[1.37,60.75]],"id":70003368},{"atl":[[2.56,38.04],[2.54,0],[2.52,26.82]],"id":67532289}],"con":true,"img":false}]}
{"op":"mcm","clk":"11449909661","pt":1717315865865,"mc":[{"id":"1.229554901","rc":[{"atb":[[1.45,8.72]],"id":47208569}],"con":true,"img":false}]}
{"op":"mcm","clk":"11449910107","pt":1717315870234,"mc":[{"id":"1.229554901","rc":[{"atb":[[4.8,0],[3.9,0]],"id":49183855}],"con":true,"img":false}]}
{"op":"mcm","clk":"11449910729","pt":1717315875760,"mc":[{"id":"1.229554901","rc":[{"atl":[[2.38,0],[2.48,16.74]],"id":70003368},{"atl":[[90,0],[100,2]],"id":63027102},{"atb":[[1.11,0],[1.1,1000]],"id":67532289}],"con":true,"img":false}]}
{"op":"mcm","clk":"11449910952","pt":1717315877766,"mc":[{"id":"1.229554901","rc":[{"atb":[[1.12,139.51]],"id":67532289},{"atl":[[2.52,0]],"id":67532289}],"con":true,"img":false}]}
{"op":"mcm","clk":"11449910962","pt":1717315877847,"mc":[{"id":"1.229554901","rc":[{"atb":[[1.11,514.02]],"id":67532289},{"atl":[[2.54,26.82]],"id":67532289}],"con":true,"img":false}]}
{"op":"mcm","clk":"11449910971","pt":1717315877949,"mc":[{"id":"1.229554901","rc":[{"atl":[[2.56,0],[2.62,61.73]],"id":67532289}],"con":true,"img":false}]}
{"op":"mcm","clk":"11449911487","pt":1717315882863,"mc":[{"id":"1.229554901","rc":[{"atl":[[2.54,33.48]],"id":70003368}],"con":true,"img":false}]}
{"op":"mcm","clk":"11449911497","pt":1717315882966,"mc":[{"id":"1.229554901","rc":[{"atl":[[2.48,0]],"id":70003368}],"con":true,"img":false}]}
{"op":"mcm","clk":"11449912084","pt":1717315888566,"mc":[{"id":"1.229554901","rc":[{"atb":[[1.46,55.31]],"id":47208569}],"con":true,"img":false}]}
{"op":"mcm","clk":"11449912099","pt":1717315888682,"mc":[{"id":"1.229554901","rc":[{"atb":[[1.43,0]],"id":47208569}],"con":true,"img":false}]}
{"op":"mcm","clk":"11449912440","pt":1717315891767,"mc":[{"id":"1.229554901","rc":[{"atl":[[2.52,26.83],[2.62,0]],"id":67532289}],"con":true,"img":false}]}
{"op":"mcm","clk":"11449912796","pt":1717315894975,"mc":[{"id":"1.229554901","rc":[{"atb":[[4.8,6.11],[3.9,12.01]],"id":49183855}],"con":true,"img":false}]}
{"op":"mcm","clk":"11449912942","pt":1717315896298,"mc":[{"id":"1.229554901","rc":[{"atb":[[1.45,0]],"id":47208569}],"con":true,"img":false}]}
{"op":"mcm","clk":"11449912962","pt":1717315896457,"mc":[{"id":"1.229554901","rc":[{"atb":[[1.46,0],[1.43,110.62]],"id":47208569}],"con":true,"img":false}]}
{"op":"mcm","clk":"11449916643","pt":1717315931523,"mc":[{"id":"1.229554901","rc":[{"atl":[[6,0]],"id":70003368},{"spn":2.01,"spf":"NaN","id":70003368},{"spn":2.76,"spf":"NaN","id":47208569},{"atl":[[2.54,0]],"id":67532289},{"spn":1.82,"spf":"NaN","id":67532289}],"con":true,"img":false}]}
{"op":"mcm","clk":"11449916654","pt":1717315931617,"mc":[{"id":"1.229554901","rc":[{"atl":[[5.2,8.37]],"id":70003368},{"atl":[[2.5,26.82],[2.62,53.66]],"id":67532289}],"con":true,"img":false}]}
{"op":"mcm","clk":"11449916665","pt":1717315931722,"mc":[{"id":"1.229554901","rc":[{"atl":[[2.52,0],[2.62,0],[2.48,26.83]],"id":67532289}],"con":true,"img":false}]}
{"op":"mcm","clk":"11449917463","pt":1717315939342,"mc":[{"id":"1.229554901","rc":[{"atb":[[1.49,0]],"id":70003368}],"con":true,"img":false}]}
{"op":"mcm","clk":"11449917691","pt":1717315941624,"mc":[{"id":"1.229554901","rc":[{"atl":[[5.3,9.51]],"id":47208569}],"con":true,"img":false}]}
{"op":"mcm","clk":"11449917723","pt":1717315942036,"mc":[{"id":"1.229554901","rc":[{"atl":[[5.7,7.18]],"id":47208569}],"con":true,"img":false}]}
{"op":"mcm","clk":"11449920986","pt":1717315972869,"mc":[{"id":"1.229554901","rc":[{"atl":[[2.64,0]],"id":67532289}],"con":true,"img":false}]}
{"op":"mcm","clk":"11449922631","pt":1717315987431,"mc":[{"id":"1.229554901","rc":[{"atl":[[70,0]],"id":63027102},{"atl":[[2.5,0]],"id":67532289}],"con":true,"img":false}]}
{"op":"mcm","clk":"11449922641","pt":1717315987483,"mc":[{"id":"1.229554901","rc":[{"atl":[[65,2.61]],"id":63027102},{"atl":[[3.1,26.82]],"id":67532289}],"con":true,"img":false}]}
{"op":"mcm","clk":"11449922650","pt":1717315987585,"mc":[{"id":"1.229554901","rc":[{"atl":[[2.72,27.14],[2.48,0]],"id":67532289}],"con":true,"img":false}]}
{"op":"mcm","clk":"11449922679","pt":1717315987898,"mc":[{"id":"1.229554901","rc":[{"atl":[[2.78,23.87]],"id":67532289}],"con":true,"img":false}]}
{"op":"mcm","clk":"11449924175","pt":1717316002908,"mc":[{"id":"1.229554901","rc":[{"spn":2.0,"spf":"NaN","id":70003368},{"atl":[[5.2,9.51]],"id":47208569},{"spn":35.15,"spf":"NaN","id":63027102},{"spn":1.9,"spf":"NaN","id":67532289}],"con":true,"img":false}]}
{"op":"mcm","clk":"11449924186","pt":1717316003005,"mc":[{"id":"1.229554901","rc":[{"atl":[[5.6,14.64]],"id":47208569}],"con":true,"img":false}]}
{"op":"mcm","clk":"11449927554","pt":1717316037886,"mc":[{"id":"1.229554901","rc":[{"atl":[[3.1,0]],"id":67532289}],"con":true,"img":false}]}
{"op":"mcm","clk":"11449927563","pt":1717316037989,"mc":[{"id":"1.229554901","rc":[{"atl":[[2.7,26.82]],"id":67532289}],"con":true,"img":false}]}
{"op":"mcm","clk":"11449927574","pt":1717316038050,"mc":[{"id":"1.229554901","rc":[{"atl":[[2.72,0],[2.68,27.14]],"id":67532289}],"con":true,"img":false}]}
{"op":"mcm","clk":"11449931932","pt":1717316084548,"mc":[{"id":"1.229554901","rc":[{"atb":[[1.46,0],[1.36,0]],"id":70003368},{"atl":[[4.3,0]],"id":70003368},{"spn":1.95,"spf":"NaN","id":70003368},{"atb":[[1.32,0],[1.42,0]],"id":47208569},{"atl":[[4.1,0]],"id":47208569},{"spn":3.31,"spf":"NaN","id":47208569},{"atb":[[4,33.33],[5,0]],"id":63027102},{"atb":[[1.01,17.89]],"id":67532289},{"atl":[[2.68,26.83]],"id":67532289}],"con":true,"img":false}]}
{"op":"mcm","clk":"11449931943","pt":1717316084654,"mc":[{"id":"1.229554901","rc":[{"atb":[[1.34,221.24]],"id":47208569},{"atl":[[5.6,33.66]],"id":47208569}],"con":true,"img":false}]}
{"op":"mcm","clk":"11449931951","pt":1717316084709,"mc":[{"id":"1.229554901","rc":[{"atb":[[1.43,0]],"id":47208569},{"atl":[[5.3,0]],"id":47208569}],"con":true,"img":false}]}
{"op":"mcm","clk":"11449932189","pt":1717316087151,"mc":[{"id":"1.229554901","rc":[{"atl":[[2.74,57.47]],"id":70003368}],"con":true,"img":false}]}
{"op":"mcm","clk":"11449932194","pt":1717316087204,"mc":[{"id":"1.229554901","rc":[{"atl":[[2.54,0]],"id":70003368}],"con":true,"img":false}]}
{"op":"mcm","clk":"11449932438","pt":1717316089750,"mc":[{"id":"1.229554901","rc":[{"atl":[[6,19.02]],"id":47208569}],"con":true,"img":false}]}
{"op":"mcm","clk":"11449932447","pt":1717316089803,"mc":[{"id":"1.229554901","rc":[{"atl":[[5.6,14.64]],"id":47208569}],"con":true,"img":false}]}
{"op":"mcm","clk":"11449932879","pt":1717316094554,"mc":[{"id":"1.229554901","rc":[{"atl":[[2.7,0]],"id":67532289}],"con":true,"img":false}]}
{"op":"mcm","clk":"11449932890","pt":1717316094655,"mc":[{"id":"1.229554901","rc":[{"atl":[[2.66,26.82],[2.68,0],[2.76,53.66]],"id":67532289}],"con":true,"img":false}]}
{"op":"mcm","clk":"11449932898","pt":1717316094708,"mc":[{"id":"1.229554901","rc":[{"atl":[[2.64,26.83]],"id":67532289}],"con":true,"img":false}]}
{"op":"mcm","clk":"11449932905","pt":1717316094863,"mc":[{"id":"1.229554901","rc":[{"atl":[[2.76,0]],"id":67532289}],"con":true,"img":false}]}
{"op":"mcm","clk":"11449933162","pt":1717316098221,"mc":[{"id":"1.229554901","rc":[{"atb":[[1.45,51.62],[1.35,99.55]],"id":70003368},{"atl":[[4.2,0.16]],"id":70003368},{"atb":[[1.45,51.62],[1.35,99.55]],"id":47208569},{"atl":[[4.2,0.16]],"id":47208569},{"atb":[[4.3,10.55],[5.3,14.91]],"id":63027102},{"atb":[[1.01,5825.15]],"id":67532289},{"atl":[[2.6,0.32]],"id":67532289}],"con":true,"img":false}]}
{"op":"mcm","clk":"11449933972","pt":1717316106836,"mc":[{"id":"1.229554901","rc":[{"atb":[[1.47,8.35]],"id":70003368},{"atb":[[1.47,8.35]],"id":47208569}],"con":true,"img":false}]}
{"op":"mcm","clk":"11449934387","pt":1717316111545,"mc":[{"id":"1.229554901","rc":[{"atl":[[2.54,8.37],[2.74,0]],"id":70003368}],"con":true,"img":false}]}
{"op":"mcm","clk":"11449934412","pt":1717316111857,"mc":[{"id":"1.229554901","rc":[{"atl":[[5.2,0]],"id":70003368},{"atb":[[1.33,0]],"id":47208569}],"con":true,"img":false}]}
{"op":"mcm","clk":"11449934419","pt":1717316111958,"mc":[{"id":"1.229554901","rc":[{"atl":[[5.8,8.37]],"id":70003368},{"atb":[[1.35,155.36]],"id":47208569}],"con":true,"img":false}]}
{"op":"mcm","clk":"11449934464","pt":1717316112382,"mc":[{"id":"1.229554901","rc":[{"atb":[[1.48,51.62],[1.34,0]],"id":47208569}],"con":true,"img":false}]}
{"op":"mcm","clk":"11449934570","pt":1717316113366,"mc":[{"id":"1.229554901","rc":[{"atl":[[2.78,0]],"id":67532289}],"con":true,"img":false}]}
{"op":"mcm","clk":"11449934587","pt":1717316113575,"mc":[{"id":"1.229554901","rc":[{"atl":[[5.7,0]],"id":47208569},{"atl":[[2.64,32.66]],"id":67532289}],"con":true,"img":false}]}
{"op":"mcm","clk":"11449934758","pt":1717316115589,"mc":[{"id":"1.229554901","rc":[{"atl":[[5.3,2.53]],"id":47208569}],"con":true,"img":false}]}
{"op":"mcm","clk":"11449934876","pt":1717316116893,"mc":[{"id":"1.229554901","rc":[{"atl":[[2.54,0],[2.44,8.37]],"id":70003368},{"atl":[[95,2],[100,0]],"id":63027102},{"atb":[[1.09,1111.11],[1.1,0]],"id":67532289},{"atl":[[2.56,26.83],[2.64,5.83]],"id":67532289}],"con":true,"img":false}]}
{"op":"mcm","clk":"11449934922","pt":1717316117357,"mc":[{"id":"1.229554901","rc":[{"atl":[[6,0],[5.4,14.65]],"id":47208569}],"con":true,"img":false}]}
{"op":"mcm","clk":"11449935328","pt":1717316121857,"mc":[{"id":"1.229554901","rc":[{"atb":[[1.47,0]],"id":47208569}],"con":true,"img":false}]}
{"op":"mcm","clk":"11449935340","pt":1717316121961,"mc":[{"id":"1.229554901","rc":[{"atb":[[1.46,155.36],[1.48,0]],"id":47208569}],"con":true,"img":false}]}
{"op":"mcm","clk":"11449935351","pt":1717316122064,"mc":[{"id":"1.229554901","rc":[{"atb":[[1.5,7.85]],"id":47208569}],"con":true,"img":false}]}
{"op":"mcm","clk":"11449935357","pt":1717316122171,"mc":[{"id":"1.229554901","rc":[{"atb":[[1.51,51.62]],"id":47208569}],"con":true,"img":false}]}
{"op":"mcm","clk":"11449935367","pt":1717316122270,"mc":[{"id":"1.229554901","rc":[{"atb":[[1.46,0]],"id":47208569}],"con":true,"img":false}]}
{"op":"mcm","clk":"11449935648","pt":1717316125172,"mc":[{"id":"1.229554901","rc":[{"atb":[[1.37,49.24]],"id":70003368}],"con":true,"img":false}]}
{"op":"mcm","clk":"11449935656","pt":1717316125277,"mc":[{"id":"1.229554901","rc":[{"atb":[[1.36,11.83]],"id":47208569}],"con":true,"img":false}]}
{"op":"mcm","clk":"11449936694","pt":1717316136520,"mc":[{"id":"1.229554901","rc":[{"atb":[[1.5,0]],"id":47208569}],"con":true,"img":false}]}
{"op":"mcm","clk":"11449936702","pt":1717316136575,"mc":[{"id":"1.229554901","rc":[{"atb":[[1.46,103.24],[1.51,0]],"id":47208569}],"con":true,"img":false}]}
{"op":"mcm","clk":"11449936713","pt":1717316136729,"mc":[{"id":"1.229554901","rc":[{"atb":[[1.53,7.4]],"id":47208569}],"con":true,"img":false}]}
{"op":"mcm","clk":"11449937403","pt":1717316144197,"mc":[{"id":"1.229554901","rc":[{"atb":[[1.11,1028.04],[1.09,0]],"id":67532289}],"con":true,"img":false}]}
{"op":"mcm","clk":"11449937573","pt":1717316146012,"mc":[{"id":"1.229554901","rc":[{"atb":[[1.37,0]],"id":70003368},{"atb":[[1.35,99.55]],"id":47208569},{"spn":2.86,"spf":"NaN","id":47208569},{"atl":[[2.66,0]],"id":67532289},{"spn":1.84,"spf":"NaN","id":67532289}],"con":true,"img":false}]}
{"op":"mcm","clk":"11449937582","pt":1717316146122,"mc":[{"id":"1.229554901","rc":[{"atb":[[1.46,49.24]],"id":70003368},{"atb":[[1.36,67.64]],"id":47208569},{"atl":[[2.54,26.82]],"id":67532289}],"con":true,"img":false}]}
{"op":"mcm","clk":"11449937597","pt":1717316146328,"mc":[{"id":"1.229554901","rc":[{"atl":[[2.56,0],[2.52,26.83]],"id":67532289}],"con":true,"img":false}]}
{"op":"mcm","clk":"11449938092","pt":1717316151656,"mc":[{"id":"1.229554901","rc":[{"atb":[[1.47,0]],"id":70003368}],"con":true,"img":false}]}
{"op":"mcm","clk":"11449938126","pt":1717316152021,"mc":[{"id":"1.229554901","rc":[{"atb":[[1.48,8.18]],"id":70003368}],"con":true,"img":false}]}
{"op":"mcm","clk":"11449939230","pt":1717316163712,"mc":[{"id":"1.229554901","rc":[{"atb":[[1.54,51.62]],"id":47208569}],"con":true,"img":false}]}
{"op":"mcm","clk":"11449939238","pt":1717316163866,"mc":[{"id":"1.229554901","rc":[{"atb":[[1.46,0]],"id":47208569}],"con":true,"img":false}]}
{"op":"mcm","clk":"11449939483","pt":1717316166608,"mc":[{"id":"1.229554901","rc":[{"atb":[[1.53,0]],"id":47208569}],"con":true,"img":false}]}
{"op":"mcm","clk":"11449939492","pt":1717316166708,"mc":[{"id":"1.229554901","rc":[{"atb":[[1.46,103.24]],"id":47208569}],"con":true,"img":false}]}
{"op":"mcm","clk":"11449939500","pt":1717316166817,"mc":[{"id":"1.229554901","rc":[{"atb":[[1.54,0]],"id":47208569}],"con":true,"img":false}]}
{"op":"mcm","clk":"11449939507","pt":1717316166968,"mc":[{"id":"1.229554901","rc":[{"atb":[[1.36,11.83]],"id":70003368}],"con":true,"img":false}]}
{"op":"mcm","clk":"11449939546","pt":1717316167327,"mc":[{"id":"1.229554901","rc":[{"atb":[[1.56,7]],"id":47208569}],"con":true,"img":false}]}
{"op":"mcm","clk":"11449940949","pt":1717316181453,"mc":[{"id":"1.229554901","rc":[{"atl":[[5.6,0]],"id":47208569}],"con":true,"img":false}]}
{"op":"mcm","clk":"11449940954","pt":1717316181556,"mc":[{"id":"1.229554901","rc":[{"atl":[[5.3,17.17]],"id":47208569}],"con":true,"img":false}]}
{"op":"mcm","clk":"11449942078","pt":1717316193596,"mc":[{"id":"1.229554901","rc":[{"atb":[[1.46,0],[1.57,51.62]],"id":47208569}],"con":true,"img":false}]}
{"op":"mcm","clk":"11449942397","pt":1717316197070,"mc":[{"id":"1.229554901","rc":[{"atb":[[1.56,0]],"id":47208569}],"con":true,"img":false}]}
{"op":"mcm","clk":"11449942407","pt":1717316197175,"mc":[{"id":"1.229554901","rc":[{"atb":[[1.46,103.24],[1.57,0]],"id":47208569}],"con":true,"img":false}]}
{"op":"mcm","clk":"11449942422","pt":1717316197383,"mc":[{"id":"1.229554901","rc":[{"atb":[[1.59,6.64]],"id":47208569}],"con":true,"img":false}]}
{"op":"mcm","clk":"11449942910","pt":1717316203005,"mc":[{"id":"1.229554901","rc":[{"atl":[[2.54,0]],"id":67532289}],"con":true,"img":false}]}
{"op":"mcm","clk":"11449942918","pt":1717316203058,"mc":[{"id":"1.229554901","rc":[{"atl":[[2.56,53.66],[2.5,26.82]],"id":67532289}],"con":true,"img":false}]}
{"op":"mcm","clk":"11449942926","pt":1717316203163,"mc":[{"id":"1.229554901","rc":[{"atl":[[2.52,0],[2.48,26.83]],"id":67532289}],"con":true,"img":false}]}
{"op":"mcm","clk":"11449942933","pt":1717316203267,"mc":[{"id":"1.229554901","rc":[{"atl":[[2.56,0]],"id":67532289}],"con":true,"img":false}]}
{"op":"mcm","clk":"11449943290","pt":1717316207007,"mc":[{"id":"1.229554901","rc":[{"spn":1.96,"spf":"NaN","id":70003368},{"atb":[[1.36,55.8]],"id":47208569},{"spn":2.89,"spf":"NaN","id":47208569},{"spn":1.8,"spf":"NaN","id":67532289}],"con":true,"img":false}]}
{"op":"mcm","clk":"11449944766","pt":1717316223725,"mc":[{"id":"1.229554901","rc":[{"atb":[[1.46,0],[1.6,51.62]],"id":47208569}],"con":true,"img":false}]}
{"op":"mcm","clk":"11449945100","pt":1717316227301,"mc":[{"id":"1.229554901","rc":[{"atb":[[1.59,0]],"id":47208569}],"con":true,"img":false}]}
{"op":"mcm","clk":"11449945118","pt":1717316227509,"mc":[{"id":"1.229554901","rc":[{"atb":[[1.46,103.24],[1.6,0],[1.62,6.32]],"id":47208569}],"con":true,"img":false}]}
{"op":"mcm","clk":"11449945965","pt":1717316236761,"mc":[{"id":"1.229554901","rc":[{"atb":[[4.8,0],[3.9,0]],"id":49183855}],"con":true,"img":false}]}
{"op":"mcm","clk":"11449946565","pt":1717316242618,"mc":[{"id":"1.229554901","rc":[{"atb":[[1.48,8.87]],"id":47208569}],"con":true,"img":false}]}
{"op":"mcm","clk":"11449947620","pt":1717316253762,"mc":[{"id":"1.229554901","rc":[{"atb":[[1.46,0],[1.62,15.2]],"id":47208569}],"con":true,"img":false}]}
{"op":"mcm","clk":"11449947626","pt":1717316253865,"mc":[{"id":"1.229554901","rc":[{"atb":[[1.62,6.32],[1.49,51.62]],"id":47208569}],"con":true,"img":false}]}
{"op":"mcm","clk":"11449948111","pt":1717316259617,"mc":[{"id":"1.229554901","rc":[{"atb":[[4,11.61],[5,16.27]],"id":49183855}],"con":true,"img":false}]}
{"op":"mcm","clk":"11449949667","pt":1717316279016,"mc":[{"id":"1.229554901","rc":[{"atb":[[1.48,0]],"id":47208569},{"spn":2.91,"spf":"NaN","id":47208569}],"con":true,"img":false}]}
{"op":"mcm","clk":"11449949676","pt":1717316279118,"mc":[{"id":"1.229554901","rc":[{"atb":[[1.62,57.94],[1.49,0]],"id":47208569}],"con":true,"img":false}]}
{"op":"mcm","clk":"11449950305","pt":1717316287406,"mc":[{"id":"1.229554901","rc":[{"atb":[[1.62,51.62]],"id":47208569}],"con":true,"img":false}]}
{"op":"mcm","clk":"11449950321","pt":1717316287611,"mc":[{"id":"1.229554901","rc":[{"atb":[[1.46,103.24],[1.62,0]],"id":47208569}],"con":true,"img":false}]}
{"op":"mcm","clk":"11449950342","pt":1717316287823,"mc":[{"id":"1.229554901","rc":[{"atb":[[1.64,6.13]],"id":47208569}],"con":true,"img":false}]}
{"op":"mcm","clk":"11449951836","pt":1717316304832,"mc":[{"id":"1.229554901","rc":[{"atb":[[1.46,0],[1.62,55.81]],"id":47208569}],"con":true,"img":false}]}
{"op":"mcm","clk":"11449952414","pt":1717316311249,"mc":[{"id":"1.229554901","rc":[{"atb":[[1.09,0],[1.49,49.24]],"id":70003368},{"atl":[[2.44,0],[5.7,8.53]],"id":70003368},{"atb":[[1.62,0],[1.29,111.62]],"id":47208569},{"atl":[[5.1,14.65],[5.4,0]],"id":47208569},{"atb":[[3.1,0],[2.78,56.18]],"id":49183855},{"atb":[[3.55,39.22]],"id":63027102},{"atl":[[65,4.61],[95,0]],"id":63027102},{"atb":[[1.11,514.02],[1.06,1666.67]],"id":67532289},{"atl":[[1.98,26.83]],"id":67532289}],"con":true,"img":false}]}
{"op":"mcm","clk":"11449952422","pt":1717316311347,"mc":[{"id":"1.229554901","rc":[{"atb":[[4,0]],"id":63027102},{"atl":[[2.48,0]],"id":67532289}],"con":true,"img":false}]}
{"op":"mcm","clk":"11449952435","pt":1717316311442,"mc":[{"id":"1.229554901","rc":[{"atl":[[5.6,4.06]],"id":70003368}],"con":true,"img":false}]}
{"op":"mcm","clk":"11449952461","pt":1717316311753,"mc":[{"id":"1.229554901","rc":[{"atl":[[5.3,14.64]],"id":47208569}],"con":true,"img":false}]}
{"op":"mcm","clk":"11449952484","pt":1717316312055,"mc":[{"id":"1.229554901","rc":[{"atl":[[5.7,7.18]],"id":47208569}],"con":true,"img":false}]}
{"op":"mcm","clk":"11449953259","pt":1717316321040,"mc":[{"id":"1.229554901","rc":[{"atb":[[1.48,0]],"id":70003368}],"con":true,"img":false}]}
{"op":"mcm","clk":"11449953270","pt":1717316321146,"mc":[{"id":"1.229554901","rc":[{"atb":[[1.49,0],[1.47,98.48]],"id":70003368}],"con":true,"img":false}]}
{"op":"mcm","clk":"11449953278","pt":1717316321245,"mc":[{"id":"1.229554901","rc":[{"atb":[[1.51,7.7]],"id":70003368}],"con":true,"img":false}]}
{"op":"mcm","clk":"11449953698","pt":1717316325955,"mc":[{"id":"1.229554901","rc":[{"atl":[[2.5,0]],"id":67532289}],"con":true,"img":false}]}
{"op":"mcm","clk":"11449953702","pt":1717316326066,"mc":[{"id":"1.229554901","rc":[{"atl":[[3.1,26.82]],"id":67532289}],"con":true,"img":false}]}
{"op":"mcm","clk":"11449953761","pt":1717316326940,"mc":[{"id":"1.229554901","rc":[{"atb":[[1.36,67.64]],"id":47208569}],"con":true,"img":false}]}
{"op":"mcm","clk":"11449953790","pt":1717316327243,"mc":[{"id":"1.229554901","rc":[{"atb":[[1.36,0]],"id":70003368}],"con":true,"img":false}]}
{"op":"mcm","clk":"11449954777","pt":1717316339868,"mc":[{"id":"1.229554901","rc":[{"atl":[[5.6,0]],"id":70003368},{"spn":2.85,"spf":"NaN","id":70003368},{"spn":2.92,"spf":"NaN","id":47208569},{"spn":1.55,"spf":"NaN","id":67532289}],"con":true,"img":false}]}
{"op":"mcm","clk":"11449954808","pt":1717316340182,"mc":[{"id":"1.229554901","rc":[{"atl":[[5.6,2.39]],"id":70003368}],"con":true,"img":false}]}
{"op":"mcm","clk":"11449954928","pt":1717316341475,"mc":[{"id":"1.229554901","rc":[{"atl":[[5.3,0]],"id":47208569}],"con":true,"img":false}]}
{"op":"mcm","clk":"11449954935","pt":1717316341584,"mc":[{"id":"1.229554901","rc":[{"atl":[[5.9,14.64]],"id":47208569}],"con":true,"img":false}]}
{"op":"mcm","clk":"11449955306","pt":1717316346479,"mc":[{"id":"1.229554901","rc":[{"atb":[[1.47,0],[1.52,49.24]],"id":70003368}],"con":true,"img":false}]}
{"op":"mcm","clk":"11449955657","pt":1717316351193,"mc":[{"id":"1.229554901","rc":[{"atb":[[1.64,0]],"id":47208569}],"con":true,"img":false}]}
{"op":"mcm","clk":"11449955690","pt":1717316351910,"mc":[{"id":"1.229554901","rc":[{"atl":[[2.64,0]],"id":67532289}],"con":true,"img":false}]}
{"op":"mcm","clk":"11449956087","pt":1717316357226,"mc":[{"id":"1.229554901","rc":[{"atb":[[1.48,34.88]],"id":70003368}],"con":true,"img":false}]}
{"op":"mcm","clk":"11449956090","pt":1717316357329,"mc":[{"id":"1.229554901","rc":[{"atb":[[1.46,0]],"id":70003368},{"atl":[[5.2,0]],"id":47208569}],"con":true,"img":false}]}
{"op":"mcm","clk":"11449956100","pt":1717316357436,"mc":[{"id":"1.229554901","rc":[{"atl":[[5.6,14.81],[5,9.51]],"id":47208569}],"con":true,"img":false}]}
{"op":"mcm","clk":"11449956106","pt":1717316357538,"mc":[{"id":"1.229554901","rc":[{"atl":[[5.1,0]],"id":47208569}],"con":true,"img":false}]}
{"op":"mcm","clk":"11449956635","pt":1717316364342,"mc":[{"id":"1.229554901","rc":[{"atl":[[5.7,0]],"id":47208569}],"con":true,"img":false}]}
{"op":"mcm","clk":"11449956653","pt":1717316364548,"mc":[{"id":"1.229554901","rc":[{"atb":[[1.36,11.83]],"id":70003368}],"con":true,"img":false}]}
{"op":"mcm","clk":"11449956662","pt":1717316364652,"mc":[{"id":"1.229554901","rc":[{"atl":[[5.3,1.75]],"id":47208569}],"con":true,"img":false}]}
{"op":"mcm","clk":"11449956841","pt":1717316367126,"mc":[{"id":"1.229554901","rc":[{"atb":[[1.51,0]],"id":70003368}],"con":true,"img":false}]}
{"op":"mcm","clk":"11449956850","pt":1717316367231,"mc":[{"id":"1.229554901","rc":[{"atb":[[1.49,98.48],[1.52,0]],"id":70003368},{"atb":[[1.47,8.35]],"id":47208569}],"con":true,"img":false}]}
{"op":"mcm","clk":"11449956868","pt":1717316367433,"mc":[{"id":"1.229554901","rc":[{"atb":[[1.54,7.26]],"id":70003368}],"con":true,"img":false}]}
{"op":"mcm","clk":"11449957189","pt":1717316371556,"mc":[{"id":"1.229554901","rc":[{"atb":[[1.55,34.88],[1.49,0]],"id":70003368}],"con":true,"img":false}]}
{"op":"mcm","clk":"11449957314","pt":1717316373050,"mc":[{"id":"1.229554901","rc":[{"atl":[[1.98,0],[1.97,26.83]],"id":67532289}],"con":true,"img":false}]}
{"op":"mcm","clk":"11449957501","pt":1717316375372,"mc":[{"id":"1.229554901","rc":[{"atb":[[1.48,0]],"id":70003368},{"atl":[[5.6,15.99],[6.6,0]],"id":70003368},{"atb":[[1.25,0],[1.3,202.99]],"id":47208569},{"atl":[[75,0]],"id":63027102}],"con":true,"img":false}]}
{"op":"mcm","clk":"11449957510","pt":1717316375471,"mc":[{"id":"1.229554901","rc":[{"atb":[[1.46,34.88]],"id":70003368},{"atl":[[60,2.61]],"id":63027102}],"con":true,"img":false}]}
{"op":"mcm","clk":"11449957675","pt":1717316378145,"mc":[{"id":"1.229554901","rc":[{"atb":[[1.47,0]],"id":47208569}],"con":true,"img":false}]}
{"op":"mcm","clk":"11449957837","pt":1717316380266,"mc":[{"id":"1.229554901","rc":[{"atl":[[5.6,2.39]],"id":70003368}],"con":true,"img":false}]}
{"op":"mcm","clk":"11449957849","pt":1717316380373,"mc":[{"id":"1.229554901","rc":[{"atl":[[6.4,13.6]],"id":70003368}],"con":true,"img":false}]}
{"op":"mcm","clk":"11449957916","pt":1717316381247,"mc":[{"id":"1.229554901","rc":[{"atb":[[1.47,8.35]],"id":47208569}],"con":true,"img":false}]}
{"op":"mcm","clk":"11449957986","pt":1717316382391,"mc":[{"id":"1.229554901","rc":[{"atl":[[5.6,0],[4.9,9.51]],"id":47208569}],"con":true,"img":false}]}
{"op":"mcm","clk":"11449960816","pt":1717316417533,"mc":[{"id":"1.229554901","rc":[{"spn":2.87,"spf":"NaN","id":70003368},{"spn":2.83,"spf":"NaN","id":47208569},{"spn":32.65,"spf":"NaN","id":63027102},{"atl":[[1.97,0],[1.93,26.83]],"id":67532289},{"spn":1.52,"spf":"NaN","id":67532289}],"con":true,"img":false}]}
{"op":"mcm","clk":"11449962072","pt":1717316432666,"mc":[{"id":"1.229554901","rc":[{"atb":[[2.54,64.94],[2.78,0]],"id":49183855},{"atb":[[3.55,0],[2.96,51.02]],"id":63027102},{"atl":[[1.92,26.83],[1.93,0]],"id":67532289}],"con":true,"img":false}]}
{"op":"mcm","clk":"11449962080","pt":1717316432769,"mc":[{"id":"1.229554901","rc":[{"atl":[[1.91,26.83]],"id":67532289}],"con":true,"img":false}]}
{"op":"mcm","clk":"11449962086","pt":1717316432823,"mc":[{"id":"1.229554901","rc":[{"atb":[[2.54,0],[2.86,53.76]],"id":49183855},{"atl":[[1.92,0]],"id":67532289}],"con":true,"img":false}]}
{"op":"mcm","clk":"11449962633","pt":1717316439656,"mc":[{"id":"1.229554901","rc":[{"atb":[[3.05,2.07]],"id":63027102}],"con":true,"img":false}]}
{"op":"mcm","clk":"11449962743","pt":1717316441051,"mc":[{"id":"1.229554901","rc":[{"atb":[[1.54,0]],"id":70003368}],"con":true,"img":false}]}
{"op":"mcm","clk":"11449962750","pt":1717316441151,"mc":[{"id":"1.229554901","rc":[{"atb":[[1.47,69.76]],"id":70003368}],"con":true,"img":false}]}
{"op":"mcm","clk":"11449962758","pt":1717316441256,"mc":[{"id":"1.229554901","rc":[{"atb":[[1.55,0]],"id":70003368}],"con":true,"img":false}]}
{"op":"mcm","clk":"11449962775","pt":1717316441464,"mc":[{"id":"1.229554901","rc":[{"atb":[[1.47,78.11]],"id":70003368}],"con":true,"img":false}]}
{"op":"mcm","clk":"11449963324","pt":1717316448645,"mc":[{"id":"1.229554901","rc":[{"atl":[[6.4,0]],"id":70003368}],"con":true,"img":false}]}
{"op":"mcm","clk":"11449963331","pt":1717316448797,"mc":[{"id":"1.229554901","rc":[{"atl":[[5.6,15.99]],"id":70003368}],"con":true,"img":false}]}
{"op":"mcm","clk":"11449963627","pt":1717316452879,"mc":[{"id":"1.229554901","rc":[{"atl":[[1.92,53.66]],"id":67532289}],"con":true,"img":false}]}
{"op":"mcm","clk":"11449963636","pt":1717316452985,"mc":[{"id":"1.229554901","rc":[{"atl":[[1.91,0]],"id":67532289}],"con":true,"img":false}]}
{"op":"mcm","clk":"11449963825","pt":1717316455778,"mc":[{"id":"1.229554901","rc":[{"atb":[[1.47,69.76]],"id":70003368}],"con":true,"img":false}]}
{"op":"mcm","clk":"11449963837","pt":1717316455984,"mc":[{"id":"1.229554901","rc":[{"atb":[[1.49,8.01]],"id":70003368}],"con":true,"img":false}]}
{"op":"mcm","clk":"11449963844","pt":1717316456092,"mc":[{"id":"1.229554901","rc":[{"atb":[[1.5,34.88],[1.47,0]],"id":70003368}],"con":true,"img":false}]}
{"op":"mcm","clk":"11449963908","pt":1717316456859,"mc":[{"id":"1.229554901","rc":[{"atb":[[2.96,0],[3.65,37.74]],"id":63027102}],"con":true,"img":false}]}
{"op":"mcm","clk":"11449963983","pt":1717316457993,"mc":[{"id":"1.229554901","rc":[{"atl":[[1.92,0],[1.93,107.32]],"id":67532289}],"con":true,"img":false}]}
{"op":"mcm","clk":"11449964595","pt":1717316466375,"mc":[{"id":"1.229554901","rc":[{"atb":[[1.46,0]],"id":70003368},{"atl":[[5.6,2.39]],"id":70003368}],"con":true,"img":false}]}
{"op":"mcm","clk":"11449964601","pt":1717316466489,"mc":[{"id":"1.229554901","rc":[{"atb":[[1.48,34.88]],"id":70003368},{"atl":[[6.4,13.6]],"id":70003368}],"con":true,"img":false}]}
{"op":"mcm","clk":"11449964723","pt":1717316468086,"mc":[{"id":"1.229554901","rc":[{"atb":[[1.21,167.2],[1.29,0]],"id":47208569},{"atl":[[4.9,0],[4.4,9.51]],"id":47208569},{"atb":[[5.1,16.27],[2.86,0]],"id":49183855},{"atl":[[160,2],[50,2.61]],"id":49183855},{"atb":[[3.65,0],[5.4,14.92]],"id":63027102},{"atl":[[65,2.61],[400,2]],"id":63027102},{"atb":[[1.06,0]],"id":67532289}],"con":true,"img":false}]}
{"op":"mcm","clk":"11449964735","pt":1717316468188,"mc":[{"id":"1.229554901","rc":[{"atl":[[4.4,0],[3.75,9.51]],"id":47208569},{"atb":[[1.04,2500]],"id":67532289}],"con":true,"img":false}]}
{"op":"mcm","clk":"11449965037","pt":1717316472174,"mc":[{"id":"1.229554901","rc":[{"atb":[[3.05,0]],"id":63027102}],"con":true,"img":false}]}
{"op":"mcm","clk":"11449965406","pt":1717316476925,"mc":[{"id":"1.229554901","rc":[{"atl":[[1.93,0],[1.76,26.83]],"id":67532289}],"con":true,"img":false}]}
{"op":"mcm","clk":"11449965740","pt":1717316481697,"mc":[{"id":"1.229554901","rc":[{"atb":[[1.48,0]],"id":70003368},{"spn":2.85,"spf":"NaN","id":70003368},{"atb":[[1.25,243.8],[1.3,0]],"id":47208569},{"spn":2.61,"spf":"NaN","id":47208569},{"spn":27.55,"spf":"NaN","id":49183855},{"atl":[[60,0]],"id":63027102},{"spn":35.2,"spf":"NaN","id":63027102},{"spn":1.44,"spf":"NaN","id":67532289}],"con":true,"img":false}]}
{"op":"mcm","clk":"11449965745","pt":1717316481801,"mc":[{"id":"1.229554901","rc":[{"atb":[[1.46,34.88]],"id":70003368},{"atl":[[70,2.61]],"id":63027102}],"con":true,"img":false}]}
{"op":"mcm","clk":"11449966463","pt":1717316492135,"mc":[{"id":"1.229554901","rc":[{"atb":[[1.45,0],[1.35,0]],"id":70003368},{"atl":[[4.2,0]],"id":70003368},{"atb":[[1.45,0],[1.35,0]],"id":47208569},{"atl":[[4.2,0]],"id":47208569},{"atb":[[4.3,0],[5.3,9.51]],"id":63027102},{"atb":[[1.01,17.89]],"id":67532289},{"atl":[[2.6,0]],"id":67532289}],"con":true,"img":false}]}
{"op":"mcm","clk":"11449967417","pt":1717316505340,"mc":[{"id":"1.229554901","rc":[{"atb":[[1.46,0]],"id":70003368},{"atb":[[1.36,11.83]],"id":47208569}],"con":true,"img":false}]}
{"op":"mcm","clk":"11449967426","pt":1717316505392,"mc":[{"id":"1.229554901","rc":[{"atb":[[1.37,34.88]],"id":70003368},{"atb":[[1.3,55.8]],"id":47208569}],"con":true,"img":false}]}
{"op":"mcm","clk":"11449967684","pt":1717316509520,"mc":[{"id":"1.229554901","rc":[{"atb":[[1.36,0]],"id":70003368},{"atb":[[1.36,0]],"id":47208569}],"con":true,"img":false}]}
{"op":"mcm","clk":"11449967759","pt":1717316510810,"mc":[{"id":"1.229554901","rc":[{"atb":[[1.49,0]],"id":70003368},{"atb":[[1.47,0]],"id":47208569}],"con":true,"img":false}]}
{"op":"mcm","clk":"11449967769","pt":1717316510916,"mc":[{"id":"1.229554901","rc":[{"atb":[[1.49,47.4],[1.39,89.34]],"id":70003368},{"atl":[[4.4,0.15]],"id":70003368},{"atb":[[1.41,56.65],[1.31,112.39]],"id":47208569},{"atl":[[4.1,0.16]],"id":47208569},{"atb":[[5.2,5.52],[4.2,10.88]],"id":63027102},{"atb":[[1.01,5825.15]],"id":67532289},{"atl":[[2.6,0.32]],"id":67532289}],"con":true,"img":false}]}
{"op":"mcm","clk":"11449967777","pt":1717316511023,"mc":[{"id":"1.229554901","rc":[{"atb":[[1.5,0],[1.38,69.76]],"id":70003368}],"con":true,"img":false}]}
{"op":"mcm","clk":"11449967809","pt":1717316511537,"mc":[{"id":"1.229554901","rc":[{"atl":[[4.5,9.68],[3.75,0]],"id":47208569},{"atb":[[5.1,0],[4.6,27.78]],"id":49183855},{"atl":[[160,0],[120,2]],"id":49183855},{"atb":[[1.04,0]],"id":67532289},{"atl":[[2,53.66],[1.76,0]],"id":67532289}],"con":true,"img":false}]}
{"op":"mcm","clk":"11449967821","pt":1717316511747,"mc":[{"id":"1.229554901","rc":[{"atl":[[4.5,0],[3.8,9.51]],"id":47208569},{"atb":[[5.1,19.36],[4.6,0]],"id":49183855},{"atl":[[2,0],[1.94,26.83]],"id":67532289}],"con":true,"img":false}]}
{"op":"mcm","clk":"11449968097","pt":1717316516145,"mc":[{"id":"1.229554901","rc":[{"atb":[[1.34,117.17]],"id":70003368}],"con":true,"img":false}]}
{"op":"mcm","clk":"11449968106","pt":1717316516246,"mc":[{"id":"1.229554901","rc":[{"atb":[[1.38,0]],"id":70003368}],"con":true,"img":false}]}
{"op":"mcm","clk":"11449968130","pt":1717316516547,"mc":[{"id":"1.229554901","rc":[{"atb":[[1.51,7.69]],"id":70003368},{"atb":[[1.43,9.13]],"id":47208569}],"con":true,"img":false}]}
{"op":"mcm","clk":"11449968251","pt":1717316518818,"mc":[{"id":"1.229554901","rc":[{"atl":[[3.8,0],[3.25,9.51]],"id":47208569},{"atl":[[90,2],[120,0]],"id":49183855},{"atl":[[290,2],[400,0]],"id":63027102},{"atl":[[1.86,26.83],[1.94,0]],"id":67532289}],"con":true,"img":false}]}
{"op":"mcm","clk":"11449968340","pt":1717316520220,"mc":[{"id":"1.229554901","rc":[{"atb":[[5,5.8]],"id":49183855},{"atb":[[5.3,0]],"id":63027102}],"con":true,"img":false}]}
{"op":"mcm","clk":"11449968349","pt":1717316520322,"mc":[{"id":"1.229554901","rc":[{"atb":[[5.2,10.46]],"id":49183855},{"atb":[[5.5,9.51],[5.3,23.26],[5.4,0]],"id":63027102}],"con":true,"img":false}]}
{"op":"mcm","clk":"11449968389","pt":1717316520840,"mc":[{"id":"1.229554901","rc":[{"atl":[[6.4,0]],"id":70003368}],"con":true,"img":false}]}
{"op":"mcm","clk":"11449968400","pt":1717316520954,"mc":[{"id":"1.229554901","rc":[{"atl":[[5.6,15.99]],"id":70003368}],"con":true,"img":false}]}
{"op":"mcm","clk":"11449969376","pt":1717316535347,"mc":[{"id":"1.229554901","rc":[{"atb":[[1.37,0]],"id":70003368}],"con":true,"img":false}]}
{"op":"mcm","clk":"11449969383","pt":1717316535450,"mc":[{"id":"1.229554901","rc":[{"atb":[[1.4,34.88]],"id":70003368}],"con":true,"img":false}]}
{"op":"mcm","clk":"11449969913","pt":1717316543661,"mc":[{"id":"1.229554901","rc":[{"spn":2.95,"spf":"NaN","id":70003368},{"spn":2.34,"spf":"NaN","id":47208569},{"spn":27.6,"spf":"NaN","id":49183855},{"atb":[[5.6,9.51],[5.3,0]],"id":63027102},{"spn":35.3,"spf":"NaN","id":63027102},{"spn":1.49,"spf":"NaN","id":67532289}],"con":true,"img":false}]}
{"op":"mcm","clk":"11449970356","pt":1717316550379,"mc":[{"id":"1.229554901","rc":[{"atb":[[1.3,0]],"id":47208569}],"con":true,"img":false}]}
{"op":"mcm","clk":"11449970362","pt":1717316550479,"mc":[{"id":"1.229554901","rc":[{"atb":[[1.32,55.8]],"id":47208569}],"con":true,"img":false}]}
{"op":"mcm","clk":"11449970473","pt":1717316552247,"mc":[{"id":"1.229554901","rc":[{"atb":[[1.32,69.11]],"id":47208569}],"con":true,"img":false}]}
{"op":"mcm","clk":"11449970493","pt":1717316552561,"mc":[{"id":"1.229554901","rc":[{"atb":[[1.41,10.39]],"id":70003368}],"con":true,"img":false}]}
{"op":"mcm","clk":"11449972453","pt":1717316582601,"mc":[{"id":"1.229554901","rc":[{"atb":[[5.5,0]],"id":63027102}],"con":true,"img":false}]}
{"op":"mcm","clk":"11449972458","pt":1717316582706,"mc":[{"id":"1.229554901","rc":[{"atb":[[5.6,0],[5.3,19.02],[5.7,9.51]],"id":63027102}],"con":true,"img":false}]}
{"op":"mcm","clk":"11449972463","pt":1717316582805,"mc":[{"id":"1.229554901","rc":[{"atb":[[5.8,9.51]],"id":63027102}],"con":true,"img":false}]}
{"op":"mcm","clk":"11449972472","pt":1717316582910,"mc":[{"id":"1.229554901","rc":[{"atb":[[5.3,0]],"id":63027102}],"con":true,"img":false}]}
{"op":"mcm","clk":"11449975118","pt":1717316620256,"mc":[{"id":"1.229554901","rc":[{"atb":[[4,0],[5,0]],"id":49183855},{"spn":35.4,"spf":"NaN","id":63027102}],"con":true,"img":false}]}
{"op":"mcm","clk":"11449975973","pt":1717316631590,"mc":[{"id":"1.229554901","rc":[{"atl":[[3.25,0],[4.2,9.68]],"id":47208569},{"atb":[[5.1,0],[4.7,27.03]],"id":49183855},{"atl":[[90,0],[120,2]],"id":49183855},{"atl":[[290,0],[400,2]],"id":63027102},{"atl":[[1.98,53.66],[1.86,0]],"id":67532289}],"con":true,"img":false}]}
{"op":"mcm","clk":"11449977005","pt":1717316646006,"mc":[{"id":"1.229554901","rc":[{"atb":[[4.6,6.45],[3.8,12.44]],"id":49183855}],"con":true,"img":false}]}
{"op":"mcm","clk":"11449977617","pt":1717316653520,"mc":[{"id":"1.229554901","rc":[{"atb":[[5.2,0]],"id":49183855},{"atb":[[5.7,0]],"id":63027102}],"con":true,"img":false}]}
{"op":"mcm","clk":"11449977624","pt":1717316653625,"mc":[{"id":"1.229554901","rc":[{"atb":[[5,10.46]],"id":49183855},{"atb":[[5.8,0],[5.3,19.02],[5.9,9.51]],"id":63027102}],"con":true,"img":false}]}
{"op":"mcm","clk":"11449978731","pt":1717316667546,"mc":[{"id":"1.229554901","rc":[{"atb":[[5.9,0]],"id":63027102}],"con":true,"img":false}]}
{"op":"mcm","clk":"11449978738","pt":1717316667624,"mc":[{"id":"1.229554901","rc":[{"atb":[[5.4,9.51]],"id":63027102}],"con":true,"img":false}]}
{"op":"mcm","clk":"11449979324","pt":1717316675639,"mc":[{"id":"1.229554901","rc":[{"atb":[[5.3,0],[5.5,9.51]],"id":63027102}],"con":true,"img":false}]}
{"op":"mcm","clk":"11449980465","pt":1717316692365,"mc":[{"id":"1.229554901","rc":[{"spn":2.76,"spf":"NaN","id":47208569},{"atb":[[4.2,0]],"id":49183855},{"spn":27.5,"spf":"NaN","id":49183855},{"spn":35.25,"spf":"NaN","id":63027102},{"atl":[[3.1,0]],"id":67532289},{"spn":1.55,"spf":"NaN","id":67532289}],"con":true,"img":false}]}
{"op":"mcm","clk":"11449980475","pt":1717316692467,"mc":[{"id":"1.229554901","rc":[{"atb":[[4.8,19.35]],"id":49183855},{"atl":[[2.86,26.82]],"id":67532289}],"con":true,"img":false}]}
{"op":"mcm","clk":"11449982484","pt":1717316720866,"mc":[{"id":"1.229554901","rc":[{"atb":[[5.4,0]],"id":63027102}],"con":true,"img":false}]}
{"op":"mcm","clk":"11449982488","pt":1717316720970,"mc":[{"id":"1.229554901","rc":[{"atb":[[5.6,9.51],[5.3,19.02]],"id":63027102}],"con":true,"img":false}]}
{"op":"mcm","clk":"11449982493","pt":1717316721071,"mc":[{"id":"1.229554901","rc":[{"atb":[[5.5,0],[5.7,9.51]],"id":63027102}],"con":true,"img":false}]}
{"op":"mcm","clk":"11449982501","pt":1717316721174,"mc":[{"id":"1.229554901","rc":[{"atb":[[5.3,0]],"id":63027102}],"con":true,"img":false}]}
{"op":"mcm","clk":"11449989711","pt":1717316821198,"mc":[{"id":"1.229554901","rc":[{"atb":[[5.6,0]],"id":63027102},{"spn":35.35,"spf":"NaN","id":63027102}],"con":true,"img":false}]}
{"op":"mcm","clk":"11449989718","pt":1717316821307,"mc":[{"id":"1.229554901","rc":[{"atb":[[5.8,9.51],[5.3,19.02],[5.7,0]],"id":63027102}],"con":true,"img":false}]}
{"op":"mcm","clk":"11449989726","pt":1717316821432,"mc":[{"id":"1.229554901","rc":[{"atb":[[5.9,9.51]],"id":63027102}],"con":true,"img":false}]}
{"op":"mcm","clk":"11449989735","pt":1717316821507,"mc":[{"id":"1.229554901","rc":[{"atb":[[5.3,0]],"id":63027102}],"con":true,"img":false}]}
{"op":"mcm","clk":"11449993076","pt":1717316863667,"mc":[{"id":"1.229554901","rc":[{"atb":[[5.8,0]],"id":63027102}],"con":true,"img":false}]}
{"op":"mcm","clk":"11449993085","pt":1717316863771,"mc":[{"id":"1.229554901","rc":[{"atb":[[5.3,19.02],[5.4,9.51]],"id":63027102}],"con":true,"img":false}]}
{"op":"mcm","clk":"11449993093","pt":1717316863877,"mc":[{"id":"1.229554901","rc":[{"atb":[[5.9,0]],"id":63027102}],"con":true,"img":false}]}
{"op":"mcm","clk":"11449993596","pt":1717316870156,"mc":[{"id":"1.229554901","rc":[{"atb":[[1.49,0],[1.39,0]],"id":70003368},{"atl":[[4.4,0]],"id":70003368},{"atb":[[1.41,0],[1.31,0]],"id":47208569},{"atl":[[4.1,0]],"id":47208569},{"atb":[[5.2,0],[4.2,0]],"id":63027102},{"atb":[[1.01,17.89]],"id":67532289},{"atl":[[2.6,0]],"id":67532289}],"con":true,"img":false}]}
{"op":"mcm","clk":"11449993608","pt":1717316870264,"mc":[{"id":"1.229554901","rc":[{"atl":[[5.5,8.53],[5.7,0]],"id":70003368}],"con":true,"img":false}]}
{"op":"mcm","clk":"11449994101","pt":1717316875836,"mc":[{"id":"1.229554901","rc":[{"atb":[[1.41,0]],"id":70003368},{"atb":[[1.32,55.8]],"id":47208569}],"con":true,"img":false}]}
{"op":"mcm","clk":"11449994368","pt":1717316878846,"mc":[{"id":"1.229554901","rc":[{"atb":[[1.4,0]],"id":70003368},{"atl":[[5.6,2.39]],"id":70003368}],"con":true,"img":false}]}
{"op":"mcm","clk":"11449994376","pt":1717316878951,"mc":[{"id":"1.229554901","rc":[{"atb":[[1.35,34.88]],"id":70003368},{"atl":[[5.6,19.45],[6.4,13.6],[5.5,0]],"id":70003368}],"con":true,"img":false}]}
{"op":"mcm","clk":"11449994388","pt":1717316879052,"mc":[{"id":"1.229554901","rc":[{"atl":[[5.6,2.39],[5.7,10.92]],"id":70003368}],"con":true,"img":false}]}
{"op":"mcm","clk":"11449994767","pt":1717316883692,"mc":[{"id":"1.229554901","rc":[{"spn":3.55,"spf":"NaN","id":70003368},{"spn":2.81,"spf":"NaN","id":47208569},{"atb":[[5.3,0],[5.5,15]],"id":63027102},{"spn":35.25,"spf":"NaN","id":63027102}],"con":true,"img":false}]}
{"op":"mcm","clk":"11449995437","pt":1717316891092,"mc":[{"id":"1.229554901","rc":[{"atb":[[1.44,52.79],[1.34,219.64]],"id":70003368},{"atl":[[4.2,0.16]],"id":70003368},{"atb":[[1.32,164.69],[1.42,55.3]],"id":47208569},{"atl":[[4.1,0.16]],"id":47208569},{"atb":[[3.95,11.81],[4.9,5.95]],"id":63027102},{"atb":[[1.01,5825.15]],"id":67532289},{"atl":[[2.68,0.31]],"id":67532289}],"con":true,"img":false}]}
{"op":"mcm","clk":"11449995601","pt":1717316892802,"mc":[{"id":"1.229554901","rc":[{"atb":[[1.43,0]],"id":47208569}],"con":true,"img":false}]}
{"op":"mcm","clk":"11449996559","pt":1717316903606,"mc":[{"id":"1.229554901","rc":[{"atl":[[5.3,0]],"id":47208569}],"con":true,"img":false}]}
{"op":"mcm","clk":"11449997899","pt":1717316920617,"mc":[{"id":"1.229554901","rc":[{"atb":[[1.33,12.91]],"id":47208569}],"con":true,"img":false}]}
{"op":"mcm","clk":"11449997914","pt":1717316920825,"mc":[{"id":"1.229554901","rc":[{"atb":[[1.35,47.05]],"id":70003368}],"con":true,"img":false}]}
{"op":"mcm","clk":"11449998062","pt":1717316922635,"mc":[{"id":"1.229554901","rc":[{"atl":[[3.5,9.51],[4.2,0]],"id":47208569},{"atl":[[100,2],[120,0]],"id":49183855},{"atl":[[330,2],[400,0]],"id":63027102},{"atl":[[1.98,0],[1.9,26.83]],"id":67532289}],"con":true,"img":false}]}
{"op":"mcm","clk":"11449999307","pt":1717316937731,"mc":[{"id":"1.229554901","rc":[{"atb":[[1.51,0]],"id":70003368}],"con":true,"img":false}]}
{"op":"mcm","clk":"11449999992","pt":1717316945752,"mc":[{"id":"1.229554901","rc":[{"spn":2.82,"spf":"NaN","id":70003368},{"atl":[[3.5,0],[4.2,9.68]],"id":47208569},{"spn":2.76,"spf":"NaN","id":47208569},{"atl":[[330,0],[400,2]],"id":63027102},{"atl":[[1.98,53.66],[1.9,0]],"id":67532289}],"con":true,"img":false}]}
{"op":"mcm","clk":"11450000141","pt":1717316947247,"mc":[{"id":"1.229554901","rc":[{"atb":[[1.35,12.17]],"id":70003368},{"atl":[[6.4,0],[5.8,0]],"id":70003368},{"atb":[[5.4,0]],"id":63027102}],"con":true,"img":false}]}
{"op":"mcm","clk":"11450000152","pt":1717316947351,"mc":[{"id":"1.229554901","rc":[{"atb":[[1.45,34.88]],"id":70003368},{"atl":[[5.6,24.36]],"id":70003368},{"atb":[[5.6,9.51],[5,25],[5.5,0]],"id":63027102}],"con":true,"img":false}]}
{"op":"mcm","clk":"11450001027","pt":1717316957178,"mc":[{"id":"1.229554901","rc":[{"atb":[[5.6,0]],"id":63027102}],"con":true,"img":false}]}
{"op":"mcm","clk":"11450001035","pt":1717316957285,"mc":[{"id":"1.229554901","rc":[{"atb":[[5.3,9.51]],"id":63027102}],"con":true,"img":false}]}
{"op":"mcm","clk":"11450001564","pt":1717316963575,"mc":[{"id":"1.229554901","rc":[{"atb":[[5,29.82],[4.7,0]],"id":49183855}],"con":true,"img":false}]}
{"op":"mcm","clk":"11450001573","pt":1717316963677,"mc":[{"id":"1.229554901","rc":[{"atb":[[5,10.46],[4.9,20.92]],"id":49183855}],"con":true,"img":false}]}
{"op":"mcm","clk":"11450001581","pt":1717316963779,"mc":[{"id":"1.229554901","rc":[{"atb":[[5,29.82]],"id":49183855}],"con":true,"img":false}]}
{"op":"mcm","clk":"11450001590","pt":1717316963893,"mc":[{"id":"1.229554901","rc":[{"atb":[[4.9,0]],"id":49183855}],"con":true,"img":false}]}
{"op":"mcm","clk":"11450001686","pt":1717316964918,"mc":[{"id":"1.229554901","rc":[{"atl":[[3.7,9.51],[4.2,0]],"id":47208569},{"atl":[[350,2],[400,0]],"id":63027102},{"atl":[[1.98,0],[1.95,26.83]],"id":67532289}],"con":true,"img":false}]}
{"op":"mcm","clk":"11450001828","pt":1717316966480,"mc":[{"id":"1.229554901","rc":[{"atb":[[5,0],[5.4,9.51]],"id":63027102}],"con":true,"img":false}]}
{"op":"mcm","clk":"11450001891","pt":1717316967204,"mc":[{"id":"1.229554901","rc":[{"atb":[[4.8,0]],"id":49183855}],"con":true,"img":false}]}
{"op":"mcm","clk":"11450001900","pt":1717316967310,"mc":[{"id":"1.229554901","rc":[{"atb":[[4.2,19.35]],"id":49183855}],"con":true,"img":false}]}
{"op":"mcm","clk":"11450002856","pt":1717316978815,"mc":[{"id":"1.229554901","rc":[{"atl":[[3.7,0],[3.8,19.02]],"id":47208569},{"atl":[[1.94,26.83],[1.95,0]],"id":67532289}],"con":true,"img":false}]}
{"op":"mcm","clk":"11450003271","pt":1717316983926,"mc":[{"id":"1.229554901","rc":[{"atl":[[5.6,21.97]],"id":70003368}],"con":true,"img":false}]}
{"op":"mcm","clk":"11450003283","pt":1717316984131,"mc":[{"id":"1.229554901","rc":[{"atl":[[6,6.83]],"id":70003368}],"con":true,"img":false}]}
{"op":"mcm","clk":"11450003558","pt":1717316987227,"mc":[{"id":"1.229554901","rc":[{"atb":[[5.3,0]],"id":63027102}],"con":true,"img":false}]}
{"op":"mcm","clk":"11450003567","pt":1717316987329,"mc":[{"id":"1.229554901","rc":[{"atb":[[5,19.02],[5.5,9.51],[5.4,0]],"id":63027102}],"con":true,"img":false}]}
{"op":"mcm","clk":"11450003947","pt":1717316992140,"mc":[{"id":"1.229554901","rc":[{"atb":[[4.6,0],[3.8,0]],"id":49183855}],"con":true,"img":false}]}
{"op":"mcm","clk":"11450004388","pt":1717316997242,"mc":[{"id":"1.229554901","rc":[{"atl":[[2.86,0]],"id":67532289}],"con":true,"img":false}]}
{"op":"mcm","clk":"11450004398","pt":1717316997352,"mc":[{"id":"1.229554901","rc":[{"atl":[[3.15,26.82]],"id":67532289}],"con":true,"img":false}]}
{"op":"mcm","clk":"11450005256","pt":1717317005942,"mc":[{"id":"1.229554901","rc":[{"spn":2.82,"spf":"NaN","id":70003368},{"spn":2.61,"spf":"NaN","id":47208569},{"atb":[[5.6,9.51],[5,0]],"id":63027102},{"spn":35.3,"spf":"NaN","id":63027102},{"spn":1.53,"spf":"NaN","id":67532289}],"con":true,"img":false}]}
{"op":"mcm","clk":"11450005654","pt":1717317009970,"mc":[{"id":"1.229554901","rc":[{"atl":[[6,0]],"id":70003368}],"con":true,"img":false}]}
{"op":"mcm","clk":"11450005674","pt":1717317010230,"mc":[{"id":"1.229554901","rc":[{"atl":[[5.6,26.03]],"id":70003368}],"con":true,"img":false}]}
{"op":"mcm","clk":"11450006320","pt":1717317017091,"mc":[{"id":"1.229554901","rc":[{"atb":[[1.46,8.53]],"id":70003368},{"atb":[[1.44,8.91]],"id":47208569}],"con":true,"img":false}]}
{"op":"mcm","clk":"11450006337","pt":1717317017246,"mc":[{"id":"1.229554901","rc":[{"atl":[[5,0],[3.75,15.21]],"id":47208569}],"con":true,"img":false}]}
{"op":"mcm","clk":"11450006347","pt":1717317017355,"mc":[{"id":"1.229554901","rc":[{"atl":[[3.7,15.22],[3.8,0]],"id":47208569}],"con":true,"img":false}]}
{"op":"mcm","clk":"11450006456","pt":1717317018448,"mc":[{"id":"1.229554901","rc":[{"atb":[[3.95,11.81],[4.9,5.95]],"id":49183855}],"con":true,"img":false}]}
{"op":"mcm","clk":"11450007331","pt":1717317027185,"mc":[{"id":"1.229554901","rc":[{"atb":[[5.5,0]],"id":63027102}],"con":true,"img":false}]}
{"op":"mcm","clk":"11450007345","pt":1717317027295,"mc":[{"id":"1.229554901","rc":[{"atb":[[5.7,9.51]],"id":63027102}],"con":true,"img":false}]}
{"op":"mcm","clk":"11450007359","pt":1717317027392,"mc":[{"id":"1.229554901","rc":[{"atb":[[5.6,0],[5,19.02]],"id":63027102}],"con":true,"img":false}]}
{"op":"mcm","clk":"11450007371","pt":1717317027498,"mc":[{"id":"1.229554901","rc":[{"atb":[[5,0],[5.8,9.51]],"id":63027102}],"con":true,"img":false}]}
{"op":"mcm","clk":"11450009267","pt":1717317047182,"mc":[{"id":"1.229554901","rc":[{"atl":[[3.75,0]],"id":47208569}],"con":true,"img":false}]}
{"op":"mcm","clk":"11450009279","pt":1717317047284,"mc":[{"id":"1.229554901","rc":[{"atl":[[3.7,0],[3.8,30.44],[3.65,15.21]],"id":47208569}],"con":true,"img":false}]}
{"op":"mcm","clk":"11450009288","pt":1717317047382,"mc":[{"id":"1.229554901","rc":[{"atl":[[3.6,15.22],[3.8,0]],"id":47208569}],"con":true,"img":false}]}
{"op":"mcm","clk":"11450010253","pt":1717317057191,"mc":[{"id":"1.229554901","rc":[{"atb":[[5.7,0]],"id":63027102}],"con":true,"img":false}]}
{"op":"mcm","clk":"11450010260","pt":1717317057294,"mc":[{"id":"1.229554901","rc":[{"atb":[[5.9,9.51]],"id":63027102}],"con":true,"img":false}]}
{"op":"mcm","clk":"11450010269","pt":1717317057393,"mc":[{"id":"1.229554901","rc":[{"atb":[[5.8,0],[5,19.02]],"id":63027102}],"con":true,"img":false}]}
{"op":"mcm","clk":"11450011265","pt":1717317067231,"mc":[{"id":"1.229554901","rc":[{"spn":2.83,"spf":"NaN","id":70003368},{"spn":2.52,"spf":"NaN","id":47208569},{"atb":[[5.9,0]],"id":63027102},{"spn":35.0,"spf":"NaN","id":63027102}],"con":true,"img":false}]}
{"op":"mcm","clk":"11450011274","pt":1717317067290,"mc":[{"id":"1.229554901","rc":[{"atb":[[5.3,9.51]],"id":63027102}],"con":true,"img":false}]}
{"op":"mcm","clk":"11450012050","pt":1717317075324,"mc":[{"id":"1.229554901","rc":[{"atb":[[5,0],[5.4,9.51]],"id":63027102}],"con":true,"img":false}]}
{"op":"mcm","clk":"11450012304","pt":1717317077236,"mc":[{"id":"1.229554901","rc":[{"atl":[[3.65,0]],"id":47208569}],"con":true,"img":false}]}
{"op":"mcm","clk":"11450012320","pt":1717317077345,"mc":[{"id":"1.229554901","rc":[{"atl":[[3.6,0],[3.8,30.44],[3.55,15.21]],"id":47208569}],"con":true,"img":false}]}
{"op":"mcm","clk":"11450013298","pt":1717317087240,"mc":[{"id":"1.229554901","rc":[{"atl":[[3.55,0]],"id":47208569}],"con":true,"img":false}]}
{"op":"mcm","clk":"11450013309","pt":1717317087342,"mc":[{"id":"1.229554901","rc":[{"atl":[[3.75,15.21]],"id":47208569}],"con":true,"img":false}]}
{"op":"mcm","clk":"11450014018","pt":1717317095028,"mc":[{"id":"1.229554901","rc":[{"atl":[[3.7,15.22],[3.8,0]],"id":47208569}],"con":true,"img":false}]}
{"op":"mcm","clk":"11450014215","pt":1717317097235,"mc":[{"id":"1.229554901","rc":[{"atb":[[5.3,0]],"id":63027102}],"con":true,"img":false}]}
{"op":"mcm","clk":"11450014227","pt":1717317097343,"mc":[{"id":"1.229554901","rc":[{"atb":[[5,19.02],[5.5,9.51],[5.4,0]],"id":63027102}],"con":true,"img":false}]}
{"op":"mcm","clk":"11450014362","pt":1717317098737,"mc":[{"id":"1.229554901","rc":[{"atb":[[5,10.46],[4.7,27.03]],"id":49183855},{"atl":[[1.98,53.66],[1.94,0]],"id":67532289}],"con":true,"img":false}]}
{"op":"mcm","clk":"11450015087","pt":1717317107179,"mc":[{"id":"1.229554901","rc":[{"atl":[[5.3,9.73],[3.75,0]],"id":47208569}],"con":true,"img":false}]}
{"op":"mcm","clk":"11450015095","pt":1717317107281,"mc":[{"id":"1.229554901","rc":[{"atl":[[3.7,0],[4.2,15.39]],"id":47208569}],"con":true,"img":false}]}
{"op":"mcm","clk":"11450015772","pt":1717317114874,"mc":[{"id":"1.229554901","rc":[{"atb":[[5.6,9.51]],"id":63027102}],"con":true,"img":false}]}
{"op":"mcm","clk":"11450015778","pt":1717317114977,"mc":[{"id":"1.229554901","rc":[{"atb":[[5,0]],"id":63027102}],"con":true,"img":false}]}
{"op":"mcm","clk":"11450018036","pt":1717317137274,"mc":[{"id":"1.229554901","rc":[{"spn":2.77,"spf":"NaN","id":47208569},{"atb":[[5.5,0]],"id":63027102},{"spn":35.3,"spf":"NaN","id":63027102},{"atl":[[3.15,0]],"id":67532289},{"spn":1.55,"spf":"NaN","id":67532289}],"con":true,"img":false}]}
{"op":"mcm","clk":"11450018043","pt":1717317137324,"mc":[{"id":"1.229554901","rc":[{"atb":[[5.6,0],[5,19.02],[5.7,9.51]],"id":63027102},{"atl":[[2.88,26.82]],"id":67532289}],"con":true,"img":false}]}
{"op":"mcm","clk":"11450019007","pt":1717317147265,"mc":[{"id":"1.229554901","rc":[{"atb":[[4.2,0]],"id":49183855},{"atb":[[5.7,0]],"id":63027102}],"con":true,"img":false}]}
{"op":"mcm","clk":"11450019019","pt":1717317147322,"mc":[{"id":"1.229554901","rc":[{"atb":[[4.8,19.35]],"id":49183855},{"atb":[[5.3,9.51]],"id":63027102}],"con":true,"img":false}]}
{"op":"mcm","clk":"11450019722","pt":1717317154538,"mc":[{"id":"1.229554901","rc":[{"atb":[[5,0],[5.4,9.51]],"id":63027102}],"con":true,"img":false}]}
{"op":"mcm","clk":"11450021968","pt":1717317177189,"mc":[{"id":"1.229554901","rc":[{"atb":[[5.3,0]],"id":63027102}],"con":true,"img":false}]}
{"op":"mcm","clk":"11450021979","pt":1717317177291,"mc":[{"id":"1.229554901","rc":[{"atb":[[5,19.02],[5.5,9.51],[5.4,0]],"id":63027102}],"con":true,"img":false}]}
{"op":"mcm","clk":"11450023683","pt":1717317194004,"mc":[{"id":"1.229554901","rc":[{"atb":[[5.6,9.51],[5,0]],"id":63027102}],"con":true,"img":false}]}
{"op":"mcm","clk":"11450026008","pt":1717317217217,"mc":[{"id":"1.229554901","rc":[{"atb":[[5.5,0]],"id":63027102}],"con":true,"img":false}]}
{"op":"mcm","clk":"11450026019","pt":1717317217318,"mc":[{"id":"1.229554901","rc":[{"atb":[[5,19.02],[5.7,9.51]],"id":63027102}],"con":true,"img":false}]}
{"op":"mcm","clk":"11450026034","pt":1717317217419,"mc":[{"id":"1.229554901","rc":[{"atb":[[5.6,0],[5,0],[5.8,9.51]],"id":63027102}],"con":true,"img":false}]}
{"op":"mcm","clk":"11450026473","pt":1717317221317,"mc":[{"id":"1.229554901","rc":[{"atl":[[5.6,21.97]],"id":70003368}],"con":true,"img":false}]}
{"op":"mcm","clk":"11450026505","pt":1717317221626,"mc":[{"id":"1.229554901","rc":[{"atl":[[5.6,24.36]],"id":70003368}],"con":true,"img":false}]}
{"op":"mcm","clk":"11450027897","pt":1717317235132,"mc":[{"id":"1.229554901","rc":[{"atb":[[1.44,0],[1.34,117.17]],"id":70003368},{"atl":[[4.2,0]],"id":70003368},{"atb":[[1.32,55.8],[1.42,0]],"id":47208569},{"atl":[[4.1,0]],"id":47208569},{"atb":[[3.95,0],[4.9,0]],"id":63027102},{"atb":[[1.01,17.89]],"id":67532289},{"atl":[[2.68,0]],"id":67532289}],"con":true,"img":false}]}
{"op":"mcm","clk":"11450027905","pt":1717317235234,"mc":[{"id":"1.229554901","rc":[{"atl":[[5.5,10.92],[5.7,0]],"id":70003368}],"con":true,"img":false}]}
{"op":"mcm","clk":"11450028106","pt":1717317237260,"mc":[{"id":"1.229554901","rc":[{"atb":[[1.45,0]],"id":70003368},{"atl":[[5.6,10.76]],"id":70003368}],"con":true,"img":false}]}
{"op":"mcm","clk":"11450028117","pt":1717317237362,"mc":[{"id":"1.229554901","rc":[{"atb":[[1.35,47.05]],"id":70003368},{"atl":[[6.4,13.6]],"id":70003368}],"con":true,"img":false}]}
{"op":"mcm","clk":"11450029046","pt":1717317247135,"mc":[{"id":"1.229554901","rc":[{"atb":[[5.7,0]],"id":63027102}],"con":true,"img":false}]}
{"op":"mcm","clk":"11450029053","pt":1717317247243,"mc":[{"id":"1.229554901","rc":[{"atb":[[5.8,0],[5.9,9.51],[4.7,27.03]],"id":63027102}],"con":true,"img":false}]}
{"op":"mcm","clk":"11450030019","pt":1717317257077,"mc":[{"id":"1.229554901","rc":[{"atb":[[1.46,0]],"id":70003368},{"atb":[[1.44,0]],"id":47208569}],"con":true,"img":false}]}
{"op":"mcm","clk":"11450030029","pt":1717317257178,"mc":[{"id":"1.229554901","rc":[{"atb":[[1.32,164.23],[1.34,0]],"id":70003368},{"atb":[[5.9,0]],"id":63027102}],"con":true,"img":false}]}
{"op":"mcm","clk":"11450030041","pt":1717317257289,"mc":[{"id":"1.229554901","rc":[{"atb":[[5.3,9.51]],"id":63027102}],"con":true,"img":false}]}
{"op":"mcm","clk":"11450030125","pt":1717317258067,"mc":[{"id":"1.229554901","rc":[{"atb":[[1.33,0]],"id":47208569}],"con":true,"img":false}]}
{"op":"mcm","clk":"11450030131","pt":1717317258168,"mc":[{"id":"1.229554901","rc":[{"atb":[[1.21,0],[1.17,334.4]],"id":47208569}],"con":true,"img":false}]}
{"op":"mcm","clk":"11450030281","pt":1717317259671,"mc":[{"id":"1.229554901","rc":[{"atb":[[1.37,94.17],[1.47,49.42]],"id":70003368},{"atl":[[4.3,0.15]],"id":70003368},{"atb":[[1.41,56.65],[1.31,112.39]],"id":47208569},{"atl":[[4.1,0.16]],"id":47208569},{"atb":[[4.3,10.55],[5.3,14.91]],"id":63027102},{"atb":[[1.01,5825.15]],"id":67532289},{"atl":[[2.64,0.31]],"id":67532289}],"con":true,"img":false}]}
{"op":"mcm","clk":"11450030690","pt":1717317263247,"mc":[{"id":"1.229554901","rc":[{"atb":[[5.4,15]],"id":63027102}],"con":true,"img":false}]}
{"op":"mcm","clk":"11450030698","pt":1717317263350,"mc":[{"id":"1.229554901","rc":[{"atb":[[4.7,0]],"id":63027102}],"con":true,"img":false}]}
{"op":"mcm","clk":"11450031066","pt":1717317267179,"mc":[{"id":"1.229554901","rc":[{"atl":[[5.6,2.39]],"id":70003368}],"con":true,"img":false}]}
{"op":"mcm","clk":"11450031079","pt":1717317267281,"mc":[{"id":"1.229554901","rc":[{"atl":[[5.4,8.37]],"id":70003368}],"con":true,"img":false}]}
{"op":"mcm","clk":"11450031091","pt":1717317267384,"mc":[{"id":"1.229554901","rc":[{"atl":[[5.5,0],[5.3,8.37]],"id":70003368}],"con":true,"img":false}]}
{"op":"mcm","clk":"11450031584","pt":1717317272302,"mc":[{"id":"1.229554901","rc":[{"atb":[[1.49,8]],"id":70003368},{"atb":[[1.43,9.13]],"id":47208569}],"con":true,"img":false}]}
{"op":"mcm","clk":"11450033180","pt":1717317287199,"mc":[{"id":"1.229554901","rc":[{"spn":2.89,"spf":"NaN","id":70003368},{"spn":2.76,"spf":"NaN","id":47208569},{"atb":[[5.3,5.4]],"id":63027102},{"spn":35.2,"spf":"NaN","id":63027102}],"con":true,"img":false}]}
{"op":"mcm","clk":"11450033193","pt":1717317287301,"mc":[{"id":"1.229554901","rc":[{"atb":[[5.5,9.51]],"id":63027102}],"con":true,"img":false}]}
{"op":"mcm","clk":"11450033204","pt":1717317287405,"mc":[{"id":"1.229554901","rc":[{"atb":[[5.6,9.51],[5.4,0]],"id":63027102}],"con":true,"img":false}]}
{"op":"mcm","clk":"11450034176","pt":1717317297225,"mc":[{"id":"1.229554901","rc":[{"atb":[[1.35,12.17]],"id":70003368}],"con":true,"img":false}]}
{"op":"mcm","clk":"11450034189","pt":1717317297328,"mc":[{"id":"1.229554901","rc":[{"atb":[[1.48,34.88]],"id":70003368}],"con":true,"img":false}]}
{"op":"mcm","clk":"11450034396","pt":1717317299099,"mc":[{"id":"1.229554901","rc":[{"atb":[[1.32,69.11]],"id":47208569}],"con":true,"img":false}]}
{"op":"mcm","clk":"11450034421","pt":1717317299302,"mc":[{"id":"1.229554901","rc":[{"atb":[[1.35,0]],"id":70003368}],"con":true,"img":false}]}
{"op":"mcm","clk":"11450035335","pt":1717317307231,"mc":[{"id":"1.229554901","rc":[{"atb":[[1.28,0]],"id":70003368}],"con":true,"img":false}]}
{"op":"mcm","clk":"11450035352","pt":1717317307297,"mc":[{"id":"1.229554901","rc":[{"atb":[[1.33,224.44]],"id":70003368}],"con":true,"img":false}]}
{"op":"mcm","clk":"11450036432","pt":1717317317251,"mc":[{"id":"1.229554901","rc":[{"atb":[[5.5,0]],"id":63027102}],"con":true,"img":false}]}
{"op":"mcm","clk":"11450036444","pt":1717317317303,"mc":[{"id":"1.229554901","rc":[{"atb":[[5.7,9.51],[5.4,19.02]],"id":63027102}],"con":true,"img":false}]}
{"op":"mcm","clk":"11450036453","pt":1717317317409,"mc":[{"id":"1.229554901","rc":[{"atb":[[5.6,0]],"id":63027102}],"con":true,"img":false}]}
{"op":"mcm","clk":"11450037526","pt":1717317327246,"mc":[{"id":"1.229554901","rc":[{"atb":[[5.7,0]],"id":63027102}],"con":true,"img":false}]}
{"op":"mcm","clk":"11450037538","pt":1717317327349,"mc":[{"id":"1.229554901","rc":[{"atb":[[5.5,9.51]],"id":63027102}],"con":true,"img":false}]}
{"op":"mcm","clk":"11450038163","pt":1717317332748,"mc":[{"id":"1.229554901","rc":[{"atb":[[5.6,9.51],[5.4,0]],"id":63027102}],"con":true,"img":false}]}
{"op":"mcm","clk":"11450038660","pt":1717317337446,"mc":[{"id":"1.229554901","rc":[{"atb":[[1.38,11.21]],"id":70003368}],"con":true,"img":false}]}
{"op":"mcm","clk":"11450040232","pt":1717317351851,"mc":[{"id":"1.229554901","rc":[{"atb":[[3.95,0],[4.9,0]],"id":49183855},{"spn":35.3,"spf":"NaN","id":63027102}],"con":true,"img":false}]}
{"op":"mcm","clk":"11450040757","pt":1717317357162,"mc":[{"id":"1.229554901","rc":[{"atb":[[5.5,0]],"id":63027102}],"con":true,"img":false}]}
{"op":"mcm","clk":"11450040765","pt":1717317357267,"mc":[{"id":"1.229554901","rc":[{"atb":[[5.7,9.51]],"id":63027102}],"con":true,"img":false}]}
{"op":"mcm","clk":"11450040777","pt":1717317357368,"mc":[{"id":"1.229554901","rc":[{"atb":[[5.6,0],[5.4,19.02]],"id":63027102}],"con":true,"img":false}]}
{"op":"mcm","clk":"11450040788","pt":1717317357465,"mc":[{"id":"1.229554901","rc":[{"atb":[[5.8,9.51],[5.4,0]],"id":63027102}],"con":true,"img":false}]}
{"op":"mcm","clk":"11450042982","pt":1717317378075,"mc":[{"id":"1.229554901","rc":[{"atb":[[3.95,11.81],[4.9,5.95]],"id":49183855}],"con":true,"img":false}]}
{"op":"mcm","clk":"11450043946","pt":1717317387171,"mc":[{"id":"1.229554901","rc":[{"atb":[[5.7,0]],"id":63027102}],"con":true,"img":false}]}
{"op":"mcm","clk":"11450043962","pt":1717317387282,"mc":[{"id":"1.229554901","rc":[{"atb":[[5.8,0],[5.9,9.51],[5.4,19.02]],"id":63027102}],"con":true,"img":false}]}
{"op":"mcm","clk":"11450044963","pt":1717317397193,"mc":[{"id":"1.229554901","rc":[{"atb":[[5.9,0]],"id":63027102}],"con":true,"img":false}]}
{"op":"mcm","clk":"11450044971","pt":1717317397296,"mc":[{"id":"1.229554901","rc":[{"atb":[[5.5,9.51]],"id":63027102}],"con":true,"img":false}]}
{"op":"mcm","clk":"11450045449","pt":1717317401976,"mc":[{"id":"1.229554901","rc":[{"atb":[[5.6,9.51],[5.4,0]],"id":63027102}],"con":true,"img":false}]}
{"op":"mcm","clk":"11450048184","pt":1717317427246,"mc":[{"id":"1.229554901","rc":[{"atb":[[5.5,0]],"id":63027102}],"con":true,"img":false}]}
{"op":"mcm","clk":"11450048196","pt":1717317427374,"mc":[{"id":"1.229554901","rc":[{"atb":[[5.7,9.51]],"id":63027102}],"con":true,"img":false}]}
{"op":"mcm","clk":"11450048212","pt":1717317427456,"mc":[{"id":"1.229554901","rc":[{"atb":[[5.6,0],[5.4,19.02]],"id":63027102}],"con":true,"img":false}]}
{"op":"mcm","clk":"11450049310","pt":1717317437151,"mc":[{"id":"1.229554901","rc":[{"atb":[[5.7,0]],"id":63027102}],"con":true,"img":false}]}
{"op":"mcm","clk":"11450049323","pt":1717317437269,"mc":[{"id":"1.229554901","rc":[{"atb":[[5.5,9.51]],"id":63027102}],"con":true,"img":false}]}
{"op":"mcm","clk":"11450049798","pt":1717317441762,"mc":[{"id":"1.229554901","rc":[{"atb":[[5.6,9.51],[5.4,0]],"id":63027102}],"con":true,"img":false}]}
{"op":"mcm","clk":"11450052255","pt":1717317467291,"mc":[{"id":"1.229554901","rc":[{"atb":[[5.5,0]],"id":63027102}],"con":true,"img":false}]}
{"op":"mcm","clk":"11450052266","pt":1717317467348,"mc":[{"id":"1.229554901","rc":[{"atb":[[5.7,9.51],[5.4,19.02]],"id":63027102}],"con":true,"img":false}]}
{"op":"mcm","clk":"11450052274","pt":1717317467455,"mc":[{"id":"1.229554901","rc":[{"atb":[[5.6,0],[5.8,9.51],[5.4,0]],"id":63027102}],"con":true,"img":false}]}
{"op":"mcm","clk":"11450054893","pt":1717317497196,"mc":[{"id":"1.229554901","rc":[{"atb":[[5.7,0]],"id":63027102},{"spn":35.4,"spf":"NaN","id":63027102}],"con":true,"img":false}]}
{"op":"mcm","clk":"11450054905","pt":1717317497311,"mc":[{"id":"1.229554901","rc":[{"atb":[[5.9,9.51],[5.4,19.02]],"id":63027102}],"con":true,"img":false}]}
{"op":"mcm","clk":"11450054917","pt":1717317497406,"mc":[{"id":"1.229554901","rc":[{"atb":[[5.8,0]],"id":63027102}],"con":true,"img":false}]}
{"op":"mcm","clk":"11450054928","pt":1717317497506,"mc":[{"id":"1.229554901","rc":[{"atb":[[5.9,19.02],[5.4,0]],"id":63027102}],"con":true,"img":false}]}
{"op":"mcm","clk":"11450056633","pt":1717317517202,"mc":[{"id":"1.229554901","rc":[{"atb":[[5.9,9.51]],"id":63027102}],"con":true,"img":false}]}
{"op":"mcm","clk":"11450056644","pt":1717317517306,"mc":[{"id":"1.229554901","rc":[{"atb":[[5.4,28.53]],"id":63027102}],"con":true,"img":false}]}
{"op":"mcm","clk":"11450056654","pt":1717317517407,"mc":[{"id":"1.229554901","rc":[{"atb":[[5.9,0]],"id":63027102}],"con":true,"img":false}]}
{"op":"mcm","clk":"11450059296","pt":1717317547226,"mc":[{"id":"1.229554901","rc":[{"atb":[[5.4,19.02]],"id":63027102}],"con":true,"img":false}]}
{"op":"mcm","clk":"11450059308","pt":1717317547331,"mc":[{"id":"1.229554901","rc":[{"atb":[[5.5,9.51]],"id":63027102}],"con":true,"img":false}]}
{"op":"mcm","clk":"11450059315","pt":1717317547433,"mc":[{"id":"1.229554901","rc":[{"atb":[[5.6,9.51],[5.4,0]],"id":63027102}],"con":true,"img":false}]}
{"op":"mcm","clk":"11450062065","pt":1717317577155,"mc":[{"id":"1.229554901","rc":[{"atb":[[5.5,0]],"id":63027102},{"spn":35.3,"spf":"NaN","id":63027102}],"con":true,"img":false}]}
{"op":"mcm","clk":"11450062071","pt":1717317577257,"mc":[{"id":"1.229554901","rc":[{"atb":[[5.7,9.51],[5.4,19.02]],"id":63027102}],"con":true,"img":false}]}
{"op":"mcm","clk":"11450062081","pt":1717317577362,"mc":[{"id":"1.229554901","rc":[{"atb":[[5.6,0],[5.8,9.51],[5.4,0]],"id":63027102}],"con":true,"img":false}]}
{"op":"mcm","clk":"11450064737","pt":1717317607210,"mc":[{"id":"1.229554901","rc":[{"atb":[[5.7,0]],"id":63027102}],"con":true,"img":false}]}
{"op":"mcm","clk":"11450064748","pt":1717317607313,"mc":[{"id":"1.229554901","rc":[{"atb":[[5.9,9.51],[5.4,19.02]],"id":63027102}],"con":true,"img":false}]}
{"op":"mcm","clk":"11450064757","pt":1717317607416,"mc":[{"id":"1.229554901","rc":[{"atb":[[5.8,0]],"id":63027102}],"con":true,"img":false}]}
{"op":"mcm","clk":"11450065676","pt":1717317617259,"mc":[{"id":"1.229554901","rc":[{"atb":[[5.9,0]],"id":63027102}],"con":true,"img":false}]}
{"op":"mcm","clk":"11450065686","pt":1717317617315,"mc":[{"id":"1.229554901","rc":[{"atb":[[5.5,9.51]],"id":63027102}],"con":true,"img":false}]}
{"op":"mcm","clk":"11450065901","pt":1717317619714,"mc":[{"id":"1.229554901","rc":[{"atb":[[5.6,9.51]],"id":63027102}],"con":true,"img":false}]}
{"op":"mcm","clk":"11450065909","pt":1717317619817,"mc":[{"id":"1.229554901","rc":[{"atb":[[5.4,0]],"id":63027102}],"con":true,"img":false}]}
{"op":"mcm","clk":"11450068130","pt":1717317644469,"mc":[{"id":"1.229554901","rc":[{"atb":[[1.37,0],[1.47,0]],"id":70003368},{"atl":[[4.3,0]],"id":70003368},{"spn":3.39,"spf":"NaN","id":70003368},{"atb":[[1.41,0],[1.31,0]],"id":47208569},{"atl":[[4.1,0]],"id":47208569},{"spn":2.81,"spf":"NaN","id":47208569},{"atb":[[4.3,0],[5.3,0]],"id":63027102},{"atb":[[1.01,17.89]],"id":67532289},{"atl":[[2.64,0]],"id":67532289}],"con":true,"img":false}]}
{"op":"mcm","clk":"11450068284","pt":1717317645875,"mc":[{"id":"1.229554901","rc":[{"atb":[[1.38,0]],"id":70003368},{"atb":[[1.32,55.8]],"id":47208569}],"con":true,"img":false}]}
{"op":"mcm","clk":"11450068403","pt":1717317647184,"mc":[{"id":"1.229554901","rc":[{"atb":[[1.33,275.17]],"id":70003368}],"con":true,"img":false}]}
{"op":"mcm","clk":"11450068414","pt":1717317647288,"mc":[{"id":"1.229554901","rc":[{"atb":[[1.48,0]],"id":70003368}],"con":true,"img":false}]}
{"op":"mcm","clk":"11450070037","pt":1717317665303,"mc":[{"id":"1.229554901","rc":[{"atb":[[1.46,50.49],[1.36,96.78]],"id":70003368},{"atl":[[4.3,0.15]],"id":70003368},{"atb":[[1.32,164.69],[1.42,55.3]],"id":47208569},{"atl":[[4.1,0.16]],"id":47208569},{"atb":[[5.1,5.66],[4.1,11.23]],"id":63027102},{"atb":[[1.01,5825.15]],"id":67532289},{"atl":[[2.64,0.31]],"id":67532289}],"con":true,"img":false}]}
{"op":"mcm","clk":"11450070226","pt":1717317667175,"mc":[{"id":"1.229554901","rc":[{"atb":[[5.5,0]],"id":63027102}],"con":true,"img":false}]}
{"op":"mcm","clk":"11450070238","pt":1717317667282,"mc":[{"id":"1.229554901","rc":[{"atb":[[5.6,0],[5.2,19.02],[5.7,9.51]],"id":63027102}],"con":true,"img":false}]}
{"op":"mcm","clk":"11450070248","pt":1717317667380,"mc":[{"id":"1.229554901","rc":[{"atb":[[5.8,9.51],[5.2,0]],"id":63027102}],"con":true,"img":false}]}
{"op":"mcm","clk":"11450071203","pt":1717317677293,"mc":[{"id":"1.229554901","rc":[{"atb":[[1.43,0]],"id":47208569}],"con":true,"img":false}]}
{"op":"mcm","clk":"11450072037","pt":1717317686411,"mc":[{"id":"1.229554901","rc":[{"atb":[[1.33,12.91]],"id":47208569}],"con":true,"img":false}]}
{"op":"mcm","clk":"11450072048","pt":1717317686550,"mc":[{"id":"1.229554901","rc":[{"atb":[[1.37,11.51]],"id":70003368}],"con":true,"img":false}]}
{"op":"mcm","clk":"11450073075","pt":1717317697128,"mc":[{"id":"1.229554901","rc":[{"atb":[[1.33,224.44],[1.47,35.62]],"id":70003368}],"con":true,"img":false}]}
{"op":"mcm","clk":"11450073085","pt":1717317697231,"mc":[{"id":"1.229554901","rc":[{"atb":[[5.7,0]],"id":63027102}],"con":true,"img":false}]}
{"op":"mcm","clk":"11450073095","pt":1717317697331,"mc":[{"id":"1.229554901","rc":[{"atb":[[5.9,9.51]],"id":63027102}],"con":true,"img":false}]}
{"op":"mcm","clk":"11450073117","pt":1717317697538,"mc":[{"id":"1.229554901","rc":[{"atb":[[5.8,0],[5.9,19.02]],"id":63027102}],"con":true,"img":false}]}
{"op":"mcm","clk":"11450073129","pt":1717317697640,"mc":[{"id":"1.229554901","rc":[{"atb":[[5.2,19.02]],"id":63027102}],"con":true,"img":false}]}
{"op":"mcm","clk":"11450073139","pt":1717317697741,"mc":[{"id":"1.229554901","rc":[{"atb":[[5.9,9.51]],"id":63027102}],"con":true,"img":false}]}
{"op":"mcm","clk":"11450074002","pt":1717317707232,"mc":[{"id":"1.229554901","rc":[{"spn":2.89,"spf":"NaN","id":70003368},{"spn":2.76,"spf":"NaN","id":47208569},{"atb":[[5.9,0]],"id":63027102},{"spn":35.1,"spf":"NaN","id":63027102}],"con":true,"img":false}]}
{"op":"mcm","clk":"11450074012","pt":1717317707340,"mc":[{"id":"1.229554901","rc":[{"atb":[[5.3,9.51]],"id":63027102}],"con":true,"img":false}]}
{"op":"mcm","clk":"11450074057","pt":1717317707854,"mc":[{"id":"1.229554901","rc":[{"atb":[[1.49,0]],"id":70003368}],"con":true,"img":false}]}
{"op":"mcm","clk":"11450074156","pt":1717317709247,"mc":[{"id":"1.229554901","rc":[{"atb":[[5.2,0],[5.4,9.51]],"id":63027102}],"con":true,"img":false}]}
{"op":"mcm","clk":"11450076046","pt":1717317730170,"mc":[{"id":"1.229554901","rc":[{"atb":[[3.95,0],[4.9,0]],"id":49183855}],"con":true,"img":false}]}
{"op":"mcm","clk":"11450076707","pt":1717317737285,"mc":[{"id":"1.229554901","rc":[{"atb":[[5.3,0]],"id":63027102}],"con":true,"img":false}]}
{"op":"mcm","clk":"11450076718","pt":1717317737386,"mc":[{"id":"1.229554901","rc":[{"atb":[[5.5,9.51],[5.2,19.02]],"id":63027102}],"con":true,"img":false}]}
{"op":"mcm","clk":"11450076729","pt":1717317737490,"mc":[{"id":"1.229554901","rc":[{"atb":[[5.6,9.51],[5.2,0],[5.4,0]],"id":63027102}],"con":true,"img":false}]}
{"op":"mcm","clk":"11450078202","pt":1717317753860,"mc":[{"id":"1.229554901","rc":[{"atb":[[3.95,11.81],[4.9,5.95]],"id":49183855}],"con":true,"img":false}]}
{"op":"mcm","clk":"11450079470","pt":1717317767243,"mc":[{"id":"1.229554901","rc":[{"spn":2.88,"spf":"NaN","id":70003368},{"atb":[[5.5,0]],"id":63027102},{"spn":35.3,"spf":"NaN","id":63027102}],"con":true,"img":false}]}
{"op":"mcm","clk":"11450079476","pt":1717317767351,"mc":[{"id":"1.229554901","rc":[{"atb":[[5.2,19.02],[5.7,9.51]],"id":63027102}],"con":true,"img":false}]}
{"op":"mcm","clk":"11450079484","pt":1717317767451,"mc":[{"id":"1.229554901","rc":[{"atb":[[5.6,0],[5.8,9.51],[5.2,0]],"id":63027102}],"con":true,"img":false}]}
{"op":"mcm","clk":"11450082027","pt":1717317797159,"mc":[{"id":"1.229554901","rc":[{"atb":[[5.7,0]],"id":63027102}],"con":true,"img":false}]}
{"op":"mcm","clk":"11450082040","pt":1717317797261,"mc":[{"id":"1.229554901","rc":[{"atb":[[5.9,9.51]],"id":63027102}],"con":true,"img":false}]}
{"op":"mcm","clk":"11450082047","pt":1717317797362,"mc":[{"id":"1.229554901","rc":[{"atb":[[5.8,0],[5.2,19.02]],"id":63027102}],"con":true,"img":false}]}
{"op":"mcm","clk":"11450082059","pt":1717317797467,"mc":[{"id":"1.229554901","rc":[{"atb":[[5.9,19.02]],"id":63027102}],"con":true,"img":false}]}
{"op":"mcm","clk":"11450082070","pt":1717317797570,"mc":[{"id":"1.229554901","rc":[{"atb":[[5.2,0]],"id":63027102}],"con":true,"img":false}]}
{"op":"mcm","clk":"11450083739","pt":1717317817215,"mc":[{"id":"1.229554901","rc":[{"atb":[[5.9,9.51]],"id":63027102}],"con":true,"img":false}]}
{"op":"mcm","clk":"11450083752","pt":1717317817327,"mc":[{"id":"1.229554901","rc":[{"atb":[[5.4,9.51]],"id":63027102}],"con":true,"img":false}]}
{"op":"mcm","clk":"11450083760","pt":1717317817422,"mc":[{"id":"1.229554901","rc":[{"atb":[[5.2,19.02],[5.9,0]],"id":63027102}],"con":true,"img":false}]}
{"op":"mcm","clk":"11450083770","pt":1717317817526,"mc":[{"id":"1.229554901","rc":[{"atb":[[5.5,19.02],[5.2,0]],"id":63027102}],"con":true,"img":false}]}
{"op":"mcm","clk":"11450085336","pt":1717317837219,"mc":[{"id":"1.229554901","rc":[{"atb":[[5.4,0]],"id":63027102},{"spn":35.25,"spf":"NaN","id":63027102}],"con":true,"img":false}]}
{"op":"mcm","clk":"11450085348","pt":1717317837326,"mc":[{"id":"1.229554901","rc":[{"atb":[[5.6,9.51],[5.5,0],[5.2,23.81]],"id":63027102}],"con":true,"img":false}]}
{"op":"mcm","clk":"11450085357","pt":1717317837427,"mc":[{"id":"1.229554901","rc":[{"atb":[[5.2,0],[5.7,9.51]],"id":63027102}],"con":true,"img":false}]}
{"op":"mcm","clk":"11450087920","pt":1717317867181,"mc":[{"id":"1.229554901","rc":[{"atb":[[5.6,0]],"id":63027102}],"con":true,"img":false}]}
{"op":"mcm","clk":"11450087928","pt":1717317867282,"mc":[{"id":"1.229554901","rc":[{"atb":[[5.8,9.51],[5.2,19.02]],"id":63027102}],"con":true,"img":false}]}
{"op":"mcm","clk":"11450087934","pt":1717317867387,"mc":[{"id":"1.229554901","rc":[{"atb":[[5.7,0]],"id":63027102}],"con":true,"img":false}]}
{"op":"mcm","clk":"11450087943","pt":1717317867446,"mc":[{"id":"1.229554901","rc":[{"atb":[[5.2,0],[5.9,9.51]],"id":63027102}],"con":true,"img":false}]}
{"op":"mcm","clk":"11450089719","pt":1717317887320,"mc":[{"id":"1.229554901","rc":[{"atb":[[5.8,0]],"id":63027102}],"con":true,"img":false}]}
{"op":"mcm","clk":"11450089726","pt":1717317887376,"mc":[{"id":"1.229554901","rc":[{"atb":[[5.4,9.51]],"id":63027102}],"con":true,"img":false}]}
{"op":"mcm","clk":"11450089733","pt":1717317887476,"mc":[{"id":"1.229554901","rc":[{"atb":[[5.2,19.02],[5.9,0]],"id":63027102}],"con":true,"img":false}]}
{"op":"mcm","clk":"11450089743","pt":1717317887582,"mc":[{"id":"1.229554901","rc":[{"atb":[[5.5,19.02]],"id":63027102}],"con":true,"img":false}]}
{"op":"mcm","clk":"11450089752","pt":1717317887685,"mc":[{"id":"1.229554901","rc":[{"atb":[[5.2,0]],"id":63027102}],"con":true,"img":false}]}
{"op":"mcm","clk":"11450091278","pt":1717317904729,"mc":[{"id":"1.229554901","rc":[{"atb":[[1.44,8.91]],"id":47208569},{"spn":2.77,"spf":"NaN","id":47208569}],"con":true,"img":false}]}
{"op":"mcm","clk":"11450091302","pt":1717317904935,"mc":[{"id":"1.229554901","rc":[{"atb":[[1.48,8.18]],"id":70003368}],"con":true,"img":false}]}
{"op":"mcm","clk":"11450091510","pt":1717317907212,"mc":[{"id":"1.229554901","rc":[{"atb":[[5.4,0]],"id":63027102}],"con":true,"img":false}]}
{"op":"mcm","clk":"11450091518","pt":1717317907312,"mc":[{"id":"1.229554901","rc":[{"atb":[[5.6,9.51]],"id":63027102}],"con":true,"img":false}]}
{"op":"mcm","clk":"11450091528","pt":1717317907414,"mc":[{"id":"1.229554901","rc":[{"atb":[[5.2,23.81]],"id":63027102}],"con":true,"img":false}]}
{"op":"mcm","clk":"11450091536","pt":1717317907520,"mc":[{"id":"1.229554901","rc":[{"atb":[[5.5,0]],"id":63027102}],"con":true,"img":false}]}
{"op":"mcm","clk":"11450092374","pt":1717317916831,"mc":[{"id":"1.229554901","rc":[{"atb":[[5.7,9.51]],"id":63027102}],"con":true,"img":false}]}
{"op":"mcm","clk":"11450092383","pt":1717317916935,"mc":[{"id":"1.229554901","rc":[{"atb":[[5.2,0]],"id":63027102}],"con":true,"img":false}]}
{"op":"mcm","clk":"11450092802","pt":1717317921743,"mc":[{"id":"1.229554901","rc":[{"atl":[[5.6,0]],"id":70003368}],"con":true,"img":false}]}
{"op":"mcm","clk":"11450092816","pt":1717317921948,"mc":[{"id":"1.229554901","rc":[{"atl":[[6,6.94]],"id":70003368}],"con":true,"img":false}]}
{"op":"mcm","clk":"11450092843","pt":1717317922313,"mc":[{"id":"1.229554901","rc":[{"atl":[[6,0]],"id":70003368}],"con":true,"img":false}]}
{"op":"mcm","clk":"11450092888","pt":1717317922730,"mc":[{"id":"1.229554901","rc":[{"atl":[[5.6,1.76]],"id":70003368}],"con":true,"img":false}]}
{"op":"mcm","clk":"11450093481","pt":1717317929331,"mc":[{"id":"1.229554901","rc":[{"atb":[[1.46,0],[1.36,0]],"id":70003368},{"atl":[[4.3,0]],"id":70003368},{"atb":[[1.32,55.8],[1.42,0]],"id":47208569},{"atl":[[4.1,0]],"id":47208569},{"atb":[[3.95,0],[4.9,0]],"id":49183855},{"atb":[[5.1,0],[4.1,0]],"id":63027102},{"atb":[[1.01,17.89]],"id":67532289},{"atl":[[2.64,0]],"id":67532289}],"con":true,"img":false}]}
{"op":"mcm","clk":"11450094216","pt":1717317937169,"mc":[{"id":"1.229554901","rc":[{"atb":[[1.34,50.73]],"id":70003368}],"con":true,"img":false}]}
{"op":"mcm","clk":"11450094225","pt":1717317937273,"mc":[{"id":"1.229554901","rc":[{"atb":[[1.47,0]],"id":70003368},{"atb":[[5.6,0]],"id":63027102}],"con":true,"img":false}]}
{"op":"mcm","clk":"11450094236","pt":1717317937382,"mc":[{"id":"1.229554901","rc":[{"atb":[[5.8,9.51]],"id":63027102}],"con":true,"img":false}]}
{"op":"mcm","clk":"11450094245","pt":1717317937482,"mc":[{"id":"1.229554901","rc":[{"atb":[[5.7,0],[4.7,27.03]],"id":63027102}],"con":true,"img":false}]}
{"op":"mcm","clk":"11450095053","pt":1717317946657,"mc":[{"id":"1.229554901","rc":[{"atb":[[5.9,15],[4.7,0]],"id":63027102}],"con":true,"img":false}]}
{"op":"mcm","clk":"11450095070","pt":1717317946860,"mc":[{"id":"1.229554901","rc":[{"atb":[[1.41,84.98],[1.51,45.54]],"id":70003368},{"atl":[[4.6,0.14]],"id":70003368},{"atb":[[1.43,54.02],[1.33,118.49]],"id":47208569},{"atl":[[4.1,0.16]],"id":47208569},{"atb":[[4.5,6.63],[3.75,12.67]],"id":49183855},{"atb":[[4.8,6.11],[3.9,12.01]],"id":63027102},{"atb":[[1.01,5825.15]],"id":67532289},{"atl":[[2.64,0.31]],"id":67532289}],"con":true,"img":false}]}
{"op":"mcm","clk":"11450095361","pt":1717317949872,"mc":[{"id":"1.229554901","rc":[{"atb":[[1.44,0]],"id":47208569}],"con":true,"img":false}]}
{"op":"mcm","clk":"11450095370","pt":1717317949974,"mc":[{"id":"1.229554901","rc":[{"atb":[[1.48,0]],"id":70003368}],"con":true,"img":false}]}
{"op":"mcm","clk":"11450095436","pt":1717317950748,"mc":[{"id":"1.229554901","rc":[{"atb":[[1.45,8.72]],"id":47208569}],"con":true,"img":false}]}
{"op":"mcm","clk":"11450095466","pt":1717317951164,"mc":[{"id":"1.229554901","rc":[{"atb":[[1.53,7.41]],"id":70003368}],"con":true,"img":false}]}
{"op":"mcm","clk":"11450095928","pt":1717317957268,"mc":[{"id":"1.229554901","rc":[{"atb":[[5.8,0]],"id":63027102}],"con":true,"img":false}]}
{"op":"mcm","clk":"11450095934","pt":1717317957372,"mc":[{"id":"1.229554901","rc":[{"atb":[[4.9,25.64],[5.9,0],[5.4,9.51]],"id":63027102}],"con":true,"img":false}]}
{"op":"mcm","clk":"11450096663","pt":1717317965992,"mc":[{"id":"1.229554901","rc":[{"atb":[[1.37,0]],"id":70003368},{"spn":3.06,"spf":"NaN","id":70003368},{"atb":[[1.33,105.58]],"id":47208569},{"spn":2.77,"spf":"NaN","id":47208569},{"spn":35.2,"spf":"NaN","id":63027102}],"con":true,"img":false}]}
{"op":"mcm","clk":"11450096688","pt":1717317966303,"mc":[{"id":"1.229554901","rc":[{"atb":[[5.5,9.51]],"id":63027102}],"con":true,"img":false}]}
{"op":"mcm","clk":"11450096699","pt":1717317966404,"mc":[{"id":"1.229554901","rc":[{"atb":[[4.9,0]],"id":63027102}],"con":true,"img":false}]}
{"op":"mcm","clk":"11450096760","pt":1717317967286,"mc":[{"id":"1.229554901","rc":[{"atb":[[1.32,0]],"id":47208569}],"con":true,"img":false}]}
{"op":"mcm","clk":"11450096770","pt":1717317967397,"mc":[{"id":"1.229554901","rc":[{"atb":[[1.34,55.8]],"id":47208569}],"con":true,"img":false}]}
{"op":"mcm","clk":"11450097562","pt":1717317977182,"mc":[{"id":"1.229554901","rc":[{"atb":[[1.34,0]],"id":70003368},{"atl":[[5.3,0]],"id":47208569},{"atb":[[5.4,0]],"id":63027102}],"con":true,"img":false}]}
{"op":"mcm","clk":"11450097575","pt":1717317977286,"mc":[{"id":"1.229554901","rc":[{"atb":[[1.42,50.73]],"id":70003368},{"atl":[[4.1,9.89]],"id":47208569},{"atb":[[5.6,9.51],[4.9,19.02]],"id":63027102}],"con":true,"img":false}]}
{"op":"mcm","clk":"11450097584","pt":1717317977390,"mc":[{"id":"1.229554901","rc":[{"atb":[[5.5,0]],"id":63027102}],"con":true,"img":false}]}
{"op":"mcm","clk":"11450097593","pt":1717317977489,"mc":[{"id":"1.229554901","rc":[{"atl":[[4,14.65],[4.2,0]],"id":47208569},{"atb":[[4.9,0],[5.7,9.51]],"id":63027102}],"con":true,"img":false}]}
{"op":"mcm","clk":"11450098387","pt":1717317987204,"mc":[{"id":"1.229554901","rc":[{"atl":[[4.1,0.16]],"id":47208569}],"con":true,"img":false}]}
{"op":"mcm","clk":"11450098395","pt":1717317987314,"mc":[{"id":"1.229554901","rc":[{"atl":[[4,0],[4.2,14.82],[5.4,9.73]],"id":47208569}],"con":true,"img":false}]}
{"op":"mcm","clk":"11450099764","pt":1717318003735,"mc":[{"id":"1.229554901","rc":[{"atb":[[1.34,68.34]],"id":47208569}],"con":true,"img":false}]}
{"op":"mcm","clk":"11450099780","pt":1717318003842,"mc":[{"id":"1.229554901","rc":[{"atb":[[1.43,9.91]],"id":70003368}],"con":true,"img":false}]}
{"op":"mcm","clk":"11450100061","pt":1717318007207,"mc":[{"id":"1.229554901","rc":[{"atb":[[5.6,0]],"id":63027102}],"con":true,"img":false}]}
{"op":"mcm","clk":"11450100072","pt":1717318007308,"mc":[{"id":"1.229554901","rc":[{"atb":[[5.8,9.51],[4.9,19.02]],"id":63027102}],"con":true,"img":false}]}
{"op":"mcm","clk":"11450100083","pt":1717318007420,"mc":[{"id":"1.229554901","rc":[{"atb":[[4.9,0],[5.7,0],[5.9,9.51]],"id":63027102}],"con":true,"img":false}]}
{"op":"mcm","clk":"11450101441","pt":1717318023581,"mc":[{"id":"1.229554901","rc":[{"atb":[[1.58,5],[1.54,10],[1.62,2.5],[1.53,19.97]],"id":70003368},{"atl":[[3.35,5],[5.2,12.56],[3.15,2.5],[3.55,10]],"id":70003368},{"atb":[[1.41,5],[1.45,29.63],[1.37,10]],"id":47208569},{"atl":[[3.2,18.41],[2.9,2.5],[2.98,5],[3.15,10]],"id":47208569},{"atb":[[4.5,11.63],[5.1,9.81],[4.9,2.5]],"id":49183855},{"atl":[[38,2.5],[48,1.7]],"id":49183855},{"atb":[[4.6,25],[5,5],[6,6.55],[5.4,2.5]],"id":63027102},{"atl":[[65,2.78]],"id":63027102},{"atb":[[1.12,260.92],[1.09,5],[1.13,2.5],[1.05,10]],"id":67532289},{"atl":[[2.3,10],[1.97,82.47],[2.22,5],[2.14,2.5]],"id":67532289}],"con":true,"img":false}]}
{"op":"mcm","clk":"11450101451","pt":1717318023636,"mc":[{"id":"1.229554901","rc":[{"atl":[[5.3,0],[3.8,10]],"id":70003368},{"atl":[[2.9,7.5],[4.2,0]],"id":47208569},{"atl":[[1.98,0],[1.96,53.66]],"id":67532289}],"con":true,"img":false}]}
{"op":"mcm","clk":"11450101795","pt":1717318027276,"mc":[{"id":"1.229554901","rc":[{"spn":2.38,"spf":"NaN","id":70003368},{"spn":2.17,"spf":"NaN","id":47208569},{"spn":21.55,"spf":"NaN","id":49183855},{"atb":[[5.8,0]],"id":63027102},{"spn":35.5,"spf":"NaN","id":63027102},{"spn":1.54,"spf":"NaN","id":67532289}],"con":true,"img":false}]}
{"op":"mcm","clk":"11450101803","pt":1717318027376,"mc":[{"id":"1.229554901","rc":[{"atb":[[5.4,12.01]],"id":63027102}],"con":true,"img":false}]}
{"op":"mcm","clk":"11450101812","pt":1717318027482,"mc":[{"id":"1.229554901","rc":[{"atb":[[5.9,0],[5.4,28.07]],"id":63027102}],"con":true,"img":false}]}
{"op":"mcm","clk":"11450101828","pt":1717318027686,"mc":[{"id":"1.229554901","rc":[{"atb":[[6,0]],"id":63027102}],"con":true,"img":false}]}
{"op":"mcm","clk":"11450101839","pt":1717318027742,"mc":[{"id":"1.229554901","rc":[{"atb":[[5.8,5.84]],"id":63027102}],"con":true,"img":false}]}
{"op":"mcm","clk":"11450101860","pt":1717318027951,"mc":[{"id":"1.229554901","rc":[{"atb":[[5.8,0]],"id":63027102}],"con":true,"img":false}]}
{"op":"mcm","clk":"11450101873","pt":1717318028158,"mc":[{"id":"1.229554901","rc":[{"atb":[[5.5,4.06]],"id":63027102}],"con":true,"img":false}]}
{"op":"mcm","clk":"11450101924","pt":1717318028787,"mc":[{"id":"1.229554901","rc":[{"atl":[[3.15,22.5]],"id":47208569},{"atl":[[1.98,102.04],[1.96,0]],"id":67532289}],"con":true,"img":false}]}
{"op":"mcm","clk":"11450101930","pt":1717318028844,"mc":[{"id":"1.229554901","rc":[{"atl":[[2.9,2.5]],"id":47208569}],"con":true,"img":false}]}
{"op":"mcm","clk":"11450102709","pt":1717318037198,"mc":[{"id":"1.229554901","rc":[{"atl":[[65,0.17],[70,0]],"id":63027102},{"atb":[[1.11,0]],"id":67532289}],"con":true,"img":false}]}
{"op":"mcm","clk":"11450102718","pt":1717318037308,"mc":[{"id":"1.229554901","rc":[{"atl":[[65,0],[75,2.61],[350,0],[85,2.61],[800,2]],"id":63027102},{"atb":[[1.09,519.02]],"id":67532289}],"con":true,"img":false}]}
{"op":"mcm","clk":"11450102730","pt":1717318037361,"mc":[{"id":"1.229554901","rc":[{"atl":[[360,0.22],[400,2]],"id":63027102}],"con":true,"img":false}]}
{"op":"mcm","clk":"11450102735","pt":1717318037463,"mc":[{"id":"1.229554901","rc":[{"atl":[[800,0]],"id":63027102}],"con":true,"img":false}]}
{"op":"mcm","clk":"11450103081","pt":1717318041002,"mc":[{"id":"1.229554901","rc":[{"atb":[[1.62,10]],"id":70003368},{"atl":[[3,7.5]],"id":70003368},{"atl":[[2.84,20.62]],"id":47208569},{"atl":[[36,2.29]],"id":49183855},{"atl":[[75,3.66]],"id":63027102}],"con":true,"img":false}]}
{"op":"mcm","clk":"11450103090","pt":1717318041101,"mc":[{"id":"1.229554901","rc":[{"atb":[[1.53,7.41]],"id":70003368},{"atl":[[5.2,0]],"id":70003368},{"atl":[[3.2,0],[2.98,23.41],[3.15,10]],"id":47208569},{"atl":[[48,0]],"id":49183855},{"atl":[[360,0]],"id":63027102},{"atb":[[1.13,140.88]],"id":67532289}],"con":true,"img":false}]}
{"op":"mcm","clk":"11450103105","pt":1717318041267,"mc":[{"id":"1.229554901","rc":[{"atb":[[1.12,139.51]],"id":67532289}],"con":true,"img":false}]}
{"op":"mcm","clk":"11450103655","pt":1717318047169,"mc":[{"id":"1.229554901","rc":[{"atl":[[2.88,0]],"id":67532289}],"con":true,"img":false}]}
{"op":"mcm","clk":"11450103666","pt":1717318047275,"mc":[{"id":"1.229554901","rc":[{"atl":[[2.7,26.82]],"id":67532289}],"con":true,"img":false}]}
{"op":"mcm","clk":"11450104587","pt":1717318057191,"mc":[{"id":"1.229554901","rc":[{"atl":[[5.4,0]],"id":70003368},{"atl":[[5.4,0]],"id":47208569},{"atb":[[4.8,0],[5,0]],"id":49183855},{"atb":[[5.4,18.56]],"id":63027102},{"atl":[[75,1.57]],"id":63027102}],"con":true,"img":false}]}
{"op":"mcm","clk":"11450104600","pt":1717318057293,"mc":[{"id":"1.229554901","rc":[{"atl":[[6.2,8.37]],"id":70003368},{"atl":[[4.6,9.73]],"id":47208569},{"atb":[[3.8,19.35],[5.2,10.46]],"id":49183855},{"atb":[[5,27.62],[5.5,13.57]],"id":63027102}],"con":true,"img":false}]}
{"op":"mcm","clk":"11450104615","pt":1717318057398,"mc":[{"id":"1.229554901","rc":[{"atb":[[5.3,3.84]],"id":49183855},{"atb":[[5.4,2.5]],"id":63027102}],"con":true,"img":false}]}
{"op":"mcm","clk":"11450104634","pt":1717318057606,"mc":[{"id":"1.229554901","rc":[{"atb":[[5.1,0]],"id":49183855}],"con":true,"img":false}]}
{"op":"mcm","clk":"11450105357","pt":1717318065319,"mc":[{"id":"1.229554901","rc":[{"atb":[[5.6,13.57],[5,5]],"id":63027102}],"con":true,"img":false}]}
{"op":"mcm","clk":"11450105365","pt":1717318065421,"mc":[{"id":"1.229554901","rc":[{"atb":[[5.7,3.84]],"id":63027102}],"con":true,"img":false}]}
{"op":"mcm","clk":"11450105376","pt":1717318065527,"mc":[{"id":"1.229554901","rc":[{"atb":[[5.5,9.51]],"id":63027102}],"con":true,"img":false}]}
{"op":"mcm","clk":"11450105555","pt":1717318067221,"mc":[{"id":"1.229554901","rc":[{"atl":[[6.8,10.98]],"id":70003368},{"atb":[[1.14,94.95]],"id":67532289}],"con":true,"img":false}]}
{"op":"mcm","clk":"11450105568","pt":1717318067333,"mc":[{"id":"1.229554901","rc":[{"atl":[[6.4,0]],"id":70003368},{"atb":[[5.2,0]],"id":49183855},{"atb":[[4.6,10]],"id":63027102},{"atb":[[1.12,0],[1.14,242.69]],"id":67532289}],"con":true,"img":false}]}
{"op":"mcm","clk":"11450105581","pt":1717318067433,"mc":[{"id":"1.229554901","rc":[{"atb":[[4.8,10.46]],"id":49183855},{"atb":[[4.9,15]],"id":63027102},{"atb":[[1.13,2.5]],"id":67532289}],"con":true,"img":false}]}
{"op":"mcm","clk":"11450105591","pt":1717318067536,"mc":[{"id":"1.229554901","rc":[{"atb":[[5.3,0]],"id":49183855}],"con":true,"img":false}]}
{"op":"mcm","clk":"11450105602","pt":1717318067590,"mc":[{"id":"1.229554901","rc":[{"atb":[[5.1,3.75]],"id":49183855}],"con":true,"img":false}]}
{"op":"mcm","clk":"11450106493","pt":1717318077243,"mc":[{"id":"1.229554901","rc":[{"atl":[[50,0]],"id":49183855}],"con":true,"img":false}]}
{"op":"mcm","clk":"11450106505","pt":1717318077347,"mc":[{"id":"1.229554901","rc":[{"atl":[[34,2.61]],"id":49183855}],"con":true,"img":false}]}
{"op":"mcm","clk":"11450106515","pt":1717318077407,"mc":[{"id":"1.229554901","rc":[{"atl":[[34,5.03]],"id":49183855}],"con":true,"img":false}]}
{"op":"mcm","clk":"11450106527","pt":1717318077510,"mc":[{"id":"1.229554901","rc":[{"atl":[[36,0]],"id":49183855}],"con":true,"img":false}]}
{"op":"mcm","clk":"11450107400","pt":1717318087228,"mc":[{"id":"1.229554901","rc":[{"atl":[[60,0]],"id":49183855},{"atb":[[1.09,5]],"id":67532289}],"con":true,"img":false}]}
{"op":"mcm","clk":"11450107413","pt":1717318087331,"mc":[{"id":"1.229554901","rc":[{"spn":2.31,"spf":"NaN","id":70003368},{"spn":2.14,"spf":"NaN","id":47208569},{"atl":[[48,2.61]],"id":49183855},{"spn":19.55,"spf":"NaN","id":49183855},{"spn":40.35,"spf":"NaN","id":63027102},{"atb":[[1.1,514.02]],"id":67532289},{"spn":1.55,"spf":"NaN","id":67532289}],"con":true,"img":false}]}
{"op":"mcm","clk":"11450107590","pt":1717318089343,"mc":[{"id":"1.229554901","rc":[{"atb":[[5,0],[4.6,0],[5.5,12.01],[5.4,0]],"id":63027102},{"atl":[[2.3,0],[2.22,0],[2.18,5],[2.14,0],[2.1,2.5]],"id":67532289}],"con":true,"img":false}]}
{"op":"mcm","clk":"11450107600","pt":1717318089448,"mc":[{"id":"1.229554901","rc":[{"atb":[[5.2,4.78]],"id":49183855}],"con":true,"img":false}]}
{"op":"mcm","clk":"11450107609","pt":1717318089554,"mc":[{"id":"1.229554901","rc":[{"atb":[[5.1,0]],"id":49183855}],"con":true,"img":false}]}
{"op":"mcm","clk":"11450107697","pt":1717318090544,"mc":[{"id":"1.229554901","rc":[{"atl":[[110,2.5]],"id":63027102}],"con":true,"img":false}]}
{"op":"mcm","clk":"11450107937","pt":1717318093439,"mc":[{"id":"1.229554901","rc":[{"atl":[[2.82,33.02]],"id":47208569}],"con":true,"img":false}]}
{"op":"mcm","clk":"11450107944","pt":1717318093535,"mc":[{"id":"1.229554901","rc":[{"atl":[[2.8,20.62]],"id":47208569}],"con":true,"img":false}]}
{"op":"mcm","clk":"11450107951","pt":1717318093641,"mc":[{"id":"1.229554901","rc":[{"atl":[[2.84,53.64],[2.98,5]],"id":47208569}],"con":true,"img":false}]}
{"op":"mcm","clk":"11450107958","pt":1717318093748,"mc":[{"id":"1.229554901","rc":[{"atl":[[2.8,0]],"id":47208569}],"con":true,"img":false}]}
{"op":"mcm","clk":"11450107963","pt":1717318093850,"mc":[{"id":"1.229554901","rc":[{"atl":[[2.9,55.13],[2.84,0]],"id":47208569}],"con":true,"img":false}]}
{"op":"mcm","clk":"11450108277","pt":1717318097265,"mc":[{"id":"1.229554901","rc":[{"atb":[[5.5,2.5]],"id":63027102},{"atl":[[75,3.66]],"id":63027102},{"atb":[[1.14,147.74]],"id":67532289}],"con":true,"img":false}]}
{"op":"mcm","clk":"11450108281","pt":1717318097365,"mc":[{"id":"1.229554901","rc":[{"atb":[[5.5,19.91],[5.7,13.35]],"id":63027102},{"atb":[[1.15,94.95]],"id":67532289}],"con":true,"img":false}]}
{"op":"mcm","clk":"11450108294","pt":1717318097468,"mc":[{"id":"1.229554901","rc":[{"atb":[[5.6,0]],"id":63027102},{"atb":[[1.15,228.01]],"id":67532289}],"con":true,"img":false}]}
{"op":"mcm","clk":"11450108310","pt":1717318097641,"mc":[{"id":"1.229554901","rc":[{"atb":[[1.14,0]],"id":67532289}],"con":true,"img":false}]}
{"op":"mcm","clk":"11450108626","pt":1717318101665,"mc":[{"id":"1.229554901","rc":[{"atl":[[3.1,2.5],[3.35,0],[3.55,0],[3.3,5],[3.5,10],[3.15,0]],"id":70003368},{"atb":[[5,2.5]],"id":49183855}],"con":true,"img":false}]}
{"op":"mcm","clk":"11450108636","pt":1717318101769,"mc":[{"id":"1.229554901","rc":[{"atb":[[4.5,6.63],[4.9,0]],"id":49183855}],"con":true,"img":false}]}
{"op":"mcm","clk":"11450108708","pt":1717318102550,"mc":[{"id":"1.229554901","rc":[{"atb":[[1.45,20.91]],"id":47208569}],"con":true,"img":false}]}
{"op":"mcm","clk":"11450108720","pt":1717318102650,"mc":[{"id":"1.229554901","rc":[{"atl":[[2.9,2.5],[2.98,55.51]],"id":47208569}],"con":true,"img":false}]}
{"op":"mcm","clk":"11450108936","pt":1717318104874,"mc":[{"id":"1.229554901","rc":[{"atb":[[5.8,15]],"id":63027102}],"con":true,"img":false}]}
{"op":"mcm","clk":"11450108948","pt":1717318104931,"mc":[{"id":"1.229554901","rc":[{"atb":[[5.8,19.72],[5.5,2.5]],"id":63027102}],"con":true,"img":false}]}
{"op":"mcm","clk":"11450108963","pt":1717318105183,"mc":[{"id":"1.229554901","rc":[{"atb":[[5.7,9.51]],"id":63027102}],"con":true,"img":false}]}
{"op":"mcm","clk":"11450109147","pt":1717318107257,"mc":[{"id":"1.229554901","rc":[{"atl":[[34,2.42]],"id":49183855}],"con":true,"img":false}]}
{"op":"mcm","clk":"11450109163","pt":1717318107360,"mc":[{"id":"1.229554901","rc":[{"atl":[[32,2.61]],"id":49183855}],"con":true,"img":false}]}
{"op":"mcm","clk":"11450109172","pt":1717318107461,"mc":[{"id":"1.229554901","rc":[{"atl":[[32,5.19],[34,0]],"id":49183855}],"con":true,"img":false}]}
{"op":"mcm","clk":"11450109590","pt":1717318112450,"mc":[{"id":"1.229554901","rc":[{"atb":[[1.58,0],[1.54,0],[1.62,0]],"id":70003368},{"atl":[[3.1,0],[3,0],[3.3,0],[3.5,0]],"id":70003368},{"atb":[[1.41,0],[1.45,0],[1.37,0]],"id":47208569},{"atl":[[2.82,0],[2.9,0],[2.98,50.51],[3.15,0]],"id":47208569},{"atb":[[5,0],[5.2,0]],"id":49183855},{"atl":[[32,2.61],[38,0]],"id":49183855},{"atb":[[5.8,15],[5.5,0]],"id":63027102},{"atl":[[75,2.61],[110,0]],"id":63027102},{"atb":[[1.15,94.95],[1.09,0],[1.13,0],[1.05,0]],"id":67532289},{"atl":[[1.97,0],[2.18,0],[2.1,0]],"id":67532289}],"con":true,"img":false}]}
{"op":"mcm","clk":"11450109610","pt":1717318112655,"mc":[{"id":"1.229554901","rc":[{"atl":[[2.98,0],[3.15,46.51]],"id":47208569}],"con":true,"img":false}]}
{"op":"mcm","clk":"11450109619","pt":1717318112762,"mc":[{"id":"1.229554901","rc":[{"atl":[[3.15,0],[4.2,31.25]],"id":47208569}],"con":true,"img":false}]}
{"op":"mcm","clk":"11450110017","pt":1717318117172,"mc":[{"id":"1.229554901","rc":[{"atl":[[6.2,0],[6.8,0]],"id":70003368},{"atl":[[5.9,0]],"id":47208569},{"atb":[[4.8,0],[3.8,0]],"id":49183855},{"atb":[[4.9,0],[5.7,0]],"id":63027102},{"atb":[[1.15,0]],"id":67532289},{"atl":[[3.6,0],[2.7,0]],"id":67532289}],"con":true,"img":false}]}
{"op":"mcm","clk":"11450110027","pt":1717318117274,"mc":[{"id":"1.229554901","rc":[{"atl":[[8,8.89],[7.2,8.37]],"id":70003368},{"atl":[[7.4,9.41]],"id":47208569},{"atb":[[2.8,23.24],[2.32,47.08]],"id":49183855},{"atb":[[2.88,22.26],[2.38,39.14]],"id":63027102},{"atb":[[1.14,94.95]],"id":67532289},{"atl":[[4.9,13.17],[3.9,14.43]],"id":67532289}],"con":true,"img":false}]}
{"op":"mcm","clk":"11450110037","pt":1717318117377,"mc":[{"id":"1.229554901","rc":[{"atl":[[5.5,10.15],[3.8,0]],"id":70003368},{"atb":[[4.6,27.78],[4.7,0]],"id":49183855},{"atb":[[5.8,0],[4.9,25.64]],"id":63027102}],"con":true,"img":false}]}
{"op":"mcm","clk":"11450110081","pt":1717318117889,"mc":[{"id":"1.229554901","rc":[{"atb":[[1.45,8.72]],"id":47208569}],"con":true,"img":false}]}
{"op":"mcm","clk":"11450110848","pt":1717318127166,"mc":[{"id":"1.229554901","rc":[{"atb":[[1.42,0]],"id":70003368},{"atb":[[1.34,12.53]],"id":47208569},{"atl":[[32,0]],"id":49183855}],"con":true,"img":false}]}
{"op":"mcm","clk":"11450110859","pt":1717318127293,"mc":[{"id":"1.229554901","rc":[{"atb":[[1.43,60.64]],"id":70003368},{"atb":[[1.37,55.8]],"id":47208569},{"atl":[[25,2.61]],"id":49183855},{"atl":[[75,0],[26,2.61]],"id":63027102}],"con":true,"img":false}]}
{"op":"mcm","clk":"11450111163","pt":1717318130681,"mc":[{"id":"1.229554901","rc":[{"atb":[[1.41,0],[1.51,0]],"id":70003368},{"atl":[[4.6,0]],"id":70003368},{"atb":[[1.43,0],[1.33,0]],"id":47208569},{"atl":[[4.1,0]],"id":47208569},{"atb":[[4.5,0],[3.75,0]],"id":49183855},{"atb":[[4.8,0],[3.9,0]],"id":63027102},{"atb":[[1.01,17.89]],"id":67532289},{"atl":[[2.64,0]],"id":67532289}],"con":true,"img":false}]}
{"op":"mcm","clk":"11450111188","pt":1717318130993,"mc":[{"id":"1.229554901","rc":[{"atl":[[5.6,22.06]],"id":70003368},{"atb":[[2.82,54.95],[4.6,0]],"id":49183855},{"atb":[[4.9,0],[2.98,50.51]],"id":63027102}],"con":true,"img":false}]}
{"op":"mcm","clk":"11450111193","pt":1717318131093,"mc":[{"id":"1.229554901","rc":[{"atl":[[5.5,0]],"id":70003368}],"con":true,"img":false}]}
{"op":"mcm","clk":"11450111295","pt":1717318132599,"mc":[{"id":"1.229554901","rc":[{"atb":[[1.01,155.74]],"id":49183855},{"atb":[[1.01,2.35]],"id":63027102}],"con":true,"img":false}]}
{"op":"mcm","clk":"11450111313","pt":1717318132807,"mc":[{"id":"1.229554901","rc":[{"atb":[[1.01,155.45]],"id":49183855},{"atb":[[1.01,1.91]],"id":63027102}],"con":true,"img":false}]}
{"op":"mcm","clk":"11450111328","pt":1717318132964,"mc":[{"id":"1.229554901","rc":[{"atb":[[1.01,153.38]],"id":49183855}],"con":true,"img":false}]}
{"op":"mcm","clk":"11450111339","pt":1717318133069,"mc":[{"id":"1.229554901","rc":[{"atb":[[2.9,2.06]],"id":49183855}],"con":true,"img":false}]}
{"op":"mcm","clk":"11450111355","pt":1717318133271,"mc":[{"id":"1.229554901","rc":[{"atb":[[1.01,0]],"id":63027102}],"con":true,"img":false}]}
{"op":"mcm","clk":"11450111362","pt":1717318133378,"mc":[{"id":"1.229554901","rc":[{"atb":[[3.05,1.91]],"id":63027102}],"con":true,"img":false}]}
{"op":"mcm","clk":"11450111713","pt":1717318137219,"mc":[{"id":"1.229554901","rc":[{"atl":[[4.6,0]],"id":47208569}],"con":true,"img":false}]}
{"op":"mcm","clk":"11450111725","pt":1717318137323,"mc":[{"id":"1.229554901","rc":[{"atl":[[4.1,9.73]],"id":47208569}],"con":true,"img":false}]}
{"op":"mcm","clk":"11450111737","pt":1717318137427,"mc":[{"id":"1.229554901","rc":[{"atl":[[4,9.73]],"id":47208569}],"con":true,"img":false}]}
{"op":"mcm","clk":"11450111743","pt":1717318137484,"mc":[{"id":"1.229554901","rc":[{"atl":[[4.2,0]],"id":47208569}],"con":true,"img":false}]}
{"op":"mcm","clk":"11450111823","pt":1717318138211,"mc":[{"id":"1.229554901","rc":[{"atb":[[2.82,0],[2.9,25.31]],"id":49183855},{"atb":[[2.98,0],[3.05,24.17]],"id":63027102}],"con":true,"img":false}]}
{"op":"mcm","clk":"11450111988","pt":1717318140287,"mc":[{"id":"1.229554901","rc":[{"atl":[[3.85,17.54],[3.95,25.42],[4.1,40.32],[3.75,7.27]],"id":70003368},{"atl":[[2.3,38.46],[2.38,90.58],[2.26,15.87],[2.34,55.97]],"id":47208569},{"atl":[[34,1.52],[38,2.03],[42,3.05],[30,1]],"id":49183855},{"atb":[[1.12,166.67],[1.06,250],[1.1,764.02],[1.08,250]],"id":67532289},{"atl":[[4.3,15.15],[4.5,21.43],[4.1,6.45],[4.7,33.78]],"id":67532289}],"con":true,"img":false}]}
{"op":"mcm","clk":"11450111995","pt":1717318140395,"mc":[{"id":"1.229554901","rc":[{"atl":[[5.6,1.76],[3.95,34.31]],"id":70003368}],"con":true,"img":false}]}
{"op":"mcm","clk":"11450112089","pt":1717318141485,"mc":[{"id":"1.229554901","rc":[{"atb":[[1.01,1]],"id":63027102}],"con":true,"img":false}]}
{"op":"mcm","clk":"11450112427","pt":1717318144588,"mc":[{"id":"1.229554901","rc":[{"atl":[[4,0],[2.64,60.98]],"id":47208569}],"con":true,"img":false}]}
{"op":"mcm","clk":"11450112652","pt":1717318146927,"mc":[{"id":"1.229554901","rc":[{"atb":[[2.9,23.25]],"id":49183855}],"con":true,"img":false}]}
{"op":"mcm","clk":"11450112669","pt":1717318147087,"mc":[{"id":"1.229554901","rc":[{"atb":[[2.82,46.5],[2.9,0]],"id":49183855}],"con":true,"img":false}]}
{"op":"mcm","clk":"11450112681","pt":1717318147223,"mc":[{"id":"1.229554901","rc":[{"atb":[[2.8,0]],"id":49183855},{"atl":[[85,0]],"id":63027102},{"atb":[[1.1,250],[1.13,395.4]],"id":67532289}],"con":true,"img":false}]}
{"op":"mcm","clk":"11450112695","pt":1717318147302,"mc":[{"id":"1.229554901","rc":[{"atb":[[2.84,23.24]],"id":49183855},{"atl":[[29,2.61]],"id":63027102}],"con":true,"img":false}]}
{"op":"mcm","clk":"11450112704","pt":1717318147408,"mc":[{"id":"1.229554901","rc":[{"spn":2.64,"spf":"NaN","id":70003368},{"spn":1.85,"spf":"NaN","id":47208569},{"atb":[[2.82,0],[2.74,57.47]],"id":49183855},{"spn":13.92,"spf":"NaN","id":49183855},{"spn":14.52,"spf":"NaN","id":63027102},{"spn":1.56,"spf":"NaN","id":67532289}],"con":true,"img":false}]}
{"op":"mcm","clk":"11450112715","pt":1717318147510,"mc":[{"id":"1.229554901","rc":[{"atb":[[2.74,0],[2.86,47.09]],"id":49183855}],"con":true,"img":false}]}
{"op":"mcm","clk":"11450112745","pt":1717318147818,"mc":[{"id":"1.229554901","rc":[{"atb":[[3.05,22.26]],"id":63027102}],"con":true,"img":false}]}
{"op":"mcm","clk":"11450112757","pt":1717318147921,"mc":[{"id":"1.229554901","rc":[{"atb":[[2.98,44.52],[3.05,0]],"id":63027102}],"con":true,"img":false}]}
{"op":"mcm","clk":"11450112792","pt":1717318148245,"mc":[{"id":"1.229554901","rc":[{"atb":[[1.01,3.35]],"id":63027102}],"con":true,"img":false}]}
{"op":"mcm","clk":"11450112834","pt":1717318148495,"mc":[{"id":"1.229554901","rc":[{"atb":[[1.01,2.82]],"id":63027102}],"con":true,"img":false}]}
{"op":"mcm","clk":"11450112853","pt":1717318148710,"mc":[{"id":"1.229554901","rc":[{"atb":[[1.01,1]],"id":63027102}],"con":true,"img":false}]}
{"op":"mcm","clk":"11450112858","pt":1717318148811,"mc":[{"id":"1.229554901","rc":[{"atb":[[3.15,1.82]],"id":63027102}],"con":true,"img":false}]}
{"op":"mcm","clk":"11450113430","pt":1717318154936,"mc":[{"id":"1.229554901","rc":[{"atb":[[3.15,24.08]],"id":63027102}],"con":true,"img":false}]}
{"op":"mcm","clk":"11450113443","pt":1717318155039,"mc":[{"id":"1.229554901","rc":[{"atb":[[2.98,0]],"id":63027102}],"con":true,"img":false}]}
{"op":"mcm","clk":"11450113619","pt":1717318157214,"mc":[{"id":"1.229554901","rc":[{"atb":[[1.43,9.91]],"id":70003368},{"atb":[[1.37,0],[1.25,0]],"id":47208569},{"atl":[[25,0]],"id":49183855},{"atb":[[2.88,0],[5.3,9.73]],"id":63027102},{"atl":[[26,0],[29,0]],"id":63027102},{"atb":[[1.14,0],[1.13,0]],"id":67532289}],"con":true,"img":false}]}
{"op":"mcm","clk":"11450113631","pt":1717318157321,"mc":[{"id":"1.229554901","rc":[{"atb":[[1.37,50.73]],"id":70003368},{"atb":[[1.21,243.8],[1.26,55.8]],"id":47208569},{"atl":[[40,2.61]],"id":49183855},{"atb":[[3.15,1.82],[5.4,22.73]],"id":63027102},{"atl":[[75,2.61],[85,2.61],[400,0],[800,2]],"id":63027102},{"atb":[[1.11,395.4],[1.13,94.95]],"id":67532289}],"con":true,"img":false}]}
{"op":"mcm","clk":"11450113662","pt":1717318157734,"mc":[{"id":"1.229554901","rc":[{"atl":[[140,1],[90,1],[100,1],[120,1]],"id":63027102}],"con":true,"img":false}]}
{"op":"mcm","clk":"11450114006","pt":1717318161413,"mc":[{"id":"1.229554901","rc":[{"atl":[[3.95,25.42],[4.1,72.58]],"id":70003368},{"atl":[[2.88,53.19],[2.64,0]],"id":47208569},{"atl":[[1.98,0],[2.12,89.29]],"id":67532289}],"con":true,"img":false}]}
{"op":"mcm","clk":"11450114028","pt":1717318161667,"mc":[{"id":"1.229554901","rc":[{"atl":[[2.16,2.99]],"id":67532289}],"con":true,"img":false}]}
{"op":"mcm","clk":"11450114044","pt":1717318161826,"mc":[{"id":"1.229554901","rc":[{"atb":[[1.43,0]],"id":70003368},{"atb":[[1.34,0]],"id":47208569}],"con":true,"img":false}]}
{"op":"mcm","clk":"11450114078","pt":1717318162239,"mc":[{"id":"1.229554901","rc":[{"atb":[[2.94,2.19]],"id":49183855}],"con":true,"img":false}]}
{"op":"mcm","clk":"11450114086","pt":1717318162345,"mc":[{"id":"1.229554901","rc":[{"atb":[[2.94,25.44]],"id":49183855}],"con":true,"img":false}]}
{"op":"mcm","clk":"11450114096","pt":1717318162445,"mc":[{"id":"1.229554901","rc":[{"atb":[[2.86,0]],"id":49183855}],"con":true,"img":false}]}
{"op":"mcm","clk":"11450114209","pt":1717318163640,"mc":[{"id":"1.229554901","rc":[{"atl":[[2.16,0]],"id":67532289}],"con":true,"img":false}]}
{"op":"mcm","clk":"11450114262","pt":1717318164148,"mc":[{"id":"1.229554901","rc":[{"atl":[[2.16,2.99]],"id":67532289}],"con":true,"img":false}]}
{"op":"mcm","clk":"11450114272","pt":1717318164214,"mc":[{"id":"1.229554901","rc":[{"atl":[[470,2]],"id":63027102}],"con":true,"img":false}]}
{"op":"mcm","clk":"11450114279","pt":1717318164310,"mc":[{"id":"1.229554901","rc":[{"atl":[[800,0]],"id":63027102}],"con":true,"img":false}]}
{"op":"mcm","clk":"11450114345","pt":1717318165041,"mc":[{"id":"1.229554901","rc":[{"atb":[[1.17,100]],"id":63027102}],"con":true,"img":false}]}
{"op":"mcm","clk":"11450114475","pt":1717318166534,"mc":[{"id":"1.229554901","rc":[{"atb":[[1.49,47.4],[1.39,89.34]],"id":70003368},{"atl":[[4.4,0.15]],"id":70003368},{"atb":[[1.43,54.02],[1.33,105.58]],"id":47208569},{"atl":[[4.1,9.89]],"id":47208569},{"atb":[[3.85,12.22],[4.7,6.27]],"id":49183855},{"atb":[[4.8,6.11],[3.9,12.01]],"id":63027102},{"atb":[[1.01,5825.15]],"id":67532289},{"atl":[[2.64,0.31]],"id":67532289}],"con":true,"img":false}]}
{"op":"mcm","clk":"11450114488","pt":1717318166651,"mc":[{"id":"1.229554901","rc":[{"atb":[[2.94,2.19],[4.7,18.5]],"id":49183855}],"con":true,"img":false}]}
{"op":"mcm","clk":"11450114506","pt":1717318166854,"mc":[{"id":"1.229554901","rc":[{"atb":[[3.9,23.25],[4.7,6.27]],"id":49183855}],"con":true,"img":false}]}
{"op":"mcm","clk":"11450114540","pt":1717318167220,"mc":[{"id":"1.229554901","rc":[{"atl":[[48,0]],"id":49183855}],"con":true,"img":false}]}
{"op":"mcm","clk":"11450114554","pt":1717318167330,"mc":[{"id":"1.229554901","rc":[{"atl":[[50,2.61]],"id":49183855}],"con":true,"img":false}]}
{"op":"mcm","clk":"11450114866","pt":1717318170834,"mc":[{"id":"1.229554901","rc":[{"atl":[[3.95,50.84]],"id":70003368},{"atl":[[2.64,60.98]],"id":47208569},{"atl":[[1.98,2.99],[2.12,0]],"id":67532289}],"con":true,"img":false}]}
{"op":"mcm","clk":"11450114875","pt":1717318170940,"mc":[{"id":"1.229554901","rc":[{"atl":[[4.1,40.32]],"id":70003368},{"atl":[[2.88,0]],"id":47208569}],"con":true,"img":false}]}
{"op":"mcm","clk":"11450114889","pt":1717318171146,"mc":[{"id":"1.229554901","rc":[{"atl":[[400,2],[470,0]],"id":63027102}],"con":true,"img":false}]}
{"op":"mcm","clk":"11450115119","pt":1717318173715,"mc":[{"id":"1.229554901","rc":[{"atb":[[3.9,0],[4.7,18.5]],"id":49183855}],"con":true,"img":false}]}
{"op":"mcm","clk":"11450115398","pt":1717318177231,"mc":[{"id":"1.229554901","rc":[{"atl":[[7.2,0],[3.9,14.43]],"id":70003368},{"atb":[[2.84,0],[4.4,12.31]],"id":49183855},{"atl":[[75,0]],"id":63027102},{"atl":[[3.9,0]],"id":67532289}],"con":true,"img":false}]}
{"op":"mcm","clk":"11450115412","pt":1717318177334,"mc":[{"id":"1.229554901","rc":[{"atl":[[65,2.61]],"id":63027102},{"atl":[[3.1,14.43]],"id":67532289}],"con":true,"img":false}]}
{"op":"mcm","clk":"11450115426","pt":1717318177533,"mc":[{"id":"1.229554901","rc":[{"atl":[[3.85,35.08]],"id":70003368}],"con":true,"img":false}]}
{"op":"mcm","clk":"11450115435","pt":1717318177651,"mc":[{"id":"1.229554901","rc":[{"atl":[[3.95,25.42]],"id":70003368}],"con":true,"img":false}]}
{"op":"mcm","clk":"11450115610","pt":1717318179980,"mc":[{"id":"1.229554901","rc":[{"atl":[[2.42,14.08],[3.75,0]],"id":70003368},{"atl":[[4.3,0],[4.5,0],[4.1,0],[4.7,0]],"id":67532289}],"con":true,"img":false}]}
{"op":"mcm","clk":"11450115618","pt":1717318180037,"mc":[{"id":"1.229554901","rc":[{"atl":[[3.6,28.16]],"id":70003368}],"con":true,"img":false}]}
{"op":"mcm","clk":"11450115629","pt":1717318180136,"mc":[{"id":"1.229554901","rc":[{"atl":[[3.85,17.54]],"id":70003368}],"con":true,"img":false}]}
{"op":"mcm","clk":"11450115748","pt":1717318181548,"mc":[{"id":"1.229554901","rc":[{"atb":[[1.57,5],[1.53,51.69],[1.61,2.5]],"id":70003368},{"atl":[[3.25,5],[3.05,2.5],[5.6,0],[3.45,10],[2.42,48.36]],"id":70003368},{"atb":[[1.41,5],[1.45,80.58],[1.37,10]],"id":47208569},{"atl":[[2.26,79.36]],"id":47208569},{"atb":[[4.8,10.7],[4.5,10],[5.3,2.5],[4.9,5]],"id":49183855},{"atl":[[38,4.53],[30,3.76]],"id":49183855},{"atb":[[4.8,11.11],[5.5,6.55],[5.2,2.5],[4.4,10]],"id":63027102},{"atl":[[65,2.78]],"id":63027102},{"atb":[[1.13,170.91]],"id":67532289},{"atl":[[1.97,73.46],[2.18,5],[2.26,10],[2.1,2.5]],"id":67532289}],"con":true,"img":false}]}
{"op":"mcm","clk":"11450115923","pt":1717318183474,"mc":[{"id":"1.229554901","rc":[{"atb":[[1.32,0],[1.39,178.68]],"id":70003368},{"atl":[[2.5,66.67],[2.64,0]],"id":47208569},{"atl":[[85,3.61],[90,0]],"id":63027102},{"atl":[[1.98,0],[1.95,2.99]],"id":67532289}],"con":true,"img":false}]}
{"op":"mcm","clk":"11450115931","pt":1717318183573,"mc":[{"id":"1.229554901","rc":[{"atl":[[350,2],[100,3.5],[400,0]],"id":63027102}],"con":true,"img":false}]}
{"op":"mcm","clk":"11450116120","pt":1717318185562,"mc":[{"id":"1.229554901","rc":[{"atb":[[1.17,100]],"id":49183855}],"con":true,"img":false}]}
{"op":"mcm","clk":"11450116290","pt":1717318187161,"mc":[{"id":"1.229554901","rc":[{"atl":[[3.5,20.56]],"id":67532289}],"con":true,"img":false}]}
{"op":"mcm","clk":"11450116306","pt":1717318187268,"mc":[{"id":"1.229554901","rc":[{"atb":[[1.37,0]],"id":70003368},{"atl":[[4.9,0]],"id":67532289}],"con":true,"img":false}]}
{"op":"mcm","clk":"11450116313","pt":1717318187367,"mc":[{"id":"1.229554901","rc":[{"atb":[[1.4,50.73]],"id":70003368}],"con":true,"img":false}]}
{"op":"mcm","clk":"11450116585","pt":1717318190270,"mc":[{"id":"1.229554901","rc":[{"atl":[[2.46,34.25]],"id":70003368}],"con":true,"img":false}]}
{"op":"mcm","clk":"11450116842","pt":1717318193164,"mc":[{"id":"1.229554901","rc":[{"atb":[[1.53,44.28]],"id":70003368},{"atb":[[1.45,71.86]],"id":47208569}],"con":true,"img":false}]}
{"op":"mcm","clk":"11450117107","pt":1717318195854,"mc":[{"id":"1.229554901","rc":[{"atb":[[1.61,31.94]],"id":70003368},{"atb":[[5.6,6.22]],"id":49183855},{"atl":[[1.94,85.11]],"id":67532289}],"con":true,"img":false}]}
{"op":"mcm","clk":"11450117118","pt":1717318195963,"mc":[{"id":"1.229554901","rc":[{"atb":[[1.53,10]],"id":70003368},{"atb":[[4.8,0],[4.9,15.7],[4.7,6.27]],"id":49183855},{"atl":[[1.97,0]],"id":67532289}],"con":true,"img":false}]}
{"op":"mcm","clk":"11450117225","pt":1717318197155,"mc":[{"id":"1.229554901","rc":[{"atl":[[8,0],[5.3,14.64]],"id":70003368},{"atl":[[7.4,0],[4.9,15.69]],"id":47208569},{"atb":[[2.32,0],[4.6,17.26]],"id":49183855},{"atb":[[4.9,13.84],[2.38,0]],"id":63027102}],"con":true,"img":false}]}
{"op":"mcm","clk":"11450117233","pt":1717318197258,"mc":[{"id":"1.229554901","rc":[{"atb":[[1.33,0]],"id":70003368},{"atb":[[1.26,0]],"id":47208569},{"atb":[[1.11,0]],"id":67532289}],"con":true,"img":false}]}
{"op":"mcm","clk":"11450117242","pt":1717318197364,"mc":[{"id":"1.229554901","rc":[{"atb":[[1.27,224.44]],"id":70003368},{"atb":[[1.34,55.8]],"id":47208569},{"atb":[[1.14,395.4]],"id":67532289}],"con":true,"img":false}]}
{"op":"mcm","clk":"11450117251","pt":1717318197469,"mc":[{"id":"1.229554901","rc":[{"atb":[[1.14,584.23]],"id":67532289}],"con":true,"img":false}]}
{"op":"mcm","clk":"11450117260","pt":1717318197573,"mc":[{"id":"1.229554901","rc":[{"atb":[[1.13,97.45]],"id":67532289}],"con":true,"img":false}]}
{"op":"mcm","clk":"11450117483","pt":1717318200495,"mc":[{"id":"1.229554901","rc":[{"atl":[[2.5,50],[4.1,0]],"id":70003368}],"con":true,"img":false}]}
{"op":"mcm","clk":"11450117695","pt":1717318202796,"mc":[{"id":"1.229554901","rc":[{"atb":[[1.41,10.39]],"id":70003368}],"con":true,"img":false}]}
{"op":"mcm","clk":"11450117775","pt":1717318203677,"mc":[{"id":"1.229554901","rc":[{"atb":[[2.94,0]],"id":49183855}],"con":true,"img":false}]}
{"op":"mcm","clk":"11450117941","pt":1717318205404,"mc":[{"id":"1.229554901","rc":[{"atl":[[60,5]],"id":70003368},{"atl":[[60,5]],"id":47208569},{"atl":[[60,5]],"id":67532289}],"con":true,"img":false}]}
{"op":"mcm","clk":"11450118089","pt":1717318207178,"mc":[{"id":"1.229554901","rc":[{"atb":[[4.4,0]],"id":49183855},{"atb":[[5.3,0]],"id":63027102},{"atb":[[1.14,188.83],[1.13,2.5]],"id":67532289}],"con":true,"img":false}]}
{"op":"mcm","clk":"11450118108","pt":1717318207386,"mc":[{"id":"1.229554901","rc":[{"atb":[[5,12.31]],"id":49183855},{"atb":[[5.5,16.28],[5.2,26.31],[5.4,0]],"id":63027102},{"atb":[[1.14,283.78],[1.13,397.9]],"id":67532289}],"con":true,"img":false}]}
{"op":"mcm","clk":"11450118132","pt":1717318207588,"mc":[{"id":"1.229554901","rc":[{"spn":2.01,"spf":"NaN","id":70003368},{"atb":[[5.1,12.31],[4.9,5]],"id":49183855},{"spn":17.8,"spf":"NaN","id":49183855},{"spn":35.25,"spf":"NaN","id":63027102},{"spn":1.54,"spf":"NaN","id":67532289}],"con":true,"img":false}]}
{"op":"mcm","clk":"11450118141","pt":1717318207693,"mc":[{"id":"1.229554901","rc":[{"atb":[[1.51,7.69]],"id":70003368}],"con":true,"img":false}]}
{"op":"mcm","clk":"11450118207","pt":1717318208365,"mc":[{"id":"1.229554901","rc":[{"atl":[[3.95,0]],"id":70003368}],"con":true,"img":false}]}
{"op":"mcm","clk":"11450118370","pt":1717318210503,"mc":[{"id":"1.229554901","rc":[{"atl":[[2.54,81.17]],"id":70003368}],"con":true,"img":false}]}
{"op":"mcm","clk":"11450118456","pt":1717318211484,"mc":[{"id":"1.229554901","rc":[{"atl":[[3.85,0]],"id":70003368}],"con":true,"img":false}]}
{"op":"mcm","clk":"11450118650","pt":1717318213869,"mc":[{"id":"1.229554901","rc":[{"atb":[[5.6,16.28],[5.2,2.5]],"id":63027102}],"con":true,"img":false}]}
{"op":"mcm","clk":"11450118660","pt":1717318213969,"mc":[{"id":"1.229554901","rc":[{"atb":[[5.6,21.62]],"id":63027102}],"con":true,"img":false}]}
{"op":"mcm","clk":"11450118667","pt":1717318214069,"mc":[{"id":"1.229554901","rc":[{"atb":[[5.5,9.73]],"id":63027102}],"con":true,"img":false}]}
{"op":"mcm","clk":"11450118949","pt":1717318217183,"mc":[{"id":"1.229554901","rc":[{"atl":[[3.1,0],[2.76,23.77]],"id":67532289}],"con":true,"img":false}]}
{"op":"mcm","clk":"11450118960","pt":1717318217288,"mc":[{"id":"1.229554901","rc":[{"atl":[[3.9,0]],"id":70003368},{"atl":[[40,0]],"id":49183855}],"con":true,"img":false}]}
{"op":"mcm","clk":"11450118970","pt":1717318217393,"mc":[{"id":"1.229554901","rc":[{"atl":[[3.55,14.43]],"id":70003368},{"atl":[[36,2.61]],"id":49183855}],"con":true,"img":false}]}
{"op":"mcm","clk":"11450119434","pt":1717318222672,"mc":[{"id":"1.229554901","rc":[{"atb":[[3.15,0]],"id":63027102}],"con":true,"img":false}]}
{"op":"mcm","clk":"11450119864","pt":1717318227181,"mc":[{"id":"1.229554901","rc":[{"atb":[[1.14,188.83]],"id":67532289}],"con":true,"img":false}]}
{"op":"mcm","clk":"11450119875","pt":1717318227284,"mc":[{"id":"1.229554901","rc":[{"atb":[[1.15,94.95]],"id":67532289}],"con":true,"img":false}]}
{"op":"mcm","clk":"11450119888","pt":1717318227390,"mc":[{"id":"1.229554901","rc":[{"atb":[[1.15,230]],"id":67532289}],"con":true,"img":false}]}
{"op":"mcm","clk":"11450119909","pt":1717318227596,"mc":[{"id":"1.229554901","rc":[{"atb":[[1.14,0]],"id":67532289}],"con":true,"img":false}]}
{"op":"mcm","clk":"11450120740","pt":1717318237174,"mc":[{"id":"1.229554901","rc":[{"atb":[[1.21,0]],"id":47208569}],"con":true,"img":false}]}
{"op":"mcm","clk":"11450120750","pt":1717318237280,"mc":[{"id":"1.229554901","rc":[{"atb":[[1.25,243.8]],"id":47208569}],"con":true,"img":false}]}
{"op":"mcm","clk":"11450120930","pt":1717318239511,"mc":[{"id":"1.229554901","rc":[{"atb":[[5.3,0],[4.9,0],[5.4,2.5],[4.5,0],[5,17.31],[5.7,4.78]],"id":49183855},{"atb":[[5.6,24.12],[4.4,0],[5.7,5.34]],"id":63027102}],"con":true,"img":false}]}
{"op":"mcm","clk":"11450120937","pt":1717318239614,"mc":[{"id":"1.229554901","rc":[{"atb":[[5.6,0],[5.1,0],[5.2,12.31]],"id":49183855},{"atl":[[36,5.11]],"id":49183855},{"atb":[[5.6,18.78]],"id":63027102}],"con":true,"img":false}]}
{"op":"mcm","clk":"11450120948","pt":1717318239720,"mc":[{"id":"1.229554901","rc":[{"atl":[[38,2.03]],"id":49183855}],"con":true,"img":false}]}
{"op":"mcm","clk":"11450121568","pt":1717318247218,"mc":[{"id":"1.229554901","rc":[{"atb":[[5,5],[4.6,0],[4.1,21.45]],"id":49183855},{"atl":[[36,2.5]],"id":49183855},{"atb":[[5.5,0]],"id":63027102}],"con":true,"img":false}]}
{"op":"mcm","clk":"11450121578","pt":1717318247322,"mc":[{"id":"1.229554901","rc":[{"atb":[[5.2,24.62]],"id":49183855},{"atl":[[40,2.61]],"id":49183855},{"atb":[[5.7,15.07]],"id":63027102}],"con":true,"img":false}]}
{"op":"mcm","clk":"11450121585","pt":1717318247426,"mc":[{"id":"1.229554901","rc":[{"atb":[[5.6,2.5],[5.2,26.31]],"id":63027102}],"con":true,"img":false}]}
{"op":"mcm","clk":"11450122032","pt":1717318252594,"mc":[{"id":"1.229554901","rc":[{"atb":[[5.8,5.34]],"id":63027102}],"con":true,"img":false}]}
{"op":"mcm","clk":"11450122053","pt":1717318252802,"mc":[{"id":"1.229554901","rc":[{"atb":[[5.7,9.73]],"id":63027102}],"con":true,"img":false}]}
{"op":"mcm","clk":"11450122132","pt":1717318253521,"mc":[{"id":"1.229554901","rc":[{"atb":[[5.8,10.68],[5.2,2.5]],"id":63027102}],"con":true,"img":false}]}
{"op":"mcm","clk":"11450122440","pt":1717318257195,"mc":[{"id":"1.229554901","rc":[{"atb":[[1.15,135.05]],"id":67532289}],"con":true,"img":false}]}
{"op":"mcm","clk":"11450122447","pt":1717318257303,"mc":[{"id":"1.229554901","rc":[{"atb":[[1.15,0],[1.16,94.95]],"id":67532289}],"con":true,"img":false}]}
{"op":"mcm","clk":"11450122458","pt":1717318257404,"mc":[{"id":"1.229554901","rc":[{"atb":[[1.13,563.02]],"id":67532289}],"con":true,"img":false}]}
{"op":"mcm","clk":"11450122498","pt":1717318257924,"mc":[{"id":"1.229554901","rc":[{"atl":[[2.26,0],[2.1,0],[2.08,2.5],[2.18,0],[2.16,7.99]],"id":67532289}],"con":true,"img":false}]}
{"op":"mcm","clk":"11450123269","pt":1717318267222,"mc":[{"id":"1.229554901","rc":[{"atb":[[1.16,0]],"id":67532289}],"con":true,"img":false}]}
{"op":"mcm","clk":"11450123277","pt":1717318267325,"mc":[{"id":"1.229554901","rc":[{"atb":[[1.14,94.95]],"id":67532289}],"con":true,"img":false}]}
{"op":"mcm","clk":"11450123283","pt":1717318267429,"mc":[{"id":"1.229554901","rc":[{"atl":[[2.28,15.63],[2.26,63.49]],"id":47208569}],"con":true,"img":false}]}
{"op":"mcm","clk":"11450123345","pt":1717318268260,"mc":[{"id":"1.229554901","rc":[{"atl":[[2.28,0],[2.26,79.36]],"id":47208569},{"spn":17.85,"spf":"NaN","id":49183855},{"spn":35.4,"spf":"NaN","id":63027102}],"con":true,"img":false}]}
{"op":"mcm","clk":"11450123381","pt":1717318268734,"mc":[{"id":"1.229554901","rc":[{"atb":[[1.49,0],[1.39,89.34]],"id":70003368},{"atl":[[4.4,0]],"id":70003368},{"atb":[[1.43,0],[1.33,0]],"id":47208569},{"atl":[[4.1,9.73]],"id":47208569},{"atb":[[3.85,0],[4.7,0]],"id":49183855},{"atb":[[4.8,5],[3.9,0]],"id":63027102},{"atb":[[1.01,17.89]],"id":67532289},{"atl":[[2.64,0]],"id":67532289}],"con":true,"img":false}]}
{"op":"mcm","clk":"11450123501","pt":1717318270122,"mc":[{"id":"1.229554901","rc":[{"atb":[[1.14,230]],"id":67532289}],"con":true,"img":false}]}
{"op":"mcm","clk":"11450123517","pt":1717318270329,"mc":[{"id":"1.229554901","rc":[{"atb":[[1.13,397.9]],"id":67532289}],"con":true,"img":false}]}
{"op":"mcm","clk":"11450124119","pt":1717318277052,"mc":[{"id":"1.229554901","rc":[{"atb":[[1.28,250],[1.26,250],[1.32,62.5],[1.3,166.67]],"id":47208569}],"con":true,"img":false}]}
{"op":"mcm","clk":"11450124135","pt":1717318277259,"mc":[{"id":"1.229554901","rc":[{"atb":[[5.2,12.31]],"id":49183855}],"con":true,"img":false}]}
{"op":"mcm","clk":"11450124144","pt":1717318277361,"mc":[{"id":"1.229554901","rc":[{"atb":[[5.3,12.31]],"id":49183855}],"con":true,"img":false}]}
{"op":"mcm","clk":"11450125011","pt":1717318287339,"mc":[{"id":"1.229554901","rc":[{"atb":[[5.7,0]],"id":63027102}],"con":true,"img":false}]}
{"op":"mcm","clk":"11450125018","pt":1717318287438,"mc":[{"id":"1.229554901","rc":[{"atb":[[5.9,9.73]],"id":63027102}],"con":true,"img":false}]}
{"op":"mcm","clk":"11450125027","pt":1717318287541,"mc":[{"id":"1.229554901","rc":[{"atb":[[5.8,5.34],[6,5.34],[5.2,15.68]],"id":63027102}],"con":true,"img":false}]}
{"op":"mcm","clk":"11450125037","pt":1717318287646,"mc":[{"id":"1.229554901","rc":[{"atb":[[5.8,0]],"id":63027102}],"con":true,"img":false}]}
{"op":"mcm","clk":"11450125080","pt":1717318288062,"mc":[{"id":"1.229554901","rc":[{"atb":[[1.48,48.39],[1.38,91.69]],"id":70003368},{"atl":[[4.4,0.15]],"id":70003368},{"atb":[[1.46,50.49],[1.36,96.78]],"id":47208569},{"atl":[[4.3,0.15]],"id":47208569},{"atb":[[3.85,12.22],[4.7,6.27]],"id":49183855},{"atb":[[3.95,11.81],[4.9,19.8]],"id":63027102},{"atb":[[1.01,5825.15]],"id":67532289},{"atl":[[2.6,0.32]],"id":67532289}],"con":true,"img":false}]}
{"op":"mcm","clk":"11450125092","pt":1717318288166,"mc":[{"id":"1.229554901","rc":[{"atb":[[1.46,130.34]],"id":47208569}],"con":true,"img":false}]}
{"op":"mcm","clk":"11450125104","pt":1717318288273,"mc":[{"id":"1.229554901","rc":[{"atb":[[1.45,2.5]],"id":47208569}],"con":true,"img":false}]}
{"op":"mcm","clk":"11450125511","pt":1717318293139,"mc":[{"id":"1.229554901","rc":[{"atb":[[6,10.68]],"id":63027102}],"con":true,"img":false}]}
{"op":"mcm","clk":"11450125521","pt":1717318293241,"mc":[{"id":"1.229554901","rc":[{"atb":[[5.2,2.5]],"id":63027102}],"con":true,"img":false}]}
{"op":"mcm","clk":"11450125584","pt":1717318294062,"mc":[{"id":"1.229554901","rc":[{"atl":[[2.28,15.63]],"id":47208569}],"con":true,"img":false}]}
{"op":"mcm","clk":"11450125591","pt":1717318294165,"mc":[{"id":"1.229554901","rc":[{"atl":[[2.26,63.49]],"id":47208569}],"con":true,"img":false}]}
{"op":"mcm","clk":"11450125624","pt":1717318294579,"mc":[{"id":"1.229554901","rc":[{"atb":[[5.9,4.7],[5.4,0],[5.6,2.5],[5,0],[5.2,17.31]],"id":49183855}],"con":true,"img":false}]}
{"op":"mcm","clk":"11450125639","pt":1717318294782,"mc":[{"id":"1.229554901","rc":[{"atb":[[5.7,0]],"id":49183855}],"con":true,"img":false}]}
{"op":"mcm","clk":"11450125693","pt":1717318295355,"mc":[{"id":"1.229554901","rc":[{"atl":[[2.28,0],[2.26,79.36]],"id":47208569}],"con":true,"img":false}]}
{"op":"mcm","clk":"11450125819","pt":1717318296955,"mc":[{"id":"1.229554901","rc":[{"atl":[[2.28,15.63]],"id":47208569}],"con":true,"img":false}]}
{"op":"mcm","clk":"11450125825","pt":1717318297057,"mc":[{"id":"1.229554901","rc":[{"atl":[[2.26,63.49]],"id":47208569}],"con":true,"img":false}]}
{"op":"mcm","clk":"11450125834","pt":1717318297159,"mc":[{"id":"1.229554901","rc":[{"atb":[[1.14,135.05]],"id":67532289}],"con":true,"img":false}]}
{"op":"mcm","clk":"11450125844","pt":1717318297263,"mc":[{"id":"1.229554901","rc":[{"atb":[[1.15,94.95]],"id":67532289}],"con":true,"img":false}]}
{"op":"mcm","clk":"11450125850","pt":1717318297364,"mc":[{"id":"1.229554901","rc":[{"atb":[[1.15,230]],"id":67532289}],"con":true,"img":false}]}
{"op":"mcm","clk":"11450125870","pt":1717318297573,"mc":[{"id":"1.229554901","rc":[{"atb":[[1.14,0]],"id":67532289}],"con":true,"img":false}]}
{"op":"mcm","clk":"11450126131","pt":1717318300643,"mc":[{"id":"1.229554901","rc":[{"atl":[[2.28,0],[2.26,79.36]],"id":47208569}],"con":true,"img":false}]}
{"op":"mcm","clk":"11450126170","pt":1717318301048,"mc":[{"id":"1.229554901","rc":[{"atl":[[2.28,15.63],[2.26,63.49]],"id":47208569}],"con":true,"img":false}]}
{"op":"mcm","clk":"11450126188","pt":1717318301257,"mc":[{"id":"1.229554901","rc":[{"atl":[[120,3.5]],"id":63027102}],"con":true,"img":false}]}
{"op":"mcm","clk":"11450126196","pt":1717318301320,"mc":[{"id":"1.229554901","rc":[{"atl":[[2.4,14.29],[2.42,34.28]],"id":70003368},{"atl":[[29,1],[30,2.76]],"id":49183855},{"atb":[[3.1,47.62],[6,5.34]],"id":63027102},{"atl":[[65,2.61],[85,2.61],[95,1],[100,1]],"id":63027102},{"atl":[[1.94,88.1],[1.95,0]],"id":67532289}],"con":true,"img":false}]}
{"op":"mcm","clk":"11450126215","pt":1717318301518,"mc":[{"id":"1.229554901","rc":[{"atl":[[2.4,48.96]],"id":70003368},{"atl":[[29,3.86]],"id":49183855}],"con":true,"img":false}]}
{"op":"mcm","clk":"11450126226","pt":1717318301628,"mc":[{"id":"1.229554901","rc":[{"atl":[[2.42,0]],"id":70003368},{"atl":[[30,0]],"id":49183855}],"con":true,"img":false}]}
{"op":"mcm","clk":"11450126715","pt":1717318307210,"mc":[{"id":"1.229554901","rc":[{"atb":[[5.9,0]],"id":63027102}],"con":true,"img":false}]}
{"op":"mcm","clk":"11450126725","pt":1717318307314,"mc":[{"id":"1.229554901","rc":[{"atb":[[5.3,9.73],[6,0]],"id":63027102}],"con":true,"img":false}]}
{"op":"mcm","clk":"11450126740","pt":1717318307468,"mc":[{"id":"1.229554901","rc":[{"atb":[[5.8,3.84]],"id":63027102}],"con":true,"img":false}]}
{"op":"mcm","clk":"11450127359","pt":1717318315160,"mc":[{"id":"1.229554901","rc":[{"atl":[[2.16,5]],"id":67532289}],"con":true,"img":false}]}
{"op":"mcm","clk":"11450127542","pt":1717318317345,"mc":[{"id":"1.229554901","rc":[{"atb":[[1.34,0]],"id":47208569}],"con":true,"img":false}]}
{"op":"mcm","clk":"11450127552","pt":1717318317448,"mc":[{"id":"1.229554901","rc":[{"atb":[[1.37,65.8]],"id":47208569}],"con":true,"img":false}]}
{"op":"mcm","clk":"11450127822","pt":1717318320559,"mc":[{"id":"1.229554901","rc":[{"atb":[[1.25,0]],"id":47208569}],"con":true,"img":false}]}
{"op":"mcm","clk":"11450127831","pt":1717318320669,"mc":[{"id":"1.229554901","rc":[{"atb":[[1.29,243.8]],"id":47208569}],"con":true,"img":false}]}
{"op":"mcm","clk":"11450128141","pt":1717318323851,"mc":[{"id":"1.229554901","rc":[{"atb":[[1.48,0],[1.38,0]],"id":70003368},{"atl":[[4.4,0]],"id":70003368},{"atb":[[1.46,79.85],[1.36,0]],"id":47208569},{"atl":[[4.3,0]],"id":47208569},{"atb":[[3.95,0],[4.9,13.84]],"id":63027102}],"con":true,"img":false}]}
{"op":"mcm","clk":"11450128452","pt":1717318327243,"mc":[{"id":"1.229554901","rc":[{"atb":[[1.15,135.05]],"id":67532289}],"con":true,"img":false}]}
{"op":"mcm","clk":"11450128460","pt":1717318327345,"mc":[{"id":"1.229554901","rc":[{"atb":[[1.16,94.95]],"id":67532289}],"con":true,"img":false}]}
{"op":"mcm","clk":"11450128470","pt":1717318327450,"mc":[{"id":"1.229554901","rc":[{"atb":[[1.16,232.24],[1.15,0]],"id":67532289}],"con":true,"img":false}]}
{"op":"mcm","clk":"11450128747","pt":1717318330238,"mc":[{"id":"1.229554901","rc":[{"spn":2.0,"spf":"NaN","id":70003368},{"atb":[[1.36,55.56],[1.32,0]],"id":47208569},{"spn":1.86,"spf":"NaN","id":47208569},{"spn":17.45,"spf":"NaN","id":49183855},{"atb":[[1.12,0],[1.14,142.86]],"id":67532289},{"spn":1.55,"spf":"NaN","id":67532289}],"con":true,"img":false}]}
{"op":"mcm","clk":"11450128884","pt":1717318331849,"mc":[{"id":"1.229554901","rc":[{"atl":[[2.38,14.49],[2.28,0]],"id":47208569}],"con":true,"img":false}]}
{"op":"mcm","clk":"11450128895","pt":1717318332054,"mc":[{"id":"1.229554901","rc":[{"atl":[[2.26,0]],"id":47208569}],"con":true,"img":false}]}
{"op":"mcm","clk":"11450128905","pt":1717318332161,"mc":[{"id":"1.229554901","rc":[{"atl":[[2.3,100]],"id":47208569}],"con":true,"img":false}]}
{"op":"mcm","clk":"11450129268","pt":1717318336095,"mc":[{"id":"1.229554901","rc":[{"atb":[[1.46,50.49],[1.36,96.78]],"id":70003368},{"atl":[[4.3,0.15]],"id":70003368},{"atb":[[1.48,48.39],[1.38,91.69]],"id":47208569},{"atl":[[4.4,0.15]],"id":47208569},{"atb":[[4.8,11.11],[3.9,12.01]],"id":63027102}],"con":true,"img":false}]}
{"op":"mcm","clk":"11450129288","pt":1717318336259,"mc":[{"id":"1.229554901","rc":[{"atb":[[1.48,126.66]],"id":47208569}],"con":true,"img":false}]}
{"op":"mcm","clk":"11450129309","pt":1717318336469,"mc":[{"id":"1.229554901","rc":[{"atb":[[1.46,0]],"id":47208569}],"con":true,"img":false}]}
{"op":"mcm","clk":"11450129350","pt":1717318336979,"mc":[{"id":"1.229554901","rc":[{"atl":[[2.3,61.54]],"id":47208569}],"con":true,"img":false}]}
{"op":"mcm","clk":"11450129358","pt":1717318337083,"mc":[{"id":"1.229554901","rc":[{"atl":[[2.3,0]],"id":47208569}],"con":true,"img":false}]}
{"op":"mcm","clk":"11450129366","pt":1717318337137,"mc":[{"id":"1.229554901","rc":[{"atl":[[2.92,2.5],[3.2,10],[3,5],[2.34,70.59]],"id":47208569}],"con":true,"img":false}]}
{"op":"mcm","clk":"11450129443","pt":1717318338069,"mc":[{"id":"1.229554901","rc":[{"atb":[[1.12,250]],"id":67532289}],"con":true,"img":false}]}
{"op":"mcm","clk":"11450129510","pt":1717318338797,"mc":[{"id":"1.229554901","rc":[{"atl":[[2.34,14.62],[2.4,14.29]],"id":47208569},{"atb":[[1.12,166.67],[1.14,0],[1.06,0]],"id":67532289}],"con":true,"img":false}]}
{"op":"mcm","clk":"11450129520","pt":1717318338851,"mc":[{"id":"1.229554901","rc":[{"atl":[[2.34,0]],"id":47208569}],"con":true,"img":false}]}
{"op":"mcm","clk":"11450129530","pt":1717318338953,"mc":[{"id":"1.229554901","rc":[{"atl":[[2.36,14.47]],"id":47208569}],"con":true,"img":false}]}
{"op":"mcm","clk":"11450129603","pt":1717318339679,"mc":[{"id":"1.229554901","rc":[{"atl":[[2.38,0]],"id":47208569}],"con":true,"img":false}]}
{"op":"mcm","clk":"11450129920","pt":1717318343783,"mc":[{"id":"1.229554901","rc":[{"atb":[[1.51,0]],"id":70003368}],"con":true,"img":false}]}
{"op":"mcm","clk":"11450130130","pt":1717318346484,"mc":[{"id":"1.229554901","rc":[{"atl":[[2.44,34.72]],"id":47208569},{"atb":[[1.06,250]],"id":67532289}],"con":true,"img":false}]}
{"op":"mcm","clk":"11450130141","pt":1717318346692,"mc":[{"id":"1.229554901","rc":[{"atl":[[2.36,0]],"id":47208569}],"con":true,"img":false}]}
{"op":"mcm","clk":"11450130150","pt":1717318346790,"mc":[{"id":"1.229554901","rc":[{"atl":[[2.5,0],[2.4,28.76],[2.52,65.79]],"id":47208569}],"con":true,"img":false}]}
{"op":"mcm","clk":"11450130192","pt":1717318347261,"mc":[{"id":"1.229554901","rc":[{"atb":[[1.37,10]],"id":47208569},{"atl":[[4.9,0]],"id":47208569},{"atb":[[1.16,137.29]],"id":67532289}],"con":true,"img":false}]}
{"op":"mcm","clk":"11450130199","pt":1717318347363,"mc":[{"id":"1.229554901","rc":[{"atb":[[1.39,55.8]],"id":47208569},{"atl":[[5.3,15.69]],"id":47208569},{"atb":[[1.14,94.95]],"id":67532289}],"con":true,"img":false}]}
{"op":"mcm","clk":"11450130204","pt":1717318347465,"mc":[{"id":"1.229554901","rc":[{"atb":[[1.16,0]],"id":67532289}],"con":true,"img":false}]}
{"op":"mcm","clk":"11450130212","pt":1717318347571,"mc":[{"id":"1.229554901","rc":[{"atb":[[1.14,232.24]],"id":67532289}],"con":true,"img":false}]}
{"op":"mcm","clk":"11450130354","pt":1717318349077,"mc":[{"id":"1.229554901","rc":[{"atb":[[3.2,1.93]],"id":63027102}],"con":true,"img":false}]}
{"op":"mcm","clk":"11450130669","pt":1717318352860,"mc":[{"id":"1.229554901","rc":[{"atb":[[5.3,14.73],[5.7,2.5]],"id":63027102}],"con":true,"img":false}]}
{"op":"mcm","clk":"11450130681","pt":1717318353010,"mc":[{"id":"1.229554901","rc":[{"atb":[[4.8,6.11],[5.6,0],[5.2,0]],"id":63027102}],"con":true,"img":false}]}
{"op":"mcm","clk":"11450130704","pt":1717318353280,"mc":[{"id":"1.229554901","rc":[{"atb":[[5.9,3.93]],"id":63027102}],"con":true,"img":false}]}
{"op":"mcm","clk":"11450130720","pt":1717318353481,"mc":[{"id":"1.229554901","rc":[{"atb":[[5.8,0]],"id":63027102}],"con":true,"img":false}]}
{"op":"mcm","clk":"11450130809","pt":1717318354101,"mc":[{"id":"1.229554901","rc":[{"atl":[[2.48,50.68]],"id":47208569}],"con":true,"img":false}]}
{"op":"mcm","clk":"11450131154","pt":1717318357980,"mc":[{"id":"1.229554901","rc":[{"atb":[[1.48,8.18]],"id":70003368}],"con":true,"img":false}]}
{"op":"mcm","clk":"11450131447","pt":1717318361510,"mc":[{"id":"1.229554901","rc":[{"atl":[[2.52,148.03]],"id":47208569}],"con":true,"img":false}]}
{"op":"mcm","clk":"11450131918","pt":1717318367222,"mc":[{"id":"1.229554901","rc":[{"atb":[[5.3,5]],"id":63027102},{"atb":[[1.14,137.29]],"id":67532289}],"con":true,"img":false}]}
{"op":"mcm","clk":"11450131929","pt":1717318367284,"mc":[{"id":"1.229554901","rc":[{"atb":[[6,9.73]],"id":63027102},{"atb":[[1.15,94.95]],"id":67532289}],"con":true,"img":false}]}
{"op":"mcm","clk":"11450131939","pt":1717318367384,"mc":[{"id":"1.229554901","rc":[{"atb":[[6.2,3.93]],"id":63027102},{"atb":[[1.15,232.24]],"id":67532289}],"con":true,"img":false}]}
{"op":"mcm","clk":"11450131951","pt":1717318367535,"mc":[{"id":"1.229554901","rc":[{"atb":[[5.9,0]],"id":63027102},{"atb":[[1.14,0]],"id":67532289}],"con":true,"img":false}]}
{"op":"mcm","clk":"11450132075","pt":1717318368784,"mc":[{"id":"1.229554901","rc":[{"atl":[[2.3,15.38]],"id":47208569}],"con":true,"img":false}]}
{"op":"mcm","clk":"11450132086","pt":1717318368886,"mc":[{"id":"1.229554901","rc":[{"atl":[[2.32,47.61],[2.4,14.47]],"id":47208569}],"con":true,"img":false}]}
{"op":"mcm","clk":"11450132101","pt":1717318369095,"mc":[{"id":"1.229554901","rc":[{"atl":[[2.4,0]],"id":47208569}],"con":true,"img":false}]}
{"op":"mcm","clk":"11450132595","pt":1717318375223,"mc":[{"id":"1.229554901","rc":[{"atb":[[1.29,0]],"id":47208569}],"con":true,"img":false}]}
{"op":"mcm","clk":"11450132603","pt":1717318375319,"mc":[{"id":"1.229554901","rc":[{"atb":[[1.31,196.71]],"id":47208569}],"con":true,"img":false}]}
{"op":"mcm","clk":"11450132652","pt":1717318376003,"mc":[{"id":"1.229554901","rc":[{"atl":[[2.34,37.31]],"id":47208569}],"con":true,"img":false}]}
{"op":"mcm","clk":"11450132938","pt":1717318379526,"mc":[{"id":"1.229554901","rc":[{"atl":[[2.3,54.9]],"id":47208569}],"con":true,"img":false}]}
{"op":"mcm","clk":"11450132944","pt":1717318379630,"mc":[{"id":"1.229554901","rc":[{"atl":[[2.32,0]],"id":47208569}],"con":true,"img":false}]}
{"op":"mcm","clk":"11450133248","pt":1717318383123,"mc":[{"id":"1.229554901","rc":[{"atl":[[2.44,0],[2.48,0],[2.52,65.79],[2.38,54.35]],"id":47208569}],"con":true,"img":false}]}
{"op":"mcm","clk":"11450133273","pt":1717318383436,"mc":[{"id":"1.229554901","rc":[{"atl":[[2.24,16.13],[2.52,0],[2.46,68.49]],"id":47208569},{"atl":[[1.92,5],[1.94,85.11],[1.93,86.02]],"id":67532289}],"con":true,"img":false}]}
{"op":"mcm","clk":"11450133285","pt":1717318383485,"mc":[{"id":"1.229554901","rc":[{"atb":[[1.14,142.86]],"id":67532289}],"con":true,"img":false}]}
{"op":"mcm","clk":"11450133294","pt":1717318383592,"mc":[{"id":"1.229554901","rc":[{"atb":[[1.12,0]],"id":67532289},{"atl":[[1.94,0]],"id":67532289}],"con":true,"img":false}]}
{"op":"mcm","clk":"11450133788","pt":1717318389800,"mc":[{"id":"1.229554901","rc":[{"atl":[[2.24,56.21]],"id":47208569}],"con":true,"img":false}]}
{"op":"mcm","clk":"11450133799","pt":1717318389906,"mc":[{"id":"1.229554901","rc":[{"atb":[[1.46,0],[1.36,0]],"id":70003368},{"atl":[[4.3,0]],"id":70003368},{"atb":[[1.48,78.27],[1.38,0]],"id":47208569},{"atl":[[2.3,15.37],[4.4,0]],"id":47208569},{"atb":[[3.85,0],[4.7,0]],"id":49183855},{"atb":[[4.8,0],[3.9,0]],"id":63027102}],"con":true,"img":false}]}
{"op":"mcm","clk":"11450133821","pt":1717318390111,"mc":[{"id":"1.229554901","rc":[{"atb":[[1.48,0]],"id":47208569},{"atl":[[2.26,15.87]],"id":47208569}],"con":true,"img":false}]}
{"op":"mcm","clk":"11450133833","pt":1717318390220,"mc":[{"id":"1.229554901","rc":[{"atb":[[1.46,15.29]],"id":47208569},{"atl":[[2.24,40.08]],"id":47208569}],"con":true,"img":false}]}
{"op":"mcm","clk":"11450133853","pt":1717318390427,"mc":[{"id":"1.229554901","rc":[{"spn":1.85,"spf":"NaN","id":47208569},{"spn":35.6,"spf":"NaN","id":63027102},{"atb":[[1.12,250]],"id":67532289},{"spn":1.53,"spf":"NaN","id":67532289}],"con":true,"img":false}]}
{"op":"mcm","clk":"11450134055","pt":1717318392922,"mc":[{"id":"1.229554901","rc":[{"atb":[[6,0]],"id":63027102}],"con":true,"img":false}]}
{"op":"mcm","clk":"11450134065","pt":1717318393024,"mc":[{"id":"1.229554901","rc":[{"atb":[[5.6,9.73]],"id":63027102}],"con":true,"img":false}]}
{"op":"mcm","clk":"11450134073","pt":1717318393127,"mc":[{"id":"1.229554901","rc":[{"atb":[[6.2,0]],"id":63027102}],"con":true,"img":false}]}
{"op":"mcm","clk":"11450134083","pt":1717318393232,"mc":[{"id":"1.229554901","rc":[{"atb":[[5.9,3.93]],"id":63027102}],"con":true,"img":false}]}
{"op":"mcm","clk":"11450134122","pt":1717318393645,"mc":[{"id":"1.229554901","rc":[{"atl":[[1.91,87.91]],"id":67532289}],"con":true,"img":false}]}
{"op":"mcm","clk":"11450134132","pt":1717318393699,"mc":[{"id":"1.229554901","rc":[{"atl":[[1.93,0]],"id":67532289}],"con":true,"img":false}]}
{"op":"mcm","clk":"11450134402","pt":1717318397005,"mc":[{"id":"1.229554901","rc":[{"atb":[[1.34,147.06]],"id":47208569}],"con":true,"img":false}]}
{"op":"mcm","clk":"11450134423","pt":1717318397312,"mc":[{"id":"1.229554901","rc":[{"atb":[[1.31,0]],"id":47208569},{"atb":[[1.06,0]],"id":67532289}],"con":true,"img":false}]}
{"op":"mcm","clk":"11450134431","pt":1717318397413,"mc":[{"id":"1.229554901","rc":[{"atb":[[1.29,196.71]],"id":47208569}],"con":true,"img":false}]}
{"op":"mcm","clk":"11450134695","pt":1717318400722,"mc":[{"id":"1.229554901","rc":[{"atb":[[1.12,166.67],[1.14,0]],"id":67532289},{"atl":[[1.92,0],[1.94,92.91]],"id":67532289}],"con":true,"img":false}]}
{"op":"mcm","clk":"11450134730","pt":1717318401243,"mc":[{"id":"1.229554901","rc":[{"atb":[[1.46,50.49],[1.36,96.78]],"id":70003368},{"atl":[[4.3,0.15]],"id":70003368},{"atb":[[1.43,54.02],[1.33,105.58]],"id":47208569},{"atl":[[4.1,9.89]],"id":47208569},{"atb":[[3.85,12.22],[4.7,6.27]],"id":49183855},{"atb":[[5.1,5.66],[4.1,11.23]],"id":63027102}],"con":true,"img":false}]}
{"op":"mcm","clk":"11450134940","pt":1717318403738,"mc":[{"id":"1.229554901","rc":[{"atl":[[2.26,0],[2.24,56.21]],"id":47208569}],"con":true,"img":false}]}
{"op":"mcm","clk":"11450135246","pt":1717318407211,"mc":[{"id":"1.229554901","rc":[{"atb":[[1.39,0]],"id":47208569},{"atb":[[1.15,137.29]],"id":67532289}],"con":true,"img":false}]}
{"op":"mcm","clk":"11450135255","pt":1717318407312,"mc":[{"id":"1.229554901","rc":[{"atb":[[1.37,65.8]],"id":47208569},{"atb":[[1.16,94.95]],"id":67532289}],"con":true,"img":false}]}
{"op":"mcm","clk":"11450135260","pt":1717318407412,"mc":[{"id":"1.229554901","rc":[{"atb":[[1.26,0]],"id":47208569},{"atb":[[1.16,235.85],[1.15,0],[1.06,250]],"id":67532289},{"atl":[[1.91,0]],"id":67532289}],"con":true,"img":false}]}
{"op":"mcm","clk":"11450135268","pt":1717318407517,"mc":[{"id":"1.229554901","rc":[{"atl":[[1.9,88.89]],"id":67532289}],"con":true,"img":false}]}
{"op":"mcm","clk":"11450135277","pt":1717318407625,"mc":[{"id":"1.229554901","rc":[{"atl":[[1.89,88.89]],"id":67532289}],"con":true,"img":false}]}
{"op":"mcm","clk":"11450135287","pt":1717318407724,"mc":[{"id":"1.229554901","rc":[{"atl":[[1.89,178.78],[1.9,0],[1.94,0]],"id":67532289}],"con":true,"img":false}]}
{"op":"mcm","clk":"11450135297","pt":1717318407837,"mc":[{"id":"1.229554901","rc":[{"atl":[[1.89,89.89],[1.94,106.38]],"id":67532289}],"con":true,"img":false}]}
{"op":"mcm","clk":"11450135307","pt":1717318407936,"mc":[{"id":"1.229554901","rc":[{"atl":[[1.89,0]],"id":67532289}],"con":true,"img":false}]}
{"op":"mcm","clk":"11450135316","pt":1717318408037,"mc":[{"id":"1.229554901","rc":[{"atl":[[1.93,86.02]],"id":67532289}],"con":true,"img":false}]}
{"op":"mcm","clk":"11450135331","pt":1717318408249,"mc":[{"id":"1.229554901","rc":[{"atb":[[1.53,46.94],[1.39,0]],"id":70003368},{"atl":[[3.6,0],[3.25,49.44],[2.76,11.36],[2.4,34.67]],"id":70003368},{"atb":[[1.6,2.5],[1.45,0],[1.37,55.8],[1.08,171.4],[1.41,0],[1.56,5],[1.55,39.52],[1.17,0],[1.52,10]],"id":47208569},{"atl":[[3.05,48.78],[2.24,40.08],[2.38,14.49],[2.46,0]],"id":47208569},{"atb":[[5.6,0],[5.2,0],[2.2,83.33],[5.9,0]],"id":49183855},{"atl":[[36,2.86],[13.5,1.6],[14.5,7.27],[16.5,5],[18.5,10],[100,0],[29,2.86]],"id":49183855},{"atb":[[3.1,0],[4.1,22.47]],"id":63027102},{"atl":[[60,1.36],[19.5,1.08],[350,0],[21,2.5],[95,0],[100,3],[25,5],[29,10],[120,1]],"id":63027102},{"atb":[[1.18,5],[1.14,10],[1.22,2.5],[1.13,395.4]],"id":67532289},{"atl":[[2.32,75.76],[1.94,0],[2.16,0],[2.08,0]],"id":67532289}],"con":true,"img":false}]}
{"op":"mcm","clk":"11450135341","pt":1717318408350,"mc":[{"id":"1.229554901","rc":[{"atl":[[2.4,0]],"id":70003368},{"atb":[[1.46,0]],"id":47208569},{"atl":[[2.24,0]],"id":47208569},{"atl":[[2.4,2.5],[2.56,10],[2.48,5]],"id":67532289}],"con":true,"img":false}]}
{"op":"mcm","clk":"11450135352","pt":1717318408452,"mc":[{"id":"1.229554901","rc":[{"atl":[[2.44,40.68]],"id":70003368},{"atl":[[2.28,39.52]],"id":47208569},{"atl":[[29,0]],"id":49183855},{"atl":[[1.93,0]],"id":67532289}],"con":true,"img":false}]}
{"op":"mcm","clk":"11450135363","pt":1717318408512,"mc":[{"id":"1.229554901","rc":[{"atb":[[5.8,2.5],[5.4,5]],"id":63027102},{"atl":[[1.95,60.57]],"id":67532289}],"con":true,"img":false}]}
{"op":"mcm","clk":"11450135373","pt":1717318408606,"mc":[{"id":"1.229554901","rc":[{"atl":[[2.46,0]],"id":70003368},{"atl":[[2.3,0]],"id":47208569},{"atb":[[5.3,0],[5.7,0]],"id":63027102}],"con":true,"img":false}]}
{"op":"mcm","clk":"11450135381","pt":1717318408716,"mc":[{"id":"1.229554901","rc":[{"atl":[[1.95,0]],"id":67532289}],"con":true,"img":false}]}
{"op":"mcm","clk":"11450135393","pt":1717318408816,"mc":[{"id":"1.229554901","rc":[{"atl":[[2.44,0]],"id":70003368},{"atl":[[2.28,0]],"id":47208569},{"atl":[[2.3,49.18]],"id":67532289}],"con":true,"img":false}]}
{"op":"mcm","clk":"11450135401","pt":1717318408919,"mc":[{"id":"1.229554901","rc":[{"atl":[[2.5,98.58]],"id":70003368},{"atl":[[2.34,76.16]],"id":47208569}],"con":true,"img":false}]}
{"op":"mcm","clk":"11450135560","pt":1717318410927,"mc":[{"id":"1.229554901","rc":[{"trd":[[13.5,3.2]],"ltp":13.5,"tv":3.2,"id":49183855},{"atl":[[13.5,0]],"id":49183855}],"con":true,"img":false}]}
{"op":"mcm","clk":"11450135702","pt":1717318412637,"mc":[{"id":"1.229554901","rc":[{"atl":[[2.4,73.93]],"id":67532289}],"con":true,"img":false}]}
{"op":"mcm","clk":"11450135712","pt":1717318412741,"mc":[{"id":"1.229554901","rc":[{"atl":[[2.32,0]],"id":67532289}],"con":true,"img":false}]}
{"op":"mcm","clk":"11450135720","pt":1717318412843,"mc":[{"id":"1.229554901","rc":[{"atl":[[2.3,0]],"id":67532289}],"con":true,"img":false}]}
{"op":"mcm","clk":"11450135729","pt":1717318412947,"mc":[{"id":"1.229554901","rc":[{"atl":[[2.34,40.64]],"id":67532289}],"con":true,"img":false}]}
{"op":"mcm","clk":"11450135748","pt":1717318413155,"mc":[{"id":"1.229554901","rc":[{"atl":[[2.5,1.89]],"id":67532289}],"con":true,"img":false}]}
{"op":"mcm","clk":"11450135768","pt":1717318413364,"mc":[{"id":"1.229554901","rc":[{"atb":[[1.08,0],[1.16,111.37]],"id":47208569},{"atl":[[2.92,54.58],[3.05,0]],"id":47208569},{"atb":[[2.4,71.43],[2.2,0]],"id":49183855},{"atb":[[4.1,11.23],[4.9,27.69]],"id":63027102}],"con":true,"img":false}]}
{"op":"mcm","clk":"11450135795","pt":1717318413676,"mc":[{"id":"1.229554901","rc":[{"atl":[[2.5,48.58]],"id":70003368},{"atl":[[2.34,38.85]],"id":47208569},{"atl":[[13.5,1.51]],"id":49183855}],"con":true,"img":false}]}
{"op":"mcm","clk":"11450135809","pt":1717318413828,"mc":[{"id":"1.229554901","rc":[{"atl":[[2.5,0]],"id":70003368},{"atl":[[2.34,0]],"id":47208569}],"con":true,"img":false}]}
{"op":"mcm","clk":"11450135817","pt":1717318413937,"mc":[{"id":"1.229554901","rc":[{"atl":[[2.54,113.64]],"id":70003368},{"atl":[[2.4,14.62]],"id":47208569}],"con":true,"img":false}]}
{"op":"mcm","clk":"11450135830","pt":1717318414043,"mc":[{"id":"1.229554901","rc":[{"atl":[[2.92,2.5],[2.64,29.11]],"id":47208569}],"con":true,"img":false}]}
{"op":"mcm","clk":"11450135893","pt":1717318414763,"mc":[{"id":"1.229554901","rc":[{"atb":[[1.48,0]],"id":70003368},{"atl":[[2.8,27.78],[2.54,32.47]],"id":70003368},{"atl":[[2.42,35.21]],"id":47208569},{"atl":[[21,5]],"id":63027102}],"con":true,"img":false}]}
{"op":"mcm","clk":"11450135905","pt":1717318414814,"mc":[{"id":"1.229554901","rc":[{"atl":[[2.54,0]],"id":70003368}],"con":true,"img":false}]}
{"op":"mcm","clk":"11450135914","pt":1717318414932,"mc":[{"id":"1.229554901","rc":[{"atl":[[2.78,29.36]],"id":70003368}],"con":true,"img":false}]}
{"op":"mcm","clk":"11450135967","pt":1717318415564,"mc":[{"id":"1.229554901","rc":[{"atl":[[140,0],[100,2],[120,0]],"id":63027102}],"con":true,"img":false}]}
{"op":"mcm","clk":"11450136097","pt":1717318417043,"mc":[{"id":"1.229554901","rc":[{"atl":[[2.4,2.5],[2.48,72.57]],"id":67532289}],"con":true,"img":false}]}
{"op":"mcm","clk":"11450136105","pt":1717318417145,"mc":[{"id":"1.229554901","rc":[{"atb":[[1.4,0]],"id":70003368},{"atl":[[5.3,0],[3.55,0]],"id":70003368},{"atb":[[5.3,0]],"id":49183855},{"atb":[[1.22,36.73]],"id":67532289}],"con":true,"img":false}]}
{"op":"mcm","clk":"11450136116","pt":1717318417249,"mc":[{"id":"1.229554901","rc":[{"atb":[[1.37,50.73]],"id":70003368},{"atl":[[5.7,14.64],[4.7,14.43]],"id":70003368},{"atb":[[2.52,10],[2.6,5],[4.4,12.31],[2.68,2.5]],"id":49183855},{"atb":[[1.16,94.95]],"id":67532289}],"con":true,"img":false}]}
{"op":"mcm","clk":"11450136191","pt":1717318418025,"mc":[{"id":"1.229554901","rc":[{"atb":[[1.6,24.33]],"id":47208569},{"atl":[[13,6.67]],"id":49183855},{"atl":[[19.5,5.4]],"id":63027102}],"con":true,"img":false}]}
{"op":"mcm","clk":"11450136200","pt":1717318418129,"mc":[{"id":"1.229554901","rc":[{"atb":[[1.55,0]],"id":47208569},{"atl":[[14.5,2.5]],"id":49183855},{"atl":[[60,0]],"id":63027102}],"con":true,"img":false}]}
{"op":"mcm","clk":"11450136208","pt":1717318418232,"mc":[{"id":"1.229554901","rc":[{"atl":[[2.76,54.22]],"id":70003368},{"atl":[[2.38,43.7]],"id":47208569}],"con":true,"img":false}]}
