{"op":"mcm","clk":"11448127641","pt":1717286034978,"mc":[{"id":"1.229554910","marketDefinition":{"bspMarket":true,"turnInPlayEnabled":false,"persistenceEnabled":false,"marketBaseRate":7.0,"eventId":"33318908","eventTypeId":"4339","numberOfWinners":1,"bettingType":"ODDS","marketType":"WIN","marketTime":"2024-06-02T09:42:00.000Z","suspendTime":"2024-06-02T09:42:00.000Z","bspReconciled":false,"complete":true,"inPlay":false,"crossMatching":true,"runnersVoidable":false,"numberOfActiveRunners":6,"betDelay":0,"status":"OPEN","runners":[{"status":"ACTIVE","sortPriority":1,"id":69676139,"name":"1. Kilkerran"},{"status":"ACTIVE","sortPriority":2,"id":54867443,"name":"2. Pumpkin Party"},{"status":"ACTIVE","sortPriority":3,"id":52272946,"name":"3. Irish Gem"},{"status":"ACTIVE","sortPriority":4,"id":55943164,"name":"5. Lektra Ringo"},{"status":"ACTIVE","sortPriority":5,"id":70003369,"name":"6. Rickis Burner"},{"status":"ACTIVE","sortPriority":6,"id":69033911,"name":"7. Elegant Evie"}],"regulators":["MR_INT"],"venue":"Murray Bridge","countryCode":"AU","discountAllowed":true,"timezone":"Australia/Adelaide","openDate":"2024-06-02T08:21:00.000Z","version":5962317640,"name":"R5 395m Gr6","eventName":"Murray Bridge (AUS) 2nd Jun"},"rc":[],"con":true,"img":false}]}
{"op":"mcm","clk":"11448135506","pt":1717286146256,"mc":[{"id":"1.229554910","marketDefinition":{"bspMarket":true,"turnInPlayEnabled":false,"persistenceEnabled":false,"marketBaseRate":7.0,"eventId":"33318908","eventTypeId":"4339","numberOfWinners":1,"bettingType":"ODDS","marketType":"WIN","marketTime":"2024-06-02T09:38:00.000Z","suspendTime":"2024-06-02T09:38:00.000Z","bspReconciled":false,"complete":true,"inPlay":false,"crossMatching":true,"runnersVoidable":false,"numberOfActiveRunners":6,"betDelay":0,"status":"OPEN","runners":[{"status":"ACTIVE","sortPriority":1,"id":69676139,"name":"1. Kilkerran"},{"status":"ACTIVE","sortPriority":2,"id":54867443,"name":"2. Pumpkin Party"},{"status":"ACTIVE","sortPriority":3,"id":52272946,"name":"3. Irish Gem"},{"status":"ACTIVE","sortPriority":4,"id":55943164,"name":"5. Lektra Ringo"},{"status":"ACTIVE","sortPriority":5,"id":70003369,"name":"6. Rickis Burner"},{"status":"ACTIVE","sortPriority":6,"id":69033911,"name":"7. Elegant Evie"}],"regulators":["MR_INT"],"venue":"Murray Bridge","countryCode":"AU","discountAllowed":true,"timezone":"Australia/Adelaide","openDate":"2024-06-02T08:21:00.000Z","version":5962327392,"name":"R5 395m Gr6","eventName":"Murray Bridge (AUS) 2nd Jun"},"rc":[],"con":true,"img":false}]}
{"op":"mcm","clk":"11448234888","pt":1717287584386,"mc":[{"id":"1.229554910","rc":[{"atl":[[2.66,2.61]],"id":69676139},{"spn":1.0,"spf":"NaN","id":69676139}],"con":true,"img":false}]}
{"op":"mcm","clk":"11448258036","pt":1717287872067,"mc":[{"id":"1.229554910","rc":[{"atb":[[4.3,31.67],[3.9,72.08],[3.65,78.88]],"id":70003369},{"atl":[[34,6.33],[22,6.63]],"id":70003369},{"spn":13.15,"spf":"NaN","id":70003369},{"atb":[[4.8,55.01],[5.8,21.77],[5.3,48.61]],"id":69033911},{"atl":[[48,4.44],[29,4.97]],"id":69033911},{"spn":17.4,"spf":"NaN","id":69033911},{"atb":[[1.73,143.19],[1.63,331.84],[1.68,307.44]],"id":69676139},{"atl":[[4,46.45],[5,52.26]],"id":69676139},{"spn":2.19,"spf":"NaN","id":69676139},{"atb":[[70,1.51],[38,5.65],[48,4.44]],"id":52272946},{"atl":[[630,0.21],[730,0.28]],"id":52272946},{"spn":350.0,"spf":"NaN","id":52272946},{"atb":[[3.4,87.1],[3.9,36.04],[3.65,78.88]],"id":55943164},{"atl":[[19,7.74],[28,7.74]],"id":55943164},{"spn":11.45,"spf":"NaN","id":55943164},{"atb":[[4.8,55.01],[5.8,21.77],[5.3,48.61]],"id":54867443},{"atl":[[48,4.44],[29,4.97]],"id":54867443},{"spn":17.4,"spf":"NaN","id":54867443}],"con":true,"img":false}]}
{"op":"mcm","clk":"11448259645","pt":1717287895294,"mc":[{"id":"1.229554910","rc":[{"atb":[[4.3,0],[3.9,0],[3.65,0]],"id":70003369},{"atl":[[34,0],[22,0]],"id":70003369},{"atb":[[4.8,0],[5.8,0],[5.3,0]],"id":69033911},{"atl":[[48,0],[29,0]],"id":69033911},{"atb":[[1.73,0],[1.63,0],[1.68,0]],"id":69676139},{"atl":[[4,0],[5,0]],"id":69676139},{"atb":[[70,0],[38,0],[48,0]],"id":52272946},{"atl":[[630,0],[730,0]],"id":52272946},{"atb":[[3.4,0],[3.9,0],[3.65,0]],"id":55943164},{"atl":[[19,0],[28,0]],"id":55943164},{"atb":[[4.8,0],[5.8,0],[5.3,0]],"id":54867443},{"atl":[[48,0],[29,0]],"id":54867443}],"con":true,"img":false}]}
{"op":"mcm","clk":"11448260604","pt":1717287908538,"mc":[{"id":"1.229554910","rc":[{"atb":[[4.3,31.67],[3.9,72.08],[3.65,78.88]],"id":70003369},{"atl":[[34,6.33],[22,6.63]],"id":70003369},{"atb":[[4.8,55.01],[5.8,21.77],[5.3,48.61]],"id":69033911},{"atl":[[48,4.44],[29,4.97]],"id":69033911},{"atb":[[1.73,143.19],[1.63,331.84],[1.68,307.44]],"id":69676139},{"atl":[[4,46.45],[5,52.26]],"id":69676139},{"atb":[[70,1.51],[38,5.65],[48,4.44]],"id":52272946},{"atl":[[630,0.21],[730,0.28]],"id":52272946},{"atb":[[3.4,87.1],[3.9,36.04],[3.65,78.88]],"id":55943164},{"atl":[[19,7.74],[28,7.74]],"id":55943164},{"atb":[[4.8,55.01],[5.8,21.77],[5.3,48.61]],"id":54867443},{"atl":[[48,4.44],[29,4.97]],"id":54867443}],"con":true,"img":false}]}
{"op":"mcm","clk":"11448264320","pt":1717287962466,"mc":[{"id":"1.229554910","rc":[{"atb":[[4.3,0],[3.9,0],[3.65,0]],"id":70003369},{"atl":[[34,0],[22,0]],"id":70003369},{"spn":"NaN","spf":"NaN","id":70003369},{"atb":[[4.8,0],[5.8,0],[5.3,0]],"id":69033911},{"atl":[[48,0],[29,0]],"id":69033911},{"spn":"NaN","spf":"NaN","id":69033911},{"atb":[[1.73,0],[1.63,0],[1.68,0]],"id":69676139},{"atl":[[4,0],[5,0]],"id":69676139},{"spn":1.0,"spf":"NaN","id":69676139},{"atb":[[70,0],[38,0],[48,0]],"id":52272946},{"atl":[[630,0],[730,0]],"id":52272946},{"spn":"NaN","spf":"NaN","id":52272946},{"atb":[[3.4,0],[3.9,0],[3.65,0]],"id":55943164},{"atl":[[19,0],[28,0]],"id":55943164},{"spn":"NaN","spf":"NaN","id":55943164},{"atb":[[4.8,0],[5.8,0],[5.3,0]],"id":54867443},{"atl":[[48,0],[29,0]],"id":54867443},{"spn":"NaN","spf":"NaN","id":54867443}],"con":true,"img":false}]}
{"op":"mcm","clk":"11448265026","pt":1717287972421,"mc":[{"id":"1.229554910","rc":[{"atb":[[4.3,31.67],[3.9,72.08],[3.65,78.88]],"id":70003369},{"atl":[[34,6.33],[22,6.63]],"id":70003369},{"atb":[[4.8,55.01],[5.8,21.77],[5.3,48.61]],"id":69033911},{"atl":[[48,4.44],[29,4.97]],"id":69033911},{"atb":[[1.73,143.19],[1.63,331.84],[1.68,307.44]],"id":69676139},{"atl":[[4,46.45],[5,52.26]],"id":69676139},{"atb":[[70,1.51],[38,5.65],[48,4.44]],"id":52272946},{"atl":[[630,0.21],[730,0.28]],"id":52272946},{"atb":[[3.4,87.1],[3.9,36.04],[3.65,78.88]],"id":55943164},{"atl":[[19,7.74],[28,7.74]],"id":55943164},{"atb":[[4.8,55.01],[5.8,21.77],[5.3,48.61]],"id":54867443},{"atl":[[48,4.44],[29,4.97]],"id":54867443}],"con":true,"img":false}]}
{"op":"mcm","clk":"11448277242","pt":1717288128429,"mc":[{"id":"1.229554910","marketDefinition":{"bspMarket":true,"turnInPlayEnabled":false,"persistenceEnabled":false,"marketBaseRate":7.0,"eventId":"33318908","eventTypeId":"4339","numberOfWinners":1,"bettingType":"ODDS","marketType":"WIN","marketTime":"2024-06-02T09:38:00.000Z","suspendTime":"2024-06-02T09:38:00.000Z","bspReconciled":false,"complete":true,"inPlay":false,"crossMatching":true,"runnersVoidable":false,"numberOfActiveRunners":6,"betDelay":0,"status":"OPEN","runners":[{"status":"ACTIVE","sortPriority":1,"id":69676139,"name":"1. Kilkerran"},{"status":"ACTIVE","sortPriority":2,"id":54867443,"name":"2. Pumpkin Party"},{"status":"ACTIVE","sortPriority":3,"id":52272946,"name":"3. Irish Gem"},{"status":"ACTIVE","sortPriority":4,"id":55943164,"name":"5. Lektra Ringo"},{"status":"ACTIVE","sortPriority":5,"id":70003369,"name":"6. Rickis Burner"},{"status":"ACTIVE","sortPriority":6,"id":69033911,"name":"7. Elegant Evie"}],"regulators":["MR_INT"],"venue":"Murray Bridge","countryCode":"AU","discountAllowed":true,"timezone":"Australia/Adelaide","openDate":"2024-06-02T08:21:00.000Z","version":5962327392,"name":"R5 395m Gr6","eventName":"Murray Bridge (AUS) 2nd Jun"},"rc":[{"atb":[[4.3,31.67],[3.9,72.08],[3.65,78.88]],"id":70003369},{"atl":[[34,6.33],[22,6.63]],"id":70003369},{"spn":13.15,"spf":"NaN","id":70003369},{"atb":[[4.8,55.01],[5.8,21.77],[5.3,48.61]],"id":69033911},{"atl":[[48,4.44],[29,4.97]],"id":69033911},{"spn":17.4,"spf":"NaN","id":69033911},{"atb":[[1.73,143.19],[1.63,331.84],[1.68,307.44]],"id":69676139},{"atl":[[4,46.45],[5,52.26],[2.66,2.61]],"id":69676139},{"spn":2.19,"spf":"NaN","id":69676139},{"atb":[[70,1.51],[38,5.65],[48,4.44]],"id":52272946},{"atl":[[630,0.21],[730,0.28]],"id":52272946},{"spn":350.0,"spf":"NaN","id":52272946},{"atb":[[3.4,87.1],[3.9,36.04],[3.65,78.88]],"id":55943164},{"atl":[[19,7.74],[28,7.74]],"id":55943164},{"spn":11.45,"spf":"NaN","id":55943164},{"atb":[[4.8,55.01],[5.8,21.77],[5.3,48.61]],"id":54867443},{"atl":[[48,4.44],[29,4.97]],"id":54867443},{"spn":17.4,"spf":"NaN","id":54867443}],"con":true,"img":true}]}
{"op":"mcm","clk":"11448292464","pt":1717288273959,"mc":[{"id":"1.229554910","rc":[{"atb":[[4.3,0],[3.9,0],[3.65,0]],"id":70003369},{"atl":[[34,0],[22,0]],"id":70003369},{"spn":17.4,"spf":"NaN","id":69033911},{"atb":[[1.73,0],[1.63,0],[1.68,0]],"id":69676139},{"atl":[[4,0],[5,0]],"id":69676139},{"spn":350.0,"spf":"NaN","id":52272946},{"atb":[[3.4,0],[3.9,0],[3.65,0]],"id":55943164},{"atl":[[19,0],[28,0]],"id":55943164},{"spn":17.4,"spf":"NaN","id":54867443}],"con":true,"img":false}]}
{"op":"mcm","clk":"11448293804","pt":1717288291623,"mc":[{"id":"1.229554910","rc":[{"atb":[[3.45,85.33],[3.95,35.43],[3.7,77.43]],"id":70003369},{"atl":[[19.5,7.53],[29,7.46]],"id":70003369},{"atb":[[1.73,143.19],[1.63,331.84],[1.68,307.44]],"id":69676139},{"atl":[[4,46.45],[5,52.26]],"id":69676139},{"atb":[[3.4,87.1],[3.9,36.04],[3.65,78.88]],"id":55943164},{"atl":[[19,7.74],[28,7.74]],"id":55943164}],"con":true,"img":false}]}
{"op":"mcm","clk":"11448298280","pt":1717288351487,"mc":[{"id":"1.229554910","rc":[{"atb":[[3.45,0],[3.95,0],[3.7,0]],"id":70003369},{"atl":[[19.5,0],[29,0]],"id":70003369},{"atb":[[4.8,0],[5.8,0],[5.3,0]],"id":69033911},{"atl":[[48,0],[29,0]],"id":69033911},{"spn":"NaN","spf":"NaN","id":69033911},{"atb":[[1.73,0],[1.63,0],[1.68,0]],"id":69676139},{"atl":[[4,0],[5,0]],"id":69676139},{"atb":[[3.4,0],[3.9,0],[3.65,0]],"id":55943164},{"atl":[[19,0],[28,0]],"id":55943164},{"atb":[[4.8,0],[5.8,0],[5.3,0]],"id":54867443},{"atl":[[48,0],[29,0]],"id":54867443},{"spn":"NaN","spf":"NaN","id":54867443}],"con":true,"img":false}]}
{"op":"mcm","clk":"11448300795","pt":1717288383947,"mc":[{"id":"1.229554910","rc":[{"atb":[[3.45,85.33],[3.95,35.43],[3.7,77.43]],"id":70003369},{"atl":[[19.5,7.53],[29,7.46]],"id":70003369},{"atb":[[4.8,55.01],[5.8,21.77],[5.3,48.61]],"id":69033911},{"atl":[[48,4.44],[29,4.97]],"id":69033911},{"atb":[[1.73,143.19],[1.63,331.84],[1.68,307.44]],"id":69676139},{"atl":[[4,46.45],[5,52.26]],"id":69676139},{"atb":[[3.4,87.1],[3.9,36.04],[3.65,78.88]],"id":55943164},{"atl":[[19,7.74],[28,7.74]],"id":55943164},{"atb":[[4.8,55.01],[5.8,21.77],[5.3,48.61]],"id":54867443},{"atl":[[48,4.44],[29,4.97]],"id":54867443}],"con":true,"img":false}]}
{"op":"mcm","clk":"11448629973","pt":1717293528419,"mc":[{"id":"1.229554910","marketDefinition":{"bspMarket":true,"turnInPlayEnabled":false,"persistenceEnabled":false,"marketBaseRate":7.0,"eventId":"33318908","eventTypeId":"4339","numberOfWinners":1,"bettingType":"ODDS","marketType":"WIN","marketTime":"2024-06-02T09:38:00.000Z","suspendTime":"2024-06-02T09:38:00.000Z","bspReconciled":false,"complete":true,"inPlay":false,"crossMatching":true,"runnersVoidable":false,"numberOfActiveRunners":6,"betDelay":0,"status":"OPEN","runners":[{"status":"ACTIVE","sortPriority":1,"id":69676139,"name":"1. Kilkerran"},{"status":"ACTIVE","sortPriority":2,"id":54867443,"name":"2. Pumpkin Party"},{"status":"ACTIVE","sortPriority":3,"id":52272946,"name":"3. Irish Gem"},{"status":"ACTIVE","sortPriority":4,"id":55943164,"name":"5. Lektra Ringo"},{"status":"ACTIVE","sortPriority":5,"id":70003369,"name":"6. Rickis Burner"},{"status":"ACTIVE","sortPriority":6,"id":69033911,"name":"7. Elegant Evie"}],"regulators":["MR_INT"],"venue":"Murray Bridge","countryCode":"AU","discountAllowed":true,"timezone":"Australia/Adelaide","openDate":"2024-06-02T08:21:00.000Z","version":5962327392,"name":"R5 395m Gr6","eventName":"Murray Bridge (AUS) 2nd Jun"},"rc":[{"atb":[[3.45,85.33],[3.95,35.43],[3.7,77.43]],"id":70003369},{"atl":[[19.5,7.53],[29,7.46]],"id":70003369},{"spn":11.72,"spf":"NaN","id":70003369},{"atb":[[4.8,55.01],[5.8,21.77],[5.3,48.61]],"id":69033911},{"atl":[[48,4.44],[29,4.97]],"id":69033911},{"spn":17.4,"spf":"NaN","id":69033911},{"atb":[[1.73,143.19],[1.63,331.84],[1.68,307.44]],"id":69676139},{"atl":[[4,46.45],[5,52.26],[2.66,2.61]],"id":69676139},{"spn":2.19,"spf":"NaN","id":69676139},{"atb":[[70,1.51],[38,5.65],[48,4.44]],"id":52272946},{"atl":[[630,0.21],[730,0.28]],"id":52272946},{"spn":350.0,"spf":"NaN","id":52272946},{"atb":[[3.4,87.1],[3.9,36.04],[3.65,78.88]],"id":55943164},{"atl":[[19,7.74],[28,7.74]],"id":55943164},{"spn":11.45,"spf":"NaN","id":55943164},{"atb":[[4.8,55.01],[5.8,21.77],[5.3,48.61]],"id":54867443},{"atl":[[48,4.44],[29,4.97]],"id":54867443},{"spn":17.4,"spf":"NaN","id":54867443}],"con":true,"img":true}]}
{"op":"mcm","clk":"11448643905","pt":1717293690063,"mc":[{"id":"1.229554910","rc":[{"spn":11.72,"spf":"NaN","id":70003369},{"spn":17.4,"spf":"NaN","id":69033911},{"spn":2.19,"spf":"NaN","id":69676139},{"atb":[[70,0],[38,0],[48,0]],"id":52272946},{"atl":[[630,0],[730,0]],"id":52272946},{"spn":"NaN","spf":"NaN","id":52272946},{"spn":11.45,"spf":"NaN","id":55943164},{"spn":17.4,"spf":"NaN","id":54867443}],"con":true,"img":false}]}
{"op":"mcm","clk":"11448644389","pt":1717293699752,"mc":[{"id":"1.229554910","rc":[{"atb":[[34,6.33],[44,4.86],[60,1.77]],"id":52272946},{"atl":[[550,0.25],[650,0.32]],"id":52272946}],"con":true,"img":false}]}
{"op":"mcm","clk":"11448885246","pt":1717298928436,"mc":[{"id":"1.229554910","marketDefinition":{"bspMarket":true,"turnInPlayEnabled":false,"persistenceEnabled":false,"marketBaseRate":7.0,"eventId":"33318908","eventTypeId":"4339","numberOfWinners":1,"bettingType":"ODDS","marketType":"WIN","marketTime":"2024-06-02T09:38:00.000Z","suspendTime":"2024-06-02T09:38:00.000Z","bspReconciled":false,"complete":true,"inPlay":false,"crossMatching":true,"runnersVoidable":false,"numberOfActiveRunners":6,"betDelay":0,"status":"OPEN","runners":[{"status":"ACTIVE","sortPriority":1,"id":69676139,"name":"1. Kilkerran"},{"status":"ACTIVE","sortPriority":2,"id":54867443,"name":"2. Pumpkin Party"},{"status":"ACTIVE","sortPriority":3,"id":52272946,"name":"3. Irish Gem"},{"status":"ACTIVE","sortPriority":4,"id":55943164,"name":"5. Lektra Ringo"},{"status":"ACTIVE","sortPriority":5,"id":70003369,"name":"6. Rickis Burner"},{"status":"ACTIVE","sortPriority":6,"id":69033911,"name":"7. Elegant Evie"}],"regulators":["MR_INT"],"venue":"Murray Bridge","countryCode":"AU","discountAllowed":true,"timezone":"Australia/Adelaide","openDate":"2024-06-02T08:21:00.000Z","version":5962327392,"name":"R5 395m Gr6","eventName":"Murray Bridge (AUS) 2nd Jun"},"rc":[{"atb":[[3.45,85.33],[3.95,35.43],[3.7,77.43]],"id":70003369},{"atl":[[19.5,7.53],[29,7.46]],"id":70003369},{"spn":11.72,"spf":"NaN","id":70003369},{"atb":[[4.8,55.01],[5.8,21.77],[5.3,48.61]],"id":69033911},{"atl":[[48,4.44],[29,4.97]],"id":69033911},{"spn":17.4,"spf":"NaN","id":69033911},{"atb":[[1.73,143.19],[1.63,331.84],[1.68,307.44]],"id":69676139},{"atl":[[4,46.45],[5,52.26],[2.66,2.61]],"id":69676139},{"spn":2.19,"spf":"NaN","id":69676139},{"atb":[[34,6.33],[44,4.86],[60,1.77]],"id":52272946},{"atl":[[550,0.25],[650,0.32]],"id":52272946},{"spn":305.0,"spf":"NaN","id":52272946},{"atb":[[3.4,87.1],[3.9,36.04],[3.65,78.88]],"id":55943164},{"atl":[[19,7.74],[28,7.74]],"id":55943164},{"spn":11.45,"spf":"NaN","id":55943164},{"atb":[[4.8,55.01],[5.8,21.77],[5.3,48.61]],"id":54867443},{"atl":[[48,4.44],[29,4.97]],"id":54867443},{"spn":17.4,"spf":"NaN","id":54867443}],"con":true,"img":true}]}
{"op":"mcm","clk":"11449025906","pt":1717302103940,"mc":[{"id":"1.229554910","rc":[{"atl":[[1.99,10.46]],"id":69676139},{"spn":1.86,"spf":"NaN","id":69676139},{"spn":305.0,"spf":"NaN","id":52272946}],"con":true,"img":false}]}
{"op":"mcm","clk":"11449174751","pt":1717305134273,"mc":[{"id":"1.229554910","rc":[{"atl":[[2.2,4.73]],"id":69676139}],"con":true,"img":false}]}
{"op":"mcm","clk":"11449175109","pt":1717305139698,"mc":[{"id":"1.229554910","rc":[{"trd":[[1.99,9.46]],"ltp":1.99,"tv":9.46,"id":69676139},{"atl":[[1.99,5.72]],"id":69676139}],"con":true,"img":false}]}
{"op":"mcm","clk":"11449524691","pt":1717310362855,"mc":[{"id":"1.229554910","rc":[{"atb":[[3.45,0],[3.95,0],[3.7,0]],"id":70003369},{"atl":[[19.5,0],[29,0]],"id":70003369},{"spn":"NaN","spf":"NaN","id":70003369},{"atb":[[4.8,0],[5.8,0],[5.3,0]],"id":69033911},{"atl":[[48,0],[29,0]],"id":69033911},{"spn":"NaN","spf":"NaN","id":69033911},{"atb":[[1.73,0],[1.63,0],[1.68,0]],"id":69676139},{"atl":[[4,0],[5,0]],"id":69676139},{"spn":1.0,"spf":"NaN","id":69676139},{"atb":[[34,0],[44,0],[60,0]],"id":52272946},{"atl":[[550,0],[650,0]],"id":52272946},{"spn":"NaN","spf":"NaN","id":52272946},{"atb":[[3.4,0],[3.9,0],[3.65,0]],"id":55943164},{"atl":[[19,0],[28,0]],"id":55943164},{"spn":"NaN","spf":"NaN","id":55943164},{"atb":[[4.8,0],[5.8,0],[5.3,0]],"id":54867443},{"atl":[[48,0],[29,0]],"id":54867443},{"spn":"NaN","spf":"NaN","id":54867443}],"con":true,"img":false}]}
{"op":"mcm","clk":"11449526463","pt":1717310391553,"mc":[{"id":"1.229554910","rc":[{"atb":[[3.45,85.33],[3.95,35.43],[3.7,77.43]],"id":70003369},{"atl":[[19.5,7.53],[29,7.46]],"id":70003369},{"atb":[[4.8,55.01],[5.8,21.77],[5.3,48.61]],"id":69033911},{"atl":[[48,4.44],[29,4.97]],"id":69033911},{"atb":[[1.73,143.19],[1.63,331.84],[1.68,307.44]],"id":69676139},{"atl":[[4,46.45],[5,52.26]],"id":69676139},{"atb":[[34,6.33],[44,4.86],[60,1.77]],"id":52272946},{"atl":[[550,0.25],[650,0.32]],"id":52272946},{"atb":[[3.4,87.1],[3.9,36.04],[3.65,78.88]],"id":55943164},{"atl":[[19,7.74],[28,7.74]],"id":55943164},{"atb":[[4.8,55.01],[5.8,21.77],[5.3,48.61]],"id":54867443},{"atl":[[48,4.44],[29,4.97]],"id":54867443}],"con":true,"img":false}]}
{"op":"mcm","clk":"11449584885","pt":1717311411272,"mc":[{"id":"1.229554910","rc":[{"atb":[[3.45,0],[3.95,0],[3.7,0]],"id":70003369},{"atl":[[19.5,0],[29,0]],"id":70003369},{"atb":[[4.8,0],[5.8,0],[5.3,0]],"id":69033911},{"atl":[[48,0],[29,0]],"id":69033911},{"atb":[[1.73,0],[1.63,0],[1.68,0]],"id":69676139},{"atl":[[4,0],[5,0]],"id":69676139},{"atb":[[34,0],[44,0],[60,0]],"id":52272946},{"atl":[[550,0],[650,0]],"id":52272946},{"atb":[[3.4,0],[3.9,0],[3.65,0]],"id":55943164},{"atl":[[19,0],[28,0]],"id":55943164},{"atb":[[4.8,0],[5.8,0],[5.3,0]],"id":54867443},{"atl":[[48,0],[29,0]],"id":54867443}],"con":true,"img":false}]}
{"op":"mcm","clk":"11449585312","pt":1717311419686,"mc":[{"id":"1.229554910","rc":[{"atb":[[3.45,85.33],[3.95,35.43],[3.7,77.43]],"id":70003369},{"atl":[[19.5,7.53],[29,7.46]],"id":70003369},{"atb":[[4.8,55.01],[5.8,21.77],[5.3,48.61]],"id":69033911},{"atl":[[48,4.44],[29,4.97]],"id":69033911},{"atb":[[1.73,143.19],[1.63,331.84],[1.68,307.44]],"id":69676139},{"atl":[[4,46.45],[5,52.26]],"id":69676139},{"atb":[[34,6.33],[44,4.86],[60,1.77]],"id":52272946},{"atl":[[550,0.25],[650,0.32]],"id":52272946},{"atb":[[3.4,87.1],[3.9,36.04],[3.65,78.88]],"id":55943164},{"atl":[[19,7.74],[28,7.74]],"id":55943164},{"atb":[[4.8,55.01],[5.8,21.77],[5.3,48.61]],"id":54867443},{"atl":[[48,4.44],[29,4.97]],"id":54867443}],"con":true,"img":false}]}
{"op":"mcm","clk":"11449586552","pt":1717311440584,"mc":[{"id":"1.229554910","rc":[{"atb":[[1.02,8.94]],"id":70003369},{"atl":[[1000,0.85]],"id":70003369},{"atb":[[1.01,17.89]],"id":69033911},{"atl":[[990,0.85]],"id":69033911},{"atb":[[1.02,8.94]],"id":69676139},{"atl":[[1000,0.85]],"id":69676139},{"atb":[[1.03,5.96]],"id":52272946},{"atl":[[1000,0.85]],"id":52272946},{"atb":[[1.01,17.89]],"id":55943164},{"atl":[[990,0.85]],"id":55943164},{"atb":[[1.03,5.96]],"id":54867443},{"atl":[[1000,0.85]],"id":54867443}],"con":true,"img":false}]}
{"op":"mcm","clk":"11449627134","pt":1717312234288,"mc":[{"id":"1.229554910","rc":[{"spn":11.72,"spf":"NaN","id":70003369},{"spn":17.4,"spf":"NaN","id":69033911},{"atl":[[1.9,1.99]],"id":69676139},{"spn":1.81,"spf":"NaN","id":69676139},{"spn":305.0,"spf":"NaN","id":52272946},{"spn":11.45,"spf":"NaN","id":55943164},{"spn":17.4,"spf":"NaN","id":54867443}],"con":true,"img":false}]}
{"op":"mcm","clk":"11449635906","pt":1717312464615,"mc":[{"id":"1.229554910","rc":[{"atb":[[1.55,100]],"id":69676139}],"con":true,"img":false}]}
{"op":"mcm","clk":"11449637263","pt":1717312502567,"mc":[{"id":"1.229554910","rc":[{"atb":[[3.45,0],[3.95,0],[3.7,0]],"id":70003369},{"atl":[[19.5,0],[29,0]],"id":70003369},{"atb":[[4.8,0],[5.8,0],[5.3,0]],"id":69033911},{"atl":[[48,0],[29,0]],"id":69033911},{"atb":[[1.73,0],[1.63,0],[1.68,0]],"id":69676139},{"atl":[[4,0],[5,0]],"id":69676139},{"atb":[[34,0],[44,0],[60,0]],"id":52272946},{"atl":[[550,0],[650,0]],"id":52272946},{"atb":[[3.4,0],[3.9,0],[3.65,0]],"id":55943164},{"atl":[[19,0],[28,0]],"id":55943164},{"atb":[[4.8,0],[5.8,0],[5.3,0]],"id":54867443},{"atl":[[48,0],[29,0]],"id":54867443}],"con":true,"img":false}]}
{"op":"mcm","clk":"11449637957","pt":1717312518476,"mc":[{"id":"1.229554910","rc":[{"atb":[[3.45,85.33],[3.95,35.43],[3.7,77.43]],"id":70003369},{"atl":[[19.5,7.53],[29,7.46]],"id":70003369},{"atb":[[4.8,55.01],[5.8,21.77],[5.3,48.61]],"id":69033911},{"atl":[[48,4.44],[29,4.97]],"id":69033911},{"atb":[[1.73,143.19],[1.63,331.84],[1.68,307.44]],"id":69676139},{"atl":[[4,46.45],[5,52.26]],"id":69676139},{"atb":[[34,6.33],[44,4.86],[60,1.77]],"id":52272946},{"atl":[[550,0.25],[650,0.32]],"id":52272946},{"atb":[[3.4,87.1],[3.9,36.04],[3.65,78.88]],"id":55943164},{"atl":[[19,7.74],[28,7.74]],"id":55943164},{"atb":[[4.8,55.01],[5.8,21.77],[5.3,48.61]],"id":54867443},{"atl":[[48,4.44],[29,4.97]],"id":54867443}],"con":true,"img":false}]}
{"op":"mcm","clk":"11449660333","pt":1717313062032,"mc":[{"id":"1.229554910","rc":[{"atl":[[20,5.23]],"id":69033911},{"spn":12.9,"spf":"NaN","id":69033911}],"con":true,"img":false}]}
{"op":"mcm","clk":"11449660786","pt":1717313073945,"mc":[{"id":"1.229554910","rc":[{"atl":[[90,26.15]],"id":69033911}],"con":true,"img":false}]}
{"op":"mcm","clk":"11449693413","pt":1717313604516,"mc":[{"id":"1.229554910","rc":[{"atb":[[3.45,0],[3.95,0],[3.7,0]],"id":70003369},{"atl":[[19.5,0],[29,0]],"id":70003369},{"spn":500.51,"spf":"NaN","id":70003369},{"atb":[[4.8,0],[5.8,0],[5.3,0]],"id":69033911},{"atl":[[48,0],[29,0]],"id":69033911},{"spn":10.5,"spf":"NaN","id":69033911},{"atb":[[1.73,0],[1.63,0],[1.68,0]],"id":69676139},{"atl":[[4,0],[5,0]],"id":69676139},{"spn":1.72,"spf":"NaN","id":69676139},{"atb":[[34,0],[44,0],[60,0]],"id":52272946},{"atl":[[550,0],[650,0]],"id":52272946},{"spn":500.51,"spf":"NaN","id":52272946},{"atb":[[3.4,0],[3.9,0],[3.65,0]],"id":55943164},{"atl":[[19,0],[28,0]],"id":55943164},{"spn":495.5,"spf":"NaN","id":55943164},{"atb":[[4.8,0],[5.8,0],[5.3,0]],"id":54867443},{"atl":[[48,0],[29,0]],"id":54867443},{"spn":500.51,"spf":"NaN","id":54867443}],"con":true,"img":false}]}
{"op":"mcm","clk":"11449695119","pt":1717313624241,"mc":[{"id":"1.229554910","rc":[{"atb":[[3.45,85.33],[3.95,35.43],[3.7,77.43]],"id":70003369},{"atl":[[19.5,7.53],[29,7.46]],"id":70003369},{"atb":[[4.8,55.01],[5.8,21.77],[5.3,48.61]],"id":69033911},{"atl":[[48,4.44],[29,4.97]],"id":69033911},{"atb":[[1.73,143.19],[1.63,331.84],[1.68,307.44]],"id":69676139},{"atl":[[4,46.45],[5,52.26]],"id":69676139},{"atb":[[34,6.33],[44,4.86],[60,1.77]],"id":52272946},{"atl":[[550,0.25],[650,0.32]],"id":52272946},{"atb":[[3.4,87.1],[3.9,36.04],[3.65,78.88]],"id":55943164},{"atl":[[19,7.74],[28,7.74]],"id":55943164},{"atb":[[4.8,55.01],[5.8,21.77],[5.3,48.61]],"id":54867443},{"atl":[[48,4.44],[29,4.97]],"id":54867443}],"con":true,"img":false}]}
{"op":"mcm","clk":"11449703767","pt":1717313733941,"mc":[{"id":"1.229554910","rc":[{"spn":11.72,"spf":"NaN","id":70003369},{"spn":12.9,"spf":"NaN","id":69033911},{"spn":1.81,"spf":"NaN","id":69676139},{"atb":[[34,0],[44,0],[60,0]],"id":52272946},{"atl":[[550,0],[650,0]],"id":52272946},{"spn":11.45,"spf":"NaN","id":55943164},{"spn":17.4,"spf":"NaN","id":54867443}],"con":true,"img":false}]}
{"op":"mcm","clk":"11449705303","pt":1717313752774,"mc":[{"id":"1.229554910","rc":[{"atb":[[70,1.51],[38,5.65],[48,4.44]],"id":52272946},{"atl":[[630,0.21],[730,0.28]],"id":52272946}],"con":true,"img":false}]}
{"op":"mcm","clk":"11449766650","pt":1717314431784,"mc":[{"id":"1.229554910","rc":[{"atb":[[3.45,0],[3.95,0],[3.7,0]],"id":70003369},{"atl":[[19.5,0],[29,0]],"id":70003369},{"spn":500.51,"spf":"NaN","id":70003369},{"atb":[[4.8,0],[5.8,0],[5.3,0]],"id":69033911},{"atl":[[48,0],[29,0]],"id":69033911},{"spn":10.5,"spf":"NaN","id":69033911},{"atb":[[1.73,0],[1.63,0],[1.68,0]],"id":69676139},{"atl":[[4,0],[5,0]],"id":69676139},{"spn":1.72,"spf":"NaN","id":69676139},{"atb":[[70,0],[38,0],[48,0]],"id":52272946},{"atl":[[630,0],[730,0]],"id":52272946},{"atb":[[3.4,0],[3.9,0],[3.65,0]],"id":55943164},{"atl":[[19,0],[28,0]],"id":55943164},{"spn":495.5,"spf":"NaN","id":55943164},{"atb":[[4.8,0],[5.8,0],[5.3,0]],"id":54867443},{"atl":[[48,0],[29,0]],"id":54867443},{"spn":500.51,"spf":"NaN","id":54867443}],"con":true,"img":false}]}
{"op":"mcm","clk":"11449767953","pt":1717314446185,"mc":[{"id":"1.229554910","rc":[{"atb":[[3.45,85.33],[3.95,35.43],[3.7,77.43]],"id":70003369},{"atl":[[19.5,7.53],[29,7.46]],"id":70003369},{"atb":[[4.8,55.01],[5.8,21.77],[5.3,48.61]],"id":69033911},{"atl":[[48,4.44],[29,4.97]],"id":69033911},{"atb":[[1.73,143.19],[1.63,331.84],[1.68,307.44]],"id":69676139},{"atl":[[4,46.45],[5,52.26]],"id":69676139},{"atb":[[70,1.51],[38,5.65],[48,4.44]],"id":52272946},{"atl":[[630,0.21],[730,0.28]],"id":52272946},{"atb":[[3.4,87.1],[3.9,36.04],[3.65,78.88]],"id":55943164},{"atl":[[19,7.74],[28,7.74]],"id":55943164},{"atb":[[4.8,55.01],[5.8,21.77],[5.3,48.61]],"id":54867443},{"atl":[[48,4.44],[29,4.97]],"id":54867443}],"con":true,"img":false}]}
{"op":"mcm","clk":"11449818989","pt":1717315031123,"mc":[{"id":"1.229554910","rc":[{"atl":[[1000,0.17]],"id":70003369},{"spn":11.72,"spf":"NaN","id":70003369},{"atl":[[990,0.17]],"id":69033911},{"spn":12.9,"spf":"NaN","id":69033911},{"atl":[[1000,0.17]],"id":69676139},{"spn":1.81,"spf":"NaN","id":69676139},{"atl":[[1000,0.17]],"id":52272946},{"spn":350.0,"spf":"NaN","id":52272946},{"atl":[[990,0.17]],"id":55943164},{"spn":11.45,"spf":"NaN","id":55943164},{"atl":[[1000,0.17]],"id":54867443},{"spn":17.4,"spf":"NaN","id":54867443}],"con":true,"img":false}]}
{"op":"mcm","clk":"11449839369","pt":1717315175737,"mc":[{"id":"1.229554910","rc":[{"atl":[[16,10],[34,10]],"id":69676139}],"con":true,"img":false}]}
{"op":"mcm","clk":"11449851214","pt":1717315295788,"mc":[{"id":"1.229554910","rc":[{"atb":[[3.45,0],[3.95,0],[3.7,0]],"id":70003369},{"atl":[[19.5,0],[29,0]],"id":70003369},{"spn":500.51,"spf":"NaN","id":70003369},{"atb":[[4.8,0],[5.8,0],[5.3,0]],"id":69033911},{"atl":[[48,0],[29,0]],"id":69033911},{"spn":10.5,"spf":"NaN","id":69033911},{"atb":[[1.73,0],[1.63,0],[1.68,0]],"id":69676139},{"atl":[[4,0],[5,0]],"id":69676139},{"spn":1.72,"spf":"NaN","id":69676139},{"atb":[[70,0],[38,0],[48,0]],"id":52272946},{"atl":[[630,0],[730,0]],"id":52272946},{"spn":500.51,"spf":"NaN","id":52272946},{"atb":[[3.4,0],[3.9,0],[3.65,0]],"id":55943164},{"atl":[[19,0],[28,0]],"id":55943164},{"spn":495.5,"spf":"NaN","id":55943164},{"atb":[[4.8,0],[5.8,0],[5.3,0]],"id":54867443},{"atl":[[48,0],[29,0]],"id":54867443},{"spn":500.51,"spf":"NaN","id":54867443}],"con":true,"img":false}]}
{"op":"mcm","clk":"11449853607","pt":1717315320659,"mc":[{"id":"1.229554910","rc":[{"atb":[[3.45,85.33],[3.95,35.43],[3.7,77.43]],"id":70003369},{"atl":[[19.5,7.53],[29,7.46]],"id":70003369},{"atb":[[4.8,55.01],[5.8,21.77],[5.3,48.61]],"id":69033911},{"atl":[[48,4.44],[29,4.97]],"id":69033911},{"atb":[[1.73,143.19],[1.63,331.84],[1.68,307.44]],"id":69676139},{"atl":[[4,46.45],[5,52.26]],"id":69676139},{"atb":[[70,1.51],[38,5.65],[48,4.44]],"id":52272946},{"atl":[[630,0.21],[730,0.28]],"id":52272946},{"atb":[[3.4,87.1],[3.9,36.04],[3.65,78.88]],"id":55943164},{"atl":[[19,7.74],[28,7.74]],"id":55943164},{"atb":[[4.8,55.01],[5.8,21.77],[5.3,48.61]],"id":54867443},{"atl":[[48,4.44],[29,4.97]],"id":54867443}],"con":true,"img":false}]}
{"op":"mcm","clk":"11449936815","pt":1717316137829,"mc":[{"id":"1.229554910","rc":[{"atb":[[3.45,0],[3.95,0],[3.7,0]],"id":70003369},{"atl":[[19.5,0],[29,0]],"id":70003369},{"atb":[[4.8,0],[5.8,0],[5.3,0]],"id":69033911},{"atl":[[48,0],[29,0]],"id":69033911},{"atb":[[1.73,0],[1.63,0],[1.68,0]],"id":69676139},{"atl":[[4,0],[5,0]],"id":69676139},{"atb":[[70,0],[38,0],[48,0]],"id":52272946},{"atl":[[630,0],[730,0]],"id":52272946},{"atb":[[3.4,0],[3.9,0],[3.65,0]],"id":55943164},{"atl":[[19,0],[28,0]],"id":55943164},{"atb":[[4.8,0],[5.8,0],[5.3,0]],"id":54867443},{"atl":[[48,0],[29,0]],"id":54867443}],"con":true,"img":false}]}
{"op":"mcm","clk":"11449938382","pt":1717316154630,"mc":[{"id":"1.229554910","rc":[{"atb":[[3.45,85.33],[3.95,35.43],[3.7,77.43]],"id":70003369},{"atl":[[19.5,7.53],[29,7.46]],"id":70003369},{"atb":[[4.8,55.01],[5.8,21.77],[5.3,48.61]],"id":69033911},{"atl":[[48,4.44],[29,4.97]],"id":69033911},{"atb":[[1.73,143.19],[1.63,331.84],[1.68,307.44]],"id":69676139},{"atl":[[4,46.45],[5,52.26]],"id":69676139},{"atb":[[70,1.51],[38,5.65],[48,4.44]],"id":52272946},{"atl":[[630,0.21],[730,0.28]],"id":52272946},{"atb":[[3.4,87.1],[3.9,36.04],[3.65,78.88]],"id":55943164},{"atl":[[19,7.74],[28,7.74]],"id":55943164},{"atb":[[4.8,55.01],[5.8,21.77],[5.3,48.61]],"id":54867443},{"atl":[[48,4.44],[29,4.97]],"id":54867443}],"con":true,"img":false}]}
{"op":"mcm","clk":"11449940394","pt":1717316175740,"mc":[{"id":"1.229554910","rc":[{"atb":[[4,18.7],[3.55,40.11]],"id":70003369},{"atl":[[19,5.68],[14.5,4.15]],"id":70003369},{"atb":[[5.3,75.87],[6,11.22]],"id":69033911},{"atl":[[34,3.55],[27,2.61]],"id":69033911},{"atb":[[1.64,178.2],[1.75,61.85]],"id":69676139},{"atl":[[4.1,18.1],[5.2,27.15]],"id":69676139},{"atb":[[70,4.13],[60,2.61]],"id":52272946},{"atb":[[3.35,47.31],[3.75,20.4]],"id":55943164},{"atl":[[17.5,6.73],[13.5,4.48]],"id":55943164},{"atb":[[5.6,12.2],[4.9,26.42]],"id":54867443},{"atl":[[32,3.32],[24,2.61]],"id":54867443}],"con":true,"img":false}]}
{"op":"mcm","clk":"11449941935","pt":1717316192186,"mc":[{"id":"1.229554910","rc":[{"atb":[[3.45,0],[3.95,0],[3.7,0]],"id":70003369},{"atl":[[19.5,0],[29,0]],"id":70003369},{"atb":[[3.4,0],[3.9,0],[3.65,0]],"id":55943164},{"atl":[[19,0],[28,0]],"id":55943164}],"con":true,"img":false}]}
{"op":"mcm","clk":"11449942648","pt":1717316199975,"mc":[{"id":"1.229554910","rc":[{"spn":9.25,"spf":"NaN","id":70003369},{"spn":13.0,"spf":"NaN","id":69033911},{"spn":1.82,"spf":"NaN","id":69676139},{"spn":350.0,"spf":"NaN","id":52272946},{"atb":[[3.4,4.72]],"id":55943164},{"spn":8.62,"spf":"NaN","id":55943164},{"spn":14.9,"spf":"NaN","id":54867443}],"con":true,"img":false}]}
{"op":"mcm","clk":"11449942970","pt":1717316203588,"mc":[{"id":"1.229554910","rc":[{"atb":[[3.45,85.33],[3.95,35.43],[3.7,77.43]],"id":70003369},{"atl":[[19.5,7.53],[29,7.46]],"id":70003369},{"atb":[[3.4,91.83],[3.9,36.04],[3.65,78.88]],"id":55943164},{"atl":[[19,7.74],[28,7.74]],"id":55943164}],"con":true,"img":false}]}
{"op":"mcm","clk":"11449945494","pt":1717316231606,"mc":[{"id":"1.229554910","rc":[{"atb":[[3.4,87.1]],"id":55943164}],"con":true,"img":false}]}
{"op":"mcm","clk":"11449945614","pt":1717316232906,"mc":[{"id":"1.229554910","rc":[{"atb":[[4,0]],"id":70003369},{"atl":[[27,0]],"id":69033911},{"atl":[[4.1,0]],"id":69676139},{"atb":[[3.75,0]],"id":55943164},{"atl":[[13.5,0]],"id":55943164},{"atb":[[5.6,0]],"id":54867443}],"con":true,"img":false}]}
{"op":"mcm","clk":"11449945623","pt":1717316233010,"mc":[{"id":"1.229554910","rc":[{"atb":[[4.1,18.7]],"id":70003369},{"atl":[[26,2.61]],"id":69033911},{"atl":[[3.95,18.1]],"id":69676139},{"atb":[[3.95,20.4]],"id":55943164},{"atl":[[13,4.48]],"id":55943164},{"atb":[[5.9,12.2]],"id":54867443}],"con":true,"img":false}]}
{"op":"mcm","clk":"11449948144","pt":1717316259884,"mc":[{"id":"1.229554910","rc":[{"atb":[[3.55,0]],"id":70003369},{"atb":[[5.3,48.61]],"id":69033911},{"atl":[[28,4.34]],"id":69033911},{"atb":[[1.64,0]],"id":69676139},{"atl":[[5.2,0]],"id":69676139},{"atb":[[3.35,0]],"id":55943164},{"atb":[[4.9,0]],"id":54867443},{"atl":[[32,0]],"id":54867443}],"con":true,"img":false}]}
{"op":"mcm","clk":"11449948155","pt":1717316259972,"mc":[{"id":"1.229554910","rc":[{"atb":[[3.75,40.11]],"id":70003369},{"atb":[[5.4,27.25]],"id":69033911},{"atl":[[34,0]],"id":69033911},{"atb":[[1.74,178.2]],"id":69676139},{"atl":[[4.9,27.15]],"id":69676139},{"atb":[[3.45,47.31]],"id":55943164},{"atb":[[5.4,26.42]],"id":54867443},{"atl":[[28,3.32]],"id":54867443}],"con":true,"img":false}]}
{"op":"mcm","clk":"11449952422","pt":1717316311347,"mc":[{"id":"1.229554910","rc":[{"spn":9.3,"spf":"NaN","id":70003369},{"atl":[[26,0]],"id":69033911},{"spn":8.47,"spf":"NaN","id":55943164},{"spn":14.95,"spf":"NaN","id":54867443}],"con":true,"img":false}]}
{"op":"mcm","clk":"11449952435","pt":1717316311442,"mc":[{"id":"1.229554910","rc":[{"atl":[[25,2.61]],"id":69033911}],"con":true,"img":false}]}
{"op":"mcm","clk":"11449954507","pt":1717316336576,"mc":[{"id":"1.229554910","rc":[{"atb":[[3.75,0]],"id":70003369}],"con":true,"img":false}]}
{"op":"mcm","clk":"11449954517","pt":1717316336678,"mc":[{"id":"1.229554910","rc":[{"atb":[[4,40.11]],"id":70003369}],"con":true,"img":false}]}
{"op":"mcm","clk":"11449958373","pt":1717316387558,"mc":[{"id":"1.229554910","rc":[{"atl":[[25,0]],"id":69033911}],"con":true,"img":false}]}
{"op":"mcm","clk":"11449958382","pt":1717316387661,"mc":[{"id":"1.229554910","rc":[{"atl":[[24,2.61]],"id":69033911}],"con":true,"img":false}]}
{"op":"mcm","clk":"11449962472","pt":1717316437538,"mc":[{"id":"1.229554910","rc":[{"atl":[[24,0]],"id":69033911}],"con":true,"img":false}]}
{"op":"mcm","clk":"11449962480","pt":1717316437641,"mc":[{"id":"1.229554910","rc":[{"atl":[[26,2.61]],"id":69033911}],"con":true,"img":false}]}
{"op":"mcm","clk":"11449966116","pt":1717316487180,"mc":[{"id":"1.229554910","rc":[{"atl":[[26,0]],"id":69033911}],"con":true,"img":false}]}
{"op":"mcm","clk":"11449966124","pt":1717316487230,"mc":[{"id":"1.229554910","rc":[{"atl":[[25,2.61]],"id":69033911}],"con":true,"img":false}]}
{"op":"mcm","clk":"11449970932","pt":1717316559379,"mc":[{"id":"1.229554910","rc":[{"atl":[[25,0]],"id":69033911}],"con":true,"img":false}]}
{"op":"mcm","clk":"11449970937","pt":1717316559480,"mc":[{"id":"1.229554910","rc":[{"atl":[[24,2.61]],"id":69033911}],"con":true,"img":false}]}
{"op":"mcm","clk":"11449974243","pt":1717316607260,"mc":[{"id":"1.229554910","rc":[{"atl":[[24,0]],"id":69033911}],"con":true,"img":false}]}
{"op":"mcm","clk":"11449974254","pt":1717316607363,"mc":[{"id":"1.229554910","rc":[{"atl":[[26,2.61]],"id":69033911}],"con":true,"img":false}]}
{"op":"mcm","clk":"11449978290","pt":1717316662026,"mc":[{"id":"1.229554910","rc":[{"atl":[[26,0]],"id":69033911}],"con":true,"img":false}]}
{"op":"mcm","clk":"11449978296","pt":1717316662126,"mc":[{"id":"1.229554910","rc":[{"atl":[[25,2.61]],"id":69033911}],"con":true,"img":false}]}
{"op":"mcm","clk":"11449982809","pt":1717316726077,"mc":[{"id":"1.229554910","rc":[{"atl":[[1000,1.17]],"id":70003369},{"atl":[[1000,1]],"id":69033911},{"atl":[[1000,1.17]],"id":69676139},{"atl":[[1000,1.17]],"id":52272946},{"atl":[[1000,1]],"id":55943164},{"atl":[[1000,1.17]],"id":54867443}],"con":true,"img":false}]}
{"op":"mcm","clk":"11449983405","pt":1717316734385,"mc":[{"id":"1.229554910","rc":[{"atl":[[25,0]],"id":69033911}],"con":true,"img":false}]}
{"op":"mcm","clk":"11449983413","pt":1717316734495,"mc":[{"id":"1.229554910","rc":[{"atl":[[24,2.61]],"id":69033911}],"con":true,"img":false}]}
{"op":"mcm","clk":"11449986681","pt":1717316779557,"mc":[{"id":"1.229554910","rc":[{"atl":[[24,0]],"id":69033911}],"con":true,"img":false}]}
{"op":"mcm","clk":"11449986690","pt":1717316779663,"mc":[{"id":"1.229554910","rc":[{"atl":[[26,2.61]],"id":69033911}],"con":true,"img":false}]}
{"op":"mcm","clk":"11449989933","pt":1717316824617,"mc":[{"id":"1.229554910","rc":[{"atl":[[26,0]],"id":69033911}],"con":true,"img":false}]}
{"op":"mcm","clk":"11449989942","pt":1717316824720,"mc":[{"id":"1.229554910","rc":[{"atl":[[25,2.61]],"id":69033911}],"con":true,"img":false}]}
{"op":"mcm","clk":"11449995370","pt":1717316890268,"mc":[{"id":"1.229554910","rc":[{"atl":[[25,0]],"id":69033911}],"con":true,"img":false}]}
{"op":"mcm","clk":"11449995380","pt":1717316890369,"mc":[{"id":"1.229554910","rc":[{"atl":[[24,2.61]],"id":69033911}],"con":true,"img":false}]}
{"op":"mcm","clk":"11449998917","pt":1717316933721,"mc":[{"id":"1.229554910","rc":[{"atl":[[24,0]],"id":69033911}],"con":true,"img":false}]}
{"op":"mcm","clk":"11449998925","pt":1717316933824,"mc":[{"id":"1.229554910","rc":[{"atl":[[26,2.61]],"id":69033911}],"con":true,"img":false}]}
{"op":"mcm","clk":"11450002902","pt":1717316979429,"mc":[{"id":"1.229554910","rc":[{"atl":[[26,0]],"id":69033911}],"con":true,"img":false}]}
{"op":"mcm","clk":"11450002909","pt":1717316979531,"mc":[{"id":"1.229554910","rc":[{"atl":[[25,2.61]],"id":69033911}],"con":true,"img":false}]}
{"op":"mcm","clk":"11450003947","pt":1717316992140,"mc":[{"id":"1.229554910","rc":[{"atb":[[3.45,0],[3.95,0],[3.7,0]],"id":70003369},{"atl":[[19.5,0],[29,0]],"id":70003369},{"atb":[[4.8,0],[5.8,0],[5.3,0]],"id":69033911},{"atl":[[48,0],[29,0]],"id":69033911},{"atb":[[1.73,0],[1.63,0],[1.68,0]],"id":69676139},{"atl":[[4,0],[5,0]],"id":69676139},{"atb":[[70,2.61],[38,0],[48,0]],"id":52272946},{"atl":[[630,0],[730,0]],"id":52272946},{"atb":[[3.4,0],[3.9,0],[3.65,0]],"id":55943164},{"atl":[[19,0],[28,0]],"id":55943164},{"atb":[[4.8,0],[5.8,0],[5.3,0]],"id":54867443},{"atl":[[48,0],[29,0]],"id":54867443}],"con":true,"img":false}]}
{"op":"mcm","clk":"11450004650","pt":1717317000462,"mc":[{"id":"1.229554910","rc":[{"atb":[[4,0]],"id":70003369},{"atl":[[34,3.55],[25,0],[28,0]],"id":69033911},{"atb":[[1.74,0]],"id":69676139},{"atl":[[3.95,0]],"id":69676139},{"atb":[[3.95,0]],"id":55943164},{"atb":[[5.9,0],[5.4,0]],"id":54867443},{"atl":[[28,0]],"id":54867443}],"con":true,"img":false}]}
{"op":"mcm","clk":"11450004661","pt":1717317000567,"mc":[{"id":"1.229554910","rc":[{"atb":[[3.7,40.11]],"id":70003369},{"atl":[[27,2.61]],"id":69033911},{"atb":[[1.64,178.2]],"id":69676139},{"atl":[[4.1,18.1]],"id":69676139},{"atb":[[3.65,20.4]],"id":55943164},{"atb":[[5.5,12.2],[4.9,26.42]],"id":54867443},{"atl":[[32,3.32]],"id":54867443}],"con":true,"img":false}]}
{"op":"mcm","clk":"11450006456","pt":1717317018448,"mc":[{"id":"1.229554910","rc":[{"atb":[[3.45,85.33],[3.95,35.43],[3.7,117.54]],"id":70003369},{"atl":[[19.5,7.53],[29,7.46]],"id":70003369},{"atb":[[4.8,55.01],[5.8,21.77],[5.3,48.61]],"id":69033911},{"atl":[[48,4.44],[29,4.97]],"id":69033911},{"atb":[[1.73,143.19],[1.63,331.84],[1.68,307.44]],"id":69676139},{"atl":[[4,46.45],[5,52.26]],"id":69676139},{"atb":[[70,4.13],[38,5.65],[48,4.44]],"id":52272946},{"atl":[[630,0.21],[730,0.28]],"id":52272946},{"atb":[[3.4,87.1],[3.9,36.04],[3.65,99.29]],"id":55943164},{"atl":[[19,7.74],[28,7.74]],"id":55943164},{"atb":[[4.8,55.01],[5.8,21.77],[5.3,48.61]],"id":54867443},{"atl":[[48,4.44],[29,4.97]],"id":54867443}],"con":true,"img":false}]}
{"op":"mcm","clk":"11450010922","pt":1717317063914,"mc":[{"id":"1.229554910","rc":[{"atb":[[3.7,77.43]],"id":70003369},{"atl":[[34,0],[27,0],[28,4.34]],"id":69033911},{"atb":[[1.64,0]],"id":69676139},{"atl":[[4.1,0]],"id":69676139},{"atb":[[3.65,78.88]],"id":55943164},{"spn":8.45,"spf":"NaN","id":55943164},{"atb":[[5.5,0],[4.9,0]],"id":54867443},{"atl":[[32,0]],"id":54867443},{"spn":14.9,"spf":"NaN","id":54867443}],"con":true,"img":false}]}
{"op":"mcm","clk":"11450010935","pt":1717317064011,"mc":[{"id":"1.229554910","rc":[{"atb":[[3.75,40.11]],"id":70003369},{"atl":[[26,2.61]],"id":69033911},{"atb":[[1.74,178.2]],"id":69676139},{"atl":[[3.95,18.1]],"id":69676139},{"atb":[[3.95,20.4]],"id":55943164},{"atb":[[5.9,12.2],[5.4,26.42]],"id":54867443},{"atl":[[28,3.32]],"id":54867443}],"con":true,"img":false}]}
{"op":"mcm","clk":"11450014728","pt":1717317103151,"mc":[{"id":"1.229554910","rc":[{"atb":[[2.12,44.64]],"id":69033911},{"atb":[[6.2,9.62],[4.1,16.13],[2.12,44.64],[1.51,98.04],[3.05,24.39]],"id":52272946},{"atb":[[2.12,44.64],[1.51,98.04]],"id":54867443}],"con":true,"img":false}]}
{"op":"mcm","clk":"11450014742","pt":1717317103256,"mc":[{"id":"1.229554910","rc":[{"atb":[[1.51,98.04]],"id":70003369},{"atb":[[1.51,98.04]],"id":69033911},{"atb":[[1.51,98.04]],"id":55943164}],"con":true,"img":false}]}
{"op":"mcm","clk":"11450017544","pt":1717317132220,"mc":[{"id":"1.229554910","rc":[{"atb":[[3.75,0]],"id":70003369},{"atl":[[26,0]],"id":69033911},{"spn":8.47,"spf":"NaN","id":55943164},{"spn":14.95,"spf":"NaN","id":54867443}],"con":true,"img":false}]}
{"op":"mcm","clk":"11450017554","pt":1717317132324,"mc":[{"id":"1.229554910","rc":[{"atb":[[4,40.11]],"id":70003369},{"atl":[[25,2.61]],"id":69033911}],"con":true,"img":false}]}
{"op":"mcm","clk":"11450023771","pt":1717317194888,"mc":[{"id":"1.229554910","rc":[{"atl":[[25,0]],"id":69033911}],"con":true,"img":false}]}
{"op":"mcm","clk":"11450023783","pt":1717317194990,"mc":[{"id":"1.229554910","rc":[{"atl":[[24,2.61]],"id":69033911}],"con":true,"img":false}]}
{"op":"mcm","clk":"11450028117","pt":1717317237362,"mc":[{"id":"1.229554910","rc":[{"atl":[[24,0]],"id":69033911}],"con":true,"img":false}]}
{"op":"mcm","clk":"11450028123","pt":1717317237468,"mc":[{"id":"1.229554910","rc":[{"atl":[[26,2.61]],"id":69033911}],"con":true,"img":false}]}
{"op":"mcm","clk":"11450033418","pt":1717317289420,"mc":[{"id":"1.229554910","rc":[{"atl":[[26,0]],"id":69033911}],"con":true,"img":false}]}
{"op":"mcm","clk":"11450033431","pt":1717317289522,"mc":[{"id":"1.229554910","rc":[{"atl":[[25,2.61]],"id":69033911}],"con":true,"img":false}]}
{"op":"mcm","clk":"11450041057","pt":1717317359953,"mc":[{"id":"1.229554910","rc":[{"atl":[[25,0]],"id":69033911}],"con":true,"img":false}]}
{"op":"mcm","clk":"11450041070","pt":1717317360054,"mc":[{"id":"1.229554910","rc":[{"atl":[[24,2.61]],"id":69033911}],"con":true,"img":false}]}
{"op":"mcm","clk":"11450045616","pt":1717317403481,"mc":[{"id":"1.229554910","rc":[{"atl":[[24,0]],"id":69033911}],"con":true,"img":false}]}
{"op":"mcm","clk":"11450045630","pt":1717317403587,"mc":[{"id":"1.229554910","rc":[{"atl":[[26,2.61]],"id":69033911}],"con":true,"img":false}]}
{"op":"mcm","clk":"11450049323","pt":1717317437269,"mc":[{"id":"1.229554910","rc":[{"atl":[[26,0]],"id":69033911}],"con":true,"img":false}]}
{"op":"mcm","clk":"11450049334","pt":1717317437355,"mc":[{"id":"1.229554910","rc":[{"atl":[[25,2.61]],"id":69033911}],"con":true,"img":false}]}
{"op":"mcm","clk":"11450053404","pt":1717317480394,"mc":[{"id":"1.229554910","rc":[{"atb":[[2.24,80.22]],"id":70003369},{"atl":[[21,5]],"id":70003369},{"atb":[[3.2,45.45]],"id":69033911},{"atl":[[34,3.03]],"id":69033911},{"atl":[[8.2,13.89]],"id":69676139},{"atb":[[44,2.33]],"id":52272946},{"atb":[[2.2,83.33]],"id":55943164},{"atl":[[19,13.3]],"id":55943164},{"atb":[[2.16,52.86]],"id":54867443},{"atl":[[34,3.03]],"id":54867443}],"con":true,"img":false}]}
{"op":"mcm","clk":"11450054195","pt":1717317489289,"mc":[{"id":"1.229554910","rc":[{"atb":[[4.1,0]],"id":70003369},{"atl":[[25,0]],"id":69033911}],"con":true,"img":false}]}
{"op":"mcm","clk":"11450054202","pt":1717317489392,"mc":[{"id":"1.229554910","rc":[{"atb":[[4.2,18.7]],"id":70003369},{"atl":[[24,2.61]],"id":69033911}],"con":true,"img":false}]}
{"op":"mcm","clk":"11450054368","pt":1717317491305,"mc":[{"id":"1.229554910","rc":[{"trd":[[1.99,20.92],[1.9,3.98]],"ltp":1.99,"tv":24.9,"id":69676139},{"atl":[[1.99,0],[1.9,0]],"id":69676139}],"con":true,"img":false}]}
{"op":"mcm","clk":"11450055051","pt":1717317498797,"mc":[{"id":"1.229554910","rc":[{"spn":9.35,"spf":"NaN","id":70003369},{"trd":[[2.2,9.46]],"ltp":2.2,"tv":9.46,"id":69676139},{"atl":[[2.2,0]],"id":69676139},{"spn":2.2,"spf":"NaN","id":69676139}],"con":true,"img":false}]}
{"op":"mcm","clk":"11450055882","pt":1717317507915,"mc":[{"id":"1.229554910","rc":[{"atb":[[1.75,76.97]],"id":69676139}],"con":true,"img":false}]}
{"op":"mcm","clk":"11450057541","pt":1717317527817,"mc":[{"id":"1.229554910","rc":[{"atl":[[19.5,0.78]],"id":69033911}],"con":true,"img":false}]}
{"op":"mcm","clk":"11450057601","pt":1717317528441,"mc":[{"id":"1.229554910","rc":[{"atl":[[19.5,0.58]],"id":69033911}],"con":true,"img":false}]}
{"op":"mcm","clk":"11450059063","pt":1717317544734,"mc":[{"id":"1.229554910","rc":[{"atl":[[24,0]],"id":69033911}],"con":true,"img":false}]}
{"op":"mcm","clk":"11450059073","pt":1717317544837,"mc":[{"id":"1.229554910","rc":[{"atl":[[26,2.61]],"id":69033911}],"con":true,"img":false}]}
{"op":"mcm","clk":"11450059105","pt":1717317545253,"mc":[{"id":"1.229554910","rc":[{"atl":[[19.5,0]],"id":69033911}],"con":true,"img":false}]}
{"op":"mcm","clk":"11450059113","pt":1717317545304,"mc":[{"id":"1.229554910","rc":[{"atl":[[1000,1.58]],"id":69033911}],"con":true,"img":false}]}
{"op":"mcm","clk":"11450061549","pt":1717317571690,"mc":[{"id":"1.229554910","rc":[{"atl":[[26,0]],"id":69033911}],"con":true,"img":false}]}
{"op":"mcm","clk":"11450061558","pt":1717317571796,"mc":[{"id":"1.229554910","rc":[{"atl":[[25,2.61]],"id":69033911}],"con":true,"img":false}]}
{"op":"mcm","clk":"11450061608","pt":1717317572290,"mc":[{"id":"1.229554910","rc":[{"atl":[[1000,1]],"id":69033911}],"con":true,"img":false}]}
{"op":"mcm","clk":"11450061617","pt":1717317572393,"mc":[{"id":"1.229554910","rc":[{"atl":[[19.5,0.58]],"id":69033911}],"con":true,"img":false}]}
{"op":"mcm","clk":"11450063867","pt":1717317597489,"mc":[{"id":"1.229554910","rc":[{"atb":[[3.45,0],[3.95,0],[3.7,0]],"id":70003369},{"atl":[[19.5,0],[29,0]],"id":70003369},{"atb":[[4.8,0],[5.8,0],[5.3,0]],"id":69033911},{"atl":[[48,0],[29,0]],"id":69033911},{"atb":[[1.73,0],[1.63,0],[1.68,0]],"id":69676139},{"atl":[[4,0],[5,0]],"id":69676139},{"atb":[[70,2.61],[38,0],[48,0]],"id":52272946},{"atl":[[630,0],[730,0]],"id":52272946},{"atb":[[3.4,0],[3.9,0],[3.65,0]],"id":55943164},{"atl":[[19,5.56],[28,0]],"id":55943164},{"atb":[[4.8,0],[5.8,0],[5.3,0]],"id":54867443},{"atl":[[48,0],[29,0]],"id":54867443}],"con":true,"img":false}]}
{"op":"mcm","clk":"11450064181","pt":1717317601209,"mc":[{"id":"1.229554910","rc":[{"atb":[[4,0]],"id":70003369},{"atl":[[34,6.58],[25,0],[28,0]],"id":69033911},{"atb":[[1.74,0]],"id":69676139},{"atb":[[3.95,0]],"id":55943164},{"atb":[[5.9,0],[5.4,0]],"id":54867443},{"atl":[[28,0]],"id":54867443}],"con":true,"img":false}]}
{"op":"mcm","clk":"11450064190","pt":1717317601305,"mc":[{"id":"1.229554910","rc":[{"atb":[[3.7,40.11]],"id":70003369},{"atl":[[27,2.61]],"id":69033911},{"atb":[[1.64,178.2]],"id":69676139},{"atb":[[3.65,20.4]],"id":55943164},{"atb":[[5.5,12.2],[4.9,26.42]],"id":54867443},{"atl":[[32,3.32]],"id":54867443}],"con":true,"img":false}]}
{"op":"mcm","clk":"11450064199","pt":1717317601409,"mc":[{"id":"1.229554910","rc":[{"atb":[[2.24,26.32],[2.16,0],[2.14,87.72]],"id":54867443}],"con":true,"img":false}]}
{"op":"mcm","clk":"11450064219","pt":1717317601719,"mc":[{"id":"1.229554910","rc":[{"atl":[[19.5,0]],"id":69033911}],"con":true,"img":false}]}
{"op":"mcm","clk":"11450064228","pt":1717317601822,"mc":[{"id":"1.229554910","rc":[{"atl":[[1000,1.58]],"id":69033911}],"con":true,"img":false}]}
{"op":"mcm","clk":"11450065161","pt":1717317612080,"mc":[{"id":"1.229554910","rc":[{"atb":[[3.45,85.33],[3.95,35.43],[3.7,117.54]],"id":70003369},{"atl":[[19.5,7.53],[29,7.46]],"id":70003369},{"atb":[[4.8,55.01],[5.8,21.77],[5.3,48.61]],"id":69033911},{"atl":[[48,4.44],[29,4.97]],"id":69033911},{"atb":[[1.73,143.19],[1.63,331.84],[1.68,307.44]],"id":69676139},{"atl":[[4,46.45],[5,52.26]],"id":69676139},{"atb":[[70,4.13],[38,5.65],[48,4.44]],"id":52272946},{"atl":[[630,0.21],[730,0.28]],"id":52272946},{"atb":[[3.4,87.1],[3.9,36.04],[3.65,99.29]],"id":55943164},{"atl":[[19,13.3],[28,7.74]],"id":55943164},{"atb":[[4.8,55.01],[5.8,21.77],[5.3,48.61]],"id":54867443},{"atl":[[48,4.44],[29,4.97]],"id":54867443}],"con":true,"img":false}]}
{"op":"mcm","clk":"11450065174","pt":1717317612233,"mc":[{"id":"1.229554910","rc":[{"atb":[[2.24,0]],"id":54867443}],"con":true,"img":false}]}
{"op":"mcm","clk":"11450067905","pt":1717317642284,"mc":[{"id":"1.229554910","rc":[{"atb":[[1.75,61.85]],"id":69676139},{"spn":8.45,"spf":"NaN","id":55943164},{"spn":14.9,"spf":"NaN","id":54867443}],"con":true,"img":false}]}
{"op":"mcm","clk":"11450069300","pt":1717317657411,"mc":[{"id":"1.229554910","rc":[{"atl":[[27,0]],"id":69033911},{"atb":[[5.5,0]],"id":54867443}],"con":true,"img":false}]}
{"op":"mcm","clk":"11450069313","pt":1717317657465,"mc":[{"id":"1.229554910","rc":[{"atl":[[26,2.61]],"id":69033911},{"atb":[[5.9,12.2]],"id":54867443}],"con":true,"img":false}]}
{"op":"mcm","clk":"11450070061","pt":1717317665515,"mc":[{"id":"1.229554910","rc":[{"atl":[[1000,2.03]],"id":54867443}],"con":true,"img":false}]}
{"op":"mcm","clk":"11450070081","pt":1717317665674,"mc":[{"id":"1.229554910","rc":[{"atl":[[1000,1.85]],"id":55943164}],"con":true,"img":false}]}
{"op":"mcm","clk":"11450070090","pt":1717317665777,"mc":[{"id":"1.229554910","rc":[{"atl":[[1000,2.03]],"id":70003369}],"con":true,"img":false}]}
{"op":"mcm","clk":"11450070107","pt":1717317665979,"mc":[{"id":"1.229554910","rc":[{"atl":[[1000,2.44]],"id":69033911}],"con":true,"img":false}]}
{"op":"mcm","clk":"11450070115","pt":1717317666082,"mc":[{"id":"1.229554910","rc":[{"atl":[[1000,1.54]],"id":54867443}],"con":true,"img":false}]}
{"op":"mcm","clk":"11450070143","pt":1717317666393,"mc":[{"id":"1.229554910","rc":[{"atl":[[1000,1.78]],"id":70003369}],"con":true,"img":false}]}
{"op":"mcm","clk":"11450070162","pt":1717317666598,"mc":[{"id":"1.229554910","rc":[{"atl":[[1000,2.02]],"id":69033911}],"con":true,"img":false}]}
{"op":"mcm","clk":"11450070192","pt":1717317666908,"mc":[{"id":"1.229554910","rc":[{"atl":[[1000,1.17]],"id":54867443}],"con":true,"img":false}]}
{"op":"mcm","clk":"11450070200","pt":1717317667011,"mc":[{"id":"1.229554910","rc":[{"atl":[[23,0.36]],"id":54867443}],"con":true,"img":false}]}
{"op":"mcm","clk":"11450070214","pt":1717317667117,"mc":[{"id":"1.229554910","rc":[{"atl":[[1000,1.68]],"id":55943164}],"con":true,"img":false}]}
{"op":"mcm","clk":"11450070238","pt":1717317667282,"mc":[{"id":"1.229554910","rc":[{"atl":[[1000,1.17]],"id":70003369}],"con":true,"img":false}]}
{"op":"mcm","clk":"11450070248","pt":1717317667380,"mc":[{"id":"1.229554910","rc":[{"atl":[[14,0.6]],"id":70003369},{"atl":[[34,3.03],[28,4.34]],"id":69033911},{"atb":[[1.64,0]],"id":69676139},{"atb":[[3.65,78.88]],"id":55943164},{"atl":[[32,0]],"id":54867443}],"con":true,"img":false}]}
{"op":"mcm","clk":"11450070263","pt":1717317667483,"mc":[{"id":"1.229554910","rc":[{"atb":[[1.74,178.2]],"id":69676139},{"atb":[[3.95,20.4]],"id":55943164},{"atl":[[28,3.32]],"id":54867443}],"con":true,"img":false}]}
{"op":"mcm","clk":"11450070289","pt":1717317667793,"mc":[{"id":"1.229554910","rc":[{"atl":[[1000,1.58]],"id":69033911}],"con":true,"img":false}]}
{"op":"mcm","clk":"11450070299","pt":1717317667896,"mc":[{"id":"1.229554910","rc":[{"atl":[[19.5,0.43]],"id":69033911}],"con":true,"img":false}]}
{"op":"mcm","clk":"11450070363","pt":1717317668515,"mc":[{"id":"1.229554910","rc":[{"atl":[[1000,1]],"id":55943164}],"con":true,"img":false}]}
{"op":"mcm","clk":"11450070370","pt":1717317668618,"mc":[{"id":"1.229554910","rc":[{"atl":[[12.5,0.68]],"id":55943164}],"con":true,"img":false}]}
{"op":"mcm","clk":"11450071214","pt":1717317677400,"mc":[{"id":"1.229554910","rc":[{"atb":[[4.9,0]],"id":54867443}],"con":true,"img":false}]}
{"op":"mcm","clk":"11450071222","pt":1717317677500,"mc":[{"id":"1.229554910","rc":[{"atb":[[5.4,26.42]],"id":54867443}],"con":true,"img":false}]}
{"op":"mcm","clk":"11450071643","pt":1717317682410,"mc":[{"id":"1.229554910","rc":[{"atb":[[1.75,76.97]],"id":69676139}],"con":true,"img":false}]}
{"op":"mcm","clk":"11450076707","pt":1717317737285,"mc":[{"id":"1.229554910","rc":[{"atb":[[3.7,77.43]],"id":70003369},{"spn":9.1,"spf":"NaN","id":70003369},{"spn":12.75,"spf":"NaN","id":69033911},{"spn":8.22,"spf":"NaN","id":55943164},{"spn":14.45,"spf":"NaN","id":54867443}],"con":true,"img":false}]}
{"op":"mcm","clk":"11450076718","pt":1717317737386,"mc":[{"id":"1.229554910","rc":[{"atb":[[4,40.11]],"id":70003369}],"con":true,"img":false}]}
{"op":"mcm","clk":"11450081009","pt":1717317785082,"mc":[{"id":"1.229554910","rc":[{"atb":[[44,0],[50,2.04]],"id":52272946}],"con":true,"img":false}]}
{"op":"mcm","clk":"11450087943","pt":1717317867446,"mc":[{"id":"1.229554910","rc":[{"atb":[[4.3,2.53]],"id":70003369},{"spn":9.15,"spf":"NaN","id":70003369},{"atb":[[6.2,2.59]],"id":69033911},{"spn":12.85,"spf":"NaN","id":69033911},{"atb":[[1.76,2.6]],"id":69676139},{"spn":2.21,"spf":"NaN","id":69676139},{"atb":[[4,2.64]],"id":55943164},{"spn":8.25,"spf":"NaN","id":55943164},{"atb":[[6,2.63]],"id":54867443},{"spn":14.5,"spf":"NaN","id":54867443}],"con":true,"img":false}]}
{"op":"mcm","clk":"11450088073","pt":1717317869255,"mc":[{"id":"1.229554910","rc":[{"atl":[[13.5,1.43]],"id":70003369},{"atl":[[12,1.61]],"id":55943164}],"con":true,"img":false}]}
{"op":"mcm","clk":"11450092169","pt":1717317914718,"mc":[{"id":"1.229554910","rc":[{"atl":[[1000,3.53]],"id":70003369},{"atl":[[1000,3.35]],"id":55943164}],"con":true,"img":false}]}
{"op":"mcm","clk":"11450092431","pt":1717317917455,"mc":[{"id":"1.229554910","rc":[{"atl":[[1000,2.16]],"id":70003369},{"atl":[[1000,2.11]],"id":55943164}],"con":true,"img":false}]}
{"op":"mcm","clk":"11450092449","pt":1717317917614,"mc":[{"id":"1.229554910","rc":[{"atl":[[1000,1]],"id":55943164}],"con":true,"img":false}]}
{"op":"mcm","clk":"11450092458","pt":1717317917718,"mc":[{"id":"1.229554910","rc":[{"atl":[[12,2.72]],"id":55943164}],"con":true,"img":false}]}
{"op":"mcm","clk":"11450092493","pt":1717317918124,"mc":[{"id":"1.229554910","rc":[{"atl":[[11.5,0.78]],"id":55943164}],"con":true,"img":false}]}
{"op":"mcm","clk":"11450092514","pt":1717317918433,"mc":[{"id":"1.229554910","rc":[{"atl":[[1000,1.17]],"id":70003369}],"con":true,"img":false}]}
{"op":"mcm","clk":"11450092520","pt":1717317918535,"mc":[{"id":"1.229554910","rc":[{"atl":[[13.5,2.42]],"id":70003369}],"con":true,"img":false}]}
{"op":"mcm","clk":"11450092542","pt":1717317918744,"mc":[{"id":"1.229554910","rc":[{"atl":[[13,0.78]],"id":70003369}],"con":true,"img":false}]}
{"op":"mcm","clk":"11450092553","pt":1717317918847,"mc":[{"id":"1.229554910","rc":[{"atl":[[11.5,0.57]],"id":55943164}],"con":true,"img":false}]}
{"op":"mcm","clk":"11450092597","pt":1717317919317,"mc":[{"id":"1.229554910","rc":[{"atl":[[13,0.57]],"id":70003369}],"con":true,"img":false}]}
{"op":"mcm","clk":"11450093051","pt":1717317924434,"mc":[{"id":"1.229554910","rc":[{"atb":[[5.4,0]],"id":69033911}],"con":true,"img":false}]}
{"op":"mcm","clk":"11450093063","pt":1717317924538,"mc":[{"id":"1.229554910","rc":[{"atb":[[5.9,27.25]],"id":69033911}],"con":true,"img":false}]}
{"op":"mcm","clk":"11450104888","pt":1717318060311,"mc":[{"id":"1.229554910","rc":[{"atb":[[3.45,0],[3.95,0],[3.7,0]],"id":70003369},{"atl":[[19.5,0],[29,0]],"id":70003369},{"spn":8.65,"spf":"NaN","id":70003369},{"atb":[[4.8,0],[5.8,0],[5.3,0]],"id":69033911},{"atl":[[48,0],[29,0]],"id":69033911},{"atb":[[1.73,0],[1.63,0],[1.68,0]],"id":69676139},{"atl":[[4,0],[5,0]],"id":69676139},{"atb":[[70,2.61],[38,0],[48,0]],"id":52272946},{"atl":[[630,0],[730,0]],"id":52272946},{"spn":535.0,"spf":"NaN","id":52272946},{"atb":[[3.4,0],[3.9,0],[3.65,0]],"id":55943164},{"atl":[[19,5.56],[28,0]],"id":55943164},{"spn":7.75,"spf":"NaN","id":55943164},{"atb":[[4.8,0],[5.8,0],[5.3,0]],"id":54867443},{"atl":[[48,0],[29,0]],"id":54867443}],"con":true,"img":false}]}
{"op":"mcm","clk":"11450104915","pt":1717318060621,"mc":[{"id":"1.229554910","rc":[{"atb":[[4,0]],"id":55943164}],"con":true,"img":false}]}
{"op":"mcm","clk":"11450105831","pt":1717318070326,"mc":[{"id":"1.229554910","rc":[{"atb":[[4,0]],"id":70003369},{"atb":[[5.9,0]],"id":69033911},{"atl":[[28,0]],"id":69033911},{"atb":[[1.74,0]],"id":69676139},{"atb":[[3.95,0]],"id":55943164},{"atb":[[5.9,0],[5.4,0]],"id":54867443},{"atl":[[28,0]],"id":54867443}],"con":true,"img":false}]}
{"op":"mcm","clk":"11450105840","pt":1717318070425,"mc":[{"id":"1.229554910","rc":[{"atb":[[3.7,40.11]],"id":70003369},{"atb":[[5.3,27.25]],"id":69033911},{"atl":[[32,4.34]],"id":69033911},{"atb":[[1.64,178.2]],"id":69676139},{"atb":[[3.65,20.4]],"id":55943164},{"atb":[[5.5,12.2],[4.9,26.42]],"id":54867443},{"atl":[[32,3.32]],"id":54867443}],"con":true,"img":false}]}
{"op":"mcm","clk":"11450105859","pt":1717318070635,"mc":[{"id":"1.229554910","rc":[{"atl":[[23,0]],"id":54867443}],"con":true,"img":false}]}
{"op":"mcm","clk":"11450105896","pt":1717318071004,"mc":[{"id":"1.229554910","rc":[{"atb":[[4.3,0]],"id":70003369},{"atb":[[6.2,0]],"id":69033911},{"atb":[[3.7,2.64]],"id":55943164},{"atb":[[6,0]],"id":54867443}],"con":true,"img":false}]}
{"op":"mcm","clk":"11450106315","pt":1717318075419,"mc":[{"id":"1.229554910","rc":[{"atl":[[12,1.11]],"id":55943164}],"con":true,"img":false}]}
{"op":"mcm","clk":"11450106324","pt":1717318075521,"mc":[{"id":"1.229554910","rc":[{"atb":[[1.75,61.85]],"id":69676139}],"con":true,"img":false}]}
{"op":"mcm","clk":"11450106330","pt":1717318075625,"mc":[{"id":"1.229554910","rc":[{"atl":[[11.5,0]],"id":55943164}],"con":true,"img":false}]}
{"op":"mcm","clk":"11450106344","pt":1717318075728,"mc":[{"id":"1.229554910","rc":[{"atl":[[1000,1.57]],"id":55943164}],"con":true,"img":false}]}
{"op":"mcm","clk":"11450106664","pt":1717318078855,"mc":[{"id":"1.229554910","rc":[{"atb":[[3.45,85.33],[3.95,35.43],[3.7,117.54]],"id":70003369},{"atl":[[19.5,7.53],[29,7.46]],"id":70003369},{"atb":[[4.8,55.01],[5.8,21.77],[5.3,75.87]],"id":69033911},{"atl":[[48,4.44],[29,4.97]],"id":69033911},{"atb":[[1.73,143.19],[1.63,331.84],[1.68,307.44]],"id":69676139},{"atl":[[4,46.45],[5,52.26]],"id":69676139},{"atb":[[70,4.13],[38,5.65],[48,4.44]],"id":52272946},{"atl":[[630,0.21],[730,0.28]],"id":52272946},{"atb":[[3.4,87.1],[3.9,36.04],[3.65,99.29]],"id":55943164},{"atl":[[19,13.3],[28,7.74]],"id":55943164},{"atb":[[4.8,55.01],[5.8,21.77],[5.3,48.61]],"id":54867443},{"atl":[[48,4.44],[29,4.97]],"id":54867443}],"con":true,"img":false}]}
{"op":"mcm","clk":"11450106678","pt":1717318078917,"mc":[{"id":"1.229554910","rc":[{"atb":[[4.3,2.53]],"id":70003369},{"atb":[[6.2,2.59]],"id":69033911},{"atb":[[3.7,0]],"id":55943164},{"atb":[[5.9,2.63]],"id":54867443}],"con":true,"img":false}]}
{"op":"mcm","clk":"11450106698","pt":1717318079089,"mc":[{"id":"1.229554910","rc":[{"atb":[[3.95,2.64]],"id":55943164}],"con":true,"img":false}]}
{"op":"mcm","clk":"11450108509","pt":1717318100154,"mc":[{"id":"1.229554910","rc":[{"atl":[[12,0]],"id":55943164}],"con":true,"img":false}]}
{"op":"mcm","clk":"11450109582","pt":1717318112349,"mc":[{"id":"1.229554910","rc":[{"atl":[[13.5,0.98]],"id":70003369}],"con":true,"img":false}]}
{"op":"mcm","clk":"11450109598","pt":1717318112553,"mc":[{"id":"1.229554910","rc":[{"atb":[[1.74,15.32]],"id":69676139}],"con":true,"img":false}]}
{"op":"mcm","clk":"11450109629","pt":1717318112868,"mc":[{"id":"1.229554910","rc":[{"atl":[[13,0]],"id":70003369}],"con":true,"img":false}]}
{"op":"mcm","clk":"11450109642","pt":1717318112974,"mc":[{"id":"1.229554910","rc":[{"atl":[[1000,1.75]],"id":70003369}],"con":true,"img":false}]}
{"op":"mcm","clk":"11450109844","pt":1717318115357,"mc":[{"id":"1.229554910","rc":[{"atl":[[13.5,0]],"id":70003369}],"con":true,"img":false}]}
{"op":"mcm","clk":"11450110064","pt":1717318117689,"mc":[{"id":"1.229554910","rc":[{"atb":[[3.65,78.88]],"id":55943164},{"atb":[[5.5,0]],"id":54867443}],"con":true,"img":false}]}
{"op":"mcm","clk":"11450110073","pt":1717318117787,"mc":[{"id":"1.229554910","rc":[{"atb":[[3.95,23.04]],"id":55943164},{"atb":[[5.9,14.83]],"id":54867443}],"con":true,"img":false}]}
{"op":"mcm","clk":"11450111128","pt":1717318130170,"mc":[{"id":"1.229554910","rc":[{"atl":[[1000,4.1]],"id":70003369},{"spn":9.15,"spf":"NaN","id":70003369},{"spn":350.0,"spf":"NaN","id":52272946},{"atl":[[1000,3.92]],"id":55943164},{"spn":8.22,"spf":"NaN","id":55943164},{"spn":14.95,"spf":"NaN","id":54867443}],"con":true,"img":false}]}
{"op":"mcm","clk":"11450111142","pt":1717318130370,"mc":[{"id":"1.229554910","rc":[{"atl":[[1000,2.74]],"id":70003369},{"atl":[[1000,2.68]],"id":55943164}],"con":true,"img":false}]}
{"op":"mcm","clk":"11450111154","pt":1717318130574,"mc":[{"id":"1.229554910","rc":[{"atl":[[1000,1.75]],"id":70003369}],"con":true,"img":false}]}
{"op":"mcm","clk":"11450111163","pt":1717318130681,"mc":[{"id":"1.229554910","rc":[{"atl":[[13.5,0.98]],"id":70003369}],"con":true,"img":false}]}
{"op":"mcm","clk":"11450111180","pt":1717318130887,"mc":[{"id":"1.229554910","rc":[{"atl":[[1000,1.57]],"id":55943164}],"con":true,"img":false}]}
{"op":"mcm","clk":"11450111188","pt":1717318130993,"mc":[{"id":"1.229554910","rc":[{"atl":[[12,1.11]],"id":55943164}],"con":true,"img":false}]}
{"op":"mcm","clk":"11450111305","pt":1717318132707,"mc":[{"id":"1.229554910","rc":[{"atb":[[3.7,77.43]],"id":70003369},{"atb":[[5.3,48.61]],"id":69033911},{"atl":[[32,0]],"id":69033911},{"atb":[[1.64,0]],"id":69676139},{"atb":[[4.9,0]],"id":54867443},{"atl":[[32,0]],"id":54867443}],"con":true,"img":false}]}
{"op":"mcm","clk":"11450111313","pt":1717318132807,"mc":[{"id":"1.229554910","rc":[{"atb":[[4,40.11]],"id":70003369},{"atb":[[5.4,27.25]],"id":69033911},{"atl":[[28,4.34]],"id":69033911},{"atb":[[1.74,193.52]],"id":69676139},{"atb":[[5.4,26.42]],"id":54867443},{"atl":[[28,3.32]],"id":54867443}],"con":true,"img":false}]}
{"op":"mcm","clk":"11450113239","pt":1717318153014,"mc":[{"id":"1.229554910","rc":[{"atl":[[12,2.72]],"id":55943164}],"con":true,"img":false}]}
{"op":"mcm","clk":"11450113247","pt":1717318153114,"mc":[{"id":"1.229554910","rc":[{"atl":[[13.5,2.42]],"id":70003369}],"con":true,"img":false}]}
{"op":"mcm","clk":"11450113268","pt":1717318153323,"mc":[{"id":"1.229554910","rc":[{"atb":[[1.74,178.2]],"id":69676139}],"con":true,"img":false}]}
{"op":"mcm","clk":"11450113308","pt":1717318153733,"mc":[{"id":"1.229554910","rc":[{"atl":[[1000,1.17]],"id":70003369},{"atl":[[1000,1]],"id":55943164}],"con":true,"img":false}]}
{"op":"mcm","clk":"11450113314","pt":1717318153791,"mc":[{"id":"1.229554910","rc":[{"atl":[[13,0.57]],"id":70003369},{"atl":[[11.5,0.57]],"id":55943164}],"con":true,"img":false}]}
{"op":"mcm","clk":"11450116670","pt":1717318191354,"mc":[{"id":"1.229554910","rc":[{"spn":8.65,"spf":"NaN","id":70003369},{"atb":[[1.75,76.97]],"id":69676139},{"spn":7.72,"spf":"NaN","id":55943164}],"con":true,"img":false}]}
{"op":"mcm","clk":"11450116871","pt":1717318193472,"mc":[{"id":"1.229554910","rc":[{"atb":[[5.4,0]],"id":69033911}],"con":true,"img":false}]}
{"op":"mcm","clk":"11450116878","pt":1717318193575,"mc":[{"id":"1.229554910","rc":[{"atb":[[5.9,27.25]],"id":69033911}],"con":true,"img":false}]}
{"op":"mcm","clk":"11450118175","pt":1717318208050,"mc":[{"id":"1.229554910","rc":[{"atl":[[1000,2.03]],"id":54867443}],"con":true,"img":false}]}
{"op":"mcm","clk":"11450118196","pt":1717318208257,"mc":[{"id":"1.229554910","rc":[{"atb":[[4,2.13]],"id":55943164}],"con":true,"img":false}]}
{"op":"mcm","clk":"11450118445","pt":1717318211373,"mc":[{"id":"1.229554910","rc":[{"atl":[[1000,1.54]],"id":54867443}],"con":true,"img":false}]}
{"op":"mcm","clk":"11450118863","pt":1717318216301,"mc":[{"id":"1.229554910","rc":[{"atl":[[1000,1.17]],"id":54867443}],"con":true,"img":false}]}
{"op":"mcm","clk":"11450118873","pt":1717318216351,"mc":[{"id":"1.229554910","rc":[{"atl":[[23,0.36]],"id":54867443}],"con":true,"img":false}]}
{"op":"mcm","clk":"11450120724","pt":1717318236913,"mc":[{"id":"1.229554910","rc":[{"atl":[[1000,2.03]],"id":70003369}],"con":true,"img":false}]}
{"op":"mcm","clk":"11450120759","pt":1717318237380,"mc":[{"id":"1.229554910","rc":[{"atl":[[14,0]],"id":70003369}],"con":true,"img":false}]}
{"op":"mcm","clk":"11450120771","pt":1717318237490,"mc":[{"id":"1.229554910","rc":[{"atl":[[1000,1.86]],"id":70003369}],"con":true,"img":false}]}
{"op":"mcm","clk":"11450120830","pt":1717318238420,"mc":[{"id":"1.229554910","rc":[{"atl":[[1000,1.17]],"id":70003369}],"con":true,"img":false}]}
{"op":"mcm","clk":"11450120839","pt":1717318238526,"mc":[{"id":"1.229554910","rc":[{"atl":[[12.5,0.68]],"id":70003369}],"con":true,"img":false}]}
{"op":"mcm","clk":"11450120900","pt":1717318239201,"mc":[{"id":"1.229554910","rc":[{"atl":[[13,0]],"id":70003369}],"con":true,"img":false}]}
{"op":"mcm","clk":"11450120911","pt":1717318239308,"mc":[{"id":"1.229554910","rc":[{"atl":[[1000,1.75]],"id":70003369}],"con":true,"img":false}]}
{"op":"mcm","clk":"11450120937","pt":1717318239614,"mc":[{"id":"1.229554910","rc":[{"atl":[[1000,2.6]],"id":70003369}],"con":true,"img":false}]}
{"op":"mcm","clk":"11450120958","pt":1717318239822,"mc":[{"id":"1.229554910","rc":[{"atl":[[1000,2.03]],"id":70003369}],"con":true,"img":false}]}
{"op":"mcm","clk":"11450120969","pt":1717318239928,"mc":[{"id":"1.229554910","rc":[{"atl":[[13,0.57]],"id":70003369}],"con":true,"img":false}]}
{"op":"mcm","clk":"11450120987","pt":1717318240189,"mc":[{"id":"1.229554910","rc":[{"atl":[[12.5,0]],"id":70003369}],"con":true,"img":false}]}
{"op":"mcm","clk":"11450121014","pt":1717318240495,"mc":[{"id":"1.229554910","rc":[{"atl":[[1000,1.86]],"id":70003369}],"con":true,"img":false}]}
{"op":"mcm","clk":"11450121075","pt":1717318241324,"mc":[{"id":"1.229554910","rc":[{"atl":[[1000,1.17]],"id":70003369}],"con":true,"img":false}]}
{"op":"mcm","clk":"11450121088","pt":1717318241424,"mc":[{"id":"1.229554910","rc":[{"atl":[[13,1.25]],"id":70003369}],"con":true,"img":false}]}
{"op":"mcm","clk":"11450121102","pt":1717318241582,"mc":[{"id":"1.229554910","rc":[{"atl":[[13,0.68]],"id":70003369}],"con":true,"img":false}]}
{"op":"mcm","clk":"11450121110","pt":1717318241683,"mc":[{"id":"1.229554910","rc":[{"atl":[[1000,1.75]],"id":70003369}],"con":true,"img":false}]}
{"op":"mcm","clk":"11450127478","pt":1717318316458,"mc":[{"id":"1.229554910","rc":[{"atl":[[12,1.61]],"id":55943164},{"spn":7.75,"spf":"NaN","id":55943164},{"spn":14.45,"spf":"NaN","id":54867443}],"con":true,"img":false}]}
{"op":"mcm","clk":"11450129001","pt":1717318333243,"mc":[{"id":"1.229554910","rc":[{"atl":[[13.5,1.43]],"id":70003369}],"con":true,"img":false}]}
{"op":"mcm","clk":"11450129791","pt":1717318342173,"mc":[{"id":"1.229554910","rc":[{"atl":[[12,0]],"id":55943164}],"con":true,"img":false}]}
{"op":"mcm","clk":"11450129829","pt":1717318342692,"mc":[{"id":"1.229554910","rc":[{"atl":[[11.5,0]],"id":55943164}],"con":true,"img":false}]}
{"op":"mcm","clk":"11450129836","pt":1717318342801,"mc":[{"id":"1.229554910","rc":[{"atl":[[1000,1.57]],"id":55943164}],"con":true,"img":false}]}
{"op":"mcm","clk":"11450130998","pt":1717318356068,"mc":[{"id":"1.229554910","rc":[{"atl":[[1000,3.92]],"id":55943164}],"con":true,"img":false}]}
{"op":"mcm","clk":"11450131006","pt":1717318356167,"mc":[{"id":"1.229554910","rc":[{"atl":[[1000,4.1]],"id":70003369}],"con":true,"img":false}]}
{"op":"mcm","clk":"11450131075","pt":1717318356998,"mc":[{"id":"1.229554910","rc":[{"atl":[[1000,2.68]],"id":55943164}],"con":true,"img":false}]}
{"op":"mcm","clk":"11450131097","pt":1717318357205,"mc":[{"id":"1.229554910","rc":[{"atl":[[1000,2.74]],"id":70003369}],"con":true,"img":false}]}
{"op":"mcm","clk":"11450131107","pt":1717318357307,"mc":[{"id":"1.229554910","rc":[{"atl":[[1000,1.57]],"id":55943164}],"con":true,"img":false}]}
{"op":"mcm","clk":"11450131116","pt":1717318357411,"mc":[{"id":"1.229554910","rc":[{"atl":[[12,1.11]],"id":55943164}],"con":true,"img":false}]}
{"op":"mcm","clk":"11450131128","pt":1717318357614,"mc":[{"id":"1.229554910","rc":[{"atl":[[1000,1.75]],"id":70003369}],"con":true,"img":false}]}
{"op":"mcm","clk":"11450131132","pt":1717318357671,"mc":[{"id":"1.229554910","rc":[{"atl":[[13.5,2.42]],"id":70003369}],"con":true,"img":false}]}
{"op":"mcm","clk":"11450132991","pt":1717318380198,"mc":[{"id":"1.229554910","rc":[{"atl":[[13.5,0.98]],"id":70003369},{"spn":8.0,"spf":"NaN","id":55943164}],"con":true,"img":false}]}
{"op":"mcm","clk":"11450134598","pt":1717318399637,"mc":[{"id":"1.229554910","rc":[{"atl":[[12,2.72]],"id":55943164}],"con":true,"img":false}]}
{"op":"mcm","clk":"11450134608","pt":1717318399743,"mc":[{"id":"1.229554910","rc":[{"atl":[[13.5,2.42]],"id":70003369}],"con":true,"img":false}]}
{"op":"mcm","clk":"11450134618","pt":1717318399845,"mc":[{"id":"1.229554910","rc":[{"atl":[[1000,1]],"id":55943164}],"con":true,"img":false}]}
{"op":"mcm","clk":"11450134630","pt":1717318399949,"mc":[{"id":"1.229554910","rc":[{"atl":[[11.5,0.57]],"id":55943164}],"con":true,"img":false}]}
{"op":"mcm","clk":"11450137021","pt":1717318427778,"mc":[{"id":"1.229554910","rc":[{"atb":[[3.45,0],[3.95,0],[3.7,0]],"id":70003369},{"atl":[[19.5,0],[29,0]],"id":70003369},{"atb":[[4.8,0],[5.8,0],[5.3,0]],"id":69033911},{"atl":[[48,0],[29,0]],"id":69033911},{"atb":[[1.73,0],[1.63,0],[1.68,0]],"id":69676139},{"atl":[[4,0],[5,0]],"id":69676139},{"atb":[[70,2.61],[38,0],[48,0]],"id":52272946},{"atl":[[630,0],[730,0]],"id":52272946},{"atb":[[3.4,0],[3.9,0],[3.65,0]],"id":55943164},{"atl":[[19,5.56],[28,0]],"id":55943164},{"atb":[[4.8,0],[5.8,0],[5.3,0]],"id":54867443},{"atl":[[48,0],[29,0]],"id":54867443}],"con":true,"img":false}]}
{"op":"mcm","clk":"11450137042","pt":1717318428088,"mc":[{"id":"1.229554910","rc":[{"atl":[[1000,1.17]],"id":70003369}],"con":true,"img":false}]}
{"op":"mcm","clk":"11450137052","pt":1717318428140,"mc":[{"id":"1.229554910","rc":[{"atl":[[13,1.25]],"id":70003369}],"con":true,"img":false}]}
{"op":"mcm","clk":"11450137077","pt":1717318428456,"mc":[{"id":"1.229554910","rc":[{"atb":[[3.95,20.4]],"id":55943164}],"con":true,"img":false}]}
{"op":"mcm","clk":"11450137094","pt":1717318428658,"mc":[{"id":"1.229554910","rc":[{"atl":[[13,0.68]],"id":70003369}],"con":true,"img":false}]}
{"op":"mcm","clk":"11450137102","pt":1717318428765,"mc":[{"id":"1.229554910","rc":[{"atl":[[1000,1.75]],"id":70003369}],"con":true,"img":false}]}
{"op":"mcm","clk":"11450137777","pt":1717318436255,"mc":[{"id":"1.229554910","rc":[{"atb":[[4,0]],"id":70003369},{"atb":[[5.9,0]],"id":69033911},{"atl":[[28,0]],"id":69033911},{"atb":[[1.74,0]],"id":69676139},{"atb":[[3.95,0]],"id":55943164},{"atb":[[5.9,2.63],[5.4,0]],"id":54867443},{"atl":[[28,0]],"id":54867443}],"con":true,"img":false}]}
{"op":"mcm","clk":"11450137783","pt":1717318436360,"mc":[{"id":"1.229554910","rc":[{"atb":[[4.3,0],[3.7,40.11]],"id":70003369},{"atb":[[6.2,0],[5.3,27.25]],"id":69033911},{"atl":[[32,4.34]],"id":69033911},{"atb":[[1.64,178.2]],"id":69676139},{"atb":[[3.5,2.64],[3.65,20.4]],"id":55943164},{"atb":[[5.5,12.2],[4.9,26.42],[5.9,0]],"id":54867443},{"atl":[[32,3.32]],"id":54867443}],"con":true,"img":false}]}
{"op":"mcm","clk":"11450137794","pt":1717318436459,"mc":[{"id":"1.229554910","rc":[{"atb":[[2.16,2.63]],"id":54867443}],"con":true,"img":false}]}
{"op":"mcm","clk":"11450137804","pt":1717318436564,"mc":[{"id":"1.229554910","rc":[{"atb":[[4,0]],"id":55943164}],"con":true,"img":false}]}
{"op":"mcm","clk":"11450137852","pt":1717318437091,"mc":[{"id":"1.229554910","rc":[{"atb":[[3.5,0]],"id":55943164}],"con":true,"img":false}]}
{"op":"mcm","clk":"11450137864","pt":1717318437144,"mc":[{"id":"1.229554910","rc":[{"atb":[[3.7,2.64]],"id":55943164}],"con":true,"img":false}]}
{"op":"mcm","clk":"11450138291","pt":1717318441682,"mc":[{"id":"1.229554910","rc":[{"spn":8.6,"spf":"NaN","id":70003369},{"spn":12.75,"spf":"NaN","id":69033911},{"atb":[[1.75,61.85]],"id":69676139},{"spn":535.0,"spf":"NaN","id":52272946},{"spn":7.6,"spf":"NaN","id":55943164},{"spn":14.25,"spf":"NaN","id":54867443}],"con":true,"img":false}]}
{"op":"mcm","clk":"11450138370","pt":1717318442408,"mc":[{"id":"1.229554910","rc":[{"atb":[[3.45,85.33],[3.95,35.43],[3.7,117.54]],"id":70003369},{"atl":[[19.5,7.53],[29,7.46]],"id":70003369},{"atb":[[4.8,55.01],[5.8,21.77],[5.3,75.87]],"id":69033911},{"atl":[[48,4.44],[29,4.97]],"id":69033911},{"atb":[[1.73,143.19],[1.63,331.84],[1.68,307.44]],"id":69676139},{"atl":[[4,46.45],[5,52.26]],"id":69676139},{"atb":[[70,4.13],[38,5.65],[48,4.44]],"id":52272946},{"atl":[[630,0.21],[730,0.28]],"id":52272946},{"atb":[[3.4,87.1],[3.9,36.04],[3.65,99.29]],"id":55943164},{"atl":[[19,13.3],[28,7.74]],"id":55943164},{"atb":[[4.8,55.01],[5.8,21.77],[5.3,48.61]],"id":54867443},{"atl":[[48,4.44],[29,4.97]],"id":54867443}],"con":true,"img":false}]}
{"op":"mcm","clk":"11450138390","pt":1717318442568,"mc":[{"id":"1.229554910","rc":[{"atb":[[4.3,2.53]],"id":70003369},{"atb":[[6.2,2.59]],"id":69033911},{"atb":[[3.7,0]],"id":55943164},{"atb":[[2.16,0]],"id":54867443}],"con":true,"img":false}]}
{"op":"mcm","clk":"11450138401","pt":1717318442668,"mc":[{"id":"1.229554910","rc":[{"atb":[[3.95,2.64]],"id":55943164},{"atb":[[5.9,2.63]],"id":54867443}],"con":true,"img":false}]}
{"op":"mcm","clk":"11450141651","pt":1717318480111,"mc":[{"id":"1.229554910","rc":[{"atb":[[1.74,15.32]],"id":69676139}],"con":true,"img":false}]}
{"op":"mcm","clk":"11450142607","pt":1717318491348,"mc":[{"id":"1.229554910","rc":[{"atb":[[5.3,48.61]],"id":69033911},{"atl":[[32,0]],"id":69033911},{"atb":[[1.64,0]],"id":69676139},{"atb":[[3.65,78.88]],"id":55943164},{"atb":[[5.5,0]],"id":54867443},{"atl":[[32,0]],"id":54867443}],"con":true,"img":false}]}
{"op":"mcm","clk":"11450142615","pt":1717318491452,"mc":[{"id":"1.229554910","rc":[{"atb":[[5.4,27.25]],"id":69033911},{"atl":[[28,4.34]],"id":69033911},{"atb":[[1.74,193.52]],"id":69676139},{"atb":[[3.95,23.04]],"id":55943164},{"atb":[[5.9,14.83]],"id":54867443},{"atl":[[28,3.32]],"id":54867443}],"con":true,"img":false}]}
{"op":"mcm","clk":"11450143324","pt":1717318499051,"mc":[{"id":"1.229554910","rc":[{"atb":[[3.7,77.43]],"id":70003369},{"atb":[[4.9,0]],"id":54867443}],"con":true,"img":false}]}
{"op":"mcm","clk":"11450143332","pt":1717318499155,"mc":[{"id":"1.229554910","rc":[{"atb":[[4,40.11]],"id":70003369},{"atb":[[5.4,26.42]],"id":54867443}],"con":true,"img":false}]}
{"op":"mcm","clk":"11450145987","pt":1717318530285,"mc":[{"id":"1.229554910","rc":[{"spn":8.65,"spf":"NaN","id":70003369},{"spn":12.85,"spf":"NaN","id":69033911},{"atb":[[1.74,178.2]],"id":69676139},{"spn":350.0,"spf":"NaN","id":52272946},{"spn":7.72,"spf":"NaN","id":55943164},{"spn":14.45,"spf":"NaN","id":54867443}],"con":true,"img":false}]}
{"op":"mcm","clk":"11450147702","pt":1717318549822,"mc":[{"id":"1.229554910","rc":[{"atb":[[1.75,76.97]],"id":69676139}],"con":true,"img":false}]}
{"op":"mcm","clk":"11450147720","pt":1717318550032,"mc":[{"id":"1.229554910","rc":[{"atl":[[1000,1.17]],"id":70003369}],"con":true,"img":false}]}
{"op":"mcm","clk":"11450147730","pt":1717318550090,"mc":[{"id":"1.229554910","rc":[{"atl":[[13,1.25]],"id":70003369}],"con":true,"img":false}]}
{"op":"mcm","clk":"11450147777","pt":1717318550604,"mc":[{"id":"1.229554910","rc":[{"atl":[[13,0.68]],"id":70003369}],"con":true,"img":false}]}
{"op":"mcm","clk":"11450147789","pt":1717318550710,"mc":[{"id":"1.229554910","rc":[{"atl":[[1000,1.75]],"id":70003369}],"con":true,"img":false}]}
{"op":"mcm","clk":"11450147831","pt":1717318551227,"mc":[{"id":"1.229554910","rc":[{"atl":[[1000,1.17]],"id":70003369}],"con":true,"img":false}]}
{"op":"mcm","clk":"11450147840","pt":1717318551284,"mc":[{"id":"1.229554910","rc":[{"atl":[[13,1.25]],"id":70003369}],"con":true,"img":false}]}
{"op":"mcm","clk":"11450147887","pt":1717318551800,"mc":[{"id":"1.229554910","rc":[{"atl":[[13,0.68]],"id":70003369}],"con":true,"img":false}]}
{"op":"mcm","clk":"11450147894","pt":1717318551901,"mc":[{"id":"1.229554910","rc":[{"atl":[[1000,1.75]],"id":70003369}],"con":true,"img":false}]}
{"op":"mcm","clk":"11450147902","pt":1717318552004,"mc":[{"id":"1.229554910","rc":[{"atl":[[12,1.61]],"id":55943164}],"con":true,"img":false}]}
{"op":"mcm","clk":"11450148414","pt":1717318557907,"mc":[{"id":"1.229554910","rc":[{"atb":[[5.4,0]],"id":69033911}],"con":true,"img":false}]}
{"op":"mcm","clk":"11450148426","pt":1717318558014,"mc":[{"id":"1.229554910","rc":[{"atb":[[5.9,27.25]],"id":69033911}],"con":true,"img":false}]}
{"op":"mcm","clk":"11450149222","pt":1717318566829,"mc":[{"id":"1.229554910","rc":[{"atl":[[13.5,1.43]],"id":70003369}],"con":true,"img":false}]}
{"op":"mcm","clk":"11450152781","pt":1717318602851,"mc":[{"id":"1.229554910","rc":[{"atl":[[12,0]],"id":55943164}],"con":true,"img":false}]}
{"op":"mcm","clk":"11450152800","pt":1717318603050,"mc":[{"id":"1.229554910","rc":[{"atl":[[11.5,0]],"id":55943164}],"con":true,"img":false}]}
{"op":"mcm","clk":"11450152811","pt":1717318603153,"mc":[{"id":"1.229554910","rc":[{"atl":[[1000,1.57]],"id":55943164}],"con":true,"img":false}]}
{"op":"mcm","clk":"11450154915","pt":1717318626271,"mc":[{"id":"1.229554910","rc":[{"atl":[[13.5,0]],"id":70003369}],"con":true,"img":false}]}
{"op":"mcm","clk":"11450155041","pt":1717318627713,"mc":[{"id":"1.229554910","rc":[{"atl":[[13,0]],"id":70003369}],"con":true,"img":false}]}
{"op":"mcm","clk":"11450157893","pt":1717318653816,"mc":[{"id":"1.229554910","rc":[{"atl":[[12,1.61]],"id":55943164}],"con":true,"img":false}]}
{"op":"mcm","clk":"11450157918","pt":1717318654023,"mc":[{"id":"1.229554910","rc":[{"atl":[[13.5,1.43]],"id":70003369}],"con":true,"img":false}]}
{"op":"mcm","clk":"11450159913","pt":1717318674140,"mc":[{"id":"1.229554910","rc":[{"atb":[[2.24,0],[2.36,73.53]],"id":70003369},{"spn":8.9,"spf":"NaN","id":70003369},{"spn":7.97,"spf":"NaN","id":55943164}],"con":true,"img":false}]}
{"op":"mcm","clk":"11450163828","pt":1717318715287,"mc":[{"id":"1.229554910","rc":[{"atl":[[3.6,6.81]],"id":69676139}],"con":true,"img":false}]}
{"op":"mcm","clk":"11450163840","pt":1717318715442,"mc":[{"id":"1.229554910","rc":[{"atl":[[17,6.81]],"id":55943164}],"con":true,"img":false}]}
{"op":"mcm","clk":"11450163854","pt":1717318715652,"mc":[{"id":"1.229554910","rc":[{"atl":[[18,6.81]],"id":70003369}],"con":true,"img":false}]}
{"op":"mcm","clk":"11450163871","pt":1717318715855,"mc":[{"id":"1.229554910","rc":[{"atl":[[32,6.81]],"id":69033911}],"con":true,"img":false}]}
{"op":"mcm","clk":"11450163892","pt":1717318716166,"mc":[{"id":"1.229554910","rc":[{"atl":[[32,6.81]],"id":54867443}],"con":true,"img":false}]}
{"op":"mcm","clk":"11450163919","pt":1717318716474,"mc":[{"id":"1.229554910","rc":[{"atb":[[1.51,7.66]],"id":69676139}],"con":true,"img":false}]}
{"op":"mcm","clk":"11450163951","pt":1717318716784,"mc":[{"id":"1.229554910","rc":[{"atb":[[3.6,7.66]],"id":55943164}],"con":true,"img":false}]}
{"op":"mcm","clk":"11450163966","pt":1717318716987,"mc":[{"id":"1.229554910","rc":[{"atb":[[3.75,7.66]],"id":70003369}],"con":true,"img":false}]}
{"op":"mcm","clk":"11450163988","pt":1717318717193,"mc":[{"id":"1.229554910","rc":[{"atb":[[5.8,29.44]],"id":69033911}],"con":true,"img":false}]}
{"op":"mcm","clk":"11450164003","pt":1717318717352,"mc":[{"id":"1.229554910","rc":[{"atb":[[5.8,29.44]],"id":54867443}],"con":true,"img":false}]}
{"op":"mcm","clk":"11450167711","pt":1717318756313,"mc":[{"id":"1.229554910","rc":[{"atl":[[19,0]],"id":70003369},{"atl":[[17.5,0]],"id":55943164}],"con":true,"img":false}]}
{"op":"mcm","clk":"11450167720","pt":1717318756410,"mc":[{"id":"1.229554910","rc":[{"atl":[[17.5,5.68]],"id":70003369},{"atl":[[16.5,6.73]],"id":55943164}],"con":true,"img":false}]}
{"op":"mcm","clk":"11450171376","pt":1717318799365,"mc":[{"id":"1.229554910","rc":[{"atb":[[3.45,0],[3.95,0],[3.7,0]],"id":70003369},{"atl":[[19.5,0],[29,0]],"id":70003369},{"atb":[[4.8,0],[5.8,7.66],[5.3,0]],"id":69033911},{"atl":[[48,0],[29,0]],"id":69033911},{"atb":[[1.73,0],[1.63,0],[1.68,0]],"id":69676139},{"atl":[[4,0],[5,0]],"id":69676139},{"atb":[[70,2.61],[38,0],[48,0]],"id":52272946},{"atl":[[630,0],[730,0]],"id":52272946},{"atb":[[3.4,0],[3.9,0],[3.65,0]],"id":55943164},{"atl":[[19,5.56],[28,0]],"id":55943164},{"atb":[[4.8,0],[5.8,7.66],[5.3,0]],"id":54867443},{"atl":[[48,0],[29,0]],"id":54867443}],"con":true,"img":false}]}
{"op":"mcm","clk":"11450171413","pt":1717318799880,"mc":[{"id":"1.229554910","rc":[{"atl":[[1000,1.68]],"id":70003369},{"atb":[[3.95,20.4]],"id":55943164}],"con":true,"img":false}]}
{"op":"mcm","clk":"11450172262","pt":1717318807291,"mc":[{"id":"1.229554910","rc":[{"atl":[[1000,4.04]],"id":70003369},{"atl":[[1000,3.92]],"id":55943164}],"con":true,"img":false}]}
{"op":"mcm","clk":"11450172282","pt":1717318807546,"mc":[{"id":"1.229554910","rc":[{"atl":[[1000,2.67]],"id":70003369},{"atl":[[1000,2.68]],"id":55943164}],"con":true,"img":false}]}
{"op":"mcm","clk":"11450172298","pt":1717318807754,"mc":[{"id":"1.229554910","rc":[{"atl":[[1000,1.68]],"id":70003369}],"con":true,"img":false}]}
{"op":"mcm","clk":"11450172306","pt":1717318807858,"mc":[{"id":"1.229554910","rc":[{"atl":[[13.5,2.42]],"id":70003369}],"con":true,"img":false}]}
{"op":"mcm","clk":"11450172323","pt":1717318808193,"mc":[{"id":"1.229554910","rc":[{"atl":[[1000,1.57]],"id":55943164}],"con":true,"img":false}]}
{"op":"mcm","clk":"11450172336","pt":1717318808270,"mc":[{"id":"1.229554910","rc":[{"atl":[[12,2.72]],"id":55943164}],"con":true,"img":false}]}
{"op":"mcm","clk":"11450172503","pt":1717318810081,"mc":[{"id":"1.229554910","rc":[{"atl":[[1000,2.54]],"id":70003369}],"con":true,"img":false}]}
{"op":"mcm","clk":"11450172527","pt":1717318810284,"mc":[{"id":"1.229554910","rc":[{"atl":[[12.5,0]],"id":55943164}],"con":true,"img":false}]}
{"op":"mcm","clk":"11450172556","pt":1717318810595,"mc":[{"id":"1.229554910","rc":[{"atl":[[1000,2.42]],"id":55943164}],"con":true,"img":false}]}
{"op":"mcm","clk":"11450172588","pt":1717318810954,"mc":[{"id":"1.229554910","rc":[{"atl":[[1000,1.85]],"id":55943164}],"con":true,"img":false}]}
{"op":"mcm","clk":"11450172606","pt":1717318811064,"mc":[{"id":"1.229554910","rc":[{"atl":[[11.5,0.57]],"id":55943164}],"con":true,"img":false}]}
{"op":"mcm","clk":"11450172823","pt":1717318813200,"mc":[{"id":"1.229554910","rc":[{"atl":[[1000,2.34]],"id":70003369}],"con":true,"img":false}]}
{"op":"mcm","clk":"11450172921","pt":1717318814088,"mc":[{"id":"1.229554910","rc":[{"atl":[[1000,1.74]],"id":55943164}],"con":true,"img":false}]}
{"op":"mcm","clk":"11450173178","pt":1717318816479,"mc":[{"id":"1.229554910","rc":[{"atb":[[3.45,85.33],[3.95,35.43],[3.7,77.43]],"id":70003369},{"atl":[[19.5,7.53],[29,7.46]],"id":70003369},{"atb":[[4.8,55.01],[5.8,29.44],[5.3,48.61]],"id":69033911},{"atl":[[48,4.44],[29,4.97]],"id":69033911},{"atb":[[1.73,143.19],[1.63,331.84],[1.68,307.44]],"id":69676139},{"atl":[[4,46.45],[5,52.26]],"id":69676139},{"atb":[[70,4.13],[38,5.65],[48,4.44]],"id":52272946},{"atl":[[630,0.21],[730,0.28]],"id":52272946},{"atb":[[3.4,87.1],[3.9,36.04],[3.65,78.88]],"id":55943164},{"atl":[[19,13.3],[28,7.74]],"id":55943164},{"spn":7.72,"spf":"NaN","id":55943164},{"atb":[[4.8,55.01],[5.8,29.44],[5.3,48.61]],"id":54867443},{"atl":[[48,4.44],[29,4.97]],"id":54867443}],"con":true,"img":false}]}
{"op":"mcm","clk":"11450173197","pt":1717318816589,"mc":[{"id":"1.229554910","rc":[{"atb":[[4,2.64]],"id":55943164}],"con":true,"img":false}]}
{"op":"mcm","clk":"11450173443","pt":1717318819070,"mc":[{"id":"1.229554910","rc":[{"atl":[[1000,1.68]],"id":70003369}],"con":true,"img":false}]}
{"op":"mcm","clk":"11450173454","pt":1717318819177,"mc":[{"id":"1.229554910","rc":[{"atl":[[13,0.65]],"id":70003369}],"con":true,"img":false}]}
{"op":"mcm","clk":"11450173524","pt":1717318820008,"mc":[{"id":"1.229554910","rc":[{"atl":[[1000,1.17]],"id":70003369}],"con":true,"img":false}]}
{"op":"mcm","clk":"11450173537","pt":1717318820101,"mc":[{"id":"1.229554910","rc":[{"atl":[[13,1.16]],"id":70003369}],"con":true,"img":false}]}
{"op":"mcm","clk":"11450173574","pt":1717318820465,"mc":[{"id":"1.229554910","rc":[{"atl":[[13,0.65]],"id":70003369}],"con":true,"img":false}]}
{"op":"mcm","clk":"11450173585","pt":1717318820568,"mc":[{"id":"1.229554910","rc":[{"atl":[[1000,1.68]],"id":70003369}],"con":true,"img":false}]}
{"op":"mcm","clk":"11450173643","pt":1717318821289,"mc":[{"id":"1.229554910","rc":[{"atl":[[1000,1]],"id":55943164}],"con":true,"img":false}]}
{"op":"mcm","clk":"11450173652","pt":1717318821392,"mc":[{"id":"1.229554910","rc":[{"atl":[[11.5,1.31]],"id":55943164}],"con":true,"img":false}]}
{"op":"mcm","clk":"11450174138","pt":1717318826809,"mc":[{"id":"1.229554910","rc":[{"atb":[[4.1,2.07]],"id":55943164}],"con":true,"img":false}]}
{"op":"mcm","clk":"11450176597","pt":1717318854056,"mc":[{"id":"1.229554910","rc":[{"atl":[[12,1.11]],"id":55943164}],"con":true,"img":false}]}
{"op":"mcm","clk":"11450176663","pt":1717318854731,"mc":[{"id":"1.229554910","rc":[{"atl":[[1000,1.17]],"id":70003369},{"atl":[[11.5,0.74]],"id":55943164}],"con":true,"img":false}]}
{"op":"mcm","clk":"11450176673","pt":1717318854833,"mc":[{"id":"1.229554910","rc":[{"atl":[[13,1.16]],"id":70003369},{"atl":[[1000,1.57]],"id":55943164}],"con":true,"img":false}]}
{"op":"mcm","clk":"11450176727","pt":1717318855443,"mc":[{"id":"1.229554910","rc":[{"atl":[[13,0.65]],"id":70003369}],"con":true,"img":false}]}
{"op":"mcm","clk":"11450176737","pt":1717318855538,"mc":[{"id":"1.229554910","rc":[{"atl":[[1000,1.68]],"id":70003369}],"con":true,"img":false}]}
{"op":"mcm","clk":"11450176788","pt":1717318856012,"mc":[{"id":"1.229554910","rc":[{"atl":[[1000,1.17]],"id":70003369}],"con":true,"img":false}]}
{"op":"mcm","clk":"11450176799","pt":1717318856116,"mc":[{"id":"1.229554910","rc":[{"atl":[[13,1.16]],"id":70003369}],"con":true,"img":false}]}
{"op":"mcm","clk":"11450176868","pt":1717318856745,"mc":[{"id":"1.229554910","rc":[{"atl":[[13,0.65]],"id":70003369}],"con":true,"img":false}]}
{"op":"mcm","clk":"11450176881","pt":1717318856851,"mc":[{"id":"1.229554910","rc":[{"atl":[[1000,1.68]],"id":70003369}],"con":true,"img":false}]}
{"op":"mcm","clk":"11450180441","pt":1717318893149,"mc":[{"id":"1.229554910","rc":[{"atl":[[13.5,0.98]],"id":70003369},{"spn":8.65,"spf":"NaN","id":70003369},{"spn":7.8,"spf":"NaN","id":55943164}],"con":true,"img":false}]}
{"op":"mcm","clk":"11450184419","pt":1717318936002,"mc":[{"id":"1.229554910","rc":[{"atl":[[12,2.72]],"id":55943164}],"con":true,"img":false}]}
{"op":"mcm","clk":"11450184431","pt":1717318936106,"mc":[{"id":"1.229554910","rc":[{"atl":[[13.5,2.42]],"id":70003369}],"con":true,"img":false}]}
{"op":"mcm","clk":"11450184514","pt":1717318936737,"mc":[{"id":"1.229554910","rc":[{"atl":[[1000,1]],"id":55943164}],"con":true,"img":false}]}
{"op":"mcm","clk":"11450184522","pt":1717318936792,"mc":[{"id":"1.229554910","rc":[{"atl":[[11.5,1.31]],"id":55943164}],"con":true,"img":false}]}
{"op":"mcm","clk":"11450190144","pt":1717318993265,"mc":[{"id":"1.229554910","rc":[{"atl":[[12,1.61]],"id":55943164}],"con":true,"img":false}]}
{"op":"mcm","clk":"11450190190","pt":1717318993785,"mc":[{"id":"1.229554910","rc":[{"atl":[[11.5,0.74]],"id":55943164}],"con":true,"img":false}]}
{"op":"mcm","clk":"11450190202","pt":1717318993992,"mc":[{"id":"1.229554910","rc":[{"atl":[[1000,1.57]],"id":55943164}],"con":true,"img":false}]}
{"op":"mcm","clk":"11450191529","pt":1717319008586,"mc":[{"id":"1.229554910","rc":[{"atl":[[13.5,1.43]],"id":70003369}],"con":true,"img":false}]}
{"op":"mcm","clk":"11450193002","pt":1717319023633,"mc":[{"id":"1.229554910","rc":[{"atl":[[1000,4.04]],"id":70003369},{"atl":[[1000,3.92]],"id":55943164}],"con":true,"img":false}]}
{"op":"mcm","clk":"11450193029","pt":1717319023841,"mc":[{"id":"1.229554910","rc":[{"atl":[[1000,2.67]],"id":70003369},{"atl":[[1000,2.68]],"id":55943164}],"con":true,"img":false}]}
{"op":"mcm","clk":"11450193063","pt":1717319024106,"mc":[{"id":"1.229554910","rc":[{"atl":[[1000,1.57]],"id":55943164}],"con":true,"img":false}]}
{"op":"mcm","clk":"11450193078","pt":1717319024222,"mc":[{"id":"1.229554910","rc":[{"atl":[[12,2.72]],"id":55943164}],"con":true,"img":false}]}
{"op":"mcm","clk":"11450193101","pt":1717319024459,"mc":[{"id":"1.229554910","rc":[{"atl":[[1000,1.68]],"id":70003369}],"con":true,"img":false}]}
{"op":"mcm","clk":"11450193110","pt":1717319024513,"mc":[{"id":"1.229554910","rc":[{"atl":[[13.5,2.42]],"id":70003369}],"con":true,"img":false}]}
{"op":"mcm","clk":"11450193179","pt":1717319025035,"mc":[{"id":"1.229554910","rc":[{"atl":[[1000,1]],"id":55943164}],"con":true,"img":false}]}
{"op":"mcm","clk":"11450193187","pt":1717319025141,"mc":[{"id":"1.229554910","rc":[{"atl":[[11.5,1.31]],"id":55943164}],"con":true,"img":false}]}
{"op":"mcm","clk":"11450203030","pt":1717319130163,"mc":[{"id":"1.229554910","rc":[{"atl":[[12,1.11]],"id":55943164}],"con":true,"img":false}]}
{"op":"mcm","clk":"11450203076","pt":1717319130733,"mc":[{"id":"1.229554910","rc":[{"atl":[[1000,1.17]],"id":70003369},{"atl":[[11.5,0.74]],"id":55943164}],"con":true,"img":false}]}
{"op":"mcm","clk":"11450203086","pt":1717319130836,"mc":[{"id":"1.229554910","rc":[{"atl":[[13,1.16]],"id":70003369},{"atl":[[1000,1.57]],"id":55943164}],"con":true,"img":false}]}
{"op":"mcm","clk":"11450203119","pt":1717319131253,"mc":[{"id":"1.229554910","rc":[{"atl":[[13,0.65]],"id":70003369}],"con":true,"img":false}]}
{"op":"mcm","clk":"11450203131","pt":1717319131357,"mc":[{"id":"1.229554910","rc":[{"atl":[[1000,1.68]],"id":70003369}],"con":true,"img":false}]}
{"op":"mcm","clk":"11450207404","pt":1717319173783,"mc":[{"id":"1.229554910","rc":[{"atl":[[13.5,0.98]],"id":70003369}],"con":true,"img":false}]}
{"op":"mcm","clk":"11450208349","pt":1717319182711,"mc":[{"id":"1.229554910","rc":[{"atb":[[3.45,0],[3.95,0],[3.7,0]],"id":70003369},{"atl":[[19.5,0],[29,0]],"id":70003369},{"atb":[[4.8,0],[5.8,7.66],[5.3,0]],"id":69033911},{"atl":[[48,0],[29,0]],"id":69033911},{"atb":[[1.73,0],[1.63,0],[1.68,0]],"id":69676139},{"atl":[[4,0],[5,0]],"id":69676139},{"atb":[[70,2.61],[38,0],[48,0]],"id":52272946},{"atl":[[630,0],[730,0]],"id":52272946},{"atb":[[3.4,0],[3.9,0],[3.65,0]],"id":55943164},{"atl":[[19,5.56],[28,0]],"id":55943164},{"atb":[[4.8,0],[5.8,7.66],[5.3,0]],"id":54867443},{"atl":[[48,0],[29,0]],"id":54867443}],"con":true,"img":false}]}
{"op":"mcm","clk":"11450208362","pt":1717319182818,"mc":[{"id":"1.229554910","rc":[{"atb":[[4,0]],"id":55943164}],"con":true,"img":false}]}
{"op":"mcm","clk":"11450208399","pt":1717319183137,"mc":[{"id":"1.229554910","rc":[{"atb":[[4.1,0]],"id":55943164}],"con":true,"img":false}]}
{"op":"mcm","clk":"11450208495","pt":1717319183804,"mc":[{"id":"1.229554910","rc":[{"atb":[[4,0]],"id":70003369},{"atl":[[28,0]],"id":69033911},{"atb":[[1.74,0]],"id":69676139},{"atb":[[3.95,0]],"id":55943164},{"atb":[[5.4,0]],"id":54867443},{"atl":[[28,0]],"id":54867443}],"con":true,"img":false}]}
{"op":"mcm","clk":"11450208507","pt":1717319183907,"mc":[{"id":"1.229554910","rc":[{"atb":[[3.8,40.11]],"id":70003369},{"atl":[[30,4.34]],"id":69033911},{"atb":[[1.64,178.2]],"id":69676139},{"atb":[[3.65,20.4]],"id":55943164},{"atb":[[4.9,26.42]],"id":54867443},{"atl":[[30,3.32]],"id":54867443}],"con":true,"img":false}]}
{"op":"mcm","clk":"11450208518","pt":1717319184011,"mc":[{"id":"1.229554910","rc":[{"atb":[[4.3,0]],"id":70003369},{"atb":[[3.7,2.64]],"id":55943164}],"con":true,"img":false}]}
{"op":"mcm","clk":"11450208533","pt":1717319184170,"mc":[{"id":"1.229554910","rc":[{"atl":[[23,0]],"id":54867443}],"con":true,"img":false}]}
{"op":"mcm","clk":"11450210488","pt":1717319203422,"mc":[{"id":"1.229554910","rc":[{"atb":[[3.45,85.33],[3.95,35.43],[3.7,77.43]],"id":70003369},{"atl":[[19.5,7.53],[29,7.46]],"id":70003369},{"spn":8.6,"spf":"NaN","id":70003369},{"atb":[[4.8,55.01],[5.8,29.44],[5.3,48.61]],"id":69033911},{"atl":[[48,4.44],[29,4.97]],"id":69033911},{"atb":[[1.73,143.19],[1.63,331.84],[1.68,307.44]],"id":69676139},{"atl":[[4,46.45],[5,52.26]],"id":69676139},{"atb":[[70,4.13],[38,5.65],[48,4.44]],"id":52272946},{"atl":[[630,0.21],[730,0.28]],"id":52272946},{"atb":[[3.4,87.1],[3.9,36.04],[3.65,99.29]],"id":55943164},{"atl":[[19,13.3],[28,7.74]],"id":55943164},{"spn":7.7,"spf":"NaN","id":55943164},{"atb":[[4.8,55.01],[5.8,29.44],[5.3,48.61]],"id":54867443},{"atl":[[48,4.44],[29,4.97]],"id":54867443},{"spn":14.95,"spf":"NaN","id":54867443}],"con":true,"img":false}]}
{"op":"mcm","clk":"11450210572","pt":1717319203994,"mc":[{"id":"1.229554910","rc":[{"atb":[[4.3,2.53]],"id":70003369},{"atb":[[3.7,0]],"id":55943164}],"con":true,"img":false}]}
{"op":"mcm","clk":"11450210582","pt":1717319204097,"mc":[{"id":"1.229554910","rc":[{"atb":[[3.95,2.64]],"id":55943164}],"con":true,"img":false}]}
{"op":"mcm","clk":"11450210605","pt":1717319204304,"mc":[{"id":"1.229554910","rc":[{"atl":[[12,0]],"id":55943164}],"con":true,"img":false}]}
{"op":"mcm","clk":"11450210721","pt":1717319205497,"mc":[{"id":"1.229554910","rc":[{"atb":[[3.95,7.12]],"id":55943164}],"con":true,"img":false}]}
{"op":"mcm","clk":"11450211093","pt":1717319209531,"mc":[{"id":"1.229554910","rc":[{"atl":[[12,1.61]],"id":55943164}],"con":true,"img":false}]}
{"op":"mcm","clk":"11450211106","pt":1717319209636,"mc":[{"id":"1.229554910","rc":[{"atl":[[13.5,2.42]],"id":70003369}],"con":true,"img":false}]}
{"op":"mcm","clk":"11450211127","pt":1717319209845,"mc":[{"id":"1.229554910","rc":[{"atl":[[1000,1.17]],"id":70003369},{"atb":[[1.75,61.85]],"id":69676139}],"con":true,"img":false}]}
{"op":"mcm","clk":"11450211142","pt":1717319209903,"mc":[{"id":"1.229554910","rc":[{"atl":[[13,1.16]],"id":70003369}],"con":true,"img":false}]}
{"op":"mcm","clk":"11450211191","pt":1717319210437,"mc":[{"id":"1.229554910","rc":[{"atl":[[13,0.65]],"id":70003369}],"con":true,"img":false}]}
{"op":"mcm","clk":"11450211201","pt":1717319210523,"mc":[{"id":"1.229554910","rc":[{"atl":[[1000,1.68]],"id":70003369}],"con":true,"img":false}]}
{"op":"mcm","clk":"11450211247","pt":1717319211035,"mc":[{"id":"1.229554910","rc":[{"atl":[[1000,1.17]],"id":70003369}],"con":true,"img":false}]}
{"op":"mcm","clk":"11450211258","pt":1717319211143,"mc":[{"id":"1.229554910","rc":[{"atl":[[13,1.16]],"id":70003369}],"con":true,"img":false}]}
{"op":"mcm","clk":"11450211309","pt":1717319211611,"mc":[{"id":"1.229554910","rc":[{"atl":[[13,0.65]],"id":70003369}],"con":true,"img":false}]}
{"op":"mcm","clk":"11450211320","pt":1717319211713,"mc":[{"id":"1.229554910","rc":[{"atl":[[1000,1.68]],"id":70003369}],"con":true,"img":false}]}
{"op":"mcm","clk":"11450212551","pt":1717319224015,"mc":[{"id":"1.229554910","rc":[{"atl":[[1000,1.54]],"id":69033911},{"atl":[[1000,1.51]],"id":55943164}],"con":true,"img":false}]}
{"op":"mcm","clk":"11450212997","pt":1717319228360,"mc":[{"id":"1.229554910","rc":[{"atl":[[13.5,1.43]],"id":70003369}],"con":true,"img":false}]}
{"op":"mcm","clk":"11450214256","pt":1717319241137,"mc":[{"id":"1.229554910","rc":[{"atb":[[3.65,78.88]],"id":55943164}],"con":true,"img":false}]}
{"op":"mcm","clk":"11450214270","pt":1717319241240,"mc":[{"id":"1.229554910","rc":[{"atb":[[3.95,27.52]],"id":55943164}],"con":true,"img":false}]}
{"op":"mcm","clk":"11450214512","pt":1717319243479,"mc":[{"id":"1.229554910","rc":[{"atl":[[1000,4.04]],"id":70003369},{"atl":[[1000,3.87]],"id":55943164}],"con":true,"img":false}]}
{"op":"mcm","clk":"11450214541","pt":1717319243656,"mc":[{"id":"1.229554910","rc":[{"atl":[[1000,2.67]],"id":70003369},{"atl":[[1000,2.63]],"id":55943164}],"con":true,"img":false}]}
{"op":"mcm","clk":"11450214566","pt":1717319243871,"mc":[{"id":"1.229554910","rc":[{"atl":[[1000,1.68]],"id":70003369}],"con":true,"img":false}]}
{"op":"mcm","clk":"11450214576","pt":1717319243972,"mc":[{"id":"1.229554910","rc":[{"atl":[[13.5,2.42]],"id":70003369}],"con":true,"img":false}]}
{"op":"mcm","clk":"11450214605","pt":1717319244274,"mc":[{"id":"1.229554910","rc":[{"atl":[[1000,1.51]],"id":55943164}],"con":true,"img":false}]}
{"op":"mcm","clk":"11450214619","pt":1717319244374,"mc":[{"id":"1.229554910","rc":[{"atl":[[12,2.72]],"id":55943164}],"con":true,"img":false}]}
{"op":"mcm","clk":"11450214686","pt":1717319244947,"mc":[{"id":"1.229554910","rc":[{"atl":[[1000,1]],"id":55943164}],"con":true,"img":false}]}
{"op":"mcm","clk":"11450214694","pt":1717319245054,"mc":[{"id":"1.229554910","rc":[{"atl":[[11.5,1.25]],"id":55943164}],"con":true,"img":false}]}
{"op":"mcm","clk":"11450214873","pt":1717319246771,"mc":[{"id":"1.229554910","rc":[{"atb":[[1.74,15.32]],"id":69676139}],"con":true,"img":false}]}
{"op":"mcm","clk":"11450215077","pt":1717319248647,"mc":[{"id":"1.229554910","rc":[{"atb":[[3.8,0]],"id":70003369},{"atl":[[30,0]],"id":69033911},{"atb":[[1.64,0]],"id":69676139},{"atl":[[30,0]],"id":54867443}],"con":true,"img":false}]}
{"op":"mcm","clk":"11450215088","pt":1717319248803,"mc":[{"id":"1.229554910","rc":[{"atb":[[4,40.11]],"id":70003369},{"atl":[[28,4.34]],"id":69033911},{"atb":[[1.74,193.52]],"id":69676139},{"atl":[[28,3.32]],"id":54867443}],"con":true,"img":false}]}
{"op":"mcm","clk":"11450216145","pt":1717319258462,"mc":[{"id":"1.229554910","rc":[{"atb":[[4.9,0]],"id":54867443}],"con":true,"img":false}]}
{"op":"mcm","clk":"11450216157","pt":1717319258568,"mc":[{"id":"1.229554910","rc":[{"atb":[[5.4,26.42]],"id":54867443}],"con":true,"img":false}]}
{"op":"mcm","clk":"11450217763","pt":1717319274400,"mc":[{"id":"1.229554910","rc":[{"spn":8.65,"spf":"NaN","id":70003369},{"spn":7.72,"spf":"NaN","id":55943164},{"atb":[[5.8,21.77]],"id":54867443}],"con":true,"img":false}]}
{"op":"mcm","clk":"11450217770","pt":1717319274499,"mc":[{"id":"1.229554910","rc":[{"atb":[[5.5,7.66]],"id":54867443}],"con":true,"img":false}]}
{"op":"mcm","clk":"11450217840","pt":1717319275323,"mc":[{"id":"1.229554910","rc":[{"atb":[[1.51,0]],"id":69676139}],"con":true,"img":false}]}
{"op":"mcm","clk":"11450217853","pt":1717319275380,"mc":[{"id":"1.229554910","rc":[{"atb":[[1.43,7.66]],"id":69676139}],"con":true,"img":false}]}
{"op":"mcm","clk":"11450217875","pt":1717319275685,"mc":[{"id":"1.229554910","rc":[{"atb":[[3.6,0]],"id":55943164}],"con":true,"img":false}]}
{"op":"mcm","clk":"11450217888","pt":1717319275793,"mc":[{"id":"1.229554910","rc":[{"atb":[[3.45,54.98]],"id":55943164}],"con":true,"img":false}]}
{"op":"mcm","clk":"11450217922","pt":1717319276102,"mc":[{"id":"1.229554910","rc":[{"atb":[[3.75,0]],"id":70003369}],"con":true,"img":false}]}
{"op":"mcm","clk":"11450217931","pt":1717319276207,"mc":[{"id":"1.229554910","rc":[{"atb":[[3.55,7.66]],"id":70003369}],"con":true,"img":false}]}
{"op":"mcm","clk":"11450217962","pt":1717319276524,"mc":[{"id":"1.229554910","rc":[{"atb":[[5.8,21.77]],"id":69033911}],"con":true,"img":false}]}
{"op":"mcm","clk":"11450217974","pt":1717319276577,"mc":[{"id":"1.229554910","rc":[{"atb":[[5.5,7.66]],"id":69033911}],"con":true,"img":false}]}
{"op":"mcm","clk":"11450218477","pt":1717319281610,"mc":[{"id":"1.229554910","rc":[{"atb":[[1.74,178.2]],"id":69676139}],"con":true,"img":false}]}
{"op":"mcm","clk":"11450218519","pt":1717319282127,"mc":[{"id":"1.229554910","rc":[{"atb":[[1.8,71.07]],"id":54867443}],"con":true,"img":false}]}
{"op":"mcm","clk":"11450218527","pt":1717319282230,"mc":[{"id":"1.229554910","rc":[{"atb":[[2.14,0]],"id":54867443}],"con":true,"img":false}]}
{"op":"mcm","clk":"11450218850","pt":1717319285406,"mc":[{"id":"1.229554910","rc":[{"atb":[[3.2,0],[3.5,40]],"id":69033911}],"con":true,"img":false}]}
{"op":"mcm","clk":"11450219583","pt":1717319292722,"mc":[{"id":"1.229554910","rc":[{"atl":[[2.64,2.61]],"id":69676139}],"con":true,"img":false}]}
{"op":"mcm","clk":"11450219598","pt":1717319292928,"mc":[{"id":"1.229554910","rc":[{"atb":[[1.77,3.39]],"id":69676139}],"con":true,"img":false}]}
{"op":"mcm","clk":"11450219617","pt":1717319293133,"mc":[{"id":"1.229554910","rc":[{"atb":[[1.76,0]],"id":69676139}],"con":true,"img":false}]}
{"op":"mcm","clk":"11450219630","pt":1717319293235,"mc":[{"id":"1.229554910","rc":[{"atb":[[1.77,6]],"id":69676139}],"con":true,"img":false}]}
{"op":"mcm","clk":"11450221086","pt":1717319308058,"mc":[{"id":"1.229554910","rc":[{"atl":[[2.64,0]],"id":69676139}],"con":true,"img":false}]}
{"op":"mcm","clk":"11450221110","pt":1717319308376,"mc":[{"id":"1.229554910","rc":[{"atb":[[1.77,2.6]],"id":69676139}],"con":true,"img":false}]}
{"op":"mcm","clk":"11450221170","pt":1717319308897,"mc":[{"id":"1.229554910","rc":[{"atb":[[1.77,0]],"id":69676139}],"con":true,"img":false}]}
{"op":"mcm","clk":"11450221184","pt":1717319309001,"mc":[{"id":"1.229554910","rc":[{"atb":[[1.76,2.6]],"id":69676139}],"con":true,"img":false}]}
{"op":"mcm","clk":"11450221647","pt":1717319313773,"mc":[{"id":"1.229554910","rc":[{"atl":[[2.64,2.61]],"id":69676139}],"con":true,"img":false}]}
{"op":"mcm","clk":"11450221667","pt":1717319313974,"mc":[{"id":"1.229554910","rc":[{"atb":[[1.77,3.39]],"id":69676139}],"con":true,"img":false}]}
{"op":"mcm","clk":"11450221722","pt":1717319314500,"mc":[{"id":"1.229554910","rc":[{"atb":[[1.76,0]],"id":69676139}],"con":true,"img":false}]}
{"op":"mcm","clk":"11450221736","pt":1717319314595,"mc":[{"id":"1.229554910","rc":[{"atb":[[1.77,6]],"id":69676139}],"con":true,"img":false}]}
{"op":"mcm","clk":"11450222432","pt":1717319321497,"mc":[{"id":"1.229554910","rc":[{"atb":[[1.75,76.97]],"id":69676139}],"con":true,"img":false}]}
{"op":"mcm","clk":"11450223073","pt":1717319329113,"mc":[{"id":"1.229554910","rc":[{"atl":[[2.64,0]],"id":69676139}],"con":true,"img":false}]}
{"op":"mcm","clk":"11450223087","pt":1717319329323,"mc":[{"id":"1.229554910","rc":[{"atb":[[1.77,2.6]],"id":69676139}],"con":true,"img":false}]}
{"op":"mcm","clk":"11450223127","pt":1717319329901,"mc":[{"id":"1.229554910","rc":[{"atb":[[1.77,0]],"id":69676139}],"con":true,"img":false}]}
{"op":"mcm","clk":"11450223137","pt":1717319330005,"mc":[{"id":"1.229554910","rc":[{"atb":[[1.76,2.6]],"id":69676139}],"con":true,"img":false}]}
{"op":"mcm","clk":"11450223915","pt":1717319339006,"mc":[{"id":"1.229554910","rc":[{"atl":[[2.64,2.61]],"id":69676139},{"spn":2.2,"spf":"NaN","id":69676139}],"con":true,"img":false}]}
{"op":"mcm","clk":"11450223927","pt":1717319339123,"mc":[{"id":"1.229554910","rc":[{"atb":[[1.77,3.39]],"id":69676139}],"con":true,"img":false}]}
{"op":"mcm","clk":"11450224006","pt":1717319339835,"mc":[{"id":"1.229554910","rc":[{"atb":[[1.76,0]],"id":69676139}],"con":true,"img":false}]}
{"op":"mcm","clk":"11450224019","pt":1717319339938,"mc":[{"id":"1.229554910","rc":[{"atb":[[1.77,6]],"id":69676139}],"con":true,"img":false}]}
{"op":"mcm","clk":"11450225382","pt":1717319354557,"mc":[{"id":"1.229554910","rc":[{"atb":[[1.77,2.6]],"id":69676139}],"con":true,"img":false}]}
{"op":"mcm","clk":"11450225401","pt":1717319354762,"mc":[{"id":"1.229554910","rc":[{"atb":[[1.77,0]],"id":69676139},{"atl":[[2.64,0]],"id":69676139}],"con":true,"img":false}]}
{"op":"mcm","clk":"11450225412","pt":1717319354868,"mc":[{"id":"1.229554910","rc":[{"atb":[[1.76,2.6]],"id":69676139}],"con":true,"img":false}]}
{"op":"mcm","clk":"11450225476","pt":1717319355437,"mc":[{"id":"1.229554910","rc":[{"atb":[[1.77,3.39]],"id":69676139},{"atl":[[2.64,2.61]],"id":69676139}],"con":true,"img":false}]}
{"op":"mcm","clk":"11450226846","pt":1717319370639,"mc":[{"id":"1.229554910","rc":[{"atl":[[2.64,0]],"id":69676139}],"con":true,"img":false}]}
{"op":"mcm","clk":"11450226865","pt":1717319370850,"mc":[{"id":"1.229554910","rc":[{"atb":[[1.77,0]],"id":69676139}],"con":true,"img":false}]}
{"op":"mcm","clk":"11450226893","pt":1717319371162,"mc":[{"id":"1.229554910","rc":[{"atb":[[1.78,3.35]],"id":69676139},{"atl":[[2.62,2.61]],"id":69676139}],"con":true,"img":false}]}
{"op":"mcm","clk":"11450226953","pt":1717319371580,"mc":[{"id":"1.229554910","rc":[{"atb":[[1.76,0]],"id":69676139}],"con":true,"img":false}]}
{"op":"mcm","clk":"11450228204","pt":1717319386376,"mc":[{"id":"1.229554910","rc":[{"atb":[[1.78,0]],"id":69676139}],"con":true,"img":false}]}
{"op":"mcm","clk":"11450228226","pt":1717319386624,"mc":[{"id":"1.229554910","rc":[{"atb":[[1.76,2.6]],"id":69676139},{"atl":[[2.62,0]],"id":69676139}],"con":true,"img":false}]}
{"op":"mcm","clk":"11450228382","pt":1717319388403,"mc":[{"id":"1.229554910","rc":[{"atl":[[2.64,2.61]],"id":69676139}],"con":true,"img":false}]}
{"op":"mcm","clk":"11450228394","pt":1717319388506,"mc":[{"id":"1.229554910","rc":[{"atb":[[1.77,3.39]],"id":69676139}],"con":true,"img":false}]}
{"op":"mcm","clk":"11450228441","pt":1717319388979,"mc":[{"id":"1.229554910","rc":[{"atb":[[1.76,0]],"id":69676139}],"con":true,"img":false}]}
{"op":"mcm","clk":"11450228447","pt":1717319389080,"mc":[{"id":"1.229554910","rc":[{"atb":[[1.77,6]],"id":69676139}],"con":true,"img":false}]}
{"op":"mcm","clk":"11450228916","pt":1717319394391,"mc":[{"id":"1.229554910","rc":[{"atb":[[1.43,0]],"id":69676139}],"con":true,"img":false}]}
{"op":"mcm","clk":"11450228924","pt":1717319394492,"mc":[{"id":"1.229554910","rc":[{"atb":[[1.48,7.66]],"id":69676139}],"con":true,"img":false}]}
{"op":"mcm","clk":"11450228953","pt":1717319394805,"mc":[{"id":"1.229554910","rc":[{"atb":[[3.45,47.31]],"id":55943164}],"con":true,"img":false}]}
{"op":"mcm","clk":"11450228964","pt":1717319394909,"mc":[{"id":"1.229554910","rc":[{"atb":[[3.55,7.66]],"id":55943164}],"con":true,"img":false}]}
{"op":"mcm","clk":"11450228987","pt":1717319395213,"mc":[{"id":"1.229554910","rc":[{"atb":[[3.55,0]],"id":70003369}],"con":true,"img":false}]}
{"op":"mcm","clk":"11450228994","pt":1717319395269,"mc":[{"id":"1.229554910","rc":[{"atb":[[3.7,85.09]],"id":70003369}],"con":true,"img":false}]}
{"op":"mcm","clk":"11450229021","pt":1717319395578,"mc":[{"id":"1.229554910","rc":[{"atb":[[5.5,0]],"id":69033911}],"con":true,"img":false}]}
{"op":"mcm","clk":"11450229030","pt":1717319395682,"mc":[{"id":"1.229554910","rc":[{"atb":[[5.7,7.66]],"id":69033911}],"con":true,"img":false}]}
{"op":"mcm","clk":"11450229058","pt":1717319395993,"mc":[{"id":"1.229554910","rc":[{"atb":[[5.5,0]],"id":54867443}],"con":true,"img":false}]}
{"op":"mcm","clk":"11450229070","pt":1717319396096,"mc":[{"id":"1.229554910","rc":[{"atb":[[5.7,7.66]],"id":54867443}],"con":true,"img":false}]}
{"op":"mcm","clk":"11450229751","pt":1717319403599,"mc":[{"id":"1.229554910","rc":[{"atb":[[1.77,2.6]],"id":69676139},{"spn":2.2,"spf":"NaN","id":69676139}],"con":true,"img":false}]}
{"op":"mcm","clk":"11450229763","pt":1717319403744,"mc":[{"id":"1.229554910","rc":[{"atb":[[1.79,2.11]],"id":69676139},{"atl":[[2.64,0]],"id":69676139}],"con":true,"img":false}]}
{"op":"mcm","clk":"11450229791","pt":1717319403902,"mc":[{"id":"1.229554910","rc":[{"atb":[[4,2.13]],"id":55943164},{"atl":[[1000,2.03]],"id":54867443}],"con":true,"img":false}]}
{"op":"mcm","clk":"11450229815","pt":1717319404107,"mc":[{"id":"1.229554910","rc":[{"atb":[[1.77,0]],"id":69676139}],"con":true,"img":false}]}
{"op":"mcm","clk":"11450229826","pt":1717319404222,"mc":[{"id":"1.229554910","rc":[{"atb":[[1.76,2.6]],"id":69676139},{"atl":[[2.64,2.61]],"id":69676139},{"atl":[[1000,1.54]],"id":54867443}],"con":true,"img":false}]}
{"op":"mcm","clk":"11450229835","pt":1717319404317,"mc":[{"id":"1.229554910","rc":[{"atb":[[1.8,3.26]],"id":69676139}],"con":true,"img":false}]}
{"op":"mcm","clk":"11450229861","pt":1717319404526,"mc":[{"id":"1.229554910","rc":[{"atl":[[1000,1.17]],"id":54867443}],"con":true,"img":false}]}
{"op":"mcm","clk":"11450229874","pt":1717319404625,"mc":[{"id":"1.229554910","rc":[{"atl":[[23,0.36]],"id":54867443}],"con":true,"img":false}]}
{"op":"mcm","clk":"11450229882","pt":1717319404727,"mc":[{"id":"1.229554910","rc":[{"atb":[[3.95,23.04]],"id":55943164}],"con":true,"img":false}]}
{"op":"mcm","clk":"11450230136","pt":1717319407726,"mc":[{"id":"1.229554910","rc":[{"atb":[[4,6.58]],"id":55943164}],"con":true,"img":false}]}
{"op":"mcm","clk":"11450230191","pt":1717319408314,"mc":[{"id":"1.229554910","rc":[{"atb":[[3.95,20.4]],"id":55943164}],"con":true,"img":false}]}
{"op":"mcm","clk":"11450230202","pt":1717319408408,"mc":[{"id":"1.229554910","rc":[{"atb":[[4.1,2.64]],"id":55943164}],"con":true,"img":false}]}
{"op":"mcm","clk":"11450230387","pt":1717319410426,"mc":[{"id":"1.229554910","rc":[{"atb":[[4,4.45]],"id":55943164}],"con":true,"img":false}]}
{"op":"mcm","clk":"11450230415","pt":1717319410741,"mc":[{"id":"1.229554910","rc":[{"atb":[[4.2,2.02]],"id":55943164}],"con":true,"img":false}]}
{"op":"mcm","clk":"11450230434","pt":1717319410904,"mc":[{"id":"1.229554910","rc":[{"atb":[[4,0]],"id":55943164}],"con":true,"img":false}]}
{"op":"mcm","clk":"11450230457","pt":1717319411118,"mc":[{"id":"1.229554910","rc":[{"atb":[[4.1,0]],"id":55943164}],"con":true,"img":false}]}
{"op":"mcm","clk":"11450230468","pt":1717319411219,"mc":[{"id":"1.229554910","rc":[{"atb":[[4,2.64]],"id":55943164}],"con":true,"img":false}]}
{"op":"mcm","clk":"11450230552","pt":1717319412055,"mc":[{"id":"1.229554910","rc":[{"atl":[[12,1.11]],"id":55943164}],"con":true,"img":false}]}
{"op":"mcm","clk":"11450230571","pt":1717319412212,"mc":[{"id":"1.229554910","rc":[{"atl":[[11.5,0.74]],"id":55943164}],"con":true,"img":false}]}
{"op":"mcm","clk":"11450230580","pt":1717319412317,"mc":[{"id":"1.229554910","rc":[{"atl":[[1000,1.51]],"id":55943164}],"con":true,"img":false}]}
{"op":"mcm","clk":"11450230806","pt":1717319415125,"mc":[{"id":"1.229554910","rc":[{"atb":[[4,4.66]],"id":55943164}],"con":true,"img":false}]}
{"op":"mcm","clk":"11450230821","pt":1717319415318,"mc":[{"id":"1.229554910","rc":[{"atb":[[4.2,0]],"id":55943164}],"con":true,"img":false}]}
{"op":"mcm","clk":"11450230925","pt":1717319416732,"mc":[{"id":"1.229554910","rc":[{"atb":[[4,9.09]],"id":55943164}],"con":true,"img":false}]}
{"op":"mcm","clk":"11450231173","pt":1717319419638,"mc":[{"id":"1.229554910","rc":[{"atb":[[1.8,0]],"id":69676139}],"con":true,"img":false}]}
{"op":"mcm","clk":"11450231191","pt":1717319419848,"mc":[{"id":"1.229554910","rc":[{"atl":[[2.64,0]],"id":69676139}],"con":true,"img":false}]}
{"op":"mcm","clk":"11450232086","pt":1717319428856,"mc":[{"id":"1.229554910","rc":[{"atl":[[2.64,2.61]],"id":69676139}],"con":true,"img":false}]}
{"op":"mcm","clk":"11450232104","pt":1717319429060,"mc":[{"id":"1.229554910","rc":[{"atb":[[1.8,3.26]],"id":69676139}],"con":true,"img":false}]}
{"op":"mcm","clk":"11450232230","pt":1717319430357,"mc":[{"id":"1.229554910","rc":[{"atl":[[12,0]],"id":55943164}],"con":true,"img":false}]}
{"op":"mcm","clk":"11450233112","pt":1717319439153,"mc":[{"id":"1.229554910","rc":[{"atl":[[11.5,0]],"id":55943164}],"con":true,"img":false}]}
{"op":"mcm","clk":"11450233159","pt":1717319439663,"mc":[{"id":"1.229554910","rc":[{"atl":[[1000,2.37]],"id":55943164}],"con":true,"img":false}]}
{"op":"mcm","clk":"11450233177","pt":1717319439865,"mc":[{"id":"1.229554910","rc":[{"atl":[[1000,1.17]],"id":70003369}],"con":true,"img":false}]}
{"op":"mcm","clk":"11450233188","pt":1717319439970,"mc":[{"id":"1.229554910","rc":[{"atl":[[13,1.16]],"id":70003369}],"con":true,"img":false}]}
{"op":"mcm","clk":"11450233237","pt":1717319440447,"mc":[{"id":"1.229554910","rc":[{"atl":[[13,0.65]],"id":70003369},{"atl":[[1000,2.25]],"id":55943164}],"con":true,"img":false}]}
{"op":"mcm","clk":"11450233245","pt":1717319440548,"mc":[{"id":"1.229554910","rc":[{"atl":[[1000,1.68]],"id":70003369}],"con":true,"img":false}]}
{"op":"mcm","clk":"11450233270","pt":1717319440753,"mc":[{"id":"1.229554910","rc":[{"atl":[[1000,1.51]],"id":55943164}],"con":true,"img":false}]}
{"op":"mcm","clk":"11450233278","pt":1717319440862,"mc":[{"id":"1.229554910","rc":[{"atl":[[12.5,0.74]],"id":55943164}],"con":true,"img":false}]}
{"op":"mcm","clk":"11450233614","pt":1717319444078,"mc":[{"id":"1.229554910","rc":[{"atl":[[2.64,0]],"id":69676139}],"con":true,"img":false}]}
{"op":"mcm","clk":"11450233639","pt":1717319444444,"mc":[{"id":"1.229554910","rc":[{"atb":[[1.8,0]],"id":69676139}],"con":true,"img":false}]}
{"op":"mcm","clk":"11450233706","pt":1717319445065,"mc":[{"id":"1.229554910","rc":[{"atl":[[13.5,1.43]],"id":70003369}],"con":true,"img":false}]}
{"op":"mcm","clk":"11450234556","pt":1717319453955,"mc":[{"id":"1.229554910","rc":[{"atl":[[2.64,2.61]],"id":69676139}],"con":true,"img":false}]}
{"op":"mcm","clk":"11450234567","pt":1717319454105,"mc":[{"id":"1.229554910","rc":[{"atb":[[1.8,3.26]],"id":69676139}],"con":true,"img":false}]}
{"op":"mcm","clk":"11450234601","pt":1717319454377,"mc":[{"id":"1.229554910","rc":[{"atb":[[5.7,0]],"id":54867443}],"con":true,"img":false}]}
{"op":"mcm","clk":"11450234610","pt":1717319454483,"mc":[{"id":"1.229554910","rc":[{"atb":[[5.8,29.44]],"id":54867443}],"con":true,"img":false}]}
{"op":"mcm","clk":"11450234677","pt":1717319455195,"mc":[{"id":"1.229554910","rc":[{"atb":[[1.48,0]],"id":69676139}],"con":true,"img":false}]}
{"op":"mcm","clk":"11450234686","pt":1717319455299,"mc":[{"id":"1.229554910","rc":[{"atb":[[1.51,7.66]],"id":69676139}],"con":true,"img":false}]}
{"op":"mcm","clk":"11450234719","pt":1717319455565,"mc":[{"id":"1.229554910","rc":[{"atb":[[3.55,0]],"id":55943164}],"con":true,"img":false}]}
{"op":"mcm","clk":"11450234729","pt":1717319455668,"mc":[{"id":"1.229554910","rc":[{"atb":[[3.6,7.66]],"id":55943164}],"con":true,"img":false}]}
{"op":"mcm","clk":"11450234759","pt":1717319455985,"mc":[{"id":"1.229554910","rc":[{"atb":[[3.7,77.43]],"id":70003369}],"con":true,"img":false}]}
{"op":"mcm","clk":"11450234767","pt":1717319456085,"mc":[{"id":"1.229554910","rc":[{"atb":[[3.75,7.66]],"id":70003369}],"con":true,"img":false}]}
{"op":"mcm","clk":"11450234796","pt":1717319456393,"mc":[{"id":"1.229554910","rc":[{"atb":[[5.7,0]],"id":69033911}],"con":true,"img":false}]}
{"op":"mcm","clk":"11450234810","pt":1717319456497,"mc":[{"id":"1.229554910","rc":[{"atb":[[5.8,29.44]],"id":69033911}],"con":true,"img":false}]}
{"op":"mcm","clk":"11450235028","pt":1717319458687,"mc":[{"id":"1.229554910","rc":[{"atl":[[6.2,19.23],[8.2,0]],"id":69676139}],"con":true,"img":false}]}
{"op":"mcm","clk":"11450235170","pt":1717319460287,"mc":[{"id":"1.229554910","rc":[{"atl":[[1000,4.04]],"id":70003369},{"atl":[[1000,3.87]],"id":55943164}],"con":true,"img":false}]}
{"op":"mcm","clk":"11450235186","pt":1717319460505,"mc":[{"id":"1.229554910","rc":[{"atl":[[1000,2.67]],"id":70003369},{"atl":[[1000,2.63]],"id":55943164}],"con":true,"img":false}]}
{"op":"mcm","clk":"11450235202","pt":1717319460712,"mc":[{"id":"1.229554910","rc":[{"atl":[[1000,1.51]],"id":55943164}],"con":true,"img":false}]}
{"op":"mcm","clk":"11450235213","pt":1717319460772,"mc":[{"id":"1.229554910","rc":[{"atl":[[12,1.11]],"id":55943164}],"con":true,"img":false}]}
{"op":"mcm","clk":"11450235231","pt":1717319460975,"mc":[{"id":"1.229554910","rc":[{"atl":[[1000,1.68]],"id":70003369}],"con":true,"img":false}]}
{"op":"mcm","clk":"11450235239","pt":1717319461077,"mc":[{"id":"1.229554910","rc":[{"atl":[[13.5,2.42]],"id":70003369}],"con":true,"img":false}]}
{"op":"mcm","clk":"11450235939","pt":1717319469200,"mc":[{"id":"1.229554910","rc":[{"atl":[[2.64,0]],"id":69676139},{"spn":2.23,"spf":"NaN","id":69676139},{"spn":8.0,"spf":"NaN","id":55943164},{"spn":14.45,"spf":"NaN","id":54867443}],"con":true,"img":false}]}
{"op":"mcm","clk":"11450235958","pt":1717319469405,"mc":[{"id":"1.229554910","rc":[{"atb":[[1.8,0]],"id":69676139}],"con":true,"img":false}]}
{"op":"mcm","clk":"11450236767","pt":1717319478102,"mc":[{"id":"1.229554910","rc":[{"atl":[[2.64,2.61]],"id":69676139}],"con":true,"img":false}]}
{"op":"mcm","clk":"11450236784","pt":1717319478297,"mc":[{"id":"1.229554910","rc":[{"atb":[[1.8,3.26]],"id":69676139}],"con":true,"img":false}]}
{"op":"mcm","clk":"11450236982","pt":1717319480829,"mc":[{"id":"1.229554910","rc":[{"atl":[[13.5,0.98]],"id":70003369}],"con":true,"img":false}]}
{"op":"mcm","clk":"11450238125","pt":1717319493416,"mc":[{"id":"1.229554910","rc":[{"atl":[[2.64,0]],"id":69676139}],"con":true,"img":false}]}
{"op":"mcm","clk":"11450238174","pt":1717319493834,"mc":[{"id":"1.229554910","rc":[{"atb":[[1.8,0]],"id":69676139}],"con":true,"img":false}]}
{"op":"mcm","clk":"11450239071","pt":1717319504537,"mc":[{"id":"1.229554910","rc":[{"atl":[[2.64,2.61]],"id":69676139}],"con":true,"img":false}]}
{"op":"mcm","clk":"11450239095","pt":1717319504740,"mc":[{"id":"1.229554910","rc":[{"atb":[[1.8,3.26]],"id":69676139}],"con":true,"img":false}]}
{"op":"mcm","clk":"11450239308","pt":1717319507060,"mc":[{"id":"1.229554910","rc":[{"atl":[[12,2.72]],"id":55943164}],"con":true,"img":false}]}
{"op":"mcm","clk":"11450239369","pt":1717319507630,"mc":[{"id":"1.229554910","rc":[{"atl":[[13.5,2.42]],"id":70003369}],"con":true,"img":false}]}
{"op":"mcm","clk":"11450239381","pt":1717319507730,"mc":[{"id":"1.229554910","rc":[{"atl":[[1000,1]],"id":55943164}],"con":true,"img":false}]}
{"op":"mcm","clk":"11450239389","pt":1717319507834,"mc":[{"id":"1.229554910","rc":[{"atl":[[11.5,0.51]],"id":55943164}],"con":true,"img":false}]}
{"op":"mcm","clk":"11450240496","pt":1717319519858,"mc":[{"id":"1.229554910","rc":[{"atl":[[2.64,0]],"id":69676139}],"con":true,"img":false}]}
{"op":"mcm","clk":"11450240504","pt":1717319519958,"mc":[{"id":"1.229554910","rc":[{"atl":[[1000,1.17]],"id":70003369}],"con":true,"img":false}]}
{"op":"mcm","clk":"11450240519","pt":1717319520057,"mc":[{"id":"1.229554910","rc":[{"atl":[[13,1.16]],"id":70003369},{"atb":[[1.8,0]],"id":69676139}],"con":true,"img":false}]}
{"op":"mcm","clk":"11450240575","pt":1717319520683,"mc":[{"id":"1.229554910","rc":[{"atl":[[13,0.65]],"id":70003369}],"con":true,"img":false}]}
{"op":"mcm","clk":"11450240587","pt":1717319520782,"mc":[{"id":"1.229554910","rc":[{"atl":[[1000,1.68]],"id":70003369}],"con":true,"img":false}]}
{"op":"mcm","clk":"11450240637","pt":1717319521260,"mc":[{"id":"1.229554910","rc":[{"atl":[[1000,1.17]],"id":70003369}],"con":true,"img":false}]}
{"op":"mcm","clk":"11450240647","pt":1717319521361,"mc":[{"id":"1.229554910","rc":[{"atl":[[13,1.16]],"id":70003369}],"con":true,"img":false}]}
{"op":"mcm","clk":"11450240693","pt":1717319521876,"mc":[{"id":"1.229554910","rc":[{"atl":[[13,0.65]],"id":70003369}],"con":true,"img":false}]}
{"op":"mcm","clk":"11450240701","pt":1717319521982,"mc":[{"id":"1.229554910","rc":[{"atl":[[1000,1.68]],"id":70003369}],"con":true,"img":false}]}
{"op":"mcm","clk":"11450241658","pt":1717319531523,"mc":[{"id":"1.229554910","rc":[{"atl":[[2.64,2.61]],"id":69676139},{"spn":2.21,"spf":"NaN","id":69676139},{"spn":7.75,"spf":"NaN","id":55943164}],"con":true,"img":false}]}
{"op":"mcm","clk":"11450241665","pt":1717319531627,"mc":[{"id":"1.229554910","rc":[{"atb":[[1.8,3.26]],"id":69676139}],"con":true,"img":false}]}
{"op":"mcm","clk":"11450243124","pt":1717319546973,"mc":[{"id":"1.229554910","rc":[{"atb":[[1.8,0]],"id":69676139}],"con":true,"img":false}]}
{"op":"mcm","clk":"11450243145","pt":1717319547129,"mc":[{"id":"1.229554910","rc":[{"atl":[[2.64,0]],"id":69676139}],"con":true,"img":false}]}
{"op":"mcm","clk":"11450243524","pt":1717319550738,"mc":[{"id":"1.229554910","rc":[{"atl":[[2.64,2.61]],"id":69676139}],"con":true,"img":false}]}
{"op":"mcm","clk":"11450243534","pt":1717319550846,"mc":[{"id":"1.229554910","rc":[{"atb":[[1.8,3.26]],"id":69676139}],"con":true,"img":false}]}
{"op":"mcm","clk":"11450244596","pt":1717319562888,"mc":[{"id":"1.229554910","rc":[{"atb":[[2.48,0.78]],"id":69676139}],"con":true,"img":false}]}
{"op":"mcm","clk":"11450244654","pt":1717319563407,"mc":[{"id":"1.229554910","rc":[{"atb":[[2.48,0]],"id":69676139},{"trd":[[2.48,1.56]],"ltp":2.48,"tv":1.56,"id":69676139},{"atl":[[2.28,3.3]],"id":69676139}],"con":true,"img":false}]}
{"op":"mcm","clk":"11450244674","pt":1717319563565,"mc":[{"id":"1.229554910","rc":[{"trd":[[2.28,0.52]],"ltp":2.28,"tv":0.52,"id":69676139},{"atl":[[2.28,3.03]],"id":69676139}],"con":true,"img":false}]}
{"op":"mcm","clk":"11450244686","pt":1717319563719,"mc":[{"id":"1.229554910","rc":[{"atb":[[1.76,0]],"id":69676139}],"con":true,"img":false}]}
{"op":"mcm","clk":"11450244763","pt":1717319564596,"mc":[{"id":"1.229554910","rc":[{"atl":[[2.28,0]],"id":69676139}],"con":true,"img":false}]}
{"op":"mcm","clk":"11450244910","pt":1717319566160,"mc":[{"id":"1.229554910","rc":[{"atb":[[1.8,0]],"id":69676139}],"con":true,"img":false}]}
{"op":"mcm","clk":"11450244928","pt":1717319566413,"mc":[{"id":"1.229554910","rc":[{"atl":[[2.64,0]],"id":69676139}],"con":true,"img":false}]}
{"op":"mcm","clk":"11450244959","pt":1717319566682,"mc":[{"id":"1.229554910","rc":[{"atb":[[1.76,2.6]],"id":69676139}],"con":true,"img":false}]}
{"op":"mcm","clk":"11450245393","pt":1717319571282,"mc":[{"id":"1.229554910","rc":[{"atl":[[2.64,2.61]],"id":69676139}],"con":true,"img":false}]}
{"op":"mcm","clk":"11450245413","pt":1717319571485,"mc":[{"id":"1.229554910","rc":[{"atb":[[1.8,3.26]],"id":69676139}],"con":true,"img":false}]}
{"op":"mcm","clk":"11450245927","pt":1717319576906,"mc":[{"id":"1.229554910","rc":[{"atb":[[1.8,2.19]],"id":69676139},{"trd":[[1.8,2.15]],"ltp":1.8,"tv":2.15,"id":69676139}],"con":true,"img":false}]}
{"op":"mcm","clk":"11450246413","pt":1717319582512,"mc":[{"id":"1.229554910","rc":[{"atb":[[3.45,0],[3.95,0],[3.7,0]],"id":70003369},{"atl":[[19.5,0],[29,0]],"id":70003369},{"atb":[[4.8,0],[5.8,7.66],[5.3,0]],"id":69033911},{"atl":[[48,0],[29,0]],"id":69033911},{"atb":[[1.73,0],[1.63,0],[1.68,0]],"id":69676139},{"atl":[[4,0],[5,0]],"id":69676139},{"atb":[[70,2.61],[38,0],[48,0]],"id":52272946},{"atl":[[630,0],[730,0]],"id":52272946},{"atb":[[3.4,0],[3.9,0],[3.65,0]],"id":55943164},{"atl":[[19,5.56],[28,0]],"id":55943164},{"atb":[[4.8,0],[5.8,7.66],[5.3,0]],"id":54867443},{"atl":[[48,0],[29,0]],"id":54867443}],"con":true,"img":false}]}
{"op":"mcm","clk":"11450246652","pt":1717319584822,"mc":[{"id":"1.229554910","rc":[{"atb":[[4,0]],"id":70003369},{"atl":[[28,0]],"id":69033911},{"atb":[[1.74,0],[1.75,15.11]],"id":69676139},{"atb":[[3.95,0]],"id":55943164},{"atb":[[5.4,0]],"id":54867443},{"atl":[[28,0]],"id":54867443}],"con":true,"img":false}]}
{"op":"mcm","clk":"11450246662","pt":1717319584930,"mc":[{"id":"1.229554910","rc":[{"atb":[[3.8,40.11]],"id":70003369},{"atl":[[30,4.34]],"id":69033911},{"atb":[[1.58,178.2],[1.67,61.85]],"id":69676139},{"atb":[[3.65,20.4]],"id":55943164},{"atb":[[4.9,26.42]],"id":54867443},{"atl":[[30,3.32]],"id":54867443}],"con":true,"img":false}]}
{"op":"mcm","clk":"11450246688","pt":1717319585141,"mc":[{"id":"1.229554910","rc":[{"atl":[[23,0]],"id":54867443}],"con":true,"img":false}]}
{"op":"mcm","clk":"11450246727","pt":1717319585504,"mc":[{"id":"1.229554910","rc":[{"atb":[[4.3,0]],"id":70003369},{"atb":[[1.76,0]],"id":69676139},{"atb":[[4,6.45]],"id":55943164}],"con":true,"img":false}]}
{"op":"mcm","clk":"11450246745","pt":1717319585715,"mc":[{"id":"1.229554910","rc":[{"atb":[[4,2.02]],"id":55943164}],"con":true,"img":false}]}
{"op":"mcm","clk":"11450246772","pt":1717319586019,"mc":[{"id":"1.229554910","rc":[{"atb":[[4,0],[3.7,2.64]],"id":55943164}],"con":true,"img":false}]}
{"op":"mcm","clk":"11450246816","pt":1717319586492,"mc":[{"id":"1.229554910","rc":[{"atl":[[2.64,0]],"id":69676139}],"con":true,"img":false}]}
{"op":"mcm","clk":"11450246839","pt":1717319586795,"mc":[{"id":"1.229554910","rc":[{"atb":[[1.8,0]],"id":69676139}],"con":true,"img":false}]}
{"op":"mcm","clk":"11450247591","pt":1717319595533,"mc":[{"id":"1.229554910","rc":[{"atb":[[3.45,85.33],[3.95,35.43],[3.7,77.43]],"id":70003369},{"atl":[[19.5,7.53],[29,7.46]],"id":70003369},{"spn":8.6,"spf":"NaN","id":70003369},{"atb":[[4.8,55.01],[5.8,29.44],[5.3,48.61]],"id":69033911},{"atl":[[48,4.44],[29,4.97]],"id":69033911},{"atb":[[1.73,143.19],[1.63,331.84],[1.68,307.44]],"id":69676139},{"atl":[[4,46.45],[5,52.26]],"id":69676139},{"spn":2.22,"spf":"NaN","id":69676139},{"atb":[[70,4.13],[38,5.65],[48,4.44]],"id":52272946},{"atl":[[630,0.21],[730,0.28]],"id":52272946},{"atb":[[3.4,87.1],[3.9,36.04],[3.65,99.29]],"id":55943164},{"atl":[[19,13.3],[28,7.74]],"id":55943164},{"spn":7.7,"spf":"NaN","id":55943164},{"atb":[[4.8,55.01],[5.8,29.44],[5.3,48.61]],"id":54867443},{"atl":[[48,4.44],[29,4.97]],"id":54867443},{"spn":14.95,"spf":"NaN","id":54867443}],"con":true,"img":false}]}
{"op":"mcm","clk":"11450247617","pt":1717319595742,"mc":[{"id":"1.229554910","rc":[{"atb":[[4.3,2.53]],"id":70003369},{"atb":[[3.7,0]],"id":55943164}],"con":true,"img":false}]}
{"op":"mcm","clk":"11450247627","pt":1717319595842,"mc":[{"id":"1.229554910","rc":[{"atb":[[3.95,2.64]],"id":55943164}],"con":true,"img":false}]}
{"op":"mcm","clk":"11450247814","pt":1717319597840,"mc":[{"id":"1.229554910","rc":[{"atb":[[3.95,7.03]],"id":55943164}],"con":true,"img":false}]}
{"op":"mcm","clk":"11450248582","pt":1717319607361,"mc":[{"id":"1.229554910","rc":[{"atl":[[2.64,1.07]],"id":69676139}],"con":true,"img":false}]}
{"op":"mcm","clk":"11450248692","pt":1717319608544,"mc":[{"id":"1.229554910","rc":[{"atb":[[1.75,0]],"id":69676139}],"con":true,"img":false}]}
{"op":"mcm","clk":"11450248719","pt":1717319608807,"mc":[{"id":"1.229554910","rc":[{"atb":[[1.74,2.6]],"id":69676139}],"con":true,"img":false}]}
{"op":"mcm","clk":"11450249960","pt":1717319622679,"mc":[{"id":"1.229554910","rc":[{"atl":[[2.64,0]],"id":69676139}],"con":true,"img":false}]}
{"op":"mcm","clk":"11450250090","pt":1717319624051,"mc":[{"id":"1.229554910","rc":[{"atl":[[2.64,1.07]],"id":69676139}],"con":true,"img":false}]}
{"op":"mcm","clk":"11450250148","pt":1717319624630,"mc":[{"id":"1.229554910","rc":[{"atb":[[1.67,0]],"id":69676139}],"con":true,"img":false}]}
{"op":"mcm","clk":"11450250156","pt":1717319624735,"mc":[{"id":"1.229554910","rc":[{"atb":[[1.74,64.46]],"id":69676139}],"con":true,"img":false}]}
{"op":"mcm","clk":"11450250710","pt":1717319630863,"mc":[{"id":"1.229554910","rc":[{"atb":[[1.74,79.78]],"id":69676139}],"con":true,"img":false}]}
{"op":"mcm","clk":"11450251037","pt":1717319634654,"mc":[{"id":"1.229554910","rc":[{"atl":[[30,0]],"id":69033911},{"atb":[[3.65,78.88]],"id":55943164},{"atl":[[30,0]],"id":54867443}],"con":true,"img":false}]}
{"op":"mcm","clk":"11450251046","pt":1717319634761,"mc":[{"id":"1.229554910","rc":[{"atl":[[28,4.34]],"id":69033911},{"atb":[[3.95,27.43]],"id":55943164},{"atl":[[28,3.32]],"id":54867443}],"con":true,"img":false}]}
{"op":"mcm","clk":"11450251415","pt":1717319639464,"mc":[{"id":"1.229554910","rc":[{"atl":[[2.64,0]],"id":69676139}],"con":true,"img":false}]}
{"op":"mcm","clk":"11450251434","pt":1717319639671,"mc":[{"id":"1.229554910","rc":[{"atb":[[3.8,0]],"id":70003369},{"atb":[[1.58,0]],"id":69676139},{"atb":[[4.9,0]],"id":54867443}],"con":true,"img":false}]}
{"op":"mcm","clk":"11450251444","pt":1717319639776,"mc":[{"id":"1.229554910","rc":[{"atb":[[4,40.11]],"id":70003369},{"atb":[[1.64,178.2]],"id":69676139},{"atb":[[5.4,26.42]],"id":54867443}],"con":true,"img":false}]}
{"op":"mcm","clk":"11450251500","pt":1717319640560,"mc":[{"id":"1.229554910","rc":[{"atl":[[12,1.61]],"id":55943164}],"con":true,"img":false}]}
{"op":"mcm","clk":"11450251623","pt":1717319642062,"mc":[{"id":"1.229554910","rc":[{"atl":[[2.64,1.07]],"id":69676139}],"con":true,"img":false}]}
{"op":"mcm","clk":"11450252822","pt":1717319655690,"mc":[{"id":"1.229554910","rc":[{"atl":[[13.5,1.43]],"id":70003369},{"spn":8.65,"spf":"NaN","id":70003369},{"spn":2.21,"spf":"NaN","id":69676139},{"spn":7.72,"spf":"NaN","id":55943164}],"con":true,"img":false}]}
{"op":"mcm","clk":"11450252986","pt":1717319657613,"mc":[{"id":"1.229554910","rc":[{"atl":[[2.64,0]],"id":69676139}],"con":true,"img":false}]}
{"op":"mcm","clk":"11450253044","pt":1717319658190,"mc":[{"id":"1.229554910","rc":[{"atl":[[2.64,1.07]],"id":69676139}],"con":true,"img":false}]}
{"op":"mcm","clk":"11450254449","pt":1717319673510,"mc":[{"id":"1.229554910","rc":[{"atl":[[2.64,0]],"id":69676139}],"con":true,"img":false}]}
{"op":"mcm","clk":"11450254552","pt":1717319674495,"mc":[{"id":"1.229554910","rc":[{"atl":[[2.64,1.07]],"id":69676139}],"con":true,"img":false}]}
{"op":"mcm","clk":"11450255897","pt":1717319689929,"mc":[{"id":"1.229554910","rc":[{"atl":[[2.64,0]],"id":69676139}],"con":true,"img":false}]}
{"op":"mcm","clk":"11450255946","pt":1717319690437,"mc":[{"id":"1.229554910","rc":[{"atl":[[2.64,1.07]],"id":69676139}],"con":true,"img":false}]}
{"op":"mcm","clk":"11450256996","pt":1717319702257,"mc":[{"id":"1.229554910","rc":[{"atl":[[1000,4.04]],"id":70003369},{"atl":[[1000,3.35]],"id":55943164}],"con":true,"img":false}]}
{"op":"mcm","clk":"11450257058","pt":1717319702881,"mc":[{"id":"1.229554910","rc":[{"atl":[[1000,2.11]],"id":55943164}],"con":true,"img":false}]}
{"op":"mcm","clk":"11450257085","pt":1717319703077,"mc":[{"id":"1.229554910","rc":[{"atl":[[1000,2.67]],"id":70003369},{"atl":[[1000,1]],"id":55943164}],"con":true,"img":false}]}
{"op":"mcm","clk":"11450257096","pt":1717319703133,"mc":[{"id":"1.229554910","rc":[{"atl":[[12,2.72]],"id":55943164}],"con":true,"img":false}]}
{"op":"mcm","clk":"11450257117","pt":1717319703349,"mc":[{"id":"1.229554910","rc":[{"atl":[[1000,1.68]],"id":70003369}],"con":true,"img":false}]}
{"op":"mcm","clk":"11450257130","pt":1717319703445,"mc":[{"id":"1.229554910","rc":[{"atl":[[13.5,2.42]],"id":70003369}],"con":true,"img":false}]}
{"op":"mcm","clk":"11450257342","pt":1717319705668,"mc":[{"id":"1.229554910","rc":[{"atl":[[2.64,0]],"id":69676139}],"con":true,"img":false}]}
{"op":"mcm","clk":"11450257379","pt":1717319706037,"mc":[{"id":"1.229554910","rc":[{"atl":[[2.62,1.07]],"id":69676139}],"con":true,"img":false}]}
{"op":"mcm","clk":"11450258866","pt":1717319721284,"mc":[{"id":"1.229554910","rc":[{"spn":2.2,"spf":"NaN","id":69676139},{"atl":[[12,1.11]],"id":55943164}],"con":true,"img":false}]}
{"op":"mcm","clk":"11450258899","pt":1717319721585,"mc":[{"id":"1.229554910","rc":[{"atl":[[2.62,0]],"id":69676139}],"con":true,"img":false}]}
{"op":"mcm","clk":"11450258932","pt":1717319722003,"mc":[{"id":"1.229554910","rc":[{"atl":[[11.5,0]],"id":55943164}],"con":true,"img":false}]}
{"op":"mcm","clk":"11450258941","pt":1717319722105,"mc":[{"id":"1.229554910","rc":[{"atl":[[1000,1.51]],"id":55943164}],"con":true,"img":false}]}
{"op":"mcm","clk":"11450260331","pt":1717319736920,"mc":[{"id":"1.229554910","rc":[{"atl":[[2.64,1.07]],"id":69676139}],"con":true,"img":false}]}
{"op":"mcm","clk":"11450261653","pt":1717319752496,"mc":[{"id":"1.229554910","rc":[{"atl":[[2.64,0]],"id":69676139}],"con":true,"img":false}]}
{"op":"mcm","clk":"11450261711","pt":1717319753014,"mc":[{"id":"1.229554910","rc":[{"atl":[[2.62,1.07]],"id":69676139}],"con":true,"img":false}]}
{"op":"mcm","clk":"11450261729","pt":1717319753226,"mc":[{"id":"1.229554910","rc":[{"atl":[[1000,1.17]],"id":70003369}],"con":true,"img":false}]}
{"op":"mcm","clk":"11450261743","pt":1717319753328,"mc":[{"id":"1.229554910","rc":[{"atl":[[13,1.16]],"id":70003369}],"con":true,"img":false}]}
{"op":"mcm","clk":"11450261794","pt":1717319753801,"mc":[{"id":"1.229554910","rc":[{"atl":[[13,0.65]],"id":70003369}],"con":true,"img":false}]}
{"op":"mcm","clk":"11450261804","pt":1717319753905,"mc":[{"id":"1.229554910","rc":[{"atl":[[1000,1.68]],"id":70003369}],"con":true,"img":false}]}
{"op":"mcm","clk":"11450263017","pt":1717319768651,"mc":[{"id":"1.229554910","rc":[{"atl":[[2.62,0]],"id":69676139}],"con":true,"img":false}]}
{"op":"mcm","clk":"11450263040","pt":1717319768933,"mc":[{"id":"1.229554910","rc":[{"atl":[[2.6,1.07]],"id":69676139}],"con":true,"img":false}]}
{"op":"mcm","clk":"11450264163","pt":1717319782064,"mc":[{"id":"1.229554910","rc":[{"atl":[[13.5,0.98]],"id":70003369},{"spn":2.19,"spf":"NaN","id":69676139},{"spn":7.97,"spf":"NaN","id":55943164}],"con":true,"img":false}]}
{"op":"mcm","clk":"11450264351","pt":1717319784385,"mc":[{"id":"1.229554910","rc":[{"atl":[[2.6,0]],"id":69676139}],"con":true,"img":false}]}
{"op":"mcm","clk":"11450265545","pt":1717319797758,"mc":[{"id":"1.229554910","rc":[{"atl":[[2.64,1.07]],"id":69676139}],"con":true,"img":false}]}
{"op":"mcm","clk":"11450266909","pt":1717319813087,"mc":[{"id":"1.229554910","rc":[{"atl":[[2.64,0]],"id":69676139}],"con":true,"img":false}]}
{"op":"mcm","clk":"11450266949","pt":1717319813600,"mc":[{"id":"1.229554910","rc":[{"atl":[[2.62,1.07]],"id":69676139}],"con":true,"img":false}]}
{"op":"mcm","clk":"11450266967","pt":1717319813811,"mc":[{"id":"1.229554910","rc":[{"atl":[[12,2.72]],"id":55943164}],"con":true,"img":false}]}
{"op":"mcm","clk":"11450266982","pt":1717319814014,"mc":[{"id":"1.229554910","rc":[{"atl":[[13.5,2.42]],"id":70003369},{"atl":[[1000,1]],"id":55943164}],"con":true,"img":false}]}
{"op":"mcm","clk":"11450266990","pt":1717319814117,"mc":[{"id":"1.229554910","rc":[{"atl":[[11.5,0.51]],"id":55943164}],"con":true,"img":false}]}
{"op":"mcm","clk":"11450268243","pt":1717319828845,"mc":[{"id":"1.229554910","rc":[{"atl":[[2.62,0]],"id":69676139}],"con":true,"img":false}]}
{"op":"mcm","clk":"11450268268","pt":1717319829008,"mc":[{"id":"1.229554910","rc":[{"atl":[[1000,1.17]],"id":70003369}],"con":true,"img":false}]}
{"op":"mcm","clk":"11450268278","pt":1717319829105,"mc":[{"id":"1.229554910","rc":[{"atl":[[13,1.16]],"id":70003369}],"con":true,"img":false}]}
{"op":"mcm","clk":"11450268329","pt":1717319829650,"mc":[{"id":"1.229554910","rc":[{"atl":[[13,0.65]],"id":70003369}],"con":true,"img":false}]}
{"op":"mcm","clk":"11450268342","pt":1717319829709,"mc":[{"id":"1.229554910","rc":[{"atl":[[1000,1.68]],"id":70003369}],"con":true,"img":false}]}
{"op":"mcm","clk":"11450268388","pt":1717319830219,"mc":[{"id":"1.229554910","rc":[{"atl":[[1000,1.17]],"id":70003369}],"con":true,"img":false}]}
{"op":"mcm","clk":"11450268395","pt":1717319830322,"mc":[{"id":"1.229554910","rc":[{"atl":[[13,1.16]],"id":70003369}],"con":true,"img":false}]}
{"op":"mcm","clk":"11450268433","pt":1717319830841,"mc":[{"id":"1.229554910","rc":[{"atl":[[13,0.65]],"id":70003369}],"con":true,"img":false}]}
{"op":"mcm","clk":"11450268442","pt":1717319830946,"mc":[{"id":"1.229554910","rc":[{"atl":[[1000,1.68]],"id":70003369}],"con":true,"img":false}]}
{"op":"mcm","clk":"11450269441","pt":1717319842850,"mc":[{"id":"1.229554910","rc":[{"atl":[[2.64,1.07]],"id":69676139},{"spn":2.21,"spf":"NaN","id":69676139},{"spn":7.72,"spf":"NaN","id":55943164}],"con":true,"img":false}]}
{"op":"mcm","clk":"11450270661","pt":1717319858266,"mc":[{"id":"1.229554910","rc":[{"atl":[[2.64,0]],"id":69676139}],"con":true,"img":false}]}
{"op":"mcm","clk":"11450270692","pt":1717319858780,"mc":[{"id":"1.229554910","rc":[{"atl":[[2.62,1.07]],"id":69676139}],"con":true,"img":false}]}
{"op":"mcm","clk":"11450271865","pt":1717319873280,"mc":[{"id":"1.229554910","rc":[{"atb":[[1.98,69.45],[3.5,0]],"id":69033911},{"atl":[[8,14.29],[6.2,0]],"id":69676139},{"atb":[[1.8,0],[2.42,70.42]],"id":54867443}],"con":true,"img":false}]}
{"op":"mcm","clk":"11450271939","pt":1717319874261,"mc":[{"id":"1.229554910","rc":[{"atl":[[2.62,0]],"id":69676139}],"con":true,"img":false}]}
{"op":"mcm","clk":"11450271989","pt":1717319874773,"mc":[{"id":"1.229554910","rc":[{"atl":[[3.6,0]],"id":69676139}],"con":true,"img":false}]}
{"op":"mcm","clk":"11450271993","pt":1717319874876,"mc":[{"id":"1.229554910","rc":[{"atl":[[5.4,6.81]],"id":69676139}],"con":true,"img":false}]}
{"op":"mcm","clk":"11450272016","pt":1717319875187,"mc":[{"id":"1.229554910","rc":[{"atl":[[2.64,1.07]],"id":69676139}],"con":true,"img":false}]}
{"op":"mcm","clk":"11450272545","pt":1717319882113,"mc":[{"id":"1.229554910","rc":[{"atb":[[6.2,4.59]],"id":69033911},{"atl":[[19.5,2.43]],"id":69033911},{"atl":[[990,2]],"id":52272946},{"atl":[[24,5.09]],"id":54867443}],"con":true,"img":false}]}
{"op":"mcm","clk":"11450272582","pt":1717319882485,"mc":[{"id":"1.229554910","rc":[{"atl":[[23,0.78]],"id":54867443}],"con":true,"img":false}]}
{"op":"mcm","clk":"11450272589","pt":1717319882582,"mc":[{"id":"1.229554910","rc":[{"atl":[[1000,1]],"id":69033911}],"con":true,"img":false}]}
{"op":"mcm","clk":"11450272602","pt":1717319882689,"mc":[{"id":"1.229554910","rc":[{"atl":[[19,0.54]],"id":69033911}],"con":true,"img":false}]}
{"op":"mcm","clk":"11450272655","pt":1717319883204,"mc":[{"id":"1.229554910","rc":[{"atl":[[23,0.5]],"id":54867443}],"con":true,"img":false}]}
{"op":"mcm","clk":"11450273212","pt":1717319890511,"mc":[{"id":"1.229554910","rc":[{"atl":[[2.64,0]],"id":69676139},{"atl":[[12,1.61]],"id":55943164}],"con":true,"img":false}]}
{"op":"mcm","clk":"11450274330","pt":1717319904631,"mc":[{"id":"1.229554910","rc":[{"spn":12.6,"spf":"NaN","id":69033911},{"atl":[[2.64,1.07]],"id":69676139},{"spn":14.45,"spf":"NaN","id":54867443}],"con":true,"img":false}]}
{"op":"mcm","clk":"11450274362","pt":1717319905150,"mc":[{"id":"1.229554910","rc":[{"atl":[[13.5,1.43]],"id":70003369}],"con":true,"img":false}]}
{"op":"mcm","clk":"11450275427","pt":1717319919872,"mc":[{"id":"1.229554910","rc":[{"atl":[[2.64,0]],"id":69676139}],"con":true,"img":false}]}
{"op":"mcm","clk":"11450275449","pt":1717319920183,"mc":[{"id":"1.229554910","rc":[{"atl":[[1000,4.04]],"id":70003369},{"atl":[[1000,3.35]],"id":55943164}],"con":true,"img":false}]}
{"op":"mcm","clk":"11450275492","pt":1717319920698,"mc":[{"id":"1.229554910","rc":[{"atl":[[1000,2.67]],"id":70003369},{"atl":[[1000,2.11]],"id":55943164}],"con":true,"img":false}]}
{"op":"mcm","clk":"11450275511","pt":1717319920902,"mc":[{"id":"1.229554910","rc":[{"atl":[[1000,1]],"id":55943164}],"con":true,"img":false}]}
{"op":"mcm","clk":"11450275523","pt":1717319921007,"mc":[{"id":"1.229554910","rc":[{"atl":[[12,2.72]],"id":55943164}],"con":true,"img":false}]}
{"op":"mcm","clk":"11450275538","pt":1717319921163,"mc":[{"id":"1.229554910","rc":[{"atl":[[1000,1.68]],"id":70003369}],"con":true,"img":false}]}
{"op":"mcm","clk":"11450275544","pt":1717319921314,"mc":[{"id":"1.229554910","rc":[{"atl":[[13.5,2.42]],"id":70003369}],"con":true,"img":false}]}
{"op":"mcm","clk":"11450275965","pt":1717319926080,"mc":[{"id":"1.229554910","rc":[{"atl":[[17,0]],"id":55943164}],"con":true,"img":false}]}
{"op":"mcm","clk":"11450275984","pt":1717319926286,"mc":[{"id":"1.229554910","rc":[{"atl":[[18,0]],"id":70003369}],"con":true,"img":false}]}
{"op":"mcm","clk":"11450276019","pt":1717319926597,"mc":[{"id":"1.229554910","rc":[{"atl":[[32,0]],"id":69033911}],"con":true,"img":false}]}
{"op":"mcm","clk":"11450276041","pt":1717319926904,"mc":[{"id":"1.229554910","rc":[{"atl":[[32,0]],"id":54867443}],"con":true,"img":false}]}
{"op":"mcm","clk":"11450276059","pt":1717319927107,"mc":[{"id":"1.229554910","rc":[{"atb":[[5.8,21.77]],"id":54867443}],"con":true,"img":false}]}
{"op":"mcm","clk":"11450276072","pt":1717319927312,"mc":[{"id":"1.229554910","rc":[{"atb":[[1.51,0]],"id":69676139}],"con":true,"img":false}]}
{"op":"mcm","clk":"11450276095","pt":1717319927574,"mc":[{"id":"1.229554910","rc":[{"atb":[[3.6,0]],"id":55943164}],"con":true,"img":false}]}
{"op":"mcm","clk":"11450276110","pt":1717319927781,"mc":[{"id":"1.229554910","rc":[{"atb":[[3.75,0]],"id":70003369}],"con":true,"img":false}]}
{"op":"mcm","clk":"11450276119","pt":1717319927991,"mc":[{"id":"1.229554910","rc":[{"atb":[[5.8,21.77]],"id":69033911}],"con":true,"img":false}]}
{"op":"mcm","clk":"11450276139","pt":1717319928302,"mc":[{"id":"1.229554910","rc":[{"atl":[[5.4,0]],"id":69676139}],"con":true,"img":false}]}
{"op":"mcm","clk":"11450276227","pt":1717319929399,"mc":[{"id":"1.229554910","rc":[{"atb":[[3.45,0],[3.95,0],[3.7,0]],"id":70003369},{"atl":[[19.5,0],[29,0]],"id":70003369},{"atb":[[4.8,0],[5.8,0],[5.3,0]],"id":69033911},{"atl":[[48,0],[29,0]],"id":69033911},{"atb":[[1.73,0],[1.63,0],[1.68,0]],"id":69676139},{"atl":[[4,0],[5,0]],"id":69676139},{"atb":[[70,2.61],[38,0],[48,0]],"id":52272946},{"atl":[[630,0],[730,0]],"id":52272946},{"atb":[[3.4,0],[3.9,0],[3.65,0]],"id":55943164},{"atl":[[19,5.56],[28,0]],"id":55943164},{"atb":[[4.8,0],[5.8,0],[5.3,0]],"id":54867443},{"atl":[[48,0],[29,0]],"id":54867443}],"con":true,"img":false}]}
{"op":"mcm","clk":"11450276243","pt":1717319929600,"mc":[{"id":"1.229554910","rc":[{"atl":[[990,0],[1000,3.17]],"id":52272946}],"con":true,"img":false}]}
{"op":"mcm","clk":"11450276257","pt":1717319929706,"mc":[{"id":"1.229554910","rc":[{"atb":[[4,0]],"id":70003369},{"atl":[[17.5,0]],"id":70003369},{"atb":[[5.9,0]],"id":69033911},{"atl":[[34,6.58],[28,0]],"id":69033911},{"atb":[[1.64,0],[1.74,17.92]],"id":69676139},{"atb":[[3.95,7.03]],"id":55943164},{"atb":[[5.9,2.63],[5.4,0]],"id":54867443},{"atl":[[28,0]],"id":54867443}],"con":true,"img":false}]}
{"op":"mcm","clk":"11450276269","pt":1717319929807,"mc":[{"id":"1.229554910","rc":[{"atb":[[3.7,40.11]],"id":70003369},{"atl":[[20,5.68]],"id":70003369},{"atb":[[5.3,27.25]],"id":69033911},{"atb":[[1.58,178.2],[1.67,61.85]],"id":69676139},{"atb":[[3.65,20.4]],"id":55943164},{"atb":[[5.5,12.2],[4.9,26.42]],"id":54867443},{"atl":[[32,3.32]],"id":54867443}],"con":true,"img":false}]}
{"op":"mcm","clk":"11450276285","pt":1717319930015,"mc":[{"id":"1.229554910","rc":[{"atb":[[4.3,0]],"id":70003369},{"atb":[[6.2,2]],"id":69033911},{"atb":[[1.74,15.32]],"id":69676139},{"atb":[[3.95,4.39]],"id":55943164},{"atb":[[5.9,0]],"id":54867443},{"atl":[[23,0]],"id":54867443}],"con":true,"img":false}]}
{"op":"mcm","clk":"11450276293","pt":1717319930121,"mc":[{"id":"1.229554910","rc":[{"atl":[[1000,1.68]],"id":54867443}],"con":true,"img":false}]}
{"op":"mcm","clk":"11450276442","pt":1717319932372,"mc":[{"id":"1.229554910","rc":[{"atb":[[3.95,0]],"id":55943164}],"con":true,"img":false}]}
{"op":"mcm","clk":"11450276456","pt":1717319932584,"mc":[{"id":"1.229554910","rc":[{"atb":[[3.7,2.64]],"id":55943164}],"con":true,"img":false}]}
{"op":"mcm","clk":"11450276634","pt":1717319935101,"mc":[{"id":"1.229554910","rc":[{"atb":[[1.69,11.37]],"id":69676139}],"con":true,"img":false}]}
{"op":"mcm","clk":"11450276673","pt":1717319935619,"mc":[{"id":"1.229554910","rc":[{"atb":[[1.75,2.6]],"id":69676139}],"con":true,"img":false}]}
{"op":"mcm","clk":"11450276700","pt":1717319935926,"mc":[{"id":"1.229554910","rc":[{"atl":[[2.64,1.07]],"id":69676139}],"con":true,"img":false}]}
{"op":"mcm","clk":"11450276990","pt":1717319939602,"mc":[{"id":"1.229554910","rc":[{"atb":[[3.45,85.33],[3.95,35.43],[3.7,117.54]],"id":70003369},{"atl":[[19.5,7.53],[29,7.46]],"id":70003369},{"atb":[[4.8,55.01],[5.8,21.77],[5.3,75.87]],"id":69033911},{"atl":[[48,4.44],[29,4.97]],"id":69033911},{"atb":[[1.73,143.19],[1.63,331.84],[1.68,307.44]],"id":69676139},{"atl":[[4,46.45],[5,52.26]],"id":69676139},{"atb":[[70,4.13],[38,5.65],[48,4.44]],"id":52272946},{"atl":[[630,0.21],[730,0.28]],"id":52272946},{"atb":[[3.4,87.1],[3.9,36.04],[3.65,99.29]],"id":55943164},{"atl":[[19,13.3],[28,7.74]],"id":55943164},{"atb":[[4.8,55.01],[5.8,21.77],[5.3,48.61]],"id":54867443},{"atl":[[48,4.44],[29,4.97]],"id":54867443}],"con":true,"img":false}]}
{"op":"mcm","clk":"11450277004","pt":1717319939806,"mc":[{"id":"1.229554910","rc":[{"atb":[[4.3,2.53]],"id":70003369},{"atb":[[6.2,4.59]],"id":69033911},{"atb":[[3.7,0]],"id":55943164},{"atb":[[5.9,2.63]],"id":54867443}],"con":true,"img":false}]}
{"op":"mcm","clk":"11450277011","pt":1717319939915,"mc":[{"id":"1.229554910","rc":[{"atb":[[3.95,2.64]],"id":55943164}],"con":true,"img":false}]}
{"op":"mcm","clk":"11450277040","pt":1717319940222,"mc":[{"id":"1.229554910","rc":[{"atl":[[1000,1.17]],"id":54867443}],"con":true,"img":false}]}
{"op":"mcm","clk":"11450277046","pt":1717319940324,"mc":[{"id":"1.229554910","rc":[{"atl":[[23,0.5]],"id":54867443}],"con":true,"img":false}]}
{"op":"mcm","clk":"11450277137","pt":1717319941307,"mc":[{"id":"1.229554910","rc":[{"atb":[[3.95,7]],"id":55943164}],"con":true,"img":false}]}
{"op":"mcm","clk":"11450277548","pt":1717319945912,"mc":[{"id":"1.229554910","rc":[{"atb":[[3.95,38.94]],"id":70003369},{"atb":[[1.63,338.38]],"id":69676139},{"atb":[[3.5,4.13]],"id":55943164}],"con":true,"img":false}]}
{"op":"mcm","clk":"11450277989","pt":1717319951126,"mc":[{"id":"1.229554910","rc":[{"atl":[[2.64,0]],"id":69676139}],"con":true,"img":false}]}
{"op":"mcm","clk":"11450278055","pt":1717319951801,"mc":[{"id":"1.229554910","rc":[{"atl":[[2.64,1.07]],"id":69676139}],"con":true,"img":false}]}
{"op":"mcm","clk":"11450279055","pt":1717319964731,"mc":[{"id":"1.229554910","rc":[{"atb":[[1.67,0]],"id":69676139}],"con":true,"img":false}]}
{"op":"mcm","clk":"11450279062","pt":1717319964889,"mc":[{"id":"1.229554910","rc":[{"atb":[[1.74,77.17]],"id":69676139}],"con":true,"img":false}]}
{"op":"mcm","clk":"11450279300","pt":1717319967627,"mc":[{"id":"1.229554910","rc":[{"atl":[[2.64,0]],"id":69676139}],"con":true,"img":false}]}
{"op":"mcm","clk":"11450279319","pt":1717319967935,"mc":[{"id":"1.229554910","rc":[{"atl":[[2.62,1.07]],"id":69676139}],"con":true,"img":false}]}
{"op":"mcm","clk":"11450280216","pt":1717319979652,"mc":[{"id":"1.229554910","rc":[{"atl":[[20,0]],"id":70003369},{"atb":[[3.65,78.88]],"id":55943164},{"atb":[[5.5,0]],"id":54867443},{"atl":[[32,0]],"id":54867443}],"con":true,"img":false}]}
{"op":"mcm","clk":"11450280220","pt":1717319979752,"mc":[{"id":"1.229554910","rc":[{"atl":[[19,5.68]],"id":70003369},{"atb":[[3.95,27.4]],"id":55943164},{"atb":[[5.9,14.83]],"id":54867443},{"atl":[[28,3.32]],"id":54867443}],"con":true,"img":false}]}
{"op":"mcm","clk":"11450280494","pt":1717319983169,"mc":[{"id":"1.229554910","rc":[{"atl":[[2.62,0]],"id":69676139}],"con":true,"img":false}]}
{"op":"mcm","clk":"11450280612","pt":1717319984667,"mc":[{"id":"1.229554910","rc":[{"atl":[[28,4.34]],"id":69033911}],"con":true,"img":false}]}
{"op":"mcm","clk":"11450280617","pt":1717319984768,"mc":[{"id":"1.229554910","rc":[{"atb":[[3.7,77.43]],"id":70003369},{"atb":[[5.3,48.61]],"id":69033911},{"atl":[[34,3.03]],"id":69033911},{"atb":[[1.58,0]],"id":69676139},{"atb":[[4.9,0]],"id":54867443}],"con":true,"img":false}]}
{"op":"mcm","clk":"11450280626","pt":1717319984874,"mc":[{"id":"1.229554910","rc":[{"atb":[[4,40.11]],"id":70003369},{"atb":[[5.9,27.25]],"id":69033911},{"atb":[[1.64,178.2]],"id":69676139},{"atb":[[5.4,26.42]],"id":54867443}],"con":true,"img":false}]}
{"op":"mcm","clk":"11450280881","pt":1717319988180,"mc":[{"id":"1.229554910","rc":[{"atb":[[1.63,331.84]],"id":69676139}],"con":true,"img":false}]}
{"op":"mcm","clk":"11450281449","pt":1717319994797,"mc":[{"id":"1.229554910","rc":[{"atb":[[3.5,0]],"id":55943164}],"con":true,"img":false}]}
{"op":"mcm","clk":"11450281472","pt":1717319995103,"mc":[{"id":"1.229554910","rc":[{"atl":[[2.64,1.07]],"id":69676139}],"con":true,"img":false}]}
{"op":"mcm","clk":"11450281927","pt":1717320000518,"mc":[{"id":"1.229554910","rc":[{"atl":[[2.62,3]],"id":69676139}],"con":true,"img":false}]}
{"op":"mcm","clk":"11450281951","pt":1717320000817,"mc":[{"id":"1.229554910","rc":[{"atb":[[4,2.13]],"id":55943164},{"atl":[[1000,2.03]],"id":54867443}],"con":true,"img":false}]}
{"op":"mcm","clk":"11450281963","pt":1717320001011,"mc":[{"id":"1.229554910","rc":[{"atl":[[12,1.11]],"id":55943164}],"con":true,"img":false}]}
{"op":"mcm","clk":"11450281971","pt":1717320001116,"mc":[{"id":"1.229554910","rc":[{"atl":[[19.5,2],[1000,1.85]],"id":69033911}],"con":true,"img":false}]}
{"op":"mcm","clk":"11450281994","pt":1717320001380,"mc":[{"id":"1.229554910","rc":[{"atl":[[1000,1.56]],"id":54867443}],"con":true,"img":false}]}
{"op":"mcm","clk":"11450282008","pt":1717320001595,"mc":[{"id":"1.229554910","rc":[{"atl":[[11.5,0]],"id":55943164}],"con":true,"img":false}]}
{"op":"mcm","clk":"11450282013","pt":1717320001707,"mc":[{"id":"1.229554910","rc":[{"atl":[[1000,1.46]],"id":69033911},{"atl":[[1000,1.51]],"id":55943164}],"con":true,"img":false}]}
{"op":"mcm","clk":"11450282021","pt":1717320001807,"mc":[{"id":"1.229554910","rc":[{"atb":[[3.95,23.04]],"id":55943164}],"con":true,"img":false}]}
{"op":"mcm","clk":"11450282043","pt":1717320002007,"mc":[{"id":"1.229554910","rc":[{"atl":[[1000,1.17]],"id":54867443}],"con":true,"img":false}]}
{"op":"mcm","clk":"11450282048","pt":1717320002106,"mc":[{"id":"1.229554910","rc":[{"atl":[[22,0.38]],"id":54867443}],"con":true,"img":false}]}
{"op":"mcm","clk":"11450282069","pt":1717320002420,"mc":[{"id":"1.229554910","rc":[{"atl":[[1000,1]],"id":69033911}],"con":true,"img":false}]}
{"op":"mcm","clk":"11450282075","pt":1717320002525,"mc":[{"id":"1.229554910","rc":[{"atl":[[18.5,0.46]],"id":69033911}],"con":true,"img":false}]}
{"op":"mcm","clk":"11450282091","pt":1717320002696,"mc":[{"id":"1.229554910","rc":[{"atl":[[4.3,3.29]],"id":69676139}],"con":true,"img":false}]}
{"op":"mcm","clk":"11450282176","pt":1717320003616,"mc":[{"id":"1.229554910","rc":[{"atb":[[3.65,83.01]],"id":55943164}],"con":true,"img":false}]}
{"op":"mcm","clk":"11450282195","pt":1717320003779,"mc":[{"id":"1.229554910","rc":[{"atl":[[18.5,0],[1000,1.85]],"id":69033911}],"con":true,"img":false}]}
{"op":"mcm","clk":"11450282243","pt":1717320004402,"mc":[{"id":"1.229554910","rc":[{"atl":[[1000,1.46]],"id":69033911}],"con":true,"img":false}]}
{"op":"mcm","clk":"11450282306","pt":1717320005210,"mc":[{"id":"1.229554910","rc":[{"atl":[[1000,1]],"id":69033911}],"con":true,"img":false}]}
{"op":"mcm","clk":"11450282317","pt":1717320005288,"mc":[{"id":"1.229554910","rc":[{"atl":[[19,1]],"id":69033911}],"con":true,"img":false}]}
{"op":"mcm","clk":"11450282554","pt":1717320008104,"mc":[{"id":"1.229554910","rc":[{"atb":[[4,6.57]],"id":55943164}],"con":true,"img":false}]}
{"op":"mcm","clk":"11450282697","pt":1717320010016,"mc":[{"id":"1.229554910","rc":[{"atb":[[3.95,20.4]],"id":55943164}],"con":true,"img":false}]}
{"op":"mcm","clk":"11450282707","pt":1717320010114,"mc":[{"id":"1.229554910","rc":[{"atb":[[4.1,2.64]],"id":55943164}],"con":true,"img":false}]}
{"op":"mcm","clk":"11450282727","pt":1717320010425,"mc":[{"id":"1.229554910","rc":[{"atl":[[2.64,0]],"id":69676139}],"con":true,"img":false}]}
{"op":"mcm","clk":"11450282761","pt":1717320010914,"mc":[{"id":"1.229554910","rc":[{"atl":[[2.6,1.07]],"id":69676139},{"atb":[[4,2.13]],"id":55943164}],"con":true,"img":false}]}
{"op":"mcm","clk":"11450282790","pt":1717320011326,"mc":[{"id":"1.229554910","rc":[{"atb":[[4.1,0]],"id":55943164}],"con":true,"img":false}]}
{"op":"mcm","clk":"11450282796","pt":1717320011432,"mc":[{"id":"1.229554910","rc":[{"atb":[[4,4.77]],"id":55943164}],"con":true,"img":false}]}
{"op":"mcm","clk":"11450282919","pt":1717320012730,"mc":[{"id":"1.229554910","rc":[{"atb":[[3.95,35.43]],"id":70003369}],"con":true,"img":false}]}
{"op":"mcm","clk":"11450283004","pt":1717320013611,"mc":[{"id":"1.229554910","rc":[{"atb":[[4,2.64]],"id":55943164}],"con":true,"img":false}]}
{"op":"mcm","clk":"11450283011","pt":1717320013713,"mc":[{"id":"1.229554910","rc":[{"atb":[[4.2,2.02]],"id":55943164}],"con":true,"img":false}]}
{"op":"mcm","clk":"11450283016","pt":1717320013817,"mc":[{"id":"1.229554910","rc":[{"atb":[[3.95,38.94]],"id":70003369}],"con":true,"img":false}]}
{"op":"mcm","clk":"11450283222","pt":1717320016518,"mc":[{"id":"1.229554910","rc":[{"atb":[[1.69,0]],"id":69676139}],"con":true,"img":false}]}
{"op":"mcm","clk":"11450283567","pt":1717320021125,"mc":[{"id":"1.229554910","rc":[{"atb":[[4.2,0]],"id":55943164}],"con":true,"img":false}]}
{"op":"mcm","clk":"11450283585","pt":1717320021432,"mc":[{"id":"1.229554910","rc":[{"atb":[[4.1,2.02]],"id":55943164}],"con":true,"img":false}]}
{"op":"mcm","clk":"11450283691","pt":1717320023037,"mc":[{"id":"1.229554910","rc":[{"atl":[[1000,2.37]],"id":55943164}],"con":true,"img":false}]}
{"op":"mcm","clk":"11450283712","pt":1717320023310,"mc":[{"id":"1.229554910","rc":[{"atl":[[12.5,0]],"id":55943164}],"con":true,"img":false}]}
{"op":"mcm","clk":"11450283906","pt":1717320025832,"mc":[{"id":"1.229554910","rc":[{"spn":2.19,"spf":"NaN","id":69676139},{"atl":[[1000,2.25]],"id":55943164},{"spn":8.05,"spf":"NaN","id":55943164},{"spn":13.95,"spf":"NaN","id":54867443}],"con":true,"img":false}]}
{"op":"mcm","clk":"11450283933","pt":1717320026241,"mc":[{"id":"1.229554910","rc":[{"atl":[[2.6,0]],"id":69676139}],"con":true,"img":false}]}
{"op":"mcm","clk":"11450283968","pt":1717320026710,"mc":[{"id":"1.229554910","rc":[{"atl":[[2.58,1.07]],"id":69676139}],"con":true,"img":false}]}
{"op":"mcm","clk":"11450284097","pt":1717320028418,"mc":[{"id":"1.229554910","rc":[{"atl":[[1000,1.51]],"id":55943164}],"con":true,"img":false}]}
{"op":"mcm","clk":"11450284105","pt":1717320028524,"mc":[{"id":"1.229554910","rc":[{"atl":[[11.5,0.74]],"id":55943164}],"con":true,"img":false}]}
{"op":"mcm","clk":"11450284678","pt":1717320036543,"mc":[{"id":"1.229554910","rc":[{"atl":[[13.5,0.98]],"id":70003369}],"con":true,"img":false}]}
{"op":"mcm","clk":"11450285038","pt":1717320042234,"mc":[{"id":"1.229554910","rc":[{"atl":[[2.58,0]],"id":69676139}],"con":true,"img":false}]}
{"op":"mcm","clk":"11450285123","pt":1717320043325,"mc":[{"id":"1.229554910","rc":[{"atl":[[2.56,1.07]],"id":69676139}],"con":true,"img":false}]}
{"op":"mcm","clk":"11450286066","pt":1717320058860,"mc":[{"id":"1.229554910","rc":[{"atl":[[2.56,0]],"id":69676139}],"con":true,"img":false}]}
{"op":"mcm","clk":"11450286503","pt":1717320066374,"mc":[{"id":"1.229554910","rc":[{"atb":[[5.6,9.06]],"id":69033911}],"con":true,"img":false}]}
{"op":"mcm","clk":"11450286509","pt":1717320066471,"mc":[{"id":"1.229554910","rc":[{"atb":[[3.9,13.01]],"id":70003369}],"con":true,"img":false}]}
{"op":"mcm","clk":"11450286517","pt":1717320066579,"mc":[{"id":"1.229554910","rc":[{"atb":[[3.75,13.53]],"id":55943164}],"con":true,"img":false}]}
{"op":"mcm","clk":"11450286523","pt":1717320066677,"mc":[{"id":"1.229554910","rc":[{"atb":[[65,0.78]],"id":52272946}],"con":true,"img":false}]}
{"op":"mcm","clk":"11450286528","pt":1717320066787,"mc":[{"id":"1.229554910","rc":[{"atb":[[5.4,35.82]],"id":54867443}],"con":true,"img":false}]}
{"op":"mcm","clk":"11450286538","pt":1717320066991,"mc":[{"id":"1.229554910","rc":[{"atb":[[1.63,362.96]],"id":69676139}],"con":true,"img":false}]}
{"op":"mcm","clk":"11450286548","pt":1717320067191,"mc":[{"id":"1.229554910","rc":[{"atb":[[3.95,40.29]],"id":70003369}],"con":true,"img":false}]}
{"op":"mcm","clk":"11450286930","pt":1717320072780,"mc":[{"id":"1.229554910","rc":[{"atl":[[2.6,1.07]],"id":69676139}],"con":true,"img":false}]}
{"op":"mcm","clk":"11450287984","pt":1717320088093,"mc":[{"id":"1.229554910","rc":[{"atl":[[2.6,0]],"id":69676139},{"spn":2.2,"spf":"NaN","id":69676139},{"spn":7.8,"spf":"NaN","id":55943164}],"con":true,"img":false}]}
{"op":"mcm","clk":"11450288028","pt":1717320088614,"mc":[{"id":"1.229554910","rc":[{"atl":[[2.58,1.07]],"id":69676139}],"con":true,"img":false}]}
{"op":"mcm","clk":"11450288085","pt":1717320089494,"mc":[{"id":"1.229554910","rc":[{"atl":[[12,2.72]],"id":55943164}],"con":true,"img":false}]}
{"op":"mcm","clk":"11450288126","pt":1717320090009,"mc":[{"id":"1.229554910","rc":[{"atl":[[13.5,2.42]],"id":70003369},{"atl":[[1000,1]],"id":55943164}],"con":true,"img":false}]}
{"op":"mcm","clk":"11450288133","pt":1717320090113,"mc":[{"id":"1.229554910","rc":[{"atl":[[11.5,1.25]],"id":55943164}],"con":true,"img":false}]}
{"op":"mcm","clk":"11450288169","pt":1717320090585,"mc":[{"id":"1.229554910","rc":[{"atl":[[1000,1.17]],"id":70003369}],"con":true,"img":false}]}
{"op":"mcm","clk":"11450288178","pt":1717320090686,"mc":[{"id":"1.229554910","rc":[{"atl":[[13,1.16]],"id":70003369},{"atb":[[3.65,78.88]],"id":55943164}],"con":true,"img":false}]}
{"op":"mcm","clk":"11450288215","pt":1717320091304,"mc":[{"id":"1.229554910","rc":[{"atl":[[13,0.65]],"id":70003369}],"con":true,"img":false}]}
{"op":"mcm","clk":"11450288224","pt":1717320091407,"mc":[{"id":"1.229554910","rc":[{"atl":[[1000,1.68]],"id":70003369}],"con":true,"img":false}]}
{"op":"mcm","clk":"11450289023","pt":1717320104213,"mc":[{"id":"1.229554910","rc":[{"atl":[[2.58,0]],"id":69676139}],"con":true,"img":false}]}
{"op":"mcm","clk":"11450289208","pt":1717320107115,"mc":[{"id":"1.229554910","rc":[{"atl":[[12,1.61]],"id":55943164}],"con":true,"img":false}]}
{"op":"mcm","clk":"11450289225","pt":1717320107425,"mc":[{"id":"1.229554910","rc":[{"atl":[[11.5,0.74]],"id":55943164}],"con":true,"img":false}]}
{"op":"mcm","clk":"11450289234","pt":1717320107528,"mc":[{"id":"1.229554910","rc":[{"atl":[[1000,1.51]],"id":55943164}],"con":true,"img":false}]}
{"op":"mcm","clk":"11450289677","pt":1717320114325,"mc":[{"id":"1.229554910","rc":[{"atb":[[3.45,0],[3.95,4.86],[3.7,0]],"id":70003369},{"atl":[[19.5,0],[29,0]],"id":70003369},{"atb":[[3.4,0],[3.9,0],[3.65,0]],"id":55943164},{"atl":[[19,5.56],[28,0]],"id":55943164}],"con":true,"img":false}]}
{"op":"mcm","clk":"11450289704","pt":1717320114742,"mc":[{"id":"1.229554910","rc":[{"atb":[[4,0]],"id":70003369},{"atb":[[3.95,0]],"id":55943164}],"con":true,"img":false}]}
{"op":"mcm","clk":"11450289710","pt":1717320114841,"mc":[{"id":"1.229554910","rc":[{"atb":[[3.7,40.11]],"id":70003369},{"atb":[[3.65,20.4]],"id":55943164}],"con":true,"img":false}]}
{"op":"mcm","clk":"11450289759","pt":1717320115524,"mc":[{"id":"1.229554910","rc":[{"atb":[[4,0],[3.5,4.13]],"id":55943164}],"con":true,"img":false}]}
{"op":"mcm","clk":"11450289765","pt":1717320115635,"mc":[{"id":"1.229554910","rc":[{"atb":[[3.8,2.64]],"id":55943164}],"con":true,"img":false}]}
{"op":"mcm","clk":"11450289780","pt":1717320115839,"mc":[{"id":"1.229554910","rc":[{"atb":[[3.8,4.66]],"id":55943164}],"con":true,"img":false}]}
{"op":"mcm","clk":"11450289787","pt":1717320115940,"mc":[{"id":"1.229554910","rc":[{"atb":[[4.1,0]],"id":55943164}],"con":true,"img":false}]}
{"op":"mcm","clk":"11450289802","pt":1717320116146,"mc":[{"id":"1.229554910","rc":[{"atb":[[3.8,2.64]],"id":55943164}],"con":true,"img":false}]}
{"op":"mcm","clk":"11450289818","pt":1717320116317,"mc":[{"id":"1.229554910","rc":[{"atb":[[4.2,2.02]],"id":55943164}],"con":true,"img":false}]}
{"op":"mcm","clk":"11450289890","pt":1717320117255,"mc":[{"id":"1.229554910","rc":[{"atl":[[2.6,1.07]],"id":69676139}],"con":true,"img":false}]}
{"op":"mcm","clk":"11450290179","pt":1717320121253,"mc":[{"id":"1.229554910","rc":[{"atl":[[2.62,0]],"id":69676139}],"con":true,"img":false}]}
{"op":"mcm","clk":"11450290291","pt":1717320122664,"mc":[{"id":"1.229554910","rc":[{"atl":[[13.5,1.43]],"id":70003369}],"con":true,"img":false}]}
{"op":"mcm","clk":"11450290726","pt":1717320128731,"mc":[{"id":"1.229554910","rc":[{"atl":[[2.58,3]],"id":69676139}],"con":true,"img":false}]}
{"op":"mcm","clk":"11450290749","pt":1717320129045,"mc":[{"id":"1.229554910","rc":[{"atb":[[4.2,0]],"id":55943164}],"con":true,"img":false}]}
{"op":"mcm","clk":"11450290773","pt":1717320129344,"mc":[{"id":"1.229554910","rc":[{"atb":[[3.85,2.02]],"id":55943164}],"con":true,"img":false}]}
{"op":"mcm","clk":"11450290812","pt":1717320129762,"mc":[{"id":"1.229554910","rc":[{"atb":[[3.45,85.33],[3.95,40.29],[3.7,117.54]],"id":70003369},{"atl":[[19.5,7.53],[29,7.46]],"id":70003369},{"atb":[[3.4,87.1],[3.9,36.04],[3.65,99.29]],"id":55943164},{"atl":[[19,13.3],[28,7.74]],"id":55943164}],"con":true,"img":false}]}
{"op":"mcm","clk":"11450290879","pt":1717320130543,"mc":[{"id":"1.229554910","rc":[{"atb":[[3.8,0]],"id":55943164}],"con":true,"img":false}]}
{"op":"mcm","clk":"11450290886","pt":1717320130645,"mc":[{"id":"1.229554910","rc":[{"atb":[[3.95,2.64]],"id":55943164}],"con":true,"img":false}]}
{"op":"mcm","clk":"11450290945","pt":1717320131566,"mc":[{"id":"1.229554910","rc":[{"atb":[[3.95,7]],"id":55943164}],"con":true,"img":false}]}
{"op":"mcm","clk":"11450291025","pt":1717320132662,"mc":[{"id":"1.229554910","rc":[{"atl":[[2.6,0]],"id":69676139}],"con":true,"img":false}]}
{"op":"mcm","clk":"11450291074","pt":1717320133380,"mc":[{"id":"1.229554910","rc":[{"atl":[[2.56,1.07]],"id":69676139}],"con":true,"img":false}]}
{"op":"mcm","clk":"11450291332","pt":1717320137173,"mc":[{"id":"1.229554910","rc":[{"atl":[[1000,4.04]],"id":70003369},{"atl":[[1000,3.87]],"id":55943164}],"con":true,"img":false}]}
{"op":"mcm","clk":"11450291346","pt":1717320137372,"mc":[{"id":"1.229554910","rc":[{"atl":[[1000,2.67]],"id":70003369}],"con":true,"img":false}]}
{"op":"mcm","clk":"11450291355","pt":1717320137474,"mc":[{"id":"1.229554910","rc":[{"atl":[[1000,2.63]],"id":55943164}],"con":true,"img":false}]}
{"op":"mcm","clk":"11450291371","pt":1717320137681,"mc":[{"id":"1.229554910","rc":[{"atl":[[1000,1.68]],"id":70003369}],"con":true,"img":false}]}
{"op":"mcm","clk":"11450291379","pt":1717320137741,"mc":[{"id":"1.229554910","rc":[{"atl":[[13.5,2.42]],"id":70003369}],"con":true,"img":false}]}
{"op":"mcm","clk":"11450291393","pt":1717320138046,"mc":[{"id":"1.229554910","rc":[{"atl":[[1000,1.17]],"id":70003369},{"atl":[[1000,1.51]],"id":55943164}],"con":true,"img":false}]}
{"op":"mcm","clk":"11450291399","pt":1717320138151,"mc":[{"id":"1.229554910","rc":[{"atl":[[13,1.16]],"id":70003369},{"atl":[[12,2.72]],"id":55943164}],"con":true,"img":false}]}
{"op":"mcm","clk":"11450291429","pt":1717320138561,"mc":[{"id":"1.229554910","rc":[{"atl":[[13,0.65]],"id":70003369},{"atl":[[1000,1]],"id":55943164}],"con":true,"img":false}]}
{"op":"mcm","clk":"11450291438","pt":1717320138670,"mc":[{"id":"1.229554910","rc":[{"atl":[[1000,1.68]],"id":70003369},{"atl":[[11.5,1.25]],"id":55943164}],"con":true,"img":false}]}
{"op":"mcm","clk":"11450291494","pt":1717320139284,"mc":[{"id":"1.229554910","rc":[{"atl":[[1000,1.17]],"id":70003369}],"con":true,"img":false}]}
{"op":"mcm","clk":"11450291501","pt":1717320139383,"mc":[{"id":"1.229554910","rc":[{"atl":[[13,1.16]],"id":70003369}],"con":true,"img":false}]}
{"op":"mcm","clk":"11450291533","pt":1717320139862,"mc":[{"id":"1.229554910","rc":[{"atl":[[13,0.65]],"id":70003369}],"con":true,"img":false}]}
{"op":"mcm","clk":"11450291539","pt":1717320139954,"mc":[{"id":"1.229554910","rc":[{"atl":[[1000,1.68]],"id":70003369}],"con":true,"img":false}]}
{"op":"mcm","clk":"11450292134","pt":1717320148852,"mc":[{"id":"1.229554910","rc":[{"atl":[[2.56,0]],"id":69676139},{"spn":2.18,"spf":"NaN","id":69676139},{"spn":7.72,"spf":"NaN","id":55943164}],"con":true,"img":false}]}
{"op":"mcm","clk":"11450292174","pt":1717320149573,"mc":[{"id":"1.229554910","rc":[{"atl":[[2.54,1.07]],"id":69676139}],"con":true,"img":false}]}
{"op":"mcm","clk":"11450292244","pt":1717320150670,"mc":[{"id":"1.229554910","rc":[{"atb":[[3.95,38.94]],"id":70003369}],"con":true,"img":false}]}
{"op":"mcm","clk":"11450292788","pt":1717320158000,"mc":[{"id":"1.229554910","rc":[{"atb":[[3.5,0]],"id":55943164}],"con":true,"img":false}]}
{"op":"mcm","clk":"11450293301","pt":1717320164814,"mc":[{"id":"1.229554910","rc":[{"atl":[[2.54,0]],"id":69676139}],"con":true,"img":false}]}
{"op":"mcm","clk":"11450293357","pt":1717320165589,"mc":[{"id":"1.229554910","rc":[{"atl":[[2.52,1.07]],"id":69676139}],"con":true,"img":false}]}
{"op":"mcm","clk":"11450293609","pt":1717320169704,"mc":[{"id":"1.229554910","rc":[{"atb":[[3.7,77.43]],"id":70003369},{"atb":[[3.65,78.88]],"id":55943164}],"con":true,"img":false}]}
{"op":"mcm","clk":"11450293617","pt":1717320169807,"mc":[{"id":"1.229554910","rc":[{"atb":[[4,40.11]],"id":70003369},{"atb":[[3.95,27.4]],"id":55943164}],"con":true,"img":false}]}
{"op":"mcm","clk":"11450293958","pt":1717320174713,"mc":[{"id":"1.229554910","rc":[{"atb":[[60,0]],"id":52272946}],"con":true,"img":false}]}
{"op":"mcm","clk":"11450293964","pt":1717320174813,"mc":[{"id":"1.229554910","rc":[{"atb":[[70,6.74]],"id":52272946}],"con":true,"img":false}]}
{"op":"mcm","clk":"11450294019","pt":1717320175795,"mc":[{"id":"1.229554910","rc":[{"atl":[[2.58,0]],"id":69676139},{"atb":[[3.85,6.15]],"id":55943164}],"con":true,"img":false}]}
{"op":"mcm","clk":"11450294027","pt":1717320176001,"mc":[{"id":"1.229554910","rc":[{"atl":[[2.5,3]],"id":69676139}],"con":true,"img":false}]}
{"op":"mcm","clk":"11450294303","pt":1717320180417,"mc":[{"id":"1.229554910","rc":[{"atb":[[3.85,2.02]],"id":55943164}],"con":true,"img":false}]}
{"op":"mcm","clk":"11450294308","pt":1717320180520,"mc":[{"id":"1.229554910","rc":[{"atb":[[3.95,35.43]],"id":70003369}],"con":true,"img":false}]}
{"op":"mcm","clk":"11450294336","pt":1717320181039,"mc":[{"id":"1.229554910","rc":[{"atl":[[2.52,0]],"id":69676139}],"con":true,"img":false}]}
{"op":"mcm","clk":"11450294353","pt":1717320181244,"mc":[{"id":"1.229554910","rc":[{"atl":[[4.3,0]],"id":69676139}],"con":true,"img":false}]}
{"op":"mcm","clk":"11450294386","pt":1717320181620,"mc":[{"id":"1.229554910","rc":[{"atb":[[3.95,38.94]],"id":70003369}],"con":true,"img":false}]}
{"op":"mcm","clk":"11450294452","pt":1717320182359,"mc":[{"id":"1.229554910","rc":[{"atl":[[4.3,3.29],[2.5,0]],"id":69676139}],"con":true,"img":false}]}
{"op":"mcm","clk":"11450294468","pt":1717320182502,"mc":[{"id":"1.229554910","rc":[{"atl":[[2.48,3]],"id":69676139}],"con":true,"img":false}]}
{"op":"mcm","clk":"11450294511","pt":1717320183231,"mc":[{"id":"1.229554910","rc":[{"atb":[[1.63,369.98]],"id":69676139}],"con":true,"img":false}]}
{"op":"mcm","clk":"11450294686","pt":1717320186034,"mc":[{"id":"1.229554910","rc":[{"atb":[[1.1,1.7]],"id":54867443}],"con":true,"img":false}]}
{"op":"mcm","clk":"11450294690","pt":1717320186138,"mc":[{"id":"1.229554910","rc":[{"atb":[[1.1,1.7]],"id":69033911}],"con":true,"img":false}]}
{"op":"mcm","clk":"11450294727","pt":1717320186447,"mc":[{"id":"1.229554910","rc":[{"atb":[[1.03,1.7]],"id":69676139}],"con":true,"img":false}]}
{"op":"mcm","clk":"11450294738","pt":1717320186651,"mc":[{"id":"1.229554910","rc":[{"atb":[[1.07,1.7]],"id":55943164}],"con":true,"img":false}]}
{"op":"mcm","clk":"11450294746","pt":1717320186755,"mc":[{"id":"1.229554910","rc":[{"atb":[[1.08,1.7]],"id":70003369}],"con":true,"img":false}]}
{"op":"mcm","clk":"11450294763","pt":1717320186920,"mc":[{"id":"1.229554910","rc":[{"atb":[[1.1,0.06]],"id":54867443}],"con":true,"img":false}]}
{"op":"mcm","clk":"11450294771","pt":1717320187022,"mc":[{"id":"1.229554910","rc":[{"atl":[[1000,2.88]],"id":69676139},{"atl":[[1000,2.88]],"id":54867443}],"con":true,"img":false}]}
{"op":"mcm","clk":"11450294783","pt":1717320187232,"mc":[{"id":"1.229554910","rc":[{"atl":[[1000,3.39]],"id":70003369},{"atb":[[1.1,0.06]],"id":69033911},{"atb":[[1.03,0.23]],"id":69676139},{"atl":[[1000,2.7]],"id":55943164}],"con":true,"img":false}]}
{"op":"mcm","clk":"11450294811","pt":1717320187546,"mc":[{"id":"1.229554910","rc":[{"atl":[[1000,2.7]],"id":69033911},{"atb":[[1.02,10.65]],"id":69676139},{"atb":[[1.07,0.1]],"id":55943164}],"con":true,"img":false}]}
{"op":"mcm","clk":"11450294828","pt":1717320187748,"mc":[{"id":"1.229554910","rc":[{"atb":[[1.1,0]],"id":54867443}],"con":true,"img":false}]}
{"op":"mcm","clk":"11450294833","pt":1717320187852,"mc":[{"id":"1.229554910","rc":[{"atb":[[1.08,0.09],[1.04,1.7]],"id":70003369},{"atb":[[1.04,1.7]],"id":55943164},{"atb":[[6,0.06]],"id":54867443}],"con":true,"img":false}]}
{"op":"mcm","clk":"11450294854","pt":1717320188159,"mc":[{"id":"1.229554910","rc":[{"atb":[[1.1,0]],"id":69033911},{"atb":[[1.8,1.7]],"id":52272946}],"con":true,"img":false}]}
{"op":"mcm","clk":"11450294863","pt":1717320188213,"mc":[{"id":"1.229554910","rc":[{"atb":[[6.4,0.06],[1.05,1.7]],"id":69033911}],"con":true,"img":false}]}
{"op":"mcm","clk":"11450294885","pt":1717320188525,"mc":[{"id":"1.229554910","rc":[{"atb":[[1.03,0]],"id":69676139},{"atl":[[1000,1.07]],"id":55943164},{"atl":[[1000,1.21]],"id":54867443}],"con":true,"img":false}]}
{"op":"mcm","clk":"11450294892","pt":1717320188629,"mc":[{"id":"1.229554910","rc":[{"atb":[[1.8,0.23]],"id":69676139}],"con":true,"img":false}]}
{"op":"mcm","clk":"11450294908","pt":1717320188836,"mc":[{"id":"1.229554910","rc":[{"atl":[[1000,1.75]],"id":70003369},{"atl":[[1000,1.52]],"id":69676139}],"con":true,"img":false}]}
{"op":"mcm","clk":"11450294919","pt":1717320189039,"mc":[{"id":"1.229554910","rc":[{"atl":[[2.48,0]],"id":69676139},{"atb":[[1.07,0]],"id":55943164}],"con":true,"img":false}]}
{"op":"mcm","clk":"11450294925","pt":1717320189144,"mc":[{"id":"1.229554910","rc":[{"atb":[[4,0.1]],"id":55943164},{"atl":[[1000,1.17]],"id":54867443}],"con":true,"img":false}]}
{"op":"mcm","clk":"11450294932","pt":1717320189251,"mc":[{"id":"1.229554910","rc":[{"atl":[[2.46,3]],"id":69676139},{"atb":[[1.05,1.7]],"id":54867443},{"atl":[[23,0.53]],"id":54867443}],"con":true,"img":false}]}
{"op":"mcm","clk":"11450294947","pt":1717320189557,"mc":[{"id":"1.229554910","rc":[{"atb":[[1.08,0]],"id":70003369}],"con":true,"img":false}]}
{"op":"mcm","clk":"11450294953","pt":1717320189656,"mc":[{"id":"1.229554910","rc":[{"atb":[[4.4,0.09]],"id":70003369},{"atl":[[1000,1.04]],"id":69033911}],"con":true,"img":false}]}
{"op":"mcm","clk":"11450294958","pt":1717320189758,"mc":[{"id":"1.229554910","rc":[{"atb":[[70,4.13],[1.8,0]],"id":52272946}],"con":true,"img":false}]}
{"op":"mcm","clk":"11450294965","pt":1717320189813,"mc":[{"id":"1.229554910","rc":[{"atb":[[3.95,35.43]],"id":70003369},{"atb":[[60,2.61]],"id":52272946}],"con":true,"img":false}]}
{"op":"mcm","clk":"11450294973","pt":1717320190024,"mc":[{"id":"1.229554910","rc":[{"atb":[[1.05,0.13]],"id":69033911}],"con":true,"img":false}]}
{"op":"mcm","clk":"11450294988","pt":1717320190334,"mc":[{"id":"1.229554910","rc":[{"atl":[[1000,1]],"id":55943164}],"con":true,"img":false}]}
{"op":"mcm","clk":"11450294996","pt":1717320190434,"mc":[{"id":"1.229554910","rc":[{"atl":[[11,0.07]],"id":55943164}],"con":true,"img":false}]}
{"op":"mcm","clk":"11450295000","pt":1717320190540,"mc":[{"id":"1.229554910","rc":[{"atb":[[1.04,0.19]],"id":70003369}],"con":true,"img":false}]}
{"op":"mcm","clk":"11450295016","pt":1717320190854,"mc":[{"id":"1.229554910","rc":[{"atb":[[1.02,9.42]],"id":69676139},{"atl":[[1000,1.17]],"id":69676139}],"con":true,"img":false}]}
{"op":"mcm","clk":"11450295023","pt":1717320190951,"mc":[{"id":"1.229554910","rc":[{"atl":[[2.46,3.34]],"id":69676139}],"con":true,"img":false}]}
{"op":"mcm","clk":"11450295051","pt":1717320191419,"mc":[{"id":"1.229554910","rc":[{"atl":[[1000,1.68]],"id":70003369}],"con":true,"img":false}]}
{"op":"mcm","clk":"11450295066","pt":1717320191656,"mc":[{"id":"1.229554910","rc":[{"atl":[[13,0.72]],"id":70003369}],"con":true,"img":false}]}
{"op":"mcm","clk":"11450295098","pt":1717320192044,"mc":[{"id":"1.229554910","rc":[{"atb":[[1.05,0.14]],"id":54867443}],"con":true,"img":false}]}
{"op":"mcm","clk":"11450295136","pt":1717320192468,"mc":[{"id":"1.229554910","rc":[{"atl":[[1000,1]],"id":69033911}],"con":true,"img":false}]}
{"op":"mcm","clk":"11450295140","pt":1717320192556,"mc":[{"id":"1.229554910","rc":[{"atl":[[18.5,0.04]],"id":69033911}],"con":true,"img":false}]}
{"op":"mcm","clk":"11450295161","pt":1717320192827,"mc":[{"id":"1.229554910","rc":[{"atb":[[1.8,0]],"id":52272946}],"con":true,"img":false}]}
{"op":"mcm","clk":"11450295170","pt":1717320192926,"mc":[{"id":"1.229554910","rc":[{"atb":[[75,0]],"id":52272946}],"con":true,"img":false}]}
{"op":"mcm","clk":"11450295188","pt":1717320193246,"mc":[{"id":"1.229554910","rc":[{"atb":[[1.05,0]],"id":69033911}],"con":true,"img":false}]}
{"op":"mcm","clk":"11450295196","pt":1717320193339,"mc":[{"id":"1.229554910","rc":[{"atb":[[6.4,0.2]],"id":69033911}],"con":true,"img":false}]}
{"op":"mcm","clk":"11450295235","pt":1717320193961,"mc":[{"id":"1.229554910","rc":[{"atb":[[1.04,0]],"id":70003369}],"con":true,"img":false}]}
{"op":"mcm","clk":"11450295246","pt":1717320194061,"mc":[{"id":"1.229554910","rc":[{"atb":[[4.4,0.28]],"id":70003369}],"con":true,"img":false}]}
{"op":"mcm","clk":"11450295273","pt":1717320194325,"mc":[{"id":"1.229554910","rc":[{"atb":[[1.02,8.94]],"id":69676139}],"con":true,"img":false}]}
{"op":"mcm","clk":"11450295284","pt":1717320194436,"mc":[{"id":"1.229554910","rc":[{"atb":[[1.8,0.71]],"id":69676139}],"con":true,"img":false}]}
{"op":"mcm","clk":"11450295303","pt":1717320194740,"mc":[{"id":"1.229554910","rc":[{"atb":[[1.75,0]],"id":69676139},{"atb":[[1.05,0]],"id":54867443}],"con":true,"img":false}]}
{"op":"mcm","clk":"11450295311","pt":1717320194843,"mc":[{"id":"1.229554910","rc":[{"atb":[[6,0.21]],"id":54867443}],"con":true,"img":false}]}
{"op":"mcm","clk":"11450295366","pt":1717320195663,"mc":[{"id":"1.229554910","rc":[{"atl":[[2.46,0.34]],"id":69676139}],"con":true,"img":false}]}
{"op":"mcm","clk":"11450295388","pt":1717320195924,"mc":[{"id":"1.229554910","rc":[{"atl":[[2.44,3]],"id":69676139}],"con":true,"img":false}]}
{"op":"mcm","clk":"11450295453","pt":1717320196549,"mc":[{"id":"1.229554910","rc":[{"atl":[[2.42,1.07]],"id":69676139}],"con":true,"img":false}]}
{"op":"mcm","clk":"11450296046","pt":1717320205364,"mc":[{"id":"1.229554910","rc":[{"atb":[[1.8,1.7]],"id":52272946}],"con":true,"img":false}]}
{"op":"mcm","clk":"11450296065","pt":1717320205779,"mc":[{"id":"1.229554910","rc":[{"atb":[[1.8,0]],"id":52272946}],"con":true,"img":false}]}
{"op":"mcm","clk":"11450296117","pt":1717320206557,"mc":[{"id":"1.229554910","rc":[{"atb":[[1.8,0]],"id":52272946}],"con":true,"img":false}]}
{"op":"mcm","clk":"11450296123","pt":1717320206656,"mc":[{"id":"1.229554910","rc":[{"atb":[[75,0.01]],"id":52272946}],"con":true,"img":false}]}
{"op":"mcm","clk":"11450296486","pt":1717320212458,"mc":[{"id":"1.229554910","rc":[{"spn":8.7,"spf":"NaN","id":70003369},{"spn":12.45,"spf":"NaN","id":69033911},{"atl":[[2.42,0]],"id":69676139},{"spn":2.12,"spf":"NaN","id":69676139},{"spn":352.5,"spf":"NaN","id":52272946},{"spn":7.5,"spf":"NaN","id":55943164},{"spn":14.0,"spf":"NaN","id":54867443}],"con":true,"img":false}]}
{"op":"mcm","clk":"11450296657","pt":1717320215560,"mc":[{"id":"1.229554910","rc":[{"atl":[[2.44,0]],"id":69676139}],"con":true,"img":false}]}
{"op":"mcm","clk":"11450296664","pt":1717320215770,"mc":[{"id":"1.229554910","rc":[{"atl":[[2.42,3]],"id":69676139}],"con":true,"img":false}]}
{"op":"mcm","clk":"11450296849","pt":1717320219493,"mc":[{"id":"1.229554910","rc":[{"atb":[[4.4,6.1]],"id":70003369},{"atb":[[6.4,4.2]],"id":69033911},{"atb":[[4,6.49]],"id":55943164},{"atb":[[6,4.47]],"id":54867443}],"con":true,"img":false}]}
{"op":"mcm","clk":"11450296854","pt":1717320219599,"mc":[{"id":"1.229554910","rc":[{"atb":[[6.2,2.59],[6.6,2]],"id":69033911}],"con":true,"img":false}]}
{"op":"mcm","clk":"11450296876","pt":1717320220066,"mc":[{"id":"1.229554910","rc":[{"atb":[[4.3,0]],"id":70003369},{"atb":[[6.2,0]],"id":69033911},{"atb":[[3.95,24.76]],"id":55943164},{"atb":[[5.9,12.2]],"id":54867443}],"con":true,"img":false}]}
{"op":"mcm","clk":"11450296883","pt":1717320220172,"mc":[{"id":"1.229554910","rc":[{"atb":[[4.5,2.53]],"id":70003369},{"atb":[[6.4,0.2],[6.6,4.59]],"id":69033911},{"atb":[[4.1,2.64]],"id":55943164},{"atb":[[6.2,2.63]],"id":54867443}],"con":true,"img":false}]}
{"op":"mcm","clk":"11450296905","pt":1717320220593,"mc":[{"id":"1.229554910","rc":[{"atb":[[6.6,2]],"id":69033911}],"con":true,"img":false}]}
{"op":"mcm","clk":"11450296913","pt":1717320220683,"mc":[{"id":"1.229554910","rc":[{"atb":[[6.2,2.59]],"id":69033911}],"con":true,"img":false}]}
{"op":"mcm","clk":"11450296938","pt":1717320221200,"mc":[{"id":"1.229554910","rc":[{"atb":[[4.4,0.28]],"id":70003369},{"atb":[[4,0.1]],"id":55943164},{"atb":[[6,0.21]],"id":54867443}],"con":true,"img":false}]}
{"op":"mcm","clk":"11450296945","pt":1717320221304,"mc":[{"id":"1.229554910","rc":[{"atb":[[4.2,6.08]],"id":55943164},{"atb":[[6.4,3.99]],"id":54867443}],"con":true,"img":false}]}
{"op":"mcm","clk":"11450296984","pt":1717320221878,"mc":[{"id":"1.229554910","rc":[{"atb":[[4.5,0]],"id":70003369}],"con":true,"img":false}]}
{"op":"mcm","clk":"11450296996","pt":1717320221985,"mc":[{"id":"1.229554910","rc":[{"atb":[[4.3,2.53]],"id":70003369}],"con":true,"img":false}]}
{"op":"mcm","clk":"11450297011","pt":1717320222186,"mc":[{"id":"1.229554910","rc":[{"atl":[[2.42,0]],"id":69676139}],"con":true,"img":false}]}
{"op":"mcm","clk":"11450297018","pt":1717320222289,"mc":[{"id":"1.229554910","rc":[{"atb":[[4.4,6.1]],"id":70003369},{"atb":[[3.95,20.4]],"id":55943164}],"con":true,"img":false}]}
{"op":"mcm","clk":"11450297027","pt":1717320222387,"mc":[{"id":"1.229554910","rc":[{"atl":[[2.4,3]],"id":69676139}],"con":true,"img":false}]}
{"op":"mcm","clk":"11450297032","pt":1717320222488,"mc":[{"id":"1.229554910","rc":[{"atb":[[3.5,4.13]],"id":55943164}],"con":true,"img":false}]}
{"op":"mcm","clk":"11450297073","pt":1717320222977,"mc":[{"id":"1.229554910","rc":[{"atb":[[4.3,0]],"id":70003369}],"con":true,"img":false}]}
{"op":"mcm","clk":"11450297080","pt":1717320223077,"mc":[{"id":"1.229554910","rc":[{"atb":[[4.5,2.53]],"id":70003369}],"con":true,"img":false}]}
{"op":"mcm","clk":"11450297125","pt":1717320223692,"mc":[{"id":"1.229554910","rc":[{"atb":[[4.4,0.28]],"id":70003369}],"con":true,"img":false}]}
{"op":"mcm","clk":"11450297187","pt":1717320224386,"mc":[{"id":"1.229554910","rc":[{"atb":[[4.5,0]],"id":70003369}],"con":true,"img":false}]}
{"op":"mcm","clk":"11450297195","pt":1717320224489,"mc":[{"id":"1.229554910","rc":[{"atb":[[4.3,2.53]],"id":70003369}],"con":true,"img":false}]}
{"op":"mcm","clk":"11450297212","pt":1717320224696,"mc":[{"id":"1.229554910","rc":[{"atb":[[6.2,4.59],[6.6,0]],"id":69033911}],"con":true,"img":false}]}
{"op":"mcm","clk":"11450297223","pt":1717320224800,"mc":[{"id":"1.229554910","rc":[{"atb":[[6.2,2.59]],"id":69033911},{"atl":[[2.38,1.07]],"id":69676139}],"con":true,"img":false}]}
{"op":"mcm","clk":"11450297234","pt":1717320224898,"mc":[{"id":"1.229554910","rc":[{"atb":[[6.2,4.59]],"id":69033911}],"con":true,"img":false}]}
{"op":"mcm","clk":"11450297249","pt":1717320225104,"mc":[{"id":"1.229554910","rc":[{"atb":[[4.4,6.1]],"id":70003369},{"atb":[[6.4,4.2]],"id":69033911}],"con":true,"img":false}]}
{"op":"mcm","clk":"11450297301","pt":1717320225484,"mc":[{"id":"1.229554910","rc":[{"atb":[[6.2,2]],"id":69033911}],"con":true,"img":false}]}
{"op":"mcm","clk":"11450297305","pt":1717320225588,"mc":[{"id":"1.229554910","rc":[{"atb":[[6.6,2.59]],"id":69033911}],"con":true,"img":false}]}
{"op":"mcm","clk":"11450297354","pt":1717320226481,"mc":[{"id":"1.229554910","rc":[{"atb":[[6.4,0.2]],"id":69033911}],"con":true,"img":false}]}
{"op":"mcm","clk":"11450297374","pt":1717320226774,"mc":[{"id":"1.229554910","rc":[{"atb":[[6.6,0]],"id":69033911}],"con":true,"img":false}]}
{"op":"mcm","clk":"11450297380","pt":1717320226882,"mc":[{"id":"1.229554910","rc":[{"atb":[[6.2,4.59]],"id":69033911}],"con":true,"img":false}]}
{"op":"mcm","clk":"11450297435","pt":1717320227501,"mc":[{"id":"1.229554910","rc":[{"atb":[[6.4,4.2]],"id":69033911}],"con":true,"img":false}]}
{"op":"mcm","clk":"11450297442","pt":1717320227635,"mc":[{"id":"1.229554910","rc":[{"atb":[[3.95,38.94]],"id":70003369}],"con":true,"img":false}]}
{"op":"mcm","clk":"11450297578","pt":1717320230000,"mc":[{"id":"1.229554910","rc":[{"atb":[[6.2,2.59],[6.6,2]],"id":69033911}],"con":true,"img":false}]}
{"op":"mcm","clk":"11450297615","pt":1717320230610,"mc":[{"id":"1.229554910","rc":[{"atb":[[6.4,0.2]],"id":69033911}],"con":true,"img":false}]}
{"op":"mcm","clk":"11450297619","pt":1717320230671,"mc":[{"id":"1.229554910","rc":[{"atb":[[6.2,4.59]],"id":69033911}],"con":true,"img":false}]}
{"op":"mcm","clk":"11450297623","pt":1717320230782,"mc":[{"id":"1.229554910","rc":[{"atb":[[6.6,0]],"id":69033911}],"con":true,"img":false}]}
{"op":"mcm","clk":"11450297664","pt":1717320231500,"mc":[{"id":"1.229554910","rc":[{"atb":[[6.4,4.2]],"id":69033911}],"con":true,"img":false}]}
{"op":"mcm","clk":"11450297670","pt":1717320231619,"mc":[{"id":"1.229554910","rc":[{"atb":[[6.2,2.59],[6.6,2]],"id":69033911}],"con":true,"img":false}]}
{"op":"mcm","clk":"11450297684","pt":1717320231822,"mc":[{"id":"1.229554910","rc":[{"atb":[[6.6,0]],"id":69033911}],"con":true,"img":false}]}
{"op":"mcm","clk":"11450297693","pt":1717320231927,"mc":[{"id":"1.229554910","rc":[{"atb":[[6.6,2]],"id":69033911}],"con":true,"img":false}]}
{"op":"mcm","clk":"11450297712","pt":1717320232175,"mc":[{"id":"1.229554910","rc":[{"atb":[[6.4,0.2]],"id":69033911}],"con":true,"img":false}]}
{"op":"mcm","clk":"11450297868","pt":1717320234818,"mc":[{"id":"1.229554910","rc":[{"atb":[[1.02,10.94]],"id":69676139}],"con":true,"img":false}]}
{"op":"mcm","clk":"11450297908","pt":1717320235393,"mc":[{"id":"1.229554910","rc":[{"atb":[[1.02,2]],"id":54867443}],"con":true,"img":false}]}
{"op":"mcm","clk":"11450297973","pt":1717320236320,"mc":[{"id":"1.229554910","rc":[{"atb":[[1.02,2]],"id":55943164}],"con":true,"img":false}]}
{"op":"mcm","clk":"11450298026","pt":1717320237003,"mc":[{"id":"1.229554910","rc":[{"atb":[[1.02,10.94]],"id":70003369},{"atb":[[6.2,4.59]],"id":69033911}],"con":true,"img":false}]}
{"op":"mcm","clk":"11450298032","pt":1717320237104,"mc":[{"id":"1.229554910","rc":[{"atb":[[6.6,0]],"id":69033911}],"con":true,"img":false}]}
{"op":"mcm","clk":"11450298061","pt":1717320237603,"mc":[{"id":"1.229554910","rc":[{"atb":[[6.4,4.2]],"id":69033911}],"con":true,"img":false}]}
{"op":"mcm","clk":"11450298065","pt":1717320237725,"mc":[{"id":"1.229554910","rc":[{"atb":[[6.2,2.59],[6.6,2]],"id":69033911}],"con":true,"img":false}]}
{"op":"mcm","clk":"11450298071","pt":1717320237828,"mc":[{"id":"1.229554910","rc":[{"atb":[[1.02,2]],"id":69033911}],"con":true,"img":false}]}
{"op":"mcm","clk":"11450298103","pt":1717320238607,"mc":[{"id":"1.229554910","rc":[{"atb":[[6.4,0.2]],"id":69033911}],"con":true,"img":false}]}
{"op":"mcm","clk":"11450298222","pt":1717320240412,"mc":[{"id":"1.229554910","rc":[{"atl":[[2.38,0]],"id":69676139}],"con":true,"img":false}]}
{"op":"mcm","clk":"11450298241","pt":1717320240729,"mc":[{"id":"1.229554910","rc":[{"atb":[[1.02,8.94]],"id":69676139}],"con":true,"img":false}]}
{"op":"mcm","clk":"11450298247","pt":1717320240824,"mc":[{"id":"1.229554910","rc":[{"atb":[[1.8,2.71]],"id":69676139}],"con":true,"img":false}]}
{"op":"mcm","clk":"11450298266","pt":1717320241205,"mc":[{"id":"1.229554910","rc":[{"atb":[[4.3,0]],"id":70003369},{"atb":[[1.02,0]],"id":54867443}],"con":true,"img":false}]}
{"op":"mcm","clk":"11450298276","pt":1717320241311,"mc":[{"id":"1.229554910","rc":[{"atb":[[4.5,2.53]],"id":70003369}],"con":true,"img":false}]}
{"op":"mcm","clk":"11450298284","pt":1717320241408,"mc":[{"id":"1.229554910","rc":[{"atb":[[6.6,2]],"id":54867443}],"con":true,"img":false}]}
{"op":"mcm","clk":"11450298302","pt":1717320241711,"mc":[{"id":"1.229554910","rc":[{"atb":[[4.4,0.28]],"id":70003369},{"atb":[[1.02,0]],"id":55943164},{"atb":[[6.4,0]],"id":54867443}],"con":true,"img":false}]}
{"op":"mcm","clk":"11450298307","pt":1717320241811,"mc":[{"id":"1.229554910","rc":[{"atb":[[4.3,2]],"id":55943164}],"con":true,"img":false}]}
{"op":"mcm","clk":"11450298318","pt":1717320242017,"mc":[{"id":"1.229554910","rc":[{"atl":[[2.4,0]],"id":69676139}],"con":true,"img":false}]}
{"op":"mcm","clk":"11450298324","pt":1717320242117,"mc":[{"id":"1.229554910","rc":[{"atb":[[1.02,8.94]],"id":70003369}],"con":true,"img":false}]}
{"op":"mcm","clk":"11450298333","pt":1717320242221,"mc":[{"id":"1.229554910","rc":[{"atb":[[4.5,4.53]],"id":70003369},{"atl":[[2.38,3]],"id":69676139}],"con":true,"img":false}]}
{"op":"mcm","clk":"11450298347","pt":1717320242426,"mc":[{"id":"1.229554910","rc":[{"atb":[[4.5,2]],"id":70003369},{"atb":[[6.2,0]],"id":54867443}],"con":true,"img":false}]}
{"op":"mcm","clk":"11450298357","pt":1717320242481,"mc":[{"id":"1.229554910","rc":[{"atb":[[4.3,2.53]],"id":70003369},{"atb":[[1.02,0]],"id":69033911},{"atb":[[4.2,0]],"id":55943164},{"atb":[[6,2.84]],"id":54867443}],"con":true,"img":false}]}
{"op":"mcm","clk":"11450298366","pt":1717320242593,"mc":[{"id":"1.229554910","rc":[{"atb":[[6.8,2]],"id":69033911}],"con":true,"img":false}]}
{"op":"mcm","clk":"11450298397","pt":1717320243011,"mc":[{"id":"1.229554910","rc":[{"atb":[[4.1,0]],"id":55943164}],"con":true,"img":false}]}
{"op":"mcm","clk":"11450298404","pt":1717320243110,"mc":[{"id":"1.229554910","rc":[{"atb":[[4,2.74]],"id":55943164}],"con":true,"img":false}]}
{"op":"mcm","clk":"11450298473","pt":1717320243995,"mc":[{"id":"1.229554910","rc":[{"atb":[[1.76,10.33]],"id":69676139}],"con":true,"img":false}]}
{"op":"mcm","clk":"11450298561","pt":1717320245393,"mc":[{"id":"1.229554910","rc":[{"atb":[[6.6,0]],"id":54867443}],"con":true,"img":false}]}
{"op":"mcm","clk":"11450298571","pt":1717320245499,"mc":[{"id":"1.229554910","rc":[{"atb":[[6.2,2]],"id":54867443}],"con":true,"img":false}]}
{"op":"mcm","clk":"11450298590","pt":1717320245810,"mc":[{"id":"1.229554910","rc":[{"atb":[[4.3,0]],"id":55943164},{"atb":[[6.4,3.99]],"id":54867443}],"con":true,"img":false}]}
{"op":"mcm","clk":"11450298602","pt":1717320245911,"mc":[{"id":"1.229554910","rc":[{"atb":[[4.1,2]],"id":55943164}],"con":true,"img":false}]}
{"op":"mcm","clk":"11450298614","pt":1717320246216,"mc":[{"id":"1.229554910","rc":[{"atb":[[4.5,0]],"id":70003369}],"con":true,"img":false}]}
{"op":"mcm","clk":"11450298623","pt":1717320246324,"mc":[{"id":"1.229554910","rc":[{"atb":[[4.4,2.28]],"id":70003369}],"con":true,"img":false}]}
{"op":"mcm","clk":"11450298631","pt":1717320246423,"mc":[{"id":"1.229554910","rc":[{"atb":[[3.95,35.43]],"id":70003369}],"con":true,"img":false}]}
{"op":"mcm","clk":"11450298646","pt":1717320246631,"mc":[{"id":"1.229554910","rc":[{"atb":[[6,0.21]],"id":54867443}],"con":true,"img":false}]}
{"op":"mcm","clk":"11450298655","pt":1717320246696,"mc":[{"id":"1.229554910","rc":[{"atb":[[6.2,4.63]],"id":54867443}],"con":true,"img":false}]}
{"op":"mcm","clk":"11450298662","pt":1717320246797,"mc":[{"id":"1.229554910","rc":[{"atb":[[4.5,5.68]],"id":70003369},{"atb":[[4.2,6.08]],"id":55943164}],"con":true,"img":false}]}
{"op":"mcm","clk":"11450298694","pt":1717320247207,"mc":[{"id":"1.229554910","rc":[{"atb":[[4,0.1]],"id":55943164}],"con":true,"img":false}]}
{"op":"mcm","clk":"11450298702","pt":1717320247315,"mc":[{"id":"1.229554910","rc":[{"atb":[[4.1,4.64]],"id":55943164}],"con":true,"img":false}]}
{"op":"mcm","clk":"11450298806","pt":1717320248611,"mc":[{"id":"1.229554910","rc":[{"atl":[[2.38,0]],"id":69676139}],"con":true,"img":false}]}
{"op":"mcm","clk":"11450298822","pt":1717320248821,"mc":[{"id":"1.229554910","rc":[{"atl":[[2.36,3]],"id":69676139}],"con":true,"img":false}]}
{"op":"mcm","clk":"11450298874","pt":1717320249494,"mc":[{"id":"1.229554910","rc":[{"atb":[[6.2,2.63]],"id":54867443}],"con":true,"img":false}]}
{"op":"mcm","clk":"11450298881","pt":1717320249640,"mc":[{"id":"1.229554910","rc":[{"atb":[[6.6,2]],"id":54867443}],"con":true,"img":false}]}
{"op":"mcm","clk":"11450298907","pt":1717320250009,"mc":[{"id":"1.229554910","rc":[{"atb":[[4.1,2.64]],"id":55943164}],"con":true,"img":false}]}
{"op":"mcm","clk":"11450298913","pt":1717320250112,"mc":[{"id":"1.229554910","rc":[{"atb":[[4.3,2]],"id":55943164}],"con":true,"img":false}]}
{"op":"mcm","clk":"11450298924","pt":1717320250319,"mc":[{"id":"1.229554910","rc":[{"atb":[[4.4,0.28]],"id":70003369}],"con":true,"img":false}]}
{"op":"mcm","clk":"11450298932","pt":1717320250419,"mc":[{"id":"1.229554910","rc":[{"atb":[[4.6,2]],"id":70003369},{"atb":[[4.2,0]],"id":55943164},{"atb":[[6.4,0]],"id":54867443}],"con":true,"img":false}]}
{"op":"mcm","clk":"11450298951","pt":1717320250731,"mc":[{"id":"1.229554910","rc":[{"atb":[[4.1,0]],"id":55943164},{"atb":[[6.2,0]],"id":54867443}],"con":true,"img":false}]}
{"op":"mcm","clk":"11450298960","pt":1717320250834,"mc":[{"id":"1.229554910","rc":[{"atb":[[4,2.74]],"id":55943164},{"atb":[[6,2.84]],"id":54867443}],"con":true,"img":false}]}
{"op":"mcm","clk":"11450298992","pt":1717320251417,"mc":[{"id":"1.229554910","rc":[{"atb":[[4.5,0]],"id":70003369}],"con":true,"img":false}]}
{"op":"mcm","clk":"11450299148","pt":1717320253905,"mc":[{"id":"1.229554910","rc":[{"atb":[[6.6,0]],"id":54867443}],"con":true,"img":false}]}
{"op":"mcm","clk":"11450299157","pt":1717320254010,"mc":[{"id":"1.229554910","rc":[{"atb":[[6.2,2]],"id":54867443}],"con":true,"img":false}]}
{"op":"mcm","clk":"11450299178","pt":1717320254217,"mc":[{"id":"1.229554910","rc":[{"atb":[[4.3,0]],"id":55943164}],"con":true,"img":false}]}
{"op":"mcm","clk":"11450299185","pt":1717320254317,"mc":[{"id":"1.229554910","rc":[{"atb":[[4.1,2]],"id":55943164}],"con":true,"img":false}]}
{"op":"mcm","clk":"11450299207","pt":1717320254632,"mc":[{"id":"1.229554910","rc":[{"atb":[[4.6,0]],"id":70003369}],"con":true,"img":false}]}
{"op":"mcm","clk":"11450299214","pt":1717320254734,"mc":[{"id":"1.229554910","rc":[{"atb":[[4.4,2.28]],"id":70003369}],"con":true,"img":false}]}
{"op":"mcm","clk":"11450299222","pt":1717320254834,"mc":[{"id":"1.229554910","rc":[{"atb":[[4.4,8.1]],"id":70003369},{"atb":[[4.2,6.08]],"id":55943164}],"con":true,"img":false}]}
{"op":"mcm","clk":"11450299263","pt":1717320255314,"mc":[{"id":"1.229554910","rc":[{"atl":[[2.34,1.07]],"id":69676139}],"con":true,"img":false}]}
{"op":"mcm","clk":"11450299433","pt":1717320257915,"mc":[{"id":"1.229554910","rc":[{"atb":[[4.1,0]],"id":55943164}],"con":true,"img":false}]}
{"op":"mcm","clk":"11450299440","pt":1717320258042,"mc":[{"id":"1.229554910","rc":[{"atb":[[4.3,2]],"id":55943164}],"con":true,"img":false}]}
{"op":"mcm","clk":"11450299464","pt":1717320258437,"mc":[{"id":"1.229554910","rc":[{"atb":[[4.2,0]],"id":55943164}],"con":true,"img":false}]}
{"op":"mcm","clk":"11450299705","pt":1717320262122,"mc":[{"id":"1.229554910","rc":[{"atb":[[4.3,0]],"id":55943164}],"con":true,"img":false}]}
{"op":"mcm","clk":"11450299709","pt":1717320262228,"mc":[{"id":"1.229554910","rc":[{"atb":[[4.1,2]],"id":55943164}],"con":true,"img":false}]}
{"op":"mcm","clk":"11450299727","pt":1717320262441,"mc":[{"id":"1.229554910","rc":[{"atb":[[4.2,6.08]],"id":55943164}],"con":true,"img":false}]}
{"op":"mcm","clk":"11450299839","pt":1717320263944,"mc":[{"id":"1.229554910","rc":[{"atb":[[6.4,3.99]],"id":54867443}],"con":true,"img":false}]}
{"op":"mcm","clk":"11450299882","pt":1717320264513,"mc":[{"id":"1.229554910","rc":[{"atb":[[6,0.21]],"id":54867443}],"con":true,"img":false}]}
{"op":"mcm","clk":"11450299888","pt":1717320264617,"mc":[{"id":"1.229554910","rc":[{"atb":[[6.2,4.63]],"id":54867443}],"con":true,"img":false}]}
{"op":"mcm","clk":"11450299894","pt":1717320264715,"mc":[{"id":"1.229554910","rc":[{"atb":[[1.74,15.32]],"id":69676139}],"con":true,"img":false}]}
{"op":"mcm","clk":"11450299897","pt":1717320264821,"mc":[{"id":"1.229554910","rc":[{"atb":[[1.75,61.85]],"id":69676139}],"con":true,"img":false}]}
{"op":"mcm","clk":"11450299908","pt":1717320265029,"mc":[{"id":"1.229554910","rc":[{"atb":[[6.2,2.63]],"id":54867443}],"con":true,"img":false}]}
{"op":"mcm","clk":"11450299916","pt":1717320265132,"mc":[{"id":"1.229554910","rc":[{"atb":[[6.6,2]],"id":54867443}],"con":true,"img":false}]}
{"op":"mcm","clk":"11450299958","pt":1717320265349,"mc":[{"id":"1.229554910","rc":[{"atb":[[4.1,0]],"id":55943164}],"con":true,"img":false}]}
{"op":"mcm","clk":"11450299967","pt":1717320265447,"mc":[{"id":"1.229554910","rc":[{"atb":[[4.3,2]],"id":55943164}],"con":true,"img":false}]}
{"op":"mcm","clk":"11450299986","pt":1717320265749,"mc":[{"id":"1.229554910","rc":[{"atb":[[4.2,0]],"id":55943164},{"atb":[[6.4,0]],"id":54867443}],"con":true,"img":false}]}
{"op":"mcm","clk":"11450300028","pt":1717320266427,"mc":[{"id":"1.229554910","rc":[{"atb":[[6.2,0]],"id":54867443}],"con":true,"img":false}]}
{"op":"mcm","clk":"11450300035","pt":1717320266535,"mc":[{"id":"1.229554910","rc":[{"atb":[[6,2.84]],"id":54867443}],"con":true,"img":false}]}
{"op":"mcm","clk":"11450300249","pt":1717320269412,"mc":[{"id":"1.229554910","rc":[{"atb":[[6.6,0]],"id":54867443}],"con":true,"img":false}]}
{"op":"mcm","clk":"11450300255","pt":1717320269515,"mc":[{"id":"1.229554910","rc":[{"atb":[[6.2,2]],"id":54867443}],"con":true,"img":false}]}
{"op":"mcm","clk":"11450300273","pt":1717320269822,"mc":[{"id":"1.229554910","rc":[{"atb":[[4.3,0]],"id":55943164}],"con":true,"img":false}]}
{"op":"mcm","clk":"11450300280","pt":1717320269928,"mc":[{"id":"1.229554910","rc":[{"atb":[[4.1,2]],"id":55943164}],"con":true,"img":false}]}
{"op":"mcm","clk":"11450300295","pt":1717320270244,"mc":[{"id":"1.229554910","rc":[{"atb":[[1.63,362.96]],"id":69676139},{"atb":[[4.2,6.08]],"id":55943164},{"atb":[[6.4,3.99]],"id":54867443}],"con":true,"img":false}]}
{"op":"mcm","clk":"11450300325","pt":1717320270756,"mc":[{"id":"1.229554910","rc":[{"atl":[[2.34,0]],"id":69676139}],"con":true,"img":false}]}
{"op":"mcm","clk":"11450300355","pt":1717320271225,"mc":[{"id":"1.229554910","rc":[{"atb":[[3.95,38.94]],"id":70003369}],"con":true,"img":false}]}
{"op":"mcm","clk":"11450300422","pt":1717320272425,"mc":[{"id":"1.229554910","rc":[{"atl":[[2.36,0]],"id":69676139}],"con":true,"img":false}]}
{"op":"mcm","clk":"11450300430","pt":1717320272532,"mc":[{"id":"1.229554910","rc":[{"spn":12.65,"spf":"NaN","id":69033911},{"atb":[[1.63,369.64]],"id":69676139},{"spn":2.13,"spf":"NaN","id":69676139},{"spn":7.6,"spf":"NaN","id":55943164},{"spn":14.2,"spf":"NaN","id":54867443}],"con":true,"img":false}]}
{"op":"mcm","clk":"11450300436","pt":1717320272642,"mc":[{"id":"1.229554910","rc":[{"atl":[[2.34,3]],"id":69676139}],"con":true,"img":false}]}
{"op":"mcm","clk":"11450300560","pt":1717320274246,"mc":[{"id":"1.229554910","rc":[{"atb":[[6.2,0]],"id":54867443}],"con":true,"img":false}]}
{"op":"mcm","clk":"11450300569","pt":1717320274346,"mc":[{"id":"1.229554910","rc":[{"atb":[[6.6,2]],"id":54867443}],"con":true,"img":false}]}
{"op":"mcm","clk":"11450300599","pt":1717320274871,"mc":[{"id":"1.229554910","rc":[{"atb":[[4.1,0]],"id":55943164}],"con":true,"img":false}]}
{"op":"mcm","clk":"11450300604","pt":1717320274965,"mc":[{"id":"1.229554910","rc":[{"atb":[[4.3,2]],"id":55943164}],"con":true,"img":false}]}
{"op":"mcm","clk":"11450300611","pt":1717320275072,"mc":[{"id":"1.229554910","rc":[{"atb":[[4.2,0]],"id":55943164},{"atb":[[6.4,0]],"id":54867443}],"con":true,"img":false}]}
{"op":"mcm","clk":"11450300898","pt":1717320279019,"mc":[{"id":"1.229554910","rc":[{"atl":[[2.34,0]],"id":69676139}],"con":true,"img":false}]}
{"op":"mcm","clk":"11450300901","pt":1717320279125,"mc":[{"id":"1.229554910","rc":[{"atb":[[6.6,0]],"id":54867443}],"con":true,"img":false}]}
{"op":"mcm","clk":"11450300905","pt":1717320279238,"mc":[{"id":"1.229554910","rc":[{"atl":[[2.32,3]],"id":69676139},{"atb":[[6.2,2]],"id":54867443}],"con":true,"img":false}]}
{"op":"mcm","clk":"11450300925","pt":1717320279559,"mc":[{"id":"1.229554910","rc":[{"atb":[[4.3,0]],"id":55943164},{"atb":[[6.4,3.99]],"id":54867443}],"con":true,"img":false}]}
{"op":"mcm","clk":"11450300929","pt":1717320279643,"mc":[{"id":"1.229554910","rc":[{"atb":[[4.1,2]],"id":55943164}],"con":true,"img":false}]}
{"op":"mcm","clk":"11450301002","pt":1717320280944,"mc":[{"id":"1.229554910","rc":[{"atb":[[4.2,6.08]],"id":55943164}],"con":true,"img":false}]}
{"op":"mcm","clk":"11450301192","pt":1717320283461,"mc":[{"id":"1.229554910","rc":[{"atb":[[1.01,1]],"id":69676139}],"con":true,"img":false}]}
{"op":"mcm","clk":"11450301235","pt":1717320284073,"mc":[{"id":"1.229554910","rc":[{"atb":[[6.2,0]],"id":54867443}],"con":true,"img":false}]}
{"op":"mcm","clk":"11450301241","pt":1717320284177,"mc":[{"id":"1.229554910","rc":[{"atb":[[6.6,2]],"id":54867443}],"con":true,"img":false}]}
{"op":"mcm","clk":"11450301266","pt":1717320284446,"mc":[{"id":"1.229554910","rc":[{"atb":[[4.1,0]],"id":55943164}],"con":true,"img":false}]}
{"op":"mcm","clk":"11450301273","pt":1717320284555,"mc":[{"id":"1.229554910","rc":[{"atb":[[4.3,2]],"id":55943164}],"con":true,"img":false}]}
{"op":"mcm","clk":"11450301292","pt":1717320284865,"mc":[{"id":"1.229554910","rc":[{"atb":[[4.2,0]],"id":55943164},{"atb":[[6.4,0]],"id":54867443}],"con":true,"img":false}]}
{"op":"mcm","clk":"11450301300","pt":1717320284961,"mc":[{"id":"1.229554910","rc":[{"atl":[[2.3,1.07]],"id":69676139}],"con":true,"img":false}]}
{"op":"mcm","clk":"11450301476","pt":1717320287971,"mc":[{"id":"1.229554910","rc":[{"atb":[[6.6,0]],"id":54867443}],"con":true,"img":false}]}
{"op":"mcm","clk":"11450301478","pt":1717320288072,"mc":[{"id":"1.229554910","rc":[{"atb":[[6.2,2]],"id":54867443}],"con":true,"img":false}]}
{"op":"mcm","clk":"11450301493","pt":1717320288283,"mc":[{"id":"1.229554910","rc":[{"atb":[[6.4,3.99]],"id":54867443}],"con":true,"img":false}]}
{"op":"mcm","clk":"11450301501","pt":1717320288350,"mc":[{"id":"1.229554910","rc":[{"atb":[[4.3,0]],"id":55943164}],"con":true,"img":false}]}
{"op":"mcm","clk":"11450301513","pt":1717320288459,"mc":[{"id":"1.229554910","rc":[{"atb":[[4.1,2]],"id":55943164}],"con":true,"img":false}]}
{"op":"mcm","clk":"11450301542","pt":1717320288965,"mc":[{"id":"1.229554910","rc":[{"atb":[[4.2,6.08]],"id":55943164}],"con":true,"img":false}]}
{"op":"mcm","clk":"11450301678","pt":1717320291040,"mc":[{"id":"1.229554910","rc":[{"atb":[[6.2,0]],"id":54867443}],"con":true,"img":false}]}
{"op":"mcm","clk":"11450301686","pt":1717320291141,"mc":[{"id":"1.229554910","rc":[{"atb":[[6.6,2]],"id":54867443}],"con":true,"img":false}]}
{"op":"mcm","clk":"11450301710","pt":1717320291458,"mc":[{"id":"1.229554910","rc":[{"atb":[[4.1,0]],"id":55943164}],"con":true,"img":false}]}
{"op":"mcm","clk":"11450301715","pt":1717320291562,"mc":[{"id":"1.229554910","rc":[{"atb":[[4.3,2]],"id":55943164}],"con":true,"img":false}]}
{"op":"mcm","clk":"11450301736","pt":1717320291974,"mc":[{"id":"1.229554910","rc":[{"atb":[[4.2,0]],"id":55943164},{"atb":[[6.4,0]],"id":54867443}],"con":true,"img":false}]}
{"op":"mcm","clk":"11450301851","pt":1717320294262,"mc":[{"id":"1.229554910","rc":[{"atl":[[12,1.11]],"id":55943164}],"con":true,"img":false}]}
{"op":"mcm","clk":"11450301854","pt":1717320294367,"mc":[{"id":"1.229554910","rc":[{"atb":[[6.6,0]],"id":54867443}],"con":true,"img":false}]}
{"op":"mcm","clk":"11450301863","pt":1717320294472,"mc":[{"id":"1.229554910","rc":[{"atb":[[6.2,2]],"id":54867443}],"con":true,"img":false}]}
{"op":"mcm","clk":"11450301877","pt":1717320294781,"mc":[{"id":"1.229554910","rc":[{"atb":[[4.3,0]],"id":55943164}],"con":true,"img":false}]}
{"op":"mcm","clk":"11450301886","pt":1717320294886,"mc":[{"id":"1.229554910","rc":[{"atb":[[4.1,2]],"id":55943164},{"atl":[[11.5,0.74]],"id":55943164}],"con":true,"img":false}]}
{"op":"mcm","clk":"11450301894","pt":1717320294940,"mc":[{"id":"1.229554910","rc":[{"atl":[[1000,1.51]],"id":55943164}],"con":true,"img":false}]}
{"op":"mcm","clk":"11450301939","pt":1717320295458,"mc":[{"id":"1.229554910","rc":[{"atb":[[4.2,6.08]],"id":55943164}],"con":true,"img":false}]}
{"op":"mcm","clk":"11450302096","pt":1717320298162,"mc":[{"id":"1.229554910","rc":[{"atb":[[4.1,0]],"id":55943164}],"con":true,"img":false}]}
{"op":"mcm","clk":"11450302098","pt":1717320298266,"mc":[{"id":"1.229554910","rc":[{"atb":[[4.3,2]],"id":55943164}],"con":true,"img":false}]}
{"op":"mcm","clk":"11450302112","pt":1717320298587,"mc":[{"id":"1.229554910","rc":[{"atb":[[4.2,0]],"id":55943164}],"con":true,"img":false}]}
{"op":"mcm","clk":"11450302195","pt":1717320300097,"mc":[{"id":"1.229554910","rc":[{"atb":[[4.3,0]],"id":55943164}],"con":true,"img":false}]}
{"op":"mcm","clk":"11450302201","pt":1717320300197,"mc":[{"id":"1.229554910","rc":[{"atl":[[2.3,0]],"id":69676139},{"atb":[[4.1,2]],"id":55943164}],"con":true,"img":false}]}
{"op":"mcm","clk":"11450302232","pt":1717320300668,"mc":[{"id":"1.229554910","rc":[{"atl":[[2.28,1.07]],"id":69676139},{"atb":[[4.2,6.08]],"id":55943164}],"con":true,"img":false}]}
{"op":"mcm","clk":"11450302307","pt":1717320302059,"mc":[{"id":"1.229554910","rc":[{"atl":[[2.32,0]],"id":69676139}],"con":true,"img":false}]}
{"op":"mcm","clk":"11450302323","pt":1717320302275,"mc":[{"id":"1.229554910","rc":[{"atl":[[2.26,3]],"id":69676139}],"con":true,"img":false}]}
{"op":"mcm","clk":"11450302348","pt":1717320302688,"mc":[{"id":"1.229554910","rc":[{"atb":[[6.4,3.99]],"id":54867443}],"con":true,"img":false}]}
{"op":"mcm","clk":"11450302520","pt":1717320304983,"mc":[{"id":"1.229554910","rc":[{"atb":[[6.2,0]],"id":54867443}],"con":true,"img":false}]}
{"op":"mcm","clk":"11450302527","pt":1717320305088,"mc":[{"id":"1.229554910","rc":[{"atb":[[6.6,2]],"id":54867443}],"con":true,"img":false}]}
{"op":"mcm","clk":"11450302552","pt":1717320305406,"mc":[{"id":"1.229554910","rc":[{"atb":[[4.1,0]],"id":55943164}],"con":true,"img":false}]}
{"op":"mcm","clk":"11450302565","pt":1717320305511,"mc":[{"id":"1.229554910","rc":[{"atb":[[4.3,2]],"id":55943164}],"con":true,"img":false}]}
{"op":"mcm","clk":"11450302601","pt":1717320305979,"mc":[{"id":"1.229554910","rc":[{"atb":[[3.45,0],[3.95,3.51],[3.7,0]],"id":70003369},{"atl":[[19.5,0],[29,0]],"id":70003369},{"atb":[[4.8,0],[5.8,0],[5.3,0]],"id":69033911},{"atl":[[48,0],[29,0]],"id":69033911},{"atb":[[1.73,0],[1.63,37.8],[1.68,0]],"id":69676139},{"atl":[[4,0],[5,0]],"id":69676139},{"atb":[[38,0],[48,0],[70,2.61]],"id":52272946},{"atl":[[630,0],[730,0]],"id":52272946},{"atb":[[3.4,0],[3.9,0],[3.65,0]],"id":55943164},{"atl":[[19,5.56],[28,0]],"id":55943164},{"atb":[[4.8,0],[5.8,0],[5.3,0]],"id":54867443},{"atl":[[48,0],[29,0]],"id":54867443}],"con":true,"img":false}]}
