{"op":"mcm","clk":"11536380644","pt":1719425245581,"mc":[{"id":"1.230178314","marketDefinition":{"bspMarket":true,"turnInPlayEnabled":false,"persistenceEnabled":false,"marketBaseRate":5.0,"eventId":"33376062","eventTypeId":"4339","numberOfWinners":1,"bettingType":"ODDS","marketType":"WIN","marketTime":"2024-06-27T14:51:00.000Z","suspendTime":"2024-06-27T14:51:00.000Z","bspReconciled":false,"complete":true,"inPlay":false,"crossMatching":false,"runnersVoidable":false,"numberOfActiveRunners":6,"betDelay":0,"status":"OPEN","runners":[{"status":"ACTIVE","sortPriority":1,"id":45375136,"name":"1. Canya Sunset"},{"status":"ACTIVE","sortPriority":2,"id":70466763,"name":"2. Takeiteasytiger"},{"status":"ACTIVE","sortPriority":3,"id":47030762,"name":"3. Dysert Rachael"},{"status":"ACTIVE","sortPriority":4,"id":46251065,"name":"4. Mustang Luca"},{"status":"ACTIVE","sortPriority":5,"id":69979804,"name":"5. Canal View Blue"},{"status":"ACTIVE","sortPriority":6,"id":63994056,"name":"6. Pyle Driver"}],"regulators":["MR_INT"],"venue":"Kinsley","countryCode":"GB","discountAllowed":false,"timezone":"Europe/London","openDate":"2024-06-27T13:36:00.000Z","version":5994643753,"name":"A5 462m","eventName":"Kinsley 27th Jun"},"rc":[],"con":true,"img":false}]}
{"op":"mcm","clk":"11536381016","pt":1719425248523,"mc":[{"id":"1.230178314","marketDefinition":{"bspMarket":true,"turnInPlayEnabled":false,"persistenceEnabled":false,"marketBaseRate":5.0,"eventId":"33376062","eventTypeId":"4339","numberOfWinners":1,"bettingType":"ODDS","marketType":"WIN","marketTime":"2024-06-27T14:51:00.000Z","suspendTime":"2024-06-27T14:51:00.000Z","bspReconciled":false,"complete":true,"inPlay":false,"crossMatching":false,"runnersVoidable":false,"numberOfActiveRunners":6,"betDelay":0,"status":"OPEN","runners":[{"status":"ACTIVE","sortPriority":1,"id":45375136,"name":"1. Canya Sunset"},{"status":"ACTIVE","sortPriority":2,"id":70466763,"name":"2. Takeiteasytiger"},{"status":"ACTIVE","sortPriority":3,"id":47030762,"name":"3. Dysert Rachael"},{"status":"ACTIVE","sortPriority":4,"id":46251065,"name":"4. Mustang Luca"},{"status":"ACTIVE","sortPriority":5,"id":69979804,"name":"5. Canal View Blue"},{"status":"ACTIVE","sortPriority":6,"id":63994056,"name":"6. Pyle Driver"}],"regulators":["MR_INT"],"venue":"Kinsley","countryCode":"GB","discountAllowed":true,"timezone":"Europe/London","openDate":"2024-06-27T13:36:00.000Z","version":5994643753,"name":"A5 462m","eventName":"Kinsley 27th Jun"},"rc":[],"con":true,"img":false}]}
{"op":"mcm","clk":"11536615212","pt":1719428245004,"mc":[{"id":"1.230178314","rc":[{"atb":[[1.03,15.09]],"id":47030762},{"atl":[[990,0.84]],"id":47030762},{"spn":495.51,"spf":"NaN","id":47030762},{"atb":[[1.02,22.63]],"id":70466763},{"atl":[[990,0.84]],"id":70466763},{"spn":495.51,"spf":"NaN","id":70466763},{"atb":[[1.01,45.27]],"id":45375136},{"atl":[[990,0.84]],"id":45375136},{"spn":495.5,"spf":"NaN","id":45375136},{"atb":[[1.01,45.27]],"id":63994056},{"atl":[[990,0.84]],"id":63994056},{"spn":495.5,"spf":"NaN","id":63994056},{"atb":[[1.02,22.63]],"id":69979804},{"atl":[[1000,0.84]],"id":69979804},{"spn":500.51,"spf":"NaN","id":69979804},{"atb":[[1.01,45.27]],"id":46251065},{"atl":[[990,0.84]],"id":46251065},{"spn":495.5,"spf":"NaN","id":46251065}],"con":true,"img":false}]}
{"op":"mcm","clk":"11536836991","pt":1719431852340,"mc":[{"id":"1.230178314","rc":[{"atb":[[1.03,15.09]],"id":47030762},{"atl":[[990,0.26]],"id":47030762},{"atb":[[1.02,22.64]],"id":70466763},{"atl":[[990,0.26]],"id":70466763},{"atb":[[1.01,45.28]],"id":45375136},{"atl":[[990,0.26]],"id":45375136},{"atb":[[1.01,45.28]],"id":63994056},{"atl":[[990,0.26]],"id":63994056},{"atb":[[1.02,22.64]],"id":69979804},{"atl":[[1000,0.26]],"id":69979804},{"atb":[[1.01,45.28]],"id":46251065},{"atl":[[990,0.26]],"id":46251065}],"con":true,"img":false}]}
{"op":"mcm","clk":"11537232246","pt":1719437882515,"mc":[{"id":"1.230178314","marketDefinition":{"bspMarket":true,"turnInPlayEnabled":false,"persistenceEnabled":false,"marketBaseRate":5.0,"eventId":"33376062","eventTypeId":"4339","numberOfWinners":1,"bettingType":"ODDS","marketType":"WIN","marketTime":"2024-06-27T14:51:00.000Z","suspendTime":"2024-06-27T14:51:00.000Z","bspReconciled":false,"complete":true,"inPlay":false,"crossMatching":false,"runnersVoidable":false,"numberOfActiveRunners":6,"betDelay":0,"status":"OPEN","runners":[{"status":"ACTIVE","sortPriority":1,"id":45375136,"name":"1. Canya Sunset"},{"status":"ACTIVE","sortPriority":2,"id":70466763,"name":"2. Takeiteasytiger"},{"status":"ACTIVE","sortPriority":3,"id":47030762,"name":"3. Dysert Rachael"},{"status":"ACTIVE","sortPriority":4,"id":46251065,"name":"4. Mustang Luca"},{"status":"ACTIVE","sortPriority":5,"id":69979804,"name":"5. Canal View Blue"},{"status":"ACTIVE","sortPriority":6,"id":63994056,"name":"6. Pyle Driver"}],"regulators":["MR_INT"],"venue":"Kinsley","countryCode":"GB","discountAllowed":true,"timezone":"Europe/London","openDate":"2024-06-27T13:36:00.000Z","version":5994643753,"name":"A5 462m","eventName":"Kinsley 27th Jun"},"rc":[{"atb":[[1.03,15.09]],"id":47030762},{"atl":[[990,0.26]],"id":47030762},{"spn":495.51,"spf":"NaN","id":47030762},{"atb":[[1.02,22.64]],"id":70466763},{"atl":[[990,0.26]],"id":70466763},{"spn":495.51,"spf":"NaN","id":70466763},{"atb":[[1.01,45.28]],"id":45375136},{"atl":[[990,0.26]],"id":45375136},{"spn":495.5,"spf":"NaN","id":45375136},{"atb":[[1.01,45.28]],"id":63994056},{"atl":[[990,0.26]],"id":63994056},{"spn":495.5,"spf":"NaN","id":63994056},{"atb":[[1.02,22.64]],"id":69979804},{"atl":[[1000,0.26]],"id":69979804},{"spn":500.51,"spf":"NaN","id":69979804},{"atb":[[1.01,45.28]],"id":46251065},{"atl":[[990,0.26]],"id":46251065},{"spn":495.5,"spf":"NaN","id":46251065}],"con":true,"img":true}]}
{"op":"mcm","clk":"11537573373","pt":1719443282536,"mc":[{"id":"1.230178314","marketDefinition":{"bspMarket":true,"turnInPlayEnabled":false,"persistenceEnabled":false,"marketBaseRate":5.0,"eventId":"33376062","eventTypeId":"4339","numberOfWinners":1,"bettingType":"ODDS","marketType":"WIN","marketTime":"2024-06-27T14:51:00.000Z","suspendTime":"2024-06-27T14:51:00.000Z","bspReconciled":false,"complete":true,"inPlay":false,"crossMatching":false,"runnersVoidable":false,"numberOfActiveRunners":6,"betDelay":0,"status":"OPEN","runners":[{"status":"ACTIVE","sortPriority":1,"id":45375136,"name":"1. Canya Sunset"},{"status":"ACTIVE","sortPriority":2,"id":70466763,"name":"2. Takeiteasytiger"},{"status":"ACTIVE","sortPriority":3,"id":47030762,"name":"3. Dysert Rachael"},{"status":"ACTIVE","sortPriority":4,"id":46251065,"name":"4. Mustang Luca"},{"status":"ACTIVE","sortPriority":5,"id":69979804,"name":"5. Canal View Blue"},{"status":"ACTIVE","sortPriority":6,"id":63994056,"name":"6. Pyle Driver"}],"regulators":["MR_INT"],"venue":"Kinsley","countryCode":"GB","discountAllowed":true,"timezone":"Europe/London","openDate":"2024-06-27T13:36:00.000Z","version":5994643753,"name":"A5 462m","eventName":"Kinsley 27th Jun"},"rc":[{"atb":[[1.03,15.09]],"id":47030762},{"atl":[[990,0.26]],"id":47030762},{"spn":495.51,"spf":"NaN","id":47030762},{"atb":[[1.02,22.64]],"id":70466763},{"atl":[[990,0.26]],"id":70466763},{"spn":495.51,"spf":"NaN","id":70466763},{"atb":[[1.01,45.29]],"id":45375136},{"atl":[[990,0.26]],"id":45375136},{"spn":495.5,"spf":"NaN","id":45375136},{"atb":[[1.01,45.29]],"id":63994056},{"atl":[[990,0.26]],"id":63994056},{"spn":495.5,"spf":"NaN","id":63994056},{"atb":[[1.02,22.64]],"id":69979804},{"atl":[[1000,0.26]],"id":69979804},{"spn":500.51,"spf":"NaN","id":69979804},{"atb":[[1.01,45.29]],"id":46251065},{"atl":[[990,0.26]],"id":46251065},{"spn":495.5,"spf":"NaN","id":46251065}],"con":true,"img":true}]}
{"op":"mcm","clk":"11537954933","pt":1719448682558,"mc":[{"id":"1.230178314","marketDefinition":{"bspMarket":true,"turnInPlayEnabled":false,"persistenceEnabled":false,"marketBaseRate":5.0,"eventId":"33376062","eventTypeId":"4339","numberOfWinners":1,"bettingType":"ODDS","marketType":"WIN","marketTime":"2024-06-27T14:51:00.000Z","suspendTime":"2024-06-27T14:51:00.000Z","bspReconciled":false,"complete":true,"inPlay":false,"crossMatching":false,"runnersVoidable":false,"numberOfActiveRunners":6,"betDelay":0,"status":"OPEN","runners":[{"status":"ACTIVE","sortPriority":1,"id":45375136,"name":"1. Canya Sunset"},{"status":"ACTIVE","sortPriority":2,"id":70466763,"name":"2. Takeiteasytiger"},{"status":"ACTIVE","sortPriority":3,"id":47030762,"name":"3. Dysert Rachael"},{"status":"ACTIVE","sortPriority":4,"id":46251065,"name":"4. Mustang Luca"},{"status":"ACTIVE","sortPriority":5,"id":69979804,"name":"5. Canal View Blue"},{"status":"ACTIVE","sortPriority":6,"id":63994056,"name":"6. Pyle Driver"}],"regulators":["MR_INT"],"venue":"Kinsley","countryCode":"GB","discountAllowed":true,"timezone":"Europe/London","openDate":"2024-06-27T13:36:00.000Z","version":5994643753,"name":"A5 462m","eventName":"Kinsley 27th Jun"},"rc":[{"atb":[[1.03,15.09]],"id":47030762},{"atl":[[990,0.26]],"id":47030762},{"spn":495.51,"spf":"NaN","id":47030762},{"atb":[[1.02,22.64]],"id":70466763},{"atl":[[990,0.26]],"id":70466763},{"spn":495.51,"spf":"NaN","id":70466763},{"atb":[[1.01,45.28]],"id":45375136},{"atl":[[990,0.26]],"id":45375136},{"spn":495.5,"spf":"NaN","id":45375136},{"atb":[[1.01,45.28]],"id":63994056},{"atl":[[990,0.26]],"id":63994056},{"spn":495.5,"spf":"NaN","id":63994056},{"atb":[[1.02,22.64]],"id":69979804},{"atl":[[1000,0.26]],"id":69979804},{"spn":500.51,"spf":"NaN","id":69979804},{"atb":[[1.01,45.28]],"id":46251065},{"atl":[[990,0.26]],"id":46251065},{"spn":495.5,"spf":"NaN","id":46251065}],"con":true,"img":true}]}
{"op":"mcm","clk":"11538170596","pt":1719454082541,"mc":[{"id":"1.230178314","marketDefinition":{"bspMarket":true,"turnInPlayEnabled":false,"persistenceEnabled":false,"marketBaseRate":5.0,"eventId":"33376062","eventTypeId":"4339","numberOfWinners":1,"bettingType":"ODDS","marketType":"WIN","marketTime":"2024-06-27T14:51:00.000Z","suspendTime":"2024-06-27T14:51:00.000Z","bspReconciled":false,"complete":true,"inPlay":false,"crossMatching":false,"runnersVoidable":false,"numberOfActiveRunners":6,"betDelay":0,"status":"OPEN","runners":[{"status":"ACTIVE","sortPriority":1,"id":45375136,"name":"1. Canya Sunset"},{"status":"ACTIVE","sortPriority":2,"id":70466763,"name":"2. Takeiteasytiger"},{"status":"ACTIVE","sortPriority":3,"id":47030762,"name":"3. Dysert Rachael"},{"status":"ACTIVE","sortPriority":4,"id":46251065,"name":"4. Mustang Luca"},{"status":"ACTIVE","sortPriority":5,"id":69979804,"name":"5. Canal View Blue"},{"status":"ACTIVE","sortPriority":6,"id":63994056,"name":"6. Pyle Driver"}],"regulators":["MR_INT"],"venue":"Kinsley","countryCode":"GB","discountAllowed":true,"timezone":"Europe/London","openDate":"2024-06-27T13:36:00.000Z","version":5994643753,"name":"A5 462m","eventName":"Kinsley 27th Jun"},"rc":[{"atb":[[1.03,15.09]],"id":47030762},{"atl":[[990,0.26]],"id":47030762},{"spn":495.51,"spf":"NaN","id":47030762},{"atb":[[1.02,22.64]],"id":70466763},{"atl":[[990,0.26]],"id":70466763},{"spn":495.51,"spf":"NaN","id":70466763},{"atb":[[1.01,45.29]],"id":45375136},{"atl":[[990,0.26]],"id":45375136},{"spn":495.5,"spf":"NaN","id":45375136},{"atb":[[1.01,45.29]],"id":63994056},{"atl":[[990,0.26]],"id":63994056},{"spn":495.5,"spf":"NaN","id":63994056},{"atb":[[1.02,22.64]],"id":69979804},{"atl":[[1000,0.26]],"id":69979804},{"spn":500.51,"spf":"NaN","id":69979804},{"atb":[[1.01,45.29]],"id":46251065},{"atl":[[990,0.26]],"id":46251065},{"spn":495.5,"spf":"NaN","id":46251065}],"con":true,"img":true}]}
{"op":"mcm","clk":"11538368254","pt":1719459482570,"mc":[{"id":"1.230178314","marketDefinition":{"bspMarket":true,"turnInPlayEnabled":false,"persistenceEnabled":false,"marketBaseRate":5.0,"eventId":"33376062","eventTypeId":"4339","numberOfWinners":1,"bettingType":"ODDS","marketType":"WIN","marketTime":"2024-06-27T14:51:00.000Z","suspendTime":"2024-06-27T14:51:00.000Z","bspReconciled":false,"complete":true,"inPlay":false,"crossMatching":false,"runnersVoidable":false,"numberOfActiveRunners":6,"betDelay":0,"status":"OPEN","runners":[{"status":"ACTIVE","sortPriority":1,"id":45375136,"name":"1. Canya Sunset"},{"status":"ACTIVE","sortPriority":2,"id":70466763,"name":"2. Takeiteasytiger"},{"status":"ACTIVE","sortPriority":3,"id":47030762,"name":"3. Dysert Rachael"},{"status":"ACTIVE","sortPriority":4,"id":46251065,"name":"4. Mustang Luca"},{"status":"ACTIVE","sortPriority":5,"id":69979804,"name":"5. Canal View Blue"},{"status":"ACTIVE","sortPriority":6,"id":63994056,"name":"6. Pyle Driver"}],"regulators":["MR_INT"],"venue":"Kinsley","countryCode":"GB","discountAllowed":true,"timezone":"Europe/London","openDate":"2024-06-27T13:36:00.000Z","version":5994643753,"name":"A5 462m","eventName":"Kinsley 27th Jun"},"rc":[{"atb":[[1.03,15.1]],"id":47030762},{"atl":[[990,0.26]],"id":47030762},{"spn":495.51,"spf":"NaN","id":47030762},{"atb":[[1.02,22.65]],"id":70466763},{"atl":[[990,0.26]],"id":70466763},{"spn":495.51,"spf":"NaN","id":70466763},{"atb":[[1.01,45.3]],"id":45375136},{"atl":[[990,0.26]],"id":45375136},{"spn":495.5,"spf":"NaN","id":45375136},{"atb":[[1.01,45.3]],"id":63994056},{"atl":[[990,0.26]],"id":63994056},{"spn":495.5,"spf":"NaN","id":63994056},{"atb":[[1.02,22.65]],"id":69979804},{"atl":[[1000,0.26]],"id":69979804},{"spn":500.51,"spf":"NaN","id":69979804},{"atb":[[1.01,45.3]],"id":46251065},{"atl":[[990,0.26]],"id":46251065},{"spn":495.5,"spf":"NaN","id":46251065}],"con":true,"img":true}]}
{"op":"mcm","clk":"11538595380","pt":1719464882540,"mc":[{"id":"1.230178314","marketDefinition":{"bspMarket":true,"turnInPlayEnabled":false,"persistenceEnabled":false,"marketBaseRate":5.0,"eventId":"33376062","eventTypeId":"4339","numberOfWinners":1,"bettingType":"ODDS","marketType":"WIN","marketTime":"2024-06-27T14:51:00.000Z","suspendTime":"2024-06-27T14:51:00.000Z","bspReconciled":false,"complete":true,"inPlay":false,"crossMatching":false,"runnersVoidable":false,"numberOfActiveRunners":6,"betDelay":0,"status":"OPEN","runners":[{"status":"ACTIVE","sortPriority":1,"id":45375136,"name":"1. Canya Sunset"},{"status":"ACTIVE","sortPriority":2,"id":70466763,"name":"2. Takeiteasytiger"},{"status":"ACTIVE","sortPriority":3,"id":47030762,"name":"3. Dysert Rachael"},{"status":"ACTIVE","sortPriority":4,"id":46251065,"name":"4. Mustang Luca"},{"status":"ACTIVE","sortPriority":5,"id":69979804,"name":"5. Canal View Blue"},{"status":"ACTIVE","sortPriority":6,"id":63994056,"name":"6. Pyle Driver"}],"regulators":["MR_INT"],"venue":"Kinsley","countryCode":"GB","discountAllowed":true,"timezone":"Europe/London","openDate":"2024-06-27T13:36:00.000Z","version":5994643753,"name":"A5 462m","eventName":"Kinsley 27th Jun"},"rc":[{"atb":[[1.03,15.09]],"id":47030762},{"atl":[[990,0.26]],"id":47030762},{"spn":495.51,"spf":"NaN","id":47030762},{"atb":[[1.02,22.64]],"id":70466763},{"atl":[[990,0.26]],"id":70466763},{"spn":495.51,"spf":"NaN","id":70466763},{"atb":[[1.01,45.29]],"id":45375136},{"atl":[[990,0.26]],"id":45375136},{"spn":495.5,"spf":"NaN","id":45375136},{"atb":[[1.01,45.29]],"id":63994056},{"atl":[[990,0.26]],"id":63994056},{"spn":495.5,"spf":"NaN","id":63994056},{"atb":[[1.02,22.64]],"id":69979804},{"atl":[[1000,0.26]],"id":69979804},{"spn":500.51,"spf":"NaN","id":69979804},{"atb":[[1.01,45.29]],"id":46251065},{"atl":[[990,0.26]],"id":46251065},{"spn":495.5,"spf":"NaN","id":46251065}],"con":true,"img":true}]}
{"op":"mcm","clk":"11538718929","pt":1719467478095,"mc":[{"id":"1.230178314","rc":[{"atb":[[1.03,15.09]],"id":47030762},{"atl":[[150,4]],"id":47030762},{"spn":75.51,"spf":"NaN","id":47030762},{"atb":[[1.02,22.64]],"id":70466763},{"atl":[[150,4]],"id":70466763},{"spn":75.51,"spf":"NaN","id":70466763},{"atb":[[1.01,45.29]],"id":45375136},{"atl":[[150,4]],"id":45375136},{"spn":75.5,"spf":"NaN","id":45375136},{"atb":[[1.01,45.29]],"id":63994056},{"atl":[[150,4]],"id":63994056},{"spn":75.5,"spf":"NaN","id":63994056},{"atb":[[1.02,22.64]],"id":69979804},{"atl":[[150,4]],"id":69979804},{"spn":75.51,"spf":"NaN","id":69979804},{"atb":[[1.01,45.29]],"id":46251065},{"atl":[[150,4]],"id":46251065},{"spn":75.5,"spf":"NaN","id":46251065}],"con":true,"img":false}]}
{"op":"mcm","clk":"11538748528","pt":1719468203108,"mc":[{"id":"1.230178314","rc":[{"atb":[[2.1,11.66]],"id":47030762},{"spn":76.05,"spf":"NaN","id":47030762},{"atb":[[2.1,9.86]],"id":70466763},{"spn":76.05,"spf":"NaN","id":70466763},{"atb":[[2.04,9.58]],"id":45375136},{"spn":76.02,"spf":"NaN","id":45375136},{"atb":[[2,8.54]],"id":63994056},{"spn":76.0,"spf":"NaN","id":63994056},{"atb":[[2.1,8.97]],"id":69979804},{"spn":76.05,"spf":"NaN","id":69979804},{"atb":[[2.06,9.68]],"id":46251065},{"spn":76.03,"spf":"NaN","id":46251065}],"con":true,"img":false}]}
{"op":"mcm","clk":"11538750896","pt":1719468251874,"mc":[{"id":"1.230178314","rc":[{"atb":[[2.08,3.16]],"id":46251065}],"con":true,"img":false}]}
{"op":"mcm","clk":"11538750908","pt":1719468252073,"mc":[{"id":"1.230178314","rc":[{"atb":[[2.12,3.16]],"id":47030762}],"con":true,"img":false}]}
{"op":"mcm","clk":"11538750927","pt":1719468252283,"mc":[{"id":"1.230178314","rc":[{"atb":[[2.12,3.16]],"id":70466763},{"atb":[[2.02,3.16]],"id":63994056}],"con":true,"img":false}]}
{"op":"mcm","clk":"11538750967","pt":1719468252850,"mc":[{"id":"1.230178314","rc":[{"atb":[[2.06,3.16]],"id":45375136}],"con":true,"img":false}]}
{"op":"mcm","clk":"11538751055","pt":1719468254486,"mc":[{"id":"1.230178314","rc":[{"atb":[[2.12,3.16]],"id":69979804}],"con":true,"img":false}]}
{"op":"mcm","clk":"11538752393","pt":1719468281754,"mc":[{"id":"1.230178314","marketDefinition":{"bspMarket":true,"turnInPlayEnabled":false,"persistenceEnabled":false,"marketBaseRate":5.0,"eventId":"33376062","eventTypeId":"4339","numberOfWinners":1,"bettingType":"ODDS","marketType":"WIN","marketTime":"2024-06-27T14:51:00.000Z","suspendTime":"2024-06-27T14:51:00.000Z","bspReconciled":false,"complete":true,"inPlay":false,"crossMatching":true,"runnersVoidable":false,"numberOfActiveRunners":6,"betDelay":0,"status":"OPEN","runners":[{"status":"ACTIVE","sortPriority":1,"id":45375136,"name":"1. Canya Sunset"},{"status":"ACTIVE","sortPriority":2,"id":70466763,"name":"2. Takeiteasytiger"},{"status":"ACTIVE","sortPriority":3,"id":47030762,"name":"3. Dysert Rachael"},{"status":"ACTIVE","sortPriority":4,"id":46251065,"name":"4. Mustang Luca"},{"status":"ACTIVE","sortPriority":5,"id":69979804,"name":"5. Canal View Blue"},{"status":"ACTIVE","sortPriority":6,"id":63994056,"name":"6. Pyle Driver"}],"regulators":["MR_INT"],"venue":"Kinsley","countryCode":"GB","discountAllowed":true,"timezone":"Europe/London","openDate":"2024-06-27T13:36:00.000Z","version":5994643753,"name":"A5 462m","eventName":"Kinsley 27th Jun"},"rc":[],"con":true,"img":false}]}
{"op":"mcm","clk":"11538752987","pt":1719468292505,"mc":[{"id":"1.230178314","rc":[{"spn":76.06,"spf":"NaN","id":47030762},{"spn":76.06,"spf":"NaN","id":70466763},{"atb":[[2.06,6.55]],"id":45375136},{"spn":76.03,"spf":"NaN","id":45375136},{"spn":76.01,"spf":"NaN","id":63994056},{"spn":76.06,"spf":"NaN","id":69979804},{"atb":[[2.08,6.55]],"id":46251065},{"spn":76.04,"spf":"NaN","id":46251065}],"con":true,"img":false}]}
{"op":"mcm","clk":"11538753026","pt":1719468293122,"mc":[{"id":"1.230178314","rc":[{"atb":[[2.12,6.55]],"id":47030762}],"con":true,"img":false}]}
{"op":"mcm","clk":"11538753041","pt":1719468293427,"mc":[{"id":"1.230178314","rc":[{"atb":[[2.02,6.55]],"id":63994056},{"atb":[[2.12,6.55]],"id":69979804}],"con":true,"img":false}]}
{"op":"mcm","clk":"11538753076","pt":1719468294197,"mc":[{"id":"1.230178314","rc":[{"atb":[[2.12,6.55]],"id":70466763}],"con":true,"img":false}]}
{"op":"mcm","clk":"11538753769","pt":1719468306437,"mc":[{"id":"1.230178314","rc":[{"spl":[[1.01,1]],"id":47030762}],"con":true,"img":false}]}
{"op":"mcm","clk":"11538851853","pt":1719470282544,"mc":[{"id":"1.230178314","marketDefinition":{"bspMarket":true,"turnInPlayEnabled":false,"persistenceEnabled":false,"marketBaseRate":5.0,"eventId":"33376062","eventTypeId":"4339","numberOfWinners":1,"bettingType":"ODDS","marketType":"WIN","marketTime":"2024-06-27T14:51:00.000Z","suspendTime":"2024-06-27T14:51:00.000Z","bspReconciled":false,"complete":true,"inPlay":false,"crossMatching":true,"runnersVoidable":false,"numberOfActiveRunners":6,"betDelay":0,"status":"OPEN","runners":[{"status":"ACTIVE","sortPriority":1,"id":45375136,"name":"1. Canya Sunset"},{"status":"ACTIVE","sortPriority":2,"id":70466763,"name":"2. Takeiteasytiger"},{"status":"ACTIVE","sortPriority":3,"id":47030762,"name":"3. Dysert Rachael"},{"status":"ACTIVE","sortPriority":4,"id":46251065,"name":"4. Mustang Luca"},{"status":"ACTIVE","sortPriority":5,"id":69979804,"name":"5. Canal View Blue"},{"status":"ACTIVE","sortPriority":6,"id":63994056,"name":"6. Pyle Driver"}],"regulators":["MR_INT"],"venue":"Kinsley","countryCode":"GB","discountAllowed":true,"timezone":"Europe/London","openDate":"2024-06-27T13:36:00.000Z","version":5994643753,"name":"A5 462m","eventName":"Kinsley 27th Jun"},"rc":[{"spl":[[1.01,1]],"id":47030762},{"atb":[[1.03,15.09],[2.12,6.55],[2.1,11.66]],"id":47030762},{"atl":[[150,4],[990,0.26]],"id":47030762},{"spn":2.12,"spf":1.0,"id":47030762},{"atb":[[1.02,22.64],[2.12,6.55],[2.1,9.86]],"id":70466763},{"atl":[[150,4],[990,0.26]],"id":70466763},{"spn":76.06,"spf":"NaN","id":70466763},{"atb":[[1.01,45.29],[2.06,6.55],[2.04,9.58]],"id":45375136},{"atl":[[150,4],[990,0.26]],"id":45375136},{"spn":76.03,"spf":"NaN","id":45375136},{"atb":[[2,8.54],[2.02,6.55],[1.01,45.29]],"id":63994056},{"atl":[[150,4],[990,0.26]],"id":63994056},{"spn":76.01,"spf":"NaN","id":63994056},{"atb":[[1.02,22.64],[2.12,6.55],[2.1,8.97]],"id":69979804},{"atl":[[150,4],[1000,0.26]],"id":69979804},{"spn":76.06,"spf":"NaN","id":69979804},{"atb":[[1.01,45.29],[2.06,9.68],[2.08,6.55]],"id":46251065},{"atl":[[150,4],[990,0.26]],"id":46251065},{"spn":76.04,"spf":"NaN","id":46251065}],"con":true,"img":true}]}
{"op":"mcm","clk":"11538905035","pt":1719471464985,"mc":[{"id":"1.230178314","rc":[{"atl":[[990,0.16]],"id":47030762},{"spn":2.12,"spf":1.0,"id":47030762},{"atl":[[990,0.16]],"id":70466763},{"atl":[[990,0.16]],"id":45375136},{"atl":[[990,0.16]],"id":63994056},{"atl":[[1000,0.16]],"id":69979804},{"atl":[[990,0.16]],"id":46251065}],"con":true,"img":false}]}
{"op":"mcm","clk":"11538940435","pt":1719472108650,"mc":[{"id":"1.230178314","rc":[{"atb":[[1.03,15.08],[2.12,6.54],[2.1,0]],"id":47030762},{"atl":[[990,0.16]],"id":47030762},{"atb":[[1.02,22.63],[2.12,6.54],[2.1,0]],"id":70466763},{"atl":[[990,0.16]],"id":70466763},{"atb":[[1.01,45.26],[2.06,6.54],[2.04,0]],"id":45375136},{"atl":[[990,0.16]],"id":45375136},{"atb":[[2,0],[2.02,6.54],[1.01,45.26]],"id":63994056},{"atl":[[990,0.16]],"id":63994056},{"atb":[[1.02,22.63],[2.12,6.54],[2.1,0]],"id":69979804},{"atl":[[1000,0.16]],"id":69979804},{"atb":[[1.01,45.26],[2.06,0],[2.08,6.54]],"id":46251065},{"atl":[[990,0.16]],"id":46251065}],"con":true,"img":false}]}
{"op":"mcm","clk":"11538940438","pt":1719472108750,"mc":[{"id":"1.230178314","rc":[{"atb":[[2.14,11.65]],"id":47030762},{"atb":[[2.14,9.86]],"id":70466763},{"atb":[[2.08,9.58]],"id":45375136},{"atb":[[2.04,8.54]],"id":63994056},{"atb":[[2.14,8.96]],"id":69979804},{"atb":[[2.1,9.67]],"id":46251065}],"con":true,"img":false}]}
{"op":"mcm","clk":"11538943706","pt":1719472160652,"mc":[{"id":"1.230178314","rc":[{"atb":[[2.08,3.38]],"id":46251065}],"con":true,"img":false}]}
{"op":"mcm","clk":"11538943800","pt":1719472162042,"mc":[{"id":"1.230178314","rc":[{"atb":[[2.12,3.38]],"id":47030762},{"atb":[[2.02,3.38]],"id":63994056}],"con":true,"img":false}]}
{"op":"mcm","clk":"11538943821","pt":1719472162349,"mc":[{"id":"1.230178314","rc":[{"atb":[[2.06,3.38]],"id":45375136}],"con":true,"img":false}]}
{"op":"mcm","clk":"11538943835","pt":1719472162713,"mc":[{"id":"1.230178314","rc":[{"atb":[[2.12,3.38]],"id":69979804}],"con":true,"img":false}]}
{"op":"mcm","clk":"11538943867","pt":1719472163120,"mc":[{"id":"1.230178314","rc":[{"atb":[[2.12,3.16]],"id":46251065}],"con":true,"img":false}]}
{"op":"mcm","clk":"11538943920","pt":1719472163843,"mc":[{"id":"1.230178314","rc":[{"atb":[[2.12,3.38]],"id":70466763}],"con":true,"img":false}]}
{"op":"mcm","clk":"11538943934","pt":1719472164043,"mc":[{"id":"1.230178314","rc":[{"atb":[[2.16,3.16]],"id":47030762}],"con":true,"img":false}]}
{"op":"mcm","clk":"11538943956","pt":1719472164353,"mc":[{"id":"1.230178314","rc":[{"atb":[[2.1,3.16]],"id":45375136}],"con":true,"img":false}]}
{"op":"mcm","clk":"11538943982","pt":1719472164720,"mc":[{"id":"1.230178314","rc":[{"atb":[[2.06,3.16]],"id":63994056}],"con":true,"img":false}]}
{"op":"mcm","clk":"11538944104","pt":1719472166917,"mc":[{"id":"1.230178314","rc":[{"atb":[[2.16,3.16]],"id":69979804}],"con":true,"img":false}]}
{"op":"mcm","clk":"11538944121","pt":1719472167129,"mc":[{"id":"1.230178314","rc":[{"atb":[[2.16,3.16]],"id":70466763}],"con":true,"img":false}]}
{"op":"mcm","clk":"11538944748","pt":1719472177553,"mc":[{"id":"1.230178314","rc":[{"spn":2.16,"spf":1.0,"id":47030762},{"spn":76.08,"spf":"NaN","id":70466763},{"atb":[[2.06,0]],"id":45375136},{"spn":76.05,"spf":"NaN","id":45375136},{"spn":76.03,"spf":"NaN","id":63994056},{"spn":76.08,"spf":"NaN","id":69979804},{"spn":76.06,"spf":"NaN","id":46251065}],"con":true,"img":false}]}
{"op":"mcm","clk":"11538944785","pt":1719472178163,"mc":[{"id":"1.230178314","rc":[{"atb":[[2.12,0]],"id":70466763}],"con":true,"img":false}]}
{"op":"mcm","clk":"11538944807","pt":1719472178469,"mc":[{"id":"1.230178314","rc":[{"atb":[[2.08,0]],"id":46251065}],"con":true,"img":false}]}
{"op":"mcm","clk":"11538944813","pt":1719472178573,"mc":[{"id":"1.230178314","rc":[{"atb":[[2.12,0]],"id":47030762}],"con":true,"img":false}]}
{"op":"mcm","clk":"11538944831","pt":1719472178831,"mc":[{"id":"1.230178314","rc":[{"atb":[[2.02,0]],"id":63994056}],"con":true,"img":false}]}
{"op":"mcm","clk":"11538944859","pt":1719472179341,"mc":[{"id":"1.230178314","rc":[{"atb":[[2.12,0]],"id":69979804}],"con":true,"img":false}]}
{"op":"mcm","clk":"11538945880","pt":1719472196055,"mc":[{"id":"1.230178314","rc":[{"atb":[[2.1,6.54]],"id":45375136}],"con":true,"img":false}]}
{"op":"mcm","clk":"11538945964","pt":1719472197185,"mc":[{"id":"1.230178314","rc":[{"atb":[[2.16,6.54]],"id":70466763}],"con":true,"img":false}]}
{"op":"mcm","clk":"11538945984","pt":1719472197492,"mc":[{"id":"1.230178314","rc":[{"atb":[[2.12,6.54]],"id":46251065}],"con":true,"img":false}]}
{"op":"mcm","clk":"11538946005","pt":1719472197800,"mc":[{"id":"1.230178314","rc":[{"atb":[[2.16,6.54]],"id":47030762}],"con":true,"img":false}]}
{"op":"mcm","clk":"11538946018","pt":1719472198059,"mc":[{"id":"1.230178314","rc":[{"atb":[[2.16,6.54]],"id":69979804}],"con":true,"img":false}]}
{"op":"mcm","clk":"11538946048","pt":1719472198571,"mc":[{"id":"1.230178314","rc":[{"atb":[[2.06,6.54]],"id":63994056}],"con":true,"img":false}]}
{"op":"mcm","clk":"11539122527","pt":1719475682546,"mc":[{"id":"1.230178314","marketDefinition":{"bspMarket":true,"turnInPlayEnabled":false,"persistenceEnabled":false,"marketBaseRate":5.0,"eventId":"33376062","eventTypeId":"4339","numberOfWinners":1,"bettingType":"ODDS","marketType":"WIN","marketTime":"2024-06-27T14:51:00.000Z","suspendTime":"2024-06-27T14:51:00.000Z","bspReconciled":false,"complete":true,"inPlay":false,"crossMatching":true,"runnersVoidable":false,"numberOfActiveRunners":6,"betDelay":0,"status":"OPEN","runners":[{"status":"ACTIVE","sortPriority":1,"id":45375136,"name":"1. Canya Sunset"},{"status":"ACTIVE","sortPriority":2,"id":70466763,"name":"2. Takeiteasytiger"},{"status":"ACTIVE","sortPriority":3,"id":47030762,"name":"3. Dysert Rachael"},{"status":"ACTIVE","sortPriority":4,"id":46251065,"name":"4. Mustang Luca"},{"status":"ACTIVE","sortPriority":5,"id":69979804,"name":"5. Canal View Blue"},{"status":"ACTIVE","sortPriority":6,"id":63994056,"name":"6. Pyle Driver"}],"regulators":["MR_INT"],"venue":"Kinsley","countryCode":"GB","discountAllowed":true,"timezone":"Europe/London","openDate":"2024-06-27T13:36:00.000Z","version":5994643753,"name":"A5 462m","eventName":"Kinsley 27th Jun"},"rc":[{"spl":[[1.01,1]],"id":47030762},{"atb":[[1.03,15.09],[2.16,6.55],[2.14,11.65]],"id":47030762},{"atl":[[150,4],[990,0.16]],"id":47030762},{"spn":2.16,"spf":1.0,"id":47030762},{"atb":[[1.02,22.64],[2.16,6.55],[2.14,9.86]],"id":70466763},{"atl":[[150,4],[990,0.16]],"id":70466763},{"spn":76.08,"spf":"NaN","id":70466763},{"atb":[[1.01,45.28],[2.1,6.55],[2.08,9.58]],"id":45375136},{"atl":[[150,4],[990,0.16]],"id":45375136},{"spn":76.05,"spf":"NaN","id":45375136},{"atb":[[1.01,45.28],[2.06,6.55],[2.04,8.54]],"id":63994056},{"atl":[[150,4],[990,0.16]],"id":63994056},{"spn":76.03,"spf":"NaN","id":63994056},{"atb":[[1.02,22.64],[2.16,6.55],[2.14,8.96]],"id":69979804},{"atl":[[150,4],[1000,0.16]],"id":69979804},{"spn":76.08,"spf":"NaN","id":69979804},{"atb":[[1.01,45.28],[2.12,6.55],[2.1,9.67]],"id":46251065},{"atl":[[150,4],[990,0.16]],"id":46251065},{"spn":76.06,"spf":"NaN","id":46251065}],"con":true,"img":true}]}
{"op":"mcm","clk":"11539127748","pt":1719475708786,"mc":[{"id":"1.230178314","rc":[{"atb":[[1.03,15.09],[2.16,6.55],[2.14,0]],"id":47030762},{"atb":[[1.02,22.64],[2.16,6.55],[2.14,0]],"id":70466763},{"atb":[[1.01,45.28],[2.1,6.55],[2.08,0]],"id":45375136},{"atb":[[1.01,45.28],[2.06,6.55],[2.04,0]],"id":63994056},{"atb":[[1.02,22.64],[2.16,6.55],[2.14,0]],"id":69979804},{"atb":[[1.01,45.28],[2.12,6.55],[2.1,0]],"id":46251065}],"con":true,"img":false}]}
{"op":"mcm","clk":"11539127755","pt":1719475708888,"mc":[{"id":"1.230178314","rc":[{"atb":[[2.18,11.65]],"id":47030762},{"atb":[[2.18,9.86]],"id":70466763},{"atb":[[2.12,9.58]],"id":45375136},{"atb":[[2.08,8.54]],"id":63994056},{"atb":[[2.18,8.96]],"id":69979804},{"atb":[[2.14,9.67]],"id":46251065}],"con":true,"img":false}]}
{"op":"mcm","clk":"11539128028","pt":1719475713123,"mc":[{"id":"1.230178314","rc":[{"atb":[[2.06,3.38]],"id":63994056}],"con":true,"img":false}]}
{"op":"mcm","clk":"11539128040","pt":1719475713281,"mc":[{"id":"1.230178314","rc":[{"atb":[[2.12,3.38]],"id":46251065}],"con":true,"img":false}]}
{"op":"mcm","clk":"11539128212","pt":1719475715081,"mc":[{"id":"1.230178314","rc":[{"atb":[[2.16,3.38]],"id":70466763}],"con":true,"img":false}]}
{"op":"mcm","clk":"11539128220","pt":1719475715188,"mc":[{"id":"1.230178314","rc":[{"atb":[[2.1,3.16]],"id":63994056}],"con":true,"img":false}]}
{"op":"mcm","clk":"11539128234","pt":1719475715390,"mc":[{"id":"1.230178314","rc":[{"atb":[[2.1,3.38]],"id":45375136}],"con":true,"img":false}]}
{"op":"mcm","clk":"11539128273","pt":1719475715597,"mc":[{"id":"1.230178314","rc":[{"atb":[[2.2,3.16]],"id":70466763}],"con":true,"img":false}]}
{"op":"mcm","clk":"11539128329","pt":1719475716009,"mc":[{"id":"1.230178314","rc":[{"atb":[[2.16,3.16]],"id":46251065}],"con":true,"img":false}]}
{"op":"mcm","clk":"11539128351","pt":1719475716516,"mc":[{"id":"1.230178314","rc":[{"atb":[[2.16,3.38]],"id":47030762}],"con":true,"img":false}]}
{"op":"mcm","clk":"11539128408","pt":1719475717543,"mc":[{"id":"1.230178314","rc":[{"atb":[[2.2,3.16]],"id":47030762}],"con":true,"img":false}]}
{"op":"mcm","clk":"11539128559","pt":1719475720016,"mc":[{"id":"1.230178314","rc":[{"atb":[[2.16,3.38]],"id":69979804}],"con":true,"img":false}]}
{"op":"mcm","clk":"11539128584","pt":1719475720521,"mc":[{"id":"1.230178314","rc":[{"atb":[[2.14,3.16]],"id":45375136}],"con":true,"img":false}]}
{"op":"mcm","clk":"11539128667","pt":1719475721924,"mc":[{"id":"1.230178314","rc":[{"atb":[[2.2,3.16]],"id":69979804}],"con":true,"img":false}]}
{"op":"mcm","clk":"11539134610","pt":1719475815532,"mc":[{"id":"1.230178314","rc":[{"spn":2.2,"spf":1.0,"id":47030762},{"spn":76.1,"spf":"NaN","id":70466763},{"spn":76.07,"spf":"NaN","id":45375136},{"spn":76.05,"spf":"NaN","id":63994056},{"atb":[[2.16,0]],"id":69979804},{"spn":76.1,"spf":"NaN","id":69979804},{"spn":76.08,"spf":"NaN","id":46251065}],"con":true,"img":false}]}
{"op":"mcm","clk":"11539134620","pt":1719475815687,"mc":[{"id":"1.230178314","rc":[{"atb":[[2.12,0]],"id":46251065}],"con":true,"img":false}]}
{"op":"mcm","clk":"11539134632","pt":1719475815944,"mc":[{"id":"1.230178314","rc":[{"atb":[[2.1,0]],"id":45375136}],"con":true,"img":false}]}
{"op":"mcm","clk":"11539134636","pt":1719475815998,"mc":[{"id":"1.230178314","rc":[{"atb":[[2.06,0]],"id":63994056}],"con":true,"img":false}]}
{"op":"mcm","clk":"11539134647","pt":1719475816203,"mc":[{"id":"1.230178314","rc":[{"atb":[[2.16,0]],"id":47030762}],"con":true,"img":false}]}
{"op":"mcm","clk":"11539134702","pt":1719475817127,"mc":[{"id":"1.230178314","rc":[{"atb":[[2.16,0]],"id":70466763}],"con":true,"img":false}]}
{"op":"mcm","clk":"11539134743","pt":1719475817798,"mc":[{"id":"1.230178314","rc":[{"atb":[[2.16,6.55]],"id":46251065}],"con":true,"img":false}]}
{"op":"mcm","clk":"11539134764","pt":1719475818108,"mc":[{"id":"1.230178314","rc":[{"atb":[[2.1,6.55]],"id":63994056}],"con":true,"img":false}]}
{"op":"mcm","clk":"11539134868","pt":1719475819706,"mc":[{"id":"1.230178314","rc":[{"atb":[[2.2,6.55]],"id":47030762}],"con":true,"img":false}]}
{"op":"mcm","clk":"11539134911","pt":1719475820426,"mc":[{"id":"1.230178314","rc":[{"atb":[[2.2,6.55]],"id":70466763},{"atb":[[2.2,6.55]],"id":69979804}],"con":true,"img":false}]}
{"op":"mcm","clk":"11539134995","pt":1719475821398,"mc":[{"id":"1.230178314","rc":[{"atb":[[2.14,6.55]],"id":45375136}],"con":true,"img":false}]}
{"op":"mcm","clk":"11539277112","pt":1719478289227,"mc":[{"id":"1.230178314","rc":[{"atb":[[2.22,2]],"id":70466763},{"spn":76.11,"spf":"NaN","id":70466763}],"con":true,"img":false}]}
{"op":"mcm","clk":"11539341236","pt":1719479307719,"mc":[{"id":"1.230178314","rc":[{"atb":[[1.03,15.09],[2.18,0],[2.2,6.54]],"id":47030762},{"atb":[[1.02,22.63],[2.18,0],[2.2,6.54]],"id":70466763},{"atb":[[1.01,45.27],[2.12,0],[2.14,6.54]],"id":45375136},{"atb":[[1.01,45.27],[2.1,6.54],[2.08,0]],"id":63994056},{"atb":[[1.02,22.63],[2.18,0],[2.2,6.54]],"id":69979804},{"atb":[[1.01,45.27],[2.16,6.54],[2.14,0]],"id":46251065}],"con":true,"img":false}]}
{"op":"mcm","clk":"11539341245","pt":1719479307824,"mc":[{"id":"1.230178314","rc":[{"atb":[[2.22,11.65]],"id":47030762},{"atb":[[2.22,11.86]],"id":70466763},{"atb":[[2.16,9.58]],"id":45375136},{"atb":[[2.12,8.54]],"id":63994056},{"atb":[[2.22,8.96]],"id":69979804},{"atb":[[2.18,9.67]],"id":46251065}],"con":true,"img":false}]}
{"op":"mcm","clk":"11539347223","pt":1719479403488,"mc":[{"id":"1.230178314","rc":[{"spn":2.22,"spf":1.0,"id":47030762},{"spn":76.08,"spf":"NaN","id":45375136},{"spn":76.06,"spf":"NaN","id":63994056},{"spn":76.11,"spf":"NaN","id":69979804},{"atb":[[2.16,3.38]],"id":46251065},{"spn":76.09,"spf":"NaN","id":46251065}],"con":true,"img":false}]}
{"op":"mcm","clk":"11539347270","pt":1719479404207,"mc":[{"id":"1.230178314","rc":[{"atb":[[2.2,3.38]],"id":47030762}],"con":true,"img":false}]}
{"op":"mcm","clk":"11539347287","pt":1719479404374,"mc":[{"id":"1.230178314","rc":[{"atb":[[2.1,3.38]],"id":63994056}],"con":true,"img":false}]}
{"op":"mcm","clk":"11539347446","pt":1719479406693,"mc":[{"id":"1.230178314","rc":[{"atb":[[2.2,3.38]],"id":69979804}],"con":true,"img":false}]}
{"op":"mcm","clk":"11539347543","pt":1719479407980,"mc":[{"id":"1.230178314","rc":[{"atb":[[2.14,3.38]],"id":45375136}],"con":true,"img":false}]}
{"op":"mcm","clk":"11539347609","pt":1719479409017,"mc":[{"id":"1.230178314","rc":[{"atb":[[2.2,3.38]],"id":70466763}],"con":true,"img":false}]}
{"op":"mcm","clk":"11539350438","pt":1719479453313,"mc":[{"id":"1.230178314","rc":[{"atb":[[2.14,0]],"id":45375136}],"con":true,"img":false}]}
{"op":"mcm","clk":"11539350453","pt":1719479453522,"mc":[{"id":"1.230178314","rc":[{"atb":[[2.2,0]],"id":70466763}],"con":true,"img":false}]}
{"op":"mcm","clk":"11539350464","pt":1719479453724,"mc":[{"id":"1.230178314","rc":[{"atb":[[2.2,0]],"id":69979804}],"con":true,"img":false}]}
{"op":"mcm","clk":"11539350473","pt":1719479453827,"mc":[{"id":"1.230178314","rc":[{"atb":[[2.1,0]],"id":63994056}],"con":true,"img":false}]}
{"op":"mcm","clk":"11539350496","pt":1719479454131,"mc":[{"id":"1.230178314","rc":[{"atb":[[2.16,0]],"id":46251065}],"con":true,"img":false}]}
{"op":"mcm","clk":"11539350525","pt":1719479454541,"mc":[{"id":"1.230178314","rc":[{"atb":[[2.2,0]],"id":47030762}],"con":true,"img":false}]}
{"op":"mcm","clk":"11539368018","pt":1719479711287,"mc":[{"id":"1.230178314","rc":[{"atb":[[2.14,3.16]],"id":63994056},{"spn":76.07,"spf":"NaN","id":63994056}],"con":true,"img":false}]}
{"op":"mcm","clk":"11539368163","pt":1719479713091,"mc":[{"id":"1.230178314","rc":[{"atb":[[2.24,3.16]],"id":47030762}],"con":true,"img":false}]}
{"op":"mcm","clk":"11539368197","pt":1719479713504,"mc":[{"id":"1.230178314","rc":[{"atb":[[2.18,3.16]],"id":45375136}],"con":true,"img":false}]}
{"op":"mcm","clk":"11539368207","pt":1719479713604,"mc":[{"id":"1.230178314","rc":[{"atb":[[2.24,3.16]],"id":69979804}],"con":true,"img":false}]}
{"op":"mcm","clk":"11539368223","pt":1719479713809,"mc":[{"id":"1.230178314","rc":[{"atb":[[2.2,3.16]],"id":46251065}],"con":true,"img":false}]}
{"op":"mcm","clk":"11539368252","pt":1719479714122,"mc":[{"id":"1.230178314","rc":[{"atb":[[2.24,3.16]],"id":70466763}],"con":true,"img":false}]}
{"op":"mcm","clk":"11539369770","pt":1719479733017,"mc":[{"id":"1.230178314","rc":[{"atb":[[2.18,6.54]],"id":45375136}],"con":true,"img":false}]}
{"op":"mcm","clk":"11539369785","pt":1719479733222,"mc":[{"id":"1.230178314","rc":[{"atb":[[2.24,6.54]],"id":70466763}],"con":true,"img":false}]}
{"op":"mcm","clk":"11539369794","pt":1719479733327,"mc":[{"id":"1.230178314","rc":[{"atb":[[2.24,6.54]],"id":69979804}],"con":true,"img":false}]}
{"op":"mcm","clk":"11539369814","pt":1719479733532,"mc":[{"id":"1.230178314","rc":[{"atb":[[2.2,6.54]],"id":46251065}],"con":true,"img":false}]}
{"op":"mcm","clk":"11539369822","pt":1719479733634,"mc":[{"id":"1.230178314","rc":[{"atb":[[2.24,6.54]],"id":47030762}],"con":true,"img":false}]}
{"op":"mcm","clk":"11539369852","pt":1719479734147,"mc":[{"id":"1.230178314","rc":[{"atb":[[2.14,6.54]],"id":63994056}],"con":true,"img":false}]}
{"op":"mcm","clk":"11539438503","pt":1719481082545,"mc":[{"id":"1.230178314","marketDefinition":{"bspMarket":true,"turnInPlayEnabled":false,"persistenceEnabled":false,"marketBaseRate":5.0,"eventId":"33376062","eventTypeId":"4339","numberOfWinners":1,"bettingType":"ODDS","marketType":"WIN","marketTime":"2024-06-27T14:51:00.000Z","suspendTime":"2024-06-27T14:51:00.000Z","bspReconciled":false,"complete":true,"inPlay":false,"crossMatching":true,"runnersVoidable":false,"numberOfActiveRunners":6,"betDelay":0,"status":"OPEN","runners":[{"status":"ACTIVE","sortPriority":1,"id":45375136,"name":"1. Canya Sunset"},{"status":"ACTIVE","sortPriority":2,"id":70466763,"name":"2. Takeiteasytiger"},{"status":"ACTIVE","sortPriority":3,"id":47030762,"name":"3. Dysert Rachael"},{"status":"ACTIVE","sortPriority":4,"id":46251065,"name":"4. Mustang Luca"},{"status":"ACTIVE","sortPriority":5,"id":69979804,"name":"5. Canal View Blue"},{"status":"ACTIVE","sortPriority":6,"id":63994056,"name":"6. Pyle Driver"}],"regulators":["MR_INT"],"venue":"Kinsley","countryCode":"GB","discountAllowed":true,"timezone":"Europe/London","openDate":"2024-06-27T13:36:00.000Z","version":5994643753,"name":"A5 462m","eventName":"Kinsley 27th Jun"},"rc":[{"spl":[[1.01,1]],"id":47030762},{"atb":[[2.24,6.54],[1.03,15.09],[2.22,11.65]],"id":47030762},{"atl":[[150,4],[990,0.16]],"id":47030762},{"spn":2.24,"spf":1.0,"id":47030762},{"atb":[[2.24,6.54],[2.22,11.86],[1.02,22.63]],"id":70466763},{"atl":[[150,4],[990,0.16]],"id":70466763},{"spn":76.12,"spf":"NaN","id":70466763},{"atb":[[1.01,45.27],[2.18,6.54],[2.16,9.58]],"id":45375136},{"atl":[[150,4],[990,0.16]],"id":45375136},{"spn":76.09,"spf":"NaN","id":45375136},{"atb":[[1.01,45.27],[2.12,8.54],[2.14,6.54]],"id":63994056},{"atl":[[150,4],[990,0.16]],"id":63994056},{"spn":76.07,"spf":"NaN","id":63994056},{"atb":[[2.24,6.54],[2.22,8.96],[1.02,22.63]],"id":69979804},{"atl":[[150,4],[1000,0.16]],"id":69979804},{"spn":76.12,"spf":"NaN","id":69979804},{"atb":[[1.01,45.27],[2.18,9.67],[2.2,6.54]],"id":46251065},{"atl":[[150,4],[990,0.16]],"id":46251065},{"spn":76.1,"spf":"NaN","id":46251065}],"con":true,"img":true}]}
{"op":"mcm","clk":"11539484287","pt":1719481871336,"mc":[{"id":"1.230178314","rc":[{"spn":2.24,"spf":1.0,"id":47030762},{"spn":76.12,"spf":"NaN","id":70466763},{"atl":[[36,8],[60,12]],"id":45375136},{"spn":19.09,"spf":"NaN","id":45375136},{"atl":[[42,12],[25,8]],"id":63994056},{"spn":13.57,"spf":"NaN","id":63994056},{"atl":[[40,12],[23,8]],"id":69979804},{"spn":12.62,"spf":"NaN","id":69979804},{"atl":[[48,12],[28,8]],"id":46251065},{"spn":15.1,"spf":"NaN","id":46251065}],"con":true,"img":false}]}
{"op":"mcm","clk":"11539545216","pt":1719482907383,"mc":[{"id":"1.230178314","rc":[{"atb":[[2.24,6.54],[1.03,15.08],[2.22,0]],"id":47030762},{"atb":[[2.24,6.54],[2.22,2],[1.02,22.63]],"id":70466763},{"atb":[[1.01,45.26],[2.18,6.54],[2.16,0]],"id":45375136},{"atb":[[1.01,45.26],[2.12,0],[2.14,6.54]],"id":63994056},{"atb":[[2.24,6.54],[2.22,0],[1.02,22.63]],"id":69979804},{"atb":[[1.01,45.26],[2.18,0],[2.2,6.54]],"id":46251065}],"con":true,"img":false}]}
{"op":"mcm","clk":"11539545235","pt":1719482907481,"mc":[{"id":"1.230178314","rc":[{"atb":[[2.26,11.65]],"id":47030762},{"atb":[[2.26,9.86]],"id":70466763},{"atb":[[2.2,9.58]],"id":45375136},{"atb":[[2.16,8.54]],"id":63994056},{"atb":[[2.26,8.96]],"id":69979804},{"atb":[[2.22,9.67]],"id":46251065}],"con":true,"img":false}]}
{"op":"mcm","clk":"11539549472","pt":1719482973459,"mc":[{"id":"1.230178314","rc":[{"spn":2.26,"spf":1.0,"id":47030762},{"spn":76.13,"spf":"NaN","id":70466763},{"spn":19.1,"spf":"NaN","id":45375136},{"spn":13.58,"spf":"NaN","id":63994056},{"spn":12.63,"spf":"NaN","id":69979804},{"atb":[[2.2,3.16]],"id":46251065},{"spn":15.11,"spf":"NaN","id":46251065}],"con":true,"img":false}]}
{"op":"mcm","clk":"11539549482","pt":1719482973561,"mc":[{"id":"1.230178314","rc":[{"atb":[[2.18,3.16]],"id":45375136}],"con":true,"img":false}]}
{"op":"mcm","clk":"11539549495","pt":1719482973715,"mc":[{"id":"1.230178314","rc":[{"atb":[[2.24,3.16]],"id":70466763}],"con":true,"img":false}]}
{"op":"mcm","clk":"11539549499","pt":1719482973923,"mc":[{"id":"1.230178314","rc":[{"atb":[[2.24,3.16]],"id":47030762}],"con":true,"img":false}]}
{"op":"mcm","clk":"11539549514","pt":1719482974236,"mc":[{"id":"1.230178314","rc":[{"atb":[[2.24,3.16]],"id":69979804}],"con":true,"img":false}]}
{"op":"mcm","clk":"11539549596","pt":1719482975634,"mc":[{"id":"1.230178314","rc":[{"atb":[[2.14,3.16]],"id":63994056}],"con":true,"img":false}]}
{"op":"mcm","clk":"11539549634","pt":1719482976149,"mc":[{"id":"1.230178314","rc":[{"atb":[[2.24,3.38]],"id":46251065}],"con":true,"img":false}]}
{"op":"mcm","clk":"11539549640","pt":1719482976251,"mc":[{"id":"1.230178314","rc":[{"atb":[[2.28,3.38]],"id":70466763}],"con":true,"img":false}]}
{"op":"mcm","clk":"11539549761","pt":1719482977545,"mc":[{"id":"1.230178314","rc":[{"atb":[[2.22,3.38]],"id":45375136}],"con":true,"img":false}]}
{"op":"mcm","clk":"11539549836","pt":1719482978276,"mc":[{"id":"1.230178314","rc":[{"atb":[[2.28,3.38]],"id":47030762}],"con":true,"img":false}]}
{"op":"mcm","clk":"11539549932","pt":1719482979261,"mc":[{"id":"1.230178314","rc":[{"atb":[[2.18,3.38]],"id":63994056}],"con":true,"img":false}]}
{"op":"mcm","clk":"11539549988","pt":1719482980445,"mc":[{"id":"1.230178314","rc":[{"atb":[[2.28,3.38]],"id":69979804}],"con":true,"img":false}]}
{"op":"mcm","clk":"11539553424","pt":1719483029623,"mc":[{"id":"1.230178314","rc":[{"atb":[[2.24,0]],"id":47030762},{"atb":[[2.24,0]],"id":70466763},{"atb":[[2.18,0]],"id":45375136},{"atb":[[2.14,0]],"id":63994056},{"atb":[[2.24,0]],"id":69979804},{"atb":[[2.2,0]],"id":46251065}],"con":true,"img":false}]}
{"op":"mcm","clk":"11539573511","pt":1719483328665,"mc":[{"id":"1.230178314","rc":[{"spn":2.28,"spf":1.0,"id":47030762},{"atb":[[2.28,6.54]],"id":70466763},{"spn":76.14,"spf":"NaN","id":70466763},{"atb":[[2.22,6.54]],"id":45375136},{"spn":19.11,"spf":"NaN","id":45375136},{"spn":13.59,"spf":"NaN","id":63994056},{"spn":12.64,"spf":"NaN","id":69979804},{"spn":15.12,"spf":"NaN","id":46251065}],"con":true,"img":false}]}
{"op":"mcm","clk":"11539573528","pt":1719483328873,"mc":[{"id":"1.230178314","rc":[{"atb":[[2.28,6.54]],"id":47030762}],"con":true,"img":false}]}
{"op":"mcm","clk":"11539573546","pt":1719483329074,"mc":[{"id":"1.230178314","rc":[{"atb":[[2.24,6.54]],"id":46251065}],"con":true,"img":false}]}
{"op":"mcm","clk":"11539573673","pt":1719483330869,"mc":[{"id":"1.230178314","rc":[{"atb":[[2.28,6.54]],"id":69979804}],"con":true,"img":false}]}
{"op":"mcm","clk":"11539573687","pt":1719483331079,"mc":[{"id":"1.230178314","rc":[{"atb":[[2.18,6.54]],"id":63994056}],"con":true,"img":false}]}
{"op":"mcm","clk":"11539709993","pt":1719485144859,"mc":[{"id":"1.230178314","rc":[{"atb":[[4.1,6]],"id":47030762},{"spn":4.1,"spf":1.0,"id":47030762},{"atb":[[4.1,6]],"id":70466763},{"spn":77.05,"spf":"NaN","id":70466763},{"atb":[[3.1,6]],"id":45375136},{"spn":19.55,"spf":"NaN","id":45375136},{"atb":[[2.58,6]],"id":63994056},{"spn":13.79,"spf":"NaN","id":63994056},{"atb":[[2.58,6]],"id":69979804},{"spn":12.79,"spf":"NaN","id":69979804},{"atb":[[3.1,6]],"id":46251065},{"spn":15.55,"spf":"NaN","id":46251065}],"con":true,"img":false}]}
{"op":"mcm","clk":"11539710893","pt":1719485154348,"mc":[{"id":"1.230178314","rc":[{"atb":[[2.28,3.38]],"id":47030762},{"atb":[[2.28,3.38]],"id":70466763},{"atb":[[2.22,3.38]],"id":45375136},{"atb":[[2.24,3.38]],"id":46251065}],"con":true,"img":false}]}
{"op":"mcm","clk":"11539713083","pt":1719485180096,"mc":[{"id":"1.230178314","rc":[{"atb":[[2.28,0]],"id":47030762},{"atb":[[2.28,0]],"id":70466763},{"atb":[[2.22,0]],"id":45375136},{"atb":[[2.24,0]],"id":46251065}],"con":true,"img":false}]}
{"op":"mcm","clk":"11539736761","pt":1719485461686,"mc":[{"id":"1.230178314","rc":[{"atb":[[5,1]],"id":47030762},{"spn":5.0,"spf":1.0,"id":47030762},{"atb":[[5,1]],"id":70466763},{"spn":77.5,"spf":"NaN","id":70466763},{"atb":[[5,1]],"id":45375136},{"spn":20.5,"spf":"NaN","id":45375136},{"atb":[[4.2,1]],"id":63994056},{"spn":14.6,"spf":"NaN","id":63994056},{"atb":[[5,1]],"id":69979804},{"spn":14.0,"spf":"NaN","id":69979804},{"atb":[[5,1]],"id":46251065},{"spn":16.5,"spf":"NaN","id":46251065}],"con":true,"img":false}]}
{"op":"mcm","clk":"11539783388","pt":1719486142079,"mc":[{"id":"1.230178314","rc":[{"atb":[[1.03,15.09],[2.26,11.65],[1.51,196.08]],"id":47030762},{"atb":[[1.02,22.63],[2.26,9.86],[1.51,196.08]],"id":70466763},{"atb":[[1.01,45.27],[2.2,9.58],[1.51,196.08]],"id":45375136},{"atb":[[1.01,45.27],[2.18,6.54],[2.16,8.54]],"id":63994056},{"atb":[[1.02,22.63],[2.28,6.54],[2.26,8.96]],"id":69979804},{"atb":[[1.01,45.27],[2.22,9.67],[1.51,196.08]],"id":46251065}],"con":true,"img":false}]}
{"op":"mcm","clk":"11539803192","pt":1719486410810,"mc":[{"id":"1.230178314","rc":[{"atb":[[2.12,89.29]],"id":47030762},{"atb":[[2.12,89.29]],"id":70466763},{"atb":[[1.51,196.08]],"id":63994056},{"atb":[[1.51,196.08]],"id":69979804}],"con":true,"img":false}]}
{"op":"mcm","clk":"11539817264","pt":1719486505530,"mc":[{"id":"1.230178314","rc":[{"atb":[[2.16,0]],"id":63994056},{"atb":[[2.26,0]],"id":69979804}],"con":true,"img":false}]}
{"op":"mcm","clk":"11539817271","pt":1719486505631,"mc":[{"id":"1.230178314","rc":[{"atb":[[2.2,8.54]],"id":63994056},{"atb":[[2.3,8.96]],"id":69979804}],"con":true,"img":false}]}
{"op":"mcm","clk":"11539819036","pt":1719486524666,"mc":[{"id":"1.230178314","rc":[{"atb":[[2.18,3.38]],"id":63994056}],"con":true,"img":false}]}
{"op":"mcm","clk":"11539819053","pt":1719486524872,"mc":[{"id":"1.230178314","rc":[{"atb":[[2.28,3.38]],"id":69979804}],"con":true,"img":false}]}
{"op":"mcm","clk":"11539819077","pt":1719486525179,"mc":[{"id":"1.230178314","rc":[{"atb":[[2.22,3.16]],"id":63994056}],"con":true,"img":false}]}
{"op":"mcm","clk":"11539819107","pt":1719486525543,"mc":[{"id":"1.230178314","rc":[{"atb":[[2.32,3.16]],"id":69979804}],"con":true,"img":false}]}
{"op":"mcm","clk":"11539825514","pt":1719486601527,"mc":[{"id":"1.230178314","rc":[{"atb":[[2.28,0]],"id":69979804}],"con":true,"img":false}]}
{"op":"mcm","clk":"11539825600","pt":1719486602717,"mc":[{"id":"1.230178314","rc":[{"atb":[[2.18,0]],"id":63994056}],"con":true,"img":false}]}
{"op":"mcm","clk":"11539825807","pt":1719486605605,"mc":[{"id":"1.230178314","rc":[{"atb":[[2.32,6.54]],"id":69979804}],"con":true,"img":false}]}
{"op":"mcm","clk":"11539825831","pt":1719486605914,"mc":[{"id":"1.230178314","rc":[{"atb":[[2.22,6.54]],"id":63994056}],"con":true,"img":false}]}
{"op":"mcm","clk":"11539840538","pt":1719486805252,"mc":[{"id":"1.230178314","rc":[{"atb":[[2.2,0]],"id":63994056},{"atb":[[2.3,0]],"id":69979804}],"con":true,"img":false}]}
{"op":"mcm","clk":"11539840543","pt":1719486805315,"mc":[{"id":"1.230178314","rc":[{"atb":[[2.24,8.54]],"id":63994056},{"atb":[[2.34,8.96]],"id":69979804}],"con":true,"img":false}]}
{"op":"mcm","clk":"11539841563","pt":1719486822078,"mc":[{"id":"1.230178314","rc":[{"atb":[[2.22,3.38]],"id":63994056},{"atb":[[2.32,3.38]],"id":69979804}],"con":true,"img":false}]}
{"op":"mcm","clk":"11539843192","pt":1719486846472,"mc":[{"id":"1.230178314","rc":[{"atb":[[2.22,0]],"id":63994056},{"atb":[[2.32,0]],"id":69979804}],"con":true,"img":false}]}
{"op":"mcm","clk":"11539848960","pt":1719486927672,"mc":[{"id":"1.230178314","rc":[{"atb":[[2.26,3.38]],"id":63994056}],"con":true,"img":false}]}
{"op":"mcm","clk":"11539848971","pt":1719486927775,"mc":[{"id":"1.230178314","rc":[{"atb":[[2.36,3.38]],"id":69979804}],"con":true,"img":false}]}
{"op":"mcm","clk":"11539850393","pt":1719486945903,"mc":[{"id":"1.230178314","rc":[{"atb":[[2.26,6.54]],"id":63994056},{"atb":[[2.36,6.54]],"id":69979804}],"con":true,"img":false}]}
{"op":"mcm","clk":"11539950641","pt":1719488220172,"mc":[{"id":"1.230178314","rc":[{"atb":[[3.7,1]],"id":70466763}],"con":true,"img":false}]}
{"op":"mcm","clk":"11539951194","pt":1719488229176,"mc":[{"id":"1.230178314","rc":[{"atb":[[3.7,1]],"id":47030762}],"con":true,"img":false}]}
{"op":"mcm","clk":"11539951557","pt":1719488235696,"mc":[{"id":"1.230178314","rc":[{"atb":[[3.7,1]],"id":69979804}],"con":true,"img":false}]}
{"op":"mcm","clk":"11539952391","pt":1719488249024,"mc":[{"id":"1.230178314","rc":[{"atb":[[2.12,89.29]],"id":69979804}],"con":true,"img":false}]}
{"op":"mcm","clk":"11540014333","pt":1719488998735,"mc":[{"id":"1.230178314","rc":[{"atl":[[550,2]],"id":47030762},{"atb":[[1.16,150]],"id":70466763},{"atl":[[390,2]],"id":70466763},{"atl":[[370,2]],"id":45375136},{"atl":[[500,2]],"id":63994056},{"atl":[[560,2]],"id":69979804},{"atl":[[270,2]],"id":46251065}],"con":true,"img":false}]}
{"op":"mcm","clk":"11540014343","pt":1719488998839,"mc":[{"id":"1.230178314","rc":[{"atb":[[1.16,150]],"id":47030762},{"atb":[[1.16,150]],"id":45375136},{"atb":[[1.16,150]],"id":63994056},{"atb":[[1.16,150]],"id":69979804},{"atb":[[1.16,150]],"id":46251065}],"con":true,"img":false}]}
{"op":"mcm","clk":"11540136133","pt":1719490398525,"mc":[{"id":"1.230178314","rc":[{"atb":[[2.24,0],[2.26,6.54]],"id":63994056},{"atb":[[2.36,6.54]],"id":69979804}],"con":true,"img":false}]}
{"op":"mcm","clk":"11540136138","pt":1719490398625,"mc":[{"id":"1.230178314","rc":[{"atb":[[2.28,8.54]],"id":63994056}],"con":true,"img":false}]}
{"op":"mcm","clk":"11540141550","pt":1719490451805,"mc":[{"id":"1.230178314","rc":[{"atb":[[2.26,3.16]],"id":63994056}],"con":true,"img":false}]}
{"op":"mcm","clk":"11540141716","pt":1719490453423,"mc":[{"id":"1.230178314","rc":[{"atb":[[2.3,3.38]],"id":63994056}],"con":true,"img":false}]}
{"op":"mcm","clk":"11540144785","pt":1719490482519,"mc":[{"id":"1.230178314","rc":[{"atb":[[2.26,0]],"id":63994056}],"con":true,"img":false}]}
{"op":"mcm","clk":"11540145516","pt":1719490489508,"mc":[{"id":"1.230178314","rc":[{"atb":[[2.3,6.54]],"id":63994056}],"con":true,"img":false}]}
{"op":"mcm","clk":"11540164598","pt":1719490696803,"mc":[{"id":"1.230178314","rc":[{"atb":[[2.28,0]],"id":63994056}],"con":true,"img":false}]}
{"op":"mcm","clk":"11540164603","pt":1719490696901,"mc":[{"id":"1.230178314","rc":[{"atb":[[2.32,8.54]],"id":63994056}],"con":true,"img":false}]}
{"op":"mcm","clk":"11540168689","pt":1719490748357,"mc":[{"id":"1.230178314","rc":[{"atb":[[2.3,3.38]],"id":63994056}],"con":true,"img":false}]}
{"op":"mcm","clk":"11540168714","pt":1719490748666,"mc":[{"id":"1.230178314","rc":[{"atb":[[2.34,3.16]],"id":63994056}],"con":true,"img":false}]}
{"op":"mcm","clk":"11540171412","pt":1719490788490,"mc":[{"id":"1.230178314","rc":[{"atb":[[2.3,0]],"id":63994056}],"con":true,"img":false}]}
{"op":"mcm","clk":"11540173325","pt":1719490812520,"mc":[{"id":"1.230178314","rc":[{"atb":[[2.34,6.54]],"id":63994056}],"con":true,"img":false}]}
{"op":"mcm","clk":"11540319561","pt":1719492949173,"mc":[{"id":"1.230178314","rc":[{"atb":[[5,0]],"id":47030762},{"spn":4.1,"spf":1.0,"id":47030762},{"atb":[[5,0]],"id":70466763},{"spn":77.05,"spf":"NaN","id":70466763},{"atb":[[5,0]],"id":45375136},{"spn":19.55,"spf":"NaN","id":45375136},{"atb":[[4.2,0]],"id":63994056},{"spn":13.79,"spf":"NaN","id":63994056},{"atb":[[5,0]],"id":69979804},{"spn":13.35,"spf":"NaN","id":69979804},{"atb":[[5,0]],"id":46251065},{"spn":15.55,"spf":"NaN","id":46251065}],"con":true,"img":false}]}
{"op":"mcm","clk":"11540325642","pt":1719493038490,"mc":[{"id":"1.230178314","marketDefinition":{"bspMarket":true,"turnInPlayEnabled":false,"persistenceEnabled":false,"marketBaseRate":5.0,"eventId":"33376062","eventTypeId":"4339","numberOfWinners":1,"bettingType":"ODDS","marketType":"WIN","marketTime":"2024-06-27T14:51:00.000Z","suspendTime":"2024-06-27T14:51:00.000Z","bspReconciled":false,"complete":true,"inPlay":false,"crossMatching":true,"runnersVoidable":false,"numberOfActiveRunners":6,"betDelay":0,"status":"SUSPENDED","runners":[{"status":"ACTIVE","sortPriority":1,"id":45375136,"name":"1. Canya Sunset"},{"status":"ACTIVE","sortPriority":2,"id":70466763,"name":"2. Takeiteasytiger"},{"status":"ACTIVE","sortPriority":3,"id":47030762,"name":"3. Dysert Rachael"},{"status":"ACTIVE","sortPriority":4,"id":46251065,"name":"4. Mustang Luca"},{"status":"ACTIVE","sortPriority":5,"id":69979804,"name":"5. Canal View Blue"},{"status":"ACTIVE","sortPriority":6,"id":63994056,"name":"6. Pyle Driver"}],"regulators":["MR_INT"],"venue":"Kinsley","countryCode":"GB","discountAllowed":true,"timezone":"Europe/London","openDate":"2024-06-27T13:36:00.000Z","version":5995379645,"name":"A5 462m","eventName":"Kinsley 27th Jun"},"rc":[],"con":true,"img":false}]}
{"op":"mcm","clk":"11540325668","pt":1719493038742,"mc":[{"id":"1.230178314","marketDefinition":{"bspMarket":true,"turnInPlayEnabled":false,"persistenceEnabled":false,"marketBaseRate":5.0,"eventId":"33376062","eventTypeId":"4339","numberOfWinners":1,"bettingType":"ODDS","marketType":"WIN","marketTime":"2024-06-27T14:51:00.000Z","suspendTime":"2024-06-27T14:51:00.000Z","bspReconciled":false,"complete":true,"inPlay":false,"crossMatching":true,"runnersVoidable":false,"numberOfActiveRunners":6,"betDelay":0,"status":"SUSPENDED","runners":[{"status":"ACTIVE","sortPriority":1,"id":45375136,"name":"1. Canya Sunset"},{"status":"ACTIVE","sortPriority":2,"id":70466763,"name":"2. Takeiteasytiger"},{"status":"ACTIVE","sortPriority":3,"id":47030762,"name":"3. Dysert Rachael"},{"status":"ACTIVE","sortPriority":4,"id":46251065,"name":"4. Mustang Luca"},{"status":"ACTIVE","sortPriority":5,"id":69979804,"name":"5. Canal View Blue"},{"status":"ACTIVE","sortPriority":6,"id":63994056,"name":"6. Pyle Driver"}],"regulators":["MR_INT"],"venue":"Kinsley","countryCode":"GB","discountAllowed":true,"timezone":"Europe/London","openDate":"2024-06-27T13:36:00.000Z","version":5995379689,"name":"A5 462m","eventName":"Kinsley 27th Jun"},"rc":[],"con":true,"img":false}]}
{"op":"mcm","clk":"11540325668","pt":1719493038742,"mc":[{"id":"1.230178314","rc":[{"spl":[[1.01,0]],"id":47030762},{"atb":[[1.16,0],[1.03,0],[4.1,0],[3.7,0],[2.12,0],[2.26,0],[1.51,0]],"id":47030762},{"atl":[[550,0],[150,0],[990,0]],"id":47030762},{"atb":[[1.16,0],[2.22,0],[4.1,0],[3.7,0],[1.02,0],[2.12,0],[2.26,0],[1.51,0]],"id":70466763},{"atl":[[150,0],[390,0],[990,0]],"id":70466763},{"atb":[[1.01,0],[1.16,0],[3.1,0],[2.2,0],[1.51,0]],"id":45375136},{"atl":[[36,0],[150,0],[370,0],[60,0],[990,0]],"id":45375136},{"atb":[[1.01,0],[2.32,0],[1.16,0],[2.58,0],[1.51,0],[2.34,0]],"id":63994056},{"atl":[[150,0],[42,0],[25,0],[990,0],[500,0]],"id":63994056},{"atb":[[2.36,0],[1.16,0],[3.7,0],[1.02,0],[2.12,0],[2.58,0],[1.51,0],[2.34,0]],"id":69979804},{"atl":[[560,0],[150,0],[40,0],[23,0],[1000,0]],"id":69979804},{"atb":[[1.01,0],[1.16,0],[3.1,0],[2.22,0],[1.51,0]],"id":46251065},{"atl":[[270,0],[150,0],[48,0],[28,0],[990,0]],"id":46251065}],"con":true,"img":false}]}
{"op":"mcm","clk":"11540325684","pt":1719493038945,"mc":[{"id":"1.230178314","marketDefinition":{"bspMarket":true,"turnInPlayEnabled":false,"persistenceEnabled":false,"marketBaseRate":5.0,"eventId":"33376062","eventTypeId":"4339","numberOfWinners":1,"bettingType":"ODDS","marketType":"WIN","marketTime":"2024-06-27T14:51:00.000Z","suspendTime":"2024-06-27T14:51:00.000Z","bspReconciled":false,"complete":true,"inPlay":false,"crossMatching":true,"runnersVoidable":false,"numberOfActiveRunners":5,"betDelay":0,"status":"SUSPENDED","runners":[{"status":"ACTIVE","sortPriority":1,"id":45375136,"name":"1. Canya Sunset"},{"status":"ACTIVE","sortPriority":2,"id":70466763,"name":"2. Takeiteasytiger"},{"status":"ACTIVE","sortPriority":3,"id":46251065,"name":"4. Mustang Luca"},{"status":"ACTIVE","sortPriority":4,"id":69979804,"name":"5. Canal View Blue"},{"status":"ACTIVE","sortPriority":5,"id":63994056,"name":"6. Pyle Driver"},{"status":"REMOVED","sortPriority":6,"removalDate":"2024-06-27T12:57:18.000Z","id":47030762,"name":"3. Dysert Rachael"}],"regulators":["MR_INT"],"venue":"Kinsley","countryCode":"GB","discountAllowed":true,"timezone":"Europe/London","openDate":"2024-06-27T13:36:00.000Z","version":5995379689,"name":"A5 462m","eventName":"Kinsley 27th Jun"},"rc":[],"con":true,"img":false}]}
{"op":"mcm","clk":"11540326001","pt":1719493042964,"mc":[{"id":"1.230178314","marketDefinition":{"bspMarket":true,"turnInPlayEnabled":false,"persistenceEnabled":false,"marketBaseRate":5.0,"eventId":"33376062","eventTypeId":"4339","numberOfWinners":1,"bettingType":"ODDS","marketType":"WIN","marketTime":"2024-06-27T14:51:00.000Z","suspendTime":"2024-06-27T14:51:00.000Z","bspReconciled":false,"complete":true,"inPlay":false,"crossMatching":false,"runnersVoidable":false,"numberOfActiveRunners":6,"betDelay":0,"status":"SUSPENDED","runners":[{"status":"ACTIVE","sortPriority":1,"id":45375136,"name":"1. Canya Sunset"},{"status":"ACTIVE","sortPriority":2,"id":70466763,"name":"2. Takeiteasytiger"},{"status":"ACTIVE","sortPriority":3,"id":70940946,"name":"3. Boherduff Biker (res)"},{"status":"ACTIVE","sortPriority":4,"id":46251065,"name":"4. Mustang Luca"},{"status":"ACTIVE","sortPriority":5,"id":69979804,"name":"5. Canal View Blue"},{"status":"ACTIVE","sortPriority":6,"id":63994056,"name":"6. Pyle Driver"},{"status":"REMOVED","sortPriority":7,"removalDate":"2024-06-27T12:57:18.000Z","id":47030762,"name":"3. Dysert Rachael"}],"regulators":["MR_INT"],"venue":"Kinsley","countryCode":"GB","discountAllowed":true,"timezone":"Europe/London","openDate":"2024-06-27T13:36:00.000Z","version":5995379748,"name":"A5 462m","eventName":"Kinsley 27th Jun"},"rc":[],"con":true,"img":false}]}
{"op":"mcm","clk":"11540326040","pt":1719493043506,"mc":[{"id":"1.230178314","marketDefinition":{"bspMarket":true,"turnInPlayEnabled":false,"persistenceEnabled":false,"marketBaseRate":5.0,"eventId":"33376062","eventTypeId":"4339","numberOfWinners":1,"bettingType":"ODDS","marketType":"WIN","marketTime":"2024-06-27T14:51:00.000Z","suspendTime":"2024-06-27T14:51:00.000Z","bspReconciled":false,"complete":true,"inPlay":false,"crossMatching":false,"runnersVoidable":false,"numberOfActiveRunners":6,"betDelay":0,"status":"OPEN","runners":[{"status":"ACTIVE","sortPriority":1,"id":45375136,"name":"1. Canya Sunset"},{"status":"ACTIVE","sortPriority":2,"id":70466763,"name":"2. Takeiteasytiger"},{"status":"ACTIVE","sortPriority":3,"id":70940946,"name":"3. Boherduff Biker (res)"},{"status":"ACTIVE","sortPriority":4,"id":46251065,"name":"4. Mustang Luca"},{"status":"ACTIVE","sortPriority":5,"id":69979804,"name":"5. Canal View Blue"},{"status":"ACTIVE","sortPriority":6,"id":63994056,"name":"6. Pyle Driver"},{"status":"REMOVED","sortPriority":7,"removalDate":"2024-06-27T12:57:18.000Z","id":47030762,"name":"3. Dysert Rachael"}],"regulators":["MR_INT"],"venue":"Kinsley","countryCode":"GB","discountAllowed":true,"timezone":"Europe/London","openDate":"2024-06-27T13:36:00.000Z","version":5995379777,"name":"A5 462m","eventName":"Kinsley 27th Jun"},"rc":[],"con":true,"img":false}]}
{"op":"mcm","clk":"11540326335","pt":1719493047326,"mc":[{"id":"1.230178314","rc":[{"atl":[[390,2]],"id":70466763},{"spn":1.0,"spf":"NaN","id":70466763},{"atl":[[370,2]],"id":45375136},{"spn":1.0,"spf":"NaN","id":45375136}],"con":true,"img":false}]}
{"op":"mcm","clk":"11540326343","pt":1719493047436,"mc":[{"id":"1.230178314","rc":[{"atb":[[1.16,150]],"id":70466763},{"atb":[[1.16,150]],"id":45375136},{"atb":[[1.16,150]],"id":63994056},{"atl":[[500,2]],"id":63994056},{"atb":[[1.16,150]],"id":69979804},{"atl":[[560,2]],"id":69979804},{"atb":[[1.16,150]],"id":70940946},{"atl":[[550,2]],"id":70940946},{"atb":[[1.16,150]],"id":46251065},{"atl":[[270,2]],"id":46251065}],"con":true,"img":false}]}
{"op":"mcm","clk":"11540326778","pt":1719493053447,"mc":[{"id":"1.230178314","rc":[{"atb":[[1.51,196.08]],"id":70466763},{"atl":[[150,4]],"id":70466763},{"atl":[[150,4]],"id":45375136},{"atb":[[1.51,196.08]],"id":69979804}],"con":true,"img":false}]}
{"op":"mcm","clk":"11540326790","pt":1719493053553,"mc":[{"id":"1.230178314","rc":[{"atb":[[2,2]],"id":70466763},{"atl":[[150,4]],"id":63994056},{"atl":[[150,4]],"id":69979804},{"atl":[[150,4]],"id":46251065}],"con":true,"img":false}]}
{"op":"mcm","clk":"11540337587","pt":1719493208802,"mc":[{"id":"1.230178314","rc":[{"spn":76.0,"spf":"NaN","id":70466763},{"atb":[[1.17,3.16]],"id":45375136},{"spn":75.58,"spf":"NaN","id":45375136},{"atb":[[1.17,3.16]],"id":63994056},{"spn":75.58,"spf":"NaN","id":63994056},{"spn":75.75,"spf":"NaN","id":69979804},{"spn":275.58,"spf":"NaN","id":70940946},{"spn":75.58,"spf":"NaN","id":46251065}],"con":true,"img":false}]}
{"op":"mcm","clk":"11540337600","pt":1719493209010,"mc":[{"id":"1.230178314","rc":[{"atb":[[1.17,3.16]],"id":46251065}],"con":true,"img":false}]}
{"op":"mcm","clk":"11540337608","pt":1719493209114,"mc":[{"id":"1.230178314","rc":[{"atb":[[1.52,3.16]],"id":69979804}],"con":true,"img":false}]}
{"op":"mcm","clk":"11540337614","pt":1719493209177,"mc":[{"id":"1.230178314","rc":[{"atb":[[1.52,3.16]],"id":70466763}],"con":true,"img":false}]}
{"op":"mcm","clk":"11540340043","pt":1719493242942,"mc":[{"id":"1.230178314","rc":[{"atb":[[1.17,6.54]],"id":45375136}],"con":true,"img":false}]}
{"op":"mcm","clk":"11540340057","pt":1719493243116,"mc":[{"id":"1.230178314","rc":[{"atb":[[1.52,6.54]],"id":70466763}],"con":true,"img":false}]}
{"op":"mcm","clk":"11540340065","pt":1719493243209,"mc":[{"id":"1.230178314","rc":[{"atb":[[1.17,6.54]],"id":46251065}],"con":true,"img":false}]}
{"op":"mcm","clk":"11540340077","pt":1719493243415,"mc":[{"id":"1.230178314","rc":[{"atb":[[1.52,6.54]],"id":69979804}],"con":true,"img":false}]}
{"op":"mcm","clk":"11540340083","pt":1719493243521,"mc":[{"id":"1.230178314","rc":[{"atb":[[1.17,6.54]],"id":63994056}],"con":true,"img":false}]}
{"op":"mcm","clk":"11540397755","pt":1719493995101,"mc":[{"id":"1.230178314","rc":[{"atb":[[2.06,11.45]],"id":70466763},{"spn":76.03,"spf":"NaN","id":70466763},{"atb":[[2.06,8.8]],"id":45375136},{"spn":76.03,"spf":"NaN","id":45375136},{"atb":[[2.08,9.78]],"id":63994056},{"spn":76.04,"spf":"NaN","id":63994056},{"atb":[[2.08,10.67]],"id":69979804},{"spn":76.04,"spf":"NaN","id":69979804},{"atb":[[2.04,10.46]],"id":70940946},{"spn":276.02,"spf":"NaN","id":70940946},{"atb":[[2.06,10.57]],"id":46251065},{"spn":76.03,"spf":"NaN","id":46251065}],"con":true,"img":false}]}
{"op":"mcm","clk":"11540398037","pt":1719493998626,"mc":[{"id":"1.230178314","rc":[{"atb":[[1.17,3.38]],"id":45375136}],"con":true,"img":false}]}
{"op":"mcm","clk":"11540398047","pt":1719493998724,"mc":[{"id":"1.230178314","rc":[{"atb":[[1.52,3.38]],"id":70466763}],"con":true,"img":false}]}
{"op":"mcm","clk":"11540398063","pt":1719493998928,"mc":[{"id":"1.230178314","rc":[{"atb":[[1.52,3.38]],"id":69979804},{"atb":[[1.17,3.38]],"id":46251065}],"con":true,"img":false}]}
{"op":"mcm","clk":"11540398087","pt":1719493999138,"mc":[{"id":"1.230178314","rc":[{"atb":[[2.08,3.16]],"id":70466763}],"con":true,"img":false}]}
{"op":"mcm","clk":"11540398094","pt":1719493999241,"mc":[{"id":"1.230178314","rc":[{"atb":[[1.17,3.38]],"id":63994056}],"con":true,"img":false}]}
{"op":"mcm","clk":"11540398104","pt":1719493999345,"mc":[{"id":"1.230178314","rc":[{"atb":[[2.08,3.16]],"id":45375136}],"con":true,"img":false}]}
{"op":"mcm","clk":"11540398118","pt":1719493999403,"mc":[{"id":"1.230178314","rc":[{"atb":[[2.08,3.16]],"id":46251065}],"con":true,"img":false}]}
{"op":"mcm","clk":"11540398130","pt":1719493999500,"mc":[{"id":"1.230178314","rc":[{"atb":[[2.1,3.16]],"id":69979804}],"con":true,"img":false}]}
{"op":"mcm","clk":"11540398142","pt":1719493999606,"mc":[{"id":"1.230178314","rc":[{"atb":[[2.1,3.16]],"id":63994056}],"con":true,"img":false}]}
{"op":"mcm","clk":"11540400182","pt":1719494024329,"mc":[{"id":"1.230178314","rc":[{"atb":[[1.17,0]],"id":45375136}],"con":true,"img":false}]}
{"op":"mcm","clk":"11540400187","pt":1719494024432,"mc":[{"id":"1.230178314","rc":[{"atb":[[1.17,0]],"id":63994056}],"con":true,"img":false}]}
{"op":"mcm","clk":"11540400206","pt":1719494024636,"mc":[{"id":"1.230178314","rc":[{"atb":[[1.52,0]],"id":70466763}],"con":true,"img":false}]}
{"op":"mcm","clk":"11540400229","pt":1719494024946,"mc":[{"id":"1.230178314","rc":[{"atb":[[2.08,6.54]],"id":45375136},{"atb":[[1.52,0]],"id":69979804}],"con":true,"img":false}]}
{"op":"mcm","clk":"11540400262","pt":1719494025261,"mc":[{"id":"1.230178314","rc":[{"atb":[[2.1,6.54]],"id":63994056},{"atb":[[1.17,0]],"id":46251065}],"con":true,"img":false}]}
{"op":"mcm","clk":"11540400291","pt":1719494025519,"mc":[{"id":"1.230178314","rc":[{"atb":[[2.1,6.54]],"id":69979804}],"con":true,"img":false}]}
{"op":"mcm","clk":"11540400309","pt":1719494025723,"mc":[{"id":"1.230178314","rc":[{"atb":[[2.08,6.54]],"id":70466763}],"con":true,"img":false}]}
{"op":"mcm","clk":"11540400324","pt":1719494025833,"mc":[{"id":"1.230178314","rc":[{"atb":[[2.08,6.54]],"id":46251065}],"con":true,"img":false}]}
{"op":"mcm","clk":"11540419289","pt":1719494295934,"mc":[{"id":"1.230178314","rc":[{"atb":[[2.06,0]],"id":70466763},{"spn":76.04,"spf":"NaN","id":70466763},{"atb":[[2.06,0]],"id":45375136},{"spn":76.04,"spf":"NaN","id":45375136},{"atb":[[2.08,0]],"id":63994056},{"spn":76.05,"spf":"NaN","id":63994056},{"atb":[[2.08,0]],"id":69979804},{"spn":76.05,"spf":"NaN","id":69979804},{"atb":[[2.06,0]],"id":46251065},{"spn":76.04,"spf":"NaN","id":46251065}],"con":true,"img":false}]}
{"op":"mcm","clk":"11540419298","pt":1719494296035,"mc":[{"id":"1.230178314","rc":[{"atb":[[2.1,11.45]],"id":70466763},{"atb":[[2.1,8.8]],"id":45375136},{"atb":[[2.12,9.78]],"id":63994056},{"atb":[[2.12,10.67]],"id":69979804},{"atb":[[2.1,10.57]],"id":46251065}],"con":true,"img":false}]}
{"op":"mcm","clk":"11540420187","pt":1719494306832,"mc":[{"id":"1.230178314","rc":[{"atb":[[2.08,3.16]],"id":45375136}],"con":true,"img":false}]}
{"op":"mcm","clk":"11540420202","pt":1719494307039,"mc":[{"id":"1.230178314","rc":[{"atb":[[2.08,3.16]],"id":46251065}],"con":true,"img":false}]}
{"op":"mcm","clk":"11540420214","pt":1719494307145,"mc":[{"id":"1.230178314","rc":[{"atb":[[2.1,3.16]],"id":69979804}],"con":true,"img":false}]}
{"op":"mcm","clk":"11540420236","pt":1719494307451,"mc":[{"id":"1.230178314","rc":[{"atb":[[2.1,3.16]],"id":63994056}],"con":true,"img":false}]}
{"op":"mcm","clk":"11540420270","pt":1719494307766,"mc":[{"id":"1.230178314","rc":[{"atb":[[2.08,3.16]],"id":70466763},{"atb":[[2.12,3.38]],"id":46251065}],"con":true,"img":false}]}
{"op":"mcm","clk":"11540420302","pt":1719494308074,"mc":[{"id":"1.230178314","rc":[{"atb":[[2.14,3.38]],"id":63994056},{"atb":[[2.14,3.38]],"id":69979804}],"con":true,"img":false}]}
{"op":"mcm","clk":"11540420335","pt":1719494308345,"mc":[{"id":"1.230178314","rc":[{"atb":[[2.12,3.38]],"id":45375136}],"con":true,"img":false}]}
{"op":"mcm","clk":"11540420366","pt":1719494308657,"mc":[{"id":"1.230178314","rc":[{"atb":[[2.12,3.38]],"id":70466763}],"con":true,"img":false}]}
{"op":"mcm","clk":"11540423238","pt":1719494342369,"mc":[{"id":"1.230178314","rc":[{"atb":[[2.08,0]],"id":45375136}],"con":true,"img":false}]}
{"op":"mcm","clk":"11540423250","pt":1719494342476,"mc":[{"id":"1.230178314","rc":[{"atb":[[2.1,0]],"id":69979804}],"con":true,"img":false}]}
{"op":"mcm","clk":"11540423257","pt":1719494342576,"mc":[{"id":"1.230178314","rc":[{"atb":[[2.08,0]],"id":46251065}],"con":true,"img":false}]}
{"op":"mcm","clk":"11540423267","pt":1719494342680,"mc":[{"id":"1.230178314","rc":[{"atb":[[2.08,0]],"id":70466763}],"con":true,"img":false}]}
{"op":"mcm","clk":"11540423276","pt":1719494342783,"mc":[{"id":"1.230178314","rc":[{"atb":[[2.12,6.54]],"id":45375136}],"con":true,"img":false}]}
{"op":"mcm","clk":"11540423286","pt":1719494342880,"mc":[{"id":"1.230178314","rc":[{"atb":[[2.14,6.54]],"id":69979804}],"con":true,"img":false}]}
{"op":"mcm","clk":"11540423295","pt":1719494342986,"mc":[{"id":"1.230178314","rc":[{"atb":[[2.1,0]],"id":63994056}],"con":true,"img":false}]}
{"op":"mcm","clk":"11540423312","pt":1719494343190,"mc":[{"id":"1.230178314","rc":[{"atb":[[2.12,6.54]],"id":70466763},{"atb":[[2.12,6.54]],"id":46251065}],"con":true,"img":false}]}
{"op":"mcm","clk":"11540423333","pt":1719494343399,"mc":[{"id":"1.230178314","rc":[{"atb":[[2.14,6.54]],"id":63994056}],"con":true,"img":false}]}
{"op":"mcm","clk":"11540445525","pt":1719494595656,"mc":[{"id":"1.230178314","rc":[{"atb":[[2.1,0]],"id":70466763},{"spn":76.06,"spf":"NaN","id":70466763},{"atb":[[2.1,0]],"id":45375136},{"spn":76.06,"spf":"NaN","id":45375136},{"atb":[[2.12,0]],"id":63994056},{"spn":76.07,"spf":"NaN","id":63994056},{"atb":[[2.12,0]],"id":69979804},{"spn":76.07,"spf":"NaN","id":69979804},{"atb":[[2.1,0]],"id":46251065},{"spn":76.06,"spf":"NaN","id":46251065}],"con":true,"img":false}]}
{"op":"mcm","clk":"11540445538","pt":1719494595759,"mc":[{"id":"1.230178314","rc":[{"atb":[[2.14,11.45]],"id":70466763},{"atb":[[2.14,8.8]],"id":45375136},{"atb":[[2.16,9.78]],"id":63994056},{"atb":[[2.16,10.67]],"id":69979804},{"atb":[[2.14,10.57]],"id":46251065}],"con":true,"img":false}]}
{"op":"mcm","clk":"11540445753","pt":1719494597897,"mc":[{"id":"1.230178314","rc":[{"atb":[[2.12,3.16]],"id":45375136}],"con":true,"img":false}]}
{"op":"mcm","clk":"11540445781","pt":1719494598049,"mc":[{"id":"1.230178314","rc":[{"atb":[[2.14,3.16]],"id":69979804}],"con":true,"img":false}]}
{"op":"mcm","clk":"11540445807","pt":1719494598255,"mc":[{"id":"1.230178314","rc":[{"atb":[[2.12,3.16]],"id":46251065}],"con":true,"img":false}]}
{"op":"mcm","clk":"11540445836","pt":1719494598568,"mc":[{"id":"1.230178314","rc":[{"atb":[[2.16,3.38]],"id":45375136}],"con":true,"img":false}]}
{"op":"mcm","clk":"11540445845","pt":1719494598674,"mc":[{"id":"1.230178314","rc":[{"atb":[[2.12,3.16]],"id":70466763}],"con":true,"img":false}]}
{"op":"mcm","clk":"11540445864","pt":1719494598873,"mc":[{"id":"1.230178314","rc":[{"atb":[[2.18,3.38]],"id":69979804}],"con":true,"img":false}]}
{"op":"mcm","clk":"11540445894","pt":1719494599185,"mc":[{"id":"1.230178314","rc":[{"atb":[[2.16,3.38]],"id":70466763},{"atb":[[2.14,3.16]],"id":63994056}],"con":true,"img":false}]}
{"op":"mcm","clk":"11540445922","pt":1719494599494,"mc":[{"id":"1.230178314","rc":[{"atb":[[2.16,3.38]],"id":46251065}],"con":true,"img":false}]}
{"op":"mcm","clk":"11540445948","pt":1719494599762,"mc":[{"id":"1.230178314","rc":[{"atb":[[2.18,3.38]],"id":63994056}],"con":true,"img":false}]}
{"op":"mcm","clk":"11540446697","pt":1719494607860,"mc":[{"id":"1.230178314","rc":[{"atb":[[2.12,0]],"id":45375136}],"con":true,"img":false}]}
{"op":"mcm","clk":"11540446712","pt":1719494608067,"mc":[{"id":"1.230178314","rc":[{"atb":[[2.12,0]],"id":70466763}],"con":true,"img":false}]}
{"op":"mcm","clk":"11540446722","pt":1719494608176,"mc":[{"id":"1.230178314","rc":[{"atb":[[2.14,0]],"id":63994056}],"con":true,"img":false}]}
{"op":"mcm","clk":"11540446737","pt":1719494608378,"mc":[{"id":"1.230178314","rc":[{"atb":[[2.16,6.54]],"id":45375136},{"atb":[[2.14,0]],"id":69979804}],"con":true,"img":false}]}
{"op":"mcm","clk":"11540446759","pt":1719494608587,"mc":[{"id":"1.230178314","rc":[{"atb":[[2.18,6.54]],"id":63994056}],"con":true,"img":false}]}
{"op":"mcm","clk":"11540446770","pt":1719494608688,"mc":[{"id":"1.230178314","rc":[{"atb":[[2.16,6.54]],"id":70466763}],"con":true,"img":false}]}
{"op":"mcm","clk":"11540446777","pt":1719494608791,"mc":[{"id":"1.230178314","rc":[{"atb":[[2.18,6.54]],"id":69979804}],"con":true,"img":false}]}
{"op":"mcm","clk":"11540446793","pt":1719494609000,"mc":[{"id":"1.230178314","rc":[{"atb":[[2.12,0]],"id":46251065}],"con":true,"img":false}]}
{"op":"mcm","clk":"11540446805","pt":1719494609155,"mc":[{"id":"1.230178314","rc":[{"atb":[[2.16,6.54]],"id":46251065}],"con":true,"img":false}]}
{"op":"mcm","clk":"11540471456","pt":1719494895583,"mc":[{"id":"1.230178314","rc":[{"atb":[[2.14,0]],"id":70466763},{"spn":76.08,"spf":"NaN","id":70466763},{"atb":[[2.14,0]],"id":45375136},{"spn":76.08,"spf":"NaN","id":45375136},{"atb":[[2.16,0]],"id":63994056},{"spn":76.09,"spf":"NaN","id":63994056},{"atb":[[2.16,0]],"id":69979804},{"spn":76.09,"spf":"NaN","id":69979804},{"atb":[[2.14,0]],"id":46251065},{"spn":76.08,"spf":"NaN","id":46251065}],"con":true,"img":false}]}
{"op":"mcm","clk":"11540471463","pt":1719494895684,"mc":[{"id":"1.230178314","rc":[{"atb":[[2.18,11.45]],"id":70466763},{"atb":[[2.18,8.8]],"id":45375136},{"atb":[[2.2,9.78]],"id":63994056},{"atb":[[2.2,10.67]],"id":69979804},{"atb":[[2.18,10.57]],"id":46251065}],"con":true,"img":false}]}
{"op":"mcm","clk":"11540473918","pt":1719494924735,"mc":[{"id":"1.230178314","rc":[{"atb":[[2.16,3.38]],"id":45375136},{"atb":[[2.16,3.38]],"id":46251065}],"con":true,"img":false}]}
{"op":"mcm","clk":"11540473940","pt":1719494925032,"mc":[{"id":"1.230178314","rc":[{"atb":[[2.16,3.38]],"id":70466763},{"atb":[[2.18,3.38]],"id":63994056}],"con":true,"img":false}]}
{"op":"mcm","clk":"11540473958","pt":1719494925240,"mc":[{"id":"1.230178314","rc":[{"atb":[[2.2,3.16]],"id":45375136}],"con":true,"img":false}]}
{"op":"mcm","clk":"11540473966","pt":1719494925344,"mc":[{"id":"1.230178314","rc":[{"atb":[[2.2,3.16]],"id":70466763}],"con":true,"img":false}]}
{"op":"mcm","clk":"11540473984","pt":1719494925553,"mc":[{"id":"1.230178314","rc":[{"atb":[[2.22,3.16]],"id":63994056}],"con":true,"img":false}]}
{"op":"mcm","clk":"11540473991","pt":1719494925630,"mc":[{"id":"1.230178314","rc":[{"atb":[[2.18,3.38]],"id":69979804}],"con":true,"img":false}]}
{"op":"mcm","clk":"11540474009","pt":1719494925826,"mc":[{"id":"1.230178314","rc":[{"atb":[[2.2,3.16]],"id":46251065}],"con":true,"img":false}]}
{"op":"mcm","clk":"11540474026","pt":1719494926039,"mc":[{"id":"1.230178314","rc":[{"atb":[[2.22,3.16]],"id":69979804}],"con":true,"img":false}]}
{"op":"mcm","clk":"11540474834","pt":1719494935351,"mc":[{"id":"1.230178314","rc":[{"atb":[[2.16,0]],"id":45375136}],"con":true,"img":false}]}
{"op":"mcm","clk":"11540474852","pt":1719494935557,"mc":[{"id":"1.230178314","rc":[{"atb":[[2.16,0]],"id":70466763}],"con":true,"img":false}]}
{"op":"mcm","clk":"11540474871","pt":1719494935752,"mc":[{"id":"1.230178314","rc":[{"atb":[[2.16,0]],"id":46251065}],"con":true,"img":false}]}
{"op":"mcm","clk":"11540474906","pt":1719494936130,"mc":[{"id":"1.230178314","rc":[{"atb":[[2.2,6.54]],"id":45375136},{"atb":[[2.18,0]],"id":69979804}],"con":true,"img":false}]}
{"op":"mcm","clk":"11540474940","pt":1719494936550,"mc":[{"id":"1.230178314","rc":[{"atb":[[2.18,0]],"id":63994056}],"con":true,"img":false}]}
{"op":"mcm","clk":"11540474965","pt":1719494936857,"mc":[{"id":"1.230178314","rc":[{"atb":[[2.2,6.54]],"id":46251065}],"con":true,"img":false}]}
{"op":"mcm","clk":"11540474975","pt":1719494936946,"mc":[{"id":"1.230178314","rc":[{"atb":[[2.22,6.54]],"id":69979804}],"con":true,"img":false}]}
{"op":"mcm","clk":"11540474992","pt":1719494937153,"mc":[{"id":"1.230178314","rc":[{"atb":[[2.22,6.54]],"id":63994056}],"con":true,"img":false}]}
{"op":"mcm","clk":"11540475030","pt":1719494937568,"mc":[{"id":"1.230178314","rc":[{"atb":[[2.2,6.54]],"id":70466763}],"con":true,"img":false}]}
{"op":"mcm","clk":"11540498681","pt":1719495201361,"mc":[{"id":"1.230178314","rc":[{"spn":76.1,"spf":"NaN","id":70466763},{"spn":76.1,"spf":"NaN","id":45375136},{"spn":76.11,"spf":"NaN","id":63994056},{"spn":76.11,"spf":"NaN","id":69979804},{"spl":[[1.01,1]],"id":46251065},{"spn":2.2,"spf":1.0,"id":46251065}],"con":true,"img":false}]}
{"op":"mcm","clk":"11540529437","pt":1719495563261,"mc":[{"id":"1.230178314","rc":[{"atb":[[3.7,1]],"id":70466763},{"spn":76.85,"spf":"NaN","id":70466763}],"con":true,"img":false}]}
{"op":"mcm","clk":"11540529495","pt":1719495563884,"mc":[{"id":"1.230178314","rc":[{"atb":[[3.75,2]],"id":70466763}],"con":true,"img":false}]}
{"op":"mcm","clk":"11540530261","pt":1719495573396,"mc":[{"id":"1.230178314","rc":[{"atb":[[3.7,1]],"id":69979804}],"con":true,"img":false}]}
{"op":"mcm","clk":"11540576410","pt":1719496077745,"mc":[{"id":"1.230178314","rc":[{"atb":[[5.5,1]],"id":70466763},{"spn":77.75,"spf":"NaN","id":70466763},{"atb":[[4.8,1]],"id":45375136},{"spn":77.4,"spf":"NaN","id":45375136},{"atb":[[3.8,1]],"id":63994056},{"spn":76.9,"spf":"NaN","id":63994056},{"atb":[[4,1]],"id":69979804},{"spn":77.0,"spf":"NaN","id":69979804},{"atb":[[5,1]],"id":70940946},{"spn":277.5,"spf":"NaN","id":70940946},{"atb":[[4.8,1]],"id":46251065},{"spn":4.8,"spf":1.0,"id":46251065}],"con":true,"img":false}]}
{"op":"mcm","clk":"11540629310","pt":1719496639506,"mc":[{"id":"1.230178314","rc":[{"atb":[[1.02,9.21]],"id":70466763},{"atl":[[1000,0.84]],"id":70466763},{"atb":[[1.01,18.42]],"id":45375136},{"atl":[[1000,0.84]],"id":45375136},{"atb":[[1.01,18.42]],"id":63994056},{"atl":[[1000,0.84]],"id":63994056},{"atb":[[1.03,6.14]],"id":69979804},{"atl":[[1000,0.84]],"id":69979804},{"atb":[[1.03,6.14]],"id":70940946},{"atl":[[990,0.84]],"id":70940946},{"atb":[[1.03,6.14]],"id":46251065},{"atl":[[1000,0.84]],"id":46251065}],"con":true,"img":false}]}
{"op":"mcm","clk":"11540637657","pt":1719496743288,"mc":[{"id":"1.230178314","rc":[{"atb":[[5,1]],"id":70466763},{"atb":[[5,1]],"id":45375136},{"spn":77.5,"spf":"NaN","id":45375136},{"atb":[[3.9,1]],"id":63994056},{"spn":76.95,"spf":"NaN","id":63994056},{"atb":[[5,1]],"id":69979804},{"spn":77.5,"spf":"NaN","id":69979804},{"atb":[[5,2]],"id":70940946},{"atb":[[5,1]],"id":46251065},{"spn":5.0,"spf":1.0,"id":46251065}],"con":true,"img":false}]}
{"op":"mcm","clk":"11540660551","pt":1719497028999,"mc":[{"id":"1.230178314","rc":[{"atb":[[1.02,9.21],[2.12,89.29],[2.18,11.44],[2.2,6.54]],"id":70466763},{"atl":[[1000,0.84]],"id":70466763},{"atb":[[1.01,18.42],[2.12,89.29],[2.18,8.8],[2.2,6.54],[1.51,196.08]],"id":45375136},{"atl":[[1000,0.84]],"id":45375136},{"atb":[[1.01,18.42],[2.22,6.54],[2.2,9.77],[1.51,196.08]],"id":63994056},{"atl":[[1000,0.84]],"id":63994056},{"atb":[[1.03,6.13],[2.22,6.54],[2.2,10.66]],"id":69979804},{"atl":[[1000,0.84]],"id":69979804},{"atb":[[1.03,6.13],[2.04,10.46]],"id":70940946},{"atl":[[990,0.84]],"id":70940946},{"atb":[[1.03,6.13],[2.12,89.29],[2.18,10.56],[2.2,6.54],[1.51,196.08]],"id":46251065},{"atl":[[1000,0.84]],"id":46251065}],"con":true,"img":false}]}
{"op":"mcm","clk":"11540715594","pt":1719497592169,"mc":[{"id":"1.230178314","rc":[{"atb":[[2.18,0]],"id":70466763},{"atb":[[2.18,0]],"id":45375136},{"atb":[[2.2,0]],"id":63994056},{"atb":[[2.2,0]],"id":69979804},{"atb":[[2.18,0]],"id":46251065}],"con":true,"img":false}]}
{"op":"mcm","clk":"11540715607","pt":1719497592271,"mc":[{"id":"1.230178314","rc":[{"atb":[[2.22,11.44]],"id":70466763},{"atb":[[2.22,8.8]],"id":45375136},{"atb":[[2.24,9.77]],"id":63994056},{"atb":[[2.24,10.66]],"id":69979804},{"atb":[[2.22,10.56]],"id":46251065}],"con":true,"img":false}]}
{"op":"mcm","clk":"11540715820","pt":1719497594692,"mc":[{"id":"1.230178314","rc":[{"atb":[[2.2,3.38]],"id":70466763},{"atb":[[2.2,3.38]],"id":45375136}],"con":true,"img":false}]}
{"op":"mcm","clk":"11540715843","pt":1719497594952,"mc":[{"id":"1.230178314","rc":[{"atb":[[2.22,3.38]],"id":63994056}],"con":true,"img":false}]}
{"op":"mcm","clk":"11540715852","pt":1719497595049,"mc":[{"id":"1.230178314","rc":[{"atb":[[2.22,3.38]],"id":69979804}],"con":true,"img":false}]}
{"op":"mcm","clk":"11540715867","pt":1719497595254,"mc":[{"id":"1.230178314","rc":[{"atb":[[2.2,3.38]],"id":46251065}],"con":true,"img":false}]}
{"op":"mcm","clk":"11540715877","pt":1719497595356,"mc":[{"id":"1.230178314","rc":[{"atb":[[2.24,3.15]],"id":70466763}],"con":true,"img":false}]}
{"op":"mcm","clk":"11540715884","pt":1719497595465,"mc":[{"id":"1.230178314","rc":[{"atb":[[2.24,3.15]],"id":45375136}],"con":true,"img":false}]}
{"op":"mcm","clk":"11540715902","pt":1719497595664,"mc":[{"id":"1.230178314","rc":[{"atb":[[2.26,3.15]],"id":69979804}],"con":true,"img":false}]}
{"op":"mcm","clk":"11540715915","pt":1719497595869,"mc":[{"id":"1.230178314","rc":[{"atb":[[2.24,3.15]],"id":46251065}],"con":true,"img":false}]}
{"op":"mcm","clk":"11540715965","pt":1719497596590,"mc":[{"id":"1.230178314","rc":[{"atb":[[2.26,3.15]],"id":63994056}],"con":true,"img":false}]}
{"op":"mcm","clk":"11540716175","pt":1719497599365,"mc":[{"id":"1.230178314","rc":[{"atb":[[2.2,0]],"id":45375136},{"atb":[[2.22,0]],"id":63994056}],"con":true,"img":false}]}
{"op":"mcm","clk":"11540716213","pt":1719497599777,"mc":[{"id":"1.230178314","rc":[{"atb":[[2.22,0]],"id":69979804}],"con":true,"img":false}]}
{"op":"mcm","clk":"11540716229","pt":1719497599981,"mc":[{"id":"1.230178314","rc":[{"atb":[[2.24,6.54]],"id":45375136}],"con":true,"img":false}]}
{"op":"mcm","clk":"11540716244","pt":1719497600083,"mc":[{"id":"1.230178314","rc":[{"atb":[[2.2,0]],"id":70466763}],"con":true,"img":false}]}
{"op":"mcm","clk":"11540716272","pt":1719497600493,"mc":[{"id":"1.230178314","rc":[{"atb":[[2.24,6.54]],"id":70466763}],"con":true,"img":false}]}
{"op":"mcm","clk":"11540716288","pt":1719497600651,"mc":[{"id":"1.230178314","rc":[{"atb":[[2.26,6.54]],"id":69979804}],"con":true,"img":false}]}
{"op":"mcm","clk":"11540716323","pt":1719497601064,"mc":[{"id":"1.230178314","rc":[{"atb":[[2.2,0]],"id":46251065}],"con":true,"img":false}]}
{"op":"mcm","clk":"11540716359","pt":1719497601575,"mc":[{"id":"1.230178314","rc":[{"atb":[[2.26,6.54]],"id":63994056}],"con":true,"img":false}]}
{"op":"mcm","clk":"11540716414","pt":1719497602345,"mc":[{"id":"1.230178314","rc":[{"atb":[[2.24,6.54]],"id":46251065}],"con":true,"img":false}]}
{"op":"mcm","clk":"11540723728","pt":1719497689559,"mc":[{"id":"1.230178314","rc":[{"atb":[[2.12,89.29]],"id":69979804}],"con":true,"img":false}]}
{"op":"mcm","clk":"11540741857","pt":1719497891871,"mc":[{"id":"1.230178314","rc":[{"atb":[[2.22,0]],"id":70466763},{"atb":[[2.22,0]],"id":45375136},{"atb":[[2.24,0]],"id":63994056},{"atb":[[2.24,0]],"id":69979804},{"atb":[[2.22,0]],"id":46251065}],"con":true,"img":false}]}
{"op":"mcm","clk":"11540741866","pt":1719497891964,"mc":[{"id":"1.230178314","rc":[{"atb":[[2.26,11.44]],"id":70466763},{"atb":[[2.26,8.8]],"id":45375136},{"atb":[[2.28,9.77]],"id":63994056},{"atb":[[2.28,10.66]],"id":69979804},{"atb":[[2.26,10.56]],"id":46251065}],"con":true,"img":false}]}
{"op":"mcm","clk":"11540742229","pt":1719497895887,"mc":[{"id":"1.230178314","rc":[{"atb":[[2.24,3.15]],"id":45375136}],"con":true,"img":false}]}
{"op":"mcm","clk":"11540742248","pt":1719497896094,"mc":[{"id":"1.230178314","rc":[{"atb":[[2.24,3.15]],"id":70466763}],"con":true,"img":false}]}
{"op":"mcm","clk":"11540742260","pt":1719497896196,"mc":[{"id":"1.230178314","rc":[{"atb":[[2.26,3.15]],"id":63994056}],"con":true,"img":false}]}
{"op":"mcm","clk":"11540742281","pt":1719497896401,"mc":[{"id":"1.230178314","rc":[{"atb":[[2.26,3.15]],"id":69979804}],"con":true,"img":false}]}
{"op":"mcm","clk":"11540742290","pt":1719497896456,"mc":[{"id":"1.230178314","rc":[{"atb":[[2.28,3.38]],"id":45375136}],"con":true,"img":false}]}
{"op":"mcm","clk":"11540742336","pt":1719497896867,"mc":[{"id":"1.230178314","rc":[{"atb":[[2.28,3.38]],"id":70466763},{"atb":[[2.24,3.15]],"id":46251065}],"con":true,"img":false}]}
{"op":"mcm","clk":"11540742366","pt":1719497897176,"mc":[{"id":"1.230178314","rc":[{"atb":[[2.3,3.38]],"id":63994056}],"con":true,"img":false}]}
{"op":"mcm","clk":"11540742387","pt":1719497897383,"mc":[{"id":"1.230178314","rc":[{"atb":[[2.3,3.38]],"id":69979804}],"con":true,"img":false}]}
{"op":"mcm","clk":"11540742395","pt":1719497897485,"mc":[{"id":"1.230178314","rc":[{"atb":[[2.28,3.38]],"id":46251065}],"con":true,"img":false}]}
{"op":"mcm","clk":"11540742404","pt":1719497897589,"mc":[{"id":"1.230178314","rc":[{"atb":[[2.24,0]],"id":45375136}],"con":true,"img":false}]}
{"op":"mcm","clk":"11540742431","pt":1719497897900,"mc":[{"id":"1.230178314","rc":[{"atb":[[2.24,0]],"id":46251065}],"con":true,"img":false}]}
{"op":"mcm","clk":"11540742459","pt":1719497898058,"mc":[{"id":"1.230178314","rc":[{"atb":[[2.26,0]],"id":63994056}],"con":true,"img":false}]}
{"op":"mcm","clk":"11540742478","pt":1719497898265,"mc":[{"id":"1.230178314","rc":[{"atb":[[2.24,0]],"id":70466763}],"con":true,"img":false}]}
{"op":"mcm","clk":"11540742530","pt":1719497898679,"mc":[{"id":"1.230178314","rc":[{"atb":[[2.28,6.54]],"id":45375136}],"con":true,"img":false}]}
{"op":"mcm","clk":"11540742539","pt":1719497898780,"mc":[{"id":"1.230178314","rc":[{"atb":[[2.26,0]],"id":69979804}],"con":true,"img":false}]}
{"op":"mcm","clk":"11540742595","pt":1719497899294,"mc":[{"id":"1.230178314","rc":[{"atb":[[2.28,6.54]],"id":46251065}],"con":true,"img":false}]}
{"op":"mcm","clk":"11540742626","pt":1719497899603,"mc":[{"id":"1.230178314","rc":[{"atb":[[2.28,6.54]],"id":70466763},{"atb":[[2.3,6.54]],"id":63994056}],"con":true,"img":false}]}
{"op":"mcm","clk":"11540742649","pt":1719497899756,"mc":[{"id":"1.230178314","rc":[{"atb":[[2.3,6.54]],"id":69979804}],"con":true,"img":false}]}
{"op":"mcm","clk":"11540768788","pt":1719498191985,"mc":[{"id":"1.230178314","rc":[{"atb":[[2.26,0]],"id":70466763},{"atb":[[2.26,0]],"id":45375136},{"atb":[[2.28,0]],"id":63994056},{"atb":[[2.28,0]],"id":69979804},{"atb":[[2.26,0]],"id":46251065}],"con":true,"img":false}]}
{"op":"mcm","clk":"11540768799","pt":1719498192086,"mc":[{"id":"1.230178314","rc":[{"atb":[[2.3,11.44]],"id":70466763},{"atb":[[2.3,8.8]],"id":45375136},{"atb":[[2.32,9.77]],"id":63994056},{"atb":[[2.32,10.66]],"id":69979804},{"atb":[[2.3,10.56]],"id":46251065}],"con":true,"img":false}]}
{"op":"mcm","clk":"11540769189","pt":1719498195493,"mc":[{"id":"1.230178314","rc":[{"atb":[[2.28,3.38]],"id":45375136}],"con":true,"img":false}]}
{"op":"mcm","clk":"11540769212","pt":1719498195701,"mc":[{"id":"1.230178314","rc":[{"atb":[[2.28,3.38]],"id":70466763},{"atb":[[2.28,3.38]],"id":46251065}],"con":true,"img":false}]}
{"op":"mcm","clk":"11540769241","pt":1719498196012,"mc":[{"id":"1.230178314","rc":[{"atb":[[2.3,3.38]],"id":69979804}],"con":true,"img":false}]}
{"op":"mcm","clk":"11540769265","pt":1719498196209,"mc":[{"id":"1.230178314","rc":[{"atb":[[2.32,3.15]],"id":45375136},{"atb":[[2.3,3.38]],"id":63994056}],"con":true,"img":false}]}
{"op":"mcm","clk":"11540769283","pt":1719498196376,"mc":[{"id":"1.230178314","rc":[{"atb":[[2.34,3.15]],"id":69979804}],"con":true,"img":false}]}
{"op":"mcm","clk":"11540769305","pt":1719498196580,"mc":[{"id":"1.230178314","rc":[{"atb":[[2.32,3.15]],"id":46251065}],"con":true,"img":false}]}
{"op":"mcm","clk":"11540769315","pt":1719498196687,"mc":[{"id":"1.230178314","rc":[{"atb":[[2.34,3.15]],"id":63994056}],"con":true,"img":false}]}
{"op":"mcm","clk":"11540769338","pt":1719498196894,"mc":[{"id":"1.230178314","rc":[{"atb":[[2.32,3.15]],"id":70466763}],"con":true,"img":false}]}
{"op":"mcm","clk":"11540770233","pt":1719498205204,"mc":[{"id":"1.230178314","rc":[{"atb":[[2.28,0]],"id":45375136}],"con":true,"img":false}]}
{"op":"mcm","clk":"11540770257","pt":1719498205416,"mc":[{"id":"1.230178314","rc":[{"atb":[[2.28,0]],"id":70466763}],"con":true,"img":false}]}
{"op":"mcm","clk":"11540770268","pt":1719498205611,"mc":[{"id":"1.230178314","rc":[{"atb":[[2.28,0]],"id":46251065}],"con":true,"img":false}]}
{"op":"mcm","clk":"11540770296","pt":1719498205872,"mc":[{"id":"1.230178314","rc":[{"atb":[[2.32,6.54]],"id":45375136},{"atb":[[2.3,0]],"id":69979804}],"con":true,"img":false}]}
{"op":"mcm","clk":"11540770335","pt":1719498206288,"mc":[{"id":"1.230178314","rc":[{"atb":[[2.3,0]],"id":63994056}],"con":true,"img":false}]}
{"op":"mcm","clk":"11540770345","pt":1719498206409,"mc":[{"id":"1.230178314","rc":[{"atb":[[2.32,6.54]],"id":46251065}],"con":true,"img":false}]}
{"op":"mcm","clk":"11540770369","pt":1719498206610,"mc":[{"id":"1.230178314","rc":[{"atb":[[2.32,6.54]],"id":70466763}],"con":true,"img":false}]}
{"op":"mcm","clk":"11540770398","pt":1719498206912,"mc":[{"id":"1.230178314","rc":[{"atb":[[2.34,6.54]],"id":69979804}],"con":true,"img":false}]}
{"op":"mcm","clk":"11540770536","pt":1719498208318,"mc":[{"id":"1.230178314","rc":[{"atb":[[2.34,6.54]],"id":63994056}],"con":true,"img":false}]}
{"op":"mcm","clk":"11540787595","pt":1719498378041,"mc":[{"id":"1.230178314","rc":[{"atl":[[190,4]],"id":70466763},{"atl":[[190,4]],"id":45375136},{"atl":[[190,4]],"id":63994056},{"atl":[[190,4]],"id":69979804},{"atl":[[190,4]],"id":46251065}],"con":true,"img":false}]}
{"op":"mcm","clk":"11540797821","pt":1719498491874,"mc":[{"id":"1.230178314","rc":[{"atb":[[2.3,0]],"id":70466763},{"atb":[[2.3,0]],"id":45375136},{"atb":[[2.32,0]],"id":63994056},{"atb":[[2.32,0]],"id":69979804},{"atb":[[2.3,0]],"id":46251065}],"con":true,"img":false}]}
{"op":"mcm","clk":"11540797831","pt":1719498491976,"mc":[{"id":"1.230178314","rc":[{"atb":[[2.34,11.44]],"id":70466763},{"atb":[[2.34,8.8]],"id":45375136},{"atb":[[2.36,9.77]],"id":63994056},{"atb":[[2.36,10.66]],"id":69979804},{"atb":[[2.34,10.56]],"id":46251065}],"con":true,"img":false}]}
{"op":"mcm","clk":"11540798673","pt":1719498500387,"mc":[{"id":"1.230178314","rc":[{"atb":[[2.32,3.38]],"id":70466763}],"con":true,"img":false}]}
{"op":"mcm","clk":"11540798692","pt":1719498500554,"mc":[{"id":"1.230178314","rc":[{"atb":[[2.32,3.38]],"id":45375136},{"atb":[[2.34,3.38]],"id":69979804}],"con":true,"img":false}]}
{"op":"mcm","clk":"11540798713","pt":1719498500759,"mc":[{"id":"1.230178314","rc":[{"atb":[[2.36,3.15]],"id":45375136}],"con":true,"img":false}]}
{"op":"mcm","clk":"11540798724","pt":1719498500862,"mc":[{"id":"1.230178314","rc":[{"atb":[[2.32,3.38]],"id":46251065}],"con":true,"img":false}]}
{"op":"mcm","clk":"11540798736","pt":1719498500970,"mc":[{"id":"1.230178314","rc":[{"atb":[[2.38,3.15]],"id":69979804}],"con":true,"img":false}]}
{"op":"mcm","clk":"11540798744","pt":1719498501066,"mc":[{"id":"1.230178314","rc":[{"atb":[[2.34,3.38]],"id":63994056}],"con":true,"img":false}]}
{"op":"mcm","clk":"11540798756","pt":1719498501159,"mc":[{"id":"1.230178314","rc":[{"atb":[[2.36,3.15]],"id":46251065}],"con":true,"img":false}]}
{"op":"mcm","clk":"11540798783","pt":1719498501470,"mc":[{"id":"1.230178314","rc":[{"atb":[[2.38,3.15]],"id":63994056}],"con":true,"img":false}]}
{"op":"mcm","clk":"11540798800","pt":1719498501677,"mc":[{"id":"1.230178314","rc":[{"atb":[[2.36,3.15]],"id":70466763}],"con":true,"img":false}]}
{"op":"mcm","clk":"11540799503","pt":1719498509390,"mc":[{"id":"1.230178314","rc":[{"atb":[[2.32,0]],"id":45375136}],"con":true,"img":false}]}
{"op":"mcm","clk":"11540799511","pt":1719498509493,"mc":[{"id":"1.230178314","rc":[{"atb":[[2.32,0]],"id":70466763}],"con":true,"img":false}]}
{"op":"mcm","clk":"11540799534","pt":1719498509698,"mc":[{"id":"1.230178314","rc":[{"atb":[[2.32,0]],"id":46251065}],"con":true,"img":false}]}
{"op":"mcm","clk":"11540799564","pt":1719498509971,"mc":[{"id":"1.230178314","rc":[{"atb":[[2.34,0]],"id":63994056}],"con":true,"img":false}]}
{"op":"mcm","clk":"11540799574","pt":1719498510075,"mc":[{"id":"1.230178314","rc":[{"atb":[[2.34,0]],"id":69979804}],"con":true,"img":false}]}
{"op":"mcm","clk":"11540799596","pt":1719498510271,"mc":[{"id":"1.230178314","rc":[{"atb":[[2.36,6.54]],"id":70466763}],"con":true,"img":false}]}
{"op":"mcm","clk":"11540799603","pt":1719498510376,"mc":[{"id":"1.230178314","rc":[{"atb":[[2.36,6.54]],"id":45375136}],"con":true,"img":false}]}
{"op":"mcm","clk":"11540799636","pt":1719498510682,"mc":[{"id":"1.230178314","rc":[{"atb":[[2.38,6.54]],"id":63994056}],"con":true,"img":false}]}
{"op":"mcm","clk":"11540799642","pt":1719498510787,"mc":[{"id":"1.230178314","rc":[{"atb":[[2.36,6.54]],"id":46251065}],"con":true,"img":false}]}
{"op":"mcm","clk":"11540799671","pt":1719498511096,"mc":[{"id":"1.230178314","rc":[{"atb":[[2.38,6.54]],"id":69979804}],"con":true,"img":false}]}
{"op":"mcm","clk":"11540812469","pt":1719498645529,"mc":[{"id":"1.230178314","rc":[{"atb":[[5.5,0]],"id":70466763},{"spn":77.5,"spf":"NaN","id":70466763},{"atb":[[4.8,0]],"id":45375136},{"atb":[[3.8,0]],"id":63994056},{"atb":[[4,0]],"id":69979804},{"atb":[[5,1]],"id":70940946},{"atb":[[4.8,0]],"id":46251065}],"con":true,"img":false}]}
{"op":"mcm","clk":"11540824003","pt":1719498784073,"mc":[{"id":"1.230178314","rc":[{"atb":[[2.94,7.5]],"id":69979804}],"con":true,"img":false}]}
{"op":"mcm","clk":"11540824023","pt":1719498784277,"mc":[{"id":"1.230178314","rc":[{"atb":[[2.94,0]],"id":69979804}],"con":true,"img":false}]}
{"op":"mcm","clk":"11540826342","pt":1719498814035,"mc":[{"id":"1.230178314","rc":[{"spl":[[1.01,2]],"id":70466763},{"spb":[[1000,22]],"id":45375136},{"spl":[[1.01,4]],"id":63994056},{"spl":[[1.01,2]],"id":69979804},{"spl":[[1.01,5]],"id":46251065}],"con":true,"img":false}]}
{"op":"mcm","clk":"11540826781","pt":1719498819554,"mc":[{"id":"1.230178314","rc":[{"spl":[[1.01,1]],"id":45375136}],"con":true,"img":false}]}
{"op":"mcm","clk":"11540827828","pt":1719498833415,"mc":[{"id":"1.230178314","rc":[{"atb":[[5,0]],"id":46251065},{"atl":[[5,14]],"id":46251065},{"trd":[[5,2]],"ltp":5.0,"tv":2.0,"id":46251065}],"con":true,"img":false}]}
{"op":"mcm","clk":"11540828017","pt":1719498835783,"mc":[{"id":"1.230178314","rc":[{"atb":[[4.5,1],[1.03,7.13]],"id":46251065}],"con":true,"img":false}]}
{"op":"mcm","clk":"11540828031","pt":1719498835991,"mc":[{"id":"1.230178314","rc":[{"atb":[[1.03,6.85]],"id":46251065}],"con":true,"img":false}]}
{"op":"mcm","clk":"11540828048","pt":1719498836149,"mc":[{"id":"1.230178314","rc":[{"atb":[[1.03,6.13]],"id":46251065}],"con":true,"img":false}]}
{"op":"mcm","clk":"11540828058","pt":1719498836303,"mc":[{"id":"1.230178314","rc":[{"atb":[[2.38,0.72]],"id":46251065}],"con":true,"img":false}]}
{"op":"mcm","clk":"11540828193","pt":1719498837950,"mc":[{"id":"1.230178314","rc":[{"atl":[[5,0]],"id":46251065}],"con":true,"img":false}]}
{"op":"mcm","clk":"11540828234","pt":1719498838568,"mc":[{"id":"1.230178314","rc":[{"atb":[[3.7,1]],"id":70940946}],"con":true,"img":false}]}
{"op":"mcm","clk":"11540828930","pt":1719498847385,"mc":[{"id":"1.230178314","rc":[{"spn":4.37,"spf":1.0,"id":70466763},{"spn":23.0,"spf":23.0,"id":45375136},{"spn":2.76,"spf":1.0,"id":63994056},{"spn":4.35,"spf":1.0,"id":69979804},{"atb":[[4.5,0]],"id":46251065},{"atl":[[4.5,2]],"id":46251065},{"trd":[[4.5,2]],"ltp":4.5,"tv":2.0,"id":46251065},{"spn":2.36,"spf":1.0,"id":46251065}],"con":true,"img":false}]}
{"op":"mcm","clk":"11540829129","pt":1719498849871,"mc":[{"id":"1.230178314","rc":[{"atl":[[4.5,0]],"id":46251065}],"con":true,"img":false}]}
{"op":"mcm","clk":"11540829238","pt":1719498850967,"mc":[{"id":"1.230178314","rc":[{"atb":[[4,1]],"id":46251065}],"con":true,"img":false}]}
{"op":"mcm","clk":"11540829280","pt":1719498851473,"mc":[{"id":"1.230178314","rc":[{"atb":[[2.38,0]],"id":46251065}],"con":true,"img":false}]}
{"op":"mcm","clk":"11540829360","pt":1719498852463,"mc":[{"id":"1.230178314","rc":[{"atl":[[1000,0.85]],"id":46251065}],"con":true,"img":false}]}
{"op":"mcm","clk":"11540829372","pt":1719498852669,"mc":[{"id":"1.230178314","rc":[{"atl":[[1000,0.84]],"id":46251065}],"con":true,"img":false}]}
{"op":"mcm","clk":"11540829383","pt":1719498852764,"mc":[{"id":"1.230178314","rc":[{"atl":[[140,0.01]],"id":46251065}],"con":true,"img":false}]}
{"op":"mcm","clk":"11540830324","pt":1719498863176,"mc":[{"id":"1.230178314","rc":[{"atb":[[4,0]],"id":46251065},{"atl":[[4,1]],"id":46251065},{"trd":[[4,2]],"ltp":4.0,"tv":2.0,"id":46251065}],"con":true,"img":false}]}
{"op":"mcm","clk":"11540830538","pt":1719498865290,"mc":[{"id":"1.230178314","rc":[{"atl":[[4,0]],"id":46251065}],"con":true,"img":false}]}
{"op":"mcm","clk":"11540830766","pt":1719498867891,"mc":[{"id":"1.230178314","rc":[{"atl":[[140,0]],"id":46251065}],"con":true,"img":false}]}
{"op":"mcm","clk":"11540830784","pt":1719498868085,"mc":[{"id":"1.230178314","rc":[{"atb":[[1.03,7.13]],"id":46251065},{"atl":[[1000,0.85]],"id":46251065}],"con":true,"img":false}]}
{"op":"mcm","clk":"11540830805","pt":1719498868292,"mc":[{"id":"1.230178314","rc":[{"atb":[[1.03,6.85]],"id":46251065},{"atl":[[1000,0.84]],"id":46251065}],"con":true,"img":false}]}
{"op":"mcm","clk":"11540830815","pt":1719498868393,"mc":[{"id":"1.230178314","rc":[{"atl":[[140,0.01]],"id":46251065}],"con":true,"img":false}]}
{"op":"mcm","clk":"11540830832","pt":1719498868603,"mc":[{"id":"1.230178314","rc":[{"atb":[[1.03,6.13]],"id":46251065}],"con":true,"img":false}]}
{"op":"mcm","clk":"11540830847","pt":1719498868702,"mc":[{"id":"1.230178314","rc":[{"atb":[[2.38,0.72]],"id":46251065}],"con":true,"img":false}]}
{"op":"mcm","clk":"11540830856","pt":1719498868806,"mc":[{"id":"1.230178314","rc":[{"atb":[[2.38,8.58]],"id":70466763}],"con":true,"img":false}]}
{"op":"mcm","clk":"11540830872","pt":1719498868908,"mc":[{"id":"1.230178314","rc":[{"atb":[[2.06,11.17]],"id":70940946}],"con":true,"img":false}]}
{"op":"mcm","clk":"11540830882","pt":1719498869011,"mc":[{"id":"1.230178314","rc":[{"atb":[[2.4,8.45]],"id":69979804}],"con":true,"img":false}]}
{"op":"mcm","clk":"11540832203","pt":1719498883222,"mc":[{"id":"1.230178314","rc":[{"atl":[[140,0.85]],"id":46251065}],"con":true,"img":false}]}
{"op":"mcm","clk":"11540832225","pt":1719498883518,"mc":[{"id":"1.230178314","rc":[{"atl":[[140,0.84]],"id":46251065}],"con":true,"img":false}]}
{"op":"mcm","clk":"11540832253","pt":1719498883900,"mc":[{"id":"1.230178314","rc":[{"atb":[[2.38,0]],"id":46251065}],"con":true,"img":false}]}
{"op":"mcm","clk":"11540832345","pt":1719498885307,"mc":[{"id":"1.230178314","rc":[{"atb":[[1.03,7.13]],"id":46251065},{"atl":[[1000,0.85]],"id":46251065}],"con":true,"img":false}]}
{"op":"mcm","clk":"11540832360","pt":1719498885502,"mc":[{"id":"1.230178314","rc":[{"atb":[[1.03,6.85]],"id":46251065},{"atl":[[1000,0.84]],"id":46251065}],"con":true,"img":false}]}
{"op":"mcm","clk":"11540832369","pt":1719498885606,"mc":[{"id":"1.230178314","rc":[{"atl":[[140,0.85]],"id":46251065}],"con":true,"img":false}]}
{"op":"mcm","clk":"11540832377","pt":1719498885708,"mc":[{"id":"1.230178314","rc":[{"atb":[[1.03,6.13]],"id":46251065}],"con":true,"img":false}]}
{"op":"mcm","clk":"11540832384","pt":1719498885811,"mc":[{"id":"1.230178314","rc":[{"atb":[[2.38,0.72]],"id":46251065}],"con":true,"img":false}]}
{"op":"mcm","clk":"11540833344","pt":1719498896507,"mc":[{"id":"1.230178314","rc":[{"atb":[[2.36,3.15]],"id":70466763}],"con":true,"img":false}]}
{"op":"mcm","clk":"11540833368","pt":1719498896826,"mc":[{"id":"1.230178314","rc":[{"atb":[[2.38,3.15]],"id":69979804},{"atb":[[1.52,22.78]],"id":46251065}],"con":true,"img":false}]}
{"op":"mcm","clk":"11540833479","pt":1719498898325,"mc":[{"id":"1.230178314","rc":[{"atb":[[2.4,3.38]],"id":70466763}],"con":true,"img":false}]}
{"op":"mcm","clk":"11540833548","pt":1719498899110,"mc":[{"id":"1.230178314","rc":[{"atb":[[2.42,3.38]],"id":69979804}],"con":true,"img":false}]}
{"op":"mcm","clk":"11540833710","pt":1719498900833,"mc":[{"id":"1.230178314","rc":[{"atl":[[140,0.84]],"id":46251065}],"con":true,"img":false}]}
{"op":"mcm","clk":"11540833728","pt":1719498901042,"mc":[{"id":"1.230178314","rc":[{"atb":[[2.38,0]],"id":46251065}],"con":true,"img":false}]}
{"op":"mcm","clk":"11540833749","pt":1719498901253,"mc":[{"id":"1.230178314","rc":[{"atb":[[1.03,7.13]],"id":46251065},{"atl":[[1000,0.85]],"id":46251065}],"con":true,"img":false}]}
{"op":"mcm","clk":"11540833768","pt":1719498901409,"mc":[{"id":"1.230178314","rc":[{"atb":[[1.03,6.85]],"id":46251065},{"atl":[[1000,0.84]],"id":46251065}],"con":true,"img":false}]}
{"op":"mcm","clk":"11540833778","pt":1719498901514,"mc":[{"id":"1.230178314","rc":[{"atl":[[140,0.85]],"id":46251065}],"con":true,"img":false}]}
{"op":"mcm","clk":"11540833792","pt":1719498901631,"mc":[{"id":"1.230178314","rc":[{"atb":[[1.03,6.13]],"id":46251065}],"con":true,"img":false}]}
{"op":"mcm","clk":"11540833797","pt":1719498901723,"mc":[{"id":"1.230178314","rc":[{"atb":[[2.38,0.72]],"id":46251065}],"con":true,"img":false}]}
{"op":"mcm","clk":"11540835091","pt":1719498916767,"mc":[{"id":"1.230178314","rc":[{"atl":[[140,0.84]],"id":46251065}],"con":true,"img":false}]}
{"op":"mcm","clk":"11540835104","pt":1719498916961,"mc":[{"id":"1.230178314","rc":[{"atb":[[2.38,0]],"id":46251065}],"con":true,"img":false}]}
{"op":"mcm","clk":"11540835300","pt":1719498918974,"mc":[{"id":"1.230178314","rc":[{"atb":[[1.03,7.13]],"id":46251065},{"atl":[[1000,0.85]],"id":46251065}],"con":true,"img":false}]}
{"op":"mcm","clk":"11540835310","pt":1719498919072,"mc":[{"id":"1.230178314","rc":[{"atb":[[1.03,6.85]],"id":46251065},{"atl":[[1000,0.84]],"id":46251065}],"con":true,"img":false}]}
{"op":"mcm","clk":"11540835319","pt":1719498919164,"mc":[{"id":"1.230178314","rc":[{"atl":[[140,0.85]],"id":46251065}],"con":true,"img":false}]}
{"op":"mcm","clk":"11540835330","pt":1719498919268,"mc":[{"id":"1.230178314","rc":[{"atb":[[1.03,6.13]],"id":46251065}],"con":true,"img":false}]}
{"op":"mcm","clk":"11540835341","pt":1719498919330,"mc":[{"id":"1.230178314","rc":[{"atb":[[2.38,0.72]],"id":46251065}],"con":true,"img":false}]}
{"op":"mcm","clk":"11540836616","pt":1719498934350,"mc":[{"id":"1.230178314","rc":[{"atl":[[140,0.84]],"id":46251065}],"con":true,"img":false}]}
{"op":"mcm","clk":"11540836644","pt":1719498934660,"mc":[{"id":"1.230178314","rc":[{"atb":[[2.38,0]],"id":46251065}],"con":true,"img":false}]}
{"op":"mcm","clk":"11540836681","pt":1719498935069,"mc":[{"id":"1.230178314","rc":[{"atb":[[1.03,7.13]],"id":46251065},{"atl":[[1000,0.85]],"id":46251065}],"con":true,"img":false}]}
{"op":"mcm","clk":"11540836704","pt":1719498935282,"mc":[{"id":"1.230178314","rc":[{"atb":[[1.03,6.85]],"id":46251065},{"atl":[[1000,0.84]],"id":46251065}],"con":true,"img":false}]}
{"op":"mcm","clk":"11540836715","pt":1719498935384,"mc":[{"id":"1.230178314","rc":[{"atl":[[140,0.85]],"id":46251065}],"con":true,"img":false}]}
{"op":"mcm","clk":"11540836730","pt":1719498935474,"mc":[{"id":"1.230178314","rc":[{"atb":[[1.03,6.13]],"id":46251065}],"con":true,"img":false}]}
{"op":"mcm","clk":"11540836740","pt":1719498935576,"mc":[{"id":"1.230178314","rc":[{"atb":[[2.38,0.72]],"id":46251065}],"con":true,"img":false}]}
{"op":"mcm","clk":"11540837571","pt":1719498943894,"mc":[{"id":"1.230178314","rc":[{"atb":[[2.4,13.35]],"id":70466763}],"con":true,"img":false}]}
{"op":"mcm","clk":"11540837624","pt":1719498944375,"mc":[{"id":"1.230178314","rc":[{"atb":[[2.42,13.22]],"id":69979804}],"con":true,"img":false}]}
{"op":"mcm","clk":"11540837632","pt":1719498944475,"mc":[{"id":"1.230178314","rc":[{"atb":[[2.08,12.93]],"id":70940946}],"con":true,"img":false}]}
{"op":"mcm","clk":"11540837661","pt":1719498944981,"mc":[{"id":"1.230178314","rc":[{"atb":[[2.48,2.09]],"id":70466763},{"atb":[[2.5,2.09]],"id":69979804},{"atb":[[2.16,2.09]],"id":70940946}],"con":true,"img":false}]}
{"op":"mcm","clk":"11540837734","pt":1719498945875,"mc":[{"id":"1.230178314","rc":[{"atb":[[2.38,0]],"id":70466763},{"atb":[[2.4,0]],"id":69979804}],"con":true,"img":false}]}
{"op":"mcm","clk":"11540838226","pt":1719498949488,"mc":[{"id":"1.230178314","rc":[{"atb":[[2.12,0]],"id":46251065}],"con":true,"img":false}]}
{"op":"mcm","clk":"11540838367","pt":1719498950487,"mc":[{"id":"1.230178314","rc":[{"atl":[[140,0.84]],"id":46251065}],"con":true,"img":false}]}
{"op":"mcm","clk":"11540838397","pt":1719498950682,"mc":[{"id":"1.230178314","rc":[{"atb":[[2.38,0]],"id":46251065}],"con":true,"img":false}]}
{"op":"mcm","clk":"11540838485","pt":1719498951513,"mc":[{"id":"1.230178314","rc":[{"atb":[[2.36,0]],"id":70466763}],"con":true,"img":false}]}
{"op":"mcm","clk":"11540838508","pt":1719498951722,"mc":[{"id":"1.230178314","rc":[{"atb":[[2.42,8.33]],"id":70466763}],"con":true,"img":false}]}
{"op":"mcm","clk":"11540838515","pt":1719498951825,"mc":[{"id":"1.230178314","rc":[{"atb":[[2.38,0]],"id":69979804}],"con":true,"img":false}]}
{"op":"mcm","clk":"11540838525","pt":1719498951890,"mc":[{"id":"1.230178314","rc":[{"atb":[[2.44,8.22]],"id":69979804}],"con":true,"img":false}]}
{"op":"mcm","clk":"11540838545","pt":1719498952086,"mc":[{"id":"1.230178314","rc":[{"atb":[[2.42,11.49]],"id":70466763}],"con":true,"img":false}]}
{"op":"mcm","clk":"11540838571","pt":1719498952400,"mc":[{"id":"1.230178314","rc":[{"atb":[[1.03,7.13]],"id":46251065},{"atl":[[1000,0.85]],"id":46251065}],"con":true,"img":false}]}
{"op":"mcm","clk":"11540838582","pt":1719498952507,"mc":[{"id":"1.230178314","rc":[{"atb":[[1.03,6.85]],"id":46251065},{"atl":[[1000,0.84]],"id":46251065}],"con":true,"img":false}]}
{"op":"mcm","clk":"11540838591","pt":1719498952613,"mc":[{"id":"1.230178314","rc":[{"atb":[[1.03,6.13]],"id":46251065},{"atl":[[140,0.85]],"id":46251065}],"con":true,"img":false}]}
{"op":"mcm","clk":"11540838600","pt":1719498952714,"mc":[{"id":"1.230178314","rc":[{"atb":[[2.44,11.38]],"id":69979804},{"atb":[[2.38,0.72]],"id":46251065}],"con":true,"img":false}]}
{"op":"mcm","clk":"11540839246","pt":1719498959403,"mc":[{"id":"1.230178314","rc":[{"atb":[[1.12,1.69]],"id":45375136}],"con":true,"img":false}]}
{"op":"mcm","clk":"11540839260","pt":1719498959508,"mc":[{"id":"1.230178314","rc":[{"atb":[[1.12,1.69]],"id":69979804}],"con":true,"img":false}]}
{"op":"mcm","clk":"11540839279","pt":1719498959714,"mc":[{"id":"1.230178314","rc":[{"atb":[[1.12,1.69]],"id":70466763}],"con":true,"img":false}]}
{"op":"mcm","clk":"11540839290","pt":1719498959818,"mc":[{"id":"1.230178314","rc":[{"atb":[[1.12,1.69]],"id":70940946}],"con":true,"img":false}]}
{"op":"mcm","clk":"11540839309","pt":1719498960025,"mc":[{"id":"1.230178314","rc":[{"atb":[[1.09,1.69]],"id":63994056}],"con":true,"img":false}]}
{"op":"mcm","clk":"11540839318","pt":1719498960129,"mc":[{"id":"1.230178314","rc":[{"atb":[[2.4,9.78]],"id":63994056},{"atl":[[60,2]],"id":63994056}],"con":true,"img":false}]}
{"op":"mcm","clk":"11540839330","pt":1719498960234,"mc":[{"id":"1.230178314","rc":[{"atb":[[3.15,11.5]],"id":70466763},{"atl":[[85,2]],"id":70466763},{"atb":[[2.38,8.8]],"id":45375136},{"atl":[[140,2]],"id":45375136},{"atb":[[2.52,11.39]],"id":69979804},{"atl":[[60,2]],"id":69979804},{"atb":[[2.18,11.17]],"id":70940946},{"atl":[[210,2]],"id":70940946},{"atb":[[2.5,6.55],[1.06,1.69]],"id":46251065},{"atl":[[140,2.85],[120,2]],"id":46251065}],"con":true,"img":false}]}
{"op":"mcm","clk":"11540839352","pt":1719498960389,"mc":[{"id":"1.230178314","rc":[{"atb":[[1.12,0.05]],"id":70466763},{"atb":[[1.12,0.05]],"id":69979804}],"con":true,"img":false}]}
{"op":"mcm","clk":"11540839387","pt":1719498960701,"mc":[{"id":"1.230178314","rc":[{"atb":[[1.12,0.05]],"id":45375136}],"con":true,"img":false}]}
{"op":"mcm","clk":"11540839405","pt":1719498960909,"mc":[{"id":"1.230178314","rc":[{"atl":[[140,0.85]],"id":46251065}],"con":true,"img":false}]}
{"op":"mcm","clk":"11540839414","pt":1719498961013,"mc":[{"id":"1.230178314","rc":[{"atb":[[1.09,0.07]],"id":63994056},{"atb":[[1.12,0.05]],"id":70940946}],"con":true,"img":false}]}
{"op":"mcm","clk":"11540839442","pt":1719498961323,"mc":[{"id":"1.230178314","rc":[{"atb":[[1.06,0.12]],"id":46251065}],"con":true,"img":false}]}
{"op":"mcm","clk":"11540839463","pt":1719498961529,"mc":[{"id":"1.230178314","rc":[{"atb":[[1.12,0]],"id":69979804}],"con":true,"img":false}]}
{"op":"mcm","clk":"11540839474","pt":1719498961593,"mc":[{"id":"1.230178314","rc":[{"atb":[[5.1,0.05]],"id":69979804}],"con":true,"img":false}]}
{"op":"mcm","clk":"11540839484","pt":1719498961701,"mc":[{"id":"1.230178314","rc":[{"atb":[[2.52,0]],"id":69979804}],"con":true,"img":false}]}
{"op":"mcm","clk":"11540839493","pt":1719498961801,"mc":[{"id":"1.230178314","rc":[{"atb":[[3.2,11.39]],"id":69979804}],"con":true,"img":false}]}
{"op":"mcm","clk":"11540839505","pt":1719498961894,"mc":[{"id":"1.230178314","rc":[{"atb":[[1.12,0]],"id":70466763}],"con":true,"img":false}]}
{"op":"mcm","clk":"11540839513","pt":1719498961999,"mc":[{"id":"1.230178314","rc":[{"atb":[[5.1,0.05]],"id":70466763},{"atl":[[1000,1.84]],"id":46251065}],"con":true,"img":false}]}
{"op":"mcm","clk":"11540839536","pt":1719498962205,"mc":[{"id":"1.230178314","rc":[{"atl":[[1000,0.86]],"id":46251065}],"con":true,"img":false}]}
{"op":"mcm","clk":"11540839560","pt":1719498962415,"mc":[{"id":"1.230178314","rc":[{"atl":[[1000,0.84]],"id":46251065}],"con":true,"img":false}]}
{"op":"mcm","clk":"11540839570","pt":1719498962518,"mc":[{"id":"1.230178314","rc":[{"atl":[[110,0.02]],"id":46251065}],"con":true,"img":false}]}
{"op":"mcm","clk":"11540839580","pt":1719498962622,"mc":[{"id":"1.230178314","rc":[{"atb":[[1.12,0]],"id":45375136}],"con":true,"img":false}]}
{"op":"mcm","clk":"11540839593","pt":1719498962728,"mc":[{"id":"1.230178314","rc":[{"atb":[[5.1,0.05]],"id":45375136}],"con":true,"img":false}]}
{"op":"mcm","clk":"11540839624","pt":1719498963001,"mc":[{"id":"1.230178314","rc":[{"atb":[[1.09,0]],"id":63994056}],"con":true,"img":false}]}
{"op":"mcm","clk":"11540839634","pt":1719498963092,"mc":[{"id":"1.230178314","rc":[{"atb":[[3.95,0.07]],"id":63994056}],"con":true,"img":false}]}
{"op":"mcm","clk":"11540839665","pt":1719498963402,"mc":[{"id":"1.230178314","rc":[{"atb":[[1.12,0]],"id":70940946}],"con":true,"img":false}]}
{"op":"mcm","clk":"11540839679","pt":1719498963504,"mc":[{"id":"1.230178314","rc":[{"atb":[[5.1,0.05]],"id":70940946}],"con":true,"img":false}]}
{"op":"mcm","clk":"11540839687","pt":1719498963607,"mc":[{"id":"1.230178314","rc":[{"atb":[[2.36,11.17],[2.18,0]],"id":70940946}],"con":true,"img":false}]}
{"op":"mcm","clk":"11540839712","pt":1719498963816,"mc":[{"id":"1.230178314","rc":[{"atb":[[1.06,0]],"id":46251065}],"con":true,"img":false}]}
{"op":"mcm","clk":"11540839719","pt":1719498963917,"mc":[{"id":"1.230178314","rc":[{"atb":[[2.38,0.84]],"id":46251065}],"con":true,"img":false}]}
{"op":"mcm","clk":"11540839870","pt":1719498965617,"mc":[{"id":"1.230178314","rc":[{"atl":[[9.4,1]],"id":69979804},{"atb":[[3.85,1]],"id":46251065},{"atl":[[11,1]],"id":46251065}],"con":true,"img":false}]}
{"op":"mcm","clk":"11540839918","pt":1719498966096,"mc":[{"id":"1.230178314","rc":[{"atl":[[110,0]],"id":46251065}],"con":true,"img":false}]}
{"op":"mcm","clk":"11540839932","pt":1719498966193,"mc":[{"id":"1.230178314","rc":[{"atl":[[10.5,0.02]],"id":46251065}],"con":true,"img":false}]}
{"op":"mcm","clk":"11540839964","pt":1719498966507,"mc":[{"id":"1.230178314","rc":[{"atl":[[9.2,1.65]],"id":69979804}],"con":true,"img":false}]}
{"op":"mcm","clk":"11540839980","pt":1719498966701,"mc":[{"id":"1.230178314","rc":[{"atl":[[11,4],[60,0]],"id":69979804}],"con":true,"img":false}]}
{"op":"mcm","clk":"11540839990","pt":1719498966803,"mc":[{"id":"1.230178314","rc":[{"atl":[[10.5,1.58]],"id":46251065}],"con":true,"img":false}]}
{"op":"mcm","clk":"11540840000","pt":1719498966909,"mc":[{"id":"1.230178314","rc":[{"atl":[[16,2.58],[120,0]],"id":46251065}],"con":true,"img":false}]}
{"op":"mcm","clk":"11540840099","pt":1719498967798,"mc":[{"id":"1.230178314","rc":[{"atb":[[2.38,0.12]],"id":46251065},{"atl":[[140,0.84]],"id":46251065}],"con":true,"img":false}]}
{"op":"mcm","clk":"11540840139","pt":1719498968207,"mc":[{"id":"1.230178314","rc":[{"atl":[[1000,0.95]],"id":46251065}],"con":true,"img":false}]}
{"op":"mcm","clk":"11540840155","pt":1719498968363,"mc":[{"id":"1.230178314","rc":[{"atl":[[1000,0.84]],"id":46251065}],"con":true,"img":false}]}
{"op":"mcm","clk":"11540840163","pt":1719498968414,"mc":[{"id":"1.230178314","rc":[{"atl":[[10,0.11]],"id":46251065}],"con":true,"img":false}]}
{"op":"mcm","clk":"11540840207","pt":1719498968834,"mc":[{"id":"1.230178314","rc":[{"atb":[[2.36,3.38]],"id":45375136}],"con":true,"img":false}]}
{"op":"mcm","clk":"11540840228","pt":1719498968998,"mc":[{"id":"1.230178314","rc":[{"atb":[[2.36,3.38]],"id":46251065}],"con":true,"img":false}]}
{"op":"mcm","clk":"11540840237","pt":1719498969102,"mc":[{"id":"1.230178314","rc":[{"atb":[[2.38,3.38]],"id":63994056},{"atl":[[10.5,1.56]],"id":46251065}],"con":true,"img":false}]}
{"op":"mcm","clk":"11540840243","pt":1719498969200,"mc":[{"id":"1.230178314","rc":[{"atl":[[9.8,0.02]],"id":46251065}],"con":true,"img":false}]}
{"op":"mcm","clk":"11540840261","pt":1719498969404,"mc":[{"id":"1.230178314","rc":[{"atb":[[2.42,8.33]],"id":70466763},{"atb":[[2.44,8.22]],"id":69979804},{"atb":[[2.52,3.15]],"id":46251065}],"con":true,"img":false}]}
{"op":"mcm","clk":"11540840279","pt":1719498969610,"mc":[{"id":"1.230178314","rc":[{"atb":[[2.4,3.15]],"id":45375136}],"con":true,"img":false}]}
{"op":"mcm","clk":"11540840316","pt":1719498970022,"mc":[{"id":"1.230178314","rc":[{"atb":[[2.42,3.15]],"id":63994056}],"con":true,"img":false}]}
{"op":"mcm","clk":"11540840514","pt":1719498972204,"mc":[{"id":"1.230178314","rc":[{"atl":[[10,2.11]],"id":46251065}],"con":true,"img":false}]}
{"op":"mcm","clk":"11540840786","pt":1719498975608,"mc":[{"id":"1.230178314","rc":[{"atl":[[10.5,0]],"id":46251065}],"con":true,"img":false}]}
{"op":"mcm","clk":"11540840837","pt":1719498976330,"mc":[{"id":"1.230178314","rc":[{"atb":[[2.36,0]],"id":45375136}],"con":true,"img":false}]}
{"op":"mcm","clk":"11540840856","pt":1719498976536,"mc":[{"id":"1.230178314","rc":[{"atb":[[2.4,9.97]],"id":70466763},{"atb":[[2.42,9.83]],"id":69979804}],"con":true,"img":false}]}
{"op":"mcm","clk":"11540840895","pt":1719498977021,"mc":[{"id":"1.230178314","rc":[{"spn":4.41,"spf":1.0,"id":70466763},{"atb":[[2.38,0]],"id":63994056},{"spn":2.81,"spf":1.0,"id":63994056},{"spn":4.39,"spf":1.0,"id":69979804},{"spn":107.55,"spf":"NaN","id":70940946},{"spn":2.78,"spf":1.0,"id":46251065}],"con":true,"img":false}]}
{"op":"mcm","clk":"11540840932","pt":1719498977322,"mc":[{"id":"1.230178314","rc":[{"atb":[[2.4,6.54]],"id":45375136},{"atl":[[10,0.11]],"id":46251065}],"con":true,"img":false}]}
{"op":"mcm","clk":"11540840964","pt":1719498977632,"mc":[{"id":"1.230178314","rc":[{"atb":[[2.42,6.54]],"id":63994056},{"atb":[[2.06,0]],"id":70940946}],"con":true,"img":false}]}
{"op":"mcm","clk":"11540841129","pt":1719498979543,"mc":[{"id":"1.230178314","rc":[{"atl":[[10.5,2]],"id":46251065}],"con":true,"img":false}]}
{"op":"mcm","clk":"11540841296","pt":1719498981521,"mc":[{"id":"1.230178314","rc":[{"atl":[[10,1.76]],"id":46251065}],"con":true,"img":false}]}
{"op":"mcm","clk":"11540841375","pt":1719498982642,"mc":[{"id":"1.230178314","rc":[{"atl":[[70,2],[85,0]],"id":70466763},{"atl":[[44,2.33]],"id":63994056},{"atl":[[11,0]],"id":69979804},{"atl":[[230,1]],"id":70940946},{"atl":[[16,0],[14,2.76]],"id":46251065}],"con":true,"img":false}]}
{"op":"mcm","clk":"11540841384","pt":1719498982747,"mc":[{"id":"1.230178314","rc":[{"atl":[[12,1]],"id":70466763},{"atl":[[140,0],[10.5,1],[100,2]],"id":45375136},{"atl":[[7.4,1],[60,0]],"id":63994056},{"atl":[[9.6,4]],"id":69979804},{"atl":[[200,2],[210,0]],"id":70940946}],"con":true,"img":false}]}
{"op":"mcm","clk":"11540841468","pt":1719498983629,"mc":[{"id":"1.230178314","rc":[{"atl":[[10,1.65]],"id":46251065}],"con":true,"img":false}]}
{"op":"mcm","clk":"11540841489","pt":1719498983838,"mc":[{"id":"1.230178314","rc":[{"atl":[[1000,0.95]],"id":46251065}],"con":true,"img":false}]}
{"op":"mcm","clk":"11540841501","pt":1719498983940,"mc":[{"id":"1.230178314","rc":[{"atl":[[1000,0.84]],"id":46251065}],"con":true,"img":false}]}
{"op":"mcm","clk":"11540841512","pt":1719498984042,"mc":[{"id":"1.230178314","rc":[{"atl":[[9.8,0.13]],"id":46251065}],"con":true,"img":false}]}
{"op":"mcm","clk":"11540841580","pt":1719498984817,"mc":[{"id":"1.230178314","rc":[{"atl":[[10.5,0]],"id":46251065}],"con":true,"img":false}]}
{"op":"mcm","clk":"11540841784","pt":1719498987029,"mc":[{"id":"1.230178314","rc":[{"atl":[[9.8,2.13]],"id":46251065}],"con":true,"img":false}]}
{"op":"mcm","clk":"11540841832","pt":1719498987644,"mc":[{"id":"1.230178314","rc":[{"atl":[[10,0]],"id":46251065}],"con":true,"img":false}]}
{"op":"mcm","clk":"11540841952","pt":1719498988729,"mc":[{"id":"1.230178314","rc":[{"atb":[[2.38,8.58]],"id":70940946}],"con":true,"img":false}]}
{"op":"mcm","clk":"11540842245","pt":1719498992242,"mc":[{"id":"1.230178314","rc":[{"atl":[[9.8,0.13]],"id":46251065}],"con":true,"img":false}]}
{"op":"mcm","clk":"11540842284","pt":1719498992719,"mc":[{"id":"1.230178314","rc":[{"atl":[[220,1],[230,0]],"id":70940946}],"con":true,"img":false}]}
{"op":"mcm","clk":"11540842381","pt":1719498993744,"mc":[{"id":"1.230178314","rc":[{"atl":[[10.5,1.63]],"id":46251065}],"con":true,"img":false}]}
{"op":"mcm","clk":"11540842424","pt":1719498994316,"mc":[{"id":"1.230178314","rc":[{"atl":[[10,2]],"id":46251065}],"con":true,"img":false}]}
{"op":"mcm","clk":"11540842592","pt":1719498996752,"mc":[{"id":"1.230178314","rc":[{"atl":[[10.5,0]],"id":46251065}],"con":true,"img":false}]}
{"op":"mcm","clk":"11540842776","pt":1719498999130,"mc":[{"id":"1.230178314","rc":[{"atl":[[9.8,0.02]],"id":46251065}],"con":true,"img":false}]}
{"op":"mcm","clk":"11540842809","pt":1719498999543,"mc":[{"id":"1.230178314","rc":[{"atl":[[10,0]],"id":46251065}],"con":true,"img":false}]}
{"op":"mcm","clk":"11540842853","pt":1719499000056,"mc":[{"id":"1.230178314","rc":[{"atl":[[1000,0.95]],"id":46251065}],"con":true,"img":false}]}
{"op":"mcm","clk":"11540842869","pt":1719499000263,"mc":[{"id":"1.230178314","rc":[{"atb":[[2.42,0]],"id":70466763},{"atb":[[1.52,0]],"id":46251065},{"atl":[[1000,0.84]],"id":46251065}],"con":true,"img":false}]}
{"op":"mcm","clk":"11540842880","pt":1719499000327,"mc":[{"id":"1.230178314","rc":[{"atl":[[10.5,0.11]],"id":46251065}],"con":true,"img":false}]}
{"op":"mcm","clk":"11540842985","pt":1719499001723,"mc":[{"id":"1.230178314","rc":[{"atl":[[10.5,2.11]],"id":46251065}],"con":true,"img":false}]}
{"op":"mcm","clk":"11540843082","pt":1719499002748,"mc":[{"id":"1.230178314","rc":[{"atl":[[10,1.62]],"id":46251065}],"con":true,"img":false}]}
{"op":"mcm","clk":"11540843114","pt":1719499003165,"mc":[{"id":"1.230178314","rc":[{"atl":[[10.5,0.11]],"id":46251065}],"con":true,"img":false}]}
{"op":"mcm","clk":"11540843411","pt":1719499007243,"mc":[{"id":"1.230178314","rc":[{"atb":[[3.2,5.38]],"id":70466763}],"con":true,"img":false}]}
{"op":"mcm","clk":"11540843433","pt":1719499007450,"mc":[{"id":"1.230178314","rc":[{"atb":[[2.4,0]],"id":70466763},{"atb":[[2.42,0]],"id":69979804},{"atb":[[2.08,0]],"id":70940946}],"con":true,"img":false}]}
{"op":"mcm","clk":"11540843562","pt":1719499009255,"mc":[{"id":"1.230178314","rc":[{"atl":[[9.8,2.02]],"id":46251065}],"con":true,"img":false}]}
{"op":"mcm","clk":"11540843744","pt":1719499011850,"mc":[{"id":"1.230178314","rc":[{"atl":[[10,0]],"id":46251065}],"con":true,"img":false}]}
{"op":"mcm","clk":"11540843959","pt":1719499014555,"mc":[{"id":"1.230178314","rc":[{"atl":[[9.8,0.02]],"id":46251065}],"con":true,"img":false}]}
{"op":"mcm","clk":"11540843974","pt":1719499014761,"mc":[{"id":"1.230178314","rc":[{"atl":[[9.6,1.74]],"id":46251065}],"con":true,"img":false}]}
{"op":"mcm","clk":"11540844020","pt":1719499015341,"mc":[{"id":"1.230178314","rc":[{"atl":[[9.8,0]],"id":46251065}],"con":true,"img":false}]}
{"op":"mcm","clk":"11540844024","pt":1719499015433,"mc":[{"id":"1.230178314","rc":[{"atl":[[10.5,0],[9.4,0.02]],"id":46251065}],"con":true,"img":false}]}
{"op":"mcm","clk":"11540844036","pt":1719499015640,"mc":[{"id":"1.230178314","rc":[{"atl":[[1000,0.96]],"id":46251065}],"con":true,"img":false}]}
{"op":"mcm","clk":"11540844054","pt":1719499015845,"mc":[{"id":"1.230178314","rc":[{"atl":[[1000,0.84]],"id":46251065}],"con":true,"img":false}]}
{"op":"mcm","clk":"11540844065","pt":1719499015947,"mc":[{"id":"1.230178314","rc":[{"atl":[[9.6,1.86]],"id":46251065}],"con":true,"img":false}]}
{"op":"mcm","clk":"11540844143","pt":1719499017145,"mc":[{"id":"1.230178314","rc":[{"atl":[[9.4,2.02]],"id":46251065}],"con":true,"img":false}]}
{"op":"mcm","clk":"11540844213","pt":1719499017963,"mc":[{"id":"1.230178314","rc":[{"atl":[[9.6,0.12]],"id":46251065}],"con":true,"img":false}]}
{"op":"mcm","clk":"11540844449","pt":1719499020852,"mc":[{"id":"1.230178314","rc":[{"atl":[[9.2,1.72]],"id":46251065}],"con":true,"img":false}]}
{"op":"mcm","clk":"11540844490","pt":1719499021472,"mc":[{"id":"1.230178314","rc":[{"atl":[[9.4,2]],"id":46251065}],"con":true,"img":false}]}
{"op":"mcm","clk":"11540844494","pt":1719499021575,"mc":[{"id":"1.230178314","rc":[{"atl":[[9,0.02]],"id":46251065}],"con":true,"img":false}]}
{"op":"mcm","clk":"11540844507","pt":1719499021783,"mc":[{"id":"1.230178314","rc":[{"atb":[[3.2,11.73]],"id":70466763},{"atb":[[2.46,9.56]],"id":69979804}],"con":true,"img":false}]}
{"op":"mcm","clk":"11540844555","pt":1719499022352,"mc":[{"id":"1.230178314","rc":[{"atl":[[9.4,0]],"id":46251065}],"con":true,"img":false}]}
{"op":"mcm","clk":"11540844728","pt":1719499024575,"mc":[{"id":"1.230178314","rc":[{"atl":[[9,2.02]],"id":46251065}],"con":true,"img":false}]}
{"op":"mcm","clk":"11540844938","pt":1719499026850,"mc":[{"id":"1.230178314","rc":[{"atl":[[9.2,0]],"id":46251065}],"con":true,"img":false}]}
{"op":"mcm","clk":"11540845175","pt":1719499029686,"mc":[{"id":"1.230178314","rc":[{"atl":[[9,0.02]],"id":46251065}],"con":true,"img":false}]}
{"op":"mcm","clk":"11540845302","pt":1719499031179,"mc":[{"id":"1.230178314","rc":[{"atl":[[9.6,0]],"id":46251065}],"con":true,"img":false}]}
{"op":"mcm","clk":"11540845361","pt":1719499031963,"mc":[{"id":"1.230178314","rc":[{"atl":[[10.5,2]],"id":46251065}],"con":true,"img":false}]}
{"op":"mcm","clk":"11540845436","pt":1719499032888,"mc":[{"id":"1.230178314","rc":[{"atl":[[10,1.61],[1000,0.95]],"id":46251065}],"con":true,"img":false}]}
{"op":"mcm","clk":"11540845447","pt":1719499032991,"mc":[{"id":"1.230178314","rc":[{"atl":[[1000,0.84]],"id":46251065}],"con":true,"img":false}]}
{"op":"mcm","clk":"11540845454","pt":1719499033053,"mc":[{"id":"1.230178314","rc":[{"atl":[[10,1.72]],"id":46251065}],"con":true,"img":false}]}
{"op":"mcm","clk":"11540845787","pt":1719499037275,"mc":[{"id":"1.230178314","rc":[{"spn":11.91,"spf":23.0,"id":45375136},{"spn":102.55,"spf":"NaN","id":70940946},{"atl":[[10.5,0]],"id":46251065}],"con":true,"img":false}]}
{"op":"mcm","clk":"11540845942","pt":1719499039388,"mc":[{"id":"1.230178314","rc":[{"atl":[[9.8,2]],"id":46251065}],"con":true,"img":false}]}
{"op":"mcm","clk":"11540846157","pt":1719499041987,"mc":[{"id":"1.230178314","rc":[{"atl":[[10,0.11]],"id":46251065}],"con":true,"img":false}]}
{"op":"mcm","clk":"11540846271","pt":1719499043377,"mc":[{"id":"1.230178314","rc":[{"atb":[[2.44,0]],"id":69979804}],"con":true,"img":false}]}
{"op":"mcm","clk":"11540846324","pt":1719499043895,"mc":[{"id":"1.230178314","rc":[{"atb":[[2.48,8]],"id":69979804}],"con":true,"img":false}]}
{"op":"mcm","clk":"11540846402","pt":1719499044680,"mc":[{"id":"1.230178314","rc":[{"atl":[[9.8,0]],"id":46251065}],"con":true,"img":false}]}
{"op":"mcm","clk":"11540846569","pt":1719499046886,"mc":[{"id":"1.230178314","rc":[{"atl":[[10.5,2]],"id":46251065}],"con":true,"img":false}]}
{"op":"mcm","clk":"11540846678","pt":1719499048307,"mc":[{"id":"1.230178314","rc":[{"atl":[[10,0]],"id":46251065}],"con":true,"img":false}]}
{"op":"mcm","clk":"11540846695","pt":1719499048477,"mc":[{"id":"1.230178314","rc":[{"atl":[[1000,0.95]],"id":46251065}],"con":true,"img":false}]}
{"op":"mcm","clk":"11540846702","pt":1719499048576,"mc":[{"id":"1.230178314","rc":[{"atl":[[1000,0.84]],"id":46251065}],"con":true,"img":false}]}
{"op":"mcm","clk":"11540846709","pt":1719499048684,"mc":[{"id":"1.230178314","rc":[{"atl":[[10,0.11]],"id":46251065}],"con":true,"img":false}]}
{"op":"mcm","clk":"11540846970","pt":1719499052103,"mc":[{"id":"1.230178314","rc":[{"atl":[[10.5,0]],"id":46251065}],"con":true,"img":false}]}
{"op":"mcm","clk":"11540847115","pt":1719499053879,"mc":[{"id":"1.230178314","rc":[{"atl":[[10.5,2]],"id":46251065}],"con":true,"img":false}]}
{"op":"mcm","clk":"11540847296","pt":1719499056398,"mc":[{"id":"1.230178314","rc":[{"atl":[[10,1.84]],"id":46251065}],"con":true,"img":false}]}
{"op":"mcm","clk":"11540847521","pt":1719499059100,"mc":[{"id":"1.230178314","rc":[{"atl":[[10.5,0]],"id":46251065}],"con":true,"img":false}]}
{"op":"mcm","clk":"11540847682","pt":1719499061404,"mc":[{"id":"1.230178314","rc":[{"atb":[[2.4,9.97]],"id":70940946},{"atl":[[9.8,2]],"id":46251065}],"con":true,"img":false}]}
{"op":"mcm","clk":"11540847799","pt":1719499063010,"mc":[{"id":"1.230178314","rc":[{"atl":[[10,0.11]],"id":46251065}],"con":true,"img":false}]}
{"op":"mcm","clk":"11540847880","pt":1719499063902,"mc":[{"id":"1.230178314","rc":[{"atl":[[10,0]],"id":46251065}],"con":true,"img":false}]}
{"op":"mcm","clk":"11540847904","pt":1719499064210,"mc":[{"id":"1.230178314","rc":[{"atl":[[1000,0.96]],"id":46251065}],"con":true,"img":false}]}
{"op":"mcm","clk":"11540847921","pt":1719499064405,"mc":[{"id":"1.230178314","rc":[{"atl":[[1000,0.84]],"id":46251065}],"con":true,"img":false}]}
{"op":"mcm","clk":"11540847928","pt":1719499064508,"mc":[{"id":"1.230178314","rc":[{"atl":[[9.6,0.12]],"id":46251065}],"con":true,"img":false}]}
{"op":"mcm","clk":"11540848016","pt":1719499065599,"mc":[{"id":"1.230178314","rc":[{"atl":[[9.6,0.96]],"id":46251065}],"con":true,"img":false}]}
{"op":"mcm","clk":"11540848094","pt":1719499066623,"mc":[{"id":"1.230178314","rc":[{"atl":[[9.8,0]],"id":46251065}],"con":true,"img":false}]}
{"op":"mcm","clk":"11540848137","pt":1719499067195,"mc":[{"id":"1.230178314","rc":[{"atl":[[9.6,0.12]],"id":46251065}],"con":true,"img":false}]}
{"op":"mcm","clk":"11540848267","pt":1719499068897,"mc":[{"id":"1.230178314","rc":[{"atl":[[10.5,2]],"id":46251065}],"con":true,"img":false}]}
{"op":"mcm","clk":"11540848279","pt":1719499069001,"mc":[{"id":"1.230178314","rc":[{"atl":[[10.5,3.53]],"id":46251065}],"con":true,"img":false}]}
{"op":"mcm","clk":"11540848547","pt":1719499072620,"mc":[{"id":"1.230178314","rc":[{"atl":[[10,0.84]],"id":46251065}],"con":true,"img":false}]}
{"op":"mcm","clk":"11540848690","pt":1719499074089,"mc":[{"id":"1.230178314","rc":[{"atl":[[10.5,1.53]],"id":46251065}],"con":true,"img":false}]}
{"op":"mcm","clk":"11540848842","pt":1719499076314,"mc":[{"id":"1.230178314","rc":[{"atl":[[10,2.84]],"id":46251065}],"con":true,"img":false}]}
{"op":"mcm","clk":"11540848955","pt":1719499078014,"mc":[{"id":"1.230178314","rc":[{"atl":[[10.5,0]],"id":46251065}],"con":true,"img":false}]}
{"op":"mcm","clk":"11540849075","pt":1719499079717,"mc":[{"id":"1.230178314","rc":[{"atl":[[9.6,0]],"id":46251065}],"con":true,"img":false}]}
{"op":"mcm","clk":"11540849092","pt":1719499079931,"mc":[{"id":"1.230178314","rc":[{"atl":[[1000,0.95]],"id":46251065}],"con":true,"img":false}]}
{"op":"mcm","clk":"11540849099","pt":1719499080017,"mc":[{"id":"1.230178314","rc":[{"atb":[[5.1,0]],"id":45375136},{"atl":[[1000,0.84]],"id":46251065}],"con":true,"img":false}]}
{"op":"mcm","clk":"11540849112","pt":1719499080134,"mc":[{"id":"1.230178314","rc":[{"atl":[[9.8,0.11]],"id":46251065}],"con":true,"img":false}]}
{"op":"mcm","clk":"11540849121","pt":1719499080222,"mc":[{"id":"1.230178314","rc":[{"atb":[[5.1,0]],"id":70466763}],"con":true,"img":false}]}
{"op":"mcm","clk":"11540849127","pt":1719499080325,"mc":[{"id":"1.230178314","rc":[{"atb":[[5.1,0]],"id":70940946}],"con":true,"img":false}]}
{"op":"mcm","clk":"11540849156","pt":1719499080616,"mc":[{"id":"1.230178314","rc":[{"atb":[[5.1,0]],"id":69979804},{"atb":[[2.38,0]],"id":46251065}],"con":true,"img":false}]}
{"op":"mcm","clk":"11540849184","pt":1719499080915,"mc":[{"id":"1.230178314","rc":[{"atb":[[1.12,1.69]],"id":70466763},{"atb":[[3.95,0]],"id":63994056}],"con":true,"img":false}]}
{"op":"mcm","clk":"11540849202","pt":1719499081122,"mc":[{"id":"1.230178314","rc":[{"atb":[[1.09,1.69]],"id":46251065}],"con":true,"img":false}]}
{"op":"mcm","clk":"11540849220","pt":1719499081322,"mc":[{"id":"1.230178314","rc":[{"atb":[[1.12,0.05]],"id":70466763},{"atb":[[1.12,1.69]],"id":45375136}],"con":true,"img":false}]}
{"op":"mcm","clk":"11540849237","pt":1719499081534,"mc":[{"id":"1.230178314","rc":[{"atb":[[1.12,1.69]],"id":70940946},{"atl":[[10,0.84]],"id":46251065}],"con":true,"img":false}]}
{"op":"mcm","clk":"11540849246","pt":1719499081598,"mc":[{"id":"1.230178314","rc":[{"atb":[[1.12,1.69]],"id":69979804}],"con":true,"img":false}]}
{"op":"mcm","clk":"11540849260","pt":1719499081807,"mc":[{"id":"1.230178314","rc":[{"atb":[[1.09,0.07]],"id":46251065}],"con":true,"img":false}]}
{"op":"mcm","clk":"11540849268","pt":1719499081923,"mc":[{"id":"1.230178314","rc":[{"atb":[[1.12,0.05]],"id":45375136}],"con":true,"img":false}]}
{"op":"mcm","clk":"11540849286","pt":1719499082131,"mc":[{"id":"1.230178314","rc":[{"atb":[[1.12,0]],"id":70466763},{"atl":[[10,0]],"id":46251065}],"con":true,"img":false}]}
{"op":"mcm","clk":"11540849297","pt":1719499082234,"mc":[{"id":"1.230178314","rc":[{"atb":[[5.1,0.05]],"id":70466763},{"atb":[[1.09,1.69]],"id":63994056}],"con":true,"img":false}]}
{"op":"mcm","clk":"11540849311","pt":1719499082664,"mc":[{"id":"1.230178314","rc":[{"atb":[[1.12,0.05]],"id":69979804}],"con":true,"img":false}]}
{"op":"mcm","clk":"11540849325","pt":1719499082727,"mc":[{"id":"1.230178314","rc":[{"atb":[[1.09,0]],"id":46251065}],"con":true,"img":false}]}
{"op":"mcm","clk":"11540849332","pt":1719499082746,"mc":[{"id":"1.230178314","rc":[{"atb":[[3.9,0.07]],"id":46251065}],"con":true,"img":false}]}
{"op":"mcm","clk":"11540849348","pt":1719499083037,"mc":[{"id":"1.230178314","rc":[{"atb":[[1.12,0]],"id":45375136},{"atb":[[1.12,0.05]],"id":70940946}],"con":true,"img":false}]}
{"op":"mcm","clk":"11540849357","pt":1719499083113,"mc":[{"id":"1.230178314","rc":[{"atb":[[5.1,0.05]],"id":45375136}],"con":true,"img":false}]}
{"op":"mcm","clk":"11540849389","pt":1719499083421,"mc":[{"id":"1.230178314","rc":[{"atb":[[1.09,0.07]],"id":63994056}],"con":true,"img":false}]}
{"op":"mcm","clk":"11540849418","pt":1719499083725,"mc":[{"id":"1.230178314","rc":[{"atb":[[1.12,0]],"id":69979804},{"atl":[[10.5,2]],"id":46251065}],"con":true,"img":false}]}
{"op":"mcm","clk":"11540849425","pt":1719499083827,"mc":[{"id":"1.230178314","rc":[{"atb":[[5.1,0.05]],"id":69979804}],"con":true,"img":false}]}
{"op":"mcm","clk":"11540849443","pt":1719499084121,"mc":[{"id":"1.230178314","rc":[{"atl":[[10,0.84],[10.5,3.67]],"id":46251065}],"con":true,"img":false}]}
{"op":"mcm","clk":"11540849450","pt":1719499084227,"mc":[{"id":"1.230178314","rc":[{"atb":[[1.12,0]],"id":70940946}],"con":true,"img":false}]}
{"op":"mcm","clk":"11540849456","pt":1719499084339,"mc":[{"id":"1.230178314","rc":[{"atb":[[5.1,0.05]],"id":70940946}],"con":true,"img":false}]}
{"op":"mcm","clk":"11540849478","pt":1719499084638,"mc":[{"id":"1.230178314","rc":[{"atb":[[1.09,0]],"id":63994056}],"con":true,"img":false}]}
{"op":"mcm","clk":"11540849487","pt":1719499084701,"mc":[{"id":"1.230178314","rc":[{"atb":[[3.95,0.07]],"id":63994056}],"con":true,"img":false}]}
{"op":"mcm","clk":"11540849601","pt":1719499085930,"mc":[{"id":"1.230178314","rc":[{"atb":[[3.5,11.5],[3.15,0]],"id":70466763},{"atb":[[2.56,8.8],[2.38,0]],"id":45375136},{"atb":[[3.45,8.01],[3.2,0]],"id":69979804},{"atl":[[200,0],[210,2]],"id":70940946},{"atb":[[3.85,0],[2.5,0],[2.6,3.39],[3.55,1]],"id":46251065}],"con":true,"img":false}]}
{"op":"mcm","clk":"11540849802","pt":1719499088115,"mc":[{"id":"1.230178314","rc":[{"atb":[[2.46,0]],"id":69979804}],"con":true,"img":false}]}
{"op":"mcm","clk":"11540849862","pt":1719499088933,"mc":[{"id":"1.230178314","rc":[{"atl":[[10.5,1.67]],"id":46251065}],"con":true,"img":false}]}
{"op":"mcm","clk":"11540850023","pt":1719499091041,"mc":[{"id":"1.230178314","rc":[{"atl":[[10,2.84]],"id":46251065}],"con":true,"img":false}]}
{"op":"mcm","clk":"11540850158","pt":1719499093126,"mc":[{"id":"1.230178314","rc":[{"atl":[[10.5,0]],"id":46251065}],"con":true,"img":false}]}
{"op":"mcm","clk":"11540850220","pt":1719499093837,"mc":[{"id":"1.230178314","rc":[{"atb":[[2.38,0]],"id":70940946}],"con":true,"img":false}]}
{"op":"mcm","clk":"11540850312","pt":1719499094830,"mc":[{"id":"1.230178314","rc":[{"spl":[[1.01,5]],"id":45375136}],"con":true,"img":false}]}
{"op":"mcm","clk":"11540850346","pt":1719499095336,"mc":[{"id":"1.230178314","rc":[{"atl":[[9.8,0]],"id":46251065}],"con":true,"img":false}]}
{"op":"mcm","clk":"11540850416","pt":1719499096229,"mc":[{"id":"1.230178314","rc":[{"atl":[[10,0.84]],"id":46251065}],"con":true,"img":false}]}
{"op":"mcm","clk":"11540850440","pt":1719499096533,"mc":[{"id":"1.230178314","rc":[{"atl":[[1000,0.95]],"id":46251065}],"con":true,"img":false}]}
{"op":"mcm","clk":"11540850450","pt":1719499096635,"mc":[{"id":"1.230178314","rc":[{"atl":[[10,0]],"id":46251065}],"con":true,"img":false}]}
{"op":"mcm","clk":"11540850456","pt":1719499096732,"mc":[{"id":"1.230178314","rc":[{"atl":[[1000,0.84]],"id":46251065}],"con":true,"img":false}]}
{"op":"mcm","clk":"11540850462","pt":1719499096833,"mc":[{"id":"1.230178314","rc":[{"atl":[[10.5,0.11]],"id":46251065}],"con":true,"img":false}]}
{"op":"mcm","clk":"11540850561","pt":1719499098436,"mc":[{"id":"1.230178314","rc":[{"spn":5.4,"spf":5.4,"id":45375136},{"spn":107.55,"spf":"NaN","id":70940946},{"atl":[[10.5,2.11]],"id":46251065},{"spn":2.8,"spf":1.0,"id":46251065}],"con":true,"img":false}]}
{"op":"mcm","clk":"11540850613","pt":1719499099146,"mc":[{"id":"1.230178314","rc":[{"atl":[[10,2.57]],"id":46251065}],"con":true,"img":false}]}
{"op":"mcm","clk":"11540850691","pt":1719499100032,"mc":[{"id":"1.230178314","rc":[{"atb":[[2.4,3.15]],"id":45375136}],"con":true,"img":false}]}
{"op":"mcm","clk":"11540850696","pt":1719499100134,"mc":[{"id":"1.230178314","rc":[{"atb":[[2.5,11.41]],"id":69979804}],"con":true,"img":false}]}
{"op":"mcm","clk":"11540850750","pt":1719499100746,"mc":[{"id":"1.230178314","rc":[{"atb":[[2.58,3.38]],"id":45375136}],"con":true,"img":false}]}
{"op":"mcm","clk":"11540850917","pt":1719499102634,"mc":[{"id":"1.230178314","rc":[{"atb":[[2.4,0]],"id":45375136}],"con":true,"img":false}]}
{"op":"mcm","clk":"11540850940","pt":1719499102942,"mc":[{"id":"1.230178314","rc":[{"atb":[[2.58,6.54]],"id":45375136}],"con":true,"img":false}]}
{"op":"mcm","clk":"11540850947","pt":1719499103043,"mc":[{"id":"1.230178314","rc":[{"atb":[[2.42,8.33]],"id":70940946}],"con":true,"img":false}]}
{"op":"mcm","clk":"11540850966","pt":1719499103253,"mc":[{"id":"1.230178314","rc":[{"atb":[[2.52,0]],"id":46251065}],"con":true,"img":false}]}
{"op":"mcm","clk":"11540850999","pt":1719499103658,"mc":[{"id":"1.230178314","rc":[{"atl":[[10.5,0.11]],"id":46251065}],"con":true,"img":false}]}
{"op":"mcm","clk":"11540851170","pt":1719499105758,"mc":[{"id":"1.230178314","rc":[{"atl":[[9.8,2]],"id":46251065}],"con":true,"img":false}]}
{"op":"mcm","clk":"11540851200","pt":1719499106148,"mc":[{"id":"1.230178314","rc":[{"atl":[[9.6,0.84]],"id":46251065}],"con":true,"img":false}]}
{"op":"mcm","clk":"11540851355","pt":1719499108282,"mc":[{"id":"1.230178314","rc":[{"atl":[[10,0.84]],"id":46251065}],"con":true,"img":false}]}
{"op":"mcm","clk":"11540851538","pt":1719499110951,"mc":[{"id":"1.230178314","rc":[{"atl":[[9.8,0]],"id":46251065}],"con":true,"img":false}]}
{"op":"mcm","clk":"11540851591","pt":1719499111732,"mc":[{"id":"1.230178314","rc":[{"atl":[[9.6,0]],"id":46251065}],"con":true,"img":false}]}
{"op":"mcm","clk":"11540851621","pt":1719499112050,"mc":[{"id":"1.230178314","rc":[{"atl":[[10.5,0]],"id":46251065}],"con":true,"img":false}]}
{"op":"mcm","clk":"11540851631","pt":1719499112149,"mc":[{"id":"1.230178314","rc":[{"atl":[[10,0]],"id":46251065}],"con":true,"img":false}]}
{"op":"mcm","clk":"11540851642","pt":1719499112254,"mc":[{"id":"1.230178314","rc":[{"atl":[[1000,0.95]],"id":46251065}],"con":true,"img":false}]}
{"op":"mcm","clk":"11540851656","pt":1719499112466,"mc":[{"id":"1.230178314","rc":[{"atl":[[1000,0.84]],"id":46251065}],"con":true,"img":false}]}
{"op":"mcm","clk":"11540851665","pt":1719499112555,"mc":[{"id":"1.230178314","rc":[{"atl":[[9.8,0.11]],"id":46251065}],"con":true,"img":false}]}
{"op":"mcm","clk":"11540851702","pt":1719499113133,"mc":[{"id":"1.230178314","rc":[{"atl":[[10.5,2]],"id":46251065}],"con":true,"img":false}]}
{"op":"mcm","clk":"11540851735","pt":1719499113650,"mc":[{"id":"1.230178314","rc":[{"atl":[[10,0.84]],"id":46251065}],"con":true,"img":false}]}
{"op":"mcm","clk":"11540851764","pt":1719499114154,"mc":[{"id":"1.230178314","rc":[{"atl":[[10,2.5]],"id":46251065}],"con":true,"img":false}]}
{"op":"mcm","clk":"11540851825","pt":1719499114932,"mc":[{"id":"1.230178314","rc":[{"atl":[[10.5,0]],"id":46251065}],"con":true,"img":false}]}
{"op":"mcm","clk":"11540852196","pt":1719499120458,"mc":[{"id":"1.230178314","rc":[{"atl":[[9.8,2.11]],"id":46251065}],"con":true,"img":false}]}
{"op":"mcm","clk":"11540852242","pt":1719499121170,"mc":[{"id":"1.230178314","rc":[{"atl":[[9.6,0.84]],"id":46251065}],"con":true,"img":false}]}
{"op":"mcm","clk":"11540852251","pt":1719499121270,"mc":[{"id":"1.230178314","rc":[{"atb":[[2.36,6.54]],"id":46251065}],"con":true,"img":false}]}
{"op":"mcm","clk":"11540852390","pt":1719499123251,"mc":[{"id":"1.230178314","rc":[{"atl":[[10,0.84]],"id":46251065}],"con":true,"img":false}]}
{"op":"mcm","clk":"11540852520","pt":1719499125469,"mc":[{"id":"1.230178314","rc":[{"atb":[[3.2,5.38]],"id":70466763},{"atb":[[2.4,0]],"id":70940946}],"con":true,"img":false}]}
{"op":"mcm","clk":"11540852543","pt":1719499125675,"mc":[{"id":"1.230178314","rc":[{"atl":[[9.8,0.11]],"id":46251065}],"con":true,"img":false}]}
{"op":"mcm","clk":"11540852569","pt":1719499126079,"mc":[{"id":"1.230178314","rc":[{"atb":[[3.2,0]],"id":70466763},{"atb":[[2.48,0]],"id":69979804}],"con":true,"img":false}]}
{"op":"mcm","clk":"11540852576","pt":1719499126180,"mc":[{"id":"1.230178314","rc":[{"atl":[[9.6,0],[9.8,1.81]],"id":46251065}],"con":true,"img":false}]}
{"op":"mcm","clk":"11540852692","pt":1719499127778,"mc":[{"id":"1.230178314","rc":[{"atl":[[9.8,1.7]],"id":46251065}],"con":true,"img":false}]}
{"op":"mcm","clk":"11540852698","pt":1719499127881,"mc":[{"id":"1.230178314","rc":[{"atl":[[9.6,2]],"id":46251065}],"con":true,"img":false}]}
{"op":"mcm","clk":"11540852718","pt":1719499128149,"mc":[{"id":"1.230178314","rc":[{"atl":[[10,0],[9.4,0.84]],"id":46251065}],"con":true,"img":false}]}
{"op":"mcm","clk":"11540852795","pt":1719499129387,"mc":[{"id":"1.230178314","rc":[{"atl":[[1000,0.96]],"id":46251065}],"con":true,"img":false}]}
{"op":"mcm","clk":"11540852811","pt":1719499129590,"mc":[{"id":"1.230178314","rc":[{"atl":[[9.8,0]],"id":46251065}],"con":true,"img":false}]}
{"op":"mcm","clk":"11540852819","pt":1719499129657,"mc":[{"id":"1.230178314","rc":[{"atl":[[1000,0.84]],"id":46251065}],"con":true,"img":false}]}
{"op":"mcm","clk":"11540852828","pt":1719499129758,"mc":[{"id":"1.230178314","rc":[{"atl":[[9.4,0.96]],"id":46251065}],"con":true,"img":false}]}
{"op":"mcm","clk":"11540852967","pt":1719499131786,"mc":[{"id":"1.230178314","rc":[{"atb":[[2.36,8.71]],"id":70466763}],"con":true,"img":false}]}
{"op":"mcm","clk":"11540852976","pt":1719499131886,"mc":[{"id":"1.230178314","rc":[{"atb":[[2.42,7.33]],"id":63994056},{"atb":[[2.6,4.17]],"id":46251065}],"con":true,"img":false}]}
{"op":"mcm","clk":"11540852984","pt":1719499131981,"mc":[{"id":"1.230178314","rc":[{"atb":[[2.52,7.79]],"id":69979804}],"con":true,"img":false}]}
{"op":"mcm","clk":"11540853051","pt":1719499133167,"mc":[{"id":"1.230178314","rc":[{"atl":[[9.6,0]],"id":46251065}],"con":true,"img":false}]}
{"op":"mcm","clk":"11540853091","pt":1719499133789,"mc":[{"id":"1.230178314","rc":[{"atl":[[9.4,0.12]],"id":46251065}],"con":true,"img":false}]}
{"op":"mcm","clk":"11540853177","pt":1719499135277,"mc":[{"id":"1.230178314","rc":[{"atl":[[10.5,1.61]],"id":46251065}],"con":true,"img":false}]}
{"op":"mcm","clk":"11540853203","pt":1719499135687,"mc":[{"id":"1.230178314","rc":[{"atl":[[10,0.84]],"id":46251065}],"con":true,"img":false}]}
{"op":"mcm","clk":"11540853226","pt":1719499135996,"mc":[{"id":"1.230178314","rc":[{"atl":[[10,2.84]],"id":46251065}],"con":true,"img":false}]}
{"op":"mcm","clk":"11540853377","pt":1719499138287,"mc":[{"id":"1.230178314","rc":[{"atl":[[10.5,0]],"id":46251065}],"con":true,"img":false}]}
{"op":"mcm","clk":"11540853577","pt":1719499141170,"mc":[{"id":"1.230178314","rc":[{"atl":[[10,0.84]],"id":46251065}],"con":true,"img":false}]}
{"op":"mcm","clk":"11540853594","pt":1719499141380,"mc":[{"id":"1.230178314","rc":[{"atl":[[9.8,1.64]],"id":46251065}],"con":true,"img":false}]}
{"op":"mcm","clk":"11540853628","pt":1719499141797,"mc":[{"id":"1.230178314","rc":[{"atl":[[10,0]],"id":46251065}],"con":true,"img":false}]}
{"op":"mcm","clk":"11540853698","pt":1719499142672,"mc":[{"id":"1.230178314","rc":[{"atl":[[9.6,0.84]],"id":46251065}],"con":true,"img":false}]}
{"op":"mcm","clk":"11540853757","pt":1719499143400,"mc":[{"id":"1.230178314","rc":[{"atl":[[9.6,2.84]],"id":46251065}],"con":true,"img":false}]}
{"op":"mcm","clk":"11540853837","pt":1719499144388,"mc":[{"id":"1.230178314","rc":[{"atl":[[9.8,0]],"id":46251065}],"con":true,"img":false}]}
{"op":"mcm","clk":"11540853889","pt":1719499144995,"mc":[{"id":"1.230178314","rc":[{"atl":[[9.4,0]],"id":46251065}],"con":true,"img":false}]}
{"op":"mcm","clk":"11540853908","pt":1719499145200,"mc":[{"id":"1.230178314","rc":[{"atl":[[1000,0.96]],"id":46251065}],"con":true,"img":false}]}
{"op":"mcm","clk":"11540853925","pt":1719499145406,"mc":[{"id":"1.230178314","rc":[{"atl":[[1000,0.84]],"id":46251065}],"con":true,"img":false}]}
{"op":"mcm","clk":"11540853932","pt":1719499145474,"mc":[{"id":"1.230178314","rc":[{"atl":[[9.4,0.12]],"id":46251065}],"con":true,"img":false}]}
{"op":"mcm","clk":"11540854074","pt":1719499147273,"mc":[{"id":"1.230178314","rc":[{"atl":[[9.4,1.73]],"id":46251065}],"con":true,"img":false}]}
{"op":"mcm","clk":"11540854170","pt":1719499148606,"mc":[{"id":"1.230178314","rc":[{"atl":[[9.6,0.84]],"id":46251065}],"con":true,"img":false}]}
{"op":"mcm","clk":"11540854284","pt":1719499150104,"mc":[{"id":"1.230178314","rc":[{"atl":[[9.2,0.84]],"id":46251065}],"con":true,"img":false}]}
{"op":"mcm","clk":"11540854338","pt":1719499150685,"mc":[{"id":"1.230178314","rc":[{"atl":[[9.2,2.84]],"id":46251065}],"con":true,"img":false}]}
{"op":"mcm","clk":"11540854373","pt":1719499151198,"mc":[{"id":"1.230178314","rc":[{"atl":[[9.6,0]],"id":46251065}],"con":true,"img":false}]}
{"op":"mcm","clk":"11540854539","pt":1719499153511,"mc":[{"id":"1.230178314","rc":[{"atl":[[9.4,0.12]],"id":46251065}],"con":true,"img":false}]}
{"op":"mcm","clk":"11540854699","pt":1719499155995,"mc":[{"id":"1.230178314","rc":[{"atl":[[9.2,0.84]],"id":46251065}],"con":true,"img":false}]}
{"op":"mcm","clk":"11540854746","pt":1719499156602,"mc":[{"id":"1.230178314","rc":[{"atl":[[9.2,0]],"id":46251065}],"con":true,"img":false}]}
{"op":"mcm","clk":"11540854851","pt":1719499158401,"mc":[{"id":"1.230178314","rc":[{"atl":[[10.5,2]],"id":46251065}],"con":true,"img":false}]}
{"op":"mcm","clk":"11540854863","pt":1719499158608,"mc":[{"id":"1.230178314","rc":[{"atl":[[10,0.84]],"id":46251065},{"spn":2.8,"spf":1.0,"id":46251065}],"con":true,"img":false}]}
{"op":"mcm","clk":"11540854869","pt":1719499158711,"mc":[{"id":"1.230178314","rc":[{"atb":[[5.2,1.62]],"id":70466763},{"atb":[[5.2,1.62]],"id":45375136}],"con":true,"img":false}]}
{"op":"mcm","clk":"11540854877","pt":1719499158815,"mc":[{"id":"1.230178314","rc":[{"atb":[[2.56,0],[3.9,8.8]],"id":45375136}],"con":true,"img":false}]}
{"op":"mcm","clk":"11540854917","pt":1719499159291,"mc":[{"id":"1.230178314","rc":[{"atb":[[5.1,1.68],[5.2,0]],"id":45375136}],"con":true,"img":false}]}
{"op":"mcm","clk":"11540854921","pt":1719499159390,"mc":[{"id":"1.230178314","rc":[{"atl":[[10,2.43]],"id":46251065}],"con":true,"img":false}]}
{"op":"mcm","clk":"11540854933","pt":1719499159808,"mc":[{"id":"1.230178314","rc":[{"atl":[[10.5,0]],"id":46251065}],"con":true,"img":false}]}
{"op":"mcm","clk":"11540854936","pt":1719499159902,"mc":[{"id":"1.230178314","rc":[{"atb":[[5.1,1.68],[5.2,0]],"id":70466763}],"con":true,"img":false}]}
{"op":"mcm","clk":"11540854983","pt":1719499160683,"mc":[{"id":"1.230178314","rc":[{"atl":[[9.4,0]],"id":46251065}],"con":true,"img":false}]}
{"op":"mcm","clk":"11540854994","pt":1719499160885,"mc":[{"id":"1.230178314","rc":[{"atl":[[1000,0.95]],"id":46251065}],"con":true,"img":false}]}
{"op":"mcm","clk":"11540855018","pt":1719499161203,"mc":[{"id":"1.230178314","rc":[{"atl":[[1000,0.84]],"id":46251065}],"con":true,"img":false}]}
{"op":"mcm","clk":"11540855028","pt":1719499161308,"mc":[{"id":"1.230178314","rc":[{"atl":[[10,2.54]],"id":46251065}],"con":true,"img":false}]}
{"op":"mcm","clk":"11540855075","pt":1719499161914,"mc":[{"id":"1.230178314","rc":[{"atb":[[2.42,0]],"id":70940946}],"con":true,"img":false}]}
{"op":"mcm","clk":"11540855420","pt":1719499166006,"mc":[{"id":"1.230178314","rc":[{"atl":[[9.8,2]],"id":46251065}],"con":true,"img":false}]}
{"op":"mcm","clk":"11540855466","pt":1719499166614,"mc":[{"id":"1.230178314","rc":[{"atl":[[9.6,0.84]],"id":46251065}],"con":true,"img":false}]}
{"op":"mcm","clk":"11540855588","pt":1719499168497,"mc":[{"id":"1.230178314","rc":[{"atl":[[10,0.95]],"id":46251065}],"con":true,"img":false}]}
{"op":"mcm","clk":"11540855620","pt":1719499169004,"mc":[{"id":"1.230178314","rc":[{"atb":[[2.58,3.38]],"id":45375136}],"con":true,"img":false}]}
{"op":"mcm","clk":"11540855633","pt":1719499169217,"mc":[{"id":"1.230178314","rc":[{"atb":[[2.38,8.58]],"id":70940946}],"con":true,"img":false}]}
{"op":"mcm","clk":"11540855791","pt":1719499171235,"mc":[{"id":"1.230178314","rc":[{"atl":[[9.8,0]],"id":46251065}],"con":true,"img":false}]}
{"op":"mcm","clk":"11540855826","pt":1719499171618,"mc":[{"id":"1.230178314","rc":[{"atl":[[9.6,0]],"id":46251065}],"con":true,"img":false}]}
{"op":"mcm","clk":"11540855870","pt":1719499172226,"mc":[{"id":"1.230178314","rc":[{"atl":[[10,0.11]],"id":46251065}],"con":true,"img":false}]}
{"op":"mcm","clk":"11540855964","pt":1719499173428,"mc":[{"id":"1.230178314","rc":[{"atl":[[10.5,2]],"id":46251065}],"con":true,"img":false}]}
{"op":"mcm","clk":"11540856025","pt":1719499174198,"mc":[{"id":"1.230178314","rc":[{"atl":[[10,0.95]],"id":46251065}],"con":true,"img":false}]}
{"op":"mcm","clk":"11540856045","pt":1719499174508,"mc":[{"id":"1.230178314","rc":[{"atl":[[10,2.58]],"id":46251065}],"con":true,"img":false}]}
{"op":"mcm","clk":"11540856202","pt":1719499176516,"mc":[{"id":"1.230178314","rc":[{"atl":[[10,2.47]],"id":46251065}],"con":true,"img":false}]}
{"op":"mcm","clk":"11540856260","pt":1719499177504,"mc":[{"id":"1.230178314","rc":[{"atl":[[1000,0.95]],"id":46251065}],"con":true,"img":false}]}
{"op":"mcm","clk":"11540856277","pt":1719499177707,"mc":[{"id":"1.230178314","rc":[{"atl":[[1000,0.84]],"id":46251065}],"con":true,"img":false}]}
{"op":"mcm","clk":"11540856289","pt":1719499177809,"mc":[{"id":"1.230178314","rc":[{"atl":[[9.8,0.11]],"id":46251065}],"con":true,"img":false}]}
{"op":"mcm","clk":"11540856353","pt":1719499178635,"mc":[{"id":"1.230178314","rc":[{"atl":[[10.5,0]],"id":46251065}],"con":true,"img":false}]}
{"op":"mcm","clk":"11540856455","pt":1719499179821,"mc":[{"id":"1.230178314","rc":[{"atb":[[2.5,2.09]],"id":69979804}],"con":true,"img":false}]}
{"op":"mcm","clk":"11540856517","pt":1719499180739,"mc":[{"id":"1.230178314","rc":[{"atl":[[9.8,2.11]],"id":46251065}],"con":true,"img":false}]}
{"op":"mcm","clk":"11540856575","pt":1719499181632,"mc":[{"id":"1.230178314","rc":[{"atl":[[9.6,0.84]],"id":46251065}],"con":true,"img":false}]}
{"op":"mcm","clk":"11540856725","pt":1719499183608,"mc":[{"id":"1.230178314","rc":[{"atl":[[10,0.84]],"id":46251065}],"con":true,"img":false}]}
{"op":"mcm","clk":"11540856913","pt":1719499186051,"mc":[{"id":"1.230178314","rc":[{"atl":[[9.8,0.11]],"id":46251065}],"con":true,"img":false}]}
{"op":"mcm","clk":"11540856965","pt":1719499186724,"mc":[{"id":"1.230178314","rc":[{"atl":[[9.6,0]],"id":46251065}],"con":true,"img":false}]}
{"op":"mcm","clk":"11540856997","pt":1719499187252,"mc":[{"id":"1.230178314","rc":[{"atl":[[10,0]],"id":46251065}],"con":true,"img":false}]}
{"op":"mcm","clk":"11540857034","pt":1719499187719,"mc":[{"id":"1.230178314","rc":[{"atl":[[9,0.84]],"id":69979804},{"atl":[[140,0]],"id":46251065}],"con":true,"img":false}]}
{"op":"mcm","clk":"11540857051","pt":1719499188040,"mc":[{"id":"1.230178314","rc":[{"atl":[[10.5,2]],"id":46251065}],"con":true,"img":false}]}
{"op":"mcm","clk":"11540857059","pt":1719499188132,"mc":[{"id":"1.230178314","rc":[{"atl":[[9,1.69]],"id":69979804}],"con":true,"img":false}]}
{"op":"mcm","clk":"11540857115","pt":1719499188754,"mc":[{"id":"1.230178314","rc":[{"atl":[[10,0.84]],"id":46251065}],"con":true,"img":false}]}
{"op":"mcm","clk":"11540857185","pt":1719499189736,"mc":[{"id":"1.230178314","rc":[{"atl":[[9.2,0]],"id":69979804}],"con":true,"img":false}]}
{"op":"mcm","clk":"11540857212","pt":1719499190052,"mc":[{"id":"1.230178314","rc":[{"atl":[[10,2.47]],"id":46251065}],"con":true,"img":false}]}
{"op":"mcm","clk":"11540857254","pt":1719499190614,"mc":[{"id":"1.230178314","rc":[{"atl":[[10.5,0]],"id":46251065}],"con":true,"img":false}]}
{"op":"mcm","clk":"11540857435","pt":1719499193043,"mc":[{"id":"1.230178314","rc":[{"atb":[[2.58,0]],"id":45375136},{"atl":[[9.8,0]],"id":46251065}],"con":true,"img":false}]}
{"op":"mcm","clk":"11540857462","pt":1719499193300,"mc":[{"id":"1.230178314","rc":[{"atb":[[2.38,10.12]],"id":70466763},{"atl":[[1000,0.95]],"id":46251065}],"con":true,"img":false}]}
{"op":"mcm","clk":"11540857473","pt":1719499193425,"mc":[{"id":"1.230178314","rc":[{"atl":[[1000,0.84]],"id":46251065}],"con":true,"img":false}]}
{"op":"mcm","clk":"11540857482","pt":1719499193508,"mc":[{"id":"1.230178314","rc":[{"atb":[[2.54,9.06]],"id":69979804},{"atl":[[9.8,0.11]],"id":46251065}],"con":true,"img":false}]}
{"op":"mcm","clk":"11540857668","pt":1719499195472,"mc":[{"id":"1.230178314","rc":[{"atl":[[9.8,2.11]],"id":46251065}],"con":true,"img":false}]}
{"op":"mcm","clk":"11540857734","pt":1719499196144,"mc":[{"id":"1.230178314","rc":[{"atl":[[9.6,0.84]],"id":46251065}],"con":true,"img":false}]}
{"op":"mcm","clk":"11540857949","pt":1719499198848,"mc":[{"id":"1.230178314","rc":[{"atl":[[10,0.84]],"id":46251065}],"con":true,"img":false}]}
{"op":"mcm","clk":"11540858080","pt":1719499200630,"mc":[{"id":"1.230178314","rc":[{"atl":[[9.8,0.11]],"id":46251065}],"con":true,"img":false}]}
{"op":"mcm","clk":"11540858114","pt":1719499201249,"mc":[{"id":"1.230178314","rc":[{"atl":[[9.6,0]],"id":46251065}],"con":true,"img":false}]}
{"op":"mcm","clk":"11540858141","pt":1719499201622,"mc":[{"id":"1.230178314","rc":[{"atb":[[5.1,1.62]],"id":70466763}],"con":true,"img":false}]}
{"op":"mcm","clk":"11540858149","pt":1719499201722,"mc":[{"id":"1.230178314","rc":[{"atl":[[10,0],[10.5,1.64]],"id":46251065}],"con":true,"img":false}]}
{"op":"mcm","clk":"11540858165","pt":1719499202034,"mc":[{"id":"1.230178314","rc":[{"atb":[[5.1,1.62]],"id":45375136}],"con":true,"img":false}]}
{"op":"mcm","clk":"11540858171","pt":1719499202139,"mc":[{"id":"1.230178314","rc":[{"atb":[[3.9,0]],"id":46251065}],"con":true,"img":false}]}
{"op":"mcm","clk":"11540858185","pt":1719499202348,"mc":[{"id":"1.230178314","rc":[{"atb":[[1.12,1.69]],"id":70466763}],"con":true,"img":false}]}
{"op":"mcm","clk":"11540858199","pt":1719499202458,"mc":[{"id":"1.230178314","rc":[{"atb":[[1.08,1.69]],"id":46251065}],"con":true,"img":false}]}
{"op":"mcm","clk":"11540858208","pt":1719499202556,"mc":[{"id":"1.230178314","rc":[{"atb":[[1.12,1.69]],"id":45375136}],"con":true,"img":false}]}
{"op":"mcm","clk":"11540858225","pt":1719499202713,"mc":[{"id":"1.230178314","rc":[{"atl":[[10,2]],"id":46251065}],"con":true,"img":false}]}
{"op":"mcm","clk":"11540858236","pt":1719499202821,"mc":[{"id":"1.230178314","rc":[{"atb":[[5.1,0]],"id":70940946}],"con":true,"img":false}]}
{"op":"mcm","clk":"11540858261","pt":1719499203134,"mc":[{"id":"1.230178314","rc":[{"atb":[[1.08,0.08]],"id":46251065}],"con":true,"img":false}]}
{"op":"mcm","clk":"11540858272","pt":1719499203241,"mc":[{"id":"1.230178314","rc":[{"atb":[[1.12,0.05]],"id":45375136}],"con":true,"img":false}]}
{"op":"mcm","clk":"11540858291","pt":1719499203551,"mc":[{"id":"1.230178314","rc":[{"atb":[[5.1,0]],"id":69979804}],"con":true,"img":false}]}
{"op":"mcm","clk":"11540858302","pt":1719499203662,"mc":[{"id":"1.230178314","rc":[{"atb":[[1.12,0.05]],"id":70466763},{"atl":[[9.8,0.95]],"id":46251065}],"con":true,"img":false}]}
{"op":"mcm","clk":"11540858321","pt":1719499203917,"mc":[{"id":"1.230178314","rc":[{"atb":[[3.95,0]],"id":63994056},{"atb":[[1.12,1.69]],"id":70940946}],"con":true,"img":false}]}
{"op":"mcm","clk":"11540858344","pt":1719499204230,"mc":[{"id":"1.230178314","rc":[{"atb":[[1.08,0]],"id":46251065}],"con":true,"img":false}]}
{"op":"mcm","clk":"11540858351","pt":1719499204334,"mc":[{"id":"1.230178314","rc":[{"atb":[[3.6,0.08]],"id":46251065}],"con":true,"img":false}]}
{"op":"mcm","clk":"11540858370","pt":1719499204646,"mc":[{"id":"1.230178314","rc":[{"atb":[[1.12,0]],"id":45375136}],"con":true,"img":false}]}
{"op":"mcm","clk":"11540858377","pt":1719499204750,"mc":[{"id":"1.230178314","rc":[{"atb":[[5.2,0.05]],"id":45375136},{"atl":[[10.5,0]],"id":46251065}],"con":true,"img":false}]}
{"op":"mcm","clk":"11540858396","pt":1719499204960,"mc":[{"id":"1.230178314","rc":[{"atb":[[1.12,1.69]],"id":69979804}],"con":true,"img":false}]}
{"op":"mcm","clk":"11540858407","pt":1719499205013,"mc":[{"id":"1.230178314","rc":[{"atb":[[1.12,0]],"id":70466763}],"con":true,"img":false}]}
{"op":"mcm","clk":"11540858412","pt":1719499205116,"mc":[{"id":"1.230178314","rc":[{"atb":[[5.2,0.05]],"id":70466763}],"con":true,"img":false}]}
{"op":"mcm","clk":"11540858424","pt":1719499205435,"mc":[{"id":"1.230178314","rc":[{"atb":[[1.09,1.69]],"id":63994056}],"con":true,"img":false}]}
{"op":"mcm","clk":"11540858441","pt":1719499205843,"mc":[{"id":"1.230178314","rc":[{"atb":[[1.12,0.05]],"id":69979804},{"atb":[[1.12,0.05]],"id":70940946}],"con":true,"img":false}]}
{"op":"mcm","clk":"11540858462","pt":1719499206167,"mc":[{"id":"1.230178314","rc":[{"atb":[[1.09,0.07]],"id":63994056}],"con":true,"img":false}]}
{"op":"mcm","clk":"11540858479","pt":1719499206362,"mc":[{"id":"1.230178314","rc":[{"atb":[[1.12,0]],"id":70940946}],"con":true,"img":false}]}
{"op":"mcm","clk":"11540858485","pt":1719499206426,"mc":[{"id":"1.230178314","rc":[{"atb":[[5.1,0.05]],"id":70940946}],"con":true,"img":false}]}
{"op":"mcm","clk":"11540858509","pt":1719499206744,"mc":[{"id":"1.230178314","rc":[{"atb":[[1.12,0]],"id":69979804}],"con":true,"img":false}]}
{"op":"mcm","clk":"11540858519","pt":1719499206844,"mc":[{"id":"1.230178314","rc":[{"atb":[[5.1,0.05]],"id":69979804}],"con":true,"img":false}]}
{"op":"mcm","clk":"11540858550","pt":1719499207262,"mc":[{"id":"1.230178314","rc":[{"atb":[[1.09,0]],"id":63994056}],"con":true,"img":false}]}
{"op":"mcm","clk":"11540858560","pt":1719499207363,"mc":[{"id":"1.230178314","rc":[{"atb":[[3.95,0.07]],"id":63994056}],"con":true,"img":false}]}
{"op":"mcm","clk":"11540858590","pt":1719499207673,"mc":[{"id":"1.230178314","rc":[{"atl":[[9.8,2.65]],"id":46251065}],"con":true,"img":false}]}
{"op":"mcm","clk":"11540858619","pt":1719499207946,"mc":[{"id":"1.230178314","rc":[{"atl":[[10,0]],"id":46251065}],"con":true,"img":false}]}
{"op":"mcm","clk":"11540858687","pt":1719499208761,"mc":[{"id":"1.230178314","rc":[{"atl":[[9.8,2.54]],"id":46251065}],"con":true,"img":false}]}
{"op":"mcm","clk":"11540858778","pt":1719499210059,"mc":[{"id":"1.230178314","rc":[{"atl":[[1000,0.96]],"id":46251065}],"con":true,"img":false}]}
{"op":"mcm","clk":"11540858787","pt":1719499210164,"mc":[{"id":"1.230178314","rc":[{"atl":[[9.6,2]],"id":46251065}],"con":true,"img":false}]}
{"op":"mcm","clk":"11540858793","pt":1719499210267,"mc":[{"id":"1.230178314","rc":[{"atl":[[1000,0.84]],"id":46251065}],"con":true,"img":false}]}
{"op":"mcm","clk":"11540858797","pt":1719499210335,"mc":[{"id":"1.230178314","rc":[{"atl":[[9.6,2.12]],"id":46251065}],"con":true,"img":false}]}
{"op":"mcm","clk":"11540858812","pt":1719499210649,"mc":[{"id":"1.230178314","rc":[{"atl":[[9.4,0.84]],"id":46251065}],"con":true,"img":false}]}
{"op":"mcm","clk":"11540858828","pt":1719499210863,"mc":[{"id":"1.230178314","rc":[{"atl":[[9.8,0.84]],"id":46251065}],"con":true,"img":false}]}
{"op":"mcm","clk":"11540858908","pt":1719499212066,"mc":[{"id":"1.230178314","rc":[{"atb":[[2.6,3.39]],"id":46251065}],"con":true,"img":false}]}
{"op":"mcm","clk":"11540859032","pt":1719499213771,"mc":[{"id":"1.230178314","rc":[{"atl":[[9.4,2.49]],"id":46251065}],"con":true,"img":false}]}
{"op":"mcm","clk":"11540859066","pt":1719499214251,"mc":[{"id":"1.230178314","rc":[{"atl":[[9.8,0]],"id":46251065}],"con":true,"img":false}]}
{"op":"mcm","clk":"11540859131","pt":1719499215344,"mc":[{"id":"1.230178314","rc":[{"atl":[[9.6,0.12]],"id":46251065}],"con":true,"img":false}]}
{"op":"mcm","clk":"11540859277","pt":1719499217675,"mc":[{"id":"1.230178314","rc":[{"atl":[[9.2,2]],"id":46251065}],"con":true,"img":false}]}
{"op":"mcm","clk":"11540859312","pt":1719499218158,"mc":[{"id":"1.230178314","rc":[{"atl":[[9,0.86]],"id":46251065}],"con":true,"img":false}]}
{"op":"mcm","clk":"11540859343","pt":1719499218671,"mc":[{"id":"1.230178314","rc":[{"spn":5.08,"spf":1.0,"id":70466763},{"atb":[[2.52,0]],"id":69979804},{"spn":2.78,"spf":1.0,"id":46251065}],"con":true,"img":false}]}
{"op":"mcm","clk":"11540859403","pt":1719499219346,"mc":[{"id":"1.230178314","rc":[{"atb":[[5.3,1.6]],"id":70466763}],"con":true,"img":false}]}
{"op":"mcm","clk":"11540859449","pt":1719499219965,"mc":[{"id":"1.230178314","rc":[{"atb":[[5.1,0]],"id":70466763}],"con":true,"img":false}]}
{"op":"mcm","clk":"11540859456","pt":1719499220068,"mc":[{"id":"1.230178314","rc":[{"atl":[[9.4,0.84]],"id":46251065}],"con":true,"img":false}]}
{"op":"mcm","clk":"11540859460","pt":1719499220175,"mc":[{"id":"1.230178314","rc":[{"atb":[[5.2,1.65]],"id":70466763}],"con":true,"img":false}]}
{"op":"mcm","clk":"11540859486","pt":1719499220553,"mc":[{"id":"1.230178314","rc":[{"atb":[[5.3,0]],"id":70466763}],"con":true,"img":false}]}
{"op":"mcm","clk":"11540859667","pt":1719499222984,"mc":[{"id":"1.230178314","rc":[{"atl":[[9.2,0]],"id":46251065}],"con":true,"img":false}]}
{"op":"mcm","clk":"11540859729","pt":1719499223781,"mc":[{"id":"1.230178314","rc":[{"atl":[[9,0.02]],"id":46251065}],"con":true,"img":false}]}
{"op":"mcm","clk":"11540859757","pt":1719499224150,"mc":[{"id":"1.230178314","rc":[{"atl":[[9.4,0]],"id":46251065}],"con":true,"img":false}]}
{"op":"mcm","clk":"11540859765","pt":1719499224258,"mc":[{"id":"1.230178314","rc":[{"atb":[[2.36,8.71]],"id":45375136}],"con":true,"img":false}]}
{"op":"mcm","clk":"11540859796","pt":1719499224679,"mc":[{"id":"1.230178314","rc":[{"atb":[[2.56,7.59]],"id":69979804}],"con":true,"img":false}]}
{"op":"mcm","clk":"11540859843","pt":1719499225186,"mc":[{"id":"1.230178314","rc":[{"atl":[[10.5,2]],"id":46251065}],"con":true,"img":false}]}
{"op":"mcm","clk":"11540859876","pt":1719499225566,"mc":[{"id":"1.230178314","rc":[{"atl":[[9.6,0]],"id":46251065}],"con":true,"img":false}]}
{"op":"mcm","clk":"11540859881","pt":1719499225669,"mc":[{"id":"1.230178314","rc":[{"atl":[[10,0.84]],"id":46251065}],"con":true,"img":false}]}
{"op":"mcm","clk":"11540859908","pt":1719499225987,"mc":[{"id":"1.230178314","rc":[{"atl":[[10,2.35],[1000,0.95]],"id":46251065}],"con":true,"img":false}]}
{"op":"mcm","clk":"11540859923","pt":1719499226181,"mc":[{"id":"1.230178314","rc":[{"atl":[[1000,0.84]],"id":46251065}],"con":true,"img":false}]}
{"op":"mcm","clk":"11540859937","pt":1719499226285,"mc":[{"id":"1.230178314","rc":[{"atl":[[10.5,2.11]],"id":46251065}],"con":true,"img":false}]}
{"op":"mcm","clk":"11540859959","pt":1719499226462,"mc":[{"id":"1.230178314","rc":[{"atl":[[10.5,0.11]],"id":46251065}],"con":true,"img":false}]}
{"op":"mcm","clk":"11540860467","pt":1719499232678,"mc":[{"id":"1.230178314","rc":[{"atl":[[9.8,2]],"id":46251065}],"con":true,"img":false}]}
{"op":"mcm","clk":"11540860491","pt":1719499232990,"mc":[{"id":"1.230178314","rc":[{"atb":[[5.1,1.6],[5.2,0.05]],"id":70466763}],"con":true,"img":false}]}
{"op":"mcm","clk":"11540860500","pt":1719499233111,"mc":[{"id":"1.230178314","rc":[{"atl":[[9.6,0.84]],"id":46251065}],"con":true,"img":false}]}
{"op":"mcm","clk":"11540860580","pt":1719499234163,"mc":[{"id":"1.230178314","rc":[{"atb":[[2.4,9.97]],"id":70940946}],"con":true,"img":false}]}
{"op":"mcm","clk":"11540860642","pt":1719499234942,"mc":[{"id":"1.230178314","rc":[{"atl":[[10,0.84]],"id":46251065}],"con":true,"img":false}]}
{"op":"mcm","clk":"11540860799","pt":1719499236878,"mc":[{"id":"1.230178314","rc":[{"atb":[[2.36,0]],"id":70466763}],"con":true,"img":false}]}
{"op":"mcm","clk":"11540860881","pt":1719499237878,"mc":[{"id":"1.230178314","rc":[{"atl":[[9.8,0]],"id":46251065}],"con":true,"img":false}]}
{"op":"mcm","clk":"11540860902","pt":1719499238192,"mc":[{"id":"1.230178314","rc":[{"atl":[[9.6,0]],"id":46251065}],"con":true,"img":false}]}
{"op":"mcm","clk":"11540860951","pt":1719499238677,"mc":[{"id":"1.230178314","rc":[{"atl":[[10,0]],"id":46251065}],"con":true,"img":false}]}
{"op":"mcm","clk":"11540861062","pt":1719499239980,"mc":[{"id":"1.230178314","rc":[{"atl":[[10.5,2.11]],"id":46251065}],"con":true,"img":false}]}
{"op":"mcm","clk":"11540861118","pt":1719499240669,"mc":[{"id":"1.230178314","rc":[{"atl":[[10,0.84]],"id":46251065}],"con":true,"img":false}]}
{"op":"mcm","clk":"11540861140","pt":1719499240983,"mc":[{"id":"1.230178314","rc":[{"atl":[[10,2.47]],"id":46251065}],"con":true,"img":false}]}
{"op":"mcm","clk":"11540861156","pt":1719499241192,"mc":[{"id":"1.230178314","rc":[{"atl":[[10.5,0.11]],"id":46251065}],"con":true,"img":false}]}
{"op":"mcm","clk":"11540861185","pt":1719499241561,"mc":[{"id":"1.230178314","rc":[{"atl":[[10.5,0]],"id":46251065}],"con":true,"img":false}]}
{"op":"mcm","clk":"11540861293","pt":1719499242965,"mc":[{"id":"1.230178314","rc":[{"atl":[[1000,0.95]],"id":46251065}],"con":true,"img":false}]}
{"op":"mcm","clk":"11540861310","pt":1719499243179,"mc":[{"id":"1.230178314","rc":[{"atl":[[1000,0.84]],"id":46251065}],"con":true,"img":false}]}
{"op":"mcm","clk":"11540861323","pt":1719499243283,"mc":[{"id":"1.230178314","rc":[{"atl":[[9.8,0.11]],"id":46251065}],"con":true,"img":false}]}
{"op":"mcm","clk":"11540861405","pt":1719499244178,"mc":[{"id":"1.230178314","rc":[{"atb":[[2.4,8.45]],"id":70466763}],"con":true,"img":false}]}
{"op":"mcm","clk":"11540861628","pt":1719499247380,"mc":[{"id":"1.230178314","rc":[{"atl":[[9.8,2.11]],"id":46251065}],"con":true,"img":false}]}
{"op":"mcm","clk":"11540861644","pt":1719499247592,"mc":[{"id":"1.230178314","rc":[{"atl":[[9.6,0.84]],"id":46251065}],"con":true,"img":false}]}
{"op":"mcm","clk":"11540861737","pt":1719499248908,"mc":[{"id":"1.230178314","rc":[{"atb":[[5.3,1.6],[5.1,0]],"id":70466763}],"con":true,"img":false}]}
{"op":"mcm","clk":"11540861788","pt":1719499249486,"mc":[{"id":"1.230178314","rc":[{"atb":[[5.1,1.6]],"id":70466763}],"con":true,"img":false}]}
{"op":"mcm","clk":"11540861822","pt":1719499249898,"mc":[{"id":"1.230178314","rc":[{"atb":[[5.3,0]],"id":70466763}],"con":true,"img":false}]}
{"op":"mcm","clk":"11540861835","pt":1719499250108,"mc":[{"id":"1.230178314","rc":[{"atl":[[10,0.84]],"id":46251065}],"con":true,"img":false}]}
{"op":"mcm","clk":"11540861867","pt":1719499250473,"mc":[{"id":"1.230178314","rc":[{"atb":[[5.1,0]],"id":70466763}],"con":true,"img":false}]}
{"op":"mcm","clk":"11540861875","pt":1719499250577,"mc":[{"id":"1.230178314","rc":[{"atb":[[5.4,1.56]],"id":70466763}],"con":true,"img":false}]}
{"op":"mcm","clk":"11540862034","pt":1719499252682,"mc":[{"id":"1.230178314","rc":[{"atl":[[9.8,0.11]],"id":46251065}],"con":true,"img":false}]}
{"op":"mcm","clk":"11540862074","pt":1719499253202,"mc":[{"id":"1.230178314","rc":[{"atl":[[9.6,1.71]],"id":46251065}],"con":true,"img":false}]}
{"op":"mcm","clk":"11540862118","pt":1719499253782,"mc":[{"id":"1.230178314","rc":[{"atl":[[10,0]],"id":46251065}],"con":true,"img":false}]}
{"op":"mcm","clk":"11540862183","pt":1719499254665,"mc":[{"id":"1.230178314","rc":[{"atl":[[9.4,2]],"id":46251065}],"con":true,"img":false}]}
{"op":"mcm","clk":"11540862211","pt":1719499255088,"mc":[{"id":"1.230178314","rc":[{"atl":[[9.2,0.84]],"id":46251065}],"con":true,"img":false}]}
{"op":"mcm","clk":"11540862285","pt":1719499256092,"mc":[{"id":"1.230178314","rc":[{"atl":[[9.6,0]],"id":46251065}],"con":true,"img":false}]}
{"op":"mcm","clk":"11540862462","pt":1719499258496,"mc":[{"id":"1.230178314","rc":[{"atl":[[9.8,0]],"id":46251065}],"con":true,"img":false}]}
{"op":"mcm","clk":"11540862480","pt":1719499258708,"mc":[{"id":"1.230178314","rc":[{"atl":[[1000,0.96]],"id":46251065}],"con":true,"img":false}]}
{"op":"mcm","clk":"11540862490","pt":1719499258817,"mc":[{"id":"1.230178314","rc":[{"atl":[[1000,0.84]],"id":46251065}],"con":true,"img":false}]}
{"op":"mcm","clk":"11540862499","pt":1719499258914,"mc":[{"id":"1.230178314","rc":[{"atl":[[9.2,0.96]],"id":46251065}],"con":true,"img":false}]}
{"op":"mcm","clk":"11540862516","pt":1719499259109,"mc":[{"id":"1.230178314","rc":[{"atl":[[9.2,2.7]],"id":46251065}],"con":true,"img":false}]}
{"op":"mcm","clk":"11540862530","pt":1719499259178,"mc":[{"id":"1.230178314","rc":[{"atb":[[5.4,0],[5.1,1.56]],"id":70466763}],"con":true,"img":false}]}
{"op":"mcm","clk":"11540862578","pt":1719499259902,"mc":[{"id":"1.230178314","rc":[{"atl":[[9.4,0]],"id":46251065}],"con":true,"img":false}]}
{"op":"mcm","clk":"11540862696","pt":1719499261500,"mc":[{"id":"1.230178314","rc":[{"atb":[[1.01,19.42]],"id":45375136}],"con":true,"img":false}]}
{"op":"mcm","clk":"11540862706","pt":1719499261608,"mc":[{"id":"1.230178314","rc":[{"atb":[[5.3,1]],"id":45375136}],"con":true,"img":false}]}
{"op":"mcm","clk":"11540862711","pt":1719499261707,"mc":[{"id":"1.230178314","rc":[{"atl":[[140,1]],"id":70466763},{"atb":[[2.44,1]],"id":63994056},{"atl":[[9.4,2]],"id":69979804},{"atb":[[2.62,1]],"id":46251065},{"atl":[[9,2.02]],"id":46251065}],"con":true,"img":false}]}
{"op":"mcm","clk":"11540862772","pt":1719499262599,"mc":[{"id":"1.230178314","rc":[{"atl":[[8.8,0.84]],"id":46251065}],"con":true,"img":false}]}
{"op":"mcm","clk":"11540862804","pt":1719499263215,"mc":[{"id":"1.230178314","rc":[{"atb":[[2.5,0],[2.64,2.09]],"id":69979804},{"atb":[[2.16,0],[2.48,2.09]],"id":70940946}],"con":true,"img":false}]}
{"op":"mcm","clk":"11540862823","pt":1719499263582,"mc":[{"id":"1.230178314","rc":[{"atl":[[9,2]],"id":46251065}],"con":true,"img":false}]}
{"op":"mcm","clk":"11540862833","pt":1719499263692,"mc":[{"id":"1.230178314","rc":[{"atl":[[8.6,0.02]],"id":46251065}],"con":true,"img":false}]}
{"op":"mcm","clk":"11540862917","pt":1719499265089,"mc":[{"id":"1.230178314","rc":[{"atl":[[9.2,0.96]],"id":46251065}],"con":true,"img":false}]}
{"op":"mcm","clk":"11540863043","pt":1719499267102,"mc":[{"id":"1.230178314","rc":[{"atl":[[9,0]],"id":46251065}],"con":true,"img":false}]}
{"op":"mcm","clk":"11540863087","pt":1719499268174,"mc":[{"id":"1.230178314","rc":[{"atl":[[8.8,0]],"id":46251065}],"con":true,"img":false}]}
{"op":"mcm","clk":"11540863115","pt":1719499268231,"mc":[{"id":"1.230178314","rc":[{"atb":[[4.1,8.8]],"id":45375136},{"atl":[[200,2],[210,0]],"id":70940946},{"atb":[[3.85,1],[3.55,0]],"id":46251065}],"con":true,"img":false}]}
{"op":"mcm","clk":"11540863121","pt":1719499268282,"mc":[{"id":"1.230178314","rc":[{"atb":[[3.9,0]],"id":45375136},{"atb":[[2.6,0],[3.55,2]],"id":46251065}],"con":true,"img":false}]}
{"op":"mcm","clk":"11540863147","pt":1719499268698,"mc":[{"id":"1.230178314","rc":[{"atb":[[2.54,0]],"id":69979804},{"atl":[[9.2,0.12],[10.5,2]],"id":46251065}],"con":true,"img":false}]}
{"op":"mcm","clk":"11540863249","pt":1719499270091,"mc":[{"id":"1.230178314","rc":[{"atl":[[10,0.84]],"id":46251065}],"con":true,"img":false}]}
{"op":"mcm","clk":"11540863324","pt":1719499271122,"mc":[{"id":"1.230178314","rc":[{"atl":[[10,2.35]],"id":46251065}],"con":true,"img":false}]}
{"op":"mcm","clk":"11540863348","pt":1719499271484,"mc":[{"id":"1.230178314","rc":[{"atl":[[10.5,0]],"id":46251065}],"con":true,"img":false}]}
{"op":"mcm","clk":"11540863445","pt":1719499272980,"mc":[{"id":"1.230178314","rc":[{"atb":[[2.38,0]],"id":70940946}],"con":true,"img":false}]}
{"op":"mcm","clk":"11540863494","pt":1719499273699,"mc":[{"id":"1.230178314","rc":[{"atb":[[2.42,6.54]],"id":63994056},{"atb":[[2.62,1.78]],"id":46251065}],"con":true,"img":false}]}
{"op":"mcm","clk":"11540863528","pt":1719499274109,"mc":[{"id":"1.230178314","rc":[{"atl":[[9.2,0]],"id":46251065}],"con":true,"img":false}]}
{"op":"mcm","clk":"11540863558","pt":1719499274624,"mc":[{"id":"1.230178314","rc":[{"atb":[[2.58,8.83]],"id":69979804},{"atl":[[1000,0.95]],"id":46251065}],"con":true,"img":false}]}
{"op":"mcm","clk":"11540863573","pt":1719499274827,"mc":[{"id":"1.230178314","rc":[{"atl":[[1000,0.84]],"id":46251065}],"con":true,"img":false}]}
{"op":"mcm","clk":"11540863581","pt":1719499274880,"mc":[{"id":"1.230178314","rc":[{"atb":[[2.38,10.12]],"id":45375136},{"atl":[[9.8,0.11]],"id":46251065}],"con":true,"img":false}]}
{"op":"mcm","clk":"11540863591","pt":1719499274983,"mc":[{"id":"1.230178314","rc":[{"atb":[[1.25,20]],"id":70466763},{"atb":[[1.25,20]],"id":45375136},{"atb":[[1.25,20]],"id":63994056},{"atb":[[1.25,20]],"id":69979804},{"atb":[[1.25,20]],"id":70940946},{"atb":[[1.25,20]],"id":46251065}],"con":true,"img":false}]}
{"op":"mcm","clk":"11540863642","pt":1719499275801,"mc":[{"id":"1.230178314","rc":[{"atl":[[9.8,2.11]],"id":46251065}],"con":true,"img":false}]}
{"op":"mcm","clk":"11540863737","pt":1719499277087,"mc":[{"id":"1.230178314","rc":[{"atl":[[9.6,0.84]],"id":46251065}],"con":true,"img":false}]}
{"op":"mcm","clk":"11540863746","pt":1719499277188,"mc":[{"id":"1.230178314","rc":[{"atl":[[10,0.84]],"id":46251065}],"con":true,"img":false}]}
{"op":"mcm","clk":"11540863844","pt":1719499278629,"mc":[{"id":"1.230178314","rc":[{"atb":[[2.42,8.33]],"id":70940946}],"con":true,"img":false}]}
{"op":"mcm","clk":"11540863870","pt":1719499278990,"mc":[{"id":"1.230178314","rc":[{"atb":[[5.3,1.6]],"id":70466763},{"spn":5.26,"spf":1.0,"id":70466763},{"spn":2.82,"spf":1.0,"id":63994056},{"spn":102.55,"spf":"NaN","id":70940946},{"spn":3.24,"spf":1.0,"id":46251065}],"con":true,"img":false}]}
{"op":"mcm","clk":"11540863880","pt":1719499279095,"mc":[{"id":"1.230178314","rc":[{"atb":[[5.1,0]],"id":70466763}],"con":true,"img":false}]}
{"op":"mcm","clk":"11540863951","pt":1719499279815,"mc":[{"id":"1.230178314","rc":[{"atb":[[5.1,1.6]],"id":70466763}],"con":true,"img":false}]}
{"op":"mcm","clk":"11540863982","pt":1719499280127,"mc":[{"id":"1.230178314","rc":[{"atb":[[5.3,0],[5.4,1.56]],"id":70466763}],"con":true,"img":false}]}
{"op":"mcm","clk":"11540864014","pt":1719499280538,"mc":[{"id":"1.230178314","rc":[{"atb":[[5.1,0]],"id":70466763}],"con":true,"img":false}]}
{"op":"mcm","clk":"11540864056","pt":1719499281014,"mc":[{"id":"1.230178314","rc":[{"atl":[[9.8,0.11]],"id":46251065}],"con":true,"img":false}]}
{"op":"mcm","clk":"11540864118","pt":1719499281632,"mc":[{"id":"1.230178314","rc":[{"atl":[[9.6,0]],"id":46251065}],"con":true,"img":false}]}
{"op":"mcm","clk":"11540864164","pt":1719499282149,"mc":[{"id":"1.230178314","rc":[{"atl":[[10,0]],"id":46251065}],"con":true,"img":false}]}
{"op":"mcm","clk":"11540864250","pt":1719499283239,"mc":[{"id":"1.230178314","rc":[{"atl":[[10.5,1.72]],"id":46251065}],"con":true,"img":false}]}
{"op":"mcm","clk":"11540864257","pt":1719499283342,"mc":[{"id":"1.230178314","rc":[{"atl":[[10.5,3.72]],"id":46251065}],"con":true,"img":false}]}
{"op":"mcm","clk":"11540864283","pt":1719499283709,"mc":[{"id":"1.230178314","rc":[{"atb":[[2.62,1]],"id":46251065}],"con":true,"img":false}]}
{"op":"mcm","clk":"11540864353","pt":1719499284636,"mc":[{"id":"1.230178314","rc":[{"atl":[[10,0.84]],"id":46251065}],"con":true,"img":false}]}
{"op":"mcm","clk":"11540864663","pt":1719499288618,"mc":[{"id":"1.230178314","rc":[{"atl":[[10.5,1.72]],"id":46251065}],"con":true,"img":false}]}
{"op":"mcm","clk":"11540864759","pt":1719499289815,"mc":[{"id":"1.230178314","rc":[{"atl":[[65,1]],"id":70466763},{"atl":[[95,1]],"id":45375136},{"atl":[[42,1]],"id":63994056},{"atl":[[8.8,1]],"id":69979804},{"atl":[[190,1]],"id":70940946},{"atl":[[10,1.84]],"id":46251065}],"con":true,"img":false}]}
{"op":"mcm","clk":"11540864787","pt":1719499290128,"mc":[{"id":"1.230178314","rc":[{"atb":[[5.1,1.56]],"id":70466763},{"atl":[[140,0]],"id":70466763},{"atl":[[9.4,1]],"id":69979804},{"atl":[[9.8,0]],"id":46251065}],"con":true,"img":false}]}
{"op":"mcm","clk":"11540864803","pt":1719499290233,"mc":[{"id":"1.230178314","rc":[{"atb":[[5.4,0]],"id":70466763}],"con":true,"img":false}]}
{"op":"mcm","clk":"11540864813","pt":1719499290331,"mc":[{"id":"1.230178314","rc":[{"atl":[[80,1]],"id":70466763},{"atl":[[8.6,1]],"id":69979804}],"con":true,"img":false}]}
{"op":"mcm","clk":"11540864823","pt":1719499290437,"mc":[{"id":"1.230178314","rc":[{"atb":[[5.5,1.54]],"id":70466763}],"con":true,"img":false}]}
{"op":"mcm","clk":"11540864832","pt":1719499290533,"mc":[{"id":"1.230178314","rc":[{"atl":[[1000,0.95]],"id":46251065}],"con":true,"img":false}]}
{"op":"mcm","clk":"11540864846","pt":1719499290747,"mc":[{"id":"1.230178314","rc":[{"atl":[[1000,0.84]],"id":46251065}],"con":true,"img":false}]}
{"op":"mcm","clk":"11540864856","pt":1719499290851,"mc":[{"id":"1.230178314","rc":[{"atb":[[5.1,0]],"id":70466763},{"atl":[[10,1.95],[9.8,2]],"id":46251065}],"con":true,"img":false}]}
{"op":"mcm","clk":"11540864930","pt":1719499291731,"mc":[{"id":"1.230178314","rc":[{"atl":[[9.6,0.84]],"id":46251065}],"con":true,"img":false}]}
{"op":"mcm","clk":"11540864945","pt":1719499291933,"mc":[{"id":"1.230178314","rc":[{"atl":[[10,0.95]],"id":46251065}],"con":true,"img":false}]}
{"op":"mcm","clk":"11540864956","pt":1719499292036,"mc":[{"id":"1.230178314","rc":[{"atl":[[9.6,1.84]],"id":46251065}],"con":true,"img":false}]}
{"op":"mcm","clk":"11540864969","pt":1719499292248,"mc":[{"id":"1.230178314","rc":[{"atl":[[10.5,0]],"id":46251065}],"con":true,"img":false}]}
{"op":"mcm","clk":"11540865004","pt":1719499292609,"mc":[{"id":"1.230178314","rc":[{"atl":[[10,0.11]],"id":46251065}],"con":true,"img":false}]}
{"op":"mcm","clk":"11540865200","pt":1719499295238,"mc":[{"id":"1.230178314","rc":[{"atl":[[9.4,1.55]],"id":46251065}],"con":true,"img":false}]}
{"op":"mcm","clk":"11540865245","pt":1719499296061,"mc":[{"id":"1.230178314","rc":[{"atl":[[9.6,0.84]],"id":46251065}],"con":true,"img":false}]}
{"op":"mcm","clk":"11540865251","pt":1719499296118,"mc":[{"id":"1.230178314","rc":[{"atl":[[9.2,1],[9.8,0]],"id":46251065}],"con":true,"img":false}]}
{"op":"mcm","clk":"11540865272","pt":1719499296427,"mc":[{"id":"1.230178314","rc":[{"atb":[[2.38,8.58]],"id":46251065}],"con":true,"img":false}]}
{"op":"mcm","clk":"11540865397","pt":1719499298118,"mc":[{"id":"1.230178314","rc":[{"atl":[[9,2]],"id":46251065}],"con":true,"img":false}]}
{"op":"mcm","clk":"11540865446","pt":1719499298744,"mc":[{"id":"1.230178314","rc":[{"atl":[[9.6,0]],"id":46251065}],"con":true,"img":false}]}
{"op":"mcm","clk":"11540865469","pt":1719499299064,"mc":[{"id":"1.230178314","rc":[{"atl":[[9.2,0]],"id":46251065}],"con":true,"img":false}]}
{"op":"mcm","clk":"11540865474","pt":1719499299160,"mc":[{"id":"1.230178314","rc":[{"atl":[[8.8,1.84]],"id":46251065}],"con":true,"img":false}]}
{"op":"mcm","clk":"11540865490","pt":1719499299369,"mc":[{"id":"1.230178314","rc":[{"atl":[[200,0],[210,2]],"id":70940946},{"atb":[[3.85,0],[3.55,3]],"id":46251065}],"con":true,"img":false}]}
{"op":"mcm","clk":"11540865517","pt":1719499299628,"mc":[{"id":"1.230178314","rc":[{"atb":[[3.6,0.93]],"id":46251065}],"con":true,"img":false}]}
{"op":"mcm","clk":"11540865530","pt":1719499299833,"mc":[{"id":"1.230178314","rc":[{"atb":[[2.64,6.55],[3.55,1]],"id":46251065}],"con":true,"img":false}]}
{"op":"mcm","clk":"11540865538","pt":1719499299941,"mc":[{"id":"1.230178314","rc":[{"atb":[[3.85,1],[3.55,0]],"id":46251065}],"con":true,"img":false}]}
{"op":"mcm","clk":"11540865547","pt":1719499300044,"mc":[{"id":"1.230178314","rc":[{"atl":[[190,0]],"id":70940946},{"atb":[[3.55,2],[2.62,0]],"id":46251065}],"con":true,"img":false}]}
{"op":"mcm","clk":"11540865555","pt":1719499300143,"mc":[{"id":"1.230178314","rc":[{"atb":[[5.1,1.54],[5.5,0]],"id":70466763},{"atl":[[200,1]],"id":70940946},{"atb":[[2.64,0]],"id":46251065}],"con":true,"img":false}]}
{"op":"mcm","clk":"11540865560","pt":1719499300246,"mc":[{"id":"1.230178314","rc":[{"atb":[[2.66,1]],"id":46251065}],"con":true,"img":false}]}
{"op":"mcm","clk":"11540865635","pt":1719499301332,"mc":[{"id":"1.230178314","rc":[{"atl":[[9.4,0]],"id":46251065}],"con":true,"img":false}]}
{"op":"mcm","clk":"11540865763","pt":1719499303344,"mc":[{"id":"1.230178314","rc":[{"atl":[[9,0]],"id":46251065}],"con":true,"img":false}]}
{"op":"mcm","clk":"11540865818","pt":1719499304175,"mc":[{"id":"1.230178314","rc":[{"atl":[[8.8,0.84]],"id":46251065}],"con":true,"img":false}]}
{"op":"mcm","clk":"11540865824","pt":1719499304271,"mc":[{"id":"1.230178314","rc":[{"atl":[[13.5,1]],"id":46251065}],"con":true,"img":false}]}
{"op":"mcm","clk":"11540865854","pt":1719499304536,"mc":[{"id":"1.230178314","rc":[{"atl":[[8.6,1.62]],"id":46251065}],"con":true,"img":false}]}
{"op":"mcm","clk":"11540865865","pt":1719499304738,"mc":[{"id":"1.230178314","rc":[{"atl":[[8.8,0]],"id":46251065}],"con":true,"img":false}]}
{"op":"mcm","clk":"11540865893","pt":1719499305154,"mc":[{"id":"1.230178314","rc":[{"atl":[[13.5,0]],"id":46251065}],"con":true,"img":false}]}
{"op":"mcm","clk":"11540865898","pt":1719499305253,"mc":[{"id":"1.230178314","rc":[{"atl":[[8.4,1]],"id":46251065}],"con":true,"img":false}]}
{"op":"mcm","clk":"11540865907","pt":1719499305356,"mc":[{"id":"1.230178314","rc":[{"atl":[[8.4,3]],"id":46251065}],"con":true,"img":false}]}
{"op":"mcm","clk":"11540865940","pt":1719499305769,"mc":[{"id":"1.230178314","rc":[{"atl":[[8.6,1.6]],"id":46251065}],"con":true,"img":false}]}
{"op":"mcm","clk":"11540865950","pt":1719499305870,"mc":[{"id":"1.230178314","rc":[{"atl":[[8.2,0.02]],"id":46251065}],"con":true,"img":false}]}
{"op":"mcm","clk":"11540865973","pt":1719499306178,"mc":[{"id":"1.230178314","rc":[{"atl":[[200,3],[210,0]],"id":70940946},{"atl":[[10,0]],"id":46251065}],"con":true,"img":false}]}
{"op":"mcm","clk":"11540866014","pt":1719499306647,"mc":[{"id":"1.230178314","rc":[{"atl":[[8.2,0.86]],"id":46251065}],"con":true,"img":false}]}
{"op":"mcm","clk":"11540866025","pt":1719499306852,"mc":[{"id":"1.230178314","rc":[{"atl":[[1000,0.98]],"id":46251065}],"con":true,"img":false}]}
{"op":"mcm","clk":"11540866044","pt":1719499307065,"mc":[{"id":"1.230178314","rc":[{"atl":[[1000,0.84]],"id":46251065}],"con":true,"img":false}]}
{"op":"mcm","clk":"11540866050","pt":1719499307169,"mc":[{"id":"1.230178314","rc":[{"atl":[[200,2]],"id":70940946},{"atl":[[8.2,1]],"id":46251065}],"con":true,"img":false}]}
{"op":"mcm","clk":"11540866061","pt":1719499307268,"mc":[{"id":"1.230178314","rc":[{"atl":[[540,1]],"id":70940946}],"con":true,"img":false}]}
{"op":"mcm","clk":"11540866070","pt":1719499307371,"mc":[{"id":"1.230178314","rc":[{"atl":[[210,2]],"id":70940946},{"atb":[[3.55,3]],"id":46251065}],"con":true,"img":false}]}
{"op":"mcm","clk":"11540866080","pt":1719499307472,"mc":[{"id":"1.230178314","rc":[{"atl":[[200,0]],"id":70940946},{"atb":[[3.85,0]],"id":46251065}],"con":true,"img":false}]}
{"op":"mcm","clk":"11540866092","pt":1719499307677,"mc":[{"id":"1.230178314","rc":[{"atl":[[8.6,0]],"id":46251065}],"con":true,"img":false}]}
{"op":"mcm","clk":"11540866104","pt":1719499307801,"mc":[{"id":"1.230178314","rc":[{"atb":[[3.55,1],[2.68,6.55]],"id":46251065},{"atl":[[8.4,1]],"id":46251065}],"con":true,"img":false}]}
{"op":"mcm","clk":"11540866126","pt":1719499308041,"mc":[{"id":"1.230178314","rc":[{"atl":[[200,2]],"id":70940946},{"atb":[[3.85,1]],"id":46251065}],"con":true,"img":false}]}
{"op":"mcm","clk":"11540866132","pt":1719499308162,"mc":[{"id":"1.230178314","rc":[{"atl":[[540,0],[210,0]],"id":70940946},{"atb":[[3.55,2],[2.68,0]],"id":46251065},{"atl":[[8.4,0]],"id":46251065}],"con":true,"img":false}]}
{"op":"mcm","clk":"11540866145","pt":1719499308253,"mc":[{"id":"1.230178314","rc":[{"atl":[[200,3]],"id":70940946},{"atl":[[13.5,1]],"id":46251065}],"con":true,"img":false}]}
{"op":"mcm","clk":"11540866176","pt":1719499308664,"mc":[{"id":"1.230178314","rc":[{"atb":[[2.38,0]],"id":70466763},{"atb":[[2.4,0]],"id":70940946},{"atl":[[8.2,0.16]],"id":46251065}],"con":true,"img":false}]}
{"op":"mcm","clk":"11540866196","pt":1719499308972,"mc":[{"id":"1.230178314","rc":[{"atb":[[5.3,1.6],[5.1,0]],"id":70466763},{"atb":[[2.36,0]],"id":45375136},{"atb":[[2.56,0]],"id":69979804}],"con":true,"img":false}]}
{"op":"mcm","clk":"11540866211","pt":1719499309188,"mc":[{"id":"1.230178314","rc":[{"atl":[[200,2]],"id":70940946}],"con":true,"img":false}]}
{"op":"mcm","clk":"11540866222","pt":1719499309292,"mc":[{"id":"1.230178314","rc":[{"atl":[[540,1]],"id":70940946}],"con":true,"img":false}]}
{"op":"mcm","clk":"11540866281","pt":1719499310162,"mc":[{"id":"1.230178314","rc":[{"atl":[[540,0]],"id":70940946}],"con":true,"img":false}]}
{"op":"mcm","clk":"11540866287","pt":1719499310271,"mc":[{"id":"1.230178314","rc":[{"atl":[[190,1]],"id":70940946}],"con":true,"img":false}]}
{"op":"mcm","clk":"11540866313","pt":1719499310579,"mc":[{"id":"1.230178314","rc":[{"atb":[[5.3,0],[5.1,1.6]],"id":70466763}],"con":true,"img":false}]}
{"op":"mcm","clk":"11540866486","pt":1719499312862,"mc":[{"id":"1.230178314","rc":[{"atl":[[10.5,2]],"id":46251065}],"con":true,"img":false}]}
{"op":"mcm","clk":"11540866545","pt":1719499313645,"mc":[{"id":"1.230178314","rc":[{"atl":[[10,1.55]],"id":46251065}],"con":true,"img":false}]}
{"op":"mcm","clk":"11540866581","pt":1719499314156,"mc":[{"id":"1.230178314","rc":[{"atl":[[9.8,0.84]],"id":46251065}],"con":true,"img":false}]}
{"op":"mcm","clk":"11540866588","pt":1719499314264,"mc":[{"id":"1.230178314","rc":[{"atl":[[10.5,0],[13.5,0]],"id":46251065}],"con":true,"img":false}]}
{"op":"mcm","clk":"11540866600","pt":1719499314361,"mc":[{"id":"1.230178314","rc":[{"atl":[[9.8,1.84]],"id":46251065}],"con":true,"img":false}]}
{"op":"mcm","clk":"11540866677","pt":1719499315445,"mc":[{"id":"1.230178314","rc":[{"atb":[[2.4,8.45]],"id":45375136},{"atb":[[2.36,3.15]],"id":46251065}],"con":true,"img":false}]}
{"op":"mcm","clk":"11540866695","pt":1719499315651,"mc":[{"id":"1.230178314","rc":[{"atb":[[2.6,7.4]],"id":69979804}],"con":true,"img":false}]}
{"op":"mcm","clk":"11540866708","pt":1719499315856,"mc":[{"id":"1.230178314","rc":[{"atb":[[2.42,8.94]],"id":70466763}],"con":true,"img":false}]}
{"op":"mcm","clk":"11540866739","pt":1719499316377,"mc":[{"id":"1.230178314","rc":[{"atb":[[2.4,3.38]],"id":46251065}],"con":true,"img":false}]}
{"op":"mcm","clk":"11540866789","pt":1719499317145,"mc":[{"id":"1.230178314","rc":[{"atl":[[10,0]],"id":46251065}],"con":true,"img":false}]}
{"op":"mcm","clk":"11540866864","pt":1719499318379,"mc":[{"id":"1.230178314","rc":[{"atl":[[9.8,0.84]],"id":46251065}],"con":true,"img":false}]}
{"op":"mcm","clk":"11540866872","pt":1719499318483,"mc":[{"id":"1.230178314","rc":[{"atl":[[13.5,1]],"id":46251065}],"con":true,"img":false}]}
{"op":"mcm","clk":"11540866890","pt":1719499318691,"mc":[{"id":"1.230178314","rc":[{"atl":[[9.8,0]],"id":46251065}],"con":true,"img":false}]}
{"op":"mcm","clk":"11540867010","pt":1719499319982,"mc":[{"id":"1.230178314","rc":[{"atl":[[10.5,2]],"id":46251065}],"con":true,"img":false}]}
{"op":"mcm","clk":"11540867096","pt":1719499320965,"mc":[{"id":"1.230178314","rc":[{"atb":[[5.2,5.74]],"id":70466763},{"atl":[[65,1.36]],"id":70466763},{"atb":[[2.44,17.47]],"id":63994056},{"atl":[[42,1.57]],"id":63994056},{"atb":[[3.6,11.47]],"id":46251065},{"atl":[[10,2.96]],"id":46251065}],"con":true,"img":false}]}
{"op":"mcm","clk":"11540867103","pt":1719499321067,"mc":[{"id":"1.230178314","rc":[{"atb":[[3.55,0],[3.65,2]],"id":46251065}],"con":true,"img":false}]}
{"op":"mcm","clk":"11540867115","pt":1719499321177,"mc":[{"id":"1.230178314","rc":[{"atb":[[2.44,16.47]],"id":63994056},{"atb":[[2.66,0]],"id":46251065}],"con":true,"img":false}]}
{"op":"mcm","clk":"11540867123","pt":1719499321276,"mc":[{"id":"1.230178314","rc":[{"atb":[[5.3,1.6],[5.1,0]],"id":70466763},{"atl":[[13.5,0]],"id":46251065}],"con":true,"img":false}]}
{"op":"mcm","clk":"11540867135","pt":1719499321382,"mc":[{"id":"1.230178314","rc":[{"atb":[[2.46,1]],"id":63994056},{"atb":[[3.65,3]],"id":46251065},{"atl":[[10,3.96]],"id":46251065}],"con":true,"img":false}]}
{"op":"mcm","clk":"11540867150","pt":1719499321583,"mc":[{"id":"1.230178314","rc":[{"atl":[[9.8,0.84]],"id":46251065}],"con":true,"img":false}]}
{"op":"mcm","clk":"11540867158","pt":1719499321687,"mc":[{"id":"1.230178314","rc":[{"atb":[[3.7,8.75]],"id":46251065}],"con":true,"img":false}]}
{"op":"mcm","clk":"11540867165","pt":1719499321793,"mc":[{"id":"1.230178314","rc":[{"atb":[[3.75,8.75]],"id":46251065}],"con":true,"img":false}]}
{"op":"mcm","clk":"11540867178","pt":1719499321896,"mc":[{"id":"1.230178314","rc":[{"atb":[[3.65,1]],"id":46251065}],"con":true,"img":false}]}
{"op":"mcm","clk":"11540867196","pt":1719499322060,"mc":[{"id":"1.230178314","rc":[{"atb":[[3.65,0]],"id":46251065}],"con":true,"img":false}]}
{"op":"mcm","clk":"11540867210","pt":1719499322162,"mc":[{"id":"1.230178314","rc":[{"atb":[[3.6,10.62]],"id":46251065}],"con":true,"img":false}]}
{"op":"mcm","clk":"11540867221","pt":1719499322264,"mc":[{"id":"1.230178314","rc":[{"atb":[[3.8,1]],"id":46251065},{"atl":[[10.5,0],[8.2,0.01]],"id":46251065}],"con":true,"img":false}]}
{"op":"mcm","clk":"11540867231","pt":1719499322373,"mc":[{"id":"1.230178314","rc":[{"atb":[[2.62,2.5]],"id":63994056},{"atb":[[2.4,2.5]],"id":70940946},{"atb":[[2.8,2.5],[3.8,10.84]],"id":46251065}],"con":true,"img":false}]}
{"op":"mcm","clk":"11540867242","pt":1719499322472,"mc":[{"id":"1.230178314","rc":[{"atb":[[2.64,2.5]],"id":63994056}],"con":true,"img":false}]}
{"op":"mcm","clk":"11540867251","pt":1719499322572,"mc":[{"id":"1.230178314","rc":[{"atb":[[2.4,0]],"id":63994056},{"atl":[[9.6,1.69],[1000,0.95]],"id":46251065}],"con":true,"img":false}]}
{"op":"mcm","clk":"11540867262","pt":1719499322676,"mc":[{"id":"1.230178314","rc":[{"atb":[[2.46,0]],"id":63994056}],"con":true,"img":false}]}
{"op":"mcm","clk":"11540867272","pt":1719499322779,"mc":[{"id":"1.230178314","rc":[{"atl":[[1000,0.84]],"id":46251065}],"con":true,"img":false}]}
{"op":"mcm","clk":"11540867282","pt":1719499322885,"mc":[{"id":"1.230178314","rc":[{"atb":[[5.2,0]],"id":45375136},{"atb":[[2.66,1]],"id":63994056},{"atl":[[10,4.07]],"id":46251065}],"con":true,"img":false}]}
{"op":"mcm","clk":"11540867315","pt":1719499323295,"mc":[{"id":"1.230178314","rc":[{"atb":[[5.2,5.69]],"id":70466763},{"atl":[[10,3.07]],"id":46251065}],"con":true,"img":false}]}
{"op":"mcm","clk":"11540867324","pt":1719499323397,"mc":[{"id":"1.230178314","rc":[{"atb":[[2.66,14.89]],"id":63994056},{"atl":[[9.4,4.06]],"id":46251065}],"con":true,"img":false}]}
{"op":"mcm","clk":"11540867336","pt":1719499323554,"mc":[{"id":"1.230178314","rc":[{"atb":[[2.66,13.89]],"id":63994056}],"con":true,"img":false}]}
{"op":"mcm","clk":"11540867342","pt":1719499323658,"mc":[{"id":"1.230178314","rc":[{"atl":[[9.8,0]],"id":46251065}],"con":true,"img":false}]}
{"op":"mcm","clk":"11540867349","pt":1719499323759,"mc":[{"id":"1.230178314","rc":[{"atb":[[2.68,1]],"id":63994056},{"atb":[[3.6,10.54]],"id":46251065}],"con":true,"img":false}]}
{"op":"mcm","clk":"11540867373","pt":1719499324187,"mc":[{"id":"1.230178314","rc":[{"atb":[[1.12,1.69]],"id":70466763},{"atb":[[1.12,1.69]],"id":45375136}],"con":true,"img":false}]}
{"op":"mcm","clk":"11540867392","pt":1719499324484,"mc":[{"id":"1.230178314","rc":[{"atb":[[1.12,0.05]],"id":70466763}],"con":true,"img":false}]}
{"op":"mcm","clk":"11540867412","pt":1719499324788,"mc":[{"id":"1.230178314","rc":[{"atb":[[1.12,0.05]],"id":45375136}],"con":true,"img":false}]}
{"op":"mcm","clk":"11540867422","pt":1719499324892,"mc":[{"id":"1.230178314","rc":[{"atb":[[1.12,0]],"id":70466763}],"con":true,"img":false}]}
{"op":"mcm","clk":"11540867432","pt":1719499324994,"mc":[{"id":"1.230178314","rc":[{"atb":[[5.4,0.05]],"id":70466763}],"con":true,"img":false}]}
{"op":"mcm","clk":"11540867446","pt":1719499325198,"mc":[{"id":"1.230178314","rc":[{"atb":[[1.09,1.69]],"id":46251065}],"con":true,"img":false}]}
{"op":"mcm","clk":"11540867468","pt":1719499325461,"mc":[{"id":"1.230178314","rc":[{"atb":[[1.12,0]],"id":45375136}],"con":true,"img":false}]}
{"op":"mcm","clk":"11540867475","pt":1719499325570,"mc":[{"id":"1.230178314","rc":[{"atb":[[5.4,0.05]],"id":45375136}],"con":true,"img":false}]}
{"op":"mcm","clk":"11540867483","pt":1719499325668,"mc":[{"id":"1.230178314","rc":[{"atl":[[9.6,0]],"id":46251065}],"con":true,"img":false}]}
{"op":"mcm","clk":"11540867502","pt":1719499325978,"mc":[{"id":"1.230178314","rc":[{"atb":[[5.1,0]],"id":70940946}],"con":true,"img":false}]}
{"op":"mcm","clk":"11540867518","pt":1719499326186,"mc":[{"id":"1.230178314","rc":[{"atb":[[5.1,0]],"id":69979804}],"con":true,"img":false}]}
{"op":"mcm","clk":"11540867525","pt":1719499326287,"mc":[{"id":"1.230178314","rc":[{"atb":[[3.95,0]],"id":63994056},{"atl":[[9.4,3.06]],"id":46251065}],"con":true,"img":false}]}
{"op":"mcm","clk":"11540867537","pt":1719499326391,"mc":[{"id":"1.230178314","rc":[{"atl":[[9.8,1]],"id":46251065}],"con":true,"img":false}]}
{"op":"mcm","clk":"11540867543","pt":1719499326493,"mc":[{"id":"1.230178314","rc":[{"atb":[[1.12,1.69]],"id":69979804}],"con":true,"img":false}]}
{"op":"mcm","clk":"11540867567","pt":1719499326801,"mc":[{"id":"1.230178314","rc":[{"atb":[[1.09,1.69]],"id":63994056},{"atb":[[1.09,0.07]],"id":46251065}],"con":true,"img":false}]}
{"op":"mcm","clk":"11540867582","pt":1719499326959,"mc":[{"id":"1.230178314","rc":[{"atb":[[1.12,1.69]],"id":70940946},{"atl":[[9.2,2]],"id":46251065}],"con":true,"img":false}]}
{"op":"mcm","clk":"11540867592","pt":1719499327070,"mc":[{"id":"1.230178314","rc":[{"atb":[[1.09,0.07]],"id":63994056}],"con":true,"img":false}]}
{"op":"mcm","clk":"11540867611","pt":1719499327372,"mc":[{"id":"1.230178314","rc":[{"atb":[[1.09,0]],"id":46251065},{"atl":[[9.8,0]],"id":46251065}],"con":true,"img":false}]}
{"op":"mcm","clk":"11540867618","pt":1719499327477,"mc":[{"id":"1.230178314","rc":[{"atb":[[1.12,0.05]],"id":69979804},{"atb":[[3.9,0.07]],"id":46251065},{"atl":[[9,4.38]],"id":46251065}],"con":true,"img":false}]}
{"op":"mcm","clk":"11540867634","pt":1719499327787,"mc":[{"id":"1.230178314","rc":[{"atb":[[1.09,0]],"id":63994056}],"con":true,"img":false}]}
{"op":"mcm","clk":"11540867644","pt":1719499327896,"mc":[{"id":"1.230178314","rc":[{"atb":[[3.95,0.07]],"id":63994056},{"atb":[[1.12,0.05]],"id":70940946}],"con":true,"img":false}]}
{"op":"mcm","clk":"11540867670","pt":1719499328161,"mc":[{"id":"1.230178314","rc":[{"atb":[[1.12,0]],"id":69979804},{"atl":[[9.2,0]],"id":46251065}],"con":true,"img":false}]}
{"op":"mcm","clk":"11540867683","pt":1719499328259,"mc":[{"id":"1.230178314","rc":[{"atb":[[5.1,0.05]],"id":69979804},{"atb":[[3.85,9.75],[3.75,0]],"id":46251065}],"con":true,"img":false}]}
{"op":"mcm","clk":"11540867702","pt":1719499328465,"mc":[{"id":"1.230178314","rc":[{"atb":[[3.8,9.84],[3.9,6.42]],"id":46251065}],"con":true,"img":false}]}
{"op":"mcm","clk":"11540867709","pt":1719499328568,"mc":[{"id":"1.230178314","rc":[{"atb":[[1.12,0]],"id":70940946},{"atb":[[3.9,7.27]],"id":46251065},{"atl":[[8.8,0.84]],"id":46251065}],"con":true,"img":false}]}
{"op":"mcm","clk":"11540867718","pt":1719499328675,"mc":[{"id":"1.230178314","rc":[{"atb":[[5.1,0.05]],"id":70940946},{"atb":[[3.95,1]],"id":46251065}],"con":true,"img":false}]}
{"op":"mcm","clk":"11540867761","pt":1719499329392,"mc":[{"id":"1.230178314","rc":[{"atb":[[3.9,0.92]],"id":46251065},{"atl":[[9,3.38]],"id":46251065}],"con":true,"img":false}]}
{"op":"mcm","clk":"11540867771","pt":1719499329506,"mc":[{"id":"1.230178314","rc":[{"atb":[[3.5,9.06]],"id":69979804},{"atl":[[8.8,3.94]],"id":69979804},{"atb":[[3.95,10.47]],"id":46251065},{"atl":[[9.2,1]],"id":46251065}],"con":true,"img":false}]}
{"op":"mcm","clk":"11540867793","pt":1719499329805,"mc":[{"id":"1.230178314","rc":[{"atb":[[3.95,9.47]],"id":46251065}],"con":true,"img":false}]}
{"op":"mcm","clk":"11540867812","pt":1719499329962,"mc":[{"id":"1.230178314","rc":[{"atb":[[3,2.5]],"id":63994056},{"atb":[[4,1]],"id":46251065}],"con":true,"img":false}]}
{"op":"mcm","clk":"11540867822","pt":1719499330072,"mc":[{"id":"1.230178314","rc":[{"atb":[[3.05,2.5]],"id":63994056}],"con":true,"img":false}]}
{"op":"mcm","clk":"11540867833","pt":1719499330174,"mc":[{"id":"1.230178314","rc":[{"atb":[[3,0],[2.64,0]],"id":63994056}],"con":true,"img":false}]}
{"op":"mcm","clk":"11540867843","pt":1719499330276,"mc":[{"id":"1.230178314","rc":[{"atb":[[3.1,13.17],[2.68,0]],"id":63994056},{"atl":[[9.2,0]],"id":46251065}],"con":true,"img":false}]}
{"op":"mcm","clk":"11540867850","pt":1719499330375,"mc":[{"id":"1.230178314","rc":[{"atl":[[8.8,1.84]],"id":46251065}],"con":true,"img":false}]}
{"op":"mcm","clk":"11540867861","pt":1719499330475,"mc":[{"id":"1.230178314","rc":[{"atb":[[3.15,1]],"id":63994056}],"con":true,"img":false}]}
{"op":"mcm","clk":"11540867870","pt":1719499330581,"mc":[{"id":"1.230178314","rc":[{"atb":[[3.05,0],[3.2,2.5]],"id":63994056}],"con":true,"img":false}]}
{"op":"mcm","clk":"11540867889","pt":1719499330793,"mc":[{"id":"1.230178314","rc":[{"atl":[[1000,1.84]],"id":63994056}],"con":true,"img":false}]}
{"op":"mcm","clk":"11540867904","pt":1719499330994,"mc":[{"id":"1.230178314","rc":[{"atl":[[1000,0.86]],"id":63994056}],"con":true,"img":false}]}
{"op":"mcm","clk":"11540867919","pt":1719499331196,"mc":[{"id":"1.230178314","rc":[{"atl":[[1000,0.84]],"id":63994056}],"con":true,"img":false}]}
{"op":"mcm","clk":"11540867927","pt":1719499331318,"mc":[{"id":"1.230178314","rc":[{"atl":[[7.2,0.02]],"id":63994056}],"con":true,"img":false}]}
{"op":"mcm","clk":"11540867935","pt":1719499331401,"mc":[{"id":"1.230178314","rc":[{"atb":[[3.25,10.94]],"id":63994056},{"atl":[[8.6,3.49]],"id":46251065}],"con":true,"img":false}]}
{"op":"mcm","clk":"11540867942","pt":1719499331504,"mc":[{"id":"1.230178314","rc":[{"atl":[[8.6,5.04]],"id":46251065}],"con":true,"img":false}]}
{"op":"mcm","clk":"11540867953","pt":1719499331661,"mc":[{"id":"1.230178314","rc":[{"atb":[[3.15,0]],"id":63994056}],"con":true,"img":false}]}
{"op":"mcm","clk":"11540867985","pt":1719499332185,"mc":[{"id":"1.230178314","rc":[{"atb":[[3.3,1]],"id":63994056}],"con":true,"img":false}]}
{"op":"mcm","clk":"11540867999","pt":1719499332391,"mc":[{"id":"1.230178314","rc":[{"atl":[[8.8,0.84]],"id":46251065}],"con":true,"img":false}]}
{"op":"mcm","clk":"11540868007","pt":1719499332492,"mc":[{"id":"1.230178314","rc":[{"atl":[[8.4,1]],"id":46251065}],"con":true,"img":false}]}
{"op":"mcm","clk":"11540868050","pt":1719499332961,"mc":[{"id":"1.230178314","rc":[{"atb":[[2.46,0.78]],"id":63994056}],"con":true,"img":false}]}
{"op":"mcm","clk":"11540868062","pt":1719499333075,"mc":[{"id":"1.230178314","rc":[{"atb":[[2.42,3.38]],"id":63994056},{"atb":[[2.36,0]],"id":46251065}],"con":true,"img":false}]}
{"op":"mcm","clk":"11540868145","pt":1719499334507,"mc":[{"id":"1.230178314","rc":[{"atl":[[7.2,2.02]],"id":63994056}],"con":true,"img":false}]}
{"op":"mcm","clk":"11540868150","pt":1719499334609,"mc":[{"id":"1.230178314","rc":[{"atl":[[7.2,5.93],[44,0],[9.4,3.02]],"id":63994056}],"con":true,"img":false}]}
{"op":"mcm","clk":"11540868163","pt":1719499334765,"mc":[{"id":"1.230178314","rc":[{"atb":[[3.85,1],[4,3]],"id":46251065}],"con":true,"img":false}]}
{"op":"mcm","clk":"11540868179","pt":1719499335081,"mc":[{"id":"1.230178314","rc":[{"atl":[[7,0.84]],"id":63994056},{"atb":[[3.9,0.07]],"id":46251065}],"con":true,"img":false}]}
{"op":"mcm","clk":"11540868202","pt":1719499335388,"mc":[{"id":"1.230178314","rc":[{"atl":[[42,0.57]],"id":63994056}],"con":true,"img":false}]}
{"op":"mcm","clk":"11540868211","pt":1719499335490,"mc":[{"id":"1.230178314","rc":[{"atl":[[7,1.84]],"id":63994056}],"con":true,"img":false}]}
{"op":"mcm","clk":"11540868217","pt":1719499335591,"mc":[{"id":"1.230178314","rc":[{"atb":[[2.8,0],[3.6,0]],"id":46251065}],"con":true,"img":false}]}
{"op":"mcm","clk":"11540868226","pt":1719499335698,"mc":[{"id":"1.230178314","rc":[{"atl":[[6.8,3.73]],"id":63994056},{"atb":[[4,11.78]],"id":46251065}],"con":true,"img":false}]}
{"op":"mcm","clk":"11540868242","pt":1719499335901,"mc":[{"id":"1.230178314","rc":[{"atl":[[7.2,5.91]],"id":63994056}],"con":true,"img":false}]}
{"op":"mcm","clk":"11540868249","pt":1719499336003,"mc":[{"id":"1.230178314","rc":[{"atl":[[6.8,3.75]],"id":63994056}],"con":true,"img":false}]}
{"op":"mcm","clk":"11540868275","pt":1719499336267,"mc":[{"id":"1.230178314","rc":[{"atl":[[7.2,3.91]],"id":63994056}],"con":true,"img":false}]}
{"op":"mcm","clk":"11540868284","pt":1719499336366,"mc":[{"id":"1.230178314","rc":[{"atl":[[6.8,8.5],[7,0.84]],"id":63994056},{"atb":[[4.1,6.19]],"id":46251065}],"con":true,"img":false}]}
{"op":"mcm","clk":"11540868292","pt":1719499336468,"mc":[{"id":"1.230178314","rc":[{"atl":[[6.6,1]],"id":63994056},{"atb":[[4,9.78],[4.2,9.47]],"id":46251065}],"con":true,"img":false}]}
{"op":"mcm","clk":"11540868306","pt":1719499336674,"mc":[{"id":"1.230178314","rc":[{"atl":[[1000,1.69]],"id":70466763}],"con":true,"img":false}]}
{"op":"mcm","clk":"11540868331","pt":1719499336987,"mc":[{"id":"1.230178314","rc":[{"atl":[[1000,1.58]],"id":70466763}],"con":true,"img":false}]}
{"op":"mcm","clk":"11540868351","pt":1719499337294,"mc":[{"id":"1.230178314","rc":[{"atl":[[1000,0.84]],"id":70466763},{"atl":[[6.8,4.77]],"id":63994056},{"atb":[[4.1,1.41]],"id":46251065}],"con":true,"img":false}]}
{"op":"mcm","clk":"11540868358","pt":1719499337399,"mc":[{"id":"1.230178314","rc":[{"atl":[[11.5,0.73]],"id":70466763}],"con":true,"img":false}]}
{"op":"mcm","clk":"11540868363","pt":1719499337501,"mc":[{"id":"1.230178314","rc":[{"atb":[[4.3,5.9],[4.1,20.35],[3.7,0],[4.2,0]],"id":46251065}],"con":true,"img":false}]}
{"op":"mcm","clk":"11540868372","pt":1719499337609,"mc":[{"id":"1.230178314","rc":[{"atl":[[11.5,1.58]],"id":70466763},{"atb":[[4,8.78],[4.1,1.41],[4.2,19.7]],"id":46251065}],"con":true,"img":false}]}
{"op":"mcm","clk":"11540868382","pt":1719499337706,"mc":[{"id":"1.230178314","rc":[{"atl":[[70,0],[12,4.16]],"id":70466763},{"atb":[[4.3,6.9]],"id":46251065}],"con":true,"img":false}]}
{"op":"mcm","clk":"11540868392","pt":1719499337809,"mc":[{"id":"1.230178314","rc":[{"atl":[[80,0]],"id":70466763}],"con":true,"img":false}]}
{"op":"mcm","clk":"11540868401","pt":1719499337913,"mc":[{"id":"1.230178314","rc":[{"atl":[[6.8,4.75]],"id":63994056}],"con":true,"img":false}]}
