{"op":"mcm","clk":"11547086382","pt":1719432856294,"mc":[{"id":"1.230178169","marketDefinition":{"bspMarket":false,"turnInPlayEnabled":false,"persistenceEnabled":false,"marketBaseRate":5.0,"eventId":"33376048","eventTypeId":"4339","numberOfWinners":1,"bettingType":"ODDS","marketType":"FORECAST","marketTime":"2024-06-27T14:26:00.000Z","suspendTime":"2024-06-27T14:26:00.000Z","bspReconciled":false,"complete":true,"inPlay":false,"crossMatching":false,"runnersVoidable":false,"numberOfActiveRunners":30,"betDelay":0,"status":"OPEN","runners":[{"status":"ACTIVE","sortPriority":1,"id":52385882,"name":"1 - 2"},{"status":"ACTIVE","sortPriority":2,"id":52385883,"name":"1 - 3"},{"status":"ACTIVE","sortPriority":3,"id":52385884,"name":"1 - 4"},{"status":"ACTIVE","sortPriority":4,"id":52385885,"name":"1 - 5"},{"status":"ACTIVE","sortPriority":5,"id":52385886,"name":"1 - 6"},{"status":"ACTIVE","sortPriority":6,"id":52385889,"name":"2 - 1"},{"status":"ACTIVE","sortPriority":7,"id":52385890,"name":"2 - 3"},{"status":"ACTIVE","sortPriority":8,"id":52385891,"name":"2 - 4"},{"status":"ACTIVE","sortPriority":9,"id":52385892,"name":"2 - 5"},{"status":"ACTIVE","sortPriority":10,"id":52385893,"name":"2 - 6"},{"status":"ACTIVE","sortPriority":11,"id":52385896,"name":"3 - 1"},{"status":"ACTIVE","sortPriority":12,"id":52385897,"name":"3 - 2"},{"status":"ACTIVE","sortPriority":13,"id":52385898,"name":"3 - 4"},{"status":"ACTIVE","sortPriority":14,"id":52385899,"name":"3 - 5"},{"status":"ACTIVE","sortPriority":15,"id":52385900,"name":"3 - 6"},{"status":"ACTIVE","sortPriority":16,"id":52385903,"name":"4 - 1"},{"status":"ACTIVE","sortPriority":17,"id":52385904,"name":"4 - 2"},{"status":"ACTIVE","sortPriority":18,"id":52385905,"name":"4 - 3"},{"status":"ACTIVE","sortPriority":19,"id":52385906,"name":"4 - 5"},{"status":"ACTIVE","sortPriority":20,"id":52385907,"name":"4 - 6"},{"status":"ACTIVE","sortPriority":21,"id":52385910,"name":"5 - 1"},{"status":"ACTIVE","sortPriority":22,"id":52385911,"name":"5 - 2"},{"status":"ACTIVE","sortPriority":23,"id":52385912,"name":"5 - 3"},{"status":"ACTIVE","sortPriority":24,"id":52385913,"name":"5 - 4"},{"status":"ACTIVE","sortPriority":25,"id":52385914,"name":"5 - 6"},{"status":"ACTIVE","sortPriority":26,"id":52385917,"name":"6 - 1"},{"status":"ACTIVE","sortPriority":27,"id":52385918,"name":"6 - 2"},{"status":"ACTIVE","sortPriority":28,"id":52385919,"name":"6 - 3"},{"status":"ACTIVE","sortPriority":29,"id":52385920,"name":"6 - 4"},{"status":"ACTIVE","sortPriority":30,"id":52385921,"name":"6 - 5"}],"regulators":["MR_INT"],"venue":"Perry Barr","countryCode":"GB","discountAllowed":false,"timezone":"Europe/London","openDate":"2024-06-27T13:29:00.000Z","version":5994794102,"name":"Forecast","eventName":"Perry Barr (F/C) 27th Jun"},"rc":[],"con":true,"img":false}]}
{"op":"mcm","clk":"11547086544","pt":1719432858309,"mc":[{"id":"1.230178169","marketDefinition":{"bspMarket":false,"turnInPlayEnabled":false,"persistenceEnabled":false,"marketBaseRate":5.0,"eventId":"33376048","eventTypeId":"4339","numberOfWinners":1,"bettingType":"ODDS","marketType":"FORECAST","marketTime":"2024-06-27T14:26:00.000Z","suspendTime":"2024-06-27T14:26:00.000Z","bspReconciled":false,"complete":true,"inPlay":false,"crossMatching":false,"runnersVoidable":false,"numberOfActiveRunners":30,"betDelay":0,"status":"OPEN","runners":[{"status":"ACTIVE","sortPriority":1,"id":52385882,"name":"1 - 2"},{"status":"ACTIVE","sortPriority":2,"id":52385883,"name":"1 - 3"},{"status":"ACTIVE","sortPriority":3,"id":52385884,"name":"1 - 4"},{"status":"ACTIVE","sortPriority":4,"id":52385885,"name":"1 - 5"},{"status":"ACTIVE","sortPriority":5,"id":52385886,"name":"1 - 6"},{"status":"ACTIVE","sortPriority":6,"id":52385889,"name":"2 - 1"},{"status":"ACTIVE","sortPriority":7,"id":52385890,"name":"2 - 3"},{"status":"ACTIVE","sortPriority":8,"id":52385891,"name":"2 - 4"},{"status":"ACTIVE","sortPriority":9,"id":52385892,"name":"2 - 5"},{"status":"ACTIVE","sortPriority":10,"id":52385893,"name":"2 - 6"},{"status":"ACTIVE","sortPriority":11,"id":52385896,"name":"3 - 1"},{"status":"ACTIVE","sortPriority":12,"id":52385897,"name":"3 - 2"},{"status":"ACTIVE","sortPriority":13,"id":52385898,"name":"3 - 4"},{"status":"ACTIVE","sortPriority":14,"id":52385899,"name":"3 - 5"},{"status":"ACTIVE","sortPriority":15,"id":52385900,"name":"3 - 6"},{"status":"ACTIVE","sortPriority":16,"id":52385903,"name":"4 - 1"},{"status":"ACTIVE","sortPriority":17,"id":52385904,"name":"4 - 2"},{"status":"ACTIVE","sortPriority":18,"id":52385905,"name":"4 - 3"},{"status":"ACTIVE","sortPriority":19,"id":52385906,"name":"4 - 5"},{"status":"ACTIVE","sortPriority":20,"id":52385907,"name":"4 - 6"},{"status":"ACTIVE","sortPriority":21,"id":52385910,"name":"5 - 1"},{"status":"ACTIVE","sortPriority":22,"id":52385911,"name":"5 - 2"},{"status":"ACTIVE","sortPriority":23,"id":52385912,"name":"5 - 3"},{"status":"ACTIVE","sortPriority":24,"id":52385913,"name":"5 - 4"},{"status":"ACTIVE","sortPriority":25,"id":52385914,"name":"5 - 6"},{"status":"ACTIVE","sortPriority":26,"id":52385917,"name":"6 - 1"},{"status":"ACTIVE","sortPriority":27,"id":52385918,"name":"6 - 2"},{"status":"ACTIVE","sortPriority":28,"id":52385919,"name":"6 - 3"},{"status":"ACTIVE","sortPriority":29,"id":52385920,"name":"6 - 4"},{"status":"ACTIVE","sortPriority":30,"id":52385921,"name":"6 - 5"}],"regulators":["MR_INT"],"venue":"Perry Barr","countryCode":"GB","discountAllowed":true,"timezone":"Europe/London","openDate":"2024-06-27T13:29:00.000Z","version":5994794102,"name":"Forecast","eventName":"Perry Barr (F/C) 27th Jun"},"rc":[],"con":true,"img":false}]}
{"op":"mcm","clk":"11547489927","pt":1719442654841,"mc":[{"id":"1.230178169","rc":[{"atb":[[1.02,9.29]],"id":52385910},{"atb":[[1.03,6.2]],"id":52385912},{"atb":[[1.03,6.2]],"id":52385906},{"atb":[[1.01,18.6]],"id":52385918},{"atb":[[1.01,18.6]],"id":52385920},{"atb":[[1.03,6.2]],"id":52385889},{"atb":[[1.01,18.6]],"id":52385914},{"atb":[[1.01,18.6]],"id":52385883},{"atb":[[1.02,9.29]],"id":52385885},{"atb":[[1.02,9.29]],"id":52385896},{"atb":[[1.03,6.2]],"id":52385890},{"atb":[[1.02,9.29]],"id":52385892},{"atb":[[1.01,18.6]],"id":52385904},{"atb":[[1.01,18.6]],"id":52385898},{"atb":[[1.03,6.2]],"id":52385900},{"atb":[[1.03,6.2]],"id":52385911},{"atb":[[1.01,18.6]],"id":52385913},{"atb":[[1.01,18.6]],"id":52385907},{"atb":[[1.01,18.6]],"id":52385886},{"atb":[[1.03,6.2]],"id":52385919},{"atb":[[1.03,6.2]],"id":52385921},{"atb":[[1.03,6.2]],"id":52385882},{"atb":[[1.03,6.2]],"id":52385884},{"atb":[[1.03,6.2]],"id":52385917},{"atb":[[1.01,18.6]],"id":52385897},{"atb":[[1.03,6.2]],"id":52385891},{"atb":[[1.02,9.29]],"id":52385893},{"atb":[[1.03,6.2]],"id":52385903},{"atb":[[1.03,6.2]],"id":52385905},{"atb":[[1.01,18.6]],"id":52385899}],"con":true,"img":false}]}
{"op":"mcm","clk":"11547660056","pt":1719445082636,"mc":[{"id":"1.230178169","marketDefinition":{"bspMarket":false,"turnInPlayEnabled":false,"persistenceEnabled":false,"marketBaseRate":5.0,"eventId":"33376048","eventTypeId":"4339","numberOfWinners":1,"bettingType":"ODDS","marketType":"FORECAST","marketTime":"2024-06-27T14:26:00.000Z","suspendTime":"2024-06-27T14:26:00.000Z","bspReconciled":false,"complete":true,"inPlay":false,"crossMatching":false,"runnersVoidable":false,"numberOfActiveRunners":30,"betDelay":0,"status":"OPEN","runners":[{"status":"ACTIVE","sortPriority":1,"id":52385882,"name":"1 - 2"},{"status":"ACTIVE","sortPriority":2,"id":52385883,"name":"1 - 3"},{"status":"ACTIVE","sortPriority":3,"id":52385884,"name":"1 - 4"},{"status":"ACTIVE","sortPriority":4,"id":52385885,"name":"1 - 5"},{"status":"ACTIVE","sortPriority":5,"id":52385886,"name":"1 - 6"},{"status":"ACTIVE","sortPriority":6,"id":52385889,"name":"2 - 1"},{"status":"ACTIVE","sortPriority":7,"id":52385890,"name":"2 - 3"},{"status":"ACTIVE","sortPriority":8,"id":52385891,"name":"2 - 4"},{"status":"ACTIVE","sortPriority":9,"id":52385892,"name":"2 - 5"},{"status":"ACTIVE","sortPriority":10,"id":52385893,"name":"2 - 6"},{"status":"ACTIVE","sortPriority":11,"id":52385896,"name":"3 - 1"},{"status":"ACTIVE","sortPriority":12,"id":52385897,"name":"3 - 2"},{"status":"ACTIVE","sortPriority":13,"id":52385898,"name":"3 - 4"},{"status":"ACTIVE","sortPriority":14,"id":52385899,"name":"3 - 5"},{"status":"ACTIVE","sortPriority":15,"id":52385900,"name":"3 - 6"},{"status":"ACTIVE","sortPriority":16,"id":52385903,"name":"4 - 1"},{"status":"ACTIVE","sortPriority":17,"id":52385904,"name":"4 - 2"},{"status":"ACTIVE","sortPriority":18,"id":52385905,"name":"4 - 3"},{"status":"ACTIVE","sortPriority":19,"id":52385906,"name":"4 - 5"},{"status":"ACTIVE","sortPriority":20,"id":52385907,"name":"4 - 6"},{"status":"ACTIVE","sortPriority":21,"id":52385910,"name":"5 - 1"},{"status":"ACTIVE","sortPriority":22,"id":52385911,"name":"5 - 2"},{"status":"ACTIVE","sortPriority":23,"id":52385912,"name":"5 - 3"},{"status":"ACTIVE","sortPriority":24,"id":52385913,"name":"5 - 4"},{"status":"ACTIVE","sortPriority":25,"id":52385914,"name":"5 - 6"},{"status":"ACTIVE","sortPriority":26,"id":52385917,"name":"6 - 1"},{"status":"ACTIVE","sortPriority":27,"id":52385918,"name":"6 - 2"},{"status":"ACTIVE","sortPriority":28,"id":52385919,"name":"6 - 3"},{"status":"ACTIVE","sortPriority":29,"id":52385920,"name":"6 - 4"},{"status":"ACTIVE","sortPriority":30,"id":52385921,"name":"6 - 5"}],"regulators":["MR_INT"],"venue":"Perry Barr","countryCode":"GB","discountAllowed":true,"timezone":"Europe/London","openDate":"2024-06-27T13:29:00.000Z","version":5994794102,"name":"Forecast","eventName":"Perry Barr (F/C) 27th Jun"},"rc":[{"atb":[[1.02,9.3]],"id":52385910},{"atb":[[1.03,6.2]],"id":52385912},{"atb":[[1.03,6.2]],"id":52385906},{"atb":[[1.01,18.6]],"id":52385918},{"atb":[[1.01,18.6]],"id":52385920},{"atb":[[1.03,6.2]],"id":52385889},{"atb":[[1.01,18.6]],"id":52385914},{"atb":[[1.01,18.6]],"id":52385883},{"atb":[[1.02,9.3]],"id":52385885},{"atb":[[1.02,9.3]],"id":52385896},{"atb":[[1.03,6.2]],"id":52385890},{"atb":[[1.02,9.3]],"id":52385892},{"atb":[[1.01,18.6]],"id":52385904},{"atb":[[1.01,18.6]],"id":52385898},{"atb":[[1.03,6.2]],"id":52385900},{"atb":[[1.03,6.2]],"id":52385911},{"atb":[[1.01,18.6]],"id":52385913},{"atb":[[1.01,18.6]],"id":52385907},{"atb":[[1.01,18.6]],"id":52385886},{"atb":[[1.03,6.2]],"id":52385919},{"atb":[[1.03,6.2]],"id":52385921},{"atb":[[1.03,6.2]],"id":52385882},{"atb":[[1.03,6.2]],"id":52385884},{"atb":[[1.03,6.2]],"id":52385917},{"atb":[[1.01,18.6]],"id":52385897},{"atb":[[1.03,6.2]],"id":52385891},{"atb":[[1.02,9.3]],"id":52385893},{"atb":[[1.03,6.2]],"id":52385903},{"atb":[[1.03,6.2]],"id":52385905},{"atb":[[1.01,18.6]],"id":52385899}],"con":true,"img":true}]}
{"op":"mcm","clk":"11548032131","pt":1719450482665,"mc":[{"id":"1.230178169","marketDefinition":{"bspMarket":false,"turnInPlayEnabled":false,"persistenceEnabled":false,"marketBaseRate":5.0,"eventId":"33376048","eventTypeId":"4339","numberOfWinners":1,"bettingType":"ODDS","marketType":"FORECAST","marketTime":"2024-06-27T14:26:00.000Z","suspendTime":"2024-06-27T14:26:00.000Z","bspReconciled":false,"complete":true,"inPlay":false,"crossMatching":false,"runnersVoidable":false,"numberOfActiveRunners":30,"betDelay":0,"status":"OPEN","runners":[{"status":"ACTIVE","sortPriority":1,"id":52385882,"name":"1 - 2"},{"status":"ACTIVE","sortPriority":2,"id":52385883,"name":"1 - 3"},{"status":"ACTIVE","sortPriority":3,"id":52385884,"name":"1 - 4"},{"status":"ACTIVE","sortPriority":4,"id":52385885,"name":"1 - 5"},{"status":"ACTIVE","sortPriority":5,"id":52385886,"name":"1 - 6"},{"status":"ACTIVE","sortPriority":6,"id":52385889,"name":"2 - 1"},{"status":"ACTIVE","sortPriority":7,"id":52385890,"name":"2 - 3"},{"status":"ACTIVE","sortPriority":8,"id":52385891,"name":"2 - 4"},{"status":"ACTIVE","sortPriority":9,"id":52385892,"name":"2 - 5"},{"status":"ACTIVE","sortPriority":10,"id":52385893,"name":"2 - 6"},{"status":"ACTIVE","sortPriority":11,"id":52385896,"name":"3 - 1"},{"status":"ACTIVE","sortPriority":12,"id":52385897,"name":"3 - 2"},{"status":"ACTIVE","sortPriority":13,"id":52385898,"name":"3 - 4"},{"status":"ACTIVE","sortPriority":14,"id":52385899,"name":"3 - 5"},{"status":"ACTIVE","sortPriority":15,"id":52385900,"name":"3 - 6"},{"status":"ACTIVE","sortPriority":16,"id":52385903,"name":"4 - 1"},{"status":"ACTIVE","sortPriority":17,"id":52385904,"name":"4 - 2"},{"status":"ACTIVE","sortPriority":18,"id":52385905,"name":"4 - 3"},{"status":"ACTIVE","sortPriority":19,"id":52385906,"name":"4 - 5"},{"status":"ACTIVE","sortPriority":20,"id":52385907,"name":"4 - 6"},{"status":"ACTIVE","sortPriority":21,"id":52385910,"name":"5 - 1"},{"status":"ACTIVE","sortPriority":22,"id":52385911,"name":"5 - 2"},{"status":"ACTIVE","sortPriority":23,"id":52385912,"name":"5 - 3"},{"status":"ACTIVE","sortPriority":24,"id":52385913,"name":"5 - 4"},{"status":"ACTIVE","sortPriority":25,"id":52385914,"name":"5 - 6"},{"status":"ACTIVE","sortPriority":26,"id":52385917,"name":"6 - 1"},{"status":"ACTIVE","sortPriority":27,"id":52385918,"name":"6 - 2"},{"status":"ACTIVE","sortPriority":28,"id":52385919,"name":"6 - 3"},{"status":"ACTIVE","sortPriority":29,"id":52385920,"name":"6 - 4"},{"status":"ACTIVE","sortPriority":30,"id":52385921,"name":"6 - 5"}],"regulators":["MR_INT"],"venue":"Perry Barr","countryCode":"GB","discountAllowed":true,"timezone":"Europe/London","openDate":"2024-06-27T13:29:00.000Z","version":5994794102,"name":"Forecast","eventName":"Perry Barr (F/C) 27th Jun"},"rc":[{"atb":[[1.02,9.3]],"id":52385910},{"atb":[[1.03,6.2]],"id":52385912},{"atb":[[1.03,6.2]],"id":52385906},{"atb":[[1.01,18.61]],"id":52385918},{"atb":[[1.01,18.61]],"id":52385920},{"atb":[[1.03,6.2]],"id":52385889},{"atb":[[1.01,18.61]],"id":52385914},{"atb":[[1.01,18.61]],"id":52385883},{"atb":[[1.02,9.3]],"id":52385885},{"atb":[[1.02,9.3]],"id":52385896},{"atb":[[1.03,6.2]],"id":52385890},{"atb":[[1.02,9.3]],"id":52385892},{"atb":[[1.01,18.61]],"id":52385904},{"atb":[[1.01,18.61]],"id":52385898},{"atb":[[1.03,6.2]],"id":52385900},{"atb":[[1.03,6.2]],"id":52385911},{"atb":[[1.01,18.61]],"id":52385913},{"atb":[[1.01,18.61]],"id":52385907},{"atb":[[1.01,18.61]],"id":52385886},{"atb":[[1.03,6.2]],"id":52385919},{"atb":[[1.03,6.2]],"id":52385921},{"atb":[[1.03,6.2]],"id":52385882},{"atb":[[1.03,6.2]],"id":52385884},{"atb":[[1.03,6.2]],"id":52385917},{"atb":[[1.01,18.61]],"id":52385897},{"atb":[[1.03,6.2]],"id":52385891},{"atb":[[1.02,9.3]],"id":52385893},{"atb":[[1.03,6.2]],"id":52385903},{"atb":[[1.03,6.2]],"id":52385905},{"atb":[[1.01,18.61]],"id":52385899}],"con":true,"img":true}]}
{"op":"mcm","clk":"11548271168","pt":1719455882674,"mc":[{"id":"1.230178169","marketDefinition":{"bspMarket":false,"turnInPlayEnabled":false,"persistenceEnabled":false,"marketBaseRate":5.0,"eventId":"33376048","eventTypeId":"4339","numberOfWinners":1,"bettingType":"ODDS","marketType":"FORECAST","marketTime":"2024-06-27T14:26:00.000Z","suspendTime":"2024-06-27T14:26:00.000Z","bspReconciled":false,"complete":true,"inPlay":false,"crossMatching":false,"runnersVoidable":false,"numberOfActiveRunners":30,"betDelay":0,"status":"OPEN","runners":[{"status":"ACTIVE","sortPriority":1,"id":52385882,"name":"1 - 2"},{"status":"ACTIVE","sortPriority":2,"id":52385883,"name":"1 - 3"},{"status":"ACTIVE","sortPriority":3,"id":52385884,"name":"1 - 4"},{"status":"ACTIVE","sortPriority":4,"id":52385885,"name":"1 - 5"},{"status":"ACTIVE","sortPriority":5,"id":52385886,"name":"1 - 6"},{"status":"ACTIVE","sortPriority":6,"id":52385889,"name":"2 - 1"},{"status":"ACTIVE","sortPriority":7,"id":52385890,"name":"2 - 3"},{"status":"ACTIVE","sortPriority":8,"id":52385891,"name":"2 - 4"},{"status":"ACTIVE","sortPriority":9,"id":52385892,"name":"2 - 5"},{"status":"ACTIVE","sortPriority":10,"id":52385893,"name":"2 - 6"},{"status":"ACTIVE","sortPriority":11,"id":52385896,"name":"3 - 1"},{"status":"ACTIVE","sortPriority":12,"id":52385897,"name":"3 - 2"},{"status":"ACTIVE","sortPriority":13,"id":52385898,"name":"3 - 4"},{"status":"ACTIVE","sortPriority":14,"id":52385899,"name":"3 - 5"},{"status":"ACTIVE","sortPriority":15,"id":52385900,"name":"3 - 6"},{"status":"ACTIVE","sortPriority":16,"id":52385903,"name":"4 - 1"},{"status":"ACTIVE","sortPriority":17,"id":52385904,"name":"4 - 2"},{"status":"ACTIVE","sortPriority":18,"id":52385905,"name":"4 - 3"},{"status":"ACTIVE","sortPriority":19,"id":52385906,"name":"4 - 5"},{"status":"ACTIVE","sortPriority":20,"id":52385907,"name":"4 - 6"},{"status":"ACTIVE","sortPriority":21,"id":52385910,"name":"5 - 1"},{"status":"ACTIVE","sortPriority":22,"id":52385911,"name":"5 - 2"},{"status":"ACTIVE","sortPriority":23,"id":52385912,"name":"5 - 3"},{"status":"ACTIVE","sortPriority":24,"id":52385913,"name":"5 - 4"},{"status":"ACTIVE","sortPriority":25,"id":52385914,"name":"5 - 6"},{"status":"ACTIVE","sortPriority":26,"id":52385917,"name":"6 - 1"},{"status":"ACTIVE","sortPriority":27,"id":52385918,"name":"6 - 2"},{"status":"ACTIVE","sortPriority":28,"id":52385919,"name":"6 - 3"},{"status":"ACTIVE","sortPriority":29,"id":52385920,"name":"6 - 4"},{"status":"ACTIVE","sortPriority":30,"id":52385921,"name":"6 - 5"}],"regulators":["MR_INT"],"venue":"Perry Barr","countryCode":"GB","discountAllowed":true,"timezone":"Europe/London","openDate":"2024-06-27T13:29:00.000Z","version":5994794102,"name":"Forecast","eventName":"Perry Barr (F/C) 27th Jun"},"rc":[{"atb":[[1.02,9.3]],"id":52385910},{"atb":[[1.03,6.2]],"id":52385912},{"atb":[[1.03,6.2]],"id":52385906},{"atb":[[1.01,18.61]],"id":52385918},{"atb":[[1.01,18.61]],"id":52385920},{"atb":[[1.03,6.2]],"id":52385889},{"atb":[[1.01,18.61]],"id":52385914},{"atb":[[1.01,18.61]],"id":52385883},{"atb":[[1.02,9.3]],"id":52385885},{"atb":[[1.02,9.3]],"id":52385896},{"atb":[[1.03,6.2]],"id":52385890},{"atb":[[1.02,9.3]],"id":52385892},{"atb":[[1.01,18.61]],"id":52385904},{"atb":[[1.01,18.61]],"id":52385898},{"atb":[[1.03,6.2]],"id":52385900},{"atb":[[1.03,6.2]],"id":52385911},{"atb":[[1.01,18.61]],"id":52385913},{"atb":[[1.01,18.61]],"id":52385907},{"atb":[[1.01,18.61]],"id":52385886},{"atb":[[1.03,6.2]],"id":52385919},{"atb":[[1.03,6.2]],"id":52385921},{"atb":[[1.03,6.2]],"id":52385882},{"atb":[[1.03,6.2]],"id":52385884},{"atb":[[1.03,6.2]],"id":52385917},{"atb":[[1.01,18.61]],"id":52385897},{"atb":[[1.03,6.2]],"id":52385891},{"atb":[[1.02,9.3]],"id":52385893},{"atb":[[1.03,6.2]],"id":52385903},{"atb":[[1.03,6.2]],"id":52385905},{"atb":[[1.01,18.61]],"id":52385899}],"con":true,"img":true}]}
{"op":"mcm","clk":"11548413063","pt":1719460856272,"mc":[{"id":"1.230178169","rc":[{"atb":[[1.16,100],[1.02,9.3]],"id":52385910},{"atb":[[1.03,6.2],[1.16,100]],"id":52385912},{"atb":[[1.03,6.2],[1.16,100]],"id":52385906},{"atb":[[1.01,18.61],[1.16,100]],"id":52385918},{"atb":[[1.01,18.61],[1.16,100]],"id":52385920},{"atb":[[1.03,6.2],[1.16,100]],"id":52385889},{"atb":[[1.01,18.61],[1.16,100]],"id":52385914},{"atb":[[1.01,18.61],[1.16,100]],"id":52385883},{"atb":[[1.16,100],[1.02,9.3]],"id":52385885},{"atb":[[1.16,100],[1.02,9.3]],"id":52385896},{"atb":[[1.03,6.2],[1.16,100]],"id":52385890},{"atb":[[1.16,100],[1.02,9.3]],"id":52385892},{"atb":[[1.01,18.61],[1.16,100]],"id":52385904},{"atb":[[1.01,18.61],[1.16,100]],"id":52385898},{"atb":[[1.03,6.2],[1.16,100]],"id":52385900},{"atb":[[1.03,6.2],[1.16,100]],"id":52385911},{"atb":[[1.01,18.61],[1.16,100]],"id":52385913},{"atb":[[1.01,18.61],[1.16,100]],"id":52385907},{"atb":[[1.01,18.61],[1.16,100]],"id":52385886},{"atb":[[1.03,6.2],[1.16,100]],"id":52385919},{"atb":[[1.03,6.2],[1.16,100]],"id":52385921},{"atb":[[1.03,6.2],[1.16,100]],"id":52385882},{"atb":[[1.03,6.2],[1.16,100]],"id":52385884},{"atb":[[1.03,6.2],[1.16,100]],"id":52385917},{"atb":[[1.01,18.61],[1.16,100]],"id":52385897},{"atb":[[1.03,6.2],[1.16,100]],"id":52385891},{"atb":[[1.16,100],[1.02,9.3]],"id":52385893},{"atb":[[1.03,6.2],[1.16,100]],"id":52385903},{"atb":[[1.03,6.2],[1.16,100]],"id":52385905},{"atb":[[1.01,18.61],[1.16,100]],"id":52385899}],"con":true,"img":false}]}
{"op":"mcm","clk":"11548536095","pt":1719466682836,"mc":[{"id":"1.230178169","marketDefinition":{"bspMarket":false,"turnInPlayEnabled":false,"persistenceEnabled":false,"marketBaseRate":5.0,"eventId":"33376048","eventTypeId":"4339","numberOfWinners":1,"bettingType":"ODDS","marketType":"FORECAST","marketTime":"2024-06-27T14:26:00.000Z","suspendTime":"2024-06-27T14:26:00.000Z","bspReconciled":false,"complete":true,"inPlay":false,"crossMatching":false,"runnersVoidable":false,"numberOfActiveRunners":30,"betDelay":0,"status":"OPEN","runners":[{"status":"ACTIVE","sortPriority":1,"id":52385882,"name":"1 - 2"},{"status":"ACTIVE","sortPriority":2,"id":52385883,"name":"1 - 3"},{"status":"ACTIVE","sortPriority":3,"id":52385884,"name":"1 - 4"},{"status":"ACTIVE","sortPriority":4,"id":52385885,"name":"1 - 5"},{"status":"ACTIVE","sortPriority":5,"id":52385886,"name":"1 - 6"},{"status":"ACTIVE","sortPriority":6,"id":52385889,"name":"2 - 1"},{"status":"ACTIVE","sortPriority":7,"id":52385890,"name":"2 - 3"},{"status":"ACTIVE","sortPriority":8,"id":52385891,"name":"2 - 4"},{"status":"ACTIVE","sortPriority":9,"id":52385892,"name":"2 - 5"},{"status":"ACTIVE","sortPriority":10,"id":52385893,"name":"2 - 6"},{"status":"ACTIVE","sortPriority":11,"id":52385896,"name":"3 - 1"},{"status":"ACTIVE","sortPriority":12,"id":52385897,"name":"3 - 2"},{"status":"ACTIVE","sortPriority":13,"id":52385898,"name":"3 - 4"},{"status":"ACTIVE","sortPriority":14,"id":52385899,"name":"3 - 5"},{"status":"ACTIVE","sortPriority":15,"id":52385900,"name":"3 - 6"},{"status":"ACTIVE","sortPriority":16,"id":52385903,"name":"4 - 1"},{"status":"ACTIVE","sortPriority":17,"id":52385904,"name":"4 - 2"},{"status":"ACTIVE","sortPriority":18,"id":52385905,"name":"4 - 3"},{"status":"ACTIVE","sortPriority":19,"id":52385906,"name":"4 - 5"},{"status":"ACTIVE","sortPriority":20,"id":52385907,"name":"4 - 6"},{"status":"ACTIVE","sortPriority":21,"id":52385910,"name":"5 - 1"},{"status":"ACTIVE","sortPriority":22,"id":52385911,"name":"5 - 2"},{"status":"ACTIVE","sortPriority":23,"id":52385912,"name":"5 - 3"},{"status":"ACTIVE","sortPriority":24,"id":52385913,"name":"5 - 4"},{"status":"ACTIVE","sortPriority":25,"id":52385914,"name":"5 - 6"},{"status":"ACTIVE","sortPriority":26,"id":52385917,"name":"6 - 1"},{"status":"ACTIVE","sortPriority":27,"id":52385918,"name":"6 - 2"},{"status":"ACTIVE","sortPriority":28,"id":52385919,"name":"6 - 3"},{"status":"ACTIVE","sortPriority":29,"id":52385920,"name":"6 - 4"},{"status":"ACTIVE","sortPriority":30,"id":52385921,"name":"6 - 5"}],"regulators":["MR_INT"],"venue":"Perry Barr","countryCode":"GB","discountAllowed":true,"timezone":"Europe/London","openDate":"2024-06-27T13:29:00.000Z","version":5994794102,"name":"Forecast","eventName":"Perry Barr (F/C) 27th Jun"},"rc":[{"atb":[[1.16,100],[1.02,9.3]],"id":52385910},{"atb":[[1.16,100],[1.03,6.2]],"id":52385912},{"atb":[[1.16,100],[1.03,6.2]],"id":52385906},{"atb":[[1.01,18.61],[1.16,100]],"id":52385918},{"atb":[[1.01,18.61],[1.16,100]],"id":52385920},{"atb":[[1.16,100],[1.03,6.2]],"id":52385889},{"atb":[[1.01,18.61],[1.16,100]],"id":52385914},{"atb":[[1.01,18.61],[1.16,100]],"id":52385883},{"atb":[[1.16,100],[1.02,9.3]],"id":52385885},{"atb":[[1.16,100],[1.02,9.3]],"id":52385896},{"atb":[[1.16,100],[1.03,6.2]],"id":52385890},{"atb":[[1.16,100],[1.02,9.3]],"id":52385892},{"atb":[[1.01,18.61],[1.16,100]],"id":52385904},{"atb":[[1.01,18.61],[1.16,100]],"id":52385898},{"atb":[[1.16,100],[1.03,6.2]],"id":52385900},{"atb":[[1.16,100],[1.03,6.2]],"id":52385911},{"atb":[[1.01,18.61],[1.16,100]],"id":52385913},{"atb":[[1.01,18.61],[1.16,100]],"id":52385907},{"atb":[[1.01,18.61],[1.16,100]],"id":52385886},{"atb":[[1.16,100],[1.03,6.2]],"id":52385919},{"atb":[[1.16,100],[1.03,6.2]],"id":52385921},{"atb":[[1.16,100],[1.03,6.2]],"id":52385882},{"atb":[[1.16,100],[1.03,6.2]],"id":52385884},{"atb":[[1.16,100],[1.03,6.2]],"id":52385917},{"atb":[[1.01,18.61],[1.16,100]],"id":52385897},{"atb":[[1.16,100],[1.03,6.2]],"id":52385891},{"atb":[[1.16,100],[1.02,9.3]],"id":52385893},{"atb":[[1.16,100],[1.03,6.2]],"id":52385903},{"atb":[[1.16,100],[1.03,6.2]],"id":52385905},{"atb":[[1.01,18.61],[1.16,100]],"id":52385899}],"con":true,"img":true}]}
{"op":"mcm","clk":"11548656557","pt":1719472082607,"mc":[{"id":"1.230178169","marketDefinition":{"bspMarket":false,"turnInPlayEnabled":false,"persistenceEnabled":false,"marketBaseRate":5.0,"eventId":"33376048","eventTypeId":"4339","numberOfWinners":1,"bettingType":"ODDS","marketType":"FORECAST","marketTime":"2024-06-27T14:26:00.000Z","suspendTime":"2024-06-27T14:26:00.000Z","bspReconciled":false,"complete":true,"inPlay":false,"crossMatching":false,"runnersVoidable":false,"numberOfActiveRunners":30,"betDelay":0,"status":"OPEN","runners":[{"status":"ACTIVE","sortPriority":1,"id":52385882,"name":"1 - 2"},{"status":"ACTIVE","sortPriority":2,"id":52385883,"name":"1 - 3"},{"status":"ACTIVE","sortPriority":3,"id":52385884,"name":"1 - 4"},{"status":"ACTIVE","sortPriority":4,"id":52385885,"name":"1 - 5"},{"status":"ACTIVE","sortPriority":5,"id":52385886,"name":"1 - 6"},{"status":"ACTIVE","sortPriority":6,"id":52385889,"name":"2 - 1"},{"status":"ACTIVE","sortPriority":7,"id":52385890,"name":"2 - 3"},{"status":"ACTIVE","sortPriority":8,"id":52385891,"name":"2 - 4"},{"status":"ACTIVE","sortPriority":9,"id":52385892,"name":"2 - 5"},{"status":"ACTIVE","sortPriority":10,"id":52385893,"name":"2 - 6"},{"status":"ACTIVE","sortPriority":11,"id":52385896,"name":"3 - 1"},{"status":"ACTIVE","sortPriority":12,"id":52385897,"name":"3 - 2"},{"status":"ACTIVE","sortPriority":13,"id":52385898,"name":"3 - 4"},{"status":"ACTIVE","sortPriority":14,"id":52385899,"name":"3 - 5"},{"status":"ACTIVE","sortPriority":15,"id":52385900,"name":"3 - 6"},{"status":"ACTIVE","sortPriority":16,"id":52385903,"name":"4 - 1"},{"status":"ACTIVE","sortPriority":17,"id":52385904,"name":"4 - 2"},{"status":"ACTIVE","sortPriority":18,"id":52385905,"name":"4 - 3"},{"status":"ACTIVE","sortPriority":19,"id":52385906,"name":"4 - 5"},{"status":"ACTIVE","sortPriority":20,"id":52385907,"name":"4 - 6"},{"status":"ACTIVE","sortPriority":21,"id":52385910,"name":"5 - 1"},{"status":"ACTIVE","sortPriority":22,"id":52385911,"name":"5 - 2"},{"status":"ACTIVE","sortPriority":23,"id":52385912,"name":"5 - 3"},{"status":"ACTIVE","sortPriority":24,"id":52385913,"name":"5 - 4"},{"status":"ACTIVE","sortPriority":25,"id":52385914,"name":"5 - 6"},{"status":"ACTIVE","sortPriority":26,"id":52385917,"name":"6 - 1"},{"status":"ACTIVE","sortPriority":27,"id":52385918,"name":"6 - 2"},{"status":"ACTIVE","sortPriority":28,"id":52385919,"name":"6 - 3"},{"status":"ACTIVE","sortPriority":29,"id":52385920,"name":"6 - 4"},{"status":"ACTIVE","sortPriority":30,"id":52385921,"name":"6 - 5"}],"regulators":["MR_INT"],"venue":"Perry Barr","countryCode":"GB","discountAllowed":true,"timezone":"Europe/London","openDate":"2024-06-27T13:29:00.000Z","version":5994794102,"name":"Forecast","eventName":"Perry Barr (F/C) 27th Jun"},"rc":[{"atb":[[1.16,100],[1.02,9.29]],"id":52385910},{"atb":[[1.16,100],[1.03,6.19]],"id":52385912},{"atb":[[1.16,100],[1.03,6.19]],"id":52385906},{"atb":[[1.01,18.59],[1.16,100]],"id":52385918},{"atb":[[1.01,18.59],[1.16,100]],"id":52385920},{"atb":[[1.16,100],[1.03,6.19]],"id":52385889},{"atb":[[1.01,18.59],[1.16,100]],"id":52385914},{"atb":[[1.01,18.59],[1.16,100]],"id":52385883},{"atb":[[1.16,100],[1.02,9.29]],"id":52385885},{"atb":[[1.16,100],[1.02,9.29]],"id":52385896},{"atb":[[1.16,100],[1.03,6.19]],"id":52385890},{"atb":[[1.16,100],[1.02,9.29]],"id":52385892},{"atb":[[1.01,18.59],[1.16,100]],"id":52385904},{"atb":[[1.01,18.59],[1.16,100]],"id":52385898},{"atb":[[1.16,100],[1.03,6.19]],"id":52385900},{"atb":[[1.16,100],[1.03,6.19]],"id":52385911},{"atb":[[1.01,18.59],[1.16,100]],"id":52385913},{"atb":[[1.01,18.59],[1.16,100]],"id":52385907},{"atb":[[1.01,18.59],[1.16,100]],"id":52385886},{"atb":[[1.16,100],[1.03,6.19]],"id":52385919},{"atb":[[1.16,100],[1.03,6.19]],"id":52385921},{"atb":[[1.16,100],[1.03,6.19]],"id":52385882},{"atb":[[1.16,100],[1.03,6.19]],"id":52385884},{"atb":[[1.16,100],[1.03,6.19]],"id":52385917},{"atb":[[1.01,18.59],[1.16,100]],"id":52385897},{"atb":[[1.16,100],[1.03,6.19]],"id":52385891},{"atb":[[1.16,100],[1.02,9.29]],"id":52385893},{"atb":[[1.16,100],[1.03,6.19]],"id":52385903},{"atb":[[1.16,100],[1.03,6.19]],"id":52385905},{"atb":[[1.01,18.59],[1.16,100]],"id":52385899}],"con":true,"img":true}]}
{"op":"mcm","clk":"11548862325","pt":1719477482605,"mc":[{"id":"1.230178169","marketDefinition":{"bspMarket":false,"turnInPlayEnabled":false,"persistenceEnabled":false,"marketBaseRate":5.0,"eventId":"33376048","eventTypeId":"4339","numberOfWinners":1,"bettingType":"ODDS","marketType":"FORECAST","marketTime":"2024-06-27T14:26:00.000Z","suspendTime":"2024-06-27T14:26:00.000Z","bspReconciled":false,"complete":true,"inPlay":false,"crossMatching":false,"runnersVoidable":false,"numberOfActiveRunners":30,"betDelay":0,"status":"OPEN","runners":[{"status":"ACTIVE","sortPriority":1,"id":52385882,"name":"1 - 2"},{"status":"ACTIVE","sortPriority":2,"id":52385883,"name":"1 - 3"},{"status":"ACTIVE","sortPriority":3,"id":52385884,"name":"1 - 4"},{"status":"ACTIVE","sortPriority":4,"id":52385885,"name":"1 - 5"},{"status":"ACTIVE","sortPriority":5,"id":52385886,"name":"1 - 6"},{"status":"ACTIVE","sortPriority":6,"id":52385889,"name":"2 - 1"},{"status":"ACTIVE","sortPriority":7,"id":52385890,"name":"2 - 3"},{"status":"ACTIVE","sortPriority":8,"id":52385891,"name":"2 - 4"},{"status":"ACTIVE","sortPriority":9,"id":52385892,"name":"2 - 5"},{"status":"ACTIVE","sortPriority":10,"id":52385893,"name":"2 - 6"},{"status":"ACTIVE","sortPriority":11,"id":52385896,"name":"3 - 1"},{"status":"ACTIVE","sortPriority":12,"id":52385897,"name":"3 - 2"},{"status":"ACTIVE","sortPriority":13,"id":52385898,"name":"3 - 4"},{"status":"ACTIVE","sortPriority":14,"id":52385899,"name":"3 - 5"},{"status":"ACTIVE","sortPriority":15,"id":52385900,"name":"3 - 6"},{"status":"ACTIVE","sortPriority":16,"id":52385903,"name":"4 - 1"},{"status":"ACTIVE","sortPriority":17,"id":52385904,"name":"4 - 2"},{"status":"ACTIVE","sortPriority":18,"id":52385905,"name":"4 - 3"},{"status":"ACTIVE","sortPriority":19,"id":52385906,"name":"4 - 5"},{"status":"ACTIVE","sortPriority":20,"id":52385907,"name":"4 - 6"},{"status":"ACTIVE","sortPriority":21,"id":52385910,"name":"5 - 1"},{"status":"ACTIVE","sortPriority":22,"id":52385911,"name":"5 - 2"},{"status":"ACTIVE","sortPriority":23,"id":52385912,"name":"5 - 3"},{"status":"ACTIVE","sortPriority":24,"id":52385913,"name":"5 - 4"},{"status":"ACTIVE","sortPriority":25,"id":52385914,"name":"5 - 6"},{"status":"ACTIVE","sortPriority":26,"id":52385917,"name":"6 - 1"},{"status":"ACTIVE","sortPriority":27,"id":52385918,"name":"6 - 2"},{"status":"ACTIVE","sortPriority":28,"id":52385919,"name":"6 - 3"},{"status":"ACTIVE","sortPriority":29,"id":52385920,"name":"6 - 4"},{"status":"ACTIVE","sortPriority":30,"id":52385921,"name":"6 - 5"}],"regulators":["MR_INT"],"venue":"Perry Barr","countryCode":"GB","discountAllowed":true,"timezone":"Europe/London","openDate":"2024-06-27T13:29:00.000Z","version":5994794102,"name":"Forecast","eventName":"Perry Barr (F/C) 27th Jun"},"rc":[{"atb":[[1.16,100],[1.02,9.29]],"id":52385910},{"atb":[[1.16,100],[1.03,6.2]],"id":52385912},{"atb":[[1.16,100],[1.03,6.2]],"id":52385906},{"atb":[[1.01,18.6],[1.16,100]],"id":52385918},{"atb":[[1.01,18.6],[1.16,100]],"id":52385920},{"atb":[[1.16,100],[1.03,6.2]],"id":52385889},{"atb":[[1.01,18.6],[1.16,100]],"id":52385914},{"atb":[[1.01,18.6],[1.16,100]],"id":52385883},{"atb":[[1.16,100],[1.02,9.29]],"id":52385885},{"atb":[[1.16,100],[1.02,9.29]],"id":52385896},{"atb":[[1.16,100],[1.03,6.2]],"id":52385890},{"atb":[[1.16,100],[1.02,9.29]],"id":52385892},{"atb":[[1.01,18.6],[1.16,100]],"id":52385904},{"atb":[[1.01,18.6],[1.16,100]],"id":52385898},{"atb":[[1.16,100],[1.03,6.2]],"id":52385900},{"atb":[[1.16,100],[1.03,6.2]],"id":52385911},{"atb":[[1.01,18.6],[1.16,100]],"id":52385913},{"atb":[[1.01,18.6],[1.16,100]],"id":52385907},{"atb":[[1.01,18.6],[1.16,100]],"id":52385886},{"atb":[[1.16,100],[1.03,6.2]],"id":52385919},{"atb":[[1.16,100],[1.03,6.2]],"id":52385921},{"atb":[[1.16,100],[1.03,6.2]],"id":52385882},{"atb":[[1.16,100],[1.03,6.2]],"id":52385884},{"atb":[[1.16,100],[1.03,6.2]],"id":52385917},{"atb":[[1.01,18.6],[1.16,100]],"id":52385897},{"atb":[[1.16,100],[1.03,6.2]],"id":52385891},{"atb":[[1.16,100],[1.02,9.29]],"id":52385893},{"atb":[[1.16,100],[1.03,6.2]],"id":52385903},{"atb":[[1.16,100],[1.03,6.2]],"id":52385905},{"atb":[[1.01,18.6],[1.16,100]],"id":52385899}],"con":true,"img":true}]}
{"op":"mcm","clk":"11549140667","pt":1719482882609,"mc":[{"id":"1.230178169","marketDefinition":{"bspMarket":false,"turnInPlayEnabled":false,"persistenceEnabled":false,"marketBaseRate":5.0,"eventId":"33376048","eventTypeId":"4339","numberOfWinners":1,"bettingType":"ODDS","marketType":"FORECAST","marketTime":"2024-06-27T14:26:00.000Z","suspendTime":"2024-06-27T14:26:00.000Z","bspReconciled":false,"complete":true,"inPlay":false,"crossMatching":false,"runnersVoidable":false,"numberOfActiveRunners":30,"betDelay":0,"status":"OPEN","runners":[{"status":"ACTIVE","sortPriority":1,"id":52385882,"name":"1 - 2"},{"status":"ACTIVE","sortPriority":2,"id":52385883,"name":"1 - 3"},{"status":"ACTIVE","sortPriority":3,"id":52385884,"name":"1 - 4"},{"status":"ACTIVE","sortPriority":4,"id":52385885,"name":"1 - 5"},{"status":"ACTIVE","sortPriority":5,"id":52385886,"name":"1 - 6"},{"status":"ACTIVE","sortPriority":6,"id":52385889,"name":"2 - 1"},{"status":"ACTIVE","sortPriority":7,"id":52385890,"name":"2 - 3"},{"status":"ACTIVE","sortPriority":8,"id":52385891,"name":"2 - 4"},{"status":"ACTIVE","sortPriority":9,"id":52385892,"name":"2 - 5"},{"status":"ACTIVE","sortPriority":10,"id":52385893,"name":"2 - 6"},{"status":"ACTIVE","sortPriority":11,"id":52385896,"name":"3 - 1"},{"status":"ACTIVE","sortPriority":12,"id":52385897,"name":"3 - 2"},{"status":"ACTIVE","sortPriority":13,"id":52385898,"name":"3 - 4"},{"status":"ACTIVE","sortPriority":14,"id":52385899,"name":"3 - 5"},{"status":"ACTIVE","sortPriority":15,"id":52385900,"name":"3 - 6"},{"status":"ACTIVE","sortPriority":16,"id":52385903,"name":"4 - 1"},{"status":"ACTIVE","sortPriority":17,"id":52385904,"name":"4 - 2"},{"status":"ACTIVE","sortPriority":18,"id":52385905,"name":"4 - 3"},{"status":"ACTIVE","sortPriority":19,"id":52385906,"name":"4 - 5"},{"status":"ACTIVE","sortPriority":20,"id":52385907,"name":"4 - 6"},{"status":"ACTIVE","sortPriority":21,"id":52385910,"name":"5 - 1"},{"status":"ACTIVE","sortPriority":22,"id":52385911,"name":"5 - 2"},{"status":"ACTIVE","sortPriority":23,"id":52385912,"name":"5 - 3"},{"status":"ACTIVE","sortPriority":24,"id":52385913,"name":"5 - 4"},{"status":"ACTIVE","sortPriority":25,"id":52385914,"name":"5 - 6"},{"status":"ACTIVE","sortPriority":26,"id":52385917,"name":"6 - 1"},{"status":"ACTIVE","sortPriority":27,"id":52385918,"name":"6 - 2"},{"status":"ACTIVE","sortPriority":28,"id":52385919,"name":"6 - 3"},{"status":"ACTIVE","sortPriority":29,"id":52385920,"name":"6 - 4"},{"status":"ACTIVE","sortPriority":30,"id":52385921,"name":"6 - 5"}],"regulators":["MR_INT"],"venue":"Perry Barr","countryCode":"GB","discountAllowed":true,"timezone":"Europe/London","openDate":"2024-06-27T13:29:00.000Z","version":5994794102,"name":"Forecast","eventName":"Perry Barr (F/C) 27th Jun"},"rc":[{"atb":[[1.16,100],[1.02,9.29]],"id":52385910},{"atb":[[1.16,100],[1.03,6.19]],"id":52385912},{"atb":[[1.16,100],[1.03,6.19]],"id":52385906},{"atb":[[1.01,18.59],[1.16,100]],"id":52385918},{"atb":[[1.01,18.59],[1.16,100]],"id":52385920},{"atb":[[1.16,100],[1.03,6.19]],"id":52385889},{"atb":[[1.01,18.59],[1.16,100]],"id":52385914},{"atb":[[1.01,18.59],[1.16,100]],"id":52385883},{"atb":[[1.16,100],[1.02,9.29]],"id":52385885},{"atb":[[1.16,100],[1.02,9.29]],"id":52385896},{"atb":[[1.16,100],[1.03,6.19]],"id":52385890},{"atb":[[1.16,100],[1.02,9.29]],"id":52385892},{"atb":[[1.01,18.59],[1.16,100]],"id":52385904},{"atb":[[1.01,18.59],[1.16,100]],"id":52385898},{"atb":[[1.16,100],[1.03,6.19]],"id":52385900},{"atb":[[1.16,100],[1.03,6.19]],"id":52385911},{"atb":[[1.01,18.59],[1.16,100]],"id":52385913},{"atb":[[1.01,18.59],[1.16,100]],"id":52385907},{"atb":[[1.01,18.59],[1.16,100]],"id":52385886},{"atb":[[1.16,100],[1.03,6.19]],"id":52385919},{"atb":[[1.16,100],[1.03,6.19]],"id":52385921},{"atb":[[1.16,100],[1.03,6.19]],"id":52385882},{"atb":[[1.16,100],[1.03,6.19]],"id":52385884},{"atb":[[1.16,100],[1.03,6.19]],"id":52385917},{"atb":[[1.01,18.59],[1.16,100]],"id":52385897},{"atb":[[1.16,100],[1.03,6.19]],"id":52385891},{"atb":[[1.16,100],[1.02,9.29]],"id":52385893},{"atb":[[1.16,100],[1.03,6.19]],"id":52385903},{"atb":[[1.16,100],[1.03,6.19]],"id":52385905},{"atb":[[1.01,18.59],[1.16,100]],"id":52385899}],"con":true,"img":true}]}
{"op":"mcm","clk":"11549585446","pt":1719488032228,"mc":[{"id":"1.230178169","rc":[{"atb":[[1.02,9.29]],"id":52385910},{"atb":[[1.03,6.2]],"id":52385912},{"atb":[[1.03,6.2]],"id":52385906},{"atb":[[1.01,18.6]],"id":52385918},{"atb":[[1.01,18.6]],"id":52385920},{"atb":[[1.03,6.2]],"id":52385889},{"atb":[[1.01,18.6]],"id":52385914},{"atb":[[1.01,18.6]],"id":52385883},{"atb":[[1.02,9.29]],"id":52385885},{"atb":[[1.02,9.29]],"id":52385896},{"atb":[[1.03,6.2]],"id":52385890},{"atb":[[1.02,9.29]],"id":52385892},{"atb":[[1.01,18.6]],"id":52385904},{"atb":[[1.01,18.6]],"id":52385898},{"atb":[[1.03,6.2]],"id":52385900},{"atb":[[1.03,6.2]],"id":52385911},{"atb":[[1.01,18.6]],"id":52385913},{"atb":[[1.01,18.6]],"id":52385907},{"atb":[[1.01,18.6]],"id":52385886},{"atb":[[1.03,6.2]],"id":52385919},{"atb":[[1.03,6.2]],"id":52385921},{"atb":[[1.01,306.12],[1.03,6.2]],"id":52385882},{"atb":[[1.03,6.2]],"id":52385884},{"atb":[[1.03,6.2]],"id":52385917},{"atb":[[1.01,18.6]],"id":52385897},{"atb":[[1.03,6.2]],"id":52385891},{"atb":[[1.02,9.29]],"id":52385893},{"atb":[[1.03,6.2]],"id":52385903},{"atb":[[1.03,6.2]],"id":52385905},{"atb":[[1.01,18.6]],"id":52385899}],"con":true,"img":false}]}
{"op":"mcm","clk":"11549585472","pt":1719488032540,"mc":[{"id":"1.230178169","rc":[{"atb":[[1.01,324.72]],"id":52385883},{"atb":[[1.01,306.12]],"id":52385884}],"con":true,"img":false}]}
{"op":"mcm","clk":"11549585488","pt":1719488032701,"mc":[{"id":"1.230178169","rc":[{"atb":[[1.01,306.12]],"id":52385885},{"atb":[[1.01,324.72]],"id":52385886}],"con":true,"img":false}]}
{"op":"mcm","clk":"11549585502","pt":1719488032909,"mc":[{"id":"1.230178169","rc":[{"atb":[[1.01,306.12]],"id":52385889},{"atb":[[1.01,306.12]],"id":52385890},{"atb":[[1.01,306.12]],"id":52385891}],"con":true,"img":false}]}
{"op":"mcm","clk":"11549585517","pt":1719488033113,"mc":[{"id":"1.230178169","rc":[{"atb":[[1.01,306.12]],"id":52385892},{"atb":[[1.01,306.12]],"id":52385893}],"con":true,"img":false}]}
{"op":"mcm","clk":"11549585529","pt":1719488033226,"mc":[{"id":"1.230178169","rc":[{"atb":[[1.01,306.12]],"id":52385896}],"con":true,"img":false}]}
{"op":"mcm","clk":"11549585536","pt":1719488033320,"mc":[{"id":"1.230178169","rc":[{"atb":[[1.01,324.72]],"id":52385898},{"atb":[[1.01,324.72]],"id":52385897}],"con":true,"img":false}]}
{"op":"mcm","clk":"11549585544","pt":1719488033425,"mc":[{"id":"1.230178169","rc":[{"atb":[[1.01,324.72]],"id":52385899}],"con":true,"img":false}]}
{"op":"mcm","clk":"11549585557","pt":1719488033530,"mc":[{"id":"1.230178169","rc":[{"atb":[[1.01,306.12]],"id":52385900},{"atb":[[1.01,306.12]],"id":52385903}],"con":true,"img":false}]}
{"op":"mcm","clk":"11549585563","pt":1719488033632,"mc":[{"id":"1.230178169","rc":[{"atb":[[1.01,324.72]],"id":52385904}],"con":true,"img":false}]}
{"op":"mcm","clk":"11549585570","pt":1719488033736,"mc":[{"id":"1.230178169","rc":[{"atb":[[1.01,306.12]],"id":52385905}],"con":true,"img":false}]}
{"op":"mcm","clk":"11549585577","pt":1719488033797,"mc":[{"id":"1.230178169","rc":[{"atb":[[1.01,306.12]],"id":52385906}],"con":true,"img":false}]}
{"op":"mcm","clk":"11549585587","pt":1719488033896,"mc":[{"id":"1.230178169","rc":[{"atb":[[1.01,306.12]],"id":52385910},{"atb":[[1.01,306.12]],"id":52385911},{"atb":[[1.01,324.72]],"id":52385907}],"con":true,"img":false}]}
{"op":"mcm","clk":"11549585603","pt":1719488034206,"mc":[{"id":"1.230178169","rc":[{"atb":[[1.01,306.12]],"id":52385912}],"con":true,"img":false}]}
{"op":"mcm","clk":"11549585611","pt":1719488034311,"mc":[{"id":"1.230178169","rc":[{"atb":[[1.01,324.72]],"id":52385913}],"con":true,"img":false}]}
{"op":"mcm","clk":"11549585620","pt":1719488034414,"mc":[{"id":"1.230178169","rc":[{"atb":[[1.01,324.72]],"id":52385914}],"con":true,"img":false}]}
{"op":"mcm","clk":"11549585633","pt":1719488034621,"mc":[{"id":"1.230178169","rc":[{"atb":[[1.01,324.72]],"id":52385918},{"atb":[[1.01,306.12]],"id":52385917}],"con":true,"img":false}]}
{"op":"mcm","clk":"11549585651","pt":1719488034829,"mc":[{"id":"1.230178169","rc":[{"atb":[[1.01,324.72]],"id":52385920},{"atb":[[1.01,306.12]],"id":52385919}],"con":true,"img":false}]}
{"op":"mcm","clk":"11549585670","pt":1719488035038,"mc":[{"id":"1.230178169","rc":[{"atb":[[1.01,306.12]],"id":52385921}],"con":true,"img":false}]}
{"op":"mcm","clk":"11549585687","pt":1719488035200,"mc":[{"id":"1.230178169","rc":[{"atb":[[1.17,120.05]],"id":52385883},{"atb":[[1.17,120.05]],"id":52385882}],"con":true,"img":false}]}
{"op":"mcm","clk":"11549585694","pt":1719488035307,"mc":[{"id":"1.230178169","rc":[{"atb":[[1.17,120.05]],"id":52385884}],"con":true,"img":false}]}
{"op":"mcm","clk":"11549585700","pt":1719488035412,"mc":[{"id":"1.230178169","rc":[{"atb":[[1.17,120.05]],"id":52385885}],"con":true,"img":false}]}
{"op":"mcm","clk":"11549585708","pt":1719488035510,"mc":[{"id":"1.230178169","rc":[{"atb":[[1.17,120.05]],"id":52385889},{"atb":[[1.17,120.05]],"id":52385886}],"con":true,"img":false}]}
{"op":"mcm","clk":"11549585715","pt":1719488035620,"mc":[{"id":"1.230178169","rc":[{"atb":[[1.17,120.05]],"id":52385890}],"con":true,"img":false}]}
{"op":"mcm","clk":"11549585721","pt":1719488035715,"mc":[{"id":"1.230178169","rc":[{"atb":[[1.17,120.05]],"id":52385891}],"con":true,"img":false}]}
{"op":"mcm","clk":"11549585729","pt":1719488035822,"mc":[{"id":"1.230178169","rc":[{"atb":[[1.17,120.05]],"id":52385892},{"atb":[[1.17,120.05]],"id":52385893}],"con":true,"img":false}]}
{"op":"mcm","clk":"11549585739","pt":1719488035925,"mc":[{"id":"1.230178169","rc":[{"atb":[[1.17,120.05]],"id":52385896}],"con":true,"img":false}]}
{"op":"mcm","clk":"11549585744","pt":1719488036026,"mc":[{"id":"1.230178169","rc":[{"atb":[[1.17,120.05]],"id":52385898},{"atb":[[1.17,120.05]],"id":52385897}],"con":true,"img":false}]}
{"op":"mcm","clk":"11549585754","pt":1719488036132,"mc":[{"id":"1.230178169","rc":[{"atb":[[1.17,120.05]],"id":52385899}],"con":true,"img":false}]}
{"op":"mcm","clk":"11549585759","pt":1719488036234,"mc":[{"id":"1.230178169","rc":[{"atb":[[1.17,120.05]],"id":52385900}],"con":true,"img":false}]}
{"op":"mcm","clk":"11549585764","pt":1719488036338,"mc":[{"id":"1.230178169","rc":[{"atb":[[1.17,120.05]],"id":52385904},{"atb":[[1.17,120.05]],"id":52385903}],"con":true,"img":false}]}
{"op":"mcm","clk":"11549585776","pt":1719488036547,"mc":[{"id":"1.230178169","rc":[{"atb":[[1.17,120.05]],"id":52385906},{"atb":[[1.17,120.05]],"id":52385907},{"atb":[[1.17,120.05]],"id":52385905}],"con":true,"img":false}]}
{"op":"mcm","clk":"11549585783","pt":1719488036709,"mc":[{"id":"1.230178169","rc":[{"atb":[[1.17,120.05]],"id":52385910}],"con":true,"img":false}]}
{"op":"mcm","clk":"11549585787","pt":1719488036811,"mc":[{"id":"1.230178169","rc":[{"atb":[[1.17,120.05]],"id":52385911}],"con":true,"img":false}]}
{"op":"mcm","clk":"11549585794","pt":1719488036915,"mc":[{"id":"1.230178169","rc":[{"atb":[[1.17,120.05]],"id":52385912}],"con":true,"img":false}]}
{"op":"mcm","clk":"11549585811","pt":1719488037117,"mc":[{"id":"1.230178169","rc":[{"atb":[[1.17,120.05]],"id":52385914},{"atb":[[1.17,120.05]],"id":52385913}],"con":true,"img":false}]}
{"op":"mcm","clk":"11549585824","pt":1719488037323,"mc":[{"id":"1.230178169","rc":[{"atb":[[1.17,120.05]],"id":52385917}],"con":true,"img":false}]}
{"op":"mcm","clk":"11549585831","pt":1719488037426,"mc":[{"id":"1.230178169","rc":[{"atb":[[1.17,120.05]],"id":52385918}],"con":true,"img":false}]}
{"op":"mcm","clk":"11549585838","pt":1719488037534,"mc":[{"id":"1.230178169","rc":[{"atb":[[1.17,120.05]],"id":52385919}],"con":true,"img":false}]}
{"op":"mcm","clk":"11549585845","pt":1719488037637,"mc":[{"id":"1.230178169","rc":[{"atb":[[1.17,120.05]],"id":52385920},{"atb":[[1.17,120.05]],"id":52385921}],"con":true,"img":false}]}
{"op":"mcm","clk":"11549970589","pt":1719493209957,"mc":[{"id":"1.230178169","rc":[{"atb":[[1.16,0],[1.02,9.3]],"id":52385910},{"atb":[[1.16,0],[1.03,6.2]],"id":52385912},{"atb":[[1.16,0],[1.03,6.2]],"id":52385906},{"atb":[[1.01,324.74],[1.16,0]],"id":52385918},{"atb":[[1.01,324.74],[1.16,0]],"id":52385920},{"atb":[[1.16,0],[1.03,6.2]],"id":52385889},{"atb":[[1.01,324.74],[1.16,0]],"id":52385914},{"atb":[[1.01,324.74],[1.16,0]],"id":52385883},{"atb":[[1.16,0],[1.02,9.3]],"id":52385885},{"atb":[[1.16,0],[1.02,9.3]],"id":52385896},{"atb":[[1.16,0],[1.03,6.2]],"id":52385890},{"atb":[[1.16,0],[1.02,9.3]],"id":52385892},{"atb":[[1.01,324.74],[1.16,0]],"id":52385904},{"atb":[[1.01,324.74],[1.16,0]],"id":52385898},{"atb":[[1.16,0],[1.03,6.2]],"id":52385900},{"atb":[[1.16,0],[1.03,6.2]],"id":52385911},{"atb":[[1.01,324.74],[1.16,0]],"id":52385913},{"atb":[[1.01,324.74],[1.16,0]],"id":52385907},{"atb":[[1.01,324.74],[1.16,0]],"id":52385886},{"atb":[[1.16,0],[1.03,6.2]],"id":52385919},{"atb":[[1.16,0],[1.03,6.2]],"id":52385921},{"atb":[[1.16,0],[1.03,6.2]],"id":52385882},{"atb":[[1.16,0],[1.03,6.2]],"id":52385884},{"atb":[[1.16,0],[1.03,6.2]],"id":52385917},{"atb":[[1.01,324.74],[1.16,0]],"id":52385897},{"atb":[[1.16,0],[1.03,6.2]],"id":52385891},{"atb":[[1.16,0],[1.02,9.3]],"id":52385893},{"atb":[[1.16,0],[1.03,6.2]],"id":52385903},{"atb":[[1.16,0],[1.03,6.2]],"id":52385905},{"atb":[[1.01,324.74],[1.16,0]],"id":52385899}],"con":true,"img":false}]}
{"op":"mcm","clk":"11549975532","pt":1719493270641,"mc":[{"id":"1.230178169","rc":[{"atb":[[1.18,150]],"id":52385910},{"atb":[[1.18,150]],"id":52385912},{"atb":[[1.18,150]],"id":52385906},{"atb":[[1.18,150]],"id":52385918},{"atb":[[1.18,150]],"id":52385920},{"atb":[[1.18,150]],"id":52385889},{"atb":[[1.18,150]],"id":52385914},{"atb":[[1.18,150]],"id":52385883},{"atb":[[1.18,150]],"id":52385885},{"atb":[[1.18,150]],"id":52385896},{"atb":[[1.18,150]],"id":52385890},{"atb":[[1.18,150]],"id":52385892},{"atb":[[1.18,150]],"id":52385904},{"atb":[[1.18,150]],"id":52385898},{"atb":[[1.18,150]],"id":52385900},{"atb":[[1.18,150]],"id":52385911},{"atb":[[1.18,150]],"id":52385913},{"atb":[[1.18,150]],"id":52385907},{"atb":[[1.18,150]],"id":52385886},{"atb":[[1.18,150]],"id":52385919},{"atb":[[1.18,150]],"id":52385921},{"atb":[[1.18,150]],"id":52385882},{"atb":[[1.18,150]],"id":52385884},{"atb":[[1.18,150]],"id":52385917},{"atb":[[1.18,150]],"id":52385897},{"atb":[[1.18,150]],"id":52385891},{"atb":[[1.18,150]],"id":52385893},{"atb":[[1.18,150]],"id":52385903},{"atb":[[1.18,150]],"id":52385905},{"atb":[[1.18,150]],"id":52385899}],"con":true,"img":false}]}
{"op":"mcm","clk":"11549990110","pt":1719493440961,"mc":[{"id":"1.230178169","rc":[{"atb":[[1.17,0]],"id":52385882}],"con":true,"img":false}]}
{"op":"mcm","clk":"11550040820","pt":1719493881131,"mc":[{"id":"1.230178169","rc":[{"atb":[[1.17,0]],"id":52385883}],"con":true,"img":false}]}
{"op":"mcm","clk":"11550064318","pt":1719494111111,"mc":[{"id":"1.230178169","rc":[{"atb":[[1.17,0]],"id":52385884}],"con":true,"img":false}]}
{"op":"mcm","clk":"11550089714","pt":1719494351245,"mc":[{"id":"1.230178169","rc":[{"atb":[[1.17,0]],"id":52385885}],"con":true,"img":false}]}
{"op":"mcm","clk":"11550115334","pt":1719494581380,"mc":[{"id":"1.230178169","rc":[{"atb":[[1.17,0]],"id":52385886}],"con":true,"img":false}]}
{"op":"mcm","clk":"11550139793","pt":1719494811457,"mc":[{"id":"1.230178169","rc":[{"atb":[[1.17,0]],"id":52385889}],"con":true,"img":false}]}
{"op":"mcm","clk":"11550160517","pt":1719495041542,"mc":[{"id":"1.230178169","rc":[{"atb":[[1.17,0]],"id":52385890}],"con":true,"img":false}]}
{"op":"mcm","clk":"11550178125","pt":1719495271742,"mc":[{"id":"1.230178169","rc":[{"atb":[[1.17,0]],"id":52385891}],"con":true,"img":false}]}
{"op":"mcm","clk":"11550197187","pt":1719495501851,"mc":[{"id":"1.230178169","rc":[{"atb":[[1.17,0]],"id":52385892}],"con":true,"img":false}]}
{"op":"mcm","clk":"11550217412","pt":1719495731949,"mc":[{"id":"1.230178169","rc":[{"atb":[[1.17,0]],"id":52385893}],"con":true,"img":false}]}
{"op":"mcm","clk":"11550239922","pt":1719495982026,"mc":[{"id":"1.230178169","rc":[{"atb":[[1.17,0]],"id":52385896}],"con":true,"img":false}]}
{"op":"mcm","clk":"11550258370","pt":1719496212085,"mc":[{"id":"1.230178169","rc":[{"atb":[[1.17,0]],"id":52385897}],"con":true,"img":false}]}
{"op":"mcm","clk":"11550273608","pt":1719496451091,"mc":[{"id":"1.230178169","rc":[{"atb":[[1.3,30]],"id":52385898}],"con":true,"img":false}]}
{"op":"mcm","clk":"11550273668","pt":1719496452176,"mc":[{"id":"1.230178169","rc":[{"atb":[[1.17,0]],"id":52385898}],"con":true,"img":false}]}
{"op":"mcm","clk":"11550273675","pt":1719496452285,"mc":[{"id":"1.230178169","rc":[{"atb":[[1.31,65.83]],"id":52385898}],"con":true,"img":false}]}
{"op":"mcm","clk":"11550273760","pt":1719496453609,"mc":[{"id":"1.230178169","rc":[{"atb":[[3.5,50]],"id":52385898}],"con":true,"img":false}]}
{"op":"mcm","clk":"11550274067","pt":1719496458911,"mc":[{"id":"1.230178169","rc":[{"atb":[[3.5,0]],"id":52385898}],"con":true,"img":false}]}
{"op":"mcm","clk":"11550275303","pt":1719496478628,"mc":[{"id":"1.230178169","rc":[{"atb":[[1.3,0]],"id":52385898}],"con":true,"img":false}]}
{"op":"mcm","clk":"11550275314","pt":1719496478734,"mc":[{"id":"1.230178169","rc":[{"atb":[[1.33,30]],"id":52385898}],"con":true,"img":false}]}
{"op":"mcm","clk":"11550275539","pt":1719496482319,"mc":[{"id":"1.230178169","marketDefinition":{"bspMarket":false,"turnInPlayEnabled":false,"persistenceEnabled":false,"marketBaseRate":5.0,"eventId":"33376048","eventTypeId":"4339","numberOfWinners":1,"bettingType":"ODDS","marketType":"FORECAST","marketTime":"2024-06-27T14:26:00.000Z","suspendTime":"2024-06-27T14:26:00.000Z","bspReconciled":false,"complete":true,"inPlay":false,"crossMatching":true,"runnersVoidable":false,"numberOfActiveRunners":30,"betDelay":0,"status":"OPEN","runners":[{"status":"ACTIVE","sortPriority":1,"id":52385882,"name":"1 - 2"},{"status":"ACTIVE","sortPriority":2,"id":52385883,"name":"1 - 3"},{"status":"ACTIVE","sortPriority":3,"id":52385884,"name":"1 - 4"},{"status":"ACTIVE","sortPriority":4,"id":52385885,"name":"1 - 5"},{"status":"ACTIVE","sortPriority":5,"id":52385886,"name":"1 - 6"},{"status":"ACTIVE","sortPriority":6,"id":52385889,"name":"2 - 1"},{"status":"ACTIVE","sortPriority":7,"id":52385890,"name":"2 - 3"},{"status":"ACTIVE","sortPriority":8,"id":52385891,"name":"2 - 4"},{"status":"ACTIVE","sortPriority":9,"id":52385892,"name":"2 - 5"},{"status":"ACTIVE","sortPriority":10,"id":52385893,"name":"2 - 6"},{"status":"ACTIVE","sortPriority":11,"id":52385896,"name":"3 - 1"},{"status":"ACTIVE","sortPriority":12,"id":52385897,"name":"3 - 2"},{"status":"ACTIVE","sortPriority":13,"id":52385898,"name":"3 - 4"},{"status":"ACTIVE","sortPriority":14,"id":52385899,"name":"3 - 5"},{"status":"ACTIVE","sortPriority":15,"id":52385900,"name":"3 - 6"},{"status":"ACTIVE","sortPriority":16,"id":52385903,"name":"4 - 1"},{"status":"ACTIVE","sortPriority":17,"id":52385904,"name":"4 - 2"},{"status":"ACTIVE","sortPriority":18,"id":52385905,"name":"4 - 3"},{"status":"ACTIVE","sortPriority":19,"id":52385906,"name":"4 - 5"},{"status":"ACTIVE","sortPriority":20,"id":52385907,"name":"4 - 6"},{"status":"ACTIVE","sortPriority":21,"id":52385910,"name":"5 - 1"},{"status":"ACTIVE","sortPriority":22,"id":52385911,"name":"5 - 2"},{"status":"ACTIVE","sortPriority":23,"id":52385912,"name":"5 - 3"},{"status":"ACTIVE","sortPriority":24,"id":52385913,"name":"5 - 4"},{"status":"ACTIVE","sortPriority":25,"id":52385914,"name":"5 - 6"},{"status":"ACTIVE","sortPriority":26,"id":52385917,"name":"6 - 1"},{"status":"ACTIVE","sortPriority":27,"id":52385918,"name":"6 - 2"},{"status":"ACTIVE","sortPriority":28,"id":52385919,"name":"6 - 3"},{"status":"ACTIVE","sortPriority":29,"id":52385920,"name":"6 - 4"},{"status":"ACTIVE","sortPriority":30,"id":52385921,"name":"6 - 5"}],"regulators":["MR_INT"],"venue":"Perry Barr","countryCode":"GB","discountAllowed":true,"timezone":"Europe/London","openDate":"2024-06-27T13:29:00.000Z","version":5994794102,"name":"Forecast","eventName":"Perry Barr (F/C) 27th Jun"},"rc":[],"con":true,"img":false}]}
{"op":"mcm","clk":"11550275745","pt":1719496485843,"mc":[{"id":"1.230178169","rc":[{"atb":[[1.41,44]],"id":52385898}],"con":true,"img":false}]}
{"op":"mcm","clk":"11550276795","pt":1719496501860,"mc":[{"id":"1.230178169","rc":[{"atb":[[1.03,1]],"id":52385910},{"atb":[[1.03,7.2]],"id":52385912},{"atb":[[1.03,7.2]],"id":52385906},{"atb":[[1.03,1]],"id":52385918},{"atb":[[1.03,1]],"id":52385920},{"atb":[[1.03,7.2]],"id":52385889},{"atb":[[1.03,1]],"id":52385914},{"atb":[[1.03,1]],"id":52385883},{"atb":[[1.03,1]],"id":52385885},{"atb":[[1.03,1]],"id":52385896},{"atb":[[1.03,7.2]],"id":52385890},{"atb":[[1.03,1]],"id":52385892},{"atb":[[1.03,1]],"id":52385904},{"atb":[[1.03,1]],"id":52385898},{"atb":[[1.03,7.2]],"id":52385900},{"atb":[[1.03,7.2]],"id":52385911},{"atb":[[1.03,1]],"id":52385913},{"atb":[[1.03,1]],"id":52385907},{"atb":[[1.03,1]],"id":52385886},{"atb":[[1.03,7.2]],"id":52385919},{"atb":[[1.03,7.2]],"id":52385921},{"atb":[[1.03,7.2]],"id":52385882},{"atb":[[1.03,7.2]],"id":52385884},{"atb":[[1.03,7.2]],"id":52385917},{"atb":[[1.03,1]],"id":52385897},{"atb":[[1.03,7.2]],"id":52385891},{"atb":[[1.03,1]],"id":52385893},{"atb":[[1.03,7.2]],"id":52385903},{"atb":[[1.03,7.2]],"id":52385905},{"atb":[[1.03,1]],"id":52385899}],"con":true,"img":false}]}
{"op":"mcm","clk":"11550276812","pt":1719496502068,"mc":[{"id":"1.230178169","rc":[{"atb":[[1.03,0.9]],"id":52385910},{"atb":[[1.03,7.1]],"id":52385912},{"atb":[[1.03,7.1]],"id":52385906},{"atb":[[1.03,0.9]],"id":52385918},{"atb":[[1.03,0.9]],"id":52385920},{"atb":[[1.03,7.1]],"id":52385889},{"atb":[[1.03,0.9]],"id":52385914},{"atb":[[1.03,0.9]],"id":52385883},{"atb":[[1.03,0.9]],"id":52385885},{"atb":[[1.03,0.9]],"id":52385896},{"atb":[[1.03,7.1]],"id":52385890},{"atb":[[1.03,0.9]],"id":52385892},{"atb":[[1.03,0.9]],"id":52385904},{"atb":[[1.03,0.9]],"id":52385898},{"atb":[[1.03,7.1]],"id":52385900},{"atb":[[1.03,7.1]],"id":52385911},{"atb":[[1.03,0.9]],"id":52385913},{"atb":[[1.03,0.9]],"id":52385907},{"atb":[[1.03,0.9]],"id":52385886},{"atb":[[1.03,7.1]],"id":52385919},{"atb":[[1.03,7.1]],"id":52385921},{"atb":[[1.03,7.1]],"id":52385882},{"atb":[[1.03,7.1]],"id":52385884},{"atb":[[1.03,7.1]],"id":52385917},{"atb":[[1.03,0.9]],"id":52385897},{"atb":[[1.03,7.1]],"id":52385891},{"atb":[[1.03,0.9]],"id":52385893},{"atb":[[1.03,7.1]],"id":52385903},{"atb":[[1.03,7.1]],"id":52385905},{"atb":[[1.03,0.9]],"id":52385899}],"con":true,"img":false}]}
{"op":"mcm","clk":"11550276826","pt":1719496502267,"mc":[{"id":"1.230178169","rc":[{"atb":[[1.03,0]],"id":52385910},{"atb":[[1.03,6.2]],"id":52385912},{"atb":[[1.03,6.2]],"id":52385906},{"atb":[[1.03,0]],"id":52385918},{"atb":[[1.03,0]],"id":52385920},{"atb":[[1.03,6.2]],"id":52385889},{"atb":[[1.03,0]],"id":52385914},{"atb":[[1.03,0]],"id":52385883},{"atb":[[1.03,0]],"id":52385885},{"atb":[[1.03,0]],"id":52385896},{"atb":[[1.03,6.2]],"id":52385890},{"atb":[[1.03,0]],"id":52385892},{"atb":[[1.03,0]],"id":52385904},{"atb":[[1.03,0]],"id":52385898},{"atb":[[1.03,6.2]],"id":52385900},{"atb":[[1.03,6.2]],"id":52385911},{"atb":[[1.03,0]],"id":52385913},{"atb":[[1.03,0]],"id":52385907},{"atb":[[1.03,0]],"id":52385886},{"atb":[[1.03,6.2]],"id":52385919},{"atb":[[1.03,6.2]],"id":52385921},{"atb":[[1.03,6.2]],"id":52385882},{"atb":[[1.03,6.2]],"id":52385884},{"atb":[[1.03,6.2]],"id":52385917},{"atb":[[1.03,0]],"id":52385897},{"atb":[[1.03,6.2]],"id":52385891},{"atb":[[1.03,0]],"id":52385893},{"atb":[[1.03,6.2]],"id":52385903},{"atb":[[1.03,6.2]],"id":52385905},{"atb":[[1.03,0]],"id":52385899}],"con":true,"img":false}]}
{"op":"mcm","clk":"11550276835","pt":1719496502335,"mc":[{"id":"1.230178169","rc":[{"atb":[[3.05,0.9]],"id":52385910},{"atb":[[3.05,0.9]],"id":52385912},{"atb":[[3.05,0.9]],"id":52385906},{"atb":[[3.05,0.9]],"id":52385918},{"atb":[[3.05,0.9]],"id":52385920},{"atb":[[3.05,0.9]],"id":52385889},{"atb":[[3.05,0.9]],"id":52385914},{"atb":[[3.05,0.9]],"id":52385883},{"atb":[[3.05,0.9]],"id":52385885},{"atb":[[3.05,0.9]],"id":52385896},{"atb":[[3.05,0.9]],"id":52385890},{"atb":[[3.05,0.9]],"id":52385892},{"atb":[[3.05,0.9]],"id":52385904},{"atb":[[3.05,0.9]],"id":52385898},{"atb":[[3.05,0.9]],"id":52385900},{"atb":[[3.05,0.9]],"id":52385911},{"atb":[[3.05,0.9]],"id":52385913},{"atb":[[3.05,0.9]],"id":52385907},{"atb":[[3.05,0.9]],"id":52385886},{"atb":[[3.05,0.9]],"id":52385919},{"atb":[[3.05,0.9]],"id":52385921},{"atb":[[3.05,0.9]],"id":52385882},{"atb":[[3.05,0.9]],"id":52385884},{"atb":[[3.05,0.9]],"id":52385917},{"atb":[[3.05,0.9]],"id":52385897},{"atb":[[3.05,0.9]],"id":52385891},{"atb":[[3.05,0.9]],"id":52385893},{"atb":[[3.05,0.9]],"id":52385903},{"atb":[[3.05,0.9]],"id":52385905},{"atb":[[3.05,0.9]],"id":52385899}],"con":true,"img":false}]}
{"op":"mcm","clk":"11550277155","pt":1719496506363,"mc":[{"id":"1.230178169","rc":[{"atb":[[1.41,0]],"id":52385898}],"con":true,"img":false}]}
{"op":"mcm","clk":"11550279032","pt":1719496537478,"mc":[{"id":"1.230178169","rc":[{"atb":[[1.33,0.9],[3.05,0]],"id":52385898},{"trd":[[1.33,58.2],[3.05,1.8]],"ltp":1.33,"tv":60.0,"id":52385898}],"con":true,"img":false}]}
{"op":"mcm","clk":"11550279522","pt":1719496545614,"mc":[{"id":"1.230178169","rc":[{"atb":[[3.05,0]],"id":52385910},{"atb":[[3.05,0]],"id":52385912},{"atb":[[3.05,0]],"id":52385906},{"atb":[[3.05,0]],"id":52385918},{"atb":[[3.05,0]],"id":52385920},{"atb":[[3.05,0]],"id":52385889},{"atb":[[3.05,0]],"id":52385914},{"atb":[[3.05,0]],"id":52385883},{"atb":[[3.05,0]],"id":52385885},{"atb":[[3.05,0]],"id":52385896},{"atb":[[3.05,0]],"id":52385890},{"atb":[[3.05,0]],"id":52385892},{"atb":[[3.05,0]],"id":52385904},{"atb":[[3.05,0]],"id":52385900},{"atb":[[3.05,0]],"id":52385911},{"atb":[[3.05,0]],"id":52385913},{"atb":[[3.05,0]],"id":52385907},{"atb":[[3.05,0]],"id":52385886},{"atb":[[3.05,0]],"id":52385919},{"atb":[[3.05,0]],"id":52385921},{"atb":[[3.05,0]],"id":52385882},{"atb":[[3.05,0]],"id":52385884},{"atb":[[3.05,0]],"id":52385917},{"atb":[[3.05,0]],"id":52385897},{"atb":[[3.05,0]],"id":52385891},{"atb":[[3.05,0]],"id":52385893},{"atb":[[3.05,0]],"id":52385903},{"atb":[[3.05,0]],"id":52385905},{"atb":[[3.05,0]],"id":52385899}],"con":true,"img":false}]}
{"op":"mcm","clk":"11550279625","pt":1719496547682,"mc":[{"id":"1.230178169","rc":[{"atb":[[1.03,1]],"id":52385910},{"atb":[[1.03,7.2]],"id":52385912},{"atb":[[1.03,7.2]],"id":52385906},{"atb":[[1.03,1]],"id":52385918},{"atb":[[1.03,1]],"id":52385920},{"atb":[[1.03,7.2]],"id":52385889},{"atb":[[1.03,1]],"id":52385914},{"atb":[[1.03,1]],"id":52385883},{"atb":[[1.03,1]],"id":52385885},{"atb":[[1.03,1]],"id":52385896},{"atb":[[1.03,7.2]],"id":52385890},{"atb":[[1.03,1]],"id":52385892},{"atb":[[1.03,1]],"id":52385904},{"atb":[[1.03,1]],"id":52385898},{"atb":[[1.03,7.2]],"id":52385900},{"atb":[[1.03,7.2]],"id":52385911},{"atb":[[1.03,1]],"id":52385913},{"atb":[[1.03,1]],"id":52385907},{"atb":[[1.03,1]],"id":52385886},{"atb":[[1.03,7.2]],"id":52385919},{"atb":[[1.03,7.2]],"id":52385921},{"atb":[[1.03,7.2]],"id":52385882},{"atb":[[1.03,7.2]],"id":52385884},{"atb":[[1.03,7.2]],"id":52385917},{"atb":[[1.03,1]],"id":52385897},{"atb":[[1.03,7.2]],"id":52385891},{"atb":[[1.03,1]],"id":52385893},{"atb":[[1.03,7.2]],"id":52385903},{"atb":[[1.03,7.2]],"id":52385905},{"atb":[[1.03,1]],"id":52385899}],"con":true,"img":false}]}
{"op":"mcm","clk":"11550279632","pt":1719496547897,"mc":[{"id":"1.230178169","rc":[{"atb":[[1.03,0.9]],"id":52385910},{"atb":[[1.03,7.1]],"id":52385912},{"atb":[[1.03,7.1]],"id":52385906},{"atb":[[1.03,0.9]],"id":52385918},{"atb":[[1.03,0.9]],"id":52385920},{"atb":[[1.03,7.1]],"id":52385889},{"atb":[[1.03,0.9]],"id":52385914},{"atb":[[1.03,0.9]],"id":52385883},{"atb":[[1.03,0.9]],"id":52385885},{"atb":[[1.03,0.9]],"id":52385896},{"atb":[[1.03,7.1]],"id":52385890},{"atb":[[1.03,0.9]],"id":52385892},{"atb":[[1.03,0.9]],"id":52385904},{"atb":[[1.03,0.9]],"id":52385898},{"atb":[[1.03,7.1]],"id":52385900},{"atb":[[1.03,7.1]],"id":52385911},{"atb":[[1.03,0.9]],"id":52385913},{"atb":[[1.03,0.9]],"id":52385907},{"atb":[[1.03,0.9]],"id":52385886},{"atb":[[1.03,7.1]],"id":52385919},{"atb":[[1.03,7.1]],"id":52385921},{"atb":[[1.03,7.1]],"id":52385882},{"atb":[[1.03,7.1]],"id":52385884},{"atb":[[1.03,7.1]],"id":52385917},{"atb":[[1.03,0.9]],"id":52385897},{"atb":[[1.03,7.1]],"id":52385891},{"atb":[[1.03,0.9]],"id":52385893},{"atb":[[1.03,7.1]],"id":52385903},{"atb":[[1.03,7.1]],"id":52385905},{"atb":[[1.03,0.9]],"id":52385899}],"con":true,"img":false}]}
{"op":"mcm","clk":"11550279675","pt":1719496548608,"mc":[{"id":"1.230178169","rc":[{"atb":[[1.03,0]],"id":52385910},{"atb":[[1.03,6.2]],"id":52385912},{"atb":[[1.03,6.2]],"id":52385906},{"atb":[[1.03,0]],"id":52385918},{"atb":[[1.03,0]],"id":52385920},{"atb":[[1.03,6.2]],"id":52385889},{"atb":[[1.03,0]],"id":52385914},{"atb":[[1.03,0]],"id":52385883},{"atb":[[1.03,0]],"id":52385885},{"atb":[[1.03,0]],"id":52385896},{"atb":[[1.03,6.2]],"id":52385890},{"atb":[[1.03,0]],"id":52385892},{"atb":[[1.03,0]],"id":52385904},{"atb":[[1.03,0]],"id":52385898},{"atb":[[1.03,6.2]],"id":52385900},{"atb":[[1.03,6.2]],"id":52385911},{"atb":[[1.03,0]],"id":52385913},{"atb":[[1.03,0]],"id":52385907},{"atb":[[1.03,0]],"id":52385886},{"atb":[[1.03,6.2]],"id":52385919},{"atb":[[1.03,6.2]],"id":52385921},{"atb":[[1.03,6.2]],"id":52385882},{"atb":[[1.03,6.2]],"id":52385884},{"atb":[[1.03,6.2]],"id":52385917},{"atb":[[1.03,0]],"id":52385897},{"atb":[[1.03,6.2]],"id":52385891},{"atb":[[1.03,0]],"id":52385893},{"atb":[[1.03,6.2]],"id":52385903},{"atb":[[1.03,6.2]],"id":52385905},{"atb":[[1.03,0]],"id":52385899}],"con":true,"img":false}]}
{"op":"mcm","clk":"11550279683","pt":1719496548716,"mc":[{"id":"1.230178169","rc":[{"atb":[[3.05,0.9]],"id":52385910},{"atb":[[3.05,0.9]],"id":52385912},{"atb":[[3.05,0.9]],"id":52385906},{"atb":[[3.05,0.9]],"id":52385918},{"atb":[[3.05,0.9]],"id":52385920},{"atb":[[3.05,0.9]],"id":52385889},{"atb":[[3.05,0.9]],"id":52385914},{"atb":[[3.05,0.9]],"id":52385883},{"atb":[[3.05,0.9]],"id":52385885},{"atb":[[3.05,0.9]],"id":52385896},{"atb":[[3.05,0.9]],"id":52385890},{"atb":[[3.05,0.9]],"id":52385892},{"atb":[[3.05,0.9]],"id":52385904},{"atb":[[3.05,0.9]],"id":52385898},{"atb":[[3.05,0.9]],"id":52385900},{"atb":[[3.05,0.9]],"id":52385911},{"atb":[[3.05,0.9]],"id":52385913},{"atb":[[3.05,0.9]],"id":52385907},{"atb":[[3.05,0.9]],"id":52385886},{"atb":[[3.05,0.9]],"id":52385919},{"atb":[[3.05,0.9]],"id":52385921},{"atb":[[3.05,0.9]],"id":52385882},{"atb":[[3.05,0.9]],"id":52385884},{"atb":[[3.05,0.9]],"id":52385917},{"atb":[[3.05,0.9]],"id":52385897},{"atb":[[3.05,0.9]],"id":52385891},{"atb":[[3.05,0.9]],"id":52385893},{"atb":[[3.05,0.9]],"id":52385903},{"atb":[[3.05,0.9]],"id":52385905},{"atb":[[3.05,0.9]],"id":52385899}],"con":true,"img":false}]}
{"op":"mcm","clk":"11550289083","pt":1719496670674,"mc":[{"id":"1.230178169","rc":[{"atb":[[3.5,50]],"id":52385898}],"con":true,"img":false}]}
{"op":"mcm","clk":"11550289550","pt":1719496675949,"mc":[{"id":"1.230178169","rc":[{"atb":[[3.5,0]],"id":52385898}],"con":true,"img":false}]}
{"op":"mcm","clk":"11550291832","pt":1719496702367,"mc":[{"id":"1.230178169","rc":[{"atb":[[1.31,0]],"id":52385898},{"atb":[[1.17,0]],"id":52385899}],"con":true,"img":false}]}
{"op":"mcm","clk":"11550313664","pt":1719496942468,"mc":[{"id":"1.230178169","rc":[{"atb":[[1.02,9.3]],"id":52385910},{"atb":[[1.03,6.2]],"id":52385912},{"atb":[[1.03,6.2]],"id":52385906},{"atb":[[1.01,324.73]],"id":52385918},{"atb":[[1.01,324.73]],"id":52385920},{"atb":[[1.03,6.2]],"id":52385889},{"atb":[[1.01,324.73]],"id":52385914},{"atb":[[1.01,324.73]],"id":52385883},{"atb":[[1.02,9.3]],"id":52385885},{"atb":[[1.02,9.3]],"id":52385896},{"atb":[[1.03,6.2]],"id":52385890},{"atb":[[1.02,9.3]],"id":52385892},{"atb":[[1.01,324.73]],"id":52385904},{"atb":[[1.01,324.73]],"id":52385898},{"atb":[[1.03,6.2],[1.17,0]],"id":52385900},{"atb":[[1.03,6.2]],"id":52385911},{"atb":[[1.01,324.73]],"id":52385913},{"atb":[[1.01,324.73]],"id":52385907},{"atb":[[1.01,324.73]],"id":52385886},{"atb":[[1.03,6.2]],"id":52385919},{"atb":[[1.03,6.2]],"id":52385921},{"atb":[[1.03,6.2]],"id":52385882},{"atb":[[1.03,6.2]],"id":52385884},{"atb":[[1.03,6.2]],"id":52385917},{"atb":[[1.01,324.73]],"id":52385897},{"atb":[[1.03,6.2]],"id":52385891},{"atb":[[1.02,9.3]],"id":52385893},{"atb":[[1.03,6.2]],"id":52385903},{"atb":[[1.03,6.2]],"id":52385905},{"atb":[[1.01,324.73]],"id":52385899}],"con":true,"img":false}]}
{"op":"mcm","clk":"11550321650","pt":1719497035890,"mc":[{"id":"1.230178169","rc":[{"atb":[[1.33,0]],"id":52385898}],"con":true,"img":false}]}
{"op":"mcm","clk":"11550333648","pt":1719497167752,"mc":[{"id":"1.230178169","rc":[{"atb":[[19,13.17]],"id":52385910},{"atb":[[10,4.35]],"id":52385911}],"con":true,"img":false}]}
{"op":"mcm","clk":"11550333838","pt":1719497169624,"mc":[{"id":"1.230178169","rc":[{"atb":[[19,0]],"id":52385910},{"atb":[[10,0]],"id":52385911}],"con":true,"img":false}]}
{"op":"mcm","clk":"11550335983","pt":1719497192595,"mc":[{"id":"1.230178169","rc":[{"atb":[[1.17,0]],"id":52385903}],"con":true,"img":false}]}
{"op":"mcm","clk":"11550339107","pt":1719497223936,"mc":[{"id":"1.230178169","rc":[{"atb":[[15,6]],"id":52385910},{"atb":[[20,5]],"id":52385912},{"atb":[[20,5]],"id":52385906},{"atb":[[13,8]],"id":52385918},{"atb":[[17,6]],"id":52385920},{"atb":[[9,11]],"id":52385889},{"atb":[[11,9]],"id":52385914},{"atb":[[20,5]],"id":52385883},{"atb":[[17,6]],"id":52385885},{"atb":[[20,5]],"id":52385896},{"atb":[[15,6]],"id":52385890},{"atb":[[10,10]],"id":52385892},{"atb":[[16,6]],"id":52385904},{"atb":[[20,5]],"id":52385898},{"atb":[[20,5]],"id":52385900},{"atb":[[13,8]],"id":52385911},{"atb":[[16,6]],"id":52385913},{"atb":[[20,5]],"id":52385907},{"atb":[[16,6]],"id":52385886},{"atb":[[20,5]],"id":52385919},{"atb":[[13,8]],"id":52385921},{"atb":[[10,10]],"id":52385882},{"atb":[[20,5]],"id":52385884},{"atb":[[16,6]],"id":52385917},{"atb":[[18,5]],"id":52385897},{"atb":[[12,8]],"id":52385891},{"atb":[[11,9]],"id":52385893},{"atb":[[20,5]],"id":52385903},{"atb":[[24,4]],"id":52385905},{"atb":[[20,5]],"id":52385899}],"con":true,"img":false}]}
{"op":"mcm","clk":"11550344005","pt":1719497283471,"mc":[{"id":"1.230178169","rc":[{"atb":[[15.5,15]],"id":52385885},{"atb":[[9,22.5]],"id":52385893}],"con":true,"img":false}]}
{"op":"mcm","clk":"11550344265","pt":1719497286575,"mc":[{"id":"1.230178169","rc":[{"atb":[[15.5,0]],"id":52385885},{"atb":[[9,0]],"id":52385893}],"con":true,"img":false}]}
{"op":"mcm","clk":"11550346171","pt":1719497308672,"mc":[{"id":"1.230178169","rc":[{"atb":[[15.5,15.72]],"id":52385914},{"atb":[[10,20]],"id":52385911}],"con":true,"img":false}]}
{"op":"mcm","clk":"11550346180","pt":1719497308775,"mc":[{"id":"1.230178169","rc":[{"atb":[[18,13.96]],"id":52385910},{"atb":[[18,12.96]],"id":52385913}],"con":true,"img":false}]}
{"op":"mcm","clk":"11550346186","pt":1719497308880,"mc":[{"id":"1.230178169","rc":[{"atb":[[15.5,0]],"id":52385914},{"atb":[[10,0]],"id":52385911}],"con":true,"img":false}]}
{"op":"mcm","clk":"11550346195","pt":1719497308985,"mc":[{"id":"1.230178169","rc":[{"atb":[[18,0]],"id":52385910},{"atb":[[18,0]],"id":52385913}],"con":true,"img":false}]}
{"op":"mcm","clk":"11550350970","pt":1719497365899,"mc":[{"id":"1.230178169","rc":[{"atb":[[19,13.44]],"id":52385910},{"atb":[[16.5,16.73]],"id":52385914},{"atb":[[11,20]],"id":52385911},{"atb":[[19,13.84]],"id":52385913}],"con":true,"img":false}]}
{"op":"mcm","clk":"11550351082","pt":1719497367083,"mc":[{"id":"1.230178169","rc":[{"atb":[[19,0]],"id":52385910},{"atb":[[16.5,0]],"id":52385914},{"atb":[[11,0]],"id":52385911},{"atb":[[19,0]],"id":52385913}],"con":true,"img":false}]}
{"op":"mcm","clk":"11550357184","pt":1719497442629,"mc":[{"id":"1.230178169","rc":[{"atb":[[1.17,0]],"id":52385904}],"con":true,"img":false}]}
{"op":"mcm","clk":"11550358292","pt":1719497456864,"mc":[{"id":"1.230178169","rc":[{"atb":[[21,12.9]],"id":52385910},{"atb":[[36,6.57]],"id":52385883},{"atb":[[44,4.85]],"id":52385896},{"atb":[[22,10.98]],"id":52385886},{"atb":[[18,13.28]],"id":52385882},{"atb":[[26,10.51]],"id":52385884},{"atb":[[19.5,13.17]],"id":52385917},{"atb":[[20,12.5]],"id":52385897}],"con":true,"img":false}]}
{"op":"mcm","clk":"11550358304","pt":1719497457070,"mc":[{"id":"1.230178169","rc":[{"atb":[[21,0]],"id":52385910},{"atb":[[36,0]],"id":52385883},{"atb":[[44,0]],"id":52385896},{"atb":[[22,0]],"id":52385886},{"atb":[[18,0]],"id":52385882},{"atb":[[26,0]],"id":52385884},{"atb":[[19.5,0]],"id":52385917},{"atb":[[20,0]],"id":52385897}],"con":true,"img":false}]}
{"op":"mcm","clk":"11550358582","pt":1719497460588,"mc":[{"id":"1.230178169","rc":[{"atb":[[5.1,24.39]],"id":52385918},{"atl":[[430,2]],"id":52385918},{"atb":[[10.5,10.53]],"id":52385883},{"atl":[[690,2]],"id":52385883}],"con":true,"img":false}]}
{"op":"mcm","clk":"11550358593","pt":1719497460693,"mc":[{"id":"1.230178169","rc":[{"atb":[[7.8,14.71]],"id":52385910},{"atl":[[530,2]],"id":52385910},{"atb":[[9.2,12.2]],"id":52385912},{"atl":[[590,2]],"id":52385912},{"atb":[[8.6,13.16]],"id":52385906},{"atl":[[560,2]],"id":52385906},{"atb":[[8,14.29]],"id":52385920},{"atl":[[530,2]],"id":52385920},{"atb":[[4.5,22]],"id":52385889},{"atl":[[340,2]],"id":52385889},{"atb":[[5.6,21.74]],"id":52385914},{"atl":[[460,2]],"id":52385914},{"atb":[[10,11.11]],"id":52385885},{"atl":[[670,2]],"id":52385885},{"atb":[[10,10]],"id":52385896},{"atl":[[660,2]],"id":52385896},{"atb":[[5.3,12]],"id":52385890},{"atl":[[440,2]],"id":52385890},{"atb":[[5.1,20]],"id":52385892},{"atl":[[430,2]],"id":52385892},{"atb":[[5.8,20.83]],"id":52385904},{"atl":[[460,2]],"id":52385904},{"atb":[[13,8.33]],"id":52385898},{"atl":[[730,2]],"id":52385898},{"atb":[[9.4,10]],"id":52385900},{"atl":[[600,2]],"id":52385900},{"atb":[[5.5,22.22]],"id":52385911},{"atl":[[450,2]],"id":52385911},{"atb":[[8.4,13.51]],"id":52385913},{"atl":[[550,2]],"id":52385913},{"atb":[[6.4,18.52]],"id":52385907},{"atl":[[490,2]],"id":52385907},{"atb":[[8.6,13.16]],"id":52385886},{"atl":[[550,2]],"id":52385886},{"atb":[[8.8,12.82]],"id":52385919},{"atl":[[560,2]],"id":52385919},{"atb":[[7.2,16.13]],"id":52385921},{"atl":[[510,2]],"id":52385921},{"atb":[[6.6,17.86]],"id":52385882},{"atl":[[490,2]],"id":52385882},{"atb":[[10,10]],"id":52385884},{"atl":[[670,2]],"id":52385884},{"atb":[[7.2,16.13]],"id":52385917},{"atl":[[510,2]],"id":52385917},{"atb":[[8.4,13.51]],"id":52385897},{"atl":[[540,2]],"id":52385897},{"atb":[[5.1,16]],"id":52385891},{"atl":[[430,2]],"id":52385891},{"atb":[[4.4,18]],"id":52385893},{"atl":[[320,2]],"id":52385893},{"atb":[[8.2,10]],"id":52385903},{"atl":[[540,2]],"id":52385903},{"atb":[[9.4,11.9]],"id":52385905},{"atl":[[610,2]],"id":52385905},{"atb":[[12.5,8.7]],"id":52385899},{"atl":[[730,2]],"id":52385899}],"con":true,"img":false}]}
{"op":"mcm","clk":"11550359104","pt":1719497467078,"mc":[{"id":"1.230178169","rc":[{"atb":[[13,0]],"id":52385918},{"atb":[[13,0]],"id":52385921}],"con":true,"img":false}]}
{"op":"mcm","clk":"11550359112","pt":1719497467181,"mc":[{"id":"1.230178169","rc":[{"atb":[[2.82,54.95],[12,8]],"id":52385918},{"atb":[[7.2,0],[12,8],[3.3,43.48]],"id":52385921}],"con":true,"img":false}]}
{"op":"mcm","clk":"11550359117","pt":1719497467284,"mc":[{"id":"1.230178169","rc":[{"atb":[[5.1,0]],"id":52385918}],"con":true,"img":false}]}
{"op":"mcm","clk":"11550359774","pt":1719497477298,"mc":[{"id":"1.230178169","rc":[{"atb":[[2.82,0],[5.1,24.39]],"id":52385918},{"atb":[[7.2,16.13],[3.3,0]],"id":52385921}],"con":true,"img":false}]}
{"op":"mcm","clk":"11550360387","pt":1719497486008,"mc":[{"id":"1.230178169","rc":[{"atb":[[9.2,0],[10.5,10.53]],"id":52385912},{"atb":[[8.6,0],[9.8,11.36]],"id":52385906},{"atb":[[8,0],[9,12.5]],"id":52385920},{"atb":[[5.6,0],[6.4,18.52]],"id":52385914},{"atl":[[670,0],[660,2]],"id":52385885},{"atb":[[5.3,0],[6,12]],"id":52385890},{"atb":[[5.1,0],[5.7,20]],"id":52385892},{"atb":[[5.8,0],[6.6,17.86]],"id":52385904},{"atb":[[13,0],[15,7.14]],"id":52385898},{"atb":[[6.2,19.23],[5.5,0]],"id":52385911},{"atb":[[9.6,11.63],[8.4,0]],"id":52385913},{"atb":[[6.4,0],[7.4,15.62]],"id":52385907},{"atb":[[10,11.11],[8.8,0]],"id":52385919},{"atb":[[8.4,0],[9.4,11.9]],"id":52385897},{"atb":[[5.1,0],[5.7,16]],"id":52385891},{"atb":[[12.5,0],[15,7.14]],"id":52385899}],"con":true,"img":false}]}
{"op":"mcm","clk":"11550360465","pt":1719497487192,"mc":[{"id":"1.230178169","rc":[{"atb":[[5.1,0],[5.8,20.83]],"id":52385918},{"atb":[[7.2,0],[8.2,13.89]],"id":52385921}],"con":true,"img":false}]}
{"op":"mcm","clk":"11550360705","pt":1719497491006,"mc":[{"id":"1.230178169","rc":[{"atl":[[530,0],[510,2]],"id":52385910},{"atl":[[540,2]],"id":52385906},{"atl":[[430,0],[420,2]],"id":52385918},{"atl":[[520,2]],"id":52385920},{"atl":[[310,2]],"id":52385889},{"atl":[[440,2],[460,0]],"id":52385914},{"atl":[[630,2],[690,0]],"id":52385883},{"atl":[[620,2],[660,0]],"id":52385896},{"atl":[[430,2],[440,0]],"id":52385890},{"atl":[[430,0],[420,2]],"id":52385892},{"atl":[[450,2]],"id":52385904},{"atl":[[700,2],[730,0]],"id":52385898},{"atl":[[600,0],[590,2]],"id":52385900},{"atl":[[440,2],[450,0]],"id":52385911},{"atl":[[540,2],[550,0]],"id":52385913},{"atl":[[470,2],[490,0]],"id":52385907},{"atl":[[520,2]],"id":52385886},{"atl":[[550,2]],"id":52385919},{"atl":[[510,0],[500,2]],"id":52385921},{"atl":[[460,2],[490,0]],"id":52385882},{"atl":[[610,2],[670,0]],"id":52385884},{"atl":[[490,2],[510,0]],"id":52385917},{"atl":[[540,0]],"id":52385897},{"atl":[[430,0]],"id":52385891},{"atl":[[310,2]],"id":52385893},{"atl":[[540,0],[520,2]],"id":52385903},{"atl":[[610,0]],"id":52385905},{"atl":[[700,2]],"id":52385899}],"con":true,"img":false}]}
{"op":"mcm","clk":"11550360712","pt":1719497491110,"mc":[{"id":"1.230178169","rc":[{"atl":[[570,2],[590,0]],"id":52385912},{"atl":[[560,0]],"id":52385906},{"atl":[[530,0]],"id":52385920},{"atl":[[340,0]],"id":52385889},{"atl":[[460,0]],"id":52385904},{"atl":[[550,0]],"id":52385886},{"atl":[[560,0]],"id":52385919},{"atl":[[530,2]],"id":52385897},{"atl":[[420,2]],"id":52385891},{"atl":[[320,0]],"id":52385893},{"atl":[[590,2]],"id":52385905},{"atl":[[730,0]],"id":52385899}],"con":true,"img":false}]}
{"op":"mcm","clk":"11550361020","pt":1719497496125,"mc":[{"id":"1.230178169","rc":[{"atl":[[530,2],[510,0]],"id":52385910},{"atl":[[420,0],[430,2]],"id":52385918},{"atl":[[630,0],[690,2]],"id":52385883},{"atl":[[620,0],[660,2]],"id":52385896},{"atl":[[430,0],[440,2]],"id":52385890},{"atl":[[700,0],[730,2]],"id":52385898},{"atl":[[590,0],[600,2]],"id":52385900},{"atl":[[440,0],[450,2]],"id":52385911},{"atl":[[470,0],[490,2]],"id":52385907},{"atl":[[500,0],[510,2]],"id":52385921},{"atl":[[610,0],[670,2]],"id":52385884},{"atl":[[520,0],[540,2]],"id":52385903}],"con":true,"img":false}]}
{"op":"mcm","clk":"11550361284","pt":1719497499990,"mc":[{"id":"1.230178169","rc":[{"atb":[[23,8.75]],"id":52385912},{"atb":[[19,10]],"id":52385885},{"atb":[[12,12.5]],"id":52385911},{"atb":[[24,8.75]],"id":52385899}],"con":true,"img":false}]}
{"op":"mcm","clk":"11550361298","pt":1719497500200,"mc":[{"id":"1.230178169","rc":[{"atb":[[23,0]],"id":52385912},{"atb":[[19,0]],"id":52385885},{"atb":[[12,0]],"id":52385911},{"atb":[[24,0]],"id":52385899}],"con":true,"img":false}]}
{"op":"mcm","clk":"11550361630","pt":1719497505101,"mc":[{"id":"1.230178169","rc":[{"atl":[[610,2],[660,0]],"id":52385885}],"con":true,"img":false}]}
{"op":"mcm","clk":"11550361698","pt":1719497505825,"mc":[{"id":"1.230178169","rc":[{"atl":[[510,2]],"id":52385910}],"con":true,"img":false}]}
{"op":"mcm","clk":"11550361714","pt":1719497505927,"mc":[{"id":"1.230178169","rc":[{"atl":[[530,0]],"id":52385910},{"atl":[[430,0],[420,2]],"id":52385918},{"atl":[[630,2],[690,0]],"id":52385883},{"atl":[[620,2],[660,0]],"id":52385896},{"atl":[[430,2],[440,0]],"id":52385890},{"atl":[[700,2],[730,0]],"id":52385898},{"atl":[[600,0],[590,2]],"id":52385900},{"atl":[[440,2],[450,0]],"id":52385911},{"atl":[[470,2],[490,0]],"id":52385907},{"atl":[[510,0],[500,2]],"id":52385921},{"atl":[[610,2],[670,0]],"id":52385884},{"atl":[[540,0],[520,2]],"id":52385903}],"con":true,"img":false}]}
{"op":"mcm","clk":"11550362636","pt":1719497517423,"mc":[{"id":"1.230178169","rc":[{"atl":[[440,0],[450,2]],"id":52385911}],"con":true,"img":false}]}
{"op":"mcm","clk":"11550362911","pt":1719497520068,"mc":[{"id":"1.230178169","rc":[{"atl":[[440,2],[450,0]],"id":52385911}],"con":true,"img":false}]}
{"op":"mcm","clk":"11550368166","pt":1719497585128,"mc":[{"id":"1.230178169","rc":[{"atb":[[15,0]],"id":52385910}],"con":true,"img":false}]}
{"op":"mcm","clk":"11550368176","pt":1719497585245,"mc":[{"id":"1.230178169","rc":[{"atb":[[14,6]],"id":52385910}],"con":true,"img":false}]}
{"op":"mcm","clk":"11550368185","pt":1719497585325,"mc":[{"id":"1.230178169","rc":[{"atb":[[7.8,0],[3.65,37.74]],"id":52385910}],"con":true,"img":false}]}
{"op":"mcm","clk":"11550368204","pt":1719497585534,"mc":[{"id":"1.230178169","rc":[{"atb":[[8.6,13.16],[3.65,0]],"id":52385910}],"con":true,"img":false}]}
{"op":"mcm","clk":"11550369788","pt":1719497606045,"mc":[{"id":"1.230178169","rc":[{"atb":[[5.2,23.81]],"id":52385918},{"atb":[[6,0],[5.4,18]],"id":52385890},{"atb":[[13,8.33],[15,0]],"id":52385898},{"atb":[[10,0],[8.8,12.82]],"id":52385919},{"atb":[[13,8.33],[15,0]],"id":52385899}],"con":true,"img":false}]}
{"op":"mcm","clk":"11550369796","pt":1719497606149,"mc":[{"id":"1.230178169","rc":[{"atb":[[5.8,0]],"id":52385918}],"con":true,"img":false}]}
{"op":"mcm","clk":"11550370682","pt":1719497618447,"mc":[{"id":"1.230178169","rc":[{"atb":[[19.5,10]],"id":52385910},{"atb":[[24,8.75]],"id":52385912},{"atb":[[34,7.22]],"id":52385883},{"atb":[[21,10]],"id":52385885},{"atb":[[36,6.58]],"id":52385896},{"atb":[[17,15]],"id":52385882},{"atb":[[26,8.75]],"id":52385899}],"con":true,"img":false}]}
{"op":"mcm","clk":"11550370703","pt":1719497618652,"mc":[{"id":"1.230178169","rc":[{"atb":[[19.5,0]],"id":52385910},{"atb":[[24,0]],"id":52385912},{"atb":[[34,0]],"id":52385883},{"atb":[[21,0]],"id":52385885},{"atb":[[36,0]],"id":52385896},{"atb":[[17,0]],"id":52385882},{"atb":[[26,0]],"id":52385899}],"con":true,"img":false}]}
{"op":"mcm","clk":"11550371985","pt":1719497636003,"mc":[{"id":"1.230178169","rc":[{"atb":[[10,0]],"id":52385882}],"con":true,"img":false}]}
{"op":"mcm","clk":"11550371997","pt":1719497636108,"mc":[{"id":"1.230178169","rc":[{"atb":[[9,10]],"id":52385882}],"con":true,"img":false}]}
{"op":"mcm","clk":"11550372005","pt":1719497636160,"mc":[{"id":"1.230178169","rc":[{"atb":[[3,50],[6.6,0]],"id":52385882}],"con":true,"img":false}]}
{"op":"mcm","clk":"11550372725","pt":1719497644477,"mc":[{"id":"1.230178169","rc":[{"atb":[[3,0],[6,20]],"id":52385882}],"con":true,"img":false}]}
{"op":"mcm","clk":"11550375538","pt":1719497679131,"mc":[{"id":"1.230178169","rc":[{"atb":[[13.5,5],[14.5,16],[15.5,2.5]],"id":52385910},{"atl":[[70,5],[50,2.5],[500,1.2]],"id":52385910},{"atb":[[19.5,5],[21,14],[23,2.5]],"id":52385912},{"atl":[[560,1.07],[80,2.5],[100,5]],"id":52385912},{"atb":[[21,14],[13.5,5],[15.5,2.5]],"id":52385906},{"atl":[[65,2.5],[530,1.13],[85,5]],"id":52385906},{"atb":[[7.4,2.5],[5.2,0],[12.5,20],[5.7,21.28],[6.6,5]],"id":52385918},{"atl":[[32,2.5],[40,5],[410,1.47]],"id":52385918},{"atb":[[17.5,16],[13.5,5],[15.5,2.5]],"id":52385920},{"atl":[[80,5],[60,2.5],[510,1.18]],"id":52385920},{"atb":[[9,37],[5.1,5],[5.5,2.5]],"id":52385889},{"atl":[[300,2.01],[38,5],[30,2.5]],"id":52385889},{"atb":[[9.6,2.5],[11.5,22],[8.8,5]],"id":52385914},{"atl":[[38,2.5],[46,5],[430,1.4]],"id":52385914},{"atb":[[20,10],[21,14],[24,2.5]],"id":52385883},{"atl":[[620,0.97],[90,2.5],[120,5]],"id":52385883},{"atb":[[17.5,16],[11.5,5],[13.5,2.5]],"id":52385885},{"atl":[[600,1],[90,2.5],[120,5]],"id":52385885},{"atb":[[21,14],[25,5],[29,2.5]],"id":52385896},{"atl":[[150,5],[610,0.99],[110,2.5]],"id":52385896},{"atb":[[9.6,2.5],[6,18],[8.8,5],[15,22],[5.4,0]],"id":52385890},{"atl":[[44,2.5],[420,1.43],[55,5]],"id":52385890},{"atb":[[10.5,24],[7.8,2.5],[7,5]],"id":52385892},{"atl":[[32,2.5],[40,5],[410,1.47]],"id":52385892},{"atb":[[16,22],[9,5],[9.8,2.5]],"id":52385904},{"atl":[[46,2.5],[440,1.37],[60,5]],"id":52385904},{"atb":[[21,14],[1.33,2.5],[13,0],[1.29,5],[15,7.14]],"id":52385898},{"atl":[[160,5],[690,0.87],[120,2.5]],"id":52385898},{"atb":[[18.5,5],[21,16.5]],"id":52385900},{"atl":[[590,0],[580,3.04],[85,2.5],[110,5]],"id":52385900},{"atb":[[10,2.5],[9.2,5],[13.5,20]],"id":52385911},{"atl":[[36,2.5],[44,5],[430,1.4]],"id":52385911},{"atb":[[16.5,16],[12,5],[14,2.5]],"id":52385913},{"atl":[[65,2.5],[530,1.13],[85,5]],"id":52385913},{"atb":[[20,19],[10.5,5],[12.5,2.5]],"id":52385907},{"atl":[[75,5],[55,2.5],[460,1.31]],"id":52385907},{"atb":[[16.5,16],[12.5,5],[14.5,2.5]],"id":52385886},{"atl":[[80,5],[60,2.5],[510,1.18]],"id":52385886},{"atb":[[17.5,5],[19.5,2.5],[10,11.11],[21,14],[8.8,0]],"id":52385919},{"atl":[[65,2.5],[540,1.11],[85,5]],"id":52385919},{"atb":[[10,2.5],[9.2,5],[12.5,20]],"id":52385921},{"atl":[[65,5],[48,2.5],[490,1.23]],"id":52385921},{"atb":[[10,5],[9.2,24],[6,0],[12,2.5],[6.8,17.24]],"id":52385882},{"atl":[[40,2.5],[48,5],[460,0],[450,3.34]],"id":52385882},{"atb":[[16.5,2.5],[21,14],[14.5,5]],"id":52385884},{"atl":[[600,1],[85,2.5],[110,5]],"id":52385884},{"atb":[[16.5,16],[10,5],[12,2.5]],"id":52385917},{"atl":[[46,2.5],[60,5],[480,1.25]],"id":52385917},{"atb":[[16,5],[18,7.5],[18.5,14]],"id":52385897},{"atl":[[520,1.16],[75,2.5],[95,5]],"id":52385897},{"atb":[[9,2.5],[8.2,5],[12.5,20]],"id":52385891},{"atl":[[32,2.5],[40,5],[410,1.47]],"id":52385891},{"atb":[[5.3,5],[5.7,2.5]],"id":52385893},{"atl":[[300,2.01],[24,2.5],[28,5]],"id":52385893},{"atb":[[21,14],[13,5],[15,2.5]],"id":52385903},{"atl":[[80,5],[60,2.5],[510,1.18]],"id":52385903},{"atb":[[21,5],[25,14.5]],"id":52385905},{"atl":[[580,1.04],[90,2.5],[120,5]],"id":52385905},{"atb":[[21,14],[13,0],[26,5],[14.5,7.41],[30,2.5]],"id":52385899},{"atl":[[160,5],[690,0.87],[120,2.5]],"id":52385899}],"con":true,"img":false}]}
{"op":"mcm","clk":"11550375547","pt":1719497679234,"mc":[{"id":"1.230178169","rc":[{"atl":[[75,2],[440,0]],"id":52385914},{"atl":[[65,2],[430,0]],"id":52385890},{"atl":[[700,0]],"id":52385898},{"atl":[[470,0]],"id":52385907},{"atl":[[520,0],[120,2]],"id":52385886},{"atl":[[95,2]],"id":52385917},{"atl":[[130,2]],"id":52385897},{"atl":[[60,2]],"id":52385891},{"atl":[[32,3.23],[310,0]],"id":52385893},{"atl":[[700,0]],"id":52385899}],"con":true,"img":false}]}
{"op":"mcm","clk":"11550375568","pt":1719497679340,"mc":[{"id":"1.230178169","rc":[{"atl":[[110,2],[510,0]],"id":52385910},{"atl":[[570,0],[180,2]],"id":52385912},{"atl":[[540,0],[150,2]],"id":52385906},{"atl":[[420,0],[60,2]],"id":52385918},{"atl":[[520,0],[120,2]],"id":52385920},{"atl":[[32,3.23],[310,0]],"id":52385889},{"atl":[[630,0],[230,2]],"id":52385883},{"atl":[[610,0],[210,2]],"id":52385885},{"atl":[[620,0],[220,2]],"id":52385896},{"atl":[[420,0],[60,2]],"id":52385892},{"atl":[[75,2],[450,0]],"id":52385904},{"atl":[[300,2]],"id":52385898},{"atl":[[70,2],[440,0]],"id":52385911},{"atl":[[540,0],[140,2]],"id":52385913},{"atl":[[85,2]],"id":52385907},{"atl":[[550,0],[150,2]],"id":52385919},{"atl":[[100,2],[500,0]],"id":52385921},{"atl":[[610,0],[210,2]],"id":52385884},{"atl":[[490,0]],"id":52385917},{"atl":[[530,0]],"id":52385897},{"atl":[[420,0]],"id":52385891},{"atl":[[520,0],[120,2]],"id":52385903},{"atl":[[590,0],[190,2]],"id":52385905},{"atl":[[300,2]],"id":52385899}],"con":true,"img":false}]}
{"op":"mcm","clk":"11550375605","pt":1719497680008,"mc":[{"id":"1.230178169","rc":[{"atb":[[9,0]],"id":52385882}],"con":true,"img":false}]}
{"op":"mcm","clk":"11550375622","pt":1719497680215,"mc":[{"id":"1.230178169","rc":[{"atb":[[20,0]],"id":52385896}],"con":true,"img":false}]}
{"op":"mcm","clk":"11550375667","pt":1719497680521,"mc":[{"id":"1.230178169","rc":[{"atb":[[20,0]],"id":52385899}],"con":true,"img":false}]}
{"op":"mcm","clk":"11550375681","pt":1719497680726,"mc":[{"id":"1.230178169","rc":[{"atb":[[17,0]],"id":52385885},{"atb":[[16,0]],"id":52385886},{"atb":[[12,0]],"id":52385891}],"con":true,"img":false}]}
{"op":"mcm","clk":"11550375692","pt":1719497680830,"mc":[{"id":"1.230178169","rc":[{"atb":[[19,6]],"id":52385885},{"atb":[[18,6]],"id":52385886},{"atb":[[13,8]],"id":52385891}],"con":true,"img":false}]}
{"op":"mcm","clk":"11550375701","pt":1719497680932,"mc":[{"id":"1.230178169","rc":[{"atb":[[12.5,0],[13,23]],"id":52385891}],"con":true,"img":false}]}
{"op":"mcm","clk":"11550375875","pt":1719497682843,"mc":[{"id":"1.230178169","rc":[{"atb":[[1.17,0]],"id":52385905}],"con":true,"img":false}]}
{"op":"mcm","clk":"11550376018","pt":1719497684548,"mc":[{"id":"1.230178169","rc":[{"atl":[[32,0],[38,7.7]],"id":52385889}],"con":true,"img":false}]}
{"op":"mcm","clk":"11550376031","pt":1719497684653,"mc":[{"id":"1.230178169","rc":[{"atl":[[38,5]],"id":52385889}],"con":true,"img":false}]}
{"op":"mcm","clk":"11550376040","pt":1719497684754,"mc":[{"id":"1.230178169","rc":[{"atl":[[300,4.01]],"id":52385889}],"con":true,"img":false}]}
{"op":"mcm","clk":"11550376836","pt":1719497692967,"mc":[{"id":"1.230178169","rc":[{"atb":[[12,0]],"id":52385918},{"atb":[[12,0]],"id":52385921}],"con":true,"img":false}]}
{"op":"mcm","clk":"11550376841","pt":1719497693069,"mc":[{"id":"1.230178169","rc":[{"atb":[[13,8]],"id":52385918},{"atb":[[13,8]],"id":52385921}],"con":true,"img":false}]}
{"op":"mcm","clk":"11550376922","pt":1719497694063,"mc":[{"id":"1.230178169","rc":[{"atb":[[8.6,0],[9.2,12.2]],"id":52385910},{"atb":[[5.1,29.39],[4.5,0]],"id":52385889},{"atb":[[10,0],[12,9.09]],"id":52385885},{"atb":[[16,6.67],[15,0]],"id":52385898},{"atb":[[11.5,9.52],[9.4,0]],"id":52385900},{"atb":[[8.6,0],[9.8,11.36]],"id":52385886},{"atb":[[8.2,0],[8.8,12.82]],"id":52385921},{"atb":[[7.2,0],[8.4,13.51]],"id":52385917},{"atb":[[5.1,18],[4.4,0]],"id":52385893},{"atb":[[9.6,10],[8.2,0]],"id":52385903},{"atb":[[11.5,9.52],[9.4,0]],"id":52385905}],"con":true,"img":false}]}
{"op":"mcm","clk":"11550377058","pt":1719497695968,"mc":[{"id":"1.230178169","rc":[{"atb":[[25,15]],"id":52385910},{"atl":[[48,12.77]],"id":52385910},{"atb":[[32,15]],"id":52385912},{"atl":[[75,8.11]],"id":52385912},{"atb":[[22,15]],"id":52385906},{"atl":[[60,10.17]],"id":52385906},{"atb":[[14.5,15]],"id":52385918},{"atl":[[30,15]],"id":52385918},{"atb":[[24,15]],"id":52385920},{"atl":[[55,11.11]],"id":52385920},{"atl":[[29,18.02]],"id":52385889},{"atl":[[36,15]],"id":52385914},{"atb":[[46,13.33]],"id":52385883},{"atl":[[85,7.14]],"id":52385883},{"atb":[[28,15]],"id":52385885},{"atl":[[85,7.14]],"id":52385885},{"atb":[[30,15]],"id":52385896},{"atl":[[100,6.06]],"id":52385896},{"atl":[[42,14.63]],"id":52385890},{"atb":[[12.5,15]],"id":52385892},{"atl":[[30,15]],"id":52385892},{"atl":[[32,15]],"id":52385904},{"atb":[[46,13.33]],"id":52385898},{"atl":[[110,5.5]],"id":52385898},{"atb":[[34,18.18]],"id":52385900},{"atl":[[80,7.59]],"id":52385900},{"atb":[[14.5,15]],"id":52385911},{"atl":[[34,15]],"id":52385911},{"atb":[[23,15]],"id":52385913},{"atl":[[60,10.17]],"id":52385913},{"atl":[[50,12.24]],"id":52385907},{"atb":[[27,15]],"id":52385886},{"atl":[[55,11.11]],"id":52385886},{"atb":[[30,15]],"id":52385919},{"atl":[[60,10.17]],"id":52385919},{"atb":[[16.5,15]],"id":52385921},{"atl":[[46,13.33]],"id":52385921},{"atb":[[12.5,16.68]],"id":52385882},{"atl":[[30,16.68]],"id":52385882},{"atb":[[34,15]],"id":52385884},{"atl":[[80,7.59]],"id":52385884},{"atl":[[44,13.95]],"id":52385917},{"atb":[[26,20]],"id":52385897},{"atl":[[70,8.7]],"id":52385897},{"atl":[[24,15]],"id":52385891},{"atl":[[18,16.46]],"id":52385893},{"atb":[[24,15]],"id":52385903},{"atl":[[55,11.11]],"id":52385903},{"atb":[[38,16.22]],"id":52385905},{"atl":[[85,7.14]],"id":52385905},{"atb":[[36,15]],"id":52385899},{"atl":[[110,5.5]],"id":52385899}],"con":true,"img":false}]}
{"op":"mcm","clk":"11550377065","pt":1719497696071,"mc":[{"id":"1.230178169","rc":[{"atb":[[21,0]],"id":52385906},{"atl":[[530,0]],"id":52385906},{"atb":[[12.5,0]],"id":52385918},{"atl":[[410,0]],"id":52385918},{"atl":[[38,7.7]],"id":52385889},{"atb":[[17.5,0]],"id":52385885},{"atl":[[600,0]],"id":52385885},{"atl":[[180,2]],"id":52385900},{"atb":[[13.5,0]],"id":52385911},{"atl":[[430,0]],"id":52385911},{"atb":[[21,0]],"id":52385919},{"atl":[[540,0]],"id":52385919},{"atb":[[12.5,0]],"id":52385921},{"atl":[[490,0]],"id":52385921},{"atl":[[450,1.34]],"id":52385882},{"atb":[[21,0]],"id":52385884},{"atl":[[600,0]],"id":52385884},{"atl":[[410,0]],"id":52385891},{"atl":[[300,0]],"id":52385893},{"atb":[[21,0]],"id":52385903},{"atl":[[510,0]],"id":52385903},{"atb":[[25,2.5]],"id":52385905},{"atl":[[580,0]],"id":52385905}],"con":true,"img":false}]}
{"op":"mcm","clk":"11550377073","pt":1719497696173,"mc":[{"id":"1.230178169","rc":[{"atb":[[14.5,0]],"id":52385910},{"atl":[[500,0]],"id":52385910},{"atb":[[21,0]],"id":52385912},{"atl":[[560,0]],"id":52385912},{"atb":[[17.5,0]],"id":52385920},{"atl":[[510,0]],"id":52385920},{"atl":[[300,0]],"id":52385889},{"atl":[[430,0]],"id":52385914},{"atb":[[21,0]],"id":52385883},{"atl":[[620,0]],"id":52385883},{"atb":[[21,0]],"id":52385896},{"atl":[[610,0]],"id":52385896},{"atl":[[420,0]],"id":52385890},{"atb":[[10.5,0]],"id":52385892},{"atl":[[410,0]],"id":52385892},{"atl":[[440,0]],"id":52385904},{"atb":[[21,0]],"id":52385898},{"atl":[[690,0]],"id":52385898},{"atb":[[21,2.5]],"id":52385900},{"atl":[[580,0]],"id":52385900},{"atb":[[16.5,0]],"id":52385913},{"atl":[[530,0]],"id":52385913},{"atl":[[460,0]],"id":52385907},{"atb":[[16.5,0]],"id":52385886},{"atl":[[510,0]],"id":52385886},{"atb":[[9.2,0]],"id":52385882},{"atl":[[75,2],[450,0]],"id":52385882},{"atl":[[480,0]],"id":52385917},{"atb":[[18.5,0]],"id":52385897},{"atl":[[520,0]],"id":52385897},{"atb":[[21,0]],"id":52385899},{"atl":[[690,0]],"id":52385899}],"con":true,"img":false}]}
{"op":"mcm","clk":"11550377151","pt":1719497697255,"mc":[{"id":"1.230178169","rc":[{"atb":[[46,0]],"id":52385883},{"atb":[[23,0],[24,22]],"id":52385913}],"con":true,"img":false}]}
{"op":"mcm","clk":"11550377161","pt":1719497697358,"mc":[{"id":"1.230178169","rc":[{"atb":[[42,14.63]],"id":52385883},{"atb":[[28,0]],"id":52385885},{"atb":[[46,0]],"id":52385898},{"atb":[[27,0]],"id":52385886},{"atb":[[34,0]],"id":52385884},{"atb":[[36,0]],"id":52385899}],"con":true,"img":false}]}
{"op":"mcm","clk":"11550377171","pt":1719497697463,"mc":[{"id":"1.230178169","rc":[{"atb":[[25,22]],"id":52385885},{"atb":[[40,15.38]],"id":52385898},{"atb":[[25,22]],"id":52385886},{"atb":[[30,20]],"id":52385884},{"atb":[[32,19.35]],"id":52385899}],"con":true,"img":false}]}
{"op":"mcm","clk":"11550377179","pt":1719497697562,"mc":[{"id":"1.230178169","rc":[{"atb":[[42,0]],"id":52385883}],"con":true,"img":false}]}
{"op":"mcm","clk":"11550377188","pt":1719497697666,"mc":[{"id":"1.230178169","rc":[{"atb":[[38,16.22]],"id":52385883}],"con":true,"img":false}]}
{"op":"mcm","clk":"11550377289","pt":1719497698954,"mc":[{"id":"1.230178169","rc":[{"atl":[[290,2],[230,0]],"id":52385883},{"atl":[[280,2],[220,0]],"id":52385896},{"atl":[[65,0],[80,2]],"id":52385890},{"atl":[[300,0],[380,2]],"id":52385898},{"atl":[[85,0],[110,2]],"id":52385907},{"atl":[[380,2]],"id":52385899}],"con":true,"img":false}]}
{"op":"mcm","clk":"11550377298","pt":1719497699056,"mc":[{"id":"1.230178169","rc":[{"atl":[[300,0]],"id":52385899}],"con":true,"img":false}]}
{"op":"mcm","clk":"11550378031","pt":1719497707562,"mc":[{"id":"1.230178169","rc":[{"atl":[[65,2]],"id":52385890}],"con":true,"img":false}]}
{"op":"mcm","clk":"11550378039","pt":1719497707664,"mc":[{"id":"1.230178169","rc":[{"atl":[[290,0],[230,2]],"id":52385883},{"atl":[[280,0],[220,2]],"id":52385896},{"atl":[[80,0]],"id":52385890},{"atl":[[300,2],[380,0]],"id":52385898},{"atl":[[85,2],[110,0]],"id":52385907},{"atl":[[300,2]],"id":52385899}],"con":true,"img":false}]}
{"op":"mcm","clk":"11550378045","pt":1719497707767,"mc":[{"id":"1.230178169","rc":[{"atl":[[380,0]],"id":52385899}],"con":true,"img":false}]}
{"op":"mcm","clk":"11550378334","pt":1719497711071,"mc":[{"id":"1.230178169","rc":[{"atb":[[13,0]],"id":52385918},{"atb":[[13,0]],"id":52385921}],"con":true,"img":false}]}
{"op":"mcm","clk":"11550378347","pt":1719497711177,"mc":[{"id":"1.230178169","rc":[{"atb":[[12,8]],"id":52385918},{"atb":[[12,8]],"id":52385921}],"con":true,"img":false}]}
{"op":"mcm","clk":"11550378438","pt":1719497712362,"mc":[{"id":"1.230178169","rc":[{"atl":[[28,22.22]],"id":52385889},{"atb":[[46,13.33]],"id":52385883},{"atb":[[27,22]],"id":52385885},{"atb":[[34,18.18]],"id":52385896},{"atl":[[40,15.38]],"id":52385890},{"atb":[[44,13.95]],"id":52385898},{"atb":[[27,22]],"id":52385886},{"atb":[[15.5,20]],"id":52385882},{"atb":[[32,19.35]],"id":52385884},{"atb":[[34,18.18]],"id":52385899}],"con":true,"img":false}]}
{"op":"mcm","clk":"11550378447","pt":1719497712465,"mc":[{"id":"1.230178169","rc":[{"atl":[[29,0]],"id":52385889},{"atb":[[38,0]],"id":52385883},{"atb":[[25,0]],"id":52385885},{"atb":[[30,0]],"id":52385896},{"atl":[[42,0]],"id":52385890},{"atb":[[40,0]],"id":52385898},{"atb":[[25,0]],"id":52385886},{"atb":[[12.5,0]],"id":52385882},{"atb":[[30,0]],"id":52385884},{"atb":[[32,0]],"id":52385899}],"con":true,"img":false}]}
{"op":"mcm","clk":"11550378482","pt":1719497712773,"mc":[{"id":"1.230178169","rc":[{"atl":[[290,2]],"id":52385883},{"atl":[[280,2],[220,0]],"id":52385896},{"atl":[[300,0],[380,2]],"id":52385898},{"atl":[[85,0],[110,2]],"id":52385907},{"atl":[[300,0],[380,2]],"id":52385899}],"con":true,"img":false}]}
{"op":"mcm","clk":"11550378489","pt":1719497712876,"mc":[{"id":"1.230178169","rc":[{"atl":[[230,0]],"id":52385883}],"con":true,"img":false}]}
{"op":"mcm","clk":"11550378613","pt":1719497714174,"mc":[{"id":"1.230178169","rc":[{"atb":[[28,22]],"id":52385885},{"atb":[[46,13.33]],"id":52385898}],"con":true,"img":false}]}
{"op":"mcm","clk":"11550378629","pt":1719497714379,"mc":[{"id":"1.230178169","rc":[{"atb":[[27,0]],"id":52385885},{"atb":[[44,0]],"id":52385898}],"con":true,"img":false}]}
{"op":"mcm","clk":"11550378647","pt":1719497714689,"mc":[{"id":"1.230178169","rc":[{"atb":[[14.5,4.61]],"id":52385910},{"atl":[[46,2.68]],"id":52385910},{"atb":[[21,3.5]],"id":52385912},{"atl":[[70,2.5]],"id":52385912},{"atb":[[18,3.57]],"id":52385906},{"atl":[[55,3]],"id":52385906},{"atb":[[10.5,5]],"id":52385918},{"atl":[[29,2.5]],"id":52385918},{"atb":[[16,4.57]],"id":52385920},{"atl":[[50,2.1]],"id":52385920},{"atb":[[9.2,6.3]],"id":52385889},{"atl":[[27,3]],"id":52385889},{"atb":[[12,5.8]],"id":52385914},{"atl":[[34,3]],"id":52385914},{"atb":[[21,3.98]],"id":52385883},{"atl":[[80,2]],"id":52385883},{"atb":[[23,4.24]],"id":52385885},{"atl":[[80,2.6]],"id":52385885},{"atb":[[26,4]],"id":52385896},{"atl":[[95,2]],"id":52385896},{"atb":[[15.5,3.7]],"id":52385890},{"atl":[[38,2.6]],"id":52385890},{"atb":[[13,6]],"id":52385892},{"atl":[[29,3.03]],"id":52385892},{"atb":[[16.5,3.3]],"id":52385904},{"atl":[[100,2]],"id":52385898},{"atb":[[21,5.4]],"id":52385900},{"atl":[[75,2]],"id":52385900},{"atb":[[15,4.3]],"id":52385911},{"atl":[[32,2.13]],"id":52385911},{"atb":[[14.5,4]],"id":52385913},{"atl":[[55,2]],"id":52385913},{"atb":[[11,5]],"id":52385907},{"atl":[[48,2.8]],"id":52385907},{"atb":[[16,3.1]],"id":52385886},{"atl":[[55,2.9]],"id":52385919},{"atb":[[10.5,6]],"id":52385921},{"atl":[[40,3]],"id":52385921},{"atb":[[10.5,5]],"id":52385882},{"atb":[[18,4.2]],"id":52385884},{"atb":[[17,3.9]],"id":52385917},{"atl":[[42,3]],"id":52385917},{"atb":[[16.5,3.12]],"id":52385897},{"atl":[[65,2]],"id":52385897},{"atb":[[13.5,3.91]],"id":52385891},{"atb":[[11.5,6]],"id":52385893},{"atb":[[18.5,3.5]],"id":52385903},{"atb":[[25,5.5]],"id":52385905},{"atb":[[27,3.8]],"id":52385899},{"atl":[[100,2]],"id":52385899}],"con":true,"img":false}]}
{"op":"mcm","clk":"11550378654","pt":1719497714793,"mc":[{"id":"1.230178169","rc":[{"atl":[[44,13.95]],"id":52385910},{"atl":[[65,9.38]],"id":52385912},{"atl":[[55,14.11]],"id":52385906},{"atl":[[28,22.22]],"id":52385918},{"atl":[[48,12.77]],"id":52385920},{"atb":[[9.2,24.9]],"id":52385889},{"atb":[[12.5,29.6]],"id":52385914},{"atl":[[32,19.35]],"id":52385914},{"atl":[[80,9.59]],"id":52385883},{"atl":[[75,8.11]],"id":52385885},{"atl":[[90,6.74]],"id":52385896},{"atb":[[15.5,16.3]],"id":52385890},{"atb":[[13,38]],"id":52385892},{"atl":[[28,22.22]],"id":52385892},{"atb":[[16.5,19.9]],"id":52385904},{"atl":[[100,8.06]],"id":52385898},{"atl":[[70,8.7]],"id":52385900},{"atb":[[15,28.9]],"id":52385911},{"atl":[[30,20.69]],"id":52385911},{"atl":[[50,12.24]],"id":52385913},{"atl":[[46,13.33]],"id":52385907},{"atl":[[55,14.01]],"id":52385919},{"atl":[[40,18.38]],"id":52385921},{"atb":[[17.5,19.8]],"id":52385917},{"atl":[[40,15.38]],"id":52385917},{"atl":[[60,10.17]],"id":52385897},{"atb":[[13.5,21.73]],"id":52385891},{"atl":[[100,8.06]],"id":52385899}],"con":true,"img":false}]}
{"op":"mcm","clk":"11550378670","pt":1719497715004,"mc":[{"id":"1.230178169","rc":[{"atl":[[48,0]],"id":52385910},{"atl":[[75,0]],"id":52385912},{"atl":[[60,0]],"id":52385906},{"atl":[[30,0]],"id":52385918},{"atl":[[55,0]],"id":52385920},{"atb":[[9,11]],"id":52385889},{"atb":[[11.5,0]],"id":52385914},{"atl":[[36,0]],"id":52385914},{"atl":[[85,0]],"id":52385883},{"atl":[[85,0]],"id":52385885},{"atl":[[100,0]],"id":52385896},{"atb":[[15,6]],"id":52385890},{"atb":[[12.5,0]],"id":52385892},{"atl":[[30,0]],"id":52385892},{"atb":[[16,6]],"id":52385904},{"atl":[[110,0]],"id":52385898},{"atl":[[80,0]],"id":52385900},{"atb":[[14.5,0]],"id":52385911},{"atl":[[34,0]],"id":52385911},{"atl":[[60,0]],"id":52385913},{"atl":[[50,0]],"id":52385907},{"atl":[[60,0]],"id":52385919},{"atl":[[46,0]],"id":52385921},{"atb":[[16.5,0]],"id":52385917},{"atl":[[44,0]],"id":52385917},{"atl":[[70,0]],"id":52385897},{"atb":[[13,8]],"id":52385891},{"atl":[[110,0]],"id":52385899}],"con":true,"img":false}]}
{"op":"mcm","clk":"11550378681","pt":1719497715056,"mc":[{"id":"1.230178169","rc":[{"atb":[[20,5]],"id":52385883}],"con":true,"img":false}]}
{"op":"mcm","clk":"11550378703","pt":1719497715370,"mc":[{"id":"1.230178169","rc":[{"atb":[[14,0]],"id":52385910}],"con":true,"img":false}]}
{"op":"mcm","clk":"11550378720","pt":1719497715578,"mc":[{"id":"1.230178169","rc":[{"atb":[[20,0]],"id":52385912}],"con":true,"img":false}]}
{"op":"mcm","clk":"11550378739","pt":1719497715786,"mc":[{"id":"1.230178169","rc":[{"atb":[[16,0]],"id":52385904}],"con":true,"img":false}]}
{"op":"mcm","clk":"11550378751","pt":1719497715890,"mc":[{"id":"1.230178169","rc":[{"atb":[[18,6]],"id":52385904}],"con":true,"img":false}]}
{"op":"mcm","clk":"11550378842","pt":1719497717083,"mc":[{"id":"1.230178169","rc":[{"atb":[[20,0]],"id":52385898}],"con":true,"img":false}]}
{"op":"mcm","clk":"11550378850","pt":1719497717188,"mc":[{"id":"1.230178169","rc":[{"atb":[[16,0],[24,5],[5.2,20]],"id":52385898}],"con":true,"img":false}]}
{"op":"mcm","clk":"11550378861","pt":1719497717293,"mc":[{"id":"1.230178169","rc":[{"atb":[[5.2,0]],"id":52385898}],"con":true,"img":false}]}
{"op":"mcm","clk":"11550378868","pt":1719497717394,"mc":[{"id":"1.230178169","rc":[{"atb":[[16,6.67]],"id":52385898}],"con":true,"img":false}]}
{"op":"mcm","clk":"11550378901","pt":1719497717757,"mc":[{"id":"1.230178169","rc":[{"atl":[[32,0]],"id":52385904}],"con":true,"img":false}]}
{"op":"mcm","clk":"11550378909","pt":1719497717860,"mc":[{"id":"1.230178169","rc":[{"atl":[[34,18.18],[75,0],[90,2]],"id":52385904}],"con":true,"img":false}]}
{"op":"mcm","clk":"11550378930","pt":1719497718170,"mc":[{"id":"1.230178169","rc":[{"atl":[[32,3.23],[38,5]],"id":52385889},{"atl":[[290,0],[230,2]],"id":52385883},{"atl":[[280,0],[220,2]],"id":52385896},{"atl":[[75,2],[90,0]],"id":52385904},{"atl":[[300,2],[380,0]],"id":52385898},{"atl":[[85,2],[110,0]],"id":52385907},{"atl":[[300,2],[380,0]],"id":52385899}],"con":true,"img":false}]}
{"op":"mcm","clk":"11550378944","pt":1719497718275,"mc":[{"id":"1.230178169","rc":[{"atb":[[46,0]],"id":52385883}],"con":true,"img":false}]}
{"op":"mcm","clk":"11550378955","pt":1719497718377,"mc":[{"id":"1.230178169","rc":[{"atb":[[36,12.96]],"id":52385883}],"con":true,"img":false}]}
{"op":"mcm","clk":"11550378988","pt":1719497718891,"mc":[{"id":"1.230178169","rc":[{"atb":[[28,0]],"id":52385885},{"atb":[[34,0]],"id":52385896},{"atb":[[46,0]],"id":52385898},{"atb":[[27,0]],"id":52385886}],"con":true,"img":false}]}
{"op":"mcm","clk":"11550379001","pt":1719497718996,"mc":[{"id":"1.230178169","rc":[{"atb":[[26,20.48]],"id":52385885},{"atb":[[30,13]],"id":52385896},{"atb":[[42,14.63]],"id":52385898},{"atb":[[25,22]],"id":52385886}],"con":true,"img":false}]}
{"op":"mcm","clk":"11550379021","pt":1719497719205,"mc":[{"id":"1.230178169","rc":[{"atb":[[26,0]],"id":52385885},{"atb":[[42,0],[44,13.95]],"id":52385898},{"atb":[[25,0],[27,22]],"id":52385886}],"con":true,"img":false}]}
{"op":"mcm","clk":"11550379030","pt":1719497719306,"mc":[{"id":"1.230178169","rc":[{"atb":[[24,20.48]],"id":52385885},{"atb":[[34,0]],"id":52385899}],"con":true,"img":false}]}
{"op":"mcm","clk":"11550379039","pt":1719497719360,"mc":[{"id":"1.230178169","rc":[{"atb":[[32,17.6]],"id":52385899}],"con":true,"img":false}]}
{"op":"mcm","clk":"11550379077","pt":1719497719872,"mc":[{"id":"1.230178169","rc":[{"atb":[[36,0]],"id":52385883}],"con":true,"img":false}]}
{"op":"mcm","clk":"11550379085","pt":1719497719975,"mc":[{"id":"1.230178169","rc":[{"atb":[[32,12.96]],"id":52385883}],"con":true,"img":false}]}
{"op":"mcm","clk":"11550379104","pt":1719497720181,"mc":[{"id":"1.230178169","rc":[{"atb":[[32,0]],"id":52385883}],"con":true,"img":false}]}
{"op":"mcm","clk":"11550379115","pt":1719497720284,"mc":[{"id":"1.230178169","rc":[{"atb":[[25,17.96]],"id":52385883}],"con":true,"img":false}]}
{"op":"mcm","clk":"11550379334","pt":1719497722974,"mc":[{"id":"1.230178169","rc":[{"atl":[[290,2],[230,0]],"id":52385883}],"con":true,"img":false}]}
{"op":"mcm","clk":"11550379355","pt":1719497723284,"mc":[{"id":"1.230178169","rc":[{"atl":[[32,0],[38,7.7]],"id":52385889},{"atl":[[280,2],[220,0]],"id":52385896},{"atl":[[300,0],[380,2]],"id":52385898},{"atl":[[110,2]],"id":52385907},{"atl":[[300,0],[380,2]],"id":52385899}],"con":true,"img":false}]}
{"op":"mcm","clk":"11550379360","pt":1719497723387,"mc":[{"id":"1.230178169","rc":[{"atl":[[85,0]],"id":52385907}],"con":true,"img":false}]}
{"op":"mcm","clk":"11550379785","pt":1719497728407,"mc":[{"id":"1.230178169","rc":[{"atb":[[19,20]],"id":52385882}],"con":true,"img":false}]}
{"op":"mcm","clk":"11550379794","pt":1719497728509,"mc":[{"id":"1.230178169","rc":[{"atl":[[26,24]],"id":52385889},{"atb":[[40,15.38]],"id":52385883},{"atb":[[25,20.48]],"id":52385885},{"atb":[[42,13]],"id":52385896},{"atl":[[36,17.14]],"id":52385890}],"con":true,"img":false}]}
{"op":"mcm","clk":"11550379807","pt":1719497728613,"mc":[{"id":"1.230178169","rc":[{"atb":[[15.5,0]],"id":52385882}],"con":true,"img":false}]}
{"op":"mcm","clk":"11550379819","pt":1719497728717,"mc":[{"id":"1.230178169","rc":[{"atl":[[28,0]],"id":52385889},{"atb":[[25,0]],"id":52385883},{"atb":[[24,0]],"id":52385885},{"atb":[[30,0]],"id":52385896},{"atl":[[40,0]],"id":52385890}],"con":true,"img":false}]}
{"op":"mcm","clk":"11550379944","pt":1719497730110,"mc":[{"id":"1.230178169","rc":[{"atb":[[46,13.33]],"id":52385898}],"con":true,"img":false}]}
{"op":"mcm","clk":"11550379957","pt":1719497730215,"mc":[{"id":"1.230178169","rc":[{"atb":[[44,0]],"id":52385898}],"con":true,"img":false}]}
{"op":"mcm","clk":"11550380002","pt":1719497730783,"mc":[{"id":"1.230178169","rc":[{"atb":[[16,17.6]],"id":52385914},{"atb":[[18,28]],"id":52385904}],"con":true,"img":false}]}
{"op":"mcm","clk":"11550380015","pt":1719497730890,"mc":[{"id":"1.230178169","rc":[{"atb":[[12.5,0]],"id":52385914},{"atb":[[16.5,3.3]],"id":52385904}],"con":true,"img":false}]}
{"op":"mcm","clk":"11550380104","pt":1719497731923,"mc":[{"id":"1.230178169","rc":[{"atl":[[32,3.23],[38,5]],"id":52385889},{"atl":[[290,0],[230,2]],"id":52385883},{"atl":[[220,2]],"id":52385896},{"atl":[[300,2]],"id":52385898},{"atl":[[85,2],[110,0]],"id":52385907},{"atl":[[300,2],[380,0]],"id":52385899}],"con":true,"img":false}]}
{"op":"mcm","clk":"11550380111","pt":1719497732022,"mc":[{"id":"1.230178169","rc":[{"atl":[[280,0]],"id":52385896},{"atl":[[380,0]],"id":52385898}],"con":true,"img":false}]}
{"op":"mcm","clk":"11550380919","pt":1719497741526,"mc":[{"id":"1.230178169","rc":[{"atl":[[46,0]],"id":52385910},{"atl":[[70,0]],"id":52385912},{"atb":[[18,0]],"id":52385906},{"atl":[[55,11.11]],"id":52385906},{"atl":[[29,0]],"id":52385918},{"atl":[[50,0]],"id":52385920},{"atl":[[27,0]],"id":52385889},{"atl":[[34,0]],"id":52385914},{"atb":[[23,0]],"id":52385885},{"atl":[[80,0]],"id":52385885},{"atl":[[95,0]],"id":52385896},{"atl":[[38,0]],"id":52385890},{"atl":[[29,0]],"id":52385892},{"atb":[[16.5,0]],"id":52385904},{"atl":[[100,6.06]],"id":52385898},{"atl":[[75,0]],"id":52385900},{"atl":[[32,0]],"id":52385911},{"atl":[[55,0]],"id":52385913},{"atb":[[11,0]],"id":52385907},{"atl":[[48,0]],"id":52385907},{"atl":[[40,15.38]],"id":52385921},{"atb":[[17,0]],"id":52385917},{"atl":[[42,0]],"id":52385917},{"atb":[[16.5,0]],"id":52385897},{"atl":[[65,0]],"id":52385897},{"atb":[[18.5,0]],"id":52385903},{"atb":[[25,2.5]],"id":52385905},{"atb":[[27,0]],"id":52385899}],"con":true,"img":false}]}
{"op":"mcm","clk":"11550380938","pt":1719497741735,"mc":[{"id":"1.230178169","rc":[{"atl":[[42,3],[44,0]],"id":52385910},{"atl":[[65,0],[80,5.1]],"id":52385912},{"atb":[[23,4.17]],"id":52385906},{"atl":[[55,0]],"id":52385906},{"atl":[[27,4],[28,0]],"id":52385918},{"atl":[[46,2.2],[48,0]],"id":52385920},{"atl":[[25,4.1],[26,0]],"id":52385889},{"atl":[[32,0],[30,3.3]],"id":52385914},{"atb":[[19.5,2.86]],"id":52385885},{"atl":[[65,2.6],[75,0]],"id":52385885},{"atl":[[85,2],[90,0]],"id":52385896},{"atl":[[36,0],[44,5.5]],"id":52385890},{"atl":[[27,3],[28,0]],"id":52385892},{"atb":[[18.5,3.38]],"id":52385904},{"atb":[[21,4.2]],"id":52385898},{"atl":[[100,0]],"id":52385898},{"atl":[[70,0],[85,4.5]],"id":52385900},{"atl":[[36,5.6],[30,0]],"id":52385911},{"atl":[[65,4.5],[50,0]],"id":52385913},{"atb":[[21,3]],"id":52385907},{"atl":[[46,0]],"id":52385907},{"atl":[[50,2]],"id":52385886},{"atb":[[21,2.63]],"id":52385919},{"atl":[[34,3],[40,0]],"id":52385921},{"atl":[[29,2]],"id":52385882},{"atl":[[75,2.5]],"id":52385884},{"atb":[[17.5,0]],"id":52385917},{"atl":[[38,2.7],[40,0]],"id":52385917},{"atb":[[27,2.54]],"id":52385897},{"atl":[[75,4.7],[60,0]],"id":52385897},{"atb":[[25,2.48]],"id":52385903},{"atb":[[40,3.4]],"id":52385905},{"atb":[[34,2.42]],"id":52385899}],"con":true,"img":false}]}
{"op":"mcm","clk":"11550380949","pt":1719497741806,"mc":[{"id":"1.230178169","rc":[{"atl":[[46,13.33]],"id":52385910},{"atl":[[70,8.7]],"id":52385912},{"atb":[[24,18.34]],"id":52385906},{"atl":[[60,10.17]],"id":52385906},{"atl":[[30,20.69]],"id":52385918},{"atl":[[55,11.11]],"id":52385920},{"atl":[[28,22.22]],"id":52385889},{"atl":[[36,17.14]],"id":52385914},{"atl":[[80,7.59]],"id":52385885},{"atl":[[95,6.38]],"id":52385896},{"atl":[[40,15.38]],"id":52385890},{"atl":[[29,21.43]],"id":52385892},{"atl":[[110,5.5]],"id":52385898},{"atl":[[75,8.11]],"id":52385900},{"atl":[[34,18.18]],"id":52385911},{"atl":[[55,11.11]],"id":52385913},{"atb":[[21,14]],"id":52385907},{"atl":[[48,12.77]],"id":52385907},{"atl":[[48,12.77]],"id":52385886},{"atl":[[46,13.33]],"id":52385921},{"atl":[[29,17]],"id":52385882},{"atl":[[75,10.61]],"id":52385884},{"atb":[[16.5,22]],"id":52385917},{"atl":[[42,14.63]],"id":52385917},{"atb":[[27,21.94]],"id":52385897},{"atl":[[65,9.38]],"id":52385897},{"atb":[[25,22.48]],"id":52385903},{"atb":[[40,18.78]],"id":52385905},{"atb":[[36,15]],"id":52385899}],"con":true,"img":false}]}
{"op":"mcm","clk":"11550380971","pt":1719497741996,"mc":[{"id":"1.230178169","rc":[{"atb":[[22,0]],"id":52385906},{"atl":[[75,0]],"id":52385900},{"atb":[[20,5]],"id":52385907},{"atl":[[48,0]],"id":52385907},{"atl":[[55,0]],"id":52385886},{"atl":[[30,0]],"id":52385882},{"atl":[[80,0]],"id":52385884},{"atb":[[26,0]],"id":52385897},{"atl":[[65,0]],"id":52385897},{"atb":[[24,0]],"id":52385903},{"atb":[[38,0],[24,0]],"id":52385905},{"atb":[[32,0]],"id":52385899}],"con":true,"img":false}]}
{"op":"mcm","clk":"11550380983","pt":1719497742100,"mc":[{"id":"1.230178169","rc":[{"atl":[[80,7.59]],"id":52385900},{"atl":[[50,12.24]],"id":52385907},{"atl":[[70,8.7]],"id":52385897}],"con":true,"img":false}]}
{"op":"mcm","clk":"11550381010","pt":1719497742406,"mc":[{"id":"1.230178169","rc":[{"atl":[[70,0]],"id":52385912},{"atl":[[55,0]],"id":52385913}],"con":true,"img":false}]}
{"op":"mcm","clk":"11550381114","pt":1719497742616,"mc":[{"id":"1.230178169","rc":[{"atl":[[75,8.11]],"id":52385912},{"atl":[[60,10.17]],"id":52385913}],"con":true,"img":false}]}
{"op":"mcm","clk":"11550381158","pt":1719497743234,"mc":[{"id":"1.230178169","rc":[{"atb":[[16,2.5],[13.5,0],[15.5,0]],"id":52385906},{"atb":[[20,0],[21,8.98],[24,0],[25,2.5]],"id":52385883},{"atb":[[16.5,0],[17,2.5],[14.5,0]],"id":52385884}],"con":true,"img":false}]}
{"op":"mcm","clk":"11550381269","pt":1719497744213,"mc":[{"id":"1.230178169","rc":[{"atl":[[24,26.09]],"id":52385889}],"con":true,"img":false}]}
{"op":"mcm","clk":"11550381289","pt":1719497744411,"mc":[{"id":"1.230178169","rc":[{"atl":[[28,0]],"id":52385889}],"con":true,"img":false}]}
{"op":"mcm","clk":"11550381475","pt":1719497746527,"mc":[{"id":"1.230178169","rc":[{"atb":[[18.5,20.14]],"id":52385904}],"con":true,"img":false}]}
{"op":"mcm","clk":"11550381491","pt":1719497746733,"mc":[{"id":"1.230178169","rc":[{"atb":[[18,6]],"id":52385904}],"con":true,"img":false}]}
{"op":"mcm","clk":"11550381712","pt":1719497749419,"mc":[{"id":"1.230178169","rc":[{"atb":[[15.5,26]],"id":52385891}],"con":true,"img":false}]}
{"op":"mcm","clk":"11550381724","pt":1719497749518,"mc":[{"id":"1.230178169","rc":[{"atb":[[13.5,3.91]],"id":52385891}],"con":true,"img":false}]}
{"op":"mcm","clk":"11550381772","pt":1719497750042,"mc":[{"id":"1.230178169","rc":[{"atb":[[11,0]],"id":52385893}],"con":true,"img":false}]}
{"op":"mcm","clk":"11550381781","pt":1719497750137,"mc":[{"id":"1.230178169","rc":[{"atb":[[10,9]],"id":52385893}],"con":true,"img":false}]}
{"op":"mcm","clk":"11550382402","pt":1719497757321,"mc":[{"id":"1.230178169","rc":[{"atl":[[42,17.63]],"id":52385910},{"atl":[[26,24]],"id":52385918},{"atl":[[46,15.53]],"id":52385920},{"atl":[[30,23.99]],"id":52385914},{"atl":[[65,10.27]],"id":52385885},{"atl":[[80,7.59]],"id":52385896},{"atl":[[26,24]],"id":52385892},{"atl":[[34,11.45]],"id":52385921},{"atl":[[38,18.92]],"id":52385917}],"con":true,"img":false}]}
{"op":"mcm","clk":"11550382417","pt":1719497757525,"mc":[{"id":"1.230178169","rc":[{"atl":[[46,0]],"id":52385910},{"atl":[[30,0]],"id":52385918},{"atl":[[55,0]],"id":52385920},{"atl":[[36,0]],"id":52385914},{"atl":[[80,0]],"id":52385885},{"atl":[[95,0]],"id":52385896},{"atl":[[29,0]],"id":52385892},{"atl":[[46,0]],"id":52385921},{"atl":[[42,0]],"id":52385917}],"con":true,"img":false}]}
{"op":"mcm","clk":"11550382666","pt":1719497760623,"mc":[{"id":"1.230178169","rc":[{"atb":[[1.31,100]],"id":52385906},{"atb":[[1.31,100]],"id":52385889},{"atb":[[1.31,100]],"id":52385883},{"atb":[[1.31,100]],"id":52385885},{"atb":[[1.31,100]],"id":52385896},{"atb":[[1.31,100]],"id":52385890},{"atb":[[1.31,100]],"id":52385892},{"atb":[[1.31,100]],"id":52385904},{"atb":[[1.31,100]],"id":52385898},{"atb":[[1.31,100]],"id":52385900},{"atb":[[1.31,100]],"id":52385907},{"atb":[[1.31,100]],"id":52385882},{"atb":[[1.31,100]],"id":52385884},{"atb":[[1.31,100]],"id":52385897},{"atb":[[1.31,100]],"id":52385891},{"atb":[[1.31,100]],"id":52385893},{"atb":[[1.31,100]],"id":52385903},{"atb":[[1.31,100]],"id":52385905},{"atb":[[1.31,100]],"id":52385899}],"con":true,"img":false}]}
{"op":"mcm","clk":"11550382684","pt":1719497760830,"mc":[{"id":"1.230178169","rc":[{"atb":[[1.31,100]],"id":52385910},{"atb":[[1.31,100]],"id":52385912},{"atb":[[1.31,100]],"id":52385918},{"atb":[[1.31,100]],"id":52385920},{"atb":[[1.31,100]],"id":52385914},{"atb":[[1.31,100]],"id":52385913},{"atb":[[1.31,100]],"id":52385919},{"atb":[[1.31,100]],"id":52385921},{"atb":[[1.31,100]],"id":52385917}],"con":true,"img":false}]}
{"op":"mcm","clk":"11550382696","pt":1719497760936,"mc":[{"id":"1.230178169","rc":[{"atb":[[1.31,100]],"id":52385886}],"con":true,"img":false}]}
{"op":"mcm","clk":"11550382706","pt":1719497761039,"mc":[{"id":"1.230178169","rc":[{"atb":[[1.31,100]],"id":52385911},{"atb":[[10,0]],"id":52385893}],"con":true,"img":false}]}
{"op":"mcm","clk":"11550382717","pt":1719497761141,"mc":[{"id":"1.230178169","rc":[{"atb":[[11,9]],"id":52385893}],"con":true,"img":false}]}
{"op":"mcm","clk":"11550382824","pt":1719497762333,"mc":[{"id":"1.230178169","rc":[{"atb":[[16,7.07]],"id":52385920}],"con":true,"img":false}]}
{"op":"mcm","clk":"11550382831","pt":1719497762437,"mc":[{"id":"1.230178169","rc":[{"atb":[[13.5,0],[15.5,0]],"id":52385920}],"con":true,"img":false}]}
{"op":"mcm","clk":"11550382847","pt":1719497762647,"mc":[{"id":"1.230178169","rc":[{"atl":[[38,0],[29,2.5],[30,0]],"id":52385889},{"atb":[[18.5,29.6]],"id":52385914},{"atl":[[36,2.5],[38,0],[44,5],[46,0]],"id":52385914},{"atl":[[34,0]],"id":52385904},{"atb":[[12,0],[14,0],[14.5,6.5]],"id":52385913},{"atl":[[24,0]],"id":52385891},{"atl":[[23,2.5],[24,0],[27,5],[28,0]],"id":52385893}],"con":true,"img":false}]}
{"op":"mcm","clk":"11550382857","pt":1719497762748,"mc":[{"id":"1.230178169","rc":[{"atb":[[16,0]],"id":52385914},{"atl":[[36,17.14]],"id":52385904},{"atl":[[25,25]],"id":52385891},{"atl":[[18,0]],"id":52385893}],"con":true,"img":false}]}
{"op":"mcm","clk":"11550382869","pt":1719497762851,"mc":[{"id":"1.230178169","rc":[{"atl":[[17.5,22]],"id":52385893}],"con":true,"img":false}]}
{"op":"mcm","clk":"11550382879","pt":1719497762956,"mc":[{"id":"1.230178169","rc":[{"atb":[[13.5,0],[14,5],[15.5,0],[16,2.5]],"id":52385910},{"atb":[[7.4,0],[7.6,2.5],[6.6,0]],"id":52385918},{"atb":[[11.5,0],[13.5,0],[14,2.5]],"id":52385885},{"atl":[[150,0],[90,2.5],[110,0],[120,5]],"id":52385896},{"atl":[[38,2.5],[44,3],[46,5],[55,0]],"id":52385890},{"atb":[[8,2.5],[7.2,5],[7.8,0],[7,0]],"id":52385892},{"atl":[[36,0]],"id":52385904},{"atl":[[75,2.5],[85,2],[95,5],[110,0]],"id":52385900},{"atb":[[12.5,0],[14.5,0],[15,2.5]],"id":52385886},{"atb":[[10,0],[10.5,5],[12,0],[12.5,2.5]],"id":52385917},{"atl":[[75,2.2],[80,5],[95,0],[60,2.5]],"id":52385897}],"con":true,"img":false}]}
{"op":"mcm","clk":"11550382890","pt":1719497763060,"mc":[{"id":"1.230178169","rc":[{"atb":[[32,0]],"id":52385912},{"atb":[[11,0]],"id":52385914},{"atb":[[40,0]],"id":52385883},{"atb":[[42,0]],"id":52385896},{"atl":[[40,0]],"id":52385890},{"atb":[[46,0]],"id":52385898},{"atb":[[34,0]],"id":52385900},{"atl":[[75,10.61]],"id":52385900},{"atb":[[10,0],[9.2,0],[11,2.5],[9.6,5]],"id":52385911},{"atl":[[50,0]],"id":52385907},{"atb":[[30,0]],"id":52385919},{"atb":[[9.2,0],[12,10.5]],"id":52385921},{"atl":[[29,2]],"id":52385882},{"atb":[[27,2.54]],"id":52385897},{"atl":[[25,0]],"id":52385891},{"atl":[[17.5,0]],"id":52385893},{"atl":[[80,0],[90,2.5],[55,0],[60,0],[120,7]],"id":52385903},{"atl":[[80,2.5],[90,0],[100,5],[120,0]],"id":52385905},{"atb":[[36,0],[26,0],[30,0]],"id":52385899}],"con":true,"img":false}]}
{"op":"mcm","clk":"11550382901","pt":1719497763112,"mc":[{"id":"1.230178169","rc":[{"atb":[[24,20.2]],"id":52385912},{"atb":[[26,24]],"id":52385883},{"atb":[[30,13]],"id":52385896},{"atl":[[38,18.72]],"id":52385890},{"atl":[[44,13.95]],"id":52385904},{"atb":[[25,20]],"id":52385898},{"atb":[[22,20.8]],"id":52385900},{"atl":[[80,0]],"id":52385900},{"atl":[[55,13.61]],"id":52385907},{"atb":[[22,20]],"id":52385919},{"atl":[[65,9.38]],"id":52385897},{"atl":[[30,20.69]],"id":52385891},{"atl":[[22,22]],"id":52385893},{"atl":[[110,5.5]],"id":52385903},{"atl":[[80,10.09]],"id":52385905}],"con":true,"img":false}]}
{"op":"mcm","clk":"11550382912","pt":1719497763214,"mc":[{"id":"1.230178169","rc":[{"atl":[[85,0]],"id":52385905},{"atb":[[11,5],[13,2.5]],"id":52385899}],"con":true,"img":false}]}
{"op":"mcm","clk":"11550382921","pt":1719497763316,"mc":[{"id":"1.230178169","rc":[{"atl":[[70,0]],"id":52385897}],"con":true,"img":false}]}
{"op":"mcm","clk":"11550382928","pt":1719497763420,"mc":[{"id":"1.230178169","rc":[{"atl":[[29,17]],"id":52385882},{"atb":[[27,17.62]],"id":52385897},{"atl":[[75,2.5],[95,5]],"id":52385903},{"atb":[[36,15]],"id":52385899}],"con":true,"img":false}]}
{"op":"mcm","clk":"11550382939","pt":1719497763523,"mc":[{"id":"1.230178169","rc":[{"atl":[[90,0],[120,2]],"id":52385903}],"con":true,"img":false}]}
{"op":"mcm","clk":"11550382965","pt":1719497763832,"mc":[{"id":"1.230178169","rc":[{"atl":[[29,2]],"id":52385882},{"atb":[[27,2.54]],"id":52385897}],"con":true,"img":false}]}
{"op":"mcm","clk":"11550382976","pt":1719497763934,"mc":[{"id":"1.230178169","rc":[{"atl":[[28,22.22]],"id":52385911},{"atl":[[29,21.96]],"id":52385882},{"atb":[[26,15.08]],"id":52385897},{"atb":[[36,0]],"id":52385899}],"con":true,"img":false}]}
{"op":"mcm","clk":"11550382997","pt":1719497764141,"mc":[{"id":"1.230178169","rc":[{"atl":[[34,0],[28,0]],"id":52385911},{"atl":[[29,2]],"id":52385882},{"atb":[[26,0]],"id":52385897}],"con":true,"img":false}]}
{"op":"mcm","clk":"11550383012","pt":1719497764250,"mc":[{"id":"1.230178169","rc":[{"atl":[[32,19.35]],"id":52385911}],"con":true,"img":false}]}
{"op":"mcm","clk":"11550383037","pt":1719497764557,"mc":[{"id":"1.230178169","rc":[{"atl":[[32,0]],"id":52385911}],"con":true,"img":false}]}
{"op":"mcm","clk":"11550383050","pt":1719497764658,"mc":[{"id":"1.230178169","rc":[{"atl":[[34,18.18]],"id":52385911}],"con":true,"img":false}]}
{"op":"mcm","clk":"11550383091","pt":1719497765024,"mc":[{"id":"1.230178169","rc":[{"atb":[[18,2.5]],"id":52385897}],"con":true,"img":false}]}
{"op":"mcm","clk":"11550383116","pt":1719497765227,"mc":[{"id":"1.230178169","rc":[{"atb":[[24,0]],"id":52385898}],"con":true,"img":false}]}
{"op":"mcm","clk":"11550383135","pt":1719497765432,"mc":[{"id":"1.230178169","rc":[{"atb":[[25,0]],"id":52385898}],"con":true,"img":false}]}
{"op":"mcm","clk":"11550383145","pt":1719497765545,"mc":[{"id":"1.230178169","rc":[{"atb":[[24,18.4]],"id":52385898},{"atb":[[20,0]],"id":52385900}],"con":true,"img":false}]}
{"op":"mcm","clk":"11550383175","pt":1719497765848,"mc":[{"id":"1.230178169","rc":[{"atb":[[20,0]],"id":52385919}],"con":true,"img":false}]}
{"op":"mcm","clk":"11550383199","pt":1719497766053,"mc":[{"id":"1.230178169","rc":[{"atb":[[12,0]],"id":52385918},{"atb":[[17,0]],"id":52385920},{"atl":[[32,0],[38,2.7]],"id":52385889},{"atl":[[290,2],[230,0]],"id":52385883},{"atl":[[280,2],[220,0]],"id":52385896},{"atb":[[15,0]],"id":52385890},{"atb":[[18,0]],"id":52385904},{"atl":[[300,0],[380,2]],"id":52385898},{"atb":[[16,0]],"id":52385913},{"atl":[[85,0],[110,2]],"id":52385907},{"atb":[[12,2.5]],"id":52385921},{"atb":[[20,0]],"id":52385884},{"atb":[[13,0]],"id":52385891},{"atl":[[300,0],[380,2]],"id":52385899}],"con":true,"img":false}]}
{"op":"mcm","clk":"11550383210","pt":1719497766155,"mc":[{"id":"1.230178169","rc":[{"atb":[[13,8]],"id":52385918},{"atb":[[20,6]],"id":52385920},{"atb":[[12,6]],"id":52385890},{"atb":[[20,6]],"id":52385904},{"atb":[[19,6]],"id":52385913},{"atb":[[13,8]],"id":52385921},{"atb":[[24,5]],"id":52385884},{"atb":[[14,8]],"id":52385891}],"con":true,"img":false}]}
{"op":"mcm","clk":"11550383219","pt":1719497766258,"mc":[{"id":"1.230178169","rc":[{"atl":[[29,17]],"id":52385882},{"atb":[[27,12.62]],"id":52385897},{"atb":[[36,15]],"id":52385899}],"con":true,"img":false}]}
{"op":"mcm","clk":"11550383389","pt":1719497767917,"mc":[{"id":"1.230178169","rc":[{"atb":[[15.5,0]],"id":52385891}],"con":true,"img":false}]}
{"op":"mcm","clk":"11550383398","pt":1719497768021,"mc":[{"id":"1.230178169","rc":[{"atb":[[15,26]],"id":52385891}],"con":true,"img":false}]}
{"op":"mcm","clk":"11550383454","pt":1719497768538,"mc":[{"id":"1.230178169","rc":[{"atb":[[21,0]],"id":52385912},{"atl":[[80,2.5]],"id":52385912},{"atb":[[23,0]],"id":52385906},{"atl":[[27,0]],"id":52385918},{"atl":[[25,0]],"id":52385889},{"atb":[[12,0]],"id":52385914},{"atb":[[21,5]],"id":52385883},{"atb":[[26,0]],"id":52385896},{"atl":[[85,0]],"id":52385896},{"atl":[[44,0]],"id":52385890},{"atl":[[27,0]],"id":52385892},{"atb":[[18.5,16.76]],"id":52385904},{"atb":[[21,0]],"id":52385898},{"atb":[[21,2.5]],"id":52385900},{"atl":[[85,0]],"id":52385900},{"atl":[[36,2.5]],"id":52385911},{"atl":[[65,2.5]],"id":52385913},{"atl":[[50,0]],"id":52385886},{"atb":[[21,0]],"id":52385919},{"atb":[[10.5,0]],"id":52385921},{"atb":[[13.5,0]],"id":52385891},{"atb":[[34,0]],"id":52385899}],"con":true,"img":false}]}
{"op":"mcm","clk":"11550383466","pt":1719497768643,"mc":[{"id":"1.230178169","rc":[{"atl":[[26,0]],"id":52385918},{"atl":[[80,0]],"id":52385896},{"atl":[[26,0]],"id":52385892},{"atb":[[16,0],[5.2,23.81]],"id":52385898},{"atl":[[48,0]],"id":52385886},{"atb":[[36,0]],"id":52385899}],"con":true,"img":false}]}
{"op":"mcm","clk":"11550383480","pt":1719497768745,"mc":[{"id":"1.230178169","rc":[{"atb":[[25,3]],"id":52385912},{"atl":[[70,2.6]],"id":52385912},{"atb":[[24,0],[25,2.42]],"id":52385906},{"atl":[[25,4],[27,23.08]],"id":52385918},{"atl":[[23,4]],"id":52385889},{"atb":[[10,6.12]],"id":52385914},{"atb":[[27,3]],"id":52385883},{"atb":[[32,2.97]],"id":52385896},{"atl":[[75,2.1],[85,7.14]],"id":52385896},{"atl":[[46,7.5]],"id":52385890},{"atl":[[32,5.6],[27,23.08]],"id":52385892},{"atb":[[21,2.7]],"id":52385904},{"atb":[[25,3.2]],"id":52385898},{"atb":[[23,3]],"id":52385900},{"atl":[[95,7]],"id":52385900},{"atl":[[32,3.1]],"id":52385911},{"atl":[[55,2.29]],"id":52385913},{"atl":[[75,7]],"id":52385907},{"atl":[[46,3],[50,12.24]],"id":52385886},{"atb":[[23,3]],"id":52385919},{"atb":[[16,3.81]],"id":52385891},{"atl":[[75,5]],"id":52385903},{"atb":[[32,19.35],[38,3.2],[13,10.83],[14.5,0]],"id":52385899}],"con":true,"img":false}]}
{"op":"mcm","clk":"11550383495","pt":1719497768849,"mc":[{"id":"1.230178169","rc":[{"atb":[[25,0]],"id":52385910},{"atl":[[65,5],[70,0],[48,2.5],[50,0]],"id":52385910},{"atl":[[75,10.61],[80,0],[95,5],[100,0]],"id":52385912},{"atb":[[23,20]],"id":52385906},{"atl":[[80,2],[60,0]],"id":52385918},{"atb":[[5.1,24.39],[5.5,0],[5.3,5],[5.7,2.5]],"id":52385889},{"atl":[[22,28.57]],"id":52385889},{"atb":[[18.5,0]],"id":52385914},{"atl":[[85,2.5],[90,0],[110,5],[120,0]],"id":52385885},{"atb":[[10,0],[12.5,8.7]],"id":52385896},{"atl":[[65,0],[85,2]],"id":52385890},{"atl":[[32,3.1],[38,5],[40,0],[30,2.5]],"id":52385892},{"atb":[[9,0],[10,2.5],[9.2,5],[9.8,0]],"id":52385904},{"atl":[[75,0],[95,2]],"id":52385904},{"atb":[[16.5,6.45],[5.2,0]],"id":52385898},{"atl":[[180,0],[240,2]],"id":52385900},{"atl":[[65,0],[80,5],[85,0],[50,12.24],[60,12.67]],"id":52385913},{"atb":[[10.5,0],[11,5],[12.5,0],[13,2.5]],"id":52385907},{"atl":[[160,2],[120,0]],"id":52385886},{"atl":[[65,0],[46,2.5],[48,0],[60,5]],"id":52385921},{"atl":[[280,2],[210,0]],"id":52385884},{"atb":[[24,22]],"id":52385917},{"atl":[[130,0],[170,2]],"id":52385897},{"atb":[[9,0],[9.2,2.5],[8.2,0],[8.4,5]],"id":52385891},{"atb":[[5.8,2.5],[5.3,0],[5.7,0],[5.4,5]],"id":52385893},{"atl":[[32,0],[40,2.56]],"id":52385893},{"atb":[[13,0],[13.5,5],[15,0],[15.5,2.5]],"id":52385903},{"atl":[[150,2],[120,0]],"id":52385903},{"atb":[[21,0],[22,5],[25,0],[26,2.5]],"id":52385905},{"atb":[[13,2.5]],"id":52385899}],"con":true,"img":false}]}
{"op":"mcm","clk":"11550383505","pt":1719497768950,"mc":[{"id":"1.230178169","rc":[{"atl":[[65,9.38]],"id":52385912},{"atl":[[27,0]],"id":52385892},{"atb":[[11,14.91]],"id":52385899}],"con":true,"img":false}]}
{"op":"mcm","clk":"11550383515","pt":1719497769063,"mc":[{"id":"1.230178169","rc":[{"atb":[[24,10]],"id":52385910},{"atl":[[24,0]],"id":52385889},{"atb":[[9.8,15]],"id":52385914},{"atb":[[17,27]],"id":52385890},{"atl":[[28,22.22]],"id":52385892},{"atl":[[60,2.5]],"id":52385913},{"atb":[[16.5,0]],"id":52385917},{"atb":[[19,5],[11,5],[15.5,6.9]],"id":52385899}],"con":true,"img":false}]}
{"op":"mcm","clk":"11550383524","pt":1719497769167,"mc":[{"id":"1.230178169","rc":[{"atl":[[75,2.5]],"id":52385912}],"con":true,"img":false}]}
{"op":"mcm","clk":"11550383535","pt":1719497769271,"mc":[{"id":"1.230178169","rc":[{"atb":[[24,0]],"id":52385910},{"atb":[[15.5,3.7]],"id":52385890}],"con":true,"img":false}]}
{"op":"mcm","clk":"11550383546","pt":1719497769367,"mc":[{"id":"1.230178169","rc":[{"atb":[[22,19.22]],"id":52385910}],"con":true,"img":false}]}
{"op":"mcm","clk":"11550383588","pt":1719497769834,"mc":[{"id":"1.230178169","rc":[{"atb":[[15,3.94]],"id":52385890}],"con":true,"img":false}]}
{"op":"mcm","clk":"11550383604","pt":1719497770047,"mc":[{"id":"1.230178169","rc":[{"atb":[[11,9]],"id":52385914}],"con":true,"img":false}]}
{"op":"mcm","clk":"11550383620","pt":1719497770143,"mc":[{"id":"1.230178169","rc":[{"atb":[[15,0]],"id":52385890}],"con":true,"img":false}]}
{"op":"mcm","clk":"11550383717","pt":1719497771231,"mc":[{"id":"1.230178169","rc":[{"atb":[[6.8,17.24],[9.8,0]],"id":52385906},{"atb":[[9,0],[10,11.11]],"id":52385920},{"atb":[[17,0]],"id":52385890},{"atb":[[21,24.7],[5.2,23.81],[6.6,0]],"id":52385904},{"atb":[[9.6,0],[8.4,13.51]],"id":52385913},{"atb":[[5.8,20.83],[7.4,0],[24,24]],"id":52385907},{"atb":[[12.5,8.7]],"id":52385884},{"atb":[[24,0]],"id":52385917},{"atb":[[6.4,16],[5.7,0]],"id":52385891},{"atb":[[9.6,0],[6.6,17.86]],"id":52385903},{"atb":[[11.5,0],[6.8,17.24]],"id":52385905},{"atl":[[280,2],[190,0]],"id":52385905},{"atl":[[150,5],[160,0],[110,2.5],[120,0]],"id":52385899}],"con":true,"img":false}]}
{"op":"mcm","clk":"11550383729","pt":1719497771329,"mc":[{"id":"1.230178169","rc":[{"atb":[[15.5,30.7]],"id":52385890},{"atb":[[18.5,0]],"id":52385904},{"atb":[[8.6,13.16]],"id":52385907},{"atb":[[10,0]],"id":52385884},{"atb":[[16.5,22]],"id":52385917},{"atb":[[12,9.09]],"id":52385905}],"con":true,"img":false}]}
{"op":"mcm","clk":"11550383736","pt":1719497771432,"mc":[{"id":"1.230178169","rc":[{"atb":[[5.8,0],[21,3],[24,0]],"id":52385907},{"atb":[[6.8,0]],"id":52385905}],"con":true,"img":false}]}
{"op":"mcm","clk":"11550383748","pt":1719497771537,"mc":[{"id":"1.230178169","rc":[{"atb":[[20,21]],"id":52385907}],"con":true,"img":false}]}
{"op":"mcm","clk":"11550383826","pt":1719497772571,"mc":[{"id":"1.230178169","rc":[{"atl":[[25,29]],"id":52385918},{"atl":[[75,10.21]],"id":52385896},{"atl":[[22,26.2]],"id":52385892}],"con":true,"img":false}]}
{"op":"mcm","clk":"11550383846","pt":1719497772727,"mc":[{"id":"1.230178169","rc":[{"atb":[[6,2]],"id":52385910},{"atb":[[6,2]],"id":52385912},{"atb":[[6,2]],"id":52385906},{"atb":[[6,2]],"id":52385918},{"atl":[[27,0]],"id":52385918},{"atb":[[6,2]],"id":52385920},{"atb":[[6,2]],"id":52385889},{"atb":[[6,2]],"id":52385914},{"atb":[[6,2]],"id":52385883},{"atb":[[6,2]],"id":52385885},{"atb":[[6,2]],"id":52385896},{"atl":[[85,0]],"id":52385896},{"atb":[[6,20]],"id":52385890},{"atb":[[6,2]],"id":52385892},{"atl":[[28,0]],"id":52385892},{"atb":[[6,2]],"id":52385904},{"atb":[[6,2]],"id":52385898},{"atb":[[6,2]],"id":52385900},{"atb":[[6,2]],"id":52385911},{"atb":[[6,2]],"id":52385913},{"atb":[[6,2]],"id":52385907},{"atb":[[6,2]],"id":52385886},{"atb":[[6,2]],"id":52385919},{"atb":[[6,2]],"id":52385921},{"atb":[[6,2]],"id":52385882},{"atb":[[6,2]],"id":52385884},{"atb":[[6,2]],"id":52385917},{"atb":[[6,2]],"id":52385897},{"atb":[[6,2]],"id":52385891},{"atb":[[6,2]],"id":52385893},{"atb":[[6,2]],"id":52385903},{"atb":[[6,2]],"id":52385905},{"atb":[[6,2]],"id":52385899}],"con":true,"img":false}]}
{"op":"mcm","clk":"11550384149","pt":1719497775932,"mc":[{"id":"1.230178169","rc":[{"atb":[[16.5,0],[17.5,6.06]],"id":52385898}],"con":true,"img":false}]}
{"op":"mcm","clk":"11550384307","pt":1719497777742,"mc":[{"id":"1.230178169","rc":[{"atb":[[11.5,30.24]],"id":52385914}],"con":true,"img":false}]}
{"op":"mcm","clk":"11550384320","pt":1719497777850,"mc":[{"id":"1.230178169","rc":[{"atb":[[9.8,0]],"id":52385914},{"atl":[[36,17.14]],"id":52385904},{"atl":[[26,24]],"id":52385891},{"atl":[[18.5,22]],"id":52385893}],"con":true,"img":false}]}
{"op":"mcm","clk":"11550384337","pt":1719497778055,"mc":[{"id":"1.230178169","rc":[{"atl":[[44,0]],"id":52385904},{"atl":[[30,0]],"id":52385891},{"atl":[[22,0]],"id":52385893}],"con":true,"img":false}]}
{"op":"mcm","clk":"11550384354","pt":1719497778264,"mc":[{"id":"1.230178169","rc":[{"atb":[[26,11.2]],"id":52385912},{"atb":[[10.5,7.5],[6.8,0]],"id":52385906},{"atl":[[29,21.43]],"id":52385914},{"atb":[[34,16]],"id":52385883},{"atb":[[34,15.94]],"id":52385896},{"atb":[[7.6,11],[5.2,0]],"id":52385904},{"atb":[[32,19.35]],"id":52385898},{"atb":[[26,20]],"id":52385900},{"atb":[[10,11.11],[8.4,0]],"id":52385913},{"atb":[[25,16]],"id":52385919},{"atl":[[55,11.11]],"id":52385897},{"atb":[[10,10],[6.6,0]],"id":52385903},{"atl":[[70,8.7]],"id":52385903}],"con":true,"img":false}]}
{"op":"mcm","clk":"11550384370","pt":1719497778466,"mc":[{"id":"1.230178169","rc":[{"atb":[[24,0]],"id":52385912},{"atl":[[30,3.3]],"id":52385914},{"atb":[[26,0]],"id":52385883},{"atb":[[30,0]],"id":52385896},{"atb":[[24,0]],"id":52385898},{"atb":[[22,0]],"id":52385900},{"atb":[[22,0]],"id":52385919},{"atl":[[65,0]],"id":52385897},{"atl":[[110,0]],"id":52385903},{"atb":[[38,19.42]],"id":52385899}],"con":true,"img":false}]}
{"op":"mcm","clk":"11550384388","pt":1719497778673,"mc":[{"id":"1.230178169","rc":[{"atb":[[32,0]],"id":52385899}],"con":true,"img":false}]}
{"op":"mcm","clk":"11550384406","pt":1719497778930,"mc":[{"id":"1.230178169","rc":[{"atl":[[26,22.2]],"id":52385911}],"con":true,"img":false}]}
{"op":"mcm","clk":"11550384424","pt":1719497779136,"mc":[{"id":"1.230178169","rc":[{"atb":[[6.2,10]],"id":52385910},{"atb":[[10.5,0],[7,10]],"id":52385912},{"atl":[[150,0],[210,2]],"id":52385906},{"atb":[[6.4,0],[4.7,27.03]],"id":52385914},{"atl":[[22,0]],"id":52385892},{"atb":[[21,2.7]],"id":52385904},{"atb":[[4.6,27.78],[6.2,0]],"id":52385911},{"atl":[[34,0],[26,0]],"id":52385911},{"atb":[[10,0],[6.8,17.24]],"id":52385913},{"atb":[[7.4,15.62],[8.8,0]],"id":52385921},{"atb":[[12.5,8.7]],"id":52385899}],"con":true,"img":false}]}
{"op":"mcm","clk":"11550384430","pt":1719497779246,"mc":[{"id":"1.230178169","rc":[{"atb":[[9,10],[9.2,0],[6.2,0]],"id":52385910},{"atb":[[11,8]],"id":52385912},{"atb":[[6.6,12.24]],"id":52385914},{"atb":[[25,0],[26,22]],"id":52385885},{"atl":[[29,21.43]],"id":52385892},{"atb":[[4.6,0],[6.6,13]],"id":52385911},{"atl":[[30,20.69]],"id":52385911},{"atb":[[10.5,10.53],[24,0],[6.8,0],[25,25]],"id":52385913},{"atb":[[7.4,0],[8.6,13.16],[20,26]],"id":52385921},{"atb":[[15.5,0]],"id":52385899}],"con":true,"img":false}]}
{"op":"mcm","clk":"11550384439","pt":1719497779345,"mc":[{"id":"1.230178169","rc":[{"atb":[[7,0]],"id":52385912},{"atb":[[4.7,0]],"id":52385914},{"atb":[[16.5,0]],"id":52385921},{"atb":[[12.5,0],[15.5,6.9]],"id":52385899}],"con":true,"img":false}]}
{"op":"mcm","clk":"11550384535","pt":1719497780535,"mc":[{"id":"1.230178169","rc":[{"atb":[[34,16.4]],"id":52385898}],"con":true,"img":false}]}
{"op":"mcm","clk":"11550384553","pt":1719497780746,"mc":[{"id":"1.230178169","rc":[{"atb":[[32,0]],"id":52385898}],"con":true,"img":false}]}
{"op":"mcm","clk":"11550384582","pt":1719497781051,"mc":[{"id":"1.230178169","rc":[{"atb":[[10,0],[8.4,13.51]],"id":52385920},{"atb":[[21,18.1]],"id":52385904},{"atb":[[8.6,0],[7.4,10]],"id":52385907},{"atb":[[8.2,12]],"id":52385886},{"atb":[[12.5,0],[9.8,10]],"id":52385884},{"atb":[[8.4,0],[7,12]],"id":52385917},{"atb":[[6.4,0],[14,0],[5.5,22.22]],"id":52385891},{"atb":[[5.1,0],[4.5,28.57]],"id":52385893},{"atb":[[8.6,10]],"id":52385903}],"con":true,"img":false}]}
{"op":"mcm","clk":"11550384588","pt":1719497781152,"mc":[{"id":"1.230178169","rc":[{"atb":[[9.8,0]],"id":52385886},{"atb":[[10,0]],"id":52385903},{"atl":[[330,2],[380,0]],"id":52385899}],"con":true,"img":false}]}
{"op":"mcm","clk":"11550384605","pt":1719497781360,"mc":[{"id":"1.230178169","rc":[{"atb":[[20,0]],"id":52385920},{"atb":[[11,0]],"id":52385914},{"atb":[[12,0]],"id":52385890},{"atb":[[20,0]],"id":52385904},{"atb":[[13,0]],"id":52385911},{"atb":[[19,0]],"id":52385913},{"atb":[[24,0]],"id":52385884}],"con":true,"img":false}]}
{"op":"mcm","clk":"11550384614","pt":1719497781462,"mc":[{"id":"1.230178169","rc":[{"atb":[[22,0]],"id":52385910},{"atb":[[18,6]],"id":52385920},{"atb":[[12,9]],"id":52385914},{"atb":[[13,6]],"id":52385890},{"atb":[[17,6]],"id":52385904},{"atb":[[14,8]],"id":52385911},{"atl":[[26,16.2]],"id":52385911},{"atb":[[17,6]],"id":52385913},{"atb":[[20,5]],"id":52385884}],"con":true,"img":false}]}
{"op":"mcm","clk":"11550384622","pt":1719497781563,"mc":[{"id":"1.230178169","rc":[{"atb":[[16.5,19.22]],"id":52385910},{"atl":[[30,0]],"id":52385911}],"con":true,"img":false}]}
{"op":"mcm","clk":"11550384749","pt":1719497783059,"mc":[{"id":"1.230178169","rc":[{"atb":[[17,17.62]],"id":52385891}],"con":true,"img":false}]}
{"op":"mcm","clk":"11550384768","pt":1719497783264,"mc":[{"id":"1.230178169","rc":[{"atb":[[15,0]],"id":52385891}],"con":true,"img":false}]}
{"op":"mcm","clk":"11550384809","pt":1719497783781,"mc":[{"id":"1.230178169","rc":[{"atl":[[46,16.33]],"id":52385886}],"con":true,"img":false}]}
{"op":"mcm","clk":"11550384818","pt":1719497783835,"mc":[{"id":"1.230178169","rc":[{"atb":[[26,20]],"id":52385906},{"atb":[[24,22]],"id":52385917}],"con":true,"img":false}]}
{"op":"mcm","clk":"11550384825","pt":1719497783937,"mc":[{"id":"1.230178169","rc":[{"atl":[[50,0]],"id":52385886}],"con":true,"img":false}]}
{"op":"mcm","clk":"11550384833","pt":1719497784042,"mc":[{"id":"1.230178169","rc":[{"atb":[[23,0]],"id":52385906},{"atb":[[16.5,30.24]],"id":52385914},{"atb":[[16.5,0]],"id":52385917}],"con":true,"img":false}]}
{"op":"mcm","clk":"11550384850","pt":1719497784252,"mc":[{"id":"1.230178169","rc":[{"atb":[[11.5,0]],"id":52385914}],"con":true,"img":false}]}
{"op":"mcm","clk":"11550384901","pt":1719497784903,"mc":[{"id":"1.230178169","rc":[{"atb":[[9,0],[6.8,10],[25,19.22]],"id":52385910},{"atb":[[11,0],[7.8,10]],"id":52385912},{"atb":[[10.5,0],[5.5,22.22]],"id":52385906},{"atl":[[65,0],[80,2.5],[85,0],[100,5]],"id":52385906},{"atb":[[24,0]],"id":52385920},{"atb":[[5.2,23.81],[6.6,0]],"id":52385914},{"atl":[[85,2.5],[90,0],[110,5],[120,0]],"id":52385883},{"atl":[[280,0],[230,2]],"id":52385896},{"atb":[[6.4,12],[7.6,0]],"id":52385904},{"atl":[[200,2],[240,0]],"id":52385900},{"atb":[[5.1,24.39],[6.6,0]],"id":52385911},{"atb":[[10.5,0],[5.3,23.26]],"id":52385913},{"atl":[[140,0],[70,2.5],[80,0],[200,2],[60,0]],"id":52385913},{"atl":[[65,0],[80,5],[85,0],[60,2.5]],"id":52385919},{"atb":[[32,0]],"id":52385884},{"atb":[[24,0]],"id":52385917},{"atl":[[140,2],[170,0]],"id":52385897},{"atb":[[17,0]],"id":52385891},{"atl":[[150,0],[190,2]],"id":52385903},{"atb":[[9,12.5],[12,0]],"id":52385905},{"atl":[[80,7.59],[90,2.5],[100,0],[120,5]],"id":52385905},{"atb":[[12.5,8.7],[15.5,0]],"id":52385899}],"con":true,"img":false}]}
{"op":"mcm","clk":"11550384911","pt":1719497784977,"mc":[{"id":"1.230178169","rc":[{"atb":[[16.5,0]],"id":52385910},{"atb":[[11,8],[7.8,0]],"id":52385912},{"atb":[[11.5,7.5],[5.5,0]],"id":52385906},{"atb":[[23,26.14]],"id":52385920},{"atb":[[5.2,0],[6.6,12.24]],"id":52385914},{"atb":[[6.4,0],[8.2,11]],"id":52385904},{"atb":[[30,20]],"id":52385884},{"atb":[[13,22]],"id":52385917},{"atb":[[16.5,17.62]],"id":52385891},{"atb":[[9,0],[12.5,8.7]],"id":52385905}],"con":true,"img":false}]}
{"op":"mcm","clk":"11550384922","pt":1719497785088,"mc":[{"id":"1.230178169","rc":[{"atb":[[11.5,0],[7.6,10]],"id":52385906},{"atl":[[290,2],[80,0],[90,2.5],[100,0],[210,0],[60,0],[120,5]],"id":52385906},{"atb":[[4.9,25.64],[5.7,0]],"id":52385918},{"atb":[[23,0]],"id":52385920},{"atl":[[180,2],[120,0]],"id":52385920},{"atb":[[4.3,30.3],[10.5,30],[5.1,0]],"id":52385889},{"atb":[[9.6,0],[10,8.62],[8.8,0]],"id":52385914},{"atl":[[290,0],[230,2]],"id":52385883},{"atb":[[8.6,12],[12,0]],"id":52385885},{"atl":[[280,2],[210,0]],"id":52385885},{"atb":[[34,0],[25,0],[12.5,0],[29,0]],"id":52385896},{"atl":[[170,2],[230,0]],"id":52385896},{"atb":[[15.5,3.7]],"id":52385890},{"atl":[[65,2],[85,0],[24,26.09]],"id":52385890},{"atb":[[4.9,25.64],[5.7,0]],"id":52385892},{"atb":[[6.4,12],[8.2,0]],"id":52385904},{"atl":[[36,0]],"id":52385904},{"atb":[[17.5,0],[12.5,8.7]],"id":52385898},{"atl":[[130,5],[300,2],[160,0],[380,0],[95,2.5],[120,0]],"id":52385898},{"atb":[[9.2,10],[11.5,0]],"id":52385900},{"atl":[[150,2],[200,0]],"id":52385900},{"atl":[[26,0]],"id":52385911},{"atl":[[150,2],[110,0]],"id":52385907},{"atb":[[8.6,0],[7,16]],"id":52385921},{"atb":[[10,0],[5.8,20.83],[10.5,10],[12,0],[6.8,0],[12.5,2.5]],"id":52385882},{"atb":[[30,0]],"id":52385884},{"atl":[[280,0],[140,5],[85,0],[340,2],[100,2.5],[110,0]],"id":52385884},{"atb":[[16,0],[18,0],[10,5],[7.4,15.62],[12,2.5],[27,2.54],[9.4,0]],"id":52385897},{"atl":[[140,0],[110,2]],"id":52385897},{"atl":[[32,0],[36,2.5],[40,0],[44,5],[90,2],[26,0],[60,0]],"id":52385891},{"atb":[[7.6,13.7],[12.5,0]],"id":52385905},{"atl":[[80,0]],"id":52385905},{"atl":[[260,2],[330,0]],"id":52385899}],"con":true,"img":false}]}
{"op":"mcm","clk":"11550384929","pt":1719497785188,"mc":[{"id":"1.230178169","rc":[{"atb":[[7.6,0]],"id":52385906},{"atl":[[1000,0.6]],"id":52385906},{"atb":[[6,15],[4.9,0]],"id":52385918},{"atb":[[16.5,22]],"id":52385920},{"atb":[[4.3,0],[9.2,6.29],[10.5,0],[5.1,24.39]],"id":52385889},{"atb":[[8.6,0],[12,8.86]],"id":52385885},{"atb":[[17,5],[19,2.5],[1.32,10.94]],"id":52385896},{"atb":[[13,33]],"id":52385890},{"atl":[[38,2.5]],"id":52385890},{"atb":[[6,17],[4.9,0]],"id":52385892},{"atb":[[6.4,0],[9.2,17]],"id":52385904},{"atl":[[55,11.11]],"id":52385904},{"atl":[[90,6.74]],"id":52385898},{"atl":[[130,2],[150,0]],"id":52385900},{"atl":[[34,11.2]],"id":52385911},{"atb":[[8.8,10.5],[7,0]],"id":52385921},{"atb":[[7.2,16.13],[5.8,0]],"id":52385882},{"atb":[[27,13.4]],"id":52385884},{"atb":[[10.5,9.4]],"id":52385897},{"atl":[[1000,0.6]],"id":52385891},{"atb":[[12,9.09]],"id":52385905},{"atl":[[85,7.14]],"id":52385905},{"atl":[[260,0],[230,2]],"id":52385899}],"con":true,"img":false}]}
{"op":"mcm","clk":"11550384940","pt":1719497785241,"mc":[{"id":"1.230178169","rc":[{"atb":[[12.5,7.5]],"id":52385906},{"atb":[[9.2,26.9]],"id":52385889},{"atb":[[10,5.94]],"id":52385896},{"atb":[[7.6,0]],"id":52385905}],"con":true,"img":false}]}
{"op":"mcm","clk":"11550384949","pt":1719497785344,"mc":[{"id":"1.230178169","rc":[{"atl":[[110,0]],"id":52385898}],"con":true,"img":false}]}
{"op":"mcm","clk":"11550384959","pt":1719497785453,"mc":[{"id":"1.230178169","rc":[{"atl":[[70,8.7]],"id":52385900},{"atb":[[34,18.18]],"id":52385903},{"atl":[[90,6.74]],"id":52385899}],"con":true,"img":false}]}
{"op":"mcm","clk":"11550384974","pt":1719497785656,"mc":[{"id":"1.230178169","rc":[{"atl":[[75,2.5]],"id":52385900},{"atb":[[25,2.48]],"id":52385903},{"atl":[[100,2]],"id":52385899}],"con":true,"img":false}]}
{"op":"mcm","clk":"11550385008","pt":1719497786074,"mc":[{"id":"1.230178169","rc":[{"atb":[[25,0]],"id":52385910},{"atb":[[11,0],[7.8,10]],"id":52385912},{"atl":[[130,2],[180,0]],"id":52385912},{"atl":[[70,2.5],[120,0]],"id":52385906},{"atl":[[32,3.23],[38,0]],"id":52385889},{"atb":[[10.5,0],[2.08,92.59]],"id":52385883},{"atl":[[170,2],[230,0]],"id":52385883},{"atl":[[280,0],[210,2]],"id":52385885},{"atb":[[17,0],[10,0],[22,2.5]],"id":52385896},{"atl":[[130,2],[170,0]],"id":52385896},{"atb":[[6,2],[2.66,60.24]],"id":52385890},{"atl":[[65,0],[24,0],[48,2.13]],"id":52385890},{"atb":[[9.2,5],[7.8,14.71]],"id":52385904},{"atl":[[85,2]],"id":52385904},{"atb":[[16,6.67],[12.5,0]],"id":52385898},{"atl":[[130,0],[300,0],[160,5],[95,0],[120,2.5],[240,2]],"id":52385898},{"atb":[[9.2,0]],"id":52385900},{"atl":[[130,0],[110,2]],"id":52385900},{"atl":[[140,2],[200,0]],"id":52385913},{"atl":[[150,0],[110,2]],"id":52385907},{"atl":[[160,0],[120,2]],"id":52385886},{"atb":[[10,0],[3.2,45.45]],"id":52385919},{"atl":[[150,0],[110,2]],"id":52385919},{"atl":[[130,5],[270,2],[140,0],[340,0],[95,2.5],[100,0]],"id":52385884},{"atb":[[10,0],[7.4,0],[11.5,5],[12,0],[13.5,2.5]],"id":52385897},{"atl":[[80,7],[110,0]],"id":52385897},{"atl":[[34,2.5],[36,0],[42,5],[44,0]],"id":52385891},{"atl":[[32,3.23],[40,0]],"id":52385893},{"atb":[[34,0]],"id":52385903},{"atl":[[150,2],[190,0]],"id":52385903},{"atl":[[280,0],[220,2]],"id":52385905},{"atb":[[12.5,0]],"id":52385899},{"atl":[[190,2],[230,0]],"id":52385899}],"con":true,"img":false}]}
{"op":"mcm","clk":"11550385017","pt":1719497786182,"mc":[{"id":"1.230178169","rc":[{"atb":[[6.8,0],[15,15],[8.6,9.61]],"id":52385910},{"atl":[[290,0],[160,2]],"id":52385906},{"atl":[[130,2],[180,0]],"id":52385920},{"atb":[[12,8],[2.08,0]],"id":52385883},{"atb":[[11.5,5.94]],"id":52385896},{"atl":[[130,0],[200,2]],"id":52385896},{"atb":[[6.2,19.23],[2.66,0]],"id":52385890},{"atl":[[65,2],[44,13.95],[48,0]],"id":52385890},{"atl":[[95,0]],"id":52385904},{"atb":[[11,8]],"id":52385900},{"atl":[[170,2],[110,0]],"id":52385900},{"atb":[[5.1,0],[6.2,13]],"id":52385911},{"atb":[[10,11.11],[5.3,0],[25,0]],"id":52385913},{"atb":[[22,20]],"id":52385907},{"atb":[[9.6,7.54]],"id":52385897},{"atl":[[80,5],[120,2]],"id":52385897},{"atl":[[65,2],[90,0]],"id":52385891},{"atb":[[32,19.35]],"id":52385903},{"atb":[[13.5,8]],"id":52385899},{"atl":[[260,2],[90,0],[190,0]],"id":52385899}],"con":true,"img":false}]}
{"op":"mcm","clk":"11550385024","pt":1719497786285,"mc":[{"id":"1.230178169","rc":[{"atb":[[10.5,10],[7.8,0]],"id":52385912},{"atb":[[15.5,16.1]],"id":52385890},{"atl":[[300,2],[90,0],[240,0]],"id":52385898},{"atb":[[24,17]],"id":52385913},{"atb":[[10.5,8],[3.2,0]],"id":52385919},{"atb":[[24,22]],"id":52385917},{"atb":[[32,0]],"id":52385903},{"atl":[[95,6.38]],"id":52385899}],"con":true,"img":false}]}
{"op":"mcm","clk":"11550385033","pt":1719497786382,"mc":[{"id":"1.230178169","rc":[{"atl":[[95,6.38]],"id":52385898},{"atb":[[20,5]],"id":52385907},{"atb":[[25,22.48]],"id":52385903}],"con":true,"img":false}]}
{"op":"mcm","clk":"11550385042","pt":1719497786434,"mc":[{"id":"1.230178169","rc":[{"atb":[[13,6]],"id":52385890},{"atl":[[95,0]],"id":52385898},{"atb":[[24,0],[25,25]],"id":52385913},{"atb":[[13,0]],"id":52385917}],"con":true,"img":false}]}
{"op":"mcm","clk":"11550385052","pt":1719497786537,"mc":[{"id":"1.230178169","rc":[{"atl":[[110,5.5]],"id":52385898}],"con":true,"img":false}]}
{"op":"mcm","clk":"11550385087","pt":1719497786958,"mc":[{"id":"1.230178169","rc":[{"atb":[[16,8.5]],"id":52385910}],"con":true,"img":false}]}
{"op":"mcm","clk":"11550385180","pt":1719497787997,"mc":[{"id":"1.230178169","rc":[{"atb":[[10,11.11],[8.4,0]],"id":52385920},{"atb":[[7.4,0],[8.8,10]],"id":52385907},{"atb":[[8.2,0],[9.8,9.1]],"id":52385886},{"atb":[[9.8,0],[12.5,8.7]],"id":52385884},{"atb":[[8.4,11],[7,0]],"id":52385917},{"atb":[[6.4,8.81],[5.5,0]],"id":52385891},{"atb":[[4.5,0],[5.1,24.39]],"id":52385893},{"atb":[[8.6,0],[10,10]],"id":52385903}],"con":true,"img":false}]}
{"op":"mcm","clk":"11550385565","pt":1719497792639,"mc":[{"id":"1.230178169","rc":[{"atl":[[38,16.22]],"id":52385904},{"atl":[[26,12.62]],"id":52385891}],"con":true,"img":false}]}
{"op":"mcm","clk":"11550385578","pt":1719497792849,"mc":[{"id":"1.230178169","rc":[{"atl":[[55,0]],"id":52385904},{"atl":[[1000,0]],"id":52385891}],"con":true,"img":false}]}
{"op":"mcm","clk":"11550385590","pt":1719497793067,"mc":[{"id":"1.230178169","rc":[{"atb":[[34,10.94]],"id":52385896},{"atb":[[27,20]],"id":52385900},{"atb":[[26,16]],"id":52385919}],"con":true,"img":false}]}
{"op":"mcm","clk":"11550385607","pt":1719497793259,"mc":[{"id":"1.230178169","rc":[{"atb":[[1.32,0]],"id":52385896},{"atb":[[26,0]],"id":52385900},{"atb":[[25,0]],"id":52385919}],"con":true,"img":false}]}
{"op":"mcm","clk":"11550385644","pt":1719497793779,"mc":[{"id":"1.230178169","rc":[{"atl":[[26,22.2]],"id":52385911}],"con":true,"img":false}]}
{"op":"mcm","clk":"11550385662","pt":1719497793983,"mc":[{"id":"1.230178169","rc":[{"atl":[[34,0]],"id":52385911}],"con":true,"img":false}]}
{"op":"mcm","clk":"11550385797","pt":1719497795693,"mc":[{"id":"1.230178169","rc":[{"atb":[[14.5,0]],"id":52385910},{"atl":[[42,14.63]],"id":52385910},{"atb":[[25,0]],"id":52385912},{"atl":[[70,0]],"id":52385912},{"atb":[[25,0]],"id":52385906},{"atl":[[25,25]],"id":52385918},{"atb":[[16,2.5]],"id":52385920},{"atl":[[23,0]],"id":52385889},{"atl":[[30,0]],"id":52385914},{"atb":[[32,0]],"id":52385896},{"atl":[[46,5]],"id":52385890},{"atl":[[32,0]],"id":52385892},{"atb":[[25,0]],"id":52385898},{"atl":[[95,5]],"id":52385900},{"atl":[[32,0]],"id":52385911},{"atb":[[27,23.08]],"id":52385913},{"atl":[[55,0]],"id":52385913},{"atl":[[75,5]],"id":52385907},{"atb":[[23,0]],"id":52385919},{"atl":[[29,15]],"id":52385882},{"atb":[[18,0]],"id":52385884},{"atb":[[27,0]],"id":52385897},{"atl":[[75,0]],"id":52385897},{"atb":[[16,0]],"id":52385891},{"atl":[[75,2.5]],"id":52385903},{"atb":[[40,15.38]],"id":52385905},{"atb":[[38,16.22]],"id":52385899},{"atl":[[100,0]],"id":52385899}],"con":true,"img":false}]}
{"op":"mcm","clk":"11550385806","pt":1719497795793,"mc":[{"id":"1.230178169","rc":[{"atl":[[42,0]],"id":52385910},{"atb":[[26,0]],"id":52385912},{"atl":[[65,0]],"id":52385912},{"atl":[[25,0]],"id":52385918},{"atb":[[16,0],[6.2,19.23]],"id":52385898},{"atb":[[25,0]],"id":52385913},{"atl":[[50,0]],"id":52385913},{"atl":[[29,0]],"id":52385882},{"atb":[[40,0]],"id":52385905},{"atb":[[38,0]],"id":52385899},{"atl":[[95,0]],"id":52385899}],"con":true,"img":false}]}
{"op":"mcm","clk":"11550385815","pt":1719497795859,"mc":[{"id":"1.230178169","rc":[{"atb":[[16.5,3.6]],"id":52385910},{"atl":[[44,13.95],[95,2],[110,0]],"id":52385910},{"atb":[[25,10],[27,3.22]],"id":52385912},{"atl":[[70,8.7],[75,4.78]],"id":52385912},{"atb":[[21,3.8]],"id":52385906},{"atl":[[70,4.5]],"id":52385906},{"atl":[[38,16.22],[80,0],[60,2]],"id":52385918},{"atb":[[18.5,4]],"id":52385920},{"atl":[[27,3]],"id":52385889},{"atl":[[28,3.4],[29,0]],"id":52385914},{"atb":[[27,2.48]],"id":52385896},{"atl":[[38,5.6]],"id":52385890},{"atb":[[21,4.09]],"id":52385898},{"atl":[[100,2]],"id":52385898},{"atl":[[65,2.73]],"id":52385900},{"atl":[[36,5.02]],"id":52385911},{"atl":[[48,2.19]],"id":52385913},{"atl":[[50,2]],"id":52385907},{"atb":[[20,2.8]],"id":52385919},{"atb":[[12.5,6]],"id":52385921},{"atl":[[40,4.6]],"id":52385882},{"atb":[[28,2.7]],"id":52385884},{"atb":[[14,3.61]],"id":52385917},{"atb":[[14,4.68]],"id":52385897},{"atl":[[70,2.1]],"id":52385897},{"atb":[[14,3.58]],"id":52385891},{"atl":[[65,2]],"id":52385903},{"atb":[[23,3.32]],"id":52385905},{"atb":[[17,3.35]],"id":52385899},{"atl":[[90,2.64]],"id":52385899}],"con":true,"img":false}]}
{"op":"mcm","clk":"11550385822","pt":1719497795951,"mc":[{"id":"1.230178169","rc":[{"atl":[[28,25.62]],"id":52385914},{"atl":[[55,9]],"id":52385913},{"atl":[[48,12.77]],"id":52385907},{"atl":[[30,15]],"id":52385882},{"atl":[[60,10.17]],"id":52385903},{"atb":[[38,15]],"id":52385905},{"atb":[[36,15]],"id":52385899},{"atl":[[100,6.06]],"id":52385899}],"con":true,"img":false}]}
{"op":"mcm","clk":"11550385831","pt":1719497796053,"mc":[{"id":"1.230178169","rc":[{"atb":[[14,11.68]],"id":52385897}],"con":true,"img":false}]}
{"op":"mcm","clk":"11550385839","pt":1719497796157,"mc":[{"id":"1.230178169","rc":[{"atl":[[55,2.5]],"id":52385907},{"atl":[[70,0]],"id":52385903}],"con":true,"img":false}]}
{"op":"mcm","clk":"11550385846","pt":1719497796268,"mc":[{"id":"1.230178169","rc":[{"atb":[[17,27]],"id":52385910}],"con":true,"img":false}]}
{"op":"mcm","clk":"11550385858","pt":1719497796465,"mc":[{"id":"1.230178169","rc":[{"atb":[[15,0]],"id":52385910}],"con":true,"img":false}]}
{"op":"mcm","clk":"11550385877","pt":1719497796755,"mc":[{"id":"1.230178169","rc":[{"atl":[[44,0]],"id":52385910},{"atb":[[38,0]],"id":52385905},{"atb":[[36,0]],"id":52385899}],"con":true,"img":false}]}
{"op":"mcm","clk":"11550385884","pt":1719497796850,"mc":[{"id":"1.230178169","rc":[{"atl":[[46,13.33]],"id":52385910},{"atb":[[36,16.64]],"id":52385905},{"atb":[[32,16.7]],"id":52385899}],"con":true,"img":false}]}
{"op":"mcm","clk":"11550385905","pt":1719497797160,"mc":[{"id":"1.230178169","rc":[{"atb":[[32,0]],"id":52385899}],"con":true,"img":false}]}
{"op":"mcm","clk":"11550385915","pt":1719497797263,"mc":[{"id":"1.230178169","rc":[{"atb":[[26,11.98]],"id":52385899}],"con":true,"img":false}]}
{"op":"mcm","clk":"11550385947","pt":1719497797677,"mc":[{"id":"1.230178169","rc":[{"atb":[[16.5,0]],"id":52385914},{"atb":[[7.2,10]],"id":52385883},{"atl":[[130,5],[85,0],[95,2.5],[110,0],[250,2]],"id":52385883},{"atb":[[7.2,12]],"id":52385885},{"atb":[[6.8,12]],"id":52385886},{"atb":[[7.2,0],[5.5,22.22]],"id":52385882},{"atb":[[7.6,10]],"id":52385884}],"con":true,"img":false}]}
{"op":"mcm","clk":"11550385961","pt":1719497797785,"mc":[{"id":"1.230178169","rc":[{"atb":[[12.5,35.24]],"id":52385914},{"atb":[[12,0]],"id":52385883},{"atl":[[170,0]],"id":52385883},{"atb":[[12,0]],"id":52385885},{"atb":[[9.8,0]],"id":52385886},{"atl":[[30,0]],"id":52385882},{"atb":[[12.5,0]],"id":52385884}],"con":true,"img":false}]}
{"op":"mcm","clk":"11550385971","pt":1719497797888,"mc":[{"id":"1.230178169","rc":[{"atl":[[38,16.22]],"id":52385882}],"con":true,"img":false}]}
{"op":"mcm","clk":"11550386020","pt":1719497798451,"mc":[{"id":"1.230178169","rc":[{"atb":[[29,16.6]],"id":52385906}],"con":true,"img":false}]}
{"op":"mcm","clk":"11550386034","pt":1719497798661,"mc":[{"id":"1.230178169","rc":[{"atb":[[26,0]],"id":52385906}],"con":true,"img":false}]}
{"op":"mcm","clk":"11550386089","pt":1719497799484,"mc":[{"id":"1.230178169","rc":[{"atb":[[25,25]],"id":52385910}],"con":true,"img":false}]}
{"op":"mcm","clk":"11550386096","pt":1719497799587,"mc":[{"id":"1.230178169","rc":[{"atb":[[17,0]],"id":52385910},{"atb":[[27,22]],"id":52385920},{"atb":[[34,18.18]],"id":52385884}],"con":true,"img":false}]}
{"op":"mcm","clk":"11550386106","pt":1719497799693,"mc":[{"id":"1.230178169","rc":[{"atb":[[16.5,0]],"id":52385920},{"atl":[[24,23.2]],"id":52385890},{"atb":[[27,0]],"id":52385884}],"con":true,"img":false}]}
{"op":"mcm","clk":"11550386112","pt":1719497799796,"mc":[{"id":"1.230178169","rc":[{"atl":[[65,9.38]],"id":52385906},{"atl":[[44,0]],"id":52385890},{"atl":[[100,8.06]],"id":52385898},{"atb":[[19,15]],"id":52385897}],"con":true,"img":false}]}
{"op":"mcm","clk":"11550386128","pt":1719497799949,"mc":[{"id":"1.230178169","rc":[{"atl":[[1000,0]],"id":52385906},{"atl":[[110,0]],"id":52385898},{"atb":[[10.5,0]],"id":52385897}],"con":true,"img":false}]}
{"op":"mcm","clk":"11550386138","pt":1719497800055,"mc":[{"id":"1.230178169","rc":[{"atl":[[60,10.17]],"id":52385900},{"atl":[[85,7.14]],"id":52385899}],"con":true,"img":false}]}
{"op":"mcm","clk":"11550386157","pt":1719497800260,"mc":[{"id":"1.230178169","rc":[{"atl":[[70,0]],"id":52385900},{"atl":[[100,0]],"id":52385899}],"con":true,"img":false}]}
{"op":"mcm","clk":"11550386232","pt":1719497801294,"mc":[{"id":"1.230178169","rc":[{"atl":[[95,0]],"id":52385910},{"atl":[[130,0],[180,2]],"id":52385912},{"atl":[[32,0],[42,2.44]],"id":52385889},{"atl":[[280,2],[210,0]],"id":52385885},{"atl":[[260,2],[200,0]],"id":52385896},{"atl":[[300,0],[370,2]],"id":52385898},{"atl":[[110,0]],"id":52385919},{"atl":[[110,2]],"id":52385882},{"atl":[[330,2]],"id":52385884},{"atl":[[260,0],[330,2]],"id":52385899}],"con":true,"img":false}]}
{"op":"mcm","clk":"11550386246","pt":1719497801398,"mc":[{"id":"1.230178169","rc":[{"atl":[[130,2]],"id":52385910},{"atb":[[6.4,10],[12.5,0]],"id":52385906},{"atl":[[160,0],[220,2]],"id":52385906},{"atl":[[22,28.57]],"id":52385892},{"atb":[[6,14],[7.8,0]],"id":52385904},{"atb":[[10,0],[7,16.67]],"id":52385913},{"atb":[[6.8,10],[26,16],[8.8,0]],"id":52385907},{"atl":[[170,2]],"id":52385919},{"atl":[[75,0]],"id":52385882},{"atl":[[270,0]],"id":52385884},{"atb":[[34,15],[10,0],[7.8,10]],"id":52385903},{"atb":[[8.2,10],[12,0]],"id":52385905},{"atl":[[280,2],[220,0]],"id":52385905}],"con":true,"img":false}]}
{"op":"mcm","clk":"11550386256","pt":1719497801503,"mc":[{"id":"1.230178169","rc":[{"atb":[[6.4,0],[11.5,9.52]],"id":52385906},{"atl":[[29,0]],"id":52385892},{"atb":[[8,11],[6,2]],"id":52385904},{"atb":[[10.5,10.53],[7,0]],"id":52385913},{"atb":[[9.2,10],[6.8,0],[22,0],[26,0]],"id":52385907},{"atb":[[11,10],[7.8,0],[25,2.48]],"id":52385903},{"atb":[[8.2,0],[12,8.32]],"id":52385905}],"con":true,"img":false}]}
{"op":"mcm","clk":"11550386274","pt":1719497801606,"mc":[{"id":"1.230178169","rc":[{"atb":[[7.2,16.13],[8.6,0]],"id":52385910},{"atl":[[150,2],[180,0]],"id":52385912},{"atb":[[11.5,0],[7.6,10]],"id":52385906},{"atl":[[70,2],[80,2.5],[90,0],[100,5]],"id":52385906},{"atb":[[6,2],[4.9,25.64]],"id":52385918},{"atb":[[10,0],[7.8,12]],"id":52385920},{"atl":[[130,0],[190,2]],"id":52385920},{"atb":[[5.1,0],[4.4,29.41]],"id":52385889},{"atb":[[5.3,23.26],[6.6,0],[15.5,35.24]],"id":52385914},{"atb":[[34,0]],"id":52385896},{"atl":[[260,0],[190,2]],"id":52385896},{"atb":[[15.5,3.7]],"id":52385890},{"atb":[[4.8,26.32],[6,2]],"id":52385892},{"atl":[[22,0]],"id":52385892},{"atb":[[6.4,12]],"id":52385904},{"atl":[[130,2],[38,0],[85,0]],"id":52385904},{"atl":[[300,2],[370,0]],"id":52385898},{"atb":[[9.2,10],[11,0],[27,0]],"id":52385900},{"atl":[[140,2],[170,0]],"id":52385900},{"atb":[[6.2,0],[5.2,23.81]],"id":52385911},{"atl":[[140,0],[200,2]],"id":52385913},{"atb":[[9.2,0],[21,12],[7,10]],"id":52385907},{"atl":[[180,2],[120,0]],"id":52385886},{"atb":[[26,0]],"id":52385919},{"atl":[[140,2],[170,0]],"id":52385919},{"atb":[[8.8,0],[6.6,14]],"id":52385921},{"atl":[[130,0],[160,5],[95,0],[120,2.5]],"id":52385884},{"atb":[[6.8,11],[8.4,0]],"id":52385917},{"atb":[[9.6,0],[19,0],[7.4,15.08]],"id":52385897},{"atl":[[100,2],[120,0]],"id":52385897},{"atb":[[6.4,0],[5.3,23.26]],"id":52385891},{"atl":[[26,0]],"id":52385891},{"atb":[[5.1,0],[4.3,30.3]],"id":52385893},{"atb":[[11,0],[7.4,10]],"id":52385903},{"atl":[[150,0],[220,2]],"id":52385903},{"atb":[[12,0],[7.6,10]],"id":52385905},{"atb":[[26,0]],"id":52385899},{"atl":[[330,0],[240,2]],"id":52385899}],"con":true,"img":false}]}
{"op":"mcm","clk":"11550386280","pt":1719497801659,"mc":[{"id":"1.230178169","rc":[{"atb":[[9.4,11.9],[7.2,0]],"id":52385910},{"atb":[[12,8.8],[7.6,0]],"id":52385906},{"atb":[[6,15],[4.9,0]],"id":52385918},{"atb":[[10.5,10],[7.8,0]],"id":52385920},{"atb":[[5.3,18.5],[4.4,0]],"id":52385889},{"atb":[[5.3,0],[12.5,0],[6.6,17.86]],"id":52385914},{"atb":[[34,0]],"id":52385883},{"atb":[[32,10]],"id":52385896},{"atb":[[13,27.2]],"id":52385890},{"atb":[[4.8,0],[6,17]],"id":52385892},{"atl":[[36,15]],"id":52385892},{"atb":[[8,0],[6.4,0],[9.2,17]],"id":52385904},{"atl":[[55,11.11]],"id":52385904},{"atb":[[34,0]],"id":52385898},{"atb":[[24,10.46]],"id":52385900},{"atb":[[6.4,13],[5.2,0]],"id":52385911},{"atb":[[10,10],[7,0]],"id":52385907},{"atb":[[25,10.6]],"id":52385919},{"atb":[[8.6,12],[6.6,0]],"id":52385921},{"atb":[[6.8,0],[8.8,10]],"id":52385917},{"atb":[[17.5,10]],"id":52385897},{"atb":[[5.3,0],[7,8.58]],"id":52385891},{"atl":[[40,12.16]],"id":52385891},{"atb":[[4.3,0],[5.1,24.39]],"id":52385893},{"atb":[[7.4,0]],"id":52385903},{"atb":[[7.6,0],[12,8.32]],"id":52385905},{"atb":[[23,11.98]],"id":52385899}],"con":true,"img":false}]}
{"op":"mcm","clk":"11550386290","pt":1719497801760,"mc":[{"id":"1.230178169","rc":[{"atb":[[32,11]],"id":52385883},{"atb":[[32,0]],"id":52385896},{"atb":[[28,18.18]],"id":52385898},{"atb":[[25,0]],"id":52385919},{"atb":[[17.5,0]],"id":52385897},{"atb":[[11.5,9.52]],"id":52385903}],"con":true,"img":false}]}
{"op":"mcm","clk":"11550386299","pt":1719497801864,"mc":[{"id":"1.230178169","rc":[{"atb":[[30,10]],"id":52385896},{"atb":[[26,15.6]],"id":52385919},{"atb":[[19.5,25]],"id":52385897},{"atl":[[36,17.14]],"id":52385897}],"con":true,"img":false}]}
{"op":"mcm","clk":"11550386309","pt":1719497801970,"mc":[{"id":"1.230178169","rc":[{"atl":[[150,0],[120,2]],"id":52385912},{"atl":[[140,2],[190,0]],"id":52385896},{"atl":[[65,0],[46,7.22]],"id":52385890},{"atl":[[300,0],[240,2]],"id":52385898},{"atl":[[140,0],[110,2]],"id":52385900},{"atl":[[110,2]],"id":52385919},{"atl":[[90,2],[110,0]],"id":52385882},{"atl":[[80,7],[100,0]],"id":52385897},{"atl":[[280,0],[210,2]],"id":52385905},{"atl":[[180,2],[240,0]],"id":52385899}],"con":true,"img":false}]}
{"op":"mcm","clk":"11550386319","pt":1719497802070,"mc":[{"id":"1.230178169","rc":[{"atb":[[26,0]],"id":52385919},{"atl":[[140,0]],"id":52385919},{"atb":[[19.5,0]],"id":52385897},{"atl":[[55,0]],"id":52385897}],"con":true,"img":false}]}
{"op":"mcm","clk":"11550386328","pt":1719497802175,"mc":[{"id":"1.230178169","rc":[{"atb":[[24,10.6]],"id":52385919},{"atb":[[18,10]],"id":52385897}],"con":true,"img":false}]}
{"op":"mcm","clk":"11550386361","pt":1719497802589,"mc":[{"id":"1.230178169","rc":[{"atb":[[12.5,8.7]],"id":52385898}],"con":true,"img":false}]}
{"op":"mcm","clk":"11550386371","pt":1719497802692,"mc":[{"id":"1.230178169","rc":[{"atb":[[6.2,0]],"id":52385898}],"con":true,"img":false}]}
{"op":"mcm","clk":"11550386429","pt":1719497803368,"mc":[{"id":"1.230178169","rc":[{"atl":[[36,0]],"id":52385897}],"con":true,"img":false}]}
{"op":"mcm","clk":"11550386439","pt":1719497803468,"mc":[{"id":"1.230178169","rc":[{"atl":[[38,10]],"id":52385897}],"con":true,"img":false}]}
{"op":"mcm","clk":"11550386453","pt":1719497803676,"mc":[{"id":"1.230178169","rc":[{"atl":[[38,0]],"id":52385897}],"con":true,"img":false}]}
{"op":"mcm","clk":"11550386461","pt":1719497803778,"mc":[{"id":"1.230178169","rc":[{"atl":[[60,12.5]],"id":52385897}],"con":true,"img":false}]}
{"op":"mcm","clk":"11550386475","pt":1719497803985,"mc":[{"id":"1.230178169","rc":[{"atb":[[18,2.5]],"id":52385906}],"con":true,"img":false}]}
{"op":"mcm","clk":"11550386483","pt":1719497804088,"mc":[{"id":"1.230178169","rc":[{"atb":[[19,2.5]],"id":52385884}],"con":true,"img":false}]}
{"op":"mcm","clk":"11550386507","pt":1719497804396,"mc":[{"id":"1.230178169","rc":[{"atb":[[11.5,8]],"id":52385883},{"atl":[[200,2],[250,0]],"id":52385883},{"atb":[[7.2,0],[12.5,8.7]],"id":52385885},{"atb":[[10,9.1],[6.8,0]],"id":52385886},{"atb":[[8,14.29],[5.5,0]],"id":52385882},{"atb":[[15.5,5.4],[7.6,0]],"id":52385884}],"con":true,"img":false}]}
{"op":"mcm","clk":"11550386515","pt":1719497804449,"mc":[{"id":"1.230178169","rc":[{"atb":[[7.2,0]],"id":52385883}],"con":true,"img":false}]}
{"op":"mcm","clk":"11550386583","pt":1719497805278,"mc":[{"id":"1.230178169","rc":[{"atb":[[10.5,0],[7.2,10]],"id":52385912},{"atl":[[170,2],[220,0]],"id":52385906},{"atl":[[130,2],[190,0]],"id":52385920},{"atb":[[11.5,0]],"id":52385883},{"atl":[[280,0],[230,2]],"id":52385885},{"atb":[[11.5,0]],"id":52385896},{"atl":[[140,0],[190,2]],"id":52385896},{"atb":[[6.2,0],[3.55,39.22]],"id":52385890},{"atb":[[9.2,5],[7.8,14.71]],"id":52385904},{"atl":[[130,0],[90,2]],"id":52385904},{"atb":[[5.6,12.79],[12.5,0]],"id":52385898},{"atb":[[1.4,100],[9.2,0]],"id":52385900},{"atl":[[150,2],[110,0]],"id":52385900},{"atl":[[140,2]],"id":52385913},{"atb":[[8.6,10],[10,0]],"id":52385907},{"atb":[[10.5,0],[5.1,24.39]],"id":52385919},{"atl":[[270,2],[330,0]],"id":52385884},{"atb":[[1.97,103.09],[7.4,0]],"id":52385897},{"atl":[[160,2],[220,0]],"id":52385903},{"atb":[[13.5,0]],"id":52385899}],"con":true,"img":false}]}
{"op":"mcm","clk":"11550386596","pt":1719497805384,"mc":[{"id":"1.230178169","rc":[{"atb":[[12.5,8]],"id":52385883},{"atb":[[11.5,5]],"id":52385896},{"atl":[[200,0]],"id":52385913}],"con":true,"img":false}]}
{"op":"mcm","clk":"11550386605","pt":1719497805491,"mc":[{"id":"1.230178169","rc":[{"atb":[[12.5,8.35]],"id":52385899}],"con":true,"img":false}]}
{"op":"mcm","clk":"11550386650","pt":1719497806001,"mc":[{"id":"1.230178169","rc":[{"atl":[[130,0],[100,2]],"id":52385910},{"atb":[[12,0],[7.2,8.8]],"id":52385906},{"atb":[[10.5,0],[8.8,12]],"id":52385920},{"atb":[[7.8,0]],"id":52385904},{"atb":[[10.5,0],[8.8,12.82]],"id":52385913},{"atb":[[8.6,0]],"id":52385907},{"atb":[[15.5,0]],"id":52385884},{"atb":[[5.8,20.83],[7,0]],"id":52385891},{"atb":[[11.5,0],[7,10]],"id":52385903},{"atb":[[7.2,10],[12,0]],"id":52385905}],"con":true,"img":false}]}
{"op":"mcm","clk":"11550386658","pt":1719497806102,"mc":[{"id":"1.230178169","rc":[{"atb":[[8.4,11]],"id":52385904},{"atb":[[9.4,10]],"id":52385907},{"atb":[[14,7.69]],"id":52385884}],"con":true,"img":false}]}
{"op":"mcm","clk":"11550386671","pt":1719497806156,"mc":[{"id":"1.230178169","rc":[{"atb":[[7.6,15.15]],"id":52385910},{"atb":[[5.4,22.73]],"id":52385914},{"atb":[[5.3,23.26]],"id":52385911}],"con":true,"img":false}]}
{"op":"mcm","clk":"11550386679","pt":1719497806259,"mc":[{"id":"1.230178169","rc":[{"atb":[[9.4,0]],"id":52385910},{"atb":[[6,2],[5.2,23.81]],"id":52385918},{"atb":[[5.3,5],[4.7,27.03]],"id":52385889},{"atb":[[6.6,0]],"id":52385914},{"atb":[[12.5,0]],"id":52385885},{"atb":[[5.1,24.39],[6,2]],"id":52385892},{"atb":[[6.4,0]],"id":52385911},{"atb":[[7.2,14],[8.6,0]],"id":52385921},{"atb":[[14,0]],"id":52385884},{"atb":[[7.4,11],[8.8,0]],"id":52385917},{"atb":[[5.1,0],[4.5,28.57]],"id":52385893}],"con":true,"img":false}]}
{"op":"mcm","clk":"11550386687","pt":1719497806362,"mc":[{"id":"1.230178169","rc":[{"atb":[[12.5,8.7]],"id":52385885},{"atb":[[15,5.4]],"id":52385884}],"con":true,"img":false}]}
{"op":"mcm","clk":"11550386694","pt":1719497806464,"mc":[{"id":"1.230178169","rc":[{"atb":[[8.4,0]],"id":52385904}],"con":true,"img":false}]}
{"op":"mcm","clk":"11550386701","pt":1719497806578,"mc":[{"id":"1.230178169","rc":[{"atl":[[28,3.4]],"id":52385914},{"atb":[[9.2,17]],"id":52385904},{"atb":[[9.4,0]],"id":52385907}],"con":true,"img":false}]}
{"op":"mcm","clk":"11550386709","pt":1719497806672,"mc":[{"id":"1.230178169","rc":[{"atl":[[29,21.43]],"id":52385914},{"atb":[[10,10]],"id":52385907}],"con":true,"img":false}]}
{"op":"mcm","clk":"11550386726","pt":1719497806880,"mc":[{"id":"1.230178169","rc":[{"atb":[[12.5,0]],"id":52385883},{"atb":[[11.5,0]],"id":52385896},{"atb":[[9.2,5]],"id":52385904},{"atb":[[34,0]],"id":52385903},{"atb":[[12.5,0]],"id":52385899}],"con":true,"img":false}]}
{"op":"mcm","clk":"11550386731","pt":1719497806979,"mc":[{"id":"1.230178169","rc":[{"atb":[[12.5,8]],"id":52385883},{"atb":[[7.8,11]],"id":52385904}],"con":true,"img":false}]}
{"op":"mcm","clk":"11550386746","pt":1719497807087,"mc":[{"id":"1.230178169","rc":[{"atb":[[11.5,5]],"id":52385896},{"atl":[[110,2]],"id":52385897},{"atb":[[34,9.96]],"id":52385903},{"atb":[[12.5,8.35]],"id":52385899}],"con":true,"img":false}]}
{"op":"mcm","clk":"11550386752","pt":1719497807188,"mc":[{"id":"1.230178169","rc":[{"atl":[[38,16.22]],"id":52385904},{"atl":[[80,5]],"id":52385897},{"atl":[[32,17.16]],"id":52385891}],"con":true,"img":false}]}
{"op":"mcm","clk":"11550386768","pt":1719497807394,"mc":[{"id":"1.230178169","rc":[{"atl":[[55,0]],"id":52385904},{"atl":[[40,0]],"id":52385891}],"con":true,"img":false}]}
{"op":"mcm","clk":"11550386784","pt":1719497807599,"mc":[{"id":"1.230178169","rc":[{"atb":[[26,11.46]],"id":52385900}],"con":true,"img":false}]}
{"op":"mcm","clk":"11550386798","pt":1719497807810,"mc":[{"id":"1.230178169","rc":[{"atb":[[24,0]],"id":52385900}],"con":true,"img":false}]}
{"op":"mcm","clk":"11550386811","pt":1719497808013,"mc":[{"id":"1.230178169","rc":[{"atl":[[36,2.86]],"id":52385889}],"con":true,"img":false}]}
{"op":"mcm","clk":"11550386828","pt":1719497808167,"mc":[{"id":"1.230178169","rc":[{"atl":[[42,0]],"id":52385889}],"con":true,"img":false}]}
{"op":"mcm","clk":"11550386991","pt":1719497810279,"mc":[{"id":"1.230178169","rc":[{"atb":[[30,19.56]],"id":52385912},{"atl":[[30,20.69]],"id":52385918}],"con":true,"img":false}]}
{"op":"mcm","clk":"11550387001","pt":1719497810383,"mc":[{"id":"1.230178169","rc":[{"atb":[[25,0]],"id":52385912},{"atl":[[38,0]],"id":52385918},{"atl":[[28,25.62]],"id":52385914},{"atl":[[48,14.96]],"id":52385913},{"atb":[[42,14.63]],"id":52385905},{"atb":[[27,16.7]],"id":52385899}],"con":true,"img":false}]}
{"op":"mcm","clk":"11550387017","pt":1719497810599,"mc":[{"id":"1.230178169","rc":[{"atl":[[29,0]],"id":52385914},{"atl":[[55,0]],"id":52385913},{"atb":[[36,0]],"id":52385905},{"atb":[[23,0]],"id":52385899}],"con":true,"img":false}]}
{"op":"mcm","clk":"11550387062","pt":1719497811258,"mc":[{"id":"1.230178169","rc":[{"atb":[[7.8,0]],"id":52385904},{"atl":[[38,0]],"id":52385904},{"atb":[[10,0]],"id":52385907},{"atb":[[15,0]],"id":52385884}],"con":true,"img":false}]}
{"op":"mcm","clk":"11550387075","pt":1719497811362,"mc":[{"id":"1.230178169","rc":[{"atb":[[8.4,11]],"id":52385904},{"atl":[[40,15.38]],"id":52385904},{"atb":[[9.4,10]],"id":52385907},{"atb":[[14,7.69]],"id":52385884}],"con":true,"img":false}]}
{"op":"mcm","clk":"11550387092","pt":1719497811574,"mc":[{"id":"1.230178169","rc":[{"atl":[[40,0]],"id":52385904}],"con":true,"img":false}]}
{"op":"mcm","clk":"11550387102","pt":1719497811673,"mc":[{"id":"1.230178169","rc":[{"atl":[[44,13.95]],"id":52385904}],"con":true,"img":false}]}
{"op":"mcm","clk":"11550387129","pt":1719497811982,"mc":[{"id":"1.230178169","rc":[{"atb":[[10,8.22],[7.2,0]],"id":52385912},{"atb":[[6,10.7]],"id":52385890},{"atb":[[5.6,0],[14.5,7.41]],"id":52385898},{"atb":[[1.4,0],[10.5,8]],"id":52385900},{"atb":[[10,7.8],[5.1,0]],"id":52385919},{"atb":[[1.97,0],[8.8,12.82]],"id":52385897}],"con":true,"img":false}]}
{"op":"mcm","clk":"11550387137","pt":1719497812088,"mc":[{"id":"1.230178169","rc":[{"atb":[[3.55,0]],"id":52385890}],"con":true,"img":false}]}
{"op":"mcm","clk":"11550387189","pt":1719497812712,"mc":[{"id":"1.230178169","rc":[{"atb":[[11.5,7.6]],"id":52385906},{"atb":[[10,10],[8.8,0]],"id":52385920},{"atb":[[10,11.11],[8.8,0]],"id":52385913},{"atb":[[5.8,0],[6.6,8.58]],"id":52385891},{"atb":[[11,10],[7,0]],"id":52385903},{"atb":[[7.2,0],[12,8.32]],"id":52385905}],"con":true,"img":false}]}
{"op":"mcm","clk":"11550387201","pt":1719497812811,"mc":[{"id":"1.230178169","rc":[{"atb":[[7.2,0],[30,17.6]],"id":52385906}],"con":true,"img":false}]}
{"op":"mcm","clk":"11550387211","pt":1719497812872,"mc":[{"id":"1.230178169","rc":[{"atb":[[7.6,0],[8.8,12.82]],"id":52385910},{"atb":[[6.2,18],[5.4,0]],"id":52385914},{"atb":[[5.3,0],[6,15]],"id":52385911}],"con":true,"img":false}]}
{"op":"mcm","clk":"11550387222","pt":1719497812967,"mc":[{"id":"1.230178169","rc":[{"atb":[[29,0]],"id":52385906},{"atb":[[6,15],[5.2,0]],"id":52385918},{"atb":[[5.2,23.81],[4.7,0]],"id":52385889},{"atb":[[5.1,0],[5.9,20.41]],"id":52385892},{"atb":[[8.2,12]],"id":52385921},{"atb":[[7.4,0],[8.8,10]],"id":52385917},{"atb":[[4.5,0],[5.1,24.39]],"id":52385893}],"con":true,"img":false}]}
{"op":"mcm","clk":"11550387234","pt":1719497813069,"mc":[{"id":"1.230178169","rc":[{"atb":[[7.2,0]],"id":52385921}],"con":true,"img":false}]}
{"op":"mcm","clk":"11550387466","pt":1719497815710,"mc":[{"id":"1.230178169","rc":[{"atl":[[22,28.57]],"id":52385892}],"con":true,"img":false}]}
{"op":"mcm","clk":"11550387477","pt":1719497815909,"mc":[{"id":"1.230178169","rc":[{"atl":[[36,0]],"id":52385892}],"con":true,"img":false}]}
{"op":"mcm","clk":"11550387497","pt":1719497816070,"mc":[{"id":"1.230178169","rc":[{"atb":[[38,16]],"id":52385883},{"atb":[[36,17.14]],"id":52385898}],"con":true,"img":false}]}
{"op":"mcm","clk":"11550387506","pt":1719497816218,"mc":[{"id":"1.230178169","rc":[{"atl":[[55,11.11]],"id":52385897}],"con":true,"img":false}]}
{"op":"mcm","clk":"11550387517","pt":1719497816280,"mc":[{"id":"1.230178169","rc":[{"atb":[[32,0]],"id":52385883},{"atb":[[32,15]],"id":52385896},{"atb":[[28,0]],"id":52385898}],"con":true,"img":false}]}
{"op":"mcm","clk":"11550387525","pt":1719497816374,"mc":[{"id":"1.230178169","rc":[{"atl":[[60,2.5]],"id":52385897}],"con":true,"img":false}]}
{"op":"mcm","clk":"11550387535","pt":1719497816481,"mc":[{"id":"1.230178169","rc":[{"atb":[[30,0]],"id":52385896}],"con":true,"img":false}]}
{"op":"mcm","clk":"11550387567","pt":1719497816899,"mc":[{"id":"1.230178169","rc":[{"atb":[[30,0]],"id":52385912},{"atl":[[160,2]],"id":52385896},{"atl":[[24,0]],"id":52385890},{"atl":[[32,2.5],[36,2.52],[40,5],[44,0]],"id":52385911},{"atb":[[28,15]],"id":52385907},{"atl":[[95,2],[110,0]],"id":52385897},{"atl":[[60,0]],"id":52385903}],"con":true,"img":false}]}
{"op":"mcm","clk":"11550387572","pt":1719497816997,"mc":[{"id":"1.230178169","rc":[{"atb":[[25,0]],"id":52385910},{"atl":[[22,0]],"id":52385889},{"atl":[[190,0]],"id":52385896},{"atl":[[48,0]],"id":52385907},{"atl":[[30,17.16]],"id":52385891},{"atl":[[18.5,0]],"id":52385893}],"con":true,"img":false}]}
{"op":"mcm","clk":"11550387580","pt":1719497817100,"mc":[{"id":"1.230178169","rc":[{"atb":[[24,26.09]],"id":52385910},{"atb":[[29,19.56]],"id":52385912},{"atl":[[23,27.27]],"id":52385889},{"atl":[[46,5],[25,25],[55,2]],"id":52385890},{"atl":[[26,0]],"id":52385911},{"atb":[[21,3]],"id":52385907},{"atl":[[48,12.77]],"id":52385907},{"atl":[[32,0]],"id":52385891},{"atl":[[19,22]],"id":52385893},{"atl":[[60,10.17]],"id":52385903}],"con":true,"img":false}]}
{"op":"mcm","clk":"11550387588","pt":1719497817202,"mc":[{"id":"1.230178169","rc":[{"atl":[[27,21.04]],"id":52385911}],"con":true,"img":false}]}
{"op":"mcm","clk":"11550387596","pt":1719497817306,"mc":[{"id":"1.230178169","rc":[{"atb":[[24,0],[25,25]],"id":52385910},{"atb":[[29,0]],"id":52385912},{"atl":[[22,28],[23,0]],"id":52385889},{"atl":[[25,0]],"id":52385890},{"atl":[[27,17.16],[30,0]],"id":52385891},{"atl":[[18.5,22],[19,0]],"id":52385893}],"con":true,"img":false}]}
{"op":"mcm","clk":"11550387604","pt":1719497817406,"mc":[{"id":"1.230178169","rc":[{"atb":[[27,22.78]],"id":52385912},{"atl":[[25,21.2]],"id":52385890}],"con":true,"img":false}]}
{"op":"mcm","clk":"11550387610","pt":1719497817516,"mc":[{"id":"1.230178169","rc":[{"atl":[[22,0]],"id":52385889}],"con":true,"img":false}]}
{"op":"mcm","clk":"11550387617","pt":1719497817618,"mc":[{"id":"1.230178169","rc":[{"atl":[[24,26.09]],"id":52385889}],"con":true,"img":false}]}
{"op":"mcm","clk":"11550387627","pt":1719497817818,"mc":[{"id":"1.230178169","rc":[{"atl":[[34,18.18]],"id":52385897}],"con":true,"img":false}]}
{"op":"mcm","clk":"11550387639","pt":1719497817923,"mc":[{"id":"1.230178169","rc":[{"atl":[[48,16.1]],"id":52385907},{"atl":[[18.5,30.82]],"id":52385893}],"con":true,"img":false}]}
{"op":"mcm","clk":"11550387641","pt":1719497817979,"mc":[{"id":"1.230178169","rc":[{"atl":[[55,0]],"id":52385897}],"con":true,"img":false}]}
{"op":"mcm","clk":"11550387649","pt":1719497818079,"mc":[{"id":"1.230178169","rc":[{"atl":[[48,12.77]],"id":52385907},{"atl":[[18.5,22]],"id":52385893}],"con":true,"img":false}]}
{"op":"mcm","clk":"11550387666","pt":1719497818283,"mc":[{"id":"1.230178169","rc":[{"atl":[[18.5,0]],"id":52385893}],"con":true,"img":false}]}
{"op":"mcm","clk":"11550387675","pt":1719497818387,"mc":[{"id":"1.230178169","rc":[{"atl":[[19,15]],"id":52385893}],"con":true,"img":false}]}
{"op":"mcm","clk":"11550387965","pt":1719497822316,"mc":[{"id":"1.230178169","rc":[{"atb":[[18,8.5]],"id":52385920}],"con":true,"img":false}]}
{"op":"mcm","clk":"11550387981","pt":1719497822522,"mc":[{"id":"1.230178169","rc":[{"atb":[[13,5],[14.5,4],[15,2.5]],"id":52385913}],"con":true,"img":false}]}
{"op":"mcm","clk":"11550388011","pt":1719497822780,"mc":[{"id":"1.230178169","rc":[{"atb":[[14,0],[14.5,5],[16.5,6.1],[16,6]],"id":52385910},{"atb":[[7.6,0],[7.8,2.5]],"id":52385918},{"atb":[[16,2.5]],"id":52385885},{"atl":[[75,12.71],[90,0],[95,5],[120,0]],"id":52385896},{"atl":[[34,2.5],[38,3.1],[42,5],[46,0]],"id":52385890},{"atl":[[95,0],[55,2.5]],"id":52385900},{"atb":[[17.5,2.5],[15,0],[15.5,5]],"id":52385886},{"atb":[[10.5,0],[12.5,0],[14,6.11]],"id":52385917},{"atl":[[80,0],[46,2.5]],"id":52385897}],"con":true,"img":false}]}
{"op":"mcm","clk":"11550388023","pt":1719497822884,"mc":[{"id":"1.230178169","rc":[{"atl":[[55,13.61]],"id":52385900},{"atl":[[85,9.64],[90,0],[110,5],[120,0]],"id":52385905}],"con":true,"img":false}]}
{"op":"mcm","clk":"11550388046","pt":1719497823093,"mc":[{"id":"1.230178169","rc":[{"atl":[[75,2.5]],"id":52385912},{"atl":[[70,0]],"id":52385906},{"atl":[[27,0]],"id":52385889},{"atb":[[19.5,0]],"id":52385885},{"atb":[[27,0]],"id":52385896},{"atb":[[21,0]],"id":52385898},{"atl":[[65,0],[60,0]],"id":52385900},{"atl":[[50,0]],"id":52385907},{"atl":[[46,13.33]],"id":52385886},{"atb":[[13,0]],"id":52385921},{"atl":[[40,2.5]],"id":52385882},{"atb":[[28,0]],"id":52385884},{"atb":[[14,7]],"id":52385897},{"atb":[[14,0]],"id":52385891},{"atb":[[25,0]],"id":52385903},{"atl":[[65,0]],"id":52385903},{"atb":[[17,5],[19,7.5]],"id":52385899},{"atl":[[90,0]],"id":52385899}],"con":true,"img":false}]}
{"op":"mcm","clk":"11550388056","pt":1719497823196,"mc":[{"id":"1.230178169","rc":[{"atb":[[6.2,19.23]],"id":52385898},{"atl":[[46,0]],"id":52385886},{"atb":[[11,0],[13,0]],"id":52385899}],"con":true,"img":false}]}
{"op":"mcm","clk":"11550388068","pt":1719497823307,"mc":[{"id":"1.230178169","rc":[{"atl":[[44,2.56]],"id":52385910},{"atl":[[65,2]],"id":52385912},{"atl":[[65,0],[60,2]],"id":52385906},{"atl":[[29,3]],"id":52385918},{"atl":[[29,5.6]],"id":52385889},{"atb":[[12,0]],"id":52385914},{"atb":[[27,3.55]],"id":52385885},{"atb":[[23,4.02]],"id":52385896},{"atb":[[17,0]],"id":52385904},{"atb":[[18.5,2.9],[14.5,0]],"id":52385898},{"atl":[[75,4.5]],"id":52385900},{"atb":[[14,0]],"id":52385911},{"atl":[[46,2.2],[48,0]],"id":52385907},{"atb":[[18,0]],"id":52385886},{"atl":[[140,2],[180,0],[55,11.11],[60,4.63]],"id":52385886},{"atl":[[36,2.7]],"id":52385882},{"atb":[[20,0],[24,2.57]],"id":52385884},{"atb":[[18.5,4.6]],"id":52385897},{"atb":[[17,4.22]],"id":52385891},{"atb":[[21,4]],"id":52385903},{"atl":[[75,4.5],[60,0]],"id":52385903},{"atl":[[80,2]],"id":52385905},{"atb":[[28,3.58]],"id":52385899},{"atl":[[80,2.6]],"id":52385899}],"con":true,"img":false}]}
{"op":"mcm","clk":"11550388074","pt":1719497823403,"mc":[{"id":"1.230178169","rc":[{"atl":[[70,8.7]],"id":52385906},{"atb":[[11,9]],"id":52385914},{"atb":[[19,6]],"id":52385904},{"atb":[[13,8]],"id":52385911},{"atl":[[50,12.24]],"id":52385907},{"atb":[[20,6]],"id":52385886},{"atb":[[24,7.57]],"id":52385884},{"atl":[[65,9.38]],"id":52385903}],"con":true,"img":false}]}
{"op":"mcm","clk":"11550388086","pt":1719497823510,"mc":[{"id":"1.230178169","rc":[{"atl":[[42,14.63]],"id":52385910},{"atl":[[60,10.17]],"id":52385912},{"atb":[[28,22]],"id":52385885},{"atb":[[6.2,0],[13,8.33]],"id":52385898},{"atl":[[36,19.84]],"id":52385882},{"atb":[[19,23.2]],"id":52385897},{"atb":[[17,22.66]],"id":52385891},{"atl":[[75,8.11]],"id":52385905},{"atb":[[29,21.43]],"id":52385899},{"atl":[[75,8.11]],"id":52385899}],"con":true,"img":false}]}
{"op":"mcm","clk":"11550388115","pt":1719497823823,"mc":[{"id":"1.230178169","rc":[{"atl":[[46,0]],"id":52385910},{"atl":[[70,0]],"id":52385912},{"atb":[[26,0]],"id":52385885},{"atl":[[38,0]],"id":52385882},{"atb":[[18,0]],"id":52385897},{"atb":[[16.5,0]],"id":52385891},{"atl":[[85,2.5]],"id":52385905},{"atb":[[27,0]],"id":52385899},{"atl":[[85,0]],"id":52385899}],"con":true,"img":false}]}
{"op":"mcm","clk":"11550388137","pt":1719497824128,"mc":[{"id":"1.230178169","rc":[{"atb":[[19,0]],"id":52385885},{"atl":[[65,0]],"id":52385903}],"con":true,"img":false}]}
{"op":"mcm","clk":"11550388143","pt":1719497824184,"mc":[{"id":"1.230178169","rc":[{"atl":[[80,7.59]],"id":52385903}],"con":true,"img":false}]}
{"op":"mcm","clk":"11550388162","pt":1719497824384,"mc":[{"id":"1.230178169","rc":[{"atl":[[24,26]],"id":52385918},{"atb":[[14,0]],"id":52385897}],"con":true,"img":false}]}
{"op":"mcm","clk":"11550388177","pt":1719497824592,"mc":[{"id":"1.230178169","rc":[{"atl":[[30,0]],"id":52385918},{"atb":[[19,2.5]],"id":52385899}],"con":true,"img":false}]}
{"op":"mcm","clk":"11550388204","pt":1719497824906,"mc":[{"id":"1.230178169","rc":[{"atl":[[34,0]],"id":52385897}],"con":true,"img":false}]}
{"op":"mcm","clk":"11550388219","pt":1719497825107,"mc":[{"id":"1.230178169","rc":[{"atl":[[36,14.2]],"id":52385897}],"con":true,"img":false}]}
{"op":"mcm","clk":"11550388271","pt":1719497825729,"mc":[{"id":"1.230178169","rc":[{"atb":[[15.5,5],[17.5,2.5],[19.5,0],[23,0]],"id":52385912},{"atb":[[11.5,0],[7.2,8.8]],"id":52385906},{"atb":[[10,0],[8.8,12.82]],"id":52385920},{"atb":[[7.2,7.1],[12.5,0]],"id":52385885},{"atl":[[140,5],[85,0],[100,2.5],[110,0]],"id":52385885},{"atb":[[6.2,12],[8.4,0]],"id":52385904},{"atb":[[9,10],[10.5,0]],"id":52385900},{"atl":[[150,0],[110,2]],"id":52385900},{"atb":[[10,0],[8.8,11]],"id":52385913},{"atb":[[6.8,10],[9.4,0],[28,0]],"id":52385907},{"atb":[[10,0],[7,11]],"id":52385886},{"atl":[[75,2.5],[80,0],[95,5],[60,2.13]],"id":52385886},{"atb":[[8,0],[5.9,20.41]],"id":52385882},{"atl":[[70,5],[40,0],[48,0],[50,2.5]],"id":52385882},{"atb":[[6.2,15.14],[14,0]],"id":52385884},{"atl":[[75,2.5]],"id":52385884},{"atb":[[7.2,10],[8.8,0]],"id":52385897},{"atl":[[80,2],[95,0]],"id":52385897},{"atb":[[11,0],[4.5,28.57]],"id":52385903}],"con":true,"img":false}]}
{"op":"mcm","clk":"11550388279","pt":1719497825783,"mc":[{"id":"1.230178169","rc":[{"atl":[[46,2.22],[55,0]],"id":52385890},{"atb":[[27,11]],"id":52385907},{"atb":[[34,0]],"id":52385884},{"atl":[[110,5.5]],"id":52385884},{"atl":[[27,0]],"id":52385891}],"con":true,"img":false}]}
{"op":"mcm","clk":"11550388285","pt":1719497825891,"mc":[{"id":"1.230178169","rc":[{"atb":[[32,10]],"id":52385884},{"atl":[[40,15]],"id":52385891}],"con":true,"img":false}]}
{"op":"mcm","clk":"11550388301","pt":1719497825992,"mc":[{"id":"1.230178169","rc":[{"atb":[[13,0]],"id":52385918},{"atb":[[29,21.43]],"id":52385920},{"atb":[[23,22]],"id":52385904},{"atb":[[29,17]],"id":52385913},{"atb":[[27,0],[29,16]],"id":52385907},{"atl":[[40,15.38]],"id":52385919},{"atb":[[38,16.22]],"id":52385903}],"con":true,"img":false}]}
{"op":"mcm","clk":"11550388306","pt":1719497826103,"mc":[{"id":"1.230178169","rc":[{"atb":[[12,8]],"id":52385918}],"con":true,"img":false}]}
{"op":"mcm","clk":"11550388317","pt":1719497826197,"mc":[{"id":"1.230178169","rc":[{"atb":[[27,0]],"id":52385920},{"atb":[[21,2.7]],"id":52385904},{"atl":[[55,2.9]],"id":52385919},{"atb":[[34,0]],"id":52385903}],"con":true,"img":false}]}
{"op":"mcm","clk":"11550388324","pt":1719497826299,"mc":[{"id":"1.230178169","rc":[{"atb":[[27,0]],"id":52385913}],"con":true,"img":false}]}
{"op":"mcm","clk":"11550388503","pt":1719497828417,"mc":[{"id":"1.230178169","rc":[{"atl":[[95,0],[55,2.5]],"id":52385912},{"atb":[[6.2,2.5],[5.3,0]],"id":52385889},{"atl":[[36,5],[38,0],[29,2.5],[30,0]],"id":52385892},{"atb":[[10,0],[9.2,0],[11,5],[13,2.5]],"id":52385904},{"atb":[[11,0],[13,0],[15.5,5],[17.5,2.5]],"id":52385907},{"atl":[[44,2.5],[46,0],[55,5],[60,0]],"id":52385921},{"atb":[[10,2.5],[8.4,0]],"id":52385891},{"atb":[[13.5,0],[15.5,0],[19,5],[22,2.5]],"id":52385903},{"atb":[[22,0],[23,8.32],[26,0],[27,2.5]],"id":52385905}],"con":true,"img":false}]}
{"op":"mcm","clk":"11550388563","pt":1719497829098,"mc":[{"id":"1.230178169","rc":[{"atb":[[20,0]],"id":52385903}],"con":true,"img":false}]}
{"op":"mcm","clk":"11550388586","pt":1719497829399,"mc":[{"id":"1.230178169","rc":[{"atb":[[13,21.2]],"id":52385890},{"atl":[[36,0]],"id":52385897}],"con":true,"img":false}]}
{"op":"mcm","clk":"11550388597","pt":1719497829502,"mc":[{"id":"1.230178169","rc":[{"atb":[[14,6]],"id":52385890},{"atl":[[44,13.95]],"id":52385897}],"con":true,"img":false}]}
{"op":"mcm","clk":"11550388657","pt":1719497830223,"mc":[{"id":"1.230178169","rc":[{"atb":[[15.5,0],[16,5],[17.5,0],[18,2.5]],"id":52385912},{"atl":[[40,14.2]],"id":52385897}],"con":true,"img":false}]}
{"op":"mcm","clk":"11550388672","pt":1719497830379,"mc":[{"id":"1.230178169","rc":[{"atl":[[44,0]],"id":52385897}],"con":true,"img":false}]}
{"op":"mcm","clk":"11550388698","pt":1719497830693,"mc":[{"id":"1.230178169","rc":[{"atl":[[70,2.5],[150,0],[90,5],[110,0]],"id":52385899}],"con":true,"img":false}]}
{"op":"mcm","clk":"11550388720","pt":1719497831004,"mc":[{"id":"1.230178169","rc":[{"atl":[[32,15]],"id":52385891}],"con":true,"img":false}]}
{"op":"mcm","clk":"11550388729","pt":1719497831111,"mc":[{"id":"1.230178169","rc":[{"atl":[[23,27.27]],"id":52385889},{"atl":[[46,15.53]],"id":52385907},{"atl":[[40,0]],"id":52385891},{"atl":[[18,22]],"id":52385893},{"atl":[[70,8.7]],"id":52385903}],"con":true,"img":false}]}
{"op":"mcm","clk":"11550388738","pt":1719497831215,"mc":[{"id":"1.230178169","rc":[{"atl":[[25,21.04]],"id":52385911}],"con":true,"img":false}]}
{"op":"mcm","clk":"11550388745","pt":1719497831314,"mc":[{"id":"1.230178169","rc":[{"atl":[[24,0]],"id":52385889},{"atl":[[50,0]],"id":52385907},{"atl":[[19,0]],"id":52385893},{"atl":[[80,0]],"id":52385903}],"con":true,"img":false}]}
{"op":"mcm","clk":"11550388754","pt":1719497831424,"mc":[{"id":"1.230178169","rc":[{"atl":[[27,0]],"id":52385911}],"con":true,"img":false}]}
{"op":"mcm","clk":"11550388788","pt":1719497831831,"mc":[{"id":"1.230178169","rc":[{"atl":[[38,14.2]],"id":52385897}],"con":true,"img":false}]}
{"op":"mcm","clk":"11550388807","pt":1719497831993,"mc":[{"id":"1.230178169","rc":[{"atl":[[40,0]],"id":52385897}],"con":true,"img":false}]}
{"op":"mcm","clk":"11550388829","pt":1719497832203,"mc":[{"id":"1.230178169","rc":[{"atb":[[12,7.6],[7.2,0]],"id":52385906},{"atb":[[10.5,10.53],[8.8,0]],"id":52385920},{"atb":[[7.2,0],[13,6.05]],"id":52385885},{"atb":[[9,10],[6.2,0]],"id":52385904},{"atb":[[10.5,10],[8.8,0]],"id":52385913},{"atb":[[10,10],[6.8,0]],"id":52385907},{"atb":[[11,10],[7,0]],"id":52385886},{"atb":[[8.6,13.16],[5.9,0]],"id":52385882},{"atb":[[17.5,6.06],[6.2,0]],"id":52385884},{"atl":[[38,0]],"id":52385897},{"atb":[[4.5,0],[12,9]],"id":52385903}],"con":true,"img":false}]}
{"op":"mcm","clk":"11550388836","pt":1719497832304,"mc":[{"id":"1.230178169","rc":[{"atl":[[40,14.2]],"id":52385897}],"con":true,"img":false}]}
{"op":"mcm","clk":"11550388946","pt":1719497833700,"mc":[{"id":"1.230178169","rc":[{"atb":[[21,0],[22,5],[25,0],[26,2.5]],"id":52385883}],"con":true,"img":false}]}
{"op":"mcm","clk":"11550388981","pt":1719497834113,"mc":[{"id":"1.230178169","rc":[{"atb":[[19,0]],"id":52385904}],"con":true,"img":false}]}
{"op":"mcm","clk":"11550389080","pt":1719497835096,"mc":[{"id":"1.230178169","rc":[{"atb":[[11,0]],"id":52385914},{"atb":[[13,0]],"id":52385911},{"atb":[[11,0]],"id":52385893}],"con":true,"img":false}]}
{"op":"mcm","clk":"11550389094","pt":1719497835196,"mc":[{"id":"1.230178169","rc":[{"atb":[[12,9]],"id":52385914},{"atb":[[14,8]],"id":52385911},{"atb":[[10,9]],"id":52385893}],"con":true,"img":false}]}
{"op":"mcm","clk":"11550389133","pt":1719497835612,"mc":[{"id":"1.230178169","rc":[{"atl":[[40,0]],"id":52385897}],"con":true,"img":false}]}
{"op":"mcm","clk":"11550389147","pt":1719497835715,"mc":[{"id":"1.230178169","rc":[{"atl":[[42,10]],"id":52385897}],"con":true,"img":false}]}
{"op":"mcm","clk":"11550389272","pt":1719497837317,"mc":[{"id":"1.230178169","rc":[{"atl":[[60,7.68]],"id":52385906}],"con":true,"img":false}]}
{"op":"mcm","clk":"11550389281","pt":1719497837417,"mc":[{"id":"1.230178169","rc":[{"atl":[[42,10]],"id":52385912},{"atb":[[19,15]],"id":52385891},{"atl":[[65,9.38]],"id":52385899}],"con":true,"img":false}]}
{"op":"mcm","clk":"11550389294","pt":1719497837518,"mc":[{"id":"1.230178169","rc":[{"atl":[[70,0]],"id":52385906}],"con":true,"img":false}]}
{"op":"mcm","clk":"11550389304","pt":1719497837621,"mc":[{"id":"1.230178169","rc":[{"atl":[[60,0]],"id":52385912},{"atb":[[17,4.21]],"id":52385891},{"atl":[[75,0]],"id":52385899}],"con":true,"img":false}]}
{"op":"mcm","clk":"11550389316","pt":1719497837726,"mc":[{"id":"1.230178169","rc":[{"atl":[[17.5,22],[18,0]],"id":52385893}],"con":true,"img":false}]}
{"op":"mcm","clk":"11550389366","pt":1719497838193,"mc":[{"id":"1.230178169","rc":[{"atb":[[16,0]],"id":52385910},{"atb":[[12,0]],"id":52385918},{"atb":[[10,0]],"id":52385892}],"con":true,"img":false}]}
{"op":"mcm","clk":"11550389375","pt":1719497838292,"mc":[{"id":"1.230178169","rc":[{"atb":[[18,6]],"id":52385910},{"atb":[[13,8]],"id":52385918},{"atb":[[11,10]],"id":52385892}],"con":true,"img":false}]}
{"op":"mcm","clk":"11550389497","pt":1719497839740,"mc":[{"id":"1.230178169","rc":[{"atb":[[6.8,12.2],[14.5,0],[16.5,3.6],[25,0],[8.8,0]],"id":52385910},{"atl":[[80,2],[100,0]],"id":52385910},{"atb":[[10,0],[8.4,13.22]],"id":52385912},{"atb":[[12,0]],"id":52385906},{"atl":[[140,2],[170,0]],"id":52385906},{"atb":[[2.56,64.1],[6,2]],"id":52385918},{"atl":[[32,0],[38,2.5],[40,0],[24,0]],"id":52385918},{"atb":[[10.5,0],[8.8,12.82],[29,0]],"id":52385920},{"atl":[[70,5],[80,0],[50,2.5],[60,0]],"id":52385920},{"atb":[[12,33.2],[2.98,50.51],[5.2,0]],"id":52385889},{"atl":[[36,0],[50,2.04]],"id":52385889},{"atb":[[15.5,0]],"id":52385914},{"atl":[[75,0],[50,2.04]],"id":52385914},{"atb":[[38,0],[12.5,0]],"id":52385883},{"atl":[[160,2],[200,0]],"id":52385883},{"atb":[[10,7.1],[13,0]],"id":52385885},{"atl":[[65,12.77],[140,0],[160,2],[85,5],[100,0],[230,0]],"id":52385885},{"atl":[[140,2],[160,0]],"id":52385896},{"atb":[[10,2.5],[9.6,0],[16,19.4],[6,2],[8.8,0]],"id":52385890},{"atl":[[34,0],[42,0],[46,0],[25,0],[100,2]],"id":52385890},{"atb":[[5.9,0]],"id":52385892},{"atl":[[36,0],[22,0],[46,2.5],[95,2],[29,0],[60,5]],"id":52385892},{"atb":[[10.5,7.7]],"id":52385904},{"atl":[[75,2]],"id":52385904},{"atb":[[8,14.29],[13,0]],"id":52385898},{"atl":[[190,2]],"id":52385898},{"atb":[[9,0]],"id":52385900},{"atl":[[70,2.5],[75,2],[150,2],[90,5],[55,11.11],[110,0]],"id":52385900},{"atb":[[6,2],[4.2,31.25]],"id":52385911},{"atb":[[10.5,0],[8.4,11],[29,0]],"id":52385913},{"atl":[[140,0],[50,2.5],[110,2]],"id":52385913},{"atb":[[10,0],[7.8,10],[29,0]],"id":52385907},{"atl":[[75,7]],"id":52385907},{"atb":[[11,0],[27,0],[8.4,11]],"id":52385886},{"atl":[[65,2.5],[140,0],[75,0],[85,5],[95,0],[110,2]],"id":52385886},{"atb":[[10,0],[7,10]],"id":52385919},{"atl":[[40,0]],"id":52385919},{"atb":[[8.2,0],[6.8,12],[20,0]],"id":52385921},{"atl":[[80,2],[100,0]],"id":52385921},{"atb":[[8.6,0],[19,0],[6.8,17.24]],"id":52385882},{"atb":[[32,0],[17.5,0],[10.5,10.53]],"id":52385884},{"atl":[[270,0],[70,8.7],[190,2]],"id":52385884},{"atb":[[7.2,16.11],[24,0],[8.8,0]],"id":52385917},{"atb":[[7.2,0]],"id":52385897},{"atl":[[65,2.5],[140,2],[80,0],[42,0],[46,0],[60,0]],"id":52385897},{"atb":[[6.6,0]],"id":52385891},{"atl":[[65,0],[34,0],[42,0],[50,2.5],[110,2]],"id":52385891},{"atb":[[12,22],[6.8,2.5],[5.1,0],[6,7]],"id":52385893},{"atl":[[32,0],[17.5,0],[70,2]],"id":52385893},{"atb":[[38,0],[19,0],[22,0],[12,0],[8.8,10]],"id":52385903},{"atl":[[130,2],[160,0]],"id":52385903},{"atb":[[42,0]],"id":52385905},{"atl":[[180,2],[210,0]],"id":52385905},{"atb":[[12.5,0]],"id":52385899},{"atl":[[70,0]],"id":52385899}],"con":true,"img":false}]}
{"op":"mcm","clk":"11550389511","pt":1719497839844,"mc":[{"id":"1.230178169","rc":[{"atl":[[85,2],[120,0]],"id":52385912},{"atl":[[130,0],[85,2]],"id":52385920},{"atb":[[9,0]],"id":52385904},{"atl":[[90,0]],"id":52385904},{"atl":[[240,0]],"id":52385898},{"atb":[[3.1,47.62]],"id":52385900},{"atl":[[25,0]],"id":52385911},{"atl":[[110,0]],"id":52385907},{"atl":[[90,2],[110,0]],"id":52385919},{"atl":[[65,2],[90,0]],"id":52385882},{"atl":[[70,2],[95,0]],"id":52385917},{"atb":[[2.58,63.29]],"id":52385891},{"atb":[[5.8,0],[5.4,0]],"id":52385893},{"atl":[[23,0],[27,0]],"id":52385893},{"atb":[[12,0],[14.5,7.41]],"id":52385905},{"atb":[[3.55,39.22]],"id":52385899}],"con":true,"img":false}]}
{"op":"mcm","clk":"11550389514","pt":1719497839894,"mc":[{"id":"1.230178169","rc":[{"atb":[[32,0]],"id":52385896},{"atl":[[65,7],[70,0],[48,2.5],[50,0]],"id":52385882},{"atl":[[70,11.2],[90,5]],"id":52385903}],"con":true,"img":false}]}
{"op":"mcm","clk":"11550389524","pt":1719497840001,"mc":[{"id":"1.230178169","rc":[{"atb":[[18,30.2],[10,5],[12,2.5]],"id":52385910},{"atb":[[12.5,7.6]],"id":52385906},{"atl":[[29,24.43]],"id":52385918},{"atb":[[19,25]],"id":52385920},{"atb":[[9.2,6.3],[12,0]],"id":52385889},{"atb":[[12,44.24]],"id":52385914},{"atb":[[13,8],[28,16]],"id":52385883},{"atb":[[13,0]],"id":52385890},{"atl":[[70,5],[38,16.7],[50,2.5]],"id":52385890},{"atl":[[55,11.11]],"id":52385892},{"atl":[[55,0]],"id":52385900},{"atb":[[17.5,17]],"id":52385913},{"atb":[[21,23]],"id":52385907},{"atb":[[20,23]],"id":52385886},{"atl":[[50,11.4]],"id":52385919},{"atb":[[13,22]],"id":52385921},{"atb":[[13,30]],"id":52385882},{"atb":[[25,16]],"id":52385884},{"atl":[[110,0]],"id":52385884},{"atb":[[16.5,24.22]],"id":52385917},{"atl":[[65,11.88]],"id":52385897},{"atl":[[32,0]],"id":52385891},{"atl":[[34,2.5],[42,5],[23,7.09]],"id":52385893},{"atb":[[21,23]],"id":52385903},{"atl":[[75,2],[95,0]],"id":52385903},{"atb":[[28,21.22]],"id":52385905},{"atl":[[65,0]],"id":52385899}],"con":true,"img":false}]}
{"op":"mcm","clk":"11550389533","pt":1719497840103,"mc":[{"id":"1.230178169","rc":[{"atb":[[30,18.04]],"id":52385896},{"atl":[[70,0],[34,10.04],[55,2]],"id":52385911},{"atb":[[13,30]],"id":52385921},{"atb":[[13,38]],"id":52385882},{"atb":[[11,5],[13,2.5]],"id":52385903}],"con":true,"img":false}]}
{"op":"mcm","clk":"11550389542","pt":1719497840205,"mc":[{"id":"1.230178169","rc":[{"atb":[[9.2,30.1]],"id":52385889},{"atb":[[27,10]],"id":52385900},{"atl":[[60,10]],"id":52385900},{"atl":[[28,22]],"id":52385921},{"atl":[[100,6.06]],"id":52385891},{"atl":[[23,0]],"id":52385893},{"atl":[[85,7.14]],"id":52385899}],"con":true,"img":false}]}
{"op":"mcm","clk":"11550389551","pt":1719497840308,"mc":[{"id":"1.230178169","rc":[{"atb":[[26,0]],"id":52385900},{"atl":[[32,19.35]],"id":52385893}],"con":true,"img":false}]}
{"op":"mcm","clk":"11550389559","pt":1719497840409,"mc":[{"id":"1.230178169","rc":[{"atl":[[34,3]],"id":52385921}],"con":true,"img":false}]}
{"op":"mcm","clk":"11550389572","pt":1719497840517,"mc":[{"id":"1.230178169","rc":[{"atl":[[28,0]],"id":52385921}],"con":true,"img":false}]}
{"op":"mcm","clk":"11550389577","pt":1719497840617,"mc":[{"id":"1.230178169","rc":[{"atl":[[32,18]],"id":52385921}],"con":true,"img":false}]}
{"op":"mcm","clk":"11550389605","pt":1719497841034,"mc":[{"id":"1.230178169","rc":[{"atb":[[16,0]],"id":52385917}],"con":true,"img":false}]}
{"op":"mcm","clk":"11550389617","pt":1719497841086,"mc":[{"id":"1.230178169","rc":[{"atb":[[18,6]],"id":52385917}],"con":true,"img":false}]}
{"op":"mcm","clk":"11550389628","pt":1719497841204,"mc":[{"id":"1.230178169","rc":[{"atb":[[16.5,0],[18,30.22]],"id":52385917}],"con":true,"img":false}]}
{"op":"mcm","clk":"11550389825","pt":1719497843624,"mc":[{"id":"1.230178169","rc":[{"atl":[[130,0],[85,2.5],[95,0],[110,5]],"id":52385883},{"atl":[[75,5],[80,0],[55,5.4],[60,0]],"id":52385919}],"con":true,"img":false}]}
{"op":"mcm","clk":"11550389844","pt":1719497843828,"mc":[{"id":"1.230178169","rc":[{"atl":[[150,5],[160,0],[110,2.5],[120,0]],"id":52385898}],"con":true,"img":false}]}
{"op":"mcm","clk":"11550389929","pt":1719497844607,"mc":[{"id":"1.230178169","rc":[{"atb":[[19,0]],"id":52385891}],"con":true,"img":false}]}
{"op":"mcm","clk":"11550389942","pt":1719497844717,"mc":[{"id":"1.230178169","rc":[{"atb":[[30,0]],"id":52385906},{"atb":[[3.1,0],[2.42,70.42]],"id":52385900},{"atb":[[17.5,0],[15.5,0]],"id":52385907},{"atb":[[18.5,10]],"id":52385891},{"atl":[[48,12.77]],"id":52385891}],"con":true,"img":false}]}
{"op":"mcm","clk":"11550389947","pt":1719497844811,"mc":[{"id":"1.230178169","rc":[{"atl":[[75,5],[80,0],[100,0],[55,2.5]],"id":52385906},{"atb":[[10,5],[12,2.5]],"id":52385907},{"atl":[[75,5],[160,0],[95,5],[120,0]],"id":52385884},{"atb":[[16.5,2.5],[11.5,0],[13.5,0],[14.5,5]],"id":52385897},{"atl":[[65,5],[48,15.27],[50,0]],"id":52385891}],"con":true,"img":false}]}
{"op":"mcm","clk":"11550389956","pt":1719497844915,"mc":[{"id":"1.230178169","rc":[{"atb":[[21,21.4]],"id":52385906},{"atl":[[30,20.69]],"id":52385911},{"atb":[[18.5,0]],"id":52385891},{"atl":[[100,0]],"id":52385891}],"con":true,"img":false}]}
{"op":"mcm","clk":"11550389974","pt":1719497845123,"mc":[{"id":"1.230178169","rc":[{"atl":[[42,0]],"id":52385912},{"atb":[[18.5,13.44]],"id":52385891},{"atb":[[3.55,0],[3.15,46.51]],"id":52385899}],"con":true,"img":false}]}
{"op":"mcm","clk":"11550389984","pt":1719497845227,"mc":[{"id":"1.230178169","rc":[{"atl":[[50,12.24]],"id":52385912},{"atl":[[34,0]],"id":52385911}],"con":true,"img":false}]}
{"op":"mcm","clk":"11550390063","pt":1719497846104,"mc":[{"id":"1.230178169","rc":[{"atb":[[6.8,0],[8.4,8.6]],"id":52385910},{"atl":[[65,7],[80,0]],"id":52385910},{"atb":[[10.5,10],[8.4,0]],"id":52385912},{"atl":[[140,0],[110,2]],"id":52385906},{"atb":[[2.56,0],[3.7,37.04]],"id":52385918},{"atb":[[11,10],[8.8,0]],"id":52385920},{"atb":[[2.98,0],[4.2,31.25]],"id":52385889},{"atl":[[38,2.7],[50,0]],"id":52385889},{"atl":[[40,2.56],[50,0],[28,3.4]],"id":52385914},{"atl":[[130,2],[160,0]],"id":52385883},{"atb":[[10,0],[12.5,6.05]],"id":52385885},{"atl":[[130,2],[160,0]],"id":52385885},{"atl":[[140,0],[110,2]],"id":52385896},{"atl":[[75,2],[100,0]],"id":52385890},{"atl":[[70,2],[95,0]],"id":52385892},{"atb":[[8,0],[12.5,8.7]],"id":52385898},{"atb":[[5.7,21.28],[4.2,0]],"id":52385911},{"atb":[[10.5,10],[8.4,0]],"id":52385913},{"atl":[[85,2],[110,0]],"id":52385913},{"atb":[[7.8,0],[9.4,10]],"id":52385907},{"atb":[[10.5,8.1],[8.4,0]],"id":52385886},{"atl":[[90,2],[110,0]],"id":52385886},{"atb":[[8.4,7.8],[7,0]],"id":52385919},{"atb":[[6.8,0],[8.4,13.51]],"id":52385882},{"atb":[[7.2,0],[9.2,12.2]],"id":52385917},{"atl":[[38,2.7]],"id":52385917},{"atl":[[140,0],[110,2]],"id":52385897},{"atb":[[18.5,0]],"id":52385891},{"atb":[[10,0]],"id":52385893},{"atl":[[70,0],[55,2]],"id":52385893},{"atb":[[10.5,10],[8.8,0]],"id":52385903},{"atl":[[130,0],[100,2]],"id":52385903},{"atl":[[130,2],[180,0]],"id":52385905}],"con":true,"img":false}]}
{"op":"mcm","clk":"11550390070","pt":1719497846203,"mc":[{"id":"1.230178169","rc":[{"atl":[[29,21.43]],"id":52385914},{"atl":[[150,0],[120,2]],"id":52385900},{"atb":[[6.8,0],[8.8,8.5]],"id":52385921},{"atl":[[65,2],[80,0]],"id":52385921},{"atb":[[10.5,0],[13.5,8]],"id":52385884},{"atl":[[150,2],[190,0]],"id":52385884},{"atb":[[16.5,13.44]],"id":52385891},{"atb":[[12,31]],"id":52385893}],"con":true,"img":false}]}
{"op":"mcm","clk":"11550390079","pt":1719497846306,"mc":[{"id":"1.230178169","rc":[{"atl":[[40,15.38]],"id":52385917},{"atb":[[2.58,0],[3.15,46.51]],"id":52385891}],"con":true,"img":false}]}
{"op":"mcm","clk":"11550390290","pt":1719497849036,"mc":[{"id":"1.230178169","rc":[{"atl":[[70,5],[75,2],[50,2.5],[55,0]],"id":52385907}],"con":true,"img":false}]}
{"op":"mcm","clk":"11550390335","pt":1719497849552,"mc":[{"id":"1.230178169","rc":[{"atl":[[29,0]],"id":52385914}],"con":true,"img":false}]}
{"op":"mcm","clk":"11550390370","pt":1719497850071,"mc":[{"id":"1.230178169","rc":[{"atl":[[65,5]],"id":52385910},{"atb":[[10.5,0]],"id":52385912},{"atl":[[75,0],[85,0],[180,2],[55,0]],"id":52385912},{"atl":[[70,2.5],[75,0],[90,5],[55,0],[110,0]],"id":52385906},{"atl":[[38,0]],"id":52385918},{"atl":[[85,0],[120,2]],"id":52385920},{"atb":[[6.2,0],[5.5,22.22]],"id":52385914},{"atl":[[40,0]],"id":52385914},{"atb":[[15,7.1]],"id":52385885},{"atl":[[80,2.5],[100,5]],"id":52385885},{"atb":[[19,0],[19.5,5],[22,0],[23,6.52]],"id":52385896},{"atb":[[3.3,43.48]],"id":52385890},{"atl":[[75,0],[60,2]],"id":52385890},{"atb":[[4.1,32.26]],"id":52385892},{"atl":[[65,2],[70,0]],"id":52385892},{"atl":[[46,0],[60,0]],"id":52385904},{"atl":[[250,2]],"id":52385898},{"atb":[[5.7,0]],"id":52385911},{"atl":[[32,0],[75,2],[40,0],[55,0]],"id":52385911},{"atb":[[10.5,0],[13.5,8]],"id":52385913},{"atl":[[140,2],[85,0],[50,0]],"id":52385913},{"atl":[[90,0],[120,2]],"id":52385886},{"atl":[[140,2],[75,0],[55,2.9]],"id":52385919},{"atb":[[9.6,8.5],[8.8,0]],"id":52385921},{"atl":[[70,0],[90,2]],"id":52385917},{"atb":[[2.06,94.34]],"id":52385897},{"atl":[[48,12.77]],"id":52385897},{"atl":[[34,0],[42,0],[24,24.5],[55,0],[28,5]],"id":52385893},{"atl":[[270,2],[160,5],[90,0],[120,2.5]],"id":52385899}],"con":true,"img":false}]}
{"op":"mcm","clk":"11550390379","pt":1719497850122,"mc":[{"id":"1.230178169","rc":[{"atl":[[85,2.5],[110,5]],"id":52385912},{"atl":[[160,2]],"id":52385906},{"atl":[[34,2.5],[42,5]],"id":52385918},{"atb":[[12.5,0]],"id":52385885},{"atl":[[65,10.27],[85,0]],"id":52385885},{"atb":[[9,10],[10.5,0],[23,0]],"id":52385904},{"atl":[[40,2.5],[42,14.63],[48,5]],"id":52385904},{"atb":[[12.5,0]],"id":52385898},{"atl":[[190,0]],"id":52385898},{"atb":[[2.42,0]],"id":52385900},{"atl":[[90,5]],"id":52385913},{"atl":[[75,0],[95,2]],"id":52385907},{"atb":[[8.4,0]],"id":52385919},{"atl":[[65,2.5],[85,5],[90,0]],"id":52385919},{"atb":[[4.4,29.41]],"id":52385893},{"atl":[[42,2.44]],"id":52385893},{"atb":[[3.15,0]],"id":52385899},{"atl":[[180,0]],"id":52385899}],"con":true,"img":false}]}
{"op":"mcm","clk":"11550390388","pt":1719497850235,"mc":[{"id":"1.230178169","rc":[{"atb":[[16.5,0]],"id":52385910},{"atl":[[44,0],[110,2]],"id":52385910},{"atl":[[60,5.68]],"id":52385906},{"atb":[[18.5,0]],"id":52385920},{"atl":[[29,2.5]],"id":52385889},{"atb":[[10,2.5]],"id":52385914},{"atl":[[70,2]],"id":52385914},{"atb":[[27,0]],"id":52385883},{"atb":[[27,0]],"id":52385885},{"atb":[[23,2.5]],"id":52385896},{"atb":[[15.5,0]],"id":52385890},{"atb":[[21,0]],"id":52385904},{"atl":[[44,0]],"id":52385904},{"atb":[[9.8,11.36]],"id":52385898},{"atb":[[23,0]],"id":52385900},{"atb":[[3.75,36.36]],"id":52385911},{"atl":[[36,0],[42,2.5],[50,5]],"id":52385911},{"atb":[[14.5,0]],"id":52385913},{"atl":[[46,13.33]],"id":52385907},{"atb":[[16,0]],"id":52385886},{"atl":[[60,0]],"id":52385886},{"atb":[[5,25]],"id":52385919},{"atl":[[55,0]],"id":52385919},{"atb":[[12.5,0]],"id":52385921},{"atl":[[34,0]],"id":52385921},{"atb":[[10.5,5]],"id":52385882},{"atb":[[24,5]],"id":52385884},{"atl":[[75,2.5]],"id":52385884},{"atb":[[14,2.5]],"id":52385917},{"atb":[[18.5,0]],"id":52385897},{"atl":[[65,2.49],[70,0]],"id":52385897},{"atb":[[11.5,0]],"id":52385893},{"atl":[[32,0],[38,2.7],[42,0]],"id":52385893},{"atl":[[75,0]],"id":52385903},{"atb":[[23,5]],"id":52385905},{"atl":[[80,0]],"id":52385905},{"atb":[[28,0]],"id":52385899}],"con":true,"img":false}]}
{"op":"mcm","clk":"11550390397","pt":1719497850341,"mc":[{"id":"1.230178169","rc":[{"atl":[[42,0]],"id":52385910},{"atl":[[50,0]],"id":52385912},{"atb":[[20,20]],"id":52385904}],"con":true,"img":false}]}
{"op":"mcm","clk":"11550390406","pt":1719497850439,"mc":[{"id":"1.230178169","rc":[{"atb":[[18.5,5.2]],"id":52385910},{"atl":[[40,2.81],[44,13.95]],"id":52385910},{"atl":[[65,11.38]],"id":52385912},{"atl":[[55,2.91]],"id":52385906},{"atb":[[19,0],[19.5,4.4]],"id":52385920},{"atl":[[22,3.5]],"id":52385889},{"atb":[[12.5,5.7]],"id":52385914},{"atb":[[29,2.9]],"id":52385883},{"atb":[[28,0],[29,3]],"id":52385885},{"atb":[[32,2]],"id":52385896},{"atb":[[16.5,3.4]],"id":52385890},{"atl":[[36,3.4]],"id":52385892},{"atb":[[24,2.6]],"id":52385904},{"atb":[[28,3.3]],"id":52385900},{"atl":[[29,2.92],[30,0]],"id":52385911},{"atb":[[18,4.1]],"id":52385913},{"atl":[[46,0]],"id":52385907},{"atb":[[21,3]],"id":52385886},{"atl":[[65,4.5],[55,0]],"id":52385886},{"atl":[[48,2.56],[50,0]],"id":52385919},{"atb":[[13.5,4]],"id":52385921},{"atl":[[32,0],[30,2.31]],"id":52385921},{"atb":[[13.5,5.78]],"id":52385882},{"atb":[[26,3.16]],"id":52385884},{"atb":[[18.5,4.27]],"id":52385917},{"atb":[[19,0],[19.5,2.73]],"id":52385897},{"atl":[[60,2.9]],"id":52385897},{"atl":[[46,2]],"id":52385891},{"atb":[[12.5,4.04]],"id":52385893},{"atl":[[30,3.44]],"id":52385893},{"atl":[[90,7]],"id":52385903},{"atb":[[29,3.9]],"id":52385905},{"atl":[[75,0],[85,4.5]],"id":52385905},{"atb":[[29,0],[30,4]],"id":52385899}],"con":true,"img":false}]}
