{"op":"mcm","clk":"11536832973","pt":1719431775494,"mc":[{"id":"1.230180120","marketDefinition":{"bspMarket":true,"turnInPlayEnabled":false,"persistenceEnabled":false,"marketBaseRate":5.0,"eventId":"33376437","eventTypeId":"4339","numberOfWinners":1,"bettingType":"ODDS","marketType":"WIN","marketTime":"2024-06-27T14:49:00.000Z","suspendTime":"2024-06-27T14:49:00.000Z","bspReconciled":false,"complete":true,"inPlay":false,"crossMatching":false,"runnersVoidable":false,"numberOfActiveRunners":6,"betDelay":0,"status":"OPEN","runners":[{"status":"ACTIVE","sortPriority":1,"id":64536702,"name":"1. Rocket Jay"},{"status":"ACTIVE","sortPriority":2,"id":69112387,"name":"2. Salacres Pacino"},{"status":"ACTIVE","sortPriority":3,"id":47370245,"name":"3. Salacres Palermo"},{"status":"ACTIVE","sortPriority":4,"id":53432239,"name":"4. Bell Rock"},{"status":"ACTIVE","sortPriority":5,"id":62847579,"name":"5. Lamornascruffles"},{"status":"ACTIVE","sortPriority":6,"id":64253834,"name":"6. Mind The Mikey"}],"regulators":["MR_INT"],"venue":"Towcester","countryCode":"GB","discountAllowed":false,"timezone":"Europe/London","openDate":"2024-06-27T13:33:00.000Z","version":5994767077,"name":"D4 270m","eventName":"Towcester 27th Jun"},"rc":[],"con":true,"img":false}]}
{"op":"mcm","clk":"11536833114","pt":1719431777494,"mc":[{"id":"1.230180120","marketDefinition":{"bspMarket":true,"turnInPlayEnabled":false,"persistenceEnabled":false,"marketBaseRate":5.0,"eventId":"33376437","eventTypeId":"4339","numberOfWinners":1,"bettingType":"ODDS","marketType":"WIN","marketTime":"2024-06-27T14:49:00.000Z","suspendTime":"2024-06-27T14:49:00.000Z","bspReconciled":false,"complete":true,"inPlay":false,"crossMatching":false,"runnersVoidable":false,"numberOfActiveRunners":6,"betDelay":0,"status":"OPEN","runners":[{"status":"ACTIVE","sortPriority":1,"id":64536702,"name":"1. Rocket Jay"},{"status":"ACTIVE","sortPriority":2,"id":69112387,"name":"2. Salacres Pacino"},{"status":"ACTIVE","sortPriority":3,"id":47370245,"name":"3. Salacres Palermo"},{"status":"ACTIVE","sortPriority":4,"id":53432239,"name":"4. Bell Rock"},{"status":"ACTIVE","sortPriority":5,"id":62847579,"name":"5. Lamornascruffles"},{"status":"ACTIVE","sortPriority":6,"id":64253834,"name":"6. Mind The Mikey"}],"regulators":["MR_INT"],"venue":"Towcester","countryCode":"GB","discountAllowed":true,"timezone":"Europe/London","openDate":"2024-06-27T13:33:00.000Z","version":5994767077,"name":"D4 270m","eventName":"Towcester 27th Jun"},"rc":[],"con":true,"img":false}]}
{"op":"mcm","clk":"11537083779","pt":1719435431098,"mc":[{"id":"1.230180120","rc":[{"atb":[[1.03,10.99]],"id":62847579},{"atl":[[990,0.84]],"id":62847579},{"spn":495.51,"spf":"NaN","id":62847579},{"atb":[[1.02,16.48]],"id":53432239},{"atl":[[990,0.84]],"id":53432239},{"spn":495.51,"spf":"NaN","id":53432239},{"atb":[[1.03,10.99]],"id":47370245},{"atl":[[1000,0.84]],"id":47370245},{"spn":500.51,"spf":"NaN","id":47370245},{"atb":[[1.03,10.99]],"id":64536702},{"atl":[[1000,0.84]],"id":64536702},{"spn":500.51,"spf":"NaN","id":64536702},{"atb":[[1.02,16.48]],"id":69112387},{"atl":[[990,0.84]],"id":69112387},{"spn":495.51,"spf":"NaN","id":69112387},{"atb":[[1.02,16.48]],"id":64253834},{"atl":[[990,0.84]],"id":64253834},{"spn":495.51,"spf":"NaN","id":64253834}],"con":true,"img":false}]}
{"op":"mcm","clk":"11537233737","pt":1719437882657,"mc":[{"id":"1.230180120","marketDefinition":{"bspMarket":true,"turnInPlayEnabled":false,"persistenceEnabled":false,"marketBaseRate":5.0,"eventId":"33376437","eventTypeId":"4339","numberOfWinners":1,"bettingType":"ODDS","marketType":"WIN","marketTime":"2024-06-27T14:49:00.000Z","suspendTime":"2024-06-27T14:49:00.000Z","bspReconciled":false,"complete":true,"inPlay":false,"crossMatching":false,"runnersVoidable":false,"numberOfActiveRunners":6,"betDelay":0,"status":"OPEN","runners":[{"status":"ACTIVE","sortPriority":1,"id":64536702,"name":"1. Rocket Jay"},{"status":"ACTIVE","sortPriority":2,"id":69112387,"name":"2. Salacres Pacino"},{"status":"ACTIVE","sortPriority":3,"id":47370245,"name":"3. Salacres Palermo"},{"status":"ACTIVE","sortPriority":4,"id":53432239,"name":"4. Bell Rock"},{"status":"ACTIVE","sortPriority":5,"id":62847579,"name":"5. Lamornascruffles"},{"status":"ACTIVE","sortPriority":6,"id":64253834,"name":"6. Mind The Mikey"}],"regulators":["MR_INT"],"venue":"Towcester","countryCode":"GB","discountAllowed":true,"timezone":"Europe/London","openDate":"2024-06-27T13:33:00.000Z","version":5994767077,"name":"D4 270m","eventName":"Towcester 27th Jun"},"rc":[{"atb":[[1.03,10.99]],"id":62847579},{"atl":[[990,0.84]],"id":62847579},{"spn":495.51,"spf":"NaN","id":62847579},{"atb":[[1.02,16.48]],"id":53432239},{"atl":[[990,0.84]],"id":53432239},{"spn":495.51,"spf":"NaN","id":53432239},{"atb":[[1.03,10.99]],"id":47370245},{"atl":[[1000,0.84]],"id":47370245},{"spn":500.51,"spf":"NaN","id":47370245},{"atb":[[1.03,10.99]],"id":64536702},{"atl":[[1000,0.84]],"id":64536702},{"spn":500.51,"spf":"NaN","id":64536702},{"atb":[[1.02,16.48]],"id":69112387},{"atl":[[990,0.84]],"id":69112387},{"spn":495.51,"spf":"NaN","id":69112387},{"atb":[[1.02,16.48]],"id":64253834},{"atl":[[990,0.84]],"id":64253834},{"spn":495.51,"spf":"NaN","id":64253834}],"con":true,"img":true}]}
{"op":"mcm","clk":"11537302022","pt":1719439028437,"mc":[{"id":"1.230180120","rc":[{"atb":[[1.03,10.99]],"id":62847579},{"atl":[[990,0.17]],"id":62847579},{"atb":[[1.02,16.48]],"id":53432239},{"atl":[[990,0.17]],"id":53432239},{"atb":[[1.03,10.99]],"id":47370245},{"atl":[[1000,0.17]],"id":47370245},{"atb":[[1.03,10.99]],"id":64536702},{"atl":[[1000,0.17]],"id":64536702},{"atb":[[1.02,16.48]],"id":69112387},{"atl":[[990,0.17]],"id":69112387},{"atb":[[1.02,16.48]],"id":64253834},{"atl":[[990,0.17]],"id":64253834}],"con":true,"img":false}]}
{"op":"mcm","clk":"11537574888","pt":1719443282707,"mc":[{"id":"1.230180120","marketDefinition":{"bspMarket":true,"turnInPlayEnabled":false,"persistenceEnabled":false,"marketBaseRate":5.0,"eventId":"33376437","eventTypeId":"4339","numberOfWinners":1,"bettingType":"ODDS","marketType":"WIN","marketTime":"2024-06-27T14:49:00.000Z","suspendTime":"2024-06-27T14:49:00.000Z","bspReconciled":false,"complete":true,"inPlay":false,"crossMatching":false,"runnersVoidable":false,"numberOfActiveRunners":6,"betDelay":0,"status":"OPEN","runners":[{"status":"ACTIVE","sortPriority":1,"id":64536702,"name":"1. Rocket Jay"},{"status":"ACTIVE","sortPriority":2,"id":69112387,"name":"2. Salacres Pacino"},{"status":"ACTIVE","sortPriority":3,"id":47370245,"name":"3. Salacres Palermo"},{"status":"ACTIVE","sortPriority":4,"id":53432239,"name":"4. Bell Rock"},{"status":"ACTIVE","sortPriority":5,"id":62847579,"name":"5. Lamornascruffles"},{"status":"ACTIVE","sortPriority":6,"id":64253834,"name":"6. Mind The Mikey"}],"regulators":["MR_INT"],"venue":"Towcester","countryCode":"GB","discountAllowed":true,"timezone":"Europe/London","openDate":"2024-06-27T13:33:00.000Z","version":5994767077,"name":"D4 270m","eventName":"Towcester 27th Jun"},"rc":[{"atb":[[1.03,10.99]],"id":62847579},{"atl":[[990,0.17]],"id":62847579},{"spn":495.51,"spf":"NaN","id":62847579},{"atb":[[1.02,16.48]],"id":53432239},{"atl":[[990,0.17]],"id":53432239},{"spn":495.51,"spf":"NaN","id":53432239},{"atb":[[1.03,10.99]],"id":47370245},{"atl":[[1000,0.17]],"id":47370245},{"spn":500.51,"spf":"NaN","id":47370245},{"atb":[[1.03,10.99]],"id":64536702},{"atl":[[1000,0.17]],"id":64536702},{"spn":500.51,"spf":"NaN","id":64536702},{"atb":[[1.02,16.48]],"id":69112387},{"atl":[[990,0.17]],"id":69112387},{"spn":495.51,"spf":"NaN","id":69112387},{"atb":[[1.02,16.48]],"id":64253834},{"atl":[[990,0.17]],"id":64253834},{"spn":495.51,"spf":"NaN","id":64253834}],"con":true,"img":true}]}
{"op":"mcm","clk":"11537956508","pt":1719448682748,"mc":[{"id":"1.230180120","marketDefinition":{"bspMarket":true,"turnInPlayEnabled":false,"persistenceEnabled":false,"marketBaseRate":5.0,"eventId":"33376437","eventTypeId":"4339","numberOfWinners":1,"bettingType":"ODDS","marketType":"WIN","marketTime":"2024-06-27T14:49:00.000Z","suspendTime":"2024-06-27T14:49:00.000Z","bspReconciled":false,"complete":true,"inPlay":false,"crossMatching":false,"runnersVoidable":false,"numberOfActiveRunners":6,"betDelay":0,"status":"OPEN","runners":[{"status":"ACTIVE","sortPriority":1,"id":64536702,"name":"1. Rocket Jay"},{"status":"ACTIVE","sortPriority":2,"id":69112387,"name":"2. Salacres Pacino"},{"status":"ACTIVE","sortPriority":3,"id":47370245,"name":"3. Salacres Palermo"},{"status":"ACTIVE","sortPriority":4,"id":53432239,"name":"4. Bell Rock"},{"status":"ACTIVE","sortPriority":5,"id":62847579,"name":"5. Lamornascruffles"},{"status":"ACTIVE","sortPriority":6,"id":64253834,"name":"6. Mind The Mikey"}],"regulators":["MR_INT"],"venue":"Towcester","countryCode":"GB","discountAllowed":true,"timezone":"Europe/London","openDate":"2024-06-27T13:33:00.000Z","version":5994767077,"name":"D4 270m","eventName":"Towcester 27th Jun"},"rc":[{"atb":[[1.03,10.99]],"id":62847579},{"atl":[[990,0.17]],"id":62847579},{"spn":495.51,"spf":"NaN","id":62847579},{"atb":[[1.02,16.48]],"id":53432239},{"atl":[[990,0.17]],"id":53432239},{"spn":495.51,"spf":"NaN","id":53432239},{"atb":[[1.03,10.99]],"id":47370245},{"atl":[[1000,0.17]],"id":47370245},{"spn":500.51,"spf":"NaN","id":47370245},{"atb":[[1.03,10.99]],"id":64536702},{"atl":[[1000,0.17]],"id":64536702},{"spn":500.51,"spf":"NaN","id":64536702},{"atb":[[1.02,16.48]],"id":69112387},{"atl":[[990,0.17]],"id":69112387},{"spn":495.51,"spf":"NaN","id":69112387},{"atb":[[1.02,16.48]],"id":64253834},{"atl":[[990,0.17]],"id":64253834},{"spn":495.51,"spf":"NaN","id":64253834}],"con":true,"img":true}]}
{"op":"mcm","clk":"11538172125","pt":1719454082691,"mc":[{"id":"1.230180120","marketDefinition":{"bspMarket":true,"turnInPlayEnabled":false,"persistenceEnabled":false,"marketBaseRate":5.0,"eventId":"33376437","eventTypeId":"4339","numberOfWinners":1,"bettingType":"ODDS","marketType":"WIN","marketTime":"2024-06-27T14:49:00.000Z","suspendTime":"2024-06-27T14:49:00.000Z","bspReconciled":false,"complete":true,"inPlay":false,"crossMatching":false,"runnersVoidable":false,"numberOfActiveRunners":6,"betDelay":0,"status":"OPEN","runners":[{"status":"ACTIVE","sortPriority":1,"id":64536702,"name":"1. Rocket Jay"},{"status":"ACTIVE","sortPriority":2,"id":69112387,"name":"2. Salacres Pacino"},{"status":"ACTIVE","sortPriority":3,"id":47370245,"name":"3. Salacres Palermo"},{"status":"ACTIVE","sortPriority":4,"id":53432239,"name":"4. Bell Rock"},{"status":"ACTIVE","sortPriority":5,"id":62847579,"name":"5. Lamornascruffles"},{"status":"ACTIVE","sortPriority":6,"id":64253834,"name":"6. Mind The Mikey"}],"regulators":["MR_INT"],"venue":"Towcester","countryCode":"GB","discountAllowed":true,"timezone":"Europe/London","openDate":"2024-06-27T13:33:00.000Z","version":5994767077,"name":"D4 270m","eventName":"Towcester 27th Jun"},"rc":[{"atb":[[1.03,10.99]],"id":62847579},{"atl":[[990,0.17]],"id":62847579},{"spn":495.51,"spf":"NaN","id":62847579},{"atb":[[1.02,16.48]],"id":53432239},{"atl":[[990,0.17]],"id":53432239},{"spn":495.51,"spf":"NaN","id":53432239},{"atb":[[1.03,10.99]],"id":47370245},{"atl":[[1000,0.17]],"id":47370245},{"spn":500.51,"spf":"NaN","id":47370245},{"atb":[[1.03,10.99]],"id":64536702},{"atl":[[1000,0.17]],"id":64536702},{"spn":500.51,"spf":"NaN","id":64536702},{"atb":[[1.02,16.48]],"id":69112387},{"atl":[[990,0.17]],"id":69112387},{"spn":495.51,"spf":"NaN","id":69112387},{"atb":[[1.02,16.48]],"id":64253834},{"atl":[[990,0.17]],"id":64253834},{"spn":495.51,"spf":"NaN","id":64253834}],"con":true,"img":true}]}
{"op":"mcm","clk":"11538369792","pt":1719459482777,"mc":[{"id":"1.230180120","marketDefinition":{"bspMarket":true,"turnInPlayEnabled":false,"persistenceEnabled":false,"marketBaseRate":5.0,"eventId":"33376437","eventTypeId":"4339","numberOfWinners":1,"bettingType":"ODDS","marketType":"WIN","marketTime":"2024-06-27T14:49:00.000Z","suspendTime":"2024-06-27T14:49:00.000Z","bspReconciled":false,"complete":true,"inPlay":false,"crossMatching":false,"runnersVoidable":false,"numberOfActiveRunners":6,"betDelay":0,"status":"OPEN","runners":[{"status":"ACTIVE","sortPriority":1,"id":64536702,"name":"1. Rocket Jay"},{"status":"ACTIVE","sortPriority":2,"id":69112387,"name":"2. Salacres Pacino"},{"status":"ACTIVE","sortPriority":3,"id":47370245,"name":"3. Salacres Palermo"},{"status":"ACTIVE","sortPriority":4,"id":53432239,"name":"4. Bell Rock"},{"status":"ACTIVE","sortPriority":5,"id":62847579,"name":"5. Lamornascruffles"},{"status":"ACTIVE","sortPriority":6,"id":64253834,"name":"6. Mind The Mikey"}],"regulators":["MR_INT"],"venue":"Towcester","countryCode":"GB","discountAllowed":true,"timezone":"Europe/London","openDate":"2024-06-27T13:33:00.000Z","version":5994767077,"name":"D4 270m","eventName":"Towcester 27th Jun"},"rc":[{"atb":[[1.03,10.99]],"id":62847579},{"atl":[[990,0.17]],"id":62847579},{"spn":495.51,"spf":"NaN","id":62847579},{"atb":[[1.02,16.48]],"id":53432239},{"atl":[[990,0.17]],"id":53432239},{"spn":495.51,"spf":"NaN","id":53432239},{"atb":[[1.03,10.99]],"id":47370245},{"atl":[[1000,0.17]],"id":47370245},{"spn":500.51,"spf":"NaN","id":47370245},{"atb":[[1.03,10.99]],"id":64536702},{"atl":[[1000,0.17]],"id":64536702},{"spn":500.51,"spf":"NaN","id":64536702},{"atb":[[1.02,16.48]],"id":69112387},{"atl":[[990,0.17]],"id":69112387},{"spn":495.51,"spf":"NaN","id":69112387},{"atb":[[1.02,16.48]],"id":64253834},{"atl":[[990,0.17]],"id":64253834},{"spn":495.51,"spf":"NaN","id":64253834}],"con":true,"img":true}]}
{"op":"mcm","clk":"11538596922","pt":1719464882721,"mc":[{"id":"1.230180120","marketDefinition":{"bspMarket":true,"turnInPlayEnabled":false,"persistenceEnabled":false,"marketBaseRate":5.0,"eventId":"33376437","eventTypeId":"4339","numberOfWinners":1,"bettingType":"ODDS","marketType":"WIN","marketTime":"2024-06-27T14:49:00.000Z","suspendTime":"2024-06-27T14:49:00.000Z","bspReconciled":false,"complete":true,"inPlay":false,"crossMatching":false,"runnersVoidable":false,"numberOfActiveRunners":6,"betDelay":0,"status":"OPEN","runners":[{"status":"ACTIVE","sortPriority":1,"id":64536702,"name":"1. Rocket Jay"},{"status":"ACTIVE","sortPriority":2,"id":69112387,"name":"2. Salacres Pacino"},{"status":"ACTIVE","sortPriority":3,"id":47370245,"name":"3. Salacres Palermo"},{"status":"ACTIVE","sortPriority":4,"id":53432239,"name":"4. Bell Rock"},{"status":"ACTIVE","sortPriority":5,"id":62847579,"name":"5. Lamornascruffles"},{"status":"ACTIVE","sortPriority":6,"id":64253834,"name":"6. Mind The Mikey"}],"regulators":["MR_INT"],"venue":"Towcester","countryCode":"GB","discountAllowed":true,"timezone":"Europe/London","openDate":"2024-06-27T13:33:00.000Z","version":5994767077,"name":"D4 270m","eventName":"Towcester 27th Jun"},"rc":[{"atb":[[1.03,10.99]],"id":62847579},{"atl":[[990,0.17]],"id":62847579},{"spn":495.51,"spf":"NaN","id":62847579},{"atb":[[1.02,16.48]],"id":53432239},{"atl":[[990,0.17]],"id":53432239},{"spn":495.51,"spf":"NaN","id":53432239},{"atb":[[1.03,10.99]],"id":47370245},{"atl":[[1000,0.17]],"id":47370245},{"spn":500.51,"spf":"NaN","id":47370245},{"atb":[[1.03,10.99]],"id":64536702},{"atl":[[1000,0.17]],"id":64536702},{"spn":500.51,"spf":"NaN","id":64536702},{"atb":[[1.02,16.48]],"id":69112387},{"atl":[[990,0.17]],"id":69112387},{"spn":495.51,"spf":"NaN","id":69112387},{"atb":[[1.02,16.48]],"id":64253834},{"atl":[[990,0.17]],"id":64253834},{"spn":495.51,"spf":"NaN","id":64253834}],"con":true,"img":true}]}
{"op":"mcm","clk":"11538714067","pt":1719467363355,"mc":[{"id":"1.230180120","rc":[{"atb":[[1.03,10.99]],"id":62847579},{"atl":[[150,4]],"id":62847579},{"spn":75.51,"spf":"NaN","id":62847579},{"atb":[[1.02,16.48]],"id":53432239},{"atl":[[150,4]],"id":53432239},{"spn":75.51,"spf":"NaN","id":53432239},{"atb":[[1.03,10.99]],"id":47370245},{"atl":[[150,4]],"id":47370245},{"spn":75.51,"spf":"NaN","id":47370245},{"atb":[[1.03,10.99]],"id":64536702},{"atl":[[150,4]],"id":64536702},{"spn":75.51,"spf":"NaN","id":64536702},{"atb":[[1.02,16.48]],"id":69112387},{"atl":[[150,4]],"id":69112387},{"spn":75.51,"spf":"NaN","id":69112387},{"atb":[[1.02,16.48]],"id":64253834}],"con":true,"img":false}]}
{"op":"mcm","clk":"11538714071","pt":1719467363455,"mc":[{"id":"1.230180120","rc":[{"atl":[[150,4]],"id":64253834}],"con":true,"img":false}]}
{"op":"mcm","clk":"11538748560","pt":1719468203723,"mc":[{"id":"1.230180120","rc":[{"atb":[[2.1,13.45]],"id":62847579},{"spn":76.05,"spf":"NaN","id":62847579},{"atb":[[2,11.96]],"id":53432239},{"spn":76.0,"spf":"NaN","id":53432239},{"atb":[[2.06,10.56]],"id":47370245},{"spn":76.03,"spf":"NaN","id":47370245},{"atb":[[2.04,9.58]],"id":64536702},{"spn":76.02,"spf":"NaN","id":64536702},{"atb":[[2.04,12.2]],"id":69112387},{"spn":76.02,"spf":"NaN","id":69112387},{"atb":[[2.06,11.44]],"id":64253834},{"spn":76.03,"spf":"NaN","id":64253834}],"con":true,"img":false}]}
{"op":"mcm","clk":"11538750892","pt":1719468251872,"mc":[{"id":"1.230180120","rc":[{"atb":[[2.02,3.16]],"id":53432239}],"con":true,"img":false}]}
{"op":"mcm","clk":"11538750910","pt":1719468252080,"mc":[{"id":"1.230180120","rc":[{"atb":[[2.08,3.16]],"id":47370245}],"con":true,"img":false}]}
{"op":"mcm","clk":"11538750941","pt":1719468252484,"mc":[{"id":"1.230180120","rc":[{"atb":[[2.06,3.16]],"id":64536702}],"con":true,"img":false}]}
{"op":"mcm","clk":"11538750955","pt":1719468252644,"mc":[{"id":"1.230180120","rc":[{"atb":[[2.08,3.16]],"id":64253834}],"con":true,"img":false}]}
{"op":"mcm","clk":"11538750985","pt":1719468253256,"mc":[{"id":"1.230180120","rc":[{"atb":[[2.12,3.16]],"id":62847579}],"con":true,"img":false}]}
{"op":"mcm","clk":"11538751001","pt":1719468253463,"mc":[{"id":"1.230180120","rc":[{"atb":[[2.06,3.16]],"id":69112387}],"con":true,"img":false}]}
{"op":"mcm","clk":"11538752373","pt":1719468281734,"mc":[{"id":"1.230180120","marketDefinition":{"bspMarket":true,"turnInPlayEnabled":false,"persistenceEnabled":false,"marketBaseRate":5.0,"eventId":"33376437","eventTypeId":"4339","numberOfWinners":1,"bettingType":"ODDS","marketType":"WIN","marketTime":"2024-06-27T14:49:00.000Z","suspendTime":"2024-06-27T14:49:00.000Z","bspReconciled":false,"complete":true,"inPlay":false,"crossMatching":true,"runnersVoidable":false,"numberOfActiveRunners":6,"betDelay":0,"status":"OPEN","runners":[{"status":"ACTIVE","sortPriority":1,"id":64536702,"name":"1. Rocket Jay"},{"status":"ACTIVE","sortPriority":2,"id":69112387,"name":"2. Salacres Pacino"},{"status":"ACTIVE","sortPriority":3,"id":47370245,"name":"3. Salacres Palermo"},{"status":"ACTIVE","sortPriority":4,"id":53432239,"name":"4. Bell Rock"},{"status":"ACTIVE","sortPriority":5,"id":62847579,"name":"5. Lamornascruffles"},{"status":"ACTIVE","sortPriority":6,"id":64253834,"name":"6. Mind The Mikey"}],"regulators":["MR_INT"],"venue":"Towcester","countryCode":"GB","discountAllowed":true,"timezone":"Europe/London","openDate":"2024-06-27T13:33:00.000Z","version":5994767077,"name":"D4 270m","eventName":"Towcester 27th Jun"},"rc":[],"con":true,"img":false}]}
{"op":"mcm","clk":"11538753052","pt":1719468293732,"mc":[{"id":"1.230180120","rc":[{"spn":76.06,"spf":"NaN","id":62847579},{"spn":76.01,"spf":"NaN","id":53432239},{"atb":[[2.08,6.55]],"id":47370245},{"spn":76.04,"spf":"NaN","id":47370245},{"atb":[[2.06,6.55]],"id":64536702},{"spn":76.03,"spf":"NaN","id":64536702},{"spn":76.03,"spf":"NaN","id":69112387},{"spn":76.04,"spf":"NaN","id":64253834}],"con":true,"img":false}]}
{"op":"mcm","clk":"11538753068","pt":1719468294039,"mc":[{"id":"1.230180120","rc":[{"atb":[[2.06,6.55]],"id":69112387}],"con":true,"img":false}]}
{"op":"mcm","clk":"11538753082","pt":1719468294300,"mc":[{"id":"1.230180120","rc":[{"atb":[[2.12,6.55]],"id":62847579}],"con":true,"img":false}]}
{"op":"mcm","clk":"11538753097","pt":1719468294501,"mc":[{"id":"1.230180120","rc":[{"atb":[[2.08,6.55]],"id":64253834}],"con":true,"img":false}]}
{"op":"mcm","clk":"11538753135","pt":1719468295219,"mc":[{"id":"1.230180120","rc":[{"atb":[[2.02,6.55]],"id":53432239}],"con":true,"img":false}]}
{"op":"mcm","clk":"11538940517","pt":1719472110233,"mc":[{"id":"1.230180120","rc":[{"atb":[[1.03,10.98],[2.12,6.54],[2.1,0]],"id":62847579},{"atl":[[990,0.17]],"id":62847579},{"atb":[[2,0],[2.02,6.54],[1.02,16.47]],"id":53432239},{"atl":[[990,0.17]],"id":53432239},{"atb":[[2.06,0],[1.03,10.98],[2.08,6.54]],"id":47370245},{"atl":[[1000,0.17]],"id":47370245},{"atb":[[2.06,6.54],[1.03,10.98],[2.04,0]],"id":64536702},{"atl":[[1000,0.17]],"id":64536702},{"atb":[[2.06,6.54],[2.04,0],[1.02,16.47]],"id":69112387},{"atl":[[990,0.17]],"id":69112387},{"atb":[[2.06,0],[1.02,16.47],[2.08,6.54]],"id":64253834},{"atl":[[990,0.17]],"id":64253834}],"con":true,"img":false}]}
{"op":"mcm","clk":"11538940525","pt":1719472110284,"mc":[{"id":"1.230180120","rc":[{"atb":[[2.14,13.44]],"id":62847579},{"atb":[[2.04,11.95]],"id":53432239},{"atb":[[2.1,10.55]],"id":47370245},{"atb":[[2.08,9.58]],"id":64536702},{"atb":[[2.08,12.19]],"id":69112387},{"atb":[[2.1,11.43]],"id":64253834}],"con":true,"img":false}]}
{"op":"mcm","clk":"11538943749","pt":1719472161169,"mc":[{"id":"1.230180120","rc":[{"atb":[[2.06,3.38]],"id":69112387}],"con":true,"img":false}]}
{"op":"mcm","clk":"11538943756","pt":1719472161272,"mc":[{"id":"1.230180120","rc":[{"atb":[[2.06,3.38]],"id":64536702}],"con":true,"img":false}]}
{"op":"mcm","clk":"11538943766","pt":1719472161477,"mc":[{"id":"1.230180120","rc":[{"atb":[[2.02,3.38]],"id":53432239}],"con":true,"img":false}]}
{"op":"mcm","clk":"11538943784","pt":1719472161785,"mc":[{"id":"1.230180120","rc":[{"atb":[[2.08,3.38]],"id":47370245}],"con":true,"img":false}]}
{"op":"mcm","clk":"11538943859","pt":1719472163016,"mc":[{"id":"1.230180120","rc":[{"atb":[[2.12,3.16]],"id":47370245}],"con":true,"img":false}]}
{"op":"mcm","clk":"11538943938","pt":1719472164096,"mc":[{"id":"1.230180120","rc":[{"atb":[[2.08,3.38]],"id":64253834}],"con":true,"img":false}]}
{"op":"mcm","clk":"11538943984","pt":1719472164819,"mc":[{"id":"1.230180120","rc":[{"atb":[[2.1,3.16]],"id":69112387}],"con":true,"img":false}]}
{"op":"mcm","clk":"11538944009","pt":1719472165177,"mc":[{"id":"1.230180120","rc":[{"atb":[[2.06,3.16]],"id":53432239}],"con":true,"img":false}]}
{"op":"mcm","clk":"11538944013","pt":1719472165279,"mc":[{"id":"1.230180120","rc":[{"atb":[[2.1,3.16]],"id":64536702}],"con":true,"img":false}]}
{"op":"mcm","clk":"11538944048","pt":1719472165994,"mc":[{"id":"1.230180120","rc":[{"atb":[[2.12,3.16]],"id":64253834}],"con":true,"img":false}]}
{"op":"mcm","clk":"11538944095","pt":1719472166813,"mc":[{"id":"1.230180120","rc":[{"atb":[[2.12,3.38]],"id":62847579}],"con":true,"img":false}]}
{"op":"mcm","clk":"11538944125","pt":1719472167221,"mc":[{"id":"1.230180120","rc":[{"atb":[[2.16,3.16]],"id":62847579}],"con":true,"img":false}]}
{"op":"mcm","clk":"11538944836","pt":1719472179032,"mc":[{"id":"1.230180120","rc":[{"spn":76.08,"spf":"NaN","id":62847579},{"spn":76.03,"spf":"NaN","id":53432239},{"spn":76.06,"spf":"NaN","id":47370245},{"atb":[[2.06,0]],"id":64536702},{"spn":76.05,"spf":"NaN","id":64536702},{"spn":76.05,"spf":"NaN","id":69112387},{"spn":76.06,"spf":"NaN","id":64253834}],"con":true,"img":false}]}
{"op":"mcm","clk":"11538944850","pt":1719472179236,"mc":[{"id":"1.230180120","rc":[{"atb":[[2.06,0]],"id":69112387}],"con":true,"img":false}]}
{"op":"mcm","clk":"11538944899","pt":1719472180007,"mc":[{"id":"1.230180120","rc":[{"atb":[[2.08,0]],"id":64253834}],"con":true,"img":false}]}
{"op":"mcm","clk":"11538944929","pt":1719472180523,"mc":[{"id":"1.230180120","rc":[{"atb":[[2.12,0]],"id":62847579}],"con":true,"img":false}]}
{"op":"mcm","clk":"11538944950","pt":1719472180927,"mc":[{"id":"1.230180120","rc":[{"atb":[[2.02,0]],"id":53432239}],"con":true,"img":false}]}
{"op":"mcm","clk":"11538945001","pt":1719472181855,"mc":[{"id":"1.230180120","rc":[{"atb":[[2.08,0]],"id":47370245}],"con":true,"img":false}]}
{"op":"mcm","clk":"11538946023","pt":1719472198260,"mc":[{"id":"1.230180120","rc":[{"atb":[[2.12,6.54]],"id":64253834}],"con":true,"img":false}]}
{"op":"mcm","clk":"11538946094","pt":1719472199336,"mc":[{"id":"1.230180120","rc":[{"atb":[[2.1,6.54]],"id":64536702}],"con":true,"img":false}]}
{"op":"mcm","clk":"11538946176","pt":1719472200730,"mc":[{"id":"1.230180120","rc":[{"atb":[[2.1,6.54]],"id":69112387}],"con":true,"img":false}]}
{"op":"mcm","clk":"11538946265","pt":1719472202223,"mc":[{"id":"1.230180120","rc":[{"atb":[[2.06,6.54]],"id":53432239}],"con":true,"img":false}]}
{"op":"mcm","clk":"11538946278","pt":1719472202530,"mc":[{"id":"1.230180120","rc":[{"atb":[[2.12,6.54]],"id":47370245}],"con":true,"img":false}]}
{"op":"mcm","clk":"11538946298","pt":1719472202838,"mc":[{"id":"1.230180120","rc":[{"atb":[[2.16,6.54]],"id":62847579}],"con":true,"img":false}]}
{"op":"mcm","clk":"11539124110","pt":1719475682707,"mc":[{"id":"1.230180120","marketDefinition":{"bspMarket":true,"turnInPlayEnabled":false,"persistenceEnabled":false,"marketBaseRate":5.0,"eventId":"33376437","eventTypeId":"4339","numberOfWinners":1,"bettingType":"ODDS","marketType":"WIN","marketTime":"2024-06-27T14:49:00.000Z","suspendTime":"2024-06-27T14:49:00.000Z","bspReconciled":false,"complete":true,"inPlay":false,"crossMatching":true,"runnersVoidable":false,"numberOfActiveRunners":6,"betDelay":0,"status":"OPEN","runners":[{"status":"ACTIVE","sortPriority":1,"id":64536702,"name":"1. Rocket Jay"},{"status":"ACTIVE","sortPriority":2,"id":69112387,"name":"2. Salacres Pacino"},{"status":"ACTIVE","sortPriority":3,"id":47370245,"name":"3. Salacres Palermo"},{"status":"ACTIVE","sortPriority":4,"id":53432239,"name":"4. Bell Rock"},{"status":"ACTIVE","sortPriority":5,"id":62847579,"name":"5. Lamornascruffles"},{"status":"ACTIVE","sortPriority":6,"id":64253834,"name":"6. Mind The Mikey"}],"regulators":["MR_INT"],"venue":"Towcester","countryCode":"GB","discountAllowed":true,"timezone":"Europe/London","openDate":"2024-06-27T13:33:00.000Z","version":5994767077,"name":"D4 270m","eventName":"Towcester 27th Jun"},"rc":[{"atb":[[1.03,10.99],[2.16,6.55],[2.14,13.45]],"id":62847579},{"atl":[[150,4],[990,0.17]],"id":62847579},{"spn":76.08,"spf":"NaN","id":62847579},{"atb":[[2.06,6.55],[2.04,11.96],[1.02,16.48]],"id":53432239},{"atl":[[150,4],[990,0.17]],"id":53432239},{"spn":76.03,"spf":"NaN","id":53432239},{"atb":[[1.03,10.99],[2.12,6.55],[2.1,10.55]],"id":47370245},{"atl":[[150,4],[1000,0.17]],"id":47370245},{"spn":76.06,"spf":"NaN","id":47370245},{"atb":[[1.03,10.99],[2.1,6.55],[2.08,9.58]],"id":64536702},{"atl":[[150,4],[1000,0.17]],"id":64536702},{"spn":76.05,"spf":"NaN","id":64536702},{"atb":[[1.02,16.48],[2.1,6.55],[2.08,12.2]],"id":69112387},{"atl":[[150,4],[990,0.17]],"id":69112387},{"spn":76.05,"spf":"NaN","id":69112387},{"atb":[[1.02,16.48],[2.12,6.55],[2.1,11.43]],"id":64253834},{"atl":[[150,4],[990,0.17]],"id":64253834},{"spn":76.06,"spf":"NaN","id":64253834}],"con":true,"img":true}]}
{"op":"mcm","clk":"11539127840","pt":1719475710267,"mc":[{"id":"1.230180120","rc":[{"atb":[[1.03,10.99],[2.16,6.55],[2.14,0]],"id":62847579},{"atb":[[2.06,6.55],[2.04,0],[1.02,16.48]],"id":53432239},{"atb":[[1.03,10.99],[2.12,6.55],[2.1,0]],"id":47370245},{"atb":[[1.03,10.99],[2.1,6.55],[2.08,0]],"id":64536702},{"atb":[[1.02,16.48],[2.1,6.55],[2.08,0]],"id":69112387},{"atb":[[1.02,16.48],[2.12,6.55],[2.1,0]],"id":64253834}],"con":true,"img":false}]}
{"op":"mcm","clk":"11539127848","pt":1719475710368,"mc":[{"id":"1.230180120","rc":[{"atb":[[2.18,13.45]],"id":62847579},{"atb":[[2.08,11.96]],"id":53432239},{"atb":[[2.14,10.55]],"id":47370245},{"atb":[[2.12,9.58]],"id":64536702},{"atb":[[2.12,12.2]],"id":69112387},{"atb":[[2.14,11.43]],"id":64253834}],"con":true,"img":false}]}
{"op":"mcm","clk":"11539134456","pt":1719475812746,"mc":[{"id":"1.230180120","rc":[{"atb":[[2.16,3.38]],"id":62847579},{"spn":76.09,"spf":"NaN","id":62847579},{"atb":[[2.06,3.38]],"id":53432239},{"spn":76.04,"spf":"NaN","id":53432239},{"atb":[[2.12,3.38]],"id":47370245},{"spn":76.07,"spf":"NaN","id":47370245},{"atb":[[2.1,3.38]],"id":64536702},{"spn":76.06,"spf":"NaN","id":64536702},{"atb":[[2.1,3.38]],"id":69112387},{"spn":76.06,"spf":"NaN","id":69112387},{"atb":[[2.12,3.38]],"id":64253834},{"spn":76.07,"spf":"NaN","id":64253834}],"con":true,"img":false}]}
{"op":"mcm","clk":"11539134656","pt":1719475816353,"mc":[{"id":"1.230180120","rc":[{"atb":[[2.1,0]],"id":69112387}],"con":true,"img":false}]}
{"op":"mcm","clk":"11539134682","pt":1719475816768,"mc":[{"id":"1.230180120","rc":[{"atb":[[2.06,0]],"id":53432239}],"con":true,"img":false}]}
{"op":"mcm","clk":"11539134708","pt":1719475817178,"mc":[{"id":"1.230180120","rc":[{"atb":[[2.12,0]],"id":47370245}],"con":true,"img":false}]}
{"op":"mcm","clk":"11539134728","pt":1719475817590,"mc":[{"id":"1.230180120","rc":[{"atb":[[2.12,0]],"id":64253834}],"con":true,"img":false}]}
{"op":"mcm","clk":"11539134821","pt":1719475818984,"mc":[{"id":"1.230180120","rc":[{"atb":[[2.1,0]],"id":64536702}],"con":true,"img":false}]}
{"op":"mcm","clk":"11539134887","pt":1719475820062,"mc":[{"id":"1.230180120","rc":[{"atb":[[2.1,3.38]],"id":53432239}],"con":true,"img":false}]}
{"op":"mcm","clk":"11539134893","pt":1719475820165,"mc":[{"id":"1.230180120","rc":[{"atb":[[2.16,0]],"id":62847579}],"con":true,"img":false}]}
{"op":"mcm","clk":"11539134930","pt":1719475820676,"mc":[{"id":"1.230180120","rc":[{"atb":[[2.14,3.38]],"id":69112387}],"con":true,"img":false}]}
{"op":"mcm","clk":"11539134939","pt":1719475820779,"mc":[{"id":"1.230180120","rc":[{"atb":[[2.16,3.38]],"id":47370245}],"con":true,"img":false}]}
{"op":"mcm","clk":"11539134952","pt":1719475820983,"mc":[{"id":"1.230180120","rc":[{"atb":[[2.16,3.38]],"id":64253834}],"con":true,"img":false}]}
{"op":"mcm","clk":"11539135012","pt":1719475821552,"mc":[{"id":"1.230180120","rc":[{"atb":[[2.2,3.38]],"id":62847579}],"con":true,"img":false}]}
{"op":"mcm","clk":"11539135066","pt":1719475822166,"mc":[{"id":"1.230180120","rc":[{"atb":[[2.14,3.38]],"id":64536702}],"con":true,"img":false}]}
{"op":"mcm","clk":"11539153627","pt":1719476122095,"mc":[{"id":"1.230180120","rc":[{"spn":76.1,"spf":"NaN","id":62847579},{"spn":76.05,"spf":"NaN","id":53432239},{"spn":76.08,"spf":"NaN","id":47370245},{"atb":[[2.14,6.55]],"id":64536702},{"spn":76.07,"spf":"NaN","id":64536702},{"atb":[[2.14,6.55]],"id":69112387},{"spn":76.07,"spf":"NaN","id":69112387},{"spn":76.08,"spf":"NaN","id":64253834}],"con":true,"img":false}]}
{"op":"mcm","clk":"11539153639","pt":1719476122280,"mc":[{"id":"1.230180120","rc":[{"atb":[[2.1,6.55]],"id":53432239}],"con":true,"img":false}]}
{"op":"mcm","clk":"11539153648","pt":1719476122388,"mc":[{"id":"1.230180120","rc":[{"atb":[[2.16,6.55]],"id":47370245}],"con":true,"img":false}]}
{"op":"mcm","clk":"11539153655","pt":1719476122493,"mc":[{"id":"1.230180120","rc":[{"atb":[[2.2,6.55]],"id":62847579}],"con":true,"img":false}]}
{"op":"mcm","clk":"11539153671","pt":1719476122694,"mc":[{"id":"1.230180120","rc":[{"atb":[[2.16,6.55]],"id":64253834}],"con":true,"img":false}]}
{"op":"mcm","clk":"11539269239","pt":1719478174718,"mc":[{"id":"1.230180120","rc":[{"atb":[[2.26,2]],"id":62847579},{"spn":76.13,"spf":"NaN","id":62847579},{"atb":[[2.26,2]],"id":64253834},{"spn":76.13,"spf":"NaN","id":64253834}],"con":true,"img":false}]}
{"op":"mcm","clk":"11539341337","pt":1719479309070,"mc":[{"id":"1.230180120","rc":[{"atb":[[1.03,10.98],[2.18,0],[2.2,6.54]],"id":62847579},{"atb":[[1.02,16.47],[2.1,6.54],[2.08,0]],"id":53432239},{"atb":[[1.03,10.98],[2.16,6.54],[2.14,0]],"id":47370245},{"atb":[[1.03,10.98],[2.12,0],[2.14,6.54]],"id":64536702},{"atb":[[1.02,16.47],[2.12,0],[2.14,6.54]],"id":69112387},{"atb":[[1.02,16.47],[2.16,6.54],[2.14,0]],"id":64253834}],"con":true,"img":false}]}
{"op":"mcm","clk":"11539341340","pt":1719479309165,"mc":[{"id":"1.230180120","rc":[{"atb":[[2.22,13.45]],"id":62847579},{"atb":[[2.12,11.96]],"id":53432239},{"atb":[[2.18,10.55]],"id":47370245},{"atb":[[2.16,9.58]],"id":64536702},{"atb":[[2.16,12.19]],"id":69112387},{"atb":[[2.18,11.43]],"id":64253834}],"con":true,"img":false}]}
{"op":"mcm","clk":"11539347202","pt":1719479403221,"mc":[{"id":"1.230180120","rc":[{"atb":[[2.2,3.38]],"id":62847579},{"spn":76.06,"spf":"NaN","id":53432239},{"spn":76.09,"spf":"NaN","id":47370245},{"spn":76.08,"spf":"NaN","id":64536702},{"spn":76.08,"spf":"NaN","id":69112387}],"con":true,"img":false}]}
{"op":"mcm","clk":"11539347370","pt":1719479405716,"mc":[{"id":"1.230180120","rc":[{"atb":[[2.1,3.38]],"id":53432239}],"con":true,"img":false}]}
{"op":"mcm","clk":"11539347391","pt":1719479406015,"mc":[{"id":"1.230180120","rc":[{"atb":[[2.16,3.38]],"id":47370245}],"con":true,"img":false}]}
{"op":"mcm","clk":"11539347504","pt":1719479407411,"mc":[{"id":"1.230180120","rc":[{"atb":[[2.16,3.38]],"id":64253834}],"con":true,"img":false}]}
{"op":"mcm","clk":"11539347525","pt":1719479407722,"mc":[{"id":"1.230180120","rc":[{"atb":[[2.14,3.38]],"id":64536702}],"con":true,"img":false}]}
{"op":"mcm","clk":"11539347631","pt":1719479409321,"mc":[{"id":"1.230180120","rc":[{"atb":[[2.14,3.38]],"id":69112387}],"con":true,"img":false}]}
{"op":"mcm","clk":"11539350497","pt":1719479454134,"mc":[{"id":"1.230180120","rc":[{"atb":[[2.14,0]],"id":64536702}],"con":true,"img":false}]}
{"op":"mcm","clk":"11539350527","pt":1719479454541,"mc":[{"id":"1.230180120","rc":[{"atb":[[2.16,0]],"id":64253834}],"con":true,"img":false}]}
{"op":"mcm","clk":"11539350552","pt":1719479454851,"mc":[{"id":"1.230180120","rc":[{"atb":[[2.1,0]],"id":53432239},{"atb":[[2.16,0]],"id":47370245}],"con":true,"img":false}]}
{"op":"mcm","clk":"11539350588","pt":1719479455312,"mc":[{"id":"1.230180120","rc":[{"atb":[[2.2,0]],"id":62847579}],"con":true,"img":false}]}
{"op":"mcm","clk":"11539350702","pt":1719479456857,"mc":[{"id":"1.230180120","rc":[{"atb":[[2.14,0]],"id":69112387}],"con":true,"img":false}]}
{"op":"mcm","clk":"11539368065","pt":1719479711856,"mc":[{"id":"1.230180120","rc":[{"atb":[[2.2,3.16]],"id":64253834}],"con":true,"img":false}]}
{"op":"mcm","clk":"11539368111","pt":1719479712470,"mc":[{"id":"1.230180120","rc":[{"atb":[[2.2,3.16]],"id":47370245}],"con":true,"img":false}]}
{"op":"mcm","clk":"11539368126","pt":1719479712676,"mc":[{"id":"1.230180120","rc":[{"atb":[[2.18,3.16]],"id":69112387}],"con":true,"img":false}]}
{"op":"mcm","clk":"11539368159","pt":1719479713038,"mc":[{"id":"1.230180120","rc":[{"atb":[[2.24,3.16]],"id":62847579}],"con":true,"img":false}]}
{"op":"mcm","clk":"11539368175","pt":1719479713247,"mc":[{"id":"1.230180120","rc":[{"atb":[[2.14,3.16]],"id":53432239}],"con":true,"img":false}]}
{"op":"mcm","clk":"11539368279","pt":1719479714480,"mc":[{"id":"1.230180120","rc":[{"atb":[[2.18,3.16]],"id":64536702}],"con":true,"img":false}]}
{"op":"mcm","clk":"11539369831","pt":1719479733783,"mc":[{"id":"1.230180120","rc":[{"atb":[[2.18,6.54]],"id":69112387}],"con":true,"img":false}]}
{"op":"mcm","clk":"11539369837","pt":1719479733885,"mc":[{"id":"1.230180120","rc":[{"atb":[[2.2,6.54]],"id":47370245}],"con":true,"img":false}]}
{"op":"mcm","clk":"11539369855","pt":1719479734200,"mc":[{"id":"1.230180120","rc":[{"atb":[[2.24,6.54]],"id":62847579}],"con":true,"img":false}]}
{"op":"mcm","clk":"11539369879","pt":1719479734501,"mc":[{"id":"1.230180120","rc":[{"atb":[[2.14,6.54]],"id":53432239},{"atb":[[2.18,6.54]],"id":64536702}],"con":true,"img":false}]}
{"op":"mcm","clk":"11539369916","pt":1719479734973,"mc":[{"id":"1.230180120","rc":[{"atb":[[2.2,6.54]],"id":64253834}],"con":true,"img":false}]}
{"op":"mcm","clk":"11539440222","pt":1719481082680,"mc":[{"id":"1.230180120","marketDefinition":{"bspMarket":true,"turnInPlayEnabled":false,"persistenceEnabled":false,"marketBaseRate":5.0,"eventId":"33376437","eventTypeId":"4339","numberOfWinners":1,"bettingType":"ODDS","marketType":"WIN","marketTime":"2024-06-27T14:49:00.000Z","suspendTime":"2024-06-27T14:49:00.000Z","bspReconciled":false,"complete":true,"inPlay":false,"crossMatching":true,"runnersVoidable":false,"numberOfActiveRunners":6,"betDelay":0,"status":"OPEN","runners":[{"status":"ACTIVE","sortPriority":1,"id":64536702,"name":"1. Rocket Jay"},{"status":"ACTIVE","sortPriority":2,"id":69112387,"name":"2. Salacres Pacino"},{"status":"ACTIVE","sortPriority":3,"id":47370245,"name":"3. Salacres Palermo"},{"status":"ACTIVE","sortPriority":4,"id":53432239,"name":"4. Bell Rock"},{"status":"ACTIVE","sortPriority":5,"id":62847579,"name":"5. Lamornascruffles"},{"status":"ACTIVE","sortPriority":6,"id":64253834,"name":"6. Mind The Mikey"}],"regulators":["MR_INT"],"venue":"Towcester","countryCode":"GB","discountAllowed":true,"timezone":"Europe/London","openDate":"2024-06-27T13:33:00.000Z","version":5994767077,"name":"D4 270m","eventName":"Towcester 27th Jun"},"rc":[{"atb":[[2.24,6.54],[1.03,10.98],[2.22,13.45],[2.26,2]],"id":62847579},{"atl":[[150,4],[990,0.17]],"id":62847579},{"spn":76.13,"spf":"NaN","id":62847579},{"atb":[[1.02,16.47],[2.12,11.96],[2.14,6.54]],"id":53432239},{"atl":[[150,4],[990,0.17]],"id":53432239},{"spn":76.07,"spf":"NaN","id":53432239},{"atb":[[1.03,10.98],[2.18,10.55],[2.2,6.54]],"id":47370245},{"atl":[[150,4],[1000,0.17]],"id":47370245},{"spn":76.1,"spf":"NaN","id":47370245},{"atb":[[1.03,10.98],[2.18,6.54],[2.16,9.58]],"id":64536702},{"atl":[[150,4],[1000,0.17]],"id":64536702},{"spn":76.09,"spf":"NaN","id":64536702},{"atb":[[1.02,16.47],[2.18,6.54],[2.16,12.19]],"id":69112387},{"atl":[[150,4],[990,0.17]],"id":69112387},{"spn":76.09,"spf":"NaN","id":69112387},{"atb":[[1.02,16.47],[2.18,11.43],[2.26,2],[2.2,6.54]],"id":64253834},{"atl":[[150,4],[990,0.17]],"id":64253834},{"spn":76.13,"spf":"NaN","id":64253834}],"con":true,"img":true}]}
{"op":"mcm","clk":"11539477206","pt":1719481756757,"mc":[{"id":"1.230180120","rc":[{"atl":[[42,12],[25,8]],"id":53432239},{"spn":13.57,"spf":"NaN","id":53432239},{"atl":[[32,8],[55,12]],"id":47370245},{"spn":17.1,"spf":"NaN","id":47370245},{"atl":[[48,12],[28,8]],"id":64536702},{"spn":15.09,"spf":"NaN","id":64536702},{"atl":[[40,12],[23,8]],"id":69112387},{"spn":12.59,"spf":"NaN","id":69112387}],"con":true,"img":false}]}
{"op":"mcm","clk":"11539545333","pt":1719482908780,"mc":[{"id":"1.230180120","rc":[{"atb":[[2.24,6.54],[1.03,10.98],[2.22,0]],"id":62847579},{"atb":[[1.02,16.47],[2.12,0],[2.14,6.54]],"id":53432239},{"atb":[[1.03,10.98],[2.18,0],[2.2,6.54]],"id":47370245},{"atb":[[1.03,10.98],[2.18,6.54],[2.16,0]],"id":64536702},{"atb":[[1.02,16.47],[2.18,6.54],[2.16,0]],"id":69112387},{"atb":[[1.02,16.47],[2.18,0],[2.2,6.54]],"id":64253834}],"con":true,"img":false}]}
{"op":"mcm","clk":"11539545340","pt":1719482908877,"mc":[{"id":"1.230180120","rc":[{"atb":[[2.26,15.44]],"id":62847579},{"atb":[[2.16,11.95]],"id":53432239},{"atb":[[2.22,10.55]],"id":47370245},{"atb":[[2.2,9.58]],"id":64536702},{"atb":[[2.2,12.19]],"id":69112387},{"atb":[[2.22,11.43]],"id":64253834}],"con":true,"img":false}]}
{"op":"mcm","clk":"11539549531","pt":1719482974599,"mc":[{"id":"1.230180120","rc":[{"atb":[[2.14,3.16]],"id":53432239},{"spn":13.58,"spf":"NaN","id":53432239},{"atb":[[2.2,3.16]],"id":47370245},{"spn":17.11,"spf":"NaN","id":47370245},{"spn":15.1,"spf":"NaN","id":64536702},{"spn":12.6,"spf":"NaN","id":69112387}],"con":true,"img":false}]}
{"op":"mcm","clk":"11539549553","pt":1719482974956,"mc":[{"id":"1.230180120","rc":[{"atb":[[2.18,3.16]],"id":69112387}],"con":true,"img":false}]}
{"op":"mcm","clk":"11539549655","pt":1719482976464,"mc":[{"id":"1.230180120","rc":[{"atb":[[2.2,3.16]],"id":64253834}],"con":true,"img":false}]}
{"op":"mcm","clk":"11539549729","pt":1719482977077,"mc":[{"id":"1.230180120","rc":[{"atb":[[2.18,3.16]],"id":64536702}],"con":true,"img":false}]}
{"op":"mcm","clk":"11539549839","pt":1719482978288,"mc":[{"id":"1.230180120","rc":[{"atb":[[2.24,3.16]],"id":62847579}],"con":true,"img":false}]}
{"op":"mcm","clk":"11539549868","pt":1719482978595,"mc":[{"id":"1.230180120","rc":[{"atb":[[2.24,3.38]],"id":47370245}],"con":true,"img":false}]}
{"op":"mcm","clk":"11539549914","pt":1719482979008,"mc":[{"id":"1.230180120","rc":[{"atb":[[2.18,3.38]],"id":53432239}],"con":true,"img":false}]}
{"op":"mcm","clk":"11539549947","pt":1719482979567,"mc":[{"id":"1.230180120","rc":[{"atb":[[2.24,3.38]],"id":64253834}],"con":true,"img":false}]}
{"op":"mcm","clk":"11539549963","pt":1719482979877,"mc":[{"id":"1.230180120","rc":[{"atb":[[2.22,3.38]],"id":69112387}],"con":true,"img":false}]}
{"op":"mcm","clk":"11539549987","pt":1719482980393,"mc":[{"id":"1.230180120","rc":[{"atb":[[2.28,3.38]],"id":62847579}],"con":true,"img":false}]}
{"op":"mcm","clk":"11539550139","pt":1719482983307,"mc":[{"id":"1.230180120","rc":[{"atb":[[2.22,3.38]],"id":64536702}],"con":true,"img":false}]}
{"op":"mcm","clk":"11539553425","pt":1719483029623,"mc":[{"id":"1.230180120","rc":[{"atb":[[2.24,0]],"id":62847579},{"atb":[[2.14,0]],"id":53432239},{"atb":[[2.2,0]],"id":47370245},{"atb":[[2.18,0]],"id":64536702},{"atb":[[2.18,0]],"id":69112387},{"atb":[[2.2,0]],"id":64253834}],"con":true,"img":false}]}
{"op":"mcm","clk":"11539573554","pt":1719483329227,"mc":[{"id":"1.230180120","rc":[{"spn":76.14,"spf":"NaN","id":62847579},{"spn":13.59,"spf":"NaN","id":53432239},{"atb":[[2.24,6.54]],"id":47370245},{"spn":17.12,"spf":"NaN","id":47370245},{"spn":15.11,"spf":"NaN","id":64536702},{"spn":12.61,"spf":"NaN","id":69112387}],"con":true,"img":false}]}
{"op":"mcm","clk":"11539573575","pt":1719483329531,"mc":[{"id":"1.230180120","rc":[{"atb":[[2.18,6.54]],"id":53432239}],"con":true,"img":false}]}
{"op":"mcm","clk":"11539573593","pt":1719483329738,"mc":[{"id":"1.230180120","rc":[{"atb":[[2.22,6.54]],"id":69112387}],"con":true,"img":false}]}
{"op":"mcm","clk":"11539573602","pt":1719483329840,"mc":[{"id":"1.230180120","rc":[{"atb":[[2.24,6.54]],"id":64253834}],"con":true,"img":false}]}
{"op":"mcm","clk":"11539573617","pt":1719483330050,"mc":[{"id":"1.230180120","rc":[{"atb":[[2.22,6.54]],"id":64536702}],"con":true,"img":false}]}
{"op":"mcm","clk":"11539573642","pt":1719483330461,"mc":[{"id":"1.230180120","rc":[{"atb":[[2.28,6.54]],"id":62847579}],"con":true,"img":false}]}
{"op":"mcm","clk":"11539705787","pt":1719485096651,"mc":[{"id":"1.230180120","rc":[{"atb":[[4.6,6]],"id":62847579},{"spn":77.3,"spf":"NaN","id":62847579},{"atb":[[3.55,6]],"id":53432239},{"spn":14.27,"spf":"NaN","id":53432239},{"atb":[[3.55,6]],"id":47370245},{"spn":17.77,"spf":"NaN","id":47370245},{"atb":[[2.72,6]],"id":64536702},{"spn":15.36,"spf":"NaN","id":64536702},{"atb":[[2,6]],"id":69112387},{"atb":[[3.75,6]],"id":64253834},{"spn":76.87,"spf":"NaN","id":64253834}],"con":true,"img":false}]}
{"op":"mcm","clk":"11539706802","pt":1719485109445,"mc":[{"id":"1.230180120","rc":[{"atb":[[3.8,2]],"id":64253834}],"con":true,"img":false}]}
{"op":"mcm","clk":"11539708211","pt":1719485125598,"mc":[{"id":"1.230180120","rc":[{"atb":[[2.28,3.16]],"id":62847579},{"atb":[[2.18,3.16]],"id":53432239},{"atb":[[2.24,3.16]],"id":47370245},{"atb":[[2.24,3.16]],"id":64253834}],"con":true,"img":false}]}
{"op":"mcm","clk":"11539708708","pt":1719485130921,"mc":[{"id":"1.230180120","rc":[{"atb":[[2.22,3.38]],"id":64536702}],"con":true,"img":false}]}
{"op":"mcm","clk":"11539708720","pt":1719485131021,"mc":[{"id":"1.230180120","rc":[{"atb":[[2.28,0]],"id":62847579},{"atb":[[2.18,0]],"id":53432239},{"atb":[[2.24,0]],"id":47370245},{"atb":[[2.24,0]],"id":64253834}],"con":true,"img":false}]}
{"op":"mcm","clk":"11539708778","pt":1719485131485,"mc":[{"id":"1.230180120","rc":[{"atb":[[2.74,3.16]],"id":64536702}],"con":true,"img":false}]}
{"op":"mcm","clk":"11539726809","pt":1719485344199,"mc":[{"id":"1.230180120","rc":[{"atb":[[5,1]],"id":62847579},{"spn":77.5,"spf":"NaN","id":62847579},{"atb":[[5,1]],"id":53432239},{"spn":15.0,"spf":"NaN","id":53432239},{"atb":[[5,1]],"id":47370245},{"spn":18.5,"spf":"NaN","id":47370245},{"atb":[[4.7,1]],"id":64536702},{"spn":16.35,"spf":"NaN","id":64536702},{"atb":[[2.56,1.44]],"id":69112387},{"spn":12.78,"spf":"NaN","id":69112387},{"atb":[[5,1]],"id":64253834},{"spn":77.5,"spf":"NaN","id":64253834}],"con":true,"img":false}]}
{"op":"mcm","clk":"11539778156","pt":1719486061236,"mc":[{"id":"1.230180120","rc":[{"atb":[[1.03,10.98],[2.12,89.29],[2.26,15.45],[1.51,196.08]],"id":62847579},{"atb":[[1.02,16.47],[1.51,196.08],[2.16,11.96]],"id":53432239},{"atb":[[1.03,10.98],[2.22,10.55],[1.51,196.08]],"id":47370245},{"atb":[[2.74,3.16],[1.03,10.98],[2.22,3.38],[2.2,9.58]],"id":64536702},{"atb":[[2.22,6.54],[1.02,16.47],[2.2,12.19]],"id":69112387},{"atb":[[2.22,11.43],[1.02,16.47],[1.51,196.08]],"id":64253834}],"con":true,"img":false}]}
{"op":"mcm","clk":"11539794655","pt":1719486303869,"mc":[{"id":"1.230180120","rc":[{"atb":[[2.12,89.29]],"id":53432239},{"atb":[[2.12,89.29]],"id":47370245},{"atb":[[1.51,196.08]],"id":64536702},{"atb":[[2.12,89.29]],"id":64253834}],"con":true,"img":false}]}
{"op":"mcm","clk":"11539817329","pt":1719486506285,"mc":[{"id":"1.230180120","rc":[{"atb":[[2.2,0]],"id":69112387}],"con":true,"img":false}]}
{"op":"mcm","clk":"11539817332","pt":1719486506355,"mc":[{"id":"1.230180120","rc":[{"atb":[[2.24,12.19]],"id":69112387}],"con":true,"img":false}]}
{"op":"mcm","clk":"11539819127","pt":1719486525752,"mc":[{"id":"1.230180120","rc":[{"atb":[[2.22,3.38]],"id":69112387}],"con":true,"img":false}]}
{"op":"mcm","clk":"11539819154","pt":1719486526165,"mc":[{"id":"1.230180120","rc":[{"atb":[[2.26,3.16]],"id":69112387}],"con":true,"img":false}]}
{"op":"mcm","clk":"11539825619","pt":1719486602977,"mc":[{"id":"1.230180120","rc":[{"atb":[[2.22,0]],"id":69112387}],"con":true,"img":false}]}
{"op":"mcm","clk":"11539825925","pt":1719486607049,"mc":[{"id":"1.230180120","rc":[{"atb":[[2.26,6.54]],"id":69112387}],"con":true,"img":false}]}
{"op":"mcm","clk":"11539840605","pt":1719486806235,"mc":[{"id":"1.230180120","rc":[{"atb":[[2.24,0]],"id":69112387}],"con":true,"img":false}]}
{"op":"mcm","clk":"11539840611","pt":1719486806330,"mc":[{"id":"1.230180120","rc":[{"atb":[[2.28,12.19]],"id":69112387}],"con":true,"img":false}]}
{"op":"mcm","clk":"11539841572","pt":1719486822232,"mc":[{"id":"1.230180120","rc":[{"atb":[[2.26,3.38]],"id":69112387}],"con":true,"img":false}]}
{"op":"mcm","clk":"11539843175","pt":1719486846168,"mc":[{"id":"1.230180120","rc":[{"atb":[[2.26,0]],"id":69112387}],"con":true,"img":false}]}
{"op":"mcm","clk":"11539848994","pt":1719486928084,"mc":[{"id":"1.230180120","rc":[{"atb":[[2.3,3.38]],"id":69112387}],"con":true,"img":false}]}
{"op":"mcm","clk":"11539850412","pt":1719486946116,"mc":[{"id":"1.230180120","rc":[{"atb":[[2.3,6.54]],"id":69112387}],"con":true,"img":false}]}
{"op":"mcm","clk":"11540014324","pt":1719488998638,"mc":[{"id":"1.230180120","rc":[{"atb":[[1.16,150]],"id":62847579},{"atl":[[560,2]],"id":62847579},{"atb":[[1.16,150]],"id":53432239},{"atl":[[270,2]],"id":53432239},{"atb":[[1.16,150]],"id":47370245},{"atl":[[550,2]],"id":47370245},{"atb":[[1.16,150]],"id":64536702},{"atl":[[370,2]],"id":64536702},{"atb":[[1.16,150]],"id":69112387},{"atl":[[390,2]],"id":69112387},{"atb":[[1.16,150]],"id":64253834},{"atl":[[500,2]],"id":64253834}],"con":true,"img":false}]}
{"op":"mcm","clk":"11540136221","pt":1719490399449,"mc":[{"id":"1.230180120","rc":[{"atb":[[2.74,3.16]],"id":64536702},{"atb":[[2.3,6.54],[2.28,0]],"id":69112387}],"con":true,"img":false}]}
{"op":"mcm","clk":"11540136233","pt":1719490399564,"mc":[{"id":"1.230180120","rc":[{"atb":[[2.32,12.19]],"id":69112387}],"con":true,"img":false}]}
{"op":"mcm","clk":"11540141837","pt":1719490454629,"mc":[{"id":"1.230180120","rc":[{"atb":[[2.3,3.16]],"id":69112387}],"con":true,"img":false}]}
{"op":"mcm","clk":"11540141995","pt":1719490455923,"mc":[{"id":"1.230180120","rc":[{"atb":[[2.34,3.38]],"id":69112387}],"con":true,"img":false}]}
{"op":"mcm","clk":"11540144701","pt":1719490481746,"mc":[{"id":"1.230180120","rc":[{"atb":[[2.3,0]],"id":69112387}],"con":true,"img":false}]}
{"op":"mcm","clk":"11540145832","pt":1719490492674,"mc":[{"id":"1.230180120","rc":[{"atb":[[2.34,6.54]],"id":69112387}],"con":true,"img":false}]}
{"op":"mcm","clk":"11540164641","pt":1719490697366,"mc":[{"id":"1.230180120","rc":[{"atb":[[2.32,0]],"id":69112387}],"con":true,"img":false}]}
{"op":"mcm","clk":"11540164646","pt":1719490697475,"mc":[{"id":"1.230180120","rc":[{"atb":[[2.36,12.19]],"id":69112387}],"con":true,"img":false}]}
{"op":"mcm","clk":"11540168701","pt":1719490748459,"mc":[{"id":"1.230180120","rc":[{"atb":[[2.34,3.38]],"id":69112387}],"con":true,"img":false}]}
{"op":"mcm","clk":"11540168726","pt":1719490748877,"mc":[{"id":"1.230180120","rc":[{"atb":[[2.38,3.16]],"id":69112387}],"con":true,"img":false}]}
{"op":"mcm","clk":"11540171422","pt":1719490788698,"mc":[{"id":"1.230180120","rc":[{"atb":[[2.34,0]],"id":69112387}],"con":true,"img":false}]}
{"op":"mcm","clk":"11540173318","pt":1719490812460,"mc":[{"id":"1.230180120","rc":[{"atb":[[2.38,6.54]],"id":69112387}],"con":true,"img":false}]}
{"op":"mcm","clk":"11540327547","pt":1719493065062,"mc":[{"id":"1.230180120","rc":[{"atb":[[1.04,108.28]],"id":62847579},{"atl":[[970,1.93]],"id":62847579},{"atb":[[1.04,105.74]],"id":53432239},{"atl":[[980,0.86]],"id":53432239},{"atb":[[1.02,90.51]],"id":47370245},{"atl":[[970,2.1]],"id":47370245},{"atb":[[1.04,162.42]],"id":64536702},{"atl":[[990,2.04]],"id":64536702},{"atb":[[1.03,86.28]],"id":69112387},{"atl":[[970,0.86]],"id":69112387},{"atb":[[1.03,225.86]],"id":64253834},{"atl":[[990,1.07]],"id":64253834}],"con":true,"img":false}]}
{"op":"mcm","clk":"11540492606","pt":1719495137806,"mc":[{"id":"1.230180120","rc":[{"atb":[[1.03,11],[2.26,15.46],[1.04,108.41]],"id":62847579},{"atl":[[970,1.93],[990,0.17]],"id":62847579},{"atb":[[1.02,16.49],[2.16,11.97],[1.04,105.86]],"id":53432239},{"atl":[[980,0.86],[990,0.17]],"id":53432239},{"atb":[[1.03,11],[2.22,10.57],[1.02,90.62]],"id":47370245},{"atl":[[970,2.1],[1000,0.17]],"id":47370245},{"atb":[[2.74,3.16],[1.03,11],[2.22,3.38],[2.2,9.59],[1.04,162.61]],"id":64536702},{"atl":[[990,2.04],[1000,0.17]],"id":64536702},{"spl":[[1.01,1]],"id":69112387},{"atb":[[2.36,12.21],[1.03,86.38],[2.38,6.54],[1.02,16.49]],"id":69112387},{"atl":[[970,0.86],[990,0.17]],"id":69112387},{"spn":2.56,"spf":1.0,"id":69112387},{"atb":[[1.03,226.13],[2.22,11.45],[1.02,16.49]],"id":64253834},{"atl":[[990,1.07]],"id":64253834}],"con":true,"img":false}]}
{"op":"mcm","clk":"11540685104","pt":1719497282634,"mc":[{"id":"1.230180120","marketDefinition":{"bspMarket":true,"turnInPlayEnabled":false,"persistenceEnabled":false,"marketBaseRate":5.0,"eventId":"33376437","eventTypeId":"4339","numberOfWinners":1,"bettingType":"ODDS","marketType":"WIN","marketTime":"2024-06-27T14:49:00.000Z","suspendTime":"2024-06-27T14:49:00.000Z","bspReconciled":false,"complete":true,"inPlay":false,"crossMatching":true,"runnersVoidable":false,"numberOfActiveRunners":6,"betDelay":0,"status":"OPEN","runners":[{"status":"ACTIVE","sortPriority":1,"id":64536702,"name":"1. Rocket Jay"},{"status":"ACTIVE","sortPriority":2,"id":69112387,"name":"2. Salacres Pacino"},{"status":"ACTIVE","sortPriority":3,"id":47370245,"name":"3. Salacres Palermo"},{"status":"ACTIVE","sortPriority":4,"id":53432239,"name":"4. Bell Rock"},{"status":"ACTIVE","sortPriority":5,"id":62847579,"name":"5. Lamornascruffles"},{"status":"ACTIVE","sortPriority":6,"id":64253834,"name":"6. Mind The Mikey"}],"regulators":["MR_INT"],"venue":"Towcester","countryCode":"GB","discountAllowed":true,"timezone":"Europe/London","openDate":"2024-06-27T13:33:00.000Z","version":5994767077,"name":"D4 270m","eventName":"Towcester 27th Jun"},"rc":[{"atb":[[5,1],[4.6,6],[1.16,150],[1.03,10.99],[2.12,89.29],[2.26,15.46],[1.51,196.08],[1.04,108.36]],"id":62847579},{"atl":[[560,2],[150,4],[970,1.93],[990,0.17]],"id":62847579},{"spn":77.5,"spf":"NaN","id":62847579},{"atb":[[5,1],[1.16,150],[1.02,16.49],[2.12,89.29],[3.55,6],[1.51,196.08],[2.16,11.97],[1.04,105.82]],"id":53432239},{"atl":[[270,2],[150,4],[42,12],[25,8],[980,0.86],[990,0.17]],"id":53432239},{"spn":15.0,"spf":"NaN","id":53432239},{"atb":[[5,1],[1.16,150],[1.03,10.99],[2.22,10.56],[1.02,90.58],[2.12,89.29],[3.55,6],[1.51,196.08]],"id":47370245},{"atl":[[32,8],[550,2],[150,4],[55,12],[970,2.1],[1000,0.17]],"id":47370245},{"spn":18.5,"spf":"NaN","id":47370245},{"atb":[[2.72,6],[2.74,3.15],[1.16,150],[1.03,10.99],[2.22,3.38],[2.2,9.59],[1.51,196.08],[1.04,162.54],[4.7,1]],"id":64536702},{"atl":[[150,4],[370,2],[48,12],[28,8],[990,2.04],[1000,0.17]],"id":64536702},{"spn":16.35,"spf":"NaN","id":64536702},{"spl":[[1.01,1]],"id":69112387},{"atb":[[2.56,1.44],[2.36,12.2],[2,6],[1.16,150],[1.03,86.35],[2.38,6.54],[1.02,16.49]],"id":69112387},{"atl":[[150,4],[40,12],[23,8],[390,2],[970,0.86],[990,0.17]],"id":69112387},{"spn":2.56,"spf":1.0,"id":69112387},{"atb":[[5,1],[1.16,150],[1.03,226.04],[2.22,11.44],[1.02,16.49],[3.8,2],[2.12,89.29],[2.26,2],[1.51,196.08],[3.75,6]],"id":64253834},{"atl":[[150,4],[990,1.07],[500,2]],"id":64253834},{"spn":77.5,"spf":"NaN","id":64253834}],"con":true,"img":true}]}
{"op":"mcm","clk":"11540712575","pt":1719497555737,"mc":[{"id":"1.230180120","rc":[{"atb":[[1.03,10.99],[2.26,15.46],[1.04,108.36]],"id":62847579},{"atl":[[970,1.93]],"id":62847579},{"atb":[[1.02,16.49],[2.16,11.97],[1.04,105.82]],"id":53432239},{"atl":[[980,0.86]],"id":53432239},{"atb":[[1.03,10.99],[2.22,10.56],[1.02,90.58]],"id":47370245},{"atl":[[970,2.1],[30,1.62]],"id":47370245},{"spn":17.5,"spf":"NaN","id":47370245},{"atb":[[2.74,3.15],[1.03,10.99],[2.22,3.38],[2.2,9.59],[1.04,162.54]],"id":64536702},{"atl":[[990,2.04]],"id":64536702},{"atb":[[2.36,12.2],[1.03,86.35],[2.38,6.54],[1.02,16.49]],"id":69112387},{"atl":[[970,0.86]],"id":69112387},{"atb":[[1.03,226.04],[2.22,11.44],[1.02,16.49]],"id":64253834},{"atl":[[990,1.07]],"id":64253834}],"con":true,"img":false}]}
{"op":"mcm","clk":"11540756789","pt":1719498063877,"mc":[{"id":"1.230180120","rc":[{"atb":[[2.34,2.09]],"id":64253834}],"con":true,"img":false}]}
{"op":"mcm","clk":"11540772003","pt":1719498223231,"mc":[{"id":"1.230180120","rc":[{"atb":[[5,2.02]],"id":47370245}],"con":true,"img":false}]}
{"op":"mcm","clk":"11540773894","pt":1719498241858,"mc":[{"id":"1.230180120","rc":[{"atl":[[190,4]],"id":62847579},{"atl":[[190,4]],"id":53432239},{"atl":[[190,4]],"id":47370245},{"atl":[[190,4]],"id":64536702},{"atl":[[190,4]],"id":69112387}],"con":true,"img":false}]}
{"op":"mcm","clk":"11540773909","pt":1719498241968,"mc":[{"id":"1.230180120","rc":[{"atl":[[190,4]],"id":64253834}],"con":true,"img":false}]}
{"op":"mcm","clk":"11540777519","pt":1719498277214,"mc":[{"id":"1.230180120","rc":[{"atb":[[1.02,2]],"id":64536702}],"con":true,"img":false}]}
{"op":"mcm","clk":"11540777548","pt":1719498277466,"mc":[{"id":"1.230180120","rc":[{"atb":[[2.58,2]],"id":69112387}],"con":true,"img":false}]}
{"op":"mcm","clk":"11540777601","pt":1719498277992,"mc":[{"id":"1.230180120","rc":[{"atb":[[1.02,92.58]],"id":47370245}],"con":true,"img":false}]}
{"op":"mcm","clk":"11540777623","pt":1719498278198,"mc":[{"id":"1.230180120","rc":[{"atb":[[1.02,18.49]],"id":53432239}],"con":true,"img":false}]}
{"op":"mcm","clk":"11540777670","pt":1719498278604,"mc":[{"id":"1.230180120","rc":[{"atb":[[1.02,2]],"id":62847579}],"con":true,"img":false}]}
{"op":"mcm","clk":"11540777712","pt":1719498278911,"mc":[{"id":"1.230180120","rc":[{"atb":[[1.02,18.49]],"id":64253834}],"con":true,"img":false}]}
{"op":"mcm","clk":"11540803662","pt":1719498555099,"mc":[{"id":"1.230180120","rc":[{"atl":[[29,0.84]],"id":47370245},{"spn":17.0,"spf":"NaN","id":47370245},{"spn":2.58,"spf":1.0,"id":69112387}],"con":true,"img":false}]}
{"op":"mcm","clk":"11540809356","pt":1719498614657,"mc":[{"id":"1.230180120","rc":[{"atb":[[5,0]],"id":47370245},{"trd":[[5,4.04]],"ltp":5.0,"tv":4.04,"id":47370245}],"con":true,"img":false}]}
{"op":"mcm","clk":"11540809643","pt":1719498617660,"mc":[{"id":"1.230180120","rc":[{"atl":[[1000,0.21]],"id":47370245},{"spn":16.27,"spf":"NaN","id":47370245}],"con":true,"img":false}]}
{"op":"mcm","clk":"11540809654","pt":1719498617763,"mc":[{"id":"1.230180120","rc":[{"atl":[[1000,0.17]],"id":47370245}],"con":true,"img":false}]}
{"op":"mcm","clk":"11540809665","pt":1719498617866,"mc":[{"id":"1.230180120","rc":[{"atl":[[29,0.88]],"id":47370245}],"con":true,"img":false}]}
{"op":"mcm","clk":"11540809800","pt":1719498619159,"mc":[{"id":"1.230180120","rc":[{"atb":[[4.5,1]],"id":47370245}],"con":true,"img":false}]}
{"op":"mcm","clk":"11540810373","pt":1719498624656,"mc":[{"id":"1.230180120","rc":[{"atb":[[2.16,34.54]],"id":53432239},{"atb":[[2.22,41.81]],"id":47370245},{"atb":[[2.74,16.09]],"id":64536702},{"atb":[[2.38,14.33]],"id":69112387}],"con":true,"img":false}]}
{"op":"mcm","clk":"11540810488","pt":1719498625746,"mc":[{"id":"1.230180120","rc":[{"atb":[[4.5,0]],"id":47370245},{"trd":[[4.5,1.99]],"ltp":4.5,"tv":1.99,"id":47370245}],"con":true,"img":false}]}
{"op":"mcm","clk":"11540810818","pt":1719498629151,"mc":[{"id":"1.230180120","rc":[{"atb":[[4,1]],"id":47370245}],"con":true,"img":false}]}
{"op":"mcm","clk":"11540811044","pt":1719498631487,"mc":[{"id":"1.230180120","rc":[{"atb":[[2.74,12.93]],"id":64536702}],"con":true,"img":false}]}
{"op":"mcm","clk":"11540811064","pt":1719498631703,"mc":[{"id":"1.230180120","rc":[{"atb":[[2.38,11.18]],"id":69112387}],"con":true,"img":false}]}
{"op":"mcm","clk":"11540811086","pt":1719498631853,"mc":[{"id":"1.230180120","rc":[{"atb":[[2.76,3.15]],"id":64536702}],"con":true,"img":false}]}
{"op":"mcm","clk":"11540811105","pt":1719498632063,"mc":[{"id":"1.230180120","rc":[{"atb":[[2.4,3.15]],"id":69112387}],"con":true,"img":false}]}
{"op":"mcm","clk":"11540811206","pt":1719498633047,"mc":[{"id":"1.230180120","rc":[{"atl":[[29,0.84]],"id":47370245}],"con":true,"img":false}]}
{"op":"mcm","clk":"11540811241","pt":1719498633358,"mc":[{"id":"1.230180120","rc":[{"atl":[[1000,0.21]],"id":47370245}],"con":true,"img":false}]}
{"op":"mcm","clk":"11540811263","pt":1719498633565,"mc":[{"id":"1.230180120","rc":[{"atl":[[1000,0.17]],"id":47370245}],"con":true,"img":false}]}
{"op":"mcm","clk":"11540811276","pt":1719498633667,"mc":[{"id":"1.230180120","rc":[{"atl":[[29,0.88]],"id":47370245}],"con":true,"img":false}]}
{"op":"mcm","clk":"11540812371","pt":1719498644695,"mc":[{"id":"1.230180120","rc":[{"atb":[[2.22,0]],"id":64536702}],"con":true,"img":false}]}
{"op":"mcm","clk":"11540812409","pt":1719498645005,"mc":[{"id":"1.230180120","rc":[{"atb":[[2.38,7.79]],"id":69112387}],"con":true,"img":false}]}
{"op":"mcm","clk":"11540812472","pt":1719498645576,"mc":[{"id":"1.230180120","rc":[{"atb":[[2.4,6.54]],"id":69112387}],"con":true,"img":false}]}
{"op":"mcm","clk":"11540812514","pt":1719498645990,"mc":[{"id":"1.230180120","rc":[{"atb":[[2.76,6.54]],"id":64536702}],"con":true,"img":false}]}
{"op":"mcm","clk":"11540812678","pt":1719498647598,"mc":[{"id":"1.230180120","rc":[{"atb":[[2.74,0]],"id":64536702},{"atb":[[2.38,0]],"id":69112387}],"con":true,"img":false}]}
{"op":"mcm","clk":"11540812809","pt":1719498648901,"mc":[{"id":"1.230180120","rc":[{"atl":[[29,0.84]],"id":47370245}],"con":true,"img":false}]}
{"op":"mcm","clk":"11540812834","pt":1719498649215,"mc":[{"id":"1.230180120","rc":[{"atl":[[1000,0.21]],"id":47370245}],"con":true,"img":false}]}
{"op":"mcm","clk":"11540812855","pt":1719498649378,"mc":[{"id":"1.230180120","rc":[{"atl":[[1000,0.17]],"id":47370245}],"con":true,"img":false}]}
{"op":"mcm","clk":"11540812869","pt":1719498649529,"mc":[{"id":"1.230180120","rc":[{"atl":[[29,0.88]],"id":47370245}],"con":true,"img":false}]}
{"op":"mcm","clk":"11540813490","pt":1719498656224,"mc":[{"id":"1.230180120","rc":[{"atb":[[2.24,9.55]],"id":47370245},{"atb":[[2.76,3.38]],"id":64536702},{"atb":[[2.4,3.38]],"id":69112387}],"con":true,"img":false}]}
{"op":"mcm","clk":"11540813505","pt":1719498656380,"mc":[{"id":"1.230180120","rc":[{"atb":[[2.02,11.61]],"id":69112387},{"atb":[[2.24,9.55]],"id":64253834}],"con":true,"img":false}]}
{"op":"mcm","clk":"11540813521","pt":1719498656587,"mc":[{"id":"1.230180120","rc":[{"atb":[[2.28,9.25]],"id":62847579}],"con":true,"img":false}]}
{"op":"mcm","clk":"11540813530","pt":1719498656690,"mc":[{"id":"1.230180120","rc":[{"atb":[[2.18,10.03]],"id":53432239}],"con":true,"img":false}]}
{"op":"mcm","clk":"11540813593","pt":1719498657521,"mc":[{"id":"1.230180120","rc":[{"atb":[[2.26,2.09]],"id":53432239},{"atb":[[2.32,2.09]],"id":47370245}],"con":true,"img":false}]}
{"op":"mcm","clk":"11540814207","pt":1719498664606,"mc":[{"id":"1.230180120","rc":[{"atl":[[29,0.84]],"id":47370245}],"con":true,"img":false}]}
{"op":"mcm","clk":"11540814304","pt":1719498665800,"mc":[{"id":"1.230180120","rc":[{"atl":[[1000,0.21]],"id":47370245}],"con":true,"img":false}]}
{"op":"mcm","clk":"11540814319","pt":1719498666011,"mc":[{"id":"1.230180120","rc":[{"atl":[[1000,0.17]],"id":47370245}],"con":true,"img":false}]}
{"op":"mcm","clk":"11540814329","pt":1719498666112,"mc":[{"id":"1.230180120","rc":[{"atl":[[29,0.88]],"id":47370245}],"con":true,"img":false}]}
{"op":"mcm","clk":"11540814868","pt":1719498671943,"mc":[{"id":"1.230180120","rc":[{"atb":[[2.16,11.97]],"id":53432239},{"atb":[[2.22,10.56]],"id":47370245}],"con":true,"img":false}]}
{"op":"mcm","clk":"11540815081","pt":1719498674421,"mc":[{"id":"1.230180120","rc":[{"atb":[[2.74,3.15]],"id":64536702},{"atb":[[2.38,3.15]],"id":69112387}],"con":true,"img":false}]}
{"op":"mcm","clk":"11540815774","pt":1719498681340,"mc":[{"id":"1.230180120","rc":[{"atl":[[29,0.84]],"id":47370245},{"spn":16.5,"spf":"NaN","id":47370245}],"con":true,"img":false}]}
{"op":"mcm","clk":"11540815791","pt":1719498681547,"mc":[{"id":"1.230180120","rc":[{"atl":[[1000,0.21]],"id":47370245}],"con":true,"img":false}]}
{"op":"mcm","clk":"11540815815","pt":1719498681707,"mc":[{"id":"1.230180120","rc":[{"atl":[[1000,0.17]],"id":47370245}],"con":true,"img":false}]}
{"op":"mcm","clk":"11540815823","pt":1719498681808,"mc":[{"id":"1.230180120","rc":[{"atl":[[29,0.88]],"id":47370245}],"con":true,"img":false}]}
{"op":"mcm","clk":"11540816026","pt":1719498684049,"mc":[{"id":"1.230180120","rc":[{"atb":[[2.76,0]],"id":64536702},{"atb":[[2.4,0]],"id":69112387}],"con":true,"img":false}]}
{"op":"mcm","clk":"11540817212","pt":1719498697035,"mc":[{"id":"1.230180120","rc":[{"atl":[[29,0.84]],"id":47370245}],"con":true,"img":false}]}
{"op":"mcm","clk":"11540817245","pt":1719498697343,"mc":[{"id":"1.230180120","rc":[{"atl":[[1000,0.21]],"id":47370245}],"con":true,"img":false}]}
{"op":"mcm","clk":"11540817262","pt":1719498697549,"mc":[{"id":"1.230180120","rc":[{"atl":[[1000,0.17]],"id":47370245}],"con":true,"img":false}]}
{"op":"mcm","clk":"11540817273","pt":1719498697654,"mc":[{"id":"1.230180120","rc":[{"atl":[[29,0.88]],"id":47370245}],"con":true,"img":false}]}
{"op":"mcm","clk":"11540818563","pt":1719498712908,"mc":[{"id":"1.230180120","rc":[{"atl":[[29,0.84]],"id":47370245}],"con":true,"img":false}]}
{"op":"mcm","clk":"11540818710","pt":1719498714564,"mc":[{"id":"1.230180120","rc":[{"atl":[[1000,0.21]],"id":47370245}],"con":true,"img":false}]}
{"op":"mcm","clk":"11540818725","pt":1719498714770,"mc":[{"id":"1.230180120","rc":[{"atl":[[1000,0.17]],"id":47370245}],"con":true,"img":false}]}
{"op":"mcm","clk":"11540818736","pt":1719498714880,"mc":[{"id":"1.230180120","rc":[{"atl":[[29,0.88]],"id":47370245}],"con":true,"img":false}]}
{"op":"mcm","clk":"11540819557","pt":1719498723783,"mc":[{"id":"1.230180120","rc":[{"atb":[[2.22,3.38]],"id":64536702}],"con":true,"img":false}]}
{"op":"mcm","clk":"11540819566","pt":1719498723888,"mc":[{"id":"1.230180120","rc":[{"atb":[[2.38,6.54]],"id":69112387}],"con":true,"img":false}]}
{"op":"mcm","clk":"11540819585","pt":1719498724095,"mc":[{"id":"1.230180120","rc":[{"atb":[[2.04,13.42]],"id":69112387}],"con":true,"img":false}]}
{"op":"mcm","clk":"11540819614","pt":1719498724413,"mc":[{"id":"1.230180120","rc":[{"atb":[[2.2,11.64]],"id":53432239},{"atb":[[2.26,11.08]],"id":47370245}],"con":true,"img":false}]}
{"op":"mcm","clk":"11540819638","pt":1719498724714,"mc":[{"id":"1.230180120","rc":[{"atb":[[2.3,10.74]],"id":62847579}],"con":true,"img":false}]}
{"op":"mcm","clk":"11540819672","pt":1719498724974,"mc":[{"id":"1.230180120","rc":[{"atb":[[2.26,13.08]],"id":64253834}],"con":true,"img":false}]}
{"op":"mcm","clk":"11540819964","pt":1719498727925,"mc":[{"id":"1.230180120","rc":[{"atb":[[2.26,23.16]],"id":53432239},{"atb":[[2.32,19.25]],"id":47370245},{"atb":[[2.74,16.09]],"id":64536702},{"atb":[[2.38,14.33]],"id":69112387}],"con":true,"img":false}]}
{"op":"mcm","clk":"11540820094","pt":1719498729214,"mc":[{"id":"1.230180120","rc":[{"atb":[[2.74,12.93]],"id":64536702},{"atb":[[2.38,11.18]],"id":69112387}],"con":true,"img":false}]}
{"op":"mcm","clk":"11540820120","pt":1719498729525,"mc":[{"id":"1.230180120","rc":[{"atb":[[2.76,3.15]],"id":64536702}],"con":true,"img":false}]}
{"op":"mcm","clk":"11540820135","pt":1719498729698,"mc":[{"id":"1.230180120","rc":[{"atb":[[2.4,3.15]],"id":69112387}],"con":true,"img":false}]}
{"op":"mcm","clk":"11540820175","pt":1719498730094,"mc":[{"id":"1.230180120","rc":[{"atl":[[29,0.84]],"id":47370245}],"con":true,"img":false}]}
{"op":"mcm","clk":"11540820194","pt":1719498730301,"mc":[{"id":"1.230180120","rc":[{"atl":[[1000,0.21]],"id":47370245}],"con":true,"img":false}]}
{"op":"mcm","clk":"11540820209","pt":1719498730507,"mc":[{"id":"1.230180120","rc":[{"atl":[[1000,0.17]],"id":47370245}],"con":true,"img":false}]}
{"op":"mcm","clk":"11540820220","pt":1719498730622,"mc":[{"id":"1.230180120","rc":[{"atl":[[29,0.88]],"id":47370245}],"con":true,"img":false}]}
{"op":"mcm","clk":"11540821306","pt":1719498745917,"mc":[{"id":"1.230180120","rc":[{"atl":[[29,0.84]],"id":47370245}],"con":true,"img":false}]}
{"op":"mcm","clk":"11540821401","pt":1719498747419,"mc":[{"id":"1.230180120","rc":[{"atb":[[2.74,0]],"id":64536702},{"atb":[[2.38,3.38]],"id":69112387}],"con":true,"img":false}]}
{"op":"mcm","clk":"11540821430","pt":1719498747929,"mc":[{"id":"1.230180120","rc":[{"atl":[[1000,0.21]],"id":47370245}],"con":true,"img":false}]}
{"op":"mcm","clk":"11540821446","pt":1719498748135,"mc":[{"id":"1.230180120","rc":[{"atl":[[1000,0.17]],"id":47370245}],"con":true,"img":false}]}
{"op":"mcm","clk":"11540821455","pt":1719498748246,"mc":[{"id":"1.230180120","rc":[{"atl":[[29,0.88]],"id":47370245}],"con":true,"img":false}]}
{"op":"mcm","clk":"11540822025","pt":1719498756454,"mc":[{"id":"1.230180120","rc":[{"atb":[[2.28,0]],"id":62847579},{"atb":[[2.18,0]],"id":53432239},{"atb":[[2.24,0]],"id":47370245},{"atb":[[2.24,0]],"id":64253834}],"con":true,"img":false}]}
{"op":"mcm","clk":"11540822506","pt":1719498763446,"mc":[{"id":"1.230180120","rc":[{"atl":[[29,0.84]],"id":47370245}],"con":true,"img":false}]}
{"op":"mcm","clk":"11540822523","pt":1719498763663,"mc":[{"id":"1.230180120","rc":[{"atl":[[1000,0.21]],"id":47370245}],"con":true,"img":false}]}
{"op":"mcm","clk":"11540822536","pt":1719498763872,"mc":[{"id":"1.230180120","rc":[{"atl":[[1000,0.17]],"id":47370245}],"con":true,"img":false}]}
{"op":"mcm","clk":"11540822543","pt":1719498763962,"mc":[{"id":"1.230180120","rc":[{"atl":[[29,0.88]],"id":47370245}],"con":true,"img":false}]}
{"op":"mcm","clk":"11540822596","pt":1719498765061,"mc":[{"id":"1.230180120","rc":[{"atb":[[2.28,9.25]],"id":53432239},{"atb":[[2.76,0]],"id":64536702},{"atb":[[2.4,0]],"id":69112387}],"con":true,"img":false}]}
{"op":"mcm","clk":"11540822608","pt":1719498765251,"mc":[{"id":"1.230180120","rc":[{"atb":[[2.32,8.97]],"id":62847579}],"con":true,"img":false}]}
{"op":"mcm","clk":"11540822614","pt":1719498765355,"mc":[{"id":"1.230180120","rc":[{"atb":[[2.28,9.25]],"id":64253834}],"con":true,"img":false}]}
{"op":"mcm","clk":"11540822622","pt":1719498765456,"mc":[{"id":"1.230180120","rc":[{"atb":[[2.34,8.83]],"id":47370245}],"con":true,"img":false}]}
{"op":"mcm","clk":"11540822656","pt":1719498765842,"mc":[{"id":"1.230180120","rc":[{"atb":[[2.4,2.09]],"id":62847579},{"atb":[[2.36,2.09],[2.26,21.06]],"id":53432239},{"atb":[[2.32,17.15],[2.42,2.09]],"id":47370245}],"con":true,"img":false}]}
{"op":"mcm","clk":"11540823543","pt":1719498779148,"mc":[{"id":"1.230180120","rc":[{"atl":[[29,0.84]],"id":47370245}],"con":true,"img":false}]}
{"op":"mcm","clk":"11540823707","pt":1719498781081,"mc":[{"id":"1.230180120","rc":[{"atl":[[1000,0.21]],"id":47370245}],"con":true,"img":false}]}
{"op":"mcm","clk":"11540823720","pt":1719498781181,"mc":[{"id":"1.230180120","rc":[{"atl":[[1000,0.17]],"id":47370245}],"con":true,"img":false}]}
{"op":"mcm","clk":"11540823732","pt":1719498781238,"mc":[{"id":"1.230180120","rc":[{"atl":[[29,0.88]],"id":47370245}],"con":true,"img":false}]}
{"op":"mcm","clk":"11540823962","pt":1719498783687,"mc":[{"id":"1.230180120","rc":[{"atb":[[2.26,0]],"id":53432239},{"atb":[[2.32,0]],"id":47370245},{"atb":[[2.74,3.15]],"id":64536702}],"con":true,"img":false}]}
{"op":"mcm","clk":"11540823981","pt":1719498783850,"mc":[{"id":"1.230180120","rc":[{"atb":[[2.38,6.54]],"id":69112387}],"con":true,"img":false}]}
{"op":"mcm","clk":"11540824730","pt":1719498792894,"mc":[{"id":"1.230180120","rc":[{"atb":[[2.26,2]],"id":62847579},{"atb":[[2.16,0]],"id":53432239},{"atb":[[2.22,0]],"id":47370245},{"atb":[[2.22,0]],"id":64253834}],"con":true,"img":false}]}
{"op":"mcm","clk":"11540824736","pt":1719498793007,"mc":[{"id":"1.230180120","rc":[{"atb":[[2.34,13.46]],"id":62847579},{"atb":[[2.3,11.97]],"id":53432239},{"atb":[[2.36,10.56]],"id":47370245},{"atb":[[2.3,11.44]],"id":64253834}],"con":true,"img":false}]}
{"op":"mcm","clk":"11540824983","pt":1719498796485,"mc":[{"id":"1.230180120","rc":[{"atl":[[29,0.84]],"id":47370245}],"con":true,"img":false}]}
{"op":"mcm","clk":"11540824997","pt":1719498796695,"mc":[{"id":"1.230180120","rc":[{"atl":[[1000,0.21]],"id":47370245}],"con":true,"img":false}]}
{"op":"mcm","clk":"11540825008","pt":1719498796903,"mc":[{"id":"1.230180120","rc":[{"atl":[[1000,0.17]],"id":47370245}],"con":true,"img":false}]}
{"op":"mcm","clk":"11540825015","pt":1719498797009,"mc":[{"id":"1.230180120","rc":[{"atl":[[29,0.88]],"id":47370245}],"con":true,"img":false}]}
{"op":"mcm","clk":"11540825758","pt":1719498806497,"mc":[{"id":"1.230180120","rc":[{"atb":[[2.3,0]],"id":62847579},{"atb":[[2.2,0]],"id":53432239},{"atb":[[2.26,0]],"id":47370245},{"atb":[[2.26,2]],"id":64253834}],"con":true,"img":false}]}
{"op":"mcm","clk":"11540826212","pt":1719498812208,"mc":[{"id":"1.230180120","rc":[{"atl":[[29,0.84]],"id":47370245}],"con":true,"img":false}]}
{"op":"mcm","clk":"11540826226","pt":1719498812415,"mc":[{"id":"1.230180120","rc":[{"atl":[[1000,0.21]],"id":47370245}],"con":true,"img":false}]}
{"op":"mcm","clk":"11540826237","pt":1719498812568,"mc":[{"id":"1.230180120","rc":[{"atl":[[1000,0.17]],"id":47370245}],"con":true,"img":false}]}
{"op":"mcm","clk":"11540826242","pt":1719498812677,"mc":[{"id":"1.230180120","rc":[{"atl":[[29,0.88]],"id":47370245}],"con":true,"img":false}]}
{"op":"mcm","clk":"11540827413","pt":1719498827900,"mc":[{"id":"1.230180120","rc":[{"atl":[[29,0.84]],"id":47370245}],"con":true,"img":false}]}
{"op":"mcm","clk":"11540827428","pt":1719498828095,"mc":[{"id":"1.230180120","rc":[{"atl":[[1000,0.21]],"id":47370245}],"con":true,"img":false}]}
{"op":"mcm","clk":"11540827446","pt":1719498828304,"mc":[{"id":"1.230180120","rc":[{"atl":[[1000,0.17]],"id":47370245}],"con":true,"img":false}]}
{"op":"mcm","clk":"11540827457","pt":1719498828408,"mc":[{"id":"1.230180120","rc":[{"atl":[[29,0.88]],"id":47370245}],"con":true,"img":false}]}
{"op":"mcm","clk":"11540827676","pt":1719498831203,"mc":[{"id":"1.230180120","rc":[{"atb":[[2.32,0]],"id":62847579},{"atb":[[2.28,0]],"id":53432239},{"atb":[[2.34,0]],"id":47370245},{"atb":[[2.28,0]],"id":64253834}],"con":true,"img":false}]}
{"op":"mcm","clk":"11540828286","pt":1719498839192,"mc":[{"id":"1.230180120","rc":[{"atb":[[1.1,1.69]],"id":64536702},{"atb":[[1.06,1.69]],"id":69112387}],"con":true,"img":false}]}
{"op":"mcm","clk":"11540828309","pt":1719498839501,"mc":[{"id":"1.230180120","rc":[{"atb":[[1.12,1.69]],"id":53432239},{"atb":[[1.12,1.69]],"id":64253834}],"con":true,"img":false}]}
{"op":"mcm","clk":"11540828325","pt":1719498839715,"mc":[{"id":"1.230180120","rc":[{"atb":[[2.38,8.58]],"id":47370245}],"con":true,"img":false}]}
{"op":"mcm","clk":"11540828333","pt":1719498839819,"mc":[{"id":"1.230180120","rc":[{"atb":[[1.12,1.69]],"id":62847579},{"atb":[[2.32,8.97]],"id":53432239},{"atb":[[1.09,1.69]],"id":47370245}],"con":true,"img":false}]}
{"op":"mcm","clk":"11540828342","pt":1719498839919,"mc":[{"id":"1.230180120","rc":[{"atb":[[2.36,8.71]],"id":62847579},{"atb":[[2.36,21.65]],"id":53432239},{"atb":[[2.42,17.74]],"id":47370245},{"atb":[[2.74,16.09]],"id":64536702},{"atb":[[2.38,14.33]],"id":69112387}],"con":true,"img":false}]}
{"op":"mcm","clk":"11540828356","pt":1719498840127,"mc":[{"id":"1.230180120","rc":[{"atb":[[1.1,0.06]],"id":64536702},{"atb":[[2.32,8.97]],"id":64253834}],"con":true,"img":false}]}
{"op":"mcm","clk":"11540828366","pt":1719498840229,"mc":[{"id":"1.230180120","rc":[{"atb":[[1.12,0.05]],"id":53432239},{"atb":[[2.76,6]],"id":64536702},{"atl":[[27,3.85]],"id":64536702},{"atb":[[3.8,4.1]],"id":64253834},{"atl":[[140,2]],"id":64253834}],"con":true,"img":false}]}
{"op":"mcm","clk":"11540828377","pt":1719498840331,"mc":[{"id":"1.230180120","rc":[{"atb":[[4.4,8.71]],"id":62847579},{"atl":[[140,2]],"id":62847579},{"atb":[[3.6,8.97]],"id":53432239},{"atl":[[24,4.35]],"id":53432239},{"atb":[[3.6,8.58],[1.09,0.07]],"id":47370245},{"atl":[[30,5.07]],"id":47370245},{"atb":[[1.98,86.35]],"id":69112387},{"atl":[[12,8]],"id":69112387}],"con":true,"img":false}]}
{"op":"mcm","clk":"11540828386","pt":1719498840436,"mc":[{"id":"1.230180120","rc":[{"atb":[[1.12,0.05]],"id":62847579},{"atl":[[22,2]],"id":69112387}],"con":true,"img":false}]}
{"op":"mcm","clk":"11540828403","pt":1719498840593,"mc":[{"id":"1.230180120","rc":[{"atb":[[1.06,0.11]],"id":69112387}],"con":true,"img":false}]}
{"op":"mcm","clk":"11540828411","pt":1719498840695,"mc":[{"id":"1.230180120","rc":[{"atb":[[1.12,0.05]],"id":64253834}],"con":true,"img":false}]}
{"op":"mcm","clk":"11540828433","pt":1719498841012,"mc":[{"id":"1.230180120","rc":[{"atb":[[1.1,0]],"id":64536702}],"con":true,"img":false}]}
{"op":"mcm","clk":"11540828442","pt":1719498841121,"mc":[{"id":"1.230180120","rc":[{"atb":[[4.8,0.06]],"id":64536702},{"atl":[[22,0]],"id":69112387}],"con":true,"img":false}]}
{"op":"mcm","clk":"11540828465","pt":1719498841429,"mc":[{"id":"1.230180120","rc":[{"atb":[[1.12,0]],"id":53432239}],"con":true,"img":false}]}
{"op":"mcm","clk":"11540828472","pt":1719498841532,"mc":[{"id":"1.230180120","rc":[{"atb":[[5.1,0.05]],"id":53432239}],"con":true,"img":false}]}
{"op":"mcm","clk":"11540828492","pt":1719498841794,"mc":[{"id":"1.230180120","rc":[{"atb":[[1.09,0]],"id":47370245}],"con":true,"img":false}]}
{"op":"mcm","clk":"11540828501","pt":1719498841898,"mc":[{"id":"1.230180120","rc":[{"atb":[[4.1,0.07]],"id":47370245}],"con":true,"img":false}]}
{"op":"mcm","clk":"11540828528","pt":1719498842310,"mc":[{"id":"1.230180120","rc":[{"atb":[[1.12,0]],"id":62847579}],"con":true,"img":false}]}
{"op":"mcm","clk":"11540828537","pt":1719498842414,"mc":[{"id":"1.230180120","rc":[{"atb":[[5.1,0.05]],"id":62847579}],"con":true,"img":false}]}
{"op":"mcm","clk":"11540828559","pt":1719498842731,"mc":[{"id":"1.230180120","rc":[{"atb":[[1.06,0]],"id":69112387}],"con":true,"img":false}]}
{"op":"mcm","clk":"11540828569","pt":1719498842829,"mc":[{"id":"1.230180120","rc":[{"atb":[[2.6,0.11]],"id":69112387}],"con":true,"img":false}]}
{"op":"mcm","clk":"11540828593","pt":1719498843141,"mc":[{"id":"1.230180120","rc":[{"atb":[[1.12,0]],"id":64253834}],"con":true,"img":false}]}
{"op":"mcm","clk":"11540828602","pt":1719498843251,"mc":[{"id":"1.230180120","rc":[{"atb":[[5.1,0.05]],"id":64253834}],"con":true,"img":false}]}
{"op":"mcm","clk":"11540828651","pt":1719498843815,"mc":[{"id":"1.230180120","rc":[{"atl":[[29,0.84]],"id":47370245}],"con":true,"img":false}]}
{"op":"mcm","clk":"11540828711","pt":1719498844647,"mc":[{"id":"1.230180120","rc":[{"atl":[[1000,0.21]],"id":47370245}],"con":true,"img":false}]}
{"op":"mcm","clk":"11540828724","pt":1719498844699,"mc":[{"id":"1.230180120","rc":[{"atl":[[1000,0.17]],"id":47370245}],"con":true,"img":false}]}
{"op":"mcm","clk":"11540828730","pt":1719498844798,"mc":[{"id":"1.230180120","rc":[{"atl":[[29,0.88]],"id":47370245}],"con":true,"img":false}]}
{"op":"mcm","clk":"11540829351","pt":1719498852405,"mc":[{"id":"1.230180120","rc":[{"atl":[[11.5,2]],"id":69112387}],"con":true,"img":false}]}
{"op":"mcm","clk":"11540829574","pt":1719498855436,"mc":[{"id":"1.230180120","rc":[{"atb":[[2.38,11.18]],"id":69112387}],"con":true,"img":false}]}
{"op":"mcm","clk":"11540829595","pt":1719498855642,"mc":[{"id":"1.230180120","rc":[{"atb":[[2.74,12.93]],"id":64536702}],"con":true,"img":false}]}
{"op":"mcm","clk":"11540829605","pt":1719498855746,"mc":[{"id":"1.230180120","rc":[{"atb":[[2.4,3.15]],"id":69112387}],"con":true,"img":false}]}
{"op":"mcm","clk":"11540829614","pt":1719498855849,"mc":[{"id":"1.230180120","rc":[{"atb":[[2.78,3.15]],"id":64536702}],"con":true,"img":false}]}
{"op":"mcm","clk":"11540829809","pt":1719498857625,"mc":[{"id":"1.230180120","rc":[{"atl":[[11.5,0]],"id":69112387}],"con":true,"img":false}]}
{"op":"mcm","clk":"11540829956","pt":1719498859236,"mc":[{"id":"1.230180120","rc":[{"atb":[[4.6,1]],"id":53432239},{"atl":[[14,1]],"id":53432239},{"atl":[[8.2,1]],"id":64536702},{"atb":[[2.38,7.79]],"id":69112387},{"atl":[[4.1,1]],"id":69112387},{"atb":[[4.9,1]],"id":64253834},{"atl":[[15.5,1]],"id":64253834}],"con":true,"img":false}]}
{"op":"mcm","clk":"11540829973","pt":1719498859339,"mc":[{"id":"1.230180120","rc":[{"atb":[[3.6,0],[3.85,8.97]],"id":53432239},{"atb":[[3.8,2],[4.2,4.1]],"id":64253834}],"con":true,"img":false}]}
{"op":"mcm","clk":"11540829993","pt":1719498859541,"mc":[{"id":"1.230180120","rc":[{"atb":[[2.22,0]],"id":64536702}],"con":true,"img":false}]}
{"op":"mcm","clk":"11540830020","pt":1719498859853,"mc":[{"id":"1.230180120","rc":[{"atb":[[2.4,6.54]],"id":69112387},{"atl":[[4,2]],"id":69112387}],"con":true,"img":false}]}
{"op":"mcm","clk":"11540830035","pt":1719498859956,"mc":[{"id":"1.230180120","rc":[{"atl":[[12,0],[4.4,8]],"id":69112387}],"con":true,"img":false}]}
{"op":"mcm","clk":"11540830050","pt":1719498860112,"mc":[{"id":"1.230180120","rc":[{"atl":[[29,0.84]],"id":47370245}],"con":true,"img":false}]}
{"op":"mcm","clk":"11540830102","pt":1719498860629,"mc":[{"id":"1.230180120","rc":[{"atb":[[2.76,9.38]],"id":64536702}],"con":true,"img":false}]}
{"op":"mcm","clk":"11540830122","pt":1719498860836,"mc":[{"id":"1.230180120","rc":[{"atl":[[130,0.84]],"id":62847579},{"atl":[[13.5,0.84]],"id":53432239}],"con":true,"img":false}]}
{"op":"mcm","clk":"11540830162","pt":1719498861253,"mc":[{"id":"1.230180120","rc":[{"atl":[[29,1.71]],"id":47370245}],"con":true,"img":false}]}
{"op":"mcm","clk":"11540830235","pt":1719498862127,"mc":[{"id":"1.230180120","rc":[{"atl":[[1000,0.21]],"id":47370245}],"con":true,"img":false}]}
{"op":"mcm","clk":"11540830262","pt":1719498862543,"mc":[{"id":"1.230180120","rc":[{"atl":[[1000,0.17]],"id":47370245}],"con":true,"img":false}]}
{"op":"mcm","clk":"11540830269","pt":1719498862647,"mc":[{"id":"1.230180120","rc":[{"atl":[[28,0.04]],"id":47370245}],"con":true,"img":false}]}
{"op":"mcm","clk":"11540830400","pt":1719498864048,"mc":[{"id":"1.230180120","rc":[{"atl":[[30,3.45]],"id":47370245}],"con":true,"img":false}]}
{"op":"mcm","clk":"11540830511","pt":1719498865031,"mc":[{"id":"1.230180120","rc":[{"atl":[[4,0]],"id":69112387}],"con":true,"img":false}]}
{"op":"mcm","clk":"11540830533","pt":1719498865238,"mc":[{"id":"1.230180120","rc":[{"atl":[[12,9],[4.4,0]],"id":69112387}],"con":true,"img":false}]}
{"op":"mcm","clk":"11540830704","pt":1719498867259,"mc":[{"id":"1.230180120","rc":[{"spn":67.55,"spf":"NaN","id":62847579},{"spn":9.3,"spf":"NaN","id":53432239},{"spn":16.05,"spf":"NaN","id":47370245},{"spn":6.5,"spf":"NaN","id":64536702},{"atl":[[4,2]],"id":69112387},{"spn":2.58,"spf":1.0,"id":69112387},{"spn":10.3,"spf":"NaN","id":64253834}],"con":true,"img":false}]}
{"op":"mcm","clk":"11540830758","pt":1719498867828,"mc":[{"id":"1.230180120","rc":[{"atb":[[2.36,2.09]],"id":53432239},{"atb":[[2.42,2.09]],"id":47370245},{"atb":[[2.74,0]],"id":64536702},{"atb":[[2.38,0]],"id":69112387}],"con":true,"img":false}]}
{"op":"mcm","clk":"11540830797","pt":1719498868241,"mc":[{"id":"1.230180120","rc":[{"atl":[[15.5,0]],"id":64253834},{"trd":[[15.5,1.99]],"ltp":15.5,"tv":1.99,"id":64253834}],"con":true,"img":false}]}
{"op":"mcm","clk":"11540830808","pt":1719498868344,"mc":[{"id":"1.230180120","rc":[{"atl":[[17,1]],"id":64253834}],"con":true,"img":false}]}
{"op":"mcm","clk":"11540830939","pt":1719498869462,"mc":[{"id":"1.230180120","rc":[{"atb":[[1.09,1]],"id":64253834}],"con":true,"img":false}]}
{"op":"mcm","clk":"11540830952","pt":1719498869596,"mc":[{"id":"1.230180120","rc":[{"atb":[[2.4,3.38]],"id":69112387}],"con":true,"img":false}]}
{"op":"mcm","clk":"11540830966","pt":1719498869665,"mc":[{"id":"1.230180120","rc":[{"atb":[[1.09,0.24]],"id":64253834}],"con":true,"img":false}]}
{"op":"mcm","clk":"11540830982","pt":1719498869724,"mc":[{"id":"1.230180120","rc":[{"atb":[[1.09,0]],"id":64253834}],"con":true,"img":false}]}
{"op":"mcm","clk":"11540830998","pt":1719498869820,"mc":[{"id":"1.230180120","rc":[{"atl":[[12,0],[4.4,9]],"id":69112387},{"atb":[[5.1,0.29]],"id":64253834}],"con":true,"img":false}]}
{"op":"mcm","clk":"11540831028","pt":1719498870030,"mc":[{"id":"1.230180120","rc":[{"atl":[[28,1.71]],"id":47370245}],"con":true,"img":false}]}
{"op":"mcm","clk":"11540831053","pt":1719498870242,"mc":[{"id":"1.230180120","rc":[{"atl":[[28,3.71],[30,0]],"id":47370245}],"con":true,"img":false}]}
{"op":"mcm","clk":"11540831070","pt":1719498870346,"mc":[{"id":"1.230180120","rc":[{"atl":[[29,5.16]],"id":47370245}],"con":true,"img":false}]}
{"op":"mcm","clk":"11540831083","pt":1719498870444,"mc":[{"id":"1.230180120","rc":[{"atl":[[28,1.71]],"id":47370245}],"con":true,"img":false}]}
{"op":"mcm","clk":"11540831101","pt":1719498870554,"mc":[{"id":"1.230180120","rc":[{"atl":[[29,4.29]],"id":47370245}],"con":true,"img":false}]}
{"op":"mcm","clk":"11540831126","pt":1719498870756,"mc":[{"id":"1.230180120","rc":[{"atl":[[27,0.93]],"id":47370245}],"con":true,"img":false}]}
{"op":"mcm","clk":"11540831288","pt":1719498872421,"mc":[{"id":"1.230180120","rc":[{"atl":[[4,0]],"id":69112387}],"con":true,"img":false}]}
{"op":"mcm","clk":"11540831296","pt":1719498872529,"mc":[{"id":"1.230180120","rc":[{"atl":[[12,9.09],[4.4,0]],"id":69112387}],"con":true,"img":false}]}
{"op":"mcm","clk":"11540831475","pt":1719498874771,"mc":[{"id":"1.230180120","rc":[{"atl":[[4,2]],"id":69112387}],"con":true,"img":false}]}
{"op":"mcm","clk":"11540831783","pt":1719498877934,"mc":[{"id":"1.230180120","rc":[{"atl":[[28,1.67]],"id":47370245}],"con":true,"img":false}]}
{"op":"mcm","clk":"11540831795","pt":1719498878141,"mc":[{"id":"1.230180120","rc":[{"atl":[[1000,0.21]],"id":47370245}],"con":true,"img":false}]}
{"op":"mcm","clk":"11540831810","pt":1719498878352,"mc":[{"id":"1.230180120","rc":[{"atl":[[1000,0.17]],"id":47370245}],"con":true,"img":false}]}
{"op":"mcm","clk":"11540831818","pt":1719498878457,"mc":[{"id":"1.230180120","rc":[{"atl":[[27,0.97]],"id":47370245}],"con":true,"img":false}]}
{"op":"mcm","clk":"11540831878","pt":1719498879071,"mc":[{"id":"1.230180120","rc":[{"atl":[[17,0]],"id":64253834},{"trd":[[17,1.99]],"ltp":17.0,"tv":1.99,"id":64253834}],"con":true,"img":false}]}
{"op":"mcm","clk":"11540831942","pt":1719498879952,"mc":[{"id":"1.230180120","rc":[{"atl":[[4,0]],"id":69112387}],"con":true,"img":false}]}
{"op":"mcm","clk":"11540831953","pt":1719498880056,"mc":[{"id":"1.230180120","rc":[{"atb":[[2.58,0]],"id":69112387}],"con":true,"img":false}]}
{"op":"mcm","clk":"11540831962","pt":1719498880160,"mc":[{"id":"1.230180120","rc":[{"atb":[[1.02,18.49]],"id":69112387}],"con":true,"img":false}]}
{"op":"mcm","clk":"11540832090","pt":1719498881775,"mc":[{"id":"1.230180120","rc":[{"atl":[[4,2]],"id":69112387}],"con":true,"img":false}]}
{"op":"mcm","clk":"11540832140","pt":1719498882343,"mc":[{"id":"1.230180120","rc":[{"atl":[[12,0],[4.4,9.09]],"id":69112387}],"con":true,"img":false}]}
{"op":"mcm","clk":"11540832150","pt":1719498882446,"mc":[{"id":"1.230180120","rc":[{"atb":[[2.02,0]],"id":69112387}],"con":true,"img":false}]}
{"op":"mcm","clk":"11540832324","pt":1719498885192,"mc":[{"id":"1.230180120","rc":[{"atb":[[4.4,0],[4.7,6]],"id":62847579},{"atb":[[3.85,0],[4.4,6]],"id":53432239},{"atb":[[1.98,0],[2.08,13.43]],"id":69112387},{"atb":[[4.8,4.1],[5.1,0.05],[4.2,0]],"id":64253834}],"con":true,"img":false}]}
{"op":"mcm","clk":"11540832347","pt":1719498885347,"mc":[{"id":"1.230180120","rc":[{"atb":[[1.09,1]],"id":64253834}],"con":true,"img":false}]}
{"op":"mcm","clk":"11540832364","pt":1719498885558,"mc":[{"id":"1.230180120","rc":[{"atb":[[1.09,0.24]],"id":64253834}],"con":true,"img":false}]}
{"op":"mcm","clk":"11540832378","pt":1719498885765,"mc":[{"id":"1.230180120","rc":[{"atb":[[1.09,0]],"id":64253834}],"con":true,"img":false}]}
{"op":"mcm","clk":"11540832387","pt":1719498885862,"mc":[{"id":"1.230180120","rc":[{"atb":[[5.1,0.29]],"id":64253834}],"con":true,"img":false}]}
{"op":"mcm","clk":"11540832484","pt":1719498887057,"mc":[{"id":"1.230180120","rc":[{"atl":[[4,0]],"id":69112387}],"con":true,"img":false}]}
{"op":"mcm","clk":"11540832492","pt":1719498887169,"mc":[{"id":"1.230180120","rc":[{"atl":[[12,9.09],[4.4,0]],"id":69112387}],"con":true,"img":false}]}
{"op":"mcm","clk":"11540832672","pt":1719498889078,"mc":[{"id":"1.230180120","rc":[{"atl":[[4,2]],"id":69112387}],"con":true,"img":false}]}
{"op":"mcm","clk":"11540832695","pt":1719498889300,"mc":[{"id":"1.230180120","rc":[{"atl":[[12,0],[4.4,9.09]],"id":69112387}],"con":true,"img":false}]}
{"op":"mcm","clk":"11540833090","pt":1719498893594,"mc":[{"id":"1.230180120","rc":[{"atl":[[27,0.93]],"id":47370245}],"con":true,"img":false}]}
{"op":"mcm","clk":"11540833163","pt":1719498894370,"mc":[{"id":"1.230180120","rc":[{"atl":[[4,0]],"id":69112387}],"con":true,"img":false}]}
{"op":"mcm","clk":"11540833174","pt":1719498894475,"mc":[{"id":"1.230180120","rc":[{"atl":[[12,9.09],[4.4,0]],"id":69112387}],"con":true,"img":false}]}
{"op":"mcm","clk":"11540833195","pt":1719498894795,"mc":[{"id":"1.230180120","rc":[{"atl":[[1000,0.21]],"id":47370245}],"con":true,"img":false}]}
{"op":"mcm","clk":"11540833216","pt":1719498894946,"mc":[{"id":"1.230180120","rc":[{"atl":[[1000,0.17]],"id":47370245}],"con":true,"img":false}]}
{"op":"mcm","clk":"11540833225","pt":1719498895048,"mc":[{"id":"1.230180120","rc":[{"atl":[[27,0.97]],"id":47370245}],"con":true,"img":false}]}
{"op":"mcm","clk":"11540833350","pt":1719498896559,"mc":[{"id":"1.230180120","rc":[{"atb":[[2.76,6]],"id":64536702},{"atb":[[2.4,0]],"id":69112387}],"con":true,"img":false}]}
{"op":"mcm","clk":"11540833391","pt":1719498897186,"mc":[{"id":"1.230180120","rc":[{"atb":[[2.38,3.15]],"id":69112387},{"atl":[[4,2]],"id":69112387}],"con":true,"img":false}]}
{"op":"mcm","clk":"11540833408","pt":1719498897344,"mc":[{"id":"1.230180120","rc":[{"atb":[[2.34,12.52]],"id":64253834}],"con":true,"img":false}]}
{"op":"mcm","clk":"11540833417","pt":1719498897559,"mc":[{"id":"1.230180120","rc":[{"atb":[[2.06,11.17]],"id":69112387}],"con":true,"img":false}]}
{"op":"mcm","clk":"11540833443","pt":1719498897862,"mc":[{"id":"1.230180120","rc":[{"atb":[[2.38,10.12]],"id":62847579}],"con":true,"img":false}]}
{"op":"mcm","clk":"11540833735","pt":1719498901099,"mc":[{"id":"1.230180120","rc":[{"atb":[[5.1,0.05]],"id":64253834}],"con":true,"img":false}]}
{"op":"mcm","clk":"11540833847","pt":1719498902308,"mc":[{"id":"1.230180120","rc":[{"atl":[[4,0]],"id":69112387},{"atb":[[1.09,1]],"id":64253834}],"con":true,"img":false}]}
{"op":"mcm","clk":"11540833866","pt":1719498902466,"mc":[{"id":"1.230180120","rc":[{"atb":[[1.09,0.24]],"id":64253834}],"con":true,"img":false}]}
{"op":"mcm","clk":"11540833876","pt":1719498902571,"mc":[{"id":"1.230180120","rc":[{"atb":[[1.09,0]],"id":64253834}],"con":true,"img":false}]}
{"op":"mcm","clk":"11540833886","pt":1719498902677,"mc":[{"id":"1.230180120","rc":[{"atb":[[5.1,0.29]],"id":64253834}],"con":true,"img":false}]}
{"op":"mcm","clk":"11540834054","pt":1719498904466,"mc":[{"id":"1.230180120","rc":[{"atl":[[4,2]],"id":69112387}],"con":true,"img":false}]}
{"op":"mcm","clk":"11540834063","pt":1719498904561,"mc":[{"id":"1.230180120","rc":[{"atl":[[12,0],[4.4,9.09]],"id":69112387}],"con":true,"img":false}]}
{"op":"mcm","clk":"11540834522","pt":1719498909680,"mc":[{"id":"1.230180120","rc":[{"atl":[[4,0]],"id":69112387}],"con":true,"img":false}]}
{"op":"mcm","clk":"11540834542","pt":1719498909892,"mc":[{"id":"1.230180120","rc":[{"atl":[[12,9.09],[4.4,0]],"id":69112387}],"con":true,"img":false}]}
{"op":"mcm","clk":"11540834570","pt":1719498910260,"mc":[{"id":"1.230180120","rc":[{"atl":[[27,0.93]],"id":47370245}],"con":true,"img":false}]}
{"op":"mcm","clk":"11540834615","pt":1719498910662,"mc":[{"id":"1.230180120","rc":[{"atl":[[1000,0.21]],"id":47370245}],"con":true,"img":false}]}
{"op":"mcm","clk":"11540834637","pt":1719498910872,"mc":[{"id":"1.230180120","rc":[{"atl":[[1000,0.17]],"id":47370245}],"con":true,"img":false}]}
{"op":"mcm","clk":"11540834646","pt":1719498910974,"mc":[{"id":"1.230180120","rc":[{"atl":[[27,0.97]],"id":47370245}],"con":true,"img":false}]}
{"op":"mcm","clk":"11540834724","pt":1719498911872,"mc":[{"id":"1.230180120","rc":[{"atl":[[4,2]],"id":69112387}],"con":true,"img":false}]}
{"op":"mcm","clk":"11540834897","pt":1719498914178,"mc":[{"id":"1.230180120","rc":[{"atl":[[12,0],[4.4,9.09]],"id":69112387}],"con":true,"img":false}]}
{"op":"mcm","clk":"11540835117","pt":1719498917067,"mc":[{"id":"1.230180120","rc":[{"atl":[[4,0]],"id":69112387}],"con":true,"img":false}]}
{"op":"mcm","clk":"11540835123","pt":1719498917171,"mc":[{"id":"1.230180120","rc":[{"atl":[[12,9.09],[4.4,0]],"id":69112387}],"con":true,"img":false}]}
{"op":"mcm","clk":"11540835193","pt":1719498917919,"mc":[{"id":"1.230180120","rc":[{"atb":[[5.1,0.05]],"id":64253834}],"con":true,"img":false}]}
{"op":"mcm","clk":"11540835212","pt":1719498918077,"mc":[{"id":"1.230180120","rc":[{"atb":[[1.09,1]],"id":64253834}],"con":true,"img":false}]}
{"op":"mcm","clk":"11540835230","pt":1719498918284,"mc":[{"id":"1.230180120","rc":[{"atb":[[1.09,0.24]],"id":64253834}],"con":true,"img":false}]}
{"op":"mcm","clk":"11540835242","pt":1719498918384,"mc":[{"id":"1.230180120","rc":[{"atb":[[1.09,0]],"id":64253834}],"con":true,"img":false}]}
{"op":"mcm","clk":"11540835253","pt":1719498918486,"mc":[{"id":"1.230180120","rc":[{"atb":[[5.1,0.29]],"id":64253834}],"con":true,"img":false}]}
{"op":"mcm","clk":"11540835335","pt":1719498919275,"mc":[{"id":"1.230180120","rc":[{"atl":[[4,2]],"id":69112387}],"con":true,"img":false}]}
{"op":"mcm","clk":"11540835348","pt":1719498919376,"mc":[{"id":"1.230180120","rc":[{"atl":[[12,0],[4.4,9.09]],"id":69112387}],"con":true,"img":false}]}
{"op":"mcm","clk":"11540835776","pt":1719498924592,"mc":[{"id":"1.230180120","rc":[{"atl":[[4,0]],"id":69112387}],"con":true,"img":false}]}
{"op":"mcm","clk":"11540835799","pt":1719498924789,"mc":[{"id":"1.230180120","rc":[{"atl":[[12,9.09],[4.4,0]],"id":69112387}],"con":true,"img":false}]}
{"op":"mcm","clk":"11540835877","pt":1719498925771,"mc":[{"id":"1.230180120","rc":[{"atb":[[4.3,1],[4.6,0]],"id":53432239},{"atb":[[4.9,0],[4.6,1]],"id":64253834}],"con":true,"img":false}]}
{"op":"mcm","clk":"11540835912","pt":1719498926188,"mc":[{"id":"1.230180120","rc":[{"atl":[[27,0.93]],"id":47370245}],"con":true,"img":false}]}
{"op":"mcm","clk":"11540835937","pt":1719498926497,"mc":[{"id":"1.230180120","rc":[{"atl":[[1000,0.21]],"id":47370245}],"con":true,"img":false}]}
{"op":"mcm","clk":"11540835950","pt":1719498926706,"mc":[{"id":"1.230180120","rc":[{"atl":[[1000,0.17]],"id":47370245},{"atl":[[4,2]],"id":69112387}],"con":true,"img":false}]}
{"op":"mcm","clk":"11540835960","pt":1719498926799,"mc":[{"id":"1.230180120","rc":[{"atl":[[27,0.97]],"id":47370245}],"con":true,"img":false}]}
{"op":"mcm","clk":"11540836402","pt":1719498931917,"mc":[{"id":"1.230180120","rc":[{"spn":15.55,"spf":"NaN","id":47370245},{"atl":[[4,0]],"id":69112387},{"spn":2.56,"spf":1.0,"id":69112387},{"spn":72.55,"spf":"NaN","id":64253834}],"con":true,"img":false}]}
{"op":"mcm","clk":"11540836426","pt":1719498932187,"mc":[{"id":"1.230180120","rc":[{"atb":[[2.04,0]],"id":69112387}],"con":true,"img":false}]}
{"op":"mcm","clk":"11540836564","pt":1719498933672,"mc":[{"id":"1.230180120","rc":[{"atb":[[5.1,0.05]],"id":64253834}],"con":true,"img":false}]}
{"op":"mcm","clk":"11540836588","pt":1719498933978,"mc":[{"id":"1.230180120","rc":[{"atb":[[1.09,1]],"id":64253834}],"con":true,"img":false}]}
{"op":"mcm","clk":"11540836598","pt":1719498934085,"mc":[{"id":"1.230180120","rc":[{"atl":[[4,2]],"id":69112387}],"con":true,"img":false}]}
{"op":"mcm","clk":"11540836605","pt":1719498934193,"mc":[{"id":"1.230180120","rc":[{"atl":[[12,0],[4.4,9.09]],"id":69112387},{"atb":[[1.09,0.24]],"id":64253834}],"con":true,"img":false}]}
{"op":"mcm","clk":"11540836627","pt":1719498934496,"mc":[{"id":"1.230180120","rc":[{"atb":[[1.09,0]],"id":64253834}],"con":true,"img":false}]}
{"op":"mcm","clk":"11540836637","pt":1719498934600,"mc":[{"id":"1.230180120","rc":[{"atb":[[5.1,0.29]],"id":64253834}],"con":true,"img":false}]}
{"op":"mcm","clk":"11540837067","pt":1719498939410,"mc":[{"id":"1.230180120","rc":[{"atl":[[4,0]],"id":69112387}],"con":true,"img":false}]}
{"op":"mcm","clk":"11540837076","pt":1719498939517,"mc":[{"id":"1.230180120","rc":[{"atl":[[12,9.09],[4.4,0]],"id":69112387}],"con":true,"img":false}]}
{"op":"mcm","clk":"11540837236","pt":1719498941405,"mc":[{"id":"1.230180120","rc":[{"atl":[[4,2]],"id":69112387}],"con":true,"img":false}]}
{"op":"mcm","clk":"11540837299","pt":1719498941921,"mc":[{"id":"1.230180120","rc":[{"atl":[[27,0.93]],"id":47370245}],"con":true,"img":false}]}
{"op":"mcm","clk":"11540837500","pt":1719498943328,"mc":[{"id":"1.230180120","rc":[{"atb":[[4.4,6.78]],"id":53432239},{"atb":[[3.6,9.36]],"id":47370245},{"atb":[[2.78,4.05]],"id":64536702},{"atb":[[2.38,3.94]],"id":69112387}],"con":true,"img":false}]}
{"op":"mcm","clk":"11540837513","pt":1719498943428,"mc":[{"id":"1.230180120","rc":[{"atl":[[1000,0.21]],"id":47370245}],"con":true,"img":false}]}
{"op":"mcm","clk":"11540837539","pt":1719498943585,"mc":[{"id":"1.230180120","rc":[{"atl":[[1000,0.17]],"id":47370245}],"con":true,"img":false}]}
{"op":"mcm","clk":"11540837552","pt":1719498943690,"mc":[{"id":"1.230180120","rc":[{"atl":[[27,0.97]],"id":47370245}],"con":true,"img":false}]}
{"op":"mcm","clk":"11540837609","pt":1719498944207,"mc":[{"id":"1.230180120","rc":[{"atb":[[2.38,7.33]],"id":69112387}],"con":true,"img":false}]}
{"op":"mcm","clk":"11540837649","pt":1719498944722,"mc":[{"id":"1.230180120","rc":[{"atb":[[2.02,13.69]],"id":69112387}],"con":true,"img":false}]}
{"op":"mcm","clk":"11540837663","pt":1719498944981,"mc":[{"id":"1.230180120","rc":[{"atb":[[2.22,3.38]],"id":64536702}],"con":true,"img":false}]}
{"op":"mcm","clk":"11540837671","pt":1719498945084,"mc":[{"id":"1.230180120","rc":[{"atb":[[2.34,10.42]],"id":53432239}],"con":true,"img":false}]}
{"op":"mcm","clk":"11540837687","pt":1719498945400,"mc":[{"id":"1.230180120","rc":[{"atb":[[2.4,9.97]],"id":47370245}],"con":true,"img":false}]}
{"op":"mcm","clk":"11540837704","pt":1719498945604,"mc":[{"id":"1.230180120","rc":[{"atl":[[13.5,1.69]],"id":53432239},{"atl":[[3.95,0.84]],"id":69112387}],"con":true,"img":false}]}
{"op":"mcm","clk":"11540837761","pt":1719498946124,"mc":[{"id":"1.230180120","rc":[{"atb":[[2.36,0]],"id":62847579},{"atb":[[2.32,0]],"id":64253834}],"con":true,"img":false}]}
{"op":"mcm","clk":"11540837843","pt":1719498946601,"mc":[{"id":"1.230180120","rc":[{"atl":[[4,0]],"id":69112387}],"con":true,"img":false}]}
{"op":"mcm","clk":"11540837912","pt":1719498947119,"mc":[{"id":"1.230180120","rc":[{"atl":[[3.95,0]],"id":69112387}],"con":true,"img":false}]}
{"op":"mcm","clk":"11540838217","pt":1719498949435,"mc":[{"id":"1.230180120","rc":[{"atl":[[4,2]],"id":69112387}],"con":true,"img":false}]}
{"op":"mcm","clk":"11540838248","pt":1719498949593,"mc":[{"id":"1.230180120","rc":[{"atl":[[12,0],[4.4,9.09]],"id":69112387}],"con":true,"img":false}]}
{"op":"mcm","clk":"11540838274","pt":1719498949805,"mc":[{"id":"1.230180120","rc":[{"atb":[[5.1,0.05]],"id":64253834}],"con":true,"img":false}]}
{"op":"mcm","clk":"11540838425","pt":1719498950942,"mc":[{"id":"1.230180120","rc":[{"atb":[[1.09,1]],"id":64253834}],"con":true,"img":false}]}
{"op":"mcm","clk":"11540838450","pt":1719498951100,"mc":[{"id":"1.230180120","rc":[{"atb":[[1.09,0.24]],"id":64253834}],"con":true,"img":false}]}
{"op":"mcm","clk":"11540838466","pt":1719498951313,"mc":[{"id":"1.230180120","rc":[{"atb":[[1.09,0]],"id":64253834}],"con":true,"img":false}]}
{"op":"mcm","clk":"11540838476","pt":1719498951408,"mc":[{"id":"1.230180120","rc":[{"atb":[[5.1,0.29]],"id":64253834}],"con":true,"img":false}]}
{"op":"mcm","clk":"11540838564","pt":1719498952297,"mc":[{"id":"1.230180120","rc":[{"atb":[[2.32,0]],"id":53432239},{"atb":[[2.38,0]],"id":47370245},{"atb":[[2.36,8.71]],"id":64253834}],"con":true,"img":false}]}
{"op":"mcm","clk":"11540838633","pt":1719498953027,"mc":[{"id":"1.230180120","rc":[{"atb":[[2.4,10.55]],"id":62847579}],"con":true,"img":false}]}
{"op":"mcm","clk":"11540838642","pt":1719498953132,"mc":[{"id":"1.230180120","rc":[{"atl":[[3.95,0.84]],"id":69112387}],"con":true,"img":false}]}
{"op":"mcm","clk":"11540838758","pt":1719498954636,"mc":[{"id":"1.230180120","rc":[{"atl":[[4,0]],"id":69112387}],"con":true,"img":false}]}
{"op":"mcm","clk":"11540838805","pt":1719498955103,"mc":[{"id":"1.230180120","rc":[{"atl":[[3.95,0]],"id":69112387}],"con":true,"img":false}]}
{"op":"mcm","clk":"11540838827","pt":1719498955317,"mc":[{"id":"1.230180120","rc":[{"atl":[[12,9.09],[4.4,0]],"id":69112387}],"con":true,"img":false}]}
{"op":"mcm","clk":"11540838959","pt":1719498956602,"mc":[{"id":"1.230180120","rc":[{"atl":[[4,2]],"id":69112387}],"con":true,"img":false}]}
{"op":"mcm","clk":"11540838980","pt":1719498956810,"mc":[{"id":"1.230180120","rc":[{"atl":[[4.4,9.09]],"id":69112387}],"con":true,"img":false}]}
{"op":"mcm","clk":"11540838989","pt":1719498956916,"mc":[{"id":"1.230180120","rc":[{"atl":[[12,0]],"id":69112387}],"con":true,"img":false}]}
{"op":"mcm","clk":"11540839203","pt":1719498958935,"mc":[{"id":"1.230180120","rc":[{"atl":[[27,0.93]],"id":47370245}],"con":true,"img":false}]}
{"op":"mcm","clk":"11540839220","pt":1719498959143,"mc":[{"id":"1.230180120","rc":[{"atl":[[1000,0.21]],"id":47370245}],"con":true,"img":false}]}
{"op":"mcm","clk":"11540839239","pt":1719498959356,"mc":[{"id":"1.230180120","rc":[{"atl":[[1000,0.17]],"id":47370245}],"con":true,"img":false}]}
{"op":"mcm","clk":"11540839253","pt":1719498959410,"mc":[{"id":"1.230180120","rc":[{"atl":[[27,0.97]],"id":47370245}],"con":true,"img":false}]}
{"op":"mcm","clk":"11540839324","pt":1719498960134,"mc":[{"id":"1.230180120","rc":[{"atb":[[4.8,0]],"id":64536702}],"con":true,"img":false}]}
{"op":"mcm","clk":"11540839380","pt":1719498960648,"mc":[{"id":"1.230180120","rc":[{"atl":[[3.95,0.84]],"id":69112387}],"con":true,"img":false}]}
{"op":"mcm","clk":"11540839393","pt":1719498960751,"mc":[{"id":"1.230180120","rc":[{"atb":[[2.6,0]],"id":69112387}],"con":true,"img":false}]}
{"op":"mcm","clk":"11540839467","pt":1719498961530,"mc":[{"id":"1.230180120","rc":[{"atb":[[4.1,0]],"id":47370245}],"con":true,"img":false}]}
{"op":"mcm","clk":"11540839497","pt":1719498961841,"mc":[{"id":"1.230180120","rc":[{"atl":[[4,0]],"id":69112387}],"con":true,"img":false}]}
{"op":"mcm","clk":"11540839539","pt":1719498962211,"mc":[{"id":"1.230180120","rc":[{"atb":[[4.4,6]],"id":53432239},{"atl":[[3.95,0]],"id":69112387}],"con":true,"img":false}]}
{"op":"mcm","clk":"11540839552","pt":1719498962368,"mc":[{"id":"1.230180120","rc":[{"atb":[[5.1,0]],"id":53432239}],"con":true,"img":false}]}
{"op":"mcm","clk":"11540839564","pt":1719498962416,"mc":[{"id":"1.230180120","rc":[{"atl":[[12,9.09],[4.4,0]],"id":69112387}],"con":true,"img":false}]}
{"op":"mcm","clk":"11540839627","pt":1719498963038,"mc":[{"id":"1.230180120","rc":[{"atb":[[5.1,0]],"id":62847579}],"con":true,"img":false}]}
{"op":"mcm","clk":"11540839739","pt":1719498964123,"mc":[{"id":"1.230180120","rc":[{"atl":[[4,2]],"id":69112387},{"atb":[[5.1,0.24]],"id":64253834}],"con":true,"img":false}]}
{"op":"mcm","clk":"11540839751","pt":1719498964330,"mc":[{"id":"1.230180120","rc":[{"atl":[[12,0],[4.4,9.09]],"id":69112387}],"con":true,"img":false}]}
{"op":"mcm","clk":"11540839775","pt":1719498964637,"mc":[{"id":"1.230180120","rc":[{"atb":[[1.06,1.69]],"id":69112387}],"con":true,"img":false}]}
{"op":"mcm","clk":"11540839803","pt":1719498964946,"mc":[{"id":"1.230180120","rc":[{"atb":[[1.12,1.69]],"id":53432239},{"atb":[[1.09,1.69]],"id":47370245}],"con":true,"img":false}]}
{"op":"mcm","clk":"11540839836","pt":1719498965205,"mc":[{"id":"1.230180120","rc":[{"atb":[[1.09,0.07]],"id":47370245}],"con":true,"img":false}]}
{"op":"mcm","clk":"11540839846","pt":1719498965314,"mc":[{"id":"1.230180120","rc":[{"atb":[[1.12,1.69]],"id":62847579}],"con":true,"img":false}]}
{"op":"mcm","clk":"11540839857","pt":1719498965412,"mc":[{"id":"1.230180120","rc":[{"atb":[[1.12,1.69]],"id":64253834}],"con":true,"img":false}]}
{"op":"mcm","clk":"11540839873","pt":1719498965617,"mc":[{"id":"1.230180120","rc":[{"atb":[[1.06,0.11]],"id":69112387}],"con":true,"img":false}]}
{"op":"mcm","clk":"11540839884","pt":1719498965720,"mc":[{"id":"1.230180120","rc":[{"atb":[[1.12,0.05]],"id":53432239}],"con":true,"img":false}]}
{"op":"mcm","clk":"11540839924","pt":1719498966133,"mc":[{"id":"1.230180120","rc":[{"atb":[[1.09,0]],"id":47370245}],"con":true,"img":false}]}
{"op":"mcm","clk":"11540839936","pt":1719498966235,"mc":[{"id":"1.230180120","rc":[{"atb":[[4.1,0.07]],"id":47370245}],"con":true,"img":false}]}
{"op":"mcm","clk":"11540839955","pt":1719498966451,"mc":[{"id":"1.230180120","rc":[{"atb":[[1.1,1.69]],"id":64536702}],"con":true,"img":false}]}
{"op":"mcm","clk":"11540839969","pt":1719498966546,"mc":[{"id":"1.230180120","rc":[{"atb":[[1.12,0.05]],"id":64253834}],"con":true,"img":false}]}
{"op":"mcm","clk":"11540839984","pt":1719498966752,"mc":[{"id":"1.230180120","rc":[{"atb":[[5.1,0]],"id":64253834}],"con":true,"img":false}]}
{"op":"mcm","clk":"11540839991","pt":1719498966861,"mc":[{"id":"1.230180120","rc":[{"atb":[[1.06,0]],"id":69112387},{"atb":[[4.8,0],[4.6,6.1]],"id":64253834}],"con":true,"img":false}]}
{"op":"mcm","clk":"11540840005","pt":1719498966913,"mc":[{"id":"1.230180120","rc":[{"atb":[[2.58,0.11]],"id":69112387},{"atb":[[3.85,7.1],[1.09,1]],"id":64253834}],"con":true,"img":false}]}
{"op":"mcm","clk":"11540840014","pt":1719498967021,"mc":[{"id":"1.230180120","rc":[{"atb":[[4.6,1]],"id":64253834}],"con":true,"img":false}]}
{"op":"mcm","clk":"11540840027","pt":1719498967117,"mc":[{"id":"1.230180120","rc":[{"atb":[[1.09,0.24]],"id":64253834}],"con":true,"img":false}]}
{"op":"mcm","clk":"11540840046","pt":1719498967335,"mc":[{"id":"1.230180120","rc":[{"atb":[[1.12,0.05]],"id":62847579},{"atb":[[1.12,0]],"id":53432239},{"atb":[[1.09,0]],"id":64253834}],"con":true,"img":false}]}
{"op":"mcm","clk":"11540840059","pt":1719498967432,"mc":[{"id":"1.230180120","rc":[{"atb":[[5.1,0.05]],"id":53432239},{"atb":[[5.1,0.24]],"id":64253834}],"con":true,"img":false}]}
{"op":"mcm","clk":"11540840070","pt":1719498967538,"mc":[{"id":"1.230180120","rc":[{"atb":[[3.85,0],[4.6,3]],"id":64253834}],"con":true,"img":false}]}
{"op":"mcm","clk":"11540840094","pt":1719498967738,"mc":[{"id":"1.230180120","rc":[{"atb":[[1.1,0.06]],"id":64536702}],"con":true,"img":false}]}
{"op":"mcm","clk":"11540840124","pt":1719498968051,"mc":[{"id":"1.230180120","rc":[{"atb":[[1.12,0]],"id":64253834}],"con":true,"img":false}]}
{"op":"mcm","clk":"11540840132","pt":1719498968157,"mc":[{"id":"1.230180120","rc":[{"atl":[[3.95,0.84]],"id":69112387},{"atb":[[5.1,0.29]],"id":64253834}],"con":true,"img":false}]}
{"op":"mcm","clk":"11540840169","pt":1719498968470,"mc":[{"id":"1.230180120","rc":[{"atb":[[1.12,0]],"id":62847579}],"con":true,"img":false}]}
{"op":"mcm","clk":"11540840178","pt":1719498968576,"mc":[{"id":"1.230180120","rc":[{"atb":[[5.1,0.05]],"id":62847579}],"con":true,"img":false}]}
{"op":"mcm","clk":"11540840213","pt":1719498968835,"mc":[{"id":"1.230180120","rc":[{"atb":[[2.42,10.43]],"id":47370245},{"atb":[[1.1,0]],"id":64536702}],"con":true,"img":false}]}
{"op":"mcm","clk":"11540840222","pt":1719498968936,"mc":[{"id":"1.230180120","rc":[{"atb":[[4.8,0.06]],"id":64536702}],"con":true,"img":false}]}
{"op":"mcm","clk":"11540840245","pt":1719498969246,"mc":[{"id":"1.230180120","rc":[{"atb":[[2.36,10.8]],"id":53432239}],"con":true,"img":false}]}
{"op":"mcm","clk":"11540840255","pt":1719498969349,"mc":[{"id":"1.230180120","rc":[{"atl":[[4,0]],"id":69112387}],"con":true,"img":false}]}
{"op":"mcm","clk":"11540840291","pt":1719498969714,"mc":[{"id":"1.230180120","rc":[{"atl":[[3.95,0]],"id":69112387}],"con":true,"img":false}]}
{"op":"mcm","clk":"11540840303","pt":1719498969822,"mc":[{"id":"1.230180120","rc":[{"atl":[[12,9.09],[4.4,0]],"id":69112387}],"con":true,"img":false}]}
{"op":"mcm","clk":"11540840456","pt":1719498971628,"mc":[{"id":"1.230180120","rc":[{"atl":[[4,2]],"id":69112387}],"con":true,"img":false}]}
{"op":"mcm","clk":"11540840588","pt":1719498973232,"mc":[{"id":"1.230180120","rc":[{"atl":[[12,0],[4.4,9.09]],"id":69112387}],"con":true,"img":false}]}
{"op":"mcm","clk":"11540840698","pt":1719498974632,"mc":[{"id":"1.230180120","rc":[{"atl":[[27,0.93]],"id":47370245}],"con":true,"img":false}]}
{"op":"mcm","clk":"11540840743","pt":1719498975145,"mc":[{"id":"1.230180120","rc":[{"atl":[[3.95,0.84]],"id":69112387}],"con":true,"img":false}]}
{"op":"mcm","clk":"11540840873","pt":1719498976747,"mc":[{"id":"1.230180120","rc":[{"atl":[[1000,0.21]],"id":47370245}],"con":true,"img":false}]}
{"op":"mcm","clk":"11540840884","pt":1719498976850,"mc":[{"id":"1.230180120","rc":[{"atl":[[4,0]],"id":69112387}],"con":true,"img":false}]}
{"op":"mcm","clk":"11540840899","pt":1719498977053,"mc":[{"id":"1.230180120","rc":[{"atl":[[1000,0.17]],"id":47370245}],"con":true,"img":false}]}
{"op":"mcm","clk":"11540840907","pt":1719498977158,"mc":[{"id":"1.230180120","rc":[{"atl":[[27,0.97]],"id":47370245},{"atl":[[3.95,0]],"id":69112387}],"con":true,"img":false}]}
{"op":"mcm","clk":"11540841030","pt":1719498978355,"mc":[{"id":"1.230180120","rc":[{"atl":[[12,9.09],[4.4,0]],"id":69112387}],"con":true,"img":false}]}
{"op":"mcm","clk":"11540841080","pt":1719498978927,"mc":[{"id":"1.230180120","rc":[{"atb":[[2.06,0]],"id":69112387},{"atl":[[4,2]],"id":69112387}],"con":true,"img":false}]}
{"op":"mcm","clk":"11540841332","pt":1719498982028,"mc":[{"id":"1.230180120","rc":[{"atl":[[12,0],[4.4,9.09]],"id":69112387}],"con":true,"img":false}]}
{"op":"mcm","clk":"11540841341","pt":1719498982130,"mc":[{"id":"1.230180120","rc":[{"atl":[[3.95,0.84]],"id":69112387}],"con":true,"img":false}]}
{"op":"mcm","clk":"11540841387","pt":1719498982748,"mc":[{"id":"1.230180120","rc":[{"atb":[[5.1,0.05]],"id":64253834}],"con":true,"img":false}]}
{"op":"mcm","clk":"11540841526","pt":1719498984146,"mc":[{"id":"1.230180120","rc":[{"atl":[[4,0]],"id":69112387},{"atb":[[1.09,1]],"id":64253834}],"con":true,"img":false}]}
{"op":"mcm","clk":"11540841544","pt":1719498984356,"mc":[{"id":"1.230180120","rc":[{"atb":[[1.09,0.24]],"id":64253834}],"con":true,"img":false}]}
{"op":"mcm","clk":"11540841558","pt":1719498984559,"mc":[{"id":"1.230180120","rc":[{"atb":[[1.09,0]],"id":64253834}],"con":true,"img":false}]}
{"op":"mcm","clk":"11540841566","pt":1719498984661,"mc":[{"id":"1.230180120","rc":[{"atb":[[5.1,0.29]],"id":64253834}],"con":true,"img":false}]}
{"op":"mcm","clk":"11540841574","pt":1719498984764,"mc":[{"id":"1.230180120","rc":[{"atl":[[3.95,0]],"id":69112387}],"con":true,"img":false}]}
{"op":"mcm","clk":"11540841723","pt":1719498986363,"mc":[{"id":"1.230180120","rc":[{"atl":[[4,2]],"id":69112387}],"con":true,"img":false}]}
{"op":"mcm","clk":"11540841944","pt":1719498988676,"mc":[{"id":"1.230180120","rc":[{"atb":[[2.04,11.38]],"id":69112387}],"con":true,"img":false}]}
{"op":"mcm","clk":"11540841998","pt":1719498989246,"mc":[{"id":"1.230180120","rc":[{"atl":[[3.95,0.84]],"id":69112387}],"con":true,"img":false}]}
{"op":"mcm","clk":"11540842198","pt":1719498991674,"mc":[{"id":"1.230180120","rc":[{"atl":[[4,0]],"id":69112387}],"con":true,"img":false}]}
{"op":"mcm","clk":"11540842256","pt":1719498992351,"mc":[{"id":"1.230180120","rc":[{"atl":[[3.95,0]],"id":69112387},{"spn":2.56,"spf":1.0,"id":69112387}],"con":true,"img":false}]}
{"op":"mcm","clk":"11540842263","pt":1719498992453,"mc":[{"id":"1.230180120","rc":[{"atl":[[27,0.93]],"id":47370245},{"atl":[[12,9.09],[4.4,0]],"id":69112387}],"con":true,"img":false}]}
{"op":"mcm","clk":"11540842278","pt":1719498992659,"mc":[{"id":"1.230180120","rc":[{"atl":[[1000,0.21]],"id":47370245}],"con":true,"img":false}]}
{"op":"mcm","clk":"11540842288","pt":1719498992765,"mc":[{"id":"1.230180120","rc":[{"atl":[[1000,0.17]],"id":47370245}],"con":true,"img":false}]}
{"op":"mcm","clk":"11540842300","pt":1719498992864,"mc":[{"id":"1.230180120","rc":[{"atl":[[27,0.97]],"id":47370245}],"con":true,"img":false}]}
{"op":"mcm","clk":"11540842385","pt":1719498993747,"mc":[{"id":"1.230180120","rc":[{"atl":[[4,2]],"id":69112387}],"con":true,"img":false}]}
{"op":"mcm","clk":"11540842585","pt":1719498996649,"mc":[{"id":"1.230180120","rc":[{"atl":[[3.95,0.84]],"id":69112387}],"con":true,"img":false}]}
{"op":"mcm","clk":"11540842771","pt":1719498999077,"mc":[{"id":"1.230180120","rc":[{"atl":[[4,0]],"id":69112387}],"con":true,"img":false}]}
{"op":"mcm","clk":"11540842831","pt":1719498999748,"mc":[{"id":"1.230180120","rc":[{"atl":[[3.95,0]],"id":69112387}],"con":true,"img":false}]}
{"op":"mcm","clk":"11540842840","pt":1719498999852,"mc":[{"id":"1.230180120","rc":[{"atb":[[5.1,0.05]],"id":64253834}],"con":true,"img":false}]}
{"op":"mcm","clk":"11540842858","pt":1719499000057,"mc":[{"id":"1.230180120","rc":[{"atb":[[1.09,1]],"id":64253834}],"con":true,"img":false}]}
{"op":"mcm","clk":"11540842874","pt":1719499000270,"mc":[{"id":"1.230180120","rc":[{"atb":[[1.09,0.24]],"id":64253834}],"con":true,"img":false}]}
{"op":"mcm","clk":"11540842891","pt":1719499000471,"mc":[{"id":"1.230180120","rc":[{"atb":[[1.09,0]],"id":64253834}],"con":true,"img":false}]}
{"op":"mcm","clk":"11540842900","pt":1719499000580,"mc":[{"id":"1.230180120","rc":[{"atb":[[5.1,0.29]],"id":64253834}],"con":true,"img":false}]}
{"op":"mcm","clk":"11540842988","pt":1719499001769,"mc":[{"id":"1.230180120","rc":[{"atl":[[4,2]],"id":69112387}],"con":true,"img":false}]}
{"op":"mcm","clk":"11540842999","pt":1719499001872,"mc":[{"id":"1.230180120","rc":[{"atl":[[12,0],[4.4,9.09]],"id":69112387}],"con":true,"img":false}]}
{"op":"mcm","clk":"11540843153","pt":1719499003681,"mc":[{"id":"1.230180120","rc":[{"atl":[[3.95,0.84]],"id":69112387}],"con":true,"img":false}]}
{"op":"mcm","clk":"11540843385","pt":1719499006985,"mc":[{"id":"1.230180120","rc":[{"atl":[[4,0]],"id":69112387}],"con":true,"img":false}]}
{"op":"mcm","clk":"11540843460","pt":1719499007761,"mc":[{"id":"1.230180120","rc":[{"atb":[[2.38,0]],"id":62847579},{"atb":[[2.34,0]],"id":53432239},{"atb":[[2.4,0]],"id":47370245},{"atl":[[3.95,0]],"id":69112387},{"atb":[[2.34,2.09]],"id":64253834}],"con":true,"img":false}]}
{"op":"mcm","clk":"11540843465","pt":1719499007863,"mc":[{"id":"1.230180120","rc":[{"atl":[[12,9.09]],"id":69112387}],"con":true,"img":false}]}
{"op":"mcm","clk":"11540843474","pt":1719499007968,"mc":[{"id":"1.230180120","rc":[{"atl":[[4.4,0]],"id":69112387}],"con":true,"img":false}]}
{"op":"mcm","clk":"11540843489","pt":1719499008176,"mc":[{"id":"1.230180120","rc":[{"atl":[[27,0.93]],"id":47370245}],"con":true,"img":false}]}
{"op":"mcm","clk":"11540843558","pt":1719499009157,"mc":[{"id":"1.230180120","rc":[{"atl":[[4,2]],"id":69112387}],"con":true,"img":false}]}
{"op":"mcm","clk":"11540843573","pt":1719499009362,"mc":[{"id":"1.230180120","rc":[{"atl":[[1000,0.21]],"id":47370245}],"con":true,"img":false}]}
{"op":"mcm","clk":"11540843588","pt":1719499009564,"mc":[{"id":"1.230180120","rc":[{"atl":[[1000,0.17]],"id":47370245}],"con":true,"img":false}]}
{"op":"mcm","clk":"11540843595","pt":1719499009674,"mc":[{"id":"1.230180120","rc":[{"atl":[[27,0.97]],"id":47370245}],"con":true,"img":false}]}
{"op":"mcm","clk":"11540843646","pt":1719499010387,"mc":[{"id":"1.230180120","rc":[{"atl":[[4.4,9.09]],"id":69112387}],"con":true,"img":false}]}
{"op":"mcm","clk":"11540843654","pt":1719499010487,"mc":[{"id":"1.230180120","rc":[{"atl":[[12,0]],"id":69112387}],"con":true,"img":false}]}
{"op":"mcm","clk":"11540843699","pt":1719499011058,"mc":[{"id":"1.230180120","rc":[{"atl":[[3.95,0.84]],"id":69112387}],"con":true,"img":false}]}
{"op":"mcm","clk":"11540843945","pt":1719499014408,"mc":[{"id":"1.230180120","rc":[{"atl":[[4,0]],"id":69112387}],"con":true,"img":false}]}
{"op":"mcm","clk":"11540844003","pt":1719499015070,"mc":[{"id":"1.230180120","rc":[{"atl":[[3.95,0]],"id":69112387}],"con":true,"img":false}]}
{"op":"mcm","clk":"11540844029","pt":1719499015483,"mc":[{"id":"1.230180120","rc":[{"atl":[[12,9.09],[4.4,0]],"id":69112387}],"con":true,"img":false}]}
{"op":"mcm","clk":"11540844048","pt":1719499015792,"mc":[{"id":"1.230180120","rc":[{"spl":[[1.01,4]],"id":64536702}],"con":true,"img":false}]}
{"op":"mcm","clk":"11540844059","pt":1719499015900,"mc":[{"id":"1.230180120","rc":[{"atb":[[5.1,0.05]],"id":64253834}],"con":true,"img":false}]}
{"op":"mcm","clk":"11540844099","pt":1719499016570,"mc":[{"id":"1.230180120","rc":[{"atl":[[4,2]],"id":69112387}],"con":true,"img":false}]}
{"op":"mcm","clk":"11540844108","pt":1719499016673,"mc":[{"id":"1.230180120","rc":[{"atb":[[1.09,1]],"id":64253834}],"con":true,"img":false}]}
{"op":"mcm","clk":"11540844126","pt":1719499016983,"mc":[{"id":"1.230180120","rc":[{"atb":[[1.09,0.24]],"id":64253834}],"con":true,"img":false}]}
{"op":"mcm","clk":"11540844136","pt":1719499017085,"mc":[{"id":"1.230180120","rc":[{"atb":[[1.09,0]],"id":64253834}],"con":true,"img":false}]}
{"op":"mcm","clk":"11540844146","pt":1719499017192,"mc":[{"id":"1.230180120","rc":[{"atb":[[5.1,0.29]],"id":64253834}],"con":true,"img":false}]}
{"op":"mcm","clk":"11540844231","pt":1719499018169,"mc":[{"id":"1.230180120","rc":[{"atl":[[3.95,0.84]],"id":69112387}],"con":true,"img":false}]}
{"op":"mcm","clk":"11540844277","pt":1719499018792,"mc":[{"id":"1.230180120","rc":[{"atl":[[12,0],[4.4,9.09]],"id":69112387}],"con":true,"img":false}]}
{"op":"mcm","clk":"11540844452","pt":1719499020904,"mc":[{"id":"1.230180120","rc":[{"atl":[[1000,0.78]],"id":69112387}],"con":true,"img":false}]}
{"op":"mcm","clk":"11540844520","pt":1719499021883,"mc":[{"id":"1.230180120","rc":[{"atl":[[4,0]],"id":69112387}],"con":true,"img":false}]}
{"op":"mcm","clk":"11540844532","pt":1719499022091,"mc":[{"id":"1.230180120","rc":[{"atb":[[2.44,9.7]],"id":47370245}],"con":true,"img":false}]}
{"op":"mcm","clk":"11540844541","pt":1719499022198,"mc":[{"id":"1.230180120","rc":[{"atl":[[3.95,0]],"id":69112387}],"con":true,"img":false}]}
{"op":"mcm","clk":"11540844549","pt":1719499022302,"mc":[{"id":"1.230180120","rc":[{"atl":[[12,9.09],[4.4,0]],"id":69112387}],"con":true,"img":false}]}
{"op":"mcm","clk":"11540844558","pt":1719499022402,"mc":[{"id":"1.230180120","rc":[{"atb":[[2.42,9.83]],"id":62847579}],"con":true,"img":false}]}
{"op":"mcm","clk":"11540844590","pt":1719499022771,"mc":[{"id":"1.230180120","rc":[{"atb":[[2.38,10.12]],"id":53432239}],"con":true,"img":false}]}
{"op":"mcm","clk":"11540844605","pt":1719499022972,"mc":[{"id":"1.230180120","rc":[{"atb":[[2.38,10.12]],"id":64253834}],"con":true,"img":false}]}
{"op":"mcm","clk":"11540844733","pt":1719499024575,"mc":[{"id":"1.230180120","rc":[{"atl":[[4,2]],"id":69112387}],"con":true,"img":false}]}
{"op":"mcm","clk":"11540844747","pt":1719499024785,"mc":[{"id":"1.230180120","rc":[{"atl":[[12,0],[4.4,9.09]],"id":69112387}],"con":true,"img":false}]}
{"op":"mcm","clk":"11540844755","pt":1719499024882,"mc":[{"id":"1.230180120","rc":[{"atl":[[27,0.93]],"id":47370245}],"con":true,"img":false}]}
{"op":"mcm","clk":"11540844773","pt":1719499025090,"mc":[{"id":"1.230180120","rc":[{"atl":[[1000,0.21]],"id":47370245}],"con":true,"img":false}]}
{"op":"mcm","clk":"11540844790","pt":1719499025302,"mc":[{"id":"1.230180120","rc":[{"atl":[[1000,0.17]],"id":47370245}],"con":true,"img":false}]}
{"op":"mcm","clk":"11540844799","pt":1719499025400,"mc":[{"id":"1.230180120","rc":[{"atl":[[27,0.97]],"id":47370245}],"con":true,"img":false}]}
{"op":"mcm","clk":"11540844821","pt":1719499025606,"mc":[{"id":"1.230180120","rc":[{"atl":[[3.95,0.84]],"id":69112387}],"con":true,"img":false}]}
{"op":"mcm","clk":"11540845195","pt":1719499029892,"mc":[{"id":"1.230180120","rc":[{"atl":[[4,0]],"id":69112387}],"con":true,"img":false}]}
{"op":"mcm","clk":"11540845220","pt":1719499030200,"mc":[{"id":"1.230180120","rc":[{"atl":[[3.95,0]],"id":69112387}],"con":true,"img":false}]}
{"op":"mcm","clk":"11540845233","pt":1719499030303,"mc":[{"id":"1.230180120","rc":[{"atl":[[12,9.09],[4.4,0]],"id":69112387}],"con":true,"img":false}]}
{"op":"mcm","clk":"11540845355","pt":1719499031902,"mc":[{"id":"1.230180120","rc":[{"atl":[[4,2]],"id":69112387}],"con":true,"img":false}]}
{"op":"mcm","clk":"11540845396","pt":1719499032420,"mc":[{"id":"1.230180120","rc":[{"atb":[[5.1,0.05]],"id":64253834}],"con":true,"img":false}]}
{"op":"mcm","clk":"11540845414","pt":1719499032632,"mc":[{"id":"1.230180120","rc":[{"atb":[[1.09,1]],"id":64253834}],"con":true,"img":false}]}
{"op":"mcm","clk":"11540845423","pt":1719499032683,"mc":[{"id":"1.230180120","rc":[{"atb":[[1.09,0.24]],"id":64253834}],"con":true,"img":false}]}
{"op":"mcm","clk":"11540845441","pt":1719499032894,"mc":[{"id":"1.230180120","rc":[{"atb":[[1.09,0]],"id":64253834}],"con":true,"img":false}]}
{"op":"mcm","clk":"11540845450","pt":1719499032993,"mc":[{"id":"1.230180120","rc":[{"atb":[[5.1,0.29]],"id":64253834}],"con":true,"img":false}]}
{"op":"mcm","clk":"11540845457","pt":1719499033093,"mc":[{"id":"1.230180120","rc":[{"atl":[[3.95,0.84]],"id":69112387}],"con":true,"img":false}]}
{"op":"mcm","clk":"11540845773","pt":1719499037120,"mc":[{"id":"1.230180120","rc":[{"atl":[[4,0]],"id":69112387}],"con":true,"img":false}]}
{"op":"mcm","clk":"11540845815","pt":1719499037634,"mc":[{"id":"1.230180120","rc":[{"atl":[[3.95,0]],"id":69112387}],"con":true,"img":false}]}
{"op":"mcm","clk":"11540845866","pt":1719499038510,"mc":[{"id":"1.230180120","rc":[{"atb":[[5.2,1.62]],"id":53432239},{"atl":[[1000,1.02]],"id":47370245}],"con":true,"img":false}]}
{"op":"mcm","clk":"11540845892","pt":1719499038818,"mc":[{"id":"1.230180120","rc":[{"atb":[[5.2,1.62]],"id":62847579},{"atb":[[5.2,0]],"id":53432239}],"con":true,"img":false}]}
{"op":"mcm","clk":"11540845907","pt":1719499039024,"mc":[{"id":"1.230180120","rc":[{"atb":[[5.1,3.31],[4.7,0]],"id":62847579},{"atb":[[5.1,1.68]],"id":53432239},{"atb":[[5.2,1.62]],"id":64253834}],"con":true,"img":false}]}
{"op":"mcm","clk":"11540845915","pt":1719499039130,"mc":[{"id":"1.230180120","rc":[{"atb":[[4.8,3],[4.6,1]],"id":64253834}],"con":true,"img":false}]}
{"op":"mcm","clk":"11540845933","pt":1719499039334,"mc":[{"id":"1.230180120","rc":[{"atb":[[5.2,0]],"id":62847579},{"atl":[[1000,0.49]],"id":47370245},{"atl":[[4,2]],"id":69112387}],"con":true,"img":false}]}
{"op":"mcm","clk":"11540845946","pt":1719499039437,"mc":[{"id":"1.230180120","rc":[{"atl":[[12,0],[4.4,9.09]],"id":69112387}],"con":true,"img":false}]}
{"op":"mcm","clk":"11540845955","pt":1719499039593,"mc":[{"id":"1.230180120","rc":[{"atb":[[5.1,4.94],[5.2,0.84]],"id":62847579},{"atb":[[5.1,1.92]],"id":64253834}],"con":true,"img":false}]}
{"op":"mcm","clk":"11540845974","pt":1719499039904,"mc":[{"id":"1.230180120","rc":[{"atb":[[5.2,0]],"id":64253834}],"con":true,"img":false}]}
{"op":"mcm","clk":"11540845990","pt":1719499040111,"mc":[{"id":"1.230180120","rc":[{"atl":[[3.95,0.84]],"id":69112387}],"con":true,"img":false}]}
{"op":"mcm","clk":"11540846010","pt":1719499040421,"mc":[{"id":"1.230180120","rc":[{"atl":[[1000,0.17]],"id":47370245}],"con":true,"img":false}]}
{"op":"mcm","clk":"11540846018","pt":1719499040522,"mc":[{"id":"1.230180120","rc":[{"atl":[[26,0.32]],"id":47370245}],"con":true,"img":false}]}
{"op":"mcm","clk":"11540846028","pt":1719499040629,"mc":[{"id":"1.230180120","rc":[{"atl":[[27,0.93]],"id":47370245},{"atb":[[5.2,0.84]],"id":64253834}],"con":true,"img":false}]}
{"op":"mcm","clk":"11540846037","pt":1719499040732,"mc":[{"id":"1.230180120","rc":[{"atl":[[27,2.93],[29,0.84]],"id":47370245}],"con":true,"img":false}]}
{"op":"mcm","clk":"11540846046","pt":1719499040833,"mc":[{"id":"1.230180120","rc":[{"atl":[[1000,0.21]],"id":47370245},{"atb":[[5.3,1.6]],"id":64253834}],"con":true,"img":false}]}
{"op":"mcm","clk":"11540846063","pt":1719499041038,"mc":[{"id":"1.230180120","rc":[{"atl":[[1000,0.17]],"id":47370245},{"atb":[[5.1,0.29]],"id":64253834}],"con":true,"img":false}]}
{"op":"mcm","clk":"11540846071","pt":1719499041141,"mc":[{"id":"1.230180120","rc":[{"atl":[[26,1.16],[27,2.97]],"id":47370245}],"con":true,"img":false}]}
{"op":"mcm","clk":"11540846100","pt":1719499041403,"mc":[{"id":"1.230180120","rc":[{"atl":[[27,2.04]],"id":47370245}],"con":true,"img":false}]}
{"op":"mcm","clk":"11540846295","pt":1719499043633,"mc":[{"id":"1.230180120","rc":[{"atb":[[2.4,2.09]],"id":62847579},{"atb":[[2.36,2.09]],"id":53432239},{"atb":[[2.42,2.09]],"id":47370245},{"atb":[[2.36,0]],"id":64253834}],"con":true,"img":false}]}
{"op":"mcm","clk":"11540846389","pt":1719499044517,"mc":[{"id":"1.230180120","rc":[{"atl":[[4,0]],"id":69112387}],"con":true,"img":false}]}
{"op":"mcm","clk":"11540846442","pt":1719499045133,"mc":[{"id":"1.230180120","rc":[{"atl":[[3.95,0]],"id":69112387}],"con":true,"img":false}]}
{"op":"mcm","clk":"11540846458","pt":1719499045343,"mc":[{"id":"1.230180120","rc":[{"atl":[[12,9.09],[4.4,0]],"id":69112387}],"con":true,"img":false}]}
{"op":"mcm","clk":"11540846618","pt":1719499047528,"mc":[{"id":"1.230180120","rc":[{"atl":[[4,2]],"id":69112387}],"con":true,"img":false}]}
{"op":"mcm","clk":"11540846665","pt":1719499048146,"mc":[{"id":"1.230180120","rc":[{"atl":[[3.95,0.84]],"id":69112387}],"con":true,"img":false}]}
{"op":"mcm","clk":"11540846672","pt":1719499048254,"mc":[{"id":"1.230180120","rc":[{"atb":[[5.1,0.05]],"id":64253834}],"con":true,"img":false}]}
{"op":"mcm","clk":"11540846697","pt":1719499048520,"mc":[{"id":"1.230180120","rc":[{"atb":[[1.09,1]],"id":64253834}],"con":true,"img":false}]}
{"op":"mcm","clk":"11540846719","pt":1719499048829,"mc":[{"id":"1.230180120","rc":[{"atb":[[1.09,0.23]],"id":64253834}],"con":true,"img":false}]}
{"op":"mcm","clk":"11540846736","pt":1719499049039,"mc":[{"id":"1.230180120","rc":[{"atb":[[1.09,0]],"id":64253834}],"con":true,"img":false}]}
{"op":"mcm","clk":"11540846746","pt":1719499049146,"mc":[{"id":"1.230180120","rc":[{"atb":[[5.4,0.23]],"id":64253834}],"con":true,"img":false}]}
{"op":"mcm","clk":"11540846771","pt":1719499049401,"mc":[{"id":"1.230180120","rc":[{"atb":[[5.1,1.65]],"id":64253834}],"con":true,"img":false}]}
{"op":"mcm","clk":"11540846779","pt":1719499049509,"mc":[{"id":"1.230180120","rc":[{"atb":[[5.3,0]],"id":64253834}],"con":true,"img":false}]}
{"op":"mcm","clk":"11540846787","pt":1719499049609,"mc":[{"id":"1.230180120","rc":[{"atb":[[5.4,1.07]],"id":64253834}],"con":true,"img":false}]}
{"op":"mcm","clk":"11540846799","pt":1719499049817,"mc":[{"id":"1.230180120","rc":[{"atb":[[5.3,1.6],[5.1,0.05]],"id":64253834}],"con":true,"img":false}]}
{"op":"mcm","clk":"11540846821","pt":1719499050125,"mc":[{"id":"1.230180120","rc":[{"atb":[[5.5,1.54]],"id":64253834}],"con":true,"img":false}]}
{"op":"mcm","clk":"11540846829","pt":1719499050230,"mc":[{"id":"1.230180120","rc":[{"atb":[[5.3,0]],"id":64253834}],"con":true,"img":false}]}
{"op":"mcm","clk":"11540846856","pt":1719499050645,"mc":[{"id":"1.230180120","rc":[{"atl":[[1000,0]],"id":69112387}],"con":true,"img":false}]}
{"op":"mcm","clk":"11540846864","pt":1719499050750,"mc":[{"id":"1.230180120","rc":[{"atb":[[5.2,0]],"id":64253834}],"con":true,"img":false}]}
{"op":"mcm","clk":"11540847026","pt":1719499052731,"mc":[{"id":"1.230180120","rc":[{"spn":67.6,"spf":"NaN","id":62847579},{"spn":15.05,"spf":"NaN","id":47370245},{"spn":3.29,"spf":1.0,"id":64536702},{"atl":[[4,0]],"id":69112387},{"spn":72.75,"spf":"NaN","id":64253834}],"con":true,"img":false}]}
{"op":"mcm","clk":"11540847058","pt":1719499053141,"mc":[{"id":"1.230180120","rc":[{"atl":[[3.95,0]],"id":69112387}],"con":true,"img":false}]}
{"op":"mcm","clk":"11540847195","pt":1719499055054,"mc":[{"id":"1.230180120","rc":[{"atl":[[4,2]],"id":69112387}],"con":true,"img":false}]}
{"op":"mcm","clk":"11540847211","pt":1719499055212,"mc":[{"id":"1.230180120","rc":[{"atl":[[12,0],[4.4,9.09]],"id":69112387}],"con":true,"img":false}]}
{"op":"mcm","clk":"11540847244","pt":1719499055625,"mc":[{"id":"1.230180120","rc":[{"atl":[[3.95,0.84]],"id":69112387}],"con":true,"img":false}]}
{"op":"mcm","clk":"11540847289","pt":1719499056353,"mc":[{"id":"1.230180120","rc":[{"atl":[[27,2]],"id":47370245}],"con":true,"img":false}]}
{"op":"mcm","clk":"11540847407","pt":1719499057742,"mc":[{"id":"1.230180120","rc":[{"atl":[[1000,0.21]],"id":47370245}],"con":true,"img":false}]}
{"op":"mcm","clk":"11540847431","pt":1719499058053,"mc":[{"id":"1.230180120","rc":[{"atl":[[1000,0.17]],"id":47370245}],"con":true,"img":false}]}
{"op":"mcm","clk":"11540847438","pt":1719499058155,"mc":[{"id":"1.230180120","rc":[{"atl":[[25,0.04]],"id":47370245}],"con":true,"img":false}]}
{"op":"mcm","clk":"11540847612","pt":1719499060219,"mc":[{"id":"1.230180120","rc":[{"atl":[[4,0]],"id":69112387}],"con":true,"img":false}]}
{"op":"mcm","clk":"11540847641","pt":1719499060735,"mc":[{"id":"1.230180120","rc":[{"atl":[[3.95,0]],"id":69112387}],"con":true,"img":false}]}
{"op":"mcm","clk":"11540847648","pt":1719499060840,"mc":[{"id":"1.230180120","rc":[{"atl":[[12,9.09],[4.4,0]],"id":69112387}],"con":true,"img":false}]}
{"op":"mcm","clk":"11540847763","pt":1719499062446,"mc":[{"id":"1.230180120","rc":[{"atl":[[4,2]],"id":69112387}],"con":true,"img":false}]}
{"op":"mcm","clk":"11540847769","pt":1719499062543,"mc":[{"id":"1.230180120","rc":[{"atl":[[12,0],[4.4,9.09]],"id":69112387}],"con":true,"img":false}]}
{"op":"mcm","clk":"11540847776","pt":1719499062648,"mc":[{"id":"1.230180120","rc":[{"atb":[[2.46,8.11]],"id":47370245}],"con":true,"img":false}]}
{"op":"mcm","clk":"11540847783","pt":1719499062757,"mc":[{"id":"1.230180120","rc":[{"atb":[[2.44,8.22]],"id":62847579}],"con":true,"img":false}]}
{"op":"mcm","clk":"11540847791","pt":1719499062856,"mc":[{"id":"1.230180120","rc":[{"atb":[[2.4,8.45]],"id":64253834}],"con":true,"img":false}]}
{"op":"mcm","clk":"11540847802","pt":1719499063060,"mc":[{"id":"1.230180120","rc":[{"atb":[[2.4,8.45]],"id":53432239}],"con":true,"img":false}]}
{"op":"mcm","clk":"11540847808","pt":1719499063170,"mc":[{"id":"1.230180120","rc":[{"atl":[[3.95,0.84]],"id":69112387}],"con":true,"img":false}]}
{"op":"mcm","clk":"11540847915","pt":1719499064360,"mc":[{"id":"1.230180120","rc":[{"atb":[[5.4,0.84]],"id":64253834}],"con":true,"img":false}]}
{"op":"mcm","clk":"11540847939","pt":1719499064661,"mc":[{"id":"1.230180120","rc":[{"atb":[[5.4,0],[5.1,1.6],[5.5,0]],"id":64253834}],"con":true,"img":false}]}
{"op":"mcm","clk":"11540847992","pt":1719499065230,"mc":[{"id":"1.230180120","rc":[{"atb":[[1.09,1]],"id":64253834}],"con":true,"img":false}]}
{"op":"mcm","clk":"11540848004","pt":1719499065435,"mc":[{"id":"1.230180120","rc":[{"atb":[[1.09,0.24]],"id":64253834}],"con":true,"img":false}]}
{"op":"mcm","clk":"11540848019","pt":1719499065657,"mc":[{"id":"1.230180120","rc":[{"atb":[[1.09,0]],"id":64253834}],"con":true,"img":false}]}
{"op":"mcm","clk":"11540848025","pt":1719499065745,"mc":[{"id":"1.230180120","rc":[{"atb":[[5.2,0.24]],"id":64253834}],"con":true,"img":false}]}
{"op":"mcm","clk":"11540848054","pt":1719499066160,"mc":[{"id":"1.230180120","rc":[{"atb":[[5.2,1.08]],"id":64253834}],"con":true,"img":false}]}
{"op":"mcm","clk":"11540848078","pt":1719499066466,"mc":[{"id":"1.230180120","rc":[{"atb":[[5.3,1.6],[5.1,0.05]],"id":64253834}],"con":true,"img":false}]}
{"op":"mcm","clk":"11540848183","pt":1719499067767,"mc":[{"id":"1.230180120","rc":[{"atl":[[4,0]],"id":69112387}],"con":true,"img":false}]}
{"op":"mcm","clk":"11540848213","pt":1719499068272,"mc":[{"id":"1.230180120","rc":[{"atl":[[3.95,0]],"id":69112387}],"con":true,"img":false}]}
{"op":"mcm","clk":"11540848221","pt":1719499068380,"mc":[{"id":"1.230180120","rc":[{"atl":[[12,9.09],[4.4,0]],"id":69112387}],"con":true,"img":false}]}
{"op":"mcm","clk":"11540848245","pt":1719499068637,"mc":[{"id":"1.230180120","rc":[{"atb":[[5.3,1.6]],"id":62847579}],"con":true,"img":false}]}
{"op":"mcm","clk":"11540848256","pt":1719499068739,"mc":[{"id":"1.230180120","rc":[{"atb":[[5.1,3.31]],"id":62847579}],"con":true,"img":false}]}
{"op":"mcm","clk":"11540848271","pt":1719499068952,"mc":[{"id":"1.230180120","rc":[{"atb":[[5.3,0]],"id":62847579}],"con":true,"img":false}]}
{"op":"mcm","clk":"11540848297","pt":1719499069261,"mc":[{"id":"1.230180120","rc":[{"atb":[[5.2,2.44]],"id":62847579}],"con":true,"img":false}]}
{"op":"mcm","clk":"11540848340","pt":1719499069975,"mc":[{"id":"1.230180120","rc":[{"atl":[[4,2]],"id":69112387}],"con":true,"img":false}]}
{"op":"mcm","clk":"11540848394","pt":1719499070647,"mc":[{"id":"1.230180120","rc":[{"atl":[[3.95,0.84]],"id":69112387}],"con":true,"img":false}]}
{"op":"mcm","clk":"11540848602","pt":1719499073292,"mc":[{"id":"1.230180120","rc":[{"atl":[[25,0]],"id":47370245}],"con":true,"img":false}]}
{"op":"mcm","clk":"11540848628","pt":1719499073453,"mc":[{"id":"1.230180120","rc":[{"atl":[[1000,0.21]],"id":47370245}],"con":true,"img":false}]}
{"op":"mcm","clk":"11540848651","pt":1719499073662,"mc":[{"id":"1.230180120","rc":[{"atl":[[1000,0.17]],"id":47370245}],"con":true,"img":false}]}
{"op":"mcm","clk":"11540848660","pt":1719499073771,"mc":[{"id":"1.230180120","rc":[{"atl":[[25,0.04]],"id":47370245}],"con":true,"img":false}]}
{"op":"mcm","clk":"11540848773","pt":1719499075268,"mc":[{"id":"1.230180120","rc":[{"atl":[[4,0]],"id":69112387}],"con":true,"img":false}]}
{"op":"mcm","clk":"11540848803","pt":1719499075781,"mc":[{"id":"1.230180120","rc":[{"atl":[[3.95,0]],"id":69112387}],"con":true,"img":false}]}
{"op":"mcm","clk":"11540848904","pt":1719499077379,"mc":[{"id":"1.230180120","rc":[{"atl":[[4,2]],"id":69112387}],"con":true,"img":false}]}
{"op":"mcm","clk":"11540848913","pt":1719499077482,"mc":[{"id":"1.230180120","rc":[{"atl":[[12,0],[4.4,9.09]],"id":69112387}],"con":true,"img":false}]}
{"op":"mcm","clk":"11540848920","pt":1719499077583,"mc":[{"id":"1.230180120","rc":[{"atl":[[3.95,0.84]],"id":69112387}],"con":true,"img":false}]}
{"op":"mcm","clk":"11540849196","pt":1719499081062,"mc":[{"id":"1.230180120","rc":[{"atb":[[5.2,0.84]],"id":64253834}],"con":true,"img":false}]}
{"op":"mcm","clk":"11540849212","pt":1719499081272,"mc":[{"id":"1.230180120","rc":[{"atb":[[1.09,1]],"id":64253834}],"con":true,"img":false}]}
{"op":"mcm","clk":"11540849223","pt":1719499081378,"mc":[{"id":"1.230180120","rc":[{"atb":[[5.1,1.65]],"id":64253834}],"con":true,"img":false}]}
{"op":"mcm","clk":"11540849231","pt":1719499081481,"mc":[{"id":"1.230180120","rc":[{"atb":[[5.3,0],[1.09,0.23]],"id":64253834}],"con":true,"img":false}]}
{"op":"mcm","clk":"11540849241","pt":1719499081585,"mc":[{"id":"1.230180120","rc":[{"atb":[[1.09,0]],"id":64253834}],"con":true,"img":false}]}
{"op":"mcm","clk":"11540849249","pt":1719499081688,"mc":[{"id":"1.230180120","rc":[{"atb":[[5.4,1.79],[5.1,0.05]],"id":64253834}],"con":true,"img":false}]}
{"op":"mcm","clk":"11540849279","pt":1719499082113,"mc":[{"id":"1.230180120","rc":[{"atb":[[5.5,0.84]],"id":64253834}],"con":true,"img":false}]}
{"op":"mcm","clk":"11540849289","pt":1719499082216,"mc":[{"id":"1.230180120","rc":[{"atb":[[5.2,0]],"id":64253834}],"con":true,"img":false}]}
{"op":"mcm","clk":"11540849318","pt":1719499082709,"mc":[{"id":"1.230180120","rc":[{"atl":[[4,0]],"id":69112387}],"con":true,"img":false}]}
{"op":"mcm","clk":"11540849361","pt":1719499083199,"mc":[{"id":"1.230180120","rc":[{"atl":[[3.95,0]],"id":69112387}],"con":true,"img":false}]}
{"op":"mcm","clk":"11540849382","pt":1719499083404,"mc":[{"id":"1.230180120","rc":[{"atl":[[12,9.09],[4.4,0]],"id":69112387}],"con":true,"img":false}]}
{"op":"mcm","clk":"11540849489","pt":1719499084791,"mc":[{"id":"1.230180120","rc":[{"atl":[[4,2]],"id":69112387}],"con":true,"img":false}]}
{"op":"mcm","clk":"11540849515","pt":1719499085108,"mc":[{"id":"1.230180120","rc":[{"atb":[[2.58,0]],"id":69112387},{"atl":[[3.95,0.84]],"id":69112387}],"con":true,"img":false}]}
{"op":"mcm","clk":"11540849537","pt":1719499085314,"mc":[{"id":"1.230180120","rc":[{"atl":[[12,0],[4.4,9.09]],"id":69112387}],"con":true,"img":false}]}
{"op":"mcm","clk":"11540849546","pt":1719499085418,"mc":[{"id":"1.230180120","rc":[{"atb":[[4.1,0]],"id":47370245}],"con":true,"img":false}]}
{"op":"mcm","clk":"11540849578","pt":1719499085675,"mc":[{"id":"1.230180120","rc":[{"atb":[[5.1,1.62]],"id":53432239},{"atb":[[1.06,1.69]],"id":69112387}],"con":true,"img":false}]}
{"op":"mcm","clk":"11540849604","pt":1719499085983,"mc":[{"id":"1.230180120","rc":[{"atb":[[1.09,1.69]],"id":47370245}],"con":true,"img":false}]}
{"op":"mcm","clk":"11540849650","pt":1719499086416,"mc":[{"id":"1.230180120","rc":[{"atb":[[1.09,0.07]],"id":47370245},{"atb":[[1.06,0.11]],"id":69112387}],"con":true,"img":false}]}
{"op":"mcm","clk":"11540849682","pt":1719499086705,"mc":[{"id":"1.230180120","rc":[{"atb":[[1.09,0]],"id":47370245}],"con":true,"img":false}]}
{"op":"mcm","clk":"11540849689","pt":1719499086812,"mc":[{"id":"1.230180120","rc":[{"atb":[[4.1,0.07]],"id":47370245}],"con":true,"img":false}]}
{"op":"mcm","clk":"11540849716","pt":1719499087070,"mc":[{"id":"1.230180120","rc":[{"atb":[[1.06,0]],"id":69112387}],"con":true,"img":false}]}
{"op":"mcm","clk":"11540849725","pt":1719499087171,"mc":[{"id":"1.230180120","rc":[{"atb":[[2.58,0.11]],"id":69112387}],"con":true,"img":false}]}
{"op":"mcm","clk":"11540849749","pt":1719499087481,"mc":[{"id":"1.230180120","rc":[{"atb":[[5.1,3.26]],"id":62847579},{"atb":[[5.1,0]],"id":64253834}],"con":true,"img":false}]}
{"op":"mcm","clk":"11540849759","pt":1719499087690,"mc":[{"id":"1.230180120","rc":[{"atb":[[1.12,1.69]],"id":53432239}],"con":true,"img":false}]}
{"op":"mcm","clk":"11540849771","pt":1719499087790,"mc":[{"id":"1.230180120","rc":[{"atb":[[4.8,0]],"id":64536702}],"con":true,"img":false}]}
{"op":"mcm","clk":"11540849788","pt":1719499087998,"mc":[{"id":"1.230180120","rc":[{"atb":[[1.12,0.05]],"id":53432239}],"con":true,"img":false}]}
{"op":"mcm","clk":"11540849804","pt":1719499088201,"mc":[{"id":"1.230180120","rc":[{"atb":[[1.1,1.69]],"id":64536702}],"con":true,"img":false}]}
{"op":"mcm","clk":"11540849810","pt":1719499088310,"mc":[{"id":"1.230180120","rc":[{"atb":[[1.12,1.69]],"id":62847579}],"con":true,"img":false}]}
{"op":"mcm","clk":"11540849826","pt":1719499088511,"mc":[{"id":"1.230180120","rc":[{"atb":[[2.42,0]],"id":62847579},{"atb":[[2.38,0]],"id":53432239},{"atb":[[2.44,0]],"id":47370245},{"atb":[[2.38,0]],"id":64253834}],"con":true,"img":false}]}
{"op":"mcm","clk":"11540849834","pt":1719499088614,"mc":[{"id":"1.230180120","rc":[{"atb":[[1.14,1.69]],"id":64253834}],"con":true,"img":false}]}
{"op":"mcm","clk":"11540849847","pt":1719499088773,"mc":[{"id":"1.230180120","rc":[{"atb":[[1.12,0]],"id":53432239}],"con":true,"img":false}]}
{"op":"mcm","clk":"11540849857","pt":1719499088877,"mc":[{"id":"1.230180120","rc":[{"atb":[[5.2,0.05]],"id":53432239}],"con":true,"img":false}]}
{"op":"mcm","clk":"11540849872","pt":1719499088982,"mc":[{"id":"1.230180120","rc":[{"atl":[[25,0]],"id":47370245}],"con":true,"img":false}]}
{"op":"mcm","clk":"11540849886","pt":1719499089186,"mc":[{"id":"1.230180120","rc":[{"atl":[[1000,0.21]],"id":47370245},{"atb":[[1.1,0.06]],"id":64536702}],"con":true,"img":false}]}
{"op":"mcm","clk":"11540849901","pt":1719499089397,"mc":[{"id":"1.230180120","rc":[{"atb":[[1.12,0.05]],"id":62847579},{"atl":[[1000,0.17]],"id":47370245}],"con":true,"img":false}]}
{"op":"mcm","clk":"11540849908","pt":1719499089496,"mc":[{"id":"1.230180120","rc":[{"atl":[[25,0.04]],"id":47370245},{"atb":[[1.14,0.05]],"id":64253834}],"con":true,"img":false}]}
{"op":"mcm","clk":"11540849932","pt":1719499089905,"mc":[{"id":"1.230180120","rc":[{"atb":[[1.1,0]],"id":64536702}],"con":true,"img":false}]}
{"op":"mcm","clk":"11540849941","pt":1719499090010,"mc":[{"id":"1.230180120","rc":[{"atb":[[4.8,0.06]],"id":64536702},{"atl":[[4,0]],"id":69112387}],"con":true,"img":false}]}
{"op":"mcm","clk":"11540849973","pt":1719499090329,"mc":[{"id":"1.230180120","rc":[{"atb":[[1.12,0]],"id":62847579}],"con":true,"img":false}]}
{"op":"mcm","clk":"11540849979","pt":1719499090378,"mc":[{"id":"1.230180120","rc":[{"atb":[[5.3,0.05]],"id":62847579}],"con":true,"img":false}]}
{"op":"mcm","clk":"11540849994","pt":1719499090688,"mc":[{"id":"1.230180120","rc":[{"atl":[[3.95,0]],"id":69112387},{"atb":[[1.14,0]],"id":64253834}],"con":true,"img":false}]}
{"op":"mcm","clk":"11540850001","pt":1719499090788,"mc":[{"id":"1.230180120","rc":[{"atb":[[5.6,0.05]],"id":64253834}],"con":true,"img":false}]}
{"op":"mcm","clk":"11540850007","pt":1719499090889,"mc":[{"id":"1.230180120","rc":[{"atl":[[12,9.09],[4.4,0]],"id":69112387}],"con":true,"img":false}]}
{"op":"mcm","clk":"11540850082","pt":1719499092079,"mc":[{"id":"1.230180120","rc":[{"atl":[[4,2]],"id":69112387}],"con":true,"img":false}]}
{"op":"mcm","clk":"11540850112","pt":1719499092601,"mc":[{"id":"1.230180120","rc":[{"atl":[[3.95,0.84]],"id":69112387}],"con":true,"img":false}]}
{"op":"mcm","clk":"11540850465","pt":1719499096880,"mc":[{"id":"1.230180120","rc":[{"atb":[[5.4,1.56]],"id":64253834}],"con":true,"img":false}]}
{"op":"mcm","clk":"11540850486","pt":1719499097291,"mc":[{"id":"1.230180120","rc":[{"atl":[[4,0]],"id":69112387}],"con":true,"img":false}]}
{"op":"mcm","clk":"11540850510","pt":1719499097703,"mc":[{"id":"1.230180120","rc":[{"atl":[[3.95,0]],"id":69112387}],"con":true,"img":false}]}
{"op":"mcm","clk":"11540850532","pt":1719499098113,"mc":[{"id":"1.230180120","rc":[{"atb":[[7.6,1]],"id":62847579},{"atb":[[5.5,1]],"id":53432239},{"atb":[[4.7,1]],"id":47370245},{"atb":[[3.7,1]],"id":64536702},{"atb":[[2.1,1]],"id":69112387},{"atb":[[6,1]],"id":64253834}],"con":true,"img":false}]}
{"op":"mcm","clk":"11540850538","pt":1719499098217,"mc":[{"id":"1.230180120","rc":[{"atb":[[3.6,0.78],[4,7]],"id":47370245},{"atb":[[3.25,6],[2.76,0]],"id":64536702}],"con":true,"img":false}]}
{"op":"mcm","clk":"11540850556","pt":1719499098425,"mc":[{"id":"1.230180120","rc":[{"atb":[[5.1,0]],"id":53432239}],"con":true,"img":false}]}
{"op":"mcm","clk":"11540850565","pt":1719499098526,"mc":[{"id":"1.230180120","rc":[{"atl":[[1000,0.84]],"id":53432239}],"con":true,"img":false}]}
{"op":"mcm","clk":"11540850579","pt":1719499098690,"mc":[{"id":"1.230180120","rc":[{"atb":[[5.6,1.51]],"id":53432239}],"con":true,"img":false}]}
{"op":"mcm","clk":"11540850585","pt":1719499098788,"mc":[{"id":"1.230180120","rc":[{"atb":[[1.11,1]],"id":64253834}],"con":true,"img":false}]}
{"op":"mcm","clk":"11540850601","pt":1719499098991,"mc":[{"id":"1.230180120","rc":[{"atl":[[1000,0.65]],"id":53432239},{"atb":[[1.11,0.19]],"id":64253834}],"con":true,"img":false}]}
{"op":"mcm","clk":"11540850609","pt":1719499099094,"mc":[{"id":"1.230180120","rc":[{"atl":[[26,0.84]],"id":47370245}],"con":true,"img":false}]}
{"op":"mcm","clk":"11540850617","pt":1719499099197,"mc":[{"id":"1.230180120","rc":[{"atb":[[1.11,0]],"id":64253834}],"con":true,"img":false}]}
{"op":"mcm","clk":"11540850627","pt":1719499099305,"mc":[{"id":"1.230180120","rc":[{"atl":[[1000,1.02]],"id":47370245},{"atb":[[6.2,0.19]],"id":64253834}],"con":true,"img":false}]}
{"op":"mcm","clk":"11540850649","pt":1719499099503,"mc":[{"id":"1.230180120","rc":[{"atl":[[4,2]],"id":69112387}],"con":true,"img":false}]}
{"op":"mcm","clk":"11540850658","pt":1719499099606,"mc":[{"id":"1.230180120","rc":[{"atl":[[1000,0]],"id":53432239},{"atl":[[12,0],[4.4,9.09]],"id":69112387}],"con":true,"img":false}]}
{"op":"mcm","clk":"11540850663","pt":1719499099710,"mc":[{"id":"1.230180120","rc":[{"atl":[[13,0.65]],"id":53432239}],"con":true,"img":false}]}
{"op":"mcm","clk":"11540850683","pt":1719499100020,"mc":[{"id":"1.230180120","rc":[{"atl":[[1000,0.53]],"id":47370245}],"con":true,"img":false}]}
{"op":"mcm","clk":"11540850701","pt":1719499100136,"mc":[{"id":"1.230180120","rc":[{"atl":[[3.95,0.84]],"id":69112387}],"con":true,"img":false}]}
{"op":"mcm","clk":"11540850710","pt":1719499100336,"mc":[{"id":"1.230180120","rc":[{"atl":[[1000,0.17]],"id":47370245}],"con":true,"img":false}]}
{"op":"mcm","clk":"11540850726","pt":1719499100446,"mc":[{"id":"1.230180120","rc":[{"atl":[[24,0.35]],"id":47370245},{"atb":[[2.22,0]],"id":64536702}],"con":true,"img":false}]}
{"op":"mcm","clk":"11540850929","pt":1719499102833,"mc":[{"id":"1.230180120","rc":[{"atb":[[2.78,0.89]],"id":64536702}],"con":true,"img":false}]}
{"op":"mcm","clk":"11540851077","pt":1719499104695,"mc":[{"id":"1.230180120","rc":[{"atl":[[25,0]],"id":47370245},{"atl":[[4,0]],"id":69112387}],"con":true,"img":false}]}
{"op":"mcm","clk":"11540851118","pt":1719499105214,"mc":[{"id":"1.230180120","rc":[{"atl":[[3.95,0]],"id":69112387}],"con":true,"img":false}]}
{"op":"mcm","clk":"11540851142","pt":1719499105427,"mc":[{"id":"1.230180120","rc":[{"atl":[[12,9.09],[4.4,0]],"id":69112387}],"con":true,"img":false}]}
{"op":"mcm","clk":"11540851197","pt":1719499106097,"mc":[{"id":"1.230180120","rc":[{"atl":[[1000,0.21]],"id":47370245}],"con":true,"img":false}]}
{"op":"mcm","clk":"11540851215","pt":1719499106411,"mc":[{"id":"1.230180120","rc":[{"atl":[[1000,0.17]],"id":47370245}],"con":true,"img":false}]}
{"op":"mcm","clk":"11540851225","pt":1719499106507,"mc":[{"id":"1.230180120","rc":[{"atl":[[25,0.04]],"id":47370245}],"con":true,"img":false}]}
{"op":"mcm","clk":"11540851245","pt":1719499106814,"mc":[{"id":"1.230180120","rc":[{"atl":[[4,2]],"id":69112387}],"con":true,"img":false}]}
{"op":"mcm","clk":"11540851263","pt":1719499107020,"mc":[{"id":"1.230180120","rc":[{"atl":[[12,0],[4.4,9.09]],"id":69112387}],"con":true,"img":false}]}
{"op":"mcm","clk":"11540851306","pt":1719499107591,"mc":[{"id":"1.230180120","rc":[{"atl":[[3.95,0.84]],"id":69112387}],"con":true,"img":false}]}
{"op":"mcm","clk":"11540851612","pt":1719499112038,"mc":[{"id":"1.230180120","rc":[{"atl":[[4,0]],"id":69112387}],"con":true,"img":false}]}
{"op":"mcm","clk":"11540851672","pt":1719499112715,"mc":[{"id":"1.230180120","rc":[{"atl":[[3.95,0]],"id":69112387}],"con":true,"img":false}]}
{"op":"mcm","clk":"11540851680","pt":1719499112813,"mc":[{"id":"1.230180120","rc":[{"spn":68.8,"spf":"NaN","id":62847579},{"spn":14.35,"spf":"NaN","id":47370245},{"spn":3.75,"spf":1.0,"id":64536702},{"atl":[[12,9.09],[4.4,0]],"id":69112387},{"spn":73.1,"spf":"NaN","id":64253834}],"con":true,"img":false}]}
{"op":"mcm","clk":"11540851768","pt":1719499114206,"mc":[{"id":"1.230180120","rc":[{"atl":[[4,2]],"id":69112387}],"con":true,"img":false}]}
{"op":"mcm","clk":"11540851787","pt":1719499114413,"mc":[{"id":"1.230180120","rc":[{"atl":[[12,0],[4.4,9.09]],"id":69112387}],"con":true,"img":false}]}
{"op":"mcm","clk":"11540851794","pt":1719499114518,"mc":[{"id":"1.230180120","rc":[{"atb":[[6.2,0]],"id":64253834}],"con":true,"img":false}]}
{"op":"mcm","clk":"11540851800","pt":1719499114616,"mc":[{"id":"1.230180120","rc":[{"atl":[[3.95,0.84]],"id":69112387}],"con":true,"img":false}]}
{"op":"mcm","clk":"11540851807","pt":1719499114718,"mc":[{"id":"1.230180120","rc":[{"atb":[[1.11,1]],"id":64253834}],"con":true,"img":false}]}
{"op":"mcm","clk":"11540851819","pt":1719499114925,"mc":[{"id":"1.230180120","rc":[{"atb":[[1.11,0.19]],"id":64253834}],"con":true,"img":false}]}
{"op":"mcm","clk":"11540851840","pt":1719499115137,"mc":[{"id":"1.230180120","rc":[{"atb":[[1.11,0]],"id":64253834}],"con":true,"img":false}]}
{"op":"mcm","clk":"11540851848","pt":1719499115241,"mc":[{"id":"1.230180120","rc":[{"atb":[[6.2,0.19]],"id":64253834}],"con":true,"img":false}]}
{"op":"mcm","clk":"11540851912","pt":1719499116215,"mc":[{"id":"1.230180120","rc":[{"atb":[[3.6,0]],"id":47370245},{"atb":[[2.78,0]],"id":64536702}],"con":true,"img":false}]}
{"op":"mcm","clk":"11540852113","pt":1719499119412,"mc":[{"id":"1.230180120","rc":[{"atl":[[4,0]],"id":69112387}],"con":true,"img":false}]}
{"op":"mcm","clk":"11540852161","pt":1719499120134,"mc":[{"id":"1.230180120","rc":[{"atl":[[3.95,0]],"id":69112387}],"con":true,"img":false}]}
{"op":"mcm","clk":"11540852170","pt":1719499120237,"mc":[{"id":"1.230180120","rc":[{"atl":[[12,9.09],[4.4,0]],"id":69112387}],"con":true,"img":false}]}
{"op":"mcm","clk":"11540852237","pt":1719499121122,"mc":[{"id":"1.230180120","rc":[{"atb":[[2.74,6.8]],"id":64536702}],"con":true,"img":false}]}
{"op":"mcm","clk":"11540852276","pt":1719499121631,"mc":[{"id":"1.230180120","rc":[{"atl":[[4,2]],"id":69112387}],"con":true,"img":false}]}
{"op":"mcm","clk":"11540852287","pt":1719499121733,"mc":[{"id":"1.230180120","rc":[{"atl":[[25,0]],"id":47370245},{"atl":[[12,0],[4.4,9.09]],"id":69112387}],"con":true,"img":false}]}
{"op":"mcm","clk":"11540852302","pt":1719499121940,"mc":[{"id":"1.230180120","rc":[{"atl":[[1000,0.21]],"id":47370245}],"con":true,"img":false}]}
{"op":"mcm","clk":"11540852316","pt":1719499122152,"mc":[{"id":"1.230180120","rc":[{"atl":[[1000,0.17]],"id":47370245},{"atl":[[3.95,0.84]],"id":69112387}],"con":true,"img":false}]}
{"op":"mcm","clk":"11540852323","pt":1719499122255,"mc":[{"id":"1.230180120","rc":[{"atl":[[25,0.04]],"id":47370245}],"con":true,"img":false}]}
{"op":"mcm","clk":"11540852570","pt":1719499126128,"mc":[{"id":"1.230180120","rc":[{"atb":[[2.44,0]],"id":62847579},{"atb":[[2.4,0]],"id":53432239},{"atb":[[2.46,0]],"id":47370245},{"atb":[[2.4,0]],"id":64253834}],"con":true,"img":false}]}
{"op":"mcm","clk":"11540852629","pt":1719499126850,"mc":[{"id":"1.230180120","rc":[{"atl":[[4,0]],"id":69112387}],"con":true,"img":false}]}
{"op":"mcm","clk":"11540852657","pt":1719499127261,"mc":[{"id":"1.230180120","rc":[{"atl":[[3.95,0]],"id":69112387}],"con":true,"img":false}]}
{"op":"mcm","clk":"11540852666","pt":1719499127319,"mc":[{"id":"1.230180120","rc":[{"atl":[[12,9.09],[4.4,0]],"id":69112387}],"con":true,"img":false}]}
{"op":"mcm","clk":"11540852748","pt":1719499128759,"mc":[{"id":"1.230180120","rc":[{"atb":[[6.4,1.32],[5.4,0]],"id":64253834}],"con":true,"img":false}]}
{"op":"mcm","clk":"11540852767","pt":1719499129070,"mc":[{"id":"1.230180120","rc":[{"atb":[[6.4,0],[6.2,1.51]],"id":64253834}],"con":true,"img":false}]}
{"op":"mcm","clk":"11540852774","pt":1719499129123,"mc":[{"id":"1.230180120","rc":[{"atb":[[5.5,0]],"id":64253834}],"con":true,"img":false}]}
{"op":"mcm","clk":"11540852813","pt":1719499129641,"mc":[{"id":"1.230180120","rc":[{"atl":[[4,2]],"id":69112387}],"con":true,"img":false}]}
{"op":"mcm","clk":"11540852821","pt":1719499129744,"mc":[{"id":"1.230180120","rc":[{"atl":[[12,0],[4.4,9.09]],"id":69112387}],"con":true,"img":false}]}
{"op":"mcm","clk":"11540852851","pt":1719499130156,"mc":[{"id":"1.230180120","rc":[{"atl":[[3.95,0.84]],"id":69112387}],"con":true,"img":false}]}
{"op":"mcm","clk":"11540852868","pt":1719499130483,"mc":[{"id":"1.230180120","rc":[{"atb":[[6.2,1.32]],"id":64253834}],"con":true,"img":false}]}
{"op":"mcm","clk":"11540852928","pt":1719499131357,"mc":[{"id":"1.230180120","rc":[{"atb":[[1.11,1]],"id":64253834}],"con":true,"img":false}]}
{"op":"mcm","clk":"11540852949","pt":1719499131661,"mc":[{"id":"1.230180120","rc":[{"atb":[[1.11,0.19]],"id":64253834}],"con":true,"img":false}]}
{"op":"mcm","clk":"11540852969","pt":1719499131869,"mc":[{"id":"1.230180120","rc":[{"atb":[[2.38,8.58]],"id":47370245},{"atb":[[1.11,0]],"id":64253834}],"con":true,"img":false}]}
{"op":"mcm","clk":"11540852978","pt":1719499131971,"mc":[{"id":"1.230180120","rc":[{"atb":[[6.4,0.19]],"id":64253834}],"con":true,"img":false}]}
{"op":"mcm","clk":"11540852985","pt":1719499132030,"mc":[{"id":"1.230180120","rc":[{"atb":[[2.36,8.71]],"id":62847579}],"con":true,"img":false}]}
{"op":"mcm","clk":"11540852994","pt":1719499132124,"mc":[{"id":"1.230180120","rc":[{"atb":[[2.32,8.97]],"id":53432239}],"con":true,"img":false}]}
{"op":"mcm","clk":"11540853009","pt":1719499132332,"mc":[{"id":"1.230180120","rc":[{"atb":[[2.32,8.97]],"id":64253834}],"con":true,"img":false}]}
{"op":"mcm","clk":"11540853151","pt":1719499134853,"mc":[{"id":"1.230180120","rc":[{"atl":[[4,0]],"id":69112387}],"con":true,"img":false}]}
{"op":"mcm","clk":"11540853173","pt":1719499135266,"mc":[{"id":"1.230180120","rc":[{"atl":[[3.95,0]],"id":69112387}],"con":true,"img":false}]}
{"op":"mcm","clk":"11540853180","pt":1719499135374,"mc":[{"id":"1.230180120","rc":[{"atl":[[12,9.09],[4.4,0]],"id":69112387}],"con":true,"img":false}]}
{"op":"mcm","clk":"11540853295","pt":1719499137031,"mc":[{"id":"1.230180120","rc":[{"atl":[[4,2]],"id":69112387}],"con":true,"img":false}]}
{"op":"mcm","clk":"11540853325","pt":1719499137540,"mc":[{"id":"1.230180120","rc":[{"atl":[[25,0]],"id":47370245}],"con":true,"img":false}]}
{"op":"mcm","clk":"11540853331","pt":1719499137647,"mc":[{"id":"1.230180120","rc":[{"atl":[[3.95,0.84]],"id":69112387}],"con":true,"img":false}]}
{"op":"mcm","clk":"11540853427","pt":1719499138941,"mc":[{"id":"1.230180120","rc":[{"atl":[[1000,0.21]],"id":47370245}],"con":true,"img":false}]}
{"op":"mcm","clk":"11540853444","pt":1719499139166,"mc":[{"id":"1.230180120","rc":[{"atl":[[1000,0.17]],"id":47370245}],"con":true,"img":false}]}
{"op":"mcm","clk":"11540853453","pt":1719499139245,"mc":[{"id":"1.230180120","rc":[{"atl":[[25,0.04]],"id":47370245}],"con":true,"img":false}]}
{"op":"mcm","clk":"11540853580","pt":1719499141259,"mc":[{"id":"1.230180120","rc":[{"atb":[[1.01,1]],"id":64536702}],"con":true,"img":false}]}
{"op":"mcm","clk":"11540853633","pt":1719499141936,"mc":[{"id":"1.230180120","rc":[{"atl":[[130,1.84]],"id":62847579},{"atl":[[13,1.65]],"id":53432239},{"atl":[[26,1.84]],"id":47370245},{"atl":[[26,1]],"id":64536702},{"atl":[[3.95,1.84]],"id":69112387},{"atl":[[130,1]],"id":64253834}],"con":true,"img":false}]}
{"op":"mcm","clk":"11540853642","pt":1719499142042,"mc":[{"id":"1.230180120","rc":[{"atl":[[25,3.05],[27,0]],"id":47370245}],"con":true,"img":false}]}
{"op":"mcm","clk":"11540853653","pt":1719499142144,"mc":[{"id":"1.230180120","rc":[{"atl":[[180,1]],"id":62847579},{"atb":[[3.3,1]],"id":64536702},{"atl":[[4.3,1]],"id":69112387},{"atb":[[5.6,1.05]],"id":64253834}],"con":true,"img":false}]}
{"op":"mcm","clk":"11540853663","pt":1719499142248,"mc":[{"id":"1.230180120","rc":[{"atl":[[4,0]],"id":69112387}],"con":true,"img":false}]}
{"op":"mcm","clk":"11540853685","pt":1719499142557,"mc":[{"id":"1.230180120","rc":[{"atl":[[12,0],[4.4,9.09]],"id":69112387}],"con":true,"img":false}]}
{"op":"mcm","clk":"11540853691","pt":1719499142661,"mc":[{"id":"1.230180120","rc":[{"atl":[[24,1.2]],"id":47370245}],"con":true,"img":false}]}
{"op":"mcm","clk":"11540853722","pt":1719499143076,"mc":[{"id":"1.230180120","rc":[{"atl":[[26,0.84]],"id":47370245},{"atl":[[3.95,0.84]],"id":69112387}],"con":true,"img":false}]}
{"op":"mcm","clk":"11540853732","pt":1719499143179,"mc":[{"id":"1.230180120","rc":[{"atl":[[24,2.2]],"id":47370245},{"atl":[[4.3,2]],"id":69112387}],"con":true,"img":false}]}
{"op":"mcm","clk":"11540853741","pt":1719499143281,"mc":[{"id":"1.230180120","rc":[{"atl":[[25,2.04]],"id":47370245}],"con":true,"img":false}]}
{"op":"mcm","clk":"11540853748","pt":1719499143334,"mc":[{"id":"1.230180120","rc":[{"atl":[[4.3,1]],"id":69112387}],"con":true,"img":false}]}
{"op":"mcm","clk":"11540853758","pt":1719499143438,"mc":[{"id":"1.230180120","rc":[{"atl":[[23,1.1]],"id":47370245}],"con":true,"img":false}]}
{"op":"mcm","clk":"11540853764","pt":1719499143547,"mc":[{"id":"1.230180120","rc":[{"atl":[[23,3.14],[25,0.04]],"id":47370245},{"atl":[[3.95,1.84]],"id":69112387}],"con":true,"img":false}]}
{"op":"mcm","clk":"11540853772","pt":1719499143646,"mc":[{"id":"1.230180120","rc":[{"atl":[[23,1.1],[24,4.4],[26,0]],"id":47370245},{"atl":[[3.95,1]],"id":69112387}],"con":true,"img":false}]}
{"op":"mcm","clk":"11540853779","pt":1719499143747,"mc":[{"id":"1.230180120","rc":[{"atl":[[24,4.04],[1000,1.02]],"id":47370245},{"atl":[[3.95,0]],"id":69112387}],"con":true,"img":false}]}
{"op":"mcm","clk":"11540853792","pt":1719499143960,"mc":[{"id":"1.230180120","rc":[{"atl":[[3.95,1]],"id":69112387}],"con":true,"img":false}]}
{"op":"mcm","clk":"11540853804","pt":1719499144074,"mc":[{"id":"1.230180120","rc":[{"atl":[[24,3.04],[1000,0.55]],"id":47370245},{"atb":[[1.02,16.49]],"id":69112387}],"con":true,"img":false}]}
{"op":"mcm","clk":"11540853815","pt":1719499144166,"mc":[{"id":"1.230180120","rc":[{"atl":[[27,1]],"id":47370245},{"atb":[[2.58,2.11]],"id":69112387},{"atl":[[3.95,0]],"id":69112387}],"con":true,"img":false}]}
{"op":"mcm","clk":"11540853842","pt":1719499144482,"mc":[{"id":"1.230180120","rc":[{"atl":[[1000,0.17]],"id":47370245},{"atl":[[4,2]],"id":69112387}],"con":true,"img":false}]}
{"op":"mcm","clk":"11540853850","pt":1719499144580,"mc":[{"id":"1.230180120","rc":[{"atl":[[22,0.38]],"id":47370245},{"atl":[[3.95,1]],"id":69112387}],"con":true,"img":false}]}
{"op":"mcm","clk":"11540853858","pt":1719499144683,"mc":[{"id":"1.230180120","rc":[{"atb":[[2.6,0.84]],"id":69112387}],"con":true,"img":false}]}
{"op":"mcm","clk":"11540853865","pt":1719499144792,"mc":[{"id":"1.230180120","rc":[{"atl":[[3.95,0]],"id":69112387}],"con":true,"img":false}]}
{"op":"mcm","clk":"11540853886","pt":1719499144948,"mc":[{"id":"1.230180120","rc":[{"atl":[[3.95,1]],"id":69112387}],"con":true,"img":false}]}
{"op":"mcm","clk":"11540853893","pt":1719499145044,"mc":[{"id":"1.230180120","rc":[{"atl":[[27,0]],"id":47370245},{"atl":[[4.3,0]],"id":69112387}],"con":true,"img":false}]}
{"op":"mcm","clk":"11540853902","pt":1719499145146,"mc":[{"id":"1.230180120","rc":[{"atl":[[23,2.1]],"id":47370245},{"atl":[[3.95,1.84]],"id":69112387}],"con":true,"img":false}]}
{"op":"mcm","clk":"11540853916","pt":1719499145362,"mc":[{"id":"1.230180120","rc":[{"atl":[[3.95,2.84]],"id":69112387}],"con":true,"img":false}]}
{"op":"mcm","clk":"11540853935","pt":1719499145558,"mc":[{"id":"1.230180120","rc":[{"atb":[[2.58,0.11]],"id":69112387}],"con":true,"img":false}]}
{"op":"mcm","clk":"11540853943","pt":1719499145667,"mc":[{"id":"1.230180120","rc":[{"atl":[[19.5,5.41],[24,0]],"id":53432239},{"atb":[[1.02,18.49]],"id":69112387},{"atl":[[3.95,4.84],[4.1,0],[4.4,0]],"id":69112387}],"con":true,"img":false}]}
{"op":"mcm","clk":"11540853952","pt":1719499145772,"mc":[{"id":"1.230180120","rc":[{"atl":[[4.4,1]],"id":69112387}],"con":true,"img":false}]}
{"op":"mcm","clk":"11540853962","pt":1719499145870,"mc":[{"id":"1.230180120","rc":[{"atl":[[4,7.7],[3.95,1.84]],"id":69112387}],"con":true,"img":false}]}
{"op":"mcm","clk":"11540853967","pt":1719499145973,"mc":[{"id":"1.230180120","rc":[{"atl":[[3.95,2.84]],"id":69112387}],"con":true,"img":false}]}
{"op":"mcm","clk":"11540853985","pt":1719499146181,"mc":[{"id":"1.230180120","rc":[{"atb":[[2.6,0]],"id":69112387}],"con":true,"img":false}]}
{"op":"mcm","clk":"11540854054","pt":1719499147073,"mc":[{"id":"1.230180120","rc":[{"atb":[[6.4,0]],"id":64253834}],"con":true,"img":false}]}
{"op":"mcm","clk":"11540854080","pt":1719499147379,"mc":[{"id":"1.230180120","rc":[{"atb":[[4.7,0]],"id":47370245},{"trd":[[4.7,1.99]],"ltp":4.7,"tv":1.99,"id":47370245},{"atb":[[1.11,1]],"id":64253834}],"con":true,"img":false}]}
{"op":"mcm","clk":"11540854089","pt":1719499147487,"mc":[{"id":"1.230180120","rc":[{"atb":[[1.11,0.19]],"id":64253834}],"con":true,"img":false}]}
{"op":"mcm","clk":"11540854098","pt":1719499147583,"mc":[{"id":"1.230180120","rc":[{"atb":[[4,1],[3.6,7.08]],"id":47370245},{"atl":[[28,0]],"id":47370245}],"con":true,"img":false}]}
{"op":"mcm","clk":"11540854111","pt":1719499147785,"mc":[{"id":"1.230180120","rc":[{"atb":[[1.11,0]],"id":64253834}],"con":true,"img":false}]}
{"op":"mcm","clk":"11540854113","pt":1719499147882,"mc":[{"id":"1.230180120","rc":[{"atb":[[6.4,0.19]],"id":64253834}],"con":true,"img":false}]}
{"op":"mcm","clk":"11540854189","pt":1719499148877,"mc":[{"id":"1.230180120","rc":[{"atb":[[2.38,4.17]],"id":69112387}],"con":true,"img":false}]}
{"op":"mcm","clk":"11540854253","pt":1719499149649,"mc":[{"id":"1.230180120","rc":[{"atl":[[4,5.7]],"id":69112387}],"con":true,"img":false}]}
{"op":"mcm","clk":"11540854289","pt":1719499150163,"mc":[{"id":"1.230180120","rc":[{"atl":[[22,1.22]],"id":47370245}],"con":true,"img":false}]}
{"op":"mcm","clk":"11540854304","pt":1719499150368,"mc":[{"id":"1.230180120","rc":[{"atl":[[22,3.32],[24,0.84]],"id":47370245}],"con":true,"img":false}]}
{"op":"mcm","clk":"11540854331","pt":1719499150674,"mc":[{"id":"1.230180120","rc":[{"atl":[[23,1],[24,0]],"id":47370245}],"con":true,"img":false}]}
{"op":"mcm","clk":"11540854341","pt":1719499150773,"mc":[{"id":"1.230180120","rc":[{"atl":[[21,1.21]],"id":47370245}],"con":true,"img":false}]}
{"op":"mcm","clk":"11540854351","pt":1719499150881,"mc":[{"id":"1.230180120","rc":[{"atl":[[23,0]],"id":47370245}],"con":true,"img":false}]}
{"op":"mcm","clk":"11540854356","pt":1719499150978,"mc":[{"id":"1.230180120","rc":[{"atl":[[30,1]],"id":47370245}],"con":true,"img":false}]}
{"op":"mcm","clk":"11540854382","pt":1719499151392,"mc":[{"id":"1.230180120","rc":[{"atl":[[30,0]],"id":47370245}],"con":true,"img":false}]}
{"op":"mcm","clk":"11540854391","pt":1719499151503,"mc":[{"id":"1.230180120","rc":[{"atl":[[21,2.21]],"id":47370245}],"con":true,"img":false}]}
{"op":"mcm","clk":"11540854424","pt":1719499151858,"mc":[{"id":"1.230180120","rc":[{"atl":[[3.9,2]],"id":69112387}],"con":true,"img":false}]}
{"op":"mcm","clk":"11540854429","pt":1719499151959,"mc":[{"id":"1.230180120","rc":[{"atl":[[4,0],[3.95,6.84]],"id":69112387}],"con":true,"img":false}]}
{"op":"mcm","clk":"11540854465","pt":1719499152480,"mc":[{"id":"1.230180120","rc":[{"atl":[[3.95,5.84]],"id":69112387}],"con":true,"img":false}]}
{"op":"mcm","clk":"11540854474","pt":1719499152581,"mc":[{"id":"1.230180120","rc":[{"atl":[[3.85,1]],"id":69112387}],"con":true,"img":false}]}
{"op":"mcm","clk":"11540854485","pt":1719499152686,"mc":[{"id":"1.230180120","rc":[{"atl":[[3.85,1.84]],"id":69112387}],"con":true,"img":false}]}
{"op":"mcm","clk":"11540854492","pt":1719499152785,"mc":[{"id":"1.230180120","rc":[{"atb":[[1.25,20]],"id":62847579},{"atb":[[1.25,20]],"id":53432239},{"atb":[[1.25,20]],"id":47370245},{"atb":[[1.25,20]],"id":64536702},{"atb":[[1.25,20]],"id":69112387},{"atb":[[1.25,20]],"id":64253834}],"con":true,"img":false}]}
{"op":"mcm","clk":"11540854514","pt":1719499153166,"mc":[{"id":"1.230180120","rc":[{"atl":[[3.95,5],[3.9,0]],"id":69112387}],"con":true,"img":false}]}
{"op":"mcm","clk":"11540854557","pt":1719499153768,"mc":[{"id":"1.230180120","rc":[{"atl":[[20,1.61]],"id":47370245}],"con":true,"img":false}]}
{"op":"mcm","clk":"11540854588","pt":1719499154290,"mc":[{"id":"1.230180120","rc":[{"atl":[[21,1]],"id":47370245}],"con":true,"img":false}]}
{"op":"mcm","clk":"11540854603","pt":1719499154495,"mc":[{"id":"1.230180120","rc":[{"atl":[[21,0]],"id":47370245},{"atl":[[3.85,0.84]],"id":69112387}],"con":true,"img":false}]}
{"op":"mcm","clk":"11540854610","pt":1719499154593,"mc":[{"id":"1.230180120","rc":[{"atl":[[19.5,1],[25,0]],"id":47370245},{"atb":[[2.38,3.38]],"id":69112387},{"atl":[[3.9,1]],"id":69112387}],"con":true,"img":false}]}
{"op":"mcm","clk":"11540854622","pt":1719499154752,"mc":[{"id":"1.230180120","rc":[{"atl":[[1000,0.22]],"id":47370245}],"con":true,"img":false}]}
{"op":"mcm","clk":"11540854641","pt":1719499154955,"mc":[{"id":"1.230180120","rc":[{"atl":[[1000,0.17]],"id":47370245}],"con":true,"img":false}]}
{"op":"mcm","clk":"11540854646","pt":1719499155059,"mc":[{"id":"1.230180120","rc":[{"atl":[[20,1.66]],"id":47370245}],"con":true,"img":false}]}
{"op":"mcm","clk":"11540854651","pt":1719499155167,"mc":[{"id":"1.230180120","rc":[{"atl":[[22,2.48]],"id":47370245}],"con":true,"img":false}]}
{"op":"mcm","clk":"11540854741","pt":1719499156554,"mc":[{"id":"1.230180120","rc":[{"atl":[[4.1,1],[4.4,0]],"id":69112387}],"con":true,"img":false}]}
{"op":"mcm","clk":"11540854784","pt":1719499157377,"mc":[{"id":"1.230180120","rc":[{"atl":[[20,3.66],[22,0.38]],"id":47370245}],"con":true,"img":false}]}
{"op":"mcm","clk":"11540854889","pt":1719499158974,"mc":[{"id":"1.230180120","rc":[{"atl":[[3.85,2.84]],"id":69112387},{"atb":[[6.6,1.28]],"id":64253834}],"con":true,"img":false}]}
{"op":"mcm","clk":"11540854898","pt":1719499159077,"mc":[{"id":"1.230180120","rc":[{"atb":[[6.2,0]],"id":64253834}],"con":true,"img":false}]}
{"op":"mcm","clk":"11540854907","pt":1719499159176,"mc":[{"id":"1.230180120","rc":[{"atb":[[5.6,0.05]],"id":64253834}],"con":true,"img":false}]}
{"op":"mcm","clk":"11540854914","pt":1719499159280,"mc":[{"id":"1.230180120","rc":[{"atb":[[6.8,1]],"id":64253834}],"con":true,"img":false}]}
{"op":"mcm","clk":"11540854924","pt":1719499159588,"mc":[{"id":"1.230180120","rc":[{"atl":[[3.9,0]],"id":69112387},{"atb":[[6.2,1.28],[6.6,0]],"id":64253834}],"con":true,"img":false}]}
{"op":"mcm","clk":"11540854927","pt":1719499159691,"mc":[{"id":"1.230180120","rc":[{"atl":[[3.8,1]],"id":69112387}],"con":true,"img":false}]}
{"op":"mcm","clk":"11540854937","pt":1719499160003,"mc":[{"id":"1.230180120","rc":[{"atl":[[3.95,4]],"id":69112387}],"con":true,"img":false}]}
{"op":"mcm","clk":"11540854950","pt":1719499160257,"mc":[{"id":"1.230180120","rc":[{"atl":[[3.85,0.84]],"id":69112387}],"con":true,"img":false}]}
{"op":"mcm","clk":"11540854957","pt":1719499160369,"mc":[{"id":"1.230180120","rc":[{"atl":[[3.9,1]],"id":69112387}],"con":true,"img":false}]}
{"op":"mcm","clk":"11540854996","pt":1719499160979,"mc":[{"id":"1.230180120","rc":[{"atl":[[3.9,0]],"id":69112387}],"con":true,"img":false}]}
{"op":"mcm","clk":"11540855008","pt":1719499161191,"mc":[{"id":"1.230180120","rc":[{"atl":[[3.9,1]],"id":69112387}],"con":true,"img":false}]}
{"op":"mcm","clk":"11540855029","pt":1719499161392,"mc":[{"id":"1.230180120","rc":[{"atl":[[3.9,0]],"id":69112387}],"con":true,"img":false}]}
{"op":"mcm","clk":"11540855036","pt":1719499161499,"mc":[{"id":"1.230180120","rc":[{"atl":[[3.8,0]],"id":69112387}],"con":true,"img":false}]}
{"op":"mcm","clk":"11540855045","pt":1719499161597,"mc":[{"id":"1.230180120","rc":[{"atl":[[3.9,2]],"id":69112387}],"con":true,"img":false}]}
{"op":"mcm","clk":"11540855053","pt":1719499161700,"mc":[{"id":"1.230180120","rc":[{"atl":[[3.95,0],[4.1,9]],"id":69112387}],"con":true,"img":false}]}
{"op":"mcm","clk":"11540855064","pt":1719499161808,"mc":[{"id":"1.230180120","rc":[{"atl":[[3.95,9],[4.1,1]],"id":69112387}],"con":true,"img":false}]}
{"op":"mcm","clk":"11540855179","pt":1719499163099,"mc":[{"id":"1.230180120","rc":[{"atb":[[6.4,0]],"id":64253834}],"con":true,"img":false}]}
{"op":"mcm","clk":"11540855192","pt":1719499163306,"mc":[{"id":"1.230180120","rc":[{"atb":[[1.12,1]],"id":64253834}],"con":true,"img":false}]}
{"op":"mcm","clk":"11540855211","pt":1719499163463,"mc":[{"id":"1.230180120","rc":[{"atb":[[1.12,0.17]],"id":64253834}],"con":true,"img":false}]}
{"op":"mcm","clk":"11540855223","pt":1719499163669,"mc":[{"id":"1.230180120","rc":[{"atb":[[1.12,0]],"id":64253834}],"con":true,"img":false}]}
{"op":"mcm","clk":"11540855231","pt":1719499163773,"mc":[{"id":"1.230180120","rc":[{"atb":[[7,0.17]],"id":64253834}],"con":true,"img":false}]}
{"op":"mcm","clk":"11540855335","pt":1719499164962,"mc":[{"id":"1.230180120","rc":[{"atb":[[30,2.36]],"id":64253834}],"con":true,"img":false}]}
{"op":"mcm","clk":"11540855344","pt":1719499165118,"mc":[{"id":"1.230180120","rc":[{"atb":[[30,0.7]],"id":64253834},{"trd":[[30,3.33]],"ltp":30.0,"tv":3.33,"id":64253834}],"con":true,"img":false}]}
{"op":"mcm","clk":"11540855359","pt":1719499165170,"mc":[{"id":"1.230180120","rc":[{"atb":[[6.8,0],[30,0.44]],"id":64253834},{"trd":[[30,3.85]],"ltp":30.0,"tv":3.85,"id":64253834}],"con":true,"img":false}]}
{"op":"mcm","clk":"11540855392","pt":1719499165598,"mc":[{"id":"1.230180120","rc":[{"atb":[[6.4,0.84]],"id":64253834}],"con":true,"img":false}]}
{"op":"mcm","clk":"11540855455","pt":1719499166529,"mc":[{"id":"1.230180120","rc":[{"atl":[[3.85,2.84]],"id":69112387}],"con":true,"img":false}]}
{"op":"mcm","clk":"11540855528","pt":1719499167602,"mc":[{"id":"1.230180120","rc":[{"atl":[[3.9,1]],"id":69112387}],"con":true,"img":false}]}
{"op":"mcm","clk":"11540855536","pt":1719499167698,"mc":[{"id":"1.230180120","rc":[{"atl":[[3.8,1]],"id":69112387}],"con":true,"img":false}]}
{"op":"mcm","clk":"11540855713","pt":1719499170289,"mc":[{"id":"1.230180120","rc":[{"atl":[[20,3.61]],"id":47370245}],"con":true,"img":false}]}
{"op":"mcm","clk":"11540855727","pt":1719499170497,"mc":[{"id":"1.230180120","rc":[{"atl":[[1000,0.23]],"id":47370245}],"con":true,"img":false}]}
{"op":"mcm","clk":"11540855742","pt":1719499170705,"mc":[{"id":"1.230180120","rc":[{"atl":[[1000,0.17]],"id":47370245}],"con":true,"img":false}]}
{"op":"mcm","clk":"11540855754","pt":1719499170804,"mc":[{"id":"1.230180120","rc":[{"atl":[[19,0.06]],"id":47370245}],"con":true,"img":false}]}
{"op":"mcm","clk":"11540855795","pt":1719499171295,"mc":[{"id":"1.230180120","rc":[{"atl":[[13.5,0.84]],"id":53432239},{"atl":[[29,0]],"id":47370245},{"atl":[[120,0.84]],"id":64253834}],"con":true,"img":false}]}
{"op":"mcm","clk":"11540855819","pt":1719499171607,"mc":[{"id":"1.230180120","rc":[{"atl":[[13,0.65]],"id":53432239}],"con":true,"img":false}]}
{"op":"mcm","clk":"11540855829","pt":1719499171715,"mc":[{"id":"1.230180120","rc":[{"atl":[[19,1]],"id":53432239},{"atl":[[3.85,0.84]],"id":69112387}],"con":true,"img":false}]}
{"op":"mcm","clk":"11540855894","pt":1719499172598,"mc":[{"id":"1.230180120","rc":[{"atl":[[3.8,0]],"id":69112387}],"con":true,"img":false}]}
{"op":"mcm","clk":"11540855899","pt":1719499172691,"mc":[{"id":"1.230180120","rc":[{"atl":[[3.9,2]],"id":69112387}],"con":true,"img":false}]}
{"op":"mcm","clk":"11540855999","pt":1719499173885,"mc":[{"id":"1.230180120","rc":[{"spn":11.55,"spf":"NaN","id":47370245},{"spn":3.76,"spf":1.0,"id":64536702},{"atl":[[3.85,2.84]],"id":69112387},{"spn":75.0,"spf":"NaN","id":64253834}],"con":true,"img":false}]}
{"op":"mcm","clk":"11540856093","pt":1719499175222,"mc":[{"id":"1.230180120","rc":[{"atb":[[4.4,8.71],[5.1,0]],"id":62847579},{"atb":[[3.85,6],[4.4,0]],"id":53432239},{"atl":[[16,5.41],[19.5,0]],"id":53432239},{"atb":[[2.98,6.81]],"id":64536702},{"atb":[[1.98,86.35],[2.08,0]],"id":69112387},{"atl":[[3.85,5.69],[3.95,0]],"id":69112387},{"atb":[[4.8,0],[4.2,2.1]],"id":64253834}],"con":true,"img":false}]}
{"op":"mcm","clk":"11540856102","pt":1719499175327,"mc":[{"id":"1.230180120","rc":[{"atb":[[3.25,0]],"id":64536702},{"atl":[[3.9,7.7]],"id":69112387}],"con":true,"img":false}]}
{"op":"mcm","clk":"11540856114","pt":1719499175382,"mc":[{"id":"1.230180120","rc":[{"atl":[[3.85,2.84]],"id":69112387}],"con":true,"img":false}]}
{"op":"mcm","clk":"11540856138","pt":1719499175683,"mc":[{"id":"1.230180120","rc":[{"atl":[[19,0]],"id":53432239},{"atl":[[3.9,6.7]],"id":69112387}],"con":true,"img":false}]}
{"op":"mcm","clk":"11540856146","pt":1719499175787,"mc":[{"id":"1.230180120","rc":[{"atl":[[15.5,1]],"id":53432239},{"atl":[[3.8,1]],"id":69112387}],"con":true,"img":false}]}
{"op":"mcm","clk":"11540856386","pt":1719499179086,"mc":[{"id":"1.230180120","rc":[{"atl":[[3.85,0.84]],"id":69112387},{"atb":[[7,0]],"id":64253834}],"con":true,"img":false}]}
{"op":"mcm","clk":"11540856423","pt":1719499179498,"mc":[{"id":"1.230180120","rc":[{"atb":[[1.12,1]],"id":64253834}],"con":true,"img":false}]}
{"op":"mcm","clk":"11540856433","pt":1719499179621,"mc":[{"id":"1.230180120","rc":[{"atl":[[3.8,0]],"id":69112387}],"con":true,"img":false}]}
{"op":"mcm","clk":"11540856440","pt":1719499179706,"mc":[{"id":"1.230180120","rc":[{"atl":[[3.85,1.84]],"id":69112387},{"atb":[[1.12,0.18]],"id":64253834}],"con":true,"img":false}]}
{"op":"mcm","clk":"11540856449","pt":1719499179813,"mc":[{"id":"1.230180120","rc":[{"atl":[[4.1,9],[3.9,1]],"id":69112387}],"con":true,"img":false}]}
{"op":"mcm","clk":"11540856459","pt":1719499179919,"mc":[{"id":"1.230180120","rc":[{"atl":[[3.85,3.84],[4.1,1]],"id":69112387},{"atb":[[1.12,0]],"id":64253834}],"con":true,"img":false}]}
{"op":"mcm","clk":"11540856463","pt":1719499180021,"mc":[{"id":"1.230180120","rc":[{"atl":[[3.85,1.84],[4.1,10]],"id":69112387},{"atb":[[6.6,0.18]],"id":64253834}],"con":true,"img":false}]}
{"op":"mcm","clk":"11540856505","pt":1719499180591,"mc":[{"id":"1.230180120","rc":[{"atl":[[3.85,0.84]],"id":69112387}],"con":true,"img":false}]}
{"op":"mcm","clk":"11540856511","pt":1719499180687,"mc":[{"id":"1.230180120","rc":[{"atl":[[4,1]],"id":69112387}],"con":true,"img":false}]}
{"op":"mcm","clk":"11540856598","pt":1719499181980,"mc":[{"id":"1.230180120","rc":[{"atl":[[3.85,2.84]],"id":69112387}],"con":true,"img":false}]}
{"op":"mcm","clk":"11540856875","pt":1719499185635,"mc":[{"id":"1.230180120","rc":[{"atl":[[4,0]],"id":69112387}],"con":true,"img":false}]}
{"op":"mcm","clk":"11540856887","pt":1719499185733,"mc":[{"id":"1.230180120","rc":[{"atl":[[3.8,1]],"id":69112387}],"con":true,"img":false}]}
{"op":"mcm","clk":"11540856904","pt":1719499185990,"mc":[{"id":"1.230180120","rc":[{"atl":[[19,0]],"id":47370245}],"con":true,"img":false}]}
{"op":"mcm","clk":"11540856959","pt":1719499186715,"mc":[{"id":"1.230180120","rc":[{"atl":[[1000,0.23]],"id":47370245},{"atl":[[3.85,5.69],[4.1,1]],"id":69112387}],"con":true,"img":false}]}
{"op":"mcm","clk":"11540856969","pt":1719499186833,"mc":[{"id":"1.230180120","rc":[{"atl":[[1000,0.17]],"id":47370245}],"con":true,"img":false}]}
{"op":"mcm","clk":"11540856977","pt":1719499186920,"mc":[{"id":"1.230180120","rc":[{"atl":[[19,0.06]],"id":47370245}],"con":true,"img":false}]}
{"op":"mcm","clk":"11540857000","pt":1719499187286,"mc":[{"id":"1.230180120","rc":[{"atl":[[3.85,3.69]],"id":69112387}],"con":true,"img":false}]}
{"op":"mcm","clk":"11540857136","pt":1719499189102,"mc":[{"id":"1.230180120","rc":[{"atb":[[2.38,6.54]],"id":69112387},{"atl":[[3.75,2]],"id":69112387}],"con":true,"img":false}]}
{"op":"mcm","clk":"11540857151","pt":1719499189309,"mc":[{"id":"1.230180120","rc":[{"atb":[[2.32,0]],"id":64253834}],"con":true,"img":false}]}
{"op":"mcm","clk":"11540857168","pt":1719499189621,"mc":[{"id":"1.230180120","rc":[{"atl":[[3.85,2.85],[3.8,0],[3.7,0.84]],"id":69112387}],"con":true,"img":false}]}
{"op":"mcm","clk":"11540857179","pt":1719499189724,"mc":[{"id":"1.230180120","rc":[{"atl":[[3.7,1.84]],"id":69112387}],"con":true,"img":false}]}
{"op":"mcm","clk":"11540857197","pt":1719499189930,"mc":[{"id":"1.230180120","rc":[{"atl":[[3.9,0]],"id":69112387}],"con":true,"img":false}]}
{"op":"mcm","clk":"11540857205","pt":1719499190042,"mc":[{"id":"1.230180120","rc":[{"atl":[[3.65,1]],"id":69112387}],"con":true,"img":false}]}
{"op":"mcm","clk":"11540857239","pt":1719499190395,"mc":[{"id":"1.230180120","rc":[{"atl":[[3.75,0]],"id":69112387}],"con":true,"img":false}]}
{"op":"mcm","clk":"11540857329","pt":1719499192170,"mc":[{"id":"1.230180120","rc":[{"atl":[[3.7,0.84]],"id":69112387}],"con":true,"img":false}]}
{"op":"mcm","clk":"11540857342","pt":1719499192250,"mc":[{"id":"1.230180120","rc":[{"atl":[[3.8,1]],"id":69112387}],"con":true,"img":false}]}
{"op":"mcm","clk":"11540857402","pt":1719499192761,"mc":[{"id":"1.230180120","rc":[{"atl":[[3.7,0]],"id":69112387}],"con":true,"img":false}]}
{"op":"mcm","clk":"11540857431","pt":1719499193042,"mc":[{"id":"1.230180120","rc":[{"atb":[[2.34,10.42]],"id":53432239}],"con":true,"img":false}]}
{"op":"mcm","clk":"11540857489","pt":1719499193618,"mc":[{"id":"1.230180120","rc":[{"atb":[[2.4,9.97]],"id":47370245}],"con":true,"img":false}]}
{"op":"mcm","clk":"11540857505","pt":1719499193825,"mc":[{"id":"1.230180120","rc":[{"atb":[[2.38,10.12]],"id":62847579}],"con":true,"img":false}]}
{"op":"mcm","clk":"11540857552","pt":1719499194204,"mc":[{"id":"1.230180120","rc":[{"atb":[[5.6,2.88]],"id":53432239},{"atb":[[3.6,7.86]],"id":47370245},{"atb":[[3.7,1.78]],"id":64536702},{"atb":[[2.38,7.33]],"id":69112387}],"con":true,"img":false}]}
{"op":"mcm","clk":"11540857582","pt":1719499194621,"mc":[{"id":"1.230180120","rc":[{"atb":[[5.7,0.84]],"id":53432239}],"con":true,"img":false}]}
{"op":"mcm","clk":"11540857642","pt":1719499195199,"mc":[{"id":"1.230180120","rc":[{"atb":[[6.6,0]],"id":64253834}],"con":true,"img":false}]}
{"op":"mcm","clk":"11540857676","pt":1719499195513,"mc":[{"id":"1.230180120","rc":[{"atb":[[1.12,1]],"id":64253834}],"con":true,"img":false}]}
{"op":"mcm","clk":"11540857698","pt":1719499195723,"mc":[{"id":"1.230180120","rc":[{"atb":[[1.12,0.18]],"id":64253834}],"con":true,"img":false}]}
{"op":"mcm","clk":"11540857712","pt":1719499195932,"mc":[{"id":"1.230180120","rc":[{"atb":[[1.12,0]],"id":64253834}],"con":true,"img":false}]}
{"op":"mcm","clk":"11540857723","pt":1719499196037,"mc":[{"id":"1.230180120","rc":[{"atb":[[6.6,0.18]],"id":64253834}],"con":true,"img":false}]}
{"op":"mcm","clk":"11540857768","pt":1719499196506,"mc":[{"id":"1.230180120","rc":[{"atl":[[3.6,2]],"id":69112387}],"con":true,"img":false}]}
{"op":"mcm","clk":"11540857789","pt":1719499196714,"mc":[{"id":"1.230180120","rc":[{"atl":[[3.6,4],[3.85,0]],"id":69112387}],"con":true,"img":false}]}
{"op":"mcm","clk":"11540857800","pt":1719499196922,"mc":[{"id":"1.230180120","rc":[{"atl":[[3.65,0]],"id":69112387}],"con":true,"img":false}]}
{"op":"mcm","clk":"11540857816","pt":1719499197128,"mc":[{"id":"1.230180120","rc":[{"atl":[[3.55,0.84]],"id":69112387}],"con":true,"img":false}]}
{"op":"mcm","clk":"11540857824","pt":1719499197235,"mc":[{"id":"1.230180120","rc":[{"atl":[[3.8,0],[3.55,1.84]],"id":69112387}],"con":true,"img":false}]}
{"op":"mcm","clk":"11540857836","pt":1719499197341,"mc":[{"id":"1.230180120","rc":[{"atl":[[3.55,2.84]],"id":69112387}],"con":true,"img":false}]}
{"op":"mcm","clk":"11540857868","pt":1719499197805,"mc":[{"id":"1.230180120","rc":[{"atl":[[3.6,2]],"id":69112387}],"con":true,"img":false}]}
{"op":"mcm","clk":"11540858162","pt":1719499202033,"mc":[{"id":"1.230180120","rc":[{"atl":[[19,0]],"id":47370245}],"con":true,"img":false}]}
{"op":"mcm","clk":"11540858169","pt":1719499202139,"mc":[{"id":"1.230180120","rc":[{"atb":[[5.7,5.61]],"id":53432239},{"atl":[[15.5,2.72]],"id":53432239},{"atb":[[3.75,9.36]],"id":64536702},{"atl":[[26,1.91]],"id":64536702},{"atb":[[2.58,17.27]],"id":69112387},{"atb":[[6.4,5.19],[30,0]],"id":64253834},{"trd":[[30,4.74]],"ltp":30.0,"tv":4.74,"id":64253834}],"con":true,"img":false}]}
{"op":"mcm","clk":"11540858174","pt":1719499202242,"mc":[{"id":"1.230180120","rc":[{"atb":[[3.3,0]],"id":64536702}],"con":true,"img":false}]}
{"op":"mcm","clk":"11540858180","pt":1719499202347,"mc":[{"id":"1.230180120","rc":[{"atl":[[1000,0.23]],"id":47370245}],"con":true,"img":false}]}
{"op":"mcm","clk":"11540858193","pt":1719499202458,"mc":[{"id":"1.230180120","rc":[{"atb":[[5.8,1.45]],"id":53432239},{"atb":[[3.8,1]],"id":64536702}],"con":true,"img":false}]}
{"op":"mcm","clk":"11540858206","pt":1719499202521,"mc":[{"id":"1.230180120","rc":[{"atl":[[1000,0.17]],"id":47370245}],"con":true,"img":false}]}
{"op":"mcm","clk":"11540858214","pt":1719499202609,"mc":[{"id":"1.230180120","rc":[{"atb":[[5.6,1.36]],"id":53432239},{"atl":[[19,0.06]],"id":47370245},{"atb":[[2.6,0.84]],"id":69112387}],"con":true,"img":false}]}
{"op":"mcm","clk":"11540858313","pt":1719499203813,"mc":[{"id":"1.230180120","rc":[{"atl":[[3.5,2]],"id":69112387}],"con":true,"img":false}]}
{"op":"mcm","clk":"11540858326","pt":1719499204023,"mc":[{"id":"1.230180120","rc":[{"atl":[[3.55,1.84]],"id":69112387}],"con":true,"img":false}]}
{"op":"mcm","clk":"11540858333","pt":1719499204128,"mc":[{"id":"1.230180120","rc":[{"atl":[[3.45,0.84]],"id":69112387}],"con":true,"img":false}]}
{"op":"mcm","clk":"11540858340","pt":1719499204230,"mc":[{"id":"1.230180120","rc":[{"atl":[[3.45,1.84]],"id":69112387}],"con":true,"img":false}]}
{"op":"mcm","clk":"11540858364","pt":1719499204646,"mc":[{"id":"1.230180120","rc":[{"atl":[[3.55,1]],"id":69112387}],"con":true,"img":false}]}
{"op":"mcm","clk":"11540858401","pt":1719499205012,"mc":[{"id":"1.230180120","rc":[{"atl":[[3.5,0]],"id":69112387}],"con":true,"img":false}]}
{"op":"mcm","clk":"11540858494","pt":1719499206643,"mc":[{"id":"1.230180120","rc":[{"atb":[[2.38,4.17]],"id":69112387},{"atl":[[3.55,0]],"id":69112387}],"con":true,"img":false}]}
{"op":"mcm","clk":"11540858503","pt":1719499206743,"mc":[{"id":"1.230180120","rc":[{"atl":[[3.4,1]],"id":69112387}],"con":true,"img":false}]}
{"op":"mcm","clk":"11540858523","pt":1719499206946,"mc":[{"id":"1.230180120","rc":[{"atb":[[2.6,4]],"id":69112387}],"con":true,"img":false}]}
{"op":"mcm","clk":"11540858585","pt":1719499207673,"mc":[{"id":"1.230180120","rc":[{"atb":[[4.1,0]],"id":47370245},{"atb":[[2.58,17.16]],"id":69112387}],"con":true,"img":false}]}
{"op":"mcm","clk":"11540858596","pt":1719499207730,"mc":[{"id":"1.230180120","rc":[{"atb":[[2.6,19.05]],"id":69112387}],"con":true,"img":false}]}
{"op":"mcm","clk":"11540858615","pt":1719499207946,"mc":[{"id":"1.230180120","rc":[{"atb":[[1.09,1.69]],"id":47370245},{"atb":[[2.62,6.34],[1.06,1.69]],"id":69112387}],"con":true,"img":false}]}
{"op":"mcm","clk":"11540858634","pt":1719499208156,"mc":[{"id":"1.230180120","rc":[{"atb":[[5.2,0]],"id":53432239}],"con":true,"img":false}]}
{"op":"mcm","clk":"11540858642","pt":1719499208256,"mc":[{"id":"1.230180120","rc":[{"atb":[[1.06,0.11]],"id":69112387}],"con":true,"img":false}]}
{"op":"mcm","clk":"11540858657","pt":1719499208448,"mc":[{"id":"1.230180120","rc":[{"atb":[[1.09,0.07]],"id":47370245}],"con":true,"img":false}]}
{"op":"mcm","clk":"11540858671","pt":1719499208553,"mc":[{"id":"1.230180120","rc":[{"atb":[[1.14,1.69]],"id":53432239}],"con":true,"img":false}]}
{"op":"mcm","clk":"11540858684","pt":1719499208721,"mc":[{"id":"1.230180120","rc":[{"atb":[[2.62,22.22]],"id":69112387}],"con":true,"img":false}]}
{"op":"mcm","clk":"11540858697","pt":1719499208932,"mc":[{"id":"1.230180120","rc":[{"atb":[[1.06,0]],"id":69112387}],"con":true,"img":false}]}
{"op":"mcm","clk":"11540858706","pt":1719499209033,"mc":[{"id":"1.230180120","rc":[{"atb":[[2.62,22.34]],"id":69112387}],"con":true,"img":false}]}
{"op":"mcm","clk":"11540858733","pt":1719499209352,"mc":[{"id":"1.230180120","rc":[{"atb":[[1.09,0]],"id":47370245}],"con":true,"img":false}]}
{"op":"mcm","clk":"11540858742","pt":1719499209450,"mc":[{"id":"1.230180120","rc":[{"atb":[[4.1,0.07]],"id":47370245}],"con":true,"img":false}]}
{"op":"mcm","clk":"11540858753","pt":1719499209656,"mc":[{"id":"1.230180120","rc":[{"atb":[[2.7,2.09]],"id":69112387}],"con":true,"img":false}]}
{"op":"mcm","clk":"11540858757","pt":1719499209763,"mc":[{"id":"1.230180120","rc":[{"atb":[[1.14,0.05]],"id":53432239},{"atb":[[4.8,0]],"id":64536702},{"atb":[[2.64,0.84]],"id":69112387}],"con":true,"img":false}]}
{"op":"mcm","clk":"11540858767","pt":1719499209961,"mc":[{"id":"1.230180120","rc":[{"atb":[[2.62,15.99]],"id":69112387}],"con":true,"img":false}]}
{"op":"mcm","clk":"11540858780","pt":1719499210126,"mc":[{"id":"1.230180120","rc":[{"atb":[[5.3,0]],"id":62847579},{"atb":[[2.64,1.41],[2.6,18.2]],"id":69112387},{"atb":[[5.6,0]],"id":64253834}],"con":true,"img":false}]}
{"op":"mcm","clk":"11540858788","pt":1719499210220,"mc":[{"id":"1.230180120","rc":[{"atb":[[2.7,17.26]],"id":69112387}],"con":true,"img":false}]}
{"op":"mcm","clk":"11540858807","pt":1719499210634,"mc":[{"id":"1.230180120","rc":[{"atb":[[1.14,0]],"id":53432239}],"con":true,"img":false}]}
{"op":"mcm","clk":"11540858816","pt":1719499210756,"mc":[{"id":"1.230180120","rc":[{"atb":[[5.9,0.05]],"id":53432239}],"con":true,"img":false}]}
{"op":"mcm","clk":"11540858834","pt":1719499210968,"mc":[{"id":"1.230180120","rc":[{"atb":[[1.16,151.69]],"id":62847579},{"atb":[[1.1,1.69]],"id":64536702}],"con":true,"img":false}]}
{"op":"mcm","clk":"11540858856","pt":1719499211219,"mc":[{"id":"1.230180120","rc":[{"atb":[[1.16,150.04]],"id":62847579},{"atl":[[3.35,2]],"id":69112387},{"atb":[[1.16,151.69],[6.6,0]],"id":64253834}],"con":true,"img":false}]}
{"op":"mcm","clk":"11540858876","pt":1719499211533,"mc":[{"id":"1.230180120","rc":[{"atb":[[1.1,0.06]],"id":64536702}],"con":true,"img":false}]}
{"op":"mcm","clk":"11540858884","pt":1719499211636,"mc":[{"id":"1.230180120","rc":[{"atl":[[3.3,0.84],[3.4,0]],"id":69112387}],"con":true,"img":false}]}
{"op":"mcm","clk":"11540858891","pt":1719499211741,"mc":[{"id":"1.230180120","rc":[{"atl":[[3.45,1],[3.3,1.84]],"id":69112387},{"atb":[[1.16,150.04]],"id":64253834}],"con":true,"img":false}]}
{"op":"mcm","clk":"11540858902","pt":1719499212044,"mc":[{"id":"1.230180120","rc":[{"atb":[[1.16,150]],"id":62847579},{"atb":[[1.12,1]],"id":64253834}],"con":true,"img":false}]}
{"op":"mcm","clk":"11540858913","pt":1719499212156,"mc":[{"id":"1.230180120","rc":[{"atb":[[7.8,0.04]],"id":62847579}],"con":true,"img":false}]}
{"op":"mcm","clk":"11540858919","pt":1719499212260,"mc":[{"id":"1.230180120","rc":[{"atb":[[1.12,0.18]],"id":64253834}],"con":true,"img":false}]}
{"op":"mcm","clk":"11540858933","pt":1719499212479,"mc":[{"id":"1.230180120","rc":[{"atb":[[1.1,0]],"id":64536702},{"atl":[[3.35,0]],"id":69112387},{"atb":[[1.12,0]],"id":64253834}],"con":true,"img":false}]}
{"op":"mcm","clk":"11540858942","pt":1719499212526,"mc":[{"id":"1.230180120","rc":[{"atb":[[4.8,0.06]],"id":64536702},{"atb":[[6.6,0.18]],"id":64253834}],"con":true,"img":false}]}
{"op":"mcm","clk":"11540858959","pt":1719499212826,"mc":[{"id":"1.230180120","rc":[{"atb":[[1.16,150]],"id":64253834}],"con":true,"img":false}]}
{"op":"mcm","clk":"11540858970","pt":1719499212948,"mc":[{"id":"1.230180120","rc":[{"atb":[[6.6,0.22]],"id":64253834}],"con":true,"img":false}]}
{"op":"mcm","clk":"11540858978","pt":1719499213050,"mc":[{"id":"1.230180120","rc":[{"atb":[[5.6,0]],"id":53432239}],"con":true,"img":false}]}
{"op":"mcm","clk":"11540859045","pt":1719499214050,"mc":[{"id":"1.230180120","rc":[{"atb":[[2.56,0]],"id":69112387}],"con":true,"img":false}]}
{"op":"mcm","clk":"11540859248","pt":1719499217166,"mc":[{"id":"1.230180120","rc":[{"atb":[[2.72,0.84]],"id":69112387}],"con":true,"img":false}]}
{"op":"mcm","clk":"11540859272","pt":1719499217633,"mc":[{"id":"1.230180120","rc":[{"atl":[[3.3,0.84]],"id":69112387}],"con":true,"img":false}]}
{"op":"mcm","clk":"11540859279","pt":1719499217729,"mc":[{"id":"1.230180120","rc":[{"atl":[[3.55,1]],"id":69112387}],"con":true,"img":false}]}
{"op":"mcm","clk":"11540859290","pt":1719499217867,"mc":[{"id":"1.230180120","rc":[{"atl":[[19,0]],"id":47370245}],"con":true,"img":false}]}
{"op":"mcm","clk":"11540859310","pt":1719499218157,"mc":[{"id":"1.230180120","rc":[{"atl":[[3.3,0]],"id":69112387}],"con":true,"img":false}]}
{"op":"mcm","clk":"11540859353","pt":1719499218782,"mc":[{"id":"1.230180120","rc":[{"atl":[[3.4,2]],"id":69112387}],"con":true,"img":false}]}
{"op":"mcm","clk":"11540859361","pt":1719499218834,"mc":[{"id":"1.230180120","rc":[{"atb":[[2.74,0]],"id":64536702}],"con":true,"img":false}]}
{"op":"mcm","clk":"11540859367","pt":1719499218937,"mc":[{"id":"1.230180120","rc":[{"atb":[[5.8,0]],"id":53432239}],"con":true,"img":false}]}
{"op":"mcm","clk":"11540859372","pt":1719499219033,"mc":[{"id":"1.230180120","rc":[{"atb":[[6,1.41]],"id":53432239}],"con":true,"img":false}]}
{"op":"mcm","clk":"11540859381","pt":1719499219146,"mc":[{"id":"1.230180120","rc":[{"atl":[[3.35,0.84],[3.55,0]],"id":69112387}],"con":true,"img":false}]}
{"op":"mcm","clk":"11540859389","pt":1719499219248,"mc":[{"id":"1.230180120","rc":[{"atl":[[1000,0.23]],"id":47370245},{"atl":[[3.35,1.84]],"id":69112387}],"con":true,"img":false}]}
{"op":"mcm","clk":"11540859420","pt":1719499219559,"mc":[{"id":"1.230180120","rc":[{"atb":[[6,0]],"id":53432239},{"atl":[[1000,0.17]],"id":47370245}],"con":true,"img":false}]}
{"op":"mcm","clk":"11540859430","pt":1719499219666,"mc":[{"id":"1.230180120","rc":[{"atl":[[19,0.06]],"id":47370245}],"con":true,"img":false}]}
{"op":"mcm","clk":"11540859440","pt":1719499219872,"mc":[{"id":"1.230180120","rc":[{"atb":[[5.8,1.41]],"id":53432239}],"con":true,"img":false}]}
{"op":"mcm","clk":"11540859452","pt":1719499220066,"mc":[{"id":"1.230180120","rc":[{"atl":[[3.4,0]],"id":69112387}],"con":true,"img":false}]}
{"op":"mcm","clk":"11540859537","pt":1719499221169,"mc":[{"id":"1.230180120","rc":[{"atl":[[3.35,0.84]],"id":69112387}],"con":true,"img":false}]}
{"op":"mcm","clk":"11540859547","pt":1719499221276,"mc":[{"id":"1.230180120","rc":[{"atl":[[3.55,1]],"id":69112387}],"con":true,"img":false}]}
{"op":"mcm","clk":"11540859579","pt":1719499221675,"mc":[{"id":"1.230180120","rc":[{"atl":[[3.35,0]],"id":69112387}],"con":true,"img":false}]}
{"op":"mcm","clk":"11540859778","pt":1719499224470,"mc":[{"id":"1.230180120","rc":[{"atb":[[2.16,5.44]],"id":47370245},{"atb":[[2.6,15.05]],"id":69112387}],"con":true,"img":false}]}
{"op":"mcm","clk":"11540859792","pt":1719499224677,"mc":[{"id":"1.230180120","rc":[{"atb":[[3,5.92]],"id":64536702}],"con":true,"img":false}]}
{"op":"mcm","clk":"11540859809","pt":1719499224882,"mc":[{"id":"1.230180120","rc":[{"atb":[[2.16,5.44]],"id":62847579},{"atb":[[2.02,19.88]],"id":69112387}],"con":true,"img":false}]}
{"op":"mcm","clk":"11540859829","pt":1719499225082,"mc":[{"id":"1.230180120","rc":[{"atb":[[2.16,5.44]],"id":53432239}],"con":true,"img":false}]}
{"op":"mcm","clk":"11540859848","pt":1719499225246,"mc":[{"id":"1.230180120","rc":[{"atb":[[2.16,5.44]],"id":64253834}],"con":true,"img":false}]}
{"op":"mcm","clk":"11540859887","pt":1719499225770,"mc":[{"id":"1.230180120","rc":[{"atb":[[4.4,0],[5.1,6]],"id":62847579},{"atb":[[3.85,0],[4.4,6]],"id":53432239},{"atl":[[16,0],[19.5,5.41]],"id":53432239},{"atl":[[11,1]],"id":47370245},{"atb":[[2.98,0],[3.25,6]],"id":64536702},{"atb":[[1.98,0],[2.08,24.42]],"id":69112387},{"atl":[[3.6,0],[3.95,8]],"id":69112387},{"atb":[[4.8,2]],"id":64253834}],"con":true,"img":false}]}
{"op":"mcm","clk":"11540859895","pt":1719499225876,"mc":[{"id":"1.230180120","rc":[{"atb":[[3.7,1]],"id":64536702},{"atb":[[2.38,3.38]],"id":69112387},{"atb":[[4.2,0]],"id":64253834}],"con":true,"img":false}]}
{"op":"mcm","clk":"11540859940","pt":1719499226286,"mc":[{"id":"1.230180120","rc":[{"atl":[[3.4,2]],"id":69112387}],"con":true,"img":false}]}
{"op":"mcm","clk":"11540859966","pt":1719499226659,"mc":[{"id":"1.230180120","rc":[{"atl":[[3.35,0.84]],"id":69112387}],"con":true,"img":false}]}
{"op":"mcm","clk":"11540860073","pt":1719499227904,"mc":[{"id":"1.230180120","rc":[{"atl":[[15.5,1.72]],"id":53432239},{"atl":[[3.55,0]],"id":69112387},{"atb":[[6.6,0.04]],"id":64253834}],"con":true,"img":false}]}
{"op":"mcm","clk":"11540860080","pt":1719499227971,"mc":[{"id":"1.230180120","rc":[{"atl":[[19,1]],"id":53432239},{"atl":[[3.35,1.84]],"id":69112387}],"con":true,"img":false}]}
{"op":"mcm","clk":"11540860102","pt":1719499228282,"mc":[{"id":"1.230180120","rc":[{"atb":[[1.12,1]],"id":64253834}],"con":true,"img":false}]}
{"op":"mcm","clk":"11540860115","pt":1719499228485,"mc":[{"id":"1.230180120","rc":[{"atb":[[1.12,0.18]],"id":64253834}],"con":true,"img":false}]}
{"op":"mcm","clk":"11540860121","pt":1719499228584,"mc":[{"id":"1.230180120","rc":[{"atl":[[19,0]],"id":53432239}],"con":true,"img":false}]}
{"op":"mcm","clk":"11540860133","pt":1719499228646,"mc":[{"id":"1.230180120","rc":[{"atl":[[15,1]],"id":53432239},{"atb":[[1.12,0]],"id":64253834}],"con":true,"img":false}]}
{"op":"mcm","clk":"11540860139","pt":1719499228757,"mc":[{"id":"1.230180120","rc":[{"atl":[[3.4,0]],"id":69112387},{"atb":[[6.6,0.22]],"id":64253834}],"con":true,"img":false}]}
{"op":"mcm","clk":"11540860214","pt":1719499229680,"mc":[{"id":"1.230180120","rc":[{"atl":[[3.35,0.84]],"id":69112387}],"con":true,"img":false}]}
{"op":"mcm","clk":"11540860224","pt":1719499229783,"mc":[{"id":"1.230180120","rc":[{"atl":[[3.9,1]],"id":69112387}],"con":true,"img":false}]}
{"op":"mcm","clk":"11540860266","pt":1719499230264,"mc":[{"id":"1.230180120","rc":[{"atl":[[3.35,0]],"id":69112387}],"con":true,"img":false}]}
{"op":"mcm","clk":"11540860311","pt":1719499230691,"mc":[{"id":"1.230180120","rc":[{"atb":[[2.66,3.01]],"id":69112387}],"con":true,"img":false}]}
{"op":"mcm","clk":"11540860381","pt":1719499231590,"mc":[{"id":"1.230180120","rc":[{"atb":[[2.72,2.25],[2.64,0]],"id":69112387}],"con":true,"img":false}]}
{"op":"mcm","clk":"11540860398","pt":1719499231781,"mc":[{"id":"1.230180120","rc":[{"atb":[[2.58,0]],"id":69112387}],"con":true,"img":false}]}
{"op":"mcm","clk":"11540860412","pt":1719499231954,"mc":[{"id":"1.230180120","rc":[{"atb":[[2.72,15.66]],"id":69112387}],"con":true,"img":false}]}
{"op":"mcm","clk":"11540860432","pt":1719499232255,"mc":[{"id":"1.230180120","rc":[{"atb":[[2.74,6.34]],"id":69112387}],"con":true,"img":false}]}
{"op":"mcm","clk":"11540860462","pt":1719499232676,"mc":[{"id":"1.230180120","rc":[{"atb":[[2.8,2.09],[2.76,0.84],[2.7,15.17]],"id":69112387}],"con":true,"img":false}]}
{"op":"mcm","clk":"11540860471","pt":1719499232777,"mc":[{"id":"1.230180120","rc":[{"atb":[[2.6,0]],"id":69112387}],"con":true,"img":false}]}
{"op":"mcm","clk":"11540860478","pt":1719499232889,"mc":[{"id":"1.230180120","rc":[{"atb":[[2.74,13.59]],"id":69112387}],"con":true,"img":false}]}
{"op":"mcm","clk":"11540860505","pt":1719499233163,"mc":[{"id":"1.230180120","rc":[{"atb":[[2.72,14.82],[2.76,0]],"id":69112387}],"con":true,"img":false}]}
{"op":"mcm","clk":"11540860546","pt":1719499233742,"mc":[{"id":"1.230180120","rc":[{"atl":[[3.4,2]],"id":69112387}],"con":true,"img":false}]}
{"op":"mcm","clk":"11540860574","pt":1719499234162,"mc":[{"id":"1.230180120","rc":[{"spn":68.9,"spf":"NaN","id":62847579},{"spn":9.45,"spf":"NaN","id":53432239},{"spn":7.55,"spf":"NaN","id":47370245},{"spn":4.01,"spf":1.0,"id":64536702},{"atl":[[3.35,0.84]],"id":69112387},{"spn":2.8,"spf":1.0,"id":69112387},{"spn":63.3,"spf":"NaN","id":64253834}],"con":true,"img":false}]}
{"op":"mcm","clk":"11540860626","pt":1719499234783,"mc":[{"id":"1.230180120","rc":[{"atl":[[3.9,0]],"id":69112387}],"con":true,"img":false}]}
{"op":"mcm","clk":"11540860633","pt":1719499234844,"mc":[{"id":"1.230180120","rc":[{"atl":[[19,0]],"id":47370245},{"atl":[[3.35,1.84]],"id":69112387}],"con":true,"img":false}]}
{"op":"mcm","clk":"11540860651","pt":1719499235052,"mc":[{"id":"1.230180120","rc":[{"atl":[[1000,0.28]],"id":47370245}],"con":true,"img":false}]}
{"op":"mcm","clk":"11540860665","pt":1719499235259,"mc":[{"id":"1.230180120","rc":[{"atl":[[1000,0.17]],"id":47370245}],"con":true,"img":false}]}
{"op":"mcm","clk":"11540860673","pt":1719499235362,"mc":[{"id":"1.230180120","rc":[{"atl":[[10.5,0.11]],"id":47370245}],"con":true,"img":false}]}
{"op":"mcm","clk":"11540860683","pt":1719499235474,"mc":[{"id":"1.230180120","rc":[{"atb":[[2.38,0]],"id":69112387},{"atl":[[3.4,0]],"id":69112387}],"con":true,"img":false}]}
{"op":"mcm","clk":"11540860717","pt":1719499235885,"mc":[{"id":"1.230180120","rc":[{"atl":[[3.35,0.84]],"id":69112387}],"con":true,"img":false}]}
{"op":"mcm","clk":"11540860727","pt":1719499235938,"mc":[{"id":"1.230180120","rc":[{"atl":[[3.9,1]],"id":69112387}],"con":true,"img":false}]}
{"op":"mcm","clk":"11540860745","pt":1719499236149,"mc":[{"id":"1.230180120","rc":[{"atl":[[3.35,0]],"id":69112387}],"con":true,"img":false}]}
{"op":"mcm","clk":"11540860802","pt":1719499236982,"mc":[{"id":"1.230180120","rc":[{"atb":[[2.36,0]],"id":62847579},{"atb":[[2.32,0]],"id":53432239},{"atb":[[2.38,0]],"id":47370245}],"con":true,"img":false}]}
{"op":"mcm","clk":"11540861067","pt":1719499240085,"mc":[{"id":"1.230180120","rc":[{"atb":[[2.82,0.84]],"id":69112387}],"con":true,"img":false}]}
{"op":"mcm","clk":"11540861084","pt":1719499240246,"mc":[{"id":"1.230180120","rc":[{"atb":[[5.2,3.88]],"id":62847579},{"atb":[[3.8,2.97]],"id":64536702}],"con":true,"img":false}]}
{"op":"mcm","clk":"11540861151","pt":1719499241191,"mc":[{"id":"1.230180120","rc":[{"atb":[[2.62,0.11]],"id":69112387},{"atl":[[3.4,2]],"id":69112387}],"con":true,"img":false}]}
{"op":"mcm","clk":"11540861166","pt":1719499241349,"mc":[{"id":"1.230180120","rc":[{"atb":[[3.85,9.49]],"id":64536702},{"atb":[[2.82,13.22]],"id":69112387}],"con":true,"img":false}]}
{"op":"mcm","clk":"11540861191","pt":1719499241659,"mc":[{"id":"1.230180120","rc":[{"atl":[[3.35,0.84]],"id":69112387}],"con":true,"img":false}]}
{"op":"mcm","clk":"11540861213","pt":1719499241972,"mc":[{"id":"1.230180120","rc":[{"atl":[[3.9,0]],"id":69112387}],"con":true,"img":false}]}
{"op":"mcm","clk":"11540861217","pt":1719499242076,"mc":[{"id":"1.230180120","rc":[{"atl":[[3.35,1.84]],"id":69112387}],"con":true,"img":false}]}
{"op":"mcm","clk":"11540861289","pt":1719499242964,"mc":[{"id":"1.230180120","rc":[{"atb":[[2.72,13.41],[2.84,1.41]],"id":69112387}],"con":true,"img":false}]}
{"op":"mcm","clk":"11540861306","pt":1719499243174,"mc":[{"id":"1.230180120","rc":[{"atb":[[2.7,0]],"id":69112387}],"con":true,"img":false}]}
{"op":"mcm","clk":"11540861319","pt":1719499243281,"mc":[{"id":"1.230180120","rc":[{"atb":[[2.8,0],[2.84,14.36],[2.9,2.09]],"id":69112387}],"con":true,"img":false}]}
{"op":"mcm","clk":"11540861351","pt":1719499243649,"mc":[{"id":"1.230180120","rc":[{"atb":[[2.82,12.38]],"id":69112387}],"con":true,"img":false}]}
{"op":"mcm","clk":"11540861377","pt":1719499243966,"mc":[{"id":"1.230180120","rc":[{"atb":[[6.6,0.04]],"id":64253834}],"con":true,"img":false}]}
{"op":"mcm","clk":"11540861387","pt":1719499244069,"mc":[{"id":"1.230180120","rc":[{"atb":[[2.72,0]],"id":69112387}],"con":true,"img":false}]}
{"op":"mcm","clk":"11540861399","pt":1719499244178,"mc":[{"id":"1.230180120","rc":[{"atb":[[2.9,13.76]],"id":69112387}],"con":true,"img":false}]}
{"op":"mcm","clk":"11540861411","pt":1719499244276,"mc":[{"id":"1.230180120","rc":[{"atb":[[3.6,4.55]],"id":53432239}],"con":true,"img":false}]}
{"op":"mcm","clk":"11540861418","pt":1719499244386,"mc":[{"id":"1.230180120","rc":[{"atb":[[2.42,10.43]],"id":47370245}],"con":true,"img":false}]}
{"op":"mcm","clk":"11540861430","pt":1719499244591,"mc":[{"id":"1.230180120","rc":[{"atb":[[2.4,10.55]],"id":62847579}],"con":true,"img":false}]}
{"op":"mcm","clk":"11540861448","pt":1719499244857,"mc":[{"id":"1.230180120","rc":[{"atb":[[1.12,1]],"id":64253834}],"con":true,"img":false}]}
{"op":"mcm","clk":"11540861463","pt":1719499245065,"mc":[{"id":"1.230180120","rc":[{"atb":[[1.12,0.18]],"id":64253834}],"con":true,"img":false}]}
{"op":"mcm","clk":"11540861468","pt":1719499245170,"mc":[{"id":"1.230180120","rc":[{"atb":[[1.12,0]],"id":64253834}],"con":true,"img":false}]}
{"op":"mcm","clk":"11540861475","pt":1719499245272,"mc":[{"id":"1.230180120","rc":[{"atb":[[6.6,0.22]],"id":64253834}],"con":true,"img":false}]}
{"op":"mcm","clk":"11540861561","pt":1719499246481,"mc":[{"id":"1.230180120","rc":[{"atl":[[3.4,0]],"id":69112387}],"con":true,"img":false}]}
{"op":"mcm","clk":"11540861598","pt":1719499246966,"mc":[{"id":"1.230180120","rc":[{"atl":[[3.35,0.84]],"id":69112387}],"con":true,"img":false}]}
{"op":"mcm","clk":"11540861605","pt":1719499247062,"mc":[{"id":"1.230180120","rc":[{"atb":[[2.92,0.84]],"id":69112387},{"atl":[[3.9,1]],"id":69112387}],"con":true,"img":false}]}
{"op":"mcm","clk":"11540861649","pt":1719499247702,"mc":[{"id":"1.230180120","rc":[{"atl":[[3.35,0]],"id":69112387}],"con":true,"img":false}]}
{"op":"mcm","clk":"11540861678","pt":1719499248064,"mc":[{"id":"1.230180120","rc":[{"atb":[[2.66,0]],"id":69112387}],"con":true,"img":false}]}
{"op":"mcm","clk":"11540861754","pt":1719499249171,"mc":[{"id":"1.230180120","rc":[{"atb":[[6,1.41]],"id":53432239},{"atb":[[6.8,1.24]],"id":64253834}],"con":true,"img":false}]}
{"op":"mcm","clk":"11540861782","pt":1719499249485,"mc":[{"id":"1.230180120","rc":[{"atb":[[6.2,0]],"id":64253834}],"con":true,"img":false}]}
{"op":"mcm","clk":"11540861818","pt":1719499249896,"mc":[{"id":"1.230180120","rc":[{"atb":[[5.8,0]],"id":53432239}],"con":true,"img":false}]}
{"op":"mcm","clk":"11540861855","pt":1719499250367,"mc":[{"id":"1.230180120","rc":[{"atb":[[6,0]],"id":53432239}],"con":true,"img":false}]}
{"op":"mcm","clk":"11540861873","pt":1719499250574,"mc":[{"id":"1.230180120","rc":[{"atl":[[10.5,0]],"id":47370245}],"con":true,"img":false}]}
{"op":"mcm","clk":"11540861885","pt":1719499250790,"mc":[{"id":"1.230180120","rc":[{"atb":[[5.9,1.46]],"id":53432239}],"con":true,"img":false}]}
{"op":"mcm","clk":"11540861892","pt":1719499250892,"mc":[{"id":"1.230180120","rc":[{"atb":[[6.6,1.46]],"id":64253834}],"con":true,"img":false}]}
{"op":"mcm","clk":"11540861915","pt":1719499251207,"mc":[{"id":"1.230180120","rc":[{"atb":[[6.8,0]],"id":64253834}],"con":true,"img":false}]}
{"op":"mcm","clk":"11540862011","pt":1719499252265,"mc":[{"id":"1.230180120","rc":[{"atl":[[1000,0.28]],"id":47370245}],"con":true,"img":false}]}
{"op":"mcm","clk":"11540862019","pt":1719499252473,"mc":[{"id":"1.230180120","rc":[{"atb":[[4.2,3.15]],"id":47370245}],"con":true,"img":false}]}
{"op":"mcm","clk":"11540862025","pt":1719499252582,"mc":[{"id":"1.230180120","rc":[{"atl":[[1000,0.17]],"id":47370245}],"con":true,"img":false}]}
{"op":"mcm","clk":"11540862032","pt":1719499252680,"mc":[{"id":"1.230180120","rc":[{"atb":[[3.6,0.78],[4,7]],"id":47370245},{"atl":[[10.5,0.11]],"id":47370245}],"con":true,"img":false}]}
{"op":"mcm","clk":"11540862059","pt":1719499253102,"mc":[{"id":"1.230180120","rc":[{"atb":[[4.3,0.84]],"id":47370245}],"con":true,"img":false}]}
{"op":"mcm","clk":"11540862069","pt":1719499253201,"mc":[{"id":"1.230180120","rc":[{"atb":[[3.6,2.86]],"id":47370245}],"con":true,"img":false}]}
{"op":"mcm","clk":"11540862139","pt":1719499254096,"mc":[{"id":"1.230180120","rc":[{"atb":[[3.75,9.25]],"id":47370245},{"atl":[[19.5,2.26]],"id":47370245}],"con":true,"img":false}]}
{"op":"mcm","clk":"11540862165","pt":1719499254517,"mc":[{"id":"1.230180120","rc":[{"atb":[[4.1,30.07]],"id":47370245}],"con":true,"img":false}]}
{"op":"mcm","clk":"11540862184","pt":1719499254668,"mc":[{"id":"1.230180120","rc":[{"atb":[[4.3,6.75]],"id":47370245}],"con":true,"img":false}]}
{"op":"mcm","clk":"11540862366","pt":1719499257097,"mc":[{"id":"1.230180120","rc":[{"atb":[[2.38,13.99]],"id":62847579}],"con":true,"img":false}]}
{"op":"mcm","clk":"11540862397","pt":1719499257563,"mc":[{"id":"1.230180120","rc":[{"atb":[[2.38,10.12]],"id":62847579}],"con":true,"img":false}]}
{"op":"mcm","clk":"11540862547","pt":1719499259386,"mc":[{"id":"1.230180120","rc":[{"atb":[[4,6]],"id":47370245}],"con":true,"img":false}]}
{"op":"mcm","clk":"11540862563","pt":1719499259693,"mc":[{"id":"1.230180120","rc":[{"atb":[[2.02,13.69]],"id":69112387}],"con":true,"img":false}]}
{"op":"mcm","clk":"11540862574","pt":1719499259899,"mc":[{"id":"1.230180120","rc":[{"atb":[[5.8,1.41]],"id":53432239}],"con":true,"img":false}]}
{"op":"mcm","clk":"11540862583","pt":1719499259999,"mc":[{"id":"1.230180120","rc":[{"atb":[[5.9,0.05]],"id":53432239}],"con":true,"img":false}]}
{"op":"mcm","clk":"11540862593","pt":1719499260104,"mc":[{"id":"1.230180120","rc":[{"atb":[[6,1.41]],"id":53432239}],"con":true,"img":false}]}
{"op":"mcm","clk":"11540862601","pt":1719499260207,"mc":[{"id":"1.230180120","rc":[{"atl":[[120,0.26]],"id":62847579},{"atl":[[12.5,0.26]],"id":53432239},{"atl":[[13,0.26]],"id":47370245},{"atl":[[8,0.26],[1000,0.79]],"id":64536702},{"atl":[[4.1,1.26]],"id":69112387},{"atl":[[110,0.26]],"id":64253834}],"con":true,"img":false}]}
{"op":"mcm","clk":"11540862610","pt":1719499260311,"mc":[{"id":"1.230180120","rc":[{"atl":[[1000,0.38]],"id":53432239},{"atl":[[16,2.26],[20,1.61]],"id":47370245},{"atl":[[1000,0.17]],"id":64536702},{"atl":[[140,0],[120,2.84]],"id":64253834}],"con":true,"img":false}]}
{"op":"mcm","clk":"11540862616","pt":1719499260416,"mc":[{"id":"1.230180120","rc":[{"atl":[[8,0],[8.2,1.62]],"id":64536702}],"con":true,"img":false}]}
{"op":"mcm","clk":"11540862626","pt":1719499260522,"mc":[{"id":"1.230180120","rc":[{"atb":[[5.8,0]],"id":53432239},{"atl":[[1000,0]],"id":53432239},{"atb":[[4.1,0.07]],"id":47370245},{"atb":[[6.6,1.28]],"id":64253834}],"con":true,"img":false}]}
