{"op":"mcm","clk":"11536832970","pt":1719431775485,"mc":[{"id":"1.230180121","marketDefinition":{"bspMarket":true,"turnInPlayEnabled":false,"persistenceEnabled":false,"marketBaseRate":5.0,"eventId":"33376437","eventTypeId":"4339","numberOfWinners":2,"bettingType":"ODDS","marketType":"PLACE","marketTime":"2024-06-27T14:49:00.000Z","suspendTime":"2024-06-27T14:49:00.000Z","bspReconciled":false,"complete":true,"inPlay":false,"crossMatching":false,"runnersVoidable":false,"numberOfActiveRunners":6,"betDelay":0,"status":"OPEN","runners":[{"status":"ACTIVE","sortPriority":1,"id":64536702,"name":"1. Rocket Jay"},{"status":"ACTIVE","sortPriority":2,"id":69112387,"name":"2. Salacres Pacino"},{"status":"ACTIVE","sortPriority":3,"id":47370245,"name":"3. Salacres Palermo"},{"status":"ACTIVE","sortPriority":4,"id":53432239,"name":"4. Bell Rock"},{"status":"ACTIVE","sortPriority":5,"id":62847579,"name":"5. Lamornascruffles"},{"status":"ACTIVE","sortPriority":6,"id":64253834,"name":"6. Mind The Mikey"}],"regulators":["MR_INT"],"venue":"Towcester","countryCode":"GB","discountAllowed":false,"timezone":"Europe/London","openDate":"2024-06-27T13:33:00.000Z","version":5994767065,"name":"To Be Placed","eventName":"Towcester 27th Jun"},"rc":[],"con":true,"img":false}]}
{"op":"mcm","clk":"11536833108","pt":1719431777486,"mc":[{"id":"1.230180121","marketDefinition":{"bspMarket":true,"turnInPlayEnabled":false,"persistenceEnabled":false,"marketBaseRate":5.0,"eventId":"33376437","eventTypeId":"4339","numberOfWinners":2,"bettingType":"ODDS","marketType":"PLACE","marketTime":"2024-06-27T14:49:00.000Z","suspendTime":"2024-06-27T14:49:00.000Z","bspReconciled":false,"complete":true,"inPlay":false,"crossMatching":false,"runnersVoidable":false,"numberOfActiveRunners":6,"betDelay":0,"status":"OPEN","runners":[{"status":"ACTIVE","sortPriority":1,"id":64536702,"name":"1. Rocket Jay"},{"status":"ACTIVE","sortPriority":2,"id":69112387,"name":"2. Salacres Pacino"},{"status":"ACTIVE","sortPriority":3,"id":47370245,"name":"3. Salacres Palermo"},{"status":"ACTIVE","sortPriority":4,"id":53432239,"name":"4. Bell Rock"},{"status":"ACTIVE","sortPriority":5,"id":62847579,"name":"5. Lamornascruffles"},{"status":"ACTIVE","sortPriority":6,"id":64253834,"name":"6. Mind The Mikey"}],"regulators":["MR_INT"],"venue":"Towcester","countryCode":"GB","discountAllowed":true,"timezone":"Europe/London","openDate":"2024-06-27T13:33:00.000Z","version":5994767065,"name":"To Be Placed","eventName":"Towcester 27th Jun"},"rc":[],"con":true,"img":false}]}
{"op":"mcm","clk":"11537084040","pt":1719435436135,"mc":[{"id":"1.230180121","rc":[{"atb":[[1.03,17.28]],"id":62847579},{"atl":[[1000,0.84]],"id":62847579},{"spn":500.51,"spf":"NaN","id":62847579},{"atb":[[1.02,25.92]],"id":53432239},{"atl":[[990,0.84]],"id":53432239},{"spn":495.51,"spf":"NaN","id":53432239},{"atb":[[1.03,17.28]],"id":47370245},{"atl":[[990,0.84]],"id":47370245},{"spn":495.51,"spf":"NaN","id":47370245},{"atb":[[1.01,51.84]],"id":64536702},{"atl":[[1000,0.84]],"id":64536702},{"spn":500.5,"spf":"NaN","id":64536702},{"atb":[[1.02,25.92]],"id":69112387},{"atl":[[990,0.84]],"id":69112387},{"spn":495.51,"spf":"NaN","id":69112387},{"atb":[[1.01,51.84]],"id":64253834},{"atl":[[1000,0.84]],"id":64253834},{"spn":500.5,"spf":"NaN","id":64253834}],"con":true,"img":false}]}
{"op":"mcm","clk":"11537233738","pt":1719437882657,"mc":[{"id":"1.230180121","marketDefinition":{"bspMarket":true,"turnInPlayEnabled":false,"persistenceEnabled":false,"marketBaseRate":5.0,"eventId":"33376437","eventTypeId":"4339","numberOfWinners":2,"bettingType":"ODDS","marketType":"PLACE","marketTime":"2024-06-27T14:49:00.000Z","suspendTime":"2024-06-27T14:49:00.000Z","bspReconciled":false,"complete":true,"inPlay":false,"crossMatching":false,"runnersVoidable":false,"numberOfActiveRunners":6,"betDelay":0,"status":"OPEN","runners":[{"status":"ACTIVE","sortPriority":1,"id":64536702,"name":"1. Rocket Jay"},{"status":"ACTIVE","sortPriority":2,"id":69112387,"name":"2. Salacres Pacino"},{"status":"ACTIVE","sortPriority":3,"id":47370245,"name":"3. Salacres Palermo"},{"status":"ACTIVE","sortPriority":4,"id":53432239,"name":"4. Bell Rock"},{"status":"ACTIVE","sortPriority":5,"id":62847579,"name":"5. Lamornascruffles"},{"status":"ACTIVE","sortPriority":6,"id":64253834,"name":"6. Mind The Mikey"}],"regulators":["MR_INT"],"venue":"Towcester","countryCode":"GB","discountAllowed":true,"timezone":"Europe/London","openDate":"2024-06-27T13:33:00.000Z","version":5994767065,"name":"To Be Placed","eventName":"Towcester 27th Jun"},"rc":[{"atb":[[1.03,17.28]],"id":62847579},{"atl":[[1000,0.84]],"id":62847579},{"spn":500.51,"spf":"NaN","id":62847579},{"atb":[[1.02,25.92]],"id":53432239},{"atl":[[990,0.84]],"id":53432239},{"spn":495.51,"spf":"NaN","id":53432239},{"atb":[[1.03,17.28]],"id":47370245},{"atl":[[990,0.84]],"id":47370245},{"spn":495.51,"spf":"NaN","id":47370245},{"atb":[[1.01,51.85]],"id":64536702},{"atl":[[1000,0.84]],"id":64536702},{"spn":500.5,"spf":"NaN","id":64536702},{"atb":[[1.02,25.92]],"id":69112387},{"atl":[[990,0.84]],"id":69112387},{"spn":495.51,"spf":"NaN","id":69112387},{"atb":[[1.01,51.85]],"id":64253834},{"atl":[[1000,0.84]],"id":64253834},{"spn":500.5,"spf":"NaN","id":64253834}],"con":true,"img":true}]}
{"op":"mcm","clk":"11537302621","pt":1719439040755,"mc":[{"id":"1.230180121","rc":[{"atb":[[1.03,17.28]],"id":62847579},{"atl":[[1000,0.23]],"id":62847579},{"atb":[[1.02,25.92]],"id":53432239},{"atl":[[990,0.23]],"id":53432239},{"atb":[[1.03,17.28]],"id":47370245},{"atl":[[990,0.23]],"id":47370245},{"atb":[[1.01,51.85]],"id":64536702},{"atl":[[1000,0.23]],"id":64536702},{"atb":[[1.02,25.92]],"id":69112387},{"atl":[[990,0.23]],"id":69112387},{"atb":[[1.01,51.85]],"id":64253834},{"atl":[[1000,0.23]],"id":64253834}],"con":true,"img":false}]}
{"op":"mcm","clk":"11537574889","pt":1719443282708,"mc":[{"id":"1.230180121","marketDefinition":{"bspMarket":true,"turnInPlayEnabled":false,"persistenceEnabled":false,"marketBaseRate":5.0,"eventId":"33376437","eventTypeId":"4339","numberOfWinners":2,"bettingType":"ODDS","marketType":"PLACE","marketTime":"2024-06-27T14:49:00.000Z","suspendTime":"2024-06-27T14:49:00.000Z","bspReconciled":false,"complete":true,"inPlay":false,"crossMatching":false,"runnersVoidable":false,"numberOfActiveRunners":6,"betDelay":0,"status":"OPEN","runners":[{"status":"ACTIVE","sortPriority":1,"id":64536702,"name":"1. Rocket Jay"},{"status":"ACTIVE","sortPriority":2,"id":69112387,"name":"2. Salacres Pacino"},{"status":"ACTIVE","sortPriority":3,"id":47370245,"name":"3. Salacres Palermo"},{"status":"ACTIVE","sortPriority":4,"id":53432239,"name":"4. Bell Rock"},{"status":"ACTIVE","sortPriority":5,"id":62847579,"name":"5. Lamornascruffles"},{"status":"ACTIVE","sortPriority":6,"id":64253834,"name":"6. Mind The Mikey"}],"regulators":["MR_INT"],"venue":"Towcester","countryCode":"GB","discountAllowed":true,"timezone":"Europe/London","openDate":"2024-06-27T13:33:00.000Z","version":5994767065,"name":"To Be Placed","eventName":"Towcester 27th Jun"},"rc":[{"atb":[[1.03,17.28]],"id":62847579},{"atl":[[1000,0.23]],"id":62847579},{"spn":500.51,"spf":"NaN","id":62847579},{"atb":[[1.02,25.92]],"id":53432239},{"atl":[[990,0.23]],"id":53432239},{"spn":495.51,"spf":"NaN","id":53432239},{"atb":[[1.03,17.28]],"id":47370245},{"atl":[[990,0.23]],"id":47370245},{"spn":495.51,"spf":"NaN","id":47370245},{"atb":[[1.01,51.85]],"id":64536702},{"atl":[[1000,0.23]],"id":64536702},{"spn":500.5,"spf":"NaN","id":64536702},{"atb":[[1.02,25.92]],"id":69112387},{"atl":[[990,0.23]],"id":69112387},{"spn":495.51,"spf":"NaN","id":69112387},{"atb":[[1.01,51.85]],"id":64253834},{"atl":[[1000,0.23]],"id":64253834},{"spn":500.5,"spf":"NaN","id":64253834}],"con":true,"img":true}]}
{"op":"mcm","clk":"11537956509","pt":1719448682749,"mc":[{"id":"1.230180121","marketDefinition":{"bspMarket":true,"turnInPlayEnabled":false,"persistenceEnabled":false,"marketBaseRate":5.0,"eventId":"33376437","eventTypeId":"4339","numberOfWinners":2,"bettingType":"ODDS","marketType":"PLACE","marketTime":"2024-06-27T14:49:00.000Z","suspendTime":"2024-06-27T14:49:00.000Z","bspReconciled":false,"complete":true,"inPlay":false,"crossMatching":false,"runnersVoidable":false,"numberOfActiveRunners":6,"betDelay":0,"status":"OPEN","runners":[{"status":"ACTIVE","sortPriority":1,"id":64536702,"name":"1. Rocket Jay"},{"status":"ACTIVE","sortPriority":2,"id":69112387,"name":"2. Salacres Pacino"},{"status":"ACTIVE","sortPriority":3,"id":47370245,"name":"3. Salacres Palermo"},{"status":"ACTIVE","sortPriority":4,"id":53432239,"name":"4. Bell Rock"},{"status":"ACTIVE","sortPriority":5,"id":62847579,"name":"5. Lamornascruffles"},{"status":"ACTIVE","sortPriority":6,"id":64253834,"name":"6. Mind The Mikey"}],"regulators":["MR_INT"],"venue":"Towcester","countryCode":"GB","discountAllowed":true,"timezone":"Europe/London","openDate":"2024-06-27T13:33:00.000Z","version":5994767065,"name":"To Be Placed","eventName":"Towcester 27th Jun"},"rc":[{"atb":[[1.03,17.28]],"id":62847579},{"atl":[[1000,0.23]],"id":62847579},{"spn":500.51,"spf":"NaN","id":62847579},{"atb":[[1.02,25.92]],"id":53432239},{"atl":[[990,0.23]],"id":53432239},{"spn":495.51,"spf":"NaN","id":53432239},{"atb":[[1.03,17.28]],"id":47370245},{"atl":[[990,0.23]],"id":47370245},{"spn":495.51,"spf":"NaN","id":47370245},{"atb":[[1.01,51.85]],"id":64536702},{"atl":[[1000,0.23]],"id":64536702},{"spn":500.5,"spf":"NaN","id":64536702},{"atb":[[1.02,25.92]],"id":69112387},{"atl":[[990,0.23]],"id":69112387},{"spn":495.51,"spf":"NaN","id":69112387},{"atb":[[1.01,51.85]],"id":64253834},{"atl":[[1000,0.23]],"id":64253834},{"spn":500.5,"spf":"NaN","id":64253834}],"con":true,"img":true}]}
{"op":"mcm","clk":"11538172126","pt":1719454082692,"mc":[{"id":"1.230180121","marketDefinition":{"bspMarket":true,"turnInPlayEnabled":false,"persistenceEnabled":false,"marketBaseRate":5.0,"eventId":"33376437","eventTypeId":"4339","numberOfWinners":2,"bettingType":"ODDS","marketType":"PLACE","marketTime":"2024-06-27T14:49:00.000Z","suspendTime":"2024-06-27T14:49:00.000Z","bspReconciled":false,"complete":true,"inPlay":false,"crossMatching":false,"runnersVoidable":false,"numberOfActiveRunners":6,"betDelay":0,"status":"OPEN","runners":[{"status":"ACTIVE","sortPriority":1,"id":64536702,"name":"1. Rocket Jay"},{"status":"ACTIVE","sortPriority":2,"id":69112387,"name":"2. Salacres Pacino"},{"status":"ACTIVE","sortPriority":3,"id":47370245,"name":"3. Salacres Palermo"},{"status":"ACTIVE","sortPriority":4,"id":53432239,"name":"4. Bell Rock"},{"status":"ACTIVE","sortPriority":5,"id":62847579,"name":"5. Lamornascruffles"},{"status":"ACTIVE","sortPriority":6,"id":64253834,"name":"6. Mind The Mikey"}],"regulators":["MR_INT"],"venue":"Towcester","countryCode":"GB","discountAllowed":true,"timezone":"Europe/London","openDate":"2024-06-27T13:33:00.000Z","version":5994767065,"name":"To Be Placed","eventName":"Towcester 27th Jun"},"rc":[{"atb":[[1.03,17.29]],"id":62847579},{"atl":[[1000,0.23]],"id":62847579},{"spn":500.51,"spf":"NaN","id":62847579},{"atb":[[1.02,25.93]],"id":53432239},{"atl":[[990,0.23]],"id":53432239},{"spn":495.51,"spf":"NaN","id":53432239},{"atb":[[1.03,17.29]],"id":47370245},{"atl":[[990,0.23]],"id":47370245},{"spn":495.51,"spf":"NaN","id":47370245},{"atb":[[1.01,51.86]],"id":64536702},{"atl":[[1000,0.23]],"id":64536702},{"spn":500.5,"spf":"NaN","id":64536702},{"atb":[[1.02,25.93]],"id":69112387},{"atl":[[990,0.23]],"id":69112387},{"spn":495.51,"spf":"NaN","id":69112387},{"atb":[[1.01,51.86]],"id":64253834},{"atl":[[1000,0.23]],"id":64253834},{"spn":500.5,"spf":"NaN","id":64253834}],"con":true,"img":true}]}
{"op":"mcm","clk":"11538369793","pt":1719459482778,"mc":[{"id":"1.230180121","marketDefinition":{"bspMarket":true,"turnInPlayEnabled":false,"persistenceEnabled":false,"marketBaseRate":5.0,"eventId":"33376437","eventTypeId":"4339","numberOfWinners":2,"bettingType":"ODDS","marketType":"PLACE","marketTime":"2024-06-27T14:49:00.000Z","suspendTime":"2024-06-27T14:49:00.000Z","bspReconciled":false,"complete":true,"inPlay":false,"crossMatching":false,"runnersVoidable":false,"numberOfActiveRunners":6,"betDelay":0,"status":"OPEN","runners":[{"status":"ACTIVE","sortPriority":1,"id":64536702,"name":"1. Rocket Jay"},{"status":"ACTIVE","sortPriority":2,"id":69112387,"name":"2. Salacres Pacino"},{"status":"ACTIVE","sortPriority":3,"id":47370245,"name":"3. Salacres Palermo"},{"status":"ACTIVE","sortPriority":4,"id":53432239,"name":"4. Bell Rock"},{"status":"ACTIVE","sortPriority":5,"id":62847579,"name":"5. Lamornascruffles"},{"status":"ACTIVE","sortPriority":6,"id":64253834,"name":"6. Mind The Mikey"}],"regulators":["MR_INT"],"venue":"Towcester","countryCode":"GB","discountAllowed":true,"timezone":"Europe/London","openDate":"2024-06-27T13:33:00.000Z","version":5994767065,"name":"To Be Placed","eventName":"Towcester 27th Jun"},"rc":[{"atb":[[1.03,17.29]],"id":62847579},{"atl":[[1000,0.23]],"id":62847579},{"spn":500.51,"spf":"NaN","id":62847579},{"atb":[[1.02,25.93]],"id":53432239},{"atl":[[990,0.23]],"id":53432239},{"spn":495.51,"spf":"NaN","id":53432239},{"atb":[[1.03,17.29]],"id":47370245},{"atl":[[990,0.23]],"id":47370245},{"spn":495.51,"spf":"NaN","id":47370245},{"atb":[[1.01,51.87]],"id":64536702},{"atl":[[1000,0.23]],"id":64536702},{"spn":500.5,"spf":"NaN","id":64536702},{"atb":[[1.02,25.93]],"id":69112387},{"atl":[[990,0.23]],"id":69112387},{"spn":495.51,"spf":"NaN","id":69112387},{"atb":[[1.01,51.87]],"id":64253834},{"atl":[[1000,0.23]],"id":64253834},{"spn":500.5,"spf":"NaN","id":64253834}],"con":true,"img":true}]}
{"op":"mcm","clk":"11538596923","pt":1719464882721,"mc":[{"id":"1.230180121","marketDefinition":{"bspMarket":true,"turnInPlayEnabled":false,"persistenceEnabled":false,"marketBaseRate":5.0,"eventId":"33376437","eventTypeId":"4339","numberOfWinners":2,"bettingType":"ODDS","marketType":"PLACE","marketTime":"2024-06-27T14:49:00.000Z","suspendTime":"2024-06-27T14:49:00.000Z","bspReconciled":false,"complete":true,"inPlay":false,"crossMatching":false,"runnersVoidable":false,"numberOfActiveRunners":6,"betDelay":0,"status":"OPEN","runners":[{"status":"ACTIVE","sortPriority":1,"id":64536702,"name":"1. Rocket Jay"},{"status":"ACTIVE","sortPriority":2,"id":69112387,"name":"2. Salacres Pacino"},{"status":"ACTIVE","sortPriority":3,"id":47370245,"name":"3. Salacres Palermo"},{"status":"ACTIVE","sortPriority":4,"id":53432239,"name":"4. Bell Rock"},{"status":"ACTIVE","sortPriority":5,"id":62847579,"name":"5. Lamornascruffles"},{"status":"ACTIVE","sortPriority":6,"id":64253834,"name":"6. Mind The Mikey"}],"regulators":["MR_INT"],"venue":"Towcester","countryCode":"GB","discountAllowed":true,"timezone":"Europe/London","openDate":"2024-06-27T13:33:00.000Z","version":5994767065,"name":"To Be Placed","eventName":"Towcester 27th Jun"},"rc":[{"atb":[[1.03,17.29]],"id":62847579},{"atl":[[1000,0.23]],"id":62847579},{"spn":500.51,"spf":"NaN","id":62847579},{"atb":[[1.02,25.93]],"id":53432239},{"atl":[[990,0.23]],"id":53432239},{"spn":495.51,"spf":"NaN","id":53432239},{"atb":[[1.03,17.29]],"id":47370245},{"atl":[[990,0.23]],"id":47370245},{"spn":495.51,"spf":"NaN","id":47370245},{"atb":[[1.01,51.86]],"id":64536702},{"atl":[[1000,0.23]],"id":64536702},{"spn":500.5,"spf":"NaN","id":64536702},{"atb":[[1.02,25.93]],"id":69112387},{"atl":[[990,0.23]],"id":69112387},{"spn":495.51,"spf":"NaN","id":69112387},{"atb":[[1.01,51.86]],"id":64253834},{"atl":[[1000,0.23]],"id":64253834},{"spn":500.5,"spf":"NaN","id":64253834}],"con":true,"img":true}]}
{"op":"mcm","clk":"11538906762","pt":1719471499095,"mc":[{"id":"1.230180121","rc":[{"atb":[[1.03,17.29],[1.07,2.48]],"id":62847579},{"atl":[[1000,1.23]],"id":62847579},{"spn":500.53,"spf":"NaN","id":62847579},{"atb":[[1.02,25.93],[1.07,2.48]],"id":53432239},{"atl":[[1000,1]],"id":53432239},{"spn":495.53,"spf":"NaN","id":53432239},{"atb":[[1.03,17.29],[1.07,2.48]],"id":47370245},{"atl":[[1000,1]],"id":47370245},{"spn":495.53,"spf":"NaN","id":47370245},{"atb":[[1.01,51.86],[1.07,2.48]],"id":64536702},{"atl":[[1000,1.23]],"id":64536702},{"spn":500.53,"spf":"NaN","id":64536702},{"atb":[[1.02,25.93],[1.07,2.48]],"id":69112387},{"atl":[[1000,1]],"id":69112387},{"spn":495.53,"spf":"NaN","id":69112387},{"atb":[[1.01,51.86],[1.07,2.48]],"id":64253834},{"atl":[[1000,1.23]],"id":64253834},{"spn":500.53,"spf":"NaN","id":64253834}],"con":true,"img":false}]}
{"op":"mcm","clk":"11538906770","pt":1719471499300,"mc":[{"id":"1.230180121","rc":[{"atl":[[1000,0.71]],"id":62847579},{"atl":[[1000,0.48]],"id":53432239},{"atl":[[1000,0.48]],"id":47370245},{"atl":[[1000,0.71]],"id":64536702},{"atl":[[1000,0.48]],"id":69112387},{"atl":[[1000,0.71]],"id":64253834}],"con":true,"img":false}]}
{"op":"mcm","clk":"11538906785","pt":1719471499517,"mc":[{"id":"1.230180121","rc":[{"atl":[[1000,0.23]],"id":62847579},{"atl":[[1000,0]],"id":53432239},{"atl":[[1000,0]],"id":47370245},{"atl":[[1000,0.23]],"id":64536702},{"atl":[[1000,0]],"id":69112387},{"atl":[[1000,0.23]],"id":64253834}],"con":true,"img":false}]}
{"op":"mcm","clk":"11538906792","pt":1719471499626,"mc":[{"id":"1.230180121","rc":[{"atl":[[75,0.48]],"id":62847579},{"atl":[[75,0.48]],"id":53432239},{"atl":[[75,0.48]],"id":47370245},{"atl":[[75,0.48]],"id":64536702},{"atl":[[75,0.48]],"id":69112387},{"atl":[[75,0.48]],"id":64253834}],"con":true,"img":false}]}
{"op":"mcm","clk":"11539124111","pt":1719475682708,"mc":[{"id":"1.230180121","marketDefinition":{"bspMarket":true,"turnInPlayEnabled":false,"persistenceEnabled":false,"marketBaseRate":5.0,"eventId":"33376437","eventTypeId":"4339","numberOfWinners":2,"bettingType":"ODDS","marketType":"PLACE","marketTime":"2024-06-27T14:49:00.000Z","suspendTime":"2024-06-27T14:49:00.000Z","bspReconciled":false,"complete":true,"inPlay":false,"crossMatching":false,"runnersVoidable":false,"numberOfActiveRunners":6,"betDelay":0,"status":"OPEN","runners":[{"status":"ACTIVE","sortPriority":1,"id":64536702,"name":"1. Rocket Jay"},{"status":"ACTIVE","sortPriority":2,"id":69112387,"name":"2. Salacres Pacino"},{"status":"ACTIVE","sortPriority":3,"id":47370245,"name":"3. Salacres Palermo"},{"status":"ACTIVE","sortPriority":4,"id":53432239,"name":"4. Bell Rock"},{"status":"ACTIVE","sortPriority":5,"id":62847579,"name":"5. Lamornascruffles"},{"status":"ACTIVE","sortPriority":6,"id":64253834,"name":"6. Mind The Mikey"}],"regulators":["MR_INT"],"venue":"Towcester","countryCode":"GB","discountAllowed":true,"timezone":"Europe/London","openDate":"2024-06-27T13:33:00.000Z","version":5994767065,"name":"To Be Placed","eventName":"Towcester 27th Jun"},"rc":[{"atb":[[1.03,17.28],[1.07,2.48]],"id":62847579},{"atl":[[75,0.48],[1000,0.23]],"id":62847579},{"spn":38.03,"spf":"NaN","id":62847579},{"atb":[[1.02,25.92],[1.07,2.48]],"id":53432239},{"atl":[[75,0.48],[990,0.23]],"id":53432239},{"spn":38.03,"spf":"NaN","id":53432239},{"atb":[[1.03,17.28],[1.07,2.48]],"id":47370245},{"atl":[[75,0.48],[990,0.23]],"id":47370245},{"spn":38.03,"spf":"NaN","id":47370245},{"atb":[[1.01,51.84],[1.07,2.48]],"id":64536702},{"atl":[[75,0.48],[1000,0.23]],"id":64536702},{"spn":38.03,"spf":"NaN","id":64536702},{"atb":[[1.02,25.92],[1.07,2.48]],"id":69112387},{"atl":[[75,0.48],[990,0.23]],"id":69112387},{"spn":38.03,"spf":"NaN","id":69112387},{"atb":[[1.01,51.84],[1.07,2.48]],"id":64253834},{"atl":[[75,0.48],[1000,0.23]],"id":64253834},{"spn":38.03,"spf":"NaN","id":64253834}],"con":true,"img":true}]}
{"op":"mcm","clk":"11539440223","pt":1719481082681,"mc":[{"id":"1.230180121","marketDefinition":{"bspMarket":true,"turnInPlayEnabled":false,"persistenceEnabled":false,"marketBaseRate":5.0,"eventId":"33376437","eventTypeId":"4339","numberOfWinners":2,"bettingType":"ODDS","marketType":"PLACE","marketTime":"2024-06-27T14:49:00.000Z","suspendTime":"2024-06-27T14:49:00.000Z","bspReconciled":false,"complete":true,"inPlay":false,"crossMatching":false,"runnersVoidable":false,"numberOfActiveRunners":6,"betDelay":0,"status":"OPEN","runners":[{"status":"ACTIVE","sortPriority":1,"id":64536702,"name":"1. Rocket Jay"},{"status":"ACTIVE","sortPriority":2,"id":69112387,"name":"2. Salacres Pacino"},{"status":"ACTIVE","sortPriority":3,"id":47370245,"name":"3. Salacres Palermo"},{"status":"ACTIVE","sortPriority":4,"id":53432239,"name":"4. Bell Rock"},{"status":"ACTIVE","sortPriority":5,"id":62847579,"name":"5. Lamornascruffles"},{"status":"ACTIVE","sortPriority":6,"id":64253834,"name":"6. Mind The Mikey"}],"regulators":["MR_INT"],"venue":"Towcester","countryCode":"GB","discountAllowed":true,"timezone":"Europe/London","openDate":"2024-06-27T13:33:00.000Z","version":5994767065,"name":"To Be Placed","eventName":"Towcester 27th Jun"},"rc":[{"atb":[[1.03,17.28],[1.07,2.48]],"id":62847579},{"atl":[[75,0.48],[1000,0.23]],"id":62847579},{"spn":38.03,"spf":"NaN","id":62847579},{"atb":[[1.02,25.91],[1.07,2.48]],"id":53432239},{"atl":[[75,0.48],[990,0.23]],"id":53432239},{"spn":38.03,"spf":"NaN","id":53432239},{"atb":[[1.03,17.28],[1.07,2.48]],"id":47370245},{"atl":[[75,0.48],[990,0.23]],"id":47370245},{"spn":38.03,"spf":"NaN","id":47370245},{"atb":[[1.01,51.83],[1.07,2.48]],"id":64536702},{"atl":[[75,0.48],[1000,0.23]],"id":64536702},{"spn":38.03,"spf":"NaN","id":64536702},{"atb":[[1.02,25.91],[1.07,2.48]],"id":69112387},{"atl":[[75,0.48],[990,0.23]],"id":69112387},{"spn":38.03,"spf":"NaN","id":69112387},{"atb":[[1.01,51.83],[1.07,2.48]],"id":64253834},{"atl":[[75,0.48],[1000,0.23]],"id":64253834},{"spn":38.03,"spf":"NaN","id":64253834}],"con":true,"img":true}]}
{"op":"mcm","clk":"11540685105","pt":1719497282635,"mc":[{"id":"1.230180121","marketDefinition":{"bspMarket":true,"turnInPlayEnabled":false,"persistenceEnabled":false,"marketBaseRate":5.0,"eventId":"33376437","eventTypeId":"4339","numberOfWinners":2,"bettingType":"ODDS","marketType":"PLACE","marketTime":"2024-06-27T14:49:00.000Z","suspendTime":"2024-06-27T14:49:00.000Z","bspReconciled":false,"complete":true,"inPlay":false,"crossMatching":false,"runnersVoidable":false,"numberOfActiveRunners":6,"betDelay":0,"status":"OPEN","runners":[{"status":"ACTIVE","sortPriority":1,"id":64536702,"name":"1. Rocket Jay"},{"status":"ACTIVE","sortPriority":2,"id":69112387,"name":"2. Salacres Pacino"},{"status":"ACTIVE","sortPriority":3,"id":47370245,"name":"3. Salacres Palermo"},{"status":"ACTIVE","sortPriority":4,"id":53432239,"name":"4. Bell Rock"},{"status":"ACTIVE","sortPriority":5,"id":62847579,"name":"5. Lamornascruffles"},{"status":"ACTIVE","sortPriority":6,"id":64253834,"name":"6. Mind The Mikey"}],"regulators":["MR_INT"],"venue":"Towcester","countryCode":"GB","discountAllowed":true,"timezone":"Europe/London","openDate":"2024-06-27T13:33:00.000Z","version":5994767065,"name":"To Be Placed","eventName":"Towcester 27th Jun"},"rc":[{"atb":[[1.03,17.29],[1.07,2.48]],"id":62847579},{"atl":[[75,0.48],[1000,0.23]],"id":62847579},{"spn":38.03,"spf":"NaN","id":62847579},{"atb":[[1.02,25.93],[1.07,2.48]],"id":53432239},{"atl":[[75,0.48],[990,0.23]],"id":53432239},{"spn":38.03,"spf":"NaN","id":53432239},{"atb":[[1.03,17.29],[1.07,2.48]],"id":47370245},{"atl":[[75,0.48],[990,0.23]],"id":47370245},{"spn":38.03,"spf":"NaN","id":47370245},{"atb":[[1.01,51.87],[1.07,2.48]],"id":64536702},{"atl":[[75,0.48],[1000,0.23]],"id":64536702},{"spn":38.03,"spf":"NaN","id":64536702},{"atb":[[1.02,25.93],[1.07,2.48]],"id":69112387},{"atl":[[75,0.48],[990,0.23]],"id":69112387},{"spn":38.03,"spf":"NaN","id":69112387},{"atb":[[1.01,51.87],[1.07,2.48]],"id":64253834},{"atl":[[75,0.48],[1000,0.23]],"id":64253834},{"spn":38.03,"spf":"NaN","id":64253834}],"con":true,"img":true}]}
{"op":"mcm","clk":"11540751397","pt":1719498003233,"mc":[{"id":"1.230180121","rc":[{"atb":[[1.03,17.29],[1.04,1]],"id":62847579},{"spn":38.03,"spf":"NaN","id":62847579},{"atb":[[1.02,25.93],[1.04,1]],"id":53432239},{"spn":38.03,"spf":"NaN","id":53432239},{"atb":[[1.03,17.29],[1.04,1]],"id":47370245},{"spn":38.03,"spf":"NaN","id":47370245},{"atb":[[1.01,51.87],[1.04,1]],"id":64536702},{"spn":38.03,"spf":"NaN","id":64536702},{"atb":[[1.02,25.93],[1.04,1]],"id":69112387},{"spn":38.03,"spf":"NaN","id":69112387},{"atb":[[1.01,51.87],[1.04,1]],"id":64253834},{"spn":38.03,"spf":"NaN","id":64253834}],"con":true,"img":false}]}
{"op":"mcm","clk":"11540751415","pt":1719498003424,"mc":[{"id":"1.230180121","rc":[{"atb":[[1.04,0.25]],"id":62847579},{"atb":[[1.04,0.25]],"id":53432239},{"atb":[[1.04,0.25]],"id":47370245},{"atb":[[1.04,0.25]],"id":64536702},{"atb":[[1.04,0.25]],"id":69112387},{"atb":[[1.04,0.25]],"id":64253834}],"con":true,"img":false}]}
{"op":"mcm","clk":"11540751435","pt":1719498003584,"mc":[{"id":"1.230180121","rc":[{"atb":[[1.04,0]],"id":62847579},{"atb":[[1.04,0]],"id":53432239},{"atb":[[1.04,0]],"id":47370245},{"atb":[[1.04,0]],"id":64536702},{"atb":[[1.04,0]],"id":69112387},{"atb":[[1.04,0]],"id":64253834}],"con":true,"img":false}]}
{"op":"mcm","clk":"11540751449","pt":1719498003697,"mc":[{"id":"1.230180121","rc":[{"atb":[[1.2,0.25]],"id":62847579},{"atb":[[1.2,0.25]],"id":53432239},{"atb":[[1.2,0.25]],"id":47370245},{"atb":[[1.2,0.25]],"id":64536702},{"atb":[[1.2,0.25]],"id":69112387},{"atb":[[1.2,0.25]],"id":64253834}],"con":true,"img":false}]}
{"op":"mcm","clk":"11540751610","pt":1719498005418,"mc":[{"id":"1.230180121","rc":[{"atb":[[1.09,43.87]],"id":62847579},{"atb":[[1.09,43.87]],"id":69112387}],"con":true,"img":false}]}
{"op":"mcm","clk":"11540751628","pt":1719498005604,"mc":[{"id":"1.230180121","rc":[{"atb":[[1.09,43.87]],"id":47370245},{"atb":[[1.09,43.87]],"id":64253834}],"con":true,"img":false}]}
{"op":"mcm","clk":"11540751650","pt":1719498005828,"mc":[{"id":"1.230180121","rc":[{"atb":[[1.09,43.87]],"id":53432239}],"con":true,"img":false}]}
{"op":"mcm","clk":"11540753146","pt":1719498022302,"mc":[{"id":"1.230180121","rc":[{"atb":[[1.1,59.26]],"id":69112387}],"con":true,"img":false}]}
{"op":"mcm","clk":"11540753196","pt":1719498022922,"mc":[{"id":"1.230180121","rc":[{"atb":[[1.11,50.25]],"id":69112387}],"con":true,"img":false}]}
{"op":"mcm","clk":"11540753218","pt":1719498023141,"mc":[{"id":"1.230180121","rc":[{"atb":[[1.09,0]],"id":69112387}],"con":true,"img":false}]}
{"op":"mcm","clk":"11540753237","pt":1719498023349,"mc":[{"id":"1.230180121","rc":[{"atb":[[1.12,32.9]],"id":69112387}],"con":true,"img":false}]}
{"op":"mcm","clk":"11540754998","pt":1719498043276,"mc":[{"id":"1.230180121","marketDefinition":{"bspMarket":true,"turnInPlayEnabled":false,"persistenceEnabled":false,"marketBaseRate":5.0,"eventId":"33376437","eventTypeId":"4339","numberOfWinners":2,"bettingType":"ODDS","marketType":"PLACE","marketTime":"2024-06-27T14:49:00.000Z","suspendTime":"2024-06-27T14:49:00.000Z","bspReconciled":false,"complete":true,"inPlay":false,"crossMatching":true,"runnersVoidable":false,"numberOfActiveRunners":6,"betDelay":0,"status":"OPEN","runners":[{"status":"ACTIVE","sortPriority":1,"id":64536702,"name":"1. Rocket Jay"},{"status":"ACTIVE","sortPriority":2,"id":69112387,"name":"2. Salacres Pacino"},{"status":"ACTIVE","sortPriority":3,"id":47370245,"name":"3. Salacres Palermo"},{"status":"ACTIVE","sortPriority":4,"id":53432239,"name":"4. Bell Rock"},{"status":"ACTIVE","sortPriority":5,"id":62847579,"name":"5. Lamornascruffles"},{"status":"ACTIVE","sortPriority":6,"id":64253834,"name":"6. Mind The Mikey"}],"regulators":["MR_INT"],"venue":"Towcester","countryCode":"GB","discountAllowed":true,"timezone":"Europe/London","openDate":"2024-06-27T13:33:00.000Z","version":5994767065,"name":"To Be Placed","eventName":"Towcester 27th Jun"},"rc":[],"con":true,"img":false}]}
{"op":"mcm","clk":"11540756340","pt":1719498058664,"mc":[{"id":"1.230180121","rc":[{"atb":[[1.1,0]],"id":69112387}],"con":true,"img":false}]}
{"op":"mcm","clk":"11540756376","pt":1719498059074,"mc":[{"id":"1.230180121","rc":[{"atb":[[1.13,45.58]],"id":69112387}],"con":true,"img":false}]}
{"op":"mcm","clk":"11540758076","pt":1719498077051,"mc":[{"id":"1.230180121","rc":[{"spn":38.1,"spf":"NaN","id":62847579},{"spn":38.1,"spf":"NaN","id":53432239},{"spn":38.1,"spf":"NaN","id":47370245},{"spn":38.1,"spf":"NaN","id":64536702},{"atb":[[1.11,0]],"id":69112387},{"spn":38.1,"spf":"NaN","id":69112387},{"spn":38.1,"spf":"NaN","id":64253834}],"con":true,"img":false}]}
{"op":"mcm","clk":"11540758092","pt":1719498077153,"mc":[{"id":"1.230180121","rc":[{"atb":[[1.12,0]],"id":69112387}],"con":true,"img":false}]}
{"op":"mcm","clk":"11540758111","pt":1719498077364,"mc":[{"id":"1.230180121","rc":[{"atb":[[1.14,39.48]],"id":69112387}],"con":true,"img":false}]}
{"op":"mcm","clk":"11540758121","pt":1719498077471,"mc":[{"id":"1.230180121","rc":[{"atb":[[1.15,26.32]],"id":69112387}],"con":true,"img":false}]}
{"op":"mcm","clk":"11540759735","pt":1719498095297,"mc":[{"id":"1.230180121","rc":[{"atb":[[1.13,0]],"id":69112387}],"con":true,"img":false}]}
{"op":"mcm","clk":"11540759764","pt":1719498095608,"mc":[{"id":"1.230180121","rc":[{"atb":[[1.16,37.03]],"id":69112387}],"con":true,"img":false}]}
{"op":"mcm","clk":"11540761520","pt":1719498114309,"mc":[{"id":"1.230180121","rc":[{"atb":[[1.14,0]],"id":69112387}],"con":true,"img":false}]}
{"op":"mcm","clk":"11540761542","pt":1719498114518,"mc":[{"id":"1.230180121","rc":[{"atb":[[1.15,0]],"id":69112387}],"con":true,"img":false}]}
{"op":"mcm","clk":"11540761577","pt":1719498114928,"mc":[{"id":"1.230180121","rc":[{"atb":[[1.17,32.51]],"id":69112387}],"con":true,"img":false}]}
{"op":"mcm","clk":"11540761587","pt":1719498115027,"mc":[{"id":"1.230180121","rc":[{"atb":[[1.18,21.93]],"id":69112387}],"con":true,"img":false}]}
{"op":"mcm","clk":"11540763360","pt":1719498135207,"mc":[{"id":"1.230180121","rc":[{"atb":[[1.16,0]],"id":69112387}],"con":true,"img":false}]}
{"op":"mcm","clk":"11540763391","pt":1719498135513,"mc":[{"id":"1.230180121","rc":[{"atb":[[1.19,31.18]],"id":69112387}],"con":true,"img":false}]}
{"op":"mcm","clk":"11540764562","pt":1719498147953,"mc":[{"id":"1.230180121","rc":[{"atb":[[1.18,0],[1.17,0]],"id":69112387}],"con":true,"img":false}]}
{"op":"mcm","clk":"11540764584","pt":1719498148165,"mc":[{"id":"1.230180121","rc":[{"atb":[[1.21,18.8]],"id":69112387}],"con":true,"img":false}]}
{"op":"mcm","clk":"11540764602","pt":1719498148364,"mc":[{"id":"1.230180121","rc":[{"atb":[[1.2,27.88]],"id":69112387}],"con":true,"img":false}]}
{"op":"mcm","clk":"11540766400","pt":1719498168286,"mc":[{"id":"1.230180121","rc":[{"atb":[[1.19,0]],"id":69112387}],"con":true,"img":false}]}
{"op":"mcm","clk":"11540766447","pt":1719498168804,"mc":[{"id":"1.230180121","rc":[{"atb":[[1.22,26.93]],"id":69112387}],"con":true,"img":false}]}
{"op":"mcm","clk":"11540767985","pt":1719498184901,"mc":[{"id":"1.230180121","rc":[{"atb":[[1.2,0.25],[1.21,0]],"id":69112387}],"con":true,"img":false}]}
{"op":"mcm","clk":"11540768027","pt":1719498185311,"mc":[{"id":"1.230180121","rc":[{"atb":[[1.24,16.44]],"id":69112387}],"con":true,"img":false}]}
{"op":"mcm","clk":"11540768054","pt":1719498185513,"mc":[{"id":"1.230180121","rc":[{"atb":[[1.23,24.03]],"id":69112387}],"con":true,"img":false}]}
{"op":"mcm","clk":"11540770613","pt":1719498209203,"mc":[{"id":"1.230180121","rc":[{"atb":[[1.26,16.28]],"id":69112387},{"spn":38.13,"spf":"NaN","id":69112387}],"con":true,"img":false}]}
{"op":"mcm","clk":"11540770621","pt":1719498209308,"mc":[{"id":"1.230180121","rc":[{"atb":[[1.22,0]],"id":69112387}],"con":true,"img":false}]}
{"op":"mcm","clk":"11540770637","pt":1719498209514,"mc":[{"id":"1.230180121","rc":[{"atb":[[1.11,38.47]],"id":64253834}],"con":true,"img":false}]}
{"op":"mcm","clk":"11540770643","pt":1719498209619,"mc":[{"id":"1.230180121","rc":[{"atb":[[1.11,38.47]],"id":47370245}],"con":true,"img":false}]}
{"op":"mcm","clk":"11540770668","pt":1719498209937,"mc":[{"id":"1.230180121","rc":[{"atb":[[1.11,38.47]],"id":62847579}],"con":true,"img":false}]}
{"op":"mcm","clk":"11540770678","pt":1719498210030,"mc":[{"id":"1.230180121","rc":[{"atb":[[1.11,38.47]],"id":53432239}],"con":true,"img":false}]}
{"op":"mcm","clk":"11540770693","pt":1719498210258,"mc":[{"id":"1.230180121","rc":[{"atb":[[1.25,23.7]],"id":69112387}],"con":true,"img":false}]}
{"op":"mcm","clk":"11540772593","pt":1719498228760,"mc":[{"id":"1.230180121","rc":[{"atb":[[1.23,0],[1.24,0]],"id":69112387}],"con":true,"img":false}]}
{"op":"mcm","clk":"11540772621","pt":1719498229026,"mc":[{"id":"1.230180121","rc":[{"atb":[[1.09,0]],"id":53432239}],"con":true,"img":false}]}
{"op":"mcm","clk":"11540772634","pt":1719498229231,"mc":[{"id":"1.230180121","rc":[{"atb":[[1.09,0]],"id":62847579},{"atb":[[1.09,0]],"id":64253834}],"con":true,"img":false}]}
{"op":"mcm","clk":"11540772653","pt":1719498229445,"mc":[{"id":"1.230180121","rc":[{"atb":[[1.13,30.37]],"id":53432239},{"atb":[[1.09,0]],"id":47370245}],"con":true,"img":false}]}
{"op":"mcm","clk":"11540772672","pt":1719498229645,"mc":[{"id":"1.230180121","rc":[{"atb":[[1.28,33.84]],"id":69112387}],"con":true,"img":false}]}
{"op":"mcm","clk":"11540772690","pt":1719498229845,"mc":[{"id":"1.230180121","rc":[{"atb":[[1.13,30.37]],"id":62847579}],"con":true,"img":false}]}
{"op":"mcm","clk":"11540772719","pt":1719498230153,"mc":[{"id":"1.230180121","rc":[{"atb":[[1.13,30.37]],"id":47370245}],"con":true,"img":false}]}
{"op":"mcm","clk":"11540772751","pt":1719498230524,"mc":[{"id":"1.230180121","rc":[{"atb":[[1.13,30.37]],"id":64253834}],"con":true,"img":false}]}
{"op":"mcm","clk":"11540775059","pt":1719498252957,"mc":[{"id":"1.230180121","rc":[{"atb":[[1.25,0],[1.26,0]],"id":69112387}],"con":true,"img":false}]}
{"op":"mcm","clk":"11540775089","pt":1719498253266,"mc":[{"id":"1.230180121","rc":[{"atb":[[1.11,0]],"id":53432239},{"atb":[[1.11,0]],"id":47370245}],"con":true,"img":false}]}
{"op":"mcm","clk":"11540775124","pt":1719498253582,"mc":[{"id":"1.230180121","rc":[{"atb":[[1.11,0]],"id":62847579},{"atb":[[1.11,0]],"id":64253834}],"con":true,"img":false}]}
{"op":"mcm","clk":"11540775196","pt":1719498254265,"mc":[{"id":"1.230180121","rc":[{"atb":[[1.3,19.75]],"id":69112387}],"con":true,"img":false}]}
{"op":"mcm","clk":"11540775205","pt":1719498254355,"mc":[{"id":"1.230180121","rc":[{"atb":[[1.15,28.21]],"id":47370245}],"con":true,"img":false}]}
{"op":"mcm","clk":"11540775225","pt":1719498254558,"mc":[{"id":"1.230180121","rc":[{"atb":[[1.3,33.86]],"id":69112387}],"con":true,"img":false}]}
{"op":"mcm","clk":"11540775234","pt":1719498254671,"mc":[{"id":"1.230180121","rc":[{"atb":[[1.15,28.21]],"id":62847579}],"con":true,"img":false}]}
{"op":"mcm","clk":"11540775256","pt":1719498254882,"mc":[{"id":"1.230180121","rc":[{"atb":[[1.15,28.21]],"id":53432239}],"con":true,"img":false}]}
{"op":"mcm","clk":"11540775265","pt":1719498254979,"mc":[{"id":"1.230180121","rc":[{"atb":[[1.15,28.21]],"id":64253834}],"con":true,"img":false}]}
{"op":"mcm","clk":"11540776351","pt":1719498265999,"mc":[{"id":"1.230180121","rc":[{"atb":[[1.28,14.1]],"id":69112387}],"con":true,"img":false}]}
{"op":"mcm","clk":"11540776361","pt":1719498266055,"mc":[{"id":"1.230180121","rc":[{"atb":[[1.13,0]],"id":47370245}],"con":true,"img":false}]}
{"op":"mcm","clk":"11540776369","pt":1719498266162,"mc":[{"id":"1.230180121","rc":[{"atb":[[1.13,0]],"id":53432239}],"con":true,"img":false}]}
{"op":"mcm","clk":"11540776392","pt":1719498266466,"mc":[{"id":"1.230180121","rc":[{"atb":[[1.28,0]],"id":69112387}],"con":true,"img":false}]}
{"op":"mcm","clk":"11540776413","pt":1719498266664,"mc":[{"id":"1.230180121","rc":[{"atb":[[1.13,0]],"id":64253834}],"con":true,"img":false}]}
{"op":"mcm","clk":"11540776427","pt":1719498266788,"mc":[{"id":"1.230180121","rc":[{"atb":[[1.17,23.22]],"id":53432239}],"con":true,"img":false}]}
{"op":"mcm","clk":"11540776466","pt":1719498267190,"mc":[{"id":"1.230180121","rc":[{"atb":[[1.32,17.27]],"id":69112387}],"con":true,"img":false}]}
{"op":"mcm","clk":"11540776510","pt":1719498267647,"mc":[{"id":"1.230180121","rc":[{"atb":[[1.13,0]],"id":62847579},{"atb":[[1.17,23.22]],"id":64253834}],"con":true,"img":false}]}
{"op":"mcm","clk":"11540776574","pt":1719498268283,"mc":[{"id":"1.230180121","rc":[{"atb":[[1.17,23.22]],"id":62847579}],"con":true,"img":false}]}
{"op":"mcm","clk":"11540776601","pt":1719498268594,"mc":[{"id":"1.230180121","rc":[{"atb":[[1.32,29.61]],"id":69112387}],"con":true,"img":false}]}
{"op":"mcm","clk":"11540776625","pt":1719498268799,"mc":[{"id":"1.230180121","rc":[{"atb":[[1.17,23.22]],"id":47370245}],"con":true,"img":false}]}
{"op":"mcm","clk":"11540778948","pt":1719498289509,"mc":[{"id":"1.230180121","rc":[{"atb":[[1.15,0]],"id":47370245},{"atb":[[1.3,14.11]],"id":69112387},{"spn":38.16,"spf":"NaN","id":69112387}],"con":true,"img":false}]}
{"op":"mcm","clk":"11540778998","pt":1719498289917,"mc":[{"id":"1.230180121","rc":[{"atb":[[1.15,0]],"id":62847579},{"atb":[[1.15,0]],"id":53432239}],"con":true,"img":false}]}
{"op":"mcm","clk":"11540779036","pt":1719498290187,"mc":[{"id":"1.230180121","rc":[{"atb":[[1.34,17.43]],"id":69112387}],"con":true,"img":false}]}
{"op":"mcm","clk":"11540779070","pt":1719498290486,"mc":[{"id":"1.230180121","rc":[{"atb":[[1.15,0]],"id":64253834}],"con":true,"img":false}]}
{"op":"mcm","clk":"11540779082","pt":1719498290589,"mc":[{"id":"1.230180121","rc":[{"atb":[[1.19,22.28]],"id":47370245}],"con":true,"img":false}]}
{"op":"mcm","clk":"11540779108","pt":1719498290804,"mc":[{"id":"1.230180121","rc":[{"atb":[[1.19,22.28]],"id":53432239}],"con":true,"img":false}]}
{"op":"mcm","clk":"11540779123","pt":1719498290903,"mc":[{"id":"1.230180121","rc":[{"atb":[[1.19,22.28]],"id":62847579}],"con":true,"img":false}]}
{"op":"mcm","clk":"11540779174","pt":1719498291316,"mc":[{"id":"1.230180121","rc":[{"atb":[[1.19,22.28]],"id":64253834}],"con":true,"img":false}]}
{"op":"mcm","clk":"11540780655","pt":1719498306485,"mc":[{"id":"1.230180121","rc":[{"atb":[[1.32,12.33]],"id":69112387}],"con":true,"img":false}]}
{"op":"mcm","clk":"11540780666","pt":1719498306588,"mc":[{"id":"1.230180121","rc":[{"atb":[[1.17,0]],"id":64253834}],"con":true,"img":false}]}
{"op":"mcm","clk":"11540780690","pt":1719498306795,"mc":[{"id":"1.230180121","rc":[{"atb":[[1.17,0]],"id":47370245}],"con":true,"img":false}]}
{"op":"mcm","clk":"11540780737","pt":1719498307310,"mc":[{"id":"1.230180121","rc":[{"atb":[[1.17,0]],"id":62847579}],"con":true,"img":false}]}
{"op":"mcm","clk":"11540780751","pt":1719498307423,"mc":[{"id":"1.230180121","rc":[{"atb":[[1.21,18.8]],"id":64253834}],"con":true,"img":false}]}
{"op":"mcm","clk":"11540780789","pt":1719498307726,"mc":[{"id":"1.230180121","rc":[{"atb":[[1.21,18.8]],"id":62847579}],"con":true,"img":false}]}
{"op":"mcm","clk":"11540780802","pt":1719498307831,"mc":[{"id":"1.230180121","rc":[{"atb":[[1.17,0]],"id":53432239}],"con":true,"img":false}]}
{"op":"mcm","clk":"11540780809","pt":1719498307931,"mc":[{"id":"1.230180121","rc":[{"atb":[[1.36,15.35]],"id":69112387}],"con":true,"img":false}]}
{"op":"mcm","clk":"11540780837","pt":1719498308089,"mc":[{"id":"1.230180121","rc":[{"atb":[[1.21,18.8]],"id":53432239},{"atb":[[1.21,18.8]],"id":47370245}],"con":true,"img":false}]}
{"op":"mcm","clk":"11540782885","pt":1719498328024,"mc":[{"id":"1.230180121","rc":[{"atb":[[1.19,0]],"id":47370245},{"atb":[[1.34,0]],"id":69112387}],"con":true,"img":false}]}
{"op":"mcm","clk":"11540782914","pt":1719498328330,"mc":[{"id":"1.230180121","rc":[{"atb":[[1.19,0]],"id":62847579},{"atb":[[1.19,0]],"id":53432239}],"con":true,"img":false}]}
{"op":"mcm","clk":"11540782945","pt":1719498328652,"mc":[{"id":"1.230180121","rc":[{"atb":[[1.23,18.4]],"id":47370245},{"atb":[[1.19,0]],"id":64253834}],"con":true,"img":false}]}
{"op":"mcm","clk":"11540782977","pt":1719498328950,"mc":[{"id":"1.230180121","rc":[{"atb":[[1.38,15.59]],"id":69112387}],"con":true,"img":false}]}
{"op":"mcm","clk":"11540783034","pt":1719498329420,"mc":[{"id":"1.230180121","rc":[{"atb":[[1.23,18.4]],"id":62847579}],"con":true,"img":false}]}
{"op":"mcm","clk":"11540783045","pt":1719498329526,"mc":[{"id":"1.230180121","rc":[{"atb":[[1.23,18.4]],"id":53432239}],"con":true,"img":false}]}
{"op":"mcm","clk":"11540783069","pt":1719498329732,"mc":[{"id":"1.230180121","rc":[{"atb":[[1.23,18.4]],"id":64253834}],"con":true,"img":false}]}
{"op":"mcm","clk":"11540784507","pt":1719498344765,"mc":[{"id":"1.230180121","rc":[{"atb":[[1.21,0]],"id":47370245}],"con":true,"img":false}]}
{"op":"mcm","clk":"11540784546","pt":1719498345170,"mc":[{"id":"1.230180121","rc":[{"atb":[[1.25,15.79]],"id":47370245}],"con":true,"img":false}]}
{"op":"mcm","clk":"11540784553","pt":1719498345274,"mc":[{"id":"1.230180121","rc":[{"atb":[[1.21,0]],"id":53432239}],"con":true,"img":false}]}
{"op":"mcm","clk":"11540784565","pt":1719498345328,"mc":[{"id":"1.230180121","rc":[{"atb":[[1.21,0]],"id":64253834}],"con":true,"img":false}]}
{"op":"mcm","clk":"11540784606","pt":1719498345748,"mc":[{"id":"1.230180121","rc":[{"atb":[[1.21,0]],"id":62847579},{"atb":[[1.25,15.79]],"id":64253834}],"con":true,"img":false}]}
{"op":"mcm","clk":"11540784627","pt":1719498345947,"mc":[{"id":"1.230180121","rc":[{"atb":[[1.25,15.79]],"id":53432239}],"con":true,"img":false}]}
{"op":"mcm","clk":"11540784656","pt":1719498346257,"mc":[{"id":"1.230180121","rc":[{"atb":[[1.25,15.79]],"id":62847579}],"con":true,"img":false}]}
{"op":"mcm","clk":"11540786332","pt":1719498364061,"mc":[{"id":"1.230180121","rc":[{"spn":38.12,"spf":"NaN","id":62847579},{"spn":38.12,"spf":"NaN","id":53432239},{"atb":[[1.23,0]],"id":47370245},{"spn":38.12,"spf":"NaN","id":47370245},{"spn":38.19,"spf":"NaN","id":69112387},{"spn":38.12,"spf":"NaN","id":64253834}],"con":true,"img":false}]}
{"op":"mcm","clk":"11540786346","pt":1719498364267,"mc":[{"id":"1.230180121","rc":[{"atb":[[1.23,0]],"id":62847579}],"con":true,"img":false}]}
{"op":"mcm","clk":"11540786353","pt":1719498364375,"mc":[{"id":"1.230180121","rc":[{"atb":[[1.23,0]],"id":64253834}],"con":true,"img":false}]}
{"op":"mcm","clk":"11540786374","pt":1719498364861,"mc":[{"id":"1.230180121","rc":[{"atb":[[1.23,0]],"id":53432239}],"con":true,"img":false}]}
{"op":"mcm","clk":"11540786396","pt":1719498365138,"mc":[{"id":"1.230180121","rc":[{"atb":[[1.27,15.67]],"id":64253834}],"con":true,"img":false}]}
{"op":"mcm","clk":"11540786427","pt":1719498365432,"mc":[{"id":"1.230180121","rc":[{"atb":[[1.27,15.67]],"id":53432239}],"con":true,"img":false}]}
{"op":"mcm","clk":"11540786440","pt":1719498365444,"mc":[{"id":"1.230180121","rc":[{"atb":[[1.27,15.67]],"id":62847579}],"con":true,"img":false}]}
{"op":"mcm","clk":"11540786454","pt":1719498365611,"mc":[{"id":"1.230180121","rc":[{"atb":[[1.27,15.67]],"id":47370245}],"con":true,"img":false}]}
{"op":"mcm","clk":"11540787769","pt":1719498380213,"mc":[{"id":"1.230180121","rc":[{"atb":[[1.32,0]],"id":69112387}],"con":true,"img":false}]}
{"op":"mcm","clk":"11540787820","pt":1719498381002,"mc":[{"id":"1.230180121","rc":[{"atb":[[1.25,0]],"id":53432239},{"atb":[[1.25,0]],"id":47370245}],"con":true,"img":false}]}
{"op":"mcm","clk":"11540787838","pt":1719498381257,"mc":[{"id":"1.230180121","rc":[{"atb":[[1.25,0]],"id":62847579},{"atb":[[1.25,0]],"id":64253834}],"con":true,"img":false}]}
{"op":"mcm","clk":"11540787882","pt":1719498381678,"mc":[{"id":"1.230180121","rc":[{"atb":[[1.29,13.61]],"id":62847579},{"atb":[[1.29,13.61]],"id":64253834}],"con":true,"img":false}]}
{"op":"mcm","clk":"11540787896","pt":1719498381882,"mc":[{"id":"1.230180121","rc":[{"atb":[[1.29,13.61]],"id":53432239},{"atb":[[1.29,13.61]],"id":47370245}],"con":true,"img":false}]}
{"op":"mcm","clk":"11540789186","pt":1719498397513,"mc":[{"id":"1.230180121","rc":[{"atb":[[1.3,0]],"id":69112387}],"con":true,"img":false}]}
{"op":"mcm","clk":"11540789425","pt":1719498400120,"mc":[{"id":"1.230180121","rc":[{"atb":[[1.27,0]],"id":47370245}],"con":true,"img":false}]}
{"op":"mcm","clk":"11540789435","pt":1719498400223,"mc":[{"id":"1.230180121","rc":[{"atb":[[1.27,0]],"id":53432239}],"con":true,"img":false}]}
{"op":"mcm","clk":"11540789455","pt":1719498400386,"mc":[{"id":"1.230180121","rc":[{"atb":[[1.27,0]],"id":62847579}],"con":true,"img":false}]}
{"op":"mcm","clk":"11540789480","pt":1719498400595,"mc":[{"id":"1.230180121","rc":[{"atb":[[1.27,0]],"id":64253834}],"con":true,"img":false}]}
{"op":"mcm","clk":"11540789509","pt":1719498400902,"mc":[{"id":"1.230180121","rc":[{"atb":[[1.31,13.65]],"id":53432239}],"con":true,"img":false}]}
{"op":"mcm","clk":"11540789528","pt":1719498401110,"mc":[{"id":"1.230180121","rc":[{"atb":[[1.31,13.65]],"id":62847579}],"con":true,"img":false}]}
{"op":"mcm","clk":"11540789592","pt":1719498401685,"mc":[{"id":"1.230180121","rc":[{"atb":[[1.31,13.65]],"id":47370245},{"atb":[[1.31,13.65]],"id":64253834}],"con":true,"img":false}]}
{"op":"mcm","clk":"11540790234","pt":1719498409031,"mc":[{"id":"1.230180121","rc":[{"atb":[[1.36,0]],"id":69112387}],"con":true,"img":false}]}
{"op":"mcm","clk":"11540790878","pt":1719498417041,"mc":[{"id":"1.230180121","rc":[{"atb":[[1.29,0]],"id":47370245}],"con":true,"img":false}]}
{"op":"mcm","clk":"11540790885","pt":1719498417145,"mc":[{"id":"1.230180121","rc":[{"atb":[[1.29,0]],"id":64253834}],"con":true,"img":false}]}
{"op":"mcm","clk":"11540790893","pt":1719498417242,"mc":[{"id":"1.230180121","rc":[{"atb":[[1.29,0]],"id":62847579}],"con":true,"img":false}]}
{"op":"mcm","clk":"11540790911","pt":1719498417452,"mc":[{"id":"1.230180121","rc":[{"atb":[[1.29,0]],"id":53432239}],"con":true,"img":false}]}
{"op":"mcm","clk":"11540790935","pt":1719498417714,"mc":[{"id":"1.230180121","rc":[{"atb":[[1.33,11.96]],"id":53432239},{"atb":[[1.33,11.96]],"id":47370245}],"con":true,"img":false}]}
{"op":"mcm","clk":"11540790960","pt":1719498417919,"mc":[{"id":"1.230180121","rc":[{"atb":[[1.33,11.96]],"id":62847579}],"con":true,"img":false}]}
{"op":"mcm","clk":"11540790980","pt":1719498418131,"mc":[{"id":"1.230180121","rc":[{"atb":[[1.33,11.96]],"id":64253834}],"con":true,"img":false}]}
{"op":"mcm","clk":"11540793434","pt":1719498443847,"mc":[{"id":"1.230180121","rc":[{"spn":38.16,"spf":"NaN","id":62847579},{"atb":[[1.31,0]],"id":53432239},{"spn":38.16,"spf":"NaN","id":53432239},{"atb":[[1.31,0]],"id":47370245},{"spn":38.16,"spf":"NaN","id":47370245},{"spn":38.16,"spf":"NaN","id":64253834}],"con":true,"img":false}]}
{"op":"mcm","clk":"11540793461","pt":1719498444162,"mc":[{"id":"1.230180121","rc":[{"atb":[[1.31,0]],"id":62847579},{"atb":[[1.31,0]],"id":64253834}],"con":true,"img":false}]}
{"op":"mcm","clk":"11540793497","pt":1719498444465,"mc":[{"id":"1.230180121","rc":[{"atb":[[1.35,12.09]],"id":53432239}],"con":true,"img":false}]}
{"op":"mcm","clk":"11540793506","pt":1719498444569,"mc":[{"id":"1.230180121","rc":[{"atb":[[1.35,12.09]],"id":47370245}],"con":true,"img":false}]}
{"op":"mcm","clk":"11540793524","pt":1719498444777,"mc":[{"id":"1.230180121","rc":[{"atb":[[1.35,12.09]],"id":64253834}],"con":true,"img":false}]}
{"op":"mcm","clk":"11540793533","pt":1719498444879,"mc":[{"id":"1.230180121","rc":[{"atb":[[1.35,12.09]],"id":62847579}],"con":true,"img":false}]}
{"op":"mcm","clk":"11540794302","pt":1719498453262,"mc":[{"id":"1.230180121","rc":[{"atb":[[1.33,0]],"id":62847579},{"atb":[[1.33,0]],"id":47370245}],"con":true,"img":false}]}
{"op":"mcm","clk":"11540794322","pt":1719498453474,"mc":[{"id":"1.230180121","rc":[{"atb":[[1.33,0]],"id":53432239},{"atb":[[1.33,0]],"id":64253834}],"con":true,"img":false}]}
{"op":"mcm","clk":"11540794341","pt":1719498453678,"mc":[{"id":"1.230180121","rc":[{"atb":[[1.37,10.66]],"id":47370245}],"con":true,"img":false}]}
{"op":"mcm","clk":"11540794349","pt":1719498453787,"mc":[{"id":"1.230180121","rc":[{"atb":[[1.37,10.66]],"id":62847579}],"con":true,"img":false}]}
{"op":"mcm","clk":"11540794357","pt":1719498453894,"mc":[{"id":"1.230180121","rc":[{"atb":[[1.37,10.66]],"id":64253834}],"con":true,"img":false}]}
{"op":"mcm","clk":"11540794372","pt":1719498453995,"mc":[{"id":"1.230180121","rc":[{"atb":[[1.37,10.66]],"id":53432239}],"con":true,"img":false}]}
{"op":"mcm","clk":"11540797118","pt":1719498483991,"mc":[{"id":"1.230180121","rc":[{"atb":[[1.35,0]],"id":53432239},{"atb":[[1.35,0]],"id":47370245}],"con":true,"img":false}]}
{"op":"mcm","clk":"11540797153","pt":1719498484407,"mc":[{"id":"1.230180121","rc":[{"atb":[[1.35,0]],"id":62847579},{"atb":[[1.35,0]],"id":64253834}],"con":true,"img":false}]}
{"op":"mcm","clk":"11540797181","pt":1719498484712,"mc":[{"id":"1.230180121","rc":[{"atb":[[1.39,10.85]],"id":53432239},{"atb":[[1.39,10.85]],"id":47370245}],"con":true,"img":false}]}
{"op":"mcm","clk":"11540797203","pt":1719498485021,"mc":[{"id":"1.230180121","rc":[{"atb":[[1.39,10.85]],"id":64253834}],"con":true,"img":false}]}
{"op":"mcm","clk":"11540797230","pt":1719498485337,"mc":[{"id":"1.230180121","rc":[{"atb":[[1.39,10.85]],"id":62847579}],"con":true,"img":false}]}
{"op":"mcm","clk":"11540797486","pt":1719498488197,"mc":[{"id":"1.230180121","rc":[{"atb":[[1.37,0]],"id":53432239},{"atb":[[1.37,0]],"id":47370245}],"con":true,"img":false}]}
{"op":"mcm","clk":"11540797505","pt":1719498488408,"mc":[{"id":"1.230180121","rc":[{"atb":[[1.37,0]],"id":62847579},{"atb":[[1.37,0]],"id":64253834}],"con":true,"img":false}]}
{"op":"mcm","clk":"11540797520","pt":1719498488610,"mc":[{"id":"1.230180121","rc":[{"atb":[[1.41,9.63]],"id":53432239},{"atb":[[1.41,9.63]],"id":47370245}],"con":true,"img":false}]}
{"op":"mcm","clk":"11540797537","pt":1719498488816,"mc":[{"id":"1.230180121","rc":[{"atb":[[1.41,9.63]],"id":62847579},{"atb":[[1.41,9.63]],"id":64253834}],"con":true,"img":false}]}
{"op":"mcm","clk":"11540799484","pt":1719498509140,"mc":[{"id":"1.230180121","rc":[{"spn":38.2,"spf":"NaN","id":62847579},{"spn":38.2,"spf":"NaN","id":53432239},{"spn":38.2,"spf":"NaN","id":47370245},{"atb":[[1.38,0]],"id":69112387},{"spn":38.1,"spf":"NaN","id":69112387},{"spn":38.2,"spf":"NaN","id":64253834}],"con":true,"img":false}]}
{"op":"mcm","clk":"11540800658","pt":1719498522649,"mc":[{"id":"1.230180121","rc":[{"atb":[[1.39,0]],"id":47370245}],"con":true,"img":false}]}
{"op":"mcm","clk":"11540800690","pt":1719498523073,"mc":[{"id":"1.230180121","rc":[{"atb":[[1.39,0]],"id":53432239}],"con":true,"img":false}]}
{"op":"mcm","clk":"11540800706","pt":1719498523274,"mc":[{"id":"1.230180121","rc":[{"atb":[[1.39,0]],"id":62847579}],"con":true,"img":false}]}
{"op":"mcm","clk":"11540800714","pt":1719498523375,"mc":[{"id":"1.230180121","rc":[{"atb":[[1.39,0]],"id":64253834}],"con":true,"img":false}]}
{"op":"mcm","clk":"11540800733","pt":1719498523580,"mc":[{"id":"1.230180121","rc":[{"atb":[[1.09,47.03]],"id":69112387}],"con":true,"img":false}]}
{"op":"mcm","clk":"11540800738","pt":1719498523676,"mc":[{"id":"1.230180121","rc":[{"atb":[[1.43,9.84]],"id":47370245}],"con":true,"img":false}]}
{"op":"mcm","clk":"11540800753","pt":1719498523830,"mc":[{"id":"1.230180121","rc":[{"atb":[[1.43,9.84]],"id":53432239}],"con":true,"img":false}]}
{"op":"mcm","clk":"11540800775","pt":1719498524140,"mc":[{"id":"1.230180121","rc":[{"atb":[[1.43,9.84]],"id":64253834}],"con":true,"img":false}]}
{"op":"mcm","clk":"11540800799","pt":1719498524461,"mc":[{"id":"1.230180121","rc":[{"atb":[[1.43,9.84]],"id":62847579}],"con":true,"img":false}]}
{"op":"mcm","clk":"11540801337","pt":1719498530563,"mc":[{"id":"1.230180121","rc":[{"atb":[[1.41,0]],"id":47370245},{"atb":[[1.1,55.27]],"id":69112387}],"con":true,"img":false}]}
{"op":"mcm","clk":"11540801352","pt":1719498530762,"mc":[{"id":"1.230180121","rc":[{"atb":[[1.41,0]],"id":62847579},{"atb":[[1.41,0]],"id":64253834}],"con":true,"img":false}]}
{"op":"mcm","clk":"11540801370","pt":1719498530972,"mc":[{"id":"1.230180121","rc":[{"atb":[[1.41,0]],"id":53432239},{"atb":[[1.45,8.77]],"id":47370245}],"con":true,"img":false}]}
{"op":"mcm","clk":"11540801388","pt":1719498531182,"mc":[{"id":"1.230180121","rc":[{"atb":[[1.11,35.89]],"id":69112387},{"atb":[[1.45,8.77]],"id":64253834}],"con":true,"img":false}]}
{"op":"mcm","clk":"11540801407","pt":1719498531381,"mc":[{"id":"1.230180121","rc":[{"atb":[[1.45,8.77]],"id":62847579},{"atb":[[1.45,8.77]],"id":53432239}],"con":true,"img":false}]}
{"op":"mcm","clk":"11540804615","pt":1719498565686,"mc":[{"id":"1.230180121","rc":[{"atb":[[1.12,49.38]],"id":69112387}],"con":true,"img":false}]}
{"op":"mcm","clk":"11540804622","pt":1719498565789,"mc":[{"id":"1.230180121","rc":[{"atb":[[1.43,0]],"id":47370245}],"con":true,"img":false}]}
{"op":"mcm","clk":"11540804642","pt":1719498566097,"mc":[{"id":"1.230180121","rc":[{"atb":[[1.43,0]],"id":62847579},{"atb":[[1.43,0]],"id":53432239}],"con":true,"img":false}]}
{"op":"mcm","clk":"11540804664","pt":1719498566407,"mc":[{"id":"1.230180121","rc":[{"atb":[[1.47,9]],"id":47370245},{"atb":[[1.09,0]],"id":69112387}],"con":true,"img":false}]}
{"op":"mcm","clk":"11540804690","pt":1719498566725,"mc":[{"id":"1.230180121","rc":[{"atb":[[1.47,9]],"id":53432239}],"con":true,"img":false}]}
{"op":"mcm","clk":"11540804717","pt":1719498567040,"mc":[{"id":"1.230180121","rc":[{"atb":[[1.43,0]],"id":64253834}],"con":true,"img":false}]}
{"op":"mcm","clk":"11540804738","pt":1719498567291,"mc":[{"id":"1.230180121","rc":[{"atb":[[1.47,9]],"id":64253834}],"con":true,"img":false}]}
{"op":"mcm","clk":"11540804745","pt":1719498567391,"mc":[{"id":"1.230180121","rc":[{"atb":[[1.47,9]],"id":62847579}],"con":true,"img":false}]}
{"op":"mcm","clk":"11540804757","pt":1719498567593,"mc":[{"id":"1.230180121","rc":[{"atb":[[1.1,0]],"id":69112387}],"con":true,"img":false}]}
{"op":"mcm","clk":"11540804765","pt":1719498567697,"mc":[{"id":"1.230180121","rc":[{"atb":[[1.13,32.56]],"id":69112387}],"con":true,"img":false}]}
{"op":"mcm","clk":"11540804776","pt":1719498567897,"mc":[{"id":"1.230180121","rc":[{"atb":[[1.45,0]],"id":47370245},{"atb":[[1.11,0]],"id":69112387}],"con":true,"img":false}]}
{"op":"mcm","clk":"11540804793","pt":1719498568107,"mc":[{"id":"1.230180121","rc":[{"atb":[[1.45,0]],"id":53432239},{"atb":[[1.13,75.08]],"id":69112387}],"con":true,"img":false}]}
{"op":"mcm","clk":"11540804810","pt":1719498568308,"mc":[{"id":"1.230180121","rc":[{"atb":[[1.49,8.05]],"id":47370245},{"atb":[[1.14,28.2]],"id":69112387}],"con":true,"img":false}]}
{"op":"mcm","clk":"11540804821","pt":1719498568521,"mc":[{"id":"1.230180121","rc":[{"atb":[[1.49,8.05]],"id":53432239}],"con":true,"img":false}]}
{"op":"mcm","clk":"11540806410","pt":1719498584915,"mc":[{"id":"1.230180121","rc":[{"spn":38.23,"spf":"NaN","id":62847579},{"spn":38.24,"spf":"NaN","id":53432239},{"spn":38.24,"spf":"NaN","id":47370245},{"atb":[[1.13,32.56]],"id":69112387},{"spn":38.23,"spf":"NaN","id":64253834}],"con":true,"img":false}]}
{"op":"mcm","clk":"11540806416","pt":1719498585022,"mc":[{"id":"1.230180121","rc":[{"atb":[[1.45,0]],"id":62847579}],"con":true,"img":false}]}
{"op":"mcm","clk":"11540806427","pt":1719498585125,"mc":[{"id":"1.230180121","rc":[{"atb":[[1.14,0]],"id":69112387}],"con":true,"img":false}]}
{"op":"mcm","clk":"11540806437","pt":1719498585225,"mc":[{"id":"1.230180121","rc":[{"atb":[[1.14,39.48]],"id":69112387}],"con":true,"img":false}]}
{"op":"mcm","clk":"11540806450","pt":1719498585328,"mc":[{"id":"1.230180121","rc":[{"atb":[[1.45,0]],"id":64253834}],"con":true,"img":false}]}
{"op":"mcm","clk":"11540806462","pt":1719498585432,"mc":[{"id":"1.230180121","rc":[{"atb":[[1.49,8.05]],"id":62847579}],"con":true,"img":false}]}
{"op":"mcm","clk":"11540806474","pt":1719498585536,"mc":[{"id":"1.230180121","rc":[{"atb":[[1.15,26.32]],"id":69112387}],"con":true,"img":false}]}
{"op":"mcm","clk":"11540806494","pt":1719498585759,"mc":[{"id":"1.230180121","rc":[{"atb":[[1.49,8.05]],"id":64253834}],"con":true,"img":false}]}
{"op":"mcm","clk":"11540808291","pt":1719498603524,"mc":[{"id":"1.230180121","rc":[{"atb":[[1.47,0]],"id":47370245},{"atb":[[1.12,0]],"id":69112387}],"con":true,"img":false}]}
{"op":"mcm","clk":"11540808326","pt":1719498603935,"mc":[{"id":"1.230180121","rc":[{"atb":[[1.47,0]],"id":53432239}],"con":true,"img":false}]}
{"op":"mcm","clk":"11540808345","pt":1719498604140,"mc":[{"id":"1.230180121","rc":[{"atb":[[1.47,0]],"id":62847579}],"con":true,"img":false}]}
{"op":"mcm","clk":"11540808363","pt":1719498604349,"mc":[{"id":"1.230180121","rc":[{"atb":[[1.13,0]],"id":69112387}],"con":true,"img":false}]}
{"op":"mcm","clk":"11540808373","pt":1719498604453,"mc":[{"id":"1.230180121","rc":[{"atb":[[1.51,8.29]],"id":53432239}],"con":true,"img":false}]}
{"op":"mcm","clk":"11540808395","pt":1719498604657,"mc":[{"id":"1.230180121","rc":[{"atb":[[1.51,8.29]],"id":47370245}],"con":true,"img":false}]}
{"op":"mcm","clk":"11540808406","pt":1719498604761,"mc":[{"id":"1.230180121","rc":[{"atb":[[1.51,8.29]],"id":62847579}],"con":true,"img":false}]}
{"op":"mcm","clk":"11540808446","pt":1719498605126,"mc":[{"id":"1.230180121","rc":[{"atb":[[1.47,0]],"id":64253834}],"con":true,"img":false}]}
{"op":"mcm","clk":"11540808458","pt":1719498605229,"mc":[{"id":"1.230180121","rc":[{"atb":[[1.16,37.03]],"id":69112387}],"con":true,"img":false}]}
{"op":"mcm","clk":"11540808493","pt":1719498605548,"mc":[{"id":"1.230180121","rc":[{"atb":[[1.17,24.89]],"id":69112387}],"con":true,"img":false}]}
{"op":"mcm","clk":"11540808537","pt":1719498605958,"mc":[{"id":"1.230180121","rc":[{"atb":[[1.51,8.29]],"id":64253834}],"con":true,"img":false}]}
{"op":"mcm","clk":"11540809964","pt":1719498620763,"mc":[{"id":"1.230180121","rc":[{"atb":[[1.49,0]],"id":47370245}],"con":true,"img":false}]}
{"op":"mcm","clk":"11540809987","pt":1719498620970,"mc":[{"id":"1.230180121","rc":[{"atb":[[1.14,0]],"id":69112387}],"con":true,"img":false}]}
{"op":"mcm","clk":"11540810006","pt":1719498621175,"mc":[{"id":"1.230180121","rc":[{"atb":[[1.49,0]],"id":53432239},{"atb":[[1.15,0]],"id":69112387}],"con":true,"img":false}]}
{"op":"mcm","clk":"11540810027","pt":1719498621383,"mc":[{"id":"1.230180121","rc":[{"atb":[[1.49,0]],"id":62847579}],"con":true,"img":false}]}
{"op":"mcm","clk":"11540810036","pt":1719498621442,"mc":[{"id":"1.230180121","rc":[{"atb":[[1.53,7.44]],"id":47370245}],"con":true,"img":false}]}
{"op":"mcm","clk":"11540810048","pt":1719498621551,"mc":[{"id":"1.230180121","rc":[{"atb":[[1.49,0]],"id":64253834}],"con":true,"img":false}]}
{"op":"mcm","clk":"11540810058","pt":1719498621643,"mc":[{"id":"1.230180121","rc":[{"atb":[[1.53,7.44]],"id":62847579}],"con":true,"img":false}]}
{"op":"mcm","clk":"11540810069","pt":1719498621749,"mc":[{"id":"1.230180121","rc":[{"atb":[[1.19,20.78]],"id":69112387}],"con":true,"img":false}]}
{"op":"mcm","clk":"11540810081","pt":1719498621851,"mc":[{"id":"1.230180121","rc":[{"atb":[[1.18,30.71]],"id":69112387}],"con":true,"img":false}]}
{"op":"mcm","clk":"11540810093","pt":1719498621955,"mc":[{"id":"1.230180121","rc":[{"atb":[[1.53,7.44]],"id":64253834}],"con":true,"img":false}]}
{"op":"mcm","clk":"11540810112","pt":1719498622165,"mc":[{"id":"1.230180121","rc":[{"atb":[[1.53,7.44]],"id":53432239}],"con":true,"img":false}]}
{"op":"mcm","clk":"11540812615","pt":1719498646872,"mc":[{"id":"1.230180121","rc":[{"spn":38.26,"spf":"NaN","id":62847579},{"spn":38.26,"spf":"NaN","id":53432239},{"spn":38.26,"spf":"NaN","id":47370245},{"atb":[[1.16,0],[1.17,0]],"id":69112387},{"spn":38.26,"spf":"NaN","id":64253834}],"con":true,"img":false}]}
{"op":"mcm","clk":"11540812640","pt":1719498647182,"mc":[{"id":"1.230180121","rc":[{"atb":[[1.51,0]],"id":47370245}],"con":true,"img":false}]}
{"op":"mcm","clk":"11540812668","pt":1719498647494,"mc":[{"id":"1.230180121","rc":[{"atb":[[1.51,0]],"id":64253834}],"con":true,"img":false}]}
{"op":"mcm","clk":"11540812690","pt":1719498647701,"mc":[{"id":"1.230180121","rc":[{"atb":[[1.55,7.69]],"id":47370245}],"con":true,"img":false}]}
{"op":"mcm","clk":"11540812704","pt":1719498647910,"mc":[{"id":"1.230180121","rc":[{"atb":[[1.51,0]],"id":53432239}],"con":true,"img":false}]}
{"op":"mcm","clk":"11540812714","pt":1719498648018,"mc":[{"id":"1.230180121","rc":[{"atb":[[1.2,29.88]],"id":69112387}],"con":true,"img":false}]}
{"op":"mcm","clk":"11540812735","pt":1719498648170,"mc":[{"id":"1.230180121","rc":[{"atb":[[1.21,20.15]],"id":69112387}],"con":true,"img":false}]}
{"op":"mcm","clk":"11540812746","pt":1719498648276,"mc":[{"id":"1.230180121","rc":[{"atb":[[1.51,0]],"id":62847579}],"con":true,"img":false}]}
{"op":"mcm","clk":"11540812763","pt":1719498648485,"mc":[{"id":"1.230180121","rc":[{"atb":[[1.55,7.69]],"id":64253834}],"con":true,"img":false}]}
{"op":"mcm","clk":"11540812793","pt":1719498648806,"mc":[{"id":"1.230180121","rc":[{"atb":[[1.55,7.69]],"id":62847579},{"atb":[[1.55,7.69]],"id":53432239}],"con":true,"img":false}]}
{"op":"mcm","clk":"11540813625","pt":1719498657827,"mc":[{"id":"1.230180121","rc":[{"atb":[[1.18,0]],"id":69112387}],"con":true,"img":false}]}
{"op":"mcm","clk":"11540813641","pt":1719498657980,"mc":[{"id":"1.230180121","rc":[{"atb":[[1.53,0]],"id":47370245},{"atb":[[1.19,0]],"id":69112387}],"con":true,"img":false}]}
{"op":"mcm","clk":"11540813661","pt":1719498658186,"mc":[{"id":"1.230180121","rc":[{"atb":[[1.53,0]],"id":62847579},{"atb":[[1.53,0]],"id":53432239}],"con":true,"img":false}]}
{"op":"mcm","clk":"11540813681","pt":1719498658393,"mc":[{"id":"1.230180121","rc":[{"atb":[[1.22,25.12]],"id":69112387}],"con":true,"img":false}]}
{"op":"mcm","clk":"11540813690","pt":1719498658500,"mc":[{"id":"1.230180121","rc":[{"atb":[[1.53,0]],"id":64253834}],"con":true,"img":false}]}
{"op":"mcm","clk":"11540813699","pt":1719498658599,"mc":[{"id":"1.230180121","rc":[{"atb":[[1.57,6.92]],"id":47370245}],"con":true,"img":false}]}
{"op":"mcm","clk":"11540813707","pt":1719498658702,"mc":[{"id":"1.230180121","rc":[{"atb":[[1.57,6.92]],"id":62847579}],"con":true,"img":false}]}
{"op":"mcm","clk":"11540813713","pt":1719498658805,"mc":[{"id":"1.230180121","rc":[{"atb":[[1.23,17.16]],"id":69112387}],"con":true,"img":false}]}
{"op":"mcm","clk":"11540813722","pt":1719498658912,"mc":[{"id":"1.230180121","rc":[{"atb":[[1.57,6.92]],"id":53432239}],"con":true,"img":false}]}
{"op":"mcm","clk":"11540813736","pt":1719498659113,"mc":[{"id":"1.230180121","rc":[{"atb":[[1.57,6.92]],"id":64253834}],"con":true,"img":false}]}
{"op":"mcm","clk":"11540816277","pt":1719498686658,"mc":[{"id":"1.230180121","rc":[{"atb":[[1.2,0.25],[1.21,0]],"id":69112387}],"con":true,"img":false}]}
{"op":"mcm","clk":"11540816327","pt":1719498687015,"mc":[{"id":"1.230180121","rc":[{"atb":[[1.55,0]],"id":62847579}],"con":true,"img":false}]}
{"op":"mcm","clk":"11540816350","pt":1719498687331,"mc":[{"id":"1.230180121","rc":[{"atb":[[1.55,0]],"id":64253834}],"con":true,"img":false}]}
{"op":"mcm","clk":"11540816358","pt":1719498687437,"mc":[{"id":"1.230180121","rc":[{"atb":[[1.55,0]],"id":47370245}],"con":true,"img":false}]}
{"op":"mcm","clk":"11540816378","pt":1719498687742,"mc":[{"id":"1.230180121","rc":[{"atb":[[1.24,24.69]],"id":69112387}],"con":true,"img":false}]}
{"op":"mcm","clk":"11540816386","pt":1719498687848,"mc":[{"id":"1.230180121","rc":[{"atb":[[1.55,0]],"id":53432239}],"con":true,"img":false}]}
{"op":"mcm","clk":"11540816406","pt":1719498688050,"mc":[{"id":"1.230180121","rc":[{"atb":[[1.25,16.93]],"id":69112387}],"con":true,"img":false}]}
{"op":"mcm","clk":"11540816439","pt":1719498688367,"mc":[{"id":"1.230180121","rc":[{"atb":[[1.59,7.17]],"id":62847579}],"con":true,"img":false}]}
{"op":"mcm","clk":"11540816452","pt":1719498688414,"mc":[{"id":"1.230180121","rc":[{"atb":[[1.59,7.17]],"id":64253834}],"con":true,"img":false}]}
{"op":"mcm","clk":"11540816470","pt":1719498688625,"mc":[{"id":"1.230180121","rc":[{"atb":[[1.59,7.17]],"id":53432239}],"con":true,"img":false}]}
{"op":"mcm","clk":"11540816482","pt":1719498688728,"mc":[{"id":"1.230180121","rc":[{"atb":[[1.59,7.17]],"id":47370245}],"con":true,"img":false}]}
{"op":"mcm","clk":"11540816935","pt":1719498693944,"mc":[{"id":"1.230180121","rc":[{"atb":[[1.57,0]],"id":47370245}],"con":true,"img":false}]}
{"op":"mcm","clk":"11540816964","pt":1719498694254,"mc":[{"id":"1.230180121","rc":[{"atb":[[1.23,0],[1.22,0]],"id":69112387}],"con":true,"img":false}]}
{"op":"mcm","clk":"11540817008","pt":1719498694778,"mc":[{"id":"1.230180121","rc":[{"atb":[[1.57,0]],"id":53432239}],"con":true,"img":false}]}
{"op":"mcm","clk":"11540817018","pt":1719498694827,"mc":[{"id":"1.230180121","rc":[{"atb":[[1.57,0]],"id":64253834}],"con":true,"img":false}]}
{"op":"mcm","clk":"11540817027","pt":1719498694931,"mc":[{"id":"1.230180121","rc":[{"atb":[[1.57,0]],"id":62847579}],"con":true,"img":false}]}
{"op":"mcm","clk":"11540817060","pt":1719498695454,"mc":[{"id":"1.230180121","rc":[{"atb":[[1.61,6.47]],"id":47370245}],"con":true,"img":false}]}
{"op":"mcm","clk":"11540817098","pt":1719498695888,"mc":[{"id":"1.230180121","rc":[{"atb":[[1.27,14.62]],"id":69112387}],"con":true,"img":false}]}
{"op":"mcm","clk":"11540817117","pt":1719498696049,"mc":[{"id":"1.230180121","rc":[{"atb":[[1.27,35.1]],"id":69112387}],"con":true,"img":false}]}
{"op":"mcm","clk":"11540817160","pt":1719498696460,"mc":[{"id":"1.230180121","rc":[{"atb":[[1.61,6.47]],"id":62847579}],"con":true,"img":false}]}
{"op":"mcm","clk":"11540817181","pt":1719498696666,"mc":[{"id":"1.230180121","rc":[{"atb":[[1.61,6.47]],"id":53432239}],"con":true,"img":false}]}
{"op":"mcm","clk":"11540817190","pt":1719498696777,"mc":[{"id":"1.230180121","rc":[{"atb":[[1.61,6.47]],"id":64253834}],"con":true,"img":false}]}
{"op":"mcm","clk":"11540819864","pt":1719498726781,"mc":[{"id":"1.230180121","rc":[{"spn":38.3,"spf":"NaN","id":62847579},{"spn":38.3,"spf":"NaN","id":53432239},{"spn":38.3,"spf":"NaN","id":47370245},{"atb":[[1.24,0]],"id":69112387},{"spn":38.13,"spf":"NaN","id":69112387},{"spn":38.3,"spf":"NaN","id":64253834}],"con":true,"img":false}]}
{"op":"mcm","clk":"11540819922","pt":1719498727408,"mc":[{"id":"1.230180121","rc":[{"atb":[[1.59,0]],"id":47370245},{"atb":[[1.25,0]],"id":69112387}],"con":true,"img":false}]}
{"op":"mcm","clk":"11540819957","pt":1719498727816,"mc":[{"id":"1.230180121","rc":[{"atb":[[1.59,0]],"id":53432239}],"con":true,"img":false}]}
{"op":"mcm","clk":"11540819999","pt":1719498728285,"mc":[{"id":"1.230180121","rc":[{"atb":[[1.59,0]],"id":62847579}],"con":true,"img":false}]}
{"op":"mcm","clk":"11540820055","pt":1719498728801,"mc":[{"id":"1.230180121","rc":[{"atb":[[1.59,0]],"id":64253834}],"con":true,"img":false}]}
{"op":"mcm","clk":"11540820102","pt":1719498729319,"mc":[{"id":"1.230180121","rc":[{"atb":[[1.29,20.43]],"id":69112387}],"con":true,"img":false}]}
{"op":"mcm","clk":"11540820120","pt":1719498729525,"mc":[{"id":"1.230180121","rc":[{"atb":[[1.63,6.72]],"id":47370245}],"con":true,"img":false}]}
{"op":"mcm","clk":"11540820144","pt":1719498729783,"mc":[{"id":"1.230180121","rc":[{"atb":[[1.63,6.72]],"id":64253834}],"con":true,"img":false}]}
{"op":"mcm","clk":"11540820153","pt":1719498729887,"mc":[{"id":"1.230180121","rc":[{"atb":[[1.63,6.72]],"id":53432239}],"con":true,"img":false}]}
{"op":"mcm","clk":"11540820175","pt":1719498730094,"mc":[{"id":"1.230180121","rc":[{"atb":[[1.29,35.03]],"id":69112387}],"con":true,"img":false}]}
{"op":"mcm","clk":"11540820194","pt":1719498730301,"mc":[{"id":"1.230180121","rc":[{"atb":[[1.27,14.62]],"id":69112387}],"con":true,"img":false}]}
{"op":"mcm","clk":"11540820200","pt":1719498730404,"mc":[{"id":"1.230180121","rc":[{"atb":[[1.63,6.72]],"id":62847579}],"con":true,"img":false}]}
{"op":"mcm","clk":"11540820220","pt":1719498730622,"mc":[{"id":"1.230180121","rc":[{"atb":[[1.27,0]],"id":69112387}],"con":true,"img":false}]}
{"op":"mcm","clk":"11540820237","pt":1719498730826,"mc":[{"id":"1.230180121","rc":[{"atb":[[1.31,17.83]],"id":69112387},{"atb":[[1.61,0]],"id":64253834}],"con":true,"img":false}]}
{"op":"mcm","clk":"11540820257","pt":1719498731036,"mc":[{"id":"1.230180121","rc":[{"atb":[[1.31,30.56]],"id":69112387}],"con":true,"img":false}]}
{"op":"mcm","clk":"11540820278","pt":1719498731187,"mc":[{"id":"1.230180121","rc":[{"atb":[[1.65,6.07]],"id":64253834}],"con":true,"img":false}]}
{"op":"mcm","clk":"11540821390","pt":1719498747208,"mc":[{"id":"1.230180121","rc":[{"atb":[[1.61,0]],"id":62847579}],"con":true,"img":false}]}
{"op":"mcm","clk":"11540821401","pt":1719498747419,"mc":[{"id":"1.230180121","rc":[{"atb":[[1.65,6.07]],"id":62847579}],"con":true,"img":false}]}
{"op":"mcm","clk":"11540822668","pt":1719498766042,"mc":[{"id":"1.230180121","rc":[{"atb":[[1.29,14.59]],"id":69112387}],"con":true,"img":false}]}
{"op":"mcm","clk":"11540822674","pt":1719498766143,"mc":[{"id":"1.230180121","rc":[{"atb":[[1.29,0]],"id":69112387}],"con":true,"img":false}]}
{"op":"mcm","clk":"11540822695","pt":1719498766441,"mc":[{"id":"1.230180121","rc":[{"atb":[[1.63,0]],"id":62847579}],"con":true,"img":false}]}
{"op":"mcm","clk":"11540822701","pt":1719498766547,"mc":[{"id":"1.230180121","rc":[{"atb":[[1.63,0]],"id":64253834}],"con":true,"img":false}]}
{"op":"mcm","clk":"11540822707","pt":1719498766742,"mc":[{"id":"1.230180121","rc":[{"atb":[[1.33,17.95]],"id":69112387}],"con":true,"img":false}]}
{"op":"mcm","clk":"11540822713","pt":1719498767067,"mc":[{"id":"1.230180121","rc":[{"atb":[[1.67,6.31]],"id":62847579}],"con":true,"img":false}]}
{"op":"mcm","clk":"11540822767","pt":1719498767266,"mc":[{"id":"1.230180121","rc":[{"atb":[[1.33,30.78]],"id":69112387}],"con":true,"img":false}]}
{"op":"mcm","clk":"11540822778","pt":1719498767574,"mc":[{"id":"1.230180121","rc":[{"atb":[[1.67,6.31]],"id":64253834}],"con":true,"img":false}]}
{"op":"mcm","clk":"11540824034","pt":1719498784476,"mc":[{"id":"1.230180121","rc":[{"atb":[[1.65,0]],"id":62847579},{"atb":[[1.31,12.73]],"id":69112387}],"con":true,"img":false}]}
{"op":"mcm","clk":"11540824050","pt":1719498784681,"mc":[{"id":"1.230180121","rc":[{"atb":[[1.69,5.72]],"id":62847579},{"atb":[[1.35,15.79]],"id":69112387}],"con":true,"img":false}]}
{"op":"mcm","clk":"11540825410","pt":1719498801784,"mc":[{"id":"1.230180121","rc":[{"spn":38.34,"spf":"NaN","id":62847579},{"atb":[[1.61,0]],"id":53432239},{"spn":38.31,"spf":"NaN","id":53432239},{"atb":[[1.61,0]],"id":47370245},{"spn":38.31,"spf":"NaN","id":47370245},{"spn":38.17,"spf":"NaN","id":69112387},{"spn":38.33,"spf":"NaN","id":64253834}],"con":true,"img":false}]}
{"op":"mcm","clk":"11540825532","pt":1719498803394,"mc":[{"id":"1.230180121","rc":[{"atb":[[1.67,0]],"id":62847579},{"atb":[[1.33,12.82]],"id":69112387}],"con":true,"img":false}]}
{"op":"mcm","clk":"11540825554","pt":1719498803715,"mc":[{"id":"1.230180121","rc":[{"atb":[[1.71,5.96]],"id":62847579},{"atb":[[1.37,16.01]],"id":69112387}],"con":true,"img":false}]}
{"op":"mcm","clk":"11540827005","pt":1719498822511,"mc":[{"id":"1.230180121","rc":[{"atb":[[1.69,0]],"id":62847579}],"con":true,"img":false}]}
{"op":"mcm","clk":"11540827017","pt":1719498822708,"mc":[{"id":"1.230180121","rc":[{"atb":[[1.73,5.4]],"id":62847579}],"con":true,"img":false}]}
{"op":"mcm","clk":"11540828377","pt":1719498840331,"mc":[{"id":"1.230180121","rc":[{"atb":[[1.74,1]],"id":47370245},{"atl":[[5.2,1]],"id":47370245},{"atb":[[1.97,1]],"id":64253834},{"atl":[[6.8,1]],"id":64253834}],"con":true,"img":false}]}
{"op":"mcm","clk":"11540828386","pt":1719498840436,"mc":[{"id":"1.230180121","rc":[{"atb":[[2.42,1],[1.94,5.41]],"id":62847579},{"atl":[[70,2],[8.6,1]],"id":62847579},{"atb":[[1.64,2.48],[1.86,1]],"id":53432239},{"atl":[[19.5,2],[5.7,1]],"id":53432239},{"atb":[[1.64,2.48]],"id":47370245},{"atl":[[19,2]],"id":47370245},{"atb":[[1.21,2.48],[1.51,1]],"id":64536702},{"atl":[[3.95,1],[9.4,2]],"id":64536702},{"atb":[[1.25,28.62]],"id":69112387},{"atl":[[4.7,2]],"id":69112387},{"atb":[[1.88,6.07]],"id":64253834},{"atl":[[60,2]],"id":64253834}],"con":true,"img":false}]}
{"op":"mcm","clk":"11540828395","pt":1719498840537,"mc":[{"id":"1.230180121","rc":[{"atl":[[2.64,1]],"id":69112387}],"con":true,"img":false}]}
{"op":"mcm","clk":"11540828593","pt":1719498843141,"mc":[{"id":"1.230180121","rc":[{"atb":[[1.76,2.11]],"id":62847579},{"atb":[[1.66,2.11]],"id":53432239},{"atb":[[1.66,2.11]],"id":47370245},{"atb":[[1.4,2.11]],"id":69112387},{"atb":[[1.7,2.11]],"id":64253834}],"con":true,"img":false}]}
{"op":"mcm","clk":"11540829192","pt":1719498850539,"mc":[{"id":"1.230180121","rc":[{"atb":[[1.64,0],[1.66,4.59]],"id":47370245}],"con":true,"img":false}]}
{"op":"mcm","clk":"11540829956","pt":1719498859236,"mc":[{"id":"1.230180121","rc":[{"atb":[[1.94,0],[2.16,5.41]],"id":62847579},{"atb":[[1.64,0],[1.7,2.48]],"id":53432239},{"atb":[[1.7,4.6],[1.66,2.11]],"id":47370245},{"atb":[[1.21,0],[1.3,2.48]],"id":64536702},{"atb":[[1.25,0],[1.3,25.66]],"id":69112387},{"atb":[[2.02,2.12],[1.88,0]],"id":64253834}],"con":true,"img":false}]}
{"op":"mcm","clk":"11540829982","pt":1719498859439,"mc":[{"id":"1.230180121","rc":[{"atl":[[8.6,0],[9.8,1]],"id":62847579},{"atl":[[5.7,0],[7,1]],"id":53432239},{"atl":[[5.2,0],[5.9,1]],"id":47370245},{"atl":[[4.6,1],[3.95,0]],"id":64536702},{"atl":[[2.92,1],[2.64,0]],"id":69112387},{"atl":[[7.4,1],[6.8,0]],"id":64253834}],"con":true,"img":false}]}
{"op":"mcm","clk":"11540829993","pt":1719498859541,"mc":[{"id":"1.230180121","rc":[{"atb":[[1.35,0]],"id":69112387}],"con":true,"img":false}]}
{"op":"mcm","clk":"11540830013","pt":1719498859748,"mc":[{"id":"1.230180121","rc":[{"atb":[[1.39,14.17]],"id":69112387}],"con":true,"img":false}]}
{"op":"mcm","clk":"11540832107","pt":1719498881978,"mc":[{"id":"1.230180121","rc":[{"spn":6.11,"spf":"NaN","id":62847579},{"atb":[[1.63,0]],"id":53432239},{"spn":4.43,"spf":"NaN","id":53432239},{"atb":[[1.63,0]],"id":47370245},{"spn":3.82,"spf":"NaN","id":47370245},{"spn":3.05,"spf":"NaN","id":64536702},{"atb":[[1.33,0]],"id":69112387},{"spn":2.16,"spf":"NaN","id":69112387},{"spn":4.71,"spf":"NaN","id":64253834}],"con":true,"img":false}]}
{"op":"mcm","clk":"11540833408","pt":1719498897344,"mc":[{"id":"1.230180121","rc":[{"atb":[[1.31,0]],"id":69112387}],"con":true,"img":false}]}
{"op":"mcm","clk":"11540833512","pt":1719498898791,"mc":[{"id":"1.230180121","rc":[{"atb":[[1.72,5.48]],"id":53432239}],"con":true,"img":false}]}
{"op":"mcm","clk":"11540833532","pt":1719498898997,"mc":[{"id":"1.230180121","rc":[{"atb":[[1.73,2.48],[1.7,0]],"id":53432239}],"con":true,"img":false}]}
{"op":"mcm","clk":"11540833552","pt":1719498899155,"mc":[{"id":"1.230180121","rc":[{"atb":[[1.02,2]],"id":64536702}],"con":true,"img":false}]}
{"op":"mcm","clk":"11540833571","pt":1719498899363,"mc":[{"id":"1.230180121","rc":[{"atb":[[1.41,2]],"id":69112387}],"con":true,"img":false}]}
{"op":"mcm","clk":"11540833590","pt":1719498899565,"mc":[{"id":"1.230180121","rc":[{"atb":[[1.02,2]],"id":47370245}],"con":true,"img":false}]}
{"op":"mcm","clk":"11540833622","pt":1719498899981,"mc":[{"id":"1.230180121","rc":[{"atb":[[1.02,27.93]],"id":53432239}],"con":true,"img":false}]}
{"op":"mcm","clk":"11540833667","pt":1719498900399,"mc":[{"id":"1.230180121","rc":[{"atb":[[2.18,2]],"id":62847579}],"con":true,"img":false}]}
{"op":"mcm","clk":"11540833687","pt":1719498900558,"mc":[{"id":"1.230180121","rc":[{"atb":[[2.04,2]],"id":64253834}],"con":true,"img":false}]}
{"op":"mcm","clk":"11540833886","pt":1719498902677,"mc":[{"id":"1.230180121","rc":[{"atb":[[1.02,25.93]],"id":53432239}],"con":true,"img":false}]}
{"op":"mcm","clk":"11540833896","pt":1719498902779,"mc":[{"id":"1.230180121","rc":[{"atb":[[1.74,2]],"id":53432239}],"con":true,"img":false}]}
{"op":"mcm","clk":"11540833938","pt":1719498903157,"mc":[{"id":"1.230180121","rc":[{"atb":[[2.18,0]],"id":62847579}],"con":true,"img":false}]}
{"op":"mcm","clk":"11540833947","pt":1719498903250,"mc":[{"id":"1.230180121","rc":[{"atb":[[1.02,2]],"id":62847579}],"con":true,"img":false}]}
{"op":"mcm","clk":"11540834063","pt":1719498904561,"mc":[{"id":"1.230180121","rc":[{"atb":[[1.02,0]],"id":62847579}],"con":true,"img":false}]}
{"op":"mcm","clk":"11540834074","pt":1719498904681,"mc":[{"id":"1.230180121","rc":[{"atb":[[2.18,2]],"id":62847579}],"con":true,"img":false}]}
{"op":"mcm","clk":"11540834172","pt":1719498905759,"mc":[{"id":"1.230180121","rc":[{"atb":[[2.18,0]],"id":62847579}],"con":true,"img":false}]}
{"op":"mcm","clk":"11540834181","pt":1719498905872,"mc":[{"id":"1.230180121","rc":[{"atb":[[1.02,2]],"id":62847579}],"con":true,"img":false}]}
{"op":"mcm","clk":"11540834273","pt":1719498906796,"mc":[{"id":"1.230180121","rc":[{"atb":[[1.02,0]],"id":62847579}],"con":true,"img":false}]}
{"op":"mcm","clk":"11540834283","pt":1719498906888,"mc":[{"id":"1.230180121","rc":[{"atb":[[2.18,2]],"id":62847579}],"con":true,"img":false}]}
{"op":"mcm","clk":"11540834348","pt":1719498907667,"mc":[{"id":"1.230180121","rc":[{"atb":[[2.18,0]],"id":62847579}],"con":true,"img":false}]}
{"op":"mcm","clk":"11540834356","pt":1719498907770,"mc":[{"id":"1.230180121","rc":[{"atb":[[1.02,2]],"id":62847579}],"con":true,"img":false}]}
{"op":"mcm","clk":"11540834444","pt":1719498908763,"mc":[{"id":"1.230180121","rc":[{"atb":[[1.02,0]],"id":62847579}],"con":true,"img":false}]}
{"op":"mcm","clk":"11540834458","pt":1719498908890,"mc":[{"id":"1.230180121","rc":[{"atb":[[2.18,2]],"id":62847579}],"con":true,"img":false}]}
{"op":"mcm","clk":"11540834529","pt":1719498909788,"mc":[{"id":"1.230180121","rc":[{"atb":[[2.18,0]],"id":62847579}],"con":true,"img":false}]}
{"op":"mcm","clk":"11540834542","pt":1719498909892,"mc":[{"id":"1.230180121","rc":[{"atb":[[1.02,2]],"id":62847579}],"con":true,"img":false}]}
{"op":"mcm","clk":"11540834637","pt":1719498910872,"mc":[{"id":"1.230180121","rc":[{"atb":[[1.02,0]],"id":62847579}],"con":true,"img":false}]}
{"op":"mcm","clk":"11540834646","pt":1719498910974,"mc":[{"id":"1.230180121","rc":[{"atb":[[2.18,2]],"id":62847579}],"con":true,"img":false}]}
{"op":"mcm","clk":"11540834699","pt":1719498911693,"mc":[{"id":"1.230180121","rc":[{"atb":[[2.18,0]],"id":62847579}],"con":true,"img":false}]}
{"op":"mcm","clk":"11540834711","pt":1719498911805,"mc":[{"id":"1.230180121","rc":[{"atb":[[1.02,2]],"id":62847579}],"con":true,"img":false}]}
{"op":"mcm","clk":"11540834771","pt":1719498912472,"mc":[{"id":"1.230180121","rc":[{"atb":[[1.02,0]],"id":62847579}],"con":true,"img":false}]}
{"op":"mcm","clk":"11540834779","pt":1719498912576,"mc":[{"id":"1.230180121","rc":[{"atb":[[2.18,2]],"id":62847579}],"con":true,"img":false}]}
{"op":"mcm","clk":"11540834877","pt":1719498913863,"mc":[{"id":"1.230180121","rc":[{"atb":[[2.18,0]],"id":62847579}],"con":true,"img":false}]}
{"op":"mcm","clk":"11540834885","pt":1719498913967,"mc":[{"id":"1.230180121","rc":[{"atb":[[1.02,2]],"id":62847579}],"con":true,"img":false}]}
{"op":"mcm","clk":"11540834980","pt":1719498915170,"mc":[{"id":"1.230180121","rc":[{"atb":[[1.02,0]],"id":62847579}],"con":true,"img":false}]}
{"op":"mcm","clk":"11540834986","pt":1719498915266,"mc":[{"id":"1.230180121","rc":[{"atb":[[2.18,2]],"id":62847579}],"con":true,"img":false}]}
{"op":"mcm","clk":"11540835014","pt":1719498915673,"mc":[{"id":"1.230180121","rc":[{"atb":[[1.72,0]],"id":53432239}],"con":true,"img":false}]}
{"op":"mcm","clk":"11540835029","pt":1719498915879,"mc":[{"id":"1.230180121","rc":[{"atb":[[1.76,5.19]],"id":53432239}],"con":true,"img":false}]}
{"op":"mcm","clk":"11540835037","pt":1719498915982,"mc":[{"id":"1.230180121","rc":[{"atb":[[1.73,0],[1.77,2.48]],"id":53432239}],"con":true,"img":false}]}
{"op":"mcm","clk":"11540835049","pt":1719498916188,"mc":[{"id":"1.230180121","rc":[{"atb":[[2.18,0]],"id":62847579}],"con":true,"img":false}]}
{"op":"mcm","clk":"11540835057","pt":1719498916299,"mc":[{"id":"1.230180121","rc":[{"atb":[[1.02,2]],"id":62847579}],"con":true,"img":false}]}
{"op":"mcm","clk":"11540835161","pt":1719498917583,"mc":[{"id":"1.230180121","rc":[{"atb":[[1.74,0]],"id":53432239}],"con":true,"img":false}]}
{"op":"mcm","clk":"11540835172","pt":1719498917687,"mc":[{"id":"1.230180121","rc":[{"atb":[[1.78,2]],"id":53432239}],"con":true,"img":false}]}
{"op":"mcm","clk":"11540835212","pt":1719498918077,"mc":[{"id":"1.230180121","rc":[{"atb":[[1.02,0]],"id":62847579}],"con":true,"img":false}]}
{"op":"mcm","clk":"11540835220","pt":1719498918177,"mc":[{"id":"1.230180121","rc":[{"atb":[[2.18,2]],"id":62847579}],"con":true,"img":false}]}
{"op":"mcm","clk":"11540835291","pt":1719498918905,"mc":[{"id":"1.230180121","rc":[{"atb":[[1.71,0]],"id":62847579},{"atb":[[1.67,0]],"id":64253834}],"con":true,"img":false}]}
{"op":"mcm","clk":"11540835324","pt":1719498919165,"mc":[{"id":"1.230180121","rc":[{"atb":[[2.18,0]],"id":62847579},{"atb":[[1.8,5.29]],"id":53432239}],"con":true,"img":false}]}
{"op":"mcm","clk":"11540835335","pt":1719498919275,"mc":[{"id":"1.230180121","rc":[{"atb":[[1.02,2]],"id":62847579},{"atb":[[1.81,2.48],[1.77,0]],"id":53432239}],"con":true,"img":false}]}
{"op":"mcm","clk":"11540835504","pt":1719498921381,"mc":[{"id":"1.230180121","rc":[{"atb":[[1.78,0]],"id":53432239}],"con":true,"img":false}]}
{"op":"mcm","clk":"11540835513","pt":1719498921485,"mc":[{"id":"1.230180121","rc":[{"atb":[[1.82,2]],"id":53432239}],"con":true,"img":false}]}
{"op":"mcm","clk":"11540835541","pt":1719498921800,"mc":[{"id":"1.230180121","rc":[{"atb":[[1.02,0]],"id":62847579}],"con":true,"img":false}]}
{"op":"mcm","clk":"11540835548","pt":1719498921898,"mc":[{"id":"1.230180121","rc":[{"atb":[[2.18,2]],"id":62847579}],"con":true,"img":false}]}
{"op":"mcm","clk":"11540835637","pt":1719498922982,"mc":[{"id":"1.230180121","rc":[{"atb":[[2.18,0]],"id":62847579}],"con":true,"img":false}]}
{"op":"mcm","clk":"11540835648","pt":1719498923087,"mc":[{"id":"1.230180121","rc":[{"atb":[[1.02,2]],"id":62847579}],"con":true,"img":false}]}
{"op":"mcm","clk":"11540835696","pt":1719498923608,"mc":[{"id":"1.230180121","rc":[{"atb":[[1.73,0]],"id":62847579},{"atb":[[1.65,0]],"id":64253834}],"con":true,"img":false}]}
{"op":"mcm","clk":"11540836655","pt":1719498934801,"mc":[{"id":"1.230180121","rc":[{"atb":[[1.76,0]],"id":53432239}],"con":true,"img":false}]}
{"op":"mcm","clk":"11540836678","pt":1719498935006,"mc":[{"id":"1.230180121","rc":[{"atb":[[1.84,4.69]],"id":53432239}],"con":true,"img":false}]}
{"op":"mcm","clk":"11540836690","pt":1719498935110,"mc":[{"id":"1.230180121","rc":[{"atb":[[1.81,0],[1.85,2.48]],"id":53432239}],"con":true,"img":false}]}
{"op":"mcm","clk":"11540836794","pt":1719498936202,"mc":[{"id":"1.230180121","rc":[{"atb":[[1.82,0]],"id":53432239}],"con":true,"img":false}]}
{"op":"mcm","clk":"11540836808","pt":1719498936302,"mc":[{"id":"1.230180121","rc":[{"atb":[[1.86,3]],"id":53432239}],"con":true,"img":false}]}
{"op":"mcm","clk":"11540837597","pt":1719498944103,"mc":[{"id":"1.230180121","rc":[{"atb":[[1.37,0]],"id":69112387},{"spn":2.16,"spf":"NaN","id":69112387},{"spn":4.72,"spf":"NaN","id":64253834}],"con":true,"img":false}]}
{"op":"mcm","clk":"11540844332","pt":1719499019560,"mc":[{"id":"1.230180121","rc":[{"atb":[[1.59,3.75]],"id":64253834}],"con":true,"img":false}]}
{"op":"mcm","clk":"11540844366","pt":1719499019873,"mc":[{"id":"1.230180121","rc":[{"atb":[[1.59,0]],"id":64253834}],"con":true,"img":false}]}
{"op":"mcm","clk":"11540844532","pt":1719499022091,"mc":[{"id":"1.230180121","rc":[{"atb":[[1.39,0]],"id":69112387}],"con":true,"img":false}]}
{"op":"mcm","clk":"11540844541","pt":1719499022198,"mc":[{"id":"1.230180121","rc":[{"atb":[[1.84,0]],"id":53432239}],"con":true,"img":false}]}
{"op":"mcm","clk":"11540844582","pt":1719499022714,"mc":[{"id":"1.230180121","rc":[{"atb":[[1.8,0]],"id":53432239}],"con":true,"img":false}]}
{"op":"mcm","clk":"11540844979","pt":1719499027313,"mc":[{"id":"1.230180121","rc":[{"atb":[[1.32,17.27]],"id":69112387}],"con":true,"img":false}]}
{"op":"mcm","clk":"11540845899","pt":1719499038923,"mc":[{"id":"1.230180121","rc":[{"atb":[[1.34,17.43]],"id":69112387}],"con":true,"img":false}]}
{"op":"mcm","clk":"11540846423","pt":1719499044926,"mc":[{"id":"1.230180121","rc":[{"atb":[[1.32,0]],"id":69112387}],"con":true,"img":false}]}
{"op":"mcm","clk":"11540846442","pt":1719499045133,"mc":[{"id":"1.230180121","rc":[{"atb":[[1.36,15.35]],"id":69112387}],"con":true,"img":false}]}
{"op":"mcm","clk":"11540848958","pt":1719499078107,"mc":[{"id":"1.230180121","rc":[{"atb":[[1.34,0]],"id":69112387}],"con":true,"img":false}]}
{"op":"mcm","clk":"11540849022","pt":1719499078875,"mc":[{"id":"1.230180121","rc":[{"atb":[[1.38,15.59]],"id":69112387}],"con":true,"img":false}]}
{"op":"mcm","clk":"11540851004","pt":1719499103709,"mc":[{"id":"1.230180121","rc":[{"atb":[[1.72,5.48]],"id":47370245}],"con":true,"img":false}]}
{"op":"mcm","clk":"11540851020","pt":1719499103914,"mc":[{"id":"1.230180121","rc":[{"atb":[[1.73,4.6]],"id":47370245}],"con":true,"img":false}]}
{"op":"mcm","clk":"11540851025","pt":1719499104021,"mc":[{"id":"1.230180121","rc":[{"atb":[[1.7,0]],"id":47370245}],"con":true,"img":false}]}
{"op":"mcm","clk":"11540851067","pt":1719499104589,"mc":[{"id":"1.230180121","rc":[{"atb":[[1.02,0]],"id":47370245}],"con":true,"img":false}]}
{"op":"mcm","clk":"11540851077","pt":1719499104695,"mc":[{"id":"1.230180121","rc":[{"atb":[[1.74,3]],"id":47370245}],"con":true,"img":false}]}
{"op":"mcm","clk":"11540854164","pt":1719499148572,"mc":[{"id":"1.230180121","rc":[{"atb":[[1.36,0]],"id":69112387}],"con":true,"img":false}]}
{"op":"mcm","clk":"11540854610","pt":1719499154593,"mc":[{"id":"1.230180121","rc":[{"atb":[[1.08,50]],"id":62847579},{"atb":[[1.08,50]],"id":53432239},{"atb":[[1.08,50]],"id":47370245},{"atb":[[1.08,50]],"id":64536702},{"atb":[[1.08,50]],"id":69112387},{"atb":[[1.08,50]],"id":64253834}],"con":true,"img":false}]}
{"op":"mcm","clk":"11540854750","pt":1719499156657,"mc":[{"id":"1.230180121","rc":[{"atb":[[1.4,15.93]],"id":69112387}],"con":true,"img":false}]}
{"op":"mcm","clk":"11540855359","pt":1719499165170,"mc":[{"id":"1.230180121","rc":[{"atl":[[7.4,0],[13.5,1]],"id":64253834},{"spn":7.77,"spf":"NaN","id":64253834}],"con":true,"img":false}]}
{"op":"mcm","clk":"11540857124","pt":1719499188895,"mc":[{"id":"1.230180121","rc":[{"atb":[[1.72,0]],"id":47370245}],"con":true,"img":false}]}
{"op":"mcm","clk":"11540858174","pt":1719499202242,"mc":[{"id":"1.230180121","rc":[{"atl":[[7.4,1],[13.5,0]],"id":64253834}],"con":true,"img":false}]}
{"op":"mcm","clk":"11540859077","pt":1719499214464,"mc":[{"id":"1.230180121","rc":[{"atb":[[1.88,4.48]],"id":53432239}],"con":true,"img":false}]}
{"op":"mcm","clk":"11540859085","pt":1719499214568,"mc":[{"id":"1.230180121","rc":[{"atb":[[1.89,3],[1.85,0]],"id":53432239}],"con":true,"img":false}]}
{"op":"mcm","clk":"11540859128","pt":1719499215343,"mc":[{"id":"1.230180121","rc":[{"atb":[[1.86,1]],"id":53432239}],"con":true,"img":false}]}
{"op":"mcm","clk":"11540859139","pt":1719499215455,"mc":[{"id":"1.230180121","rc":[{"atb":[[1.9,2]],"id":53432239}],"con":true,"img":false}]}
{"op":"mcm","clk":"11540859887","pt":1719499225770,"mc":[{"id":"1.230180121","rc":[{"atl":[[10.5,1],[9.8,0]],"id":62847579},{"spn":6.46,"spf":"NaN","id":62847579},{"atl":[[7.2,1],[7,0]],"id":53432239},{"spn":4.55,"spf":"NaN","id":53432239},{"atb":[[1.74,2]],"id":47370245},{"atl":[[5.7,1],[5.9,0]],"id":47370245},{"spn":3.72,"spf":"NaN","id":47370245},{"atl":[[4.6,0],[4.7,1]],"id":64536702},{"spn":3.1,"spf":"NaN","id":64536702},{"atl":[[2.92,0],[3,1]],"id":69112387},{"spn":2.2,"spf":"NaN","id":69112387},{"atl":[[7.4,0],[7.8,1]],"id":64253834},{"spn":4.92,"spf":"NaN","id":64253834}],"con":true,"img":false}]}
{"op":"mcm","clk":"11540859903","pt":1719499225984,"mc":[{"id":"1.230180121","rc":[{"atb":[[1.73,0],[1.7,6.6]],"id":47370245}],"con":true,"img":false}]}
{"op":"mcm","clk":"11540859915","pt":1719499226079,"mc":[{"id":"1.230180121","rc":[{"atb":[[1.7,0]],"id":47370245}],"con":true,"img":false}]}
{"op":"mcm","clk":"11540859927","pt":1719499226186,"mc":[{"id":"1.230180121","rc":[{"atb":[[1.74,4.12]],"id":47370245}],"con":true,"img":false}]}
{"op":"mcm","clk":"11540859947","pt":1719499226346,"mc":[{"id":"1.230180121","rc":[{"atb":[[1.74,2],[1.7,4]],"id":47370245}],"con":true,"img":false}]}
{"op":"mcm","clk":"11540859994","pt":1719499226981,"mc":[{"id":"1.230180121","rc":[{"atb":[[1.74,0]],"id":47370245}],"con":true,"img":false}]}
{"op":"mcm","clk":"11540860003","pt":1719499227071,"mc":[{"id":"1.230180121","rc":[{"atb":[[1.71,2]],"id":47370245}],"con":true,"img":false}]}
{"op":"mcm","clk":"11540860471","pt":1719499232777,"mc":[{"id":"1.230180121","rc":[{"atb":[[1.88,0]],"id":53432239},{"atb":[[1.43,9.18]],"id":69112387}],"con":true,"img":false}]}
{"op":"mcm","clk":"11540860486","pt":1719499232989,"mc":[{"id":"1.230180121","rc":[{"atb":[[1.92,4.28]],"id":53432239}],"con":true,"img":false}]}
{"op":"mcm","clk":"11540860496","pt":1719499233041,"mc":[{"id":"1.230180121","rc":[{"atb":[[1.93,3]],"id":53432239}],"con":true,"img":false}]}
{"op":"mcm","clk":"11540860505","pt":1719499233163,"mc":[{"id":"1.230180121","rc":[{"atb":[[1.89,0]],"id":53432239}],"con":true,"img":false}]}
{"op":"mcm","clk":"11540860546","pt":1719499233742,"mc":[{"id":"1.230180121","rc":[{"atb":[[1.41,0],[1.4,13.81],[1.44,2.11]],"id":69112387}],"con":true,"img":false}]}
{"op":"mcm","clk":"11540860552","pt":1719499233850,"mc":[{"id":"1.230180121","rc":[{"atb":[[1.44,4.11]],"id":69112387}],"con":true,"img":false}]}
{"op":"mcm","clk":"11540860557","pt":1719499233950,"mc":[{"id":"1.230180121","rc":[{"atb":[[1.37,5.15]],"id":69112387}],"con":true,"img":false}]}
{"op":"mcm","clk":"11540860574","pt":1719499234162,"mc":[{"id":"1.230180121","rc":[{"atb":[[1.37,0]],"id":69112387}],"con":true,"img":false}]}
{"op":"mcm","clk":"11540860586","pt":1719499234264,"mc":[{"id":"1.230180121","rc":[{"atb":[[1.9,0]],"id":53432239},{"atb":[[1.38,0]],"id":69112387}],"con":true,"img":false}]}
{"op":"mcm","clk":"11540860593","pt":1719499234370,"mc":[{"id":"1.230180121","rc":[{"atb":[[1.94,2]],"id":53432239}],"con":true,"img":false}]}
{"op":"mcm","clk":"11540860802","pt":1719499236982,"mc":[{"id":"1.230180121","rc":[{"atb":[[1.42,14.11]],"id":69112387}],"con":true,"img":false}]}
{"op":"mcm","clk":"11540861336","pt":1719499243490,"mc":[{"id":"1.230180121","rc":[{"atb":[[1.4,0]],"id":69112387}],"con":true,"img":false}]}
{"op":"mcm","clk":"11540861994","pt":1719499252112,"mc":[{"id":"1.230180121","rc":[{"atb":[[1.45,12.28]],"id":69112387}],"con":true,"img":false}]}
{"op":"mcm","clk":"11540862044","pt":1719499252887,"mc":[{"id":"1.230180121","rc":[{"atb":[[1.44,2.11]],"id":69112387}],"con":true,"img":false}]}
{"op":"mcm","clk":"11540862050","pt":1719499252993,"mc":[{"id":"1.230180121","rc":[{"atb":[[1.46,2]],"id":69112387}],"con":true,"img":false}]}
{"op":"mcm","clk":"11540862131","pt":1719499253988,"mc":[{"id":"1.230180121","rc":[{"atb":[[1.44,0],[1.48,2.11]],"id":69112387}],"con":true,"img":false}]}
{"op":"mcm","clk":"11540862174","pt":1719499254567,"mc":[{"id":"1.230180121","rc":[{"atb":[[1.46,0]],"id":69112387}],"con":true,"img":false}]}
{"op":"mcm","clk":"11540862184","pt":1719499254668,"mc":[{"id":"1.230180121","rc":[{"atb":[[1.49,2]],"id":69112387}],"con":true,"img":false}]}
{"op":"mcm","clk":"11540862806","pt":1719499263222,"mc":[{"id":"1.230180121","rc":[{"atb":[[1.42,19.11]],"id":69112387}],"con":true,"img":false}]}
{"op":"mcm","clk":"11540862825","pt":1719499263590,"mc":[{"id":"1.230180121","rc":[{"atb":[[2.42,3.1]],"id":62847579},{"atb":[[1.94,4.6]],"id":53432239},{"atb":[[1.71,5]],"id":47370245},{"atb":[[1.31,3.78]],"id":64536702},{"atb":[[1.49,6],[1.42,14.11]],"id":69112387},{"atb":[[2.04,5.3]],"id":64253834}],"con":true,"img":false}]}
{"op":"mcm","clk":"11540862830","pt":1719499263691,"mc":[{"id":"1.230180121","rc":[{"atb":[[1.95,4.29]],"id":53432239},{"atb":[[1.72,4]],"id":47370245},{"atb":[[2.02,0],[2.06,2.12]],"id":64253834}],"con":true,"img":false}]}
{"op":"mcm","clk":"11540862840","pt":1719499263793,"mc":[{"id":"1.230180121","rc":[{"atb":[[2.42,6.2],[2.16,0]],"id":62847579},{"atb":[[1.93,0]],"id":53432239},{"atb":[[1.7,0]],"id":47370245}],"con":true,"img":false}]}
{"op":"mcm","clk":"11540862845","pt":1719499263900,"mc":[{"id":"1.230180121","rc":[{"atb":[[2.42,3.1],[2.16,6.2]],"id":62847579}],"con":true,"img":false}]}
{"op":"mcm","clk":"11540862884","pt":1719499264524,"mc":[{"id":"1.230180121","rc":[{"atb":[[1.71,3]],"id":47370245}],"con":true,"img":false}]}
{"op":"mcm","clk":"11540862891","pt":1719499264628,"mc":[{"id":"1.230180121","rc":[{"atb":[[1.73,2],[1.72,0],[1.71,11]],"id":47370245}],"con":true,"img":false}]}
{"op":"mcm","clk":"11540862900","pt":1719499264678,"mc":[{"id":"1.230180121","rc":[{"atb":[[1.7,7],[1.71,3]],"id":47370245}],"con":true,"img":false}]}
{"op":"mcm","clk":"11540862903","pt":1719499264778,"mc":[{"id":"1.230180121","rc":[{"atb":[[1.73,4.12],[1.7,0]],"id":47370245}],"con":true,"img":false}]}
{"op":"mcm","clk":"11540862907","pt":1719499264887,"mc":[{"id":"1.230180121","rc":[{"atb":[[1.73,2],[1.71,7]],"id":47370245}],"con":true,"img":false}]}
{"op":"mcm","clk":"11540862912","pt":1719499264985,"mc":[{"id":"1.230180121","rc":[{"atb":[[1.73,5],[1.71,3]],"id":47370245}],"con":true,"img":false}]}
{"op":"mcm","clk":"11540862920","pt":1719499265096,"mc":[{"id":"1.230180121","rc":[{"atb":[[1.94,2.6]],"id":53432239},{"atb":[[1.71,7]],"id":47370245}],"con":true,"img":false}]}
{"op":"mcm","clk":"11540862927","pt":1719499265195,"mc":[{"id":"1.230180121","rc":[{"atb":[[1.96,2]],"id":53432239},{"atb":[[1.73,2]],"id":47370245}],"con":true,"img":false}]}
{"op":"mcm","clk":"11540862938","pt":1719499265303,"mc":[{"id":"1.230180121","rc":[{"atb":[[1.94,11.18],[1.95,0]],"id":53432239}],"con":true,"img":false}]}
{"op":"mcm","clk":"11540862949","pt":1719499265407,"mc":[{"id":"1.230180121","rc":[{"atb":[[1.73,7],[1.71,3]],"id":47370245}],"con":true,"img":false}]}
{"op":"mcm","clk":"11540862968","pt":1719499265711,"mc":[{"id":"1.230180121","rc":[{"atb":[[2.04,3.3]],"id":64253834}],"con":true,"img":false}]}
{"op":"mcm","clk":"11540862972","pt":1719499265818,"mc":[{"id":"1.230180121","rc":[{"atb":[[2.08,2]],"id":64253834}],"con":true,"img":false}]}
{"op":"mcm","clk":"11540863009","pt":1719499266589,"mc":[{"id":"1.230180121","rc":[{"atb":[[1.96,0]],"id":53432239}],"con":true,"img":false}]}
{"op":"mcm","clk":"11540863018","pt":1719499266699,"mc":[{"id":"1.230180121","rc":[{"atb":[[1.95,2]],"id":53432239}],"con":true,"img":false}]}
{"op":"mcm","clk":"11540863122","pt":1719499268286,"mc":[{"id":"1.230180121","rc":[{"atb":[[1.75,5.26]],"id":47370245}],"con":true,"img":false}]}
{"op":"mcm","clk":"11540863173","pt":1719499269014,"mc":[{"id":"1.230180121","rc":[{"atb":[[1.73,5]],"id":47370245}],"con":true,"img":false}]}
{"op":"mcm","clk":"11540863183","pt":1719499269110,"mc":[{"id":"1.230180121","rc":[{"atb":[[1.76,2]],"id":47370245}],"con":true,"img":false}]}
{"op":"mcm","clk":"11540863335","pt":1719499271330,"mc":[{"id":"1.230180121","rc":[{"atb":[[1.73,0],[1.76,7]],"id":47370245}],"con":true,"img":false}]}
{"op":"mcm","clk":"11540863697","pt":1719499276726,"mc":[{"id":"1.230180121","rc":[{"atb":[[1.42,0]],"id":69112387}],"con":true,"img":false}]}
{"op":"mcm","clk":"11540863749","pt":1719499277190,"mc":[{"id":"1.230180121","rc":[{"atb":[[1.78,5.42]],"id":47370245}],"con":true,"img":false}]}
{"op":"mcm","clk":"11540863757","pt":1719499277295,"mc":[{"id":"1.230180121","rc":[{"atb":[[1.79,5.43],[1.76,2]],"id":47370245}],"con":true,"img":false}]}
{"op":"mcm","clk":"11540863766","pt":1719499277416,"mc":[{"id":"1.230180121","rc":[{"atb":[[1.48,14.45]],"id":69112387}],"con":true,"img":false}]}
{"op":"mcm","clk":"11540863788","pt":1719499277810,"mc":[{"id":"1.230180121","rc":[{"atb":[[1.94,8.58]],"id":53432239},{"atb":[[1.71,0]],"id":47370245},{"atb":[[2.04,0]],"id":64253834}],"con":true,"img":false}]}
{"op":"mcm","clk":"11540863796","pt":1719499277919,"mc":[{"id":"1.230180121","rc":[{"atb":[[1.95,6.2]],"id":53432239},{"atb":[[1.8,3.2]],"id":47370245},{"atb":[[2.08,5.4]],"id":64253834}],"con":true,"img":false}]}
{"op":"mcm","clk":"11540863803","pt":1719499278014,"mc":[{"id":"1.230180121","rc":[{"atb":[[1.96,6.2],[1.94,0]],"id":53432239},{"atb":[[1.81,5.43],[1.76,0]],"id":47370245},{"atb":[[2.06,0],[2.1,2.12]],"id":64253834}],"con":true,"img":false}]}
{"op":"mcm","clk":"11540863814","pt":1719499278118,"mc":[{"id":"1.230180121","rc":[{"atb":[[1.8,5.2],[1.79,0]],"id":47370245}],"con":true,"img":false}]}
{"op":"mcm","clk":"11540863831","pt":1719499278430,"mc":[{"id":"1.230180121","rc":[{"atb":[[1.82,2.11],[1.66,0]],"id":47370245}],"con":true,"img":false}]}
{"op":"mcm","clk":"11540863891","pt":1719499279196,"mc":[{"id":"1.230180121","rc":[{"atb":[[1.8,3.2]],"id":47370245}],"con":true,"img":false}]}
{"op":"mcm","clk":"11540863902","pt":1719499279302,"mc":[{"id":"1.230180121","rc":[{"atb":[[1.83,2]],"id":47370245}],"con":true,"img":false}]}
{"op":"mcm","clk":"11540863968","pt":1719499280025,"mc":[{"id":"1.230180121","rc":[{"atb":[[1.95,4.2]],"id":53432239}],"con":true,"img":false}]}
{"op":"mcm","clk":"11540863978","pt":1719499280125,"mc":[{"id":"1.230180121","rc":[{"atb":[[1.97,2]],"id":53432239}],"con":true,"img":false}]}
{"op":"mcm","clk":"11540864017","pt":1719499280542,"mc":[{"id":"1.230180121","rc":[{"atb":[[2.08,3.4]],"id":64253834}],"con":true,"img":false}]}
{"op":"mcm","clk":"11540864023","pt":1719499280590,"mc":[{"id":"1.230180121","rc":[{"atb":[[1.02,2]],"id":64253834}],"con":true,"img":false}]}
{"op":"mcm","clk":"11540864293","pt":1719499283821,"mc":[{"id":"1.230180121","rc":[{"atb":[[1.83,4.12],[1.81,0]],"id":47370245}],"con":true,"img":false}]}
{"op":"mcm","clk":"11540864477","pt":1719499286135,"mc":[{"id":"1.230180121","rc":[{"atb":[[2.4,3.65]],"id":62847579},{"atb":[[1.92,9.28]],"id":53432239},{"spn":4.58,"spf":"NaN","id":53432239},{"atb":[[1.79,5.15]],"id":47370245},{"spn":3.76,"spf":"NaN","id":47370245},{"atb":[[1.29,3.75]],"id":64536702},{"spn":2.24,"spf":"NaN","id":69112387},{"atb":[[2.08,7.15]],"id":64253834},{"spn":4.95,"spf":"NaN","id":64253834}],"con":true,"img":false}]}
{"op":"mcm","clk":"11540864489","pt":1719499286251,"mc":[{"id":"1.230180121","rc":[{"atb":[[2.42,6.75],[2.16,0]],"id":62847579}],"con":true,"img":false}]}
{"op":"mcm","clk":"11540864501","pt":1719499286442,"mc":[{"id":"1.230180121","rc":[{"atb":[[1.45,0]],"id":69112387}],"con":true,"img":false}]}
{"op":"mcm","clk":"11540864513","pt":1719499286648,"mc":[{"id":"1.230180121","rc":[{"atb":[[1.51,10.84]],"id":69112387}],"con":true,"img":false}]}
{"op":"mcm","clk":"11540864661","pt":1719499288617,"mc":[{"id":"1.230180121","rc":[{"atb":[[1.02,0]],"id":64536702}],"con":true,"img":false}]}
{"op":"mcm","clk":"11540864668","pt":1719499288741,"mc":[{"id":"1.230180121","rc":[{"atb":[[1.32,2]],"id":64536702}],"con":true,"img":false}]}
{"op":"mcm","clk":"11540864709","pt":1719499289249,"mc":[{"id":"1.230180121","rc":[{"atb":[[1.49,4]],"id":69112387}],"con":true,"img":false}]}
{"op":"mcm","clk":"11540864719","pt":1719499289343,"mc":[{"id":"1.230180121","rc":[{"atb":[[1.52,2]],"id":69112387}],"con":true,"img":false}]}
{"op":"mcm","clk":"11540864738","pt":1719499289604,"mc":[{"id":"1.230180121","rc":[{"atb":[[1.44,5]],"id":69112387}],"con":true,"img":false}]}
{"op":"mcm","clk":"11540864836","pt":1719499290646,"mc":[{"id":"1.230180121","rc":[{"atb":[[1.54,2.11],[1.48,12.34]],"id":69112387}],"con":true,"img":false}]}
{"op":"mcm","clk":"11540864861","pt":1719499290950,"mc":[{"id":"1.230180121","rc":[{"atb":[[1.79,4.63]],"id":47370245}],"con":true,"img":false}]}
{"op":"mcm","clk":"11540864882","pt":1719499291259,"mc":[{"id":"1.230180121","rc":[{"atb":[[1.44,0]],"id":69112387}],"con":true,"img":false}]}
{"op":"mcm","clk":"11540865013","pt":1719499292814,"mc":[{"id":"1.230180121","rc":[{"atb":[[1.92,4.28]],"id":53432239},{"atb":[[1.52,0]],"id":69112387}],"con":true,"img":false}]}
{"op":"mcm","clk":"11540865021","pt":1719499292923,"mc":[{"id":"1.230180121","rc":[{"atb":[[1.95,0]],"id":53432239},{"atb":[[1.8,0]],"id":47370245},{"atb":[[1.31,0]],"id":64536702},{"atb":[[1.55,2],[1.49,0]],"id":69112387},{"atb":[[2.08,3.75]],"id":64253834}],"con":true,"img":false}]}
{"op":"mcm","clk":"11540865031","pt":1719499293022,"mc":[{"id":"1.230180121","rc":[{"atb":[[1.97,5.8]],"id":53432239},{"atb":[[1.84,3]],"id":47370245},{"atb":[[1.42,3.7]],"id":64536702},{"atb":[[1.54,6.91]],"id":69112387},{"atb":[[2.02,5.87],[2.1,3.66]],"id":64253834}],"con":true,"img":false}]}
{"op":"mcm","clk":"11540865041","pt":1719499293131,"mc":[{"id":"1.230180121","rc":[{"atb":[[1.98,5.8],[1.96,0]],"id":53432239},{"atb":[[1.83,2],[1.85,3]],"id":47370245},{"atb":[[1.43,2.48],[1.3,0]],"id":64536702}],"con":true,"img":false}]}
{"op":"mcm","clk":"11540865051","pt":1719499293232,"mc":[{"id":"1.230180121","rc":[{"atb":[[1.84,6]],"id":47370245}],"con":true,"img":false}]}
{"op":"mcm","clk":"11540865065","pt":1719499293333,"mc":[{"id":"1.230180121","rc":[{"atb":[[1.85,0]],"id":47370245}],"con":true,"img":false}]}
{"op":"mcm","clk":"11540865133","pt":1719499294314,"mc":[{"id":"1.230180121","rc":[{"atb":[[1.32,0]],"id":64536702}],"con":true,"img":false}]}
{"op":"mcm","clk":"11540865140","pt":1719499294418,"mc":[{"id":"1.230180121","rc":[{"atb":[[1.44,2]],"id":64536702}],"con":true,"img":false}]}
{"op":"mcm","clk":"11540865179","pt":1719499295035,"mc":[{"id":"1.230180121","rc":[{"atb":[[1.83,0]],"id":47370245}],"con":true,"img":false}]}
{"op":"mcm","clk":"11540865188","pt":1719499295132,"mc":[{"id":"1.230180121","rc":[{"atb":[[1.85,2]],"id":47370245}],"con":true,"img":false}]}
{"op":"mcm","clk":"11540865223","pt":1719499295650,"mc":[{"id":"1.230180121","rc":[{"atb":[[1.97,3.8]],"id":53432239}],"con":true,"img":false}]}
{"op":"mcm","clk":"11540865230","pt":1719499295752,"mc":[{"id":"1.230180121","rc":[{"atb":[[1.99,2]],"id":53432239}],"con":true,"img":false}]}
{"op":"mcm","clk":"11540865248","pt":1719499296117,"mc":[{"id":"1.230180121","rc":[{"atb":[[1.02,0]],"id":64253834}],"con":true,"img":false}]}
{"op":"mcm","clk":"11540865256","pt":1719499296216,"mc":[{"id":"1.230180121","rc":[{"atb":[[2.12,2]],"id":64253834}],"con":true,"img":false}]}
{"op":"mcm","clk":"11540865302","pt":1719499296834,"mc":[{"id":"1.230180121","rc":[{"atb":[[2.08,0]],"id":64253834}],"con":true,"img":false}]}
{"op":"mcm","clk":"11540865439","pt":1719499298639,"mc":[{"id":"1.230180121","rc":[{"atb":[[2.02,0],[2.12,5.66]],"id":64253834}],"con":true,"img":false}]}
{"op":"mcm","clk":"11540865511","pt":1719499299626,"mc":[{"id":"1.230180121","rc":[{"atb":[[2.12,3.66]],"id":64253834}],"con":true,"img":false}]}
{"op":"mcm","clk":"11540865521","pt":1719499299730,"mc":[{"id":"1.230180121","rc":[{"atb":[[1.02,2]],"id":64253834}],"con":true,"img":false}]}
{"op":"mcm","clk":"11540865699","pt":1719499302364,"mc":[{"id":"1.230180121","rc":[{"atb":[[1.29,0]],"id":64536702}],"con":true,"img":false}]}
{"op":"mcm","clk":"11540865830","pt":1719499304322,"mc":[{"id":"1.230180121","rc":[{"atb":[[1.46,8.58]],"id":64536702}],"con":true,"img":false}]}
{"op":"mcm","clk":"11540865840","pt":1719499304426,"mc":[{"id":"1.230180121","rc":[{"atb":[[1.43,0],[1.47,2.48]],"id":64536702}],"con":true,"img":false}]}
{"op":"mcm","clk":"11540865897","pt":1719499305251,"mc":[{"id":"1.230180121","rc":[{"atb":[[1.44,0]],"id":64536702}],"con":true,"img":false}]}
{"op":"mcm","clk":"11540865904","pt":1719499305356,"mc":[{"id":"1.230180121","rc":[{"atb":[[1.48,2]],"id":64536702}],"con":true,"img":false}]}
{"op":"mcm","clk":"11540866032","pt":1719499306953,"mc":[{"id":"1.230180121","rc":[{"atb":[[1.97,0]],"id":53432239},{"atb":[[1.84,3]],"id":47370245},{"atb":[[1.42,0],[1.49,2.11]],"id":64536702},{"atb":[[1.54,2.11]],"id":69112387},{"atb":[[2.1,0]],"id":64253834}],"con":true,"img":false}]}
{"op":"mcm","clk":"11540866039","pt":1719499307064,"mc":[{"id":"1.230180121","rc":[{"atb":[[1.99,5.3]],"id":53432239},{"atb":[[1.85,6]],"id":47370245},{"atb":[[1.49,4.23],[1.51,4.16],[1.47,0]],"id":64536702},{"atb":[[1.55,6.5]],"id":69112387},{"atb":[[2.02,7.32],[2.12,0],[2.14,2.5]],"id":64253834}],"con":true,"img":false}]}
{"op":"mcm","clk":"11540866057","pt":1719499307267,"mc":[{"id":"1.230180121","rc":[{"atb":[[2,5.3],[1.98,0]],"id":53432239},{"atb":[[1.84,0],[1.86,3]],"id":47370245}],"con":true,"img":false}]}
{"op":"mcm","clk":"11540866113","pt":1719499307937,"mc":[{"id":"1.230180121","rc":[{"atb":[[1.48,0]],"id":64536702}],"con":true,"img":false}]}
{"op":"mcm","clk":"11540866121","pt":1719499308038,"mc":[{"id":"1.230180121","rc":[{"atb":[[1.52,2]],"id":64536702}],"con":true,"img":false}]}
{"op":"mcm","clk":"11540866173","pt":1719499308663,"mc":[{"id":"1.230180121","rc":[{"atb":[[1.85,4]],"id":47370245}],"con":true,"img":false}]}
{"op":"mcm","clk":"11540866184","pt":1719499308765,"mc":[{"id":"1.230180121","rc":[{"atb":[[1.87,2]],"id":47370245}],"con":true,"img":false}]}
{"op":"mcm","clk":"11540866190","pt":1719499308868,"mc":[{"id":"1.230180121","rc":[{"atb":[[1.79,5.15]],"id":47370245}],"con":true,"img":false}]}
{"op":"mcm","clk":"11540866202","pt":1719499309075,"mc":[{"id":"1.230180121","rc":[{"atb":[[1.99,3.3]],"id":53432239}],"con":true,"img":false}]}
{"op":"mcm","clk":"11540866207","pt":1719499309136,"mc":[{"id":"1.230180121","rc":[{"atb":[[2.02,2]],"id":53432239}],"con":true,"img":false}]}
{"op":"mcm","clk":"11540866233","pt":1719499309438,"mc":[{"id":"1.230180121","rc":[{"atb":[[1.02,0]],"id":64253834}],"con":true,"img":false}]}
{"op":"mcm","clk":"11540866241","pt":1719499309541,"mc":[{"id":"1.230180121","rc":[{"atb":[[2.16,2]],"id":64253834}],"con":true,"img":false}]}
{"op":"mcm","clk":"11540866256","pt":1719499309850,"mc":[{"id":"1.230180121","rc":[{"atb":[[2.4,0],[3.1,10],[2.44,3.09],[3.5,2.5],[3.3,5]],"id":62847579},{"atl":[[10,3.09],[10.5,3.5],[12.5,5],[14.5,10]],"id":62847579},{"atb":[[2.3,10],[2.04,3],[1.97,5],[2.38,5],[2.46,2.5]],"id":53432239},{"atl":[[19.5,0],[6.2,2.5],[7,8],[7.8,10],[14,2]],"id":53432239},{"atb":[[2.04,10],[2.12,5],[1.79,0],[1.88,3],[2.2,2.5]],"id":47370245},{"atl":[[5.6,3],[16.5,2],[19,0],[5.5,2.5],[6.6,10],[5.9,5]],"id":47370245},{"atb":[[1.58,5],[1.54,10],[1.62,2.5],[1.42,4.46],[1.52,5]],"id":64536702},{"atl":[[4,5],[4.6,3],[3.8,2.5],[4.4,10],[7,2],[9.4,0]],"id":64536702},{"atb":[[1.55,12.09],[1.19,25.94],[1.3,0],[1.51,15.84]],"id":69112387},{"atl":[[3.7,10],[2.98,3.09],[3.3,2.5],[3.5,5],[7,3],[4.7,0]],"id":69112387},{"atb":[[2.12,4.4],[3.25,2.5],[2.94,10],[3.05,5],[2.18,3]],"id":64253834},{"atl":[[8.6,2.5],[36,2],[10.5,10],[7.6,3],[60,0],[9.4,5]],"id":64253834}],"con":true,"img":false}]}
{"op":"mcm","clk":"11540866263","pt":1719499309954,"mc":[{"id":"1.230180121","rc":[{"atb":[[3.1,13.65],[2.42,3.1]],"id":62847579},{"atl":[[70,0],[14.5,12]],"id":62847579},{"atb":[[2,0],[2.3,13.3],[1.97,0]],"id":53432239},{"atb":[[2.2,7.5]],"id":47370245},{"atb":[[2.12,0]],"id":64253834}],"con":true,"img":false}]}
{"op":"mcm","clk":"11540866270","pt":1719499310061,"mc":[{"id":"1.230180121","rc":[{"atl":[[12.5,11.59],[14.5,10]],"id":62847579},{"atb":[[2.04,17.5],[1.86,0],[2.2,2.5]],"id":47370245},{"atl":[[5.7,7.37]],"id":47370245},{"atl":[[2.98,5.07]],"id":69112387}],"con":true,"img":false}]}
{"op":"mcm","clk":"11540866276","pt":1719499310162,"mc":[{"id":"1.230180121","rc":[{"atl":[[9.8,0.84]],"id":62847579},{"atl":[[6,0.84]],"id":53432239},{"atl":[[5.4,0.84]],"id":47370245},{"atl":[[3.75,0.84]],"id":64536702},{"atl":[[2.96,0.84]],"id":69112387},{"atl":[[7.4,0.84]],"id":64253834}],"con":true,"img":false}]}
{"op":"mcm","clk":"11540866293","pt":1719499310370,"mc":[{"id":"1.230180121","rc":[{"atl":[[10.5,13.5],[12.5,5]],"id":62847579},{"atb":[[1.42,0]],"id":64536702}],"con":true,"img":false}]}
{"op":"mcm","clk":"11540866302","pt":1719499310471,"mc":[{"id":"1.230180121","rc":[{"atb":[[1.52,3]],"id":64536702}],"con":true,"img":false}]}
{"op":"mcm","clk":"11540866310","pt":1719499310579,"mc":[{"id":"1.230180121","rc":[{"atb":[[1.63,2]],"id":64536702}],"con":true,"img":false}]}
{"op":"mcm","clk":"11540866317","pt":1719499310627,"mc":[{"id":"1.230180121","rc":[{"atl":[[2.98,3.09]],"id":69112387}],"con":true,"img":false}]}
{"op":"mcm","clk":"11540866322","pt":1719499310832,"mc":[{"id":"1.230180121","rc":[{"atb":[[1.87,0]],"id":47370245}],"con":true,"img":false}]}
{"op":"mcm","clk":"11540866332","pt":1719499310941,"mc":[{"id":"1.230180121","rc":[{"atb":[[1.02,2]],"id":47370245},{"atb":[[1.57,2.11],[1.49,2.12]],"id":64536702},{"atb":[[1.58,2.11],[1.54,0]],"id":69112387}],"con":true,"img":false}]}
{"op":"mcm","clk":"11540866340","pt":1719499311147,"mc":[{"id":"1.230180121","rc":[{"atb":[[2.02,0]],"id":53432239}],"con":true,"img":false}]}
{"op":"mcm","clk":"11540866347","pt":1719499311248,"mc":[{"id":"1.230180121","rc":[{"atb":[[2.48,2]],"id":53432239}],"con":true,"img":false}]}
{"op":"mcm","clk":"11540866353","pt":1719499311355,"mc":[{"id":"1.230180121","rc":[{"atb":[[2.3,10],[2.48,4.5]],"id":53432239}],"con":true,"img":false}]}
{"op":"mcm","clk":"11540866368","pt":1719499311560,"mc":[{"id":"1.230180121","rc":[{"atb":[[2.48,2],[2.38,10]],"id":53432239},{"atb":[[2.16,0]],"id":64253834}],"con":true,"img":false}]}
{"op":"mcm","clk":"11540866376","pt":1719499311667,"mc":[{"id":"1.230180121","rc":[{"atb":[[2.48,6.5],[2.38,5]],"id":53432239},{"atb":[[3.3,2]],"id":64253834}],"con":true,"img":false}]}
{"op":"mcm","clk":"11540866386","pt":1719499311769,"mc":[{"id":"1.230180121","rc":[{"atb":[[2.48,2],[2.38,15]],"id":53432239}],"con":true,"img":false}]}
{"op":"mcm","clk":"11540866397","pt":1719499311873,"mc":[{"id":"1.230180121","rc":[{"atb":[[2.48,7],[2.38,5]],"id":53432239}],"con":true,"img":false}]}
{"op":"mcm","clk":"11540866433","pt":1719499312246,"mc":[{"id":"1.230180121","rc":[{"atl":[[5.7,1]],"id":47370245}],"con":true,"img":false}]}
{"op":"mcm","clk":"11540866449","pt":1719499312450,"mc":[{"id":"1.230180121","rc":[{"atl":[[5.6,4.63]],"id":47370245}],"con":true,"img":false}]}
{"op":"mcm","clk":"11540866460","pt":1719499312554,"mc":[{"id":"1.230180121","rc":[{"atb":[[1.6,5],[1.49,0]],"id":64536702},{"atb":[[3.3,4.5],[2.02,0]],"id":64253834}],"con":true,"img":false}]}
{"op":"mcm","clk":"11540866469","pt":1719499312653,"mc":[{"id":"1.230180121","rc":[{"atb":[[3.3,2],[3.05,10]],"id":64253834}],"con":true,"img":false}]}
{"op":"mcm","clk":"11540866475","pt":1719499312758,"mc":[{"id":"1.230180121","rc":[{"atb":[[3.3,6.5],[3.05,5]],"id":64253834}],"con":true,"img":false}]}
{"op":"mcm","clk":"11540866482","pt":1719499312861,"mc":[{"id":"1.230180121","rc":[{"atb":[[3.3,2],[3.05,15]],"id":64253834}],"con":true,"img":false}]}
{"op":"mcm","clk":"11540866490","pt":1719499312972,"mc":[{"id":"1.230180121","rc":[{"atb":[[3.3,7],[3.05,5]],"id":64253834}],"con":true,"img":false}]}
{"op":"mcm","clk":"11540866496","pt":1719499313074,"mc":[{"id":"1.230180121","rc":[{"atb":[[3.3,2],[3.05,15]],"id":64253834}],"con":true,"img":false}]}
{"op":"mcm","clk":"11540866505","pt":1719499313173,"mc":[{"id":"1.230180121","rc":[{"atb":[[1.57,5.67]],"id":69112387},{"atb":[[3.3,7],[3.05,5]],"id":64253834}],"con":true,"img":false}]}
{"op":"mcm","clk":"11540866514","pt":1719499313278,"mc":[{"id":"1.230180121","rc":[{"atb":[[3.3,2],[3.05,15]],"id":64253834}],"con":true,"img":false}]}
{"op":"mcm","clk":"11540866524","pt":1719499313377,"mc":[{"id":"1.230180121","rc":[{"atb":[[3.3,7],[3.05,5]],"id":64253834}],"con":true,"img":false}]}
{"op":"mcm","clk":"11540866538","pt":1719499313537,"mc":[{"id":"1.230180121","rc":[{"atl":[[5.6,3]],"id":47370245}],"con":true,"img":false}]}
{"op":"mcm","clk":"11540866556","pt":1719499313845,"mc":[{"id":"1.230180121","rc":[{"atl":[[5.4,5.82]],"id":47370245}],"con":true,"img":false}]}
{"op":"mcm","clk":"11540866562","pt":1719499313953,"mc":[{"id":"1.230180121","rc":[{"atb":[[1.55,10.09]],"id":69112387}],"con":true,"img":false}]}
{"op":"mcm","clk":"11540866569","pt":1719499314059,"mc":[{"id":"1.230180121","rc":[{"atb":[[1.59,2]],"id":69112387}],"con":true,"img":false}]}
{"op":"mcm","clk":"11540866594","pt":1719499314361,"mc":[{"id":"1.230180121","rc":[{"atl":[[5.4,0.84]],"id":47370245}],"con":true,"img":false}]}
{"op":"mcm","clk":"11540866613","pt":1719499314668,"mc":[{"id":"1.230180121","rc":[{"atl":[[5.3,3.33]],"id":47370245}],"con":true,"img":false}]}
{"op":"mcm","clk":"11540866657","pt":1719499315239,"mc":[{"id":"1.230180121","rc":[{"atl":[[7,16],[14,0]],"id":53432239},{"atl":[[16.5,0],[5.2,2.5]],"id":47370245},{"atl":[[4,10],[7,0]],"id":64536702},{"atb":[[1.19,0],[1.29,25.94]],"id":69112387},{"atl":[[3,4.94]],"id":69112387},{"atl":[[8.6,7.5],[36,0]],"id":64253834}],"con":true,"img":false}]}
{"op":"mcm","clk":"11540866667","pt":1719499315347,"mc":[{"id":"1.230180121","rc":[{"atl":[[5.3,0]],"id":47370245},{"atl":[[7,0]],"id":69112387}],"con":true,"img":false}]}
{"op":"mcm","clk":"11540866693","pt":1719499315649,"mc":[{"id":"1.230180121","rc":[{"atl":[[5.2,7.95],[5.4,0]],"id":47370245}],"con":true,"img":false}]}
{"op":"mcm","clk":"11540866735","pt":1719499316376,"mc":[{"id":"1.230180121","rc":[{"atl":[[5.2,2.5]],"id":47370245}],"con":true,"img":false}]}
{"op":"mcm","clk":"11540866757","pt":1719499316683,"mc":[{"id":"1.230180121","rc":[{"atl":[[5,3.78]],"id":47370245}],"con":true,"img":false}]}
{"op":"mcm","clk":"11540866773","pt":1719499316884,"mc":[{"id":"1.230180121","rc":[{"atl":[[5,0]],"id":47370245}],"con":true,"img":false}]}
{"op":"mcm","clk":"11540866782","pt":1719499317045,"mc":[{"id":"1.230180121","rc":[{"atl":[[4.8,1.56]],"id":47370245},{"atb":[[1.61,6.94]],"id":69112387}],"con":true,"img":false}]}
{"op":"mcm","clk":"11540866787","pt":1719499317141,"mc":[{"id":"1.230180121","rc":[{"atl":[[5.1,0.84]],"id":47370245}],"con":true,"img":false}]}
{"op":"mcm","clk":"11540866800","pt":1719499317353,"mc":[{"id":"1.230180121","rc":[{"atb":[[1.57,12.51]],"id":64536702}],"con":true,"img":false}]}
{"op":"mcm","clk":"11540866812","pt":1719499317560,"mc":[{"id":"1.230180121","rc":[{"atl":[[4.8,0]],"id":47370245},{"atb":[[1.48,0]],"id":69112387}],"con":true,"img":false}]}
{"op":"mcm","clk":"11540866829","pt":1719499317863,"mc":[{"id":"1.230180121","rc":[{"atl":[[4.8,5.5]],"id":47370245}],"con":true,"img":false}]}
{"op":"mcm","clk":"11540866847","pt":1719499318173,"mc":[{"id":"1.230180121","rc":[{"atl":[[5.1,0]],"id":47370245}],"con":true,"img":false}]}
{"op":"mcm","clk":"11540866870","pt":1719499318482,"mc":[{"id":"1.230180121","rc":[{"atb":[[1.65,6.51]],"id":64536702},{"atb":[[1.59,0],[1.58,12.33]],"id":69112387}],"con":true,"img":false}]}
{"op":"mcm","clk":"11540866878","pt":1719499318585,"mc":[{"id":"1.230180121","rc":[{"atb":[[1.62,2]],"id":69112387}],"con":true,"img":false}]}
{"op":"mcm","clk":"11540866999","pt":1719499319879,"mc":[{"id":"1.230180121","rc":[{"atb":[[1.6,0],[1.63,15.02]],"id":64536702}],"con":true,"img":false}]}
{"op":"mcm","clk":"11540867036","pt":1719499320349,"mc":[{"id":"1.230180121","rc":[{"atl":[[4.8,0]],"id":47370245}],"con":true,"img":false}]}
{"op":"mcm","clk":"11540867047","pt":1719499320449,"mc":[{"id":"1.230180121","rc":[{"atl":[[5.6,8]],"id":47370245},{"atb":[[1.63,13.02]],"id":64536702}],"con":true,"img":false}]}
{"op":"mcm","clk":"11540867056","pt":1719499320556,"mc":[{"id":"1.230180121","rc":[{"atl":[[5.2,0]],"id":47370245},{"atb":[[1.66,2]],"id":64536702}],"con":true,"img":false}]}
{"op":"mcm","clk":"11540867065","pt":1719499320656,"mc":[{"id":"1.230180121","rc":[{"atl":[[5.6,3],[5.7,11.5],[4.7,1.63]],"id":47370245},{"atl":[[8.6,2.5],[7.8,6]],"id":64253834}],"con":true,"img":false}]}
{"op":"mcm","clk":"11540867071","pt":1719499320760,"mc":[{"id":"1.230180121","rc":[{"atl":[[5.7,1],[4.7,4.13]],"id":47370245}],"con":true,"img":false}]}
{"op":"mcm","clk":"11540867090","pt":1719499320965,"mc":[{"id":"1.230180121","rc":[{"atb":[[2.42,1]],"id":62847579},{"atb":[[1.99,0]],"id":53432239},{"atb":[[1.85,0]],"id":47370245},{"atb":[[1.51,1]],"id":64536702},{"atb":[[1.55,5.59]],"id":69112387},{"atb":[[2.14,0]],"id":64253834}],"con":true,"img":false}]}
{"op":"mcm","clk":"11540867110","pt":1719499321177,"mc":[{"id":"1.230180121","rc":[{"atb":[[3.5,4.77]],"id":62847579},{"atb":[[2.5,2]],"id":53432239},{"atb":[[2.2,5.1]],"id":47370245},{"atb":[[1.66,7]],"id":64536702},{"atb":[[1.62,6]],"id":69112387},{"atb":[[3.35,2.23]],"id":64253834}],"con":true,"img":false}]}
{"op":"mcm","clk":"11540867118","pt":1719499321275,"mc":[{"id":"1.230180121","rc":[{"atb":[[3.1,10],[3.3,14.54]],"id":62847579},{"atb":[[2.04,10],[2.2,10.2]],"id":47370245}],"con":true,"img":false}]}
{"op":"mcm","clk":"11540867147","pt":1719499321582,"mc":[{"id":"1.230180121","rc":[{"atb":[[3.5,15.85]],"id":62847579},{"atl":[[9.8,9.93]],"id":62847579},{"atb":[[2.5,5.75]],"id":53432239},{"atl":[[6,4.59]],"id":53432239},{"atl":[[4.6,6.85]],"id":47370245},{"atb":[[1.66,17.13]],"id":64536702},{"atb":[[1.62,14.21]],"id":69112387},{"atb":[[3.4,4.12]],"id":64253834},{"atl":[[7.4,4.96]],"id":64253834}],"con":true,"img":false}]}
{"op":"mcm","clk":"11540867155","pt":1719499321687,"mc":[{"id":"1.230180121","rc":[{"atb":[[2.44,0]],"id":62847579},{"atl":[[10,0]],"id":62847579},{"atb":[[2.04,0]],"id":53432239},{"atl":[[7,13]],"id":53432239},{"atb":[[2.2,17.05]],"id":47370245},{"atl":[[5.6,0]],"id":47370245},{"atb":[[1.52,0]],"id":64536702},{"atl":[[3.75,10.97]],"id":64536702},{"atb":[[1.55,2.5]],"id":69112387},{"atl":[[2.96,9.05]],"id":69112387},{"atb":[[2.18,0]],"id":64253834},{"atl":[[7.6,0]],"id":64253834}],"con":true,"img":false}]}
{"op":"mcm","clk":"11540867162","pt":1719499321742,"mc":[{"id":"1.230180121","rc":[{"atb":[[2.48,5]],"id":53432239},{"atl":[[4.7,2.5]],"id":47370245}],"con":true,"img":false}]}
{"op":"mcm","clk":"11540867170","pt":1719499321851,"mc":[{"id":"1.230180121","rc":[{"atb":[[2.52,2]],"id":53432239},{"atb":[[1.88,0]],"id":47370245},{"atl":[[4,5],[4.6,0],[3.7,10]],"id":64536702},{"atl":[[3,1],[2.98,0],[2.94,4.94]],"id":69112387}],"con":true,"img":false}]}
{"op":"mcm","clk":"11540867183","pt":1719499321952,"mc":[{"id":"1.230180121","rc":[{"atl":[[5.5,11.85],[4.7,0]],"id":47370245},{"atl":[[3.7,0],[3.8,23.48]],"id":64536702},{"atl":[[2.98,14],[2.94,0]],"id":69112387}],"con":true,"img":false}]}
{"op":"mcm","clk":"11540867190","pt":1719499322058,"mc":[{"id":"1.230180121","rc":[{"atl":[[4.5,2.66]],"id":47370245}],"con":true,"img":false}]}
{"op":"mcm","clk":"11540867203","pt":1719499322156,"mc":[{"id":"1.230180121","rc":[{"atl":[[4.5,9.51],[5.5,2.5]],"id":47370245},{"atl":[[3.65,0.84]],"id":64536702},{"atl":[[2.92,0.84]],"id":69112387}],"con":true,"img":false}]}
{"op":"mcm","clk":"11540867226","pt":1719499322371,"mc":[{"id":"1.230180121","rc":[{"atl":[[4.5,6.85]],"id":47370245}],"con":true,"img":false}]}
{"op":"mcm","clk":"11540867239","pt":1719499322470,"mc":[{"id":"1.230180121","rc":[{"atl":[[4.5,0],[5.5,16.2]],"id":47370245},{"atb":[[1.57,0]],"id":69112387}],"con":true,"img":false}]}
{"op":"mcm","clk":"11540867259","pt":1719499322675,"mc":[{"id":"1.230180121","rc":[{"atl":[[4.6,0]],"id":47370245},{"atl":[[3.65,0]],"id":64536702},{"atl":[[2.92,0]],"id":69112387},{"atb":[[3.3,5]],"id":64253834}],"con":true,"img":false}]}
{"op":"mcm","clk":"11540867269","pt":1719499322776,"mc":[{"id":"1.230180121","rc":[{"atl":[[4.3,1.76],[4.7,12.64]],"id":47370245},{"atl":[[4,38.33],[3.8,2.5]],"id":64536702},{"atl":[[3,24.06],[2.98,0]],"id":69112387},{"atb":[[3.4,6.12]],"id":64253834},{"atl":[[8.6,13.47],[7.8,1]],"id":64253834}],"con":true,"img":false}]}
{"op":"mcm","clk":"11540867278","pt":1719499322883,"mc":[{"id":"1.230180121","rc":[{"atb":[[3.4,11.12],[3.3,0]],"id":64253834}],"con":true,"img":false}]}
{"op":"mcm","clk":"11540867302","pt":1719499323148,"mc":[{"id":"1.230180121","rc":[{"atl":[[4.3,0]],"id":47370245}],"con":true,"img":false}]}
{"op":"mcm","clk":"11540867313","pt":1719499323242,"mc":[{"id":"1.230180121","rc":[{"atb":[[1.69,2.11],[1.57,10.39]],"id":64536702},{"atb":[[1.58,10.21],[1.65,2.11]],"id":69112387}],"con":true,"img":false}]}
{"op":"mcm","clk":"11540867329","pt":1719499323448,"mc":[{"id":"1.230180121","rc":[{"atl":[[4.4,1.72]],"id":47370245}],"con":true,"img":false}]}
{"op":"mcm","clk":"11540867340","pt":1719499323658,"mc":[{"id":"1.230180121","rc":[{"atb":[[1.7,7.89]],"id":64536702}],"con":true,"img":false}]}
{"op":"mcm","clk":"11540867354","pt":1719499323862,"mc":[{"id":"1.230180121","rc":[{"atb":[[1.51,5]],"id":69112387}],"con":true,"img":false}]}
{"op":"mcm","clk":"11540867361","pt":1719499323964,"mc":[{"id":"1.230180121","rc":[{"atl":[[4.4,0]],"id":47370245},{"atb":[[1.46,0]],"id":64536702}],"con":true,"img":false}]}
{"op":"mcm","clk":"11540867369","pt":1719499324185,"mc":[{"id":"1.230180121","rc":[{"atb":[[1.66,8.37]],"id":69112387}],"con":true,"img":false}]}
{"op":"mcm","clk":"11540867375","pt":1719499324272,"mc":[{"id":"1.230180121","rc":[{"atl":[[4.3,4.22]],"id":47370245},{"atb":[[1.68,5.8],[1.66,15.13]],"id":64536702}],"con":true,"img":false}]}
{"op":"mcm","clk":"11540867378","pt":1719499324375,"mc":[{"id":"1.230180121","rc":[{"atb":[[1.71,2]],"id":64536702}],"con":true,"img":false}]}
{"op":"mcm","clk":"11540867402","pt":1719499324689,"mc":[{"id":"1.230180121","rc":[{"atl":[[4.2,0.84]],"id":47370245},{"atb":[[1.62,12.21]],"id":69112387}],"con":true,"img":false}]}
{"op":"mcm","clk":"11540867410","pt":1719499324786,"mc":[{"id":"1.230180121","rc":[{"atb":[[1.66,10.37]],"id":69112387}],"con":true,"img":false}]}
{"op":"mcm","clk":"11540867428","pt":1719499324993,"mc":[{"id":"1.230180121","rc":[{"atb":[[2.5,10.75],[2.48,0]],"id":53432239}],"con":true,"img":false}]}
{"op":"mcm","clk":"11540867548","pt":1719499326544,"mc":[{"id":"1.230180121","rc":[{"atb":[[3.35,31.7],[3.3,5]],"id":62847579}],"con":true,"img":false}]}
{"op":"mcm","clk":"11540867554","pt":1719499326652,"mc":[{"id":"1.230180121","rc":[{"atl":[[12.5,13.7]],"id":62847579}],"con":true,"img":false}]}
{"op":"mcm","clk":"11540867561","pt":1719499326755,"mc":[{"id":"1.230180121","rc":[{"atl":[[10.5,3.5]],"id":62847579}],"con":true,"img":false}]}
{"op":"mcm","clk":"11540867579","pt":1719499326958,"mc":[{"id":"1.230180121","rc":[{"atl":[[4.3,0]],"id":47370245}],"con":true,"img":false}]}
{"op":"mcm","clk":"11540867602","pt":1719499327269,"mc":[{"id":"1.230180121","rc":[{"atl":[[4.2,2.62]],"id":47370245}],"con":true,"img":false}]}
{"op":"mcm","clk":"11540867635","pt":1719499327839,"mc":[{"id":"1.230180121","rc":[{"atl":[[5.5,2.5],[4.2,15.26]],"id":47370245}],"con":true,"img":false}]}
{"op":"mcm","clk":"11540867640","pt":1719499327891,"mc":[{"id":"1.230180121","rc":[{"atb":[[3.25,5.37]],"id":62847579},{"atl":[[3,1],[3.3,35.62]],"id":69112387}],"con":true,"img":false}]}
{"op":"mcm","clk":"11540867648","pt":1719499327946,"mc":[{"id":"1.230180121","rc":[{"atl":[[5.5,17.77],[4.2,2.62]],"id":47370245},{"atb":[[3.35,24.47]],"id":64253834}],"con":true,"img":false}]}
{"op":"mcm","clk":"11540867655","pt":1719499328054,"mc":[{"id":"1.230180121","rc":[{"atl":[[5.5,2.5],[4.2,13.48]],"id":47370245},{"atb":[[3.4,6.12]],"id":64253834}],"con":true,"img":false}]}
{"op":"mcm","clk":"11540867666","pt":1719499328158,"mc":[{"id":"1.230180121","rc":[{"atl":[[5.5,17.77]],"id":47370245}],"con":true,"img":false}]}
{"op":"mcm","clk":"11540867678","pt":1719499328256,"mc":[{"id":"1.230180121","rc":[{"atl":[[4.2,0.84]],"id":47370245}],"con":true,"img":false}]}
{"op":"mcm","clk":"11540867698","pt":1719499328462,"mc":[{"id":"1.230180121","rc":[{"atl":[[4.2,6.05]],"id":47370245}],"con":true,"img":false}]}
{"op":"mcm","clk":"11540867704","pt":1719499328565,"mc":[{"id":"1.230180121","rc":[{"atl":[[4.2,18.69]],"id":47370245}],"con":true,"img":false}]}
{"op":"mcm","clk":"11540867713","pt":1719499328675,"mc":[{"id":"1.230180121","rc":[{"atl":[[5.5,2.5],[4.2,17.85]],"id":47370245}],"con":true,"img":false}]}
{"op":"mcm","clk":"11540867765","pt":1719499329505,"mc":[{"id":"1.230180121","rc":[{"atl":[[4.2,12.64]],"id":47370245}],"con":true,"img":false}]}
{"op":"mcm","clk":"11540867775","pt":1719499329600,"mc":[{"id":"1.230180121","rc":[{"atl":[[5.5,24.72],[4.2,0]],"id":47370245}],"con":true,"img":false}]}
{"op":"mcm","clk":"11540867784","pt":1719499329648,"mc":[{"id":"1.230180121","rc":[{"atl":[[4.1,1.98]],"id":47370245}],"con":true,"img":false}]}
{"op":"mcm","clk":"11540867789","pt":1719499329753,"mc":[{"id":"1.230180121","rc":[{"atb":[[3.5,13.58]],"id":62847579},{"atb":[[2.5,8.75]],"id":53432239},{"atb":[[2.2,14.45]],"id":47370245},{"atl":[[5.5,2.5],[4.2,12.64]],"id":47370245},{"atb":[[1.66,10.13]],"id":64536702},{"atb":[[1.62,8.21]],"id":69112387},{"atb":[[3.35,22.24]],"id":64253834}],"con":true,"img":false}]}
{"op":"mcm","clk":"11540867799","pt":1719499329860,"mc":[{"id":"1.230180121","rc":[{"atb":[[2.52,4.28]],"id":53432239},{"atb":[[2.04,29.45]],"id":47370245},{"atb":[[1.71,5.53]],"id":64536702},{"atb":[[1.67,4]],"id":69112387},{"atb":[[3.45,2.78]],"id":64253834}],"con":true,"img":false}]}
{"op":"mcm","clk":"11540867807","pt":1719499329959,"mc":[{"id":"1.230180121","rc":[{"atb":[[3.35,0],[3.3,48.48]],"id":62847579},{"atb":[[2.2,9.35]],"id":47370245}],"con":true,"img":false}]}
{"op":"mcm","clk":"11540867827","pt":1719499330170,"mc":[{"id":"1.230180121","rc":[{"atb":[[3.25,0]],"id":62847579}],"con":true,"img":false}]}
{"op":"mcm","clk":"11540867837","pt":1719499330272,"mc":[{"id":"1.230180121","rc":[{"atb":[[3.35,0],[3.3,12.24]],"id":64253834}],"con":true,"img":false}]}
{"op":"mcm","clk":"11540867847","pt":1719499330371,"mc":[{"id":"1.230180121","rc":[{"atb":[[3.1,57.62],[3.3,5]],"id":62847579}],"con":true,"img":false}]}
{"op":"mcm","clk":"11540867858","pt":1719499330473,"mc":[{"id":"1.230180121","rc":[{"atb":[[3.45,12.42]],"id":64253834},{"atl":[[7.4,8.45]],"id":64253834}],"con":true,"img":false}]}
{"op":"mcm","clk":"11540867866","pt":1719499330581,"mc":[{"id":"1.230180121","rc":[{"atl":[[8.6,2.5],[7.8,15.71]],"id":64253834}],"con":true,"img":false}]}
{"op":"mcm","clk":"11540867931","pt":1719499331352,"mc":[{"id":"1.230180121","rc":[{"atb":[[1.66,8.37]],"id":69112387}],"con":true,"img":false}]}
{"op":"mcm","clk":"11540867939","pt":1719499331453,"mc":[{"id":"1.230180121","rc":[{"atb":[[1.68,2]],"id":69112387}],"con":true,"img":false}]}
{"op":"mcm","clk":"11540867951","pt":1719499331660,"mc":[{"id":"1.230180121","rc":[{"atl":[[4,0.84]],"id":47370245}],"con":true,"img":false}]}
{"op":"mcm","clk":"11540867972","pt":1719499332084,"mc":[{"id":"1.230180121","rc":[{"atb":[[3.4,4.12]],"id":64253834}],"con":true,"img":false}]}
{"op":"mcm","clk":"11540867982","pt":1719499332181,"mc":[{"id":"1.230180121","rc":[{"atb":[[3.5,2]],"id":64253834}],"con":true,"img":false}]}
{"op":"mcm","clk":"11540867996","pt":1719499332390,"mc":[{"id":"1.230180121","rc":[{"atb":[[1.64,5.23]],"id":64536702}],"con":true,"img":false}]}
{"op":"mcm","clk":"11540868013","pt":1719499332595,"mc":[{"id":"1.230180121","rc":[{"atb":[[1.64,0]],"id":64536702}],"con":true,"img":false}]}
{"op":"mcm","clk":"11540868019","pt":1719499332649,"mc":[{"id":"1.230180121","rc":[{"atb":[[1.43,0]],"id":69112387}],"con":true,"img":false}]}
{"op":"mcm","clk":"11540868028","pt":1719499332753,"mc":[{"id":"1.230180121","rc":[{"atb":[[3.45,10.79]],"id":64253834}],"con":true,"img":false}]}
{"op":"mcm","clk":"11540868037","pt":1719499332859,"mc":[{"id":"1.230180121","rc":[{"atb":[[2.48,4.79]],"id":53432239},{"atb":[[2.18,5.12]],"id":47370245}],"con":true,"img":false}]}
{"op":"mcm","clk":"11540868046","pt":1719499332960,"mc":[{"id":"1.230180121","rc":[{"atb":[[2.48,3.68]],"id":53432239},{"atb":[[2.04,10],[2.12,23.7],[2.18,4.41]],"id":47370245},{"atb":[[3.45,2.78]],"id":64253834}],"con":true,"img":false}]}
{"op":"mcm","clk":"11540868055","pt":1719499333071,"mc":[{"id":"1.230180121","rc":[{"atb":[[2.52,11.32]],"id":53432239},{"atl":[[5.9,7.04]],"id":53432239},{"atl":[[4,8.43]],"id":47370245},{"atb":[[1.71,15.6]],"id":64536702},{"atb":[[1.68,11.28]],"id":69112387},{"atb":[[3.5,19.45]],"id":64253834}],"con":true,"img":false}]}
{"op":"mcm","clk":"11540868066","pt":1719499333172,"mc":[{"id":"1.230180121","rc":[{"atb":[[2.5,0],[2.48,16.71]],"id":53432239},{"atl":[[6.2,11.7],[6,0.84],[7,5]],"id":53432239},{"atl":[[4.7,0]],"id":47370245},{"atb":[[1.66,0]],"id":64536702},{"atl":[[3.7,10.07]],"id":64536702},{"atb":[[1.62,0]],"id":69112387},{"atb":[[3.4,0]],"id":64253834}],"con":true,"img":false}]}
{"op":"mcm","clk":"11540868075","pt":1719499333269,"mc":[{"id":"1.230180121","rc":[{"atl":[[3.8,24.46]],"id":64536702}],"con":true,"img":false}]}
{"op":"mcm","clk":"11540868081","pt":1719499333372,"mc":[{"id":"1.230180121","rc":[{"atl":[[4,5],[3.75,0.84]],"id":64536702}],"con":true,"img":false}]}
{"op":"mcm","clk":"11540868094","pt":1719499333580,"mc":[{"id":"1.230180121","rc":[{"atl":[[5.8,0.84]],"id":53432239},{"atl":[[3.65,0.84]],"id":64536702}],"con":true,"img":false}]}
{"op":"mcm","clk":"11540868115","pt":1719499333993,"mc":[{"id":"1.230180121","rc":[{"atb":[[2.48,13.03]],"id":53432239}],"con":true,"img":false}]}
{"op":"mcm","clk":"11540868161","pt":1719499334765,"mc":[{"id":"1.230180121","rc":[{"atb":[[3.35,22.23],[3.3,0]],"id":64253834}],"con":true,"img":false}]}
{"op":"mcm","clk":"11540868198","pt":1719499335384,"mc":[{"id":"1.230180121","rc":[{"atb":[[2.58,2.11],[1.66,0]],"id":53432239},{"atb":[[2.24,2.11],[1.82,0]],"id":47370245},{"atb":[[1.69,0],[1.74,2.11]],"id":64536702},{"atb":[[1.71,2.11],[1.65,0]],"id":69112387}],"con":true,"img":false}]}
{"op":"mcm","clk":"11540868206","pt":1719499335489,"mc":[{"id":"1.230180121","rc":[{"atb":[[2.24,16.16],[2.12,5]],"id":47370245}],"con":true,"img":false}]}
{"op":"mcm","clk":"11540868215","pt":1719499335591,"mc":[{"id":"1.230180121","rc":[{"atb":[[2.24,11.75],[2.18,15.88],[2.2,2.5]],"id":47370245},{"atb":[[1.66,14.04]],"id":69112387}],"con":true,"img":false}]}
{"op":"mcm","clk":"11540868222","pt":1719499335697,"mc":[{"id":"1.230180121","rc":[{"atb":[[2.24,21.1],[2.18,4.41]],"id":47370245}],"con":true,"img":false}]}
{"op":"mcm","clk":"11540868232","pt":1719499335796,"mc":[{"id":"1.230180121","rc":[{"atb":[[2.24,11.75],[2.18,18.67]],"id":47370245}],"con":true,"img":false}]}
{"op":"mcm","clk":"11540868238","pt":1719499335901,"mc":[{"id":"1.230180121","rc":[{"atb":[[2.24,16.16]],"id":47370245}],"con":true,"img":false}]}
{"op":"mcm","clk":"11540868246","pt":1719499335951,"mc":[{"id":"1.230180121","rc":[{"atb":[[2.18,0]],"id":47370245}],"con":true,"img":false}]}
{"op":"mcm","clk":"11540868320","pt":1719499336881,"mc":[{"id":"1.230180121","rc":[{"atb":[[1.71,13.6]],"id":64536702}],"con":true,"img":false}]}
{"op":"mcm","clk":"11540868326","pt":1719499336984,"mc":[{"id":"1.230180121","rc":[{"atb":[[1.75,2]],"id":64536702}],"con":true,"img":false}]}
{"op":"mcm","clk":"11540868389","pt":1719499337763,"mc":[{"id":"1.230180121","rc":[{"atb":[[1.68,9.28]],"id":69112387}],"con":true,"img":false}]}
{"op":"mcm","clk":"11540868398","pt":1719499337863,"mc":[{"id":"1.230180121","rc":[{"atb":[[1.72,2]],"id":69112387}],"con":true,"img":false}]}
{"op":"mcm","clk":"11540868430","pt":1719499338277,"mc":[{"id":"1.230180121","rc":[{"atb":[[2.52,9.32]],"id":53432239}],"con":true,"img":false}]}
{"op":"mcm","clk":"11540868439","pt":1719499338381,"mc":[{"id":"1.230180121","rc":[{"atb":[[2.5,13.44],[2.6,2],[2.48,0],[2.52,7.04]],"id":53432239},{"atb":[[1.71,10.07]],"id":64536702},{"atb":[[1.67,0]],"id":69112387},{"atb":[[3.45,0]],"id":64253834}],"con":true,"img":false}]}
{"op":"mcm","clk":"11540868446","pt":1719499338489,"mc":[{"id":"1.230180121","rc":[{"atb":[[2.58,4.91]],"id":53432239},{"atb":[[1.75,6]],"id":64536702},{"atb":[[1.72,6]],"id":69112387},{"atb":[[3.55,3.3]],"id":64253834}],"con":true,"img":false}]}
{"op":"mcm","clk":"11540868472","pt":1719499338897,"mc":[{"id":"1.230180121","rc":[{"atb":[[3.5,11.44]],"id":64253834}],"con":true,"img":false}]}
{"op":"mcm","clk":"11540868526","pt":1719499339567,"mc":[{"id":"1.230180121","rc":[{"atb":[[3.55,11.44]],"id":64253834}],"con":true,"img":false}]}
{"op":"mcm","clk":"11540868535","pt":1719499339668,"mc":[{"id":"1.230180121","rc":[{"atb":[[3.45,4.38]],"id":64253834}],"con":true,"img":false}]}
{"op":"mcm","clk":"11540868578","pt":1719499340183,"mc":[{"id":"1.230180121","rc":[{"atb":[[1.7,0],[1.68,0]],"id":64536702}],"con":true,"img":false}]}
{"op":"mcm","clk":"11540868587","pt":1719499340286,"mc":[{"id":"1.230180121","rc":[{"atb":[[3.45,3.75]],"id":64253834}],"con":true,"img":false}]}
{"op":"mcm","clk":"11540868595","pt":1719499340389,"mc":[{"id":"1.230180121","rc":[{"atb":[[1.66,5.67]],"id":69112387}],"con":true,"img":false}]}
{"op":"mcm","clk":"11540868615","pt":1719499340594,"mc":[{"id":"1.230180121","rc":[{"atb":[[1.72,13.67]],"id":69112387}],"con":true,"img":false}]}
{"op":"mcm","clk":"11540868634","pt":1719499340905,"mc":[{"id":"1.230180121","rc":[{"atb":[[3.5,9.44]],"id":64253834}],"con":true,"img":false}]}
{"op":"mcm","clk":"11540868641","pt":1719499341010,"mc":[{"id":"1.230180121","rc":[{"atb":[[3.6,2]],"id":64253834}],"con":true,"img":false}]}
{"op":"mcm","clk":"11540868683","pt":1719499341375,"mc":[{"id":"1.230180121","rc":[{"atb":[[3.45,0]],"id":64253834}],"con":true,"img":false}]}
{"op":"mcm","clk":"11540868735","pt":1719499341988,"mc":[{"id":"1.230180121","rc":[{"atb":[[3.55,3.3]],"id":64253834}],"con":true,"img":false}]}
{"op":"mcm","clk":"11540868781","pt":1719499342507,"mc":[{"id":"1.230180121","rc":[{"atb":[[1.66,0]],"id":69112387}],"con":true,"img":false}]}
{"op":"mcm","clk":"11540868828","pt":1719499343083,"mc":[{"id":"1.230180121","rc":[{"atb":[[3.6,10.86]],"id":64253834}],"con":true,"img":false}]}
{"op":"mcm","clk":"11540868936","pt":1719499344374,"mc":[{"id":"1.230180121","rc":[{"atb":[[2.6,7.19]],"id":53432239},{"atl":[[5.8,6.03]],"id":53432239},{"atb":[[1.72,27.43]],"id":69112387},{"atb":[[3.65,13.42]],"id":64253834}],"con":true,"img":false}]}
{"op":"mcm","clk":"11540868942","pt":1719499344388,"mc":[{"id":"1.230180121","rc":[{"atb":[[1.75,12.09]],"id":64536702}],"con":true,"img":false}]}
{"op":"mcm","clk":"11540868948","pt":1719499344480,"mc":[{"id":"1.230180121","rc":[{"atb":[[2.52,0]],"id":53432239},{"atl":[[5.9,0]],"id":53432239},{"atb":[[1.71,0]],"id":64536702},{"atl":[[3.65,6.93]],"id":64536702},{"atb":[[1.68,0]],"id":69112387},{"atb":[[3.5,0]],"id":64253834}],"con":true,"img":false}]}
{"op":"mcm","clk":"11540868955","pt":1719499344584,"mc":[{"id":"1.230180121","rc":[{"atl":[[3.7,0]],"id":64536702}],"con":true,"img":false}]}
{"op":"mcm","clk":"11540868960","pt":1719499344684,"mc":[{"id":"1.230180121","rc":[{"atl":[[6,0]],"id":53432239}],"con":true,"img":false}]}
{"op":"mcm","clk":"11540868972","pt":1719499344788,"mc":[{"id":"1.230180121","rc":[{"atl":[[6.2,2.5],[7,21.67]],"id":53432239}],"con":true,"img":false}]}
{"op":"mcm","clk":"11540868991","pt":1719499345099,"mc":[{"id":"1.230180121","rc":[{"atl":[[3.75,0]],"id":64536702},{"atb":[[3.6,2]],"id":64253834}],"con":true,"img":false}]}
{"op":"mcm","clk":"11540868999","pt":1719499345201,"mc":[{"id":"1.230180121","rc":[{"atl":[[3.8,2.5]],"id":64536702}],"con":true,"img":false}]}
{"op":"mcm","clk":"11540869007","pt":1719499345303,"mc":[{"id":"1.230180121","rc":[{"atl":[[4,36.4]],"id":64536702}],"con":true,"img":false}]}
{"op":"mcm","clk":"11540869067","pt":1719499345971,"mc":[{"id":"1.230180121","rc":[{"atb":[[3.65,22.7]],"id":64253834}],"con":true,"img":false}]}
{"op":"mcm","clk":"11540869141","pt":1719499346797,"mc":[{"id":"1.230180121","rc":[{"spn":6.65,"spf":"NaN","id":62847579},{"spn":4.2,"spf":"NaN","id":53432239},{"spn":3.12,"spf":"NaN","id":47370245},{"spn":2.7,"spf":"NaN","id":64536702},{"spn":2.34,"spf":"NaN","id":69112387},{"atb":[[3.6,0]],"id":64253834},{"spn":5.52,"spf":"NaN","id":64253834}],"con":true,"img":false}]}
{"op":"mcm","clk":"11540869152","pt":1719499346903,"mc":[{"id":"1.230180121","rc":[{"atb":[[1.02,2]],"id":64253834}],"con":true,"img":false}]}
{"op":"mcm","clk":"11540869177","pt":1719499347208,"mc":[{"id":"1.230180121","rc":[{"atb":[[2.58,2.11]],"id":53432239},{"atb":[[1.75,8.09]],"id":64536702},{"atb":[[1.72,23.43]],"id":69112387},{"atb":[[3.55,0]],"id":64253834}],"con":true,"img":false}]}
{"op":"mcm","clk":"11540869196","pt":1719499347416,"mc":[{"id":"1.230180121","rc":[{"atb":[[3.55,2.92]],"id":62847579},{"atb":[[2.62,2.7]],"id":53432239},{"atb":[[1.76,4]],"id":64536702},{"atb":[[1.73,3.96]],"id":69112387},{"atb":[[3.7,2.3]],"id":64253834}],"con":true,"img":false}]}
{"op":"mcm","clk":"11540869211","pt":1719499347628,"mc":[{"id":"1.230180121","rc":[{"atb":[[3.45,16.5],[3.1,10],[3.55,14.12]],"id":62847579},{"atb":[[1.6,3]],"id":69112387}],"con":true,"img":false}]}
{"op":"mcm","clk":"11540869222","pt":1719499347774,"mc":[{"id":"1.230180121","rc":[{"atb":[[3.5,2.5]],"id":62847579},{"atb":[[1.6,0]],"id":69112387}],"con":true,"img":false}]}
{"op":"mcm","clk":"11540869253","pt":1719499348393,"mc":[{"id":"1.230180121","rc":[{"atb":[[3.65,20.96]],"id":64253834}],"con":true,"img":false}]}
{"op":"mcm","clk":"11540869274","pt":1719499348715,"mc":[{"id":"1.230180121","rc":[{"atb":[[3.35,0],[3.4,23.26]],"id":64253834}],"con":true,"img":false}]}
{"op":"mcm","clk":"11540869279","pt":1719499348802,"mc":[{"id":"1.230180121","rc":[{"atl":[[8,1],[7.6,15.15],[7.8,14.71]],"id":64253834}],"con":true,"img":false}]}
{"op":"mcm","clk":"11540869288","pt":1719499348906,"mc":[{"id":"1.230180121","rc":[{"atl":[[7.8,0]],"id":64253834}],"con":true,"img":false}]}
{"op":"mcm","clk":"11540869296","pt":1719499349009,"mc":[{"id":"1.230180121","rc":[{"atb":[[1.75,6.09]],"id":64536702},{"atb":[[3.65,13.42]],"id":64253834}],"con":true,"img":false}]}
{"op":"mcm","clk":"11540869304","pt":1719499349133,"mc":[{"id":"1.230180121","rc":[{"atb":[[1.77,2]],"id":64536702},{"atb":[[3.7,9.84]],"id":64253834}],"con":true,"img":false}]}
{"op":"mcm","clk":"11540869319","pt":1719499349292,"mc":[{"id":"1.230180121","rc":[{"atb":[[1.34,25.94],[1.29,0]],"id":69112387}],"con":true,"img":false}]}
{"op":"mcm","clk":"11540869332","pt":1719499349496,"mc":[{"id":"1.230180121","rc":[{"atb":[[3.4,3.62]],"id":62847579},{"atb":[[1.72,21.43]],"id":69112387}],"con":true,"img":false}]}
{"op":"mcm","clk":"11540869339","pt":1719499349600,"mc":[{"id":"1.230180121","rc":[{"atb":[[1.74,2]],"id":69112387}],"con":true,"img":false}]}
{"op":"mcm","clk":"11540869364","pt":1719499350014,"mc":[{"id":"1.230180121","rc":[{"atb":[[2.6,5.19]],"id":53432239}],"con":true,"img":false}]}
{"op":"mcm","clk":"11540869373","pt":1719499350115,"mc":[{"id":"1.230180121","rc":[{"atb":[[2.64,2]],"id":53432239}],"con":true,"img":false}]}
{"op":"mcm","clk":"11540869429","pt":1719499350792,"mc":[{"id":"1.230180121","rc":[{"atb":[[2.24,11.75],[2.16,18.67]],"id":47370245}],"con":true,"img":false}]}
{"op":"mcm","clk":"11540869436","pt":1719499350892,"mc":[{"id":"1.230180121","rc":[{"atb":[[2.12,23.67],[2.16,0]],"id":47370245}],"con":true,"img":false}]}
{"op":"mcm","clk":"11540869617","pt":1719499353524,"mc":[{"id":"1.230180121","rc":[{"atl":[[10.5,2.5],[11,1]],"id":62847579}],"con":true,"img":false}]}
{"op":"mcm","clk":"11540869624","pt":1719499353626,"mc":[{"id":"1.230180121","rc":[{"atl":[[11,11],[12.5,5]],"id":62847579}],"con":true,"img":false}]}
{"op":"mcm","clk":"11540869638","pt":1719499353782,"mc":[{"id":"1.230180121","rc":[{"atb":[[3.4,0]],"id":62847579},{"atb":[[2.52,5]],"id":53432239},{"atb":[[2.12,4.99],[2.14,14.26]],"id":47370245},{"atb":[[1.73,5.23]],"id":64536702},{"atl":[[4.6,1],[4.7,0]],"id":64536702},{"atl":[[3.1,1]],"id":69112387},{"atb":[[3.5,23.26],[3.4,0]],"id":64253834}],"con":true,"img":false}]}
{"op":"mcm","clk":"11540869648","pt":1719499353888,"mc":[{"id":"1.230180121","rc":[{"atb":[[2.5,0]],"id":53432239},{"atl":[[3.1,11.06],[3,0],[3.3,2.5]],"id":69112387},{"atl":[[7.6,0],[7.8,14.71]],"id":64253834}],"con":true,"img":false}]}
{"op":"mcm","clk":"11540869655","pt":1719499353994,"mc":[{"id":"1.230180121","rc":[{"atl":[[3.1,0]],"id":69112387}],"con":true,"img":false}]}
{"op":"mcm","clk":"11540869664","pt":1719499354098,"mc":[{"id":"1.230180121","rc":[{"atl":[[3.3,22.62]],"id":69112387}],"con":true,"img":false}]}
{"op":"mcm","clk":"11540869676","pt":1719499354198,"mc":[{"id":"1.230180121","rc":[{"atb":[[2.22,4.27]],"id":47370245},{"atl":[[3.3,2.5],[3.5,16.56]],"id":69112387}],"con":true,"img":false}]}
{"op":"mcm","clk":"11540869681","pt":1719499354300,"mc":[{"id":"1.230180121","rc":[{"atb":[[2.58,5.56]],"id":53432239}],"con":true,"img":false}]}
{"op":"mcm","clk":"11540869694","pt":1719499354506,"mc":[{"id":"1.230180121","rc":[{"atb":[[1.34,0],[1.41,25.94]],"id":69112387}],"con":true,"img":false}]}
{"op":"mcm","clk":"11540869700","pt":1719499354612,"mc":[{"id":"1.230180121","rc":[{"atb":[[1.65,0]],"id":64536702},{"atl":[[3.1,1]],"id":69112387}],"con":true,"img":false}]}
{"op":"mcm","clk":"11540869710","pt":1719499354715,"mc":[{"id":"1.230180121","rc":[{"atl":[[3.3,12.56],[3.5,5]],"id":69112387}],"con":true,"img":false}]}
{"op":"mcm","clk":"11540869729","pt":1719499354923,"mc":[{"id":"1.230180121","rc":[{"atb":[[1.57,0]],"id":64536702}],"con":true,"img":false}]}
{"op":"mcm","clk":"11540869753","pt":1719499355133,"mc":[{"id":"1.230180121","rc":[{"atl":[[3.95,9.53]],"id":47370245}],"con":true,"img":false}]}
{"op":"mcm","clk":"11540869765","pt":1719499355183,"mc":[{"id":"1.230180121","rc":[{"atl":[[4,9.28],[4.1,0],[4.2,0]],"id":47370245}],"con":true,"img":false}]}
{"op":"mcm","clk":"11540869773","pt":1719499355285,"mc":[{"id":"1.230180121","rc":[{"atl":[[4,0.84],[5.5,21.32]],"id":47370245}],"con":true,"img":false}]}
{"op":"mcm","clk":"11540869783","pt":1719499355388,"mc":[{"id":"1.230180121","rc":[{"atb":[[2.64,7.92]],"id":53432239},{"atl":[[4,7.33],[5.2,1]],"id":47370245},{"atb":[[1.67,8.84],[1.77,9.57]],"id":64536702},{"atb":[[1.74,11.76]],"id":69112387},{"atb":[[3.75,17.44]],"id":64253834}],"con":true,"img":false}]}
{"op":"mcm","clk":"11540869797","pt":1719499355495,"mc":[{"id":"1.230180121","rc":[{"atb":[[2.6,0]],"id":53432239},{"atl":[[5.5,2.5],[5.2,11.38],[5.7,0]],"id":47370245},{"atb":[[1.75,0]],"id":64536702},{"atb":[[1.72,7.67]],"id":69112387},{"atb":[[3.65,0]],"id":64253834}],"con":true,"img":false}]}
{"op":"mcm","clk":"11540869806","pt":1719499355596,"mc":[{"id":"1.230180121","rc":[{"atl":[[3.95,16.87],[5.2,1],[3.9,0.84]],"id":47370245},{"atb":[[3.7,2.3]],"id":64253834}],"con":true,"img":false}]}
{"op":"mcm","clk":"11540869817","pt":1719499355803,"mc":[{"id":"1.230180121","rc":[{"atb":[[2.62,0]],"id":53432239},{"atl":[[4,0.84]],"id":47370245},{"atb":[[1.76,0]],"id":64536702},{"atb":[[1.73,0]],"id":69112387},{"atb":[[3.7,0]],"id":64253834}],"con":true,"img":false}]}
{"op":"mcm","clk":"11540869834","pt":1719499356009,"mc":[{"id":"1.230180121","rc":[{"atb":[[2.66,2]],"id":53432239},{"atb":[[2.26,3]],"id":47370245},{"atl":[[4,18.56],[3.95,15.98]],"id":47370245},{"atb":[[1.78,3]],"id":64536702},{"atb":[[1.75,3.2]],"id":69112387},{"atb":[[3.8,2.6],[3.25,43.2],[3.5,0],[3.75,0]],"id":64253834}],"con":true,"img":false}]}
{"op":"mcm","clk":"11540869845","pt":1719499356117,"mc":[{"id":"1.230180121","rc":[{"atb":[[2.58,2.11]],"id":53432239},{"atb":[[2.26,15.02]],"id":47370245},{"atb":[[1.73,0]],"id":64536702},{"atb":[[1.58,0]],"id":69112387},{"atb":[[3.8,5.3]],"id":64253834}],"con":true,"img":false}]}
{"op":"mcm","clk":"11540869866","pt":1719499356318,"mc":[{"id":"1.230180121","rc":[{"atb":[[2.24,2.11]],"id":47370245}],"con":true,"img":false}]}
{"op":"mcm","clk":"11540869881","pt":1719499356424,"mc":[{"id":"1.230180121","rc":[{"atb":[[1.76,7.79]],"id":69112387}],"con":true,"img":false}]}
{"op":"mcm","clk":"11540869896","pt":1719499356626,"mc":[{"id":"1.230180121","rc":[{"atb":[[2.22,0]],"id":47370245}],"con":true,"img":false}]}
{"op":"mcm","clk":"11540869941","pt":1719499357093,"mc":[{"id":"1.230180121","rc":[{"atb":[[2.56,4.25]],"id":53432239}],"con":true,"img":false}]}
{"op":"mcm","clk":"11540869951","pt":1719499357196,"mc":[{"id":"1.230180121","rc":[{"atb":[[2.56,0]],"id":53432239}],"con":true,"img":false}]}
{"op":"mcm","clk":"11540869978","pt":1719499357506,"mc":[{"id":"1.230180121","rc":[{"atl":[[3.95,9.53]],"id":47370245}],"con":true,"img":false}]}
{"op":"mcm","clk":"11540870002","pt":1719499357819,"mc":[{"id":"1.230180121","rc":[{"atl":[[3.9,3.44]],"id":47370245},{"atb":[[1.72,13.34]],"id":69112387}],"con":true,"img":false}]}
{"op":"mcm","clk":"11540870021","pt":1719499358025,"mc":[{"id":"1.230180121","rc":[{"atb":[[1.92,0]],"id":53432239},{"atb":[[1.75,0]],"id":47370245},{"atb":[[1.77,7.57]],"id":64536702}],"con":true,"img":false}]}
{"op":"mcm","clk":"11540870033","pt":1719499358127,"mc":[{"id":"1.230180121","rc":[{"atl":[[4,17.72]],"id":47370245},{"atb":[[1.79,2]],"id":64536702}],"con":true,"img":false}]}
{"op":"mcm","clk":"11540870064","pt":1719499358386,"mc":[{"id":"1.230180121","rc":[{"atb":[[1.74,9.76]],"id":69112387}],"con":true,"img":false}]}
{"op":"mcm","clk":"11540870075","pt":1719499358489,"mc":[{"id":"1.230180121","rc":[{"atb":[[1.77,2]],"id":69112387}],"con":true,"img":false}]}
{"op":"mcm","clk":"11540870083","pt":1719499358594,"mc":[{"id":"1.230180121","rc":[{"atl":[[7,22.67]],"id":53432239},{"atl":[[3.9,0.84]],"id":47370245},{"atl":[[8.4,1]],"id":64253834}],"con":true,"img":false}]}
{"op":"mcm","clk":"11540870095","pt":1719499358696,"mc":[{"id":"1.230180121","rc":[{"atl":[[11,10],[11.5,1]],"id":62847579},{"atl":[[7.2,0]],"id":53432239},{"atl":[[8,0]],"id":64253834}],"con":true,"img":false}]}
{"op":"mcm","clk":"11540870115","pt":1719499358904,"mc":[{"id":"1.230180121","rc":[{"atb":[[2.64,5.92]],"id":53432239}],"con":true,"img":false}]}
{"op":"mcm","clk":"11540870125","pt":1719499359008,"mc":[{"id":"1.230180121","rc":[{"atb":[[2.68,2]],"id":53432239},{"atb":[[2.14,0],[2.16,10]],"id":47370245},{"atl":[[5.1,1],[5.2,0]],"id":47370245}],"con":true,"img":false}]}
{"op":"mcm","clk":"11540870133","pt":1719499359114,"mc":[{"id":"1.230180121","rc":[{"atl":[[3.85,4.78]],"id":47370245}],"con":true,"img":false}]}
{"op":"mcm","clk":"11540870183","pt":1719499359734,"mc":[{"id":"1.230180121","rc":[{"atb":[[2.24,0]],"id":47370245},{"atb":[[1.71,0]],"id":69112387}],"con":true,"img":false}]}
{"op":"mcm","clk":"11540870190","pt":1719499359784,"mc":[{"id":"1.230180121","rc":[{"atb":[[2.32,2.11]],"id":47370245},{"atb":[[1.78,2.11]],"id":69112387}],"con":true,"img":false}]}
{"op":"mcm","clk":"11540870294","pt":1719499361130,"mc":[{"id":"1.230180121","rc":[{"atl":[[4,0],[3.8,4.78]],"id":47370245},{"atb":[[3.25,2.49],[3.5,10.6]],"id":64253834}],"con":true,"img":false}]}
{"op":"mcm","clk":"11540870313","pt":1719499361330,"mc":[{"id":"1.230180121","rc":[{"atl":[[9,2.5],[10.5,0],[11.5,11],[9.8,14.93],[12.5,0],[14.5,0]],"id":62847579},{"atb":[[2.3,0],[2.38,0],[2.46,0]],"id":53432239},{"atl":[[5.5,0],[6.6,0],[5.9,0]],"id":47370245},{"atb":[[1.51,0],[1.55,0]],"id":69112387},{"atb":[[3.1,5],[3.25,0],[3.3,2.5],[2.94,0],[3.05,0]],"id":64253834}],"con":true,"img":false}]}
{"op":"mcm","clk":"11540870322","pt":1719499361435,"mc":[{"id":"1.230180121","rc":[{"atl":[[9,12.5],[11,0],[8.8,10.26]],"id":62847579}],"con":true,"img":false}]}
{"op":"mcm","clk":"11540870338","pt":1719499361591,"mc":[{"id":"1.230180121","rc":[{"atl":[[9.8,5],[8.8,11.1]],"id":62847579},{"atl":[[3.9,0]],"id":47370245}],"con":true,"img":false}]}
{"op":"mcm","clk":"11540870343","pt":1719499361694,"mc":[{"id":"1.230180121","rc":[{"atl":[[5,2.5]],"id":47370245},{"atb":[[1.77,0]],"id":69112387}],"con":true,"img":false}]}
{"op":"mcm","clk":"11540870355","pt":1719499361796,"mc":[{"id":"1.230180121","rc":[{"atb":[[1.79,2]],"id":69112387}],"con":true,"img":false}]}
{"op":"mcm","clk":"11540870382","pt":1719499362117,"mc":[{"id":"1.230180121","rc":[{"atb":[[1.71,7.78]],"id":64536702},{"atb":[[1.72,7.67]],"id":69112387}],"con":true,"img":false}]}
{"op":"mcm","clk":"11540870434","pt":1719499362728,"mc":[{"id":"1.230180121","rc":[{"atl":[[3.85,0],[3.75,0.84]],"id":47370245}],"con":true,"img":false}]}
{"op":"mcm","clk":"11540870442","pt":1719499362832,"mc":[{"id":"1.230180121","rc":[{"atl":[[3.95,15.16],[3.8,0]],"id":47370245}],"con":true,"img":false}]}
{"op":"mcm","clk":"11540870464","pt":1719499363088,"mc":[{"id":"1.230180121","rc":[{"atl":[[3.75,0]],"id":47370245}],"con":true,"img":false}]}
{"op":"mcm","clk":"11540870472","pt":1719499363191,"mc":[{"id":"1.230180121","rc":[{"atl":[[5.1,18.66],[3.95,9.53]],"id":47370245}],"con":true,"img":false}]}
{"op":"mcm","clk":"11540870497","pt":1719499363500,"mc":[{"id":"1.230180121","rc":[{"atl":[[3.8,2.74]],"id":47370245}],"con":true,"img":false}]}
{"op":"mcm","clk":"11540870504","pt":1719499363610,"mc":[{"id":"1.230180121","rc":[{"atl":[[3.8,0]],"id":47370245}],"con":true,"img":false}]}
{"op":"mcm","clk":"11540870539","pt":1719499364023,"mc":[{"id":"1.230180121","rc":[{"atb":[[3.45,0],[3.5,30.74]],"id":62847579}],"con":true,"img":false}]}
{"op":"mcm","clk":"11540870583","pt":1719499364492,"mc":[{"id":"1.230180121","rc":[{"atb":[[2.66,0]],"id":53432239},{"atb":[[2.26,12.02]],"id":47370245},{"atb":[[1.78,0]],"id":64536702},{"atb":[[1.75,0]],"id":69112387}],"con":true,"img":false}]}
{"op":"mcm","clk":"11540870593","pt":1719499364604,"mc":[{"id":"1.230180121","rc":[{"atb":[[2.52,7.5]],"id":53432239}],"con":true,"img":false}]}
{"op":"mcm","clk":"11540870606","pt":1719499364707,"mc":[{"id":"1.230180121","rc":[{"atb":[[2.68,5]],"id":53432239},{"atb":[[1.79,4.77]],"id":64536702},{"atb":[[1.79,4.5]],"id":69112387}],"con":true,"img":false}]}
{"op":"mcm","clk":"11540870718","pt":1719499366195,"mc":[{"id":"1.230180121","rc":[{"atb":[[2.68,13.19]],"id":53432239},{"atb":[[1.79,13.55]],"id":64536702},{"atb":[[1.79,13.73]],"id":69112387}],"con":true,"img":false}]}
{"op":"mcm","clk":"11540870721","pt":1719499366300,"mc":[{"id":"1.230180121","rc":[{"atl":[[9,2.5],[9.8,16.36]],"id":62847579},{"atb":[[2.64,0]],"id":53432239},{"atb":[[1.77,0]],"id":64536702},{"atb":[[1.74,0]],"id":69112387}],"con":true,"img":false}]}
{"op":"mcm","clk":"11540870728","pt":1719499366400,"mc":[{"id":"1.230180121","rc":[{"atb":[[1.72,10.17]],"id":69112387}],"con":true,"img":false}]}
{"op":"mcm","clk":"11540870749","pt":1719499366811,"mc":[{"id":"1.230180121","rc":[{"atb":[[1.76,3.52]],"id":64536702}],"con":true,"img":false}]}
{"op":"mcm","clk":"11540870757","pt":1719499366913,"mc":[{"id":"1.230180121","rc":[{"atb":[[2.32,11.13]],"id":47370245},{"atb":[[1.76,0]],"id":64536702}],"con":true,"img":false}]}
{"op":"mcm","clk":"11540870764","pt":1719499367017,"mc":[{"id":"1.230180121","rc":[{"atb":[[2.26,0]],"id":47370245}],"con":true,"img":false}]}
{"op":"mcm","clk":"11540870990","pt":1719499370112,"mc":[{"id":"1.230180121","rc":[{"atl":[[3.9,0.84]],"id":47370245}],"con":true,"img":false}]}
{"op":"mcm","clk":"11540871004","pt":1719499370319,"mc":[{"id":"1.230180121","rc":[{"atl":[[3.9,9.86]],"id":47370245}],"con":true,"img":false}]}
{"op":"mcm","clk":"11540871018","pt":1719499370526,"mc":[{"id":"1.230180121","rc":[{"atl":[[3.95,0]],"id":47370245}],"con":true,"img":false}]}
{"op":"mcm","clk":"11540871060","pt":1719499371042,"mc":[{"id":"1.230180121","rc":[{"spl":[[1.01,10]],"id":47370245}],"con":true,"img":false}]}
{"op":"mcm","clk":"11540871155","pt":1719499372030,"mc":[{"id":"1.230180121","rc":[{"atb":[[1.82,2.11],[1.78,0]],"id":69112387}],"con":true,"img":false}]}
{"op":"mcm","clk":"11540871246","pt":1719499373108,"mc":[{"id":"1.230180121","rc":[{"atb":[[2.68,10.19]],"id":53432239},{"atb":[[1.79,10.78]],"id":64536702},{"atb":[[1.79,11.23]],"id":69112387}],"con":true,"img":false}]}
{"op":"mcm","clk":"11540871256","pt":1719499373211,"mc":[{"id":"1.230180121","rc":[{"atb":[[2.7,3.7]],"id":53432239},{"atb":[[1.8,3.2]],"id":64536702},{"atb":[[1.82,6.11]],"id":69112387}],"con":true,"img":false}]}
{"op":"mcm","clk":"11540871278","pt":1719499373522,"mc":[{"id":"1.230180121","rc":[{"atb":[[1.79,9.23]],"id":69112387}],"con":true,"img":false}]}
{"op":"mcm","clk":"11540871285","pt":1719499373630,"mc":[{"id":"1.230180121","rc":[{"atb":[[1.83,2]],"id":69112387}],"con":true,"img":false}]}
{"op":"mcm","clk":"11540871339","pt":1719499374153,"mc":[{"id":"1.230180121","rc":[{"atb":[[1.77,5.23]],"id":64536702}],"con":true,"img":false}]}
{"op":"mcm","clk":"11540871377","pt":1719499374506,"mc":[{"id":"1.230180121","rc":[{"atb":[[2.66,3.28]],"id":53432239},{"atb":[[2.3,4.04]],"id":47370245}],"con":true,"img":false}]}
{"op":"mcm","clk":"11540871400","pt":1719499374815,"mc":[{"id":"1.230180121","rc":[{"atb":[[1.79,8.78]],"id":64536702}],"con":true,"img":false}]}
{"op":"mcm","clk":"11540871407","pt":1719499374918,"mc":[{"id":"1.230180121","rc":[{"atb":[[1.81,2]],"id":64536702}],"con":true,"img":false}]}
{"op":"mcm","clk":"11540871444","pt":1719499375329,"mc":[{"id":"1.230180121","rc":[{"atb":[[2.68,8.19]],"id":53432239}],"con":true,"img":false}]}
{"op":"mcm","clk":"11540871448","pt":1719499375432,"mc":[{"id":"1.230180121","rc":[{"atb":[[2.72,2]],"id":53432239}],"con":true,"img":false}]}
{"op":"mcm","clk":"11540871550","pt":1719499376730,"mc":[{"id":"1.230180121","rc":[{"atb":[[2.66,0]],"id":53432239},{"atb":[[1.77,0]],"id":64536702}],"con":true,"img":false}]}
{"op":"mcm","clk":"11540871557","pt":1719499376824,"mc":[{"id":"1.230180121","rc":[{"atb":[[2.72,9.3]],"id":53432239},{"atb":[[1.81,9.6]],"id":64536702},{"atb":[[1.83,13.38]],"id":69112387}],"con":true,"img":false}]}
{"op":"mcm","clk":"11540871578","pt":1719499377032,"mc":[{"id":"1.230180121","rc":[{"atb":[[2.68,0]],"id":53432239},{"atb":[[1.79,0]],"id":64536702},{"atb":[[1.79,0]],"id":69112387}],"con":true,"img":false}]}
{"op":"mcm","clk":"11540871655","pt":1719499377905,"mc":[{"id":"1.230180121","rc":[{"atb":[[1.81,5.67]],"id":69112387}],"con":true,"img":false}]}
{"op":"mcm","clk":"11540871747","pt":1719499379319,"mc":[{"id":"1.230180121","rc":[{"atb":[[3.45,40.82],[3.5,2.5]],"id":62847579},{"atb":[[2.2,17.68],[2.16,0]],"id":47370245},{"atb":[[3.55,10.6]],"id":64253834},{"atl":[[8,14.29]],"id":64253834}],"con":true,"img":false}]}
{"op":"mcm","clk":"11540871756","pt":1719499379422,"mc":[{"id":"1.230180121","rc":[{"atb":[[3.5,0]],"id":64253834},{"atl":[[7.8,0]],"id":64253834}],"con":true,"img":false}]}
{"op":"mcm","clk":"11540871922","pt":1719499381452,"mc":[{"id":"1.230180121","rc":[{"atl":[[4,31.4],[4.3,10],[3.95,5],[3.8,0],[4.4,0],[3.75,2.5]],"id":64536702}],"con":true,"img":false}]}
{"op":"mcm","clk":"11540871927","pt":1719499381553,"mc":[{"id":"1.230180121","rc":[{"atb":[[3.4,4.88]],"id":62847579},{"atl":[[4,0]],"id":64536702}],"con":true,"img":false}]}
{"op":"mcm","clk":"11540871934","pt":1719499381659,"mc":[{"id":"1.230180121","rc":[{"atl":[[3.75,16.38]],"id":64536702}],"con":true,"img":false}]}
{"op":"mcm","clk":"11540871943","pt":1719499381715,"mc":[{"id":"1.230180121","rc":[{"atb":[[2.7,0]],"id":53432239},{"atb":[[1.8,0]],"id":64536702},{"atb":[[1.82,2.11]],"id":69112387}],"con":true,"img":false}]}
{"op":"mcm","clk":"11540871952","pt":1719499381818,"mc":[{"id":"1.230180121","rc":[{"atb":[[2.74,3]],"id":53432239},{"atb":[[1.82,3]],"id":64536702},{"atl":[[3.95,28.32],[3.75,2.5]],"id":64536702},{"atb":[[1.84,3.5]],"id":69112387}],"con":true,"img":false}]}
{"op":"mcm","clk":"11540872115","pt":1719499383828,"mc":[{"id":"1.230180121","rc":[{"atb":[[1.81,7.6]],"id":64536702}],"con":true,"img":false}]}
{"op":"mcm","clk":"11540872125","pt":1719499383932,"mc":[{"id":"1.230180121","rc":[{"atb":[[1.83,2]],"id":64536702}],"con":true,"img":false}]}
{"op":"mcm","clk":"11540872146","pt":1719499384144,"mc":[{"id":"1.230180121","rc":[{"atb":[[1.82,0],[1.86,2.11]],"id":69112387}],"con":true,"img":false}]}
{"op":"mcm","clk":"11540872155","pt":1719499384243,"mc":[{"id":"1.230180121","rc":[{"atb":[[2.3,0]],"id":47370245}],"con":true,"img":false}]}
{"op":"mcm","clk":"11540872164","pt":1719499384350,"mc":[{"id":"1.230180121","rc":[{"atb":[[1.83,11.38]],"id":69112387}],"con":true,"img":false}]}
{"op":"mcm","clk":"11540872174","pt":1719499384454,"mc":[{"id":"1.230180121","rc":[{"atb":[[1.85,2]],"id":69112387}],"con":true,"img":false}]}
{"op":"mcm","clk":"11540872194","pt":1719499384621,"mc":[{"id":"1.230180121","rc":[{"atb":[[2.72,7.3]],"id":53432239}],"con":true,"img":false}]}
{"op":"mcm","clk":"11540872202","pt":1719499384726,"mc":[{"id":"1.230180121","rc":[{"atb":[[2.76,2]],"id":53432239},{"atb":[[1.81,0]],"id":64536702},{"atb":[[3.55,0],[3.5,15.9]],"id":64253834},{"atl":[[8,0],[8.2,13.89]],"id":64253834}],"con":true,"img":false}]}
{"op":"mcm","clk":"11540872244","pt":1719499385240,"mc":[{"id":"1.230180121","rc":[{"atl":[[7.4,7.84]],"id":64253834}],"con":true,"img":false}]}
{"op":"mcm","clk":"11540872278","pt":1719499385655,"mc":[{"id":"1.230180121","rc":[{"atl":[[7.4,4.96]],"id":64253834}],"con":true,"img":false}]}
{"op":"mcm","clk":"11540872290","pt":1719499385766,"mc":[{"id":"1.230180121","rc":[{"atb":[[1.85,0]],"id":69112387},{"atl":[[8,2.88],[8.2,0],[8.4,14.51]],"id":64253834}],"con":true,"img":false}]}
{"op":"mcm","clk":"11540872301","pt":1719499385812,"mc":[{"id":"1.230180121","rc":[{"atb":[[1.87,2]],"id":69112387},{"atl":[[8.2,7.85],[8.4,1]],"id":64253834}],"con":true,"img":false}]}
{"op":"mcm","clk":"11540872350","pt":1719499386433,"mc":[{"id":"1.230180121","rc":[{"atl":[[7.2,1],[7,21.67]],"id":53432239}],"con":true,"img":false}]}
{"op":"mcm","clk":"11540872388","pt":1719499386742,"mc":[{"id":"1.230180121","rc":[{"atb":[[1.81,0]],"id":69112387}],"con":true,"img":false}]}
{"op":"mcm","clk":"11540872397","pt":1719499386850,"mc":[{"id":"1.230180121","rc":[{"atl":[[5.1,17.66],[4.9,1]],"id":47370245},{"atl":[[3.2,1]],"id":69112387}],"con":true,"img":false}]}
{"op":"mcm","clk":"11540872411","pt":1719499386949,"mc":[{"id":"1.230180121","rc":[{"atl":[[3.1,0],[3.15,10.06],[3.3,2.5]],"id":69112387}],"con":true,"img":false}]}
{"op":"mcm","clk":"11540872427","pt":1719499387161,"mc":[{"id":"1.230180121","rc":[{"atb":[[2.1,3.75]],"id":47370245}],"con":true,"img":false}]}
{"op":"mcm","clk":"11540872435","pt":1719499387260,"mc":[{"id":"1.230180121","rc":[{"atb":[[2.76,8.78]],"id":53432239},{"atb":[[1.87,6.22]],"id":69112387}],"con":true,"img":false}]}
{"op":"mcm","clk":"11540872442","pt":1719499387312,"mc":[{"id":"1.230180121","rc":[{"atb":[[2.72,0]],"id":53432239},{"atb":[[1.83,0]],"id":69112387}],"con":true,"img":false}]}
{"op":"mcm","clk":"11540872455","pt":1719499387518,"mc":[{"id":"1.230180121","rc":[{"atl":[[12,1]],"id":62847579},{"atl":[[7.2,0]],"id":53432239},{"atl":[[4.8,1],[4.9,0]],"id":47370245}],"con":true,"img":false}]}
{"op":"mcm","clk":"11540872462","pt":1719499387626,"mc":[{"id":"1.230180121","rc":[{"atl":[[11.5,10]],"id":62847579},{"atl":[[7,22.67]],"id":53432239}],"con":true,"img":false}]}
{"op":"mcm","clk":"11540872520","pt":1719499388463,"mc":[{"id":"1.230180121","rc":[{"atb":[[1.78,0]],"id":47370245},{"atl":[[4.5,1],[4.6,0]],"id":64536702}],"con":true,"img":false}]}
{"op":"mcm","clk":"11540872668","pt":1719499390451,"mc":[{"id":"1.230180121","rc":[{"atb":[[2.74,0]],"id":53432239},{"atb":[[1.82,0]],"id":64536702},{"atb":[[1.84,0]],"id":69112387}],"con":true,"img":false}]}
{"op":"mcm","clk":"11540872676","pt":1719499390553,"mc":[{"id":"1.230180121","rc":[{"atb":[[2.78,2.8]],"id":53432239},{"atb":[[1.83,5.2]],"id":64536702},{"atb":[[1.88,2.38]],"id":69112387}],"con":true,"img":false}]}
{"op":"mcm","clk":"11540872722","pt":1719499391237,"mc":[{"id":"1.230180121","rc":[{"atb":[[3.4,0]],"id":62847579}],"con":true,"img":false}]}
{"op":"mcm","clk":"11540872757","pt":1719499391648,"mc":[{"id":"1.230180121","rc":[{"atl":[[3.2,20.12],[3.15,0]],"id":69112387}],"con":true,"img":false}]}
{"op":"mcm","clk":"11540872820","pt":1719499392429,"mc":[{"id":"1.230180121","rc":[{"atb":[[1.87,4.22]],"id":69112387}],"con":true,"img":false}]}
{"op":"mcm","clk":"11540872827","pt":1719499392531,"mc":[{"id":"1.230180121","rc":[{"atb":[[1.89,2]],"id":69112387}],"con":true,"img":false}]}
{"op":"mcm","clk":"11540872855","pt":1719499392849,"mc":[{"id":"1.230180121","rc":[{"atb":[[2.76,6.78]],"id":53432239}],"con":true,"img":false}]}
{"op":"mcm","clk":"11540872866","pt":1719499392948,"mc":[{"id":"1.230180121","rc":[{"atb":[[1.02,27.93]],"id":53432239}],"con":true,"img":false}]}
{"op":"mcm","clk":"11540872910","pt":1719499393469,"mc":[{"id":"1.230180121","rc":[{"atb":[[1.79,5.23]],"id":64536702}],"con":true,"img":false}]}
{"op":"mcm","clk":"11540872944","pt":1719499393833,"mc":[{"id":"1.230180121","rc":[{"atb":[[2.74,3.13]],"id":53432239},{"atb":[[2.18,4.41]],"id":47370245}],"con":true,"img":false}]}
{"op":"mcm","clk":"11540872960","pt":1719499394037,"mc":[{"id":"1.230180121","rc":[{"atb":[[2.18,3.26],[2.1,0]],"id":47370245}],"con":true,"img":false}]}
{"op":"mcm","clk":"11540873075","pt":1719499395340,"mc":[{"id":"1.230180121","rc":[{"atb":[[3.55,10.6],[3.5,0]],"id":64253834}],"con":true,"img":false}]}
{"op":"mcm","clk":"11540873177","pt":1719499396746,"mc":[{"id":"1.230180121","rc":[{"atb":[[2.74,0]],"id":53432239}],"con":true,"img":false}]}
{"op":"mcm","clk":"11540873241","pt":1719499397427,"mc":[{"id":"1.230180121","rc":[{"atb":[[2.78,9.43]],"id":53432239},{"atb":[[1.89,7.04]],"id":69112387}],"con":true,"img":false}]}
{"op":"mcm","clk":"11540873254","pt":1719499397634,"mc":[{"id":"1.230180121","rc":[{"atb":[[2.76,0]],"id":53432239}],"con":true,"img":false}]}
{"op":"mcm","clk":"11540873261","pt":1719499397737,"mc":[{"id":"1.230180121","rc":[{"atb":[[1.87,0]],"id":69112387}],"con":true,"img":false}]}
{"op":"mcm","clk":"11540873287","pt":1719499398049,"mc":[{"id":"1.230180121","rc":[{"atb":[[1.87,5.67]],"id":69112387}],"con":true,"img":false}]}
{"op":"mcm","clk":"11540873372","pt":1719499399140,"mc":[{"id":"1.230180121","rc":[{"atb":[[1.88,0]],"id":69112387}],"con":true,"img":false}]}
{"op":"mcm","clk":"11540873380","pt":1719499399250,"mc":[{"id":"1.230180121","rc":[{"atb":[[1.9,3]],"id":69112387}],"con":true,"img":false}]}
{"op":"mcm","clk":"11540873453","pt":1719499400239,"mc":[{"id":"1.230180121","rc":[{"atb":[[1.89,5.04]],"id":69112387}],"con":true,"img":false}]}
{"op":"mcm","clk":"11540873458","pt":1719499400346,"mc":[{"id":"1.230180121","rc":[{"atb":[[1.91,2]],"id":69112387}],"con":true,"img":false}]}
{"op":"mcm","clk":"11540873471","pt":1719499400548,"mc":[{"id":"1.230180121","rc":[{"atb":[[3.4,4.88]],"id":62847579},{"atb":[[1.83,13.02]],"id":64536702}],"con":true,"img":false}]}
{"op":"mcm","clk":"11540873475","pt":1719499400654,"mc":[{"id":"1.230180121","rc":[{"atb":[[1.58,0],[1.62,0],[1.54,0]],"id":64536702}],"con":true,"img":false}]}
{"op":"mcm","clk":"11540873527","pt":1719499401380,"mc":[{"id":"1.230180121","rc":[{"atb":[[1.79,0]],"id":64536702}],"con":true,"img":false}]}
{"op":"mcm","clk":"11540873901","pt":1719499405843,"mc":[{"id":"1.230180121","rc":[{"atb":[[2.18,6.51]],"id":47370245}],"con":true,"img":false}]}
{"op":"mcm","clk":"11540874042","pt":1719499407252,"mc":[{"id":"1.230180121","rc":[{"spn":6.17,"spf":"NaN","id":62847579},{"spn":4.29,"spf":"NaN","id":53432239},{"spn":2.32,"spf":1.0,"id":47370245},{"atb":[[1.83,5.2]],"id":64536702},{"spn":2.74,"spf":"NaN","id":64536702},{"spn":2.43,"spf":"NaN","id":69112387},{"spn":5.6,"spf":"NaN","id":64253834}],"con":true,"img":false}]}
{"op":"mcm","clk":"11540874051","pt":1719499407354,"mc":[{"id":"1.230180121","rc":[{"atb":[[1.82,9.1]],"id":64536702},{"atb":[[1.87,0]],"id":69112387}],"con":true,"img":false}]}
{"op":"mcm","clk":"11540874057","pt":1719499407456,"mc":[{"id":"1.230180121","rc":[{"atb":[[1.91,8.03]],"id":69112387}],"con":true,"img":false}]}
{"op":"mcm","clk":"11540874064","pt":1719499407561,"mc":[{"id":"1.230180121","rc":[{"atb":[[1.89,0]],"id":69112387}],"con":true,"img":false}]}
{"op":"mcm","clk":"11540874080","pt":1719499407768,"mc":[{"id":"1.230180121","rc":[{"atb":[[1.9,0]],"id":69112387}],"con":true,"img":false}]}
{"op":"mcm","clk":"11540874087","pt":1719499407875,"mc":[{"id":"1.230180121","rc":[{"atb":[[1.91,11.03]],"id":69112387}],"con":true,"img":false}]}
{"op":"mcm","clk":"11540874169","pt":1719499408754,"mc":[{"id":"1.230180121","rc":[{"atb":[[2.18,3.26]],"id":47370245}],"con":true,"img":false}]}
{"op":"mcm","clk":"11540874303","pt":1719499410256,"mc":[{"id":"1.230180121","rc":[{"atb":[[3.1,0],[3.35,2.5],[3.3,0],[3.15,5]],"id":64253834}],"con":true,"img":false}]}
{"op":"mcm","clk":"11540874333","pt":1719499410669,"mc":[{"id":"1.230180121","rc":[{"atl":[[4.8,3.5],[5,0]],"id":47370245}],"con":true,"img":false}]}
{"op":"mcm","clk":"11540874341","pt":1719499410773,"mc":[{"id":"1.230180121","rc":[{"atl":[[4.8,23.24],[5.1,0]],"id":47370245}],"con":true,"img":false}]}
{"op":"mcm","clk":"11540874375","pt":1719499411186,"mc":[{"id":"1.230180121","rc":[{"atb":[[2.18,4.41]],"id":47370245}],"con":true,"img":false}]}
{"op":"mcm","clk":"11540874429","pt":1719499411863,"mc":[{"id":"1.230180121","rc":[{"atb":[[1.81,5.23]],"id":64536702}],"con":true,"img":false}]}
{"op":"mcm","clk":"11540874454","pt":1719499412177,"mc":[{"id":"1.230180121","rc":[{"atb":[[2.76,3.1]],"id":53432239}],"con":true,"img":false}]}
{"op":"mcm","clk":"11540874464","pt":1719499412280,"mc":[{"id":"1.230180121","rc":[{"atb":[[1.82,0]],"id":64536702}],"con":true,"img":false}]}
{"op":"mcm","clk":"11540874480","pt":1719499412439,"mc":[{"id":"1.230180121","rc":[{"atl":[[3.7,2.28]],"id":47370245}],"con":true,"img":false}]}
{"op":"mcm","clk":"11540874489","pt":1719499412542,"mc":[{"id":"1.230180121","rc":[{"atl":[[3.7,18.04]],"id":47370245}],"con":true,"img":false}]}
{"op":"mcm","clk":"11540874497","pt":1719499412645,"mc":[{"id":"1.230180121","rc":[{"atl":[[3.9,0.84]],"id":47370245}],"con":true,"img":false}]}
{"op":"mcm","clk":"11540874518","pt":1719499412852,"mc":[{"id":"1.230180121","rc":[{"atl":[[3.7,15.76]],"id":47370245}],"con":true,"img":false}]}
{"op":"mcm","clk":"11540874535","pt":1719499413064,"mc":[{"id":"1.230180121","rc":[{"atl":[[3.7,0],[3.65,6.18]],"id":47370245}],"con":true,"img":false}]}
{"op":"mcm","clk":"11540874544","pt":1719499413167,"mc":[{"id":"1.230180121","rc":[{"atl":[[3.9,0],[3.65,7.02],[3.75,20.17]],"id":47370245}],"con":true,"img":false}]}
{"op":"mcm","clk":"11540874570","pt":1719499413476,"mc":[{"id":"1.230180121","rc":[{"atb":[[2.56,2.5],[2.52,5]],"id":53432239}],"con":true,"img":false}]}
{"op":"mcm","clk":"11540874619","pt":1719499413943,"mc":[{"id":"1.230180121","rc":[{"atb":[[2.76,0]],"id":53432239},{"atb":[[2.18,0]],"id":47370245},{"atb":[[1.81,0]],"id":64536702}],"con":true,"img":false}]}
{"op":"mcm","clk":"11540874713","pt":1719499415182,"mc":[{"id":"1.230180121","rc":[{"atl":[[3.65,0.84]],"id":47370245}],"con":true,"img":false}]}
{"op":"mcm","clk":"11540874739","pt":1719499415440,"mc":[{"id":"1.230180121","rc":[{"atl":[[3.6,8.29]],"id":47370245}],"con":true,"img":false}]}
{"op":"mcm","clk":"11540874753","pt":1719499415646,"mc":[{"id":"1.230180121","rc":[{"atl":[[3.65,0]],"id":47370245}],"con":true,"img":false}]}
{"op":"mcm","clk":"11540874775","pt":1719499415963,"mc":[{"id":"1.230180121","rc":[{"atl":[[4.8,3.5],[3.55,20.17]],"id":47370245}],"con":true,"img":false}]}
{"op":"mcm","clk":"11540874793","pt":1719499416166,"mc":[{"id":"1.230180121","rc":[{"atb":[[1.89,5.67]],"id":69112387}],"con":true,"img":false}]}
{"op":"mcm","clk":"11540874823","pt":1719499416477,"mc":[{"id":"1.230180121","rc":[{"atb":[[1.91,8.03]],"id":69112387}],"con":true,"img":false}]}
{"op":"mcm","clk":"11540874836","pt":1719499416684,"mc":[{"id":"1.230180121","rc":[{"atb":[[1.92,3]],"id":69112387}],"con":true,"img":false}]}
{"op":"mcm","clk":"11540874873","pt":1719499417153,"mc":[{"id":"1.230180121","rc":[{"atb":[[1.91,6.03]],"id":69112387}],"con":true,"img":false}]}
{"op":"mcm","clk":"11540874883","pt":1719499417257,"mc":[{"id":"1.230180121","rc":[{"atb":[[1.93,2],[1.92,13.27]],"id":69112387}],"con":true,"img":false}]}
{"op":"mcm","clk":"11540874895","pt":1719499417360,"mc":[{"id":"1.230180121","rc":[{"atb":[[1.91,0]],"id":69112387}],"con":true,"img":false}]}
{"op":"mcm","clk":"11540874906","pt":1719499417465,"mc":[{"id":"1.230180121","rc":[{"atb":[[3.5,30.74],[3.45,0]],"id":62847579},{"atb":[[1.63,0],[1.57,15.58]],"id":64536702},{"atb":[[1.72,7.67]],"id":69112387},{"atl":[[8.2,0],[8.4,10.94]],"id":64253834}],"con":true,"img":false}]}
{"op":"mcm","clk":"11540874925","pt":1719499417672,"mc":[{"id":"1.230180121","rc":[{"atb":[[3.4,10.5]],"id":62847579}],"con":true,"img":false}]}
{"op":"mcm","clk":"11540874942","pt":1719499417879,"mc":[{"id":"1.230180121","rc":[{"atl":[[3.6,0]],"id":47370245}],"con":true,"img":false}]}
{"op":"mcm","clk":"11540874953","pt":1719499417982,"mc":[{"id":"1.230180121","rc":[{"atb":[[1.89,0]],"id":69112387}],"con":true,"img":false}]}
{"op":"mcm","clk":"11540874968","pt":1719499418140,"mc":[{"id":"1.230180121","rc":[{"atb":[[3.4,0]],"id":62847579}],"con":true,"img":false}]}
{"op":"mcm","clk":"11540874977","pt":1719499418244,"mc":[{"id":"1.230180121","rc":[{"atl":[[3.55,23.27]],"id":47370245}],"con":true,"img":false}]}
{"op":"mcm","clk":"11540875168","pt":1719499420678,"mc":[{"id":"1.230180121","rc":[{"atl":[[3.5,0.84]],"id":47370245}],"con":true,"img":false}]}
{"op":"mcm","clk":"11540875276","pt":1719499422284,"mc":[{"id":"1.230180121","rc":[{"atl":[[3.5,22.46]],"id":47370245}],"con":true,"img":false}]}
{"op":"mcm","clk":"11540875289","pt":1719499422394,"mc":[{"id":"1.230180121","rc":[{"atl":[[3.55,3.09],[3.5,44.93]],"id":47370245}],"con":true,"img":false}]}
{"op":"mcm","clk":"11540875299","pt":1719499422439,"mc":[{"id":"1.230180121","rc":[{"atl":[[3.75,0]],"id":47370245}],"con":true,"img":false}]}
{"op":"mcm","clk":"11540875306","pt":1719499422544,"mc":[{"id":"1.230180121","rc":[{"atb":[[3.55,0],[3.5,15.9]],"id":64253834},{"atl":[[8.2,7.85],[8.4,1]],"id":64253834}],"con":true,"img":false}]}
{"op":"mcm","clk":"11540875432","pt":1719499424164,"mc":[{"id":"1.230180121","rc":[{"atb":[[2.18,3.25]],"id":47370245}],"con":true,"img":false}]}
{"op":"mcm","clk":"11540875448","pt":1719499424349,"mc":[{"id":"1.230180121","rc":[{"atb":[[2.18,0]],"id":47370245}],"con":true,"img":false}]}
{"op":"mcm","clk":"11540875504","pt":1719499425174,"mc":[{"id":"1.230180121","rc":[{"atb":[[1.92,10.27]],"id":69112387}],"con":true,"img":false}]}
{"op":"mcm","clk":"11540875509","pt":1719499425282,"mc":[{"id":"1.230180121","rc":[{"atb":[[1.93,4.95]],"id":69112387}],"con":true,"img":false}]}
{"op":"mcm","clk":"11540875646","pt":1719499426887,"mc":[{"id":"1.230180121","rc":[{"atb":[[1.93,15.46]],"id":69112387}],"con":true,"img":false}]}
{"op":"mcm","clk":"11540875666","pt":1719499427052,"mc":[{"id":"1.230180121","rc":[{"atb":[[1.92,0]],"id":69112387}],"con":true,"img":false}]}
{"op":"mcm","clk":"11540875680","pt":1719499427157,"mc":[{"id":"1.230180121","rc":[{"atb":[[1.73,2.5]],"id":69112387}],"con":true,"img":false}]}
{"op":"mcm","clk":"11540875742","pt":1719499428251,"mc":[{"id":"1.230180121","rc":[{"atb":[[1.61,0]],"id":69112387}],"con":true,"img":false}]}
{"op":"mcm","clk":"11540875824","pt":1719499429291,"mc":[{"id":"1.230180121","rc":[{"atb":[[1.7,5.23]],"id":64536702}],"con":true,"img":false}]}
{"op":"mcm","clk":"11540875846","pt":1719499429553,"mc":[{"id":"1.230180121","rc":[{"atb":[[2.76,3.1]],"id":53432239}],"con":true,"img":false}]}
{"op":"mcm","clk":"11540876032","pt":1719499432163,"mc":[{"id":"1.230180121","rc":[{"atb":[[2.3,4.04]],"id":47370245}],"con":true,"img":false}]}
{"op":"mcm","clk":"11540876111","pt":1719499433362,"mc":[{"id":"1.230180121","rc":[{"atb":[[1.91,5.67]],"id":69112387}],"con":true,"img":false}]}
{"op":"mcm","clk":"11540876136","pt":1719499433778,"mc":[{"id":"1.230180121","rc":[{"atb":[[1.93,12.51]],"id":69112387}],"con":true,"img":false}]}
{"op":"mcm","clk":"11540876152","pt":1719499433988,"mc":[{"id":"1.230180121","rc":[{"atb":[[1.94,2.6]],"id":69112387}],"con":true,"img":false}]}
{"op":"mcm","clk":"11540876204","pt":1719499434660,"mc":[{"id":"1.230180121","rc":[{"atb":[[1.93,10.51]],"id":69112387}],"con":true,"img":false}]}
{"op":"mcm","clk":"11540876213","pt":1719499434768,"mc":[{"id":"1.230180121","rc":[{"atb":[[1.95,2]],"id":69112387}],"con":true,"img":false}]}
{"op":"mcm","clk":"11540876318","pt":1719499436067,"mc":[{"id":"1.230180121","rc":[{"atb":[[1.91,0]],"id":69112387}],"con":true,"img":false}]}
{"op":"mcm","clk":"11540876337","pt":1719499436273,"mc":[{"id":"1.230180121","rc":[{"atb":[[1.95,10.75]],"id":69112387}],"con":true,"img":false}]}
{"op":"mcm","clk":"11540876354","pt":1719499436480,"mc":[{"id":"1.230180121","rc":[{"atb":[[1.93,0]],"id":69112387}],"con":true,"img":false}]}
{"op":"mcm","clk":"11540876593","pt":1719499439490,"mc":[{"id":"1.230180121","rc":[{"atb":[[1.94,0]],"id":69112387}],"con":true,"img":false}]}
{"op":"mcm","clk":"11540876600","pt":1719499439597,"mc":[{"id":"1.230180121","rc":[{"atb":[[1.96,4]],"id":69112387}],"con":true,"img":false}]}
{"op":"mcm","clk":"11540876637","pt":1719499440117,"mc":[{"id":"1.230180121","rc":[{"atb":[[1.95,8.75]],"id":69112387}],"con":true,"img":false}]}
{"op":"mcm","clk":"11540876645","pt":1719499440216,"mc":[{"id":"1.230180121","rc":[{"atb":[[1.97,2]],"id":69112387}],"con":true,"img":false}]}
{"op":"mcm","clk":"11540876689","pt":1719499440802,"mc":[{"id":"1.230180121","rc":[{"atb":[[2.24,15.18],[2.2,2.5]],"id":47370245},{"atb":[[1.63,10.46],[1.57,0]],"id":64536702},{"atb":[[3.7,10.6],[3.5,0]],"id":64253834}],"con":true,"img":false}]}
{"op":"mcm","clk":"11540876702","pt":1719499440905,"mc":[{"id":"1.230180121","rc":[{"atb":[[2.52,0],[2.58,14.64]],"id":53432239},{"atb":[[2.3,0]],"id":47370245}],"con":true,"img":false}]}
{"op":"mcm","clk":"11540876711","pt":1719499441006,"mc":[{"id":"1.230180121","rc":[{"atl":[[3.55,0]],"id":47370245}],"con":true,"img":false}]}
{"op":"mcm","clk":"11540876715","pt":1719499441115,"mc":[{"id":"1.230180121","rc":[{"atl":[[7.6,15.15],[3.5,22.46]],"id":47370245},{"atb":[[1.7,0]],"id":64536702},{"atl":[[8,0]],"id":64253834}],"con":true,"img":false}]}
{"op":"mcm","clk":"11540876724","pt":1719499441220,"mc":[{"id":"1.230180121","rc":[{"atb":[[3.8,14.53]],"id":64253834},{"atl":[[8.2,0]],"id":64253834}],"con":true,"img":false}]}
{"op":"mcm","clk":"11540876732","pt":1719499441272,"mc":[{"id":"1.230180121","rc":[{"atl":[[3.45,2.99]],"id":47370245},{"atl":[[8.4,13.82]],"id":64253834}],"con":true,"img":false}]}
{"op":"mcm","clk":"11540876752","pt":1719499441477,"mc":[{"id":"1.230180121","rc":[{"atl":[[3.45,13.97]],"id":47370245}],"con":true,"img":false}]}
{"op":"mcm","clk":"11540876761","pt":1719499441581,"mc":[{"id":"1.230180121","rc":[{"atl":[[3.4,0.84],[3.5,0.84]],"id":47370245}],"con":true,"img":false}]}
{"op":"mcm","clk":"11540876916","pt":1719499443409,"mc":[{"id":"1.230180121","rc":[{"atb":[[3.55,17.3]],"id":62847579},{"atl":[[8.8,16]],"id":62847579},{"atb":[[2.78,12.02]],"id":53432239},{"atl":[[5.8,12.95]],"id":53432239},{"atl":[[3.45,22.68]],"id":47370245},{"atl":[[2.96,19.59]],"id":69112387},{"atb":[[3.8,22.87]],"id":64253834}],"con":true,"img":false}]}
{"op":"mcm","clk":"11540876923","pt":1719499443508,"mc":[{"id":"1.230180121","rc":[{"atb":[[3.6,17.3],[3.5,2.5]],"id":62847579},{"atl":[[8.6,13.16],[9.8,5]],"id":62847579},{"atl":[[5.7,12.95],[7,5.99]],"id":53432239},{"atl":[[3.2,1],[2.94,19.59]],"id":69112387}],"con":true,"img":false}]}
{"op":"mcm","clk":"11540876929","pt":1719499443613,"mc":[{"id":"1.230180121","rc":[{"atb":[[3.6,39.18]],"id":62847579},{"atl":[[8.6,23.69]],"id":62847579},{"atl":[[5.7,24.3]],"id":53432239},{"atl":[[2.94,29.15]],"id":69112387}],"con":true,"img":false}]}
{"op":"mcm","clk":"11540876936","pt":1719499443665,"mc":[{"id":"1.230180121","rc":[{"atl":[[5.8,7.76]],"id":53432239},{"atl":[[2.96,11.38]],"id":69112387}],"con":true,"img":false}]}
{"op":"mcm","clk":"11540876945","pt":1719499443770,"mc":[{"id":"1.230180121","rc":[{"atb":[[3.55,6.1]],"id":62847579},{"atl":[[8.8,5.74]],"id":62847579}],"con":true,"img":false}]}
{"op":"mcm","clk":"11540876970","pt":1719499444084,"mc":[{"id":"1.230180121","rc":[{"atl":[[8.4,0.84]],"id":62847579},{"atl":[[5.6,0.84]],"id":53432239},{"atl":[[2.92,0.84]],"id":69112387}],"con":true,"img":false}]}
{"op":"mcm","clk":"11540877010","pt":1719499444495,"mc":[{"id":"1.230180121","rc":[{"atl":[[8.4,17.11]],"id":64253834}],"con":true,"img":false}]}
{"op":"mcm","clk":"11540877069","pt":1719499445271,"mc":[{"id":"1.230180121","rc":[{"atb":[[3.55,3.18]],"id":62847579},{"atb":[[1.96,0]],"id":69112387}],"con":true,"img":false}]}
{"op":"mcm","clk":"11540877075","pt":1719499445375,"mc":[{"id":"1.230180121","rc":[{"atb":[[3.65,3.91]],"id":62847579},{"atb":[[1.97,4.21]],"id":69112387}],"con":true,"img":false}]}
{"op":"mcm","clk":"11540877081","pt":1719499445477,"mc":[{"id":"1.230180121","rc":[{"atb":[[1.97,12.36]],"id":69112387}],"con":true,"img":false}]}
{"op":"mcm","clk":"11540877101","pt":1719499445685,"mc":[{"id":"1.230180121","rc":[{"atb":[[1.95,0]],"id":69112387}],"con":true,"img":false}]}
{"op":"mcm","clk":"11540877116","pt":1719499445898,"mc":[{"id":"1.230180121","rc":[{"atb":[[3.6,21.88],[3.7,3.91]],"id":62847579},{"atl":[[8.6,10.53],[11,1],[12,0],[8.8,18.56]],"id":62847579},{"atb":[[2.24,0],[2.22,26.32]],"id":47370245},{"atl":[[3.2,0]],"id":69112387},{"atb":[[3.6,33.48],[3.7,0]],"id":64253834},{"atl":[[9,1],[8.4,16.11]],"id":64253834}],"con":true,"img":false}]}
{"op":"mcm","clk":"11540877138","pt":1719499446208,"mc":[{"id":"1.230180121","rc":[{"atl":[[3.4,2.84],[7.6,0]],"id":47370245}],"con":true,"img":false}]}
{"op":"mcm","clk":"11540877176","pt":1719499446619,"mc":[{"id":"1.230180121","rc":[{"atl":[[3.5,0]],"id":47370245},{"atb":[[3.8,21.9]],"id":64253834}],"con":true,"img":false}]}
{"op":"mcm","clk":"11540877184","pt":1719499446723,"mc":[{"id":"1.230180121","rc":[{"atb":[[3.7,12.87]],"id":62847579},{"atl":[[8.4,4.14]],"id":62847579}],"con":true,"img":false}]}
{"op":"mcm","clk":"11540877197","pt":1719499446780,"mc":[{"id":"1.230180121","rc":[{"atb":[[3.8,13.64]],"id":64253834}],"con":true,"img":false}]}
{"op":"mcm","clk":"11540877205","pt":1719499446881,"mc":[{"id":"1.230180121","rc":[{"atb":[[3.65,8.26]],"id":64253834}],"con":true,"img":false}]}
{"op":"mcm","clk":"11540877234","pt":1719499447193,"mc":[{"id":"1.230180121","rc":[{"atl":[[8.8,17.72]],"id":62847579}],"con":true,"img":false}]}
{"op":"mcm","clk":"11540877288","pt":1719499448016,"mc":[{"id":"1.230180121","rc":[{"atb":[[3.55,0]],"id":62847579},{"atl":[[8.8,12.82]],"id":62847579},{"atl":[[5.8,0.84]],"id":53432239},{"atl":[[2.96,0.84]],"id":69112387}],"con":true,"img":false}]}
{"op":"mcm","clk":"11540877293","pt":1719499448126,"mc":[{"id":"1.230180121","rc":[{"atl":[[5.8,21.67]],"id":53432239},{"atl":[[2.96,30.84],[2.94,9.56]],"id":69112387}],"con":true,"img":false}]}
{"op":"mcm","clk":"11540877302","pt":1719499448174,"mc":[{"id":"1.230180121","rc":[{"atb":[[3.7,15.38]],"id":62847579},{"atl":[[8.4,8.83]],"id":62847579},{"atl":[[5.7,18.15]],"id":53432239},{"atl":[[2.94,19.99]],"id":69112387}],"con":true,"img":false}]}
{"op":"mcm","clk":"11540877327","pt":1719499448585,"mc":[{"id":"1.230180121","rc":[{"atb":[[2.2,6.84]],"id":47370245}],"con":true,"img":false}]}
{"op":"mcm","clk":"11540877365","pt":1719499449111,"mc":[{"id":"1.230180121","rc":[{"atb":[[3.6,37.59]],"id":64253834}],"con":true,"img":false}]}
{"op":"mcm","clk":"11540877373","pt":1719499449208,"mc":[{"id":"1.230180121","rc":[{"atb":[[1.41,0],[1.46,25.94]],"id":69112387}],"con":true,"img":false}]}
{"op":"mcm","clk":"11540877410","pt":1719499449782,"mc":[{"id":"1.230180121","rc":[{"atb":[[1.96,5.67]],"id":69112387}],"con":true,"img":false}]}
{"op":"mcm","clk":"11540877422","pt":1719499449988,"mc":[{"id":"1.230180121","rc":[{"atb":[[2.2,2.5]],"id":47370245}],"con":true,"img":false}]}
{"op":"mcm","clk":"11540877430","pt":1719499450098,"mc":[{"id":"1.230180121","rc":[{"atb":[[3.6,33.48]],"id":64253834}],"con":true,"img":false}]}
{"op":"mcm","clk":"11540877438","pt":1719499450199,"mc":[{"id":"1.230180121","rc":[{"atb":[[2.18,3.46]],"id":47370245}],"con":true,"img":false}]}
{"op":"mcm","clk":"11540877444","pt":1719499450304,"mc":[{"id":"1.230180121","rc":[{"atb":[[2.18,0]],"id":47370245}],"con":true,"img":false}]}
{"op":"mcm","clk":"11540877465","pt":1719499450616,"mc":[{"id":"1.230180121","rc":[{"atl":[[3.4,13.82]],"id":47370245},{"atb":[[1.62,7.6]],"id":64536702}],"con":true,"img":false}]}
{"op":"mcm","clk":"11540877473","pt":1719499450721,"mc":[{"id":"1.230180121","rc":[{"atl":[[3.45,11.7]],"id":47370245}],"con":true,"img":false}]}
{"op":"mcm","clk":"11540877490","pt":1719499450928,"mc":[{"id":"1.230180121","rc":[{"atl":[[6.8,1],[7,4.99]],"id":53432239},{"atb":[[1.97,4.21]],"id":69112387},{"atb":[[3.6,0],[3.55,27.3]],"id":64253834},{"atl":[[9,0],[9.2,1]],"id":64253834}],"con":true,"img":false}]}
{"op":"mcm","clk":"11540877505","pt":1719499451084,"mc":[{"id":"1.230180121","rc":[{"atb":[[3.65,0]],"id":62847579},{"atb":[[1.97,2]],"id":69112387}],"con":true,"img":false}]}
{"op":"mcm","clk":"11540877526","pt":1719499451288,"mc":[{"id":"1.230180121","rc":[{"atb":[[3.75,3.34]],"id":62847579},{"atb":[[1.98,2.59]],"id":69112387}],"con":true,"img":false}]}
{"op":"mcm","clk":"11540877540","pt":1719499451493,"mc":[{"id":"1.230180121","rc":[{"atb":[[3.75,18.72],[3.7,11.47]],"id":62847579}],"con":true,"img":false}]}
{"op":"mcm","clk":"11540877590","pt":1719499452011,"mc":[{"id":"1.230180121","rc":[{"atb":[[1.97,0]],"id":69112387}],"con":true,"img":false}]}
{"op":"mcm","clk":"11540877598","pt":1719499452120,"mc":[{"id":"1.230180121","rc":[{"atb":[[1.99,2]],"id":69112387}],"con":true,"img":false}]}
{"op":"mcm","clk":"11540877607","pt":1719499452223,"mc":[{"id":"1.230180121","rc":[{"atb":[[3.7,2.51]],"id":62847579}],"con":true,"img":false}]}
{"op":"mcm","clk":"11540877627","pt":1719499452480,"mc":[{"id":"1.230180121","rc":[{"atb":[[1.71,0]],"id":64536702},{"atb":[[1.72,0]],"id":69112387}],"con":true,"img":false}]}
{"op":"mcm","clk":"11540877639","pt":1719499452686,"mc":[{"id":"1.230180121","rc":[{"atb":[[3.75,36.23]],"id":62847579},{"atl":[[8.2,11.11]],"id":62847579},{"atl":[[5.6,18.23]],"id":53432239},{"atb":[[1.62,6.29]],"id":64536702},{"atl":[[2.92,7.04]],"id":69112387}],"con":true,"img":false}]}
{"op":"mcm","clk":"11540877646","pt":1719499452790,"mc":[{"id":"1.230180121","rc":[{"atb":[[3.7,0]],"id":62847579},{"atl":[[3.45,2.99]],"id":47370245},{"atl":[[2.94,9.56]],"id":69112387}],"con":true,"img":false}]}
{"op":"mcm","clk":"11540877653","pt":1719499452894,"mc":[{"id":"1.230180121","rc":[{"atb":[[3.6,0]],"id":62847579},{"atl":[[8.6,0]],"id":62847579},{"atl":[[5.7,6.8]],"id":53432239},{"atl":[[2.94,0]],"id":69112387}],"con":true,"img":false}]}
{"op":"mcm","clk":"11540877660","pt":1719499452997,"mc":[{"id":"1.230180121","rc":[{"atb":[[3.75,38.53]],"id":62847579},{"atl":[[3.45,30.65],[3.4,20.35]],"id":47370245}],"con":true,"img":false}]}
{"op":"mcm","clk":"11540877668","pt":1719499453105,"mc":[{"id":"1.230180121","rc":[{"atl":[[8,0.84],[8.4,8.55]],"id":62847579},{"atl":[[5.8,20.83]],"id":53432239},{"atl":[[2.96,0],[3.3,40.4]],"id":69112387}],"con":true,"img":false}]}
{"op":"mcm","clk":"11540877684","pt":1719499453308,"mc":[{"id":"1.230180121","rc":[{"atl":[[8.4,5.53]],"id":62847579},{"atl":[[5.6,36.47],[5.8,0]],"id":53432239}],"con":true,"img":false}]}
{"op":"mcm","clk":"11540877692","pt":1719499453420,"mc":[{"id":"1.230180121","rc":[{"atl":[[8.2,14.13]],"id":62847579},{"atb":[[1.74,0],[1.7,2.11]],"id":64536702}],"con":true,"img":false}]}
{"op":"mcm","clk":"11540877712","pt":1719499453722,"mc":[{"id":"1.230180121","rc":[{"atl":[[5.8,4.2]],"id":53432239}],"con":true,"img":false}]}
{"op":"mcm","clk":"11540877720","pt":1719499453826,"mc":[{"id":"1.230180121","rc":[{"atl":[[5.8,0]],"id":53432239}],"con":true,"img":false}]}
{"op":"mcm","clk":"11540877748","pt":1719499454189,"mc":[{"id":"1.230180121","rc":[{"atb":[[1.62,0]],"id":64536702},{"atb":[[1.96,0]],"id":69112387}],"con":true,"img":false}]}
{"op":"mcm","clk":"11540877764","pt":1719499454396,"mc":[{"id":"1.230180121","rc":[{"atb":[[3.45,5.12]],"id":62847579}],"con":true,"img":false}]}
{"op":"mcm","clk":"11540877847","pt":1719499455486,"mc":[{"id":"1.230180121","rc":[{"atb":[[3.45,0]],"id":62847579}],"con":true,"img":false}]}
{"op":"mcm","clk":"11540877885","pt":1719499456110,"mc":[{"id":"1.230180121","rc":[{"atb":[[3.7,37.04],[3.75,23.15]],"id":62847579},{"atl":[[8.6,11.08],[8.8,0]],"id":62847579},{"atb":[[2.22,0],[2.2,39.96]],"id":47370245},{"atb":[[1.83,14.3]],"id":64536702},{"atl":[[3.4,1]],"id":69112387},{"atb":[[3.55,0],[3.5,27.3]],"id":64253834}],"con":true,"img":false}]}
{"op":"mcm","clk":"11540877906","pt":1719499456413,"mc":[{"id":"1.230180121","rc":[{"atb":[[1.71,7.78]],"id":64536702}],"con":true,"img":false}]}
{"op":"mcm","clk":"11540877935","pt":1719499456828,"mc":[{"id":"1.230180121","rc":[{"atb":[[1.83,11.1]],"id":64536702},{"atb":[[1.98,0]],"id":69112387},{"atb":[[3.35,0],[3.45,2.5],[3.15,0]],"id":64253834}],"con":true,"img":false}]}
{"op":"mcm","clk":"11540877945","pt":1719499456931,"mc":[{"id":"1.230180121","rc":[{"atb":[[2.22,3.6]],"id":47370245},{"atb":[[1.84,3.8]],"id":64536702},{"atb":[[1.96,3]],"id":69112387}],"con":true,"img":false}]}
{"op":"mcm","clk":"11540877978","pt":1719499457240,"mc":[{"id":"1.230180121","rc":[{"atl":[[4.8,1],[5.1,5],[5.5,10],[4.7,2.5]],"id":47370245}],"con":true,"img":false}]}
{"op":"mcm","clk":"11540877993","pt":1719499457394,"mc":[{"id":"1.230180121","rc":[{"atb":[[1.83,9.1]],"id":64536702}],"con":true,"img":false}]}
{"op":"mcm","clk":"11540877999","pt":1719499457497,"mc":[{"id":"1.230180121","rc":[{"atb":[[1.85,2]],"id":64536702}],"con":true,"img":false}]}
{"op":"mcm","clk":"11540878005","pt":1719499457601,"mc":[{"id":"1.230180121","rc":[{"atl":[[8.4,0.84]],"id":62847579},{"atl":[[5.7,0]],"id":53432239}],"con":true,"img":false}]}
{"op":"mcm","clk":"11540878011","pt":1719499457704,"mc":[{"id":"1.230180121","rc":[{"atl":[[8.2,18.7]],"id":62847579},{"atl":[[5.6,24.91],[6.8,18.24]],"id":53432239},{"atb":[[1.83,22.7]],"id":64536702},{"atl":[[3.65,13.24]],"id":64536702},{"atb":[[1.46,46.98]],"id":69112387},{"atl":[[2.92,17.38]],"id":69112387}],"con":true,"img":false}]}
{"op":"mcm","clk":"11540878018","pt":1719499457810,"mc":[{"id":"1.230180121","rc":[{"atl":[[3.95,5]],"id":64536702},{"atb":[[1.99,0]],"id":69112387}],"con":true,"img":false}]}
{"op":"mcm","clk":"11540878027","pt":1719499457914,"mc":[{"id":"1.230180121","rc":[{"atl":[[3.6,13.24]],"id":64536702},{"atb":[[1.97,2]],"id":69112387}],"con":true,"img":false}]}
{"op":"mcm","clk":"11540878038","pt":1719499458016,"mc":[{"id":"1.230180121","rc":[{"atl":[[3.6,17.96]],"id":64536702}],"con":true,"img":false}]}
{"op":"mcm","clk":"11540878045","pt":1719499458126,"mc":[{"id":"1.230180121","rc":[{"atl":[[3.45,2.99],[3.35,20.35]],"id":47370245}],"con":true,"img":false}]}
{"op":"mcm","clk":"11540878052","pt":1719499458223,"mc":[{"id":"1.230180121","rc":[{"atl":[[3.65,7.15]],"id":64536702},{"atl":[[2.9,17.38],[3.3,2.5]],"id":69112387}],"con":true,"img":false}]}
{"op":"mcm","clk":"11540878078","pt":1719499458637,"mc":[{"id":"1.230180121","rc":[{"atl":[[3.3,0.84]],"id":47370245},{"atl":[[3.55,0.84]],"id":64536702},{"atl":[[2.88,0.84]],"id":69112387}],"con":true,"img":false}]}
{"op":"mcm","clk":"11540878141","pt":1719499459514,"mc":[{"id":"1.230180121","rc":[{"atl":[[3.35,43.97]],"id":47370245}],"con":true,"img":false}]}
{"op":"mcm","clk":"11540878154","pt":1719499459726,"mc":[{"id":"1.230180121","rc":[{"atl":[[3.4,9.37]],"id":47370245}],"con":true,"img":false}]}
{"op":"mcm","clk":"11540878242","pt":1719499461229,"mc":[{"id":"1.230180121","rc":[{"atb":[[3.7,0],[3.75,46.31]],"id":62847579},{"atb":[[2.22,25.88],[2.2,2.5]],"id":47370245},{"atb":[[3.6,21.91],[3.5,0]],"id":64253834}],"con":true,"img":false}]}
{"op":"mcm","clk":"11540878251","pt":1719499461326,"mc":[{"id":"1.230180121","rc":[{"atb":[[3.5,42.5]],"id":62847579}],"con":true,"img":false}]}
{"op":"mcm","clk":"11540878257","pt":1719499461430,"mc":[{"id":"1.230180121","rc":[{"atb":[[3.75,23.15]],"id":62847579}],"con":true,"img":false}]}
{"op":"mcm","clk":"11540878262","pt":1719499461535,"mc":[{"id":"1.230180121","rc":[{"atb":[[3.5,2.5],[3.3,48.48]],"id":62847579}],"con":true,"img":false}]}
{"op":"mcm","clk":"11540878268","pt":1719499461637,"mc":[{"id":"1.230180121","rc":[{"atl":[[8,12.27]],"id":62847579},{"atl":[[2.9,21.22]],"id":69112387}],"con":true,"img":false}]}
{"op":"mcm","clk":"11540878275","pt":1719499461746,"mc":[{"id":"1.230180121","rc":[{"atb":[[3.3,5],[3.75,46.31]],"id":62847579},{"atl":[[8.2,7.59]],"id":62847579}],"con":true,"img":false}]}
{"op":"mcm","clk":"11540878283","pt":1719499461801,"mc":[{"id":"1.230180121","rc":[{"atl":[[2.92,11.18]],"id":69112387}],"con":true,"img":false}]}
{"op":"mcm","clk":"11540878299","pt":1719499462001,"mc":[{"id":"1.230180121","rc":[{"atl":[[8.2,7.49]],"id":62847579}],"con":true,"img":false}]}
{"op":"mcm","clk":"11540878308","pt":1719499462103,"mc":[{"id":"1.230180121","rc":[{"atl":[[8.4,0]],"id":62847579}],"con":true,"img":false}]}
{"op":"mcm","clk":"11540878320","pt":1719499462208,"mc":[{"id":"1.230180121","rc":[{"atl":[[8.2,4.57]],"id":62847579}],"con":true,"img":false}]}
{"op":"mcm","clk":"11540878330","pt":1719499462312,"mc":[{"id":"1.230180121","rc":[{"atl":[[8,15.19]],"id":62847579}],"con":true,"img":false}]}
{"op":"mcm","clk":"11540878355","pt":1719499462621,"mc":[{"id":"1.230180121","rc":[{"atb":[[2.22,22.28]],"id":47370245}],"con":true,"img":false}]}
{"op":"mcm","clk":"11540878360","pt":1719499462729,"mc":[{"id":"1.230180121","rc":[{"atl":[[8.2,0]],"id":62847579},{"atb":[[2.24,3]],"id":47370245},{"atl":[[3.4,0.84]],"id":47370245},{"atl":[[3.65,0.84]],"id":64536702},{"atl":[[2.92,0.84]],"id":69112387}],"con":true,"img":false}]}
{"op":"mcm","clk":"11540878370","pt":1719499462827,"mc":[{"id":"1.230180121","rc":[{"atl":[[5.5,18.24],[6.8,1]],"id":53432239}],"con":true,"img":false}]}
{"op":"mcm","clk":"11540878378","pt":1719499462930,"mc":[{"id":"1.230180121","rc":[{"atl":[[8,19.65]],"id":62847579},{"atl":[[5.5,29.59]],"id":53432239},{"atl":[[3.35,31.95],[3.4,42.51]],"id":47370245},{"atl":[[3.6,10.85],[3.65,19.65]],"id":64536702},{"atl":[[2.92,22.91],[2.9,14.07]],"id":69112387}],"con":true,"img":false}]}
{"op":"mcm","clk":"11540878383","pt":1719499463032,"mc":[{"id":"1.230180121","rc":[{"atl":[[5.6,7.52]],"id":53432239}],"con":true,"img":false}]}
{"op":"mcm","clk":"11540878388","pt":1719499463140,"mc":[{"id":"1.230180121","rc":[{"atl":[[6.2,21.73],[5.5,11.35],[5.4,0.84]],"id":53432239}],"con":true,"img":false}]}
{"op":"mcm","clk":"11540878404","pt":1719499463342,"mc":[{"id":"1.230180121","rc":[{"atl":[[6.2,2.5],[5.5,22.7]],"id":53432239}],"con":true,"img":false}]}
{"op":"mcm","clk":"11540878422","pt":1719499463499,"mc":[{"id":"1.230180121","rc":[{"atb":[[1.67,0]],"id":64536702}],"con":true,"img":false}]}
{"op":"mcm","clk":"11540878435","pt":1719499463706,"mc":[{"id":"1.230180121","rc":[{"atl":[[3.55,11.69],[3.65,0.84]],"id":64536702}],"con":true,"img":false}]}
{"op":"mcm","clk":"11540878468","pt":1719499464125,"mc":[{"id":"1.230180121","rc":[{"atl":[[3.65,0]],"id":64536702}],"con":true,"img":false}]}
{"op":"mcm","clk":"11540878474","pt":1719499464224,"mc":[{"id":"1.230180121","rc":[{"atl":[[2.9,17.09]],"id":69112387}],"con":true,"img":false}]}
{"op":"mcm","clk":"11540878483","pt":1719499464326,"mc":[{"id":"1.230180121","rc":[{"atb":[[2.22,26.55]],"id":47370245},{"atb":[[1.96,8.67]],"id":69112387},{"atl":[[2.88,17.93]],"id":69112387}],"con":true,"img":false}]}
{"op":"mcm","clk":"11540878493","pt":1719499464429,"mc":[{"id":"1.230180121","rc":[{"atl":[[2.92,0.84]],"id":69112387}],"con":true,"img":false}]}
{"op":"mcm","clk":"11540878499","pt":1719499464532,"mc":[{"id":"1.230180121","rc":[{"atl":[[3.4,0.84],[3.3,32.8]],"id":47370245}],"con":true,"img":false}]}
{"op":"mcm","clk":"11540878504","pt":1719499464637,"mc":[{"id":"1.230180121","rc":[{"atl":[[2.92,0]],"id":69112387}],"con":true,"img":false}]}
{"op":"mcm","clk":"11540878548","pt":1719499465101,"mc":[{"id":"1.230180121","rc":[{"atl":[[3.4,0]],"id":47370245}],"con":true,"img":false}]}
{"op":"mcm","clk":"11540878584","pt":1719499465619,"mc":[{"id":"1.230180121","rc":[{"atl":[[7.8,1.94]],"id":62847579},{"atl":[[5.4,2.99]],"id":53432239},{"atl":[[3.25,3.48]],"id":47370245},{"atl":[[3.5,2.9]],"id":64536702},{"atl":[[2.86,1.9]],"id":69112387}],"con":true,"img":false}]}
{"op":"mcm","clk":"11540878591","pt":1719499465722,"mc":[{"id":"1.230180121","rc":[{"atl":[[5.5,11.35],[5.3,7.52]],"id":53432239}],"con":true,"img":false}]}
{"op":"mcm","clk":"11540878598","pt":1719499465826,"mc":[{"id":"1.230180121","rc":[{"atl":[[3.4,6.6]],"id":47370245},{"atl":[[2.92,3.94],[2.9,14.07]],"id":69112387}],"con":true,"img":false}]}
{"op":"mcm","clk":"11540878605","pt":1719499465928,"mc":[{"id":"1.230180121","rc":[{"atl":[[3.4,0]],"id":47370245},{"atl":[[3.25,3]],"id":64536702}],"con":true,"img":false}]}
{"op":"mcm","clk":"11540878613","pt":1719499466031,"mc":[{"id":"1.230180121","rc":[{"atl":[[8,16.73]],"id":62847579},{"atl":[[2.92,0]],"id":69112387}],"con":true,"img":false}]}
{"op":"mcm","clk":"11540878620","pt":1719499466140,"mc":[{"id":"1.230180121","rc":[{"atl":[[7.6,0.84]],"id":62847579},{"atb":[[2.5,15.13]],"id":53432239},{"atl":[[5.6,6.67]],"id":53432239},{"atl":[[3.2,0.84]],"id":47370245},{"atl":[[3.45,0.84]],"id":64536702},{"atl":[[2.84,0.84]],"id":69112387}],"con":true,"img":false}]}
{"op":"mcm","clk":"11540878630","pt":1719499466238,"mc":[{"id":"1.230180121","rc":[{"atl":[[8.6,0],[8.8,12.82]],"id":62847579},{"atb":[[2.58,2.11],[2.76,0]],"id":53432239},{"atb":[[2.22,4.27],[2.2,24.78]],"id":47370245},{"atb":[[3.6,0],[3.45,29.8]],"id":64253834}],"con":true,"img":false}]}
{"op":"mcm","clk":"11540878634","pt":1719499466344,"mc":[{"id":"1.230180121","rc":[{"atb":[[2.22,0]],"id":47370245}],"con":true,"img":false}]}
{"op":"mcm","clk":"11540878660","pt":1719499466711,"mc":[{"id":"1.230180121","rc":[{"atl":[[3.45,0],[3.55,10.85]],"id":64536702}],"con":true,"img":false}]}
{"op":"mcm","clk":"11540878668","pt":1719499466816,"mc":[{"id":"1.230180121","rc":[{"atl":[[7.6,4.65]],"id":62847579},{"atb":[[2.18,5.38]],"id":47370245},{"atl":[[3.2,4.43]],"id":64536702}],"con":true,"img":false}]}
{"op":"mcm","clk":"11540878677","pt":1719499466918,"mc":[{"id":"1.230180121","rc":[{"atl":[[3.6,6.13]],"id":64536702}],"con":true,"img":false}]}
{"op":"mcm","clk":"11540878694","pt":1719499467128,"mc":[{"id":"1.230180121","rc":[{"atl":[[8,15.88]],"id":62847579}],"con":true,"img":false}]}
{"op":"mcm","clk":"11540878706","pt":1719499467226,"mc":[{"id":"1.230180121","rc":[{"atb":[[2.18,0]],"id":47370245}],"con":true,"img":false}]}
{"op":"mcm","clk":"11540878727","pt":1719499467537,"mc":[{"id":"1.230180121","rc":[{"atl":[[8,11.43]],"id":62847579},{"spn":5.67,"spf":"NaN","id":62847579},{"atl":[[5.6,0]],"id":53432239},{"spn":4.04,"spf":"NaN","id":53432239},{"atl":[[3.35,23.62]],"id":47370245},{"atl":[[3.6,0]],"id":64536702},{"spn":2.52,"spf":"NaN","id":64536702},{"atb":[[1.46,25.94]],"id":69112387},{"atl":[[2.9,3.84]],"id":69112387},{"spn":2.4,"spf":"NaN","id":69112387}],"con":true,"img":false}]}
{"op":"mcm","clk":"11540878742","pt":1719499467710,"mc":[{"id":"1.230180121","rc":[{"atl":[[7.6,8.84]],"id":62847579},{"atb":[[2.76,3.1]],"id":53432239},{"atl":[[5.3,13.78]],"id":53432239},{"atl":[[3.3,40.93]],"id":47370245},{"atl":[[3.2,8.88]],"id":64536702},{"atl":[[2.88,28.05]],"id":69112387}],"con":true,"img":false}]}
{"op":"mcm","clk":"11540878781","pt":1719499468221,"mc":[{"id":"1.230180121","rc":[{"atl":[[3.25,14.44]],"id":47370245}],"con":true,"img":false}]}
{"op":"mcm","clk":"11540878790","pt":1719499468319,"mc":[{"id":"1.230180121","rc":[{"atl":[[3.35,0]],"id":47370245}],"con":true,"img":false}]}
{"op":"mcm","clk":"11540878799","pt":1719499468421,"mc":[{"id":"1.230180121","rc":[{"atb":[[1.96,5.67]],"id":69112387}],"con":true,"img":false}]}
{"op":"mcm","clk":"11540878820","pt":1719499468731,"mc":[{"id":"1.230180121","rc":[{"atb":[[2.76,0]],"id":53432239}],"con":true,"img":false}]}
{"op":"mcm","clk":"11540878826","pt":1719499468834,"mc":[{"id":"1.230180121","rc":[{"atl":[[3.15,3]],"id":64536702}],"con":true,"img":false}]}
{"op":"mcm","clk":"11540878833","pt":1719499468937,"mc":[{"id":"1.230180121","rc":[{"atl":[[3.55,0]],"id":64536702}],"con":true,"img":false}]}
{"op":"mcm","clk":"11540878958","pt":1719499470342,"mc":[{"id":"1.230180121","rc":[{"atl":[[7.4,10.38]],"id":62847579},{"atl":[[2.86,4.99]],"id":69112387}],"con":true,"img":false}]}
{"op":"mcm","clk":"11540878975","pt":1719499470551,"mc":[{"id":"1.230180121","rc":[{"atl":[[8,0]],"id":62847579},{"atl":[[2.9,0]],"id":69112387}],"con":true,"img":false}]}
{"op":"mcm","clk":"11540878987","pt":1719499470655,"mc":[{"id":"1.230180121","rc":[{"atl":[[5.2,0.84]],"id":53432239}],"con":true,"img":false}]}
{"op":"mcm","clk":"11540878995","pt":1719499470709,"mc":[{"id":"1.230180121","rc":[{"atl":[[7.2,2.31]],"id":62847579},{"atl":[[5.2,3.18]],"id":53432239},{"atl":[[3.1,3.66]],"id":64536702},{"atl":[[9.6,1],[9.2,0]],"id":64253834}],"con":true,"img":false}]}
{"op":"mcm","clk":"11540879006","pt":1719499470810,"mc":[{"id":"1.230180121","rc":[{"atl":[[3.25,0]],"id":64536702}],"con":true,"img":false}]}
{"op":"mcm","clk":"11540879012","pt":1719499470913,"mc":[{"id":"1.230180121","rc":[{"atl":[[5.1,3.19],[5.3,6.26]],"id":53432239}],"con":true,"img":false}]}
{"op":"mcm","clk":"11540879021","pt":1719499471017,"mc":[{"id":"1.230180121","rc":[{"atl":[[5,2.56]],"id":53432239}],"con":true,"img":false}]}
{"op":"mcm","clk":"11540879029","pt":1719499471124,"mc":[{"id":"1.230180121","rc":[{"atl":[[7.6,7.99]],"id":62847579},{"atl":[[5.4,2.15]],"id":53432239},{"atl":[[3.15,6.15]],"id":64536702}],"con":true,"img":false}]}
{"op":"mcm","clk":"11540879040","pt":1719499471327,"mc":[{"id":"1.230180121","rc":[{"atl":[[7.6,4.18]],"id":62847579}],"con":true,"img":false}]}
{"op":"mcm","clk":"11540879061","pt":1719499471638,"mc":[{"id":"1.230180121","rc":[{"atl":[[4.9,4.31]],"id":53432239}],"con":true,"img":false}]}
{"op":"mcm","clk":"11540879068","pt":1719499471744,"mc":[{"id":"1.230180121","rc":[{"atl":[[4.8,2.8],[5.5,0],[5.2,2.34]],"id":53432239}],"con":true,"img":false}]}
{"op":"mcm","clk":"11540879077","pt":1719499471844,"mc":[{"id":"1.230180121","rc":[{"atl":[[4.8,5.6],[5.1,0]],"id":53432239}],"con":true,"img":false}]}
{"op":"mcm","clk":"11540879083","pt":1719499471903,"mc":[{"id":"1.230180121","rc":[{"atl":[[4.8,2.8],[4.9,9.91]],"id":53432239}],"con":true,"img":false}]}
{"op":"mcm","clk":"11540879092","pt":1719499472000,"mc":[{"id":"1.230180121","rc":[{"atl":[[7.2,6.2]],"id":62847579}],"con":true,"img":false}]}
{"op":"mcm","clk":"11540879112","pt":1719499472313,"mc":[{"id":"1.230180121","rc":[{"atl":[[7.6,0]],"id":62847579},{"atl":[[5.3,0]],"id":53432239},{"atl":[[3.3,32.8]],"id":47370245},{"atl":[[3.2,4.43]],"id":64536702},{"atl":[[2.88,17.93]],"id":69112387}],"con":true,"img":false}]}
{"op":"mcm","clk":"11540879126","pt":1719499472518,"mc":[{"id":"1.230180121","rc":[{"atl":[[7.2,10.08]],"id":62847579},{"atl":[[4.8,8.24]],"id":53432239},{"atl":[[3.25,22.36]],"id":47370245},{"atl":[[3.15,10.34]],"id":64536702},{"atb":[[1.46,46.98]],"id":69112387},{"atl":[[2.86,15]],"id":69112387}],"con":true,"img":false}]}
{"op":"mcm","clk":"11540879133","pt":1719499472622,"mc":[{"id":"1.230180121","rc":[{"atl":[[4.9,4.31],[4.7,8.24]],"id":53432239},{"atl":[[2.88,0.84],[2.84,15.84]],"id":69112387}],"con":true,"img":false}]}
{"op":"mcm","clk":"11540879138","pt":1719499472725,"mc":[{"id":"1.230180121","rc":[{"atl":[[4.6,2.84]],"id":53432239},{"atl":[[2.82,1.97]],"id":69112387}],"con":true,"img":false}]}
{"op":"mcm","clk":"11540879144","pt":1719499472828,"mc":[{"id":"1.230180121","rc":[{"atl":[[4.7,13.75]],"id":53432239}],"con":true,"img":false}]}
{"op":"mcm","clk":"11540879150","pt":1719499472932,"mc":[{"id":"1.230180121","rc":[{"atl":[[5.5,5.12]],"id":53432239}],"con":true,"img":false}]}
{"op":"mcm","clk":"11540879160","pt":1719499473035,"mc":[{"id":"1.230180121","rc":[{"atl":[[5.5,0]],"id":53432239}],"con":true,"img":false}]}
{"op":"mcm","clk":"11540879168","pt":1719499473139,"mc":[{"id":"1.230180121","rc":[{"atl":[[2.88,0]],"id":69112387}],"con":true,"img":false}]}
{"op":"mcm","clk":"11540879208","pt":1719499473606,"mc":[{"id":"1.230180121","rc":[{"atl":[[7,0.84]],"id":62847579},{"atl":[[3.05,0.84]],"id":64536702},{"atl":[[2.8,0.84]],"id":69112387}],"con":true,"img":false}]}
{"op":"mcm","clk":"11540879214","pt":1719499473710,"mc":[{"id":"1.230180121","rc":[{"atl":[[4.7,8.24]],"id":53432239}],"con":true,"img":false}]}
{"op":"mcm","clk":"11540879232","pt":1719499473921,"mc":[{"id":"1.230180121","rc":[{"atl":[[3.15,7.34],[3.05,4.5]],"id":64536702}],"con":true,"img":false}]}
{"op":"mcm","clk":"11540879241","pt":1719499474025,"mc":[{"id":"1.230180121","rc":[{"atl":[[3,1.68]],"id":64536702}],"con":true,"img":false}]}
{"op":"mcm","clk":"11540879250","pt":1719499474126,"mc":[{"id":"1.230180121","rc":[{"atb":[[1.97,5.4]],"id":69112387}],"con":true,"img":false}]}
{"op":"mcm","clk":"11540879271","pt":1719499474436,"mc":[{"id":"1.230180121","rc":[{"atl":[[4.6,8.8]],"id":53432239}],"con":true,"img":false}]}
{"op":"mcm","clk":"11540879282","pt":1719499474645,"mc":[{"id":"1.230180121","rc":[{"atl":[[4.5,8.24],[4.7,0]],"id":53432239}],"con":true,"img":false}]}
{"op":"mcm","clk":"11540879287","pt":1719499474697,"mc":[{"id":"1.230180121","rc":[{"atl":[[4.4,2.74]],"id":53432239}],"con":true,"img":false}]}
{"op":"mcm","clk":"11540879329","pt":1719499475315,"mc":[{"id":"1.230180121","rc":[{"atl":[[4.6,8.73]],"id":53432239}],"con":true,"img":false}]}
{"op":"mcm","clk":"11540879337","pt":1719499475417,"mc":[{"id":"1.230180121","rc":[{"atl":[[2.98,5.6]],"id":64536702}],"con":true,"img":false}]}
{"op":"mcm","clk":"11540879343","pt":1719499475520,"mc":[{"id":"1.230180121","rc":[{"atl":[[3.2,0],[2.96,1.74]],"id":64536702}],"con":true,"img":false}]}
