{"op":"mcm","clk":"11536380655","pt":1719425245599,"mc":[{"id":"1.230178322","marketDefinition":{"bspMarket":true,"turnInPlayEnabled":false,"persistenceEnabled":false,"marketBaseRate":5.0,"eventId":"33376062","eventTypeId":"4339","numberOfWinners":1,"bettingType":"ODDS","marketType":"WIN","marketTime":"2024-06-27T16:06:00.000Z","suspendTime":"2024-06-27T16:06:00.000Z","bspReconciled":false,"complete":true,"inPlay":false,"crossMatching":false,"runnersVoidable":false,"numberOfActiveRunners":6,"betDelay":0,"status":"OPEN","runners":[{"status":"ACTIVE","sortPriority":1,"id":70681333,"name":"1. Request"},{"status":"ACTIVE","sortPriority":2,"id":51569790,"name":"2. Jaxx Casparon"},{"status":"ACTIVE","sortPriority":3,"id":63650892,"name":"3. Brosna Summer"},{"status":"ACTIVE","sortPriority":4,"id":47885365,"name":"4. Springwell Zoey"},{"status":"ACTIVE","sortPriority":5,"id":68274051,"name":"5. Drumdoit Loret"},{"status":"ACTIVE","sortPriority":6,"id":60192591,"name":"6. Corruptor"}],"regulators":["MR_INT"],"venue":"Kinsley","countryCode":"GB","discountAllowed":false,"timezone":"Europe/London","openDate":"2024-06-27T13:36:00.000Z","version":5994643767,"name":"A7 462m","eventName":"Kinsley 27th Jun"},"rc":[],"con":true,"img":false}]}
{"op":"mcm","clk":"11536381019","pt":1719425248531,"mc":[{"id":"1.230178322","marketDefinition":{"bspMarket":true,"turnInPlayEnabled":false,"persistenceEnabled":false,"marketBaseRate":5.0,"eventId":"33376062","eventTypeId":"4339","numberOfWinners":1,"bettingType":"ODDS","marketType":"WIN","marketTime":"2024-06-27T16:06:00.000Z","suspendTime":"2024-06-27T16:06:00.000Z","bspReconciled":false,"complete":true,"inPlay":false,"crossMatching":false,"runnersVoidable":false,"numberOfActiveRunners":6,"betDelay":0,"status":"OPEN","runners":[{"status":"ACTIVE","sortPriority":1,"id":70681333,"name":"1. Request"},{"status":"ACTIVE","sortPriority":2,"id":51569790,"name":"2. Jaxx Casparon"},{"status":"ACTIVE","sortPriority":3,"id":63650892,"name":"3. Brosna Summer"},{"status":"ACTIVE","sortPriority":4,"id":47885365,"name":"4. Springwell Zoey"},{"status":"ACTIVE","sortPriority":5,"id":68274051,"name":"5. Drumdoit Loret"},{"status":"ACTIVE","sortPriority":6,"id":60192591,"name":"6. Corruptor"}],"regulators":["MR_INT"],"venue":"Kinsley","countryCode":"GB","discountAllowed":true,"timezone":"Europe/London","openDate":"2024-06-27T13:36:00.000Z","version":5994643767,"name":"A7 462m","eventName":"Kinsley 27th Jun"},"rc":[],"con":true,"img":false}]}
{"op":"mcm","clk":"11536614457","pt":1719428234705,"mc":[{"id":"1.230178322","rc":[{"atb":[[1.03,7.88]],"id":70681333},{"atl":[[990,0.84]],"id":70681333},{"spn":495.51,"spf":"NaN","id":70681333},{"atb":[[1.02,11.82]],"id":47885365},{"atl":[[990,0.84]],"id":47885365},{"spn":495.51,"spf":"NaN","id":47885365},{"atb":[[1.01,23.65]],"id":63650892},{"atl":[[990,0.84]],"id":63650892},{"spn":495.5,"spf":"NaN","id":63650892},{"atb":[[1.03,7.88]],"id":68274051},{"atl":[[1000,0.84]],"id":68274051},{"spn":500.51,"spf":"NaN","id":68274051},{"atb":[[1.03,7.88]],"id":51569790},{"atl":[[990,0.84]],"id":51569790},{"spn":495.51,"spf":"NaN","id":51569790},{"atb":[[1.03,7.88]],"id":60192591},{"atl":[[990,0.84]],"id":60192591},{"spn":495.51,"spf":"NaN","id":60192591}],"con":true,"img":false}]}
{"op":"mcm","clk":"11536836539","pt":1719431844413,"mc":[{"id":"1.230178322","rc":[{"atb":[[1.03,7.88]],"id":70681333},{"atl":[[990,0.22]],"id":70681333},{"atb":[[1.02,11.82]],"id":47885365},{"atl":[[990,0.22]],"id":47885365},{"atb":[[1.01,23.66]],"id":63650892},{"atl":[[990,0.22]],"id":63650892},{"atb":[[1.03,7.88]],"id":68274051},{"atl":[[1000,0.22]],"id":68274051},{"atb":[[1.03,7.88]],"id":51569790},{"atl":[[990,0.22]],"id":51569790},{"atb":[[1.03,7.88]],"id":60192591},{"atl":[[990,0.22]],"id":60192591}],"con":true,"img":false}]}
{"op":"mcm","clk":"11537232279","pt":1719437882527,"mc":[{"id":"1.230178322","marketDefinition":{"bspMarket":true,"turnInPlayEnabled":false,"persistenceEnabled":false,"marketBaseRate":5.0,"eventId":"33376062","eventTypeId":"4339","numberOfWinners":1,"bettingType":"ODDS","marketType":"WIN","marketTime":"2024-06-27T16:06:00.000Z","suspendTime":"2024-06-27T16:06:00.000Z","bspReconciled":false,"complete":true,"inPlay":false,"crossMatching":false,"runnersVoidable":false,"numberOfActiveRunners":6,"betDelay":0,"status":"OPEN","runners":[{"status":"ACTIVE","sortPriority":1,"id":70681333,"name":"1. Request"},{"status":"ACTIVE","sortPriority":2,"id":51569790,"name":"2. Jaxx Casparon"},{"status":"ACTIVE","sortPriority":3,"id":63650892,"name":"3. Brosna Summer"},{"status":"ACTIVE","sortPriority":4,"id":47885365,"name":"4. Springwell Zoey"},{"status":"ACTIVE","sortPriority":5,"id":68274051,"name":"5. Drumdoit Loret"},{"status":"ACTIVE","sortPriority":6,"id":60192591,"name":"6. Corruptor"}],"regulators":["MR_INT"],"venue":"Kinsley","countryCode":"GB","discountAllowed":true,"timezone":"Europe/London","openDate":"2024-06-27T13:36:00.000Z","version":5994643767,"name":"A7 462m","eventName":"Kinsley 27th Jun"},"rc":[{"atb":[[1.03,7.88]],"id":70681333},{"atl":[[990,0.22]],"id":70681333},{"spn":495.51,"spf":"NaN","id":70681333},{"atb":[[1.02,11.82]],"id":47885365},{"atl":[[990,0.22]],"id":47885365},{"spn":495.51,"spf":"NaN","id":47885365},{"atb":[[1.01,23.66]],"id":63650892},{"atl":[[990,0.22]],"id":63650892},{"spn":495.5,"spf":"NaN","id":63650892},{"atb":[[1.03,7.88]],"id":68274051},{"atl":[[1000,0.22]],"id":68274051},{"spn":500.51,"spf":"NaN","id":68274051},{"atb":[[1.03,7.88]],"id":51569790},{"atl":[[990,0.22]],"id":51569790},{"spn":495.51,"spf":"NaN","id":51569790},{"atb":[[1.03,7.88]],"id":60192591},{"atl":[[990,0.22]],"id":60192591},{"spn":495.51,"spf":"NaN","id":60192591}],"con":true,"img":true}]}
{"op":"mcm","clk":"11537573406","pt":1719443282546,"mc":[{"id":"1.230178322","marketDefinition":{"bspMarket":true,"turnInPlayEnabled":false,"persistenceEnabled":false,"marketBaseRate":5.0,"eventId":"33376062","eventTypeId":"4339","numberOfWinners":1,"bettingType":"ODDS","marketType":"WIN","marketTime":"2024-06-27T16:06:00.000Z","suspendTime":"2024-06-27T16:06:00.000Z","bspReconciled":false,"complete":true,"inPlay":false,"crossMatching":false,"runnersVoidable":false,"numberOfActiveRunners":6,"betDelay":0,"status":"OPEN","runners":[{"status":"ACTIVE","sortPriority":1,"id":70681333,"name":"1. Request"},{"status":"ACTIVE","sortPriority":2,"id":51569790,"name":"2. Jaxx Casparon"},{"status":"ACTIVE","sortPriority":3,"id":63650892,"name":"3. Brosna Summer"},{"status":"ACTIVE","sortPriority":4,"id":47885365,"name":"4. Springwell Zoey"},{"status":"ACTIVE","sortPriority":5,"id":68274051,"name":"5. Drumdoit Loret"},{"status":"ACTIVE","sortPriority":6,"id":60192591,"name":"6. Corruptor"}],"regulators":["MR_INT"],"venue":"Kinsley","countryCode":"GB","discountAllowed":true,"timezone":"Europe/London","openDate":"2024-06-27T13:36:00.000Z","version":5994643767,"name":"A7 462m","eventName":"Kinsley 27th Jun"},"rc":[{"atb":[[1.03,7.88]],"id":70681333},{"atl":[[990,0.22]],"id":70681333},{"spn":495.51,"spf":"NaN","id":70681333},{"atb":[[1.02,11.83]],"id":47885365},{"atl":[[990,0.22]],"id":47885365},{"spn":495.51,"spf":"NaN","id":47885365},{"atb":[[1.01,23.66]],"id":63650892},{"atl":[[990,0.22]],"id":63650892},{"spn":495.5,"spf":"NaN","id":63650892},{"atb":[[1.03,7.88]],"id":68274051},{"atl":[[1000,0.22]],"id":68274051},{"spn":500.51,"spf":"NaN","id":68274051},{"atb":[[1.03,7.88]],"id":51569790},{"atl":[[990,0.22]],"id":51569790},{"spn":495.51,"spf":"NaN","id":51569790},{"atb":[[1.03,7.88]],"id":60192591},{"atl":[[990,0.22]],"id":60192591},{"spn":495.51,"spf":"NaN","id":60192591}],"con":true,"img":true}]}
{"op":"mcm","clk":"11537954966","pt":1719448682570,"mc":[{"id":"1.230178322","marketDefinition":{"bspMarket":true,"turnInPlayEnabled":false,"persistenceEnabled":false,"marketBaseRate":5.0,"eventId":"33376062","eventTypeId":"4339","numberOfWinners":1,"bettingType":"ODDS","marketType":"WIN","marketTime":"2024-06-27T16:06:00.000Z","suspendTime":"2024-06-27T16:06:00.000Z","bspReconciled":false,"complete":true,"inPlay":false,"crossMatching":false,"runnersVoidable":false,"numberOfActiveRunners":6,"betDelay":0,"status":"OPEN","runners":[{"status":"ACTIVE","sortPriority":1,"id":70681333,"name":"1. Request"},{"status":"ACTIVE","sortPriority":2,"id":51569790,"name":"2. Jaxx Casparon"},{"status":"ACTIVE","sortPriority":3,"id":63650892,"name":"3. Brosna Summer"},{"status":"ACTIVE","sortPriority":4,"id":47885365,"name":"4. Springwell Zoey"},{"status":"ACTIVE","sortPriority":5,"id":68274051,"name":"5. Drumdoit Loret"},{"status":"ACTIVE","sortPriority":6,"id":60192591,"name":"6. Corruptor"}],"regulators":["MR_INT"],"venue":"Kinsley","countryCode":"GB","discountAllowed":true,"timezone":"Europe/London","openDate":"2024-06-27T13:36:00.000Z","version":5994643767,"name":"A7 462m","eventName":"Kinsley 27th Jun"},"rc":[{"atb":[[1.03,7.88]],"id":70681333},{"atl":[[990,0.22]],"id":70681333},{"spn":495.51,"spf":"NaN","id":70681333},{"atb":[[1.02,11.82]],"id":47885365},{"atl":[[990,0.22]],"id":47885365},{"spn":495.51,"spf":"NaN","id":47885365},{"atb":[[1.01,23.66]],"id":63650892},{"atl":[[990,0.22]],"id":63650892},{"spn":495.5,"spf":"NaN","id":63650892},{"atb":[[1.03,7.88]],"id":68274051},{"atl":[[1000,0.22]],"id":68274051},{"spn":500.51,"spf":"NaN","id":68274051},{"atb":[[1.03,7.88]],"id":51569790},{"atl":[[990,0.22]],"id":51569790},{"spn":495.51,"spf":"NaN","id":51569790},{"atb":[[1.03,7.88]],"id":60192591},{"atl":[[990,0.22]],"id":60192591},{"spn":495.51,"spf":"NaN","id":60192591}],"con":true,"img":true}]}
{"op":"mcm","clk":"11538170629","pt":1719454082552,"mc":[{"id":"1.230178322","marketDefinition":{"bspMarket":true,"turnInPlayEnabled":false,"persistenceEnabled":false,"marketBaseRate":5.0,"eventId":"33376062","eventTypeId":"4339","numberOfWinners":1,"bettingType":"ODDS","marketType":"WIN","marketTime":"2024-06-27T16:06:00.000Z","suspendTime":"2024-06-27T16:06:00.000Z","bspReconciled":false,"complete":true,"inPlay":false,"crossMatching":false,"runnersVoidable":false,"numberOfActiveRunners":6,"betDelay":0,"status":"OPEN","runners":[{"status":"ACTIVE","sortPriority":1,"id":70681333,"name":"1. Request"},{"status":"ACTIVE","sortPriority":2,"id":51569790,"name":"2. Jaxx Casparon"},{"status":"ACTIVE","sortPriority":3,"id":63650892,"name":"3. Brosna Summer"},{"status":"ACTIVE","sortPriority":4,"id":47885365,"name":"4. Springwell Zoey"},{"status":"ACTIVE","sortPriority":5,"id":68274051,"name":"5. Drumdoit Loret"},{"status":"ACTIVE","sortPriority":6,"id":60192591,"name":"6. Corruptor"}],"regulators":["MR_INT"],"venue":"Kinsley","countryCode":"GB","discountAllowed":true,"timezone":"Europe/London","openDate":"2024-06-27T13:36:00.000Z","version":5994643767,"name":"A7 462m","eventName":"Kinsley 27th Jun"},"rc":[{"atb":[[1.03,7.88]],"id":70681333},{"atl":[[990,0.22]],"id":70681333},{"spn":495.51,"spf":"NaN","id":70681333},{"atb":[[1.02,11.83]],"id":47885365},{"atl":[[990,0.22]],"id":47885365},{"spn":495.51,"spf":"NaN","id":47885365},{"atb":[[1.01,23.67]],"id":63650892},{"atl":[[990,0.22]],"id":63650892},{"spn":495.5,"spf":"NaN","id":63650892},{"atb":[[1.03,7.88]],"id":68274051},{"atl":[[1000,0.22]],"id":68274051},{"spn":500.51,"spf":"NaN","id":68274051},{"atb":[[1.03,7.88]],"id":51569790},{"atl":[[990,0.22]],"id":51569790},{"spn":495.51,"spf":"NaN","id":51569790},{"atb":[[1.03,7.88]],"id":60192591},{"atl":[[990,0.22]],"id":60192591},{"spn":495.51,"spf":"NaN","id":60192591}],"con":true,"img":true}]}
{"op":"mcm","clk":"11538368287","pt":1719459482603,"mc":[{"id":"1.230178322","marketDefinition":{"bspMarket":true,"turnInPlayEnabled":false,"persistenceEnabled":false,"marketBaseRate":5.0,"eventId":"33376062","eventTypeId":"4339","numberOfWinners":1,"bettingType":"ODDS","marketType":"WIN","marketTime":"2024-06-27T16:06:00.000Z","suspendTime":"2024-06-27T16:06:00.000Z","bspReconciled":false,"complete":true,"inPlay":false,"crossMatching":false,"runnersVoidable":false,"numberOfActiveRunners":6,"betDelay":0,"status":"OPEN","runners":[{"status":"ACTIVE","sortPriority":1,"id":70681333,"name":"1. Request"},{"status":"ACTIVE","sortPriority":2,"id":51569790,"name":"2. Jaxx Casparon"},{"status":"ACTIVE","sortPriority":3,"id":63650892,"name":"3. Brosna Summer"},{"status":"ACTIVE","sortPriority":4,"id":47885365,"name":"4. Springwell Zoey"},{"status":"ACTIVE","sortPriority":5,"id":68274051,"name":"5. Drumdoit Loret"},{"status":"ACTIVE","sortPriority":6,"id":60192591,"name":"6. Corruptor"}],"regulators":["MR_INT"],"venue":"Kinsley","countryCode":"GB","discountAllowed":true,"timezone":"Europe/London","openDate":"2024-06-27T13:36:00.000Z","version":5994643767,"name":"A7 462m","eventName":"Kinsley 27th Jun"},"rc":[{"atb":[[1.03,7.88]],"id":70681333},{"atl":[[990,0.22]],"id":70681333},{"spn":495.51,"spf":"NaN","id":70681333},{"atb":[[1.02,11.83]],"id":47885365},{"atl":[[990,0.22]],"id":47885365},{"spn":495.51,"spf":"NaN","id":47885365},{"atb":[[1.01,23.67]],"id":63650892},{"atl":[[990,0.22]],"id":63650892},{"spn":495.5,"spf":"NaN","id":63650892},{"atb":[[1.03,7.88]],"id":68274051},{"atl":[[1000,0.22]],"id":68274051},{"spn":500.51,"spf":"NaN","id":68274051},{"atb":[[1.03,7.88]],"id":51569790},{"atl":[[990,0.22]],"id":51569790},{"spn":495.51,"spf":"NaN","id":51569790},{"atb":[[1.03,7.88]],"id":60192591},{"atl":[[990,0.22]],"id":60192591},{"spn":495.51,"spf":"NaN","id":60192591}],"con":true,"img":true}]}
{"op":"mcm","clk":"11538595413","pt":1719464882551,"mc":[{"id":"1.230178322","marketDefinition":{"bspMarket":true,"turnInPlayEnabled":false,"persistenceEnabled":false,"marketBaseRate":5.0,"eventId":"33376062","eventTypeId":"4339","numberOfWinners":1,"bettingType":"ODDS","marketType":"WIN","marketTime":"2024-06-27T16:06:00.000Z","suspendTime":"2024-06-27T16:06:00.000Z","bspReconciled":false,"complete":true,"inPlay":false,"crossMatching":false,"runnersVoidable":false,"numberOfActiveRunners":6,"betDelay":0,"status":"OPEN","runners":[{"status":"ACTIVE","sortPriority":1,"id":70681333,"name":"1. Request"},{"status":"ACTIVE","sortPriority":2,"id":51569790,"name":"2. Jaxx Casparon"},{"status":"ACTIVE","sortPriority":3,"id":63650892,"name":"3. Brosna Summer"},{"status":"ACTIVE","sortPriority":4,"id":47885365,"name":"4. Springwell Zoey"},{"status":"ACTIVE","sortPriority":5,"id":68274051,"name":"5. Drumdoit Loret"},{"status":"ACTIVE","sortPriority":6,"id":60192591,"name":"6. Corruptor"}],"regulators":["MR_INT"],"venue":"Kinsley","countryCode":"GB","discountAllowed":true,"timezone":"Europe/London","openDate":"2024-06-27T13:36:00.000Z","version":5994643767,"name":"A7 462m","eventName":"Kinsley 27th Jun"},"rc":[{"atb":[[1.03,7.88]],"id":70681333},{"atl":[[990,0.22]],"id":70681333},{"spn":495.51,"spf":"NaN","id":70681333},{"atb":[[1.02,11.83]],"id":47885365},{"atl":[[990,0.22]],"id":47885365},{"spn":495.51,"spf":"NaN","id":47885365},{"atb":[[1.01,23.67]],"id":63650892},{"atl":[[990,0.22]],"id":63650892},{"spn":495.5,"spf":"NaN","id":63650892},{"atb":[[1.03,7.88]],"id":68274051},{"atl":[[1000,0.22]],"id":68274051},{"spn":500.51,"spf":"NaN","id":68274051},{"atb":[[1.03,7.88]],"id":51569790},{"atl":[[990,0.22]],"id":51569790},{"spn":495.51,"spf":"NaN","id":51569790},{"atb":[[1.03,7.88]],"id":60192591},{"atl":[[990,0.22]],"id":60192591},{"spn":495.51,"spf":"NaN","id":60192591}],"con":true,"img":true}]}
{"op":"mcm","clk":"11538748630","pt":1719468205015,"mc":[{"id":"1.230178322","rc":[{"atb":[[2.02,12.08],[1.03,7.88]],"id":70681333},{"spn":496.01,"spf":"NaN","id":70681333},{"atb":[[1.02,11.83],[2.1,11.66]],"id":47885365},{"spn":496.05,"spf":"NaN","id":47885365},{"atb":[[2,9.4],[1.01,23.67]],"id":63650892},{"spn":496.0,"spf":"NaN","id":63650892},{"atb":[[1.03,7.88],[2.1,13.45]],"id":68274051},{"spn":501.05,"spf":"NaN","id":68274051},{"atb":[[2,12.82],[1.03,7.88]],"id":51569790},{"spn":496.0,"spf":"NaN","id":51569790},{"atb":[[1.03,7.88],[2.06,13.2]],"id":60192591},{"spn":496.03,"spf":"NaN","id":60192591}],"con":true,"img":false}]}
{"op":"mcm","clk":"11538750456","pt":1719468244036,"mc":[{"id":"1.230178322","rc":[{"atb":[[2.04,3.16]],"id":70681333}],"con":true,"img":false}]}
{"op":"mcm","clk":"11538750469","pt":1719468244240,"mc":[{"id":"1.230178322","rc":[{"atb":[[2.02,3.16]],"id":63650892}],"con":true,"img":false}]}
{"op":"mcm","clk":"11538750482","pt":1719468244445,"mc":[{"id":"1.230178322","rc":[{"atb":[[2.08,3.16]],"id":60192591}],"con":true,"img":false}]}
{"op":"mcm","clk":"11538750497","pt":1719468244645,"mc":[{"id":"1.230178322","rc":[{"atb":[[2.02,3.16]],"id":51569790}],"con":true,"img":false}]}
{"op":"mcm","clk":"11538750504","pt":1719468244746,"mc":[{"id":"1.230178322","rc":[{"atb":[[2.12,3.16]],"id":47885365}],"con":true,"img":false}]}
{"op":"mcm","clk":"11538750513","pt":1719468244852,"mc":[{"id":"1.230178322","rc":[{"atb":[[2.12,3.16]],"id":68274051}],"con":true,"img":false}]}
{"op":"mcm","clk":"11538752353","pt":1719468281481,"mc":[{"id":"1.230178322","rc":[{"spn":496.02,"spf":"NaN","id":70681333},{"spn":496.06,"spf":"NaN","id":47885365},{"atb":[[2.02,6.55]],"id":63650892},{"spn":496.01,"spf":"NaN","id":63650892},{"spn":501.06,"spf":"NaN","id":68274051},{"spn":496.01,"spf":"NaN","id":51569790},{"spn":496.04,"spf":"NaN","id":60192591}],"con":true,"img":false}]}
{"op":"mcm","clk":"11538752402","pt":1719468281787,"mc":[{"id":"1.230178322","rc":[{"atb":[[2.04,6.55]],"id":70681333},{"atb":[[2.02,6.55]],"id":51569790}],"con":true,"img":false}]}
{"op":"mcm","clk":"11538752418","pt":1719468282096,"mc":[{"id":"1.230178322","rc":[{"atb":[[2.12,6.55]],"id":47885365},{"atb":[[2.12,6.55]],"id":68274051}],"con":true,"img":false}]}
{"op":"mcm","clk":"11538752448","pt":1719468282817,"mc":[{"id":"1.230178322","rc":[{"atb":[[2.08,6.55]],"id":60192591}],"con":true,"img":false}]}
{"op":"mcm","clk":"11538754055","pt":1719468311787,"mc":[{"id":"1.230178322","marketDefinition":{"bspMarket":true,"turnInPlayEnabled":false,"persistenceEnabled":false,"marketBaseRate":5.0,"eventId":"33376062","eventTypeId":"4339","numberOfWinners":1,"bettingType":"ODDS","marketType":"WIN","marketTime":"2024-06-27T16:06:00.000Z","suspendTime":"2024-06-27T16:06:00.000Z","bspReconciled":false,"complete":true,"inPlay":false,"crossMatching":true,"runnersVoidable":false,"numberOfActiveRunners":6,"betDelay":0,"status":"OPEN","runners":[{"status":"ACTIVE","sortPriority":1,"id":70681333,"name":"1. Request"},{"status":"ACTIVE","sortPriority":2,"id":51569790,"name":"2. Jaxx Casparon"},{"status":"ACTIVE","sortPriority":3,"id":63650892,"name":"3. Brosna Summer"},{"status":"ACTIVE","sortPriority":4,"id":47885365,"name":"4. Springwell Zoey"},{"status":"ACTIVE","sortPriority":5,"id":68274051,"name":"5. Drumdoit Loret"},{"status":"ACTIVE","sortPriority":6,"id":60192591,"name":"6. Corruptor"}],"regulators":["MR_INT"],"venue":"Kinsley","countryCode":"GB","discountAllowed":true,"timezone":"Europe/London","openDate":"2024-06-27T13:36:00.000Z","version":5994643767,"name":"A7 462m","eventName":"Kinsley 27th Jun"},"rc":[],"con":true,"img":false}]}
{"op":"mcm","clk":"11538932716","pt":1719471965405,"mc":[{"id":"1.230178322","rc":[{"atb":[[2.02,12.07],[1.03,7.88],[2.04,6.54]],"id":70681333},{"atl":[[150,4],[990,0.22]],"id":70681333},{"spn":76.02,"spf":"NaN","id":70681333},{"atb":[[1.02,11.82],[2.12,6.54],[2.1,11.65]],"id":47885365},{"atl":[[990,0.22]],"id":47885365},{"atb":[[2,9.39],[2.02,6.54],[1.01,23.65]],"id":63650892},{"atl":[[150,4],[990,0.22]],"id":63650892},{"spn":76.01,"spf":"NaN","id":63650892},{"atb":[[1.03,7.88],[2.12,6.54],[2.1,13.44]],"id":68274051},{"atl":[[1000,0.22]],"id":68274051},{"atb":[[2,12.81],[2.02,6.54],[1.03,7.88]],"id":51569790},{"atl":[[990,0.22]],"id":51569790},{"atb":[[2.06,13.19],[1.03,7.88],[2.08,6.54]],"id":60192591},{"atl":[[990,0.22]],"id":60192591}],"con":true,"img":false}]}
{"op":"mcm","clk":"11538932725","pt":1719471965511,"mc":[{"id":"1.230178322","rc":[{"atl":[[150,4]],"id":47885365},{"atl":[[150,4]],"id":68274051},{"atl":[[150,4]],"id":51569790},{"atl":[[150,4]],"id":60192591}],"con":true,"img":false}]}
{"op":"mcm","clk":"11538938883","pt":1719472079440,"mc":[{"id":"1.230178322","rc":[{"spn":76.06,"spf":"NaN","id":47885365},{"atl":[[26,0.6]],"id":63650892},{"spn":14.01,"spf":"NaN","id":63650892},{"spn":76.06,"spf":"NaN","id":68274051},{"spn":76.01,"spf":"NaN","id":51569790},{"atb":[[6,4],[4.2,15.62]],"id":60192591},{"spn":78.0,"spf":"NaN","id":60192591}],"con":true,"img":false}]}
{"op":"mcm","clk":"11538939714","pt":1719472096063,"mc":[{"id":"1.230178322","rc":[{"atb":[[2.08,3.38]],"id":60192591}],"con":true,"img":false}]}
{"op":"mcm","clk":"11538940668","pt":1719472112387,"mc":[{"id":"1.230178322","rc":[{"atb":[[2.02,0]],"id":70681333},{"atb":[[2.1,0]],"id":47885365},{"atb":[[2,0]],"id":63650892},{"atb":[[2.1,0]],"id":68274051},{"atb":[[2,0]],"id":51569790},{"atb":[[2.06,0]],"id":60192591}],"con":true,"img":false}]}
{"op":"mcm","clk":"11538940675","pt":1719472112441,"mc":[{"id":"1.230178322","rc":[{"atb":[[2.06,12.07]],"id":70681333},{"atb":[[2.14,11.65]],"id":47885365},{"atb":[[2.04,9.39]],"id":63650892},{"atb":[[2.14,13.44]],"id":68274051},{"atb":[[2.04,12.81]],"id":51569790},{"atb":[[2.1,13.19]],"id":60192591}],"con":true,"img":false}]}
{"op":"mcm","clk":"11538942747","pt":1719472145107,"mc":[{"id":"1.230178322","rc":[{"atb":[[2.04,3.38]],"id":70681333},{"spn":76.03,"spf":"NaN","id":70681333},{"spn":76.07,"spf":"NaN","id":47885365},{"spn":14.02,"spf":"NaN","id":63650892},{"spn":76.07,"spf":"NaN","id":68274051},{"spn":76.02,"spf":"NaN","id":51569790}],"con":true,"img":false}]}
{"op":"mcm","clk":"11538942809","pt":1719472145931,"mc":[{"id":"1.230178322","rc":[{"atb":[[2.12,3.38]],"id":68274051}],"con":true,"img":false}]}
{"op":"mcm","clk":"11538942880","pt":1719472146813,"mc":[{"id":"1.230178322","rc":[{"atb":[[2.02,3.38]],"id":63650892}],"con":true,"img":false}]}
{"op":"mcm","clk":"11538942897","pt":1719472147022,"mc":[{"id":"1.230178322","rc":[{"atb":[[2.08,3.16]],"id":70681333}],"con":true,"img":false}]}
{"op":"mcm","clk":"11538942990","pt":1719472148207,"mc":[{"id":"1.230178322","rc":[{"atb":[[2.06,3.16]],"id":63650892}],"con":true,"img":false}]}
{"op":"mcm","clk":"11538943001","pt":1719472148408,"mc":[{"id":"1.230178322","rc":[{"atb":[[2.02,3.38]],"id":51569790}],"con":true,"img":false}]}
{"op":"mcm","clk":"11538943045","pt":1719472149129,"mc":[{"id":"1.230178322","rc":[{"atb":[[2.12,3.38]],"id":47885365}],"con":true,"img":false}]}
{"op":"mcm","clk":"11538943088","pt":1719472149898,"mc":[{"id":"1.230178322","rc":[{"atb":[[2.06,3.16]],"id":51569790}],"con":true,"img":false}]}
{"op":"mcm","clk":"11538943115","pt":1719472150306,"mc":[{"id":"1.230178322","rc":[{"atb":[[2.16,3.16]],"id":68274051}],"con":true,"img":false}]}
{"op":"mcm","clk":"11538943328","pt":1719472153902,"mc":[{"id":"1.230178322","rc":[{"atb":[[2.16,3.16]],"id":47885365}],"con":true,"img":false}]}
{"op":"mcm","clk":"11538943596","pt":1719472158505,"mc":[{"id":"1.230178322","rc":[{"atb":[[2.12,0]],"id":68274051}],"con":true,"img":false}]}
{"op":"mcm","clk":"11538943615","pt":1719472158913,"mc":[{"id":"1.230178322","rc":[{"atb":[[2.04,0]],"id":70681333},{"atb":[[2.02,0]],"id":51569790}],"con":true,"img":false}]}
{"op":"mcm","clk":"11538943632","pt":1719472159221,"mc":[{"id":"1.230178322","rc":[{"atb":[[2.02,0]],"id":63650892},{"atb":[[2.08,0]],"id":60192591}],"con":true,"img":false}]}
{"op":"mcm","clk":"11538943667","pt":1719472159936,"mc":[{"id":"1.230178322","rc":[{"atb":[[2.12,0]],"id":47885365}],"con":true,"img":false}]}
{"op":"mcm","clk":"11538944520","pt":1719472173763,"mc":[{"id":"1.230178322","rc":[{"atb":[[2.16,6.54]],"id":68274051}],"con":true,"img":false}]}
{"op":"mcm","clk":"11538944558","pt":1719472174429,"mc":[{"id":"1.230178322","rc":[{"atb":[[2.06,6.54]],"id":51569790}],"con":true,"img":false}]}
{"op":"mcm","clk":"11538944581","pt":1719472174839,"mc":[{"id":"1.230178322","rc":[{"atb":[[2.08,6.54]],"id":70681333}],"con":true,"img":false}]}
{"op":"mcm","clk":"11538944587","pt":1719472174941,"mc":[{"id":"1.230178322","rc":[{"atb":[[2.06,6.54]],"id":63650892}],"con":true,"img":false}]}
{"op":"mcm","clk":"11538944605","pt":1719472175246,"mc":[{"id":"1.230178322","rc":[{"atb":[[2.16,6.54]],"id":47885365}],"con":true,"img":false}]}
{"op":"mcm","clk":"11539122560","pt":1719475682560,"mc":[{"id":"1.230178322","marketDefinition":{"bspMarket":true,"turnInPlayEnabled":false,"persistenceEnabled":false,"marketBaseRate":5.0,"eventId":"33376062","eventTypeId":"4339","numberOfWinners":1,"bettingType":"ODDS","marketType":"WIN","marketTime":"2024-06-27T16:06:00.000Z","suspendTime":"2024-06-27T16:06:00.000Z","bspReconciled":false,"complete":true,"inPlay":false,"crossMatching":true,"runnersVoidable":false,"numberOfActiveRunners":6,"betDelay":0,"status":"OPEN","runners":[{"status":"ACTIVE","sortPriority":1,"id":70681333,"name":"1. Request"},{"status":"ACTIVE","sortPriority":2,"id":51569790,"name":"2. Jaxx Casparon"},{"status":"ACTIVE","sortPriority":3,"id":63650892,"name":"3. Brosna Summer"},{"status":"ACTIVE","sortPriority":4,"id":47885365,"name":"4. Springwell Zoey"},{"status":"ACTIVE","sortPriority":5,"id":68274051,"name":"5. Drumdoit Loret"},{"status":"ACTIVE","sortPriority":6,"id":60192591,"name":"6. Corruptor"}],"regulators":["MR_INT"],"venue":"Kinsley","countryCode":"GB","discountAllowed":true,"timezone":"Europe/London","openDate":"2024-06-27T13:36:00.000Z","version":5994643767,"name":"A7 462m","eventName":"Kinsley 27th Jun"},"rc":[{"atb":[[2.06,12.08],[1.03,7.88],[2.08,6.55]],"id":70681333},{"atl":[[150,4],[990,0.22]],"id":70681333},{"spn":76.04,"spf":"NaN","id":70681333},{"atb":[[1.02,11.82],[2.16,6.55],[2.14,11.65]],"id":47885365},{"atl":[[150,4],[990,0.22]],"id":47885365},{"spn":76.08,"spf":"NaN","id":47885365},{"atb":[[1.01,23.66],[2.06,6.55],[2.04,9.4]],"id":63650892},{"atl":[[150,4],[26,0.6],[990,0.22]],"id":63650892},{"spn":14.03,"spf":"NaN","id":63650892},{"atb":[[1.03,7.88],[2.16,6.55],[2.14,13.45]],"id":68274051},{"atl":[[150,4],[1000,0.22]],"id":68274051},{"spn":76.08,"spf":"NaN","id":68274051},{"atb":[[2.06,6.55],[1.03,7.88],[2.04,12.81]],"id":51569790},{"atl":[[150,4],[990,0.22]],"id":51569790},{"spn":76.03,"spf":"NaN","id":51569790},{"atb":[[1.03,7.88],[6,4],[4.2,15.62],[2.1,13.19]],"id":60192591},{"atl":[[150,4],[990,0.22]],"id":60192591},{"spn":78.0,"spf":"NaN","id":60192591}],"con":true,"img":true}]}
{"op":"mcm","clk":"11539127983","pt":1719475712404,"mc":[{"id":"1.230178322","rc":[{"atb":[[2.06,0],[1.03,7.88],[2.08,6.55]],"id":70681333},{"spn":76.04,"spf":"NaN","id":70681333},{"atb":[[1.02,11.82],[2.16,6.55],[2.14,0]],"id":47885365},{"spn":76.08,"spf":"NaN","id":47885365},{"atb":[[1.01,23.66],[2.06,6.55],[2.04,0]],"id":63650892},{"spn":14.03,"spf":"NaN","id":63650892},{"atb":[[1.03,7.88],[2.16,6.55],[2.14,0]],"id":68274051},{"spn":76.08,"spf":"NaN","id":68274051},{"atb":[[2.06,6.55],[1.03,7.88],[2.04,0]],"id":51569790},{"spn":76.03,"spf":"NaN","id":51569790},{"atb":[[1.03,7.88],[2.1,13.19]],"id":60192591}],"con":true,"img":false}]}
{"op":"mcm","clk":"11539127991","pt":1719475712508,"mc":[{"id":"1.230178322","rc":[{"atb":[[2.1,12.08]],"id":70681333},{"atb":[[2.18,11.65]],"id":47885365},{"atb":[[2.08,9.4]],"id":63650892},{"atb":[[2.18,13.45]],"id":68274051},{"atb":[[2.08,12.81]],"id":51569790}],"con":true,"img":false}]}
{"op":"mcm","clk":"11539132868","pt":1719475790884,"mc":[{"id":"1.230178322","rc":[{"spn":76.05,"spf":"NaN","id":70681333},{"spn":76.09,"spf":"NaN","id":47885365},{"spn":14.04,"spf":"NaN","id":63650892},{"spn":76.09,"spf":"NaN","id":68274051},{"atb":[[2.06,3.16]],"id":51569790},{"spn":76.04,"spf":"NaN","id":51569790}],"con":true,"img":false}]}
{"op":"mcm","clk":"11539132887","pt":1719475791188,"mc":[{"id":"1.230178322","rc":[{"atb":[[2.08,3.16]],"id":70681333}],"con":true,"img":false}]}
{"op":"mcm","clk":"11539132922","pt":1719475791807,"mc":[{"id":"1.230178322","rc":[{"atb":[[2.06,3.16]],"id":63650892}],"con":true,"img":false}]}
{"op":"mcm","clk":"11539132969","pt":1719475792631,"mc":[{"id":"1.230178322","rc":[{"atb":[[2.16,3.16]],"id":47885365}],"con":true,"img":false}]}
{"op":"mcm","clk":"11539132990","pt":1719475792895,"mc":[{"id":"1.230178322","rc":[{"atb":[[2.16,3.16]],"id":68274051}],"con":true,"img":false}]}
{"op":"mcm","clk":"11539133016","pt":1719475793231,"mc":[{"id":"1.230178322","rc":[{"atb":[[2.12,3.38]],"id":70681333}],"con":true,"img":false}]}
{"op":"mcm","clk":"11539133118","pt":1719475794592,"mc":[{"id":"1.230178322","rc":[{"atb":[[2.1,3.38]],"id":63650892}],"con":true,"img":false}]}
{"op":"mcm","clk":"11539133135","pt":1719475794796,"mc":[{"id":"1.230178322","rc":[{"atb":[[2.2,3.38]],"id":68274051}],"con":true,"img":false}]}
{"op":"mcm","clk":"11539133204","pt":1719475795822,"mc":[{"id":"1.230178322","rc":[{"atb":[[2.2,3.38]],"id":47885365}],"con":true,"img":false}]}
{"op":"mcm","clk":"11539133228","pt":1719475796130,"mc":[{"id":"1.230178322","rc":[{"atb":[[2.1,3.38]],"id":51569790}],"con":true,"img":false}]}
{"op":"mcm","clk":"11539134303","pt":1719475810630,"mc":[{"id":"1.230178322","rc":[{"atb":[[2.08,0]],"id":70681333},{"atb":[[2.16,0]],"id":47885365},{"atb":[[2.06,0]],"id":63650892},{"atb":[[2.16,0]],"id":68274051},{"atb":[[2.06,0]],"id":51569790}],"con":true,"img":false}]}
{"op":"mcm","clk":"11539153259","pt":1719476116616,"mc":[{"id":"1.230178322","rc":[{"atb":[[2.12,6.55]],"id":70681333},{"spn":76.06,"spf":"NaN","id":70681333},{"spn":76.1,"spf":"NaN","id":47885365},{"spn":14.05,"spf":"NaN","id":63650892},{"spn":76.1,"spf":"NaN","id":68274051},{"spn":76.05,"spf":"NaN","id":51569790}],"con":true,"img":false}]}
{"op":"mcm","clk":"11539153273","pt":1719476116822,"mc":[{"id":"1.230178322","rc":[{"atb":[[2.1,6.55]],"id":63650892},{"atb":[[2.1,6.55]],"id":51569790}],"con":true,"img":false}]}
{"op":"mcm","clk":"11539153287","pt":1719476116977,"mc":[{"id":"1.230178322","rc":[{"atb":[[2.2,6.55]],"id":68274051}],"con":true,"img":false}]}
{"op":"mcm","clk":"11539153295","pt":1719476117082,"mc":[{"id":"1.230178322","rc":[{"atb":[[2.2,6.55]],"id":47885365}],"con":true,"img":false}]}
{"op":"mcm","clk":"11539341459","pt":1719479311125,"mc":[{"id":"1.230178322","rc":[{"atb":[[1.03,7.88],[2.12,6.54],[2.1,0]],"id":70681333},{"atb":[[1.02,11.82],[2.18,0],[2.2,6.54]],"id":47885365},{"atb":[[1.01,23.66],[2.1,6.54],[2.08,0]],"id":63650892},{"atb":[[1.03,7.88],[2.18,0],[2.2,6.54]],"id":68274051},{"atb":[[1.03,7.88],[2.1,6.54],[2.08,0]],"id":51569790},{"atb":[[1.03,7.88],[2.1,13.19]],"id":60192591}],"con":true,"img":false}]}
{"op":"mcm","clk":"11539341466","pt":1719479311226,"mc":[{"id":"1.230178322","rc":[{"atb":[[2.14,12.08]],"id":70681333},{"atb":[[2.22,11.65]],"id":47885365},{"atb":[[2.12,9.39]],"id":63650892},{"atb":[[2.22,13.45]],"id":68274051},{"atb":[[2.12,12.81]],"id":51569790}],"con":true,"img":false}]}
{"op":"mcm","clk":"11539346613","pt":1719479393767,"mc":[{"id":"1.230178322","rc":[{"spn":76.07,"spf":"NaN","id":70681333},{"spn":76.11,"spf":"NaN","id":47885365},{"spn":14.06,"spf":"NaN","id":63650892},{"spn":76.11,"spf":"NaN","id":68274051},{"atb":[[2.1,3.38]],"id":51569790},{"spn":76.06,"spf":"NaN","id":51569790}],"con":true,"img":false}]}
{"op":"mcm","clk":"11539346629","pt":1719479394073,"mc":[{"id":"1.230178322","rc":[{"atb":[[2.2,3.38]],"id":47885365}],"con":true,"img":false}]}
{"op":"mcm","clk":"11539346634","pt":1719479394176,"mc":[{"id":"1.230178322","rc":[{"atb":[[2.1,3.38]],"id":63650892}],"con":true,"img":false}]}
{"op":"mcm","clk":"11539346663","pt":1719479394844,"mc":[{"id":"1.230178322","rc":[{"atb":[[2.12,3.38]],"id":70681333}],"con":true,"img":false}]}
{"op":"mcm","clk":"11539346733","pt":1719479396179,"mc":[{"id":"1.230178322","rc":[{"atb":[[2.2,3.38]],"id":68274051}],"con":true,"img":false}]}
{"op":"mcm","clk":"11539348821","pt":1719479428133,"mc":[{"id":"1.230178322","rc":[{"atb":[[2.12,0]],"id":70681333},{"atb":[[2.2,0]],"id":47885365}],"con":true,"img":false}]}
{"op":"mcm","clk":"11539348880","pt":1719479428906,"mc":[{"id":"1.230178322","rc":[{"atb":[[2.1,0]],"id":51569790}],"con":true,"img":false}]}
{"op":"mcm","clk":"11539348898","pt":1719479429215,"mc":[{"id":"1.230178322","rc":[{"atb":[[2.2,0]],"id":68274051}],"con":true,"img":false}]}
{"op":"mcm","clk":"11539348943","pt":1719479429990,"mc":[{"id":"1.230178322","rc":[{"atb":[[2.1,0]],"id":63650892}],"con":true,"img":false}]}
{"op":"mcm","clk":"11539348972","pt":1719479430508,"mc":[{"id":"1.230178322","rc":[{"atb":[[2.16,3.38]],"id":70681333}],"con":true,"img":false}]}
{"op":"mcm","clk":"11539349056","pt":1719479431914,"mc":[{"id":"1.230178322","rc":[{"atb":[[2.24,3.38]],"id":68274051}],"con":true,"img":false}]}
{"op":"mcm","clk":"11539349071","pt":1719479432212,"mc":[{"id":"1.230178322","rc":[{"atb":[[2.24,3.38]],"id":47885365},{"atb":[[2.14,3.38]],"id":63650892}],"con":true,"img":false}]}
{"op":"mcm","clk":"11539349087","pt":1719479432522,"mc":[{"id":"1.230178322","rc":[{"atb":[[2.14,3.38]],"id":51569790}],"con":true,"img":false}]}
{"op":"mcm","clk":"11539367540","pt":1719479705294,"mc":[{"id":"1.230178322","rc":[{"atb":[[2.16,6.54]],"id":70681333},{"spn":76.08,"spf":"NaN","id":70681333},{"spn":76.12,"spf":"NaN","id":47885365},{"spn":14.07,"spf":"NaN","id":63650892},{"spn":76.12,"spf":"NaN","id":68274051},{"spn":76.07,"spf":"NaN","id":51569790}],"con":true,"img":false}]}
{"op":"mcm","clk":"11539367599","pt":1719479706021,"mc":[{"id":"1.230178322","rc":[{"atb":[[2.24,6.54]],"id":47885365}],"con":true,"img":false}]}
{"op":"mcm","clk":"11539367629","pt":1719479706304,"mc":[{"id":"1.230178322","rc":[{"atb":[[2.24,6.54]],"id":68274051}],"con":true,"img":false}]}
{"op":"mcm","clk":"11539367772","pt":1719479708192,"mc":[{"id":"1.230178322","rc":[{"atb":[[2.14,6.54]],"id":63650892}],"con":true,"img":false}]}
{"op":"mcm","clk":"11539367839","pt":1719479709065,"mc":[{"id":"1.230178322","rc":[{"atb":[[2.14,6.54]],"id":51569790}],"con":true,"img":false}]}
{"op":"mcm","clk":"11539545499","pt":1719482911307,"mc":[{"id":"1.230178322","rc":[{"atb":[[1.03,7.88],[2.16,6.54],[2.14,0]],"id":70681333},{"atb":[[2.24,6.54],[2.22,0],[1.02,11.82]],"id":47885365},{"atb":[[1.01,23.65],[2.12,0],[2.14,6.54]],"id":63650892},{"atb":[[2.24,6.54],[1.03,7.88],[2.22,0]],"id":68274051},{"atb":[[1.03,7.88],[2.12,0],[2.14,6.54]],"id":51569790},{"atb":[[1.03,7.88],[2.1,13.19]],"id":60192591}],"con":true,"img":false}]}
{"op":"mcm","clk":"11539545503","pt":1719482911360,"mc":[{"id":"1.230178322","rc":[{"atb":[[2.18,12.07]],"id":70681333},{"atb":[[2.26,11.65]],"id":47885365},{"atb":[[2.16,9.39]],"id":63650892},{"atb":[[2.26,13.44]],"id":68274051},{"atb":[[2.16,12.81]],"id":51569790}],"con":true,"img":false}]}
{"op":"mcm","clk":"11539548005","pt":1719482948826,"mc":[{"id":"1.230178322","rc":[{"atb":[[2.16,3.16]],"id":70681333},{"atb":[[2.24,3.16]],"id":47885365}],"con":true,"img":false}]}
{"op":"mcm","clk":"11539548035","pt":1719482949191,"mc":[{"id":"1.230178322","rc":[{"atb":[[2.14,3.16]],"id":63650892}],"con":true,"img":false}]}
{"op":"mcm","clk":"11539548041","pt":1719482949399,"mc":[{"id":"1.230178322","rc":[{"atb":[[2.14,3.16]],"id":51569790}],"con":true,"img":false}]}
{"op":"mcm","clk":"11539548087","pt":1719482950105,"mc":[{"id":"1.230178322","rc":[{"atb":[[2.24,3.16]],"id":68274051}],"con":true,"img":false}]}
{"op":"mcm","clk":"11539548154","pt":1719482951712,"mc":[{"id":"1.230178322","rc":[{"atb":[[2.2,3.38]],"id":70681333}],"con":true,"img":false}]}
{"op":"mcm","clk":"11539548189","pt":1719482952241,"mc":[{"id":"1.230178322","rc":[{"atb":[[2.18,3.38]],"id":63650892}],"con":true,"img":false}]}
{"op":"mcm","clk":"11539548193","pt":1719482952339,"mc":[{"id":"1.230178322","rc":[{"atb":[[2.28,3.38]],"id":47885365}],"con":true,"img":false}]}
{"op":"mcm","clk":"11539548214","pt":1719482952602,"mc":[{"id":"1.230178322","rc":[{"atb":[[2.18,3.38]],"id":51569790}],"con":true,"img":false}]}
{"op":"mcm","clk":"11539548257","pt":1719482953225,"mc":[{"id":"1.230178322","rc":[{"atb":[[2.28,3.38]],"id":68274051}],"con":true,"img":false}]}
{"op":"mcm","clk":"11539553303","pt":1719483027902,"mc":[{"id":"1.230178322","rc":[{"atb":[[2.16,0]],"id":70681333},{"spn":76.1,"spf":"NaN","id":70681333},{"atb":[[2.24,0]],"id":47885365},{"spn":76.14,"spf":"NaN","id":47885365},{"atb":[[2.14,0]],"id":63650892},{"spn":14.09,"spf":"NaN","id":63650892},{"atb":[[2.24,0]],"id":68274051},{"spn":76.14,"spf":"NaN","id":68274051},{"atb":[[2.14,0]],"id":51569790},{"spn":76.09,"spf":"NaN","id":51569790}],"con":true,"img":false}]}
{"op":"mcm","clk":"11539572883","pt":1719483321670,"mc":[{"id":"1.230178322","rc":[{"atb":[[2.2,6.54]],"id":70681333}],"con":true,"img":false}]}
{"op":"mcm","clk":"11539572889","pt":1719483321726,"mc":[{"id":"1.230178322","rc":[{"atb":[[2.28,6.54]],"id":68274051}],"con":true,"img":false}]}
{"op":"mcm","clk":"11539572934","pt":1719483322449,"mc":[{"id":"1.230178322","rc":[{"atb":[[2.18,6.54]],"id":51569790}],"con":true,"img":false}]}
{"op":"mcm","clk":"11539573131","pt":1719483324549,"mc":[{"id":"1.230178322","rc":[{"atb":[[2.18,6.54]],"id":63650892}],"con":true,"img":false}]}
{"op":"mcm","clk":"11539573149","pt":1719483324766,"mc":[{"id":"1.230178322","rc":[{"atb":[[2.28,6.54]],"id":47885365}],"con":true,"img":false}]}
{"op":"mcm","clk":"11539780427","pt":1719486096605,"mc":[{"id":"1.230178322","rc":[{"atb":[[1.03,7.88],[3.1,6],[2.18,12.08],[2.2,6.54]],"id":70681333},{"spn":76.55,"spf":"NaN","id":70681333},{"atb":[[4.1,6],[1.02,11.82],[2.28,6.54],[2.26,11.65]],"id":47885365},{"spn":77.05,"spf":"NaN","id":47885365},{"atb":[[1.01,23.66],[2.86,6],[2.18,6.54],[2.16,9.39]],"id":63650892},{"spn":14.43,"spf":"NaN","id":63650892},{"atb":[[1.03,7.88],[2.28,6.54],[2.44,6],[2.26,13.45]],"id":68274051},{"spn":76.22,"spf":"NaN","id":68274051},{"atb":[[1.03,7.88],[3,6],[2.18,6.54],[2.16,12.81]],"id":51569790},{"spn":76.5,"spf":"NaN","id":51569790},{"atb":[[1.03,7.88],[4.1,6],[2.1,13.19]],"id":60192591}],"con":true,"img":false}]}
{"op":"mcm","clk":"11539781829","pt":1719486119349,"mc":[{"id":"1.230178322","rc":[{"atb":[[2.18,3.16]],"id":63650892}],"con":true,"img":false}]}
{"op":"mcm","clk":"11539781850","pt":1719486119622,"mc":[{"id":"1.230178322","rc":[{"atb":[[2.2,3.16]],"id":70681333},{"atb":[[2.28,3.16]],"id":47885365},{"atb":[[2.18,3.16]],"id":51569790}],"con":true,"img":false}]}
{"op":"mcm","clk":"11539781868","pt":1719486119936,"mc":[{"id":"1.230178322","rc":[{"atb":[[2.88,3.38]],"id":63650892}],"con":true,"img":false}]}
{"op":"mcm","clk":"11539782082","pt":1719486123553,"mc":[{"id":"1.230178322","rc":[{"atb":[[2.2,0]],"id":70681333},{"atb":[[2.28,0]],"id":47885365},{"atb":[[2.18,0]],"id":63650892},{"atb":[[2.18,0]],"id":51569790}],"con":true,"img":false}]}
{"op":"mcm","clk":"11539782092","pt":1719486123756,"mc":[{"id":"1.230178322","rc":[{"atb":[[2.88,6.54]],"id":63650892}],"con":true,"img":false}]}
{"op":"mcm","clk":"11539799270","pt":1719486360764,"mc":[{"id":"1.230178322","rc":[{"atl":[[32,8],[55,12]],"id":70681333},{"spn":17.55,"spf":"NaN","id":70681333},{"atl":[[40,12],[23,8]],"id":63650892},{"spn":12.94,"spf":"NaN","id":63650892},{"atl":[[36,12],[21,8]],"id":68274051},{"spn":11.72,"spf":"NaN","id":68274051},{"atl":[[36,8],[60,12]],"id":51569790},{"spn":19.5,"spf":"NaN","id":51569790}],"con":true,"img":false}]}
{"op":"mcm","clk":"11539817311","pt":1719486506045,"mc":[{"id":"1.230178322","rc":[{"atb":[[2.26,0]],"id":68274051}],"con":true,"img":false}]}
{"op":"mcm","clk":"11539817320","pt":1719486506190,"mc":[{"id":"1.230178322","rc":[{"atb":[[2.3,13.45]],"id":68274051}],"con":true,"img":false}]}
{"op":"mcm","clk":"11539818588","pt":1719486519959,"mc":[{"id":"1.230178322","rc":[{"atb":[[2.28,3.38]],"id":68274051}],"con":true,"img":false}]}
{"op":"mcm","clk":"11539818687","pt":1719486521063,"mc":[{"id":"1.230178322","rc":[{"atb":[[2.32,3.16]],"id":68274051}],"con":true,"img":false}]}
{"op":"mcm","clk":"11539824718","pt":1719486590902,"mc":[{"id":"1.230178322","rc":[{"atb":[[2.28,0]],"id":68274051}],"con":true,"img":false}]}
{"op":"mcm","clk":"11539825701","pt":1719486604010,"mc":[{"id":"1.230178322","rc":[{"atb":[[2.32,6.54]],"id":68274051}],"con":true,"img":false}]}
{"op":"mcm","clk":"11539840578","pt":1719486805827,"mc":[{"id":"1.230178322","rc":[{"atb":[[2.3,0]],"id":68274051}],"con":true,"img":false}]}
{"op":"mcm","clk":"11539840586","pt":1719486805924,"mc":[{"id":"1.230178322","rc":[{"atb":[[2.34,13.45]],"id":68274051}],"con":true,"img":false}]}
{"op":"mcm","clk":"11539841469","pt":1719486820370,"mc":[{"id":"1.230178322","rc":[{"atb":[[2.32,3.38]],"id":68274051}],"con":true,"img":false}]}
{"op":"mcm","clk":"11539842995","pt":1719486843486,"mc":[{"id":"1.230178322","rc":[{"atb":[[2.32,0]],"id":68274051}],"con":true,"img":false}]}
{"op":"mcm","clk":"11539848712","pt":1719486924046,"mc":[{"id":"1.230178322","rc":[{"atb":[[2.36,3.38]],"id":68274051}],"con":true,"img":false}]}
{"op":"mcm","clk":"11539850302","pt":1719486944779,"mc":[{"id":"1.230178322","rc":[{"atb":[[2.36,6.54]],"id":68274051}],"con":true,"img":false}]}
{"op":"mcm","clk":"11540014493","pt":1719489000435,"mc":[{"id":"1.230178322","rc":[{"atl":[[370,2]],"id":70681333},{"atl":[[270,2]],"id":47885365},{"atl":[[550,2]],"id":63650892},{"atl":[[560,2]],"id":68274051},{"atl":[[390,2]],"id":51569790},{"atl":[[500,2]],"id":60192591}],"con":true,"img":false}]}
{"op":"mcm","clk":"11540014503","pt":1719489000541,"mc":[{"id":"1.230178322","rc":[{"atb":[[1.16,150]],"id":70681333},{"atb":[[1.16,150]],"id":47885365},{"atb":[[1.16,150]],"id":63650892},{"atb":[[1.16,150]],"id":51569790},{"atb":[[1.16,150]],"id":60192591}],"con":true,"img":false}]}
{"op":"mcm","clk":"11540014513","pt":1719489000669,"mc":[{"id":"1.230178322","rc":[{"atb":[[1.16,150]],"id":68274051}],"con":true,"img":false}]}
{"op":"mcm","clk":"11540094233","pt":1719489963820,"mc":[{"id":"1.230178322","rc":[{"atb":[[5,1]],"id":70681333},{"spn":18.5,"spf":"NaN","id":70681333},{"atb":[[5,1]],"id":47885365},{"spn":77.5,"spf":"NaN","id":47885365},{"atb":[[2.88,6.54],[4.7,1]],"id":63650892},{"spn":13.85,"spf":"NaN","id":63650892},{"atb":[[2.36,6.54],[3.35,1]],"id":68274051},{"spn":12.17,"spf":"NaN","id":68274051},{"atb":[[4.7,1]],"id":51569790},{"spn":20.35,"spf":"NaN","id":51569790},{"atb":[[5,1]],"id":60192591}],"con":true,"img":false}]}
{"op":"mcm","clk":"11540094420","pt":1719489965937,"mc":[{"id":"1.230178322","rc":[{"atb":[[1.51,196.08]],"id":47885365},{"atb":[[1.51,196.08]],"id":60192591}],"con":true,"img":false}]}
{"op":"mcm","clk":"11540094428","pt":1719489966039,"mc":[{"id":"1.230178322","rc":[{"atb":[[1.51,196.08]],"id":70681333},{"atb":[[2.12,89.29]],"id":60192591}],"con":true,"img":false}]}
{"op":"mcm","clk":"11540136400","pt":1719490401107,"mc":[{"id":"1.230178322","rc":[{"atb":[[2.1,0]],"id":60192591}],"con":true,"img":false}]}
{"op":"mcm","clk":"11540136410","pt":1719490401212,"mc":[{"id":"1.230178322","rc":[{"atb":[[2.14,13.19]],"id":60192591}],"con":true,"img":false}]}
{"op":"mcm","clk":"11540180575","pt":1719490917033,"mc":[{"id":"1.230178322","rc":[{"atb":[[2.12,89.29]],"id":47885365},{"atb":[[1.51,196.08]],"id":63650892},{"atb":[[1.51,196.08]],"id":68274051},{"atb":[[1.51,196.08]],"id":51569790}],"con":true,"img":false}]}
{"op":"mcm","clk":"11540606986","pt":1719496383669,"mc":[{"id":"1.230178322","rc":[{"atb":[[5,2],[1.03,7.89],[2.18,12.09]],"id":70681333},{"atl":[[990,0.22]],"id":70681333},{"atb":[[1.02,11.84],[7.4,1],[2.26,11.67]],"id":47885365},{"atl":[[990,0.22]],"id":47885365},{"spn":78.7,"spf":"NaN","id":47885365},{"atb":[[2.88,6.54],[1.01,23.68],[2.16,9.4],[4.2,1]],"id":63650892},{"atl":[[990,0.22]],"id":63650892},{"atb":[[2.36,6.54],[1.03,7.89],[3.4,1],[2.34,13.46]],"id":68274051},{"atl":[[1000,0.22]],"id":68274051},{"spn":12.2,"spf":"NaN","id":68274051},{"atb":[[1.03,7.89],[3.3,1],[2.16,12.83]],"id":51569790},{"atl":[[990,0.22]],"id":51569790},{"atb":[[1.03,7.89],[7,1],[2.14,13.21]],"id":60192591},{"atl":[[990,0.22]],"id":60192591},{"spn":78.5,"spf":"NaN","id":60192591}],"con":true,"img":false}]}
{"op":"mcm","clk":"11540608583","pt":1719496400343,"mc":[{"id":"1.230178322","rc":[{"atb":[[2.12,89.29]],"id":63650892},{"atb":[[2.12,89.29]],"id":51569790}],"con":true,"img":false}]}
{"op":"mcm","clk":"11540683370","pt":1719497282518,"mc":[{"id":"1.230178322","marketDefinition":{"bspMarket":true,"turnInPlayEnabled":false,"persistenceEnabled":false,"marketBaseRate":5.0,"eventId":"33376062","eventTypeId":"4339","numberOfWinners":1,"bettingType":"ODDS","marketType":"WIN","marketTime":"2024-06-27T16:06:00.000Z","suspendTime":"2024-06-27T16:06:00.000Z","bspReconciled":false,"complete":true,"inPlay":false,"crossMatching":true,"runnersVoidable":false,"numberOfActiveRunners":6,"betDelay":0,"status":"OPEN","runners":[{"status":"ACTIVE","sortPriority":1,"id":70681333,"name":"1. Request"},{"status":"ACTIVE","sortPriority":2,"id":51569790,"name":"2. Jaxx Casparon"},{"status":"ACTIVE","sortPriority":3,"id":63650892,"name":"3. Brosna Summer"},{"status":"ACTIVE","sortPriority":4,"id":47885365,"name":"4. Springwell Zoey"},{"status":"ACTIVE","sortPriority":5,"id":68274051,"name":"5. Drumdoit Loret"},{"status":"ACTIVE","sortPriority":6,"id":60192591,"name":"6. Corruptor"}],"regulators":["MR_INT"],"venue":"Kinsley","countryCode":"GB","discountAllowed":true,"timezone":"Europe/London","openDate":"2024-06-27T13:36:00.000Z","version":5994643767,"name":"A7 462m","eventName":"Kinsley 27th Jun"},"rc":[{"atb":[[5,2],[1.16,150],[1.03,7.89],[3.1,6],[2.18,12.08],[1.51,196.08]],"id":70681333},{"atl":[[32,8],[150,4],[370,2],[55,12],[990,0.22]],"id":70681333},{"spn":18.5,"spf":"NaN","id":70681333},{"atb":[[5,1],[1.16,150],[4.1,6],[7.4,1],[1.02,11.83],[2.12,89.29],[2.26,11.66],[1.51,196.08]],"id":47885365},{"atl":[[270,2],[150,4],[990,0.22]],"id":47885365},{"spn":78.7,"spf":"NaN","id":47885365},{"atb":[[2.88,6.54],[1.01,23.67],[2.86,6],[1.16,150],[2.12,89.29],[1.51,196.08],[4.2,1],[2.16,9.4],[4.7,1]],"id":63650892},{"atl":[[550,2],[150,4],[40,12],[23,8],[26,0.6],[990,0.22]],"id":63650892},{"spn":13.85,"spf":"NaN","id":63650892},{"atb":[[2.36,6.54],[1.16,150],[1.03,7.89],[3.35,1],[3.4,1],[2.44,6],[1.51,196.08],[2.34,13.46]],"id":68274051},{"atl":[[560,2],[36,12],[150,4],[21,8],[1000,0.22]],"id":68274051},{"spn":12.2,"spf":"NaN","id":68274051},{"atb":[[1.16,150],[1.03,7.89],[3,6],[2.12,89.29],[1.51,196.08],[3.3,1],[2.16,12.82],[4.7,1]],"id":51569790},{"atl":[[36,8],[150,4],[390,2],[60,12],[990,0.22]],"id":51569790},{"spn":20.35,"spf":"NaN","id":51569790},{"atb":[[5,1],[1.16,150],[1.03,7.89],[4.1,6],[6,4],[2.12,89.29],[1.51,196.08],[7,1],[4.2,15.62],[2.14,13.2]],"id":60192591},{"atl":[[150,4],[990,0.22],[500,2]],"id":60192591},{"spn":78.5,"spf":"NaN","id":60192591}],"con":true,"img":true}]}
{"op":"mcm","clk":"11540693856","pt":1719497354149,"mc":[{"id":"1.230178322","rc":[{"atb":[[1.03,7.89],[2.18,12.08]],"id":70681333},{"atb":[[2.02,30.3],[1.02,11.83],[2.26,11.66]],"id":47885365},{"atb":[[2.88,6.54],[1.01,23.67],[2.16,9.4]],"id":63650892},{"atb":[[2.36,6.54],[1.03,7.89],[2.34,13.46]],"id":68274051},{"atb":[[1.03,7.89],[2.16,12.82]],"id":51569790},{"atb":[[1.03,7.89],[2.14,13.2]],"id":60192591}],"con":true,"img":false}]}
{"op":"mcm","clk":"11540731445","pt":1719497775050,"mc":[{"id":"1.230178322","rc":[{"spl":[[1.01,1]],"id":68274051},{"spn":3.4,"spf":1.0,"id":68274051}],"con":true,"img":false}]}
{"op":"mcm","clk":"11540815301","pt":1719498676685,"mc":[{"id":"1.230178322","rc":[{"atb":[[5,1]],"id":70681333},{"atb":[[7.4,0]],"id":47885365},{"spn":77.5,"spf":"NaN","id":47885365},{"atb":[[4.2,0]],"id":63650892},{"atb":[[3.4,0]],"id":68274051},{"spn":3.35,"spf":1.0,"id":68274051},{"atb":[[3.3,0]],"id":51569790},{"atb":[[7,0]],"id":60192591},{"spn":78.0,"spf":"NaN","id":60192591}],"con":true,"img":false}]}
{"op":"mcm","clk":"11540839634","pt":1719498963092,"mc":[{"id":"1.230178322","rc":[{"atb":[[3.7,1]],"id":70681333}],"con":true,"img":false}]}
{"op":"mcm","clk":"11540840411","pt":1719498971211,"mc":[{"id":"1.230178322","rc":[{"atb":[[2.12,89.29]],"id":70681333}],"con":true,"img":false}]}
{"op":"mcm","clk":"11540840864","pt":1719498976640,"mc":[{"id":"1.230178322","rc":[{"atb":[[3.7,1]],"id":51569790}],"con":true,"img":false}]}
{"op":"mcm","clk":"11540841531","pt":1719498984209,"mc":[{"id":"1.230178322","rc":[{"atb":[[3.7,1]],"id":63650892}],"con":true,"img":false}]}
{"op":"mcm","clk":"11540842321","pt":1719498993124,"mc":[{"id":"1.230178322","rc":[{"atb":[[3.7,1]],"id":47885365}],"con":true,"img":false}]}
{"op":"mcm","clk":"11540953403","pt":1719500397112,"mc":[{"id":"1.230178322","rc":[{"atb":[[4,2.5]],"id":70681333},{"atb":[[5,3]],"id":47885365},{"atb":[[3.5,2.85]],"id":63650892},{"atb":[[2.6,3.84]],"id":68274051},{"atb":[[3.5,2.85]],"id":51569790},{"atb":[[5,3]],"id":60192591}],"con":true,"img":false}]}
{"op":"mcm","clk":"11541090135","pt":1719502056395,"mc":[{"id":"1.230178322","rc":[{"atb":[[1.03,7.89],[2.18,12.09]],"id":70681333},{"atb":[[1.02,11.83],[2.26,11.66]],"id":47885365},{"atb":[[2.88,6.54],[1.01,23.68],[2.16,9.4]],"id":63650892},{"atb":[[2.36,6.54],[1.03,7.89],[2.34,13.46]],"id":68274051},{"atl":[[20,1.71]],"id":68274051},{"atb":[[1.03,7.89],[2.16,12.82]],"id":51569790},{"atb":[[1.03,7.89],[2.14,13.2]],"id":60192591}],"con":true,"img":false}]}
{"op":"mcm","clk":"11541090153","pt":1719502056704,"mc":[{"id":"1.230178322","rc":[{"atl":[[34,1.63]],"id":51569790}],"con":true,"img":false}]}
{"op":"mcm","clk":"11541139081","pt":1719502682531,"mc":[{"id":"1.230178322","marketDefinition":{"bspMarket":true,"turnInPlayEnabled":false,"persistenceEnabled":false,"marketBaseRate":5.0,"eventId":"33376062","eventTypeId":"4339","numberOfWinners":1,"bettingType":"ODDS","marketType":"WIN","marketTime":"2024-06-27T16:06:00.000Z","suspendTime":"2024-06-27T16:06:00.000Z","bspReconciled":false,"complete":true,"inPlay":false,"crossMatching":true,"runnersVoidable":false,"numberOfActiveRunners":6,"betDelay":0,"status":"OPEN","runners":[{"status":"ACTIVE","sortPriority":1,"id":70681333,"name":"1. Request"},{"status":"ACTIVE","sortPriority":2,"id":51569790,"name":"2. Jaxx Casparon"},{"status":"ACTIVE","sortPriority":3,"id":63650892,"name":"3. Brosna Summer"},{"status":"ACTIVE","sortPriority":4,"id":47885365,"name":"4. Springwell Zoey"},{"status":"ACTIVE","sortPriority":5,"id":68274051,"name":"5. Drumdoit Loret"},{"status":"ACTIVE","sortPriority":6,"id":60192591,"name":"6. Corruptor"}],"regulators":["MR_INT"],"venue":"Kinsley","countryCode":"GB","discountAllowed":true,"timezone":"Europe/London","openDate":"2024-06-27T13:36:00.000Z","version":5994643767,"name":"A7 462m","eventName":"Kinsley 27th Jun"},"rc":[{"atb":[[4,2.5],[5,1],[1.16,150],[1.03,7.89],[3.1,6],[3.7,1],[2.12,89.29],[2.18,12.09],[1.51,196.08]],"id":70681333},{"atl":[[32,8],[150,4],[370,2],[55,12],[990,0.22]],"id":70681333},{"spn":18.5,"spf":"NaN","id":70681333},{"atb":[[2.02,30.3],[5,3],[1.16,150],[4.1,6],[3.7,1],[1.02,11.83],[2.12,89.29],[2.26,11.66],[1.51,196.08]],"id":47885365},{"atl":[[270,2],[150,4],[990,0.22]],"id":47885365},{"spn":77.5,"spf":"NaN","id":47885365},{"atb":[[2.88,6.54],[1.01,23.68],[2.86,6],[1.16,150],[3.7,1],[2.12,89.29],[1.51,196.08],[3.5,2.85],[2.16,9.4],[4.7,1]],"id":63650892},{"atl":[[550,2],[150,4],[40,12],[23,8],[26,0.6],[990,0.22]],"id":63650892},{"spn":13.85,"spf":"NaN","id":63650892},{"spl":[[1.01,1]],"id":68274051},{"atb":[[2.36,6.54],[1.16,150],[1.03,7.89],[3.35,1],[2.6,3.84],[2.44,6],[1.51,196.08],[2.34,13.46]],"id":68274051},{"atl":[[560,2],[36,12],[150,4],[20,1.71],[21,8],[1000,0.22]],"id":68274051},{"spn":3.35,"spf":1.0,"id":68274051},{"atb":[[1.16,150],[1.03,7.89],[3.7,1],[3,6],[2.12,89.29],[1.51,196.08],[3.5,2.85],[2.16,12.82],[4.7,1]],"id":51569790},{"atl":[[34,1.63],[36,8],[150,4],[390,2],[60,12],[990,0.22]],"id":51569790},{"spn":19.35,"spf":"NaN","id":51569790},{"atb":[[5,3],[1.16,150],[1.03,7.89],[4.1,6],[6,4],[2.12,89.29],[1.51,196.08],[4.2,15.62],[2.14,13.2]],"id":60192591},{"atl":[[150,4],[990,0.22],[500,2]],"id":60192591},{"spn":78.0,"spf":"NaN","id":60192591}],"con":true,"img":true}]}
{"op":"mcm","clk":"11541160366","pt":1719502871256,"mc":[{"id":"1.230178322","rc":[{"atl":[[190,4]],"id":70681333},{"atl":[[190,4]],"id":47885365},{"atl":[[190,4]],"id":63650892},{"atl":[[190,4]],"id":68274051},{"atl":[[190,4]],"id":51569790},{"spn":19.35,"spf":"NaN","id":51569790},{"atl":[[190,4]],"id":60192591}],"con":true,"img":false}]}
{"op":"mcm","clk":"11541162473","pt":1719502897002,"mc":[{"id":"1.230178322","rc":[{"atb":[[1.02,2]],"id":70681333}],"con":true,"img":false}]}
{"op":"mcm","clk":"11541162489","pt":1719502897313,"mc":[{"id":"1.230178322","rc":[{"atb":[[1.02,2]],"id":51569790}],"con":true,"img":false}]}
{"op":"mcm","clk":"11541162517","pt":1719502897586,"mc":[{"id":"1.230178322","rc":[{"atb":[[1.02,2]],"id":63650892}],"con":true,"img":false}]}
{"op":"mcm","clk":"11541162536","pt":1719502897887,"mc":[{"id":"1.230178322","rc":[{"atb":[[1.02,13.83]],"id":47885365}],"con":true,"img":false}]}
{"op":"mcm","clk":"11541162553","pt":1719502898197,"mc":[{"id":"1.230178322","rc":[{"atb":[[1.02,2]],"id":68274051}],"con":true,"img":false}]}
{"op":"mcm","clk":"11541162577","pt":1719502898601,"mc":[{"id":"1.230178322","rc":[{"atb":[[6.2,2]],"id":60192591}],"con":true,"img":false}]}
{"op":"mcm","clk":"11541188450","pt":1719503173501,"mc":[{"id":"1.230178322","rc":[{"atb":[[4.7,0]],"id":51569790},{"trd":[[4.7,2]],"ltp":4.7,"tv":2.0,"id":51569790},{"spn":18.85,"spf":"NaN","id":51569790},{"spn":78.1,"spf":"NaN","id":60192591}],"con":true,"img":false}]}
{"op":"mcm","clk":"11541188499","pt":1719503173915,"mc":[{"id":"1.230178322","rc":[{"atl":[[1000,0.03]],"id":51569790}],"con":true,"img":false}]}
{"op":"mcm","clk":"11541188522","pt":1719503174073,"mc":[{"id":"1.230178322","rc":[{"atl":[[1000,0]],"id":51569790}],"con":true,"img":false}]}
{"op":"mcm","clk":"11541188537","pt":1719503174176,"mc":[{"id":"1.230178322","rc":[{"atl":[[32,0.03]],"id":51569790}],"con":true,"img":false}]}
{"op":"mcm","clk":"11541188693","pt":1719503175581,"mc":[{"id":"1.230178322","rc":[{"atb":[[4.2,1]],"id":51569790}],"con":true,"img":false}]}
{"op":"mcm","clk":"11541189684","pt":1719503184224,"mc":[{"id":"1.230178322","rc":[{"atb":[[4.2,0]],"id":51569790},{"trd":[[4.2,2]],"ltp":4.2,"tv":2.0,"id":51569790}],"con":true,"img":false}]}
{"op":"mcm","clk":"11541189851","pt":1719503185624,"mc":[{"id":"1.230178322","rc":[{"atb":[[3.85,1]],"id":51569790}],"con":true,"img":false}]}
{"op":"mcm","clk":"11541190314","pt":1719503189406,"mc":[{"id":"1.230178322","rc":[{"atl":[[32,0]],"id":51569790}],"con":true,"img":false}]}
{"op":"mcm","clk":"11541190367","pt":1719503189824,"mc":[{"id":"1.230178322","rc":[{"atl":[[1000,0.03]],"id":51569790}],"con":true,"img":false}]}
{"op":"mcm","clk":"11541190394","pt":1719503190030,"mc":[{"id":"1.230178322","rc":[{"atl":[[1000,0]],"id":51569790}],"con":true,"img":false}]}
{"op":"mcm","clk":"11541190405","pt":1719503190134,"mc":[{"id":"1.230178322","rc":[{"atl":[[32,0.03]],"id":51569790}],"con":true,"img":false}]}
{"op":"mcm","clk":"11541191002","pt":1719503195322,"mc":[{"id":"1.230178322","rc":[{"atb":[[3.85,0]],"id":51569790},{"trd":[[3.85,2]],"ltp":3.85,"tv":2.0,"id":51569790}],"con":true,"img":false}]}
{"op":"mcm","clk":"11541191040","pt":1719503195631,"mc":[{"id":"1.230178322","rc":[{"atb":[[3.6,1]],"id":51569790}],"con":true,"img":false}]}
{"op":"mcm","clk":"11541192219","pt":1719503205230,"mc":[{"id":"1.230178322","rc":[{"atl":[[32,0]],"id":51569790}],"con":true,"img":false}]}
{"op":"mcm","clk":"11541192246","pt":1719503205436,"mc":[{"id":"1.230178322","rc":[{"atl":[[1000,0.03]],"id":51569790}],"con":true,"img":false}]}
{"op":"mcm","clk":"11541192271","pt":1719503205642,"mc":[{"id":"1.230178322","rc":[{"atl":[[1000,0]],"id":51569790}],"con":true,"img":false}]}
{"op":"mcm","clk":"11541192281","pt":1719503205745,"mc":[{"id":"1.230178322","rc":[{"atl":[[32,0.03]],"id":51569790}],"con":true,"img":false}]}
{"op":"mcm","clk":"11541192393","pt":1719503206622,"mc":[{"id":"1.230178322","rc":[{"atb":[[3.7,0]],"id":51569790},{"trd":[[3.7,2]],"ltp":3.7,"tv":2.0,"id":51569790}],"con":true,"img":false}]}
{"op":"mcm","clk":"11541193088","pt":1719503213258,"mc":[{"id":"1.230178322","rc":[{"atb":[[3.15,5.51]],"id":70681333}],"con":true,"img":false}]}
{"op":"mcm","clk":"11541193122","pt":1719503213516,"mc":[{"id":"1.230178322","rc":[{"atb":[[2.18,10.04]],"id":51569790}],"con":true,"img":false}]}
{"op":"mcm","clk":"11541193146","pt":1719503213723,"mc":[{"id":"1.230178322","rc":[{"atb":[[2.9,6.23]],"id":63650892}],"con":true,"img":false}]}
{"op":"mcm","clk":"11541193169","pt":1719503213930,"mc":[{"id":"1.230178322","rc":[{"atb":[[2.28,9.26]],"id":47885365}],"con":true,"img":false}]}
{"op":"mcm","clk":"11541193191","pt":1719503214137,"mc":[{"id":"1.230178322","rc":[{"atb":[[2.46,8.11]],"id":68274051}],"con":true,"img":false}]}
{"op":"mcm","clk":"11541193217","pt":1719503214342,"mc":[{"id":"1.230178322","rc":[{"atb":[[2.26,2.09]],"id":51569790},{"atb":[[2.16,10.22]],"id":60192591}],"con":true,"img":false}]}
{"op":"mcm","clk":"11541193343","pt":1719503215529,"mc":[{"id":"1.230178322","rc":[{"atb":[[2.54,2.09]],"id":68274051}],"con":true,"img":false}]}
{"op":"mcm","clk":"11541193586","pt":1719503217970,"mc":[{"id":"1.230178322","rc":[{"atb":[[2.88,3.16]],"id":63650892}],"con":true,"img":false}]}
{"op":"mcm","clk":"11541193610","pt":1719503218129,"mc":[{"id":"1.230178322","rc":[{"atb":[[3.6,0]],"id":51569790},{"trd":[[3.6,2]],"ltp":3.6,"tv":2.0,"id":51569790}],"con":true,"img":false}]}
{"op":"mcm","clk":"11541193639","pt":1719503218337,"mc":[{"id":"1.230178322","rc":[{"atb":[[2.36,3.16]],"id":68274051}],"con":true,"img":false}]}
{"op":"mcm","clk":"11541193750","pt":1719503219328,"mc":[{"id":"1.230178322","rc":[{"atb":[[2.92,3.38]],"id":63650892}],"con":true,"img":false}]}
{"op":"mcm","clk":"11541193806","pt":1719503219855,"mc":[{"id":"1.230178322","rc":[{"atb":[[2.48,3.38]],"id":68274051}],"con":true,"img":false}]}
{"op":"mcm","clk":"11541193916","pt":1719503220950,"mc":[{"id":"1.230178322","rc":[{"atl":[[32,0]],"id":51569790}],"con":true,"img":false}]}
{"op":"mcm","clk":"11541193922","pt":1719503221054,"mc":[{"id":"1.230178322","rc":[{"atb":[[3.05,3.9]],"id":51569790}],"con":true,"img":false}]}
{"op":"mcm","clk":"11541193932","pt":1719503221159,"mc":[{"id":"1.230178322","rc":[{"atl":[[1000,0.03]],"id":51569790}],"con":true,"img":false}]}
{"op":"mcm","clk":"11541193944","pt":1719503221262,"mc":[{"id":"1.230178322","rc":[{"atl":[[1000,0]],"id":51569790}],"con":true,"img":false}]}
{"op":"mcm","clk":"11541193951","pt":1719503221366,"mc":[{"id":"1.230178322","rc":[{"atl":[[32,0.03]],"id":51569790}],"con":true,"img":false}]}
{"op":"mcm","clk":"11541194078","pt":1719503222563,"mc":[{"id":"1.230178322","rc":[{"atl":[[32,0.87]],"id":51569790}],"con":true,"img":false}]}
{"op":"mcm","clk":"11541194089","pt":1719503222667,"mc":[{"id":"1.230178322","rc":[{"atl":[[140,0.84]],"id":47885365},{"atl":[[19.5,0.84]],"id":68274051}],"con":true,"img":false}]}
{"op":"mcm","clk":"11541194833","pt":1719503229827,"mc":[{"id":"1.230178322","rc":[{"atb":[[3.5,0]],"id":51569790},{"trd":[[3.5,5.69]],"ltp":3.5,"tv":5.69,"id":51569790}],"con":true,"img":false}]}
{"op":"mcm","clk":"11541195097","pt":1719503232670,"mc":[{"id":"1.230178322","rc":[{"atl":[[32,1.92]],"id":51569790}],"con":true,"img":false}]}
{"op":"mcm","clk":"11541195105","pt":1719503232733,"mc":[{"id":"1.230178322","rc":[{"atb":[[3.1,0.75]],"id":51569790}],"con":true,"img":false}]}
{"op":"mcm","clk":"11541195234","pt":1719503234070,"mc":[{"id":"1.230178322","rc":[{"spn":72.5,"spf":"NaN","id":47885365},{"atl":[[34,0]],"id":51569790},{"spn":17.55,"spf":"NaN","id":51569790}],"con":true,"img":false}]}
{"op":"mcm","clk":"11541195490","pt":1719503236531,"mc":[{"id":"1.230178322","rc":[{"atl":[[32,1.89]],"id":51569790}],"con":true,"img":false}]}
{"op":"mcm","clk":"11541195506","pt":1719503236737,"mc":[{"id":"1.230178322","rc":[{"atl":[[1000,0.03]],"id":51569790}],"con":true,"img":false}]}
{"op":"mcm","clk":"11541195532","pt":1719503236943,"mc":[{"id":"1.230178322","rc":[{"atl":[[1000,0]],"id":51569790}],"con":true,"img":false}]}
{"op":"mcm","clk":"11541195542","pt":1719503237046,"mc":[{"id":"1.230178322","rc":[{"atl":[[30,0.03]],"id":51569790}],"con":true,"img":false}]}
{"op":"mcm","clk":"11541195846","pt":1719503240044,"mc":[{"id":"1.230178322","rc":[{"atl":[[30,1.73]],"id":51569790}],"con":true,"img":false}]}
{"op":"mcm","clk":"11541196593","pt":1719503248181,"mc":[{"id":"1.230178322","rc":[{"atb":[[3.1,0]],"id":51569790}],"con":true,"img":false}]}
{"op":"mcm","clk":"11541196613","pt":1719503248390,"mc":[{"id":"1.230178322","rc":[{"atl":[[32,0.84]],"id":51569790}],"con":true,"img":false}]}
{"op":"mcm","clk":"11541196660","pt":1719503248956,"mc":[{"id":"1.230178322","rc":[{"atl":[[29,1.05]],"id":51569790}],"con":true,"img":false}]}
{"op":"mcm","clk":"11541196670","pt":1719503249063,"mc":[{"id":"1.230178322","rc":[{"atb":[[3.1,0.75]],"id":51569790}],"con":true,"img":false}]}
{"op":"mcm","clk":"11541196692","pt":1719503249269,"mc":[{"id":"1.230178322","rc":[{"atb":[[2.16,5.45]],"id":70681333}],"con":true,"img":false}]}
{"op":"mcm","clk":"11541196705","pt":1719503249371,"mc":[{"id":"1.230178322","rc":[{"atb":[[2.16,18.28]],"id":51569790}],"con":true,"img":false}]}
{"op":"mcm","clk":"11541196727","pt":1719503249582,"mc":[{"id":"1.230178322","rc":[{"atb":[[2.16,5.45]],"id":47885365}],"con":true,"img":false}]}
{"op":"mcm","clk":"11541196755","pt":1719503249847,"mc":[{"id":"1.230178322","rc":[{"atb":[[2.44,6.58]],"id":51569790}],"con":true,"img":false}]}
{"op":"mcm","clk":"11541196775","pt":1719503250049,"mc":[{"id":"1.230178322","rc":[{"atb":[[2.16,14.86]],"id":63650892}],"con":true,"img":false}]}
{"op":"mcm","clk":"11541197021","pt":1719503252285,"mc":[{"id":"1.230178322","rc":[{"atl":[[30,1.7]],"id":51569790}],"con":true,"img":false}]}
{"op":"mcm","clk":"11541197041","pt":1719503252451,"mc":[{"id":"1.230178322","rc":[{"atl":[[1000,0.04]],"id":51569790}],"con":true,"img":false}]}
{"op":"mcm","clk":"11541197064","pt":1719503252649,"mc":[{"id":"1.230178322","rc":[{"atl":[[1000,0]],"id":51569790}],"con":true,"img":false}]}
{"op":"mcm","clk":"11541197077","pt":1719503252756,"mc":[{"id":"1.230178322","rc":[{"atl":[[28,0.04]],"id":51569790}],"con":true,"img":false}]}
{"op":"mcm","clk":"11541197537","pt":1719503257761,"mc":[{"id":"1.230178322","rc":[{"atb":[[2.9,0]],"id":63650892},{"atb":[[2.46,0]],"id":68274051}],"con":true,"img":false}]}
{"op":"mcm","clk":"11541198190","pt":1719503264385,"mc":[{"id":"1.230178322","rc":[{"atl":[[29,0]],"id":51569790}],"con":true,"img":false}]}
{"op":"mcm","clk":"11541198236","pt":1719503264901,"mc":[{"id":"1.230178322","rc":[{"atb":[[3.1,0]],"id":51569790}],"con":true,"img":false}]}
{"op":"mcm","clk":"11541198264","pt":1719503265271,"mc":[{"id":"1.230178322","rc":[{"atb":[[3.15,11.42]],"id":70681333},{"atb":[[2.92,0]],"id":63650892},{"atb":[[2.48,0]],"id":68274051},{"atl":[[28,1.09]],"id":51569790}],"con":true,"img":false}]}
{"op":"mcm","clk":"11541198281","pt":1719503265472,"mc":[{"id":"1.230178322","rc":[{"atb":[[3.1,0.75]],"id":51569790}],"con":true,"img":false}]}
{"op":"mcm","clk":"11541198290","pt":1719503265575,"mc":[{"id":"1.230178322","rc":[{"atb":[[2.3,9.77]],"id":47885365}],"con":true,"img":false}]}
{"op":"mcm","clk":"11541198308","pt":1719503265780,"mc":[{"id":"1.230178322","rc":[{"atb":[[2.18,10.76]],"id":60192591}],"con":true,"img":false}]}
{"op":"mcm","clk":"11541198498","pt":1719503268000,"mc":[{"id":"1.230178322","rc":[{"atl":[[28,1.05]],"id":51569790}],"con":true,"img":false}]}
{"op":"mcm","clk":"11541198592","pt":1719503269083,"mc":[{"id":"1.230178322","rc":[{"atl":[[1000,0.04]],"id":51569790}],"con":true,"img":false}]}
{"op":"mcm","clk":"11541198604","pt":1719503269186,"mc":[{"id":"1.230178322","rc":[{"atl":[[1000,0]],"id":51569790}],"con":true,"img":false}]}
{"op":"mcm","clk":"11541198613","pt":1719503269293,"mc":[{"id":"1.230178322","rc":[{"atl":[[27,0.04]],"id":51569790}],"con":true,"img":false}]}
{"op":"mcm","clk":"11541199671","pt":1719503280610,"mc":[{"id":"1.230178322","rc":[{"atl":[[28,0]],"id":51569790}],"con":true,"img":false}]}
{"op":"mcm","clk":"11541199685","pt":1719503280817,"mc":[{"id":"1.230178322","rc":[{"atb":[[3.1,0]],"id":51569790}],"con":true,"img":false}]}
{"op":"mcm","clk":"11541200044","pt":1719503284609,"mc":[{"id":"1.230178322","rc":[{"atl":[[27,0]],"id":51569790}],"con":true,"img":false}]}
{"op":"mcm","clk":"11541200069","pt":1719503284830,"mc":[{"id":"1.230178322","rc":[{"atl":[[1000,0.04]],"id":51569790}],"con":true,"img":false}]}
{"op":"mcm","clk":"11541200086","pt":1719503284987,"mc":[{"id":"1.230178322","rc":[{"atl":[[1000,0]],"id":51569790}],"con":true,"img":false}]}
{"op":"mcm","clk":"11541200095","pt":1719503285093,"mc":[{"id":"1.230178322","rc":[{"atl":[[29,0.04]],"id":51569790}],"con":true,"img":false}]}
{"op":"mcm","clk":"11541200472","pt":1719503288424,"mc":[{"id":"1.230178322","rc":[{"atb":[[2.46,8.11]],"id":68274051}],"con":true,"img":false}]}
{"op":"mcm","clk":"11541200486","pt":1719503288591,"mc":[{"id":"1.230178322","rc":[{"atb":[[2.88,9.47]],"id":63650892}],"con":true,"img":false}]}
{"op":"mcm","clk":"11541200563","pt":1719503289424,"mc":[{"id":"1.230178322","rc":[{"atb":[[2.26,0]],"id":47885365},{"atb":[[2.16,5.45]],"id":51569790},{"atb":[[2.14,0]],"id":60192591}],"con":true,"img":false}]}
{"op":"mcm","clk":"11541200573","pt":1719503289528,"mc":[{"id":"1.230178322","rc":[{"atb":[[2.32,11.66]],"id":47885365},{"atb":[[2.2,12.82]],"id":51569790},{"atb":[[2.2,13.2]],"id":60192591}],"con":true,"img":false}]}
{"op":"mcm","clk":"11541201132","pt":1719503294710,"mc":[{"id":"1.230178322","rc":[{"atl":[[29,1.09]],"id":51569790},{"spn":16.02,"spf":"NaN","id":51569790}],"con":true,"img":false}]}
{"op":"mcm","clk":"11541201143","pt":1719503294813,"mc":[{"id":"1.230178322","rc":[{"atb":[[3.1,0.75]],"id":51569790}],"con":true,"img":false}]}
{"op":"mcm","clk":"11541201478","pt":1719503298337,"mc":[{"id":"1.230178322","rc":[{"atb":[[2.28,0]],"id":47885365},{"atb":[[2.16,0]],"id":60192591}],"con":true,"img":false}]}
{"op":"mcm","clk":"11541201641","pt":1719503300316,"mc":[{"id":"1.230178322","rc":[{"atl":[[29,1.05]],"id":51569790}],"con":true,"img":false}]}
{"op":"mcm","clk":"11541201656","pt":1719503300523,"mc":[{"id":"1.230178322","rc":[{"atl":[[1000,0.04]],"id":51569790}],"con":true,"img":false}]}
{"op":"mcm","clk":"11541201677","pt":1719503300719,"mc":[{"id":"1.230178322","rc":[{"atl":[[1000,0]],"id":51569790}],"con":true,"img":false}]}
{"op":"mcm","clk":"11541201685","pt":1719503300823,"mc":[{"id":"1.230178322","rc":[{"atl":[[28,0.04]],"id":51569790}],"con":true,"img":false}]}
{"op":"mcm","clk":"11541202101","pt":1719503305610,"mc":[{"id":"1.230178322","rc":[{"atb":[[2.44,13.63]],"id":51569790}],"con":true,"img":false}]}
{"op":"mcm","clk":"11541202136","pt":1719503305918,"mc":[{"id":"1.230178322","rc":[{"atb":[[2.46,8.69]],"id":51569790}],"con":true,"img":false}]}
{"op":"mcm","clk":"11541202531","pt":1719503310122,"mc":[{"id":"1.230178322","rc":[{"atl":[[29,0]],"id":51569790}],"con":true,"img":false}]}
{"op":"mcm","clk":"11541202559","pt":1719503310431,"mc":[{"id":"1.230178322","rc":[{"atb":[[3.1,0]],"id":51569790}],"con":true,"img":false}]}
{"op":"mcm","clk":"11541202609","pt":1719503311048,"mc":[{"id":"1.230178322","rc":[{"atl":[[28,1.09]],"id":51569790}],"con":true,"img":false}]}
{"op":"mcm","clk":"11541202619","pt":1719503311114,"mc":[{"id":"1.230178322","rc":[{"atb":[[3.1,0.75]],"id":51569790}],"con":true,"img":false}]}
{"op":"mcm","clk":"11541203080","pt":1719503316038,"mc":[{"id":"1.230178322","rc":[{"atl":[[28,1.05]],"id":51569790}],"con":true,"img":false}]}
{"op":"mcm","clk":"11541203104","pt":1719503316236,"mc":[{"id":"1.230178322","rc":[{"atl":[[1000,0.04]],"id":51569790}],"con":true,"img":false}]}
{"op":"mcm","clk":"11541203123","pt":1719503316443,"mc":[{"id":"1.230178322","rc":[{"atl":[[1000,0]],"id":51569790}],"con":true,"img":false}]}
{"op":"mcm","clk":"11541203132","pt":1719503316547,"mc":[{"id":"1.230178322","rc":[{"atl":[[27,0.04]],"id":51569790}],"con":true,"img":false}]}
{"op":"mcm","clk":"11541203846","pt":1719503323943,"mc":[{"id":"1.230178322","rc":[{"atb":[[2.34,8.84]],"id":47885365}],"con":true,"img":false}]}
{"op":"mcm","clk":"11541203856","pt":1719503324047,"mc":[{"id":"1.230178322","rc":[{"atb":[[2.22,9.72]],"id":60192591}],"con":true,"img":false}]}
{"op":"mcm","clk":"11541203889","pt":1719503324460,"mc":[{"id":"1.230178322","rc":[{"atb":[[2.3,0]],"id":47885365},{"atb":[[2.18,0]],"id":60192591}],"con":true,"img":false}]}
{"op":"mcm","clk":"11541203995","pt":1719503325648,"mc":[{"id":"1.230178322","rc":[{"atb":[[2.9,3.38]],"id":63650892}],"con":true,"img":false}]}
{"op":"mcm","clk":"11541204026","pt":1719503325958,"mc":[{"id":"1.230178322","rc":[{"atb":[[2.48,8.58]],"id":68274051}],"con":true,"img":false}]}
{"op":"mcm","clk":"11541204054","pt":1719503326267,"mc":[{"id":"1.230178322","rc":[{"atb":[[2.9,10.06]],"id":63650892}],"con":true,"img":false}]}
{"op":"mcm","clk":"11541204060","pt":1719503326370,"mc":[{"id":"1.230178322","rc":[{"atl":[[28,0]],"id":51569790}],"con":true,"img":false}]}
{"op":"mcm","clk":"11541204068","pt":1719503326428,"mc":[{"id":"1.230178322","rc":[{"atb":[[2.48,11.97]],"id":68274051}],"con":true,"img":false}]}
{"op":"mcm","clk":"11541204082","pt":1719503326635,"mc":[{"id":"1.230178322","rc":[{"atb":[[3.1,0]],"id":51569790}],"con":true,"img":false}]}
{"op":"mcm","clk":"11541204163","pt":1719503327760,"mc":[{"id":"1.230178322","rc":[{"atb":[[2.42,4.76]],"id":68274051}],"con":true,"img":false}]}
{"op":"mcm","clk":"11541204318","pt":1719503329666,"mc":[{"id":"1.230178322","rc":[{"atb":[[2.42,0]],"id":68274051}],"con":true,"img":false}]}
{"op":"mcm","clk":"11541204463","pt":1719503331168,"mc":[{"id":"1.230178322","rc":[{"atb":[[2.18,0]],"id":51569790}],"con":true,"img":false}]}
{"op":"mcm","clk":"11541204523","pt":1719503331741,"mc":[{"id":"1.230178322","rc":[{"atl":[[27,0]],"id":51569790}],"con":true,"img":false}]}
{"op":"mcm","clk":"11541204590","pt":1719503332661,"mc":[{"id":"1.230178322","rc":[{"atl":[[1000,0.04]],"id":51569790}],"con":true,"img":false}]}
{"op":"mcm","clk":"11541204609","pt":1719503332868,"mc":[{"id":"1.230178322","rc":[{"atl":[[1000,0]],"id":51569790}],"con":true,"img":false}]}
{"op":"mcm","clk":"11541204619","pt":1719503332972,"mc":[{"id":"1.230178322","rc":[{"atl":[[29,0.04]],"id":51569790}],"con":true,"img":false}]}
{"op":"mcm","clk":"11541205080","pt":1719503337961,"mc":[{"id":"1.230178322","rc":[{"atb":[[3.4,4.72]],"id":51569790}],"con":true,"img":false}]}
{"op":"mcm","clk":"11541205164","pt":1719503338748,"mc":[{"id":"1.230178322","rc":[{"atl":[[29,1.09]],"id":51569790}],"con":true,"img":false}]}
{"op":"mcm","clk":"11541205175","pt":1719503338852,"mc":[{"id":"1.230178322","rc":[{"atb":[[3.45,0.64]],"id":51569790}],"con":true,"img":false}]}
{"op":"mcm","clk":"11541205423","pt":1719503340778,"mc":[{"id":"1.230178322","rc":[{"atb":[[2.88,6.3]],"id":63650892},{"atb":[[2.36,0]],"id":68274051}],"con":true,"img":false}]}
{"op":"mcm","clk":"11541205440","pt":1719503340978,"mc":[{"id":"1.230178322","rc":[{"atb":[[2.48,8.01]],"id":51569790}],"con":true,"img":false}]}
{"op":"mcm","clk":"11541205456","pt":1719503341187,"mc":[{"id":"1.230178322","rc":[{"atb":[[2.5,3.16]],"id":68274051}],"con":true,"img":false}]}
{"op":"mcm","clk":"11541205487","pt":1719503341457,"mc":[{"id":"1.230178322","rc":[{"atb":[[2.92,3.16]],"id":63650892}],"con":true,"img":false}]}
{"op":"mcm","clk":"11541206001","pt":1719503346486,"mc":[{"id":"1.230178322","rc":[{"atl":[[1000,1.22]],"id":68274051}],"con":true,"img":false}]}
{"op":"mcm","clk":"11541206018","pt":1719503346691,"mc":[{"id":"1.230178322","rc":[{"atl":[[1000,0.25]],"id":68274051}],"con":true,"img":false}]}
{"op":"mcm","clk":"11541206033","pt":1719503346899,"mc":[{"id":"1.230178322","rc":[{"atb":[[3.7,3.18]],"id":63650892},{"atb":[[2.6,7.42]],"id":68274051},{"atl":[[1000,0.22]],"id":68274051},{"atb":[[2.46,23.11]],"id":51569790}],"con":true,"img":false}]}
{"op":"mcm","clk":"11541206045","pt":1719503346971,"mc":[{"id":"1.230178322","rc":[{"atl":[[19,0.03]],"id":68274051}],"con":true,"img":false}]}
{"op":"mcm","clk":"11541206169","pt":1719503348195,"mc":[{"id":"1.230178322","rc":[{"atl":[[29,1.05]],"id":51569790}],"con":true,"img":false}]}
{"op":"mcm","clk":"11541206190","pt":1719503348401,"mc":[{"id":"1.230178322","rc":[{"atl":[[1000,0.04]],"id":51569790}],"con":true,"img":false}]}
{"op":"mcm","clk":"11541206207","pt":1719503348565,"mc":[{"id":"1.230178322","rc":[{"atl":[[1000,0]],"id":51569790}],"con":true,"img":false}]}
{"op":"mcm","clk":"11541206221","pt":1719503348670,"mc":[{"id":"1.230178322","rc":[{"atl":[[28,0.04]],"id":51569790}],"con":true,"img":false}]}
{"op":"mcm","clk":"11541206307","pt":1719503349489,"mc":[{"id":"1.230178322","rc":[{"atb":[[6,2.28]],"id":47885365}],"con":true,"img":false}]}
{"op":"mcm","clk":"11541206554","pt":1719503352073,"mc":[{"id":"1.230178322","rc":[{"atb":[[3.45,0]],"id":51569790},{"trd":[[3.45,1.28]],"ltp":3.45,"tv":1.28,"id":51569790}],"con":true,"img":false}]}
{"op":"mcm","clk":"11541206693","pt":1719503353882,"mc":[{"id":"1.230178322","rc":[{"atb":[[3.4,0]],"id":51569790}],"con":true,"img":false}]}
{"op":"mcm","clk":"11541206702","pt":1719503353986,"mc":[{"id":"1.230178322","rc":[{"atb":[[3.55,4.72]],"id":51569790}],"con":true,"img":false}]}
{"op":"mcm","clk":"11541206710","pt":1719503354088,"mc":[{"id":"1.230178322","rc":[{"atl":[[29,0]],"id":51569790}],"con":true,"img":false}]}
{"op":"mcm","clk":"11541207014","pt":1719503358088,"mc":[{"id":"1.230178322","rc":[{"spn":73.0,"spf":"NaN","id":47885365},{"atb":[[2.46,8.69]],"id":51569790},{"spn":15.77,"spf":"NaN","id":51569790}],"con":true,"img":false}]}
{"op":"mcm","clk":"11541207297","pt":1719503361396,"mc":[{"id":"1.230178322","rc":[{"atb":[[2.88,0]],"id":63650892},{"atb":[[2.46,0]],"id":68274051}],"con":true,"img":false}]}
{"op":"mcm","clk":"11541207420","pt":1719503362919,"mc":[{"id":"1.230178322","rc":[{"atb":[[3.55,0]],"id":51569790},{"trd":[[3.55,9.44]],"ltp":3.55,"tv":9.44,"id":51569790}],"con":true,"img":false}]}
{"op":"mcm","clk":"11541207483","pt":1719503363490,"mc":[{"id":"1.230178322","rc":[{"atl":[[1000,1]],"id":51569790}],"con":true,"img":false}]}
{"op":"mcm","clk":"11541207502","pt":1719503363695,"mc":[{"id":"1.230178322","rc":[{"atl":[[1000,0.03]],"id":51569790}],"con":true,"img":false}]}
{"op":"mcm","clk":"11541207524","pt":1719503363904,"mc":[{"id":"1.230178322","rc":[{"atl":[[28,0],[1000,0]],"id":51569790}],"con":true,"img":false}]}
{"op":"mcm","clk":"11541207535","pt":1719503364007,"mc":[{"id":"1.230178322","rc":[{"atl":[[27,0.03]],"id":51569790}],"con":true,"img":false}]}
{"op":"mcm","clk":"11541207547","pt":1719503364111,"mc":[{"id":"1.230178322","rc":[{"atl":[[1000,0.04]],"id":51569790}],"con":true,"img":false}]}
{"op":"mcm","clk":"11541207570","pt":1719503364319,"mc":[{"id":"1.230178322","rc":[{"atl":[[1000,0]],"id":51569790}],"con":true,"img":false}]}
{"op":"mcm","clk":"11541207583","pt":1719503364383,"mc":[{"id":"1.230178322","rc":[{"atb":[[2.92,9.33]],"id":63650892},{"atl":[[29,0.04]],"id":51569790}],"con":true,"img":false}]}
{"op":"mcm","clk":"11541207592","pt":1719503364484,"mc":[{"id":"1.230178322","rc":[{"atb":[[2.5,0]],"id":68274051}],"con":true,"img":false}]}
{"op":"mcm","clk":"11541207611","pt":1719503364685,"mc":[{"id":"1.230178322","rc":[{"atb":[[2.5,7.9]],"id":68274051}],"con":true,"img":false}]}
{"op":"mcm","clk":"11541207625","pt":1719503364886,"mc":[{"id":"1.230178322","rc":[{"atb":[[2.62,3.16]],"id":68274051}],"con":true,"img":false}]}
{"op":"mcm","clk":"11541208468","pt":1719503369308,"mc":[{"id":"1.230178322","rc":[{"atl":[[29,0.68]],"id":51569790}],"con":true,"img":false}]}
{"op":"mcm","clk":"11541208818","pt":1719503372330,"mc":[{"id":"1.230178322","rc":[{"atb":[[3.55,4.72]],"id":51569790}],"con":true,"img":false}]}
{"op":"mcm","clk":"11541209171","pt":1719503375121,"mc":[{"id":"1.230178322","rc":[{"atb":[[2.9,6.68]],"id":63650892}],"con":true,"img":false}]}
{"op":"mcm","clk":"11541209228","pt":1719503375740,"mc":[{"id":"1.230178322","rc":[{"atb":[[2.24,10.24]],"id":60192591}],"con":true,"img":false}]}
{"op":"mcm","clk":"11541209240","pt":1719503375809,"mc":[{"id":"1.230178322","rc":[{"atb":[[2.36,9.33]],"id":47885365}],"con":true,"img":false}]}
{"op":"mcm","clk":"11541209284","pt":1719503376159,"mc":[{"id":"1.230178322","rc":[{"atb":[[2.48,8.58]],"id":68274051}],"con":true,"img":false}]}
{"op":"mcm","clk":"11541209339","pt":1719503376474,"mc":[{"id":"1.230178322","rc":[{"atb":[[2.94,3.38]],"id":63650892}],"con":true,"img":false}]}
{"op":"mcm","clk":"11541209353","pt":1719503376542,"mc":[{"id":"1.230178322","rc":[{"atb":[[2.62,6.54]],"id":68274051}],"con":true,"img":false}]}
{"op":"mcm","clk":"11541209682","pt":1719503379614,"mc":[{"id":"1.230178322","rc":[{"atl":[[29,0.64]],"id":51569790}],"con":true,"img":false}]}
{"op":"mcm","clk":"11541209743","pt":1719503379824,"mc":[{"id":"1.230178322","rc":[{"atl":[[1000,0.04]],"id":51569790}],"con":true,"img":false}]}
{"op":"mcm","clk":"11541209774","pt":1719503380132,"mc":[{"id":"1.230178322","rc":[{"atl":[[1000,0]],"id":51569790}],"con":true,"img":false}]}
{"op":"mcm","clk":"11541209789","pt":1719503380240,"mc":[{"id":"1.230178322","rc":[{"atl":[[29,0.68]],"id":51569790}],"con":true,"img":false}]}
{"op":"mcm","clk":"11541209878","pt":1719503381210,"mc":[{"id":"1.230178322","rc":[{"atb":[[2.6,3.84]],"id":68274051}],"con":true,"img":false}]}
{"op":"mcm","clk":"11541209886","pt":1719503381313,"mc":[{"id":"1.230178322","rc":[{"atb":[[2.64,5.3]],"id":51569790}],"con":true,"img":false}]}
{"op":"mcm","clk":"11541210137","pt":1719503384121,"mc":[{"id":"1.230178322","rc":[{"atb":[[3.55,0]],"id":51569790},{"trd":[[3.55,18.88]],"ltp":3.55,"tv":18.88,"id":51569790}],"con":true,"img":false}]}
{"op":"mcm","clk":"11541210149","pt":1719503384226,"mc":[{"id":"1.230178322","rc":[{"atb":[[3.2,1.67]],"id":70681333},{"atb":[[2.64,1.82]],"id":68274051},{"atb":[[3.1,1.65]],"id":51569790}],"con":true,"img":false}]}
{"op":"mcm","clk":"11541210181","pt":1719503384537,"mc":[{"id":"1.230178322","rc":[{"atl":[[29,0.04]],"id":51569790}],"con":true,"img":false}]}
{"op":"mcm","clk":"11541210196","pt":1719503384735,"mc":[{"id":"1.230178322","rc":[{"atl":[[1000,0.79]],"id":47885365},{"atl":[[1000,0.79]],"id":60192591}],"con":true,"img":false}]}
{"op":"mcm","clk":"11541210215","pt":1719503384906,"mc":[{"id":"1.230178322","rc":[{"atb":[[2.64,2.67]],"id":68274051},{"atb":[[3.1,2.49]],"id":51569790}],"con":true,"img":false}]}
{"op":"mcm","clk":"11541210225","pt":1719503385010,"mc":[{"id":"1.230178322","rc":[{"atl":[[29,0.68]],"id":51569790}],"con":true,"img":false}]}
{"op":"mcm","clk":"11541210249","pt":1719503385310,"mc":[{"id":"1.230178322","rc":[{"atl":[[1000,0.45]],"id":47885365},{"atl":[[1000,0.46]],"id":60192591}],"con":true,"img":false}]}
{"op":"mcm","clk":"11541210336","pt":1719503386318,"mc":[{"id":"1.230178322","rc":[{"atb":[[6,0]],"id":47885365}],"con":true,"img":false}]}
{"op":"mcm","clk":"11541210350","pt":1719503386409,"mc":[{"id":"1.230178322","rc":[{"atb":[[2.64,2.1]],"id":68274051},{"atb":[[3.1,1.92]],"id":51569790}],"con":true,"img":false}]}
{"op":"mcm","clk":"11541210515","pt":1719503388013,"mc":[{"id":"1.230178322","rc":[{"atb":[[2.48,11.97]],"id":68274051}],"con":true,"img":false}]}
{"op":"mcm","clk":"11541210806","pt":1719503391028,"mc":[{"id":"1.230178322","rc":[{"atb":[[2.92,4.53]],"id":51569790}],"con":true,"img":false}]}
{"op":"mcm","clk":"11541211098","pt":1719503394036,"mc":[{"id":"1.230178322","rc":[{"atb":[[2.92,0]],"id":51569790}],"con":true,"img":false}]}
{"op":"mcm","clk":"11541211240","pt":1719503395436,"mc":[{"id":"1.230178322","rc":[{"atl":[[29,0.64]],"id":51569790}],"con":true,"img":false}]}
{"op":"mcm","clk":"11541211260","pt":1719503395647,"mc":[{"id":"1.230178322","rc":[{"atl":[[1000,0.04]],"id":51569790}],"con":true,"img":false}]}
{"op":"mcm","clk":"11541211280","pt":1719503395815,"mc":[{"id":"1.230178322","rc":[{"atl":[[1000,0]],"id":51569790}],"con":true,"img":false}]}
{"op":"mcm","clk":"11541211286","pt":1719503395919,"mc":[{"id":"1.230178322","rc":[{"atl":[[29,0.68]],"id":51569790}],"con":true,"img":false}]}
{"op":"mcm","clk":"11541211669","pt":1719503399904,"mc":[{"id":"1.230178322","rc":[{"atb":[[2.9,0]],"id":63650892},{"atb":[[2.48,3.39]],"id":68274051},{"atb":[[2.46,0]],"id":51569790}],"con":true,"img":false}]}
{"op":"mcm","clk":"11541211679","pt":1719503400007,"mc":[{"id":"1.230178322","rc":[{"atb":[[2.62,3.38]],"id":68274051}],"con":true,"img":false}]}
{"op":"mcm","clk":"11541211712","pt":1719503400336,"mc":[{"id":"1.230178322","rc":[{"atl":[[29,0.04]],"id":51569790}],"con":true,"img":false}]}
{"op":"mcm","clk":"11541211767","pt":1719503400851,"mc":[{"id":"1.230178322","rc":[{"atl":[[29,0.68]],"id":51569790}],"con":true,"img":false}]}
{"op":"mcm","clk":"11541212346","pt":1719503406329,"mc":[{"id":"1.230178322","rc":[{"atb":[[2.34,0]],"id":47885365},{"atb":[[2.92,3.16]],"id":63650892},{"atb":[[2.22,0]],"id":60192591}],"con":true,"img":false}]}
{"op":"mcm","clk":"11541212747","pt":1719503410119,"mc":[{"id":"1.230178322","rc":[{"atb":[[2.5,8.46]],"id":51569790}],"con":true,"img":false}]}
{"op":"mcm","clk":"11541212777","pt":1719503410435,"mc":[{"id":"1.230178322","rc":[{"atb":[[2.16,11.29]],"id":70681333}],"con":true,"img":false}]}
{"op":"mcm","clk":"11541212789","pt":1719503410541,"mc":[{"id":"1.230178322","rc":[{"atb":[[2.94,0]],"id":63650892},{"atb":[[2.62,0]],"id":68274051}],"con":true,"img":false}]}
{"op":"mcm","clk":"11541212809","pt":1719503410744,"mc":[{"id":"1.230178322","rc":[{"atb":[[2.52,8.35]],"id":68274051}],"con":true,"img":false}]}
{"op":"mcm","clk":"11541212850","pt":1719503411057,"mc":[{"id":"1.230178322","rc":[{"atb":[[2.16,11.29]],"id":47885365},{"atb":[[2.64,0.27]],"id":68274051},{"atb":[[2.16,11.29]],"id":51569790}],"con":true,"img":false}]}
{"op":"mcm","clk":"11541212859","pt":1719503411110,"mc":[{"id":"1.230178322","rc":[{"atl":[[29,0.64]],"id":51569790}],"con":true,"img":false}]}
{"op":"mcm","clk":"11541212867","pt":1719503411215,"mc":[{"id":"1.230178322","rc":[{"atb":[[2.64,0]],"id":68274051}],"con":true,"img":false}]}
{"op":"mcm","clk":"11541212877","pt":1719503411318,"mc":[{"id":"1.230178322","rc":[{"atb":[[2.16,20.7]],"id":63650892},{"atb":[[2.62,0.27]],"id":68274051},{"atb":[[2.64,10.98]],"id":51569790},{"atl":[[1000,0.04]],"id":51569790}],"con":true,"img":false}]}
{"op":"mcm","clk":"11541212895","pt":1719503411528,"mc":[{"id":"1.230178322","rc":[{"atl":[[1000,0]],"id":51569790}],"con":true,"img":false}]}
{"op":"mcm","clk":"11541212903","pt":1719503411630,"mc":[{"id":"1.230178322","rc":[{"atl":[[29,0.68]],"id":51569790}],"con":true,"img":false}]}
{"op":"mcm","clk":"11541213286","pt":1719503416039,"mc":[{"id":"1.230178322","rc":[{"atl":[[29,0.04]],"id":51569790}],"con":true,"img":false}]}
{"op":"mcm","clk":"11541213320","pt":1719503416440,"mc":[{"id":"1.230178322","rc":[{"atl":[[29,0.68]],"id":51569790}],"con":true,"img":false}]}
{"op":"mcm","clk":"11541213436","pt":1719503417740,"mc":[{"id":"1.230178322","rc":[{"atb":[[2.92,0]],"id":63650892},{"atb":[[2.26,9.4]],"id":60192591}],"con":true,"img":false}]}
{"op":"mcm","clk":"11541213455","pt":1719503417944,"mc":[{"id":"1.230178322","rc":[{"atb":[[2.38,8.59]],"id":47885365}],"con":true,"img":false}]}
{"op":"mcm","clk":"11541213867","pt":1719503422855,"mc":[{"id":"1.230178322","rc":[{"spn":72.5,"spf":"NaN","id":47885365},{"atl":[[5,2]],"id":51569790},{"spn":4.05,"spf":"NaN","id":51569790}],"con":true,"img":false}]}
{"op":"mcm","clk":"11541213880","pt":1719503423061,"mc":[{"id":"1.230178322","rc":[{"atb":[[3.1,0.27],[3.05,0]],"id":51569790}],"con":true,"img":false}]}
{"op":"mcm","clk":"11541213973","pt":1719503424086,"mc":[{"id":"1.230178322","rc":[{"atl":[[30,0]],"id":51569790}],"con":true,"img":false}]}
{"op":"mcm","clk":"11541214000","pt":1719503424450,"mc":[{"id":"1.230178322","rc":[{"atb":[[3.1,0]],"id":51569790}],"con":true,"img":false}]}
{"op":"mcm","clk":"11541214015","pt":1719503424558,"mc":[{"id":"1.230178322","rc":[{"atb":[[1.13,0.27]],"id":51569790}],"con":true,"img":false}]}
{"op":"mcm","clk":"11541214262","pt":1719503427094,"mc":[{"id":"1.230178322","rc":[{"atl":[[29,0.64]],"id":51569790}],"con":true,"img":false}]}
{"op":"mcm","clk":"11541214648","pt":1719503431797,"mc":[{"id":"1.230178322","rc":[{"atl":[[29,0]],"id":51569790}],"con":true,"img":false}]}
{"op":"mcm","clk":"11541214979","pt":1719503435081,"mc":[{"id":"1.230178322","rc":[{"atb":[[2.36,0]],"id":47885365},{"atb":[[2.24,0]],"id":60192591}],"con":true,"img":false}]}
{"op":"mcm","clk":"11541215034","pt":1719503435597,"mc":[{"id":"1.230178322","rc":[{"atb":[[2.88,3.16]],"id":63650892}],"con":true,"img":false}]}
{"op":"mcm","clk":"11541215062","pt":1719503435962,"mc":[{"id":"1.230178322","rc":[{"atb":[[2.54,5.26]],"id":68274051}],"con":true,"img":false}]}
{"op":"mcm","clk":"11541215671","pt":1719503443506,"mc":[{"id":"1.230178322","rc":[{"atb":[[2.5,0]],"id":68274051},{"atb":[[2.48,0]],"id":51569790}],"con":true,"img":false}]}
{"op":"mcm","clk":"11541215715","pt":1719503443974,"mc":[{"id":"1.230178322","rc":[{"atb":[[2.48,0]],"id":68274051}],"con":true,"img":false}]}
{"op":"mcm","clk":"11541215753","pt":1719503444492,"mc":[{"id":"1.230178322","rc":[{"atl":[[4.9,0.64]],"id":51569790}],"con":true,"img":false}]}
{"op":"mcm","clk":"11541215870","pt":1719503445789,"mc":[{"id":"1.230178322","rc":[{"atb":[[2.88,6.54]],"id":63650892}],"con":true,"img":false}]}
{"op":"mcm","clk":"11541216751","pt":1719503456681,"mc":[{"id":"1.230178322","rc":[{"atb":[[2.46,8.11]],"id":51569790}],"con":true,"img":false}]}
{"op":"mcm","clk":"11541216759","pt":1719503456784,"mc":[{"id":"1.230178322","rc":[{"atb":[[2.54,12.96]],"id":68274051}],"con":true,"img":false}]}
{"op":"mcm","clk":"11541216784","pt":1719503457197,"mc":[{"id":"1.230178322","rc":[{"atb":[[3.3,4.43]],"id":51569790}],"con":true,"img":false}]}
{"op":"mcm","clk":"11541217007","pt":1719503459888,"mc":[{"id":"1.230178322","rc":[{"atl":[[4.9,0]],"id":51569790}],"con":true,"img":false}]}
{"op":"mcm","clk":"11541217041","pt":1719503460302,"mc":[{"id":"1.230178322","rc":[{"atb":[[3.9,13.21]],"id":60192591},{"atl":[[140,2]],"id":60192591}],"con":true,"img":false}]}
{"op":"mcm","clk":"11541217048","pt":1719503460405,"mc":[{"id":"1.230178322","rc":[{"atb":[[4.2,6]],"id":47885365},{"atl":[[140,2.84]],"id":47885365},{"atl":[[4.9,0.64]],"id":51569790}],"con":true,"img":false}]}
{"op":"mcm","clk":"11541217052","pt":1719503460510,"mc":[{"id":"1.230178322","rc":[{"atb":[[3.6,6]],"id":70681333},{"atl":[[30,3.45]],"id":70681333},{"atb":[[3,6.55]],"id":63650892},{"atl":[[22,4.76]],"id":63650892},{"atb":[[2.46,13.46]],"id":68274051},{"atl":[[19.5,2.84]],"id":68274051},{"atb":[[2.84,10.43]],"id":51569790},{"atl":[[10.5,4]],"id":51569790}],"con":true,"img":false}]}
{"op":"mcm","clk":"11541217083","pt":1719503461025,"mc":[{"id":"1.230178322","rc":[{"atb":[[1.03,9.59]],"id":70681333},{"atl":[[1000,1.7]],"id":70681333},{"atb":[[1.02,3.7]],"id":63650892},{"atl":[[1000,1.7]],"id":63650892},{"atb":[[1.03,9.59]],"id":51569790},{"atl":[[1000,1.7]],"id":51569790}],"con":true,"img":false}]}
{"op":"mcm","clk":"11541217092","pt":1719503461132,"mc":[{"id":"1.230178322","rc":[{"atb":[[3.2,1]],"id":51569790}],"con":true,"img":false}]}
{"op":"mcm","clk":"11541217102","pt":1719503461185,"mc":[{"id":"1.230178322","rc":[{"atb":[[1.03,7.99]],"id":70681333},{"atl":[[1000,0.01]],"id":70681333},{"atb":[[1.02,2.11]],"id":63650892},{"atl":[[1000,0.01]],"id":63650892},{"atb":[[1.03,7.97]],"id":51569790},{"atl":[[1000,0.05]],"id":51569790}],"con":true,"img":false}]}
{"op":"mcm","clk":"11541217120","pt":1719503461392,"mc":[{"id":"1.230178322","rc":[{"atb":[[1.03,7.89]],"id":70681333},{"atl":[[1000,0]],"id":70681333},{"atb":[[1.02,2]],"id":63650892},{"atl":[[1000,0]],"id":63650892},{"atb":[[1.03,7.89],[3.2,0]],"id":51569790},{"atl":[[1000,0]],"id":51569790}],"con":true,"img":false}]}
{"op":"mcm","clk":"11541217125","pt":1719503461495,"mc":[{"id":"1.230178322","rc":[{"atb":[[4.1,0.1]],"id":70681333},{"atl":[[29,0.01]],"id":70681333},{"atb":[[3.75,0.11]],"id":63650892},{"atl":[[21,0.01]],"id":63650892},{"atb":[[3.35,0.08]],"id":51569790},{"atl":[[4.9,0.69]],"id":51569790}],"con":true,"img":false}]}
{"op":"mcm","clk":"11541217148","pt":1719503461908,"mc":[{"id":"1.230178322","rc":[{"atb":[[1.08,1.69]],"id":51569790}],"con":true,"img":false}]}
{"op":"mcm","clk":"11541217157","pt":1719503462012,"mc":[{"id":"1.230178322","rc":[{"atb":[[1.12,1.69]],"id":70681333},{"atb":[[2.42,3.39]],"id":68274051}],"con":true,"img":false}]}
{"op":"mcm","clk":"11541217174","pt":1719503462219,"mc":[{"id":"1.230178322","rc":[{"atb":[[1.12,1.69]],"id":47885365}],"con":true,"img":false}]}
{"op":"mcm","clk":"11541217183","pt":1719503462323,"mc":[{"id":"1.230178322","rc":[{"atb":[[1.1,1.69]],"id":63650892}],"con":true,"img":false}]}
{"op":"mcm","clk":"11541217197","pt":1719503462427,"mc":[{"id":"1.230178322","rc":[{"atb":[[2.42,0]],"id":68274051},{"atb":[[1.08,0.09]],"id":51569790}],"con":true,"img":false}]}
{"op":"mcm","clk":"11541217208","pt":1719503462531,"mc":[{"id":"1.230178322","rc":[{"atb":[[1.12,0.05]],"id":70681333}],"con":true,"img":false}]}
{"op":"mcm","clk":"11541217222","pt":1719503462638,"mc":[{"id":"1.230178322","rc":[{"atb":[[1.12,0.05]],"id":47885365}],"con":true,"img":false}]}
{"op":"mcm","clk":"11541217233","pt":1719503462689,"mc":[{"id":"1.230178322","rc":[{"atb":[[1.08,1.69]],"id":68274051}],"con":true,"img":false}]}
{"op":"mcm","clk":"11541217252","pt":1719503462898,"mc":[{"id":"1.230178322","rc":[{"atb":[[1.14,1.69]],"id":60192591}],"con":true,"img":false}]}
{"op":"mcm","clk":"11541217264","pt":1719503463010,"mc":[{"id":"1.230178322","rc":[{"atb":[[1.1,0.06]],"id":63650892}],"con":true,"img":false}]}
{"op":"mcm","clk":"11541217285","pt":1719503463219,"mc":[{"id":"1.230178322","rc":[{"atb":[[1.08,0]],"id":51569790}],"con":true,"img":false}]}
{"op":"mcm","clk":"11541217296","pt":1719503463317,"mc":[{"id":"1.230178322","rc":[{"atl":[[20,0]],"id":68274051},{"atb":[[3.35,0.18]],"id":51569790}],"con":true,"img":false}]}
{"op":"mcm","clk":"11541217307","pt":1719503463422,"mc":[{"id":"1.230178322","rc":[{"atl":[[19.5,0.84],[20,5.26]],"id":68274051}],"con":true,"img":false}]}
{"op":"mcm","clk":"11541217323","pt":1719503463628,"mc":[{"id":"1.230178322","rc":[{"atb":[[1.12,0]],"id":70681333}],"con":true,"img":false}]}
{"op":"mcm","clk":"11541217331","pt":1719503463733,"mc":[{"id":"1.230178322","rc":[{"atb":[[5.1,0.05]],"id":70681333}],"con":true,"img":false}]}
{"op":"mcm","clk":"11541217363","pt":1719503463996,"mc":[{"id":"1.230178322","rc":[{"atb":[[1.12,0]],"id":47885365},{"atl":[[19.5,1.63]],"id":68274051}],"con":true,"img":false}]}
{"op":"mcm","clk":"11541217376","pt":1719503464104,"mc":[{"id":"1.230178322","rc":[{"atb":[[5.1,0.05]],"id":47885365}],"con":true,"img":false}]}
{"op":"mcm","clk":"11541217404","pt":1719503464412,"mc":[{"id":"1.230178322","rc":[{"atb":[[1.08,0.09]],"id":68274051},{"atb":[[1.14,0.05]],"id":60192591}],"con":true,"img":false}]}
{"op":"mcm","clk":"11541217427","pt":1719503464720,"mc":[{"id":"1.230178322","rc":[{"atb":[[1.1,0]],"id":63650892},{"atl":[[19.5,1.32]],"id":68274051}],"con":true,"img":false}]}
{"op":"mcm","clk":"11541217440","pt":1719503464825,"mc":[{"id":"1.230178322","rc":[{"atb":[[4.8,0.06]],"id":63650892}],"con":true,"img":false}]}
{"op":"mcm","clk":"11541217468","pt":1719503465089,"mc":[{"id":"1.230178322","rc":[{"atb":[[1.08,0]],"id":68274051}],"con":true,"img":false}]}
{"op":"mcm","clk":"11541217477","pt":1719503465197,"mc":[{"id":"1.230178322","rc":[{"atb":[[3.4,0.09]],"id":68274051}],"con":true,"img":false}]}
{"op":"mcm","clk":"11541217501","pt":1719503465505,"mc":[{"id":"1.230178322","rc":[{"atb":[[1.14,0]],"id":60192591}],"con":true,"img":false}]}
{"op":"mcm","clk":"11541217509","pt":1719503465610,"mc":[{"id":"1.230178322","rc":[{"atb":[[6.4,0.05]],"id":60192591}],"con":true,"img":false}]}
{"op":"mcm","clk":"11541217532","pt":1719503465920,"mc":[{"id":"1.230178322","rc":[{"atb":[[2.52,0]],"id":68274051},{"atb":[[2.5,0]],"id":51569790}],"con":true,"img":false}]}
{"op":"mcm","clk":"11541217676","pt":1719503467633,"mc":[{"id":"1.230178322","rc":[{"atb":[[3.3,0]],"id":51569790}],"con":true,"img":false}]}
{"op":"mcm","clk":"11541217867","pt":1719503469310,"mc":[{"id":"1.230178322","rc":[{"atl":[[19,1.74]],"id":68274051}],"con":true,"img":false}]}
{"op":"mcm","clk":"11541218017","pt":1719503471137,"mc":[{"id":"1.230178322","rc":[{"atb":[[2.84,11.43]],"id":51569790}],"con":true,"img":false}]}
{"op":"mcm","clk":"11541218235","pt":1719503473535,"mc":[{"id":"1.230178322","rc":[{"atl":[[19,3.74],[20,0]],"id":68274051}],"con":true,"img":false}]}
{"op":"mcm","clk":"11541218246","pt":1719503473637,"mc":[{"id":"1.230178322","rc":[{"atl":[[19,1.74],[19.5,6.58]],"id":68274051}],"con":true,"img":false}]}
{"op":"mcm","clk":"11541218350","pt":1719503474940,"mc":[{"id":"1.230178322","rc":[{"atb":[[2.88,3.38]],"id":63650892}],"con":true,"img":false}]}
{"op":"mcm","clk":"11541218368","pt":1719503475099,"mc":[{"id":"1.230178322","rc":[{"atb":[[2.54,9.8]],"id":68274051}],"con":true,"img":false}]}
{"op":"mcm","clk":"11541218387","pt":1719503475308,"mc":[{"id":"1.230178322","rc":[{"atb":[[3.05,3.16]],"id":63650892}],"con":true,"img":false}]}
{"op":"mcm","clk":"11541218410","pt":1719503475618,"mc":[{"id":"1.230178322","rc":[{"atl":[[4.9,0.05]],"id":51569790}],"con":true,"img":false}]}
{"op":"mcm","clk":"11541218454","pt":1719503476093,"mc":[{"id":"1.230178322","rc":[{"atl":[[4.9,0.69]],"id":51569790}],"con":true,"img":false}]}
{"op":"mcm","clk":"11541218524","pt":1719503477029,"mc":[{"id":"1.230178322","rc":[{"atb":[[3.7,1]],"id":63650892}],"con":true,"img":false}]}
{"op":"mcm","clk":"11541218646","pt":1719503478532,"mc":[{"id":"1.230178322","rc":[{"atb":[[3.35,0]],"id":51569790},{"trd":[[3.35,0.36]],"ltp":3.35,"tv":0.36,"id":51569790}],"con":true,"img":false}]}
{"op":"mcm","clk":"11541218769","pt":1719503480033,"mc":[{"id":"1.230178322","rc":[{"atb":[[5.1,0]],"id":70681333},{"atb":[[5.1,0]],"id":47885365},{"atb":[[4.8,0]],"id":63650892},{"atb":[[3.4,0]],"id":68274051},{"atb":[[6.4,0]],"id":60192591}],"con":true,"img":false}]}
{"op":"mcm","clk":"11541218915","pt":1719503481846,"mc":[{"id":"1.230178322","rc":[{"atb":[[2.38,0]],"id":47885365},{"atb":[[2.26,0]],"id":60192591}],"con":true,"img":false}]}
{"op":"mcm","clk":"11541219435","pt":1719503487621,"mc":[{"id":"1.230178322","rc":[{"atl":[[29,0.88]],"id":70681333},{"spn":17.0,"spf":"NaN","id":70681333},{"atl":[[21,1.22]],"id":63650892},{"spn":12.85,"spf":"NaN","id":63650892},{"spn":3.95,"spf":"NaN","id":51569790},{"spn":73.1,"spf":"NaN","id":60192591}],"con":true,"img":false}]}
{"op":"mcm","clk":"11541219707","pt":1719503491335,"mc":[{"id":"1.230178322","rc":[{"atl":[[4.9,0.05]],"id":51569790}],"con":true,"img":false}]}
{"op":"mcm","clk":"11541219768","pt":1719503492055,"mc":[{"id":"1.230178322","rc":[{"atb":[[3.6,0],[4,5]],"id":70681333},{"atb":[[4.9,6],[4.2,0]],"id":47885365},{"atb":[[3,0],[3.3,3.39]],"id":63650892},{"atb":[[2.46,0],[2.62,4.11]],"id":68274051},{"atb":[[2.84,1],[3.05,10.99]],"id":51569790},{"atb":[[4.4,13.21]],"id":60192591}],"con":true,"img":false}]}
{"op":"mcm","clk":"11541219777","pt":1719503492159,"mc":[{"id":"1.230178322","rc":[{"atb":[[3.9,0]],"id":60192591}],"con":true,"img":false}]}
{"op":"mcm","clk":"11541219800","pt":1719503492320,"mc":[{"id":"1.230178322","rc":[{"atb":[[3.1,6.35]],"id":51569790}],"con":true,"img":false}]}
{"op":"mcm","clk":"11541219834","pt":1719503492729,"mc":[{"id":"1.230178322","rc":[{"atb":[[5.1,1.74]],"id":47885365},{"atb":[[2.64,1.82]],"id":68274051},{"atb":[[3.15,1.65]],"id":51569790}],"con":true,"img":false}]}
{"op":"mcm","clk":"11541219872","pt":1719503493043,"mc":[{"id":"1.230178322","rc":[{"atb":[[5,3.84]],"id":47885365},{"atb":[[1.13,0]],"id":51569790}],"con":true,"img":false}]}
{"op":"mcm","clk":"11541219876","pt":1719503493140,"mc":[{"id":"1.230178322","rc":[{"atb":[[3.1,0],[3.15,1.92]],"id":51569790}],"con":true,"img":false}]}
{"op":"mcm","clk":"11541219919","pt":1719503493556,"mc":[{"id":"1.230178322","rc":[{"atb":[[2.34,8.84]],"id":47885365}],"con":true,"img":false}]}
{"op":"mcm","clk":"11541219926","pt":1719503493652,"mc":[{"id":"1.230178322","rc":[{"atb":[[3.05,0]],"id":63650892}],"con":true,"img":false}]}
{"op":"mcm","clk":"11541219933","pt":1719503493757,"mc":[{"id":"1.230178322","rc":[{"atb":[[3.15,0.27]],"id":51569790}],"con":true,"img":false}]}
{"op":"mcm","clk":"11541219941","pt":1719503493859,"mc":[{"id":"1.230178322","rc":[{"atb":[[3.1,1.65]],"id":51569790},{"atb":[[2.22,9.72]],"id":60192591}],"con":true,"img":false}]}
{"op":"mcm","clk":"11541219981","pt":1719503494371,"mc":[{"id":"1.230178322","rc":[{"atb":[[3.15,6.62]],"id":51569790}],"con":true,"img":false}]}
{"op":"mcm","clk":"11541219996","pt":1719503494577,"mc":[{"id":"1.230178322","rc":[{"atb":[[5,3.26]],"id":47885365}],"con":true,"img":false}]}
{"op":"mcm","clk":"11541220037","pt":1719503494938,"mc":[{"id":"1.230178322","rc":[{"atb":[[3.1,0]],"id":51569790}],"con":true,"img":false}]}
{"op":"mcm","clk":"11541220047","pt":1719503495042,"mc":[{"id":"1.230178322","rc":[{"atb":[[3.2,1.65]],"id":51569790}],"con":true,"img":false}]}
{"op":"mcm","clk":"11541220119","pt":1719503495761,"mc":[{"id":"1.230178322","rc":[{"atb":[[3.15,0.27]],"id":51569790}],"con":true,"img":false}]}
{"op":"mcm","clk":"11541220134","pt":1719503495967,"mc":[{"id":"1.230178322","rc":[{"atb":[[3.15,0]],"id":51569790}],"con":true,"img":false}]}
{"op":"mcm","clk":"11541220142","pt":1719503496068,"mc":[{"id":"1.230178322","rc":[{"atb":[[3.1,0.27]],"id":51569790}],"con":true,"img":false}]}
{"op":"mcm","clk":"11541220154","pt":1719503496171,"mc":[{"id":"1.230178322","rc":[{"atb":[[3.2,0]],"id":51569790}],"con":true,"img":false}]}
{"op":"mcm","clk":"11541220167","pt":1719503496273,"mc":[{"id":"1.230178322","rc":[{"atb":[[3.1,1.92]],"id":51569790}],"con":true,"img":false}]}
{"op":"mcm","clk":"11541220178","pt":1719503496376,"mc":[{"id":"1.230178322","rc":[{"atb":[[3.1,8.27]],"id":51569790}],"con":true,"img":false}]}
{"op":"mcm","clk":"11541220479","pt":1719503499665,"mc":[{"id":"1.230178322","rc":[{"atb":[[2.54,2.09]],"id":68274051}],"con":true,"img":false}]}
{"op":"mcm","clk":"11541220664","pt":1719503501887,"mc":[{"id":"1.230178322","rc":[{"atb":[[3.1,16.54],[3.05,0]],"id":51569790}],"con":true,"img":false}]}
{"op":"mcm","clk":"11541220880","pt":1719503503957,"mc":[{"id":"1.230178322","rc":[{"atl":[[4.9,0.69]],"id":51569790}],"con":true,"img":false}]}
{"op":"mcm","clk":"11541220889","pt":1719503504052,"mc":[{"id":"1.230178322","rc":[{"atb":[[4.1,0]],"id":70681333},{"atl":[[29,0.87]],"id":70681333},{"atb":[[3.75,0]],"id":63650892},{"atl":[[21,1.21]],"id":63650892},{"atl":[[4.9,0.64]],"id":51569790}],"con":true,"img":false}]}
{"op":"mcm","clk":"11541221046","pt":1719503505550,"mc":[{"id":"1.230178322","rc":[{"atb":[[2.36,3.16]],"id":68274051}],"con":true,"img":false}]}
{"op":"mcm","clk":"11541221068","pt":1719503505756,"mc":[{"id":"1.230178322","rc":[{"atb":[[2.88,6.54]],"id":63650892}],"con":true,"img":false}]}
{"op":"mcm","clk":"11541221079","pt":1719503505859,"mc":[{"id":"1.230178322","rc":[{"atb":[[2.9,6.23]],"id":63650892}],"con":true,"img":false}]}
{"op":"mcm","clk":"11541221096","pt":1719503506067,"mc":[{"id":"1.230178322","rc":[{"atb":[[2.46,8.11]],"id":68274051}],"con":true,"img":false}]}
{"op":"mcm","clk":"11541222134","pt":1719503516555,"mc":[{"id":"1.230178322","rc":[{"atb":[[5.2,4.88]],"id":47885365}],"con":true,"img":false}]}
{"op":"mcm","clk":"11541222188","pt":1719503517070,"mc":[{"id":"1.230178322","rc":[{"atb":[[5.1,0]],"id":47885365}],"con":true,"img":false}]}
{"op":"mcm","clk":"11541222198","pt":1719503517169,"mc":[{"id":"1.230178322","rc":[{"atb":[[5.3,1.74]],"id":47885365}],"con":true,"img":false}]}
{"op":"mcm","clk":"11541222244","pt":1719503517695,"mc":[{"id":"1.230178322","rc":[{"atb":[[5.2,0]],"id":47885365},{"atb":[[2.46,0]],"id":51569790}],"con":true,"img":false}]}
{"op":"mcm","clk":"11541222296","pt":1719503518268,"mc":[{"id":"1.230178322","rc":[{"atb":[[5.3,0]],"id":47885365}],"con":true,"img":false}]}
{"op":"mcm","clk":"11541222306","pt":1719503518375,"mc":[{"id":"1.230178322","rc":[{"atb":[[5.1,1.74]],"id":47885365}],"con":true,"img":false}]}
{"op":"mcm","clk":"11541222348","pt":1719503518886,"mc":[{"id":"1.230178322","rc":[{"atb":[[5.2,4.88]],"id":47885365}],"con":true,"img":false}]}
{"op":"mcm","clk":"11541222379","pt":1719503519394,"mc":[{"id":"1.230178322","rc":[{"atb":[[5,3]],"id":47885365},{"atl":[[4.9,0]],"id":51569790}],"con":true,"img":false}]}
{"op":"mcm","clk":"11541222391","pt":1719503519497,"mc":[{"id":"1.230178322","rc":[{"atb":[[5.3,0.26]],"id":47885365}],"con":true,"img":false}]}
{"op":"mcm","clk":"11541222586","pt":1719503521471,"mc":[{"id":"1.230178322","rc":[{"atb":[[2.44,7.05]],"id":51569790}],"con":true,"img":false}]}
{"op":"mcm","clk":"11541222856","pt":1719503523898,"mc":[{"id":"1.230178322","rc":[{"atl":[[29,1.71]],"id":70681333},{"atl":[[20,0.84]],"id":63650892},{"atl":[[19.5,5.74]],"id":68274051},{"atl":[[130,0.84]],"id":60192591}],"con":true,"img":false}]}
{"op":"mcm","clk":"11541222871","pt":1719503524008,"mc":[{"id":"1.230178322","rc":[{"atl":[[32,0]],"id":51569790}],"con":true,"img":false}]}
{"op":"mcm","clk":"11541222904","pt":1719503524264,"mc":[{"id":"1.230178322","rc":[{"atl":[[21,0]],"id":63650892}],"con":true,"img":false}]}
{"op":"mcm","clk":"11541222957","pt":1719503524678,"mc":[{"id":"1.230178322","rc":[{"atl":[[21,0.79]],"id":63650892}],"con":true,"img":false}]}
{"op":"mcm","clk":"11541223029","pt":1719503525399,"mc":[{"id":"1.230178322","rc":[{"atl":[[21,0.46]],"id":63650892}],"con":true,"img":false}]}
{"op":"mcm","clk":"11541223079","pt":1719503525869,"mc":[{"id":"1.230178322","rc":[{"atl":[[21,0]],"id":63650892}],"con":true,"img":false}]}
{"op":"mcm","clk":"11541223094","pt":1719503525970,"mc":[{"id":"1.230178322","rc":[{"atl":[[1000,0.46]],"id":63650892}],"con":true,"img":false}]}
{"op":"mcm","clk":"11541223116","pt":1719503526174,"mc":[{"id":"1.230178322","rc":[{"atb":[[2.44,0]],"id":51569790}],"con":true,"img":false}]}
{"op":"mcm","clk":"11541223139","pt":1719503526482,"mc":[{"id":"1.230178322","rc":[{"atl":[[1000,0]],"id":63650892}],"con":true,"img":false}]}
{"op":"mcm","clk":"11541223155","pt":1719503526588,"mc":[{"id":"1.230178322","rc":[{"atl":[[21,0.46]],"id":63650892}],"con":true,"img":false}]}
{"op":"mcm","clk":"11541223219","pt":1719503527101,"mc":[{"id":"1.230178322","rc":[{"atl":[[21,0]],"id":63650892}],"con":true,"img":false}]}
{"op":"mcm","clk":"11541223232","pt":1719503527204,"mc":[{"id":"1.230178322","rc":[{"atl":[[1000,0.46]],"id":63650892}],"con":true,"img":false}]}
{"op":"mcm","clk":"11541223842","pt":1719503532686,"mc":[{"id":"1.230178322","rc":[{"atl":[[4.9,0.64]],"id":51569790}],"con":true,"img":false}]}
{"op":"mcm","clk":"11541223986","pt":1719503534081,"mc":[{"id":"1.230178322","rc":[{"atb":[[3.6,6],[4,2.5]],"id":70681333},{"atb":[[4.9,0],[4.2,6]],"id":47885365},{"atb":[[3,6.24],[3.3,0]],"id":63650892},{"atb":[[2.62,0.27],[2.46,14.11]],"id":68274051},{"atb":[[3.1,8.27],[2.84,23.54]],"id":51569790},{"atb":[[4.4,0],[3.9,13.21]],"id":60192591}],"con":true,"img":false}]}
{"op":"mcm","clk":"11541224006","pt":1719503534284,"mc":[{"id":"1.230178322","rc":[{"atb":[[2.64,0]],"id":68274051},{"atb":[[3.1,6.62]],"id":51569790}],"con":true,"img":false}]}
{"op":"mcm","clk":"11541224029","pt":1719503534491,"mc":[{"id":"1.230178322","rc":[{"atb":[[2.88,3.16]],"id":63650892}],"con":true,"img":false}]}
{"op":"mcm","clk":"11541224063","pt":1719503534802,"mc":[{"id":"1.230178322","rc":[{"atb":[[2.92,3.38]],"id":63650892}],"con":true,"img":false}]}
{"op":"mcm","clk":"11541224118","pt":1719503535366,"mc":[{"id":"1.230178322","rc":[{"atb":[[2.62,0]],"id":68274051},{"atb":[[3.1,6.35]],"id":51569790}],"con":true,"img":false}]}
{"op":"mcm","clk":"11541224131","pt":1719503535474,"mc":[{"id":"1.230178322","rc":[{"atb":[[1.13,0.27]],"id":68274051},{"atb":[[1.13,0.27]],"id":51569790}],"con":true,"img":false}]}
{"op":"mcm","clk":"11541224584","pt":1719503540114,"mc":[{"id":"1.230178322","rc":[{"atb":[[2.88,0]],"id":63650892}],"con":true,"img":false}]}
{"op":"mcm","clk":"11541224601","pt":1719503540276,"mc":[{"id":"1.230178322","rc":[{"atb":[[3.05,3.16]],"id":63650892}],"con":true,"img":false}]}
{"op":"mcm","clk":"11541225285","pt":1719503547325,"mc":[{"id":"1.230178322","rc":[{"atb":[[3.7,3.49]],"id":70681333},{"atb":[[3.7,3.18]],"id":63650892},{"atb":[[2.64,3.38]],"id":68274051},{"atb":[[2.84,44.3]],"id":51569790}],"con":true,"img":false}]}
{"op":"mcm","clk":"11541225315","pt":1719503547602,"mc":[{"id":"1.230178322","rc":[{"atb":[[2.66,1.82]],"id":68274051}],"con":true,"img":false}]}
{"op":"mcm","clk":"11541225329","pt":1719503547693,"mc":[{"id":"1.230178322","rc":[{"atb":[[3.2,0]],"id":70681333},{"spn":72.65,"spf":"NaN","id":47885365},{"spn":12.35,"spf":"NaN","id":63650892},{"spn":4.0,"spf":"NaN","id":51569790},{"spn":68.1,"spf":"NaN","id":60192591}],"con":true,"img":false}]}
{"op":"mcm","clk":"11541225335","pt":1719503547792,"mc":[{"id":"1.230178322","rc":[{"atb":[[3.75,1.67]],"id":70681333}],"con":true,"img":false}]}
{"op":"mcm","clk":"11541225357","pt":1719503547999,"mc":[{"id":"1.230178322","rc":[{"atl":[[4.9,0]],"id":51569790}],"con":true,"img":false}]}
{"op":"mcm","clk":"11541225395","pt":1719503548442,"mc":[{"id":"1.230178322","rc":[{"atl":[[4.9,0.64]],"id":51569790}],"con":true,"img":false}]}
{"op":"mcm","clk":"11541225994","pt":1719503555006,"mc":[{"id":"1.230178322","rc":[{"atb":[[2.16,5.84]],"id":51569790}],"con":true,"img":false}]}
{"op":"mcm","clk":"11541226286","pt":1719503558305,"mc":[{"id":"1.230178322","rc":[{"atb":[[2.22,9.72]],"id":51569790}],"con":true,"img":false}]}
{"op":"mcm","clk":"11541226304","pt":1719503558511,"mc":[{"id":"1.230178322","rc":[{"atb":[[2.9,3.32]],"id":51569790}],"con":true,"img":false}]}
{"op":"mcm","clk":"11541226761","pt":1719503563018,"mc":[{"id":"1.230178322","rc":[{"atb":[[3.6,0],[4,5]],"id":70681333},{"atb":[[4.9,6],[4.2,0]],"id":47885365},{"atb":[[3,0],[3.3,5.7]],"id":63650892},{"atb":[[2.46,8.11],[2.66,5.2]],"id":68274051},{"atb":[[3.1,12.35],[2.84,21.76]],"id":51569790},{"atb":[[4.4,13.21]],"id":60192591}],"con":true,"img":false}]}
{"op":"mcm","clk":"11541226766","pt":1719503563117,"mc":[{"id":"1.230178322","rc":[{"atb":[[3.8,3.5]],"id":70681333},{"atb":[[3.1,6.35],[3.05,12.7]],"id":51569790},{"atb":[[3.9,0]],"id":60192591}],"con":true,"img":false}]}
{"op":"mcm","clk":"11541226778","pt":1719503563222,"mc":[{"id":"1.230178322","rc":[{"atb":[[4,2.5]],"id":70681333}],"con":true,"img":false}]}
{"op":"mcm","clk":"11541226798","pt":1719503563332,"mc":[{"id":"1.230178322","rc":[{"atb":[[4,6]],"id":70681333},{"atb":[[3.15,1.65]],"id":51569790}],"con":true,"img":false}]}
{"op":"mcm","clk":"11541226808","pt":1719503563428,"mc":[{"id":"1.230178322","rc":[{"atb":[[3.8,0]],"id":70681333}],"con":true,"img":false}]}
{"op":"mcm","clk":"11541226823","pt":1719503563537,"mc":[{"id":"1.230178322","rc":[{"atb":[[3.1,0]],"id":51569790},{"atl":[[4.9,0]],"id":51569790}],"con":true,"img":false}]}
{"op":"mcm","clk":"11541226870","pt":1719503563945,"mc":[{"id":"1.230178322","rc":[{"atb":[[3.15,0]],"id":51569790}],"con":true,"img":false}]}
{"op":"mcm","clk":"11541226882","pt":1719503564002,"mc":[{"id":"1.230178322","rc":[{"atb":[[3.1,1.65]],"id":51569790},{"atl":[[10,1]],"id":51569790}],"con":true,"img":false}]}
{"op":"mcm","clk":"11541226944","pt":1719503564631,"mc":[{"id":"1.230178322","rc":[{"atb":[[4.1,0.84]],"id":70681333},{"atb":[[1.13,0]],"id":68274051},{"atb":[[1.13,0]],"id":51569790}],"con":true,"img":false}]}
{"op":"mcm","clk":"11541226952","pt":1719503564728,"mc":[{"id":"1.230178322","rc":[{"atb":[[2.68,0.27]],"id":68274051},{"atb":[[3.1,1.92]],"id":51569790}],"con":true,"img":false}]}
{"op":"mcm","clk":"11541227001","pt":1719503565242,"mc":[{"id":"1.230178322","rc":[{"atb":[[3.15,6.35]],"id":51569790}],"con":true,"img":false}]}
{"op":"mcm","clk":"11541227052","pt":1719503565705,"mc":[{"id":"1.230178322","rc":[{"atb":[[3.1,0.27]],"id":51569790}],"con":true,"img":false}]}
{"op":"mcm","clk":"11541227063","pt":1719503565809,"mc":[{"id":"1.230178322","rc":[{"atl":[[28,0.84]],"id":70681333},{"atb":[[5.3,1.1]],"id":47885365},{"atl":[[18.5,0.84]],"id":68274051},{"atb":[[3.2,2.49]],"id":51569790},{"atl":[[4.9,0.84]],"id":51569790},{"atb":[[6.4,0.84]],"id":60192591}],"con":true,"img":false}]}
{"op":"mcm","clk":"11541227082","pt":1719503566016,"mc":[{"id":"1.230178322","rc":[{"atl":[[29,0.84]],"id":70681333},{"atb":[[5.2,0]],"id":47885365},{"atb":[[3.15,0]],"id":51569790}],"con":true,"img":false}]}
{"op":"mcm","clk":"11541227099","pt":1719503566121,"mc":[{"id":"1.230178322","rc":[{"atb":[[4.1,0.26]],"id":70681333},{"atb":[[3.1,0]],"id":51569790},{"atb":[[6.2,2.84]],"id":60192591}],"con":true,"img":false}]}
{"op":"mcm","clk":"11541227109","pt":1719503566221,"mc":[{"id":"1.230178322","rc":[{"atb":[[3.2,2.76]],"id":51569790}],"con":true,"img":false}]}
{"op":"mcm","clk":"11541227116","pt":1719503566322,"mc":[{"id":"1.230178322","rc":[{"atb":[[6.4,2.54]],"id":60192591}],"con":true,"img":false}]}
{"op":"mcm","clk":"11541227131","pt":1719503566427,"mc":[{"id":"1.230178322","rc":[{"atb":[[3.2,1.11]],"id":51569790}],"con":true,"img":false}]}
{"op":"mcm","clk":"11541227137","pt":1719503566528,"mc":[{"id":"1.230178322","rc":[{"atb":[[3.1,1.65]],"id":51569790}],"con":true,"img":false}]}
{"op":"mcm","clk":"11541227158","pt":1719503566735,"mc":[{"id":"1.230178322","rc":[{"atb":[[5.3,0.26]],"id":47885365},{"atb":[[3.2,0.27]],"id":51569790}],"con":true,"img":false}]}
{"op":"mcm","clk":"11541227190","pt":1719503567045,"mc":[{"id":"1.230178322","rc":[{"atb":[[6.2,0.84]],"id":60192591}],"con":true,"img":false}]}
{"op":"mcm","clk":"11541227198","pt":1719503567147,"mc":[{"id":"1.230178322","rc":[{"atb":[[6.6,2]],"id":60192591}],"con":true,"img":false}]}
{"op":"mcm","clk":"11541227255","pt":1719503567621,"mc":[{"id":"1.230178322","rc":[{"atb":[[5.3,0]],"id":47885365},{"atb":[[3.2,0],[3.15,6.35]],"id":51569790},{"atb":[[6.4,0.84],[6.2,0.27]],"id":60192591}],"con":true,"img":false}]}
{"op":"mcm","clk":"11541227266","pt":1719503567728,"mc":[{"id":"1.230178322","rc":[{"atb":[[5,3.26]],"id":47885365},{"atb":[[3.1,1.92]],"id":51569790}],"con":true,"img":false}]}
{"op":"mcm","clk":"11541227339","pt":1719503568546,"mc":[{"id":"1.230178322","rc":[{"atb":[[6.6,0]],"id":60192591}],"con":true,"img":false}]}
{"op":"mcm","clk":"11541227355","pt":1719503568659,"mc":[{"id":"1.230178322","rc":[{"atb":[[6.4,2.84]],"id":60192591}],"con":true,"img":false}]}
{"op":"mcm","clk":"11541227364","pt":1719503568758,"mc":[{"id":"1.230178322","rc":[{"atb":[[6.4,2],[6.6,1.69]],"id":60192591}],"con":true,"img":false}]}
{"op":"mcm","clk":"11541227396","pt":1719503569066,"mc":[{"id":"1.230178322","rc":[{"atb":[[6.2,0]],"id":60192591}],"con":true,"img":false}]}
{"op":"mcm","clk":"11541227404","pt":1719503569124,"mc":[{"id":"1.230178322","rc":[{"atb":[[1.13,0.27]],"id":60192591}],"con":true,"img":false}]}
{"op":"mcm","clk":"11541227426","pt":1719503569335,"mc":[{"id":"1.230178322","rc":[{"atb":[[6.6,0]],"id":60192591}],"con":true,"img":false}]}
{"op":"mcm","clk":"11541227458","pt":1719503569650,"mc":[{"id":"1.230178322","rc":[{"atb":[[6.4,0]],"id":60192591}],"con":true,"img":false}]}
{"op":"mcm","clk":"11541227468","pt":1719503569748,"mc":[{"id":"1.230178322","rc":[{"atb":[[6.8,2]],"id":60192591}],"con":true,"img":false}]}
{"op":"mcm","clk":"11541227552","pt":1719503570527,"mc":[{"id":"1.230178322","rc":[{"atb":[[6.8,0]],"id":60192591}],"con":true,"img":false}]}
{"op":"mcm","clk":"11541227562","pt":1719503570630,"mc":[{"id":"1.230178322","rc":[{"atb":[[6.2,2]],"id":60192591}],"con":true,"img":false}]}
{"op":"mcm","clk":"11541227716","pt":1719503571918,"mc":[{"id":"1.230178322","rc":[{"atb":[[2.9,0]],"id":63650892},{"atb":[[2.46,0]],"id":68274051}],"con":true,"img":false}]}
{"op":"mcm","clk":"11541227753","pt":1719503572225,"mc":[{"id":"1.230178322","rc":[{"atb":[[3.1,14.62],[3.05,0]],"id":51569790}],"con":true,"img":false}]}
{"op":"mcm","clk":"11541227765","pt":1719503572330,"mc":[{"id":"1.230178322","rc":[{"atb":[[3.7,1]],"id":70681333},{"atb":[[2.64,0]],"id":68274051},{"atb":[[2.84,1]],"id":51569790}],"con":true,"img":false}]}
{"op":"mcm","clk":"11541227809","pt":1719503572845,"mc":[{"id":"1.230178322","rc":[{"atb":[[5.2,0.84]],"id":47885365},{"atb":[[3.2,0.84]],"id":51569790},{"atb":[[6.4,0.84]],"id":60192591}],"con":true,"img":false}]}
{"op":"mcm","clk":"11541227819","pt":1719503572949,"mc":[{"id":"1.230178322","rc":[{"atb":[[2.66,3.38]],"id":68274051},{"atb":[[6.4,2.54]],"id":60192591}],"con":true,"img":false}]}
{"op":"mcm","clk":"11541227870","pt":1719503573417,"mc":[{"id":"1.230178322","rc":[{"atb":[[5,3]],"id":47885365},{"atb":[[2.68,0]],"id":68274051},{"atb":[[1.13,0]],"id":60192591}],"con":true,"img":false}]}
{"op":"mcm","clk":"11541227880","pt":1719503573519,"mc":[{"id":"1.230178322","rc":[{"atb":[[5.1,2]],"id":47885365},{"atb":[[1.13,0.27]],"id":68274051},{"atb":[[6.4,1.12]],"id":60192591}],"con":true,"img":false}]}
{"op":"mcm","clk":"11541227892","pt":1719503573623,"mc":[{"id":"1.230178322","rc":[{"atb":[[6.2,0]],"id":60192591}],"con":true,"img":false}]}
{"op":"mcm","clk":"11541227900","pt":1719503573725,"mc":[{"id":"1.230178322","rc":[{"atb":[[3.15,0]],"id":51569790},{"atb":[[6.6,2]],"id":60192591}],"con":true,"img":false}]}
{"op":"mcm","clk":"11541227948","pt":1719503574243,"mc":[{"id":"1.230178322","rc":[{"atb":[[3.2,0]],"id":51569790}],"con":true,"img":false}]}
{"op":"mcm","clk":"11541228015","pt":1719503574935,"mc":[{"id":"1.230178322","rc":[{"atb":[[6.4,0.84]],"id":60192591}],"con":true,"img":false}]}
{"op":"mcm","clk":"11541228023","pt":1719503575038,"mc":[{"id":"1.230178322","rc":[{"atb":[[1.13,0.27]],"id":60192591}],"con":true,"img":false}]}
{"op":"mcm","clk":"11541228143","pt":1719503576229,"mc":[{"id":"1.230178322","rc":[{"atb":[[6.6,0]],"id":60192591}],"con":true,"img":false}]}
{"op":"mcm","clk":"11541228152","pt":1719503576333,"mc":[{"id":"1.230178322","rc":[{"atl":[[4.9,1.48]],"id":51569790},{"atb":[[6.2,2]],"id":60192591}],"con":true,"img":false}]}
{"op":"mcm","clk":"11541228190","pt":1719503576645,"mc":[{"id":"1.230178322","rc":[{"atb":[[3.2,18.59]],"id":51569790}],"con":true,"img":false}]}
{"op":"mcm","clk":"11541228246","pt":1719503577110,"mc":[{"id":"1.230178322","rc":[{"atb":[[2.94,6.11]],"id":63650892},{"atb":[[3.1,12.97]],"id":51569790}],"con":true,"img":false}]}
{"op":"mcm","clk":"11541228258","pt":1719503577213,"mc":[{"id":"1.230178322","rc":[{"atb":[[3.25,1.65]],"id":51569790}],"con":true,"img":false}]}
{"op":"mcm","clk":"11541228269","pt":1719503577318,"mc":[{"id":"1.230178322","rc":[{"atb":[[3.05,0]],"id":63650892}],"con":true,"img":false}]}
{"op":"mcm","clk":"11541228311","pt":1719503577832,"mc":[{"id":"1.230178322","rc":[{"atb":[[3.1,12.7]],"id":51569790},{"atb":[[1.13,0]],"id":60192591}],"con":true,"img":false}]}
{"op":"mcm","clk":"11541228325","pt":1719503577938,"mc":[{"id":"1.230178322","rc":[{"atb":[[3.25,1.92]],"id":51569790},{"atb":[[6.2,2.27]],"id":60192591}],"con":true,"img":false}]}
{"op":"mcm","clk":"11541228354","pt":1719503578351,"mc":[{"id":"1.230178322","rc":[{"atb":[[3.3,6.35]],"id":51569790}],"con":true,"img":false}]}
{"op":"mcm","clk":"11541228406","pt":1719503578922,"mc":[{"id":"1.230178322","rc":[{"atb":[[3.25,0.27]],"id":51569790}],"con":true,"img":false}]}
{"op":"mcm","clk":"11541228415","pt":1719503579025,"mc":[{"id":"1.230178322","rc":[{"atb":[[3.35,1.65]],"id":51569790}],"con":true,"img":false}]}
{"op":"mcm","clk":"11541228457","pt":1719503579548,"mc":[{"id":"1.230178322","rc":[{"atb":[[3.3,0]],"id":51569790}],"con":true,"img":false}]}
{"op":"mcm","clk":"11541228507","pt":1719503580161,"mc":[{"id":"1.230178322","rc":[{"atb":[[3.35,0]],"id":51569790}],"con":true,"img":false}]}
{"op":"mcm","clk":"11541228515","pt":1719503580267,"mc":[{"id":"1.230178322","rc":[{"atb":[[3.25,1.92]],"id":51569790}],"con":true,"img":false}]}
{"op":"mcm","clk":"11541228567","pt":1719503580734,"mc":[{"id":"1.230178322","rc":[{"atb":[[3.3,7.19]],"id":51569790}],"con":true,"img":false}]}
{"op":"mcm","clk":"11541228634","pt":1719503581356,"mc":[{"id":"1.230178322","rc":[{"atb":[[2.92,0]],"id":63650892}],"con":true,"img":false}]}
{"op":"mcm","clk":"11541228665","pt":1719503581615,"mc":[{"id":"1.230178322","rc":[{"atb":[[2.24,10.24]],"id":60192591}],"con":true,"img":false}]}
{"op":"mcm","clk":"11541228699","pt":1719503581926,"mc":[{"id":"1.230178322","rc":[{"atb":[[2.36,9.33]],"id":47885365}],"con":true,"img":false}]}
{"op":"mcm","clk":"11541229422","pt":1719503588954,"mc":[{"id":"1.230178322","rc":[{"atb":[[2.32,0]],"id":47885365},{"atb":[[2.2,0]],"id":51569790},{"atb":[[2.2,0]],"id":60192591}],"con":true,"img":false}]}
{"op":"mcm","clk":"11541229435","pt":1719503589055,"mc":[{"id":"1.230178322","rc":[{"atb":[[2.36,21]],"id":47885365},{"atb":[[2.24,12.82]],"id":51569790},{"atb":[[2.24,23.45]],"id":60192591}],"con":true,"img":false}]}
{"op":"mcm","clk":"11541229501","pt":1719503589627,"mc":[{"id":"1.230178322","rc":[{"atb":[[3.25,1.65]],"id":51569790}],"con":true,"img":false}]}
{"op":"mcm","clk":"11541229514","pt":1719503589730,"mc":[{"id":"1.230178322","rc":[{"atb":[[3.35,0.27]],"id":51569790}],"con":true,"img":false}]}
{"op":"mcm","clk":"11541229536","pt":1719503589935,"mc":[{"id":"1.230178322","rc":[{"atb":[[1.03,9.59]],"id":70681333},{"atl":[[1000,1.7]],"id":70681333},{"atb":[[1.03,1.7]],"id":63650892},{"atl":[[1000,2.16]],"id":63650892},{"atb":[[1.03,9.59]],"id":51569790},{"atl":[[1000,1.7]],"id":51569790}],"con":true,"img":false}]}
{"op":"mcm","clk":"11541229556","pt":1719503590142,"mc":[{"id":"1.230178322","rc":[{"atb":[[1.03,7.99]],"id":70681333},{"atl":[[1000,0.01]],"id":70681333},{"atb":[[1.03,0.11]],"id":63650892},{"atl":[[1000,0.48]],"id":63650892},{"atb":[[1.03,7.97]],"id":51569790},{"atl":[[1000,0.04]],"id":51569790}],"con":true,"img":false}]}
{"op":"mcm","clk":"11541229578","pt":1719503590351,"mc":[{"id":"1.230178322","rc":[{"atb":[[1.03,7.89]],"id":70681333},{"atl":[[1000,0]],"id":70681333},{"atb":[[1.03,0]],"id":63650892},{"atl":[[1000,0.46]],"id":63650892},{"atb":[[1.03,7.89]],"id":51569790},{"atl":[[1000,0]],"id":51569790}],"con":true,"img":false}]}
{"op":"mcm","clk":"11541229589","pt":1719503590453,"mc":[{"id":"1.230178322","rc":[{"atb":[[4.1,0.36]],"id":70681333},{"atl":[[29,0.85]],"id":70681333},{"atb":[[3.75,0.11]],"id":63650892},{"atl":[[21,0.01]],"id":63650892},{"atb":[[3.35,0.35]],"id":51569790},{"atl":[[4.9,1.53]],"id":51569790}],"con":true,"img":false}]}
{"op":"mcm","clk":"11541229706","pt":1719503591635,"mc":[{"id":"1.230178322","rc":[{"atl":[[4.9,0.89]],"id":51569790}],"con":true,"img":false}]}
{"op":"mcm","clk":"11541229738","pt":1719503592046,"mc":[{"id":"1.230178322","rc":[{"atb":[[2.84,0],[3.2,19.59]],"id":51569790},{"atl":[[4.8,0.64]],"id":51569790}],"con":true,"img":false}]}
{"op":"mcm","clk":"11541229847","pt":1719503593128,"mc":[{"id":"1.230178322","rc":[{"atb":[[2.9,0]],"id":51569790}],"con":true,"img":false}]}
{"op":"mcm","clk":"11541229973","pt":1719503594522,"mc":[{"id":"1.230178322","rc":[{"atb":[[2.46,8.11]],"id":68274051}],"con":true,"img":false}]}
{"op":"mcm","clk":"11541230618","pt":1719503601547,"mc":[{"id":"1.230178322","rc":[{"atb":[[3.35,0]],"id":51569790},{"trd":[[3.35,1.07]],"ltp":3.35,"tv":1.07,"id":51569790}],"con":true,"img":false}]}
{"op":"mcm","clk":"11541230645","pt":1719503601752,"mc":[{"id":"1.230178322","rc":[{"atb":[[2.98,4.56]],"id":51569790}],"con":true,"img":false}]}
{"op":"mcm","clk":"11541230842","pt":1719503603359,"mc":[{"id":"1.230178322","rc":[{"atb":[[2.98,0]],"id":51569790}],"con":true,"img":false}]}
{"op":"mcm","clk":"11541231167","pt":1719503606367,"mc":[{"id":"1.230178322","rc":[{"atb":[[3.5,3.14]],"id":51569790}],"con":true,"img":false}]}
{"op":"mcm","clk":"11541231205","pt":1719503606776,"mc":[{"id":"1.230178322","rc":[{"atb":[[3.3,6.35]],"id":51569790}],"con":true,"img":false}]}
{"op":"mcm","clk":"11541231226","pt":1719503606981,"mc":[{"id":"1.230178322","rc":[{"atb":[[3.3,0]],"id":51569790}],"con":true,"img":false}]}
{"op":"mcm","clk":"11541231245","pt":1719503607186,"mc":[{"id":"1.230178322","rc":[{"atb":[[3.25,0]],"id":51569790}],"con":true,"img":false}]}
{"op":"mcm","clk":"11541231258","pt":1719503607290,"mc":[{"id":"1.230178322","rc":[{"atl":[[4.8,0]],"id":51569790}],"con":true,"img":false}]}
{"op":"mcm","clk":"11541231327","pt":1719503608063,"mc":[{"id":"1.230178322","rc":[{"spn":16.5,"spf":"NaN","id":70681333},{"spn":72.6,"spf":"NaN","id":47885365},{"atb":[[3.7,1]],"id":63650892},{"spn":4.2,"spf":"NaN","id":51569790},{"spn":68.2,"spf":"NaN","id":60192591}],"con":true,"img":false}]}
{"op":"mcm","clk":"11541231726","pt":1719503612186,"mc":[{"id":"1.230178322","rc":[{"atl":[[9,2.9],[10.5,0]],"id":51569790}],"con":true,"img":false}]}
{"op":"mcm","clk":"11541231773","pt":1719503612650,"mc":[{"id":"1.230178322","rc":[{"atb":[[3.5,0]],"id":51569790},{"trd":[[3.5,11.99]],"ltp":3.5,"tv":11.99,"id":51569790}],"con":true,"img":false}]}
{"op":"mcm","clk":"11541231801","pt":1719503612962,"mc":[{"id":"1.230178322","rc":[{"atb":[[2.16,0]],"id":51569790}],"con":true,"img":false}]}
{"op":"mcm","clk":"11541231831","pt":1719503613270,"mc":[{"id":"1.230178322","rc":[{"atb":[[3.25,2.49]],"id":51569790}],"con":true,"img":false}]}
{"op":"mcm","clk":"11541231886","pt":1719503613926,"mc":[{"id":"1.230178322","rc":[{"atb":[[3.3,6.35]],"id":51569790}],"con":true,"img":false}]}
{"op":"mcm","clk":"11541231949","pt":1719503614555,"mc":[{"id":"1.230178322","rc":[{"atb":[[3.25,0.84]],"id":51569790}],"con":true,"img":false}]}
{"op":"mcm","clk":"11541231961","pt":1719503614657,"mc":[{"id":"1.230178322","rc":[{"atb":[[3.35,1.65]],"id":51569790}],"con":true,"img":false}]}
{"op":"mcm","clk":"11541231991","pt":1719503614964,"mc":[{"id":"1.230178322","rc":[{"atb":[[3.3,0]],"id":51569790}],"con":true,"img":false}]}
{"op":"mcm","clk":"11541232060","pt":1719503615786,"mc":[{"id":"1.230178322","rc":[{"atb":[[3.35,0]],"id":51569790}],"con":true,"img":false}]}
{"op":"mcm","clk":"11541232069","pt":1719503615888,"mc":[{"id":"1.230178322","rc":[{"atb":[[3.25,2.49]],"id":51569790}],"con":true,"img":false}]}
{"op":"mcm","clk":"11541232088","pt":1719503616094,"mc":[{"id":"1.230178322","rc":[{"atb":[[3.3,6.35]],"id":51569790}],"con":true,"img":false}]}
{"op":"mcm","clk":"11541232176","pt":1719503617273,"mc":[{"id":"1.230178322","rc":[{"atl":[[9,0],[10.5,8]],"id":51569790}],"con":true,"img":false}]}
{"op":"mcm","clk":"11541232200","pt":1719503617581,"mc":[{"id":"1.230178322","rc":[{"atb":[[2.96,6.47]],"id":63650892}],"con":true,"img":false}]}
{"op":"mcm","clk":"11541232223","pt":1719503617890,"mc":[{"id":"1.230178322","rc":[{"atb":[[3.25,5.51]],"id":51569790}],"con":true,"img":false}]}
{"op":"mcm","clk":"11541232459","pt":1719503620268,"mc":[{"id":"1.230178322","rc":[{"atl":[[4.9,1.53]],"id":51569790}],"con":true,"img":false}]}
{"op":"mcm","clk":"11541232471","pt":1719503620402,"mc":[{"id":"1.230178322","rc":[{"atb":[[3.35,0.84]],"id":51569790}],"con":true,"img":false}]}
{"op":"mcm","clk":"11541232514","pt":1719503620764,"mc":[{"id":"1.230178322","rc":[{"atb":[[3.3,0]],"id":51569790}],"con":true,"img":false}]}
{"op":"mcm","clk":"11541232563","pt":1719503621279,"mc":[{"id":"1.230178322","rc":[{"atb":[[3.35,0]],"id":51569790}],"con":true,"img":false}]}
{"op":"mcm","clk":"11541232584","pt":1719503621486,"mc":[{"id":"1.230178322","rc":[{"atb":[[3.3,6.35]],"id":51569790}],"con":true,"img":false}]}
{"op":"mcm","clk":"11541232696","pt":1719503622873,"mc":[{"id":"1.230178322","rc":[{"atb":[[2.64,5.3]],"id":51569790}],"con":true,"img":false}]}
{"op":"mcm","clk":"11541233113","pt":1719503627775,"mc":[{"id":"1.230178322","rc":[{"atb":[[3.35,0.84]],"id":51569790}],"con":true,"img":false}]}
{"op":"mcm","clk":"11541233136","pt":1719503628085,"mc":[{"id":"1.230178322","rc":[{"atb":[[3.3,0]],"id":51569790}],"con":true,"img":false}]}
{"op":"mcm","clk":"11541233184","pt":1719503628803,"mc":[{"id":"1.230178322","rc":[{"atb":[[3.35,0]],"id":51569790}],"con":true,"img":false}]}
{"op":"mcm","clk":"11541233196","pt":1719503628906,"mc":[{"id":"1.230178322","rc":[{"atb":[[4.1,0.26]],"id":70681333},{"atl":[[29,0.84]],"id":70681333},{"atb":[[2.34,0]],"id":47885365},{"atb":[[2.94,0],[3.75,0]],"id":63650892},{"atl":[[21,0]],"id":63650892},{"atb":[[2.22,0]],"id":51569790},{"atl":[[4.9,1.48]],"id":51569790},{"atb":[[2.22,0]],"id":60192591}],"con":true,"img":false}]}
{"op":"mcm","clk":"11541233229","pt":1719503629266,"mc":[{"id":"1.230178322","rc":[{"atb":[[3.3,6.35]],"id":51569790}],"con":true,"img":false}]}
{"op":"mcm","clk":"11541233258","pt":1719503629574,"mc":[{"id":"1.230178322","rc":[{"atb":[[3.2,18.59]],"id":51569790}],"con":true,"img":false}]}
{"op":"mcm","clk":"11541233358","pt":1719503630703,"mc":[{"id":"1.230178322","rc":[{"atb":[[4,7]],"id":70681333},{"atl":[[11.5,1]],"id":70681333},{"atb":[[4.9,7]],"id":47885365},{"atl":[[18.5,1]],"id":47885365},{"atb":[[3.3,6.7]],"id":63650892},{"atl":[[8.8,1]],"id":63650892},{"atb":[[2.62,1]],"id":68274051},{"atl":[[6.4,1]],"id":68274051},{"atl":[[17.5,1]],"id":60192591}],"con":true,"img":false}]}
{"op":"mcm","clk":"11541233372","pt":1719503630807,"mc":[{"id":"1.230178322","rc":[{"atb":[[4.9,1],[5,9]],"id":47885365},{"atl":[[9,1]],"id":63650892},{"atl":[[18.5,2.84],[19.5,0.48]],"id":68274051},{"atl":[[9.2,3.49],[10.5,0]],"id":51569790},{"atb":[[4.4,0],[4.7,13.21]],"id":60192591}],"con":true,"img":false}]}
{"op":"mcm","clk":"11541233417","pt":1719503631171,"mc":[{"id":"1.230178322","rc":[{"atl":[[19.5,0]],"id":68274051}],"con":true,"img":false}]}
{"op":"mcm","clk":"11541233433","pt":1719503631272,"mc":[{"id":"1.230178322","rc":[{"atl":[[1000,0.71]],"id":68274051}],"con":true,"img":false}]}
{"op":"mcm","clk":"11541233514","pt":1719503632102,"mc":[{"id":"1.230178322","rc":[{"atl":[[18,1.59]],"id":47885365},{"atb":[[2.98,1]],"id":51569790}],"con":true,"img":false}]}
{"op":"mcm","clk":"11541233531","pt":1719503632309,"mc":[{"id":"1.230178322","rc":[{"atl":[[140,0.84],[29,3.57]],"id":47885365}],"con":true,"img":false}]}
{"op":"mcm","clk":"11541233705","pt":1719503634113,"mc":[{"id":"1.230178322","rc":[{"atb":[[2.26,11.5]],"id":51569790}],"con":true,"img":false}]}
{"op":"mcm","clk":"11541233722","pt":1719503634167,"mc":[{"id":"1.230178322","rc":[{"atb":[[2.38,8.59]],"id":47885365}],"con":true,"img":false}]}
{"op":"mcm","clk":"11541233734","pt":1719503634269,"mc":[{"id":"1.230178322","rc":[{"atb":[[2.26,9.4]],"id":60192591}],"con":true,"img":false}]}
{"op":"mcm","clk":"11541233750","pt":1719503634474,"mc":[{"id":"1.230178322","rc":[{"atb":[[3.25,8.32]],"id":51569790}],"con":true,"img":false}]}
{"op":"mcm","clk":"11541233773","pt":1719503634682,"mc":[{"id":"1.230178322","rc":[{"atb":[[2.98,0]],"id":51569790}],"con":true,"img":false}]}
{"op":"mcm","clk":"11541233788","pt":1719503634892,"mc":[{"id":"1.230178322","rc":[{"atb":[[3.35,0.84]],"id":51569790}],"con":true,"img":false}]}
{"op":"mcm","clk":"11541233842","pt":1719503635405,"mc":[{"id":"1.230178322","rc":[{"atb":[[3.3,0]],"id":51569790}],"con":true,"img":false}]}
{"op":"mcm","clk":"11541233863","pt":1719503635613,"mc":[{"id":"1.230178322","rc":[{"atl":[[4.9,0.84]],"id":51569790}],"con":true,"img":false}]}
{"op":"mcm","clk":"11541233893","pt":1719503635870,"mc":[{"id":"1.230178322","rc":[{"atb":[[3.35,0]],"id":51569790}],"con":true,"img":false}]}
{"op":"mcm","clk":"11541233901","pt":1719503635975,"mc":[{"id":"1.230178322","rc":[{"atb":[[3.3,6.35]],"id":51569790}],"con":true,"img":false}]}
{"op":"mcm","clk":"11541234224","pt":1719503639383,"mc":[{"id":"1.230178322","rc":[{"atb":[[2.98,1]],"id":51569790}],"con":true,"img":false}]}
{"op":"mcm","clk":"11541234349","pt":1719503640723,"mc":[{"id":"1.230178322","rc":[{"atl":[[6.4,0],[6.2,1]],"id":68274051}],"con":true,"img":false}]}
{"op":"mcm","clk":"11541234357","pt":1719503640825,"mc":[{"id":"1.230178322","rc":[{"atl":[[8.8,0]],"id":63650892}],"con":true,"img":false}]}
{"op":"mcm","clk":"11541234492","pt":1719503641914,"mc":[{"id":"1.230178322","rc":[{"atb":[[3.35,0.84]],"id":51569790}],"con":true,"img":false}]}
{"op":"mcm","clk":"11541234508","pt":1719503642122,"mc":[{"id":"1.230178322","rc":[{"atb":[[2.98,0]],"id":51569790}],"con":true,"img":false}]}
{"op":"mcm","clk":"11541234566","pt":1719503642593,"mc":[{"id":"1.230178322","rc":[{"atb":[[3.3,0]],"id":51569790}],"con":true,"img":false}]}
{"op":"mcm","clk":"11541234643","pt":1719503643415,"mc":[{"id":"1.230178322","rc":[{"atb":[[3.35,0]],"id":51569790}],"con":true,"img":false}]}
{"op":"mcm","clk":"11541234670","pt":1719503643675,"mc":[{"id":"1.230178322","rc":[{"atb":[[3.3,6.35]],"id":51569790}],"con":true,"img":false}]}
{"op":"mcm","clk":"11541235159","pt":1719503648907,"mc":[{"id":"1.230178322","rc":[{"atl":[[11.5,0]],"id":70681333},{"trd":[[11.5,2]],"ltp":11.5,"tv":2.0,"id":70681333},{"atb":[[2.64,0]],"id":51569790}],"con":true,"img":false}]}
{"op":"mcm","clk":"11541235180","pt":1719503649113,"mc":[{"id":"1.230178322","rc":[{"atb":[[3.3,7.55]],"id":51569790},{"atl":[[4.9,1.48]],"id":51569790}],"con":true,"img":false}]}
{"op":"mcm","clk":"11541235194","pt":1719503649219,"mc":[{"id":"1.230178322","rc":[{"atb":[[3.35,0.84]],"id":51569790}],"con":true,"img":false}]}
{"op":"mcm","clk":"11541235262","pt":1719503649786,"mc":[{"id":"1.230178322","rc":[{"atb":[[3.3,1.2]],"id":51569790}],"con":true,"img":false}]}
{"op":"mcm","clk":"11541235311","pt":1719503650303,"mc":[{"id":"1.230178322","rc":[{"atb":[[3.3,0]],"id":51569790}],"con":true,"img":false}]}
{"op":"mcm","clk":"11541235322","pt":1719503650406,"mc":[{"id":"1.230178322","rc":[{"atb":[[3.25,9.52]],"id":51569790}],"con":true,"img":false}]}
{"op":"mcm","clk":"11541235355","pt":1719503650716,"mc":[{"id":"1.230178322","rc":[{"atl":[[6.4,1],[6.2,0]],"id":68274051},{"atb":[[3.35,0]],"id":51569790}],"con":true,"img":false}]}
{"op":"mcm","clk":"11541235386","pt":1719503651024,"mc":[{"id":"1.230178322","rc":[{"atb":[[3.3,6.35]],"id":51569790}],"con":true,"img":false}]}
{"op":"mcm","clk":"11541235442","pt":1719503651386,"mc":[{"id":"1.230178322","rc":[{"atb":[[1.09,1]],"id":70681333},{"atl":[[1000,0.04]],"id":70681333}],"con":true,"img":false}]}
{"op":"mcm","clk":"11541235466","pt":1719503651594,"mc":[{"id":"1.230178322","rc":[{"atb":[[1.09,0.24],[2.16,18.11]],"id":70681333},{"atl":[[1000,0]],"id":70681333},{"atb":[[2.98,5.99]],"id":63650892},{"atb":[[3.25,8.32]],"id":51569790}],"con":true,"img":false}]}
{"op":"mcm","clk":"11541235480","pt":1719503651695,"mc":[{"id":"1.230178322","rc":[{"atl":[[28,0.88]],"id":70681333},{"atb":[[3.3,7.55]],"id":51569790}],"con":true,"img":false}]}
{"op":"mcm","clk":"11541235492","pt":1719503651799,"mc":[{"id":"1.230178322","rc":[{"atb":[[1.09,0]],"id":70681333},{"atb":[[2.38,10.88]],"id":68274051}],"con":true,"img":false}]}
{"op":"mcm","clk":"11541235504","pt":1719503651902,"mc":[{"id":"1.230178322","rc":[{"atb":[[5.1,0.24]],"id":70681333}],"con":true,"img":false}]}
{"op":"mcm","clk":"11541235517","pt":1719503652005,"mc":[{"id":"1.230178322","rc":[{"atb":[[2.16,27.51]],"id":63650892},{"atb":[[2.62,5.36]],"id":51569790}],"con":true,"img":false}]}
{"op":"mcm","clk":"11541235548","pt":1719503652214,"mc":[{"id":"1.230178322","rc":[{"atb":[[2.44,6.58]],"id":51569790}],"con":true,"img":false}]}
{"op":"mcm","clk":"11541235596","pt":1719503652628,"mc":[{"id":"1.230178322","rc":[{"atb":[[3.25,5.51]],"id":51569790}],"con":true,"img":false}]}
{"op":"mcm","clk":"11541235964","pt":1719503656294,"mc":[{"id":"1.230178322","rc":[{"atb":[[3.35,0.84]],"id":51569790}],"con":true,"img":false}]}
{"op":"mcm","clk":"11541235997","pt":1719503656706,"mc":[{"id":"1.230178322","rc":[{"atb":[[3.3,1.2]],"id":51569790}],"con":true,"img":false}]}
{"op":"mcm","clk":"11541236024","pt":1719503657013,"mc":[{"id":"1.230178322","rc":[{"atb":[[3.3,0]],"id":51569790}],"con":true,"img":false}]}
{"op":"mcm","clk":"11541236035","pt":1719503657118,"mc":[{"id":"1.230178322","rc":[{"atb":[[3.25,6.71]],"id":51569790}],"con":true,"img":false}]}
{"op":"mcm","clk":"11541236103","pt":1719503657891,"mc":[{"id":"1.230178322","rc":[{"atb":[[3.35,0]],"id":51569790}],"con":true,"img":false}]}
{"op":"mcm","clk":"11541236146","pt":1719503658307,"mc":[{"id":"1.230178322","rc":[{"atb":[[3.3,6.35]],"id":51569790}],"con":true,"img":false}]}
{"op":"mcm","clk":"11541236195","pt":1719503658724,"mc":[{"id":"1.230178322","rc":[{"atb":[[3.25,5.51]],"id":51569790}],"con":true,"img":false}]}
{"op":"mcm","clk":"11541236208","pt":1719503658826,"mc":[{"id":"1.230178322","rc":[{"atb":[[3.3,7.55]],"id":51569790}],"con":true,"img":false}]}
{"op":"mcm","clk":"11541236362","pt":1719503660426,"mc":[{"id":"1.230178322","rc":[{"atb":[[5.2,1.62]],"id":70681333},{"atb":[[6.6,1.28]],"id":60192591}],"con":true,"img":false}]}
{"op":"mcm","clk":"11541236386","pt":1719503660633,"mc":[{"id":"1.230178322","rc":[{"atb":[[4,3.5],[4.2,2]],"id":70681333}],"con":true,"img":false}]}
{"op":"mcm","clk":"11541236408","pt":1719503660839,"mc":[{"id":"1.230178322","rc":[{"atb":[[6.2,0.27]],"id":60192591}],"con":true,"img":false}]}
{"op":"mcm","clk":"11541236420","pt":1719503660940,"mc":[{"id":"1.230178322","rc":[{"atb":[[6.8,2]],"id":60192591}],"con":true,"img":false}]}
{"op":"mcm","clk":"11541236436","pt":1719503661097,"mc":[{"id":"1.230178322","rc":[{"atb":[[5.2,0]],"id":70681333},{"atb":[[6.6,0]],"id":60192591}],"con":true,"img":false}]}
{"op":"mcm","clk":"11541236447","pt":1719503661199,"mc":[{"id":"1.230178322","rc":[{"atb":[[4.1,0]],"id":70681333},{"atb":[[6.2,0],[7,0.84]],"id":60192591}],"con":true,"img":false}]}
{"op":"mcm","clk":"11541236459","pt":1719503661305,"mc":[{"id":"1.230178322","rc":[{"atb":[[1.13,0.26]],"id":70681333},{"atb":[[6.4,0],[1.13,0.27]],"id":60192591}],"con":true,"img":false}]}
{"op":"mcm","clk":"11541236471","pt":1719503661409,"mc":[{"id":"1.230178322","rc":[{"atb":[[5.1,1.86]],"id":70681333}],"con":true,"img":false}]}
{"op":"mcm","clk":"11541236502","pt":1719503661720,"mc":[{"id":"1.230178322","rc":[{"atb":[[5.2,0.84]],"id":70681333},{"atb":[[6.4,1.28]],"id":60192591}],"con":true,"img":false}]}
{"op":"mcm","clk":"11541236530","pt":1719503662033,"mc":[{"id":"1.230178322","rc":[{"atb":[[6.8,0],[7,2.05]],"id":60192591}],"con":true,"img":false}]}
{"op":"mcm","clk":"11541236543","pt":1719503662136,"mc":[{"id":"1.230178322","rc":[{"atb":[[6.2,2]],"id":60192591}],"con":true,"img":false}]}
{"op":"mcm","clk":"11541236568","pt":1719503662343,"mc":[{"id":"1.230178322","rc":[{"atb":[[6.4,0]],"id":60192591}],"con":true,"img":false}]}
{"op":"mcm","clk":"11541236657","pt":1719503663120,"mc":[{"id":"1.230178322","rc":[{"atb":[[6.2,0]],"id":60192591}],"con":true,"img":false}]}
{"op":"mcm","clk":"11541236669","pt":1719503663225,"mc":[{"id":"1.230178322","rc":[{"atb":[[7.2,2]],"id":60192591}],"con":true,"img":false}]}
{"op":"mcm","clk":"11541236724","pt":1719503663846,"mc":[{"id":"1.230178322","rc":[{"atb":[[3.35,0.84]],"id":51569790}],"con":true,"img":false}]}
{"op":"mcm","clk":"11541236783","pt":1719503664311,"mc":[{"id":"1.230178322","rc":[{"atb":[[3.3,1.2]],"id":51569790}],"con":true,"img":false}]}
{"op":"mcm","clk":"11541236797","pt":1719503664413,"mc":[{"id":"1.230178322","rc":[{"atl":[[4.9,0.84]],"id":51569790}],"con":true,"img":false}]}
{"op":"mcm","clk":"11541236838","pt":1719503664825,"mc":[{"id":"1.230178322","rc":[{"atb":[[3.3,0]],"id":51569790}],"con":true,"img":false}]}
{"op":"mcm","clk":"11541236850","pt":1719503664929,"mc":[{"id":"1.230178322","rc":[{"atb":[[3.25,6.71]],"id":51569790}],"con":true,"img":false}]}
{"op":"mcm","clk":"11541236880","pt":1719503665238,"mc":[{"id":"1.230178322","rc":[{"atb":[[3.35,0]],"id":51569790}],"con":true,"img":false}]}
{"op":"mcm","clk":"11541236891","pt":1719503665344,"mc":[{"id":"1.230178322","rc":[{"atl":[[4.9,1.48]],"id":51569790}],"con":true,"img":false}]}
{"op":"mcm","clk":"11541236902","pt":1719503665444,"mc":[{"id":"1.230178322","rc":[{"atb":[[3.3,6.35]],"id":51569790}],"con":true,"img":false}]}
{"op":"mcm","clk":"11541236953","pt":1719503665911,"mc":[{"id":"1.230178322","rc":[{"atb":[[4.1,1.79]],"id":70681333},{"atb":[[5.2,1.63]],"id":47885365},{"atb":[[3.7,3.18]],"id":63650892},{"atb":[[2.66,6.66]],"id":68274051}],"con":true,"img":false}]}
{"op":"mcm","clk":"11541236965","pt":1719503666013,"mc":[{"id":"1.230178322","rc":[{"atb":[[5,3],[5.2,3.64]],"id":47885365},{"atb":[[3.25,5.51]],"id":51569790}],"con":true,"img":false}]}
{"op":"mcm","clk":"11541236976","pt":1719503666116,"mc":[{"id":"1.230178322","rc":[{"atb":[[3.3,7.55]],"id":51569790}],"con":true,"img":false}]}
{"op":"mcm","clk":"11541237013","pt":1719503666527,"mc":[{"id":"1.230178322","rc":[{"atb":[[5.3,4.79]],"id":47885365},{"atb":[[2.66,7.87]],"id":68274051}],"con":true,"img":false}]}
{"op":"mcm","clk":"11541237058","pt":1719503667040,"mc":[{"id":"1.230178322","rc":[{"atl":[[28,0.84]],"id":70681333},{"atb":[[5.1,0]],"id":47885365},{"atl":[[5,0]],"id":51569790}],"con":true,"img":false}]}
{"op":"mcm","clk":"11541237066","pt":1719503667142,"mc":[{"id":"1.230178322","rc":[{"atb":[[5.1,1.62]],"id":70681333},{"atb":[[5.4,2]],"id":47885365},{"atl":[[4.5,2]],"id":51569790}],"con":true,"img":false}]}
{"op":"mcm","clk":"11541237073","pt":1719503667246,"mc":[{"id":"1.230178322","rc":[{"atb":[[5.4,2.85]],"id":47885365}],"con":true,"img":false}]}
{"op":"mcm","clk":"11541237086","pt":1719503667349,"mc":[{"id":"1.230178322","rc":[{"atb":[[1.09,1]],"id":70681333},{"atl":[[1000,0.04]],"id":70681333}],"con":true,"img":false}]}
{"op":"mcm","clk":"11541237104","pt":1719503667504,"mc":[{"id":"1.230178322","rc":[{"atb":[[1.09,0.24]],"id":70681333},{"atl":[[1000,0]],"id":70681333}],"con":true,"img":false}]}
{"op":"mcm","clk":"11541237114","pt":1719503667606,"mc":[{"id":"1.230178322","rc":[{"atl":[[28,0.88]],"id":70681333},{"atb":[[5.3,0]],"id":47885365}],"con":true,"img":false}]}
{"op":"mcm","clk":"11541237130","pt":1719503667813,"mc":[{"id":"1.230178322","rc":[{"atb":[[1.09,0]],"id":70681333},{"atl":[[4.4,0.84]],"id":51569790}],"con":true,"img":false}]}
{"op":"mcm","clk":"11541237142","pt":1719503667915,"mc":[{"id":"1.230178322","rc":[{"atb":[[5.2,1.08]],"id":70681333},{"atb":[[5.2,2.8]],"id":47885365},{"atl":[[4.9,0.64]],"id":51569790}],"con":true,"img":false}]}
{"op":"mcm","clk":"11541237161","pt":1719503668121,"mc":[{"id":"1.230178322","rc":[{"atb":[[5.3,1.6]],"id":70681333},{"spn":16.65,"spf":"NaN","id":70681333},{"atb":[[5.4,1.1]],"id":47885365},{"spn":11.7,"spf":"NaN","id":47885365},{"spn":6.85,"spf":"NaN","id":63650892},{"spn":3.85,"spf":"NaN","id":51569790},{"spn":12.35,"spf":"NaN","id":60192591}],"con":true,"img":false}]}
{"op":"mcm","clk":"11541237169","pt":1719503668224,"mc":[{"id":"1.230178322","rc":[{"atb":[[5.1,0]],"id":70681333},{"atb":[[7.4,0.84]],"id":60192591}],"con":true,"img":false}]}
{"op":"mcm","clk":"11541237193","pt":1719503668531,"mc":[{"id":"1.230178322","rc":[{"atb":[[5.4,0.84]],"id":47885365}],"con":true,"img":false}]}
{"op":"mcm","clk":"11541237203","pt":1719503668638,"mc":[{"id":"1.230178322","rc":[{"atb":[[5.3,1.74],[1.13,0.26]],"id":47885365}],"con":true,"img":false}]}
{"op":"mcm","clk":"11541237222","pt":1719503668840,"mc":[{"id":"1.230178322","rc":[{"atb":[[5.4,0]],"id":47885365}],"con":true,"img":false}]}
{"op":"mcm","clk":"11541237266","pt":1719503669306,"mc":[{"id":"1.230178322","rc":[{"atb":[[5.3,0]],"id":47885365}],"con":true,"img":false}]}
{"op":"mcm","clk":"11541237378","pt":1719503670643,"mc":[{"id":"1.230178322","rc":[{"atl":[[980,1.62]],"id":51569790}],"con":true,"img":false}]}
{"op":"mcm","clk":"11541237418","pt":1719503671157,"mc":[{"id":"1.230178322","rc":[{"atb":[[5,8.6],[5.2,0.79]],"id":47885365}],"con":true,"img":false}]}
{"op":"mcm","clk":"11541237427","pt":1719503671210,"mc":[{"id":"1.230178322","rc":[{"atb":[[4.9,6.8],[5,3]],"id":47885365},{"atb":[[1.02,216.22]],"id":51569790}],"con":true,"img":false}]}
{"op":"mcm","clk":"11541237434","pt":1719503671314,"mc":[{"id":"1.230178322","rc":[{"atb":[[1.13,0]],"id":47885365},{"atb":[[3.35,0.84]],"id":51569790}],"con":true,"img":false}]}
{"op":"mcm","clk":"11541237443","pt":1719503671417,"mc":[{"id":"1.230178322","rc":[{"atb":[[5.1,0.26]],"id":47885365}],"con":true,"img":false}]}
{"op":"mcm","clk":"11541237461","pt":1719503671625,"mc":[{"id":"1.230178322","rc":[{"atb":[[5.1,2]],"id":47885365},{"atb":[[3.3,1.2]],"id":51569790}],"con":true,"img":false}]}
{"op":"mcm","clk":"11541237479","pt":1719503671833,"mc":[{"id":"1.230178322","rc":[{"atb":[[1.02,270.41]],"id":70681333},{"atb":[[5.2,5.67]],"id":47885365},{"atb":[[3.3,0]],"id":51569790}],"con":true,"img":false}]}
{"op":"mcm","clk":"11541237490","pt":1719503671935,"mc":[{"id":"1.230178322","rc":[{"atb":[[3.25,6.71]],"id":51569790}],"con":true,"img":false}]}
{"op":"mcm","clk":"11541237508","pt":1719503672141,"mc":[{"id":"1.230178322","rc":[{"atl":[[24,3.57],[29,0]],"id":47885365},{"atl":[[7.8,2]],"id":51569790}],"con":true,"img":false}]}
{"op":"mcm","clk":"11541237518","pt":1719503672244,"mc":[{"id":"1.230178322","rc":[{"atl":[[9.2,0]],"id":51569790}],"con":true,"img":false}]}
{"op":"mcm","clk":"11541237523","pt":1719503672346,"mc":[{"id":"1.230178322","rc":[{"atb":[[5.1,0.26]],"id":47885365},{"atb":[[3.35,0]],"id":51569790}],"con":true,"img":false}]}
{"op":"mcm","clk":"11541237532","pt":1719503672448,"mc":[{"id":"1.230178322","rc":[{"atl":[[970,2.21]],"id":70681333},{"atb":[[5.3,1.74]],"id":47885365}],"con":true,"img":false}]}
{"op":"mcm","clk":"11541237563","pt":1719503672758,"mc":[{"id":"1.230178322","rc":[{"atb":[[5.2,0.79]],"id":47885365}],"con":true,"img":false}]}
{"op":"mcm","clk":"11541237578","pt":1719503672863,"mc":[{"id":"1.230178322","rc":[{"atb":[[5.1,0]],"id":47885365}],"con":true,"img":false}]}
{"op":"mcm","clk":"11541237594","pt":1719503672917,"mc":[{"id":"1.230178322","rc":[{"atb":[[5.3,0.26]],"id":47885365},{"atb":[[3.3,6.35]],"id":51569790}],"con":true,"img":false}]}
{"op":"mcm","clk":"11541237609","pt":1719503673019,"mc":[{"id":"1.230178322","rc":[{"atb":[[5.1,1.74]],"id":47885365},{"atl":[[970,1.98]],"id":63650892}],"con":true,"img":false}]}
{"op":"mcm","clk":"11541237686","pt":1719503673743,"mc":[{"id":"1.230178322","rc":[{"atb":[[3.25,5.51]],"id":51569790}],"con":true,"img":false}]}
{"op":"mcm","clk":"11541237695","pt":1719503673845,"mc":[{"id":"1.230178322","rc":[{"atb":[[3.3,7.55]],"id":51569790}],"con":true,"img":false}]}
{"op":"mcm","clk":"11541237733","pt":1719503674258,"mc":[{"id":"1.230178322","rc":[{"atl":[[960,2.54]],"id":47885365}],"con":true,"img":false}]}
{"op":"mcm","clk":"11541237744","pt":1719503674360,"mc":[{"id":"1.230178322","rc":[{"atb":[[5.3,0]],"id":47885365}],"con":true,"img":false}]}
{"op":"mcm","clk":"11541237755","pt":1719503674461,"mc":[{"id":"1.230178322","rc":[{"atb":[[5,3.26]],"id":47885365}],"con":true,"img":false}]}
{"op":"mcm","clk":"11541237765","pt":1719503674515,"mc":[{"id":"1.230178322","rc":[{"atb":[[5.2,5.67]],"id":47885365}],"con":true,"img":false}]}
{"op":"mcm","clk":"11541237788","pt":1719503674720,"mc":[{"id":"1.230178322","rc":[{"atb":[[5.2,6.52]],"id":47885365}],"con":true,"img":false}]}
{"op":"mcm","clk":"11541237796","pt":1719503674821,"mc":[{"id":"1.230178322","rc":[{"atb":[[1.04,139.71]],"id":47885365}],"con":true,"img":false}]}
{"op":"mcm","clk":"11541237852","pt":1719503675442,"mc":[{"id":"1.230178322","rc":[{"atb":[[1.03,282.81]],"id":63650892}],"con":true,"img":false}]}
{"op":"mcm","clk":"11541238049","pt":1719503677552,"mc":[{"id":"1.230178322","rc":[{"atb":[[2.36,0]],"id":68274051}],"con":true,"img":false}]}
{"op":"mcm","clk":"11541238056","pt":1719503677653,"mc":[{"id":"1.230178322","rc":[{"atb":[[2.38,5.73]],"id":68274051}],"con":true,"img":false}]}
{"op":"mcm","clk":"11541238073","pt":1719503677860,"mc":[{"id":"1.230178322","rc":[{"atl":[[960,1.8]],"id":68274051}],"con":true,"img":false}]}
{"op":"mcm","clk":"11541238141","pt":1719503678427,"mc":[{"id":"1.230178322","rc":[{"atb":[[2.68,3.16]],"id":68274051},{"atb":[[3.35,0.84]],"id":51569790}],"con":true,"img":false}]}
{"op":"mcm","clk":"11541238178","pt":1719503678737,"mc":[{"id":"1.230178322","rc":[{"atb":[[1.13,0]],"id":68274051}],"con":true,"img":false}]}
{"op":"mcm","clk":"11541238189","pt":1719503678840,"mc":[{"id":"1.230178322","rc":[{"atb":[[2.7,2.1]],"id":68274051}],"con":true,"img":false}]}
{"op":"mcm","clk":"11541238210","pt":1719503679047,"mc":[{"id":"1.230178322","rc":[{"atb":[[2.66,6.66]],"id":68274051},{"atb":[[3.3,1.2]],"id":51569790}],"con":true,"img":false}]}
{"op":"mcm","clk":"11541238221","pt":1719503679148,"mc":[{"id":"1.230178322","rc":[{"atb":[[2.68,4.36]],"id":68274051}],"con":true,"img":false}]}
{"op":"mcm","clk":"11541238233","pt":1719503679251,"mc":[{"id":"1.230178322","rc":[{"atb":[[4.9,1],[5.2,9.78]],"id":47885365}],"con":true,"img":false}]}
{"op":"mcm","clk":"11541238289","pt":1719503679661,"mc":[{"id":"1.230178322","rc":[{"atb":[[3.3,0]],"id":51569790}],"con":true,"img":false}]}
{"op":"mcm","clk":"11541238302","pt":1719503679713,"mc":[{"id":"1.230178322","rc":[{"atb":[[3.25,6.71]],"id":51569790}],"con":true,"img":false}]}
{"op":"mcm","clk":"11541238350","pt":1719503680226,"mc":[{"id":"1.230178322","rc":[{"atl":[[970,1.06]],"id":60192591}],"con":true,"img":false}]}
{"op":"mcm","clk":"11541238361","pt":1719503680331,"mc":[{"id":"1.230178322","rc":[{"atb":[[3.35,0]],"id":51569790}],"con":true,"img":false}]}
{"op":"mcm","clk":"11541238401","pt":1719503680743,"mc":[{"id":"1.230178322","rc":[{"atb":[[3.3,6.35]],"id":51569790}],"con":true,"img":false}]}
{"op":"mcm","clk":"11541238410","pt":1719503680844,"mc":[{"id":"1.230178322","rc":[{"atl":[[4.9,0]],"id":51569790},{"atb":[[1.04,153.25]],"id":60192591}],"con":true,"img":false}]}
{"op":"mcm","clk":"11541238480","pt":1719503681461,"mc":[{"id":"1.230178322","rc":[{"atb":[[3.25,5.51]],"id":51569790}],"con":true,"img":false}]}
{"op":"mcm","clk":"11541238490","pt":1719503681563,"mc":[{"id":"1.230178322","rc":[{"atb":[[3.3,7.55]],"id":51569790}],"con":true,"img":false}]}
{"op":"mcm","clk":"11541238527","pt":1719503681925,"mc":[{"id":"1.230178322","rc":[{"atb":[[1.02,130.7]],"id":68274051}],"con":true,"img":false}]}
{"op":"mcm","clk":"11541238600","pt":1719503682855,"mc":[{"id":"1.230178322","rc":[{"atl":[[28,0.84]],"id":70681333}],"con":true,"img":false}]}
{"op":"mcm","clk":"11541238622","pt":1719503683061,"mc":[{"id":"1.230178322","rc":[{"atb":[[5.2,0.84]],"id":70681333}],"con":true,"img":false}]}
{"op":"mcm","clk":"11541238639","pt":1719503683266,"mc":[{"id":"1.230178322","rc":[{"atb":[[1.09,1]],"id":70681333},{"atl":[[1000,0.04]],"id":70681333}],"con":true,"img":false}]}
{"op":"mcm","clk":"11541238648","pt":1719503683319,"mc":[{"id":"1.230178322","rc":[{"atb":[[5.3,0],[5.1,1.6]],"id":70681333}],"con":true,"img":false}]}
{"op":"mcm","clk":"11541238657","pt":1719503683420,"mc":[{"id":"1.230178322","rc":[{"atb":[[1.09,0.23]],"id":70681333},{"atl":[[1000,0]],"id":70681333}],"con":true,"img":false}]}
{"op":"mcm","clk":"11541238666","pt":1719503683524,"mc":[{"id":"1.230178322","rc":[{"atl":[[28,0.88]],"id":70681333}],"con":true,"img":false}]}
{"op":"mcm","clk":"11541238675","pt":1719503683627,"mc":[{"id":"1.230178322","rc":[{"atb":[[1.09,0]],"id":70681333}],"con":true,"img":false}]}
{"op":"mcm","clk":"11541238683","pt":1719503683752,"mc":[{"id":"1.230178322","rc":[{"atb":[[5.4,0.23]],"id":70681333}],"con":true,"img":false}]}
{"op":"mcm","clk":"11541238706","pt":1719503684062,"mc":[{"id":"1.230178322","rc":[{"atb":[[5.3,1.6]],"id":70681333}],"con":true,"img":false}]}
{"op":"mcm","clk":"11541238717","pt":1719503684165,"mc":[{"id":"1.230178322","rc":[{"atb":[[5.1,0]],"id":70681333}],"con":true,"img":false}]}
{"op":"mcm","clk":"11541238725","pt":1719503684217,"mc":[{"id":"1.230178322","rc":[{"atb":[[5.4,1.07]],"id":70681333}],"con":true,"img":false}]}
{"op":"mcm","clk":"11541238743","pt":1719503684422,"mc":[{"id":"1.230178322","rc":[{"atb":[[5.5,1.54]],"id":70681333}],"con":true,"img":false}]}
{"op":"mcm","clk":"11541238753","pt":1719503684526,"mc":[{"id":"1.230178322","rc":[{"atb":[[5.3,0]],"id":70681333}],"con":true,"img":false}]}
{"op":"mcm","clk":"11541238772","pt":1719503684733,"mc":[{"id":"1.230178322","rc":[{"atb":[[5.2,0]],"id":70681333}],"con":true,"img":false}]}
{"op":"mcm","clk":"11541238869","pt":1719503685763,"mc":[{"id":"1.230178322","rc":[{"atb":[[3.35,0.84]],"id":51569790}],"con":true,"img":false}]}
{"op":"mcm","clk":"11541238948","pt":1719503686540,"mc":[{"id":"1.230178322","rc":[{"atb":[[3.3,1.2]],"id":51569790}],"con":true,"img":false}]}
{"op":"mcm","clk":"11541238984","pt":1719503686851,"mc":[{"id":"1.230178322","rc":[{"atb":[[3.3,0]],"id":51569790}],"con":true,"img":false}]}
{"op":"mcm","clk":"11541238996","pt":1719503686959,"mc":[{"id":"1.230178322","rc":[{"atb":[[3.25,6.71]],"id":51569790}],"con":true,"img":false}]}
{"op":"mcm","clk":"11541239035","pt":1719503687265,"mc":[{"id":"1.230178322","rc":[{"atb":[[3.35,0]],"id":51569790}],"con":true,"img":false}]}
{"op":"mcm","clk":"11541239073","pt":1719503687524,"mc":[{"id":"1.230178322","rc":[{"atb":[[3.3,6.35]],"id":51569790}],"con":true,"img":false}]}
{"op":"mcm","clk":"11541239124","pt":1719503688037,"mc":[{"id":"1.230178322","rc":[{"atb":[[3.25,5.51]],"id":51569790}],"con":true,"img":false}]}
{"op":"mcm","clk":"11541239137","pt":1719503688140,"mc":[{"id":"1.230178322","rc":[{"atb":[[3.3,7.55]],"id":51569790}],"con":true,"img":false}]}
{"op":"mcm","clk":"11541239348","pt":1719503690459,"mc":[{"id":"1.230178322","rc":[{"atl":[[1000,0.84]],"id":70681333},{"atl":[[1000,1.3]],"id":47885365}],"con":true,"img":false}]}
{"op":"mcm","clk":"11541239421","pt":1719503691438,"mc":[{"id":"1.230178322","rc":[{"atl":[[1000,0.94]],"id":47885365}],"con":true,"img":false}]}
{"op":"mcm","clk":"11541239468","pt":1719503692058,"mc":[{"id":"1.230178322","rc":[{"atl":[[1000,0.45]],"id":47885365}],"con":true,"img":false}]}
{"op":"mcm","clk":"11541239479","pt":1719503692163,"mc":[{"id":"1.230178322","rc":[{"atl":[[17.5,0.48]],"id":47885365}],"con":true,"img":false}]}
{"op":"mcm","clk":"11541239508","pt":1719503692471,"mc":[{"id":"1.230178322","rc":[{"atl":[[1000,0.31]],"id":70681333}],"con":true,"img":false}]}
{"op":"mcm","clk":"11541239538","pt":1719503692782,"mc":[{"id":"1.230178322","rc":[{"atl":[[1000,0]],"id":70681333}],"con":true,"img":false}]}
{"op":"mcm","clk":"11541239549","pt":1719503692833,"mc":[{"id":"1.230178322","rc":[{"atl":[[27,0.31]],"id":70681333},{"atl":[[17.5,1.32]],"id":47885365},{"atb":[[3.35,0.84]],"id":51569790}],"con":true,"img":false}]}
{"op":"mcm","clk":"11541239576","pt":1719503693142,"mc":[{"id":"1.230178322","rc":[{"atb":[[3.3,1.2]],"id":51569790}],"con":true,"img":false}]}
{"op":"mcm","clk":"11541239613","pt":1719503693553,"mc":[{"id":"1.230178322","rc":[{"atb":[[3.3,0]],"id":51569790}],"con":true,"img":false}]}
{"op":"mcm","clk":"11541239624","pt":1719503693657,"mc":[{"id":"1.230178322","rc":[{"atb":[[3.25,6.71]],"id":51569790}],"con":true,"img":false}]}
{"op":"mcm","clk":"11541239688","pt":1719503694328,"mc":[{"id":"1.230178322","rc":[{"atb":[[3.35,0]],"id":51569790}],"con":true,"img":false}]}
{"op":"mcm","clk":"11541239712","pt":1719503694636,"mc":[{"id":"1.230178322","rc":[{"atl":[[4.4,1.48]],"id":51569790}],"con":true,"img":false}]}
{"op":"mcm","clk":"11541239724","pt":1719503694739,"mc":[{"id":"1.230178322","rc":[{"atb":[[3.3,6.35]],"id":51569790}],"con":true,"img":false}]}
{"op":"mcm","clk":"11541239754","pt":1719503695047,"mc":[{"id":"1.230178322","rc":[{"atb":[[4.1,0]],"id":70681333},{"atb":[[2.66,3.38],[2.7,6.29]],"id":68274051}],"con":true,"img":false}]}
{"op":"mcm","clk":"11541239790","pt":1719503695356,"mc":[{"id":"1.230178322","rc":[{"atb":[[2.68,3.16]],"id":68274051},{"atb":[[3.25,5.51]],"id":51569790},{"atb":[[7.4,0]],"id":60192591},{"trd":[[7.4,1.69]],"ltp":7.4,"tv":1.69,"id":60192591}],"con":true,"img":false}]}
{"op":"mcm","clk":"11541239796","pt":1719503695459,"mc":[{"id":"1.230178322","rc":[{"atb":[[2.7,7.49]],"id":68274051},{"atb":[[3.3,7.55]],"id":51569790}],"con":true,"img":false}]}
{"op":"mcm","clk":"11541239816","pt":1719503695667,"mc":[{"id":"1.230178322","rc":[{"atb":[[4.8,1.76]],"id":63650892},{"atl":[[1000,1.31]],"id":60192591}],"con":true,"img":false}]}
{"op":"mcm","clk":"11541239847","pt":1719503695976,"mc":[{"id":"1.230178322","rc":[{"atl":[[1000,0.96]],"id":60192591}],"con":true,"img":false}]}
{"op":"mcm","clk":"11541239887","pt":1719503696235,"mc":[{"id":"1.230178322","rc":[{"atl":[[1000,0.46]],"id":60192591}],"con":true,"img":false}]}
{"op":"mcm","clk":"11541239897","pt":1719503696335,"mc":[{"id":"1.230178322","rc":[{"atb":[[4.9,0.84]],"id":63650892},{"atl":[[17,0.49]],"id":60192591}],"con":true,"img":false}]}
{"op":"mcm","clk":"11541240136","pt":1719503698755,"mc":[{"id":"1.230178322","rc":[{"atl":[[28,0.84]],"id":70681333}],"con":true,"img":false}]}
{"op":"mcm","clk":"11541240149","pt":1719503698962,"mc":[{"id":"1.230178322","rc":[{"atb":[[5.4,0.84]],"id":70681333}],"con":true,"img":false}]}
{"op":"mcm","clk":"11541240168","pt":1719503699169,"mc":[{"id":"1.230178322","rc":[{"atb":[[1.1,1]],"id":70681333}],"con":true,"img":false}]}
{"op":"mcm","clk":"11541240178","pt":1719503699272,"mc":[{"id":"1.230178322","rc":[{"atb":[[1.1,0.22],[5.5,0]],"id":70681333},{"atl":[[1000,0.04]],"id":70681333}],"con":true,"img":false}]}
{"op":"mcm","clk":"11541240197","pt":1719503699479,"mc":[{"id":"1.230178322","rc":[{"atb":[[1.1,0],[5.1,1.54]],"id":70681333},{"atl":[[1000,0]],"id":70681333}],"con":true,"img":false}]}
{"op":"mcm","clk":"11541240206","pt":1719503699583,"mc":[{"id":"1.230178322","rc":[{"atb":[[5.6,0.22]],"id":70681333},{"atl":[[11.5,1],[27,0.35]],"id":70681333},{"atb":[[5.1,21.3],[5.2,6.52]],"id":47885365},{"atl":[[17,1.49],[17.5,0]],"id":60192591}],"con":true,"img":false}]}
{"op":"mcm","clk":"11541240217","pt":1719503699686,"mc":[{"id":"1.230178322","rc":[{"atl":[[28,2.84],[30,0]],"id":70681333}],"con":true,"img":false}]}
{"op":"mcm","clk":"11541240231","pt":1719503699739,"mc":[{"id":"1.230178322","rc":[{"atb":[[5.4,0]],"id":70681333}],"con":true,"img":false}]}
{"op":"mcm","clk":"11541240237","pt":1719503699845,"mc":[{"id":"1.230178322","rc":[{"atb":[[5.5,1.54]],"id":70681333}],"con":true,"img":false}]}
{"op":"mcm","clk":"11541240256","pt":1719503700050,"mc":[{"id":"1.230178322","rc":[{"atb":[[5.1,0]],"id":70681333},{"atb":[[5.2,7.69]],"id":47885365}],"con":true,"img":false}]}
{"op":"mcm","clk":"11541240274","pt":1719503700255,"mc":[{"id":"1.230178322","rc":[{"atb":[[5.6,1.06]],"id":70681333},{"atb":[[3.35,0.84]],"id":51569790}],"con":true,"img":false}]}
{"op":"mcm","clk":"11541240313","pt":1719503700668,"mc":[{"id":"1.230178322","rc":[{"atb":[[3.3,1.2]],"id":51569790}],"con":true,"img":false}]}
{"op":"mcm","clk":"11541240389","pt":1719503701341,"mc":[{"id":"1.230178322","rc":[{"atb":[[3.3,0]],"id":51569790}],"con":true,"img":false}]}
{"op":"mcm","clk":"11541240399","pt":1719503701444,"mc":[{"id":"1.230178322","rc":[{"atb":[[3.25,6.71]],"id":51569790}],"con":true,"img":false}]}
{"op":"mcm","clk":"11541240428","pt":1719503701757,"mc":[{"id":"1.230178322","rc":[{"atb":[[3.35,0]],"id":51569790}],"con":true,"img":false}]}
{"op":"mcm","clk":"11541240499","pt":1719503702585,"mc":[{"id":"1.230178322","rc":[{"atb":[[3.3,6.35]],"id":51569790}],"con":true,"img":false}]}
{"op":"mcm","clk":"11541240553","pt":1719503703150,"mc":[{"id":"1.230178322","rc":[{"atb":[[3.25,5.51]],"id":51569790}],"con":true,"img":false}]}
{"op":"mcm","clk":"11541240560","pt":1719503703255,"mc":[{"id":"1.230178322","rc":[{"atb":[[5,2.26]],"id":47885365},{"atb":[[3.3,7.55]],"id":51569790}],"con":true,"img":false}]}
{"op":"mcm","clk":"11541240943","pt":1719503707283,"mc":[{"id":"1.230178322","rc":[{"atb":[[3.35,0.84]],"id":51569790}],"con":true,"img":false}]}
{"op":"mcm","clk":"11541240968","pt":1719503707589,"mc":[{"id":"1.230178322","rc":[{"atb":[[3.3,1.2]],"id":51569790}],"con":true,"img":false}]}
{"op":"mcm","clk":"11541241002","pt":1719503708002,"mc":[{"id":"1.230178322","rc":[{"atb":[[1.04,1.7]],"id":70681333},{"atl":[[1000,1.7]],"id":70681333},{"atb":[[1.03,284.51]],"id":63650892},{"atl":[[1000,2.16]],"id":63650892},{"atb":[[1.03,9.59],[3.3,0]],"id":51569790},{"atl":[[1000,1.7]],"id":51569790}],"con":true,"img":false}]}
{"op":"mcm","clk":"11541241014","pt":1719503708056,"mc":[{"id":"1.230178322","rc":[{"atb":[[3.25,6.71]],"id":51569790}],"con":true,"img":false}]}
{"op":"mcm","clk":"11541241027","pt":1719503708157,"mc":[{"id":"1.230178322","rc":[{"atb":[[1.04,0.06]],"id":70681333},{"atl":[[1000,0.01]],"id":70681333},{"atb":[[1.03,282.88]],"id":63650892},{"atl":[[1000,0.48]],"id":63650892},{"atb":[[1.03,7.96]],"id":51569790},{"atl":[[1000,0.05]],"id":51569790}],"con":true,"img":false}]}
{"op":"mcm","clk":"11541241044","pt":1719503708361,"mc":[{"id":"1.230178322","rc":[{"atb":[[1.04,0]],"id":70681333},{"atl":[[1000,0]],"id":70681333},{"atb":[[1.03,282.81]],"id":63650892},{"atl":[[1000,0.46]],"id":63650892},{"atb":[[1.03,7.89],[3.35,0]],"id":51569790},{"atl":[[1000,0]],"id":51569790}],"con":true,"img":false}]}
{"op":"mcm","clk":"11541241058","pt":1719503708469,"mc":[{"id":"1.230178322","rc":[{"atb":[[5.6,1.13]],"id":70681333},{"atl":[[27,0.36]],"id":70681333},{"atb":[[4.9,0.92]],"id":63650892},{"atl":[[19.5,0.01]],"id":63650892},{"atb":[[3.35,0.07]],"id":51569790},{"atl":[[4.4,1.54]],"id":51569790}],"con":true,"img":false}]}
{"op":"mcm","clk":"11541241076","pt":1719503708671,"mc":[{"id":"1.230178322","rc":[{"atl":[[11.5,0]],"id":70681333},{"trd":[[11.5,4]],"ltp":11.5,"tv":4.0,"id":70681333},{"atb":[[7.2,0]],"id":60192591},{"trd":[[7.2,4]],"ltp":7.2,"tv":4.0,"id":60192591}],"con":true,"img":false}]}
{"op":"mcm","clk":"11541241086","pt":1719503708774,"mc":[{"id":"1.230178322","rc":[{"atl":[[29,4.41]],"id":70681333}],"con":true,"img":false}]}
{"op":"mcm","clk":"11541241097","pt":1719503708877,"mc":[{"id":"1.230178322","rc":[{"atl":[[28,0.84]],"id":70681333},{"atb":[[3.3,6.35]],"id":51569790}],"con":true,"img":false}]}
{"op":"mcm","clk":"11541241125","pt":1719503709084,"mc":[{"id":"1.230178322","rc":[{"atb":[[3.25,5.51]],"id":51569790}],"con":true,"img":false}]}
{"op":"mcm","clk":"11541241135","pt":1719503709187,"mc":[{"id":"1.230178322","rc":[{"atb":[[3.3,7.55]],"id":51569790}],"con":true,"img":false}]}
{"op":"mcm","clk":"11541241163","pt":1719503709495,"mc":[{"id":"1.230178322","rc":[{"atl":[[11.5,1]],"id":70681333}],"con":true,"img":false}]}
{"op":"mcm","clk":"11541241199","pt":1719503709958,"mc":[{"id":"1.230178322","rc":[{"atb":[[4.8,2.78]],"id":63650892},{"atl":[[4.4,0.9]],"id":51569790}],"con":true,"img":false}]}
{"op":"mcm","clk":"11541241610","pt":1719503713879,"mc":[{"id":"1.230178322","rc":[{"atb":[[2.68,0]],"id":68274051}],"con":true,"img":false}]}
{"op":"mcm","clk":"11541241620","pt":1719503713982,"mc":[{"id":"1.230178322","rc":[{"atb":[[2.7,3.31]],"id":68274051}],"con":true,"img":false}]}
{"op":"mcm","clk":"11541241651","pt":1719503714293,"mc":[{"id":"1.230178322","rc":[{"atb":[[2.7,1.48]],"id":68274051}],"con":true,"img":false}]}
{"op":"mcm","clk":"11541241659","pt":1719503714393,"mc":[{"id":"1.230178322","rc":[{"atb":[[3.35,0.92]],"id":51569790}],"con":true,"img":false}]}
{"op":"mcm","clk":"11541241690","pt":1719503714702,"mc":[{"id":"1.230178322","rc":[{"atb":[[2.7,0.27]],"id":68274051}],"con":true,"img":false}]}
{"op":"mcm","clk":"11541241702","pt":1719503714805,"mc":[{"id":"1.230178322","rc":[{"atl":[[27,0.32]],"id":70681333}],"con":true,"img":false}]}
{"op":"mcm","clk":"11541241711","pt":1719503714909,"mc":[{"id":"1.230178322","rc":[{"atb":[[5.6,0.91]],"id":70681333},{"atb":[[3.3,1.2]],"id":51569790}],"con":true,"img":false}]}
{"op":"mcm","clk":"11541241746","pt":1719503715170,"mc":[{"id":"1.230178322","rc":[{"atb":[[1.1,1]],"id":70681333},{"atb":[[3.3,0]],"id":51569790}],"con":true,"img":false}]}
{"op":"mcm","clk":"11541241757","pt":1719503715276,"mc":[{"id":"1.230178322","rc":[{"atb":[[2.7,0]],"id":68274051},{"atb":[[3.25,6.71]],"id":51569790}],"con":true,"img":false}]}
{"op":"mcm","clk":"11541241771","pt":1719503715378,"mc":[{"id":"1.230178322","rc":[{"atb":[[1.1,0.21]],"id":70681333},{"atb":[[1.13,0.27]],"id":68274051}],"con":true,"img":false}]}
{"op":"mcm","clk":"11541241789","pt":1719503715582,"mc":[{"id":"1.230178322","rc":[{"atb":[[1.1,0]],"id":70681333}],"con":true,"img":false}]}
{"op":"mcm","clk":"11541241803","pt":1719503715687,"mc":[{"id":"1.230178322","rc":[{"atb":[[5.7,0.21]],"id":70681333}],"con":true,"img":false}]}
{"op":"mcm","clk":"11541241839","pt":1719503715996,"mc":[{"id":"1.230178322","rc":[{"atb":[[3.35,0.07]],"id":51569790}],"con":true,"img":false}]}
{"op":"mcm","clk":"11541241890","pt":1719503716408,"mc":[{"id":"1.230178322","rc":[{"atb":[[3.3,6.35]],"id":51569790}],"con":true,"img":false}]}
{"op":"mcm","clk":"11541241952","pt":1719503716973,"mc":[{"id":"1.230178322","rc":[{"atb":[[3.25,5.51]],"id":51569790}],"con":true,"img":false}]}
{"op":"mcm","clk":"11541241969","pt":1719503717077,"mc":[{"id":"1.230178322","rc":[{"atb":[[3.3,7.55]],"id":51569790}],"con":true,"img":false}]}
{"op":"mcm","clk":"11541242145","pt":1719503718980,"mc":[{"id":"1.230178322","rc":[{"atb":[[2.58,3.42]],"id":68274051}],"con":true,"img":false}]}
{"op":"mcm","clk":"11541242157","pt":1719503719080,"mc":[{"id":"1.230178322","rc":[{"atb":[[2.58,0]],"id":68274051}],"con":true,"img":false}]}
{"op":"mcm","clk":"11541242321","pt":1719503720377,"mc":[{"id":"1.230178322","rc":[{"atb":[[4,1]],"id":70681333},{"atb":[[5,0.26]],"id":47885365},{"atb":[[3.5,0]],"id":63650892},{"atb":[[2.6,0]],"id":68274051},{"atl":[[4.5,0]],"id":51569790},{"atb":[[5,1]],"id":60192591}],"con":true,"img":false}]}
{"op":"mcm","clk":"11541242334","pt":1719503720478,"mc":[{"id":"1.230178322","rc":[{"atl":[[11.5,0]],"id":70681333},{"trd":[[11.5,6]],"ltp":11.5,"tv":6.0,"id":70681333},{"atb":[[3.35,3.47]],"id":51569790},{"atl":[[4,2]],"id":51569790},{"atb":[[7,0]],"id":60192591},{"trd":[[7,4.11]],"ltp":7.0,"tv":4.11,"id":60192591}],"con":true,"img":false}]}
{"op":"mcm","clk":"11541242350","pt":1719503720583,"mc":[{"id":"1.230178322","rc":[{"atb":[[5.7,3.05]],"id":70681333},{"atb":[[3.35,0.07]],"id":51569790},{"atl":[[7.8,0],[9.8,2.9]],"id":51569790}],"con":true,"img":false}]}
{"op":"mcm","clk":"11541242362","pt":1719503720686,"mc":[{"id":"1.230178322","rc":[{"atl":[[7.6,1.32],[9.8,0]],"id":51569790}],"con":true,"img":false}]}
{"op":"mcm","clk":"11541242372","pt":1719503720790,"mc":[{"id":"1.230178322","rc":[{"atl":[[7.8,2.9],[3.95,0.84]],"id":51569790},{"atb":[[6.2,0.84]],"id":60192591}],"con":true,"img":false}]}
{"op":"mcm","clk":"11541242380","pt":1719503720893,"mc":[{"id":"1.230178322","rc":[{"atb":[[3.25,4.66]],"id":51569790},{"atl":[[4.4,0.05]],"id":51569790}],"con":true,"img":false}]}
{"op":"mcm","clk":"11541242400","pt":1719503721098,"mc":[{"id":"1.230178322","rc":[{"atb":[[5,0]],"id":47885365}],"con":true,"img":false}]}
{"op":"mcm","clk":"11541242412","pt":1719503721205,"mc":[{"id":"1.230178322","rc":[{"atb":[[5.3,0.26]],"id":47885365}],"con":true,"img":false}]}
{"op":"mcm","clk":"11541242425","pt":1719503721308,"mc":[{"id":"1.230178322","rc":[{"atb":[[5.8,0.84]],"id":70681333}],"con":true,"img":false}]}
{"op":"mcm","clk":"11541242437","pt":1719503721362,"mc":[{"id":"1.230178322","rc":[{"atb":[[3.35,0.92]],"id":51569790}],"con":true,"img":false}]}
{"op":"mcm","clk":"11541242481","pt":1719503721775,"mc":[{"id":"1.230178322","rc":[{"atb":[[3.7,1]],"id":63650892}],"con":true,"img":false}]}
{"op":"mcm","clk":"11541242493","pt":1719503721879,"mc":[{"id":"1.230178322","rc":[{"atb":[[3.3,1.2]],"id":51569790}],"con":true,"img":false}]}
{"op":"mcm","clk":"11541242531","pt":1719503722191,"mc":[{"id":"1.230178322","rc":[{"atb":[[3.3,0]],"id":51569790}],"con":true,"img":false}]}
{"op":"mcm","clk":"11541242541","pt":1719503722296,"mc":[{"id":"1.230178322","rc":[{"atb":[[3.25,5.86]],"id":51569790}],"con":true,"img":false}]}
{"op":"mcm","clk":"11541242561","pt":1719503722501,"mc":[{"id":"1.230178322","rc":[{"atb":[[2.48,3.38]],"id":68274051}],"con":true,"img":false}]}
{"op":"mcm","clk":"11541242569","pt":1719503722604,"mc":[{"id":"1.230178322","rc":[{"atb":[[1.13,0]],"id":70681333},{"atb":[[2.44,13.63]],"id":51569790}],"con":true,"img":false}]}
{"op":"mcm","clk":"11541242588","pt":1719503722811,"mc":[{"id":"1.230178322","rc":[{"atb":[[5.8,1.1]],"id":70681333},{"atb":[[3.35,0.07]],"id":51569790}],"con":true,"img":false}]}
{"op":"mcm","clk":"11541242611","pt":1719503722979,"mc":[{"id":"1.230178322","rc":[{"atb":[[2.48,11.97]],"id":68274051}],"con":true,"img":false}]}
{"op":"mcm","clk":"11541242640","pt":1719503723182,"mc":[{"id":"1.230178322","rc":[{"atb":[[3.3,6.35]],"id":51569790}],"con":true,"img":false}]}
{"op":"mcm","clk":"11541242650","pt":1719503723288,"mc":[{"id":"1.230178322","rc":[{"atb":[[2.66,4.55]],"id":68274051},{"atb":[[2.62,11.11]],"id":51569790}],"con":true,"img":false}]}
{"op":"mcm","clk":"11541242661","pt":1719503723382,"mc":[{"id":"1.230178322","rc":[{"atb":[[4.6,1]],"id":63650892},{"atb":[[3.3,1]],"id":68274051}],"con":true,"img":false}]}
{"op":"mcm","clk":"11541242671","pt":1719503723484,"mc":[{"id":"1.230178322","rc":[{"atb":[[4.7,0]],"id":63650892},{"atb":[[3.35,0]],"id":68274051}],"con":true,"img":false}]}
{"op":"mcm","clk":"11541242698","pt":1719503723795,"mc":[{"id":"1.230178322","rc":[{"atl":[[3.95,1.48]],"id":51569790}],"con":true,"img":false}]}
{"op":"mcm","clk":"11541242718","pt":1719503724000,"mc":[{"id":"1.230178322","rc":[{"atb":[[3.25,4.66]],"id":51569790}],"con":true,"img":false}]}
{"op":"mcm","clk":"11541242733","pt":1719503724104,"mc":[{"id":"1.230178322","rc":[{"atb":[[5.8,0.84]],"id":70681333},{"atb":[[3.3,7.55]],"id":51569790}],"con":true,"img":false}]}
{"op":"mcm","clk":"11541242743","pt":1719503724207,"mc":[{"id":"1.230178322","rc":[{"atb":[[1.13,0.26]],"id":70681333}],"con":true,"img":false}]}
{"op":"mcm","clk":"11541242803","pt":1719503724675,"mc":[{"id":"1.230178322","rc":[{"atb":[[5.1,1.74],[4.6,8.69]],"id":47885365},{"atb":[[3.1,0],[2.92,13.55]],"id":51569790}],"con":true,"img":false}]}
{"op":"mcm","clk":"11541242851","pt":1719503725186,"mc":[{"id":"1.230178322","rc":[{"atb":[[3.05,4.36]],"id":51569790}],"con":true,"img":false}]}
{"op":"mcm","clk":"11541242876","pt":1719503725495,"mc":[{"id":"1.230178322","rc":[{"atb":[[3.05,0]],"id":51569790}],"con":true,"img":false}]}
{"op":"mcm","clk":"11541242891","pt":1719503725719,"mc":[{"id":"1.230178322","rc":[{"atl":[[17.5,2.32],[18.5,0]],"id":47885365},{"atl":[[9,0],[8.6,1]],"id":63650892},{"atl":[[6.4,0],[6.2,1]],"id":68274051},{"atb":[[2.98,1]],"id":51569790},{"atl":[[17,0.49],[15.5,1]],"id":60192591}],"con":true,"img":false}]}
{"op":"mcm","clk":"11541242900","pt":1719503725780,"mc":[{"id":"1.230178322","rc":[{"atl":[[19.5,2.01]],"id":63650892}],"con":true,"img":false}]}
{"op":"mcm","clk":"11541242910","pt":1719503725887,"mc":[{"id":"1.230178322","rc":[{"atl":[[22,0]],"id":63650892}],"con":true,"img":false}]}
{"op":"mcm","clk":"11541242957","pt":1719503726390,"mc":[{"id":"1.230178322","rc":[{"atb":[[5.2,6.52]],"id":47885365}],"con":true,"img":false}]}
{"op":"mcm","clk":"11541243079","pt":1719503727792,"mc":[{"id":"1.230178322","rc":[{"atl":[[17,0]],"id":60192591}],"con":true,"img":false}]}
{"op":"mcm","clk":"11541243098","pt":1719503727994,"mc":[{"id":"1.230178322","rc":[{"atl":[[120,0.49]],"id":60192591}],"con":true,"img":false}]}
{"op":"mcm","clk":"11541243134","pt":1719503728397,"mc":[{"id":"1.230178322","rc":[{"spn":16.4,"spf":"NaN","id":70681333},{"atb":[[5,1]],"id":47885365},{"spn":11.4,"spf":"NaN","id":47885365},{"spn":6.75,"spf":"NaN","id":63650892},{"spn":3.3,"spf":1.0,"id":68274051},{"atb":[[3.35,0.92]],"id":51569790},{"spn":3.65,"spf":"NaN","id":51569790},{"spn":10.85,"spf":"NaN","id":60192591}],"con":true,"img":false}]}
{"op":"mcm","clk":"11541243170","pt":1719503728811,"mc":[{"id":"1.230178322","rc":[{"atl":[[18,0]],"id":47885365}],"con":true,"img":false}]}
{"op":"mcm","clk":"11541243193","pt":1719503729017,"mc":[{"id":"1.230178322","rc":[{"atb":[[3.3,1.2]],"id":51569790}],"con":true,"img":false}]}
{"op":"mcm","clk":"11541243229","pt":1719503729283,"mc":[{"id":"1.230178322","rc":[{"atl":[[17.5,1.32],[18.5,1]],"id":47885365},{"atl":[[8.8,1]],"id":63650892},{"atl":[[18,1]],"id":60192591}],"con":true,"img":false}]}
{"op":"mcm","clk":"11541243241","pt":1719503729389,"mc":[{"id":"1.230178322","rc":[{"atl":[[8.6,0]],"id":63650892},{"atb":[[3.3,0]],"id":51569790},{"atl":[[15.5,0]],"id":60192591}],"con":true,"img":false}]}
{"op":"mcm","clk":"11541243253","pt":1719503729486,"mc":[{"id":"1.230178322","rc":[{"atb":[[3.25,5.86]],"id":51569790}],"con":true,"img":false}]}
{"op":"mcm","clk":"11541243275","pt":1719503729692,"mc":[{"id":"1.230178322","rc":[{"atb":[[2.16,5.84]],"id":47885365}],"con":true,"img":false}]}
{"op":"mcm","clk":"11541243298","pt":1719503729899,"mc":[{"id":"1.230178322","rc":[{"atl":[[17.5,0.48]],"id":47885365},{"atb":[[3.35,0.07]],"id":51569790}],"con":true,"img":false}]}
{"op":"mcm","clk":"11541243387","pt":1719503730824,"mc":[{"id":"1.230178322","rc":[{"atb":[[5.7,2.84]],"id":70681333},{"atb":[[3.3,6.35]],"id":51569790}],"con":true,"img":false}]}
{"op":"mcm","clk":"11541243407","pt":1719503730987,"mc":[{"id":"1.230178322","rc":[{"atb":[[1.1,1]],"id":70681333}],"con":true,"img":false}]}
{"op":"mcm","clk":"11541243417","pt":1719503731087,"mc":[{"id":"1.230178322","rc":[{"atb":[[1.1,0.21]],"id":70681333},{"atl":[[1000,0.04]],"id":70681333}],"con":true,"img":false}]}
{"op":"mcm","clk":"11541243430","pt":1719503731189,"mc":[{"id":"1.230178322","rc":[{"atb":[[3.25,4.66]],"id":51569790}],"con":true,"img":false}]}
{"op":"mcm","clk":"11541243440","pt":1719503731289,"mc":[{"id":"1.230178322","rc":[{"atb":[[1.1,0]],"id":70681333},{"atl":[[1000,0]],"id":70681333},{"atb":[[3.3,7.55]],"id":51569790}],"con":true,"img":false}]}
{"op":"mcm","clk":"11541243452","pt":1719503731393,"mc":[{"id":"1.230178322","rc":[{"atb":[[5.8,1.05]],"id":70681333},{"atl":[[27,0.36]],"id":70681333}],"con":true,"img":false}]}
{"op":"mcm","clk":"11541243529","pt":1719503732115,"mc":[{"id":"1.230178322","rc":[{"atl":[[18,1.74]],"id":47885365}],"con":true,"img":false}]}
{"op":"mcm","clk":"11541243541","pt":1719503732219,"mc":[{"id":"1.230178322","rc":[{"atb":[[4.8,6],[4.6,0]],"id":47885365}],"con":true,"img":false}]}
{"op":"mcm","clk":"11541243569","pt":1719503732482,"mc":[{"id":"1.230178322","rc":[{"atb":[[5.2,5.73]],"id":47885365}],"con":true,"img":false}]}
{"op":"mcm","clk":"11541243589","pt":1719503732691,"mc":[{"id":"1.230178322","rc":[{"atl":[[17.5,1.32]],"id":47885365}],"con":true,"img":false}]}
{"op":"mcm","clk":"11541243877","pt":1719503735688,"mc":[{"id":"1.230178322","rc":[{"atb":[[3.35,0.92]],"id":51569790}],"con":true,"img":false}]}
{"op":"mcm","clk":"11541243944","pt":1719503736407,"mc":[{"id":"1.230178322","rc":[{"atb":[[5.9,2.77]],"id":70681333},{"atb":[[3.3,1.2]],"id":51569790}],"con":true,"img":false}]}
{"op":"mcm","clk":"11541243950","pt":1719503736511,"mc":[{"id":"1.230178322","rc":[{"atb":[[5.7,0]],"id":70681333}],"con":true,"img":false}]}
{"op":"mcm","clk":"11541243963","pt":1719503736614,"mc":[{"id":"1.230178322","rc":[{"atb":[[3.75,0]],"id":70681333}],"con":true,"img":false}]}
{"op":"mcm","clk":"11541243971","pt":1719503736717,"mc":[{"id":"1.230178322","rc":[{"atb":[[5.9,4.44],[6,0.84]],"id":70681333}],"con":true,"img":false}]}
{"op":"mcm","clk":"11541243982","pt":1719503736821,"mc":[{"id":"1.230178322","rc":[{"atb":[[5.6,0.06]],"id":70681333}],"con":true,"img":false}]}
{"op":"mcm","clk":"11541243999","pt":1719503737025,"mc":[{"id":"1.230178322","rc":[{"spl":[[1.01,4]],"id":70681333}],"con":true,"img":false}]}
{"op":"mcm","clk":"11541244011","pt":1719503737129,"mc":[{"id":"1.230178322","rc":[{"atb":[[1.13,0]],"id":70681333},{"atl":[[6.2,0],[6,1]],"id":68274051},{"atb":[[3.3,0]],"id":51569790}],"con":true,"img":false}]}
{"op":"mcm","clk":"11541244025","pt":1719503737234,"mc":[{"id":"1.230178322","rc":[{"atb":[[5.9,2.77],[3.75,6],[6,1.1],[4.2,0]],"id":70681333},{"atl":[[24,0],[29,3.57]],"id":47885365},{"atb":[[2.8,11.51],[3.25,5.86],[2.92,0]],"id":51569790}],"con":true,"img":false}]}
{"op":"mcm","clk":"11541244090","pt":1719503737816,"mc":[{"id":"1.230178322","rc":[{"atb":[[3.35,0.07]],"id":51569790}],"con":true,"img":false}]}
{"op":"mcm","clk":"11541244108","pt":1719503738010,"mc":[{"id":"1.230178322","rc":[{"atb":[[3.3,6.35]],"id":51569790}],"con":true,"img":false}]}
{"op":"mcm","clk":"11541244147","pt":1719503738320,"mc":[{"id":"1.230178322","rc":[{"atb":[[3.25,4.66]],"id":51569790}],"con":true,"img":false}]}
{"op":"mcm","clk":"11541244159","pt":1719503738423,"mc":[{"id":"1.230178322","rc":[{"atb":[[3.3,7.55]],"id":51569790}],"con":true,"img":false}]}
{"op":"mcm","clk":"11541244191","pt":1719503738691,"mc":[{"id":"1.230178322","rc":[{"atb":[[6,0.84]],"id":70681333}],"con":true,"img":false}]}
{"op":"mcm","clk":"11541244201","pt":1719503738792,"mc":[{"id":"1.230178322","rc":[{"atb":[[1.13,0.26]],"id":70681333}],"con":true,"img":false}]}
{"op":"mcm","clk":"11541244243","pt":1719503739204,"mc":[{"id":"1.230178322","rc":[{"atl":[[3.95,0.84]],"id":51569790}],"con":true,"img":false}]}
{"op":"mcm","clk":"11541244275","pt":1719503739612,"mc":[{"id":"1.230178322","rc":[{"atb":[[4.8,0],[5,4.48]],"id":47885365}],"con":true,"img":false}]}
{"op":"mcm","clk":"11541244300","pt":1719503739921,"mc":[{"id":"1.230178322","rc":[{"atl":[[4,0]],"id":51569790}],"con":true,"img":false}]}
{"op":"mcm","clk":"11541244312","pt":1719503740024,"mc":[{"id":"1.230178322","rc":[{"atl":[[4.5,2]],"id":51569790}],"con":true,"img":false}]}
{"op":"mcm","clk":"11541244330","pt":1719503740231,"mc":[{"id":"1.230178322","rc":[{"atb":[[5.3,1.86]],"id":47885365}],"con":true,"img":false}]}
{"op":"mcm","clk":"11541244344","pt":1719503740333,"mc":[{"id":"1.230178322","rc":[{"atl":[[3.95,0]],"id":51569790}],"con":true,"img":false}]}
{"op":"mcm","clk":"11541244390","pt":1719503740814,"mc":[{"id":"1.230178322","rc":[{"atb":[[5.4,0.84],[5.2,0.84]],"id":47885365},{"atl":[[4.4,0.9]],"id":51569790}],"con":true,"img":false}]}
{"op":"mcm","clk":"11541244557","pt":1719503742707,"mc":[{"id":"1.230178322","rc":[{"atb":[[3.35,0.92]],"id":51569790}],"con":true,"img":false}]}
{"op":"mcm","clk":"11541244600","pt":1719503743114,"mc":[{"id":"1.230178322","rc":[{"atb":[[3.3,1.2]],"id":51569790}],"con":true,"img":false}]}
{"op":"mcm","clk":"11541244656","pt":1719503743733,"mc":[{"id":"1.230178322","rc":[{"atb":[[3.3,0]],"id":51569790}],"con":true,"img":false}]}
{"op":"mcm","clk":"11541244670","pt":1719503743787,"mc":[{"id":"1.230178322","rc":[{"atb":[[3.25,5.86]],"id":51569790}],"con":true,"img":false}]}
{"op":"mcm","clk":"11541244717","pt":1719503744408,"mc":[{"id":"1.230178322","rc":[{"atb":[[3.35,0.07]],"id":51569790}],"con":true,"img":false}]}
{"op":"mcm","clk":"11541244744","pt":1719503744613,"mc":[{"id":"1.230178322","rc":[{"atb":[[3.3,6.35]],"id":51569790}],"con":true,"img":false}]}
{"op":"mcm","clk":"11541244775","pt":1719503744925,"mc":[{"id":"1.230178322","rc":[{"atb":[[3.25,4.66]],"id":51569790}],"con":true,"img":false}]}
{"op":"mcm","clk":"11541244789","pt":1719503745032,"mc":[{"id":"1.230178322","rc":[{"atb":[[3.3,7.55]],"id":51569790}],"con":true,"img":false}]}
{"op":"mcm","clk":"11541244964","pt":1719503746635,"mc":[{"id":"1.230178322","rc":[{"atb":[[5.8,0.84]],"id":70681333},{"atl":[[27,0.32]],"id":70681333}],"con":true,"img":false}]}
{"op":"mcm","clk":"11541244982","pt":1719503746795,"mc":[{"id":"1.230178322","rc":[{"atb":[[1.1,1]],"id":70681333},{"atl":[[1000,0.04]],"id":70681333}],"con":true,"img":false}]}
{"op":"mcm","clk":"11541244989","pt":1719503746897,"mc":[{"id":"1.230178322","rc":[{"atb":[[1.1,0.2]],"id":70681333},{"atl":[[1000,0]],"id":70681333}],"con":true,"img":false}]}
{"op":"mcm","clk":"11541245000","pt":1719503746999,"mc":[{"id":"1.230178322","rc":[{"atb":[[5.6,0]],"id":70681333},{"atl":[[27,0.35]],"id":70681333},{"atb":[[4.9,0.84]],"id":63650892},{"atl":[[19.5,2]],"id":63650892},{"atb":[[3.35,0]],"id":51569790},{"atl":[[4.4,0.84]],"id":51569790}],"con":true,"img":false}]}
{"op":"mcm","clk":"11541245009","pt":1719503747104,"mc":[{"id":"1.230178322","rc":[{"atb":[[1.1,0]],"id":70681333}],"con":true,"img":false}]}
{"op":"mcm","clk":"11541245018","pt":1719503747206,"mc":[{"id":"1.230178322","rc":[{"atb":[[6,1.04]],"id":70681333}],"con":true,"img":false}]}
{"op":"mcm","clk":"11541245160","pt":1719503748917,"mc":[{"id":"1.230178322","rc":[{"atb":[[2.16,11.29]],"id":47885365}],"con":true,"img":false}]}
{"op":"mcm","clk":"11541245178","pt":1719503749120,"mc":[{"id":"1.230178322","rc":[{"atb":[[2.52,4.68]],"id":68274051}],"con":true,"img":false}]}
{"op":"mcm","clk":"11541245203","pt":1719503749423,"mc":[{"id":"1.230178322","rc":[{"atb":[[2.5,3.16]],"id":68274051}],"con":true,"img":false}]}
{"op":"mcm","clk":"11541245280","pt":1719503750309,"mc":[{"id":"1.230178322","rc":[{"atb":[[3.35,0.84]],"id":51569790}],"con":true,"img":false}]}
{"op":"mcm","clk":"11541245307","pt":1719503750619,"mc":[{"id":"1.230178322","rc":[{"atb":[[6.2,1.36]],"id":70681333}],"con":true,"img":false}]}
{"op":"mcm","clk":"11541245316","pt":1719503750724,"mc":[{"id":"1.230178322","rc":[{"atb":[[5.5,0]],"id":70681333}],"con":true,"img":false}]}
{"op":"mcm","clk":"11541245335","pt":1719503750922,"mc":[{"id":"1.230178322","rc":[{"atb":[[3.3,1.2]],"id":51569790}],"con":true,"img":false}]}
{"op":"mcm","clk":"11541245372","pt":1719503751336,"mc":[{"id":"1.230178322","rc":[{"atb":[[5.8,0]],"id":70681333}],"con":true,"img":false}]}
{"op":"mcm","clk":"11541245398","pt":1719503751646,"mc":[{"id":"1.230178322","rc":[{"atb":[[3.3,0]],"id":51569790}],"con":true,"img":false}]}
{"op":"mcm","clk":"11541245409","pt":1719503751704,"mc":[{"id":"1.230178322","rc":[{"atb":[[3.25,5.86]],"id":51569790}],"con":true,"img":false}]}
{"op":"mcm","clk":"11541245428","pt":1719503751908,"mc":[{"id":"1.230178322","rc":[{"atb":[[6.4,2.68],[5.9,0]],"id":70681333}],"con":true,"img":false}]}
{"op":"mcm","clk":"11541245464","pt":1719503752216,"mc":[{"id":"1.230178322","rc":[{"atb":[[6,0.2],[6.6,0.84]],"id":70681333},{"atb":[[3.35,0]],"id":51569790}],"con":true,"img":false}]}
{"op":"mcm","clk":"11541245490","pt":1719503752420,"mc":[{"id":"1.230178322","rc":[{"atb":[[3.3,6.35]],"id":51569790},{"atl":[[4.4,1.48]],"id":51569790}],"con":true,"img":false}]}
{"op":"mcm","clk":"11541245529","pt":1719503752832,"mc":[{"id":"1.230178322","rc":[{"atb":[[3.25,4.66]],"id":51569790}],"con":true,"img":false}]}
{"op":"mcm","clk":"11541245538","pt":1719503752936,"mc":[{"id":"1.230178322","rc":[{"atb":[[3.3,7.55]],"id":51569790}],"con":true,"img":false}]}
{"op":"mcm","clk":"11541245575","pt":1719503753306,"mc":[{"id":"1.230178322","rc":[{"atb":[[5.3,1.6]],"id":47885365}],"con":true,"img":false}]}
{"op":"mcm","clk":"11541245587","pt":1719503753410,"mc":[{"id":"1.230178322","rc":[{"atb":[[1.13,0.26]],"id":47885365}],"con":true,"img":false}]}
{"op":"mcm","clk":"11541245597","pt":1719503753513,"mc":[{"id":"1.230178322","rc":[{"atb":[[2.36,11.66]],"id":47885365},{"atb":[[2.96,0]],"id":63650892},{"atb":[[2.24,13.2]],"id":60192591}],"con":true,"img":false}]}
{"op":"mcm","clk":"11541245659","pt":1719503754127,"mc":[{"id":"1.230178322","rc":[{"atb":[[5.1,0]],"id":47885365}],"con":true,"img":false}]}
{"op":"mcm","clk":"11541245683","pt":1719503754333,"mc":[{"id":"1.230178322","rc":[{"atb":[[2.16,5.45]],"id":47885365}],"con":true,"img":false}]}
{"op":"mcm","clk":"11541245712","pt":1719503754644,"mc":[{"id":"1.230178322","rc":[{"atb":[[5.1,1.74]],"id":47885365}],"con":true,"img":false}]}
{"op":"mcm","clk":"11541245777","pt":1719503755217,"mc":[{"id":"1.230178322","rc":[{"atb":[[5.1,0]],"id":47885365}],"con":true,"img":false}]}
{"op":"mcm","clk":"11541245830","pt":1719503755833,"mc":[{"id":"1.230178322","rc":[{"atb":[[2.46,0]],"id":68274051}],"con":true,"img":false}]}
{"op":"mcm","clk":"11541245977","pt":1719503757327,"mc":[{"id":"1.230178322","rc":[{"atb":[[3.35,0.84]],"id":51569790}],"con":true,"img":false}]}
{"op":"mcm","clk":"11541245996","pt":1719503757638,"mc":[{"id":"1.230178322","rc":[{"atb":[[3.3,1.2]],"id":51569790}],"con":true,"img":false}]}
{"op":"mcm","clk":"11541246058","pt":1719503758205,"mc":[{"id":"1.230178322","rc":[{"atb":[[3.3,0]],"id":51569790}],"con":true,"img":false}]}
{"op":"mcm","clk":"11541246068","pt":1719503758311,"mc":[{"id":"1.230178322","rc":[{"atb":[[3.25,5.86]],"id":51569790}],"con":true,"img":false}]}
{"op":"mcm","clk":"11541246124","pt":1719503758929,"mc":[{"id":"1.230178322","rc":[{"atb":[[3.35,0]],"id":51569790}],"con":true,"img":false}]}
{"op":"mcm","clk":"11541246153","pt":1719503759238,"mc":[{"id":"1.230178322","rc":[{"atb":[[3.3,6.35]],"id":51569790}],"con":true,"img":false}]}
{"op":"mcm","clk":"11541246193","pt":1719503759751,"mc":[{"id":"1.230178322","rc":[{"atb":[[2.4,9.06]],"id":47885365},{"atb":[[2.48,8.58]],"id":68274051}],"con":true,"img":false}]}
{"op":"mcm","clk":"11541246226","pt":1719503760015,"mc":[{"id":"1.230178322","rc":[{"atb":[[3,6.35]],"id":63650892},{"atb":[[3.25,4.66]],"id":51569790}],"con":true,"img":false}]}
{"op":"mcm","clk":"11541246239","pt":1719503760120,"mc":[{"id":"1.230178322","rc":[{"atb":[[3.3,7.55]],"id":51569790}],"con":true,"img":false}]}
{"op":"mcm","clk":"11541246249","pt":1719503760222,"mc":[{"id":"1.230178322","rc":[{"atb":[[3.25,1.65]],"id":51569790}],"con":true,"img":false}]}
{"op":"mcm","clk":"11541246260","pt":1719503760325,"mc":[{"id":"1.230178322","rc":[{"atb":[[2.28,9.92]],"id":60192591}],"con":true,"img":false}]}
{"op":"mcm","clk":"11541246286","pt":1719503760533,"mc":[{"id":"1.230178322","rc":[{"atb":[[2.16,25.41]],"id":70681333}],"con":true,"img":false}]}
{"op":"mcm","clk":"11541246335","pt":1719503760937,"mc":[{"id":"1.230178322","rc":[{"atb":[[2.16,34.81]],"id":63650892}],"con":true,"img":false}]}
{"op":"mcm","clk":"11541246362","pt":1719503761248,"mc":[{"id":"1.230178322","rc":[{"atb":[[1.01,1]],"id":70681333},{"atb":[[2.66,3.38]],"id":68274051}],"con":true,"img":false}]}
{"op":"mcm","clk":"11541246451","pt":1719503762132,"mc":[{"id":"1.230178322","rc":[{"atb":[[4.4,2]],"id":70681333},{"atb":[[5.3,3.6],[5,1]],"id":47885365},{"atb":[[3.55,6.35],[3.3,1]],"id":63650892},{"atb":[[2.8,0],[3.15,15.1]],"id":51569790},{"atb":[[5.1,13.21]],"id":60192591}],"con":true,"img":false}]}
{"op":"mcm","clk":"11541246461","pt":1719503762232,"mc":[{"id":"1.230178322","rc":[{"atb":[[3.75,0],[6.6,1.84]],"id":70681333},{"atl":[[27,0.31]],"id":70681333},{"atb":[[5.3,4.6]],"id":47885365},{"atb":[[4.9,1.84]],"id":63650892},{"atl":[[18,1]],"id":68274051},{"atl":[[3.95,1]],"id":51569790},{"atb":[[4.7,0]],"id":60192591}],"con":true,"img":false}]}
{"op":"mcm","clk":"11541246505","pt":1719503762756,"mc":[{"id":"1.230178322","rc":[{"atb":[[6,0]],"id":70681333}],"con":true,"img":false}]}
{"op":"mcm","clk":"11541246522","pt":1719503762963,"mc":[{"id":"1.230178322","rc":[{"atl":[[3.95,0]],"id":51569790}],"con":true,"img":false}]}
{"op":"mcm","clk":"11541246544","pt":1719503763170,"mc":[{"id":"1.230178322","rc":[{"atl":[[1000,0.04]],"id":70681333},{"atl":[[3.95,1]],"id":51569790}],"con":true,"img":false}]}
{"op":"mcm","clk":"11541246563","pt":1719503763378,"mc":[{"id":"1.230178322","rc":[{"atl":[[1000,0]],"id":70681333},{"atl":[[3.95,0]],"id":51569790}],"con":true,"img":false}]}
{"op":"mcm","clk":"11541246574","pt":1719503763438,"mc":[{"id":"1.230178322","rc":[{"atl":[[27,0.35]],"id":70681333},{"atb":[[1.13,0]],"id":47885365}],"con":true,"img":false}]}
{"op":"mcm","clk":"11541246584","pt":1719503763534,"mc":[{"id":"1.230178322","rc":[{"atb":[[5.4,1.1]],"id":47885365},{"atl":[[3.95,1]],"id":51569790}],"con":true,"img":false}]}
{"op":"mcm","clk":"11541246601","pt":1719503763743,"mc":[{"id":"1.230178322","rc":[{"atl":[[3.95,0]],"id":51569790}],"con":true,"img":false}]}
{"op":"mcm","clk":"11541246619","pt":1719503763951,"mc":[{"id":"1.230178322","rc":[{"atl":[[3.95,1]],"id":51569790}],"con":true,"img":false}]}
{"op":"mcm","clk":"11541246638","pt":1719503764155,"mc":[{"id":"1.230178322","rc":[{"atl":[[3.95,0]],"id":51569790}],"con":true,"img":false}]}
{"op":"mcm","clk":"11541246696","pt":1719503764771,"mc":[{"id":"1.230178322","rc":[{"atb":[[3.35,0.84]],"id":51569790}],"con":true,"img":false}]}
{"op":"mcm","clk":"11541246707","pt":1719503764874,"mc":[{"id":"1.230178322","rc":[{"atb":[[5.4,0.84]],"id":47885365},{"atl":[[3.95,1]],"id":51569790}],"con":true,"img":false}]}
{"op":"mcm","clk":"11541246716","pt":1719503764953,"mc":[{"id":"1.230178322","rc":[{"atb":[[1.13,0.26]],"id":47885365}],"con":true,"img":false}]}
{"op":"mcm","clk":"11541246763","pt":1719503765446,"mc":[{"id":"1.230178322","rc":[{"atb":[[3.3,1.2]],"id":51569790}],"con":true,"img":false}]}
{"op":"mcm","clk":"11541246795","pt":1719503765756,"mc":[{"id":"1.230178322","rc":[{"atl":[[3.95,0]],"id":51569790}],"con":true,"img":false}]}
{"op":"mcm","clk":"11541246802","pt":1719503765858,"mc":[{"id":"1.230178322","rc":[{"atl":[[3.95,1]],"id":51569790}],"con":true,"img":false}]}
{"op":"mcm","clk":"11541246822","pt":1719503766065,"mc":[{"id":"1.230178322","rc":[{"atb":[[3.3,0]],"id":51569790}],"con":true,"img":false}]}
{"op":"mcm","clk":"11541246833","pt":1719503766167,"mc":[{"id":"1.230178322","rc":[{"atb":[[3.25,2.85]],"id":51569790}],"con":true,"img":false}]}
{"op":"mcm","clk":"11541246846","pt":1719503766270,"mc":[{"id":"1.230178322","rc":[{"atl":[[3.95,0]],"id":51569790}],"con":true,"img":false}]}
{"op":"mcm","clk":"11541246893","pt":1719503766631,"mc":[{"id":"1.230178322","rc":[{"atl":[[3.95,1]],"id":51569790}],"con":true,"img":false}]}
{"op":"mcm","clk":"11541246913","pt":1719503766837,"mc":[{"id":"1.230178322","rc":[{"atb":[[1.25,20]],"id":70681333},{"atb":[[1.25,20]],"id":47885365},{"atb":[[1.25,20]],"id":63650892},{"atb":[[1.25,20]],"id":68274051},{"atb":[[3.35,0],[1.25,20]],"id":51569790},{"atb":[[1.25,20]],"id":60192591}],"con":true,"img":false}]}
{"op":"mcm","clk":"11541246930","pt":1719503767054,"mc":[{"id":"1.230178322","rc":[{"atb":[[6.4,0],[6.8,2.92]],"id":70681333},{"atl":[[3.95,0]],"id":51569790}],"con":true,"img":false}]}
{"op":"mcm","clk":"11541246941","pt":1719503767144,"mc":[{"id":"1.230178322","rc":[{"atb":[[3.3,6.35]],"id":51569790}],"con":true,"img":false}]}
{"op":"mcm","clk":"11541246954","pt":1719503767251,"mc":[{"id":"1.230178322","rc":[{"atl":[[3.95,1]],"id":51569790}],"con":true,"img":false}]}
{"op":"mcm","clk":"11541246971","pt":1719503767454,"mc":[{"id":"1.230178322","rc":[{"atl":[[3.95,0]],"id":51569790}],"con":true,"img":false}]}
{"op":"mcm","clk":"11541246991","pt":1719503767661,"mc":[{"id":"1.230178322","rc":[{"atl":[[3.95,1]],"id":51569790}],"con":true,"img":false}]}
{"op":"mcm","clk":"11541247001","pt":1719503767770,"mc":[{"id":"1.230178322","rc":[{"atb":[[7,0.84]],"id":70681333},{"atb":[[3.25,1.65]],"id":51569790},{"atl":[[4.4,0.84]],"id":51569790}],"con":true,"img":false}]}
{"op":"mcm","clk":"11541247010","pt":1719503767865,"mc":[{"id":"1.230178322","rc":[{"atb":[[3.3,7.55]],"id":51569790}],"con":true,"img":false}]}
{"op":"mcm","clk":"11541247023","pt":1719503767967,"mc":[{"id":"1.230178322","rc":[{"atb":[[6.6,0.84]],"id":70681333}],"con":true,"img":false}]}
{"op":"mcm","clk":"11541247036","pt":1719503768072,"mc":[{"id":"1.230178322","rc":[{"atl":[[3.95,0]],"id":51569790}],"con":true,"img":false}]}
{"op":"mcm","clk":"11541247047","pt":1719503768175,"mc":[{"id":"1.230178322","rc":[{"atb":[[7,1.84]],"id":70681333}],"con":true,"img":false}]}
{"op":"mcm","clk":"11541247064","pt":1719503768336,"mc":[{"id":"1.230178322","rc":[{"atl":[[3.95,1]],"id":51569790}],"con":true,"img":false}]}
{"op":"mcm","clk":"11541247097","pt":1719503768645,"mc":[{"id":"1.230178322","rc":[{"atb":[[2.5,11.06]],"id":68274051}],"con":true,"img":false}]}
{"op":"mcm","clk":"11541247106","pt":1719503768748,"mc":[{"id":"1.230178322","rc":[{"atb":[[6.6,0]],"id":70681333}],"con":true,"img":false}]}
{"op":"mcm","clk":"11541247117","pt":1719503768851,"mc":[{"id":"1.230178322","rc":[{"atl":[[3.95,0]],"id":51569790}],"con":true,"img":false}]}
{"op":"mcm","clk":"11541247125","pt":1719503768954,"mc":[{"id":"1.230178322","rc":[{"atb":[[2.66,4.51]],"id":68274051}],"con":true,"img":false}]}
{"op":"mcm","clk":"11541247137","pt":1719503769058,"mc":[{"id":"1.230178322","rc":[{"atl":[[3.95,1]],"id":51569790}],"con":true,"img":false}]}
{"op":"mcm","clk":"11541247157","pt":1719503769264,"mc":[{"id":"1.230178322","rc":[{"atl":[[3.95,0]],"id":51569790}],"con":true,"img":false}]}
{"op":"mcm","clk":"11541247205","pt":1719503769779,"mc":[{"id":"1.230178322","rc":[{"atl":[[3.95,1]],"id":51569790}],"con":true,"img":false}]}
{"op":"mcm","clk":"11541247436","pt":1719503772253,"mc":[{"id":"1.230178322","rc":[{"atb":[[3.35,0.84]],"id":51569790}],"con":true,"img":false}]}
{"op":"mcm","clk":"11541247462","pt":1719503772561,"mc":[{"id":"1.230178322","rc":[{"atl":[[3.95,0]],"id":51569790}],"con":true,"img":false}]}
{"op":"mcm","clk":"11541247481","pt":1719503772767,"mc":[{"id":"1.230178322","rc":[{"atl":[[3.95,1]],"id":51569790}],"con":true,"img":false}]}
{"op":"mcm","clk":"11541247512","pt":1719503773077,"mc":[{"id":"1.230178322","rc":[{"atb":[[3.3,1.2]],"id":51569790}],"con":true,"img":false}]}
{"op":"mcm","clk":"11541247521","pt":1719503773180,"mc":[{"id":"1.230178322","rc":[{"atl":[[3.95,0]],"id":51569790}],"con":true,"img":false}]}
{"op":"mcm","clk":"11541247534","pt":1719503773338,"mc":[{"id":"1.230178322","rc":[{"atl":[[3.95,1]],"id":51569790}],"con":true,"img":false}]}
{"op":"mcm","clk":"11541247567","pt":1719503773746,"mc":[{"id":"1.230178322","rc":[{"atb":[[6.8,0],[7,4.76]],"id":70681333},{"atb":[[3.3,0],[3.05,6],[3.15,0]],"id":51569790}],"con":true,"img":false}]}
{"op":"mcm","clk":"11541247576","pt":1719503773848,"mc":[{"id":"1.230178322","rc":[{"atb":[[3.25,2.85]],"id":51569790}],"con":true,"img":false}]}
{"op":"mcm","clk":"11541247583","pt":1719503773951,"mc":[{"id":"1.230178322","rc":[{"atl":[[3.95,0]],"id":51569790}],"con":true,"img":false}]}
{"op":"mcm","clk":"11541247591","pt":1719503774055,"mc":[{"id":"1.230178322","rc":[{"atl":[[3.95,1]],"id":51569790}],"con":true,"img":false}]}
{"op":"mcm","clk":"11541247606","pt":1719503774261,"mc":[{"id":"1.230178322","rc":[{"atb":[[3.35,0]],"id":51569790},{"atl":[[3.95,0]],"id":51569790}],"con":true,"img":false}]}
{"op":"mcm","clk":"11541247623","pt":1719503774466,"mc":[{"id":"1.230178322","rc":[{"atl":[[3.95,1]],"id":51569790}],"con":true,"img":false}]}
{"op":"mcm","clk":"11541247662","pt":1719503774876,"mc":[{"id":"1.230178322","rc":[{"atb":[[3.3,6.35]],"id":51569790}],"con":true,"img":false}]}
{"op":"mcm","clk":"11541247681","pt":1719503775083,"mc":[{"id":"1.230178322","rc":[{"atl":[[3.95,0]],"id":51569790}],"con":true,"img":false}]}
{"op":"mcm","clk":"11541247703","pt":1719503775252,"mc":[{"id":"1.230178322","rc":[{"atl":[[3.95,1]],"id":51569790}],"con":true,"img":false}]}
{"op":"mcm","clk":"11541247721","pt":1719503775448,"mc":[{"id":"1.230178322","rc":[{"atl":[[3.95,0]],"id":51569790}],"con":true,"img":false}]}
{"op":"mcm","clk":"11541247741","pt":1719503775655,"mc":[{"id":"1.230178322","rc":[{"atb":[[3.25,1.65]],"id":51569790},{"atl":[[3.95,1]],"id":51569790}],"con":true,"img":false}]}
{"op":"mcm","clk":"11541247748","pt":1719503775756,"mc":[{"id":"1.230178322","rc":[{"atb":[[3.3,7.55]],"id":51569790}],"con":true,"img":false}]}
{"op":"mcm","clk":"11541247773","pt":1719503776066,"mc":[{"id":"1.230178322","rc":[{"atl":[[3.95,0]],"id":51569790}],"con":true,"img":false}]}
{"op":"mcm","clk":"11541247798","pt":1719503776376,"mc":[{"id":"1.230178322","rc":[{"atl":[[3.95,1]],"id":51569790}],"con":true,"img":false}]}
{"op":"mcm","clk":"11541247807","pt":1719503776480,"mc":[{"id":"1.230178322","rc":[{"atl":[[3.95,0]],"id":51569790}],"con":true,"img":false}]}
{"op":"mcm","clk":"11541247815","pt":1719503776536,"mc":[{"id":"1.230178322","rc":[{"atl":[[3.95,1]],"id":51569790}],"con":true,"img":false}]}
{"op":"mcm","clk":"11541247984","pt":1719503778652,"mc":[{"id":"1.230178322","rc":[{"atl":[[27,0.31]],"id":70681333}],"con":true,"img":false}]}
{"op":"mcm","clk":"11541248008","pt":1719503778853,"mc":[{"id":"1.230178322","rc":[{"atl":[[3.95,0]],"id":51569790}],"con":true,"img":false}]}
{"op":"mcm","clk":"11541248016","pt":1719503778953,"mc":[{"id":"1.230178322","rc":[{"atl":[[1000,0.04]],"id":70681333}],"con":true,"img":false}]}
{"op":"mcm","clk":"11541248033","pt":1719503779159,"mc":[{"id":"1.230178322","rc":[{"atl":[[1000,0]],"id":70681333},{"atl":[[3.95,1]],"id":51569790}],"con":true,"img":false}]}
{"op":"mcm","clk":"11541248043","pt":1719503779263,"mc":[{"id":"1.230178322","rc":[{"atl":[[27,0.35]],"id":70681333}],"con":true,"img":false}]}
{"op":"mcm","clk":"11541248054","pt":1719503779366,"mc":[{"id":"1.230178322","rc":[{"atb":[[3.35,0.84]],"id":51569790}],"con":true,"img":false}]}
{"op":"mcm","clk":"11541248073","pt":1719503779571,"mc":[{"id":"1.230178322","rc":[{"atl":[[3.95,0]],"id":51569790}],"con":true,"img":false}]}
{"op":"mcm","clk":"11541248086","pt":1719503779674,"mc":[{"id":"1.230178322","rc":[{"atb":[[3.3,1.2]],"id":51569790}],"con":true,"img":false}]}
{"op":"mcm","clk":"11541248096","pt":1719503779778,"mc":[{"id":"1.230178322","rc":[{"atl":[[3.95,1]],"id":51569790}],"con":true,"img":false}]}
{"op":"mcm","clk":"11541248158","pt":1719503780451,"mc":[{"id":"1.230178322","rc":[{"atb":[[3.3,0]],"id":51569790}],"con":true,"img":false}]}
{"op":"mcm","clk":"11541248185","pt":1719503780759,"mc":[{"id":"1.230178322","rc":[{"atb":[[3.1,6],[3.35,0],[3.05,0]],"id":51569790},{"atl":[[3.95,0]],"id":51569790},{"atl":[[1000,1.31]],"id":60192591}],"con":true,"img":false}]}
{"op":"mcm","clk":"11541248192","pt":1719503780862,"mc":[{"id":"1.230178322","rc":[{"atl":[[3.95,1]],"id":51569790}],"con":true,"img":false}]}
{"op":"mcm","clk":"11541248206","pt":1719503780966,"mc":[{"id":"1.230178322","rc":[{"atb":[[3.25,2.81]],"id":51569790},{"atl":[[120,0]],"id":60192591}],"con":true,"img":false}]}
{"op":"mcm","clk":"11541248227","pt":1719503781172,"mc":[{"id":"1.230178322","rc":[{"atb":[[3.3,6.35]],"id":51569790},{"atl":[[4.4,1.48],[3.95,0]],"id":51569790},{"atl":[[1000,0.94]],"id":60192591}],"con":true,"img":false}]}
{"op":"mcm","clk":"11541248243","pt":1719503781378,"mc":[{"id":"1.230178322","rc":[{"atl":[[3.95,1]],"id":51569790}],"con":true,"img":false}]}
{"op":"mcm","clk":"11541248252","pt":1719503781481,"mc":[{"id":"1.230178322","rc":[{"atl":[[1000,0.46]],"id":60192591}],"con":true,"img":false}]}
{"op":"mcm","clk":"11541248261","pt":1719503781583,"mc":[{"id":"1.230178322","rc":[{"atb":[[3.25,1.65]],"id":51569790},{"atl":[[3.95,0]],"id":51569790},{"atl":[[17.5,0.48]],"id":60192591}],"con":true,"img":false}]}
{"op":"mcm","clk":"11541248276","pt":1719503781686,"mc":[{"id":"1.230178322","rc":[{"atb":[[3.3,7.51]],"id":51569790}],"con":true,"img":false}]}
{"op":"mcm","clk":"11541248281","pt":1719503781743,"mc":[{"id":"1.230178322","rc":[{"atl":[[3.95,1]],"id":51569790}],"con":true,"img":false}]}
{"op":"mcm","clk":"11541248408","pt":1719503783081,"mc":[{"id":"1.230178322","rc":[{"atl":[[3.95,0]],"id":51569790}],"con":true,"img":false}]}
{"op":"mcm","clk":"11541248438","pt":1719503783289,"mc":[{"id":"1.230178322","rc":[{"atl":[[3.95,1]],"id":51569790}],"con":true,"img":false}]}
{"op":"mcm","clk":"11541248459","pt":1719503783451,"mc":[{"id":"1.230178322","rc":[{"atl":[[3.95,0]],"id":51569790}],"con":true,"img":false}]}
{"op":"mcm","clk":"11541248537","pt":1719503784171,"mc":[{"id":"1.230178322","rc":[{"atb":[[3.15,5.51]],"id":70681333},{"atb":[[2.48,0]],"id":68274051},{"atl":[[3.95,1]],"id":51569790}],"con":true,"img":false}]}
{"op":"mcm","clk":"11541248679","pt":1719503785564,"mc":[{"id":"1.230178322","rc":[{"atb":[[2.16,18.59]],"id":70681333}],"con":true,"img":false}]}
{"op":"mcm","clk":"11541248702","pt":1719503785771,"mc":[{"id":"1.230178322","rc":[{"atl":[[3.95,0]],"id":51569790}],"con":true,"img":false}]}
{"op":"mcm","clk":"11541248713","pt":1719503785873,"mc":[{"id":"1.230178322","rc":[{"atb":[[2.5,7.9]],"id":68274051}],"con":true,"img":false}]}
{"op":"mcm","clk":"11541248723","pt":1719503785977,"mc":[{"id":"1.230178322","rc":[{"atb":[[2.52,0]],"id":68274051},{"atl":[[3.95,1]],"id":51569790}],"con":true,"img":false}]}
{"op":"mcm","clk":"11541248764","pt":1719503786392,"mc":[{"id":"1.230178322","rc":[{"atb":[[2.16,12.26]],"id":47885365}],"con":true,"img":false}]}
{"op":"mcm","clk":"11541248790","pt":1719503786597,"mc":[{"id":"1.230178322","rc":[{"atl":[[3.95,0]],"id":51569790}],"con":true,"img":false}]}
{"op":"mcm","clk":"11541248799","pt":1719503786656,"mc":[{"id":"1.230178322","rc":[{"atb":[[1.01,0.71]],"id":68274051}],"con":true,"img":false}]}
{"op":"mcm","clk":"11541248810","pt":1719503786759,"mc":[{"id":"1.230178322","rc":[{"atl":[[3.95,1]],"id":51569790}],"con":true,"img":false}]}
{"op":"mcm","clk":"11541248819","pt":1719503786861,"mc":[{"id":"1.230178322","rc":[{"atb":[[3.35,0.84]],"id":51569790}],"con":true,"img":false}]}
{"op":"mcm","clk":"11541248830","pt":1719503786965,"mc":[{"id":"1.230178322","rc":[{"atl":[[3.95,0]],"id":51569790}],"con":true,"img":false}]}
{"op":"mcm","clk":"11541248856","pt":1719503787166,"mc":[{"id":"1.230178322","rc":[{"atb":[[1.01,0.28]],"id":68274051},{"atb":[[3.3,1.16]],"id":51569790}],"con":true,"img":false}]}
{"op":"mcm","clk":"11541248869","pt":1719503787269,"mc":[{"id":"1.230178322","rc":[{"atl":[[3.95,1]],"id":51569790}],"con":true,"img":false}]}
{"op":"mcm","clk":"11541248904","pt":1719503787579,"mc":[{"id":"1.230178322","rc":[{"atb":[[1.01,0],[2.66,3.38]],"id":68274051},{"atb":[[3.3,0]],"id":51569790},{"atl":[[3.95,0]],"id":51569790}],"con":true,"img":false}]}
{"op":"mcm","clk":"11541248916","pt":1719503787682,"mc":[{"id":"1.230178322","rc":[{"atb":[[3.3,1.28]],"id":68274051},{"atb":[[3.25,2.81]],"id":51569790}],"con":true,"img":false}]}
{"op":"mcm","clk":"11541248929","pt":1719503787786,"mc":[{"id":"1.230178322","rc":[{"atb":[[2.88,2.58]],"id":68274051},{"atl":[[3.95,1]],"id":51569790}],"con":true,"img":false}]}
{"op":"mcm","clk":"11541248942","pt":1719503787890,"mc":[{"id":"1.230178322","rc":[{"atb":[[2.66,0]],"id":68274051}],"con":true,"img":false}]}
{"op":"mcm","clk":"11541248966","pt":1719503788095,"mc":[{"id":"1.230178322","rc":[{"atl":[[3.95,0]],"id":51569790}],"con":true,"img":false}]}
{"op":"mcm","clk":"11541248976","pt":1719503788155,"mc":[{"id":"1.230178322","rc":[{"atb":[[2.5,9.14]],"id":68274051},{"atl":[[3.95,1]],"id":51569790}],"con":true,"img":false}]}
{"op":"mcm","clk":"11541248986","pt":1719503788259,"mc":[{"id":"1.230178322","rc":[{"atb":[[3.35,0]],"id":51569790}],"con":true,"img":false}]}
{"op":"mcm","clk":"11541249010","pt":1719503788460,"mc":[{"id":"1.230178322","rc":[{"spn":7.0,"spf":1.0,"id":70681333},{"spn":11.45,"spf":"NaN","id":47885365},{"spn":6.85,"spf":"NaN","id":63650892},{"atl":[[3.95,0]],"id":51569790},{"spn":3.82,"spf":"NaN","id":51569790},{"spn":11.85,"spf":"NaN","id":60192591}],"con":true,"img":false}]}
{"op":"mcm","clk":"11541249031","pt":1719503788664,"mc":[{"id":"1.230178322","rc":[{"atb":[[1.01,0.71]],"id":51569790},{"atl":[[3.95,1]],"id":51569790}],"con":true,"img":false}]}
{"op":"mcm","clk":"11541249048","pt":1719503788869,"mc":[{"id":"1.230178322","rc":[{"atb":[[2.52,1.82]],"id":68274051}],"con":true,"img":false}]}
{"op":"mcm","clk":"11541249058","pt":1719503788973,"mc":[{"id":"1.230178322","rc":[{"atl":[[3.95,0]],"id":51569790}],"con":true,"img":false}]}
{"op":"mcm","clk":"11541249068","pt":1719503789075,"mc":[{"id":"1.230178322","rc":[{"atb":[[1.01,0.28]],"id":51569790}],"con":true,"img":false}]}
{"op":"mcm","clk":"11541249076","pt":1719503789178,"mc":[{"id":"1.230178322","rc":[{"atb":[[3.3,6.35]],"id":51569790}],"con":true,"img":false}]}
{"op":"mcm","clk":"11541249098","pt":1719503789383,"mc":[{"id":"1.230178322","rc":[{"atb":[[3.25,1.65]],"id":51569790},{"atl":[[3.95,1]],"id":51569790}],"con":true,"img":false}]}
{"op":"mcm","clk":"11541249109","pt":1719503789486,"mc":[{"id":"1.230178322","rc":[{"atb":[[1.01,0],[3.3,7.51]],"id":51569790}],"con":true,"img":false}]}
{"op":"mcm","clk":"11541249119","pt":1719503789588,"mc":[{"id":"1.230178322","rc":[{"atb":[[3.35,0.28]],"id":51569790}],"con":true,"img":false}]}
{"op":"mcm","clk":"11541249130","pt":1719503789691,"mc":[{"id":"1.230178322","rc":[{"atl":[[3.95,0]],"id":51569790}],"con":true,"img":false}]}
