{"op":"mcm","clk":"11536380656","pt":1719425245599,"mc":[{"id":"1.230178326","marketDefinition":{"bspMarket":true,"turnInPlayEnabled":false,"persistenceEnabled":false,"marketBaseRate":5.0,"eventId":"33376062","eventTypeId":"4339","numberOfWinners":1,"bettingType":"ODDS","marketType":"WIN","marketTime":"2024-06-27T16:43:00.000Z","suspendTime":"2024-06-27T16:43:00.000Z","bspReconciled":false,"complete":true,"inPlay":false,"crossMatching":false,"runnersVoidable":false,"numberOfActiveRunners":6,"betDelay":0,"status":"OPEN","runners":[{"status":"ACTIVE","sortPriority":1,"id":58221357,"name":"1. Ballymac Wynett"},{"status":"ACTIVE","sortPriority":2,"id":62600242,"name":"2. Swanley Petunia"},{"status":"ACTIVE","sortPriority":3,"id":60748118,"name":"3. Ballymac Dom"},{"status":"ACTIVE","sortPriority":4,"id":67674431,"name":"4. Fairyhill Daisy"},{"status":"ACTIVE","sortPriority":5,"id":68687941,"name":"5. Killieford Negri"},{"status":"ACTIVE","sortPriority":6,"id":65710029,"name":"6. Da Man Joey"}],"regulators":["MR_INT"],"venue":"Kinsley","countryCode":"GB","discountAllowed":false,"timezone":"Europe/London","openDate":"2024-06-27T13:36:00.000Z","version":5994643771,"name":"A3 462m","eventName":"Kinsley 27th Jun"},"rc":[],"con":true,"img":false}]}
{"op":"mcm","clk":"11536381026","pt":1719425248531,"mc":[{"id":"1.230178326","marketDefinition":{"bspMarket":true,"turnInPlayEnabled":false,"persistenceEnabled":false,"marketBaseRate":5.0,"eventId":"33376062","eventTypeId":"4339","numberOfWinners":1,"bettingType":"ODDS","marketType":"WIN","marketTime":"2024-06-27T16:43:00.000Z","suspendTime":"2024-06-27T16:43:00.000Z","bspReconciled":false,"complete":true,"inPlay":false,"crossMatching":false,"runnersVoidable":false,"numberOfActiveRunners":6,"betDelay":0,"status":"OPEN","runners":[{"status":"ACTIVE","sortPriority":1,"id":58221357,"name":"1. Ballymac Wynett"},{"status":"ACTIVE","sortPriority":2,"id":62600242,"name":"2. Swanley Petunia"},{"status":"ACTIVE","sortPriority":3,"id":60748118,"name":"3. Ballymac Dom"},{"status":"ACTIVE","sortPriority":4,"id":67674431,"name":"4. Fairyhill Daisy"},{"status":"ACTIVE","sortPriority":5,"id":68687941,"name":"5. Killieford Negri"},{"status":"ACTIVE","sortPriority":6,"id":65710029,"name":"6. Da Man Joey"}],"regulators":["MR_INT"],"venue":"Kinsley","countryCode":"GB","discountAllowed":true,"timezone":"Europe/London","openDate":"2024-06-27T13:36:00.000Z","version":5994643771,"name":"A3 462m","eventName":"Kinsley 27th Jun"},"rc":[],"con":true,"img":false}]}
{"op":"mcm","clk":"11536615153","pt":1719428244223,"mc":[{"id":"1.230178326","rc":[{"atb":[[1.02,22.63]],"id":58221357},{"atl":[[990,0.84]],"id":58221357},{"spn":495.51,"spf":"NaN","id":58221357},{"atb":[[1.03,15.09]],"id":62600242},{"atl":[[1000,0.84]],"id":62600242},{"spn":500.51,"spf":"NaN","id":62600242},{"atb":[[1.02,22.63]],"id":60748118},{"atl":[[1000,0.84]],"id":60748118},{"spn":500.51,"spf":"NaN","id":60748118},{"atb":[[1.02,22.63]],"id":68687941},{"atl":[[990,0.84]],"id":68687941},{"spn":495.51,"spf":"NaN","id":68687941},{"atb":[[1.01,45.27]],"id":67674431},{"atl":[[1000,0.84]],"id":67674431},{"spn":500.5,"spf":"NaN","id":67674431},{"atb":[[1.02,22.63]],"id":65710029},{"atl":[[1000,0.84]],"id":65710029},{"spn":500.51,"spf":"NaN","id":65710029}],"con":true,"img":false}]}
{"op":"mcm","clk":"11536836919","pt":1719431850947,"mc":[{"id":"1.230178326","rc":[{"atb":[[1.02,22.64]],"id":58221357},{"atl":[[990,0.26]],"id":58221357},{"atb":[[1.03,15.09]],"id":62600242},{"atl":[[1000,0.26]],"id":62600242},{"atb":[[1.02,22.64]],"id":60748118},{"atl":[[1000,0.26]],"id":60748118},{"atb":[[1.02,22.64]],"id":68687941},{"atl":[[990,0.26]],"id":68687941},{"atb":[[1.01,45.28]],"id":67674431},{"atl":[[1000,0.26]],"id":67674431},{"atb":[[1.02,22.64]],"id":65710029},{"atl":[[1000,0.26]],"id":65710029}],"con":true,"img":false}]}
{"op":"mcm","clk":"11537232275","pt":1719437882524,"mc":[{"id":"1.230178326","marketDefinition":{"bspMarket":true,"turnInPlayEnabled":false,"persistenceEnabled":false,"marketBaseRate":5.0,"eventId":"33376062","eventTypeId":"4339","numberOfWinners":1,"bettingType":"ODDS","marketType":"WIN","marketTime":"2024-06-27T16:43:00.000Z","suspendTime":"2024-06-27T16:43:00.000Z","bspReconciled":false,"complete":true,"inPlay":false,"crossMatching":false,"runnersVoidable":false,"numberOfActiveRunners":6,"betDelay":0,"status":"OPEN","runners":[{"status":"ACTIVE","sortPriority":1,"id":58221357,"name":"1. Ballymac Wynett"},{"status":"ACTIVE","sortPriority":2,"id":62600242,"name":"2. Swanley Petunia"},{"status":"ACTIVE","sortPriority":3,"id":60748118,"name":"3. Ballymac Dom"},{"status":"ACTIVE","sortPriority":4,"id":67674431,"name":"4. Fairyhill Daisy"},{"status":"ACTIVE","sortPriority":5,"id":68687941,"name":"5. Killieford Negri"},{"status":"ACTIVE","sortPriority":6,"id":65710029,"name":"6. Da Man Joey"}],"regulators":["MR_INT"],"venue":"Kinsley","countryCode":"GB","discountAllowed":true,"timezone":"Europe/London","openDate":"2024-06-27T13:36:00.000Z","version":5994643771,"name":"A3 462m","eventName":"Kinsley 27th Jun"},"rc":[{"atb":[[1.02,22.64]],"id":58221357},{"atl":[[990,0.26]],"id":58221357},{"spn":495.51,"spf":"NaN","id":58221357},{"atb":[[1.03,15.09]],"id":62600242},{"atl":[[1000,0.26]],"id":62600242},{"spn":500.51,"spf":"NaN","id":62600242},{"atb":[[1.02,22.64]],"id":60748118},{"atl":[[1000,0.26]],"id":60748118},{"spn":500.51,"spf":"NaN","id":60748118},{"atb":[[1.02,22.64]],"id":68687941},{"atl":[[990,0.26]],"id":68687941},{"spn":495.51,"spf":"NaN","id":68687941},{"atb":[[1.01,45.28]],"id":67674431},{"atl":[[1000,0.26]],"id":67674431},{"spn":500.5,"spf":"NaN","id":67674431},{"atb":[[1.02,22.64]],"id":65710029},{"atl":[[1000,0.26]],"id":65710029},{"spn":500.51,"spf":"NaN","id":65710029}],"con":true,"img":true}]}
{"op":"mcm","clk":"11537573402","pt":1719443282543,"mc":[{"id":"1.230178326","marketDefinition":{"bspMarket":true,"turnInPlayEnabled":false,"persistenceEnabled":false,"marketBaseRate":5.0,"eventId":"33376062","eventTypeId":"4339","numberOfWinners":1,"bettingType":"ODDS","marketType":"WIN","marketTime":"2024-06-27T16:43:00.000Z","suspendTime":"2024-06-27T16:43:00.000Z","bspReconciled":false,"complete":true,"inPlay":false,"crossMatching":false,"runnersVoidable":false,"numberOfActiveRunners":6,"betDelay":0,"status":"OPEN","runners":[{"status":"ACTIVE","sortPriority":1,"id":58221357,"name":"1. Ballymac Wynett"},{"status":"ACTIVE","sortPriority":2,"id":62600242,"name":"2. Swanley Petunia"},{"status":"ACTIVE","sortPriority":3,"id":60748118,"name":"3. Ballymac Dom"},{"status":"ACTIVE","sortPriority":4,"id":67674431,"name":"4. Fairyhill Daisy"},{"status":"ACTIVE","sortPriority":5,"id":68687941,"name":"5. Killieford Negri"},{"status":"ACTIVE","sortPriority":6,"id":65710029,"name":"6. Da Man Joey"}],"regulators":["MR_INT"],"venue":"Kinsley","countryCode":"GB","discountAllowed":true,"timezone":"Europe/London","openDate":"2024-06-27T13:36:00.000Z","version":5994643771,"name":"A3 462m","eventName":"Kinsley 27th Jun"},"rc":[{"atb":[[1.02,22.64]],"id":58221357},{"atl":[[990,0.26]],"id":58221357},{"spn":495.51,"spf":"NaN","id":58221357},{"atb":[[1.03,15.09]],"id":62600242},{"atl":[[1000,0.26]],"id":62600242},{"spn":500.51,"spf":"NaN","id":62600242},{"atb":[[1.02,22.64]],"id":60748118},{"atl":[[1000,0.26]],"id":60748118},{"spn":500.51,"spf":"NaN","id":60748118},{"atb":[[1.02,22.64]],"id":68687941},{"atl":[[990,0.26]],"id":68687941},{"spn":495.51,"spf":"NaN","id":68687941},{"atb":[[1.01,45.29]],"id":67674431},{"atl":[[1000,0.26]],"id":67674431},{"spn":500.5,"spf":"NaN","id":67674431},{"atb":[[1.02,22.64]],"id":65710029},{"atl":[[1000,0.26]],"id":65710029},{"spn":500.51,"spf":"NaN","id":65710029}],"con":true,"img":true}]}
{"op":"mcm","clk":"11537954962","pt":1719448682568,"mc":[{"id":"1.230178326","marketDefinition":{"bspMarket":true,"turnInPlayEnabled":false,"persistenceEnabled":false,"marketBaseRate":5.0,"eventId":"33376062","eventTypeId":"4339","numberOfWinners":1,"bettingType":"ODDS","marketType":"WIN","marketTime":"2024-06-27T16:43:00.000Z","suspendTime":"2024-06-27T16:43:00.000Z","bspReconciled":false,"complete":true,"inPlay":false,"crossMatching":false,"runnersVoidable":false,"numberOfActiveRunners":6,"betDelay":0,"status":"OPEN","runners":[{"status":"ACTIVE","sortPriority":1,"id":58221357,"name":"1. Ballymac Wynett"},{"status":"ACTIVE","sortPriority":2,"id":62600242,"name":"2. Swanley Petunia"},{"status":"ACTIVE","sortPriority":3,"id":60748118,"name":"3. Ballymac Dom"},{"status":"ACTIVE","sortPriority":4,"id":67674431,"name":"4. Fairyhill Daisy"},{"status":"ACTIVE","sortPriority":5,"id":68687941,"name":"5. Killieford Negri"},{"status":"ACTIVE","sortPriority":6,"id":65710029,"name":"6. Da Man Joey"}],"regulators":["MR_INT"],"venue":"Kinsley","countryCode":"GB","discountAllowed":true,"timezone":"Europe/London","openDate":"2024-06-27T13:36:00.000Z","version":5994643771,"name":"A3 462m","eventName":"Kinsley 27th Jun"},"rc":[{"atb":[[1.02,22.64]],"id":58221357},{"atl":[[990,0.26]],"id":58221357},{"spn":495.51,"spf":"NaN","id":58221357},{"atb":[[1.03,15.09]],"id":62600242},{"atl":[[1000,0.26]],"id":62600242},{"spn":500.51,"spf":"NaN","id":62600242},{"atb":[[1.02,22.64]],"id":60748118},{"atl":[[1000,0.26]],"id":60748118},{"spn":500.51,"spf":"NaN","id":60748118},{"atb":[[1.02,22.64]],"id":68687941},{"atl":[[990,0.26]],"id":68687941},{"spn":495.51,"spf":"NaN","id":68687941},{"atb":[[1.01,45.28]],"id":67674431},{"atl":[[1000,0.26]],"id":67674431},{"spn":500.5,"spf":"NaN","id":67674431},{"atb":[[1.02,22.64]],"id":65710029},{"atl":[[1000,0.26]],"id":65710029},{"spn":500.51,"spf":"NaN","id":65710029}],"con":true,"img":true}]}
{"op":"mcm","clk":"11538170625","pt":1719454082550,"mc":[{"id":"1.230178326","marketDefinition":{"bspMarket":true,"turnInPlayEnabled":false,"persistenceEnabled":false,"marketBaseRate":5.0,"eventId":"33376062","eventTypeId":"4339","numberOfWinners":1,"bettingType":"ODDS","marketType":"WIN","marketTime":"2024-06-27T16:43:00.000Z","suspendTime":"2024-06-27T16:43:00.000Z","bspReconciled":false,"complete":true,"inPlay":false,"crossMatching":false,"runnersVoidable":false,"numberOfActiveRunners":6,"betDelay":0,"status":"OPEN","runners":[{"status":"ACTIVE","sortPriority":1,"id":58221357,"name":"1. Ballymac Wynett"},{"status":"ACTIVE","sortPriority":2,"id":62600242,"name":"2. Swanley Petunia"},{"status":"ACTIVE","sortPriority":3,"id":60748118,"name":"3. Ballymac Dom"},{"status":"ACTIVE","sortPriority":4,"id":67674431,"name":"4. Fairyhill Daisy"},{"status":"ACTIVE","sortPriority":5,"id":68687941,"name":"5. Killieford Negri"},{"status":"ACTIVE","sortPriority":6,"id":65710029,"name":"6. Da Man Joey"}],"regulators":["MR_INT"],"venue":"Kinsley","countryCode":"GB","discountAllowed":true,"timezone":"Europe/London","openDate":"2024-06-27T13:36:00.000Z","version":5994643771,"name":"A3 462m","eventName":"Kinsley 27th Jun"},"rc":[{"atb":[[1.02,22.64]],"id":58221357},{"atl":[[990,0.26]],"id":58221357},{"spn":495.51,"spf":"NaN","id":58221357},{"atb":[[1.03,15.09]],"id":62600242},{"atl":[[1000,0.26]],"id":62600242},{"spn":500.51,"spf":"NaN","id":62600242},{"atb":[[1.02,22.64]],"id":60748118},{"atl":[[1000,0.26]],"id":60748118},{"spn":500.51,"spf":"NaN","id":60748118},{"atb":[[1.02,22.64]],"id":68687941},{"atl":[[990,0.26]],"id":68687941},{"spn":495.51,"spf":"NaN","id":68687941},{"atb":[[1.01,45.29]],"id":67674431},{"atl":[[1000,0.26]],"id":67674431},{"spn":500.5,"spf":"NaN","id":67674431},{"atb":[[1.02,22.64]],"id":65710029},{"atl":[[1000,0.26]],"id":65710029},{"spn":500.51,"spf":"NaN","id":65710029}],"con":true,"img":true}]}
{"op":"mcm","clk":"11538368283","pt":1719459482600,"mc":[{"id":"1.230178326","marketDefinition":{"bspMarket":true,"turnInPlayEnabled":false,"persistenceEnabled":false,"marketBaseRate":5.0,"eventId":"33376062","eventTypeId":"4339","numberOfWinners":1,"bettingType":"ODDS","marketType":"WIN","marketTime":"2024-06-27T16:43:00.000Z","suspendTime":"2024-06-27T16:43:00.000Z","bspReconciled":false,"complete":true,"inPlay":false,"crossMatching":false,"runnersVoidable":false,"numberOfActiveRunners":6,"betDelay":0,"status":"OPEN","runners":[{"status":"ACTIVE","sortPriority":1,"id":58221357,"name":"1. Ballymac Wynett"},{"status":"ACTIVE","sortPriority":2,"id":62600242,"name":"2. Swanley Petunia"},{"status":"ACTIVE","sortPriority":3,"id":60748118,"name":"3. Ballymac Dom"},{"status":"ACTIVE","sortPriority":4,"id":67674431,"name":"4. Fairyhill Daisy"},{"status":"ACTIVE","sortPriority":5,"id":68687941,"name":"5. Killieford Negri"},{"status":"ACTIVE","sortPriority":6,"id":65710029,"name":"6. Da Man Joey"}],"regulators":["MR_INT"],"venue":"Kinsley","countryCode":"GB","discountAllowed":true,"timezone":"Europe/London","openDate":"2024-06-27T13:36:00.000Z","version":5994643771,"name":"A3 462m","eventName":"Kinsley 27th Jun"},"rc":[{"atb":[[1.02,22.65]],"id":58221357},{"atl":[[990,0.26]],"id":58221357},{"spn":495.51,"spf":"NaN","id":58221357},{"atb":[[1.03,15.1]],"id":62600242},{"atl":[[1000,0.26]],"id":62600242},{"spn":500.51,"spf":"NaN","id":62600242},{"atb":[[1.02,22.65]],"id":60748118},{"atl":[[1000,0.26]],"id":60748118},{"spn":500.51,"spf":"NaN","id":60748118},{"atb":[[1.02,22.65]],"id":68687941},{"atl":[[990,0.26]],"id":68687941},{"spn":495.51,"spf":"NaN","id":68687941},{"atb":[[1.01,45.3]],"id":67674431},{"atl":[[1000,0.26]],"id":67674431},{"spn":500.5,"spf":"NaN","id":67674431},{"atb":[[1.02,22.65]],"id":65710029},{"atl":[[1000,0.26]],"id":65710029},{"spn":500.51,"spf":"NaN","id":65710029}],"con":true,"img":true}]}
{"op":"mcm","clk":"11538595409","pt":1719464882548,"mc":[{"id":"1.230178326","marketDefinition":{"bspMarket":true,"turnInPlayEnabled":false,"persistenceEnabled":false,"marketBaseRate":5.0,"eventId":"33376062","eventTypeId":"4339","numberOfWinners":1,"bettingType":"ODDS","marketType":"WIN","marketTime":"2024-06-27T16:43:00.000Z","suspendTime":"2024-06-27T16:43:00.000Z","bspReconciled":false,"complete":true,"inPlay":false,"crossMatching":false,"runnersVoidable":false,"numberOfActiveRunners":6,"betDelay":0,"status":"OPEN","runners":[{"status":"ACTIVE","sortPriority":1,"id":58221357,"name":"1. Ballymac Wynett"},{"status":"ACTIVE","sortPriority":2,"id":62600242,"name":"2. Swanley Petunia"},{"status":"ACTIVE","sortPriority":3,"id":60748118,"name":"3. Ballymac Dom"},{"status":"ACTIVE","sortPriority":4,"id":67674431,"name":"4. Fairyhill Daisy"},{"status":"ACTIVE","sortPriority":5,"id":68687941,"name":"5. Killieford Negri"},{"status":"ACTIVE","sortPriority":6,"id":65710029,"name":"6. Da Man Joey"}],"regulators":["MR_INT"],"venue":"Kinsley","countryCode":"GB","discountAllowed":true,"timezone":"Europe/London","openDate":"2024-06-27T13:36:00.000Z","version":5994643771,"name":"A3 462m","eventName":"Kinsley 27th Jun"},"rc":[{"atb":[[1.02,22.64]],"id":58221357},{"atl":[[990,0.26]],"id":58221357},{"spn":495.51,"spf":"NaN","id":58221357},{"atb":[[1.03,15.09]],"id":62600242},{"atl":[[1000,0.26]],"id":62600242},{"spn":500.51,"spf":"NaN","id":62600242},{"atb":[[1.02,22.64]],"id":60748118},{"atl":[[1000,0.26]],"id":60748118},{"spn":500.51,"spf":"NaN","id":60748118},{"atb":[[1.02,22.64]],"id":68687941},{"atl":[[990,0.26]],"id":68687941},{"spn":495.51,"spf":"NaN","id":68687941},{"atb":[[1.01,45.29]],"id":67674431},{"atl":[[1000,0.26]],"id":67674431},{"spn":500.5,"spf":"NaN","id":67674431},{"atb":[[1.02,22.64]],"id":65710029},{"atl":[[1000,0.26]],"id":65710029},{"spn":500.51,"spf":"NaN","id":65710029}],"con":true,"img":true}]}
{"op":"mcm","clk":"11538748640","pt":1719468205215,"mc":[{"id":"1.230178326","rc":[{"atb":[[2,12.82],[1.02,22.64]],"id":58221357},{"spn":496.0,"spf":"NaN","id":58221357},{"atb":[[1.03,15.09],[2.1,12.55]],"id":62600242},{"spn":501.05,"spf":"NaN","id":62600242},{"atb":[[1.02,22.64],[2.04,12.2]],"id":60748118},{"spn":501.02,"spf":"NaN","id":60748118},{"atb":[[2,11.96],[1.02,22.64]],"id":68687941},{"spn":496.0,"spf":"NaN","id":68687941},{"atb":[[1.01,45.29],[2.08,8.88]],"id":67674431},{"spn":501.04,"spf":"NaN","id":67674431},{"atb":[[1.02,22.64],[2.08,13.32]],"id":65710029},{"spn":501.04,"spf":"NaN","id":65710029}],"con":true,"img":false}]}
{"op":"mcm","clk":"11538750261","pt":1719468240475,"mc":[{"id":"1.230178326","rc":[{"atb":[[2.06,3.16]],"id":60748118},{"atb":[[2.1,3.16]],"id":65710029}],"con":true,"img":false}]}
{"op":"mcm","clk":"11538750270","pt":1719468240635,"mc":[{"id":"1.230178326","rc":[{"atb":[[2.02,3.16]],"id":58221357}],"con":true,"img":false}]}
{"op":"mcm","clk":"11538750298","pt":1719468241251,"mc":[{"id":"1.230178326","rc":[{"atb":[[2.12,3.16]],"id":62600242}],"con":true,"img":false}]}
{"op":"mcm","clk":"11538750323","pt":1719468241662,"mc":[{"id":"1.230178326","rc":[{"atb":[[2.1,3.16]],"id":67674431}],"con":true,"img":false}]}
{"op":"mcm","clk":"11538750332","pt":1719468241873,"mc":[{"id":"1.230178326","rc":[{"atb":[[2.02,3.16]],"id":68687941}],"con":true,"img":false}]}
{"op":"mcm","clk":"11538752082","pt":1719468275482,"mc":[{"id":"1.230178326","rc":[{"spn":496.01,"spf":"NaN","id":58221357},{"atb":[[2.12,6.55]],"id":62600242},{"spn":501.06,"spf":"NaN","id":62600242},{"spn":501.03,"spf":"NaN","id":60748118},{"spn":496.01,"spf":"NaN","id":68687941},{"spn":501.05,"spf":"NaN","id":67674431},{"spn":501.05,"spf":"NaN","id":65710029}],"con":true,"img":false}]}
{"op":"mcm","clk":"11538752096","pt":1719468275787,"mc":[{"id":"1.230178326","rc":[{"atb":[[2.02,6.55]],"id":58221357}],"con":true,"img":false}]}
{"op":"mcm","clk":"11538752100","pt":1719468275888,"mc":[{"id":"1.230178326","rc":[{"atb":[[2.02,6.55]],"id":68687941}],"con":true,"img":false}]}
{"op":"mcm","clk":"11538752110","pt":1719468276094,"mc":[{"id":"1.230178326","rc":[{"atb":[[2.1,6.55]],"id":67674431}],"con":true,"img":false}]}
{"op":"mcm","clk":"11538752114","pt":1719468276196,"mc":[{"id":"1.230178326","rc":[{"atb":[[2.06,6.55]],"id":60748118}],"con":true,"img":false}]}
{"op":"mcm","clk":"11538752163","pt":1719468277478,"mc":[{"id":"1.230178326","rc":[{"atb":[[2.1,6.55]],"id":65710029}],"con":true,"img":false}]}
{"op":"mcm","clk":"11538752394","pt":1719468281755,"mc":[{"id":"1.230178326","marketDefinition":{"bspMarket":true,"turnInPlayEnabled":false,"persistenceEnabled":false,"marketBaseRate":5.0,"eventId":"33376062","eventTypeId":"4339","numberOfWinners":1,"bettingType":"ODDS","marketType":"WIN","marketTime":"2024-06-27T16:43:00.000Z","suspendTime":"2024-06-27T16:43:00.000Z","bspReconciled":false,"complete":true,"inPlay":false,"crossMatching":true,"runnersVoidable":false,"numberOfActiveRunners":6,"betDelay":0,"status":"OPEN","runners":[{"status":"ACTIVE","sortPriority":1,"id":58221357,"name":"1. Ballymac Wynett"},{"status":"ACTIVE","sortPriority":2,"id":62600242,"name":"2. Swanley Petunia"},{"status":"ACTIVE","sortPriority":3,"id":60748118,"name":"3. Ballymac Dom"},{"status":"ACTIVE","sortPriority":4,"id":67674431,"name":"4. Fairyhill Daisy"},{"status":"ACTIVE","sortPriority":5,"id":68687941,"name":"5. Killieford Negri"},{"status":"ACTIVE","sortPriority":6,"id":65710029,"name":"6. Da Man Joey"}],"regulators":["MR_INT"],"venue":"Kinsley","countryCode":"GB","discountAllowed":true,"timezone":"Europe/London","openDate":"2024-06-27T13:36:00.000Z","version":5994643771,"name":"A3 462m","eventName":"Kinsley 27th Jun"},"rc":[],"con":true,"img":false}]}
{"op":"mcm","clk":"11538904961","pt":1719471463482,"mc":[{"id":"1.230178326","rc":[{"atl":[[990,0.16]],"id":58221357},{"atl":[[1000,0.16]],"id":62600242},{"atl":[[1000,0.16]],"id":60748118},{"atl":[[990,0.16]],"id":68687941},{"atl":[[1000,0.16]],"id":67674431},{"atl":[[1000,0.16]],"id":65710029}],"con":true,"img":false}]}
{"op":"mcm","clk":"11538937429","pt":1719472052597,"mc":[{"id":"1.230178326","rc":[{"atb":[[2,12.81],[2.02,6.54],[1.02,22.63]],"id":58221357},{"atl":[[990,0.16]],"id":58221357},{"atb":[[1.03,15.08],[2.12,6.54],[2.1,12.55]],"id":62600242},{"atl":[[1000,0.16]],"id":62600242},{"atb":[[2.06,6.54],[2.04,12.19],[1.02,22.63]],"id":60748118},{"atl":[[1000,0.16]],"id":60748118},{"atb":[[2,11.95],[2.02,6.54],[1.02,22.63]],"id":68687941},{"atl":[[990,0.16]],"id":68687941},{"atb":[[1.01,45.26],[2.1,6.54],[2.08,8.88]],"id":67674431},{"atl":[[1000,0.16]],"id":67674431},{"atb":[[1.02,22.63],[2.1,6.54],[2.08,13.32]],"id":65710029},{"atl":[[32,0.6],[1000,0.16]],"id":65710029},{"spn":17.05,"spf":"NaN","id":65710029}],"con":true,"img":false}]}
{"op":"mcm","clk":"11538940708","pt":1719472112854,"mc":[{"id":"1.230178326","rc":[{"atb":[[2,0]],"id":58221357},{"atb":[[2.1,0]],"id":62600242},{"atb":[[2.04,0]],"id":60748118},{"atb":[[2,0]],"id":68687941},{"atb":[[2.08,0]],"id":67674431},{"atb":[[2.08,0]],"id":65710029}],"con":true,"img":false}]}
{"op":"mcm","clk":"11538940714","pt":1719472112955,"mc":[{"id":"1.230178326","rc":[{"atb":[[2.04,12.81]],"id":58221357},{"atb":[[2.14,12.55]],"id":62600242},{"atb":[[2.08,12.19]],"id":60748118},{"atb":[[2.04,11.95]],"id":68687941},{"atb":[[2.12,8.88]],"id":67674431},{"atb":[[2.12,13.32]],"id":65710029}],"con":true,"img":false}]}
{"op":"mcm","clk":"11538942148","pt":1719472136070,"mc":[{"id":"1.230178326","rc":[{"atb":[[2.1,3.38]],"id":67674431}],"con":true,"img":false}]}
{"op":"mcm","clk":"11538942281","pt":1719472138014,"mc":[{"id":"1.230178326","rc":[{"atb":[[2.1,3.38]],"id":65710029}],"con":true,"img":false}]}
{"op":"mcm","clk":"11538942294","pt":1719472138322,"mc":[{"id":"1.230178326","rc":[{"atb":[[2.06,3.38]],"id":60748118}],"con":true,"img":false}]}
{"op":"mcm","clk":"11538942322","pt":1719472138687,"mc":[{"id":"1.230178326","rc":[{"atb":[[2.12,3.38]],"id":62600242}],"con":true,"img":false}]}
{"op":"mcm","clk":"11538942346","pt":1719472139093,"mc":[{"id":"1.230178326","rc":[{"atb":[[2.14,3.16]],"id":67674431}],"con":true,"img":false}]}
{"op":"mcm","clk":"11538942391","pt":1719472140014,"mc":[{"id":"1.230178326","rc":[{"atb":[[2.02,3.38]],"id":58221357}],"con":true,"img":false}]}
{"op":"mcm","clk":"11538942427","pt":1719472140528,"mc":[{"id":"1.230178326","rc":[{"atb":[[2.02,3.38]],"id":68687941}],"con":true,"img":false}]}
{"op":"mcm","clk":"11538942467","pt":1719472140991,"mc":[{"id":"1.230178326","rc":[{"atb":[[2.1,3.16]],"id":60748118}],"con":true,"img":false}]}
{"op":"mcm","clk":"11538942474","pt":1719472141094,"mc":[{"id":"1.230178326","rc":[{"atb":[[2.06,3.16]],"id":68687941}],"con":true,"img":false}]}
{"op":"mcm","clk":"11538942530","pt":1719472141712,"mc":[{"id":"1.230178326","rc":[{"atb":[[2.06,3.16]],"id":58221357}],"con":true,"img":false}]}
{"op":"mcm","clk":"11538942573","pt":1719472142325,"mc":[{"id":"1.230178326","rc":[{"atb":[[2.14,3.16]],"id":65710029}],"con":true,"img":false}]}
{"op":"mcm","clk":"11538942581","pt":1719472142380,"mc":[{"id":"1.230178326","rc":[{"atb":[[2.16,3.16]],"id":62600242}],"con":true,"img":false}]}
{"op":"mcm","clk":"11538942955","pt":1719472147802,"mc":[{"id":"1.230178326","rc":[{"atb":[[2.02,0]],"id":58221357}],"con":true,"img":false}]}
{"op":"mcm","clk":"11538942981","pt":1719472148103,"mc":[{"id":"1.230178326","rc":[{"atb":[[2.06,0]],"id":60748118}],"con":true,"img":false}]}
{"op":"mcm","clk":"11538943009","pt":1719472148511,"mc":[{"id":"1.230178326","rc":[{"atb":[[2.12,0]],"id":62600242},{"atb":[[2.1,0]],"id":67674431}],"con":true,"img":false}]}
{"op":"mcm","clk":"11538943045","pt":1719472149129,"mc":[{"id":"1.230178326","rc":[{"atb":[[2.02,0]],"id":68687941},{"atb":[[2.1,0]],"id":65710029}],"con":true,"img":false}]}
{"op":"mcm","clk":"11538943496","pt":1719472156411,"mc":[{"id":"1.230178326","rc":[{"atb":[[2.1,6.54]],"id":60748118}],"con":true,"img":false}]}
{"op":"mcm","clk":"11538943504","pt":1719472156512,"mc":[{"id":"1.230178326","rc":[{"atb":[[2.06,6.54]],"id":58221357}],"con":true,"img":false}]}
{"op":"mcm","clk":"11538943535","pt":1719472157125,"mc":[{"id":"1.230178326","rc":[{"atb":[[2.16,6.54]],"id":62600242}],"con":true,"img":false}]}
{"op":"mcm","clk":"11538943549","pt":1719472157431,"mc":[{"id":"1.230178326","rc":[{"atb":[[2.14,6.54]],"id":67674431}],"con":true,"img":false}]}
{"op":"mcm","clk":"11538943647","pt":1719472159528,"mc":[{"id":"1.230178326","rc":[{"atb":[[2.14,6.54]],"id":65710029}],"con":true,"img":false}]}
{"op":"mcm","clk":"11538943673","pt":1719472160038,"mc":[{"id":"1.230178326","rc":[{"atb":[[2.06,6.54]],"id":68687941}],"con":true,"img":false}]}
{"op":"mcm","clk":"11539041520","pt":1719474194546,"mc":[{"id":"1.230178326","rc":[{"atl":[[150,4]],"id":58221357},{"spn":76.03,"spf":"NaN","id":58221357},{"atl":[[150,4]],"id":62600242},{"spn":76.08,"spf":"NaN","id":62600242},{"atl":[[150,4]],"id":60748118},{"spn":76.05,"spf":"NaN","id":60748118},{"atl":[[150,4]],"id":68687941},{"spn":76.03,"spf":"NaN","id":68687941},{"atl":[[150,4]],"id":67674431},{"spn":76.07,"spf":"NaN","id":67674431},{"atl":[[150,4]],"id":65710029},{"spn":17.07,"spf":"NaN","id":65710029}],"con":true,"img":false}]}
{"op":"mcm","clk":"11539122556","pt":1719475682556,"mc":[{"id":"1.230178326","marketDefinition":{"bspMarket":true,"turnInPlayEnabled":false,"persistenceEnabled":false,"marketBaseRate":5.0,"eventId":"33376062","eventTypeId":"4339","numberOfWinners":1,"bettingType":"ODDS","marketType":"WIN","marketTime":"2024-06-27T16:43:00.000Z","suspendTime":"2024-06-27T16:43:00.000Z","bspReconciled":false,"complete":true,"inPlay":false,"crossMatching":true,"runnersVoidable":false,"numberOfActiveRunners":6,"betDelay":0,"status":"OPEN","runners":[{"status":"ACTIVE","sortPriority":1,"id":58221357,"name":"1. Ballymac Wynett"},{"status":"ACTIVE","sortPriority":2,"id":62600242,"name":"2. Swanley Petunia"},{"status":"ACTIVE","sortPriority":3,"id":60748118,"name":"3. Ballymac Dom"},{"status":"ACTIVE","sortPriority":4,"id":67674431,"name":"4. Fairyhill Daisy"},{"status":"ACTIVE","sortPriority":5,"id":68687941,"name":"5. Killieford Negri"},{"status":"ACTIVE","sortPriority":6,"id":65710029,"name":"6. Da Man Joey"}],"regulators":["MR_INT"],"venue":"Kinsley","countryCode":"GB","discountAllowed":true,"timezone":"Europe/London","openDate":"2024-06-27T13:36:00.000Z","version":5994643771,"name":"A3 462m","eventName":"Kinsley 27th Jun"},"rc":[{"atb":[[2.06,6.55],[2.04,12.81],[1.02,22.64]],"id":58221357},{"atl":[[150,4],[990,0.16]],"id":58221357},{"spn":76.03,"spf":"NaN","id":58221357},{"atb":[[1.03,15.09],[2.16,6.55],[2.14,12.55]],"id":62600242},{"atl":[[150,4],[1000,0.16]],"id":62600242},{"spn":76.08,"spf":"NaN","id":62600242},{"atb":[[1.02,22.64],[2.1,6.55],[2.08,12.2]],"id":60748118},{"atl":[[150,4],[1000,0.16]],"id":60748118},{"spn":76.05,"spf":"NaN","id":60748118},{"atb":[[2.06,6.55],[2.04,11.96],[1.02,22.64]],"id":68687941},{"atl":[[150,4],[990,0.16]],"id":68687941},{"spn":76.03,"spf":"NaN","id":68687941},{"atb":[[1.01,45.28],[2.12,8.88],[2.14,6.55]],"id":67674431},{"atl":[[150,4],[1000,0.16]],"id":67674431},{"spn":76.07,"spf":"NaN","id":67674431},{"atb":[[1.02,22.64],[2.12,13.32],[2.14,6.55]],"id":65710029},{"atl":[[32,0.6],[150,4],[1000,0.16]],"id":65710029},{"spn":17.07,"spf":"NaN","id":65710029}],"con":true,"img":true}]}
{"op":"mcm","clk":"11539128021","pt":1719475713020,"mc":[{"id":"1.230178326","rc":[{"atb":[[2.06,6.55],[2.04,0],[1.02,22.64]],"id":58221357},{"atb":[[1.03,15.09],[2.16,6.55],[2.14,0]],"id":62600242},{"atb":[[1.02,22.64],[2.1,6.55],[2.08,0]],"id":60748118},{"atb":[[2.06,6.55],[2.04,0],[1.02,22.64]],"id":68687941},{"atb":[[1.01,45.28],[2.12,0],[2.14,6.55]],"id":67674431},{"atb":[[1.02,22.64],[2.12,0],[2.14,6.55]],"id":65710029}],"con":true,"img":false}]}
{"op":"mcm","clk":"11539128028","pt":1719475713123,"mc":[{"id":"1.230178326","rc":[{"atb":[[2.08,12.81]],"id":58221357},{"atb":[[2.18,12.55]],"id":62600242},{"atb":[[2.12,12.2]],"id":60748118},{"atb":[[2.08,11.96]],"id":68687941},{"atb":[[2.16,8.88]],"id":67674431},{"atb":[[2.16,13.32]],"id":65710029}],"con":true,"img":false}]}
{"op":"mcm","clk":"11539132288","pt":1719475782389,"mc":[{"id":"1.230178326","rc":[{"spn":76.04,"spf":"NaN","id":58221357},{"spn":76.09,"spf":"NaN","id":62600242},{"spn":76.06,"spf":"NaN","id":60748118},{"spn":76.04,"spf":"NaN","id":68687941},{"spn":76.08,"spf":"NaN","id":67674431},{"atb":[[2.14,3.16]],"id":65710029},{"spn":17.08,"spf":"NaN","id":65710029}],"con":true,"img":false}]}
{"op":"mcm","clk":"11539132310","pt":1719475782694,"mc":[{"id":"1.230178326","rc":[{"atb":[[2.16,3.16]],"id":62600242}],"con":true,"img":false}]}
{"op":"mcm","clk":"11539132370","pt":1719475783676,"mc":[{"id":"1.230178326","rc":[{"atb":[[2.06,3.16]],"id":58221357}],"con":true,"img":false}]}
{"op":"mcm","clk":"11539132392","pt":1719475784088,"mc":[{"id":"1.230178326","rc":[{"atb":[[2.14,3.16]],"id":67674431}],"con":true,"img":false}]}
{"op":"mcm","clk":"11539132403","pt":1719475784291,"mc":[{"id":"1.230178326","rc":[{"atb":[[2.06,3.16]],"id":68687941}],"con":true,"img":false}]}
{"op":"mcm","clk":"11539132420","pt":1719475784595,"mc":[{"id":"1.230178326","rc":[{"atb":[[2.1,3.16]],"id":60748118}],"con":true,"img":false}]}
{"op":"mcm","clk":"11539132611","pt":1719475787388,"mc":[{"id":"1.230178326","rc":[{"atb":[[2.2,3.38]],"id":62600242}],"con":true,"img":false}]}
{"op":"mcm","clk":"11539132646","pt":1719475787897,"mc":[{"id":"1.230178326","rc":[{"atb":[[2.18,3.38]],"id":67674431}],"con":true,"img":false}]}
{"op":"mcm","clk":"11539132659","pt":1719475788104,"mc":[{"id":"1.230178326","rc":[{"atb":[[2.1,3.38]],"id":68687941}],"con":true,"img":false}]}
{"op":"mcm","clk":"11539132680","pt":1719475788412,"mc":[{"id":"1.230178326","rc":[{"atb":[[2.1,3.38]],"id":58221357}],"con":true,"img":false}]}
{"op":"mcm","clk":"11539132705","pt":1719475788672,"mc":[{"id":"1.230178326","rc":[{"atb":[[2.18,3.38]],"id":65710029}],"con":true,"img":false}]}
{"op":"mcm","clk":"11539132734","pt":1719475788983,"mc":[{"id":"1.230178326","rc":[{"atb":[[2.14,3.38]],"id":60748118}],"con":true,"img":false}]}
{"op":"mcm","clk":"11539134256","pt":1719475810013,"mc":[{"id":"1.230178326","rc":[{"atb":[[2.06,0]],"id":58221357},{"atb":[[2.16,0]],"id":62600242},{"atb":[[2.1,0]],"id":60748118},{"atb":[[2.06,0]],"id":68687941},{"atb":[[2.14,0]],"id":67674431},{"atb":[[2.14,0]],"id":65710029}],"con":true,"img":false}]}
{"op":"mcm","clk":"11539153001","pt":1719476112970,"mc":[{"id":"1.230178326","rc":[{"atb":[[2.1,6.55]],"id":58221357},{"spn":76.05,"spf":"NaN","id":58221357},{"spn":76.1,"spf":"NaN","id":62600242},{"spn":76.07,"spf":"NaN","id":60748118},{"spn":76.05,"spf":"NaN","id":68687941},{"spn":76.09,"spf":"NaN","id":67674431},{"spn":17.09,"spf":"NaN","id":65710029}],"con":true,"img":false}]}
{"op":"mcm","clk":"11539153018","pt":1719476113177,"mc":[{"id":"1.230178326","rc":[{"atb":[[2.14,6.55]],"id":60748118}],"con":true,"img":false}]}
{"op":"mcm","clk":"11539153026","pt":1719476113278,"mc":[{"id":"1.230178326","rc":[{"atb":[[2.18,6.55]],"id":67674431}],"con":true,"img":false}]}
{"op":"mcm","clk":"11539153032","pt":1719476113382,"mc":[{"id":"1.230178326","rc":[{"atb":[[2.1,6.55]],"id":68687941}],"con":true,"img":false}]}
{"op":"mcm","clk":"11539153047","pt":1719476113590,"mc":[{"id":"1.230178326","rc":[{"atb":[[2.2,6.55]],"id":62600242}],"con":true,"img":false}]}
{"op":"mcm","clk":"11539153052","pt":1719476113694,"mc":[{"id":"1.230178326","rc":[{"atb":[[2.18,6.55]],"id":65710029}],"con":true,"img":false}]}
{"op":"mcm","clk":"11539341477","pt":1719479311488,"mc":[{"id":"1.230178326","rc":[{"atb":[[1.02,22.63],[2.1,6.54],[2.08,0]],"id":58221357},{"atb":[[1.03,15.09],[2.18,0],[2.2,6.54]],"id":62600242},{"atb":[[1.02,22.63],[2.12,0],[2.14,6.54]],"id":60748118},{"atb":[[1.02,22.63],[2.1,6.54],[2.08,0]],"id":68687941},{"atb":[[1.01,45.27],[2.18,6.54],[2.16,0]],"id":67674431},{"atb":[[1.02,22.63],[2.18,6.54],[2.16,0]],"id":65710029}],"con":true,"img":false}]}
{"op":"mcm","clk":"11539341488","pt":1719479311542,"mc":[{"id":"1.230178326","rc":[{"atb":[[2.12,12.81]],"id":58221357},{"atb":[[2.22,12.55]],"id":62600242},{"atb":[[2.16,12.19]],"id":60748118},{"atb":[[2.12,11.96]],"id":68687941},{"atb":[[2.2,8.88]],"id":67674431},{"atb":[[2.2,13.32]],"id":65710029}],"con":true,"img":false}]}
{"op":"mcm","clk":"11539346309","pt":1719479388751,"mc":[{"id":"1.230178326","rc":[{"spn":76.06,"spf":"NaN","id":58221357},{"spn":76.11,"spf":"NaN","id":62600242},{"atb":[[2.14,3.38]],"id":60748118},{"spn":76.08,"spf":"NaN","id":60748118},{"spn":76.06,"spf":"NaN","id":68687941},{"spn":76.1,"spf":"NaN","id":67674431},{"atb":[[2.18,3.38]],"id":65710029},{"spn":17.1,"spf":"NaN","id":65710029}],"con":true,"img":false}]}
{"op":"mcm","clk":"11539346330","pt":1719479389059,"mc":[{"id":"1.230178326","rc":[{"atb":[[2.18,3.38]],"id":67674431}],"con":true,"img":false}]}
{"op":"mcm","clk":"11539346361","pt":1719479389429,"mc":[{"id":"1.230178326","rc":[{"atb":[[2.2,3.38]],"id":62600242}],"con":true,"img":false}]}
{"op":"mcm","clk":"11539346440","pt":1719479390662,"mc":[{"id":"1.230178326","rc":[{"atb":[[2.1,3.38]],"id":58221357}],"con":true,"img":false}]}
{"op":"mcm","clk":"11539346484","pt":1719479391333,"mc":[{"id":"1.230178326","rc":[{"atb":[[2.1,3.38]],"id":68687941}],"con":true,"img":false}]}
{"op":"mcm","clk":"11539348314","pt":1719479420710,"mc":[{"id":"1.230178326","rc":[{"atb":[[2.1,0]],"id":58221357}],"con":true,"img":false}]}
{"op":"mcm","clk":"11539348352","pt":1719479421357,"mc":[{"id":"1.230178326","rc":[{"atb":[[2.14,0]],"id":60748118}],"con":true,"img":false}]}
{"op":"mcm","clk":"11539348360","pt":1719479421414,"mc":[{"id":"1.230178326","rc":[{"atb":[[2.2,0]],"id":62600242}],"con":true,"img":false}]}
{"op":"mcm","clk":"11539348384","pt":1719479421721,"mc":[{"id":"1.230178326","rc":[{"atb":[[2.18,0]],"id":65710029}],"con":true,"img":false}]}
{"op":"mcm","clk":"11539348433","pt":1719479422398,"mc":[{"id":"1.230178326","rc":[{"atb":[[2.18,0]],"id":67674431}],"con":true,"img":false}]}
{"op":"mcm","clk":"11539348442","pt":1719479422500,"mc":[{"id":"1.230178326","rc":[{"atb":[[2.1,0]],"id":68687941}],"con":true,"img":false}]}
{"op":"mcm","clk":"11539348490","pt":1719479423223,"mc":[{"id":"1.230178326","rc":[{"atb":[[2.14,3.38]],"id":58221357}],"con":true,"img":false}]}
{"op":"mcm","clk":"11539348541","pt":1719479423899,"mc":[{"id":"1.230178326","rc":[{"atb":[[2.22,3.38]],"id":65710029}],"con":true,"img":false}]}
{"op":"mcm","clk":"11539348575","pt":1719479424404,"mc":[{"id":"1.230178326","rc":[{"atb":[[2.24,3.38]],"id":62600242}],"con":true,"img":false}]}
{"op":"mcm","clk":"11539348589","pt":1719479424616,"mc":[{"id":"1.230178326","rc":[{"atb":[[2.14,3.38]],"id":68687941}],"con":true,"img":false}]}
{"op":"mcm","clk":"11539348595","pt":1719479424715,"mc":[{"id":"1.230178326","rc":[{"atb":[[2.22,3.38]],"id":67674431}],"con":true,"img":false}]}
{"op":"mcm","clk":"11539348677","pt":1719479426110,"mc":[{"id":"1.230178326","rc":[{"atb":[[2.18,3.38]],"id":60748118}],"con":true,"img":false}]}
{"op":"mcm","clk":"11539367264","pt":1719479702107,"mc":[{"id":"1.230178326","rc":[{"spn":76.07,"spf":"NaN","id":58221357},{"spn":76.12,"spf":"NaN","id":62600242},{"spn":76.09,"spf":"NaN","id":60748118},{"spn":76.07,"spf":"NaN","id":68687941},{"atb":[[2.22,6.54]],"id":67674431},{"spn":76.11,"spf":"NaN","id":67674431},{"spn":17.11,"spf":"NaN","id":65710029}],"con":true,"img":false}]}
{"op":"mcm","clk":"11539367281","pt":1719479702312,"mc":[{"id":"1.230178326","rc":[{"atb":[[2.18,6.54]],"id":60748118}],"con":true,"img":false}]}
{"op":"mcm","clk":"11539367325","pt":1719479702728,"mc":[{"id":"1.230178326","rc":[{"atb":[[2.14,6.54]],"id":68687941}],"con":true,"img":false}]}
{"op":"mcm","clk":"11539367367","pt":1719479703189,"mc":[{"id":"1.230178326","rc":[{"atb":[[2.24,6.54]],"id":62600242}],"con":true,"img":false}]}
{"op":"mcm","clk":"11539367462","pt":1719479704269,"mc":[{"id":"1.230178326","rc":[{"atb":[[2.14,6.54]],"id":58221357}],"con":true,"img":false}]}
{"op":"mcm","clk":"11539367504","pt":1719479704781,"mc":[{"id":"1.230178326","rc":[{"atb":[[2.22,6.54]],"id":65710029}],"con":true,"img":false}]}
{"op":"mcm","clk":"11539402384","pt":1719480366083,"mc":[{"id":"1.230178326","rc":[{"spl":[[5,1]],"id":62600242},{"spn":3.62,"spf":1.0,"id":62600242}],"con":true,"img":false}]}
{"op":"mcm","clk":"11539545513","pt":1719482911572,"mc":[{"id":"1.230178326","rc":[{"atb":[[1.02,22.63],[2.12,0],[2.14,6.54]],"id":58221357},{"atb":[[2.24,6.54],[1.03,15.08],[2.22,0]],"id":62600242},{"atb":[[1.02,22.63],[2.18,6.54],[2.16,0]],"id":60748118},{"atb":[[1.02,22.63],[2.12,0],[2.14,6.54]],"id":68687941},{"atb":[[1.01,45.26],[2.22,6.54],[2.2,0]],"id":67674431},{"atb":[[2.22,6.54],[1.02,22.63],[2.2,0]],"id":65710029}],"con":true,"img":false}]}
{"op":"mcm","clk":"11539545520","pt":1719482911675,"mc":[{"id":"1.230178326","rc":[{"atb":[[2.16,12.81]],"id":58221357},{"atb":[[2.26,12.55]],"id":62600242},{"atb":[[2.2,12.19]],"id":60748118},{"atb":[[2.16,11.95]],"id":68687941},{"atb":[[2.24,8.88]],"id":67674431},{"atb":[[2.24,13.32]],"id":65710029}],"con":true,"img":false}]}
{"op":"mcm","clk":"11539547507","pt":1719482940606,"mc":[{"id":"1.230178326","rc":[{"atb":[[2.14,3.16]],"id":58221357},{"atb":[[2.22,3.16]],"id":65710029}],"con":true,"img":false}]}
{"op":"mcm","clk":"11539547527","pt":1719482940928,"mc":[{"id":"1.230178326","rc":[{"atb":[[2.26,3.38]],"id":65710029}],"con":true,"img":false}]}
{"op":"mcm","clk":"11539547529","pt":1719482941022,"mc":[{"id":"1.230178326","rc":[{"atb":[[2.22,3.16]],"id":67674431}],"con":true,"img":false}]}
{"op":"mcm","clk":"11539547551","pt":1719482941336,"mc":[{"id":"1.230178326","rc":[{"atb":[[2.18,3.16]],"id":60748118}],"con":true,"img":false}]}
{"op":"mcm","clk":"11539547566","pt":1719482941602,"mc":[{"id":"1.230178326","rc":[{"atb":[[2.24,3.16]],"id":62600242}],"con":true,"img":false}]}
{"op":"mcm","clk":"11539547597","pt":1719482942114,"mc":[{"id":"1.230178326","rc":[{"atb":[[2.14,3.16]],"id":68687941}],"con":true,"img":false}]}
{"op":"mcm","clk":"11539547708","pt":1719482944106,"mc":[{"id":"1.230178326","rc":[{"atb":[[2.18,3.38]],"id":58221357}],"con":true,"img":false}]}
{"op":"mcm","clk":"11539547714","pt":1719482944209,"mc":[{"id":"1.230178326","rc":[{"atb":[[2.22,3.38]],"id":60748118}],"con":true,"img":false}]}
{"op":"mcm","clk":"11539547733","pt":1719482944523,"mc":[{"id":"1.230178326","rc":[{"atb":[[2.26,3.38]],"id":67674431}],"con":true,"img":false}]}
{"op":"mcm","clk":"11539547771","pt":1719482945093,"mc":[{"id":"1.230178326","rc":[{"atb":[[2.28,3.38]],"id":62600242}],"con":true,"img":false}]}
{"op":"mcm","clk":"11539547793","pt":1719482945407,"mc":[{"id":"1.230178326","rc":[{"atb":[[2.18,3.38]],"id":68687941}],"con":true,"img":false}]}
{"op":"mcm","clk":"11539552662","pt":1719483019802,"mc":[{"id":"1.230178326","rc":[{"atb":[[2.14,0]],"id":58221357},{"spn":76.09,"spf":"NaN","id":58221357},{"spn":3.64,"spf":1.0,"id":62600242},{"spn":76.11,"spf":"NaN","id":60748118},{"spn":76.09,"spf":"NaN","id":68687941},{"spn":76.13,"spf":"NaN","id":67674431},{"spn":17.13,"spf":"NaN","id":65710029}],"con":true,"img":false}]}
{"op":"mcm","clk":"11539552709","pt":1719483020281,"mc":[{"id":"1.230178326","rc":[{"atb":[[2.22,0]],"id":67674431}],"con":true,"img":false}]}
{"op":"mcm","clk":"11539552728","pt":1719483020483,"mc":[{"id":"1.230178326","rc":[{"atb":[[2.22,0]],"id":65710029}],"con":true,"img":false}]}
{"op":"mcm","clk":"11539552760","pt":1719483020791,"mc":[{"id":"1.230178326","rc":[{"atb":[[2.24,0]],"id":62600242}],"con":true,"img":false}]}
{"op":"mcm","clk":"11539552779","pt":1719483020997,"mc":[{"id":"1.230178326","rc":[{"atb":[[2.18,6.54]],"id":58221357}],"con":true,"img":false}]}
{"op":"mcm","clk":"11539552811","pt":1719483021412,"mc":[{"id":"1.230178326","rc":[{"atb":[[2.14,0]],"id":68687941}],"con":true,"img":false}]}
{"op":"mcm","clk":"11539552832","pt":1719483021620,"mc":[{"id":"1.230178326","rc":[{"atb":[[2.28,6.54]],"id":62600242}],"con":true,"img":false}]}
{"op":"mcm","clk":"11539552858","pt":1719483021883,"mc":[{"id":"1.230178326","rc":[{"atb":[[2.18,0]],"id":60748118}],"con":true,"img":false}]}
{"op":"mcm","clk":"11539552909","pt":1719483022502,"mc":[{"id":"1.230178326","rc":[{"atb":[[2.26,6.54]],"id":65710029}],"con":true,"img":false}]}
{"op":"mcm","clk":"11539553005","pt":1719483023800,"mc":[{"id":"1.230178326","rc":[{"atb":[[2.26,6.54]],"id":67674431}],"con":true,"img":false}]}
{"op":"mcm","clk":"11539553074","pt":1719483024679,"mc":[{"id":"1.230178326","rc":[{"atb":[[2.22,6.54]],"id":60748118}],"con":true,"img":false}]}
{"op":"mcm","clk":"11539553083","pt":1719483024784,"mc":[{"id":"1.230178326","rc":[{"atb":[[2.18,6.54]],"id":68687941}],"con":true,"img":false}]}
{"op":"mcm","clk":"11539810829","pt":1719486482542,"mc":[{"id":"1.230178326","marketDefinition":{"bspMarket":true,"turnInPlayEnabled":false,"persistenceEnabled":false,"marketBaseRate":5.0,"eventId":"33376062","eventTypeId":"4339","numberOfWinners":1,"bettingType":"ODDS","marketType":"WIN","marketTime":"2024-06-27T16:43:00.000Z","suspendTime":"2024-06-27T16:43:00.000Z","bspReconciled":false,"complete":true,"inPlay":false,"crossMatching":true,"runnersVoidable":false,"numberOfActiveRunners":6,"betDelay":0,"status":"OPEN","runners":[{"status":"ACTIVE","sortPriority":1,"id":58221357,"name":"1. Ballymac Wynett"},{"status":"ACTIVE","sortPriority":2,"id":62600242,"name":"2. Swanley Petunia"},{"status":"ACTIVE","sortPriority":3,"id":60748118,"name":"3. Ballymac Dom"},{"status":"ACTIVE","sortPriority":4,"id":67674431,"name":"4. Fairyhill Daisy"},{"status":"ACTIVE","sortPriority":5,"id":68687941,"name":"5. Killieford Negri"},{"status":"ACTIVE","sortPriority":6,"id":65710029,"name":"6. Da Man Joey"}],"regulators":["MR_INT"],"venue":"Kinsley","countryCode":"GB","discountAllowed":true,"timezone":"Europe/London","openDate":"2024-06-27T13:36:00.000Z","version":5994643771,"name":"A3 462m","eventName":"Kinsley 27th Jun"},"rc":[{"atb":[[1.02,22.63],[2.18,6.54],[2.16,12.81]],"id":58221357},{"atl":[[150,4],[990,0.16]],"id":58221357},{"spn":76.09,"spf":"NaN","id":58221357},{"spl":[[5,1]],"id":62600242},{"atb":[[1.03,15.09],[2.28,6.54],[2.26,12.55]],"id":62600242},{"atl":[[150,4],[1000,0.16]],"id":62600242},{"spn":3.64,"spf":1.0,"id":62600242},{"atb":[[2.22,6.54],[1.02,22.63],[2.2,12.19]],"id":60748118},{"atl":[[150,4],[1000,0.16]],"id":60748118},{"spn":76.11,"spf":"NaN","id":60748118},{"atb":[[1.02,22.63],[2.18,6.54],[2.16,11.96]],"id":68687941},{"atl":[[150,4],[990,0.16]],"id":68687941},{"spn":76.09,"spf":"NaN","id":68687941},{"atb":[[2.24,8.88],[1.01,45.27],[2.26,6.54]],"id":67674431},{"atl":[[150,4],[1000,0.16]],"id":67674431},{"spn":76.13,"spf":"NaN","id":67674431},{"atb":[[2.24,13.32],[1.02,22.63],[2.26,6.54]],"id":65710029},{"atl":[[32,0.6],[150,4],[1000,0.16]],"id":65710029},{"spn":17.13,"spf":"NaN","id":65710029}],"con":true,"img":true}]}
{"op":"mcm","clk":"11539817520","pt":1719486508323,"mc":[{"id":"1.230178326","rc":[{"atb":[[1.02,22.63],[2.18,6.54],[2.16,0]],"id":58221357},{"atb":[[1.03,15.09],[2.28,6.54],[2.26,0]],"id":62600242},{"atb":[[2.22,6.54],[1.02,22.63],[2.2,0]],"id":60748118},{"atb":[[1.02,22.63],[2.18,6.54],[2.16,0]],"id":68687941},{"atb":[[2.24,0],[1.01,45.27],[2.26,6.54]],"id":67674431},{"atb":[[2.24,0],[1.02,22.63],[2.26,6.54]],"id":65710029}],"con":true,"img":false}]}
{"op":"mcm","clk":"11539817530","pt":1719486508426,"mc":[{"id":"1.230178326","rc":[{"atb":[[2.2,12.81]],"id":58221357},{"atb":[[2.3,12.55]],"id":62600242},{"atb":[[2.24,12.19]],"id":60748118},{"atb":[[2.2,11.96]],"id":68687941},{"atb":[[2.28,8.88]],"id":67674431},{"atb":[[2.28,13.32]],"id":65710029}],"con":true,"img":false}]}
{"op":"mcm","clk":"11539818063","pt":1719486514549,"mc":[{"id":"1.230178326","rc":[{"atb":[[2.28,3.38]],"id":62600242}],"con":true,"img":false}]}
{"op":"mcm","clk":"11539818120","pt":1719486515221,"mc":[{"id":"1.230178326","rc":[{"atb":[[2.22,3.38]],"id":60748118}],"con":true,"img":false}]}
{"op":"mcm","clk":"11539818151","pt":1719486515634,"mc":[{"id":"1.230178326","rc":[{"atb":[[2.26,3.38]],"id":67674431}],"con":true,"img":false}]}
{"op":"mcm","clk":"11539818171","pt":1719486515837,"mc":[{"id":"1.230178326","rc":[{"atb":[[2.3,3.16]],"id":67674431}],"con":true,"img":false}]}
{"op":"mcm","clk":"11539818203","pt":1719486516253,"mc":[{"id":"1.230178326","rc":[{"atb":[[2.26,3.38]],"id":65710029}],"con":true,"img":false}]}
{"op":"mcm","clk":"11539818213","pt":1719486516357,"mc":[{"id":"1.230178326","rc":[{"atb":[[2.18,3.38]],"id":58221357}],"con":true,"img":false}]}
{"op":"mcm","clk":"11539818224","pt":1719486516458,"mc":[{"id":"1.230178326","rc":[{"atb":[[2.26,3.16]],"id":60748118}],"con":true,"img":false}]}
{"op":"mcm","clk":"11539818295","pt":1719486517045,"mc":[{"id":"1.230178326","rc":[{"atb":[[2.22,3.16]],"id":58221357}],"con":true,"img":false}]}
{"op":"mcm","clk":"11539818317","pt":1719486517261,"mc":[{"id":"1.230178326","rc":[{"atb":[[2.32,3.16]],"id":62600242}],"con":true,"img":false}]}
{"op":"mcm","clk":"11539818360","pt":1719486517631,"mc":[{"id":"1.230178326","rc":[{"atb":[[2.3,3.16]],"id":65710029}],"con":true,"img":false}]}
{"op":"mcm","clk":"11539818387","pt":1719486517836,"mc":[{"id":"1.230178326","rc":[{"atb":[[2.18,3.38]],"id":68687941}],"con":true,"img":false}]}
{"op":"mcm","clk":"11539818409","pt":1719486518042,"mc":[{"id":"1.230178326","rc":[{"atb":[[2.22,3.16]],"id":68687941}],"con":true,"img":false}]}
{"op":"mcm","clk":"11539831802","pt":1719486678484,"mc":[{"id":"1.230178326","rc":[{"atb":[[2.18,0]],"id":58221357},{"spn":76.11,"spf":"NaN","id":58221357},{"spn":3.66,"spf":1.0,"id":62600242},{"spn":76.13,"spf":"NaN","id":60748118},{"spn":76.11,"spf":"NaN","id":68687941},{"spn":76.15,"spf":"NaN","id":67674431},{"spn":17.15,"spf":"NaN","id":65710029}],"con":true,"img":false}]}
{"op":"mcm","clk":"11539831807","pt":1719486678587,"mc":[{"id":"1.230178326","rc":[{"atb":[[2.18,0]],"id":68687941}],"con":true,"img":false}]}
{"op":"mcm","clk":"11539831824","pt":1719486678797,"mc":[{"id":"1.230178326","rc":[{"atb":[[2.28,0]],"id":62600242}],"con":true,"img":false}]}
{"op":"mcm","clk":"11539831857","pt":1719486679250,"mc":[{"id":"1.230178326","rc":[{"atb":[[2.26,0]],"id":67674431}],"con":true,"img":false}]}
{"op":"mcm","clk":"11539831881","pt":1719486679500,"mc":[{"id":"1.230178326","rc":[{"atb":[[2.26,0]],"id":65710029}],"con":true,"img":false}]}
{"op":"mcm","clk":"11539831906","pt":1719486679815,"mc":[{"id":"1.230178326","rc":[{"atb":[[2.22,0]],"id":60748118}],"con":true,"img":false}]}
{"op":"mcm","clk":"11539831934","pt":1719486680127,"mc":[{"id":"1.230178326","rc":[{"atb":[[2.22,6.54]],"id":58221357}],"con":true,"img":false}]}
{"op":"mcm","clk":"11539831970","pt":1719486680493,"mc":[{"id":"1.230178326","rc":[{"atb":[[2.22,6.54]],"id":68687941}],"con":true,"img":false}]}
{"op":"mcm","clk":"11539831992","pt":1719486680802,"mc":[{"id":"1.230178326","rc":[{"atb":[[2.32,6.54]],"id":62600242},{"atb":[[2.3,6.54]],"id":65710029}],"con":true,"img":false}]}
{"op":"mcm","clk":"11539832042","pt":1719486681525,"mc":[{"id":"1.230178326","rc":[{"atb":[[2.3,6.54]],"id":67674431}],"con":true,"img":false}]}
{"op":"mcm","clk":"11539832070","pt":1719486681897,"mc":[{"id":"1.230178326","rc":[{"atb":[[2.26,6.54]],"id":60748118}],"con":true,"img":false}]}
{"op":"mcm","clk":"11539840723","pt":1719486808244,"mc":[{"id":"1.230178326","rc":[{"atb":[[2.2,0]],"id":58221357},{"atb":[[2.3,0]],"id":62600242},{"atb":[[2.24,0]],"id":60748118},{"atb":[[2.2,0]],"id":68687941},{"atb":[[2.28,0]],"id":67674431},{"atb":[[2.28,0]],"id":65710029}],"con":true,"img":false}]}
{"op":"mcm","clk":"11539840730","pt":1719486808343,"mc":[{"id":"1.230178326","rc":[{"atb":[[2.24,12.81]],"id":58221357},{"atb":[[2.34,12.55]],"id":62600242},{"atb":[[2.28,12.19]],"id":60748118},{"atb":[[2.24,11.96]],"id":68687941},{"atb":[[2.32,8.88]],"id":67674431},{"atb":[[2.32,13.32]],"id":65710029}],"con":true,"img":false}]}
{"op":"mcm","clk":"11539841400","pt":1719486819241,"mc":[{"id":"1.230178326","rc":[{"atb":[[2.22,3.38]],"id":58221357},{"atb":[[2.32,3.38]],"id":62600242},{"atb":[[2.26,3.38]],"id":60748118},{"atb":[[2.22,3.38]],"id":68687941},{"atb":[[2.3,3.38]],"id":67674431},{"atb":[[2.3,3.38]],"id":65710029}],"con":true,"img":false}]}
{"op":"mcm","clk":"11539842890","pt":1719486841889,"mc":[{"id":"1.230178326","rc":[{"atb":[[2.22,0]],"id":58221357},{"atb":[[2.32,0]],"id":62600242},{"atb":[[2.26,0]],"id":60748118},{"atb":[[2.22,0]],"id":68687941},{"atb":[[2.3,0]],"id":67674431},{"atb":[[2.3,0]],"id":65710029}],"con":true,"img":false}]}
{"op":"mcm","clk":"11539848464","pt":1719486920474,"mc":[{"id":"1.230178326","rc":[{"atb":[[2.26,3.38]],"id":58221357},{"spn":76.13,"spf":"NaN","id":58221357},{"spn":3.67,"spf":1.0,"id":62600242},{"spn":76.14,"spf":"NaN","id":60748118},{"spn":76.12,"spf":"NaN","id":68687941},{"spn":76.16,"spf":"NaN","id":67674431},{"spn":17.16,"spf":"NaN","id":65710029}],"con":true,"img":false}]}
{"op":"mcm","clk":"11539848478","pt":1719486920742,"mc":[{"id":"1.230178326","rc":[{"atb":[[2.3,3.38]],"id":60748118}],"con":true,"img":false}]}
{"op":"mcm","clk":"11539848481","pt":1719486920841,"mc":[{"id":"1.230178326","rc":[{"atb":[[2.36,3.38]],"id":62600242}],"con":true,"img":false}]}
{"op":"mcm","clk":"11539848526","pt":1719486921459,"mc":[{"id":"1.230178326","rc":[{"atb":[[2.34,3.38]],"id":65710029}],"con":true,"img":false}]}
{"op":"mcm","clk":"11539848535","pt":1719486921564,"mc":[{"id":"1.230178326","rc":[{"atb":[[2.26,3.38]],"id":68687941}],"con":true,"img":false}]}
{"op":"mcm","clk":"11539848580","pt":1719486922234,"mc":[{"id":"1.230178326","rc":[{"atb":[[2.34,3.38]],"id":67674431}],"con":true,"img":false}]}
{"op":"mcm","clk":"11539850203","pt":1719486943487,"mc":[{"id":"1.230178326","rc":[{"atb":[[2.26,6.54]],"id":58221357},{"atb":[[2.36,6.54]],"id":62600242}],"con":true,"img":false}]}
{"op":"mcm","clk":"11539850215","pt":1719486943689,"mc":[{"id":"1.230178326","rc":[{"atb":[[2.34,6.54]],"id":65710029}],"con":true,"img":false}]}
{"op":"mcm","clk":"11539850246","pt":1719486944105,"mc":[{"id":"1.230178326","rc":[{"atb":[[2.3,6.54]],"id":60748118}],"con":true,"img":false}]}
{"op":"mcm","clk":"11539850280","pt":1719486944466,"mc":[{"id":"1.230178326","rc":[{"atb":[[2.26,6.54]],"id":68687941}],"con":true,"img":false}]}
{"op":"mcm","clk":"11539850289","pt":1719486944569,"mc":[{"id":"1.230178326","rc":[{"atb":[[2.34,6.54]],"id":67674431}],"con":true,"img":false}]}
{"op":"mcm","clk":"11539977374","pt":1719488585503,"mc":[{"id":"1.230178326","rc":[{"spn":3.68,"spf":1.0,"id":62600242},{"atl":[[36,8],[60,12]],"id":60748118},{"spn":19.15,"spf":"NaN","id":60748118},{"atl":[[46,12],[27,8]],"id":68687941},{"spn":14.63,"spf":"NaN","id":68687941},{"atl":[[36,8]],"id":67674431},{"spn":19.17,"spf":"NaN","id":67674431},{"atl":[[48,12],[28,8]],"id":65710029},{"spn":15.17,"spf":"NaN","id":65710029}],"con":true,"img":false}]}
{"op":"mcm","clk":"11539977382","pt":1719488585604,"mc":[{"id":"1.230178326","rc":[{"atl":[[60,12]],"id":67674431}],"con":true,"img":false}]}
{"op":"mcm","clk":"11540014596","pt":1719489001337,"mc":[{"id":"1.230178326","rc":[{"atb":[[1.16,150]],"id":58221357},{"atl":[[370,2]],"id":58221357},{"atb":[[1.16,150]],"id":62600242},{"atl":[[390,2]],"id":62600242},{"atl":[[550,2]],"id":60748118},{"atl":[[560,2]],"id":68687941},{"atl":[[270,2]],"id":67674431},{"atl":[[500,2]],"id":65710029}],"con":true,"img":false}]}
{"op":"mcm","clk":"11540014604","pt":1719489001441,"mc":[{"id":"1.230178326","rc":[{"atb":[[1.16,150]],"id":60748118},{"atb":[[1.16,150]],"id":68687941},{"atb":[[1.16,150]],"id":65710029}],"con":true,"img":false}]}
{"op":"mcm","clk":"11540014614","pt":1719489001545,"mc":[{"id":"1.230178326","rc":[{"atb":[[1.16,150]],"id":67674431}],"con":true,"img":false}]}
{"op":"mcm","clk":"11540136418","pt":1719490401315,"mc":[{"id":"1.230178326","rc":[{"atb":[[2.24,0],[2.26,6.54]],"id":58221357},{"atb":[[2.36,6.54]],"id":62600242},{"atb":[[2.3,6.54],[2.28,0]],"id":60748118},{"atb":[[2.24,0],[2.26,6.54]],"id":68687941},{"atb":[[2.32,0],[2.34,6.54]],"id":67674431},{"atb":[[2.32,0],[2.34,6.54]],"id":65710029}],"con":true,"img":false}]}
{"op":"mcm","clk":"11540136427","pt":1719490401413,"mc":[{"id":"1.230178326","rc":[{"atb":[[2.28,12.81]],"id":58221357},{"atb":[[2.32,12.19]],"id":60748118},{"atb":[[2.28,11.96]],"id":68687941},{"atb":[[2.36,8.88]],"id":67674431},{"atb":[[2.36,13.32]],"id":65710029}],"con":true,"img":false}]}
{"op":"mcm","clk":"11540143217","pt":1719490467223,"mc":[{"id":"1.230178326","rc":[{"atb":[[2.26,3.38]],"id":58221357},{"spn":76.14,"spf":"NaN","id":58221357},{"spn":19.16,"spf":"NaN","id":60748118},{"spn":14.64,"spf":"NaN","id":68687941},{"spn":19.18,"spf":"NaN","id":67674431},{"spn":15.18,"spf":"NaN","id":65710029}],"con":true,"img":false}]}
{"op":"mcm","clk":"11540143251","pt":1719490467534,"mc":[{"id":"1.230178326","rc":[{"atb":[[2.26,3.38]],"id":68687941}],"con":true,"img":false}]}
{"op":"mcm","clk":"11540143287","pt":1719490467998,"mc":[{"id":"1.230178326","rc":[{"atb":[[2.34,3.38]],"id":67674431}],"con":true,"img":false}]}
{"op":"mcm","clk":"11540143302","pt":1719490468202,"mc":[{"id":"1.230178326","rc":[{"atb":[[2.3,3.38]],"id":60748118}],"con":true,"img":false}]}
{"op":"mcm","clk":"11540143395","pt":1719490469184,"mc":[{"id":"1.230178326","rc":[{"atb":[[2.34,3.38]],"id":65710029}],"con":true,"img":false}]}
{"op":"mcm","clk":"11540144973","pt":1719490484227,"mc":[{"id":"1.230178326","rc":[{"atb":[[2.3,3.16]],"id":68687941}],"con":true,"img":false}]}
{"op":"mcm","clk":"11540145032","pt":1719490484848,"mc":[{"id":"1.230178326","rc":[{"atb":[[2.38,3.16]],"id":67674431}],"con":true,"img":false}]}
{"op":"mcm","clk":"11540145155","pt":1719490486039,"mc":[{"id":"1.230178326","rc":[{"atb":[[2.38,3.16]],"id":65710029}],"con":true,"img":false}]}
{"op":"mcm","clk":"11540145340","pt":1719490487847,"mc":[{"id":"1.230178326","rc":[{"atb":[[2.34,3.16]],"id":60748118}],"con":true,"img":false}]}
{"op":"mcm","clk":"11540145392","pt":1719490488311,"mc":[{"id":"1.230178326","rc":[{"atb":[[2.3,3.16]],"id":58221357}],"con":true,"img":false}]}
{"op":"mcm","clk":"11540159274","pt":1719490630237,"mc":[{"id":"1.230178326","rc":[{"atb":[[2.26,0]],"id":58221357},{"spn":76.15,"spf":"NaN","id":58221357},{"spn":19.17,"spf":"NaN","id":60748118},{"spn":14.65,"spf":"NaN","id":68687941},{"spn":19.19,"spf":"NaN","id":67674431},{"spn":15.19,"spf":"NaN","id":65710029}],"con":true,"img":false}]}
{"op":"mcm","clk":"11540159290","pt":1719490630442,"mc":[{"id":"1.230178326","rc":[{"atb":[[2.3,0]],"id":60748118}],"con":true,"img":false}]}
{"op":"mcm","clk":"11540159320","pt":1719490630757,"mc":[{"id":"1.230178326","rc":[{"atb":[[2.26,0]],"id":68687941}],"con":true,"img":false}]}
{"op":"mcm","clk":"11540159348","pt":1719490631065,"mc":[{"id":"1.230178326","rc":[{"atb":[[2.34,0]],"id":67674431}],"con":true,"img":false}]}
{"op":"mcm","clk":"11540159385","pt":1719490631472,"mc":[{"id":"1.230178326","rc":[{"atb":[[2.34,0]],"id":65710029}],"con":true,"img":false}]}
{"op":"mcm","clk":"11540159396","pt":1719490631578,"mc":[{"id":"1.230178326","rc":[{"atb":[[2.34,6.54]],"id":60748118}],"con":true,"img":false}]}
{"op":"mcm","clk":"11540159431","pt":1719490631847,"mc":[{"id":"1.230178326","rc":[{"atb":[[2.3,6.54]],"id":68687941}],"con":true,"img":false}]}
{"op":"mcm","clk":"11540159455","pt":1719490632052,"mc":[{"id":"1.230178326","rc":[{"atb":[[2.38,6.54]],"id":65710029}],"con":true,"img":false}]}
{"op":"mcm","clk":"11540159484","pt":1719490632369,"mc":[{"id":"1.230178326","rc":[{"atb":[[2.38,6.54]],"id":67674431}],"con":true,"img":false}]}
{"op":"mcm","clk":"11540159514","pt":1719490632671,"mc":[{"id":"1.230178326","rc":[{"atb":[[2.3,6.54]],"id":58221357}],"con":true,"img":false}]}
{"op":"mcm","clk":"11540164745","pt":1719490698607,"mc":[{"id":"1.230178326","rc":[{"atb":[[2.28,0]],"id":58221357},{"atb":[[2.32,0]],"id":60748118},{"atb":[[2.28,0]],"id":68687941}],"con":true,"img":false}]}
{"op":"mcm","clk":"11540164757","pt":1719490698716,"mc":[{"id":"1.230178326","rc":[{"atb":[[2.32,12.81]],"id":58221357},{"atb":[[2.36,12.19]],"id":60748118},{"atb":[[2.32,11.96]],"id":68687941}],"con":true,"img":false}]}
{"op":"mcm","clk":"11540168391","pt":1719490744745,"mc":[{"id":"1.230178326","rc":[{"atb":[[2.3,3.38]],"id":68687941}],"con":true,"img":false}]}
{"op":"mcm","clk":"11540168415","pt":1719490745056,"mc":[{"id":"1.230178326","rc":[{"atb":[[2.34,3.38]],"id":60748118}],"con":true,"img":false}]}
{"op":"mcm","clk":"11540168441","pt":1719490745365,"mc":[{"id":"1.230178326","rc":[{"atb":[[2.34,3.16]],"id":68687941}],"con":true,"img":false}]}
{"op":"mcm","clk":"11540168447","pt":1719490745464,"mc":[{"id":"1.230178326","rc":[{"atb":[[2.38,3.16]],"id":60748118}],"con":true,"img":false}]}
{"op":"mcm","clk":"11540168493","pt":1719490745980,"mc":[{"id":"1.230178326","rc":[{"atb":[[2.3,3.38]],"id":58221357}],"con":true,"img":false}]}
{"op":"mcm","clk":"11540168552","pt":1719490746652,"mc":[{"id":"1.230178326","rc":[{"atb":[[2.34,3.16]],"id":58221357}],"con":true,"img":false}]}
{"op":"mcm","clk":"11540170725","pt":1719490778558,"mc":[{"id":"1.230178326","rc":[{"atb":[[2.3,0]],"id":58221357},{"spn":76.17,"spf":"NaN","id":58221357},{"spn":19.19,"spf":"NaN","id":60748118},{"spn":14.67,"spf":"NaN","id":68687941}],"con":true,"img":false}]}
{"op":"mcm","clk":"11540170749","pt":1719490778866,"mc":[{"id":"1.230178326","rc":[{"atb":[[2.34,0]],"id":60748118}],"con":true,"img":false}]}
{"op":"mcm","clk":"11540170770","pt":1719490779173,"mc":[{"id":"1.230178326","rc":[{"atb":[[2.3,0]],"id":68687941}],"con":true,"img":false}]}
{"op":"mcm","clk":"11540173060","pt":1719490809008,"mc":[{"id":"1.230178326","rc":[{"atb":[[2.38,6.54]],"id":60748118}],"con":true,"img":false}]}
{"op":"mcm","clk":"11540173108","pt":1719490809827,"mc":[{"id":"1.230178326","rc":[{"atb":[[2.34,6.54]],"id":58221357}],"con":true,"img":false}]}
{"op":"mcm","clk":"11540173149","pt":1719490810402,"mc":[{"id":"1.230178326","rc":[{"atb":[[2.34,6.54]],"id":68687941}],"con":true,"img":false}]}
{"op":"mcm","clk":"11540268983","pt":1719492183412,"mc":[{"id":"1.230178326","rc":[{"atb":[[5,1]],"id":58221357},{"spn":77.5,"spf":"NaN","id":58221357},{"atb":[[4.6,1]],"id":62600242},{"spn":4.8,"spf":1.0,"id":62600242},{"atb":[[5,1]],"id":60748118},{"spn":20.5,"spf":"NaN","id":60748118},{"atb":[[4.6,1]],"id":68687941},{"spn":15.8,"spf":"NaN","id":68687941},{"atb":[[5,1]],"id":67674431},{"spn":20.5,"spf":"NaN","id":67674431},{"atb":[[5,1]],"id":65710029},{"spn":16.5,"spf":"NaN","id":65710029}],"con":true,"img":false}]}
{"op":"mcm","clk":"11540329382","pt":1719493089691,"mc":[{"id":"1.230178326","rc":[{"spl":[[1.01,5]],"id":65710029},{"spn":2.9,"spf":1.0,"id":65710029}],"con":true,"img":false}]}
{"op":"mcm","clk":"11540331978","pt":1719493126728,"mc":[{"id":"1.230178326","rc":[{"atb":[[1.51,196.08]],"id":58221357},{"atb":[[1.51,196.08]],"id":62600242},{"atb":[[1.51,196.08]],"id":60748118},{"atb":[[1.51,196.08]],"id":68687941},{"atb":[[1.51,196.08]],"id":67674431},{"atb":[[1.51,196.08]],"id":65710029}],"con":true,"img":false}]}
{"op":"mcm","clk":"11540376127","pt":1719493725249,"mc":[{"id":"1.230178326","rc":[{"atb":[[5,0],[2.32,12.83],[1.02,22.66],[4.9,1],[2.34,6.54]],"id":58221357},{"atl":[[990,0.16]],"id":58221357},{"spn":77.45,"spf":"NaN","id":58221357},{"atb":[[2.36,6.54],[1.03,15.1],[2.34,12.56]],"id":62600242},{"atl":[[1000,0.16]],"id":62600242},{"atb":[[2.36,12.21],[2.38,6.54],[1.02,22.66]],"id":60748118},{"atl":[[1000,0.16]],"id":60748118},{"atb":[[2.32,11.97],[1.02,22.66],[2.34,6.54]],"id":68687941},{"atl":[[990,0.16]],"id":68687941},{"atb":[[2.36,8.89],[1.01,45.32],[2.38,6.54]],"id":67674431},{"atl":[[1000,0.16]],"id":67674431},{"atb":[[2.36,13.33],[2.38,6.54],[1.02,22.66]],"id":65710029},{"atl":[[1000,0.16]],"id":65710029}],"con":true,"img":false}]}
{"op":"mcm","clk":"11540397913","pt":1719493997026,"mc":[{"id":"1.230178326","rc":[{"atb":[[2.32,0]],"id":58221357},{"atb":[[2.32,0]],"id":68687941}],"con":true,"img":false}]}
{"op":"mcm","clk":"11540397921","pt":1719493997124,"mc":[{"id":"1.230178326","rc":[{"atb":[[2.36,12.83]],"id":58221357},{"atb":[[2.36,11.97]],"id":68687941}],"con":true,"img":false}]}
{"op":"mcm","clk":"11540399614","pt":1719494017450,"mc":[{"id":"1.230178326","rc":[{"atb":[[2.34,3.16]],"id":68687941}],"con":true,"img":false}]}
{"op":"mcm","clk":"11540399708","pt":1719494018434,"mc":[{"id":"1.230178326","rc":[{"atb":[[2.34,3.16]],"id":58221357}],"con":true,"img":false}]}
{"op":"mcm","clk":"11540399734","pt":1719494018745,"mc":[{"id":"1.230178326","rc":[{"atb":[[2.38,3.38]],"id":68687941}],"con":true,"img":false}]}
{"op":"mcm","clk":"11540399829","pt":1719494019931,"mc":[{"id":"1.230178326","rc":[{"atb":[[2.38,3.38]],"id":58221357}],"con":true,"img":false}]}
{"op":"mcm","clk":"11540401583","pt":1719494040564,"mc":[{"id":"1.230178326","rc":[{"atb":[[2.34,0]],"id":68687941}],"con":true,"img":false}]}
{"op":"mcm","clk":"11540401691","pt":1719494041969,"mc":[{"id":"1.230178326","rc":[{"atb":[[2.34,0]],"id":58221357}],"con":true,"img":false}]}
{"op":"mcm","clk":"11540402369","pt":1719494049450,"mc":[{"id":"1.230178326","rc":[{"atb":[[2.38,6.54]],"id":58221357}],"con":true,"img":false}]}
{"op":"mcm","clk":"11540402400","pt":1719494049968,"mc":[{"id":"1.230178326","rc":[{"atb":[[2.38,6.54]],"id":68687941}],"con":true,"img":false}]}
{"op":"mcm","clk":"11540507515","pt":1719495301370,"mc":[{"id":"1.230178326","rc":[{"atb":[[3.75,6]],"id":60748118},{"atb":[[3.75,6]],"id":67674431}],"con":true,"img":false}]}
{"op":"mcm","clk":"11540507529","pt":1719495301475,"mc":[{"id":"1.230178326","rc":[{"atb":[[3.3,6]],"id":58221357},{"atb":[[3.3,6]],"id":62600242},{"atb":[[2.72,6]],"id":68687941},{"atb":[[2.86,6]],"id":65710029}],"con":true,"img":false}]}
{"op":"mcm","clk":"11540508368","pt":1719495310096,"mc":[{"id":"1.230178326","rc":[{"atb":[[2.38,3.38]],"id":68687941}],"con":true,"img":false}]}
{"op":"mcm","clk":"11540508374","pt":1719495310199,"mc":[{"id":"1.230178326","rc":[{"atb":[[2.38,3.38]],"id":58221357},{"atb":[[2.36,3.38]],"id":62600242},{"atb":[[2.38,3.38]],"id":60748118},{"atb":[[2.38,3.38]],"id":67674431}],"con":true,"img":false}]}
{"op":"mcm","clk":"11540508382","pt":1719495310302,"mc":[{"id":"1.230178326","rc":[{"atb":[[2.38,3.38]],"id":65710029}],"con":true,"img":false}]}
{"op":"mcm","clk":"11540508396","pt":1719495310509,"mc":[{"id":"1.230178326","rc":[{"atb":[[2.88,3.16]],"id":65710029}],"con":true,"img":false}]}
{"op":"mcm","clk":"11540508415","pt":1719495310682,"mc":[{"id":"1.230178326","rc":[{"atb":[[2.74,3.16]],"id":68687941}],"con":true,"img":false}]}
{"op":"mcm","clk":"11540508460","pt":1719495311188,"mc":[{"id":"1.230178326","rc":[{"atb":[[2.12,89.29]],"id":58221357},{"atb":[[2.12,89.29]],"id":62600242},{"atb":[[2.12,89.29]],"id":60748118},{"atb":[[2.12,89.29]],"id":67674431}],"con":true,"img":false}]}
{"op":"mcm","clk":"11540511089","pt":1719495340058,"mc":[{"id":"1.230178326","rc":[{"atb":[[2.38,0]],"id":65710029}],"con":true,"img":false}]}
{"op":"mcm","clk":"11540511098","pt":1719495340153,"mc":[{"id":"1.230178326","rc":[{"atb":[[2.38,0]],"id":58221357},{"atb":[[2.36,0]],"id":62600242},{"atb":[[2.38,0]],"id":60748118},{"atb":[[2.38,0]],"id":67674431}],"con":true,"img":false}]}
{"op":"mcm","clk":"11540511146","pt":1719495340677,"mc":[{"id":"1.230178326","rc":[{"atb":[[2.88,6.54]],"id":65710029}],"con":true,"img":false}]}
{"op":"mcm","clk":"11540609774","pt":1719496414600,"mc":[{"id":"1.230178326","rc":[{"atb":[[4.6,1]],"id":58221357},{"atb":[[4.6,2]],"id":62600242},{"atb":[[5,2]],"id":60748118},{"atb":[[3.8,1]],"id":68687941},{"atb":[[5.5,1]],"id":67674431},{"spn":20.75,"spf":"NaN","id":67674431},{"atb":[[3.9,1]],"id":65710029},{"spn":3.5,"spf":1.0,"id":65710029}],"con":true,"img":false}]}
{"op":"mcm","clk":"11540610518","pt":1719496422512,"mc":[{"id":"1.230178326","rc":[{"atb":[[2.12,89.29]],"id":68687941},{"atb":[[2.12,89.29]],"id":65710029}],"con":true,"img":false}]}
{"op":"mcm","clk":"11540683366","pt":1719497282515,"mc":[{"id":"1.230178326","marketDefinition":{"bspMarket":true,"turnInPlayEnabled":false,"persistenceEnabled":false,"marketBaseRate":5.0,"eventId":"33376062","eventTypeId":"4339","numberOfWinners":1,"bettingType":"ODDS","marketType":"WIN","marketTime":"2024-06-27T16:43:00.000Z","suspendTime":"2024-06-27T16:43:00.000Z","bspReconciled":false,"complete":true,"inPlay":false,"crossMatching":true,"runnersVoidable":false,"numberOfActiveRunners":6,"betDelay":0,"status":"OPEN","runners":[{"status":"ACTIVE","sortPriority":1,"id":58221357,"name":"1. Ballymac Wynett"},{"status":"ACTIVE","sortPriority":2,"id":62600242,"name":"2. Swanley Petunia"},{"status":"ACTIVE","sortPriority":3,"id":60748118,"name":"3. Ballymac Dom"},{"status":"ACTIVE","sortPriority":4,"id":67674431,"name":"4. Fairyhill Daisy"},{"status":"ACTIVE","sortPriority":5,"id":68687941,"name":"5. Killieford Negri"},{"status":"ACTIVE","sortPriority":6,"id":65710029,"name":"6. Da Man Joey"}],"regulators":["MR_INT"],"venue":"Kinsley","countryCode":"GB","discountAllowed":true,"timezone":"Europe/London","openDate":"2024-06-27T13:36:00.000Z","version":5994643771,"name":"A3 462m","eventName":"Kinsley 27th Jun"},"rc":[{"atb":[[2.36,12.82],[4.6,1],[1.16,150],[1.02,22.65],[2.12,89.29],[4.9,1],[1.51,196.08],[3.3,6]],"id":58221357},{"atl":[[150,4],[370,2],[990,0.16]],"id":58221357},{"spn":77.45,"spf":"NaN","id":58221357},{"spl":[[5,1]],"id":62600242},{"atb":[[4.6,2],[1.16,150],[1.03,15.1],[2.12,89.29],[1.51,196.08],[3.3,6],[2.34,12.56]],"id":62600242},{"atl":[[150,4],[390,2],[1000,0.16]],"id":62600242},{"spn":4.8,"spf":1.0,"id":62600242},{"atb":[[2.36,12.2],[5,2],[1.16,150],[1.02,22.65],[2.12,89.29],[1.51,196.08],[3.75,6]],"id":60748118},{"atl":[[550,2],[36,8],[150,4],[60,12],[1000,0.16]],"id":60748118},{"spn":20.5,"spf":"NaN","id":60748118},{"atb":[[2.36,11.97],[2.72,6],[4.6,1],[2.74,3.15],[1.16,150],[2.38,3.38],[1.02,22.65],[3.8,1],[2.12,89.29],[1.51,196.08]],"id":68687941},{"atl":[[560,2],[150,4],[46,12],[27,8],[990,0.16]],"id":68687941},{"spn":15.8,"spf":"NaN","id":68687941},{"atb":[[2.36,8.88],[1.01,45.3],[5,1],[1.16,150],[5.5,1],[2.12,89.29],[1.51,196.08],[3.75,6]],"id":67674431},{"atl":[[270,2],[36,8],[150,4],[60,12],[1000,0.16]],"id":67674431},{"spn":20.75,"spf":"NaN","id":67674431},{"spl":[[1.01,5]],"id":65710029},{"atb":[[2.36,13.33],[2.88,6.54],[5,1],[2.86,6],[1.16,150],[1.02,22.65],[2.12,89.29],[1.51,196.08],[3.9,1]],"id":65710029},{"atl":[[32,0.6],[150,4],[48,12],[28,8],[500,2],[1000,0.16]],"id":65710029},{"spn":3.5,"spf":1.0,"id":65710029}],"con":true,"img":true}]}
{"op":"mcm","clk":"11540734516","pt":1719497810385,"mc":[{"id":"1.230178326","rc":[{"atb":[[2.36,12.82],[1.02,22.65]],"id":58221357},{"atb":[[1.03,15.1],[2.34,12.56]],"id":62600242},{"atb":[[2.36,12.2],[1.02,22.65]],"id":60748118},{"spl":[[1.01,1]],"id":68687941},{"atb":[[2.36,11.97],[2.74,3.15],[2.38,3.38],[1.02,22.65]],"id":68687941},{"spn":4.6,"spf":1.0,"id":68687941},{"atb":[[2.36,8.88],[1.01,45.3]],"id":67674431},{"atb":[[2.36,13.33],[2.88,6.54],[1.02,22.65]],"id":65710029}],"con":true,"img":false}]}
{"op":"mcm","clk":"11540816489","pt":1719498688786,"mc":[{"id":"1.230178326","rc":[{"atb":[[4.6,0]],"id":58221357},{"atb":[[4.6,1]],"id":62600242},{"atb":[[5,1]],"id":60748118},{"atb":[[3.8,0]],"id":68687941},{"atb":[[5.5,0]],"id":67674431},{"spn":20.5,"spf":"NaN","id":67674431},{"atb":[[3.9,0]],"id":65710029},{"spn":3.3,"spf":1.0,"id":65710029}],"con":true,"img":false}]}
{"op":"mcm","clk":"11540934224","pt":1719500154159,"mc":[{"id":"1.230178326","rc":[{"atb":[[1.02,191.12]],"id":58221357},{"atl":[[970,0.85]],"id":58221357},{"atb":[[1.02,71.96]],"id":62600242},{"atl":[[970,0.85]],"id":62600242},{"atb":[[1.03,191.33]],"id":60748118},{"atl":[[970,0.85]],"id":60748118},{"atb":[[1.03,71.11]],"id":68687941},{"atl":[[990,2.12]],"id":68687941},{"atb":[[1.03,84.65]],"id":67674431},{"atl":[[990,1.71]],"id":67674431},{"atb":[[1.04,71.11]],"id":65710029},{"atl":[[960,1.21]],"id":65710029}],"con":true,"img":false}]}
{"op":"mcm","clk":"11540956867","pt":1719500435574,"mc":[{"id":"1.230178326","rc":[{"atb":[[2.36,12.82],[1.02,191.16],[3.5,2.85]],"id":58221357},{"atl":[[970,0.85]],"id":58221357},{"atb":[[1.03,15.1],[1.02,71.97],[3.5,2.85],[2.34,12.56]],"id":62600242},{"atl":[[970,0.85]],"id":62600242},{"atb":[[2.36,12.2],[1.03,191.36],[1.02,22.65],[3.75,8.66]],"id":60748118},{"atl":[[970,0.85]],"id":60748118},{"atb":[[2.36,11.97],[2.74,3.16],[1.03,71.12],[2.38,3.38],[1.02,22.65],[3.5,2.85]],"id":68687941},{"atl":[[990,2.12]],"id":68687941},{"atb":[[2.36,8.89],[1.01,45.31],[5,3],[1.03,84.67]],"id":67674431},{"atl":[[990,1.71]],"id":67674431},{"atb":[[2.36,13.33],[2.88,6.54],[1.02,22.65],[1.04,71.12],[3.75,2.66]],"id":65710029},{"atl":[[960,1.21]],"id":65710029},{"spn":3.76,"spf":1.0,"id":65710029}],"con":true,"img":false}]}
{"op":"mcm","clk":"11541250083","pt":1719503799417,"mc":[{"id":"1.230178326","rc":[{"atb":[[3.5,0]],"id":58221357},{"atb":[[3.5,0]],"id":62600242},{"atb":[[3.75,6]],"id":60748118},{"atb":[[3.5,0]],"id":68687941},{"atb":[[5,1]],"id":67674431},{"atb":[[3.75,0]],"id":65710029},{"spn":3.3,"spf":1.0,"id":65710029}],"con":true,"img":false}]}
{"op":"mcm","clk":"11541318806","pt":1719504458100,"mc":[{"id":"1.230178326","rc":[{"atb":[[2.36,12.82],[1.02,191.06]],"id":58221357},{"atl":[[970,0.85]],"id":58221357},{"atb":[[1.03,15.09],[1.02,71.93],[2.34,12.55]],"id":62600242},{"atl":[[970,0.85]],"id":62600242},{"atb":[[2.36,12.2],[1.03,191.26],[1.02,22.64]],"id":60748118},{"atl":[[970,0.85]],"id":60748118},{"atb":[[2.36,11.96],[2.74,3.16],[1.03,71.09],[2.38,3.38],[1.02,22.64]],"id":68687941},{"atl":[[990,2.12]],"id":68687941},{"atb":[[2.36,8.88],[1.01,45.29],[1.03,84.63]],"id":67674431},{"atl":[[990,1.71]],"id":67674431},{"atb":[[2.36,13.32],[2.88,6.54],[1.02,22.64],[1.04,71.09]],"id":65710029},{"atl":[[27,1.61],[960,1.21]],"id":65710029}],"con":true,"img":false}]}
{"op":"mcm","clk":"11541318828","pt":1719504458407,"mc":[{"id":"1.230178326","rc":[{"atl":[[26,1.71]],"id":68687941}],"con":true,"img":false}]}
{"op":"mcm","clk":"11541318851","pt":1719504458715,"mc":[{"id":"1.230178326","rc":[{"atl":[[34,1.74]],"id":60748118}],"con":true,"img":false}]}
{"op":"mcm","clk":"11541352397","pt":1719504860322,"mc":[{"id":"1.230178326","rc":[{"spb":[[1000,15]],"id":58221357},{"spn":150.0,"spf":"Infinity","id":58221357},{"spn":19.5,"spf":"NaN","id":60748118}],"con":true,"img":false}]}
{"op":"mcm","clk":"11541373114","pt":1719505081349,"mc":[{"id":"1.230178326","rc":[{"atl":[[190,4]],"id":58221357},{"atl":[[190,4]],"id":62600242},{"atl":[[190,4]],"id":60748118},{"atl":[[190,4]],"id":68687941},{"atl":[[190,4]],"id":67674431},{"atl":[[190,4]],"id":65710029}],"con":true,"img":false}]}
{"op":"mcm","clk":"11541378661","pt":1719505141086,"mc":[{"id":"1.230178326","rc":[{"atb":[[1.02,193.06]],"id":58221357}],"con":true,"img":false}]}
{"op":"mcm","clk":"11541378679","pt":1719505141297,"mc":[{"id":"1.230178326","rc":[{"atb":[[1.02,73.93]],"id":62600242}],"con":true,"img":false}]}
{"op":"mcm","clk":"11541378705","pt":1719505141510,"mc":[{"id":"1.230178326","rc":[{"atb":[[1.02,24.64]],"id":60748118}],"con":true,"img":false}]}
{"op":"mcm","clk":"11541378725","pt":1719505141710,"mc":[{"id":"1.230178326","rc":[{"atb":[[1.02,2]],"id":67674431}],"con":true,"img":false}]}
{"op":"mcm","clk":"11541378771","pt":1719505142079,"mc":[{"id":"1.230178326","rc":[{"atb":[[1.02,24.64]],"id":68687941}],"con":true,"img":false}]}
{"op":"mcm","clk":"11541378790","pt":1719505142285,"mc":[{"id":"1.230178326","rc":[{"atb":[[1.02,24.64]],"id":65710029}],"con":true,"img":false}]}
{"op":"mcm","clk":"11541385583","pt":1719505206405,"mc":[{"id":"1.230178326","rc":[{"atb":[[5,0]],"id":65710029},{"trd":[[5,2]],"ltp":5.0,"tv":2.0,"id":65710029},{"spn":2.88,"spf":1.0,"id":65710029}],"con":true,"img":false}]}
{"op":"mcm","clk":"11541386145","pt":1719505211096,"mc":[{"id":"1.230178326","rc":[{"atb":[[4.5,1]],"id":65710029}],"con":true,"img":false}]}
{"op":"mcm","clk":"11541386305","pt":1719505212596,"mc":[{"id":"1.230178326","rc":[{"atb":[[5,0]],"id":60748118},{"trd":[[5,2]],"ltp":5.0,"tv":2.0,"id":60748118}],"con":true,"img":false}]}
{"op":"mcm","clk":"11541386661","pt":1719505216123,"mc":[{"id":"1.230178326","rc":[{"atb":[[4.5,1]],"id":60748118}],"con":true,"img":false}]}
{"op":"mcm","clk":"11541389798","pt":1719505246535,"mc":[{"id":"1.230178326","rc":[{"atb":[[2.38,8.59]],"id":58221357},{"atb":[[2.36,8.71]],"id":62600242}],"con":true,"img":false}]}
{"op":"mcm","clk":"11541389830","pt":1719505246846,"mc":[{"id":"1.230178326","rc":[{"atb":[[2.38,8.59]],"id":60748118},{"atb":[[2.38,8.59]],"id":67674431}],"con":true,"img":false}]}
{"op":"mcm","clk":"11541394395","pt":1719505292891,"mc":[{"id":"1.230178326","rc":[{"atb":[[2.38,9.19]],"id":62600242},{"spn":19.25,"spf":"NaN","id":60748118},{"spn":3.2,"spf":1.0,"id":65710029}],"con":true,"img":false}]}
{"op":"mcm","clk":"11541394413","pt":1719505293092,"mc":[{"id":"1.230178326","rc":[{"atb":[[2.4,9.06]],"id":60748118}],"con":true,"img":false}]}
{"op":"mcm","clk":"11541394443","pt":1719505293404,"mc":[{"id":"1.230178326","rc":[{"atb":[[2.4,9.06]],"id":58221357}],"con":true,"img":false}]}
{"op":"mcm","clk":"11541394487","pt":1719505293880,"mc":[{"id":"1.230178326","rc":[{"atb":[[2.4,9.06]],"id":67674431}],"con":true,"img":false}]}
{"op":"mcm","clk":"11541397990","pt":1719505330941,"mc":[{"id":"1.230178326","rc":[{"atb":[[2.38,0]],"id":58221357},{"atb":[[2.36,0]],"id":62600242},{"atb":[[2.38,0]],"id":60748118},{"atb":[[2.38,0]],"id":67674431}],"con":true,"img":false}]}
{"op":"mcm","clk":"11541398504","pt":1719505336249,"mc":[{"id":"1.230178326","rc":[{"atb":[[2.42,8.34]],"id":58221357}],"con":true,"img":false}]}
{"op":"mcm","clk":"11541398511","pt":1719505336363,"mc":[{"id":"1.230178326","rc":[{"atb":[[2.4,8.46]],"id":62600242}],"con":true,"img":false}]}
{"op":"mcm","clk":"11541398521","pt":1719505336458,"mc":[{"id":"1.230178326","rc":[{"atb":[[2.42,8.34]],"id":60748118}],"con":true,"img":false}]}
{"op":"mcm","clk":"11541398531","pt":1719505336563,"mc":[{"id":"1.230178326","rc":[{"atb":[[2.42,8.34]],"id":67674431}],"con":true,"img":false}]}
{"op":"mcm","clk":"11541403392","pt":1719505384427,"mc":[{"id":"1.230178326","rc":[{"atl":[[1000,0.19]],"id":60748118}],"con":true,"img":false}]}
{"op":"mcm","clk":"11541403406","pt":1719505384528,"mc":[{"id":"1.230178326","rc":[{"atl":[[1000,0.16]],"id":60748118}],"con":true,"img":false}]}
{"op":"mcm","clk":"11541403417","pt":1719505384632,"mc":[{"id":"1.230178326","rc":[{"atl":[[32,0.03]],"id":60748118}],"con":true,"img":false}]}
{"op":"mcm","clk":"11541403711","pt":1719505387344,"mc":[{"id":"1.230178326","rc":[{"atb":[[2.4,0]],"id":58221357},{"atb":[[2.38,0]],"id":62600242},{"atb":[[2.4,0]],"id":60748118},{"atb":[[2.4,0]],"id":67674431}],"con":true,"img":false}]}
{"op":"mcm","clk":"11541404827","pt":1719505396824,"mc":[{"id":"1.230178326","rc":[{"atb":[[2.42,8.93]],"id":62600242}],"con":true,"img":false}]}
{"op":"mcm","clk":"11541404835","pt":1719505396927,"mc":[{"id":"1.230178326","rc":[{"atb":[[2.44,8.81]],"id":58221357}],"con":true,"img":false}]}
{"op":"mcm","clk":"11541404852","pt":1719505397135,"mc":[{"id":"1.230178326","rc":[{"atb":[[2.44,8.81]],"id":60748118}],"con":true,"img":false}]}
{"op":"mcm","clk":"11541404884","pt":1719505397444,"mc":[{"id":"1.230178326","rc":[{"atb":[[2.44,8.81]],"id":67674431}],"con":true,"img":false}]}
{"op":"mcm","clk":"11541405121","pt":1719505399823,"mc":[{"id":"1.230178326","rc":[{"atl":[[32,0]],"id":60748118}],"con":true,"img":false}]}
{"op":"mcm","clk":"11541405136","pt":1719505400043,"mc":[{"id":"1.230178326","rc":[{"atl":[[1000,0.19]],"id":60748118}],"con":true,"img":false}]}
{"op":"mcm","clk":"11541405155","pt":1719505400241,"mc":[{"id":"1.230178326","rc":[{"atl":[[1000,0.16]],"id":60748118}],"con":true,"img":false}]}
{"op":"mcm","clk":"11541405166","pt":1719505400345,"mc":[{"id":"1.230178326","rc":[{"atl":[[32,0.03]],"id":60748118}],"con":true,"img":false}]}
{"op":"mcm","clk":"11541406745","pt":1719505415450,"mc":[{"id":"1.230178326","rc":[{"atl":[[32,0]],"id":60748118}],"con":true,"img":false}]}
{"op":"mcm","clk":"11541406784","pt":1719505415762,"mc":[{"id":"1.230178326","rc":[{"atl":[[1000,0.19]],"id":60748118}],"con":true,"img":false}]}
{"op":"mcm","clk":"11541406811","pt":1719505415975,"mc":[{"id":"1.230178326","rc":[{"atl":[[1000,0.16]],"id":60748118}],"con":true,"img":false}]}
{"op":"mcm","clk":"11541406823","pt":1719505416076,"mc":[{"id":"1.230178326","rc":[{"atl":[[32,0.03]],"id":60748118}],"con":true,"img":false}]}
{"op":"mcm","clk":"11541407883","pt":1719505426377,"mc":[{"id":"1.230178326","rc":[{"atb":[[2.42,0]],"id":58221357},{"atb":[[2.4,0]],"id":62600242},{"atb":[[2.42,0]],"id":60748118},{"atb":[[2.42,0]],"id":67674431}],"con":true,"img":false}]}
{"op":"mcm","clk":"11541408365","pt":1719505431179,"mc":[{"id":"1.230178326","rc":[{"atb":[[2.46,8.11]],"id":58221357}],"con":true,"img":false}]}
{"op":"mcm","clk":"11541408375","pt":1719505431281,"mc":[{"id":"1.230178326","rc":[{"atl":[[32,0]],"id":60748118}],"con":true,"img":false}]}
{"op":"mcm","clk":"11541408387","pt":1719505431386,"mc":[{"id":"1.230178326","rc":[{"atb":[[2.46,8.11]],"id":60748118}],"con":true,"img":false}]}
{"op":"mcm","clk":"11541408396","pt":1719505431502,"mc":[{"id":"1.230178326","rc":[{"atb":[[2.44,8.23]],"id":62600242},{"atl":[[1000,0.19]],"id":60748118}],"con":true,"img":false}]}
{"op":"mcm","clk":"11541408414","pt":1719505431696,"mc":[{"id":"1.230178326","rc":[{"atl":[[1000,0.16]],"id":60748118}],"con":true,"img":false}]}
{"op":"mcm","clk":"11541408424","pt":1719505431801,"mc":[{"id":"1.230178326","rc":[{"atl":[[32,0.03]],"id":60748118},{"atb":[[2.46,8.11]],"id":67674431}],"con":true,"img":false}]}
{"op":"mcm","clk":"11541410028","pt":1719505447021,"mc":[{"id":"1.230178326","rc":[{"atl":[[32,0]],"id":60748118}],"con":true,"img":false}]}
{"op":"mcm","clk":"11541410050","pt":1719505447175,"mc":[{"id":"1.230178326","rc":[{"atl":[[1000,0.19]],"id":60748118}],"con":true,"img":false}]}
{"op":"mcm","clk":"11541410074","pt":1719505447385,"mc":[{"id":"1.230178326","rc":[{"atl":[[1000,0.16]],"id":60748118}],"con":true,"img":false}]}
{"op":"mcm","clk":"11541410084","pt":1719505447488,"mc":[{"id":"1.230178326","rc":[{"atl":[[32,0.03]],"id":60748118}],"con":true,"img":false}]}
{"op":"mcm","clk":"11541411381","pt":1719505462609,"mc":[{"id":"1.230178326","rc":[{"atl":[[32,0]],"id":60748118}],"con":true,"img":false}]}
{"op":"mcm","clk":"11541411396","pt":1719505462816,"mc":[{"id":"1.230178326","rc":[{"atl":[[1000,0.19]],"id":60748118}],"con":true,"img":false}]}
{"op":"mcm","clk":"11541411409","pt":1719505463024,"mc":[{"id":"1.230178326","rc":[{"atl":[[1000,0.16]],"id":60748118}],"con":true,"img":false}]}
{"op":"mcm","clk":"11541411416","pt":1719505463125,"mc":[{"id":"1.230178326","rc":[{"atl":[[32,0.03]],"id":60748118}],"con":true,"img":false}]}
{"op":"mcm","clk":"11541411606","pt":1719505465405,"mc":[{"id":"1.230178326","rc":[{"atb":[[2.44,0]],"id":58221357},{"atb":[[2.42,0]],"id":62600242},{"atb":[[2.44,0]],"id":60748118},{"atb":[[2.44,0]],"id":67674431}],"con":true,"img":false}]}
{"op":"mcm","clk":"11541412212","pt":1719505472106,"mc":[{"id":"1.230178326","rc":[{"atb":[[2.46,8.69]],"id":62600242}],"con":true,"img":false}]}
{"op":"mcm","clk":"11541412231","pt":1719505472312,"mc":[{"id":"1.230178326","rc":[{"atb":[[2.48,8.58]],"id":58221357}],"con":true,"img":false}]}
{"op":"mcm","clk":"11541412250","pt":1719505472415,"mc":[{"id":"1.230178326","rc":[{"atb":[[2.48,8.58]],"id":67674431}],"con":true,"img":false}]}
{"op":"mcm","clk":"11541412272","pt":1719505472621,"mc":[{"id":"1.230178326","rc":[{"atb":[[2.48,8.58]],"id":60748118}],"con":true,"img":false}]}
{"op":"mcm","clk":"11541412748","pt":1719505478236,"mc":[{"id":"1.230178326","rc":[{"atl":[[32,0]],"id":60748118}],"con":true,"img":false}]}
{"op":"mcm","clk":"11541412801","pt":1719505478446,"mc":[{"id":"1.230178326","rc":[{"atl":[[1000,0.19]],"id":60748118}],"con":true,"img":false}]}
{"op":"mcm","clk":"11541412816","pt":1719505478647,"mc":[{"id":"1.230178326","rc":[{"atl":[[1000,0.16]],"id":60748118}],"con":true,"img":false}]}
{"op":"mcm","clk":"11541412827","pt":1719505478750,"mc":[{"id":"1.230178326","rc":[{"atl":[[32,0.03]],"id":60748118}],"con":true,"img":false}]}
{"op":"mcm","clk":"11541414004","pt":1719505492270,"mc":[{"id":"1.230178326","rc":[{"atb":[[2.46,0]],"id":58221357},{"atb":[[2.44,0]],"id":62600242},{"atb":[[2.46,0]],"id":60748118},{"atb":[[2.46,0]],"id":67674431}],"con":true,"img":false}]}
{"op":"mcm","clk":"11541414179","pt":1719505494037,"mc":[{"id":"1.230178326","rc":[{"atl":[[32,0]],"id":60748118}],"con":true,"img":false}]}
{"op":"mcm","clk":"11541414248","pt":1719505494760,"mc":[{"id":"1.230178326","rc":[{"atl":[[1000,0.19]],"id":60748118}],"con":true,"img":false}]}
{"op":"mcm","clk":"11541414271","pt":1719505495066,"mc":[{"id":"1.230178326","rc":[{"atl":[[1000,0.16]],"id":60748118}],"con":true,"img":false}]}
{"op":"mcm","clk":"11541414280","pt":1719505495170,"mc":[{"id":"1.230178326","rc":[{"atl":[[32,0.03]],"id":60748118}],"con":true,"img":false}]}
{"op":"mcm","clk":"11541415008","pt":1719505503945,"mc":[{"id":"1.230178326","rc":[{"atb":[[2.5,7.9]],"id":58221357}],"con":true,"img":false}]}
{"op":"mcm","clk":"11541415016","pt":1719505504099,"mc":[{"id":"1.230178326","rc":[{"atb":[[2.48,8.01]],"id":62600242}],"con":true,"img":false}]}
{"op":"mcm","clk":"11541415038","pt":1719505504256,"mc":[{"id":"1.230178326","rc":[{"atb":[[2.5,7.9]],"id":60748118},{"atb":[[2.5,7.9]],"id":67674431}],"con":true,"img":false}]}
{"op":"mcm","clk":"11541415610","pt":1719505510353,"mc":[{"id":"1.230178326","rc":[{"atl":[[32,0]],"id":60748118}],"con":true,"img":false}]}
{"op":"mcm","clk":"11541415720","pt":1719505511695,"mc":[{"id":"1.230178326","rc":[{"atl":[[1000,0.19]],"id":60748118}],"con":true,"img":false}]}
{"op":"mcm","clk":"11541415737","pt":1719505511852,"mc":[{"id":"1.230178326","rc":[{"atl":[[1000,0.16]],"id":60748118}],"con":true,"img":false}]}
{"op":"mcm","clk":"11541415746","pt":1719505511952,"mc":[{"id":"1.230178326","rc":[{"atl":[[32,0.03]],"id":60748118}],"con":true,"img":false}]}
{"op":"mcm","clk":"11541417010","pt":1719505527178,"mc":[{"id":"1.230178326","rc":[{"atl":[[32,0]],"id":60748118}],"con":true,"img":false}]}
{"op":"mcm","clk":"11541417020","pt":1719505527280,"mc":[{"id":"1.230178326","rc":[{"atb":[[2.48,0]],"id":58221357},{"atb":[[2.46,0]],"id":62600242},{"atb":[[2.48,0]],"id":60748118},{"atb":[[2.48,0]],"id":67674431}],"con":true,"img":false}]}
{"op":"mcm","clk":"11541417027","pt":1719505527384,"mc":[{"id":"1.230178326","rc":[{"atl":[[1000,0.19]],"id":60748118}],"con":true,"img":false}]}
{"op":"mcm","clk":"11541417037","pt":1719505527487,"mc":[{"id":"1.230178326","rc":[{"atl":[[1000,0.16]],"id":60748118}],"con":true,"img":false}]}
{"op":"mcm","clk":"11541417047","pt":1719505527588,"mc":[{"id":"1.230178326","rc":[{"atl":[[32,0.03]],"id":60748118}],"con":true,"img":false}]}
{"op":"mcm","clk":"11541418352","pt":1719505542893,"mc":[{"id":"1.230178326","rc":[{"atl":[[32,0]],"id":60748118}],"con":true,"img":false}]}
{"op":"mcm","clk":"11541418374","pt":1719505543201,"mc":[{"id":"1.230178326","rc":[{"atl":[[1000,0.19]],"id":60748118}],"con":true,"img":false}]}
{"op":"mcm","clk":"11541418389","pt":1719505543406,"mc":[{"id":"1.230178326","rc":[{"atl":[[1000,0.16]],"id":60748118}],"con":true,"img":false}]}
{"op":"mcm","clk":"11541418398","pt":1719505543509,"mc":[{"id":"1.230178326","rc":[{"atl":[[32,0.03]],"id":60748118}],"con":true,"img":false}]}
{"op":"mcm","clk":"11541419767","pt":1719505558731,"mc":[{"id":"1.230178326","rc":[{"atl":[[32,0]],"id":60748118}],"con":true,"img":false}]}
{"op":"mcm","clk":"11541419817","pt":1719505559304,"mc":[{"id":"1.230178326","rc":[{"atl":[[1000,0.19]],"id":60748118}],"con":true,"img":false}]}
{"op":"mcm","clk":"11541419827","pt":1719505559400,"mc":[{"id":"1.230178326","rc":[{"atl":[[1000,0.16]],"id":60748118}],"con":true,"img":false}]}
{"op":"mcm","clk":"11541419836","pt":1719505559502,"mc":[{"id":"1.230178326","rc":[{"atl":[[32,0.03]],"id":60748118}],"con":true,"img":false}]}
{"op":"mcm","clk":"11541421525","pt":1719505574246,"mc":[{"id":"1.230178326","rc":[{"atb":[[2.5,0]],"id":58221357},{"atb":[[2.48,0]],"id":62600242},{"atb":[[2.5,0]],"id":60748118},{"spn":18.25,"spf":"NaN","id":60748118},{"atb":[[2.5,0]],"id":67674431}],"con":true,"img":false}]}
{"op":"mcm","clk":"11541421583","pt":1719505574718,"mc":[{"id":"1.230178326","rc":[{"atl":[[32,0]],"id":60748118}],"con":true,"img":false}]}
{"op":"mcm","clk":"11541421606","pt":1719505574923,"mc":[{"id":"1.230178326","rc":[{"atl":[[1000,0.19]],"id":60748118}],"con":true,"img":false}]}
{"op":"mcm","clk":"11541421622","pt":1719505575127,"mc":[{"id":"1.230178326","rc":[{"atl":[[1000,0.16]],"id":60748118}],"con":true,"img":false}]}
{"op":"mcm","clk":"11541421629","pt":1719505575223,"mc":[{"id":"1.230178326","rc":[{"atl":[[32,0.03]],"id":60748118}],"con":true,"img":false}]}
{"op":"mcm","clk":"11541421661","pt":1719505575634,"mc":[{"id":"1.230178326","rc":[{"atb":[[2.52,8.35]],"id":58221357}],"con":true,"img":false}]}
{"op":"mcm","clk":"11541421694","pt":1719505575944,"mc":[{"id":"1.230178326","rc":[{"atb":[[2.52,8.35]],"id":67674431}],"con":true,"img":false}]}
{"op":"mcm","clk":"11541421724","pt":1719505576356,"mc":[{"id":"1.230178326","rc":[{"atb":[[2.5,8.46]],"id":62600242}],"con":true,"img":false}]}
{"op":"mcm","clk":"11541421728","pt":1719505576408,"mc":[{"id":"1.230178326","rc":[{"atb":[[2.52,8.35]],"id":60748118}],"con":true,"img":false}]}
{"op":"mcm","clk":"11541422956","pt":1719505590474,"mc":[{"id":"1.230178326","rc":[{"atl":[[32,0]],"id":60748118}],"con":true,"img":false}]}
{"op":"mcm","clk":"11541422979","pt":1719505590889,"mc":[{"id":"1.230178326","rc":[{"atl":[[1000,0.19]],"id":60748118}],"con":true,"img":false}]}
{"op":"mcm","clk":"11541422998","pt":1719505591050,"mc":[{"id":"1.230178326","rc":[{"atl":[[1000,0.16]],"id":60748118}],"con":true,"img":false}]}
{"op":"mcm","clk":"11541423008","pt":1719505591170,"mc":[{"id":"1.230178326","rc":[{"atl":[[32,0.03]],"id":60748118}],"con":true,"img":false}]}
{"op":"mcm","clk":"11541423525","pt":1719505597197,"mc":[{"id":"1.230178326","rc":[{"atb":[[2.54,7.69]],"id":58221357}],"con":true,"img":false}]}
{"op":"mcm","clk":"11541423533","pt":1719505597301,"mc":[{"id":"1.230178326","rc":[{"atb":[[2.52,7.8]],"id":62600242}],"con":true,"img":false}]}
{"op":"mcm","clk":"11541423542","pt":1719505597357,"mc":[{"id":"1.230178326","rc":[{"atb":[[2.54,7.69]],"id":60748118}],"con":true,"img":false}]}
{"op":"mcm","clk":"11541423561","pt":1719505597564,"mc":[{"id":"1.230178326","rc":[{"atb":[[2.54,7.69]],"id":67674431}],"con":true,"img":false}]}
{"op":"mcm","clk":"11541424295","pt":1719505606427,"mc":[{"id":"1.230178326","rc":[{"atl":[[32,0]],"id":60748118}],"con":true,"img":false}]}
{"op":"mcm","clk":"11541424313","pt":1719505606631,"mc":[{"id":"1.230178326","rc":[{"atl":[[1000,0.19]],"id":60748118}],"con":true,"img":false}]}
{"op":"mcm","clk":"11541424332","pt":1719505606790,"mc":[{"id":"1.230178326","rc":[{"atl":[[1000,0.16]],"id":60748118}],"con":true,"img":false}]}
{"op":"mcm","clk":"11541424338","pt":1719505606892,"mc":[{"id":"1.230178326","rc":[{"atl":[[32,0.03]],"id":60748118}],"con":true,"img":false}]}
{"op":"mcm","clk":"11541425153","pt":1719505616108,"mc":[{"id":"1.230178326","rc":[{"atl":[[32,0.87]],"id":60748118},{"atl":[[25,0.84]],"id":68687941},{"atl":[[26,0.84]],"id":65710029}],"con":true,"img":false}]}
{"op":"mcm","clk":"11541425713","pt":1719505622120,"mc":[{"id":"1.230178326","rc":[{"atl":[[32,0.84]],"id":60748118}],"con":true,"img":false}]}
{"op":"mcm","clk":"11541425731","pt":1719505622328,"mc":[{"id":"1.230178326","rc":[{"atl":[[1000,0.19]],"id":60748118}],"con":true,"img":false}]}
{"op":"mcm","clk":"11541425752","pt":1719505622537,"mc":[{"id":"1.230178326","rc":[{"atl":[[1000,0.16]],"id":60748118}],"con":true,"img":false}]}
{"op":"mcm","clk":"11541425763","pt":1719505622641,"mc":[{"id":"1.230178326","rc":[{"atl":[[32,0.87]],"id":60748118}],"con":true,"img":false}]}
{"op":"mcm","clk":"11541427011","pt":1719505635961,"mc":[{"id":"1.230178326","rc":[{"atb":[[2.52,0]],"id":58221357},{"atb":[[2.5,0]],"id":62600242},{"atb":[[2.52,0]],"id":60748118},{"atb":[[2.52,0]],"id":67674431}],"con":true,"img":false}]}
{"op":"mcm","clk":"11541427189","pt":1719505637826,"mc":[{"id":"1.230178326","rc":[{"atl":[[32,0.84]],"id":60748118}],"con":true,"img":false}]}
{"op":"mcm","clk":"11541427203","pt":1719505638031,"mc":[{"id":"1.230178326","rc":[{"atl":[[1000,0.19]],"id":60748118}],"con":true,"img":false}]}
{"op":"mcm","clk":"11541427220","pt":1719505638239,"mc":[{"id":"1.230178326","rc":[{"atl":[[1000,0.16]],"id":60748118}],"con":true,"img":false}]}
{"op":"mcm","clk":"11541427230","pt":1719505638339,"mc":[{"id":"1.230178326","rc":[{"atl":[[32,0.87]],"id":60748118}],"con":true,"img":false}]}
{"op":"mcm","clk":"11541427649","pt":1719505643051,"mc":[{"id":"1.230178326","rc":[{"atb":[[2.56,8.14]],"id":67674431}],"con":true,"img":false}]}
{"op":"mcm","clk":"11541427685","pt":1719505643466,"mc":[{"id":"1.230178326","rc":[{"atb":[[2.56,8.14]],"id":60748118}],"con":true,"img":false}]}
{"op":"mcm","clk":"11541427765","pt":1719505644245,"mc":[{"id":"1.230178326","rc":[{"atb":[[2.54,8.24]],"id":62600242}],"con":true,"img":false}]}
{"op":"mcm","clk":"11541427807","pt":1719505644656,"mc":[{"id":"1.230178326","rc":[{"atb":[[2.56,8.14]],"id":58221357}],"con":true,"img":false}]}
{"op":"mcm","clk":"11541428605","pt":1719505653556,"mc":[{"id":"1.230178326","rc":[{"atl":[[32,0.84]],"id":60748118}],"con":true,"img":false}]}
{"op":"mcm","clk":"11541428622","pt":1719505653762,"mc":[{"id":"1.230178326","rc":[{"atl":[[1000,0.19]],"id":60748118}],"con":true,"img":false}]}
{"op":"mcm","clk":"11541428649","pt":1719505654072,"mc":[{"id":"1.230178326","rc":[{"atl":[[1000,0.16]],"id":60748118}],"con":true,"img":false}]}
{"op":"mcm","clk":"11541428659","pt":1719505654175,"mc":[{"id":"1.230178326","rc":[{"atl":[[32,0.87]],"id":60748118}],"con":true,"img":false}]}
{"op":"mcm","clk":"11541430063","pt":1719505669382,"mc":[{"id":"1.230178326","rc":[{"atl":[[32,0.84]],"id":60748118}],"con":true,"img":false}]}
{"op":"mcm","clk":"11541430086","pt":1719505669586,"mc":[{"id":"1.230178326","rc":[{"atl":[[1000,0.19]],"id":60748118}],"con":true,"img":false}]}
{"op":"mcm","clk":"11541430106","pt":1719505669794,"mc":[{"id":"1.230178326","rc":[{"atl":[[1000,0.16]],"id":60748118}],"con":true,"img":false}]}
{"op":"mcm","clk":"11541430117","pt":1719505669896,"mc":[{"id":"1.230178326","rc":[{"atl":[[32,0.87]],"id":60748118}],"con":true,"img":false}]}
{"op":"mcm","clk":"11541430771","pt":1719505677206,"mc":[{"id":"1.230178326","rc":[{"atb":[[1.12,1.69]],"id":58221357},{"atb":[[1.1,1.69]],"id":62600242}],"con":true,"img":false}]}
{"op":"mcm","clk":"11541430802","pt":1719505677516,"mc":[{"id":"1.230178326","rc":[{"atb":[[1.1,1.69]],"id":60748118},{"atb":[[1.12,1.69]],"id":67674431}],"con":true,"img":false}]}
{"op":"mcm","clk":"11541430828","pt":1719505677783,"mc":[{"id":"1.230178326","rc":[{"atb":[[1.1,0.06]],"id":62600242},{"atb":[[1.1,1.69]],"id":68687941}],"con":true,"img":false}]}
{"op":"mcm","clk":"11541430842","pt":1719505677992,"mc":[{"id":"1.230178326","rc":[{"atb":[[1.1,1.69]],"id":65710029}],"con":true,"img":false}]}
{"op":"mcm","clk":"11541430851","pt":1719505678088,"mc":[{"id":"1.230178326","rc":[{"atb":[[1.12,0.05]],"id":58221357}],"con":true,"img":false}]}
{"op":"mcm","clk":"11541430861","pt":1719505678187,"mc":[{"id":"1.230178326","rc":[{"atb":[[1.12,0.05]],"id":67674431}],"con":true,"img":false}]}
{"op":"mcm","clk":"11541430902","pt":1719505678599,"mc":[{"id":"1.230178326","rc":[{"atb":[[1.1,0]],"id":62600242},{"atb":[[1.1,0.06]],"id":60748118}],"con":true,"img":false}]}
{"op":"mcm","clk":"11541430911","pt":1719505678702,"mc":[{"id":"1.230178326","rc":[{"atb":[[4.7,0.06]],"id":62600242}],"con":true,"img":false}]}
{"op":"mcm","clk":"11541430953","pt":1719505679119,"mc":[{"id":"1.230178326","rc":[{"atb":[[1.1,0.06]],"id":68687941}],"con":true,"img":false}]}
{"op":"mcm","clk":"11541430966","pt":1719505679223,"mc":[{"id":"1.230178326","rc":[{"atb":[[1.1,0.06]],"id":65710029}],"con":true,"img":false}]}
{"op":"mcm","clk":"11541430984","pt":1719505679387,"mc":[{"id":"1.230178326","rc":[{"atb":[[1.12,0]],"id":58221357}],"con":true,"img":false}]}
{"op":"mcm","clk":"11541430995","pt":1719505679490,"mc":[{"id":"1.230178326","rc":[{"atb":[[5,0.05]],"id":58221357}],"con":true,"img":false}]}
{"op":"mcm","clk":"11541431019","pt":1719505679790,"mc":[{"id":"1.230178326","rc":[{"atb":[[1.12,0]],"id":67674431}],"con":true,"img":false}]}
{"op":"mcm","clk":"11541431030","pt":1719505679896,"mc":[{"id":"1.230178326","rc":[{"atb":[[5.1,0.05]],"id":67674431}],"con":true,"img":false}]}
{"op":"mcm","clk":"11541431040","pt":1719505679997,"mc":[{"id":"1.230178326","rc":[{"atb":[[2.54,0]],"id":58221357},{"atb":[[2.52,0]],"id":62600242},{"atb":[[2.54,0]],"id":60748118},{"atb":[[2.54,0]],"id":67674431}],"con":true,"img":false}]}
{"op":"mcm","clk":"11541431051","pt":1719505680101,"mc":[{"id":"1.230178326","rc":[{"atb":[[3.35,7.7]],"id":58221357},{"atl":[[60,2]],"id":58221357},{"atb":[[3.35,7.8]],"id":62600242},{"atl":[[55,2]],"id":62600242},{"atb":[[3.7,8.14]],"id":60748118},{"atl":[[34,4.77]],"id":60748118},{"atb":[[3.8,7.7]],"id":67674431},{"atl":[[34,3.03]],"id":67674431}],"con":true,"img":false}]}
{"op":"mcm","clk":"11541431061","pt":1719505680205,"mc":[{"id":"1.230178326","rc":[{"atb":[[2.76,3.39]],"id":68687941},{"atl":[[26,5.71]],"id":68687941},{"atb":[[2.9,6.55]],"id":65710029},{"atl":[[27,3.61]],"id":65710029}],"con":true,"img":false}]}
{"op":"mcm","clk":"11541431073","pt":1719505680308,"mc":[{"id":"1.230178326","rc":[{"atb":[[1.1,0]],"id":60748118}],"con":true,"img":false}]}
{"op":"mcm","clk":"11541431084","pt":1719505680425,"mc":[{"id":"1.230178326","rc":[{"atb":[[4.6,0.06]],"id":60748118}],"con":true,"img":false}]}
{"op":"mcm","clk":"11541431116","pt":1719505680696,"mc":[{"id":"1.230178326","rc":[{"atb":[[1.1,0]],"id":68687941}],"con":true,"img":false}]}
{"op":"mcm","clk":"11541431124","pt":1719505680808,"mc":[{"id":"1.230178326","rc":[{"atb":[[4.7,0.06]],"id":68687941}],"con":true,"img":false}]}
{"op":"mcm","clk":"11541431151","pt":1719505681110,"mc":[{"id":"1.230178326","rc":[{"atb":[[1.1,0]],"id":65710029}],"con":true,"img":false}]}
{"op":"mcm","clk":"11541431161","pt":1719505681212,"mc":[{"id":"1.230178326","rc":[{"atb":[[4.6,0.06]],"id":65710029}],"con":true,"img":false}]}
{"op":"mcm","clk":"11541431431","pt":1719505683916,"mc":[{"id":"1.230178326","rc":[{"atl":[[8.2,1]],"id":68687941}],"con":true,"img":false}]}
{"op":"mcm","clk":"11541431559","pt":1719505685011,"mc":[{"id":"1.230178326","rc":[{"atl":[[32,0.84]],"id":60748118}],"con":true,"img":false}]}
{"op":"mcm","clk":"11541431576","pt":1719505685216,"mc":[{"id":"1.230178326","rc":[{"atl":[[1000,0.19]],"id":60748118}],"con":true,"img":false}]}
{"op":"mcm","clk":"11541431596","pt":1719505685424,"mc":[{"id":"1.230178326","rc":[{"atb":[[1.02,194.76]],"id":58221357},{"atl":[[1000,1.7]],"id":58221357},{"atb":[[1.02,75.63]],"id":62600242},{"atl":[[1000,1.87]],"id":62600242},{"atb":[[1.02,26.34]],"id":60748118},{"atl":[[1000,1.87]],"id":60748118}],"con":true,"img":false}]}
{"op":"mcm","clk":"11541431608","pt":1719505685489,"mc":[{"id":"1.230178326","rc":[{"atl":[[32,0.87]],"id":60748118}],"con":true,"img":false}]}
{"op":"mcm","clk":"11541431617","pt":1719505685587,"mc":[{"id":"1.230178326","rc":[{"atb":[[1.02,193.19]],"id":58221357},{"atl":[[1000,0]],"id":58221357},{"atb":[[1.02,74.06]],"id":62600242},{"atl":[[1000,0.17]],"id":62600242},{"atb":[[1.02,24.76]],"id":60748118},{"atl":[[1000,0.17]],"id":60748118}],"con":true,"img":false}]}
{"op":"mcm","clk":"11541431649","pt":1719505685896,"mc":[{"id":"1.230178326","rc":[{"atb":[[1.02,193.06]],"id":58221357},{"atl":[[1000,0]],"id":58221357},{"atb":[[1.02,73.93]],"id":62600242},{"atl":[[1000,0.16]],"id":62600242},{"atb":[[1.02,24.64]],"id":60748118},{"atl":[[1000,0.16]],"id":60748118}],"con":true,"img":false}]}
{"op":"mcm","clk":"11541431663","pt":1719505686000,"mc":[{"id":"1.230178326","rc":[{"atb":[[3.4,0.13]],"id":58221357},{"atl":[[55,0]],"id":58221357},{"atb":[[3.4,0.13]],"id":62600242},{"atl":[[50,0]],"id":62600242},{"atb":[[3.8,0.11]],"id":60748118},{"atl":[[32,0.88]],"id":60748118}],"con":true,"img":false}]}
{"op":"mcm","clk":"11541431795","pt":1719505687292,"mc":[{"id":"1.230178326","rc":[{"atb":[[2.88,3.38]],"id":65710029}],"con":true,"img":false}]}
{"op":"mcm","clk":"11541431809","pt":1719505687398,"mc":[{"id":"1.230178326","rc":[{"atb":[[2.58,7.5]],"id":58221357}],"con":true,"img":false}]}
{"op":"mcm","clk":"11541431830","pt":1719505687601,"mc":[{"id":"1.230178326","rc":[{"atb":[[2.58,7.5]],"id":60748118}],"con":true,"img":false}]}
{"op":"mcm","clk":"11541431838","pt":1719505687708,"mc":[{"id":"1.230178326","rc":[{"atb":[[2.58,7.5]],"id":67674431}],"con":true,"img":false}]}
{"op":"mcm","clk":"11541431858","pt":1719505687908,"mc":[{"id":"1.230178326","rc":[{"atb":[[2.56,7.6]],"id":62600242},{"atb":[[2.92,3.16]],"id":65710029}],"con":true,"img":false}]}
{"op":"mcm","clk":"11541432108","pt":1719505690507,"mc":[{"id":"1.230178326","rc":[{"atl":[[9.4,1]],"id":58221357},{"atl":[[9.4,1]],"id":62600242},{"atl":[[11,1]],"id":60748118},{"atl":[[8,1],[8.2,0]],"id":68687941},{"atb":[[4.3,1]],"id":67674431},{"atl":[[15,1]],"id":67674431},{"atl":[[9.4,1]],"id":65710029}],"con":true,"img":false}]}
{"op":"mcm","clk":"11541432119","pt":1719505690613,"mc":[{"id":"1.230178326","rc":[{"atl":[[50,2],[60,0]],"id":58221357},{"atb":[[3.8,6.11],[3.7,0]],"id":60748118}],"con":true,"img":false}]}
{"op":"mcm","clk":"11541432130","pt":1719505690704,"mc":[{"id":"1.230178326","rc":[{"atb":[[3.8,0],[4.4,6]],"id":67674431}],"con":true,"img":false}]}
{"op":"mcm","clk":"11541433080","pt":1719505700798,"mc":[{"id":"1.230178326","rc":[{"spn":14.21,"spf":"Infinity","id":58221357},{"spn":4.85,"spf":1.0,"id":62600242},{"atl":[[32,0.85]],"id":60748118},{"spn":7.8,"spf":"NaN","id":60748118},{"spn":4.6,"spf":1.0,"id":68687941},{"spn":10.05,"spf":"NaN","id":67674431},{"spn":3.25,"spf":1.0,"id":65710029}],"con":true,"img":false}]}
{"op":"mcm","clk":"11541433096","pt":1719505701005,"mc":[{"id":"1.230178326","rc":[{"atl":[[1000,0.27]],"id":60748118}],"con":true,"img":false}]}
{"op":"mcm","clk":"11541433120","pt":1719505701317,"mc":[{"id":"1.230178326","rc":[{"atl":[[1000,0.16]],"id":60748118}],"con":true,"img":false}]}
{"op":"mcm","clk":"11541433132","pt":1719505701421,"mc":[{"id":"1.230178326","rc":[{"atl":[[10.5,0.11]],"id":60748118}],"con":true,"img":false}]}
{"op":"mcm","clk":"11541433262","pt":1719505702918,"mc":[{"id":"1.230178326","rc":[{"spl":[[1.01,9]],"id":65710029}],"con":true,"img":false}]}
{"op":"mcm","clk":"11541433926","pt":1719505709712,"mc":[{"id":"1.230178326","rc":[{"atb":[[2.88,0]],"id":65710029}],"con":true,"img":false}]}
{"op":"mcm","clk":"11541433969","pt":1719505710226,"mc":[{"id":"1.230178326","rc":[{"atb":[[2.92,6.54]],"id":65710029}],"con":true,"img":false}]}
{"op":"mcm","clk":"11541434531","pt":1719505716560,"mc":[{"id":"1.230178326","rc":[{"atl":[[10.5,0]],"id":60748118}],"con":true,"img":false}]}
{"op":"mcm","clk":"11541434592","pt":1719505717236,"mc":[{"id":"1.230178326","rc":[{"atl":[[1000,0.27]],"id":60748118}],"con":true,"img":false}]}
{"op":"mcm","clk":"11541434614","pt":1719505717544,"mc":[{"id":"1.230178326","rc":[{"atl":[[1000,0.16]],"id":60748118}],"con":true,"img":false}]}
{"op":"mcm","clk":"11541434626","pt":1719505717645,"mc":[{"id":"1.230178326","rc":[{"atl":[[10.5,0.11]],"id":60748118}],"con":true,"img":false}]}
{"op":"mcm","clk":"11541435540","pt":1719505727660,"mc":[{"id":"1.230178326","rc":[{"atb":[[3.4,0]],"id":58221357},{"atl":[[55,0]],"id":58221357},{"atb":[[3.4,0]],"id":62600242},{"atl":[[50,0]],"id":62600242},{"atb":[[3.8,6]],"id":60748118},{"atl":[[32,0.84]],"id":60748118}],"con":true,"img":false}]}
{"op":"mcm","clk":"11541435980","pt":1719505732841,"mc":[{"id":"1.230178326","rc":[{"atl":[[10.5,0]],"id":60748118}],"con":true,"img":false}]}
{"op":"mcm","clk":"11541435997","pt":1719505733045,"mc":[{"id":"1.230178326","rc":[{"atl":[[1000,0.27]],"id":60748118}],"con":true,"img":false}]}
{"op":"mcm","clk":"11541436020","pt":1719505733260,"mc":[{"id":"1.230178326","rc":[{"atl":[[1000,0.16]],"id":60748118}],"con":true,"img":false}]}
{"op":"mcm","clk":"11541436026","pt":1719505733357,"mc":[{"id":"1.230178326","rc":[{"atl":[[10.5,0.11]],"id":60748118}],"con":true,"img":false}]}
{"op":"mcm","clk":"11541436568","pt":1719505739243,"mc":[{"id":"1.230178326","rc":[{"atb":[[2.56,0]],"id":58221357},{"atb":[[2.54,0]],"id":62600242},{"atb":[[2.56,0]],"id":60748118},{"atb":[[2.56,0]],"id":67674431}],"con":true,"img":false}]}
{"op":"mcm","clk":"11541436767","pt":1719505741189,"mc":[{"id":"1.230178326","rc":[{"atb":[[4.5,0.15],[4.6,0]],"id":65710029},{"trd":[[4.5,1.7],[4.6,0.13]],"ltp":4.5,"tv":1.83,"id":65710029}],"con":true,"img":false}]}
{"op":"mcm","clk":"11541436922","pt":1719505742388,"mc":[{"id":"1.230178326","rc":[{"atb":[[1.04,72.09]],"id":65710029}],"con":true,"img":false}]}
{"op":"mcm","clk":"11541436946","pt":1719505742602,"mc":[{"id":"1.230178326","rc":[{"atb":[[1.04,71.61]],"id":65710029}],"con":true,"img":false}]}
{"op":"mcm","clk":"11541436955","pt":1719505742699,"mc":[{"id":"1.230178326","rc":[{"atb":[[5,0]],"id":58221357},{"atb":[[4.7,0]],"id":62600242},{"atb":[[4.6,0]],"id":60748118},{"atb":[[4.7,0]],"id":68687941},{"atb":[[5.1,0]],"id":67674431}],"con":true,"img":false}]}
{"op":"mcm","clk":"11541436976","pt":1719505742856,"mc":[{"id":"1.230178326","rc":[{"atb":[[1.04,71.09]],"id":65710029}],"con":true,"img":false}]}
{"op":"mcm","clk":"11541436990","pt":1719505742959,"mc":[{"id":"1.230178326","rc":[{"atb":[[2.94,0.52]],"id":65710029}],"con":true,"img":false}]}
{"op":"mcm","clk":"11541437055","pt":1719505743680,"mc":[{"id":"1.230178326","rc":[{"atb":[[4,1],[4.5,0]],"id":65710029}],"con":true,"img":false}]}
{"op":"mcm","clk":"11541437289","pt":1719505745961,"mc":[{"id":"1.230178326","rc":[{"atb":[[2.6,7.93]],"id":58221357}],"con":true,"img":false}]}
{"op":"mcm","clk":"11541437308","pt":1719505746076,"mc":[{"id":"1.230178326","rc":[{"atb":[[2.58,8.03]],"id":62600242}],"con":true,"img":false}]}
{"op":"mcm","clk":"11541437346","pt":1719505746305,"mc":[{"id":"1.230178326","rc":[{"atb":[[2.6,7.93]],"id":60748118}],"con":true,"img":false}]}
{"op":"mcm","clk":"11541437406","pt":1719505747049,"mc":[{"id":"1.230178326","rc":[{"atb":[[2.6,7.93]],"id":67674431}],"con":true,"img":false}]}
{"op":"mcm","clk":"11541437540","pt":1719505748593,"mc":[{"id":"1.230178326","rc":[{"atl":[[10.5,0]],"id":60748118}],"con":true,"img":false}]}
{"op":"mcm","clk":"11541437570","pt":1719505748917,"mc":[{"id":"1.230178326","rc":[{"atl":[[1000,0.27]],"id":60748118}],"con":true,"img":false}]}
{"op":"mcm","clk":"11541437586","pt":1719505749073,"mc":[{"id":"1.230178326","rc":[{"atl":[[1000,0.16]],"id":60748118}],"con":true,"img":false}]}
{"op":"mcm","clk":"11541437594","pt":1719505749160,"mc":[{"id":"1.230178326","rc":[{"atl":[[10.5,0.11]],"id":60748118}],"con":true,"img":false}]}
{"op":"mcm","clk":"11541438445","pt":1719505758091,"mc":[{"id":"1.230178326","rc":[{"atb":[[2.94,0]],"id":65710029}],"con":true,"img":false}]}
{"op":"mcm","clk":"11541438456","pt":1719505758196,"mc":[{"id":"1.230178326","rc":[{"atb":[[2.38,8.59]],"id":65710029}],"con":true,"img":false}]}
{"op":"mcm","clk":"11541439069","pt":1719505764508,"mc":[{"id":"1.230178326","rc":[{"spn":4.8,"spf":1.0,"id":62600242},{"atl":[[10.5,0]],"id":60748118},{"spn":7.75,"spf":"NaN","id":60748118},{"spn":4.6,"spf":1.0,"id":68687941},{"spn":10.0,"spf":"NaN","id":67674431},{"spn":3.03,"spf":1.0,"id":65710029}],"con":true,"img":false}]}
{"op":"mcm","clk":"11541439084","pt":1719505764716,"mc":[{"id":"1.230178326","rc":[{"atl":[[1000,0.27]],"id":60748118}],"con":true,"img":false}]}
{"op":"mcm","clk":"11541439100","pt":1719505764872,"mc":[{"id":"1.230178326","rc":[{"atl":[[1000,0.16]],"id":60748118}],"con":true,"img":false}]}
{"op":"mcm","clk":"11541439109","pt":1719505764976,"mc":[{"id":"1.230178326","rc":[{"atl":[[10.5,0.11]],"id":60748118}],"con":true,"img":false}]}
{"op":"mcm","clk":"11541439753","pt":1719505772411,"mc":[{"id":"1.230178326","rc":[{"atl":[[1000,1.16]],"id":65710029}],"con":true,"img":false}]}
{"op":"mcm","clk":"11541439765","pt":1719505772514,"mc":[{"id":"1.230178326","rc":[{"atl":[[1000,0.17]],"id":65710029}],"con":true,"img":false}]}
{"op":"mcm","clk":"11541439779","pt":1719505772669,"mc":[{"id":"1.230178326","rc":[{"atl":[[1000,0.16]],"id":65710029}],"con":true,"img":false}]}
{"op":"mcm","clk":"11541439791","pt":1719505772785,"mc":[{"id":"1.230178326","rc":[{"atl":[[9.2,0.01]],"id":65710029}],"con":true,"img":false}]}
{"op":"mcm","clk":"11541439986","pt":1719505775095,"mc":[{"id":"1.230178326","rc":[{"atb":[[2.58,0]],"id":58221357},{"atb":[[2.56,0]],"id":62600242},{"atb":[[2.58,0]],"id":60748118},{"atb":[[2.58,0]],"id":67674431}],"con":true,"img":false}]}
{"op":"mcm","clk":"11541440353","pt":1719505779189,"mc":[{"id":"1.230178326","rc":[{"atb":[[2.62,7.31]],"id":60748118}],"con":true,"img":false}]}
{"op":"mcm","clk":"11541440370","pt":1719505779396,"mc":[{"id":"1.230178326","rc":[{"atb":[[2.6,7.41]],"id":62600242}],"con":true,"img":false}]}
{"op":"mcm","clk":"11541440377","pt":1719505779498,"mc":[{"id":"1.230178326","rc":[{"atb":[[2.62,7.31]],"id":58221357}],"con":true,"img":false}]}
{"op":"mcm","clk":"11541440438","pt":1719505780222,"mc":[{"id":"1.230178326","rc":[{"atl":[[10.5,0]],"id":60748118}],"con":true,"img":false}]}
{"op":"mcm","clk":"11541440455","pt":1719505780426,"mc":[{"id":"1.230178326","rc":[{"atl":[[1000,0.27]],"id":60748118}],"con":true,"img":false}]}
{"op":"mcm","clk":"11541440472","pt":1719505780583,"mc":[{"id":"1.230178326","rc":[{"atl":[[1000,0.16]],"id":60748118}],"con":true,"img":false}]}
{"op":"mcm","clk":"11541440482","pt":1719505780690,"mc":[{"id":"1.230178326","rc":[{"atl":[[10.5,0.11]],"id":60748118}],"con":true,"img":false}]}
{"op":"mcm","clk":"11541440492","pt":1719505780791,"mc":[{"id":"1.230178326","rc":[{"atb":[[2.62,7.31]],"id":67674431}],"con":true,"img":false}]}
{"op":"mcm","clk":"11541441861","pt":1719505795907,"mc":[{"id":"1.230178326","rc":[{"atl":[[10.5,0]],"id":60748118}],"con":true,"img":false}]}
{"op":"mcm","clk":"11541441884","pt":1719505796112,"mc":[{"id":"1.230178326","rc":[{"atl":[[1000,0.27]],"id":60748118}],"con":true,"img":false}]}
{"op":"mcm","clk":"11541441907","pt":1719505796321,"mc":[{"id":"1.230178326","rc":[{"atl":[[1000,0.16]],"id":60748118}],"con":true,"img":false}]}
{"op":"mcm","clk":"11541441917","pt":1719505796413,"mc":[{"id":"1.230178326","rc":[{"atl":[[10.5,0.11]],"id":60748118}],"con":true,"img":false}]}
{"op":"mcm","clk":"11541442601","pt":1719505803320,"mc":[{"id":"1.230178326","rc":[{"atb":[[1.02,194.76]],"id":58221357},{"atl":[[1000,1.7]],"id":58221357},{"atb":[[1.02,75.63]],"id":62600242},{"atl":[[1000,1.87]],"id":62600242},{"atb":[[1.03,192.96]],"id":60748118},{"atl":[[1000,1.87]],"id":60748118}],"con":true,"img":false}]}
{"op":"mcm","clk":"11541442622","pt":1719505803528,"mc":[{"id":"1.230178326","rc":[{"atb":[[1.02,193.19]],"id":58221357},{"atl":[[1000,0]],"id":58221357},{"atb":[[1.02,74.06]],"id":62600242},{"atl":[[1000,0.17]],"id":62600242},{"atb":[[1.03,191.37]],"id":60748118},{"atl":[[1000,0.17]],"id":60748118}],"con":true,"img":false}]}
{"op":"mcm","clk":"11541442640","pt":1719505803734,"mc":[{"id":"1.230178326","rc":[{"atb":[[1.02,193.06]],"id":58221357},{"atl":[[1000,0]],"id":58221357},{"atb":[[1.02,73.93]],"id":62600242},{"atl":[[1000,0.16]],"id":62600242},{"atb":[[1.03,191.26]],"id":60748118},{"atl":[[1000,0.16]],"id":60748118}],"con":true,"img":false}]}
{"op":"mcm","clk":"11541442653","pt":1719505803839,"mc":[{"id":"1.230178326","rc":[{"atb":[[3.4,0.12]],"id":58221357},{"atl":[[48,0]],"id":58221357},{"atb":[[3.4,0.12]],"id":62600242},{"atl":[[50,0]],"id":62600242},{"atb":[[3.85,0.1]],"id":60748118},{"atl":[[30,0.01]],"id":60748118}],"con":true,"img":false}]}
{"op":"mcm","clk":"11541443212","pt":1719505809051,"mc":[{"id":"1.230178326","rc":[{"atb":[[2.6,0]],"id":58221357},{"atb":[[2.58,0]],"id":62600242},{"atb":[[2.6,0]],"id":60748118},{"atb":[[2.6,0]],"id":67674431}],"con":true,"img":false}]}
{"op":"mcm","clk":"11541443493","pt":1719505811640,"mc":[{"id":"1.230178326","rc":[{"atl":[[10.5,0]],"id":60748118}],"con":true,"img":false}]}
{"op":"mcm","clk":"11541443525","pt":1719505811950,"mc":[{"id":"1.230178326","rc":[{"atl":[[1000,0.27]],"id":60748118}],"con":true,"img":false}]}
{"op":"mcm","clk":"11541443553","pt":1719505812158,"mc":[{"id":"1.230178326","rc":[{"atl":[[1000,0.16]],"id":60748118}],"con":true,"img":false}]}
{"op":"mcm","clk":"11541443566","pt":1719505812262,"mc":[{"id":"1.230178326","rc":[{"atl":[[10.5,0.11]],"id":60748118}],"con":true,"img":false}]}
{"op":"mcm","clk":"11541444018","pt":1719505816864,"mc":[{"id":"1.230178326","rc":[{"atb":[[2.64,7.74]],"id":58221357}],"con":true,"img":false}]}
{"op":"mcm","clk":"11541444046","pt":1719505817126,"mc":[{"id":"1.230178326","rc":[{"atb":[[2.64,7.74]],"id":60748118}],"con":true,"img":false}]}
{"op":"mcm","clk":"11541444057","pt":1719505817236,"mc":[{"id":"1.230178326","rc":[{"atb":[[2.62,7.83]],"id":62600242}],"con":true,"img":false}]}
{"op":"mcm","clk":"11541444082","pt":1719505817441,"mc":[{"id":"1.230178326","rc":[{"atb":[[2.64,7.74]],"id":67674431}],"con":true,"img":false}]}
{"op":"mcm","clk":"11541444109","pt":1719505817744,"mc":[{"id":"1.230178326","rc":[{"atb":[[2.4,9.06]],"id":65710029}],"con":true,"img":false}]}
{"op":"mcm","clk":"11541445018","pt":1719505827471,"mc":[{"id":"1.230178326","rc":[{"spn":14.21,"spf":"Infinity","id":58221357},{"atl":[[10.5,0]],"id":60748118}],"con":true,"img":false}]}
{"op":"mcm","clk":"11541445035","pt":1719505827677,"mc":[{"id":"1.230178326","rc":[{"atl":[[1000,0.27]],"id":60748118}],"con":true,"img":false}]}
{"op":"mcm","clk":"11541445056","pt":1719505827884,"mc":[{"id":"1.230178326","rc":[{"atl":[[1000,0.16]],"id":60748118}],"con":true,"img":false}]}
{"op":"mcm","clk":"11541445067","pt":1719505827945,"mc":[{"id":"1.230178326","rc":[{"atl":[[10.5,0.11]],"id":60748118}],"con":true,"img":false}]}
{"op":"mcm","clk":"11541445976","pt":1719505837573,"mc":[{"id":"1.230178326","rc":[{"atb":[[3.15,1]],"id":68687941},{"atb":[[4.3,0],[4.6,1]],"id":67674431},{"atb":[[3.3,1]],"id":65710029}],"con":true,"img":false}]}
{"op":"mcm","clk":"11541446115","pt":1719505838968,"mc":[{"id":"1.230178326","rc":[{"atb":[[3.2,1],[3.15,0]],"id":68687941},{"atb":[[4.3,1],[4.6,0]],"id":67674431},{"atb":[[3.25,1],[3.3,0]],"id":65710029}],"con":true,"img":false}]}
{"op":"mcm","clk":"11541446126","pt":1719505839073,"mc":[{"id":"1.230178326","rc":[{"atb":[[3.15,3.39]],"id":68687941},{"atb":[[3.3,6.55],[2.9,0]],"id":65710029}],"con":true,"img":false}]}
{"op":"mcm","clk":"11541446134","pt":1719505839176,"mc":[{"id":"1.230178326","rc":[{"atb":[[2.76,0]],"id":68687941}],"con":true,"img":false}]}
{"op":"mcm","clk":"11541446230","pt":1719505840060,"mc":[{"id":"1.230178326","rc":[{"atb":[[3.2,0],[3.15,4.39]],"id":68687941},{"atb":[[4.3,0],[4.6,1]],"id":67674431},{"atb":[[3.25,0],[3.3,7.55]],"id":65710029}],"con":true,"img":false}]}
{"op":"mcm","clk":"11541446291","pt":1719505840576,"mc":[{"id":"1.230178326","rc":[{"atb":[[3.2,1],[3.15,3.39]],"id":68687941},{"atb":[[4.3,1],[4.6,0]],"id":67674431},{"atb":[[3.25,1],[3.3,6.55]],"id":65710029}],"con":true,"img":false}]}
{"op":"mcm","clk":"11541446314","pt":1719505840785,"mc":[{"id":"1.230178326","rc":[{"atb":[[3.2,0],[3.15,4.39]],"id":68687941},{"atb":[[4.3,0],[4.6,1]],"id":67674431},{"atb":[[3.25,0],[3.3,7.55]],"id":65710029}],"con":true,"img":false}]}
{"op":"mcm","clk":"11541446397","pt":1719505841457,"mc":[{"id":"1.230178326","rc":[{"atb":[[3.2,1],[3.15,3.39]],"id":68687941},{"atb":[[4.3,1],[4.6,0]],"id":67674431},{"atb":[[3.25,1],[3.3,6.55]],"id":65710029}],"con":true,"img":false}]}
{"op":"mcm","clk":"11541446434","pt":1719505841871,"mc":[{"id":"1.230178326","rc":[{"atb":[[3.2,0],[3.15,4.39]],"id":68687941},{"atb":[[4.3,0],[4.6,1]],"id":67674431},{"atb":[[3.25,0],[3.3,7.55]],"id":65710029}],"con":true,"img":false}]}
{"op":"mcm","clk":"11541446547","pt":1719505842958,"mc":[{"id":"1.230178326","rc":[{"atb":[[3.2,1],[3.15,3.39]],"id":68687941},{"atb":[[4.3,1],[4.6,0]],"id":67674431},{"atb":[[3.25,1],[3.3,6.55]],"id":65710029}],"con":true,"img":false}]}
{"op":"mcm","clk":"11541446566","pt":1719505843165,"mc":[{"id":"1.230178326","rc":[{"atl":[[10.5,0]],"id":60748118}],"con":true,"img":false}]}
{"op":"mcm","clk":"11541446597","pt":1719505843477,"mc":[{"id":"1.230178326","rc":[{"atl":[[1000,0.27]],"id":60748118}],"con":true,"img":false}]}
{"op":"mcm","clk":"11541446619","pt":1719505843686,"mc":[{"id":"1.230178326","rc":[{"atl":[[1000,0.16]],"id":60748118}],"con":true,"img":false}]}
{"op":"mcm","clk":"11541446630","pt":1719505843791,"mc":[{"id":"1.230178326","rc":[{"atl":[[10.5,0.11]],"id":60748118}],"con":true,"img":false}]}
{"op":"mcm","clk":"11541446938","pt":1719505846583,"mc":[{"id":"1.230178326","rc":[{"atb":[[3.4,0]],"id":58221357},{"atl":[[48,0]],"id":58221357},{"atb":[[3.4,0]],"id":62600242},{"atl":[[50,0]],"id":62600242},{"atb":[[3.85,0]],"id":60748118},{"atl":[[30,0]],"id":60748118}],"con":true,"img":false}]}
{"op":"mcm","clk":"11541447049","pt":1719505847568,"mc":[{"id":"1.230178326","rc":[{"atb":[[2.62,0]],"id":58221357},{"atb":[[2.6,0]],"id":62600242},{"atb":[[2.62,0]],"id":60748118},{"atb":[[2.62,0]],"id":67674431},{"atb":[[2.92,3.16],[2.38,0]],"id":65710029}],"con":true,"img":false}]}
{"op":"mcm","clk":"11541448020","pt":1719505857004,"mc":[{"id":"1.230178326","rc":[{"atb":[[2.66,7.14]],"id":58221357},{"atb":[[2.92,0]],"id":65710029}],"con":true,"img":false}]}
{"op":"mcm","clk":"11541448040","pt":1719505857213,"mc":[{"id":"1.230178326","rc":[{"atb":[[2.66,7.14]],"id":60748118}],"con":true,"img":false}]}
{"op":"mcm","clk":"11541448051","pt":1719505857264,"mc":[{"id":"1.230178326","rc":[{"atb":[[2.64,7.23]],"id":62600242}],"con":true,"img":false}]}
{"op":"mcm","clk":"11541448062","pt":1719505857376,"mc":[{"id":"1.230178326","rc":[{"atb":[[2.42,8.34]],"id":65710029}],"con":true,"img":false}]}
{"op":"mcm","clk":"11541448132","pt":1719505858194,"mc":[{"id":"1.230178326","rc":[{"atb":[[2.66,7.14]],"id":67674431}],"con":true,"img":false}]}
{"op":"mcm","clk":"11541448221","pt":1719505858972,"mc":[{"id":"1.230178326","rc":[{"atl":[[10.5,0]],"id":60748118}],"con":true,"img":false}]}
{"op":"mcm","clk":"11541448253","pt":1719505859306,"mc":[{"id":"1.230178326","rc":[{"atl":[[1000,0.27]],"id":60748118}],"con":true,"img":false}]}
{"op":"mcm","clk":"11541448275","pt":1719505859515,"mc":[{"id":"1.230178326","rc":[{"atl":[[1000,0.16]],"id":60748118}],"con":true,"img":false}]}
{"op":"mcm","clk":"11541448285","pt":1719505859618,"mc":[{"id":"1.230178326","rc":[{"atl":[[10.5,0.11]],"id":60748118}],"con":true,"img":false}]}
{"op":"mcm","clk":"11541449410","pt":1719505870816,"mc":[{"id":"1.230178326","rc":[{"atb":[[2.74,9.97]],"id":68687941}],"con":true,"img":false}]}
{"op":"mcm","clk":"11541449534","pt":1719505872112,"mc":[{"id":"1.230178326","rc":[{"atb":[[2.76,7.21]],"id":68687941}],"con":true,"img":false}]}
{"op":"mcm","clk":"11541449573","pt":1719505872489,"mc":[{"id":"1.230178326","rc":[{"atb":[[2.38,0]],"id":68687941}],"con":true,"img":false}]}
{"op":"mcm","clk":"11541449655","pt":1719505873408,"mc":[{"id":"1.230178326","rc":[{"atb":[[2.76,10.59]],"id":68687941}],"con":true,"img":false}]}
{"op":"mcm","clk":"11541449774","pt":1719505874900,"mc":[{"id":"1.230178326","rc":[{"atl":[[10.5,0]],"id":60748118}],"con":true,"img":false}]}
{"op":"mcm","clk":"11541449791","pt":1719505875105,"mc":[{"id":"1.230178326","rc":[{"atl":[[1000,0.27]],"id":60748118}],"con":true,"img":false}]}
{"op":"mcm","clk":"11541449816","pt":1719505875413,"mc":[{"id":"1.230178326","rc":[{"atl":[[1000,0.16]],"id":60748118}],"con":true,"img":false}]}
{"op":"mcm","clk":"11541449827","pt":1719505875516,"mc":[{"id":"1.230178326","rc":[{"atl":[[10.5,0.11]],"id":60748118}],"con":true,"img":false}]}
{"op":"mcm","clk":"11541450527","pt":1719505883223,"mc":[{"id":"1.230178326","rc":[{"atb":[[5,1.69]],"id":58221357}],"con":true,"img":false}]}
{"op":"mcm","clk":"11541450540","pt":1719505883427,"mc":[{"id":"1.230178326","rc":[{"atb":[[4.7,1.8]],"id":62600242}],"con":true,"img":false}]}
{"op":"mcm","clk":"11541450549","pt":1719505883530,"mc":[{"id":"1.230178326","rc":[{"atl":[[9,0.93]],"id":65710029}],"con":true,"img":false}]}
{"op":"mcm","clk":"11541450558","pt":1719505883634,"mc":[{"id":"1.230178326","rc":[{"atl":[[11.5,3.61]],"id":65710029}],"con":true,"img":false}]}
{"op":"mcm","clk":"11541450567","pt":1719505883699,"mc":[{"id":"1.230178326","rc":[{"atl":[[1000,1.01]],"id":67674431},{"atl":[[27,1.61]],"id":65710029}],"con":true,"img":false}]}
{"op":"mcm","clk":"11541450576","pt":1719505883796,"mc":[{"id":"1.230178326","rc":[{"atb":[[5.1,0.84]],"id":58221357},{"atb":[[4.8,0.84]],"id":62600242},{"atl":[[10,0.84]],"id":60748118}],"con":true,"img":false}]}
{"op":"mcm","clk":"11541450585","pt":1719505883904,"mc":[{"id":"1.230178326","rc":[{"atl":[[34,1.74],[13,4.77]],"id":60748118},{"atl":[[9.2,0]],"id":65710029}],"con":true,"img":false}]}
{"op":"mcm","clk":"11541450594","pt":1719505883998,"mc":[{"id":"1.230178326","rc":[{"atl":[[8.8,0.01]],"id":65710029}],"con":true,"img":false}]}
{"op":"mcm","clk":"11541450611","pt":1719505884212,"mc":[{"id":"1.230178326","rc":[{"atl":[[1000,0.75]],"id":67674431}],"con":true,"img":false}]}
{"op":"mcm","clk":"11541450648","pt":1719505884616,"mc":[{"id":"1.230178326","rc":[{"atl":[[1000,0.16]],"id":67674431}],"con":true,"img":false}]}
{"op":"mcm","clk":"11541450658","pt":1719505884718,"mc":[{"id":"1.230178326","rc":[{"atl":[[14.5,0.58]],"id":67674431}],"con":true,"img":false}]}
{"op":"mcm","clk":"11541450768","pt":1719505885917,"mc":[{"id":"1.230178326","rc":[{"atl":[[27,0]],"id":65710029}],"con":true,"img":false}]}
{"op":"mcm","clk":"11541450794","pt":1719505886224,"mc":[{"id":"1.230178326","rc":[{"atl":[[34,0]],"id":60748118}],"con":true,"img":false}]}
{"op":"mcm","clk":"11541451243","pt":1719505890848,"mc":[{"id":"1.230178326","rc":[{"spn":14.21,"spf":"Infinity","id":58221357},{"spn":4.9,"spf":1.0,"id":62600242},{"atl":[[10.5,0]],"id":60748118},{"spn":7.25,"spf":"NaN","id":60748118},{"spn":9.75,"spf":"NaN","id":67674431},{"spn":3.35,"spf":1.0,"id":65710029}],"con":true,"img":false}]}
{"op":"mcm","clk":"11541451275","pt":1719505891117,"mc":[{"id":"1.230178326","rc":[{"atl":[[1000,0.27]],"id":60748118}],"con":true,"img":false}]}
{"op":"mcm","clk":"11541451302","pt":1719505891422,"mc":[{"id":"1.230178326","rc":[{"atl":[[1000,0.16]],"id":60748118}],"con":true,"img":false}]}
{"op":"mcm","clk":"11541451312","pt":1719505891526,"mc":[{"id":"1.230178326","rc":[{"atl":[[10.5,0.11]],"id":60748118}],"con":true,"img":false}]}
{"op":"mcm","clk":"11541451342","pt":1719505891837,"mc":[{"id":"1.230178326","rc":[{"atl":[[10.5,1.82]],"id":60748118}],"con":true,"img":false}]}
{"op":"mcm","clk":"11541451841","pt":1719505897906,"mc":[{"id":"1.230178326","rc":[{"atb":[[2.64,0]],"id":58221357},{"atb":[[2.62,0]],"id":62600242},{"atb":[[2.64,0]],"id":60748118},{"atb":[[2.64,0]],"id":67674431},{"atb":[[2.4,0]],"id":65710029}],"con":true,"img":false}]}
{"op":"mcm","clk":"11541452262","pt":1719505903035,"mc":[{"id":"1.230178326","rc":[{"atb":[[4.8,0],[4.7,0]],"id":62600242},{"atl":[[4.7,3.61]],"id":62600242},{"trd":[[4.7,3.6],[4.8,1.69]],"ltp":4.7,"tv":5.29,"id":62600242},{"atb":[[4.6,0]],"id":68687941},{"atl":[[4.6,5.39]],"id":68687941},{"trd":[[4.6,2]],"ltp":4.6,"tv":2.0,"id":68687941},{"atb":[[4,0]],"id":65710029},{"atl":[[4,6.35]],"id":65710029},{"trd":[[4,2]],"ltp":4.0,"tv":2.0,"id":65710029}],"con":true,"img":false}]}
{"op":"mcm","clk":"11541452273","pt":1719505903123,"mc":[{"id":"1.230178326","rc":[{"atl":[[4.7,0]],"id":62600242},{"trd":[[4.7,10.82]],"ltp":4.7,"tv":10.82,"id":62600242},{"atb":[[3.65,1]],"id":60748118},{"atb":[[3.15,0],[2.78,9.97]],"id":68687941},{"atl":[[11,6.39],[26,1.71]],"id":68687941}],"con":true,"img":false}]}
{"op":"mcm","clk":"11541452282","pt":1719505903226,"mc":[{"id":"1.230178326","rc":[{"atl":[[11,4.61],[55,0]],"id":62600242},{"atb":[[2.88,8.35],[3.3,0]],"id":65710029}],"con":true,"img":false}]}
{"op":"mcm","clk":"11541452289","pt":1719505903329,"mc":[{"id":"1.230178326","rc":[{"atb":[[3.85,0.84]],"id":68687941},{"atb":[[5.1,1.65]],"id":67674431},{"atb":[[3.4,0.84]],"id":65710029}],"con":true,"img":false}]}
{"op":"mcm","clk":"11541452296","pt":1719505903432,"mc":[{"id":"1.230178326","rc":[{"atb":[[5.1,0]],"id":58221357}],"con":true,"img":false}]}
{"op":"mcm","clk":"11541452332","pt":1719505903849,"mc":[{"id":"1.230178326","rc":[{"atb":[[5.1,0.84]],"id":58221357},{"atb":[[3.85,0]],"id":68687941},{"atb":[[3.4,0]],"id":65710029}],"con":true,"img":false}]}
{"op":"mcm","clk":"11541452342","pt":1719505903952,"mc":[{"id":"1.230178326","rc":[{"atb":[[2.86,2.09]],"id":68687941}],"con":true,"img":false}]}
{"op":"mcm","clk":"11541452351","pt":1719505904012,"mc":[{"id":"1.230178326","rc":[{"atl":[[26,0]],"id":68687941}],"con":true,"img":false}]}
{"op":"mcm","clk":"11541452372","pt":1719505904221,"mc":[{"id":"1.230178326","rc":[{"atb":[[5,2.69],[4.9,0]],"id":58221357},{"atb":[[4.6,0],[4.7,1]],"id":62600242},{"atl":[[1000,0.28]],"id":62600242},{"atb":[[1.05,1]],"id":68687941}],"con":true,"img":false}]}
{"op":"mcm","clk":"11541452382","pt":1719505904323,"mc":[{"id":"1.230178326","rc":[{"atb":[[3.4,3.33]],"id":62600242}],"con":true,"img":false}]}
{"op":"mcm","clk":"11541452395","pt":1719505904426,"mc":[{"id":"1.230178326","rc":[{"atl":[[1000,0.16]],"id":62600242},{"atb":[[1.05,0.43]],"id":68687941}],"con":true,"img":false}]}
{"op":"mcm","clk":"11541452405","pt":1719505904522,"mc":[{"id":"1.230178326","rc":[{"atl":[[9.2,0.12]],"id":62600242}],"con":true,"img":false}]}
{"op":"mcm","clk":"11541452416","pt":1719505904625,"mc":[{"id":"1.230178326","rc":[{"atb":[[1.05,0]],"id":68687941}],"con":true,"img":false}]}
{"op":"mcm","clk":"11541452426","pt":1719505904729,"mc":[{"id":"1.230178326","rc":[{"atb":[[3.25,0.44]],"id":68687941}],"con":true,"img":false}]}
{"op":"mcm","clk":"11541452548","pt":1719505905727,"mc":[{"id":"1.230178326","rc":[{"atb":[[2.44,8.81]],"id":65710029}],"con":true,"img":false}]}
{"op":"mcm","clk":"11541452582","pt":1719505906143,"mc":[{"id":"1.230178326","rc":[{"atb":[[2.76,7.21]],"id":68687941}],"con":true,"img":false}]}
{"op":"mcm","clk":"11541452599","pt":1719505906248,"mc":[{"id":"1.230178326","rc":[{"atb":[[2.68,7.55]],"id":58221357}],"con":true,"img":false}]}
{"op":"mcm","clk":"11541452649","pt":1719505906742,"mc":[{"id":"1.230178326","rc":[{"atl":[[10.5,1.71]],"id":60748118}],"con":true,"img":false}]}
{"op":"mcm","clk":"11541452668","pt":1719505906950,"mc":[{"id":"1.230178326","rc":[{"atl":[[1000,0.27]],"id":60748118}],"con":true,"img":false}]}
{"op":"mcm","clk":"11541452692","pt":1719505907250,"mc":[{"id":"1.230178326","rc":[{"atb":[[3.3,7]],"id":62600242},{"atl":[[13,0],[14.5,7.41],[1000,0.16]],"id":60748118},{"atl":[[8,0]],"id":68687941},{"atb":[[3.25,0],[3.15,1]],"id":65710029}],"con":true,"img":false}]}
{"op":"mcm","clk":"11541452706","pt":1719505907355,"mc":[{"id":"1.230178326","rc":[{"atl":[[10,0.95]],"id":60748118}],"con":true,"img":false}]}
{"op":"mcm","clk":"11541453048","pt":1719505911031,"mc":[{"id":"1.230178326","rc":[{"atb":[[2.88,7.21],[2.78,0]],"id":68687941}],"con":true,"img":false}]}
{"op":"mcm","clk":"11541453138","pt":1719505912137,"mc":[{"id":"1.230178326","rc":[{"atl":[[9.6,1],[9.4,0]],"id":58221357},{"atl":[[9.6,1],[9.4,0]],"id":62600242},{"atl":[[19,1],[15,0]],"id":67674431}],"con":true,"img":false}]}
{"op":"mcm","clk":"11541453148","pt":1719505912251,"mc":[{"id":"1.230178326","rc":[{"atl":[[34,0],[19,6.56]],"id":67674431}],"con":true,"img":false}]}
{"op":"mcm","clk":"11541453161","pt":1719505912335,"mc":[{"id":"1.230178326","rc":[{"atl":[[34,3.03],[19,1]],"id":67674431}],"con":true,"img":false}]}
{"op":"mcm","clk":"11541453172","pt":1719505912447,"mc":[{"id":"1.230178326","rc":[{"atl":[[9.4,1]],"id":58221357},{"atl":[[9.6,0],[9.4,1]],"id":62600242},{"atl":[[13.5,7.41],[14.5,0]],"id":60748118},{"atb":[[4.4,0],[4.6,6]],"id":67674431}],"con":true,"img":false}]}
{"op":"mcm","clk":"11541453183","pt":1719505912549,"mc":[{"id":"1.230178326","rc":[{"atl":[[9.6,0]],"id":58221357}],"con":true,"img":false}]}
{"op":"mcm","clk":"11541453266","pt":1719505913328,"mc":[{"id":"1.230178326","rc":[{"atl":[[14.5,0]],"id":67674431}],"con":true,"img":false}]}
{"op":"mcm","clk":"11541453338","pt":1719505914251,"mc":[{"id":"1.230178326","rc":[{"atl":[[1000,1.01]],"id":67674431}],"con":true,"img":false}]}
{"op":"mcm","clk":"11541453349","pt":1719505914354,"mc":[{"id":"1.230178326","rc":[{"atb":[[5.2,1.62]],"id":58221357}],"con":true,"img":false}]}
{"op":"mcm","clk":"11541453373","pt":1719505914660,"mc":[{"id":"1.230178326","rc":[{"atb":[[5,1]],"id":58221357}],"con":true,"img":false}]}
{"op":"mcm","clk":"11541453385","pt":1719505914867,"mc":[{"id":"1.230178326","rc":[{"atl":[[4,0]],"id":65710029},{"trd":[[4,14.7]],"ltp":4.0,"tv":14.7,"id":65710029}],"con":true,"img":false}]}
{"op":"mcm","clk":"11541453402","pt":1719505915030,"mc":[{"id":"1.230178326","rc":[{"atl":[[1000,0.75]],"id":67674431}],"con":true,"img":false}]}
{"op":"mcm","clk":"11541453415","pt":1719505915163,"mc":[{"id":"1.230178326","rc":[{"atb":[[5.2,0]],"id":58221357}],"con":true,"img":false}]}
{"op":"mcm","clk":"11541453429","pt":1719505915253,"mc":[{"id":"1.230178326","rc":[{"atb":[[3.4,1.69]],"id":58221357},{"atb":[[3.45,1.91]],"id":62600242},{"atb":[[3.85,1.92]],"id":60748118},{"atb":[[2.9,1.88]],"id":65710029}],"con":true,"img":false}]}
{"op":"mcm","clk":"11541453439","pt":1719505915364,"mc":[{"id":"1.230178326","rc":[{"atb":[[5.1,2.47]],"id":58221357}],"con":true,"img":false}]}
{"op":"mcm","clk":"11541453469","pt":1719505915735,"mc":[{"id":"1.230178326","rc":[{"atl":[[1000,0.16]],"id":67674431}],"con":true,"img":false}]}
{"op":"mcm","clk":"11541453478","pt":1719505915828,"mc":[{"id":"1.230178326","rc":[{"atl":[[18.5,0.58]],"id":67674431}],"con":true,"img":false}]}
{"op":"mcm","clk":"11541453487","pt":1719505915932,"mc":[{"id":"1.230178326","rc":[{"atb":[[2.9,6.09]],"id":65710029}],"con":true,"img":false}]}
{"op":"mcm","clk":"11541453498","pt":1719505916037,"mc":[{"id":"1.230178326","rc":[{"atb":[[2.92,6.1]],"id":65710029}],"con":true,"img":false}]}
{"op":"mcm","clk":"11541453506","pt":1719505916137,"mc":[{"id":"1.230178326","rc":[{"atb":[[2.88,0]],"id":65710029}],"con":true,"img":false}]}
{"op":"mcm","clk":"11541453531","pt":1719505916550,"mc":[{"id":"1.230178326","rc":[{"atb":[[2.9,4.21]],"id":65710029}],"con":true,"img":false}]}
{"op":"mcm","clk":"11541453542","pt":1719505916658,"mc":[{"id":"1.230178326","rc":[{"atb":[[2.94,1.88]],"id":65710029}],"con":true,"img":false}]}
{"op":"mcm","clk":"11541453595","pt":1719505917269,"mc":[{"id":"1.230178326","rc":[{"atl":[[9.2,1],[9.4,0]],"id":65710029}],"con":true,"img":false}]}
{"op":"mcm","clk":"11541453773","pt":1719505919338,"mc":[{"id":"1.230178326","rc":[{"atb":[[4.3,1]],"id":65710029}],"con":true,"img":false}]}
{"op":"mcm","clk":"11541453785","pt":1719505919441,"mc":[{"id":"1.230178326","rc":[{"atb":[[2.94,6]],"id":65710029}],"con":true,"img":false}]}
{"op":"mcm","clk":"11541453809","pt":1719505919754,"mc":[{"id":"1.230178326","rc":[{"atl":[[9.2,0]],"id":62600242}],"con":true,"img":false}]}
{"op":"mcm","clk":"11541453822","pt":1719505919853,"mc":[{"id":"1.230178326","rc":[{"atl":[[70,2],[11,0]],"id":62600242}],"con":true,"img":false}]}
{"op":"mcm","clk":"11541453836","pt":1719505920059,"mc":[{"id":"1.230178326","rc":[{"atb":[[3.25,0]],"id":68687941}],"con":true,"img":false}]}
{"op":"mcm","clk":"11541453852","pt":1719505920265,"mc":[{"id":"1.230178326","rc":[{"atl":[[1000,0.28]],"id":62600242}],"con":true,"img":false}]}
{"op":"mcm","clk":"11541453860","pt":1719505920369,"mc":[{"id":"1.230178326","rc":[{"atl":[[1000,0.16]],"id":62600242},{"atl":[[32,0]],"id":60748118},{"atb":[[1.05,1]],"id":68687941},{"atl":[[25,0]],"id":68687941},{"atl":[[18.5,1.43]],"id":67674431},{"atl":[[26,0]],"id":65710029}],"con":true,"img":false}]}
{"op":"mcm","clk":"11541453867","pt":1719505920470,"mc":[{"id":"1.230178326","rc":[{"atl":[[9.2,0.12]],"id":62600242}],"con":true,"img":false}]}
{"op":"mcm","clk":"11541453877","pt":1719505920573,"mc":[{"id":"1.230178326","rc":[{"atb":[[1.05,0.43]],"id":68687941},{"atl":[[34,0],[22,4.76]],"id":67674431}],"con":true,"img":false}]}
{"op":"mcm","clk":"11541453892","pt":1719505920743,"mc":[{"id":"1.230178326","rc":[{"atb":[[1.05,0]],"id":68687941}],"con":true,"img":false}]}
{"op":"mcm","clk":"11541453900","pt":1719505920835,"mc":[{"id":"1.230178326","rc":[{"atb":[[3.25,0.44]],"id":68687941}],"con":true,"img":false}]}
{"op":"mcm","clk":"11541453923","pt":1719505921151,"mc":[{"id":"1.230178326","rc":[{"atb":[[2.74,6.81]],"id":68687941}],"con":true,"img":false}]}
{"op":"mcm","clk":"11541454050","pt":1719505922699,"mc":[{"id":"1.230178326","rc":[{"atl":[[9.6,1],[9.4,0]],"id":58221357},{"atl":[[9.6,1],[9.4,0]],"id":62600242},{"atl":[[10,0.84]],"id":60748118},{"atl":[[19,0],[19.5,1]],"id":67674431},{"atl":[[10.5,3.61],[11.5,0]],"id":65710029}],"con":true,"img":false}]}
{"op":"mcm","clk":"11541454058","pt":1719505922751,"mc":[{"id":"1.230178326","rc":[{"atl":[[70,0],[12,4]],"id":62600242}],"con":true,"img":false}]}
{"op":"mcm","clk":"11541454081","pt":1719505923064,"mc":[{"id":"1.230178326","rc":[{"atl":[[1000,0.27]],"id":60748118}],"con":true,"img":false}]}
{"op":"mcm","clk":"11541454111","pt":1719505923373,"mc":[{"id":"1.230178326","rc":[{"atl":[[1000,0.16]],"id":60748118}],"con":true,"img":false}]}
{"op":"mcm","clk":"11541454117","pt":1719505923436,"mc":[{"id":"1.230178326","rc":[{"atl":[[10,0.95]],"id":60748118}],"con":true,"img":false}]}
{"op":"mcm","clk":"11541454125","pt":1719505923540,"mc":[{"id":"1.230178326","rc":[{"atb":[[1.04,1.7]],"id":58221357},{"atl":[[1000,1.7]],"id":58221357},{"atb":[[1.02,75.63]],"id":62600242},{"atl":[[1000,1.87]],"id":62600242},{"atb":[[1.03,192.96]],"id":60748118},{"atl":[[1000,1.87]],"id":60748118}],"con":true,"img":false}]}
{"op":"mcm","clk":"11541454146","pt":1719505923745,"mc":[{"id":"1.230178326","rc":[{"atb":[[1.04,0.07]],"id":58221357},{"atl":[[1000,0]],"id":58221357},{"atb":[[1.02,74.05]],"id":62600242},{"atl":[[1000,0.19]],"id":62600242},{"atb":[[1.03,191.36]],"id":60748118},{"atl":[[1000,0.2]],"id":60748118}],"con":true,"img":false}]}
{"op":"mcm","clk":"11541454167","pt":1719505923948,"mc":[{"id":"1.230178326","rc":[{"atb":[[1.04,0]],"id":58221357},{"atl":[[1000,0]],"id":58221357},{"atb":[[1.02,73.93]],"id":62600242},{"atl":[[1000,0.16]],"id":62600242},{"atb":[[1.03,191.26]],"id":60748118},{"atl":[[1000,0.16]],"id":60748118}],"con":true,"img":false}]}
{"op":"mcm","clk":"11541454183","pt":1719505924051,"mc":[{"id":"1.230178326","rc":[{"atb":[[5.2,0.07]],"id":58221357},{"atl":[[48,0]],"id":58221357},{"atb":[[3.5,0.11]],"id":62600242},{"atl":[[11.5,0.02]],"id":62600242},{"atb":[[3.9,0.1]],"id":60748118},{"atl":[[10,0.98]],"id":60748118}],"con":true,"img":false}]}
{"op":"mcm","clk":"11541454286","pt":1719505924940,"mc":[{"id":"1.230178326","rc":[{"atb":[[3.2,0],[3.15,1]],"id":68687941},{"atb":[[4.3,0],[4.6,7]],"id":67674431},{"atb":[[3.15,0]],"id":65710029}],"con":true,"img":false}]}
{"op":"mcm","clk":"11541454298","pt":1719505925039,"mc":[{"id":"1.230178326","rc":[{"atl":[[9.6,0],[10.5,1]],"id":58221357},{"atl":[[9.6,0],[10.5,1]],"id":62600242},{"atl":[[11,0],[13,1]],"id":60748118},{"atb":[[2.88,0],[3.15,8.21]],"id":68687941},{"atb":[[4.6,1],[4.7,6]],"id":67674431},{"atl":[[9.2,0],[8.6,1]],"id":65710029}],"con":true,"img":false}]}
{"op":"mcm","clk":"11541454309","pt":1719505925142,"mc":[{"id":"1.230178326","rc":[{"atb":[[2.88,7.21],[3.15,1]],"id":68687941}],"con":true,"img":false}]}
{"op":"mcm","clk":"11541454335","pt":1719505925355,"mc":[{"id":"1.230178326","rc":[{"atb":[[3.2,0.84]],"id":68687941}],"con":true,"img":false}]}
{"op":"mcm","clk":"11541454359","pt":1719505925559,"mc":[{"id":"1.230178326","rc":[{"atb":[[2.88,0],[3.15,3.1]],"id":68687941},{"atl":[[9,0]],"id":65710029}],"con":true,"img":false}]}
{"op":"mcm","clk":"11541454369","pt":1719505925661,"mc":[{"id":"1.230178326","rc":[{"atb":[[4.8,1.88]],"id":67674431}],"con":true,"img":false}]}
{"op":"mcm","clk":"11541454396","pt":1719505925981,"mc":[{"id":"1.230178326","rc":[{"atl":[[10,0.93]],"id":65710029}],"con":true,"img":false}]}
{"op":"mcm","clk":"11541454578","pt":1719505927775,"mc":[{"id":"1.230178326","rc":[{"atl":[[8.4,1.05]],"id":65710029}],"con":true,"img":false}]}
{"op":"mcm","clk":"11541455279","pt":1719505935072,"mc":[{"id":"1.230178326","rc":[{"atb":[[2.8,1]],"id":65710029}],"con":true,"img":false}]}
{"op":"mcm","clk":"11541455345","pt":1719505935693,"mc":[{"id":"1.230178326","rc":[{"atl":[[9.2,0]],"id":62600242}],"con":true,"img":false}]}
{"op":"mcm","clk":"11541455357","pt":1719505935748,"mc":[{"id":"1.230178326","rc":[{"atl":[[12,0],[12.5,4]],"id":62600242}],"con":true,"img":false}]}
{"op":"mcm","clk":"11541455366","pt":1719505935852,"mc":[{"id":"1.230178326","rc":[{"atl":[[1000,0.27]],"id":62600242}],"con":true,"img":false}]}
{"op":"mcm","clk":"11541455387","pt":1719505936058,"mc":[{"id":"1.230178326","rc":[{"atl":[[1000,0.16]],"id":62600242}],"con":true,"img":false}]}
{"op":"mcm","clk":"11541455397","pt":1719505936164,"mc":[{"id":"1.230178326","rc":[{"atl":[[10,0.11]],"id":62600242},{"atb":[[3.25,0]],"id":68687941}],"con":true,"img":false}]}
{"op":"mcm","clk":"11541455405","pt":1719505936267,"mc":[{"id":"1.230178326","rc":[{"atb":[[2.88,6.81],[3.15,1]],"id":68687941}],"con":true,"img":false}]}
{"op":"mcm","clk":"11541455443","pt":1719505936679,"mc":[{"id":"1.230178326","rc":[{"atb":[[1.05,1]],"id":68687941}],"con":true,"img":false}]}
{"op":"mcm","clk":"11541455459","pt":1719505936884,"mc":[{"id":"1.230178326","rc":[{"atb":[[1.05,0.44]],"id":68687941}],"con":true,"img":false}]}
{"op":"mcm","clk":"11541455480","pt":1719505937086,"mc":[{"id":"1.230178326","rc":[{"atb":[[1.05,0]],"id":68687941}],"con":true,"img":false}]}
{"op":"mcm","clk":"11541455491","pt":1719505937189,"mc":[{"id":"1.230178326","rc":[{"atb":[[3.2,1.29]],"id":68687941}],"con":true,"img":false}]}
{"op":"mcm","clk":"11541455592","pt":1719505938177,"mc":[{"id":"1.230178326","rc":[{"atl":[[13.5,8.41]],"id":60748118},{"atl":[[19.5,0],[20,1]],"id":67674431}],"con":true,"img":false}]}
{"op":"mcm","clk":"11541455603","pt":1719505938277,"mc":[{"id":"1.230178326","rc":[{"atb":[[3.6,6]],"id":58221357},{"atl":[[13,0]],"id":60748118},{"atb":[[4.6,7],[4.7,0]],"id":67674431},{"atl":[[22,0],[23,4.55]],"id":67674431},{"atl":[[9.8,3.61]],"id":65710029}],"con":true,"img":false}]}
{"op":"mcm","clk":"11541455613","pt":1719505938383,"mc":[{"id":"1.230178326","rc":[{"atb":[[3.35,0]],"id":58221357},{"atl":[[10.5,0]],"id":65710029}],"con":true,"img":false}]}
{"op":"mcm","clk":"11541455634","pt":1719505938583,"mc":[{"id":"1.230178326","rc":[{"atb":[[2.16,5.45]],"id":58221357},{"atb":[[2.96,3.16]],"id":65710029}],"con":true,"img":false}]}
{"op":"mcm","clk":"11541455656","pt":1719505938790,"mc":[{"id":"1.230178326","rc":[{"atb":[[2.16,6.81]],"id":62600242},{"atl":[[10,0.87]],"id":60748118},{"atb":[[2.98,3.59]],"id":65710029}],"con":true,"img":false}]}
{"op":"mcm","clk":"11541455667","pt":1719505938892,"mc":[{"id":"1.230178326","rc":[{"atb":[[4.8,0]],"id":67674431},{"atb":[[2.94,4.12]],"id":65710029}],"con":true,"img":false}]}
{"op":"mcm","clk":"11541455680","pt":1719505938997,"mc":[{"id":"1.230178326","rc":[{"atb":[[2.16,12.26]],"id":62600242},{"atb":[[2.98,5.48],[2.16,5.45]],"id":65710029}],"con":true,"img":false}]}
{"op":"mcm","clk":"11541455705","pt":1719505939168,"mc":[{"id":"1.230178326","rc":[{"atb":[[2.16,5.45]],"id":60748118},{"atb":[[2.16,5.45]],"id":68687941}],"con":true,"img":false}]}
{"op":"mcm","clk":"11541455725","pt":1719505939371,"mc":[{"id":"1.230178326","rc":[{"atb":[[2.78,5.32]],"id":62600242},{"atl":[[1000,0.27]],"id":60748118},{"atb":[[2.64,5.78]],"id":65710029}],"con":true,"img":false}]}
{"op":"mcm","clk":"11541455744","pt":1719505939566,"mc":[{"id":"1.230178326","rc":[{"atl":[[1000,0.16]],"id":60748118},{"atb":[[2.16,12.26]],"id":67674431}],"con":true,"img":false}]}
{"op":"mcm","clk":"11541455753","pt":1719505939680,"mc":[{"id":"1.230178326","rc":[{"atl":[[10,0.98]],"id":60748118}],"con":true,"img":false}]}
{"op":"mcm","clk":"11541455761","pt":1719505939783,"mc":[{"id":"1.230178326","rc":[{"atb":[[2.16,12.26]],"id":60748118}],"con":true,"img":false}]}
{"op":"mcm","clk":"11541455780","pt":1719505939980,"mc":[{"id":"1.230178326","rc":[{"atb":[[2.16,12.26]],"id":68687941}],"con":true,"img":false}]}
{"op":"mcm","clk":"11541455788","pt":1719505940084,"mc":[{"id":"1.230178326","rc":[{"atb":[[2.4,5.64]],"id":65710029}],"con":true,"img":false}]}
{"op":"mcm","clk":"11541455800","pt":1719505940188,"mc":[{"id":"1.230178326","rc":[{"atb":[[2.96,4.43]],"id":62600242}],"con":true,"img":false}]}
{"op":"mcm","clk":"11541455817","pt":1719505940390,"mc":[{"id":"1.230178326","rc":[{"atb":[[2.82,4.77]],"id":65710029}],"con":true,"img":false}]}
{"op":"mcm","clk":"11541455944","pt":1719505941677,"mc":[{"id":"1.230178326","rc":[{"atb":[[3.05,2.09]],"id":65710029}],"con":true,"img":false}]}
{"op":"mcm","clk":"11541455954","pt":1719505941779,"mc":[{"id":"1.230178326","rc":[{"atl":[[8.6,2.17]],"id":65710029}],"con":true,"img":false}]}
{"op":"mcm","clk":"11541455964","pt":1719505941882,"mc":[{"id":"1.230178326","rc":[{"atb":[[3.05,5.25]],"id":65710029}],"con":true,"img":false}]}
{"op":"mcm","clk":"11541455973","pt":1719505941988,"mc":[{"id":"1.230178326","rc":[{"atb":[[2.92,0]],"id":65710029}],"con":true,"img":false}]}
{"op":"mcm","clk":"11541456009","pt":1719505942399,"mc":[{"id":"1.230178326","rc":[{"atb":[[3.25,1.98]],"id":60748118}],"con":true,"img":false}]}
{"op":"mcm","clk":"11541456025","pt":1719505942557,"mc":[{"id":"1.230178326","rc":[{"atb":[[2.98,3.59]],"id":65710029}],"con":true,"img":false}]}
{"op":"mcm","clk":"11541456036","pt":1719505942657,"mc":[{"id":"1.230178326","rc":[{"atb":[[3.1,1.88]],"id":65710029}],"con":true,"img":false}]}
{"op":"mcm","clk":"11541456073","pt":1719505943073,"mc":[{"id":"1.230178326","rc":[{"atb":[[2.76,0]],"id":68687941},{"atl":[[8.4,0]],"id":65710029}],"con":true,"img":false}]}
{"op":"mcm","clk":"11541456098","pt":1719505943282,"mc":[{"id":"1.230178326","rc":[{"atl":[[8.4,3.86]],"id":65710029}],"con":true,"img":false}]}
{"op":"mcm","clk":"11541456109","pt":1719505943379,"mc":[{"id":"1.230178326","rc":[{"atb":[[5.3,1.59]],"id":58221357}],"con":true,"img":false}]}
{"op":"mcm","clk":"11541456142","pt":1719505943687,"mc":[{"id":"1.230178326","rc":[{"atb":[[5.1,0.84]],"id":58221357}],"con":true,"img":false}]}
{"op":"mcm","clk":"11541456150","pt":1719505943793,"mc":[{"id":"1.230178326","rc":[{"atb":[[5.3,0]],"id":58221357}],"con":true,"img":false}]}
{"op":"mcm","clk":"11541456159","pt":1719505943899,"mc":[{"id":"1.230178326","rc":[{"atb":[[3.2,3.29],[2.88,0]],"id":68687941}],"con":true,"img":false}]}
{"op":"mcm","clk":"11541456181","pt":1719505944109,"mc":[{"id":"1.230178326","rc":[{"atb":[[5.2,1.66]],"id":58221357}],"con":true,"img":false}]}
{"op":"mcm","clk":"11541456194","pt":1719505944167,"mc":[{"id":"1.230178326","rc":[{"atb":[[3.95,1.5]],"id":67674431}],"con":true,"img":false}]}
{"op":"mcm","clk":"11541456204","pt":1719505944269,"mc":[{"id":"1.230178326","rc":[{"atb":[[3.25,6.34]],"id":68687941}],"con":true,"img":false}]}
{"op":"mcm","clk":"11541456250","pt":1719505944779,"mc":[{"id":"1.230178326","rc":[{"atb":[[3.3,0.84]],"id":68687941}],"con":true,"img":false}]}
{"op":"mcm","clk":"11541456315","pt":1719505945398,"mc":[{"id":"1.230178326","rc":[{"atb":[[3.25,0]],"id":68687941}],"con":true,"img":false}]}
{"op":"mcm","clk":"11541456347","pt":1719505945761,"mc":[{"id":"1.230178326","rc":[{"atb":[[3.25,0]],"id":60748118}],"con":true,"img":false}]}
{"op":"mcm","clk":"11541456359","pt":1719505945866,"mc":[{"id":"1.230178326","rc":[{"atb":[[3.3,0]],"id":68687941},{"atb":[[4.6,1],[4.7,6]],"id":67674431},{"atl":[[9.6,4.34],[9.8,0]],"id":65710029}],"con":true,"img":false}]}
{"op":"mcm","clk":"11541456365","pt":1719505945969,"mc":[{"id":"1.230178326","rc":[{"atb":[[3.25,6.34]],"id":68687941},{"atb":[[3.1,5.69]],"id":65710029}],"con":true,"img":false}]}
{"op":"mcm","clk":"11541456371","pt":1719505946068,"mc":[{"id":"1.230178326","rc":[{"atb":[[4.8,1.88]],"id":67674431}],"con":true,"img":false}]}
{"op":"mcm","clk":"11541456379","pt":1719505946177,"mc":[{"id":"1.230178326","rc":[{"atb":[[3.25,1.53]],"id":60748118}],"con":true,"img":false}]}
{"op":"mcm","clk":"11541456678","pt":1719505949381,"mc":[{"id":"1.230178326","rc":[{"atb":[[3.95,0]],"id":67674431}],"con":true,"img":false}]}
{"op":"mcm","clk":"11541456870","pt":1719505951402,"mc":[{"id":"1.230178326","rc":[{"spn":14.48,"spf":"Infinity","id":58221357},{"atl":[[10,0]],"id":62600242},{"spn":4.85,"spf":1.0,"id":62600242},{"atb":[[3.3,3.3]],"id":68687941},{"spn":3.3,"spf":1.0,"id":68687941},{"spn":11.8,"spf":"NaN","id":67674431},{"spn":3.22,"spf":1.0,"id":65710029}],"con":true,"img":false}]}
{"op":"mcm","clk":"11541456881","pt":1719505951506,"mc":[{"id":"1.230178326","rc":[{"atb":[[3.2,1.29],[2.38,9.19]],"id":68687941}],"con":true,"img":false}]}
{"op":"mcm","clk":"11541456889","pt":1719505951609,"mc":[{"id":"1.230178326","rc":[{"atl":[[1000,0.27]],"id":62600242}],"con":true,"img":false}]}
{"op":"mcm","clk":"11541456899","pt":1719505951673,"mc":[{"id":"1.230178326","rc":[{"atb":[[3.25,0]],"id":68687941},{"atb":[[2.16,18.1]],"id":67674431}],"con":true,"img":false}]}
{"op":"mcm","clk":"11541456909","pt":1719505951774,"mc":[{"id":"1.230178326","rc":[{"atb":[[2.16,11.29]],"id":58221357},{"atl":[[1000,0.16]],"id":62600242},{"atb":[[3.3,0],[3.2,7.89]],"id":68687941}],"con":true,"img":false}]}
{"op":"mcm","clk":"11541456918","pt":1719505951878,"mc":[{"id":"1.230178326","rc":[{"atl":[[10,0.11]],"id":62600242},{"atb":[[3.2,7.05]],"id":68687941}],"con":true,"img":false}]}
{"op":"mcm","clk":"11541456926","pt":1719505951977,"mc":[{"id":"1.230178326","rc":[{"atb":[[2.16,11.29]],"id":65710029}],"con":true,"img":false}]}
{"op":"mcm","clk":"11541456936","pt":1719505952080,"mc":[{"id":"1.230178326","rc":[{"atb":[[2.16,18.1]],"id":60748118},{"atl":[[13,1],[13.5,7.41]],"id":60748118},{"atl":[[19.5,1]],"id":67674431}],"con":true,"img":false}]}
{"op":"mcm","clk":"11541456958","pt":1719505952286,"mc":[{"id":"1.230178326","rc":[{"atb":[[3.25,7.19],[3.2,6.6]],"id":68687941},{"atl":[[20,0],[22,4.76],[23,0]],"id":67674431},{"atl":[[10.5,8],[9.6,0],[8.6,1.17],[8.8,1.01]],"id":65710029}],"con":true,"img":false}]}
{"op":"mcm","clk":"11541456971","pt":1719505952389,"mc":[{"id":"1.230178326","rc":[{"atl":[[10,0.14],[12.5,0.84]],"id":60748118},{"atb":[[2.16,18.1]],"id":68687941}],"con":true,"img":false}]}
{"op":"mcm","clk":"11541456984","pt":1719505952697,"mc":[{"id":"1.230178326","rc":[{"atb":[[2.78,11.03]],"id":62600242},{"atl":[[10,0.98],[12.5,0]],"id":60748118}],"con":true,"img":false}]}
{"op":"mcm","clk":"11541457001","pt":1719505952802,"mc":[{"id":"1.230178326","rc":[{"atb":[[2.16,18.1]],"id":62600242},{"atl":[[10,1.83]],"id":60748118}],"con":true,"img":false}]}
{"op":"mcm","clk":"11541457033","pt":1719505953175,"mc":[{"id":"1.230178326","rc":[{"atl":[[4.6,0]],"id":68687941},{"trd":[[4.6,12.78]],"ltp":4.6,"tv":12.78,"id":68687941}],"con":true,"img":false}]}
{"op":"mcm","clk":"11541457044","pt":1719505953276,"mc":[{"id":"1.230178326","rc":[{"atl":[[9.8,2.58]],"id":60748118},{"atl":[[11,0],[26,4]],"id":68687941}],"con":true,"img":false}]}
{"op":"mcm","clk":"11541457079","pt":1719505953681,"mc":[{"id":"1.230178326","rc":[{"atl":[[25,0.79]],"id":68687941}],"con":true,"img":false}]}
{"op":"mcm","clk":"11541457088","pt":1719505953785,"mc":[{"id":"1.230178326","rc":[{"atl":[[25,1.63]],"id":68687941}],"con":true,"img":false}]}
{"op":"mcm","clk":"11541457100","pt":1719505953889,"mc":[{"id":"1.230178326","rc":[{"atb":[[5.1,2.44]],"id":58221357},{"atb":[[3.3,1.92]],"id":68687941}],"con":true,"img":false}]}
{"op":"mcm","clk":"11541457112","pt":1719505953991,"mc":[{"id":"1.230178326","rc":[{"atb":[[5.2,0.07]],"id":58221357}],"con":true,"img":false}]}
{"op":"mcm","clk":"11541457135","pt":1719505954200,"mc":[{"id":"1.230178326","rc":[{"atb":[[5.1,0.84]],"id":58221357}],"con":true,"img":false}]}
{"op":"mcm","clk":"11541457146","pt":1719505954304,"mc":[{"id":"1.230178326","rc":[{"atb":[[5.3,1.59],[2.66,0]],"id":58221357},{"atb":[[2.64,0]],"id":62600242},{"atb":[[2.66,0]],"id":60748118},{"atb":[[2.74,0]],"id":68687941},{"atl":[[25,1.28]],"id":68687941},{"atb":[[2.66,0]],"id":67674431},{"atb":[[2.42,0]],"id":65710029}],"con":true,"img":false}]}
{"op":"mcm","clk":"11541457155","pt":1719505954407,"mc":[{"id":"1.230178326","rc":[{"atb":[[3.25,0.84],[3.3,5.4]],"id":68687941}],"con":true,"img":false}]}
{"op":"mcm","clk":"11541457165","pt":1719505954510,"mc":[{"id":"1.230178326","rc":[{"atb":[[4.7,1]],"id":68687941}],"con":true,"img":false}]}
{"op":"mcm","clk":"11541457200","pt":1719505954881,"mc":[{"id":"1.230178326","rc":[{"atl":[[10,1.72]],"id":60748118},{"atl":[[8.2,1.05]],"id":65710029}],"con":true,"img":false}]}
{"op":"mcm","clk":"11541457221","pt":1719505955084,"mc":[{"id":"1.230178326","rc":[{"atl":[[8.4,0.84]],"id":65710029}],"con":true,"img":false}]}
{"op":"mcm","clk":"11541457283","pt":1719505955801,"mc":[{"id":"1.230178326","rc":[{"atl":[[1000,0.28]],"id":60748118},{"atl":[[1000,0.04]],"id":68687941}],"con":true,"img":false}]}
{"op":"mcm","clk":"11541457300","pt":1719505956009,"mc":[{"id":"1.230178326","rc":[{"atl":[[1000,0.16]],"id":60748118},{"atl":[[1000,0]],"id":68687941}],"con":true,"img":false}]}
{"op":"mcm","clk":"11541457309","pt":1719505956111,"mc":[{"id":"1.230178326","rc":[{"atl":[[9.6,0.12]],"id":60748118},{"atl":[[24,0.04]],"id":68687941}],"con":true,"img":false}]}
{"op":"mcm","clk":"11541457349","pt":1719505956501,"mc":[{"id":"1.230178326","rc":[{"atl":[[24,1.61]],"id":68687941}],"con":true,"img":false}]}
{"op":"mcm","clk":"11541457359","pt":1719505956578,"mc":[{"id":"1.230178326","rc":[{"atl":[[24,3.61],[26,0]],"id":68687941}],"con":true,"img":false}]}
{"op":"mcm","clk":"11541457391","pt":1719505956886,"mc":[{"id":"1.230178326","rc":[{"atl":[[10.5,0]],"id":60748118}],"con":true,"img":false}]}
{"op":"mcm","clk":"11541457429","pt":1719505957401,"mc":[{"id":"1.230178326","rc":[{"atl":[[25,0.84]],"id":68687941}],"con":true,"img":false}]}
{"op":"mcm","clk":"11541457436","pt":1719505957505,"mc":[{"id":"1.230178326","rc":[{"atl":[[23,0.44]],"id":68687941}],"con":true,"img":false}]}
{"op":"mcm","clk":"11541457485","pt":1719505958083,"mc":[{"id":"1.230178326","rc":[{"atb":[[2.94,1.6]],"id":62600242}],"con":true,"img":false}]}
{"op":"mcm","clk":"11541457551","pt":1719505958799,"mc":[{"id":"1.230178326","rc":[{"atl":[[11.5,4.02],[12.5,0]],"id":62600242},{"atl":[[12,7.41],[13.5,0]],"id":60748118},{"atl":[[8.2,1]],"id":68687941},{"atl":[[20,1]],"id":67674431},{"atl":[[10.5,0],[8.8,3.11]],"id":65710029}],"con":true,"img":false}]}
{"op":"mcm","clk":"11541457561","pt":1719505958901,"mc":[{"id":"1.230178326","rc":[{"atl":[[13,0],[13.5,1]],"id":60748118},{"atl":[[19.5,0]],"id":67674431}],"con":true,"img":false}]}
{"op":"mcm","clk":"11541457580","pt":1719505959112,"mc":[{"id":"1.230178326","rc":[{"atl":[[11.5,0.79]],"id":60748118},{"atb":[[4.3,1],[4.6,0]],"id":67674431}],"con":true,"img":false}]}
{"op":"mcm","clk":"11541457606","pt":1719505959316,"mc":[{"id":"1.230178326","rc":[{"atb":[[4.8,0]],"id":67674431}],"con":true,"img":false}]}
{"op":"mcm","clk":"11541457620","pt":1719505959420,"mc":[{"id":"1.230178326","rc":[{"atb":[[2.96,0]],"id":65710029}],"con":true,"img":false}]}
{"op":"mcm","clk":"11541457632","pt":1719505959483,"mc":[{"id":"1.230178326","rc":[{"atl":[[13,1],[13.5,0]],"id":60748118},{"atb":[[4.3,0],[4.6,1],[2.38,8.59]],"id":67674431},{"atl":[[19.5,1],[20,0]],"id":67674431}],"con":true,"img":false}]}
{"op":"mcm","clk":"11541457643","pt":1719505959595,"mc":[{"id":"1.230178326","rc":[{"atb":[[2.38,8.59]],"id":60748118},{"atl":[[13,0]],"id":60748118},{"atl":[[19.5,0],[20,1]],"id":67674431}],"con":true,"img":false}]}
{"op":"mcm","clk":"11541457653","pt":1719505959700,"mc":[{"id":"1.230178326","rc":[{"atl":[[11.5,0.48]],"id":60748118},{"atl":[[18.5,3.43]],"id":67674431}],"con":true,"img":false}]}
{"op":"mcm","clk":"11541457664","pt":1719505959802,"mc":[{"id":"1.230178326","rc":[{"atb":[[2.7,6.97]],"id":58221357},{"atl":[[13.5,1],[9.6,0.96]],"id":60748118},{"atb":[[4.6,7],[4.7,0]],"id":67674431},{"atl":[[22,0]],"id":67674431},{"atb":[[2.92,6.17]],"id":65710029}],"con":true,"img":false}]}
{"op":"mcm","clk":"11541457689","pt":1719505960091,"mc":[{"id":"1.230178326","rc":[{"atl":[[9.8,0]],"id":60748118},{"atb":[[2.98,0]],"id":65710029}],"con":true,"img":false}]}
{"op":"mcm","clk":"11541457708","pt":1719505960300,"mc":[{"id":"1.230178326","rc":[{"atl":[[9.6,0.12]],"id":60748118},{"atl":[[18,0.84]],"id":67674431}],"con":true,"img":false}]}
{"op":"mcm","clk":"11541457739","pt":1719505960610,"mc":[{"id":"1.230178326","rc":[{"atl":[[13,1]],"id":60748118},{"atl":[[19.5,1],[20,0]],"id":67674431}],"con":true,"img":false}]}
{"op":"mcm","clk":"11541457752","pt":1719505960713,"mc":[{"id":"1.230178326","rc":[{"atl":[[13.5,0],[9.8,2.58]],"id":60748118}],"con":true,"img":false}]}
{"op":"mcm","clk":"11541457762","pt":1719505960816,"mc":[{"id":"1.230178326","rc":[{"atb":[[5.2,0]],"id":58221357},{"atl":[[48,0]],"id":58221357},{"atb":[[3.5,0]],"id":62600242},{"atl":[[11.5,4]],"id":62600242},{"atb":[[3.9,0]],"id":60748118},{"atl":[[10,1.69]],"id":60748118}],"con":true,"img":false}]}
{"op":"mcm","clk":"11541457798","pt":1719505961193,"mc":[{"id":"1.230178326","rc":[{"atl":[[9.6,1.83]],"id":60748118}],"con":true,"img":false}]}
{"op":"mcm","clk":"11541457858","pt":1719505961803,"mc":[{"id":"1.230178326","rc":[{"atl":[[10,0.84],[9.8,0]],"id":60748118}],"con":true,"img":false}]}
{"op":"mcm","clk":"11541457875","pt":1719505962009,"mc":[{"id":"1.230178326","rc":[{"atl":[[9.4,2.69]],"id":60748118}],"con":true,"img":false}]}
{"op":"mcm","clk":"11541458046","pt":1719505964298,"mc":[{"id":"1.230178326","rc":[{"atl":[[9.6,0.12]],"id":60748118}],"con":true,"img":false}]}
{"op":"mcm","clk":"11541458069","pt":1719505964595,"mc":[{"id":"1.230178326","rc":[{"atb":[[5.1,2.44]],"id":58221357}],"con":true,"img":false}]}
{"op":"mcm","clk":"11541458080","pt":1719505964699,"mc":[{"id":"1.230178326","rc":[{"atb":[[5.3,0]],"id":58221357}],"con":true,"img":false}]}
{"op":"mcm","clk":"11541458090","pt":1719505964801,"mc":[{"id":"1.230178326","rc":[{"atb":[[5.4,1.56]],"id":58221357}],"con":true,"img":false}]}
{"op":"mcm","clk":"11541458100","pt":1719505964906,"mc":[{"id":"1.230178326","rc":[{"atl":[[9.4,0]],"id":60748118}],"con":true,"img":false}]}
{"op":"mcm","clk":"11541458124","pt":1719505965215,"mc":[{"id":"1.230178326","rc":[{"atb":[[5.1,0.84]],"id":58221357}],"con":true,"img":false}]}
{"op":"mcm","clk":"11541458278","pt":1719505967086,"mc":[{"id":"1.230178326","rc":[{"atl":[[10,0]],"id":62600242}],"con":true,"img":false}]}
{"op":"mcm","clk":"11541458289","pt":1719505967198,"mc":[{"id":"1.230178326","rc":[{"atl":[[11.5,0],[55,2]],"id":62600242},{"atl":[[11,1.57]],"id":60748118},{"atb":[[4.6,1],[4.7,7]],"id":67674431}],"con":true,"img":false}]}
{"op":"mcm","clk":"11541458302","pt":1719505967305,"mc":[{"id":"1.230178326","rc":[{"atl":[[1000,0.27]],"id":62600242}],"con":true,"img":false}]}
{"op":"mcm","clk":"11541458325","pt":1719505967602,"mc":[{"id":"1.230178326","rc":[{"atl":[[1000,0.16]],"id":62600242}],"con":true,"img":false}]}
{"op":"mcm","clk":"11541458334","pt":1719505967697,"mc":[{"id":"1.230178326","rc":[{"atl":[[10,0.11]],"id":62600242}],"con":true,"img":false}]}
{"op":"mcm","clk":"11541458434","pt":1719505968697,"mc":[{"id":"1.230178326","rc":[{"atb":[[3.2,7.6],[3.15,0]],"id":68687941},{"atb":[[4.3,1],[4.6,0]],"id":67674431},{"atb":[[3.15,1]],"id":65710029}],"con":true,"img":false}]}
{"op":"mcm","clk":"11541458444","pt":1719505968791,"mc":[{"id":"1.230178326","rc":[{"atb":[[2.8,0]],"id":65710029}],"con":true,"img":false}]}
{"op":"mcm","clk":"11541458600","pt":1719505970509,"mc":[{"id":"1.230178326","rc":[{"atl":[[8.2,0]],"id":65710029}],"con":true,"img":false}]}
{"op":"mcm","clk":"11541458609","pt":1719505970613,"mc":[{"id":"1.230178326","rc":[{"atl":[[11,2.57]],"id":60748118},{"atb":[[2.98,2.56]],"id":65710029}],"con":true,"img":false}]}
{"op":"mcm","clk":"11541458618","pt":1719505970700,"mc":[{"id":"1.230178326","rc":[{"atl":[[13,0]],"id":60748118}],"con":true,"img":false}]}
{"op":"mcm","clk":"11541458627","pt":1719505970803,"mc":[{"id":"1.230178326","rc":[{"atb":[[2.98,0]],"id":65710029}],"con":true,"img":false}]}
{"op":"mcm","clk":"11541458656","pt":1719505971114,"mc":[{"id":"1.230178326","rc":[{"atl":[[11.5,0]],"id":60748118}],"con":true,"img":false}]}
{"op":"mcm","clk":"11541458662","pt":1719505971215,"mc":[{"id":"1.230178326","rc":[{"atl":[[10.5,0.48]],"id":60748118}],"con":true,"img":false}]}
{"op":"mcm","clk":"11541458677","pt":1719505971319,"mc":[{"id":"1.230178326","rc":[{"atl":[[9.6,0]],"id":60748118},{"atl":[[24,3.57]],"id":68687941}],"con":true,"img":false}]}
{"op":"mcm","clk":"11541458724","pt":1719505971731,"mc":[{"id":"1.230178326","rc":[{"atl":[[10.5,0]],"id":60748118}],"con":true,"img":false}]}
{"op":"mcm","clk":"11541458736","pt":1719505971834,"mc":[{"id":"1.230178326","rc":[{"atl":[[1000,0.65]],"id":60748118}],"con":true,"img":false}]}
{"op":"mcm","clk":"11541458768","pt":1719505972100,"mc":[{"id":"1.230178326","rc":[{"atl":[[1000,0.76]],"id":60748118},{"atl":[[1000,0.14]],"id":68687941}],"con":true,"img":false}]}
{"op":"mcm","clk":"11541458786","pt":1719505972299,"mc":[{"id":"1.230178326","rc":[{"atl":[[1000,0.16]],"id":60748118},{"atl":[[1000,0]],"id":68687941}],"con":true,"img":false}]}
{"op":"mcm","clk":"11541458791","pt":1719505972402,"mc":[{"id":"1.230178326","rc":[{"atl":[[10.5,0.11],[11,3.05]],"id":60748118},{"atl":[[8,0.14]],"id":68687941}],"con":true,"img":false}]}
{"op":"mcm","clk":"11541458819","pt":1719505972814,"mc":[{"id":"1.230178326","rc":[{"atb":[[2.94,0]],"id":62600242}],"con":true,"img":false}]}
{"op":"mcm","clk":"11541458879","pt":1719505973509,"mc":[{"id":"1.230178326","rc":[{"atl":[[9.8,0.86]],"id":62600242}],"con":true,"img":false}]}
{"op":"mcm","clk":"11541458907","pt":1719505973804,"mc":[{"id":"1.230178326","rc":[{"atb":[[2.98,1.55]],"id":62600242}],"con":true,"img":false}]}
{"op":"mcm","clk":"11541458918","pt":1719505973906,"mc":[{"id":"1.230178326","rc":[{"atb":[[4.4,1.92]],"id":65710029}],"con":true,"img":false}]}
{"op":"mcm","clk":"11541458935","pt":1719505974114,"mc":[{"id":"1.230178326","rc":[{"atl":[[18.5,2.84]],"id":67674431},{"atb":[[3.3,5.26],[3.05,2.09]],"id":65710029}],"con":true,"img":false}]}
{"op":"mcm","clk":"11541458946","pt":1719505974215,"mc":[{"id":"1.230178326","rc":[{"atl":[[1000,1.01]],"id":67674431}],"con":true,"img":false}]}
{"op":"mcm","clk":"11541458958","pt":1719505974320,"mc":[{"id":"1.230178326","rc":[{"atl":[[18.5,0.84],[19.5,6.41]],"id":67674431}],"con":true,"img":false}]}
{"op":"mcm","clk":"11541458977","pt":1719505974527,"mc":[{"id":"1.230178326","rc":[{"atl":[[10.5,3],[55,0]],"id":62600242},{"atl":[[1000,0.65]],"id":67674431}],"con":true,"img":false}]}
{"op":"mcm","clk":"11541459051","pt":1719505975139,"mc":[{"id":"1.230178326","rc":[{"atb":[[5.4,0],[5.2,1.56]],"id":58221357}],"con":true,"img":false}]}
{"op":"mcm","clk":"11541459094","pt":1719505975508,"mc":[{"id":"1.230178326","rc":[{"atb":[[2.98,0]],"id":62600242},{"atl":[[1000,0.16]],"id":67674431}],"con":true,"img":false}]}
{"op":"mcm","clk":"11541459107","pt":1719505975610,"mc":[{"id":"1.230178326","rc":[{"atl":[[17.5,0.48]],"id":67674431}],"con":true,"img":false}]}
{"op":"mcm","clk":"11541459129","pt":1719505975817,"mc":[{"id":"1.230178326","rc":[{"atb":[[2.98,1.55]],"id":62600242},{"atl":[[18.5,6.55],[19.5,1]],"id":67674431}],"con":true,"img":false}]}
{"op":"mcm","clk":"11541459141","pt":1719505975921,"mc":[{"id":"1.230178326","rc":[{"atb":[[2.36,8.71]],"id":62600242}],"con":true,"img":false}]}
{"op":"mcm","clk":"11541459163","pt":1719505976127,"mc":[{"id":"1.230178326","rc":[{"atb":[[2.74,6.81]],"id":68687941},{"atb":[[2.16,11.29]],"id":67674431}],"con":true,"img":false}]}
{"op":"mcm","clk":"11541459180","pt":1719505976333,"mc":[{"id":"1.230178326","rc":[{"atb":[[2.94,4.48]],"id":68687941}],"con":true,"img":false}]}
{"op":"mcm","clk":"11541459198","pt":1719505976502,"mc":[{"id":"1.230178326","rc":[{"atb":[[2.16,18.1]],"id":58221357},{"atl":[[18,1.63]],"id":67674431},{"atb":[[2.44,0]],"id":65710029}],"con":true,"img":false}]}
{"op":"mcm","clk":"11541459221","pt":1719505976703,"mc":[{"id":"1.230178326","rc":[{"atb":[[2.76,5.39]],"id":68687941},{"atl":[[17.5,1.92]],"id":67674431}],"con":true,"img":false}]}
{"op":"mcm","clk":"11541459270","pt":1719505977211,"mc":[{"id":"1.230178326","rc":[{"atl":[[18,1.34]],"id":67674431}],"con":true,"img":false}]}
{"op":"mcm","clk":"11541459280","pt":1719505977315,"mc":[{"id":"1.230178326","rc":[{"atl":[[17,0.84]],"id":67674431}],"con":true,"img":false}]}
{"op":"mcm","clk":"11541459315","pt":1719505977727,"mc":[{"id":"1.230178326","rc":[{"atl":[[17.5,0.48]],"id":67674431}],"con":true,"img":false}]}
{"op":"mcm","clk":"11541459395","pt":1719505978400,"mc":[{"id":"1.230178326","rc":[{"atl":[[17,0]],"id":67674431}],"con":true,"img":false}]}
{"op":"mcm","clk":"11541459413","pt":1719505978603,"mc":[{"id":"1.230178326","rc":[{"atb":[[2.98,0]],"id":62600242}],"con":true,"img":false}]}
{"op":"mcm","clk":"11541459433","pt":1719505978812,"mc":[{"id":"1.230178326","rc":[{"atb":[[2.98,1.55]],"id":62600242}],"con":true,"img":false}]}
{"op":"mcm","clk":"11541459593","pt":1719505980516,"mc":[{"id":"1.230178326","rc":[{"atl":[[8.4,1.89]],"id":65710029}],"con":true,"img":false}]}
{"op":"mcm","clk":"11541459706","pt":1719505981613,"mc":[{"id":"1.230178326","rc":[{"atb":[[1.01,1]],"id":58221357},{"atb":[[2.98,0]],"id":62600242}],"con":true,"img":false}]}
{"op":"mcm","clk":"11541459725","pt":1719505981817,"mc":[{"id":"1.230178326","rc":[{"atb":[[2.94,5.98]],"id":62600242}],"con":true,"img":false}]}
{"op":"mcm","clk":"11541459747","pt":1719505982025,"mc":[{"id":"1.230178326","rc":[{"atb":[[2.94,0]],"id":62600242}],"con":true,"img":false}]}
{"op":"mcm","clk":"11541459787","pt":1719505982398,"mc":[{"id":"1.230178326","rc":[{"atb":[[2.98,1.55]],"id":62600242}],"con":true,"img":false}]}
{"op":"mcm","clk":"11541459821","pt":1719505982750,"mc":[{"id":"1.230178326","rc":[{"atl":[[10.5,0],[9.8,1]],"id":58221357},{"atl":[[10.5,2],[9.8,1.86]],"id":62600242},{"atb":[[4.9,6],[4.7,0]],"id":67674431},{"atl":[[19.5,0],[20,1]],"id":67674431},{"atb":[[3.3,0],[3.45,5.26]],"id":65710029}],"con":true,"img":false}]}
{"op":"mcm","clk":"11541459834","pt":1719505982805,"mc":[{"id":"1.230178326","rc":[{"atl":[[48,1]],"id":58221357},{"atl":[[10.5,0],[11,4]],"id":62600242},{"atb":[[3.35,1]],"id":68687941},{"atl":[[18.5,0.84],[19,5.56]],"id":67674431},{"atb":[[3.35,1]],"id":65710029},{"atl":[[8.2,1],[8.6,4.97],[8.8,0.01]],"id":65710029}],"con":true,"img":false}]}
{"op":"mcm","clk":"11541459843","pt":1719505982910,"mc":[{"id":"1.230178326","rc":[{"atl":[[9.6,2.64],[10,0]],"id":62600242},{"atb":[[4.9,0],[5,4.32]],"id":67674431}],"con":true,"img":false}]}
{"op":"mcm","clk":"11541459853","pt":1719505983015,"mc":[{"id":"1.230178326","rc":[{"atb":[[3.25,1.84]],"id":68687941},{"atb":[[4.9,1]],"id":67674431},{"atb":[[3.3,2.09]],"id":65710029}],"con":true,"img":false}]}
{"op":"mcm","clk":"11541459865","pt":1719505983117,"mc":[{"id":"1.230178326","rc":[{"atl":[[48,0]],"id":58221357},{"atl":[[1000,0.28]],"id":62600242},{"atb":[[3.2,6.6]],"id":68687941},{"atb":[[4.3,0]],"id":67674431},{"atb":[[3.35,0],[3.05,0]],"id":65710029}],"con":true,"img":false}]}
{"op":"mcm","clk":"11541459873","pt":1719505983219,"mc":[{"id":"1.230178326","rc":[{"atl":[[9.8,1],[9.4,0.89]],"id":62600242},{"atl":[[18,0.84]],"id":67674431}],"con":true,"img":false}]}
{"op":"mcm","clk":"11541459883","pt":1719505983322,"mc":[{"id":"1.230178326","rc":[{"atl":[[9.2,1]],"id":58221357},{"atl":[[9.4,1.74],[1000,0.16]],"id":62600242},{"atb":[[3.25,1]],"id":68687941},{"atb":[[5.1,3.54]],"id":67674431},{"atl":[[18.5,1.34]],"id":67674431},{"atb":[[3.5,1]],"id":65710029}],"con":true,"img":false}]}
{"op":"mcm","clk":"11541459892","pt":1719505983424,"mc":[{"id":"1.230178326","rc":[{"atl":[[9.4,1.86]],"id":62600242}],"con":true,"img":false}]}
{"op":"mcm","clk":"11541459911","pt":1719505983632,"mc":[{"id":"1.230178326","rc":[{"atl":[[9.6,0]],"id":62600242}],"con":true,"img":false}]}
{"op":"mcm","clk":"11541459931","pt":1719505983800,"mc":[{"id":"1.230178326","rc":[{"atl":[[9.2,2.75]],"id":62600242},{"atb":[[5.2,0.84]],"id":67674431},{"atl":[[18.5,0.84]],"id":67674431}],"con":true,"img":false}]}
{"op":"mcm","clk":"11541459942","pt":1719505983908,"mc":[{"id":"1.230178326","rc":[{"atl":[[1000,0.66]],"id":67674431}],"con":true,"img":false}]}
{"op":"mcm","clk":"11541460014","pt":1719505984521,"mc":[{"id":"1.230178326","rc":[{"atl":[[1000,0.16]],"id":67674431}],"con":true,"img":false}]}
{"op":"mcm","clk":"11541460023","pt":1719505984622,"mc":[{"id":"1.230178326","rc":[{"atl":[[18.5,1.34]],"id":67674431}],"con":true,"img":false}]}
{"op":"mcm","clk":"11541460076","pt":1719505985036,"mc":[{"id":"1.230178326","rc":[{"atl":[[18.5,0.84]],"id":67674431}],"con":true,"img":false}]}
{"op":"mcm","clk":"11541460089","pt":1719505985138,"mc":[{"id":"1.230178326","rc":[{"atl":[[1000,0.66]],"id":67674431}],"con":true,"img":false}]}
{"op":"mcm","clk":"11541460194","pt":1719505986118,"mc":[{"id":"1.230178326","rc":[{"atb":[[3.2,7.6]],"id":68687941},{"atb":[[4.3,1],[4.9,0]],"id":67674431}],"con":true,"img":false}]}
{"op":"mcm","clk":"11541460207","pt":1719505986223,"mc":[{"id":"1.230178326","rc":[{"atb":[[3.25,0]],"id":68687941}],"con":true,"img":false}]}
{"op":"mcm","clk":"11541460231","pt":1719505986438,"mc":[{"id":"1.230178326","rc":[{"atb":[[3.35,0]],"id":68687941}],"con":true,"img":false}]}
{"op":"mcm","clk":"11541460253","pt":1719505986644,"mc":[{"id":"1.230178326","rc":[{"atb":[[3.25,1]],"id":68687941}],"con":true,"img":false}]}
{"op":"mcm","clk":"11541460288","pt":1719505986919,"mc":[{"id":"1.230178326","rc":[{"atb":[[3.25,2],[3.2,6.6]],"id":68687941},{"atb":[[4.3,0],[4.9,1]],"id":67674431}],"con":true,"img":false}]}
{"op":"mcm","clk":"11541460347","pt":1719505987525,"mc":[{"id":"1.230178326","rc":[{"atl":[[10.5,0]],"id":60748118},{"atl":[[8,0]],"id":68687941}],"con":true,"img":false}]}
{"op":"mcm","clk":"11541460369","pt":1719505987734,"mc":[{"id":"1.230178326","rc":[{"atl":[[1000,0.27]],"id":60748118},{"atl":[[1000,0.14]],"id":68687941}],"con":true,"img":false}]}
{"op":"mcm","clk":"11541460381","pt":1719505987935,"mc":[{"id":"1.230178326","rc":[{"atl":[[1000,0.16]],"id":60748118},{"atl":[[1000,0]],"id":68687941}],"con":true,"img":false}]}
{"op":"mcm","clk":"11541460391","pt":1719505988040,"mc":[{"id":"1.230178326","rc":[{"atb":[[2.16,25.4]],"id":58221357},{"atl":[[10.5,0.11]],"id":60748118},{"atl":[[8,0.14]],"id":68687941}],"con":true,"img":false}]}
{"op":"mcm","clk":"11541460409","pt":1719505988244,"mc":[{"id":"1.230178326","rc":[{"atb":[[2.98,7.96]],"id":62600242}],"con":true,"img":false}]}
{"op":"mcm","clk":"11541460414","pt":1719505988309,"mc":[{"id":"1.230178326","rc":[{"atb":[[1.06,1.7],[1.05,3.4]],"id":58221357},{"atl":[[1000,5.1]],"id":58221357},{"atb":[[2.16,18.58]],"id":67674431}],"con":true,"img":false}]}
{"op":"mcm","clk":"11541460427","pt":1719505988517,"mc":[{"id":"1.230178326","rc":[{"atb":[[1.06,0.04],[1.05,0.09]],"id":58221357},{"atl":[[1000,0.06]],"id":58221357},{"atb":[[2.16,25.4]],"id":60748118}],"con":true,"img":false}]}
{"op":"mcm","clk":"11541460435","pt":1719505988613,"mc":[{"id":"1.230178326","rc":[{"atb":[[3.5,1],[2.16,25.4]],"id":62600242},{"atb":[[3.5,0]],"id":65710029}],"con":true,"img":false}]}
{"op":"mcm","clk":"11541460448","pt":1719505988716,"mc":[{"id":"1.230178326","rc":[{"atb":[[1.06,0],[1.05,0]],"id":58221357},{"atl":[[1000,0]],"id":58221357},{"atl":[[9.6,1.05]],"id":62600242}],"con":true,"img":false}]}
{"op":"mcm","clk":"11541460458","pt":1719505988826,"mc":[{"id":"1.230178326","rc":[{"atb":[[5.2,1.7]],"id":58221357},{"atl":[[9.6,0.06]],"id":58221357}],"con":true,"img":false}]}
{"op":"mcm","clk":"11541460466","pt":1719505988921,"mc":[{"id":"1.230178326","rc":[{"atl":[[10.5,4],[50,0]],"id":58221357},{"atb":[[2.98,6.41]],"id":62600242},{"atb":[[2.64,11.98]],"id":65710029}],"con":true,"img":false}]}
{"op":"mcm","clk":"11541460475","pt":1719505989023,"mc":[{"id":"1.230178326","rc":[{"atb":[[2.96,9.18]],"id":62600242}],"con":true,"img":false}]}
{"op":"mcm","clk":"11541460483","pt":1719505989126,"mc":[{"id":"1.230178326","rc":[{"atl":[[9.2,0]],"id":58221357}],"con":true,"img":false}]}
{"op":"mcm","clk":"11541460494","pt":1719505989229,"mc":[{"id":"1.230178326","rc":[{"atb":[[3,1.6]],"id":62600242},{"atb":[[2.16,18.58]],"id":65710029}],"con":true,"img":false}]}
{"op":"mcm","clk":"11541460502","pt":1719505989331,"mc":[{"id":"1.230178326","rc":[{"atb":[[5.3,0.84]],"id":58221357},{"atl":[[9,1]],"id":58221357},{"atb":[[2.16,25.4]],"id":68687941}],"con":true,"img":false}]}
{"op":"mcm","clk":"11541460524","pt":1719505989539,"mc":[{"id":"1.230178326","rc":[{"atb":[[2.82,9.88]],"id":65710029}],"con":true,"img":false}]}
{"op":"mcm","clk":"11541460667","pt":1719505990834,"mc":[{"id":"1.230178326","rc":[{"atl":[[9,0.84]],"id":62600242}],"con":true,"img":false}]}
{"op":"mcm","clk":"11541460675","pt":1719505990935,"mc":[{"id":"1.230178326","rc":[{"atl":[[9.2,3.84]],"id":62600242}],"con":true,"img":false}]}
{"op":"mcm","clk":"11541460729","pt":1719505991512,"mc":[{"id":"1.230178326","rc":[{"atl":[[9.2,1.09]],"id":62600242}],"con":true,"img":false}]}
{"op":"mcm","clk":"11541460860","pt":1719505992752,"mc":[{"id":"1.230178326","rc":[{"atb":[[1.25,20]],"id":58221357},{"atb":[[1.25,20]],"id":62600242},{"atb":[[1.25,20]],"id":60748118},{"atb":[[1.25,20]],"id":68687941},{"atb":[[1.25,20]],"id":67674431},{"atb":[[1.25,20]],"id":65710029}],"con":true,"img":false}]}
{"op":"mcm","clk":"11541460922","pt":1719505993225,"mc":[{"id":"1.230178326","rc":[{"atl":[[9.2,1],[9.8,0]],"id":58221357},{"atl":[[9.6,2.05],[9.8,0]],"id":62600242},{"atl":[[8,1],[8.2,0]],"id":65710029}],"con":true,"img":false}]}
{"op":"mcm","clk":"11541460936","pt":1719505993325,"mc":[{"id":"1.230178326","rc":[{"atl":[[10.5,4],[11,0]],"id":62600242},{"atb":[[5,1],[5.2,4.39]],"id":67674431},{"atl":[[19,0],[19.5,5.41]],"id":67674431},{"atl":[[7.8,1],[8.4,3.89],[8.6,1.17]],"id":65710029}],"con":true,"img":false}]}
{"op":"mcm","clk":"11541460949","pt":1719505993428,"mc":[{"id":"1.230178326","rc":[{"atl":[[19.5,0],[21,5]],"id":67674431}],"con":true,"img":false}]}
{"op":"mcm","clk":"11541460959","pt":1719505993531,"mc":[{"id":"1.230178326","rc":[{"atb":[[5.1,1.65]],"id":67674431}],"con":true,"img":false}]}
{"op":"mcm","clk":"11541460972","pt":1719505993634,"mc":[{"id":"1.230178326","rc":[{"atb":[[5.3,1.88],[5.1,10.45],[5.2,0.84]],"id":67674431}],"con":true,"img":false}]}
{"op":"mcm","clk":"11541460981","pt":1719505993738,"mc":[{"id":"1.230178326","rc":[{"atb":[[5.1,1.65],[5.2,4.62]],"id":67674431}],"con":true,"img":false}]}
{"op":"mcm","clk":"11541461000","pt":1719505993943,"mc":[{"id":"1.230178326","rc":[{"atl":[[8.4,3.05]],"id":65710029}],"con":true,"img":false}]}
{"op":"mcm","clk":"11541461039","pt":1719505994319,"mc":[{"id":"1.230178326","rc":[{"atb":[[3.8,0],[3.3,8.59]],"id":60748118},{"atb":[[5.4,0.84]],"id":67674431}],"con":true,"img":false}]}
{"op":"mcm","clk":"11541461094","pt":1719505994826,"mc":[{"id":"1.230178326","rc":[{"atb":[[3.85,0],[4.5,0]],"id":60748118},{"trd":[[4.5,2]],"ltp":4.5,"tv":2.0,"id":60748118}],"con":true,"img":false}]}
{"op":"mcm","clk":"11541461105","pt":1719505994927,"mc":[{"id":"1.230178326","rc":[{"atl":[[8.2,1.22]],"id":65710029}],"con":true,"img":false}]}
{"op":"mcm","clk":"11541461142","pt":1719505995341,"mc":[{"id":"1.230178326","rc":[{"atb":[[3.8,0.84]],"id":60748118}],"con":true,"img":false}]}
{"op":"mcm","clk":"11541461202","pt":1719505995913,"mc":[{"id":"1.230178326","rc":[{"atl":[[8.4,2]],"id":65710029}],"con":true,"img":false}]}
{"op":"mcm","clk":"11541461470","pt":1719505998655,"mc":[{"id":"1.230178326","rc":[{"atl":[[9.4,1.74]],"id":62600242}],"con":true,"img":false}]}
{"op":"mcm","clk":"11541461495","pt":1719505998914,"mc":[{"id":"1.230178326","rc":[{"atl":[[1000,0.28]],"id":62600242}],"con":true,"img":false}]}
{"op":"mcm","clk":"11541461517","pt":1719505999130,"mc":[{"id":"1.230178326","rc":[{"atl":[[1000,0.16]],"id":62600242}],"con":true,"img":false}]}
{"op":"mcm","clk":"11541461527","pt":1719505999234,"mc":[{"id":"1.230178326","rc":[{"atl":[[9,0.96]],"id":62600242}],"con":true,"img":false}]}
{"op":"mcm","clk":"11541461579","pt":1719505999739,"mc":[{"id":"1.230178326","rc":[{"atb":[[4,1]],"id":60748118}],"con":true,"img":false}]}
{"op":"mcm","clk":"11541461916","pt":1719506003246,"mc":[{"id":"1.230178326","rc":[{"atl":[[10.5,0]],"id":60748118},{"atl":[[8,0]],"id":68687941}],"con":true,"img":false}]}
{"op":"mcm","clk":"11541461936","pt":1719506003453,"mc":[{"id":"1.230178326","rc":[{"atl":[[1000,0.27]],"id":60748118},{"atl":[[1000,0.14]],"id":68687941}],"con":true,"img":false}]}
{"op":"mcm","clk":"11541461969","pt":1719506003735,"mc":[{"id":"1.230178326","rc":[{"atl":[[1000,0.16]],"id":60748118},{"atl":[[1000,0]],"id":68687941}],"con":true,"img":false}]}
{"op":"mcm","clk":"11541461983","pt":1719506003825,"mc":[{"id":"1.230178326","rc":[{"atl":[[10.5,0.11]],"id":60748118},{"atl":[[8,0.14]],"id":68687941}],"con":true,"img":false}]}
{"op":"mcm","clk":"11541462021","pt":1719506004236,"mc":[{"id":"1.230178326","rc":[{"atl":[[8,0]],"id":65710029}],"con":true,"img":false}]}
{"op":"mcm","clk":"11541462306","pt":1719506006836,"mc":[{"id":"1.230178326","rc":[{"atl":[[7.6,1.05]],"id":65710029}],"con":true,"img":false}]}
{"op":"mcm","clk":"11541462900","pt":1719506013052,"mc":[{"id":"1.230178326","rc":[{"atb":[[2.68,0]],"id":58221357},{"spn":9.09,"spf":"Infinity","id":58221357},{"spn":7.0,"spf":"NaN","id":60748118},{"atb":[[2.38,0]],"id":68687941},{"spn":4.7,"spf":1.0,"id":68687941},{"atb":[[2.16,25.4]],"id":67674431},{"spn":11.45,"spf":"NaN","id":67674431},{"spn":3.73,"spf":1.0,"id":65710029}],"con":true,"img":false}]}
{"op":"mcm","clk":"11541463037","pt":1719506014554,"mc":[{"id":"1.230178326","rc":[{"atl":[[9,0.84]],"id":62600242}],"con":true,"img":false}]}
{"op":"mcm","clk":"11541463056","pt":1719506014761,"mc":[{"id":"1.230178326","rc":[{"atl":[[1000,0.28]],"id":62600242}],"con":true,"img":false}]}
{"op":"mcm","clk":"11541463090","pt":1719506015040,"mc":[{"id":"1.230178326","rc":[{"atl":[[1000,0.16]],"id":62600242}],"con":true,"img":false}]}
{"op":"mcm","clk":"11541463098","pt":1719506015136,"mc":[{"id":"1.230178326","rc":[{"atb":[[3.5,3.6]],"id":62600242},{"atl":[[9,0.96]],"id":62600242},{"atb":[[3.3,8.41]],"id":68687941},{"atb":[[5.4,1.63]],"id":67674431}],"con":true,"img":false}]}
{"op":"mcm","clk":"11541463119","pt":1719506015335,"mc":[{"id":"1.230178326","rc":[{"atb":[[3.25,1]],"id":68687941}],"con":true,"img":false}]}
{"op":"mcm","clk":"11541463139","pt":1719506015539,"mc":[{"id":"1.230178326","rc":[{"atb":[[3.35,1]],"id":68687941}],"con":true,"img":false}]}
{"op":"mcm","clk":"11541463153","pt":1719506015746,"mc":[{"id":"1.230178326","rc":[{"atb":[[3.45,0]],"id":62600242}],"con":true,"img":false}]}
{"op":"mcm","clk":"11541463163","pt":1719506015848,"mc":[{"id":"1.230178326","rc":[{"atb":[[3.55,1.91]],"id":62600242}],"con":true,"img":false}]}
{"op":"mcm","clk":"11541463185","pt":1719506016054,"mc":[{"id":"1.230178326","rc":[{"atb":[[3.5,2.6]],"id":62600242}],"con":true,"img":false}]}
{"op":"mcm","clk":"11541463206","pt":1719506016260,"mc":[{"id":"1.230178326","rc":[{"atb":[[3.6,1]],"id":62600242}],"con":true,"img":false}]}
{"op":"mcm","clk":"11541463226","pt":1719506016464,"mc":[{"id":"1.230178326","rc":[{"atb":[[3.6,3],[3.35,0]],"id":62600242}],"con":true,"img":false}]}
{"op":"mcm","clk":"11541463390","pt":1719506018072,"mc":[{"id":"1.230178326","rc":[{"atb":[[3,0]],"id":62600242}],"con":true,"img":false}]}
{"op":"mcm","clk":"11541463405","pt":1719506018243,"mc":[{"id":"1.230178326","rc":[{"atb":[[3.05,5.86]],"id":62600242}],"con":true,"img":false}]}
{"op":"mcm","clk":"11541463473","pt":1719506018956,"mc":[{"id":"1.230178326","rc":[{"atl":[[10.5,0]],"id":60748118},{"atb":[[3.25,0],[3.2,7.6]],"id":68687941},{"atl":[[8,0]],"id":68687941}],"con":true,"img":false}]}
{"op":"mcm","clk":"11541463483","pt":1719506019060,"mc":[{"id":"1.230178326","rc":[{"atb":[[3.55,5.05]],"id":62600242}],"con":true,"img":false}]}
{"op":"mcm","clk":"11541463495","pt":1719506019162,"mc":[{"id":"1.230178326","rc":[{"atl":[[1000,0.27]],"id":60748118},{"atl":[[1000,0.14]],"id":68687941}],"con":true,"img":false}]}
{"op":"mcm","clk":"11541463510","pt":1719506019371,"mc":[{"id":"1.230178326","rc":[{"atl":[[1000,0.16]],"id":60748118},{"atb":[[3.25,1],[3.2,6.6]],"id":68687941},{"atl":[[1000,0]],"id":68687941}],"con":true,"img":false}]}
{"op":"mcm","clk":"11541463519","pt":1719506019473,"mc":[{"id":"1.230178326","rc":[{"atb":[[3.55,3.14]],"id":62600242},{"atl":[[10.5,0.11]],"id":60748118},{"atl":[[8,0.14]],"id":68687941}],"con":true,"img":false}]}
{"op":"mcm","clk":"11541463528","pt":1719506019538,"mc":[{"id":"1.230178326","rc":[{"atb":[[3.65,1.91]],"id":62600242}],"con":true,"img":false}]}
{"op":"mcm","clk":"11541463547","pt":1719506019739,"mc":[{"id":"1.230178326","rc":[{"atb":[[3.6,2]],"id":62600242}],"con":true,"img":false}]}
{"op":"mcm","clk":"11541463566","pt":1719506019944,"mc":[{"id":"1.230178326","rc":[{"atb":[[3.7,1]],"id":62600242}],"con":true,"img":false}]}
{"op":"mcm","clk":"11541463578","pt":1719506020046,"mc":[{"id":"1.230178326","rc":[{"atb":[[3.65,0]],"id":62600242}],"con":true,"img":false}]}
{"op":"mcm","clk":"11541463590","pt":1719506020149,"mc":[{"id":"1.230178326","rc":[{"atb":[[3.6,3.91]],"id":62600242}],"con":true,"img":false}]}
{"op":"mcm","clk":"11541463630","pt":1719506020561,"mc":[{"id":"1.230178326","rc":[{"atb":[[3.05,0]],"id":62600242}],"con":true,"img":false}]}
{"op":"mcm","clk":"11541463800","pt":1719506022162,"mc":[{"id":"1.230178326","rc":[{"atl":[[7.6,0]],"id":65710029}],"con":true,"img":false}]}
{"op":"mcm","clk":"11541463809","pt":1719506022266,"mc":[{"id":"1.230178326","rc":[{"atb":[[3.65,3.02]],"id":62600242}],"con":true,"img":false}]}
{"op":"mcm","clk":"11541463836","pt":1719506022576,"mc":[{"id":"1.230178326","rc":[{"atb":[[3.6,2]],"id":62600242},{"atb":[[2.4,9.06]],"id":67674431}],"con":true,"img":false}]}
{"op":"mcm","clk":"11541463845","pt":1719506022636,"mc":[{"id":"1.230178326","rc":[{"atb":[[3.7,2.91]],"id":62600242}],"con":true,"img":false}]}
{"op":"mcm","clk":"11541463863","pt":1719506022845,"mc":[{"id":"1.230178326","rc":[{"atb":[[2.72,7.37]],"id":58221357},{"atb":[[2.4,9.06]],"id":60748118}],"con":true,"img":false}]}
{"op":"mcm","clk":"11541463888","pt":1719506023150,"mc":[{"id":"1.230178326","rc":[{"atb":[[2.76,11.16]],"id":68687941},{"atb":[[2.94,10.66]],"id":65710029}],"con":true,"img":false}]}
{"op":"mcm","clk":"11541463921","pt":1719506023458,"mc":[{"id":"1.230178326","rc":[{"atb":[[2.96,6.47]],"id":68687941}],"con":true,"img":false}]}
{"op":"mcm","clk":"11541463937","pt":1719506023663,"mc":[{"id":"1.230178326","rc":[{"atb":[[2.94,9.28]],"id":68687941}],"con":true,"img":false}]}
{"op":"mcm","clk":"11541464142","pt":1719506025803,"mc":[{"id":"1.230178326","rc":[{"atb":[[2.36,0]],"id":62600242}],"con":true,"img":false}]}
{"op":"mcm","clk":"11541464589","pt":1719506030485,"mc":[{"id":"1.230178326","rc":[{"atl":[[9,0.84]],"id":62600242}],"con":true,"img":false}]}
{"op":"mcm","clk":"11541464609","pt":1719506030690,"mc":[{"id":"1.230178326","rc":[{"atl":[[1000,0.28]],"id":62600242},{"atb":[[4.6,1]],"id":65710029}],"con":true,"img":false}]}
{"op":"mcm","clk":"11541464618","pt":1719506030747,"mc":[{"id":"1.230178326","rc":[{"atb":[[4.2,12.86]],"id":60748118}],"con":true,"img":false}]}
{"op":"mcm","clk":"11541464627","pt":1719506030848,"mc":[{"id":"1.230178326","rc":[{"atl":[[1000,0.16]],"id":62600242}],"con":true,"img":false}]}
{"op":"mcm","clk":"11541464637","pt":1719506030972,"mc":[{"id":"1.230178326","rc":[{"atl":[[9,0.96]],"id":62600242}],"con":true,"img":false}]}
{"op":"mcm","clk":"11541464667","pt":1719506031280,"mc":[{"id":"1.230178326","rc":[{"atl":[[11,2.57]],"id":60748118}],"con":true,"img":false}]}
{"op":"mcm","clk":"11541464677","pt":1719506031383,"mc":[{"id":"1.230178326","rc":[{"atb":[[4.3,0.84],[3.8,0]],"id":60748118},{"atl":[[1000,0.65]],"id":60748118}],"con":true,"img":false}]}
{"op":"mcm","clk":"11541464691","pt":1719506031486,"mc":[{"id":"1.230178326","rc":[{"atb":[[4.3,2.76]],"id":60748118}],"con":true,"img":false}]}
{"op":"mcm","clk":"11541464721","pt":1719506031756,"mc":[{"id":"1.230178326","rc":[{"atb":[[4.4,5.77]],"id":60748118}],"con":true,"img":false}]}
{"op":"mcm","clk":"11541464730","pt":1719506031854,"mc":[{"id":"1.230178326","rc":[{"atb":[[4.4,4.27]],"id":65710029}],"con":true,"img":false}]}
{"op":"mcm","clk":"11541464756","pt":1719506032060,"mc":[{"id":"1.230178326","rc":[{"atb":[[4.3,0.84]],"id":60748118},{"atb":[[4.6,0]],"id":65710029}],"con":true,"img":false}]}
{"op":"mcm","clk":"11541464765","pt":1719506032161,"mc":[{"id":"1.230178326","rc":[{"atb":[[4.5,1.92]],"id":60748118}],"con":true,"img":false}]}
{"op":"mcm","clk":"11541464777","pt":1719506032268,"mc":[{"id":"1.230178326","rc":[{"atb":[[3,5.92]],"id":62600242},{"atb":[[4.5,1]],"id":65710029}],"con":true,"img":false}]}
{"op":"mcm","clk":"11541464788","pt":1719506032370,"mc":[{"id":"1.230178326","rc":[{"atb":[[4.4,0],[2.16,18.58]],"id":60748118},{"atb":[[2.4,0]],"id":65710029}],"con":true,"img":false}]}
{"op":"mcm","clk":"11541464824","pt":1719506032785,"mc":[{"id":"1.230178326","rc":[{"atb":[[4.5,0]],"id":60748118}],"con":true,"img":false}]}
{"op":"mcm","clk":"11541464832","pt":1719506032887,"mc":[{"id":"1.230178326","rc":[{"atb":[[4.3,1.92]],"id":60748118}],"con":true,"img":false}]}
{"op":"mcm","clk":"11541464854","pt":1719506033090,"mc":[{"id":"1.230178326","rc":[{"atl":[[10.5,0],[9.8,4]],"id":58221357},{"atl":[[10,4],[10.5,0]],"id":62600242},{"atb":[[4.4,5.77]],"id":60748118},{"atl":[[11.5,8],[12,0]],"id":60748118},{"atl":[[20,6],[21,0]],"id":67674431}],"con":true,"img":false}]}
{"op":"mcm","clk":"11541464876","pt":1719506033252,"mc":[{"id":"1.230178326","rc":[{"atl":[[9,0]],"id":58221357}],"con":true,"img":false}]}
{"op":"mcm","clk":"11541464892","pt":1719506033459,"mc":[{"id":"1.230178326","rc":[{"atl":[[1000,4.05]],"id":60748118},{"atl":[[17.5,0]],"id":67674431}],"con":true,"img":false}]}
{"op":"mcm","clk":"11541464901","pt":1719506033564,"mc":[{"id":"1.230178326","rc":[{"atl":[[8.8,1]],"id":58221357},{"atb":[[1.05,1.7],[1.04,1.7]],"id":60748118},{"atl":[[1000,5.75]],"id":60748118}],"con":true,"img":false}]}
{"op":"mcm","clk":"11541464912","pt":1719506033665,"mc":[{"id":"1.230178326","rc":[{"atl":[[1000,1.91]],"id":60748118}],"con":true,"img":false}]}
{"op":"mcm","clk":"11541464920","pt":1719506033766,"mc":[{"id":"1.230178326","rc":[{"atl":[[8.8,0.96]],"id":62600242},{"atb":[[1.05,0.05],[1.04,0.05]],"id":60748118},{"atl":[[10.5,0.59],[1000,0.23]],"id":60748118},{"atl":[[1000,1.51]],"id":67674431}],"con":true,"img":false}]}
{"op":"mcm","clk":"11541464944","pt":1719506033971,"mc":[{"id":"1.230178326","rc":[{"atl":[[1000,0.18]],"id":60748118}],"con":true,"img":false}]}
{"op":"mcm","clk":"11541464952","pt":1719506034076,"mc":[{"id":"1.230178326","rc":[{"atb":[[1.05,0],[1.04,0]],"id":60748118},{"atl":[[10.5,0.63],[1000,0.16]],"id":60748118}],"con":true,"img":false}]}
{"op":"mcm","clk":"11541464960","pt":1719506034178,"mc":[{"id":"1.230178326","rc":[{"atb":[[4.5,0.11]],"id":60748118},{"atl":[[10.5,0.65]],"id":60748118},{"atl":[[1000,1.14]],"id":67674431}],"con":true,"img":false}]}
{"op":"mcm","clk":"11541464969","pt":1719506034282,"mc":[{"id":"1.230178326","rc":[{"atl":[[10.5,0.17]],"id":60748118}],"con":true,"img":false}]}
{"op":"mcm","clk":"11541464980","pt":1719506034383,"mc":[{"id":"1.230178326","rc":[{"atl":[[9.4,0]],"id":62600242},{"atl":[[1000,0.65]],"id":60748118},{"atl":[[7.6,1.05]],"id":65710029}],"con":true,"img":false}]}
{"op":"mcm","clk":"11541465001","pt":1719506034591,"mc":[{"id":"1.230178326","rc":[{"atb":[[3.7,1]],"id":62600242},{"atl":[[1000,0.66]],"id":67674431},{"atl":[[8,2.05],[8.4,0]],"id":65710029}],"con":true,"img":false}]}
{"op":"mcm","clk":"11541465012","pt":1719506034698,"mc":[{"id":"1.230178326","rc":[{"atl":[[10.5,0.06]],"id":60748118},{"atl":[[8,0]],"id":68687941},{"atl":[[19.5,0.48]],"id":67674431}],"con":true,"img":false}]}
{"op":"mcm","clk":"11541465040","pt":1719506034954,"mc":[{"id":"1.230178326","rc":[{"atl":[[10,0],[10.5,0.9]],"id":60748118}],"con":true,"img":false}]}
{"op":"mcm","clk":"11541465093","pt":1719506035471,"mc":[{"id":"1.230178326","rc":[{"atl":[[1000,0.16]],"id":60748118},{"atl":[[19.5,0],[1000,1.51]],"id":67674431}],"con":true,"img":false}]}
{"op":"mcm","clk":"11541465103","pt":1719506035575,"mc":[{"id":"1.230178326","rc":[{"atl":[[11,3.05]],"id":60748118}],"con":true,"img":false}]}
{"op":"mcm","clk":"11541465124","pt":1719506035778,"mc":[{"id":"1.230178326","rc":[{"atl":[[1000,0.27]],"id":60748118},{"atl":[[1000,0.14]],"id":68687941}],"con":true,"img":false}]}
{"op":"mcm","clk":"11541465141","pt":1719506035882,"mc":[{"id":"1.230178326","rc":[{"atl":[[1000,1.14]],"id":67674431}],"con":true,"img":false}]}
{"op":"mcm","clk":"11541465151","pt":1719506035983,"mc":[{"id":"1.230178326","rc":[{"atl":[[1000,0.16]],"id":60748118},{"atl":[[1000,0]],"id":68687941}],"con":true,"img":false}]}
{"op":"mcm","clk":"11541465160","pt":1719506036088,"mc":[{"id":"1.230178326","rc":[{"atl":[[10.5,1.01]],"id":60748118},{"atl":[[8,0.14]],"id":68687941}],"con":true,"img":false}]}
{"op":"mcm","clk":"11541465169","pt":1719506036191,"mc":[{"id":"1.230178326","rc":[{"atl":[[1000,0.66]],"id":67674431}],"con":true,"img":false}]}
{"op":"mcm","clk":"11541465177","pt":1719506036291,"mc":[{"id":"1.230178326","rc":[{"atl":[[18,1.32]],"id":67674431}],"con":true,"img":false}]}
{"op":"mcm","clk":"11541465206","pt":1719506036656,"mc":[{"id":"1.230178326","rc":[{"atl":[[11,2.57]],"id":60748118}],"con":true,"img":false}]}
{"op":"mcm","clk":"11541465214","pt":1719506036779,"mc":[{"id":"1.230178326","rc":[{"atl":[[1000,0.65]],"id":60748118}],"con":true,"img":false}]}
{"op":"mcm","clk":"11541465545","pt":1719506040573,"mc":[{"id":"1.230178326","rc":[{"atl":[[9.6,3]],"id":58221357},{"atb":[[3.7,10.41]],"id":62600242},{"atl":[[9.4,2.93]],"id":62600242},{"atb":[[4.5,6.88]],"id":60748118},{"atl":[[10.5,3.64]],"id":60748118},{"atb":[[3.35,12.64]],"id":68687941},{"atl":[[23,1.7]],"id":68687941},{"atl":[[7.8,4.41]],"id":65710029}],"con":true,"img":false}]}
{"op":"mcm","clk":"11541465555","pt":1719506040678,"mc":[{"id":"1.230178326","rc":[{"atb":[[3.75,3.02]],"id":62600242},{"atl":[[7.8,5.7]],"id":65710029}],"con":true,"img":false}]}
{"op":"mcm","clk":"11541465566","pt":1719506040781,"mc":[{"id":"1.230178326","rc":[{"atl":[[8.8,0]],"id":58221357},{"atb":[[3.6,0],[3.7,9.41]],"id":62600242},{"atl":[[10,0.84],[1000,0.16]],"id":60748118},{"atb":[[3.35,11.64]],"id":68687941},{"atl":[[23,1.26],[25,0]],"id":68687941}],"con":true,"img":false}]}
{"op":"mcm","clk":"11541465572","pt":1719506040885,"mc":[{"id":"1.230178326","rc":[{"atl":[[10,1.32]],"id":60748118},{"atb":[[3.4,1]],"id":68687941},{"atl":[[1000,0.44]],"id":68687941}],"con":true,"img":false}]}
{"op":"mcm","clk":"11541465579","pt":1719506040988,"mc":[{"id":"1.230178326","rc":[{"atl":[[8.6,1]],"id":58221357},{"atb":[[3.8,1.91],[3.75,4.02]],"id":62600242}],"con":true,"img":false}]}
{"op":"mcm","clk":"11541465589","pt":1719506041092,"mc":[{"id":"1.230178326","rc":[{"atb":[[4.3,0]],"id":60748118},{"atb":[[3.3,6.49]],"id":68687941}],"con":true,"img":false}]}
{"op":"mcm","clk":"11541465597","pt":1719506041196,"mc":[{"id":"1.230178326","rc":[{"atb":[[4.6,1.92]],"id":60748118},{"atl":[[10.5,2.8],[9.8,0.86]],"id":60748118},{"atb":[[3.4,2.92]],"id":68687941}],"con":true,"img":false}]}
{"op":"mcm","clk":"11541465604","pt":1719506041298,"mc":[{"id":"1.230178326","rc":[{"atb":[[3.75,3.02]],"id":62600242},{"atb":[[4.4,0]],"id":60748118}],"con":true,"img":false}]}
{"op":"mcm","clk":"11541465612","pt":1719506041400,"mc":[{"id":"1.230178326","rc":[{"atb":[[3.85,9.33]],"id":62600242},{"atb":[[4.6,8.12]],"id":60748118},{"atl":[[9.8,3.79]],"id":60748118},{"atb":[[3.45,10.82]],"id":68687941}],"con":true,"img":false}]}
{"op":"mcm","clk":"11541465623","pt":1719506041503,"mc":[{"id":"1.230178326","rc":[{"atb":[[3.85,10.33]],"id":62600242},{"atl":[[10,0.84]],"id":60748118}],"con":true,"img":false}]}
{"op":"mcm","clk":"11541465632","pt":1719506041606,"mc":[{"id":"1.230178326","rc":[{"atl":[[1000,0.65]],"id":60748118},{"atb":[[3.5,10.82],[3.2,0]],"id":68687941}],"con":true,"img":false}]}
{"op":"mcm","clk":"11541465643","pt":1719506041668,"mc":[{"id":"1.230178326","rc":[{"atb":[[3.85,9.33],[3.8,0]],"id":62600242},{"atb":[[3.4,1]],"id":68687941}],"con":true,"img":false}]}
{"op":"mcm","clk":"11541465654","pt":1719506041767,"mc":[{"id":"1.230178326","rc":[{"atb":[[3.9,1.91]],"id":62600242},{"atb":[[3.5,12.74]],"id":68687941}],"con":true,"img":false}]}
{"op":"mcm","clk":"11541465664","pt":1719506041869,"mc":[{"id":"1.230178326","rc":[{"atb":[[3.9,2.91]],"id":62600242}],"con":true,"img":false}]}
{"op":"mcm","clk":"11541465684","pt":1719506042075,"mc":[{"id":"1.230178326","rc":[{"atb":[[3.95,8.81]],"id":62600242},{"atb":[[4.7,5.39]],"id":60748118},{"atl":[[9.6,2.64]],"id":60748118},{"atb":[[3.55,9.65],[3.4,0]],"id":68687941}],"con":true,"img":false}]}
{"op":"mcm","clk":"11541465701","pt":1719506042289,"mc":[{"id":"1.230178326","rc":[{"atb":[[3.9,0]],"id":62600242},{"atb":[[4.6,6.2]],"id":60748118},{"atb":[[3.5,10.82]],"id":68687941}],"con":true,"img":false}]}
{"op":"mcm","clk":"11541465711","pt":1719506042384,"mc":[{"id":"1.230178326","rc":[{"atb":[[4,1.91]],"id":62600242},{"atb":[[4.8,1.92]],"id":60748118},{"atl":[[10,0]],"id":60748118},{"atb":[[3.6,1.92]],"id":68687941}],"con":true,"img":false}]}
{"op":"mcm","clk":"11541465720","pt":1719506042486,"mc":[{"id":"1.230178326","rc":[{"atb":[[4,2.91]],"id":62600242},{"atb":[[3.6,2.92]],"id":68687941}],"con":true,"img":false}]}
{"op":"mcm","clk":"11541465750","pt":1719506042799,"mc":[{"id":"1.230178326","rc":[{"atb":[[4.7,0]],"id":60748118}],"con":true,"img":false}]}
{"op":"mcm","clk":"11541465784","pt":1719506043165,"mc":[{"id":"1.230178326","rc":[{"atb":[[3.5,0]],"id":62600242},{"atl":[[11,1]],"id":60748118},{"atb":[[3.3,3.48]],"id":68687941}],"con":true,"img":false}]}
{"op":"mcm","clk":"11541465814","pt":1719506043471,"mc":[{"id":"1.230178326","rc":[{"atb":[[4.1,8.26]],"id":62600242},{"atb":[[4.8,6.64]],"id":60748118},{"atl":[[9.6,5.75]],"id":60748118},{"atb":[[3.65,10.22]],"id":68687941}],"con":true,"img":false}]}
{"op":"mcm","clk":"11541465824","pt":1719506043577,"mc":[{"id":"1.230178326","rc":[{"atb":[[4.7,1.92]],"id":60748118}],"con":true,"img":false}]}
{"op":"mcm","clk":"11541465834","pt":1719506043678,"mc":[{"id":"1.230178326","rc":[{"atb":[[4,1.91]],"id":62600242},{"atb":[[3.6,1.92]],"id":68687941}],"con":true,"img":false}]}
{"op":"mcm","clk":"11541465854","pt":1719506043883,"mc":[{"id":"1.230178326","rc":[{"atb":[[4.2,1]],"id":62600242},{"atl":[[1000,0.16]],"id":60748118},{"atb":[[3.7,1]],"id":68687941}],"con":true,"img":false}]}
{"op":"mcm","clk":"11541465866","pt":1719506043988,"mc":[{"id":"1.230178326","rc":[{"atl":[[9.4,0.48]],"id":60748118}],"con":true,"img":false}]}
{"op":"mcm","clk":"11541465875","pt":1719506044092,"mc":[{"id":"1.230178326","rc":[{"atb":[[4,0]],"id":62600242},{"atb":[[4.7,0]],"id":60748118},{"atb":[[3.6,0]],"id":68687941}],"con":true,"img":false}]}
{"op":"mcm","clk":"11541465888","pt":1719506044197,"mc":[{"id":"1.230178326","rc":[{"atb":[[4.2,2.91]],"id":62600242},{"atb":[[4.9,1.92]],"id":60748118},{"atb":[[3.7,2.92]],"id":68687941}],"con":true,"img":false}]}
{"op":"mcm","clk":"11541465990","pt":1719506045078,"mc":[{"id":"1.230178326","rc":[{"atb":[[4,0]],"id":60748118}],"con":true,"img":false}]}
{"op":"mcm","clk":"11541466092","pt":1719506046274,"mc":[{"id":"1.230178326","rc":[{"atl":[[9,0.84]],"id":62600242}],"con":true,"img":false}]}
{"op":"mcm","clk":"11541466116","pt":1719506046479,"mc":[{"id":"1.230178326","rc":[{"atb":[[4.2,5.41]],"id":62600242}],"con":true,"img":false}]}
{"op":"mcm","clk":"11541466153","pt":1719506046887,"mc":[{"id":"1.230178326","rc":[{"atl":[[1000,0.29]],"id":62600242}],"con":true,"img":false}]}
{"op":"mcm","clk":"11541466174","pt":1719506047094,"mc":[{"id":"1.230178326","rc":[{"atl":[[1000,0.16]],"id":62600242}],"con":true,"img":false}]}
{"op":"mcm","clk":"11541466184","pt":1719506047206,"mc":[{"id":"1.230178326","rc":[{"atl":[[8.8,1.09]],"id":62600242}],"con":true,"img":false}]}
{"op":"mcm","clk":"11541466211","pt":1719506047503,"mc":[{"id":"1.230178326","rc":[{"atl":[[9,1.81],[8.8,0.13]],"id":62600242}],"con":true,"img":false}]}
{"op":"mcm","clk":"11541466269","pt":1719506048081,"mc":[{"id":"1.230178326","rc":[{"atb":[[2.98,0],[2.16,18.58]],"id":62600242},{"atb":[[3.5,0],[2.16,18.58],[3.65,20.44]],"id":68687941}],"con":true,"img":false}]}
{"op":"mcm","clk":"11541466287","pt":1719506048286,"mc":[{"id":"1.230178326","rc":[{"atl":[[9.4,1.32]],"id":60748118},{"atb":[[3.7,5.88]],"id":68687941}],"con":true,"img":false}]}
{"op":"mcm","clk":"11541466328","pt":1719506048700,"mc":[{"id":"1.230178326","rc":[{"atl":[[9.6,3.11]],"id":60748118}],"con":true,"img":false}]}
{"op":"mcm","clk":"11541466340","pt":1719506048801,"mc":[{"id":"1.230178326","rc":[{"atl":[[9.4,4.29]],"id":60748118}],"con":true,"img":false}]}
{"op":"mcm","clk":"11541466359","pt":1719506049012,"mc":[{"id":"1.230178326","rc":[{"atl":[[9.2,1.72]],"id":60748118}],"con":true,"img":false}]}
{"op":"mcm","clk":"11541466389","pt":1719506049272,"mc":[{"id":"1.230178326","rc":[{"atl":[[1000,1.7]],"id":58221357},{"atl":[[1000,6.97]],"id":62600242},{"atl":[[9.4,3.81],[1000,1.87]],"id":60748118}],"con":true,"img":false}]}
{"op":"mcm","clk":"11541466403","pt":1719506049378,"mc":[{"id":"1.230178326","rc":[{"atb":[[1.06,1.7]],"id":58221357},{"atb":[[1.05,5.1],[1.04,3.4]],"id":62600242},{"atb":[[1.06,1.7]],"id":60748118},{"atl":[[9,2.81],[1000,2.35]],"id":60748118}],"con":true,"img":false}]}
{"op":"mcm","clk":"11541466426","pt":1719506049591,"mc":[{"id":"1.230178326","rc":[{"atb":[[1.06,0.03]],"id":58221357},{"atl":[[1000,0.02]],"id":58221357},{"atb":[[1.05,0.15],[1.04,0.12]],"id":62600242},{"atl":[[1000,0.26]],"id":62600242},{"atb":[[1.06,0.04]],"id":60748118},{"atl":[[1000,0.67]],"id":60748118}],"con":true,"img":false}]}
{"op":"mcm","clk":"11541466462","pt":1719506049900,"mc":[{"id":"1.230178326","rc":[{"atb":[[1.06,0]],"id":58221357},{"atl":[[1000,0]],"id":58221357},{"atb":[[1.05,0],[1.04,0]],"id":62600242},{"atl":[[1000,0.16]],"id":62600242},{"atb":[[1.06,0]],"id":60748118},{"atl":[[9.4,2.97],[1000,0.65]],"id":60748118},{"atl":[[7.6,0]],"id":65710029}],"con":true,"img":false}]}
{"op":"mcm","clk":"11541466475","pt":1719506049992,"mc":[{"id":"1.230178326","rc":[{"atb":[[5.3,0.88]],"id":58221357},{"atl":[[9,0.02]],"id":58221357},{"atb":[[4.3,0.28]],"id":62600242},{"atl":[[8.8,0.22]],"id":62600242},{"atb":[[5,0.04]],"id":60748118},{"atl":[[9.2,1.74]],"id":60748118}],"con":true,"img":false}]}
{"op":"mcm","clk":"11541466511","pt":1719506050305,"mc":[{"id":"1.230178326","rc":[{"atl":[[7.6,0.84]],"id":65710029}],"con":true,"img":false}]}
{"op":"mcm","clk":"11541466546","pt":1719506050584,"mc":[{"id":"1.230178326","rc":[{"atl":[[10.5,0.17]],"id":60748118}],"con":true,"img":false}]}
{"op":"mcm","clk":"11541466564","pt":1719506050821,"mc":[{"id":"1.230178326","rc":[{"atl":[[9,6.01]],"id":60748118}],"con":true,"img":false}]}
{"op":"mcm","clk":"11541466592","pt":1719506051098,"mc":[{"id":"1.230178326","rc":[{"atl":[[1000,0.16]],"id":60748118}],"con":true,"img":false}]}
{"op":"mcm","clk":"11541466601","pt":1719506051197,"mc":[{"id":"1.230178326","rc":[{"atb":[[3.7,0]],"id":62600242},{"atl":[[8.8,0.48]],"id":60748118}],"con":true,"img":false}]}
{"op":"mcm","clk":"11541466612","pt":1719506051293,"mc":[{"id":"1.230178326","rc":[{"atl":[[10.5,0.06]],"id":60748118},{"atl":[[8,0]],"id":68687941}],"con":true,"img":false}]}
{"op":"mcm","clk":"11541466624","pt":1719506051389,"mc":[{"id":"1.230178326","rc":[{"atb":[[3.5,9.52]],"id":58221357},{"atb":[[4.3,8.76]],"id":62600242}],"con":true,"img":false}]}
{"op":"mcm","clk":"11541466632","pt":1719506051495,"mc":[{"id":"1.230178326","rc":[{"atl":[[1000,0.29]],"id":60748118},{"atl":[[1000,0.58]],"id":68687941}],"con":true,"img":false}]}
{"op":"mcm","clk":"11541466647","pt":1719506051713,"mc":[{"id":"1.230178326","rc":[{"atb":[[4.2,4.41]],"id":62600242}],"con":true,"img":false}]}
{"op":"mcm","clk":"11541466655","pt":1719506051813,"mc":[{"id":"1.230178326","rc":[{"atl":[[9.2,0.02],[1000,0.16]],"id":60748118},{"atl":[[1000,0.44]],"id":68687941}],"con":true,"img":false}]}
{"op":"mcm","clk":"11541466665","pt":1719506051921,"mc":[{"id":"1.230178326","rc":[{"atb":[[4.4,1],[4.2,2.5]],"id":62600242},{"atl":[[8.8,0.61]],"id":60748118},{"atl":[[8,0.14]],"id":68687941}],"con":true,"img":false}]}
{"op":"mcm","clk":"11541466671","pt":1719506052012,"mc":[{"id":"1.230178326","rc":[{"atb":[[4.4,2.91]],"id":62600242}],"con":true,"img":false}]}
{"op":"mcm","clk":"11541466701","pt":1719506052274,"mc":[{"id":"1.230178326","rc":[{"atl":[[8.8,0.13]],"id":60748118}],"con":true,"img":false}]}
{"op":"mcm","clk":"11541466712","pt":1719506052390,"mc":[{"id":"1.230178326","rc":[{"atb":[[5,6.96]],"id":60748118},{"atl":[[1000,0.65]],"id":60748118}],"con":true,"img":false}]}
{"op":"mcm","clk":"11541466751","pt":1719506052793,"mc":[{"id":"1.230178326","rc":[{"atb":[[5.1,4.97]],"id":60748118},{"atb":[[3.35,0]],"id":68687941}],"con":true,"img":false}]}
{"op":"mcm","clk":"11541466764","pt":1719506052895,"mc":[{"id":"1.230178326","rc":[{"atb":[[4.4,5.26]],"id":62600242}],"con":true,"img":false}]}
{"op":"mcm","clk":"11541466777","pt":1719506053106,"mc":[{"id":"1.230178326","rc":[{"atb":[[4.9,0]],"id":60748118}],"con":true,"img":false}]}
{"op":"mcm","clk":"11541466789","pt":1719506053205,"mc":[{"id":"1.230178326","rc":[{"atb":[[5.2,1.92]],"id":60748118}],"con":true,"img":false}]}
{"op":"mcm","clk":"11541466812","pt":1719506053414,"mc":[{"id":"1.230178326","rc":[{"atb":[[5.1,0]],"id":60748118}],"con":true,"img":false}]}
{"op":"mcm","clk":"11541466851","pt":1719506053680,"mc":[{"id":"1.230178326","rc":[{"atb":[[5.2,0]],"id":60748118}],"con":true,"img":false}]}
{"op":"mcm","clk":"11541466863","pt":1719506053783,"mc":[{"id":"1.230178326","rc":[{"atl":[[9.2,4.16]],"id":62600242},{"atb":[[5.1,1.92]],"id":60748118},{"atb":[[3.7,14.11]],"id":68687941}],"con":true,"img":false}]}
{"op":"mcm","clk":"11541466903","pt":1719506054097,"mc":[{"id":"1.230178326","rc":[{"atl":[[8.8,3.11]],"id":62600242}],"con":true,"img":false}]}
{"op":"mcm","clk":"11541466938","pt":1719506054411,"mc":[{"id":"1.230178326","rc":[{"atl":[[8.6,0.98]],"id":62600242}],"con":true,"img":false}]}
{"op":"mcm","clk":"11541466950","pt":1719506054512,"mc":[{"id":"1.230178326","rc":[{"atl":[[9,0.84]],"id":62600242}],"con":true,"img":false}]}
{"op":"mcm","clk":"11541466963","pt":1719506054613,"mc":[{"id":"1.230178326","rc":[{"atb":[[4.5,0.11]],"id":60748118}],"con":true,"img":false}]}
{"op":"mcm","clk":"11541466973","pt":1719506054718,"mc":[{"id":"1.230178326","rc":[{"atl":[[8.8,0.22]],"id":62600242},{"atb":[[5.2,6.4]],"id":60748118}],"con":true,"img":false}]}
{"op":"mcm","clk":"11541466996","pt":1719506054875,"mc":[{"id":"1.230178326","rc":[{"atb":[[5.3,4.79]],"id":60748118}],"con":true,"img":false}]}
{"op":"mcm","clk":"11541467033","pt":1719506055186,"mc":[{"id":"1.230178326","rc":[{"atb":[[3.85,0]],"id":62600242}],"con":true,"img":false}]}
{"op":"mcm","clk":"11541467050","pt":1719506055393,"mc":[{"id":"1.230178326","rc":[{"atb":[[4.4,13.04]],"id":62600242}],"con":true,"img":false}]}
{"op":"mcm","clk":"11541467058","pt":1719506055497,"mc":[{"id":"1.230178326","rc":[{"atb":[[5.1,0]],"id":60748118}],"con":true,"img":false}]}
{"op":"mcm","clk":"11541467070","pt":1719506055597,"mc":[{"id":"1.230178326","rc":[{"atb":[[4.4,12.04]],"id":62600242},{"atb":[[5.4,1.92]],"id":60748118}],"con":true,"img":false}]}
{"op":"mcm","clk":"11541467092","pt":1719506055820,"mc":[{"id":"1.230178326","rc":[{"atb":[[4.5,1]],"id":62600242},{"atl":[[8.8,0.97]],"id":60748118}],"con":true,"img":false}]}
{"op":"mcm","clk":"11541467111","pt":1719506056013,"mc":[{"id":"1.230178326","rc":[{"atb":[[5.3,0]],"id":60748118}],"con":true,"img":false}]}
{"op":"mcm","clk":"11541467182","pt":1719506056692,"mc":[{"id":"1.230178326","rc":[{"atb":[[5.4,0]],"id":60748118},{"atl":[[9,3.2]],"id":60748118}],"con":true,"img":false}]}
{"op":"mcm","clk":"11541467198","pt":1719506056791,"mc":[{"id":"1.230178326","rc":[{"atb":[[5.3,1.92]],"id":60748118}],"con":true,"img":false}]}
{"op":"mcm","clk":"11541467225","pt":1719506056999,"mc":[{"id":"1.230178326","rc":[{"atb":[[2.16,18.1]],"id":58221357},{"atb":[[2.16,11.29]],"id":62600242},{"atb":[[2.16,11.29]],"id":60748118},{"atb":[[2.16,11.29]],"id":68687941}],"con":true,"img":false}]}
{"op":"mcm","clk":"11541467420","pt":1719506058916,"mc":[{"id":"1.230178326","rc":[{"atb":[[4.5,7.72]],"id":65710029}],"con":true,"img":false}]}
{"op":"mcm","clk":"11541467458","pt":1719506059179,"mc":[{"id":"1.230178326","rc":[{"atl":[[8.6,0],[9,1.82]],"id":62600242}],"con":true,"img":false}]}
{"op":"mcm","clk":"11541467493","pt":1719506059492,"mc":[{"id":"1.230178326","rc":[{"atl":[[8.8,3.11]],"id":62600242}],"con":true,"img":false}]}
{"op":"mcm","clk":"11541467526","pt":1719506059800,"mc":[{"id":"1.230178326","rc":[{"atl":[[9,0.84],[8.6,1.82]],"id":62600242}],"con":true,"img":false}]}
{"op":"mcm","clk":"11541467569","pt":1719506060212,"mc":[{"id":"1.230178326","rc":[{"atl":[[8.8,0.22]],"id":62600242}],"con":true,"img":false}]}
{"op":"mcm","clk":"11541467591","pt":1719506060419,"mc":[{"id":"1.230178326","rc":[{"atl":[[9,0],[8.4,3.02]],"id":62600242}],"con":true,"img":false}]}
{"op":"mcm","clk":"11541467602","pt":1719506060523,"mc":[{"id":"1.230178326","rc":[{"atl":[[7.6,1.89]],"id":65710029}],"con":true,"img":false}]}
{"op":"mcm","clk":"11541467719","pt":1719506061819,"mc":[{"id":"1.230178326","rc":[{"atb":[[2.7,0]],"id":58221357},{"atb":[[2.38,0]],"id":60748118},{"atb":[[2.74,0]],"id":68687941},{"atb":[[2.38,0]],"id":67674431},{"atb":[[2.92,0]],"id":65710029}],"con":true,"img":false}]}
{"op":"mcm","clk":"11541467753","pt":1719506062130,"mc":[{"id":"1.230178326","rc":[{"atl":[[7.6,5.8]],"id":65710029}],"con":true,"img":false}]}
{"op":"mcm","clk":"11541467763","pt":1719506062183,"mc":[{"id":"1.230178326","rc":[{"atb":[[4.6,2.22]],"id":65710029}],"con":true,"img":false}]}
{"op":"mcm","clk":"11541467785","pt":1719506062391,"mc":[{"id":"1.230178326","rc":[{"atl":[[8.8,0.09]],"id":62600242},{"atl":[[7.4,0.79]],"id":65710029}],"con":true,"img":false}]}
{"op":"mcm","clk":"11541467818","pt":1719506062704,"mc":[{"id":"1.230178326","rc":[{"atl":[[1000,0.3]],"id":62600242}],"con":true,"img":false}]}
{"op":"mcm","clk":"11541467835","pt":1719506062910,"mc":[{"id":"1.230178326","rc":[{"atl":[[1000,0.16]],"id":62600242},{"atb":[[4.6,9.15]],"id":65710029},{"atl":[[7.4,4.21]],"id":65710029}],"con":true,"img":false}]}
{"op":"mcm","clk":"11541467843","pt":1719506063013,"mc":[{"id":"1.230178326","rc":[{"atl":[[8.2,0.14]],"id":62600242}],"con":true,"img":false}]}
{"op":"mcm","clk":"11541467857","pt":1719506063118,"mc":[{"id":"1.230178326","rc":[{"atb":[[4.5,6.72]],"id":65710029},{"atl":[[7.4,3.87]],"id":65710029}],"con":true,"img":false}]}
{"op":"mcm","clk":"11541467883","pt":1719506063327,"mc":[{"id":"1.230178326","rc":[{"atb":[[3.1,3.81],[4.7,1]],"id":65710029}],"con":true,"img":false}]}
{"op":"mcm","clk":"11541467893","pt":1719506063432,"mc":[{"id":"1.230178326","rc":[{"atb":[[4.7,2.88]],"id":65710029},{"atl":[[7.2,0.84]],"id":65710029}],"con":true,"img":false}]}
{"op":"mcm","clk":"11541467940","pt":1719506063897,"mc":[{"id":"1.230178326","rc":[{"atl":[[7.2,4.89]],"id":65710029}],"con":true,"img":false}]}
{"op":"mcm","clk":"11541467954","pt":1719506064002,"mc":[{"id":"1.230178326","rc":[{"atl":[[7.4,5.23]],"id":65710029}],"con":true,"img":false}]}
