{"op":"mcm","clk":"11547086385","pt":1719432856305,"mc":[{"id":"1.230178172","marketDefinition":{"bspMarket":false,"turnInPlayEnabled":false,"persistenceEnabled":false,"marketBaseRate":5.0,"eventId":"33376048","eventTypeId":"4339","numberOfWinners":1,"bettingType":"ODDS","marketType":"FORECAST","marketTime":"2024-06-27T15:22:00.000Z","suspendTime":"2024-06-27T15:22:00.000Z","bspReconciled":false,"complete":true,"inPlay":false,"crossMatching":false,"runnersVoidable":false,"numberOfActiveRunners":30,"betDelay":0,"status":"OPEN","runners":[{"status":"ACTIVE","sortPriority":1,"id":52385882,"name":"1 - 2"},{"status":"ACTIVE","sortPriority":2,"id":52385883,"name":"1 - 3"},{"status":"ACTIVE","sortPriority":3,"id":52385884,"name":"1 - 4"},{"status":"ACTIVE","sortPriority":4,"id":52385885,"name":"1 - 5"},{"status":"ACTIVE","sortPriority":5,"id":52385886,"name":"1 - 6"},{"status":"ACTIVE","sortPriority":6,"id":52385889,"name":"2 - 1"},{"status":"ACTIVE","sortPriority":7,"id":52385890,"name":"2 - 3"},{"status":"ACTIVE","sortPriority":8,"id":52385891,"name":"2 - 4"},{"status":"ACTIVE","sortPriority":9,"id":52385892,"name":"2 - 5"},{"status":"ACTIVE","sortPriority":10,"id":52385893,"name":"2 - 6"},{"status":"ACTIVE","sortPriority":11,"id":52385896,"name":"3 - 1"},{"status":"ACTIVE","sortPriority":12,"id":52385897,"name":"3 - 2"},{"status":"ACTIVE","sortPriority":13,"id":52385898,"name":"3 - 4"},{"status":"ACTIVE","sortPriority":14,"id":52385899,"name":"3 - 5"},{"status":"ACTIVE","sortPriority":15,"id":52385900,"name":"3 - 6"},{"status":"ACTIVE","sortPriority":16,"id":52385903,"name":"4 - 1"},{"status":"ACTIVE","sortPriority":17,"id":52385904,"name":"4 - 2"},{"status":"ACTIVE","sortPriority":18,"id":52385905,"name":"4 - 3"},{"status":"ACTIVE","sortPriority":19,"id":52385906,"name":"4 - 5"},{"status":"ACTIVE","sortPriority":20,"id":52385907,"name":"4 - 6"},{"status":"ACTIVE","sortPriority":21,"id":52385910,"name":"5 - 1"},{"status":"ACTIVE","sortPriority":22,"id":52385911,"name":"5 - 2"},{"status":"ACTIVE","sortPriority":23,"id":52385912,"name":"5 - 3"},{"status":"ACTIVE","sortPriority":24,"id":52385913,"name":"5 - 4"},{"status":"ACTIVE","sortPriority":25,"id":52385914,"name":"5 - 6"},{"status":"ACTIVE","sortPriority":26,"id":52385917,"name":"6 - 1"},{"status":"ACTIVE","sortPriority":27,"id":52385918,"name":"6 - 2"},{"status":"ACTIVE","sortPriority":28,"id":52385919,"name":"6 - 3"},{"status":"ACTIVE","sortPriority":29,"id":52385920,"name":"6 - 4"},{"status":"ACTIVE","sortPriority":30,"id":52385921,"name":"6 - 5"}],"regulators":["MR_INT"],"venue":"Perry Barr","countryCode":"GB","discountAllowed":false,"timezone":"Europe/London","openDate":"2024-06-27T13:29:00.000Z","version":5994794122,"name":"Forecast","eventName":"Perry Barr (F/C) 27th Jun"},"rc":[],"con":true,"img":false}]}
{"op":"mcm","clk":"11547086546","pt":1719432858317,"mc":[{"id":"1.230178172","marketDefinition":{"bspMarket":false,"turnInPlayEnabled":false,"persistenceEnabled":false,"marketBaseRate":5.0,"eventId":"33376048","eventTypeId":"4339","numberOfWinners":1,"bettingType":"ODDS","marketType":"FORECAST","marketTime":"2024-06-27T15:22:00.000Z","suspendTime":"2024-06-27T15:22:00.000Z","bspReconciled":false,"complete":true,"inPlay":false,"crossMatching":false,"runnersVoidable":false,"numberOfActiveRunners":30,"betDelay":0,"status":"OPEN","runners":[{"status":"ACTIVE","sortPriority":1,"id":52385882,"name":"1 - 2"},{"status":"ACTIVE","sortPriority":2,"id":52385883,"name":"1 - 3"},{"status":"ACTIVE","sortPriority":3,"id":52385884,"name":"1 - 4"},{"status":"ACTIVE","sortPriority":4,"id":52385885,"name":"1 - 5"},{"status":"ACTIVE","sortPriority":5,"id":52385886,"name":"1 - 6"},{"status":"ACTIVE","sortPriority":6,"id":52385889,"name":"2 - 1"},{"status":"ACTIVE","sortPriority":7,"id":52385890,"name":"2 - 3"},{"status":"ACTIVE","sortPriority":8,"id":52385891,"name":"2 - 4"},{"status":"ACTIVE","sortPriority":9,"id":52385892,"name":"2 - 5"},{"status":"ACTIVE","sortPriority":10,"id":52385893,"name":"2 - 6"},{"status":"ACTIVE","sortPriority":11,"id":52385896,"name":"3 - 1"},{"status":"ACTIVE","sortPriority":12,"id":52385897,"name":"3 - 2"},{"status":"ACTIVE","sortPriority":13,"id":52385898,"name":"3 - 4"},{"status":"ACTIVE","sortPriority":14,"id":52385899,"name":"3 - 5"},{"status":"ACTIVE","sortPriority":15,"id":52385900,"name":"3 - 6"},{"status":"ACTIVE","sortPriority":16,"id":52385903,"name":"4 - 1"},{"status":"ACTIVE","sortPriority":17,"id":52385904,"name":"4 - 2"},{"status":"ACTIVE","sortPriority":18,"id":52385905,"name":"4 - 3"},{"status":"ACTIVE","sortPriority":19,"id":52385906,"name":"4 - 5"},{"status":"ACTIVE","sortPriority":20,"id":52385907,"name":"4 - 6"},{"status":"ACTIVE","sortPriority":21,"id":52385910,"name":"5 - 1"},{"status":"ACTIVE","sortPriority":22,"id":52385911,"name":"5 - 2"},{"status":"ACTIVE","sortPriority":23,"id":52385912,"name":"5 - 3"},{"status":"ACTIVE","sortPriority":24,"id":52385913,"name":"5 - 4"},{"status":"ACTIVE","sortPriority":25,"id":52385914,"name":"5 - 6"},{"status":"ACTIVE","sortPriority":26,"id":52385917,"name":"6 - 1"},{"status":"ACTIVE","sortPriority":27,"id":52385918,"name":"6 - 2"},{"status":"ACTIVE","sortPriority":28,"id":52385919,"name":"6 - 3"},{"status":"ACTIVE","sortPriority":29,"id":52385920,"name":"6 - 4"},{"status":"ACTIVE","sortPriority":30,"id":52385921,"name":"6 - 5"}],"regulators":["MR_INT"],"venue":"Perry Barr","countryCode":"GB","discountAllowed":true,"timezone":"Europe/London","openDate":"2024-06-27T13:29:00.000Z","version":5994794122,"name":"Forecast","eventName":"Perry Barr (F/C) 27th Jun"},"rc":[],"con":true,"img":false}]}
{"op":"mcm","clk":"11547344199","pt":1719439055392,"mc":[{"id":"1.230178172","rc":[{"atb":[[1.02,8.9]],"id":52385910},{"atb":[[1.01,17.8]],"id":52385912},{"atb":[[1.03,5.93]],"id":52385906},{"atb":[[1.02,8.9]],"id":52385918},{"atb":[[1.03,5.93]],"id":52385920},{"atb":[[1.02,8.9]],"id":52385889},{"atb":[[1.01,17.8]],"id":52385914},{"atb":[[1.03,5.93]],"id":52385883},{"atb":[[1.03,5.93]],"id":52385885},{"atb":[[1.02,8.9]],"id":52385896},{"atb":[[1.01,17.8]],"id":52385890},{"atb":[[1.02,8.9]],"id":52385892},{"atb":[[1.03,5.93]],"id":52385904},{"atb":[[1.03,5.93]],"id":52385898},{"atb":[[1.02,8.9]],"id":52385900},{"atb":[[1.03,5.93]],"id":52385911},{"atb":[[1.02,8.9]],"id":52385913},{"atb":[[1.03,5.93]],"id":52385907},{"atb":[[1.01,17.8]],"id":52385886},{"atb":[[1.02,8.9]],"id":52385919},{"atb":[[1.01,17.8]],"id":52385921},{"atb":[[1.02,8.9]],"id":52385882},{"atb":[[1.02,8.9]],"id":52385884},{"atb":[[1.01,17.8]],"id":52385917},{"atb":[[1.03,5.93]],"id":52385897},{"atb":[[1.01,17.8]],"id":52385891},{"atb":[[1.02,8.9]],"id":52385893},{"atb":[[1.03,5.93]],"id":52385903},{"atb":[[1.03,5.93]],"id":52385905},{"atb":[[1.01,17.8]],"id":52385899}],"con":true,"img":false}]}
{"op":"mcm","clk":"11547371017","pt":1719439682593,"mc":[{"id":"1.230178172","marketDefinition":{"bspMarket":false,"turnInPlayEnabled":false,"persistenceEnabled":false,"marketBaseRate":5.0,"eventId":"33376048","eventTypeId":"4339","numberOfWinners":1,"bettingType":"ODDS","marketType":"FORECAST","marketTime":"2024-06-27T15:22:00.000Z","suspendTime":"2024-06-27T15:22:00.000Z","bspReconciled":false,"complete":true,"inPlay":false,"crossMatching":false,"runnersVoidable":false,"numberOfActiveRunners":30,"betDelay":0,"status":"OPEN","runners":[{"status":"ACTIVE","sortPriority":1,"id":52385882,"name":"1 - 2"},{"status":"ACTIVE","sortPriority":2,"id":52385883,"name":"1 - 3"},{"status":"ACTIVE","sortPriority":3,"id":52385884,"name":"1 - 4"},{"status":"ACTIVE","sortPriority":4,"id":52385885,"name":"1 - 5"},{"status":"ACTIVE","sortPriority":5,"id":52385886,"name":"1 - 6"},{"status":"ACTIVE","sortPriority":6,"id":52385889,"name":"2 - 1"},{"status":"ACTIVE","sortPriority":7,"id":52385890,"name":"2 - 3"},{"status":"ACTIVE","sortPriority":8,"id":52385891,"name":"2 - 4"},{"status":"ACTIVE","sortPriority":9,"id":52385892,"name":"2 - 5"},{"status":"ACTIVE","sortPriority":10,"id":52385893,"name":"2 - 6"},{"status":"ACTIVE","sortPriority":11,"id":52385896,"name":"3 - 1"},{"status":"ACTIVE","sortPriority":12,"id":52385897,"name":"3 - 2"},{"status":"ACTIVE","sortPriority":13,"id":52385898,"name":"3 - 4"},{"status":"ACTIVE","sortPriority":14,"id":52385899,"name":"3 - 5"},{"status":"ACTIVE","sortPriority":15,"id":52385900,"name":"3 - 6"},{"status":"ACTIVE","sortPriority":16,"id":52385903,"name":"4 - 1"},{"status":"ACTIVE","sortPriority":17,"id":52385904,"name":"4 - 2"},{"status":"ACTIVE","sortPriority":18,"id":52385905,"name":"4 - 3"},{"status":"ACTIVE","sortPriority":19,"id":52385906,"name":"4 - 5"},{"status":"ACTIVE","sortPriority":20,"id":52385907,"name":"4 - 6"},{"status":"ACTIVE","sortPriority":21,"id":52385910,"name":"5 - 1"},{"status":"ACTIVE","sortPriority":22,"id":52385911,"name":"5 - 2"},{"status":"ACTIVE","sortPriority":23,"id":52385912,"name":"5 - 3"},{"status":"ACTIVE","sortPriority":24,"id":52385913,"name":"5 - 4"},{"status":"ACTIVE","sortPriority":25,"id":52385914,"name":"5 - 6"},{"status":"ACTIVE","sortPriority":26,"id":52385917,"name":"6 - 1"},{"status":"ACTIVE","sortPriority":27,"id":52385918,"name":"6 - 2"},{"status":"ACTIVE","sortPriority":28,"id":52385919,"name":"6 - 3"},{"status":"ACTIVE","sortPriority":29,"id":52385920,"name":"6 - 4"},{"status":"ACTIVE","sortPriority":30,"id":52385921,"name":"6 - 5"}],"regulators":["MR_INT"],"venue":"Perry Barr","countryCode":"GB","discountAllowed":true,"timezone":"Europe/London","openDate":"2024-06-27T13:29:00.000Z","version":5994794122,"name":"Forecast","eventName":"Perry Barr (F/C) 27th Jun"},"rc":[{"atb":[[1.02,8.9]],"id":52385910},{"atb":[[1.01,17.8]],"id":52385912},{"atb":[[1.03,5.93]],"id":52385906},{"atb":[[1.02,8.9]],"id":52385918},{"atb":[[1.03,5.93]],"id":52385920},{"atb":[[1.02,8.9]],"id":52385889},{"atb":[[1.01,17.8]],"id":52385914},{"atb":[[1.03,5.93]],"id":52385883},{"atb":[[1.03,5.93]],"id":52385885},{"atb":[[1.02,8.9]],"id":52385896},{"atb":[[1.01,17.8]],"id":52385890},{"atb":[[1.02,8.9]],"id":52385892},{"atb":[[1.03,5.93]],"id":52385904},{"atb":[[1.03,5.93]],"id":52385898},{"atb":[[1.02,8.9]],"id":52385900},{"atb":[[1.03,5.93]],"id":52385911},{"atb":[[1.02,8.9]],"id":52385913},{"atb":[[1.03,5.93]],"id":52385907},{"atb":[[1.01,17.8]],"id":52385886},{"atb":[[1.02,8.9]],"id":52385919},{"atb":[[1.01,17.8]],"id":52385921},{"atb":[[1.02,8.9]],"id":52385882},{"atb":[[1.02,8.9]],"id":52385884},{"atb":[[1.01,17.8]],"id":52385917},{"atb":[[1.03,5.93]],"id":52385897},{"atb":[[1.01,17.8]],"id":52385891},{"atb":[[1.02,8.9]],"id":52385893},{"atb":[[1.03,5.93]],"id":52385903},{"atb":[[1.03,5.93]],"id":52385905},{"atb":[[1.01,17.8]],"id":52385899}],"con":true,"img":true}]}
{"op":"mcm","clk":"11547659685","pt":1719445082619,"mc":[{"id":"1.230178172","marketDefinition":{"bspMarket":false,"turnInPlayEnabled":false,"persistenceEnabled":false,"marketBaseRate":5.0,"eventId":"33376048","eventTypeId":"4339","numberOfWinners":1,"bettingType":"ODDS","marketType":"FORECAST","marketTime":"2024-06-27T15:22:00.000Z","suspendTime":"2024-06-27T15:22:00.000Z","bspReconciled":false,"complete":true,"inPlay":false,"crossMatching":false,"runnersVoidable":false,"numberOfActiveRunners":30,"betDelay":0,"status":"OPEN","runners":[{"status":"ACTIVE","sortPriority":1,"id":52385882,"name":"1 - 2"},{"status":"ACTIVE","sortPriority":2,"id":52385883,"name":"1 - 3"},{"status":"ACTIVE","sortPriority":3,"id":52385884,"name":"1 - 4"},{"status":"ACTIVE","sortPriority":4,"id":52385885,"name":"1 - 5"},{"status":"ACTIVE","sortPriority":5,"id":52385886,"name":"1 - 6"},{"status":"ACTIVE","sortPriority":6,"id":52385889,"name":"2 - 1"},{"status":"ACTIVE","sortPriority":7,"id":52385890,"name":"2 - 3"},{"status":"ACTIVE","sortPriority":8,"id":52385891,"name":"2 - 4"},{"status":"ACTIVE","sortPriority":9,"id":52385892,"name":"2 - 5"},{"status":"ACTIVE","sortPriority":10,"id":52385893,"name":"2 - 6"},{"status":"ACTIVE","sortPriority":11,"id":52385896,"name":"3 - 1"},{"status":"ACTIVE","sortPriority":12,"id":52385897,"name":"3 - 2"},{"status":"ACTIVE","sortPriority":13,"id":52385898,"name":"3 - 4"},{"status":"ACTIVE","sortPriority":14,"id":52385899,"name":"3 - 5"},{"status":"ACTIVE","sortPriority":15,"id":52385900,"name":"3 - 6"},{"status":"ACTIVE","sortPriority":16,"id":52385903,"name":"4 - 1"},{"status":"ACTIVE","sortPriority":17,"id":52385904,"name":"4 - 2"},{"status":"ACTIVE","sortPriority":18,"id":52385905,"name":"4 - 3"},{"status":"ACTIVE","sortPriority":19,"id":52385906,"name":"4 - 5"},{"status":"ACTIVE","sortPriority":20,"id":52385907,"name":"4 - 6"},{"status":"ACTIVE","sortPriority":21,"id":52385910,"name":"5 - 1"},{"status":"ACTIVE","sortPriority":22,"id":52385911,"name":"5 - 2"},{"status":"ACTIVE","sortPriority":23,"id":52385912,"name":"5 - 3"},{"status":"ACTIVE","sortPriority":24,"id":52385913,"name":"5 - 4"},{"status":"ACTIVE","sortPriority":25,"id":52385914,"name":"5 - 6"},{"status":"ACTIVE","sortPriority":26,"id":52385917,"name":"6 - 1"},{"status":"ACTIVE","sortPriority":27,"id":52385918,"name":"6 - 2"},{"status":"ACTIVE","sortPriority":28,"id":52385919,"name":"6 - 3"},{"status":"ACTIVE","sortPriority":29,"id":52385920,"name":"6 - 4"},{"status":"ACTIVE","sortPriority":30,"id":52385921,"name":"6 - 5"}],"regulators":["MR_INT"],"venue":"Perry Barr","countryCode":"GB","discountAllowed":true,"timezone":"Europe/London","openDate":"2024-06-27T13:29:00.000Z","version":5994794122,"name":"Forecast","eventName":"Perry Barr (F/C) 27th Jun"},"rc":[{"atb":[[1.02,8.9]],"id":52385910},{"atb":[[1.01,17.8]],"id":52385912},{"atb":[[1.03,5.93]],"id":52385906},{"atb":[[1.02,8.9]],"id":52385918},{"atb":[[1.03,5.93]],"id":52385920},{"atb":[[1.02,8.9]],"id":52385889},{"atb":[[1.01,17.8]],"id":52385914},{"atb":[[1.03,5.93]],"id":52385883},{"atb":[[1.03,5.93]],"id":52385885},{"atb":[[1.02,8.9]],"id":52385896},{"atb":[[1.01,17.8]],"id":52385890},{"atb":[[1.02,8.9]],"id":52385892},{"atb":[[1.03,5.93]],"id":52385904},{"atb":[[1.03,5.93]],"id":52385898},{"atb":[[1.02,8.9]],"id":52385900},{"atb":[[1.03,5.93]],"id":52385911},{"atb":[[1.02,8.9]],"id":52385913},{"atb":[[1.03,5.93]],"id":52385907},{"atb":[[1.01,17.8]],"id":52385886},{"atb":[[1.02,8.9]],"id":52385919},{"atb":[[1.01,17.8]],"id":52385921},{"atb":[[1.02,8.9]],"id":52385882},{"atb":[[1.02,8.9]],"id":52385884},{"atb":[[1.01,17.8]],"id":52385917},{"atb":[[1.03,5.93]],"id":52385897},{"atb":[[1.01,17.8]],"id":52385891},{"atb":[[1.02,8.9]],"id":52385893},{"atb":[[1.03,5.93]],"id":52385903},{"atb":[[1.03,5.93]],"id":52385905},{"atb":[[1.01,17.8]],"id":52385899}],"con":true,"img":true}]}
{"op":"mcm","clk":"11548031729","pt":1719450482634,"mc":[{"id":"1.230178172","marketDefinition":{"bspMarket":false,"turnInPlayEnabled":false,"persistenceEnabled":false,"marketBaseRate":5.0,"eventId":"33376048","eventTypeId":"4339","numberOfWinners":1,"bettingType":"ODDS","marketType":"FORECAST","marketTime":"2024-06-27T15:22:00.000Z","suspendTime":"2024-06-27T15:22:00.000Z","bspReconciled":false,"complete":true,"inPlay":false,"crossMatching":false,"runnersVoidable":false,"numberOfActiveRunners":30,"betDelay":0,"status":"OPEN","runners":[{"status":"ACTIVE","sortPriority":1,"id":52385882,"name":"1 - 2"},{"status":"ACTIVE","sortPriority":2,"id":52385883,"name":"1 - 3"},{"status":"ACTIVE","sortPriority":3,"id":52385884,"name":"1 - 4"},{"status":"ACTIVE","sortPriority":4,"id":52385885,"name":"1 - 5"},{"status":"ACTIVE","sortPriority":5,"id":52385886,"name":"1 - 6"},{"status":"ACTIVE","sortPriority":6,"id":52385889,"name":"2 - 1"},{"status":"ACTIVE","sortPriority":7,"id":52385890,"name":"2 - 3"},{"status":"ACTIVE","sortPriority":8,"id":52385891,"name":"2 - 4"},{"status":"ACTIVE","sortPriority":9,"id":52385892,"name":"2 - 5"},{"status":"ACTIVE","sortPriority":10,"id":52385893,"name":"2 - 6"},{"status":"ACTIVE","sortPriority":11,"id":52385896,"name":"3 - 1"},{"status":"ACTIVE","sortPriority":12,"id":52385897,"name":"3 - 2"},{"status":"ACTIVE","sortPriority":13,"id":52385898,"name":"3 - 4"},{"status":"ACTIVE","sortPriority":14,"id":52385899,"name":"3 - 5"},{"status":"ACTIVE","sortPriority":15,"id":52385900,"name":"3 - 6"},{"status":"ACTIVE","sortPriority":16,"id":52385903,"name":"4 - 1"},{"status":"ACTIVE","sortPriority":17,"id":52385904,"name":"4 - 2"},{"status":"ACTIVE","sortPriority":18,"id":52385905,"name":"4 - 3"},{"status":"ACTIVE","sortPriority":19,"id":52385906,"name":"4 - 5"},{"status":"ACTIVE","sortPriority":20,"id":52385907,"name":"4 - 6"},{"status":"ACTIVE","sortPriority":21,"id":52385910,"name":"5 - 1"},{"status":"ACTIVE","sortPriority":22,"id":52385911,"name":"5 - 2"},{"status":"ACTIVE","sortPriority":23,"id":52385912,"name":"5 - 3"},{"status":"ACTIVE","sortPriority":24,"id":52385913,"name":"5 - 4"},{"status":"ACTIVE","sortPriority":25,"id":52385914,"name":"5 - 6"},{"status":"ACTIVE","sortPriority":26,"id":52385917,"name":"6 - 1"},{"status":"ACTIVE","sortPriority":27,"id":52385918,"name":"6 - 2"},{"status":"ACTIVE","sortPriority":28,"id":52385919,"name":"6 - 3"},{"status":"ACTIVE","sortPriority":29,"id":52385920,"name":"6 - 4"},{"status":"ACTIVE","sortPriority":30,"id":52385921,"name":"6 - 5"}],"regulators":["MR_INT"],"venue":"Perry Barr","countryCode":"GB","discountAllowed":true,"timezone":"Europe/London","openDate":"2024-06-27T13:29:00.000Z","version":5994794122,"name":"Forecast","eventName":"Perry Barr (F/C) 27th Jun"},"rc":[{"atb":[[1.02,8.9]],"id":52385910},{"atb":[[1.01,17.8]],"id":52385912},{"atb":[[1.03,5.93]],"id":52385906},{"atb":[[1.02,8.9]],"id":52385918},{"atb":[[1.03,5.93]],"id":52385920},{"atb":[[1.02,8.9]],"id":52385889},{"atb":[[1.01,17.8]],"id":52385914},{"atb":[[1.03,5.93]],"id":52385883},{"atb":[[1.03,5.93]],"id":52385885},{"atb":[[1.02,8.9]],"id":52385896},{"atb":[[1.01,17.8]],"id":52385890},{"atb":[[1.02,8.9]],"id":52385892},{"atb":[[1.03,5.93]],"id":52385904},{"atb":[[1.03,5.93]],"id":52385898},{"atb":[[1.02,8.9]],"id":52385900},{"atb":[[1.03,5.93]],"id":52385911},{"atb":[[1.02,8.9]],"id":52385913},{"atb":[[1.03,5.93]],"id":52385907},{"atb":[[1.01,17.8]],"id":52385886},{"atb":[[1.02,8.9]],"id":52385919},{"atb":[[1.01,17.8]],"id":52385921},{"atb":[[1.02,8.9]],"id":52385882},{"atb":[[1.02,8.9]],"id":52385884},{"atb":[[1.01,17.8]],"id":52385917},{"atb":[[1.03,5.93]],"id":52385897},{"atb":[[1.01,17.8]],"id":52385891},{"atb":[[1.02,8.9]],"id":52385893},{"atb":[[1.03,5.93]],"id":52385903},{"atb":[[1.03,5.93]],"id":52385905},{"atb":[[1.01,17.8]],"id":52385899}],"con":true,"img":true}]}
{"op":"mcm","clk":"11548270793","pt":1719455882654,"mc":[{"id":"1.230178172","marketDefinition":{"bspMarket":false,"turnInPlayEnabled":false,"persistenceEnabled":false,"marketBaseRate":5.0,"eventId":"33376048","eventTypeId":"4339","numberOfWinners":1,"bettingType":"ODDS","marketType":"FORECAST","marketTime":"2024-06-27T15:22:00.000Z","suspendTime":"2024-06-27T15:22:00.000Z","bspReconciled":false,"complete":true,"inPlay":false,"crossMatching":false,"runnersVoidable":false,"numberOfActiveRunners":30,"betDelay":0,"status":"OPEN","runners":[{"status":"ACTIVE","sortPriority":1,"id":52385882,"name":"1 - 2"},{"status":"ACTIVE","sortPriority":2,"id":52385883,"name":"1 - 3"},{"status":"ACTIVE","sortPriority":3,"id":52385884,"name":"1 - 4"},{"status":"ACTIVE","sortPriority":4,"id":52385885,"name":"1 - 5"},{"status":"ACTIVE","sortPriority":5,"id":52385886,"name":"1 - 6"},{"status":"ACTIVE","sortPriority":6,"id":52385889,"name":"2 - 1"},{"status":"ACTIVE","sortPriority":7,"id":52385890,"name":"2 - 3"},{"status":"ACTIVE","sortPriority":8,"id":52385891,"name":"2 - 4"},{"status":"ACTIVE","sortPriority":9,"id":52385892,"name":"2 - 5"},{"status":"ACTIVE","sortPriority":10,"id":52385893,"name":"2 - 6"},{"status":"ACTIVE","sortPriority":11,"id":52385896,"name":"3 - 1"},{"status":"ACTIVE","sortPriority":12,"id":52385897,"name":"3 - 2"},{"status":"ACTIVE","sortPriority":13,"id":52385898,"name":"3 - 4"},{"status":"ACTIVE","sortPriority":14,"id":52385899,"name":"3 - 5"},{"status":"ACTIVE","sortPriority":15,"id":52385900,"name":"3 - 6"},{"status":"ACTIVE","sortPriority":16,"id":52385903,"name":"4 - 1"},{"status":"ACTIVE","sortPriority":17,"id":52385904,"name":"4 - 2"},{"status":"ACTIVE","sortPriority":18,"id":52385905,"name":"4 - 3"},{"status":"ACTIVE","sortPriority":19,"id":52385906,"name":"4 - 5"},{"status":"ACTIVE","sortPriority":20,"id":52385907,"name":"4 - 6"},{"status":"ACTIVE","sortPriority":21,"id":52385910,"name":"5 - 1"},{"status":"ACTIVE","sortPriority":22,"id":52385911,"name":"5 - 2"},{"status":"ACTIVE","sortPriority":23,"id":52385912,"name":"5 - 3"},{"status":"ACTIVE","sortPriority":24,"id":52385913,"name":"5 - 4"},{"status":"ACTIVE","sortPriority":25,"id":52385914,"name":"5 - 6"},{"status":"ACTIVE","sortPriority":26,"id":52385917,"name":"6 - 1"},{"status":"ACTIVE","sortPriority":27,"id":52385918,"name":"6 - 2"},{"status":"ACTIVE","sortPriority":28,"id":52385919,"name":"6 - 3"},{"status":"ACTIVE","sortPriority":29,"id":52385920,"name":"6 - 4"},{"status":"ACTIVE","sortPriority":30,"id":52385921,"name":"6 - 5"}],"regulators":["MR_INT"],"venue":"Perry Barr","countryCode":"GB","discountAllowed":true,"timezone":"Europe/London","openDate":"2024-06-27T13:29:00.000Z","version":5994794122,"name":"Forecast","eventName":"Perry Barr (F/C) 27th Jun"},"rc":[{"atb":[[1.02,8.9]],"id":52385910},{"atb":[[1.01,17.8]],"id":52385912},{"atb":[[1.03,5.93]],"id":52385906},{"atb":[[1.02,8.9]],"id":52385918},{"atb":[[1.03,5.93]],"id":52385920},{"atb":[[1.02,8.9]],"id":52385889},{"atb":[[1.01,17.8]],"id":52385914},{"atb":[[1.03,5.93]],"id":52385883},{"atb":[[1.03,5.93]],"id":52385885},{"atb":[[1.02,8.9]],"id":52385896},{"atb":[[1.01,17.8]],"id":52385890},{"atb":[[1.02,8.9]],"id":52385892},{"atb":[[1.03,5.93]],"id":52385904},{"atb":[[1.03,5.93]],"id":52385898},{"atb":[[1.02,8.9]],"id":52385900},{"atb":[[1.03,5.93]],"id":52385911},{"atb":[[1.02,8.9]],"id":52385913},{"atb":[[1.03,5.93]],"id":52385907},{"atb":[[1.01,17.8]],"id":52385886},{"atb":[[1.02,8.9]],"id":52385919},{"atb":[[1.01,17.8]],"id":52385921},{"atb":[[1.02,8.9]],"id":52385882},{"atb":[[1.02,8.9]],"id":52385884},{"atb":[[1.01,17.8]],"id":52385917},{"atb":[[1.03,5.93]],"id":52385897},{"atb":[[1.01,17.8]],"id":52385891},{"atb":[[1.02,8.9]],"id":52385893},{"atb":[[1.03,5.93]],"id":52385903},{"atb":[[1.03,5.93]],"id":52385905},{"atb":[[1.01,17.8]],"id":52385899}],"con":true,"img":true}]}
{"op":"mcm","clk":"11548413886","pt":1719460892413,"mc":[{"id":"1.230178172","rc":[{"atb":[[1.16,100],[1.02,8.9]],"id":52385910},{"atb":[[1.01,17.8],[1.16,100]],"id":52385912},{"atb":[[1.03,5.93],[1.16,100]],"id":52385906},{"atb":[[1.16,100],[1.02,8.9]],"id":52385918},{"atb":[[1.03,5.93],[1.16,100]],"id":52385920},{"atb":[[1.16,100],[1.02,8.9]],"id":52385889},{"atb":[[1.01,17.8],[1.16,100]],"id":52385914},{"atb":[[1.03,5.93],[1.16,100]],"id":52385883},{"atb":[[1.03,5.93],[1.16,100]],"id":52385885},{"atb":[[1.16,100],[1.02,8.9]],"id":52385896},{"atb":[[1.01,17.8],[1.16,100]],"id":52385890},{"atb":[[1.16,100],[1.02,8.9]],"id":52385892},{"atb":[[1.03,5.93],[1.16,100]],"id":52385904},{"atb":[[1.03,5.93],[1.16,100]],"id":52385898},{"atb":[[1.16,100],[1.02,8.9]],"id":52385900},{"atb":[[1.03,5.93],[1.16,100]],"id":52385911},{"atb":[[1.16,100],[1.02,8.9]],"id":52385913},{"atb":[[1.03,5.93],[1.16,100]],"id":52385907},{"atb":[[1.01,17.8],[1.16,100]],"id":52385886},{"atb":[[1.16,100],[1.02,8.9]],"id":52385919},{"atb":[[1.01,17.8],[1.16,100]],"id":52385921},{"atb":[[1.16,100],[1.02,8.9]],"id":52385882},{"atb":[[1.16,100],[1.02,8.9]],"id":52385884},{"atb":[[1.01,17.8],[1.16,100]],"id":52385917},{"atb":[[1.03,5.93],[1.16,100]],"id":52385897},{"atb":[[1.01,17.8],[1.16,100]],"id":52385891},{"atb":[[1.16,100],[1.02,8.9]],"id":52385893},{"atb":[[1.03,5.93],[1.16,100]],"id":52385903},{"atb":[[1.03,5.93],[1.16,100]],"id":52385905},{"atb":[[1.01,17.8],[1.16,100]],"id":52385899}],"con":true,"img":false}]}
{"op":"mcm","clk":"11548535729","pt":1719466682820,"mc":[{"id":"1.230178172","marketDefinition":{"bspMarket":false,"turnInPlayEnabled":false,"persistenceEnabled":false,"marketBaseRate":5.0,"eventId":"33376048","eventTypeId":"4339","numberOfWinners":1,"bettingType":"ODDS","marketType":"FORECAST","marketTime":"2024-06-27T15:22:00.000Z","suspendTime":"2024-06-27T15:22:00.000Z","bspReconciled":false,"complete":true,"inPlay":false,"crossMatching":false,"runnersVoidable":false,"numberOfActiveRunners":30,"betDelay":0,"status":"OPEN","runners":[{"status":"ACTIVE","sortPriority":1,"id":52385882,"name":"1 - 2"},{"status":"ACTIVE","sortPriority":2,"id":52385883,"name":"1 - 3"},{"status":"ACTIVE","sortPriority":3,"id":52385884,"name":"1 - 4"},{"status":"ACTIVE","sortPriority":4,"id":52385885,"name":"1 - 5"},{"status":"ACTIVE","sortPriority":5,"id":52385886,"name":"1 - 6"},{"status":"ACTIVE","sortPriority":6,"id":52385889,"name":"2 - 1"},{"status":"ACTIVE","sortPriority":7,"id":52385890,"name":"2 - 3"},{"status":"ACTIVE","sortPriority":8,"id":52385891,"name":"2 - 4"},{"status":"ACTIVE","sortPriority":9,"id":52385892,"name":"2 - 5"},{"status":"ACTIVE","sortPriority":10,"id":52385893,"name":"2 - 6"},{"status":"ACTIVE","sortPriority":11,"id":52385896,"name":"3 - 1"},{"status":"ACTIVE","sortPriority":12,"id":52385897,"name":"3 - 2"},{"status":"ACTIVE","sortPriority":13,"id":52385898,"name":"3 - 4"},{"status":"ACTIVE","sortPriority":14,"id":52385899,"name":"3 - 5"},{"status":"ACTIVE","sortPriority":15,"id":52385900,"name":"3 - 6"},{"status":"ACTIVE","sortPriority":16,"id":52385903,"name":"4 - 1"},{"status":"ACTIVE","sortPriority":17,"id":52385904,"name":"4 - 2"},{"status":"ACTIVE","sortPriority":18,"id":52385905,"name":"4 - 3"},{"status":"ACTIVE","sortPriority":19,"id":52385906,"name":"4 - 5"},{"status":"ACTIVE","sortPriority":20,"id":52385907,"name":"4 - 6"},{"status":"ACTIVE","sortPriority":21,"id":52385910,"name":"5 - 1"},{"status":"ACTIVE","sortPriority":22,"id":52385911,"name":"5 - 2"},{"status":"ACTIVE","sortPriority":23,"id":52385912,"name":"5 - 3"},{"status":"ACTIVE","sortPriority":24,"id":52385913,"name":"5 - 4"},{"status":"ACTIVE","sortPriority":25,"id":52385914,"name":"5 - 6"},{"status":"ACTIVE","sortPriority":26,"id":52385917,"name":"6 - 1"},{"status":"ACTIVE","sortPriority":27,"id":52385918,"name":"6 - 2"},{"status":"ACTIVE","sortPriority":28,"id":52385919,"name":"6 - 3"},{"status":"ACTIVE","sortPriority":29,"id":52385920,"name":"6 - 4"},{"status":"ACTIVE","sortPriority":30,"id":52385921,"name":"6 - 5"}],"regulators":["MR_INT"],"venue":"Perry Barr","countryCode":"GB","discountAllowed":true,"timezone":"Europe/London","openDate":"2024-06-27T13:29:00.000Z","version":5994794122,"name":"Forecast","eventName":"Perry Barr (F/C) 27th Jun"},"rc":[{"atb":[[1.16,100],[1.02,8.9]],"id":52385910},{"atb":[[1.01,17.8],[1.16,100]],"id":52385912},{"atb":[[1.16,100],[1.03,5.93]],"id":52385906},{"atb":[[1.16,100],[1.02,8.9]],"id":52385918},{"atb":[[1.16,100],[1.03,5.93]],"id":52385920},{"atb":[[1.16,100],[1.02,8.9]],"id":52385889},{"atb":[[1.01,17.8],[1.16,100]],"id":52385914},{"atb":[[1.16,100],[1.03,5.93]],"id":52385883},{"atb":[[1.16,100],[1.03,5.93]],"id":52385885},{"atb":[[1.16,100],[1.02,8.9]],"id":52385896},{"atb":[[1.01,17.8],[1.16,100]],"id":52385890},{"atb":[[1.16,100],[1.02,8.9]],"id":52385892},{"atb":[[1.16,100],[1.03,5.93]],"id":52385904},{"atb":[[1.16,100],[1.03,5.93]],"id":52385898},{"atb":[[1.16,100],[1.02,8.9]],"id":52385900},{"atb":[[1.16,100],[1.03,5.93]],"id":52385911},{"atb":[[1.16,100],[1.02,8.9]],"id":52385913},{"atb":[[1.16,100],[1.03,5.93]],"id":52385907},{"atb":[[1.01,17.8],[1.16,100]],"id":52385886},{"atb":[[1.16,100],[1.02,8.9]],"id":52385919},{"atb":[[1.01,17.8],[1.16,100]],"id":52385921},{"atb":[[1.16,100],[1.02,8.9]],"id":52385882},{"atb":[[1.16,100],[1.02,8.9]],"id":52385884},{"atb":[[1.01,17.8],[1.16,100]],"id":52385917},{"atb":[[1.16,100],[1.03,5.93]],"id":52385897},{"atb":[[1.01,17.8],[1.16,100]],"id":52385891},{"atb":[[1.16,100],[1.02,8.9]],"id":52385893},{"atb":[[1.16,100],[1.03,5.93]],"id":52385903},{"atb":[[1.16,100],[1.03,5.93]],"id":52385905},{"atb":[[1.01,17.8],[1.16,100]],"id":52385899}],"con":true,"img":true}]}
{"op":"mcm","clk":"11548656210","pt":1719472082591,"mc":[{"id":"1.230178172","marketDefinition":{"bspMarket":false,"turnInPlayEnabled":false,"persistenceEnabled":false,"marketBaseRate":5.0,"eventId":"33376048","eventTypeId":"4339","numberOfWinners":1,"bettingType":"ODDS","marketType":"FORECAST","marketTime":"2024-06-27T15:22:00.000Z","suspendTime":"2024-06-27T15:22:00.000Z","bspReconciled":false,"complete":true,"inPlay":false,"crossMatching":false,"runnersVoidable":false,"numberOfActiveRunners":30,"betDelay":0,"status":"OPEN","runners":[{"status":"ACTIVE","sortPriority":1,"id":52385882,"name":"1 - 2"},{"status":"ACTIVE","sortPriority":2,"id":52385883,"name":"1 - 3"},{"status":"ACTIVE","sortPriority":3,"id":52385884,"name":"1 - 4"},{"status":"ACTIVE","sortPriority":4,"id":52385885,"name":"1 - 5"},{"status":"ACTIVE","sortPriority":5,"id":52385886,"name":"1 - 6"},{"status":"ACTIVE","sortPriority":6,"id":52385889,"name":"2 - 1"},{"status":"ACTIVE","sortPriority":7,"id":52385890,"name":"2 - 3"},{"status":"ACTIVE","sortPriority":8,"id":52385891,"name":"2 - 4"},{"status":"ACTIVE","sortPriority":9,"id":52385892,"name":"2 - 5"},{"status":"ACTIVE","sortPriority":10,"id":52385893,"name":"2 - 6"},{"status":"ACTIVE","sortPriority":11,"id":52385896,"name":"3 - 1"},{"status":"ACTIVE","sortPriority":12,"id":52385897,"name":"3 - 2"},{"status":"ACTIVE","sortPriority":13,"id":52385898,"name":"3 - 4"},{"status":"ACTIVE","sortPriority":14,"id":52385899,"name":"3 - 5"},{"status":"ACTIVE","sortPriority":15,"id":52385900,"name":"3 - 6"},{"status":"ACTIVE","sortPriority":16,"id":52385903,"name":"4 - 1"},{"status":"ACTIVE","sortPriority":17,"id":52385904,"name":"4 - 2"},{"status":"ACTIVE","sortPriority":18,"id":52385905,"name":"4 - 3"},{"status":"ACTIVE","sortPriority":19,"id":52385906,"name":"4 - 5"},{"status":"ACTIVE","sortPriority":20,"id":52385907,"name":"4 - 6"},{"status":"ACTIVE","sortPriority":21,"id":52385910,"name":"5 - 1"},{"status":"ACTIVE","sortPriority":22,"id":52385911,"name":"5 - 2"},{"status":"ACTIVE","sortPriority":23,"id":52385912,"name":"5 - 3"},{"status":"ACTIVE","sortPriority":24,"id":52385913,"name":"5 - 4"},{"status":"ACTIVE","sortPriority":25,"id":52385914,"name":"5 - 6"},{"status":"ACTIVE","sortPriority":26,"id":52385917,"name":"6 - 1"},{"status":"ACTIVE","sortPriority":27,"id":52385918,"name":"6 - 2"},{"status":"ACTIVE","sortPriority":28,"id":52385919,"name":"6 - 3"},{"status":"ACTIVE","sortPriority":29,"id":52385920,"name":"6 - 4"},{"status":"ACTIVE","sortPriority":30,"id":52385921,"name":"6 - 5"}],"regulators":["MR_INT"],"venue":"Perry Barr","countryCode":"GB","discountAllowed":true,"timezone":"Europe/London","openDate":"2024-06-27T13:29:00.000Z","version":5994794122,"name":"Forecast","eventName":"Perry Barr (F/C) 27th Jun"},"rc":[{"atb":[[1.16,100],[1.02,8.89]],"id":52385910},{"atb":[[1.01,17.79],[1.16,100]],"id":52385912},{"atb":[[1.16,100],[1.03,5.92]],"id":52385906},{"atb":[[1.16,100],[1.02,8.89]],"id":52385918},{"atb":[[1.16,100],[1.03,5.92]],"id":52385920},{"atb":[[1.16,100],[1.02,8.89]],"id":52385889},{"atb":[[1.01,17.79],[1.16,100]],"id":52385914},{"atb":[[1.16,100],[1.03,5.92]],"id":52385883},{"atb":[[1.16,100],[1.03,5.92]],"id":52385885},{"atb":[[1.16,100],[1.02,8.89]],"id":52385896},{"atb":[[1.01,17.79],[1.16,100]],"id":52385890},{"atb":[[1.16,100],[1.02,8.89]],"id":52385892},{"atb":[[1.16,100],[1.03,5.92]],"id":52385904},{"atb":[[1.16,100],[1.03,5.92]],"id":52385898},{"atb":[[1.16,100],[1.02,8.89]],"id":52385900},{"atb":[[1.16,100],[1.03,5.92]],"id":52385911},{"atb":[[1.16,100],[1.02,8.89]],"id":52385913},{"atb":[[1.16,100],[1.03,5.92]],"id":52385907},{"atb":[[1.01,17.79],[1.16,100]],"id":52385886},{"atb":[[1.16,100],[1.02,8.89]],"id":52385919},{"atb":[[1.01,17.79],[1.16,100]],"id":52385921},{"atb":[[1.16,100],[1.02,8.89]],"id":52385882},{"atb":[[1.16,100],[1.02,8.89]],"id":52385884},{"atb":[[1.01,17.79],[1.16,100]],"id":52385917},{"atb":[[1.16,100],[1.03,5.92]],"id":52385897},{"atb":[[1.01,17.79],[1.16,100]],"id":52385891},{"atb":[[1.16,100],[1.02,8.89]],"id":52385893},{"atb":[[1.16,100],[1.03,5.92]],"id":52385903},{"atb":[[1.16,100],[1.03,5.92]],"id":52385905},{"atb":[[1.01,17.79],[1.16,100]],"id":52385899}],"con":true,"img":true}]}
{"op":"mcm","clk":"11548861956","pt":1719477482591,"mc":[{"id":"1.230178172","marketDefinition":{"bspMarket":false,"turnInPlayEnabled":false,"persistenceEnabled":false,"marketBaseRate":5.0,"eventId":"33376048","eventTypeId":"4339","numberOfWinners":1,"bettingType":"ODDS","marketType":"FORECAST","marketTime":"2024-06-27T15:22:00.000Z","suspendTime":"2024-06-27T15:22:00.000Z","bspReconciled":false,"complete":true,"inPlay":false,"crossMatching":false,"runnersVoidable":false,"numberOfActiveRunners":30,"betDelay":0,"status":"OPEN","runners":[{"status":"ACTIVE","sortPriority":1,"id":52385882,"name":"1 - 2"},{"status":"ACTIVE","sortPriority":2,"id":52385883,"name":"1 - 3"},{"status":"ACTIVE","sortPriority":3,"id":52385884,"name":"1 - 4"},{"status":"ACTIVE","sortPriority":4,"id":52385885,"name":"1 - 5"},{"status":"ACTIVE","sortPriority":5,"id":52385886,"name":"1 - 6"},{"status":"ACTIVE","sortPriority":6,"id":52385889,"name":"2 - 1"},{"status":"ACTIVE","sortPriority":7,"id":52385890,"name":"2 - 3"},{"status":"ACTIVE","sortPriority":8,"id":52385891,"name":"2 - 4"},{"status":"ACTIVE","sortPriority":9,"id":52385892,"name":"2 - 5"},{"status":"ACTIVE","sortPriority":10,"id":52385893,"name":"2 - 6"},{"status":"ACTIVE","sortPriority":11,"id":52385896,"name":"3 - 1"},{"status":"ACTIVE","sortPriority":12,"id":52385897,"name":"3 - 2"},{"status":"ACTIVE","sortPriority":13,"id":52385898,"name":"3 - 4"},{"status":"ACTIVE","sortPriority":14,"id":52385899,"name":"3 - 5"},{"status":"ACTIVE","sortPriority":15,"id":52385900,"name":"3 - 6"},{"status":"ACTIVE","sortPriority":16,"id":52385903,"name":"4 - 1"},{"status":"ACTIVE","sortPriority":17,"id":52385904,"name":"4 - 2"},{"status":"ACTIVE","sortPriority":18,"id":52385905,"name":"4 - 3"},{"status":"ACTIVE","sortPriority":19,"id":52385906,"name":"4 - 5"},{"status":"ACTIVE","sortPriority":20,"id":52385907,"name":"4 - 6"},{"status":"ACTIVE","sortPriority":21,"id":52385910,"name":"5 - 1"},{"status":"ACTIVE","sortPriority":22,"id":52385911,"name":"5 - 2"},{"status":"ACTIVE","sortPriority":23,"id":52385912,"name":"5 - 3"},{"status":"ACTIVE","sortPriority":24,"id":52385913,"name":"5 - 4"},{"status":"ACTIVE","sortPriority":25,"id":52385914,"name":"5 - 6"},{"status":"ACTIVE","sortPriority":26,"id":52385917,"name":"6 - 1"},{"status":"ACTIVE","sortPriority":27,"id":52385918,"name":"6 - 2"},{"status":"ACTIVE","sortPriority":28,"id":52385919,"name":"6 - 3"},{"status":"ACTIVE","sortPriority":29,"id":52385920,"name":"6 - 4"},{"status":"ACTIVE","sortPriority":30,"id":52385921,"name":"6 - 5"}],"regulators":["MR_INT"],"venue":"Perry Barr","countryCode":"GB","discountAllowed":true,"timezone":"Europe/London","openDate":"2024-06-27T13:29:00.000Z","version":5994794122,"name":"Forecast","eventName":"Perry Barr (F/C) 27th Jun"},"rc":[{"atb":[[1.16,100],[1.02,8.9]],"id":52385910},{"atb":[[1.01,17.8],[1.16,100]],"id":52385912},{"atb":[[1.16,100],[1.03,5.93]],"id":52385906},{"atb":[[1.16,100],[1.02,8.9]],"id":52385918},{"atb":[[1.16,100],[1.03,5.93]],"id":52385920},{"atb":[[1.16,100],[1.02,8.9]],"id":52385889},{"atb":[[1.01,17.8],[1.16,100]],"id":52385914},{"atb":[[1.16,100],[1.03,5.93]],"id":52385883},{"atb":[[1.16,100],[1.03,5.93]],"id":52385885},{"atb":[[1.16,100],[1.02,8.9]],"id":52385896},{"atb":[[1.01,17.8],[1.16,100]],"id":52385890},{"atb":[[1.16,100],[1.02,8.9]],"id":52385892},{"atb":[[1.16,100],[1.03,5.93]],"id":52385904},{"atb":[[1.16,100],[1.03,5.93]],"id":52385898},{"atb":[[1.16,100],[1.02,8.9]],"id":52385900},{"atb":[[1.16,100],[1.03,5.93]],"id":52385911},{"atb":[[1.16,100],[1.02,8.9]],"id":52385913},{"atb":[[1.16,100],[1.03,5.93]],"id":52385907},{"atb":[[1.01,17.8],[1.16,100]],"id":52385886},{"atb":[[1.16,100],[1.02,8.9]],"id":52385919},{"atb":[[1.01,17.8],[1.16,100]],"id":52385921},{"atb":[[1.16,100],[1.02,8.9]],"id":52385882},{"atb":[[1.16,100],[1.02,8.9]],"id":52385884},{"atb":[[1.01,17.8],[1.16,100]],"id":52385917},{"atb":[[1.16,100],[1.03,5.93]],"id":52385897},{"atb":[[1.01,17.8],[1.16,100]],"id":52385891},{"atb":[[1.16,100],[1.02,8.9]],"id":52385893},{"atb":[[1.16,100],[1.03,5.93]],"id":52385903},{"atb":[[1.16,100],[1.03,5.93]],"id":52385905},{"atb":[[1.01,17.8],[1.16,100]],"id":52385899}],"con":true,"img":true}]}
{"op":"mcm","clk":"11549140220","pt":1719482882591,"mc":[{"id":"1.230178172","marketDefinition":{"bspMarket":false,"turnInPlayEnabled":false,"persistenceEnabled":false,"marketBaseRate":5.0,"eventId":"33376048","eventTypeId":"4339","numberOfWinners":1,"bettingType":"ODDS","marketType":"FORECAST","marketTime":"2024-06-27T15:22:00.000Z","suspendTime":"2024-06-27T15:22:00.000Z","bspReconciled":false,"complete":true,"inPlay":false,"crossMatching":false,"runnersVoidable":false,"numberOfActiveRunners":30,"betDelay":0,"status":"OPEN","runners":[{"status":"ACTIVE","sortPriority":1,"id":52385882,"name":"1 - 2"},{"status":"ACTIVE","sortPriority":2,"id":52385883,"name":"1 - 3"},{"status":"ACTIVE","sortPriority":3,"id":52385884,"name":"1 - 4"},{"status":"ACTIVE","sortPriority":4,"id":52385885,"name":"1 - 5"},{"status":"ACTIVE","sortPriority":5,"id":52385886,"name":"1 - 6"},{"status":"ACTIVE","sortPriority":6,"id":52385889,"name":"2 - 1"},{"status":"ACTIVE","sortPriority":7,"id":52385890,"name":"2 - 3"},{"status":"ACTIVE","sortPriority":8,"id":52385891,"name":"2 - 4"},{"status":"ACTIVE","sortPriority":9,"id":52385892,"name":"2 - 5"},{"status":"ACTIVE","sortPriority":10,"id":52385893,"name":"2 - 6"},{"status":"ACTIVE","sortPriority":11,"id":52385896,"name":"3 - 1"},{"status":"ACTIVE","sortPriority":12,"id":52385897,"name":"3 - 2"},{"status":"ACTIVE","sortPriority":13,"id":52385898,"name":"3 - 4"},{"status":"ACTIVE","sortPriority":14,"id":52385899,"name":"3 - 5"},{"status":"ACTIVE","sortPriority":15,"id":52385900,"name":"3 - 6"},{"status":"ACTIVE","sortPriority":16,"id":52385903,"name":"4 - 1"},{"status":"ACTIVE","sortPriority":17,"id":52385904,"name":"4 - 2"},{"status":"ACTIVE","sortPriority":18,"id":52385905,"name":"4 - 3"},{"status":"ACTIVE","sortPriority":19,"id":52385906,"name":"4 - 5"},{"status":"ACTIVE","sortPriority":20,"id":52385907,"name":"4 - 6"},{"status":"ACTIVE","sortPriority":21,"id":52385910,"name":"5 - 1"},{"status":"ACTIVE","sortPriority":22,"id":52385911,"name":"5 - 2"},{"status":"ACTIVE","sortPriority":23,"id":52385912,"name":"5 - 3"},{"status":"ACTIVE","sortPriority":24,"id":52385913,"name":"5 - 4"},{"status":"ACTIVE","sortPriority":25,"id":52385914,"name":"5 - 6"},{"status":"ACTIVE","sortPriority":26,"id":52385917,"name":"6 - 1"},{"status":"ACTIVE","sortPriority":27,"id":52385918,"name":"6 - 2"},{"status":"ACTIVE","sortPriority":28,"id":52385919,"name":"6 - 3"},{"status":"ACTIVE","sortPriority":29,"id":52385920,"name":"6 - 4"},{"status":"ACTIVE","sortPriority":30,"id":52385921,"name":"6 - 5"}],"regulators":["MR_INT"],"venue":"Perry Barr","countryCode":"GB","discountAllowed":true,"timezone":"Europe/London","openDate":"2024-06-27T13:29:00.000Z","version":5994794122,"name":"Forecast","eventName":"Perry Barr (F/C) 27th Jun"},"rc":[{"atb":[[1.16,100],[1.02,8.89]],"id":52385910},{"atb":[[1.01,17.79],[1.16,100]],"id":52385912},{"atb":[[1.16,100],[1.03,5.92]],"id":52385906},{"atb":[[1.16,100],[1.02,8.89]],"id":52385918},{"atb":[[1.16,100],[1.03,5.92]],"id":52385920},{"atb":[[1.16,100],[1.02,8.89]],"id":52385889},{"atb":[[1.01,17.79],[1.16,100]],"id":52385914},{"atb":[[1.16,100],[1.03,5.92]],"id":52385883},{"atb":[[1.16,100],[1.03,5.92]],"id":52385885},{"atb":[[1.16,100],[1.02,8.89]],"id":52385896},{"atb":[[1.01,17.79],[1.16,100]],"id":52385890},{"atb":[[1.16,100],[1.02,8.89]],"id":52385892},{"atb":[[1.16,100],[1.03,5.92]],"id":52385904},{"atb":[[1.16,100],[1.03,5.92]],"id":52385898},{"atb":[[1.16,100],[1.02,8.89]],"id":52385900},{"atb":[[1.16,100],[1.03,5.92]],"id":52385911},{"atb":[[1.16,100],[1.02,8.89]],"id":52385913},{"atb":[[1.16,100],[1.03,5.92]],"id":52385907},{"atb":[[1.01,17.79],[1.16,100]],"id":52385886},{"atb":[[1.16,100],[1.02,8.89]],"id":52385919},{"atb":[[1.01,17.79],[1.16,100]],"id":52385921},{"atb":[[1.16,100],[1.02,8.89]],"id":52385882},{"atb":[[1.16,100],[1.02,8.89]],"id":52385884},{"atb":[[1.01,17.79],[1.16,100]],"id":52385917},{"atb":[[1.16,100],[1.03,5.92]],"id":52385897},{"atb":[[1.01,17.79],[1.16,100]],"id":52385891},{"atb":[[1.16,100],[1.02,8.89]],"id":52385893},{"atb":[[1.16,100],[1.03,5.92]],"id":52385903},{"atb":[[1.16,100],[1.03,5.92]],"id":52385905},{"atb":[[1.01,17.79],[1.16,100]],"id":52385899}],"con":true,"img":true}]}
{"op":"mcm","clk":"11549606655","pt":1719488282609,"mc":[{"id":"1.230178172","marketDefinition":{"bspMarket":false,"turnInPlayEnabled":false,"persistenceEnabled":false,"marketBaseRate":5.0,"eventId":"33376048","eventTypeId":"4339","numberOfWinners":1,"bettingType":"ODDS","marketType":"FORECAST","marketTime":"2024-06-27T15:22:00.000Z","suspendTime":"2024-06-27T15:22:00.000Z","bspReconciled":false,"complete":true,"inPlay":false,"crossMatching":false,"runnersVoidable":false,"numberOfActiveRunners":30,"betDelay":0,"status":"OPEN","runners":[{"status":"ACTIVE","sortPriority":1,"id":52385882,"name":"1 - 2"},{"status":"ACTIVE","sortPriority":2,"id":52385883,"name":"1 - 3"},{"status":"ACTIVE","sortPriority":3,"id":52385884,"name":"1 - 4"},{"status":"ACTIVE","sortPriority":4,"id":52385885,"name":"1 - 5"},{"status":"ACTIVE","sortPriority":5,"id":52385886,"name":"1 - 6"},{"status":"ACTIVE","sortPriority":6,"id":52385889,"name":"2 - 1"},{"status":"ACTIVE","sortPriority":7,"id":52385890,"name":"2 - 3"},{"status":"ACTIVE","sortPriority":8,"id":52385891,"name":"2 - 4"},{"status":"ACTIVE","sortPriority":9,"id":52385892,"name":"2 - 5"},{"status":"ACTIVE","sortPriority":10,"id":52385893,"name":"2 - 6"},{"status":"ACTIVE","sortPriority":11,"id":52385896,"name":"3 - 1"},{"status":"ACTIVE","sortPriority":12,"id":52385897,"name":"3 - 2"},{"status":"ACTIVE","sortPriority":13,"id":52385898,"name":"3 - 4"},{"status":"ACTIVE","sortPriority":14,"id":52385899,"name":"3 - 5"},{"status":"ACTIVE","sortPriority":15,"id":52385900,"name":"3 - 6"},{"status":"ACTIVE","sortPriority":16,"id":52385903,"name":"4 - 1"},{"status":"ACTIVE","sortPriority":17,"id":52385904,"name":"4 - 2"},{"status":"ACTIVE","sortPriority":18,"id":52385905,"name":"4 - 3"},{"status":"ACTIVE","sortPriority":19,"id":52385906,"name":"4 - 5"},{"status":"ACTIVE","sortPriority":20,"id":52385907,"name":"4 - 6"},{"status":"ACTIVE","sortPriority":21,"id":52385910,"name":"5 - 1"},{"status":"ACTIVE","sortPriority":22,"id":52385911,"name":"5 - 2"},{"status":"ACTIVE","sortPriority":23,"id":52385912,"name":"5 - 3"},{"status":"ACTIVE","sortPriority":24,"id":52385913,"name":"5 - 4"},{"status":"ACTIVE","sortPriority":25,"id":52385914,"name":"5 - 6"},{"status":"ACTIVE","sortPriority":26,"id":52385917,"name":"6 - 1"},{"status":"ACTIVE","sortPriority":27,"id":52385918,"name":"6 - 2"},{"status":"ACTIVE","sortPriority":28,"id":52385919,"name":"6 - 3"},{"status":"ACTIVE","sortPriority":29,"id":52385920,"name":"6 - 4"},{"status":"ACTIVE","sortPriority":30,"id":52385921,"name":"6 - 5"}],"regulators":["MR_INT"],"venue":"Perry Barr","countryCode":"GB","discountAllowed":true,"timezone":"Europe/London","openDate":"2024-06-27T13:29:00.000Z","version":5994794122,"name":"Forecast","eventName":"Perry Barr (F/C) 27th Jun"},"rc":[{"atb":[[1.16,100],[1.02,8.89]],"id":52385910},{"atb":[[1.01,17.79],[1.16,100]],"id":52385912},{"atb":[[1.16,100],[1.03,5.93]],"id":52385906},{"atb":[[1.16,100],[1.02,8.89]],"id":52385918},{"atb":[[1.16,100],[1.03,5.93]],"id":52385920},{"atb":[[1.16,100],[1.02,8.89]],"id":52385889},{"atb":[[1.01,17.79],[1.16,100]],"id":52385914},{"atb":[[1.16,100],[1.03,5.93]],"id":52385883},{"atb":[[1.16,100],[1.03,5.93]],"id":52385885},{"atb":[[1.16,100],[1.02,8.89]],"id":52385896},{"atb":[[1.01,17.79],[1.16,100]],"id":52385890},{"atb":[[1.16,100],[1.02,8.89]],"id":52385892},{"atb":[[1.16,100],[1.03,5.93]],"id":52385904},{"atb":[[1.16,100],[1.03,5.93]],"id":52385898},{"atb":[[1.16,100],[1.02,8.89]],"id":52385900},{"atb":[[1.16,100],[1.03,5.93]],"id":52385911},{"atb":[[1.16,100],[1.02,8.89]],"id":52385913},{"atb":[[1.16,100],[1.03,5.93]],"id":52385907},{"atb":[[1.01,17.79],[1.16,100]],"id":52385886},{"atb":[[1.16,100],[1.02,8.89]],"id":52385919},{"atb":[[1.01,17.79],[1.16,100]],"id":52385921},{"atb":[[1.16,100],[1.02,8.89]],"id":52385882},{"atb":[[1.16,100],[1.02,8.89]],"id":52385884},{"atb":[[1.01,17.79],[1.16,100]],"id":52385917},{"atb":[[1.16,100],[1.03,5.93]],"id":52385897},{"atb":[[1.01,17.79],[1.16,100]],"id":52385891},{"atb":[[1.16,100],[1.02,8.89]],"id":52385893},{"atb":[[1.16,100],[1.03,5.93]],"id":52385903},{"atb":[[1.16,100],[1.03,5.93]],"id":52385905},{"atb":[[1.01,17.79],[1.16,100]],"id":52385899}],"con":true,"img":true}]}
{"op":"mcm","clk":"11549802851","pt":1719490959784,"mc":[{"id":"1.230178172","rc":[{"atb":[[1.02,8.89]],"id":52385910},{"atb":[[1.01,17.79]],"id":52385912},{"atb":[[1.03,5.93]],"id":52385906},{"atb":[[1.02,8.89]],"id":52385918},{"atb":[[1.03,5.93]],"id":52385920},{"atb":[[1.02,8.89]],"id":52385889},{"atb":[[1.01,17.79]],"id":52385914},{"atb":[[1.01,306.12],[1.03,5.93]],"id":52385883},{"atb":[[1.03,5.93]],"id":52385885},{"atb":[[1.02,8.89]],"id":52385896},{"atb":[[1.01,17.79]],"id":52385890},{"atb":[[1.02,8.89]],"id":52385892},{"atb":[[1.03,5.93]],"id":52385904},{"atb":[[1.03,5.93]],"id":52385898},{"atb":[[1.02,8.89]],"id":52385900},{"atb":[[1.03,5.93]],"id":52385911},{"atb":[[1.02,8.89]],"id":52385913},{"atb":[[1.03,5.93]],"id":52385907},{"atb":[[1.01,17.79]],"id":52385886},{"atb":[[1.02,8.89]],"id":52385919},{"atb":[[1.01,17.79]],"id":52385921},{"atb":[[1.01,306.12],[1.02,8.89]],"id":52385882},{"atb":[[1.01,306.12],[1.02,8.89]],"id":52385884},{"atb":[[1.01,17.79]],"id":52385917},{"atb":[[1.03,5.93]],"id":52385897},{"atb":[[1.01,17.79]],"id":52385891},{"atb":[[1.02,8.89]],"id":52385893},{"atb":[[1.03,5.93]],"id":52385903},{"atb":[[1.03,5.93]],"id":52385905},{"atb":[[1.01,17.79]],"id":52385899}],"con":true,"img":false}]}
{"op":"mcm","clk":"11549802865","pt":1719490959987,"mc":[{"id":"1.230178172","rc":[{"atb":[[1.01,306.12]],"id":52385889},{"atb":[[1.01,306.12]],"id":52385885},{"atb":[[1.01,323.91]],"id":52385886}],"con":true,"img":false}]}
{"op":"mcm","clk":"11549802878","pt":1719490960192,"mc":[{"id":"1.230178172","rc":[{"atb":[[1.01,323.91]],"id":52385890},{"atb":[[1.01,323.91]],"id":52385891}],"con":true,"img":false}]}
{"op":"mcm","clk":"11549802906","pt":1719490960505,"mc":[{"id":"1.230178172","rc":[{"atb":[[1.01,306.12]],"id":52385892},{"atb":[[1.01,306.12]],"id":52385893}],"con":true,"img":false}]}
{"op":"mcm","clk":"11549802920","pt":1719490960708,"mc":[{"id":"1.230178172","rc":[{"atb":[[1.01,306.12]],"id":52385896},{"atb":[[1.01,306.12]],"id":52385897}],"con":true,"img":false}]}
{"op":"mcm","clk":"11549802929","pt":1719490960913,"mc":[{"id":"1.230178172","rc":[{"atb":[[1.01,306.12]],"id":52385898},{"atb":[[1.01,323.91]],"id":52385899}],"con":true,"img":false}]}
{"op":"mcm","clk":"11549802940","pt":1719490961121,"mc":[{"id":"1.230178172","rc":[{"atb":[[1.01,306.12]],"id":52385900}],"con":true,"img":false}]}
{"op":"mcm","clk":"11549802948","pt":1719490961226,"mc":[{"id":"1.230178172","rc":[{"atb":[[1.01,306.12]],"id":52385903}],"con":true,"img":false}]}
{"op":"mcm","clk":"11549802954","pt":1719490961280,"mc":[{"id":"1.230178172","rc":[{"atb":[[1.01,306.12]],"id":52385904}],"con":true,"img":false}]}
{"op":"mcm","clk":"11549802961","pt":1719490961380,"mc":[{"id":"1.230178172","rc":[{"atb":[[1.01,306.12]],"id":52385905}],"con":true,"img":false}]}
{"op":"mcm","clk":"11549802967","pt":1719490961490,"mc":[{"id":"1.230178172","rc":[{"atb":[[1.01,306.12]],"id":52385906},{"atb":[[1.01,306.12]],"id":52385907}],"con":true,"img":false}]}
{"op":"mcm","clk":"11549802976","pt":1719490961586,"mc":[{"id":"1.230178172","rc":[{"atb":[[1.01,306.12]],"id":52385910}],"con":true,"img":false}]}
{"op":"mcm","clk":"11549802982","pt":1719490961690,"mc":[{"id":"1.230178172","rc":[{"atb":[[1.01,323.91]],"id":52385912},{"atb":[[1.01,306.12]],"id":52385911}],"con":true,"img":false}]}
{"op":"mcm","clk":"11549802990","pt":1719490961894,"mc":[{"id":"1.230178172","rc":[{"atb":[[1.01,323.91]],"id":52385914},{"atb":[[1.01,306.12]],"id":52385913},{"atb":[[1.01,323.91]],"id":52385917}],"con":true,"img":false}]}
{"op":"mcm","clk":"11549803004","pt":1719490962104,"mc":[{"id":"1.230178172","rc":[{"atb":[[1.01,306.12]],"id":52385918},{"atb":[[1.01,306.12]],"id":52385919}],"con":true,"img":false}]}
{"op":"mcm","clk":"11549803010","pt":1719490962202,"mc":[{"id":"1.230178172","rc":[{"atb":[[1.01,306.12]],"id":52385920}],"con":true,"img":false}]}
{"op":"mcm","clk":"11549803017","pt":1719490962309,"mc":[{"id":"1.230178172","rc":[{"atb":[[1.01,323.91]],"id":52385921}],"con":true,"img":false}]}
{"op":"mcm","clk":"11549803024","pt":1719490962413,"mc":[{"id":"1.230178172","rc":[{"atb":[[1.17,120.05]],"id":52385883},{"atb":[[1.17,120.05]],"id":52385882}],"con":true,"img":false}]}
{"op":"mcm","clk":"11549803033","pt":1719490962519,"mc":[{"id":"1.230178172","rc":[{"atb":[[1.17,120.05]],"id":52385884}],"con":true,"img":false}]}
{"op":"mcm","clk":"11549803036","pt":1719490962620,"mc":[{"id":"1.230178172","rc":[{"atb":[[1.17,120.05]],"id":52385885},{"atb":[[1.17,120.05]],"id":52385886}],"con":true,"img":false}]}
{"op":"mcm","clk":"11549803041","pt":1719490962726,"mc":[{"id":"1.230178172","rc":[{"atb":[[1.17,120.05]],"id":52385889}],"con":true,"img":false}]}
{"op":"mcm","clk":"11549803044","pt":1719490962826,"mc":[{"id":"1.230178172","rc":[{"atb":[[1.17,120.05]],"id":52385890},{"atb":[[1.17,120.05]],"id":52385891}],"con":true,"img":false}]}
{"op":"mcm","clk":"11549803053","pt":1719490962984,"mc":[{"id":"1.230178172","rc":[{"atb":[[1.17,120.05]],"id":52385892}],"con":true,"img":false}]}
{"op":"mcm","clk":"11549803058","pt":1719490963094,"mc":[{"id":"1.230178172","rc":[{"atb":[[1.17,120.05]],"id":52385893}],"con":true,"img":false}]}
{"op":"mcm","clk":"11549803062","pt":1719490963193,"mc":[{"id":"1.230178172","rc":[{"atb":[[1.17,120.05]],"id":52385896}],"con":true,"img":false}]}
{"op":"mcm","clk":"11549803073","pt":1719490963402,"mc":[{"id":"1.230178172","rc":[{"atb":[[1.17,120.05]],"id":52385897}],"con":true,"img":false}]}
{"op":"mcm","clk":"11549803080","pt":1719490963507,"mc":[{"id":"1.230178172","rc":[{"atb":[[1.17,120.05]],"id":52385898}],"con":true,"img":false}]}
{"op":"mcm","clk":"11549803089","pt":1719490963611,"mc":[{"id":"1.230178172","rc":[{"atb":[[1.17,120.05]],"id":52385899}],"con":true,"img":false}]}
{"op":"mcm","clk":"11549803095","pt":1719490963715,"mc":[{"id":"1.230178172","rc":[{"atb":[[1.17,120.05]],"id":52385900}],"con":true,"img":false}]}
{"op":"mcm","clk":"11549803102","pt":1719490963815,"mc":[{"id":"1.230178172","rc":[{"atb":[[1.17,120.05]],"id":52385903}],"con":true,"img":false}]}
{"op":"mcm","clk":"11549803108","pt":1719490963919,"mc":[{"id":"1.230178172","rc":[{"atb":[[1.17,120.05]],"id":52385904}],"con":true,"img":false}]}
{"op":"mcm","clk":"11549803113","pt":1719490964021,"mc":[{"id":"1.230178172","rc":[{"atb":[[1.17,120.05]],"id":52385906},{"atb":[[1.17,120.05]],"id":52385905}],"con":true,"img":false}]}
{"op":"mcm","clk":"11549803125","pt":1719490964226,"mc":[{"id":"1.230178172","rc":[{"atb":[[1.17,120.05]],"id":52385910},{"atb":[[1.17,120.05]],"id":52385907}],"con":true,"img":false}]}
{"op":"mcm","clk":"11549803130","pt":1719490964284,"mc":[{"id":"1.230178172","rc":[{"atb":[[1.17,120.05]],"id":52385911}],"con":true,"img":false}]}
{"op":"mcm","clk":"11549803134","pt":1719490964382,"mc":[{"id":"1.230178172","rc":[{"atb":[[1.17,120.05]],"id":52385912}],"con":true,"img":false}]}
{"op":"mcm","clk":"11549803144","pt":1719490964496,"mc":[{"id":"1.230178172","rc":[{"atb":[[1.17,120.05]],"id":52385914},{"atb":[[1.17,120.05]],"id":52385913}],"con":true,"img":false}]}
{"op":"mcm","clk":"11549803153","pt":1719490964597,"mc":[{"id":"1.230178172","rc":[{"atb":[[1.17,120.05]],"id":52385917}],"con":true,"img":false}]}
{"op":"mcm","clk":"11549803158","pt":1719490964700,"mc":[{"id":"1.230178172","rc":[{"atb":[[1.17,120.05]],"id":52385918}],"con":true,"img":false}]}
{"op":"mcm","clk":"11549803163","pt":1719490964800,"mc":[{"id":"1.230178172","rc":[{"atb":[[1.17,120.05]],"id":52385920},{"atb":[[1.17,120.05]],"id":52385919}],"con":true,"img":false}]}
{"op":"mcm","clk":"11549803166","pt":1719490964899,"mc":[{"id":"1.230178172","rc":[{"atb":[[1.17,120.05]],"id":52385921}],"con":true,"img":false}]}
{"op":"mcm","clk":"11549970648","pt":1719493210478,"mc":[{"id":"1.230178172","rc":[{"atb":[[1.16,0],[1.02,8.9]],"id":52385910},{"atb":[[1.01,323.93],[1.16,0]],"id":52385912},{"atb":[[1.16,0],[1.03,5.93]],"id":52385906},{"atb":[[1.16,0],[1.02,8.9]],"id":52385918},{"atb":[[1.16,0],[1.03,5.93]],"id":52385920},{"atb":[[1.16,0],[1.02,8.9]],"id":52385889},{"atb":[[1.01,323.93],[1.16,0]],"id":52385914},{"atb":[[1.16,0],[1.03,5.93]],"id":52385883},{"atb":[[1.16,0],[1.03,5.93]],"id":52385885},{"atb":[[1.16,0],[1.02,8.9]],"id":52385896},{"atb":[[1.01,323.93],[1.16,0]],"id":52385890},{"atb":[[1.16,0],[1.02,8.9]],"id":52385892},{"atb":[[1.16,0],[1.03,5.93]],"id":52385904},{"atb":[[1.16,0],[1.03,5.93]],"id":52385898},{"atb":[[1.16,0],[1.02,8.9]],"id":52385900},{"atb":[[1.16,0],[1.03,5.93]],"id":52385911},{"atb":[[1.16,0],[1.02,8.9]],"id":52385913},{"atb":[[1.16,0],[1.03,5.93]],"id":52385907},{"atb":[[1.01,323.93],[1.16,0]],"id":52385886},{"atb":[[1.16,0],[1.02,8.9]],"id":52385919},{"atb":[[1.01,323.93],[1.16,0]],"id":52385921},{"atb":[[1.16,0],[1.02,8.9]],"id":52385882},{"atb":[[1.16,0],[1.02,8.9]],"id":52385884},{"atb":[[1.01,323.93],[1.16,0]],"id":52385917},{"atb":[[1.16,0],[1.03,5.93]],"id":52385897},{"atb":[[1.01,323.93],[1.16,0]],"id":52385891},{"atb":[[1.16,0],[1.02,8.9]],"id":52385893},{"atb":[[1.16,0],[1.03,5.93]],"id":52385903},{"atb":[[1.16,0],[1.03,5.93]],"id":52385905},{"atb":[[1.01,323.93],[1.16,0]],"id":52385899}],"con":true,"img":false}]}
{"op":"mcm","clk":"11549974819","pt":1719493262942,"mc":[{"id":"1.230178172","rc":[{"atb":[[1.18,150]],"id":52385910},{"atb":[[1.18,150]],"id":52385912},{"atb":[[1.18,150]],"id":52385906},{"atb":[[1.18,150]],"id":52385918},{"atb":[[1.18,150]],"id":52385920},{"atb":[[1.18,150]],"id":52385889},{"atb":[[1.18,150]],"id":52385914},{"atb":[[1.18,150]],"id":52385883},{"atb":[[1.18,150]],"id":52385885},{"atb":[[1.18,150]],"id":52385896},{"atb":[[1.18,150]],"id":52385890},{"atb":[[1.18,150]],"id":52385892},{"atb":[[1.18,150]],"id":52385904},{"atb":[[1.18,150]],"id":52385898},{"atb":[[1.18,150]],"id":52385900},{"atb":[[1.18,150]],"id":52385911},{"atb":[[1.18,150]],"id":52385913},{"atb":[[1.18,150]],"id":52385907},{"atb":[[1.18,150]],"id":52385886},{"atb":[[1.18,150]],"id":52385919},{"atb":[[1.18,150]],"id":52385921},{"atb":[[1.18,150]],"id":52385882},{"atb":[[1.18,150]],"id":52385884},{"atb":[[1.18,150]],"id":52385917},{"atb":[[1.18,150]],"id":52385897},{"atb":[[1.18,150]],"id":52385891},{"atb":[[1.18,150]],"id":52385893},{"atb":[[1.18,150]],"id":52385903},{"atb":[[1.18,150]],"id":52385905},{"atb":[[1.18,150]],"id":52385899}],"con":true,"img":false}]}
{"op":"mcm","clk":"11549977392","pt":1719493290839,"mc":[{"id":"1.230178172","rc":[{"atb":[[1.17,0]],"id":52385882}],"con":true,"img":false}]}
{"op":"mcm","clk":"11549995467","pt":1719493500930,"mc":[{"id":"1.230178172","rc":[{"atb":[[1.17,0]],"id":52385883}],"con":true,"img":false}]}
{"op":"mcm","clk":"11550047008","pt":1719493941105,"mc":[{"id":"1.230178172","rc":[{"atb":[[1.17,0]],"id":52385884}],"con":true,"img":false}]}
{"op":"mcm","clk":"11550070005","pt":1719494171288,"mc":[{"id":"1.230178172","rc":[{"atb":[[1.17,0]],"id":52385885}],"con":true,"img":false}]}
{"op":"mcm","clk":"11550096465","pt":1719494411337,"mc":[{"id":"1.230178172","rc":[{"atb":[[1.17,0]],"id":52385886}],"con":true,"img":false}]}
{"op":"mcm","clk":"11550122145","pt":1719494641346,"mc":[{"id":"1.230178172","rc":[{"atb":[[1.17,0]],"id":52385889}],"con":true,"img":false}]}
{"op":"mcm","clk":"11550146119","pt":1719494871505,"mc":[{"id":"1.230178172","rc":[{"atb":[[1.17,0]],"id":52385890}],"con":true,"img":false}]}
{"op":"mcm","clk":"11550165008","pt":1719495101692,"mc":[{"id":"1.230178172","rc":[{"atb":[[1.17,0]],"id":52385891}],"con":true,"img":false}]}
{"op":"mcm","clk":"11550183007","pt":1719495331740,"mc":[{"id":"1.230178172","rc":[{"atb":[[1.17,0]],"id":52385892}],"con":true,"img":false}]}
{"op":"mcm","clk":"11550202621","pt":1719495561923,"mc":[{"id":"1.230178172","rc":[{"atb":[[1.17,0]],"id":52385893}],"con":true,"img":false}]}
{"op":"mcm","clk":"11550223357","pt":1719495801932,"mc":[{"id":"1.230178172","rc":[{"atb":[[1.17,0]],"id":52385896}],"con":true,"img":false}]}
{"op":"mcm","clk":"11550245386","pt":1719496041997,"mc":[{"id":"1.230178172","rc":[{"atb":[[1.17,0]],"id":52385897}],"con":true,"img":false}]}
{"op":"mcm","clk":"11550263205","pt":1719496282182,"mc":[{"id":"1.230178172","rc":[{"atb":[[1.17,0]],"id":52385898}],"con":true,"img":false}]}
{"op":"mcm","clk":"11550277576","pt":1719496512159,"mc":[{"id":"1.230178172","rc":[{"atb":[[1.17,0]],"id":52385899}],"con":true,"img":false}]}
{"op":"mcm","clk":"11550296964","pt":1719496762460,"mc":[{"id":"1.230178172","rc":[{"atb":[[1.17,0]],"id":52385900}],"con":true,"img":false}]}
{"op":"mcm","clk":"11550318497","pt":1719497002411,"mc":[{"id":"1.230178172","rc":[{"atb":[[1.02,8.9]],"id":52385910},{"atb":[[1.01,323.93]],"id":52385912},{"atb":[[1.03,5.93]],"id":52385906},{"atb":[[1.02,8.9]],"id":52385918},{"atb":[[1.03,5.93]],"id":52385920},{"atb":[[1.02,8.9]],"id":52385889},{"atb":[[1.01,323.93]],"id":52385914},{"atb":[[1.03,5.93]],"id":52385883},{"atb":[[1.03,5.93]],"id":52385885},{"atb":[[1.02,8.9]],"id":52385896},{"atb":[[1.01,323.93]],"id":52385890},{"atb":[[1.02,8.9]],"id":52385892},{"atb":[[1.03,5.93]],"id":52385904},{"atb":[[1.03,5.93]],"id":52385898},{"atb":[[1.02,8.9]],"id":52385900},{"atb":[[1.03,5.93]],"id":52385911},{"atb":[[1.02,8.9]],"id":52385913},{"atb":[[1.03,5.93]],"id":52385907},{"atb":[[1.01,323.93]],"id":52385886},{"atb":[[1.02,8.9]],"id":52385919},{"atb":[[1.01,323.93]],"id":52385921},{"atb":[[1.02,8.9]],"id":52385882},{"atb":[[1.02,8.9]],"id":52385884},{"atb":[[1.01,323.93]],"id":52385917},{"atb":[[1.03,5.93]],"id":52385897},{"atb":[[1.01,323.93]],"id":52385891},{"atb":[[1.02,8.9]],"id":52385893},{"atb":[[1.03,5.93],[1.17,0]],"id":52385903},{"atb":[[1.03,5.93]],"id":52385905},{"atb":[[1.01,323.93]],"id":52385899}],"con":true,"img":false}]}
{"op":"mcm","clk":"11550341550","pt":1719497252550,"mc":[{"id":"1.230178172","rc":[{"atb":[[1.17,0]],"id":52385904}],"con":true,"img":false}]}
{"op":"mcm","clk":"11550361472","pt":1719497502726,"mc":[{"id":"1.230178172","rc":[{"atb":[[1.17,0]],"id":52385905}],"con":true,"img":false}]}
{"op":"mcm","clk":"11550381119","pt":1719497742713,"mc":[{"id":"1.230178172","rc":[{"atb":[[1.17,0]],"id":52385906}],"con":true,"img":false}]}
{"op":"mcm","clk":"11550401578","pt":1719497982910,"mc":[{"id":"1.230178172","rc":[{"atb":[[1.17,0]],"id":52385907}],"con":true,"img":false}]}
{"op":"mcm","clk":"11550420950","pt":1719498233095,"mc":[{"id":"1.230178172","rc":[{"atb":[[1.17,0]],"id":52385910}],"con":true,"img":false}]}
{"op":"mcm","clk":"11550440189","pt":1719498483160,"mc":[{"id":"1.230178172","rc":[{"atb":[[1.17,0]],"id":52385911}],"con":true,"img":false}]}
{"op":"mcm","clk":"11550458098","pt":1719498723336,"mc":[{"id":"1.230178172","rc":[{"atb":[[1.17,0]],"id":52385912}],"con":true,"img":false}]}
{"op":"mcm","clk":"11550478467","pt":1719498963248,"mc":[{"id":"1.230178172","rc":[{"atb":[[1.17,0]],"id":52385914}],"con":true,"img":false}]}
{"op":"mcm","clk":"11550499917","pt":1719499163422,"mc":[{"id":"1.230178172","rc":[{"atb":[[1.17,0]],"id":52385913}],"con":true,"img":false}]}
{"op":"mcm","clk":"11550517803","pt":1719499393521,"mc":[{"id":"1.230178172","rc":[{"atb":[[1.17,0]],"id":52385917}],"con":true,"img":false}]}
{"op":"mcm","clk":"11550534676","pt":1719499623651,"mc":[{"id":"1.230178172","rc":[{"atb":[[1.17,0]],"id":52385918}],"con":true,"img":false}]}
{"op":"mcm","clk":"11550551102","pt":1719499853751,"mc":[{"id":"1.230178172","rc":[{"atb":[[1.17,0]],"id":52385919}],"con":true,"img":false}]}
{"op":"mcm","clk":"11550564724","pt":1719500073898,"mc":[{"id":"1.230178172","rc":[{"atb":[[1.17,0]],"id":52385920}],"con":true,"img":false}]}
{"op":"mcm","clk":"11550572942","pt":1719500184429,"mc":[{"id":"1.230178172","rc":[{"atb":[[1.03,1]],"id":52385910},{"atb":[[1.03,1]],"id":52385912},{"atb":[[1.03,6.93]],"id":52385906},{"atb":[[1.03,1]],"id":52385918},{"atb":[[1.03,6.93]],"id":52385920},{"atb":[[1.03,1]],"id":52385889},{"atb":[[1.03,1]],"id":52385914},{"atb":[[1.03,6.93]],"id":52385883},{"atb":[[1.03,6.93]],"id":52385885},{"atb":[[1.03,1]],"id":52385896},{"atb":[[1.03,1]],"id":52385890},{"atb":[[1.03,1]],"id":52385892},{"atb":[[1.03,6.93]],"id":52385904},{"atb":[[1.03,6.93]],"id":52385898},{"atb":[[1.03,1]],"id":52385900},{"atb":[[1.03,6.93]],"id":52385911},{"atb":[[1.03,1]],"id":52385913},{"atb":[[1.03,6.93]],"id":52385907},{"atb":[[1.03,1]],"id":52385886},{"atb":[[1.03,1]],"id":52385919},{"atb":[[1.03,1]],"id":52385921},{"atb":[[1.03,1]],"id":52385882},{"atb":[[1.03,1]],"id":52385884},{"atb":[[1.03,1]],"id":52385917},{"atb":[[1.03,6.93]],"id":52385897},{"atb":[[1.03,1]],"id":52385891},{"atb":[[1.03,1]],"id":52385893},{"atb":[[1.03,6.93]],"id":52385903},{"atb":[[1.03,6.93]],"id":52385905},{"atb":[[1.03,1]],"id":52385899}],"con":true,"img":false}]}
{"op":"mcm","clk":"11550572959","pt":1719500184639,"mc":[{"id":"1.230178172","rc":[{"atb":[[1.03,0.9]],"id":52385910},{"atb":[[1.03,0.9]],"id":52385912},{"atb":[[1.03,6.83]],"id":52385906},{"atb":[[1.03,0.9]],"id":52385918},{"atb":[[1.03,6.83]],"id":52385920},{"atb":[[1.03,0.9]],"id":52385889},{"atb":[[1.03,0.9]],"id":52385914},{"atb":[[1.03,6.83]],"id":52385883},{"atb":[[1.03,6.83]],"id":52385885},{"atb":[[1.03,0.9]],"id":52385896},{"atb":[[1.03,0.9]],"id":52385890},{"atb":[[1.03,0.9]],"id":52385892},{"atb":[[1.03,6.83]],"id":52385904},{"atb":[[1.03,6.83]],"id":52385898},{"atb":[[1.03,0.9]],"id":52385900},{"atb":[[1.03,6.83]],"id":52385911},{"atb":[[1.03,0.9]],"id":52385913},{"atb":[[1.03,6.83]],"id":52385907},{"atb":[[1.03,0.9]],"id":52385886},{"atb":[[1.03,0.9]],"id":52385919},{"atb":[[1.03,0.9]],"id":52385921},{"atb":[[1.03,0.9]],"id":52385882},{"atb":[[1.03,0.9]],"id":52385884},{"atb":[[1.03,0.9]],"id":52385917},{"atb":[[1.03,6.83]],"id":52385897},{"atb":[[1.03,0.9]],"id":52385891},{"atb":[[1.03,0.9]],"id":52385893},{"atb":[[1.03,6.83]],"id":52385903},{"atb":[[1.03,6.83]],"id":52385905},{"atb":[[1.03,0.9]],"id":52385899}],"con":true,"img":false}]}
{"op":"mcm","clk":"11550572975","pt":1719500184797,"mc":[{"id":"1.230178172","rc":[{"atb":[[1.03,0]],"id":52385910},{"atb":[[1.03,0]],"id":52385912},{"atb":[[1.03,5.93]],"id":52385906},{"atb":[[1.03,0]],"id":52385918},{"atb":[[1.03,5.93]],"id":52385920},{"atb":[[1.03,0]],"id":52385889},{"atb":[[1.03,0]],"id":52385914},{"atb":[[1.03,5.93]],"id":52385883},{"atb":[[1.03,5.93]],"id":52385885},{"atb":[[1.03,0]],"id":52385896},{"atb":[[1.03,0]],"id":52385890},{"atb":[[1.03,0]],"id":52385892},{"atb":[[1.03,5.93]],"id":52385904},{"atb":[[1.03,5.93]],"id":52385898},{"atb":[[1.03,0]],"id":52385900},{"atb":[[1.03,5.93]],"id":52385911},{"atb":[[1.03,0]],"id":52385913},{"atb":[[1.03,5.93]],"id":52385907},{"atb":[[1.03,0]],"id":52385886},{"atb":[[1.03,0]],"id":52385919},{"atb":[[1.03,0]],"id":52385921},{"atb":[[1.03,0]],"id":52385882},{"atb":[[1.03,0]],"id":52385884},{"atb":[[1.03,0]],"id":52385917},{"atb":[[1.03,5.93]],"id":52385897},{"atb":[[1.03,0]],"id":52385891},{"atb":[[1.03,0]],"id":52385893},{"atb":[[1.03,5.93]],"id":52385903},{"atb":[[1.03,5.93]],"id":52385905},{"atb":[[1.03,0]],"id":52385899}],"con":true,"img":false}]}
{"op":"mcm","clk":"11550572983","pt":1719500184900,"mc":[{"id":"1.230178172","rc":[{"atb":[[3.05,0.9]],"id":52385910},{"atb":[[3.05,0.9]],"id":52385912},{"atb":[[3.05,0.9]],"id":52385906},{"atb":[[3.05,0.9]],"id":52385918},{"atb":[[3.05,0.9]],"id":52385920},{"atb":[[3.05,0.9]],"id":52385889},{"atb":[[3.05,0.9]],"id":52385914},{"atb":[[3.05,0.9]],"id":52385883},{"atb":[[3.05,0.9]],"id":52385885},{"atb":[[3.05,0.9]],"id":52385896},{"atb":[[3.05,0.9]],"id":52385890},{"atb":[[3.05,0.9]],"id":52385892},{"atb":[[3.05,0.9]],"id":52385904},{"atb":[[3.05,0.9]],"id":52385898},{"atb":[[3.05,0.9]],"id":52385900},{"atb":[[3.05,0.9]],"id":52385911},{"atb":[[3.05,0.9]],"id":52385913},{"atb":[[3.05,0.9]],"id":52385907},{"atb":[[3.05,0.9]],"id":52385886},{"atb":[[3.05,0.9]],"id":52385919},{"atb":[[3.05,0.9]],"id":52385921},{"atb":[[3.05,0.9]],"id":52385882},{"atb":[[3.05,0.9]],"id":52385884},{"atb":[[3.05,0.9]],"id":52385917},{"atb":[[3.05,0.9]],"id":52385897},{"atb":[[3.05,0.9]],"id":52385891},{"atb":[[3.05,0.9]],"id":52385893},{"atb":[[3.05,0.9]],"id":52385903},{"atb":[[3.05,0.9]],"id":52385905},{"atb":[[3.05,0.9]],"id":52385899}],"con":true,"img":false}]}
{"op":"mcm","clk":"11550574293","pt":1719500201695,"mc":[{"id":"1.230178172","marketDefinition":{"bspMarket":false,"turnInPlayEnabled":false,"persistenceEnabled":false,"marketBaseRate":5.0,"eventId":"33376048","eventTypeId":"4339","numberOfWinners":1,"bettingType":"ODDS","marketType":"FORECAST","marketTime":"2024-06-27T15:22:00.000Z","suspendTime":"2024-06-27T15:22:00.000Z","bspReconciled":false,"complete":true,"inPlay":false,"crossMatching":true,"runnersVoidable":false,"numberOfActiveRunners":30,"betDelay":0,"status":"OPEN","runners":[{"status":"ACTIVE","sortPriority":1,"id":52385882,"name":"1 - 2"},{"status":"ACTIVE","sortPriority":2,"id":52385883,"name":"1 - 3"},{"status":"ACTIVE","sortPriority":3,"id":52385884,"name":"1 - 4"},{"status":"ACTIVE","sortPriority":4,"id":52385885,"name":"1 - 5"},{"status":"ACTIVE","sortPriority":5,"id":52385886,"name":"1 - 6"},{"status":"ACTIVE","sortPriority":6,"id":52385889,"name":"2 - 1"},{"status":"ACTIVE","sortPriority":7,"id":52385890,"name":"2 - 3"},{"status":"ACTIVE","sortPriority":8,"id":52385891,"name":"2 - 4"},{"status":"ACTIVE","sortPriority":9,"id":52385892,"name":"2 - 5"},{"status":"ACTIVE","sortPriority":10,"id":52385893,"name":"2 - 6"},{"status":"ACTIVE","sortPriority":11,"id":52385896,"name":"3 - 1"},{"status":"ACTIVE","sortPriority":12,"id":52385897,"name":"3 - 2"},{"status":"ACTIVE","sortPriority":13,"id":52385898,"name":"3 - 4"},{"status":"ACTIVE","sortPriority":14,"id":52385899,"name":"3 - 5"},{"status":"ACTIVE","sortPriority":15,"id":52385900,"name":"3 - 6"},{"status":"ACTIVE","sortPriority":16,"id":52385903,"name":"4 - 1"},{"status":"ACTIVE","sortPriority":17,"id":52385904,"name":"4 - 2"},{"status":"ACTIVE","sortPriority":18,"id":52385905,"name":"4 - 3"},{"status":"ACTIVE","sortPriority":19,"id":52385906,"name":"4 - 5"},{"status":"ACTIVE","sortPriority":20,"id":52385907,"name":"4 - 6"},{"status":"ACTIVE","sortPriority":21,"id":52385910,"name":"5 - 1"},{"status":"ACTIVE","sortPriority":22,"id":52385911,"name":"5 - 2"},{"status":"ACTIVE","sortPriority":23,"id":52385912,"name":"5 - 3"},{"status":"ACTIVE","sortPriority":24,"id":52385913,"name":"5 - 4"},{"status":"ACTIVE","sortPriority":25,"id":52385914,"name":"5 - 6"},{"status":"ACTIVE","sortPriority":26,"id":52385917,"name":"6 - 1"},{"status":"ACTIVE","sortPriority":27,"id":52385918,"name":"6 - 2"},{"status":"ACTIVE","sortPriority":28,"id":52385919,"name":"6 - 3"},{"status":"ACTIVE","sortPriority":29,"id":52385920,"name":"6 - 4"},{"status":"ACTIVE","sortPriority":30,"id":52385921,"name":"6 - 5"}],"regulators":["MR_INT"],"venue":"Perry Barr","countryCode":"GB","discountAllowed":true,"timezone":"Europe/London","openDate":"2024-06-27T13:29:00.000Z","version":5994794122,"name":"Forecast","eventName":"Perry Barr (F/C) 27th Jun"},"rc":[],"con":true,"img":false}]}
{"op":"mcm","clk":"11550582208","pt":1719500313939,"mc":[{"id":"1.230178172","rc":[{"atb":[[1.17,0]],"id":52385921}],"con":true,"img":false}]}
{"op":"mcm","clk":"11550601509","pt":1719500583161,"mc":[{"id":"1.230178172","rc":[{"atb":[[1.02,8.9],[13,8]],"id":52385910},{"atb":[[16,6],[1.01,323.93]],"id":52385912},{"atb":[[1.03,5.93],[15,6]],"id":52385906},{"atb":[[16,6],[1.02,8.9]],"id":52385918},{"atb":[[1.03,5.93],[20,5]],"id":52385920},{"atb":[[9,11],[1.02,8.9]],"id":52385889},{"atb":[[1.01,323.93],[13,8]],"id":52385914},{"atb":[[16,6],[1.03,5.93]],"id":52385883},{"atb":[[16,6],[1.03,5.93]],"id":52385885},{"atb":[[1.02,8.9],[15,6]],"id":52385896},{"atb":[[1.01,323.93],[12,8]],"id":52385890},{"atb":[[10,10],[1.02,8.9]],"id":52385892},{"atb":[[1.03,5.93],[13,8]],"id":52385904},{"atb":[[1.03,5.93],[14,7]],"id":52385898},{"atb":[[17,6],[1.02,8.9]],"id":52385900},{"atb":[[1.03,5.93],[13,8]],"id":52385911},{"atb":[[1.02,8.9],[14,7]],"id":52385913},{"atb":[[18,5],[1.03,5.93]],"id":52385907},{"atb":[[18,5],[1.01,323.93]],"id":52385886},{"atb":[[20,5],[1.02,8.9]],"id":52385919},{"atb":[[16,6],[1.01,323.93]],"id":52385921},{"atb":[[9,11],[1.02,8.9]],"id":52385882},{"atb":[[17,6],[1.02,8.9]],"id":52385884},{"atb":[[1.01,323.93],[19,5]],"id":52385917},{"atb":[[1.03,5.93],[12,8]],"id":52385897},{"atb":[[1.01,323.93],[11,9]],"id":52385891},{"atb":[[1.02,8.9],[13,8]],"id":52385893},{"atb":[[1.03,5.93],[14,7]],"id":52385903},{"atb":[[16,6],[1.03,5.93]],"id":52385905},{"atb":[[16,6],[1.01,323.93]],"id":52385899}],"con":true,"img":false}]}
{"op":"mcm","clk":"11550603534","pt":1719500614397,"mc":[{"id":"1.230178172","rc":[{"atb":[[18,13.96]],"id":52385906}],"con":true,"img":false}]}
{"op":"mcm","clk":"11550603541","pt":1719500614501,"mc":[{"id":"1.230178172","rc":[{"atb":[[15.5,17.86]],"id":52385904},{"atb":[[25,9.96]],"id":52385907},{"atb":[[21,11.54]],"id":52385903}],"con":true,"img":false}]}
{"op":"mcm","clk":"11550603625","pt":1719500615792,"mc":[{"id":"1.230178172","rc":[{"atb":[[18,0]],"id":52385906},{"atb":[[15.5,0]],"id":52385904},{"atb":[[25,0]],"id":52385907},{"atb":[[21,0]],"id":52385903}],"con":true,"img":false}]}
{"op":"mcm","clk":"11550616376","pt":1719500820854,"mc":[{"id":"1.230178172","rc":[{"atb":[[7,16]],"id":52385910},{"atl":[[520,2]],"id":52385910},{"atb":[[5.4,22.73]],"id":52385912},{"atl":[[460,2]],"id":52385912},{"atb":[[7,12]],"id":52385906},{"atl":[[520,2]],"id":52385906},{"atb":[[9.4,11.9]],"id":52385918},{"atl":[[600,2]],"id":52385918},{"atb":[[10,10]],"id":52385920},{"atl":[[650,2]],"id":52385920},{"atb":[[5.6,21.74]],"id":52385889},{"atl":[[470,2]],"id":52385889},{"atb":[[7.8,14.71]],"id":52385914},{"atl":[[540,2]],"id":52385914},{"atb":[[6.4,12]],"id":52385883},{"atl":[[510,2]],"id":52385883},{"atb":[[7.2,12]],"id":52385885},{"atl":[[530,2]],"id":52385885},{"atb":[[9.4,11.9]],"id":52385896},{"atl":[[600,2]],"id":52385896},{"atb":[[5.1,24.39]],"id":52385890},{"atl":[[430,2]],"id":52385890},{"atb":[[5.4,20]],"id":52385892},{"atl":[[450,2]],"id":52385892},{"atb":[[7.2,16]],"id":52385904},{"atl":[[530,2]],"id":52385904},{"atb":[[9.4,11.9]],"id":52385898},{"atl":[[600,2]],"id":52385898},{"atb":[[11,10]],"id":52385900},{"atl":[[730,2]],"id":52385900},{"atb":[[5.7,16]],"id":52385911},{"atl":[[480,2]],"id":52385911},{"atb":[[6.4,14]],"id":52385913},{"atl":[[510,2]],"id":52385913},{"atb":[[10,10]],"id":52385907},{"atl":[[640,2]],"id":52385907},{"atb":[[10,11.11]],"id":52385886},{"atl":[[660,2]],"id":52385886},{"atb":[[9,10]],"id":52385919},{"atl":[[580,2]],"id":52385919},{"atb":[[8.6,13.16]],"id":52385921},{"atl":[[560,2]],"id":52385921},{"atb":[[6.2,19.23]],"id":52385882},{"atl":[[500,2]],"id":52385882},{"atb":[[8.6,12]],"id":52385884},{"atl":[[560,2]],"id":52385884},{"atb":[[10.5,10.53]],"id":52385917},{"atl":[[700,2]],"id":52385917},{"atb":[[7.8,14.71]],"id":52385897},{"atl":[[540,2]],"id":52385897},{"atb":[[6.2,19.23]],"id":52385891},{"atl":[[500,2]],"id":52385891},{"atb":[[8.2,13.89]],"id":52385893},{"atl":[[550,2]],"id":52385893},{"atb":[[8.8,12.82]],"id":52385903},{"atl":[[580,2]],"id":52385903},{"atb":[[6.8,12]],"id":52385905},{"atl":[[520,2]],"id":52385905},{"atb":[[8.2,13.89]],"id":52385899},{"atl":[[550,2]],"id":52385899}],"con":true,"img":false}]}
{"op":"mcm","clk":"11550616462","pt":1719500822513,"mc":[{"id":"1.230178172","rc":[{"atl":[[55,4.69]],"id":52385910},{"atl":[[42,5]],"id":52385912},{"atl":[[60,4.99]],"id":52385914},{"atl":[[46,4.95]],"id":52385885},{"atl":[[38,7.76]],"id":52385911},{"atl":[[55,4.89]],"id":52385913}],"con":true,"img":false}]}
{"op":"mcm","clk":"11550616468","pt":1719500822621,"mc":[{"id":"1.230178172","rc":[{"atl":[[46,0]],"id":52385885},{"atl":[[38,0]],"id":52385911}],"con":true,"img":false}]}
{"op":"mcm","clk":"11550616475","pt":1719500822724,"mc":[{"id":"1.230178172","rc":[{"atl":[[55,0]],"id":52385910},{"atl":[[42,0]],"id":52385912},{"atl":[[60,0]],"id":52385914},{"atl":[[55,0]],"id":52385913}],"con":true,"img":false}]}
{"op":"mcm","clk":"11550616538","pt":1719500823606,"mc":[{"id":"1.230178172","rc":[{"atb":[[12.5,13.75]],"id":52385891}],"con":true,"img":false}]}
{"op":"mcm","clk":"11550616679","pt":1719500825729,"mc":[{"id":"1.230178172","rc":[{"atb":[[12.5,0]],"id":52385891}],"con":true,"img":false}]}
{"op":"mcm","clk":"11550617262","pt":1719500835950,"mc":[{"id":"1.230178172","rc":[{"atl":[[570,2],[600,0]],"id":52385918},{"atl":[[610,2]],"id":52385920},{"atl":[[440,2],[470,0]],"id":52385889},{"atl":[[540,0]],"id":52385914},{"atl":[[510,2]],"id":52385885},{"atl":[[430,0]],"id":52385890},{"atl":[[500,2]],"id":52385904},{"atl":[[470,2]],"id":52385913},{"atl":[[600,2]],"id":52385907},{"atl":[[620,2]],"id":52385886},{"atl":[[530,2]],"id":52385921},{"atl":[[470,2]],"id":52385882},{"atl":[[530,2]],"id":52385884},{"atl":[[470,2]],"id":52385891},{"atl":[[530,2],[550,0]],"id":52385893},{"atl":[[490,2]],"id":52385905}],"con":true,"img":false}]}
{"op":"mcm","clk":"11550617269","pt":1719500836051,"mc":[{"id":"1.230178172","rc":[{"atl":[[520,0],[500,2]],"id":52385910},{"atl":[[430,2],[460,0]],"id":52385912},{"atl":[[520,0],[490,2]],"id":52385906},{"atl":[[650,0]],"id":52385920},{"atl":[[520,2]],"id":52385914},{"atl":[[480,2],[510,0]],"id":52385883},{"atl":[[530,0]],"id":52385885},{"atl":[[560,2],[600,0]],"id":52385896},{"atl":[[400,2]],"id":52385890},{"atl":[[430,2],[450,0]],"id":52385892},{"atl":[[530,0]],"id":52385904},{"atl":[[570,2],[600,0]],"id":52385898},{"atl":[[660,2],[730,0]],"id":52385900},{"atl":[[450,2],[480,0]],"id":52385911},{"atl":[[510,0]],"id":52385913},{"atl":[[640,0]],"id":52385907},{"atl":[[660,0]],"id":52385886},{"atl":[[550,2],[580,0]],"id":52385919},{"atl":[[560,0]],"id":52385921},{"atl":[[500,0]],"id":52385882},{"atl":[[560,0]],"id":52385884},{"atl":[[640,2],[700,0]],"id":52385917},{"atl":[[540,0],[520,2]],"id":52385897},{"atl":[[500,0]],"id":52385891},{"atl":[[540,2],[580,0]],"id":52385903},{"atl":[[520,0]],"id":52385905},{"atl":[[530,2],[550,0]],"id":52385899}],"con":true,"img":false}]}
{"op":"mcm","clk":"11550618063","pt":1719500849048,"mc":[{"id":"1.230178172","rc":[{"atl":[[560,0]],"id":52385896},{"atl":[[430,2]],"id":52385911}],"con":true,"img":false}]}
{"op":"mcm","clk":"11550618072","pt":1719500849199,"mc":[{"id":"1.230178172","rc":[{"atb":[[8.2,13.89],[7,0]],"id":52385910},{"atl":[[480,2],[500,0]],"id":52385910},{"atb":[[6,20],[5.4,0]],"id":52385912},{"atl":[[430,0],[420,2]],"id":52385912},{"atb":[[8,12],[7,0]],"id":52385906},{"atl":[[490,0],[480,2]],"id":52385906},{"atb":[[10.5,10.53],[9.4,0]],"id":52385918},{"atl":[[570,0],[550,2]],"id":52385918},{"atl":[[590,2],[610,0]],"id":52385920},{"atb":[[5.6,0],[6,20]],"id":52385889},{"atl":[[430,2],[440,0]],"id":52385889},{"atb":[[9,12.5],[7.8,0]],"id":52385914},{"atl":[[520,0],[510,2]],"id":52385914},{"atb":[[6.4,0],[7.4,12]],"id":52385883},{"atl":[[460,2],[480,0]],"id":52385883},{"atb":[[7.2,0],[8.4,12]],"id":52385885},{"atl":[[490,2],[510,0]],"id":52385885},{"atb":[[10.5,10.53],[9.4,0]],"id":52385896},{"atl":[[550,2]],"id":52385896},{"atb":[[5.6,21.74],[5.1,0]],"id":52385890},{"atl":[[370,2],[400,0]],"id":52385890},{"atb":[[5.9,20],[5.4,0]],"id":52385892},{"atl":[[410,2],[430,0]],"id":52385892},{"atl":[[480,2],[500,0]],"id":52385904},{"atb":[[9.8,11.36],[9.4,0]],"id":52385898},{"atl":[[570,0],[550,2]],"id":52385898},{"atb":[[11,0],[12.5,8.7]],"id":52385900},{"atl":[[660,0],[640,2]],"id":52385900},{"atl":[[450,0]],"id":52385911},{"atb":[[6.4,0],[7.4,14]],"id":52385913},{"atl":[[460,2],[470,0]],"id":52385913},{"atb":[[10,0],[11.5,9.52]],"id":52385907},{"atl":[[600,0],[580,2]],"id":52385907},{"atb":[[10,0],[11.5,9.52]],"id":52385886},{"atl":[[600,2],[620,0]],"id":52385886},{"atb":[[9,0],[10,10]],"id":52385919},{"atl":[[540,2],[550,0]],"id":52385919},{"atb":[[8.6,0],[9.8,11.36]],"id":52385921},{"atl":[[530,0],[520,2]],"id":52385921},{"atb":[[6.2,0],[7,16.67]],"id":52385882},{"atl":[[450,2],[470,0]],"id":52385882},{"atb":[[8.6,0],[9.8,11.36]],"id":52385884},{"atl":[[530,0],[520,2]],"id":52385884},{"atb":[[10.5,0],[12,9.09]],"id":52385917},{"atl":[[620,2],[640,0]],"id":52385917},{"atb":[[8.8,12.82],[7.8,0]],"id":52385897},{"atl":[[520,0],[500,2]],"id":52385897},{"atl":[[440,2],[470,0]],"id":52385891},{"atb":[[9,12.5],[8.2,0]],"id":52385893},{"atl":[[530,0],[510,2]],"id":52385893},{"atb":[[8.8,0],[9.4,11.9]],"id":52385903},{"atl":[[540,0],[530,2]],"id":52385903},{"atb":[[6.8,0],[7.8,12]],"id":52385905},{"atl":[[470,2],[490,0]],"id":52385905},{"atb":[[9.6,11.63],[8.2,0]],"id":52385899},{"atl":[[530,0],[510,2]],"id":52385899}],"con":true,"img":false}]}
{"op":"mcm","clk":"11550618085","pt":1719500849366,"mc":[{"id":"1.230178172","rc":[{"atl":[[430,0],[420,2]],"id":52385889},{"atb":[[10.5,10.53],[9.8,0]],"id":52385898},{"atb":[[10,11.11],[9.4,0]],"id":52385903}],"con":true,"img":false}]}
{"op":"mcm","clk":"11550619201","pt":1719500868158,"mc":[{"id":"1.230178172","rc":[{"atb":[[9,0]],"id":52385889},{"atb":[[15,0]],"id":52385896}],"con":true,"img":false}]}
{"op":"mcm","clk":"11550619209","pt":1719500868269,"mc":[{"id":"1.230178172","rc":[{"atb":[[8,11],[6,0],[3,50]],"id":52385889},{"atb":[[14,6]],"id":52385896}],"con":true,"img":false}]}
{"op":"mcm","clk":"11550619213","pt":1719500868364,"mc":[{"id":"1.230178172","rc":[{"atb":[[10.5,0],[4.1,21.06]],"id":52385896}],"con":true,"img":false}]}
{"op":"mcm","clk":"11550619221","pt":1719500868473,"mc":[{"id":"1.230178172","rc":[{"atb":[[3,0],[6,20]],"id":52385889},{"atb":[[10.5,10.53],[4.1,0]],"id":52385896}],"con":true,"img":false}]}
{"op":"mcm","clk":"11550621480","pt":1719500904245,"mc":[{"id":"1.230178172","rc":[{"atb":[[15,0]],"id":52385906},{"atb":[[16,0]],"id":52385883},{"atb":[[12,0]],"id":52385890}],"con":true,"img":false}]}
{"op":"mcm","clk":"11550621487","pt":1719500904334,"mc":[{"id":"1.230178172","rc":[{"atb":[[14,6]],"id":52385906},{"atb":[[14,6]],"id":52385883},{"atb":[[11,8]],"id":52385890}],"con":true,"img":false}]}
{"op":"mcm","clk":"11550621494","pt":1719500904435,"mc":[{"id":"1.230178172","rc":[{"atb":[[8,0],[3.5,24]],"id":52385906},{"atb":[[7.4,0],[3.35,24]],"id":52385883},{"atb":[[5.6,0],[2.92,52.08]],"id":52385890}],"con":true,"img":false}]}
{"op":"mcm","clk":"11550621498","pt":1719500904540,"mc":[{"id":"1.230178172","rc":[{"atb":[[8,14.29],[3.5,0]],"id":52385906},{"atb":[[3.35,0],[7.4,15.62]],"id":52385883},{"atb":[[5.6,21.74]],"id":52385890}],"con":true,"img":false}]}
{"op":"mcm","clk":"11550621503","pt":1719500904643,"mc":[{"id":"1.230178172","rc":[{"atb":[[2.92,0]],"id":52385890}],"con":true,"img":false}]}
{"op":"mcm","clk":"11550623396","pt":1719500938267,"mc":[{"id":"1.230178172","rc":[{"atl":[[480,0],[500,2]],"id":52385910},{"atl":[[420,0],[430,2]],"id":52385912},{"atl":[[550,0],[570,2]],"id":52385918},{"atl":[[590,0],[610,2]],"id":52385920},{"atl":[[520,2],[510,0]],"id":52385914},{"atl":[[490,0],[510,2]],"id":52385885},{"atl":[[410,0],[430,2]],"id":52385892},{"atl":[[480,0],[500,2]],"id":52385904},{"atl":[[640,0],[660,2]],"id":52385900},{"atl":[[430,0],[450,2]],"id":52385911},{"atl":[[460,0],[470,2]],"id":52385913},{"atl":[[580,0],[600,2]],"id":52385907},{"atl":[[600,0],[620,2]],"id":52385886},{"atl":[[540,0],[550,2]],"id":52385919},{"atl":[[520,0],[530,2]],"id":52385921},{"atl":[[450,0],[470,2]],"id":52385882},{"atl":[[520,0],[530,2]],"id":52385884},{"atl":[[640,2]],"id":52385917},{"atl":[[520,2],[500,0]],"id":52385897},{"atl":[[470,2]],"id":52385891},{"atl":[[530,2],[510,0]],"id":52385893},{"atl":[[470,0],[490,2]],"id":52385905},{"atl":[[530,2],[510,0]],"id":52385899}],"con":true,"img":false}]}
{"op":"mcm","clk":"11550623402","pt":1719500938371,"mc":[{"id":"1.230178172","rc":[{"atl":[[620,0]],"id":52385917},{"atl":[[440,0]],"id":52385891}],"con":true,"img":false}]}
{"op":"mcm","clk":"11550625268","pt":1719500969111,"mc":[{"id":"1.230178172","rc":[{"atb":[[5.5,22.22],[6,0]],"id":52385889},{"atb":[[10.5,0],[9.4,11.9]],"id":52385896},{"atb":[[5.6,0],[5,25]],"id":52385890},{"atb":[[5.3,23.26],[5.9,0]],"id":52385892},{"atb":[[10.5,0],[9.4,11.9]],"id":52385898},{"atb":[[8.6,13.16],[9.8,0]],"id":52385921},{"atb":[[6.2,19.23],[7,0]],"id":52385882},{"atb":[[8.6,13.16],[9.8,0]],"id":52385884},{"atb":[[8.8,0],[7.8,14.71]],"id":52385897},{"atb":[[9,12.5],[10,0]],"id":52385903},{"atb":[[9.6,0],[8.4,13.51]],"id":52385899}],"con":true,"img":false}]}
{"op":"mcm","clk":"11550625568","pt":1719500973188,"mc":[{"id":"1.230178172","rc":[{"atb":[[18,0]],"id":52385886}],"con":true,"img":false}]}
{"op":"mcm","clk":"11550625573","pt":1719500973310,"mc":[{"id":"1.230178172","rc":[{"atb":[[16,5]],"id":52385886}],"con":true,"img":false}]}
{"op":"mcm","clk":"11550625580","pt":1719500973427,"mc":[{"id":"1.230178172","rc":[{"atb":[[4,33.33],[11.5,0]],"id":52385886}],"con":true,"img":false}]}
{"op":"mcm","clk":"11550625586","pt":1719500973534,"mc":[{"id":"1.230178172","rc":[{"atb":[[4,0],[10,11.11]],"id":52385886}],"con":true,"img":false}]}
{"op":"mcm","clk":"11550628301","pt":1719501013667,"mc":[{"id":"1.230178172","rc":[{"atl":[[420,2]],"id":52385892},{"atl":[[440,2]],"id":52385911},{"atl":[[470,0]],"id":52385891},{"atl":[[520,2]],"id":52385893}],"con":true,"img":false}]}
{"op":"mcm","clk":"11550628307","pt":1719501013769,"mc":[{"id":"1.230178172","rc":[{"atl":[[570,0],[560,2]],"id":52385918},{"atl":[[430,0]],"id":52385892},{"atl":[[450,0]],"id":52385911},{"atl":[[460,2]],"id":52385891},{"atl":[[530,0]],"id":52385893}],"con":true,"img":false}]}
{"op":"mcm","clk":"11550628621","pt":1719501018558,"mc":[{"id":"1.230178172","rc":[{"atb":[[14.5,12.5]],"id":52385904}],"con":true,"img":false}]}
{"op":"mcm","clk":"11550628627","pt":1719501018660,"mc":[{"id":"1.230178172","rc":[{"atb":[[17.5,10]],"id":52385906},{"atb":[[24,8.75]],"id":52385907},{"atb":[[19.5,11.25]],"id":52385903}],"con":true,"img":false}]}
{"op":"mcm","clk":"11550628640","pt":1719501018767,"mc":[{"id":"1.230178172","rc":[{"atb":[[17.5,0]],"id":52385906},{"atb":[[14.5,0]],"id":52385904},{"atb":[[24,0]],"id":52385907},{"atb":[[19.5,0]],"id":52385903}],"con":true,"img":false}]}
{"op":"mcm","clk":"11550628785","pt":1719501021248,"mc":[{"id":"1.230178172","rc":[{"atb":[[14,0]],"id":52385896},{"atb":[[12,0]],"id":52385897}],"con":true,"img":false}]}
{"op":"mcm","clk":"11550628791","pt":1719501021351,"mc":[{"id":"1.230178172","rc":[{"atl":[[70,3.17]],"id":52385906},{"atb":[[13,6]],"id":52385896},{"atb":[[11,8]],"id":52385897}],"con":true,"img":false}]}
{"op":"mcm","clk":"11550628798","pt":1719501021455,"mc":[{"id":"1.230178172","rc":[{"atb":[[3.85,23.8],[9.4,0]],"id":52385896},{"atb":[[3.45,29.42],[7.8,0]],"id":52385897}],"con":true,"img":false}]}
{"op":"mcm","clk":"11550628973","pt":1719501024058,"mc":[{"id":"1.230178172","rc":[{"atl":[[70,0]],"id":52385906}],"con":true,"img":false}]}
{"op":"mcm","clk":"11550629339","pt":1719501029547,"mc":[{"id":"1.230178172","rc":[{"atb":[[3.85,0],[9.4,11.9]],"id":52385896},{"atb":[[7.8,14.71]],"id":52385897}],"con":true,"img":false}]}
{"op":"mcm","clk":"11550629344","pt":1719501029647,"mc":[{"id":"1.230178172","rc":[{"atb":[[3.45,0]],"id":52385897}],"con":true,"img":false}]}
{"op":"mcm","clk":"11550632720","pt":1719501083854,"mc":[{"id":"1.230178172","rc":[{"atl":[[40,5.37]],"id":52385885}],"con":true,"img":false}]}
{"op":"mcm","clk":"11550632732","pt":1719501084008,"mc":[{"id":"1.230178172","rc":[{"atl":[[40,0]],"id":52385885}],"con":true,"img":false}]}
{"op":"mcm","clk":"11550634290","pt":1719501111237,"mc":[{"id":"1.230178172","rc":[{"atb":[[13,0]],"id":52385910},{"atb":[[16,0]],"id":52385912},{"atb":[[13,0]],"id":52385914},{"atb":[[10,0]],"id":52385892},{"atb":[[13,0]],"id":52385904},{"atb":[[14,0]],"id":52385898},{"atb":[[13,0]],"id":52385911},{"atb":[[14,0]],"id":52385913},{"atb":[[18,0]],"id":52385907},{"atb":[[11,0]],"id":52385891},{"atb":[[14,0]],"id":52385903},{"atb":[[16,0]],"id":52385905}],"con":true,"img":false}]}
{"op":"mcm","clk":"11550634301","pt":1719501111343,"mc":[{"id":"1.230178172","rc":[{"atb":[[16,8],[8.2,0],[3.3,27.78]],"id":52385910},{"atb":[[19,6],[2.9,52.63],[6,0]],"id":52385912},{"atb":[[16,8],[9,0],[3.5,40]],"id":52385914},{"atb":[[2.86,53.76],[5.3,0],[11,10]],"id":52385892},{"atb":[[16,8],[7.2,0],[3.3,32]],"id":52385904},{"atb":[[16,7],[3.85,23.8],[9.4,0]],"id":52385898},{"atb":[[16,8],[2.92,52.08],[5.7,0]],"id":52385911},{"atb":[[19,7],[3.15,28]],"id":52385913},{"atb":[[4,19.04],[20,5],[11.5,0]],"id":52385907},{"atb":[[6.2,0],[12,9],[3,50]],"id":52385891},{"atb":[[16,7],[9,0],[3.75,25]],"id":52385903},{"atb":[[20,6],[3.25,24],[7.8,0]],"id":52385905}],"con":true,"img":false}]}
{"op":"mcm","clk":"11550634312","pt":1719501111449,"mc":[{"id":"1.230178172","rc":[{"atb":[[2.9,0],[5.5,22.22]],"id":52385912},{"atb":[[7.4,0]],"id":52385913},{"atb":[[7,16.67]],"id":52385905}],"con":true,"img":false}]}
{"op":"mcm","clk":"11550634321","pt":1719501111553,"mc":[{"id":"1.230178172","rc":[{"atb":[[3.25,0]],"id":52385905}],"con":true,"img":false}]}
{"op":"mcm","clk":"11550634698","pt":1719501118566,"mc":[{"id":"1.230178172","rc":[{"atb":[[7.2,16.13],[3.3,0]],"id":52385910},{"atb":[[8,14.29],[3.5,0]],"id":52385914},{"atb":[[2.86,0],[5.3,23.26]],"id":52385892},{"atb":[[7.2,16.13],[3.3,0]],"id":52385904},{"atb":[[3.85,0],[9.4,11.9]],"id":52385898},{"atb":[[5.6,21.74],[2.92,0]],"id":52385911},{"atb":[[3.15,0],[6.6,17.86]],"id":52385913},{"atb":[[4,0],[10,11.11]],"id":52385907},{"atb":[[3,0],[6,20]],"id":52385891},{"atb":[[9,12.5],[3.75,0]],"id":52385903}],"con":true,"img":false}]}
{"op":"mcm","clk":"11550634961","pt":1719501123273,"mc":[{"id":"1.230178172","rc":[{"atb":[[16,0]],"id":52385921}],"con":true,"img":false}]}
{"op":"mcm","clk":"11550634968","pt":1719501123385,"mc":[{"id":"1.230178172","rc":[{"atb":[[8.6,0],[19,6],[3.65,37.74]],"id":52385921}],"con":true,"img":false}]}
{"op":"mcm","clk":"11550634979","pt":1719501123585,"mc":[{"id":"1.230178172","rc":[{"atb":[[8.6,13.16],[3.65,0]],"id":52385921}],"con":true,"img":false}]}
{"op":"mcm","clk":"11550635188","pt":1719501127374,"mc":[{"id":"1.230178172","rc":[{"atb":[[1.31,100]],"id":52385896},{"atb":[[1.31,100]],"id":52385882},{"atb":[[1.31,100]],"id":52385897},{"atb":[[1.31,100]],"id":52385891},{"atb":[[1.31,100]],"id":52385893},{"atb":[[1.31,100]],"id":52385899}],"con":true,"img":false}]}
{"op":"mcm","clk":"11550635193","pt":1719501127471,"mc":[{"id":"1.230178172","rc":[{"atb":[[1.31,100]],"id":52385914}],"con":true,"img":false}]}
{"op":"mcm","clk":"11550635199","pt":1719501127577,"mc":[{"id":"1.230178172","rc":[{"atb":[[1.31,100]],"id":52385918},{"atb":[[1.31,100]],"id":52385920},{"atb":[[1.31,100]],"id":52385885},{"atb":[[1.31,100]],"id":52385904},{"atb":[[1.31,100]],"id":52385898},{"atb":[[1.31,100]],"id":52385900},{"atb":[[1.31,100]],"id":52385919},{"atb":[[1.31,100]],"id":52385905}],"con":true,"img":false}]}
{"op":"mcm","clk":"11550635205","pt":1719501127681,"mc":[{"id":"1.230178172","rc":[{"atb":[[1.31,100]],"id":52385910},{"atb":[[1.31,100]],"id":52385921}],"con":true,"img":false}]}
{"op":"mcm","clk":"11550635240","pt":1719501128375,"mc":[{"id":"1.230178172","rc":[{"atb":[[1.31,100]],"id":52385890},{"atb":[[1.31,100]],"id":52385892},{"atb":[[1.31,100]],"id":52385886},{"atb":[[1.31,100]],"id":52385884},{"atb":[[1.31,100]],"id":52385903}],"con":true,"img":false}]}
{"op":"mcm","clk":"11550635246","pt":1719501128480,"mc":[{"id":"1.230178172","rc":[{"atb":[[1.31,100]],"id":52385911},{"atb":[[1.31,100]],"id":52385913},{"atb":[[1.31,100]],"id":52385907}],"con":true,"img":false}]}
{"op":"mcm","clk":"11550635257","pt":1719501128690,"mc":[{"id":"1.230178172","rc":[{"atb":[[1.31,100]],"id":52385889}],"con":true,"img":false}]}
{"op":"mcm","clk":"11550635262","pt":1719501128794,"mc":[{"id":"1.230178172","rc":[{"atb":[[1.31,100]],"id":52385917}],"con":true,"img":false}]}
{"op":"mcm","clk":"11550635276","pt":1719501128952,"mc":[{"id":"1.230178172","rc":[{"atb":[[1.31,100]],"id":52385912}],"con":true,"img":false}]}
{"op":"mcm","clk":"11550635404","pt":1719501131367,"mc":[{"id":"1.230178172","rc":[{"atb":[[1.31,100]],"id":52385883}],"con":true,"img":false}]}
{"op":"mcm","clk":"11550635413","pt":1719501131471,"mc":[{"id":"1.230178172","rc":[{"atb":[[1.31,100]],"id":52385906}],"con":true,"img":false}]}
{"op":"mcm","clk":"11550635821","pt":1719501138302,"mc":[{"id":"1.230178172","rc":[{"atb":[[16,0]],"id":52385918},{"atb":[[19,0]],"id":52385921},{"atb":[[19,0]],"id":52385917},{"atb":[[13,0]],"id":52385893},{"atb":[[16,0]],"id":52385899}],"con":true,"img":false}]}
{"op":"mcm","clk":"11550635827","pt":1719501138400,"mc":[{"id":"1.230178172","rc":[{"atb":[[10.5,0],[3.8,35.71],[14,6]],"id":52385918},{"atb":[[16,6],[3.65,37.74]],"id":52385921},{"atb":[[16,5],[4.1,32.26],[12,0]],"id":52385917},{"atb":[[9,0],[12,8],[3.5,40]],"id":52385893},{"atb":[[3.6,38.46],[18,6]],"id":52385899}],"con":true,"img":false}]}
{"op":"mcm","clk":"11550635831","pt":1719501138510,"mc":[{"id":"1.230178172","rc":[{"atb":[[8.6,0]],"id":52385921},{"atb":[[8.4,0]],"id":52385899}],"con":true,"img":false}]}
{"op":"mcm","clk":"11550635942","pt":1719501140730,"mc":[{"id":"1.230178172","rc":[{"atb":[[8.6,13.16],[10,0]],"id":52385919}],"con":true,"img":false}]}
{"op":"mcm","clk":"11550635948","pt":1719501140794,"mc":[{"id":"1.230178172","rc":[{"atb":[[8,0],[6.6,17.86]],"id":52385906},{"atb":[[6.2,19.23],[7.4,0]],"id":52385883},{"atb":[[7,16.67],[8.4,0]],"id":52385885},{"atb":[[10,11.11],[12.5,0]],"id":52385900}],"con":true,"img":false}]}
{"op":"mcm","clk":"11550636031","pt":1719501142037,"mc":[{"id":"1.230178172","rc":[{"atb":[[19,25]],"id":52385913},{"atl":[[460,1.31]],"id":52385913}],"con":true,"img":false}]}
{"op":"mcm","clk":"11550636038","pt":1719501142140,"mc":[{"id":"1.230178172","rc":[{"atb":[[16.5,20],[10,5],[12,2.5]],"id":52385910},{"atl":[[80,5],[60,2.5],[490,1.23]],"id":52385910},{"atb":[[8,2.5],[7.2,5]],"id":52385912},{"atl":[[65,2.5],[85,5],[420,1.43]],"id":52385912},{"atb":[[12,5],[14,8.5],[14.5,16]],"id":52385906},{"atl":[[65,2.5],[85,5],[470,1.28]],"id":52385906},{"atb":[[8,2.5],[7.2,5],[14.5,16]],"id":52385918},{"atl":[[65,2.5],[550,1.09],[85,5]],"id":52385918},{"atb":[[9.6,5],[21,14],[11,2.5]],"id":52385920},{"atl":[[600,1],[80,2.5],[100,5]],"id":52385920},{"atb":[[10.5,2.5],[5.5,0],[8.2,26],[5.9,20.41],[9.4,5]],"id":52385889},{"atl":[[36,2.5],[44,5],[410,1.47]],"id":52385889},{"atb":[[16.5,20],[10,5],[12,2.5]],"id":52385914},{"atl":[[65,5],[48,2.5],[510,1.18]],"id":52385914},{"atb":[[11,5],[13,2.5],[14.5,16]],"id":52385883},{"atl":[[80,5],[450,1.34],[60,2.5]],"id":52385883},{"atb":[[16.5,16],[12,5],[14,2.5]],"id":52385885},{"atl":[[75,5],[55,2.5],[500,1.2]],"id":52385885},{"atb":[[18,5],[20,2.5],[10,11.11],[13.5,16],[9.4,0]],"id":52385896},{"atl":[[540,1.11],[70,2.5],[90,5]],"id":52385896},{"atb":[[8,5],[11,28],[8.8,2.5]],"id":52385890},{"atl":[[38,2.5],[360,1.67],[46,5]],"id":52385890},{"atb":[[9.6,2.5],[11.5,24],[8.8,5]],"id":52385892},{"atl":[[36,2.5],[44,5],[410,1.47]],"id":52385892},{"atb":[[16.5,20],[11.5,5],[13.5,2.5]],"id":52385904},{"atl":[[70,5],[50,2.5],[490,1.23]],"id":52385904},{"atb":[[16.5,18],[18,5],[20,2.5],[10,11.11],[9.4,0]],"id":52385898},{"atl":[[540,1.11],[75,2.5],[95,5]],"id":52385898},{"atb":[[17.5,16],[10,0],[11.5,9.52],[12,5],[14,2.5]],"id":52385900},{"atl":[[650,0.92],[90,2.5],[120,5]],"id":52385900},{"atb":[[16,28],[10.5,2.5],[9.4,5]],"id":52385911},{"atl":[[46,2.5],[430,1.4],[60,5]],"id":52385911},{"atb":[[3.2,45.45],[11.5,2.5],[9.8,5],[6.6,0]],"id":52385913},{"atl":[[65,2.5],[85,5]],"id":52385913},{"atb":[[16.5,5],[18.5,2.5],[21,14]],"id":52385907},{"atl":[[75,2.5],[590,1.02],[95,5]],"id":52385907},{"atb":[[16.5,14],[10,0],[11,10],[13,5],[15,2.5]],"id":52385886},{"atl":[[610,0.99],[80,2.5],[100,5]],"id":52385886},{"atb":[[9.6,11.63],[8.6,0],[21,14],[11,5],[13,2.5]],"id":52385919},{"atl":[[65,2.5],[540,1.11],[85,5]],"id":52385919},{"atb":[[16.5,16],[10.5,5],[12.5,2.5]],"id":52385921},{"atl":[[520,1.16],[80,5],[60,2.5]],"id":52385921},{"atb":[[9.2,26],[10.5,5],[12.5,2.5]],"id":52385882},{"atl":[[44,2.5],[55,5],[460,1.31]],"id":52385882},{"atb":[[16,5],[17.5,16],[18,2.5]],"id":52385884},{"atl":[[65,2.5],[520,1.16],[85,5]],"id":52385884},{"atb":[[16.5,14],[9,5],[9.8,2.5]],"id":52385917},{"atl":[[630,0.95],[90,2.5],[120,5]],"id":52385917},{"atb":[[16,2.5],[11.5,20],[7.8,0],[14,5],[8.4,13.51]],"id":52385897},{"atl":[[75,5],[55,2.5],[510,1.18]],"id":52385897},{"atb":[[9.6,5],[11,2.5],[12.5,22]],"id":52385891},{"atl":[[38,2.5],[46,5],[450,1.34]],"id":52385891},{"atb":[[8.2,2.5],[7.4,5],[12.5,20]],"id":52385893},{"atl":[[75,5],[55,2.5],[510,1.18]],"id":52385893},{"atb":[[16.5,18],[18,5],[20,2.5]],"id":52385903},{"atl":[[65,2.5],[520,1.16],[85,5]],"id":52385903},{"atb":[[20,22],[10.5,2.5],[9.4,5]],"id":52385905},{"atl":[[70,2.5],[90,5],[480,1.25]],"id":52385905},{"atb":[[18.5,16],[13.5,5],[15.5,2.5]],"id":52385899},{"atl":[[520,1.16],[70,2.5],[90,5]],"id":52385899}],"con":true,"img":false}]}
{"op":"mcm","clk":"11550636050","pt":1719501142297,"mc":[{"id":"1.230178172","rc":[{"atl":[[110,2],[500,0]],"id":52385910},{"atl":[[75,2],[430,0]],"id":52385912},{"atl":[[110,2],[480,0]],"id":52385906},{"atl":[[560,0],[180,2]],"id":52385918},{"atl":[[610,0],[230,2]],"id":52385920},{"atl":[[80,2],[420,0]],"id":52385889},{"atl":[[520,0],[130,2]],"id":52385914},{"atl":[[100,2],[460,0]],"id":52385883},{"atl":[[120,2],[510,0]],"id":52385885},{"atl":[[550,0],[180,2]],"id":52385896},{"atl":[[370,0],[60,2]],"id":52385890},{"atl":[[70,2],[420,0]],"id":52385892},{"atl":[[120,2],[500,0]],"id":52385904},{"atl":[[550,0],[180,2]],"id":52385898},{"atl":[[290,2],[660,0]],"id":52385900},{"atl":[[80,2],[440,0]],"id":52385911},{"atl":[[95,2],[470,0]],"id":52385913},{"atl":[[600,0],[220,2]],"id":52385907},{"atl":[[620,0],[240,2]],"id":52385886},{"atl":[[550,0],[170,2]],"id":52385919},{"atl":[[530,0],[150,2]],"id":52385921},{"atl":[[95,2],[470,0]],"id":52385882},{"atl":[[530,0],[150,2]],"id":52385884},{"atl":[[270,2],[640,0]],"id":52385917},{"atl":[[520,0],[130,2]],"id":52385897},{"atl":[[90,2],[460,0]],"id":52385891},{"atl":[[520,0],[140,2]],"id":52385893},{"atl":[[530,0],[160,2]],"id":52385903},{"atl":[[110,2],[490,0]],"id":52385905},{"atl":[[530,0],[140,2]],"id":52385899}],"con":true,"img":false}]}
{"op":"mcm","clk":"11550636054","pt":1719501142401,"mc":[{"id":"1.230178172","rc":[{"atl":[[110,0],[490,3.23]],"id":52385910},{"atl":[[75,0],[420,3.43]],"id":52385912},{"atl":[[110,0],[470,3.28]],"id":52385906},{"atl":[[550,3.09],[180,0]],"id":52385918},{"atl":[[230,0]],"id":52385920},{"atl":[[80,0],[410,3.47]],"id":52385889},{"atl":[[130,0],[510,3.18]],"id":52385914},{"atl":[[100,0],[450,3.34]],"id":52385883},{"atl":[[120,0],[500,3.2]],"id":52385885},{"atl":[[540,3.11],[180,0]],"id":52385896},{"atl":[[360,3.67],[60,0]],"id":52385890},{"atl":[[70,0],[410,3.47]],"id":52385892},{"atl":[[490,3.23]],"id":52385904},{"atl":[[540,3.11],[180,0]],"id":52385898},{"atl":[[290,0],[650,2.92]],"id":52385900},{"atl":[[80,0],[430,3.4]],"id":52385911},{"atl":[[95,0],[460,3.31]],"id":52385913},{"atl":[[590,3.02],[220,0]],"id":52385907},{"atl":[[610,2.99],[240,0]],"id":52385886},{"atl":[[540,3.11],[170,0]],"id":52385919},{"atl":[[520,3.16],[150,0]],"id":52385921},{"atl":[[95,0],[460,3.31]],"id":52385882},{"atl":[[520,3.16],[150,0]],"id":52385884},{"atl":[[270,0],[630,2.95]],"id":52385917},{"atl":[[130,0],[510,3.18]],"id":52385897},{"atl":[[90,0],[450,3.34]],"id":52385891},{"atl":[[140,0],[510,3.18]],"id":52385893},{"atl":[[520,3.16],[160,0]],"id":52385903},{"atl":[[110,0],[480,3.25]],"id":52385905},{"atl":[[520,3.16],[140,0]],"id":52385899}],"con":true,"img":false}]}
{"op":"mcm","clk":"11550636061","pt":1719501142504,"mc":[{"id":"1.230178172","rc":[{"atl":[[110,2],[490,1.23]],"id":52385910},{"atl":[[85,7],[420,1.43]],"id":52385912},{"atl":[[110,2],[470,1.28]],"id":52385906},{"atl":[[180,2]],"id":52385918},{"atl":[[600,3]],"id":52385920},{"atl":[[80,2],[410,1.47]],"id":52385889},{"atl":[[100,2],[450,1.34]],"id":52385883},{"atl":[[120,2]],"id":52385885},{"atl":[[60,2]],"id":52385890},{"atl":[[70,2]],"id":52385892},{"atl":[[120,0]],"id":52385904},{"atl":[[540,1.11]],"id":52385898},{"atl":[[290,2],[650,0.92]],"id":52385900},{"atl":[[430,1.4]],"id":52385911},{"atl":[[95,2]],"id":52385913},{"atl":[[590,1.02],[220,2]],"id":52385907},{"atl":[[610,0.99]],"id":52385886},{"atl":[[540,1.11]],"id":52385919},{"atl":[[95,2],[460,1.31]],"id":52385882},{"atl":[[520,1.16],[150,2]],"id":52385884},{"atl":[[270,2],[630,0.95]],"id":52385917},{"atl":[[130,2],[510,1.18]],"id":52385897},{"atl":[[90,2],[450,1.34]],"id":52385891},{"atl":[[140,2],[510,1.18]],"id":52385893},{"atl":[[110,2],[480,1.25]],"id":52385905},{"atl":[[520,1.16]],"id":52385899}],"con":true,"img":false}]}
{"op":"mcm","clk":"11550636064","pt":1719501142600,"mc":[{"id":"1.230178172","rc":[{"atl":[[550,1.09]],"id":52385918},{"atl":[[130,2],[510,1.18]],"id":52385914},{"atl":[[500,1.2]],"id":52385885},{"atl":[[540,1.11],[180,2]],"id":52385896},{"atl":[[410,1.47]],"id":52385892},{"atl":[[180,2]],"id":52385898},{"atl":[[80,2]],"id":52385911},{"atl":[[460,1.31]],"id":52385913},{"atl":[[240,2]],"id":52385886},{"atl":[[170,2]],"id":52385919},{"atl":[[520,1.16],[150,2]],"id":52385921},{"atl":[[520,1.16],[160,2]],"id":52385903},{"atl":[[140,2]],"id":52385899}],"con":true,"img":false}]}
{"op":"mcm","clk":"11550636066","pt":1719501142706,"mc":[{"id":"1.230178172","rc":[{"atb":[[5.5,0],[6,20]],"id":52385912},{"atl":[[85,5],[420,3.43]],"id":52385912},{"atb":[[6.6,0],[7.8,14.71]],"id":52385906},{"atb":[[6.2,0],[7.4,15.62]],"id":52385883},{"atb":[[8.2,13.89],[7,0]],"id":52385885},{"atb":[[5,0],[5.7,21.28]],"id":52385890},{"atl":[[360,1.67]],"id":52385890},{"atb":[[5.3,0],[6,20]],"id":52385892},{"atb":[[7.2,0],[8.2,13.89]],"id":52385904},{"atl":[[490,1.23],[120,2]],"id":52385904},{"atb":[[5.6,0],[6.4,18.52]],"id":52385911},{"atb":[[8.6,0],[9.8,11.36]],"id":52385884},{"atb":[[6,0],[7,16.67]],"id":52385891},{"atb":[[9,0],[10,11.11]],"id":52385903}],"con":true,"img":false}]}
{"op":"mcm","clk":"11550636071","pt":1719501142819,"mc":[{"id":"1.230178172","rc":[{"atb":[[8.2,13.89]],"id":52385910},{"atb":[[8,0],[9,12.5]],"id":52385914}],"con":true,"img":false}]}
{"op":"mcm","clk":"11550636076","pt":1719501142916,"mc":[{"id":"1.230178172","rc":[{"atb":[[7.2,0]],"id":52385910}],"con":true,"img":false}]}
{"op":"mcm","clk":"11550636104","pt":1719501143177,"mc":[{"id":"1.230178172","rc":[{"atb":[[9,0]],"id":52385882}],"con":true,"img":false}]}
{"op":"mcm","clk":"11550636120","pt":1719501143505,"mc":[{"id":"1.230178172","rc":[{"atb":[[8,0]],"id":52385889}],"con":true,"img":false}]}
{"op":"mcm","clk":"11550636137","pt":1719501143702,"mc":[{"id":"1.230178172","rc":[{"atb":[[13,0]],"id":52385896}],"con":true,"img":false}]}
{"op":"mcm","clk":"11550636146","pt":1719501143808,"mc":[{"id":"1.230178172","rc":[{"atb":[[23,9.38]],"id":52385896}],"con":true,"img":false}]}
{"op":"mcm","clk":"11550636164","pt":1719501144019,"mc":[{"id":"1.230178172","rc":[{"atb":[[23,0]],"id":52385896},{"atb":[[11,0]],"id":52385897}],"con":true,"img":false}]}
{"op":"mcm","clk":"11550636184","pt":1719501144324,"mc":[{"id":"1.230178172","rc":[{"atb":[[16,0]],"id":52385898}],"con":true,"img":false}]}
{"op":"mcm","clk":"11550636198","pt":1719501144495,"mc":[{"id":"1.230178172","rc":[{"atb":[[16,0]],"id":52385903}],"con":true,"img":false}]}
{"op":"mcm","clk":"11550636217","pt":1719501144799,"mc":[{"id":"1.230178172","rc":[{"atb":[[14,2.5]],"id":52385906}],"con":true,"img":false}]}
{"op":"mcm","clk":"11550636222","pt":1719501144899,"mc":[{"id":"1.230178172","rc":[{"atb":[[20,6]],"id":52385906}],"con":true,"img":false}]}
{"op":"mcm","clk":"11550636244","pt":1719501145316,"mc":[{"id":"1.230178172","rc":[{"atb":[[12,9.09]],"id":52385917},{"atb":[[12,0]],"id":52385891},{"atb":[[9.6,11.63]],"id":52385899}],"con":true,"img":false}]}
{"op":"mcm","clk":"11550636253","pt":1719501145416,"mc":[{"id":"1.230178172","rc":[{"atb":[[10.5,10.53],[3.8,0]],"id":52385918},{"atb":[[9.8,11.36],[3.65,0]],"id":52385921},{"atb":[[4.1,0]],"id":52385917},{"atb":[[11,11.5]],"id":52385891},{"atb":[[9,12.5],[3.5,0]],"id":52385893},{"atb":[[3.6,0]],"id":52385899}],"con":true,"img":false}]}
{"op":"mcm","clk":"11550636314","pt":1719501146221,"mc":[{"id":"1.230178172","rc":[{"atb":[[6,2]],"id":52385910},{"atb":[[6,22]],"id":52385912},{"atb":[[6,2]],"id":52385906},{"atb":[[6,2]],"id":52385918},{"atb":[[6,2]],"id":52385920},{"atb":[[6,2]],"id":52385889},{"atb":[[6,2]],"id":52385914},{"atb":[[6,2]],"id":52385883},{"atb":[[6,2]],"id":52385885},{"atb":[[6,2]],"id":52385896},{"atb":[[6,2]],"id":52385890},{"atb":[[6,22]],"id":52385892},{"atb":[[6,2]],"id":52385904},{"atb":[[6,2]],"id":52385898},{"atb":[[6,2]],"id":52385900},{"atb":[[6,2]],"id":52385911},{"atb":[[6,2]],"id":52385913},{"atb":[[6,2]],"id":52385907},{"atb":[[6,2]],"id":52385886},{"atb":[[6,2]],"id":52385919},{"atb":[[6,2]],"id":52385921},{"atb":[[6,2]],"id":52385882},{"atb":[[6,2]],"id":52385884},{"atb":[[6,2]],"id":52385917},{"atb":[[6,2]],"id":52385897},{"atb":[[6,2]],"id":52385891},{"atb":[[6,2]],"id":52385893},{"atb":[[6,2]],"id":52385903},{"atb":[[6,2]],"id":52385905},{"atb":[[6,2]],"id":52385899}],"con":true,"img":false}]}
{"op":"mcm","clk":"11550636507","pt":1719501149109,"mc":[{"id":"1.230178172","rc":[{"atb":[[11.5,0],[12.5,8.7]],"id":52385900},{"atb":[[3.2,0],[7.4,10]],"id":52385913}],"con":true,"img":false}]}
{"op":"mcm","clk":"11550636518","pt":1719501149321,"mc":[{"id":"1.230178172","rc":[{"atb":[[12,0]],"id":52385893}],"con":true,"img":false}]}
{"op":"mcm","clk":"11550636524","pt":1719501149422,"mc":[{"id":"1.230178172","rc":[{"atb":[[11,8]],"id":52385893}],"con":true,"img":false}]}
{"op":"mcm","clk":"11550636529","pt":1719501149523,"mc":[{"id":"1.230178172","rc":[{"atb":[[9,0],[8.2,16.39]],"id":52385893}],"con":true,"img":false}]}
{"op":"mcm","clk":"11550636801","pt":1719501153307,"mc":[{"id":"1.230178172","rc":[{"atb":[[14,0]],"id":52385918}],"con":true,"img":false}]}
{"op":"mcm","clk":"11550636808","pt":1719501153407,"mc":[{"id":"1.230178172","rc":[{"atb":[[16,6]],"id":52385918}],"con":true,"img":false}]}
{"op":"mcm","clk":"11550636815","pt":1719501153513,"mc":[{"id":"1.230178172","rc":[{"atb":[[8,16.79],[10.5,0]],"id":52385918}],"con":true,"img":false}]}
{"op":"mcm","clk":"11550636824","pt":1719501153618,"mc":[{"id":"1.230178172","rc":[{"atb":[[8,2.5],[10.5,10.53]],"id":52385918}],"con":true,"img":false}]}
{"op":"mcm","clk":"11550636922","pt":1719501155009,"mc":[{"id":"1.230178172","rc":[{"atb":[[8,10],[7,0]],"id":52385905}],"con":true,"img":false}]}
{"op":"mcm","clk":"11550637001","pt":1719501156291,"mc":[{"id":"1.230178172","rc":[{"atb":[[8.2,2.5],[8.8,12.82]],"id":52385893}],"con":true,"img":false}]}
{"op":"mcm","clk":"11550637027","pt":1719501156703,"mc":[{"id":"1.230178172","rc":[{"atl":[[42,14.63]],"id":52385913}],"con":true,"img":false}]}
{"op":"mcm","clk":"11550637039","pt":1719501156809,"mc":[{"id":"1.230178172","rc":[{"atb":[[21,15]],"id":52385910},{"atl":[[38,15]],"id":52385910},{"atl":[[40,15.38]],"id":52385912},{"atb":[[21,15]],"id":52385906},{"atl":[[60,10.17]],"id":52385906},{"atb":[[17.5,22]],"id":52385918},{"atl":[[60,10.17]],"id":52385918},{"atb":[[29,16]],"id":52385920},{"atl":[[75,8.11]],"id":52385920},{"atb":[[15,15]],"id":52385889},{"atl":[[26,15]],"id":52385889},{"atb":[[20,15]],"id":52385914},{"atl":[[46,13.33]],"id":52385914},{"atl":[[55,11.11]],"id":52385883},{"atb":[[21,15]],"id":52385885},{"atl":[[36,15]],"id":52385885},{"atb":[[29,15]],"id":52385896},{"atl":[[65,9.38]],"id":52385896},{"atl":[[23,15]],"id":52385890},{"atb":[[13,15]],"id":52385892},{"atl":[[22,15]],"id":52385892},{"atb":[[18.5,15]],"id":52385904},{"atl":[[34,15]],"id":52385904},{"atb":[[30,15]],"id":52385898},{"atl":[[70,8.7]],"id":52385898},{"atb":[[29,15]],"id":52385900},{"atl":[[85,7.14]],"id":52385900},{"atl":[[27,15]],"id":52385911},{"atl":[[460,0]],"id":52385913},{"atb":[[29,15]],"id":52385907},{"atl":[[70,8.7]],"id":52385907},{"atb":[[26,15]],"id":52385886},{"atl":[[75,8.11]],"id":52385886},{"atb":[[30,15]],"id":52385919},{"atl":[[60,10.17]],"id":52385919},{"atb":[[22,15]],"id":52385921},{"atl":[[55,11.11]],"id":52385921},{"atb":[[17,15]],"id":52385882},{"atl":[[42,14.63]],"id":52385882},{"atb":[[28,15]],"id":52385884},{"atl":[[60,10.17]],"id":52385884},{"atb":[[27,20]],"id":52385917},{"atl":[[85,7.14]],"id":52385917},{"atb":[[20,15]],"id":52385897},{"atl":[[48,12.77]],"id":52385897},{"atb":[[16,20]],"id":52385891},{"atl":[[29,20]],"id":52385891},{"atb":[[16,26]],"id":52385893},{"atl":[[38,16.22]],"id":52385893},{"atb":[[28,15]],"id":52385903},{"atl":[[60,10.17]],"id":52385903},{"atl":[[65,9.38]],"id":52385905},{"atb":[[25,15]],"id":52385899},{"atl":[[65,9.38]],"id":52385899}],"con":true,"img":false}]}
{"op":"mcm","clk":"11550637046","pt":1719501156910,"mc":[{"id":"1.230178172","rc":[{"atl":[[85,7],[420,2]],"id":52385912},{"atb":[[14.5,0]],"id":52385906},{"atl":[[470,0]],"id":52385906},{"atb":[[14.5,0]],"id":52385918},{"atl":[[550,0]],"id":52385918},{"atb":[[21,0]],"id":52385920},{"atl":[[600,0],[240,2]],"id":52385920},{"atb":[[16.5,0]],"id":52385914},{"atl":[[510,0]],"id":52385914},{"atl":[[450,0]],"id":52385883},{"atb":[[13.5,0]],"id":52385896},{"atl":[[540,0]],"id":52385896},{"atl":[[360,0],[50,2.04],[60,0]],"id":52385890},{"atb":[[11.5,0]],"id":52385892},{"atl":[[410,0]],"id":52385892},{"atb":[[16.5,0]],"id":52385898},{"atl":[[540,0]],"id":52385898},{"atb":[[17.5,0]],"id":52385900},{"atl":[[650,0]],"id":52385900},{"atl":[[430,0]],"id":52385911},{"atb":[[21,0]],"id":52385919},{"atl":[[540,0]],"id":52385919},{"atb":[[9.2,0]],"id":52385882},{"atl":[[460,0]],"id":52385882},{"atb":[[16.5,0]],"id":52385917},{"atl":[[630,0]],"id":52385917},{"atb":[[11.5,0]],"id":52385897},{"atl":[[510,0]],"id":52385897},{"atb":[[12.5,0]],"id":52385891},{"atl":[[450,0]],"id":52385891},{"atb":[[12.5,0]],"id":52385893},{"atl":[[510,0]],"id":52385893},{"atb":[[16.5,0]],"id":52385903},{"atl":[[520,0]],"id":52385903},{"atl":[[480,0]],"id":52385905},{"atb":[[18.5,0]],"id":52385899},{"atl":[[520,0]],"id":52385899}],"con":true,"img":false}]}
{"op":"mcm","clk":"11550637054","pt":1719501157011,"mc":[{"id":"1.230178172","rc":[{"atb":[[16.5,0]],"id":52385910},{"atl":[[490,0]],"id":52385910},{"atl":[[420,0]],"id":52385912},{"atb":[[8.2,0]],"id":52385889},{"atl":[[410,0]],"id":52385889},{"atb":[[16.5,0]],"id":52385885},{"atl":[[500,0]],"id":52385885},{"atb":[[16.5,0]],"id":52385904},{"atl":[[490,0]],"id":52385904},{"atb":[[21,0]],"id":52385907},{"atl":[[590,0]],"id":52385907},{"atb":[[16.5,0]],"id":52385886},{"atl":[[610,0]],"id":52385886},{"atb":[[16.5,0]],"id":52385921},{"atl":[[520,0]],"id":52385921},{"atb":[[17.5,0]],"id":52385884},{"atl":[[520,0]],"id":52385884}],"con":true,"img":false}]}
{"op":"mcm","clk":"11550637071","pt":1719501157218,"mc":[{"id":"1.230178172","rc":[{"atb":[[17,0]],"id":52385884}],"con":true,"img":false}]}
{"op":"mcm","clk":"11550637148","pt":1719501158612,"mc":[{"id":"1.230178172","rc":[{"atb":[[8.2,0],[7,16]],"id":52385910},{"atb":[[6,2],[5.4,22.73]],"id":52385912},{"atl":[[150,2],[180,0]],"id":52385918},{"atl":[[190,2],[240,0]],"id":52385920},{"atb":[[5.2,23.81],[5.9,0]],"id":52385889},{"atb":[[22,22]],"id":52385883},{"atl":[[36,0]],"id":52385885},{"atb":[[10,0],[8.8,12.82]],"id":52385896},{"atb":[[4.9,25.64],[5.7,0]],"id":52385890},{"atb":[[5.1,24.39],[6,2]],"id":52385892},{"atb":[[8.2,0],[7,16]],"id":52385904},{"atb":[[10,0],[8.8,12.82]],"id":52385898},{"atb":[[5.5,22.22]],"id":52385911},{"atb":[[30,0]],"id":52385919},{"atl":[[140,2],[170,0]],"id":52385919},{"atb":[[9.8,0],[8.4,12]],"id":52385921},{"atb":[[8.2,13.89],[9.8,0]],"id":52385884},{"atl":[[270,0],[220,2]],"id":52385917},{"atb":[[5.8,20.83],[7,0]],"id":52385891},{"atb":[[10,0],[8.4,13.51]],"id":52385903},{"atb":[[23,20]],"id":52385905},{"atb":[[9.6,0],[8,12]],"id":52385899}],"con":true,"img":false}]}
{"op":"mcm","clk":"11550637154","pt":1719501158707,"mc":[{"id":"1.230178172","rc":[{"atb":[[8.6,13],[7,0]],"id":52385910},{"atb":[[6.2,10],[5.2,0]],"id":52385889},{"atb":[[14.5,0]],"id":52385883},{"atl":[[50,12.24]],"id":52385885},{"atb":[[5.6,21.74],[4.9,0]],"id":52385890},{"atl":[[34,0]],"id":52385904},{"atb":[[6.4,0]],"id":52385911},{"atb":[[21,20]],"id":52385919},{"atl":[[150,0],[120,2]],"id":52385921},{"atb":[[7.2,10],[6.2,0]],"id":52385882},{"atb":[[10,10],[8.2,0]],"id":52385884},{"atb":[[10.5,10],[8.4,0]],"id":52385903},{"atb":[[20,6]],"id":52385905},{"atb":[[8,0],[9.8,11]],"id":52385899}],"con":true,"img":false}]}
{"op":"mcm","clk":"11550637162","pt":1719501158810,"mc":[{"id":"1.230178172","rc":[{"atb":[[29,0]],"id":52385896},{"atl":[[48,12.77]],"id":52385904},{"atb":[[29,0]],"id":52385900},{"atb":[[20,0]],"id":52385897}],"con":true,"img":false}]}
{"op":"mcm","clk":"11550637169","pt":1719501158917,"mc":[{"id":"1.230178172","rc":[{"atb":[[32,19.35]],"id":52385896},{"atb":[[30,20.69]],"id":52385900},{"atb":[[21,20]],"id":52385897}],"con":true,"img":false}]}
{"op":"mcm","clk":"11550637187","pt":1719501159331,"mc":[{"id":"1.230178172","rc":[{"atb":[[16,0]],"id":52385921},{"atb":[[16,0]],"id":52385917},{"atb":[[11,2.5]],"id":52385891}],"con":true,"img":false}]}
{"op":"mcm","clk":"11550637193","pt":1719501159428,"mc":[{"id":"1.230178172","rc":[{"atb":[[18,6]],"id":52385921},{"atb":[[18,5]],"id":52385917},{"atb":[[12,9]],"id":52385891}],"con":true,"img":false}]}
{"op":"mcm","clk":"11550637241","pt":1719501160305,"mc":[{"id":"1.230178172","rc":[{"atb":[[10.5,0],[2.64,60.98]],"id":52385918},{"atb":[[10,0],[1.87,100]],"id":52385920},{"atb":[[9,0],[6.2,16]],"id":52385914},{"atb":[[22,0]],"id":52385883},{"atb":[[7.2,12],[12.5,0]],"id":52385900},{"atb":[[10,0],[7,10]],"id":52385907},{"atb":[[7,10]],"id":52385886},{"atb":[[9.6,0],[2.7,58.82]],"id":52385919},{"atb":[[2.9,52.63],[8.4,0]],"id":52385921},{"atb":[[1.25,236.97],[12,0]],"id":52385917},{"atl":[[280,2],[220,0]],"id":52385917},{"atb":[[11,0],[6,18],[8.8,0]],"id":52385893},{"atb":[[23,0]],"id":52385905}],"con":true,"img":false}]}
{"op":"mcm","clk":"11550637247","pt":1719501160414,"mc":[{"id":"1.230178172","rc":[{"atb":[[10.5,10.53],[2.64,0]],"id":52385918},{"atb":[[14.5,22]],"id":52385883},{"atb":[[32,0]],"id":52385896},{"atb":[[30,0]],"id":52385898},{"atb":[[7.2,0],[30,0]],"id":52385900},{"atb":[[11,0]],"id":52385886},{"atb":[[13,8]],"id":52385893},{"atb":[[20,28]],"id":52385905}],"con":true,"img":false}]}
{"op":"mcm","clk":"11550637256","pt":1719501160516,"mc":[{"id":"1.230178172","rc":[{"atb":[[30,20]],"id":52385896},{"atb":[[29,20]],"id":52385898},{"atb":[[12.5,8.7],[27,22]],"id":52385900}],"con":true,"img":false}]}
{"op":"mcm","clk":"11550637276","pt":1719501160825,"mc":[{"id":"1.230178172","rc":[{"atb":[[29,0]],"id":52385898},{"atb":[[27,0]],"id":52385900}],"con":true,"img":false}]}
{"op":"mcm","clk":"11550637282","pt":1719501160933,"mc":[{"id":"1.230178172","rc":[{"atb":[[22,15]],"id":52385898},{"atb":[[22,15]],"id":52385900}],"con":true,"img":false}]}
{"op":"mcm","clk":"11550637291","pt":1719501161036,"mc":[{"id":"1.230178172","rc":[{"atb":[[21,0]],"id":52385897}],"con":true,"img":false}]}
{"op":"mcm","clk":"11550637298","pt":1719501161136,"mc":[{"id":"1.230178172","rc":[{"atb":[[20,15]],"id":52385897}],"con":true,"img":false}]}
{"op":"mcm","clk":"11550637336","pt":1719501161707,"mc":[{"id":"1.230178172","rc":[{"atb":[[8.6,0]],"id":52385910},{"atb":[[6.2,0],[5.2,23.81]],"id":52385889},{"atb":[[7.2,0]],"id":52385882},{"atb":[[10,0]],"id":52385884},{"atb":[[10.5,0],[8.4,13.51]],"id":52385903},{"atb":[[8,0],[6.8,15]],"id":52385905},{"atb":[[9.8,0]],"id":52385899}],"con":true,"img":false}]}
{"op":"mcm","clk":"11550637344","pt":1719501161811,"mc":[{"id":"1.230178172","rc":[{"atb":[[8.6,13]],"id":52385910},{"atb":[[30,0]],"id":52385896},{"atb":[[7.2,10]],"id":52385882},{"atb":[[10,10]],"id":52385884},{"atb":[[9.8,11]],"id":52385899}],"con":true,"img":false}]}
{"op":"mcm","clk":"11550637350","pt":1719501161914,"mc":[{"id":"1.230178172","rc":[{"atb":[[27,20]],"id":52385896}],"con":true,"img":false}]}
{"op":"mcm","clk":"11550637379","pt":1719501162331,"mc":[{"id":"1.230178172","rc":[{"atb":[[11,20]],"id":52385890}],"con":true,"img":false}]}
{"op":"mcm","clk":"11550637388","pt":1719501162448,"mc":[{"id":"1.230178172","rc":[{"atb":[[10,8]],"id":52385890}],"con":true,"img":false}]}
{"op":"mcm","clk":"11550637399","pt":1719501162622,"mc":[{"id":"1.230178172","rc":[{"atb":[[11,0]],"id":52385890}],"con":true,"img":false}]}
{"op":"mcm","clk":"11550637405","pt":1719501162733,"mc":[{"id":"1.230178172","rc":[{"atb":[[10.5,0]],"id":52385918},{"atb":[[10.5,26]],"id":52385890},{"atb":[[12.5,0]],"id":52385900},{"atb":[[25,0]],"id":52385899}],"con":true,"img":false}]}
{"op":"mcm","clk":"11550637420","pt":1719501162861,"mc":[{"id":"1.230178172","rc":[{"atb":[[8.6,0]],"id":52385910},{"atb":[[9.2,12.2]],"id":52385918},{"atb":[[12,14.09]],"id":52385900},{"atb":[[7.2,0]],"id":52385882},{"atb":[[10,0]],"id":52385884},{"atl":[[38,0]],"id":52385893},{"atb":[[24,22],[9.8,0]],"id":52385899}],"con":true,"img":false}]}
{"op":"mcm","clk":"11550637435","pt":1719501163006,"mc":[{"id":"1.230178172","rc":[{"atb":[[8.6,13]],"id":52385910},{"atb":[[7.2,10]],"id":52385882},{"atb":[[10,10]],"id":52385884},{"atl":[[40,15.38]],"id":52385893},{"atb":[[24,0],[9.8,11],[27,22]],"id":52385899}],"con":true,"img":false}]}
{"op":"mcm","clk":"11550637450","pt":1719501163213,"mc":[{"id":"1.230178172","rc":[{"atb":[[9.2,0]],"id":52385918}],"con":true,"img":false}]}
{"op":"mcm","clk":"11550637463","pt":1719501163321,"mc":[{"id":"1.230178172","rc":[{"atb":[[10.5,10.53]],"id":52385918},{"atb":[[12,5]],"id":52385900},{"atl":[[40,0]],"id":52385893},{"atb":[[27,0]],"id":52385899}],"con":true,"img":false}]}
{"op":"mcm","clk":"11550637471","pt":1719501163422,"mc":[{"id":"1.230178172","rc":[{"atb":[[12.5,8.7]],"id":52385900},{"atl":[[50,12.24]],"id":52385893},{"atb":[[25,22]],"id":52385899}],"con":true,"img":false}]}
{"op":"mcm","clk":"11550637506","pt":1719501163836,"mc":[{"id":"1.230178172","rc":[{"atb":[[24,10.15]],"id":52385900},{"atl":[[46,5.9]],"id":52385893}],"con":true,"img":false}]}
{"op":"mcm","clk":"11550637529","pt":1719501164046,"mc":[{"id":"1.230178172","rc":[{"atb":[[24,0]],"id":52385900},{"atl":[[46,0]],"id":52385893}],"con":true,"img":false}]}
{"op":"mcm","clk":"11550637667","pt":1719501165343,"mc":[{"id":"1.230178172","rc":[{"atb":[[6.2,10]],"id":52385912},{"atb":[[8,13]],"id":52385904}],"con":true,"img":false}]}
{"op":"mcm","clk":"11550637681","pt":1719501165444,"mc":[{"id":"1.230178172","rc":[{"atb":[[5.4,0]],"id":52385912},{"atb":[[10.5,10],[8.8,0]],"id":52385896},{"atb":[[5.1,0],[5.8,20.83]],"id":52385892},{"atb":[[7,0]],"id":52385904},{"atb":[[10.5,10],[8.8,0]],"id":52385898},{"atb":[[6.2,10],[5.5,0]],"id":52385911},{"atb":[[5.8,0],[6.6,14]],"id":52385891}],"con":true,"img":false}]}
{"op":"mcm","clk":"11550637850","pt":1719501167050,"mc":[{"id":"1.230178172","rc":[{"atb":[[11.5,9.52],[1.87,0]],"id":52385920},{"atb":[[9,12.5],[6.2,0]],"id":52385914},{"atb":[[11.5,9.52],[7,0]],"id":52385907},{"atb":[[11.5,9.52],[7,0]],"id":52385886},{"atb":[[10,10],[2.7,0]],"id":52385919},{"atb":[[2.9,0],[9.8,11]],"id":52385921},{"atb":[[1.25,0],[12,9.09]],"id":52385917},{"atb":[[6,2],[8.8,12.82]],"id":52385893}],"con":true,"img":false}]}
{"op":"mcm","clk":"11550637897","pt":1719501167513,"mc":[{"id":"1.230178172","rc":[{"atb":[[8.6,0]],"id":52385910},{"atb":[[10.5,0],[8.8,12.82]],"id":52385896},{"atb":[[5.6,0]],"id":52385890},{"atb":[[5.1,24.39],[5.8,0]],"id":52385892},{"atb":[[10.5,0],[8.8,12.82]],"id":52385898},{"atb":[[6.2,0],[5.5,22.22]],"id":52385911},{"atb":[[10,0]],"id":52385884},{"atl":[[220,2]],"id":52385917},{"atb":[[9.8,0]],"id":52385899}],"con":true,"img":false}]}
{"op":"mcm","clk":"11550637908","pt":1719501167617,"mc":[{"id":"1.230178172","rc":[{"atb":[[4.9,25.64]],"id":52385890},{"atb":[[7.2,0]],"id":52385882},{"atl":[[280,0]],"id":52385917}],"con":true,"img":false}]}
{"op":"mcm","clk":"11550637918","pt":1719501167724,"mc":[{"id":"1.230178172","rc":[{"atb":[[8.6,13]],"id":52385910},{"atb":[[11,10],[8.8,0]],"id":52385896},{"atb":[[5.6,21.74],[4.9,0]],"id":52385890},{"atb":[[5.1,0],[6,17]],"id":52385892},{"atb":[[11,10],[8.8,0]],"id":52385898},{"atb":[[6.4,10],[5.5,0]],"id":52385911},{"atb":[[7.2,10]],"id":52385882},{"atb":[[10,10]],"id":52385884},{"atb":[[9.8,11]],"id":52385899}],"con":true,"img":false}]}
{"op":"mcm","clk":"11550637949","pt":1719501168033,"mc":[{"id":"1.230178172","rc":[{"atb":[[10.5,0],[7.4,15.62]],"id":52385918},{"atb":[[10,0]],"id":52385919}],"con":true,"img":false}]}
{"op":"mcm","clk":"11550637958","pt":1719501168137,"mc":[{"id":"1.230178172","rc":[{"atb":[[11.5,0]],"id":52385920},{"atb":[[27,0]],"id":52385896},{"atb":[[9.6,10]],"id":52385919},{"atb":[[9.8,0]],"id":52385921},{"atb":[[12,0]],"id":52385917},{"atb":[[20,0]],"id":52385897},{"atb":[[25,0]],"id":52385899}],"con":true,"img":false}]}
{"op":"mcm","clk":"11550637966","pt":1719501168241,"mc":[{"id":"1.230178172","rc":[{"atl":[[38,0]],"id":52385910},{"atl":[[40,0]],"id":52385912},{"atb":[[11,12.5]],"id":52385920},{"atb":[[29,20]],"id":52385896},{"atb":[[22,0]],"id":52385898},{"atl":[[27,0]],"id":52385911},{"atl":[[42,0]],"id":52385913},{"atb":[[9,12]],"id":52385921},{"atb":[[11.5,9.52]],"id":52385917},{"atb":[[20,20]],"id":52385897},{"atb":[[21,22]],"id":52385899}],"con":true,"img":false}]}
{"op":"mcm","clk":"11550637977","pt":1719501168344,"mc":[{"id":"1.230178172","rc":[{"atl":[[60,10.17]],"id":52385912},{"atl":[[60,10.17]],"id":52385913}],"con":true,"img":false}]}
{"op":"mcm","clk":"11550637987","pt":1719501168451,"mc":[{"id":"1.230178172","rc":[{"atl":[[40,15.38]],"id":52385910},{"atb":[[6,12],[5.2,0]],"id":52385889},{"atb":[[21,20]],"id":52385898},{"atl":[[28,20]],"id":52385911},{"atb":[[10.5,10],[8.4,0]],"id":52385903},{"atb":[[8.2,10],[6.8,0]],"id":52385905},{"atb":[[21,0]],"id":52385899}],"con":true,"img":false}]}
{"op":"mcm","clk":"11550637996","pt":1719501168553,"mc":[{"id":"1.230178172","rc":[{"atb":[[18.5,22]],"id":52385899}],"con":true,"img":false}]}
{"op":"mcm","clk":"11550638006","pt":1719501168600,"mc":[{"id":"1.230178172","rc":[{"atl":[[40,0]],"id":52385910},{"atl":[[28,0]],"id":52385911}],"con":true,"img":false}]}
{"op":"mcm","clk":"11550638016","pt":1719501168707,"mc":[{"id":"1.230178172","rc":[{"atl":[[55,11.11]],"id":52385910},{"atb":[[29,0]],"id":52385896},{"atl":[[44,13.95]],"id":52385911}],"con":true,"img":false}]}
{"op":"mcm","clk":"11550638025","pt":1719501168806,"mc":[{"id":"1.230178172","rc":[{"atb":[[25,20]],"id":52385896}],"con":true,"img":false}]}
{"op":"mcm","clk":"11550638038","pt":1719501169013,"mc":[{"id":"1.230178172","rc":[{"atb":[[32,19.35],[25,0]],"id":52385896}],"con":true,"img":false}]}
{"op":"mcm","clk":"11550638082","pt":1719501169532,"mc":[{"id":"1.230178172","rc":[{"atb":[[9.2,12.2],[7.4,0]],"id":52385918}],"con":true,"img":false}]}
{"op":"mcm","clk":"11550638123","pt":1719501170212,"mc":[{"id":"1.230178172","rc":[{"atb":[[12,0]],"id":52385891}],"con":true,"img":false}]}
{"op":"mcm","clk":"11550638129","pt":1719501170315,"mc":[{"id":"1.230178172","rc":[{"atb":[[11,11.5]],"id":52385891}],"con":true,"img":false}]}
{"op":"mcm","clk":"11550638172","pt":1719501171130,"mc":[{"id":"1.230178172","rc":[{"atl":[[42,14.63]],"id":52385913}],"con":true,"img":false}]}
{"op":"mcm","clk":"11550638184","pt":1719501171243,"mc":[{"id":"1.230178172","rc":[{"atl":[[40,15.38]],"id":52385918},{"atl":[[42,14.63]],"id":52385914},{"atb":[[34,18.18]],"id":52385898},{"atb":[[30,20.69]],"id":52385900},{"atl":[[27,20]],"id":52385911},{"atb":[[21,20]],"id":52385897},{"atl":[[38,16.22]],"id":52385893},{"atb":[[27,22]],"id":52385899}],"con":true,"img":false}]}
{"op":"mcm","clk":"11550638192","pt":1719501171338,"mc":[{"id":"1.230178172","rc":[{"atl":[[60,0]],"id":52385913},{"atb":[[13,0]],"id":52385893}],"con":true,"img":false}]}
{"op":"mcm","clk":"11550638203","pt":1719501171446,"mc":[{"id":"1.230178172","rc":[{"atl":[[60,0]],"id":52385918},{"atl":[[46,0]],"id":52385914},{"atb":[[21,0]],"id":52385898},{"atb":[[22,0]],"id":52385900},{"atl":[[44,0]],"id":52385911},{"atb":[[20,0]],"id":52385897},{"atb":[[12,8]],"id":52385893},{"atl":[[50,0]],"id":52385893},{"atb":[[18.5,0]],"id":52385899}],"con":true,"img":false}]}
{"op":"mcm","clk":"11550638250","pt":1719501172014,"mc":[{"id":"1.230178172","rc":[{"atb":[[23,22]],"id":52385906},{"atl":[[80,7.59]],"id":52385917}],"con":true,"img":false}]}
{"op":"mcm","clk":"11550638259","pt":1719501172118,"mc":[{"id":"1.230178172","rc":[{"atl":[[36,17.14]],"id":52385910},{"atl":[[85,0]],"id":52385917}],"con":true,"img":false}]}
{"op":"mcm","clk":"11550638269","pt":1719501172225,"mc":[{"id":"1.230178172","rc":[{"atb":[[21,0]],"id":52385906}],"con":true,"img":false}]}
{"op":"mcm","clk":"11550638277","pt":1719501172325,"mc":[{"id":"1.230178172","rc":[{"atl":[[55,0]],"id":52385910}],"con":true,"img":false}]}
{"op":"mcm","clk":"11550638335","pt":1719501173050,"mc":[{"id":"1.230178172","rc":[{"atl":[[21,3]],"id":52385889},{"atl":[[29,2.93]],"id":52385882}],"con":true,"img":false}]}
{"op":"mcm","clk":"11550638346","pt":1719501173156,"mc":[{"id":"1.230178172","rc":[{"atl":[[29,18.79]],"id":52385882}],"con":true,"img":false}]}
{"op":"mcm","clk":"11550638355","pt":1719501173206,"mc":[{"id":"1.230178172","rc":[{"atl":[[21,9.3]],"id":52385889},{"atb":[[10,0]],"id":52385890}],"con":true,"img":false}]}
{"op":"mcm","clk":"11550638363","pt":1719501173312,"mc":[{"id":"1.230178172","rc":[{"atb":[[11,8]],"id":52385890},{"atb":[[32,19.35]],"id":52385900},{"atl":[[42,0]],"id":52385882}],"con":true,"img":false}]}
{"op":"mcm","clk":"11550638370","pt":1719501173412,"mc":[{"id":"1.230178172","rc":[{"atl":[[26,0]],"id":52385889}],"con":true,"img":false}]}
{"op":"mcm","clk":"11550638376","pt":1719501173515,"mc":[{"id":"1.230178172","rc":[{"atb":[[30,0]],"id":52385900}],"con":true,"img":false}]}
{"op":"mcm","clk":"11550638624","pt":1719501176414,"mc":[{"id":"1.230178172","rc":[{"atb":[[22,20]],"id":52385913}],"con":true,"img":false}]}
{"op":"mcm","clk":"11550638638","pt":1719501176622,"mc":[{"id":"1.230178172","rc":[{"atb":[[19,7]],"id":52385913}],"con":true,"img":false}]}
{"op":"mcm","clk":"11550638660","pt":1719501176933,"mc":[{"id":"1.230178172","rc":[{"atb":[[11,34]],"id":52385890}],"con":true,"img":false}]}
{"op":"mcm","clk":"11550638686","pt":1719501177241,"mc":[{"id":"1.230178172","rc":[{"atb":[[10.5,0]],"id":52385890}],"con":true,"img":false}]}
{"op":"mcm","clk":"11550638815","pt":1719501179151,"mc":[{"id":"1.230178172","rc":[{"atl":[[36,0]],"id":52385910},{"atl":[[42,0]],"id":52385914},{"atl":[[27,0]],"id":52385911},{"atl":[[42,0]],"id":52385913}],"con":true,"img":false}]}
{"op":"mcm","clk":"11550638824","pt":1719501179258,"mc":[{"id":"1.230178172","rc":[{"atl":[[75,8.11]],"id":52385910},{"atl":[[48,15.27]],"id":52385914},{"atl":[[44,13.95]],"id":52385911},{"atl":[[60,10.17]],"id":52385913}],"con":true,"img":false}]}
{"op":"mcm","clk":"11550638960","pt":1719501181233,"mc":[{"id":"1.230178172","rc":[{"atb":[[11,2.5]],"id":52385891}],"con":true,"img":false}]}
{"op":"mcm","clk":"11550638969","pt":1719501181338,"mc":[{"id":"1.230178172","rc":[{"atb":[[12,9]],"id":52385891}],"con":true,"img":false}]}
{"op":"mcm","clk":"11550639031","pt":1719501182117,"mc":[{"id":"1.230178172","rc":[{"atl":[[65,0],[70,2.5],[90,5],[48,0]],"id":52385914},{"atb":[[12,0]],"id":52385893}],"con":true,"img":false}]}
{"op":"mcm","clk":"11550639039","pt":1719501182219,"mc":[{"id":"1.230178172","rc":[{"atb":[[32,0]],"id":52385896},{"atb":[[13,8]],"id":52385893},{"atl":[[34,18.18]],"id":52385893}],"con":true,"img":false}]}
{"op":"mcm","clk":"11550639047","pt":1719501182324,"mc":[{"id":"1.230178172","rc":[{"atl":[[50,10]],"id":52385914},{"atb":[[30,15]],"id":52385896},{"atl":[[38,0]],"id":52385893}],"con":true,"img":false}]}
{"op":"mcm","clk":"11550639059","pt":1719501182531,"mc":[{"id":"1.230178172","rc":[{"atl":[[50,0]],"id":52385914},{"atl":[[55,11.11]],"id":52385913}],"con":true,"img":false}]}
{"op":"mcm","clk":"11550639066","pt":1719501182636,"mc":[{"id":"1.230178172","rc":[{"atl":[[46,13.33]],"id":52385910},{"atb":[[30,0]],"id":52385896},{"atl":[[36,17.14]],"id":52385911}],"con":true,"img":false}]}
{"op":"mcm","clk":"11550639075","pt":1719501182739,"mc":[{"id":"1.230178172","rc":[{"atl":[[55,11.11]],"id":52385914},{"atb":[[30,20]],"id":52385896},{"atl":[[60,0]],"id":52385913}],"con":true,"img":false}]}
{"op":"mcm","clk":"11550639084","pt":1719501182845,"mc":[{"id":"1.230178172","rc":[{"atl":[[75,0],[44,13.95]],"id":52385910},{"atl":[[34,18.18],[44,0]],"id":52385911}],"con":true,"img":false}]}
{"op":"mcm","clk":"11550639094","pt":1719501182951,"mc":[{"id":"1.230178172","rc":[{"atl":[[36,0]],"id":52385911}],"con":true,"img":false}]}
{"op":"mcm","clk":"11550639103","pt":1719501183053,"mc":[{"id":"1.230178172","rc":[{"atl":[[46,0]],"id":52385910}],"con":true,"img":false}]}
{"op":"mcm","clk":"11550639123","pt":1719501183316,"mc":[{"id":"1.230178172","rc":[{"atb":[[14,0]],"id":52385883},{"atb":[[18,0]],"id":52385899}],"con":true,"img":false}]}
{"op":"mcm","clk":"11550639130","pt":1719501183420,"mc":[{"id":"1.230178172","rc":[{"atb":[[16,6]],"id":52385883},{"atb":[[20,6]],"id":52385899}],"con":true,"img":false}]}
{"op":"mcm","clk":"11550639139","pt":1719501183525,"mc":[{"id":"1.230178172","rc":[{"atb":[[16.5,22],[14.5,0]],"id":52385883}],"con":true,"img":false}]}
{"op":"mcm","clk":"11550639352","pt":1719501186433,"mc":[{"id":"1.230178172","rc":[{"atb":[[17,0]],"id":52385900}],"con":true,"img":false}]}
{"op":"mcm","clk":"11550639358","pt":1719501186532,"mc":[{"id":"1.230178172","rc":[{"atb":[[19,6]],"id":52385900}],"con":true,"img":false}]}
{"op":"mcm","clk":"11550639395","pt":1719501187151,"mc":[{"id":"1.230178172","rc":[{"atl":[[22,0]],"id":52385892},{"atl":[[34,0]],"id":52385911}],"con":true,"img":false}]}
{"op":"mcm","clk":"11550639405","pt":1719501187255,"mc":[{"id":"1.230178172","rc":[{"atl":[[23,27.27]],"id":52385892},{"atl":[[36,17.14]],"id":52385911}],"con":true,"img":false}]}
{"op":"mcm","clk":"11550639421","pt":1719501187464,"mc":[{"id":"1.230178172","rc":[{"atl":[[23,0]],"id":52385892}],"con":true,"img":false}]}
{"op":"mcm","clk":"11550639428","pt":1719501187520,"mc":[{"id":"1.230178172","rc":[{"atl":[[24,26.09]],"id":52385892}],"con":true,"img":false}]}
{"op":"mcm","clk":"11550639529","pt":1719501188918,"mc":[{"id":"1.230178172","rc":[{"atl":[[55,0]],"id":52385914},{"atl":[[55,0]],"id":52385913}],"con":true,"img":false}]}
{"op":"mcm","clk":"11550639538","pt":1719501189024,"mc":[{"id":"1.230178172","rc":[{"atl":[[55,3.68]],"id":52385914}],"con":true,"img":false}]}
{"op":"mcm","clk":"11550639547","pt":1719501189131,"mc":[{"id":"1.230178172","rc":[{"atl":[[60,10.17]],"id":52385914},{"atl":[[60,10.17]],"id":52385913}],"con":true,"img":false}]}
{"op":"mcm","clk":"11550639599","pt":1719501189955,"mc":[{"id":"1.230178172","rc":[{"atl":[[55,0]],"id":52385914}],"con":true,"img":false}]}
{"op":"mcm","clk":"11550639788","pt":1719501192232,"mc":[{"id":"1.230178172","rc":[{"atb":[[12,0]],"id":52385891}],"con":true,"img":false}]}
{"op":"mcm","clk":"11550639797","pt":1719501192337,"mc":[{"id":"1.230178172","rc":[{"atb":[[11,11.5]],"id":52385891}],"con":true,"img":false}]}
{"op":"mcm","clk":"11550639859","pt":1719501193271,"mc":[{"id":"1.230178172","rc":[{"atb":[[13,0]],"id":52385893}],"con":true,"img":false}]}
{"op":"mcm","clk":"11550639872","pt":1719501193321,"mc":[{"id":"1.230178172","rc":[{"atb":[[12,8]],"id":52385893}],"con":true,"img":false}]}
{"op":"mcm","clk":"11550639934","pt":1719501194146,"mc":[{"id":"1.230178172","rc":[{"atb":[[28,0]],"id":52385884}],"con":true,"img":false}]}
{"op":"mcm","clk":"11550639945","pt":1719501194250,"mc":[{"id":"1.230178172","rc":[{"atb":[[27,20]],"id":52385884}],"con":true,"img":false}]}
{"op":"mcm","clk":"11550639958","pt":1719501194460,"mc":[{"id":"1.230178172","rc":[{"atb":[[27,0]],"id":52385884}],"con":true,"img":false}]}
{"op":"mcm","clk":"11550639966","pt":1719501194561,"mc":[{"id":"1.230178172","rc":[{"atb":[[26,20]],"id":52385884}],"con":true,"img":false}]}
{"op":"mcm","clk":"11550640092","pt":1719501196627,"mc":[{"id":"1.230178172","rc":[{"atb":[[15,0]],"id":52385889}],"con":true,"img":false}]}
{"op":"mcm","clk":"11550640098","pt":1719501196729,"mc":[{"id":"1.230178172","rc":[{"atb":[[13.5,15]],"id":52385889}],"con":true,"img":false}]}
{"op":"mcm","clk":"11550640111","pt":1719501197039,"mc":[{"id":"1.230178172","rc":[{"atb":[[30,0]],"id":52385896}],"con":true,"img":false}]}
{"op":"mcm","clk":"11550640117","pt":1719501197145,"mc":[{"id":"1.230178172","rc":[{"atb":[[29,20]],"id":52385896}],"con":true,"img":false}]}
{"op":"mcm","clk":"11550640142","pt":1719501197455,"mc":[{"id":"1.230178172","rc":[{"atl":[[36,0]],"id":52385911}],"con":true,"img":false}]}
{"op":"mcm","clk":"11550640154","pt":1719501197558,"mc":[{"id":"1.230178172","rc":[{"atl":[[38,16.22]],"id":52385911}],"con":true,"img":false}]}
{"op":"mcm","clk":"11550640176","pt":1719501197766,"mc":[{"id":"1.230178172","rc":[{"atl":[[38,0]],"id":52385911}],"con":true,"img":false}]}
{"op":"mcm","clk":"11550640193","pt":1719501197973,"mc":[{"id":"1.230178172","rc":[{"atl":[[44,13.95]],"id":52385911}],"con":true,"img":false}]}
{"op":"mcm","clk":"11550640211","pt":1719501198178,"mc":[{"id":"1.230178172","rc":[{"atl":[[60,0]],"id":52385914},{"atl":[[24,0]],"id":52385892}],"con":true,"img":false}]}
{"op":"mcm","clk":"11550640220","pt":1719501198282,"mc":[{"id":"1.230178172","rc":[{"atl":[[65,9.38]],"id":52385914},{"atl":[[25,25]],"id":52385892}],"con":true,"img":false}]}
{"op":"mcm","clk":"11550640393","pt":1719501200456,"mc":[{"id":"1.230178172","rc":[{"atb":[[18,3.61]],"id":52385918},{"atl":[[55,2.1]],"id":52385918},{"atb":[[17,5]],"id":52385883},{"atl":[[50,2.8]],"id":52385883},{"atb":[[18.5,2.9]],"id":52385896},{"atl":[[55,2.34]],"id":52385896},{"atb":[[11.5,4]],"id":52385890},{"atl":[[32,3.39]],"id":52385890},{"atb":[[15.5,5]],"id":52385886},{"atl":[[65,2.7]],"id":52385886},{"atb":[[11,5]],"id":52385882},{"atb":[[16.5,4]],"id":52385917},{"atl":[[65,2.3]],"id":52385917},{"atb":[[14.5,3.9]],"id":52385897},{"atl":[[46,3]],"id":52385897},{"atb":[[10.5,4.9]],"id":52385893},{"atl":[[32,3]],"id":52385893}],"con":true,"img":false}]}
{"op":"mcm","clk":"11550640402","pt":1719501200560,"mc":[{"id":"1.230178172","rc":[{"atb":[[17.5,22]],"id":52385883},{"atl":[[48,12.77]],"id":52385883},{"atl":[[55,13.14]],"id":52385896},{"atb":[[11.5,18.78]],"id":52385890},{"atl":[[65,12.08]],"id":52385886},{"atl":[[60,10.17]],"id":52385917},{"atl":[[44,13.8]],"id":52385897}],"con":true,"img":false}]}
{"op":"mcm","clk":"11550640411","pt":1719501200662,"mc":[{"id":"1.230178172","rc":[{"atb":[[18.5,19.22]],"id":52385918},{"atl":[[55,0]],"id":52385921},{"atl":[[32,15.74]],"id":52385893}],"con":true,"img":false}]}
{"op":"mcm","clk":"11550640423","pt":1719501200768,"mc":[{"id":"1.230178172","rc":[{"atb":[[17.5,0]],"id":52385918},{"atb":[[16.5,0]],"id":52385883},{"atl":[[55,0]],"id":52385883},{"atl":[[65,0]],"id":52385896},{"atb":[[11,8]],"id":52385890},{"atl":[[75,0]],"id":52385886},{"atl":[[60,12.67]],"id":52385921},{"atb":[[26,0]],"id":52385884},{"atl":[[80,0]],"id":52385917},{"atl":[[48,0]],"id":52385897},{"atl":[[34,0]],"id":52385893}],"con":true,"img":false}]}
{"op":"mcm","clk":"11550640434","pt":1719501200868,"mc":[{"id":"1.230178172","rc":[{"atb":[[23,20]],"id":52385884}],"con":true,"img":false}]}
{"op":"mcm","clk":"11550640444","pt":1719501200979,"mc":[{"id":"1.230178172","rc":[{"atb":[[10,0],[11.5,5],[12,0],[13.5,2.5]],"id":52385910},{"atb":[[7.2,0],[8.8,2.5]],"id":52385912},{"atb":[[12,0],[13.5,5],[14,0],[15.5,2.5]],"id":52385906},{"atb":[[8,0],[11.5,5],[13.5,2.5],[7.2,0]],"id":52385918},{"atb":[[9.6,0],[16,5],[18,2.5],[11,10]],"id":52385920},{"atl":[[34,2.5],[36,0],[42,5],[44,0]],"id":52385889},{"atb":[[10,0],[10.5,5],[12,0],[12.5,2.5]],"id":52385914},{"atb":[[11,0],[13,0],[13.5,2.5]],"id":52385883},{"atl":[[65,5],[75,0],[48,2.5],[55,0]],"id":52385885},{"atl":[[36,5],[38,0],[46,0],[29,2.5]],"id":52385890},{"atl":[[32,2.5],[36,0],[40,5],[44,0]],"id":52385892},{"atl":[[70,0],[44,2.5],[50,0],[55,5]],"id":52385904},{"atb":[[17,5],[19,8.5],[12,0],[14,0]],"id":52385900},{"atb":[[9.6,5],[10.5,0],[11,2.5],[9.4,0]],"id":52385911},{"atb":[[11,5],[11.5,0],[13,2.5],[9.8,0]],"id":52385913},{"atb":[[16.5,0],[18.5,0],[20,10],[24,2.5]],"id":52385907},{"atb":[[13,0],[15,0],[15.5,7.5]],"id":52385886},{"atb":[[11,0],[13,0],[15,5],[17,2.5]],"id":52385919},{"atb":[[10.5,0],[12.5,0],[13.5,5],[15.5,2.5]],"id":52385921},{"atl":[[40,2.5],[44,0],[48,5],[55,0]],"id":52385882},{"atb":[[9,0],[13,5],[15,2.5],[9.8,0]],"id":52385917},{"atl":[[36,2.5],[38,0],[44,5],[46,0]],"id":52385891},{"atb":[[8.2,0],[7.4,0],[9.6,2.5],[8.8,17.82]],"id":52385893},{"atb":[[10.5,0],[11.5,2.5],[9.8,5],[9.4,0]],"id":52385905},{"atb":[[17,2.5],[13.5,0],[15,5],[15.5,0]],"id":52385899}],"con":true,"img":false}]}
{"op":"mcm","clk":"11550640452","pt":1719501201081,"mc":[{"id":"1.230178172","rc":[{"atl":[[65,0],[75,5],[85,0],[55,4.6]],"id":52385918},{"atl":[[75,10.61],[80,0],[95,5],[100,0]],"id":52385920},{"atl":[[80,0],[42,2.5],[50,7.8],[60,0]],"id":52385883},{"atl":[[48,15.27]],"id":52385885},{"atl":[[46,13.33]],"id":52385904},{"atl":[[85,9.64],[90,0],[110,5],[120,0]],"id":52385900},{"atl":[[70,11.2],[75,0],[90,5],[95,0]],"id":52385907},{"atl":[[75,2.5],[80,0],[95,5],[100,0]],"id":52385886},{"atl":[[75,2.5],[90,0],[95,5],[120,0]],"id":52385917},{"atl":[[44,2.5]],"id":52385893},{"atl":[[70,0],[90,0]],"id":52385905}],"con":true,"img":false}]}
{"op":"mcm","clk":"11550640459","pt":1719501201131,"mc":[{"id":"1.230178172","rc":[{"atl":[[36,17.14]],"id":52385911},{"atl":[[75,0]],"id":52385893},{"atl":[[80,5],[60,2.5]],"id":52385905}],"con":true,"img":false}]}
{"op":"mcm","clk":"11550640472","pt":1719501201287,"mc":[{"id":"1.230178172","rc":[{"atb":[[16,0]],"id":52385918},{"atb":[[16,0]],"id":52385914},{"atl":[[50,0]],"id":52385885},{"atl":[[48,0]],"id":52385904},{"atb":[[16,0]],"id":52385886},{"atb":[[20,0]],"id":52385919},{"atb":[[18,0]],"id":52385921},{"atb":[[18,0]],"id":52385917},{"atl":[[55,11.11]],"id":52385905}],"con":true,"img":false}]}
{"op":"mcm","clk":"11550640480","pt":1719501201338,"mc":[{"id":"1.230178172","rc":[{"atb":[[19,6]],"id":52385918},{"atb":[[18,8]],"id":52385914},{"atl":[[44,0]],"id":52385911},{"atb":[[19,5]],"id":52385886},{"atb":[[24,5]],"id":52385919},{"atb":[[20,6]],"id":52385921},{"atb":[[20,5]],"id":52385917}],"con":true,"img":false}]}
{"op":"mcm","clk":"11550640488","pt":1719501201443,"mc":[{"id":"1.230178172","rc":[{"atb":[[21,0],[24,25]],"id":52385919},{"atl":[[65,0]],"id":52385905}],"con":true,"img":false}]}
{"op":"mcm","clk":"11550640616","pt":1719501203047,"mc":[{"id":"1.230178172","rc":[{"atb":[[17,0]],"id":52385882}],"con":true,"img":false}]}
{"op":"mcm","clk":"11550640624","pt":1719501203151,"mc":[{"id":"1.230178172","rc":[{"atb":[[16.5,20]],"id":52385882}],"con":true,"img":false}]}
{"op":"mcm","clk":"11550640632","pt":1719501203252,"mc":[{"id":"1.230178172","rc":[{"atl":[[24,26.09]],"id":52385892},{"atb":[[12,0]],"id":52385893}],"con":true,"img":false}]}
{"op":"mcm","clk":"11550640640","pt":1719501203360,"mc":[{"id":"1.230178172","rc":[{"atb":[[13,8]],"id":52385893}],"con":true,"img":false}]}
{"op":"mcm","clk":"11550640647","pt":1719501203460,"mc":[{"id":"1.230178172","rc":[{"atl":[[25,0]],"id":52385892}],"con":true,"img":false}]}
{"op":"mcm","clk":"11550640711","pt":1719501204237,"mc":[{"id":"1.230178172","rc":[{"atb":[[20,0]],"id":52385906},{"atb":[[20,0]],"id":52385920},{"atb":[[11,0]],"id":52385892},{"atb":[[16,20]],"id":52385911},{"atb":[[19,0]],"id":52385913}],"con":true,"img":false}]}
{"op":"mcm","clk":"11550640720","pt":1719501204343,"mc":[{"id":"1.230178172","rc":[{"atb":[[18,6]],"id":52385906},{"atb":[[24,5]],"id":52385920},{"atb":[[10,10]],"id":52385892},{"atb":[[16,0],[14,8]],"id":52385911},{"atb":[[17,7]],"id":52385913}],"con":true,"img":false}]}
{"op":"mcm","clk":"11550640727","pt":1719501204443,"mc":[{"id":"1.230178172","rc":[{"atb":[[15.5,15]],"id":52385911}],"con":true,"img":false}]}
{"op":"mcm","clk":"11550640783","pt":1719501205371,"mc":[{"id":"1.230178172","rc":[{"atb":[[15.5,0]],"id":52385911}],"con":true,"img":false}]}
{"op":"mcm","clk":"11550640791","pt":1719501205472,"mc":[{"id":"1.230178172","rc":[{"atb":[[14.5,26]],"id":52385911}],"con":true,"img":false}]}
{"op":"mcm","clk":"11550640799","pt":1719501205577,"mc":[{"id":"1.230178172","rc":[{"atb":[[15.5,10]],"id":52385911}],"con":true,"img":false}]}
{"op":"mcm","clk":"11550640812","pt":1719501205782,"mc":[{"id":"1.230178172","rc":[{"atb":[[15.5,0]],"id":52385911}],"con":true,"img":false}]}
{"op":"mcm","clk":"11550640845","pt":1719501206250,"mc":[{"id":"1.230178172","rc":[{"atl":[[80,0],[90,2.5],[60,0],[120,7]],"id":52385921}],"con":true,"img":false}]}
{"op":"mcm","clk":"11550640860","pt":1719501206454,"mc":[{"id":"1.230178172","rc":[{"atl":[[65,9.38]],"id":52385921}],"con":true,"img":false}]}
{"op":"mcm","clk":"11550640875","pt":1719501206663,"mc":[{"id":"1.230178172","rc":[{"atl":[[65,0]],"id":52385921}],"con":true,"img":false}]}
{"op":"mcm","clk":"11550640885","pt":1719501206765,"mc":[{"id":"1.230178172","rc":[{"atl":[[75,8.11]],"id":52385921}],"con":true,"img":false}]}
{"op":"mcm","clk":"11550640897","pt":1719501206971,"mc":[{"id":"1.230178172","rc":[{"atl":[[75,0]],"id":52385921},{"atb":[[16.5,0]],"id":52385882}],"con":true,"img":false}]}
{"op":"mcm","clk":"11550640905","pt":1719501207073,"mc":[{"id":"1.230178172","rc":[{"atl":[[85,7.14]],"id":52385921},{"atb":[[16,20]],"id":52385882}],"con":true,"img":false}]}
{"op":"mcm","clk":"11550640918","pt":1719501207330,"mc":[{"id":"1.230178172","rc":[{"atb":[[20,5]],"id":52385907}],"con":true,"img":false}]}
{"op":"mcm","clk":"11550640927","pt":1719501207434,"mc":[{"id":"1.230178172","rc":[{"atb":[[24,7.5]],"id":52385907}],"con":true,"img":false}]}
{"op":"mcm","clk":"11550640956","pt":1719501207846,"mc":[{"id":"1.230178172","rc":[{"atb":[[26,20]],"id":52385884}],"con":true,"img":false}]}
{"op":"mcm","clk":"11550640970","pt":1719501208055,"mc":[{"id":"1.230178172","rc":[{"atb":[[23,0]],"id":52385884}],"con":true,"img":false}]}
{"op":"mcm","clk":"11550641014","pt":1719501208670,"mc":[{"id":"1.230178172","rc":[{"atl":[[65,5],[80,0],[48,2.5],[60,0]],"id":52385910},{"atl":[[24,0]],"id":52385892},{"atb":[[18,0],[18.5,5],[20,0],[21,2.5]],"id":52385898},{"atl":[[38,2.5],[60,0]],"id":52385911},{"atl":[[65,0],[80,5],[85,0],[60,12.67]],"id":52385913},{"atl":[[60,0]],"id":52385919},{"atl":[[65,11.88],[70,0],[85,5],[90,0]],"id":52385899}],"con":true,"img":false}]}
{"op":"mcm","clk":"11550641025","pt":1719501208772,"mc":[{"id":"1.230178172","rc":[{"atl":[[36,17.14],[44,0]],"id":52385910},{"atl":[[60,10.17]],"id":52385914},{"atl":[[25,25]],"id":52385892},{"atl":[[48,12.77]],"id":52385913},{"atl":[[65,11.88]],"id":52385919}],"con":true,"img":false}]}
{"op":"mcm","clk":"11550641035","pt":1719501208979,"mc":[{"id":"1.230178172","rc":[{"atl":[[65,0]],"id":52385914},{"atl":[[60,2.5]],"id":52385913}],"con":true,"img":false}]}
{"op":"mcm","clk":"11550641074","pt":1719501209553,"mc":[{"id":"1.230178172","rc":[{"atb":[[29,0]],"id":52385896}],"con":true,"img":false}]}
{"op":"mcm","clk":"11550641084","pt":1719501209659,"mc":[{"id":"1.230178172","rc":[{"atb":[[28,15.8]],"id":52385896}],"con":true,"img":false}]}
{"op":"mcm","clk":"11550641174","pt":1719501210739,"mc":[{"id":"1.230178172","rc":[{"atb":[[30,15.8]],"id":52385896}],"con":true,"img":false}]}
{"op":"mcm","clk":"11550641187","pt":1719501210998,"mc":[{"id":"1.230178172","rc":[{"atb":[[28,0]],"id":52385896}],"con":true,"img":false}]}
{"op":"mcm","clk":"11550641201","pt":1719501211155,"mc":[{"id":"1.230178172","rc":[{"atl":[[28,21]],"id":52385911},{"atl":[[65,0],[140,7],[85,0],[100,2.5]],"id":52385919}],"con":true,"img":false}]}
{"op":"mcm","clk":"11550641213","pt":1719501211259,"mc":[{"id":"1.230178172","rc":[{"atl":[[36,0]],"id":52385911},{"atl":[[130,2],[140,5],[70,8.7]],"id":52385919}],"con":true,"img":false}]}
{"op":"mcm","clk":"11550641231","pt":1719501211467,"mc":[{"id":"1.230178172","rc":[{"atl":[[70,0]],"id":52385919}],"con":true,"img":false}]}
{"op":"mcm","clk":"11550641238","pt":1719501211567,"mc":[{"id":"1.230178172","rc":[{"atl":[[130,0],[140,7],[95,6.38]],"id":52385919}],"con":true,"img":false}]}
{"op":"mcm","clk":"11550641278","pt":1719501212146,"mc":[{"id":"1.230178172","rc":[{"atl":[[40,0]],"id":52385918}],"con":true,"img":false}]}
{"op":"mcm","clk":"11550641287","pt":1719501212251,"mc":[{"id":"1.230178172","rc":[{"atl":[[42,14.63]],"id":52385918},{"atb":[[20,0]],"id":52385917}],"con":true,"img":false}]}
{"op":"mcm","clk":"11550641293","pt":1719501212354,"mc":[{"id":"1.230178172","rc":[{"atb":[[24,5]],"id":52385917}],"con":true,"img":false}]}
{"op":"mcm","clk":"11550641303","pt":1719501212459,"mc":[{"id":"1.230178172","rc":[{"atl":[[42,0]],"id":52385918}],"con":true,"img":false}]}
{"op":"mcm","clk":"11550641310","pt":1719501212563,"mc":[{"id":"1.230178172","rc":[{"atl":[[44,13.95]],"id":52385918}],"con":true,"img":false}]}
{"op":"mcm","clk":"11550641365","pt":1719501213346,"mc":[{"id":"1.230178172","rc":[{"atb":[[6.6,2.5]],"id":52385889},{"atl":[[200,2]],"id":52385921},{"atb":[[13,0]],"id":52385893}],"con":true,"img":false}]}
{"op":"mcm","clk":"11550641374","pt":1719501213501,"mc":[{"id":"1.230178172","rc":[{"atb":[[4,33.33],[8.6,0]],"id":52385910},{"atl":[[65,0],[36,0],[80,5],[48,0],[60,2.5]],"id":52385910},{"atb":[[2.24,80.65],[19.5,17],[6.2,0]],"id":52385912},{"atl":[[85,5],[120,2]],"id":52385912},{"atb":[[3.7,37.04],[7.8,0]],"id":52385906},{"atl":[[150,2],[110,0]],"id":52385906},{"atb":[[9.2,0]],"id":52385918},{"atl":[[70,2.5],[75,0],[150,0],[44,0],[90,5],[210,2],[55,2.1]],"id":52385918},{"atb":[[11,0],[30,20]],"id":52385920},{"atl":[[75,8.11],[150,5],[310,2],[95,0],[190,0],[110,2.5]],"id":52385920},{"atb":[[10.5,0],[6,2],[5.2,23.81],[13.5,0],[9.4,0]],"id":52385889},{"atl":[[80,0],[48,2.13]],"id":52385889},{"atb":[[9,0]],"id":52385914},{"atl":[[130,0],[190,2]],"id":52385914},{"atb":[[17.5,0],[7.4,0],[6,14],[13.5,0]],"id":52385883},{"atl":[[80,2],[100,0]],"id":52385883},{"atl":[[70,0],[80,5],[90,0],[60,2.5]],"id":52385896},{"atb":[[11.5,4]],"id":52385890},{"atb":[[11,0]],"id":52385898},{"atb":[[5,25],[12.5,0]],"id":52385900},{"atl":[[140,5],[85,7.14],[100,2.5],[110,0]],"id":52385900},{"atb":[[6.4,0],[1.14,156.03]],"id":52385911},{"atl":[[38,0],[80,0],[28,0],[60,5],[120,2]],"id":52385911},{"atb":[[7.4,0],[23,24]],"id":52385913},{"atl":[[160,2],[95,0]],"id":52385913},{"atb":[[11.5,0],[3.9,34.48]],"id":52385907},{"atl":[[70,8.7],[280,2],[220,0],[120,5]],"id":52385907},{"atl":[[190,2],[240,0]],"id":52385886},{"atb":[[9.6,0]],"id":52385919},{"atb":[[9,0],[23,26]],"id":52385921},{"atl":[[120,5]],"id":52385921},{"atb":[[16,0],[7.2,0],[10.5,0],[12.5,0],[5.4,22.73]],"id":52385882},{"atl":[[95,0],[27,20],[60,2]],"id":52385882},{"atb":[[8.6,13.16],[10,0],[26,0]],"id":52385884},{"atl":[[85,0],[48,2.5]],"id":52385884},{"atb":[[11.5,0],[4.2,31.25]],"id":52385917},{"atl":[[75,0],[290,2],[220,0]],"id":52385917},{"atl":[[65,5],[75,0],[48,2.5],[55,0]],"id":52385897},{"atl":[[25,25]],"id":52385891},{"atb":[[16,34],[6.8,16],[8.8,5]],"id":52385893},{"atl":[[65,0],[80,5],[85,0],[60,12.67]],"id":52385903},{"atb":[[8.2,0],[25,20],[7,15]],"id":52385905},{"atl":[[90,2],[110,0]],"id":52385905},{"atb":[[6,14],[9.8,0]],"id":52385899},{"atl":[[140,0],[180,2]],"id":52385899}],"con":true,"img":false}]}
{"op":"mcm","clk":"11550641384","pt":1719501213555,"mc":[{"id":"1.230178172","rc":[{"atl":[[100,6.06]],"id":52385910},{"atb":[[1.76,100]],"id":52385918},{"atl":[[55,13.21]],"id":52385918},{"atb":[[29,0]],"id":52385920},{"atb":[[9,5],[9.8,2.5]],"id":52385883},{"atb":[[8.2,0],[9.4,11]],"id":52385885},{"atl":[[85,2],[120,0]],"id":52385885},{"atl":[[180,0],[120,2]],"id":52385896},{"atb":[[5.6,0],[6.4,13]],"id":52385890},{"atl":[[36,7.86],[50,0]],"id":52385890},{"atb":[[6,2],[7,16.67]],"id":52385892},{"atb":[[8,0],[10,11.11]],"id":52385904},{"atl":[[90,2],[120,0]],"id":52385904},{"atb":[[13.5,8]],"id":52385898},{"atl":[[290,0],[85,0],[240,2]],"id":52385900},{"atl":[[44,13.95]],"id":52385911},{"atb":[[1.32,100]],"id":52385913},{"atl":[[70,0]],"id":52385907},{"atb":[[22,0]],"id":52385921},{"atb":[[11,25],[7.8,2.5],[7,5]],"id":52385882},{"atl":[[29,2.93]],"id":52385882},{"atb":[[25,20]],"id":52385884},{"atl":[[150,0],[100,2],[55,11.11]],"id":52385884},{"atb":[[10.5,8.9],[8.4,0]],"id":52385897},{"atl":[[130,0],[90,2]],"id":52385897},{"atb":[[8,14.29],[6.6,0]],"id":52385891},{"atl":[[65,2],[90,0],[29,0]],"id":52385891},{"atl":[[140,0],[90,2]],"id":52385893},{"atl":[[130,2],[160,0]],"id":52385903},{"atb":[[20,6]],"id":52385905}],"con":true,"img":false}]}
{"op":"mcm","clk":"11550641392","pt":1719501213658,"mc":[{"id":"1.230178172","rc":[{"atb":[[6.2,10]],"id":52385889},{"atl":[[90,6.74]],"id":52385900},{"atb":[[22,0]],"id":52385913},{"atl":[[48,0]],"id":52385913}],"con":true,"img":false}]}
{"op":"mcm","clk":"11550641402","pt":1719501213763,"mc":[{"id":"1.230178172","rc":[{"atl":[[19.5,10]],"id":52385889},{"atl":[[50,12.24]],"id":52385913},{"atl":[[75,8.11]],"id":52385907},{"atl":[[60,0]],"id":52385884}],"con":true,"img":false}]}
{"op":"mcm","clk":"11550641415","pt":1719501213971,"mc":[{"id":"1.230178172","rc":[{"atl":[[21,3]],"id":52385889}],"con":true,"img":false}]}
{"op":"mcm","clk":"11550641422","pt":1719501214074,"mc":[{"id":"1.230178172","rc":[{"atl":[[40,15.38]],"id":52385883},{"atl":[[75,0]],"id":52385907}],"con":true,"img":false}]}
{"op":"mcm","clk":"11550641427","pt":1719501214179,"mc":[{"id":"1.230178172","rc":[{"atb":[[19.5,22]],"id":52385918},{"atb":[[8,12]],"id":52385889},{"atl":[[48,0]],"id":52385883},{"atl":[[85,7.14]],"id":52385907}],"con":true,"img":false}]}
{"op":"mcm","clk":"11550641441","pt":1719501214387,"mc":[{"id":"1.230178172","rc":[{"atl":[[65,0],[80,5],[85,0],[60,12.67]],"id":52385912},{"atb":[[18.5,0]],"id":52385918}],"con":true,"img":false}]}
{"op":"mcm","clk":"11550641449","pt":1719501214555,"mc":[{"id":"1.230178172","rc":[{"atl":[[42,14.63]],"id":52385904}],"con":true,"img":false}]}
{"op":"mcm","clk":"11550641456","pt":1719501214659,"mc":[{"id":"1.230178172","rc":[{"atl":[[46,0]],"id":52385904},{"atl":[[34,18.18]],"id":52385911}],"con":true,"img":false}]}
{"op":"mcm","clk":"11550641471","pt":1719501214854,"mc":[{"id":"1.230178172","rc":[{"atl":[[44,0]],"id":52385911}],"con":true,"img":false}]}
{"op":"mcm","clk":"11550641480","pt":1719501214958,"mc":[{"id":"1.230178172","rc":[{"atb":[[30,20.69]],"id":52385919}],"con":true,"img":false}]}
{"op":"mcm","clk":"11550641494","pt":1719501215167,"mc":[{"id":"1.230178172","rc":[{"atb":[[24,5]],"id":52385919}],"con":true,"img":false}]}
{"op":"mcm","clk":"11550641501","pt":1719501215270,"mc":[{"id":"1.230178172","rc":[{"atl":[[65,0],[80,5],[85,0],[60,12.67]],"id":52385906}],"con":true,"img":false}]}
{"op":"mcm","clk":"11550641509","pt":1719501215375,"mc":[{"id":"1.230178172","rc":[{"atb":[[30,0]],"id":52385896},{"atl":[[50,0]],"id":52385913}],"con":true,"img":false}]}
{"op":"mcm","clk":"11550641519","pt":1719501215483,"mc":[{"id":"1.230178172","rc":[{"atb":[[23,15.8]],"id":52385896}],"con":true,"img":false}]}
{"op":"mcm","clk":"11550641526","pt":1719501215581,"mc":[{"id":"1.230178172","rc":[{"atl":[[23,27.27]],"id":52385892},{"atl":[[55,11.11]],"id":52385913}],"con":true,"img":false}]}
{"op":"mcm","clk":"11550641543","pt":1719501215752,"mc":[{"id":"1.230178172","rc":[{"atl":[[25,0]],"id":52385892}],"con":true,"img":false}]}
{"op":"mcm","clk":"11550641578","pt":1719501216260,"mc":[{"id":"1.230178172","rc":[{"atb":[[10,0]],"id":52385892}],"con":true,"img":false}]}
{"op":"mcm","clk":"11550641600","pt":1719501216569,"mc":[{"id":"1.230178172","rc":[{"atb":[[24,0]],"id":52385919},{"atb":[[11,2.5]],"id":52385891}],"con":true,"img":false}]}
{"op":"mcm","clk":"11550641609","pt":1719501216675,"mc":[{"id":"1.230178172","rc":[{"atb":[[38,5]],"id":52385919},{"atb":[[10,9]],"id":52385891}],"con":true,"img":false}]}
{"op":"mcm","clk":"11550641816","pt":1719501219575,"mc":[{"id":"1.230178172","rc":[{"atl":[[150,2],[200,0]],"id":52385921}],"con":true,"img":false}]}
{"op":"mcm","clk":"11550641824","pt":1719501219679,"mc":[{"id":"1.230178172","rc":[{"atb":[[4,0],[6.6,13]],"id":52385910},{"atl":[[90,2],[120,0]],"id":52385912},{"atb":[[6.2,11],[3.7,0]],"id":52385906},{"atl":[[150,2],[210,0]],"id":52385918},{"atl":[[310,0],[230,2]],"id":52385920},{"atb":[[6.2,24.5],[5.2,0]],"id":52385889},{"atl":[[38,2.7],[48,0]],"id":52385889},{"atl":[[150,2],[190,0]],"id":52385914},{"atb":[[7.4,14],[6,2]],"id":52385883},{"atl":[[80,0],[60,2]],"id":52385883},{"atb":[[5,0],[8.8,12.82]],"id":52385900},{"atb":[[3.2,45.45],[1.14,0]],"id":52385911},{"atl":[[85,2],[120,0]],"id":52385911},{"atl":[[160,0],[120,2]],"id":52385913},{"atl":[[280,0],[210,2]],"id":52385907},{"atl":[[150,2],[190,0]],"id":52385886},{"atb":[[6.4,10],[5.4,0]],"id":52385882},{"atl":[[46,2.22],[60,0]],"id":52385882},{"atb":[[8.6,0],[10.5,10]],"id":52385884},{"atl":[[290,0],[210,2]],"id":52385917},{"atb":[[9,9.8],[6.8,0]],"id":52385893},{"atb":[[9.2,11],[7,0]],"id":52385905},{"atb":[[6,2],[8.8,12.82]],"id":52385899},{"atl":[[140,2],[180,0]],"id":52385899}],"con":true,"img":false}]}
{"op":"mcm","clk":"11550641839","pt":1719501219887,"mc":[{"id":"1.230178172","rc":[{"atl":[[75,0]],"id":52385920}],"con":true,"img":false}]}
{"op":"mcm","clk":"11550641848","pt":1719501219989,"mc":[{"id":"1.230178172","rc":[{"atl":[[80,7.59]],"id":52385920}],"con":true,"img":false}]}
{"op":"mcm","clk":"11550641866","pt":1719501220197,"mc":[{"id":"1.230178172","rc":[{"atl":[[80,0]],"id":52385920},{"atl":[[60,0]],"id":52385914}],"con":true,"img":false}]}
{"op":"mcm","clk":"11550641883","pt":1719501220403,"mc":[{"id":"1.230178172","rc":[{"atl":[[100,6.06]],"id":52385920},{"atl":[[65,9.38]],"id":52385914}],"con":true,"img":false}]}
{"op":"mcm","clk":"11550641890","pt":1719501220510,"mc":[{"id":"1.230178172","rc":[{"atl":[[60,0]],"id":52385917}],"con":true,"img":false}]}
{"op":"mcm","clk":"11550641912","pt":1719501220664,"mc":[{"id":"1.230178172","rc":[{"atl":[[65,7.82]],"id":52385917}],"con":true,"img":false}]}
{"op":"mcm","clk":"11550642014","pt":1719501222159,"mc":[{"id":"1.230178172","rc":[{"atl":[[55,11.11]],"id":52385910},{"atl":[[48,12.77]],"id":52385913},{"atl":[[90,6.74]],"id":52385919}],"con":true,"img":false}]}
{"op":"mcm","clk":"11550642027","pt":1719501222367,"mc":[{"id":"1.230178172","rc":[{"atl":[[100,0]],"id":52385910},{"atl":[[55,0]],"id":52385913},{"atl":[[95,0]],"id":52385919}],"con":true,"img":false}]}
{"op":"mcm","clk":"11550642061","pt":1719501222987,"mc":[{"id":"1.230178172","rc":[{"atb":[[29,15.8]],"id":52385896}],"con":true,"img":false}]}
{"op":"mcm","clk":"11550642073","pt":1719501223195,"mc":[{"id":"1.230178172","rc":[{"atb":[[23,0]],"id":52385896}],"con":true,"img":false}]}
{"op":"mcm","clk":"11550642320","pt":1719501226661,"mc":[{"id":"1.230178172","rc":[{"atl":[[25,15.86]],"id":52385882}],"con":true,"img":false}]}
{"op":"mcm","clk":"11550642328","pt":1719501226765,"mc":[{"id":"1.230178172","rc":[{"atl":[[27,0]],"id":52385882},{"atl":[[46,13.33]],"id":52385884}],"con":true,"img":false}]}
{"op":"mcm","clk":"11550642339","pt":1719501226970,"mc":[{"id":"1.230178172","rc":[{"atb":[[8.2,26]],"id":52385889},{"atl":[[55,0]],"id":52385884}],"con":true,"img":false}]}
{"op":"mcm","clk":"11550642348","pt":1719501227073,"mc":[{"id":"1.230178172","rc":[{"atl":[[19,26]],"id":52385889}],"con":true,"img":false}]}
{"op":"mcm","clk":"11550642354","pt":1719501227178,"mc":[{"id":"1.230178172","rc":[{"atb":[[6.2,14.5]],"id":52385889}],"con":true,"img":false}]}
{"op":"mcm","clk":"11550642365","pt":1719501227280,"mc":[{"id":"1.230178172","rc":[{"atl":[[19.5,0]],"id":52385889},{"atb":[[38,0]],"id":52385919},{"atb":[[10,0]],"id":52385891}],"con":true,"img":false}]}
{"op":"mcm","clk":"11550642373","pt":1719501227383,"mc":[{"id":"1.230178172","rc":[{"atb":[[24,5]],"id":52385919},{"atb":[[11,11.5]],"id":52385891}],"con":true,"img":false}]}
{"op":"mcm","clk":"11550642402","pt":1719501227792,"mc":[{"id":"1.230178172","rc":[{"atb":[[18,0]],"id":52385918},{"atl":[[21,0]],"id":52385889},{"atb":[[17,0]],"id":52385883},{"atl":[[50,5]],"id":52385883},{"atb":[[18.5,0]],"id":52385896},{"atb":[[11.5,0]],"id":52385890},{"atl":[[32,0]],"id":52385890},{"atb":[[11,20]],"id":52385882},{"atl":[[29,0]],"id":52385882},{"atl":[[46,0]],"id":52385897},{"atb":[[10.5,0]],"id":52385893}],"con":true,"img":false}]}
{"op":"mcm","clk":"11550642405","pt":1719501227895,"mc":[{"id":"1.230178172","rc":[{"atb":[[11,33.72]],"id":52385890}],"con":true,"img":false}]}
{"op":"mcm","clk":"11550642410","pt":1719501227999,"mc":[{"id":"1.230178172","rc":[{"atb":[[22,3.4]],"id":52385910},{"atb":[[20,3.87]],"id":52385912},{"atb":[[24,3.85]],"id":52385906},{"atb":[[20,4.16]],"id":52385918},{"atb":[[21,2.73]],"id":52385920},{"atl":[[95,2.3]],"id":52385920},{"atl":[[16.5,3]],"id":52385889},{"atb":[[21,4.3]],"id":52385914},{"atb":[[16.5,4.37]],"id":52385883},{"atl":[[38,2.4]],"id":52385883},{"atb":[[22,2.6]],"id":52385885},{"atb":[[9.6,5]],"id":52385890},{"atl":[[22,3.4]],"id":52385890},{"atb":[[13.5,3.3]],"id":52385892},{"atb":[[18.5,18.5]],"id":52385904},{"atb":[[19,3.69]],"id":52385898},{"atb":[[17.5,4.08]],"id":52385900},{"atl":[[85,2.6]],"id":52385900},{"atb":[[15,4.7]],"id":52385911},{"atb":[[24,3]],"id":52385913},{"atb":[[30,3.2]],"id":52385907},{"atl":[[80,2.38]],"id":52385907},{"atb":[[32,3.61]],"id":52385919},{"atl":[[85,2.4]],"id":52385919},{"atb":[[24,2.85]],"id":52385921},{"atb":[[7.2,5.04],[11,0]],"id":52385882},{"atl":[[23,2.87]],"id":52385882},{"atb":[[16.5,3.62]],"id":52385884},{"atl":[[42,3.07],[44,0]],"id":52385897},{"atb":[[10.5,6]],"id":52385891},{"atl":[[36,5.73]],"id":52385891},{"atb":[[9.6,7.5]],"id":52385893},{"atb":[[18.5,4.1]],"id":52385903},{"atl":[[55,2.77]],"id":52385903},{"atb":[[26,4]],"id":52385905},{"atb":[[28,3.63]],"id":52385899}],"con":true,"img":false}]}
{"op":"mcm","clk":"11550642420","pt":1719501228103,"mc":[{"id":"1.230178172","rc":[{"atb":[[23,26]],"id":52385910},{"atb":[[20,25.87]],"id":52385912},{"atb":[[21,22]],"id":52385918},{"atb":[[22,26]],"id":52385914},{"atl":[[85,9.74]],"id":52385900},{"atl":[[80,7.59]],"id":52385919},{"atb":[[10.5,15]],"id":52385882},{"atl":[[46,13.33]],"id":52385897}],"con":true,"img":false}]}
{"op":"mcm","clk":"11550642428","pt":1719501228205,"mc":[{"id":"1.230178172","rc":[{"atb":[[24,25.85]],"id":52385906},{"atl":[[36,13.74]],"id":52385883},{"atl":[[21,16.8]],"id":52385890},{"atb":[[13.5,19.9]],"id":52385892},{"atb":[[15.5,26]],"id":52385911},{"atb":[[25,24]],"id":52385913},{"atb":[[32,19.35]],"id":52385907},{"atl":[[75,8.11]],"id":52385907},{"atb":[[32,20.83]],"id":52385919},{"atb":[[25,22]],"id":52385921},{"atl":[[50,12.24]],"id":52385903},{"atb":[[28,25.63]],"id":52385899}],"con":true,"img":false}]}
{"op":"mcm","clk":"11550642435","pt":1719501228261,"mc":[{"id":"1.230178172","rc":[{"atb":[[21,0]],"id":52385910},{"atb":[[19.5,0]],"id":52385918},{"atl":[[90,0]],"id":52385900}],"con":true,"img":false}]}
{"op":"mcm","clk":"11550642443","pt":1719501228364,"mc":[{"id":"1.230178172","rc":[{"atb":[[19.5,0]],"id":52385912},{"atb":[[23,0]],"id":52385906},{"atb":[[20,0]],"id":52385914},{"atl":[[40,0]],"id":52385883},{"atl":[[23,0]],"id":52385890},{"atb":[[13,0]],"id":52385892},{"atb":[[14.5,0]],"id":52385911},{"atb":[[23,0]],"id":52385913},{"atb":[[29,0]],"id":52385907},{"atl":[[85,0]],"id":52385907},{"atb":[[30,0]],"id":52385919},{"atl":[[90,0]],"id":52385919},{"atb":[[23,0]],"id":52385921},{"atl":[[60,2.5]],"id":52385903},{"atb":[[27,0]],"id":52385899}],"con":true,"img":false}]}
{"op":"mcm","clk":"11550642474","pt":1719501228875,"mc":[{"id":"1.230178172","rc":[{"atb":[[10.5,10],[6.6,0]],"id":52385910},{"atl":[[42,14.63],[90,2],[110,0]],"id":52385910},{"atb":[[2.24,0],[20,3.87],[7.6,8.5]],"id":52385912},{"atb":[[6.2,0],[8.4,11]],"id":52385906},{"atb":[[11,10],[1.76,0]],"id":52385918},{"atl":[[150,0],[100,2]],"id":52385918},{"atb":[[12,9.09]],"id":52385920},{"atl":[[140,2],[230,0]],"id":52385920},{"atb":[[7.2,16.13],[6.2,0],[6.8,2.5],[6.6,0]],"id":52385889},{"atl":[[38,0],[55,2]],"id":52385889},{"atb":[[10,10]],"id":52385914},{"atl":[[150,0],[90,7]],"id":52385914},{"atb":[[9.2,8.74],[7.4,0],[17,13.74]],"id":52385883},{"atl":[[85,2],[60,0]],"id":52385883},{"atb":[[22,24.6]],"id":52385885},{"atl":[[85,0],[120,2]],"id":52385885},{"atb":[[11,0],[14.5,7.41]],"id":52385896},{"atl":[[100,5],[230,2],[60,0],[120,0]],"id":52385896},{"atb":[[5.6,21.74],[6.4,0]],"id":52385890},{"atl":[[36,5],[55,2]],"id":52385890},{"atb":[[5.8,20.83],[7,0]],"id":52385892},{"atl":[[70,0],[22,15],[46,2.22]],"id":52385892},{"atb":[[8.8,12.82]],"id":52385904},{"atb":[[13.5,0],[7.8,10]],"id":52385898},{"atl":[[180,0],[250,2]],"id":52385898},{"atb":[[11.5,9.52],[8.8,0]],"id":52385900},{"atl":[[310,2]],"id":52385900},{"atb":[[3.2,0],[7.6,10]],"id":52385911},{"atl":[[85,0],[60,7]],"id":52385911},{"atb":[[9,10],[25,0],[1.32,0]],"id":52385913},{"atl":[[85,2],[120,0]],"id":52385913},{"atb":[[3.9,0]],"id":52385907},{"atl":[[210,0]],"id":52385907},{"atb":[[11.5,0],[14,7.69]],"id":52385886},{"atl":[[150,0],[210,2]],"id":52385886},{"atb":[[32,3.61],[10.5,10]],"id":52385919},{"atl":[[140,5],[110,2]],"id":52385919},{"atb":[[10,10],[25,0]],"id":52385921},{"atl":[[150,0],[120,7]],"id":52385921},{"atb":[[6.4,0],[7.4,15.62]],"id":52385882},{"atl":[[70,2],[46,0]],"id":52385882},{"atb":[[10.5,0],[13,8.33]],"id":52385884},{"atl":[[85,5],[170,2],[48,0],[100,0]],"id":52385884},{"atb":[[14,7.69],[4.2,0]],"id":52385917},{"atl":[[150,2],[210,0]],"id":52385917},{"atl":[[140,2],[90,0]],"id":52385897},{"atb":[[8,0],[6.8,17.24]],"id":52385891},{"atl":[[25,0]],"id":52385891},{"atb":[[9,0],[7.6,15.15]],"id":52385893},{"atb":[[10.5,0],[14,7.69]],"id":52385903},{"atl":[[130,0],[70,2.5],[80,0],[200,2],[60,0]],"id":52385903},{"atb":[[9.2,0],[26,26],[7,11]],"id":52385905},{"atl":[[90,0],[110,2]],"id":52385905},{"atb":[[10,11],[8.8,0]],"id":52385899}],"con":true,"img":false}]}
{"op":"mcm","clk":"11550642482","pt":1719501228982,"mc":[{"id":"1.230178172","rc":[{"atb":[[11,44.22]],"id":52385890},{"atb":[[10,0]],"id":52385904},{"atl":[[240,0]],"id":52385900},{"atb":[[10.5,10.53]],"id":52385907},{"atl":[[170,2]],"id":52385907}],"con":true,"img":false}]}
{"op":"mcm","clk":"11550642489","pt":1719501229085,"mc":[{"id":"1.230178172","rc":[{"atb":[[10.5,0],[8.4,10]],"id":52385910},{"atl":[[90,0],[55,0],[120,2]],"id":52385910},{"atb":[[11,0],[8.8,10]],"id":52385918},{"atl":[[140,0],[190,2]],"id":52385920},{"atb":[[7.2,0],[6,22]],"id":52385889},{"atb":[[10,0],[8.2,10]],"id":52385914},{"atl":[[90,5],[120,2]],"id":52385914},{"atb":[[8,9.37],[9.2,0]],"id":52385883},{"atb":[[21,0]],"id":52385885},{"atb":[[11.5,9.52],[14.5,0]],"id":52385896},{"atl":[[23,0]],"id":52385892},{"atb":[[12,9.09],[7.8,0]],"id":52385898},{"atb":[[6.2,10],[7.6,0]],"id":52385911},{"atl":[[80,2],[60,5]],"id":52385911},{"atl":[[85,0],[110,2]],"id":52385913},{"atl":[[170,0],[230,2]],"id":52385907},{"atb":[[11,10],[14,0]],"id":52385886},{"atl":[[140,7],[110,0]],"id":52385919},{"atb":[[10,0],[8.2,10]],"id":52385921},{"atb":[[10.5,0]],"id":52385882},{"atb":[[10,10],[13,0]],"id":52385884},{"atl":[[46,0]],"id":52385884},{"atb":[[11,10],[14,0]],"id":52385917},{"atl":[[34,18.18],[85,2]],"id":52385891},{"atb":[[11,9.1],[14,0]],"id":52385903},{"atb":[[9.4,10],[25,0],[7,0]],"id":52385905}],"con":true,"img":false}]}
{"op":"mcm","clk":"11550642497","pt":1719501229187,"mc":[{"id":"1.230178172","rc":[{"atb":[[10,35.74],[6.8,10.08]],"id":52385882},{"atl":[[60,10.17]],"id":52385884},{"atl":[[65,0]],"id":52385891}],"con":true,"img":false}]}
{"op":"mcm","clk":"11550642504","pt":1719501229289,"mc":[{"id":"1.230178172","rc":[{"atb":[[7.4,0]],"id":52385882}],"con":true,"img":false}]}
{"op":"mcm","clk":"11550642512","pt":1719501229393,"mc":[{"id":"1.230178172","rc":[{"atl":[[42,0]],"id":52385910},{"atl":[[34,0]],"id":52385911}],"con":true,"img":false}]}
{"op":"mcm","clk":"11550642528","pt":1719501229602,"mc":[{"id":"1.230178172","rc":[{"atb":[[3.85,35.09],[8.4,0]],"id":52385910},{"atl":[[55,11.11]],"id":52385910},{"atb":[[1.63,150],[20,21.61],[7.6,0]],"id":52385912},{"atl":[[90,0],[110,2]],"id":52385912},{"atb":[[10,11],[8.4,0]],"id":52385906},{"atb":[[8.8,0]],"id":52385918},{"atl":[[100,0],[240,2]],"id":52385918},{"atb":[[12,0]],"id":52385920},{"atl":[[340,2],[190,0]],"id":52385920},{"atb":[[6,2],[5.2,23.81]],"id":52385889},{"atl":[[38,2.7],[55,0]],"id":52385889},{"atb":[[8.2,0]],"id":52385914},{"atl":[[200,2],[120,0]],"id":52385914},{"atb":[[8,0],[5.9,20.41],[17,0]],"id":52385883},{"atl":[[85,0],[60,2]],"id":52385883},{"atb":[[22,2.6],[7.4,12],[9.4,0]],"id":52385885},{"atb":[[11.5,0]],"id":52385896},{"atl":[[160,2],[230,0]],"id":52385896},{"atb":[[5.6,0],[6.2,10]],"id":52385890},{"atl":[[36,7.86],[55,0]],"id":52385890},{"atb":[[4,33.33],[5.8,0]],"id":52385892},{"atl":[[70,2],[22,0],[46,0]],"id":52385892},{"atb":[[10,11.11],[8.8,0]],"id":52385904},{"atl":[[70,11.2],[75,0],[90,5],[95,0],[200,2],[250,0]],"id":52385898},{"atb":[[8.6,13.16],[11.5,0]],"id":52385900},{"atl":[[310,0],[250,2]],"id":52385900},{"atb":[[6.2,0],[2.16,86.21]],"id":52385911},{"atl":[[36,17.14],[80,0],[110,2]],"id":52385911},{"atb":[[9,0],[3.35,42.55],[25,16]],"id":52385913},{"atb":[[10.5,0],[2.94,51.55]],"id":52385907},{"atl":[[290,2],[230,0]],"id":52385907},{"atb":[[11,0],[14,7.69]],"id":52385886},{"atl":[[150,2],[210,0]],"id":52385886},{"atb":[[34,12.22],[10.5,0]],"id":52385919},{"atl":[[140,5],[230,2]],"id":52385919},{"atb":[[8.2,0],[25,17.7]],"id":52385921},{"atl":[[220,2],[120,5]],"id":52385921},{"atb":[[6.8,0],[5.4,22.73]],"id":52385882},{"atl":[[70,0],[46,2.22]],"id":52385882},{"atb":[[10,0],[25,0],[8.4,10]],"id":52385884},{"atl":[[130,2],[170,0]],"id":52385884},{"atb":[[11,0]],"id":52385917},{"atl":[[150,0],[320,2]],"id":52385917},{"atb":[[10.5,0],[8.2,10]],"id":52385897},{"atl":[[140,0],[90,2]],"id":52385897},{"atb":[[8,14.29],[6.8,0]],"id":52385891},{"atl":[[65,2],[85,0]],"id":52385891},{"atb":[[2.22,81.97],[7.6,0]],"id":52385893},{"atl":[[70,5],[140,2],[44,0],[90,0],[50,2.5],[55,0]],"id":52385893},{"atl":[[130,2],[200,0]],"id":52385903},{"atb":[[8.2,12],[26,4],[9.4,0]],"id":52385905},{"atl":[[90,2],[110,0]],"id":52385905},{"atb":[[10,0],[13,8.33]],"id":52385899}],"con":true,"img":false}]}
{"op":"mcm","clk":"11550642534","pt":1719501229704,"mc":[{"id":"1.230178172","rc":[{"atb":[[11,33.72]],"id":52385890}],"con":true,"img":false}]}
{"op":"mcm","clk":"11550642542","pt":1719501229809,"mc":[{"id":"1.230178172","rc":[{"atb":[[3.85,0],[6.2,13]],"id":52385910},{"atb":[[1.63,0],[3.65,37.74]],"id":52385912},{"atl":[[90,2],[110,0]],"id":52385912},{"atl":[[180,2],[240,0]],"id":52385918},{"atb":[[34,15.46],[30,0]],"id":52385920},{"atl":[[340,0],[250,2]],"id":52385920},{"atb":[[6.2,19.23],[5.2,0]],"id":52385889},{"atl":[[150,2],[200,0]],"id":52385914},{"atb":[[7.2,11],[5.9,0]],"id":52385883},{"atb":[[7.4,0],[9.4,11]],"id":52385885},{"atb":[[12,9.09]],"id":52385896},{"atl":[[160,0],[120,2]],"id":52385896},{"atb":[[4,0],[5.3,23.26]],"id":52385892},{"atl":[[70,0],[55,2],[30,20]],"id":52385892},{"atl":[[160,2],[200,0]],"id":52385898},{"atb":[[8.6,0],[12.5,8.7]],"id":52385900},{"atl":[[36,0],[85,2],[110,0]],"id":52385911},{"atb":[[6.6,15],[2.94,0]],"id":52385907},{"atl":[[290,0],[210,2]],"id":52385907},{"atl":[[80,0],[170,2],[230,0]],"id":52385919},{"atl":[[80,7.59],[170,2],[220,0]],"id":52385921},{"atb":[[6.4,10.08],[5.4,0]],"id":52385882},{"atb":[[18.5,17.24],[10.5,8.62],[8.4,0]],"id":52385884},{"atl":[[130,0],[100,2]],"id":52385884},{"atl":[[320,0],[240,2]],"id":52385917},{"atb":[[10,10],[8.2,0]],"id":52385897},{"atb":[[4.6,27.78],[2.22,0]],"id":52385893},{"atb":[[10,11.11],[8.2,0]],"id":52385905}],"con":true,"img":false}]}
{"op":"mcm","clk":"11550642555","pt":1719501229965,"mc":[{"id":"1.230178172","rc":[{"atl":[[38,16.22]],"id":52385911},{"atl":[[85,9.54]],"id":52385919},{"atl":[[85,0]],"id":52385921}],"con":true,"img":false}]}
{"op":"mcm","clk":"11550642687","pt":1719501231981,"mc":[{"id":"1.230178172","rc":[{"atl":[[85,2.4]],"id":52385919},{"atl":[[80,0]],"id":52385921}],"con":true,"img":false}]}
{"op":"mcm","clk":"11550642693","pt":1719501232085,"mc":[{"id":"1.230178172","rc":[{"atl":[[85,7.14]],"id":52385921}],"con":true,"img":false}]}
{"op":"mcm","clk":"11550642758","pt":1719501233119,"mc":[{"id":"1.230178172","rc":[{"atl":[[90,6.74]],"id":52385920}],"con":true,"img":false}]}
{"op":"mcm","clk":"11550642780","pt":1719501233274,"mc":[{"id":"1.230178172","rc":[{"atl":[[100,0]],"id":52385920}],"con":true,"img":false}]}
{"op":"mcm","clk":"11550642828","pt":1719501233895,"mc":[{"id":"1.230178172","rc":[{"atb":[[29,0]],"id":52385896}],"con":true,"img":false}]}
{"op":"mcm","clk":"11550642838","pt":1719501233998,"mc":[{"id":"1.230178172","rc":[{"atb":[[28,20]],"id":52385896}],"con":true,"img":false}]}
{"op":"mcm","clk":"11550642850","pt":1719501234204,"mc":[{"id":"1.230178172","rc":[{"atb":[[16,0]],"id":52385910}],"con":true,"img":false}]}
{"op":"mcm","clk":"11550642872","pt":1719501234514,"mc":[{"id":"1.230178172","rc":[{"atb":[[19,2.5]],"id":52385900}],"con":true,"img":false}]}
{"op":"mcm","clk":"11550642879","pt":1719501234567,"mc":[{"id":"1.230178172","rc":[{"atb":[[24,6]],"id":52385900}],"con":true,"img":false}]}
{"op":"mcm","clk":"11550643003","pt":1719501236122,"mc":[{"id":"1.230178172","rc":[{"atb":[[29,20]],"id":52385896}],"con":true,"img":false}]}
{"op":"mcm","clk":"11550643022","pt":1719501236329,"mc":[{"id":"1.230178172","rc":[{"atb":[[28,0]],"id":52385896}],"con":true,"img":false}]}
{"op":"mcm","clk":"11550643110","pt":1719501237306,"mc":[{"id":"1.230178172","rc":[{"atb":[[24,0]],"id":52385919}],"con":true,"img":false}]}
{"op":"mcm","clk":"11550643117","pt":1719501237411,"mc":[{"id":"1.230178172","rc":[{"atb":[[38,5]],"id":52385919}],"con":true,"img":false}]}
{"op":"mcm","clk":"11550643292","pt":1719501239683,"mc":[{"id":"1.230178172","rc":[{"atl":[[22,15.82]],"id":52385882}],"con":true,"img":false}]}
{"op":"mcm","clk":"11550643307","pt":1719501239891,"mc":[{"id":"1.230178172","rc":[{"atl":[[25,0]],"id":52385882}],"con":true,"img":false}]}
{"op":"mcm","clk":"11550643314","pt":1719501239992,"mc":[{"id":"1.230178172","rc":[{"atb":[[9,30]],"id":52385889}],"con":true,"img":false}]}
{"op":"mcm","clk":"11550643320","pt":1719501240096,"mc":[{"id":"1.230178172","rc":[{"atl":[[16.5,33]],"id":52385889}],"con":true,"img":false}]}
{"op":"mcm","clk":"11550643329","pt":1719501240203,"mc":[{"id":"1.230178172","rc":[{"atb":[[8.2,0]],"id":52385889}],"con":true,"img":false}]}
{"op":"mcm","clk":"11550643335","pt":1719501240303,"mc":[{"id":"1.230178172","rc":[{"atl":[[19,0]],"id":52385889}],"con":true,"img":false}]}
{"op":"mcm","clk":"11550643395","pt":1719501241132,"mc":[{"id":"1.230178172","rc":[{"atl":[[40,13.94]],"id":52385897}],"con":true,"img":false}]}
{"op":"mcm","clk":"11550643401","pt":1719501241183,"mc":[{"id":"1.230178172","rc":[{"atb":[[38,21.22]],"id":52385919}],"con":true,"img":false}]}
{"op":"mcm","clk":"11550643410","pt":1719501241290,"mc":[{"id":"1.230178172","rc":[{"atb":[[34,0]],"id":52385919},{"atb":[[26,22]],"id":52385921},{"atl":[[65,2.3]],"id":52385917},{"atl":[[46,0]],"id":52385897}],"con":true,"img":false}]}
{"op":"mcm","clk":"11550643419","pt":1719501241392,"mc":[{"id":"1.230178172","rc":[{"atl":[[90,6.74]],"id":52385917}],"con":true,"img":false}]}
{"op":"mcm","clk":"11550643428","pt":1719501241494,"mc":[{"id":"1.230178172","rc":[{"atb":[[25,0]],"id":52385921}],"con":true,"img":false}]}
{"op":"mcm","clk":"11550643466","pt":1719501242012,"mc":[{"id":"1.230178172","rc":[{"atl":[[26,24]],"id":52385891}],"con":true,"img":false}]}
{"op":"mcm","clk":"11550643489","pt":1719501242321,"mc":[{"id":"1.230178172","rc":[{"atl":[[34,0]],"id":52385891}],"con":true,"img":false}]}
{"op":"mcm","clk":"11550643523","pt":1719501242784,"mc":[{"id":"1.230178172","rc":[{"atb":[[23,17.24]],"id":52385884}],"con":true,"img":false}]}
{"op":"mcm","clk":"11550643531","pt":1719501242888,"mc":[{"id":"1.230178172","rc":[{"atb":[[36,15.46]],"id":52385920}],"con":true,"img":false}]}
{"op":"mcm","clk":"11550643539","pt":1719501242993,"mc":[{"id":"1.230178172","rc":[{"atb":[[18.5,0]],"id":52385884}],"con":true,"img":false}]}
{"op":"mcm","clk":"11550643547","pt":1719501243094,"mc":[{"id":"1.230178172","rc":[{"atb":[[34,0]],"id":52385920}],"con":true,"img":false}]}
{"op":"mcm","clk":"11550644130","pt":1719501251715,"mc":[{"id":"1.230178172","rc":[{"atl":[[85,0]],"id":52385921}],"con":true,"img":false}]}
{"op":"mcm","clk":"11550644139","pt":1719501251818,"mc":[{"id":"1.230178172","rc":[{"atl":[[90,9.24]],"id":52385921}],"con":true,"img":false}]}
{"op":"mcm","clk":"11550644324","pt":1719501254820,"mc":[{"id":"1.230178172","rc":[{"atb":[[22,0]],"id":52385910},{"atb":[[20,0]],"id":52385918},{"atb":[[21,0]],"id":52385920},{"atl":[[95,0]],"id":52385920},{"atb":[[21,0]],"id":52385914},{"atl":[[38,0]],"id":52385883},{"atb":[[22,0]],"id":52385885},{"atb":[[9.6,0]],"id":52385890},{"atl":[[22,0]],"id":52385890},{"atb":[[13.5,16.6]],"id":52385892},{"atb":[[18.5,15]],"id":52385904},{"atb":[[17.5,0]],"id":52385900},{"atb":[[15,0]],"id":52385911},{"atb":[[24,0]],"id":52385913},{"atb":[[30,0]],"id":52385907},{"atl":[[80,0]],"id":52385907},{"atb":[[15.5,2.5]],"id":52385886},{"atb":[[32,0]],"id":52385919},{"atl":[[85,0]],"id":52385919},{"atb":[[24,0]],"id":52385921},{"atl":[[23,0]],"id":52385882},{"atb":[[16.5,0]],"id":52385917},{"atl":[[65,0]],"id":52385917},{"atl":[[42,0]],"id":52385897},{"atl":[[36,2.5]],"id":52385891},{"atb":[[9.6,2.5]],"id":52385893},{"atl":[[55,0]],"id":52385903}],"con":true,"img":false}]}
{"op":"mcm","clk":"11550644335","pt":1719501254910,"mc":[{"id":"1.230178172","rc":[{"atb":[[23,0]],"id":52385910},{"atb":[[22,0]],"id":52385914},{"atb":[[21,20]],"id":52385885},{"atl":[[21,0]],"id":52385890},{"atb":[[13.5,0]],"id":52385892},{"atl":[[22,20]],"id":52385892},{"atb":[[25,0]],"id":52385913},{"atb":[[32,0]],"id":52385907},{"atl":[[75,0]],"id":52385907},{"atl":[[95,6.38]],"id":52385919},{"atl":[[22,0]],"id":52385882},{"atl":[[40,0]],"id":52385897},{"atl":[[50,0]],"id":52385903}],"con":true,"img":false}]}
{"op":"mcm","clk":"11550644345","pt":1719501255014,"mc":[{"id":"1.230178172","rc":[{"atb":[[22,20],[24,3.9]],"id":52385910},{"atb":[[22,3]],"id":52385918},{"atb":[[38,3.1]],"id":52385920},{"atl":[[90,0],[110,4.9]],"id":52385920},{"atb":[[21,26],[23,4.1]],"id":52385914},{"atl":[[34,3]],"id":52385883},{"atb":[[16.5,4.84]],"id":52385885},{"atl":[[65,7.69]],"id":52385885},{"atb":[[18.5,3.7]],"id":52385896},{"atb":[[8.8,7.8]],"id":52385890},{"atl":[[20,2.9],[22,25.72]],"id":52385890},{"atb":[[9,6.7],[13.5,20]],"id":52385892},{"atl":[[30,0]],"id":52385892},{"atb":[[14,3.8]],"id":52385904},{"atl":[[40,2.7]],"id":52385904},{"atb":[[34,2.69]],"id":52385900},{"atb":[[16,4]],"id":52385911},{"atb":[[24,24],[26,3]],"id":52385913},{"atb":[[34,3],[30,20.69]],"id":52385907},{"atl":[[80,7.59],[85,2]],"id":52385907},{"atb":[[27,3.59]],"id":52385886},{"atb":[[40,3]],"id":52385919},{"atl":[[100,4.5]],"id":52385919},{"atb":[[27,2.7]],"id":52385921},{"atl":[[21,3],[46,0],[23,15.08],[48,7.13]],"id":52385882},{"atl":[[55,2.1]],"id":52385884},{"atb":[[28,3.25]],"id":52385917},{"atl":[[85,2]],"id":52385917},{"atl":[[38,2.1],[42,14.63]],"id":52385897},{"atl":[[25,2.8]],"id":52385891},{"atb":[[16.5,4]],"id":52385893},{"atl":[[48,3],[55,11.11]],"id":52385903}],"con":true,"img":false}]}
{"op":"mcm","clk":"11550644353","pt":1719501255116,"mc":[{"id":"1.230178172","rc":[{"atb":[[23,22]],"id":52385918},{"atl":[[95,6.38]],"id":52385920},{"atl":[[32,14.74]],"id":52385883},{"atl":[[80,2],[120,0]],"id":52385885},{"atb":[[13.5,0]],"id":52385892},{"atl":[[38,16.22]],"id":52385904},{"atb":[[36,17.14]],"id":52385900},{"atb":[[16.5,26]],"id":52385911},{"atb":[[28,20]],"id":52385886},{"atb":[[40,18.38]],"id":52385919},{"atl":[[95,0]],"id":52385919},{"atb":[[28,22]],"id":52385921},{"atl":[[50,12.24]],"id":52385884},{"atb":[[29,20]],"id":52385917},{"atl":[[85,9.14]],"id":52385917},{"atl":[[25,27.8]],"id":52385891},{"atb":[[17,18]],"id":52385893}],"con":true,"img":false}]}
{"op":"mcm","clk":"11550644362","pt":1719501255220,"mc":[{"id":"1.230178172","rc":[{"atb":[[14,7]],"id":52385910},{"atb":[[21,0]],"id":52385918},{"atl":[[36,0]],"id":52385883},{"atb":[[10,10],[13,23.4]],"id":52385892},{"atl":[[42,0]],"id":52385904},{"atb":[[32,0]],"id":52385900},{"atb":[[15.5,0]],"id":52385911},{"atb":[[26,0]],"id":52385886},{"atb":[[38,5]],"id":52385919},{"atl":[[100,10.56]],"id":52385919},{"atb":[[26,0]],"id":52385921},{"atl":[[60,0]],"id":52385884},{"atb":[[27,0]],"id":52385917},{"atl":[[90,0]],"id":52385917},{"atb":[[16,8]],"id":52385893}],"con":true,"img":false}]}
{"op":"mcm","clk":"11550644371","pt":1719501255321,"mc":[{"id":"1.230178172","rc":[{"atl":[[26,0]],"id":52385891}],"con":true,"img":false}]}
{"op":"mcm","clk":"11550644383","pt":1719501255528,"mc":[{"id":"1.230178172","rc":[{"atb":[[40,15.38]],"id":52385920}],"con":true,"img":false}]}
{"op":"mcm","clk":"11550644391","pt":1719501255734,"mc":[{"id":"1.230178172","rc":[{"atb":[[36,0]],"id":52385920}],"con":true,"img":false}]}
{"op":"mcm","clk":"11550644396","pt":1719501255836,"mc":[{"id":"1.230178172","rc":[{"atl":[[95,0]],"id":52385920},{"atb":[[13,0]],"id":52385892}],"con":true,"img":false}]}
{"op":"mcm","clk":"11550644403","pt":1719501255940,"mc":[{"id":"1.230178172","rc":[{"atl":[[100,6.06]],"id":52385920}],"con":true,"img":false}]}
{"op":"mcm","clk":"11550644409","pt":1719501256041,"mc":[{"id":"1.230178172","rc":[{"atb":[[12,15]],"id":52385892}],"con":true,"img":false}]}
{"op":"mcm","clk":"11550644454","pt":1719501256917,"mc":[{"id":"1.230178172","rc":[{"atb":[[8,0],[11.5,2.5],[9.8,5],[8.8,0]],"id":52385912},{"atb":[[16,5],[18,8.5],[13.5,0],[15.5,0]],"id":52385906},{"atb":[[19,11],[22,5.5]],"id":52385918},{"atb":[[16,0],[18,0],[25,5],[29,2.5]],"id":52385920},{"atl":[[34,0],[42,0],[22,2.5],[26,5]],"id":52385889},{"atb":[[17.5,5],[19.5,2.5],[10.5,0],[12.5,0]],"id":52385914},{"atl":[[65,2.69],[40,2.5]],"id":52385885},{"atl":[[32,0],[36,5],[40,0],[29,2.5]],"id":52385892},{"atb":[[17,0],[19,0],[25,5],[29,2.5]],"id":52385900},{"atb":[[11,0],[13,0],[14,5],[16,2.5]],"id":52385913},{"atb":[[32,2.5],[20,0],[24,5],[27,5]],"id":52385907},{"atb":[[19,10],[22,2.5],[15.5,0]],"id":52385886},{"atb":[[17,0],[22,5],[26,2.5],[15,0]],"id":52385919},{"atb":[[22,5],[26,2.5],[13.5,0],[15.5,0]],"id":52385921},{"atl":[[40,0],[48,2.13],[26,2.5],[30,5]],"id":52385882},{"atb":[[23,5],[13,0],[27,2.5],[15,0]],"id":52385917},{"atl":[[32,2.5],[36,0],[40,5],[44,0]],"id":52385891},{"atb":[[11,5],[13,2.5],[9.6,0],[8.8,0]],"id":52385893},{"atb":[[16,5],[17,0],[18,2.5],[15,0]],"id":52385899}],"con":true,"img":false}]}
{"op":"mcm","clk":"11550644461","pt":1719501257021,"mc":[{"id":"1.230178172","rc":[{"atb":[[11.5,0],[13.5,0]],"id":52385918}],"con":true,"img":false}]}
{"op":"mcm","clk":"11550644467","pt":1719501257123,"mc":[{"id":"1.230178172","rc":[{"atl":[[38,16.22]],"id":52385885},{"atl":[[70,2.5],[75,0],[90,5],[95,0]],"id":52385886}],"con":true,"img":false}]}
{"op":"mcm","clk":"11550644472","pt":1719501257227,"mc":[{"id":"1.230178172","rc":[{"atb":[[19,5]],"id":52385886}],"con":true,"img":false}]}
{"op":"mcm","clk":"11550644478","pt":1719501257329,"mc":[{"id":"1.230178172","rc":[{"atl":[[48,2.5]],"id":52385885}],"con":true,"img":false}]}
{"op":"mcm","clk":"11550644492","pt":1719501257555,"mc":[{"id":"1.230178172","rc":[{"atb":[[24,0]],"id":52385900}],"con":true,"img":false}]}
{"op":"mcm","clk":"11550644512","pt":1719501257813,"mc":[{"id":"1.230178172","rc":[{"atb":[[24,0]],"id":52385907}],"con":true,"img":false}]}
{"op":"mcm","clk":"11550644524","pt":1719501258019,"mc":[{"id":"1.230178172","rc":[{"atb":[[18,0]],"id":52385914}],"con":true,"img":false}]}
{"op":"mcm","clk":"11550644536","pt":1719501258225,"mc":[{"id":"1.230178172","rc":[{"atb":[[24,0]],"id":52385917}],"con":true,"img":false}]}
{"op":"mcm","clk":"11550644548","pt":1719501258433,"mc":[{"id":"1.230178172","rc":[{"atb":[[24,0]],"id":52385920}],"con":true,"img":false}]}
{"op":"mcm","clk":"11550644569","pt":1719501258744,"mc":[{"id":"1.230178172","rc":[{"atb":[[20,0]],"id":52385921}],"con":true,"img":false}]}
{"op":"mcm","clk":"11550644706","pt":1719501260865,"mc":[{"id":"1.230178172","rc":[{"atl":[[55,2.1]],"id":52385918}],"con":true,"img":false}]}
{"op":"mcm","clk":"11550644783","pt":1719501262354,"mc":[{"id":"1.230178172","rc":[{"atl":[[55,7.54]],"id":52385918}],"con":true,"img":false}]}
{"op":"mcm","clk":"11550644811","pt":1719501262792,"mc":[{"id":"1.230178172","rc":[{"atl":[[55,2.1]],"id":52385918}],"con":true,"img":false}]}
{"op":"mcm","clk":"11550644820","pt":1719501262846,"mc":[{"id":"1.230178172","rc":[{"atl":[[60,10.17]],"id":52385918}],"con":true,"img":false}]}
{"op":"mcm","clk":"11550644916","pt":1719501264243,"mc":[{"id":"1.230178172","rc":[{"atl":[[75,5],[80,0],[55,13.61],[60,0]],"id":52385910},{"atl":[[75,5],[80,0],[55,2.5],[60,0]],"id":52385913}],"con":true,"img":false}]}
{"op":"mcm","clk":"11550645121","pt":1719501267443,"mc":[{"id":"1.230178172","rc":[{"atb":[[24,27.9]],"id":52385910},{"atb":[[24,18.2]],"id":52385914},{"atl":[[19.5,25.6]],"id":52385890},{"atb":[[26,27]],"id":52385913},{"atb":[[36,16]],"id":52385907},{"atl":[[20,16.08]],"id":52385882},{"atl":[[38,14.9]],"id":52385897},{"atl":[[48,15.77]],"id":52385903}],"con":true,"img":false}]}
{"op":"mcm","clk":"11550645127","pt":1719501267545,"mc":[{"id":"1.230178172","rc":[{"atb":[[25,25]],"id":52385918},{"atb":[[32,16.5]],"id":52385917}],"con":true,"img":false}]}
{"op":"mcm","clk":"11550645135","pt":1719501267649,"mc":[{"id":"1.230178172","rc":[{"atb":[[22,0]],"id":52385910},{"atb":[[21,0]],"id":52385914},{"atl":[[22,0]],"id":52385890},{"atb":[[24,0]],"id":52385913},{"atb":[[30,0]],"id":52385907},{"atl":[[23,0]],"id":52385882},{"atl":[[42,0]],"id":52385897},{"atl":[[55,0]],"id":52385903}],"con":true,"img":false}]}
{"op":"mcm","clk":"11550645141","pt":1719501267753,"mc":[{"id":"1.230178172","rc":[{"atb":[[23,0]],"id":52385918},{"atb":[[29,0]],"id":52385917}],"con":true,"img":false}]}
{"op":"mcm","clk":"11550645208","pt":1719501268733,"mc":[{"id":"1.230178172","rc":[{"atl":[[100,0],[60,2.5]],"id":52385896},{"atl":[[85,0],[48,2.5]],"id":52385884},{"atl":[[65,0],[46,2.5],[48,0],[60,5]],"id":52385897},{"atl":[[70,0],[80,5],[60,2.5]],"id":52385903}],"con":true,"img":false}]}
{"op":"mcm","clk":"11550645216","pt":1719501268837,"mc":[{"id":"1.230178172","rc":[{"atl":[[46,12.24]],"id":52385884}],"con":true,"img":false}]}
{"op":"mcm","clk":"11550645222","pt":1719501268940,"mc":[{"id":"1.230178172","rc":[{"atb":[[24,18.1]],"id":52385914},{"trd":[[24,0.2]],"ltp":24.0,"tv":0.2,"id":52385914}],"con":true,"img":false}]}
{"op":"mcm","clk":"11550645227","pt":1719501269043,"mc":[{"id":"1.230178172","rc":[{"atl":[[50,0]],"id":52385884}],"con":true,"img":false}]}
{"op":"mcm","clk":"11550645250","pt":1719501269354,"mc":[{"id":"1.230178172","rc":[{"atl":[[140,2],[180,0]],"id":52385918},{"atl":[[200,2],[250,0]],"id":52385920},{"atl":[[150,0],[120,2]],"id":52385914},{"atl":[[50,7.04],[60,0]],"id":52385883},{"atl":[[65,4.69],[80,0]],"id":52385885},{"atl":[[100,2],[120,0]],"id":52385896},{"atl":[[36,5],[29,6.07]],"id":52385890},{"atl":[[42,2.44],[55,0]],"id":52385892},{"atl":[[75,2],[90,0]],"id":52385904},{"atl":[[190,2],[250,0]],"id":52385900},{"atl":[[70,2],[85,0]],"id":52385911},{"atl":[[90,2],[110,0]],"id":52385913},{"atl":[[170,2],[210,0]],"id":52385907},{"atl":[[150,0],[120,2]],"id":52385886},{"atl":[[140,7],[170,0]],"id":52385919},{"atl":[[38,2.7],[48,0]],"id":52385882},{"atl":[[85,2],[100,0]],"id":52385884},{"atl":[[190,2],[240,0]],"id":52385917},{"atl":[[75,2],[90,0]],"id":52385897},{"atl":[[65,0],[50,2.04]],"id":52385891},{"atl":[[140,0],[80,2]],"id":52385893},{"atl":[[130,0],[100,2]],"id":52385903},{"atl":[[80,7],[90,0]],"id":52385905}],"con":true,"img":false}]}
{"op":"mcm","clk":"11550645284","pt":1719501269876,"mc":[{"id":"1.230178172","rc":[{"atl":[[55,5.16]],"id":52385884}],"con":true,"img":false}]}
{"op":"mcm","clk":"11550645299","pt":1719501270085,"mc":[{"id":"1.230178172","rc":[{"atl":[[55,2.1]],"id":52385884}],"con":true,"img":false}]}
{"op":"mcm","clk":"11550645316","pt":1719501270289,"mc":[{"id":"1.230178172","rc":[{"atb":[[10,11.11],[6.2,0]],"id":52385910},{"atl":[[40,15.38]],"id":52385910},{"atb":[[20,3.87],[7.6,11],[3.65,0]],"id":52385912},{"atb":[[10,0],[8.8,12.82]],"id":52385906},{"atb":[[19,6],[10.5,10.53],[22,3],[11.5,5],[13.5,2.5]],"id":52385918},{"atl":[[140,0],[75,2]],"id":52385918},{"atb":[[40,0],[25,0],[13.5,8],[29,0]],"id":52385920},{"atl":[[200,0],[110,6.9]],"id":52385920},{"atb":[[7.2,16.13],[6.2,0],[11.5,34]],"id":52385889},{"atl":[[36,5],[38,0],[22,0],[26,0],[55,2],[29,2.5]],"id":52385889},{"atb":[[17.5,0],[19.5,0],[10,9.1],[24,0]],"id":52385914},{"atl":[[90,7],[120,0]],"id":52385914},{"atb":[[9,0],[12,5],[14,2.5],[9.4,8.74],[7.2,0],[17,14.74],[9.8,0]],"id":52385883},{"atl":[[70,2],[50,5]],"id":52385883},{"atl":[[40,0],[46,2.5],[95,2],[48,0],[60,5]],"id":52385885},{"atb":[[12,0],[15.5,6.9]],"id":52385896},{"atl":[[150,2],[80,0],[90,2.5],[100,0],[60,0]],"id":52385896},{"atb":[[12,27.74]],"id":52385890},{"atl":[[44,2.33],[29,2.5]],"id":52385890},{"atb":[[5.3,0],[6.8,13.4]],"id":52385892},{"atl":[[36,7.86],[42,0]],"id":52385892},{"atb":[[10,0],[8.6,13]],"id":52385904},{"atb":[[16,6.67],[12,0]],"id":52385898},{"atl":[[130,5],[70,8.7],[160,0],[90,0],[95,2.5],[220,2]],"id":52385898},{"atb":[[17.5,6.06],[12.5,0]],"id":52385900},{"atl":[[260,2],[190,0]],"id":52385900},{"atb":[[7.4,10],[2.16,0]],"id":52385911},{"atl":[[32,19.35],[70,0],[34,2.5],[42,5],[46,0],[60,2]],"id":52385911},{"atb":[[3.35,0],[9.8,11.36],[26,3]],"id":52385913},{"atl":[[75,7],[90,0]],"id":52385913},{"atb":[[32,0],[27,0],[6.6,0],[14.5,7.41]],"id":52385907},{"atl":[[130,2],[170,0]],"id":52385907},{"atb":[[11,10],[14,0]],"id":52385886},{"atl":[[160,2],[120,0]],"id":52385886},{"atb":[[40,3],[10.5,10],[22,0],[26,0]],"id":52385919},{"atl":[[140,5],[100,12.56]],"id":52385919},{"atb":[[10,7.7],[22,0],[26,0],[28,0]],"id":52385921},{"atb":[[6.4,0],[7.4,15.62],[7.8,0],[8.4,2.5],[15.5,16.08],[7.6,5],[7,0]],"id":52385882},{"atl":[[38,0],[20,0],[26,0],[55,2],[30,0]],"id":52385882},{"atb":[[10.5,0],[13,8.33]],"id":52385884},{"atl":[[140,2],[85,0],[48,0]],"id":52385884},{"atb":[[14,7.69]],"id":52385917},{"atl":[[190,0],[120,2]],"id":52385917},{"atb":[[10,0],[12.5,8.7]],"id":52385897},{"atl":[[75,0],[46,0],[95,2]],"id":52385897},{"atb":[[8,0],[6.6,17.86]],"id":52385891},{"atb":[[9.2,10],[4.6,0]],"id":52385893},{"atl":[[70,0],[80,0],[44,2.5],[50,0],[55,5],[60,2]],"id":52385893},{"atb":[[11,0],[13.5,8]],"id":52385903},{"atl":[[70,2.5],[80,0],[90,5],[60,0]],"id":52385903},{"atb":[[11.5,0],[12,5],[14,2.5],[9.8,0],[26,24]],"id":52385905},{"atl":[[80,5],[85,2]],"id":52385905},{"atb":[[10,11.11],[13,0]],"id":52385899}],"con":true,"img":false}]}
{"op":"mcm","clk":"11550645326","pt":1719501270339,"mc":[{"id":"1.230178172","rc":[{"atl":[[65,2.69]],"id":52385885},{"atl":[[160,2],[100,0]],"id":52385903}],"con":true,"img":false}]}
{"op":"mcm","clk":"11550645335","pt":1719501270448,"mc":[{"id":"1.230178172","rc":[{"atb":[[8,14],[10,0],[24,3.9]],"id":52385910},{"atl":[[90,2],[55,2.5],[120,0]],"id":52385910},{"atl":[[75,5],[80,0],[55,2.5],[60,10.17]],"id":52385912},{"atb":[[8.8,0]],"id":52385906},{"atl":[[75,5],[55,2.5]],"id":52385906},{"atb":[[10.5,0],[8.6,11],[25,0]],"id":52385918},{"atl":[[75,0],[95,2]],"id":52385918},{"atb":[[16,5],[18,2.5],[9.2,11.1],[13.5,0],[14,16.2]],"id":52385920},{"atl":[[160,2],[110,4.9]],"id":52385920},{"atb":[[7.2,0],[9,0],[11.5,0]],"id":52385889},{"atb":[[10,0],[23,17.3],[11.5,2.5],[9.8,5],[7.8,13.2]],"id":52385914},{"atb":[[8.2,11],[9.4,0]],"id":52385885},{"atb":[[11.5,9.52],[15.5,0]],"id":52385896},{"atb":[[11,8],[12,0]],"id":52385890},{"atb":[[6.8,0],[5.6,21.74]],"id":52385892},{"atl":[[36,5],[44,2.33]],"id":52385892},{"atb":[[6.4,13],[8.6,0]],"id":52385904},{"atl":[[75,0],[44,0],[50,2.5],[55,0],[110,2]],"id":52385904},{"atb":[[16,0],[10,10]],"id":52385898},{"atl":[[70,0]],"id":52385898},{"atb":[[17.5,0]],"id":52385900},{"atb":[[16.5,0],[7.4,0]],"id":52385911},{"atl":[[38,0]],"id":52385911},{"atb":[[17.5,20],[9.8,0]],"id":52385913},{"atb":[[22,5],[26,2.5],[14.5,0]],"id":52385907},{"atb":[[16,5],[18,2.5]],"id":52385919},{"atb":[[8,10.4],[10,0],[10.5,9.4],[12.5,5],[14.5,2.5]],"id":52385921},{"atb":[[10,0],[15.5,0]],"id":52385882},{"atl":[[36,2.5],[21,3.51],[44,5]],"id":52385882},{"atb":[[9,10],[13,0]],"id":52385884},{"atl":[[85,5]],"id":52385884},{"atb":[[14,0]],"id":52385917},{"atb":[[12.5,0],[9.8,10]],"id":52385897},{"atl":[[80,5]],"id":52385897},{"atb":[[9.2,0]],"id":52385893},{"atb":[[13.5,0]],"id":52385903},{"atb":[[10,0],[6.8,12]],"id":52385905},{"atl":[[85,0]],"id":52385905}],"con":true,"img":false}]}
{"op":"mcm","clk":"11550645346","pt":1719501270550,"mc":[{"id":"1.230178172","rc":[{"atl":[[75,7],[90,0],[55,13.61]],"id":52385912},{"atb":[[9.4,11.9]],"id":52385906},{"atl":[[150,0],[80,0],[55,13.61],[110,2],[60,10.17]],"id":52385906},{"atb":[[24,18]],"id":52385918},{"atb":[[9.2,0],[10.5,10.53]],"id":52385920},{"atb":[[9,75],[5.9,20.41]],"id":52385889},{"atb":[[11,68]],"id":52385890},{"atl":[[22,0]],"id":52385892},{"atb":[[6.4,0],[9.2,10]],"id":52385904},{"atb":[[10,0],[12.5,8.7]],"id":52385898},{"atl":[[75,8.11]],"id":52385898},{"atb":[[13,8.33]],"id":52385900},{"atb":[[16,44],[6,15]],"id":52385911},{"atb":[[8,10]],"id":52385913},{"atb":[[11.5,9.52]],"id":52385907},{"atb":[[15.5,11]],"id":52385882},{"atb":[[9,0],[10.5,10]],"id":52385884},{"atb":[[32,0],[10.5,10]],"id":52385917},{"atb":[[7.4,13]],"id":52385893},{"atb":[[11,10]],"id":52385903},{"atb":[[10,11],[6.8,0]],"id":52385905},{"atl":[[130,2]],"id":52385905}],"con":true,"img":false}]}
{"op":"mcm","clk":"11550645357","pt":1719501270655,"mc":[{"id":"1.230178172","rc":[{"atl":[[40,0]],"id":52385910},{"atl":[[23,27.27]],"id":52385892},{"atl":[[46,0]],"id":52385884},{"atb":[[30,11.5]],"id":52385917}],"con":true,"img":false}]}
{"op":"mcm","clk":"11550645366","pt":1719501270759,"mc":[{"id":"1.230178172","rc":[{"atl":[[48,12.77]],"id":52385910},{"atl":[[60,0]],"id":52385912},{"atl":[[60,0]],"id":52385906},{"atb":[[24,0]],"id":52385918},{"atl":[[23,0]],"id":52385892},{"atb":[[15.5,0]],"id":52385882},{"atl":[[48,12.24]],"id":52385884}],"con":true,"img":false}]}
{"op":"mcm","clk":"11550645376","pt":1719501270864,"mc":[{"id":"1.230178172","rc":[{"atb":[[21,11]],"id":52385918},{"atl":[[30,15]],"id":52385892},{"atb":[[10,12.02]],"id":52385882},{"atl":[[48,0]],"id":52385884}],"con":true,"img":false}]}
{"op":"mcm","clk":"11550645383","pt":1719501270967,"mc":[{"id":"1.230178172","rc":[{"atb":[[30,12.4]],"id":52385896},{"atl":[[50,12.24]],"id":52385884}],"con":true,"img":false}]}
{"op":"mcm","clk":"11550645392","pt":1719501271070,"mc":[{"id":"1.230178172","rc":[{"atl":[[75,0]],"id":52385898},{"atb":[[30,0]],"id":52385917}],"con":true,"img":false}]}
{"op":"mcm","clk":"11550645399","pt":1719501271174,"mc":[{"id":"1.230178172","rc":[{"atb":[[29,0]],"id":52385896},{"atl":[[85,7.14]],"id":52385898},{"atb":[[29,16.5]],"id":52385917}],"con":true,"img":false}]}
{"op":"mcm","clk":"11550645414","pt":1719501271329,"mc":[{"id":"1.230178172","rc":[{"atb":[[28,3.75]],"id":52385896},{"atl":[[85,0]],"id":52385898}],"con":true,"img":false}]}
{"op":"mcm","clk":"11550645428","pt":1719501271431,"mc":[{"id":"1.230178172","rc":[{"atl":[[90,6.74]],"id":52385898}],"con":true,"img":false}]}
{"op":"mcm","clk":"11550645481","pt":1719501272055,"mc":[{"id":"1.230178172","rc":[{"atb":[[28,0]],"id":52385896}],"con":true,"img":false}]}
{"op":"mcm","clk":"11550645506","pt":1719501272472,"mc":[{"id":"1.230178172","rc":[{"atb":[[8,0],[6.2,10],[24,21.7]],"id":52385910},{"atl":[[75,7],[90,0],[48,0]],"id":52385910},{"atb":[[20,23.61],[7.6,0]],"id":52385912},{"atb":[[8.6,0]],"id":52385918},{"atl":[[260,2],[70,0],[90,0],[95,0]],"id":52385918},{"atb":[[10.5,0]],"id":52385920},{"atl":[[140,2.5],[150,0],[160,0],[320,2],[110,2.4]],"id":52385920},{"atb":[[9,0]],"id":52385889},{"atl":[[38,2.7],[55,0]],"id":52385889},{"atb":[[7.8,0]],"id":52385914},{"atl":[[170,2],[90,5]],"id":52385914},{"atb":[[17,0],[12,0],[14,0],[9.4,0]],"id":52385883},{"atb":[[8.2,0],[21,0],[7,11]],"id":52385885},{"atl":[[32,19.35]],"id":52385885},{"atb":[[30,0]],"id":52385896},{"atb":[[6.2,0],[5.4,22.73]],"id":52385890},{"atb":[[5.6,0],[4.6,27.78]],"id":52385892},{"atl":[[38,2.7],[44,0]],"id":52385892},{"atl":[[70,2],[42,2.5],[110,0]],"id":52385904},{"atb":[[13,0]],"id":52385900},{"atl":[[260,0],[130,2.5],[140,0],[320,2],[170,5],[100,0]],"id":52385900},{"atb":[[6,2]],"id":52385911},{"atb":[[8,0]],"id":52385913},{"atb":[[11.5,0]],"id":52385907},{"atl":[[130,0]],"id":52385907},{"atb":[[3.95,33.9],[11,0]],"id":52385886},{"atl":[[70,0],[85,2.5],[90,0],[110,5]],"id":52385886},{"atb":[[10.5,0],[42,14.63]],"id":52385919},{"atl":[[100,10.56]],"id":52385919},{"atb":[[8,0]],"id":52385921},{"atl":[[170,0],[230,2]],"id":52385921},{"atb":[[10,0],[7.4,0]],"id":52385882},{"atb":[[10.5,0]],"id":52385884},{"atl":[[140,0],[110,2]],"id":52385884},{"atb":[[10.5,0]],"id":52385917},{"atl":[[130,2.5],[170,5],[95,0],[120,0]],"id":52385917},{"atl":[[80,7],[95,0]],"id":52385897},{"atb":[[7.4,0]],"id":52385893},{"atl":[[32,3],[44,0],[55,0],[60,2.5]],"id":52385893},{"atb":[[10,0],[26,4]],"id":52385905},{"atb":[[10,0],[13,8.33]],"id":52385899}],"con":true,"img":false}]}
{"op":"mcm","clk":"11550645515","pt":1719501272525,"mc":[{"id":"1.230178172","rc":[{"atl":[[70,8.7]],"id":52385910},{"atb":[[5.5,22.22]],"id":52385912},{"atl":[[140,5],[100,2.5]],"id":52385918},{"atl":[[180,5]],"id":52385920},{"atb":[[9,15]],"id":52385889},{"atb":[[9,5],[7.4,10.37],[9.8,2.5]],"id":52385883},{"atb":[[16,27.68]],"id":52385885},{"atl":[[32,0],[38,0]],"id":52385885},{"atb":[[29,10]],"id":52385896},{"atb":[[4.1,32.26]],"id":52385900},{"atb":[[3.8,35.71]],"id":52385911},{"atb":[[8,10]],"id":52385913},{"atb":[[4.7,27.03]],"id":52385907},{"atl":[[190,2]],"id":52385907},{"atb":[[6.4,10],[7.8,12.02]],"id":52385882},{"atl":[[230,2]],"id":52385917},{"atl":[[100,2],[55,11.11]],"id":52385893},{"atb":[[20,24],[10,9]],"id":52385905}],"con":true,"img":false}]}
{"op":"mcm","clk":"11550645520","pt":1719501272627,"mc":[{"id":"1.230178172","rc":[{"atl":[[30,20.69]],"id":52385885},{"atb":[[7.2,8.59],[3.95,0]],"id":52385886},{"atl":[[190,2]],"id":52385919},{"atb":[[10,8.62]],"id":52385884}],"con":true,"img":false}]}
{"op":"mcm","clk":"11550645533","pt":1719501272834,"mc":[{"id":"1.230178172","rc":[{"atl":[[30,0]],"id":52385885}],"con":true,"img":false}]}
{"op":"mcm","clk":"11550645541","pt":1719501272993,"mc":[{"id":"1.230178172","rc":[{"atl":[[38,16.22]],"id":52385885},{"atl":[[24,26.09]],"id":52385891}],"con":true,"img":false}]}
{"op":"mcm","clk":"11550645555","pt":1719501273149,"mc":[{"id":"1.230178172","rc":[{"atl":[[25,2.8]],"id":52385891}],"con":true,"img":false}]}
{"op":"mcm","clk":"11550645564","pt":1719501273251,"mc":[{"id":"1.230178172","rc":[{"atb":[[9,11]],"id":52385882}],"con":true,"img":false}]}
{"op":"mcm","clk":"11550645724","pt":1719501275478,"mc":[{"id":"1.230178172","rc":[{"atl":[[75,5],[95,2]],"id":52385913},{"atl":[[250,2]],"id":52385919},{"atl":[[290,2],[230,0]],"id":52385917}],"con":true,"img":false}]}
{"op":"mcm","clk":"11550645736","pt":1719501275529,"mc":[{"id":"1.230178172","rc":[{"atl":[[190,0]],"id":52385919}],"con":true,"img":false}]}
{"op":"mcm","clk":"11550645773","pt":1719501275944,"mc":[{"id":"1.230178172","rc":[{"atl":[[75,2],[95,0]],"id":52385885},{"atl":[[38,2.7],[44,0]],"id":52385890},{"atl":[[170,2],[220,0]],"id":52385898},{"atb":[[7.6,15.15],[6.6,0]],"id":52385891},{"atl":[[160,0],[120,2]],"id":52385903}],"con":true,"img":false}]}
{"op":"mcm","clk":"11550645792","pt":1719501276149,"mc":[{"id":"1.230178172","rc":[{"atl":[[95,2],[110,0]],"id":52385906},{"atl":[[95,2]],"id":52385905}],"con":true,"img":false}]}
{"op":"mcm","clk":"11550645800","pt":1719501276256,"mc":[{"id":"1.230178172","rc":[{"atl":[[130,0]],"id":52385905}],"con":true,"img":false}]}
{"op":"mcm","clk":"11550645900","pt":1719501277594,"mc":[{"id":"1.230178172","rc":[{"atl":[[75,5],[95,2]],"id":52385910},{"atl":[[75,5],[80,2]],"id":52385912},{"atl":[[38,0],[46,2.22]],"id":52385892},{"atl":[[70,0],[90,2]],"id":52385904},{"atb":[[4.1,0],[3.35,42.55]],"id":52385900},{"atb":[[3.85,35.09],[4.7,0]],"id":52385907},{"atl":[[90,0],[190,0],[110,2.5],[120,0],[250,2]],"id":52385907},{"atl":[[42,2.44],[55,0]],"id":52385882}],"con":true,"img":false}]}
{"op":"mcm","clk":"11550645921","pt":1719501277901,"mc":[{"id":"1.230178172","rc":[{"atb":[[20,23.51]],"id":52385912},{"trd":[[20,0.2]],"ltp":20.0,"tv":0.2,"id":52385912}],"con":true,"img":false}]}
{"op":"mcm","clk":"11550645940","pt":1719501278110,"mc":[{"id":"1.230178172","rc":[{"atb":[[6.2,0],[8.2,12]],"id":52385910},{"atb":[[8.6,9.84],[7,0]],"id":52385885},{"atb":[[6.4,15.6],[5.4,0]],"id":52385890},{"atb":[[4.6,0],[6.2,13.4]],"id":52385892}],"con":true,"img":false}]}
{"op":"mcm","clk":"11550646044","pt":1719501279196,"mc":[{"id":"1.230178172","rc":[{"atb":[[18.5,0],[19,8.69],[21,0],[22,2.5]],"id":52385898},{"atl":[[140,0],[150,2.5],[190,5],[100,2]],"id":52385919}],"con":true,"img":false}]}
{"op":"mcm","clk":"11550646071","pt":1719501279606,"mc":[{"id":"1.230178172","rc":[{"atb":[[26,27]],"id":52385913}],"con":true,"img":false}]}
{"op":"mcm","clk":"11550646078","pt":1719501279706,"mc":[{"id":"1.230178172","rc":[{"atb":[[23,18]],"id":52385918}],"con":true,"img":false}]}
{"op":"mcm","clk":"11550646082","pt":1719501279809,"mc":[{"id":"1.230178172","rc":[{"atb":[[17.5,0]],"id":52385913}],"con":true,"img":false}]}
{"op":"mcm","clk":"11550646090","pt":1719501279914,"mc":[{"id":"1.230178172","rc":[{"atb":[[21,0]],"id":52385918}],"con":true,"img":false}]}
{"op":"mcm","clk":"11550646098","pt":1719501279970,"mc":[{"id":"1.230178172","rc":[{"atb":[[30,16.5]],"id":52385917}],"con":true,"img":false}]}
{"op":"mcm","clk":"11550646110","pt":1719501280174,"mc":[{"id":"1.230178172","rc":[{"atb":[[29,0]],"id":52385917}],"con":true,"img":false}]}
{"op":"mcm","clk":"11550646153","pt":1719501280588,"mc":[{"id":"1.230178172","rc":[{"atl":[[100,8.06]],"id":52385919}],"con":true,"img":false}]}
{"op":"mcm","clk":"11550646210","pt":1719501281410,"mc":[{"id":"1.230178172","rc":[{"atl":[[100,2]],"id":52385919}],"con":true,"img":false}]}
{"op":"mcm","clk":"11550646220","pt":1719501281512,"mc":[{"id":"1.230178172","rc":[{"atl":[[110,5.5]],"id":52385919}],"con":true,"img":false}]}
{"op":"mcm","clk":"11550646244","pt":1719501281979,"mc":[{"id":"1.230178172","rc":[{"atb":[[24,17.8]],"id":52385910},{"atb":[[24,22]],"id":52385906},{"atb":[[22,0]],"id":52385918},{"atl":[[55,0]],"id":52385918},{"atb":[[38,0]],"id":52385920},{"atl":[[110,0]],"id":52385920},{"atl":[[34,0]],"id":52385883},{"atl":[[65,0]],"id":52385885},{"atb":[[8.8,2.5]],"id":52385890},{"atl":[[20,0]],"id":52385890},{"atb":[[9,0]],"id":52385892},{"atl":[[40,0]],"id":52385904},{"atb":[[34,0]],"id":52385900},{"atl":[[85,7.14]],"id":52385900},{"atb":[[26,24]],"id":52385913},{"atb":[[34,0]],"id":52385907},{"atl":[[85,0]],"id":52385907},{"atb":[[27,0]],"id":52385886},{"atb":[[40,0]],"id":52385919},{"atl":[[100,0]],"id":52385919},{"atb":[[27,0]],"id":52385921},{"atb":[[7.2,0]],"id":52385882},{"atl":[[55,0]],"id":52385884},{"atb":[[28,0]],"id":52385917},{"atl":[[25,0]],"id":52385891},{"atb":[[16.5,0]],"id":52385893},{"atl":[[32,0]],"id":52385893},{"atb":[[18.5,0]],"id":52385903}],"con":true,"img":false}]}
{"op":"mcm","clk":"11550646253","pt":1719501282081,"mc":[{"id":"1.230178172","rc":[{"atb":[[24,0]],"id":52385910},{"atb":[[24,0]],"id":52385906},{"atb":[[23,0]],"id":52385918},{"atl":[[60,0]],"id":52385918},{"atl":[[100,0]],"id":52385920},{"atl":[[38,0]],"id":52385904},{"atb":[[36,0]],"id":52385900},{"atl":[[85,0]],"id":52385900},{"atb":[[26,0]],"id":52385913},{"atl":[[80,0]],"id":52385907},{"atb":[[28,0]],"id":52385886},{"atb":[[42,0]],"id":52385919},{"atb":[[17,0]],"id":52385893}],"con":true,"img":false}]}
{"op":"mcm","clk":"11550646262","pt":1719501282187,"mc":[{"id":"1.230178172","rc":[{"atb":[[23,15],[13.5,5.89]],"id":52385910},{"atl":[[55,5.5]],"id":52385910},{"atb":[[16.5,3.2],[10.5,10.53],[23,20],[9.4,0]],"id":52385906},{"atb":[[22,10],[24,3]],"id":52385918},{"atl":[[130,4.65]],"id":52385918},{"atl":[[170,3.55]],"id":52385920},{"atb":[[7.4,6.5]],"id":52385889},{"atl":[[42,4.93]],"id":52385883},{"atb":[[11.5,4.5]],"id":52385890},{"atl":[[24,3]],"id":52385890},{"atb":[[12.5,4.4]],"id":52385892},{"atl":[[36,2.1],[40,12.6]],"id":52385904},{"atl":[[85,2.07]],"id":52385898},{"atb":[[34,10],[38,2.7]],"id":52385900},{"atl":[[160,3.77],[120,2]],"id":52385900},{"atb":[[16.5,3.8],[25,15]],"id":52385913},{"atb":[[28,2]],"id":52385907},{"atl":[[85,7.14],[100,2]],"id":52385907},{"atb":[[27,15],[29,2.93]],"id":52385886},{"atb":[[40,15],[44,3.24]],"id":52385919},{"atl":[[150,4.5],[110,0]],"id":52385919},{"atb":[[9,16.67]],"id":52385882},{"atl":[[48,2]],"id":52385884},{"atb":[[32,3]],"id":52385917},{"atl":[[29,3]],"id":52385891},{"atb":[[16.5,10],[17.5,4.49]],"id":52385893},{"atl":[[50,2.92]],"id":52385893}],"con":true,"img":false}]}
{"op":"mcm","clk":"11550646271","pt":1719501282290,"mc":[{"id":"1.230178172","rc":[{"atb":[[12.5,34.4]],"id":52385892},{"atl":[[140,4.32]],"id":52385919},{"atl":[[46,12.24]],"id":52385884}],"con":true,"img":false}]}
{"op":"mcm","clk":"11550646277","pt":1719501282394,"mc":[{"id":"1.230178172","rc":[{"atb":[[11.5,19.5]],"id":52385890},{"atb":[[12,0]],"id":52385892},{"atl":[[50,0]],"id":52385884}],"con":true,"img":false}]}
{"op":"mcm","clk":"11550646286","pt":1719501282509,"mc":[{"id":"1.230178172","rc":[{"atb":[[23,0]],"id":52385910},{"atl":[[36,17.14]],"id":52385910},{"atb":[[11,8]],"id":52385890},{"atl":[[30,20.69]],"id":52385911},{"atb":[[25,0]],"id":52385913},{"atl":[[85,0]],"id":52385907},{"atb":[[9.2,12.02]],"id":52385882}],"con":true,"img":false}]}
{"op":"mcm","clk":"11550646291","pt":1719501282599,"mc":[{"id":"1.230178172","rc":[{"atb":[[21,25.78]],"id":52385910},{"atl":[[70,0]],"id":52385910},{"atb":[[26,17.1]],"id":52385920},{"atl":[[32,0]],"id":52385911},{"atb":[[24,24]],"id":52385913},{"atl":[[140,5],[95,6.38],[100,4.5]],"id":52385907},{"atb":[[29,20]],"id":52385921},{"atb":[[7.8,0]],"id":52385882}],"con":true,"img":false}]}
{"op":"mcm","clk":"11550646298","pt":1719501282709,"mc":[{"id":"1.230178172","rc":[{"atb":[[25,19.3]],"id":52385918},{"atl":[[80,7.59]],"id":52385898},{"atl":[[110,0]],"id":52385907}],"con":true,"img":false}]}
{"op":"mcm","clk":"11550646306","pt":1719501282814,"mc":[{"id":"1.230178172","rc":[{"atb":[[22,0]],"id":52385918},{"atb":[[14,0]],"id":52385920},{"atl":[[28,22.22]],"id":52385892},{"atl":[[90,0]],"id":52385898},{"atb":[[24,0]],"id":52385913},{"atb":[[10.5,0]],"id":52385921},{"atb":[[34,16]],"id":52385917}],"con":true,"img":false}]}
{"op":"mcm","clk":"11550646310","pt":1719501282910,"mc":[{"id":"1.230178172","rc":[{"atb":[[21,24]],"id":52385913}],"con":true,"img":false}]}
{"op":"mcm","clk":"11550646318","pt":1719501283014,"mc":[{"id":"1.230178172","rc":[{"atl":[[30,0]],"id":52385892},{"atb":[[30,0]],"id":52385917}],"con":true,"img":false}]}
{"op":"mcm","clk":"11550646332","pt":1719501283220,"mc":[{"id":"1.230178172","rc":[{"atb":[[11,0]],"id":52385890}],"con":true,"img":false}]}
