{"op":"mcm","clk":"11547086387","pt":1719432856307,"mc":[{"id":"1.230178173","marketDefinition":{"bspMarket":false,"turnInPlayEnabled":false,"persistenceEnabled":false,"marketBaseRate":5.0,"eventId":"33376048","eventTypeId":"4339","numberOfWinners":1,"bettingType":"ODDS","marketType":"FORECAST","marketTime":"2024-06-27T15:41:00.000Z","suspendTime":"2024-06-27T15:41:00.000Z","bspReconciled":false,"complete":true,"inPlay":false,"crossMatching":false,"runnersVoidable":false,"numberOfActiveRunners":30,"betDelay":0,"status":"OPEN","runners":[{"status":"ACTIVE","sortPriority":1,"id":52385882,"name":"1 - 2"},{"status":"ACTIVE","sortPriority":2,"id":52385883,"name":"1 - 3"},{"status":"ACTIVE","sortPriority":3,"id":52385884,"name":"1 - 4"},{"status":"ACTIVE","sortPriority":4,"id":52385885,"name":"1 - 5"},{"status":"ACTIVE","sortPriority":5,"id":52385886,"name":"1 - 6"},{"status":"ACTIVE","sortPriority":6,"id":52385889,"name":"2 - 1"},{"status":"ACTIVE","sortPriority":7,"id":52385890,"name":"2 - 3"},{"status":"ACTIVE","sortPriority":8,"id":52385891,"name":"2 - 4"},{"status":"ACTIVE","sortPriority":9,"id":52385892,"name":"2 - 5"},{"status":"ACTIVE","sortPriority":10,"id":52385893,"name":"2 - 6"},{"status":"ACTIVE","sortPriority":11,"id":52385896,"name":"3 - 1"},{"status":"ACTIVE","sortPriority":12,"id":52385897,"name":"3 - 2"},{"status":"ACTIVE","sortPriority":13,"id":52385898,"name":"3 - 4"},{"status":"ACTIVE","sortPriority":14,"id":52385899,"name":"3 - 5"},{"status":"ACTIVE","sortPriority":15,"id":52385900,"name":"3 - 6"},{"status":"ACTIVE","sortPriority":16,"id":52385903,"name":"4 - 1"},{"status":"ACTIVE","sortPriority":17,"id":52385904,"name":"4 - 2"},{"status":"ACTIVE","sortPriority":18,"id":52385905,"name":"4 - 3"},{"status":"ACTIVE","sortPriority":19,"id":52385906,"name":"4 - 5"},{"status":"ACTIVE","sortPriority":20,"id":52385907,"name":"4 - 6"},{"status":"ACTIVE","sortPriority":21,"id":52385910,"name":"5 - 1"},{"status":"ACTIVE","sortPriority":22,"id":52385911,"name":"5 - 2"},{"status":"ACTIVE","sortPriority":23,"id":52385912,"name":"5 - 3"},{"status":"ACTIVE","sortPriority":24,"id":52385913,"name":"5 - 4"},{"status":"ACTIVE","sortPriority":25,"id":52385914,"name":"5 - 6"},{"status":"ACTIVE","sortPriority":26,"id":52385917,"name":"6 - 1"},{"status":"ACTIVE","sortPriority":27,"id":52385918,"name":"6 - 2"},{"status":"ACTIVE","sortPriority":28,"id":52385919,"name":"6 - 3"},{"status":"ACTIVE","sortPriority":29,"id":52385920,"name":"6 - 4"},{"status":"ACTIVE","sortPriority":30,"id":52385921,"name":"6 - 5"}],"regulators":["MR_INT"],"venue":"Perry Barr","countryCode":"GB","discountAllowed":false,"timezone":"Europe/London","openDate":"2024-06-27T13:29:00.000Z","version":5994794124,"name":"Forecast","eventName":"Perry Barr (F/C) 27th Jun"},"rc":[],"con":true,"img":false}]}
{"op":"mcm","clk":"11547086550","pt":1719432858318,"mc":[{"id":"1.230178173","marketDefinition":{"bspMarket":false,"turnInPlayEnabled":false,"persistenceEnabled":false,"marketBaseRate":5.0,"eventId":"33376048","eventTypeId":"4339","numberOfWinners":1,"bettingType":"ODDS","marketType":"FORECAST","marketTime":"2024-06-27T15:41:00.000Z","suspendTime":"2024-06-27T15:41:00.000Z","bspReconciled":false,"complete":true,"inPlay":false,"crossMatching":false,"runnersVoidable":false,"numberOfActiveRunners":30,"betDelay":0,"status":"OPEN","runners":[{"status":"ACTIVE","sortPriority":1,"id":52385882,"name":"1 - 2"},{"status":"ACTIVE","sortPriority":2,"id":52385883,"name":"1 - 3"},{"status":"ACTIVE","sortPriority":3,"id":52385884,"name":"1 - 4"},{"status":"ACTIVE","sortPriority":4,"id":52385885,"name":"1 - 5"},{"status":"ACTIVE","sortPriority":5,"id":52385886,"name":"1 - 6"},{"status":"ACTIVE","sortPriority":6,"id":52385889,"name":"2 - 1"},{"status":"ACTIVE","sortPriority":7,"id":52385890,"name":"2 - 3"},{"status":"ACTIVE","sortPriority":8,"id":52385891,"name":"2 - 4"},{"status":"ACTIVE","sortPriority":9,"id":52385892,"name":"2 - 5"},{"status":"ACTIVE","sortPriority":10,"id":52385893,"name":"2 - 6"},{"status":"ACTIVE","sortPriority":11,"id":52385896,"name":"3 - 1"},{"status":"ACTIVE","sortPriority":12,"id":52385897,"name":"3 - 2"},{"status":"ACTIVE","sortPriority":13,"id":52385898,"name":"3 - 4"},{"status":"ACTIVE","sortPriority":14,"id":52385899,"name":"3 - 5"},{"status":"ACTIVE","sortPriority":15,"id":52385900,"name":"3 - 6"},{"status":"ACTIVE","sortPriority":16,"id":52385903,"name":"4 - 1"},{"status":"ACTIVE","sortPriority":17,"id":52385904,"name":"4 - 2"},{"status":"ACTIVE","sortPriority":18,"id":52385905,"name":"4 - 3"},{"status":"ACTIVE","sortPriority":19,"id":52385906,"name":"4 - 5"},{"status":"ACTIVE","sortPriority":20,"id":52385907,"name":"4 - 6"},{"status":"ACTIVE","sortPriority":21,"id":52385910,"name":"5 - 1"},{"status":"ACTIVE","sortPriority":22,"id":52385911,"name":"5 - 2"},{"status":"ACTIVE","sortPriority":23,"id":52385912,"name":"5 - 3"},{"status":"ACTIVE","sortPriority":24,"id":52385913,"name":"5 - 4"},{"status":"ACTIVE","sortPriority":25,"id":52385914,"name":"5 - 6"},{"status":"ACTIVE","sortPriority":26,"id":52385917,"name":"6 - 1"},{"status":"ACTIVE","sortPriority":27,"id":52385918,"name":"6 - 2"},{"status":"ACTIVE","sortPriority":28,"id":52385919,"name":"6 - 3"},{"status":"ACTIVE","sortPriority":29,"id":52385920,"name":"6 - 4"},{"status":"ACTIVE","sortPriority":30,"id":52385921,"name":"6 - 5"}],"regulators":["MR_INT"],"venue":"Perry Barr","countryCode":"GB","discountAllowed":true,"timezone":"Europe/London","openDate":"2024-06-27T13:29:00.000Z","version":5994794124,"name":"Forecast","eventName":"Perry Barr (F/C) 27th Jun"},"rc":[],"con":true,"img":false}]}
{"op":"mcm","clk":"11547344306","pt":1719439057195,"mc":[{"id":"1.230178173","rc":[{"atb":[[1.03,7.81]],"id":52385910},{"atb":[[1.03,7.81]],"id":52385912},{"atb":[[1.02,11.71]],"id":52385906},{"atb":[[1.03,7.81]],"id":52385918},{"atb":[[1.02,11.71]],"id":52385920},{"atb":[[1.01,23.42]],"id":52385889},{"atb":[[1.01,23.42]],"id":52385914},{"atb":[[1.03,7.81]],"id":52385883},{"atb":[[1.01,23.42]],"id":52385885},{"atb":[[1.03,7.81]],"id":52385896},{"atb":[[1.02,11.71]],"id":52385890},{"atb":[[1.01,23.42]],"id":52385892},{"atb":[[1.03,7.81]],"id":52385904},{"atb":[[1.03,7.81]],"id":52385898},{"atb":[[1.03,7.81]],"id":52385900},{"atb":[[1.02,11.71]],"id":52385911},{"atb":[[1.03,7.81]],"id":52385913},{"atb":[[1.02,11.71]],"id":52385907},{"atb":[[1.03,7.81]],"id":52385886},{"atb":[[1.01,23.42]],"id":52385919},{"atb":[[1.01,23.42]],"id":52385921},{"atb":[[1.01,23.42]],"id":52385882},{"atb":[[1.02,11.71]],"id":52385884},{"atb":[[1.01,23.42]],"id":52385917},{"atb":[[1.01,23.42]],"id":52385897},{"atb":[[1.02,11.71]],"id":52385891},{"atb":[[1.01,23.42]],"id":52385893},{"atb":[[1.01,23.42]],"id":52385903},{"atb":[[1.03,7.81]],"id":52385905},{"atb":[[1.02,11.71]],"id":52385899}],"con":true,"img":false}]}
{"op":"mcm","clk":"11547371016","pt":1719439682592,"mc":[{"id":"1.230178173","marketDefinition":{"bspMarket":false,"turnInPlayEnabled":false,"persistenceEnabled":false,"marketBaseRate":5.0,"eventId":"33376048","eventTypeId":"4339","numberOfWinners":1,"bettingType":"ODDS","marketType":"FORECAST","marketTime":"2024-06-27T15:41:00.000Z","suspendTime":"2024-06-27T15:41:00.000Z","bspReconciled":false,"complete":true,"inPlay":false,"crossMatching":false,"runnersVoidable":false,"numberOfActiveRunners":30,"betDelay":0,"status":"OPEN","runners":[{"status":"ACTIVE","sortPriority":1,"id":52385882,"name":"1 - 2"},{"status":"ACTIVE","sortPriority":2,"id":52385883,"name":"1 - 3"},{"status":"ACTIVE","sortPriority":3,"id":52385884,"name":"1 - 4"},{"status":"ACTIVE","sortPriority":4,"id":52385885,"name":"1 - 5"},{"status":"ACTIVE","sortPriority":5,"id":52385886,"name":"1 - 6"},{"status":"ACTIVE","sortPriority":6,"id":52385889,"name":"2 - 1"},{"status":"ACTIVE","sortPriority":7,"id":52385890,"name":"2 - 3"},{"status":"ACTIVE","sortPriority":8,"id":52385891,"name":"2 - 4"},{"status":"ACTIVE","sortPriority":9,"id":52385892,"name":"2 - 5"},{"status":"ACTIVE","sortPriority":10,"id":52385893,"name":"2 - 6"},{"status":"ACTIVE","sortPriority":11,"id":52385896,"name":"3 - 1"},{"status":"ACTIVE","sortPriority":12,"id":52385897,"name":"3 - 2"},{"status":"ACTIVE","sortPriority":13,"id":52385898,"name":"3 - 4"},{"status":"ACTIVE","sortPriority":14,"id":52385899,"name":"3 - 5"},{"status":"ACTIVE","sortPriority":15,"id":52385900,"name":"3 - 6"},{"status":"ACTIVE","sortPriority":16,"id":52385903,"name":"4 - 1"},{"status":"ACTIVE","sortPriority":17,"id":52385904,"name":"4 - 2"},{"status":"ACTIVE","sortPriority":18,"id":52385905,"name":"4 - 3"},{"status":"ACTIVE","sortPriority":19,"id":52385906,"name":"4 - 5"},{"status":"ACTIVE","sortPriority":20,"id":52385907,"name":"4 - 6"},{"status":"ACTIVE","sortPriority":21,"id":52385910,"name":"5 - 1"},{"status":"ACTIVE","sortPriority":22,"id":52385911,"name":"5 - 2"},{"status":"ACTIVE","sortPriority":23,"id":52385912,"name":"5 - 3"},{"status":"ACTIVE","sortPriority":24,"id":52385913,"name":"5 - 4"},{"status":"ACTIVE","sortPriority":25,"id":52385914,"name":"5 - 6"},{"status":"ACTIVE","sortPriority":26,"id":52385917,"name":"6 - 1"},{"status":"ACTIVE","sortPriority":27,"id":52385918,"name":"6 - 2"},{"status":"ACTIVE","sortPriority":28,"id":52385919,"name":"6 - 3"},{"status":"ACTIVE","sortPriority":29,"id":52385920,"name":"6 - 4"},{"status":"ACTIVE","sortPriority":30,"id":52385921,"name":"6 - 5"}],"regulators":["MR_INT"],"venue":"Perry Barr","countryCode":"GB","discountAllowed":true,"timezone":"Europe/London","openDate":"2024-06-27T13:29:00.000Z","version":5994794124,"name":"Forecast","eventName":"Perry Barr (F/C) 27th Jun"},"rc":[{"atb":[[1.03,7.8]],"id":52385910},{"atb":[[1.03,7.8]],"id":52385912},{"atb":[[1.02,11.7]],"id":52385906},{"atb":[[1.03,7.8]],"id":52385918},{"atb":[[1.02,11.7]],"id":52385920},{"atb":[[1.01,23.41]],"id":52385889},{"atb":[[1.01,23.41]],"id":52385914},{"atb":[[1.03,7.8]],"id":52385883},{"atb":[[1.01,23.41]],"id":52385885},{"atb":[[1.03,7.8]],"id":52385896},{"atb":[[1.02,11.7]],"id":52385890},{"atb":[[1.01,23.41]],"id":52385892},{"atb":[[1.03,7.8]],"id":52385904},{"atb":[[1.03,7.8]],"id":52385898},{"atb":[[1.03,7.8]],"id":52385900},{"atb":[[1.02,11.7]],"id":52385911},{"atb":[[1.03,7.8]],"id":52385913},{"atb":[[1.02,11.7]],"id":52385907},{"atb":[[1.03,7.8]],"id":52385886},{"atb":[[1.01,23.41]],"id":52385919},{"atb":[[1.01,23.41]],"id":52385921},{"atb":[[1.01,23.41]],"id":52385882},{"atb":[[1.02,11.7]],"id":52385884},{"atb":[[1.01,23.41]],"id":52385917},{"atb":[[1.01,23.41]],"id":52385897},{"atb":[[1.02,11.7]],"id":52385891},{"atb":[[1.01,23.41]],"id":52385893},{"atb":[[1.01,23.41]],"id":52385903},{"atb":[[1.03,7.8]],"id":52385905},{"atb":[[1.02,11.7]],"id":52385899}],"con":true,"img":true}]}
{"op":"mcm","clk":"11547659684","pt":1719445082619,"mc":[{"id":"1.230178173","marketDefinition":{"bspMarket":false,"turnInPlayEnabled":false,"persistenceEnabled":false,"marketBaseRate":5.0,"eventId":"33376048","eventTypeId":"4339","numberOfWinners":1,"bettingType":"ODDS","marketType":"FORECAST","marketTime":"2024-06-27T15:41:00.000Z","suspendTime":"2024-06-27T15:41:00.000Z","bspReconciled":false,"complete":true,"inPlay":false,"crossMatching":false,"runnersVoidable":false,"numberOfActiveRunners":30,"betDelay":0,"status":"OPEN","runners":[{"status":"ACTIVE","sortPriority":1,"id":52385882,"name":"1 - 2"},{"status":"ACTIVE","sortPriority":2,"id":52385883,"name":"1 - 3"},{"status":"ACTIVE","sortPriority":3,"id":52385884,"name":"1 - 4"},{"status":"ACTIVE","sortPriority":4,"id":52385885,"name":"1 - 5"},{"status":"ACTIVE","sortPriority":5,"id":52385886,"name":"1 - 6"},{"status":"ACTIVE","sortPriority":6,"id":52385889,"name":"2 - 1"},{"status":"ACTIVE","sortPriority":7,"id":52385890,"name":"2 - 3"},{"status":"ACTIVE","sortPriority":8,"id":52385891,"name":"2 - 4"},{"status":"ACTIVE","sortPriority":9,"id":52385892,"name":"2 - 5"},{"status":"ACTIVE","sortPriority":10,"id":52385893,"name":"2 - 6"},{"status":"ACTIVE","sortPriority":11,"id":52385896,"name":"3 - 1"},{"status":"ACTIVE","sortPriority":12,"id":52385897,"name":"3 - 2"},{"status":"ACTIVE","sortPriority":13,"id":52385898,"name":"3 - 4"},{"status":"ACTIVE","sortPriority":14,"id":52385899,"name":"3 - 5"},{"status":"ACTIVE","sortPriority":15,"id":52385900,"name":"3 - 6"},{"status":"ACTIVE","sortPriority":16,"id":52385903,"name":"4 - 1"},{"status":"ACTIVE","sortPriority":17,"id":52385904,"name":"4 - 2"},{"status":"ACTIVE","sortPriority":18,"id":52385905,"name":"4 - 3"},{"status":"ACTIVE","sortPriority":19,"id":52385906,"name":"4 - 5"},{"status":"ACTIVE","sortPriority":20,"id":52385907,"name":"4 - 6"},{"status":"ACTIVE","sortPriority":21,"id":52385910,"name":"5 - 1"},{"status":"ACTIVE","sortPriority":22,"id":52385911,"name":"5 - 2"},{"status":"ACTIVE","sortPriority":23,"id":52385912,"name":"5 - 3"},{"status":"ACTIVE","sortPriority":24,"id":52385913,"name":"5 - 4"},{"status":"ACTIVE","sortPriority":25,"id":52385914,"name":"5 - 6"},{"status":"ACTIVE","sortPriority":26,"id":52385917,"name":"6 - 1"},{"status":"ACTIVE","sortPriority":27,"id":52385918,"name":"6 - 2"},{"status":"ACTIVE","sortPriority":28,"id":52385919,"name":"6 - 3"},{"status":"ACTIVE","sortPriority":29,"id":52385920,"name":"6 - 4"},{"status":"ACTIVE","sortPriority":30,"id":52385921,"name":"6 - 5"}],"regulators":["MR_INT"],"venue":"Perry Barr","countryCode":"GB","discountAllowed":true,"timezone":"Europe/London","openDate":"2024-06-27T13:29:00.000Z","version":5994794124,"name":"Forecast","eventName":"Perry Barr (F/C) 27th Jun"},"rc":[{"atb":[[1.03,7.81]],"id":52385910},{"atb":[[1.03,7.81]],"id":52385912},{"atb":[[1.02,11.71]],"id":52385906},{"atb":[[1.03,7.81]],"id":52385918},{"atb":[[1.02,11.71]],"id":52385920},{"atb":[[1.01,23.42]],"id":52385889},{"atb":[[1.01,23.42]],"id":52385914},{"atb":[[1.03,7.81]],"id":52385883},{"atb":[[1.01,23.42]],"id":52385885},{"atb":[[1.03,7.81]],"id":52385896},{"atb":[[1.02,11.71]],"id":52385890},{"atb":[[1.01,23.42]],"id":52385892},{"atb":[[1.03,7.81]],"id":52385904},{"atb":[[1.03,7.81]],"id":52385898},{"atb":[[1.03,7.81]],"id":52385900},{"atb":[[1.02,11.71]],"id":52385911},{"atb":[[1.03,7.81]],"id":52385913},{"atb":[[1.02,11.71]],"id":52385907},{"atb":[[1.03,7.81]],"id":52385886},{"atb":[[1.01,23.42]],"id":52385919},{"atb":[[1.01,23.42]],"id":52385921},{"atb":[[1.01,23.42]],"id":52385882},{"atb":[[1.02,11.71]],"id":52385884},{"atb":[[1.01,23.42]],"id":52385917},{"atb":[[1.01,23.42]],"id":52385897},{"atb":[[1.02,11.71]],"id":52385891},{"atb":[[1.01,23.42]],"id":52385893},{"atb":[[1.01,23.42]],"id":52385903},{"atb":[[1.03,7.81]],"id":52385905},{"atb":[[1.02,11.71]],"id":52385899}],"con":true,"img":true}]}
{"op":"mcm","clk":"11548031728","pt":1719450482634,"mc":[{"id":"1.230178173","marketDefinition":{"bspMarket":false,"turnInPlayEnabled":false,"persistenceEnabled":false,"marketBaseRate":5.0,"eventId":"33376048","eventTypeId":"4339","numberOfWinners":1,"bettingType":"ODDS","marketType":"FORECAST","marketTime":"2024-06-27T15:41:00.000Z","suspendTime":"2024-06-27T15:41:00.000Z","bspReconciled":false,"complete":true,"inPlay":false,"crossMatching":false,"runnersVoidable":false,"numberOfActiveRunners":30,"betDelay":0,"status":"OPEN","runners":[{"status":"ACTIVE","sortPriority":1,"id":52385882,"name":"1 - 2"},{"status":"ACTIVE","sortPriority":2,"id":52385883,"name":"1 - 3"},{"status":"ACTIVE","sortPriority":3,"id":52385884,"name":"1 - 4"},{"status":"ACTIVE","sortPriority":4,"id":52385885,"name":"1 - 5"},{"status":"ACTIVE","sortPriority":5,"id":52385886,"name":"1 - 6"},{"status":"ACTIVE","sortPriority":6,"id":52385889,"name":"2 - 1"},{"status":"ACTIVE","sortPriority":7,"id":52385890,"name":"2 - 3"},{"status":"ACTIVE","sortPriority":8,"id":52385891,"name":"2 - 4"},{"status":"ACTIVE","sortPriority":9,"id":52385892,"name":"2 - 5"},{"status":"ACTIVE","sortPriority":10,"id":52385893,"name":"2 - 6"},{"status":"ACTIVE","sortPriority":11,"id":52385896,"name":"3 - 1"},{"status":"ACTIVE","sortPriority":12,"id":52385897,"name":"3 - 2"},{"status":"ACTIVE","sortPriority":13,"id":52385898,"name":"3 - 4"},{"status":"ACTIVE","sortPriority":14,"id":52385899,"name":"3 - 5"},{"status":"ACTIVE","sortPriority":15,"id":52385900,"name":"3 - 6"},{"status":"ACTIVE","sortPriority":16,"id":52385903,"name":"4 - 1"},{"status":"ACTIVE","sortPriority":17,"id":52385904,"name":"4 - 2"},{"status":"ACTIVE","sortPriority":18,"id":52385905,"name":"4 - 3"},{"status":"ACTIVE","sortPriority":19,"id":52385906,"name":"4 - 5"},{"status":"ACTIVE","sortPriority":20,"id":52385907,"name":"4 - 6"},{"status":"ACTIVE","sortPriority":21,"id":52385910,"name":"5 - 1"},{"status":"ACTIVE","sortPriority":22,"id":52385911,"name":"5 - 2"},{"status":"ACTIVE","sortPriority":23,"id":52385912,"name":"5 - 3"},{"status":"ACTIVE","sortPriority":24,"id":52385913,"name":"5 - 4"},{"status":"ACTIVE","sortPriority":25,"id":52385914,"name":"5 - 6"},{"status":"ACTIVE","sortPriority":26,"id":52385917,"name":"6 - 1"},{"status":"ACTIVE","sortPriority":27,"id":52385918,"name":"6 - 2"},{"status":"ACTIVE","sortPriority":28,"id":52385919,"name":"6 - 3"},{"status":"ACTIVE","sortPriority":29,"id":52385920,"name":"6 - 4"},{"status":"ACTIVE","sortPriority":30,"id":52385921,"name":"6 - 5"}],"regulators":["MR_INT"],"venue":"Perry Barr","countryCode":"GB","discountAllowed":true,"timezone":"Europe/London","openDate":"2024-06-27T13:29:00.000Z","version":5994794124,"name":"Forecast","eventName":"Perry Barr (F/C) 27th Jun"},"rc":[{"atb":[[1.03,7.81]],"id":52385910},{"atb":[[1.03,7.81]],"id":52385912},{"atb":[[1.02,11.71]],"id":52385906},{"atb":[[1.03,7.81]],"id":52385918},{"atb":[[1.02,11.71]],"id":52385920},{"atb":[[1.01,23.42]],"id":52385889},{"atb":[[1.01,23.42]],"id":52385914},{"atb":[[1.03,7.81]],"id":52385883},{"atb":[[1.01,23.42]],"id":52385885},{"atb":[[1.03,7.81]],"id":52385896},{"atb":[[1.02,11.71]],"id":52385890},{"atb":[[1.01,23.42]],"id":52385892},{"atb":[[1.03,7.81]],"id":52385904},{"atb":[[1.03,7.81]],"id":52385898},{"atb":[[1.03,7.81]],"id":52385900},{"atb":[[1.02,11.71]],"id":52385911},{"atb":[[1.03,7.81]],"id":52385913},{"atb":[[1.02,11.71]],"id":52385907},{"atb":[[1.03,7.81]],"id":52385886},{"atb":[[1.01,23.42]],"id":52385919},{"atb":[[1.01,23.42]],"id":52385921},{"atb":[[1.01,23.42]],"id":52385882},{"atb":[[1.02,11.71]],"id":52385884},{"atb":[[1.01,23.42]],"id":52385917},{"atb":[[1.01,23.42]],"id":52385897},{"atb":[[1.02,11.71]],"id":52385891},{"atb":[[1.01,23.42]],"id":52385893},{"atb":[[1.01,23.42]],"id":52385903},{"atb":[[1.03,7.81]],"id":52385905},{"atb":[[1.02,11.71]],"id":52385899}],"con":true,"img":true}]}
{"op":"mcm","clk":"11548270792","pt":1719455882654,"mc":[{"id":"1.230178173","marketDefinition":{"bspMarket":false,"turnInPlayEnabled":false,"persistenceEnabled":false,"marketBaseRate":5.0,"eventId":"33376048","eventTypeId":"4339","numberOfWinners":1,"bettingType":"ODDS","marketType":"FORECAST","marketTime":"2024-06-27T15:41:00.000Z","suspendTime":"2024-06-27T15:41:00.000Z","bspReconciled":false,"complete":true,"inPlay":false,"crossMatching":false,"runnersVoidable":false,"numberOfActiveRunners":30,"betDelay":0,"status":"OPEN","runners":[{"status":"ACTIVE","sortPriority":1,"id":52385882,"name":"1 - 2"},{"status":"ACTIVE","sortPriority":2,"id":52385883,"name":"1 - 3"},{"status":"ACTIVE","sortPriority":3,"id":52385884,"name":"1 - 4"},{"status":"ACTIVE","sortPriority":4,"id":52385885,"name":"1 - 5"},{"status":"ACTIVE","sortPriority":5,"id":52385886,"name":"1 - 6"},{"status":"ACTIVE","sortPriority":6,"id":52385889,"name":"2 - 1"},{"status":"ACTIVE","sortPriority":7,"id":52385890,"name":"2 - 3"},{"status":"ACTIVE","sortPriority":8,"id":52385891,"name":"2 - 4"},{"status":"ACTIVE","sortPriority":9,"id":52385892,"name":"2 - 5"},{"status":"ACTIVE","sortPriority":10,"id":52385893,"name":"2 - 6"},{"status":"ACTIVE","sortPriority":11,"id":52385896,"name":"3 - 1"},{"status":"ACTIVE","sortPriority":12,"id":52385897,"name":"3 - 2"},{"status":"ACTIVE","sortPriority":13,"id":52385898,"name":"3 - 4"},{"status":"ACTIVE","sortPriority":14,"id":52385899,"name":"3 - 5"},{"status":"ACTIVE","sortPriority":15,"id":52385900,"name":"3 - 6"},{"status":"ACTIVE","sortPriority":16,"id":52385903,"name":"4 - 1"},{"status":"ACTIVE","sortPriority":17,"id":52385904,"name":"4 - 2"},{"status":"ACTIVE","sortPriority":18,"id":52385905,"name":"4 - 3"},{"status":"ACTIVE","sortPriority":19,"id":52385906,"name":"4 - 5"},{"status":"ACTIVE","sortPriority":20,"id":52385907,"name":"4 - 6"},{"status":"ACTIVE","sortPriority":21,"id":52385910,"name":"5 - 1"},{"status":"ACTIVE","sortPriority":22,"id":52385911,"name":"5 - 2"},{"status":"ACTIVE","sortPriority":23,"id":52385912,"name":"5 - 3"},{"status":"ACTIVE","sortPriority":24,"id":52385913,"name":"5 - 4"},{"status":"ACTIVE","sortPriority":25,"id":52385914,"name":"5 - 6"},{"status":"ACTIVE","sortPriority":26,"id":52385917,"name":"6 - 1"},{"status":"ACTIVE","sortPriority":27,"id":52385918,"name":"6 - 2"},{"status":"ACTIVE","sortPriority":28,"id":52385919,"name":"6 - 3"},{"status":"ACTIVE","sortPriority":29,"id":52385920,"name":"6 - 4"},{"status":"ACTIVE","sortPriority":30,"id":52385921,"name":"6 - 5"}],"regulators":["MR_INT"],"venue":"Perry Barr","countryCode":"GB","discountAllowed":true,"timezone":"Europe/London","openDate":"2024-06-27T13:29:00.000Z","version":5994794124,"name":"Forecast","eventName":"Perry Barr (F/C) 27th Jun"},"rc":[{"atb":[[1.03,7.81]],"id":52385910},{"atb":[[1.03,7.81]],"id":52385912},{"atb":[[1.02,11.71]],"id":52385906},{"atb":[[1.03,7.81]],"id":52385918},{"atb":[[1.02,11.71]],"id":52385920},{"atb":[[1.01,23.42]],"id":52385889},{"atb":[[1.01,23.42]],"id":52385914},{"atb":[[1.03,7.81]],"id":52385883},{"atb":[[1.01,23.42]],"id":52385885},{"atb":[[1.03,7.81]],"id":52385896},{"atb":[[1.02,11.71]],"id":52385890},{"atb":[[1.01,23.42]],"id":52385892},{"atb":[[1.03,7.81]],"id":52385904},{"atb":[[1.03,7.81]],"id":52385898},{"atb":[[1.03,7.81]],"id":52385900},{"atb":[[1.02,11.71]],"id":52385911},{"atb":[[1.03,7.81]],"id":52385913},{"atb":[[1.02,11.71]],"id":52385907},{"atb":[[1.03,7.81]],"id":52385886},{"atb":[[1.01,23.42]],"id":52385919},{"atb":[[1.01,23.42]],"id":52385921},{"atb":[[1.01,23.42]],"id":52385882},{"atb":[[1.02,11.71]],"id":52385884},{"atb":[[1.01,23.42]],"id":52385917},{"atb":[[1.01,23.42]],"id":52385897},{"atb":[[1.02,11.71]],"id":52385891},{"atb":[[1.01,23.42]],"id":52385893},{"atb":[[1.01,23.42]],"id":52385903},{"atb":[[1.03,7.81]],"id":52385905},{"atb":[[1.02,11.71]],"id":52385899}],"con":true,"img":true}]}
{"op":"mcm","clk":"11548414829","pt":1719460930481,"mc":[{"id":"1.230178173","rc":[{"atb":[[1.03,7.81],[1.16,100]],"id":52385910},{"atb":[[1.03,7.81],[1.16,100]],"id":52385912},{"atb":[[1.16,100],[1.02,11.71]],"id":52385906},{"atb":[[1.03,7.81],[1.16,100]],"id":52385918},{"atb":[[1.16,100],[1.02,11.71]],"id":52385920},{"atb":[[1.01,23.42],[1.16,100]],"id":52385889},{"atb":[[1.01,23.42],[1.16,100]],"id":52385914},{"atb":[[1.03,7.81],[1.16,100]],"id":52385883},{"atb":[[1.01,23.42],[1.16,100]],"id":52385885},{"atb":[[1.03,7.81],[1.16,100]],"id":52385896},{"atb":[[1.16,100],[1.02,11.71]],"id":52385890},{"atb":[[1.01,23.42],[1.16,100]],"id":52385892},{"atb":[[1.03,7.81],[1.16,100]],"id":52385904},{"atb":[[1.03,7.81],[1.16,100]],"id":52385898},{"atb":[[1.03,7.81],[1.16,100]],"id":52385900},{"atb":[[1.16,100],[1.02,11.71]],"id":52385911},{"atb":[[1.03,7.81],[1.16,100]],"id":52385913},{"atb":[[1.16,100],[1.02,11.71]],"id":52385907},{"atb":[[1.03,7.81],[1.16,100]],"id":52385886},{"atb":[[1.01,23.42],[1.16,100]],"id":52385919},{"atb":[[1.01,23.42],[1.16,100]],"id":52385921},{"atb":[[1.01,23.42],[1.16,100]],"id":52385882},{"atb":[[1.16,100],[1.02,11.71]],"id":52385884},{"atb":[[1.01,23.42],[1.16,100]],"id":52385917},{"atb":[[1.01,23.42],[1.16,100]],"id":52385897},{"atb":[[1.16,100],[1.02,11.71]],"id":52385891},{"atb":[[1.01,23.42],[1.16,100]],"id":52385893},{"atb":[[1.01,23.42],[1.16,100]],"id":52385903},{"atb":[[1.03,7.81],[1.16,100]],"id":52385905},{"atb":[[1.16,100],[1.02,11.71]],"id":52385899}],"con":true,"img":false}]}
{"op":"mcm","clk":"11548535728","pt":1719466682820,"mc":[{"id":"1.230178173","marketDefinition":{"bspMarket":false,"turnInPlayEnabled":false,"persistenceEnabled":false,"marketBaseRate":5.0,"eventId":"33376048","eventTypeId":"4339","numberOfWinners":1,"bettingType":"ODDS","marketType":"FORECAST","marketTime":"2024-06-27T15:41:00.000Z","suspendTime":"2024-06-27T15:41:00.000Z","bspReconciled":false,"complete":true,"inPlay":false,"crossMatching":false,"runnersVoidable":false,"numberOfActiveRunners":30,"betDelay":0,"status":"OPEN","runners":[{"status":"ACTIVE","sortPriority":1,"id":52385882,"name":"1 - 2"},{"status":"ACTIVE","sortPriority":2,"id":52385883,"name":"1 - 3"},{"status":"ACTIVE","sortPriority":3,"id":52385884,"name":"1 - 4"},{"status":"ACTIVE","sortPriority":4,"id":52385885,"name":"1 - 5"},{"status":"ACTIVE","sortPriority":5,"id":52385886,"name":"1 - 6"},{"status":"ACTIVE","sortPriority":6,"id":52385889,"name":"2 - 1"},{"status":"ACTIVE","sortPriority":7,"id":52385890,"name":"2 - 3"},{"status":"ACTIVE","sortPriority":8,"id":52385891,"name":"2 - 4"},{"status":"ACTIVE","sortPriority":9,"id":52385892,"name":"2 - 5"},{"status":"ACTIVE","sortPriority":10,"id":52385893,"name":"2 - 6"},{"status":"ACTIVE","sortPriority":11,"id":52385896,"name":"3 - 1"},{"status":"ACTIVE","sortPriority":12,"id":52385897,"name":"3 - 2"},{"status":"ACTIVE","sortPriority":13,"id":52385898,"name":"3 - 4"},{"status":"ACTIVE","sortPriority":14,"id":52385899,"name":"3 - 5"},{"status":"ACTIVE","sortPriority":15,"id":52385900,"name":"3 - 6"},{"status":"ACTIVE","sortPriority":16,"id":52385903,"name":"4 - 1"},{"status":"ACTIVE","sortPriority":17,"id":52385904,"name":"4 - 2"},{"status":"ACTIVE","sortPriority":18,"id":52385905,"name":"4 - 3"},{"status":"ACTIVE","sortPriority":19,"id":52385906,"name":"4 - 5"},{"status":"ACTIVE","sortPriority":20,"id":52385907,"name":"4 - 6"},{"status":"ACTIVE","sortPriority":21,"id":52385910,"name":"5 - 1"},{"status":"ACTIVE","sortPriority":22,"id":52385911,"name":"5 - 2"},{"status":"ACTIVE","sortPriority":23,"id":52385912,"name":"5 - 3"},{"status":"ACTIVE","sortPriority":24,"id":52385913,"name":"5 - 4"},{"status":"ACTIVE","sortPriority":25,"id":52385914,"name":"5 - 6"},{"status":"ACTIVE","sortPriority":26,"id":52385917,"name":"6 - 1"},{"status":"ACTIVE","sortPriority":27,"id":52385918,"name":"6 - 2"},{"status":"ACTIVE","sortPriority":28,"id":52385919,"name":"6 - 3"},{"status":"ACTIVE","sortPriority":29,"id":52385920,"name":"6 - 4"},{"status":"ACTIVE","sortPriority":30,"id":52385921,"name":"6 - 5"}],"regulators":["MR_INT"],"venue":"Perry Barr","countryCode":"GB","discountAllowed":true,"timezone":"Europe/London","openDate":"2024-06-27T13:29:00.000Z","version":5994794124,"name":"Forecast","eventName":"Perry Barr (F/C) 27th Jun"},"rc":[{"atb":[[1.16,100],[1.03,7.81]],"id":52385910},{"atb":[[1.16,100],[1.03,7.81]],"id":52385912},{"atb":[[1.16,100],[1.02,11.71]],"id":52385906},{"atb":[[1.16,100],[1.03,7.81]],"id":52385918},{"atb":[[1.16,100],[1.02,11.71]],"id":52385920},{"atb":[[1.01,23.42],[1.16,100]],"id":52385889},{"atb":[[1.01,23.42],[1.16,100]],"id":52385914},{"atb":[[1.16,100],[1.03,7.81]],"id":52385883},{"atb":[[1.01,23.42],[1.16,100]],"id":52385885},{"atb":[[1.16,100],[1.03,7.81]],"id":52385896},{"atb":[[1.16,100],[1.02,11.71]],"id":52385890},{"atb":[[1.01,23.42],[1.16,100]],"id":52385892},{"atb":[[1.16,100],[1.03,7.81]],"id":52385904},{"atb":[[1.16,100],[1.03,7.81]],"id":52385898},{"atb":[[1.16,100],[1.03,7.81]],"id":52385900},{"atb":[[1.16,100],[1.02,11.71]],"id":52385911},{"atb":[[1.16,100],[1.03,7.81]],"id":52385913},{"atb":[[1.16,100],[1.02,11.71]],"id":52385907},{"atb":[[1.16,100],[1.03,7.81]],"id":52385886},{"atb":[[1.01,23.42],[1.16,100]],"id":52385919},{"atb":[[1.01,23.42],[1.16,100]],"id":52385921},{"atb":[[1.01,23.42],[1.16,100]],"id":52385882},{"atb":[[1.16,100],[1.02,11.71]],"id":52385884},{"atb":[[1.01,23.42],[1.16,100]],"id":52385917},{"atb":[[1.01,23.42],[1.16,100]],"id":52385897},{"atb":[[1.16,100],[1.02,11.71]],"id":52385891},{"atb":[[1.01,23.42],[1.16,100]],"id":52385893},{"atb":[[1.01,23.42],[1.16,100]],"id":52385903},{"atb":[[1.16,100],[1.03,7.81]],"id":52385905},{"atb":[[1.16,100],[1.02,11.71]],"id":52385899}],"con":true,"img":true}]}
{"op":"mcm","clk":"11548656209","pt":1719472082591,"mc":[{"id":"1.230178173","marketDefinition":{"bspMarket":false,"turnInPlayEnabled":false,"persistenceEnabled":false,"marketBaseRate":5.0,"eventId":"33376048","eventTypeId":"4339","numberOfWinners":1,"bettingType":"ODDS","marketType":"FORECAST","marketTime":"2024-06-27T15:41:00.000Z","suspendTime":"2024-06-27T15:41:00.000Z","bspReconciled":false,"complete":true,"inPlay":false,"crossMatching":false,"runnersVoidable":false,"numberOfActiveRunners":30,"betDelay":0,"status":"OPEN","runners":[{"status":"ACTIVE","sortPriority":1,"id":52385882,"name":"1 - 2"},{"status":"ACTIVE","sortPriority":2,"id":52385883,"name":"1 - 3"},{"status":"ACTIVE","sortPriority":3,"id":52385884,"name":"1 - 4"},{"status":"ACTIVE","sortPriority":4,"id":52385885,"name":"1 - 5"},{"status":"ACTIVE","sortPriority":5,"id":52385886,"name":"1 - 6"},{"status":"ACTIVE","sortPriority":6,"id":52385889,"name":"2 - 1"},{"status":"ACTIVE","sortPriority":7,"id":52385890,"name":"2 - 3"},{"status":"ACTIVE","sortPriority":8,"id":52385891,"name":"2 - 4"},{"status":"ACTIVE","sortPriority":9,"id":52385892,"name":"2 - 5"},{"status":"ACTIVE","sortPriority":10,"id":52385893,"name":"2 - 6"},{"status":"ACTIVE","sortPriority":11,"id":52385896,"name":"3 - 1"},{"status":"ACTIVE","sortPriority":12,"id":52385897,"name":"3 - 2"},{"status":"ACTIVE","sortPriority":13,"id":52385898,"name":"3 - 4"},{"status":"ACTIVE","sortPriority":14,"id":52385899,"name":"3 - 5"},{"status":"ACTIVE","sortPriority":15,"id":52385900,"name":"3 - 6"},{"status":"ACTIVE","sortPriority":16,"id":52385903,"name":"4 - 1"},{"status":"ACTIVE","sortPriority":17,"id":52385904,"name":"4 - 2"},{"status":"ACTIVE","sortPriority":18,"id":52385905,"name":"4 - 3"},{"status":"ACTIVE","sortPriority":19,"id":52385906,"name":"4 - 5"},{"status":"ACTIVE","sortPriority":20,"id":52385907,"name":"4 - 6"},{"status":"ACTIVE","sortPriority":21,"id":52385910,"name":"5 - 1"},{"status":"ACTIVE","sortPriority":22,"id":52385911,"name":"5 - 2"},{"status":"ACTIVE","sortPriority":23,"id":52385912,"name":"5 - 3"},{"status":"ACTIVE","sortPriority":24,"id":52385913,"name":"5 - 4"},{"status":"ACTIVE","sortPriority":25,"id":52385914,"name":"5 - 6"},{"status":"ACTIVE","sortPriority":26,"id":52385917,"name":"6 - 1"},{"status":"ACTIVE","sortPriority":27,"id":52385918,"name":"6 - 2"},{"status":"ACTIVE","sortPriority":28,"id":52385919,"name":"6 - 3"},{"status":"ACTIVE","sortPriority":29,"id":52385920,"name":"6 - 4"},{"status":"ACTIVE","sortPriority":30,"id":52385921,"name":"6 - 5"}],"regulators":["MR_INT"],"venue":"Perry Barr","countryCode":"GB","discountAllowed":true,"timezone":"Europe/London","openDate":"2024-06-27T13:29:00.000Z","version":5994794124,"name":"Forecast","eventName":"Perry Barr (F/C) 27th Jun"},"rc":[{"atb":[[1.16,100],[1.03,7.8]],"id":52385910},{"atb":[[1.16,100],[1.03,7.8]],"id":52385912},{"atb":[[1.16,100],[1.02,11.7]],"id":52385906},{"atb":[[1.16,100],[1.03,7.8]],"id":52385918},{"atb":[[1.16,100],[1.02,11.7]],"id":52385920},{"atb":[[1.01,23.41],[1.16,100]],"id":52385889},{"atb":[[1.01,23.41],[1.16,100]],"id":52385914},{"atb":[[1.16,100],[1.03,7.8]],"id":52385883},{"atb":[[1.01,23.41],[1.16,100]],"id":52385885},{"atb":[[1.16,100],[1.03,7.8]],"id":52385896},{"atb":[[1.16,100],[1.02,11.7]],"id":52385890},{"atb":[[1.01,23.41],[1.16,100]],"id":52385892},{"atb":[[1.16,100],[1.03,7.8]],"id":52385904},{"atb":[[1.16,100],[1.03,7.8]],"id":52385898},{"atb":[[1.16,100],[1.03,7.8]],"id":52385900},{"atb":[[1.16,100],[1.02,11.7]],"id":52385911},{"atb":[[1.16,100],[1.03,7.8]],"id":52385913},{"atb":[[1.16,100],[1.02,11.7]],"id":52385907},{"atb":[[1.16,100],[1.03,7.8]],"id":52385886},{"atb":[[1.01,23.41],[1.16,100]],"id":52385919},{"atb":[[1.01,23.41],[1.16,100]],"id":52385921},{"atb":[[1.01,23.41],[1.16,100]],"id":52385882},{"atb":[[1.16,100],[1.02,11.7]],"id":52385884},{"atb":[[1.01,23.41],[1.16,100]],"id":52385917},{"atb":[[1.01,23.41],[1.16,100]],"id":52385897},{"atb":[[1.16,100],[1.02,11.7]],"id":52385891},{"atb":[[1.01,23.41],[1.16,100]],"id":52385893},{"atb":[[1.01,23.41],[1.16,100]],"id":52385903},{"atb":[[1.16,100],[1.03,7.8]],"id":52385905},{"atb":[[1.16,100],[1.02,11.7]],"id":52385899}],"con":true,"img":true}]}
{"op":"mcm","clk":"11548861955","pt":1719477482591,"mc":[{"id":"1.230178173","marketDefinition":{"bspMarket":false,"turnInPlayEnabled":false,"persistenceEnabled":false,"marketBaseRate":5.0,"eventId":"33376048","eventTypeId":"4339","numberOfWinners":1,"bettingType":"ODDS","marketType":"FORECAST","marketTime":"2024-06-27T15:41:00.000Z","suspendTime":"2024-06-27T15:41:00.000Z","bspReconciled":false,"complete":true,"inPlay":false,"crossMatching":false,"runnersVoidable":false,"numberOfActiveRunners":30,"betDelay":0,"status":"OPEN","runners":[{"status":"ACTIVE","sortPriority":1,"id":52385882,"name":"1 - 2"},{"status":"ACTIVE","sortPriority":2,"id":52385883,"name":"1 - 3"},{"status":"ACTIVE","sortPriority":3,"id":52385884,"name":"1 - 4"},{"status":"ACTIVE","sortPriority":4,"id":52385885,"name":"1 - 5"},{"status":"ACTIVE","sortPriority":5,"id":52385886,"name":"1 - 6"},{"status":"ACTIVE","sortPriority":6,"id":52385889,"name":"2 - 1"},{"status":"ACTIVE","sortPriority":7,"id":52385890,"name":"2 - 3"},{"status":"ACTIVE","sortPriority":8,"id":52385891,"name":"2 - 4"},{"status":"ACTIVE","sortPriority":9,"id":52385892,"name":"2 - 5"},{"status":"ACTIVE","sortPriority":10,"id":52385893,"name":"2 - 6"},{"status":"ACTIVE","sortPriority":11,"id":52385896,"name":"3 - 1"},{"status":"ACTIVE","sortPriority":12,"id":52385897,"name":"3 - 2"},{"status":"ACTIVE","sortPriority":13,"id":52385898,"name":"3 - 4"},{"status":"ACTIVE","sortPriority":14,"id":52385899,"name":"3 - 5"},{"status":"ACTIVE","sortPriority":15,"id":52385900,"name":"3 - 6"},{"status":"ACTIVE","sortPriority":16,"id":52385903,"name":"4 - 1"},{"status":"ACTIVE","sortPriority":17,"id":52385904,"name":"4 - 2"},{"status":"ACTIVE","sortPriority":18,"id":52385905,"name":"4 - 3"},{"status":"ACTIVE","sortPriority":19,"id":52385906,"name":"4 - 5"},{"status":"ACTIVE","sortPriority":20,"id":52385907,"name":"4 - 6"},{"status":"ACTIVE","sortPriority":21,"id":52385910,"name":"5 - 1"},{"status":"ACTIVE","sortPriority":22,"id":52385911,"name":"5 - 2"},{"status":"ACTIVE","sortPriority":23,"id":52385912,"name":"5 - 3"},{"status":"ACTIVE","sortPriority":24,"id":52385913,"name":"5 - 4"},{"status":"ACTIVE","sortPriority":25,"id":52385914,"name":"5 - 6"},{"status":"ACTIVE","sortPriority":26,"id":52385917,"name":"6 - 1"},{"status":"ACTIVE","sortPriority":27,"id":52385918,"name":"6 - 2"},{"status":"ACTIVE","sortPriority":28,"id":52385919,"name":"6 - 3"},{"status":"ACTIVE","sortPriority":29,"id":52385920,"name":"6 - 4"},{"status":"ACTIVE","sortPriority":30,"id":52385921,"name":"6 - 5"}],"regulators":["MR_INT"],"venue":"Perry Barr","countryCode":"GB","discountAllowed":true,"timezone":"Europe/London","openDate":"2024-06-27T13:29:00.000Z","version":5994794124,"name":"Forecast","eventName":"Perry Barr (F/C) 27th Jun"},"rc":[{"atb":[[1.16,100],[1.03,7.8]],"id":52385910},{"atb":[[1.16,100],[1.03,7.8]],"id":52385912},{"atb":[[1.16,100],[1.02,11.7]],"id":52385906},{"atb":[[1.16,100],[1.03,7.8]],"id":52385918},{"atb":[[1.16,100],[1.02,11.7]],"id":52385920},{"atb":[[1.01,23.41],[1.16,100]],"id":52385889},{"atb":[[1.01,23.41],[1.16,100]],"id":52385914},{"atb":[[1.16,100],[1.03,7.8]],"id":52385883},{"atb":[[1.01,23.41],[1.16,100]],"id":52385885},{"atb":[[1.16,100],[1.03,7.8]],"id":52385896},{"atb":[[1.16,100],[1.02,11.7]],"id":52385890},{"atb":[[1.01,23.41],[1.16,100]],"id":52385892},{"atb":[[1.16,100],[1.03,7.8]],"id":52385904},{"atb":[[1.16,100],[1.03,7.8]],"id":52385898},{"atb":[[1.16,100],[1.03,7.8]],"id":52385900},{"atb":[[1.16,100],[1.02,11.7]],"id":52385911},{"atb":[[1.16,100],[1.03,7.8]],"id":52385913},{"atb":[[1.16,100],[1.02,11.7]],"id":52385907},{"atb":[[1.16,100],[1.03,7.8]],"id":52385886},{"atb":[[1.01,23.41],[1.16,100]],"id":52385919},{"atb":[[1.01,23.41],[1.16,100]],"id":52385921},{"atb":[[1.01,23.41],[1.16,100]],"id":52385882},{"atb":[[1.16,100],[1.02,11.7]],"id":52385884},{"atb":[[1.01,23.41],[1.16,100]],"id":52385917},{"atb":[[1.01,23.41],[1.16,100]],"id":52385897},{"atb":[[1.16,100],[1.02,11.7]],"id":52385891},{"atb":[[1.01,23.41],[1.16,100]],"id":52385893},{"atb":[[1.01,23.41],[1.16,100]],"id":52385903},{"atb":[[1.16,100],[1.03,7.8]],"id":52385905},{"atb":[[1.16,100],[1.02,11.7]],"id":52385899}],"con":true,"img":true}]}
{"op":"mcm","clk":"11549140219","pt":1719482882591,"mc":[{"id":"1.230178173","marketDefinition":{"bspMarket":false,"turnInPlayEnabled":false,"persistenceEnabled":false,"marketBaseRate":5.0,"eventId":"33376048","eventTypeId":"4339","numberOfWinners":1,"bettingType":"ODDS","marketType":"FORECAST","marketTime":"2024-06-27T15:41:00.000Z","suspendTime":"2024-06-27T15:41:00.000Z","bspReconciled":false,"complete":true,"inPlay":false,"crossMatching":false,"runnersVoidable":false,"numberOfActiveRunners":30,"betDelay":0,"status":"OPEN","runners":[{"status":"ACTIVE","sortPriority":1,"id":52385882,"name":"1 - 2"},{"status":"ACTIVE","sortPriority":2,"id":52385883,"name":"1 - 3"},{"status":"ACTIVE","sortPriority":3,"id":52385884,"name":"1 - 4"},{"status":"ACTIVE","sortPriority":4,"id":52385885,"name":"1 - 5"},{"status":"ACTIVE","sortPriority":5,"id":52385886,"name":"1 - 6"},{"status":"ACTIVE","sortPriority":6,"id":52385889,"name":"2 - 1"},{"status":"ACTIVE","sortPriority":7,"id":52385890,"name":"2 - 3"},{"status":"ACTIVE","sortPriority":8,"id":52385891,"name":"2 - 4"},{"status":"ACTIVE","sortPriority":9,"id":52385892,"name":"2 - 5"},{"status":"ACTIVE","sortPriority":10,"id":52385893,"name":"2 - 6"},{"status":"ACTIVE","sortPriority":11,"id":52385896,"name":"3 - 1"},{"status":"ACTIVE","sortPriority":12,"id":52385897,"name":"3 - 2"},{"status":"ACTIVE","sortPriority":13,"id":52385898,"name":"3 - 4"},{"status":"ACTIVE","sortPriority":14,"id":52385899,"name":"3 - 5"},{"status":"ACTIVE","sortPriority":15,"id":52385900,"name":"3 - 6"},{"status":"ACTIVE","sortPriority":16,"id":52385903,"name":"4 - 1"},{"status":"ACTIVE","sortPriority":17,"id":52385904,"name":"4 - 2"},{"status":"ACTIVE","sortPriority":18,"id":52385905,"name":"4 - 3"},{"status":"ACTIVE","sortPriority":19,"id":52385906,"name":"4 - 5"},{"status":"ACTIVE","sortPriority":20,"id":52385907,"name":"4 - 6"},{"status":"ACTIVE","sortPriority":21,"id":52385910,"name":"5 - 1"},{"status":"ACTIVE","sortPriority":22,"id":52385911,"name":"5 - 2"},{"status":"ACTIVE","sortPriority":23,"id":52385912,"name":"5 - 3"},{"status":"ACTIVE","sortPriority":24,"id":52385913,"name":"5 - 4"},{"status":"ACTIVE","sortPriority":25,"id":52385914,"name":"5 - 6"},{"status":"ACTIVE","sortPriority":26,"id":52385917,"name":"6 - 1"},{"status":"ACTIVE","sortPriority":27,"id":52385918,"name":"6 - 2"},{"status":"ACTIVE","sortPriority":28,"id":52385919,"name":"6 - 3"},{"status":"ACTIVE","sortPriority":29,"id":52385920,"name":"6 - 4"},{"status":"ACTIVE","sortPriority":30,"id":52385921,"name":"6 - 5"}],"regulators":["MR_INT"],"venue":"Perry Barr","countryCode":"GB","discountAllowed":true,"timezone":"Europe/London","openDate":"2024-06-27T13:29:00.000Z","version":5994794124,"name":"Forecast","eventName":"Perry Barr (F/C) 27th Jun"},"rc":[{"atb":[[1.16,100],[1.03,7.8]],"id":52385910},{"atb":[[1.16,100],[1.03,7.8]],"id":52385912},{"atb":[[1.16,100],[1.02,11.7]],"id":52385906},{"atb":[[1.16,100],[1.03,7.8]],"id":52385918},{"atb":[[1.16,100],[1.02,11.7]],"id":52385920},{"atb":[[1.01,23.41],[1.16,100]],"id":52385889},{"atb":[[1.01,23.41],[1.16,100]],"id":52385914},{"atb":[[1.16,100],[1.03,7.8]],"id":52385883},{"atb":[[1.01,23.41],[1.16,100]],"id":52385885},{"atb":[[1.16,100],[1.03,7.8]],"id":52385896},{"atb":[[1.16,100],[1.02,11.7]],"id":52385890},{"atb":[[1.01,23.41],[1.16,100]],"id":52385892},{"atb":[[1.16,100],[1.03,7.8]],"id":52385904},{"atb":[[1.16,100],[1.03,7.8]],"id":52385898},{"atb":[[1.16,100],[1.03,7.8]],"id":52385900},{"atb":[[1.16,100],[1.02,11.7]],"id":52385911},{"atb":[[1.16,100],[1.03,7.8]],"id":52385913},{"atb":[[1.16,100],[1.02,11.7]],"id":52385907},{"atb":[[1.16,100],[1.03,7.8]],"id":52385886},{"atb":[[1.01,23.41],[1.16,100]],"id":52385919},{"atb":[[1.01,23.41],[1.16,100]],"id":52385921},{"atb":[[1.01,23.41],[1.16,100]],"id":52385882},{"atb":[[1.16,100],[1.02,11.7]],"id":52385884},{"atb":[[1.01,23.41],[1.16,100]],"id":52385917},{"atb":[[1.01,23.41],[1.16,100]],"id":52385897},{"atb":[[1.16,100],[1.02,11.7]],"id":52385891},{"atb":[[1.01,23.41],[1.16,100]],"id":52385893},{"atb":[[1.01,23.41],[1.16,100]],"id":52385903},{"atb":[[1.16,100],[1.03,7.8]],"id":52385905},{"atb":[[1.16,100],[1.02,11.7]],"id":52385899}],"con":true,"img":true}]}
{"op":"mcm","clk":"11549606654","pt":1719488282609,"mc":[{"id":"1.230178173","marketDefinition":{"bspMarket":false,"turnInPlayEnabled":false,"persistenceEnabled":false,"marketBaseRate":5.0,"eventId":"33376048","eventTypeId":"4339","numberOfWinners":1,"bettingType":"ODDS","marketType":"FORECAST","marketTime":"2024-06-27T15:41:00.000Z","suspendTime":"2024-06-27T15:41:00.000Z","bspReconciled":false,"complete":true,"inPlay":false,"crossMatching":false,"runnersVoidable":false,"numberOfActiveRunners":30,"betDelay":0,"status":"OPEN","runners":[{"status":"ACTIVE","sortPriority":1,"id":52385882,"name":"1 - 2"},{"status":"ACTIVE","sortPriority":2,"id":52385883,"name":"1 - 3"},{"status":"ACTIVE","sortPriority":3,"id":52385884,"name":"1 - 4"},{"status":"ACTIVE","sortPriority":4,"id":52385885,"name":"1 - 5"},{"status":"ACTIVE","sortPriority":5,"id":52385886,"name":"1 - 6"},{"status":"ACTIVE","sortPriority":6,"id":52385889,"name":"2 - 1"},{"status":"ACTIVE","sortPriority":7,"id":52385890,"name":"2 - 3"},{"status":"ACTIVE","sortPriority":8,"id":52385891,"name":"2 - 4"},{"status":"ACTIVE","sortPriority":9,"id":52385892,"name":"2 - 5"},{"status":"ACTIVE","sortPriority":10,"id":52385893,"name":"2 - 6"},{"status":"ACTIVE","sortPriority":11,"id":52385896,"name":"3 - 1"},{"status":"ACTIVE","sortPriority":12,"id":52385897,"name":"3 - 2"},{"status":"ACTIVE","sortPriority":13,"id":52385898,"name":"3 - 4"},{"status":"ACTIVE","sortPriority":14,"id":52385899,"name":"3 - 5"},{"status":"ACTIVE","sortPriority":15,"id":52385900,"name":"3 - 6"},{"status":"ACTIVE","sortPriority":16,"id":52385903,"name":"4 - 1"},{"status":"ACTIVE","sortPriority":17,"id":52385904,"name":"4 - 2"},{"status":"ACTIVE","sortPriority":18,"id":52385905,"name":"4 - 3"},{"status":"ACTIVE","sortPriority":19,"id":52385906,"name":"4 - 5"},{"status":"ACTIVE","sortPriority":20,"id":52385907,"name":"4 - 6"},{"status":"ACTIVE","sortPriority":21,"id":52385910,"name":"5 - 1"},{"status":"ACTIVE","sortPriority":22,"id":52385911,"name":"5 - 2"},{"status":"ACTIVE","sortPriority":23,"id":52385912,"name":"5 - 3"},{"status":"ACTIVE","sortPriority":24,"id":52385913,"name":"5 - 4"},{"status":"ACTIVE","sortPriority":25,"id":52385914,"name":"5 - 6"},{"status":"ACTIVE","sortPriority":26,"id":52385917,"name":"6 - 1"},{"status":"ACTIVE","sortPriority":27,"id":52385918,"name":"6 - 2"},{"status":"ACTIVE","sortPriority":28,"id":52385919,"name":"6 - 3"},{"status":"ACTIVE","sortPriority":29,"id":52385920,"name":"6 - 4"},{"status":"ACTIVE","sortPriority":30,"id":52385921,"name":"6 - 5"}],"regulators":["MR_INT"],"venue":"Perry Barr","countryCode":"GB","discountAllowed":true,"timezone":"Europe/London","openDate":"2024-06-27T13:29:00.000Z","version":5994794124,"name":"Forecast","eventName":"Perry Barr (F/C) 27th Jun"},"rc":[{"atb":[[1.16,100],[1.03,7.8]],"id":52385910},{"atb":[[1.16,100],[1.03,7.8]],"id":52385912},{"atb":[[1.16,100],[1.02,11.7]],"id":52385906},{"atb":[[1.16,100],[1.03,7.8]],"id":52385918},{"atb":[[1.16,100],[1.02,11.7]],"id":52385920},{"atb":[[1.01,23.41],[1.16,100]],"id":52385889},{"atb":[[1.01,23.41],[1.16,100]],"id":52385914},{"atb":[[1.16,100],[1.03,7.8]],"id":52385883},{"atb":[[1.01,23.41],[1.16,100]],"id":52385885},{"atb":[[1.16,100],[1.03,7.8]],"id":52385896},{"atb":[[1.16,100],[1.02,11.7]],"id":52385890},{"atb":[[1.01,23.41],[1.16,100]],"id":52385892},{"atb":[[1.16,100],[1.03,7.8]],"id":52385904},{"atb":[[1.16,100],[1.03,7.8]],"id":52385898},{"atb":[[1.16,100],[1.03,7.8]],"id":52385900},{"atb":[[1.16,100],[1.02,11.7]],"id":52385911},{"atb":[[1.16,100],[1.03,7.8]],"id":52385913},{"atb":[[1.16,100],[1.02,11.7]],"id":52385907},{"atb":[[1.16,100],[1.03,7.8]],"id":52385886},{"atb":[[1.01,23.41],[1.16,100]],"id":52385919},{"atb":[[1.01,23.41],[1.16,100]],"id":52385921},{"atb":[[1.01,23.41],[1.16,100]],"id":52385882},{"atb":[[1.16,100],[1.02,11.7]],"id":52385884},{"atb":[[1.01,23.41],[1.16,100]],"id":52385917},{"atb":[[1.01,23.41],[1.16,100]],"id":52385897},{"atb":[[1.16,100],[1.02,11.7]],"id":52385891},{"atb":[[1.01,23.41],[1.16,100]],"id":52385893},{"atb":[[1.01,23.41],[1.16,100]],"id":52385903},{"atb":[[1.16,100],[1.03,7.8]],"id":52385905},{"atb":[[1.16,100],[1.02,11.7]],"id":52385899}],"con":true,"img":true}]}
{"op":"mcm","clk":"11549893795","pt":1719492260267,"mc":[{"id":"1.230178173","rc":[{"atb":[[1.03,7.8]],"id":52385910},{"atb":[[1.03,7.8]],"id":52385912},{"atb":[[1.02,11.7]],"id":52385906},{"atb":[[1.03,7.8]],"id":52385918},{"atb":[[1.02,11.7]],"id":52385920},{"atb":[[1.01,23.41]],"id":52385889},{"atb":[[1.01,23.41]],"id":52385914},{"atb":[[1.01,306.12],[1.03,7.8]],"id":52385883},{"atb":[[1.01,23.41]],"id":52385885},{"atb":[[1.03,7.8]],"id":52385896},{"atb":[[1.01,306.12],[1.02,11.7]],"id":52385890},{"atb":[[1.01,23.41]],"id":52385892},{"atb":[[1.03,7.8]],"id":52385904},{"atb":[[1.03,7.8]],"id":52385898},{"atb":[[1.03,7.8]],"id":52385900},{"atb":[[1.02,11.7]],"id":52385911},{"atb":[[1.03,7.8]],"id":52385913},{"atb":[[1.02,11.7]],"id":52385907},{"atb":[[1.01,306.12],[1.03,7.8]],"id":52385886},{"atb":[[1.01,23.41]],"id":52385919},{"atb":[[1.01,23.41]],"id":52385921},{"atb":[[1.01,329.53]],"id":52385882},{"atb":[[1.02,11.7]],"id":52385884},{"atb":[[1.01,23.41]],"id":52385917},{"atb":[[1.01,23.41]],"id":52385897},{"atb":[[1.02,11.7]],"id":52385891},{"atb":[[1.01,23.41]],"id":52385893},{"atb":[[1.01,23.41]],"id":52385903},{"atb":[[1.03,7.8]],"id":52385905},{"atb":[[1.02,11.7]],"id":52385899}],"con":true,"img":false}]}
{"op":"mcm","clk":"11549893801","pt":1719492260370,"mc":[{"id":"1.230178173","rc":[{"atb":[[1.01,306.12]],"id":52385910},{"atb":[[1.01,306.12]],"id":52385906},{"atb":[[1.01,329.53]],"id":52385889},{"atb":[[1.01,329.53]],"id":52385885},{"atb":[[1.01,306.12]],"id":52385896},{"atb":[[1.01,329.53]],"id":52385892},{"atb":[[1.01,306.12]],"id":52385904},{"atb":[[1.01,306.12]],"id":52385898},{"atb":[[1.01,306.12]],"id":52385900},{"atb":[[1.01,306.12]],"id":52385911},{"atb":[[1.01,306.12]],"id":52385907},{"atb":[[1.01,306.12]],"id":52385884},{"atb":[[1.01,329.53]],"id":52385897},{"atb":[[1.01,306.12]],"id":52385891},{"atb":[[1.01,329.53]],"id":52385893},{"atb":[[1.01,329.53]],"id":52385903},{"atb":[[1.01,306.12]],"id":52385905},{"atb":[[1.01,306.12]],"id":52385899}],"con":true,"img":false}]}
{"op":"mcm","clk":"11549893814","pt":1719492260578,"mc":[{"id":"1.230178173","rc":[{"atb":[[1.01,306.12]],"id":52385912},{"atb":[[1.01,329.53]],"id":52385914},{"atb":[[1.01,306.12]],"id":52385913}],"con":true,"img":false}]}
{"op":"mcm","clk":"11549893840","pt":1719492260985,"mc":[{"id":"1.230178173","rc":[{"atb":[[1.01,306.12]],"id":52385918},{"atb":[[1.17,120.05]],"id":52385889},{"atb":[[1.17,120.05]],"id":52385883},{"atb":[[1.17,120.05]],"id":52385885},{"atb":[[1.17,120.05]],"id":52385896},{"atb":[[1.17,120.05]],"id":52385890},{"atb":[[1.17,120.05]],"id":52385892},{"atb":[[1.17,120.05]],"id":52385886},{"atb":[[1.01,329.53]],"id":52385919},{"atb":[[1.01,329.53]],"id":52385921},{"atb":[[1.17,120.05]],"id":52385884},{"atb":[[1.01,329.53]],"id":52385917},{"atb":[[1.17,120.05]],"id":52385897},{"atb":[[1.17,120.05]],"id":52385891},{"atb":[[1.17,120.05]],"id":52385893}],"con":true,"img":false}]}
{"op":"mcm","clk":"11549893844","pt":1719492261087,"mc":[{"id":"1.230178173","rc":[{"atb":[[1.01,306.12]],"id":52385920},{"atb":[[1.17,120.05]],"id":52385904},{"atb":[[1.17,120.05]],"id":52385898},{"atb":[[1.17,120.05]],"id":52385900},{"atb":[[1.17,120.05]],"id":52385882},{"atb":[[1.17,120.05]],"id":52385903},{"atb":[[1.17,120.05]],"id":52385899}],"con":true,"img":false}]}
{"op":"mcm","clk":"11549893879","pt":1719492261562,"mc":[{"id":"1.230178173","rc":[{"atb":[[1.17,120.05]],"id":52385910},{"atb":[[1.17,120.05]],"id":52385912},{"atb":[[1.17,120.05]],"id":52385906},{"atb":[[1.17,120.05]],"id":52385918},{"atb":[[1.17,120.05]],"id":52385920},{"atb":[[1.17,120.05]],"id":52385914},{"atb":[[1.17,120.05]],"id":52385911},{"atb":[[1.17,120.05]],"id":52385913},{"atb":[[1.17,120.05]],"id":52385907},{"atb":[[1.17,120.05]],"id":52385919},{"atb":[[1.17,120.05]],"id":52385921},{"atb":[[1.17,120.05]],"id":52385917},{"atb":[[1.17,120.05]],"id":52385905}],"con":true,"img":false}]}
{"op":"mcm","clk":"11549970663","pt":1719493210684,"mc":[{"id":"1.230178173","rc":[{"atb":[[1.16,0],[1.03,7.81]],"id":52385910},{"atb":[[1.16,0],[1.03,7.81]],"id":52385912},{"atb":[[1.16,0],[1.02,11.72]],"id":52385906},{"atb":[[1.16,0],[1.03,7.81]],"id":52385918},{"atb":[[1.16,0],[1.02,11.72]],"id":52385920},{"atb":[[1.01,329.56],[1.16,0]],"id":52385889},{"atb":[[1.01,329.56],[1.16,0]],"id":52385914},{"atb":[[1.16,0],[1.03,7.81]],"id":52385883},{"atb":[[1.01,329.56],[1.16,0]],"id":52385885},{"atb":[[1.16,0],[1.03,7.81]],"id":52385896},{"atb":[[1.16,0],[1.02,11.72]],"id":52385890},{"atb":[[1.01,329.56],[1.16,0]],"id":52385892},{"atb":[[1.16,0],[1.03,7.81]],"id":52385904},{"atb":[[1.16,0],[1.03,7.81]],"id":52385898},{"atb":[[1.16,0],[1.03,7.81]],"id":52385900},{"atb":[[1.16,0],[1.02,11.72]],"id":52385911},{"atb":[[1.16,0],[1.03,7.81]],"id":52385913},{"atb":[[1.16,0],[1.02,11.72]],"id":52385907},{"atb":[[1.16,0],[1.03,7.81]],"id":52385886},{"atb":[[1.01,329.56],[1.16,0]],"id":52385919},{"atb":[[1.01,329.56],[1.16,0]],"id":52385921},{"atb":[[1.01,329.56],[1.16,0]],"id":52385882},{"atb":[[1.16,0],[1.02,11.72]],"id":52385884},{"atb":[[1.01,329.56],[1.16,0]],"id":52385917},{"atb":[[1.01,329.56],[1.16,0]],"id":52385897},{"atb":[[1.16,0],[1.02,11.72]],"id":52385891},{"atb":[[1.01,329.56],[1.16,0]],"id":52385893},{"atb":[[1.01,329.56],[1.16,0]],"id":52385903},{"atb":[[1.16,0],[1.03,7.81]],"id":52385905},{"atb":[[1.16,0],[1.02,11.72]],"id":52385899}],"con":true,"img":false}]}
{"op":"mcm","clk":"11549974772","pt":1719493262334,"mc":[{"id":"1.230178173","rc":[{"atb":[[1.18,150]],"id":52385910},{"atb":[[1.18,150]],"id":52385912},{"atb":[[1.18,150]],"id":52385906},{"atb":[[1.18,150]],"id":52385918},{"atb":[[1.18,150]],"id":52385920},{"atb":[[1.18,150]],"id":52385889},{"atb":[[1.18,150]],"id":52385914},{"atb":[[1.18,150]],"id":52385883},{"atb":[[1.18,150]],"id":52385885},{"atb":[[1.18,150]],"id":52385896},{"atb":[[1.18,150]],"id":52385890},{"atb":[[1.18,150]],"id":52385892},{"atb":[[1.18,150]],"id":52385904},{"atb":[[1.18,150]],"id":52385898},{"atb":[[1.18,150]],"id":52385900},{"atb":[[1.18,150]],"id":52385911},{"atb":[[1.18,150]],"id":52385913},{"atb":[[1.18,150]],"id":52385907},{"atb":[[1.18,150]],"id":52385886},{"atb":[[1.18,150]],"id":52385919},{"atb":[[1.18,150]],"id":52385921},{"atb":[[1.18,150]],"id":52385882},{"atb":[[1.18,150]],"id":52385884},{"atb":[[1.18,150]],"id":52385917},{"atb":[[1.18,150]],"id":52385897},{"atb":[[1.18,150]],"id":52385891},{"atb":[[1.18,150]],"id":52385893},{"atb":[[1.18,150]],"id":52385903},{"atb":[[1.18,150]],"id":52385905},{"atb":[[1.18,150]],"id":52385899}],"con":true,"img":false}]}
{"op":"mcm","clk":"11549978954","pt":1719493310906,"mc":[{"id":"1.230178173","rc":[{"atb":[[1.17,0]],"id":52385896}],"con":true,"img":false}]}
{"op":"mcm","clk":"11549997596","pt":1719493520967,"mc":[{"id":"1.230178173","rc":[{"atb":[[1.17,0]],"id":52385885}],"con":true,"img":false}]}
{"op":"mcm","clk":"11550049074","pt":1719493961204,"mc":[{"id":"1.230178173","rc":[{"atb":[[1.17,0]],"id":52385891}],"con":true,"img":false}]}
{"op":"mcm","clk":"11550071978","pt":1719494191114,"mc":[{"id":"1.230178173","rc":[{"atb":[[1.17,0]],"id":52385889}],"con":true,"img":false}]}
{"op":"mcm","clk":"11550098598","pt":1719494431274,"mc":[{"id":"1.230178173","rc":[{"atb":[[1.17,0]],"id":52385893}],"con":true,"img":false}]}
{"op":"mcm","clk":"11550124272","pt":1719494661361,"mc":[{"id":"1.230178173","rc":[{"atb":[[1.17,0]],"id":52385883}],"con":true,"img":false}]}
{"op":"mcm","clk":"11550148008","pt":1719494891631,"mc":[{"id":"1.230178173","rc":[{"atb":[[1.17,0]],"id":52385897}],"con":true,"img":false}]}
{"op":"mcm","clk":"11550166493","pt":1719495121682,"mc":[{"id":"1.230178173","rc":[{"atb":[[1.17,0]],"id":52385884}],"con":true,"img":false}]}
{"op":"mcm","clk":"11550184734","pt":1719495351726,"mc":[{"id":"1.230178173","rc":[{"atb":[[1.17,0]],"id":52385886}],"con":true,"img":false}]}
{"op":"mcm","clk":"11550204547","pt":1719495581838,"mc":[{"id":"1.230178173","rc":[{"atb":[[1.17,0]],"id":52385892}],"con":true,"img":false}]}
{"op":"mcm","clk":"11550225130","pt":1719495822004,"mc":[{"id":"1.230178173","rc":[{"atb":[[1.17,0]],"id":52385890}],"con":true,"img":false}]}
{"op":"mcm","clk":"11550247343","pt":1719496062113,"mc":[{"id":"1.230178173","rc":[{"atb":[[1.17,0]],"id":52385903}],"con":true,"img":false}]}
{"op":"mcm","clk":"11550263842","pt":1719496292173,"mc":[{"id":"1.230178173","rc":[{"atb":[[1.17,0]],"id":52385904}],"con":true,"img":false}]}
{"op":"mcm","clk":"11550278701","pt":1719496532203,"mc":[{"id":"1.230178173","rc":[{"atb":[[1.17,0]],"id":52385899}],"con":true,"img":false}]}
{"op":"mcm","clk":"11550279417","pt":1719496543713,"mc":[{"id":"1.230178173","rc":[{"atb":[[1.02,114.33]],"id":52385910},{"atl":[[990,1.57]],"id":52385910},{"atb":[[1.04,72.83]],"id":52385912},{"atl":[[990,1.23]],"id":52385912},{"atb":[[1.04,90.62]],"id":52385906},{"atl":[[980,0.85]],"id":52385906},{"atb":[[1.04,137.2]],"id":52385889},{"atl":[[970,1.75]],"id":52385889},{"atb":[[1.04,151.6]],"id":52385914},{"atl":[[960,0.85]],"id":52385914},{"atb":[[1.02,77.07]],"id":52385883},{"atl":[[960,1.31]],"id":52385883},{"atb":[[1.02,73.68]],"id":52385885},{"atl":[[960,0.85]],"id":52385885},{"atb":[[1.04,133.81]],"id":52385896},{"atl":[[970,0.85]],"id":52385896},{"atb":[[1.03,86.38]],"id":52385890},{"atl":[[980,1.27]],"id":52385890},{"atb":[[1.04,116.03]],"id":52385892},{"atl":[[980,0.85]],"id":52385892},{"atb":[[1.03,93.35]],"id":52385904},{"atl":[[990,1.99]],"id":52385904},{"atb":[[1.03,108.6]],"id":52385898},{"atl":[[990,0.88]],"id":52385898},{"atb":[[1.03,171.27]],"id":52385900},{"atl":[[960,1.93]],"id":52385900},{"atb":[[1.02,95.57]],"id":52385911},{"atl":[[960,1.6]],"id":52385911},{"atb":[[1.03,136.55]],"id":52385913},{"atl":[[960,1.49]],"id":52385913},{"atb":[[1.02,112.5]],"id":52385907},{"atl":[[970,1.43]],"id":52385907},{"atb":[[1.04,163.46]],"id":52385886},{"atl":[[970,1.1]],"id":52385886},{"atb":[[1.02,106.71]],"id":52385882},{"atl":[[990,0.85]],"id":52385882},{"atb":[[1.02,87.1]],"id":52385884},{"atl":[[960,1.7]],"id":52385884},{"atb":[[1.04,103.32]],"id":52385897},{"atl":[[970,1.94]],"id":52385897},{"atb":[[1.04,168.54]],"id":52385891},{"atl":[[980,1.1]],"id":52385891},{"atb":[[1.02,100.78]],"id":52385893},{"atl":[[960,0.85]],"id":52385893},{"atb":[[1.03,97.39]],"id":52385903},{"atl":[[990,1.81]],"id":52385903},{"atb":[[1.04,89.77]],"id":52385905},{"atl":[[980,1.98]],"id":52385905},{"atb":[[1.04,153.29]],"id":52385899},{"atl":[[960,1.91]],"id":52385899}],"con":true,"img":false}]}
{"op":"mcm","clk":"11550281225","pt":1719496572517,"mc":[{"id":"1.230178173","marketDefinition":{"bspMarket":false,"turnInPlayEnabled":false,"persistenceEnabled":false,"marketBaseRate":5.0,"eventId":"33376048","eventTypeId":"4339","numberOfWinners":1,"bettingType":"ODDS","marketType":"FORECAST","marketTime":"2024-06-27T15:41:00.000Z","suspendTime":"2024-06-27T15:41:00.000Z","bspReconciled":false,"complete":true,"inPlay":false,"crossMatching":true,"runnersVoidable":false,"numberOfActiveRunners":30,"betDelay":0,"status":"OPEN","runners":[{"status":"ACTIVE","sortPriority":1,"id":52385882,"name":"1 - 2"},{"status":"ACTIVE","sortPriority":2,"id":52385883,"name":"1 - 3"},{"status":"ACTIVE","sortPriority":3,"id":52385884,"name":"1 - 4"},{"status":"ACTIVE","sortPriority":4,"id":52385885,"name":"1 - 5"},{"status":"ACTIVE","sortPriority":5,"id":52385886,"name":"1 - 6"},{"status":"ACTIVE","sortPriority":6,"id":52385889,"name":"2 - 1"},{"status":"ACTIVE","sortPriority":7,"id":52385890,"name":"2 - 3"},{"status":"ACTIVE","sortPriority":8,"id":52385891,"name":"2 - 4"},{"status":"ACTIVE","sortPriority":9,"id":52385892,"name":"2 - 5"},{"status":"ACTIVE","sortPriority":10,"id":52385893,"name":"2 - 6"},{"status":"ACTIVE","sortPriority":11,"id":52385896,"name":"3 - 1"},{"status":"ACTIVE","sortPriority":12,"id":52385897,"name":"3 - 2"},{"status":"ACTIVE","sortPriority":13,"id":52385898,"name":"3 - 4"},{"status":"ACTIVE","sortPriority":14,"id":52385899,"name":"3 - 5"},{"status":"ACTIVE","sortPriority":15,"id":52385900,"name":"3 - 6"},{"status":"ACTIVE","sortPriority":16,"id":52385903,"name":"4 - 1"},{"status":"ACTIVE","sortPriority":17,"id":52385904,"name":"4 - 2"},{"status":"ACTIVE","sortPriority":18,"id":52385905,"name":"4 - 3"},{"status":"ACTIVE","sortPriority":19,"id":52385906,"name":"4 - 5"},{"status":"ACTIVE","sortPriority":20,"id":52385907,"name":"4 - 6"},{"status":"ACTIVE","sortPriority":21,"id":52385910,"name":"5 - 1"},{"status":"ACTIVE","sortPriority":22,"id":52385911,"name":"5 - 2"},{"status":"ACTIVE","sortPriority":23,"id":52385912,"name":"5 - 3"},{"status":"ACTIVE","sortPriority":24,"id":52385913,"name":"5 - 4"},{"status":"ACTIVE","sortPriority":25,"id":52385914,"name":"5 - 6"},{"status":"ACTIVE","sortPriority":26,"id":52385917,"name":"6 - 1"},{"status":"ACTIVE","sortPriority":27,"id":52385918,"name":"6 - 2"},{"status":"ACTIVE","sortPriority":28,"id":52385919,"name":"6 - 3"},{"status":"ACTIVE","sortPriority":29,"id":52385920,"name":"6 - 4"},{"status":"ACTIVE","sortPriority":30,"id":52385921,"name":"6 - 5"}],"regulators":["MR_INT"],"venue":"Perry Barr","countryCode":"GB","discountAllowed":true,"timezone":"Europe/London","openDate":"2024-06-27T13:29:00.000Z","version":5994794124,"name":"Forecast","eventName":"Perry Barr (F/C) 27th Jun"},"rc":[],"con":true,"img":false}]}
{"op":"mcm","clk":"11550298784","pt":1719496782387,"mc":[{"id":"1.230178173","rc":[{"atb":[[1.17,0]],"id":52385882}],"con":true,"img":false}]}
{"op":"mcm","clk":"11550320343","pt":1719497022474,"mc":[{"id":"1.230178173","rc":[{"atb":[[1.03,7.81],[1.02,114.29]],"id":52385910},{"atl":[[990,1.57]],"id":52385910},{"atb":[[1.03,7.81],[1.04,72.8]],"id":52385912},{"atl":[[990,1.23]],"id":52385912},{"atb":[[1.02,11.71],[1.04,90.58]],"id":52385906},{"atl":[[980,0.85]],"id":52385906},{"atb":[[1.03,7.81]],"id":52385918},{"atb":[[1.02,11.71]],"id":52385920},{"atb":[[1.01,329.55],[1.04,137.14]],"id":52385889},{"atl":[[970,1.75]],"id":52385889},{"atb":[[1.01,329.55],[1.04,151.54]],"id":52385914},{"atl":[[960,0.85]],"id":52385914},{"atb":[[1.03,7.81],[1.02,77.04]],"id":52385883},{"atl":[[960,1.31]],"id":52385883},{"atb":[[1.01,329.55],[1.02,73.65]],"id":52385885},{"atl":[[960,0.85]],"id":52385885},{"atb":[[1.03,7.81],[1.04,133.76]],"id":52385896},{"atl":[[970,0.85]],"id":52385896},{"atb":[[1.03,86.35],[1.02,11.71]],"id":52385890},{"atl":[[980,1.26]],"id":52385890},{"atb":[[1.01,329.55],[1.04,115.98]],"id":52385892},{"atl":[[980,0.85]],"id":52385892},{"atb":[[1.03,93.32]],"id":52385904},{"atl":[[990,1.98]],"id":52385904},{"atb":[[1.03,108.55]],"id":52385898},{"atl":[[990,0.88]],"id":52385898},{"atb":[[1.03,171.2],[1.17,0]],"id":52385900},{"atl":[[960,1.93]],"id":52385900},{"atb":[[1.02,95.52]],"id":52385911},{"atl":[[960,1.6]],"id":52385911},{"atb":[[1.03,136.49]],"id":52385913},{"atl":[[960,1.49]],"id":52385913},{"atb":[[1.02,112.46]],"id":52385907},{"atl":[[970,1.43]],"id":52385907},{"atb":[[1.03,7.81],[1.04,163.39]],"id":52385886},{"atl":[[970,1.1]],"id":52385886},{"atb":[[1.01,329.55]],"id":52385919},{"atb":[[1.01,329.55]],"id":52385921},{"atb":[[1.01,329.55],[1.02,106.67]],"id":52385882},{"atl":[[990,0.85]],"id":52385882},{"atb":[[1.02,87.06]],"id":52385884},{"atl":[[960,1.7]],"id":52385884},{"atb":[[1.01,329.55]],"id":52385917},{"atb":[[1.01,329.55],[1.04,103.28]],"id":52385897},{"atl":[[970,1.94]],"id":52385897},{"atb":[[1.02,11.71],[1.04,168.47]],"id":52385891},{"atl":[[980,1.1]],"id":52385891},{"atb":[[1.01,329.55],[1.02,100.74]],"id":52385893},{"atl":[[960,0.85]],"id":52385893},{"atb":[[1.01,329.55],[1.03,97.35]],"id":52385903},{"atl":[[990,1.81]],"id":52385903},{"atb":[[1.03,7.81],[1.04,89.73]],"id":52385905},{"atl":[[980,1.98]],"id":52385905},{"atb":[[1.02,11.71],[1.04,153.23]],"id":52385899},{"atl":[[960,1.91]],"id":52385899}],"con":true,"img":false}]}
{"op":"mcm","clk":"11550343142","pt":1719497272470,"mc":[{"id":"1.230178173","rc":[{"atb":[[1.17,0]],"id":52385898}],"con":true,"img":false}]}
{"op":"mcm","clk":"11550363167","pt":1719497522737,"mc":[{"id":"1.230178173","rc":[{"atb":[[1.17,0]],"id":52385914}],"con":true,"img":false}]}
{"op":"mcm","clk":"11550382857","pt":1719497762748,"mc":[{"id":"1.230178173","rc":[{"atb":[[1.17,0]],"id":52385913}],"con":true,"img":false}]}
{"op":"mcm","clk":"11550403090","pt":1719498003041,"mc":[{"id":"1.230178173","rc":[{"atb":[[1.17,0]],"id":52385919}],"con":true,"img":false}]}
{"op":"mcm","clk":"11550422587","pt":1719498252997,"mc":[{"id":"1.230178173","rc":[{"atb":[[1.17,0]],"id":52385910}],"con":true,"img":false}]}
{"op":"mcm","clk":"11550441848","pt":1719498503175,"mc":[{"id":"1.230178173","rc":[{"atb":[[1.17,0]],"id":52385907}],"con":true,"img":false}]}
{"op":"mcm","clk":"11550459720","pt":1719498743330,"mc":[{"id":"1.230178173","rc":[{"atb":[[1.17,0]],"id":52385911}],"con":true,"img":false}]}
{"op":"mcm","clk":"11550480307","pt":1719498983319,"mc":[{"id":"1.230178173","rc":[{"atb":[[1.17,0]],"id":52385920}],"con":true,"img":false}]}
{"op":"mcm","clk":"11550501505","pt":1719499183443,"mc":[{"id":"1.230178173","rc":[{"atb":[[1.17,0]],"id":52385918}],"con":true,"img":false}]}
{"op":"mcm","clk":"11550519188","pt":1719499413684,"mc":[{"id":"1.230178173","rc":[{"atb":[[1.17,0]],"id":52385905}],"con":true,"img":false}]}
{"op":"mcm","clk":"11550536173","pt":1719499643728,"mc":[{"id":"1.230178173","rc":[{"atb":[[1.17,0]],"id":52385906}],"con":true,"img":false}]}
{"op":"mcm","clk":"11550550002","pt":1719499836704,"mc":[{"id":"1.230178173","rc":[{"atb":[[2,10]],"id":52385884}],"con":true,"img":false}]}
{"op":"mcm","clk":"11550550102","pt":1719499838502,"mc":[{"id":"1.230178173","rc":[{"atb":[[3.5,50]],"id":52385884}],"con":true,"img":false}]}
{"op":"mcm","clk":"11550550452","pt":1719499843834,"mc":[{"id":"1.230178173","rc":[{"atb":[[3.5,0]],"id":52385884}],"con":true,"img":false}]}
{"op":"mcm","clk":"11550550698","pt":1719499847804,"mc":[{"id":"1.230178173","rc":[{"atb":[[2,0]],"id":52385884},{"trd":[[2,20]],"ltp":2.0,"tv":20.0,"id":52385884}],"con":true,"img":false}]}
{"op":"mcm","clk":"11550551171","pt":1719499854730,"mc":[{"id":"1.230178173","rc":[{"atb":[[1.03,8.81]],"id":52385910},{"atb":[[1.03,8.81]],"id":52385912},{"atb":[[1.03,1]],"id":52385906},{"atb":[[1.03,8.81]],"id":52385918},{"atb":[[1.03,1]],"id":52385920},{"atb":[[1.03,1]],"id":52385889},{"atb":[[1.03,1]],"id":52385914},{"atb":[[1.03,8.81]],"id":52385883},{"atb":[[1.03,1]],"id":52385885},{"atb":[[1.03,8.81]],"id":52385896},{"atb":[[1.03,87.35]],"id":52385890},{"atb":[[1.03,1]],"id":52385892},{"atb":[[1.03,94.32]],"id":52385904},{"atb":[[1.03,109.55]],"id":52385898},{"atb":[[1.03,172.2]],"id":52385900},{"atb":[[1.03,1]],"id":52385911},{"atb":[[1.03,137.49]],"id":52385913},{"atb":[[1.03,1]],"id":52385907},{"atb":[[1.03,8.81]],"id":52385886},{"atb":[[1.03,1]],"id":52385919},{"atb":[[1.03,1]],"id":52385921},{"atb":[[1.03,1]],"id":52385882},{"atb":[[1.03,1]],"id":52385884},{"atb":[[1.03,1]],"id":52385917},{"atb":[[1.03,1]],"id":52385897},{"atb":[[1.03,1]],"id":52385891},{"atb":[[1.03,1]],"id":52385893},{"atb":[[1.03,98.35]],"id":52385903},{"atb":[[1.03,8.81]],"id":52385905},{"atb":[[1.03,1]],"id":52385899}],"con":true,"img":false}]}
{"op":"mcm","clk":"11550551181","pt":1719499854935,"mc":[{"id":"1.230178173","rc":[{"atb":[[1.03,8.71]],"id":52385910},{"atb":[[1.03,8.71]],"id":52385912},{"atb":[[1.03,0.9]],"id":52385906},{"atb":[[1.03,8.71]],"id":52385918},{"atb":[[1.03,0.9]],"id":52385920},{"atb":[[1.03,0.9]],"id":52385889},{"atb":[[1.03,0.9]],"id":52385914},{"atb":[[1.03,8.71]],"id":52385883},{"atb":[[1.03,0.9]],"id":52385885},{"atb":[[1.03,8.71]],"id":52385896},{"atb":[[1.03,87.25]],"id":52385890},{"atb":[[1.03,0.9]],"id":52385892},{"atb":[[1.03,94.22]],"id":52385904},{"atb":[[1.03,109.45]],"id":52385898},{"atb":[[1.03,172.1]],"id":52385900},{"atb":[[1.03,0.9]],"id":52385911},{"atb":[[1.03,137.39]],"id":52385913},{"atb":[[1.03,0.9]],"id":52385907},{"atb":[[1.03,8.71]],"id":52385886},{"atb":[[1.03,0.9]],"id":52385919},{"atb":[[1.03,0.9]],"id":52385921},{"atb":[[1.03,0.9]],"id":52385882},{"atb":[[1.03,0.9]],"id":52385884},{"atb":[[1.03,0.9]],"id":52385917},{"atb":[[1.03,0.9]],"id":52385897},{"atb":[[1.03,0.9]],"id":52385891},{"atb":[[1.03,0.9]],"id":52385893},{"atb":[[1.03,98.25]],"id":52385903},{"atb":[[1.03,8.71]],"id":52385905},{"atb":[[1.03,0.9]],"id":52385899}],"con":true,"img":false}]}
{"op":"mcm","clk":"11550551197","pt":1719499855143,"mc":[{"id":"1.230178173","rc":[{"atb":[[1.03,7.81]],"id":52385910},{"atb":[[1.03,7.81]],"id":52385912},{"atb":[[1.03,0]],"id":52385906},{"atb":[[1.03,7.81]],"id":52385918},{"atb":[[1.03,0]],"id":52385920},{"atb":[[1.03,0]],"id":52385889},{"atb":[[1.03,0]],"id":52385914},{"atb":[[1.03,7.81]],"id":52385883},{"atb":[[1.03,0]],"id":52385885},{"atb":[[1.03,7.81]],"id":52385896},{"atb":[[1.03,86.35]],"id":52385890},{"atb":[[1.03,0]],"id":52385892},{"atb":[[1.03,93.32]],"id":52385904},{"atb":[[1.03,108.55]],"id":52385898},{"atb":[[1.03,171.2]],"id":52385900},{"atb":[[1.03,0]],"id":52385911},{"atb":[[1.03,136.49]],"id":52385913},{"atb":[[1.03,0]],"id":52385907},{"atb":[[1.03,7.81]],"id":52385886},{"atb":[[1.03,0]],"id":52385919},{"atb":[[1.03,0]],"id":52385921},{"atb":[[1.03,0]],"id":52385882},{"atb":[[1.03,0]],"id":52385884},{"atb":[[1.03,0]],"id":52385917},{"atb":[[1.03,0]],"id":52385897},{"atb":[[1.03,0]],"id":52385891},{"atb":[[1.03,0]],"id":52385893},{"atb":[[1.03,97.35]],"id":52385903},{"atb":[[1.03,7.81]],"id":52385905},{"atb":[[1.03,0]],"id":52385899}],"con":true,"img":false}]}
{"op":"mcm","clk":"11550551205","pt":1719499855246,"mc":[{"id":"1.230178173","rc":[{"atb":[[3.05,0.9]],"id":52385910},{"atb":[[3.05,0.9]],"id":52385912},{"atb":[[3.05,0.9]],"id":52385906},{"atb":[[3.05,0.9]],"id":52385918},{"atb":[[3.05,0.9]],"id":52385920},{"atb":[[3.05,0.9]],"id":52385889},{"atb":[[3.05,0.9]],"id":52385914},{"atb":[[3.05,0.9]],"id":52385883},{"atb":[[3.05,0.9]],"id":52385885},{"atb":[[3.05,0.9]],"id":52385896},{"atb":[[3.05,0.9]],"id":52385890},{"atb":[[3.05,0.9]],"id":52385892},{"atb":[[3.05,0.9]],"id":52385904},{"atb":[[3.05,0.9]],"id":52385898},{"atb":[[3.05,0.9]],"id":52385900},{"atb":[[3.05,0.9]],"id":52385911},{"atb":[[3.05,0.9]],"id":52385913},{"atb":[[3.05,0.9]],"id":52385907},{"atb":[[3.05,0.9]],"id":52385886},{"atb":[[3.05,0.9]],"id":52385919},{"atb":[[3.05,0.9]],"id":52385921},{"atb":[[3.05,0.9]],"id":52385882},{"atb":[[3.05,0.9]],"id":52385884},{"atb":[[3.05,0.9]],"id":52385917},{"atb":[[3.05,0.9]],"id":52385897},{"atb":[[3.05,0.9]],"id":52385891},{"atb":[[3.05,0.9]],"id":52385893},{"atb":[[3.05,0.9]],"id":52385903},{"atb":[[3.05,0.9]],"id":52385905},{"atb":[[3.05,0.9]],"id":52385899}],"con":true,"img":false}]}
{"op":"mcm","clk":"11550551508","pt":1719499860145,"mc":[{"id":"1.230178173","rc":[{"atb":[[2,11.9]],"id":52385903}],"con":true,"img":false}]}
{"op":"mcm","clk":"11550551516","pt":1719499860251,"mc":[{"id":"1.230178173","rc":[{"atb":[[3.5,50]],"id":52385903}],"con":true,"img":false}]}
{"op":"mcm","clk":"11550551834","pt":1719499865736,"mc":[{"id":"1.230178173","rc":[{"atb":[[3.5,0]],"id":52385903}],"con":true,"img":false}]}
{"op":"mcm","clk":"11550552231","pt":1719499872173,"mc":[{"id":"1.230178173","rc":[{"atb":[[2,0.9],[3.05,0]],"id":52385903},{"trd":[[2,22],[3.05,1.8]],"ltp":2.0,"tv":23.8,"id":52385903}],"con":true,"img":false}]}
{"op":"mcm","clk":"11550552306","pt":1719499873771,"mc":[{"id":"1.230178173","rc":[{"atb":[[1.17,0]],"id":52385912}],"con":true,"img":false}]}
{"op":"mcm","clk":"11550552479","pt":1719499877165,"mc":[{"id":"1.230178173","rc":[{"atb":[[2,0]],"id":52385903}],"con":true,"img":false}]}
{"op":"mcm","clk":"11550552684","pt":1719499880674,"mc":[{"id":"1.230178173","rc":[{"atb":[[3.05,0]],"id":52385910},{"atb":[[3.05,0]],"id":52385912},{"atb":[[3.05,0]],"id":52385906},{"atb":[[3.05,0]],"id":52385918},{"atb":[[3.05,0]],"id":52385920},{"atb":[[3.05,0]],"id":52385889},{"atb":[[3.05,0]],"id":52385914},{"atb":[[3.05,0]],"id":52385883},{"atb":[[3.05,0]],"id":52385885},{"atb":[[3.05,0]],"id":52385896},{"atb":[[3.05,0]],"id":52385890},{"atb":[[3.05,0]],"id":52385892},{"atb":[[3.05,0]],"id":52385904},{"atb":[[3.05,0]],"id":52385898},{"atb":[[3.05,0]],"id":52385900},{"atb":[[3.05,0]],"id":52385911},{"atb":[[3.05,0]],"id":52385913},{"atb":[[3.05,0]],"id":52385907},{"atb":[[3.05,0]],"id":52385886},{"atb":[[3.05,0]],"id":52385919},{"atb":[[3.05,0]],"id":52385921},{"atb":[[3.05,0]],"id":52385882},{"atb":[[3.05,0]],"id":52385884},{"atb":[[3.05,0]],"id":52385917},{"atb":[[3.05,0]],"id":52385897},{"atb":[[3.05,0]],"id":52385891},{"atb":[[3.05,0]],"id":52385893},{"atb":[[3.05,0]],"id":52385905},{"atb":[[3.05,0]],"id":52385899}],"con":true,"img":false}]}
{"op":"mcm","clk":"11550552809","pt":1719499882484,"mc":[{"id":"1.230178173","rc":[{"atb":[[1.03,8.81]],"id":52385910},{"atb":[[1.03,8.81]],"id":52385912},{"atb":[[1.03,1]],"id":52385906},{"atb":[[1.03,8.81]],"id":52385918},{"atb":[[1.03,1]],"id":52385920},{"atb":[[1.03,1]],"id":52385889},{"atb":[[1.03,1]],"id":52385914},{"atb":[[1.03,8.81]],"id":52385883},{"atb":[[1.03,1]],"id":52385885},{"atb":[[1.03,8.81]],"id":52385896},{"atb":[[1.03,87.35]],"id":52385890},{"atb":[[1.03,1]],"id":52385892},{"atb":[[1.03,94.32]],"id":52385904},{"atb":[[1.03,109.55]],"id":52385898},{"atb":[[1.03,172.2]],"id":52385900},{"atb":[[1.03,1]],"id":52385911},{"atb":[[1.03,137.49]],"id":52385913},{"atb":[[1.03,1]],"id":52385907},{"atb":[[1.03,8.81]],"id":52385886},{"atb":[[1.03,1]],"id":52385919},{"atb":[[1.03,1]],"id":52385921},{"atb":[[1.03,1]],"id":52385882},{"atb":[[1.03,1]],"id":52385884},{"atb":[[1.03,1]],"id":52385917},{"atb":[[1.03,1]],"id":52385897},{"atb":[[1.03,1]],"id":52385891},{"atb":[[1.03,1]],"id":52385893},{"atb":[[1.03,98.35]],"id":52385903},{"atb":[[1.03,8.81]],"id":52385905},{"atb":[[1.03,1]],"id":52385899}],"con":true,"img":false}]}
{"op":"mcm","clk":"11550552869","pt":1719499883254,"mc":[{"id":"1.230178173","rc":[{"atb":[[1.03,8.71]],"id":52385910},{"atb":[[1.03,8.71]],"id":52385912},{"atb":[[1.03,0.9]],"id":52385906},{"atb":[[1.03,8.71]],"id":52385918},{"atb":[[1.03,0.9]],"id":52385920},{"atb":[[1.03,0.9]],"id":52385889},{"atb":[[1.03,0.9]],"id":52385914},{"atb":[[1.03,8.71]],"id":52385883},{"atb":[[1.03,0.9]],"id":52385885},{"atb":[[1.03,8.71]],"id":52385896},{"atb":[[1.03,87.25]],"id":52385890},{"atb":[[1.03,0.9]],"id":52385892},{"atb":[[1.03,94.22]],"id":52385904},{"atb":[[1.03,109.45]],"id":52385898},{"atb":[[1.03,172.1]],"id":52385900},{"atb":[[1.03,0.9]],"id":52385911},{"atb":[[1.03,137.39]],"id":52385913},{"atb":[[1.03,0.9]],"id":52385907},{"atb":[[1.03,8.71]],"id":52385886},{"atb":[[1.03,0.9]],"id":52385919},{"atb":[[1.03,0.9]],"id":52385921},{"atb":[[1.03,0.9]],"id":52385882},{"atb":[[1.03,0.9]],"id":52385884},{"atb":[[1.03,0.9]],"id":52385917},{"atb":[[1.03,0.9]],"id":52385897},{"atb":[[1.03,0.9]],"id":52385891},{"atb":[[1.03,0.9]],"id":52385893},{"atb":[[1.03,98.25]],"id":52385903},{"atb":[[1.03,8.71]],"id":52385905},{"atb":[[1.03,0.9]],"id":52385899}],"con":true,"img":false}]}
{"op":"mcm","clk":"11550552883","pt":1719499883464,"mc":[{"id":"1.230178173","rc":[{"atb":[[1.03,7.81]],"id":52385910},{"atb":[[1.03,7.81]],"id":52385912},{"atb":[[1.03,0]],"id":52385906},{"atb":[[1.03,7.81]],"id":52385918},{"atb":[[1.03,0]],"id":52385920},{"atb":[[1.03,0]],"id":52385889},{"atb":[[1.03,0]],"id":52385914},{"atb":[[1.03,7.81]],"id":52385883},{"atb":[[1.03,0]],"id":52385885},{"atb":[[1.03,7.81]],"id":52385896},{"atb":[[1.03,86.35]],"id":52385890},{"atb":[[1.03,0]],"id":52385892},{"atb":[[1.03,93.32]],"id":52385904},{"atb":[[1.03,108.55]],"id":52385898},{"atb":[[1.03,171.2]],"id":52385900},{"atb":[[1.03,0]],"id":52385911},{"atb":[[1.03,136.49]],"id":52385913},{"atb":[[1.03,0]],"id":52385907},{"atb":[[1.03,7.81]],"id":52385886},{"atb":[[1.03,0]],"id":52385919},{"atb":[[1.03,0]],"id":52385921},{"atb":[[1.03,0]],"id":52385882},{"atb":[[1.03,0]],"id":52385884},{"atb":[[1.03,0]],"id":52385917},{"atb":[[1.03,0]],"id":52385897},{"atb":[[1.03,0]],"id":52385891},{"atb":[[1.03,0]],"id":52385893},{"atb":[[1.03,97.35]],"id":52385903},{"atb":[[1.03,7.81]],"id":52385905},{"atb":[[1.03,0]],"id":52385899}],"con":true,"img":false}]}
{"op":"mcm","clk":"11550552891","pt":1719499883567,"mc":[{"id":"1.230178173","rc":[{"atb":[[3.05,0.9]],"id":52385910},{"atb":[[3.05,0.9]],"id":52385912},{"atb":[[3.05,0.9]],"id":52385906},{"atb":[[3.05,0.9]],"id":52385918},{"atb":[[3.05,0.9]],"id":52385920},{"atb":[[3.05,0.9]],"id":52385889},{"atb":[[3.05,0.9]],"id":52385914},{"atb":[[3.05,0.9]],"id":52385883},{"atb":[[3.05,0.9]],"id":52385885},{"atb":[[3.05,0.9]],"id":52385896},{"atb":[[3.05,0.9]],"id":52385890},{"atb":[[3.05,0.9]],"id":52385892},{"atb":[[3.05,0.9]],"id":52385904},{"atb":[[3.05,0.9]],"id":52385898},{"atb":[[3.05,0.9]],"id":52385900},{"atb":[[3.05,0.9]],"id":52385911},{"atb":[[3.05,0.9]],"id":52385913},{"atb":[[3.05,0.9]],"id":52385907},{"atb":[[3.05,0.9]],"id":52385886},{"atb":[[3.05,0.9]],"id":52385919},{"atb":[[3.05,0.9]],"id":52385921},{"atb":[[3.05,0.9]],"id":52385882},{"atb":[[3.05,0.9]],"id":52385884},{"atb":[[3.05,0.9]],"id":52385917},{"atb":[[3.05,0.9]],"id":52385897},{"atb":[[3.05,0.9]],"id":52385891},{"atb":[[3.05,0.9]],"id":52385893},{"atb":[[3.05,0.9]],"id":52385903},{"atb":[[3.05,0.9]],"id":52385905},{"atb":[[3.05,0.9]],"id":52385899}],"con":true,"img":false}]}
{"op":"mcm","clk":"11550554023","pt":1719499902866,"mc":[{"id":"1.230178173","rc":[{"atb":[[1.19,1.11]],"id":52385884},{"atb":[[1.19,1.16]],"id":52385903}],"con":true,"img":false}]}
{"op":"mcm","clk":"11550554066","pt":1719499903485,"mc":[{"id":"1.230178173","rc":[{"atl":[[960,1.17]],"id":52385919}],"con":true,"img":false}]}
{"op":"mcm","clk":"11550554107","pt":1719499904104,"mc":[{"id":"1.230178173","rc":[{"atl":[[960,2.73]],"id":52385917}],"con":true,"img":false}]}
{"op":"mcm","clk":"11550554147","pt":1719499904672,"mc":[{"id":"1.230178173","rc":[{"atb":[[1.04,209.95]],"id":52385920}],"con":true,"img":false}]}
{"op":"mcm","clk":"11550554184","pt":1719499905295,"mc":[{"id":"1.230178173","rc":[{"atl":[[960,2.53]],"id":52385918}],"con":true,"img":false}]}
{"op":"mcm","clk":"11550554231","pt":1719499905907,"mc":[{"id":"1.230178173","rc":[{"atl":[[980,1.23]],"id":52385920}],"con":true,"img":false}]}
{"op":"mcm","clk":"11550554265","pt":1719499906483,"mc":[{"id":"1.230178173","rc":[{"atb":[[1.03,207.41]],"id":52385917}],"con":true,"img":false}]}
{"op":"mcm","clk":"11550554310","pt":1719499907104,"mc":[{"id":"1.230178173","rc":[{"atl":[[960,1.54]],"id":52385921}],"con":true,"img":false}]}
{"op":"mcm","clk":"11550554356","pt":1719499907671,"mc":[{"id":"1.230178173","rc":[{"atb":[[1.02,105.82]],"id":52385919}],"con":true,"img":false}]}
{"op":"mcm","clk":"11550561418","pt":1719500020520,"mc":[{"id":"1.230178173","rc":[{"atb":[[1.03,131.41]],"id":52385918}],"con":true,"img":false}]}
{"op":"mcm","clk":"11550566065","pt":1719500093820,"mc":[{"id":"1.230178173","rc":[{"atb":[[1.17,0]],"id":52385917}],"con":true,"img":false}]}
{"op":"mcm","clk":"11550566097","pt":1719500094231,"mc":[{"id":"1.230178173","rc":[{"atb":[[1.02,160.85]],"id":52385921}],"con":true,"img":false}]}
{"op":"mcm","clk":"11550583505","pt":1719500333997,"mc":[{"id":"1.230178173","rc":[{"atb":[[1.17,0]],"id":52385921}],"con":true,"img":false}]}
{"op":"mcm","clk":"11550677022","pt":1719501724298,"mc":[{"id":"1.230178173","rc":[{"atb":[[1.03,7.81],[1.02,114.3],[13,8]],"id":52385910},{"atl":[[990,1.57]],"id":52385910},{"atb":[[1.03,7.81],[12,8],[1.04,72.81]],"id":52385912},{"atl":[[990,1.23]],"id":52385912},{"atb":[[1.02,11.71],[12,8],[1.04,90.6]],"id":52385906},{"atl":[[980,0.85]],"id":52385906},{"atb":[[19,5],[1.03,131.43]],"id":52385918},{"atl":[[960,2.54]],"id":52385918},{"atb":[[18,5],[1.02,11.71],[1.04,209.99]],"id":52385920},{"atl":[[980,1.23]],"id":52385920},{"atb":[[1.01,329.55],[12,8],[1.04,137.17]],"id":52385889},{"atl":[[970,1.75]],"id":52385889},{"atb":[[1.01,329.55],[11,9],[1.04,151.56]],"id":52385914},{"atl":[[960,0.85]],"id":52385914},{"atb":[[18,5],[1.03,7.81],[1.02,77.05]],"id":52385883},{"atl":[[960,1.31]],"id":52385883},{"atb":[[18,5],[1.01,329.55],[1.02,73.66]],"id":52385885},{"atl":[[960,0.85]],"id":52385885},{"atb":[[1.03,7.81],[1.04,133.78],[15,6]],"id":52385896},{"atl":[[970,0.85]],"id":52385896},{"atb":[[1.03,86.36],[1.02,11.71],[15,6]],"id":52385890},{"atl":[[980,1.27]],"id":52385890},{"atb":[[1.01,329.55],[13,8],[1.04,116]],"id":52385892},{"atl":[[980,0.85]],"id":52385892},{"atb":[[1.03,93.33],[14,7]],"id":52385904},{"atl":[[990,1.98]],"id":52385904},{"atb":[[1.03,108.57],[12,8]],"id":52385898},{"atl":[[990,0.88]],"id":52385898},{"atb":[[16,6],[1.03,171.23]],"id":52385900},{"atl":[[960,1.93]],"id":52385900},{"atb":[[1.02,95.54],[12,8]],"id":52385911},{"atl":[[960,1.6]],"id":52385911},{"atb":[[1.03,136.51],[11,9]],"id":52385913},{"atl":[[960,1.49]],"id":52385913},{"atb":[[17,6],[1.02,112.48]],"id":52385907},{"atl":[[970,1.43]],"id":52385907},{"atb":[[1.03,7.81],[20,5],[1.04,163.42]],"id":52385886},{"atl":[[970,1.1]],"id":52385886},{"atb":[[1.01,329.55],[20,5],[1.02,105.84]],"id":52385919},{"atl":[[960,1.17]],"id":52385919},{"atb":[[1.01,329.55],[1.02,160.88],[15,6]],"id":52385921},{"atl":[[960,1.54]],"id":52385921},{"atb":[[1.01,329.55],[1.02,106.68],[13,8]],"id":52385882},{"atl":[[990,0.85]],"id":52385882},{"atb":[[20,5],[1.19,1.11],[1.02,87.07]],"id":52385884},{"atl":[[960,1.7]],"id":52385884},{"atb":[[1.01,329.55],[1.03,207.45],[20,5]],"id":52385917},{"atl":[[960,2.73]],"id":52385917},{"atb":[[1.01,329.55],[12,8],[1.04,103.3]],"id":52385897},{"atl":[[970,1.94]],"id":52385897},{"atb":[[1.02,11.71],[14,7],[1.04,168.5]],"id":52385891},{"atl":[[980,1.1]],"id":52385891},{"atb":[[17,6],[1.01,329.55],[1.02,100.76]],"id":52385893},{"atl":[[960,0.85]],"id":52385893},{"atb":[[1.01,329.55],[1.03,97.37],[1.19,1.16],[15,6]],"id":52385903},{"atl":[[990,1.81]],"id":52385903},{"atb":[[1.03,7.81],[1.04,89.75],[15,6]],"id":52385905},{"atl":[[980,1.98]],"id":52385905},{"atb":[[1.02,11.71],[13,8],[1.04,153.25]],"id":52385899},{"atl":[[960,1.91]],"id":52385899}],"con":true,"img":false}]}
{"op":"mcm","clk":"11550677087","pt":1719501725324,"mc":[{"id":"1.230178173","rc":[{"atb":[[10.5,11.12]],"id":52385906},{"atb":[[13,11.24]],"id":52385904},{"atb":[[17,11.12]],"id":52385898},{"atb":[[16.5,9.98]],"id":52385905}],"con":true,"img":false}]}
{"op":"mcm","clk":"11550677096","pt":1719501725429,"mc":[{"id":"1.230178173","rc":[{"atb":[[9.8,13.12]],"id":52385913},{"atb":[[12.5,10.12]],"id":52385891},{"atb":[[18,3.72]],"id":52385903},{"atb":[[16.5,0]],"id":52385905}],"con":true,"img":false}]}
{"op":"mcm","clk":"11550677102","pt":1719501725529,"mc":[{"id":"1.230178173","rc":[{"atb":[[10.5,0]],"id":52385906},{"atb":[[13,0]],"id":52385904},{"atb":[[17,0]],"id":52385898}],"con":true,"img":false}]}
{"op":"mcm","clk":"11550677108","pt":1719501725633,"mc":[{"id":"1.230178173","rc":[{"atb":[[9.8,0]],"id":52385913},{"atb":[[12.5,0]],"id":52385891},{"atb":[[18,0]],"id":52385903}],"con":true,"img":false}]}
{"op":"mcm","clk":"11550687701","pt":1719501917158,"mc":[{"id":"1.230178173","rc":[{"atb":[[14.5,11.96]],"id":52385910},{"atb":[[16.5,7.38]],"id":52385885},{"atb":[[20,8.62]],"id":52385896},{"atb":[[18,11.12]],"id":52385898},{"atb":[[18,11.12]],"id":52385882},{"atb":[[19.5,3.53]],"id":52385884},{"atb":[[17.5,9.98]],"id":52385905}],"con":true,"img":false}]}
{"op":"mcm","clk":"11550687833","pt":1719501919333,"mc":[{"id":"1.230178173","rc":[{"atb":[[14.5,0]],"id":52385910},{"atb":[[16.5,0]],"id":52385885},{"atb":[[20,0]],"id":52385896},{"atb":[[18,0]],"id":52385898},{"atb":[[18,0]],"id":52385882},{"atb":[[19.5,0]],"id":52385884},{"atb":[[17.5,0]],"id":52385905}],"con":true,"img":false}]}
{"op":"mcm","clk":"11550690461","pt":1719501960590,"mc":[{"id":"1.230178173","rc":[{"atb":[[4.3,30.3]],"id":52385911},{"atl":[[350,2]],"id":52385911}],"con":true,"img":false}]}
{"op":"mcm","clk":"11550690468","pt":1719501960697,"mc":[{"id":"1.230178173","rc":[{"atb":[[5.6,16]],"id":52385910},{"atl":[[480,2]],"id":52385910},{"atb":[[4.9,25.64]],"id":52385912},{"atl":[[430,2]],"id":52385912},{"atb":[[5,25]],"id":52385906},{"atl":[[440,2]],"id":52385906},{"atb":[[11.5,9.52]],"id":52385918},{"atl":[[780,2]],"id":52385918},{"atb":[[18.5,5]],"id":52385920},{"atl":[[970,2]],"id":52385920},{"atb":[[5.6,21.74]],"id":52385889},{"atl":[[490,2]],"id":52385889},{"atb":[[8,14.29]],"id":52385914},{"atl":[[560,2]],"id":52385914},{"atb":[[9.6,10]],"id":52385883},{"atl":[[670,2]],"id":52385883},{"atb":[[8.2,13.89]],"id":52385885},{"atl":[[570,2]],"id":52385885},{"atb":[[8.2,13.89]],"id":52385896},{"atl":[[560,2]],"id":52385896},{"atb":[[5.1,24.39]],"id":52385890},{"atl":[[450,2]],"id":52385890},{"atb":[[4.5,28.57]],"id":52385892},{"atl":[[370,2]],"id":52385892},{"atb":[[5.4,22.73]],"id":52385904},{"atl":[[480,2]],"id":52385904},{"atb":[[8.6,13.16]],"id":52385898},{"atl":[[590,2]],"id":52385898},{"atb":[[12,9.09]],"id":52385900},{"atl":[[800,2]],"id":52385900},{"atb":[[5.5,22.22]],"id":52385913},{"atl":[[480,2]],"id":52385913},{"atb":[[11,10]],"id":52385907},{"atl":[[770,2]],"id":52385907},{"atb":[[21,5]],"id":52385886},{"atl":[[970,3.1]],"id":52385886},{"atb":[[17.5,6.06]],"id":52385919},{"atl":[[890,2]],"id":52385919},{"atb":[[9.8,11.36]],"id":52385921},{"atl":[[670,2]],"id":52385921},{"atb":[[7.8,14.71]],"id":52385882},{"atl":[[550,2]],"id":52385882},{"atb":[[12.5,8.7]],"id":52385884},{"atl":[[800,2]],"id":52385884},{"atb":[[21,5]],"id":52385917},{"atl":[[960,4.73]],"id":52385917},{"atb":[[5.2,23.81]],"id":52385897},{"atl":[[470,2]],"id":52385897},{"atb":[[6.6,17.86]],"id":52385891},{"atl":[[520,2]],"id":52385891},{"atb":[[9.6,11.63]],"id":52385893},{"atl":[[650,2]],"id":52385893},{"atb":[[8.2,12]],"id":52385903},{"atl":[[570,2]],"id":52385903},{"atb":[[6.8,17.24]],"id":52385905},{"atl":[[530,2]],"id":52385905},{"atb":[[5.1,24.39]],"id":52385899},{"atl":[[460,2]],"id":52385899}],"con":true,"img":false}]}
{"op":"mcm","clk":"11550690740","pt":1719501965322,"mc":[{"id":"1.230178173","rc":[{"atl":[[450,2],[480,0]],"id":52385910},{"atl":[[410,2],[430,0]],"id":52385912},{"atl":[[420,2],[440,0]],"id":52385906},{"atl":[[710,2],[780,0]],"id":52385918},{"atl":[[870,2],[970,0]],"id":52385920},{"atl":[[450,2],[490,0]],"id":52385889},{"atb":[[8,0],[8.4,13.51]],"id":52385914},{"atl":[[530,2],[560,0]],"id":52385914},{"atl":[[620,2],[670,0]],"id":52385883},{"atl":[[540,2],[570,0]],"id":52385885},{"atl":[[540,2],[560,0]],"id":52385896},{"atl":[[450,0]],"id":52385890},{"atl":[[340,2],[370,0]],"id":52385892},{"atl":[[450,2],[480,0]],"id":52385904},{"atb":[[8.6,0],[9,12.5]],"id":52385898},{"atl":[[550,2],[590,0]],"id":52385898},{"atb":[[12,0],[13,8.33]],"id":52385900},{"atl":[[720,2],[800,0]],"id":52385900},{"atl":[[310,2],[350,0]],"id":52385911},{"atl":[[450,2]],"id":52385913},{"atl":[[700,2]],"id":52385907},{"atl":[[890,2],[970,1.1]],"id":52385886},{"atb":[[17.5,0],[18.5,5.71]],"id":52385919},{"atl":[[800,2],[890,0]],"id":52385919},{"atl":[[620,2]],"id":52385921},{"atl":[[530,2],[550,0]],"id":52385882},{"atl":[[730,2],[800,0]],"id":52385884},{"atl":[[870,2]],"id":52385917},{"atl":[[440,2]],"id":52385897},{"atl":[[520,0],[490,2]],"id":52385891},{"atl":[[610,2],[650,0]],"id":52385893},{"atl":[[540,2],[570,0]],"id":52385903},{"atl":[[530,0],[500,2]],"id":52385905},{"atl":[[430,2],[460,0]],"id":52385899}],"con":true,"img":false}]}
{"op":"mcm","clk":"11550690745","pt":1719501965368,"mc":[{"id":"1.230178173","rc":[{"atl":[[430,2]],"id":52385890},{"atl":[[480,0]],"id":52385913},{"atl":[[670,0]],"id":52385921},{"atl":[[960,2.73]],"id":52385917},{"atl":[[470,0]],"id":52385897}],"con":true,"img":false}]}
{"op":"mcm","clk":"11550690752","pt":1719501965474,"mc":[{"id":"1.230178173","rc":[{"atl":[[770,0]],"id":52385907}],"con":true,"img":false}]}
{"op":"mcm","clk":"11550691014","pt":1719501970283,"mc":[{"id":"1.230178173","rc":[{"atb":[[12,0]],"id":52385889},{"atb":[[15,0]],"id":52385890},{"atb":[[13,0]],"id":52385892},{"atb":[[14,0]],"id":52385904},{"atb":[[12,0]],"id":52385911},{"atb":[[14,0]],"id":52385891}],"con":true,"img":false}]}
{"op":"mcm","clk":"11550691021","pt":1719501970385,"mc":[{"id":"1.230178173","rc":[{"atb":[[5.6,0],[10,8],[2.98,50.51]],"id":52385889},{"atb":[[5.1,0],[2.88,53.19],[13,6]],"id":52385890},{"atb":[[4.5,0],[2.74,57.47],[11,8]],"id":52385892},{"atb":[[13,7],[2.94,51.55],[5.4,0]],"id":52385904},{"atb":[[4.3,0],[11,8],[2.7,58.82]],"id":52385911},{"atb":[[12,7],[3.25,44.44],[6.6,0]],"id":52385891}],"con":true,"img":false}]}
{"op":"mcm","clk":"11550691075","pt":1719501971320,"mc":[{"id":"1.230178173","rc":[{"atl":[[450,0],[480,2]],"id":52385910},{"atl":[[410,0],[430,2]],"id":52385912},{"atl":[[420,0],[440,2]],"id":52385906},{"atl":[[710,0],[780,2]],"id":52385918},{"atl":[[870,0],[970,2]],"id":52385920},{"atl":[[450,0],[490,2]],"id":52385889},{"atl":[[530,0],[560,2]],"id":52385914},{"atl":[[620,0],[670,2]],"id":52385883},{"atl":[[540,0],[570,2]],"id":52385885},{"atl":[[540,0],[560,2]],"id":52385896},{"atl":[[430,0],[450,2]],"id":52385890},{"atl":[[340,0],[370,2]],"id":52385892},{"atl":[[450,0],[480,2]],"id":52385904},{"atl":[[550,0],[590,2]],"id":52385898},{"atl":[[720,0],[800,2]],"id":52385900},{"atl":[[310,0],[350,2]],"id":52385911},{"atl":[[450,0],[480,2]],"id":52385913},{"atl":[[700,0],[770,2]],"id":52385907},{"atl":[[890,0],[970,3.1]],"id":52385886},{"atl":[[800,0],[890,2]],"id":52385919},{"atl":[[620,0],[670,2]],"id":52385921},{"atl":[[530,0],[550,2]],"id":52385882},{"atl":[[730,0],[800,2]],"id":52385884},{"atl":[[870,0],[960,4.73]],"id":52385917},{"atl":[[440,0],[470,2]],"id":52385897},{"atl":[[520,2],[490,0]],"id":52385891},{"atl":[[610,0],[650,2]],"id":52385893},{"atl":[[540,0],[570,2]],"id":52385903},{"atl":[[530,2],[500,0]],"id":52385905},{"atl":[[430,0],[460,2]],"id":52385899}],"con":true,"img":false}]}
{"op":"mcm","clk":"11550691126","pt":1719501972404,"mc":[{"id":"1.230178173","rc":[{"atb":[[18,0]],"id":52385920},{"atb":[[13,0]],"id":52385882},{"atb":[[12,0]],"id":52385897}],"con":true,"img":false}]}
{"op":"mcm","clk":"11550691130","pt":1719501972507,"mc":[{"id":"1.230178173","rc":[{"atb":[[18.5,0],[20,5],[7.4,15.62]],"id":52385920},{"atb":[[12,8],[3.55,39.22],[7.8,0]],"id":52385882},{"atb":[[11,8],[5.2,0]],"id":52385897}],"con":true,"img":false}]}
{"op":"mcm","clk":"11550691134","pt":1719501972612,"mc":[{"id":"1.230178173","rc":[{"atb":[[21,5]],"id":52385920},{"atb":[[8.2,13.89],[3.55,0]],"id":52385882},{"atb":[[2.9,52.63]],"id":52385897}],"con":true,"img":false}]}
{"op":"mcm","clk":"11550691141","pt":1719501972714,"mc":[{"id":"1.230178173","rc":[{"atb":[[7.4,0]],"id":52385920}],"con":true,"img":false}]}
{"op":"mcm","clk":"11550691569","pt":1719501980228,"mc":[{"id":"1.230178173","rc":[{"atb":[[13,0]],"id":52385890},{"atb":[[11,0]],"id":52385892},{"atb":[[13,0]],"id":52385904},{"atb":[[12,0]],"id":52385891}],"con":true,"img":false}]}
{"op":"mcm","clk":"11550691579","pt":1719501980332,"mc":[{"id":"1.230178173","rc":[{"atb":[[12,6]],"id":52385890},{"atb":[[10,8]],"id":52385892},{"atb":[[12,7]],"id":52385904},{"atb":[[11,7]],"id":52385891}],"con":true,"img":false}]}
{"op":"mcm","clk":"11550691588","pt":1719501980429,"mc":[{"id":"1.230178173","rc":[{"atb":[[2.98,0],[5.9,20.41]],"id":52385889},{"atb":[[2.88,0],[5.4,22.73]],"id":52385890},{"atb":[[2.74,0],[4.7,27.03]],"id":52385892},{"atb":[[4.5,28.57]],"id":52385911},{"atb":[[3.25,0],[7,16.67]],"id":52385891}],"con":true,"img":false}]}
{"op":"mcm","clk":"11550691597","pt":1719501980537,"mc":[{"id":"1.230178173","rc":[{"atb":[[5.7,21.28],[2.94,0]],"id":52385904},{"atb":[[2.7,0]],"id":52385911}],"con":true,"img":false}]}
{"op":"mcm","clk":"11550691603","pt":1719501980650,"mc":[{"id":"1.230178173","rc":[{"atb":[[5.6,0],[6.4,16]],"id":52385910},{"atb":[[5.8,20.83]],"id":52385912},{"atb":[[5,0],[5.5,22.22]],"id":52385906},{"atb":[[11.5,0],[13.5,8]],"id":52385918},{"atb":[[8.4,0],[9.4,11.9]],"id":52385914},{"atb":[[9.6,0],[11,10]],"id":52385883},{"atb":[[8.2,0],[9.4,11.9]],"id":52385885},{"atl":[[540,2],[570,0]],"id":52385885},{"atb":[[9.6,11.63],[8.2,0]],"id":52385896},{"atl":[[440,2],[450,0]],"id":52385890},{"atb":[[5.2,23.81],[4.7,0]],"id":52385892},{"atb":[[9,0],[9.4,11.9]],"id":52385898},{"atb":[[13,0],[14.5,7.41]],"id":52385900},{"atb":[[5.5,0],[6,20]],"id":52385913},{"atb":[[11,0],[13.5,8]],"id":52385907},{"atl":[[930,2],[970,1.1]],"id":52385886},{"atb":[[18.5,0],[20,10]],"id":52385919},{"atb":[[11.5,9.52],[9.8,0]],"id":52385921},{"atb":[[12.5,0],[14,7.69]],"id":52385884},{"atb":[[8,14.29],[7,0]],"id":52385891},{"atb":[[9.6,0],[11.5,9.52]],"id":52385893},{"atb":[[8.2,0],[9.8,11.36]],"id":52385903},{"atb":[[8.4,13.51]],"id":52385905},{"atb":[[5.6,21.74],[5.1,0]],"id":52385899}],"con":true,"img":false}]}
{"op":"mcm","clk":"11550691611","pt":1719501980694,"mc":[{"id":"1.230178173","rc":[{"atb":[[4.9,0]],"id":52385912},{"atb":[[6,20],[5.4,0]],"id":52385890},{"atb":[[10.5,10.53]],"id":52385898},{"atb":[[4.5,0],[5.1,24.39]],"id":52385911},{"atl":[[920,2],[930,0]],"id":52385886},{"atb":[[20,5]],"id":52385919},{"atb":[[6.8,0]],"id":52385905}],"con":true,"img":false}]}
{"op":"mcm","clk":"11550691618","pt":1719501980794,"mc":[{"id":"1.230178173","rc":[{"atb":[[6,20]],"id":52385919}],"con":true,"img":false}]}
{"op":"mcm","clk":"11550691625","pt":1719501980899,"mc":[{"id":"1.230178173","rc":[{"atb":[[9.4,0]],"id":52385898}],"con":true,"img":false}]}
{"op":"mcm","clk":"11550691653","pt":1719501981314,"mc":[{"id":"1.230178173","rc":[{"atl":[[460,2],[480,0]],"id":52385910},{"atl":[[430,0],[420,2]],"id":52385912},{"atl":[[430,2],[440,0]],"id":52385906},{"atl":[[740,2],[780,0]],"id":52385918},{"atl":[[910,2],[970,0]],"id":52385920},{"atl":[[460,2],[490,0]],"id":52385889},{"atl":[[540,2],[560,0]],"id":52385914},{"atl":[[620,2],[670,0]],"id":52385883},{"atl":[[540,2],[560,0]],"id":52385896},{"atl":[[360,2],[370,0]],"id":52385892},{"atl":[[470,2],[480,0]],"id":52385904},{"atl":[[590,0],[580,2]],"id":52385898},{"atl":[[760,2],[800,0]],"id":52385900},{"atl":[[350,0],[340,2]],"id":52385911},{"atl":[[470,2],[480,0]],"id":52385913},{"atl":[[730,2],[770,0]],"id":52385907},{"atl":[[830,2],[890,0]],"id":52385919},{"atl":[[670,0],[640,2]],"id":52385921},{"atl":[[530,2],[550,0]],"id":52385882},{"atl":[[740,2],[800,0]],"id":52385884},{"atl":[[900,2],[960,2.73]],"id":52385917},{"atl":[[460,2],[470,0]],"id":52385897},{"atl":[[520,0],[510,2]],"id":52385891},{"atl":[[630,2],[650,0]],"id":52385893},{"atl":[[570,0],[550,2]],"id":52385903},{"atl":[[530,0],[520,2]],"id":52385905},{"atl":[[460,0],[450,2]],"id":52385899}],"con":true,"img":false}]}
{"op":"mcm","clk":"11550691743","pt":1719501982612,"mc":[{"id":"1.230178173","rc":[{"atb":[[8.2,0],[8.8,12.82]],"id":52385882}],"con":true,"img":false}]}
{"op":"mcm","clk":"11550691755","pt":1719501982816,"mc":[{"id":"1.230178173","rc":[{"atb":[[2.9,0],[6.2,19.23]],"id":52385897}],"con":true,"img":false}]}
{"op":"mcm","clk":"11550692209","pt":1719501990398,"mc":[{"id":"1.230178173","rc":[{"atb":[[6.4,18.52]],"id":52385904}],"con":true,"img":false}]}
{"op":"mcm","clk":"11550692213","pt":1719501990506,"mc":[{"id":"1.230178173","rc":[{"atb":[[5.7,0]],"id":52385904}],"con":true,"img":false}]}
{"op":"mcm","clk":"11550692224","pt":1719501990703,"mc":[{"id":"1.230178173","rc":[{"atb":[[20,10]],"id":52385919}],"con":true,"img":false}]}
{"op":"mcm","clk":"11550692230","pt":1719501990810,"mc":[{"id":"1.230178173","rc":[{"atb":[[6,0]],"id":52385919}],"con":true,"img":false}]}
{"op":"mcm","clk":"11550693137","pt":1719502006979,"mc":[{"id":"1.230178173","rc":[{"atl":[[430,2],[460,0]],"id":52385910},{"atl":[[390,2],[420,0]],"id":52385912},{"atl":[[410,2],[430,0]],"id":52385906},{"atl":[[670,2],[740,0]],"id":52385918},{"atl":[[810,2],[910,0]],"id":52385920},{"atl":[[430,2],[460,0]],"id":52385889},{"atl":[[540,0],[510,2]],"id":52385914},{"atl":[[570,2],[620,0]],"id":52385883},{"atl":[[540,0],[510,2]],"id":52385885},{"atl":[[540,0],[520,2]],"id":52385896},{"atl":[[420,2],[440,0]],"id":52385890},{"atl":[[320,2],[360,0]],"id":52385892},{"atl":[[430,2],[470,0]],"id":52385904},{"atl":[[540,2],[580,0]],"id":52385898},{"atl":[[680,2],[760,0]],"id":52385900},{"atl":[[310,2],[340,0]],"id":52385911},{"atl":[[440,2],[470,0]],"id":52385913},{"atl":[[660,2],[730,0]],"id":52385907},{"atl":[[810,2],[920,0]],"id":52385886},{"atl":[[740,2],[830,0]],"id":52385919},{"atl":[[590,2],[640,0]],"id":52385921},{"atl":[[530,0],[500,2]],"id":52385882},{"atl":[[670,2],[740,0]],"id":52385884},{"atl":[[800,2],[900,0]],"id":52385917},{"atl":[[430,2],[460,0]],"id":52385897},{"atl":[[480,2],[510,0]],"id":52385891},{"atl":[[580,2],[630,0]],"id":52385893},{"atl":[[520,2],[550,0]],"id":52385903},{"atl":[[520,0],[490,2]],"id":52385905},{"atl":[[420,2],[450,0]],"id":52385899}],"con":true,"img":false}]}
{"op":"mcm","clk":"11550693972","pt":1719502021056,"mc":[{"id":"1.230178173","rc":[{"atl":[[430,0],[460,2]],"id":52385910},{"atl":[[390,0],[420,2]],"id":52385912},{"atl":[[410,0],[430,2]],"id":52385906},{"atl":[[670,0],[740,2]],"id":52385918},{"atl":[[810,0],[910,2]],"id":52385920},{"atl":[[430,0],[460,2]],"id":52385889},{"atl":[[540,2],[510,0]],"id":52385914},{"atl":[[570,0],[620,2]],"id":52385883},{"atl":[[540,2],[510,0]],"id":52385885},{"atl":[[520,0],[540,2]],"id":52385896},{"atl":[[420,0],[440,2]],"id":52385890},{"atl":[[320,0],[360,2]],"id":52385892},{"atl":[[430,0],[470,2]],"id":52385904},{"atl":[[540,0],[580,2]],"id":52385898},{"atl":[[680,0],[760,2]],"id":52385900},{"atl":[[310,0],[340,2]],"id":52385911},{"atl":[[440,0],[470,2]],"id":52385913},{"atl":[[660,0],[730,2]],"id":52385907},{"atl":[[810,0],[920,2]],"id":52385886},{"atl":[[740,0],[830,2]],"id":52385919},{"atl":[[590,0],[640,2]],"id":52385921},{"atl":[[530,2],[500,0]],"id":52385882},{"atl":[[670,0],[740,2]],"id":52385884},{"atl":[[800,0],[900,2]],"id":52385917},{"atl":[[430,0],[460,2]],"id":52385897},{"atl":[[480,0],[510,2]],"id":52385891},{"atl":[[580,0],[630,2]],"id":52385893},{"atl":[[520,0],[550,2]],"id":52385903},{"atl":[[520,2],[490,0]],"id":52385905},{"atl":[[420,0],[450,2]],"id":52385899}],"con":true,"img":false}]}
{"op":"mcm","clk":"11550698156","pt":1719502089651,"mc":[{"id":"1.230178173","rc":[{"atl":[[430,2],[460,0]],"id":52385910},{"atl":[[390,2],[420,0]],"id":52385912},{"atl":[[410,2],[430,0]],"id":52385906},{"atl":[[670,2],[740,0]],"id":52385918},{"atl":[[810,2],[910,0]],"id":52385920},{"atl":[[430,2],[460,0]],"id":52385889},{"atl":[[540,0],[510,2]],"id":52385914},{"atl":[[570,2],[620,0]],"id":52385883},{"atl":[[540,0],[510,2]],"id":52385885},{"atl":[[540,0],[520,2]],"id":52385896},{"atl":[[420,2]],"id":52385890},{"atl":[[320,2],[360,0]],"id":52385892},{"atl":[[430,2],[470,0]],"id":52385904},{"atl":[[540,2],[580,0]],"id":52385898},{"atl":[[680,2],[760,0]],"id":52385900},{"atl":[[310,2],[340,0]],"id":52385911},{"atl":[[440,2],[470,0]],"id":52385913},{"atl":[[660,2],[730,0]],"id":52385907},{"atl":[[810,2],[920,0]],"id":52385886},{"atl":[[740,2]],"id":52385919},{"atl":[[590,2],[640,0]],"id":52385921},{"atl":[[530,0],[500,2]],"id":52385882},{"atl":[[670,2],[740,0]],"id":52385884},{"atl":[[800,2],[900,0]],"id":52385917},{"atl":[[430,2],[460,0]],"id":52385897},{"atl":[[480,2],[510,0]],"id":52385891},{"atl":[[580,2]],"id":52385893},{"atl":[[520,2],[550,0]],"id":52385903},{"atl":[[490,2]],"id":52385905},{"atl":[[420,2],[450,0]],"id":52385899}],"con":true,"img":false}]}
{"op":"mcm","clk":"11550698163","pt":1719502089744,"mc":[{"id":"1.230178173","rc":[{"atl":[[440,0]],"id":52385890},{"atl":[[830,0]],"id":52385919},{"atl":[[630,0]],"id":52385893},{"atl":[[520,0]],"id":52385905}],"con":true,"img":false}]}
{"op":"mcm","clk":"11550698786","pt":1719502100664,"mc":[{"id":"1.230178173","rc":[{"atl":[[430,0],[450,2]],"id":52385910},{"atb":[[5.8,0],[5.2,23.81]],"id":52385912},{"atl":[[390,0],[410,2]],"id":52385912},{"atl":[[410,0],[420,2]],"id":52385906},{"atl":[[670,0],[700,2]],"id":52385918},{"atl":[[810,0],[860,2]],"id":52385920},{"atl":[[430,0],[450,2]],"id":52385889},{"atb":[[8.4,13.51],[9.4,0]],"id":52385914},{"atl":[[530,2],[510,0]],"id":52385914},{"atl":[[570,0],[600,2]],"id":52385883},{"atb":[[8.2,13.89],[9.4,0]],"id":52385885},{"atl":[[530,2],[510,0]],"id":52385885},{"atb":[[9.6,0],[8.4,13.51]],"id":52385896},{"atl":[[520,0],[530,2]],"id":52385896},{"atb":[[6,0],[5.4,22.73]],"id":52385890},{"atl":[[420,0],[430,2]],"id":52385890},{"atl":[[320,0],[340,2]],"id":52385892},{"atl":[[430,0],[450,2]],"id":52385904},{"atb":[[9.2,12.2],[10.5,0]],"id":52385898},{"atl":[[540,0],[560,2]],"id":52385898},{"atb":[[13,8.33],[14.5,0]],"id":52385900},{"atl":[[680,0],[720,2]],"id":52385900},{"atl":[[310,0],[320,2]],"id":52385911},{"atl":[[440,0],[450,2]],"id":52385913},{"atb":[[11.5,9.52],[13.5,0]],"id":52385907},{"atl":[[660,0],[700,2]],"id":52385907},{"atl":[[810,0],[870,2]],"id":52385886},{"atb":[[17.5,6.06],[20,5]],"id":52385919},{"atl":[[740,0],[780,2]],"id":52385919},{"atb":[[10,11.11],[11.5,0]],"id":52385921},{"atl":[[590,0],[610,2]],"id":52385921},{"atb":[[8.8,0],[7.8,14.71]],"id":52385882},{"atl":[[520,2],[500,0]],"id":52385882},{"atl":[[670,0],[710,2]],"id":52385884},{"atl":[[800,0],[850,2]],"id":52385917},{"atl":[[430,0],[440,2]],"id":52385897},{"atl":[[480,0],[500,2]],"id":52385891},{"atl":[[580,0],[600,2]],"id":52385893},{"atb":[[8.6,13.16],[9.8,0]],"id":52385903},{"atl":[[520,0],[540,2]],"id":52385903},{"atl":[[490,0],[510,2]],"id":52385905},{"atl":[[420,0],[440,2]],"id":52385899}],"con":true,"img":false}]}
{"op":"mcm","clk":"11550698793","pt":1719502100765,"mc":[{"id":"1.230178173","rc":[{"atb":[[17.5,0],[5.5,22.22]],"id":52385919}],"con":true,"img":false}]}
{"op":"mcm","clk":"11550699030","pt":1719502104858,"mc":[{"id":"1.230178173","rc":[{"atl":[[450,0],[480,2]],"id":52385910},{"atl":[[410,0],[430,2]],"id":52385912},{"atl":[[420,0],[450,2]],"id":52385906},{"atl":[[700,0],[770,2]],"id":52385918},{"atl":[[860,0],[960,2]],"id":52385920},{"atl":[[450,0],[480,2]],"id":52385889},{"atl":[[530,0],[560,2]],"id":52385914},{"atl":[[600,0],[640,2]],"id":52385883},{"atl":[[530,0],[550,2]],"id":52385885},{"atl":[[530,0],[560,2]],"id":52385896},{"atl":[[430,0],[460,2]],"id":52385890},{"atl":[[340,0],[380,2]],"id":52385892},{"atl":[[450,0],[480,2]],"id":52385904},{"atl":[[560,0],[590,2]],"id":52385898},{"atl":[[720,0],[790,2]],"id":52385900},{"atl":[[320,0],[350,2]],"id":52385911},{"atl":[[450,0],[490,2]],"id":52385913},{"atl":[[700,0],[770,2]],"id":52385907},{"atl":[[870,0],[960,2]],"id":52385886},{"atl":[[780,0],[870,2]],"id":52385919},{"atl":[[610,0],[660,2]],"id":52385921},{"atl":[[520,0],[540,2]],"id":52385882},{"atl":[[710,0],[780,2]],"id":52385884},{"atl":[[850,0],[950,2]],"id":52385917},{"atl":[[440,0],[470,2]],"id":52385897},{"atl":[[520,2],[500,0]],"id":52385891},{"atl":[[600,0],[650,2]],"id":52385893},{"atl":[[540,0],[560,2]],"id":52385903},{"atl":[[530,2],[510,0]],"id":52385905},{"atl":[[440,0],[460,2]],"id":52385899}],"con":true,"img":false}]}
{"op":"mcm","clk":"11550699043","pt":1719502105066,"mc":[{"id":"1.230178173","rc":[{"atl":[[960,0],[970,3.1]],"id":52385886}],"con":true,"img":false}]}
{"op":"mcm","clk":"11550699062","pt":1719502105478,"mc":[{"id":"1.230178173","rc":[{"atb":[[19,0]],"id":52385918},{"atb":[[17,0]],"id":52385893}],"con":true,"img":false}]}
{"op":"mcm","clk":"11550699071","pt":1719502105544,"mc":[{"id":"1.230178173","rc":[{"atb":[[17,5]],"id":52385918},{"atb":[[4,33.33],[11.5,0],[15,6]],"id":52385893}],"con":true,"img":false}]}
{"op":"mcm","clk":"11550699078","pt":1719502105648,"mc":[{"id":"1.230178173","rc":[{"atb":[[13.5,0],[4.4,29.41]],"id":52385918},{"atb":[[4,0],[10,11.11]],"id":52385893}],"con":true,"img":false}]}
{"op":"mcm","clk":"11550699083","pt":1719502105747,"mc":[{"id":"1.230178173","rc":[{"atb":[[12,9.09],[4.4,0]],"id":52385918}],"con":true,"img":false}]}
{"op":"mcm","clk":"11550699166","pt":1719502107289,"mc":[{"id":"1.230178173","rc":[{"atl":[[410,2]],"id":52385912},{"atl":[[860,2]],"id":52385920},{"atl":[[530,2]],"id":52385914},{"atl":[[530,2]],"id":52385896},{"atl":[[560,2],[590,0]],"id":52385898},{"atl":[[720,2]],"id":52385900},{"atl":[[870,2]],"id":52385886},{"atl":[[500,2]],"id":52385891},{"atl":[[540,2]],"id":52385903}],"con":true,"img":false}]}
{"op":"mcm","clk":"11550699171","pt":1719502107390,"mc":[{"id":"1.230178173","rc":[{"atl":[[450,2],[480,0]],"id":52385910},{"atl":[[430,0]],"id":52385912},{"atl":[[420,2],[450,0]],"id":52385906},{"atl":[[700,2],[770,0]],"id":52385918},{"atl":[[960,0]],"id":52385920},{"atl":[[450,2],[480,0]],"id":52385889},{"atl":[[560,0]],"id":52385914},{"atl":[[600,2]],"id":52385883},{"atl":[[530,2],[550,0]],"id":52385885},{"atl":[[560,0]],"id":52385896},{"atl":[[430,2]],"id":52385890},{"atl":[[340,2],[380,0]],"id":52385892},{"atl":[[450,2],[480,0]],"id":52385904},{"atl":[[790,0]],"id":52385900},{"atl":[[320,2],[350,0]],"id":52385911},{"atl":[[450,2],[490,0]],"id":52385913},{"atl":[[700,2],[770,0]],"id":52385907},{"atl":[[970,1.1]],"id":52385886},{"atl":[[780,2],[870,0]],"id":52385919},{"atl":[[610,2],[660,0]],"id":52385921},{"atl":[[540,0],[520,2]],"id":52385882},{"atl":[[710,2],[780,0]],"id":52385884},{"atl":[[850,2],[950,0]],"id":52385917},{"atl":[[440,2],[470,0]],"id":52385897},{"atl":[[520,0]],"id":52385891},{"atl":[[600,2],[650,0]],"id":52385893},{"atl":[[560,0]],"id":52385903},{"atl":[[530,0],[510,2]],"id":52385905},{"atl":[[440,2],[460,0]],"id":52385899}],"con":true,"img":false}]}
{"op":"mcm","clk":"11550699177","pt":1719502107450,"mc":[{"id":"1.230178173","rc":[{"atl":[[640,0]],"id":52385883},{"atl":[[460,0]],"id":52385890}],"con":true,"img":false}]}
{"op":"mcm","clk":"11550699291","pt":1719502109472,"mc":[{"id":"1.230178173","rc":[{"atb":[[17.5,6.06],[5.5,0]],"id":52385919}],"con":true,"img":false}]}
{"op":"mcm","clk":"11550699508","pt":1719502112777,"mc":[{"id":"1.230178173","rc":[{"atl":[[450,0],[480,2]],"id":52385910},{"atl":[[410,0],[430,2]],"id":52385912},{"atl":[[420,0],[450,2]],"id":52385906},{"atl":[[700,0],[770,2]],"id":52385918},{"atl":[[860,0],[960,2]],"id":52385920},{"atl":[[450,0],[480,2]],"id":52385889},{"atl":[[530,0],[560,2]],"id":52385914},{"atl":[[600,0],[640,2]],"id":52385883},{"atl":[[530,0],[550,2]],"id":52385885},{"atl":[[530,0],[560,2]],"id":52385896},{"atl":[[430,0],[460,2]],"id":52385890},{"atl":[[340,0],[380,2]],"id":52385892},{"atl":[[450,0],[480,2]],"id":52385904},{"atl":[[560,0],[590,2]],"id":52385898},{"atl":[[720,0],[790,2]],"id":52385900},{"atl":[[320,0],[350,2]],"id":52385911},{"atl":[[450,0],[490,2]],"id":52385913},{"atl":[[700,0],[770,2]],"id":52385907},{"atl":[[870,0],[970,3.1]],"id":52385886},{"atl":[[780,0],[870,2]],"id":52385919},{"atl":[[610,0],[660,2]],"id":52385921},{"atl":[[520,0],[540,2]],"id":52385882},{"atl":[[710,0],[780,2]],"id":52385884},{"atl":[[850,0],[950,2]],"id":52385917},{"atl":[[440,0],[470,2]],"id":52385897},{"atl":[[520,2],[500,0]],"id":52385891},{"atl":[[600,0],[650,2]],"id":52385893},{"atl":[[540,0],[560,2]],"id":52385903},{"atl":[[530,2],[510,0]],"id":52385905},{"atl":[[440,0],[460,2]],"id":52385899}],"con":true,"img":false}]}
{"op":"mcm","clk":"11550699898","pt":1719502118288,"mc":[{"id":"1.230178173","rc":[{"atl":[[450,2],[480,0]],"id":52385910},{"atl":[[410,2],[430,0]],"id":52385912},{"atl":[[420,2]],"id":52385906},{"atl":[[700,2],[770,0]],"id":52385918},{"atl":[[860,2],[960,0]],"id":52385920},{"atl":[[450,2],[480,0]],"id":52385889},{"atl":[[530,2],[560,0]],"id":52385914},{"atl":[[600,2],[640,0]],"id":52385883},{"atl":[[530,2],[550,0]],"id":52385885},{"atl":[[530,2],[560,0]],"id":52385896},{"atl":[[430,2],[460,0]],"id":52385890},{"atl":[[340,2],[380,0]],"id":52385892},{"atl":[[450,2]],"id":52385904},{"atl":[[560,2],[590,0]],"id":52385898},{"atl":[[720,2],[790,0]],"id":52385900},{"atl":[[320,2],[350,0]],"id":52385911},{"atl":[[450,2],[490,0]],"id":52385913},{"atl":[[700,2],[770,0]],"id":52385907},{"atl":[[870,2],[970,1.1]],"id":52385886},{"atl":[[780,2],[870,0]],"id":52385919},{"atl":[[610,2],[660,0]],"id":52385921},{"atl":[[520,2]],"id":52385882},{"atl":[[710,2],[780,0]],"id":52385884},{"atl":[[850,2],[950,0]],"id":52385917},{"atl":[[440,2]],"id":52385897},{"atl":[[520,0],[500,2]],"id":52385891},{"atl":[[600,2],[650,0]],"id":52385893},{"atl":[[540,2],[560,0]],"id":52385903},{"atl":[[530,0],[510,2]],"id":52385905},{"atl":[[440,2],[460,0]],"id":52385899}],"con":true,"img":false}]}
{"op":"mcm","clk":"11550699902","pt":1719502118390,"mc":[{"id":"1.230178173","rc":[{"atl":[[450,0]],"id":52385906},{"atl":[[540,0]],"id":52385882}],"con":true,"img":false}]}
{"op":"mcm","clk":"11550699912","pt":1719502118494,"mc":[{"id":"1.230178173","rc":[{"atl":[[480,0]],"id":52385904},{"atl":[[470,0]],"id":52385897}],"con":true,"img":false}]}
{"op":"mcm","clk":"11550701497","pt":1719502141599,"mc":[{"id":"1.230178173","rc":[{"atl":[[430,2]],"id":52385912},{"atl":[[790,2]],"id":52385900},{"atl":[[350,2]],"id":52385911},{"atl":[[660,2]],"id":52385921},{"atl":[[560,2]],"id":52385903}],"con":true,"img":false}]}
{"op":"mcm","clk":"11550701504","pt":1719502141704,"mc":[{"id":"1.230178173","rc":[{"atl":[[450,0],[480,2]],"id":52385910},{"atl":[[410,0]],"id":52385912},{"atl":[[420,0],[450,2]],"id":52385906},{"atl":[[700,0],[770,2]],"id":52385918},{"atl":[[860,0],[960,2]],"id":52385920},{"atl":[[450,0],[480,2]],"id":52385889},{"atl":[[530,0],[560,2]],"id":52385914},{"atl":[[600,0],[640,2]],"id":52385883},{"atl":[[530,0],[550,2]],"id":52385885},{"atl":[[530,0],[560,2]],"id":52385896},{"atl":[[430,0],[460,2]],"id":52385890},{"atl":[[340,0],[380,2]],"id":52385892},{"atl":[[450,0],[480,2]],"id":52385904},{"atl":[[560,0],[590,2]],"id":52385898},{"atl":[[720,0]],"id":52385900},{"atl":[[320,0]],"id":52385911},{"atl":[[450,0],[490,2]],"id":52385913},{"atl":[[700,0],[770,2]],"id":52385907},{"atl":[[870,0],[970,3.1]],"id":52385886},{"atl":[[780,0],[870,2]],"id":52385919},{"atl":[[610,0]],"id":52385921},{"atl":[[520,0],[540,2]],"id":52385882},{"atl":[[710,0],[780,2]],"id":52385884},{"atl":[[850,0],[950,2]],"id":52385917},{"atl":[[440,0],[470,2]],"id":52385897},{"atl":[[520,2],[500,0]],"id":52385891},{"atl":[[600,0],[650,2]],"id":52385893},{"atl":[[540,0]],"id":52385903},{"atl":[[530,2],[510,0]],"id":52385905},{"atl":[[440,0],[460,2]],"id":52385899}],"con":true,"img":false}]}
{"op":"mcm","clk":"11550701694","pt":1719502144413,"mc":[{"id":"1.230178173","rc":[{"atb":[[13,0]],"id":52385910}],"con":true,"img":false}]}
{"op":"mcm","clk":"11550701701","pt":1719502144506,"mc":[{"id":"1.230178173","rc":[{"atb":[[12,8]],"id":52385910}],"con":true,"img":false}]}
{"op":"mcm","clk":"11550701709","pt":1719502144611,"mc":[{"id":"1.230178173","rc":[{"atb":[[6.4,0],[2.94,51.55]],"id":52385910}],"con":true,"img":false}]}
{"op":"mcm","clk":"11550702267","pt":1719502152932,"mc":[{"id":"1.230178173","rc":[{"atb":[[5.7,21.28],[2.94,0]],"id":52385910}],"con":true,"img":false}]}
{"op":"mcm","clk":"11550702727","pt":1719502159322,"mc":[{"id":"1.230178173","rc":[{"atb":[[11,0]],"id":52385913}],"con":true,"img":false}]}
{"op":"mcm","clk":"11550702734","pt":1719502159424,"mc":[{"id":"1.230178173","rc":[{"atb":[[10,9]],"id":52385913}],"con":true,"img":false}]}
{"op":"mcm","clk":"11550702739","pt":1719502159519,"mc":[{"id":"1.230178173","rc":[{"atb":[[2.98,50.51]],"id":52385913}],"con":true,"img":false}]}
{"op":"mcm","clk":"11550702747","pt":1719502159625,"mc":[{"id":"1.230178173","rc":[{"atb":[[6,0],[2.98,0],[5.9,20.41]],"id":52385913}],"con":true,"img":false}]}
{"op":"mcm","clk":"11550703266","pt":1719502166935,"mc":[{"id":"1.230178173","rc":[{"atb":[[20,5]],"id":52385914}],"con":true,"img":false}]}
{"op":"mcm","clk":"11550703281","pt":1719502167135,"mc":[{"id":"1.230178173","rc":[{"atb":[[20,0]],"id":52385914}],"con":true,"img":false}]}
{"op":"mcm","clk":"11550703302","pt":1719502167448,"mc":[{"id":"1.230178173","rc":[{"atb":[[11,0]],"id":52385914}],"con":true,"img":false}]}
{"op":"mcm","clk":"11550703310","pt":1719502167551,"mc":[{"id":"1.230178173","rc":[{"atb":[[3.6,38.46],[12,9],[8.4,0]],"id":52385914}],"con":true,"img":false}]}
{"op":"mcm","clk":"11550703349","pt":1719502168225,"mc":[{"id":"1.230178173","rc":[{"atl":[[960,1.95]],"id":52385898}],"con":true,"img":false}]}
{"op":"mcm","clk":"11550703362","pt":1719502168427,"mc":[{"id":"1.230178173","rc":[{"atb":[[12,0]],"id":52385906},{"atb":[[20,0]],"id":52385886},{"atb":[[20,0]],"id":52385917}],"con":true,"img":false}]}
{"op":"mcm","clk":"11550703371","pt":1719502168538,"mc":[{"id":"1.230178173","rc":[{"atb":[[11,8]],"id":52385906},{"atb":[[21,0],[7.4,15.62],[24,5]],"id":52385886},{"atb":[[21,0],[24,5],[6.8,17.24]],"id":52385917}],"con":true,"img":false}]}
{"op":"mcm","clk":"11550703376","pt":1719502168631,"mc":[{"id":"1.230178173","rc":[{"atb":[[2.86,53.76],[5.5,0]],"id":52385906}],"con":true,"img":false}]}
{"op":"mcm","clk":"11550703834","pt":1719502175661,"mc":[{"id":"1.230178173","rc":[{"atb":[[8.4,13.51]],"id":52385914}],"con":true,"img":false}]}
{"op":"mcm","clk":"11550703845","pt":1719502175764,"mc":[{"id":"1.230178173","rc":[{"atb":[[3.6,0]],"id":52385914}],"con":true,"img":false}]}
{"op":"mcm","clk":"11550703901","pt":1719502176642,"mc":[{"id":"1.230178173","rc":[{"atb":[[7.4,0],[25,4.17]],"id":52385886},{"atb":[[24,9.35],[6.8,0]],"id":52385917}],"con":true,"img":false}]}
{"op":"mcm","clk":"11550703909","pt":1719502176745,"mc":[{"id":"1.230178173","rc":[{"atb":[[2.86,0],[5.3,23.26]],"id":52385906}],"con":true,"img":false}]}
{"op":"mcm","clk":"11550703949","pt":1719502177362,"mc":[{"id":"1.230178173","rc":[{"atb":[[12,0]],"id":52385914}],"con":true,"img":false}]}
{"op":"mcm","clk":"11550703956","pt":1719502177465,"mc":[{"id":"1.230178173","rc":[{"atb":[[11,9]],"id":52385914}],"con":true,"img":false}]}
{"op":"mcm","clk":"11550703964","pt":1719502177567,"mc":[{"id":"1.230178173","rc":[{"atb":[[3.6,38.46],[8.4,0]],"id":52385914}],"con":true,"img":false}]}
{"op":"mcm","clk":"11550703970","pt":1719502177670,"mc":[{"id":"1.230178173","rc":[{"atb":[[3.6,0],[8.4,13.51]],"id":52385914}],"con":true,"img":false}]}
{"op":"mcm","clk":"11550706086","pt":1719502206573,"mc":[{"id":"1.230178173","rc":[{"atb":[[5.6,6.2]],"id":52385892},{"atl":[[30,2.9]],"id":52385892},{"atb":[[5.8,6.26]],"id":52385911},{"atl":[[27,2.41]],"id":52385911}],"con":true,"img":false}]}
{"op":"mcm","clk":"11550706097","pt":1719502206678,"mc":[{"id":"1.230178173","rc":[{"atl":[[380,0],[46,2.22]],"id":52385892},{"atl":[[350,0]],"id":52385911}],"con":true,"img":false}]}
{"op":"mcm","clk":"11550706103","pt":1719502206779,"mc":[{"id":"1.230178173","rc":[{"atl":[[40,2.56]],"id":52385911}],"con":true,"img":false}]}
{"op":"mcm","clk":"11550707392","pt":1719502225314,"mc":[{"id":"1.230178173","rc":[{"atb":[[24,0]],"id":52385886},{"atb":[[24,4.35]],"id":52385917}],"con":true,"img":false}]}
{"op":"mcm","clk":"11550707399","pt":1719502225416,"mc":[{"id":"1.230178173","rc":[{"atb":[[20,5],[7.4,15.62],[25,0]],"id":52385886},{"atb":[[20,5],[6.8,17.24]],"id":52385917}],"con":true,"img":false}]}
{"op":"mcm","clk":"11550707406","pt":1719502225519,"mc":[{"id":"1.230178173","rc":[{"atb":[[24,0]],"id":52385917}],"con":true,"img":false}]}
{"op":"mcm","clk":"11550707998","pt":1719502232899,"mc":[{"id":"1.230178173","rc":[{"atb":[[21,5]],"id":52385886},{"atb":[[21,5],[6.8,0]],"id":52385917}],"con":true,"img":false}]}
{"op":"mcm","clk":"11550708002","pt":1719502232998,"mc":[{"id":"1.230178173","rc":[{"atb":[[7.4,0]],"id":52385886}],"con":true,"img":false}]}
{"op":"mcm","clk":"11550708066","pt":1719502233727,"mc":[{"id":"1.230178173","rc":[{"atb":[[5.6,0]],"id":52385892},{"atl":[[30,0]],"id":52385892},{"atb":[[5.8,0]],"id":52385911},{"atl":[[27,0]],"id":52385911}],"con":true,"img":false}]}
{"op":"mcm","clk":"11550708084","pt":1719502233931,"mc":[{"id":"1.230178173","rc":[{"atl":[[46,0],[380,2]],"id":52385892},{"atl":[[40,0],[350,2]],"id":52385911}],"con":true,"img":false}]}
{"op":"mcm","clk":"11550709402","pt":1719502252432,"mc":[{"id":"1.230178173","rc":[{"atb":[[12,0]],"id":52385912},{"atb":[[18,0]],"id":52385883},{"atb":[[15,0]],"id":52385896},{"atb":[[12,0]],"id":52385898},{"atb":[[16,0]],"id":52385900},{"atb":[[20,0]],"id":52385919},{"atb":[[15,0]],"id":52385921},{"atb":[[13,0]],"id":52385899}],"con":true,"img":false}]}
{"op":"mcm","clk":"11550709410","pt":1719502252536,"mc":[{"id":"1.230178173","rc":[{"atb":[[14,8]],"id":52385912},{"atb":[[20,5]],"id":52385883},{"atb":[[18,6]],"id":52385896},{"atb":[[15,8]],"id":52385898},{"atb":[[20,6]],"id":52385900},{"atb":[[24,5]],"id":52385919},{"atb":[[17,6]],"id":52385921},{"atb":[[16,8]],"id":52385899}],"con":true,"img":false}]}
{"op":"mcm","clk":"11550709416","pt":1719502252639,"mc":[{"id":"1.230178173","rc":[{"atb":[[5.2,0],[2.84,54.35]],"id":52385912},{"atb":[[3.95,20],[11,0]],"id":52385883},{"atb":[[3.6,38.46],[8.4,0]],"id":52385896},{"atb":[[9.2,0],[3.8,35.71]],"id":52385898},{"atb":[[4.6,27.78],[13,0]],"id":52385900},{"atb":[[17.5,0],[5.5,22.22]],"id":52385919},{"atb":[[4,33.33],[10,0]],"id":52385921},{"atb":[[5.6,0],[2.88,53.19]],"id":52385899}],"con":true,"img":false}]}
{"op":"mcm","clk":"11550709947","pt":1719502259872,"mc":[{"id":"1.230178173","rc":[{"atb":[[5.2,23.81],[2.84,0]],"id":52385912},{"atb":[[3.95,0],[9.8,11.36]],"id":52385883},{"atb":[[3.6,0],[8.4,13.51]],"id":52385896},{"atb":[[9.2,12.2],[3.8,0]],"id":52385898},{"atb":[[4.6,0],[13,8.33]],"id":52385900},{"atb":[[17.5,6.06],[5.5,0]],"id":52385919},{"atb":[[4,0],[10,11.11]],"id":52385921},{"atb":[[2.88,0],[5.4,22.73]],"id":52385899}],"con":true,"img":false}]}
{"op":"mcm","clk":"11550709987","pt":1719502260544,"mc":[{"id":"1.230178173","rc":[{"atb":[[5.8,3.5]],"id":52385890},{"atl":[[32,2.7]],"id":52385890},{"atb":[[10,14.07]],"id":52385892},{"atl":[[30,2.48]],"id":52385892},{"atb":[[5.8,5.66]],"id":52385911},{"atl":[[27,3.59]],"id":52385911},{"atb":[[11,13]],"id":52385897},{"atl":[[48,3]],"id":52385897}],"con":true,"img":false}]}
{"op":"mcm","clk":"11550709996","pt":1719502260651,"mc":[{"id":"1.230178173","rc":[{"atl":[[80,2],[460,0]],"id":52385890},{"atl":[[380,0],[46,2.22]],"id":52385892},{"atl":[[40,2.56],[350,0]],"id":52385911},{"atl":[[85,2],[470,0]],"id":52385897}],"con":true,"img":false}]}
{"op":"mcm","clk":"11550710061","pt":1719502261379,"mc":[{"id":"1.230178173","rc":[{"atb":[[18,0]],"id":52385885},{"atb":[[20,0]],"id":52385886},{"atb":[[20,0]],"id":52385917},{"atb":[[15,0]],"id":52385905}],"con":true,"img":false}]}
{"op":"mcm","clk":"11550710073","pt":1719502261432,"mc":[{"id":"1.230178173","rc":[{"atb":[[20,5],[3.55,39.22]],"id":52385885},{"atb":[[7.4,15.62],[24,5]],"id":52385886},{"atb":[[24,5]],"id":52385917},{"atb":[[3.35,42.55],[14,6]],"id":52385905}],"con":true,"img":false}]}
{"op":"mcm","clk":"11550710082","pt":1719502261536,"mc":[{"id":"1.230178173","rc":[{"atb":[[8.2,0]],"id":52385885},{"atb":[[21,0]],"id":52385886},{"atb":[[21,0],[6.8,17.24]],"id":52385917},{"atb":[[8.4,0]],"id":52385905}],"con":true,"img":false}]}
{"op":"mcm","clk":"11550710091","pt":1719502261641,"mc":[{"id":"1.230178173","rc":[{"atb":[[7.4,0],[25,4.17]],"id":52385886},{"atb":[[24,9.35],[6.8,0]],"id":52385917},{"atb":[[3.35,0],[7.4,15.62]],"id":52385905}],"con":true,"img":false}]}
{"op":"mcm","clk":"11550710100","pt":1719502261743,"mc":[{"id":"1.230178173","rc":[{"atb":[[8.2,13.89],[3.55,0]],"id":52385885}],"con":true,"img":false}]}
{"op":"mcm","clk":"11550710116","pt":1719502261851,"mc":[{"id":"1.230178173","rc":[{"atb":[[6.8,17.24]],"id":52385917}],"con":true,"img":false}]}
{"op":"mcm","clk":"11550710129","pt":1719502261954,"mc":[{"id":"1.230178173","rc":[{"atb":[[24,5]],"id":52385917}],"con":true,"img":false}]}
{"op":"mcm","clk":"11550710170","pt":1719502262429,"mc":[{"id":"1.230178173","rc":[{"atb":[[14,0]],"id":52385912},{"atb":[[18,0]],"id":52385896},{"atb":[[15,0]],"id":52385898},{"atb":[[20,0]],"id":52385900},{"atb":[[24,0]],"id":52385919},{"atb":[[16,0]],"id":52385899}],"con":true,"img":false}]}
{"op":"mcm","clk":"11550710178","pt":1719502262524,"mc":[{"id":"1.230178173","rc":[{"atb":[[12,8]],"id":52385912},{"atb":[[16,6]],"id":52385896},{"atb":[[12,8]],"id":52385898},{"atb":[[17,6]],"id":52385900},{"atb":[[20,5]],"id":52385919},{"atb":[[13,8]],"id":52385899}],"con":true,"img":false}]}
{"op":"mcm","clk":"11550710322","pt":1719502264442,"mc":[{"id":"1.230178173","rc":[{"atb":[[20,0]],"id":52385884},{"atb":[[15,0]],"id":52385903}],"con":true,"img":false}]}
{"op":"mcm","clk":"11550710330","pt":1719502264544,"mc":[{"id":"1.230178173","rc":[{"atb":[[24,5]],"id":52385884},{"atb":[[17,6]],"id":52385903}],"con":true,"img":false}]}
{"op":"mcm","clk":"11550710337","pt":1719502264646,"mc":[{"id":"1.230178173","rc":[{"atb":[[4.4,15.38],[14,0]],"id":52385884},{"atb":[[8.6,0],[3.65,26.32]],"id":52385903}],"con":true,"img":false}]}
{"op":"mcm","clk":"11550710346","pt":1719502264753,"mc":[{"id":"1.230178173","rc":[{"atb":[[12,9.09]],"id":52385884},{"atb":[[8.6,12]],"id":52385903}],"con":true,"img":false}]}
{"op":"mcm","clk":"11550710353","pt":1719502264852,"mc":[{"id":"1.230178173","rc":[{"atb":[[4.4,0]],"id":52385884},{"atb":[[3.65,0]],"id":52385903}],"con":true,"img":false}]}
{"op":"mcm","clk":"11550710550","pt":1719502267441,"mc":[{"id":"1.230178173","rc":[{"atb":[[20,0]],"id":52385920},{"atb":[[11,0]],"id":52385914},{"atb":[[17,0]],"id":52385921}],"con":true,"img":false}]}
{"op":"mcm","clk":"11550710558","pt":1719502267546,"mc":[{"id":"1.230178173","rc":[{"atb":[[7.2,16.13],[18,5]],"id":52385920},{"atb":[[3.6,38.46],[10,9]],"id":52385914},{"atb":[[4,33.33],[10,0],[14,6]],"id":52385921}],"con":true,"img":false}]}
{"op":"mcm","clk":"11550710566","pt":1719502267651,"mc":[{"id":"1.230178173","rc":[{"atb":[[8.4,0]],"id":52385914}],"con":true,"img":false}]}
{"op":"mcm","clk":"11550710576","pt":1719502267752,"mc":[{"id":"1.230178173","rc":[{"atb":[[7.2,0],[18.5,5.71],[21,0]],"id":52385920},{"atb":[[3.6,0],[8.4,13.51]],"id":52385914},{"atb":[[4,0],[10,11.11]],"id":52385921}],"con":true,"img":false}]}
{"op":"mcm","clk":"11550710794","pt":1719502270364,"mc":[{"id":"1.230178173","rc":[{"atb":[[17,0]],"id":52385918},{"atb":[[15,0]],"id":52385893}],"con":true,"img":false}]}
{"op":"mcm","clk":"11550710802","pt":1719502270468,"mc":[{"id":"1.230178173","rc":[{"atb":[[4.4,29.41],[14,5]],"id":52385918},{"atb":[[4,33.33],[14,6]],"id":52385893}],"con":true,"img":false}]}
{"op":"mcm","clk":"11550710811","pt":1719502270570,"mc":[{"id":"1.230178173","rc":[{"atb":[[12,0]],"id":52385918},{"atb":[[10,0]],"id":52385893}],"con":true,"img":false}]}
{"op":"mcm","clk":"11550710827","pt":1719502270775,"mc":[{"id":"1.230178173","rc":[{"atb":[[12,9.09],[4.4,0]],"id":52385918}],"con":true,"img":false}]}
{"op":"mcm","clk":"11550710869","pt":1719502271399,"mc":[{"id":"1.230178173","rc":[{"atb":[[24,0]],"id":52385886},{"atb":[[24,0]],"id":52385917}],"con":true,"img":false}]}
{"op":"mcm","clk":"11550710877","pt":1719502271450,"mc":[{"id":"1.230178173","rc":[{"atb":[[20,5]],"id":52385886},{"atb":[[20,5]],"id":52385917}],"con":true,"img":false}]}
{"op":"mcm","clk":"11550710886","pt":1719502271553,"mc":[{"id":"1.230178173","rc":[{"atb":[[7.4,15.62],[25,0]],"id":52385886},{"atb":[[21,5]],"id":52385917}],"con":true,"img":false}]}
{"op":"mcm","clk":"11550710894","pt":1719502271662,"mc":[{"id":"1.230178173","rc":[{"atb":[[6.8,0]],"id":52385917}],"con":true,"img":false}]}
{"op":"mcm","clk":"11550710963","pt":1719502272394,"mc":[{"id":"1.230178173","rc":[{"atb":[[6,2]],"id":52385910},{"atb":[[6,2]],"id":52385912},{"atb":[[6,2]],"id":52385906},{"atb":[[6,2]],"id":52385918},{"atb":[[6,2]],"id":52385920},{"atb":[[6,2]],"id":52385889},{"atb":[[6,2]],"id":52385914},{"atb":[[6,2]],"id":52385883},{"atb":[[6,2]],"id":52385885},{"atb":[[6,2]],"id":52385896},{"atb":[[6,2]],"id":52385890},{"atb":[[6,2]],"id":52385892},{"atb":[[6,2]],"id":52385904},{"atb":[[6,2]],"id":52385898},{"atb":[[6,2]],"id":52385900},{"atb":[[6,2]],"id":52385911},{"atb":[[6,2]],"id":52385913},{"atb":[[6,2]],"id":52385907},{"atb":[[6,2]],"id":52385886},{"atb":[[6,2]],"id":52385919},{"atb":[[6,2]],"id":52385921},{"atb":[[6,2]],"id":52385882},{"atb":[[6,2]],"id":52385884},{"atb":[[6,2]],"id":52385917},{"atb":[[6,2]],"id":52385897},{"atb":[[6,2]],"id":52385891},{"atb":[[6,2]],"id":52385893},{"atb":[[6,2]],"id":52385903},{"atb":[[6,2]],"id":52385905},{"atb":[[6,2]],"id":52385899}],"con":true,"img":false}]}
{"op":"mcm","clk":"11550711070","pt":1719502273369,"mc":[{"id":"1.230178173","rc":[{"atb":[[17,0]],"id":52385907},{"atb":[[20,0]],"id":52385919}],"con":true,"img":false}]}
{"op":"mcm","clk":"11550711079","pt":1719502273473,"mc":[{"id":"1.230178173","rc":[{"atb":[[11.5,0],[6,21.04],[15,6]],"id":52385907},{"atb":[[16,5],[17.5,0],[6,14.12]],"id":52385919}],"con":true,"img":false}]}
{"op":"mcm","clk":"11550711347","pt":1719502277385,"mc":[{"id":"1.230178173","rc":[{"atb":[[18,0]],"id":52385920},{"atb":[[10,0]],"id":52385914},{"atb":[[14,0]],"id":52385921}],"con":true,"img":false}]}
{"op":"mcm","clk":"11550711358","pt":1719502277490,"mc":[{"id":"1.230178173","rc":[{"atb":[[7.2,11.42],[18.5,0],[15,5]],"id":52385920},{"atb":[[9,9],[6,22],[8.4,0]],"id":52385914},{"atb":[[10,0],[11,6],[6,22]],"id":52385921},{"atb":[[4,0],[10,11.11]],"id":52385893}],"con":true,"img":false}]}
{"op":"mcm","clk":"11550711364","pt":1719502277590,"mc":[{"id":"1.230178173","rc":[{"atb":[[7.2,0],[15.5,5]],"id":52385920},{"atb":[[3.6,38.46],[6,2]],"id":52385914},{"atb":[[4,33.33],[6,2]],"id":52385921}],"con":true,"img":false}]}
{"op":"mcm","clk":"11550711372","pt":1719502277657,"mc":[{"id":"1.230178173","rc":[{"atb":[[3.6,0],[8.4,13.51]],"id":52385914},{"atb":[[4,0],[10,11.11]],"id":52385921}],"con":true,"img":false}]}
{"op":"mcm","clk":"11550711446","pt":1719502278574,"mc":[{"id":"1.230178173","rc":[{"atb":[[21,5],[7.4,0]],"id":52385886}],"con":true,"img":false}]}
{"op":"mcm","clk":"11550711596","pt":1719502280497,"mc":[{"id":"1.230178173","rc":[{"atb":[[11.5,9.52],[6,2]],"id":52385907},{"atb":[[16.5,5]],"id":52385919}],"con":true,"img":false}]}
{"op":"mcm","clk":"11550711604","pt":1719502280552,"mc":[{"id":"1.230178173","rc":[{"atb":[[6,2]],"id":52385919}],"con":true,"img":false}]}
{"op":"mcm","clk":"11550711644","pt":1719502281069,"mc":[{"id":"1.230178173","rc":[{"atb":[[11,10],[12,0]],"id":52385918},{"atb":[[8,14.29],[8.4,0]],"id":52385914},{"atb":[[4.5,28.57],[5.2,0]],"id":52385892},{"atb":[[6.4,0],[5.5,22.22]],"id":52385904},{"atb":[[5.1,0],[4.4,29.41]],"id":52385911},{"atb":[[9.6,11.63],[10,0]],"id":52385921},{"atb":[[6.2,0],[5.3,23.26]],"id":52385897},{"atb":[[8,0],[6.8,17.24]],"id":52385891}],"con":true,"img":false}]}
{"op":"mcm","clk":"11550711681","pt":1719502281689,"mc":[{"id":"1.230178173","rc":[{"atb":[[10.5,2.5],[12.5,8],[9.4,5]],"id":52385910},{"atl":[[75,5],[55,2.5],[460,2],[470,1.28],[480,0]],"id":52385910},{"atb":[[9,2.5],[8.2,5],[12,16]],"id":52385912},{"atl":[[42,2.5],[50,5],[430,0],[420,3.43]],"id":52385912},{"atb":[[11.5,8],[7.8,2.5],[7,5]],"id":52385906},{"atl":[[46,2.5],[440,3.37],[450,0],[60,5]],"id":52385906},{"atb":[[10.5,2.5],[11,0],[12,9.09],[14.5,10.16],[9.4,5]],"id":52385918},{"atl":[[130,5],[720,2],[95,2.5],[760,0.79],[770,0]],"id":52385918},{"atb":[[16,8],[9.6,5],[11,2.5]],"id":52385920},{"atl":[[180,2.5],[220,5],[900,2],[950,0.63],[960,0]],"id":52385920},{"atb":[[10,10.5],[9.2,5],[10.5,8]],"id":52385889},{"atl":[[44,2.5],[55,5],[470,3.28],[480,0]],"id":52385889},{"atb":[[8,0],[9.6,2.5],[8.6,13.16],[9.2,8],[8.8,5]],"id":52385914},{"atl":[[540,2],[560,0],[550,1.09],[75,5],[55,2.5]],"id":52385914},{"atb":[[18.5,5],[21,10.5]],"id":52385883},{"atl":[[150,5],[620,2],[630,0.95],[640,0],[110,2.5]],"id":52385883},{"atb":[[16,5],[18,2.5],[21,8]],"id":52385885},{"atl":[[540,3.11],[550,0],[80,2.5],[100,5]],"id":52385885},{"atb":[[16.5,8],[12.5,5],[14.5,2.5]],"id":52385896},{"atl":[[130,5],[560,0],[550,3.09],[95,2.5]],"id":52385896},{"atb":[[9.6,2.5],[12.5,9.4],[8.8,5]],"id":52385890},{"atl":[[36,2.5],[44,5],[30,9.4]],"id":52385890},{"atb":[[5.6,5],[4.5,0],[10,23.47],[5,25],[6,4.5]],"id":52385892},{"atl":[[32,5],[42,2.44],[46,0],[27,2.5],[29,9.4]],"id":52385892},{"atb":[[8.6,5],[5.5,0],[6,16],[12.5,8],[9.4,2.5]],"id":52385904},{"atl":[[42,2.5],[50,5],[470,3.28],[480,0]],"id":52385904},{"atb":[[17,2.5],[9.2,0],[12.5,8],[9.8,11.36],[15,5]],"id":52385898},{"atl":[[70,2.5],[590,0],[580,3.04],[90,5]],"id":52385898},{"atb":[[16,5],[17.5,8],[18,2.5]],"id":52385900},{"atl":[[160,5],[750,2],[790,0],[780,0.77],[120,2.5]],"id":52385900},{"atb":[[6.4,2.5],[5.8,10.66]],"id":52385911},{"atl":[[34,5],[26,12.3],[28,2.5]],"id":52385911},{"atb":[[10.5,10.5],[9.4,5]],"id":52385913},{"atl":[[40,2.5],[48,5],[470,2],[490,0],[480,1.25]],"id":52385913},{"atb":[[16.5,2.5],[14.5,5],[15.5,8]],"id":52385907},{"atl":[[140,5],[730,2],[760,0.79],[770,0],[100,2.5]],"id":52385907},{"atb":[[19,5],[22,18.7]],"id":52385886},{"atl":[[190,2.5],[230,5],[910,2],[970,1.1],[960,0.63]],"id":52385886},{"atb":[[17,8],[12.5,5],[14.5,2.5]],"id":52385919},{"atl":[[140,2.5],[180,5],[810,2],[860,0.7],[870,0]],"id":52385919},{"atb":[[9.6,5],[10.5,10.53],[11,8.5],[11.5,8]],"id":52385921},{"atl":[[75,2.5],[620,2],[660,0],[650,0.92],[95,5]],"id":52385921},{"atb":[[12,13],[12.5,8],[14,2.5]],"id":52385882},{"atl":[[540,0],[530,3.13],[75,2.5],[95,5]],"id":52385882},{"atb":[[25,8]],"id":52385884},{"atl":[[150,5],[750,2],[780,0],[770,0.78],[110,2.5]],"id":52385884},{"atb":[[22,10.92],[13.5,5],[15.5,2.5]],"id":52385917},{"atl":[[170,2.5],[210,5],[880,2],[950,0],[940,0.64]],"id":52385917},{"atb":[[9,2.5],[5.8,20.83],[5.3,0],[8.2,5],[11.5,10]],"id":52385897},{"atl":[[65,5],[46,10],[48,5.5]],"id":52385897},{"atb":[[10,2.5],[9.2,5],[11.5,8],[7.4,14],[6.8,0]],"id":52385891},{"atl":[[520,0],[46,2.5],[60,5],[510,3.18]],"id":52385891},{"atb":[[7.2,2.5],[6.4,5],[14.5,8]],"id":52385893},{"atl":[[75,2.5],[620,2],[650,0],[640,0.94],[95,5]],"id":52385893},{"atb":[[17.5,8]],"id":52385903},{"atl":[[560,0],[550,3.09],[75,2.5],[95,5]],"id":52385903},{"atb":[[10,5],[12,2.5],[14.5,8]],"id":52385905},{"atl":[[530,0],[65,2.5],[520,3.16],[85,5]],"id":52385905},{"atb":[[10,2.5],[9.2,5],[13,16]],"id":52385899},{"atl":[[75,5],[55,2.5],[460,0],[450,3.34]],"id":52385899}],"con":true,"img":false}]}
{"op":"mcm","clk":"11550711698","pt":1719502281895,"mc":[{"id":"1.230178173","rc":[{"atb":[[12,8]],"id":52385912},{"atl":[[430,2],[440,1.37]],"id":52385906},{"atl":[[720,0],[710,2]],"id":52385918},{"atl":[[890,2],[900,0]],"id":52385920},{"atl":[[460,2],[470,1.28]],"id":52385889},{"atb":[[10,11.11],[9.8,0]],"id":52385898},{"atl":[[730,0],[720,2]],"id":52385907},{"atl":[[750,0],[740,2]],"id":52385884},{"atl":[[880,0],[870,2]],"id":52385917},{"atl":[[450,1.34],[460,2]],"id":52385899}],"con":true,"img":false}]}
{"op":"mcm","clk":"11550711707","pt":1719502281949,"mc":[{"id":"1.230178173","rc":[{"atb":[[9.2,16.86]],"id":52385912}],"con":true,"img":false}]}
{"op":"mcm","clk":"11550711721","pt":1719502282157,"mc":[{"id":"1.230178173","rc":[{"atb":[[20,12.5]],"id":52385920},{"atb":[[22,9.56]],"id":52385919},{"atb":[[17,15.73]],"id":52385921},{"atb":[[26,9.71]],"id":52385917},{"atb":[[14.5,21.75]],"id":52385893}],"con":true,"img":false}]}
{"op":"mcm","clk":"11550711736","pt":1719502282368,"mc":[{"id":"1.230178173","rc":[{"atb":[[20,0]],"id":52385920},{"atb":[[12,0]],"id":52385898},{"atb":[[17,0]],"id":52385921}],"con":true,"img":false}]}
{"op":"mcm","clk":"11550711744","pt":1719502282464,"mc":[{"id":"1.230178173","rc":[{"atb":[[20,10.16]],"id":52385882},{"atb":[[23,12.5]],"id":52385884}],"con":true,"img":false}]}
{"op":"mcm","clk":"11550711750","pt":1719502282570,"mc":[{"id":"1.230178173","rc":[{"atb":[[12,0]],"id":52385910},{"atb":[[11,0]],"id":52385906},{"atb":[[14,0]],"id":52385918},{"atb":[[10,2.5]],"id":52385889},{"atb":[[20,0]],"id":52385883},{"atb":[[16,0]],"id":52385896},{"atb":[[12,0]],"id":52385890},{"atb":[[12,0]],"id":52385904},{"atb":[[10,0]],"id":52385913},{"atb":[[20,0]],"id":52385886},{"atb":[[22,0]],"id":52385919},{"atb":[[12,5]],"id":52385882},{"atb":[[26,0]],"id":52385917},{"atb":[[11,5]],"id":52385897},{"atb":[[11,0]],"id":52385891},{"atb":[[14.5,8]],"id":52385893},{"atb":[[14,0]],"id":52385905}],"con":true,"img":false}]}
{"op":"mcm","clk":"11550711757","pt":1719502282672,"mc":[{"id":"1.230178173","rc":[{"atb":[[15,8]],"id":52385910},{"atb":[[13,8]],"id":52385906},{"atb":[[16,5]],"id":52385918},{"atb":[[13,8]],"id":52385889},{"atb":[[24,5]],"id":52385883},{"atb":[[20,6]],"id":52385896},{"atb":[[16,6]],"id":52385890},{"atb":[[14,7]],"id":52385904},{"atb":[[11,9]],"id":52385913},{"atb":[[24,5]],"id":52385886},{"atb":[[16,8],[20,0]],"id":52385882},{"atb":[[23,0]],"id":52385884},{"atb":[[15,8]],"id":52385897},{"atb":[[13,7]],"id":52385891},{"atb":[[16,6]],"id":52385905}],"con":true,"img":false}]}
{"op":"mcm","clk":"11550711764","pt":1719502282779,"mc":[{"id":"1.230178173","rc":[{"atb":[[16.5,20],[10.5,13.03],[12,0],[14.5,0]],"id":52385918},{"atb":[[12.5,0]],"id":52385890},{"atb":[[19,10.56],[21,0]],"id":52385886}],"con":true,"img":false}]}
{"op":"mcm","clk":"11550711772","pt":1719502282879,"mc":[{"id":"1.230178173","rc":[{"atb":[[12,9.09]],"id":52385918},{"atb":[[19,5],[25,4.17]],"id":52385886}],"con":true,"img":false}]}
{"op":"mcm","clk":"11550711779","pt":1719502282982,"mc":[{"id":"1.230178173","rc":[{"atb":[[10.5,2.5]],"id":52385918}],"con":true,"img":false}]}
{"op":"mcm","clk":"11550711804","pt":1719502283396,"mc":[{"id":"1.230178173","rc":[{"atb":[[2.64,60.98],[5.7,0]],"id":52385910},{"atb":[[5.2,0],[1.24,72.82]],"id":52385912},{"atb":[[5.3,0]],"id":52385906},{"atb":[[16.5,0],[5.6,21.74],[12,0]],"id":52385918},{"atl":[[710,0],[510,2]],"id":52385918},{"atb":[[9.8,10],[15.5,0]],"id":52385920},{"atl":[[650,2],[890,0]],"id":52385920},{"atb":[[7.6,13],[5.9,0]],"id":52385889},{"atb":[[5.6,21.74],[8.6,0]],"id":52385914},{"atl":[[540,0],[460,2]],"id":52385914},{"atb":[[9.8,0]],"id":52385883},{"atb":[[2.02,98.04],[8.2,0]],"id":52385885},{"atb":[[8.4,0]],"id":52385896},{"atb":[[16,21.4],[4.1,32.26],[5.4,0]],"id":52385890},{"atl":[[65,2]],"id":52385890},{"atb":[[5,0],[3.55,39.22]],"id":52385892},{"atl":[[42,0],[50,2.04]],"id":52385892},{"atb":[[2.42,70.42],[6,2]],"id":52385904},{"atb":[[10,0]],"id":52385898},{"atl":[[130,2.5],[70,0],[170,5],[90,0]],"id":52385898},{"atb":[[11,10],[13,0]],"id":52385900},{"atl":[[660,2],[750,0]],"id":52385900},{"atb":[[2.54,64.94],[11,20.18],[4.4,0]],"id":52385911},{"atl":[[40,0],[50,2.04]],"id":52385911},{"atb":[[5.9,0]],"id":52385913},{"atl":[[75,5],[40,0],[48,0],[55,2.5]],"id":52385913},{"atl":[[620,2],[720,0]],"id":52385907},{"atb":[[25,0],[13.5,8]],"id":52385886},{"atl":[[800,2],[910,0]],"id":52385886},{"atb":[[16.5,0],[16,0]],"id":52385919},{"atl":[[590,2],[810,0]],"id":52385919},{"atb":[[9.6,0],[10.5,0],[11,6],[5.2,23.81]],"id":52385921},{"atl":[[620,0],[460,2]],"id":52385921},{"atb":[[6.4,16],[7.8,0]],"id":52385882},{"atb":[[12,0]],"id":52385884},{"atl":[[150,0],[170,2.5],[210,5],[110,0]],"id":52385884},{"atb":[[9,10],[21,0]],"id":52385917},{"atl":[[620,2],[870,0]],"id":52385917},{"atb":[[5.8,0],[2.86,53.76]],"id":52385897},{"atl":[[85,0],[120,2]],"id":52385897},{"atb":[[2.82,54.95],[7.4,0]],"id":52385891},{"atl":[[75,5],[46,0],[55,2.5],[60,0]],"id":52385891},{"atb":[[6.4,19],[10,0]],"id":52385893},{"atl":[[520,2],[620,0]],"id":52385893},{"atb":[[8.6,0]],"id":52385903},{"atl":[[75,0],[85,2.5],[95,0],[110,5]],"id":52385903},{"atb":[[7.4,0]],"id":52385905},{"atl":[[65,0],[80,2.5],[85,0],[100,5]],"id":52385905},{"atb":[[5.4,0]],"id":52385899}],"con":true,"img":false}]}
{"op":"mcm","clk":"11550711811","pt":1719502283499,"mc":[{"id":"1.230178173","rc":[{"atl":[[80,0]],"id":52385890},{"atl":[[280,2],[580,1.04]],"id":52385898},{"atb":[[20,5]],"id":52385919},{"atb":[[7.4,2.5],[6.6,5]],"id":52385921},{"atl":[[350,2],[740,0]],"id":52385884},{"atl":[[110,2],[510,1.18]],"id":52385891},{"atl":[[550,1.09],[200,2]],"id":52385903},{"atl":[[520,1.16],[180,2]],"id":52385905}],"con":true,"img":false}]}
{"op":"mcm","clk":"11550711817","pt":1719502283604,"mc":[{"id":"1.230178173","rc":[{"atb":[[9.6,9],[7.2,10]],"id":52385918},{"atb":[[9.8,0],[13,8.33]],"id":52385920},{"atb":[[5.6,0],[7.2,13]],"id":52385914},{"atb":[[4.1,0],[6,12]],"id":52385890},{"atb":[[5,25],[3.55,0]],"id":52385892},{"atl":[[40,2.56],[50,0]],"id":52385892},{"atb":[[11,0],[15,7.14]],"id":52385900},{"atl":[[600,2],[660,0]],"id":52385900},{"atb":[[4,33.33],[2.54,0]],"id":52385911},{"atl":[[38,2.7],[50,0]],"id":52385911},{"atl":[[100,2],[470,0]],"id":52385913},{"atl":[[570,2],[620,0]],"id":52385907},{"atb":[[18.5,5.71],[13.5,0]],"id":52385886},{"atl":[[710,2],[800,0]],"id":52385886},{"atb":[[11,10]],"id":52385919},{"atb":[[6.6,19]],"id":52385921},{"atb":[[6.4,0],[9.4,11.9]],"id":52385882},{"atb":[[12,9.09]],"id":52385917},{"atl":[[85,2],[120,0]],"id":52385897},{"atb":[[2.82,0],[5.8,20.83]],"id":52385891},{"atb":[[6.4,5],[8.4,13.51]],"id":52385893}],"con":true,"img":false}]}
{"op":"mcm","clk":"11550711823","pt":1719502283658,"mc":[{"id":"1.230178173","rc":[{"atb":[[5.6,0]],"id":52385918},{"atb":[[5.2,0]],"id":52385921},{"atb":[[9,0]],"id":52385917}],"con":true,"img":false}]}
{"op":"mcm","clk":"11550711833","pt":1719502283759,"mc":[{"id":"1.230178173","rc":[{"atb":[[22,0]],"id":52385917}],"con":true,"img":false}]}
{"op":"mcm","clk":"11550711838","pt":1719502283863,"mc":[{"id":"1.230178173","rc":[{"atb":[[21,15]],"id":52385917}],"con":true,"img":false}]}
{"op":"mcm","clk":"11550712099","pt":1719502287373,"mc":[{"id":"1.230178173","rc":[{"atb":[[11.5,0],[14,7.69]],"id":52385907},{"atb":[[11,0]],"id":52385921}],"con":true,"img":false}]}
{"op":"mcm","clk":"11550712105","pt":1719502287481,"mc":[{"id":"1.230178173","rc":[{"atb":[[5.8,0]],"id":52385890},{"atl":[[32,0]],"id":52385890},{"atb":[[10,17.4]],"id":52385892},{"atl":[[30,0]],"id":52385892},{"atb":[[5.8,5]],"id":52385911},{"atl":[[27,0]],"id":52385911},{"atb":[[12,6]],"id":52385921},{"atb":[[11,0]],"id":52385897},{"atl":[[48,2.5]],"id":52385897}],"con":true,"img":false}]}
{"op":"mcm","clk":"11550712114","pt":1719502287580,"mc":[{"id":"1.230178173","rc":[{"atb":[[9,5.51]],"id":52385890},{"atl":[[29,2.7]],"id":52385890},{"atb":[[5.7,8.2]],"id":52385892},{"atl":[[24,2.97]],"id":52385892},{"atb":[[6.2,8.9]],"id":52385911},{"atl":[[23,3.9]],"id":52385911},{"atb":[[11.5,0]],"id":52385921},{"atb":[[15.5,5]],"id":52385897},{"atl":[[44,2.5]],"id":52385897}],"con":true,"img":false}]}
{"op":"mcm","clk":"11550712173","pt":1719502288354,"mc":[{"id":"1.230178173","rc":[{"atb":[[15,0],[15.5,6.9]],"id":52385920},{"atb":[[9,0]],"id":52385914},{"atb":[[17,0]],"id":52385900},{"atb":[[15,0]],"id":52385907},{"atb":[[12.5,15]],"id":52385921},{"atb":[[24,0]],"id":52385884},{"atb":[[20,0]],"id":52385917},{"atb":[[14,0]],"id":52385893}],"con":true,"img":false}]}
{"op":"mcm","clk":"11550712186","pt":1719502288507,"mc":[{"id":"1.230178173","rc":[{"atb":[[5.5,22.22],[2.64,0]],"id":52385910},{"atb":[[3.9,34.48],[1.24,0]],"id":52385912},{"atb":[[2.4,71.43]],"id":52385906},{"atb":[[7.2,0],[10.5,12.5]],"id":52385918},{"atb":[[20,5],[13,0]],"id":52385920},{"atl":[[410,2],[460,0]],"id":52385889},{"atb":[[7.2,0],[8.2,13],[12,9]],"id":52385914},{"atb":[[10.5,10]],"id":52385883},{"atb":[[2.02,0],[7.8,10]],"id":52385885},{"atb":[[6.6,11]],"id":52385896},{"atb":[[16,6],[7.2,12],[6,2]],"id":52385890},{"atb":[[5,0],[6.2,19.23]],"id":52385892},{"atl":[[32,8.23],[40,0]],"id":52385892},{"atb":[[4.6,27.78],[2.42,0]],"id":52385904},{"atb":[[16,11.67],[20,6],[15,0]],"id":52385900},{"atb":[[4,0],[11,8],[5.2,23.81]],"id":52385911},{"atl":[[34,8.03],[38,0]],"id":52385911},{"atb":[[3.65,37.74]],"id":52385913},{"atb":[[20,6]],"id":52385907},{"atb":[[18.5,0],[22,23.46]],"id":52385886},{"atb":[[11,0],[14.5,9.91]],"id":52385919},{"atb":[[8.8,12],[6.6,5]],"id":52385921},{"atb":[[10,11.11],[9.4,0]],"id":52385882},{"atl":[[530,1.13],[480,2]],"id":52385882},{"atb":[[2,2.5],[6.4,13],[20,5],[1.96,5]],"id":52385884},{"atb":[[12,0],[24,5],[15,7.14]],"id":52385917},{"atb":[[2.86,0],[6,12]],"id":52385897},{"atl":[[70,2],[85,0]],"id":52385897},{"atb":[[8.6,12],[5.8,0]],"id":52385891},{"atb":[[17,6],[10,11.11],[8.4,0]],"id":52385893},{"atb":[[2.68,59.52]],"id":52385903},{"atb":[[2.92,52.08]],"id":52385899}],"con":true,"img":false}]}
{"op":"mcm","clk":"11550712196","pt":1719502288562,"mc":[{"id":"1.230178173","rc":[{"atb":[[9.8,16.42]],"id":52385890}],"con":true,"img":false}]}
{"op":"mcm","clk":"11550712208","pt":1719502288666,"mc":[{"id":"1.230178173","rc":[{"atb":[[10.5,23.8]],"id":52385911},{"atb":[[7.2,18.63]],"id":52385893}],"con":true,"img":false}]}
{"op":"mcm","clk":"11550712217","pt":1719502288773,"mc":[{"id":"1.230178173","rc":[{"atb":[[10,0]],"id":52385893}],"con":true,"img":false}]}
{"op":"mcm","clk":"11550712465","pt":1719502292287,"mc":[{"id":"1.230178173","rc":[{"atb":[[15,0]],"id":52385910},{"atb":[[13,0]],"id":52385906},{"atb":[[13,0]],"id":52385889},{"atb":[[24,0]],"id":52385883},{"atb":[[14,0]],"id":52385904},{"atb":[[11,0]],"id":52385913},{"atb":[[15,0]],"id":52385897},{"atb":[[13,0]],"id":52385891}],"con":true,"img":false}]}
{"op":"mcm","clk":"11550712474","pt":1719502292386,"mc":[{"id":"1.230178173","rc":[{"atb":[[14,8]],"id":52385910},{"atb":[[12,8]],"id":52385906},{"atb":[[12,8]],"id":52385889},{"atb":[[20,5]],"id":52385883},{"atb":[[13,7]],"id":52385904},{"atb":[[10,9]],"id":52385913},{"atb":[[14,8]],"id":52385897},{"atb":[[12,7]],"id":52385891}],"con":true,"img":false}]}
{"op":"mcm","clk":"11550712542","pt":1719502293522,"mc":[{"id":"1.230178173","rc":[{"atb":[[1.85,90.6]],"id":52385906},{"atb":[[3.15,46.51],[3.65,0]],"id":52385913},{"atb":[[21,5],[22,18.7]],"id":52385886},{"atb":[[6.4,0],[7.4,13]],"id":52385884},{"atb":[[2.36,73.53],[2.68,0]],"id":52385903},{"atb":[[2.92,0],[2.74,57.47]],"id":52385899}],"con":true,"img":false}]}
{"op":"mcm","clk":"11550712554","pt":1719502293575,"mc":[{"id":"1.230178173","rc":[{"atb":[[6.2,13],[5.5,0]],"id":52385910},{"atb":[[2.4,0]],"id":52385906},{"atb":[[10.5,0],[15,7.14]],"id":52385883},{"atb":[[11,10],[7.8,0]],"id":52385885},{"atb":[[10,11],[6.6,0]],"id":52385896}],"con":true,"img":false}]}
{"op":"mcm","clk":"11550712608","pt":1719502294299,"mc":[{"id":"1.230178173","rc":[{"atb":[[14,0],[15.5,14.9]],"id":52385907}],"con":true,"img":false}]}
{"op":"mcm","clk":"11550712694","pt":1719502295285,"mc":[{"id":"1.230178173","rc":[{"atb":[[17.5,6.06],[15.5,0]],"id":52385920}],"con":true,"img":false}]}
{"op":"mcm","clk":"11550712720","pt":1719502295593,"mc":[{"id":"1.230178173","rc":[{"atb":[[7.2,2.5],[10,11.11]],"id":52385893}],"con":true,"img":false}]}
{"op":"mcm","clk":"11550712782","pt":1719502296370,"mc":[{"id":"1.230178173","rc":[{"atb":[[19,15]],"id":52385910},{"atb":[[17,16.86]],"id":52385912},{"atl":[[29,16.86]],"id":52385912},{"atb":[[17,15]],"id":52385906},{"atb":[[24,20]],"id":52385920},{"atl":[[130,4.65]],"id":52385920},{"atb":[[17.5,15]],"id":52385914},{"atb":[[30,20]],"id":52385883},{"atl":[[100,6.06]],"id":52385883},{"atb":[[29,16.18]],"id":52385896},{"atl":[[27,17.4]],"id":52385890},{"atl":[[110,5.5]],"id":52385898},{"atl":[[110,5.5]],"id":52385900},{"atl":[[50,12.24]],"id":52385913},{"atl":[[95,6.38]],"id":52385907},{"atb":[[26,20]],"id":52385919},{"atl":[[130,4.65]],"id":52385919},{"atl":[[70,8.7]],"id":52385882},{"atl":[[150,4.03]],"id":52385884},{"atl":[[36,17.14]],"id":52385897},{"atb":[[18,15]],"id":52385891},{"atl":[[36,15]],"id":52385891},{"atb":[[19,22]],"id":52385893},{"atb":[[27,15]],"id":52385903},{"atb":[[25,15]],"id":52385905},{"atb":[[18.5,15]],"id":52385899}],"con":true,"img":false}]}
{"op":"mcm","clk":"11550712789","pt":1719502296475,"mc":[{"id":"1.230178173","rc":[{"atl":[[38,15]],"id":52385910},{"atb":[[9.2,0]],"id":52385912},{"atl":[[65,2],[420,0]],"id":52385912},{"atb":[[11.5,0]],"id":52385906},{"atl":[[34,15]],"id":52385906},{"atb":[[21,20]],"id":52385918},{"atl":[[90,6.74]],"id":52385918},{"atb":[[16,0]],"id":52385920},{"atl":[[280,2],[650,0],[950,0]],"id":52385920},{"atb":[[12,23]],"id":52385889},{"atl":[[32,15]],"id":52385889},{"atb":[[9.2,0]],"id":52385914},{"atl":[[34,15]],"id":52385914},{"atl":[[620,0],[180,2]],"id":52385883},{"atl":[[75,8.11]],"id":52385885},{"atb":[[16.5,0]],"id":52385896},{"atl":[[90,6.74]],"id":52385896},{"atl":[[30,0]],"id":52385890},{"atl":[[19,27.8]],"id":52385892},{"atb":[[18.5,16.56]],"id":52385904},{"atl":[[40,15.38]],"id":52385904},{"atb":[[24,15]],"id":52385898},{"atl":[[280,0],[580,0],[240,2]],"id":52385898},{"atb":[[28,15]],"id":52385900},{"atl":[[600,0],[780,0],[220,2]],"id":52385900},{"atl":[[21,23.8]],"id":52385911},{"atb":[[15.5,20]],"id":52385913},{"atl":[[90,2],[100,0],[480,0]],"id":52385913},{"atb":[[24,15]],"id":52385907},{"atl":[[570,0],[760,0],[210,2]],"id":52385907},{"atb":[[30,20]],"id":52385886},{"atl":[[180,3.35]],"id":52385886},{"atb":[[17,0]],"id":52385919},{"atl":[[590,0],[190,2],[860,0]],"id":52385919},{"atb":[[19,22]],"id":52385921},{"atl":[[70,8.7]],"id":52385921},{"atb":[[18.5,15]],"id":52385882},{"atl":[[530,0],[95,7],[480,0]],"id":52385882},{"atb":[[28,20]],"id":52385884},{"atl":[[300,2],[350,0],[770,0]],"id":52385884},{"atb":[[29,15]],"id":52385917},{"atl":[[150,4.03]],"id":52385917},{"atb":[[16,26]],"id":52385897},{"atl":[[46,0]],"id":52385897},{"atb":[[11.5,0]],"id":52385891},{"atl":[[90,2],[110,0],[510,0]],"id":52385891},{"atl":[[60,10.17]],"id":52385893},{"atb":[[17.5,0]],"id":52385903},{"atl":[[80,7.59]],"id":52385903},{"atb":[[14.5,0]],"id":52385905},{"atl":[[75,8.11]],"id":52385905},{"atb":[[13,8]],"id":52385899},{"atl":[[40,15]],"id":52385899}],"con":true,"img":false}]}
{"op":"mcm","clk":"11550712795","pt":1719502296577,"mc":[{"id":"1.230178173","rc":[{"atb":[[12.5,0]],"id":52385910},{"atl":[[75,7],[460,0],[470,0]],"id":52385910},{"atl":[[75,2],[430,0],[440,0]],"id":52385906},{"atb":[[9.6,0]],"id":52385918},{"atl":[[130,7],[760,0],[510,0]],"id":52385918},{"atb":[[10.5,0]],"id":52385889},{"atl":[[410,0],[55,7],[470,0]],"id":52385889},{"atl":[[550,0],[75,7],[460,0]],"id":52385914},{"atb":[[21,2.5]],"id":52385883},{"atl":[[630,0]],"id":52385883},{"atl":[[540,0],[120,2]],"id":52385885},{"atl":[[550,2],[140,2]],"id":52385896},{"atb":[[12.5,0]],"id":52385904},{"atl":[[80,2],[470,0]],"id":52385904},{"atb":[[12.5,0]],"id":52385898},{"atb":[[17.5,0]],"id":52385900},{"atl":[[26,0]],"id":52385911},{"atb":[[10.5,2.5]],"id":52385913},{"atb":[[15.5,6.9]],"id":52385907},{"atb":[[22,2.5]],"id":52385886},{"atl":[[320,2],[710,0],[960,0]],"id":52385886},{"atl":[[95,7],[460,0]],"id":52385921},{"atb":[[25,0]],"id":52385884},{"atb":[[21,0]],"id":52385917},{"atl":[[620,0],[230,2],[940,0]],"id":52385917},{"atb":[[11.5,0]],"id":52385897},{"atb":[[14.5,0]],"id":52385893},{"atl":[[520,0],[640,0],[100,2]],"id":52385893},{"atl":[[550,0],[160,2],[200,0]],"id":52385903},{"atl":[[520,0],[150,2],[180,0]],"id":52385905},{"atl":[[80,2],[450,0],[460,0]],"id":52385899}],"con":true,"img":false}]}
{"op":"mcm","clk":"11550712802","pt":1719502296686,"mc":[{"id":"1.230178173","rc":[{"atl":[[550,0]],"id":52385896},{"atl":[[29,0]],"id":52385892},{"atb":[[12.5,0]],"id":52385921},{"atl":[[650,0]],"id":52385921},{"atb":[[12.5,0]],"id":52385882}],"con":true,"img":false}]}
{"op":"mcm","clk":"11550712847","pt":1719502297407,"mc":[{"id":"1.230178173","rc":[{"atb":[[12,0]],"id":52385912},{"atb":[[12,0]],"id":52385921},{"atb":[[13,0]],"id":52385899}],"con":true,"img":false}]}
{"op":"mcm","clk":"11550712854","pt":1719502297509,"mc":[{"id":"1.230178173","rc":[{"atb":[[14,8]],"id":52385912},{"atb":[[13,6]],"id":52385921},{"atb":[[16,8]],"id":52385899}],"con":true,"img":false}]}
{"op":"mcm","clk":"11550712863","pt":1719502297578,"mc":[{"id":"1.230178173","rc":[{"atb":[[7.4,18.12],[8.8,0]],"id":52385921}],"con":true,"img":false}]}
{"op":"mcm","clk":"11550712871","pt":1719502297682,"mc":[{"id":"1.230178173","rc":[{"atb":[[7.4,2.5],[8.8,12.82]],"id":52385921}],"con":true,"img":false}]}
{"op":"mcm","clk":"11550712904","pt":1719502298087,"mc":[{"id":"1.230178173","rc":[{"atb":[[11,31.8]],"id":52385911}],"con":true,"img":false}]}
{"op":"mcm","clk":"11550712919","pt":1719502298286,"mc":[{"id":"1.230178173","rc":[{"atb":[[10.5,0]],"id":52385911}],"con":true,"img":false}]}
{"op":"mcm","clk":"11550712927","pt":1719502298389,"mc":[{"id":"1.230178173","rc":[{"atb":[[20,0]],"id":52385907},{"atb":[[30,0]],"id":52385886},{"atb":[[29,0]],"id":52385917}],"con":true,"img":false}]}
{"op":"mcm","clk":"11550712937","pt":1719502298496,"mc":[{"id":"1.230178173","rc":[{"atb":[[19,0]],"id":52385910},{"atb":[[30,0]],"id":52385883},{"atb":[[29,0]],"id":52385896},{"atb":[[29,11.7]],"id":52385886},{"atb":[[28,0]],"id":52385884},{"atb":[[28,13.06]],"id":52385917},{"atb":[[27,0]],"id":52385903}],"con":true,"img":false}]}
{"op":"mcm","clk":"11550712944","pt":1719502298597,"mc":[{"id":"1.230178173","rc":[{"atb":[[15.5,19]],"id":52385910},{"atb":[[20,0]],"id":52385920},{"atb":[[26,15]],"id":52385883},{"atb":[[28,15]],"id":52385896},{"atb":[[4.6,0],[5.5,22.22]],"id":52385904},{"atb":[[11,8]],"id":52385911},{"atb":[[29,0]],"id":52385886},{"atb":[[27,18.06]],"id":52385884},{"atb":[[28,0]],"id":52385917},{"atl":[[210,7],[230,0]],"id":52385917},{"atb":[[7.2,12],[6,2]],"id":52385897},{"atb":[[26,15]],"id":52385903},{"atb":[[1.75,89.75]],"id":52385905}],"con":true,"img":false}]}
{"op":"mcm","clk":"11550712955","pt":1719502298709,"mc":[{"id":"1.230178173","rc":[{"atb":[[32,16.7]],"id":52385886}],"con":true,"img":false}]}
{"op":"mcm","clk":"11550712964","pt":1719502298805,"mc":[{"id":"1.230178173","rc":[{"atb":[[10.5,23.8]],"id":52385911},{"atb":[[32,18.06]],"id":52385917}],"con":true,"img":false}]}
{"op":"mcm","clk":"11550712973","pt":1719502298910,"mc":[{"id":"1.230178173","rc":[{"atb":[[12,0]],"id":52385914},{"atb":[[32,0]],"id":52385886},{"atb":[[20,0]],"id":52385884},{"atb":[[24,0]],"id":52385917}],"con":true,"img":false}]}
{"op":"mcm","clk":"11550712981","pt":1719502299010,"mc":[{"id":"1.230178173","rc":[{"atb":[[10,9]],"id":52385914},{"atb":[[24,5]],"id":52385884},{"atb":[[32,0],[20,5]],"id":52385917}],"con":true,"img":false}]}
{"op":"mcm","clk":"11550712990","pt":1719502299078,"mc":[{"id":"1.230178173","rc":[{"atb":[[30,16.7]],"id":52385886},{"atb":[[6.2,19.23],[7.4,0]],"id":52385884},{"atb":[[30,13.06]],"id":52385917}],"con":true,"img":false}]}
{"op":"mcm","clk":"11550713008","pt":1719502299275,"mc":[{"id":"1.230178173","rc":[{"atb":[[19,0]],"id":52385893}],"con":true,"img":false}]}
{"op":"mcm","clk":"11550713014","pt":1719502299377,"mc":[{"id":"1.230178173","rc":[{"atl":[[38,0]],"id":52385910},{"atl":[[36,0]],"id":52385897},{"atb":[[18.5,22]],"id":52385893},{"atl":[[40,0]],"id":52385899}],"con":true,"img":false}]}
{"op":"mcm","clk":"11550713021","pt":1719502299480,"mc":[{"id":"1.230178173","rc":[{"atl":[[38,15]],"id":52385897},{"atb":[[18.5,0]],"id":52385893},{"atl":[[42,14.63]],"id":52385899}],"con":true,"img":false}]}
{"op":"mcm","clk":"11550713027","pt":1719502299583,"mc":[{"id":"1.230178173","rc":[{"atl":[[40,15.38]],"id":52385910},{"atb":[[16.5,22]],"id":52385893}],"con":true,"img":false}]}
{"op":"mcm","clk":"11550713034","pt":1719502299687,"mc":[{"id":"1.230178173","rc":[{"atl":[[40,0]],"id":52385910},{"atl":[[38,0]],"id":52385897},{"atl":[[40,15.38],[42,0]],"id":52385899}],"con":true,"img":false}]}
{"op":"mcm","clk":"11550713041","pt":1719502299791,"mc":[{"id":"1.230178173","rc":[{"atl":[[42,14.63]],"id":52385910},{"atl":[[32,0]],"id":52385889},{"atl":[[40,15]],"id":52385897}],"con":true,"img":false}]}
{"op":"mcm","clk":"11550713049","pt":1719502299996,"mc":[{"id":"1.230178173","rc":[{"atb":[[21,0]],"id":52385918},{"atl":[[34,15]],"id":52385889},{"atb":[[26,20]],"id":52385885},{"atl":[[40,0]],"id":52385897}],"con":true,"img":false}]}
{"op":"mcm","clk":"11550713058","pt":1719502300105,"mc":[{"id":"1.230178173","rc":[{"atb":[[28,0]],"id":52385900}],"con":true,"img":false}]}
{"op":"mcm","clk":"11550713067","pt":1719502300205,"mc":[{"id":"1.230178173","rc":[{"atb":[[20,23.48]],"id":52385918},{"atl":[[34,0]],"id":52385889},{"atb":[[21,0]],"id":52385885},{"atl":[[42,14.63]],"id":52385897}],"con":true,"img":false}]}
{"op":"mcm","clk":"11550713075","pt":1719502300310,"mc":[{"id":"1.230178173","rc":[{"atb":[[1.85,0],[2.96,51.02]],"id":52385906},{"atl":[[42,14.63]],"id":52385889},{"atb":[[27,15]],"id":52385900},{"atb":[[3.85,35.09],[3.15,0]],"id":52385913},{"atb":[[2.36,0],[6.4,18.52]],"id":52385903},{"atb":[[3.85,35.09],[2.74,0]],"id":52385899}],"con":true,"img":false}]}
{"op":"mcm","clk":"11550713082","pt":1719502300412,"mc":[{"id":"1.230178173","rc":[{"atb":[[20,0]],"id":52385918},{"atl":[[410,2],[55,5]],"id":52385889}],"con":true,"img":false}]}
{"op":"mcm","clk":"11550713091","pt":1719502300464,"mc":[{"id":"1.230178173","rc":[{"atb":[[19.5,27.48]],"id":52385918},{"atb":[[17.5,0],[11,12.5]],"id":52385920},{"atl":[[410,0],[55,7]],"id":52385889},{"atb":[[27,0]],"id":52385900},{"atl":[[40,0]],"id":52385899}],"con":true,"img":false}]}
{"op":"mcm","clk":"11550713099","pt":1719502300569,"mc":[{"id":"1.230178173","rc":[{"atb":[[26,0]],"id":52385885},{"atb":[[22,21]],"id":52385900},{"atl":[[42,14.63]],"id":52385899}],"con":true,"img":false}]}
{"op":"mcm","clk":"11550713105","pt":1719502300673,"mc":[{"id":"1.230178173","rc":[{"atb":[[19.5,0]],"id":52385918},{"atb":[[21,15]],"id":52385885}],"con":true,"img":false}]}
{"op":"mcm","clk":"11550713114","pt":1719502300777,"mc":[{"id":"1.230178173","rc":[{"atb":[[20,27.48]],"id":52385918}],"con":true,"img":false}]}
{"op":"mcm","clk":"11550713216","pt":1719502302388,"mc":[{"id":"1.230178173","rc":[{"atb":[[10,0]],"id":52385913},{"atb":[[12,0]],"id":52385891}],"con":true,"img":false}]}
{"op":"mcm","clk":"11550713229","pt":1719502302493,"mc":[{"id":"1.230178173","rc":[{"atb":[[11,9]],"id":52385913},{"atb":[[13,7]],"id":52385891}],"con":true,"img":false}]}
{"op":"mcm","clk":"11550713249","pt":1719502302811,"mc":[{"id":"1.230178173","rc":[{"atb":[[20,0]],"id":52385918},{"atb":[[34,18.18],[28,0]],"id":52385896}],"con":true,"img":false}]}
{"op":"mcm","clk":"11550713259","pt":1719502302912,"mc":[{"id":"1.230178173","rc":[{"atb":[[20,27.48]],"id":52385918},{"atl":[[42,0]],"id":52385899}],"con":true,"img":false}]}
{"op":"mcm","clk":"11550713268","pt":1719502302978,"mc":[{"id":"1.230178173","rc":[{"atl":[[46,13.33]],"id":52385899}],"con":true,"img":false}]}
{"op":"mcm","clk":"11550713284","pt":1719502303175,"mc":[{"id":"1.230178173","rc":[{"atb":[[11,31.8]],"id":52385911},{"atl":[[46,0]],"id":52385899}],"con":true,"img":false}]}
{"op":"mcm","clk":"11550713294","pt":1719502303281,"mc":[{"id":"1.230178173","rc":[{"atb":[[10.5,0]],"id":52385911},{"atl":[[50,12.24]],"id":52385899}],"con":true,"img":false}]}
{"op":"mcm","clk":"11550713343","pt":1719502303906,"mc":[{"id":"1.230178173","rc":[{"atb":[[6.2,0],[4.7,13]],"id":52385910},{"atb":[[3.9,0],[2.34,72.82]],"id":52385912},{"atb":[[2.96,0],[1.17,90.6]],"id":52385906},{"atb":[[8,14.29],[20,0]],"id":52385918},{"atl":[[280,0],[220,7]],"id":52385920},{"atb":[[11,0],[8.4,10]],"id":52385885},{"atb":[[34,0]],"id":52385896},{"atb":[[5.5,0],[4.4,29.41]],"id":52385904},{"atl":[[200,2],[220,0]],"id":52385900},{"atb":[[5.2,0],[4.4,29.41]],"id":52385911},{"atb":[[3.85,0],[1.88,113.64]],"id":52385913},{"atl":[[180,2],[210,0]],"id":52385907},{"atb":[[19,0],[8.8,0]],"id":52385921},{"atl":[[150,0]],"id":52385917},{"atb":[[7.2,0],[5.4,22.73]],"id":52385897},{"atb":[[6.4,0]],"id":52385903},{"atb":[[1.75,0]],"id":52385905},{"atb":[[3.85,0],[1.08,153.26]],"id":52385899},{"atl":[[80,0],[95,2]],"id":52385899}],"con":true,"img":false}]}
{"op":"mcm","clk":"11550713350","pt":1719502304008,"mc":[{"id":"1.230178173","rc":[{"atb":[[16,32.48],[10.5,2.5]],"id":52385918},{"atb":[[17.5,0]],"id":52385914},{"atb":[[12,9.09],[15,0]],"id":52385883},{"atb":[[10,0],[5.9,20.41]],"id":52385896},{"atl":[[140,0],[170,2]],"id":52385896},{"atb":[[7.2,16.13]],"id":52385921},{"atb":[[10,0],[8.8,12.82]],"id":52385893},{"atb":[[2.3,76.92]],"id":52385903}],"con":true,"img":false}]}
{"op":"mcm","clk":"11550713356","pt":1719502304125,"mc":[{"id":"1.230178173","rc":[{"atb":[[10.5,32]],"id":52385914},{"atb":[[29,21.43]],"id":52385896},{"atb":[[13,37.4]],"id":52385921},{"atl":[[140,4.32],[570,2],[210,5]],"id":52385917}],"con":true,"img":false}]}
{"op":"mcm","clk":"11550713361","pt":1719502304167,"mc":[{"id":"1.230178173","rc":[{"atl":[[570,0],[210,7]],"id":52385917},{"atl":[[36,0]],"id":52385891}],"con":true,"img":false}]}
{"op":"mcm","clk":"11550713368","pt":1719502304283,"mc":[{"id":"1.230178173","rc":[{"atl":[[50,12.24]],"id":52385891}],"con":true,"img":false}]}
{"op":"mcm","clk":"11550713393","pt":1719502304754,"mc":[{"id":"1.230178173","rc":[{"atb":[[26,9.48]],"id":52385886}],"con":true,"img":false}]}
{"op":"mcm","clk":"11550713403","pt":1719502304888,"mc":[{"id":"1.230178173","rc":[{"atb":[[26,0]],"id":52385886}],"con":true,"img":false}]}
{"op":"mcm","clk":"11550713436","pt":1719502305655,"mc":[{"id":"1.230178173","rc":[{"atl":[[140,0]],"id":52385917}],"con":true,"img":false}]}
{"op":"mcm","clk":"11550713444","pt":1719502305663,"mc":[{"id":"1.230178173","rc":[{"atb":[[30,0]],"id":52385886},{"atl":[[150,4.03]],"id":52385917}],"con":true,"img":false}]}
{"op":"mcm","clk":"11550713452","pt":1719502305671,"mc":[{"id":"1.230178173","rc":[{"atb":[[19,10.56],[27,16.7]],"id":52385886},{"atl":[[170,4.5],[210,5]],"id":52385917}],"con":true,"img":false}]}
{"op":"mcm","clk":"11550713458","pt":1719502305707,"mc":[{"id":"1.230178173","rc":[{"atb":[[21,0]],"id":52385886}],"con":true,"img":false}]}
{"op":"mcm","clk":"11550713464","pt":1719502305811,"mc":[{"id":"1.230178173","rc":[{"atb":[[6.2,0],[11,10]],"id":52385884},{"atl":[[170,2.5],[200,2]],"id":52385917}],"con":true,"img":false}]}
{"op":"mcm","clk":"11550713473","pt":1719502305921,"mc":[{"id":"1.230178173","rc":[{"atl":[[200,0],[210,7]],"id":52385917}],"con":true,"img":false}]}
{"op":"mcm","clk":"11550713522","pt":1719502306799,"mc":[{"id":"1.230178173","rc":[{"atb":[[18,26]],"id":52385912},{"atl":[[29,0]],"id":52385912}],"con":true,"img":false}]}
{"op":"mcm","clk":"11550713529","pt":1719502306905,"mc":[{"id":"1.230178173","rc":[{"atl":[[42,0]],"id":52385910},{"atb":[[17,0]],"id":52385912},{"atl":[[30,20.69]],"id":52385912},{"atl":[[27,0]],"id":52385890}],"con":true,"img":false}]}
{"op":"mcm","clk":"11550713535","pt":1719502307015,"mc":[{"id":"1.230178173","rc":[{"atl":[[75,5],[80,2],[44,13.95]],"id":52385910},{"atl":[[28,17.4]],"id":52385890}],"con":true,"img":false}]}
{"op":"mcm","clk":"11550713555","pt":1719502307284,"mc":[{"id":"1.230178173","rc":[{"atl":[[30,0]],"id":52385912}],"con":true,"img":false}]}
{"op":"mcm","clk":"11550713563","pt":1719502307427,"mc":[{"id":"1.230178173","rc":[{"atl":[[36,15]],"id":52385912}],"con":true,"img":false}]}
{"op":"mcm","clk":"11550713593","pt":1719502307690,"mc":[{"id":"1.230178173","rc":[{"atl":[[36,0]],"id":52385912}],"con":true,"img":false}]}
{"op":"mcm","clk":"11550713602","pt":1719502307793,"mc":[{"id":"1.230178173","rc":[{"atl":[[34,18.18]],"id":52385912}],"con":true,"img":false}]}
{"op":"mcm","clk":"11550713624","pt":1719502308101,"mc":[{"id":"1.230178173","rc":[{"atl":[[34,0]],"id":52385912}],"con":true,"img":false}]}
{"op":"mcm","clk":"11550713632","pt":1719502308206,"mc":[{"id":"1.230178173","rc":[{"atl":[[38,15]],"id":52385912}],"con":true,"img":false}]}
{"op":"mcm","clk":"11550713705","pt":1719502309194,"mc":[{"id":"1.230178173","rc":[{"atb":[[3.9,13],[4.7,0]],"id":52385910},{"atb":[[1.72,72.82],[2.34,0]],"id":52385912},{"atb":[[1.17,0]],"id":52385906},{"atl":[[34,0]],"id":52385906},{"atb":[[8.2,0],[7.4,15.62]],"id":52385914},{"atb":[[9,10],[12,0]],"id":52385883},{"atl":[[180,0],[230,2]],"id":52385883},{"atb":[[6.6,10],[8.4,0]],"id":52385885},{"atl":[[150,2],[120,0]],"id":52385885},{"atb":[[3.55,39.22]],"id":52385896},{"atb":[[16,23.4]],"id":52385890},{"atb":[[22,0]],"id":52385900},{"atb":[[1.25,150],[1.88,0]],"id":52385913},{"atl":[[95,5],[100,2]],"id":52385882},{"atb":[[11,0],[8.4,13.51]],"id":52385884},{"atb":[[15,0]],"id":52385917},{"atb":[[2.3,0]],"id":52385903},{"atl":[[160,0],[200,2]],"id":52385903},{"atb":[[1.08,0]],"id":52385899}],"con":true,"img":false}]}
{"op":"mcm","clk":"11550713711","pt":1719502309296,"mc":[{"id":"1.230178173","rc":[{"atb":[[22,26],[15.5,0]],"id":52385910},{"atb":[[1.61,90.6]],"id":52385906},{"atl":[[75,0],[44,13.95],[90,2]],"id":52385906},{"atl":[[55,5],[60,2]],"id":52385889},{"atb":[[5.9,0]],"id":52385896},{"atb":[[9.8,0]],"id":52385890},{"atb":[[5.3,23.26],[13,0],[4.4,0]],"id":52385904},{"atb":[[20,0],[27,21]],"id":52385900},{"atl":[[290,2],[320,0]],"id":52385886},{"atb":[[14.5,2.5]],"id":52385919},{"atb":[[27,0]],"id":52385884},{"atb":[[12.5,8.7],[30,0]],"id":52385917},{"atb":[[6,12],[5.4,0]],"id":52385897},{"atb":[[8.6,0],[9.8,11.36]],"id":52385891},{"atb":[[17,0]],"id":52385893},{"atb":[[2.44,69.44],[26,0]],"id":52385903},{"atb":[[1.24,153.26]],"id":52385899}],"con":true,"img":false}]}
{"op":"mcm","clk":"11550713717","pt":1719502309399,"mc":[{"id":"1.230178173","rc":[{"atb":[[14,7]],"id":52385904},{"atb":[[18,8.5],[27,0]],"id":52385900},{"atb":[[12,9.09]],"id":52385919},{"atb":[[26,18.06]],"id":52385884},{"atb":[[29,13.06]],"id":52385917},{"atb":[[7.2,18.63],[8.8,0],[15,6]],"id":52385893},{"atb":[[25,15]],"id":52385903}],"con":true,"img":false}]}
{"op":"mcm","clk":"11550713722","pt":1719502309503,"mc":[{"id":"1.230178173","rc":[{"atb":[[16,5],[19.5,21],[15.5,6.9]],"id":52385900}],"con":true,"img":false}]}
{"op":"mcm","clk":"11550713728","pt":1719502309605,"mc":[{"id":"1.230178173","rc":[{"atb":[[26,0]],"id":52385884},{"atb":[[29,0]],"id":52385917},{"atb":[[25,0]],"id":52385903}],"con":true,"img":false}]}
{"op":"mcm","clk":"11550713736","pt":1719502309710,"mc":[{"id":"1.230178173","rc":[{"atb":[[25,20]],"id":52385884},{"atb":[[28,18.06]],"id":52385917},{"atb":[[24,22]],"id":52385903}],"con":true,"img":false}]}
{"op":"mcm","clk":"11550713749","pt":1719502309868,"mc":[{"id":"1.230178173","rc":[{"atb":[[26,0]],"id":52385883}],"con":true,"img":false}]}
{"op":"mcm","clk":"11550713757","pt":1719502310020,"mc":[{"id":"1.230178173","rc":[{"atb":[[25,20]],"id":52385883}],"con":true,"img":false}]}
{"op":"mcm","clk":"11550713767","pt":1719502310185,"mc":[{"id":"1.230178173","rc":[{"atb":[[25,0]],"id":52385883},{"atb":[[14.5,13.27]],"id":52385913}],"con":true,"img":false}]}
{"op":"mcm","clk":"11550713775","pt":1719502310279,"mc":[{"id":"1.230178173","rc":[{"atb":[[36,17.14]],"id":52385883}],"con":true,"img":false}]}
{"op":"mcm","clk":"11550713781","pt":1719502310386,"mc":[{"id":"1.230178173","rc":[{"atb":[[14.5,0]],"id":52385913},{"atb":[[27,0]],"id":52385886}],"con":true,"img":false}]}
{"op":"mcm","clk":"11550713790","pt":1719502310488,"mc":[{"id":"1.230178173","rc":[{"atb":[[26,16.7]],"id":52385886}],"con":true,"img":false}]}
{"op":"mcm","clk":"11550713807","pt":1719502310695,"mc":[{"id":"1.230178173","rc":[{"atb":[[26,0]],"id":52385886}],"con":true,"img":false}]}
{"op":"mcm","clk":"11550713816","pt":1719502310800,"mc":[{"id":"1.230178173","rc":[{"atl":[[36,17.14]],"id":52385912},{"atb":[[25,24]],"id":52385920},{"atl":[[85,7.14]],"id":52385920},{"atb":[[14,32]],"id":52385914},{"atb":[[38,16.22]],"id":52385883},{"atb":[[34,18.18]],"id":52385896},{"atl":[[27,10.4]],"id":52385890},{"atb":[[24,0],[26,20]],"id":52385898},{"atl":[[100,6.06]],"id":52385900},{"atl":[[90,6.74]],"id":52385907},{"atb":[[34,16.7]],"id":52385886},{"atb":[[28,19.3]],"id":52385919},{"atl":[[60,10.17]],"id":52385919},{"atl":[[150,0],[75,8.11]],"id":52385917},{"atb":[[18.5,24]],"id":52385891},{"atb":[[17.5,22]],"id":52385893},{"atb":[[30,20.69]],"id":52385903},{"atb":[[26,22]],"id":52385905},{"atb":[[18.5,0],[19,26]],"id":52385899}],"con":true,"img":false}]}
{"op":"mcm","clk":"11550713825","pt":1719502310908,"mc":[{"id":"1.230178173","rc":[{"atl":[[42,14.63]],"id":52385910},{"atl":[[38,0]],"id":52385912},{"atb":[[17,0]],"id":52385906},{"atl":[[40,15.38]],"id":52385906},{"atl":[[28,22.22]],"id":52385918},{"atb":[[24,0]],"id":52385920},{"atl":[[130,0],[180,4.5],[220,5]],"id":52385920},{"atb":[[10.5,0]],"id":52385914},{"atl":[[27,23.08]],"id":52385914},{"atb":[[36,0]],"id":52385883},{"atb":[[29,0]],"id":52385896},{"atl":[[28,0]],"id":52385890},{"atb":[[25,21]],"id":52385900},{"atl":[[110,0]],"id":52385900},{"atb":[[16.5,28]],"id":52385913},{"atl":[[95,0]],"id":52385907},{"atl":[[120,5.04]],"id":52385886},{"atb":[[26,0]],"id":52385919},{"atl":[[130,0],[140,4.5],[190,0]],"id":52385919},{"atb":[[23,26]],"id":52385882},{"atb":[[34,18.18]],"id":52385884},{"atl":[[170,4.5]],"id":52385917},{"atb":[[21,26]],"id":52385897},{"atb":[[18,0]],"id":52385891},{"atb":[[16.5,0]],"id":52385893},{"atl":[[27,22]],"id":52385893},{"atb":[[24,0]],"id":52385903},{"atb":[[25,0]],"id":52385905},{"atl":[[70,8.7]],"id":52385905},{"atl":[[46,13.33]],"id":52385899}],"con":true,"img":false}]}
{"op":"mcm","clk":"11550713830","pt":1719502311008,"mc":[{"id":"1.230178173","rc":[{"atl":[[44,0]],"id":52385910},{"atb":[[16.5,21]],"id":52385906},{"atl":[[40,0]],"id":52385906},{"atl":[[130,5],[75,2],[90,0],[28,0]],"id":52385918},{"atl":[[34,0],[75,5],[60,2]],"id":52385914},{"atb":[[26,0]],"id":52385898},{"atb":[[19.5,0]],"id":52385900},{"atl":[[180,0]],"id":52385886},{"atl":[[60,0]],"id":52385919},{"atb":[[25,0]],"id":52385884},{"atl":[[210,5]],"id":52385917},{"atb":[[16,0]],"id":52385897},{"atb":[[17.5,0]],"id":52385893},{"atl":[[60,0]],"id":52385893},{"atl":[[50,0]],"id":52385899}],"con":true,"img":false}]}
{"op":"mcm","clk":"11550713842","pt":1719502311113,"mc":[{"id":"1.230178173","rc":[{"atl":[[42,14.63],[44,0]],"id":52385906},{"atl":[[75,0],[90,2],[100,6.06]],"id":52385918},{"atb":[[23,15]],"id":52385898},{"atb":[[15.5,0]],"id":52385913},{"atl":[[140,2.5],[150,4.03],[180,7]],"id":52385919},{"atb":[[18.5,0]],"id":52385882},{"atb":[[8.6,17]],"id":52385893},{"atl":[[75,0]],"id":52385905}],"con":true,"img":false}]}
{"op":"mcm","clk":"11550713848","pt":1719502311215,"mc":[{"id":"1.230178173","rc":[{"atl":[[90,0],[95,4.5]],"id":52385918},{"atl":[[140,4.5],[180,5]],"id":52385919},{"atb":[[26,0]],"id":52385905}],"con":true,"img":false}]}
{"op":"mcm","clk":"11550713858","pt":1719502311319,"mc":[{"id":"1.230178173","rc":[{"atl":[[95,2.5],[100,8.06]],"id":52385918},{"atl":[[140,2.5],[180,7]],"id":52385919},{"atl":[[34,18.18]],"id":52385921},{"atl":[[75,0]],"id":52385917},{"atb":[[25,15]],"id":52385905}],"con":true,"img":false}]}
{"op":"mcm","clk":"11550713864","pt":1719502311377,"mc":[{"id":"1.230178173","rc":[{"atl":[[34,0],[70,0],[75,4.5],[95,5]],"id":52385921},{"atl":[[160,3.77],[170,2.5],[210,7]],"id":52385917},{"atl":[[46,0]],"id":52385899}],"con":true,"img":false}]}
{"op":"mcm","clk":"11550713872","pt":1719502311487,"mc":[{"id":"1.230178173","rc":[{"atl":[[65,9.38]],"id":52385921},{"atl":[[60,10.17]],"id":52385899}],"con":true,"img":false}]}
{"op":"mcm","clk":"11550713936","pt":1719502312308,"mc":[{"id":"1.230178173","rc":[{"atb":[[10,0]],"id":52385914}],"con":true,"img":false}]}
{"op":"mcm","clk":"11550713945","pt":1719502312412,"mc":[{"id":"1.230178173","rc":[{"atb":[[11,9]],"id":52385914}],"con":true,"img":false}]}
{"op":"mcm","clk":"11550713968","pt":1719502312786,"mc":[{"id":"1.230178173","rc":[{"atl":[[18.5,34.29]],"id":52385892}],"con":true,"img":false}]}
{"op":"mcm","clk":"11550713976","pt":1719502312890,"mc":[{"id":"1.230178173","rc":[{"atb":[[36,15]],"id":52385886}],"con":true,"img":false}]}
{"op":"mcm","clk":"11550713982","pt":1719502312994,"mc":[{"id":"1.230178173","rc":[{"atl":[[19,0]],"id":52385892},{"atb":[[32,19.35]],"id":52385903}],"con":true,"img":false}]}
{"op":"mcm","clk":"11550713992","pt":1719502313088,"mc":[{"id":"1.230178173","rc":[{"atb":[[34,0]],"id":52385886}],"con":true,"img":false}]}
{"op":"mcm","clk":"11550713999","pt":1719502313192,"mc":[{"id":"1.230178173","rc":[{"atb":[[30,0]],"id":52385903}],"con":true,"img":false}]}
{"op":"mcm","clk":"11550714040","pt":1719502313715,"mc":[{"id":"1.230178173","rc":[{"atb":[[17.5,36.36]],"id":52385893}],"con":true,"img":false}]}
{"op":"mcm","clk":"11550714049","pt":1719502313818,"mc":[{"id":"1.230178173","rc":[{"atb":[[8.6,0]],"id":52385893},{"atl":[[46,13.33]],"id":52385899}],"con":true,"img":false}]}
{"op":"mcm","clk":"11550714064","pt":1719502313989,"mc":[{"id":"1.230178173","rc":[{"atl":[[27,0]],"id":52385914},{"atl":[[60,0]],"id":52385899}],"con":true,"img":false}]}
{"op":"mcm","clk":"11550714074","pt":1719502314090,"mc":[{"id":"1.230178173","rc":[{"atl":[[75,7],[28,22.22],[60,0]],"id":52385914},{"atl":[[27,0]],"id":52385893}],"con":true,"img":false}]}
{"op":"mcm","clk":"11550714079","pt":1719502314193,"mc":[{"id":"1.230178173","rc":[{"atl":[[75,5]],"id":52385914},{"atl":[[28,22]],"id":52385893}],"con":true,"img":false}]}
{"op":"mcm","clk":"11550714087","pt":1719502314289,"mc":[{"id":"1.230178173","rc":[{"atb":[[22,0]],"id":52385910},{"atb":[[18,0]],"id":52385912},{"atb":[[8,0],[17.5,20],[11,10]],"id":52385918},{"atb":[[11,2.5]],"id":52385920},{"atl":[[260,2],[85,0],[180,2.5]],"id":52385920},{"atl":[[28,0]],"id":52385914},{"atb":[[27,20]],"id":52385885},{"atl":[[140,2],[170,0]],"id":52385896},{"atb":[[16,6]],"id":52385890},{"atl":[[32,19.35]],"id":52385904},{"atb":[[1.85,117.65]],"id":52385898},{"atb":[[12,9.09],[15.5,0]],"id":52385900},{"atb":[[11,8],[4.4,0],[5.9,11.4]],"id":52385911},{"atl":[[38,16.22]],"id":52385913},{"atb":[[8.6,11.9],[15.5,0]],"id":52385907},{"atb":[[19,5],[23,4.55]],"id":52385886},{"atb":[[12,0]],"id":52385919},{"atb":[[7.2,0],[9.2,12.2],[14.5,28.76]],"id":52385921},{"atb":[[32,17.54],[12.5,0]],"id":52385917},{"atb":[[21,0]],"id":52385897},{"atl":[[36,17.14]],"id":52385891},{"atb":[[19,22]],"id":52385893},{"atl":[[28,0]],"id":52385893},{"atb":[[4.2,31.25]],"id":52385905},{"atl":[[38,16.22],[80,2],[95,0]],"id":52385899}],"con":true,"img":false}]}
{"op":"mcm","clk":"11550714093","pt":1719502314403,"mc":[{"id":"1.230178173","rc":[{"atb":[[14.5,21]],"id":52385910},{"atl":[[38,16.22]],"id":52385910},{"atb":[[14,29]],"id":52385912},{"atb":[[16,5],[17.5,0],[11,0],[7,16.67]],"id":52385918},{"atl":[[210,2.87]],"id":52385920},{"atl":[[28,22.22]],"id":52385914},{"atb":[[21,0]],"id":52385885},{"atl":[[40,0]],"id":52385904},{"atb":[[8.2,10],[1.85,0]],"id":52385898},{"atb":[[8.2,13.89],[12,0]],"id":52385900},{"atl":[[50,0]],"id":52385913},{"atb":[[8.6,0],[6.8,11.9]],"id":52385907},{"atb":[[4.3,30.3]],"id":52385919},{"atb":[[4.8,26.32],[9.2,0],[13,6]],"id":52385921},{"atb":[[23,0]],"id":52385882},{"atb":[[28,0],[8.4,10]],"id":52385917},{"atb":[[14.5,15]],"id":52385897},{"atl":[[50,0]],"id":52385891},{"atb":[[17.5,0]],"id":52385893},{"atl":[[28,0.38]],"id":52385893},{"atb":[[9.2,11],[4.2,0]],"id":52385905},{"atl":[[46,0]],"id":52385899}],"con":true,"img":false}]}
{"op":"mcm","clk":"11550714099","pt":1719502314498,"mc":[{"id":"1.230178173","rc":[{"atb":[[25,0]],"id":52385920},{"atl":[[32,0]],"id":52385904},{"atl":[[38,0]],"id":52385913}],"con":true,"img":false}]}
{"op":"mcm","clk":"11550714108","pt":1719502314600,"mc":[{"id":"1.230178173","rc":[{"atl":[[42,0]],"id":52385910},{"atb":[[16.5,36.12]],"id":52385918},{"atb":[[24,15.74]],"id":52385920},{"atl":[[28,0]],"id":52385914},{"atl":[[29,0]],"id":52385890},{"atb":[[5.7,0]],"id":52385892},{"atl":[[24,0]],"id":52385892},{"atl":[[40,15.38]],"id":52385904},{"atb":[[26,22.12]],"id":52385900},{"atb":[[6.2,0]],"id":52385911},{"atl":[[23,0]],"id":52385911},{"atl":[[85,2],[90,0],[50,12.24]],"id":52385913},{"atb":[[22,26]],"id":52385882},{"atl":[[44,0]],"id":52385897},{"atl":[[28,0]],"id":52385893}],"con":true,"img":false}]}
{"op":"mcm","clk":"11550714117","pt":1719502314708,"mc":[{"id":"1.230178173","rc":[{"atl":[[34,18.18]],"id":52385914},{"atb":[[25,0]],"id":52385900},{"atl":[[70,8.7]],"id":52385893}],"con":true,"img":false}]}
{"op":"mcm","clk":"11550714123","pt":1719502314809,"mc":[{"id":"1.230178173","rc":[{"atb":[[18.5,3.67]],"id":52385912},{"atb":[[16.5,40.12],[20,20]],"id":52385918},{"atl":[[60,2.48]],"id":52385918},{"atl":[[26,3.2]],"id":52385890},{"atb":[[10.5,6]],"id":52385892},{"atl":[[27,6.43]],"id":52385892},{"atb":[[11.5,5]],"id":52385911},{"atl":[[27,2.9]],"id":52385911},{"atl":[[40,2],[42,0]],"id":52385897},{"atb":[[13.5,3.85]],"id":52385893},{"atb":[[19.5,4]],"id":52385899},{"atl":[[44,2.4]],"id":52385899}],"con":true,"img":false}]}
{"op":"mcm","clk":"11550714130","pt":1719502314913,"mc":[{"id":"1.230178173","rc":[{"atb":[[16.5,4]],"id":52385918},{"atb":[[24,0]],"id":52385920},{"atb":[[10.5,57.26]],"id":52385892},{"atl":[[38,15]],"id":52385897}],"con":true,"img":false}]}
{"op":"mcm","clk":"11550714143","pt":1719502315120,"mc":[{"id":"1.230178173","rc":[{"atb":[[22,10.74]],"id":52385920},{"atb":[[10,8]],"id":52385892}],"con":true,"img":false}]}
{"op":"mcm","clk":"11550714151","pt":1719502315226,"mc":[{"id":"1.230178173","rc":[{"atl":[[38,0]],"id":52385910}],"con":true,"img":false}]}
{"op":"mcm","clk":"11550714161","pt":1719502315287,"mc":[{"id":"1.230178173","rc":[{"atl":[[21,0]],"id":52385911},{"atb":[[11,0]],"id":52385913},{"atl":[[65,0]],"id":52385921},{"atl":[[38,0]],"id":52385899}],"con":true,"img":false}]}
{"op":"mcm","clk":"11550714169","pt":1719502315388,"mc":[{"id":"1.230178173","rc":[{"atl":[[40,15]],"id":52385910},{"atl":[[36,0]],"id":52385912},{"atl":[[32,3.23],[22,15.8]],"id":52385911},{"atl":[[70,8.7]],"id":52385921},{"atl":[[42,14.63]],"id":52385899}],"con":true,"img":false}]}
{"op":"mcm","clk":"11550714176","pt":1719502315484,"mc":[{"id":"1.230178173","rc":[{"atl":[[75,7],[80,0]],"id":52385910},{"atl":[[27,17.34],[60,2]],"id":52385912},{"atb":[[24,4]],"id":52385920},{"atl":[[34,0]],"id":52385914},{"atl":[[34,5]],"id":52385911}],"con":true,"img":false}]}
{"op":"mcm","clk":"11550714184","pt":1719502315588,"mc":[{"id":"1.230178173","rc":[{"atl":[[65,0]],"id":52385912},{"atl":[[38,16.22]],"id":52385914}],"con":true,"img":false}]}
{"op":"mcm","clk":"11550714191","pt":1719502315691,"mc":[{"id":"1.230178173","rc":[{"atb":[[14,21]],"id":52385912},{"atb":[[16,0]],"id":52385918},{"atb":[[10,0]],"id":52385892},{"atb":[[20,0]],"id":52385919},{"atb":[[13,0]],"id":52385921},{"atb":[[24,0]],"id":52385884},{"atb":[[20,0]],"id":52385917},{"atb":[[13,0]],"id":52385891}],"con":true,"img":false}]}
{"op":"mcm","clk":"11550714206","pt":1719502315798,"mc":[{"id":"1.230178173","rc":[{"atb":[[3.9,0],[8.4,13]],"id":52385910},{"atb":[[6.4,8.67],[13,8],[1.72,0]],"id":52385912},{"atb":[[24,5]],"id":52385918},{"atb":[[9,0],[15,7.14]],"id":52385883},{"atl":[[190,2]],"id":52385883},{"atl":[[150,0]],"id":52385885},{"atb":[[3.55,0],[13.5,8]],"id":52385896},{"atb":[[11,8]],"id":52385892},{"atb":[[1.25,0],[7,10]],"id":52385913},{"atb":[[24,5]],"id":52385919},{"atb":[[20,6]],"id":52385921},{"atb":[[20,5],[6.8,17.24],[8.4,0]],"id":52385884},{"atb":[[24,5]],"id":52385917},{"atb":[[12,7]],"id":52385891},{"atl":[[160,2],[200,0]],"id":52385903}],"con":true,"img":false}]}
{"op":"mcm","clk":"11550714213","pt":1719502315899,"mc":[{"id":"1.230178173","rc":[{"atl":[[90,0]],"id":52385906},{"atl":[[230,0]],"id":52385883},{"atb":[[12.5,8.7],[6.6,0]],"id":52385885},{"atl":[[120,2]],"id":52385885},{"atb":[[9.6,11.63]],"id":52385904},{"atb":[[8.6,13]],"id":52385897},{"atb":[[2.44,0],[13.5,8]],"id":52385903},{"atb":[[7.2,10],[1.24,0]],"id":52385899}],"con":true,"img":false}]}
{"op":"mcm","clk":"11550714223","pt":1719502316003,"mc":[{"id":"1.230178173","rc":[{"atb":[[6.4,13],[1.61,0]],"id":52385906},{"atl":[[75,2]],"id":52385906},{"atb":[[24,23]],"id":52385918},{"atb":[[5.3,0]],"id":52385904},{"atb":[[6,2]],"id":52385897}],"con":true,"img":false}]}
{"op":"mcm","clk":"11550714232","pt":1719502316110,"mc":[{"id":"1.230178173","rc":[{"atb":[[20,0]],"id":52385918},{"atb":[[7.2,2.5],[10.5,10.53]],"id":52385893}],"con":true,"img":false}]}
{"op":"mcm","clk":"11550714265","pt":1719502316483,"mc":[{"id":"1.230178173","rc":[{"atl":[[95,7]],"id":52385921}],"con":true,"img":false}]}
{"op":"mcm","clk":"11550714271","pt":1719502316582,"mc":[{"id":"1.230178173","rc":[{"atl":[[75,2.5]],"id":52385921}],"con":true,"img":false}]}
{"op":"mcm","clk":"11550714321","pt":1719502317304,"mc":[{"id":"1.230178173","rc":[{"atl":[[34,18.18]],"id":52385899}],"con":true,"img":false}]}
{"op":"mcm","clk":"11550714332","pt":1719502317510,"mc":[{"id":"1.230178173","rc":[{"atl":[[42,0]],"id":52385899}],"con":true,"img":false}]}
{"op":"mcm","clk":"11550714394","pt":1719502318401,"mc":[{"id":"1.230178173","rc":[{"atb":[[14,0]],"id":52385910},{"atb":[[12,0]],"id":52385906},{"atb":[[16.5,28]],"id":52385914},{"atb":[[24,0]],"id":52385886},{"atb":[[20,32]],"id":52385921},{"atl":[[150,4.03]],"id":52385917}],"con":true,"img":false}]}
{"op":"mcm","clk":"11550714401","pt":1719502318494,"mc":[{"id":"1.230178173","rc":[{"atb":[[13,8]],"id":52385910},{"atb":[[11,8]],"id":52385906},{"atb":[[14,0]],"id":52385914},{"atb":[[38,5]],"id":52385886},{"atl":[[200,2]],"id":52385917}],"con":true,"img":false}]}
{"op":"mcm","clk":"11550714413","pt":1719502318598,"mc":[{"id":"1.230178173","rc":[{"atb":[[14.5,0]],"id":52385910},{"atl":[[27,0]],"id":52385912},{"atl":[[38,0],[60,2]],"id":52385914},{"atb":[[40,15.38]],"id":52385886},{"atb":[[14.5,0]],"id":52385921},{"atl":[[160,0],[210,5]],"id":52385917}],"con":true,"img":false}]}
{"op":"mcm","clk":"11550714422","pt":1719502318701,"mc":[{"id":"1.230178173","rc":[{"atb":[[13.5,30]],"id":52385910},{"atl":[[34,18.18]],"id":52385912},{"atl":[[42,14.63]],"id":52385914}],"con":true,"img":false}]}
{"op":"mcm","clk":"11550714430","pt":1719502318805,"mc":[{"id":"1.230178173","rc":[{"atb":[[36,0]],"id":52385886},{"atl":[[32,19.35]],"id":52385899}],"con":true,"img":false}]}
{"op":"mcm","clk":"11550714443","pt":1719502319014,"mc":[{"id":"1.230178173","rc":[{"atl":[[34,0]],"id":52385899}],"con":true,"img":false}]}
{"op":"mcm","clk":"11550714464","pt":1719502319326,"mc":[{"id":"1.230178173","rc":[{"atb":[[8,14.29],[6.4,0]],"id":52385906},{"atb":[[7,0]],"id":52385918},{"atl":[[170,2],[100,6.06]],"id":52385918},{"atl":[[260,0],[360,2]],"id":52385920},{"atb":[[7.4,0],[3.9,34.48]],"id":52385914},{"atb":[[38,0]],"id":52385883},{"atl":[[110,2],[120,0]],"id":52385885},{"atb":[[34,0]],"id":52385896},{"atl":[[65,0],[50,2.04]],"id":52385890},{"atb":[[10.5,6]],"id":52385892},{"atb":[[14,0]],"id":52385904},{"atb":[[8.2,0],[15,12.14]],"id":52385898},{"atl":[[190,2],[240,0]],"id":52385898},{"atb":[[18,2.5],[8.2,0]],"id":52385900},{"atl":[[260,2],[200,0]],"id":52385900},{"atl":[[75,7],[85,0]],"id":52385913},{"atb":[[6.8,0]],"id":52385907},{"atl":[[260,2],[180,0]],"id":52385907},{"atb":[[15.5,6.9]],"id":52385886},{"atb":[[4.3,0]],"id":52385919},{"atl":[[270,2],[180,5]],"id":52385919},{"atb":[[4.8,0]],"id":52385921},{"atb":[[22,0]],"id":52385882},{"atb":[[8.4,0]],"id":52385917},{"atl":[[290,2],[200,0]],"id":52385917},{"atb":[[10.5,0],[5.2,23.81],[15,0]],"id":52385893},{"atb":[[9.2,0],[12.5,8.7]],"id":52385905},{"atl":[[150,0],[120,2]],"id":52385905},{"atb":[[8.4,10],[7.2,0],[19,0]],"id":52385899}],"con":true,"img":false}]}
{"op":"mcm","clk":"11550714469","pt":1719502319384,"mc":[{"id":"1.230178173","rc":[{"atb":[[13,20]],"id":52385889},{"atb":[[27,0]],"id":52385885},{"atb":[[13,7]],"id":52385904},{"atb":[[20,6]],"id":52385900},{"atb":[[23,0]],"id":52385886},{"atb":[[20,6]],"id":52385893}],"con":true,"img":false}]}
{"op":"mcm","clk":"11550714483","pt":1719502319492,"mc":[{"id":"1.230178173","rc":[{"atb":[[36,15]],"id":52385883},{"atb":[[26,20]],"id":52385885},{"atb":[[29,15]],"id":52385896},{"atb":[[20,15]],"id":52385882}],"con":true,"img":false}]}
{"op":"mcm","clk":"11550714491","pt":1719502319586,"mc":[{"id":"1.230178173","rc":[{"atb":[[12,8]],"id":52385889},{"atl":[[95,6.38],[110,0]],"id":52385898},{"atl":[[140,4.32],[150,0]],"id":52385884}],"con":true,"img":false}]}
{"op":"mcm","clk":"11550714616","pt":1719502321093,"mc":[{"id":"1.230178173","rc":[{"atl":[[25,25]],"id":52385912}],"con":true,"img":false}]}
{"op":"mcm","clk":"11550714620","pt":1719502321197,"mc":[{"id":"1.230178173","rc":[{"atl":[[34,18.18]],"id":52385910},{"atl":[[25,17.42]],"id":52385890}],"con":true,"img":false}]}
{"op":"mcm","clk":"11550714628","pt":1719502321299,"mc":[{"id":"1.230178173","rc":[{"atl":[[34,0]],"id":52385912}],"con":true,"img":false}]}
{"op":"mcm","clk":"11550714634","pt":1719502321403,"mc":[{"id":"1.230178173","rc":[{"atl":[[65,2],[75,5],[40,0]],"id":52385910},{"atl":[[27,0]],"id":52385890}],"con":true,"img":false}]}
{"op":"mcm","clk":"11550714643","pt":1719502321507,"mc":[{"id":"1.230178173","rc":[{"atb":[[12,0]],"id":52385889},{"atb":[[16,0]],"id":52385890}],"con":true,"img":false}]}
{"op":"mcm","clk":"11550714647","pt":1719502321610,"mc":[{"id":"1.230178173","rc":[{"atl":[[24,26]],"id":52385912},{"atb":[[11,8]],"id":52385889},{"atb":[[14,6]],"id":52385890},{"atl":[[95,5],[120,2]],"id":52385921}],"con":true,"img":false}]}
{"op":"mcm","clk":"11550714651","pt":1719502321713,"mc":[{"id":"1.230178173","rc":[{"atb":[[9.8,16.4]],"id":52385890}],"con":true,"img":false}]}
{"op":"mcm","clk":"11550714659","pt":1719502321819,"mc":[{"id":"1.230178173","rc":[{"atl":[[25,0]],"id":52385912}],"con":true,"img":false}]}
{"op":"mcm","clk":"11550714671","pt":1719502322029,"mc":[{"id":"1.230178173","rc":[{"atl":[[34,0]],"id":52385910}],"con":true,"img":false}]}
{"op":"mcm","clk":"11550714678","pt":1719502322094,"mc":[{"id":"1.230178173","rc":[{"atl":[[65,0],[75,7],[44,13.95]],"id":52385910}],"con":true,"img":false}]}
{"op":"mcm","clk":"11550714692","pt":1719502322304,"mc":[{"id":"1.230178173","rc":[{"atl":[[44,0]],"id":52385910}],"con":true,"img":false}]}
{"op":"mcm","clk":"11550714699","pt":1719502322398,"mc":[{"id":"1.230178173","rc":[{"atl":[[48,12.77]],"id":52385910},{"atb":[[11,0]],"id":52385914},{"atl":[[170,2],[190,0]],"id":52385883},{"atb":[[9.2,10],[7,0]],"id":52385913},{"atb":[[21,5],[6.8,0]],"id":52385884}],"con":true,"img":false}]}
{"op":"mcm","clk":"11550714707","pt":1719502322501,"mc":[{"id":"1.230178173","rc":[{"atb":[[15,9]],"id":52385914}],"con":true,"img":false}]}
{"op":"mcm","clk":"11550714714","pt":1719502322605,"mc":[{"id":"1.230178173","rc":[{"atl":[[48,0]],"id":52385910}],"con":true,"img":false}]}
{"op":"mcm","clk":"11550714721","pt":1719502322708,"mc":[{"id":"1.230178173","rc":[{"atl":[[50,12.24]],"id":52385910}],"con":true,"img":false}]}
{"op":"mcm","clk":"11550714766","pt":1719502323432,"mc":[{"id":"1.230178173","rc":[{"atl":[[32,19.35]],"id":52385906}],"con":true,"img":false}]}
{"op":"mcm","clk":"11550714774","pt":1719502323496,"mc":[{"id":"1.230178173","rc":[{"atl":[[42,0]],"id":52385906},{"atb":[[34,13.06]],"id":52385917}],"con":true,"img":false}]}
{"op":"mcm","clk":"11550714785","pt":1719502323701,"mc":[{"id":"1.230178173","rc":[{"atl":[[85,2],[60,0]],"id":52385914},{"atb":[[32,0]],"id":52385917}],"con":true,"img":false}]}
{"op":"mcm","clk":"11550714805","pt":1719502324001,"mc":[{"id":"1.230178173","rc":[{"atl":[[32,0]],"id":52385906}],"con":true,"img":false}]}
{"op":"mcm","clk":"11550714816","pt":1719502324104,"mc":[{"id":"1.230178173","rc":[{"atl":[[34,18.18],[70,2],[75,0]],"id":52385906}],"con":true,"img":false}]}
{"op":"mcm","clk":"11550714833","pt":1719502324311,"mc":[{"id":"1.230178173","rc":[{"atb":[[14,0]],"id":52385912},{"atl":[[34,0]],"id":52385906},{"atl":[[28,6.2]],"id":52385911},{"atl":[[130,2.5],[140,0],[170,5],[100,0]],"id":52385907},{"atb":[[15.5,0]],"id":52385886},{"atl":[[290,0],[360,2]],"id":52385886},{"atl":[[130,2],[100,0]],"id":52385893},{"atb":[[12.5,0]],"id":52385905},{"atl":[[65,2],[80,0]],"id":52385899}],"con":true,"img":false}]}
{"op":"mcm","clk":"11550714843","pt":1719502324415,"mc":[{"id":"1.230178173","rc":[{"atl":[[44,13.95]],"id":52385906},{"atl":[[95,0]],"id":52385898},{"atb":[[11,0]],"id":52385911},{"atl":[[32,0]],"id":52385911},{"atl":[[90,0]],"id":52385907},{"atb":[[10.5,10]],"id":52385886},{"atl":[[120,0]],"id":52385886},{"atb":[[9.4,11.9]],"id":52385905}],"con":true,"img":false}]}
{"op":"mcm","clk":"11550714849","pt":1719502324517,"mc":[{"id":"1.230178173","rc":[{"atb":[[8,0],[6.8,16]],"id":52385906},{"atb":[[10,8]],"id":52385911}],"con":true,"img":false}]}
{"op":"mcm","clk":"11550714856","pt":1719502324622,"mc":[{"id":"1.230178173","rc":[{"atl":[[100,6.06]],"id":52385898},{"atl":[[120,5.04]],"id":52385907},{"atl":[[220,2.74]],"id":52385886}],"con":true,"img":false}]}
{"op":"mcm","clk":"11550714877","pt":1719502324892,"mc":[{"id":"1.230178173","rc":[{"atb":[[25,13.74]],"id":52385920},{"atl":[[170,3.55]],"id":52385920},{"atb":[[17,28]],"id":52385914},{"atb":[[30,20.69]],"id":52385896},{"atb":[[24,22.12]],"id":52385898},{"atb":[[29,18.06]],"id":52385919},{"atl":[[130,4.65]],"id":52385919},{"atb":[[21,22]],"id":52385893}],"con":true,"img":false}]}
{"op":"mcm","clk":"11550714884","pt":1719502324996,"mc":[{"id":"1.230178173","rc":[{"atl":[[32,19.35]],"id":52385910},{"atl":[[32,19.35]],"id":52385906},{"atl":[[60,10.58]],"id":52385918},{"atb":[[16.5,0]],"id":52385914},{"atl":[[40,15.38]],"id":52385914},{"atb":[[23,0]],"id":52385898},{"atl":[[180,3.35]],"id":52385886},{"atb":[[17,26]],"id":52385897}],"con":true,"img":false}]}
{"op":"mcm","clk":"11550714891","pt":1719502325098,"mc":[{"id":"1.230178173","rc":[{"atb":[[17,26]],"id":52385906},{"atb":[[22,0]],"id":52385920},{"atl":[[210,0]],"id":52385920},{"atb":[[29,0]],"id":52385896},{"atb":[[28,0]],"id":52385919},{"atl":[[150,0]],"id":52385919},{"atb":[[19,0]],"id":52385893}],"con":true,"img":false}]}
{"op":"mcm","clk":"11550714897","pt":1719502325195,"mc":[{"id":"1.230178173","rc":[{"atl":[[50,0]],"id":52385910},{"atl":[[44,0]],"id":52385906},{"atl":[[100,0]],"id":52385918},{"atl":[[42,0]],"id":52385914},{"atl":[[220,0]],"id":52385886},{"atb":[[14.5,0]],"id":52385897}],"con":true,"img":false}]}
{"op":"mcm","clk":"11550714903","pt":1719502325298,"mc":[{"id":"1.230178173","rc":[{"atb":[[16.5,0]],"id":52385906}],"con":true,"img":false}]}
{"op":"mcm","clk":"11550714908","pt":1719502325401,"mc":[{"id":"1.230178173","rc":[{"atb":[[14,0]],"id":52385897}],"con":true,"img":false}]}
{"op":"mcm","clk":"11550714920","pt":1719502325611,"mc":[{"id":"1.230178173","rc":[{"atb":[[11,0]],"id":52385892},{"atb":[[24,0]],"id":52385919},{"atb":[[24,0]],"id":52385917}],"con":true,"img":false}]}
{"op":"mcm","clk":"11550714926","pt":1719502325714,"mc":[{"id":"1.230178173","rc":[{"atb":[[10,8]],"id":52385892},{"atb":[[42,5]],"id":52385919},{"atb":[[42,5]],"id":52385917}],"con":true,"img":false}]}
{"op":"mcm","clk":"11550714940","pt":1719502325927,"mc":[{"id":"1.230178173","rc":[{"atb":[[4.6,27.78]],"id":52385914},{"atb":[[44,13.95]],"id":52385917}],"con":true,"img":false}]}
{"op":"mcm","clk":"11550714951","pt":1719502326028,"mc":[{"id":"1.230178173","rc":[{"atb":[[3.9,0]],"id":52385914}],"con":true,"img":false}]}
{"op":"mcm","clk":"11550714957","pt":1719502326133,"mc":[{"id":"1.230178173","rc":[{"atb":[[34,0]],"id":52385917}],"con":true,"img":false}]}
{"op":"mcm","clk":"11550714986","pt":1719502326506,"mc":[{"id":"1.230178173","rc":[{"atb":[[18.5,0]],"id":52385891}],"con":true,"img":false}]}
{"op":"mcm","clk":"11550714992","pt":1719502326600,"mc":[{"id":"1.230178173","rc":[{"atb":[[18,24],[10.5,10.53],[9.8,0]],"id":52385891}],"con":true,"img":false}]}
{"op":"mcm","clk":"11550715006","pt":1719502326808,"mc":[{"id":"1.230178173","rc":[{"atl":[[17,32.46]],"id":52385892}],"con":true,"img":false}]}
{"op":"mcm","clk":"11550715021","pt":1719502327017,"mc":[{"id":"1.230178173","rc":[{"atl":[[18.5,0]],"id":52385892}],"con":true,"img":false}]}
{"op":"mcm","clk":"11550715048","pt":1719502327433,"mc":[{"id":"1.230178173","rc":[{"atb":[[12,0]],"id":52385891}],"con":true,"img":false}]}
{"op":"mcm","clk":"11550715059","pt":1719502327497,"mc":[{"id":"1.230178173","rc":[{"atb":[[11,7]],"id":52385891}],"con":true,"img":false}]}
{"op":"mcm","clk":"11550715112","pt":1719502328323,"mc":[{"id":"1.230178173","rc":[{"atl":[[34,18.18]],"id":52385913}],"con":true,"img":false}]}
{"op":"mcm","clk":"11550715128","pt":1719502328532,"mc":[{"id":"1.230178173","rc":[{"atb":[[13,0]],"id":52385910},{"atl":[[50,0]],"id":52385913}],"con":true,"img":false}]}
{"op":"mcm","clk":"11550715137","pt":1719502328596,"mc":[{"id":"1.230178173","rc":[{"atb":[[14,8]],"id":52385910}],"con":true,"img":false}]}
{"op":"mcm","clk":"11550715149","pt":1719502328697,"mc":[{"id":"1.230178173","rc":[{"atb":[[13.5,0],[14,38]],"id":52385910}],"con":true,"img":false}]}
{"op":"mcm","clk":"11550715201","pt":1719502329418,"mc":[{"id":"1.230178173","rc":[{"atb":[[30,0]],"id":52385896},{"atl":[[32,5],[28,3.7]],"id":52385892},{"atb":[[9.6,0],[13,0],[8.4,13.51]],"id":52385904},{"atb":[[10.5,10.53],[15,5]],"id":52385898},{"atb":[[20,0]],"id":52385900},{"atl":[[17,22.4]],"id":52385911},{"atl":[[29,21.43]],"id":52385913},{"atb":[[10.5,0]],"id":52385886},{"atb":[[23,26]],"id":52385882},{"atb":[[5.2,0],[4.2,31.25]],"id":52385893},{"atb":[[9.8,11.36],[13.5,0]],"id":52385903}],"con":true,"img":false}]}
{"op":"mcm","clk":"11550715209","pt":1719502329521,"mc":[{"id":"1.230178173","rc":[{"atb":[[12,7]],"id":52385904},{"atb":[[24,6]],"id":52385900}],"con":true,"img":false}]}
{"op":"mcm","clk":"11550715214","pt":1719502329625,"mc":[{"id":"1.230178173","rc":[{"atb":[[29,21.43]],"id":52385896},{"atl":[[26,4]],"id":52385911},{"atl":[[34,0]],"id":52385913},{"atb":[[4.3,30.3]],"id":52385886},{"atb":[[8,12],[9.4,0]],"id":52385905}],"con":true,"img":false}]}
{"op":"mcm","clk":"11550715219","pt":1719502329727,"mc":[{"id":"1.230178173","rc":[{"atl":[[22,0],[28,2.5]],"id":52385911},{"atb":[[20,0],[23,0]],"id":52385882}],"con":true,"img":false}]}
{"op":"mcm","clk":"11550715226","pt":1719502329790,"mc":[{"id":"1.230178173","rc":[{"atb":[[29,0]],"id":52385896},{"atb":[[19.5,32.43]],"id":52385882}],"con":true,"img":false}]}
{"op":"mcm","clk":"11550715237","pt":1719502329892,"mc":[{"id":"1.230178173","rc":[{"atb":[[23,15]],"id":52385896}],"con":true,"img":false}]}
{"op":"mcm","clk":"11550715247","pt":1719502330000,"mc":[{"id":"1.230178173","rc":[{"atl":[[38,16.22],[40,0]],"id":52385914}],"con":true,"img":false}]}
{"op":"mcm","clk":"11550715254","pt":1719502330099,"mc":[{"id":"1.230178173","rc":[{"atl":[[80,2],[85,0]],"id":52385914}],"con":true,"img":false}]}
{"op":"mcm","clk":"11550715282","pt":1719502330506,"mc":[{"id":"1.230178173","rc":[{"atb":[[13,0]],"id":52385912},{"atb":[[38,0]],"id":52385886}],"con":true,"img":false}]}
{"op":"mcm","clk":"11550715288","pt":1719502330610,"mc":[{"id":"1.230178173","rc":[{"atl":[[32,0]],"id":52385910},{"atb":[[12,8]],"id":52385912},{"atb":[[42,5]],"id":52385886}],"con":true,"img":false}]}
{"op":"mcm","clk":"11550715294","pt":1719502330713,"mc":[{"id":"1.230178173","rc":[{"atl":[[34,18.18]],"id":52385910},{"atb":[[40,0]],"id":52385886}],"con":true,"img":false}]}
{"op":"mcm","clk":"11550715299","pt":1719502330819,"mc":[{"id":"1.230178173","rc":[{"atl":[[75,5],[430,2]],"id":52385910},{"atb":[[44,13.95]],"id":52385886}],"con":true,"img":false}]}
{"op":"mcm","clk":"11550715306","pt":1719502330924,"mc":[{"id":"1.230178173","rc":[{"atb":[[18,0]],"id":52385891}],"con":true,"img":false}]}
{"op":"mcm","clk":"11550715314","pt":1719502331029,"mc":[{"id":"1.230178173","rc":[{"atb":[[17,35.06]],"id":52385891}],"con":true,"img":false}]}
{"op":"mcm","clk":"11550715402","pt":1719502332442,"mc":[{"id":"1.230178173","rc":[{"atb":[[15,0]],"id":52385914}],"con":true,"img":false}]}
{"op":"mcm","clk":"11550715407","pt":1719502332494,"mc":[{"id":"1.230178173","rc":[{"atb":[[14,9]],"id":52385914}],"con":true,"img":false}]}
{"op":"mcm","clk":"11550715423","pt":1719502332700,"mc":[{"id":"1.230178173","rc":[{"atb":[[16,20]],"id":52385910}],"con":true,"img":false}]}
{"op":"mcm","clk":"11550715440","pt":1719502332902,"mc":[{"id":"1.230178173","rc":[{"atb":[[14,8]],"id":52385910}],"con":true,"img":false}]}
{"op":"mcm","clk":"11550715477","pt":1719502333522,"mc":[{"id":"1.230178173","rc":[{"atb":[[11,0]],"id":52385906},{"atb":[[11,0]],"id":52385889},{"atb":[[14,0]],"id":52385890}],"con":true,"img":false}]}
{"op":"mcm","clk":"11550715484","pt":1719502333631,"mc":[{"id":"1.230178173","rc":[{"atb":[[12,8]],"id":52385906},{"atb":[[10,10.5]],"id":52385889},{"atb":[[13,6]],"id":52385890}],"con":true,"img":false}]}
{"op":"mcm","clk":"11550715496","pt":1719502333732,"mc":[{"id":"1.230178173","rc":[{"atb":[[13,24.4]],"id":52385890}],"con":true,"img":false}]}
{"op":"mcm","clk":"11550715510","pt":1719502333898,"mc":[{"id":"1.230178173","rc":[{"atb":[[9.8,0]],"id":52385890}],"con":true,"img":false}]}
{"op":"mcm","clk":"11550715533","pt":1719502334314,"mc":[{"id":"1.230178173","rc":[{"atl":[[38,0]],"id":52385914}],"con":true,"img":false}]}
{"op":"mcm","clk":"11550715542","pt":1719502334407,"mc":[{"id":"1.230178173","rc":[{"atb":[[16,0]],"id":52385910},{"atb":[[10,8],[9.2,0],[7.6,0],[13,0]],"id":52385889},{"atb":[[4.6,0],[6,16]],"id":52385914},{"atl":[[40,15.38]],"id":52385914},{"atl":[[170,0],[210,2]],"id":52385883},{"atb":[[34,18.18],[10,11.11],[13.5,0]],"id":52385896},{"atl":[[140,0],[170,2]],"id":52385896},{"atb":[[6.2,0],[5.3,23.26]],"id":52385892},{"atb":[[10.5,0],[3.55,39.22]],"id":52385898},{"atl":[[280,2],[190,0]],"id":52385898},{"atl":[[260,0],[330,2],[100,0],[200,5],[120,0]],"id":52385900},{"atb":[[6.4,0],[5.8,0],[5.2,23.81],[5.9,0]],"id":52385911},{"atb":[[21,26]],"id":52385882},{"atb":[[8.6,0],[18.5,15],[9.8,11.36]],"id":52385897},{"atb":[[7.4,12],[4.2,0]],"id":52385893},{"atl":[[130,0],[46,13.33],[110,2]],"id":52385893},{"atb":[[8,0]],"id":52385905},{"atl":[[180,2],[120,0]],"id":52385905},{"atb":[[5.6,21.74],[19.5,17],[8.4,0]],"id":52385899},{"atl":[[32,0]],"id":52385899}],"con":true,"img":false}]}
{"op":"mcm","clk":"11550715553","pt":1719502334512,"mc":[{"id":"1.230178173","rc":[{"atb":[[7.4,15.62],[8.4,0],[15.5,26]],"id":52385910},{"atb":[[10,39],[6.6,17.86]],"id":52385889},{"atb":[[10,0],[23,0],[14.5,9.91]],"id":52385896},{"atl":[[150,4.03]],"id":52385900},{"atb":[[19.5,0]],"id":52385882},{"atb":[[17,0]],"id":52385897},{"atb":[[17,0]],"id":52385891},{"atl":[[70,0]],"id":52385893},{"atb":[[4.2,31.25]],"id":52385905},{"atb":[[5.6,0],[8,10]],"id":52385899},{"atl":[[65,0],[32,11.93],[85,2]],"id":52385899}],"con":true,"img":false}]}
{"op":"mcm","clk":"11550715560","pt":1719502334615,"mc":[{"id":"1.230178173","rc":[{"atb":[[6.2,5],[7,2.5]],"id":52385889},{"atl":[[40,0]],"id":52385914},{"atb":[[18.5,0]],"id":52385897},{"atb":[[16.5,35.06],[10.5,0],[9.8,11.36]],"id":52385891},{"atl":[[32,0]],"id":52385899}],"con":true,"img":false}]}
{"op":"mcm","clk":"11550715570","pt":1719502334720,"mc":[{"id":"1.230178173","rc":[{"atl":[[50,12.24]],"id":52385914},{"atb":[[16,32.72]],"id":52385897},{"atl":[[42,14.63]],"id":52385899}],"con":true,"img":false}]}
{"op":"mcm","clk":"11550715581","pt":1719502334926,"mc":[{"id":"1.230178173","rc":[{"atl":[[32,19.35]],"id":52385891}],"con":true,"img":false}]}
{"op":"mcm","clk":"11550715596","pt":1719502335136,"mc":[{"id":"1.230178173","rc":[{"atl":[[29,21.43]],"id":52385910},{"atl":[[36,0]],"id":52385891}],"con":true,"img":false}]}
{"op":"mcm","clk":"11550715607","pt":1719502335320,"mc":[{"id":"1.230178173","rc":[{"atl":[[34,0]],"id":52385910},{"atb":[[16.5,0]],"id":52385891}],"con":true,"img":false}]}
{"op":"mcm","clk":"11550715615","pt":1719502335403,"mc":[{"id":"1.230178173","rc":[{"atb":[[10,0]],"id":52385892},{"atb":[[16,15]],"id":52385891}],"con":true,"img":false}]}
{"op":"mcm","clk":"11550715622","pt":1719502335508,"mc":[{"id":"1.230178173","rc":[{"atb":[[9,8]],"id":52385892}],"con":true,"img":false}]}
{"op":"mcm","clk":"11550715649","pt":1719502336017,"mc":[{"id":"1.230178173","rc":[{"atl":[[28,22.22]],"id":52385910},{"atb":[[4.3,0],[5.7,21.28]],"id":52385886}],"con":true,"img":false}]}
{"op":"mcm","clk":"11550715657","pt":1719502336120,"mc":[{"id":"1.230178173","rc":[{"atl":[[29,0]],"id":52385910}],"con":true,"img":false}]}
{"op":"mcm","clk":"11550715741","pt":1719502337217,"mc":[{"id":"1.230178173","rc":[{"atl":[[75,7],[430,0]],"id":52385910}],"con":true,"img":false}]}
{"op":"mcm","clk":"11550715754","pt":1719502337405,"mc":[{"id":"1.230178173","rc":[{"atb":[[11,0]],"id":52385891}],"con":true,"img":false}]}
{"op":"mcm","clk":"11550715761","pt":1719502337510,"mc":[{"id":"1.230178173","rc":[{"atb":[[10,9.5]],"id":52385891}],"con":true,"img":false}]}
{"op":"mcm","clk":"11550715828","pt":1719502338402,"mc":[{"id":"1.230178173","rc":[{"atb":[[34,0]],"id":52385896}],"con":true,"img":false}]}
{"op":"mcm","clk":"11550715839","pt":1719502338509,"mc":[{"id":"1.230178173","rc":[{"atb":[[26,0]],"id":52385885},{"atb":[[30,20.69]],"id":52385896}],"con":true,"img":false}]}
{"op":"mcm","clk":"11550715845","pt":1719502338607,"mc":[{"id":"1.230178173","rc":[{"atb":[[25,20]],"id":52385885}],"con":true,"img":false}]}
{"op":"mcm","clk":"11550715851","pt":1719502338702,"mc":[{"id":"1.230178173","rc":[{"atb":[[30,0]],"id":52385896},{"atb":[[44,13.95]],"id":52385919}],"con":true,"img":false}]}
{"op":"mcm","clk":"11550715856","pt":1719502338818,"mc":[{"id":"1.230178173","rc":[{"atl":[[36,17.14]],"id":52385914},{"atb":[[25,0]],"id":52385885},{"atb":[[25,25]],"id":52385896},{"atb":[[20,31.58]],"id":52385897}],"con":true,"img":false}]}
{"op":"mcm","clk":"11550715864","pt":1719502338909,"mc":[{"id":"1.230178173","rc":[{"atl":[[75,7]],"id":52385914},{"atb":[[23,20]],"id":52385885},{"atb":[[29,0]],"id":52385919},{"atb":[[16,0]],"id":52385897}],"con":true,"img":false}]}
{"op":"mcm","clk":"11550715873","pt":1719502339012,"mc":[{"id":"1.230178173","rc":[{"atl":[[80,0],[50,0]],"id":52385914}],"con":true,"img":false}]}
{"op":"mcm","clk":"11550715890","pt":1719502339325,"mc":[{"id":"1.230178173","rc":[{"atb":[[18.5,26]],"id":52385906},{"atb":[[24,0],[25,20]],"id":52385898},{"atb":[[34,0],[38,16.22]],"id":52385884},{"atb":[[20,0]],"id":52385897},{"atb":[[34,18.18]],"id":52385903}],"con":true,"img":false}]}
{"op":"mcm","clk":"11550715897","pt":1719502339428,"mc":[{"id":"1.230178173","rc":[{"atb":[[19,32.72]],"id":52385897}],"con":true,"img":false}]}
{"op":"mcm","clk":"11550715904","pt":1719502339532,"mc":[{"id":"1.230178173","rc":[{"atb":[[17,0]],"id":52385906},{"atb":[[3.55,0]],"id":52385898},{"atb":[[4.9,25.64],[5.7,0]],"id":52385886},{"atl":[[270,0],[330,2]],"id":52385919},{"atb":[[32,0]],"id":52385903},{"atb":[[2.44,69.44],[4.2,0]],"id":52385905}],"con":true,"img":false}]}
{"op":"mcm","clk":"11550715940","pt":1719502340218,"mc":[{"id":"1.230178173","rc":[{"atl":[[32,0]],"id":52385891}],"con":true,"img":false}]}
{"op":"mcm","clk":"11550715946","pt":1719502340325,"mc":[{"id":"1.230178173","rc":[{"atl":[[85,2],[90,0],[50,12.24]],"id":52385891}],"con":true,"img":false}]}
{"op":"mcm","clk":"11550715952","pt":1719502340416,"mc":[{"id":"1.230178173","rc":[{"atb":[[12,0]],"id":52385912},{"atb":[[16.5,29]],"id":52385891}],"con":true,"img":false}]}
{"op":"mcm","clk":"11550715957","pt":1719502340536,"mc":[{"id":"1.230178173","rc":[{"atb":[[9.8,2.5],[13,8]],"id":52385912},{"atb":[[10.5,2.5],[9.4,5]],"id":52385906},{"atb":[[22,5],[26,2.5]],"id":52385918},{"atb":[[11,2.5]],"id":52385914},{"atl":[[29,2.5]],"id":52385890},{"atl":[[16,2.5],[18,5]],"id":52385892},{"atb":[[8.6,0]],"id":52385904},{"atb":[[17.5,5],[19.5,2.5]],"id":52385898},{"atl":[[34,0],[28,0]],"id":52385911},{"atb":[[32,5],[40,2.5]],"id":52385886},{"atb":[[12.5,0],[14.5,0]],"id":52385919},{"atb":[[18,5],[20,34.5],[7.4,0],[6.6,0]],"id":52385921},{"atl":[[80,5],[60,2.5]],"id":52385882},{"atl":[[150,2.5],[190,5]],"id":52385884},{"atb":[[16,0]],"id":52385891}],"con":true,"img":false}]}
{"op":"mcm","clk":"11550715966","pt":1719502340627,"mc":[{"id":"1.230178173","rc":[{"atl":[[75,2],[36,2.5],[44,5],[55,0]],"id":52385910},{"atb":[[8.2,0]],"id":52385912},{"atb":[[7.8,0],[7,0]],"id":52385906},{"atb":[[10.5,0],[9.4,0]],"id":52385918},{"atb":[[9.6,0],[32,2.5],[11,0],[27,5]],"id":52385920},{"atl":[[32,2.5],[40,5],[44,0],[55,0]],"id":52385889},{"atb":[[8.8,0]],"id":52385914},{"atb":[[18.5,0],[21,0],[22,5],[26,2.5]],"id":52385883},{"atb":[[16,0],[16.5,5],[18,0],[18.5,2.5]],"id":52385885},{"atb":[[19,5],[22,2.5],[12.5,0],[14.5,7.41]],"id":52385896},{"atl":[[44,0]],"id":52385890},{"atl":[[32,0],[27,3.93],[15.5,22]],"id":52385892},{"atb":[[10.5,2.5]],"id":52385904},{"atb":[[17,0],[15,0]],"id":52385898},{"atb":[[16,0],[18,0],[36,2.5],[29,5]],"id":52385900},{"atl":[[16,2.5],[18,5]],"id":52385911},{"atl":[[75,2],[36,2.5],[44,5],[55,0]],"id":52385913},{"atb":[[16.5,0],[32,2.5],[27,5],[14.5,0]],"id":52385907},{"atb":[[19,0],[22,0]],"id":52385886},{"atb":[[36,5],[44,16.45]],"id":52385919},{"atl":[[75,0],[95,0]],"id":52385882},{"atl":[[170,0],[210,0]],"id":52385884},{"atb":[[32,5],[40,2.5],[13.5,0],[15.5,0]],"id":52385917},{"atb":[[9,0],[10,5],[8.2,0],[12,2.5]],"id":52385897},{"atl":[[75,0],[44,2.5]],"id":52385891},{"atb":[[6.4,0],[10.5,2.5],[9.4,5],[7.2,0]],"id":52385893},{"atl":[[80,10.09],[85,0],[100,5],[110,0]],"id":52385903},{"atb":[[16,11],[18,2.5],[10,0],[12,0]],"id":52385905},{"atb":[[10,0],[9.2,0],[13.5,5],[15.5,2.5]],"id":52385899}],"con":true,"img":false}]}
{"op":"mcm","clk":"11550715972","pt":1719502340735,"mc":[{"id":"1.230178173","rc":[{"atl":[[75,0],[60,2]],"id":52385910},{"atl":[[38,5],[42,0],[50,0],[30,2.5]],"id":52385912},{"atl":[[38,2.5],[60,0]],"id":52385906},{"atb":[[27,20]],"id":52385918},{"atl":[[130,0],[80,2.5],[95,0],[100,5]],"id":52385918},{"atb":[[34,17.1]],"id":52385920},{"atl":[[48,2.13],[60,0],[30,20.69]],"id":52385889},{"atl":[[75,2],[42,2.5],[50,5],[55,0]],"id":52385914},{"atl":[[65,2.5],[85,5]],"id":52385885},{"atl":[[25,4.17],[28,0]],"id":52385892},{"atb":[[38,16.22]],"id":52385900},{"atl":[[26,0]],"id":52385911},{"atb":[[34,18.18]],"id":52385907},{"atl":[[180,5.85],[190,0],[220,5],[230,0]],"id":52385886},{"atl":[[90,2],[100,0],[55,11.11]],"id":52385882},{"atl":[[65,0],[48,0]],"id":52385897}],"con":true,"img":false}]}
{"op":"mcm","clk":"11550715979","pt":1719502340838,"mc":[{"id":"1.230178173","rc":[{"atl":[[65,11.88],[80,0],[100,0]],"id":52385885},{"atl":[[17,0]],"id":52385892},{"atl":[[23,4.55]],"id":52385911},{"atb":[[46,13.33]],"id":52385917},{"atl":[[46,2.5],[60,5]],"id":52385897},{"atl":[[75,0],[80,5],[95,0],[60,2.5]],"id":52385893},{"atl":[[70,5],[75,0],[50,2.5],[55,0]],"id":52385899}],"con":true,"img":false}]}
{"op":"mcm","clk":"11550715984","pt":1719502340941,"mc":[{"id":"1.230178173","rc":[{"atb":[[24,5]],"id":52385918},{"atb":[[25,0]],"id":52385920},{"atl":[[42,0]],"id":52385889},{"atb":[[26,0]],"id":52385900},{"atb":[[24,0]],"id":52385907},{"atl":[[70,0]],"id":52385882}],"con":true,"img":false}]}
{"op":"mcm","clk":"11550715989","pt":1719502341045,"mc":[{"id":"1.230178173","rc":[{"atl":[[75,0]],"id":52385885},{"atb":[[44,0]],"id":52385917}],"con":true,"img":false}]}
{"op":"mcm","clk":"11550716005","pt":1719502341310,"mc":[{"id":"1.230178173","rc":[{"atb":[[23,0],[28,20]],"id":52385885},{"atb":[[38,0]],"id":52385884}],"con":true,"img":false}]}
{"op":"mcm","clk":"11550716013","pt":1719502341425,"mc":[{"id":"1.230178173","rc":[{"atb":[[20,0]],"id":52385883},{"atb":[[36,17.14]],"id":52385884}],"con":true,"img":false}]}
{"op":"mcm","clk":"11550716027","pt":1719502341638,"mc":[{"id":"1.230178173","rc":[{"atb":[[28,0]],"id":52385885},{"atb":[[24,0]],"id":52385900}],"con":true,"img":false}]}
{"op":"mcm","clk":"11550716034","pt":1719502341728,"mc":[{"id":"1.230178173","rc":[{"atb":[[18.5,0]],"id":52385912},{"atb":[[16.5,0]],"id":52385918},{"atb":[[26,20]],"id":52385885},{"atb":[[9,0]],"id":52385890},{"atl":[[26,0]],"id":52385890},{"atb":[[10.5,0]],"id":52385892},{"atl":[[27,0]],"id":52385892},{"atb":[[11.5,0]],"id":52385911},{"atl":[[27,0]],"id":52385911},{"atb":[[15.5,0]],"id":52385897},{"atl":[[40,0]],"id":52385897},{"atl":[[44,0]],"id":52385899}],"con":true,"img":false}]}
