{"op":"mcm","clk":"11536833041","pt":1719431776484,"mc":[{"id":"1.230180116","marketDefinition":{"bspMarket":true,"turnInPlayEnabled":false,"persistenceEnabled":false,"marketBaseRate":5.0,"eventId":"33376437","eventTypeId":"4339","numberOfWinners":1,"bettingType":"ODDS","marketType":"WIN","marketTime":"2024-06-27T14:11:00.000Z","suspendTime":"2024-06-27T14:11:00.000Z","bspReconciled":false,"complete":true,"inPlay":false,"crossMatching":false,"runnersVoidable":false,"numberOfActiveRunners":6,"betDelay":0,"status":"OPEN","runners":[{"status":"ACTIVE","sortPriority":1,"id":48536142,"name":"1. Liz Of Rhyl"},{"status":"ACTIVE","sortPriority":2,"id":64253836,"name":"2. Keeperhill Fagan"},{"status":"ACTIVE","sortPriority":3,"id":68900945,"name":"3. Salacres Elmejor"},{"status":"ACTIVE","sortPriority":4,"id":69366841,"name":"4. Fleurs Gamble"},{"status":"ACTIVE","sortPriority":5,"id":63031611,"name":"5. Greencroft Oscar"},{"status":"ACTIVE","sortPriority":6,"id":40831161,"name":"6. Milton Mia"}],"regulators":["MR_INT"],"venue":"Towcester","countryCode":"GB","discountAllowed":false,"timezone":"Europe/London","openDate":"2024-06-27T13:33:00.000Z","version":5994767141,"name":"A5 500m","eventName":"Towcester 27th Jun"},"rc":[],"con":true,"img":false}]}
{"op":"mcm","clk":"11536833151","pt":1719431777535,"mc":[{"id":"1.230180116","marketDefinition":{"bspMarket":true,"turnInPlayEnabled":false,"persistenceEnabled":false,"marketBaseRate":5.0,"eventId":"33376437","eventTypeId":"4339","numberOfWinners":1,"bettingType":"ODDS","marketType":"WIN","marketTime":"2024-06-27T14:11:00.000Z","suspendTime":"2024-06-27T14:11:00.000Z","bspReconciled":false,"complete":true,"inPlay":false,"crossMatching":false,"runnersVoidable":false,"numberOfActiveRunners":6,"betDelay":0,"status":"OPEN","runners":[{"status":"ACTIVE","sortPriority":1,"id":48536142,"name":"1. Liz Of Rhyl"},{"status":"ACTIVE","sortPriority":2,"id":64253836,"name":"2. Keeperhill Fagan"},{"status":"ACTIVE","sortPriority":3,"id":68900945,"name":"3. Salacres Elmejor"},{"status":"ACTIVE","sortPriority":4,"id":69366841,"name":"4. Fleurs Gamble"},{"status":"ACTIVE","sortPriority":5,"id":63031611,"name":"5. Greencroft Oscar"},{"status":"ACTIVE","sortPriority":6,"id":40831161,"name":"6. Milton Mia"}],"regulators":["MR_INT"],"venue":"Towcester","countryCode":"GB","discountAllowed":true,"timezone":"Europe/London","openDate":"2024-06-27T13:33:00.000Z","version":5994767141,"name":"A5 500m","eventName":"Towcester 27th Jun"},"rc":[],"con":true,"img":false}]}
{"op":"mcm","clk":"11537083788","pt":1719435431300,"mc":[{"id":"1.230180116","rc":[{"atb":[[1.03,10.99]],"id":63031611},{"atl":[[990,0.84]],"id":63031611},{"spn":495.51,"spf":"NaN","id":63031611},{"atb":[[1.03,10.99]],"id":69366841},{"atl":[[1000,0.84]],"id":69366841},{"spn":500.51,"spf":"NaN","id":69366841},{"atb":[[1.02,16.48]],"id":40831161},{"atl":[[990,0.84]],"id":40831161},{"spn":495.51,"spf":"NaN","id":40831161},{"atb":[[1.03,10.99]],"id":64253836},{"atl":[[990,0.84]],"id":64253836},{"spn":495.51,"spf":"NaN","id":64253836},{"atb":[[1.01,32.96]],"id":48536142},{"atl":[[990,0.84]],"id":48536142},{"spn":495.5,"spf":"NaN","id":48536142},{"atb":[[1.02,16.48]],"id":68900945},{"atl":[[990,0.84]],"id":68900945},{"spn":495.51,"spf":"NaN","id":68900945}],"con":true,"img":false}]}
{"op":"mcm","clk":"11537233750","pt":1719437882659,"mc":[{"id":"1.230180116","marketDefinition":{"bspMarket":true,"turnInPlayEnabled":false,"persistenceEnabled":false,"marketBaseRate":5.0,"eventId":"33376437","eventTypeId":"4339","numberOfWinners":1,"bettingType":"ODDS","marketType":"WIN","marketTime":"2024-06-27T14:11:00.000Z","suspendTime":"2024-06-27T14:11:00.000Z","bspReconciled":false,"complete":true,"inPlay":false,"crossMatching":false,"runnersVoidable":false,"numberOfActiveRunners":6,"betDelay":0,"status":"OPEN","runners":[{"status":"ACTIVE","sortPriority":1,"id":48536142,"name":"1. Liz Of Rhyl"},{"status":"ACTIVE","sortPriority":2,"id":64253836,"name":"2. Keeperhill Fagan"},{"status":"ACTIVE","sortPriority":3,"id":68900945,"name":"3. Salacres Elmejor"},{"status":"ACTIVE","sortPriority":4,"id":69366841,"name":"4. Fleurs Gamble"},{"status":"ACTIVE","sortPriority":5,"id":63031611,"name":"5. Greencroft Oscar"},{"status":"ACTIVE","sortPriority":6,"id":40831161,"name":"6. Milton Mia"}],"regulators":["MR_INT"],"venue":"Towcester","countryCode":"GB","discountAllowed":true,"timezone":"Europe/London","openDate":"2024-06-27T13:33:00.000Z","version":5994767141,"name":"A5 500m","eventName":"Towcester 27th Jun"},"rc":[{"atb":[[1.03,10.99]],"id":63031611},{"atl":[[990,0.84]],"id":63031611},{"spn":495.51,"spf":"NaN","id":63031611},{"atb":[[1.03,10.99]],"id":69366841},{"atl":[[1000,0.84]],"id":69366841},{"spn":500.51,"spf":"NaN","id":69366841},{"atb":[[1.02,16.48]],"id":40831161},{"atl":[[990,0.84]],"id":40831161},{"spn":495.51,"spf":"NaN","id":40831161},{"atb":[[1.03,10.99]],"id":64253836},{"atl":[[990,0.84]],"id":64253836},{"spn":495.51,"spf":"NaN","id":64253836},{"atb":[[1.01,32.96]],"id":48536142},{"atl":[[990,0.84]],"id":48536142},{"spn":495.5,"spf":"NaN","id":48536142},{"atb":[[1.02,16.48]],"id":68900945},{"atl":[[990,0.84]],"id":68900945},{"spn":495.51,"spf":"NaN","id":68900945}],"con":true,"img":true}]}
{"op":"mcm","clk":"11537302046","pt":1719439028743,"mc":[{"id":"1.230180116","rc":[{"atb":[[1.03,10.99]],"id":63031611},{"atl":[[990,0.17]],"id":63031611},{"atb":[[1.03,10.99]],"id":69366841},{"atl":[[1000,0.17]],"id":69366841},{"atb":[[1.02,16.48]],"id":40831161},{"atl":[[990,0.17]],"id":40831161},{"atb":[[1.03,10.99]],"id":64253836},{"atl":[[990,0.17]],"id":64253836},{"atb":[[1.01,32.96]],"id":48536142},{"atl":[[990,0.17]],"id":48536142},{"atb":[[1.02,16.48]],"id":68900945},{"atl":[[990,0.17]],"id":68900945}],"con":true,"img":false}]}
{"op":"mcm","clk":"11537574903","pt":1719443282710,"mc":[{"id":"1.230180116","marketDefinition":{"bspMarket":true,"turnInPlayEnabled":false,"persistenceEnabled":false,"marketBaseRate":5.0,"eventId":"33376437","eventTypeId":"4339","numberOfWinners":1,"bettingType":"ODDS","marketType":"WIN","marketTime":"2024-06-27T14:11:00.000Z","suspendTime":"2024-06-27T14:11:00.000Z","bspReconciled":false,"complete":true,"inPlay":false,"crossMatching":false,"runnersVoidable":false,"numberOfActiveRunners":6,"betDelay":0,"status":"OPEN","runners":[{"status":"ACTIVE","sortPriority":1,"id":48536142,"name":"1. Liz Of Rhyl"},{"status":"ACTIVE","sortPriority":2,"id":64253836,"name":"2. Keeperhill Fagan"},{"status":"ACTIVE","sortPriority":3,"id":68900945,"name":"3. Salacres Elmejor"},{"status":"ACTIVE","sortPriority":4,"id":69366841,"name":"4. Fleurs Gamble"},{"status":"ACTIVE","sortPriority":5,"id":63031611,"name":"5. Greencroft Oscar"},{"status":"ACTIVE","sortPriority":6,"id":40831161,"name":"6. Milton Mia"}],"regulators":["MR_INT"],"venue":"Towcester","countryCode":"GB","discountAllowed":true,"timezone":"Europe/London","openDate":"2024-06-27T13:33:00.000Z","version":5994767141,"name":"A5 500m","eventName":"Towcester 27th Jun"},"rc":[{"atb":[[1.03,10.99]],"id":63031611},{"atl":[[990,0.17]],"id":63031611},{"spn":495.51,"spf":"NaN","id":63031611},{"atb":[[1.03,10.99]],"id":69366841},{"atl":[[1000,0.17]],"id":69366841},{"spn":500.51,"spf":"NaN","id":69366841},{"atb":[[1.02,16.48]],"id":40831161},{"atl":[[990,0.17]],"id":40831161},{"spn":495.51,"spf":"NaN","id":40831161},{"atb":[[1.03,10.99]],"id":64253836},{"atl":[[990,0.17]],"id":64253836},{"spn":495.51,"spf":"NaN","id":64253836},{"atb":[[1.01,32.96]],"id":48536142},{"atl":[[990,0.17]],"id":48536142},{"spn":495.5,"spf":"NaN","id":48536142},{"atb":[[1.02,16.48]],"id":68900945},{"atl":[[990,0.17]],"id":68900945},{"spn":495.51,"spf":"NaN","id":68900945}],"con":true,"img":true}]}
{"op":"mcm","clk":"11537956523","pt":1719448682751,"mc":[{"id":"1.230180116","marketDefinition":{"bspMarket":true,"turnInPlayEnabled":false,"persistenceEnabled":false,"marketBaseRate":5.0,"eventId":"33376437","eventTypeId":"4339","numberOfWinners":1,"bettingType":"ODDS","marketType":"WIN","marketTime":"2024-06-27T14:11:00.000Z","suspendTime":"2024-06-27T14:11:00.000Z","bspReconciled":false,"complete":true,"inPlay":false,"crossMatching":false,"runnersVoidable":false,"numberOfActiveRunners":6,"betDelay":0,"status":"OPEN","runners":[{"status":"ACTIVE","sortPriority":1,"id":48536142,"name":"1. Liz Of Rhyl"},{"status":"ACTIVE","sortPriority":2,"id":64253836,"name":"2. Keeperhill Fagan"},{"status":"ACTIVE","sortPriority":3,"id":68900945,"name":"3. Salacres Elmejor"},{"status":"ACTIVE","sortPriority":4,"id":69366841,"name":"4. Fleurs Gamble"},{"status":"ACTIVE","sortPriority":5,"id":63031611,"name":"5. Greencroft Oscar"},{"status":"ACTIVE","sortPriority":6,"id":40831161,"name":"6. Milton Mia"}],"regulators":["MR_INT"],"venue":"Towcester","countryCode":"GB","discountAllowed":true,"timezone":"Europe/London","openDate":"2024-06-27T13:33:00.000Z","version":5994767141,"name":"A5 500m","eventName":"Towcester 27th Jun"},"rc":[{"atb":[[1.03,10.99]],"id":63031611},{"atl":[[990,0.17]],"id":63031611},{"spn":495.51,"spf":"NaN","id":63031611},{"atb":[[1.03,10.99]],"id":69366841},{"atl":[[1000,0.17]],"id":69366841},{"spn":500.51,"spf":"NaN","id":69366841},{"atb":[[1.02,16.48]],"id":40831161},{"atl":[[990,0.17]],"id":40831161},{"spn":495.51,"spf":"NaN","id":40831161},{"atb":[[1.03,10.99]],"id":64253836},{"atl":[[990,0.17]],"id":64253836},{"spn":495.51,"spf":"NaN","id":64253836},{"atb":[[1.01,32.96]],"id":48536142},{"atl":[[990,0.17]],"id":48536142},{"spn":495.5,"spf":"NaN","id":48536142},{"atb":[[1.02,16.48]],"id":68900945},{"atl":[[990,0.17]],"id":68900945},{"spn":495.51,"spf":"NaN","id":68900945}],"con":true,"img":true}]}
{"op":"mcm","clk":"11538172140","pt":1719454082694,"mc":[{"id":"1.230180116","marketDefinition":{"bspMarket":true,"turnInPlayEnabled":false,"persistenceEnabled":false,"marketBaseRate":5.0,"eventId":"33376437","eventTypeId":"4339","numberOfWinners":1,"bettingType":"ODDS","marketType":"WIN","marketTime":"2024-06-27T14:11:00.000Z","suspendTime":"2024-06-27T14:11:00.000Z","bspReconciled":false,"complete":true,"inPlay":false,"crossMatching":false,"runnersVoidable":false,"numberOfActiveRunners":6,"betDelay":0,"status":"OPEN","runners":[{"status":"ACTIVE","sortPriority":1,"id":48536142,"name":"1. Liz Of Rhyl"},{"status":"ACTIVE","sortPriority":2,"id":64253836,"name":"2. Keeperhill Fagan"},{"status":"ACTIVE","sortPriority":3,"id":68900945,"name":"3. Salacres Elmejor"},{"status":"ACTIVE","sortPriority":4,"id":69366841,"name":"4. Fleurs Gamble"},{"status":"ACTIVE","sortPriority":5,"id":63031611,"name":"5. Greencroft Oscar"},{"status":"ACTIVE","sortPriority":6,"id":40831161,"name":"6. Milton Mia"}],"regulators":["MR_INT"],"venue":"Towcester","countryCode":"GB","discountAllowed":true,"timezone":"Europe/London","openDate":"2024-06-27T13:33:00.000Z","version":5994767141,"name":"A5 500m","eventName":"Towcester 27th Jun"},"rc":[{"atb":[[1.03,10.99]],"id":63031611},{"atl":[[990,0.17]],"id":63031611},{"spn":495.51,"spf":"NaN","id":63031611},{"atb":[[1.03,10.99]],"id":69366841},{"atl":[[1000,0.17]],"id":69366841},{"spn":500.51,"spf":"NaN","id":69366841},{"atb":[[1.02,16.48]],"id":40831161},{"atl":[[990,0.17]],"id":40831161},{"spn":495.51,"spf":"NaN","id":40831161},{"atb":[[1.03,10.99]],"id":64253836},{"atl":[[990,0.17]],"id":64253836},{"spn":495.51,"spf":"NaN","id":64253836},{"atb":[[1.01,32.97]],"id":48536142},{"atl":[[990,0.17]],"id":48536142},{"spn":495.5,"spf":"NaN","id":48536142},{"atb":[[1.02,16.48]],"id":68900945},{"atl":[[990,0.17]],"id":68900945},{"spn":495.51,"spf":"NaN","id":68900945}],"con":true,"img":true}]}
{"op":"mcm","clk":"11538369807","pt":1719459482780,"mc":[{"id":"1.230180116","marketDefinition":{"bspMarket":true,"turnInPlayEnabled":false,"persistenceEnabled":false,"marketBaseRate":5.0,"eventId":"33376437","eventTypeId":"4339","numberOfWinners":1,"bettingType":"ODDS","marketType":"WIN","marketTime":"2024-06-27T14:11:00.000Z","suspendTime":"2024-06-27T14:11:00.000Z","bspReconciled":false,"complete":true,"inPlay":false,"crossMatching":false,"runnersVoidable":false,"numberOfActiveRunners":6,"betDelay":0,"status":"OPEN","runners":[{"status":"ACTIVE","sortPriority":1,"id":48536142,"name":"1. Liz Of Rhyl"},{"status":"ACTIVE","sortPriority":2,"id":64253836,"name":"2. Keeperhill Fagan"},{"status":"ACTIVE","sortPriority":3,"id":68900945,"name":"3. Salacres Elmejor"},{"status":"ACTIVE","sortPriority":4,"id":69366841,"name":"4. Fleurs Gamble"},{"status":"ACTIVE","sortPriority":5,"id":63031611,"name":"5. Greencroft Oscar"},{"status":"ACTIVE","sortPriority":6,"id":40831161,"name":"6. Milton Mia"}],"regulators":["MR_INT"],"venue":"Towcester","countryCode":"GB","discountAllowed":true,"timezone":"Europe/London","openDate":"2024-06-27T13:33:00.000Z","version":5994767141,"name":"A5 500m","eventName":"Towcester 27th Jun"},"rc":[{"atb":[[1.03,10.99]],"id":63031611},{"atl":[[990,0.17]],"id":63031611},{"spn":495.51,"spf":"NaN","id":63031611},{"atb":[[1.03,10.99]],"id":69366841},{"atl":[[1000,0.17]],"id":69366841},{"spn":500.51,"spf":"NaN","id":69366841},{"atb":[[1.02,16.48]],"id":40831161},{"atl":[[990,0.17]],"id":40831161},{"spn":495.51,"spf":"NaN","id":40831161},{"atb":[[1.03,10.99]],"id":64253836},{"atl":[[990,0.17]],"id":64253836},{"spn":495.51,"spf":"NaN","id":64253836},{"atb":[[1.01,32.97]],"id":48536142},{"atl":[[990,0.17]],"id":48536142},{"spn":495.5,"spf":"NaN","id":48536142},{"atb":[[1.02,16.48]],"id":68900945},{"atl":[[990,0.17]],"id":68900945},{"spn":495.51,"spf":"NaN","id":68900945}],"con":true,"img":true}]}
{"op":"mcm","clk":"11538596937","pt":1719464882723,"mc":[{"id":"1.230180116","marketDefinition":{"bspMarket":true,"turnInPlayEnabled":false,"persistenceEnabled":false,"marketBaseRate":5.0,"eventId":"33376437","eventTypeId":"4339","numberOfWinners":1,"bettingType":"ODDS","marketType":"WIN","marketTime":"2024-06-27T14:11:00.000Z","suspendTime":"2024-06-27T14:11:00.000Z","bspReconciled":false,"complete":true,"inPlay":false,"crossMatching":false,"runnersVoidable":false,"numberOfActiveRunners":6,"betDelay":0,"status":"OPEN","runners":[{"status":"ACTIVE","sortPriority":1,"id":48536142,"name":"1. Liz Of Rhyl"},{"status":"ACTIVE","sortPriority":2,"id":64253836,"name":"2. Keeperhill Fagan"},{"status":"ACTIVE","sortPriority":3,"id":68900945,"name":"3. Salacres Elmejor"},{"status":"ACTIVE","sortPriority":4,"id":69366841,"name":"4. Fleurs Gamble"},{"status":"ACTIVE","sortPriority":5,"id":63031611,"name":"5. Greencroft Oscar"},{"status":"ACTIVE","sortPriority":6,"id":40831161,"name":"6. Milton Mia"}],"regulators":["MR_INT"],"venue":"Towcester","countryCode":"GB","discountAllowed":true,"timezone":"Europe/London","openDate":"2024-06-27T13:33:00.000Z","version":5994767141,"name":"A5 500m","eventName":"Towcester 27th Jun"},"rc":[{"atb":[[1.03,10.99]],"id":63031611},{"atl":[[990,0.17]],"id":63031611},{"spn":495.51,"spf":"NaN","id":63031611},{"atb":[[1.03,10.99]],"id":69366841},{"atl":[[1000,0.17]],"id":69366841},{"spn":500.51,"spf":"NaN","id":69366841},{"atb":[[1.02,16.48]],"id":40831161},{"atl":[[990,0.17]],"id":40831161},{"spn":495.51,"spf":"NaN","id":40831161},{"atb":[[1.03,10.99]],"id":64253836},{"atl":[[990,0.17]],"id":64253836},{"spn":495.51,"spf":"NaN","id":64253836},{"atb":[[1.01,32.97]],"id":48536142},{"atl":[[990,0.17]],"id":48536142},{"spn":495.5,"spf":"NaN","id":48536142},{"atb":[[1.02,16.48]],"id":68900945},{"atl":[[990,0.17]],"id":68900945},{"spn":495.51,"spf":"NaN","id":68900945}],"con":true,"img":true}]}
{"op":"mcm","clk":"11538608203","pt":1719465079042,"mc":[{"id":"1.230180116","rc":[{"atb":[[1.03,10.99]],"id":63031611},{"atl":[[150,4]],"id":63031611},{"spn":75.51,"spf":"NaN","id":63031611},{"atb":[[1.03,10.99]],"id":69366841},{"atl":[[150,4]],"id":69366841},{"spn":75.51,"spf":"NaN","id":69366841},{"atb":[[1.02,16.48]],"id":40831161},{"atb":[[1.03,10.99]],"id":64253836},{"atl":[[150,4]],"id":64253836},{"spn":75.51,"spf":"NaN","id":64253836},{"atb":[[1.01,32.97]],"id":48536142},{"atl":[[150,4]],"id":48536142},{"spn":75.5,"spf":"NaN","id":48536142},{"atb":[[1.02,16.48]],"id":68900945},{"atl":[[150,4]],"id":68900945},{"spn":75.51,"spf":"NaN","id":68900945}],"con":true,"img":false}]}
{"op":"mcm","clk":"11538608209","pt":1719465079145,"mc":[{"id":"1.230180116","rc":[{"atl":[[150,4]],"id":40831161}],"con":true,"img":false}]}
{"op":"mcm","clk":"11538748546","pt":1719468203468,"mc":[{"id":"1.230180116","rc":[{"atb":[[2.06,8.8]],"id":63031611},{"spn":76.03,"spf":"NaN","id":63031611},{"atb":[[2.08,9.77]],"id":69366841},{"spn":76.04,"spf":"NaN","id":69366841},{"atb":[[2.1,13.45]],"id":40831161},{"spn":76.05,"spf":"NaN","id":40831161},{"atb":[[2.1,12.55]],"id":64253836},{"spn":76.05,"spf":"NaN","id":64253836},{"atb":[[2.06,10.56]],"id":48536142},{"spn":76.03,"spf":"NaN","id":48536142},{"atb":[[2.08,10.66]],"id":68900945},{"spn":76.04,"spf":"NaN","id":68900945}],"con":true,"img":false}]}
{"op":"mcm","clk":"11538751105","pt":1719468255557,"mc":[{"id":"1.230180116","rc":[{"atb":[[2.08,3.16]],"id":48536142}],"con":true,"img":false}]}
{"op":"mcm","clk":"11538751164","pt":1719468256689,"mc":[{"id":"1.230180116","rc":[{"atb":[[2.08,3.16]],"id":63031611},{"atb":[[2.12,3.16]],"id":64253836}],"con":true,"img":false}]}
{"op":"mcm","clk":"11538751173","pt":1719468256847,"mc":[{"id":"1.230180116","rc":[{"atb":[[2.1,3.16]],"id":69366841}],"con":true,"img":false}]}
{"op":"mcm","clk":"11538751208","pt":1719468257558,"mc":[{"id":"1.230180116","rc":[{"atb":[[2.1,3.16]],"id":68900945}],"con":true,"img":false}]}
{"op":"mcm","clk":"11538751222","pt":1719468257763,"mc":[{"id":"1.230180116","rc":[{"atb":[[2.12,3.16]],"id":40831161}],"con":true,"img":false}]}
{"op":"mcm","clk":"11538752382","pt":1719468281744,"mc":[{"id":"1.230180116","marketDefinition":{"bspMarket":true,"turnInPlayEnabled":false,"persistenceEnabled":false,"marketBaseRate":5.0,"eventId":"33376437","eventTypeId":"4339","numberOfWinners":1,"bettingType":"ODDS","marketType":"WIN","marketTime":"2024-06-27T14:11:00.000Z","suspendTime":"2024-06-27T14:11:00.000Z","bspReconciled":false,"complete":true,"inPlay":false,"crossMatching":true,"runnersVoidable":false,"numberOfActiveRunners":6,"betDelay":0,"status":"OPEN","runners":[{"status":"ACTIVE","sortPriority":1,"id":48536142,"name":"1. Liz Of Rhyl"},{"status":"ACTIVE","sortPriority":2,"id":64253836,"name":"2. Keeperhill Fagan"},{"status":"ACTIVE","sortPriority":3,"id":68900945,"name":"3. Salacres Elmejor"},{"status":"ACTIVE","sortPriority":4,"id":69366841,"name":"4. Fleurs Gamble"},{"status":"ACTIVE","sortPriority":5,"id":63031611,"name":"5. Greencroft Oscar"},{"status":"ACTIVE","sortPriority":6,"id":40831161,"name":"6. Milton Mia"}],"regulators":["MR_INT"],"venue":"Towcester","countryCode":"GB","discountAllowed":true,"timezone":"Europe/London","openDate":"2024-06-27T13:33:00.000Z","version":5994767141,"name":"A5 500m","eventName":"Towcester 27th Jun"},"rc":[],"con":true,"img":false}]}
{"op":"mcm","clk":"11538753303","pt":1719468298543,"mc":[{"id":"1.230180116","rc":[{"spn":76.04,"spf":"NaN","id":63031611},{"spn":76.05,"spf":"NaN","id":69366841},{"spn":76.06,"spf":"NaN","id":40831161},{"atb":[[2.12,6.55]],"id":64253836},{"spn":76.06,"spf":"NaN","id":64253836},{"spn":76.04,"spf":"NaN","id":48536142},{"spn":76.05,"spf":"NaN","id":68900945}],"con":true,"img":false}]}
{"op":"mcm","clk":"11538753355","pt":1719468299424,"mc":[{"id":"1.230180116","rc":[{"atb":[[2.1,6.55]],"id":69366841},{"atb":[[2.12,6.55]],"id":40831161}],"con":true,"img":false}]}
{"op":"mcm","clk":"11538753396","pt":1719468300043,"mc":[{"id":"1.230180116","rc":[{"atb":[[2.1,6.55]],"id":68900945}],"con":true,"img":false}]}
{"op":"mcm","clk":"11538753433","pt":1719468300611,"mc":[{"id":"1.230180116","rc":[{"atb":[[2.08,6.55]],"id":63031611}],"con":true,"img":false}]}
{"op":"mcm","clk":"11538753447","pt":1719468300927,"mc":[{"id":"1.230180116","rc":[{"atb":[[2.08,6.55]],"id":48536142}],"con":true,"img":false}]}
{"op":"mcm","clk":"11538937084","pt":1719472045831,"mc":[{"id":"1.230180116","rc":[{"atb":[[2.06,8.79],[1.03,10.98],[2.08,6.54]],"id":63031611},{"atl":[[990,0.17]],"id":63031611},{"atb":[[1.03,10.98],[2.1,6.54],[2.08,9.76]],"id":69366841},{"atl":[[1000,0.17]],"id":69366841},{"atb":[[1.02,16.47],[2.12,6.54],[2.1,13.44]],"id":40831161},{"atl":[[990,0.17]],"id":40831161},{"atb":[[1.03,10.98],[2.12,6.54],[2.1,12.55]],"id":64253836},{"atl":[[21,4],[990,0.17]],"id":64253836},{"spn":11.56,"spf":"NaN","id":64253836},{"atb":[[1.01,32.94],[2.06,10.55],[2.08,6.54]],"id":48536142},{"atl":[[990,0.17]],"id":48536142},{"atb":[[1.02,16.47],[2.1,6.54],[2.08,10.65]],"id":68900945},{"atl":[[28,0.6],[990,0.17]],"id":68900945},{"spn":15.05,"spf":"NaN","id":68900945}],"con":true,"img":false}]}
{"op":"mcm","clk":"11538940481","pt":1719472109620,"mc":[{"id":"1.230180116","rc":[{"atb":[[2.06,0]],"id":63031611},{"atb":[[2.08,0]],"id":69366841},{"atb":[[2.1,0]],"id":40831161},{"atb":[[2.1,0]],"id":64253836},{"atb":[[2.06,0]],"id":48536142},{"atb":[[2.08,0]],"id":68900945}],"con":true,"img":false}]}
{"op":"mcm","clk":"11538940486","pt":1719472109721,"mc":[{"id":"1.230180116","rc":[{"atb":[[2.1,8.79]],"id":63031611},{"atb":[[2.12,9.76]],"id":69366841},{"atb":[[2.14,13.44]],"id":40831161},{"atb":[[2.14,12.55]],"id":64253836},{"atb":[[2.1,10.55]],"id":48536142},{"atb":[[2.12,10.65]],"id":68900945}],"con":true,"img":false}]}
{"op":"mcm","clk":"11538944410","pt":1719472172075,"mc":[{"id":"1.230180116","rc":[{"spn":76.05,"spf":"NaN","id":63031611},{"atb":[[2.1,3.38]],"id":69366841},{"spn":76.06,"spf":"NaN","id":69366841},{"spn":76.07,"spf":"NaN","id":40831161},{"spn":11.57,"spf":"NaN","id":64253836},{"spn":76.05,"spf":"NaN","id":48536142},{"spn":15.06,"spf":"NaN","id":68900945}],"con":true,"img":false}]}
{"op":"mcm","clk":"11538944481","pt":1719472173303,"mc":[{"id":"1.230180116","rc":[{"atb":[[2.14,3.16]],"id":69366841}],"con":true,"img":false}]}
{"op":"mcm","clk":"11538944495","pt":1719472173511,"mc":[{"id":"1.230180116","rc":[{"atb":[[2.08,3.38]],"id":48536142}],"con":true,"img":false}]}
{"op":"mcm","clk":"11538944541","pt":1719472174120,"mc":[{"id":"1.230180116","rc":[{"atb":[[2.12,3.16]],"id":48536142}],"con":true,"img":false}]}
{"op":"mcm","clk":"11538944564","pt":1719472174631,"mc":[{"id":"1.230180116","rc":[{"atb":[[2.08,3.38]],"id":63031611}],"con":true,"img":false}]}
{"op":"mcm","clk":"11538944584","pt":1719472174889,"mc":[{"id":"1.230180116","rc":[{"atb":[[2.12,3.38]],"id":64253836}],"con":true,"img":false}]}
{"op":"mcm","clk":"11538944690","pt":1719472176728,"mc":[{"id":"1.230180116","rc":[{"atb":[[2.12,3.38]],"id":40831161}],"con":true,"img":false}]}
{"op":"mcm","clk":"11538944707","pt":1719472176884,"mc":[{"id":"1.230180116","rc":[{"atb":[[2.12,3.16]],"id":63031611},{"atb":[[2.16,3.16]],"id":40831161}],"con":true,"img":false}]}
{"op":"mcm","clk":"11538944717","pt":1719472177088,"mc":[{"id":"1.230180116","rc":[{"atb":[[2.16,3.16]],"id":64253836}],"con":true,"img":false}]}
{"op":"mcm","clk":"11538944725","pt":1719472177191,"mc":[{"id":"1.230180116","rc":[{"atb":[[2.1,3.38]],"id":68900945}],"con":true,"img":false}]}
{"op":"mcm","clk":"11538944749","pt":1719472177604,"mc":[{"id":"1.230180116","rc":[{"atb":[[2.14,3.16]],"id":68900945}],"con":true,"img":false}]}
{"op":"mcm","clk":"11538945677","pt":1719472193216,"mc":[{"id":"1.230180116","rc":[{"atb":[[2.08,0]],"id":48536142}],"con":true,"img":false}]}
{"op":"mcm","clk":"11538945704","pt":1719472193635,"mc":[{"id":"1.230180116","rc":[{"atb":[[2.08,0]],"id":63031611}],"con":true,"img":false}]}
{"op":"mcm","clk":"11538945746","pt":1719472194250,"mc":[{"id":"1.230180116","rc":[{"atb":[[2.12,0]],"id":64253836},{"atb":[[2.1,0]],"id":68900945}],"con":true,"img":false}]}
{"op":"mcm","clk":"11538945828","pt":1719472195337,"mc":[{"id":"1.230180116","rc":[{"atb":[[2.12,0]],"id":40831161}],"con":true,"img":false}]}
{"op":"mcm","clk":"11538945911","pt":1719472196571,"mc":[{"id":"1.230180116","rc":[{"atb":[[2.1,0]],"id":69366841}],"con":true,"img":false}]}
{"op":"mcm","clk":"11538946810","pt":1719472211168,"mc":[{"id":"1.230180116","rc":[{"atb":[[2.12,6.54]],"id":48536142}],"con":true,"img":false}]}
{"op":"mcm","clk":"11538946877","pt":1719472212346,"mc":[{"id":"1.230180116","rc":[{"atb":[[2.12,6.54]],"id":63031611}],"con":true,"img":false}]}
{"op":"mcm","clk":"11538946918","pt":1719472213063,"mc":[{"id":"1.230180116","rc":[{"atb":[[2.16,6.54]],"id":64253836}],"con":true,"img":false}]}
{"op":"mcm","clk":"11538946926","pt":1719472213270,"mc":[{"id":"1.230180116","rc":[{"atb":[[2.14,6.54]],"id":69366841}],"con":true,"img":false}]}
{"op":"mcm","clk":"11538946945","pt":1719472213574,"mc":[{"id":"1.230180116","rc":[{"atb":[[2.16,6.54]],"id":40831161},{"atb":[[2.14,6.54]],"id":68900945}],"con":true,"img":false}]}
{"op":"mcm","clk":"11539124125","pt":1719475682710,"mc":[{"id":"1.230180116","marketDefinition":{"bspMarket":true,"turnInPlayEnabled":false,"persistenceEnabled":false,"marketBaseRate":5.0,"eventId":"33376437","eventTypeId":"4339","numberOfWinners":1,"bettingType":"ODDS","marketType":"WIN","marketTime":"2024-06-27T14:11:00.000Z","suspendTime":"2024-06-27T14:11:00.000Z","bspReconciled":false,"complete":true,"inPlay":false,"crossMatching":true,"runnersVoidable":false,"numberOfActiveRunners":6,"betDelay":0,"status":"OPEN","runners":[{"status":"ACTIVE","sortPriority":1,"id":48536142,"name":"1. Liz Of Rhyl"},{"status":"ACTIVE","sortPriority":2,"id":64253836,"name":"2. Keeperhill Fagan"},{"status":"ACTIVE","sortPriority":3,"id":68900945,"name":"3. Salacres Elmejor"},{"status":"ACTIVE","sortPriority":4,"id":69366841,"name":"4. Fleurs Gamble"},{"status":"ACTIVE","sortPriority":5,"id":63031611,"name":"5. Greencroft Oscar"},{"status":"ACTIVE","sortPriority":6,"id":40831161,"name":"6. Milton Mia"}],"regulators":["MR_INT"],"venue":"Towcester","countryCode":"GB","discountAllowed":true,"timezone":"Europe/London","openDate":"2024-06-27T13:33:00.000Z","version":5994767141,"name":"A5 500m","eventName":"Towcester 27th Jun"},"rc":[{"atb":[[1.03,10.99],[2.12,6.55],[2.1,8.79]],"id":63031611},{"atl":[[150,4],[990,0.17]],"id":63031611},{"spn":76.06,"spf":"NaN","id":63031611},{"atb":[[1.03,10.99],[2.12,9.77],[2.14,6.55]],"id":69366841},{"atl":[[150,4],[1000,0.17]],"id":69366841},{"spn":76.07,"spf":"NaN","id":69366841},{"atb":[[1.02,16.48],[2.16,6.55],[2.14,13.45]],"id":40831161},{"atl":[[150,4],[990,0.17]],"id":40831161},{"spn":76.08,"spf":"NaN","id":40831161},{"atb":[[1.03,10.99],[2.16,6.55],[2.14,12.55]],"id":64253836},{"atl":[[150,4],[21,4],[990,0.17]],"id":64253836},{"spn":11.58,"spf":"NaN","id":64253836},{"atb":[[1.01,32.96],[2.12,6.55],[2.1,10.55]],"id":48536142},{"atl":[[150,4],[990,0.17]],"id":48536142},{"spn":76.06,"spf":"NaN","id":48536142},{"atb":[[1.02,16.48],[2.12,10.66],[2.14,6.55]],"id":68900945},{"atl":[[150,4],[28,0.6],[990,0.17]],"id":68900945},{"spn":15.07,"spf":"NaN","id":68900945}],"con":true,"img":true}]}
{"op":"mcm","clk":"11539127805","pt":1719475709754,"mc":[{"id":"1.230180116","rc":[{"atb":[[1.03,10.99],[2.12,6.55],[2.1,0]],"id":63031611},{"spn":76.06,"spf":"NaN","id":63031611},{"atb":[[1.03,10.99],[2.12,0],[2.14,6.55]],"id":69366841},{"spn":76.07,"spf":"NaN","id":69366841},{"atb":[[1.02,16.48],[2.16,6.55],[2.14,0]],"id":40831161},{"spn":76.08,"spf":"NaN","id":40831161},{"atb":[[1.03,10.99],[2.16,6.55],[2.14,0]],"id":64253836},{"spn":11.58,"spf":"NaN","id":64253836},{"atb":[[1.01,32.96],[2.12,6.55],[2.1,0]],"id":48536142},{"spn":76.06,"spf":"NaN","id":48536142},{"atb":[[1.02,16.48],[2.12,0],[2.14,6.55]],"id":68900945},{"spn":15.07,"spf":"NaN","id":68900945}],"con":true,"img":false}]}
{"op":"mcm","clk":"11539127814","pt":1719475709857,"mc":[{"id":"1.230180116","rc":[{"atb":[[2.14,8.79]],"id":63031611},{"atb":[[2.16,9.77]],"id":69366841},{"atb":[[2.18,13.45]],"id":40831161},{"atb":[[2.18,12.55]],"id":64253836},{"atb":[[2.14,10.55]],"id":48536142},{"atb":[[2.16,10.66]],"id":68900945}],"con":true,"img":false}]}
{"op":"mcm","clk":"11539128398","pt":1719475717335,"mc":[{"id":"1.230180116","rc":[{"atb":[[2.12,3.38]],"id":63031611},{"atb":[[2.16,3.38]],"id":40831161}],"con":true,"img":false}]}
{"op":"mcm","clk":"11539128429","pt":1719475717848,"mc":[{"id":"1.230180116","rc":[{"atb":[[2.14,3.38]],"id":69366841},{"atb":[[2.14,3.38]],"id":68900945}],"con":true,"img":false}]}
{"op":"mcm","clk":"11539128454","pt":1719475718262,"mc":[{"id":"1.230180116","rc":[{"atb":[[2.2,3.16]],"id":40831161}],"con":true,"img":false}]}
{"op":"mcm","clk":"11539128469","pt":1719475718570,"mc":[{"id":"1.230180116","rc":[{"atb":[[2.12,3.38]],"id":48536142}],"con":true,"img":false}]}
{"op":"mcm","clk":"11539128475","pt":1719475718671,"mc":[{"id":"1.230180116","rc":[{"atb":[[2.16,3.38]],"id":64253836}],"con":true,"img":false}]}
{"op":"mcm","clk":"11539128536","pt":1719475719545,"mc":[{"id":"1.230180116","rc":[{"atb":[[2.18,3.16]],"id":68900945}],"con":true,"img":false}]}
{"op":"mcm","clk":"11539128562","pt":1719475720161,"mc":[{"id":"1.230180116","rc":[{"atb":[[2.16,3.16]],"id":63031611}],"con":true,"img":false}]}
{"op":"mcm","clk":"11539128600","pt":1719475720778,"mc":[{"id":"1.230180116","rc":[{"atb":[[2.2,3.16]],"id":64253836}],"con":true,"img":false}]}
{"op":"mcm","clk":"11539128643","pt":1719475721451,"mc":[{"id":"1.230180116","rc":[{"atb":[[2.16,3.16]],"id":48536142}],"con":true,"img":false}]}
{"op":"mcm","clk":"11539128751","pt":1719475723163,"mc":[{"id":"1.230180116","rc":[{"atb":[[2.18,3.16]],"id":69366841}],"con":true,"img":false}]}
{"op":"mcm","clk":"11539135778","pt":1719475832503,"mc":[{"id":"1.230180116","rc":[{"spn":76.08,"spf":"NaN","id":63031611},{"spn":76.09,"spf":"NaN","id":69366841},{"spn":76.1,"spf":"NaN","id":40831161},{"spn":11.6,"spf":"NaN","id":64253836},{"atb":[[2.12,0]],"id":48536142},{"spn":76.08,"spf":"NaN","id":48536142},{"spn":15.09,"spf":"NaN","id":68900945}],"con":true,"img":false}]}
{"op":"mcm","clk":"11539135810","pt":1719475832975,"mc":[{"id":"1.230180116","rc":[{"atb":[[2.16,0]],"id":64253836}],"con":true,"img":false}]}
{"op":"mcm","clk":"11539135825","pt":1719475833173,"mc":[{"id":"1.230180116","rc":[{"atb":[[2.14,0]],"id":68900945}],"con":true,"img":false}]}
{"op":"mcm","clk":"11539135836","pt":1719475833379,"mc":[{"id":"1.230180116","rc":[{"atb":[[2.16,0]],"id":40831161}],"con":true,"img":false}]}
{"op":"mcm","clk":"11539135845","pt":1719475833589,"mc":[{"id":"1.230180116","rc":[{"atb":[[2.12,0]],"id":63031611}],"con":true,"img":false}]}
{"op":"mcm","clk":"11539135857","pt":1719475833794,"mc":[{"id":"1.230180116","rc":[{"atb":[[2.14,0]],"id":69366841}],"con":true,"img":false}]}
{"op":"mcm","clk":"11539135908","pt":1719475834611,"mc":[{"id":"1.230180116","rc":[{"atb":[[2.2,6.55]],"id":64253836}],"con":true,"img":false}]}
{"op":"mcm","clk":"11539135939","pt":1719475834972,"mc":[{"id":"1.230180116","rc":[{"atb":[[2.16,6.55]],"id":63031611}],"con":true,"img":false}]}
{"op":"mcm","clk":"11539135957","pt":1719475835279,"mc":[{"id":"1.230180116","rc":[{"atb":[[2.16,6.55]],"id":48536142}],"con":true,"img":false}]}
{"op":"mcm","clk":"11539135963","pt":1719475835484,"mc":[{"id":"1.230180116","rc":[{"atb":[[2.2,6.55]],"id":40831161}],"con":true,"img":false}]}
{"op":"mcm","clk":"11539135968","pt":1719475835587,"mc":[{"id":"1.230180116","rc":[{"atb":[[2.18,6.55]],"id":68900945}],"con":true,"img":false}]}
{"op":"mcm","clk":"11539135978","pt":1719475835791,"mc":[{"id":"1.230180116","rc":[{"atb":[[2.18,6.55]],"id":69366841}],"con":true,"img":false}]}
{"op":"mcm","clk":"11539341307","pt":1719479308648,"mc":[{"id":"1.230180116","rc":[{"atb":[[1.03,10.98],[2.16,6.54],[2.14,0]],"id":63031611},{"atb":[[1.03,10.98],[2.18,6.54],[2.16,0]],"id":69366841},{"atb":[[1.02,16.47],[2.18,0],[2.2,6.54]],"id":40831161},{"atb":[[1.03,10.98],[2.18,0],[2.2,6.54]],"id":64253836},{"atb":[[1.01,32.95],[2.16,6.54],[2.14,0]],"id":48536142},{"atb":[[1.02,16.47],[2.18,6.54],[2.16,0]],"id":68900945}],"con":true,"img":false}]}
{"op":"mcm","clk":"11539341317","pt":1719479308759,"mc":[{"id":"1.230180116","rc":[{"atb":[[2.18,8.79]],"id":63031611},{"atb":[[2.2,9.77]],"id":69366841},{"atb":[[2.22,13.45]],"id":40831161},{"atb":[[2.22,12.55]],"id":64253836},{"atb":[[2.18,10.55]],"id":48536142},{"atb":[[2.2,10.65]],"id":68900945}],"con":true,"img":false}]}
{"op":"mcm","clk":"11539347690","pt":1719479410305,"mc":[{"id":"1.230180116","rc":[{"atb":[[2.16,3.38]],"id":63031611},{"spn":76.09,"spf":"NaN","id":63031611},{"spn":76.1,"spf":"NaN","id":69366841},{"spn":76.11,"spf":"NaN","id":40831161},{"spn":11.61,"spf":"NaN","id":64253836},{"spn":76.09,"spf":"NaN","id":48536142},{"spn":15.1,"spf":"NaN","id":68900945}],"con":true,"img":false}]}
{"op":"mcm","clk":"11539347699","pt":1719479410409,"mc":[{"id":"1.230180116","rc":[{"atb":[[2.2,3.38]],"id":64253836}],"con":true,"img":false}]}
{"op":"mcm","clk":"11539347786","pt":1719479411597,"mc":[{"id":"1.230180116","rc":[{"atb":[[2.18,3.38]],"id":69366841}],"con":true,"img":false}]}
{"op":"mcm","clk":"11539347856","pt":1719479412620,"mc":[{"id":"1.230180116","rc":[{"atb":[[2.2,3.38]],"id":40831161},{"atb":[[2.16,3.38]],"id":48536142}],"con":true,"img":false}]}
{"op":"mcm","clk":"11539347913","pt":1719479413710,"mc":[{"id":"1.230180116","rc":[{"atb":[[2.18,3.38]],"id":68900945}],"con":true,"img":false}]}
{"op":"mcm","clk":"11539350847","pt":1719479458963,"mc":[{"id":"1.230180116","rc":[{"atb":[[2.16,0]],"id":63031611},{"atb":[[2.18,0]],"id":69366841},{"atb":[[2.2,0]],"id":40831161},{"atb":[[2.2,0]],"id":64253836},{"atb":[[2.16,0]],"id":48536142},{"atb":[[2.18,0]],"id":68900945}],"con":true,"img":false}]}
{"op":"mcm","clk":"11539350983","pt":1719479460775,"mc":[{"id":"1.230180116","rc":[{"atl":[[48,12],[28,8]],"id":69366841},{"atl":[[42,12],[25,8]],"id":64253836},{"atl":[[36,8],[60,12]],"id":48536142},{"atl":[[42,12],[25,8]],"id":68900945}],"con":true,"img":false}]}
{"op":"mcm","clk":"11539368518","pt":1719479717368,"mc":[{"id":"1.230180116","rc":[{"atb":[[2.2,3.16]],"id":63031611},{"spn":76.1,"spf":"NaN","id":63031611},{"spn":15.1,"spf":"NaN","id":69366841},{"spn":19.09,"spf":"NaN","id":48536142},{"spn":13.6,"spf":"NaN","id":68900945}],"con":true,"img":false}]}
{"op":"mcm","clk":"11539368544","pt":1719479717775,"mc":[{"id":"1.230180116","rc":[{"atb":[[2.24,3.16]],"id":40831161}],"con":true,"img":false}]}
{"op":"mcm","clk":"11539368559","pt":1719479717983,"mc":[{"id":"1.230180116","rc":[{"atb":[[2.24,3.16]],"id":64253836}],"con":true,"img":false}]}
{"op":"mcm","clk":"11539368608","pt":1719479718553,"mc":[{"id":"1.230180116","rc":[{"atb":[[2.2,3.16]],"id":48536142},{"atb":[[2.22,3.16]],"id":68900945}],"con":true,"img":false}]}
{"op":"mcm","clk":"11539368641","pt":1719479718966,"mc":[{"id":"1.230180116","rc":[{"atb":[[2.22,3.16]],"id":69366841}],"con":true,"img":false}]}
{"op":"mcm","clk":"11539370293","pt":1719479740611,"mc":[{"id":"1.230180116","rc":[{"atb":[[2.24,6.54]],"id":64253836},{"atb":[[2.2,6.54]],"id":48536142}],"con":true,"img":false}]}
{"op":"mcm","clk":"11539370313","pt":1719479740918,"mc":[{"id":"1.230180116","rc":[{"atb":[[2.22,6.54]],"id":69366841}],"con":true,"img":false}]}
{"op":"mcm","clk":"11539370332","pt":1719479741183,"mc":[{"id":"1.230180116","rc":[{"atb":[[2.24,6.54]],"id":40831161},{"atb":[[2.22,6.54]],"id":68900945}],"con":true,"img":false}]}
{"op":"mcm","clk":"11539370453","pt":1719479742590,"mc":[{"id":"1.230180116","rc":[{"atb":[[2.2,6.54]],"id":63031611}],"con":true,"img":false}]}
{"op":"mcm","clk":"11539440238","pt":1719481082682,"mc":[{"id":"1.230180116","marketDefinition":{"bspMarket":true,"turnInPlayEnabled":false,"persistenceEnabled":false,"marketBaseRate":5.0,"eventId":"33376437","eventTypeId":"4339","numberOfWinners":1,"bettingType":"ODDS","marketType":"WIN","marketTime":"2024-06-27T14:11:00.000Z","suspendTime":"2024-06-27T14:11:00.000Z","bspReconciled":false,"complete":true,"inPlay":false,"crossMatching":true,"runnersVoidable":false,"numberOfActiveRunners":6,"betDelay":0,"status":"OPEN","runners":[{"status":"ACTIVE","sortPriority":1,"id":48536142,"name":"1. Liz Of Rhyl"},{"status":"ACTIVE","sortPriority":2,"id":64253836,"name":"2. Keeperhill Fagan"},{"status":"ACTIVE","sortPriority":3,"id":68900945,"name":"3. Salacres Elmejor"},{"status":"ACTIVE","sortPriority":4,"id":69366841,"name":"4. Fleurs Gamble"},{"status":"ACTIVE","sortPriority":5,"id":63031611,"name":"5. Greencroft Oscar"},{"status":"ACTIVE","sortPriority":6,"id":40831161,"name":"6. Milton Mia"}],"regulators":["MR_INT"],"venue":"Towcester","countryCode":"GB","discountAllowed":true,"timezone":"Europe/London","openDate":"2024-06-27T13:33:00.000Z","version":5994767141,"name":"A5 500m","eventName":"Towcester 27th Jun"},"rc":[{"atb":[[1.03,10.98],[2.18,8.79],[2.2,6.54]],"id":63031611},{"atl":[[150,4],[990,0.17]],"id":63031611},{"spn":76.1,"spf":"NaN","id":63031611},{"atb":[[1.03,10.98],[2.22,6.54],[2.2,9.77]],"id":69366841},{"atl":[[150,4],[48,12],[28,8],[1000,0.17]],"id":69366841},{"spn":15.11,"spf":"NaN","id":69366841},{"atb":[[2.24,6.54],[2.22,13.45],[1.02,16.47]],"id":40831161},{"atl":[[150,4],[990,0.17]],"id":40831161},{"spn":76.12,"spf":"NaN","id":40831161},{"atb":[[2.24,6.54],[1.03,10.98],[2.22,12.55]],"id":64253836},{"atl":[[150,4],[21,4],[42,12],[25,8],[990,0.17]],"id":64253836},{"spn":11.62,"spf":"NaN","id":64253836},{"atb":[[1.01,32.95],[2.18,10.55],[2.2,6.54]],"id":48536142},{"atl":[[36,8],[150,4],[60,12],[990,0.17]],"id":48536142},{"spn":19.1,"spf":"NaN","id":48536142},{"atb":[[2.22,6.54],[1.02,16.47],[2.2,10.65]],"id":68900945},{"atl":[[150,4],[42,12],[25,8],[28,0.6],[990,0.17]],"id":68900945},{"spn":13.61,"spf":"NaN","id":68900945}],"con":true,"img":true}]}
{"op":"mcm","clk":"11539545287","pt":1719482908213,"mc":[{"id":"1.230180116","rc":[{"atb":[[1.03,10.98],[2.18,0],[2.2,6.54]],"id":63031611},{"atb":[[1.03,10.98],[2.22,6.54],[2.2,0]],"id":69366841},{"spn":15.11,"spf":"NaN","id":69366841},{"atb":[[2.24,6.54],[2.22,0],[1.02,16.47]],"id":40831161},{"spn":76.12,"spf":"NaN","id":40831161},{"atb":[[2.24,6.54],[1.03,10.98],[2.22,0]],"id":64253836},{"spn":11.62,"spf":"NaN","id":64253836},{"atb":[[1.01,32.95],[2.18,0],[2.2,6.54]],"id":48536142},{"spn":19.1,"spf":"NaN","id":48536142},{"atb":[[2.22,6.54],[1.02,16.47],[2.2,0]],"id":68900945},{"spn":13.61,"spf":"NaN","id":68900945}],"con":true,"img":false}]}
{"op":"mcm","clk":"11539545295","pt":1719482908257,"mc":[{"id":"1.230180116","rc":[{"atb":[[2.22,8.79]],"id":63031611},{"atb":[[2.24,9.76]],"id":69366841},{"atb":[[2.26,13.44]],"id":40831161},{"atb":[[2.26,12.55]],"id":64253836},{"atb":[[2.22,10.55]],"id":48536142},{"atb":[[2.24,10.65]],"id":68900945}],"con":true,"img":false}]}
{"op":"mcm","clk":"11539545512","pt":1719482911570,"mc":[{"id":"1.230180116","rc":[{"atb":[[2.2,3.38]],"id":48536142}],"con":true,"img":false}]}
{"op":"mcm","clk":"11539545536","pt":1719482912088,"mc":[{"id":"1.230180116","rc":[{"atb":[[2.24,3.38]],"id":64253836}],"con":true,"img":false}]}
{"op":"mcm","clk":"11539545578","pt":1719482912607,"mc":[{"id":"1.230180116","rc":[{"atb":[[2.22,3.38]],"id":69366841}],"con":true,"img":false}]}
{"op":"mcm","clk":"11539545609","pt":1719482912986,"mc":[{"id":"1.230180116","rc":[{"atb":[[2.2,3.38]],"id":63031611}],"con":true,"img":false}]}
{"op":"mcm","clk":"11539545628","pt":1719482913293,"mc":[{"id":"1.230180116","rc":[{"atb":[[2.22,3.38]],"id":68900945}],"con":true,"img":false}]}
{"op":"mcm","clk":"11539545730","pt":1719482914485,"mc":[{"id":"1.230180116","rc":[{"atb":[[2.24,3.38]],"id":40831161}],"con":true,"img":false}]}
{"op":"mcm","clk":"11539545797","pt":1719482915507,"mc":[{"id":"1.230180116","rc":[{"atb":[[2.24,3.16]],"id":48536142}],"con":true,"img":false}]}
{"op":"mcm","clk":"11539545813","pt":1719482915768,"mc":[{"id":"1.230180116","rc":[{"atb":[[2.28,3.16]],"id":64253836}],"con":true,"img":false}]}
{"op":"mcm","clk":"11539545894","pt":1719482916693,"mc":[{"id":"1.230180116","rc":[{"atb":[[2.26,3.16]],"id":69366841}],"con":true,"img":false}]}
{"op":"mcm","clk":"11539545951","pt":1719482917412,"mc":[{"id":"1.230180116","rc":[{"atb":[[2.26,3.16]],"id":68900945}],"con":true,"img":false}]}
{"op":"mcm","clk":"11539545970","pt":1719482917572,"mc":[{"id":"1.230180116","rc":[{"atb":[[2.28,3.16]],"id":40831161}],"con":true,"img":false}]}
{"op":"mcm","clk":"11539546288","pt":1719482922018,"mc":[{"id":"1.230180116","rc":[{"atb":[[2.24,3.16]],"id":63031611}],"con":true,"img":false}]}
{"op":"mcm","clk":"11539550473","pt":1719482988110,"mc":[{"id":"1.230180116","rc":[{"spn":76.12,"spf":"NaN","id":63031611},{"spn":15.13,"spf":"NaN","id":69366841},{"spn":76.14,"spf":"NaN","id":40831161},{"spn":11.64,"spf":"NaN","id":64253836},{"atb":[[2.2,0]],"id":48536142},{"spn":19.12,"spf":"NaN","id":48536142},{"spn":13.63,"spf":"NaN","id":68900945}],"con":true,"img":false}]}
{"op":"mcm","clk":"11539550509","pt":1719482988581,"mc":[{"id":"1.230180116","rc":[{"atb":[[2.24,0]],"id":64253836}],"con":true,"img":false}]}
{"op":"mcm","clk":"11539550530","pt":1719482988899,"mc":[{"id":"1.230180116","rc":[{"atb":[[2.22,0]],"id":68900945}],"con":true,"img":false}]}
{"op":"mcm","clk":"11539550547","pt":1719482989201,"mc":[{"id":"1.230180116","rc":[{"atb":[[2.2,0]],"id":63031611}],"con":true,"img":false}]}
{"op":"mcm","clk":"11539550558","pt":1719482989409,"mc":[{"id":"1.230180116","rc":[{"atb":[[2.22,0]],"id":69366841}],"con":true,"img":false}]}
{"op":"mcm","clk":"11539550653","pt":1719482990805,"mc":[{"id":"1.230180116","rc":[{"atb":[[2.24,6.54]],"id":48536142}],"con":true,"img":false}]}
{"op":"mcm","clk":"11539550692","pt":1719482991375,"mc":[{"id":"1.230180116","rc":[{"atb":[[2.26,6.54]],"id":68900945}],"con":true,"img":false}]}
{"op":"mcm","clk":"11539550714","pt":1719482991688,"mc":[{"id":"1.230180116","rc":[{"atb":[[2.24,6.54]],"id":63031611}],"con":true,"img":false}]}
{"op":"mcm","clk":"11539550777","pt":1719482992390,"mc":[{"id":"1.230180116","rc":[{"atb":[[2.24,0]],"id":40831161},{"atb":[[2.28,6.54]],"id":64253836}],"con":true,"img":false}]}
{"op":"mcm","clk":"11539550793","pt":1719482992697,"mc":[{"id":"1.230180116","rc":[{"atb":[[2.26,6.54]],"id":69366841}],"con":true,"img":false}]}
{"op":"mcm","clk":"11539550980","pt":1719482995479,"mc":[{"id":"1.230180116","rc":[{"atb":[[2.28,6.54]],"id":40831161}],"con":true,"img":false}]}
{"op":"mcm","clk":"11539555655","pt":1719483064980,"mc":[{"id":"1.230180116","rc":[{"atb":[[5,1]],"id":63031611},{"spn":77.5,"spf":"NaN","id":63031611},{"atb":[[5,1]],"id":69366841},{"spn":16.5,"spf":"NaN","id":69366841},{"atb":[[5,1]],"id":40831161},{"spn":77.5,"spf":"NaN","id":40831161},{"atb":[[4.7,1]],"id":64253836},{"spn":12.85,"spf":"NaN","id":64253836},{"atb":[[3.9,1]],"id":48536142},{"spn":19.95,"spf":"NaN","id":48536142},{"atb":[[4.7,1]],"id":68900945},{"spn":14.85,"spf":"NaN","id":68900945}],"con":true,"img":false}]}
{"op":"mcm","clk":"11539627733","pt":1719484027594,"mc":[{"id":"1.230180116","rc":[{"atb":[[1.51,196.08]],"id":63031611},{"atb":[[1.51,196.08]],"id":69366841},{"atb":[[1.51,196.08]],"id":40831161},{"atb":[[1.51,196.08]],"id":64253836},{"atb":[[1.51,196.08]],"id":48536142},{"atb":[[1.51,196.08]],"id":68900945}],"con":true,"img":false}]}
{"op":"mcm","clk":"11539670199","pt":1719484633033,"mc":[{"id":"1.230180116","rc":[{"atb":[[3.1,6]],"id":63031611},{"atb":[[3.3,6]],"id":69366841},{"atb":[[4.7,6]],"id":40831161},{"atb":[[2.86,6]],"id":64253836},{"atb":[[2.58,6]],"id":48536142},{"atb":[[2.86,6]],"id":68900945}],"con":true,"img":false}]}
{"op":"mcm","clk":"11539670770","pt":1719484640315,"mc":[{"id":"1.230180116","rc":[{"atb":[[2.12,89.29]],"id":69366841},{"atb":[[2.12,89.29]],"id":40831161}],"con":true,"img":false}]}
{"op":"mcm","clk":"11539671193","pt":1719484645795,"mc":[{"id":"1.230180116","rc":[{"atb":[[2.28,3.38]],"id":64253836}],"con":true,"img":false}]}
{"op":"mcm","clk":"11539671203","pt":1719484645905,"mc":[{"id":"1.230180116","rc":[{"atb":[[2.24,3.38]],"id":63031611},{"atb":[[2.26,3.38]],"id":69366841},{"atb":[[2.28,3.38]],"id":40831161}],"con":true,"img":false}]}
{"op":"mcm","clk":"11539671212","pt":1719484646010,"mc":[{"id":"1.230180116","rc":[{"atb":[[2.26,3.38]],"id":68900945}],"con":true,"img":false}]}
{"op":"mcm","clk":"11539671230","pt":1719484646211,"mc":[{"id":"1.230180116","rc":[{"atb":[[2.88,3.16]],"id":64253836}],"con":true,"img":false}]}
{"op":"mcm","clk":"11539671234","pt":1719484646315,"mc":[{"id":"1.230180116","rc":[{"atb":[[2.88,3.16]],"id":68900945}],"con":true,"img":false}]}
{"op":"mcm","clk":"11539676363","pt":1719484719503,"mc":[{"id":"1.230180116","rc":[{"atb":[[2.26,0]],"id":68900945}],"con":true,"img":false}]}
{"op":"mcm","clk":"11539676401","pt":1719484719864,"mc":[{"id":"1.230180116","rc":[{"atb":[[2.28,0]],"id":64253836}],"con":true,"img":false}]}
{"op":"mcm","clk":"11539676426","pt":1719484720176,"mc":[{"id":"1.230180116","rc":[{"atb":[[2.88,6.54]],"id":68900945}],"con":true,"img":false}]}
{"op":"mcm","clk":"11539676443","pt":1719484720387,"mc":[{"id":"1.230180116","rc":[{"atb":[[2.24,0]],"id":63031611},{"atb":[[2.26,0]],"id":69366841},{"atb":[[2.28,0]],"id":40831161}],"con":true,"img":false}]}
{"op":"mcm","clk":"11539676450","pt":1719484720487,"mc":[{"id":"1.230180116","rc":[{"atb":[[2.88,6.54]],"id":64253836}],"con":true,"img":false}]}
{"op":"mcm","clk":"11539812651","pt":1719486482670,"mc":[{"id":"1.230180116","marketDefinition":{"bspMarket":true,"turnInPlayEnabled":false,"persistenceEnabled":false,"marketBaseRate":5.0,"eventId":"33376437","eventTypeId":"4339","numberOfWinners":1,"bettingType":"ODDS","marketType":"WIN","marketTime":"2024-06-27T14:11:00.000Z","suspendTime":"2024-06-27T14:11:00.000Z","bspReconciled":false,"complete":true,"inPlay":false,"crossMatching":true,"runnersVoidable":false,"numberOfActiveRunners":6,"betDelay":0,"status":"OPEN","runners":[{"status":"ACTIVE","sortPriority":1,"id":48536142,"name":"1. Liz Of Rhyl"},{"status":"ACTIVE","sortPriority":2,"id":64253836,"name":"2. Keeperhill Fagan"},{"status":"ACTIVE","sortPriority":3,"id":68900945,"name":"3. Salacres Elmejor"},{"status":"ACTIVE","sortPriority":4,"id":69366841,"name":"4. Fleurs Gamble"},{"status":"ACTIVE","sortPriority":5,"id":63031611,"name":"5. Greencroft Oscar"},{"status":"ACTIVE","sortPriority":6,"id":40831161,"name":"6. Milton Mia"}],"regulators":["MR_INT"],"venue":"Towcester","countryCode":"GB","discountAllowed":true,"timezone":"Europe/London","openDate":"2024-06-27T13:33:00.000Z","version":5994767141,"name":"A5 500m","eventName":"Towcester 27th Jun"},"rc":[{"atb":[[5,1],[1.03,10.98],[3.1,6],[2.22,8.79],[1.51,196.08]],"id":63031611},{"atl":[[150,4],[990,0.17]],"id":63031611},{"spn":77.5,"spf":"NaN","id":63031611},{"atb":[[2.24,9.77],[5,1],[1.03,10.98],[2.12,89.29],[1.51,196.08],[3.3,6]],"id":69366841},{"atl":[[150,4],[48,12],[28,8],[1000,0.17]],"id":69366841},{"spn":16.5,"spf":"NaN","id":69366841},{"atb":[[5,1],[1.02,16.47],[2.12,89.29],[2.26,13.45],[1.51,196.08],[4.7,6]],"id":40831161},{"atl":[[150,4],[990,0.17]],"id":40831161},{"spn":77.5,"spf":"NaN","id":40831161},{"atb":[[2.88,6.54],[2.86,6],[1.03,10.98],[2.26,12.55],[1.51,196.08],[4.7,1]],"id":64253836},{"atl":[[150,4],[21,4],[42,12],[25,8],[990,0.17]],"id":64253836},{"spn":12.85,"spf":"NaN","id":64253836},{"atb":[[2.24,6.54],[1.01,32.95],[2.22,10.55],[2.58,6],[1.51,196.08],[3.9,1]],"id":48536142},{"atl":[[36,8],[150,4],[60,12],[990,0.17]],"id":48536142},{"spn":19.95,"spf":"NaN","id":48536142},{"atb":[[2.24,10.65],[2.88,6.54],[2.86,6],[1.02,16.47],[1.51,196.08],[4.7,1]],"id":68900945},{"atl":[[150,4],[42,12],[25,8],[28,0.6],[990,0.17]],"id":68900945},{"spn":14.85,"spf":"NaN","id":68900945}],"con":true,"img":true}]}
{"op":"mcm","clk":"11539817115","pt":1719486503922,"mc":[{"id":"1.230180116","rc":[{"atb":[[1.03,10.98],[2.22,8.79]],"id":63031611},{"atb":[[2.24,9.77],[1.03,10.98]],"id":69366841},{"atb":[[1.02,16.47],[2.26,13.45]],"id":40831161},{"atb":[[2.88,6.54],[1.03,10.98],[2.26,12.55]],"id":64253836},{"atb":[[2.24,6.54],[1.01,32.95],[2.22,0]],"id":48536142},{"atb":[[2.24,10.65],[2.88,6.54],[1.02,16.47]],"id":68900945}],"con":true,"img":false}]}
{"op":"mcm","clk":"11539817126","pt":1719486504027,"mc":[{"id":"1.230180116","rc":[{"atb":[[2.26,10.55]],"id":48536142}],"con":true,"img":false}]}
{"op":"mcm","clk":"11539819219","pt":1719486526946,"mc":[{"id":"1.230180116","rc":[{"atb":[[2.24,3.38]],"id":48536142}],"con":true,"img":false}]}
{"op":"mcm","clk":"11539819286","pt":1719486527670,"mc":[{"id":"1.230180116","rc":[{"atb":[[2.28,3.16]],"id":48536142}],"con":true,"img":false}]}
{"op":"mcm","clk":"11539825778","pt":1719486605046,"mc":[{"id":"1.230180116","rc":[{"atb":[[2.24,0]],"id":48536142}],"con":true,"img":false}]}
{"op":"mcm","clk":"11539826160","pt":1719486609883,"mc":[{"id":"1.230180116","rc":[{"atb":[[2.28,6.54]],"id":48536142}],"con":true,"img":false}]}
{"op":"mcm","clk":"11539840427","pt":1719486803410,"mc":[{"id":"1.230180116","rc":[{"atb":[[2.26,0]],"id":48536142}],"con":true,"img":false}]}
{"op":"mcm","clk":"11539840433","pt":1719486803509,"mc":[{"id":"1.230180116","rc":[{"atb":[[2.3,10.55]],"id":48536142}],"con":true,"img":false}]}
{"op":"mcm","clk":"11539841637","pt":1719486823446,"mc":[{"id":"1.230180116","rc":[{"atb":[[2.28,3.38]],"id":48536142}],"con":true,"img":false}]}
{"op":"mcm","clk":"11539843343","pt":1719486848584,"mc":[{"id":"1.230180116","rc":[{"atb":[[2.28,0]],"id":48536142}],"con":true,"img":false}]}
{"op":"mcm","clk":"11539849152","pt":1719486930209,"mc":[{"id":"1.230180116","rc":[{"atb":[[2.32,3.38]],"id":48536142}],"con":true,"img":false}]}
{"op":"mcm","clk":"11539850530","pt":1719486947215,"mc":[{"id":"1.230180116","rc":[{"atb":[[2.32,6.54]],"id":48536142}],"con":true,"img":false}]}
{"op":"mcm","clk":"11540014247","pt":1719488997762,"mc":[{"id":"1.230180116","rc":[{"atl":[[560,2]],"id":63031611},{"atb":[[1.16,150]],"id":69366841},{"atl":[[270,2]],"id":69366841},{"atl":[[500,2]],"id":40831161},{"atb":[[1.16,150]],"id":64253836},{"atl":[[390,2]],"id":64253836},{"atb":[[1.16,150]],"id":48536142},{"atl":[[370,2]],"id":48536142},{"atb":[[1.16,150]],"id":68900945},{"atl":[[550,2]],"id":68900945}],"con":true,"img":false}]}
{"op":"mcm","clk":"11540014255","pt":1719488997859,"mc":[{"id":"1.230180116","rc":[{"atb":[[1.16,150]],"id":63031611}],"con":true,"img":false}]}
{"op":"mcm","clk":"11540014267","pt":1719488997962,"mc":[{"id":"1.230180116","rc":[{"atb":[[1.16,150]],"id":40831161}],"con":true,"img":false}]}
{"op":"mcm","clk":"11540136172","pt":1719490398982,"mc":[{"id":"1.230180116","rc":[{"atb":[[2.88,6.54]],"id":64253836},{"atb":[[2.32,6.54],[2.3,0]],"id":48536142},{"atb":[[2.88,6.54]],"id":68900945}],"con":true,"img":false}]}
{"op":"mcm","clk":"11540136178","pt":1719490399085,"mc":[{"id":"1.230180116","rc":[{"atb":[[2.34,10.55]],"id":48536142}],"con":true,"img":false}]}
{"op":"mcm","clk":"11540142115","pt":1719490456931,"mc":[{"id":"1.230180116","rc":[{"atb":[[2.32,3.16]],"id":48536142}],"con":true,"img":false}]}
{"op":"mcm","clk":"11540142185","pt":1719490457501,"mc":[{"id":"1.230180116","rc":[{"atb":[[2.36,3.38]],"id":48536142}],"con":true,"img":false}]}
{"op":"mcm","clk":"11540144838","pt":1719490483044,"mc":[{"id":"1.230180116","rc":[{"atb":[[2.32,0]],"id":48536142}],"con":true,"img":false}]}
{"op":"mcm","clk":"11540145656","pt":1719490491014,"mc":[{"id":"1.230180116","rc":[{"atb":[[2.36,6.54]],"id":48536142}],"con":true,"img":false}]}
{"op":"mcm","clk":"11540326518","pt":1719493049869,"mc":[{"id":"1.230180116","rc":[{"atb":[[1.04,75.28]],"id":63031611},{"atl":[[980,1.54]],"id":63031611},{"atb":[[1.03,220.78]],"id":69366841},{"atl":[[990,1.58]],"id":69366841},{"atb":[[1.04,120.12]],"id":40831161},{"atl":[[990,1.53]],"id":40831161},{"atb":[[1.03,156.49]],"id":64253836},{"atl":[[960,0.87]],"id":64253836},{"atb":[[1.04,193.72]],"id":48536142},{"atl":[[990,2.1]],"id":48536142},{"atb":[[1.04,119.27]],"id":68900945},{"atl":[[980,2.02]],"id":68900945}],"con":true,"img":false}]}
{"op":"mcm","clk":"11540490824","pt":1719495119090,"mc":[{"id":"1.230180116","rc":[{"atb":[[1.03,11],[2.22,8.8],[1.04,75.37]],"id":63031611},{"atl":[[980,1.54],[990,0.17]],"id":63031611},{"atb":[[2.24,9.78],[1.03,221.04]],"id":69366841},{"atl":[[990,1.58],[1000,0.17]],"id":69366841},{"atb":[[1.02,16.49],[2.26,13.46],[1.04,120.26]],"id":40831161},{"atl":[[990,1.53]],"id":40831161},{"spl":[[1.01,1]],"id":64253836},{"atb":[[2.88,6.54],[1.03,156.67],[2.26,12.56]],"id":64253836},{"atl":[[960,0.87],[990,0.17]],"id":64253836},{"spn":4.7,"spf":1.0,"id":64253836},{"atb":[[2.36,6.54],[1.01,32.99],[2.34,10.57],[1.04,193.95]],"id":48536142},{"atl":[[990,2.1]],"id":48536142},{"atb":[[2.24,10.67],[2.88,6.54],[1.02,16.49],[1.04,119.42]],"id":68900945},{"atl":[[980,2.02],[990,0.17]],"id":68900945}],"con":true,"img":false}]}
{"op":"mcm","clk":"11540494416","pt":1719495156415,"mc":[{"id":"1.230180116","rc":[{"atl":[[24,1.74]],"id":68900945}],"con":true,"img":false}]}
{"op":"mcm","clk":"11540494443","pt":1719495156724,"mc":[{"id":"1.230180116","rc":[{"atl":[[20,1.54]],"id":64253836}],"con":true,"img":false}]}
{"op":"mcm","clk":"11540551390","pt":1719495811594,"mc":[{"id":"1.230180116","rc":[{"atb":[[7,1.5]],"id":63031611},{"spn":78.5,"spf":"NaN","id":63031611},{"spn":14.35,"spf":"NaN","id":68900945}],"con":true,"img":false}]}
{"op":"mcm","clk":"11540551694","pt":1719495814784,"mc":[{"id":"1.230180116","rc":[{"atb":[[2.12,89.29]],"id":63031611}],"con":true,"img":false}]}
{"op":"mcm","clk":"11540565791","pt":1719495960533,"mc":[{"id":"1.230180116","rc":[{"atl":[[190,4]],"id":63031611},{"atl":[[190,4]],"id":69366841},{"atl":[[190,4]],"id":64253836},{"atl":[[190,4]],"id":48536142},{"atl":[[190,4]],"id":68900945}],"con":true,"img":false}]}
{"op":"mcm","clk":"11540565797","pt":1719495960641,"mc":[{"id":"1.230180116","rc":[{"atl":[[190,4]],"id":40831161}],"con":true,"img":false}]}
{"op":"mcm","clk":"11540566123","pt":1719495964740,"mc":[{"id":"1.230180116","rc":[{"atb":[[1.02,2]],"id":48536142}],"con":true,"img":false}]}
{"op":"mcm","clk":"11540566143","pt":1719495964945,"mc":[{"id":"1.230180116","rc":[{"atb":[[1.02,2]],"id":64253836}],"con":true,"img":false}]}
{"op":"mcm","clk":"11540566159","pt":1719495965147,"mc":[{"id":"1.230180116","rc":[{"atb":[[1.02,18.49]],"id":68900945}],"con":true,"img":false}]}
{"op":"mcm","clk":"11540566175","pt":1719495965350,"mc":[{"id":"1.230180116","rc":[{"atb":[[1.02,2]],"id":69366841}],"con":true,"img":false}]}
{"op":"mcm","clk":"11540566216","pt":1719495965667,"mc":[{"id":"1.230180116","rc":[{"atb":[[1.02,2]],"id":63031611}],"con":true,"img":false}]}
{"op":"mcm","clk":"11540566245","pt":1719495965922,"mc":[{"id":"1.230180116","rc":[{"atb":[[1.02,18.49]],"id":40831161}],"con":true,"img":false}]}
{"op":"mcm","clk":"11540621512","pt":1719496547059,"mc":[{"id":"1.230180116","rc":[{"atl":[[19.5,0.84]],"id":64253836},{"atl":[[23,0.84]],"id":68900945},{"spn":13.85,"spf":"NaN","id":68900945}],"con":true,"img":false}]}
{"op":"mcm","clk":"11540622397","pt":1719496558102,"mc":[{"id":"1.230180116","rc":[{"atb":[[1.1,1.69]],"id":64253836},{"atb":[[1.09,1.69]],"id":48536142}],"con":true,"img":false}]}
{"op":"mcm","clk":"11540622428","pt":1719496558359,"mc":[{"id":"1.230180116","rc":[{"atb":[[1.12,1.69]],"id":69366841},{"atb":[[1.1,1.69]],"id":68900945}],"con":true,"img":false}]}
{"op":"mcm","clk":"11540622456","pt":1719496558667,"mc":[{"id":"1.230180116","rc":[{"atb":[[1.1,0.06]],"id":64253836},{"atb":[[1.09,0.07]],"id":48536142}],"con":true,"img":false}]}
{"op":"mcm","clk":"11540622472","pt":1719496558879,"mc":[{"id":"1.230180116","rc":[{"atb":[[1.16,151.69]],"id":63031611}],"con":true,"img":false}]}
{"op":"mcm","clk":"11540622492","pt":1719496559079,"mc":[{"id":"1.230180116","rc":[{"atb":[[1.12,1.69]],"id":40831161}],"con":true,"img":false}]}
{"op":"mcm","clk":"11540622500","pt":1719496559182,"mc":[{"id":"1.230180116","rc":[{"atb":[[1.12,0.05]],"id":69366841}],"con":true,"img":false}]}
{"op":"mcm","clk":"11540622529","pt":1719496559491,"mc":[{"id":"1.230180116","rc":[{"atb":[[1.1,0.06]],"id":68900945}],"con":true,"img":false}]}
{"op":"mcm","clk":"11540622537","pt":1719496559593,"mc":[{"id":"1.230180116","rc":[{"atb":[[1.09,0]],"id":48536142}],"con":true,"img":false}]}
{"op":"mcm","clk":"11540622543","pt":1719496559696,"mc":[{"id":"1.230180116","rc":[{"atb":[[3.95,0.07]],"id":48536142}],"con":true,"img":false}]}
{"op":"mcm","clk":"11540622577","pt":1719496560162,"mc":[{"id":"1.230180116","rc":[{"atb":[[1.1,0]],"id":64253836}],"con":true,"img":false}]}
{"op":"mcm","clk":"11540622591","pt":1719496560322,"mc":[{"id":"1.230180116","rc":[{"atb":[[4.8,0.06],[2.9,6.55]],"id":64253836},{"atl":[[20,5.54]],"id":64253836}],"con":true,"img":false}]}
{"op":"mcm","clk":"11540622601","pt":1719496560417,"mc":[{"id":"1.230180116","rc":[{"atb":[[3.8,8.81]],"id":63031611},{"atl":[[70,2]],"id":63031611},{"atb":[[3.35,9.78]],"id":69366841},{"atl":[[27,3.85]],"id":69366841},{"atb":[[4.8,13.47]],"id":40831161},{"atl":[[140,2]],"id":40831161},{"atb":[[2.6,6.55]],"id":48536142},{"atl":[[22,4.76]],"id":48536142},{"atb":[[2.9,6.55]],"id":68900945},{"atl":[[24,3.74]],"id":68900945}],"con":true,"img":false}]}
{"op":"mcm","clk":"11540622626","pt":1719496560678,"mc":[{"id":"1.230180116","rc":[{"atb":[[1.12,0.05]],"id":40831161},{"atl":[[21,2]],"id":48536142}],"con":true,"img":false}]}
{"op":"mcm","clk":"11540622637","pt":1719496560781,"mc":[{"id":"1.230180116","rc":[{"atb":[[1.16,150.04]],"id":63031611}],"con":true,"img":false}]}
{"op":"mcm","clk":"11540622673","pt":1719496561200,"mc":[{"id":"1.230180116","rc":[{"atb":[[1.12,0]],"id":69366841},{"atb":[[1.02,3.7]],"id":64253836},{"atl":[[1000,1.7]],"id":64253836},{"atb":[[1.02,3.7]],"id":48536142},{"atl":[[1000,1.7]],"id":48536142},{"atb":[[1.02,20.2]],"id":68900945},{"atl":[[1000,1.7]],"id":68900945}],"con":true,"img":false}]}
{"op":"mcm","clk":"11540622682","pt":1719496561297,"mc":[{"id":"1.230180116","rc":[{"atb":[[5.1,0.05]],"id":69366841}],"con":true,"img":false}]}
{"op":"mcm","clk":"11540622689","pt":1719496561399,"mc":[{"id":"1.230180116","rc":[{"atb":[[1.02,2.16]],"id":64253836},{"atl":[[1000,0.01]],"id":64253836},{"atb":[[1.02,2.19]],"id":48536142},{"atl":[[1000,0.01]],"id":48536142},{"atb":[[1.02,18.66]],"id":68900945},{"atl":[[1000,0.01]],"id":68900945}],"con":true,"img":false}]}
{"op":"mcm","clk":"11540622702","pt":1719496561607,"mc":[{"id":"1.230180116","rc":[{"atb":[[1.02,2]],"id":64253836},{"atl":[[1000,0]],"id":64253836},{"atb":[[1.02,2]],"id":48536142},{"atl":[[1000,0]],"id":48536142},{"atb":[[1.02,18.49],[1.1,0]],"id":68900945},{"atl":[[1000,0]],"id":68900945}],"con":true,"img":false}]}
{"op":"mcm","clk":"11540622711","pt":1719496561661,"mc":[{"id":"1.230180116","rc":[{"atb":[[2.92,0.16]],"id":64253836},{"atl":[[19.5,0.86]],"id":64253836},{"atb":[[2.62,0.19]],"id":48536142},{"atl":[[20,0.01]],"id":48536142},{"atb":[[4.8,0.06],[2.92,0.16]],"id":68900945},{"atl":[[23,0.86]],"id":68900945}],"con":true,"img":false}]}
{"op":"mcm","clk":"11540622738","pt":1719496561969,"mc":[{"id":"1.230180116","rc":[{"atb":[[1.12,0]],"id":40831161}],"con":true,"img":false}]}
{"op":"mcm","clk":"11540622750","pt":1719496562078,"mc":[{"id":"1.230180116","rc":[{"atb":[[5.1,0.05]],"id":40831161}],"con":true,"img":false}]}
{"op":"mcm","clk":"11540622758","pt":1719496562176,"mc":[{"id":"1.230180116","rc":[{"atl":[[70,0],[85,2],[11,1]],"id":63031611},{"atl":[[6.8,1]],"id":48536142}],"con":true,"img":false}]}
{"op":"mcm","clk":"11540622769","pt":1719496562280,"mc":[{"id":"1.230180116","rc":[{"atl":[[20,2.01],[22,0]],"id":48536142}],"con":true,"img":false}]}
{"op":"mcm","clk":"11540622786","pt":1719496562485,"mc":[{"id":"1.230180116","rc":[{"atb":[[1.16,150]],"id":63031611}],"con":true,"img":false}]}
{"op":"mcm","clk":"11540622793","pt":1719496562588,"mc":[{"id":"1.230180116","rc":[{"atb":[[7.2,0.04]],"id":63031611}],"con":true,"img":false}]}
{"op":"mcm","clk":"11540622843","pt":1719496563316,"mc":[{"id":"1.230180116","rc":[{"atl":[[21,0]],"id":48536142}],"con":true,"img":false}]}
{"op":"mcm","clk":"11540622854","pt":1719496563364,"mc":[{"id":"1.230180116","rc":[{"atl":[[20,0.01],[26,4]],"id":48536142}],"con":true,"img":false}]}
{"op":"mcm","clk":"11540623636","pt":1719496572184,"mc":[{"id":"1.230180116","rc":[{"atb":[[2.36,3.16]],"id":48536142}],"con":true,"img":false}]}
{"op":"mcm","clk":"11540623650","pt":1719496572390,"mc":[{"id":"1.230180116","rc":[{"atl":[[6.6,2]],"id":48536142}],"con":true,"img":false}]}
{"op":"mcm","clk":"11540623658","pt":1719496572493,"mc":[{"id":"1.230180116","rc":[{"atl":[[7.2,4],[26,0]],"id":48536142}],"con":true,"img":false}]}
{"op":"mcm","clk":"11540623677","pt":1719496572812,"mc":[{"id":"1.230180116","rc":[{"atb":[[2.88,3.16]],"id":68900945}],"con":true,"img":false}]}
{"op":"mcm","clk":"11540623685","pt":1719496572910,"mc":[{"id":"1.230180116","rc":[{"atb":[[2.88,3.16]],"id":64253836}],"con":true,"img":false}]}
{"op":"mcm","clk":"11540623730","pt":1719496573523,"mc":[{"id":"1.230180116","rc":[{"atb":[[2.92,3.55]],"id":64253836}],"con":true,"img":false}]}
{"op":"mcm","clk":"11540623736","pt":1719496573625,"mc":[{"id":"1.230180116","rc":[{"atb":[[2.92,3.55]],"id":68900945}],"con":true,"img":false}]}
{"op":"mcm","clk":"11540623764","pt":1719496573888,"mc":[{"id":"1.230180116","rc":[{"atb":[[2.62,3.58]],"id":48536142}],"con":true,"img":false}]}
{"op":"mcm","clk":"11540623922","pt":1719496575584,"mc":[{"id":"1.230180116","rc":[{"atb":[[2.36,0]],"id":48536142}],"con":true,"img":false}]}
{"op":"mcm","clk":"11540623930","pt":1719496575692,"mc":[{"id":"1.230180116","rc":[{"atb":[[2.88,0]],"id":64253836}],"con":true,"img":false}]}
{"op":"mcm","clk":"11540623946","pt":1719496575896,"mc":[{"id":"1.230180116","rc":[{"atb":[[2.62,6.74]],"id":48536142}],"con":true,"img":false}]}
{"op":"mcm","clk":"11540623956","pt":1719496575999,"mc":[{"id":"1.230180116","rc":[{"atb":[[2.88,0]],"id":68900945}],"con":true,"img":false}]}
{"op":"mcm","clk":"11540623974","pt":1719496576202,"mc":[{"id":"1.230180116","rc":[{"atb":[[2.92,6.71]],"id":64253836}],"con":true,"img":false}]}
{"op":"mcm","clk":"11540623997","pt":1719496576510,"mc":[{"id":"1.230180116","rc":[{"atb":[[2.92,6.71]],"id":68900945}],"con":true,"img":false}]}
{"op":"mcm","clk":"11540624088","pt":1719496577694,"mc":[{"id":"1.230180116","rc":[{"atl":[[6.6,0]],"id":48536142}],"con":true,"img":false}]}
{"op":"mcm","clk":"11540624095","pt":1719496577802,"mc":[{"id":"1.230180116","rc":[{"atl":[[7.2,0],[20,5.27]],"id":48536142}],"con":true,"img":false}]}
{"op":"mcm","clk":"11540624105","pt":1719496577904,"mc":[{"id":"1.230180116","rc":[{"atl":[[20,0.01],[26,4]],"id":48536142}],"con":true,"img":false}]}
{"op":"mcm","clk":"11540624236","pt":1719496579397,"mc":[{"id":"1.230180116","rc":[{"atl":[[6.6,2]],"id":48536142}],"con":true,"img":false}]}
{"op":"mcm","clk":"11540624247","pt":1719496579502,"mc":[{"id":"1.230180116","rc":[{"atl":[[7.2,4],[26,0]],"id":48536142}],"con":true,"img":false}]}
{"op":"mcm","clk":"11540624310","pt":1719496580325,"mc":[{"id":"1.230180116","rc":[{"atb":[[3.95,0]],"id":48536142},{"trd":[[3.95,0.14]],"ltp":3.95,"tv":0.14,"id":48536142}],"con":true,"img":false}]}
{"op":"mcm","clk":"11540624350","pt":1719496580737,"mc":[{"id":"1.230180116","rc":[{"atb":[[7.2,0]],"id":63031611},{"atb":[[5.1,0]],"id":69366841},{"atb":[[5.1,0]],"id":40831161},{"atb":[[4.8,0]],"id":64253836},{"atb":[[4.8,0]],"id":68900945}],"con":true,"img":false}]}
{"op":"mcm","clk":"11540624426","pt":1719496581413,"mc":[{"id":"1.230180116","rc":[{"atl":[[10.5,1]],"id":63031611},{"atb":[[2.98,1]],"id":48536142}],"con":true,"img":false}]}
{"op":"mcm","clk":"11540624440","pt":1719496581515,"mc":[{"id":"1.230180116","rc":[{"atl":[[11,0]],"id":63031611}],"con":true,"img":false}]}
{"op":"mcm","clk":"11540624676","pt":1719496584101,"mc":[{"id":"1.230180116","rc":[{"atl":[[1000,0.19]],"id":48536142}],"con":true,"img":false}]}
{"op":"mcm","clk":"11540624703","pt":1719496584410,"mc":[{"id":"1.230180116","rc":[{"atl":[[1000,0]],"id":48536142}],"con":true,"img":false}]}
{"op":"mcm","clk":"11540624711","pt":1719496584513,"mc":[{"id":"1.230180116","rc":[{"atl":[[6.4,0.19]],"id":48536142}],"con":true,"img":false}]}
{"op":"mcm","clk":"11540624723","pt":1719496584618,"mc":[{"id":"1.230180116","rc":[{"atl":[[6.6,0]],"id":48536142}],"con":true,"img":false}]}
{"op":"mcm","clk":"11540624814","pt":1719496585699,"mc":[{"id":"1.230180116","rc":[{"atl":[[26,0.97]],"id":69366841}],"con":true,"img":false}]}
{"op":"mcm","clk":"11540624981","pt":1719496587201,"mc":[{"id":"1.230180116","rc":[{"atl":[[6.6,2]],"id":48536142}],"con":true,"img":false}]}
{"op":"mcm","clk":"11540625328","pt":1719496591331,"mc":[{"id":"1.230180116","rc":[{"atb":[[3.9,0]],"id":48536142},{"trd":[[3.9,2]],"ltp":3.9,"tv":2.0,"id":48536142}],"con":true,"img":false}]}
{"op":"mcm","clk":"11540625391","pt":1719496592015,"mc":[{"id":"1.230180116","rc":[{"atb":[[3.65,1]],"id":48536142}],"con":true,"img":false}]}
{"op":"mcm","clk":"11540625434","pt":1719496592530,"mc":[{"id":"1.230180116","rc":[{"atl":[[6.6,0]],"id":48536142}],"con":true,"img":false}]}
{"op":"mcm","clk":"11540625577","pt":1719496594331,"mc":[{"id":"1.230180116","rc":[{"atl":[[6.6,2]],"id":48536142}],"con":true,"img":false}]}
{"op":"mcm","clk":"11540626024","pt":1719496599640,"mc":[{"id":"1.230180116","rc":[{"atl":[[6.6,0]],"id":48536142}],"con":true,"img":false}]}
{"op":"mcm","clk":"11540626040","pt":1719496599848,"mc":[{"id":"1.230180116","rc":[{"atl":[[6.4,0]],"id":48536142}],"con":true,"img":false}]}
{"op":"mcm","clk":"11540626048","pt":1719496599910,"mc":[{"id":"1.230180116","rc":[{"atl":[[7.2,0],[20,5.27]],"id":48536142}],"con":true,"img":false}]}
{"op":"mcm","clk":"11540626142","pt":1719496601042,"mc":[{"id":"1.230180116","rc":[{"atl":[[1000,0.18]],"id":48536142}],"con":true,"img":false}]}
{"op":"mcm","clk":"11540626165","pt":1719496601347,"mc":[{"id":"1.230180116","rc":[{"atl":[[1000,0]],"id":48536142}],"con":true,"img":false}]}
{"op":"mcm","clk":"11540626172","pt":1719496601450,"mc":[{"id":"1.230180116","rc":[{"atl":[[6.6,0.18]],"id":48536142}],"con":true,"img":false}]}
{"op":"mcm","clk":"11540626259","pt":1719496602230,"mc":[{"id":"1.230180116","rc":[{"atb":[[3.65,0]],"id":48536142},{"trd":[[3.65,2]],"ltp":3.65,"tv":2.0,"id":48536142}],"con":true,"img":false}]}
{"op":"mcm","clk":"11540626323","pt":1719496602911,"mc":[{"id":"1.230180116","rc":[{"atl":[[6.6,2.18]],"id":48536142}],"con":true,"img":false}]}
{"op":"mcm","clk":"11540626677","pt":1719496607243,"mc":[{"id":"1.230180116","rc":[{"spn":8.75,"spf":"NaN","id":63031611},{"spn":15.5,"spf":"NaN","id":69366841},{"spn":72.5,"spf":"NaN","id":40831161},{"atb":[[3.4,1]],"id":48536142},{"spn":5.0,"spf":"NaN","id":48536142}],"con":true,"img":false}]}
{"op":"mcm","clk":"11540626750","pt":1719496608128,"mc":[{"id":"1.230180116","rc":[{"atl":[[6.6,0.18]],"id":48536142}],"con":true,"img":false}]}
{"op":"mcm","clk":"11540626766","pt":1719496608327,"mc":[{"id":"1.230180116","rc":[{"atb":[[2.92,6.54]],"id":64253836},{"atl":[[19.5,0.84]],"id":64253836},{"atb":[[2.62,6.54]],"id":48536142},{"atl":[[20,5.26]],"id":48536142},{"atb":[[2.92,6.54]],"id":68900945},{"atl":[[23,0.84]],"id":68900945}],"con":true,"img":false}]}
{"op":"mcm","clk":"11540626893","pt":1719496609932,"mc":[{"id":"1.230180116","rc":[{"atl":[[6.6,2.18]],"id":48536142}],"con":true,"img":false}]}
{"op":"mcm","clk":"11540626914","pt":1719496610138,"mc":[{"id":"1.230180116","rc":[{"atl":[[20,0],[7.4,8]],"id":48536142}],"con":true,"img":false}]}
{"op":"mcm","clk":"11540627329","pt":1719496615225,"mc":[{"id":"1.230180116","rc":[{"atl":[[6.6,0.18]],"id":48536142}],"con":true,"img":false}]}
{"op":"mcm","clk":"11540627431","pt":1719496616665,"mc":[{"id":"1.230180116","rc":[{"atl":[[6.6,0]],"id":48536142}],"con":true,"img":false}]}
{"op":"mcm","clk":"11540627436","pt":1719496616772,"mc":[{"id":"1.230180116","rc":[{"atl":[[7.4,0],[27,3.85]],"id":48536142}],"con":true,"img":false}]}
{"op":"mcm","clk":"11540627442","pt":1719496616822,"mc":[{"id":"1.230180116","rc":[{"atl":[[1000,0.18]],"id":48536142}],"con":true,"img":false}]}
{"op":"mcm","clk":"11540627449","pt":1719496616926,"mc":[{"id":"1.230180116","rc":[{"atl":[[6.6,2]],"id":48536142}],"con":true,"img":false}]}
{"op":"mcm","clk":"11540627455","pt":1719496617027,"mc":[{"id":"1.230180116","rc":[{"atl":[[1000,0]],"id":48536142}],"con":true,"img":false}]}
{"op":"mcm","clk":"11540627461","pt":1719496617130,"mc":[{"id":"1.230180116","rc":[{"atl":[[6.6,2.18]],"id":48536142}],"con":true,"img":false}]}
{"op":"mcm","clk":"11540627896","pt":1719496622140,"mc":[{"id":"1.230180116","rc":[{"atl":[[6.6,0.18]],"id":48536142}],"con":true,"img":false}]}
{"op":"mcm","clk":"11540628123","pt":1719496624787,"mc":[{"id":"1.230180116","rc":[{"atl":[[6.6,2.18]],"id":48536142}],"con":true,"img":false}]}
{"op":"mcm","clk":"11540628225","pt":1719496626276,"mc":[{"id":"1.230180116","rc":[{"atl":[[27,0]],"id":48536142}],"con":true,"img":false}]}
{"op":"mcm","clk":"11540628232","pt":1719496626379,"mc":[{"id":"1.230180116","rc":[{"atl":[[7.4,8]],"id":48536142}],"con":true,"img":false}]}
{"op":"mcm","clk":"11540628429","pt":1719496628556,"mc":[{"id":"1.230180116","rc":[{"atb":[[2.28,9.25]],"id":40831161}],"con":true,"img":false}]}
{"op":"mcm","clk":"11540628439","pt":1719496628653,"mc":[{"id":"1.230180116","rc":[{"atb":[[2.26,9.4]],"id":69366841}],"con":true,"img":false}]}
{"op":"mcm","clk":"11540628449","pt":1719496628757,"mc":[{"id":"1.230180116","rc":[{"atb":[[2.62,13.86]],"id":48536142}],"con":true,"img":false}]}
{"op":"mcm","clk":"11540628559","pt":1719496629992,"mc":[{"id":"1.230180116","rc":[{"atl":[[6.6,0.18]],"id":48536142}],"con":true,"img":false}]}
{"op":"mcm","clk":"11540628698","pt":1719496631855,"mc":[{"id":"1.230180116","rc":[{"atl":[[6.6,2.18]],"id":48536142}],"con":true,"img":false}]}
{"op":"mcm","clk":"11540628741","pt":1719496632375,"mc":[{"id":"1.230180116","rc":[{"atl":[[6.6,2]],"id":48536142}],"con":true,"img":false}]}
{"op":"mcm","clk":"11540628761","pt":1719496632581,"mc":[{"id":"1.230180116","rc":[{"atl":[[1000,0.18]],"id":48536142}],"con":true,"img":false}]}
{"op":"mcm","clk":"11540628784","pt":1719496632787,"mc":[{"id":"1.230180116","rc":[{"atl":[[1000,0]],"id":48536142}],"con":true,"img":false}]}
{"op":"mcm","clk":"11540628795","pt":1719496632890,"mc":[{"id":"1.230180116","rc":[{"atl":[[6.6,2.18]],"id":48536142}],"con":true,"img":false}]}
{"op":"mcm","clk":"11540629116","pt":1719496637078,"mc":[{"id":"1.230180116","rc":[{"atl":[[6.6,0.18]],"id":48536142}],"con":true,"img":false}]}
{"op":"mcm","clk":"11540629261","pt":1719496638885,"mc":[{"id":"1.230180116","rc":[{"atl":[[6.6,2.18]],"id":48536142}],"con":true,"img":false}]}
{"op":"mcm","clk":"11540629664","pt":1719496644107,"mc":[{"id":"1.230180116","rc":[{"atl":[[6.6,0.18]],"id":48536142}],"con":true,"img":false}]}
{"op":"mcm","clk":"11540629862","pt":1719496646683,"mc":[{"id":"1.230180116","rc":[{"atl":[[6.6,2.18]],"id":48536142}],"con":true,"img":false}]}
{"op":"mcm","clk":"11540629975","pt":1719496648183,"mc":[{"id":"1.230180116","rc":[{"atl":[[6.6,2]],"id":48536142}],"con":true,"img":false}]}
{"op":"mcm","clk":"11540629984","pt":1719496648390,"mc":[{"id":"1.230180116","rc":[{"atl":[[1000,0.19]],"id":48536142}],"con":true,"img":false}]}
{"op":"mcm","clk":"11540630000","pt":1719496648594,"mc":[{"id":"1.230180116","rc":[{"atl":[[1000,0]],"id":48536142}],"con":true,"img":false}]}
{"op":"mcm","clk":"11540630010","pt":1719496648698,"mc":[{"id":"1.230180116","rc":[{"atl":[[6.4,0.19]],"id":48536142}],"con":true,"img":false}]}
{"op":"mcm","clk":"11540630042","pt":1719496649115,"mc":[{"id":"1.230180116","rc":[{"atb":[[2.62,10.47]],"id":48536142}],"con":true,"img":false}]}
{"op":"mcm","clk":"11540630058","pt":1719496649314,"mc":[{"id":"1.230180116","rc":[{"atb":[[2.62,19.1]],"id":48536142}],"con":true,"img":false}]}
{"op":"mcm","clk":"11540630068","pt":1719496649369,"mc":[{"id":"1.230180116","rc":[{"atb":[[2.64,3.38]],"id":48536142}],"con":true,"img":false}]}
{"op":"mcm","clk":"11540630302","pt":1719496652023,"mc":[{"id":"1.230180116","rc":[{"atl":[[6.6,0]],"id":48536142}],"con":true,"img":false}]}
{"op":"mcm","clk":"11540630474","pt":1719496653786,"mc":[{"id":"1.230180116","rc":[{"atl":[[6.6,2]],"id":48536142}],"con":true,"img":false}]}
{"op":"mcm","clk":"11540630911","pt":1719496659019,"mc":[{"id":"1.230180116","rc":[{"atl":[[6.6,0]],"id":48536142}],"con":true,"img":false}]}
{"op":"mcm","clk":"11540630969","pt":1719496659689,"mc":[{"id":"1.230180116","rc":[{"spl":[[1.01,4]],"id":63031611}],"con":true,"img":false}]}
{"op":"mcm","clk":"11540631035","pt":1719496660821,"mc":[{"id":"1.230180116","rc":[{"atl":[[6.6,2]],"id":48536142}],"con":true,"img":false}]}
{"op":"mcm","clk":"11540631270","pt":1719496664099,"mc":[{"id":"1.230180116","rc":[{"atl":[[6.4,0]],"id":48536142}],"con":true,"img":false}]}
{"op":"mcm","clk":"11540631315","pt":1719496664612,"mc":[{"id":"1.230180116","rc":[{"atl":[[1000,0.19]],"id":48536142}],"con":true,"img":false}]}
{"op":"mcm","clk":"11540631334","pt":1719496664920,"mc":[{"id":"1.230180116","rc":[{"atl":[[1000,0]],"id":48536142}],"con":true,"img":false}]}
{"op":"mcm","clk":"11540631346","pt":1719496665030,"mc":[{"id":"1.230180116","rc":[{"atl":[[6.4,0.19]],"id":48536142}],"con":true,"img":false}]}
{"op":"mcm","clk":"11540631373","pt":1719496665391,"mc":[{"id":"1.230180116","rc":[{"atb":[[2.62,15.94]],"id":48536142}],"con":true,"img":false}]}
{"op":"mcm","clk":"11540631382","pt":1719496665490,"mc":[{"id":"1.230180116","rc":[{"atl":[[6.4,1.03]],"id":48536142}],"con":true,"img":false}]}
{"op":"mcm","clk":"11540631393","pt":1719496665593,"mc":[{"id":"1.230180116","rc":[{"atb":[[2.64,6.54]],"id":48536142}],"con":true,"img":false}]}
{"op":"mcm","clk":"11540631427","pt":1719496666115,"mc":[{"id":"1.230180116","rc":[{"atl":[[6.6,0]],"id":48536142}],"con":true,"img":false}]}
{"op":"mcm","clk":"11540631469","pt":1719496666626,"mc":[{"id":"1.230180116","rc":[{"atl":[[6.4,0.19]],"id":48536142}],"con":true,"img":false}]}
{"op":"mcm","clk":"11540631631","pt":1719496668610,"mc":[{"id":"1.230180116","rc":[{"spn":5.3,"spf":1.0,"id":63031611},{"atl":[[6.6,2]],"id":48536142},{"spn":4.9,"spf":"NaN","id":48536142}],"con":true,"img":false}]}
{"op":"mcm","clk":"11540631989","pt":1719496673039,"mc":[{"id":"1.230180116","rc":[{"atl":[[6.4,1.03]],"id":48536142}],"con":true,"img":false}]}
{"op":"mcm","clk":"11540632067","pt":1719496673820,"mc":[{"id":"1.230180116","rc":[{"atl":[[6.6,0]],"id":48536142}],"con":true,"img":false}]}
{"op":"mcm","clk":"11540632089","pt":1719496674135,"mc":[{"id":"1.230180116","rc":[{"atl":[[6.4,0.19]],"id":48536142}],"con":true,"img":false}]}
{"op":"mcm","clk":"11540632203","pt":1719496675733,"mc":[{"id":"1.230180116","rc":[{"atl":[[6.6,2]],"id":48536142}],"con":true,"img":false}]}
{"op":"mcm","clk":"11540632522","pt":1719496680048,"mc":[{"id":"1.230180116","rc":[{"atl":[[6.4,1.03]],"id":48536142}],"con":true,"img":false}]}
{"op":"mcm","clk":"11540632545","pt":1719496680257,"mc":[{"id":"1.230180116","rc":[{"atl":[[6.4,0.84]],"id":48536142}],"con":true,"img":false}]}
{"op":"mcm","clk":"11540632573","pt":1719496680521,"mc":[{"id":"1.230180116","rc":[{"atl":[[1000,0.19]],"id":48536142}],"con":true,"img":false}]}
{"op":"mcm","clk":"11540632592","pt":1719496680733,"mc":[{"id":"1.230180116","rc":[{"atl":[[1000,0]],"id":48536142}],"con":true,"img":false}]}
{"op":"mcm","clk":"11540632601","pt":1719496680839,"mc":[{"id":"1.230180116","rc":[{"atl":[[6.4,1.03]],"id":48536142}],"con":true,"img":false}]}
{"op":"mcm","clk":"11540632609","pt":1719496680942,"mc":[{"id":"1.230180116","rc":[{"atl":[[6.6,0]],"id":48536142}],"con":true,"img":false}]}
{"op":"mcm","clk":"11540632671","pt":1719496681627,"mc":[{"id":"1.230180116","rc":[{"atl":[[6.4,0.19]],"id":48536142}],"con":true,"img":false}]}
{"op":"mcm","clk":"11540632861","pt":1719496684246,"mc":[{"id":"1.230180116","rc":[{"atl":[[6.6,2]],"id":48536142}],"con":true,"img":false}]}
{"op":"mcm","clk":"11540632911","pt":1719496684721,"mc":[{"id":"1.230180116","rc":[{"atl":[[1000,1.7]],"id":48536142}],"con":true,"img":false}]}
{"op":"mcm","clk":"11540632923","pt":1719496684827,"mc":[{"id":"1.230180116","rc":[{"atb":[[1.02,3.7]],"id":64253836},{"atl":[[1000,1.7]],"id":64253836},{"atb":[[1.02,3.7]],"id":48536142},{"atb":[[1.02,20.2]],"id":68900945},{"atl":[[1000,1.7]],"id":68900945}],"con":true,"img":false}]}
{"op":"mcm","clk":"11540632936","pt":1719496685036,"mc":[{"id":"1.230180116","rc":[{"atl":[[1000,0.05]],"id":48536142},{"atb":[[1.02,18.65]],"id":68900945},{"atl":[[1000,0.01]],"id":68900945}],"con":true,"img":false}]}
{"op":"mcm","clk":"11540632945","pt":1719496685138,"mc":[{"id":"1.230180116","rc":[{"atb":[[1.02,2.15]],"id":64253836},{"atl":[[1000,0.01]],"id":64253836},{"atb":[[1.02,2.15]],"id":48536142}],"con":true,"img":false}]}
{"op":"mcm","clk":"11540632952","pt":1719496685241,"mc":[{"id":"1.230180116","rc":[{"atl":[[1000,0]],"id":48536142},{"atl":[[1000,0]],"id":68900945}],"con":true,"img":false}]}
{"op":"mcm","clk":"11540632961","pt":1719496685347,"mc":[{"id":"1.230180116","rc":[{"atb":[[2.28,10.91]],"id":69366841},{"atb":[[2.3,10.74]],"id":40831161},{"atb":[[1.02,2]],"id":64253836},{"atl":[[1000,0]],"id":64253836},{"atb":[[1.02,2]],"id":48536142},{"atl":[[6.4,0.24]],"id":48536142},{"atb":[[1.02,18.49]],"id":68900945},{"atl":[[23,0.86]],"id":68900945}],"con":true,"img":false}]}
{"op":"mcm","clk":"11540632968","pt":1719496685461,"mc":[{"id":"1.230180116","rc":[{"atb":[[2.94,0.15]],"id":64253836},{"atl":[[19.5,0.86]],"id":64253836},{"atb":[[3,0.15]],"id":48536142},{"atb":[[2.94,0.15]],"id":68900945}],"con":true,"img":false}]}
{"op":"mcm","clk":"11540632975","pt":1719496685558,"mc":[{"id":"1.230180116","rc":[{"atb":[[2.6,0],[2.84,6.55]],"id":48536142}],"con":true,"img":false}]}
{"op":"mcm","clk":"11540633177","pt":1719496687549,"mc":[{"id":"1.230180116","rc":[{"atl":[[6.4,1.09]],"id":48536142}],"con":true,"img":false}]}
{"op":"mcm","clk":"11540633337","pt":1719496689429,"mc":[{"id":"1.230180116","rc":[{"atl":[[6.6,0]],"id":48536142}],"con":true,"img":false}]}
{"op":"mcm","clk":"11540633394","pt":1719496690051,"mc":[{"id":"1.230180116","rc":[{"atl":[[6.4,0.24]],"id":48536142}],"con":true,"img":false}]}
{"op":"mcm","clk":"11540633527","pt":1719496691928,"mc":[{"id":"1.230180116","rc":[{"atl":[[6.6,2]],"id":48536142}],"con":true,"img":false}]}
{"op":"mcm","clk":"11540633717","pt":1719496694641,"mc":[{"id":"1.230180116","rc":[{"atl":[[6.4,1.09]],"id":48536142}],"con":true,"img":false}]}
{"op":"mcm","clk":"11540633814","pt":1719496696062,"mc":[{"id":"1.230180116","rc":[{"atl":[[6.4,0.9]],"id":48536142}],"con":true,"img":false}]}
{"op":"mcm","clk":"11540633829","pt":1719496696250,"mc":[{"id":"1.230180116","rc":[{"atl":[[1000,0.19]],"id":48536142}],"con":true,"img":false}]}
{"op":"mcm","clk":"11540633846","pt":1719496696456,"mc":[{"id":"1.230180116","rc":[{"atl":[[1000,0]],"id":48536142}],"con":true,"img":false}]}
{"op":"mcm","clk":"11540633852","pt":1719496696565,"mc":[{"id":"1.230180116","rc":[{"atl":[[6.2,0.19]],"id":48536142}],"con":true,"img":false}]}
{"op":"mcm","clk":"11540633903","pt":1719496697246,"mc":[{"id":"1.230180116","rc":[{"atl":[[6.6,0]],"id":48536142}],"con":true,"img":false}]}
{"op":"mcm","clk":"11540633931","pt":1719496697659,"mc":[{"id":"1.230180116","rc":[{"atl":[[6.4,0.05]],"id":48536142}],"con":true,"img":false}]}
{"op":"mcm","clk":"11540634100","pt":1719496699757,"mc":[{"id":"1.230180116","rc":[{"atl":[[6.6,2]],"id":48536142}],"con":true,"img":false}]}
{"op":"mcm","clk":"11540634281","pt":1719496701840,"mc":[{"id":"1.230180116","rc":[{"atb":[[2.64,3.38]],"id":48536142}],"con":true,"img":false}]}
{"op":"mcm","clk":"11540634298","pt":1719496702046,"mc":[{"id":"1.230180116","rc":[{"atl":[[6.4,0.9]],"id":48536142}],"con":true,"img":false}]}
{"op":"mcm","clk":"11540634322","pt":1719496702362,"mc":[{"id":"1.230180116","rc":[{"atb":[[2.86,3.16]],"id":48536142}],"con":true,"img":false}]}
{"op":"mcm","clk":"11540634561","pt":1719496705177,"mc":[{"id":"1.230180116","rc":[{"atl":[[6.6,0]],"id":48536142}],"con":true,"img":false}]}
{"op":"mcm","clk":"11540634610","pt":1719496705646,"mc":[{"id":"1.230180116","rc":[{"atl":[[6.4,0.05]],"id":48536142}],"con":true,"img":false}]}
{"op":"mcm","clk":"11540634762","pt":1719496707462,"mc":[{"id":"1.230180116","rc":[{"atl":[[6.6,2]],"id":48536142}],"con":true,"img":false}]}
{"op":"mcm","clk":"11540634890","pt":1719496709075,"mc":[{"id":"1.230180116","rc":[{"atl":[[6.4,0.9]],"id":48536142}],"con":true,"img":false}]}
{"op":"mcm","clk":"11540635114","pt":1719496711852,"mc":[{"id":"1.230180116","rc":[{"atl":[[6.2,0]],"id":48536142}],"con":true,"img":false}]}
{"op":"mcm","clk":"11540635129","pt":1719496712048,"mc":[{"id":"1.230180116","rc":[{"atl":[[1000,0.19]],"id":48536142}],"con":true,"img":false}]}
{"op":"mcm","clk":"11540635143","pt":1719496712264,"mc":[{"id":"1.230180116","rc":[{"atl":[[1000,0]],"id":48536142}],"con":true,"img":false}]}
{"op":"mcm","clk":"11540635148","pt":1719496712363,"mc":[{"id":"1.230180116","rc":[{"atl":[[6.2,0.19]],"id":48536142}],"con":true,"img":false}]}
{"op":"mcm","clk":"11540635189","pt":1719496712780,"mc":[{"id":"1.230180116","rc":[{"atl":[[6.6,0]],"id":48536142}],"con":true,"img":false}]}
{"op":"mcm","clk":"11540635223","pt":1719496713196,"mc":[{"id":"1.230180116","rc":[{"atl":[[6.4,0.05]],"id":48536142}],"con":true,"img":false}]}
{"op":"mcm","clk":"11540635421","pt":1719496715371,"mc":[{"id":"1.230180116","rc":[{"atl":[[6.6,2]],"id":48536142}],"con":true,"img":false}]}
{"op":"mcm","clk":"11540635519","pt":1719496716563,"mc":[{"id":"1.230180116","rc":[{"atl":[[6.4,0.9]],"id":48536142}],"con":true,"img":false}]}
{"op":"mcm","clk":"11540635561","pt":1719496717083,"mc":[{"id":"1.230180116","rc":[{"atl":[[6.6,0]],"id":48536142}],"con":true,"img":false}]}
{"op":"mcm","clk":"11540635599","pt":1719496717549,"mc":[{"id":"1.230180116","rc":[{"atl":[[6.4,0.05]],"id":48536142}],"con":true,"img":false}]}
{"op":"mcm","clk":"11540635864","pt":1719496721076,"mc":[{"id":"1.230180116","rc":[{"atb":[[2.64,0]],"id":48536142}],"con":true,"img":false}]}
{"op":"mcm","clk":"11540635883","pt":1719496721385,"mc":[{"id":"1.230180116","rc":[{"atb":[[2.86,6.54]],"id":48536142}],"con":true,"img":false}]}
{"op":"mcm","clk":"11540635961","pt":1719496722373,"mc":[{"id":"1.230180116","rc":[{"atl":[[6.6,2]],"id":48536142}],"con":true,"img":false}]}
{"op":"mcm","clk":"11540636042","pt":1719496723099,"mc":[{"id":"1.230180116","rc":[{"atb":[[2.94,0]],"id":64253836},{"atl":[[19.5,0.84]],"id":64253836},{"atb":[[3,0]],"id":48536142},{"atl":[[6.4,0]],"id":48536142},{"atb":[[2.94,0]],"id":68900945},{"atl":[[23,0.84]],"id":68900945}],"con":true,"img":false}]}
{"op":"mcm","clk":"11540636137","pt":1719496724085,"mc":[{"id":"1.230180116","rc":[{"atl":[[6.4,0.84]],"id":48536142}],"con":true,"img":false}]}
{"op":"mcm","clk":"11540636413","pt":1719496727672,"mc":[{"id":"1.230180116","rc":[{"atl":[[6.2,0],[6.6,0]],"id":48536142}],"con":true,"img":false}]}
{"op":"mcm","clk":"11540636420","pt":1719496727791,"mc":[{"id":"1.230180116","rc":[{"atb":[[2.26,0]],"id":69366841},{"atb":[[2.28,0]],"id":40831161},{"atb":[[2.62,8.63]],"id":48536142}],"con":true,"img":false}]}
{"op":"mcm","clk":"11540636454","pt":1719496728194,"mc":[{"id":"1.230180116","rc":[{"atl":[[6.4,0],[1000,0.18]],"id":48536142}],"con":true,"img":false}]}
{"op":"mcm","clk":"11540636467","pt":1719496728290,"mc":[{"id":"1.230180116","rc":[{"atl":[[27,3.85]],"id":48536142}],"con":true,"img":false}]}
{"op":"mcm","clk":"11540636476","pt":1719496728396,"mc":[{"id":"1.230180116","rc":[{"atl":[[7.4,0],[1000,0]],"id":48536142}],"con":true,"img":false}]}
{"op":"mcm","clk":"11540636485","pt":1719496728499,"mc":[{"id":"1.230180116","rc":[{"atl":[[6.6,0.18]],"id":48536142}],"con":true,"img":false}]}
{"op":"mcm","clk":"11540636564","pt":1719496729385,"mc":[{"id":"1.230180116","rc":[{"atl":[[6.6,2.18]],"id":48536142},{"spn":5.0,"spf":"NaN","id":48536142}],"con":true,"img":false}]}
{"op":"mcm","clk":"11540636777","pt":1719496731588,"mc":[{"id":"1.230180116","rc":[{"atl":[[6.4,0.84]],"id":48536142}],"con":true,"img":false}]}
{"op":"mcm","clk":"11540637016","pt":1719496734585,"mc":[{"id":"1.230180116","rc":[{"atl":[[6.6,0.18]],"id":48536142}],"con":true,"img":false}]}
{"op":"mcm","clk":"11540637068","pt":1719496735207,"mc":[{"id":"1.230180116","rc":[{"atl":[[6.4,0]],"id":48536142}],"con":true,"img":false}]}
{"op":"mcm","clk":"11540637227","pt":1719496737181,"mc":[{"id":"1.230180116","rc":[{"atl":[[6.6,2.18]],"id":48536142}],"con":true,"img":false}]}
{"op":"mcm","clk":"11540637242","pt":1719496737384,"mc":[{"id":"1.230180116","rc":[{"atl":[[7.4,8],[27,0]],"id":48536142}],"con":true,"img":false}]}
{"op":"mcm","clk":"11540637269","pt":1719496737811,"mc":[{"id":"1.230180116","rc":[{"atb":[[2.6,7.41]],"id":48536142}],"con":true,"img":false}]}
{"op":"mcm","clk":"11540637280","pt":1719496738316,"mc":[{"id":"1.230180116","rc":[{"atb":[[2.32,8.97]],"id":40831161}],"con":true,"img":false}]}
{"op":"mcm","clk":"11540637288","pt":1719496738357,"mc":[{"id":"1.230180116","rc":[{"atb":[[2.3,9.11]],"id":69366841}],"con":true,"img":false}]}
{"op":"mcm","clk":"11540637317","pt":1719496738670,"mc":[{"id":"1.230180116","rc":[{"atl":[[6.4,0.84]],"id":48536142}],"con":true,"img":false}]}
{"op":"mcm","clk":"11540637593","pt":1719496742419,"mc":[{"id":"1.230180116","rc":[{"atl":[[6.6,0.18]],"id":48536142}],"con":true,"img":false}]}
{"op":"mcm","clk":"11540637615","pt":1719496742719,"mc":[{"id":"1.230180116","rc":[{"atb":[[3.35,12.98]],"id":69366841},{"atb":[[2.92,10.56]],"id":64253836},{"atb":[[2.86,8.95]],"id":48536142},{"atb":[[2.92,10.56]],"id":68900945}],"con":true,"img":false}]}
{"op":"mcm","clk":"11540637644","pt":1719496743084,"mc":[{"id":"1.230180116","rc":[{"atl":[[6.4,0]],"id":48536142}],"con":true,"img":false}]}
{"op":"mcm","clk":"11540637677","pt":1719496743506,"mc":[{"id":"1.230180116","rc":[{"atb":[[7,2.52]],"id":63031611}],"con":true,"img":false}]}
{"op":"mcm","clk":"11540637697","pt":1719496743707,"mc":[{"id":"1.230180116","rc":[{"atb":[[2.62,0]],"id":48536142},{"atl":[[6.6,0]],"id":48536142}],"con":true,"img":false}]}
{"op":"mcm","clk":"11540637714","pt":1719496743914,"mc":[{"id":"1.230180116","rc":[{"atl":[[7.4,0],[27,3.85]],"id":48536142}],"con":true,"img":false}]}
{"op":"mcm","clk":"11540637724","pt":1719496744017,"mc":[{"id":"1.230180116","rc":[{"atb":[[7.2,0.84]],"id":63031611}],"con":true,"img":false}]}
{"op":"mcm","clk":"11540637747","pt":1719496744223,"mc":[{"id":"1.230180116","rc":[{"atl":[[1000,0.18]],"id":48536142}],"con":true,"img":false}]}
{"op":"mcm","clk":"11540637756","pt":1719496744279,"mc":[{"id":"1.230180116","rc":[{"atl":[[6.6,2]],"id":48536142}],"con":true,"img":false}]}
{"op":"mcm","clk":"11540637777","pt":1719496744484,"mc":[{"id":"1.230180116","rc":[{"atl":[[7.4,8],[27,0],[1000,0]],"id":48536142}],"con":true,"img":false}]}
{"op":"mcm","clk":"11540637789","pt":1719496744593,"mc":[{"id":"1.230180116","rc":[{"atl":[[6.6,2.18]],"id":48536142}],"con":true,"img":false}]}
{"op":"mcm","clk":"11540637901","pt":1719496746035,"mc":[{"id":"1.230180116","rc":[{"atl":[[6.4,0.84]],"id":48536142}],"con":true,"img":false}]}
{"op":"mcm","clk":"11540638202","pt":1719496749511,"mc":[{"id":"1.230180116","rc":[{"atl":[[6.6,0.18]],"id":48536142}],"con":true,"img":false}]}
{"op":"mcm","clk":"11540638268","pt":1719496750134,"mc":[{"id":"1.230180116","rc":[{"atl":[[6.4,0]],"id":48536142}],"con":true,"img":false}]}
{"op":"mcm","clk":"11540638356","pt":1719496751373,"mc":[{"id":"1.230180116","rc":[{"atl":[[6.6,2.18]],"id":48536142}],"con":true,"img":false}]}
{"op":"mcm","clk":"11540638529","pt":1719496753618,"mc":[{"id":"1.230180116","rc":[{"atl":[[6.4,0.84]],"id":48536142}],"con":true,"img":false}]}
{"op":"mcm","clk":"11540638688","pt":1719496755942,"mc":[{"id":"1.230180116","rc":[{"atb":[[2.92,7.17]],"id":68900945}],"con":true,"img":false}]}
{"op":"mcm","clk":"11540638696","pt":1719496756005,"mc":[{"id":"1.230180116","rc":[{"atb":[[2.92,7.17]],"id":64253836}],"con":true,"img":false}]}
{"op":"mcm","clk":"11540638714","pt":1719496756217,"mc":[{"id":"1.230180116","rc":[{"atb":[[2.92,4.01]],"id":68900945}],"con":true,"img":false}]}
{"op":"mcm","clk":"11540638727","pt":1719496756326,"mc":[{"id":"1.230180116","rc":[{"atb":[[2.92,4.01]],"id":64253836}],"con":true,"img":false}]}
{"op":"mcm","clk":"11540638748","pt":1719496756524,"mc":[{"id":"1.230180116","rc":[{"atl":[[6.6,0.18]],"id":48536142},{"atb":[[2.94,3.16]],"id":68900945}],"con":true,"img":false}]}
{"op":"mcm","clk":"11540638760","pt":1719496756630,"mc":[{"id":"1.230180116","rc":[{"atb":[[2.94,3.16]],"id":64253836}],"con":true,"img":false}]}
{"op":"mcm","clk":"11540638791","pt":1719496757133,"mc":[{"id":"1.230180116","rc":[{"atb":[[2.86,5.79]],"id":48536142},{"atl":[[6.4,0]],"id":48536142},{"atb":[[2.94,6.54]],"id":68900945}],"con":true,"img":false}]}
{"op":"mcm","clk":"11540638797","pt":1719496757241,"mc":[{"id":"1.230180116","rc":[{"atb":[[2.94,6.54]],"id":64253836}],"con":true,"img":false}]}
{"op":"mcm","clk":"11540638807","pt":1719496757341,"mc":[{"id":"1.230180116","rc":[{"atb":[[2.88,3.16]],"id":48536142}],"con":true,"img":false}]}
{"op":"mcm","clk":"11540638922","pt":1719496759022,"mc":[{"id":"1.230180116","rc":[{"atl":[[6.6,2.18]],"id":48536142}],"con":true,"img":false}]}
{"op":"mcm","clk":"11540638992","pt":1719496759837,"mc":[{"id":"1.230180116","rc":[{"atl":[[6.6,2]],"id":48536142}],"con":true,"img":false}]}
{"op":"mcm","clk":"11540639026","pt":1719496760230,"mc":[{"id":"1.230180116","rc":[{"atl":[[1000,0.19]],"id":48536142}],"con":true,"img":false}]}
{"op":"mcm","clk":"11540639041","pt":1719496760432,"mc":[{"id":"1.230180116","rc":[{"atl":[[1000,0]],"id":48536142}],"con":true,"img":false}]}
{"op":"mcm","clk":"11540639047","pt":1719496760540,"mc":[{"id":"1.230180116","rc":[{"atl":[[6.4,0.19]],"id":48536142}],"con":true,"img":false}]}
{"op":"mcm","clk":"11540639082","pt":1719496761015,"mc":[{"id":"1.230180116","rc":[{"atl":[[6.4,1.03]],"id":48536142}],"con":true,"img":false}]}
{"op":"mcm","clk":"11540639342","pt":1719496764228,"mc":[{"id":"1.230180116","rc":[{"atl":[[6.6,0]],"id":48536142}],"con":true,"img":false}]}
{"op":"mcm","clk":"11540639377","pt":1719496764643,"mc":[{"id":"1.230180116","rc":[{"atl":[[6.4,0.19]],"id":48536142}],"con":true,"img":false}]}
{"op":"mcm","clk":"11540639483","pt":1719496766127,"mc":[{"id":"1.230180116","rc":[{"atl":[[6.6,2]],"id":48536142}],"con":true,"img":false}]}
{"op":"mcm","clk":"11540639619","pt":1719496768047,"mc":[{"id":"1.230180116","rc":[{"atl":[[6.4,1.03]],"id":48536142}],"con":true,"img":false}]}
{"op":"mcm","clk":"11540639863","pt":1719496771326,"mc":[{"id":"1.230180116","rc":[{"atl":[[6.6,0]],"id":48536142}],"con":true,"img":false}]}
{"op":"mcm","clk":"11540639885","pt":1719496771641,"mc":[{"id":"1.230180116","rc":[{"atl":[[6.4,0.19]],"id":48536142}],"con":true,"img":false}]}
{"op":"mcm","clk":"11540640013","pt":1719496773157,"mc":[{"id":"1.230180116","rc":[{"atl":[[6.6,2]],"id":48536142}],"con":true,"img":false}]}
{"op":"mcm","clk":"11540640064","pt":1719496773838,"mc":[{"id":"1.230180116","rc":[{"atb":[[2.92,0]],"id":64253836},{"atb":[[2.86,3.38]],"id":48536142},{"atb":[[2.92,0]],"id":68900945}],"con":true,"img":false}]}
{"op":"mcm","clk":"11540640163","pt":1719496775035,"mc":[{"id":"1.230180116","rc":[{"atl":[[6.4,1.03]],"id":48536142}],"con":true,"img":false}]}
{"op":"mcm","clk":"11540640199","pt":1719496775448,"mc":[{"id":"1.230180116","rc":[{"atb":[[2.94,3.38]],"id":64253836},{"atb":[[2.88,0]],"id":48536142},{"atb":[[2.94,3.38]],"id":68900945}],"con":true,"img":false}]}
{"op":"mcm","clk":"11540640224","pt":1719496775766,"mc":[{"id":"1.230180116","rc":[{"atl":[[6.4,0.84]],"id":48536142}],"con":true,"img":false}]}
{"op":"mcm","clk":"11540640251","pt":1719496776025,"mc":[{"id":"1.230180116","rc":[{"atl":[[1000,0.19]],"id":48536142}],"con":true,"img":false}]}
{"op":"mcm","clk":"11540640268","pt":1719496776229,"mc":[{"id":"1.230180116","rc":[{"atl":[[1000,0]],"id":48536142}],"con":true,"img":false}]}
{"op":"mcm","clk":"11540640278","pt":1719496776328,"mc":[{"id":"1.230180116","rc":[{"atl":[[6.2,0.19]],"id":48536142}],"con":true,"img":false}]}
{"op":"mcm","clk":"11540640447","pt":1719496778442,"mc":[{"id":"1.230180116","rc":[{"atl":[[6.6,0]],"id":48536142}],"con":true,"img":false}]}
{"op":"mcm","clk":"11540640499","pt":1719496779123,"mc":[{"id":"1.230180116","rc":[{"atl":[[6.4,0]],"id":48536142}],"con":true,"img":false}]}
{"op":"mcm","clk":"11540640635","pt":1719496780957,"mc":[{"id":"1.230180116","rc":[{"atb":[[2.28,0]],"id":69366841},{"atb":[[2.3,0]],"id":40831161}],"con":true,"img":false}]}
{"op":"mcm","clk":"11540640643","pt":1719496781005,"mc":[{"id":"1.230180116","rc":[{"atl":[[6.6,2]],"id":48536142}],"con":true,"img":false}]}
{"op":"mcm","clk":"11540640755","pt":1719496782547,"mc":[{"id":"1.230180116","rc":[{"atl":[[6.4,0.84]],"id":48536142}],"con":true,"img":false}]}
{"op":"mcm","clk":"11540641092","pt":1719496786254,"mc":[{"id":"1.230180116","rc":[{"atl":[[6.6,0]],"id":48536142}],"con":true,"img":false}]}
{"op":"mcm","clk":"11540641123","pt":1719496786559,"mc":[{"id":"1.230180116","rc":[{"atl":[[6.4,0]],"id":48536142}],"con":true,"img":false}]}
{"op":"mcm","clk":"11540641143","pt":1719496786776,"mc":[{"id":"1.230180116","rc":[{"atb":[[4.8,1.76]],"id":64253836},{"atl":[[6,1.41]],"id":48536142}],"con":true,"img":false}]}
{"op":"mcm","clk":"11540641153","pt":1719496786827,"mc":[{"id":"1.230180116","rc":[{"atb":[[2.9,0],[3.15,6]],"id":64253836}],"con":true,"img":false}]}
{"op":"mcm","clk":"11540641171","pt":1719496787026,"mc":[{"id":"1.230180116","rc":[{"atb":[[4.9,0.84]],"id":64253836},{"atl":[[1000,0.84]],"id":64253836},{"atl":[[1000,0.84]],"id":68900945}],"con":true,"img":false}]}
{"op":"mcm","clk":"11540641195","pt":1719496787343,"mc":[{"id":"1.230180116","rc":[{"atb":[[5.1,1.66]],"id":69366841},{"atb":[[4.8,1.76]],"id":68900945}],"con":true,"img":false}]}
{"op":"mcm","clk":"11540641206","pt":1719496787454,"mc":[{"id":"1.230180116","rc":[{"atb":[[3.2,6]],"id":68900945}],"con":true,"img":false}]}
{"op":"mcm","clk":"11540641212","pt":1719496787549,"mc":[{"id":"1.230180116","rc":[{"atb":[[4,9.12],[3.35,3.2]],"id":69366841},{"atb":[[2.9,0]],"id":68900945}],"con":true,"img":false}]}
{"op":"mcm","clk":"11540641221","pt":1719496787653,"mc":[{"id":"1.230180116","rc":[{"atl":[[1000,1.02]],"id":69366841},{"atb":[[5.1,1.66]],"id":40831161}],"con":true,"img":false}]}
{"op":"mcm","clk":"11540641232","pt":1719496787755,"mc":[{"id":"1.230180116","rc":[{"atb":[[5.1,3.66]],"id":40831161}],"con":true,"img":false}]}
{"op":"mcm","clk":"11540641241","pt":1719496787870,"mc":[{"id":"1.230180116","rc":[{"atb":[[4.8,0]],"id":40831161}],"con":true,"img":false}]}
{"op":"mcm","clk":"11540641254","pt":1719496787967,"mc":[{"id":"1.230180116","rc":[{"atl":[[6,0],[6.6,1.41]],"id":48536142}],"con":true,"img":false}]}
{"op":"mcm","clk":"11540641263","pt":1719496788065,"mc":[{"id":"1.230180116","rc":[{"atb":[[5.2,0.84]],"id":40831161},{"atl":[[5.9,2]],"id":48536142},{"atb":[[4.9,0.84]],"id":68900945}],"con":true,"img":false}]}
{"op":"mcm","clk":"11540641278","pt":1719496788223,"mc":[{"id":"1.230180116","rc":[{"atl":[[5.9,3.43]],"id":48536142}],"con":true,"img":false}]}
{"op":"mcm","clk":"11540641287","pt":1719496788342,"mc":[{"id":"1.230180116","rc":[{"atl":[[1000,1.69]],"id":64253836}],"con":true,"img":false}]}
{"op":"mcm","clk":"11540641305","pt":1719496788533,"mc":[{"id":"1.230180116","rc":[{"atl":[[1000,2.54]],"id":64253836}],"con":true,"img":false}]}
{"op":"mcm","clk":"11540641311","pt":1719496788638,"mc":[{"id":"1.230180116","rc":[{"atl":[[1000,2.14]],"id":64253836}],"con":true,"img":false}]}
{"op":"mcm","clk":"11540641333","pt":1719496788844,"mc":[{"id":"1.230180116","rc":[{"atl":[[1000,0.38]],"id":68900945}],"con":true,"img":false}]}
{"op":"mcm","clk":"11540641345","pt":1719496789052,"mc":[{"id":"1.230180116","rc":[{"atl":[[1000,1.74]],"id":64253836}],"con":true,"img":false}]}
{"op":"mcm","clk":"11540641364","pt":1719496789257,"mc":[{"id":"1.230180116","rc":[{"atl":[[1000,1.34]],"id":64253836}],"con":true,"img":false}]}
{"op":"mcm","clk":"11540641370","pt":1719496789368,"mc":[{"id":"1.230180116","rc":[{"atl":[[1000,0.89]],"id":64253836}],"con":true,"img":false}]}
{"op":"mcm","clk":"11540641379","pt":1719496789463,"mc":[{"id":"1.230180116","rc":[{"spn":6.72,"spf":1.0,"id":63031611},{"spn":15.55,"spf":"NaN","id":69366841},{"spn":72.6,"spf":"NaN","id":40831161},{"atl":[[19,0.44]],"id":64253836},{"spn":4.88,"spf":1.0,"id":64253836},{"spn":4.65,"spf":"NaN","id":48536142},{"spn":13.95,"spf":"NaN","id":68900945}],"con":true,"img":false}]}
{"op":"mcm","clk":"11540641387","pt":1719496789566,"mc":[{"id":"1.230180116","rc":[{"atl":[[1000,0.51]],"id":69366841},{"atl":[[5.8,0.84]],"id":48536142}],"con":true,"img":false}]}
{"op":"mcm","clk":"11540641416","pt":1719496789936,"mc":[{"id":"1.230180116","rc":[{"atl":[[1000,0]],"id":68900945}],"con":true,"img":false}]}
{"op":"mcm","clk":"11540641424","pt":1719496790040,"mc":[{"id":"1.230180116","rc":[{"atl":[[22,0.38]],"id":68900945}],"con":true,"img":false}]}
{"op":"mcm","clk":"11540641443","pt":1719496790347,"mc":[{"id":"1.230180116","rc":[{"atl":[[1000,0.44]],"id":64253836}],"con":true,"img":false}]}
{"op":"mcm","clk":"11540641451","pt":1719496790458,"mc":[{"id":"1.230180116","rc":[{"atl":[[19,0.89]],"id":64253836}],"con":true,"img":false}]}
{"op":"mcm","clk":"11540641487","pt":1719496790865,"mc":[{"id":"1.230180116","rc":[{"atl":[[1000,0]],"id":64253836}],"con":true,"img":false}]}
{"op":"mcm","clk":"11540641494","pt":1719496790967,"mc":[{"id":"1.230180116","rc":[{"atl":[[19,1.34]],"id":64253836}],"con":true,"img":false}]}
{"op":"mcm","clk":"11540641502","pt":1719496791021,"mc":[{"id":"1.230180116","rc":[{"atl":[[19,3.34]],"id":64253836}],"con":true,"img":false}]}
{"op":"mcm","clk":"11540641511","pt":1719496791124,"mc":[{"id":"1.230180116","rc":[{"atl":[[20,1.54]],"id":64253836}],"con":true,"img":false}]}
{"op":"mcm","clk":"11540641519","pt":1719496791227,"mc":[{"id":"1.230180116","rc":[{"atl":[[1000,0.17]],"id":69366841},{"atl":[[20,0]],"id":64253836}],"con":true,"img":false}]}
{"op":"mcm","clk":"11540641528","pt":1719496791332,"mc":[{"id":"1.230180116","rc":[{"atl":[[25,0.33]],"id":69366841}],"con":true,"img":false}]}
{"op":"mcm","clk":"11540641544","pt":1719496791540,"mc":[{"id":"1.230180116","rc":[{"atl":[[18.5,0.84]],"id":64253836},{"atl":[[6.2,0]],"id":48536142}],"con":true,"img":false}]}
{"op":"mcm","clk":"11540641573","pt":1719496791851,"mc":[{"id":"1.230180116","rc":[{"atl":[[1000,0.21]],"id":48536142}],"con":true,"img":false}]}
{"op":"mcm","clk":"11540641588","pt":1719496792073,"mc":[{"id":"1.230180116","rc":[{"atl":[[1000,0]],"id":48536142}],"con":true,"img":false}]}
{"op":"mcm","clk":"11540641597","pt":1719496792163,"mc":[{"id":"1.230180116","rc":[{"atl":[[5.8,1.05]],"id":48536142}],"con":true,"img":false}]}
{"op":"mcm","clk":"11540641663","pt":1719496792949,"mc":[{"id":"1.230180116","rc":[{"atb":[[3.2,100]],"id":48536142}],"con":true,"img":false}]}
{"op":"mcm","clk":"11540641697","pt":1719496793256,"mc":[{"id":"1.230180116","rc":[{"atl":[[5.9,1.43]],"id":48536142}],"con":true,"img":false}]}
{"op":"mcm","clk":"11540641732","pt":1719496793825,"mc":[{"id":"1.230180116","rc":[{"atb":[[2.94,0]],"id":64253836},{"atb":[[2.86,0]],"id":48536142},{"atb":[[2.94,0]],"id":68900945}],"con":true,"img":false}]}
{"op":"mcm","clk":"11540641738","pt":1719496794029,"mc":[{"id":"1.230180116","rc":[{"atb":[[2.62,8.63]],"id":48536142}],"con":true,"img":false}]}
{"op":"mcm","clk":"11540641751","pt":1719496794190,"mc":[{"id":"1.230180116","rc":[{"atb":[[2.32,10.58]],"id":69366841},{"atl":[[18.5,2.36]],"id":64253836}],"con":true,"img":false}]}
{"op":"mcm","clk":"11540641760","pt":1719496794345,"mc":[{"id":"1.230180116","rc":[{"atb":[[2.34,10.42]],"id":40831161}],"con":true,"img":false}]}
{"op":"mcm","clk":"11540641767","pt":1719496794445,"mc":[{"id":"1.230180116","rc":[{"atl":[[19,2.89],[1000,0.84]],"id":64253836}],"con":true,"img":false}]}
{"op":"mcm","clk":"11540641788","pt":1719496794754,"mc":[{"id":"1.230180116","rc":[{"atl":[[1000,0.47]],"id":64253836}],"con":true,"img":false}]}
{"op":"mcm","clk":"11540641816","pt":1719496795171,"mc":[{"id":"1.230180116","rc":[{"atl":[[1000,0]],"id":64253836}],"con":true,"img":false}]}
{"op":"mcm","clk":"11540641823","pt":1719496795277,"mc":[{"id":"1.230180116","rc":[{"atl":[[18,0.47]],"id":64253836}],"con":true,"img":false}]}
{"op":"mcm","clk":"11540641870","pt":1719496795843,"mc":[{"id":"1.230180116","rc":[{"atl":[[5.7,2]],"id":48536142}],"con":true,"img":false}]}
{"op":"mcm","clk":"11540641957","pt":1719496797041,"mc":[{"id":"1.230180116","rc":[{"atl":[[5.6,0.84]],"id":48536142}],"con":true,"img":false}]}
{"op":"mcm","clk":"11540642145","pt":1719496799684,"mc":[{"id":"1.230180116","rc":[{"atb":[[1.03,3.4]],"id":48536142},{"atl":[[1000,3.4]],"id":48536142}],"con":true,"img":false}]}
{"op":"mcm","clk":"11540642153","pt":1719496799847,"mc":[{"id":"1.230180116","rc":[{"atb":[[1.03,1.78]],"id":48536142},{"atl":[[1000,1.74]],"id":48536142}],"con":true,"img":false}]}
{"op":"mcm","clk":"11540642160","pt":1719496799946,"mc":[{"id":"1.230180116","rc":[{"atb":[[1.03,0.17],[3.2,0]],"id":48536142},{"atl":[[1000,0.08]],"id":48536142}],"con":true,"img":false}]}
{"op":"mcm","clk":"11540642165","pt":1719496800049,"mc":[{"id":"1.230180116","rc":[{"atb":[[1.03,0.09],[3.1,100]],"id":48536142},{"atl":[[1000,0.04]],"id":48536142}],"con":true,"img":false}]}
{"op":"mcm","clk":"11540642172","pt":1719496800158,"mc":[{"id":"1.230180116","rc":[{"atb":[[1.03,0],[3.25,0.08]],"id":48536142},{"atl":[[1000,0],[5.6,0.89]],"id":48536142}],"con":true,"img":false}]}
{"op":"mcm","clk":"11540642182","pt":1719496800268,"mc":[{"id":"1.230180116","rc":[{"atb":[[3.25,0.17]],"id":48536142},{"atl":[[5.6,0.93]],"id":48536142}],"con":true,"img":false}]}
{"op":"mcm","clk":"11540642264","pt":1719496800955,"mc":[{"id":"1.230180116","rc":[{"atl":[[5.7,0]],"id":48536142}],"con":true,"img":false}]}
{"op":"mcm","clk":"11540642330","pt":1719496801684,"mc":[{"id":"1.230180116","rc":[{"atl":[[5.6,0.08]],"id":48536142}],"con":true,"img":false}]}
{"op":"mcm","clk":"11540642501","pt":1719496803590,"mc":[{"id":"1.230180116","rc":[{"atb":[[2.3,9.11],[3.35,3.2]],"id":69366841},{"atb":[[2.32,8.97]],"id":40831161},{"atb":[[2.6,7.4]],"id":48536142},{"atl":[[5.7,2]],"id":48536142},{"trd":[[3.65,1.99],[3.9,1.99]],"ltp":3.65,"tv":3.98,"id":48536142}],"con":true,"img":false}]}
{"op":"mcm","clk":"11540642540","pt":1719496804055,"mc":[{"id":"1.230180116","rc":[{"atl":[[5.6,0.93]],"id":48536142}],"con":true,"img":false}]}
{"op":"mcm","clk":"11540642703","pt":1719496805671,"mc":[{"id":"1.230180116","rc":[{"atb":[[7.2,0.84],[1.03,10.99],[2.22,8.8],[1.04,75.34]],"id":63031611},{"atl":[[980,1.54]],"id":63031611},{"atb":[[2.32,10.58],[1.03,220.95],[3.35,0],[2.24,9.77],[5.1,1.65]],"id":69366841},{"atl":[[25,0.33],[26,0.97],[990,1.58]],"id":69366841},{"atb":[[5.1,3.65],[1.02,18.49],[5.2,0.84],[2.26,13.46],[2.34,10.42],[1.04,120.21]],"id":40831161},{"atl":[[990,1.53]],"id":40831161},{"atb":[[4.8,1.76],[1.03,156.61],[4.9,0.84],[2.26,12.56]],"id":64253836},{"atl":[[18,0.47],[18.5,2.36],[19,2.89],[19.5,0.84],[960,0.87]],"id":64253836},{"atb":[[1.01,32.98],[2.62,8.62],[2.34,10.56],[1.04,193.87]],"id":48536142},{"atl":[[5.8,1.05],[5.9,1.43],[990,2.1],[5.6,0.93],[6.6,1.41]],"id":48536142},{"atb":[[4.8,1.76],[2.24,10.66],[1.02,18.49],[4.9,0.84],[1.04,119.37]],"id":68900945},{"atl":[[22,0.38],[23,0.84],[980,2.02]],"id":68900945}],"con":true,"img":false}]}
{"op":"mcm","clk":"11540642830","pt":1719496807484,"mc":[{"id":"1.230180116","rc":[{"atl":[[5.8,0.84]],"id":48536142}],"con":true,"img":false}]}
{"op":"mcm","clk":"11540642863","pt":1719496807962,"mc":[{"id":"1.230180116","rc":[{"atl":[[1000,0.22]],"id":48536142}],"con":true,"img":false}]}
{"op":"mcm","clk":"11540642885","pt":1719496808173,"mc":[{"id":"1.230180116","rc":[{"atl":[[1000,0]],"id":48536142}],"con":true,"img":false}]}
{"op":"mcm","clk":"11540642893","pt":1719496808263,"mc":[{"id":"1.230180116","rc":[{"atl":[[5.6,1.15]],"id":48536142}],"con":true,"img":false}]}
{"op":"mcm","clk":"11540642939","pt":1719496808788,"mc":[{"id":"1.230180116","rc":[{"atl":[[5.7,0]],"id":48536142}],"con":true,"img":false}]}
{"op":"mcm","clk":"11540642973","pt":1719496809092,"mc":[{"id":"1.230180116","rc":[{"atl":[[5.6,0.3]],"id":48536142}],"con":true,"img":false}]}
{"op":"mcm","clk":"11540643126","pt":1719496810600,"mc":[{"id":"1.230180116","rc":[{"atl":[[5.7,2]],"id":48536142}],"con":true,"img":false}]}
{"op":"mcm","clk":"11540643181","pt":1719496811166,"mc":[{"id":"1.230180116","rc":[{"atl":[[5.6,1.15]],"id":48536142}],"con":true,"img":false}]}
{"op":"mcm","clk":"11540643279","pt":1719496812371,"mc":[{"id":"1.230180116","rc":[{"atl":[[1000,1.7]],"id":64253836},{"atl":[[1000,1.7]],"id":68900945}],"con":true,"img":false}]}
{"op":"mcm","clk":"11540643288","pt":1719496812477,"mc":[{"id":"1.230180116","rc":[{"atb":[[1.03,158.31]],"id":64253836},{"atb":[[1.03,1.7]],"id":48536142},{"atl":[[1000,1.7]],"id":48536142},{"atb":[[1.03,1.7]],"id":68900945}],"con":true,"img":false}]}
{"op":"mcm","clk":"11540643307","pt":1719496812677,"mc":[{"id":"1.230180116","rc":[{"atl":[[1000,0.01]],"id":64253836},{"atb":[[1.03,0.08]],"id":48536142},{"atl":[[1000,0.03]],"id":48536142},{"atb":[[1.03,0.07]],"id":68900945},{"atl":[[1000,0.01]],"id":68900945}],"con":true,"img":false}]}
{"op":"mcm","clk":"11540643317","pt":1719496812784,"mc":[{"id":"1.230180116","rc":[{"atb":[[1.03,156.68]],"id":64253836}],"con":true,"img":false}]}
{"op":"mcm","clk":"11540643324","pt":1719496812883,"mc":[{"id":"1.230180116","rc":[{"atl":[[1000,0]],"id":64253836},{"atb":[[1.03,0]],"id":48536142},{"atl":[[1000,0]],"id":68900945}],"con":true,"img":false}]}
{"op":"mcm","clk":"11540643330","pt":1719496812986,"mc":[{"id":"1.230180116","rc":[{"atb":[[1.03,156.61]],"id":64253836},{"atl":[[18,0.49]],"id":64253836},{"atb":[[3.15,0.08]],"id":48536142},{"atl":[[1000,0]],"id":48536142},{"atb":[[1.03,0]],"id":68900945},{"atl":[[23,0.86]],"id":68900945}],"con":true,"img":false}]}
{"op":"mcm","clk":"11540643337","pt":1719496813094,"mc":[{"id":"1.230180116","rc":[{"atb":[[4.9,0.92]],"id":64253836},{"atl":[[5.6,1.19]],"id":48536142},{"atb":[[4.9,0.92]],"id":68900945}],"con":true,"img":false}]}
{"op":"mcm","clk":"11540643555","pt":1719496815788,"mc":[{"id":"1.230180116","rc":[{"atl":[[5.7,0]],"id":48536142}],"con":true,"img":false}]}
{"op":"mcm","clk":"11540643581","pt":1719496816100,"mc":[{"id":"1.230180116","rc":[{"atl":[[5.6,0.34]],"id":48536142}],"con":true,"img":false}]}
{"op":"mcm","clk":"11540643591","pt":1719496816196,"mc":[{"id":"1.230180116","rc":[{"atb":[[2.3,0]],"id":69366841},{"atb":[[2.32,0]],"id":40831161}],"con":true,"img":false}]}
{"op":"mcm","clk":"11540643620","pt":1719496816468,"mc":[{"id":"1.230180116","rc":[{"atb":[[2.88,6.3]],"id":64253836}],"con":true,"img":false}]}
{"op":"mcm","clk":"11540643648","pt":1719496816777,"mc":[{"id":"1.230180116","rc":[{"atb":[[2.88,6.3]],"id":68900945}],"con":true,"img":false}]}
{"op":"mcm","clk":"11540643820","pt":1719496818692,"mc":[{"id":"1.230180116","rc":[{"atl":[[5.7,2]],"id":48536142}],"con":true,"img":false}]}
{"op":"mcm","clk":"11540643853","pt":1719496819106,"mc":[{"id":"1.230180116","rc":[{"atl":[[5.6,1.19]],"id":48536142}],"con":true,"img":false}]}
{"op":"mcm","clk":"11540643901","pt":1719496819582,"mc":[{"id":"1.230180116","rc":[{"atl":[[5.7,0]],"id":48536142}],"con":true,"img":false}]}
{"op":"mcm","clk":"11540643940","pt":1719496820096,"mc":[{"id":"1.230180116","rc":[{"atl":[[5.6,0.34]],"id":48536142}],"con":true,"img":false}]}
{"op":"mcm","clk":"11540644214","pt":1719496823467,"mc":[{"id":"1.230180116","rc":[{"atl":[[5.6,0.12]],"id":48536142}],"con":true,"img":false}]}
{"op":"mcm","clk":"11540644233","pt":1719496823779,"mc":[{"id":"1.230180116","rc":[{"atl":[[1000,0.21]],"id":48536142}],"con":true,"img":false}]}
{"op":"mcm","clk":"11540644252","pt":1719496823987,"mc":[{"id":"1.230180116","rc":[{"atl":[[1000,0]],"id":48536142}],"con":true,"img":false}]}
{"op":"mcm","clk":"11540644259","pt":1719496824093,"mc":[{"id":"1.230180116","rc":[{"atl":[[5.7,0.21]],"id":48536142}],"con":true,"img":false}]}
{"op":"mcm","clk":"11540644405","pt":1719496825818,"mc":[{"id":"1.230180116","rc":[{"atl":[[5.7,2.21]],"id":48536142}],"con":true,"img":false}]}
{"op":"mcm","clk":"11540644465","pt":1719496826585,"mc":[{"id":"1.230180116","rc":[{"atl":[[5.6,0.97]],"id":48536142}],"con":true,"img":false}]}
{"op":"mcm","clk":"11540644813","pt":1719496831094,"mc":[{"id":"1.230180116","rc":[{"atl":[[5.7,0.21]],"id":48536142}],"con":true,"img":false}]}
{"op":"mcm","clk":"11540644865","pt":1719496831834,"mc":[{"id":"1.230180116","rc":[{"atl":[[5.6,0.12]],"id":48536142}],"con":true,"img":false}]}
{"op":"mcm","clk":"11540644965","pt":1719496832911,"mc":[{"id":"1.230180116","rc":[{"atl":[[5.7,2.21]],"id":48536142}],"con":true,"img":false}]}
{"op":"mcm","clk":"11540645029","pt":1719496833595,"mc":[{"id":"1.230180116","rc":[{"atl":[[5.6,0.97]],"id":48536142}],"con":true,"img":false}]}
{"op":"mcm","clk":"11540645184","pt":1719496835193,"mc":[{"id":"1.230180116","rc":[{"atb":[[2.36,8.71]],"id":40831161}],"con":true,"img":false}]}
{"op":"mcm","clk":"11540645192","pt":1719496835301,"mc":[{"id":"1.230180116","rc":[{"atb":[[2.34,8.83]],"id":69366841}],"con":true,"img":false}]}
{"op":"mcm","clk":"11540645419","pt":1719496838087,"mc":[{"id":"1.230180116","rc":[{"atl":[[5.7,0.21]],"id":48536142}],"con":true,"img":false}]}
{"op":"mcm","clk":"11540645460","pt":1719496838603,"mc":[{"id":"1.230180116","rc":[{"atl":[[5.6,0.12]],"id":48536142}],"con":true,"img":false}]}
{"op":"mcm","clk":"11540645518","pt":1719496839425,"mc":[{"id":"1.230180116","rc":[{"atl":[[5.7,0]],"id":48536142}],"con":true,"img":false}]}
{"op":"mcm","clk":"11540645532","pt":1719496839578,"mc":[{"id":"1.230180116","rc":[{"atl":[[1000,0.21]],"id":48536142}],"con":true,"img":false}]}
{"op":"mcm","clk":"11540645551","pt":1719496839798,"mc":[{"id":"1.230180116","rc":[{"atl":[[1000,0]],"id":48536142}],"con":true,"img":false}]}
{"op":"mcm","clk":"11540645560","pt":1719496839894,"mc":[{"id":"1.230180116","rc":[{"atl":[[5.7,0.21]],"id":48536142}],"con":true,"img":false}]}
{"op":"mcm","clk":"11540645623","pt":1719496840722,"mc":[{"id":"1.230180116","rc":[{"atl":[[5.7,2.21]],"id":48536142}],"con":true,"img":false}]}
{"op":"mcm","clk":"11540645649","pt":1719496841034,"mc":[{"id":"1.230180116","rc":[{"atl":[[5.6,0.97]],"id":48536142}],"con":true,"img":false}]}
{"op":"mcm","clk":"11540646083","pt":1719496845919,"mc":[{"id":"1.230180116","rc":[{"atl":[[5.7,0.21]],"id":48536142}],"con":true,"img":false}]}
{"op":"mcm","clk":"11540646131","pt":1719496846543,"mc":[{"id":"1.230180116","rc":[{"atl":[[5.6,0.12]],"id":48536142}],"con":true,"img":false}]}
{"op":"mcm","clk":"11540646160","pt":1719496846804,"mc":[{"id":"1.230180116","rc":[{"atl":[[5.5,1.54],[5.7,1.69]],"id":48536142}],"con":true,"img":false}]}
{"op":"mcm","clk":"11540646195","pt":1719496847215,"mc":[{"id":"1.230180116","rc":[{"atl":[[5.9,0]],"id":48536142}],"con":true,"img":false}]}
{"op":"mcm","clk":"11540646227","pt":1719496847630,"mc":[{"id":"1.230180116","rc":[{"atl":[[5.5,0],[6.6,0]],"id":48536142}],"con":true,"img":false}]}
{"op":"mcm","clk":"11540646235","pt":1719496847745,"mc":[{"id":"1.230180116","rc":[{"atl":[[5.4,2]],"id":48536142}],"con":true,"img":false}]}
{"op":"mcm","clk":"11540646247","pt":1719496847832,"mc":[{"id":"1.230180116","rc":[{"atl":[[5.6,1.66]],"id":48536142}],"con":true,"img":false}]}
{"op":"mcm","clk":"11540646264","pt":1719496847992,"mc":[{"id":"1.230180116","rc":[{"atl":[[5.8,0],[5.3,2.44]],"id":48536142}],"con":true,"img":false}]}
{"op":"mcm","clk":"11540646289","pt":1719496848303,"mc":[{"id":"1.230180116","rc":[{"atl":[[5.7,0.21]],"id":48536142}],"con":true,"img":false}]}
{"op":"mcm","clk":"11540646300","pt":1719496848511,"mc":[{"id":"1.230180116","rc":[{"atb":[[4.9,0.84]],"id":64253836},{"atl":[[18,0.47]],"id":64253836},{"atb":[[3.25,0],[3.15,0]],"id":48536142},{"atl":[[5.6,1.54]],"id":48536142},{"atb":[[4.9,0.84]],"id":68900945},{"atl":[[23,0.84]],"id":68900945}],"con":true,"img":false}]}
{"op":"mcm","clk":"11540646308","pt":1719496848614,"mc":[{"id":"1.230180116","rc":[{"atl":[[5.4,0]],"id":48536142}],"con":true,"img":false}]}
{"op":"mcm","clk":"11540646624","pt":1719496852429,"mc":[{"id":"1.230180116","rc":[{"spn":6.72,"spf":1.0,"id":63031611},{"atl":[[25,1.18]],"id":69366841},{"spn":15.05,"spf":"NaN","id":69366841},{"atl":[[130,0.84]],"id":40831161},{"spn":67.6,"spf":"NaN","id":40831161},{"spn":4.35,"spf":"NaN","id":48536142},{"spn":13.45,"spf":"NaN","id":68900945}],"con":true,"img":false}]}
{"op":"mcm","clk":"11540646640","pt":1719496852529,"mc":[{"id":"1.230180116","rc":[{"atl":[[19.5,0]],"id":64253836}],"con":true,"img":false}]}
{"op":"mcm","clk":"11540646651","pt":1719496852632,"mc":[{"id":"1.230180116","rc":[{"atl":[[25,3.18],[27,0]],"id":69366841}],"con":true,"img":false}]}
{"op":"mcm","clk":"11540646693","pt":1719496853045,"mc":[{"id":"1.230180116","rc":[{"atl":[[24,0.84],[26,0]],"id":69366841}],"con":true,"img":false}]}
{"op":"mcm","clk":"11540646712","pt":1719496853209,"mc":[{"id":"1.230180116","rc":[{"atb":[[2.32,0]],"id":69366841},{"atb":[[2.34,0]],"id":40831161}],"con":true,"img":false}]}
{"op":"mcm","clk":"11540646835","pt":1719496854716,"mc":[{"id":"1.230180116","rc":[{"atl":[[5.2,2]],"id":48536142}],"con":true,"img":false}]}
{"op":"mcm","clk":"11540646875","pt":1719496855126,"mc":[{"id":"1.230180116","rc":[{"atl":[[5.7,0]],"id":48536142}],"con":true,"img":false}]}
{"op":"mcm","clk":"11540646909","pt":1719496855540,"mc":[{"id":"1.230180116","rc":[{"atl":[[5.1,0.84]],"id":48536142}],"con":true,"img":false}]}
{"op":"mcm","clk":"11540647159","pt":1719496858411,"mc":[{"id":"1.230180116","rc":[{"atb":[[4,12.43]],"id":69366841},{"atb":[[4.9,1.67]],"id":64253836},{"atb":[[4.9,1.67]],"id":68900945}],"con":true,"img":false}]}
{"op":"mcm","clk":"11540647290","pt":1719496859904,"mc":[{"id":"1.230180116","rc":[{"atl":[[5.2,0]],"id":48536142}],"con":true,"img":false}]}
{"op":"mcm","clk":"11540647365","pt":1719496860632,"mc":[{"id":"1.230180116","rc":[{"atl":[[5.1,0]],"id":48536142}],"con":true,"img":false}]}
{"op":"mcm","clk":"11540647428","pt":1719496861313,"mc":[{"id":"1.230180116","rc":[{"atb":[[1.01,33.98]],"id":48536142}],"con":true,"img":false}]}
{"op":"mcm","clk":"11540647472","pt":1719496861932,"mc":[{"id":"1.230180116","rc":[{"atb":[[3.85,1]],"id":63031611},{"atb":[[4.1,1]],"id":69366841},{"atb":[[2.38,1]],"id":40831161},{"atl":[[24,1]],"id":64253836},{"atb":[[2.98,0]],"id":48536142},{"atl":[[5.1,1]],"id":48536142}],"con":true,"img":false}]}
{"op":"mcm","clk":"11540647526","pt":1719496862505,"mc":[{"id":"1.230180116","rc":[{"atl":[[5,2]],"id":48536142}],"con":true,"img":false}]}
{"op":"mcm","clk":"11540647579","pt":1719496863129,"mc":[{"id":"1.230180116","rc":[{"atl":[[5.3,1.6],[4.9,0.84]],"id":48536142}],"con":true,"img":false}]}
{"op":"mcm","clk":"11540648005","pt":1719496867762,"mc":[{"id":"1.230180116","rc":[{"atl":[[5,0]],"id":48536142}],"con":true,"img":false}]}
{"op":"mcm","clk":"11540648034","pt":1719496868021,"mc":[{"id":"1.230180116","rc":[{"atl":[[4.9,0]],"id":48536142}],"con":true,"img":false}]}
{"op":"mcm","clk":"11540648181","pt":1719496869522,"mc":[{"id":"1.230180116","rc":[{"atl":[[5,2]],"id":48536142}],"con":true,"img":false}]}
{"op":"mcm","clk":"11540648232","pt":1719496870241,"mc":[{"id":"1.230180116","rc":[{"atb":[[2.9,7.34]],"id":64253836}],"con":true,"img":false}]}
{"op":"mcm","clk":"11540648250","pt":1719496870530,"mc":[{"id":"1.230180116","rc":[{"atl":[[4.9,0.84]],"id":48536142}],"con":true,"img":false}]}
{"op":"mcm","clk":"11540648269","pt":1719496870738,"mc":[{"id":"1.230180116","rc":[{"atb":[[2.9,7.34]],"id":68900945}],"con":true,"img":false}]}
{"op":"mcm","clk":"11540648578","pt":1719496874836,"mc":[{"id":"1.230180116","rc":[{"atl":[[5,0]],"id":48536142}],"con":true,"img":false}]}
{"op":"mcm","clk":"11540648606","pt":1719496875150,"mc":[{"id":"1.230180116","rc":[{"atl":[[4.9,0]],"id":48536142}],"con":true,"img":false}]}
{"op":"mcm","clk":"11540648692","pt":1719496876344,"mc":[{"id":"1.230180116","rc":[{"atb":[[3.1,0]],"id":48536142}],"con":true,"img":false}]}
{"op":"mcm","clk":"11540648703","pt":1719496876445,"mc":[{"id":"1.230180116","rc":[{"atb":[[3.4,101],[2.64,7.55],[2.84,0]],"id":48536142}],"con":true,"img":false}]}
{"op":"mcm","clk":"11540648708","pt":1719496876550,"mc":[{"id":"1.230180116","rc":[{"atb":[[2.64,0],[2.84,54.35]],"id":48536142},{"atl":[[5,2]],"id":48536142}],"con":true,"img":false}]}
{"op":"mcm","clk":"11540648755","pt":1719496877019,"mc":[{"id":"1.230180116","rc":[{"atb":[[3.45,0.84]],"id":48536142}],"con":true,"img":false}]}
{"op":"mcm","clk":"11540648861","pt":1719496878051,"mc":[{"id":"1.230180116","rc":[{"atl":[[4.9,0.84]],"id":48536142}],"con":true,"img":false}]}
{"op":"mcm","clk":"11540648960","pt":1719496879240,"mc":[{"id":"1.230180116","rc":[{"atb":[[3.4,100]],"id":48536142}],"con":true,"img":false}]}
{"op":"mcm","clk":"11540648965","pt":1719496879344,"mc":[{"id":"1.230180116","rc":[{"atb":[[4,9.12]],"id":69366841}],"con":true,"img":false}]}
{"op":"mcm","clk":"11540649158","pt":1719496881831,"mc":[{"id":"1.230180116","rc":[{"atl":[[5,0]],"id":48536142}],"con":true,"img":false}]}
{"op":"mcm","clk":"11540649227","pt":1719496882651,"mc":[{"id":"1.230180116","rc":[{"atl":[[4.9,0]],"id":48536142}],"con":true,"img":false}]}
{"op":"mcm","clk":"11540649358","pt":1719496884368,"mc":[{"id":"1.230180116","rc":[{"atb":[[1.25,20]],"id":63031611},{"atb":[[1.25,20]],"id":69366841},{"atb":[[1.25,20]],"id":40831161},{"atb":[[1.25,20]],"id":64253836},{"atb":[[1.25,20]],"id":48536142},{"atb":[[1.25,20]],"id":68900945}],"con":true,"img":false}]}
{"op":"mcm","clk":"11540649368","pt":1719496884466,"mc":[{"id":"1.230180116","rc":[{"atl":[[5,2]],"id":48536142}],"con":true,"img":false}]}
{"op":"mcm","clk":"11540649438","pt":1719496885551,"mc":[{"id":"1.230180116","rc":[{"atl":[[4.9,0.84]],"id":48536142}],"con":true,"img":false}]}
{"op":"mcm","clk":"11540649741","pt":1719496889731,"mc":[{"id":"1.230180116","rc":[{"atl":[[5,0]],"id":48536142}],"con":true,"img":false}]}
{"op":"mcm","clk":"11540649765","pt":1719496890143,"mc":[{"id":"1.230180116","rc":[{"atl":[[4.9,0]],"id":48536142}],"con":true,"img":false}]}
{"op":"mcm","clk":"11540649852","pt":1719496891560,"mc":[{"id":"1.230180116","rc":[{"atl":[[80,1]],"id":63031611},{"atl":[[24,1.84]],"id":69366841},{"atl":[[130,1.84]],"id":40831161},{"atl":[[18,1.47]],"id":64253836},{"atl":[[4.9,1],[5,2]],"id":48536142},{"atl":[[23,1.84]],"id":68900945}],"con":true,"img":false}]}
{"op":"mcm","clk":"11540649863","pt":1719496891660,"mc":[{"id":"1.230180116","rc":[{"atl":[[18,3.84],[19,0.89]],"id":64253836}],"con":true,"img":false}]}
{"op":"mcm","clk":"11540649873","pt":1719496891763,"mc":[{"id":"1.230180116","rc":[{"atl":[[18,1.47],[18.5,5.3],[24,0]],"id":64253836}],"con":true,"img":false}]}
{"op":"mcm","clk":"11540649878","pt":1719496891868,"mc":[{"id":"1.230180116","rc":[{"atl":[[22,1.53]],"id":68900945}],"con":true,"img":false}]}
{"op":"mcm","clk":"11540649887","pt":1719496891971,"mc":[{"id":"1.230180116","rc":[{"atl":[[20,1]],"id":64253836},{"atl":[[22,3.53],[24,1.74]],"id":68900945}],"con":true,"img":false}]}
{"op":"mcm","clk":"11540649892","pt":1719496892074,"mc":[{"id":"1.230180116","rc":[{"atl":[[22,2.37],[23,5.58]],"id":68900945}],"con":true,"img":false}]}
{"op":"mcm","clk":"11540649919","pt":1719496892542,"mc":[{"id":"1.230180116","rc":[{"atl":[[5,0]],"id":48536142}],"con":true,"img":false}]}
{"op":"mcm","clk":"11540649926","pt":1719496892645,"mc":[{"id":"1.230180116","rc":[{"atl":[[23,4.58]],"id":68900945}],"con":true,"img":false}]}
{"op":"mcm","clk":"11540649932","pt":1719496892749,"mc":[{"id":"1.230180116","rc":[{"atl":[[21,1]],"id":68900945}],"con":true,"img":false}]}
{"op":"mcm","clk":"11540649943","pt":1719496892967,"mc":[{"id":"1.230180116","rc":[{"atl":[[22,1.22]],"id":68900945}],"con":true,"img":false}]}
{"op":"mcm","clk":"11540649987","pt":1719496893576,"mc":[{"id":"1.230180116","rc":[{"atl":[[4.9,0]],"id":48536142},{"atl":[[21,0]],"id":68900945}],"con":true,"img":false}]}
{"op":"mcm","clk":"11540649999","pt":1719496893679,"mc":[{"id":"1.230180116","rc":[{"atl":[[5.2,1]],"id":48536142},{"atl":[[22,2.22]],"id":68900945}],"con":true,"img":false}]}
{"op":"mcm","clk":"11540650035","pt":1719496894147,"mc":[{"id":"1.230180116","rc":[{"atl":[[21,1.21]],"id":68900945}],"con":true,"img":false}]}
{"op":"mcm","clk":"11540650344","pt":1719496898536,"mc":[{"id":"1.230180116","rc":[{"atl":[[5,2]],"id":48536142}],"con":true,"img":false}]}
{"op":"mcm","clk":"11540650357","pt":1719496898843,"mc":[{"id":"1.230180116","rc":[{"atl":[[21,3.44],[23,0.84]],"id":68900945}],"con":true,"img":false}]}
{"op":"mcm","clk":"11540650361","pt":1719496898946,"mc":[{"id":"1.230180116","rc":[{"atl":[[21,1.21],[22,4.64]],"id":68900945}],"con":true,"img":false}]}
{"op":"mcm","clk":"11540650366","pt":1719496899048,"mc":[{"id":"1.230180116","rc":[{"atl":[[4.9,0.84]],"id":48536142}],"con":true,"img":false}]}
{"op":"mcm","clk":"11540650549","pt":1719496901892,"mc":[{"id":"1.230180116","rc":[{"atb":[[3.4,0]],"id":48536142}],"con":true,"img":false}]}
{"op":"mcm","clk":"11540650562","pt":1719496901950,"mc":[{"id":"1.230180116","rc":[{"atb":[[2.64,55.2],[2.84,0]],"id":48536142}],"con":true,"img":false}]}
{"op":"mcm","clk":"11540650578","pt":1719496902257,"mc":[{"id":"1.230180116","rc":[{"atb":[[2.66,6.34]],"id":48536142}],"con":true,"img":false}]}
{"op":"mcm","clk":"11540650597","pt":1719496902567,"mc":[{"id":"1.230180116","rc":[{"atb":[[3.45,0],[2.68,0.84]],"id":48536142},{"atl":[[5.2,0]],"id":48536142},{"atl":[[22,3.64]],"id":68900945}],"con":true,"img":false}]}
{"op":"mcm","clk":"11540650602","pt":1719496902679,"mc":[{"id":"1.230180116","rc":[{"atb":[[2.64,0],[2.68,7.19],[1.04,194.87]],"id":48536142},{"atl":[[4.9,1.84]],"id":48536142},{"atl":[[23,1.84]],"id":68900945}],"con":true,"img":false}]}
{"op":"mcm","clk":"11540650616","pt":1719496902875,"mc":[{"id":"1.230180116","rc":[{"atb":[[1.04,194.47]],"id":48536142}],"con":true,"img":false}]}
{"op":"mcm","clk":"11540650622","pt":1719496902978,"mc":[{"id":"1.230180116","rc":[{"atb":[[2.66,0]],"id":48536142}],"con":true,"img":false}]}
{"op":"mcm","clk":"11540650629","pt":1719496903094,"mc":[{"id":"1.230180116","rc":[{"atb":[[1.04,193.87]],"id":48536142},{"atl":[[23,0.84]],"id":68900945}],"con":true,"img":false}]}
{"op":"mcm","clk":"11540650637","pt":1719496903184,"mc":[{"id":"1.230180116","rc":[{"atb":[[2.68,7.79]],"id":48536142},{"atl":[[21,2.21]],"id":68900945}],"con":true,"img":false}]}
{"op":"mcm","clk":"11540650644","pt":1719496903287,"mc":[{"id":"1.230180116","rc":[{"atl":[[1000,0.78]],"id":48536142}],"con":true,"img":false}]}
{"op":"mcm","clk":"11540650666","pt":1719496903545,"mc":[{"id":"1.230180116","rc":[{"atl":[[20,0.84]],"id":68900945}],"con":true,"img":false}]}
{"op":"mcm","clk":"11540650676","pt":1719496903757,"mc":[{"id":"1.230180116","rc":[{"atl":[[5,0]],"id":48536142}],"con":true,"img":false}]}
{"op":"mcm","clk":"11540650720","pt":1719496904267,"mc":[{"id":"1.230180116","rc":[{"atb":[[2.34,0]],"id":69366841},{"atb":[[2.36,0]],"id":40831161},{"atb":[[2.88,0]],"id":64253836},{"atb":[[3.4,1]],"id":48536142},{"atb":[[2.88,0]],"id":68900945}],"con":true,"img":false}]}
{"op":"mcm","clk":"11540650729","pt":1719496904371,"mc":[{"id":"1.230180116","rc":[{"atb":[[3.4,0]],"id":48536142},{"trd":[[3.4,2]],"ltp":3.4,"tv":2.0,"id":48536142}],"con":true,"img":false}]}
{"op":"mcm","clk":"11540650766","pt":1719496904887,"mc":[{"id":"1.230180116","rc":[{"atl":[[4.9,0.84]],"id":48536142}],"con":true,"img":false}]}
{"op":"mcm","clk":"11540650772","pt":1719496904944,"mc":[{"id":"1.230180116","rc":[{"atl":[[5.2,1]],"id":48536142}],"con":true,"img":false}]}
{"op":"mcm","clk":"11540650813","pt":1719496905662,"mc":[{"id":"1.230180116","rc":[{"atl":[[4.9,0]],"id":48536142}],"con":true,"img":false}]}
{"op":"mcm","clk":"11540650837","pt":1719496905975,"mc":[{"id":"1.230180116","rc":[{"atl":[[24,0]],"id":68900945}],"con":true,"img":false}]}
{"op":"mcm","clk":"11540650875","pt":1719496906401,"mc":[{"id":"1.230180116","rc":[{"atl":[[5,2]],"id":48536142}],"con":true,"img":false}]}
{"op":"mcm","clk":"11540650911","pt":1719496906850,"mc":[{"id":"1.230180116","rc":[{"atl":[[5.2,0]],"id":48536142}],"con":true,"img":false}]}
{"op":"mcm","clk":"11540650920","pt":1719496906952,"mc":[{"id":"1.230180116","rc":[{"atl":[[4.9,1],[5,3.69]],"id":48536142}],"con":true,"img":false}]}
{"op":"mcm","clk":"11540650928","pt":1719496907058,"mc":[{"id":"1.230180116","rc":[{"atl":[[5.3,0],[4.9,1.84]],"id":48536142}],"con":true,"img":false}]}
{"op":"mcm","clk":"11540650933","pt":1719496907176,"mc":[{"id":"1.230180116","rc":[{"atl":[[1000,1.02]],"id":69366841},{"atl":[[5.1,0]],"id":48536142}],"con":true,"img":false}]}
{"op":"mcm","clk":"11540650952","pt":1719496907363,"mc":[{"id":"1.230180116","rc":[{"atl":[[25,2.84]],"id":69366841},{"atl":[[4.8,2.76],[5,1.69]],"id":48536142}],"con":true,"img":false}]}
{"op":"mcm","clk":"11540650976","pt":1719496907671,"mc":[{"id":"1.230180116","rc":[{"atl":[[1000,0.54]],"id":69366841},{"atl":[[5,0]],"id":48536142}],"con":true,"img":false}]}
{"op":"mcm","clk":"11540650990","pt":1719496907888,"mc":[{"id":"1.230180116","rc":[{"atl":[[4.9,0.84]],"id":48536142}],"con":true,"img":false}]}
{"op":"mcm","clk":"11540650998","pt":1719496907980,"mc":[{"id":"1.230180116","rc":[{"atl":[[1000,0.17]],"id":69366841},{"atl":[[4.7,1]],"id":48536142}],"con":true,"img":false}]}
{"op":"mcm","clk":"11540651006","pt":1719496908082,"mc":[{"id":"1.230180116","rc":[{"atl":[[23,0.36]],"id":69366841}],"con":true,"img":false}]}
{"op":"mcm","clk":"11540651070","pt":1719496908966,"mc":[{"id":"1.230180116","rc":[{"atb":[[1.02,3.7]],"id":48536142},{"atl":[[1000,2.49]],"id":48536142}],"con":true,"img":false}]}
{"op":"mcm","clk":"11540651093","pt":1719496909269,"mc":[{"id":"1.230180116","rc":[{"atb":[[1.02,2.17]],"id":48536142},{"atl":[[1000,0.86]],"id":48536142}],"con":true,"img":false}]}
{"op":"mcm","clk":"11540651099","pt":1719496909371,"mc":[{"id":"1.230180116","rc":[{"atb":[[3.15,1.02]],"id":48536142}],"con":true,"img":false}]}
{"op":"mcm","clk":"11540651107","pt":1719496909476,"mc":[{"id":"1.230180116","rc":[{"atb":[[2.84,7.8],[1.02,2],[2.68,1.44]],"id":48536142},{"atl":[[1000,0.78]],"id":48536142}],"con":true,"img":false}]}
{"op":"mcm","clk":"11540651113","pt":1719496909586,"mc":[{"id":"1.230180116","rc":[{"atb":[[2.7,0.17]],"id":48536142},{"atl":[[4.7,1.07]],"id":48536142}],"con":true,"img":false}]}
{"op":"mcm","clk":"11540651140","pt":1719496909997,"mc":[{"id":"1.230180116","rc":[{"atb":[[2.26,9.39]],"id":69366841}],"con":true,"img":false}]}
{"op":"mcm","clk":"11540651148","pt":1719496910098,"mc":[{"id":"1.230180116","rc":[{"atb":[[2.92,6.16]],"id":64253836}],"con":true,"img":false}]}
{"op":"mcm","clk":"11540651162","pt":1719496910257,"mc":[{"id":"1.230180116","rc":[{"atb":[[2.68,0.6]],"id":48536142},{"atb":[[2.92,6.16]],"id":68900945}],"con":true,"img":false}]}
{"op":"mcm","clk":"11540651180","pt":1719496910466,"mc":[{"id":"1.230180116","rc":[{"atb":[[2.28,9.25]],"id":40831161}],"con":true,"img":false}]}
{"op":"mcm","clk":"11540651289","pt":1719496911864,"mc":[{"id":"1.230180116","rc":[{"atl":[[20,2.53]],"id":68900945}],"con":true,"img":false}]}
{"op":"mcm","clk":"11540651308","pt":1719496912068,"mc":[{"id":"1.230180116","rc":[{"atl":[[20,5.07],[22,1.22]],"id":68900945}],"con":true,"img":false}]}
{"op":"mcm","clk":"11540651315","pt":1719496912172,"mc":[{"id":"1.230180116","rc":[{"atl":[[20,2.53],[21,6]],"id":68900945}],"con":true,"img":false}]}
{"op":"mcm","clk":"11540651331","pt":1719496912377,"mc":[{"id":"1.230180116","rc":[{"atl":[[19.5,1.3]],"id":68900945}],"con":true,"img":false}]}
{"op":"mcm","clk":"11540651339","pt":1719496912487,"mc":[{"id":"1.230180116","rc":[{"spn":14.05,"spf":"NaN","id":69366841},{"spn":4.9,"spf":1.0,"id":64253836},{"spn":3.92,"spf":"NaN","id":48536142},{"atl":[[19.5,3.84],[21,1]],"id":68900945},{"spn":12.2,"spf":"NaN","id":68900945}],"con":true,"img":false}]}
{"op":"mcm","clk":"11540651344","pt":1719496912589,"mc":[{"id":"1.230180116","rc":[{"atl":[[22,0.38]],"id":68900945}],"con":true,"img":false}]}
{"op":"mcm","clk":"11540651372","pt":1719496912899,"mc":[{"id":"1.230180116","rc":[{"atl":[[21,0]],"id":68900945}],"con":true,"img":false}]}
{"op":"mcm","clk":"11540651383","pt":1719496912997,"mc":[{"id":"1.230180116","rc":[{"atl":[[19,1]],"id":68900945}],"con":true,"img":false}]}
{"op":"mcm","clk":"11540651393","pt":1719496913057,"mc":[{"id":"1.230180116","rc":[{"atl":[[19,1.84]],"id":68900945}],"con":true,"img":false}]}
{"op":"mcm","clk":"11540651419","pt":1719496913365,"mc":[{"id":"1.230180116","rc":[{"atl":[[19.5,2.54]],"id":68900945}],"con":true,"img":false}]}
{"op":"mcm","clk":"11540651427","pt":1719496913465,"mc":[{"id":"1.230180116","rc":[{"atl":[[4.6,2]],"id":48536142}],"con":true,"img":false}]}
{"op":"mcm","clk":"11540651440","pt":1719496913668,"mc":[{"id":"1.230180116","rc":[{"atl":[[20,1.69]],"id":68900945}],"con":true,"img":false}]}
{"op":"mcm","clk":"11540651448","pt":1719496913776,"mc":[{"id":"1.230180116","rc":[{"atl":[[4.8,1.76]],"id":48536142}],"con":true,"img":false}]}
{"op":"mcm","clk":"11540651476","pt":1719496914189,"mc":[{"id":"1.230180116","rc":[{"atl":[[4.9,0],[4.5,0.84]],"id":48536142}],"con":true,"img":false}]}
{"op":"mcm","clk":"11540651482","pt":1719496914287,"mc":[{"id":"1.230180116","rc":[{"atl":[[4.5,1.84]],"id":48536142}],"con":true,"img":false}]}
{"op":"mcm","clk":"11540651502","pt":1719496914494,"mc":[{"id":"1.230180116","rc":[{"atl":[[4.7,0.07]],"id":48536142}],"con":true,"img":false}]}
{"op":"mcm","clk":"11540651510","pt":1719496914595,"mc":[{"id":"1.230180116","rc":[{"atl":[[4.5,2.84]],"id":48536142}],"con":true,"img":false}]}
{"op":"mcm","clk":"11540651534","pt":1719496914964,"mc":[{"id":"1.230180116","rc":[{"atl":[[20,0]],"id":68900945}],"con":true,"img":false}]}
{"op":"mcm","clk":"11540651749","pt":1719496917908,"mc":[{"id":"1.230180116","rc":[{"atl":[[18.5,1.64]],"id":68900945}],"con":true,"img":false}]}
{"op":"mcm","clk":"11540651794","pt":1719496918475,"mc":[{"id":"1.230180116","rc":[{"atb":[[2.68,0]],"id":48536142}],"con":true,"img":false}]}
{"op":"mcm","clk":"11540651812","pt":1719496918678,"mc":[{"id":"1.230180116","rc":[{"atl":[[4.6,0]],"id":48536142}],"con":true,"img":false}]}
{"op":"mcm","clk":"11540651842","pt":1719496919088,"mc":[{"id":"1.230180116","rc":[{"atl":[[18.5,3.64],[19.5,0]],"id":68900945}],"con":true,"img":false}]}
{"op":"mcm","clk":"11540651914","pt":1719496920068,"mc":[{"id":"1.230180116","rc":[{"atl":[[18,0.84]],"id":68900945}],"con":true,"img":false}]}
{"op":"mcm","clk":"11540651925","pt":1719496920275,"mc":[{"id":"1.230180116","rc":[{"atb":[[2.86,14.01]],"id":48536142},{"atl":[[4.5,9.16]],"id":48536142}],"con":true,"img":false}]}
{"op":"mcm","clk":"11540651939","pt":1719496920485,"mc":[{"id":"1.230180116","rc":[{"atl":[[4.4,2],[4.5,8.16]],"id":48536142}],"con":true,"img":false}]}
{"op":"mcm","clk":"11540652002","pt":1719496921373,"mc":[{"id":"1.230180116","rc":[{"atl":[[4.4,8.58]],"id":48536142}],"con":true,"img":false}]}
{"op":"mcm","clk":"11540652013","pt":1719496921475,"mc":[{"id":"1.230180116","rc":[{"atb":[[2.24,13.09]],"id":69366841},{"atb":[[2.26,17.89]],"id":40831161},{"atl":[[4.4,9.58]],"id":48536142}],"con":true,"img":false}]}
{"op":"mcm","clk":"11540652023","pt":1719496921575,"mc":[{"id":"1.230180116","rc":[{"atl":[[4.3,0.84]],"id":48536142}],"con":true,"img":false}]}
{"op":"mcm","clk":"11540652042","pt":1719496921778,"mc":[{"id":"1.230180116","rc":[{"atb":[[2.6,0]],"id":48536142},{"atl":[[4.4,8.58]],"id":48536142}],"con":true,"img":false}]}
{"op":"mcm","clk":"11540652060","pt":1719496921985,"mc":[{"id":"1.230180116","rc":[{"atl":[[4.3,1.84]],"id":48536142}],"con":true,"img":false}]}
{"op":"mcm","clk":"11540652102","pt":1719496922603,"mc":[{"id":"1.230180116","rc":[{"atl":[[4.5,6.32]],"id":48536142},{"atl":[[19,0.84]],"id":68900945}],"con":true,"img":false}]}
{"op":"mcm","clk":"11540652111","pt":1719496922708,"mc":[{"id":"1.230180116","rc":[{"atl":[[4.3,9.34],[4.7,1.07]],"id":48536142},{"atl":[[18,1.84]],"id":68900945}],"con":true,"img":false}]}
{"op":"mcm","clk":"11540652139","pt":1719496923180,"mc":[{"id":"1.230180116","rc":[{"atl":[[4.7,0.07]],"id":48536142},{"atl":[[19,0]],"id":68900945}],"con":true,"img":false}]}
{"op":"mcm","clk":"11540652147","pt":1719496923275,"mc":[{"id":"1.230180116","rc":[{"atl":[[4.2,1]],"id":48536142}],"con":true,"img":false}]}
{"op":"mcm","clk":"11540652181","pt":1719496923791,"mc":[{"id":"1.230180116","rc":[{"atl":[[4.4,6.58]],"id":48536142}],"con":true,"img":false}]}
{"op":"mcm","clk":"11540652188","pt":1719496923895,"mc":[{"id":"1.230180116","rc":[{"atb":[[2.26,17.39]],"id":40831161}],"con":true,"img":false}]}
{"op":"mcm","clk":"11540652201","pt":1719496924101,"mc":[{"id":"1.230180116","rc":[{"atl":[[18.5,2]],"id":68900945}],"con":true,"img":false}]}
{"op":"mcm","clk":"11540652386","pt":1719496926371,"mc":[{"id":"1.230180116","rc":[{"atb":[[1.04,1.7]],"id":64253836},{"atl":[[1000,1.7]],"id":64253836},{"atb":[[1.03,1.7]],"id":48536142},{"atl":[[1000,2.49]],"id":48536142},{"atb":[[1.04,121.07]],"id":68900945},{"atl":[[1000,1.7]],"id":68900945}],"con":true,"img":false}]}
{"op":"mcm","clk":"11540652411","pt":1719496926680,"mc":[{"id":"1.230180116","rc":[{"atb":[[1.04,0.07]],"id":64253836},{"atl":[[1000,0.01]],"id":64253836},{"atb":[[1.03,0.09]],"id":48536142},{"atl":[[1000,0.84]],"id":48536142},{"atb":[[1.04,119.44]],"id":68900945},{"atl":[[1000,0.01]],"id":68900945}],"con":true,"img":false}]}
{"op":"mcm","clk":"11540652439","pt":1719496926988,"mc":[{"id":"1.230180116","rc":[{"atb":[[1.04,0]],"id":64253836},{"atl":[[1000,0]],"id":64253836},{"atb":[[1.03,0]],"id":48536142},{"atl":[[1000,0.78]],"id":48536142},{"atb":[[1.04,119.37]],"id":68900945},{"atl":[[1000,0],[17.5,1.57]],"id":68900945}],"con":true,"img":false}]}
{"op":"mcm","clk":"11540652452","pt":1719496927092,"mc":[{"id":"1.230180116","rc":[{"atb":[[4.9,1.74]],"id":64253836},{"atl":[[18,1.49]],"id":64253836},{"atb":[[2.88,0.09]],"id":48536142},{"atl":[[4.2,1.05]],"id":48536142},{"atb":[[4.9,1.74]],"id":68900945},{"atl":[[17.5,3.58],[18.5,0]],"id":68900945}],"con":true,"img":false}]}
{"op":"mcm","clk":"11540652487","pt":1719496927509,"mc":[{"id":"1.230180116","rc":[{"atl":[[4.1,2]],"id":48536142}],"con":true,"img":false}]}
{"op":"mcm","clk":"11540652491","pt":1719496927607,"mc":[{"id":"1.230180116","rc":[{"atl":[[4.1,10.07]],"id":48536142},{"atl":[[17,0.84]],"id":68900945}],"con":true,"img":false}]}
{"op":"mcm","clk":"11540652498","pt":1719496927710,"mc":[{"id":"1.230180116","rc":[{"atl":[[4,6.34]],"id":48536142}],"con":true,"img":false}]}
{"op":"mcm","clk":"11540652504","pt":1719496927812,"mc":[{"id":"1.230180116","rc":[{"atl":[[4.3,8.34]],"id":48536142}],"con":true,"img":false}]}
{"op":"mcm","clk":"11540652515","pt":1719496928018,"mc":[{"id":"1.230180116","rc":[{"atb":[[2.36,8.71]],"id":48536142},{"atl":[[4.2,2.05]],"id":48536142}],"con":true,"img":false}]}
{"op":"mcm","clk":"11540652520","pt":1719496928120,"mc":[{"id":"1.230180116","rc":[{"atl":[[4.2,1.05]],"id":48536142},{"atl":[[18,0.84]],"id":68900945}],"con":true,"img":false}]}
{"op":"mcm","clk":"11540652524","pt":1719496928172,"mc":[{"id":"1.230180116","rc":[{"atl":[[4.3,7.5],[3.95,1]],"id":48536142},{"atl":[[17,1.84]],"id":68900945}],"con":true,"img":false}]}
{"op":"mcm","clk":"11540652545","pt":1719496928487,"mc":[{"id":"1.230180116","rc":[{"atl":[[4.1,8.07]],"id":48536142}],"con":true,"img":false}]}
{"op":"mcm","clk":"11540652556","pt":1719496928586,"mc":[{"id":"1.230180116","rc":[{"atl":[[18,0]],"id":68900945}],"con":true,"img":false}]}
{"op":"mcm","clk":"11540652564","pt":1719496928690,"mc":[{"id":"1.230180116","rc":[{"atl":[[4.5,0]],"id":48536142}],"con":true,"img":false}]}
{"op":"mcm","clk":"11540652571","pt":1719496928801,"mc":[{"id":"1.230180116","rc":[{"atl":[[4,0],[3.95,10.42]],"id":48536142}],"con":true,"img":false}]}
{"op":"mcm","clk":"11540652577","pt":1719496928899,"mc":[{"id":"1.230180116","rc":[{"atl":[[4.2,0.05]],"id":48536142}],"con":true,"img":false}]}
{"op":"mcm","clk":"11540652590","pt":1719496929110,"mc":[{"id":"1.230180116","rc":[{"atl":[[3.9,0.84]],"id":48536142}],"con":true,"img":false}]}
{"op":"mcm","clk":"11540652596","pt":1719496929217,"mc":[{"id":"1.230180116","rc":[{"atl":[[3.9,1.84]],"id":48536142}],"con":true,"img":false}]}
{"op":"mcm","clk":"11540652663","pt":1719496930086,"mc":[{"id":"1.230180116","rc":[{"atl":[[17.5,2.01]],"id":68900945}],"con":true,"img":false}]}
{"op":"mcm","clk":"11540652683","pt":1719496930292,"mc":[{"id":"1.230180116","rc":[{"atl":[[4.4,0]],"id":48536142}],"con":true,"img":false}]}
{"op":"mcm","clk":"11540652716","pt":1719496930704,"mc":[{"id":"1.230180116","rc":[{"atl":[[3.9,10.52]],"id":48536142}],"con":true,"img":false}]}
{"op":"mcm","clk":"11540652745","pt":1719496931119,"mc":[{"id":"1.230180116","rc":[{"atl":[[3.85,6.34]],"id":48536142}],"con":true,"img":false}]}
{"op":"mcm","clk":"11540652761","pt":1719496931279,"mc":[{"id":"1.230180116","rc":[{"atl":[[4.3,0]],"id":48536142}],"con":true,"img":false}]}
{"op":"mcm","clk":"11540652772","pt":1719496931381,"mc":[{"id":"1.230180116","rc":[{"atl":[[3.85,14.76]],"id":48536142}],"con":true,"img":false}]}
{"op":"mcm","clk":"11540652792","pt":1719496931593,"mc":[{"id":"1.230180116","rc":[{"atl":[[3.9,9.52]],"id":48536142}],"con":true,"img":false}]}
{"op":"mcm","clk":"11540652806","pt":1719496931795,"mc":[{"id":"1.230180116","rc":[{"atl":[[3.8,1]],"id":48536142}],"con":true,"img":false}]}
{"op":"mcm","clk":"11540652849","pt":1719496932312,"mc":[{"id":"1.230180116","rc":[{"atl":[[3.85,8.42]],"id":48536142}],"con":true,"img":false}]}
{"op":"mcm","clk":"11540652877","pt":1719496932681,"mc":[{"id":"1.230180116","rc":[{"atb":[[2.9,0]],"id":64253836},{"atb":[[2.62,0]],"id":48536142},{"atl":[[3.95,9.42],[3.7,27.63]],"id":48536142},{"atb":[[2.9,0]],"id":68900945}],"con":true,"img":false}]}
{"op":"mcm","clk":"11540652883","pt":1719496932777,"mc":[{"id":"1.230180116","rc":[{"atl":[[3.8,2]],"id":48536142}],"con":true,"img":false}]}
{"op":"mcm","clk":"11540652891","pt":1719496932885,"mc":[{"id":"1.230180116","rc":[{"atl":[[3.8,1]],"id":48536142}],"con":true,"img":false}]}
{"op":"mcm","clk":"11540652899","pt":1719496932985,"mc":[{"id":"1.230180116","rc":[{"atl":[[16.5,1.66]],"id":68900945}],"con":true,"img":false}]}
{"op":"mcm","clk":"11540652909","pt":1719496933086,"mc":[{"id":"1.230180116","rc":[{"atl":[[3.9,8.68],[3.65,1]],"id":48536142}],"con":true,"img":false}]}
{"op":"mcm","clk":"11540652913","pt":1719496933188,"mc":[{"id":"1.230180116","rc":[{"atl":[[16.5,3.66]],"id":68900945}],"con":true,"img":false}]}
{"op":"mcm","clk":"11540652927","pt":1719496933297,"mc":[{"id":"1.230180116","rc":[{"atl":[[16.5,1.66],[17,5.16],[17.5,0.01]],"id":68900945}],"con":true,"img":false}]}
{"op":"mcm","clk":"11540652972","pt":1719496933919,"mc":[{"id":"1.230180116","rc":[{"atl":[[3.8,0]],"id":48536142},{"atl":[[17,4.16]],"id":68900945}],"con":true,"img":false}]}
{"op":"mcm","clk":"11540652980","pt":1719496934017,"mc":[{"id":"1.230180116","rc":[{"atl":[[3.65,2]],"id":48536142},{"atl":[[16,1]],"id":68900945}],"con":true,"img":false}]}
{"op":"mcm","clk":"11540653168","pt":1719496936593,"mc":[{"id":"1.230180116","rc":[{"atl":[[3.6,0.84]],"id":48536142}],"con":true,"img":false}]}
{"op":"mcm","clk":"11540653508","pt":1719496942310,"mc":[{"id":"1.230180116","rc":[{"atl":[[3.7,0]],"id":48536142}],"con":true,"img":false}]}
{"op":"mcm","clk":"11540653549","pt":1719496942933,"mc":[{"id":"1.230180116","rc":[{"atl":[[3.65,1]],"id":48536142}],"con":true,"img":false}]}
{"op":"mcm","clk":"11540653554","pt":1719496943031,"mc":[{"id":"1.230180116","rc":[{"atl":[[3.8,1]],"id":48536142}],"con":true,"img":false}]}
{"op":"mcm","clk":"11540653595","pt":1719496943706,"mc":[{"id":"1.230180116","rc":[{"atb":[[3.2,3.42]],"id":48536142}],"con":true,"img":false}]}
{"op":"mcm","clk":"11540653610","pt":1719496943913,"mc":[{"id":"1.230180116","rc":[{"atb":[[3.2,13.6]],"id":48536142}],"con":true,"img":false}]}
{"op":"mcm","clk":"11540653616","pt":1719496944017,"mc":[{"id":"1.230180116","rc":[{"atb":[[3.25,0.84]],"id":48536142}],"con":true,"img":false}]}
{"op":"mcm","clk":"11540653770","pt":1719496946127,"mc":[{"id":"1.230180116","rc":[{"spl":[[1.01,10]],"id":40831161}],"con":true,"img":false}]}
{"op":"mcm","clk":"11540653927","pt":1719496948399,"mc":[{"id":"1.230180116","rc":[{"atb":[[2.26,17.89]],"id":40831161}],"con":true,"img":false}]}
{"op":"mcm","clk":"11540654733","pt":1719496960316,"mc":[{"id":"1.230180116","rc":[{"atb":[[4.2,1.79]],"id":69366841}],"con":true,"img":false}]}
{"op":"mcm","clk":"11540654740","pt":1719496960414,"mc":[{"id":"1.230180116","rc":[{"atb":[[3.9,1.92]],"id":63031611},{"atb":[[2.24,14.08]],"id":69366841}],"con":true,"img":false}]}
{"op":"mcm","clk":"11540654780","pt":1719496961133,"mc":[{"id":"1.230180116","rc":[{"atb":[[2.24,9.77]],"id":69366841}],"con":true,"img":false}]}
{"op":"mcm","clk":"11540655072","pt":1719496965263,"mc":[{"id":"1.230180116","rc":[{"atb":[[4.9,1.67]],"id":64253836},{"atl":[[18,1.47]],"id":64253836},{"atb":[[2.88,0],[2.7,0]],"id":48536142},{"atl":[[4.2,0],[4.7,0]],"id":48536142},{"atb":[[4.9,1.67]],"id":68900945},{"atl":[[17.5,0]],"id":68900945}],"con":true,"img":false}]}
{"op":"mcm","clk":"11540655191","pt":1719496967020,"mc":[{"id":"1.230180116","rc":[{"atl":[[1000,0.84]],"id":68900945}],"con":true,"img":false}]}
{"op":"mcm","clk":"11540655225","pt":1719496967435,"mc":[{"id":"1.230180116","rc":[{"atl":[[1000,0.55],[22,0]],"id":68900945}],"con":true,"img":false}]}
{"op":"mcm","clk":"11540655275","pt":1719496967952,"mc":[{"id":"1.230180116","rc":[{"atl":[[1000,0]],"id":68900945}],"con":true,"img":false}]}
{"op":"mcm","clk":"11540655289","pt":1719496968053,"mc":[{"id":"1.230180116","rc":[{"atl":[[15.5,0.55]],"id":68900945}],"con":true,"img":false}]}
{"op":"mcm","clk":"11540655298","pt":1719496968156,"mc":[{"id":"1.230180116","rc":[{"atl":[[16,3],[17,0.84]],"id":68900945}],"con":true,"img":false}]}
{"op":"mcm","clk":"11540655331","pt":1719496968572,"mc":[{"id":"1.230180116","rc":[{"atl":[[15.5,1.39],[17,0]],"id":68900945}],"con":true,"img":false}]}
{"op":"mcm","clk":"11540655548","pt":1719496971668,"mc":[{"id":"1.230180116","rc":[{"atb":[[2.92,0]],"id":64253836},{"atb":[[2.92,0]],"id":68900945}],"con":true,"img":false}]}
{"op":"mcm","clk":"11540656299","pt":1719496980356,"mc":[{"id":"1.230180116","rc":[{"atl":[[1000,0.38]],"id":69366841},{"spn":4.91,"spf":1.0,"id":40831161},{"atl":[[1000,0.28]],"id":64253836},{"spn":3.42,"spf":"NaN","id":48536142},{"atl":[[1000,0.33]],"id":68900945},{"spn":10.2,"spf":"NaN","id":68900945}],"con":true,"img":false}]}
{"op":"mcm","clk":"11540656315","pt":1719496980561,"mc":[{"id":"1.230180116","rc":[{"atl":[[1000,0.17]],"id":69366841}],"con":true,"img":false}]}
{"op":"mcm","clk":"11540656326","pt":1719496980665,"mc":[{"id":"1.230180116","rc":[{"atl":[[24,2.05]],"id":69366841},{"atl":[[1000,0]],"id":64253836},{"atl":[[1000,0]],"id":68900945}],"con":true,"img":false}]}
{"op":"mcm","clk":"11540656336","pt":1719496980764,"mc":[{"id":"1.230180116","rc":[{"atl":[[18,1.75]],"id":64253836},{"atl":[[15.5,1.72]],"id":68900945}],"con":true,"img":false}]}
{"op":"mcm","clk":"11540656369","pt":1719496981075,"mc":[{"id":"1.230180116","rc":[{"atl":[[17.5,0.84]],"id":64253836}],"con":true,"img":false}]}
{"op":"mcm","clk":"11540656424","pt":1719496981649,"mc":[{"id":"1.230180116","rc":[{"atb":[[2.88,6.3]],"id":64253836},{"atl":[[17.5,2.29]],"id":64253836},{"atb":[[2.88,6.3]],"id":68900945}],"con":true,"img":false}]}
{"op":"mcm","clk":"11540656437","pt":1719496981749,"mc":[{"id":"1.230180116","rc":[{"atl":[[17.5,4.58],[18.5,2.36]],"id":64253836}],"con":true,"img":false}]}
{"op":"mcm","clk":"11540656444","pt":1719496981853,"mc":[{"id":"1.230180116","rc":[{"atl":[[20,0]],"id":64253836}],"con":true,"img":false}]}
{"op":"mcm","clk":"11540656452","pt":1719496981955,"mc":[{"id":"1.230180116","rc":[{"atl":[[1000,0.84],[17,1],[18,1.28]],"id":64253836}],"con":true,"img":false}]}
{"op":"mcm","clk":"11540656460","pt":1719496982059,"mc":[{"id":"1.230180116","rc":[{"atl":[[18.5,1.52]],"id":64253836}],"con":true,"img":false}]}
{"op":"mcm","clk":"11540656479","pt":1719496982268,"mc":[{"id":"1.230180116","rc":[{"atl":[[1000,0.49]],"id":64253836}],"con":true,"img":false}]}
{"op":"mcm","clk":"11540656489","pt":1719496982373,"mc":[{"id":"1.230180116","rc":[{"atl":[[17.5,3.13]],"id":64253836}],"con":true,"img":false}]}
{"op":"mcm","clk":"11540656512","pt":1719496982579,"mc":[{"id":"1.230180116","rc":[{"atl":[[1000,0]],"id":64253836}],"con":true,"img":false}]}
{"op":"mcm","clk":"11540656521","pt":1719496982637,"mc":[{"id":"1.230180116","rc":[{"atl":[[17,1.49]],"id":64253836}],"con":true,"img":false}]}
{"op":"mcm","clk":"11540656529","pt":1719496982734,"mc":[{"id":"1.230180116","rc":[{"atb":[[2.3,10.74]],"id":40831161}],"con":true,"img":false}]}
{"op":"mcm","clk":"11540656535","pt":1719496982838,"mc":[{"id":"1.230180116","rc":[{"atb":[[2.28,10.91]],"id":69366841}],"con":true,"img":false}]}
{"op":"mcm","clk":"11540656558","pt":1719496983045,"mc":[{"id":"1.230180116","rc":[{"atb":[[2.38,10.12]],"id":48536142}],"con":true,"img":false}]}
{"op":"mcm","clk":"11540656578","pt":1719496983251,"mc":[{"id":"1.230180116","rc":[{"atb":[[2.26,13.46]],"id":40831161}],"con":true,"img":false}]}
{"op":"mcm","clk":"11540656609","pt":1719496983670,"mc":[{"id":"1.230180116","rc":[{"atl":[[16,2]],"id":68900945}],"con":true,"img":false}]}
{"op":"mcm","clk":"11540656620","pt":1719496983769,"mc":[{"id":"1.230180116","rc":[{"atl":[[15,1]],"id":68900945}],"con":true,"img":false}]}
{"op":"mcm","clk":"11540656652","pt":1719496984031,"mc":[{"id":"1.230180116","rc":[{"atl":[[18,0.28]],"id":64253836}],"con":true,"img":false}]}
{"op":"mcm","clk":"11540656662","pt":1719496984133,"mc":[{"id":"1.230180116","rc":[{"atl":[[16.5,1]],"id":64253836}],"con":true,"img":false}]}
{"op":"mcm","clk":"11540656686","pt":1719496984447,"mc":[{"id":"1.230180116","rc":[{"atl":[[1000,0.84],[17,1]],"id":64253836}],"con":true,"img":false}]}
{"op":"mcm","clk":"11540656705","pt":1719496984757,"mc":[{"id":"1.230180116","rc":[{"atl":[[1000,0.52]],"id":64253836}],"con":true,"img":false}]}
{"op":"mcm","clk":"11540656732","pt":1719496985070,"mc":[{"id":"1.230180116","rc":[{"atl":[[1000,0]],"id":64253836}],"con":true,"img":false}]}
{"op":"mcm","clk":"11540656743","pt":1719496985170,"mc":[{"id":"1.230180116","rc":[{"atl":[[16,0.52]],"id":64253836}],"con":true,"img":false}]}
{"op":"mcm","clk":"11540656755","pt":1719496985279,"mc":[{"id":"1.230180116","rc":[{"atl":[[16.5,3],[17.5,0.84]],"id":64253836}],"con":true,"img":false}]}
{"op":"mcm","clk":"11540656782","pt":1719496985539,"mc":[{"id":"1.230180116","rc":[{"atl":[[16.5,2]],"id":64253836}],"con":true,"img":false}]}
{"op":"mcm","clk":"11540656796","pt":1719496985643,"mc":[{"id":"1.230180116","rc":[{"atl":[[17.5,0],[18,1.28]],"id":64253836}],"con":true,"img":false}]}
{"op":"mcm","clk":"11540656879","pt":1719496986578,"mc":[{"id":"1.230180116","rc":[{"atl":[[18,0.28]],"id":64253836}],"con":true,"img":false}]}
{"op":"mcm","clk":"11540656888","pt":1719496986679,"mc":[{"id":"1.230180116","rc":[{"atl":[[16,1.52]],"id":64253836}],"con":true,"img":false}]}
{"op":"mcm","clk":"11540657680","pt":1719496994978,"mc":[{"id":"1.230180116","rc":[{"atl":[[24,1.84]],"id":69366841},{"atl":[[18,0]],"id":64253836},{"atl":[[15.5,1.39]],"id":68900945}],"con":true,"img":false}]}
{"op":"mcm","clk":"11540657791","pt":1719496996177,"mc":[{"id":"1.230180116","rc":[{"atl":[[15,0]],"id":68900945}],"con":true,"img":false}]}
{"op":"mcm","clk":"11540657800","pt":1719496996282,"mc":[{"id":"1.230180116","rc":[{"atl":[[15.5,2.39]],"id":68900945}],"con":true,"img":false}]}
{"op":"mcm","clk":"11540658047","pt":1719496998687,"mc":[{"id":"1.230180116","rc":[{"atb":[[3.65,9.15]],"id":48536142},{"atl":[[3.6,0],[3.65,0]],"id":48536142},{"trd":[[3.65,3.99],[3.6,1.69]],"ltp":3.65,"tv":5.68,"id":48536142}],"con":true,"img":false}]}
{"op":"mcm","clk":"11540658055","pt":1719496998796,"mc":[{"id":"1.230180116","rc":[{"atb":[[3.65,0]],"id":48536142},{"trd":[[3.65,22.29]],"ltp":3.65,"tv":22.29,"id":48536142}],"con":true,"img":false}]}
{"op":"mcm","clk":"11540658067","pt":1719496998897,"mc":[{"id":"1.230180116","rc":[{"atb":[[3.85,0]],"id":63031611},{"atb":[[4.1,0]],"id":69366841},{"atb":[[2.38,0]],"id":40831161},{"atb":[[3.55,4.43],[3.2,10.18]],"id":48536142},{"atl":[[3.65,0.26]],"id":48536142}],"con":true,"img":false}]}
{"op":"mcm","clk":"11540658075","pt":1719496998952,"mc":[{"id":"1.230180116","rc":[{"atl":[[4.1,0]],"id":48536142}],"con":true,"img":false}]}
{"op":"mcm","clk":"11540658083","pt":1719496999058,"mc":[{"id":"1.230180116","rc":[{"atb":[[4.8,1]],"id":40831161},{"atb":[[3.55,0]],"id":48536142}],"con":true,"img":false}]}
{"op":"mcm","clk":"11540658094","pt":1719496999158,"mc":[{"id":"1.230180116","rc":[{"atb":[[3.25,6.35]],"id":48536142}],"con":true,"img":false}]}
{"op":"mcm","clk":"11540658101","pt":1719496999264,"mc":[{"id":"1.230180116","rc":[{"atb":[[3.25,18.22]],"id":48536142}],"con":true,"img":false}]}
{"op":"mcm","clk":"11540658107","pt":1719496999368,"mc":[{"id":"1.230180116","rc":[{"atl":[[16.5,0]],"id":68900945}],"con":true,"img":false}]}
{"op":"mcm","clk":"11540658125","pt":1719496999577,"mc":[{"id":"1.230180116","rc":[{"atb":[[3.3,6.34]],"id":48536142}],"con":true,"img":false}]}
{"op":"mcm","clk":"11540658133","pt":1719496999680,"mc":[{"id":"1.230180116","rc":[{"atl":[[3.8,4.64]],"id":48536142}],"con":true,"img":false}]}
{"op":"mcm","clk":"11540658170","pt":1719497000094,"mc":[{"id":"1.230180116","rc":[{"atb":[[3.35,0.84]],"id":48536142},{"atl":[[3.75,0.84]],"id":48536142}],"con":true,"img":false}]}
{"op":"mcm","clk":"11540658191","pt":1719497000255,"mc":[{"id":"1.230180116","rc":[{"atl":[[3.8,4.32],[3.65,0]],"id":48536142}],"con":true,"img":false}]}
{"op":"mcm","clk":"11540658210","pt":1719497000461,"mc":[{"id":"1.230180116","rc":[{"atl":[[1000,0.38]],"id":69366841},{"atl":[[1000,0.32]],"id":64253836},{"atl":[[1000,0.33]],"id":68900945}],"con":true,"img":false}]}
{"op":"mcm","clk":"11540658226","pt":1719497000677,"mc":[{"id":"1.230180116","rc":[{"atl":[[1000,0.17]],"id":69366841},{"atl":[[1000,0]],"id":64253836},{"atl":[[1000,0]],"id":68900945}],"con":true,"img":false}]}
{"op":"mcm","clk":"11540658234","pt":1719497000775,"mc":[{"id":"1.230180116","rc":[{"atl":[[24,2.05]],"id":69366841},{"atl":[[16,1.84]],"id":64253836},{"atl":[[15.5,2.72]],"id":68900945}],"con":true,"img":false}]}
{"op":"mcm","clk":"11540658245","pt":1719497000879,"mc":[{"id":"1.230180116","rc":[{"atl":[[3.8,3.86]],"id":48536142}],"con":true,"img":false}]}
{"op":"mcm","clk":"11540658256","pt":1719497000984,"mc":[{"id":"1.230180116","rc":[{"atl":[[1000,1.25]],"id":48536142}],"con":true,"img":false}]}
{"op":"mcm","clk":"11540658264","pt":1719497001087,"mc":[{"id":"1.230180116","rc":[{"atl":[[15.5,0.84]],"id":64253836}],"con":true,"img":false}]}
{"op":"mcm","clk":"11540658388","pt":1719497002294,"mc":[{"id":"1.230180116","rc":[{"atl":[[18.5,0]],"id":64253836}],"con":true,"img":false}]}
{"op":"mcm","clk":"11540658488","pt":1719497003503,"mc":[{"id":"1.230180116","rc":[{"atl":[[10.5,0],[11,1]],"id":63031611},{"atb":[[2.98,1]],"id":48536142}],"con":true,"img":false}]}
{"op":"mcm","clk":"11540658494","pt":1719497003560,"mc":[{"id":"1.230180116","rc":[{"atl":[[75,2],[85,0]],"id":63031611}],"con":true,"img":false}]}
{"op":"mcm","clk":"11540658519","pt":1719497003875,"mc":[{"id":"1.230180116","rc":[{"atl":[[80,0]],"id":63031611},{"atl":[[1000,0.46]],"id":48536142}],"con":true,"img":false}]}
{"op":"mcm","clk":"11540658533","pt":1719497003970,"mc":[{"id":"1.230180116","rc":[{"atl":[[70,1]],"id":63031611}],"con":true,"img":false}]}
{"op":"mcm","clk":"11540658819","pt":1719497007101,"mc":[{"id":"1.230180116","rc":[{"atb":[[3.25,12.71],[2.98,0]],"id":48536142}],"con":true,"img":false}]}
{"op":"mcm","clk":"11540659114","pt":1719497010880,"mc":[{"id":"1.230180116","rc":[{"atb":[[2.7,14.32]],"id":48536142}],"con":true,"img":false}]}
{"op":"mcm","clk":"11540659163","pt":1719497011399,"mc":[{"id":"1.230180116","rc":[{"atb":[[3.35,6.19]],"id":48536142}],"con":true,"img":false}]}
{"op":"mcm","clk":"11540659176","pt":1719497011606,"mc":[{"id":"1.230180116","rc":[{"atb":[[2.26,13.7]],"id":69366841}],"con":true,"img":false}]}
{"op":"mcm","clk":"11540659194","pt":1719497011810,"mc":[{"id":"1.230180116","rc":[{"atb":[[3.3,0]],"id":48536142}],"con":true,"img":false}]}
{"op":"mcm","clk":"11540659216","pt":1719497012072,"mc":[{"id":"1.230180116","rc":[{"atb":[[3.25,11.87]],"id":48536142}],"con":true,"img":false}]}
{"op":"mcm","clk":"11540659282","pt":1719497013211,"mc":[{"id":"1.230180116","rc":[{"atb":[[2.7,0]],"id":48536142}],"con":true,"img":false}]}
{"op":"mcm","clk":"11540659400","pt":1719497014973,"mc":[{"id":"1.230180116","rc":[{"atl":[[24,1.84]],"id":69366841},{"atl":[[16,1.52]],"id":64253836}],"con":true,"img":false}]}
{"op":"mcm","clk":"11540659409","pt":1719497015077,"mc":[{"id":"1.230180116","rc":[{"atl":[[15.5,2.39]],"id":68900945}],"con":true,"img":false}]}
{"op":"mcm","clk":"11540659735","pt":1719497019482,"mc":[{"id":"1.230180116","rc":[{"atb":[[2.9,7.34]],"id":64253836}],"con":true,"img":false}]}
{"op":"mcm","clk":"11540659758","pt":1719497019788,"mc":[{"id":"1.230180116","rc":[{"atb":[[2.9,7.34]],"id":68900945}],"con":true,"img":false}]}
{"op":"mcm","clk":"11540659796","pt":1719497020305,"mc":[{"id":"1.230180116","rc":[{"atb":[[2.16,5.44]],"id":69366841}],"con":true,"img":false}]}
{"op":"mcm","clk":"11540659803","pt":1719497020414,"mc":[{"id":"1.230180116","rc":[{"atb":[[2.5,6.31]],"id":48536142}],"con":true,"img":false}]}
{"op":"mcm","clk":"11540659811","pt":1719497020512,"mc":[{"id":"1.230180116","rc":[{"atb":[[4.2,0]],"id":69366841},{"atb":[[2.16,5.44]],"id":40831161},{"atb":[[3.35,0.84]],"id":48536142}],"con":true,"img":false}]}
{"op":"mcm","clk":"11540659815","pt":1719497020618,"mc":[{"id":"1.230180116","rc":[{"atb":[[3.9,0],[2.16,5.44]],"id":63031611}],"con":true,"img":false}]}
{"op":"mcm","clk":"11540659821","pt":1719497020673,"mc":[{"id":"1.230180116","rc":[{"atb":[[2.68,5.17]],"id":48536142}],"con":true,"img":false}]}
{"op":"mcm","clk":"11540659826","pt":1719497020778,"mc":[{"id":"1.230180116","rc":[{"atb":[[4.1,1.83]],"id":69366841},{"atl":[[1000,0.38]],"id":69366841},{"atl":[[1000,0.32]],"id":64253836},{"atl":[[1000,0.33]],"id":68900945}],"con":true,"img":false}]}
{"op":"mcm","clk":"11540659845","pt":1719497020982,"mc":[{"id":"1.230180116","rc":[{"atl":[[1000,0.17]],"id":69366841},{"atl":[[1000,0]],"id":64253836},{"atl":[[1000,0]],"id":68900945}],"con":true,"img":false}]}
{"op":"mcm","clk":"11540659854","pt":1719497021090,"mc":[{"id":"1.230180116","rc":[{"atl":[[24,2.05]],"id":69366841},{"atl":[[16,1.84]],"id":64253836},{"atb":[[3.35,0],[3.3,0.84]],"id":48536142},{"atl":[[15.5,2.72]],"id":68900945}],"con":true,"img":false}]}
{"op":"mcm","clk":"11540659866","pt":1719497021192,"mc":[{"id":"1.230180116","rc":[{"atb":[[3.85,1.95]],"id":63031611}],"con":true,"img":false}]}
{"op":"mcm","clk":"11540659918","pt":1719497021716,"mc":[{"id":"1.230180116","rc":[{"atb":[[2.26,9.39]],"id":69366841}],"con":true,"img":false}]}
{"op":"mcm","clk":"11540660095","pt":1719497023405,"mc":[{"id":"1.230180116","rc":[{"atb":[[3.3,6.27]],"id":48536142}],"con":true,"img":false}]}
{"op":"mcm","clk":"11540660408","pt":1719497027183,"mc":[{"id":"1.230180116","rc":[{"atl":[[1000,0.84],[16,1.32]],"id":64253836}],"con":true,"img":false}]}
{"op":"mcm","clk":"11540660441","pt":1719497027707,"mc":[{"id":"1.230180116","rc":[{"atl":[[1000,0.56]],"id":64253836}],"con":true,"img":false}]}
{"op":"mcm","clk":"11540660472","pt":1719497028116,"mc":[{"id":"1.230180116","rc":[{"atl":[[1000,0]],"id":64253836}],"con":true,"img":false}]}
{"op":"mcm","clk":"11540660481","pt":1719497028219,"mc":[{"id":"1.230180116","rc":[{"atl":[[15,0.56]],"id":64253836}],"con":true,"img":false}]}
{"op":"mcm","clk":"11540660498","pt":1719497028432,"mc":[{"id":"1.230180116","rc":[{"atl":[[15.5,2.84],[16.5,0]],"id":64253836}],"con":true,"img":false}]}
{"op":"mcm","clk":"11540660556","pt":1719497029100,"mc":[{"id":"1.230180116","rc":[{"atb":[[2.26,0]],"id":69366841},{"atb":[[2.28,0]],"id":40831161},{"atb":[[2.36,0]],"id":48536142}],"con":true,"img":false}]}
{"op":"mcm","clk":"11540660577","pt":1719497029619,"mc":[{"id":"1.230180116","rc":[{"atl":[[16,0.32]],"id":64253836}],"con":true,"img":false}]}
{"op":"mcm","clk":"11540660584","pt":1719497029727,"mc":[{"id":"1.230180116","rc":[{"atl":[[15,1.56]],"id":64253836}],"con":true,"img":false}]}
{"op":"mcm","clk":"11540660598","pt":1719497029885,"mc":[{"id":"1.230180116","rc":[{"atl":[[17,0]],"id":64253836}],"con":true,"img":false}]}
{"op":"mcm","clk":"11540660616","pt":1719497030094,"mc":[{"id":"1.230180116","rc":[{"atl":[[14.5,1]],"id":64253836}],"con":true,"img":false}]}
{"op":"mcm","clk":"11540660642","pt":1719497030399,"mc":[{"id":"1.230180116","rc":[{"atb":[[4.8,0],[5,1.69]],"id":64253836},{"atb":[[3.3,106.27]],"id":48536142}],"con":true,"img":false}]}
{"op":"mcm","clk":"11540660703","pt":1719497031023,"mc":[{"id":"1.230180116","rc":[{"atb":[[5.1,0.84]],"id":64253836}],"con":true,"img":false}]}
{"op":"mcm","clk":"11540660789","pt":1719497031918,"mc":[{"id":"1.230180116","rc":[{"atl":[[14.5,3.03]],"id":64253836}],"con":true,"img":false}]}
{"op":"mcm","clk":"11540660843","pt":1719497032627,"mc":[{"id":"1.230180116","rc":[{"atl":[[14,0.84]],"id":64253836}],"con":true,"img":false}]}
{"op":"mcm","clk":"11540660851","pt":1719497032732,"mc":[{"id":"1.230180116","rc":[{"atl":[[15.5,2]],"id":64253836}],"con":true,"img":false}]}
{"op":"mcm","clk":"11540660859","pt":1719497032800,"mc":[{"id":"1.230180116","rc":[{"atl":[[15,0.56]],"id":64253836}],"con":true,"img":false}]}
{"op":"mcm","clk":"11540660868","pt":1719497032907,"mc":[{"id":"1.230180116","rc":[{"atl":[[14,1.84]],"id":64253836}],"con":true,"img":false}]}
{"op":"mcm","clk":"11540660915","pt":1719497033625,"mc":[{"id":"1.230180116","rc":[{"atb":[[3.35,6.34]],"id":48536142}],"con":true,"img":false}]}
{"op":"mcm","clk":"11540660925","pt":1719497033737,"mc":[{"id":"1.230180116","rc":[{"atl":[[14,3.79]],"id":64253836}],"con":true,"img":false}]}
{"op":"mcm","clk":"11540660941","pt":1719497033935,"mc":[{"id":"1.230180116","rc":[{"atl":[[13.5,3.81],[14.5,2.03],[15.5,0]],"id":64253836}],"con":true,"img":false}]}
{"op":"mcm","clk":"11540660953","pt":1719497034136,"mc":[{"id":"1.230180116","rc":[{"atl":[[13,1.95]],"id":64253836},{"atb":[[3.4,0.84]],"id":48536142}],"con":true,"img":false}]}
{"op":"mcm","clk":"11540660969","pt":1719497034293,"mc":[{"id":"1.230180116","rc":[{"atl":[[12.5,1]],"id":64253836},{"atb":[[3.3,100.84]],"id":48536142}],"con":true,"img":false}]}
{"op":"mcm","clk":"11540660982","pt":1719497034500,"mc":[{"id":"1.230180116","rc":[{"atl":[[13.5,3.48]],"id":64253836}],"con":true,"img":false}]}
{"op":"mcm","clk":"11540660999","pt":1719497034707,"mc":[{"id":"1.230180116","rc":[{"atl":[[12.5,3.19],[13,0],[14,2.95]],"id":64253836}],"con":true,"img":false}]}
{"op":"mcm","clk":"11540661008","pt":1719497034810,"mc":[{"id":"1.230180116","rc":[{"atl":[[14,1.95]],"id":64253836}],"con":true,"img":false}]}
{"op":"mcm","clk":"11540661016","pt":1719497034924,"mc":[{"id":"1.230180116","rc":[{"atl":[[12,3.19],[12.5,4.19],[13.5,0.45]],"id":64253836}],"con":true,"img":false}]}
{"op":"mcm","clk":"11540661036","pt":1719497035118,"mc":[{"id":"1.230180116","rc":[{"atl":[[12.5,3.19]],"id":64253836},{"atb":[[3.4,6.11]],"id":48536142}],"con":true,"img":false}]}
{"op":"mcm","clk":"11540661053","pt":1719497035369,"mc":[{"id":"1.230180116","rc":[{"atl":[[24,1.84]],"id":69366841},{"atb":[[2.32,8.97]],"id":40831161},{"atl":[[16,0]],"id":64253836},{"atb":[[3.35,0]],"id":48536142},{"atl":[[15.5,2.39]],"id":68900945}],"con":true,"img":false}]}
{"op":"mcm","clk":"11540661065","pt":1719497035526,"mc":[{"id":"1.230180116","rc":[{"atl":[[11.5,1],[12,5.46]],"id":64253836},{"atb":[[2.6,7.4],[3.15,0]],"id":48536142}],"con":true,"img":false}]}
{"op":"mcm","clk":"11540661077","pt":1719497035733,"mc":[{"id":"1.230180116","rc":[{"atb":[[2.3,9.11]],"id":69366841},{"atl":[[12.5,2.19],[13.5,0]],"id":64253836},{"atb":[[3.3,100]],"id":48536142}],"con":true,"img":false}]}
{"op":"mcm","clk":"11540661086","pt":1719497035786,"mc":[{"id":"1.230180116","rc":[{"atl":[[11.5,2.45]],"id":64253836}],"con":true,"img":false}]}
{"op":"mcm","clk":"11540661096","pt":1719497036001,"mc":[{"id":"1.230180116","rc":[{"atl":[[11,2.31]],"id":64253836}],"con":true,"img":false}]}
{"op":"mcm","clk":"11540661110","pt":1719497036205,"mc":[{"id":"1.230180116","rc":[{"atl":[[11,4.77],[12,2.27]],"id":64253836}],"con":true,"img":false}]}
{"op":"mcm","clk":"11540661124","pt":1719497036419,"mc":[{"id":"1.230180116","rc":[{"atl":[[11.5,1.45],[14.5,0]],"id":64253836}],"con":true,"img":false}]}
{"op":"mcm","clk":"11540661138","pt":1719497036622,"mc":[{"id":"1.230180116","rc":[{"atl":[[10.5,1],[11,7.42]],"id":64253836}],"con":true,"img":false}]}
{"op":"mcm","clk":"11540661155","pt":1719497037035,"mc":[{"id":"1.230180116","rc":[{"atl":[[11,5.11],[11.5,1]],"id":64253836}],"con":true,"img":false}]}
{"op":"mcm","clk":"11540661161","pt":1719497037085,"mc":[{"id":"1.230180116","rc":[{"atl":[[10.5,1.45]],"id":64253836}],"con":true,"img":false}]}
{"op":"mcm","clk":"11540661197","pt":1719497037710,"mc":[{"id":"1.230180116","rc":[{"atl":[[11.5,0]],"id":64253836}],"con":true,"img":false}]}
{"op":"mcm","clk":"11540661206","pt":1719497037815,"mc":[{"id":"1.230180116","rc":[{"atl":[[10.5,2.45]],"id":64253836}],"con":true,"img":false}]}
{"op":"mcm","clk":"11540661221","pt":1719497038025,"mc":[{"id":"1.230180116","rc":[{"atl":[[14,0]],"id":64253836}],"con":true,"img":false}]}
{"op":"mcm","clk":"11540661237","pt":1719497038227,"mc":[{"id":"1.230180116","rc":[{"atl":[[10.5,5.16]],"id":64253836}],"con":true,"img":false}]}
{"op":"mcm","clk":"11540661254","pt":1719497038434,"mc":[{"id":"1.230180116","rc":[{"atl":[[10,2.53]],"id":64253836}],"con":true,"img":false}]}
{"op":"mcm","clk":"11540661291","pt":1719497039009,"mc":[{"id":"1.230180116","rc":[{"atl":[[10.5,4.16]],"id":64253836}],"con":true,"img":false}]}
{"op":"mcm","clk":"11540661301","pt":1719497039117,"mc":[{"id":"1.230180116","rc":[{"atl":[[9.8,1]],"id":64253836}],"con":true,"img":false}]}
{"op":"mcm","clk":"11540661307","pt":1719497039216,"mc":[{"id":"1.230180116","rc":[{"atl":[[12.5,0]],"id":64253836}],"con":true,"img":false}]}
{"op":"mcm","clk":"11540661321","pt":1719497039423,"mc":[{"id":"1.230180116","rc":[{"atl":[[10,0]],"id":64253836}],"con":true,"img":false}]}
{"op":"mcm","clk":"11540661341","pt":1719497039740,"mc":[{"id":"1.230180116","rc":[{"atl":[[10,3.1]],"id":64253836}],"con":true,"img":false}]}
{"op":"mcm","clk":"11540661397","pt":1719497040432,"mc":[{"id":"1.230180116","rc":[{"spn":4.92,"spf":1.0,"id":40831161},{"spn":5.08,"spf":1.0,"id":64253836},{"atb":[[3.4,0.84]],"id":48536142},{"spn":3.57,"spf":"NaN","id":48536142}],"con":true,"img":false}]}
{"op":"mcm","clk":"11540661437","pt":1719497040905,"mc":[{"id":"1.230180116","rc":[{"atl":[[1000,0.38]],"id":69366841},{"atl":[[1000,0.52]],"id":64253836},{"atb":[[3.35,6.34]],"id":48536142},{"atl":[[1000,0.33]],"id":68900945}],"con":true,"img":false}]}
{"op":"mcm","clk":"11540661449","pt":1719497041012,"mc":[{"id":"1.230180116","rc":[{"atl":[[1000,0.17]],"id":69366841},{"atl":[[1000,0]],"id":64253836},{"atb":[[3.4,0]],"id":48536142},{"atl":[[1000,0]],"id":68900945}],"con":true,"img":false}]}
{"op":"mcm","clk":"11540661460","pt":1719497041112,"mc":[{"id":"1.230180116","rc":[{"atl":[[24,2.05]],"id":69366841},{"atl":[[9.8,1.52]],"id":64253836},{"atl":[[15.5,2.72]],"id":68900945}],"con":true,"img":false}]}
{"op":"mcm","clk":"11540661488","pt":1719497041529,"mc":[{"id":"1.230180116","rc":[{"atb":[[3.4,0.84]],"id":48536142}],"con":true,"img":false}]}
{"op":"mcm","clk":"11540661496","pt":1719497041633,"mc":[{"id":"1.230180116","rc":[{"atl":[[11,2.65],[9.8,4.62]],"id":64253836}],"con":true,"img":false}]}
{"op":"mcm","clk":"11540661509","pt":1719497041737,"mc":[{"id":"1.230180116","rc":[{"atl":[[12,0]],"id":64253836}],"con":true,"img":false}]}
{"op":"mcm","clk":"11540661524","pt":1719497041947,"mc":[{"id":"1.230180116","rc":[{"atl":[[10.5,3.16],[9.6,2.64],[9.8,7.6]],"id":64253836}],"con":true,"img":false}]}
{"op":"mcm","clk":"11540661530","pt":1719497042002,"mc":[{"id":"1.230180116","rc":[{"atl":[[9.6,3.48]],"id":64253836}],"con":true,"img":false}]}
{"op":"mcm","clk":"11540661536","pt":1719497042101,"mc":[{"id":"1.230180116","rc":[{"atl":[[9.4,3.49],[9.6,4.48],[9.8,4.5]],"id":64253836}],"con":true,"img":false}]}
{"op":"mcm","clk":"11540661544","pt":1719497042314,"mc":[{"id":"1.230180116","rc":[{"atl":[[10.5,2.71]],"id":64253836}],"con":true,"img":false}]}
{"op":"mcm","clk":"11540661552","pt":1719497042419,"mc":[{"id":"1.230180116","rc":[{"atl":[[9.4,3.94]],"id":64253836}],"con":true,"img":false}]}
{"op":"mcm","clk":"11540661561","pt":1719497042519,"mc":[{"id":"1.230180116","rc":[{"atl":[[11,0],[9.6,3.48]],"id":64253836}],"con":true,"img":false}]}
{"op":"mcm","clk":"11540661568","pt":1719497042625,"mc":[{"id":"1.230180116","rc":[{"atl":[[9.2,1],[9.6,0.84]],"id":64253836}],"con":true,"img":false}]}
{"op":"mcm","clk":"11540661581","pt":1719497042725,"mc":[{"id":"1.230180116","rc":[{"atl":[[9.4,3.7],[9.6,5.79]],"id":64253836}],"con":true,"img":false}]}
{"op":"mcm","clk":"11540661638","pt":1719497043522,"mc":[{"id":"1.230180116","rc":[{"atb":[[2.38,0]],"id":48536142}],"con":true,"img":false}]}
{"op":"mcm","clk":"11540661656","pt":1719497043720,"mc":[{"id":"1.230180116","rc":[{"atl":[[9.8,3.5]],"id":64253836}],"con":true,"img":false}]}
{"op":"mcm","clk":"11540661665","pt":1719497043824,"mc":[{"id":"1.230180116","rc":[{"atl":[[9.2,2]],"id":64253836}],"con":true,"img":false}]}
{"op":"mcm","clk":"11540661687","pt":1719497044139,"mc":[{"id":"1.230180116","rc":[{"atl":[[9,2.81],[9.6,4.95]],"id":64253836}],"con":true,"img":false}]}
{"op":"mcm","clk":"11540661718","pt":1719497044398,"mc":[{"id":"1.230180116","rc":[{"atl":[[10.5,0]],"id":64253836}],"con":true,"img":false}]}
{"op":"mcm","clk":"11540661754","pt":1719497044914,"mc":[{"id":"1.230180116","rc":[{"atl":[[9,6.28]],"id":64253836}],"con":true,"img":false}]}
{"op":"mcm","clk":"11540661770","pt":1719497045121,"mc":[{"id":"1.230180116","rc":[{"atl":[[9.2,1]],"id":64253836}],"con":true,"img":false}]}
{"op":"mcm","clk":"11540661782","pt":1719497045227,"mc":[{"id":"1.230180116","rc":[{"atl":[[9.2,0],[8.8,1]],"id":64253836}],"con":true,"img":false}]}
{"op":"mcm","clk":"11540661789","pt":1719497045329,"mc":[{"id":"1.230180116","rc":[{"atl":[[9.4,3.25],[8.8,2]],"id":64253836}],"con":true,"img":false}]}
{"op":"mcm","clk":"11540661805","pt":1719497045433,"mc":[{"id":"1.230180116","rc":[{"atl":[[8.8,2.45]],"id":64253836}],"con":true,"img":false}]}
{"op":"mcm","clk":"11540661829","pt":1719497045644,"mc":[{"id":"1.230180116","rc":[{"atb":[[4.9,0.84]],"id":64253836}],"con":true,"img":false}]}
{"op":"mcm","clk":"11540661860","pt":1719497046010,"mc":[{"id":"1.230180116","rc":[{"atl":[[9,3.47]],"id":64253836}],"con":true,"img":false}]}
{"op":"mcm","clk":"11540661870","pt":1719497046117,"mc":[{"id":"1.230180116","rc":[{"atb":[[3.2,2.34]],"id":64253836}],"con":true,"img":false}]}
{"op":"mcm","clk":"11540661900","pt":1719497046522,"mc":[{"id":"1.230180116","rc":[{"atl":[[8.8,2]],"id":64253836}],"con":true,"img":false}]}
{"op":"mcm","clk":"11540661907","pt":1719497046638,"mc":[{"id":"1.230180116","rc":[{"atb":[[2.88,0]],"id":64253836},{"atl":[[9.4,3.7]],"id":64253836},{"atb":[[3.4,6.11]],"id":48536142},{"atb":[[2.88,0]],"id":68900945}],"con":true,"img":false}]}
{"op":"mcm","clk":"11540661932","pt":1719497046944,"mc":[{"id":"1.230180116","rc":[{"atb":[[3.35,0]],"id":48536142}],"con":true,"img":false}]}
{"op":"mcm","clk":"11540661939","pt":1719497047044,"mc":[{"id":"1.230180116","rc":[{"atl":[[10,0]],"id":64253836}],"con":true,"img":false}]}
{"op":"mcm","clk":"11540661962","pt":1719497047306,"mc":[{"id":"1.230180116","rc":[{"atl":[[8.8,5.45]],"id":64253836}],"con":true,"img":false}]}
{"op":"mcm","clk":"11540661993","pt":1719497047621,"mc":[{"id":"1.230180116","rc":[{"atl":[[8.6,2.95]],"id":64253836}],"con":true,"img":false}]}
{"op":"mcm","clk":"11540661998","pt":1719497047719,"mc":[{"id":"1.230180116","rc":[{"atl":[[9.4,3.25]],"id":64253836}],"con":true,"img":false}]}
{"op":"mcm","clk":"11540662004","pt":1719497047826,"mc":[{"id":"1.230180116","rc":[{"atl":[[8.6,3.41]],"id":64253836}],"con":true,"img":false}]}
{"op":"mcm","clk":"11540662015","pt":1719497048040,"mc":[{"id":"1.230180116","rc":[{"atb":[[3.8,0],[4.2,6]],"id":63031611},{"atb":[[4,0],[4.5,6]],"id":69366841},{"atl":[[12.5,1]],"id":69366841},{"atb":[[5.2,1.84]],"id":40831161},{"atl":[[26,1]],"id":40831161},{"atb":[[3.45,6],[3.15,0]],"id":64253836},{"atl":[[8.2,1],[9.6,0],[8.6,6.88],[9.8,0.52]],"id":64253836},{"atb":[[2.84,0],[2.58,23.98]],"id":48536142},{"atl":[[7.4,0],[6.2,8]],"id":48536142},{"atb":[[3.5,6],[3.2,0]],"id":68900945},{"atl":[[9,1]],"id":68900945}],"con":true,"img":false}]}
{"op":"mcm","clk":"11540662023","pt":1719497048137,"mc":[{"id":"1.230180116","rc":[{"atl":[[8.6,9.94],[8.8,4.45]],"id":64253836},{"atb":[[3.4,0.84]],"id":48536142}],"con":true,"img":false}]}
{"op":"mcm","clk":"11540662029","pt":1719497048243,"mc":[{"id":"1.230180116","rc":[{"atl":[[8.4,1],[8.8,3.45]],"id":64253836}],"con":true,"img":false}]}
{"op":"mcm","clk":"11540662045","pt":1719497048402,"mc":[{"id":"1.230180116","rc":[{"atl":[[8.4,2]],"id":64253836}],"con":true,"img":false}]}
{"op":"mcm","clk":"11540662055","pt":1719497048505,"mc":[{"id":"1.230180116","rc":[{"atl":[[8.6,6.98]],"id":64253836}],"con":true,"img":false}]}
{"op":"mcm","clk":"11540662063","pt":1719497048613,"mc":[{"id":"1.230180116","rc":[{"atl":[[9.4,0]],"id":64253836},{"atb":[[3.35,0.84],[3.4,0]],"id":48536142}],"con":true,"img":false}]}
{"op":"mcm","clk":"11540662070","pt":1719497048716,"mc":[{"id":"1.230180116","rc":[{"atl":[[8.2,4.11]],"id":64253836},{"atb":[[3.35,7.19]],"id":48536142}],"con":true,"img":false}]}
{"op":"mcm","clk":"11540662092","pt":1719497048921,"mc":[{"id":"1.230180116","rc":[{"atl":[[8.6,6.53]],"id":64253836}],"con":true,"img":false}]}
{"op":"mcm","clk":"11540662104","pt":1719497049020,"mc":[{"id":"1.230180116","rc":[{"atl":[[8,0.45]],"id":64253836}],"con":true,"img":false}]}
{"op":"mcm","clk":"11540662125","pt":1719497049331,"mc":[{"id":"1.230180116","rc":[{"atl":[[8,3.63]],"id":64253836}],"con":true,"img":false}]}
{"op":"mcm","clk":"11540662138","pt":1719497049543,"mc":[{"id":"1.230180116","rc":[{"atl":[[7.8,0.84]],"id":64253836}],"con":true,"img":false}]}
{"op":"mcm","clk":"11540662165","pt":1719497049804,"mc":[{"id":"1.230180116","rc":[{"atl":[[8.4,1]],"id":64253836}],"con":true,"img":false}]}
{"op":"mcm","clk":"11540662172","pt":1719497049907,"mc":[{"id":"1.230180116","rc":[{"atl":[[7.8,1.84]],"id":64253836}],"con":true,"img":false}]}
{"op":"mcm","clk":"11540662195","pt":1719497050322,"mc":[{"id":"1.230180116","rc":[{"atl":[[8,0.45],[9,0]],"id":64253836}],"con":true,"img":false}]}
{"op":"mcm","clk":"11540662214","pt":1719497050635,"mc":[{"id":"1.230180116","rc":[{"atl":[[7.8,5.63]],"id":64253836}],"con":true,"img":false}]}
{"op":"mcm","clk":"11540662225","pt":1719497050735,"mc":[{"id":"1.230180116","rc":[{"atb":[[4.9,1.84],[4.7,0]],"id":64253836},{"atb":[[3.45,1]],"id":48536142},{"atb":[[4.9,2.67],[4.7,0]],"id":68900945}],"con":true,"img":false}]}
{"op":"mcm","clk":"11540662250","pt":1719497051047,"mc":[{"id":"1.230180116","rc":[{"atb":[[3.35,0.84]],"id":48536142}],"con":true,"img":false}]}
{"op":"mcm","clk":"11540662258","pt":1719497051109,"mc":[{"id":"1.230180116","rc":[{"atb":[[3.55,2.11]],"id":68900945}],"con":true,"img":false}]}
{"op":"mcm","clk":"11540662266","pt":1719497051209,"mc":[{"id":"1.230180116","rc":[{"atl":[[15,1.86]],"id":68900945}],"con":true,"img":false}]}
{"op":"mcm","clk":"11540662277","pt":1719497051310,"mc":[{"id":"1.230180116","rc":[{"atl":[[8,0]],"id":64253836}],"con":true,"img":false}]}
{"op":"mcm","clk":"11540662285","pt":1719497051413,"mc":[{"id":"1.230180116","rc":[{"atl":[[7.8,4.63],[7.6,0.45]],"id":64253836}],"con":true,"img":false}]}
{"op":"mcm","clk":"11540662297","pt":1719497051517,"mc":[{"id":"1.230180116","rc":[{"atl":[[8,1]],"id":64253836}],"con":true,"img":false}]}
{"op":"mcm","clk":"11540662343","pt":1719497052141,"mc":[{"id":"1.230180116","rc":[{"atl":[[7.6,3.8]],"id":64253836}],"con":true,"img":false}]}
{"op":"mcm","clk":"11540662357","pt":1719497052347,"mc":[{"id":"1.230180116","rc":[{"atl":[[8.2,3.11]],"id":64253836}],"con":true,"img":false}]}
{"op":"mcm","clk":"11540662365","pt":1719497052450,"mc":[{"id":"1.230180116","rc":[{"atl":[[8,0]],"id":64253836},{"atb":[[2.92,6.16]],"id":68900945},{"atl":[[15.5,1.72]],"id":68900945}],"con":true,"img":false}]}
{"op":"mcm","clk":"11540662377","pt":1719497052503,"mc":[{"id":"1.230180116","rc":[{"atl":[[7.4,1],[7.6,3.34]],"id":64253836},{"atl":[[14.5,1]],"id":68900945}],"con":true,"img":false}]}
{"op":"mcm","clk":"11540662382","pt":1719497052621,"mc":[{"id":"1.230180116","rc":[{"atl":[[7.4,2],[1000,0.45]],"id":64253836}],"con":true,"img":false}]}
{"op":"mcm","clk":"11540662391","pt":1719497052710,"mc":[{"id":"1.230180116","rc":[{"atl":[[14.5,3],[16,0]],"id":68900945}],"con":true,"img":false}]}
{"op":"mcm","clk":"11540662401","pt":1719497052814,"mc":[{"id":"1.230180116","rc":[{"atl":[[8.8,0]],"id":64253836}],"con":true,"img":false}]}
{"op":"mcm","clk":"11540662409","pt":1719497052927,"mc":[{"id":"1.230180116","rc":[{"atl":[[7.4,5.65]],"id":64253836}],"con":true,"img":false}]}
{"op":"mcm","clk":"11540662427","pt":1719497053131,"mc":[{"id":"1.230180116","rc":[{"atl":[[7.4,4.65],[1000,0],[7.6,0]],"id":64253836}],"con":true,"img":false}]}
{"op":"mcm","clk":"11540662437","pt":1719497053228,"mc":[{"id":"1.230180116","rc":[{"atl":[[7.8,3.79],[7.2,1.45]],"id":64253836},{"atl":[[15.5,0.88]],"id":68900945}],"con":true,"img":false}]}
{"op":"mcm","clk":"11540662448","pt":1719497053334,"mc":[{"id":"1.230180116","rc":[{"atb":[[2.58,6],[2.9,20.36]],"id":48536142}],"con":true,"img":false}]}
{"op":"mcm","clk":"11540662456","pt":1719497053437,"mc":[{"id":"1.230180116","rc":[{"atl":[[7.4,3.65]],"id":64253836},{"atb":[[3.35,4.24]],"id":48536142}],"con":true,"img":false}]}
{"op":"mcm","clk":"11540662466","pt":1719497053539,"mc":[{"id":"1.230180116","rc":[{"atl":[[7.6,1]],"id":64253836},{"atl":[[14,1.97]],"id":68900945}],"con":true,"img":false}]}
{"op":"mcm","clk":"11540662492","pt":1719497053803,"mc":[{"id":"1.230180116","rc":[{"atl":[[7.2,1]],"id":64253836}],"con":true,"img":false}]}
{"op":"mcm","clk":"11540662503","pt":1719497053913,"mc":[{"id":"1.230180116","rc":[{"atl":[[1000,0.45]],"id":64253836}],"con":true,"img":false}]}
{"op":"mcm","clk":"11540662536","pt":1719497054425,"mc":[{"id":"1.230180116","rc":[{"atl":[[7.6,0]],"id":64253836},{"atl":[[14.5,2]],"id":68900945}],"con":true,"img":false}]}
{"op":"mcm","clk":"11540662544","pt":1719497054532,"mc":[{"id":"1.230180116","rc":[{"atl":[[7.2,2]],"id":64253836},{"atl":[[13.5,1]],"id":68900945}],"con":true,"img":false}]}
{"op":"mcm","clk":"11540662606","pt":1719497055205,"mc":[{"id":"1.230180116","rc":[{"atb":[[2.16,11.87]],"id":63031611},{"atb":[[2.16,11.87]],"id":40831161}],"con":true,"img":false}]}
{"op":"mcm","clk":"11540662614","pt":1719497055310,"mc":[{"id":"1.230180116","rc":[{"atl":[[24,1.84]],"id":69366841},{"atl":[[9.8,0]],"id":64253836},{"atl":[[15.5,0.55]],"id":68900945}],"con":true,"img":false}]}
{"op":"mcm","clk":"11540662631","pt":1719497055514,"mc":[{"id":"1.230180116","rc":[{"atb":[[2.5,13.76]],"id":48536142}],"con":true,"img":false}]}
{"op":"mcm","clk":"11540662638","pt":1719497055617,"mc":[{"id":"1.230180116","rc":[{"atb":[[2.16,11.87]],"id":69366841}],"con":true,"img":false}]}
{"op":"mcm","clk":"11540662668","pt":1719497055936,"mc":[{"id":"1.230180116","rc":[{"atl":[[11,0],[11.5,1]],"id":63031611},{"atb":[[2.68,11.26]],"id":48536142}],"con":true,"img":false}]}
{"op":"mcm","clk":"11540662723","pt":1719497056350,"mc":[{"id":"1.230180116","rc":[{"atb":[[7,1.02]],"id":63031611}],"con":true,"img":false}]}
{"op":"mcm","clk":"11540662750","pt":1719497056611,"mc":[{"id":"1.230180116","rc":[{"atl":[[7,0.84]],"id":64253836}],"con":true,"img":false}]}
{"op":"mcm","clk":"11540662791","pt":1719497057141,"mc":[{"id":"1.230180116","rc":[{"atb":[[4.5,0],[4.6,6]],"id":69366841},{"atl":[[12.5,0],[13,1]],"id":69366841},{"atl":[[8.4,0],[8.6,3.47]],"id":64253836},{"atb":[[2.64,23.14],[2.9,0]],"id":48536142},{"atl":[[5.6,13.82]],"id":48536142},{"atl":[[9,0],[9.2,1]],"id":68900945}],"con":true,"img":false}]}
{"op":"mcm","clk":"11540662797","pt":1719497057243,"mc":[{"id":"1.230180116","rc":[{"atb":[[4.3,8.42]],"id":63031611},{"atl":[[70,1.38]],"id":63031611},{"atl":[[23,2.36],[25,0.84]],"id":69366841},{"atl":[[7,4.63]],"id":64253836},{"atb":[[3.35,15.61]],"id":48536142},{"atl":[[6.2,0]],"id":48536142},{"atl":[[13,2],[14.5,0]],"id":68900945}],"con":true,"img":false}]}
{"op":"mcm","clk":"11540662838","pt":1719497057651,"mc":[{"id":"1.230180116","rc":[{"atl":[[12.5,2.05]],"id":68900945}],"con":true,"img":false}]}
{"op":"mcm","clk":"11540662844","pt":1719497057705,"mc":[{"id":"1.230180116","rc":[{"atl":[[6.8,3.73]],"id":64253836}],"con":true,"img":false}]}
{"op":"mcm","clk":"11540662865","pt":1719497057915,"mc":[{"id":"1.230180116","rc":[{"atb":[[3.4,5.27]],"id":48536142}],"con":true,"img":false}]}
{"op":"mcm","clk":"11540662920","pt":1719497058537,"mc":[{"id":"1.230180116","rc":[{"atl":[[8.2,0]],"id":64253836}],"con":true,"img":false}]}
{"op":"mcm","clk":"11540662948","pt":1719497058953,"mc":[{"id":"1.230180116","rc":[{"atl":[[6.8,7.88]],"id":64253836}],"con":true,"img":false}]}
{"op":"mcm","clk":"11540662967","pt":1719497059110,"mc":[{"id":"1.230180116","rc":[{"atl":[[1000,0],[7.2,1]],"id":64253836}],"con":true,"img":false}]}
{"op":"mcm","clk":"11540662976","pt":1719497059208,"mc":[{"id":"1.230180116","rc":[{"atl":[[6.6,0.45]],"id":64253836}],"con":true,"img":false}]}
{"op":"mcm","clk":"11540662983","pt":1719497059311,"mc":[{"id":"1.230180116","rc":[{"atl":[[6.6,1.45]],"id":64253836}],"con":true,"img":false}]}
{"op":"mcm","clk":"11540663023","pt":1719497059727,"mc":[{"id":"1.230180116","rc":[{"atl":[[24,0.84]],"id":69366841},{"atl":[[7.2,0]],"id":64253836},{"atl":[[13.5,0]],"id":68900945}],"con":true,"img":false}]}
{"op":"mcm","clk":"11540663037","pt":1719497059830,"mc":[{"id":"1.230180116","rc":[{"atl":[[22,1]],"id":69366841},{"atl":[[6.6,2.45]],"id":64253836},{"atl":[[12,1]],"id":68900945}],"con":true,"img":false}]}
{"op":"mcm","clk":"11540663049","pt":1719497059932,"mc":[{"id":"1.230180116","rc":[{"atl":[[6.8,4.15]],"id":64253836}],"con":true,"img":false}]}
{"op":"mcm","clk":"11540663064","pt":1719497060139,"mc":[{"id":"1.230180116","rc":[{"atl":[[6.4,3.97],[7.8,0]],"id":64253836}],"con":true,"img":false}]}
{"op":"mcm","clk":"11540663072","pt":1719497060251,"mc":[{"id":"1.230180116","rc":[{"atl":[[6.6,7.34]],"id":64253836}],"con":true,"img":false}]}
{"op":"mcm","clk":"11540663084","pt":1719497060451,"mc":[{"id":"1.230180116","rc":[{"atl":[[6.6,6.89]],"id":64253836}],"con":true,"img":false}]}
{"op":"mcm","clk":"11540663093","pt":1719497060504,"mc":[{"id":"1.230180116","rc":[{"atl":[[1000,0.45]],"id":64253836}],"con":true,"img":false}]}
{"op":"mcm","clk":"11540663107","pt":1719497060711,"mc":[{"id":"1.230180116","rc":[{"atl":[[24,0]],"id":69366841},{"atl":[[7,3.79]],"id":64253836}],"con":true,"img":false}]}
{"op":"mcm","clk":"11540663119","pt":1719497060819,"mc":[{"id":"1.230180116","rc":[{"atl":[[7.4,0],[6.6,5.89]],"id":64253836}],"con":true,"img":false}]}
{"op":"mcm","clk":"11540663130","pt":1719497060919,"mc":[{"id":"1.230180116","rc":[{"atl":[[6.4,8.68],[1000,0],[6.2,1]],"id":64253836}],"con":true,"img":false}]}
{"op":"mcm","clk":"11540663136","pt":1719497061023,"mc":[{"id":"1.230180116","rc":[{"atl":[[6.2,1.45]],"id":64253836},{"atb":[[3.45,0],[3.4,0]],"id":48536142},{"atl":[[3.4,14.9]],"id":48536142},{"trd":[[3.4,12.53],[3.45,1.99]],"ltp":3.4,"tv":14.52,"id":48536142}],"con":true,"img":false}]}
{"op":"mcm","clk":"11540663143","pt":1719497061132,"mc":[{"id":"1.230180116","rc":[{"atb":[[4.4,1.7]],"id":63031611},{"atl":[[6.6,4.89]],"id":64253836},{"atb":[[3.35,12.21],[3.4,0.26]],"id":48536142},{"atl":[[3.4,0]],"id":48536142},{"trd":[[3.4,42.33]],"ltp":3.4,"tv":42.33,"id":48536142}],"con":true,"img":false}]}
{"op":"mcm","clk":"11540663158","pt":1719497061336,"mc":[{"id":"1.230180116","rc":[{"atb":[[4.4,2.7]],"id":63031611},{"atl":[[6.2,2.45]],"id":64253836}],"con":true,"img":false}]}
{"op":"mcm","clk":"11540663166","pt":1719497061443,"mc":[{"id":"1.230180116","rc":[{"atb":[[3.35,13.39]],"id":48536142}],"con":true,"img":false}]}
{"op":"mcm","clk":"11540663173","pt":1719497061540,"mc":[{"id":"1.230180116","rc":[{"atl":[[6.4,4.71]],"id":64253836}],"con":true,"img":false}]}
{"op":"mcm","clk":"11540663185","pt":1719497061748,"mc":[{"id":"1.230180116","rc":[{"atb":[[5.2,3.6]],"id":40831161},{"atb":[[3.4,6.61]],"id":48536142}],"con":true,"img":false}]}
{"op":"mcm","clk":"11540663188","pt":1719497061854,"mc":[{"id":"1.230180116","rc":[{"atb":[[4.5,7.39]],"id":63031611},{"atl":[[3.75,9.26]],"id":48536142}],"con":true,"img":false}]}
{"op":"mcm","clk":"11540663206","pt":1719497062015,"mc":[{"id":"1.230180116","rc":[{"atb":[[4.4,1.7],[4.5,8.58]],"id":63031611}],"con":true,"img":false}]}
{"op":"mcm","clk":"11540663222","pt":1719497062222,"mc":[{"id":"1.230180116","rc":[{"atb":[[4.6,1]],"id":63031611}],"con":true,"img":false}]}
{"op":"mcm","clk":"11540663231","pt":1719497062324,"mc":[{"id":"1.230180116","rc":[{"atb":[[2.64,0],[2.74,25.26],[3.4,6.34]],"id":48536142}],"con":true,"img":false}]}
{"op":"mcm","clk":"11540663242","pt":1719497062428,"mc":[{"id":"1.230180116","rc":[{"atl":[[12,3],[13,0]],"id":68900945}],"con":true,"img":false}]}
{"op":"mcm","clk":"11540663254","pt":1719497062530,"mc":[{"id":"1.230180116","rc":[{"atl":[[7.2,5.39]],"id":64253836}],"con":true,"img":false}]}
{"op":"mcm","clk":"11540663280","pt":1719497062843,"mc":[{"id":"1.230180116","rc":[{"atl":[[3.8,2.86]],"id":48536142}],"con":true,"img":false}]}
{"op":"mcm","clk":"11540663285","pt":1719497062951,"mc":[{"id":"1.230180116","rc":[{"atl":[[3.7,1]],"id":48536142}],"con":true,"img":false}]}
{"op":"mcm","clk":"11540663331","pt":1719497063412,"mc":[{"id":"1.230180116","rc":[{"atl":[[11.5,2.55]],"id":68900945}],"con":true,"img":false}]}
{"op":"mcm","clk":"11540663371","pt":1719497063829,"mc":[{"id":"1.230180116","rc":[{"atb":[[4.9,1.84]],"id":68900945}],"con":true,"img":false}]}
{"op":"mcm","clk":"11540663378","pt":1719497063936,"mc":[{"id":"1.230180116","rc":[{"atl":[[12,2]],"id":68900945}],"con":true,"img":false}]}
{"op":"mcm","clk":"11540663391","pt":1719497064039,"mc":[{"id":"1.230180116","rc":[{"atl":[[6,0.84]],"id":64253836},{"atl":[[11,1]],"id":68900945}],"con":true,"img":false}]}
{"op":"mcm","clk":"11540663415","pt":1719497064250,"mc":[{"id":"1.230180116","rc":[{"atl":[[7,0]],"id":64253836}],"con":true,"img":false}]}
{"op":"mcm","clk":"11540663429","pt":1719497064351,"mc":[{"id":"1.230180116","rc":[{"atl":[[7.2,0],[6,5.66]],"id":64253836}],"con":true,"img":false}]}
{"op":"mcm","clk":"11540663446","pt":1719497064565,"mc":[{"id":"1.230180116","rc":[{"atl":[[6.2,1.45]],"id":64253836}],"con":true,"img":false}]}
{"op":"mcm","clk":"11540663458","pt":1719497064613,"mc":[{"id":"1.230180116","rc":[{"atl":[[6.2,1]],"id":64253836}],"con":true,"img":false}]}
{"op":"mcm","clk":"11540663467","pt":1719497064724,"mc":[{"id":"1.230180116","rc":[{"atl":[[5.9,1],[1000,0.45]],"id":64253836}],"con":true,"img":false}]}
{"op":"mcm","clk":"11540663481","pt":1719497064923,"mc":[{"id":"1.230180116","rc":[{"atl":[[6.2,0]],"id":64253836}],"con":true,"img":false}]}
{"op":"mcm","clk":"11540663486","pt":1719497065031,"mc":[{"id":"1.230180116","rc":[{"atl":[[5.9,2]],"id":64253836}],"con":true,"img":false}]}
{"op":"mcm","clk":"11540663547","pt":1719497065754,"mc":[{"id":"1.230180116","rc":[{"atl":[[6.8,0]],"id":64253836}],"con":true,"img":false}]}
{"op":"mcm","clk":"11540663559","pt":1719497065911,"mc":[{"id":"1.230180116","rc":[{"atl":[[5.9,7.54]],"id":64253836}],"con":true,"img":false}]}
{"op":"mcm","clk":"11540663589","pt":1719497066339,"mc":[{"id":"1.230180116","rc":[{"atl":[[1000,0]],"id":64253836}],"con":true,"img":false}]}
{"op":"mcm","clk":"11540663598","pt":1719497066438,"mc":[{"id":"1.230180116","rc":[{"atl":[[5.8,0.45]],"id":64253836}],"con":true,"img":false}]}
{"op":"mcm","clk":"11540663614","pt":1719497066643,"mc":[{"id":"1.230180116","rc":[{"atl":[[5.9,6.54]],"id":64253836}],"con":true,"img":false}]}
{"op":"mcm","clk":"11540663623","pt":1719497066746,"mc":[{"id":"1.230180116","rc":[{"atl":[[6.6,0]],"id":64253836}],"con":true,"img":false}]}
{"op":"mcm","clk":"11540663630","pt":1719497066856,"mc":[{"id":"1.230180116","rc":[{"atl":[[5.8,1.45]],"id":64253836}],"con":true,"img":false}]}
{"op":"mcm","clk":"11540663637","pt":1719497066954,"mc":[{"id":"1.230180116","rc":[{"atb":[[5.1,0]],"id":64253836},{"trd":[[5.1,1.69]],"ltp":5.1,"tv":1.69,"id":64253836}],"con":true,"img":false}]}
{"op":"mcm","clk":"11540663659","pt":1719497067122,"mc":[{"id":"1.230180116","rc":[{"atb":[[4.7,1]],"id":69366841}],"con":true,"img":false}]}
{"op":"mcm","clk":"11540663697","pt":1719497067541,"mc":[{"id":"1.230180116","rc":[{"atl":[[5.8,7.09]],"id":64253836},{"atl":[[11,3],[12,0]],"id":68900945}],"con":true,"img":false}]}
{"op":"mcm","clk":"11540663736","pt":1719497068060,"mc":[{"id":"1.230180116","rc":[{"atl":[[6,4.82]],"id":64253836}],"con":true,"img":false}]}
{"op":"mcm","clk":"11540663749","pt":1719497068160,"mc":[{"id":"1.230180116","rc":[{"atl":[[5.8,6.64]],"id":64253836}],"con":true,"img":false}]}
{"op":"mcm","clk":"11540663759","pt":1719497068263,"mc":[{"id":"1.230180116","rc":[{"atl":[[1000,0.45]],"id":64253836}],"con":true,"img":false}]}
{"op":"mcm","clk":"11540663772","pt":1719497068370,"mc":[{"id":"1.230180116","rc":[{"atl":[[15,0]],"id":68900945}],"con":true,"img":false}]}
{"op":"mcm","clk":"11540663792","pt":1719497068521,"mc":[{"id":"1.230180116","rc":[{"atl":[[10.5,2.33]],"id":68900945}],"con":true,"img":false}]}
{"op":"mcm","clk":"11540663951","pt":1719497070647,"mc":[{"id":"1.230180116","rc":[{"atl":[[5.9,5.54]],"id":64253836}],"con":true,"img":false}]}
{"op":"mcm","clk":"11540663957","pt":1719497070756,"mc":[{"id":"1.230180116","rc":[{"atl":[[5.7,1]],"id":64253836}],"con":true,"img":false}]}
{"op":"mcm","clk":"11540663968","pt":1719497070857,"mc":[{"id":"1.230180116","rc":[{"atl":[[6.4,0],[5.8,1],[5.9,0],[6,0]],"id":64253836}],"con":true,"img":false}]}
{"op":"mcm","clk":"11540663972","pt":1719497070962,"mc":[{"id":"1.230180116","rc":[{"atb":[[3.7,8.8],[4.2,0]],"id":63031611},{"atl":[[11.5,0],[12,1]],"id":63031611},{"atb":[[5.1,1.65],[5,8.27]],"id":40831161},{"atl":[[7.8,10.36],[8.4,2.99],[8.6,0]],"id":64253836},{"atb":[[2.62,25.26],[2.74,0]],"id":48536142},{"atl":[[4.9,16.84],[5.6,1.54]],"id":48536142},{"atb":[[3,6.17],[3.5,0]],"id":68900945}],"con":true,"img":false}]}
{"op":"mcm","clk":"11540663979","pt":1719497071065,"mc":[{"id":"1.230180116","rc":[{"atl":[[65,2],[75,0]],"id":63031611},{"atb":[[2.92,6.16]],"id":64253836},{"atl":[[11,2]],"id":68900945}],"con":true,"img":false}]}
{"op":"mcm","clk":"11540663989","pt":1719497071167,"mc":[{"id":"1.230180116","rc":[{"atb":[[3.15,5.51]],"id":63031611},{"atl":[[1000,0]],"id":64253836},{"atl":[[10,1]],"id":68900945}],"con":true,"img":false}]}
{"op":"mcm","clk":"11540664000","pt":1719497071221,"mc":[{"id":"1.230180116","rc":[{"atb":[[5.3,4.79]],"id":40831161},{"atl":[[7.6,0.45]],"id":64253836}],"con":true,"img":false}]}
{"op":"mcm","clk":"11540664019","pt":1719497071429,"mc":[{"id":"1.230180116","rc":[{"atb":[[4.8,0]],"id":40831161}],"con":true,"img":false}]}
{"op":"mcm","clk":"11540664029","pt":1719497071538,"mc":[{"id":"1.230180116","rc":[{"atb":[[5.4,0.84],[5.1,2.65]],"id":40831161}],"con":true,"img":false}]}
{"op":"mcm","clk":"11540664042","pt":1719497071638,"mc":[{"id":"1.230180116","rc":[{"atl":[[70,0.38],[60,0.38]],"id":63031611},{"atl":[[7.6,4.24],[5.7,0]],"id":64253836},{"atb":[[3,7.28]],"id":68900945}],"con":true,"img":false}]}
{"op":"mcm","clk":"11540664053","pt":1719497071750,"mc":[{"id":"1.230180116","rc":[{"atl":[[60,1.38]],"id":63031611},{"atl":[[7.6,5.24]],"id":64253836}],"con":true,"img":false}]}
{"op":"mcm","clk":"11540664069","pt":1719497071949,"mc":[{"id":"1.230180116","rc":[{"atb":[[5.2,1.84]],"id":40831161}],"con":true,"img":false}]}
{"op":"mcm","clk":"11540664081","pt":1719497072056,"mc":[{"id":"1.230180116","rc":[{"atb":[[5.4,2.6]],"id":40831161}],"con":true,"img":false}]}
{"op":"mcm","clk":"11540664100","pt":1719497072260,"mc":[{"id":"1.230180116","rc":[{"atb":[[5.1,1.65]],"id":40831161}],"con":true,"img":false}]}
{"op":"mcm","clk":"11540664107","pt":1719497072366,"mc":[{"id":"1.230180116","rc":[{"atb":[[5.3,0]],"id":40831161}],"con":true,"img":false}]}
{"op":"mcm","clk":"11540664122","pt":1719497072578,"mc":[{"id":"1.230180116","rc":[{"atb":[[5.4,0.84],[5.5,1],[5.2,1]],"id":40831161}],"con":true,"img":false}]}
{"op":"mcm","clk":"11540664132","pt":1719497072626,"mc":[{"id":"1.230180116","rc":[{"atb":[[5.2,2.76]],"id":40831161},{"atl":[[10,3],[11,0]],"id":68900945}],"con":true,"img":false}]}
{"op":"mcm","clk":"11540664163","pt":1719497073043,"mc":[{"id":"1.230180116","rc":[{"atb":[[5.4,0]],"id":40831161}],"con":true,"img":false}]}
{"op":"mcm","clk":"11540664199","pt":1719497073457,"mc":[{"id":"1.230180116","rc":[{"atl":[[14,0]],"id":68900945}],"con":true,"img":false}]}
{"op":"mcm","clk":"11540664206","pt":1719497073566,"mc":[{"id":"1.230180116","rc":[{"atl":[[9.8,2.62]],"id":68900945}],"con":true,"img":false}]}
{"op":"mcm","clk":"11540664304","pt":1719497074662,"mc":[{"id":"1.230180116","rc":[{"atl":[[10,2]],"id":68900945}],"con":true,"img":false}]}
{"op":"mcm","clk":"11540664316","pt":1719497074766,"mc":[{"id":"1.230180116","rc":[{"atl":[[9.6,1]],"id":68900945}],"con":true,"img":false}]}
{"op":"mcm","clk":"11540664478","pt":1719497076366,"mc":[{"id":"1.230180116","rc":[{"atb":[[2.28,0]],"id":69366841},{"atb":[[2.3,0]],"id":40831161},{"atb":[[2.9,0]],"id":64253836},{"atb":[[2.9,0]],"id":68900945}],"con":true,"img":false}]}
{"op":"mcm","clk":"11540664579","pt":1719497077460,"mc":[{"id":"1.230180116","rc":[{"atb":[[5,0]],"id":64253836},{"trd":[[5,3.38]],"ltp":5.0,"tv":3.38,"id":64253836}],"con":true,"img":false}]}
{"op":"mcm","clk":"11540664608","pt":1719497077772,"mc":[{"id":"1.230180116","rc":[{"atb":[[5.1,7.65],[5,1]],"id":40831161},{"atb":[[3.5,1.69]],"id":64253836},{"atl":[[8.6,1]],"id":64253836},{"atl":[[10,0],[9.8,4.95]],"id":68900945}],"con":true,"img":false}]}
{"op":"mcm","clk":"11540664624","pt":1719497078001,"mc":[{"id":"1.230180116","rc":[{"atb":[[5.5,0]],"id":40831161}],"con":true,"img":false}]}
{"op":"mcm","clk":"11540664634","pt":1719497078061,"mc":[{"id":"1.230180116","rc":[{"atb":[[5.3,4.79],[5.4,1]],"id":40831161}],"con":true,"img":false}]}
{"op":"mcm","clk":"11540664649","pt":1719497078262,"mc":[{"id":"1.230180116","rc":[{"atb":[[5,1.69]],"id":68900945}],"con":true,"img":false}]}
{"op":"mcm","clk":"11540664658","pt":1719497078371,"mc":[{"id":"1.230180116","rc":[{"atb":[[4.8,0],[3,6.17]],"id":68900945}],"con":true,"img":false}]}
{"op":"mcm","clk":"11540664672","pt":1719497078578,"mc":[{"id":"1.230180116","rc":[{"atb":[[5.1,0.84]],"id":68900945}],"con":true,"img":false}]}
{"op":"mcm","clk":"11540664679","pt":1719497078676,"mc":[{"id":"1.230180116","rc":[{"atb":[[5.3,0]],"id":40831161},{"atb":[[4.9,3.53],[5,0]],"id":68900945}],"con":true,"img":false}]}
{"op":"mcm","clk":"11540664728","pt":1719497078834,"mc":[{"id":"1.230180116","rc":[{"atl":[[1000,0.84]],"id":40831161}],"con":true,"img":false}]}
{"op":"mcm","clk":"11540664750","pt":1719497079148,"mc":[{"id":"1.230180116","rc":[{"atl":[[1000,0.33]],"id":40831161}],"con":true,"img":false}]}
{"op":"mcm","clk":"11540664758","pt":1719497079255,"mc":[{"id":"1.230180116","rc":[{"atb":[[5.1,0]],"id":68900945}],"con":true,"img":false}]}
{"op":"mcm","clk":"11540664779","pt":1719497079454,"mc":[{"id":"1.230180116","rc":[{"atl":[[1000,0]],"id":40831161}],"con":true,"img":false}]}
{"op":"mcm","clk":"11540664786","pt":1719497079562,"mc":[{"id":"1.230180116","rc":[{"atl":[[25,0.33]],"id":40831161}],"con":true,"img":false}]}
{"op":"mcm","clk":"11540664928","pt":1719497081065,"mc":[{"id":"1.230180116","rc":[{"atb":[[4.1,0]],"id":69366841}],"con":true,"img":false}]}
{"op":"mcm","clk":"11540664950","pt":1719497081377,"mc":[{"id":"1.230180116","rc":[{"atb":[[3.85,0]],"id":63031611}],"con":true,"img":false}]}
{"op":"mcm","clk":"11540664979","pt":1719497081646,"mc":[{"id":"1.230180116","rc":[{"atb":[[3.3,0]],"id":48536142}],"con":true,"img":false}]}
{"op":"mcm","clk":"11540665001","pt":1719497081846,"mc":[{"id":"1.230180116","rc":[{"atl":[[3.7,3.96]],"id":48536142}],"con":true,"img":false}]}
{"op":"mcm","clk":"11540665015","pt":1719497082053,"mc":[{"id":"1.230180116","rc":[{"atl":[[3.65,0.84]],"id":48536142}],"con":true,"img":false}]}
{"op":"mcm","clk":"11540665061","pt":1719497082679,"mc":[{"id":"1.230180116","rc":[{"atl":[[3.95,0]],"id":48536142}],"con":true,"img":false}]}
{"op":"mcm","clk":"11540665073","pt":1719497082837,"mc":[{"id":"1.230180116","rc":[{"atl":[[3.65,11.12]],"id":48536142}],"con":true,"img":false}]}
{"op":"mcm","clk":"11540665084","pt":1719497082990,"mc":[{"id":"1.230180116","rc":[{"atb":[[5.1,1.65],[5,7]],"id":40831161},{"atl":[[10,2.33],[9.8,2.62]],"id":68900945}],"con":true,"img":false}]}
{"op":"mcm","clk":"11540665124","pt":1719497083561,"mc":[{"id":"1.230180116","rc":[{"atl":[[3.7,2.96],[3.9,0]],"id":48536142}],"con":true,"img":false}]}
{"op":"mcm","clk":"11540665132","pt":1719497083666,"mc":[{"id":"1.230180116","rc":[{"atb":[[3.4,1.37]],"id":48536142},{"atl":[[3.75,8.42]],"id":48536142},{"trd":[[3.4,52.29]],"ltp":3.4,"tv":52.29,"id":48536142}],"con":true,"img":false}]}
{"op":"mcm","clk":"11540665208","pt":1719497084335,"mc":[{"id":"1.230180116","rc":[{"atb":[[3.35,12.21]],"id":48536142}],"con":true,"img":false}]}
{"op":"mcm","clk":"11540665326","pt":1719497085871,"mc":[{"id":"1.230180116","rc":[{"atb":[[2.68,6.09]],"id":48536142}],"con":true,"img":false}]}
{"op":"mcm","clk":"11540665334","pt":1719497085969,"mc":[{"id":"1.230180116","rc":[{"atl":[[3.6,3.08]],"id":48536142}],"con":true,"img":false}]}
{"op":"mcm","clk":"11540665367","pt":1719497086380,"mc":[{"id":"1.230180116","rc":[{"atb":[[3.5,3.83]],"id":64253836}],"con":true,"img":false}]}
{"op":"mcm","clk":"11540665392","pt":1719497086801,"mc":[{"id":"1.230180116","rc":[{"atl":[[3.6,13.5]],"id":48536142}],"con":true,"img":false}]}
{"op":"mcm","clk":"11540665556","pt":1719497088667,"mc":[{"id":"1.230180116","rc":[{"atb":[[2.58,11.49]],"id":48536142}],"con":true,"img":false}]}
{"op":"mcm","clk":"11540665578","pt":1719497088975,"mc":[{"id":"1.230180116","rc":[{"atb":[[5.1,7.65],[5,1]],"id":40831161}],"con":true,"img":false}]}
{"op":"mcm","clk":"11540665625","pt":1719497089549,"mc":[{"id":"1.230180116","rc":[{"atl":[[3.55,0.84]],"id":48536142}],"con":true,"img":false}]}
{"op":"mcm","clk":"11540665880","pt":1719497092848,"mc":[{"id":"1.230180116","rc":[{"atb":[[2.62,33.88]],"id":48536142}],"con":true,"img":false}]}
{"op":"mcm","clk":"11540665896","pt":1719497093071,"mc":[{"id":"1.230180116","rc":[{"atb":[[2.32,10.58]],"id":69366841}],"con":true,"img":false}]}
{"op":"mcm","clk":"11540665913","pt":1719497093262,"mc":[{"id":"1.230180116","rc":[{"atb":[[2.68,0]],"id":48536142}],"con":true,"img":false}]}
{"op":"mcm","clk":"11540665971","pt":1719497093990,"mc":[{"id":"1.230180116","rc":[{"atl":[[3.85,0]],"id":48536142}],"con":true,"img":false}]}
{"op":"mcm","clk":"11540665976","pt":1719497094097,"mc":[{"id":"1.230180116","rc":[{"atb":[[3.4,0]],"id":48536142},{"trd":[[3.4,55.03]],"ltp":3.4,"tv":55.03,"id":48536142}],"con":true,"img":false}]}
{"op":"mcm","clk":"11540665993","pt":1719497094351,"mc":[{"id":"1.230180116","rc":[{"atb":[[4.5,9.11],[4.6,0]],"id":69366841}],"con":true,"img":false}]}
{"op":"mcm","clk":"11540666003","pt":1719497094562,"mc":[{"id":"1.230180116","rc":[{"atl":[[3.55,6.92]],"id":48536142}],"con":true,"img":false}]}
{"op":"mcm","clk":"11540666019","pt":1719497094766,"mc":[{"id":"1.230180116","rc":[{"atl":[[3.55,15.91]],"id":48536142}],"con":true,"img":false}]}
{"op":"mcm","clk":"11540666036","pt":1719497095075,"mc":[{"id":"1.230180116","rc":[{"atl":[[3.65,10.28]],"id":48536142}],"con":true,"img":false}]}
{"op":"mcm","clk":"11540666438","pt":1719497099977,"mc":[{"id":"1.230180116","rc":[{"atl":[[3.4,1.88]],"id":48536142}],"con":true,"img":false}]}
{"op":"mcm","clk":"11540666445","pt":1719497100080,"mc":[{"id":"1.230180116","rc":[{"atb":[[3.35,10.81]],"id":48536142},{"atl":[[3.4,0]],"id":48536142},{"trd":[[3.35,2.81],[3.4,58.79]],"ltp":3.35,"tv":61.6,"id":48536142}],"con":true,"img":false}]}
{"op":"mcm","clk":"11540666462","pt":1719497100193,"mc":[{"id":"1.230180116","rc":[{"atl":[[10,0]],"id":68900945}],"con":true,"img":false}]}
{"op":"mcm","clk":"11540666477","pt":1719497100289,"mc":[{"id":"1.230180116","rc":[{"atl":[[10.5,5.66]],"id":68900945}],"con":true,"img":false}]}
{"op":"mcm","clk":"11540666546","pt":1719497100865,"mc":[{"id":"1.230180116","rc":[{"spn":5.85,"spf":1.0,"id":63031611},{"atb":[[2.3,0]],"id":69366841},{"spn":9.05,"spf":"NaN","id":69366841},{"atb":[[2.32,0]],"id":40831161},{"spn":5.15,"spf":1.0,"id":40831161},{"spn":4.9,"spf":1.0,"id":64253836},{"spn":3.45,"spf":"NaN","id":48536142},{"spn":7.05,"spf":"NaN","id":68900945}],"con":true,"img":false}]}
{"op":"mcm","clk":"11540666557","pt":1719497100969,"mc":[{"id":"1.230180116","rc":[{"atl":[[22,1]],"id":63031611}],"con":true,"img":false}]}
{"op":"mcm","clk":"11540666727","pt":1719497102472,"mc":[{"id":"1.230180116","rc":[{"atb":[[5.1,3.15]],"id":69366841},{"atb":[[5.4,1.9]],"id":40831161},{"atb":[[3.5,9]],"id":64253836},{"atb":[[3,19.61]],"id":68900945}],"con":true,"img":false}]}
{"op":"mcm","clk":"11540666765","pt":1719497102991,"mc":[{"id":"1.230180116","rc":[{"atb":[[5.1,9.22]],"id":69366841},{"atl":[[22,2.31]],"id":69366841}],"con":true,"img":false}]}
{"op":"mcm","clk":"11540666774","pt":1719497103092,"mc":[{"id":"1.230180116","rc":[{"atb":[[5.2,2.47],[4.7,0]],"id":69366841},{"atb":[[5.5,0.84]],"id":40831161}],"con":true,"img":false}]}
{"op":"mcm","clk":"11540666800","pt":1719497103407,"mc":[{"id":"1.230180116","rc":[{"atb":[[5.3,1.6],[5.1,7.56]],"id":69366841}],"con":true,"img":false}]}
{"op":"mcm","clk":"11540666816","pt":1719497103607,"mc":[{"id":"1.230180116","rc":[{"atb":[[5.2,3.47]],"id":69366841}],"con":true,"img":false}]}
{"op":"mcm","clk":"11540666835","pt":1719497103762,"mc":[{"id":"1.230180116","rc":[{"atb":[[5.2,1.84]],"id":69366841}],"con":true,"img":false}]}
{"op":"mcm","clk":"11540666843","pt":1719497103868,"mc":[{"id":"1.230180116","rc":[{"atb":[[5.3,9.2]],"id":69366841}],"con":true,"img":false}]}
{"op":"mcm","clk":"11540666866","pt":1719497104077,"mc":[{"id":"1.230180116","rc":[{"atb":[[5.2,0.84]],"id":69366841}],"con":true,"img":false}]}
{"op":"mcm","clk":"11540666880","pt":1719497104179,"mc":[{"id":"1.230180116","rc":[{"atb":[[5.3,10.41]],"id":69366841}],"con":true,"img":false}]}
{"op":"mcm","clk":"11540666892","pt":1719497104279,"mc":[{"id":"1.230180116","rc":[{"atb":[[5.4,1]],"id":69366841}],"con":true,"img":false}]}
{"op":"mcm","clk":"11540666911","pt":1719497104488,"mc":[{"id":"1.230180116","rc":[{"atb":[[5.3,8.81],[5.5,1.54]],"id":69366841}],"con":true,"img":false}]}
{"op":"mcm","clk":"11540666940","pt":1719497104898,"mc":[{"id":"1.230180116","rc":[{"atb":[[5.3,7.19]],"id":69366841}],"con":true,"img":false}]}
{"op":"mcm","clk":"11540666947","pt":1719497105000,"mc":[{"id":"1.230180116","rc":[{"atb":[[5.5,3.16]],"id":69366841}],"con":true,"img":false}]}
{"op":"mcm","clk":"11540666953","pt":1719497105107,"mc":[{"id":"1.230180116","rc":[{"atb":[[5.5,8.32],[5.2,0]],"id":69366841}],"con":true,"img":false}]}
{"op":"mcm","clk":"11540666970","pt":1719497105317,"mc":[{"id":"1.230180116","rc":[{"atb":[[5.4,0],[5.6,4.53]],"id":69366841}],"con":true,"img":false}]}
